1633806856.055477: {"ch":"ticker/1s","data":{"DOGEUSDT":{"t":1633806855647,"a":"0.24808248","A":"34540","b":"0.24765126","B":"34320","o":"0.24716516","c":"0.24785108","h":"0.25200000","l":"0.24609780","v":"229140","q":"56558.87119500","p":"0.00068592","P":"0.2775148406838569","L":1417909170}}}
1633806856.055569: {"ch":"ticker/1s","data":{"NEOBTC":{"t":1633806855840,"a":"0.0008790","A":"18.89","b":"0.0008785","B":"17.00","o":"0.0008662","c":"0.0008788","h":"0.0009067","l":"0.0008475","v":"155804.60","q":"136.161718879","p":"0.0000126","P":"1.454629415839298","L":1417984622}}}
1633806856.0556118: {"ch":"ticker/1s","data":{"DCRETH":{"t":1633806855938,"a":"0.036723","A":"0.448","b":"0.035979","B":"12.392","o":"0.035004","c":"0.036373","h":"0.036686","l":"0.035072","v":"8.326","q":"0.297986431","p":"0.001369","P":"3.910981602102617","L":1417957304}}}
1633806856.0556428: {"ch":"ticker/1s","data":{"EOSUSDT":{"t":1633806855941,"a":"4.98248","A":"26.49","b":"4.98144","B":"760.00","o":"4.71891","c":"4.98523","h":"5.06033","l":"4.57171","v":"7224629.96","q":"34899840.7456554","p":"0.26632","P":"5.643676187933230","L":1417984568}}}
1633806856.084353: {"ch":"orderbook/full","update":{"DCRETH":{"t":1633806856013,"s":499127,"a":[],"b":[["0.035702","17.000"],["0.035701","55.274"],["0.035656","0"],["0.035635","0.122"],["0.032563","251.202"],["0.032509","0"]]}}}
1633806856.0946481: {"ch":"orderbook/full","update":{"ATOMBCH":{"t":1633806855975,"s":274277,"a":[["0.1702422","0"],["0.1702498","0.13"]],"b":[["0.0170249","0.13"],["0.0170242","0"]]}}}
1633806856.09479: {"ch":"orderbook/full","update":{"XVSUSDT":{"t":1633806855962,"s":483980,"a":[],"b":[["28.0188","2.014"],["28.0011","22.945"],["27.9888","0"]]}}}
1633806856.10263: {"ch":"orderbook/full","update":{"HTBTC":{"t":1633806855959,"s":660755,"a":[["0.00026756","11985.76"],["0.00026795","0"]],"b":[]}}}
1633806856.1027598: {"ch":"orderbook/full","update":{"EOSUSDT":{"t":1633806856004,"s":1876024,"a":[],"b":[["4.98144","0"],["4.98122","0"],["4.98116","31.66"]]}}}
1633806856.18606: {"ch":"orderbook/full","update":{"XVSUSDT":{"t":1633806856060,"s":483981,"a":[["28.1262","105.569"],["28.1312","0"]],"b":[]}}}
1633806856.186183: {"ch":"orderbook/full","update":{"NEOBTC":{"t":1633806856044,"s":1498343,"a":[],"b":[["0.0008741","72.00"],["0.0008731","94.00"]]}}}
1633806856.192478: {"ch":"orderbook/full","update":{"EOSUSDT":{"t":1633806856129,"s":1876025,"a":[["4.98247","100.26"],["4.98290","0"],["4.98387","100.26"],["4.98598","0"]],"b":[["4.98028","440.89"]]}}}
1633806856.1952121: {"ch":"orderbook/full","update":{"USDTUSDP":{"t":1633806856052,"s":384579,"a":[["1.100000","5.96"]],"b":[["0.900000","15.34"]]}}}
1633806856.280579: {"ch":"orderbook/full","update":{"DCRETH":{"t":1633806856201,"s":499128,"a":[],"b":[["0.035635","0"]]}}}
1633806856.286478: {"ch":"orderbook/full","update":{"XVSUSDT":{"t":1633806856158,"s":483982,"a":[["28.2859","262.137"],["28.2938","0"]],"b":[]}}}
1633806856.2983942: {"ch":"orderbook/full","update":{"EOSUSDT":{"t":1633806856201,"s":1876026,"a":[["4.98247","0"],["4.98248","0"],["4.98255","26.49"],["4.98290","100.26"],["4.98387","0"],["4.98598","100.26"]],"b":[["4.98157","760.00"],["4.98139","31.66"],["4.98130","551.10"],["4.98129","330.67"],["4.98116","0"],["4.97892","0"],["4.97878","80.34"]]}}}
1633806856.307473: {"ch":"orderbook/full","update":{"DOGEUSDT":{"t":1633806856191,"s":1308099,"a":[["0.25013937","0"],["0.25014562","424550"],["0.25022127","0"],["0.25022776","409220"],["0.25088310","0"],["0.25089143","442420"],["0.25257467","0"],["0.25258226","423620"],["0.25276580","0"],["0.25277196","453760"],["0.25302853","0"],["0.25303619","473840"],["0.25323063","0"],["0.25323764","457270"],["0.25358561","0"],["0.25359411","426270"],["0.25460026","0"],["0.25460740","388830"],["0.25472971","0"],["0.25473232","370970"],["0.25482593","0"],["0.25483319","443810"],["0.25510773","0"],["0.25511763","344150"]],"b":[]}}}
1633806856.39028: {"ch":"orderbook/full","update":{"DCRETH":{"t":1633806856308,"s":499129,"a":[["0.036723","0.224"]],"b":[]}}}
1633806856.392713: {"ch":"orderbook/full","update":{"NEOBTC":{"t":1633806856250,"s":1498344,"a":[["0.0009450","793.22"],["0.0009571","0"],["0.0027536","1063.16"],["0.0028169","0"]],"b":[["0.0008741","0"],["0.0008731","166.00"]]}}}
1633806856.392864: {"ch":"orderbook/full","update":{"EOSUSDT":{"t":1633806856268,"s":1876027,"a":[["4.98255","0"],["4.98262","26.49"]],"b":[["4.98146","31.66"],["4.98139","0"]]}}}
1633806856.481461: {"ch":"orderbook/full","update":{"DCRETH":{"t":1633806856418,"s":499130,"a":[],"b":[["0.035979","11.376"]]}}}
1633806856.483406: {"ch":"orderbook/full","update":{"XVSUSDT":{"t":1633806856387,"s":483983,"a":[],"b":[["27.9705","113.816"],["27.9656","0"]]}}}
1633806856.4908988: {"ch":"orderbook/full","update":{"EOSUSDT":{"t":1633806856397,"s":1876028,"a":[["5.04223","0"],["5.04589","0"]],"b":[["4.98157","0"],["4.98146","0"],["4.98141","31.66"],["4.97889","80.33"],["4.97878","0"],["4.92486","0"],["4.92387","0"],["4.92227","0"]]}}}
1633806856.582788: {"ch":"orderbook/full","update":{"DCRETH":{"t":1633806856466,"s":499131,"a":[],"b":[["0.035980","0.162"]]}}}
1633806856.582835: {"ch":"orderbook/full","update":{"XVSUSDT":{"t":1633806856458,"s":483984,"a":[],"b":[["27.9535","109.088"],["27.9488","0"]]}}}
1633806856.5832782: {"ch":"orderbook/full","update":{"NEOBTC":{"t":1633806856448,"s":1498345,"a":[["0.0008832","0"],["0.0008835","72.00"],["0.0008836","24.00"]],"b":[["0.0008741","72.00"],["0.0008731","94.00"]]}}}
1633806856.602157: {"ch":"orderbook/full","update":{"EOSUSDT":{"t":1633806856519,"s":1876029,"a":[["4.98290","0"],["4.98387","100.26"],["5.06619","0"],["5.07930","8821.94"],["5.12961","0"],["5.14121","24335.25"]],"b":[["4.98152","760.00"],["4.98148","31.66"],["4.98141","0"],["4.97889","0"],["4.97883","80.34"]]}}}
1633806856.6827798: {"ch":"orderbook/full","update":{"DCRETH":{"t":1633806856564,"s":499132,"a":[],"b":[["0.035981","7.196"],["0.035979","0"]]}}}
1633806856.694747: {"ch":"orderbook/full","update":{"HTBTC":{"t":1633806856542,"s":660756,"a":[["0.00029731","17212.22"],["0.00029771","0"]],"b":[]}}}
1633806856.69696: {"ch":"orderbook/full","update":{"EOSUSDT":{"t":1633806856608,"s":1876030,"a":[["4.98290","100.26"],["4.98387","0"]],"b":[]}}}
1633806856.697092: {"ch":"orderbook/full","update":{"USDTUSDP":{"t":1633806856556,"s":384580,"a":[["1.100000","5.98"]],"b":[["0.900000","15.36"]]}}}
1633806856.7799869: {"ch":"orderbook/full","update":{"DCRETH":{"t":1633806856685,"s":499133,"a":[["0.036724","0"],["0.036771","16.000"]],"b":[["0.035982","0.195"],["0.035980","0"]]}}}
1633806856.790951: {"ch":"orderbook/full","update":{"NEOBTC":{"t":1633806856641,"s":1498346,"a":[["0.0008835","24.00"],["0.0008836","72.00"]],"b":[["0.0008741","0"],["0.0008731","166.00"]]}}}
1633806856.796269: {"ch":"orderbook/full","update":{"EOSUSDT":{"t":1633806856692,"s":1876031,"a":[["4.98290","0"],["4.98387","100.26"]],"b":[["4.97653","1811.59"],["4.97525","0"]]}}}
1633806856.805731: {"ch":"orderbook/full","update":{"DOGEUSDT":{"t":1633806856721,"s":1308100,"a":[["0.24986150","182460"],["0.24986304","0"],["0.24991604","343310"],["0.24992556","0"],["0.24999450","476010"],["0.25001126","0"],["0.25031196","459820"],["0.25031651","0"]],"b":[]}}}
1633806856.88979: {"ch":"orderbook/full","update":{"DCRETH":{"t":1633806856833,"s":499134,"a":[["0.038287","0"],["0.038467","287.394"],["0.039322","0"],["0.039517","302.234"],["0.040045","0"],["0.040235","299.425"],["0.040552","0"],["0.040729","282.555"],["0.040986","0"],["0.041146","316.090"],["0.041385","0"],["0.041517","330.080"],["0.041785","0"],["0.041898","330.415"],["0.042140","0"],["0.042241","335.803"]],"b":[["0.035983","4.250"],["0.035981","0"],["0.035703","17.000"],["0.035702","0"],["0.035701","0"],["0.035673","55.274"]]}}}
1633806856.890025: {"ch":"orderbook/full","update":{"NEOBTC":{"t":1633806856834,"s":1498347,"a":[],"b":[["0.0008769","0"],["0.0008763","43.00"]]}}}
1633806856.8956459: {"ch":"orderbook/full","update":{"EOSUSDT":{"t":1633806856763,"s":1876032,"a":[["5.04233","16381.41"],["5.04596","29154.10"]],"b":[["4.97330","2737.39"],["4.97010","0"],["4.92466","13206.04"],["4.92367","19348.42"],["4.92224","3831.85"]]}}}
1633806856.9018948: {"ch":"orderbook/full","update":{"DOGEUSDT":{"t":1633806856821,"s":1308101,"a":[["0.25100420","423890"],["0.25102802","0"],["0.25113379","361950"],["0.25114270","0"]],"b":[["0.24726712","0"],["0.24724941","22000"]]}}}
1633806856.9803112: {"ch":"orderbook/full","update":{"DCRETH":{"t":1633806856932,"s":499135,"a":[],"b":[["0.035983","4.941"],["0.035982","0"],["0.035972","2.268"],["0.035941","0"],["0.035703","0"],["0.035674","17.000"],["0.033669","242.650"],["0.033604","0"]]}}}
1633806856.9874141: {"ch":"orderbook/full","update":{"NEOBTC":{"t":1633806856917,"s":1498348,"a":[["0.0008832","24.00"],["0.0008835","0"]],"b":[["0.0008732","72.00"],["0.0008731","94.00"]]}}}
1633806856.9875531: {"ch":"orderbook/full","update":{"EOSUSDT":{"t":1633806856923,"s":1876033,"a":[["4.99122","685.96"],["4.99175","1831.91"],["4.99387","0"],["4.99429","700.00"],["4.99446","2463.07"],["4.99489","0"]],"b":[["4.98152","0"],["4.97887","80.33"],["4.97883","0"],["4.95900","4542.71"],["4.93854","0"]]}}}
1633806857.051371: {"ch":"ticker/1s","data":{"DCRETH":{"t":1633806856938,"a":"0.036723","A":"0.224","b":"0.035983","B":"4.941","o":"0.035004","c":"0.036373","h":"0.036686","l":"0.035072","v":"8.326","q":"0.297986431","p":"0.001369","P":"3.910981602102617","L":1417957304}}}
1633806857.051462: {"ch":"ticker/1s","data":{"XVSUSDT":{"t":1633806856540,"a":"28.0481","A":"0.063","b":"28.0188","B":"2.014","o":"28.7985","c":"27.9280","h":"28.5542","l":"27.6611","v":"7.058","q":"197.8450039","p":"-0.8705","P":"-3.022726878136014","L":1417859101}}}
1633806857.051501: {"ch":"ticker/1s","data":{"EOSUSDT":{"t":1633806856943,"a":"4.98262","A":"26.49","b":"4.98148","B":"31.66","o":"4.71891","c":"4.98523","h":"5.06033","l":"4.57171","v":"7224629.96","q":"34899840.7456554","p":"0.26632","P":"5.643676187933230","L":1417984568}}}
1633806857.088236: {"ch":"orderbook/full","update":{"ATOMBCH":{"t":1633806856975,"s":274278,"a":[["0.1702440","0.18"],["0.1702498","0"]],"b":[["0.0170249","0"],["0.0170243","0.19"]]}}}
1633806857.0883808: {"ch":"orderbook/full","update":{"NEOBTC":{"t":1633806856941,"s":1498349,"a":[],"b":[["0.0008745","0"],["0.0008741","24.00"]]}}}
1633806857.0884428: {"ch":"orderbook/full","update":{"HTBTC":{"t":1633806856954,"s":660757,"a":[["0.00025489","8802.07"],["0.00025517","0"]],"b":[]}}}
1633806857.090616: {"ch":"orderbook/full","update":{"EOSUSDT":{"t":1633806857026,"s":1876034,"a":[["4.98256","26.49"],["4.98262","0"],["5.03196","6023.83"],["5.04040","0"],["5.09391","13225.51"],["5.10555","0"],["5.12954","24335.25"],["5.14121","0"]],"b":[["4.98154","760.00"],["4.97887","0"],["4.97881","552.32"]]}}}
1633806857.184999: {"ch":"orderbook/full","update":{"DCRETH":{"t":1633806857102,"s":499136,"a":[],"b":[["0.033655","0"]]}}}
1633806857.189255: {"ch":"orderbook/full","update":{"NEOBTC":{"t":1633806857134,"s":1498350,"a":[],"b":[["0.0008745","24.00"],["0.0008741","0"]]}}}
1633806857.189384: {"ch":"orderbook/full","update":{"EOSUSDT":{"t":1633806857128,"s":1876035,"a":[],"b":[["4.93508","6751.44"],["4.89615","0"]]}}}
1633806857.198456: {"ch":"orderbook/full","update":{"USDTUSDP":{"t":1633806857060,"s":384581,"a":[["1.100000","5.51"]],"b":[["0.900000","14.89"]]}}}
1633806857.2831: {"ch":"orderbook/full","update":{"DCRETH":{"t":1633806857190,"s":499137,"a":[],"b":[["0.033670","2.296"]]}}}
1633806857.289335: {"ch":"orderbook/full","update":{"NEOBTC":{"t":1633806857188,"s":1498351,"a":[],"b":[["0.0008769","43.00"],["0.0008763","0"],["0.0008732","0"],["0.0008731","166.00"]]}}}
1633806857.300606: {"ch":"orderbook/full","update":{"EOSUSDT":{"t":1633806857223,"s":1876036,"a":[],"b":[["4.98153","31.66"],["4.98148","0"],["4.97071","2814.85"],["4.96605","0"],["4.94867","6107.92"],["4.92282","0"]]}}}
1633806857.391171: {"ch":"orderbook/full","update":{"NEOBTC":{"t":1633806857332,"s":1498352,"a":[],"b":[["0.0008732","72.00"],["0.0008731","94.00"]]}}}
1633806857.391295: {"ch":"orderbook/full","update":{"EOSUSDT":{"t":1633806857236,"s":1876037,"a":[["5.01601","0"],["5.01753","30.00"]],"b":[]}}}
1633806857.488489: {"ch":"orderbook/full","update":{"HTBTC":{"t":1633806857418,"s":660758,"a":[["0.00025489","0"],["0.00025557","8802.07"],["0.00026756","0"],["0.00026810","11985.76"],["0.00029731","0"],["0.00029787","17212.22"],["0.00034318","0"],["0.00034372","46776.23"]],"b":[]}}}
1633806857.4891121: {"ch":"orderbook/full","update":{"EOSUSDT":{"t":1633806857421,"s":1876038,"a":[["5.04233","0"],["5.04596","0"],["5.09391","0"],["5.10788","13225.51"],["5.12954","0"],["5.15298","24335.25"],["5.43942","0"],["5.45938","93429.49"]],"b":[["4.92466","0"],["4.92367","0"],["4.92224","0"],["4.92116","9113.33"],["4.90013","11826.73"],["4.87010","0"],["4.79601","0.01"]]}}}
1633806857.4963021: {"ch":"orderbook/full","update":{"DOGEUSDT":{"t":1633806857359,"s":1308102,"a":[["0.24986150","0"],["0.24986556","182450"],["0.24991604","0"],["0.24992281","343300"],["0.24999450","0"],["0.25000407","475990"],["0.25014562","0"],["0.25014888","424540"],["0.25089143","0"],["0.25089798","442410"],["0.25100420","0"],["0.25101854","423870"],["0.25118155","0"],["0.25118721","381380"],["0.25258226","0"],["0.25259027","423610"],["0.25277196","0"],["0.25277885","453750"],["0.25303619","0"],["0.25304477","473820"],["0.25323764","0"],["0.25324562","457260"],["0.25342088","0"],["0.25343007","336970"],["0.25359411","0"],["0.25360378","426250"],["0.25460740","0"],["0.25461568","388820"],["0.25483319","0"],["0.25484221","443800"],["0.25511763","0"],["0.25512844","344140"]],"b":[]}}}
1633806857.592754: {"ch":"orderbook/full","update":{"DCRETH":{"t":1633806857466,"s":499138,"a":[["0.036725","0"],["0.036754","8.903"],["0.036771","0"],["0.036772","0"],["0.036808","16.000"],["0.036809","27.022"],["0.036962","0"],["0.036963","0"],["0.037025","17.000"],["0.037026","59.324"]],"b":[]}}}
1633806857.614879: {"ch":"orderbook/full","update":{"NEOBTC":{"t":1633806857527,"s":1498353,"a":[["0.0008832","0"],["0.0008835","72.00"],["0.0008836","24.00"]],"b":[["0.0008741","72.00"],["0.0008732","0"]]}}}
1633806857.615026: {"ch":"orderbook/full","update":{"HTBTC":{"t":1633806857450,"s":660759,"a":[["0.00022787","6848.62"],["0.00023010","0"]],"b":[]}}}
1633806857.61509: {"ch":"orderbook/full","update":{"EOSUSDT":{"t":1633806857529,"s":1876039,"a":[["4.98290","100.26"],["4.98387","0"]],"b":[["4.98153","0"],["4.98147","31.66"]]}}}
1633806857.615159: {"ch":"orderbook/full","update":{"DOGEUSDT":{"t":1633806857484,"s":1308103,"a":[["0.25000407","0"],["0.25000557","475980"]],"b":[]}}}
1633806857.705564: {"ch":"orderbook/full","update":{"XVSUSDT":{"t":1633806857592,"s":483985,"a":[["28.0785","0"],["28.0846","20.388"]],"b":[]}}}
1633806857.7056918: {"ch":"orderbook/full","update":{"NEOBTC":{"t":1633806857544,"s":1498354,"a":[["0.0008823","233.23"],["0.0008827","40.61"],["0.0009165","0"],["0.0009179","923.52"],["0.0010627","0"],["0.0010650","5847.59"]],"b":[]}}}
1633806857.7057831: {"ch":"orderbook/full","update":{"EOSUSDT":{"t":1633806857597,"s":1876040,"a":[["4.98290","0"],["4.98387","100.26"]],"b":[]}}}
1633806857.705837: {"ch":"orderbook/full","update":{"USDTUSDP":{"t":1633806857564,"s":384582,"a":[["1.100000","5.93"]],"b":[["0.900000","15.31"]]}}}
1633806857.7916749: {"ch":"orderbook/full","update":{"NEOBTC":{"t":1633806857719,"s":1498355,"a":[["0.0008832","24.00"],["0.0008835","0"],["0.0008836","72.00"],["0.0008842","0"],["0.0008844","94.00"]],"b":[]}}}
1633806857.8200479: {"ch":"orderbook/full","update":{"EOSUSDT":{"t":1633806857726,"s":1876041,"a":[["5.43789","93429.49"],["5.45938","0"]],"b":[["4.98147","0"],["4.98131","31.66"],["4.97525","1635.38"],["4.97196","0"],["4.83349","17800.28"],["4.58340","0"]]}}}
1633806857.82022: {"ch":"orderbook/full","update":{"DOGEUSDT":{"t":1633806857703,"s":1308104,"a":[["0.25022776","0"],["0.25023224","409210"],["0.25031196","0"],["0.25031597","459810"],["0.25089798","0"],["0.25090248","442400"],["0.25101854","0"],["0.25102256","423860"],["0.25113379","0"],["0.25114118","361940"],["0.25259027","0"],["0.25259752","423590"],["0.25277885","0"],["0.25278489","453740"],["0.25304477","0"],["0.25305228","473810"],["0.25324562","0"],["0.25325250","457250"],["0.25360378","0"],["0.25361187","426240"],["0.25461568","0"],["0.25462273","388810"],["0.25473232","0"],["0.25473775","370960"],["0.25484221","0"],["0.25485076","443780"],["0.25512844","0"],["0.25513669","344120"]],"b":[]}}}
1633806857.89043: {"ch":"orderbook/full","update":{"EOSUSDT":{"t":1633806857829,"s":1876042,"a":[["5.04223","16381.41"],["5.04595","29154.10"],["5.07568","0"]],"b":[["4.98131","0"],["4.98120","31.66"],["4.97797","0"],["4.97631","109.20"],["4.92486","13206.04"],["4.92387","19348.42"],["4.92237","3831.85"],["4.48977","0"],["4.42907","0"],["4.36837","0"],["4.30767","0"],["4.24697","0"]]}}}
1633806858.00928: {"ch":"orderbook/full","update":{"NEOBTC":{"t":1633806857913,"s":1498356,"a":[["0.0008832","0"],["0.0008835","72.00"],["0.0008836","24.00"],["0.0008842","94.00"],["0.0008844","0"],["0.0009450","0"],["0.0009473","793.22"],["0.0027536","0"],["0.0027666","1063.16"]],"b":[["0.0008741","0"],["0.0008731","166.00"]]}}}
1633806858.009462: {"ch":"orderbook/full","update":{"EOSUSDT":{"t":1633806857865,"s":1876043,"a":[],"b":[["4.98129","362.33"],["4.98120","0"]]}}}
1633806858.053622: {"ch":"ticker/1s","data":{"EOSUSDT":{"t":1633806857942,"a":"4.98256","A":"26.49","b":"4.98154","B":"760.00","o":"4.71891","c":"4.98523","h":"5.06033","l":"4.57171","v":"7224629.96","q":"34899840.7456554","p":"0.26632","P":"5.643676187933230","L":1417984568}}}
1633806858.0892212: {"ch":"orderbook/full","update":{"ATOMBCH":{"t":1633806857977,"s":274279,"a":[["0.1702440","0.17"]],"b":[["0.0170243","0.12"]]}}}
1633806858.098437: {"ch":"orderbook/full","update":{"EOSUSDT":{"t":1633806858021,"s":1876044,"a":[["5.03755","0"],["5.12507","0"],["5.21259","0"],["5.30011","0"],["5.38764","0"]],"b":[["4.14366","0"],["4.09808","0"],["4.05250","0"],["4.00692","0"],["3.96134","0"],["3.91576","0"],["3.87018","0"],["3.82460","0"],["3.77902","0"],["3.73344","0"]]}}}
1633806858.2042649: {"ch":"orderbook/full","update":{"NEOBTC":{"t":1633806858107,"s":1498357,"a":[["0.0008835","24.00"],["0.0008836","72.00"]],"b":[["0.0008741","72.00"],["0.0008731","94.00"]]}}}
1633806858.204415: {"ch":"orderbook/full","update":{"EOSUSDT":{"t":1633806858133,"s":1876045,"a":[["5.43789","0"],["5.45902","93429.49"]],"b":[["4.98143","31.66"],["4.98129","330.67"],["4.95694","4676.44"],["4.94106","0"]]}}}
1633806858.2045062: {"ch":"orderbook/full","update":{"USDTUSDP":{"t":1633806858068,"s":384583,"a":[["1.100000","6.38"]],"b":[["0.900000","15.76"]]}}}
1633806858.2045581: {"ch":"orderbook/full","update":{"DOGEUSDT":{"t":1633806858069,"s":1308105,"a":[["0.25023224","0"],["0.25023905","409200"],["0.25090248","0"],["0.25090755","442390"],["0.25102256","0"],["0.25102700","423850"],["0.25118721","0"],["0.25119363","381370"],["0.25259752","0"],["0.25260572","423580"],["0.25278489","0"],["0.25279182","453730"],["0.25305228","0"],["0.25306091","473790"],["0.25325250","0"],["0.25326040","457230"],["0.25343007","0"],["0.25343965","336960"],["0.25361187","0"],["0.25362181","426220"],["0.25462273","0"],["0.25463038","388790"],["0.25485076","0"],["0.25486062","443770"],["0.25513669","0"],["0.25514691","344110"]],"b":[]}}}
1633806858.2894049: {"ch":"orderbook/full","update":{"BORUSDT":{"t":1633806858153,"s":56255,"a":[["100000.000","0.0010"]],"b":[["0.001","1026.5996"]]}}}
1633806858.293223: {"ch":"orderbook/full","update":{"EOSUSDT":{"t":1633806858184,"s":1876046,"a":[],"b":[["4.98148","31.66"],["4.98143","0"]]}}}
1633806858.397246: {"ch":"orderbook/full","update":{"NEOBTC":{"t":1633806858303,"s":1498358,"a":[["0.0008835","72.00"],["0.0008836","24.00"]],"b":[["0.0008741","0"],["0.0008731","166.00"]]}}}
1633806858.397393: {"ch":"orderbook/full","update":{"EOSUSDT":{"t":1633806858258,"s":1876047,"a":[["5.01845","5507.50"],["5.02732","0"]],"b":[]}}}
1633806858.49129: {"ch":"orderbook/full","update":{"EOSUSDT":{"t":1633806858432,"s":1876048,"a":[["5.04223","0"],["5.04595","0"]],"b":[["4.92486","0"],["4.92387","0"],["4.92237","0"]]}}}
1633806858.498977: {"ch":"orderbook/full","update":{"DOGEUSDT":{"t":1633806858394,"s":1308106,"a":[["0.25000557","0"],["0.25001132","475970"]],"b":[]}}}
1633806858.588991: {"ch":"orderbook/full","update":{"NEOBTC":{"t":1633806858497,"s":1498359,"a":[["0.0008832","24.00"],["0.0008835","0"],["0.0008836","72.00"]],"b":[["0.0008745","0"],["0.0008741","24.00"],["0.0008732","72.00"],["0.0008731","94.00"]]}}}
1633806858.591102: {"ch":"orderbook/full","update":{"EOSUSDT":{"t":1633806858523,"s":1876049,"a":[],"b":[["4.98148","0"],["4.98141","31.66"]]}}}
1633806858.591192: {"ch":"orderbook/full","update":{"DOGEUSDT":{"t":1633806858496,"s":1308107,"a":[["0.25014888","0"],["0.25015335","424530"],["0.25031597","0"],["0.25034619","459760"],["0.25090755","0"],["0.25097239","442270"],["0.25102700","0"],["0.25108403","423760"],["0.25109077","0"],["0.25111689","442020"],["0.25114118","0"],["0.25115690","361920"],["0.25119363","0"],["0.25124765","381290"],["0.25260572","0"],["0.25268793","423440"],["0.25279182","0"],["0.25288617","453560"],["0.25306091","0"],["0.25313205","473660"],["0.25326040","0"],["0.25335248","457070"],["0.25343965","0"],["0.25350012","336880"],["0.25362181","0"],["0.25375526","426000"],["0.25463038","0"],["0.25468698","388710"],["0.25473775","0"],["0.25476443","370930"],["0.25486062","0"],["0.25498268","443550"],["0.25514691","0"],["0.25526655","343950"]],"b":[]}}}
1633806858.689311: {"ch":"orderbook/full","update":{"EOSUSDT":{"t":1633806858626,"s":1876050,"a":[["4.98290","100.26"],["4.98387","0"]],"b":[]}}}
1633806858.693944: {"ch":"orderbook/full","update":{"USDTUSDP":{"t":1633806858572,"s":384584,"a":[["1.100000","5.55"]],"b":[["0.900000","14.93"]]}}}
1633806858.7894132: {"ch":"orderbook/full","update":{"NEOBTC":{"t":1633806858730,"s":1498360,"a":[["0.0008832","0"],["0.0008836","24.00"],["0.0008839","72.00"],["0.0008842","0"],["0.0008844","94.00"],["0.0009455","793.22"],["0.0009473","0"]],"b":[["0.0008745","24.00"],["0.0008741","0"],["0.0008732","0"],["0.0008731","72.00"],["0.0008721","94.00"]]}}}
1633806858.7954419: {"ch":"orderbook/full","update":{"EOSUSDT":{"t":1633806858731,"s":1876051,"a":[["4.98790","103.69"],["4.99207","0"],["4.99281","0"],["4.99383","240.00"],["4.99429","0"],["4.99530","700.00"],["4.99720","0"],["4.99813","960.00"]],"b":[["4.98141","0"],["4.98133","31.66"],["4.97305","0"],["4.97236","240.00"],["4.97172","0"],["4.97060","700.00"],["4.96916","0"],["4.96756","960.00"],["4.96331","0"],["4.96153","1900.00"],["4.90013","0"],["4.88700","11826.73"],["4.83349","0"],["4.79965","17800.28"]]}}}
1633806858.81233: {"ch":"orderbook/full","update":{"DOGEUSDT":{"t":1633806858730,"s":1308108,"a":[],"b":[["0.24765049","46400"],["0.24762224","0"]]}}}
1633806858.89732: {"ch":"orderbook/full","update":{"NEOBTC":{"t":1633806858760,"s":1498361,"a":[["0.0008823","273.84"],["0.0008827","0"]],"b":[]}}}
1633806858.897452: {"ch":"orderbook/full","update":{"EOSUSDT":{"t":1633806858813,"s":1876052,"a":[["5.43571","93429.49"],["5.45902","0"]],"b":[["4.98154","0"],["4.98146","760.00"],["4.98133","0"],["4.98126","31.66"],["4.97899","80.33"],["4.97881","471.98"]]}}}
1633806859.000225: {"ch":"orderbook/full","update":{"NEOBTC":{"t":1633806858910,"s":1498362,"a":[["0.0008835","24.00"],["0.0008836","0"],["0.0008844","0"],["0.0008848","94.00"]],"b":[["0.0008745","0"],["0.0008741","24.00"],["0.0008732","72.00"],["0.0008731","0"]]}}}
1633806859.0003982: {"ch":"orderbook/full","update":{"EOSUSDT":{"t":1633806858893,"s":1876053,"a":[["4.98290","0"],["4.98387","100.26"],["5.04223","16381.41"],["5.04595","29154.10"]],"b":[["4.98126","0"],["4.98123","31.66"],["4.92486","13206.04"],["4.92387","19348.42"],["4.92256","3831.85"]]}}}
1633806859.0069199: {"ch":"orderbook/full","update":{"DOGEUSDT":{"t":1633806858917,"s":1308109,"a":[],"b":[["0.24765049","0"],["0.24762224","46400"]]}}}
1633806859.052653: {"ch":"ticker/1s","data":{"EOSUSDT":{"t":1633806858944,"a":"4.98256","A":"26.49","b":"4.98146","B":"760.00","o":"4.71891","c":"4.98523","h":"5.06033","l":"4.57171","v":"7224629.96","q":"34899840.7456554","p":"0.26632","P":"5.643676187933230","L":1417984568}}}
1633806859.089241: {"ch":"orderbook/full","update":{"ATOMBCH":{"t":1633806858977,"s":274280,"a":[["0.1702289","0.10"],["0.1702440","0"]],"b":[["0.0170243","0"],["0.0170228","0.19"]]}}}
1633806859.089385: {"ch":"orderbook/full","update":{"HTBTC":{"t":1633806859018,"s":660760,"a":[["0.00014713","0"],["0.00014736","4561.05"],["0.00022787","0"],["0.00022907","6848.62"]],"b":[]}}}
1633806859.0946681: {"ch":"orderbook/full","update":{"EOSUSDT":{"t":1633806859029,"s":1876054,"a":[["4.99277","2448.24"],["4.99484","0"]],"b":[["4.95758","2447.99"],["4.95292","0"]]}}}
1633806859.195509: {"ch":"orderbook/full","update":{"NEOBTC":{"t":1633806859104,"s":1498363,"a":[["0.0008835","0"],["0.0008836","24.00"],["0.0008844","94.00"],["0.0008848","0"]],"b":[["0.0008732","0"],["0.0008731","72.00"]]}}}
1633806859.195662: {"ch":"orderbook/full","update":{"EOSUSDT":{"t":1633806859054,"s":1876055,"a":[],"b":[["4.98131","31.66"],["4.98123","0"]]}}}
1633806859.197949: {"ch":"orderbook/full","update":{"USDTUSDP":{"t":1633806859076,"s":384585,"a":[["1.100000","6.18"]],"b":[["0.900000","15.56"]]}}}
1633806859.2915452: {"ch":"orderbook/full","update":{"NEOBTC":{"t":1633806859222,"s":1498364,"a":[["0.0009455","0"],["0.0009558","793.22"],["0.0027666","0"],["0.0028103","1063.16"]],"b":[["0.0008745","24.00"],["0.0008741","0"]]}}}
1633806859.29534: {"ch":"orderbook/full","update":{"EOSUSDT":{"t":1633806859154,"s":1876056,"a":[],"b":[["4.98136","63.33"],["4.98131","0"]]}}}
1633806859.393017: {"ch":"orderbook/full","update":{"HTBTC":{"t":1633806859333,"s":660761,"a":[],"b":[["0.00014092","1442.46"],["0.00014075","0"]]}}}
1633806859.393143: {"ch":"orderbook/full","update":{"EOSUSDT":{"t":1633806859288,"s":1876057,"a":[],"b":[["4.98141","31.66"],["4.98136","31.67"]]}}}
1633806859.493303: {"ch":"orderbook/full","update":{"NEOBTC":{"t":1633806859354,"s":1498365,"a":[],"b":[["0.0008745","0"],["0.0008741","24.00"]]}}}
1633806859.493431: {"ch":"orderbook/full","update":{"HTBTC":{"t":1633806859424,"s":660762,"a":[["0.00014716","4561.05"],["0.00014736","0"]],"b":[]}}}
1633806859.4934962: {"ch":"orderbook/full","update":{"EOSUSDT":{"t":1633806859419,"s":1876058,"a":[],"b":[["4.98157","31.66"],["4.98141","0"],["4.97899","0"],["4.97883","80.34"]]}}}
1633806859.493561: {"ch":"orderbook/full","update":{"DOGEUSDT":{"t":1633806859388,"s":1308110,"a":[["0.25023618","409210"],["0.25023905","0"]],"b":[]}}}
1633806859.58194: {"ch":"orderbook/full","update":{"DCRETH":{"t":1633806859463,"s":499139,"a":[["0.036723","0"],["0.036753","0.397"]],"b":[]}}}
1633806859.6011431: {"ch":"orderbook/full","update":{"XVSUSDT":{"t":1633806859481,"s":483986,"a":[],"b":[["27.7354","318.487"],["27.7054","0"]]}}}
1633806859.601274: {"ch":"orderbook/full","update":{"NEOBTC":{"t":1633806859498,"s":1498366,"a":[],"b":[["0.0008769","0"],["0.0008763","43.00"]]}}}
1633806859.6013398: {"ch":"orderbook/full","update":{"EOSUSDT":{"t":1633806859474,"s":1876059,"a":[["5.04223","0"],["5.04595","0"]],"b":[["4.92486","0"],["4.92387","0"],["4.92256","0"]]}}}
1633806859.601413: {"ch":"orderbook/full","update":{"DOGEUSDT":{"t":1633806859519,"s":1308111,"a":[],"b":[["0.24728301","22000"],["0.24724941","0"]]}}}
1633806859.6810791: {"ch":"orderbook/full","update":{"DCRETH":{"t":1633806859616,"s":499140,"a":[["0.036752","0.448"],["0.036753","0"]],"b":[]}}}
1633806859.689964: {"ch":"orderbook/full","update":{"EOSUSDT":{"t":1633806859556,"s":1876060,"a":[],"b":[["4.96259","2692.59"],["4.95822","0"]]}}}
1633806859.694589: {"ch":"orderbook/full","update":{"USDTUSDP":{"t":1633806859579,"s":384586,"a":[["1.100000","6.21"]],"b":[["0.900000","15.59"]]}}}
1633806859.800503: {"ch":"orderbook/full","update":{"EOSUSDT":{"t":1633806859666,"s":1876061,"a":[],"b":[["3.64761","0"]]}}}
1633806859.812831: {"ch":"orderbook/full","update":{"DOGEUSDT":{"t":1633806859697,"s":1308112,"a":[["0.25001015","475980"],["0.25001132","0"]],"b":[]}}}
1633806859.899261: {"ch":"orderbook/full","update":{"NEOBTC":{"t":1633806859810,"s":1498367,"a":[],"b":[["0.0008769","43.00"],["0.0008763","0"]]}}}
1633806859.899387: {"ch":"orderbook/full","update":{"EOSUSDT":{"t":1633806859817,"s":1876062,"a":[],"b":[["4.98157","0"],["4.98143","31.66"],["4.97887","80.33"],["4.97883","0"]]}}}
1633806859.8994591: {"ch":"orderbook/full","update":{"DOGEUSDT":{"t":1633806859789,"s":1308113,"a":[["0.25032125","459800"],["0.25034619","0"],["0.25090539","442390"],["0.25097239","0"],["0.25102290","423860"],["0.25108403","0"],["0.25108984","442070"],["0.25111689","0"],["0.25114119","361940"],["0.25115690","0"],["0.25117905","381400"],["0.25124765","0"],["0.25256748","423640"],["0.25268793","0"],["0.25276009","453780"],["0.25288617","0"],["0.25302125","473870"],["0.25313205","0"],["0.25322427","457300"],["0.25335248","0"],["0.25341702","336990"],["0.25350012","0"],["0.25357807","426290"],["0.25375526","0"],["0.25459389","388850"],["0.25468698","0"],["0.25472718","370980"],["0.25476443","0"],["0.25481947","443840"],["0.25498268","0"],["0.25509990","344170"],["0.25526655","0"]],"b":[]}}}
1633806859.9790342: {"ch":"orderbook/full","update":{"DCRETH":{"t":1633806859917,"s":499141,"a":[],"b":[["0.006447","0"]]}}}
1633806859.984438: {"ch":"orderbook/full","update":{"NEOBTC":{"t":1633806859866,"s":1498368,"a":[["0.0009558","0"],["0.0009725","793.22"],["0.0028103","0"],["0.0028957","1063.16"]],"b":[]}}}
1633806859.986198: {"ch":"orderbook/full","update":{"EOSUSDT":{"t":1633806859891,"s":1876063,"a":[["5.04124","12807.83"],["5.04223","16381.41"],["5.04422","29154.10"],["5.06114","0"]],"b":[["4.98143","0"],["4.98138","31.66"],["4.92486","13206.04"],["4.92387","19348.42"],["4.92268","3831.85"],["4.23428","0"]]}}}
1633806860.050196: {"ch":"ticker/1s","data":{"DCRETH":{"t":1633806859938,"a":"0.036752","A":"0.448","b":"0.035983","B":"4.941","o":"0.035004","c":"0.036373","h":"0.036686","l":"0.035072","v":"8.326","q":"0.297986431","p":"0.001369","P":"3.910981602102617","L":1417957304}}}
1633806860.0502882: {"ch":"ticker/1s","data":{"EOSUSDT":{"t":1633806859942,"a":"4.98256","A":"26.49","b":"4.98146","B":"760.00","o":"4.71891","c":"4.98523","h":"5.06033","l":"4.57171","v":"7224629.96","q":"34899840.7456554","p":"0.26632","P":"5.643676187933230","L":1417984568}}}
1633806860.095007: {"ch":"orderbook/full","update":{"DCRETH":{"t":1633806859982,"s":499142,"a":[],"b":[["0.006449","1.200"]]}}}
1633806860.131424: {"ch":"orderbook/full","update":{"ATOMBCH":{"t":1633806859993,"s":274281,"a":[["0.1702289","0"],["0.1702431","0.19"]],"b":[["0.0170243","0.10"],["0.0170228","0"]]}}}
1633806860.131566: {"ch":"orderbook/full","update":{"XVSUSDT":{"t":1633806859958,"s":483987,"a":[["28.0915","98.436"],["28.0965","0"]],"b":[]}}}
1633806860.1316302: {"ch":"orderbook/full","update":{"NEOBTC":{"t":1633806859949,"s":1498369,"a":[],"b":[["0.0008745","24.00"],["0.0008741","0"]]}}}
1633806860.131685: {"ch":"orderbook/full","update":{"HTBTC":{"t":1633806860026,"s":660763,"a":[["0.00014716","0"],["0.00014744","4561.05"],["0.00022907","0"],["0.00022983","6848.62"]],"b":[]}}}
1633806860.131745: {"ch":"orderbook/full","update":{"EOSUSDT":{"t":1633806859995,"s":1876064,"a":[],"b":[["4.98138","0"],["4.98133","31.66"],["4.10322","0"]]}}}
1633806860.266036: {"ch":"orderbook/full","update":{"NEOBTC":{"t":1633806860081,"s":1498370,"a":[["0.0008844","0"],["0.0008848","94.00"]],"b":[]}}}
1633806860.266159: {"ch":"orderbook/full","update":{"EOSUSDT":{"t":1633806860087,"s":1876065,"a":[],"b":[["3.84462","0"]]}}}
1633806860.2662148: {"ch":"orderbook/full","update":{"USDTUSDP":{"t":1633806860083,"s":384587,"a":[["1.100000","5.51"]],"b":[["0.900000","14.89"]]}}}
1633806860.2992032: {"ch":"orderbook/full","update":{"DCRETH":{"t":1633806860194,"s":499143,"a":[],"b":[["0.035984","4.392"],["0.035978","0"]]}}}
1633806860.299326: {"ch":"orderbook/full","update":{"NEOBTC":{"t":1633806860142,"s":1498371,"a":[],"b":[["0.0008745","0"],["0.0008741","24.00"]]}}}
1633806860.299389: {"ch":"orderbook/full","update":{"EOSUSDT":{"t":1633806860215,"s":1876066,"a":[],"b":[["4.98140","31.66"],["4.98133","0"],["4.35091","0"]]}}}
1633806860.379776: {"ch":"orderbook/full","update":{"DCRETH":{"t":1633806860320,"s":499144,"a":[],"b":[["0.035985","4.941"],["0.035983","0"]]}}}
1633806860.385291: {"ch":"orderbook/full","update":{"NEOBTC":{"t":1633806860321,"s":1498372,"a":[["0.0008844","94.00"],["0.0008848","0"]],"b":[]}}}
1633806860.498451: {"ch":"orderbook/full","update":{"HTBTC":{"t":1633806860401,"s":660764,"a":[["0.00014184","64.89"],["0.00014188","0"],["0.00022983","0"],["0.00023017","6848.62"]],"b":[]}}}
1633806860.498593: {"ch":"orderbook/full","update":{"EOSUSDT":{"t":1633806860423,"s":1876067,"a":[],"b":[["4.98140","0"],["4.98135","31.66"],["4.26784","0"]]}}}
1633806860.5882208: {"ch":"orderbook/full","update":{"NEOBTC":{"t":1633806860512,"s":1498373,"a":[],"b":[["0.0008745","24.00"],["0.0008741","0"]]}}}
1633806860.598371: {"ch":"orderbook/full","update":{"EOSUSDT":{"t":1633806860502,"s":1876068,"a":[["5.04223","0"],["5.04422","0"]],"b":[["4.92486","0"],["4.92387","0"],["4.92268","0"]]}}}
1633806860.700044: {"ch":"orderbook/full","update":{"EOSUSDT":{"t":1633806860622,"s":1876069,"a":[["5.43571","0"],["5.45691","93429.49"]],"b":[["4.10321","0"]]}}}
1633806860.700177: {"ch":"orderbook/full","update":{"USDTUSDP":{"t":1633806860587,"s":384588,"a":[["1.100000","6.38"]],"b":[["0.900000","15.76"]]}}}
1633806860.8017988: {"ch":"orderbook/full","update":{"EOSUSDT":{"t":1633806860724,"s":1876070,"a":[["5.06876","8821.94"],["5.07930","0"]],"b":[["4.40262","0"]]}}}
1633806860.880349: {"ch":"orderbook/full","update":{"DCRETH":{"t":1633806860749,"s":499145,"a":[],"b":[["0.006450","2.936"],["0.006448","0"]]}}}
1633806860.89553: {"ch":"orderbook/full","update":{"EOSUSDT":{"t":1633806860835,"s":1876071,"a":[["5.04124","0"],["5.05650","12807.83"],["5.43434","93429.49"],["5.45691","0"]],"b":[["4.98143","31.66"],["4.98135","0"],["4.97881","0"],["4.97797","471.98"]]}}}
1633806860.8956952: {"ch":"orderbook/full","update":{"DOGEUSDT":{"t":1633806860772,"s":1308114,"a":[["0.24878813","0"],["0.24879951","62210"],["0.24986556","0"],["0.24987728","182440"],["0.24992281","0"],["0.24993496","343280"],["0.25001015","0"],["0.25002414","475950"],["0.25015335","0"],["0.25016358","424520"],["0.25023618","0"],["0.25024902","409190"],["0.25090539","0"],["0.25092033","442370"],["0.25102290","0"],["0.25103476","423840"],["0.25108984","0"],["0.25109370","442060"],["0.25117905","0"],["0.25118795","381380"],["0.25256748","0"],["0.25259156","423600"],["0.25276009","0"],["0.25277990","453750"],["0.25302125","0"],["0.25304600","473820"],["0.25322427","0"],["0.25324677","457260"],["0.25341702","0"],["0.25343091","336970"],["0.25357807","0"],["0.25360506","426250"],["0.25459389","0"],["0.25461690","388810"],["0.25472718","0"],["0.25473602","370970"],["0.25481947","0"],["0.25484362","443800"],["0.25509990","0"],["0.25512977","344130"]],"b":[]}}}
1633806860.987177: {"ch":"orderbook/full","update":{"XVSUSDT":{"t":1633806860888,"s":483988,"a":[["28.0598","0"],["28.0731","60.540"],["28.0742","0"],["28.0849","107.095"],["28.0915","0"],["28.1094","98.436"],["28.1262","0"],["28.1452","105.569"],["28.1608","0"],["28.1789","207.692"],["28.2859","0"],["28.3153","262.137"],["28.5122","0"],["28.5469","411.194"],["28.6075","0"],["28.6323","475.637"],["28.7963","0"],["28.8403","541.210"]],"b":[]}}}
1633806861.013414: {"ch":"orderbook/full","update":{"EOSUSDT":{"t":1633806860924,"s":1876072,"a":[["4.99122","0"],["4.99170","685.96"],["4.99222","0"],["4.99322","1019.31"],["4.99338","0"],["4.99383","0"],["4.99449","1348.10"],["4.99484","240.00"],["5.04223","16381.41"],["5.04570","29154.10"],["5.14699","88370.30"],["5.16099","0"]],"b":[["4.98143","0"],["4.98130","582.76"],["4.92486","13206.04"],["4.92387","19348.42"],["4.92268","3831.85"]]}}}
1633806861.0135622: {"ch":"orderbook/full","update":{"DOGEUSDT":{"t":1633806860859,"s":1308115,"a":[["0.24987728","0"],["0.24989127","182430"],["0.24993496","0"],["0.24994637","343270"],["0.25002414","0"],["0.25004227","475910"],["0.25016358","0"],["0.25017635","424500"],["0.25024902","0"],["0.25026923","409150"],["0.25032125","0"],["0.25032929","459790"],["0.25092033","0"],["0.25094441","442320"],["0.25103476","0"],["0.25105464","423810"],["0.25109370","0"],["0.25110236","442050"],["0.25114119","0"],["0.25114979","361930"],["0.25118795","0"],["0.25120535","381360"],["0.25259156","0"],["0.25263105","423540"],["0.25277990","0"],["0.25281423","453690"],["0.25304600","0"],["0.25308590","473750"],["0.25324677","0"],["0.25328581","457190"],["0.25343091","0"],["0.25345505","336940"],["0.25360506","0"],["0.25365644","426160"],["0.25461690","0"],["0.25464960","388760"],["0.25473602","0"],["0.25474882","370950"],["0.25484362","0"],["0.25489077","443710"],["0.25512977","0"],["0.25518263","344060"]],"b":[["0.24642211","0"],["0.24637990","49860"]]}}}
1633806861.0507572: {"ch":"ticker/1s","data":{"DCRETH":{"t":1633806860838,"a":"0.036752","A":"0.448","b":"0.035985","B":"4.941","o":"0.035004","c":"0.036373","h":"0.036686","l":"0.035072","v":"8.326","q":"0.297986431","p":"0.001369","P":"3.910981602102617","L":1417957304}}}
1633806861.0949252: {"ch":"orderbook/full","update":{"ATOMBCH":{"t":1633806860994,"s":274282,"a":[["0.1702431","0.14"]],"b":[["0.0170243","0.18"]]}}}
1633806861.0950558: {"ch":"orderbook/full","update":{"EOSUSDT":{"t":1633806861030,"s":1876073,"a":[["4.98256","0"],["4.98270","26.49"]],"b":[["4.98145","31.66"],["4.98130","551.10"]]}}}
1633806861.103862: {"ch":"orderbook/full","update":{"DOGEUSDT":{"t":1633806861023,"s":1308116,"a":[["0.24839821","90410"],["0.24849080","0"],["0.24857438","113330"],["0.24867839","0"],["0.24872722","142410"],["0.24887815","0"]],"b":[]}}}
1633806861.207598: {"ch":"orderbook/full","update":{"USDTUSDP":{"t":1633806861091,"s":384589,"a":[["1.100000","6.40"]],"b":[["0.900000","15.78"]]}}}
1633806861.28929: {"ch":"orderbook/full","update":{"XVSUSDT":{"t":1633806861188,"s":483989,"a":[["35.7160","0"],["35.8142","196.695"]],"b":[["27.8843","168.599"],["27.8775","0"],["27.8095","199.881"],["27.8009","0"]]}}}
1633806861.289442: {"ch":"orderbook/full","update":{"NEOBTC":{"t":1633806861199,"s":1498374,"a":[],"b":[["0.0007282","557.30"],["0.0006844","1157.34"]]}}}
1633806861.2995698: {"ch":"orderbook/full","update":{"EOSUSDT":{"t":1633806861205,"s":1876074,"a":[["4.98261","26.49"],["4.98270","0"],["4.99122","685.96"],["4.99170","0"],["4.99222","1019.31"],["4.99322","0"]],"b":[]}}}
1633806861.2997272: {"ch":"orderbook/full","update":{"DOGEUSDT":{"t":1633806861185,"s":1308117,"a":[["0.24994637","0"],["0.24995402","343260"],["0.25004227","0"],["0.25005137","475900"],["0.25017635","0"],["0.25018262","424480"],["0.25026923","0"],["0.25027646","409140"],["0.25105464","0"],["0.25105961","423800"],["0.25110236","0"],["0.25110569","442040"],["0.25120535","0"],["0.25121420","381340"],["0.25263105","0"],["0.25264466","423510"],["0.25281423","0"],["0.25282984","453660"],["0.25308590","0"],["0.25309870","473720"],["0.25328581","0"],["0.25330116","457160"],["0.25345505","0"],["0.25346459","336930"],["0.25365644","0"],["0.25367841","426130"],["0.25464960","0"],["0.25466004","388750"],["0.25474882","0"],["0.25475351","370940"],["0.25489077","0"],["0.25490845","443680"],["0.25518263","0"],["0.25520657","344030"]],"b":[]}}}
1633806861.3845592: {"ch":"orderbook/full","update":{"XVSUSDT":{"t":1633806861294,"s":483990,"a":[["28.0846","0"],["28.0897","20.388"]],"b":[]}}}
1633806861.393831: {"ch":"orderbook/full","update":{"EOSUSDT":{"t":1633806861250,"s":1876075,"a":[["4.98261","0"],["4.98269","26.49"]],"b":[["4.97931","471.98"],["4.97797","0"]]}}}
1633806861.400141: {"ch":"orderbook/full","update":{"DOGEUSDT":{"t":1633806861290,"s":1308118,"a":[],"b":[["0.24765126","110310"],["0.24760193","0"]]}}}
1633806861.496345: {"ch":"orderbook/full","update":{"EOSUSDT":{"t":1633806861388,"s":1876076,"a":[["4.98262","26.49"],["4.98269","0"]],"b":[["4.98154","31.66"],["4.98145","0"],["4.97887","0"],["4.97881","80.34"]]}}}
1633806861.501424: {"ch":"orderbook/full","update":{"DOGEUSDT":{"t":1633806861420,"s":1308119,"a":[["0.24805962","34540"],["0.24808248","0"],["0.25110569","0"],["0.25111101","442030"]],"b":[]}}}
1633806861.6050282: {"ch":"orderbook/full","update":{"EOSUSDT":{"t":1633806861530,"s":1876077,"a":[["4.98262","0"],["4.98269","26.49"],["5.04223","0"],["5.04570","0"]],"b":[["4.92486","0"],["4.92387","0"],["4.92268","0"]]}}}
1633806861.695647: {"ch":"orderbook/full","update":{"EOSUSDT":{"t":1633806861586,"s":1876078,"a":[["4.98262","26.49"],["4.98269","0"]],"b":[]}}}
1633806861.695738: {"ch":"orderbook/full","update":{"USDTUSDP":{"t":1633806861595,"s":384590,"a":[["1.100000","5.62"]],"b":[["0.900000","15.00"]]}}}
1633806861.695779: {"ch":"orderbook/full","update":{"DOGEUSDT":{"t":1633806861621,"s":1308120,"a":[["0.25105961","0"],["0.25106265","423790"]],"b":[]}}}
1633806861.781499: {"ch":"trades","update":{"NEOBTC":[{"t":1633806861647,"i":1633806861647,"p":"0.0008786","q":"0.41","s":"buy"}]}}
1633806861.7815921: {"ch":"candles/M1","update":{"NEOBTC":[{"t":1633806840000,"o":"0.0008788","c":"0.0008786","h":"0.0008788","l":"0.0008786","v":"2.22","q":"0.001950722"}]}}
1633806861.7864718: {"ch":"orderbook/full","update":{"NEOBTC":{"t":1633806861712,"s":1498375,"a":[["0.0008844","0"],["0.0008848","94.00"]],"b":[]}}}
1633806861.79076: {"ch":"orderbook/full","update":{"EOSUSDT":{"t":1633806861679,"s":1876079,"a":[["4.98262","0"],["4.98269","26.49"]],"b":[]}}}
1633806861.796606: {"ch":"orderbook/full","update":{"DOGEUSDT":{"t":1633806861696,"s":1308121,"a":[],"b":[["0.24692662","45000"],["0.24689247","0"]]}}}
1633806861.897581: {"ch":"orderbook/full","update":{"EOSUSDT":{"t":1633806861828,"s":1876080,"a":[["4.98262","26.49"],["4.98269","0"]],"b":[["4.98154","0"],["4.98145","31.66"],["4.97889","80.33"],["4.97881","0"]]}}}
1633806862.005562: {"ch":"orderbook/full","update":{"EOSUSDT":{"t":1633806861914,"s":1876081,"a":[["5.04233","16381.41"],["5.04491","29154.10"]],"b":[["4.92496","13206.04"],["4.92397","19348.42"],["4.92255","3831.85"]]}}}
1633806862.051004: {"ch":"ticker/1s","data":{"DOGEUSDT":{"t":1633806861747,"a":"0.24805962","A":"34540","b":"0.24765126","B":"110310","o":"0.24716516","c":"0.24785108","h":"0.25200000","l":"0.24609780","v":"229140","q":"56558.87119500","p":"0.00068592","P":"0.2775148406838569","L":1417909170}}}
1633806862.051093: {"ch":"ticker/1s","data":{"NEOBTC":{"t":1633806861740,"a":"0.0008790","A":"18.89","b":"0.0008785","B":"17.00","o":"0.0008662","c":"0.0008786","h":"0.0009067","l":"0.0008475","v":"155805.01","q":"136.162079105","p":"0.0000124","P":"1.431540060032325","L":1417984656}}}
1633806862.0511339: {"ch":"ticker/1s","data":{"EOSUSDT":{"t":1633806861944,"a":"4.98262","A":"26.49","b":"4.98146","B":"760.00","o":"4.71891","c":"4.98523","h":"5.06033","l":"4.57171","v":"7224629.96","q":"34899840.7456554","p":"0.26632","P":"5.643676187933230","L":1417984568}}}
1633806862.09066: {"ch":"orderbook/full","update":{"ATOMBCH":{"t":1633806861995,"s":274283,"a":[["0.1702356","0.15"],["0.1702431","0"]],"b":[["0.0170243","0"],["0.0170235","0.14"]]}}}
1633806862.0928938: {"ch":"orderbook/full","update":{"HTBTC":{"t":1633806862033,"s":660765,"a":[["0.00029746","17212.22"],["0.00029787","0"]],"b":[]}}}
1633806862.107143: {"ch":"orderbook/full","update":{"EOSUSDT":{"t":1633806862030,"s":1876082,"a":[],"b":[["4.98146","0"],["4.98145","0"],["4.98129","362.33"]]}}}
1633806862.1909828: {"ch":"orderbook/full","update":{"NEOBTC":{"t":1633806862065,"s":1498376,"a":[["0.0008833","286.58"],["0.0008840","0"]],"b":[]}}}
1633806862.208666: {"ch":"orderbook/full","update":{"EOSUSDT":{"t":1633806862134,"s":1876083,"a":[["4.98253","26.49"],["4.98262","0"],["4.99384","240.00"],["4.99484","0"],["5.01417","30.00"],["5.01753","0"],["5.02029","6023.83"],["5.03196","0"],["5.43434","0"],["5.45790","93429.49"]],"b":[["4.98144","760.00"],["4.98129","330.67"],["4.98124","31.66"],["4.97931","0"],["4.97835","471.98"],["4.79965","0"],["4.75155","17800.28"]]}}}
1633806862.208877: {"ch":"orderbook/full","update":{"USDTUSDP":{"t":1633806862100,"s":384591,"a":[["1.100000","6.49"]],"b":[["0.900000","15.87"]]}}}
1633806862.299225: {"ch":"orderbook/full","update":{"NEOBTC":{"t":1633806862231,"s":1498377,"a":[["0.0008832","24.00"],["0.0008836","0"],["0.0008844","94.00"],["0.0008848","0"],["0.0009163","923.52"],["0.0009179","0"]],"b":[["0.0008745","0"],["0.0008741","24.00"],["0.0007282","0"],["0.0006911","557.30"]]}}}
1633806862.2998211: {"ch":"orderbook/full","update":{"EOSUSDT":{"t":1633806862197,"s":1876084,"a":[],"b":[["4.98144","0"]]}}}
1633806862.3956769: {"ch":"orderbook/full","update":{"NEOBTC":{"t":1633806862258,"s":1498378,"a":[["0.0008839","0"],["0.0008842","72.00"]],"b":[]}}}
1633806862.395807: {"ch":"orderbook/full","update":{"HTBTC":{"t":1633806862314,"s":660766,"a":[["0.00029704","17212.22"],["0.00029746","0"]],"b":[]}}}
1633806862.4046311: {"ch":"orderbook/full","update":{"EOSUSDT":{"t":1633806862328,"s":1876085,"a":[["4.98746","1379.87"],["4.98839","0"],["4.98920","1851.98"],["4.99026","0"],["4.99526","2368.39"],["4.99797","0"],["5.02960","79.52"],["5.03073","0"]],"b":[["4.98124","0"],["4.98112","31.66"],["4.97889","0"],["4.97781","80.35"],["4.97236","0"],["4.97166","240.00"]]}}}
1633806862.499649: {"ch":"orderbook/full","update":{"EOSUSDT":{"t":1633806862423,"s":1876086,"a":[["4.98242","26.49"],["4.98253","0"],["4.98290","100.26"],["4.98598","0"],["5.00920","4270.16"],["5.01645","0"]],"b":[["4.98112","0"],["4.98103","31.66"],["4.97993","0"],["4.97951","58.80"]]}}}
1633806862.589771: {"ch":"orderbook/full","update":{"XVSUSDT":{"t":1633806862489,"s":483991,"a":[["28.0765","107.095"],["28.0849","0"],["28.1492","0"],["28.1627","177.366"],["28.1789","0"],["28.2739","207.692"],["28.3153","0"],["28.3360","262.137"],["28.3530","0"],["28.3696","302.568"],["28.3780","0"],["28.4214","342.344"],["28.5469","0"],["28.5961","411.194"],["28.6323","0"],["28.6580","475.637"],["28.8403","0"],["28.8974","541.210"],["29.0369","0"],["29.0816","721.028"],["29.3708","0"],["29.4608","858.968"],["29.9034","0"],["29.9915","1131.987"],["30.4053","0"],["30.5031","1353.895"],["30.9336","0"],["31.0163","1576.464"]],"b":[]}}}
1633806862.5900311: {"ch":"orderbook/full","update":{"NEOBTC":{"t":1633806862522,"s":1498379,"a":[["0.0008832","0"],["0.0008836","24.00"]],"b":[["0.0008769","0"],["0.0008763","43.00"]]}}}
1633806862.6060941: {"ch":"orderbook/full","update":{"EOSUSDT":{"t":1633806862477,"s":1876087,"a":[["4.98290","0"],["4.98386","100.26"]],"b":[]}}}
1633806862.606227: {"ch":"orderbook/full","update":{"DOGEUSDT":{"t":1633806862492,"s":1308122,"a":[["0.24994352","343270"],["0.24995402","0"],["0.25002934","475940"],["0.25005137","0"],["0.25016959","424510"],["0.25018262","0"],["0.25026150","409170"],["0.25027646","0"],["0.25093456","442340"],["0.25094441","0"],["0.25120426","381360"],["0.25121420","0"],["0.25262927","423540"],["0.25264466","0"],["0.25281264","453690"],["0.25282984","0"],["0.25308134","473760"],["0.25309870","0"],["0.25328073","457200"],["0.25330116","0"],["0.25345189","336940"],["0.25346459","0"],["0.25364938","426170"],["0.25367841","0"],["0.25464610","388770"],["0.25466004","0"],["0.25474708","370950"],["0.25475351","0"],["0.25488492","443720"],["0.25490845","0"],["0.25517536","344070"],["0.25520657","0"]],"b":[]}}}
1633806862.689186: {"ch":"orderbook/full","update":{"XVSUSDT":{"t":1633806862590,"s":483992,"a":[["28.0908","98.436"],["28.1094","0"],["28.1434","105.569"],["28.1452","0"],["28.1627","0"],["28.1875","177.366"],["28.2739","0"],["28.3130","207.692"],["28.3360","0"],["28.3411","262.137"]],"b":[]}}}
1633806862.695623: {"ch":"orderbook/full","update":{"HTBTC":{"t":1633806862625,"s":660767,"a":[["0.00026777","11985.76"],["0.00026810","0"],["0.00029704","0"],["0.00029764","17212.22"]],"b":[]}}}
1633806862.6957598: {"ch":"orderbook/full","update":{"EOSUSDT":{"t":1633806862625,"s":1876088,"a":[["4.98639","391.27"],["4.98746","988.60"],["5.04233","0"],["5.04491","0"]],"b":[["4.98139","760.00"],["4.97525","0"],["4.97330","420.00"],["4.97303","1635.38"],["4.97230","240.00"],["4.97166","0"],["4.97062","2317.39"],["4.94867","0"],["4.93922","6107.92"],["4.92496","0"],["4.92397","0"],["4.92255","0"]]}}}
1633806862.695901: {"ch":"orderbook/full","update":{"USDTUSDP":{"t":1633806862604,"s":384592,"a":[["1.100000","5.74"]],"b":[["0.900000","15.12"]]}}}
1633806862.802697: {"ch":"orderbook/full","update":{"EOSUSDT":{"t":1633806862652,"s":1876089,"a":[],"b":[["4.98109","31.66"],["4.98103","0"]]}}}
1633806862.802839: {"ch":"orderbook/full","update":{"DOGEUSDT":{"t":1633806862647,"s":1308123,"a":[["0.25474708","0"],["0.25475328","370940"],["0.25488492","0"],["0.25490755","443690"],["0.25517536","0"],["0.25520526","344030"]],"b":[]}}}
1633806862.897312: {"ch":"orderbook/full","update":{"EOSUSDT":{"t":1633806862815,"s":1876090,"a":[["4.98387","0"],["4.98598","100.26"],["4.98639","0"],["4.98735","391.27"],["5.02960","0"],["5.03071","79.51"]],"b":[["4.97896","80.33"],["4.97781","0"]]}}}
1633806863.0081348: {"ch":"orderbook/full","update":{"HTBTC":{"t":1633806862932,"s":660768,"a":[["0.00014246","0"],["0.00014263","1357.31"],["0.00014359","0"],["0.00014374","1869.80"],["0.00014404","0"],["0.00014418","2494.12"]],"b":[]}}}
1633806863.008285: {"ch":"orderbook/full","update":{"EOSUSDT":{"t":1633806862935,"s":1876091,"a":[["4.99322","1348.10"],["4.99449","0"],["5.04223","16381.41"],["5.04442","29154.10"]],"b":[["4.92486","13206.04"],["4.92387","19348.42"],["4.92259","3831.85"]]}}}
1633806863.008378: {"ch":"orderbook/full","update":{"DOGEUSDT":{"t":1633806862879,"s":1308124,"a":[["0.24988615","182440"],["0.24989127","0"],["0.25002934","0"],["0.25003225","475930"],["0.25026150","0"],["0.25026416","409160"],["0.25105346","423810"],["0.25106265","0"],["0.25110536","442040"],["0.25111101","0"]],"b":[]}}}
1633806863.052354: {"ch":"ticker/1s","data":{"EOSUSDT":{"t":1633806862945,"a":"4.98242","A":"26.49","b":"4.98139","B":"760.00","o":"4.71891","c":"4.98523","h":"5.06033","l":"4.57171","v":"7224629.96","q":"34899840.7456554","p":"0.26632","P":"5.643676187933230","L":1417984568}}}
1633806863.0859761: {"ch":"orderbook/full","update":{"ATOMBCH":{"t":1633806862996,"s":274284,"a":[["0.1702356","0"],["0.1702431","0.13"]],"b":[]}}}
1633806863.0892942: {"ch":"orderbook/full","update":{"EOSUSDT":{"t":1633806862967,"s":1876092,"a":[],"b":[["4.98139","0"],["4.98114","31.66"],["4.98109","0"],["4.39357","1.27"]]}}}
1633806863.096832: {"ch":"orderbook/full","update":{"DOGEUSDT":{"t":1633806862981,"s":1308125,"a":[["0.24887662","209940"],["0.24904640","0"],["0.24933268","0"],["0.24935687","101010"],["0.24988615","0"],["0.24989431","182430"],["0.24994352","0"],["0.24994965","343260"],["0.25003225","0"],["0.25004045","475920"],["0.25016959","0"],["0.25017494","424500"],["0.25026416","0"],["0.25026967","409150"],["0.25093456","0"],["0.25094567","442320"],["0.25105346","0"],["0.25105951","423800"],["0.25110536","0"],["0.25110924","442030"],["0.25120426","0"],["0.25120739","381350"],["0.25262927","0"],["0.25263437","423530"],["0.25281264","0"],["0.25281807","453680"],["0.25308134","0"],["0.25308639","473750"],["0.25328073","0"],["0.25328638","457180"],["0.25364938","0"],["0.25365726","426160"],["0.25464610","0"],["0.25465218","388760"]],"b":[]}}}
1633806863.207703: {"ch":"orderbook/full","update":{"XVSUSDT":{"t":1633806863062,"s":483993,"a":[["28.1696","177.366"],["28.1852","207.692"],["28.1875","0"],["28.3130","0"],["28.3164","262.137"],["28.3411","0"],["28.3574","302.568"],["28.3696","0"],["28.3784","342.344"],["28.4214","0"],["28.5072","411.194"],["28.5961","0"],["28.6213","475.637"],["28.6580","0"],["28.8016","541.210"],["28.8974","0"]],"b":[]}}}
1633806863.207932: {"ch":"orderbook/full","update":{"EOSUSDT":{"t":1633806863123,"s":1876093,"a":[],"b":[["4.98139","760.00"],["4.98121","31.66"],["4.98114","0"]]}}}
1633806863.2080011: {"ch":"orderbook/full","update":{"USDTUSDP":{"t":1633806863108,"s":384593,"a":[["1.100000","6.38"]],"b":[["0.900000","15.76"]]}}}
1633806863.2080698: {"ch":"orderbook/full","update":{"DOGEUSDT":{"t":1633806863089,"s":1308126,"a":[["0.24887662","0"],["0.24901101","209940"],["0.25004045","0"],["0.25005281","475890"],["0.25017494","0"],["0.25017998","424490"],["0.25026967","0"],["0.25027547","409140"],["0.25094567","0"],["0.25095288","442310"],["0.25105951","0"],["0.25106566","423790"],["0.25120739","0"],["0.25121459","381340"],["0.25263437","0"],["0.25264532","423510"],["0.25281807","0"],["0.25283032","453660"],["0.25308639","0"],["0.25309680","473730"],["0.25328638","0"],["0.25329868","457160"],["0.25345189","0"],["0.25346310","336930"],["0.25365726","0"],["0.25367476","426130"],["0.25465218","0"],["0.25466123","388750"]],"b":[]}}}
1633806863.290526: {"ch":"orderbook/full","update":{"BORUSDT":{"t":1633806863155,"s":56256,"a":[["100000.000","0.0012"]],"b":[["0.001","1026.5998"]]}}}
1633806863.290656: {"ch":"orderbook/full","update":{"XVSUSDT":{"t":1633806863158,"s":483994,"a":[["29.3274","858.968"],["29.4608","0"],["29.8990","1131.987"],["29.9915","0"]],"b":[]}}}
1633806863.290741: {"ch":"orderbook/full","update":{"NEOBTC":{"t":1633806863172,"s":1498380,"a":[["0.0008795","18.02"],["0.0008797","0"],["0.0009462","793.22"],["0.0009725","0"],["0.0027639","1063.16"],["0.0028957","0"]],"b":[]}}}
1633806863.309011: {"ch":"orderbook/full","update":{"EOSUSDT":{"t":1633806863232,"s":1876094,"a":[["5.32094","0"],["5.33551","59703.38"]],"b":[["4.98129","362.33"],["4.98121","0"],["4.88700","0"],["4.87596","11826.73"],["4.75155","0"],["4.73923","17800.28"]]}}}
1633806863.309175: {"ch":"orderbook/full","update":{"DOGEUSDT":{"t":1633806863225,"s":1308127,"a":[["0.24839821","0"],["0.24853191","90410"]],"b":[]}}}
1633806863.389262: {"ch":"orderbook/full","update":{"XVSUSDT":{"t":1633806863246,"s":483995,"a":[["30.3949","1353.895"],["30.5031","0"]],"b":[]}}}
1633806863.40491: {"ch":"orderbook/full","update":{"DOGEUSDT":{"t":1633806863308,"s":1308128,"a":[["0.25309680","0"],["0.25309778","473720"]],"b":[]}}}
1633806863.587598: {"ch":"orderbook/full","update":{"HTBTC":{"t":1633806863452,"s":660769,"a":[["0.00022377","6848.62"],["0.00023017","0"]],"b":[]}}}
1633806863.587733: {"ch":"orderbook/full","update":{"EOSUSDT":{"t":1633806863530,"s":1876095,"a":[["4.99250","1470.03"],["4.99529","0"],["5.45790","0"],["5.47143","93429.49"]],"b":[]}}}
1633806863.68683: {"ch":"orderbook/full","update":{"NEOBTC":{"t":1633806863618,"s":1498381,"a":[["0.0008832","24.00"],["0.0008836","0"]],"b":[]}}}
1633806863.687886: {"ch":"orderbook/full","update":{"HTBTC":{"t":1633806863544,"s":660770,"a":[["0.00022377","0"],["0.00022920","6848.62"],["0.00034307","46776.23"],["0.00034372","0"]],"b":[]}}}
1633806863.690159: {"ch":"orderbook/full","update":{"EOSUSDT":{"t":1633806863579,"s":1876096,"a":[["4.98242","0"],["4.98249","26.49"],["5.04223","0"],["5.04442","0"]],"b":[["4.98135","31.66"],["4.98129","330.67"],["4.92486","0"],["4.92387","0"],["4.92259","0"]]}}}
1633806863.698251: {"ch":"orderbook/full","update":{"USDTUSDP":{"t":1633806863612,"s":384594,"a":[["1.100000","6.20"]],"b":[["0.900000","15.58"]]}}}
1633806863.7828019: {"ch":"orderbook/full","update":{"DCRETH":{"t":1633806863669,"s":499146,"a":[],"b":[["0.035986","4.535"],["0.035984","0"]]}}}
1633806863.786634: {"ch":"orderbook/full","update":{"NEOBTC":{"t":1633806863640,"s":1498382,"a":[["0.0009462","0"],["0.0009725","793.22"],["0.0027639","0"],["0.0028957","1063.16"]],"b":[]}}}
1633806863.7969642: {"ch":"orderbook/full","update":{"HTBTC":{"t":1633806863716,"s":660771,"a":[["0.00025512","8802.07"],["0.00025557","0"]],"b":[]}}}
1633806863.7970939: {"ch":"orderbook/full","update":{"EOSUSDT":{"t":1633806863713,"s":1876097,"a":[],"b":[["4.98139","0"]]}}}
1633806863.882978: {"ch":"orderbook/full","update":{"DCRETH":{"t":1633806863788,"s":499147,"a":[],"b":[["0.035987","7.673"],["0.035985","0"]]}}}
1633806863.885025: {"ch":"orderbook/full","update":{"NEOBTC":{"t":1633806863810,"s":1498383,"a":[["0.0008832","0"],["0.0008836","24.00"]],"b":[]}}}
1633806863.8947: {"ch":"orderbook/full","update":{"EOSUSDT":{"t":1633806863826,"s":1876098,"a":[],"b":[["4.98145","760.00"],["4.98135","0"],["4.98130","582.76"]]}}}
1633806863.985802: {"ch":"orderbook/full","update":{"NEOBTC":{"t":1633806863857,"s":1498384,"a":[["0.0008836","96.00"],["0.0008842","0"]],"b":[]}}}
1633806864.0043142: {"ch":"orderbook/full","update":{"EOSUSDT":{"t":1633806863934,"s":1876099,"a":[["4.99322","0"],["4.99422","1348.10"],["5.04469","20692.38"],["5.04723","8821.94"],["5.05555","0"],["5.06876","0"]],"b":[]}}}
1633806864.0659368: {"ch":"ticker/1s","data":{"DCRETH":{"t":1633806863838,"a":"0.036752","A":"0.448","b":"0.035987","B":"7.673","o":"0.035004","c":"0.036373","h":"0.036686","l":"0.035072","v":"8.326","q":"0.297986431","p":"0.001369","P":"3.910981602102617","L":1417957304}}}
1633806864.066039: {"ch":"ticker/1s","data":{"EOSUSDT":{"t":1633806863943,"a":"4.98249","A":"26.49","b":"4.98145","B":"760.00","o":"4.71891","c":"4.98523","h":"5.06033","l":"4.57171","v":"7224629.96","q":"34899840.7456554","p":"0.26632","P":"5.643676187933230","L":1417984568}}}
1633806864.080828: {"ch":"orderbook/full","update":{"DCRETH":{"t":1633806864033,"s":499148,"a":[],"b":[["0.035904","29.366"],["0.035889","0"],["0.035888","0"],["0.035674","33.000"]]}}}
1633806864.08436: {"ch":"orderbook/full","update":{"ATOMBCH":{"t":1633806864001,"s":274285,"a":[],"b":[["0.0170235","0"],["0.0170224","0.16"]]}}}
1633806864.091289: {"ch":"orderbook/full","update":{"EOSUSDT":{"t":1633806864028,"s":1876100,"a":[["5.00662","24879.28"],["5.01092","0"],["5.04203","16381.41"],["5.04443","29154.10"]],"b":[["4.98145","0"],["4.98132","31.66"],["4.98130","551.10"],["4.92466","13206.04"],["4.92367","19348.42"],["4.92247","3831.85"]]}}}
1633806864.091462: {"ch":"orderbook/full","update":{"DOGEUSDT":{"t":1633806863975,"s":1308129,"a":[["0.25485062","443780"],["0.25490755","0"],["0.25513649","344120"],["0.25520526","0"]],"b":[]}}}
1633806864.203598: {"ch":"orderbook/full","update":{"NEOBTC":{"t":1633806864131,"s":1498385,"a":[["0.0008832","24.00"],["0.0008836","0"],["0.0008842","166.00"],["0.0008844","0"]],"b":[]}}}
1633806864.203744: {"ch":"orderbook/full","update":{"EOSUSDT":{"t":1633806864133,"s":1876101,"a":[["5.05283","23366.02"],["5.06083","23957.85"],["5.06422","0"],["5.07556","0"]],"b":[["4.98142","760.00"],["4.26292","2.61"]]}}}
1633806864.20383: {"ch":"orderbook/full","update":{"USDTUSDP":{"t":1633806864117,"s":384595,"a":[["1.100000","6.49"]],"b":[["0.900000","15.87"]]}}}
1633806864.299006: {"ch":"orderbook/full","update":{"NEOBTC":{"t":1633806864220,"s":1498386,"a":[["0.0008791","2.96"],["0.0008792","0"],["0.0008793","7.17"],["0.0008795","10.85"]],"b":[]}}}
1633806864.313705: {"ch":"orderbook/full","update":{"EOSUSDT":{"t":1633806864225,"s":1876102,"a":[["5.02905","6980.08"],["5.04836","0"]],"b":[["4.98043","112.96"],["4.97913","0"],["4.97230","0"],["4.97220","0"],["4.97168","240.00"],["4.97052","30.00"],["4.48977","0.01"],["4.42907","0.01"]]}}}
1633806864.383688: {"ch":"orderbook/full","update":{"DCRETH":{"t":1633806864255,"s":499149,"a":[],"b":[["0.035983","7.643"],["0.035971","0"]]}}}
1633806864.391559: {"ch":"orderbook/full","update":{"NEOBTC":{"t":1633806864324,"s":1498387,"a":[["0.0008836","72.00"],["0.0008842","0"],["0.0008844","94.00"]],"b":[]}}}
1633806864.395844: {"ch":"orderbook/full","update":{"EOSUSDT":{"t":1633806864326,"s":1876103,"a":[],"b":[["4.98132","0"],["4.98122","31.66"],["4.97293","2317.39"],["4.97062","0"],["4.95001","6107.92"],["4.93922","0"],["4.36837","0.01"],["4.30767","0.01"],["4.24697","0.01"]]}}}
1633806864.3989382: {"ch":"orderbook/full","update":{"DOGEUSDT":{"t":1633806864301,"s":1308130,"a":[["0.24989245","182430"],["0.24989431","0"],["0.24994896","343270"],["0.24994965","0"],["0.25032310","459800"],["0.25032929","0"],["0.25485062","0"],["0.25486924","443750"],["0.25513649","0"],["0.25515628","344100"]],"b":[]}}}
1633806864.496046: {"ch":"orderbook/full","update":{"NEOBTC":{"t":1633806864434,"s":1498388,"a":[["0.0008791","0"],["0.0008792","2.96"],["0.0008832","0"],["0.0008836","24.00"],["0.0008842","72.00"]],"b":[]}}}
1633806864.497969: {"ch":"orderbook/full","update":{"EOSUSDT":{"t":1633806864415,"s":1876104,"a":[],"b":[["4.98142","0"],["4.98122","0"],["4.98114","31.66"],["4.97901","0"],["4.97820","0"],["4.97801","154.19"],["4.97732","457.24"]]}}}
1633806864.504367: {"ch":"orderbook/full","update":{"DOGEUSDT":{"t":1633806864396,"s":1308131,"a":[["0.24994896","0"],["0.24994947","343260"]],"b":[]}}}
1633806864.599148: {"ch":"orderbook/full","update":{"EOSUSDT":{"t":1633806864520,"s":1876105,"a":[["4.98242","26.49"],["4.98249","0"],["4.99321","1348.10"],["4.99422","0"],["5.01629","0"],["5.02859","79.54"],["5.03071","0"]],"b":[["4.98136","0"],["4.98114","0"],["4.98099","31.66"],["4.98043","0"],["4.98033","31.67"],["4.97896","0"],["4.97816","0"],["4.97794","112.96"],["4.97717","939.97"],["4.97687","80.37"]]}}}
1633806864.599375: {"ch":"orderbook/full","update":{"DOGEUSDT":{"t":1633806864530,"s":1308132,"a":[["0.24934531","101020"],["0.24935687","0"],["0.24998884","476020"],["0.25005281","0"]],"b":[["0.24765126","34320"],["0.24760997","75990"],["0.24735294","0"],["0.24725407","87230"],["0.24692662","0"],["0.24688494","45000"]]}}}
1633806864.683774: {"ch":"orderbook/full","update":{"XVSUSDT":{"t":1633806864590,"s":483996,"a":[],"b":[["27.8843","0"],["27.8780","168.599"],["27.8095","0"],["27.8017","199.881"]]}}}
1633806864.690371: {"ch":"orderbook/full","update":{"NEOBTC":{"t":1633806864611,"s":1498389,"a":[["0.0008832","24.00"],["0.0008836","0"]],"b":[["0.0008785","0"],["0.0008782","0"],["0.0008781","0"],["0.0008779","10.13"]]}}}
1633806864.690509: {"ch":"orderbook/full","update":{"EOSUSDT":{"t":1633806864631,"s":1876106,"a":[["4.98212","26.49"],["4.98242","0"],["4.98340","63.97"],["4.98388","0"],["5.01125","2.27"],["5.02782","79.55"],["5.02859","0"],["5.04203","0"],["5.04443","0"]],"b":[["4.98099","0"],["4.98078","31.66"],["4.98032","0"],["4.97981","0"],["4.97980","0"],["4.97915","1653.51"],["4.97835","0"],["4.97802","1102.41"],["4.97801","0"],["4.97753","471.98"],["4.97701","2745.62"],["4.97687","0"],["4.97682","990.87"],["4.97569","80.39"],["4.97546","0"],["4.97545","0"],["4.97316","430.00"],["4.97298","1783.00"],["4.97293","0"],["4.97077","2317.39"],["4.97060","0"],["4.97008","700.00"],["4.92466","0"],["4.92367","0"],["4.92247","0"],["4.89242","11826.73"],["4.87596","0"]]}}}
1633806864.6992772: {"ch":"orderbook/full","update":{"DOGEUSDT":{"t":1633806864618,"s":1308133,"a":[["0.24857438","0"],["0.24871918","113330"],["0.24872722","0"],["0.24892864","142410"],["0.24999892","0"],["0.25009386","424640"],["0.25017998","0"],["0.25019490","409280"],["0.25024755","363370"],["0.25027547","0"],["0.25083899","442510"],["0.25095288","0"],["0.25097238","423950"],["0.25106566","0"],["0.25108335","442080"],["0.25110779","361990"],["0.25110924","0"],["0.25114875","381440"],["0.25114979","0"],["0.25121459","0"],["0.25155797","0"],["0.25207936","148520"],["0.25246896","423810"],["0.25264532","0"],["0.25268244","453920"],["0.25283032","0"],["0.25288931","474120"],["0.25309778","0"],["0.25313632","457460"],["0.25329868","0"],["0.25333317","337100"],["0.25346310","0"],["0.25346892","426480"],["0.25367476","0"],["0.25446243","389050"],["0.25466123","0"],["0.25466975","371060"],["0.25475328","0"]],"b":[["0.24740252","0"],["0.24734245","129030"],["0.24728301","0"],["0.24721014","22000"],["0.24715870","0"],["0.24711320","38000"],["0.24688494","0"],["0.24685099","45000"]]}}}
1633806864.7939599: {"ch":"orderbook/full","update":{"NEOBTC":{"t":1633806864662,"s":1498390,"a":[["0.0008832","135.18"],["0.0008837","0"]],"b":[["0.0008779","3.54"],["0.0008777","6.59"]]}}}
1633806864.7994099: {"ch":"orderbook/full","update":{"HTBTC":{"t":1633806864649,"s":660772,"a":[["0.00014214","993.61"],["0.00014224","0"]],"b":[]}}}
1633806864.808894: {"ch":"orderbook/full","update":{"EOSUSDT":{"t":1633806864735,"s":1876107,"a":[["4.98171","760.00"],["4.98172","26.49"],["4.98212","0"],["4.98289","100.26"],["4.98290","100.26"],["4.98386","0"],["4.98555","140.81"],["4.98598","0"],["4.98669","0"],["4.98945","1698.95"],["4.99236","0"],["4.99313","240.00"],["4.99384","0"],["4.99469","2261.88"],["4.99515","2410.95"],["4.99530","0"],["4.99731","960.00"],["4.99746","2351.66"],["4.99813","0"],["4.99958","0"],["4.99968","2394.28"],["5.00230","0"],["5.00469","0"],["5.02641","79.57"],["5.02782","0"],["5.10057","16900.84"],["5.11317","0"]],"b":[["4.98130","0"],["4.98129","0"],["4.98078","0"],["4.98033","0"],["4.98031","0"],["4.98028","0"],["4.97985","31.66"],["4.97951","0"],["4.97916","31.67"],["4.97914","0"],["4.97872","0"],["4.97848","58.80"],["4.97784","664.26"],["4.97780","0"],["4.97745","133.97"],["4.97569","0"],["4.97527","0"],["4.97503","80.40"],["4.97356","445.04"],["4.97283","2171.87"],["4.97168","0"],["4.97107","240.00"],["4.97071","0"],["4.96796","2814.85"],["4.96756","0"],["4.96670","960.00"],["4.95001","0"],["4.93958","6107.92"]]}}}
1633806864.817759: {"ch":"orderbook/full","update":{"USDTUSDP":{"t":1633806864639,"s":384596,"a":[["1.100000","6.06"]],"b":[["0.900000","15.44"]]}}}
1633806864.8178618: {"ch":"orderbook/full","update":{"DOGEUSDT":{"t":1633806864722,"s":1308134,"a":[["0.24867336","36000"],["0.24870601","0"],["0.25019490","0"],["0.25019599","409270"],["0.25288931","0"],["0.25288958","474110"]],"b":[]}}}
1633806864.884879: {"ch":"orderbook/full","update":{"ATOMBCH":{"t":1633806864743,"s":274286,"a":[["0.0568306","0.88"],["0.0568476","0"]],"b":[]}}}
1633806864.8850071: {"ch":"orderbook/full","update":{"XVSUSDT":{"t":1633806864793,"s":483997,"a":[],"b":[["27.9741","113.816"],["27.9705","0"]]}}}
1633806864.889973: {"ch":"orderbook/full","update":{"NEOBTC":{"t":1633806864830,"s":1498391,"a":[["0.0008832","111.18"],["0.0008836","24.00"]],"b":[["0.0007282","557.30"],["0.0006911","0"]]}}}
1633806864.906396: {"ch":"orderbook/full","update":{"EOSUSDT":{"t":1633806864834,"s":1876108,"a":[["4.98159","26.49"],["4.98172","0"],["4.98288","100.26"],["4.98290","0"],["4.98825","1737.51"],["4.98952","0"],["4.99022","685.96"],["4.99122","0"],["4.99201","1721.26"],["4.99423","0"],["4.99469","700.00"],["4.99704","1561.88"],["5.02641","0"],["5.02753","79.56"],["5.02905","0"],["5.04494","6980.08"],["5.10057","0"],["5.11426","16900.84"]],"b":[["4.97985","0"],["4.97969","31.67"],["4.97968","31.66"],["4.97916","0"],["4.97803","1102.42"],["4.97753","0"],["4.97717","0"],["4.97705","0"],["4.97701","1071.38"],["4.97664","471.98"],["4.97661","0"],["4.97659","80.37"],["4.97653","0"],["4.97631","0"],["4.97605","939.97"],["4.97588","1723.94"],["4.97571","0"],["4.97569","1674.24"],["4.97557","422.89"],["4.97542","1636.04"],["4.97503","0"],["4.97486","1811.59"],["4.97464","109.20"],["4.97401","1619.89"],["4.97346","943.91"],["4.97226","0"],["4.97207","30.00"],["4.97052","0"],["4.97008","0"],["4.96934","700.00"],["4.96803","5265.26"],["4.96259","0"],["4.95796","2692.59"]]}}}
1633806864.906799: {"ch":"orderbook/full","update":{"DOGEUSDT":{"t":1633806864753,"s":1308135,"a":[["0.25009386","0"],["0.25009797","424630"],["0.25097238","0"],["0.25097471","423940"],["0.25108335","0"],["0.25108643","442070"],["0.25246896","0"],["0.25247361","423800"],["0.25268244","0"],["0.25268822","453910"],["0.25288958","0"],["0.25289548","474100"],["0.25313632","0"],["0.25314195","457450"],["0.25333317","0"],["0.25333968","337090"],["0.25346892","0"],["0.25347369","426470"],["0.25446243","0"],["0.25447250","389040"]],"b":[]}}}
1633806864.992685: {"ch":"orderbook/full","update":{"XVSUSDT":{"t":1633806864844,"s":483998,"a":[],"b":[["27.9610","109.088"],["27.9535","0"]]}}}
1633806864.992776: {"ch":"orderbook/full","update":{"NEOBTC":{"t":1633806864927,"s":1498392,"a":[["0.0008844","0"],["0.0008848","94.00"]],"b":[["0.0008780","14.15"],["0.0008779","0"]]}}}
1633806864.992828: {"ch":"orderbook/full","update":{"EOSUSDT":{"t":1633806864918,"s":1876109,"a":[["4.98144","26.49"],["4.98159","0"],["4.98499","580.23"],["4.98599","6336.24"],["4.99122","1019.31"],["4.99222","0"],["4.99474","1561.88"],["4.99704","0"],["5.02753","0"],["5.02768","79.55"],["5.03294","25103.85"],["5.03668","0"]],"b":[["4.97968","0"],["4.97957","31.66"],["4.97930","440.97"],["4.97848","0"],["4.97805","58.80"],["4.97616","0"],["4.97557","0"],["4.97456","139.05"],["4.97375","422.89"],["4.97207","0"],["4.97107","0"],["4.97056","240.00"],["4.96906","30.00"],["4.96670","0"],["4.96592","960.00"],["4.96237","2692.59"],["4.95900","0"],["4.95796","0"],["4.95694","0"],["4.94285","4542.71"],["4.93958","0"],["4.93737","4676.44"],["4.93508","0"],["4.92616","6107.92"],["4.92116","0"],["4.91511","6751.44"],["4.89412","9113.33"],["4.89242","0"],["4.85759","11826.73"]]}}}
1633806865.001112: {"ch":"orderbook/full","update":{"DOGEUSDT":{"t":1633806864889,"s":1308136,"a":[["0.24877276","62220"],["0.24879951","0"],["0.25009797","0"],["0.25012798","424580"],["0.25019599","0"],["0.25021317","409250"],["0.25083899","0"],["0.25086530","442460"],["0.25097471","0"],["0.25099562","423910"],["0.25108643","0"],["0.25109788","442050"],["0.25110779","0"],["0.25111886","361970"],["0.25114875","0"],["0.25115714","381430"],["0.25247361","0"],["0.25251071","423740"],["0.25268822","0"],["0.25272686","453840"],["0.25289548","0"],["0.25294531","474010"],["0.25314195","0"],["0.25317756","457380"],["0.25333968","0"],["0.25337761","337040"],["0.25347369","0"],["0.25351685","426400"],["0.25447250","0"],["0.25453276","388940"],["0.25466975","0"],["0.25469674","371020"]],"b":[["0.24685099","0"],["0.24681478","45000"]]}}}
1633806865.053897: {"ch":"ticker/1s","data":{"DOGEUSDT":{"t":1633806864948,"a":"0.24805962","A":"34540","b":"0.24765126","B":"34320","o":"0.24716516","c":"0.24785108","h":"0.25200000","l":"0.24609780","v":"229140","q":"56558.87119500","p":"0.00068592","P":"0.2775148406838569","L":1417909170}}}
1633806865.053988: {"ch":"ticker/1s","data":{"NEOBTC":{"t":1633806864942,"a":"0.0008790","A":"18.89","b":"0.0008780","B":"14.15","o":"0.0008662","c":"0.0008786","h":"0.0009067","l":"0.0008475","v":"155805.01","q":"136.162079105","p":"0.0000124","P":"1.431540060032325","L":1417984656}}}
1633806865.054027: {"ch":"ticker/1s","data":{"EOSUSDT":{"t":1633806864945,"a":"4.98144","A":"26.49","b":"4.97969","B":"31.67","o":"4.71891","c":"4.98523","h":"5.06033","l":"4.57171","v":"7224629.96","q":"34899840.7456554","p":"0.26632","P":"5.643676187933230","L":1417984568}}}
1633806865.054058: {"ch":"ticker/1s","data":{"ATOMBCH":{"t":1633806864841,"a":"0.0568306","A":"0.88","b":"0.0566683","B":"1.05","o":"0.0698883","c":"0.0585227","h":"0.0698883","l":"0.0585227","v":"0.72","q":"0.042136344","p":"-0.0113656","P":"-16.26252176687657","L":1417149989}}}
1633806865.093486: {"ch":"orderbook/full","update":{"ATOMBCH":{"t":1633806865001,"s":274287,"a":[["0.1702148","0.17"],["0.1702431","0"]],"b":[["0.0170224","0"],["0.0170214","0.13"]]}}}
1633806865.093627: {"ch":"orderbook/full","update":{"NEOBTC":{"t":1633806865030,"s":1498393,"a":[["0.0008836","0"],["0.0008841","72.00"],["0.0008842","24.00"]],"b":[["0.0008780","10.61"],["0.0008779","3.54"]]}}}
1633806865.108133: {"ch":"orderbook/full","update":{"EOSUSDT":{"t":1633806865020,"s":1876110,"a":[["4.98549","391.27"],["4.98735","0"],["4.98919","473.14"],["4.99076","0"],["4.99257","240.00"],["4.99313","0"],["5.02029","0"],["5.03033","6023.83"],["5.04093","16381.41"],["5.04521","29154.10"],["5.04723","0"],["5.06049","8821.94"]],"b":[["4.97970","551.22"],["4.97969","362.39"],["4.97915","0"],["4.97804","1653.64"],["4.97703","0"],["4.97599","1773.87"],["4.97542","0"],["4.97486","0"],["4.97314","1636.04"],["4.97303","0"],["4.97218","1811.59"],["4.97077","0"],["4.97010","1635.38"],["4.96814","2317.39"],["4.96742","0"],["4.96441","0"],["4.96407","2322.09"],["4.95979","2559.31"],["4.95862","0"],["4.94972","4070.73"],["4.92357","13206.04"],["4.92257","19348.42"],["4.92157","3831.85"],["4.89412","0"],["4.88420","9113.33"],["4.73923","0"],["4.70669","17800.28"]]}}}
1633806865.127629: {"ch":"orderbook/full","update":{"NEOBTC":{"t":1633806865103,"s":1498394,"a":[],"b":[["0.0008781","17.00"]]}}}
1633806865.130832: {"ch":"orderbook/full","update":{"EOSUSDT":{"t":1633806865122,"s":1876111,"a":[["4.98127","26.49"],["4.98144","0"],["4.98170","100.26"],["4.98288","0"],["4.98291","823.97"],["4.98340","0"],["4.98479","140.81"],["4.98555","0"],["4.99418","700.00"],["4.99469","0"],["4.99515","0"],["4.99746","0"],["4.99838","2410.95"],["4.99968","0"],["5.00156","2351.66"],["5.00445","2394.28"],["5.33551","0"],["5.36131","59703.38"]],"b":[["4.85759","0"],["4.84084","11826.73"],["4.70669","0"],["4.68179","17800.28"]]}}}
1633806865.137842: {"ch":"orderbook/full","update":{"DOGEUSDT":{"t":1633806865069,"s":1308137,"a":[],"b":[["0.24721014","0"],["0.24719273","22000"],["0.24686347","45000"],["0.24681478","0"]]}}}
1633806865.2234108: {"ch":"orderbook/full","update":{"NEOBTC":{"t":1633806865226,"s":1498395,"a":[["0.0008840","72.00"],["0.0008841","24.00"],["0.0008842","0"]],"b":[["0.0008780","14.15"],["0.0008779","0"]]}}}
1633806865.223561: {"ch":"orderbook/full","update":{"HTBTC":{"t":1633806865148,"s":660773,"a":[["0.00014254","1357.31"],["0.00014263","0"]],"b":[]}}}
1633806865.223625: {"ch":"orderbook/full","update":{"EOSUSDT":{"t":1633806865193,"s":1876112,"a":[["4.98101","26.49"],["4.98127","0"],["4.98170","0"],["4.98288","100.26"],["4.98499","3520.14"],["4.98599","3396.33"],["4.99221","1348.10"],["4.99321","0"],["5.01417","0"],["5.01577","30.00"]],"b":[["4.97957","0"],["4.97944","31.66"]]}}}
1633806865.229995: {"ch":"orderbook/full","update":{"USDTUSDP":{"t":1633806865232,"s":384597,"a":[["1.100000","6.20"]],"b":[["0.900000","15.58"]]}}}
1633806865.230121: {"ch":"orderbook/full","update":{"DOGEUSDT":{"t":1633806865229,"s":1308138,"a":[["0.25294531","0"],["0.25295837","473990"],["0.25317756","0"],["0.25318386","457370"],["0.25337761","0"],["0.25338471","337030"],["0.25351685","0"],["0.25352741","426380"],["0.25453276","0"],["0.25454382","388930"]],"b":[["0.24641332","49860"],["0.24637990","0"]]}}}
1633806865.326022: {"ch":"orderbook/full","update":{"HTBTC":{"t":1633806865314,"s":660774,"a":[["0.00014243","1357.31"],["0.00014254","0"],["0.00014401","2494.12"],["0.00014418","0"]],"b":[]}}}
1633806865.326161: {"ch":"orderbook/full","update":{"EOSUSDT":{"t":1633806865333,"s":1876113,"a":[["4.98540","988.60"],["4.98661","1612.05"],["4.98746","0"],["4.98857","0"],["4.98922","685.96"],["4.99022","0"],["4.99321","1476.43"],["4.99521","0"]],"b":[["4.85240","11826.73"],["4.84084","0"],["4.09420","5.44"]]}}}
1633806865.3302422: {"ch":"orderbook/full","update":{"DOGEUSDT":{"t":1633806865295,"s":1308139,"a":[],"b":[["0.24760997","0"],["0.24758940","75990"]]}}}
1633806865.441685: {"ch":"orderbook/full","update":{"ATOMBCH":{"t":1633806865358,"s":274288,"a":[],"b":[["0.0566683","0"],["0.0566552","1.05"]]}}}
1633806865.4418108: {"ch":"orderbook/full","update":{"XVSUSDT":{"t":1633806865360,"s":483999,"a":[["28.0679","60.540"],["28.0731","0"],["28.1320","105.569"],["28.1434","0"]],"b":[]}}}
1633806865.441887: {"ch":"orderbook/full","update":{"NEOBTC":{"t":1633806865417,"s":1498396,"a":[["0.0008840","24.00"],["0.0008841","0"],["0.0008842","72.00"]],"b":[]}}}
1633806865.441947: {"ch":"orderbook/full","update":{"EOSUSDT":{"t":1633806865406,"s":1876114,"a":[["4.98170","100.26"],["4.98288","0"],["4.98898","3125.73"],["4.98913","1072.37"],["4.99022","1019.31"],["4.99066","0"],["4.99122","0"],["4.99152","0"],["4.99338","1561.88"],["4.99474","0"]],"b":[]}}}
1633806865.518518: {"ch":"orderbook/full","update":{"XVSUSDT":{"t":1633806865460,"s":484000,"a":[["28.1772","207.692"],["28.1852","0"],["28.3103","262.137"],["28.3164","0"]],"b":[]}}}
1633806865.5242: {"ch":"orderbook/full","update":{"EOSUSDT":{"t":1633806865436,"s":1876115,"a":[["5.06049","0"],["5.07411","8821.94"]],"b":[["4.91511","0"],["4.90007","6751.44"],["4.88420","0"],["4.87332","9113.33"],["4.85240","0"],["4.82684","11826.73"],["4.68179","0"],["4.65487","17800.28"]]}}}
1633806865.6289852: {"ch":"orderbook/full","update":{"NEOBTC":{"t":1633806865600,"s":1498397,"a":[["0.0008839","24.00"],["0.0008840","0"]],"b":[]}}}
1633806865.6291149: {"ch":"orderbook/full","update":{"HTBTC":{"t":1633806865622,"s":660775,"a":[["0.00014363","1869.80"],["0.00014374","0"]],"b":[]}}}
1633806865.631953: {"ch":"orderbook/full","update":{"EOSUSDT":{"t":1633806865634,"s":1876116,"a":[["4.98469","391.27"],["4.98549","0"],["4.99338","0"],["4.99596","1561.88"]],"b":[["4.97985","760.00"],["4.97969","330.72"],["4.97806","31.67"],["4.97659","0"],["4.97633","80.38"],["4.97441","0"],["4.97355","0"],["4.97186","1753.83"],["4.97023","1796.32"],["4.96934","0"],["4.96881","700.00"]]}}}
1633806865.738401: {"ch":"orderbook/full","update":{"EOSUSDT":{"t":1633806865723,"s":1876117,"a":[["4.98170","0"],["4.98288","100.26"],["4.98469","0"],["4.98550","391.27"],["4.99330","1561.88"],["4.99596","0"],["5.04093","0"],["5.04521","0"],["5.09327","13225.51"],["5.10788","0"]],"b":[["4.97732","0"],["4.97701","154.19"],["4.97625","457.24"],["4.97599","0"],["4.97591","917.19"],["4.97501","1773.87"],["4.97146","0"],["4.97056","0"],["4.96994","240.00"],["4.96728","2595.81"],["4.92357","0"],["4.92257","0"],["4.92157","0"]]}}}
1633806865.738658: {"ch":"orderbook/full","update":{"DOGEUSDT":{"t":1633806865712,"s":1308140,"a":[["0.24984510","182470"],["0.24989245","0"],["0.24989881","343330"],["0.24994947","0"],["0.25029132","459860"],["0.25032310","0"],["0.25476651","443930"],["0.25486924","0"],["0.25496931","344350"],["0.25515628","0"]],"b":[]}}}
1633806865.824627: {"ch":"orderbook/full","update":{"NEOBTC":{"t":1633806865797,"s":1498398,"a":[["0.0008839","0"],["0.0008841","72.00"],["0.0008842","24.00"]],"b":[]}}}
1633806865.838627: {"ch":"orderbook/full","update":{"EOSUSDT":{"t":1633806865831,"s":1876118,"a":[["4.98985","1583.32"],["4.99217","0"]],"b":[["4.97986","31.67"],["4.97956","31.66"],["4.97944","0"],["4.97806","0"],["4.97665","0"],["4.97192","0"],["4.97181","6027.61"],["4.97134","2427.43"],["4.97010","0"],["4.96854","2486.04"],["4.95718","4070.73"],["4.94972","0"]]}}}
1633806865.838767: {"ch":"orderbook/full","update":{"USDTUSDP":{"t":1633806865736,"s":384598,"a":[["1.100000","6.24"]],"b":[["0.900000","15.62"]]}}}
1633806865.838807: {"ch":"orderbook/full","update":{"DOGEUSDT":{"t":1633806865823,"s":1308141,"a":[["0.24997232","476050"],["0.24998884","0"],["0.25476651","0"],["0.25477874","443910"],["0.25496931","0"],["0.25501976","344280"]],"b":[["0.24752367","0"],["0.24749930","46200"]]}}}
1633806865.9487958: {"ch":"orderbook/full","update":{"HTBTC":{"t":1633806865867,"s":660776,"a":[["0.00014184","0"],["0.00014187","64.89"]],"b":[]}}}
1633806865.9489238: {"ch":"orderbook/full","update":{"EOSUSDT":{"t":1633806865928,"s":1876119,"a":[],"b":[["4.97970","2204.81"],["4.97804","0"],["4.97049","2317.39"],["4.96814","0"],["4.95201","4542.71"],["4.94285","0"]]}}}
1633806865.9490151: {"ch":"orderbook/full","update":{"DOGEUSDT":{"t":1633806865864,"s":1308142,"a":[["0.24997232","0"],["0.24997404","476040"]],"b":[]}}}
1633806865.988298: {"ch":"ticker/1s","data":{"NEOBTC":{"t":1633806865841,"a":"0.0008790","A":"18.89","b":"0.0008781","B":"17.00","o":"0.0008662","c":"0.0008786","h":"0.0009067","l":"0.0008475","v":"155805.01","q":"136.162079105","p":"0.0000124","P":"1.431540060032325","L":1417984656}}}
1633806865.988387: {"ch":"ticker/1s","data":{"EOSUSDT":{"t":1633806865948,"a":"4.98101","A":"26.49","b":"4.97986","B":"31.67","o":"4.71891","c":"4.98523","h":"5.06033","l":"4.57171","v":"7224629.96","q":"34899840.7456554","p":"0.26632","P":"5.643676187933230","L":1417984568}}}
1633806865.988428: {"ch":"ticker/1s","data":{"ATOMBCH":{"t":1633806865442,"a":"0.0568306","A":"0.88","b":"0.0566552","B":"1.05","o":"0.0698883","c":"0.0585227","h":"0.0698883","l":"0.0585227","v":"0.72","q":"0.042136344","p":"-0.0113656","P":"-16.26252176687657","L":1417149989}}}
1633806866.018327: {"ch":"orderbook/full","update":{"ATOMBCH":{"t":1633806866013,"s":274289,"a":[["0.1702148","0.16"]],"b":[]}}}
1633806866.022356: {"ch":"orderbook/full","update":{"NEOBTC":{"t":1633806865995,"s":1498399,"a":[["0.0008832","135.18"],["0.0008841","0"],["0.0008842","72.00"]],"b":[["0.0008741","0"],["0.0008732","72.00"],["0.0008731","24.00"]]}}}
1633806866.035129: {"ch":"orderbook/full","update":{"EOSUSDT":{"t":1633806866033,"s":1876120,"a":[["4.99097","2463.07"],["4.99397","5056.24"],["4.99446","0"],["4.99892","0"],["5.04143","16381.41"],["5.04525","72759.75"]],"b":[["4.92137","13206.04"],["4.92037","19348.42"],["4.91938","3831.85"]]}}}
1633806866.120762: {"ch":"orderbook/full","update":{"NEOBTC":{"t":1633806866078,"s":1498400,"a":[],"b":[["0.0008780","10.61"],["0.0008779","3.54"]]}}}
1633806866.123453: {"ch":"orderbook/full","update":{"EOSUSDT":{"t":1633806866081,"s":1876121,"a":[["4.98093","26.49"],["4.98101","0"]],"b":[["4.97985","0"]]}}}
1633806866.305886: {"ch":"orderbook/full","update":{"NEOBTC":{"t":1633806866185,"s":1498401,"a":[],"b":[["0.0008733","72.00"],["0.0008732","24.00"],["0.0008731","0"]]}}}
1633806866.305938: {"ch":"orderbook/full","update":{"HTBTC":{"t":1633806866153,"s":660777,"a":[["0.00014707","4561.05"],["0.00014744","0"]],"b":[]}}}
1633806866.305957: {"ch":"orderbook/full","update":{"EOSUSDT":{"t":1633806866148,"s":1876122,"a":[],"b":[["4.97990","760.00"]]}}}
1633806866.305971: {"ch":"orderbook/full","update":{"DOGEUSDT":{"t":1633806866186,"s":1308143,"a":[["0.25010012","424620"],["0.25012798","0"],["0.25019563","409270"],["0.25021317","0"],["0.25029132","0"],["0.25029513","459850"],["0.25083899","442510"],["0.25086530","0"],["0.25097426","423940"],["0.25099562","0"],["0.25107060","442100"],["0.25109788","0"],["0.25109908","362000"],["0.25111886","0"],["0.25114919","381440"],["0.25115714","0"],["0.25249554","423760"],["0.25251071","0"],["0.25271070","453870"],["0.25272686","0"]],"b":[]}}}
1633806866.3214989: {"ch":"orderbook/full","update":{"NEOBTC":{"t":1633806866277,"s":1498402,"a":[["0.0008832","111.18"],["0.0008841","72.00"],["0.0008842","24.00"]],"b":[]}}}
1633806866.3277252: {"ch":"orderbook/full","update":{"EOSUSDT":{"t":1633806866316,"s":1876123,"a":[["4.98694","1737.51"],["4.98825","0"],["4.99615","3214.58"],["5.00195","0"]],"b":[["4.97990","0"]]}}}
1633806866.3278239: {"ch":"orderbook/full","update":{"USDTUSDP":{"t":1633806866241,"s":384599,"a":[["1.100000","6.22"]],"b":[["0.900000","15.60"]]}}}
1633806866.564208: {"ch":"orderbook/full","update":{"NEOBTC":{"t":1633806866377,"s":1498403,"a":[],"b":[["0.0008733","0"],["0.0008732","0"],["0.0008731","96.00"]]}}}
1633806866.564291: {"ch":"orderbook/full","update":{"EOSUSDT":{"t":1633806866372,"s":1876124,"a":[["4.99501","2385.82"],["4.99850","0"]],"b":[]}}}
1633806866.5643132: {"ch":"orderbook/full","update":{"DOGEUSDT":{"t":1633806866391,"s":1308144,"a":[["0.25010012","0"],["0.25010608","424610"],["0.25083899","0"],["0.25084328","442500"]],"b":[]}}}
1633806866.5643442: {"ch":"orderbook/full","update":{"NEOBTC":{"t":1633806866469,"s":1498404,"a":[["0.0008841","0"],["0.0008842","96.00"]],"b":[]}}}
1633806866.5643609: {"ch":"orderbook/full","update":{"EOSUSDT":{"t":1633806866524,"s":1876125,"a":[["4.99293","1561.88"],["4.99330","0"]],"b":[["4.97992","760.00"],["4.97963","31.66"],["4.97956","0"],["4.93474","6107.92"],["4.92616","0"],["3.90021","8.56"]]}}}
1633806866.6581619: {"ch":"orderbook/full","update":{"NEOBTC":{"t":1633806866556,"s":1498405,"a":[],"b":[["0.0008741","24.00"],["0.0008731","72.00"]]}}}
1633806866.6582851: {"ch":"orderbook/full","update":{"HTBTC":{"t":1633806866620,"s":660778,"a":[["0.00014707","0"],["0.00014732","4561.05"],["0.00025512","0"],["0.00025580","8802.07"],["0.00026777","0"],["0.00026823","11985.76"],["0.00034307","0"],["0.00034401","46776.23"]],"b":[]}}}
1633806866.658366: {"ch":"orderbook/full","update":{"EOSUSDT":{"t":1633806866619,"s":1876126,"a":[["4.99067","2448.24"],["4.99277","0"],["4.99961","2394.28"],["5.00445","0"],["5.08008","13225.51"],["5.09327","0"]],"b":[["4.97977","31.66"],["4.97963","0"]]}}}
1633806866.658428: {"ch":"orderbook/full","update":{"DOGEUSDT":{"t":1633806866631,"s":1308145,"a":[["0.24989881","0"],["0.24990737","343320"],["0.24997404","0"],["0.24998249","476030"],["0.25010608","0"],["0.25011249","424600"],["0.25019563","0"],["0.25020204","409260"],["0.25029513","0"],["0.25030149","459840"],["0.25084328","0"],["0.25084969","442490"],["0.25097426","0"],["0.25098176","423930"],["0.25107060","0"],["0.25107618","442090"],["0.25109908","0"],["0.25110677","361990"],["0.25114919","0"],["0.25115481","381430"],["0.25249554","0"],["0.25251418","423730"],["0.25271070","0"],["0.25272458","453850"],["0.25294835","474000"],["0.25295837","0"],["0.25317902","457380"],["0.25318386","0"],["0.25337923","337040"],["0.25338471","0"],["0.25351921","426390"],["0.25352741","0"],["0.25453523","388940"],["0.25454382","0"],["0.25469344","371030"],["0.25469674","0"]],"b":[]}}}
1633806866.833955: {"ch":"orderbook/full","update":{"NEOBTC":{"t":1633806866679,"s":1498406,"a":[["0.0008832","135.18"],["0.0008842","72.00"],["0.0008844","94.00"],["0.0008848","0"]],"b":[]}}}
1633806866.8340101: {"ch":"orderbook/full","update":{"DOGEUSDT":{"t":1633806866708,"s":1308146,"a":[["0.24984510","0"],["0.24985085","182460"],["0.24998249","0"],["0.24998660","476020"],["0.25011249","0"],["0.25011810","424590"],["0.25030149","0"],["0.25030495","459830"],["0.25084969","0"],["0.25085424","442480"],["0.25251418","0"],["0.25252094","423720"],["0.25272458","0"],["0.25273038","453840"],["0.25294835","0"],["0.25295979","473980"],["0.25317902","0"],["0.25318456","457370"],["0.25337923","0"],["0.25338536","337030"],["0.25351921","0"],["0.25353012","426370"],["0.25453523","0"],["0.25454490","388920"],["0.25469344","0"],["0.25469828","371020"],["0.25477874","0"],["0.25478263","443900"],["0.25501976","0"],["0.25503374","344260"]],"b":[]}}}
1633806866.834081: {"ch":"orderbook/full","update":{"EOSUSDT":{"t":1633806866721,"s":1876127,"a":[["5.04143","0"],["5.04525","43605.65"],["5.08008","0"],["5.09373","13225.51"]],"b":[["4.97983","31.66"],["4.97977","0"],["4.97508","1636.04"],["4.97314","0"],["4.92137","0"],["4.92037","0"],["4.91938","0"]]}}}
1633806866.834115: {"ch":"orderbook/full","update":{"NEOBTC":{"t":1633806866751,"s":1498407,"a":[["0.0028957","0"],["0.0028988","1063.16"]],"b":[]}}}
1633806866.836981: {"ch":"orderbook/full","update":{"HTBTC":{"t":1633806866832,"s":660779,"a":[["0.00022346","6848.62"],["0.00022920","0"]],"b":[]}}}
1633806866.837007: {"ch":"orderbook/full","update":{"EOSUSDT":{"t":1633806866751,"s":1876128,"a":[],"b":[["4.97460","1811.59"],["4.97218","0"]]}}}
1633806866.837023: {"ch":"orderbook/full","update":{"USDTUSDP":{"t":1633806866744,"s":384600,"a":[["1.100000","5.56"]],"b":[["0.900000","14.94"]]}}}
1633806866.92314: {"ch":"orderbook/full","update":{"NEOBTC":{"t":1633806866871,"s":1498408,"a":[["0.0008832","111.18"],["0.0008841","72.00"],["0.0008842","24.00"],["0.0008844","0"],["0.0008848","94.00"]],"b":[]}}}
1633806866.932726: {"ch":"orderbook/full","update":{"HTBTC":{"t":1633806866913,"s":660780,"a":[["0.00022346","0"],["0.00022427","6848.62"]],"b":[]}}}
1633806866.9328132: {"ch":"orderbook/full","update":{"EOSUSDT":{"t":1633806866930,"s":1876129,"a":[["4.98170","100.26"],["4.98288","0"],["4.98848","143.85"],["4.99048","0"]],"b":[]}}}
1633806866.939048: {"ch":"orderbook/full","update":{"DOGEUSDT":{"t":1633806866935,"s":1308147,"a":[["0.24990737","0"],["0.24991605","343310"],["0.24998660","0"],["0.24999272","476010"],["0.25011810","0"],["0.25012380","424580"],["0.25020204","0"],["0.25020947","409250"],["0.25085424","0"],["0.25086137","442470"],["0.25098176","0"],["0.25098904","423920"],["0.25110677","0"],["0.25111368","361980"],["0.25115481","0"],["0.25116258","381420"],["0.25252094","0"],["0.25253356","423700"],["0.25273038","0"],["0.25273775","453830"],["0.25295979","0"],["0.25297700","473950"]],"b":[]}}}
1633806867.017612: {"ch":"ticker/1s","data":{"EOSUSDT":{"t":1633806866944,"a":"4.98093","A":"26.49","b":"4.97992","B":"760.00","o":"4.71891","c":"4.98523","h":"5.06033","l":"4.57171","v":"7224629.96","q":"34899840.7456554","p":"0.26632","P":"5.643676187933230","L":1417984568}}}
1633806867.0202591: {"ch":"orderbook/full","update":{"ATOMBCH":{"t":1633806867014,"s":274290,"a":[["0.1702148","0.11"]],"b":[["0.0170214","0.16"]]}}}
1633806867.0203211: {"ch":"orderbook/full","update":{"NEOBTC":{"t":1633806867034,"s":1498409,"a":[["0.0008841","96.00"],["0.0008842","0"]],"b":[]}}}
1633806867.0203562: {"ch":"orderbook/full","update":{"EOSUSDT":{"t":1633806867024,"s":1876130,"a":[["4.99226","2368.39"],["4.99462","2410.95"],["4.99526","0"],["4.99732","2351.66"],["4.99838","0"],["5.00156","0"],["5.03381","6980.08"],["5.04494","0"]],"b":[]}}}
1633806867.0288472: {"ch":"orderbook/full","update":{"DOGEUSDT":{"t":1633806866935,"s":1308148,"a":[["0.25318456","0"],["0.25319360","457350"],["0.25338536","0"],["0.25339466","337020"],["0.25353012","0"],["0.25354269","426350"],["0.25454490","0"],["0.25455810","388900"],["0.25469828","0"],["0.25470555","371010"],["0.25478263","0"],["0.25478939","443890"],["0.25503374","0"],["0.25505399","344240"]],"b":[]}}}
1633806867.198566: {"ch":"orderbook/full","update":{"NEOBTC":{"t":1633806867042,"s":1498410,"a":[["0.0008840","72.00"],["0.0008841","24.00"]],"b":[]}}}
1633806867.19871: {"ch":"orderbook/full","update":{"HTBTC":{"t":1633806867121,"s":660781,"a":[["0.00014705","4561.05"],["0.00014732","0"]],"b":[]}}}
1633806867.19876: {"ch":"orderbook/full","update":{"EOSUSDT":{"t":1633806867120,"s":1876131,"a":[["5.04112","16381.41"],["5.04485","29154.10"]],"b":[["4.97983","0"],["4.97976","31.66"],["4.92227","13206.04"],["4.92128","19348.42"],["4.92028","3831.85"]]}}}
1633806867.22239: {"ch":"orderbook/full","update":{"NEOBTC":{"t":1633806867226,"s":1498411,"a":[["0.0008832","135.18"],["0.0008841","0"]],"b":[]}}}
1633806867.228548: {"ch":"orderbook/full","update":{"DOGEUSDT":{"t":1633806867215,"s":1308149,"a":[["0.25086137","0"],["0.25094094","442330"],["0.25098904","0"],["0.25104775","423820"],["0.25107618","0"],["0.25109187","442060"],["0.25111368","0"],["0.25114496","361940"],["0.25116258","0"],["0.25122236","381330"],["0.25253356","0"],["0.25265611","423500"],["0.25273775","0"],["0.25284119","453640"],["0.25297700","0"],["0.25310625","473710"],["0.25319360","0"],["0.25331151","457140"],["0.25339466","0"],["0.25347083","336920"],["0.25354269","0"],["0.25369414","426100"],["0.25455810","0"],["0.25466551","388740"],["0.25470555","0"],["0.25475521","370940"],["0.25478939","0"],["0.25492125","443660"],["0.25505399","0"],["0.25522216","344010"]],"b":[]}}}
1633806867.380574: {"ch":"orderbook/full","update":{"NEOBTC":{"t":1633806867334,"s":1498412,"a":[["0.0008840","0"],["0.0008842","72.00"]],"b":[["0.0008780","0"],["0.0008777","17.20"]]}}}
1633806867.38071: {"ch":"orderbook/full","update":{"EOSUSDT":{"t":1633806867268,"s":1876132,"a":[["4.98532","1612.05"],["4.98661","0"],["4.99091","1809.39"],["4.99311","0"]],"b":[["4.60156","7565.88"],["4.58105","0"]]}}}
1633806867.380772: {"ch":"orderbook/full","update":{"USDTUSDP":{"t":1633806867248,"s":384601,"a":[["1.100000","6.44"]],"b":[["0.900000","15.82"]]}}}
1633806867.562321: {"ch":"orderbook/full","update":{"DOGEUSDT":{"t":1633806867364,"s":1308150,"a":[],"b":[["0.24721891","22000"],["0.24719273","0"]]}}}
1633806867.562421: {"ch":"orderbook/full","update":{"DCRETH":{"t":1633806867463,"s":499150,"a":[["0.036972","17.000"],["0.036973","59.264"],["0.037025","0"],["0.037026","0"],["0.038256","287.401"],["0.038467","0"],["0.039281","302.242"],["0.039517","0"],["0.040018","299.433"],["0.040235","0"],["0.040531","282.563"],["0.040729","0"],["0.040967","316.098"],["0.041146","0"]],"b":[]}}}
1633806867.5625012: {"ch":"orderbook/full","update":{"EOSUSDT":{"t":1633806867520,"s":1876133,"a":[["4.98170","0"],["4.98288","100.26"],["4.98674","1851.98"],["4.98920","0"]],"b":[]}}}
1633806867.7454998: {"ch":"orderbook/full","update":{"EOSUSDT":{"t":1633806867625,"s":1876134,"a":[["4.98086","26.49"],["4.98093","0"],["4.98170","100.26"],["4.98288","0"]],"b":[["4.97976","0"],["4.97971","31.66"],["4.60156","0"],["4.58107","7565.88"],["3.77339","10.32"]]}}}
1633806867.745631: {"ch":"orderbook/full","update":{"EOSUSDT":{"t":1633806867729,"s":1876135,"a":[["5.02089","6023.83"],["5.03033","0"],["5.04112","0"],["5.04485","0"]],"b":[["4.92227","0"],["4.92128","0"],["4.92028","0"]]}}}
1633806867.955013: {"ch":"orderbook/full","update":{"EOSUSDT":{"t":1633806867777,"s":1876136,"a":[],"b":[["4.97979","31.66"],["4.97971","0"]]}}}
1633806867.9551518: {"ch":"orderbook/full","update":{"USDTUSDP":{"t":1633806867751,"s":384602,"a":[["1.100000","6.02"]],"b":[["0.900000","15.40"]]}}}
1633806867.955221: {"ch":"orderbook/full","update":{"NEOBTC":{"t":1633806867887,"s":1498413,"a":[["0.0008817","232.96"],["0.0008823","40.61"]],"b":[]}}}
1633806867.955282: {"ch":"orderbook/full","update":{"EOSUSDT":{"t":1633806867920,"s":1876137,"a":[],"b":[["4.97992","0"],["4.97986","791.67"],["4.97979","0"],["4.97974","31.66"]]}}}
1633806867.982309: {"ch":"ticker/1s","data":{"EOSUSDT":{"t":1633806867943,"a":"4.98086","A":"26.49","b":"4.97986","B":"791.67","o":"4.71891","c":"4.98523","h":"5.06033","l":"4.57171","v":"7224629.96","q":"34899840.7456554","p":"0.26632","P":"5.643676187933230","L":1417984568}}}
1633806868.025168: {"ch":"orderbook/full","update":{"ATOMBCH":{"t":1633806868015,"s":274291,"a":[["0.1702148","0.17"]],"b":[["0.0170214","0.12"]]}}}
1633806868.025297: {"ch":"orderbook/full","update":{"XVSUSDT":{"t":1633806867990,"s":484001,"a":[["28.1320","0"],["28.1411","105.569"],["28.1772","0"],["28.1829","207.692"],["28.3103","0"],["28.3155","262.137"]],"b":[]}}}
1633806868.033084: {"ch":"orderbook/full","update":{"EOSUSDT":{"t":1633806867991,"s":1876138,"a":[],"b":[["4.97986","31.67"]]}}}
1633806868.1239219: {"ch":"orderbook/full","update":{"EOSUSDT":{"t":1633806868107,"s":1876139,"a":[["5.04082","16381.41"],["5.04393","29154.10"]],"b":[["4.92267","13206.04"],["4.92168","19348.42"],["4.92068","3831.85"]]}}}
1633806868.2231429: {"ch":"orderbook/full","update":{"BORUSDT":{"t":1633806868163,"s":56257,"a":[["100000.000","0.0011"]],"b":[["0.001","1026.5997"]]}}}
1633806868.3220422: {"ch":"orderbook/full","update":{"EOSUSDT":{"t":1633806868239,"s":1876140,"a":[],"b":[["4.93139","6751.44"],["4.90007","0"]]}}}
1633806868.329099: {"ch":"orderbook/full","update":{"USDTUSDP":{"t":1633806868256,"s":384603,"a":[["1.100000","5.88"]],"b":[["0.900000","15.26"]]}}}
1633806868.436694: {"ch":"orderbook/full","update":{"EOSUSDT":{"t":1633806868420,"s":1876141,"a":[],"b":[["4.97986","791.67"],["4.94563","6107.92"],["4.93474","0"]]}}}
1633806868.533375: {"ch":"orderbook/full","update":{"NEOBTC":{"t":1633806868501,"s":1498414,"a":[["0.0008809","43.00"],["0.0008814","0"]],"b":[]}}}
1633806868.533504: {"ch":"orderbook/full","update":{"EOSUSDT":{"t":1633806868508,"s":1876142,"a":[],"b":[["4.97980","31.66"],["4.97974","0"]]}}}
1633806868.533568: {"ch":"orderbook/full","update":{"DOGEUSDT":{"t":1633806868530,"s":1308151,"a":[["0.25028814","459860"],["0.25030495","0"],["0.25084688","442500"],["0.25094094","0"],["0.25097078","423950"],["0.25104775","0"],["0.25107660","442090"],["0.25109187","0"],["0.25110746","361990"],["0.25114496","0"],["0.25115543","381430"],["0.25122236","0"],["0.25251472","423730"],["0.25265611","0"],["0.25272648","453850"],["0.25284119","0"],["0.25295518","473990"],["0.25310625","0"],["0.25318224","457370"],["0.25331151","0"],["0.25338300","337030"],["0.25347083","0"],["0.25352472","426380"],["0.25369414","0"],["0.25454100","388930"],["0.25466551","0"],["0.25469632","371030"],["0.25475521","0"],["0.25478100","443910"],["0.25492125","0"],["0.25502820","344270"],["0.25522216","0"]],"b":[]}}}
1633806868.612361: {"ch":"orderbook/full","update":{"DCRETH":{"t":1633806868556,"s":499151,"a":[],"b":[["0.035905","16.000"],["0.035674","17.000"]]}}}
1633806868.6210911: {"ch":"orderbook/full","update":{"NEOBTC":{"t":1633806868610,"s":1498415,"a":[["0.0008809","0"],["0.0008814","43.00"],["0.0008831","922.64"],["0.0008832","111.18"],["0.0008844","94.00"],["0.0008848","0"]],"b":[]}}}
1633806868.628437: {"ch":"orderbook/full","update":{"EOSUSDT":{"t":1633806868600,"s":1876143,"a":[["4.98170","0"],["4.98288","100.26"],["5.04973","8821.94"],["5.07411","0"],["5.13856","24335.25"],["5.15298","0"]],"b":[["4.91937","9113.33"],["4.89619","11826.73"],["4.87332","0"],["4.82684","0"]]}}}
1633806868.631646: {"ch":"orderbook/full","update":{"DOGEUSDT":{"t":1633806868541,"s":1308152,"a":[["0.25272648","0"],["0.25272670","453840"],["0.25469632","0"],["0.25469651","371020"]],"b":[]}}}
1633806868.730716: {"ch":"orderbook/full","update":{"EOSUSDT":{"t":1633806868734,"s":1876144,"a":[],"b":[["4.43237","2.51"]]}}}
1633806868.738528: {"ch":"orderbook/full","update":{"DOGEUSDT":{"t":1633806868730,"s":1308153,"a":[["0.25084688","0"],["0.25085326","442480"],["0.25097078","0"],["0.25097435","423940"],["0.25251472","0"],["0.25252192","423720"],["0.25272670","0"],["0.25273344","453830"],["0.25295518","0"],["0.25296532","473970"],["0.25318224","0"],["0.25318733","457360"],["0.25338300","0"],["0.25339058","337020"],["0.25352472","0"],["0.25353615","426360"],["0.25454100","0"],["0.25455239","388910"],["0.25478100","0"],["0.25478458","443900"],["0.25502820","0"],["0.25504037","344250"]],"b":[]}}}
1633806868.811915: {"ch":"orderbook/full","update":{"DCRETH":{"t":1633806868789,"s":499152,"a":[],"b":[["0.032693","250.620"],["0.032563","0"],["0.031969","276.700"],["0.031809","0"]]}}}
1633806868.820671: {"ch":"orderbook/full","update":{"NEOBTC":{"t":1633806868809,"s":1498416,"a":[["0.0008816","0.12"],["0.0008819","0"]],"b":[]}}}
1633806868.823606: {"ch":"orderbook/full","update":{"EOSUSDT":{"t":1633806868829,"s":1876145,"a":[["4.99436","1846.40"],["4.99728","0"],["5.04082","0"],["5.04393","0"]],"b":[["4.97980","0"],["4.97972","31.66"],["4.92267","0"],["4.92168","0"],["4.92068","0"],["4.83911","17800.28"],["4.65487","0"]]}}}
1633806868.828347: {"ch":"orderbook/full","update":{"USDTUSDP":{"t":1633806868760,"s":384604,"a":[["1.100000","5.50"]],"b":[["0.900000","14.88"]]}}}
1633806868.8310442: {"ch":"orderbook/full","update":{"DOGEUSDT":{"t":1633806868825,"s":1308154,"a":[["0.24863212","113330"],["0.24871918","0"],["0.25252192","0"],["0.25252624","423710"],["0.25296532","0"],["0.25296986","473960"],["0.25469651","0"],["0.25470328","371010"],["0.25504037","0"],["0.25504789","344240"]],"b":[]}}}
1633806868.9116359: {"ch":"orderbook/full","update":{"DCRETH":{"t":1633806868853,"s":499153,"a":[],"b":[["0.032693","0"],["0.032574","250.620"],["0.031969","0"],["0.031870","276.700"]]}}}
1633806868.919911: {"ch":"orderbook/full","update":{"EOSUSDT":{"t":1633806868929,"s":1876146,"a":[["4.99022","0"],["4.99079","1019.31"],["4.99436","0"],["4.99521","1846.40"],["5.20948","43331.32"],["5.26784","0"],["5.32092","59703.38"],["5.36131","0"]],"b":[["4.97354","1635.38"],["4.97181","4392.23"],["4.96743","2322.09"],["4.96407","0"]]}}}
1633806868.985067: {"ch":"ticker/1s","data":{"EOSUSDT":{"t":1633806868943,"a":"4.98086","A":"26.49","b":"4.97986","B":"791.67","o":"4.71891","c":"4.98523","h":"5.06033","l":"4.57171","v":"7224629.96","q":"34899840.7456554","p":"0.26632","P":"5.643676187933230","L":1417984568}}}
1633806869.0179: {"ch":"orderbook/full","update":{"ATOMBCH":{"t":1633806869015,"s":274292,"a":[["0.1702148","0.10"]],"b":[["0.0170214","0.17"]]}}}
1633806869.0249941: {"ch":"orderbook/full","update":{"EOSUSDT":{"t":1633806869017,"s":1876147,"a":[],"b":[["4.85383","17800.28"],["4.83911","0"]]}}}
1633806869.0334148: {"ch":"orderbook/full","update":{"DOGEUSDT":{"t":1633806868993,"s":1308155,"a":[["0.24811211","78270"],["0.24814874","40260"]],"b":[]}}}
1633806869.116684: {"ch":"orderbook/full","update":{"DCRETH":{"t":1633806869115,"s":499154,"a":[],"b":[["0.035905","0"],["0.035674","33.000"]]}}}
1633806869.116817: {"ch":"trades","update":{"NEOBTC":[{"t":1633806869067,"i":1633806869067,"p":"0.0008785","q":"0.15","s":"buy"}]}}
1633806869.116862: {"ch":"candles/M1","update":{"NEOBTC":[{"t":1633806840000,"o":"0.0008788","c":"0.0008785","h":"0.0008788","l":"0.0008785","v":"2.37","q":"0.002082497"}]}}
1633806869.121621: {"ch":"orderbook/full","update":{"NEOBTC":{"t":1633806869067,"s":1498417,"a":[["0.0008844","0"],["0.0008848","94.00"]],"b":[]}}}
1633806869.12174: {"ch":"orderbook/full","update":{"EOSUSDT":{"t":1633806869126,"s":1876148,"a":[],"b":[["4.97986","31.67"],["4.96454","2559.31"],["4.95979","0"],["4.92287","13206.04"],["4.92188","19348.42"],["4.92088","3831.85"],["4.90804","11826.73"],["4.89619","0"]]}}}
1633806869.2258308: {"ch":"orderbook/full","update":{"XVSUSDT":{"t":1633806869136,"s":484002,"a":[],"b":[["28.0188","0"],["28.0142","2.014"],["28.0011","0"],["27.9879","22.945"],["27.8017","0"],["27.7963","199.881"]]}}}
1633806869.225984: {"ch":"orderbook/full","update":{"HTBTC":{"t":1633806869151,"s":660782,"a":[["0.00014705","0"],["0.00014727","4561.05"],["0.00022427","0"],["0.00022821","6848.62"]],"b":[]}}}
1633806869.2260559: {"ch":"orderbook/full","update":{"EOSUSDT":{"t":1633806869224,"s":1876149,"a":[["4.98170","100.26"],["4.98288","0"],["5.04062","16381.41"],["5.04402","29154.10"]],"b":[["4.97986","791.67"]]}}}
1633806869.22613: {"ch":"orderbook/full","update":{"DOGEUSDT":{"t":1633806869194,"s":1308156,"a":[["0.24984793","182470"],["0.24985085","0"],["0.24990824","343320"],["0.24991605","0"],["0.24998330","476030"],["0.24999272","0"],["0.25011396","424600"],["0.25012380","0"],["0.25020386","409260"],["0.25020947","0"]],"b":[]}}}
1633806869.3136032: {"ch":"orderbook/full","update":{"DCRETH":{"t":1633806869314,"s":499155,"a":[],"b":[["0.035987","6.982"]]}}}
1633806869.325264: {"ch":"orderbook/full","update":{"EOSUSDT":{"t":1633806869283,"s":1876150,"a":[],"b":[["4.97072","2814.85"],["4.96796","0"],["4.95447","6107.92"],["4.94563","0"],["4.94303","6751.44"],["4.93139","0"],["4.93003","9113.33"],["4.91937","0"],["4.86466","17800.28"],["4.85383","0"]]}}}
1633806869.330511: {"ch":"orderbook/full","update":{"USDTUSDP":{"t":1633806869263,"s":384605,"a":[["1.100000","5.93"]],"b":[["0.900000","15.31"]]}}}
1633806869.3306391: {"ch":"orderbook/full","update":{"DOGEUSDT":{"t":1633806869324,"s":1308157,"a":[],"b":[["0.24641332","0"],["0.24637641","49860"]]}}}
1633806869.4110668: {"ch":"orderbook/full","update":{"DCRETH":{"t":1633806869370,"s":499156,"a":[],"b":[["0.035988","0.553"]]}}}
1633806869.416791: {"ch":"orderbook/full","update":{"XVSUSDT":{"t":1633806869360,"s":484003,"a":[],"b":[["28.0188","2.014"],["28.0142","0"],["27.9941","22.945"],["27.9879","0"]]}}}
1633806869.515918: {"ch":"orderbook/full","update":{"DCRETH":{"t":1633806869462,"s":499157,"a":[],"b":[["0.035989","4.250"],["0.035987","0"]]}}}
1633806869.52311: {"ch":"orderbook/full","update":{"EOSUSDT":{"t":1633806869506,"s":1876151,"a":[],"b":[["4.96831","2543.89"],["4.96418","0"]]}}}
1633806869.620181: {"ch":"orderbook/full","update":{"DCRETH":{"t":1633806869566,"s":499158,"a":[],"b":[["0.035988","0"]]}}}
1633806869.6227179: {"ch":"orderbook/full","update":{"EOSUSDT":{"t":1633806869544,"s":1876152,"a":[],"b":[["4.97978","31.66"],["4.97972","0"]]}}}
1633806869.731106: {"ch":"orderbook/full","update":{"EOSUSDT":{"t":1633806869704,"s":1876153,"a":[["4.98170","0"],["4.98288","100.26"]],"b":[["4.97983","31.66"],["4.97978","0"]]}}}
1633806869.739639: {"ch":"orderbook/full","update":{"DOGEUSDT":{"t":1633806869694,"s":1308158,"a":[],"b":[["0.24740252","129030"],["0.24734245","0"]]}}}
1633806869.8133981: {"ch":"orderbook/full","update":{"DCRETH":{"t":1633806869767,"s":499159,"a":[],"b":[["0.035990","0.108"]]}}}
1633806869.8147368: {"ch":"orderbook/full","update":{"NEOBTC":{"t":1633806869799,"s":1498418,"a":[["0.0027292","1063.16"],["0.0028988","0"]],"b":[]}}}
1633806869.823277: {"ch":"orderbook/full","update":{"USDTUSDP":{"t":1633806869767,"s":384606,"a":[["1.100000","6.34"]],"b":[["0.900000","15.72"]]}}}
1633806869.823404: {"ch":"orderbook/full","update":{"DOGEUSDT":{"t":1633806869781,"s":1308159,"a":[["0.25005098","363370"],["0.25024755","0"],["0.25105393","442130"],["0.25107660","0"]],"b":[]}}}
1633806869.823482: {"ch":"orderbook/full","update":{"EOSUSDT":{"t":1633806869824,"s":1876154,"a":[["4.98170","100.26"],["4.98288","0"],["5.04062","0"],["5.04402","0"],["5.20948","0"],["5.26216","43331.32"],["5.32092","0"],["5.35308","59703.38"]],"b":[["4.97983","0"],["4.97978","31.66"],["4.92287","0"],["4.92188","0"],["4.92088","0"]]}}}
1633806869.9159732: {"ch":"orderbook/full","update":{"DCRETH":{"t":1633806869863,"s":499160,"a":[],"b":[["0.035991","4.250"],["0.035989","0"]]}}}
1633806869.921867: {"ch":"orderbook/full","update":{"DOGEUSDT":{"t":1633806869885,"s":1308160,"a":[["0.25105393","0"],["0.25105864","442120"],["0.25115543","0"],["0.25116588","381420"],["0.25177341","148520"],["0.25207936","0"],["0.25252624","0"],["0.25254238","423690"],["0.25273344","0"],["0.25274218","453820"],["0.25296986","0"],["0.25299231","473920"],["0.25318733","0"],["0.25320242","457340"],["0.25339058","0"],["0.25340216","337010"],["0.25353615","0"],["0.25355441","426330"],["0.25455239","0"],["0.25456912","388890"],["0.25470328","0"],["0.25471165","371000"],["0.25478458","0"],["0.25479708","443880"],["0.25504789","0"],["0.25507069","344210"]],"b":[]}}}
1633806869.984318: {"ch":"ticker/1s","data":{"NEOBTC":{"t":1633806869841,"a":"0.0008790","A":"18.89","b":"0.0008781","B":"17.00","o":"0.0008662","c":"0.0008785","h":"0.0009067","l":"0.0008475","v":"155805.16","q":"136.162210880","p":"0.0000123","P":"1.419995382128839","L":1417984717}}}
1633806869.98441: {"ch":"ticker/1s","data":{"DCRETH":{"t":1633806869938,"a":"0.036752","A":"0.448","b":"0.035991","B":"4.250","o":"0.035004","c":"0.036373","h":"0.036686","l":"0.035072","v":"8.326","q":"0.297986431","p":"0.001369","P":"3.910981602102617","L":1417957304}}}
1633806869.984451: {"ch":"ticker/1s","data":{"XVSUSDT":{"t":1633806869439,"a":"28.0481","A":"0.063","b":"28.0188","B":"2.014","o":"28.7985","c":"27.9280","h":"28.5542","l":"27.6611","v":"7.058","q":"197.8450039","p":"-0.8705","P":"-3.022726878136014","L":1417859101}}}
1633806869.9844842: {"ch":"ticker/1s","data":{"EOSUSDT":{"t":1633806869842,"a":"4.98086","A":"26.49","b":"4.97986","B":"791.67","o":"4.71891","c":"4.98523","h":"5.06033","l":"4.57171","v":"7224629.96","q":"34899840.7456554","p":"0.26632","P":"5.643676187933230","L":1417984568}}}
1633806870.025208: {"ch":"orderbook/full","update":{"DCRETH":{"t":1633806869974,"s":499161,"a":[],"b":[["0.035992","0.129"],["0.035990","0"]]}}}
1633806870.025296: {"ch":"orderbook/full","update":{"ATOMBCH":{"t":1633806870016,"s":274293,"a":[["0.1702148","0.15"]],"b":[]}}}
1633806870.032217: {"ch":"orderbook/full","update":{"EOSUSDT":{"t":1633806870013,"s":1876155,"a":[],"b":[["4.97986","31.67"],["4.97978","0"],["4.97970","2236.47"],["4.30138","5.17"]]}}}
1633806870.0323331: {"ch":"orderbook/full","update":{"DOGEUSDT":{"t":1633806870029,"s":1308161,"a":[["0.24933052","101030"],["0.24934531","0"],["0.25028121","459880"],["0.25028814","0"],["0.25083107","442520"],["0.25085326","0"],["0.25095866","423970"],["0.25097435","0"],["0.25108136","362030"],["0.25110746","0"]],"b":[]}}}
1633806870.125472: {"ch":"orderbook/full","update":{"DCRETH":{"t":1633806870071,"s":499162,"a":[],"b":[["0.035993","4.250"],["0.035991","0"]]}}}
1633806870.125597: {"ch":"orderbook/full","update":{"XVSUSDT":{"t":1633806870129,"s":484004,"a":[],"b":[["28.0188","0"],["27.9941","0"],["27.9888","2.014"],["27.9872","22.945"],["27.9706","0"],["27.9656","19.022"],["27.9610","0"],["27.9547","109.088"]]}}}
1633806870.125692: {"ch":"orderbook/full","update":{"NEOBTC":{"t":1633806870092,"s":1498419,"a":[],"b":[["0.0008741","0"],["0.0008731","96.00"]]}}}
1633806870.125746: {"ch":"orderbook/full","update":{"HTBTC":{"t":1633806870115,"s":660783,"a":[["0.00014703","4561.05"],["0.00014727","0"]],"b":[]}}}
1633806870.128961: {"ch":"orderbook/full","update":{"EOSUSDT":{"t":1633806870111,"s":1876156,"a":[["4.98076","26.49"],["4.98086","0"],["4.98170","0"],["4.98250","100.26"],["4.98251","63.97"],["4.98291","760.00"],["5.02768","0"],["5.02836","79.54"]],"b":[["4.97970","2204.81"],["4.97955","31.66"]]}}}
1633806870.143453: {"ch":"orderbook/full","update":{"DOGEUSDT":{"t":1633806870097,"s":1308162,"a":[["0.25028121","0"],["0.25028461","459870"],["0.25083107","0"],["0.25083743","442510"],["0.25095866","0"],["0.25096377","423960"],["0.25105864","0"],["0.25106387","442110"],["0.25108136","0"],["0.25108638","362020"]],"b":[]}}}
1633806870.210474: {"ch":"orderbook/full","update":{"DCRETH":{"t":1633806870205,"s":499163,"a":[],"b":[["0.035992","0"]]}}}
1633806870.2178628: {"ch":"orderbook/full","update":{"XVSUSDT":{"t":1633806870199,"s":484005,"a":[],"b":[["27.9800","0"],["27.9741","0"],["27.9736","63.003"],["27.9579","113.816"],["27.9547","0"],["27.9478","109.088"],["27.9454","0"],["27.9057","0"],["27.8966","102.335"],["27.8940","249.028"],["27.8780","0"],["27.8388","168.599"],["27.7963","0"],["27.7677","199.881"],["27.7431","0"],["27.7314","221.917"],["27.6884","0"],["27.6724","293.088"]]}}}
1633806870.218582: {"ch":"orderbook/full","update":{"NEOBTC":{"t":1633806870141,"s":1498420,"a":[["0.0008830","24.00"],["0.0008831","898.64"],["0.0027292","0"],["0.0028656","1063.16"]],"b":[]}}}
1633806870.234244: {"ch":"orderbook/full","update":{"EOSUSDT":{"t":1633806870231,"s":1876157,"a":[["4.98052","26.49"],["4.98076","0"],["4.98249","100.26"],["4.98250","0"],["5.04042","16381.41"],["5.04410","29154.10"]],"b":[["4.97986","791.67"],["4.97970","551.22"],["4.97955","0"],["4.97939","31.66"],["4.97804","1653.54"],["4.97509","0"],["4.97311","1450.34"],["4.92307","13206.04"],["4.92208","19348.42"],["4.92108","3831.85"]]}}}
1633806870.234453: {"ch":"orderbook/full","update":{"DOGEUSDT":{"t":1633806870187,"s":1308163,"a":[],"b":[["0.24725410","22000"],["0.24721891","0"]]}}}
1633806870.311379: {"ch":"orderbook/full","update":{"DCRETH":{"t":1633806870265,"s":499164,"a":[],"b":[["0.035994","0.024"]]}}}
1633806870.3235042: {"ch":"orderbook/full","update":{"XVSUSDT":{"t":1633806870294,"s":484006,"a":[["28.0620","60.540"],["28.0679","0"],["28.0730","107.095"],["28.0765","0"]],"b":[]}}}
1633806870.323652: {"ch":"orderbook/full","update":{"NEOBTC":{"t":1633806870333,"s":1498421,"a":[["0.0008830","0"],["0.0008831","922.64"],["0.0009666","793.22"],["0.0009725","0"]],"b":[["0.0008741","24.00"],["0.0008731","72.00"]]}}}
1633806870.323742: {"ch":"orderbook/full","update":{"HTBTC":{"t":1633806870325,"s":660784,"a":[["0.00014703","0"],["0.00014734","4561.05"],["0.00022821","0"],["0.00022890","6848.62"],["0.00025500","8802.07"],["0.00025580","0"],["0.00026779","11985.76"],["0.00026823","0"]],"b":[["0.00014152","76.34"],["0.00014149","0"]]}}}
1633806870.357208: {"ch":"orderbook/full","update":{"EOSUSDT":{"t":1633806870332,"s":1876158,"a":[["4.98983","1053.61"],["4.99022","1019.31"],["4.99079","0"],["4.99172","0"]],"b":[["4.97986","31.67"],["4.97258","2317.39"],["4.97049","0"],["4.86466","0"],["4.84712","17800.28"]]}}}
1633806870.3573298: {"ch":"orderbook/full","update":{"USDTUSDP":{"t":1633806870274,"s":384607,"a":[["1.100000","5.50"]],"b":[["0.900000","14.88"]]}}}
1633806870.3573718: {"ch":"orderbook/full","update":{"DOGEUSDT":{"t":1633806870323,"s":1308164,"a":[],"b":[["0.24762224","0"],["0.24760118","46400"]]}}}
1633806870.414484: {"ch":"orderbook/full","update":{"DCRETH":{"t":1633806870389,"s":499165,"a":[],"b":[["0.035995","4.250"],["0.035993","0"],["0.035988","4.523"],["0.035986","0"]]}}}
1633806870.4229052: {"ch":"orderbook/full","update":{"XVSUSDT":{"t":1633806870359,"s":484007,"a":[["28.0867","98.436"],["28.0908","0"],["28.1221","105.569"],["28.1411","0"]],"b":[]}}}
1633806870.5150878: {"ch":"orderbook/full","update":{"DCRETH":{"t":1633806870468,"s":499166,"a":[],"b":[["0.035996","0.029"],["0.035994","0"]]}}}
1633806870.528509: {"ch":"orderbook/full","update":{"XVSUSDT":{"t":1633806870456,"s":484008,"a":[["28.1738","207.692"],["28.1829","0"],["28.3023","262.137"],["28.3155","0"]],"b":[]}}}
1633806870.528646: {"ch":"orderbook/full","update":{"NEOBTC":{"t":1633806870531,"s":1498422,"a":[],"b":[["0.0008779","0"],["0.0008778","3.54"]]}}}
1633806870.528712: {"ch":"orderbook/full","update":{"EOSUSDT":{"t":1633806870519,"s":1876159,"a":[],"b":[["4.97986","791.67"],["4.95680","4676.44"],["4.93737","0"]]}}}
1633806870.5372438: {"ch":"orderbook/full","update":{"DOGEUSDT":{"t":1633806870457,"s":1308165,"a":[["0.24990369","343330"],["0.24990824","0"],["0.25010183","424620"],["0.25011396","0"],["0.25019379","409280"],["0.25020386","0"]],"b":[]}}}
1633806870.614671: {"ch":"orderbook/full","update":{"DCRETH":{"t":1633806870569,"s":499167,"a":[],"b":[["0.035997","4.250"],["0.035995","0"]]}}}
1633806870.6172109: {"ch":"orderbook/full","update":{"XVSUSDT":{"t":1633806870594,"s":484009,"a":[["28.0620","0"],["28.0673","60.540"],["28.1221","0"],["28.1323","105.569"],["28.3023","0"],["28.3105","262.137"],["28.4873","411.194"],["28.5072","0"]],"b":[["27.9240","102.335"],["27.8966","0"],["27.8665","168.599"],["27.8388","0"],["27.7842","199.881"],["27.7677","0"]]}}}
1633806870.6256871: {"ch":"orderbook/full","update":{"NEOBTC":{"t":1633806870589,"s":1498423,"a":[["0.0008831","898.64"],["0.0008832","135.18"]],"b":[]}}}
1633806870.6258152: {"ch":"orderbook/full","update":{"HTBTC":{"t":1633806870554,"s":660785,"a":[["0.00025500","0"],["0.00025582","8802.07"],["0.00026779","0"],["0.00026825","11985.76"]],"b":[]}}}
1633806870.6258938: {"ch":"orderbook/full","update":{"DOGEUSDT":{"t":1633806870622,"s":1308166,"a":[["0.24845225","90410"],["0.24853191","0"],["0.24933052","0"],["0.24933708","101020"],["0.24984793","0"],["0.24985069","182460"],["0.24990369","0"],["0.24990537","343320"],["0.24998330","0"],["0.24998632","476020"],["0.25010183","0"],["0.25011325","424600"],["0.25019379","0"],["0.25020170","409260"],["0.25028461","0"],["0.25028836","459860"],["0.25083743","0"],["0.25084585","442500"],["0.25096377","0"],["0.25096749","423950"],["0.25108638","0"],["0.25109190","362010"]],"b":[]}}}
1633806870.731589: {"ch":"orderbook/full","update":{"DCRETH":{"t":1633806870665,"s":499168,"a":[],"b":[["0.035998","0.034"],["0.035996","0"]]}}}
1633806870.731717: {"ch":"orderbook/full","update":{"XVSUSDT":{"t":1633806870659,"s":484010,"a":[],"b":[["27.7416","221.917"],["27.7314","0"]]}}}
1633806870.731783: {"ch":"orderbook/full","update":{"EOSUSDT":{"t":1633806870650,"s":1876160,"a":[["4.99777","2721.68"],["5.00204","0"]],"b":[]}}}
1633806870.731839: {"ch":"orderbook/full","update":{"DOGEUSDT":{"t":1633806870711,"s":1308167,"a":[["0.24990537","0"],["0.24992093","343300"],["0.24998632","0"],["0.24999605","476000"],["0.25011325","0"],["0.25012554","424580"],["0.25020170","0"],["0.25020986","409250"],["0.25028836","0"],["0.25029449","459850"],["0.25084585","0"],["0.25085995","442470"],["0.25096749","0"],["0.25097941","423930"],["0.25106387","0"],["0.25106882","442100"],["0.25109190","0"],["0.25110068","362000"]],"b":[]}}}
1633806870.814019: {"ch":"orderbook/full","update":{"DCRETH":{"t":1633806870768,"s":499169,"a":[],"b":[["0.035999","0.070"],["0.035997","0"]]}}}
1633806870.8208241: {"ch":"orderbook/full","update":{"XVSUSDT":{"t":1633806870792,"s":484011,"a":[],"b":[["27.9988","2.014"],["27.9959","22.945"],["27.9888","0"],["27.9872","0"],["27.9789","63.003"],["27.9736","0"],["27.9624","113.816"],["27.9579","0"]]}}}
1633806870.820982: {"ch":"orderbook/full","update":{"NEOBTC":{"t":1633806870781,"s":1498424,"a":[["0.0008831","922.64"],["0.0008832","111.18"]],"b":[]}}}
1633806870.821054: {"ch":"orderbook/full","update":{"EOSUSDT":{"t":1633806870800,"s":1876161,"a":[["5.04042","0"],["5.04410","0"]],"b":[["4.97986","31.67"],["4.92307","0"],["4.92208","0"],["4.92108","0"]]}}}
1633806870.8334222: {"ch":"orderbook/full","update":{"USDTUSDP":{"t":1633806870778,"s":384608,"a":[["1.100000","5.72"]],"b":[["0.900000","15.10"]]}}}
1633806870.929198: {"ch":"orderbook/full","update":{"DCRETH":{"t":1633806870879,"s":499170,"a":[],"b":[["0.036000","0.039"],["0.035998","0"]]}}}
1633806870.929321: {"ch":"orderbook/full","update":{"ATOMBCH":{"t":1633806870878,"s":274294,"a":[["0.0568306","0"],["0.0568505","0.88"]],"b":[]}}}
1633806870.9293828: {"ch":"orderbook/full","update":{"XVSUSDT":{"t":1633806870860,"s":484012,"a":[],"b":[["27.9541","109.088"],["27.9478","0"],["27.9406","102.335"],["27.9240","0"]]}}}
1633806870.990496: {"ch":"ticker/1s","data":{"ATOMBCH":{"t":1633806870940,"a":"0.0568505","A":"0.88","b":"0.0566552","B":"1.05","o":"0.0698883","c":"0.0585227","h":"0.0698883","l":"0.0585227","v":"0.72","q":"0.042136344","p":"-0.0113656","P":"-16.26252176687657","L":1417149989}}}
1633806870.990592: {"ch":"ticker/1s","data":{"DCRETH":{"t":1633806870938,"a":"0.036752","A":"0.448","b":"0.036000","B":"0.039","o":"0.035004","c":"0.036373","h":"0.036686","l":"0.035072","v":"8.326","q":"0.297986431","p":"0.001369","P":"3.910981602102617","L":1417957304}}}
1633806870.9906318: {"ch":"ticker/1s","data":{"XVSUSDT":{"t":1633806870940,"a":"28.0481","A":"0.063","b":"27.9988","B":"2.014","o":"28.7985","c":"27.9280","h":"28.5542","l":"27.6611","v":"7.058","q":"197.8450039","p":"-0.8705","P":"-3.022726878136014","L":1417859101}}}
1633806870.990666: {"ch":"ticker/1s","data":{"HTBTC":{"t":1633806870644,"a":"0.00014177","A":"72.70","b":"0.00014152","B":"76.34","o":"0.00014331","c":"0.00014179","h":"0.00014449","l":"0.00014066","v":"3159.62","q":"0.4483378290","p":"-0.00000152","P":"-1.060637778242970","L":1417961502}}}
1633806870.990695: {"ch":"ticker/1s","data":{"EOSUSDT":{"t":1633806870843,"a":"4.98052","A":"26.49","b":"4.97986","B":"31.67","o":"4.71891","c":"4.98523","h":"5.06033","l":"4.57171","v":"7224629.96","q":"34899840.7456554","p":"0.26632","P":"5.643676187933230","L":1417984568}}}
1633806871.018545: {"ch":"orderbook/full","update":{"ATOMBCH":{"t":1633806871017,"s":274295,"a":[["0.1702148","0"],["0.1702373","0.13"]],"b":[["0.0170237","0.18"],["0.0170214","0"]]}}}
1633806871.0186281: {"ch":"orderbook/full","update":{"NEOBTC":{"t":1633806870973,"s":1498425,"a":[["0.0008831","898.64"],["0.0008832","135.18"]],"b":[]}}}
1633806871.029993: {"ch":"orderbook/full","update":{"DOGEUSDT":{"t":1633806871015,"s":1308168,"a":[["0.25085995","0"],["0.25088123","442440"],["0.25097941","0"],["0.25099719","423900"],["0.25110068","0"],["0.25111254","361980"],["0.25116588","0"],["0.25117861","381400"],["0.25254238","0"],["0.25257146","423640"],["0.25274218","0"],["0.25276194","453780"],["0.25299231","0"],["0.25302533","473860"],["0.25320242","0"],["0.25322768","457290"],["0.25340216","0"],["0.25341905","336990"],["0.25355441","0"],["0.25358214","426290"],["0.25456912","0"],["0.25459739","388840"],["0.25471165","0"],["0.25472693","370980"],["0.25479708","0"],["0.25482305","443830"],["0.25507069","0"],["0.25510416","344170"]],"b":[]}}}
1633806871.1258812: {"ch":"orderbook/full","update":{"XVSUSDT":{"t":1633806871092,"s":484013,"a":[],"b":[["27.8717","168.599"],["27.8665","0"],["27.7920","199.881"],["27.7842","0"]]}}}
1633806871.1381109: {"ch":"orderbook/full","update":{"EOSUSDT":{"t":1633806871123,"s":1876162,"a":[["4.98170","100.26"],["4.98249","0"]],"b":[["4.97946","31.66"],["4.97939","0"],["4.17106","10.67"]]}}}
1633806871.138263: {"ch":"orderbook/full","update":{"DOGEUSDT":{"t":1633806871123,"s":1308169,"a":[["0.25012554","0"],["0.25013263","424570"],["0.25020986","0"],["0.25021610","409240"]],"b":[]}}}
1633806871.2462249: {"ch":"orderbook/full","update":{"XVSUSDT":{"t":1633806871158,"s":484014,"a":[],"b":[["27.6845","293.088"],["27.6724","0"]]}}}
1633806871.246351: {"ch":"orderbook/full","update":{"NEOBTC":{"t":1633806871167,"s":1498426,"a":[["0.0008831","922.64"],["0.0008832","111.18"]],"b":[]}}}
1633806871.2464159: {"ch":"orderbook/full","update":{"HTBTC":{"t":1633806871136,"s":660786,"a":[["0.00022890","0"],["0.00022981","6848.62"]],"b":[]}}}
1633806871.246471: {"ch":"orderbook/full","update":{"EOSUSDT":{"t":1633806871217,"s":1876163,"a":[["4.98052","0"],["4.98060","26.49"],["4.98532","0"],["4.98652","1612.05"],["4.98674","0"],["4.98838","1851.98"],["5.03381","0"],["5.04002","16381.41"],["5.04380","29154.10"],["5.04629","6980.08"]],"b":[["4.97946","0"],["4.97940","31.66"],["4.97680","0"],["4.97311","2901.94"],["4.92267","13206.04"],["4.92168","19348.42"],["4.92068","3831.85"]]}}}
1633806871.3442729: {"ch":"orderbook/full","update":{"EOSUSDT":{"t":1633806871319,"s":1876164,"a":[["4.99206","240.00"],["4.99257","0"],["5.02752","79.56"],["5.02836","0"],["5.13856","0"],["5.14992","24335.25"]],"b":[["4.97745","0"],["4.97649","133.97"],["4.97633","0"],["4.97550","80.39"],["4.96153","0"],["4.95979","1900.00"]]}}}
1633806871.3444648: {"ch":"orderbook/full","update":{"USDTUSDP":{"t":1633806871283,"s":384609,"a":[["1.100000","6.28"]],"b":[["0.900000","15.66"]]}}}
1633806871.445945: {"ch":"orderbook/full","update":{"EOSUSDT":{"t":1633806871425,"s":1876165,"a":[],"b":[["4.85853","17800.28"],["4.84712","0"],["4.79727","7565.88"],["4.58107","0"]]}}}
1633806871.446089: {"ch":"orderbook/full","update":{"NEOBTC":{"t":1633806871365,"s":1498427,"a":[],"b":[["0.0008741","0"],["0.0008732","72.00"],["0.0008731","24.00"]]}}}
1633806871.551031: {"ch":"orderbook/full","update":{"EOSUSDT":{"t":1633806871532,"s":1876166,"a":[["4.99421","1982.70"],["4.99621","0"]],"b":[["4.90804","0"],["4.89154","11826.73"],["4.85853","0"],["4.83639","17800.28"],["4.79727","0"],["4.73092","7565.88"]]}}}
1633806871.643279: {"ch":"orderbook/full","update":{"NEOBTC":{"t":1633806871567,"s":1498428,"a":[["0.0008844","94.00"],["0.0008848","0"]],"b":[["0.0008732","0"],["0.0008731","96.00"]]}}}
1633806871.643378: {"ch":"orderbook/full","update":{"EOSUSDT":{"t":1633806871607,"s":1876167,"a":[["5.29169","3.05"],["5.37925","3.00"]],"b":[]}}}
1633806871.6434188: {"ch":"orderbook/full","update":{"DOGEUSDT":{"t":1633806871624,"s":1308170,"a":[["0.24809895","46370"],["0.24813479","0"]],"b":[]}}}
1633806871.739965: {"ch":"orderbook/full","update":{"EOSUSDT":{"t":1633806871716,"s":1876168,"a":[["5.02901","3.21"],["5.04973","0"],["5.06995","8821.94"],["5.11657","3.16"],["5.20413","3.10"]],"b":[]}}}
1633806871.8279018: {"ch":"orderbook/full","update":{"NEOBTC":{"t":1633806871814,"s":1498429,"a":[["0.0008831","898.64"],["0.0008841","72.00"],["0.0008842","24.00"],["0.0008844","0"],["0.0008848","94.00"]],"b":[["0.0008769","43.00"],["0.0008763","0"],["0.0008741","24.00"],["0.0008731","166.00"],["0.0008721","0"]]}}}
1633806871.8314219: {"ch":"orderbook/full","update":{"EOSUSDT":{"t":1633806871828,"s":1876169,"a":[["4.99364","700.00"],["4.99418","0"],["4.99620","3471.01"],["4.99655","960.00"],["4.99731","0"],["5.00064","0"],["5.04002","0"],["5.04380","0"],["5.33667","59703.38"],["5.35308","0"]],"b":[["4.92267","0"],["4.92168","0"],["4.92068","0"]]}}}
1633806871.854558: {"ch":"orderbook/full","update":{"USDTUSDP":{"t":1633806871787,"s":384610,"a":[["1.100000","6.02"]],"b":[["0.900000","15.40"]]}}}
1633806871.945788: {"ch":"orderbook/full","update":{"NEOBTC":{"t":1633806871921,"s":1498430,"a":[["0.0009666","0"],["0.0009854","793.22"],["0.0028656","0"],["0.0029619","1063.16"]],"b":[["0.0008779","3.54"],["0.0008778","0"]]}}}
1633806871.986593: {"ch":"ticker/1s","data":{"EOSUSDT":{"t":1633806871942,"a":"4.98034","A":"26.49","b":"4.97786","B":"31.66","o":"4.71891","c":"4.98523","h":"5.06033","l":"4.57171","v":"7224629.96","q":"34899840.7456554","p":"0.26632","P":"5.643676187933230","L":1417984568}}}
1633806871.988241: {"ch":"orderbook/full","update":{"EOSUSDT":{"t":1633806871934,"s":1876170,"a":[["4.98034","26.49"],["4.98060","0"],["4.98388","140.81"],["4.98479","0"],["4.98684","1851.98"],["4.98834","142.44"],["4.98837","430.00"],["4.98838","0"],["4.99003","0"],["4.99091","0"],["4.99094","1809.39"],["4.99138","0"],["4.99293","0"],["4.99501","4232.22"],["4.99521","0"],["4.99622","1561.88"],["4.99938","0"],["5.00041","0"],["5.00229","0"],["5.00394","2666.25"],["5.00634","2649.95"],["5.00729","0"],["5.00880","0"],["5.01084","2725.57"],["5.01162","0"],["5.01193","30.00"],["5.01456","2566.48"],["5.01529","0"],["5.01551","2343.99"],["5.01577","0"],["5.02285","3409.00"],["5.02385","4391.27"],["5.02655","79.57"],["5.02752","0"],["5.02793","0"],["5.03863","0"],["5.04004","6877.74"],["5.05650","0"],["5.06241","9862.48"]],"b":[["4.97986","0"],["4.97970","0"],["4.97969","0"],["4.97940","0"],["4.97930","0"],["4.97805","0"],["4.97804","0"],["4.97803","0"],["4.97802","0"],["4.97794","0"],["4.97786","31.66"],["4.97784","0"],["4.97708","441.03"],["4.97701","0"],["4.97700","31.67"],["4.97682","0"],["4.97667","1653.78"],["4.97666","1102.44"],["4.97665","1102.33"],["4.97664","0"],["4.97650","58.80"],["4.97649","0"],["4.97639","80.37"],["4.97625","0"],["4.97605","0"],["4.97602","0"],["4.97601","0"],["4.97591","0"],["4.97588","0"],["4.97569","471.98"],["4.97550","0"],["4.97544","133.97"],["4.97501","0"],["4.97498","0"],["4.97497","112.99"],["4.97490","939.97"],["4.97485","0"],["4.97482","664.26"],["4.97478","1723.94"],["4.97464","0"],["4.97460","0"],["4.97456","0"],["4.97425","0"],["4.97404","0"],["4.97402","0"],["4.97401","154.19"],["4.97382","990.87"],["4.97375","0"],["4.97360","0"],["4.97356","0"],["4.97354","0"],["4.97330","0"],["4.97318","457.24"],["4.97315","0"],["4.97301","4365.30"],["4.97298","0"],["4.97286","1627.26"],["4.97278","109.20"],["4.97263","139.05"],["4.97258","1811.59"],["4.97250","1299.34"],["4.97211","0"],["4.97208","0"],["4.97203","0"],["4.97186","2176.72"],["4.97182","128.58"],["4.97105","1783.00"],["4.97102","1619.89"],["4.97078","0"],["4.97072","0"],["4.97059","30.00"],["4.97053","159.94"],["4.97036","1582.24"],["4.97026","1635.38"],["4.97003","420.00"],["4.97002","2320.00"],["4.96994","0"],["4.96974","0"],["4.96971","0"],["4.96939","914.11"],["4.96932","445.04"],["4.96906","1654.12"],["4.96881","0"],["4.96872","2317.39"],["4.96862","240.00"],["4.96851","0"],["4.96825","700.00"],["4.96824","2783.94"],["4.96783","3358.01"],["4.96772","5385.22"],["4.96770","1988.36"],["4.96741","0"],["4.96703","2530.31"],["4.96688","1754.33"],["4.96668","0"],["4.96642","1833.38"],["4.96640","0"],["4.96592","0"],["4.96556","0"],["4.96513","3281.80"],["4.96404","3470.64"],["4.96374","1696.31"],["4.96237","0"],["4.96105","4226.52"],["4.96104","2728.74"],["4.95777","4983.12"],["4.95758","0"],["4.95731","2692.59"],["4.95447","0"],["4.95211","2447.99"],["4.94970","0"],["4.94560","6107.92"],["4.94303","0"],["4.94231","0"],["4.93807","18972.33"],["4.93367","6751.44"],["4.93203","5483.57"],["4.93003","0"],["4.92425","0"],["4.91967","9113.33"],["4.89492","9955.22"],["4.73092","0"],["4.71603","7565.88"]]}}}
1633806872.048782: {"ch":"orderbook/full","update":{"ATOMBCH":{"t":1633806872019,"s":274296,"a":[["0.1702148","0.18"],["0.1702373","0"]],"b":[["0.0170237","0"],["0.0170214","0.16"]]}}}
1633806872.053804: {"ch":"orderbook/full","update":{"NEOBTC":{"t":1633806872033,"s":1498431,"a":[["0.0008840","72.00"],["0.0008841","24.00"],["0.0008842","0"]],"b":[["0.0008745","24.00"],["0.0008741","0"],["0.0007282","0"],["0.0007215","557.30"]]}}}
1633806872.0741608: {"ch":"orderbook/full","update":{"EOSUSDT":{"t":1633806872035,"s":1876171,"a":[["4.97961","26.49"],["4.98008","100.26"],["4.98009","760.00"],["4.98033","100.26"],["4.98034","0"],["4.98038","63.97"],["4.98170","0"],["4.98251","0"],["4.98289","0"],["4.98291","0"],["4.98704","1698.95"],["4.98746","473.14"],["4.98833","420.00"],["4.98919","0"],["4.98945","0"],["4.98977","1348.10"],["4.99121","1476.43"],["4.99138","240.00"],["4.99167","0"],["4.99206","0"],["4.99221","0"],["4.99279","700.00"],["4.99308","1561.88"],["4.99321","0"],["4.99364","0"],["4.99501","0"],["4.99549","960.00"],["4.99622","0"],["4.99655","0"],["4.99850","1846.40"],["4.99945","2385.82"],["5.00142","1900.00"],["5.00336","0"],["5.01551","0"],["5.02185","2343.99"],["5.02326","79.62"],["5.02655","0"]],"b":[["4.97786","0"],["4.97725","31.66"],["4.97708","0"],["4.97700","0"],["4.97667","0"],["4.97666","0"],["4.97665","0"],["4.97650","0"],["4.97639","0"],["4.97593","31.67"],["4.97592","58.80"],["4.97569","0"],["4.97545","1654.12"],["4.97508","0"],["4.97497","0"],["4.97490","0"],["4.97478","0"],["4.97383","1102.87"],["4.97351","113.02"],["4.97346","0"],["4.97316","0"],["4.97311","1451.60"],["4.97302","471.98"],["4.97293","80.43"],["4.97271","939.97"],["4.97258","0"],["4.97214","1723.94"],["4.97186","422.89"],["4.97181","0"],["4.97094","1636.04"],["4.97071","1811.59"],["4.97066","943.91"],["4.97059","0"],["4.97037","430.00"],["4.97023","0"],["4.96939","2667.94"],["4.96854","0"],["4.96831","0"],["4.96772","2814.85"],["4.96771","30.00"],["4.96770","0"],["4.96743","0"],["4.96735","1451.14"],["4.96695","0"],["4.96586","1796.32"],["4.96513","960.00"],["4.96495","4392.23"],["4.96458","2486.04"],["4.96374","0"],["4.96356","1988.91"],["4.96288","2322.09"],["4.96261","0"],["4.96259","2570.37"],["4.96252","2.41"],["4.96207","0"],["4.96173","2543.89"],["4.96122","2399.48"],["4.96104","0"],["4.96074","1696.31"],["4.95979","0"],["4.95804","21913.36"],["4.95801","1900.00"],["4.95758","2728.74"],["4.95731","0"],["4.95680","0"],["4.95503","2321.80"],["4.95459","0"],["4.95253","2692.59"],["4.95115","3704.80"],["4.94885","21396.67"],["4.94560","0"],["4.93901","0"],["4.93757","4676.44"],["4.93367","0"],["4.93152","6107.92"],["4.92610","13521.49"],["4.91967","0"],["4.91669","6751.44"],["4.90219","9113.33"],["4.89492","0"],["4.89154","0"],["4.86670","11826.73"],["4.83639","0"],["4.78082","17800.28"],["4.71603","0"],["4.58108","7565.88"]]}}}
1633806872.081627: {"ch":"orderbook/full","update":{"DOGEUSDT":{"t":1633806871981,"s":1308171,"a":[["0.24989653","343340"],["0.24992093","0"]],"b":[]}}}
1633806872.1128619: {"ch":"orderbook/full","update":{"DCRETH":{"t":1633806872092,"s":499171,"a":[],"b":[["0.035984","2.261"],["0.035972","0"]]}}}
1633806872.1397812: {"ch":"orderbook/full","update":{"NEOBTC":{"t":1633806872134,"s":1498432,"a":[["0.0008841","0"],["0.0008842","24.00"]],"b":[]}}}
1633806872.154839: {"ch":"orderbook/full","update":{"EOSUSDT":{"t":1633806872134,"s":1876172,"a":[["4.97870","26.49"],["4.97913","100.26"],["4.97914","760.00"],["4.97960","100.26"],["4.97961","0"],["4.98008","0"],["4.98033","0"],["4.98171","0"],["4.98653","142.44"],["4.98712","436.89"],["4.98790","1157.30"],["4.98834","0"],["4.98895","1831.91"],["4.98898","2688.84"],["4.98973","1721.26"],["4.98983","0"],["4.99071","1865.82"],["4.99094","0"],["4.99175","0"],["4.99201","0"],["4.99206","1765.74"],["4.99291","0"],["4.99308","0"],["4.99320","2665.05"],["4.99387","1809.39"],["4.99526","2385.82"],["4.99544","0"],["4.99721","0"],["4.99848","1561.88"],["4.99945","0"],["5.00716","4132.71"],["5.01456","0"],["5.01521","0"],["5.02061","2566.48"],["5.02326","0"],["5.02397","79.61"]],"b":[["4.97725","0"],["4.97651","31.66"],["4.97592","0"],["4.97544","0"],["4.97489","58.80"],["4.97451","133.97"],["4.97337","80.42"],["4.97293","0"],["4.96862","0"],["4.96825","0"],["4.96772","3054.85"],["4.96672","0"],["4.96642","0"],["4.96610","700.00"],["4.96513","0"],["4.96294","960.00"],["4.96287","1833.38"],["4.95933","4564.84"],["4.94491","0"],["4.93843","22719.70"],["4.93718","0"],["4.92968","25946.41"],["4.88946","0"],["4.87639","25733.89"]]}}}
1633806872.2301729: {"ch":"orderbook/full","update":{"NEOBTC":{"t":1633806872162,"s":1498433,"a":[["0.0008840","0"],["0.0008842","96.00"]],"b":[["0.0008745","0"],["0.0008741","24.00"],["0.0008731","72.00"],["0.0008721","94.00"]]}}}
1633806872.2434828: {"ch":"orderbook/full","update":{"EOSUSDT":{"t":1633806872223,"s":1876173,"a":[["4.97834","100.26"],["4.97835","26.49"],["4.97870","0"],["4.97913","0"],["4.98199","391.27"],["4.98257","147.22"],["4.98299","433.01"],["4.98377","110.49"],["4.98499","2939.91"],["4.98550","0"],["4.98622","685.96"],["4.98686","143.85"],["4.98693","0"],["4.98790","2176.61"],["4.98819","2448.24"],["4.98838","1583.32"],["4.98848","0"],["4.98922","0"],["4.98985","0"],["4.99005","240.00"],["4.99022","0"],["4.99067","0"],["4.99124","700.00"],["4.99138","0"],["4.99279","0"],["4.99387","0"],["4.99427","960.00"],["4.99511","1809.39"],["4.99548","1561.88"],["4.99549","0"],["4.99848","0"],["4.99850","0"],["4.99890","1846.40"],["5.00618","2649.95"],["5.00634","0"],["5.01411","2566.48"],["5.02061","0"],["5.02397","0"],["5.02461","79.60"],["5.03982","16381.41"],["5.06119","29154.10"],["5.06721","12807.83"]],"b":[["4.97651","0"],["4.97633","31.66"],["4.97398","80.41"],["4.97337","0"],["4.97278","0"],["4.97095","109.20"],["4.96532","1833.38"],["4.96287","0"],["4.92248","13206.04"],["4.92148","19348.42"],["4.91955","3831.85"],["4.90134","9955.22"]]}}}
1633806872.2529721: {"ch":"orderbook/full","update":{"DOGEUSDT":{"t":1633806872204,"s":1308172,"a":[["0.24886183","24610"],["0.24890441","0"]],"b":[]}}}
1633806872.345592: {"ch":"orderbook/full","update":{"EOSUSDT":{"t":1633806872335,"s":1876174,"a":[["4.97781","26.49"],["4.97834","0"],["4.97835","0"],["4.97913","100.26"],["4.98197","140.81"],["4.98388","0"],["4.98509","1698.95"],["4.98590","473.14"],["4.98703","1072.37"],["4.98704","0"],["4.98746","0"],["4.98913","0"],["4.99251","1809.39"],["4.99494","1561.88"],["4.99511","0"],["4.99548","0"]],"b":[["4.97633","0"],["4.97628","31.66"],["4.97401","611.43"],["4.97398","0"],["4.97383","0"],["4.97318","0"],["4.97272","1103.23"],["4.97243","80.44"],["4.97105","0"],["4.96910","1783.00"],["4.96728","0"],["4.96454","0"],["4.96313","2595.81"],["4.95842","2559.31"],["4.95801","0"],["4.95758","0"],["4.95607","1900.00"],["4.95397","2728.74"],["4.95201","0"],["4.93870","4542.71"],["4.93152","0"],["4.92182","6107.92"],["4.90219","0"],["4.88737","9113.33"],["4.86670","0"],["4.85159","11826.73"],["4.78082","0"],["4.72150","17800.28"]]}}}
1633806872.3538618: {"ch":"orderbook/full","update":{"USDTUSDP":{"t":1633806872293,"s":384611,"a":[["1.100000","6.03"]],"b":[["0.900000","15.41"]]}}}
1633806872.354432: {"ch":"orderbook/full","update":{"DOGEUSDT":{"t":1633806872297,"s":1308173,"a":[["0.24932470","101030"],["0.24933708","0"],["0.24983710","182470"],["0.24985069","0"],["0.24996314","476070"],["0.24999605","0"],["0.25026411","459910"],["0.25029449","0"],["0.25081779","442550"],["0.25088123","0"],["0.25094979","423980"],["0.25099719","0"],["0.25106150","442120"],["0.25106882","0"],["0.25108910","362020"],["0.25111254","0"],["0.25114302","381450"],["0.25117861","0"],["0.25247197","423800"],["0.25257146","0"],["0.25267962","453930"],["0.25276194","0"],["0.25289635","474100"],["0.25302533","0"],["0.25314276","457440"],["0.25322768","0"],["0.25334040","337090"],["0.25341905","0"],["0.25347416","426470"],["0.25358214","0"],["0.25447379","389030"],["0.25459739","0"],["0.25466582","371070"],["0.25472693","0"],["0.25475973","443940"],["0.25482305","0"],["0.25494449","344380"],["0.25510416","0"]],"b":[]}}}
1633806872.426346: {"ch":"orderbook/full","update":{"EOSUSDT":{"t":1633806872424,"s":1876175,"a":[["4.97949","63.97"],["4.98038","0"],["4.98497","129.87"],["4.98926","240.00"],["4.98986","0"],["4.99005","0"],["4.99092","1809.39"],["4.99251","0"],["4.99350","960.00"],["4.99427","0"],["4.99494","0"],["4.99520","6136.68"],["4.99921","0"],["4.99965","1900.00"],["5.00142","0"],["5.02461","0"],["5.02529","79.59"]],"b":[["4.97628","0"],["4.97585","31.66"],["4.97489","0"],["4.97440","58.80"],["4.97401","154.19"],["4.97301","4822.54"],["4.97286","0"],["4.97283","0"],["4.97271","1020.40"],["4.97263","0"],["4.97243","0"],["4.97186","0"],["4.97182","0"],["4.97165","1627.26"],["4.97100","139.05"],["4.97036","0"],["4.97024","422.89"],["4.96939","914.11"],["4.96859","128.58"],["4.96817","1582.24"],["4.96798","2171.87"],["4.96772","2814.85"],["4.96711","240.00"],["4.96659","1753.83"],["4.96610","0"],["4.96559","700.00"],["4.96313","0"],["4.96259","0"],["4.96122","0"],["4.95884","2595.81"],["4.95524","2570.37"],["4.95496","2399.48"]]}}}
1633806872.42717: {"ch":"orderbook/full","update":{"DOGEUSDT":{"t":1633806872364,"s":1308174,"a":[["0.25008117","424660"],["0.25013263","0"],["0.25018150","409300"],["0.25021610","0"]],"b":[]}}}
1633806872.669652: {"ch":"orderbook/full","update":{"NEOBTC":{"t":1633806872488,"s":1498434,"a":[],"b":[["0.0008780","3.54"],["0.0008779","0"]]}}}
1633806872.6697862: {"ch":"orderbook/full","update":{"EOSUSDT":{"t":1633806872533,"s":1876176,"a":[["4.98165","988.60"],["4.98197","1752.86"],["4.98216","1083.81"],["4.98299","2289.11"],["4.98499","0"],["4.98540","0"],["4.98585","1053.61"],["4.98652","0"],["4.98790","1123.00"],["4.98909","2368.39"],["4.99052","700.00"],["4.99124","0"],["4.99226","0"],["4.99284","1561.88"],["4.99520","4574.80"],["5.00037","3221.49"],["5.00614","0"],["5.02329","79.62"],["5.02529","0"],["5.03491","6980.08"],["5.04629","0"]],"b":[["4.97311","0"],["4.97301","1374.43"],["4.97271","939.97"],["4.97261","80.44"],["4.97201","1773.87"],["4.97173","1674.24"],["4.96928","1451.60"],["4.96906","0"],["4.96803","2645.54"],["4.96688","0"],["4.96672","1654.12"],["4.96532","0"],["4.96462","1754.33"],["4.96304","2619.72"],["4.96253","1833.38"],["4.96144","0"],["4.96074","0"],["4.96023","1696.31"],["4.95804","0"],["4.95553","3485.93"],["4.95381","21913.23"],["4.94623","0"]]}}}
1633806872.670109: {"ch":"orderbook/full","update":{"DOGEUSDT":{"t":1633806872473,"s":1308175,"a":[["0.24996314","0"],["0.24996771","476060"],["0.25008117","0"],["0.25009468","424630"],["0.25018150","0"],["0.25018729","409290"],["0.25026411","0"],["0.25026706","459900"],["0.25081779","0"],["0.25082459","442540"],["0.25106150","0"],["0.25106830","442110"],["0.25247197","0"],["0.25248138","423790"],["0.25267962","0"],["0.25269224","453910"],["0.25289635","0"],["0.25290933","474080"],["0.25314276","0"],["0.25315417","457420"],["0.25334040","0"],["0.25335166","337080"],["0.25347416","0"],["0.25348409","426450"],["0.25447379","0"],["0.25449408","389000"],["0.25466582","0"],["0.25467248","371060"],["0.25475973","0"],["0.25476474","443930"],["0.25494449","0"],["0.25496259","344360"]],"b":[]}}}
1633806872.678455: {"ch":"orderbook/full","update":{"HTBTC":{"t":1633806872542,"s":660787,"a":[],"b":[["0.00014092","0"],["0.00014076","1442.46"]]}}}
1633806872.678586: {"ch":"orderbook/full","update":{"EOSUSDT":{"t":1633806872634,"s":1876177,"a":[["4.97768","26.49"],["4.97781","0"],["4.98099","147.22"],["4.98158","433.01"],["4.98257","0"],["4.98299","1856.10"],["4.98653","1974.35"],["4.98752","1721.26"],["4.98785","1865.82"],["4.98872","240.00"],["4.98895","0"],["4.98926","0"],["4.98973","0"],["4.99071","0"],["4.99907","11253.00"],["5.00501","0"]],"b":[["4.94582","29.81"],["4.91669","0"],["4.90477","6751.44"],["4.88737","0"],["4.87605","9113.33"],["4.85159","0"],["4.83587","11826.73"],["4.72150","0"],["4.67346","17800.28"]]}}}
1633806872.678792: {"ch":"orderbook/full","update":{"DOGEUSDT":{"t":1633806872559,"s":1308176,"a":[["0.24989653","0"],["0.24989814","343330"]],"b":[]}}}
1633806872.735872: {"ch":"orderbook/full","update":{"NEOBTC":{"t":1633806872645,"s":1498435,"a":[["0.0008791","2.96"],["0.0008792","0"]],"b":[]}}}
1633806872.7531672: {"ch":"orderbook/full","update":{"DOGEUSDT":{"t":1633806872679,"s":1308177,"a":[["0.25082459","0"],["0.25082493","442530"]],"b":[]}}}
1633806872.753268: {"ch":"orderbook/full","update":{"EOSUSDT":{"t":1633806872727,"s":1876178,"a":[["4.98608","2448.24"],["4.98721","1019.31"],["4.98790","103.69"],["4.98819","0"],["4.98821","1348.10"],["4.98977","0"],["4.98983","700.00"],["4.99052","0"],["4.99719","9017.29"],["5.00321","0"],["5.01561","5886.22"],["5.02594","0"]],"b":[["4.96772","0"],["4.96493","2814.85"]]}}}
1633806872.828672: {"ch":"orderbook/full","update":{"EOSUSDT":{"t":1633806872817,"s":1876179,"a":[["4.97755","26.49"],["4.97768","0"],["4.98166","1737.51"],["4.98299","5252.43"],["4.98517","143.85"],["4.98599","0"],["4.98686","0"],["4.98694","0"],["4.99020","1982.70"],["4.99421","0"]],"b":[["4.97585","0"],["4.97579","31.66"],["4.97026","0"],["4.97002","0"],["4.96872","0"],["4.96839","1635.38"],["4.96803","0"],["4.96802","2320.00"],["4.96672","3971.51"],["4.96499","1833.38"],["4.96404","6116.18"],["4.96294","0"],["4.96253","0"],["4.96219","960.00"]]}}}
1633806872.834443: {"ch":"orderbook/full","update":{"DOGEUSDT":{"t":1633806872829,"s":1308178,"a":[["0.24989814","0"],["0.24990614","343320"],["0.24996771","0"],["0.24997585","476040"],["0.25009468","0"],["0.25010497","424620"],["0.25018729","0"],["0.25019388","409280"],["0.25082493","0"],["0.25083472","442520"],["0.25094979","0"],["0.25096013","423970"],["0.25106830","0"],["0.25107744","442090"],["0.25108910","0"],["0.25109443","362010"],["0.25114302","0"],["0.25114994","381440"],["0.25248138","0"],["0.25249603","423760"],["0.25269224","0"],["0.25270889","453880"],["0.25290933","0"],["0.25293058","474040"],["0.25315417","0"],["0.25316818","457400"],["0.25335166","0"],["0.25336752","337050"],["0.25348409","0"],["0.25350291","426420"],["0.25449408","0"],["0.25451838","388960"],["0.25467248","0"],["0.25468207","371050"],["0.25476474","0"],["0.25477250","443920"],["0.25496259","0"],["0.25499457","344320"]],"b":[]}}}
1633806872.922282: {"ch":"orderbook/full","update":{"EOSUSDT":{"t":1633806872922,"s":1876180,"a":[["4.98166","0"],["4.98277","1737.51"],["4.98336","1851.98"],["4.98482","142.44"],["4.98653","1831.91"],["4.98684","0"],["4.98983","0"],["4.99039","700.00"],["5.03982","0"],["5.06119","0"],["5.06721","0"],["5.08213","13225.51"],["5.09373","0"],["5.32091","59703.38"],["5.33667","0"],["5.45540","93429.49"],["5.47143","0"]],"b":[["4.96910","0"],["4.96709","1783.00"],["4.92248","0"],["4.92148","0"],["4.91955","0"]]}}}
1633806872.923132: {"ch":"orderbook/full","update":{"USDTUSDP":{"t":1633806872893,"s":384612,"a":[["1.100000","6.47"]],"b":[["0.900000","15.85"]]}}}
1633806872.930038: {"ch":"orderbook/full","update":{"DOGEUSDT":{"t":1633806872896,"s":1308179,"a":[["0.25010497","0"],["0.25010698","424610"],["0.25019388","0"],["0.25019691","409270"],["0.25026706","0"],["0.25027242","459890"],["0.25083472","0"],["0.25083924","442510"],["0.25096013","0"],["0.25096361","423960"],["0.25249603","0"],["0.25250349","423750"],["0.25270889","0"],["0.25271504","453870"],["0.25293058","0"],["0.25293994","474020"],["0.25316818","0"],["0.25317398","457390"],["0.25350291","0"],["0.25351166","426410"],["0.25451838","0"],["0.25452739","388950"],["0.25468207","0"],["0.25468634","371040"],["0.25477250","0"],["0.25477578","443910"],["0.25499457","0"],["0.25500826","344300"]],"b":[]}}}
1633806872.981733: {"ch":"ticker/1s","data":{"EOSUSDT":{"t":1633806872941,"a":"4.97755","A":"26.49","b":"4.97593","B":"31.67","o":"4.71891","c":"4.98523","h":"5.06033","l":"4.57171","v":"7224629.96","q":"34899840.7456554","p":"0.26632","P":"5.643676187933230","L":1417984568}}}
1633806873.016913: {"ch":"orderbook/full","update":{"ATOMBCH":{"t":1633806873019,"s":274297,"a":[["0.1702148","0"],["0.1702227","0.17"]],"b":[["0.0170222","0.11"],["0.0170214","0"]]}}}
1633806873.022753: {"ch":"orderbook/full","update":{"EOSUSDT":{"t":1633806873022,"s":1876181,"a":[["4.98537","436.89"],["4.98607","430.00"],["4.98712","0"],["4.98785","0"],["4.98837","0"],["4.98871","1809.39"],["4.98921","1476.43"],["4.99018","1865.82"],["4.99092","0"],["4.99121","0"],["5.00136","2539.23"],["5.00808","0"],["5.01041","30.00"],["5.01193","0"],["5.01577","4391.27"],["5.02385","0"],["5.02834","6877.74"],["5.04004","0"],["5.06192","12807.83"]],"b":[["4.96861","1654.12"],["4.96672","2317.39"],["4.96336","1696.31"],["4.96023","0"],["4.95851","2728.74"],["4.95397","0"]]}}}
1633806873.1141171: {"ch":"orderbook/full","update":{"DCRETH":{"t":1633806873121,"s":499172,"a":[],"b":[["0.033669","0"],["0.033580","242.087"],["0.032574","0"],["0.032480","250.620"],["0.031870","0"],["0.031786","276.700"]]}}}
1633806873.129099: {"ch":"orderbook/full","update":{"EOSUSDT":{"t":1633806873095,"s":1876182,"a":[["4.98398","1881.33"],["4.98498","2688.84"],["4.98745","0"],["4.98898","0"],["4.99253","3471.01"],["4.99620","0"]],"b":[["4.97585","31.66"],["4.97579","0"]]}}}
1633806873.219319: {"ch":"orderbook/full","update":{"BORUSDT":{"t":1633806873163,"s":56258,"a":[["100000.000","0.0013"]],"b":[["0.001","1026.5999"]]}}}
1633806873.235035: {"ch":"orderbook/full","update":{"EOSUSDT":{"t":1633806873233,"s":1876183,"a":[["4.98769","1865.82"],["4.99018","0"],["4.99270","960.00"],["4.99350","0"],["5.00127","3908.49"],["5.00767","0"],["5.26216","0"],["5.29036","43331.32"],["5.32091","0"],["5.33762","59703.38"]],"b":[["4.97592","31.66"],["4.97585","0"],["4.94582","0"],["4.93249","6107.92"],["4.92182","0"],["4.91690","6751.44"],["4.90477","0"]]}}}
1633806873.333015: {"ch":"orderbook/full","update":{"EOSUSDT":{"t":1633806873276,"s":1876184,"a":[["5.04071","16381.41"],["5.05898","29154.10"]],"b":[["4.94362","29.83"],["4.91749","13206.04"],["4.91649","19348.42"],["4.91549","3831.85"]]}}}
1633806873.421537: {"ch":"orderbook/full","update":{"DCRETH":{"t":1633806873366,"s":499173,"a":[],"b":[["0.033670","0"]]}}}
1633806873.4232209: {"ch":"orderbook/full","update":{"EOSUSDT":{"t":1633806873435,"s":1876185,"a":[["4.98626","2356.20"],["4.98998","0"],["4.99619","5911.59"],["5.00128","0"],["5.04537","29154.10"],["5.05898","0"]],"b":[]}}}
1633806873.428169: {"ch":"orderbook/full","update":{"USDTUSDP":{"t":1633806873397,"s":384613,"a":[["1.100000","6.11"]],"b":[["0.900000","15.49"]]}}}
1633806873.513472: {"ch":"orderbook/full","update":{"DCRETH":{"t":1633806873450,"s":499174,"a":[],"b":[["0.033655","2.297"]]}}}
1633806873.5287302: {"ch":"orderbook/full","update":{"EOSUSDT":{"t":1633806873529,"s":1876186,"a":[["4.98917","1765.74"],["4.99206","0"],["5.08213","0"],["5.09425","13225.51"]],"b":[]}}}
1633806873.630302: {"ch":"orderbook/full","update":{"DOGEUSDT":{"t":1633806873614,"s":1308180,"a":[["0.24809895","0"],["0.24812438","46370"]],"b":[]}}}
1633806873.72141: {"ch":"orderbook/full","update":{"XVSUSDT":{"t":1633806873715,"s":484015,"a":[["28.0811","20.380"],["28.0897","0"]],"b":[]}}}
1633806873.721537: {"ch":"orderbook/full","update":{"NEOBTC":{"t":1633806873657,"s":1498436,"a":[["0.0008791","0"],["0.0008792","2.96"]],"b":[]}}}
1633806873.731915: {"ch":"orderbook/full","update":{"EOSUSDT":{"t":1633806873728,"s":1876187,"a":[["4.98167","103.77"],["4.98570","1471.17"],["4.98790","0"],["4.98881","2636.36"],["4.99017","2109.03"],["4.99250","0"],["4.99397","2419.88"],["4.99926","0"]],"b":[["4.97598","31.66"],["4.97592","0"],["4.96559","0"],["4.96505","700.00"]]}}}
1633806873.827275: {"ch":"orderbook/full","update":{"EOSUSDT":{"t":1633806873816,"s":1876188,"a":[["5.00181","2714.98"],["5.00799","0"]],"b":[["4.94967","4542.71"],["4.93870","0"]]}}}
1633806873.934479: {"ch":"orderbook/full","update":{"EOSUSDT":{"t":1633806873893,"s":1876189,"a":[["4.98933","1561.88"],["4.99284","0"],["4.99495","4821.90"],["5.00539","0"],["5.04071","0"],["5.04537","0"],["5.33762","0"],["5.35271","59703.38"],["5.45540","0"],["5.47645","93429.49"]],"b":[["4.91749","0"],["4.91649","0"],["4.91549","0"]]}}}
1633806873.9355452: {"ch":"orderbook/full","update":{"USDTUSDP":{"t":1633806873901,"s":384614,"a":[["1.100000","6.34"]],"b":[["0.900000","15.72"]]}}}
1633806873.980771: {"ch":"ticker/1s","data":{"EOSUSDT":{"t":1633806873942,"a":"4.97755","A":"26.49","b":"4.97598","B":"31.66","o":"4.71891","c":"4.98523","h":"5.06033","l":"4.57171","v":"7224629.96","q":"34899840.7456554","p":"0.26632","P":"5.643676187933230","L":1417984568}}}
1633806874.0398269: {"ch":"orderbook/full","update":{"ATOMBCH":{"t":1633806874020,"s":274298,"a":[["0.1702183","0.15"],["0.1702227","0"]],"b":[["0.0170222","0"],["0.0170218","0.15"]]}}}
1633806874.039979: {"ch":"orderbook/full","update":{"EOSUSDT":{"t":1633806874031,"s":1876190,"a":[["4.97746","26.49"],["4.97755","0"]],"b":[["4.97622","760.00"],["4.97402","1103.37"],["4.97272","0"]]}}}
1633806874.120359: {"ch":"orderbook/full","update":{"EOSUSDT":{"t":1633806874126,"s":1876191,"a":[["5.05371","8821.94"],["5.06995","0"]],"b":[["4.97611","31.66"],["4.97598","0"],["4.97301","457.24"],["4.97261","0"],["4.97201","2691.06"],["4.97198","80.45"],["4.96771","0"],["4.96607","30.00"],["4.94756","4676.44"],["4.93757","0"],["4.92617","6751.44"],["4.91690","0"]]}}}
1633806874.2227788: {"ch":"orderbook/full","update":{"HTBTC":{"t":1633806874219,"s":660788,"a":[["0.00022339","6848.62"],["0.00022981","0"],["0.00025408","8802.07"],["0.00025582","0"],["0.00026735","11985.76"],["0.00026825","0"]],"b":[]}}}
1633806874.2229362: {"ch":"orderbook/full","update":{"EOSUSDT":{"t":1633806874200,"s":1876192,"a":[["4.99107","1846.40"],["4.99206","2666.25"],["4.99890","0"],["5.00394","0"]],"b":[]}}}
1633806874.229024: {"ch":"orderbook/full","update":{"DOGEUSDT":{"t":1633806874218,"s":1308181,"a":[["0.24809564","46370"],["0.24812438","0"],["0.24990167","343330"],["0.24990614","0"],["0.24997158","476050"],["0.24997585","0"],["0.25009911","424630"],["0.25010698","0"],["0.25018781","409290"],["0.25019691","0"],["0.25026887","459900"],["0.25027242","0"],["0.25082637","442530"],["0.25083924","0"],["0.25095249","423980"],["0.25096361","0"],["0.25107274","442100"],["0.25107744","0"],["0.25248763","423780"],["0.25250349","0"],["0.25270055","453890"],["0.25271504","0"],["0.25291901","474060"],["0.25293994","0"],["0.25316091","457410"],["0.25317398","0"],["0.25335908","337070"],["0.25336752","0"],["0.25349216","426440"],["0.25351166","0"],["0.25450618","388980"],["0.25452739","0"],["0.25467695","371050"],["0.25468634","0"],["0.25476822","443930"],["0.25477578","0"],["0.25497749","344340"],["0.25500826","0"]],"b":[]}}}
1633806874.319752: {"ch":"orderbook/full","update":{"XVSUSDT":{"t":1633806874297,"s":484016,"a":[],"b":[["27.9682","113.816"],["27.9624","0"]]}}}
1633806874.319881: {"ch":"orderbook/full","update":{"NEOBTC":{"t":1633806874320,"s":1498437,"a":[],"b":[["0.0008780","0"],["0.0008779","3.54"]]}}}
1633806874.32459: {"ch":"orderbook/full","update":{"HTBTC":{"t":1633806874319,"s":660789,"a":[["0.00025408","0"],["0.00025449","8802.07"]],"b":[]}}}
1633806874.324727: {"ch":"orderbook/full","update":{"EOSUSDT":{"t":1633806874329,"s":1876193,"a":[["5.03861","16381.41"],["5.04427","29154.10"]],"b":[["4.97619","31.66"],["4.97611","0"],["4.97546","551.61"],["4.97494","441.29"],["4.92009","9955.22"],["4.91839","13206.04"],["4.91739","19348.42"],["4.91639","3831.85"],["4.90134","0"]]}}}
1633806874.33285: {"ch":"orderbook/full","update":{"DOGEUSDT":{"t":1633806874306,"s":1308182,"a":[["0.25009911","0"],["0.25010009","424620"],["0.25335908","0"],["0.25336060","337060"],["0.25497749","0"],["0.25498056","344330"]],"b":[]}}}
1633806874.433646: {"ch":"orderbook/full","update":{"HTBTC":{"t":1633806874434,"s":660790,"a":[["0.00022339","0"],["0.00022413","6848.62"]],"b":[["0.00014054","5257.85"],["0.00014038","0"]]}}}
1633806874.433793: {"ch":"orderbook/full","update":{"EOSUSDT":{"t":1633806874433,"s":1876194,"a":[],"b":[["4.97597","330.97"],["4.94362","0"]]}}}
1633806874.433863: {"ch":"orderbook/full","update":{"USDTUSDP":{"t":1633806874405,"s":384615,"a":[["1.100000","5.59"]],"b":[["0.900000","14.97"]]}}}
1633806874.433918: {"ch":"orderbook/full","update":{"DOGEUSDT":{"t":1633806874412,"s":1308183,"a":[["0.24997158","0"],["0.24997422","476040"],["0.25018781","0"],["0.25019002","409280"],["0.25082637","0"],["0.25083066","442520"],["0.25107274","0"],["0.25107638","442090"],["0.25248763","0"],["0.25249394","423770"],["0.25270055","0"],["0.25272153","453850"],["0.25291901","0"],["0.25296460","473970"],["0.25316091","0"],["0.25318681","457360"],["0.25336060","0"],["0.25338759","337030"],["0.25349216","0"],["0.25353216","426370"],["0.25450618","0"],["0.25454870","388920"],["0.25467695","0"],["0.25469706","371020"],["0.25476822","0"],["0.25478409","443900"],["0.25498056","0"],["0.25503951","344260"]],"b":[]}}}
1633806874.5397491: {"ch":"orderbook/full","update":{"EOSUSDT":{"t":1633806874530,"s":1876195,"a":[["4.98608","0"],["4.98832","2448.24"],["4.99306","2649.95"],["4.99462","5136.52"],["5.00618","0"],["5.01041","0"],["5.01084","0"],["5.01220","30.00"]],"b":[["4.97645","31.66"],["4.97619","0"],["4.97198","0"],["4.97193","80.45"],["4.96900","1783.00"],["4.96810","240.00"],["4.96725","30.00"],["4.96711","0"],["4.96709","0"],["4.96607","0"],["4.96557","700.00"],["4.96505","0"],["4.94344","29.83"]]}}}
1633806874.5442529: {"ch":"orderbook/full","update":{"DOGEUSDT":{"t":1633806874525,"s":1308184,"a":[["0.24809564","0"],["0.24813852","46370"],["0.24845225","0"],["0.24853150","90410"],["0.24932470","0"],["0.24933688","101020"],["0.24983710","0"],["0.24985619","182460"],["0.24990167","0"],["0.24991943","343310"],["0.24997422","0"],["0.24999177","476010"],["0.25010009","0"],["0.25012125","424590"],["0.25019002","0"],["0.25020447","409260"],["0.25026887","0"],["0.25027959","459880"],["0.25083066","0"],["0.25085308","442490"],["0.25095249","0"],["0.25097240","423950"],["0.25107638","0"],["0.25108564","442080"],["0.25109443","0"],["0.25110392","362000"],["0.25114994","0"],["0.25116095","381420"],["0.25249394","0"],["0.25252914","423710"],["0.25272153","0"],["0.25273352","453830"],["0.25296460","0"],["0.25297623","473950"],["0.25318681","0"],["0.25319299","457350"],["0.25338759","0"],["0.25339178","337020"],["0.25353216","0"],["0.25354182","426350"],["0.25454870","0"],["0.25455398","388910"],["0.25478409","0"],["0.25478884","443890"],["0.25503951","0"],["0.25504789","344240"]],"b":[]}}}
1633806874.616837: {"ch":"orderbook/full","update":{"DCRETH":{"t":1633806874632,"s":499175,"a":[],"b":[["0.036001","4.547"],["0.035999","0"],["0.035988","0"]]}}}
1633806874.624567: {"ch":"orderbook/full","update":{"EOSUSDT":{"t":1633806874595,"s":1876196,"a":[],"b":[["4.97660","31.66"],["4.97645","0"]]}}}
1633806874.632284: {"ch":"orderbook/full","update":{"DOGEUSDT":{"t":1633806874572,"s":1308185,"a":[["0.24886183","0"],["0.24889426","24610"]],"b":[]}}}
1633806874.713241: {"ch":"orderbook/full","update":{"DCRETH":{"t":1633806874673,"s":499176,"a":[],"b":[["0.036002","0.044"],["0.036000","0"]]}}}
1633806874.723234: {"ch":"orderbook/full","update":{"NEOBTC":{"t":1633806874685,"s":1498438,"a":[],"b":[["0.0008731","166.00"],["0.0008721","0"]]}}}
1633806874.723358: {"ch":"orderbook/full","update":{"HTBTC":{"t":1633806874641,"s":660791,"a":[],"b":[["0.00014146","0"],["0.00014143","65.67"]]}}}
1633806874.7352781: {"ch":"orderbook/full","update":{"DOGEUSDT":{"t":1633806874714,"s":1308186,"a":[["0.24991943","0"],["0.24992032","343300"],["0.25085308","0"],["0.25085348","442480"],["0.25455398","0"],["0.25455805","388900"]],"b":[]}}}
1633806874.830631: {"ch":"orderbook/full","update":{"DCRETH":{"t":1633806874792,"s":499177,"a":[],"b":[["0.035983","0"],["0.035972","7.643"],["0.035674","0"],["0.035673","0"],["0.035643","33.000"],["0.035642","55.148"]]}}}
1633806874.830723: {"ch":"orderbook/full","update":{"NEOBTC":{"t":1633806874799,"s":1498439,"a":[],"b":[["0.0007282","557.30"],["0.0007215","0"]]}}}
1633806874.842772: {"ch":"orderbook/full","update":{"EOSUSDT":{"t":1633806874833,"s":1876197,"a":[["4.97746","0"],["4.97770","26.49"],["5.00240","2566.48"],["5.00603","2343.99"],["5.01411","0"],["5.02185","0"]],"b":[["4.97660","0"],["4.97628","31.66"],["4.97622","0"],["4.97401","0"],["4.97301","0"],["4.97201","0"],["4.97165","0"],["4.97104","917.19"],["4.97102","0"],["4.97101","2385.30"],["4.97060","1627.26"],["4.96902","1619.89"]]}}}
1633806874.84287: {"ch":"orderbook/full","update":{"DOGEUSDT":{"t":1633806874826,"s":1308187,"a":[["0.24844951","90410"],["0.24853150","0"]],"b":[]}}}
1633806874.9366012: {"ch":"orderbook/full","update":{"NEOBTC":{"t":1633806874877,"s":1498440,"a":[],"b":[["0.0008731","72.00"],["0.0008721","94.00"]]}}}
1633806874.955539: {"ch":"orderbook/full","update":{"EOSUSDT":{"t":1633806874925,"s":1876198,"a":[["4.97756","26.49"],["4.97770","0"],["5.01125","0"],["5.03861","0"],["5.04427","0"],["5.08351","13225.51"],["5.09425","0"]],"b":[["4.97628","0"],["4.97586","31.66"],["4.97210","80.44"],["4.97193","0"],["4.96861","0"],["4.96810","0"],["4.96695","240.00"],["4.96662","1654.12"],["4.96336","0"],["4.95977","1696.31"],["4.95851","0"],["4.95489","2728.74"],["4.94756","0"],["4.93903","4676.44"],["4.92009","0"],["4.91839","0"],["4.91739","0"],["4.91639","0"],["4.89995","9955.22"]]}}}
1633806874.9558148: {"ch":"orderbook/full","update":{"USDTUSDP":{"t":1633806874910,"s":384616,"a":[["1.100000","5.55"]],"b":[["0.900000","14.93"]]}}}
1633806874.955883: {"ch":"orderbook/full","update":{"DOGEUSDT":{"t":1633806874918,"s":1308188,"a":[["0.25027959","0"],["0.25028679","459870"],["0.25085348","0"],["0.25087382","442450"],["0.25097240","0"],["0.25099303","423910"],["0.25108564","0"],["0.25108729","442070"],["0.25110392","0"],["0.25111312","361980"],["0.25116095","0"],["0.25117611","381400"],["0.25252914","0"],["0.25256409","423650"],["0.25273352","0"],["0.25275604","453790"],["0.25297623","0"],["0.25301962","473870"],["0.25319299","0"],["0.25322271","457300"],["0.25339178","0"],["0.25341575","336990"],["0.25354182","0"],["0.25357621","426300"],["0.25455805","0"],["0.25459214","388850"],["0.25469706","0"],["0.25472157","370990"],["0.25478884","0"],["0.25481777","443840"],["0.25504789","0"],["0.25509798","344180"]],"b":[]}}}
1633806874.982033: {"ch":"ticker/1s","data":{"DCRETH":{"t":1633806874839,"a":"0.036752","A":"0.448","b":"0.036002","B":"0.044","o":"0.035004","c":"0.036373","h":"0.036686","l":"0.035072","v":"8.326","q":"0.297986431","p":"0.001369","P":"3.910981602102617","L":1417957304}}}
1633806874.982125: {"ch":"ticker/1s","data":{"EOSUSDT":{"t":1633806874946,"a":"4.97756","A":"26.49","b":"4.97597","B":"330.97","o":"4.71891","c":"4.98523","h":"5.06033","l":"4.57171","v":"7224629.96","q":"34899840.7456554","p":"0.26632","P":"5.643676187933230","L":1417984568}}}
1633806875.0231721: {"ch":"orderbook/full","update":{"ATOMBCH":{"t":1633806875021,"s":274299,"a":[["0.1702183","0.16"]],"b":[["0.0170218","0.13"]]}}}
1633806875.023306: {"ch":"orderbook/full","update":{"NEOBTC":{"t":1633806874998,"s":1498441,"a":[["0.0009462","793.22"],["0.0009854","0"],["0.0027605","1063.16"],["0.0029619","0"]],"b":[]}}}
1633806875.027924: {"ch":"orderbook/full","update":{"EOSUSDT":{"t":1633806875035,"s":1876199,"a":[["4.97741","100.26"],["4.97742","26.49"],["4.97756","0"],["4.97913","0"],["4.98697","2463.07"],["4.99097","0"],["5.00622","18334.01"],["5.05371","0"],["5.06495","8821.94"],["5.08351","0"],["5.09661","13225.51"]],"b":[["4.97440","0"],["4.97390","58.80"],["4.96557","0"],["4.96498","700.00"],["4.96385","2595.81"],["4.96271","1696.31"],["4.96172","2570.37"],["4.95977","0"],["4.95884","0"],["4.95831","2728.74"],["4.95524","0"],["4.95489","0"],["4.92617","0"],["4.91699","28265.02"],["4.91156","9955.22"],["4.89995","0"]]}}}
1633806875.11159: {"ch":"orderbook/full","update":{"DCRETH":{"t":1633806875093,"s":499178,"a":[["0.041784","329.777"],["0.041898","0"]],"b":[]}}}
1633806875.1478798: {"ch":"orderbook/full","update":{"EOSUSDT":{"t":1633806875132,"s":1876200,"a":[["4.97741","0"],["4.97742","0"],["4.97753","26.49"],["4.97913","100.26"],["5.01055","3409.00"],["5.02285","0"]],"b":[["4.97619","760.00"],["4.97599","31.66"],["4.97586","0"],["4.96695","0"],["4.96620","240.00"],["4.94344","0"],["4.94302","29.83"]]}}}
1633806875.148087: {"ch":"orderbook/full","update":{"DOGEUSDT":{"t":1633806875122,"s":1308189,"a":[["0.24880425","142410"],["0.24892864","0"]],"b":[]}}}
1633806875.2296479: {"ch":"orderbook/full","update":{"HTBTC":{"t":1633806875150,"s":660792,"a":[["0.00034077","46776.23"],["0.00034401","0"]],"b":[]}}}
1633806875.2297778: {"ch":"orderbook/full","update":{"EOSUSDT":{"t":1633806875234,"s":1876201,"a":[],"b":[["4.97605","31.66"],["4.97599","0"],["4.97401","154.19"],["4.97400","457.24"],["4.97101","1773.87"],["4.94091","6107.92"],["4.93249","0"]]}}}
1633806875.3235588: {"ch":"orderbook/full","update":{"HTBTC":{"t":1633806875317,"s":660793,"a":[["0.00022413","0"],["0.00022970","6848.62"],["0.00025449","0"],["0.00025522","8802.07"],["0.00026735","0"],["0.00026790","11985.76"],["0.00034077","0"],["0.00034324","46776.23"]],"b":[]}}}
1633806875.325993: {"ch":"orderbook/full","update":{"EOSUSDT":{"t":1633806875291,"s":1876202,"a":[["5.03811","16381.41"],["5.04526","29154.10"]],"b":[["4.91809","13206.04"],["4.91709","19348.42"],["4.91609","3831.85"]]}}}
1633806875.410187: {"ch":"orderbook/full","update":{"DCRETH":{"t":1633806875406,"s":499179,"a":[],"b":[["0.036002","0"]]}}}
1633806875.418672: {"ch":"orderbook/full","update":{"EOSUSDT":{"t":1633806875379,"s":1876203,"a":[["4.99810","2481.59"],["5.00309","0"]],"b":[]}}}
1633806875.426555: {"ch":"orderbook/full","update":{"USDTUSDP":{"t":1633806875414,"s":384617,"a":[["1.100000","6.44"]],"b":[["0.900000","15.82"]]}}}
1633806875.530227: {"ch":"orderbook/full","update":{"DCRETH":{"t":1633806875463,"s":499180,"a":[],"b":[["0.036002","0.018"]]}}}
1633806875.5303411: {"ch":"orderbook/full","update":{"EOSUSDT":{"t":1633806875485,"s":1876204,"a":[],"b":[["4.97614","31.66"],["4.97605","0"],["4.97272","917.19"],["4.97201","1773.87"],["4.97104","0"],["4.97101","0"]]}}}
1633806875.628926: {"ch":"orderbook/full","update":{"EOSUSDT":{"t":1633806875621,"s":1876205,"a":[["5.08290","13225.51"],["5.09661","0"],["5.45578","93429.49"],["5.47645","0"]],"b":[["4.96696","1754.33"],["4.96462","0"]]}}}
1633806875.7273228: {"ch":"orderbook/full","update":{"DOGEUSDT":{"t":1633806875694,"s":1308190,"a":[["0.25108729","0"],["0.25111260","442030"],["0.25111312","0"],["0.25117611","0"],["0.25118684","361880"],["0.25132977","381170"],["0.25256409","0"],["0.25274521","423350"],["0.25275604","0"],["0.25298868","453370"],["0.25301962","0"],["0.25320104","473530"],["0.25322271","0"],["0.25341575","0"],["0.25342531","456930"],["0.25357621","0"],["0.25359028","336760"],["0.25384843","425840"],["0.25459214","0"],["0.25472157","0"],["0.25472898","388640"],["0.25480962","370860"],["0.25481777","0"],["0.25509798","0"],["0.25511160","443330"],["0.25536605","343820"]],"b":[]}}}
1633806875.827067: {"ch":"orderbook/full","update":{"EOSUSDT":{"t":1633806875823,"s":1876206,"a":[],"b":[["4.97614","0"],["4.97606","31.66"],["4.92059","9113.33"],["4.90104","11826.73"],["4.87605","0"],["4.83587","0"]]}}}
1633806875.92221: {"ch":"orderbook/full","update":{"EOSUSDT":{"t":1633806875934,"s":1876207,"a":[["4.99020","0"],["4.99218","1982.70"],["5.03811","0"],["5.04526","0"]],"b":[["4.91809","0"],["4.91709","0"],["4.91609","0"],["4.90104","0"],["4.88446","11826.73"]]}}}
1633806875.922325: {"ch":"orderbook/full","update":{"USDTUSDP":{"t":1633806875918,"s":384618,"a":[["1.100000","5.64"]],"b":[["0.900000","15.02"]]}}}
1633806875.980407: {"ch":"ticker/1s","data":{"DCRETH":{"t":1633806875538,"a":"0.036752","A":"0.448","b":"0.036002","B":"0.018","o":"0.035004","c":"0.036373","h":"0.036686","l":"0.035072","v":"8.326","q":"0.297986431","p":"0.001369","P":"3.910981602102617","L":1417957304}}}
1633806875.980496: {"ch":"ticker/1s","data":{"EOSUSDT":{"t":1633806875942,"a":"4.97753","A":"26.49","b":"4.97619","B":"760.00","o":"4.71891","c":"4.98523","h":"5.06033","l":"4.57171","v":"7224629.96","q":"34899840.7456554","p":"0.26632","P":"5.643676187933230","L":1417984568}}}
1633806876.0173: {"ch":"orderbook/full","update":{"DCRETH":{"t":1633806876028,"s":499181,"a":[["0.036781","16.000"],["0.036782","26.994"],["0.036808","0"],["0.036809","0"]],"b":[["0.033654","0"]]}}}
1633806876.022491: {"ch":"orderbook/full","update":{"ATOMBCH":{"t":1633806876026,"s":274300,"a":[["0.1702183","0.19"]],"b":[["0.0170218","0.19"]]}}}
1633806876.030793: {"ch":"orderbook/full","update":{"EOSUSDT":{"t":1633806876029,"s":1876208,"a":[["4.98165","0"],["4.98197","140.81"],["4.98295","988.60"],["4.98319","1612.05"],["5.01436","27977.16"],["5.01968","0"],["5.03881","9862.48"],["5.06241","0"]],"b":[["4.97598","1103.15"],["4.97402","0"],["4.85033","17800.28"],["4.67346","0"]]}}}
1633806876.030991: {"ch":"orderbook/full","update":{"DOGEUSDT":{"t":1633806876019,"s":1308191,"a":[["0.24984550","182470"],["0.24985619","0"],["0.24991306","343310"],["0.24992032","0"],["0.24998223","476030"],["0.24999177","0"],["0.25011311","424600"],["0.25012125","0"],["0.25019587","409270"],["0.25020447","0"]],"b":[]}}}
1633806876.128062: {"ch":"orderbook/full","update":{"EOSUSDT":{"t":1633806876130,"s":1876209,"a":[["4.98769","0"],["4.98917","0"],["4.98921","0"],["4.98990","1865.82"],["4.99053","1476.43"],["4.99213","1765.74"]],"b":[["4.96820","240.00"],["4.96620","0"],["4.96564","700.00"],["4.96498","0"]]}}}
1633806876.219604: {"ch":"orderbook/full","update":{"EOSUSDT":{"t":1633806876231,"s":1876210,"a":[["4.97753","0"],["4.97757","26.49"],["4.98821","0"],["4.98921","1348.10"],["5.00730","12110.19"],["5.01819","0"],["5.08290","0"],["5.09605","13225.51"],["5.13219","24335.25"],["5.14992","0"]],"b":[["4.97637","31.66"],["4.97606","0"],["4.97210","0"],["4.97201","1854.32"]]}}}
1633806876.22291: {"ch":"orderbook/full","update":{"DOGEUSDT":{"t":1633806876229,"s":1308192,"a":[["0.25083823","442510"],["0.25087382","0"],["0.25095926","423970"],["0.25099303","0"]],"b":[]}}}
1633806876.3122518: {"ch":"orderbook/full","update":{"DCRETH":{"t":1633806876331,"s":499182,"a":[["0.036731","8.901"],["0.036754","0"],["0.041376","329.437"],["0.041517","0"]],"b":[["0.035972","0"],["0.035904","0"],["0.035743","7.648"],["0.035643","16.000"],["0.035642","0"],["0.035560","29.388"],["0.035386","55.188"],["0.033656","17.000"],["0.033580","0"],["0.033390","242.081"],["0.032480","0"],["0.032342","250.614"],["0.031786","0"],["0.031683","276.693"],["0.031397","0"],["0.031293","241.619"],["0.031068","0"],["0.030980","254.751"],["0.030793","0"],["0.030700","242.364"]]}}}
1633806876.335639: {"ch":"orderbook/full","update":{"HTBTC":{"t":1633806876316,"s":660794,"a":[["0.00014713","4561.05"],["0.00014734","0"]],"b":[]}}}
1633806876.335774: {"ch":"orderbook/full","update":{"EOSUSDT":{"t":1633806876322,"s":1876211,"a":[["4.97757","0"],["4.97782","26.49"],["4.97960","0"],["4.98098","100.26"],["4.98199","0"],["4.98278","391.27"],["4.98622","0"],["4.98721","685.96"],["4.98821","1019.31"]],"b":[["4.97647","31.66"],["4.97637","0"],["4.97598","0"],["4.97495","1103.20"]]}}}
1633806876.4133272: {"ch":"orderbook/full","update":{"DCRETH":{"t":1633806876377,"s":499183,"a":[["0.036730","0.228"],["0.036752","0"]],"b":[["0.035743","0"],["0.035708","7.648"],["0.035643","0"],["0.035617","16.000"],["0.035560","0"],["0.035508","29.388"],["0.035386","0"],["0.035324","17.000"],["0.035323","55.188"],["0.033656","0"]]}}}
1633806876.428138: {"ch":"orderbook/full","update":{"EOSUSDT":{"t":1633806876434,"s":1876212,"a":[["4.97782","0"],["4.97823","26.49"],["4.97949","0"],["4.98003","63.97"],["4.98099","0"],["4.98158","0"],["4.98167","0"],["4.98261","103.77"],["4.98281","433.01"],["4.98284","147.22"],["4.98398","0"],["4.98482","0"],["4.98498","0"],["4.98562","1881.33"],["4.98570","0"],["4.98644","142.44"],["4.98698","2688.84"],["4.98721","0"],["4.98752","0"],["4.98768","1471.17"],["4.98820","685.96"],["4.98821","0"],["4.98872","0"],["4.98921","0"],["4.98974","1721.26"],["4.99021","1019.31"],["4.99034","240.00"],["4.99039","0"],["4.99053","0"],["4.99117","700.00"],["4.99120","1348.10"],["4.99221","1476.43"],["4.99253","0"],["4.99270","0"],["4.99350","960.00"],["4.99602","3471.01"],["5.02316","79.63"],["5.02329","0"],["5.03821","16381.41"],["5.04482","29154.10"]],"b":[["4.97688","31.66"],["4.97674","31.67"],["4.97672","760.00"],["4.97648","1103.06"],["4.97647","0"],["4.97593","0"],["4.97495","0"],["4.97450","58.80"],["4.97390","0"],["4.97181","422.89"],["4.97024","0"],["4.96872","2317.39"],["4.96772","2814.85"],["4.96672","0"],["4.96648","2322.09"],["4.96617","700.00"],["4.96564","0"],["4.96493","0"],["4.96288","0"],["4.95109","6107.92"],["4.94091","0"],["4.91869","13206.04"],["4.91769","19348.42"],["4.91669","3831.85"]]}}}
1633806876.4286048: {"ch":"orderbook/full","update":{"USDTUSDP":{"t":1633806876422,"s":384619,"a":[["1.100000","6.09"]],"b":[["0.900000","15.47"]]}}}
1633806876.4286761: {"ch":"orderbook/full","update":{"DOGEUSDT":{"t":1633806876341,"s":1308193,"a":[["0.25083823","0"],["0.25084475","442500"],["0.25095926","0"],["0.25096346","423960"]],"b":[]}}}
1633806876.526172: {"ch":"orderbook/full","update":{"EOSUSDT":{"t":1633806876526,"s":1876213,"a":[["4.97823","0"],["4.97913","0"],["4.97914","0"],["4.97925","26.49"],["4.98002","100.26"],["4.98003","0"],["4.98068","63.97"],["4.98098","0"],["4.98196","100.26"],["4.98197","0"],["4.98216","0"],["4.98277","0"],["4.98278","0"],["4.98281","0"],["4.98295","0"],["4.98299","0"],["4.98318","140.81"],["4.98319","0"],["4.98336","0"],["4.98374","391.27"],["4.98386","1083.81"],["4.98399","2289.11"],["4.98443","988.60"],["4.98472","1612.05"],["4.98489","1685.82"],["4.98509","0"],["4.98517","0"],["4.98537","0"],["4.98550","1710.51"],["4.98626","0"],["4.98653","0"],["4.98672","1737.51"],["4.98697","143.85"],["4.98714","436.89"],["4.98767","1851.98"],["4.98820","0"],["4.98832","0"],["4.98844","1831.91"],["4.98854","685.96"],["4.98881","0"],["4.98909","0"],["4.98929","2356.20"],["4.98939","1698.95"],["4.99099","2463.07"],["4.99218","0"],["4.99267","2448.24"],["4.99297","2636.36"],["4.99411","1982.70"],["4.99428","2368.39"],["4.99462","2410.95"],["5.00026","2725.57"],["5.00127","0"],["5.00886","3908.49"],["5.00920","0"],["5.01053","30.00"],["5.01220","0"],["5.01845","0"],["5.02089","0"],["5.02105","4270.16"],["5.02316","0"],["5.02423","79.61"],["5.02762","5507.50"],["5.03491","0"],["5.04214","6023.83"],["5.05275","6980.08"],["5.08993","0"],["5.10466","58821.16"],["5.14699","0"],["5.16210","88370.30"]],"b":[["4.97730","31.66"],["4.97726","760.00"],["4.97702","1654.36"],["4.97688","0"],["4.97619","0"],["4.97545","0"],["4.97541","133.97"],["4.97451","0"],["4.97307","80.43"],["4.97201","1773.87"],["4.97092","445.04"],["4.96932","0"],["4.96878","1753.83"],["4.96659","0"],["4.96573","2543.89"],["4.96359","2559.31"],["4.96173","0"],["4.95842","0"]]}}}
1633806876.632582: {"ch":"orderbook/full","update":{"HTBTC":{"t":1633806876542,"s":660795,"a":[["0.00014713","0"],["0.00014741","4561.05"]],"b":[]}}}
1633806876.643081: {"ch":"orderbook/full","update":{"EOSUSDT":{"t":1633806876633,"s":1876214,"a":[["4.97925","0"],["4.97941","26.49"],["4.98002","0"],["4.98068","0"],["4.98127","63.97"],["4.98196","0"],["4.98261","0"],["4.98282","100.26"],["4.98283","100.26"],["4.98448","103.77"],["4.98590","0"],["4.98607","0"],["4.98762","473.14"],["4.98837","430.00"],["4.98854","0"],["4.98912","685.96"],["4.98990","0"],["4.99017","0"],["4.99034","0"],["4.99090","240.00"],["4.99117","0"],["4.99168","700.00"],["4.99215","1865.82"],["4.99350","0"],["4.99356","2109.03"],["4.99429","960.00"],["4.99965","0"],["5.00141","1900.00"],["5.02423","0"],["5.02504","79.60"]],"b":[["4.97828","760.00"],["4.97804","1102.75"],["4.97803","31.66"],["4.97774","760.00"],["4.97750","31.67"],["4.97749","441.14"],["4.97730","0"],["4.97726","0"],["4.97674","0"],["4.97672","0"],["4.97648","0"],["4.97599","58.80"],["4.97546","0"],["4.97494","0"],["4.97493","917.19"],["4.97450","0"],["4.97309","80.43"],["4.97307","0"],["4.97272","0"],["4.96968","30.00"],["4.96725","0"],["4.96300","960.00"],["4.96219","0"],["4.95109","0"],["4.94070","6107.92"],["4.85033","0"],["4.83826","17800.28"]]}}}
1633806876.651368: {"ch":"orderbook/full","update":{"DOGEUSDT":{"t":1633806876550,"s":1308194,"a":[["0.24998223","0"],["0.24998552","476020"],["0.25019587","0"],["0.25020394","409260"],["0.25028679","0"],["0.25028872","459860"],["0.25084475","0"],["0.25084909","442490"]],"b":[]}}}
1633806876.718234: {"ch":"orderbook/full","update":{"DCRETH":{"t":1633806876735,"s":499184,"a":[],"b":[["0.033655","0"]]}}}
1633806876.731064: {"ch":"orderbook/full","update":{"NEOBTC":{"t":1633806876645,"s":1498442,"a":[["0.0008791","2.96"],["0.0008792","0"]],"b":[]}}}
1633806876.731193: {"ch":"orderbook/full","update":{"EOSUSDT":{"t":1633806876726,"s":1876215,"a":[["4.97941","0"],["4.97967","26.49"],["4.98374","0"],["4.98377","0"],["4.98386","0"],["4.98399","433.01"],["4.98464","391.27"],["4.98492","1083.81"],["4.98499","1856.10"],["4.98583","110.49"],["4.98585","0"],["4.98644","0"],["4.98762","0"],["4.98767","0"],["4.98768","0"],["4.98831","142.44"],["4.98844","0"],["4.98923","1851.98"],["4.98939","0"],["4.98950","473.14"],["4.98974","0"],["4.98993","1470.92"],["4.99005","1053.61"],["4.99118","1698.95"],["4.99166","1831.91"],["4.99213","0"],["4.99215","0"],["4.99232","1721.26"],["4.99526","0"],["4.99528","1865.82"],["4.99628","1765.74"],["4.99863","2385.82"],["5.02504","0"],["5.02570","79.59"]],"b":[["4.97847","31.67"],["4.97846","760.00"],["4.97838","31.66"],["4.97835","551.41"],["4.97803","0"],["4.97774","0"],["4.97750","0"],["4.97630","133.97"],["4.97621","471.98"],["4.97601","154.19"],["4.97597","0"],["4.97541","0"],["4.97502","457.24"],["4.97401","0"],["4.97400","0"],["4.97390","80.41"],["4.97309","0"],["4.97302","0"],["4.97257","139.05"],["4.97100","0"],["4.96968","0"],["4.96876","240.00"],["4.96820","0"],["4.96800","30.00"],["4.96689","700.00"],["4.96617","0"]]}}}
1633806876.7433338: {"ch":"orderbook/full","update":{"DOGEUSDT":{"t":1633806876660,"s":1308195,"a":[["0.24984550","0"],["0.24985071","182460"],["0.25011311","0"],["0.25011781","424590"],["0.25096346","0"],["0.25096914","423950"]],"b":[]}}}
1633806876.8634691: {"ch":"orderbook/full","update":{"DCRETH":{"t":1633806876817,"s":499185,"a":[],"b":[["0.033391","2.315"]]}}}
1633806876.8635468: {"ch":"orderbook/full","update":{"NEOBTC":{"t":1633806876793,"s":1498443,"a":[["0.0008814","43.12"],["0.0008816","0"]],"b":[["0.0008780","3.54"],["0.0008779","0"],["0.0008745","24.00"],["0.0008741","0"]]}}}
1633806876.863606: {"ch":"orderbook/full","update":{"EOSUSDT":{"t":1633806876826,"s":1876216,"a":[["4.97967","0"],["4.98003","26.49"],["4.98127","0"],["4.98176","63.97"],["4.98282","0"],["4.98318","0"],["4.98398","100.26"],["4.98431","140.81"],["4.98443","0"],["4.98472","0"],["4.98497","0"],["4.98587","988.60"],["4.98672","0"],["4.98769","1612.05"],["4.98855","129.87"],["4.98923","0"],["4.98988","1737.51"],["4.99043","1851.98"],["4.99090","0"],["4.99168","0"],["4.99232","1961.26"],["4.99352","700.00"],["4.99429","0"],["4.99672","960.00"],["5.00037","0"],["5.00667","3221.49"],["5.01053","0"],["5.01340","30.00"],["5.02508","79.60"],["5.02570","0"],["5.06495","0"],["5.07926","8821.94"]],"b":[["4.97882","760.00"],["4.97864","31.66"],["4.97858","1654.08"],["4.97838","0"],["4.97828","0"],["4.97702","0"],["4.97655","58.80"],["4.97599","0"],["4.97401","1773.87"],["4.97390","0"],["4.97380","80.42"],["4.97201","0"],["4.83826","0"],["4.82667","17800.28"]]}}}
1633806876.939448: {"ch":"orderbook/full","update":{"EOSUSDT":{"t":1633806876919,"s":1876217,"a":[["4.98003","0"],["4.98004","26.49"],["4.98972","1831.91"],["4.99166","0"],["4.99302","1865.82"],["4.99528","0"]],"b":[["4.97924","31.66"],["4.97923","760.00"],["4.97904","330.80"],["4.97864","0"],["4.97846","0"],["4.97601","1828.43"],["4.97380","0"],["4.97314","80.43"],["4.97173","0"],["4.97072","2317.39"],["4.96932","240.00"],["4.96876","0"],["4.96872","0"],["4.96376","960.00"],["4.96300","0"]]}}}
1633806876.939557: {"ch":"orderbook/full","update":{"DOGEUSDT":{"t":1633806876864,"s":1308196,"a":[["0.25084909","0"],["0.25085317","442480"]],"b":[]}}}
1633806876.982988: {"ch":"ticker/1s","data":{"DCRETH":{"t":1633806876838,"a":"0.036730","A":"0.228","b":"0.036002","B":"0.018","o":"0.035004","c":"0.036373","h":"0.036686","l":"0.035072","v":"8.326","q":"0.297986431","p":"0.001369","P":"3.910981602102617","L":1417957304}}}
1633806876.983022: {"ch":"ticker/1s","data":{"EOSUSDT":{"t":1633806876943,"a":"4.98004","A":"26.49","b":"4.97924","B":"31.66","o":"4.71891","c":"4.98523","h":"5.06033","l":"4.57171","v":"7224629.96","q":"34899840.7456554","p":"0.26632","P":"5.643676187933230","L":1417984568}}}
1633806877.013142: {"ch":"orderbook/full","update":{"ATOMBCH":{"t":1633806877027,"s":274301,"a":[["0.1702183","0.15"]],"b":[["0.0170218","0.13"]]}}}
1633806877.043662: {"ch":"orderbook/full","update":{"NEOBTC":{"t":1633806876948,"s":1498444,"a":[],"b":[["0.0008745","0"],["0.0008741","24.00"]]}}}
1633806877.0437171: {"ch":"orderbook/full","update":{"EOSUSDT":{"t":1633806877029,"s":1876218,"a":[["4.98282","100.26"],["4.98398","0"],["5.03821","0"],["5.04482","0"]],"b":[["4.97925","31.67"],["4.97847","0"],["4.97724","58.80"],["4.97655","0"],["4.97624","939.97"],["4.97562","1723.94"],["4.97271","0"],["4.97253","159.94"],["4.97214","0"],["4.97053","0"],["4.96771","700.00"],["4.96689","0"],["4.91869","0"],["4.91769","0"],["4.91669","0"],["4.82667","0"],["4.80999","17800.28"]]}}}
1633806877.043784: {"ch":"orderbook/full","update":{"DOGEUSDT":{"t":1633806877003,"s":1308197,"a":[["0.25107745","442090"],["0.25109548","362010"],["0.25111260","0"],["0.25115647","381430"],["0.25118684","0"],["0.25132977","0"],["0.25251812","423730"],["0.25272606","453850"],["0.25274521","0"],["0.25296046","473980"],["0.25298868","0"],["0.25318471","457370"],["0.25320104","0"],["0.25338541","337030"],["0.25342531","0"],["0.25352869","426380"],["0.25359028","0"],["0.25384843","0"],["0.25454521","388920"],["0.25469527","371030"],["0.25472898","0"],["0.25478260","443900"],["0.25480962","0"],["0.25503443","344260"],["0.25511160","0"],["0.25536605","0"]],"b":[]}}}
1633806877.126365: {"ch":"orderbook/full","update":{"EOSUSDT":{"t":1633806877097,"s":1876219,"a":[["4.98004","0"],["4.98006","26.49"]],"b":[["4.97932","31.66"],["4.97924","0"],["4.97532","1627.26"],["4.97060","0"],["4.66737","7565.88"],["4.58108","0"]]}}}
1633806877.1282592: {"ch":"orderbook/full","update":{"DOGEUSDT":{"t":1633806877124,"s":1308198,"a":[["0.24985071","0"],["0.24986305","182450"],["0.24991306","0"],["0.24992414","343300"],["0.24998552","0"],["0.24999740","476000"],["0.25011781","0"],["0.25012915","424580"],["0.25020394","0"],["0.25021384","409240"],["0.25028872","0"],["0.25029543","459850"],["0.25085317","0"],["0.25086451","442460"],["0.25096914","0"],["0.25098295","423930"],["0.25109548","0"],["0.25110466","362000"],["0.25115647","0"],["0.25116809","381410"],["0.25251812","0"],["0.25254639","423680"],["0.25272606","0"],["0.25274343","453810"],["0.25296046","0"],["0.25299889","473910"],["0.25318471","0"],["0.25320645","457330"],["0.25338541","0"],["0.25340539","337000"],["0.25352869","0"],["0.25355961","426320"],["0.25454521","0"],["0.25457413","388880"],["0.25469527","0"],["0.25471153","371000"],["0.25478260","0"],["0.25480117","443870"],["0.25503443","0"],["0.25507707","344200"]],"b":[]}}}
1633806877.223279: {"ch":"orderbook/full","update":{"EOSUSDT":{"t":1633806877233,"s":1876220,"a":[["4.98006","0"],["4.98009","0"],["4.98017","26.49"],["4.98282","0"],["4.98398","100.26"],["4.99120","0"],["4.99221","2824.53"],["4.99320","0"],["4.99520","0"],["4.99581","2665.05"],["4.99719","0"],["4.99859","4574.80"],["5.00191","9017.29"],["5.05275","0"],["5.06664","6980.08"],["5.07926","0"],["5.09141","8821.94"],["5.09605","0"],["5.11111","13225.51"],["5.13219","0"],["5.14954","24335.25"],["5.29036","0"],["5.30356","43331.32"],["5.45578","0"],["5.47075","93429.49"]],"b":[["4.97601","2285.67"],["4.97502","0"],["4.97090","1783.00"],["4.96900","0"],["4.95783","1900.00"],["4.95607","0"]]}}}
1633806877.313688: {"ch":"orderbook/full","update":{"DCRETH":{"t":1633806877284,"s":499186,"a":[["0.036730","0.448"]],"b":[]}}}
1633806877.3189728: {"ch":"orderbook/full","update":{"NEOBTC":{"t":1633806877264,"s":1498445,"a":[["0.0008799","12.38"],["0.0008803","0"]],"b":[]}}}
1633806877.319535: {"ch":"orderbook/full","update":{"EOSUSDT":{"t":1633806877334,"s":1876221,"a":[["4.98017","0"],["4.98064","26.49"],["4.98176","0"],["4.98262","63.97"],["4.98399","0"],["4.98448","0"],["4.98499","2289.11"],["4.98543","103.76"],["4.98912","0"],["4.98980","685.96"],["4.99021","0"],["4.99121","1019.31"],["4.99175","240.00"],["4.99221","1348.10"],["4.99232","1721.26"],["4.99370","1476.43"],["4.99462","0"],["4.99619","0"],["4.99907","0"],["4.99914","2410.95"],["5.00104","5911.59"],["5.00488","11253.00"],["5.01190","30.00"],["5.01340","0"],["5.02508","0"],["5.02571","79.59"]],"b":[["4.97957","31.66"],["4.97932","0"],["4.97383","1451.60"],["4.97379","80.42"],["4.97355","422.89"],["4.97314","0"],["4.97269","445.04"],["4.97262","943.91"],["4.97230","914.11"],["4.97181","0"],["4.97092","0"],["4.97066","0"],["4.96985","240.00"],["4.96939","0"],["4.96932","0"],["4.96928","0"],["4.96853","1654.12"],["4.96828","700.00"],["4.96771","0"],["4.96662","0"],["4.96059","2399.48"],["4.95496","0"]]}}}
1633806877.4337878: {"ch":"orderbook/full","update":{"EOSUSDT":{"t":1633806877435,"s":1876222,"a":[["4.98064","0"],["4.98105","26.49"],["4.98284","0"],["4.98425","147.22"],["4.98464","0"],["4.98489","0"],["4.98580","391.27"],["4.98599","1685.82"],["4.98703","0"],["4.98868","1737.51"],["4.98897","1072.37"],["4.98980","0"],["4.98988","0"],["4.99022","685.96"],["5.04152","16381.41"],["5.04705","29154.10"]],"b":[["4.97990","31.66"],["4.97968","1102.47"],["4.97957","0"],["4.97804","0"],["4.97601","4976.73"],["4.97557","1636.04"],["4.97493","0"],["4.97401","0"],["4.97353","1811.59"],["4.97094","0"],["4.97071","0"],["4.97037","2012.24"],["4.96817","0"],["4.96452","960.00"],["4.96376","0"],["4.94302","0"],["4.91938","13206.04"],["4.91838","19348.42"],["4.91738","3831.85"]]}}}
1633806877.434113: {"ch":"orderbook/full","update":{"USDTUSDP":{"t":1633806877428,"s":384620,"a":[["1.100000","6.45"]],"b":[["0.900000","15.83"]]}}}
1633806877.434187: {"ch":"orderbook/full","update":{"DOGEUSDT":{"t":1633806877395,"s":1308199,"a":[["0.25012915","0"],["0.25012987","424570"],["0.25110466","0"],["0.25110511","361990"]],"b":[]}}}
1633806877.515339: {"ch":"orderbook/full","update":{"DCRETH":{"t":1633806877447,"s":499187,"a":[],"b":[["0.033656","59.424"]]}}}
1633806877.523434: {"ch":"orderbook/full","update":{"NEOBTC":{"t":1633806877485,"s":1498446,"a":[],"b":[["0.0008780","0"],["0.0008779","3.54"]]}}}
1633806877.530551: {"ch":"orderbook/full","update":{"EOSUSDT":{"t":1633806877523,"s":1876223,"a":[["4.98105","0"],["4.98119","26.49"],["4.98262","0"],["4.98308","63.97"],["4.98431","0"],["4.98492","0"],["4.98499","433.01"],["4.98517","140.81"],["4.98562","0"],["4.98599","4625.73"],["4.98668","1612.05"],["4.98697","0"],["4.98698","0"],["4.98714","0"],["4.98752","1881.33"],["4.98769","0"],["4.98898","2688.84"],["4.98940","143.85"],["4.98999","436.89"],["4.99306","0"],["4.99774","2649.95"],["5.02511","79.60"],["5.02571","0"]],"b":[["4.98003","63.33"],["4.98002","760.00"],["4.97990","0"],["4.97925","0"],["4.97882","0"],["4.97804","58.80"],["4.97782","664.26"],["4.97742","133.97"],["4.97731","471.98"],["4.97724","0"],["4.97682","990.87"],["4.97630","0"],["4.97621","0"],["4.97482","0"],["4.97382","0"],["4.97042","240.00"],["4.96985","0"],["4.96891","700.00"],["4.96828","0"],["4.95235","4676.44"],["4.94362","29.83"],["4.93903","0"]]}}}
1633806877.626606: {"ch":"orderbook/full","update":{"EOSUSDT":{"t":1633806877629,"s":1876224,"a":[["4.98119","0"],["4.98141","26.49"],["4.98583","0"],["4.98780","110.49"],["4.99175","0"],["4.99273","240.00"],["5.02511","0"],["5.02595","79.58"],["5.14954","0"],["5.16203","24335.25"],["5.30356","0"],["5.31672","43331.32"]],"b":[["4.98014","31.66"],["4.98003","31.67"],["4.97731","1411.95"],["4.97624","0"],["4.97422","80.41"],["4.97380","109.20"],["4.97379","0"],["4.97095","0"]]}}}
1633806877.633897: {"ch":"orderbook/full","update":{"DOGEUSDT":{"t":1633806877607,"s":1308200,"a":[["0.25012987","0"],["0.25014131","424560"],["0.25021384","0"],["0.25022484","409230"],["0.25029543","0"],["0.25029980","459840"],["0.25086451","0"],["0.25087954","442440"],["0.25098295","0"],["0.25099664","423910"],["0.25110511","0"],["0.25111241","361980"],["0.25116809","0"],["0.25117912","381400"],["0.25254639","0"],["0.25257098","423640"],["0.25274343","0"],["0.25276149","453780"],["0.25299889","0"],["0.25302669","473860"],["0.25320645","0"],["0.25322886","457290"],["0.25340539","0"],["0.25341968","336990"],["0.25355961","0"],["0.25358358","426280"],["0.25457413","0"],["0.25459819","388840"],["0.25471153","0"],["0.25472459","370980"],["0.25480117","0"],["0.25482422","443830"],["0.25507707","0"],["0.25510589","344170"]],"b":[]}}}
1633806877.720544: {"ch":"orderbook/full","update":{"EOSUSDT":{"t":1633806877729,"s":1876225,"a":[["4.98139","26.49"],["4.98141","0"],["5.02595","0"],["5.02692","79.57"]],"b":[["4.97701","154.19"],["4.97601","4822.54"],["4.97522","80.39"],["4.97462","1619.89"],["4.97427","139.05"],["4.97422","0"],["4.97296","2320.00"],["4.97257","0"],["4.97173","1635.38"],["4.96902","0"],["4.96839","0"],["4.96802","0"]]}}}
1633806877.733365: {"ch":"orderbook/full","update":{"DOGEUSDT":{"t":1633806877708,"s":1308201,"a":[["0.25099664","0"],["0.25099679","423900"]],"b":[]}}}
1633806877.822453: {"ch":"orderbook/full","update":{"EOSUSDT":{"t":1633806877827,"s":1876226,"a":[["4.98134","26.49"],["4.98139","0"]],"b":[["4.93368","6751.44"],["4.91699","21513.58"]]}}}
1633806877.937454: {"ch":"orderbook/full","update":{"EOSUSDT":{"t":1633806877918,"s":1876227,"a":[],"b":[["4.97723","1723.94"],["4.97562","0"],["4.97102","2783.94"],["4.96824","0"]]}}}
1633806877.9375901: {"ch":"orderbook/full","update":{"USDTUSDP":{"t":1633806877932,"s":384621,"a":[["1.100000","6.31"]],"b":[["0.900000","15.69"]]}}}
1633806877.982219: {"ch":"ticker/1s","data":{"DCRETH":{"t":1633806877538,"a":"0.036730","A":"0.448","b":"0.036002","B":"0.018","o":"0.035004","c":"0.036373","h":"0.036686","l":"0.035072","v":"8.326","q":"0.297986431","p":"0.001369","P":"3.910981602102617","L":1417957304}}}
1633806877.982309: {"ch":"ticker/1s","data":{"EOSUSDT":{"t":1633806877943,"a":"4.98134","A":"26.49","b":"4.98014","B":"31.66","o":"4.71891","c":"4.98523","h":"5.06033","l":"4.57171","v":"7224629.96","q":"34899840.7456554","p":"0.26632","P":"5.643676187933230","L":1417984568}}}
1633806878.028982: {"ch":"orderbook/full","update":{"ATOMBCH":{"t":1633806878029,"s":274302,"a":[["0.1702183","0"],["0.1702258","0.10"]],"b":[["0.0170225","0.17"],["0.0170218","0"]]}}}
1633806878.034467: {"ch":"orderbook/full","update":{"EOSUSDT":{"t":1633806878018,"s":1876228,"a":[["4.98118","26.49"],["4.98134","0"],["5.04152","0"],["5.04705","0"]],"b":[["4.91938","0"],["4.91838","0"],["4.91738","0"]]}}}
1633806878.120754: {"ch":"orderbook/full","update":{"HTBTC":{"t":1633806878051,"s":660796,"a":[],"b":[["0.00014089","1442.46"],["0.00014076","0"]]}}}
1633806878.1208808: {"ch":"orderbook/full","update":{"EOSUSDT":{"t":1633806878111,"s":1876229,"a":[["4.98104","26.49"],["4.98118","0"],["5.02692","0"],["5.02703","79.56"]],"b":[["4.97476","1811.59"],["4.97353","0"],["4.96928","1796.32"],["4.96791","2486.04"],["4.96586","0"],["4.96458","0"],["4.96116","3485.93"],["4.95553","0"]]}}}
1633806878.211356: {"ch":"orderbook/full","update":{"DCRETH":{"t":1633806878217,"s":499188,"a":[],"b":[["0.033657","2.297"],["0.033391","0"]]}}}
1633806878.21539: {"ch":"orderbook/full","update":{"BORUSDT":{"t":1633806878164,"s":56259,"a":[["100000.000","0.0011"]],"b":[["0.001","1026.5997"]]}}}
1633806878.22016: {"ch":"orderbook/full","update":{"EOSUSDT":{"t":1633806878200,"s":1876230,"a":[["4.98104","0"],["4.98105","26.49"],["4.98499","1516.82"],["4.98599","3541.92"]],"b":[["4.95842","3704.80"],["4.95115","0"]]}}}
1633806878.3365362: {"ch":"orderbook/full","update":{"EOSUSDT":{"t":1633806878317,"s":1876231,"a":[["5.45463","93429.49"],["5.47075","0"]],"b":[]}}}
1633806878.336661: {"ch":"orderbook/full","update":{"DOGEUSDT":{"t":1633806878308,"s":1308202,"a":[["0.24811211","0"],["0.24813608","78270"],["0.24877276","0"],["0.24880011","62210"],["0.24986305","0"],["0.24989502","182430"],["0.24992414","0"],["0.24994248","343270"],["0.24999740","0"],["0.25003292","475930"],["0.25014131","0"],["0.25016691","424510"],["0.25022484","0"],["0.25025201","409180"],["0.25029980","0"],["0.25031144","459820"],["0.25087954","0"],["0.25091662","442370"],["0.25099679","0"],["0.25103111","423850"],["0.25111241","0"],["0.25113678","361950"],["0.25117912","0"],["0.25120807","381350"],["0.25257098","0"],["0.25263259","423530"],["0.25276149","0"],["0.25281771","453680"],["0.25302669","0"],["0.25309005","473740"],["0.25322886","0"],["0.25329052","457180"],["0.25341968","0"],["0.25345789","336930"],["0.25358358","0"],["0.25366303","426150"],["0.25459819","0"],["0.25465613","388750"],["0.25472459","0"],["0.25475742","370940"],["0.25482422","0"],["0.25493457","443640"],["0.25510589","0"],["0.25523296","343990"]],"b":[]}}}
1633806878.419424: {"ch":"orderbook/full","update":{"DCRETH":{"t":1633806878338,"s":499189,"a":[],"b":[["0.035709","16.000"],["0.035617","0"]]}}}
1633806878.424118: {"ch":"orderbook/full","update":{"EOSUSDT":{"t":1633806878410,"s":1876232,"a":[["4.98096","26.49"],["4.98105","0"],["4.99178","240.00"],["4.99273","0"],["5.04342","16381.41"],["5.04834","29154.10"]],"b":[["4.91937","13206.04"],["4.91838","19348.42"],["4.91738","3884.95"]]}}}
1633806878.431993: {"ch":"orderbook/full","update":{"DOGEUSDT":{"t":1633806878415,"s":1308203,"a":[["0.24933688","0"],["0.24935689","101010"],["0.24994248","0"],["0.24994933","343260"],["0.25003292","0"],["0.25004077","475920"],["0.25091662","0"],["0.25092686","442350"],["0.25103111","0"],["0.25103971","423830"],["0.25281771","0"],["0.25282244","453670"],["0.25309005","0"],["0.25309398","473730"],["0.25329052","0"],["0.25329520","457170"],["0.25366303","0"],["0.25366977","426140"]],"b":[["0.24752386","46200"],["0.24749930","0"]]}}}
1633806878.525696: {"ch":"orderbook/full","update":{"XVSUSDT":{"t":1633806878506,"s":484017,"a":[["28.0673","0"],["28.0712","60.540"],["28.0730","0"],["28.0765","107.095"],["28.0867","0"],["28.0947","98.436"],["28.1323","0"],["28.1434","105.569"],["28.1738","0"],["28.1852","207.692"],["28.3105","0"],["28.3164","262.137"],["28.4873","0"],["28.5072","411.194"]],"b":[]}}}
1633806878.5261261: {"ch":"orderbook/full","update":{"EOSUSDT":{"t":1633806878535,"s":1876233,"a":[["4.98089","26.49"],["4.98096","0"]],"b":[]}}}
1633806878.526913: {"ch":"orderbook/full","update":{"USDTUSDP":{"t":1633806878527,"s":384622,"a":[["1.100000","6.11"]],"b":[["0.900000","15.49"]]}}}
1633806878.527015: {"ch":"orderbook/full","update":{"DOGEUSDT":{"t":1633806878532,"s":1308204,"a":[["0.25147231","148520"],["0.25177341","0"]],"b":[]}}}
1633806878.6384552: {"ch":"trades","update":{"NEOBTC":[{"t":1633806878547,"i":1633806878547,"p":"0.0008785","q":"0.56","s":"buy"}]}}
1633806878.6385431: {"ch":"candles/M1","update":{"NEOBTC":[{"t":1633806840000,"o":"0.0008788","c":"0.0008785","h":"0.0008788","l":"0.0008785","v":"2.93","q":"0.002574457"}]}}
1633806878.638597: {"ch":"orderbook/full","update":{"NEOBTC":{"t":1633806878582,"s":1498447,"a":[],"b":[["0.0008780","10.61"],["0.0008777","6.59"]]}}}
1633806878.6386712: {"ch":"orderbook/full","update":{"HTBTC":{"t":1633806878616,"s":660797,"a":[["0.00014741","0"],["0.00014804","4561.05"],["0.00022970","0"],["0.00023069","6848.62"],["0.00025522","0"],["0.00025559","8802.07"],["0.00034324","0"],["0.00034369","46776.23"]],"b":[]}}}
1633806878.638771: {"ch":"orderbook/full","update":{"EOSUSDT":{"t":1633806878604,"s":1876234,"a":[["4.98086","26.49"],["4.98089","0"],["4.99178","0"],["4.99275","240.00"],["5.01359","4270.16"],["5.02105","0"]],"b":[["4.97968","0"],["4.97923","0"],["4.97859","1102.50"]]}}}
1633806878.6388638: {"ch":"orderbook/full","update":{"DOGEUSDT":{"t":1633806878615,"s":1308205,"a":[["0.24978505","363370"],["0.25005098","0"]],"b":[["0.24739311","0"],["0.24734165","58720"]]}}}
1633806878.7183511: {"ch":"orderbook/full","update":{"EOSUSDT":{"t":1633806878721,"s":1876235,"a":[],"b":[["4.98021","31.66"],["4.98014","0"],["4.97043","1654.12"],["4.96853","0"],["4.96727","1833.38"],["4.96499","0"]]}}}
1633806878.724969: {"ch":"orderbook/full","update":{"DOGEUSDT":{"t":1633806878657,"s":1308206,"a":[],"b":[["0.24714071","38000"],["0.24711320","0"]]}}}
1633806878.82909: {"ch":"orderbook/full","update":{"HTBTC":{"t":1633806878738,"s":660798,"a":[["0.00014804","0"],["0.00014859","4561.05"]],"b":[]}}}
1633806878.8356748: {"ch":"orderbook/full","update":{"EOSUSDT":{"t":1633806878832,"s":1876236,"a":[["4.98081","26.49"],["4.98086","0"]],"b":[["4.97339","1635.38"],["4.97173","0"],["4.95026","6107.92"],["4.94070","0"]]}}}
1633806878.923979: {"ch":"orderbook/full","update":{"EOSUSDT":{"t":1633806878922,"s":1876237,"a":[["4.98080","26.49"],["4.98081","0"]],"b":[["4.98021","0"],["4.98009","31.66"],["4.97723","0"],["4.97603","1723.94"],["4.97601","3148.30"],["4.97532","0"],["4.97472","1674.24"],["4.97462","0"],["4.97401","1627.26"],["4.97302","1619.89"],["4.96824","2645.54"],["4.96404","3470.64"]]}}}
1633806878.935051: {"ch":"orderbook/full","update":{"DOGEUSDT":{"t":1633806878925,"s":1308207,"a":[],"b":[["0.24761858","46400"],["0.24760118","0"]]}}}
1633806878.981099: {"ch":"ticker/1s","data":{"NEOBTC":{"t":1633806878642,"a":"0.0008790","A":"18.89","b":"0.0008781","B":"17.00","o":"0.0008662","c":"0.0008785","h":"0.0009067","l":"0.0008475","v":"155805.72","q":"136.162702840","p":"0.0000123","P":"1.419995382128839","L":1417984792}}}
1633806878.981189: {"ch":"ticker/1s","data":{"EOSUSDT":{"t":1633806878943,"a":"4.98080","A":"26.49","b":"4.98009","B":"31.66","o":"4.71891","c":"4.98523","h":"5.06033","l":"4.57171","v":"7224629.96","q":"34899840.7456554","p":"0.26632","P":"5.643676187933230","L":1417984568}}}
1633806879.014508: {"ch":"orderbook/full","update":{"DCRETH":{"t":1633806879032,"s":499190,"a":[],"b":[["0.036001","0"]]}}}
1633806879.015759: {"ch":"orderbook/full","update":{"ATOMBCH":{"t":1633806879035,"s":274303,"a":[["0.1702258","0.14"]],"b":[["0.0170225","0.14"]]}}}
1633806879.025694: {"ch":"orderbook/full","update":{"EOSUSDT":{"t":1633806879029,"s":1876238,"a":[["4.98063","26.49"],["4.98080","0"],["5.04342","0"],["5.04834","0"]],"b":[["4.98009","0"],["4.98002","791.66"],["4.91937","0"],["4.91838","0"],["4.91738","0"]]}}}
1633806879.025866: {"ch":"orderbook/full","update":{"USDTUSDP":{"t":1633806879032,"s":384623,"a":[["1.100000","6.25"]],"b":[["0.900000","15.63"]]}}}
1633806879.1123252: {"ch":"orderbook/full","update":{"DCRETH":{"t":1633806879064,"s":499191,"a":[],"b":[["0.036002","0"],["0.035985","0.777"]]}}}
1633806879.125622: {"ch":"orderbook/full","update":{"XVSUSDT":{"t":1633806879078,"s":484018,"a":[["28.0811","0"],["28.0861","20.380"]],"b":[]}}}
1633806879.125752: {"ch":"orderbook/full","update":{"NEOBTC":{"t":1633806879096,"s":1498448,"a":[["0.0008795","0"],["0.0008797","10.85"]],"b":[]}}}
1633806879.218509: {"ch":"orderbook/full","update":{"DCRETH":{"t":1633806879169,"s":499192,"a":[],"b":[["0.035986","7.282"]]}}}
1633806879.2288: {"ch":"orderbook/full","update":{"EOSUSDT":{"t":1633806879183,"s":1876239,"a":[["4.98262","63.97"],["4.98308","0"]],"b":[["4.80999","0"],["4.78927","17800.28"],["4.66737","0"],["4.58107","7565.88"]]}}}
1633806879.312482: {"ch":"orderbook/full","update":{"DCRETH":{"t":1633806879278,"s":499193,"a":[],"b":[["0.035987","0.779"],["0.035985","0"]]}}}
1633806879.3241448: {"ch":"orderbook/full","update":{"EOSUSDT":{"t":1633806879335,"s":1876240,"a":[["4.98063","0"],["4.98066","26.49"]],"b":[["4.97601","1374.43"],["4.97510","1773.87"]]}}}
1633806879.327491: {"ch":"orderbook/full","update":{"DOGEUSDT":{"t":1633806879309,"s":1308208,"a":[["0.25107745","0"],["0.25108024","442080"],["0.25113678","0"],["0.25114117","361940"]],"b":[]}}}
1633806879.414418: {"ch":"orderbook/full","update":{"DCRETH":{"t":1633806879364,"s":499194,"a":[],"b":[["0.035988","7.282"],["0.035986","0"]]}}}
1633806879.443261: {"ch":"orderbook/full","update":{"EOSUSDT":{"t":1633806879414,"s":1876241,"a":[["4.98066","0"],["4.98081","26.49"],["4.98283","0"],["4.98397","100.26"],["5.04262","16381.41"],["5.04657","29154.10"]],"b":[["4.98008","31.66"],["4.98002","760.00"],["4.96954","1754.33"],["4.96696","0"],["4.96192","2728.74"],["4.95831","0"],["4.95725","4542.71"],["4.94967","0"],["4.92037","13206.04"],["4.91938","19348.42"],["4.91838","3884.95"]]}}}
1633806879.520384: {"ch":"orderbook/full","update":{"DCRETH":{"t":1633806879470,"s":499195,"a":[],"b":[["0.035989","0.779"],["0.035987","0"]]}}}
1633806879.532224: {"ch":"orderbook/full","update":{"EOSUSDT":{"t":1633806879527,"s":1876242,"a":[["4.98081","0"],["4.98091","26.49"],["4.99121","0"],["4.99207","1019.31"],["4.99221","0"],["4.99321","1348.10"],["5.05721","6980.08"],["5.06664","0"],["5.08013","8821.94"],["5.09141","0"]],"b":[["4.98015","31.66"],["4.98008","0"],["4.97272","2317.39"],["4.97146","2814.85"],["4.97072","0"],["4.96772","0"]]}}}
1633806879.6194692: {"ch":"orderbook/full","update":{"DCRETH":{"t":1633806879576,"s":499196,"a":[],"b":[["0.035990","7.282"],["0.035988","0"]]}}}
1633806879.623032: {"ch":"orderbook/full","update":{"EOSUSDT":{"t":1633806879634,"s":1876243,"a":[["4.98091","0"],["4.98126","26.49"],["4.98262","0"],["4.98306","63.97"],["4.99275","0"],["4.99327","240.00"],["4.99352","0"],["4.99440","700.00"],["5.00622","18331.74"],["5.02703","0"],["5.02718","79.56"],["5.09687","13225.51"],["5.11111","0"]],"b":[["4.98031","31.66"],["4.98015","0"],["4.97522","0"],["4.97505","80.40"]]}}}
1633806879.623253: {"ch":"orderbook/full","update":{"USDTUSDP":{"t":1633806879536,"s":384624,"a":[["1.100000","5.73"]],"b":[["0.900000","15.11"]]}}}
1633806879.633663: {"ch":"orderbook/full","update":{"DOGEUSDT":{"t":1633806879599,"s":1308209,"a":[["0.25463308","388790"],["0.25465613","0"],["0.25474219","370960"],["0.25475742","0"],["0.25487007","443750"],["0.25493457","0"],["0.25515779","344100"],["0.25523296","0"]],"b":[]}}}
1633806879.712895: {"ch":"orderbook/full","update":{"DCRETH":{"t":1633806879674,"s":499197,"a":[],"b":[["0.035991","0.779"],["0.035989","0"]]}}}
1633806879.728926: {"ch":"orderbook/full","update":{"EOSUSDT":{"t":1633806879724,"s":1876244,"a":[["4.98126","0"],["4.98160","26.49"],["4.98306","0"],["4.98351","63.97"],["4.98397","0"],["4.98398","0"],["4.98424","100.26"],["4.98498","100.26"],["4.98580","0"],["4.98587","0"],["4.98668","0"],["4.98695","391.27"],["4.98764","988.60"],["4.98868","0"],["4.98934","1612.05"],["4.99020","1737.51"],["5.01125","2.27"],["5.02699","79.57"],["5.02718","0"]],"b":[["4.98059","31.66"],["4.98031","0"],["4.97702","457.24"],["4.97601","917.19"],["4.97129","1753.83"],["4.97092","240.00"],["4.97042","0"],["4.96878","0"],["4.96531","960.00"],["4.96452","0"]]}}}
1633806879.736919: {"ch":"orderbook/full","update":{"DOGEUSDT":{"t":1633806879699,"s":1308210,"a":[["0.24935115","101020"],["0.24935689","0"],["0.24994630","343270"],["0.24994933","0"],["0.25003366","475930"],["0.25004077","0"],["0.25119614","381370"],["0.25120807","0"],["0.25261006","423570"],["0.25263259","0"],["0.25279434","453720"],["0.25282244","0"],["0.25306746","473780"],["0.25309398","0"],["0.25326626","457220"],["0.25329520","0"],["0.25344327","336950"],["0.25345789","0"],["0.25362943","426210"],["0.25366977","0"]],"b":[]}}}
1633806879.812994: {"ch":"orderbook/full","update":{"DCRETH":{"t":1633806879766,"s":499198,"a":[],"b":[["0.035992","7.282"],["0.035990","0"]]}}}
1633806879.8246698: {"ch":"orderbook/full","update":{"HTBTC":{"t":1633806879756,"s":660799,"a":[["0.00025559","0"],["0.00025595","8802.07"],["0.00026790","0"],["0.00026834","11985.76"],["0.00034369","0"],["0.00034419","46776.23"]],"b":[]}}}
1633806879.824822: {"ch":"orderbook/full","update":{"EOSUSDT":{"t":1633806879816,"s":1876245,"a":[["4.98160","0"],["4.98166","26.49"],["4.98350","100.26"],["4.98424","0"],["5.04702","6980.08"],["5.05721","0"],["5.06386","8821.94"],["5.08013","0"],["5.43984","93429.49"],["5.45463","0"]],"b":[["4.98060","31.67"],["4.98003","0"],["4.97871","58.80"],["4.97804","0"],["4.97000","2322.09"],["4.96648","0"]]}}}
1633806879.837949: {"ch":"orderbook/full","update":{"DOGEUSDT":{"t":1633806879819,"s":1308211,"a":[["0.25092686","0"],["0.25093284","442340"],["0.25119614","0"],["0.25120906","381350"],["0.25261006","0"],["0.25263388","423530"],["0.25279434","0"],["0.25281957","453680"],["0.25306746","0"],["0.25309156","473740"],["0.25326626","0"],["0.25329235","457170"],["0.25344327","0"],["0.25345892","336930"],["0.25362943","0"],["0.25366576","426150"],["0.25463308","0"],["0.25464960","388760"],["0.25474219","0"],["0.25475058","370950"],["0.25487007","0"],["0.25489831","443700"],["0.25515779","0"],["0.25519241","344050"]],"b":[["0.24690846","45000"],["0.24686347","0"]]}}}
