1633806879.919622: {"ch":"orderbook/full","update":{"DCRETH":{"t":1633806879867,"s":499199,"a":[],"b":[["0.035993","0.779"],["0.035991","0"]]}}}
1633806879.9264781: {"ch":"orderbook/full","update":{"XVSUSDT":{"t":1633806879900,"s":484019,"a":[],"b":[["27.7971","199.881"],["27.7920","0"]]}}}
1633806879.934813: {"ch":"orderbook/full","update":{"NEOBTC":{"t":1633806879845,"s":1498449,"a":[["0.0009462","0"],["0.0009480","793.22"],["0.0027605","0"],["0.0027703","1063.16"]],"b":[]}}}
1633806879.9349718: {"ch":"orderbook/full","update":{"EOSUSDT":{"t":1633806879935,"s":1876246,"a":[["4.98424","100.26"],["4.98498","0"]],"b":[["4.97801","154.19"],["4.97701","0"],["4.97624","1299.34"],["4.97250","0"],["4.96149","2321.80"],["4.95503","0"]]}}}
1633806879.982288: {"ch":"ticker/1s","data":{"DCRETH":{"t":1633806879938,"a":"0.036730","A":"0.448","b":"0.035993","B":"0.779","o":"0.035004","c":"0.036373","h":"0.036686","l":"0.035072","v":"8.326","q":"0.297986431","p":"0.001369","P":"3.910981602102617","L":1417957304}}}
1633806879.982379: {"ch":"ticker/1s","data":{"EOSUSDT":{"t":1633806879944,"a":"4.98166","A":"26.49","b":"4.98060","B":"31.67","o":"4.71891","c":"4.98523","h":"5.06033","l":"4.57171","v":"7224629.96","q":"34899840.7456554","p":"0.26632","P":"5.643676187933230","L":1417984568}}}
1633806880.01321: {"ch":"orderbook/full","update":{"DCRETH":{"t":1633806879968,"s":499200,"a":[],"b":[["0.035994","7.282"],["0.035992","0"]]}}}
1633806880.0160892: {"ch":"orderbook/full","update":{"ATOMBCH":{"t":1633806880035,"s":274304,"a":[["0.1702258","0"],["0.1702378","0.12"]],"b":[]}}}
1633806880.0162182: {"ch":"orderbook/full","update":{"NEOBTC":{"t":1633806879959,"s":1498450,"a":[],"b":[["0.0008745","24.00"],["0.0008741","0"]]}}}
1633806880.02882: {"ch":"orderbook/full","update":{"EOSUSDT":{"t":1633806880017,"s":1876247,"a":[["5.04262","0"],["5.04657","0"]],"b":[["4.97601","2691.06"],["4.97510","0"],["4.92037","0"],["4.91938","0"],["4.91838","0"]]}}}
1633806880.123594: {"ch":"orderbook/full","update":{"DCRETH":{"t":1633806880041,"s":499201,"a":[],"b":[["0.035993","0"]]}}}
1633806880.123709: {"ch":"orderbook/full","update":{"ATOMBCH":{"t":1633806880036,"s":274305,"a":[],"b":[["0.0170237","0.10"],["0.0170225","0"]]}}}
1633806880.1318321: {"ch":"orderbook/full","update":{"USDTUSDP":{"t":1633806880041,"s":384625,"a":[["1.100000","6.31"]],"b":[["0.900000","15.69"]]}}}
1633806880.2117062: {"ch":"orderbook/full","update":{"DCRETH":{"t":1633806880166,"s":499202,"a":[],"b":[["0.035995","0.124"]]}}}
1633806880.2162519: {"ch":"orderbook/full","update":{"NEOBTC":{"t":1633806880150,"s":1498451,"a":[],"b":[["0.0008745","0"],["0.0008741","24.00"]]}}}
1633806880.220393: {"ch":"orderbook/full","update":{"EOSUSDT":{"t":1633806880171,"s":1876248,"a":[["4.98142","760.00"],["4.98154","26.49"],["4.98166","0"],["4.98350","0"],["4.98423","100.26"],["5.02699","0"],["5.02706","79.56"],["5.03265","6023.83"],["5.04214","0"]],"b":[]}}}
1633806880.314815: {"ch":"orderbook/full","update":{"DCRETH":{"t":1633806880266,"s":499203,"a":[],"b":[["0.035996","7.282"],["0.035995","0.249"],["0.035994","0"]]}}}
1633806880.3355799: {"ch":"orderbook/full","update":{"EOSUSDT":{"t":1633806880296,"s":1876249,"a":[["4.98151","26.49"],["4.98154","0"]],"b":[["4.97601","4365.30"],["4.97517","1627.26"],["4.97472","0"],["4.97401","0"],["4.97325","2171.87"],["4.96798","0"]]}}}
1633806880.4123: {"ch":"orderbook/full","update":{"DCRETH":{"t":1633806880421,"s":499204,"a":[],"b":[["0.035997","0.388"],["0.035995","0"],["0.035984","4.547"],["0.035709","0"],["0.035617","16.000"]]}}}
1633806880.427935: {"ch":"orderbook/full","update":{"NEOBTC":{"t":1633806880376,"s":1498452,"a":[["0.0009480","0"],["0.0009584","793.22"],["0.0027703","0"],["0.0028236","1063.16"]],"b":[]}}}
1633806880.42808: {"ch":"orderbook/full","update":{"EOSUSDT":{"t":1633806880433,"s":1876250,"a":[["4.98142","0"],["4.98151","0"],["4.98162","26.49"],["4.98350","100.26"],["4.98423","0"],["4.98740","1612.05"],["4.98934","0"],["5.02697","79.57"],["5.02706","0"],["5.04252","16381.41"],["5.04768","29154.10"]],"b":[["4.97750","1723.94"],["4.97603","0"],["4.92127","13206.04"],["4.92028","19348.42"],["4.91928","3884.95"]]}}}
1633806880.512233: {"ch":"orderbook/full","update":{"DCRETH":{"t":1633806880502,"s":499205,"a":[],"b":[["0.035998","2.474"],["0.035996","0"],["0.035709","16.000"],["0.035617","0"]]}}}
1633806880.521007: {"ch":"orderbook/full","update":{"NEOBTC":{"t":1633806880531,"s":1498453,"a":[],"b":[["0.0008779","0"],["0.0008778","46.54"],["0.0008772","0"],["0.0008745","24.00"],["0.0008741","0"]]}}}
1633806880.535136: {"ch":"orderbook/full","update":{"HTBTC":{"t":1633806880529,"s":660800,"a":[["0.00014214","0"],["0.00014221","993.61"],["0.00014243","0"],["0.00014253","1357.31"]],"b":[]}}}
1633806880.5352802: {"ch":"orderbook/full","update":{"EOSUSDT":{"t":1633806880517,"s":1876251,"a":[["4.98162","0"],["4.98174","26.49"],["4.98499","433.01"],["4.98599","4625.73"]],"b":[["4.98079","31.66"],["4.98059","0"],["4.97225","128.58"],["4.96941","700.00"],["4.96891","0"],["4.96859","0"],["4.95967","1900.00"],["4.95783","0"]]}}}
1633806880.540239: {"ch":"orderbook/full","update":{"DOGEUSDT":{"t":1633806880487,"s":1308212,"a":[["0.25281957","0"],["0.25282435","453670"],["0.25309156","0"],["0.25309556","473730"],["0.25366576","0"],["0.25367253","426130"],["0.25475058","0"],["0.25475203","370940"],["0.25489831","0"],["0.25490377","443690"],["0.25519241","0"],["0.25519952","344040"]],"b":[]}}}
1633806880.616959: {"ch":"orderbook/full","update":{"DCRETH":{"t":1633806880600,"s":499206,"a":[],"b":[["0.035997","0"]]}}}
1633806880.636585: {"ch":"orderbook/full","update":{"NEOBTC":{"t":1633806880575,"s":1498454,"a":[],"b":[["0.0008779","3.54"],["0.0008778","0"],["0.0008772","43.00"],["0.0007282","0"],["0.0006911","557.30"]]}}}
1633806880.6367319: {"ch":"orderbook/full","update":{"EOSUSDT":{"t":1633806880626,"s":1876252,"a":[["4.98174","0"],["4.98185","26.49"],["5.04702","0"],["5.05649","6980.08"],["5.06386","0"],["5.07906","8821.94"]],"b":[["4.98097","31.66"],["4.98079","0"],["4.97505","0"],["4.97448","80.41"]]}}}
1633806880.636843: {"ch":"orderbook/full","update":{"USDTUSDP":{"t":1633806880560,"s":384626,"a":[["1.100000","6.16"]],"b":[["0.900000","15.54"]]}}}
1633806880.636896: {"ch":"orderbook/full","update":{"DOGEUSDT":{"t":1633806880610,"s":1308213,"a":[["0.25107990","442090"],["0.25108024","0"],["0.25113914","361950"],["0.25114117","0"],["0.25263388","0"],["0.25264067","423520"]],"b":[]}}}
1633806880.715704: {"ch":"orderbook/full","update":{"DCRETH":{"t":1633806880641,"s":499207,"a":[],"b":[["0.035998","2.536"]]}}}
1633806880.72149: {"ch":"orderbook/full","update":{"EOSUSDT":{"t":1633806880725,"s":1876253,"a":[["4.98180","26.49"],["4.98185","0"],["4.98827","1737.51"],["4.99020","0"]],"b":[["4.97663","1636.04"],["4.97557","0"]]}}}
1633806880.731624: {"ch":"orderbook/full","update":{"DOGEUSDT":{"t":1633806880660,"s":1308214,"a":[],"b":[["0.24764267","46400"],["0.24761858","0"]]}}}
1633806880.816182: {"ch":"orderbook/full","update":{"NEOBTC":{"t":1633806880821,"s":1498455,"a":[],"b":[["0.0008671","1298.27"],["0.0008657","0"],["0.0008568","1269.72"],["0.0008552","0"],["0.0008502","1291.85"],["0.0008484","0"]]}}}
1633806880.81857: {"ch":"orderbook/full","update":{"HTBTC":{"t":1633806880832,"s":660801,"a":[["0.00014244","1357.31"],["0.00014253","0"]],"b":[]}}}
1633806880.823912: {"ch":"orderbook/full","update":{"EOSUSDT":{"t":1633806880763,"s":1876254,"a":[["4.98176","26.49"],["4.98180","0"]],"b":[]}}}
1633806880.926663: {"ch":"orderbook/full","update":{"NEOBTC":{"t":1633806880929,"s":1498456,"a":[],"b":[["0.0008731","166.00"],["0.0008721","0"]]}}}
1633806880.9267929: {"ch":"orderbook/full","update":{"EOSUSDT":{"t":1633806880869,"s":1876255,"a":[["4.98176","0"],["4.98177","26.49"]],"b":[]}}}
1633806880.982091: {"ch":"ticker/1s","data":{"DCRETH":{"t":1633806880738,"a":"0.036730","A":"0.448","b":"0.035998","B":"2.536","o":"0.035004","c":"0.036373","h":"0.036686","l":"0.035072","v":"8.326","q":"0.297986431","p":"0.001369","P":"3.910981602102617","L":1417957304}}}
1633806880.98218: {"ch":"ticker/1s","data":{"EOSUSDT":{"t":1633806880943,"a":"4.98177","A":"26.49","b":"4.98097","B":"31.66","o":"4.71891","c":"4.98523","h":"5.06033","l":"4.57171","v":"7224629.96","q":"34899840.7456554","p":"0.26632","P":"5.643676187933230","L":1417984568}}}
1633806881.022728: {"ch":"orderbook/full","update":{"EOSUSDT":{"t":1633806880993,"s":1876256,"a":[["4.98175","26.49"],["4.98177","0"]],"b":[["4.98060","0"],["4.98003","31.67"],["4.97452","159.94"],["4.97253","0"]]}}}
1633806881.120358: {"ch":"orderbook/full","update":{"ATOMBCH":{"t":1633806881038,"s":274306,"a":[["0.1702378","0"],["0.1702431","0.14"]],"b":[["0.0170243","0.12"],["0.0170237","0"]]}}}
1633806881.1205041: {"ch":"orderbook/full","update":{"XVSUSDT":{"t":1633806881106,"s":484020,"a":[],"b":[["27.9988","0"],["27.9959","0"],["27.9888","2.014"],["27.9872","22.945"],["27.9789","0"],["27.9736","63.003"],["27.9682","0"],["27.9584","113.816"],["27.9541","0"],["27.9472","109.088"],["27.9406","0"],["27.8930","102.335"],["27.8717","0"],["27.8367","168.599"],["27.7971","0"],["27.7664","199.881"],["27.7416","0"],["27.7354","0"],["27.7300","221.917"],["27.7108","318.508"],["27.6845","0"],["27.6720","293.088"]]}}}
1633806881.122018: {"ch":"orderbook/full","update":{"NEOBTC":{"t":1633806881129,"s":1498457,"a":[],"b":[["0.0008780","14.15"],["0.0008779","0"],["0.0008745","0"],["0.0008741","24.00"],["0.0008731","72.00"],["0.0008721","94.00"]]}}}
1633806881.1247091: {"ch":"orderbook/full","update":{"HTBTC":{"t":1633806881115,"s":660802,"a":[["0.00029764","0"],["0.00029799","17212.22"],["0.00030401","0"],["0.00030439","22735.32"]],"b":[]}}}
1633806881.126362: {"ch":"orderbook/full","update":{"EOSUSDT":{"t":1633806881123,"s":1876257,"a":[["4.98155","26.49"],["4.98159","760.00"],["4.98175","0"],["5.04252","0"],["5.04768","0"],["5.09687","0"],["5.11048","13225.51"],["5.43984","0"],["5.45981","93429.49"]],"b":[["4.95708","2692.59"],["4.95253","0"],["4.92127","0"],["4.92028","0"],["4.91928","0"]]}}}
1633806881.13269: {"ch":"orderbook/full","update":{"USDTUSDP":{"t":1633806881064,"s":384627,"a":[["1.100000","5.89"]],"b":[["0.900000","15.27"]]}}}
1633806881.2280161: {"ch":"orderbook/full","update":{"NEOBTC":{"t":1633806881158,"s":1498458,"a":[["0.0008791","0"],["0.0008792","2.96"]],"b":[["0.0008780","10.61"],["0.0008779","3.54"],["0.0008671","0"],["0.0008659","1298.27"],["0.0006911","0"],["0.0006844","1714.64"]]}}}
1633806881.228191: {"ch":"orderbook/full","update":{"EOSUSDT":{"t":1633806881201,"s":1876258,"a":[["4.98504","1083.81"],["4.98599","3541.92"],["4.99122","1019.31"],["4.99207","0"]],"b":[]}}}
1633806881.325686: {"ch":"orderbook/full","update":{"ATOMBCH":{"t":1633806881248,"s":274307,"a":[["0.0568321","0.88"],["0.0568505","0"]],"b":[]}}}
1633806881.334091: {"ch":"orderbook/full","update":{"EOSUSDT":{"t":1633806881306,"s":1876259,"a":[["4.98349","100.26"],["4.98424","0"]],"b":[]}}}
1633806881.334217: {"ch":"orderbook/full","update":{"DOGEUSDT":{"t":1633806881260,"s":1308215,"a":[["0.25107990","0"],["0.25108525","442080"],["0.25113914","0"],["0.25114058","361940"]],"b":[]}}}
1633806881.418643: {"ch":"orderbook/full","update":{"NEOBTC":{"t":1633806881375,"s":1498459,"a":[],"b":[["0.0008731","166.00"],["0.0008721","0"]]}}}
1633806881.433814: {"ch":"orderbook/full","update":{"EOSUSDT":{"t":1633806881431,"s":1876260,"a":[["4.98152","26.49"],["4.98155","0"],["4.98926","1851.98"],["4.99043","0"],["5.04223","16381.41"],["5.04561","29154.10"],["5.27197","43331.32"],["5.31672","0"],["5.32092","59703.38"],["5.35271","0"]],"b":[["4.97456","445.04"],["4.97269","0"],["4.96580","1696.31"],["4.96271","0"],["4.92187","13206.04"],["4.92087","19348.42"],["4.91988","3884.95"]]}}}
1633806881.434029: {"ch":"orderbook/full","update":{"DOGEUSDT":{"t":1633806881362,"s":1308216,"a":[["0.25093198","442350"],["0.25093284","0"],["0.25519952","0"],["0.25520301","344030"]],"b":[]}}}
1633806881.5320399: {"ch":"orderbook/full","update":{"XVSUSDT":{"t":1633806881499,"s":484021,"a":[],"b":[["27.9533","109.088"],["27.9472","0"],["27.9370","102.335"],["27.8930","0"],["27.8691","168.599"],["27.8367","0"],["27.7870","199.881"],["27.7664","0"]]}}}
1633806881.532206: {"ch":"orderbook/full","update":{"EOSUSDT":{"t":1633806881519,"s":1876261,"a":[["5.01962","5507.50"],["5.02762","0"],["5.14736","88370.30"],["5.16210","0"]],"b":[["4.94196","5483.57"],["4.93203","0"]]}}}
1633806881.619168: {"ch":"orderbook/full","update":{"XVSUSDT":{"t":1633806881563,"s":484022,"a":[],"b":[["27.7420","221.917"],["27.7300","0"],["27.6823","293.088"],["27.6720","0"]]}}}
1633806881.6193101: {"ch":"orderbook/full","update":{"NEOBTC":{"t":1633806881568,"s":1498460,"a":[],"b":[["0.0008731","72.00"],["0.0008721","94.00"]]}}}
1633806881.633499: {"ch":"orderbook/full","update":{"EOSUSDT":{"t":1633806881635,"s":1876262,"a":[["4.98147","26.49"],["4.98152","0"],["5.07906","0"],["5.08898","8821.94"],["5.27197","0"],["5.29058","43331.32"],["5.32092","0"],["5.33515","59703.38"]],"b":[]}}}
1633806881.6336699: {"ch":"orderbook/full","update":{"USDTUSDP":{"t":1633806881568,"s":384628,"a":[["1.100000","6.06"]],"b":[["0.900000","15.44"]]}}}
1633806881.6337512: {"ch":"orderbook/full","update":{"DOGEUSDT":{"t":1633806881571,"s":1308217,"a":[],"b":[["0.24764267","0"],["0.24762007","46400"]]}}}
1633806881.7304971: {"ch":"orderbook/full","update":{"EOSUSDT":{"t":1633806881671,"s":1876263,"a":[["4.98142","26.49"],["4.98147","0"]],"b":[]}}}
1633806881.828629: {"ch":"orderbook/full","update":{"EOSUSDT":{"t":1633806881820,"s":1876264,"a":[["5.04713","6980.08"],["5.05649","0"]],"b":[["4.98097","0"],["4.98092","31.66"]]}}}
1633806881.919317: {"ch":"orderbook/full","update":{"DCRETH":{"t":1633806881855,"s":499208,"a":[["0.036972","0"],["0.036973","0"],["0.037004","17.000"],["0.037005","59.308"],["0.038256","0"],["0.038296","286.834"]],"b":[]}}}
1633806881.922427: {"ch":"orderbook/full","update":{"NEOBTC":{"t":1633806881846,"s":1498461,"a":[["0.0008791","2.96"],["0.0008792","0"]],"b":[]}}}
1633806881.925733: {"ch":"orderbook/full","update":{"HTBTC":{"t":1633806881846,"s":660803,"a":[["0.00014696","4561.05"],["0.00014859","0"],["0.00022239","6848.62"],["0.00023069","0"]],"b":[]}}}
1633806881.933311: {"ch":"orderbook/full","update":{"EOSUSDT":{"t":1633806881897,"s":1876265,"a":[["4.98142","0"],["4.98143","26.49"]],"b":[]}}}
1633806881.984919: {"ch":"ticker/1s","data":{"ATOMBCH":{"t":1633806881340,"a":"0.0568321","A":"0.88","b":"0.0566552","B":"1.05","o":"0.0698883","c":"0.0585227","h":"0.0698883","l":"0.0585227","v":"0.72","q":"0.042136344","p":"-0.0113656","P":"-16.26252176687657","L":1417149989}}}
1633806881.98501: {"ch":"ticker/1s","data":{"XVSUSDT":{"t":1633806881640,"a":"28.0481","A":"0.063","b":"27.9888","B":"2.014","o":"28.7985","c":"27.9280","h":"28.5542","l":"27.6611","v":"7.058","q":"197.8450039","p":"-0.8705","P":"-3.022726878136014","L":1417859101}}}
1633806881.9850502: {"ch":"ticker/1s","data":{"EOSUSDT":{"t":1633806881941,"a":"4.98143","A":"26.49","b":"4.98092","B":"31.66","o":"4.71891","c":"4.98523","h":"5.06033","l":"4.57171","v":"7224629.96","q":"34899840.7456554","p":"0.26632","P":"5.643676187933230","L":1417984568}}}
1633806882.023305: {"ch":"orderbook/full","update":{"HTBTC":{"t":1633806882017,"s":660804,"a":[["0.00022239","0"],["0.00022287","6848.62"]],"b":[]}}}
1633806882.023435: {"ch":"orderbook/full","update":{"EOSUSDT":{"t":1633806882000,"s":1876266,"a":[["4.98143","0"],["4.98147","26.49"],["4.98159","0"],["4.98349","0"],["4.98424","100.26"]],"b":[]}}}
1633806882.121098: {"ch":"orderbook/full","update":{"ATOMBCH":{"t":1633806882052,"s":274308,"a":[["0.1702431","0.11"]],"b":[["0.0170243","0.14"]]}}}
1633806882.122711: {"ch":"orderbook/full","update":{"EOSUSDT":{"t":1633806882104,"s":1876267,"a":[["4.98811","1851.98"],["4.98926","0"],["5.04223","0"],["5.04561","0"]],"b":[["4.98093","31.67"],["4.98003","0"],["4.97709","113.00"],["4.97351","0"],["4.97332","1450.82"],["4.96874","1988.47"],["4.96735","0"],["4.96356","0"],["4.92187","0"],["4.92087","0"],["4.91988","0"]]}}}
1633806882.129796: {"ch":"orderbook/full","update":{"USDTUSDP":{"t":1633806882073,"s":384629,"a":[["1.100000","5.73"]],"b":[["0.900000","15.11"]]}}}
1633806882.129921: {"ch":"orderbook/full","update":{"DOGEUSDT":{"t":1633806882113,"s":1308218,"a":[["0.24988933","182440"],["0.24989502","0"],["0.25003051","475940"],["0.25003366","0"],["0.25263699","423530"],["0.25264067","0"],["0.25282135","453680"],["0.25282435","0"],["0.25309210","473740"],["0.25309556","0"],["0.25366669","426140"],["0.25367253","0"]],"b":[]}}}
1633806882.220355: {"ch":"orderbook/full","update":{"NEOBTC":{"t":1633806882199,"s":1498462,"a":[["0.0008947","0"],["0.0009012","731.62"],["0.0009163","0"],["0.0009292","923.52"],["0.0009605","0"],["0.0009698","2867.67"],["0.0010108","0"],["0.0010146","4129.99"],["0.0010650","0"],["0.0010766","5847.59"],["0.0012609","0"],["0.0012691","7917.61"]],"b":[]}}}
1633806882.22545: {"ch":"orderbook/full","update":{"HTBTC":{"t":1633806882229,"s":660805,"a":[["0.00022287","0"],["0.00022403","6848.62"]],"b":[]}}}
1633806882.233438: {"ch":"orderbook/full","update":{"EOSUSDT":{"t":1633806882219,"s":1876268,"a":[["4.99596","2410.95"],["4.99914","0"]],"b":[]}}}
1633806882.3146508: {"ch":"orderbook/full","update":{"DCRETH":{"t":1633806882311,"s":499209,"a":[],"b":[["0.035905","2.273"],["0.035709","0"],["0.035617","16.000"]]}}}
1633806882.323046: {"ch":"orderbook/full","update":{"EOSUSDT":{"t":1633806882323,"s":1876269,"a":[["4.98140","26.49"],["4.98145","760.00"],["4.98147","0"]],"b":[["4.98093","0"],["4.98003","31.67"]]}}}
1633806882.418504: {"ch":"orderbook/full","update":{"NEOBTC":{"t":1633806882362,"s":1498463,"a":[],"b":[["0.0008731","166.00"],["0.0008721","0"]]}}}
1633806882.423295: {"ch":"orderbook/full","update":{"EOSUSDT":{"t":1633806882373,"s":1876270,"a":[["4.98139","26.49"],["4.98140","0"],["4.98349","100.26"],["4.98424","0"]],"b":[["4.98003","0"],["4.97905","31.67"]]}}}
1633806882.525701: {"ch":"orderbook/full","update":{"EOSUSDT":{"t":1633806882514,"s":1876271,"a":[["4.98138","26.49"],["4.98139","0"],["4.98940","1842.80"],["4.99118","0"],["5.04203","16381.41"],["5.04520","29154.10"]],"b":[["4.92197","13206.04"],["4.92097","19348.42"],["4.91998","3884.95"]]}}}
1633806882.5316339: {"ch":"orderbook/full","update":{"DOGEUSDT":{"t":1633806882516,"s":1308219,"a":[],"b":[["0.24641233","49860"],["0.24637641","0"]]}}}
1633806882.6114402: {"ch":"orderbook/full","update":{"DCRETH":{"t":1633806882536,"s":499210,"a":[],"b":[["0.035709","16.000"],["0.035617","0"]]}}}
1633806882.6168902: {"ch":"orderbook/full","update":{"NEOBTC":{"t":1633806882568,"s":1498464,"a":[],"b":[["0.0008731","72.00"],["0.0008721","94.00"]]}}}
1633806882.617014: {"ch":"orderbook/full","update":{"HTBTC":{"t":1633806882625,"s":660806,"a":[["0.00014696","0"],["0.00014717","4561.05"],["0.00022403","0"],["0.00022440","6848.62"],["0.00030403","22735.32"],["0.00030439","0"]],"b":[]}}}
1633806882.626246: {"ch":"orderbook/full","update":{"EOSUSDT":{"t":1633806882623,"s":1876272,"a":[["4.98137","26.49"],["4.98138","0"],["4.98145","0"],["4.98349","0"],["4.98424","100.26"]],"b":[["4.93309","9113.33"],["4.92059","0"],["4.84563","17800.28"],["4.78927","0"]]}}}
1633806882.626415: {"ch":"orderbook/full","update":{"USDTUSDP":{"t":1633806882577,"s":384630,"a":[["1.100000","5.82"]],"b":[["0.900000","15.20"]]}}}
1633806882.6330922: {"ch":"orderbook/full","update":{"DOGEUSDT":{"t":1633806882627,"s":1308220,"a":[["0.25009379","424640"],["0.25016691","0"],["0.25019357","409280"],["0.25025201","0"],["0.25028492","459870"],["0.25031144","0"],["0.25096700","423960"],["0.25103971","0"],["0.25107227","442100"],["0.25108525","0"],["0.25109545","362010"],["0.25114058","0"]],"b":[]}}}
1633806882.7211142: {"ch":"orderbook/full","update":{"NEOBTC":{"t":1633806882646,"s":1498465,"a":[],"b":[["0.0008778","43.00"],["0.0008772","0"]]}}}
1633806882.735329: {"ch":"orderbook/full","update":{"EOSUSDT":{"t":1633806882724,"s":1876273,"a":[["4.98137","0"],["4.98138","26.49"],["5.33515","0"],["5.35637","59703.38"],["5.45981","0"],["5.47879","93429.49"]],"b":[["4.98093","31.67"],["4.97905","0"],["4.95854","21913.34"],["4.95381","0"]]}}}
1633806882.743222: {"ch":"orderbook/full","update":{"DOGEUSDT":{"t":1633806882729,"s":1308221,"a":[["0.24978505","0"],["0.25009379","0"],["0.25010773","363370"],["0.25012235","424590"],["0.25019357","0"],["0.25020862","409250"],["0.25028492","0"],["0.25029678","459850"],["0.25087562","442450"],["0.25093198","0"],["0.25096700","0"],["0.25099375","423910"],["0.25107227","0"],["0.25107882","442090"],["0.25109545","0"],["0.25111377","361980"],["0.25147231","0"],["0.25181949","148520"],["0.25473725","370970"],["0.25475203","0"],["0.25484931","443790"],["0.25490377","0"],["0.25513557","344130"],["0.25520301","0"]],"b":[]}}}
1633806882.8380868: {"ch":"orderbook/full","update":{"DOGEUSDT":{"t":1633806882833,"s":1308222,"a":[["0.24878561","62220"],["0.24880011","0"],["0.25012235","0"],["0.25013485","424570"],["0.25020862","0"],["0.25021922","409240"],["0.25029678","0"],["0.25030079","459840"],["0.25087562","0"],["0.25089118","442420"],["0.25099375","0"],["0.25100535","423890"],["0.25111377","0"],["0.25111995","361970"],["0.25473725","0"],["0.25474411","370960"],["0.25484931","0"],["0.25487603","443740"],["0.25513557","0"],["0.25516492","344090"]],"b":[["0.24690846","0"],["0.24686963","45000"]]}}}
1633806882.923429: {"ch":"orderbook/full","update":{"NEOBTC":{"t":1633806882860,"s":1498466,"a":[],"b":[["0.0008778","0"],["0.0008772","43.00"]]}}}
1633806882.9257128: {"ch":"orderbook/full","update":{"DOGEUSDT":{"t":1633806882901,"s":1308223,"a":[],"b":[["0.24761344","75990"],["0.24758940","0"]]}}}
1633806882.9845371: {"ch":"ticker/1s","data":{"EOSUSDT":{"t":1633806882741,"a":"4.98138","A":"26.49","b":"4.98093","B":"31.67","o":"4.71891","c":"4.98523","h":"5.06033","l":"4.57171","v":"7224629.96","q":"34899840.7456554","p":"0.26632","P":"5.643676187933230","L":1417984568}}}
1633806883.0195599: {"ch":"orderbook/full","update":{"EOSUSDT":{"t":1633806882997,"s":1876274,"a":[["4.98138","760.00"],["4.98139","26.49"],["4.99329","1765.74"],["4.99628","0"],["5.00074","3221.49"],["5.00623","4270.16"],["5.00667","0"],["5.01359","0"]],"b":[["4.98093","0"],["4.98003","31.67"]]}}}
1633806883.1193259: {"ch":"orderbook/full","update":{"ATOMBCH":{"t":1633806883053,"s":274309,"a":[["0.1702431","0.14"]],"b":[["0.0170243","0.17"]]}}}
1633806883.128426: {"ch":"orderbook/full","update":{"NEOBTC":{"t":1633806883086,"s":1498467,"a":[["0.0008791","0"],["0.0008792","2.96"]],"b":[["0.0008731","166.00"],["0.0008721","0"]]}}}
1633806883.1285691: {"ch":"orderbook/full","update":{"EOSUSDT":{"t":1633806883105,"s":1876275,"a":[["4.98349","100.26"],["4.98424","0"],["4.99531","2385.82"],["4.99863","0"],["5.04203","0"],["5.04520","0"],["5.07568","0.44"]],"b":[["4.98003","0"],["4.97905","31.67"],["4.92197","0"],["4.92097","0"],["4.91998","0"]]}}}
1633806883.138613: {"ch":"orderbook/full","update":{"USDTUSDP":{"t":1633806883080,"s":384631,"a":[["1.100000","5.59"]],"b":[["0.900000","14.97"]]}}}
1633806883.1387389: {"ch":"orderbook/full","update":{"DOGEUSDT":{"t":1633806883122,"s":1308224,"a":[["0.25153445","148520"],["0.25181949","0"]],"b":[]}}}
1633806883.219031: {"ch":"orderbook/full","update":{"BORUSDT":{"t":1633806883188,"s":56260,"a":[["100000.000","0.0013"]],"b":[["0.001","1026.5999"]]}}}
1633806883.223491: {"ch":"orderbook/full","update":{"NEOBTC":{"t":1633806883144,"s":1498468,"a":[["0.0008791","2.96"],["0.0008792","0"]],"b":[]}}}
1633806883.223619: {"ch":"orderbook/full","update":{"EOSUSDT":{"t":1633806883191,"s":1876276,"a":[["4.98139","0"],["4.98142","26.49"]],"b":[["4.98092","0"],["4.98083","31.66"],["4.97453","80.40"],["4.97448","0"]]}}}
1633806883.418839: {"ch":"orderbook/full","update":{"NEOBTC":{"t":1633806883398,"s":1498469,"a":[["0.0009462","793.22"],["0.0009584","0"],["0.0027605","1063.16"],["0.0028236","0"]],"b":[]}}}
1633806883.418987: {"ch":"orderbook/full","update":{"EOSUSDT":{"t":1633806883338,"s":1876277,"a":[["4.98593","391.27"],["4.98695","0"]],"b":[]}}}
1633806883.427799: {"ch":"orderbook/full","update":{"DOGEUSDT":{"t":1633806883426,"s":1308225,"a":[["0.24989870","363370"],["0.25010773","0"],["0.25013485","0"],["0.25013735","424560"],["0.25021922","0"],["0.25022092","409230"],["0.25089118","0"],["0.25089399","442410"]],"b":[]}}}
1633806883.54275: {"ch":"orderbook/full","update":{"DCRETH":{"t":1633806883516,"s":499211,"a":[],"b":[["0.035998","2.474"]]}}}
1633806883.542869: {"ch":"orderbook/full","update":{"NEOBTC":{"t":1633806883515,"s":1498470,"a":[],"b":[["0.0008778","43.00"],["0.0008772","0"],["0.0008731","72.00"],["0.0008721","94.00"]]}}}
1633806883.542946: {"ch":"orderbook/full","update":{"EOSUSDT":{"t":1633806883501,"s":1876278,"a":[["4.98138","0"],["4.98142","0"],["4.98145","26.49"],["4.98349","0"],["4.98424","100.26"],["5.04183","16381.41"],["5.04446","29154.10"]],"b":[["4.92207","13206.04"],["4.92107","19348.42"],["4.92008","3884.95"],["4.91496","11826.73"],["4.88446","0"]]}}}
1633806883.6148732: {"ch":"orderbook/full","update":{"DCRETH":{"t":1633806883606,"s":499212,"a":[],"b":[["0.035999","0.050"]]}}}
1633806883.6297479: {"ch":"orderbook/full","update":{"NEOBTC":{"t":1633806883583,"s":1498471,"a":[["0.0008791","0"],["0.0008792","2.96"]],"b":[]}}}
1633806883.6485472: {"ch":"orderbook/full","update":{"EOSUSDT":{"t":1633806883610,"s":1876279,"a":[["4.98137","760.00"],["4.98145","0"],["4.98147","26.49"]],"b":[["4.98003","31.67"],["4.97905","0"]]}}}
1633806883.648696: {"ch":"orderbook/full","update":{"USDTUSDP":{"t":1633806883585,"s":384632,"a":[["1.100000","5.66"]],"b":[["0.900000","15.04"]]}}}
1633806883.648758: {"ch":"orderbook/full","update":{"DOGEUSDT":{"t":1633806883548,"s":1308226,"a":[["0.24985766","182460"],["0.24988933","0"],["0.24991594","343310"],["0.24994630","0"],["0.24999074","476010"],["0.25003051","0"],["0.25100535","0"],["0.25101257","423880"],["0.25107882","0"],["0.25108062","442080"],["0.25117788","381400"],["0.25120906","0"],["0.25257526","423630"],["0.25263699","0"],["0.25276909","453770"],["0.25282135","0"],["0.25303299","473850"],["0.25309210","0"],["0.25323465","457280"],["0.25329235","0"],["0.25343383","336970"],["0.25345892","0"],["0.25361870","426230"],["0.25366669","0"],["0.25462805","388800"],["0.25464960","0"]],"b":[]}}}
1633806883.712558: {"ch":"orderbook/full","update":{"DCRETH":{"t":1633806883668,"s":499213,"a":[],"b":[["0.035998","0"]]}}}
1633806883.722929: {"ch":"orderbook/full","update":{"NEOBTC":{"t":1633806883734,"s":1498472,"a":[["0.0008791","2.96"],["0.0008792","0"]],"b":[["0.0008780","14.15"],["0.0008779","0"],["0.0008778","0"],["0.0008772","43.00"],["0.0008732","72.00"],["0.0008731","0"],["0.0007215","557.30"],["0.0006844","1157.34"]]}}}
1633806883.743548: {"ch":"orderbook/full","update":{"HTBTC":{"t":1633806883717,"s":660807,"a":[["0.00014717","0"],["0.00014740","4561.05"],["0.00022440","0"],["0.00022949","6848.62"]],"b":[]}}}
1633806883.743711: {"ch":"orderbook/full","update":{"DOGEUSDT":{"t":1633806883675,"s":1308227,"a":[["0.24985766","0"],["0.24986534","182450"],["0.24991594","0"],["0.24992304","343300"],["0.24999074","0"],["0.25000197","475990"],["0.25013735","0"],["0.25014673","424550"],["0.25022092","0"],["0.25023087","409220"],["0.25030079","0"],["0.25030539","459830"],["0.25089399","0"],["0.25091055","442380"],["0.25101257","0"],["0.25102382","423860"],["0.25111995","0"],["0.25113103","361960"],["0.25117788","0"],["0.25118605","381390"],["0.25257526","0"],["0.25259844","423590"],["0.25276909","0"],["0.25278681","453740"],["0.25303299","0"],["0.25305658","473800"],["0.25323465","0"],["0.25325624","457240"],["0.25343383","0"],["0.25344808","336950"],["0.25361870","0"],["0.25364875","426170"],["0.25462805","0"],["0.25464558","388770"],["0.25474411","0"],["0.25474656","370950"],["0.25487603","0"],["0.25488438","443730"],["0.25516492","0"],["0.25517516","344070"]],"b":[]}}}
1633806883.814579: {"ch":"orderbook/full","update":{"DCRETH":{"t":1633806883768,"s":499214,"a":[],"b":[["0.035999","0"],["0.035985","0.057"]]}}}
1633806883.840106: {"ch":"orderbook/full","update":{"EOSUSDT":{"t":1633806883834,"s":1876280,"a":[["4.98349","100.26"],["4.98424","0"]],"b":[["4.98088","31.66"],["4.98083","0"],["4.96606","960.00"],["4.96531","0"],["4.69453","7565.88"],["4.58107","0"]]}}}
1633806883.840275: {"ch":"orderbook/full","update":{"DOGEUSDT":{"t":1633806883801,"s":1308228,"a":[["0.25118605","0"],["0.25119746","381370"],["0.25259844","0"],["0.25262761","423540"],["0.25278681","0"],["0.25281133","453690"],["0.25305658","0"],["0.25308464","473750"],["0.25325624","0"],["0.25328419","457190"],["0.25344808","0"],["0.25346621","336920"],["0.25364875","0"],["0.25368950","426110"],["0.25464558","0"],["0.25466519","388740"],["0.25474656","0"],["0.25475463","370940"],["0.25488438","0"],["0.25491708","443670"],["0.25517516","0"],["0.25521819","344010"]],"b":[]}}}
1633806883.933238: {"ch":"orderbook/full","update":{"DCRETH":{"t":1633806883864,"s":499215,"a":[],"b":[["0.035986","4.250"]]}}}
1633806883.9333608: {"ch":"orderbook/full","update":{"NEOBTC":{"t":1633806883919,"s":1498473,"a":[["0.0008830","24.00"],["0.0008842","72.00"],["0.0009462","0"],["0.0009571","793.22"],["0.0027605","0"],["0.0028172","1063.16"]],"b":[["0.0008745","24.00"],["0.0008741","0"],["0.0008732","0"],["0.0008731","72.00"]]}}}
1633806883.933485: {"ch":"orderbook/full","update":{"EOSUSDT":{"t":1633806883904,"s":1876281,"a":[["4.98147","0"],["4.98155","26.49"]],"b":[["4.98088","0"],["4.98080","31.66"],["4.98003","0"],["4.97905","31.67"],["4.97801","0"],["4.97701","154.19"],["4.97456","525.44"],["4.97453","0"]]}}}
1633806883.933588: {"ch":"orderbook/full","update":{"DOGEUSDT":{"t":1633806883903,"s":1308229,"a":[["0.25368950","0"],["0.25369185","426100"]],"b":[["0.24735294","87230"],["0.24725407","0"]]}}}
1633806883.988099: {"ch":"ticker/1s","data":{"DCRETH":{"t":1633806883938,"a":"0.036730","A":"0.448","b":"0.035986","B":"4.250","o":"0.035004","c":"0.036373","h":"0.036686","l":"0.035072","v":"8.326","q":"0.297986431","p":"0.001369","P":"3.910981602102617","L":1417957304}}}
1633806883.988191: {"ch":"ticker/1s","data":{"EOSUSDT":{"t":1633806883943,"a":"4.98137","A":"760.00","b":"4.98080","B":"31.66","o":"4.71891","c":"4.98523","h":"5.06033","l":"4.57171","v":"7224629.96","q":"34899840.7456554","p":"0.26632","P":"5.643676187933230","L":1417984568}}}
1633806884.0110888: {"ch":"orderbook/full","update":{"DCRETH":{"t":1633806883965,"s":499216,"a":[],"b":[["0.035987","0.060"],["0.035985","0"]]}}}
1633806884.03596: {"ch":"orderbook/full","update":{"EOSUSDT":{"t":1633806884035,"s":1876282,"a":[["4.98113","26.49"],["4.98155","0"],["4.99191","240.00"],["4.99327","0"]],"b":[["4.98080","0"],["4.98037","31.66"],["4.98002","0"],["4.97750","0"],["4.97731","471.98"],["4.97702","0"],["4.97663","0"],["4.97615","457.24"],["4.97604","939.97"],["4.97545","1723.94"],["4.97471","1636.04"],["4.94699","6751.44"],["4.93368","0"]]}}}
1633806884.127313: {"ch":"orderbook/full","update":{"DCRETH":{"t":1633806884062,"s":499217,"a":[],"b":[["0.035988","4.250"],["0.035986","0"]]}}}
1633806884.127441: {"ch":"orderbook/full","update":{"ATOMBCH":{"t":1633806884063,"s":274310,"a":[["0.1702356","0.15"],["0.1702431","0"]],"b":[]}}}
1633806884.127508: {"ch":"orderbook/full","update":{"NEOBTC":{"t":1633806884125,"s":1498474,"a":[["0.0008830","0"],["0.0008841","72.00"],["0.0008842","24.00"]],"b":[["0.0008745","0"],["0.0008741","24.00"],["0.0008731","166.00"],["0.0008721","0"],["0.0007215","0"],["0.0006844","1714.64"]]}}}
1633806884.127611: {"ch":"orderbook/full","update":{"EOSUSDT":{"t":1633806884132,"s":1876283,"a":[["4.98100","26.49"],["4.98113","0"],["4.98275","63.97"],["4.98351","0"],["5.02697","0"],["5.02706","79.56"],["5.04183","0"],["5.04446","0"]],"b":[["4.98037","0"],["4.98030","31.66"],["4.92207","0"],["4.92107","0"],["4.92008","0"]]}}}
1633806884.128737: {"ch":"orderbook/full","update":{"USDTUSDP":{"t":1633806884090,"s":384633,"a":[["1.100000","6.36"]],"b":[["0.900000","15.74"]]}}}
1633806884.1288278: {"ch":"orderbook/full","update":{"DOGEUSDT":{"t":1633806884101,"s":1308230,"a":[],"b":[["0.24641233","0"],["0.24636760","49860"]]}}}
1633806884.210801: {"ch":"orderbook/full","update":{"DCRETH":{"t":1633806884167,"s":499218,"a":[],"b":[["0.035989","0.065"],["0.035987","0"]]}}}
1633806884.215958: {"ch":"orderbook/full","update":{"NEOBTC":{"t":1633806884234,"s":1498475,"a":[],"b":[["0.0008780","10.61"],["0.0008779","3.54"]]}}}
1633806884.2241988: {"ch":"orderbook/full","update":{"HTBTC":{"t":1633806884218,"s":660808,"a":[["0.00029765","17212.22"],["0.00029799","0"]],"b":[]}}}
1633806884.2443001: {"ch":"orderbook/full","update":{"EOSUSDT":{"t":1633806884229,"s":1876284,"a":[["4.98082","26.49"],["4.98100","0"],["4.98273","100.26"],["4.98274","100.26"],["4.98349","0"],["4.98350","0"],["5.02630","79.58"],["5.02706","0"]],"b":[["4.98030","0"],["4.98025","31.66"],["4.97601","2591.43"],["4.97501","1773.87"],["4.97456","445.04"],["4.97411","80.41"]]}}}
1633806884.3171148: {"ch":"orderbook/full","update":{"DCRETH":{"t":1633806884264,"s":499219,"a":[],"b":[["0.035990","4.250"],["0.035988","0"]]}}}
1633806884.3181: {"ch":"orderbook/full","update":{"NEOBTC":{"t":1633806884318,"s":1498476,"a":[["0.0008841","24.00"],["0.0008842","72.00"]],"b":[["0.0008745","24.00"],["0.0008741","0"]]}}}
1633806884.323493: {"ch":"orderbook/full","update":{"EOSUSDT":{"t":1633806884331,"s":1876285,"a":[["4.98071","100.26"],["4.98072","26.49"],["4.98082","0"],["4.98274","0"],["4.99009","2448.24"],["4.99267","0"],["4.99390","700.00"],["4.99440","0"],["5.00244","3908.49"],["5.00886","0"],["5.01162","5507.50"],["5.01962","0"],["5.02630","0"],["5.02640","79.57"],["5.03796","6980.08"],["5.04713","0"]],"b":[["4.98025","0"],["4.97988","31.66"],["4.97905","0"],["4.97871","0"],["4.97859","0"],["4.97824","58.80"],["4.97783","31.67"],["4.97750","1102.55"],["4.97731","0"],["4.97638","471.98"],["4.97601","1674.24"],["4.97501","2691.06"],["4.97092","0"],["4.97008","240.00"],["4.96941","0"],["4.96879","700.00"]]}}}
1633806884.414762: {"ch":"orderbook/full","update":{"DCRETH":{"t":1633806884370,"s":499220,"a":[],"b":[["0.035991","0.070"],["0.035989","0"]]}}}
1633806884.428847: {"ch":"orderbook/full","update":{"EOSUSDT":{"t":1633806884432,"s":1876286,"a":[["4.98039","760.00"],["4.98049","26.49"],["4.98071","0"],["4.98072","0"],["4.98135","100.26"],["4.98136","100.26"],["4.98273","0"],["5.01190","0"],["5.01345","30.00"]],"b":[["4.97988","0"],["4.97950","31.66"],["4.97824","0"],["4.97774","58.80"],["4.97459","80.40"],["4.97411","0"],["4.96606","0"],["4.96523","960.00"]]}}}
1633806884.512563: {"ch":"orderbook/full","update":{"DCRETH":{"t":1633806884464,"s":499221,"a":[],"b":[["0.035992","4.250"],["0.035990","0"],["0.035709","0"],["0.035617","16.000"]]}}}
1633806884.536441: {"ch":"orderbook/full","update":{"XVSUSDT":{"t":1633806884500,"s":484023,"a":[],"b":[["27.9888","178.833"],["27.9775","109.088"],["27.9736","0"],["27.9599","102.335"],["27.9584","0"],["27.9533","0"],["27.9370","0"]]}}}
1633806884.536591: {"ch":"orderbook/full","update":{"NEOBTC":{"t":1633806884436,"s":1498477,"a":[["0.0008840","24.00"],["0.0008841","0"]],"b":[]}}}
1633806884.5366552: {"ch":"orderbook/full","update":{"HTBTC":{"t":1633806884524,"s":660809,"a":[["0.00014713","4561.05"],["0.00014740","0"]],"b":[]}}}
1633806884.536711: {"ch":"orderbook/full","update":{"EOSUSDT":{"t":1633806884523,"s":1876287,"a":[["4.98922","685.96"],["4.99022","0"],["4.99031","1019.31"],["4.99122","0"],["5.04153","16381.41"],["5.04643","29154.10"]],"b":[["4.97951","760.00"],["4.96879","0"],["4.96824","3345.54"],["4.95026","0"],["4.94699","0"],["4.93859","6107.92"],["4.93309","0"],["4.93054","6751.44"],["4.92197","13206.04"],["4.92097","19348.42"],["4.91998","3884.95"],["4.91496","0"],["4.91427","9113.33"],["4.88739","11826.73"],["4.84563","0"],["4.80672","17800.28"],["4.69453","0"],["4.58107","7565.88"]]}}}
1633806884.536905: {"ch":"orderbook/full","update":{"DOGEUSDT":{"t":1633806884459,"s":1308231,"a":[["0.25000197","0"],["0.25000652","475980"],["0.25014673","0"],["0.25015005","424540"],["0.25023087","0"],["0.25023226","409210"],["0.25102382","0"],["0.25102666","423850"],["0.25113103","0"],["0.25113357","361950"],["0.25119746","0"],["0.25120175","381360"],["0.25262761","0"],["0.25263706","423530"],["0.25281133","0"],["0.25282093","453680"],["0.25308464","0"],["0.25309267","473730"],["0.25328419","0"],["0.25329370","457170"],["0.25369185","0"],["0.25370475","426080"],["0.25466519","0"],["0.25467077","388730"],["0.25491708","0"],["0.25493147","443640"],["0.25521819","0"],["0.25522941","344000"]],"b":[]}}}
1633806884.612483: {"ch":"orderbook/full","update":{"DCRETH":{"t":1633806884569,"s":499222,"a":[],"b":[["0.035993","0.075"],["0.035991","0"]]}}}
1633806884.620024: {"ch":"orderbook/full","update":{"XVSUSDT":{"t":1633806884600,"s":484024,"a":[],"b":[["27.9520","168.599"],["27.8823","199.881"],["27.8691","0"],["27.7895","221.917"],["27.7870","0"],["27.7420","0"],["27.7243","293.088"],["27.6823","0"]]}}}
1633806884.620183: {"ch":"orderbook/full","update":{"NEOBTC":{"t":1633806884631,"s":1498478,"a":[["0.0008840","0"],["0.0008841","72.00"],["0.0008842","24.00"],["0.0008946","731.62"],["0.0009012","0"],["0.0009168","923.52"],["0.0009292","0"]],"b":[]}}}
1633806884.620275: {"ch":"orderbook/full","update":{"EOSUSDT":{"t":1633806884566,"s":1876288,"a":[["4.99221","1348.10"],["4.99321","0"]],"b":[["4.97836","31.67"],["4.97783","0"],["4.97008","0"],["4.96955","240.00"]]}}}
1633806884.620383: {"ch":"orderbook/full","update":{"USDTUSDP":{"t":1633806884612,"s":384634,"a":[["1.100000","5.75"]],"b":[["0.900000","15.13"]]}}}
1633806884.715862: {"ch":"orderbook/full","update":{"DCRETH":{"t":1633806884664,"s":499223,"a":[],"b":[["0.035994","4.250"],["0.035992","0"]]}}}
1633806884.723959: {"ch":"orderbook/full","update":{"EOSUSDT":{"t":1633806884650,"s":1876289,"a":[["4.98449","391.27"],["4.98593","0"]],"b":[]}}}
1633806884.726141: {"ch":"orderbook/full","update":{"DOGEUSDT":{"t":1633806884718,"s":1308232,"a":[["0.24989870","0"],["0.25008963","363370"],["0.25153445","0"],["0.25179494","148520"]],"b":[]}}}
1633806884.813756: {"ch":"orderbook/full","update":{"DCRETH":{"t":1633806884774,"s":499224,"a":[],"b":[["0.035995","0.080"],["0.035993","0"]]}}}
1633806884.829958: {"ch":"orderbook/full","update":{"NEOBTC":{"t":1633806884826,"s":1498479,"a":[["0.0008840","72.00"],["0.0008841","24.00"],["0.0008842","0"]],"b":[]}}}
1633806884.830097: {"ch":"orderbook/full","update":{"EOSUSDT":{"t":1633806884802,"s":1876290,"a":[["4.98499","2289.11"],["4.98599","1685.82"],["5.05328","8821.94"],["5.08898","0"]],"b":[]}}}
1633806884.91341: {"ch":"orderbook/full","update":{"DCRETH":{"t":1633806884864,"s":499225,"a":[],"b":[["0.035996","4.250"],["0.035994","0"]]}}}
1633806884.9268281: {"ch":"orderbook/full","update":{"HTBTC":{"t":1633806884838,"s":660810,"a":[["0.00025318","8802.07"],["0.00025595","0"],["0.00026687","11985.76"],["0.00026834","0"]],"b":[]}}}
1633806884.98073: {"ch":"ticker/1s","data":{"DCRETH":{"t":1633806884938,"a":"0.036730","A":"0.448","b":"0.035996","B":"4.250","o":"0.035004","c":"0.036373","h":"0.036686","l":"0.035072","v":"8.326","q":"0.297986431","p":"0.001369","P":"3.910981602102617","L":1417957304}}}
1633806884.98082: {"ch":"ticker/1s","data":{"XVSUSDT":{"t":1633806884640,"a":"28.0481","A":"0.063","b":"27.9888","B":"178.833","o":"28.7985","c":"27.9280","h":"28.5542","l":"27.6611","v":"7.058","q":"197.8450039","p":"-0.8705","P":"-3.022726878136014","L":1417859101}}}
1633806884.980861: {"ch":"ticker/1s","data":{"EOSUSDT":{"t":1633806884844,"a":"4.98039","A":"760.00","b":"4.97951","B":"760.00","o":"4.71891","c":"4.98523","h":"5.06033","l":"4.57171","v":"7224629.96","q":"34899840.7456554","p":"0.26632","P":"5.643676187933230","L":1417984568}}}
1633806885.018991: {"ch":"orderbook/full","update":{"DCRETH":{"t":1633806884966,"s":499226,"a":[],"b":[["0.035997","0.085"],["0.035995","0"]]}}}
1633806885.0308108: {"ch":"orderbook/full","update":{"NEOBTC":{"t":1633806885017,"s":1498480,"a":[["0.0008840","0"],["0.0008841","0"],["0.0008842","96.00"]],"b":[["0.0008780","14.15"],["0.0008779","0"]]}}}
1633806885.030933: {"ch":"orderbook/full","update":{"HTBTC":{"t":1633806884937,"s":660811,"a":[],"b":[["0.00014124","981.99"],["0.00014115","0"]]}}}
1633806885.030995: {"ch":"orderbook/full","update":{"EOSUSDT":{"t":1633806884950,"s":1876291,"a":[["4.98449","1379.87"],["4.98516","1612.05"],["4.98740","0"],["4.98764","0"]],"b":[]}}}
1633806885.126189: {"ch":"orderbook/full","update":{"DCRETH":{"t":1633806885079,"s":499227,"a":[],"b":[["0.035998","0.070"],["0.035996","0"]]}}}
