1618677899.676266: {"channel": "orderbook", "market": "SXPBULL/USD", "type": "update", "data": {"time": 1618677899.5709298, "checksum": 1740032145, "bids": [], "asks": [], "action": "update"}}
1618677899.6793878: {"channel": "orderbook", "market": "AKRO/USD", "type": "update", "data": {"time": 1618677899.6054926, "checksum": 1299003101, "bids": [], "asks": [], "action": "update"}}
1618677899.685707: {"channel": "orderbook", "market": "NVDA-0625", "type": "update", "data": {"time": 1618677899.609846, "checksum": 3644189371, "bids": [], "asks": [], "action": "update"}}
1618677899.733647: {"channel": "orderbook", "market": "XRP/USD", "type": "update", "data": {"time": 1618677899.6580703, "checksum": 3965134761, "bids": [], "asks": [[1.59745, 0.0], [1.6215, 6.0]], "action": "update"}}
1618677899.773823: {"channel": "orderbook", "market": "SXPBULL/USD", "type": "update", "data": {"time": 1618677899.6893125, "checksum": 4185438320, "bids": [[51.175, 3.862]], "asks": [[52.425, 2.393]], "action": "update"}}
1618677899.812754: {"channel": "orderbook", "market": "XRP/USD", "type": "update", "data": {"time": 1618677899.73618, "checksum": 1238773673, "bids": [], "asks": [[1.594225, 246256.0]], "action": "update"}}
1618677899.819814: {"channel": "orderbook", "market": "SXPBULL/USD", "type": "update", "data": {"time": 1618677899.7384753, "checksum": 398826109, "bids": [[51.075, 2.676], [50.7, 1.702]], "asks": [], "action": "update"}}
1618677899.8637471: {"channel": "orderbook", "market": "XRP/USD", "type": "update", "data": {"time": 1618677899.784823, "checksum": 1981615245, "bids": [], "asks": [[1.590925, 0.0], [1.591125, 633.0]], "action": "update"}}
1618677899.925786: {"channel": "orderbook", "market": "THETAHEDGE/USD", "type": "update", "data": {"time": 1618677899.8497946, "checksum": 3670658753, "bids": [], "asks": [], "action": "update"}}
1618677899.9287958: {"channel": "orderbook", "market": "SXPBULL/USD", "type": "update", "data": {"time": 1618677899.844525, "checksum": 3362243921, "bids": [[51.175, 89.993]], "asks": [], "action": "update"}}
1618677899.9365919: {"channel": "orderbook", "market": "XRP/USD", "type": "update", "data": {"time": 1618677899.8598707, "checksum": 3700427976, "bids": [[1.587475, 1436.0]], "asks": [[1.591375, 0.0], [1.6225, 1413.0]], "action": "update"}}
1618677899.948533: {"channel": "orderbook", "market": "SXPBULL/USD", "type": "update", "data": {"time": 1618677899.8662045, "checksum": 1701270751, "bids": [], "asks": [[51.975, 0.242]], "action": "update"}}
1618677899.958163: {"channel": "orderbook", "market": "PAXG/USD", "type": "update", "data": {"time": 1618677899.8733482, "checksum": 852366897, "bids": [], "asks": [], "action": "update"}}
1618677899.964056: {"channel": "orderbook", "market": "XRP/USD", "type": "update", "data": {"time": 1618677899.8850284, "checksum": 3584333295, "bids": [], "asks": [[1.595925, 188.0], [1.6225, 0.0]], "action": "update"}}
1618677899.973506: {"channel": "orderbook", "market": "ZECBULL/USD", "type": "update", "data": {"time": 1618677899.897989, "checksum": 3244957388, "bids": [[7210.0, 0.0]], "asks": [], "action": "update"}}
1618677900.002235: {"channel": "orderbook", "market": "XRP/USD", "type": "update", "data": {"time": 1618677899.9212444, "checksum": 4177539826, "bids": [[1.5885, 0.0], [1.5542, 1412.0]], "asks": [[1.591025, 5.0], [1.59135, 0.0]], "action": "update"}}
1618677900.03756: {"channel": "orderbook", "market": "XRP/USD", "type": "update", "data": {"time": 1618677899.9464989, "checksum": 2996955609, "bids": [], "asks": [[1.591125, 0.0], [1.6225, 1413.0]], "action": "update"}}
1618677900.043395: {"channel": "orderbook", "market": "SXPBULL/USD", "type": "update", "data": {"time": 1618677899.964301, "checksum": 682521807, "bids": [[51.025, 6.006]], "asks": [], "action": "update"}}
1618677900.067758: {"channel": "orderbook", "market": "XRP/USD", "type": "update", "data": {"time": 1618677899.9895823, "checksum": 1993600387, "bids": [[1.587825, 1412.0], [1.586925, 9000.0], [1.55525, 0.0], [1.5542, 0.0]], "asks": [[1.590575, 0.0], [1.592125, 633.0], [1.593475, 0.0], [1.623, 8078.0]], "action": "update"}}
1618677900.123997: {"channel": "orderbook", "market": "BTC-MOVE-WK-0507", "type": "update", "data": {"time": 1618677900.0383737, "checksum": 901794806, "bids": [], "asks": [], "action": "update"}}
1618677900.146352: {"channel": "orderbook", "market": "SXPBULL/USD", "type": "update", "data": {"time": 1618677900.0640097, "checksum": 1024815623, "bids": [[51.175, 3.862]], "asks": [], "action": "update"}}
1618677900.281683: {"channel": "orderbook", "market": "SXPBULL/USD", "type": "update", "data": {"time": 1618677900.1901517, "checksum": 3356907548, "bids": [], "asks": [[52.35, 2.17]], "action": "update"}}
1618677900.40433: {"channel": "orderbook", "market": "SXPBULL/USD", "type": "update", "data": {"time": 1618677900.313004, "checksum": 1733898923, "bids": [], "asks": [[52.5, 43.531]], "action": "update"}}
1618677900.43593: {"channel": "orderbook", "market": "XRP/USD", "type": "update", "data": {"time": 1618677900.3201644, "checksum": 1842545062, "bids": [[1.5892, 2516.0], [1.588675, 1733.0], [1.588275, 310542.0], [1.586925, 0.0], [1.585, 1532.0], [1.58, 1544.0], [1.5553, 0.0]], "asks": [[1.59075, 0.0], [1.59165, 0.0], [1.591975, 2514.0], [1.5925, 1434.0], [1.5927, 1488.0], [1.593, 1506.0], [1.593075, 0.0], [1.5941, 0.0], [1.595225, 0.0], [1.623175, 2.0], [1.62335, 8051.0]], "action": "update"}}
1618677900.4522939: {"channel": "orderbook", "market": "XRP/USD", "type": "update", "data": {"time": 1618677900.375589, "checksum": 3618451170, "bids": [[1.588175, 1367.0], [1.58645, 0.0], [1.5855, 0.0], [1.5553, 6.0]], "asks": [[1.591025, 0.0], [1.591925, 0.0], [1.592125, 0.0], [1.592375, 633.0], [1.5963, 0.0], [1.597, 0.0], [1.6235, 4.0], [1.6239, 1.0], [1.62425, 4.0], [1.624325, 6.0]], "action": "update"}}
1618677900.474607: {"channel": "orderbook", "market": "XRP/USD", "type": "update", "data": {"time": 1618677900.3998477, "checksum": 3121934965, "bids": [[1.5892, 0.0], [1.588675, 633.0], [1.55525, 1.0]], "asks": [[1.591975, 0.0], [1.6256, 1.0]], "action": "update"}}
1618677900.493792: {"channel": "orderbook", "market": "AMD/USD", "type": "update", "data": {"time": 1618677900.422108, "checksum": 1935389369, "bids": [], "asks": [], "action": "update"}}
1618677900.5025332: {"channel": "orderbook", "market": "THETAHEDGE/USD", "type": "update", "data": {"time": 1618677900.4307725, "checksum": 3734690219, "bids": [[24.9225, 128.63]], "asks": [], "action": "update"}}
1618677900.5155032: {"channel": "orderbook", "market": "SUSHIBEAR/USD", "type": "update", "data": {"time": 1618677900.426841, "checksum": 3649246176, "bids": [[1.19e-05, 25500000.0], [1.18e-05, 0.0], [1.175e-05, 0.0], [1.17e-05, 2100000.0]], "asks": [[1.235e-05, 0.0], [0.04, 1091000.0]], "action": "update"}}
1618677900.5345669: {"channel": "orderbook", "market": "XRP/USD", "type": "update", "data": {"time": 1618677900.4544942, "checksum": 414730478, "bids": [[1.5892, 5260.0], [1.58805, 9000.0], [1.5553, 0.0], [1.55525, 0.0]], "asks": [[1.5918, 1100.0], [1.592475, 5526.0], [1.59255, 0.0], [1.592575, 0.0]], "action": "update"}}
1618677900.561696: {"channel": "orderbook", "market": "XRP/USD", "type": "update", "data": {"time": 1618677900.4811988, "checksum": 3178235163, "bids": [[1.58885, 1100.0], [1.5554, 0.0]], "asks": [[1.5918, 0.0], [1.5922, 1100.0], [1.5957, 1685.0], [1.5985, 1308.0], [1.6256, 0.0]], "action": "update"}}
1618677900.563191: {"channel": "orderbook", "market": "SXPBULL/USD", "type": "update", "data": {"time": 1618677900.4837391, "checksum": 3846630258, "bids": [[51.2, 64.974]], "asks": [], "action": "update"}}
1618677900.564024: {"channel": "orderbook", "market": "ZECBULL/USD", "type": "update", "data": {"time": 1618677900.4916553, "checksum": 3379166829, "bids": [[7155.0, 0.02748]], "asks": [], "action": "update"}}
1618677900.567245: {"channel": "orderbook", "market": "SUSHIBEAR/USD", "type": "update", "data": {"time": 1618677900.4884698, "checksum": 621518657, "bids": [[1.18e-05, 8530000.0], [1.17e-05, 10780000.0], [1.165e-05, 8660000.0]], "asks": [[1.255e-05, 25010000.0]], "action": "update"}}
1618677900.5763452: {"channel": "orderbook", "market": "XRP/USD", "type": "update", "data": {"time": 1618677900.4965556, "checksum": 3660972869, "bids": [[1.58885, 0.0], [1.5554, 1.0]], "asks": [], "action": "update"}}
1618677900.6009111: {"channel": "orderbook", "market": "XRP/USD", "type": "update", "data": {"time": 1618677900.525367, "checksum": 1295634937, "bids": [[1.589375, 1100.0], [1.58805, 0.0]], "asks": [[1.592475, 0.0], [1.59635, 0.0], [1.6256, 1.0], [1.6258, 1.0]], "action": "update"}}
1618677900.6049972: {"channel": "orderbook", "market": "SUSHIBEAR/USD", "type": "update", "data": {"time": 1618677900.5285075, "checksum": 3614867403, "bids": [[1.175e-05, 8460000.0]], "asks": [], "action": "update"}}
1618677900.6179159: {"channel": "orderbook", "market": "ZECBULL/USD", "type": "update", "data": {"time": 1618677900.5432441, "checksum": 3379166829, "bids": [], "asks": [], "action": "update"}}
1618677900.624513: {"channel": "orderbook", "market": "XRP/USD", "type": "update", "data": {"time": 1618677900.5509934, "checksum": 474312214, "bids": [], "asks": [[1.593975, 1051.0], [1.6258, 0.0]], "action": "update"}}
1618677900.675491: {"channel": "orderbook", "market": "SXPBULL/USD", "type": "update", "data": {"time": 1618677900.5865226, "checksum": 3846630258, "bids": [], "asks": [], "action": "update"}}
1618677900.684201: {"channel": "orderbook", "market": "XRP/USD", "type": "update", "data": {"time": 1618677900.6076937, "checksum": 1015659739, "bids": [[1.5805, 1664.0], [1.5554, 0.0]], "asks": [[1.5935, 1525.0], [1.5969, 1569.0], [1.6256, 0.0]], "action": "update"}}
1618677900.705476: {"channel": "orderbook", "market": "XRP/USD", "type": "update", "data": {"time": 1618677900.6283104, "checksum": 2120017800, "bids": [[1.58825, 9000.0], [1.55565, 0.0]], "asks": [[1.593975, 6705.0]], "action": "update"}}
1618677900.7063098: {"channel": "orderbook", "market": "AKRO/USD", "type": "update", "data": {"time": 1618677900.63179, "checksum": 1299003101, "bids": [], "asks": [], "action": "update"}}
1618677900.732235: {"channel": "orderbook", "market": "NVDA-0625", "type": "update", "data": {"time": 1618677900.6532419, "checksum": 3644189371, "bids": [], "asks": [], "action": "update"}}
1618677900.749303: {"channel": "orderbook", "market": "XRP/USD", "type": "update", "data": {"time": 1618677900.6733289, "checksum": 460304029, "bids": [], "asks": [[1.593975, 10865.0]], "action": "update"}}
1618677900.826091: {"channel": "orderbook", "market": "SXPBULL/USD", "type": "update", "data": {"time": 1618677900.74069, "checksum": 1733898923, "bids": [[51.2, 1.717]], "asks": [], "action": "update"}}
1618677900.826147: {"channel": "orderbook", "market": "XRP/USD", "type": "update", "data": {"time": 1618677900.7519586, "checksum": 2174658117, "bids": [[1.5887, 18.0], [1.588675, 0.0]], "asks": [], "action": "update"}}
1618677900.8496928: {"channel": "orderbook", "market": "XRP/USD", "type": "update", "data": {"time": 1618677900.7771385, "checksum": 3394856311, "bids": [[1.589075, 633.0], [1.5561, 0.0]], "asks": [[1.590575, 5.0], [1.5982, 188.0], [1.62425, 0.0], [1.624325, 0.0]], "action": "update"}}
1618677900.861691: {"channel": "orderbook", "market": "SXPBULL/USD", "type": "update", "data": {"time": 1618677900.774512, "checksum": 2713578134, "bids": [], "asks": [[52.55, 43.246]], "action": "update"}}
1618677900.9531991: {"channel": "orderbook", "market": "XRP/USD", "type": "update", "data": {"time": 1618677900.871205, "checksum": 2520021407, "bids": [[1.5896, 2515.0], [1.5894, 63.0], [1.5571, 0.0], [1.556625, 0.0]], "asks": [[1.594125, 4870.0], [1.6239, 0.0]], "action": "update"}}
1618677900.953402: {"channel": "orderbook", "market": "THETAHEDGE/USD", "type": "update", "data": {"time": 1618677900.8739793, "checksum": 3734690219, "bids": [], "asks": [], "action": "update"}}
1618677900.993268: {"channel": "orderbook", "market": "ZECBULL/USD", "type": "update", "data": {"time": 1618677900.9186642, "checksum": 1741367334, "bids": [[7220.0, 0.0]], "asks": [], "action": "update"}}
1618677900.9975638: {"channel": "orderbook", "market": "XRP/USD", "type": "update", "data": {"time": 1618677900.9045146, "checksum": 791493783, "bids": [[1.589375, 0.0], [1.5571, 10.0]], "asks": [[1.590575, 0.0], [1.6239, 1.0]], "action": "update"}}
1618677901.013579: {"channel": "orderbook", "market": "SXPBULL/USD", "type": "update", "data": {"time": 1618677900.925641, "checksum": 1580244799, "bids": [[51.2, 64.974]], "asks": [], "action": "update"}}
1618677901.0188649: {"channel": "orderbook", "market": "PAXG/USD", "type": "update", "data": {"time": 1618677900.9249554, "checksum": 852366897, "bids": [], "asks": [], "action": "update"}}
1618677901.045318: {"channel": "orderbook", "market": "XRP/USD", "type": "update", "data": {"time": 1618677900.960474, "checksum": 3090902710, "bids": [[1.589775, 1100.0], [1.589075, 0.0]], "asks": [], "action": "update"}}
1618677901.084219: {"channel": "orderbook", "market": "XRP/USD", "type": "update", "data": {"time": 1618677900.9893138, "checksum": 2850399744, "bids": [[1.5886, 633.0], [1.5571, 0.0]], "asks": [[1.592375, 3146.0]], "action": "update"}}
1618677901.100526: {"channel": "orderbook", "market": "XRP/USD", "type": "update", "data": {"time": 1618677901.0261142, "checksum": 1320129462, "bids": [], "asks": [[1.5932, 1342.0], [1.6239, 0.0]], "action": "update"}}
1618677901.101366: {"channel": "orderbook", "market": "SXPBULL/USD", "type": "update", "data": {"time": 1618677901.0220125, "checksum": 2713578134, "bids": [[51.2, 1.717]], "asks": [], "action": "update"}}
1618677901.136819: {"channel": "orderbook", "market": "BTC-MOVE-WK-0507", "type": "update", "data": {"time": 1618677901.06326, "checksum": 901794806, "bids": [], "asks": [], "action": "update"}}
1618677901.143136: {"channel": "orderbook", "market": "XRP/USD", "type": "update", "data": {"time": 1618677901.0679615, "checksum": 2287466354, "bids": [[1.588825, 1370.0], [1.557225, 0.0]], "asks": [], "action": "update"}}
1618677901.156687: {"channel": "orderbook", "market": "SXPBULL/USD", "type": "update", "data": {"time": 1618677901.072362, "checksum": 4029225823, "bids": [], "asks": [[52.4, 45.316]], "action": "update"}}
1618677901.197746: {"channel": "orderbook", "market": "XRP/USD", "type": "update", "data": {"time": 1618677901.1201725, "checksum": 3611649510, "bids": [[1.5894, 0.0], [1.557225, 3.0]], "asks": [[1.5927, 0.0], [1.6239, 1.0]], "action": "update"}}
1618677901.207604: {"channel": "orderbook", "market": "SXPBULL/USD", "type": "update", "data": {"time": 1618677901.1222558, "checksum": 2717380189, "bids": [[51.175, 54.556]], "asks": [], "action": "update"}}
1618677901.248734: {"channel": "orderbook", "market": "XRP/USD", "type": "update", "data": {"time": 1618677901.168509, "checksum": 3638860918, "bids": [[1.586975, 0.0], [1.5571, 10.0]], "asks": [[1.592375, 2513.0], [1.598, 164110.0]], "action": "update"}}
1618677901.27709: {"channel": "orderbook", "market": "XRP/USD", "type": "update", "data": {"time": 1618677901.2024477, "checksum": 3953397891, "bids": [[1.586, 0.0], [1.581, 2138.0], [1.556625, 1.0]], "asks": [[1.592625, 633.0], [1.6239, 0.0]], "action": "update"}}
1618677901.3218298: {"channel": "orderbook", "market": "THETAHEDGE/USD", "type": "update", "data": {"time": 1618677901.2493134, "checksum": 611471902, "bids": [[24.895, 0.0]], "asks": [], "action": "update"}}
1618677901.3826041: {"channel": "orderbook", "market": "SXPBULL/USD", "type": "update", "data": {"time": 1618677901.2961597, "checksum": 4029225823, "bids": [[51.175, 3.862]], "asks": [], "action": "update"}}
1618677901.382719: {"channel": "orderbook", "market": "XRP/USD", "type": "update", "data": {"time": 1618677901.3034346, "checksum": 2128074599, "bids": [[1.5896, 0.0], [1.5561, 4.0]], "asks": [[1.592375, 0.0], [1.6239, 1.0]], "action": "update"}}
1618677901.403879: {"channel": "orderbook", "market": "XRP/USD", "type": "update", "data": {"time": 1618677901.3211687, "checksum": 3187004422, "bids": [[1.58825, 0.0], [1.55565, 2.0]], "asks": [[1.595925, 0.0], [1.62425, 4.0]], "action": "update"}}
1618677901.4417222: {"channel": "orderbook", "market": "ZECBULL/USD", "type": "update", "data": {"time": 1618677901.3682137, "checksum": 3948373180, "bids": [], "asks": [[8407.5, 14.47006]], "action": "update"}}
1618677901.445962: {"channel": "orderbook", "market": "XRP/USD", "type": "update", "data": {"time": 1618677901.3643296, "checksum": 4121514132, "bids": [[1.592175, 63.0], [1.589775, 0.0]], "asks": [], "action": "update"}}
1618677901.455931: {"channel": "orderbook", "market": "SXPBULL/USD", "type": "update", "data": {"time": 1618677901.3721051, "checksum": 2713578134, "bids": [], "asks": [[52.4, 4.016]], "action": "update"}}
1618677901.4877272: {"channel": "orderbook", "market": "XRP/USD", "type": "update", "data": {"time": 1618677901.410027, "checksum": 94851969, "bids": [[1.589375, 1100.0], [1.55565, 0.0]], "asks": [], "action": "update"}}
1618677901.500126: {"channel": "orderbook", "market": "XRP/USD", "type": "update", "data": {"time": 1618677901.4249153, "checksum": 1791142627, "bids": [[1.5898, 2515.0], [1.5561, 0.0]], "asks": [[1.5922, 0.0], [1.592775, 2513.0], [1.594125, 0.0], [1.624325, 6.0]], "action": "update"}}
1618677901.522912: {"channel": "orderbook", "market": "AMD/USD", "type": "update", "data": {"time": 1618677901.4479709, "checksum": 1935389369, "bids": [], "asks": [], "action": "update"}}
1618677901.556028: {"channel": "orderbook", "market": "XRP/USD", "type": "update", "data": {"time": 1618677901.4596312, "checksum": 478526807, "bids": [[1.592175, 0.0], [1.590325, 3990.0], [1.587475, 1.0]], "asks": [[1.59215, 633.0], [1.592625, 0.0]], "action": "update"}}
1618677901.577558: {"channel": "orderbook", "market": "SXPBULL/USD", "type": "update", "data": {"time": 1618677901.4749393, "checksum": 1788890476, "bids": [[51.15, 33.164], [50.35, 6.581]], "asks": [], "action": "update"}}
1618677901.577675: {"channel": "orderbook", "market": "XRP/USD", "type": "update", "data": {"time": 1618677901.4910185, "checksum": 3609463668, "bids": [[1.58945, 1359.0], [1.556625, 0.0]], "asks": [[1.592325, 1100.0], [1.624325, 0.0]], "action": "update"}}
1618677901.5916438: {"channel": "orderbook", "market": "SUSHIBEAR/USD", "type": "update", "data": {"time": 1618677901.5126586, "checksum": 3614867403, "bids": [], "asks": [], "action": "update"}}
1618677901.615475: {"channel": "orderbook", "market": "AKRO/USD", "type": "update", "data": {"time": 1618677901.5361915, "checksum": 1012179311, "bids": [], "asks": [[0.068575, 164.0], [0.085, 0.0]], "action": "update"}}
1618677901.631246: {"channel": "orderbook", "market": "AKRO/USD", "type": "update", "data": {"time": 1618677901.557119, "checksum": 1088290762, "bids": [], "asks": [[0.068525, 0.0], [0.085, 1084.0]], "action": "update"}}
1618677901.6428852: {"channel": "orderbook", "market": "ZECBULL/USD", "type": "update", "data": {"time": 1618677901.5669184, "checksum": 1392247404, "bids": [], "asks": [[7382.5, 0.0]], "action": "update"}}
1618677901.649367: {"channel": "orderbook", "market": "XRP/USD", "type": "update", "data": {"time": 1618677901.569662, "checksum": 3982301384, "bids": [[1.588025, 0.0], [1.5875, 5295.0], [1.556625, 1.0]], "asks": [[1.59215, 0.0], [1.5932, 0.0], [1.5975, 188.0], [1.624325, 6.0]], "action": "update"}}
1618677901.690996: {"channel": "orderbook", "market": "SXPBULL/USD", "type": "update", "data": {"time": 1618677901.5959203, "checksum": 1788890476, "bids": [], "asks": [], "action": "update"}}
1618677901.6946182: {"channel": "orderbook", "market": "XRP/USD", "type": "update", "data": {"time": 1618677901.6194491, "checksum": 2608866268, "bids": [], "asks": [[1.592325, 0.0], [1.6256, 1.0]], "action": "update"}}
1618677901.710557: {"channel": "orderbook", "market": "ZECBULL/USD", "type": "update", "data": {"time": 1618677901.6339498, "checksum": 1879244388, "bids": [[7212.5, 0.60678]], "asks": [], "action": "update"}}
1618677901.72647: {"channel": "orderbook", "market": "XRP/USD", "type": "update", "data": {"time": 1618677901.6486151, "checksum": 3891770846, "bids": [[1.588275, 0.0], [1.586875, 372046.0]], "asks": [[1.592325, 1100.0], [1.6256, 0.0]], "action": "update"}}
1618677901.73718: {"channel": "orderbook", "market": "AKRO/USD", "type": "update", "data": {"time": 1618677901.6570902, "checksum": 1088290762, "bids": [], "asks": [], "action": "update"}}
1618677901.737939: {"channel": "orderbook", "market": "XRP/USD", "type": "update", "data": {"time": 1618677901.6637378, "checksum": 2195467559, "bids": [], "asks": [[1.592625, 633.0], [1.624325, 0.0]], "action": "update"}}
1618677901.788619: {"channel": "orderbook", "market": "XRP/USD", "type": "update", "data": {"time": 1618677901.714337, "checksum": 1840408331, "bids": [[1.5887, 0.0], [1.5561, 4.0]], "asks": [], "action": "update"}}
1618677901.8457851: {"channel": "orderbook", "market": "SXPBULL/USD", "type": "update", "data": {"time": 1618677901.7477393, "checksum": 3861181333, "bids": [], "asks": [[52.375, 42.355]], "action": "update"}}
1618677901.8459039: {"channel": "orderbook", "market": "XRP/USD", "type": "update", "data": {"time": 1618677901.7657917, "checksum": 1109788599, "bids": [[1.58885, 4361.0], [1.5561, 0.0]], "asks": [[1.59385, 4440.0], [1.62425, 0.0]], "action": "update"}}
1618677901.864466: {"channel": "orderbook", "market": "ZECBULL/USD", "type": "update", "data": {"time": 1618677901.7840254, "checksum": 3337657052, "bids": [], "asks": [[7390.0, 0.02774]], "action": "update"}}
1618677901.890207: {"channel": "orderbook", "market": "XRP/USD", "type": "update", "data": {"time": 1618677901.8124828, "checksum": 1450831910, "bids": [], "asks": [[1.5943, 0.0], [1.62425, 4.0]], "action": "update"}}
1618677901.9118772: {"channel": "orderbook", "market": "XRP/USD", "type": "update", "data": {"time": 1618677901.8376656, "checksum": 4015781564, "bids": [], "asks": [[1.5982, 0.0], [1.624325, 6.0]], "action": "update"}}
1618677901.9362292: {"channel": "orderbook", "market": "NVDA-0625", "type": "update", "data": {"time": 1618677901.8599896, "checksum": 3644189371, "bids": [], "asks": [], "action": "update"}}
1618677901.944663: {"channel": "orderbook", "market": "XRP/USD", "type": "update", "data": {"time": 1618677901.8674753, "checksum": 2141220933, "bids": [[1.5898, 0.0], [1.5561, 4.0]], "asks": [], "action": "update"}}
1618677901.963776: {"channel": "orderbook", "market": "XRP/USD", "type": "update", "data": {"time": 1618677901.8878899, "checksum": 3756045820, "bids": [[1.58945, 0.0], [1.55565, 2.0]], "asks": [[1.592775, 0.0], [1.6256, 1.0]], "action": "update"}}
1618677901.97228: {"channel": "orderbook", "market": "THETAHEDGE/USD", "type": "update", "data": {"time": 1618677901.8991098, "checksum": 611471902, "bids": [], "asks": [], "action": "update"}}
1618677901.988387: {"channel": "orderbook", "market": "XRP/USD", "type": "update", "data": {"time": 1618677901.9135516, "checksum": 996898211, "bids": [], "asks": [[1.5924, 15.0], [1.6256, 0.0]], "action": "update"}}
1618677902.023686: {"channel": "orderbook", "market": "SXPBULL/USD", "type": "update", "data": {"time": 1618677901.9289412, "checksum": 1790336755, "bids": [[51.15, 2.485]], "asks": [], "action": "update"}}
1618677902.048291: {"channel": "orderbook", "market": "PAXG/USD", "type": "update", "data": {"time": 1618677901.9484327, "checksum": 852366897, "bids": [], "asks": [], "action": "update"}}
1618677902.048332: {"channel": "orderbook", "market": "XRP/USD", "type": "update", "data": {"time": 1618677901.9640388, "checksum": 589028861, "bids": [[1.5896, 2515.0], [1.55565, 0.0]], "asks": [[1.592475, 2513.0], [1.624325, 0.0]], "action": "update"}}
1618677902.048419: {"channel": "orderbook", "market": "SXPBULL/USD", "type": "update", "data": {"time": 1618677901.9603074, "checksum": 1350015857, "bids": [[50.275, 318.212]], "asks": [], "action": "update"}}
1618677902.0966961: {"channel": "orderbook", "market": "XRP/USD", "type": "update", "data": {"time": 1618677902.0135188, "checksum": 1586357485, "bids": [], "asks": [[1.592825, 4880.0], [1.62425, 0.0]], "action": "update"}}
1618677902.145638: {"channel": "orderbook", "market": "XRP/USD", "type": "update", "data": {"time": 1618677902.0636816, "checksum": 220759536, "bids": [], "asks": [[1.592625, 0.0], [1.59295, 326843.0], [1.597825, 188.0], [1.6239, 0.0]], "action": "update"}}
1618677902.158336: {"channel": "orderbook", "market": "BTC-MOVE-WK-0507", "type": "update", "data": {"time": 1618677902.085879, "checksum": 901794806, "bids": [], "asks": [], "action": "update"}}
1618677902.170194: {"channel": "orderbook", "market": "XRP/USD", "type": "update", "data": {"time": 1618677902.0916958, "checksum": 3867011561, "bids": [], "asks": [[1.5923, 633.0], [1.6235, 0.0]], "action": "update"}}
1618677902.195198: {"channel": "orderbook", "market": "SXPBULL/USD", "type": "update", "data": {"time": 1618677902.1089356, "checksum": 3417769111, "bids": [[51.15, 33.164]], "asks": [], "action": "update"}}
1618677902.2064278: {"channel": "orderbook", "market": "XRP/USD", "type": "update", "data": {"time": 1618677902.1241574, "checksum": 3859935563, "bids": [[1.5896, 0.0], [1.55565, 2.0]], "asks": [], "action": "update"}}
1618677902.2431302: {"channel": "orderbook", "market": "XRP/USD", "type": "update", "data": {"time": 1618677902.1627412, "checksum": 1140678516, "bids": [[1.589225, 3584.0], [1.55565, 0.0]], "asks": [[1.5922, 5.0], [1.62335, 0.0]], "action": "update"}}
1618677902.289694: {"channel": "orderbook", "market": "XRP/USD", "type": "update", "data": {"time": 1618677902.2145133, "checksum": 4032714369, "bids": [], "asks": [[1.592325, 0.0], [1.592475, 0.0], [1.592825, 0.0], [1.5933, 1430.0], [1.62335, 8051.0], [1.6235, 4.0]], "action": "update"}}
1618677902.325014: {"channel": "orderbook", "market": "XRP/USD", "type": "update", "data": {"time": 1618677902.2516203, "checksum": 657420328, "bids": [[1.5894, 2515.0], [1.5561, 0.0]], "asks": [[1.592025, 1100.0], [1.6235, 0.0]], "action": "update"}}
1618677902.357806: {"channel": "orderbook", "market": "XRP/USD", "type": "update", "data": {"time": 1618677902.2821786, "checksum": 1374430053, "bids": [], "asks": [[1.592175, 633.0], [1.5923, 0.0]], "action": "update"}}
1618677902.375417: {"channel": "orderbook", "market": "XRP/USD", "type": "update", "data": {"time": 1618677902.3001761, "checksum": 3695741867, "bids": [], "asks": [[1.5933, 0.0], [1.6235, 4.0]], "action": "update"}}
1618677902.435307: {"channel": "orderbook", "market": "XRP/USD", "type": "update", "data": {"time": 1618677902.3558104, "checksum": 284971174, "bids": [[1.5886, 0.0], [1.587825, 0.0], [1.5561, 4.0], [1.55565, 2.0]], "asks": [[1.592175, 0.0], [1.6239, 1.0]], "action": "update"}}
1618677902.446836: {"channel": "orderbook", "market": "SXPBULL/USD", "type": "update", "data": {"time": 1618677902.3626819, "checksum": 571493484, "bids": [], "asks": [[52.375, 0.155]], "action": "update"}}
1618677902.471117: {"channel": "orderbook", "market": "XRP/USD", "type": "update", "data": {"time": 1618677902.3935344, "checksum": 929772970, "bids": [[1.5894, 0.0], [1.589375, 0.0], [1.5554, 1.0], [1.5553, 6.0]], "asks": [[1.592625, 633.0], [1.5969, 1412.0], [1.6239, 0.0]], "action": "update"}}
1618677902.4861782: {"channel": "orderbook", "market": "XRP/USD", "type": "update", "data": {"time": 1618677902.406069, "checksum": 222459205, "bids": [[1.588775, 633.0], [1.5553, 0.0]], "asks": [[1.592675, 2513.0], [1.6235, 0.0]], "action": "update"}}
1618677902.536824: {"channel": "orderbook", "market": "SXPBULL/USD", "type": "update", "data": {"time": 1618677902.3935816, "checksum": 370392110, "bids": [], "asks": [[51.8, 0.0], [51.825, 0.0], [51.85, 0.0], [51.875, 2.024], [54.325, 4.529], [54.35, 1.537], [54.375, 3.308]], "action": "update"}}
1618677902.536971: {"channel": "orderbook", "market": "XRP/USD", "type": "update", "data": {"time": 1618677902.4548557, "checksum": 3699750097, "bids": [[1.590325, 5090.0]], "asks": [], "action": "update"}}
1618677902.549918: {"channel": "orderbook", "market": "SXPBULL/USD", "type": "update", "data": {"time": 1618677902.4567254, "checksum": 2237498410, "bids": [[51.15, 2.485]], "asks": [], "action": "update"}}
1618677902.5552619: {"channel": "orderbook", "market": "AMD/USD", "type": "update", "data": {"time": 1618677902.4704127, "checksum": 1935389369, "bids": [], "asks": [], "action": "update"}}
1618677902.5968928: {"channel": "orderbook", "market": "XRP/USD", "type": "update", "data": {"time": 1618677902.4851427, "checksum": 2641205373, "bids": [[1.5899, 2515.0], [1.5875, 0.0]], "asks": [], "action": "update"}}
1618677902.5970519: {"channel": "orderbook", "market": "XRP/USD", "type": "update", "data": {"time": 1618677902.5044236, "checksum": 3236330573, "bids": [[1.590325, 3990.0]], "asks": [[1.592675, 0.0], [1.6235, 4.0]], "action": "update"}}
1618677902.621264: {"channel": "orderbook", "market": "SUSHIBEAR/USD", "type": "update", "data": {"time": 1618677902.5394578, "checksum": 3614867403, "bids": [], "asks": [], "action": "update"}}
1618677902.6324139: {"channel": "orderbook", "market": "XRP/USD", "type": "update", "data": {"time": 1618677902.5564337, "checksum": 163710315, "bids": [[1.59035, 1100.0], [1.589975, 1346.0], [1.55565, 0.0], [1.5554, 0.0]], "asks": [[1.59385, 0.0], [1.5975, 1844.0], [1.6239, 1.0]], "action": "update"}}
1618677902.6632771: {"channel": "orderbook", "market": "SXPBULL/USD", "type": "update", "data": {"time": 1618677902.58199, "checksum": 2136950751, "bids": [[51.175, 54.556]], "asks": [], "action": "update"}}
1618677902.670628: {"channel": "orderbook", "market": "ZECBULL/USD", "type": "update", "data": {"time": 1618677902.5971794, "checksum": 3337657052, "bids": [], "asks": [], "action": "update"}}
1618677902.6930401: {"channel": "orderbook", "market": "XRP/USD", "type": "update", "data": {"time": 1618677902.6114583, "checksum": 274326243, "bids": [[1.588875, 5497.0], [1.5561, 0.0]], "asks": [[1.597675, 212.0]], "action": "update"}}
1618677902.717843: {"channel": "orderbook", "market": "SXPBULL/USD", "type": "update", "data": {"time": 1618677902.6272423, "checksum": 2136950751, "bids": [], "asks": [], "action": "update"}}
1618677902.743246: {"channel": "orderbook", "market": "XRP/USD", "type": "update", "data": {"time": 1618677902.654918, "checksum": 2688273939, "bids": [], "asks": [[1.592975, 2512.0], [1.6239, 0.0]], "action": "update"}}
1618677902.771313: {"channel": "orderbook", "market": "AKRO/USD", "type": "update", "data": {"time": 1618677902.6854446, "checksum": 1088290762, "bids": [], "asks": [], "action": "update"}}
1618677902.8059871: {"channel": "orderbook", "market": "XRP/USD", "type": "update", "data": {"time": 1618677902.7305846, "checksum": 3909048048, "bids": [[1.59035, 1118.0]], "asks": [[1.5922, 0.0], [1.6239, 1.0]], "action": "update"}}
1618677902.8487701: {"channel": "orderbook", "market": "XRP/USD", "type": "update", "data": {"time": 1618677902.7544525, "checksum": 1456182929, "bids": [], "asks": [[1.592975, 0.0], [1.62425, 4.0]], "action": "update"}}
1618677902.86019: {"channel": "orderbook", "market": "AKRO/USD", "type": "update", "data": {"time": 1618677902.783784, "checksum": 2669914641, "bids": [[0.068125, 38091.0], [0.059365, 0.0]], "asks": [], "action": "update"}}
1618677902.868864: {"channel": "orderbook", "market": "ZECBULL/USD", "type": "update", "data": {"time": 1618677902.792103, "checksum": 1518561518, "bids": [[7155.0, 0.0]], "asks": [], "action": "update"}}
1618677902.921359: {"channel": "orderbook", "market": "XRP/USD", "type": "update", "data": {"time": 1618677902.8403091, "checksum": 354376013, "bids": [[1.5899, 0.0], [1.5561, 4.0]], "asks": [[1.593375, 2512.0], [1.62425, 0.0]], "action": "update"}}
1618677902.9335968: {"channel": "orderbook", "market": "SXPBULL/USD", "type": "update", "data": {"time": 1618677902.8533213, "checksum": 2237498410, "bids": [[51.175, 3.862]], "asks": [], "action": "update"}}
1618677902.9864619: {"channel": "orderbook", "market": "XRP/USD", "type": "update", "data": {"time": 1618677902.906183, "checksum": 2582467969, "bids": [[1.5897, 2515.0], [1.5884, 3591.0], [1.5561, 0.0]], "asks": [[1.59375, 1387.0], [1.6239, 0.0]], "action": "update"}}
1618677902.986659: {"channel": "orderbook", "market": "NVDA-0625", "type": "update", "data": {"time": 1618677902.9115527, "checksum": 3644189371, "bids": [], "asks": [], "action": "update"}}
1618677902.998243: {"channel": "orderbook", "market": "THETAHEDGE/USD", "type": "update", "data": {"time": 1618677902.9236906, "checksum": 611471902, "bids": [], "asks": [], "action": "update"}}
1618677903.0066361: {"channel": "orderbook", "market": "XRP/USD", "type": "update", "data": {"time": 1618677902.9302864, "checksum": 779203581, "bids": [[1.589975, 0.0], [1.5561, 4.0]], "asks": [], "action": "update"}}
1618677903.0309691: {"channel": "orderbook", "market": "XRP/USD", "type": "update", "data": {"time": 1618677902.9558473, "checksum": 1924356721, "bids": [[1.590375, 63.0], [1.5561, 0.0]], "asks": [[1.59295, 0.0], [1.593375, 0.0], [1.598, 165615.0], [1.6239, 1.0], [1.62425, 4.0]], "action": "update"}}
1618677903.0564768: {"channel": "orderbook", "market": "XRP/USD", "type": "update", "data": {"time": 1618677902.9800372, "checksum": 1924356721, "bids": [], "asks": [], "action": "update"}}
1618677903.08635: {"channel": "orderbook", "market": "PAXG/USD", "type": "update", "data": {"time": 1618677902.9981303, "checksum": 852366897, "bids": [], "asks": [], "action": "update"}}
1618677903.086386: {"channel": "orderbook", "market": "XRP/USD", "type": "update", "data": {"time": 1618677903.0059505, "checksum": 104542536, "bids": [[1.5897, 0.0], [1.5561, 4.0]], "asks": [], "action": "update"}}
1618677903.092233: {"channel": "orderbook", "market": "ZECBULL/USD", "type": "update", "data": {"time": 1618677903.0106013, "checksum": 3532295873, "bids": [[7162.5, 0.02748]], "asks": [], "action": "update"}}
1618677903.09484: {"channel": "orderbook", "market": "SXPBULL/USD", "type": "update", "data": {"time": 1618677903.0080166, "checksum": 2136950751, "bids": [[51.175, 54.556]], "asks": [], "action": "update"}}
1618677903.127477: {"channel": "orderbook", "market": "XRP/USD", "type": "update", "data": {"time": 1618677903.0411942, "checksum": 885612789, "bids": [[1.59035, 18.0], [1.58, 0.0], [1.55565, 2.0]], "asks": [], "action": "update"}}
1618677903.153428: {"channel": "orderbook", "market": "XRP/USD", "type": "update", "data": {"time": 1618677903.0783844, "checksum": 1616766491, "bids": [[1.590375, 1163.0]], "asks": [[1.594225, 8183.0]], "action": "update"}}
1618677903.193383: {"channel": "orderbook", "market": "BTC-MOVE-WK-0507", "type": "update", "data": {"time": 1618677903.1142545, "checksum": 901794806, "bids": [], "asks": [], "action": "update"}}
1618677903.193442: {"channel": "orderbook", "market": "SXPBULL/USD", "type": "update", "data": {"time": 1618677903.1067176, "checksum": 2914868873, "bids": [[51.175, 87.755]], "asks": [], "action": "update"}}
1618677903.2073238: {"channel": "orderbook", "market": "XRP/USD", "type": "update", "data": {"time": 1618677903.1325378, "checksum": 3742718426, "bids": [[1.5897, 2515.0], [1.55565, 0.0]], "asks": [[1.592025, 1105.0], [1.592975, 2512.0], [1.62425, 0.0]], "action": "update"}}
1618677903.207519: {"channel": "orderbook", "market": "SXPBULL/USD", "type": "update", "data": {"time": 1618677903.128888, "checksum": 1243697388, "bids": [[51.175, 37.061]], "asks": [], "action": "update"}}
1618677903.282916: {"channel": "orderbook", "market": "XRP/USD", "type": "update", "data": {"time": 1618677903.2077422, "checksum": 2515403031, "bids": [], "asks": [[1.5975, 1656.0], [1.597825, 0.0], [1.62425, 4.0]], "action": "update"}}
1618677903.294039: {"channel": "orderbook", "market": "XRP/USD", "type": "update", "data": {"time": 1618677903.220158, "checksum": 2479134096, "bids": [[1.56855, 331.0]], "asks": [], "action": "update"}}
1618677903.354462: {"channel": "orderbook", "market": "XRP/USD", "type": "update", "data": {"time": 1618677903.2795498, "checksum": 3015388643, "bids": [[1.590375, 1100.0]], "asks": [[1.5925, 0.0], [1.624325, 6.0]], "action": "update"}}
1618677903.365907: {"channel": "orderbook", "market": "SXPBULL/USD", "type": "update", "data": {"time": 1618677903.27888, "checksum": 2914868873, "bids": [[51.175, 87.755]], "asks": [], "action": "update"}}
1618677903.36802: {"channel": "orderbook", "market": "ZECBULL/USD", "type": "update", "data": {"time": 1618677903.2920618, "checksum": 599600039, "bids": [], "asks": [[9380.0, 0.0]], "action": "update"}}
1618677903.404258: {"channel": "orderbook", "market": "XRP/USD", "type": "update", "data": {"time": 1618677903.3280938, "checksum": 2913982749, "bids": [], "asks": [[1.592975, 0.0], [1.593, 0.0], [1.6256, 1.0], [1.6258, 1.0]], "action": "update"}}
1618677903.420279: {"channel": "orderbook", "market": "SXPBULL/USD", "type": "update", "data": {"time": 1618677903.3335032, "checksum": 1243697388, "bids": [[51.175, 37.061]], "asks": [], "action": "update"}}
1618677903.484268: {"channel": "orderbook", "market": "SXPBULL/USD", "type": "update", "data": {"time": 1618677903.4043858, "checksum": 1163634430, "bids": [[51.2, 109.277]], "asks": [], "action": "update"}}
1618677903.495751: {"channel": "orderbook", "market": "XRP/USD", "type": "update", "data": {"time": 1618677903.4136517, "checksum": 1828012614, "bids": [[1.5897, 0.0], [1.586, 1476.0]], "asks": [[1.597875, 188.0], [1.5982, 188.0], [1.6256, 0.0], [1.6258, 0.0]], "action": "update"}}
1618677903.5184598: {"channel": "orderbook", "market": "XRP/USD", "type": "update", "data": {"time": 1618677903.4341457, "checksum": 803086053, "bids": [], "asks": [[1.592775, 2513.0], [1.593375, 1347.0], [1.62425, 0.0], [1.624325, 0.0]], "action": "update"}}
1618677903.53025: {"channel": "orderbook", "market": "SUSHIBEAR/USD", "type": "update", "data": {"time": 1618677903.4424124, "checksum": 3649246176, "bids": [[1.18e-05, 0.0], [1.175e-05, 0.0], [1.17e-05, 2100000.0], [1.165e-05, 0.0]], "asks": [[1.255e-05, 16690000.0]], "action": "update"}}
1618677903.563072: {"channel": "orderbook", "market": "XRP/USD", "type": "update", "data": {"time": 1618677903.4880326, "checksum": 3682001899, "bids": [[1.592, 63.0], [1.5893, 1441.0], [1.556625, 0.0], [1.5561, 0.0]], "asks": [[1.592625, 0.0], [1.62425, 4.0]], "action": "update"}}
1618677903.57597: {"channel": "orderbook", "market": "AMD/USD", "type": "update", "data": {"time": 1618677903.49593, "checksum": 1935389369, "bids": [], "asks": [], "action": "update"}}
1618677903.576004: {"channel": "orderbook", "market": "SXPBULL/USD", "type": "update", "data": {"time": 1618677903.4814415, "checksum": 542746617, "bids": [], "asks": [[52.5, 0.931]], "action": "update"}}
1618677903.5822568: {"channel": "orderbook", "market": "XRP/USD", "type": "update", "data": {"time": 1618677903.5080833, "checksum": 1348052496, "bids": [[1.568725, 20.0], [1.5571, 0.0]], "asks": [[1.592025, 1738.0]], "action": "update"}}
1618677903.605546: {"channel": "orderbook", "market": "XRP/USD", "type": "update", "data": {"time": 1618677903.5322316, "checksum": 3069796941, "bids": [[1.5895, 2515.0], [1.557225, 0.0]], "asks": [], "action": "update"}}
1618677903.605599: {"channel": "orderbook", "market": "SUSHIBEAR/USD", "type": "update", "data": {"time": 1618677903.5318196, "checksum": 1009453851, "bids": [[1.19e-05, 34030000.0], [1.17e-05, 10760000.0]], "asks": [], "action": "update"}}
1618677903.644397: {"channel": "orderbook", "market": "SUSHIBEAR/USD", "type": "update", "data": {"time": 1618677903.5695105, "checksum": 3682397038, "bids": [[1.18e-05, 8460000.0], [1.175e-05, 8680000.0]], "asks": [[1.235e-05, 8320000.0], [0.04, 0.0]], "action": "update"}}
1618677903.644459: {"channel": "orderbook", "market": "SXPBULL/USD", "type": "update", "data": {"time": 1618677903.5628114, "checksum": 1515618736, "bids": [[51.2, 1.717]], "asks": [], "action": "update"}}
1618677903.691953: {"channel": "orderbook", "market": "XRP/USD", "type": "update", "data": {"time": 1618677903.591667, "checksum": 1422955496, "bids": [[1.592, 0.0], [1.5869, 48925.0], [1.5855, 1582.0], [1.5805, 0.0]], "asks": [[1.5917, 633.0], [1.592025, 1105.0], [1.62425, 0.0]], "action": "update"}}
1618677903.702359: {"channel": "orderbook", "market": "ZECBULL/USD", "type": "update", "data": {"time": 1618677903.624667, "checksum": 599600039, "bids": [], "asks": [], "action": "update"}}
1618677903.7302341: {"channel": "orderbook", "market": "XRP/USD", "type": "update", "data": {"time": 1618677903.6547992, "checksum": 1216763930, "bids": [[1.5895, 0.0], [1.557225, 3.0]], "asks": [[1.592775, 0.0], [1.62425, 4.0]], "action": "update"}}
1618677903.7429461: {"channel": "orderbook", "market": "SXPBULL/USD", "type": "update", "data": {"time": 1618677903.639733, "checksum": 1515618736, "bids": [], "asks": [], "action": "update"}}
1618677903.759202: {"channel": "orderbook", "market": "XRP/USD", "type": "update", "data": {"time": 1618677903.6815448, "checksum": 3341090524, "bids": [], "asks": [[1.593375, 0.0], [1.624325, 6.0]], "action": "update"}}
1618677903.781445: {"channel": "orderbook", "market": "XRP/USD", "type": "update", "data": {"time": 1618677903.7052608, "checksum": 1927198815, "bids": [[1.59035, 0.0], [1.5884, 1412.0], [1.5571, 10.0]], "asks": [[1.5917, 0.0], [1.592025, 5.0], [1.6256, 1.0]], "action": "update"}}
1618677903.7965682: {"channel": "orderbook", "market": "AKRO/USD", "type": "update", "data": {"time": 1618677903.7133396, "checksum": 2669914641, "bids": [], "asks": [], "action": "update"}}
1618677903.810591: {"channel": "orderbook", "market": "XRP/USD", "type": "update", "data": {"time": 1618677903.7357938, "checksum": 2174722072, "bids": [], "asks": [[1.592175, 633.0], [1.6256, 0.0]], "action": "update"}}
1618677903.8470368: {"channel": "orderbook", "market": "SXPBULL/USD", "type": "update", "data": {"time": 1618677903.766867, "checksum": 1959915501, "bids": [[51.6, 0.088], [49.05, 0.0]], "asks": [], "action": "update"}}
1618677903.8699782: {"channel": "orderbook", "market": "XRP/USD", "type": "update", "data": {"time": 1618677903.7934597, "checksum": 2067928521, "bids": [[1.5899, 2515.0], [1.585, 3140.0], [1.581, 657.0], [1.5571, 0.0]], "asks": [], "action": "update"}}
1618677903.885391: {"channel": "orderbook", "market": "XRP/USD", "type": "update", "data": {"time": 1618677903.8073742, "checksum": 3434538939, "bids": [], "asks": [[1.59375, 0.0], [1.6256, 1.0]], "action": "update"}}
1618677903.8905878: {"channel": "orderbook", "market": "SXPBULL/USD", "type": "update", "data": {"time": 1618677903.8076766, "checksum": 939756778, "bids": [[51.2, 73.841]], "asks": [], "action": "update"}}
1618677903.918427: {"channel": "orderbook", "market": "XRP/USD", "type": "update", "data": {"time": 1618677903.833673, "checksum": 4104715837, "bids": [], "asks": [[1.591875, 1100.0], [1.592175, 0.0], [1.592525, 633.0], [1.593075, 2512.0], [1.624325, 0.0], [1.6256, 0.0]], "action": "update"}}
1618677903.930055: {"channel": "orderbook", "market": "XRP/USD", "type": "update", "data": {"time": 1618677903.8566833, "checksum": 3799481258, "bids": [[1.588175, 0.0], [1.5571, 10.0]], "asks": [], "action": "update"}}
1618677903.986397: {"channel": "orderbook", "market": "XRP/USD", "type": "update", "data": {"time": 1618677903.9069476, "checksum": 3996619599, "bids": [], "asks": [[1.593975, 374568.0]], "action": "update"}}
1618677904.02911: {"channel": "orderbook", "market": "THETAHEDGE/USD", "type": "update", "data": {"time": 1618677903.951406, "checksum": 611471902, "bids": [], "asks": [], "action": "update"}}
1618677904.041515: {"channel": "orderbook", "market": "NVDA-0625", "type": "update", "data": {"time": 1618677903.9616666, "checksum": 3644189371, "bids": [], "asks": [], "action": "update"}}
1618677904.069775: {"channel": "orderbook", "market": "SXPBULL/USD", "type": "update", "data": {"time": 1618677903.9853349, "checksum": 2726263828, "bids": [[51.175, 3.862]], "asks": [], "action": "update"}}
1618677904.096416: {"channel": "orderbook", "market": "XRP/USD", "type": "update", "data": {"time": 1618677904.009305, "checksum": 3996619599, "bids": [], "asks": [], "action": "update"}}
1618677904.096452: {"channel": "orderbook", "market": "ZECBULL/USD", "type": "update", "data": {"time": 1618677904.0181026, "checksum": 1337647587, "bids": [[7210.0, 0.43344]], "asks": [], "action": "update"}}
1618677904.129992: {"channel": "orderbook", "market": "PAXG/USD", "type": "update", "data": {"time": 1618677904.0486603, "checksum": 852366897, "bids": [], "asks": [], "action": "update"}}
1618677904.133129: {"channel": "orderbook", "market": "XRP/USD", "type": "update", "data": {"time": 1618677904.057148, "checksum": 3387299780, "bids": [], "asks": [[1.592025, 0.0], [1.597675, 55.0], [1.624325, 6.0]], "action": "update"}}
1618677904.1513479: {"channel": "orderbook", "market": "SXPBULL/USD", "type": "update", "data": {"time": 1618677904.0607915, "checksum": 1999439359, "bids": [[51.2, 1.717]], "asks": [[52.275, 39.037]], "action": "update"}}
1618677904.166122: {"channel": "orderbook", "market": "ZECBULL/USD", "type": "update", "data": {"time": 1618677904.0895426, "checksum": 2085762207, "bids": [], "asks": [[7315.0, 0.54204]], "action": "update"}}
1618677904.181024: {"channel": "orderbook", "market": "XRP/USD", "type": "update", "data": {"time": 1618677904.1067023, "checksum": 3347919451, "bids": [], "asks": [[1.591875, 0.0], [1.6256, 1.0]], "action": "update"}}
1618677904.214346: {"channel": "orderbook", "market": "BTC-MOVE-WK-0507", "type": "update", "data": {"time": 1618677904.1391854, "checksum": 901794806, "bids": [], "asks": [], "action": "update"}}
1618677904.2370932: {"channel": "orderbook", "market": "XRP/USD", "type": "update", "data": {"time": 1618677904.1588616, "checksum": 2461231800, "bids": [], "asks": [[1.592225, 1100.0], [1.6256, 0.0]], "action": "update"}}
1618677904.3151932: {"channel": "orderbook", "market": "SXPBULL/USD", "type": "update", "data": {"time": 1618677904.2351153, "checksum": 1006593784, "bids": [[51.2, 73.841]], "asks": [], "action": "update"}}
1618677904.3365812: {"channel": "orderbook", "market": "XRP/USD", "type": "update", "data": {"time": 1618677904.2610803, "checksum": 3841941116, "bids": [], "asks": [[1.5982, 0.0], [1.6256, 1.0]], "action": "update"}}
1618677904.394513: {"channel": "orderbook", "market": "XRP/USD", "type": "update", "data": {"time": 1618677904.3128188, "checksum": 4057599441, "bids": [], "asks": [[1.5983, 811.0]], "action": "update"}}
1618677904.425956: {"channel": "orderbook", "market": "SXPBULL/USD", "type": "update", "data": {"time": 1618677904.3414826, "checksum": 2725511868, "bids": [[50.7, 1.726]], "asks": [], "action": "update"}}
1618677904.454334: {"channel": "orderbook", "market": "XRP/USD", "type": "update", "data": {"time": 1618677904.371246, "checksum": 46337776, "bids": [[1.5899, 0.0], [1.556625, 1.0]], "asks": [[1.592525, 0.0], [1.5957, 0.0], [1.6258, 1.0], [1.6268, 1412.0]], "action": "update"}}
1618677904.471777: {"channel": "orderbook", "market": "XRP/USD", "type": "update", "data": {"time": 1618677904.3908203, "checksum": 1610922725, "bids": [[1.5893, 0.0], [1.5561, 4.0]], "asks": [[1.592225, 0.0], [1.593075, 0.0], [1.593575, 633.0], [1.6273, 1.0]], "action": "update"}}
1618677904.5268521: {"channel": "orderbook", "market": "SXPBULL/USD", "type": "update", "data": {"time": 1618677904.439253, "checksum": 4003881403, "bids": [[51.2, 1.717]], "asks": [], "action": "update"}}
1618677904.58607: {"channel": "orderbook", "market": "XRP/USD", "type": "update", "data": {"time": 1618677904.492314, "checksum": 3757193346, "bids": [[1.588825, 0.0], [1.588775, 0.0], [1.588725, 9000.0], [1.588425, 2179.0], [1.587975, 275136.0], [1.5561, 0.0]], "asks": [[1.59525, 0.0], [1.596625, 4130.0], [1.598475, 188.0], [1.6273, 0.0]], "action": "update"}}
1618677904.605886: {"channel": "orderbook", "market": "XRP/USD", "type": "update", "data": {"time": 1618677904.5275898, "checksum": 2399476915, "bids": [[1.588975, 633.0], [1.556625, 0.0]], "asks": [], "action": "update"}}
1618677904.608143: {"channel": "orderbook", "market": "AMD/USD", "type": "update", "data": {"time": 1618677904.5267951, "checksum": 1935389369, "bids": [], "asks": [], "action": "update"}}
1618677904.652302: {"channel": "orderbook", "market": "XRP/USD", "type": "update", "data": {"time": 1618677904.5727408, "checksum": 1090953560, "bids": [[1.588975, 0.0], [1.556625, 1.0]], "asks": [[1.594, 1680.0]], "action": "update"}}
1618677904.6746628: {"channel": "orderbook", "market": "SUSHIBEAR/USD", "type": "update", "data": {"time": 1618677904.5985074, "checksum": 3682397038, "bids": [], "asks": [], "action": "update"}}
1618677904.699512: {"channel": "orderbook", "market": "SXPBULL/USD", "type": "update", "data": {"time": 1618677904.5933182, "checksum": 3919723381, "bids": [[51.2, 73.841]], "asks": [[52.1, 0.97]], "action": "update"}}
1618677904.730517: {"channel": "orderbook", "market": "ZECBULL/USD", "type": "update", "data": {"time": 1618677904.650068, "checksum": 189128736, "bids": [[7212.5, 1e-05]], "asks": [[7322.5, 0.0]], "action": "update"}}
1618677904.7517598: {"channel": "orderbook", "market": "XRP/USD", "type": "update", "data": {"time": 1618677904.6743422, "checksum": 2112816236, "bids": [], "asks": [[1.593975, 373517.0]], "action": "update"}}
1618677904.763488: {"channel": "orderbook", "market": "SXPBULL/USD", "type": "update", "data": {"time": 1618677904.6713667, "checksum": 1011609502, "bids": [[51.2, 1.717]], "asks": [], "action": "update"}}
1618677904.7890491: {"channel": "orderbook", "market": "XRP/USD", "type": "update", "data": {"time": 1618677904.7035663, "checksum": 1319201327, "bids": [[1.589275, 633.0], [1.556625, 0.0]], "asks": [], "action": "update"}}
1618677904.794576: {"channel": "orderbook", "market": "ZECBULL/USD", "type": "update", "data": {"time": 1618677904.7206495, "checksum": 2097672642, "bids": [], "asks": [[7315.0, 0.0]], "action": "update"}}
1618677904.8194911: {"channel": "orderbook", "market": "AKRO/USD", "type": "update", "data": {"time": 1618677904.7370677, "checksum": 2669914641, "bids": [], "asks": [], "action": "update"}}
1618677904.8404999: {"channel": "orderbook", "market": "XRP/USD", "type": "update", "data": {"time": 1618677904.7588344, "checksum": 3584182712, "bids": [[1.5904, 18.0], [1.5571, 0.0]], "asks": [], "action": "update"}}
1618677904.8511271: {"channel": "orderbook", "market": "SXPBULL/USD", "type": "update", "data": {"time": 1618677904.753097, "checksum": 2578727934, "bids": [[51.225, 37.587]], "asks": [], "action": "update"}}
1618677904.856317: {"channel": "orderbook", "market": "XRP/USD", "type": "update", "data": {"time": 1618677904.779126, "checksum": 1561712893, "bids": [[1.589275, 0.0], [1.58735, 0.0], [1.5571, 10.0], [1.556625, 1.0]], "asks": [[1.59555, 1431.0], [1.6268, 0.0]], "action": "update"}}
1618677904.877728: {"channel": "orderbook", "market": "XRP/USD", "type": "update", "data": {"time": 1618677904.802763, "checksum": 956863923, "bids": [[1.590375, 0.0], [1.58925, 3675.0]], "asks": [], "action": "update"}}
1618677904.9021702: {"channel": "orderbook", "market": "SXPBULL/USD", "type": "update", "data": {"time": 1618677904.818874, "checksum": 1135135714, "bids": [], "asks": [[52.1, 1.155]], "action": "update"}}
1618677904.91424: {"channel": "orderbook", "market": "XRP/USD", "type": "update", "data": {"time": 1618677904.8394988, "checksum": 225956793, "bids": [[1.590575, 1100.0], [1.556625, 0.0]], "asks": [[1.5944, 4912.0], [1.597875, 0.0]], "action": "update"}}
1618677904.964389: {"channel": "orderbook", "market": "XRP/USD", "type": "update", "data": {"time": 1618677904.8837001, "checksum": 134663359, "bids": [[1.591175, 1420.0], [1.589775, 633.0], [1.557225, 0.0], [1.5571, 0.0]], "asks": [], "action": "update"}}
1618677904.984747: {"channel": "orderbook", "market": "SXPBULL/USD", "type": "update", "data": {"time": 1618677904.897095, "checksum": 1081811957, "bids": [[51.225, 2.152]], "asks": [], "action": "update"}}
1618677905.014459: {"channel": "orderbook", "market": "XRP/USD", "type": "update", "data": {"time": 1618677904.9376476, "checksum": 3159160262, "bids": [[1.5912, 2512.0], [1.590575, 0.0]], "asks": [[1.594175, 2510.0], [1.596375, 1334.0], [1.6256, 0.0], [1.6258, 0.0]], "action": "update"}}
1618677905.0571609: {"channel": "orderbook", "market": "SXPBULL/USD", "type": "update", "data": {"time": 1618677904.9726462, "checksum": 3663280688, "bids": [[51.25, 38.151]], "asks": [], "action": "update"}}
1618677905.05722: {"channel": "orderbook", "market": "XRP/USD", "type": "update", "data": {"time": 1618677904.9795697, "checksum": 203598472, "bids": [[1.59135, 1100.0], [1.586875, 0.0]], "asks": [], "action": "update"}}
1618677905.063516: {"channel": "orderbook", "market": "THETAHEDGE/USD", "type": "update", "data": {"time": 1618677904.985493, "checksum": 611471902, "bids": [], "asks": [], "action": "update"}}
1618677905.08267: {"channel": "orderbook", "market": "XRP/USD", "type": "update", "data": {"time": 1618677905.006017, "checksum": 1923930243, "bids": [], "asks": [[1.594875, 3248.0], [1.624325, 0.0]], "action": "update"}}
1618677905.11045: {"channel": "orderbook", "market": "NVDA-0625", "type": "update", "data": {"time": 1618677905.0312445, "checksum": 3644189371, "bids": [], "asks": [], "action": "update"}}
1618677905.1221561: {"channel": "orderbook", "market": "XRP/USD", "type": "update", "data": {"time": 1618677905.0387697, "checksum": 1923930243, "bids": [], "asks": [], "action": "update"}}
1618677905.156249: {"channel": "orderbook", "market": "XRP/USD", "type": "update", "data": {"time": 1618677905.070607, "checksum": 4131626155, "bids": [[1.589225, 0.0], [1.557225, 3.0]], "asks": [[1.59865, 188.0], [1.62425, 0.0]], "action": "update"}}
1618677905.171941: {"channel": "orderbook", "market": "XRP/USD", "type": "update", "data": {"time": 1618677905.0849345, "checksum": 332150801, "bids": [[1.59135, 5550.0], [1.588725, 0.0], [1.5571, 10.0]], "asks": [], "action": "update"}}
1618677905.17202: {"channel": "orderbook", "market": "ZECBULL/USD", "type": "update", "data": {"time": 1618677905.0892782, "checksum": 963147081, "bids": [], "asks": [[7322.5, 0.55982]], "action": "update"}}
1618677905.2017689: {"channel": "orderbook", "market": "PAXG/USD", "type": "update", "data": {"time": 1618677905.1175113, "checksum": 852366897, "bids": [], "asks": [], "action": "update"}}
1618677905.221845: {"channel": "orderbook", "market": "XRP/USD", "type": "update", "data": {"time": 1618677905.1440444, "checksum": 2760479756, "bids": [[1.5912, 2575.0]], "asks": [], "action": "update"}}
1618677905.239085: {"channel": "orderbook", "market": "BTC-MOVE-WK-0507", "type": "update", "data": {"time": 1618677905.1680713, "checksum": 901794806, "bids": [], "asks": [], "action": "update"}}
1618677905.2718909: {"channel": "orderbook", "market": "XRP/USD", "type": "update", "data": {"time": 1618677905.197506, "checksum": 1561938718, "bids": [[1.590225, 633.0], [1.589775, 0.0]], "asks": [], "action": "update"}}
1618677905.34173: {"channel": "orderbook", "market": "XRP/USD", "type": "update", "data": {"time": 1618677905.2665007, "checksum": 3386423642, "bids": [], "asks": [[1.594175, 0.0], [1.62425, 4.0]], "action": "update"}}
1618677905.4488199: {"channel": "orderbook", "market": "XRP/USD", "type": "update", "data": {"time": 1618677905.3379679, "checksum": 1413033485, "bids": [], "asks": [[1.5924, 0.0], [1.624325, 6.0]], "action": "update"}}
1618677905.465158: {"channel": "orderbook", "market": "SXPBULL/USD", "type": "update", "data": {"time": 1618677905.3794255, "checksum": 3308030925, "bids": [], "asks": [[52.55, 6.246]], "action": "update"}}
1618677905.473695: {"channel": "orderbook", "market": "XRP/USD", "type": "update", "data": {"time": 1618677905.3962774, "checksum": 2583907345, "bids": [[1.5912, 0.0], [1.586, 0.0], [1.56915, 0.0], [1.556625, 1.0], [1.5561, 4.0], [1.55565, 2.0]], "asks": [], "action": "update"}}
1618677905.4918551: {"channel": "orderbook", "market": "SXPBULL/USD", "type": "update", "data": {"time": 1618677905.40365, "checksum": 1485240396, "bids": [[51.25, 1.438]], "asks": [], "action": "update"}}
1618677905.52069: {"channel": "orderbook", "market": "XRP/USD", "type": "update", "data": {"time": 1618677905.438875, "checksum": 1263162779, "bids": [[1.591675, 1371.0], [1.55565, 0.0]], "asks": [[1.59555, 0.0], [1.596625, 0.0], [1.6256, 1.0], [1.6258, 1.0]], "action": "update"}}
1618677905.552827: {"channel": "orderbook", "market": "XRP/USD", "type": "update", "data": {"time": 1618677905.4666293, "checksum": 4245850090, "bids": [[1.59135, 4450.0]], "asks": [[1.59335, 1100.0], [1.6258, 0.0]], "action": "update"}}
1618677905.5828118: {"channel": "orderbook", "market": "XRP/USD", "type": "update", "data": {"time": 1618677905.4890597, "checksum": 3311545851, "bids": [[1.590425, 3680.0], [1.5561, 0.0]], "asks": [], "action": "update"}}
1618677905.618198: {"channel": "orderbook", "market": "XRP/USD", "type": "update", "data": {"time": 1618677905.535785, "checksum": 3802543258, "bids": [[1.59185, 1100.0], [1.586525, 8766.0], [1.581, 2203.0], [1.5571, 0.0], [1.556625, 0.0]], "asks": [], "action": "update"}}
1618677905.633605: {"channel": "orderbook", "market": "XRP/USD", "type": "update", "data": {"time": 1618677905.5558078, "checksum": 1994618961, "bids": [[1.5846, 0.0], [1.583925, 0.0], [1.5571, 10.0], [1.556625, 1.0]], "asks": [[1.59335, 0.0], [1.59715, 0.0], [1.6258, 1.0], [1.6268, 1412.0]], "action": "update"}}
1618677905.6400719: {"channel": "orderbook", "market": "AMD/USD", "type": "update", "data": {"time": 1618677905.561293, "checksum": 1935389369, "bids": [], "asks": [], "action": "update"}}
1618677905.6577668: {"channel": "orderbook", "market": "XRP/USD", "type": "update", "data": {"time": 1618677905.580395, "checksum": 2202615001, "bids": [], "asks": [[1.593575, 0.0], [1.5944, 0.0], [1.6273, 1.0], [1.628075, 1.0]], "action": "update"}}
1618677905.670781: {"channel": "orderbook", "market": "SXPBULL/USD", "type": "update", "data": {"time": 1618677905.580648, "checksum": 3748079772, "bids": [[51.25, 42.213]], "asks": [], "action": "update"}}
1618677905.691158: {"channel": "orderbook", "market": "XRP/USD", "type": "update", "data": {"time": 1618677905.6067448, "checksum": 1744559763, "bids": [[1.592375, 63.0], [1.556625, 0.0]], "asks": [[1.594175, 633.0], [1.597975, 1685.0], [1.6273, 0.0], [1.628075, 0.0]], "action": "update"}}
1618677905.743639: {"channel": "orderbook", "market": "SUSHIBEAR/USD", "type": "update", "data": {"time": 1618677905.6428287, "checksum": 3682397038, "bids": [], "asks": [], "action": "update"}}
1618677905.761889: {"channel": "orderbook", "market": "XRP/USD", "type": "update", "data": {"time": 1618677905.685766, "checksum": 4039322232, "bids": [[1.5917, 2512.0], [1.58765, 0.0], [1.5869, 51380.0], [1.576225, 4.0], [1.5571, 0.0]], "asks": [[1.594975, 2509.0], [1.59965, 8279.0], [1.6258, 0.0], [1.6268, 0.0]], "action": "update"}}
1618677905.773513: {"channel": "orderbook", "market": "SXPBULL/USD", "type": "update", "data": {"time": 1618677905.6830137, "checksum": 3748079772, "bids": [], "asks": [], "action": "update"}}
1618677905.788503: {"channel": "orderbook", "market": "XRP/USD", "type": "update", "data": {"time": 1618677905.70786, "checksum": 382627429, "bids": [[1.592375, 5533.0], [1.5904, 0.0], [1.5571, 10.0]], "asks": [[1.59665, 7688.0], [1.598475, 0.0]], "action": "update"}}
1618677905.7944682: {"channel": "orderbook", "market": "ZECBULL/USD", "type": "update", "data": {"time": 1618677905.7136443, "checksum": 963147081, "bids": [], "asks": [], "action": "update"}}
1618677905.81088: {"channel": "orderbook", "market": "XRP/USD", "type": "update", "data": {"time": 1618677905.7320342, "checksum": 3824383657, "bids": [], "asks": [[1.594225, 0.0], [1.6258, 1.0]], "action": "update"}}
1618677905.832293: {"channel": "orderbook", "market": "XRP/USD", "type": "update", "data": {"time": 1618677905.755074, "checksum": 2836279615, "bids": [[1.570025, 293.0], [1.5571, 0.0]], "asks": [[1.593975, 367863.0]], "action": "update"}}
1618677905.8323572: {"channel": "orderbook", "market": "AKRO/USD", "type": "update", "data": {"time": 1618677905.756838, "checksum": 2669914641, "bids": [], "asks": [], "action": "update"}}
1618677905.8613818: {"channel": "orderbook", "market": "XRP/USD", "type": "update", "data": {"time": 1618677905.7801254, "checksum": 406008276, "bids": [[1.590225, 0.0], [1.5571, 10.0]], "asks": [], "action": "update"}}
1618677905.879432: {"channel": "orderbook", "market": "XRP/USD", "type": "update", "data": {"time": 1618677905.8051026, "checksum": 1605686279, "bids": [[1.59185, 0.0], [1.5907, 633.0], [1.588875, 0.0], [1.556625, 1.0]], "asks": [], "action": "update"}}
1618677905.9116192: {"channel": "orderbook", "market": "SXPBULL/USD", "type": "update", "data": {"time": 1618677905.8225043, "checksum": 1485240396, "bids": [[51.25, 1.438]], "asks": [], "action": "update"}}
1618677905.935592: {"channel": "orderbook", "market": "XRP/USD", "type": "update", "data": {"time": 1618677905.8554826, "checksum": 2320698326, "bids": [[1.5924, 1100.0], [1.556625, 0.0]], "asks": [], "action": "update"}}
1618677906.005976: {"channel": "orderbook", "market": "XRP/USD", "type": "update", "data": {"time": 1618677905.929578, "checksum": 258276572, "bids": [], "asks": [[1.593975, 363703.0], [1.599025, 188.0], [1.6258, 0.0]], "action": "update"}}
1618677906.0650291: {"channel": "orderbook", "market": "XRP/USD", "type": "update", "data": {"time": 1618677905.9856825, "checksum": 915000184, "bids": [[1.5907, 0.0], [1.556625, 1.0]], "asks": [[1.594175, 0.0], [1.6258, 1.0]], "action": "update"}}
1618677906.095391: {"channel": "orderbook", "market": "THETAHEDGE/USD", "type": "update", "data": {"time": 1618677906.0018969, "checksum": 611471902, "bids": [], "asks": [], "action": "update"}}
1618677906.0954292: {"channel": "orderbook", "market": "SXPBULL/USD", "type": "update", "data": {"time": 1618677905.996092, "checksum": 3748079772, "bids": [[51.25, 42.213]], "asks": [], "action": "update"}}
1618677906.095467: {"channel": "orderbook", "market": "XRP/USD", "type": "update", "data": {"time": 1618677906.0064955, "checksum": 3793194692, "bids": [[1.5917, 0.0], [1.5561, 4.0]], "asks": [[1.594625, 633.0], [1.594975, 0.0]], "action": "update"}}
1618677906.127989: {"channel": "orderbook", "market": "XRP/USD", "type": "update", "data": {"time": 1618677906.030293, "checksum": 2800133464, "bids": [[1.5916, 633.0], [1.5561, 0.0]], "asks": [], "action": "update"}}
1618677906.133499: {"channel": "orderbook", "market": "XRP/USD", "type": "update", "data": {"time": 1618677906.054372, "checksum": 1021751582, "bids": [[1.592375, 63.0]], "asks": [], "action": "update"}}
1618677906.1335418: {"channel": "orderbook", "market": "SXPBULL/USD", "type": "update", "data": {"time": 1618677906.0506516, "checksum": 482276114, "bids": [], "asks": [[52.575, 1.75]], "action": "update"}}
1618677906.184692: {"channel": "orderbook", "market": "XRP/USD", "type": "update", "data": {"time": 1618677906.105301, "checksum": 143540167, "bids": [[1.5924, 0.0], [1.59035, 3675.0], [1.58925, 0.0], [1.5561, 4.0]], "asks": [[1.594875, 0.0], [1.6268, 1412.0]], "action": "update"}}
1618677906.2157: {"channel": "orderbook", "market": "NVDA-0625", "type": "update", "data": {"time": 1618677906.1312597, "checksum": 3644189371, "bids": [], "asks": [], "action": "update"}}
1618677906.246229: {"channel": "orderbook", "market": "XRP/USD", "type": "update", "data": {"time": 1618677906.1570344, "checksum": 2337807288, "bids": [[1.5917, 2512.0], [1.5561, 0.0]], "asks": [[1.5983, 654.0]], "action": "update"}}
1618677906.246294: {"channel": "orderbook", "market": "PAXG/USD", "type": "update", "data": {"time": 1618677906.163826, "checksum": 852366897, "bids": [], "asks": [], "action": "update"}}
1618677906.270108: {"channel": "orderbook", "market": "BTC-MOVE-WK-0507", "type": "update", "data": {"time": 1618677906.1932979, "checksum": 901794806, "bids": [], "asks": [], "action": "update"}}
1618677906.275647: {"channel": "orderbook", "market": "XRP/USD", "type": "update", "data": {"time": 1618677906.1787317, "checksum": 1306041476, "bids": [[1.5916, 0.0], [1.59135, 0.0], [1.5561, 4.0], [1.55565, 2.0]], "asks": [], "action": "update"}}
1618677906.287803: {"channel": "orderbook", "market": "XRP/USD", "type": "update", "data": {"time": 1618677906.2059863, "checksum": 3803382827, "bids": [[1.5902, 633.0], [1.589225, 5386.0], [1.5561, 0.0], [1.55565, 0.0]], "asks": [[1.595575, 3381.0], [1.6268, 0.0]], "action": "update"}}
1618677906.342326: {"channel": "orderbook", "market": "XRP/USD", "type": "update", "data": {"time": 1618677906.2552347, "checksum": 2483371072, "bids": [], "asks": [[1.594875, 5427.0], [1.595975, 4119.0], [1.6256, 0.0], [1.6258, 0.0]], "action": "update"}}
1618677906.36346: {"channel": "orderbook", "market": "XRP/USD", "type": "update", "data": {"time": 1618677906.282438, "checksum": 3657230105, "bids": [[1.5902, 0.0], [1.5561, 4.0]], "asks": [], "action": "update"}}
1618677906.4850519: {"channel": "orderbook", "market": "XRP/USD", "type": "update", "data": {"time": 1618677906.307263, "checksum": 3201862500, "bids": [], "asks": [[1.594875, 0.0], [1.595575, 0.0], [1.6256, 1.0], [1.6258, 1.0]], "action": "update"}}
1618677906.485125: {"channel": "orderbook", "market": "XRP/USD", "type": "update", "data": {"time": 1618677906.3339336, "checksum": 3211171159, "bids": [[1.583, 1503.0]], "asks": [[1.593475, 1100.0], [1.594225, 4910.0], [1.5965, 1608.0], [1.6256, 0.0], [1.6258, 0.0]], "action": "update"}}
1618677906.485188: {"channel": "orderbook", "market": "SXPBULL/USD", "type": "update", "data": {"time": 1618677906.3735785, "checksum": 1304095231, "bids": [], "asks": [[51.875, 2.505]], "action": "update"}}
1618677906.4852202: {"channel": "orderbook", "market": "XRP/USD", "type": "update", "data": {"time": 1618677906.3878498, "checksum": 3184308004, "bids": [[1.590725, 633.0], [1.5561, 0.0]], "asks": [[1.599675, 157.0], [1.624325, 0.0]], "action": "update"}}
1618677906.4901838: {"channel": "orderbook", "market": "XRP/USD", "type": "update", "data": {"time": 1618677906.4100466, "checksum": 218746416, "bids": [], "asks": [[1.594375, 2510.0], [1.5984, 2455.0], [1.6239, 0.0], [1.62425, 0.0]], "action": "update"}}
1618677906.5196302: {"channel": "orderbook", "market": "XRP/USD", "type": "update", "data": {"time": 1618677906.432792, "checksum": 3370499999, "bids": [[1.585425, 8279.0], [1.556625, 0.0]], "asks": [[1.594225, 0.0], [1.6239, 1.0]], "action": "update"}}
1618677906.519701: {"channel": "orderbook", "market": "SUSHIBEAR/USD", "type": "update", "data": {"time": 1618677906.4407778, "checksum": 2830010465, "bids": [[1.17e-05, 2100000.0]], "asks": [], "action": "update"}}
1618677906.530685: {"channel": "orderbook", "market": "SXPBULL/USD", "type": "update", "data": {"time": 1618677906.4475846, "checksum": 1060818852, "bids": [[50.65, 63.107]], "asks": [], "action": "update"}}
1618677906.565221: {"channel": "orderbook", "market": "XRP/USD", "type": "update", "data": {"time": 1618677906.4891467, "checksum": 3876688670, "bids": [[1.5917, 0.0], [1.556625, 1.0]], "asks": [], "action": "update"}}
1618677906.578357: {"channel": "orderbook", "market": "SXPBULL/USD", "type": "update", "data": {"time": 1618677906.497993, "checksum": 1887674484, "bids": [[51.25, 1.438]], "asks": [], "action": "update"}}
1618677906.59962: {"channel": "orderbook", "market": "XRP/USD", "type": "update", "data": {"time": 1618677906.507303, "checksum": 416525823, "bids": [], "asks": [[1.5945, 0.0], [1.62425, 4.0]], "action": "update"}}
1618677906.609104: {"channel": "orderbook", "market": "SXPBULL/USD", "type": "update", "data": {"time": 1618677906.524233, "checksum": 4089536980, "bids": [], "asks": [[52.675, 64.43]], "action": "update"}}
1618677906.6523662: {"channel": "orderbook", "market": "AMD/USD", "type": "update", "data": {"time": 1618677906.5777543, "checksum": 1935389369, "bids": [], "asks": [], "action": "update"}}
1618677906.664563: {"channel": "orderbook", "market": "XRP/USD", "type": "update", "data": {"time": 1618677906.5834246, "checksum": 4126350331, "bids": [], "asks": [[1.5935, 1530.0], [1.596875, 3484.0], [1.62425, 0.0]], "action": "update"}}
1618677906.6861892: {"channel": "orderbook", "market": "SUSHIBEAR/USD", "type": "update", "data": {"time": 1618677906.594492, "checksum": 3719675452, "bids": [[1.19e-05, 25500000.0], [1.18e-05, 0.0], [1.175e-05, 0.0], [1.165e-05, 8660000.0]], "asks": [[1.235e-05, 0.0], [0.04, 1091000.0]], "action": "update"}}
1618677906.7025468: {"channel": "orderbook", "market": "XRP/USD", "type": "update", "data": {"time": 1618677906.6204767, "checksum": 3947785728, "bids": [], "asks": [[1.595975, 9688.0], [1.59865, 0.0], [1.600325, 0.0], [1.62425, 4.0], [1.624325, 6.0]], "action": "update"}}
1618677906.70368: {"channel": "orderbook", "market": "SXPBULL/USD", "type": "update", "data": {"time": 1618677906.621719, "checksum": 1099228256, "bids": [[51.175, 75.145]], "asks": [], "action": "update"}}
1618677906.774957: {"channel": "orderbook", "market": "SUSHIBEAR/USD", "type": "update", "data": {"time": 1618677906.6903424, "checksum": 1032527643, "bids": [[1.18e-05, 8530000.0]], "asks": [], "action": "update"}}
1618677906.780509: {"channel": "orderbook", "market": "XRP/USD", "type": "update", "data": {"time": 1618677906.699779, "checksum": 3804447026, "bids": [[1.5913, 2512.0], [1.556625, 0.0]], "asks": [[1.596025, 1391.0], [1.624325, 0.0]], "action": "update"}}
1618677906.786859: {"channel": "orderbook", "market": "SUSHIBEAR/USD", "type": "update", "data": {"time": 1618677906.7043312, "checksum": 3614867403, "bids": [[1.175e-05, 8460000.0], [1.17e-05, 10780000.0]], "asks": [[1.255e-05, 25010000.0]], "action": "update"}}
1618677906.79506: {"channel": "orderbook", "market": "SXPBULL/USD", "type": "update", "data": {"time": 1618677906.699414, "checksum": 1099228256, "bids": [], "asks": [], "action": "update"}}
1618677906.835021: {"channel": "orderbook", "market": "ZECBULL/USD", "type": "update", "data": {"time": 1618677906.7557542, "checksum": 963147081, "bids": [], "asks": [], "action": "update"}}
1618677906.845299: {"channel": "orderbook", "market": "XRP/USD", "type": "update", "data": {"time": 1618677906.7602205, "checksum": 251873957, "bids": [[1.5924, 18.0], [1.591825, 4910.0], [1.591675, 0.0], [1.5571, 0.0]], "asks": [], "action": "update"}}
1618677906.858454: {"channel": "orderbook", "market": "XRP/USD", "type": "update", "data": {"time": 1618677906.7788165, "checksum": 3932911191, "bids": [], "asks": [[1.5935, 5.0], [1.595775, 0.0], [1.624325, 6.0]], "action": "update"}}
1618677906.866571: {"channel": "orderbook", "market": "AKRO/USD", "type": "update", "data": {"time": 1618677906.7828841, "checksum": 2669914641, "bids": [], "asks": [], "action": "update"}}
1618677906.8763762: {"channel": "orderbook", "market": "XRP/USD", "type": "update", "data": {"time": 1618677906.798638, "checksum": 4155267025, "bids": [], "asks": [[1.5954, 1362.0], [1.624325, 0.0]], "action": "update"}}
1618677906.955022: {"channel": "orderbook", "market": "XRP/USD", "type": "update", "data": {"time": 1618677906.8747866, "checksum": 2587856913, "bids": [], "asks": [[1.5995, 188.0], [1.62425, 0.0]], "action": "update"}}
1618677906.956608: {"channel": "orderbook", "market": "SXPBULL/USD", "type": "update", "data": {"time": 1618677906.8725052, "checksum": 4089536980, "bids": [[51.175, 3.862]], "asks": [], "action": "update"}}
1618677906.978704: {"channel": "orderbook", "market": "SXPBULL/USD", "type": "update", "data": {"time": 1618677906.8947954, "checksum": 4105261738, "bids": [[51.175, 37.061]], "asks": [], "action": "update"}}
1618677906.983199: {"channel": "orderbook", "market": "XRP/USD", "type": "update", "data": {"time": 1618677906.9026637, "checksum": 1745576618, "bids": [[1.591725, 1365.0], [1.587, 1698.0], [1.582, 0.0], [1.557225, 0.0]], "asks": [], "action": "update"}}
1618677907.008933: {"channel": "orderbook", "market": "XRP/USD", "type": "update", "data": {"time": 1618677906.9276137, "checksum": 3347720476, "bids": [], "asks": [[1.593975, 0.0], [1.599, 1705.0]], "action": "update"}}
1618677907.026752: {"channel": "orderbook", "market": "XRP/USD", "type": "update", "data": {"time": 1618677906.9505405, "checksum": 798777315, "bids": [[1.586, 1487.0], [1.5573, 0.0]], "asks": [[1.5935, 0.0], [1.5954, 0.0], [1.62425, 4.0], [1.624325, 6.0]], "action": "update"}}
1618677907.054485: {"channel": "orderbook", "market": "SXPBULL/USD", "type": "update", "data": {"time": 1618677906.9558609, "checksum": 2696471574, "bids": [[50.5, 35.987]], "asks": [], "action": "update"}}
1618677907.064469: {"channel": "orderbook", "market": "XRP/USD", "type": "update", "data": {"time": 1618677906.9826198, "checksum": 2021454188, "bids": [[1.5815, 0.0], [1.581, 657.0], [1.5573, 1.0]], "asks": [[1.594, 0.0], [1.5985, 2824.0], [1.599025, 0.0], [1.6256, 1.0], [1.6258, 1.0]], "action": "update"}}
1618677907.086456: {"channel": "orderbook", "market": "XRP/USD", "type": "update", "data": {"time": 1618677906.9974613, "checksum": 4004350010, "bids": [[1.5924, 5478.0], [1.591725, 0.0], [1.557225, 3.0]], "asks": [[1.593475, 0.0], [1.6268, 1412.0]], "action": "update"}}
1618677907.109941: {"channel": "orderbook", "market": "THETAHEDGE/USD", "type": "update", "data": {"time": 1618677907.0325024, "checksum": 611471902, "bids": [], "asks": [], "action": "update"}}
1618677907.135573: {"channel": "orderbook", "market": "XRP/USD", "type": "update", "data": {"time": 1618677907.0560522, "checksum": 1070494157, "bids": [[1.5924, 6578.0], [1.5865, 1659.0], [1.557225, 0.0]], "asks": [], "action": "update"}}
1618677907.147095: {"channel": "orderbook", "market": "SXPBULL/USD", "type": "update", "data": {"time": 1618677907.0635352, "checksum": 3238989939, "bids": [[51.175, 70.73]], "asks": [], "action": "update"}}
1618677907.151037: {"channel": "orderbook", "market": "XRP/USD", "type": "update", "data": {"time": 1618677907.0732958, "checksum": 187517284, "bids": [[1.592425, 1100.0], [1.5924, 5478.0], [1.589225, 0.0], [1.58885, 0.0], [1.557225, 3.0]], "asks": [], "action": "update"}}
1618677907.1827142: {"channel": "orderbook", "market": "XRP/USD", "type": "update", "data": {"time": 1618677907.105846, "checksum": 1235446125, "bids": [], "asks": [[1.596875, 0.0], [1.6273, 1.0]], "action": "update"}}
1618677907.2206268: {"channel": "orderbook", "market": "ZECBULL/USD", "type": "update", "data": {"time": 1618677907.1430135, "checksum": 1733361171, "bids": [], "asks": [[7350.0, 0.0]], "action": "update"}}
1618677907.24877: {"channel": "orderbook", "market": "NVDA-0625", "type": "update", "data": {"time": 1618677907.1696103, "checksum": 3644189371, "bids": [], "asks": [], "action": "update"}}
1618677907.26226: {"channel": "orderbook", "market": "XRP/USD", "type": "update", "data": {"time": 1618677907.177394, "checksum": 1974144810, "bids": [[1.59035, 0.0], [1.5571, 10.0]], "asks": [], "action": "update"}}
1618677907.2802858: {"channel": "orderbook", "market": "XRP/USD", "type": "update", "data": {"time": 1618677907.2070022, "checksum": 3773513917, "bids": [[1.59045, 3675.0], [1.5571, 0.0]], "asks": [[1.5994, 188.0], [1.6005, 20.0], [1.6268, 0.0], [1.6273, 0.0]], "action": "update"}}
1618677907.2890291: {"channel": "orderbook", "market": "PAXG/USD", "type": "update", "data": {"time": 1618677907.2046912, "checksum": 852366897, "bids": [], "asks": [], "action": "update"}}
1618677907.289063: {"channel": "orderbook", "market": "BTC-MOVE-WK-0507", "type": "update", "data": {"time": 1618677907.2161114, "checksum": 901794806, "bids": [], "asks": [], "action": "update"}}
1618677907.306392: {"channel": "orderbook", "market": "SUSHIBEAR/USD", "type": "update", "data": {"time": 1618677907.2311983, "checksum": 2905967126, "bids": [[1.165e-05, 0.0]], "asks": [[1.255e-05, 16690000.0]], "action": "update"}}
1618677907.3320289: {"channel": "orderbook", "market": "XRP/USD", "type": "update", "data": {"time": 1618677907.2561922, "checksum": 2503295901, "bids": [], "asks": [[1.594575, 4909.0], [1.6258, 0.0]], "action": "update"}}
1618677907.36511: {"channel": "orderbook", "market": "XRP/USD", "type": "update", "data": {"time": 1618677907.283986, "checksum": 186293364, "bids": [[1.58935, 329798.0], [1.557225, 0.0]], "asks": [[1.595375, 253681.0], [1.5995, 1875.0], [1.6256, 0.0]], "action": "update"}}
1618677907.383241: {"channel": "orderbook", "market": "XRP/USD", "type": "update", "data": {"time": 1618677907.3050027, "checksum": 4206680056, "bids": [[1.5913, 0.0], [1.557225, 3.0]], "asks": [[1.594375, 0.0], [1.6256, 1.0]], "action": "update"}}
1618677907.4111922: {"channel": "orderbook", "market": "XRP/USD", "type": "update", "data": {"time": 1618677907.3321624, "checksum": 3158652536, "bids": [], "asks": [[1.593475, 5.0], [1.5955, 2909.0], [1.6256, 0.0]], "action": "update"}}
1618677907.423947: {"channel": "orderbook", "market": "SUSHIBEAR/USD", "type": "update", "data": {"time": 1618677907.3499358, "checksum": 2285654877, "bids": [], "asks": [[1.235e-05, 8320000.0], [0.04, 0.0]], "action": "update"}}
1618677907.4389381: {"channel": "orderbook", "market": "SUSHIBEAR/USD", "type": "update", "data": {"time": 1618677907.362758, "checksum": 2427838287, "bids": [[1.135e-05, 8660000.0]], "asks": [], "action": "update"}}
1618677907.513031: {"channel": "orderbook", "market": "XRP/USD", "type": "update", "data": {"time": 1618677907.433776, "checksum": 1868409149, "bids": [[1.570025, 0.0], [1.5571, 10.0]], "asks": [], "action": "update"}}
1618677907.53496: {"channel": "orderbook", "market": "XRP/USD", "type": "update", "data": {"time": 1618677907.4558215, "checksum": 604944139, "bids": [[1.592375, 2574.0]], "asks": [], "action": "update"}}
1618677907.550698: {"channel": "orderbook", "market": "SXPBULL/USD", "type": "update", "data": {"time": 1618677907.4629688, "checksum": 2696471574, "bids": [[51.175, 37.061]], "asks": [], "action": "update"}}
1618677907.57257: {"channel": "orderbook", "market": "SUSHIBEAR/USD", "type": "update", "data": {"time": 1618677907.495488, "checksum": 2905967126, "bids": [[1.135e-05, 0.0]], "asks": [[1.235e-05, 0.0], [0.04, 1091000.0]], "action": "update"}}
1618677907.6130629: {"channel": "orderbook", "market": "XRP/USD", "type": "update", "data": {"time": 1618677907.5178435, "checksum": 2611045339, "bids": [], "asks": [[1.595275, 2509.0], [1.624325, 0.0]], "action": "update"}}
1618677907.699722: {"channel": "orderbook", "market": "AMD/USD", "type": "update", "data": {"time": 1618677907.6058602, "checksum": 1935389369, "bids": [], "asks": [], "action": "update"}}
1618677907.699754: {"channel": "orderbook", "market": "SXPBULL/USD", "type": "update", "data": {"time": 1618677907.6130779, "checksum": 1809680157, "bids": [[51.175, 259.715]], "asks": [], "action": "update"}}
1618677907.699787: {"channel": "orderbook", "market": "XRP/USD", "type": "update", "data": {"time": 1618677907.6235929, "checksum": 643595949, "bids": [[1.591625, 1424.0], [1.5571, 0.0]], "asks": [[1.5949, 0.0], [1.624325, 6.0]], "action": "update"}}
1618677907.719508: {"channel": "orderbook", "market": "ZECBULL/USD", "type": "update", "data": {"time": 1618677907.643527, "checksum": 1702138326, "bids": [[7220.0, 0.5169]], "asks": [], "action": "update"}}
1618677907.751907: {"channel": "orderbook", "market": "AKRO/USD", "type": "update", "data": {"time": 1618677907.6639152, "checksum": 1744623557, "bids": [[0.068135, 227.0], [0.05937, 0.0]], "asks": [], "action": "update"}}
1618677907.751963: {"channel": "orderbook", "market": "ZECBULL/USD", "type": "update", "data": {"time": 1618677907.670858, "checksum": 392208797, "bids": [], "asks": [[7327.5, 0.50939]], "action": "update"}}
1618677907.777833: {"channel": "orderbook", "market": "SUSHIBEAR/USD", "type": "update", "data": {"time": 1618677907.6658573, "checksum": 3614867403, "bids": [[1.165e-05, 8660000.0]], "asks": [[1.255e-05, 25010000.0]], "action": "update"}}
1618677907.7915862: {"channel": "orderbook", "market": "AKRO/USD", "type": "update", "data": {"time": 1618677907.7144325, "checksum": 3904963521, "bids": [[0.06808, 0.0], [0.05937, 1.0]], "asks": [], "action": "update"}}
1618677907.799631: {"channel": "orderbook", "market": "XRP/USD", "type": "update", "data": {"time": 1618677907.6512713, "checksum": 2604589491, "bids": [], "asks": [[1.593475, 0.0], [1.5955, 1554.0], [1.59595, 1085.0]], "action": "update"}}
1618677907.823945: {"channel": "orderbook", "market": "XRP/USD", "type": "update", "data": {"time": 1618677907.742868, "checksum": 1489248904, "bids": [[1.5924, 5460.0], [1.592375, 63.0]], "asks": [], "action": "update"}}
1618677907.823988: {"channel": "orderbook", "market": "SXPBULL/USD", "type": "update", "data": {"time": 1618677907.7205513, "checksum": 1809680157, "bids": [], "asks": [], "action": "update"}}
1618677907.86775: {"channel": "orderbook", "market": "ZECBULL/USD", "type": "update", "data": {"time": 1618677907.7800267, "checksum": 392208797, "bids": [], "asks": [], "action": "update"}}
1618677907.867784: {"channel": "orderbook", "market": "SUSHIBEAR/USD", "type": "update", "data": {"time": 1618677907.774737, "checksum": 3614867403, "bids": [], "asks": [], "action": "update"}}
1618677907.8784902: {"channel": "orderbook", "market": "XRP/USD", "type": "update", "data": {"time": 1618677907.7912412, "checksum": 88554627, "bids": [[1.571425, 292.0], [1.557225, 0.0]], "asks": [[1.596025, 0.0], [1.6256, 1.0]], "action": "update"}}
1618677907.8785532: {"channel": "orderbook", "market": "SUSHIBEAR/USD", "type": "update", "data": {"time": 1618677907.8015068, "checksum": 540723843, "bids": [[1.165e-05, 0.0]], "asks": [], "action": "update"}}
1618677907.88325: {"channel": "orderbook", "market": "AKRO/USD", "type": "update", "data": {"time": 1618677907.807943, "checksum": 3904963521, "bids": [], "asks": [], "action": "update"}}
1618677907.965274: {"channel": "orderbook", "market": "XRP/USD", "type": "update", "data": {"time": 1618677907.815001, "checksum": 1560202507, "bids": [[1.5908, 9000.0], [1.5573, 0.0]], "asks": [[1.593625, 0.0], [1.6258, 1.0]], "action": "update"}}
1618677907.983365: {"channel": "orderbook", "market": "XRP/USD", "type": "update", "data": {"time": 1618677907.9003024, "checksum": 3806509296, "bids": [], "asks": [[1.595275, 0.0], [1.6268, 1412.0]], "action": "update"}}
1618677908.0218759: {"channel": "orderbook", "market": "SUSHIBEAR/USD", "type": "update", "data": {"time": 1618677907.9384484, "checksum": 703654248, "bids": [[1.135e-05, 8660000.0]], "asks": [], "action": "update"}}
1618677908.0550542: {"channel": "orderbook", "market": "ZECBULL/USD", "type": "update", "data": {"time": 1618677907.9687824, "checksum": 4142900637, "bids": [], "asks": [[7322.5, 0.0], [7432.5, 2.74151]], "action": "update"}}
1618677908.055125: {"channel": "orderbook", "market": "XRP/USD", "type": "update", "data": {"time": 1618677907.9718976, "checksum": 2961826972, "bids": [], "asks": [[1.594625, 0.0], [1.5976, 95570.0]], "action": "update"}}
1618677908.055231: {"channel": "orderbook", "market": "SXPBULL/USD", "type": "update", "data": {"time": 1618677907.9265792, "checksum": 2923230672, "bids": [[50.275, 2.876]], "asks": [[51.875, 0.0], [52.825, 43.851], [54.4, 2.907]], "action": "update"}}
1618677908.081602: {"channel": "orderbook", "market": "XRP/USD", "type": "update", "data": {"time": 1618677907.9962046, "checksum": 3379245470, "bids": [], "asks": [[1.59515, 633.0], [1.6268, 0.0]], "action": "update"}}
1618677908.0965052: {"channel": "orderbook", "market": "SXPBULL/USD", "type": "update", "data": {"time": 1618677907.9857075, "checksum": 3457036416, "bids": [[51.175, 37.061]], "asks": [], "action": "update"}}
1618677908.1176262: {"channel": "orderbook", "market": "XRP/USD", "type": "update", "data": {"time": 1618677908.0243084, "checksum": 2540568843, "bids": [[1.59225, 1362.0], [1.5908, 12675.0], [1.59045, 0.0]], "asks": [[1.599675, 0.0], [1.6268, 1412.0]], "action": "update"}}
1618677908.1247501: {"channel": "orderbook", "market": "THETAHEDGE/USD", "type": "update", "data": {"time": 1618677908.053584, "checksum": 611471902, "bids": [], "asks": [], "action": "update"}}
1618677908.127274: {"channel": "orderbook", "market": "SXPBULL/USD", "type": "update", "data": {"time": 1618677908.03677, "checksum": 3737192199, "bids": [[51.175, 108.344]], "asks": [], "action": "update"}}
1618677908.1422012: {"channel": "orderbook", "market": "AKRO/USD", "type": "update", "data": {"time": 1618677908.060236, "checksum": 1844747694, "bids": [], "asks": [[0.06864, 176.0], [0.085, 0.0]], "action": "update"}}
1618677908.1478221: {"channel": "orderbook", "market": "XRP/USD", "type": "update", "data": {"time": 1618677908.0723152, "checksum": 4273724389, "bids": [[1.593175, 2509.0], [1.590725, 0.0]], "asks": [], "action": "update"}}
1618677908.1765819: {"channel": "orderbook", "market": "XRP/USD", "type": "update", "data": {"time": 1618677908.1013343, "checksum": 1963887086, "bids": [[1.5912, 633.0], [1.5578, 0.0]], "asks": [[1.595975, 12196.0], [1.5994, 0.0], [1.6273, 1.0]], "action": "update"}}
1618677908.18622: {"channel": "orderbook", "market": "AKRO/USD", "type": "update", "data": {"time": 1618677908.1094341, "checksum": 441288169, "bids": [], "asks": [[0.068575, 0.0], [0.085, 1084.0]], "action": "update"}}
1618677908.203746: {"channel": "orderbook", "market": "SUSHIBEAR/USD", "type": "update", "data": {"time": 1618677908.113898, "checksum": 2567287145, "bids": [[1.18e-05, 0.0], [1.175e-05, 0.0]], "asks": [[1.255e-05, 16690000.0]], "action": "update"}}
1618677908.203829: {"channel": "orderbook", "market": "SXPBULL/USD", "type": "update", "data": {"time": 1618677908.1174047, "checksum": 2574477978, "bids": [[51.175, 37.061]], "asks": [[52.825, 3.951]], "action": "update"}}
1618677908.205483: {"channel": "orderbook", "market": "XRP/USD", "type": "update", "data": {"time": 1618677908.1272063, "checksum": 4025265894, "bids": [[1.592425, 0.0], [1.5578, 312008.0]], "asks": [[1.593625, 5.0], [1.6273, 0.0]], "action": "update"}}
1618677908.281108: {"channel": "orderbook", "market": "XRP/USD", "type": "update", "data": {"time": 1618677908.2058482, "checksum": 1050525663, "bids": [[1.593325, 1100.0], [1.5578, 0.0]], "asks": [], "action": "update"}}
1618677908.281186: {"channel": "orderbook", "market": "NVDA-0625", "type": "update", "data": {"time": 1618677908.2076116, "checksum": 3644189371, "bids": [], "asks": [], "action": "update"}}
1618677908.312952: {"channel": "orderbook", "market": "AKRO/USD", "type": "update", "data": {"time": 1618677908.2364066, "checksum": 3574358736, "bids": [], "asks": [[0.068565, 33.0]], "action": "update"}}
1618677908.315318: {"channel": "orderbook", "market": "BTC-MOVE-WK-0507", "type": "update", "data": {"time": 1618677908.2416725, "checksum": 932313911, "bids": [], "asks": [[4480.0, 0.0]], "action": "update"}}
1618677908.3300328: {"channel": "orderbook", "market": "SXPBULL/USD", "type": "update", "data": {"time": 1618677908.224771, "checksum": 3363824785, "bids": [[51.225, 59.117]], "asks": [], "action": "update"}}
1618677908.33009: {"channel": "orderbook", "market": "XRP/USD", "type": "update", "data": {"time": 1618677908.224638, "checksum": 809066157, "bids": [[1.567725, 0.0], [1.5578, 312008.0]], "asks": [], "action": "update"}}
1618677908.330154: {"channel": "orderbook", "market": "PAXG/USD", "type": "update", "data": {"time": 1618677908.2463377, "checksum": 852366897, "bids": [], "asks": [], "action": "update"}}
1618677908.346126: {"channel": "orderbook", "market": "XRP/USD", "type": "update", "data": {"time": 1618677908.2687035, "checksum": 2236898463, "bids": [[1.5912, 0.0], [1.5573, 1.0]], "asks": [[1.600625, 157.0], [1.6268, 0.0]], "action": "update"}}
1618677908.349365: {"channel": "orderbook", "market": "SXPBULL/USD", "type": "update", "data": {"time": 1618677908.2698162, "checksum": 69692258, "bids": [[51.225, 2.152], [50.45, 317.135]], "asks": [], "action": "update"}}
1618677908.3590121: {"channel": "orderbook", "market": "SUSHIBEAR/USD", "type": "update", "data": {"time": 1618677908.2805097, "checksum": 3935649454, "bids": [[1.19e-05, 34030000.0]], "asks": [[1.235e-05, 8320000.0], [0.04, 0.0]], "action": "update"}}
1618677908.409803: {"channel": "orderbook", "market": "XRP/USD", "type": "update", "data": {"time": 1618677908.290193, "checksum": 3392517709, "bids": [[1.5921, 1.0], [1.5573, 0.0]], "asks": [[1.593625, 0.0], [1.6268, 1412.0]], "action": "update"}}
1618677908.4181519: {"channel": "orderbook", "market": "XRP/USD", "type": "update", "data": {"time": 1618677908.3434763, "checksum": 3351641449, "bids": [[1.59145, 633.0], [1.591225, 5608.0], [1.590425, 0.0], [1.5578, 0.0]], "asks": [[1.600225, 188.0], [1.6268, 0.0]], "action": "update"}}
1618677908.446269: {"channel": "orderbook", "market": "XRP/USD", "type": "update", "data": {"time": 1618677908.3686519, "checksum": 3896716299, "bids": [], "asks": [[1.597125, 1426.0], [1.6258, 0.0]], "action": "update"}}
1618677908.449095: {"channel": "orderbook", "market": "SXPBULL/USD", "type": "update", "data": {"time": 1618677908.3641975, "checksum": 315193335, "bids": [[51.25, 29.099]], "asks": [], "action": "update"}}
1618677908.519553: {"channel": "orderbook", "market": "XRP/USD", "type": "update", "data": {"time": 1618677908.4409964, "checksum": 2668745305, "bids": [], "asks": [[1.594575, 0.0], [1.5995, 1687.0], [1.6258, 1.0]], "action": "update"}}
1618677908.5940459: {"channel": "orderbook", "market": "BTC-MOVE-WK-0507", "type": "update", "data": {"time": 1618677908.4983828, "checksum": 3559958065, "bids": [], "asks": [[4486.0, 0.75]], "action": "update"}}
1618677908.605932: {"channel": "orderbook", "market": "ZECBULL/USD", "type": "update", "data": {"time": 1618677908.5201712, "checksum": 4201412700, "bids": [[7210.0, 0.0]], "asks": [], "action": "update"}}
1618677908.6181881: {"channel": "orderbook", "market": "XRP/USD", "type": "update", "data": {"time": 1618677908.5300035, "checksum": 190542796, "bids": [], "asks": [[1.594875, 1.0], [1.6258, 0.0]], "action": "update"}}
1618677908.637562: {"channel": "orderbook", "market": "XRP/USD", "type": "update", "data": {"time": 1618677908.5527918, "checksum": 1629035088, "bids": [[1.5931, 11.0], [1.59185, 3496.0], [1.55905, 0.0], [1.5585, 0.0]], "asks": [[1.5948, 1100.0], [1.59595, 0.0]], "action": "update"}}
1618677908.657829: {"channel": "orderbook", "market": "XRP/USD", "type": "update", "data": {"time": 1618677908.581303, "checksum": 267044692, "bids": [[1.5912, 4281.0], [1.5908, 3675.0], [1.5594, 0.0]], "asks": [], "action": "update"}}
1618677908.700177: {"channel": "orderbook", "market": "ZECBULL/USD", "type": "update", "data": {"time": 1618677908.6197495, "checksum": 3130375084, "bids": [[6955.0, 0.0]], "asks": [], "action": "update"}}
1618677908.700238: {"channel": "orderbook", "market": "SUSHIBEAR/USD", "type": "update", "data": {"time": 1618677908.6180472, "checksum": 2567287145, "bids": [[1.19e-05, 25500000.0]], "asks": [[1.235e-05, 0.0], [0.04, 1091000.0]], "action": "update"}}
1618677908.717663: {"channel": "orderbook", "market": "AMD/USD", "type": "update", "data": {"time": 1618677908.6441607, "checksum": 1935389369, "bids": [], "asks": [], "action": "update"}}
1618677908.7512782: {"channel": "orderbook", "market": "XRP/USD", "type": "update", "data": {"time": 1618677908.6763833, "checksum": 3355976880, "bids": [[1.5926, 1411.0], [1.5869, 2455.0], [1.56, 0.0]], "asks": [[1.600475, 188.0], [1.6256, 0.0]], "action": "update"}}
1618677908.8636649: {"channel": "orderbook", "market": "SXPBULL/USD", "type": "update", "data": {"time": 1618677908.7426596, "checksum": 315193335, "bids": [], "asks": [], "action": "update"}}
1618677908.863703: {"channel": "orderbook", "market": "BTC-MOVE-WK-0507", "type": "update", "data": {"time": 1618677908.7729218, "checksum": 932313911, "bids": [], "asks": [[4486.0, 0.0]], "action": "update"}}
1618677908.863748: {"channel": "orderbook", "market": "XRP/USD", "type": "update", "data": {"time": 1618677908.7787328, "checksum": 707969057, "bids": [[1.59335, 18.0], [1.589375, 34970.0], [1.560525, 0.0], [1.5605, 0.0]], "asks": [[1.595975, 9688.0]], "action": "update"}}
1618677908.870193: {"channel": "orderbook", "market": "SXPBULL/USD", "type": "update", "data": {"time": 1618677908.7888181, "checksum": 3049817682, "bids": [[51.325, 0.118], [51.25, 1.438], [51.025, 0.198], [49.075, 0.0]], "asks": [], "action": "update"}}
1618677908.878866: {"channel": "orderbook", "market": "XRP/USD", "type": "update", "data": {"time": 1618677908.8008907, "checksum": 2611588124, "bids": [], "asks": [[1.596375, 0.0], [1.6256, 1.0]], "action": "update"}}
1618677908.8870678: {"channel": "orderbook", "market": "ZECBULL/USD", "type": "update", "data": {"time": 1618677908.8062549, "checksum": 3130375084, "bids": [], "asks": [], "action": "update"}}
1618677908.887105: {"channel": "orderbook", "market": "SUSHIBEAR/USD", "type": "update", "data": {"time": 1618677908.8027482, "checksum": 3055922495, "bids": [[1.18e-05, 8530000.0]], "asks": [[1.255e-05, 25010000.0]], "action": "update"}}
1618677908.904246: {"channel": "orderbook", "market": "AKRO/USD", "type": "update", "data": {"time": 1618677908.8234239, "checksum": 3574358736, "bids": [], "asks": [], "action": "update"}}
1618677908.9042828: {"channel": "orderbook", "market": "XRP/USD", "type": "update", "data": {"time": 1618677908.8273308, "checksum": 459275392, "bids": [[1.593325, 0.0], [1.560525, 4.0]], "asks": [], "action": "update"}}
1618677908.909007: {"channel": "orderbook", "market": "SXPBULL/USD", "type": "update", "data": {"time": 1618677908.8169165, "checksum": 914251391, "bids": [[51.0, 35.414]], "asks": [], "action": "update"}}
1618677908.9336991: {"channel": "orderbook", "market": "SXPBULL/USD", "type": "update", "data": {"time": 1618677908.8510761, "checksum": 2808036161, "bids": [[51.175, 3.862]], "asks": [], "action": "update"}}
1618677908.963774: {"channel": "orderbook", "market": "ZECBULL/USD", "type": "update", "data": {"time": 1618677908.8780994, "checksum": 1625731315, "bids": [[7227.5, 0.41955]], "asks": [], "action": "update"}}
1618677908.9777799: {"channel": "orderbook", "market": "XRP/USD", "type": "update", "data": {"time": 1618677908.9012506, "checksum": 963447031, "bids": [[1.5935, 1100.0], [1.560525, 0.0]], "asks": [[1.594775, 633.0], [1.59515, 0.0]], "action": "update"}}
1618677909.0055768: {"channel": "orderbook", "market": "THETAHEDGE/USD", "type": "update", "data": {"time": 1618677908.9273038, "checksum": 3408591325, "bids": [[24.9225, 0.0]], "asks": [], "action": "update"}}
1618677909.00563: {"channel": "orderbook", "market": "XRP/USD", "type": "update", "data": {"time": 1618677908.9286036, "checksum": 1323631804, "bids": [[1.587975, 0.0], [1.560525, 4.0]], "asks": [[1.596875, 3698.0], [1.6256, 0.0]], "action": "update"}}
1618677909.033254: {"channel": "orderbook", "market": "XRP/USD", "type": "update", "data": {"time": 1618677908.9524806, "checksum": 2266519614, "bids": [[1.5825, 0.0], [1.5605, 1.0]], "asks": [[1.594575, 5.0], [1.596175, 2507.0], [1.62425, 0.0], [1.624325, 0.0]], "action": "update"}}
1618677909.036476: {"channel": "orderbook", "market": "SXPBULL/USD", "type": "update", "data": {"time": 1618677908.9307957, "checksum": 1049064155, "bids": [[51.475, 30.197], [51.3, 4.276]], "asks": [], "action": "update"}}
1618677909.048222: {"channel": "orderbook", "market": "THETAHEDGE/USD", "type": "update", "data": {"time": 1618677908.9766848, "checksum": 1485399247, "bids": [[24.9025, 131.69]], "asks": [], "action": "update"}}
1618677909.063096: {"channel": "orderbook", "market": "XRP/USD", "type": "update", "data": {"time": 1618677908.9805164, "checksum": 2709149789, "bids": [[1.59145, 0.0], [1.5875, 1631.0]], "asks": [[1.594775, 0.0], [1.62425, 4.0]], "action": "update"}}
1618677909.0680919: {"channel": "orderbook", "market": "BTC-MOVE-WK-0507", "type": "update", "data": {"time": 1618677908.993718, "checksum": 3218502230, "bids": [], "asks": [[4488.0, 0.75]], "action": "update"}}
1618677909.083057: {"channel": "orderbook", "market": "SXPBULL/USD", "type": "update", "data": {"time": 1618677908.9935052, "checksum": 2971727601, "bids": [[51.1, 6.249]], "asks": [], "action": "update"}}
1618677909.086729: {"channel": "orderbook", "market": "XRP/USD", "type": "update", "data": {"time": 1618677909.0032856, "checksum": 2284093472, "bids": [[1.5917, 633.0], [1.5605, 0.0]], "asks": [], "action": "update"}}
1618677909.103101: {"channel": "orderbook", "market": "ZECBULL/USD", "type": "update", "data": {"time": 1618677909.0230453, "checksum": 710964946, "bids": [[7007.5, 0.05813]], "asks": [], "action": "update"}}
1618677909.1553438: {"channel": "orderbook", "market": "THETAHEDGE/USD", "type": "update", "data": {"time": 1618677909.0760577, "checksum": 1485399247, "bids": [], "asks": [], "action": "update"}}
1618677909.1584451: {"channel": "orderbook", "market": "SXPBULL/USD", "type": "update", "data": {"time": 1618677909.0716374, "checksum": 3232951680, "bids": [[51.3, 0.929]], "asks": [], "action": "update"}}
1618677909.1909518: {"channel": "orderbook", "market": "XRP/USD", "type": "update", "data": {"time": 1618677909.1036873, "checksum": 365120259, "bids": [], "asks": [[1.595175, 633.0], [1.5954, 4906.0], [1.6239, 0.0], [1.62425, 0.0]], "action": "update"}}
1618677909.308458: {"channel": "orderbook", "market": "XRP/USD", "type": "update", "data": {"time": 1618677909.2162604, "checksum": 467208359, "bids": [[1.59335, 28.0], [1.593175, 0.0], [1.5605, 1.0]], "asks": [[1.600225, 0.0], [1.6239, 1.0]], "action": "update"}}
1618677909.3085399: {"channel": "orderbook", "market": "SXPBULL/USD", "type": "update", "data": {"time": 1618677909.2109077, "checksum": 864782779, "bids": [[50.325, 17.452]], "asks": [], "action": "update"}}
1618677909.331425: {"channel": "orderbook", "market": "SXPBULL/USD", "type": "update", "data": {"time": 1618677909.2489433, "checksum": 4238633414, "bids": [[51.25, 50.998]], "asks": [], "action": "update"}}
1618677909.342487: {"channel": "orderbook", "market": "XRP/USD", "type": "update", "data": {"time": 1618677909.2595673, "checksum": 1403187841, "bids": [], "asks": [[1.5954, 0.0], [1.62425, 4.0]], "action": "update"}}
1618677909.342548: {"channel": "orderbook", "market": "NVDA-0625", "type": "update", "data": {"time": 1618677909.263092, "checksum": 3644189371, "bids": [], "asks": [], "action": "update"}}
1618677909.353781: {"channel": "orderbook", "market": "BTC-MOVE-WK-0507", "type": "update", "data": {"time": 1618677909.275327, "checksum": 3218502230, "bids": [], "asks": [], "action": "update"}}
1618677909.364448: {"channel": "orderbook", "market": "PAXG/USD", "type": "update", "data": {"time": 1618677909.2807586, "checksum": 852366897, "bids": [], "asks": [], "action": "update"}}
1618677909.3803399: {"channel": "orderbook", "market": "SXPBULL/USD", "type": "update", "data": {"time": 1618677909.2977002, "checksum": 951070954, "bids": [[50.45, 322.135]], "asks": [], "action": "update"}}
1618677909.409251: {"channel": "orderbook", "market": "SXPBULL/USD", "type": "update", "data": {"time": 1618677909.318568, "checksum": 4154445975, "bids": [[51.25, 1.438]], "asks": [], "action": "update"}}
1618677909.434874: {"channel": "orderbook", "market": "XRP/USD", "type": "update", "data": {"time": 1618677909.3431382, "checksum": 70287113, "bids": [[1.5935, 0.0], [1.56, 10.0]], "asks": [[1.5948, 0.0], [1.596175, 0.0], [1.624325, 6.0], [1.6256, 1.0]], "action": "update"}}
1618677909.4489: {"channel": "orderbook", "market": "ZECBULL/USD", "type": "update", "data": {"time": 1618677909.3722796, "checksum": 3478938942, "bids": [[7220.0, 0.0]], "asks": [], "action": "update"}}
1618677909.530714: {"channel": "orderbook", "market": "SXPBULL/USD", "type": "update", "data": {"time": 1618677909.444299, "checksum": 1868900549, "bids": [[51.4, 4.57], [51.25, 50.998]], "asks": [], "action": "update"}}
1618677909.638519: {"channel": "orderbook", "market": "SXPBULL/USD", "type": "update", "data": {"time": 1618677909.523179, "checksum": 1243423269, "bids": [[51.675, 0.0], [51.25, 1.438], [49.075, 0.656]], "asks": [[51.675, 0.315], [54.4, 0.0]], "action": "update"}}
1618677909.677027: {"channel": "orderbook", "market": "ZECBULL/USD", "type": "update", "data": {"time": 1618677909.5967438, "checksum": 155173464, "bids": [], "asks": [[7327.5, 0.0]], "action": "update"}}
1618677909.718196: {"channel": "orderbook", "market": "XRP/USD", "type": "update", "data": {"time": 1618677909.62759, "checksum": 2570951645, "bids": [[1.5926, 0.0], [1.59225, 0.0], [1.591625, 0.0], [1.59125, 3675.0], [1.5908, 0.0], [1.5594, 2.0], [1.55905, 1.0], [1.5585, 1412.0]], "asks": [[1.59455, 1100.0], [1.594575, 0.0], [1.595625, 4906.0], [1.5966, 1445.0], [1.6008, 188.0], [1.62425, 0.0], [1.624325, 0.0], [1.6256, 0.0]], "action": "update"}}
1618677909.7226481: {"channel": "orderbook", "market": "ZECBULL/USD", "type": "update", "data": {"time": 1618677909.6480393, "checksum": 1716064173, "bids": [], "asks": [[7330.0, 0.0]], "action": "update"}}
1618677909.739825: {"channel": "orderbook", "market": "SXPBULL/USD", "type": "update", "data": {"time": 1618677909.655675, "checksum": 3505740357, "bids": [[51.625, 0.0], [49.05, 2.231]], "asks": [[52.675, 104.43]], "action": "update"}}
1618677909.739887: {"channel": "orderbook", "market": "AMD/USD", "type": "update", "data": {"time": 1618677909.664937, "checksum": 1935389369, "bids": [], "asks": [], "action": "update"}}
1618677909.7492092: {"channel": "orderbook", "market": "ZECBULL/USD", "type": "update", "data": {"time": 1618677909.6728995, "checksum": 3939289707, "bids": [], "asks": [[7335.0, 0.51822]], "action": "update"}}
1618677909.750037: {"channel": "orderbook", "market": "XRP/USD", "type": "update", "data": {"time": 1618677909.6740954, "checksum": 3994671951, "bids": [[1.592575, 2510.0], [1.5585, 0.0]], "asks": [[1.595875, 2508.0], [1.6239, 0.0]], "action": "update"}}
1618677909.77331: {"channel": "orderbook", "market": "ZECBULL/USD", "type": "update", "data": {"time": 1618677909.697913, "checksum": 726027219, "bids": [], "asks": [[7902.5, 5.22525]], "action": "update"}}
1618677909.788173: {"channel": "orderbook", "market": "XRP/USD", "type": "update", "data": {"time": 1618677909.7151904, "checksum": 2189907465, "bids": [[1.59335, 10.0]], "asks": [], "action": "update"}}
1618677909.79375: {"channel": "orderbook", "market": "SXPBULL/USD", "type": "update", "data": {"time": 1618677909.6835568, "checksum": 3912555534, "bids": [], "asks": [[51.675, 0.0], [54.4, 2.907]], "action": "update"}}
1618677909.7982001: {"channel": "orderbook", "market": "ZECBULL/USD", "type": "update", "data": {"time": 1618677909.7233698, "checksum": 1966053108, "bids": [], "asks": [[9517.5, 25.03237]], "action": "update"}}
1618677909.8435369: {"channel": "orderbook", "market": "SXPBULL/USD", "type": "update", "data": {"time": 1618677909.755351, "checksum": 2091718413, "bids": [], "asks": [[52.6, 38.142]], "action": "update"}}
1618677909.8919628: {"channel": "orderbook", "market": "XRP/USD", "type": "update", "data": {"time": 1618677909.8156185, "checksum": 2308732949, "bids": [], "asks": [[1.600625, 0.0], [1.6239, 1.0]], "action": "update"}}
1618677909.907329: {"channel": "orderbook", "market": "SUSHIBEAR/USD", "type": "update", "data": {"time": 1618677909.8299103, "checksum": 3055922495, "bids": [], "asks": [], "action": "update"}}
1618677909.9169211: {"channel": "orderbook", "market": "ZECBULL/USD", "type": "update", "data": {"time": 1618677909.8339584, "checksum": 1966053108, "bids": [], "asks": [], "action": "update"}}
1618677909.933347: {"channel": "orderbook", "market": "AKRO/USD", "type": "update", "data": {"time": 1618677909.8504522, "checksum": 3574358736, "bids": [], "asks": [], "action": "update"}}
1618677909.969325: {"channel": "orderbook", "market": "XRP/USD", "type": "update", "data": {"time": 1618677909.8907244, "checksum": 850297139, "bids": [], "asks": [[1.595625, 0.0], [1.62425, 4.0]], "action": "update"}}
1618677910.020381: {"channel": "orderbook", "market": "SXPBULL/USD", "type": "update", "data": {"time": 1618677909.8739285, "checksum": 3356439309, "bids": [[51.3, 40.277]], "asks": [[51.9, 0.0], [54.425, 0.305]], "action": "update"}}
1618677910.0263848: {"channel": "orderbook", "market": "XRP/USD", "type": "update", "data": {"time": 1618677909.9425862, "checksum": 2781863204, "bids": [[1.59125, 0.0], [1.5585, 1412.0]], "asks": [], "action": "update"}}
1618677910.1167328: {"channel": "orderbook", "market": "XRP/USD", "type": "update", "data": {"time": 1618677910.0411038, "checksum": 1942469840, "bids": [], "asks": [[1.597975, 0.0], [1.6004, 157.0]], "action": "update"}}
1618677910.15464: {"channel": "orderbook", "market": "XRP/USD", "type": "update", "data": {"time": 1618677910.0745602, "checksum": 3520293589, "bids": [], "asks": [[1.600475, 0.0], [1.624325, 6.0]], "action": "update"}}
1618677910.154803: {"channel": "orderbook", "market": "SXPBULL/USD", "type": "update", "data": {"time": 1618677910.057158, "checksum": 1898402385, "bids": [], "asks": [[52.6, 0.542]], "action": "update"}}
1618677910.1732538: {"channel": "orderbook", "market": "THETAHEDGE/USD", "type": "update", "data": {"time": 1618677910.100519, "checksum": 1485399247, "bids": [], "asks": [], "action": "update"}}
1618677910.1937191: {"channel": "orderbook", "market": "XRP/USD", "type": "update", "data": {"time": 1618677910.1150408, "checksum": 3520293589, "bids": [], "asks": [], "action": "update"}}
1618677910.217653: {"channel": "orderbook", "market": "XRP/USD", "type": "update", "data": {"time": 1618677910.1414275, "checksum": 1397641663, "bids": [[1.5912, 7956.0]], "asks": [[1.595875, 7414.0]], "action": "update"}}
1618677910.235052: {"channel": "orderbook", "market": "ZECBULL/USD", "type": "update", "data": {"time": 1618677910.160206, "checksum": 3518491597, "bids": [], "asks": [[8375.0, 0.0]], "action": "update"}}
1618677910.286724: {"channel": "orderbook", "market": "XRP/USD", "type": "update", "data": {"time": 1618677910.2055552, "checksum": 3468239215, "bids": [], "asks": [[1.594775, 5.0], [1.624325, 0.0]], "action": "update"}}
1618677910.312432: {"channel": "orderbook", "market": "SXPBULL/USD", "type": "update", "data": {"time": 1618677910.2188597, "checksum": 2519639231, "bids": [[51.3, 0.929]], "asks": [], "action": "update"}}
1618677910.354982: {"channel": "orderbook", "market": "XRP/USD", "type": "update", "data": {"time": 1618677910.278627, "checksum": 3941145136, "bids": [[1.591725, 1402.0], [1.5917, 0.0]], "asks": [[1.600275, 188.0], [1.6008, 0.0]], "action": "update"}}
1618677910.369635: {"channel": "orderbook", "market": "XRP/USD", "type": "update", "data": {"time": 1618677910.2928576, "checksum": 3656457753, "bids": [[1.5919, 633.0], [1.5585, 0.0]], "asks": [], "action": "update"}}
1618677910.3935308: {"channel": "orderbook", "market": "XRP/USD", "type": "update", "data": {"time": 1618677910.317942, "checksum": 2182807781, "bids": [[1.592575, 0.0], [1.5585, 1412.0]], "asks": [[1.595875, 4906.0]], "action": "update"}}
1618677910.394164: {"channel": "orderbook", "market": "NVDA-0625", "type": "update", "data": {"time": 1618677910.3178506, "checksum": 3644189371, "bids": [], "asks": [], "action": "update"}}
1618677910.410518: {"channel": "orderbook", "market": "PAXG/USD", "type": "update", "data": {"time": 1618677910.327662, "checksum": 852366897, "bids": [], "asks": [], "action": "update"}}
1618677910.4564: {"channel": "orderbook", "market": "XRP/USD", "type": "update", "data": {"time": 1618677910.3752537, "checksum": 1646422034, "bids": [], "asks": [[1.59605, 1414.0], [1.62425, 0.0]], "action": "update"}}
1618677910.4678311: {"channel": "orderbook", "market": "XRP/USD", "type": "update", "data": {"time": 1618677910.3936138, "checksum": 2618909860, "bids": [], "asks": [[1.595, 1526.0]], "action": "update"}}
1618677910.500395: {"channel": "orderbook", "market": "AKRO/USD", "type": "update", "data": {"time": 1618677910.4212751, "checksum": 2317111948, "bids": [], "asks": [[0.068565, 38107.0]], "action": "update"}}
1618677910.507633: {"channel": "orderbook", "market": "XRP/USD", "type": "update", "data": {"time": 1618677910.4244714, "checksum": 1077043810, "bids": [], "asks": [[1.595, 0.0], [1.62425, 4.0]], "action": "update"}}
1618677910.507794: {"channel": "orderbook", "market": "SXPBULL/USD", "type": "update", "data": {"time": 1618677910.4189785, "checksum": 2619532233, "bids": [[51.375, 29.948], [51.25, 50.998]], "asks": [], "action": "update"}}
1618677910.532863: {"channel": "orderbook", "market": "XRP/USD", "type": "update", "data": {"time": 1618677910.4530072, "checksum": 3503846484, "bids": [[1.589, 1655.0], [1.5585, 0.0]], "asks": [], "action": "update"}}
1618677910.534333: {"channel": "orderbook", "market": "SXPBULL/USD", "type": "update", "data": {"time": 1618677910.4456346, "checksum": 2870963912, "bids": [[51.1, 0.441]], "asks": [], "action": "update"}}
1618677910.5403929: {"channel": "orderbook", "market": "BTC-MOVE-WK-0507", "type": "update", "data": {"time": 1618677910.4563463, "checksum": 3218502230, "bids": [], "asks": [], "action": "update"}}
1618677910.541248: {"channel": "orderbook", "market": "AKRO/USD", "type": "update", "data": {"time": 1618677910.4681406, "checksum": 3656726081, "bids": [[0.068185, 218.0], [0.05937, 0.0]], "asks": [], "action": "update"}}
1618677910.552753: {"channel": "orderbook", "market": "XRP/USD", "type": "update", "data": {"time": 1618677910.4678059, "checksum": 415993972, "bids": [], "asks": [[1.5955, 4.0]], "action": "update"}}
1618677910.5759969: {"channel": "orderbook", "market": "AKRO/USD", "type": "update", "data": {"time": 1618677910.488416, "checksum": 2037208036, "bids": [[0.068135, 0.0], [0.05937, 1.0]], "asks": [], "action": "update"}}
1618677910.576154: {"channel": "orderbook", "market": "XRP/USD", "type": "update", "data": {"time": 1618677910.4938078, "checksum": 1731256982, "bids": [[1.5885, 1631.0], [1.55905, 0.0]], "asks": [[1.595725, 0.0], [1.624325, 6.0]], "action": "update"}}
1618677910.5981781: {"channel": "orderbook", "market": "XRP/USD", "type": "update", "data": {"time": 1618677910.5185256, "checksum": 6046961, "bids": [], "asks": [[1.601125, 188.0], [1.624325, 0.0]], "action": "update"}}
1618677910.6270342: {"channel": "orderbook", "market": "XRP/USD", "type": "update", "data": {"time": 1618677910.5435786, "checksum": 740564184, "bids": [[1.5845, 0.0], [1.55905, 1.0]], "asks": [[1.598, 1505.0], [1.6005, 1488.0]], "action": "update"}}
1618677910.679647: {"channel": "orderbook", "market": "XRP/USD", "type": "update", "data": {"time": 1618677910.5709586, "checksum": 1883942518, "bids": [], "asks": [[1.59455, 1090.0]], "action": "update"}}
1618677910.7535172: {"channel": "orderbook", "market": "XRP/USD", "type": "update", "data": {"time": 1618677910.6443803, "checksum": 4277109389, "bids": [[1.59335, 0.0], [1.592775, 2510.0]], "asks": [[1.595375, 0.0], [1.595875, 7414.0], [1.6, 1445.0], [1.624325, 6.0]], "action": "update"}}
1618677910.7700438: {"channel": "orderbook", "market": "AMD/USD", "type": "update", "data": {"time": 1618677910.6884937, "checksum": 1935389369, "bids": [], "asks": [], "action": "update"}}
1618677910.770092: {"channel": "orderbook", "market": "SXPBULL/USD", "type": "update", "data": {"time": 1618677910.678115, "checksum": 508667993, "bids": [[51.125, 11.989]], "asks": [], "action": "update"}}
1618677910.777191: {"channel": "orderbook", "market": "XRP/USD", "type": "update", "data": {"time": 1618677910.6999524, "checksum": 2976524873, "bids": [[1.5835, 0.0], [1.5585, 1412.0]], "asks": [[1.597575, 1685.0], [1.624325, 0.0]], "action": "update"}}
