wss://ftexchange.com/ws/ <- 1618677880.648871: {"channel":"orderbook","market":"AMD/USD","op":"subscribe"}
wss://ftexchange.com/ws/ <- 1618677880.6489: {"channel":"orderbook","market":"BTC-MOVE-WK-0507","op":"subscribe"}
wss://ftexchange.com/ws/ <- 1618677880.648928: {"channel":"orderbook","market":"PAXG/USD","op":"subscribe"}
wss://ftexchange.com/ws/ <- 1618677880.6489542: {"channel":"orderbook","market":"XRP/USD","op":"subscribe"}
wss://ftexchange.com/ws/ <- 1618677880.648982: {"channel":"orderbook","market":"AKRO/USD","op":"subscribe"}
wss://ftexchange.com/ws/ <- 1618677880.649009: {"channel":"orderbook","market":"NVDA-0625","op":"subscribe"}
wss://ftexchange.com/ws/ <- 1618677880.649036: {"channel":"orderbook","market":"ZECBULL/USD","op":"subscribe"}
wss://ftexchange.com/ws/ <- 1618677880.649062: {"channel":"orderbook","market":"THETAHEDGE/USD","op":"subscribe"}
wss://ftexchange.com/ws/ <- 1618677880.649089: {"channel":"orderbook","market":"SXPBULL/USD","op":"subscribe"}
wss://ftexchange.com/ws/ <- 1618677880.6491148: {"channel":"orderbook","market":"SUSHIBEAR/USD","op":"subscribe"}
1618677881.0619268: {"type": "subscribed", "channel": "orderbook", "market": "AMD/USD"}
1618677881.061931: {"type": "subscribed", "channel": "orderbook", "market": "BTC-MOVE-WK-0507"}
1618677881.068128: {"type": "subscribed", "channel": "orderbook", "market": "PAXG/USD"}
1618677881.074929: {"type": "subscribed", "channel": "orderbook", "market": "XRP/USD"}
1618677881.079017: {"type": "subscribed", "channel": "orderbook", "market": "AKRO/USD"}
1618677881.094157: {"type": "subscribed", "channel": "orderbook", "market": "NVDA-0625"}
1618677881.1053572: {"type": "subscribed", "channel": "orderbook", "market": "ZECBULL/USD"}
1618677881.1113138: {"type": "subscribed", "channel": "orderbook", "market": "THETAHEDGE/USD"}
1618677881.124104: {"type": "subscribed", "channel": "orderbook", "market": "SXPBULL/USD"}
1618677881.131594: {"channel": "orderbook", "market": "PAXG/USD", "type": "partial", "data": {"time": 1618677881.0430884, "checksum": 2811656200, "bids": [[1784.4, 0.0001], [1784.3, 0.0385], [1784.2, 0.0299], [1781.5, 2.311], [1781.4, 0.5822], [1781.0, 0.0005], [1780.9, 0.0005], [1780.7, 2.7955], [1780.6, 0.2594], [1778.6, 0.0005], [1777.6, 0.0005], [1777.3, 0.0005], [1777.2, 0.0005], [1777.1, 0.0005], [1775.8, 0.0005], [1775.7, 0.5028], [1775.5, 0.0007], [1774.8, 0.0005], [1774.7, 0.2916], [1773.9, 0.0005], [1773.4, 0.0005], [1772.6, 0.0005], [1772.3, 0.7032], [1772.0, 0.0105], [1771.4, 0.0005], [1769.7, 0.0633], [1769.6, 1.2536], [1768.7, 0.0005], [1768.3, 0.0005], [1766.9, 1.4747], [1766.0, 0.0005], [1765.9, 0.1005], [1765.8, 0.0005], [1765.7, 0.0005], [1765.1, 0.0005], [1765.0, 0.0005], [1764.8, 0.0005], [1764.4, 0.0005], [1764.3, 1.3198], [1764.0, 0.0005], [1763.3, 0.0105], [1762.8, 0.0005], [1762.2, 0.0005], [1761.7, 1.421], [1761.0, 0.0005], [1760.8, 0.0005], [1760.4, 0.0005], [1760.3, 0.0005], [1760.2, 0.0005], [1759.2, 1.4313], [1757.5, 0.0005], [1757.4, 0.0005], [1757.2, 0.0005], [1756.4, 1.3758], [1755.0, 0.0005], [1754.9, 0.0005], [1754.8, 0.0005], [1754.7, 0.0005], [1754.6, 0.0099], [1753.9, 1.5458], [1751.3, 1.6332], [1748.8, 1.9058], [1748.7, 0.0005], [1748.3, 0.0005], [1747.1, 0.0005], [1747.0, 0.0005], [1746.1, 1.829], [1746.0, 0.01], [1745.2, 0.0005], [1745.1, 0.0005], [1743.7, 0.0005], [1743.6, 1.8284], [1741.7, 0.0005], [1741.6, 0.0005], [1741.0, 2.0563], [1740.0, 0.0005], [1738.5, 2.0502], [1738.2, 0.0011], [1738.0, 0.0005], [1737.9, 0.0005], [1737.3, 0.0102], [1735.9, 2.2547], [1734.4, 0.0005], [1734.3, 0.0005], [1733.8, 0.0005], [1733.4, 2.7538], [1733.3, 0.0005], [1732.9, 0.0005], [1732.7, 0.0005], [1732.0, 0.0005], [1731.6, 0.0001], [1731.3, 0.0001], [1731.2, 0.0005], [1731.1, 0.0005], [1730.9, 0.0006], [1730.8, 2.8535], [1730.3, 0.0005], [1730.0, 1.0], [1729.7, 0.0005], [1729.6, 0.0005]], "asks": [[1798.0, 0.0101], [1806.5, 1.3169], [1806.6, 0.01], [1809.7, 0.5909], [1813.9, 1.0682], [1815.3, 0.01], [1816.0, 0.9538], [1818.2, 1.2549], [1818.4, 1.4268], [1820.7, 1.1855], [1823.5, 1.238], [1824.0, 0.01], [1825.0, 5.0], [1826.2, 1.7364], [1830.2, 2.5889], [1831.5, 1.4745], [1832.6, 0.01], [1834.2, 1.5457], [1836.7, 1.6251], [1839.5, 1.665], [1841.3, 0.01], [1842.2, 2.1326], [1843.4, 0.0692], [1844.9, 2.645], [1847.5, 2.0651], [1847.7, 1.8313], [1850.0, 0.01], [1852.8, 2.0297], [1855.0, 5.0], [1855.5, 2.3096], [1859.1, 2.0935], [1875.0, 5.0], [1885.0, 5.0], [1897.6, 1.1215], [1902.2, 1.4882], [1906.2, 1.2519], [1915.0, 5.0], [1935.0, 5.0], [2025.5, 0.0148], [2072.1, 2.3564], [2100.0, 0.0001], [2161.2, 2.6414], [2168.0, 2.9568], [2200.0, 0.0001], [2300.0, 0.0001], [2400.0, 0.0001], [2500.0, 0.14], [2600.0, 0.3064], [17437.0, 0.03]], "action": "partial"}}
1618677881.1360571: {"type": "subscribed", "channel": "orderbook", "market": "SUSHIBEAR/USD"}
1618677881.236022: {"channel": "orderbook", "market": "AKRO/USD", "type": "partial", "data": {"time": 1618677881.161164, "checksum": 509768734, "bids": [[0.068165, 33.0], [0.06816, 38085.0], [0.068155, 15224.0], [0.068135, 188.0], [0.06801, 7629.0], [0.06798, 33.0], [0.06781, 1.0], [0.0678, 33.0], [0.067765, 155941.0], [0.067615, 33.0], [0.067435, 33.0], [0.0674, 1.0], [0.067255, 33.0], [0.06707, 33.0], [0.06698, 1.0], [0.06697, 156418.0], [0.06689, 34.0], [0.06671, 34.0], [0.066635, 188164.0], [0.06656, 1.0], [0.066535, 34.0], [0.066405, 9094.0], [0.0664, 3012.0], [0.066355, 34.0], [0.066175, 34.0], [0.06615, 217078.0], [0.06614, 1.0], [0.066035, 3749.0], [0.066, 64.0], [0.06582, 34.0], [0.06573, 1.0], [0.06564, 34.0], [0.06546, 34.0], [0.06531, 1.0], [0.065285, 34.0], [0.06511, 34.0], [0.06505, 319703.0], [0.06493, 35.0], [0.0649, 341744.0], [0.06489, 1.0], [0.064755, 35.0], [0.06458, 35.0], [0.06448, 1.0], [0.064405, 35.0], [0.06423, 35.0], [0.06406, 1.0], [0.064055, 35.0], [0.064025, 392156.0], [0.06388, 35.0], [0.06371, 35.0], [0.06364, 1.0], [0.063535, 35.0], [0.063365, 35.0], [0.06322, 1.0], [0.06321, 459550.0], [0.06319, 36.0], [0.06315, 452145.0], [0.06302, 36.0], [0.06285, 36.0], [0.06281, 1.0], [0.06268, 36.0], [0.06266, 4828.0], [0.0626, 405208.0], [0.06251, 36.0], [0.0625, 1172.0], [0.06239, 1.0], [0.06234, 36.0], [0.06217, 36.0], [0.062, 439.0], [0.06197, 1.0], [0.061835, 36.0], [0.061665, 36.0], [0.061625, 550529.0], [0.06156, 1.0], [0.0615, 37.0], [0.06133, 37.0], [0.061195, 408.0], [0.061165, 37.0], [0.06114, 542350.0], [0.061, 37.0], [0.060845, 821.0], [0.060835, 37.0], [0.06072, 1.0], [0.06067, 37.0], [0.060505, 37.0], [0.0605, 24793.0], [0.06034, 37.0], [0.06032, 7305.0], [0.06031, 1.0], [0.060175, 37.0], [0.060015, 37.0], [0.05989, 1.0], [0.05985, 38.0], [0.05969, 37.0], [0.05964, 1.0], [0.059525, 38.0], [0.05947, 1.0], [0.05945, 1.0], [0.05939, 1.0], [0.05937, 1.0]], "asks": [[0.068565, 38308.0], [0.06865, 1.0], [0.06875, 33.0], [0.068905, 160174.0], [0.068935, 33.0], [0.06906, 1.0], [0.06912, 33.0], [0.069305, 32.0], [0.06948, 1.0], [0.06949, 32.0], [0.06968, 32.0], [0.069865, 32.0], [0.0699, 1.0], [0.06997, 209200.0], [0.070055, 32.0], [0.070245, 32.0], [0.07031, 1.0], [0.070435, 32.0], [0.07054, 198634.0], [0.070625, 32.0], [0.07073, 1.0], [0.070815, 32.0], [0.071005, 32.0], [0.07115, 1.0], [0.071195, 13.0], [0.07139, 32.0], [0.07157, 1.0], [0.07158, 31.0], [0.071775, 306832.0], [0.071965, 31.0], [0.07198, 1.0], [0.072, 6.0], [0.07216, 31.0], [0.072205, 364013.0], [0.072355, 31.0], [0.0724, 1.0], [0.072415, 3791.0], [0.07282, 1.0], [0.073155, 324864.0], [0.07323, 1.0], [0.0733, 1853.0], [0.07365, 1.0], [0.074, 6.0], [0.07407, 1.0], [0.07448, 1.0], [0.07458, 323167.0], [0.0749, 1.0], [0.07532, 1.0], [0.0755, 358214.0], [0.0756, 5685.0], [0.07574, 1.0], [0.07575, 350949.0], [0.076, 6.0], [0.07615, 1.0], [0.07657, 1.0], [0.07699, 1.0], [0.07716, 501334.0], [0.0774, 1.0], [0.07741, 1000.0], [0.077455, 343542.0], [0.07782, 1.0], [0.078, 6.0], [0.07822, 527302.0], [0.07824, 1.0], [0.07866, 1.0], [0.07907, 1.0], [0.07924, 25.0], [0.07942, 25.0], [0.07949, 1.0], [0.079695, 25.0], [0.07982, 25.0], [0.07991, 1.0], [0.08, 13908.0], [0.08005, 5849.0], [0.080075, 25.0], [0.08026, 25.0], [0.08032, 1.0], [0.080455, 25.0], [0.080655, 25.0], [0.08074, 1.0], [0.0808, 76296.0], [0.08085, 25.0], [0.081, 24998.0], [0.08116, 1.0], [0.08157, 1.0], [0.081675, 4000.0], [0.081985, 4643.0], [0.08199, 1.0], [0.082, 6.0], [0.08241, 1.0], [0.0825, 25.0], [0.08283, 1.0], [0.08324, 1.0], [0.08366, 1.0], [0.084, 12178.0], [0.08408, 1.0], [0.08449, 1.0], [0.08491, 1.0], [0.085, 1084.0], [0.08533, 1.0]], "action": "partial"}}
1618677881.335297: {"channel": "orderbook", "market": "THETAHEDGE/USD", "type": "partial", "data": {"time": 1618677881.2639272, "checksum": 3276145593, "bids": [[24.89, 145.67], [24.865, 1136.87], [24.8225, 1266.79], [24.72, 1.62], [24.7175, 1577.28], [24.4575, 0.13], [23.785, 923.08], [23.6925, 0.13], [22.9225, 0.14], [22.715, 8685.69], [22.1425, 0.14], [21.355, 0.15]], "asks": [[25.455, 182.75], [25.5375, 1282.45], [25.635, 1260.44], [25.65, 1382.08], [25.99, 0.07], [26.825, 661.7], [28.09, 7536.62], [55.78, 0.5], [111.0, 0.5], [223.0, 0.5], [446.0, 0.5], [892.0, 0.5], [1784.0, 0.5], [3569.0, 0.5], [7139.0, 0.5], [10000.0, 0.04], [14279.0, 0.5], [20000.0, 0.01], [28559.0, 0.5], [30000.0, 0.01], [90000.0, 0.01]], "action": "partial"}}
1618677881.423315: {"channel": "orderbook", "market": "SXPBULL/USD", "type": "partial", "data": {"time": 1618677881.3352423, "checksum": 400692486, "bids": [[51.675, 28.768], [51.525, 34.4], [51.5, 0.137], [51.425, 0.227], [51.4, 1.556], [51.375, 29.89], [51.3, 0.825], [51.275, 1.789], [51.25, 1.438], [51.225, 2.152], [51.2, 1.717], [51.175, 3.862], [51.15, 3.078], [51.125, 6.181], [51.1, 0.441], [51.075, 2.083], [51.05, 0.482], [51.025, 6.02], [51.0, 11.721], [50.975, 0.167], [50.95, 0.895], [50.925, 0.526], [50.9, 0.47], [50.875, 6.11], [50.85, 3.082], [50.825, 2.51], [50.8, 3.966], [50.775, 6.368], [50.75, 1.959], [50.725, 0.135], [50.7, 34.811], [50.675, 1.321], [50.65, 0.84], [50.625, 0.589], [50.6, 9.259], [50.575, 6.733], [50.55, 5.017], [50.525, 4.163], [50.5, 101.893], [50.475, 0.381], [50.45, 2.893], [50.425, 0.624], [50.4, 2.112], [50.375, 0.3], [50.35, 6.581], [50.325, 22.452], [50.3, 2.904], [50.275, 318.212], [50.25, 0.23], [50.225, 0.32], [50.2, 4.21], [50.175, 3.999], [50.15, 0.385], [50.125, 4.117], [50.1, 4.609], [50.075, 2.523], [50.05, 0.699], [50.025, 1.907], [50.0, 16.812], [49.975, 1.498], [49.95, 0.562], [49.925, 0.431], [49.9, 3.582], [49.875, 0.251], [49.85, 4.795], [49.825, 282.861], [49.8, 6.566], [49.775, 3.56], [49.75, 8.628], [49.725, 0.576], [49.7, 2.715], [49.675, 1.705], [49.65, 0.826], [49.625, 2.186], [49.6, 10.621], [49.575, 6.791], [49.55, 0.789], [49.525, 1.367], [49.5, 5.248], [49.475, 262.445], [49.45, 4.978], [49.425, 0.118], [49.4, 5.473], [49.375, 33.835], [49.35, 4.976], [49.325, 0.959], [49.3, 0.519], [49.275, 0.613], [49.25, 3.391], [49.225, 313.447], [49.2, 3.483], [49.175, 3.144], [49.15, 0.582], [49.125, 0.588], [49.1, 4.811], [49.075, 0.656], [49.05, 2.231], [49.025, 0.248], [49.0, 53.247], [48.975, 5.546]], "asks": [[51.775, 1.596], [51.8, 0.088], [51.825, 0.059], [51.85, 3.287], [51.875, 2.366], [51.9, 0.263], [51.925, 0.188], [51.95, 6.338], [51.975, 16.163], [52.0, 1.139], [52.05, 0.083], [52.075, 3.72], [52.1, 0.338], [52.125, 1.107], [52.15, 0.488], [52.175, 0.609], [52.2, 12.658], [52.225, 1.146], [52.25, 0.732], [52.275, 0.562], [52.3, 3.019], [52.325, 1.846], [52.35, 2.17], [52.375, 26.555], [52.4, 3.144], [52.425, 38.895], [52.45, 5.165], [52.475, 0.41], [52.5, 1.44], [52.525, 3.459], [52.55, 5.803], [52.575, 82.619], [52.6, 0.542], [52.625, 0.847], [52.65, 2.231], [52.675, 0.298], [52.7, 3.808], [52.725, 6.306], [52.75, 30.675], [52.775, 1.361], [52.8, 0.817], [52.825, 3.951], [52.85, 357.494], [52.875, 2.772], [52.9, 0.789], [52.925, 1.209], [52.95, 3.391], [52.975, 0.576], [53.0, 222.697], [53.025, 3.958], [53.05, 9.627], [53.075, 1.904], [53.1, 118.276], [53.125, 1.28], [53.15, 3.758], [53.175, 312.419], [53.2, 4.981], [53.225, 0.271], [53.25, 11.617], [53.275, 0.561], [53.3, 0.968], [53.325, 1.237], [53.35, 1.396], [53.375, 1.695], [53.4, 1.63], [53.425, 1.547], [53.45, 1.124], [53.475, 2.393], [53.5, 1.474], [53.525, 4.71], [53.55, 5.048], [53.575, 4.553], [53.6, 1.538], [53.625, 1.268], [53.65, 1.354], [53.675, 1.818], [53.7, 533.958], [53.725, 0.803], [53.75, 0.638], [53.775, 0.515], [53.8, 4.927], [53.825, 1.249], [53.85, 13.559], [53.875, 3.218], [53.9, 54.009], [53.925, 1.78], [53.95, 0.801], [53.975, 0.35], [54.0, 432.706], [54.025, 1.019], [54.05, 7.892], [54.075, 7.509], [54.1, 3.23], [54.125, 0.756], [54.15, 3.459], [54.175, 0.531], [54.2, 0.493], [54.225, 431.085], [54.25, 8.593], [54.275, 7.631]], "action": "partial"}}
1618677881.467031: {"channel": "orderbook", "market": "SXPBULL/USD", "type": "update", "data": {"time": 1618677881.385007, "checksum": 117816834, "bids": [[51.05, 12.35]], "asks": [], "action": "update"}}
1618677881.642765: {"channel": "orderbook", "market": "XRP/USD", "type": "partial", "data": {"time": 1618677881.5542355, "checksum": 2034651458, "bids": [[1.59105, 1102.0], [1.590775, 532.0], [1.5907, 2513.0], [1.59025, 63.0], [1.590075, 2040.0], [1.5898, 3511.0], [1.589625, 1453.0], [1.589275, 3675.0], [1.58925, 1366.0], [1.589, 4690.0], [1.588925, 4371.0], [1.588875, 367277.0], [1.58885, 5610.0], [1.5884, 1412.0], [1.588, 5300.0], [1.587475, 1.0], [1.587075, 2179.0], [1.586325, 95503.0], [1.58625, 1.0], [1.586, 1541.0], [1.5855, 1569.0], [1.5852, 162700.0], [1.585, 3185.0], [1.5846, 2455.0], [1.5845, 1495.0], [1.584275, 1.0], [1.5842, 4.0], [1.5841, 1412.0], [1.583925, 9817.0], [1.583625, 169187.0], [1.5835, 1585.0], [1.583, 9782.0], [1.5825, 1583.0], [1.582, 1474.0], [1.581675, 163999.0], [1.581125, 194978.0], [1.581075, 1.0], [1.581, 657.0], [1.5807, 1.0], [1.5798, 1413.0], [1.579675, 158863.0], [1.5795, 1.0], [1.579475, 245960.0], [1.57915, 186913.0], [1.5786, 4.0], [1.57785, 4.0], [1.576875, 1.0], [1.575675, 1.0], [1.5756, 1412.0], [1.5755, 1.0], [1.574875, 1.0], [1.573975, 173414.0], [1.5739, 83093.0], [1.573125, 3.0], [1.573, 24.0], [1.572925, 260277.0], [1.572725, 1.0], [1.57265, 1.0], [1.5717, 1.0], [1.571425, 292.0], [1.5714, 10.0], [1.5713, 1313.0], [1.571, 1.0], [1.57095, 5.0], [1.57045, 1.0], [1.57, 105.0], [1.569825, 4310.0], [1.569475, 4.0], [1.56855, 331.0], [1.5684, 1.0], [1.568375, 20.0], [1.56835, 4.0], [1.567725, 41565.0], [1.5677, 274881.0], [1.5674, 4.0], [1.5673, 3.0], [1.567, 1412.0], [1.5659, 308589.0], [1.565575, 1.0], [1.5654, 1.0], [1.564325, 1.0], [1.563425, 251989.0], [1.56305, 214197.0], [1.5628, 1413.0], [1.561875, 303925.0], [1.5617, 4.0], [1.56165, 15939.0], [1.56115, 4.0], [1.560525, 4.0], [1.5605, 1.0], [1.56, 10.0], [1.5594, 2.0], [1.55905, 1.0], [1.5585, 1412.0], [1.5578, 312008.0], [1.5573, 1.0], [1.557225, 3.0], [1.5571, 10.0], [1.556625, 1.0], [1.5561, 4.0]], "asks": [[1.592025, 5.0], [1.59205, 1.0], [1.593175, 633.0], [1.593625, 1.0], [1.593725, 2511.0], [1.593875, 5460.0], [1.5939, 4263.0], [1.593925, 5353.0], [1.594, 4911.0], [1.594175, 1404.0], [1.594225, 8183.0], [1.594475, 3785.0], [1.5945, 1441.0], [1.59455, 1375.0], [1.594925, 1.0], [1.59495, 1433.0], [1.595, 3218.0], [1.595075, 292474.0], [1.595325, 4.0], [1.5955, 1554.0], [1.5956, 1.0], [1.5957, 1685.0], [1.595725, 89410.0], [1.595775, 100707.0], [1.596, 1596.0], [1.596325, 3800.0], [1.5965, 4063.0], [1.5969, 1412.0], [1.597, 1444.0], [1.59715, 8279.0], [1.597675, 55.0], [1.598, 1709.0], [1.59825, 189.0], [1.5983, 654.0], [1.5984, 157.0], [1.5985, 2769.0], [1.5987, 1.0], [1.598925, 2.0], [1.599, 1582.0], [1.59915, 10.0], [1.599375, 187389.0], [1.5999, 10.0], [1.59995, 119410.0], [1.599975, 20.0], [1.6, 5.0], [1.6011, 4.0], [1.6012, 1412.0], [1.601275, 189799.0], [1.6017, 1.0], [1.6018, 6.0], [1.6022, 1.0], [1.60305, 223161.0], [1.603375, 4.0], [1.603475, 284426.0], [1.603825, 4.0], [1.6049, 2.0], [1.6053, 256841.0], [1.60535, 159840.0], [1.6055, 1412.0], [1.6057, 1.0], [1.60605, 253513.0], [1.606275, 1.0], [1.606425, 181799.0], [1.606625, 41645.0], [1.6067, 4.0], [1.6069, 2.0], [1.607075, 314202.0], [1.6076, 1.0], [1.60805, 4.0], [1.608575, 48.0], [1.608725, 232163.0], [1.609175, 247632.0], [1.6097, 1412.0], [1.61015, 22.0], [1.610825, 228258.0], [1.61085, 266263.0], [1.611025, 2180.0], [1.6123, 4.0], [1.612375, 4.0], [1.612525, 228089.0], [1.6128, 1.0], [1.613025, 6.0], [1.614, 764.0], [1.6142, 10.0], [1.615, 221.0], [1.615625, 15778.0], [1.6158, 1.0], [1.616125, 4.0], [1.61645, 248476.0], [1.616575, 343352.0], [1.6166, 1.0], [1.6178, 1.0], [1.6179, 4.0], [1.6183, 1412.0], [1.6195, 129.0], [1.62, 33.0], [1.620775, 2.0], [1.620975, 3.0], [1.6215, 6.0], [1.6225, 1413.0]], "action": "partial"}}
1618677881.6436422: {"channel": "orderbook", "market": "SXPBULL/USD", "type": "update", "data": {"time": 1618677881.5573564, "checksum": 400692486, "bids": [[51.05, 0.482]], "asks": [], "action": "update"}}
1618677881.652627: {"channel": "orderbook", "market": "XRP/USD", "type": "update", "data": {"time": 1618677881.5729685, "checksum": 2200371702, "bids": [[1.591075, 1100.0], [1.59105, 2.0], [1.5561, 0.0]], "asks": [[1.593875, 0.0], [1.5957, 0.0], [1.623, 8078.0], [1.623175, 2.0]], "action": "update"}}
1618677881.676265: {"channel": "orderbook", "market": "BTC-MOVE-WK-0507", "type": "partial", "data": {"time": 1618677881.5981214, "checksum": 901794806, "bids": [[4233.0, 0.0001], [4232.0, 2.2558], [4223.0, 3.0], [4139.0, 2.6323], [4121.0, 0.75], [4007.0, 1.5601], [3951.0, 1.8986], [3865.0, 4.0415], [3810.0, 2.9098], [3533.0, 3.6388], [3528.0, 2.734], [3422.0, 4.8814], [3360.0, 4.4035], [3207.0, 3.7228], [3054.0, 3.8222], [2904.0, 4.4623], [2764.0, 3.977], [2677.0, 4.4789], [2551.0, 5.8532], [2257.0, 7.0166], [2193.0, 7.6303], [1792.0, 10.9597]], "asks": [[4480.0, 0.75], [4481.0, 0.01], [4540.0, 2.3303], [4590.0, 1.9], [4642.0, 3.0162], [4663.0, 3.0], [4676.0, 1.6056], [4963.0, 1.7686], [4983.0, 0.003], [4999.0, 1.0], [5049.0, 1.0], [5099.0, 1.0], [5149.0, 1.0], [5160.0, 1.8926], [5283.0, 0.003], [5372.0, 2.6241], [5601.0, 2.54], [5648.0, 3.8069], [5649.0, 3.1212], [5783.0, 0.003], [5850.0, 0.05], [6050.0, 0.05], [6145.0, 2.6329], [6184.0, 4.2402], [6250.0, 0.05], [6400.0, 0.2], [6450.0, 0.05], [6514.0, 3.4714], [6771.0, 5.067], [6800.0, 0.2], [7051.0, 5.1213], [7414.0, 3.7892], [7473.0, 4.9852], [8038.0, 6.6824], [9101.0, 8.4351], [10229.0, 6.8484], [11489.0, 8.0186]], "action": "partial"}}
1618677881.676497: {"channel": "orderbook", "market": "SXPBULL/USD", "type": "update", "data": {"time": 1618677881.584734, "checksum": 2299278095, "bids": [], "asks": [[52.5, 1.524]], "action": "update"}}
1618677881.717955: {"channel": "orderbook", "market": "XRP/USD", "type": "update", "data": {"time": 1618677881.608664, "checksum": 1993312281, "bids": [[1.588875, 0.0], [1.5561, 4.0]], "asks": [[1.592025, 0.0], [1.62335, 8051.0]], "action": "update"}}
1618677881.750856: {"channel": "orderbook", "market": "XRP/USD", "type": "update", "data": {"time": 1618677881.6729164, "checksum": 1013115250, "bids": [[1.591075, 6380.0]], "asks": [], "action": "update"}}
1618677881.784395: {"channel": "orderbook", "market": "SXPBULL/USD", "type": "update", "data": {"time": 1618677881.691584, "checksum": 3463709329, "bids": [[51.05, 1.669]], "asks": [], "action": "update"}}
1618677881.79818: {"channel": "orderbook", "market": "XRP/USD", "type": "update", "data": {"time": 1618677881.7235777, "checksum": 4105758199, "bids": [[1.5907, 0.0], [1.590525, 1438.0], [1.589275, 0.0], [1.55565, 2.0]], "asks": [[1.5934, 633.0], [1.593725, 0.0], [1.594175, 0.0], [1.6235, 4.0]], "action": "update"}}
1618677881.8256829: {"channel": "orderbook", "market": "XRP/USD", "type": "update", "data": {"time": 1618677881.7483766, "checksum": 1049591304, "bids": [[1.589625, 5128.0]], "asks": [], "action": "update"}}
1618677881.861801: {"channel": "orderbook", "market": "NVDA-0625", "type": "partial", "data": {"time": 1618677881.7723677, "checksum": 3644189371, "bids": [[638.05, 0.03], [636.15, 0.05], [635.05, 62.0925], [634.9, 13.6125], [633.9, 41.195], [633.4, 57.6625], [633.15, 61.2725], [632.25, 62.3975], [631.15, 82.5325], [630.1, 56.86], [628.9, 84.31], [627.6, 74.835], [626.15, 64.96], [624.7, 186.73], [623.3, 0.05], [623.15, 76.1225], [610.4, 0.1], [578.2, 223.52], [578.1, 243.6875], [551.3, 364.3225], [524.9, 401.9425], [508.5, 9.0], [507.0, 6.0], [499.1, 512.5025]], "asks": [[643.45, 59.4625], [643.8, 17.3975], [644.4, 30.7375], [646.1, 40.775], [647.0, 54.0775], [648.0, 57.82], [649.0, 58.2675], [650.15, 74.885], [651.35, 63.7475], [652.7, 69.245], [654.2, 100.9975], [655.8, 70.5525], [657.35, 90.945], [659.6, 0.05], [680.15, 57.48], [712.15, 247.975], [746.7, 304.305], [784.0, 349.4375], [824.3, 438.895], [867.85, 403.11]], "action": "partial"}}
1618677881.8969522: {"channel": "orderbook", "market": "XRP/USD", "type": "update", "data": {"time": 1618677881.7935188, "checksum": 1487563444, "bids": [], "asks": [[1.593175, 0.0], [1.6239, 1.0]], "action": "update"}}
1618677881.897027: {"channel": "orderbook", "market": "THETAHEDGE/USD", "type": "update", "data": {"time": 1618677881.8058205, "checksum": 2207731473, "bids": [], "asks": [[25.4225, 183.67]], "action": "update"}}
1618677881.903709: {"channel": "orderbook", "market": "SXPBULL/USD", "type": "update", "data": {"time": 1618677881.8234105, "checksum": 2718027086, "bids": [[51.025, 0.198]], "asks": [], "action": "update"}}
1618677881.934796: {"channel": "orderbook", "market": "SXPBULL/USD", "type": "update", "data": {"time": 1618677881.8481572, "checksum": 3207825186, "bids": [[51.05, 0.482]], "asks": [[52.375, 0.155]], "action": "update"}}
1618677881.9838889: {"channel": "orderbook", "market": "XRP/USD", "type": "update", "data": {"time": 1618677881.880787, "checksum": 4105269541, "bids": [], "asks": [[1.59205, 0.0], [1.62425, 4.0]], "action": "update"}}
1618677882.0008361: {"channel": "orderbook", "market": "XRP/USD", "type": "update", "data": {"time": 1618677881.921854, "checksum": 1592148127, "bids": [[1.591, 2513.0], [1.5815, 1527.0], [1.5561, 0.0], [1.55565, 0.0]], "asks": [[1.594025, 2511.0], [1.62425, 0.0]], "action": "update"}}
1618677882.025842: {"channel": "orderbook", "market": "SXPBULL/USD", "type": "update", "data": {"time": 1618677881.9474382, "checksum": 1761722564, "bids": [], "asks": [[52.4, 3.18]], "action": "update"}}
1618677882.043582: {"channel": "orderbook", "market": "AMD/USD", "type": "partial", "data": {"time": 1618677881.969603, "checksum": 1935389369, "bids": [[81.94, 0.08], [81.69, 691.17], [81.53, 169.49], [81.52, 0.08], [81.27, 253.76], [81.17, 273.11], [81.13, 0.04], [81.1, 0.08], [81.06, 1.21], [81.05, 302.72], [81.0, 7.0], [80.99, 237.88], [80.78, 0.04], [80.68, 0.08], [80.48, 472.74], [80.44, 327.88], [80.29, 445.73], [80.26, 338.7], [80.1, 413.37], [80.07, 422.83], [79.92, 447.08], [79.84, 0.08], [79.72, 499.93], [79.42, 0.08], [79.0, 0.08], [78.0, 0.1], [77.0, 0.1], [76.0, 0.1], [75.0, 0.2], [74.63, 1.48], [74.48, 1138.04], [74.26, 1706.49], [74.0, 0.1], [73.0, 0.1], [72.0, 0.1], [71.25, 1687.28], [71.0, 0.1], [70.0, 0.1], [69.0, 0.1], [68.28, 1646.0], [65.56, 1947.45]], "asks": [[82.37, 472.66], [82.49, 135.95], [82.68, 221.33], [82.78, 0.08], [82.88, 217.99], [83.07, 355.21], [83.21, 0.08], [83.27, 293.5], [83.46, 285.58], [83.63, 0.08], [83.65, 469.8], [83.84, 507.72], [84.04, 391.69], [84.05, 0.08], [84.24, 566.31], [84.42, 495.76], [84.47, 0.08], [84.61, 624.11], [84.89, 0.08], [85.0, 0.43], [85.09, 0.1], [85.31, 0.08], [85.73, 0.08], [86.0, 0.1], [86.15, 0.08], [86.5, 0.1], [86.57, 0.08], [87.0, 0.08], [87.07, 1073.71], [87.8, 20.0], [88.0, 0.1], [89.0, 4.0], [89.5, 0.1], [90.0, 0.01], [91.0, 0.26], [91.21, 1504.53], [92.0, 0.01], [93.0, 0.01], [95.33, 1886.21], [96.0, 0.21], [98.0, 0.01], [98.5, 0.2], [98.89, 9.99], [99.37, 1793.43], [100.0, 2.03], [102.0, 0.01], [103.47, 2130.16], [104.0, 0.01], [106.0, 0.01], [107.04, 2482.54], [131.0, 0.99]], "action": "partial"}}
1618677882.1009018: {"channel": "orderbook", "market": "XRP/USD", "type": "update", "data": {"time": 1618677882.0204022, "checksum": 4143697153, "bids": [], "asks": [[1.593225, 1100.0], [1.594025, 0.0]], "action": "update"}}
1618677882.114568: {"channel": "orderbook", "market": "ZECBULL/USD", "type": "partial", "data": {"time": 1618677882.0354176, "checksum": 728765294, "bids": [[7187.5, 0.63174], [7170.0, 1e-05], [7100.0, 2.37034], [7005.0, 1.71047], [6955.0, 0.05857], [6952.5, 1.93667], [6912.5, 2.16635], [6885.0, 3.3285], [6840.0, 0.00021], [6765.0, 3.11987], [6762.5, 2.23897], [6667.5, 3.04729], [6630.0, 2.80635], [6602.5, 0.00089], [6600.0, 2.85106], [6552.5, 1.92504], [6550.0, 0.03019], [6525.0, 15.49135], [6500.0, 0.03076], [6490.0, 2.54065], [6370.0, 17.47201], [6337.5, 16.62347], [6250.0, 0.8], [6095.0, 21.70248], [6040.0, 0.11791], [5825.0, 1.0], [5822.5, 23.78117], [5700.0, 0.17543], [5400.0, 0.02314], [5260.0, 0.00095], [5220.0, 1.0], [5082.5, 0.02214], [4995.0, 0.001], [4735.0, 0.0117], [4277.5, 0.02354], [3600.0, 0.03472], [2400.0, 0.10208], [2301.0, 0.04345], [2101.0, 0.04759], [2001.0, 0.04997], [1901.0, 0.0526], [1801.0, 0.05552], [1701.0, 0.05878], [1650.0, 0.07575], [1643.0, 0.1217], [1524.0, 0.0096], [1501.0, 0.06662], [1384.0, 0.0101], [1201.0, 0.08326], [1151.0, 0.0087], [1100.0, 0.11363], [1001.0, 0.0999], [1000.0, 0.005], [901.0, 0.11098], [808.0, 0.01], [800.0, 0.7052]], "asks": [[7295.0, 0.60465], [7307.5, 2.00806], [7330.0, 2.56957], [7350.0, 1.91774], [7362.5, 0.02774], [7417.5, 1.9473], [7467.5, 0.0008], [7532.5, 3.088], [7547.5, 4.84679], [7615.0, 2.63705], [7635.0, 4.22299], [7650.0, 1.95015], [7792.5, 4.19768], [7820.0, 5.99843], [7852.5, 4.59103], [8000.0, 0.14803], [8020.0, 0.09195], [8150.0, 0.001], [8550.0, 1.53079], [8652.0, 0.00919], [9000.0, 1.0952], [9085.0, 19.54425], [9192.5, 28.94761], [9380.0, 23.77249], [9417.5, 19.54278], [9457.5, 27.83476], [9500.0, 0.15767], [9597.5, 0.0498], [10000.0, 0.9231], [10290.0, 0.00047], [10500.0, 0.00442], [10900.0, 0.39396], [11000.0, 1.73469], [11500.0, 0.44668], [12000.0, 0.85297], [12500.0, 0.29765], [13000.0, 0.5], [14000.0, 3.30707], [14264.0, 0.0105], [14704.0, 0.00352], [15000.0, 0.575], [15435.0, 0.00047], [16000.0, 0.5], [17000.0, 0.5], [18000.0, 0.65217], [18500.0, 0.28914], [19000.0, 0.25665], [21000.0, 0.69035], [23000.0, 0.49015], [24000.0, 0.00017], [24500.0, 0.2636], [25000.0, 0.1], [27000.0, 0.00462], [29408.0, 0.00352], [32000.0, 0.32611], [40000.0, 0.00312], [50000.0, 0.15], [56595.0, 0.00047], [58816.0, 0.00352], [60000.0, 0.00208], [70000.0, 0.1], [75000.0, 0.0355], [100000.0, 0.46698], [117632.0, 0.00352], [150000.0, 0.05], [159495.0, 0.00047], [200000.0, 0.0525], [235264.0, 0.00352], [470528.0, 0.00352], [500000.0, 0.0327], [941056.0, 0.00352], [1882112.0, 0.00352], [3764224.0, 0.00352]], "action": "partial"}}
1618677882.123314: {"channel": "orderbook", "market": "XRP/USD", "type": "update", "data": {"time": 1618677882.0439568, "checksum": 1604065879, "bids": [], "asks": [[1.5984, 0.0], [1.62425, 4.0]], "action": "update"}}
1618677882.125512: {"channel": "orderbook", "market": "SUSHIBEAR/USD", "type": "partial", "data": {"time": 1618677882.047766, "checksum": 19331518, "bids": [[1.201e-05, 91430000.0], [1.194e-05, 99990000.0], [1.19e-05, 25500000.0], [1.185e-05, 230020000.0], [1.18e-05, 8530000.0], [1.178e-05, 99990000.0], [1.175e-05, 8460000.0], [1.173e-05, 99990000.0], [1.17e-05, 10780000.0], [1.169e-05, 99990000.0], [1.168e-05, 99990000.0], [1.165e-05, 8660000.0], [1.164e-05, 99990000.0], [1.163e-05, 99990000.0], [1.16e-05, 99990000.0], [1.157e-05, 99990000.0], [1.146e-05, 99990000.0], [1.144e-05, 99990000.0], [1.063e-05, 99990000.0], [1.023e-05, 99990000.0], [9.47e-06, 99990000.0], [9.41e-06, 99990000.0], [9.3e-06, 99990000.0], [7.86e-06, 200000.0], [7.01e-06, 140000.0], [7e-06, 970000.0], [6.5e-06, 2500000.0], [6e-06, 16660000.0], [5.55e-06, 200000.0], [5.14e-06, 1130000.0], [5.11e-06, 390000.0], [5e-06, 1600000.0], [4.9e-06, 30000.0], [4.86e-06, 2060000.0], [4.2e-06, 200000.0], [3.3e-06, 3030000.0], [3e-06, 710000.0], [2.9e-06, 55000.0], [2.45e-06, 150000.0], [2e-06, 10000000.0], [1.58e-06, 25520000.0], [1.44e-06, 13880000.0], [1.17e-06, 4270000.0], [1.11e-06, 200000.0], [1e-06, 143700000.0], [8e-07, 12500000.0], [6e-07, 16660000.0], [5.5e-07, 10000000.0], [5e-07, 33710000.0], [4.4e-07, 22720000.0], [3e-07, 3330000.0], [2e-07, 100000000.0], [1e-07, 100000000.0], [9e-08, 100000.0], [8e-08, 100000.0], [7e-08, 100000.0], [6e-08, 100000.0], [5e-08, 80100000.0], [4e-08, 50100000.0], [3e-08, 100000.0], [2e-08, 50100000.0], [1e-08, 203990000.0]], "asks": [[1.22e-05, 8700000.0], [1.222e-05, 70530000.0], [1.231e-05, 99990000.0], [1.232e-05, 99990000.0], [1.235e-05, 8320000.0], [1.24e-05, 117070000.0], [1.255e-05, 16690000.0], [1.259e-05, 99990000.0], [1.265e-05, 99990000.0], [1.279e-05, 99990000.0], [1.282e-05, 99990000.0], [1.288e-05, 99990000.0], [1.301e-05, 99990000.0], [1.307e-05, 99990000.0], [1.312e-05, 99990000.0], [1.322e-05, 99990000.0], [1.329e-05, 99990000.0], [1.342e-05, 99990000.0], [1.36e-05, 99990000.0], [1.396e-05, 99990000.0], [1.597e-05, 99990000.0], [1.6e-05, 100000.0], [2.022e-05, 590000.0], [2.15e-05, 50000.0], [2.19e-05, 40000.0], [2.501e-05, 50000.0], [2.6e-05, 78910000.0], [2.878e-05, 3600000.0], [3.999e-05, 80060000.0], [4e-05, 60000.0], [4.5e-05, 40000.0], [5.2e-05, 50000.0], [5.756e-05, 1800000.0], [6e-05, 30000.0], [7.55e-05, 255000.0], [8e-05, 40000.0], [9e-05, 60000.0], [0.0001, 9948000.0], [0.0001151, 900000.0], [0.000129, 38000.0], [0.00015558, 72000.0], [0.000169, 29000.0], [0.00018, 145000.0], [0.000219, 22000.0], [0.0002302, 450000.0], [0.00027, 10000.0], [0.000299, 16000.0], [0.000399, 12000.0], [0.00044, 205000.0], [0.0004604, 220000.0], [0.000539, 9000.0], [0.000729, 6000.0], [0.0008, 25000.0], [0.0009209, 110000.0], [0.000989, 5000.0], [0.001, 10000.0], [0.001376, 100000.0], [0.0014, 120000.0], [0.001485, 4000.0], [0.00175558, 48000.0], [0.001841, 60000.0], [0.001985, 3000.0], [0.00285, 2000.0], [0.00315692, 80000.0], [0.003683, 30000.0], [0.0038, 140000.0], [0.00383, 730000.0], [0.00395, 1000.0], [0.00403, 50000.0], [0.00423, 10000.0], [0.00444, 10000.0], [0.00475558, 21000.0], [0.006, 720000.0], [0.006211, 2000.0], [0.007, 10000.0], [0.00715692, 72000.0], [0.0072, 3000.0], [0.007367, 10000.0], [0.008, 322000.0], [0.0081, 160000.0], [0.0092, 5000.0], [0.00945, 30000.0], [0.01, 12690000.0], [0.012, 270000.0], [0.01213, 1200000.0], [0.01373, 10000.0], [0.01376, 100000.0], [0.0139, 4000.0], [0.01429, 140000.0], [0.01473, 10000.0], [0.018, 10000.0], [0.02, 3132000.0], [0.02112198, 10000.0], [0.02363, 2140000.0], [0.0246, 30000.0], [0.025, 12000.0], [0.027, 220000.0], [0.02999, 350000.0], [0.03, 23000.0], [0.035, 12000.0]], "action": "partial"}}
1618677882.134159: {"channel": "orderbook", "market": "SXPBULL/USD", "type": "update", "data": {"time": 1618677882.0496082, "checksum": 405220806, "bids": [[51.05, 268.092]], "asks": [], "action": "update"}}
1618677882.173208: {"channel": "orderbook", "market": "XRP/USD", "type": "update", "data": {"time": 1618677882.094051, "checksum": 2077334798, "bids": [], "asks": [[1.594475, 0.0], [1.59825, 0.0], [1.624325, 6.0], [1.6256, 1.0]], "action": "update"}}
1618677882.1778262: {"channel": "orderbook", "market": "PAXG/USD", "type": "update", "data": {"time": 1618677882.0969095, "checksum": 2811656200, "bids": [], "asks": [], "action": "update"}}
1618677882.204352: {"channel": "orderbook", "market": "THETAHEDGE/USD", "type": "update", "data": {"time": 1618677882.1317623, "checksum": 586011437, "bids": [[24.89, 0.0]], "asks": [], "action": "update"}}
1618677882.223249: {"channel": "orderbook", "market": "XRP/USD", "type": "update", "data": {"time": 1618677882.1450818, "checksum": 2285451605, "bids": [], "asks": [[1.594225, 10693.0]], "action": "update"}}
1618677882.270028: {"channel": "orderbook", "market": "AKRO/USD", "type": "update", "data": {"time": 1618677882.1864939, "checksum": 509768734, "bids": [], "asks": [], "action": "update"}}
1618677882.270079: {"channel": "orderbook", "market": "THETAHEDGE/USD", "type": "update", "data": {"time": 1618677882.1880763, "checksum": 3997660689, "bids": [], "asks": [[25.455, 0.0]], "action": "update"}}
1618677882.274018: {"channel": "orderbook", "market": "SXPBULL/USD", "type": "update", "data": {"time": 1618677882.1858797, "checksum": 1761722564, "bids": [[51.05, 0.482]], "asks": [], "action": "update"}}
1618677882.281494: {"channel": "orderbook", "market": "XRP/USD", "type": "update", "data": {"time": 1618677882.2027733, "checksum": 3642703806, "bids": [], "asks": [[1.5934, 0.0], [1.5936, 633.0]], "action": "update"}}
1618677882.301183: {"channel": "orderbook", "market": "XRP/USD", "type": "update", "data": {"time": 1618677882.2214978, "checksum": 2517661546, "bids": [[1.571425, 0.0], [1.5561, 4.0]], "asks": [[1.594, 6442.0], [1.599, 0.0], [1.6258, 1.0]], "action": "update"}}
1618677882.30758: {"channel": "orderbook", "market": "THETAHEDGE/USD", "type": "update", "data": {"time": 1618677882.2352455, "checksum": 3313924624, "bids": [[24.8675, 146.91]], "asks": [], "action": "update"}}
1618677882.3115351: {"channel": "orderbook", "market": "ZECBULL/USD", "type": "update", "data": {"time": 1618677882.2342763, "checksum": 776531947, "bids": [], "asks": [[8012.5, 15.65945]], "action": "update"}}
1618677882.322635: {"channel": "orderbook", "market": "XRP/USD", "type": "update", "data": {"time": 1618677882.2479727, "checksum": 135520236, "bids": [], "asks": [[1.594625, 330064.0], [1.6258, 0.0]], "action": "update"}}
1618677882.34567: {"channel": "orderbook", "market": "SUSHIBEAR/USD", "type": "update", "data": {"time": 1618677882.2723181, "checksum": 3663511381, "bids": [], "asks": [[1.224e-05, 99990000.0], [0.035, 0.0]], "action": "update"}}
1618677882.3481688: {"channel": "orderbook", "market": "XRP/USD", "type": "update", "data": {"time": 1618677882.2720468, "checksum": 1182617111, "bids": [], "asks": [[1.598875, 157.0], [1.6256, 0.0]], "action": "update"}}
1618677882.352608: {"channel": "orderbook", "market": "THETAHEDGE/USD", "type": "update", "data": {"time": 1618677882.2785926, "checksum": 3313924624, "bids": [], "asks": [], "action": "update"}}
1618677882.381563: {"channel": "orderbook", "market": "ZECBULL/USD", "type": "update", "data": {"time": 1618677882.301273, "checksum": 509401118, "bids": [], "asks": [[8375.0, 18.5281]], "action": "update"}}
1618677882.403706: {"channel": "orderbook", "market": "SXPBULL/USD", "type": "update", "data": {"time": 1618677882.2900116, "checksum": 21307571, "bids": [[51.1, 50.001]], "asks": [], "action": "update"}}
1618677882.403761: {"channel": "orderbook", "market": "XRP/USD", "type": "update", "data": {"time": 1618677882.3250499, "checksum": 822754478, "bids": [], "asks": [[1.598725, 189.0], [1.624325, 0.0]], "action": "update"}}
1618677882.456852: {"channel": "orderbook", "market": "SXPBULL/USD", "type": "update", "data": {"time": 1618677882.3633668, "checksum": 2669244079, "bids": [[51.3, 0.929], [51.1, 0.441]], "asks": [], "action": "update"}}
1618677882.480835: {"channel": "orderbook", "market": "XRP/USD", "type": "update", "data": {"time": 1618677882.3986998, "checksum": 646395141, "bids": [[1.5898, 7186.0], [1.589625, 1453.0], [1.588475, 274360.0], [1.5561, 0.0]], "asks": [], "action": "update"}}
1618677882.480938: {"channel": "orderbook", "market": "SXPBULL/USD", "type": "update", "data": {"time": 1618677882.3965006, "checksum": 3070079899, "bids": [[50.975, 5.985]], "asks": [], "action": "update"}}
1618677882.515594: {"channel": "orderbook", "market": "XRP/USD", "type": "update", "data": {"time": 1618677882.429358, "checksum": 2831584331, "bids": [], "asks": [[1.594225, 8183.0]], "action": "update"}}
1618677882.541877: {"channel": "orderbook", "market": "SXPBULL/USD", "type": "update", "data": {"time": 1618677882.4473078, "checksum": 2582757709, "bids": [[51.0, 11.761]], "asks": [[52.55, 5.913]], "action": "update"}}
1618677882.590229: {"channel": "orderbook", "market": "XRP/USD", "type": "update", "data": {"time": 1618677882.5015495, "checksum": 3916670607, "bids": [[1.591, 0.0], [1.5561, 4.0]], "asks": [[1.5996, 188.0], [1.62425, 0.0]], "action": "update"}}
1618677882.606399: {"channel": "orderbook", "market": "SUSHIBEAR/USD", "type": "update", "data": {"time": 1618677882.5269623, "checksum": 4057438042, "bids": [[1.202e-05, 85160000.0]], "asks": [[1.222e-05, 0.0], [0.035, 12000.0]], "action": "update"}}
1618677882.6202052: {"channel": "orderbook", "market": "SXPBULL/USD", "type": "update", "data": {"time": 1618677882.5317152, "checksum": 360347527, "bids": [[50.275, 2.876]], "asks": [], "action": "update"}}
1618677882.641867: {"channel": "orderbook", "market": "XRP/USD", "type": "update", "data": {"time": 1618677882.5501535, "checksum": 3971391493, "bids": [[1.5815, 3090.0]], "asks": [], "action": "update"}}
1618677882.6744928: {"channel": "orderbook", "market": "ZECBULL/USD", "type": "update", "data": {"time": 1618677882.5766952, "checksum": 974421272, "bids": [], "asks": [[9085.0, 0.0]], "action": "update"}}
1618677882.674618: {"channel": "orderbook", "market": "XRP/USD", "type": "update", "data": {"time": 1618677882.5800352, "checksum": 3971391493, "bids": [], "asks": [], "action": "update"}}
1618677882.6780229: {"channel": "orderbook", "market": "SXPBULL/USD", "type": "update", "data": {"time": 1618677882.5784097, "checksum": 3360370235, "bids": [[51.05, 104.377]], "asks": [], "action": "update"}}
1618677882.680639: {"channel": "orderbook", "market": "XRP/USD", "type": "update", "data": {"time": 1618677882.6016498, "checksum": 2379692042, "bids": [[1.568575, 293.0], [1.5561, 0.0]], "asks": [], "action": "update"}}
1618677882.696317: {"channel": "orderbook", "market": "BTC-MOVE-WK-0507", "type": "update", "data": {"time": 1618677882.6209877, "checksum": 901794806, "bids": [], "asks": [], "action": "update"}}
1618677882.7096362: {"channel": "orderbook", "market": "XRP/USD", "type": "update", "data": {"time": 1618677882.6320348, "checksum": 4162183910, "bids": [[1.5907, 2513.0], [1.556625, 0.0]], "asks": [[1.593925, 7864.0]], "action": "update"}}
1618677882.756474: {"channel": "orderbook", "market": "XRP/USD", "type": "update", "data": {"time": 1618677882.6745296, "checksum": 2264313969, "bids": [[1.589, 50478.0]], "asks": [[1.5953, 3668.0], [1.6239, 0.0]], "action": "update"}}
1618677882.80927: {"channel": "orderbook", "market": "XRP/USD", "type": "update", "data": {"time": 1618677882.7292278, "checksum": 4065776854, "bids": [[1.5911, 18.0], [1.5571, 0.0]], "asks": [], "action": "update"}}
1618677882.854733: {"channel": "orderbook", "market": "ZECBULL/USD", "type": "update", "data": {"time": 1618677882.775178, "checksum": 3257661835, "bids": [], "asks": [[9192.5, 0.0]], "action": "update"}}
1618677882.885149: {"channel": "orderbook", "market": "XRP/USD", "type": "update", "data": {"time": 1618677882.804111, "checksum": 2315085032, "bids": [[1.589, 4690.0]], "asks": [], "action": "update"}}
1618677882.906423: {"channel": "orderbook", "market": "NVDA-0625", "type": "update", "data": {"time": 1618677882.830128, "checksum": 3644189371, "bids": [], "asks": [], "action": "update"}}
1618677882.990417: {"channel": "orderbook", "market": "SXPBULL/USD", "type": "update", "data": {"time": 1618677882.9049728, "checksum": 1288041767, "bids": [[50.525, 317.939]], "asks": [[52.35, 41.97]], "action": "update"}}
1618677883.009525: {"channel": "orderbook", "market": "XRP/USD", "type": "update", "data": {"time": 1618677882.9327385, "checksum": 1251357234, "bids": [[1.591075, 5280.0], [1.590525, 0.0], [1.5571, 10.0]], "asks": [[1.5936, 0.0], [1.6239, 1.0]], "action": "update"}}
1618677883.082253: {"channel": "orderbook", "market": "XRP/USD", "type": "update", "data": {"time": 1618677882.9585357, "checksum": 1001065565, "bids": [], "asks": [[1.5932, 633.0], [1.5941, 1398.0], [1.6235, 0.0], [1.6239, 0.0]], "action": "update"}}
1618677883.082328: {"channel": "orderbook", "market": "SXPBULL/USD", "type": "update", "data": {"time": 1618677882.9547622, "checksum": 3123057833, "bids": [[51.05, 0.482]], "asks": [], "action": "update"}}
1618677883.0823581: {"channel": "orderbook", "market": "XRP/USD", "type": "update", "data": {"time": 1618677882.9768279, "checksum": 1214954177, "bids": [[1.590075, 633.0]], "asks": [], "action": "update"}}
1618677883.089298: {"channel": "orderbook", "market": "XRP/USD", "type": "update", "data": {"time": 1618677883.001665, "checksum": 3902456802, "bids": [], "asks": [[1.593225, 0.0], [1.593675, 1356.0], [1.594225, 302841.0]], "action": "update"}}
1618677883.094485: {"channel": "orderbook", "market": "AMD/USD", "type": "update", "data": {"time": 1618677883.002635, "checksum": 1935389369, "bids": [], "asks": [], "action": "update"}}
1618677883.1299179: {"channel": "orderbook", "market": "XRP/USD", "type": "update", "data": {"time": 1618677883.0525205, "checksum": 2289512101, "bids": [], "asks": [[1.593025, 1100.0], [1.594425, 3470.0], [1.623175, 0.0], [1.62335, 0.0]], "action": "update"}}
1618677883.141842: {"channel": "orderbook", "market": "ZECBULL/USD", "type": "update", "data": {"time": 1618677883.065263, "checksum": 3257661835, "bids": [], "asks": [], "action": "update"}}
1618677883.151764: {"channel": "orderbook", "market": "XRP/USD", "type": "update", "data": {"time": 1618677883.0754118, "checksum": 4016946793, "bids": [], "asks": [[1.59205, 5.0], [1.623, 0.0]], "action": "update"}}
1618677883.185364: {"channel": "orderbook", "market": "XRP/USD", "type": "update", "data": {"time": 1618677883.1056783, "checksum": 2489540817, "bids": [[1.591075, 0.0], [1.5907, 0.0], [1.556625, 1.0], [1.5561, 4.0]], "asks": [[1.593025, 0.0], [1.593925, 5353.0], [1.5996, 0.0], [1.623, 8078.0], [1.623175, 2.0]], "action": "update"}}
1618677883.214508: {"channel": "orderbook", "market": "XRP/USD", "type": "update", "data": {"time": 1618677883.1301134, "checksum": 2237802581, "bids": [], "asks": [[1.5932, 0.0], [1.595075, 0.0], [1.5953, 0.0], [1.62335, 8051.0], [1.6235, 4.0], [1.6239, 1.0]], "action": "update"}}
1618677883.221709: {"channel": "orderbook", "market": "PAXG/USD", "type": "update", "data": {"time": 1618677883.1417708, "checksum": 2811656200, "bids": [], "asks": [], "action": "update"}}
1618677883.239264: {"channel": "orderbook", "market": "XRP/USD", "type": "update", "data": {"time": 1618677883.1565125, "checksum": 3707374415, "bids": [[1.5865, 1487.0], [1.5561, 0.0]], "asks": [[1.59195, 1100.0], [1.593, 633.0], [1.593275, 3880.0], [1.62335, 0.0], [1.6235, 0.0], [1.6239, 0.0]], "action": "update"}}
1618677883.25213: {"channel": "orderbook", "market": "SXPBULL/USD", "type": "update", "data": {"time": 1618677883.1712015, "checksum": 3919961616, "bids": [[51.05, 268.092]], "asks": [], "action": "update"}}
1618677883.282112: {"channel": "orderbook", "market": "XRP/USD", "type": "update", "data": {"time": 1618677883.204314, "checksum": 3844310038, "bids": [[1.5815, 1563.0]], "asks": [], "action": "update"}}
1618677883.304699: {"channel": "orderbook", "market": "XRP/USD", "type": "update", "data": {"time": 1618677883.2243228, "checksum": 2732425750, "bids": [[1.5815, 0.0], [1.5561, 4.0]], "asks": [[1.593, 0.0], [1.599, 1536.0]], "action": "update"}}
1618677883.3179772: {"channel": "orderbook", "market": "AKRO/USD", "type": "update", "data": {"time": 1618677883.2354248, "checksum": 509768734, "bids": [], "asks": [], "action": "update"}}
1618677883.391351: {"channel": "orderbook", "market": "XRP/USD", "type": "update", "data": {"time": 1618677883.2770336, "checksum": 3583677605, "bids": [[1.590225, 2514.0], [1.5561, 0.0]], "asks": [[1.5931, 2512.0], [1.594075, 3466.0], [1.623, 0.0], [1.623175, 0.0]], "action": "update"}}
1618677883.391554: {"channel": "orderbook", "market": "THETAHEDGE/USD", "type": "update", "data": {"time": 1618677883.3034084, "checksum": 3313924624, "bids": [], "asks": [], "action": "update"}}
1618677883.4227872: {"channel": "orderbook", "market": "XRP/USD", "type": "update", "data": {"time": 1618677883.3268588, "checksum": 2736007110, "bids": [], "asks": [[1.592575, 633.0], [1.594, 4911.0], [1.6225, 0.0]], "action": "update"}}
1618677883.422953: {"channel": "orderbook", "market": "ZECBULL/USD", "type": "update", "data": {"time": 1618677883.3319368, "checksum": 564942557, "bids": [[7195.0, 0.41445]], "asks": [], "action": "update"}}
1618677883.438883: {"channel": "orderbook", "market": "XRP/USD", "type": "update", "data": {"time": 1618677883.3496633, "checksum": 1607735361, "bids": [], "asks": [[1.59875, 188.0], [1.6215, 0.0]], "action": "update"}}
1618677883.480523: {"channel": "orderbook", "market": "ZECBULL/USD", "type": "update", "data": {"time": 1618677883.3947911, "checksum": 481539776, "bids": [[7170.0, 0.0]], "asks": [], "action": "update"}}
1618677883.4806569: {"channel": "orderbook", "market": "SXPBULL/USD", "type": "update", "data": {"time": 1618677883.386677, "checksum": 3919961616, "bids": [], "asks": [], "action": "update"}}
1618677883.5081222: {"channel": "orderbook", "market": "XRP/USD", "type": "update", "data": {"time": 1618677883.4266393, "checksum": 2842733546, "bids": [[1.58875, 328051.0], [1.556625, 0.0]], "asks": [], "action": "update"}}
1618677883.525386: {"channel": "orderbook", "market": "SXPBULL/USD", "type": "update", "data": {"time": 1618677883.4408371, "checksum": 2449277119, "bids": [], "asks": [[52.35, 2.17]], "action": "update"}}
1618677883.5259252: {"channel": "orderbook", "market": "XRP/USD", "type": "update", "data": {"time": 1618677883.4517355, "checksum": 3043883435, "bids": [[1.590225, 0.0], [1.556625, 1.0]], "asks": [], "action": "update"}}
1618677883.557237: {"channel": "orderbook", "market": "XRP/USD", "type": "update", "data": {"time": 1618677883.4768858, "checksum": 1780475815, "bids": [], "asks": [[1.5931, 0.0], [1.6215, 6.0]], "action": "update"}}
1618677883.575108: {"channel": "orderbook", "market": "XRP/USD", "type": "update", "data": {"time": 1618677883.499319, "checksum": 571098978, "bids": [], "asks": [[1.59205, 0.0], [1.6225, 1413.0]], "action": "update"}}
1618677883.598422: {"channel": "orderbook", "market": "SXPBULL/USD", "type": "update", "data": {"time": 1618677883.5119326, "checksum": 2711914829, "bids": [[51.05, 0.482]], "asks": [], "action": "update"}}
1618677883.603937: {"channel": "orderbook", "market": "XRP/USD", "type": "update", "data": {"time": 1618677883.5300488, "checksum": 1996856142, "bids": [], "asks": [[1.59195, 0.0], [1.623, 8078.0]], "action": "update"}}
1618677883.6448488: {"channel": "orderbook", "market": "AKRO/USD", "type": "update", "data": {"time": 1618677883.5629995, "checksum": 2733880379, "bids": [[0.06816, 0.0], [0.059365, 38.0]], "asks": [], "action": "update"}}
1618677883.655787: {"channel": "orderbook", "market": "XRP/USD", "type": "update", "data": {"time": 1618677883.5751967, "checksum": 3049063894, "bids": [], "asks": [[1.5924, 1100.0], [1.592575, 0.0], [1.592875, 633.0], [1.623, 0.0]], "action": "update"}}
1618677883.67572: {"channel": "orderbook", "market": "XRP/USD", "type": "update", "data": {"time": 1618677883.5992937, "checksum": 3812317180, "bids": [], "asks": [[1.5924, 0.0], [1.623, 8078.0]], "action": "update"}}
1618677883.694205: {"channel": "orderbook", "market": "ZECBULL/USD", "type": "update", "data": {"time": 1618677883.620732, "checksum": 2405867030, "bids": [[7190.0, 1e-05], [7187.5, 0.0]], "asks": [], "action": "update"}}
1618677883.7231119: {"channel": "orderbook", "market": "BTC-MOVE-WK-0507", "type": "update", "data": {"time": 1618677883.6456401, "checksum": 901794806, "bids": [], "asks": [], "action": "update"}}
1618677883.7231731: {"channel": "orderbook", "market": "SXPBULL/USD", "type": "update", "data": {"time": 1618677883.628886, "checksum": 3849217839, "bids": [[51.1, 50.001]], "asks": [], "action": "update"}}
1618677883.7302258: {"channel": "orderbook", "market": "XRP/USD", "type": "update", "data": {"time": 1618677883.6545393, "checksum": 610153299, "bids": [[1.590025, 2514.0], [1.556625, 0.0]], "asks": [[1.5927, 1100.0], [1.623, 0.0]], "action": "update"}}
1618677883.750607: {"channel": "orderbook", "market": "XRP/USD", "type": "update", "data": {"time": 1618677883.677887, "checksum": 1884031349, "bids": [], "asks": [[1.598875, 0.0], [1.623, 8078.0]], "action": "update"}}
1618677883.8222132: {"channel": "orderbook", "market": "XRP/USD", "type": "update", "data": {"time": 1618677883.7489483, "checksum": 2312213196, "bids": [], "asks": [[1.598725, 0.0], [1.623175, 2.0]], "action": "update"}}
1618677883.8570292: {"channel": "orderbook", "market": "XRP/USD", "type": "update", "data": {"time": 1618677883.7742581, "checksum": 3897854106, "bids": [[1.588475, 0.0], [1.556625, 1.0]], "asks": [[1.594625, 0.0], [1.62335, 8051.0]], "action": "update"}}
1618677883.8668532: {"channel": "orderbook", "market": "SXPBULL/USD", "type": "update", "data": {"time": 1618677883.7852366, "checksum": 3431643675, "bids": [[50.975, 0.167]], "asks": [], "action": "update"}}
1618677883.897693: {"channel": "orderbook", "market": "XRP/USD", "type": "update", "data": {"time": 1618677883.8247037, "checksum": 1624189184, "bids": [], "asks": [[1.5931, 2512.0], [1.62335, 0.0]], "action": "update"}}
1618677883.916901: {"channel": "orderbook", "market": "SXPBULL/USD", "type": "update", "data": {"time": 1618677883.835189, "checksum": 2285917305, "bids": [[51.1, 0.441]], "asks": [], "action": "update"}}
1618677883.94052: {"channel": "orderbook", "market": "SXPBULL/USD", "type": "update", "data": {"time": 1618677883.859546, "checksum": 2738990412, "bids": [], "asks": [[52.225, 1.283]], "action": "update"}}
1618677883.940632: {"channel": "orderbook", "market": "NVDA-0625", "type": "update", "data": {"time": 1618677883.8669798, "checksum": 3644189371, "bids": [], "asks": [], "action": "update"}}
1618677884.0243819: {"channel": "orderbook", "market": "XRP/USD", "type": "update", "data": {"time": 1618677883.9004073, "checksum": 3249569911, "bids": [], "asks": [[1.59795, 157.0], [1.623175, 0.0]], "action": "update"}}
1618677884.024533: {"channel": "orderbook", "market": "ZECBULL/USD", "type": "update", "data": {"time": 1618677883.9224403, "checksum": 583721235, "bids": [], "asks": [[7295.0, 0.0]], "action": "update"}}
1618677884.024632: {"channel": "orderbook", "market": "XRP/USD", "type": "update", "data": {"time": 1618677883.9291065, "checksum": 3648281837, "bids": [], "asks": [[1.5931, 0.0], [1.623175, 2.0]], "action": "update"}}
1618677884.0247428: {"channel": "orderbook", "market": "SUSHIBEAR/USD", "type": "update", "data": {"time": 1618677883.9088464, "checksum": 3808203141, "bids": [[1.206e-05, 40000.0], [1.201e-05, 0.0]], "asks": [], "action": "update"}}
1618677884.0491679: {"channel": "orderbook", "market": "SUSHIBEAR/USD", "type": "update", "data": {"time": 1618677883.9701607, "checksum": 494643089, "bids": [[1.17e-05, 2100000.0]], "asks": [[1.235e-05, 0.0], [0.04, 1091000.0]], "action": "update"}}
1618677884.0492501: {"channel": "orderbook", "market": "SXPBULL/USD", "type": "update", "data": {"time": 1618677883.9656646, "checksum": 4257581251, "bids": [[51.675, 0.168], [51.1, 50.001]], "asks": [], "action": "update"}}
1618677884.063095: {"channel": "orderbook", "market": "XRP/USD", "type": "update", "data": {"time": 1618677883.9830852, "checksum": 1029440980, "bids": [], "asks": [[1.5978, 189.0], [1.623175, 0.0]], "action": "update"}}
1618677884.091816: {"channel": "orderbook", "market": "SXPBULL/USD", "type": "update", "data": {"time": 1618677883.9859304, "checksum": 3411621597, "bids": [], "asks": [[52.25, 34.632]], "action": "update"}}
1618677884.1100001: {"channel": "orderbook", "market": "SUSHIBEAR/USD", "type": "update", "data": {"time": 1618677884.007879, "checksum": 1834154298, "bids": [[1.165e-05, 17340000.0]], "asks": [], "action": "update"}}
1618677884.1100569: {"channel": "orderbook", "market": "SXPBULL/USD", "type": "update", "data": {"time": 1618677884.0238996, "checksum": 3260662789, "bids": [[51.1, 0.441], [51.0, 17.579]], "asks": [], "action": "update"}}
1618677884.114204: {"channel": "orderbook", "market": "AMD/USD", "type": "update", "data": {"time": 1618677884.0319765, "checksum": 1935389369, "bids": [], "asks": [], "action": "update"}}
1618677884.13787: {"channel": "orderbook", "market": "XRP/USD", "type": "update", "data": {"time": 1618677884.058622, "checksum": 3994372134, "bids": [], "asks": [[1.5929, 2512.0], [1.623, 0.0]], "action": "update"}}
1618677884.139452: {"channel": "orderbook", "market": "SUSHIBEAR/USD", "type": "update", "data": {"time": 1618677884.0626292, "checksum": 3988427185, "bids": [], "asks": [[1.255e-05, 25010000.0]], "action": "update"}}
1618677884.156662: {"channel": "orderbook", "market": "AKRO/USD", "type": "update", "data": {"time": 1618677884.0794683, "checksum": 920247687, "bids": [[0.068135, 38276.0]], "asks": [], "action": "update"}}
1618677884.1721878: {"channel": "orderbook", "market": "ZECBULL/USD", "type": "update", "data": {"time": 1618677884.0984678, "checksum": 583721235, "bids": [], "asks": [], "action": "update"}}
1618677884.172235: {"channel": "orderbook", "market": "SXPBULL/USD", "type": "update", "data": {"time": 1618677884.0930135, "checksum": 4274039001, "bids": [[51.05, 59.738]], "asks": [], "action": "update"}}
1618677884.1830242: {"channel": "orderbook", "market": "XRP/USD", "type": "update", "data": {"time": 1618677884.105547, "checksum": 698039059, "bids": [], "asks": [[1.594225, 8183.0], [1.59485, 308914.0], [1.6225, 0.0]], "action": "update"}}
1618677884.271571: {"channel": "orderbook", "market": "XRP/USD", "type": "update", "data": {"time": 1618677884.178078, "checksum": 2206139103, "bids": [[1.582, 0.0], [1.5561, 4.0]], "asks": [], "action": "update"}}
1618677884.27165: {"channel": "orderbook", "market": "PAXG/USD", "type": "update", "data": {"time": 1618677884.1853852, "checksum": 2811656200, "bids": [], "asks": [], "action": "update"}}
1618677884.3038201: {"channel": "orderbook", "market": "XRP/USD", "type": "update", "data": {"time": 1618677884.2295816, "checksum": 3061248381, "bids": [], "asks": [[1.59875, 0.0], [1.5995, 1529.0]], "action": "update"}}
1618677884.3289468: {"channel": "orderbook", "market": "AKRO/USD", "type": "update", "data": {"time": 1618677884.2527142, "checksum": 920247687, "bids": [], "asks": [], "action": "update"}}
1618677884.356003: {"channel": "orderbook", "market": "SXPBULL/USD", "type": "update", "data": {"time": 1618677884.2754653, "checksum": 2949257228, "bids": [], "asks": [[52.4, 3.229]], "action": "update"}}
1618677884.38615: {"channel": "orderbook", "market": "SXPBULL/USD", "type": "update", "data": {"time": 1618677884.2971036, "checksum": 415283044, "bids": [[51.15, 2.485]], "asks": [], "action": "update"}}
1618677884.386206: {"channel": "orderbook", "market": "XRP/USD", "type": "update", "data": {"time": 1618677884.3034887, "checksum": 2545642911, "bids": [], "asks": [[1.593025, 5.0], [1.6215, 0.0]], "action": "update"}}
1618677884.396949: {"channel": "orderbook", "market": "ZECBULL/USD", "type": "update", "data": {"time": 1618677884.3205352, "checksum": 2913238206, "bids": [], "asks": [[7307.5, 0.0]], "action": "update"}}
1618677884.4306712: {"channel": "orderbook", "market": "XRP/USD", "type": "update", "data": {"time": 1618677884.353055, "checksum": 3660817130, "bids": [[1.587, 1715.0], [1.5561, 0.0]], "asks": [[1.5945, 0.0], [1.6215, 6.0]], "action": "update"}}
1618677884.43077: {"channel": "orderbook", "market": "THETAHEDGE/USD", "type": "update", "data": {"time": 1618677884.354697, "checksum": 3313924624, "bids": [], "asks": [], "action": "update"}}
1618677884.456374: {"channel": "orderbook", "market": "SXPBULL/USD", "type": "update", "data": {"time": 1618677884.3644054, "checksum": 2539670753, "bids": [[51.05, 0.482]], "asks": [], "action": "update"}}
1618677884.529035: {"channel": "orderbook", "market": "SXPBULL/USD", "type": "update", "data": {"time": 1618677884.3963172, "checksum": 2539670753, "bids": [], "asks": [], "action": "update"}}
1618677884.529081: {"channel": "orderbook", "market": "SXPBULL/USD", "type": "update", "data": {"time": 1618677884.4201207, "checksum": 4029261928, "bids": [], "asks": [[52.175, 43.509]], "action": "update"}}
1618677884.544209: {"channel": "orderbook", "market": "XRP/USD", "type": "update", "data": {"time": 1618677884.4589298, "checksum": 4151082235, "bids": [], "asks": [[1.598525, 188.0], [1.6215, 0.0]], "action": "update"}}
1618677884.568566: {"channel": "orderbook", "market": "SXPBULL/USD", "type": "update", "data": {"time": 1618677884.471787, "checksum": 3585189949, "bids": [], "asks": [[52.5, 0.931]], "action": "update"}}
1618677884.627519: {"channel": "orderbook", "market": "SUSHIBEAR/USD", "type": "update", "data": {"time": 1618677884.547378, "checksum": 2423580420, "bids": [[1.165e-05, 8660000.0]], "asks": [], "action": "update"}}
1618677884.706506: {"channel": "orderbook", "market": "XRP/USD", "type": "update", "data": {"time": 1618677884.6278381, "checksum": 4151082235, "bids": [], "asks": [], "action": "update"}}
1618677884.7105029: {"channel": "orderbook", "market": "SXPBULL/USD", "type": "update", "data": {"time": 1618677884.620571, "checksum": 4131875668, "bids": [[51.05, 246.369]], "asks": [], "action": "update"}}
1618677884.722548: {"channel": "orderbook", "market": "SUSHIBEAR/USD", "type": "update", "data": {"time": 1618677884.6456366, "checksum": 631320025, "bids": [[1.17e-05, 10780000.0]], "asks": [], "action": "update"}}
1618677884.7256792: {"channel": "orderbook", "market": "ZECBULL/USD", "type": "update", "data": {"time": 1618677884.6487606, "checksum": 2369127379, "bids": [], "asks": [[7305.0, 0.42677]], "action": "update"}}
1618677884.748134: {"channel": "orderbook", "market": "BTC-MOVE-WK-0507", "type": "update", "data": {"time": 1618677884.6711662, "checksum": 901794806, "bids": [], "asks": [], "action": "update"}}
1618677884.764724: {"channel": "orderbook", "market": "XRP/USD", "type": "update", "data": {"time": 1618677884.687802, "checksum": 3854257233, "bids": [], "asks": [[1.593025, 0.0], [1.5957, 1685.0]], "action": "update"}}
1618677884.7781901: {"channel": "orderbook", "market": "SXPBULL/USD", "type": "update", "data": {"time": 1618677884.6948826, "checksum": 3585189949, "bids": [[51.05, 0.482]], "asks": [], "action": "update"}}
1618677884.8037791: {"channel": "orderbook", "market": "ZECBULL/USD", "type": "update", "data": {"time": 1618677884.7263508, "checksum": 634882380, "bids": [], "asks": [[7870.0, 6.09446], [9477.5, 31.62353]], "action": "update"}}
1618677884.809061: {"channel": "orderbook", "market": "XRP/USD", "type": "update", "data": {"time": 1618677884.7319527, "checksum": 3971758706, "bids": [[1.590025, 0.0], [1.5561, 4.0]], "asks": [[1.5929, 0.0], [1.6215, 6.0]], "action": "update"}}
1618677884.809155: {"channel": "orderbook", "market": "SXPBULL/USD", "type": "update", "data": {"time": 1618677884.725948, "checksum": 3615615447, "bids": [[51.525, 0.0], [51.45, 31.0], [51.0, 17.628]], "asks": [], "action": "update"}}
1618677884.827899: {"channel": "orderbook", "market": "ZECBULL/USD", "type": "update", "data": {"time": 1618677884.7486928, "checksum": 3938980104, "bids": [], "asks": [[7662.5, 2.16186]], "action": "update"}}
1618677884.8930671: {"channel": "orderbook", "market": "SUSHIBEAR/USD", "type": "update", "data": {"time": 1618677884.7774365, "checksum": 3120722056, "bids": [[1.175e-05, 0.0]], "asks": [], "action": "update"}}
1618677884.893306: {"channel": "orderbook", "market": "XRP/USD", "type": "update", "data": {"time": 1618677884.7818925, "checksum": 3640988198, "bids": [[1.5911, 0.0], [1.590075, 0.0], [1.589625, 0.0], [1.55565, 2.0], [1.5554, 1.0], [1.5553, 6.0]], "asks": [[1.593275, 5280.0]], "action": "update"}}
1618677884.893431: {"channel": "orderbook", "market": "SXPBULL/USD", "type": "update", "data": {"time": 1618677884.7871294, "checksum": 66354209, "bids": [[51.05, 115.302]], "asks": [], "action": "update"}}
1618677884.893483: {"channel": "orderbook", "market": "SUSHIBEAR/USD", "type": "update", "data": {"time": 1618677884.8132126, "checksum": 3798027848, "bids": [[1.18e-05, 16990000.0]], "asks": [], "action": "update"}}
1618677884.896033: {"channel": "orderbook", "market": "XRP/USD", "type": "update", "data": {"time": 1618677884.8148665, "checksum": 3118838097, "bids": [[1.589625, 633.0], [1.5553, 0.0]], "asks": [], "action": "update"}}
1618677884.937824: {"channel": "orderbook", "market": "XRP/USD", "type": "update", "data": {"time": 1618677884.8636284, "checksum": 3935963678, "bids": [[1.58925, 0.0], [1.589, 0.0], [1.5553, 6.0], [1.55525, 1.0]], "asks": [], "action": "update"}}
1618677884.977531: {"channel": "orderbook", "market": "SXPBULL/USD", "type": "update", "data": {"time": 1618677884.8903315, "checksum": 3615615447, "bids": [[51.05, 0.482]], "asks": [], "action": "update"}}
1618677884.9776142: {"channel": "orderbook", "market": "NVDA-0625", "type": "update", "data": {"time": 1618677884.9011152, "checksum": 3644189371, "bids": [], "asks": [], "action": "update"}}
1618677885.016908: {"channel": "orderbook", "market": "XRP/USD", "type": "update", "data": {"time": 1618677884.9053779, "checksum": 3884488836, "bids": [[1.59105, 0.0], [1.589725, 2515.0]], "asks": [[1.5925, 2513.0], [1.592675, 633.0], [1.592825, 1383.0], [1.592875, 0.0], [1.620975, 0.0], [1.6215, 0.0]], "action": "update"}}
1618677885.030518: {"channel": "orderbook", "market": "SXPBULL/USD", "type": "update", "data": {"time": 1618677884.9420035, "checksum": 2948134260, "bids": [[51.0, 11.81]], "asks": [], "action": "update"}}
1618677885.035868: {"channel": "orderbook", "market": "SUSHIBEAR/USD", "type": "update", "data": {"time": 1618677884.9579914, "checksum": 3798027848, "bids": [], "asks": [], "action": "update"}}
1618677885.054035: {"channel": "orderbook", "market": "XRP/USD", "type": "update", "data": {"time": 1618677884.9779208, "checksum": 2984193773, "bids": [[1.589625, 0.0], [1.5542, 1412.0]], "asks": [[1.5927, 0.0], [1.59495, 0.0], [1.620975, 3.0], [1.6215, 6.0]], "action": "update"}}
1618677885.0913448: {"channel": "orderbook", "market": "XRP/USD", "type": "update", "data": {"time": 1618677885.0025132, "checksum": 3521137900, "bids": [[1.589225, 633.0], [1.5542, 0.0]], "asks": [[1.592675, 0.0], [1.59455, 0.0], [1.6225, 1413.0], [1.623, 8078.0]], "action": "update"}}
1618677885.0976691: {"channel": "orderbook", "market": "SXPBULL/USD", "type": "update", "data": {"time": 1618677884.9934278, "checksum": 772666250, "bids": [[51.05, 11.96]], "asks": [], "action": "update"}}
1618677885.123756: {"channel": "orderbook", "market": "XRP/USD", "type": "update", "data": {"time": 1618677885.0476518, "checksum": 1287044060, "bids": [[1.587, 0.0], [1.5542, 1412.0]], "asks": [[1.592325, 1100.0], [1.623, 0.0]], "action": "update"}}
1618677885.12384: {"channel": "orderbook", "market": "AMD/USD", "type": "update", "data": {"time": 1618677885.0491977, "checksum": 1935389369, "bids": [], "asks": [], "action": "update"}}
1618677885.13554: {"channel": "orderbook", "market": "SXPBULL/USD", "type": "update", "data": {"time": 1618677885.0452242, "checksum": 4248124979, "bids": [[50.525, 4.163]], "asks": [], "action": "update"}}
1618677885.1651819: {"channel": "orderbook", "market": "XRP/USD", "type": "update", "data": {"time": 1618677885.0776665, "checksum": 2353265811, "bids": [], "asks": [[1.5927, 5.0], [1.594, 6539.0], [1.599, 0.0], [1.599975, 0.0], [1.623, 8078.0]], "action": "update"}}
1618677885.16539: {"channel": "orderbook", "market": "SXPBULL/USD", "type": "update", "data": {"time": 1618677885.0788124, "checksum": 920243196, "bids": [[51.05, 0.482]], "asks": [], "action": "update"}}
1618677885.207936: {"channel": "orderbook", "market": "XRP/USD", "type": "update", "data": {"time": 1618677885.1273878, "checksum": 2817272930, "bids": [], "asks": [[1.5925, 0.0], [1.592825, 0.0], [1.623175, 2.0], [1.62335, 8051.0]], "action": "update"}}
1618677885.2080472: {"channel": "orderbook", "market": "ZECBULL/USD", "type": "update", "data": {"time": 1618677885.129716, "checksum": 3938980104, "bids": [], "asks": [], "action": "update"}}
1618677885.2456782: {"channel": "orderbook", "market": "XRP/USD", "type": "update", "data": {"time": 1618677885.1701725, "checksum": 2071588527, "bids": [], "asks": [[1.5923, 633.0], [1.598, 165819.0], [1.62335, 0.0]], "action": "update"}}
1618677885.2836008: {"channel": "orderbook", "market": "SXPBULL/USD", "type": "update", "data": {"time": 1618677885.157388, "checksum": 3118432167, "bids": [[51.05, 1.63]], "asks": [], "action": "update"}}
1618677885.305069: {"channel": "orderbook", "market": "XRP/USD", "type": "update", "data": {"time": 1618677885.2257595, "checksum": 1589731826, "bids": [[1.582, 1440.0], [1.5542, 0.0]], "asks": [[1.592325, 0.0], [1.5927, 2518.0], [1.59465, 245230.0], [1.5995, 0.0], [1.62335, 8051.0]], "action": "update"}}
1618677885.3146582: {"channel": "orderbook", "market": "PAXG/USD", "type": "update", "data": {"time": 1618677885.233054, "checksum": 2811656200, "bids": [], "asks": [], "action": "update"}}
1618677885.3446531: {"channel": "orderbook", "market": "XRP/USD", "type": "update", "data": {"time": 1618677885.2680318, "checksum": 4017757038, "bids": [], "asks": [[1.592125, 1100.0], [1.598525, 0.0]], "action": "update"}}
1618677885.3632588: {"channel": "orderbook", "market": "AKRO/USD", "type": "update", "data": {"time": 1618677885.2768703, "checksum": 920247687, "bids": [], "asks": [], "action": "update"}}
1618677885.368613: {"channel": "orderbook", "market": "XRP/USD", "type": "update", "data": {"time": 1618677885.292719, "checksum": 858855084, "bids": [], "asks": [[1.5945, 1515.0], [1.62335, 0.0]], "action": "update"}}
1618677885.4165099: {"channel": "orderbook", "market": "SXPBULL/USD", "type": "update", "data": {"time": 1618677885.3295875, "checksum": 375962925, "bids": [], "asks": [[52.225, 1.43]], "action": "update"}}
1618677885.440823: {"channel": "orderbook", "market": "ZECBULL/USD", "type": "update", "data": {"time": 1618677885.3658261, "checksum": 580636503, "bids": [], "asks": [[7547.5, 0.0], [8012.5, 0.0]], "action": "update"}}
1618677885.441555: {"channel": "orderbook", "market": "SXPBULL/USD", "type": "update", "data": {"time": 1618677885.358428, "checksum": 3012317441, "bids": [[51.575, 26.4], [48.975, 0.0]], "asks": [], "action": "update"}}
1618677885.450351: {"channel": "orderbook", "market": "XRP/USD", "type": "update", "data": {"time": 1618677885.37275, "checksum": 3096029063, "bids": [], "asks": [[1.5923, 0.0], [1.60015, 20.0]], "action": "update"}}
1618677885.454606: {"channel": "orderbook", "market": "THETAHEDGE/USD", "type": "update", "data": {"time": 1618677885.37675, "checksum": 3313924624, "bids": [], "asks": [], "action": "update"}}
1618677885.49516: {"channel": "orderbook", "market": "SXPBULL/USD", "type": "update", "data": {"time": 1618677885.386484, "checksum": 185781616, "bids": [[51.05, 0.482]], "asks": [], "action": "update"}}
1618677885.4952698: {"channel": "orderbook", "market": "XRP/USD", "type": "update", "data": {"time": 1618677885.4180312, "checksum": 1329021453, "bids": [[1.568575, 0.0], [1.5542, 1412.0]], "asks": [[1.592125, 0.0], [1.592525, 633.0]], "action": "update"}}
1618677885.496908: {"channel": "orderbook", "market": "SUSHIBEAR/USD", "type": "update", "data": {"time": 1618677885.4222589, "checksum": 3804698419, "bids": [], "asks": [[1.255e-05, 16690000.0]], "action": "update"}}
1618677885.512706: {"channel": "orderbook", "market": "SXPBULL/USD", "type": "update", "data": {"time": 1618677885.407183, "checksum": 2662755138, "bids": [[50.35, 321.447]], "asks": [], "action": "update"}}
1618677885.533192: {"channel": "orderbook", "market": "XRP/USD", "type": "update", "data": {"time": 1618677885.4522007, "checksum": 3462730825, "bids": [[1.589725, 0.0], [1.5538, 1.0]], "asks": [[1.592525, 1733.0]], "action": "update"}}
1618677885.551126: {"channel": "orderbook", "market": "XRP/USD", "type": "update", "data": {"time": 1618677885.4743946, "checksum": 188928258, "bids": [], "asks": [[1.592525, 633.0], [1.5927, 0.0], [1.62335, 8051.0]], "action": "update"}}
1618677885.572101: {"channel": "orderbook", "market": "XRP/USD", "type": "update", "data": {"time": 1618677885.4959626, "checksum": 2672761898, "bids": [[1.589875, 5120.0], [1.5538, 0.0]], "asks": [[1.597625, 188.0], [1.62335, 0.0]], "action": "update"}}
1618677885.5806909: {"channel": "orderbook", "market": "SUSHIBEAR/USD", "type": "update", "data": {"time": 1618677885.4979131, "checksum": 497311280, "bids": [[1.18e-05, 8530000.0]], "asks": [[1.235e-05, 8320000.0], [0.04, 0.0]], "action": "update"}}
1618677885.6131892: {"channel": "orderbook", "market": "SXPBULL/USD", "type": "update", "data": {"time": 1618677885.5278084, "checksum": 1473863565, "bids": [[51.05, 241.877]], "asks": [], "action": "update"}}
1618677885.6218948: {"channel": "orderbook", "market": "XRP/USD", "type": "update", "data": {"time": 1618677885.5473394, "checksum": 3915301843, "bids": [[1.589875, 0.0], [1.5538, 1.0]], "asks": [[1.59235, 1100.0], [1.623175, 0.0]], "action": "update"}}
1618677885.6570911: {"channel": "orderbook", "market": "SUSHIBEAR/USD", "type": "update", "data": {"time": 1618677885.5791018, "checksum": 3808203141, "bids": [[1.175e-05, 8460000.0]], "asks": [], "action": "update"}}
1618677885.7029288: {"channel": "orderbook", "market": "XRP/USD", "type": "update", "data": {"time": 1618677885.620847, "checksum": 2972207158, "bids": [], "asks": [[1.59485, 0.0], [1.623175, 2.0]], "action": "update"}}
1618677885.741375: {"channel": "orderbook", "market": "XRP/USD", "type": "update", "data": {"time": 1618677885.657632, "checksum": 2803300775, "bids": [[1.590125, 2514.0], [1.5538, 0.0]], "asks": [[1.592525, 0.0], [1.5929, 2512.0]], "action": "update"}}
1618677885.772031: {"channel": "orderbook", "market": "BTC-MOVE-WK-0507", "type": "update", "data": {"time": 1618677885.694383, "checksum": 901794806, "bids": [], "asks": [], "action": "update"}}
1618677885.780792: {"channel": "orderbook", "market": "XRP/USD", "type": "update", "data": {"time": 1618677885.7052314, "checksum": 1738832296, "bids": [], "asks": [[1.59235, 0.0], [1.592825, 633.0]], "action": "update"}}
1618677885.796863: {"channel": "orderbook", "market": "XRP/USD", "type": "update", "data": {"time": 1618677885.723122, "checksum": 1382952649, "bids": [], "asks": [[1.59995, 0.0], [1.62335, 8051.0]], "action": "update"}}
1618677885.838482: {"channel": "orderbook", "market": "XRP/USD", "type": "update", "data": {"time": 1618677885.757987, "checksum": 2800381225, "bids": [], "asks": [[1.592725, 1100.0], [1.62335, 0.0]], "action": "update"}}
1618677885.8561668: {"channel": "orderbook", "market": "ZECBULL/USD", "type": "update", "data": {"time": 1618677885.7812276, "checksum": 3880538193, "bids": [], "asks": [[7307.5, 0.3939]], "action": "update"}}
1618677885.865095: {"channel": "orderbook", "market": "XRP/USD", "type": "update", "data": {"time": 1618677885.7874799, "checksum": 3662665251, "bids": [[1.5898, 3675.0], [1.571425, 292.0], [1.5542, 0.0]], "asks": [], "action": "update"}}
1618677885.914357: {"channel": "orderbook", "market": "XRP/USD", "type": "update", "data": {"time": 1618677885.8349462, "checksum": 584185216, "bids": [], "asks": [[1.592825, 0.0], [1.5978, 0.0], [1.62335, 8051.0], [1.6235, 4.0]], "action": "update"}}
1618677885.93088: {"channel": "orderbook", "market": "XRP/USD", "type": "update", "data": {"time": 1618677885.8513043, "checksum": 3661038905, "bids": [], "asks": [[1.5927, 633.0], [1.59795, 0.0]], "action": "update"}}
1618677885.9700422: {"channel": "orderbook", "market": "XRP/USD", "type": "update", "data": {"time": 1618677885.8840952, "checksum": 893824006, "bids": [], "asks": [[1.592325, 5.0], [1.592725, 0.0]], "action": "update"}}
1618677885.970207: {"channel": "orderbook", "market": "SXPBULL/USD", "type": "update", "data": {"time": 1618677885.8815808, "checksum": 2662755138, "bids": [[51.05, 0.482]], "asks": [], "action": "update"}}
1618677885.9832268: {"channel": "orderbook", "market": "XRP/USD", "type": "update", "data": {"time": 1618677885.904398, "checksum": 3980783044, "bids": [[1.590125, 0.0], [1.589, 1362.0]], "asks": [[1.5929, 0.0], [1.6239, 1.0]], "action": "update"}}
1618677886.035071: {"channel": "orderbook", "market": "NVDA-0625", "type": "update", "data": {"time": 1618677885.947683, "checksum": 3644189371, "bids": [], "asks": [], "action": "update"}}
1618677886.035163: {"channel": "orderbook", "market": "XRP/USD", "type": "update", "data": {"time": 1618677885.95071, "checksum": 1929810004, "bids": [[1.588275, 1409.0], [1.55525, 0.0]], "asks": [[1.5927, 0.0], [1.62425, 4.0]], "action": "update"}}
1618677886.07249: {"channel": "orderbook", "market": "XRP/USD", "type": "update", "data": {"time": 1618677885.9914474, "checksum": 3629327958, "bids": [], "asks": [[1.59215, 1100.0], [1.5923, 633.0], [1.609125, 249020.0], [1.6235, 0.0], [1.6239, 0.0], [1.62425, 0.0]], "action": "update"}}
1618677886.0831401: {"channel": "orderbook", "market": "SXPBULL/USD", "type": "update", "data": {"time": 1618677885.9911265, "checksum": 2547570116, "bids": [[51.575, 0.0], [48.975, 5.546]], "asks": [[52.1, 34.738]], "action": "update"}}
1618677886.083312: {"channel": "orderbook", "market": "SUSHIBEAR/USD", "type": "update", "data": {"time": 1618677885.9957736, "checksum": 3808203141, "bids": [], "asks": [], "action": "update"}}
1618677886.1425438: {"channel": "orderbook", "market": "XRP/USD", "type": "update", "data": {"time": 1618677886.0567234, "checksum": 3609354874, "bids": [], "asks": [[1.5929, 1389.0], [1.598175, 189.0], [1.623175, 0.0], [1.62335, 0.0]], "action": "update"}}
1618677886.142756: {"channel": "orderbook", "market": "SXPBULL/USD", "type": "update", "data": {"time": 1618677886.0468075, "checksum": 4150345195, "bids": [[51.05, 171.729], [50.7, 34.957]], "asks": [], "action": "update"}}
1618677886.156072: {"channel": "orderbook", "market": "AMD/USD", "type": "update", "data": {"time": 1618677886.0810199, "checksum": 1935389369, "bids": [], "asks": [], "action": "update"}}
1618677886.198794: {"channel": "orderbook", "market": "XRP/USD", "type": "update", "data": {"time": 1618677886.1174595, "checksum": 3312878454, "bids": [[1.5914, 2.0], [1.5553, 0.0]], "asks": [], "action": "update"}}
1618677886.231211: {"channel": "orderbook", "market": "ZECBULL/USD", "type": "update", "data": {"time": 1618677886.1553054, "checksum": 3880538193, "bids": [], "asks": [], "action": "update"}}
1618677886.317465: {"channel": "orderbook", "market": "XRP/USD", "type": "update", "data": {"time": 1618677886.2148356, "checksum": 287430325, "bids": [[1.5914, 0.0], [1.5865, 0.0], [1.5553, 6.0], [1.55525, 1.0]], "asks": [], "action": "update"}}
1618677886.322732: {"channel": "orderbook", "market": "SXPBULL/USD", "type": "update", "data": {"time": 1618677886.2316003, "checksum": 2787653998, "bids": [], "asks": [[52.4, 3.822]], "action": "update"}}
1618677886.3469892: {"channel": "orderbook", "market": "SUSHIBEAR/USD", "type": "update", "data": {"time": 1618677886.2717357, "checksum": 2773042514, "bids": [], "asks": [[1.235e-05, 0.0], [0.04, 1091000.0]], "action": "update"}}
1618677886.360254: {"channel": "orderbook", "market": "XRP/USD", "type": "update", "data": {"time": 1618677886.2782218, "checksum": 3205589797, "bids": [], "asks": [[1.592325, 0.0], [1.623175, 2.0]], "action": "update"}}
1618677886.360415: {"channel": "orderbook", "market": "PAXG/USD", "type": "update", "data": {"time": 1618677886.2772875, "checksum": 2811656200, "bids": [], "asks": [], "action": "update"}}
1618677886.382366: {"channel": "orderbook", "market": "XRP/USD", "type": "update", "data": {"time": 1618677886.3050082, "checksum": 571755110, "bids": [], "asks": [[1.592125, 633.0], [1.5923, 0.0]], "action": "update"}}
1618677886.382528: {"channel": "orderbook", "market": "AKRO/USD", "type": "update", "data": {"time": 1618677886.3036258, "checksum": 920247687, "bids": [], "asks": [], "action": "update"}}
1618677886.404495: {"channel": "orderbook", "market": "XRP/USD", "type": "update", "data": {"time": 1618677886.3290715, "checksum": 1840512286, "bids": [], "asks": [[1.59215, 5560.0], [1.597625, 0.0], [1.62335, 8051.0]], "action": "update"}}
1618677886.421731: {"channel": "orderbook", "market": "SUSHIBEAR/USD", "type": "update", "data": {"time": 1618677886.346789, "checksum": 631320025, "bids": [], "asks": [[1.255e-05, 25010000.0]], "action": "update"}}
1618677886.465736: {"channel": "orderbook", "market": "THETAHEDGE/USD", "type": "update", "data": {"time": 1618677886.3931394, "checksum": 3313924624, "bids": [], "asks": [], "action": "update"}}
1618677886.468228: {"channel": "orderbook", "market": "SXPBULL/USD", "type": "update", "data": {"time": 1618677886.3842514, "checksum": 3928797329, "bids": [[51.05, 0.482]], "asks": [], "action": "update"}}
1618677886.4872131: {"channel": "orderbook", "market": "XRP/USD", "type": "update", "data": {"time": 1618677886.4062479, "checksum": 232751071, "bids": [[1.589025, 3619.0], [1.55525, 0.0]], "asks": [[1.59195, 1100.0], [1.61085, 0.0]], "action": "update"}}
1618677886.5324109: {"channel": "orderbook", "market": "XRP/USD", "type": "update", "data": {"time": 1618677886.4568737, "checksum": 3398154524, "bids": [], "asks": [[1.59215, 4460.0], [1.5926, 2513.0], [1.62335, 0.0]], "action": "update"}}
1618677886.532594: {"channel": "orderbook", "market": "SXPBULL/USD", "type": "update", "data": {"time": 1618677886.434458, "checksum": 3928797329, "bids": [], "asks": [], "action": "update"}}
1618677886.557257: {"channel": "orderbook", "market": "XRP/USD", "type": "update", "data": {"time": 1618677886.4791903, "checksum": 2453937748, "bids": [[1.589725, 2515.0], [1.5553, 0.0]], "asks": [], "action": "update"}}
1618677886.6151118: {"channel": "orderbook", "market": "SXPBULL/USD", "type": "update", "data": {"time": 1618677886.4948843, "checksum": 3481781524, "bids": [[51.075, 2.676]], "asks": [], "action": "update"}}
1618677886.6307461: {"channel": "orderbook", "market": "XRP/USD", "type": "update", "data": {"time": 1618677886.5547671, "checksum": 8065761, "bids": [], "asks": [[1.59815, 188.0], [1.623175, 0.0]], "action": "update"}}
1618677886.697483: {"channel": "orderbook", "market": "SUSHIBEAR/USD", "type": "update", "data": {"time": 1618677886.621907, "checksum": 625095421, "bids": [[1.207e-05, 10000.0]], "asks": [], "action": "update"}}
1618677886.71347: {"channel": "orderbook", "market": "XRP/USD", "type": "update", "data": {"time": 1618677886.6295285, "checksum": 2065376986, "bids": [[1.58875, 0.0], [1.5882, 279974.0]], "asks": [], "action": "update"}}
1618677886.752884: {"channel": "orderbook", "market": "SXPBULL/USD", "type": "update", "data": {"time": 1618677886.6701033, "checksum": 4231141008, "bids": [[51.05, 214.289]], "asks": [[52.45, 5.326]], "action": "update"}}
1618677886.7593129: {"channel": "orderbook", "market": "XRP/USD", "type": "update", "data": {"time": 1618677886.6808593, "checksum": 2065376986, "bids": [], "asks": [], "action": "update"}}
1618677886.793932: {"channel": "orderbook", "market": "BTC-MOVE-WK-0507", "type": "update", "data": {"time": 1618677886.7191877, "checksum": 901794806, "bids": [], "asks": [], "action": "update"}}
1618677886.838093: {"channel": "orderbook", "market": "XRP/USD", "type": "update", "data": {"time": 1618677886.7568364, "checksum": 4160999179, "bids": [[1.5815, 1529.0], [1.5554, 0.0]], "asks": [], "action": "update"}}
1618677886.956379: {"channel": "orderbook", "market": "ZECBULL/USD", "type": "update", "data": {"time": 1618677886.8798656, "checksum": 3442597104, "bids": [], "asks": [[7305.0, 0.0]], "action": "update"}}
1618677886.989614: {"channel": "orderbook", "market": "XRP/USD", "type": "update", "data": {"time": 1618677886.9114988, "checksum": 1150166677, "bids": [], "asks": [[1.5929, 0.0], [1.594275, 310713.0]], "action": "update"}}
1618677887.006114: {"channel": "orderbook", "market": "XRP/USD", "type": "update", "data": {"time": 1618677886.9304814, "checksum": 3913650908, "bids": [[1.5898, 0.0], [1.589725, 0.0], [1.5554, 1.0], [1.5553, 6.0]], "asks": [], "action": "update"}}
1618677887.03525: {"channel": "orderbook", "market": "SXPBULL/USD", "type": "update", "data": {"time": 1618677886.9447973, "checksum": 2246382652, "bids": [[51.05, 0.482]], "asks": [], "action": "update"}}
1618677887.03999: {"channel": "orderbook", "market": "XRP/USD", "type": "update", "data": {"time": 1618677886.9631424, "checksum": 275483259, "bids": [], "asks": [[1.592125, 0.0], [1.5926, 0.0], [1.5927, 5.0], [1.623175, 2.0]], "action": "update"}}
1618677887.054788: {"channel": "orderbook", "market": "NVDA-0625", "type": "update", "data": {"time": 1618677886.9811416, "checksum": 3644189371, "bids": [], "asks": [], "action": "update"}}
1618677887.1029198: {"channel": "orderbook", "market": "SXPBULL/USD", "type": "update", "data": {"time": 1618677887.0219276, "checksum": 3088529450, "bids": [], "asks": [[52.1, 0.338]], "action": "update"}}
1618677887.111722: {"channel": "orderbook", "market": "XRP/USD", "type": "update", "data": {"time": 1618677887.0299633, "checksum": 1381406699, "bids": [[1.589325, 1384.0], [1.5553, 0.0]], "asks": [[1.59215, 0.0], [1.592425, 633.0], [1.593275, 1400.0]], "action": "update"}}
1618677887.111826: {"channel": "orderbook", "market": "SUSHIBEAR/USD", "type": "update", "data": {"time": 1618677887.0284371, "checksum": 625095421, "bids": [], "asks": [], "action": "update"}}
1618677887.140816: {"channel": "orderbook", "market": "SXPBULL/USD", "type": "update", "data": {"time": 1618677887.0466166, "checksum": 3696392033, "bids": [[51.05, 43.452]], "asks": [], "action": "update"}}
1618677887.14582: {"channel": "orderbook", "market": "XRP/USD", "type": "update", "data": {"time": 1618677887.070248, "checksum": 434347617, "bids": [[1.589225, 0.0], [1.588525, 3675.0]], "asks": [[1.59195, 0.0], [1.593275, 0.0], [1.62335, 8051.0], [1.6235, 4.0]], "action": "update"}}
1618677887.172787: {"channel": "orderbook", "market": "AMD/USD", "type": "update", "data": {"time": 1618677887.0990007, "checksum": 1935389369, "bids": [], "asks": [], "action": "update"}}
1618677887.196998: {"channel": "orderbook", "market": "XRP/USD", "type": "update", "data": {"time": 1618677887.1208522, "checksum": 940384433, "bids": [[1.589775, 633.0], [1.589725, 1352.0], [1.55565, 0.0], [1.5554, 0.0]], "asks": [[1.59225, 1100.0], [1.594425, 0.0]], "action": "update"}}
1618677887.256701: {"channel": "orderbook", "market": "XRP/USD", "type": "update", "data": {"time": 1618677887.1723676, "checksum": 4199477986, "bids": [[1.590775, 4952.0]], "asks": [[1.592425, 0.0], [1.595, 6893.0], [1.5985, 1308.0], [1.6239, 1.0]], "action": "update"}}
1618677887.2568262: {"channel": "orderbook", "market": "ZECBULL/USD", "type": "update", "data": {"time": 1618677887.1799722, "checksum": 3442597104, "bids": [], "asks": [], "action": "update"}}
1618677887.289979: {"channel": "orderbook", "market": "SUSHIBEAR/USD", "type": "update", "data": {"time": 1618677887.2036335, "checksum": 4260891389, "bids": [[1.165e-05, 0.0]], "asks": [], "action": "update"}}
1618677887.290118: {"channel": "orderbook", "market": "XRP/USD", "type": "update", "data": {"time": 1618677887.2137008, "checksum": 3865350620, "bids": [], "asks": [[1.59225, 0.0], [1.59285, 633.0], [1.5935, 1670.0], [1.6239, 0.0]], "action": "update"}}
1618677887.302737: {"channel": "orderbook", "market": "XRP/USD", "type": "update", "data": {"time": 1618677887.2264414, "checksum": 4165568716, "bids": [], "asks": [[1.595325, 5674.0]], "action": "update"}}
1618677887.349479: {"channel": "orderbook", "market": "XRP/USD", "type": "update", "data": {"time": 1618677887.2758431, "checksum": 2753353926, "bids": [[1.590825, 1100.0], [1.590125, 2514.0], [1.556625, 0.0], [1.5561, 0.0]], "asks": [[1.592525, 1100.0], [1.5932, 2512.0], [1.595, 3218.0], [1.62335, 0.0], [1.6235, 0.0]], "action": "update"}}
1618677887.3671339: {"channel": "orderbook", "market": "SXPBULL/USD", "type": "update", "data": {"time": 1618677887.275413, "checksum": 1210227402, "bids": [[51.625, 37.3], [48.975, 0.0]], "asks": [[52.175, 0.609]], "action": "update"}}
1618677887.399919: {"channel": "orderbook", "market": "PAXG/USD", "type": "update", "data": {"time": 1618677887.3227463, "checksum": 2811656200, "bids": [], "asks": [], "action": "update"}}
1618677887.4036229: {"channel": "orderbook", "market": "AKRO/USD", "type": "update", "data": {"time": 1618677887.326086, "checksum": 920247687, "bids": [], "asks": [], "action": "update"}}
1618677887.410412: {"channel": "orderbook", "market": "XRP/USD", "type": "update", "data": {"time": 1618677887.3321602, "checksum": 3631637394, "bids": [[1.571425, 0.0], [1.556625, 1.0]], "asks": [], "action": "update"}}
1618677887.429217: {"channel": "orderbook", "market": "SUSHIBEAR/USD", "type": "update", "data": {"time": 1618677887.3482993, "checksum": 3687097438, "bids": [[1.135e-05, 8660000.0]], "asks": [], "action": "update"}}
1618677887.454839: {"channel": "orderbook", "market": "XRP/USD", "type": "update", "data": {"time": 1618677887.3750393, "checksum": 31096796, "bids": [], "asks": [[1.5927, 0.0], [1.62335, 8051.0]], "action": "update"}}
1618677887.458234: {"channel": "orderbook", "market": "SXPBULL/USD", "type": "update", "data": {"time": 1618677887.3687372, "checksum": 1050600771, "bids": [[51.05, 0.482]], "asks": [], "action": "update"}}
1618677887.502293: {"channel": "orderbook", "market": "THETAHEDGE/USD", "type": "update", "data": {"time": 1618677887.4211383, "checksum": 3313924624, "bids": [], "asks": [], "action": "update"}}
1618677887.540524: {"channel": "orderbook", "market": "XRP/USD", "type": "update", "data": {"time": 1618677887.4572926, "checksum": 3272158000, "bids": [], "asks": [[1.59285, 0.0], [1.6235, 4.0]], "action": "update"}}
1618677887.542484: {"channel": "orderbook", "market": "SXPBULL/USD", "type": "update", "data": {"time": 1618677887.4409852, "checksum": 1050600771, "bids": [], "asks": [], "action": "update"}}
1618677887.584578: {"channel": "orderbook", "market": "XRP/USD", "type": "update", "data": {"time": 1618677887.500926, "checksum": 1983745005, "bids": [], "asks": [[1.592525, 0.0], [1.5932, 3145.0], [1.6239, 1.0]], "action": "update"}}
1618677887.5916731: {"channel": "orderbook", "market": "SXPBULL/USD", "type": "update", "data": {"time": 1618677887.4992187, "checksum": 950808588, "bids": [[51.05, 290.571]], "asks": [], "action": "update"}}
1618677887.634288: {"channel": "orderbook", "market": "SUSHIBEAR/USD", "type": "update", "data": {"time": 1618677887.554189, "checksum": 1358154069, "bids": [[1.18e-05, 0.0], [1.175e-05, 0.0]], "asks": [[1.255e-05, 16690000.0]], "action": "update"}}
1618677887.63446: {"channel": "orderbook", "market": "XRP/USD", "type": "update", "data": {"time": 1618677887.555797, "checksum": 1981086714, "bids": [[1.590125, 0.0], [1.589275, 9000.0]], "asks": [[1.593025, 1100.0], [1.5932, 633.0], [1.6239, 0.0]], "action": "update"}}
1618677887.690079: {"channel": "orderbook", "market": "SXPBULL/USD", "type": "update", "data": {"time": 1618677887.6051836, "checksum": 1050600771, "bids": [[51.05, 0.482]], "asks": [], "action": "update"}}
1618677887.709952: {"channel": "orderbook", "market": "XRP/USD", "type": "update", "data": {"time": 1618677887.627788, "checksum": 1367539903, "bids": [[1.589275, 0.0], [1.5561, 4.0]], "asks": [[1.598175, 0.0], [1.6239, 1.0]], "action": "update"}}
1618677887.7115352: {"channel": "orderbook", "market": "SXPBULL/USD", "type": "update", "data": {"time": 1618677887.62958, "checksum": 1303551411, "bids": [], "asks": [[52.525, 3.615]], "action": "update"}}
1618677887.729485: {"channel": "orderbook", "market": "SUSHIBEAR/USD", "type": "update", "data": {"time": 1618677887.65155, "checksum": 3243905266, "bids": [[1.19e-05, 34030000.0], [1.18e-05, 8460000.0]], "asks": [], "action": "update"}}
1618677887.753079: {"channel": "orderbook", "market": "SUSHIBEAR/USD", "type": "update", "data": {"time": 1618677887.6752386, "checksum": 1472358331, "bids": [], "asks": [[1.235e-05, 8320000.0], [0.04, 0.0]], "action": "update"}}
1618677887.753243: {"channel": "orderbook", "market": "XRP/USD", "type": "update", "data": {"time": 1618677887.6765156, "checksum": 2385107454, "bids": [[1.56775, 293.0], [1.5561, 0.0]], "asks": [[1.5932, 3145.0], [1.59465, 0.0], [1.62425, 4.0]], "action": "update"}}
1618677887.7860749: {"channel": "orderbook", "market": "XRP/USD", "type": "update", "data": {"time": 1618677887.7048047, "checksum": 84499383, "bids": [[1.590525, 2514.0], [1.556625, 0.0]], "asks": [[1.597875, 157.0], [1.62425, 0.0]], "action": "update"}}
1618677887.821265: {"channel": "orderbook", "market": "BTC-MOVE-WK-0507", "type": "update", "data": {"time": 1618677887.7464654, "checksum": 901794806, "bids": [], "asks": [], "action": "update"}}
1618677887.9164958: {"channel": "orderbook", "market": "SXPBULL/USD", "type": "update", "data": {"time": 1618677887.8046656, "checksum": 3317936465, "bids": [[51.05, 128.785]], "asks": [], "action": "update"}}
1618677888.007534: {"channel": "orderbook", "market": "SXPBULL/USD", "type": "update", "data": {"time": 1618677887.9116406, "checksum": 1303551411, "bids": [[51.05, 0.482]], "asks": [], "action": "update"}}
1618677888.007597: {"channel": "orderbook", "market": "XRP/USD", "type": "update", "data": {"time": 1618677887.9264665, "checksum": 868105950, "bids": [], "asks": [[1.59815, 0.0], [1.62425, 4.0]], "action": "update"}}
1618677888.088984: {"channel": "orderbook", "market": "SXPBULL/USD", "type": "update", "data": {"time": 1618677887.9878862, "checksum": 1738844884, "bids": [[51.1, 13.259]], "asks": [], "action": "update"}}
1618677888.089062: {"channel": "orderbook", "market": "XRP/USD", "type": "update", "data": {"time": 1618677888.0018492, "checksum": 3751044274, "bids": [], "asks": [[1.593, 633.0], [1.5932, 2512.0], [1.62425, 0.0]], "action": "update"}}
1618677888.120351: {"channel": "orderbook", "market": "NVDA-0625", "type": "update", "data": {"time": 1618677888.03564, "checksum": 3644189371, "bids": [], "asks": [], "action": "update"}}
1618677888.143692: {"channel": "orderbook", "market": "XRP/USD", "type": "update", "data": {"time": 1618677888.0599458, "checksum": 924673416, "bids": [[1.5882, 0.0], [1.556625, 1.0]], "asks": [[1.593025, 0.0], [1.62425, 4.0]], "action": "update"}}
1618677888.1989272: {"channel": "orderbook", "market": "XRP/USD", "type": "update", "data": {"time": 1618677888.1061933, "checksum": 4037079725, "bids": [[1.589025, 39268.0]], "asks": [[1.592825, 1100.0], [1.597875, 0.0]], "action": "update"}}
1618677888.208354: {"channel": "orderbook", "market": "SUSHIBEAR/USD", "type": "update", "data": {"time": 1618677888.0580666, "checksum": 1472358331, "bids": [], "asks": [], "action": "update"}}
1618677888.2084439: {"channel": "orderbook", "market": "AMD/USD", "type": "update", "data": {"time": 1618677888.1260874, "checksum": 1935389369, "bids": [], "asks": [], "action": "update"}}
1618677888.2363431: {"channel": "orderbook", "market": "AKRO/USD", "type": "update", "data": {"time": 1618677888.1504683, "checksum": 1967062938, "bids": [[0.06808, 180.0], [0.059365, 0.0]], "asks": [[0.06863, 143.0], [0.08533, 0.0]], "action": "update"}}
1618677888.236474: {"channel": "orderbook", "market": "XRP/USD", "type": "update", "data": {"time": 1618677888.1521015, "checksum": 2392996961, "bids": [], "asks": [[1.597825, 188.0], [1.62425, 0.0]], "action": "update"}}
1618677888.26793: {"channel": "orderbook", "market": "SXPBULL/USD", "type": "update", "data": {"time": 1618677888.155907, "checksum": 1303551411, "bids": [[51.1, 0.441]], "asks": [], "action": "update"}}
1618677888.2680478: {"channel": "orderbook", "market": "AKRO/USD", "type": "update", "data": {"time": 1618677888.1863427, "checksum": 3029497349, "bids": [[0.068135, 38088.0]], "asks": [[0.068565, 38126.0]], "action": "update"}}
1618677888.268142: {"channel": "orderbook", "market": "XRP/USD", "type": "update", "data": {"time": 1618677888.1790056, "checksum": 2267193796, "bids": [[1.589025, 3619.0]], "asks": [[1.593, 0.0], [1.62425, 4.0]], "action": "update"}}
1618677888.289449: {"channel": "orderbook", "market": "XRP/USD", "type": "update", "data": {"time": 1618677888.2049084, "checksum": 3504800076, "bids": [], "asks": [[1.5928, 633.0], [1.62425, 0.0]], "action": "update"}}
1618677888.289612: {"channel": "orderbook", "market": "ZECBULL/USD", "type": "update", "data": {"time": 1618677888.2054796, "checksum": 3442597104, "bids": [], "asks": [], "action": "update"}}
1618677888.2896829: {"channel": "orderbook", "market": "SUSHIBEAR/USD", "type": "update", "data": {"time": 1618677888.2111707, "checksum": 3997630392, "bids": [[1.135e-05, 0.0]], "asks": [], "action": "update"}}
1618677888.3302882: {"channel": "orderbook", "market": "ZECBULL/USD", "type": "update", "data": {"time": 1618677888.2534184, "checksum": 2821235903, "bids": [], "asks": [[7362.5, 0.0]], "action": "update"}}
1618677888.335391: {"channel": "orderbook", "market": "XRP/USD", "type": "update", "data": {"time": 1618677888.2564054, "checksum": 3603680970, "bids": [], "asks": [[1.592825, 0.0], [1.60965, 243444.0]], "action": "update"}}
1618677888.3465421: {"channel": "orderbook", "market": "SXPBULL/USD", "type": "update", "data": {"time": 1618677888.265769, "checksum": 145178341, "bids": [[51.1, 1.723]], "asks": [], "action": "update"}}
1618677888.378989: {"channel": "orderbook", "market": "XRP/USD", "type": "update", "data": {"time": 1618677888.3050327, "checksum": 3087618767, "bids": [], "asks": [[1.592625, 1100.0], [1.6239, 0.0]], "action": "update"}}
1618677888.3910022: {"channel": "orderbook", "market": "SUSHIBEAR/USD", "type": "update", "data": {"time": 1618677888.3110032, "checksum": 3095200563, "bids": [[1.165e-05, 8660000.0]], "asks": [], "action": "update"}}
1618677888.425513: {"channel": "orderbook", "market": "SXPBULL/USD", "type": "update", "data": {"time": 1618677888.3408797, "checksum": 1098707111, "bids": [[50.35, 6.581]], "asks": [], "action": "update"}}
1618677888.429591: {"channel": "orderbook", "market": "XRP/USD", "type": "update", "data": {"time": 1618677888.3543837, "checksum": 2548784745, "bids": [], "asks": [[1.59765, 157.0], [1.6235, 0.0]], "action": "update"}}
1618677888.444531: {"channel": "orderbook", "market": "AKRO/USD", "type": "update", "data": {"time": 1618677888.361144, "checksum": 3029497349, "bids": [], "asks": [], "action": "update"}}
1618677888.449831: {"channel": "orderbook", "market": "PAXG/USD", "type": "update", "data": {"time": 1618677888.3724418, "checksum": 2811656200, "bids": [], "asks": [], "action": "update"}}
1618677888.476591: {"channel": "orderbook", "market": "XRP/USD", "type": "update", "data": {"time": 1618677888.4032226, "checksum": 190703142, "bids": [[1.58795, 315759.0], [1.586, 0.0]], "asks": [], "action": "update"}}
1618677888.5096462: {"channel": "orderbook", "market": "XRP/USD", "type": "update", "data": {"time": 1618677888.4325938, "checksum": 3410368527, "bids": [], "asks": [[1.59405, 326105.0], [1.62335, 0.0]], "action": "update"}}
1618677888.518153: {"channel": "orderbook", "market": "THETAHEDGE/USD", "type": "update", "data": {"time": 1618677888.446663, "checksum": 3313924624, "bids": [], "asks": [], "action": "update"}}
1618677888.554687: {"channel": "orderbook", "market": "ZECBULL/USD", "type": "update", "data": {"time": 1618677888.4781902, "checksum": 2576671, "bids": [], "asks": [[7375.0, 0.02774]], "action": "update"}}
1618677888.554836: {"channel": "orderbook", "market": "XRP/USD", "type": "update", "data": {"time": 1618677888.477837, "checksum": 20050585, "bids": [[1.590525, 0.0], [1.5561, 4.0]], "asks": [], "action": "update"}}
1618677888.565511: {"channel": "orderbook", "market": "SXPBULL/USD", "type": "update", "data": {"time": 1618677888.4640276, "checksum": 77420374, "bids": [[51.1, 0.441]], "asks": [], "action": "update"}}
1618677888.648523: {"channel": "orderbook", "market": "XRP/USD", "type": "update", "data": {"time": 1618677888.5689933, "checksum": 4226749482, "bids": [[1.590325, 2514.0], [1.5561, 0.0]], "asks": [[1.59195, 5.0], [1.623175, 0.0]], "action": "update"}}
1618677888.703896: {"channel": "orderbook", "market": "SXPBULL/USD", "type": "update", "data": {"time": 1618677888.6119025, "checksum": 2900095155, "bids": [[51.1, 122.593]], "asks": [], "action": "update"}}
1618677888.709117: {"channel": "orderbook", "market": "XRP/USD", "type": "update", "data": {"time": 1618677888.635022, "checksum": 2315515596, "bids": [[1.590775, 532.0]], "asks": [], "action": "update"}}
1618677888.747803: {"channel": "orderbook", "market": "XRP/USD", "type": "update", "data": {"time": 1618677888.6609926, "checksum": 946773569, "bids": [], "asks": [[1.592625, 0.0], [1.59285, 4550.0]], "action": "update"}}
1618677888.809845: {"channel": "orderbook", "market": "SXPBULL/USD", "type": "update", "data": {"time": 1618677888.7146707, "checksum": 1481914348, "bids": [[50.275, 318.212]], "asks": [], "action": "update"}}
1618677888.827092: {"channel": "orderbook", "market": "XRP/USD", "type": "update", "data": {"time": 1618677888.7358396, "checksum": 3453504301, "bids": [[1.589725, 0.0], [1.5561, 4.0]], "asks": [[1.59195, 1105.0]], "action": "update"}}
1618677888.843114: {"channel": "orderbook", "market": "BTC-MOVE-WK-0507", "type": "update", "data": {"time": 1618677888.7709394, "checksum": 901794806, "bids": [], "asks": [], "action": "update"}}
1618677888.847262: {"channel": "orderbook", "market": "SXPBULL/USD", "type": "update", "data": {"time": 1618677888.7555454, "checksum": 206031524, "bids": [[51.625, 0.0], [51.55, 39.7]], "asks": [], "action": "update"}}
1618677888.860181: {"channel": "orderbook", "market": "XRP/USD", "type": "update", "data": {"time": 1618677888.7792275, "checksum": 4267642179, "bids": [], "asks": [[1.59195, 5.0]], "action": "update"}}
1618677888.875138: {"channel": "orderbook", "market": "SXPBULL/USD", "type": "update", "data": {"time": 1618677888.7896311, "checksum": 1317587901, "bids": [[51.1, 0.441]], "asks": [], "action": "update"}}
1618677888.905729: {"channel": "orderbook", "market": "XRP/USD", "type": "update", "data": {"time": 1618677888.8297005, "checksum": 1617458212, "bids": [], "asks": [[1.591925, 1100.0], [1.612525, 0.0]], "action": "update"}}
1618677888.922973: {"channel": "orderbook", "market": "XRP/USD", "type": "update", "data": {"time": 1618677888.8475435, "checksum": 2688847270, "bids": [], "asks": [[1.59285, 0.0], [1.623175, 2.0]], "action": "update"}}
1618677888.957092: {"channel": "orderbook", "market": "XRP/USD", "type": "update", "data": {"time": 1618677888.8783388, "checksum": 284034032, "bids": [[1.581, 2246.0]], "asks": [[1.5941, 6348.0]], "action": "update"}}
1618677889.0243142: {"channel": "orderbook", "market": "SXPBULL/USD", "type": "update", "data": {"time": 1618677888.941309, "checksum": 206031524, "bids": [[51.1, 122.593]], "asks": [], "action": "update"}}
1618677889.0270631: {"channel": "orderbook", "market": "XRP/USD", "type": "update", "data": {"time": 1618677888.9525561, "checksum": 514917291, "bids": [], "asks": [[1.59195, 0.0], [1.597825, 0.0], [1.62335, 8051.0], [1.6235, 4.0]], "action": "update"}}
1618677889.0942762: {"channel": "orderbook", "market": "XRP/USD", "type": "update", "data": {"time": 1618677889.002834, "checksum": 3880119713, "bids": [], "asks": [[1.591925, 0.0], [1.6239, 1.0]], "action": "update"}}
1618677889.133913: {"channel": "orderbook", "market": "ZECBULL/USD", "type": "update", "data": {"time": 1618677889.0578835, "checksum": 657318418, "bids": [[7147.5, 0.02751]], "asks": [], "action": "update"}}
1618677889.148854: {"channel": "orderbook", "market": "XRP/USD", "type": "update", "data": {"time": 1618677889.0561192, "checksum": 2572552216, "bids": [], "asks": [[1.592625, 1100.0], [1.6239, 0.0]], "action": "update"}}
1618677889.151974: {"channel": "orderbook", "market": "NVDA-0625", "type": "update", "data": {"time": 1618677889.0770936, "checksum": 3644189371, "bids": [], "asks": [], "action": "update"}}
1618677889.176169: {"channel": "orderbook", "market": "SUSHIBEAR/USD", "type": "update", "data": {"time": 1618677889.097064, "checksum": 3095200563, "bids": [], "asks": [], "action": "update"}}
1618677889.183845: {"channel": "orderbook", "market": "XRP/USD", "type": "update", "data": {"time": 1618677889.1100993, "checksum": 2335291842, "bids": [], "asks": [[1.594275, 0.0], [1.6239, 1.0]], "action": "update"}}
1618677889.210457: {"channel": "orderbook", "market": "XRP/USD", "type": "update", "data": {"time": 1618677889.1354825, "checksum": 3089584932, "bids": [[1.58995, 5060.0], [1.5561, 0.0]], "asks": [[1.592775, 1.0], [1.59385, 250566.0], [1.6235, 0.0], [1.6239, 0.0]], "action": "update"}}
1618677889.224682: {"channel": "orderbook", "market": "AMD/USD", "type": "update", "data": {"time": 1618677889.1503365, "checksum": 1935389369, "bids": [], "asks": [], "action": "update"}}
1618677889.251772: {"channel": "orderbook", "market": "SXPBULL/USD", "type": "update", "data": {"time": 1618677889.1359656, "checksum": 1317587901, "bids": [[51.1, 0.441]], "asks": [], "action": "update"}}
1618677889.282759: {"channel": "orderbook", "market": "XRP/USD", "type": "update", "data": {"time": 1618677889.2071745, "checksum": 3707273963, "bids": [], "asks": [[1.598425, 188.0], [1.62335, 0.0]], "action": "update"}}
1618677889.325475: {"channel": "orderbook", "market": "ZECBULL/USD", "type": "update", "data": {"time": 1618677889.2424476, "checksum": 657318418, "bids": [], "asks": [], "action": "update"}}
1618677889.345749: {"channel": "orderbook", "market": "XRP/USD", "type": "update", "data": {"time": 1618677889.2694807, "checksum": 1622429263, "bids": [[1.590325, 0.0], [1.589725, 1454.0]], "asks": [[1.5928, 0.0], [1.5932, 0.0], [1.62335, 8051.0], [1.6235, 4.0]], "action": "update"}}
1618677889.356333: {"channel": "orderbook", "market": "SUSHIBEAR/USD", "type": "update", "data": {"time": 1618677889.2781527, "checksum": 562755462, "bids": [[1.17e-05, 2100000.0]], "asks": [], "action": "update"}}
1618677889.405123: {"channel": "orderbook", "market": "XRP/USD", "type": "update", "data": {"time": 1618677889.3222246, "checksum": 1292546476, "bids": [], "asks": [[1.5926, 633.0], [1.592625, 1105.0], [1.5935, 0.0], [1.593675, 0.0], [1.5957, 0.0], [1.6239, 1.0], [1.62425, 4.0]], "action": "update"}}
1618677889.405251: {"channel": "orderbook", "market": "SXPBULL/USD", "type": "update", "data": {"time": 1618677889.3184044, "checksum": 206031524, "bids": [[51.1, 122.593]], "asks": [], "action": "update"}}
1618677889.4239302: {"channel": "orderbook", "market": "XRP/USD", "type": "update", "data": {"time": 1618677889.3504283, "checksum": 2836025545, "bids": [[1.591075, 1413.0], [1.556625, 0.0]], "asks": [], "action": "update"}}
1618677889.4240398: {"channel": "orderbook", "market": "SUSHIBEAR/USD", "type": "update", "data": {"time": 1618677889.351347, "checksum": 3853802005, "bids": [[1.175e-05, 8680000.0]], "asks": [], "action": "update"}}
1618677889.444861: {"channel": "orderbook", "market": "XRP/USD", "type": "update", "data": {"time": 1618677889.3684037, "checksum": 315147320, "bids": [[1.589, 0.0], [1.556625, 1.0]], "asks": [[1.5926, 0.0], [1.592625, 5.0], [1.624325, 6.0]], "action": "update"}}
1618677889.466305: {"channel": "orderbook", "market": "AKRO/USD", "type": "update", "data": {"time": 1618677889.3854842, "checksum": 3029497349, "bids": [], "asks": [], "action": "update"}}
1618677889.47367: {"channel": "orderbook", "market": "XRP/USD", "type": "update", "data": {"time": 1618677889.3973777, "checksum": 338949876, "bids": [[1.590825, 0.0], [1.5561, 4.0]], "asks": [[1.5934, 633.0], [1.594, 9050.0], [1.5941, 1398.0], [1.624325, 0.0]], "action": "update"}}
1618677889.4923398: {"channel": "orderbook", "market": "PAXG/USD", "type": "update", "data": {"time": 1618677889.4138448, "checksum": 2811656200, "bids": [], "asks": [], "action": "update"}}
1618677889.521146: {"channel": "orderbook", "market": "SXPBULL/USD", "type": "update", "data": {"time": 1618677889.4393494, "checksum": 1317587901, "bids": [[51.1, 0.441]], "asks": [], "action": "update"}}
1618677889.545351: {"channel": "orderbook", "market": "THETAHEDGE/USD", "type": "update", "data": {"time": 1618677889.4696302, "checksum": 3313924624, "bids": [], "asks": [], "action": "update"}}
1618677889.586748: {"channel": "orderbook", "market": "SXPBULL/USD", "type": "update", "data": {"time": 1618677889.489324, "checksum": 1317587901, "bids": [], "asks": [], "action": "update"}}
1618677889.6514912: {"channel": "orderbook", "market": "SXPBULL/USD", "type": "update", "data": {"time": 1618677889.5689313, "checksum": 3243576633, "bids": [], "asks": [[52.2, 49.058]], "action": "update"}}
1618677889.729124: {"channel": "orderbook", "market": "SXPBULL/USD", "type": "update", "data": {"time": 1618677889.645621, "checksum": 3635261508, "bids": [[51.1, 122.593]], "asks": [[52.55, 6.246]], "action": "update"}}
1618677889.732158: {"channel": "orderbook", "market": "XRP/USD", "type": "update", "data": {"time": 1618677889.6510484, "checksum": 481539917, "bids": [[1.591225, 1100.0], [1.591075, 4690.0], [1.590825, 2513.0], [1.589025, 0.0], [1.588875, 3675.0], [1.588525, 0.0], [1.588275, 0.0]], "asks": [[1.592525, 1100.0], [1.594075, 0.0], [1.5941, 0.0], [1.5985, 2939.0], [1.5986, 188.0]], "action": "update"}}
1618677889.74809: {"channel": "orderbook", "market": "ZECBULL/USD", "type": "update", "data": {"time": 1618677889.669351, "checksum": 3238000454, "bids": [[7205.0, 0.38616]], "asks": [], "action": "update"}}
1618677889.820506: {"channel": "orderbook", "market": "XRP/USD", "type": "update", "data": {"time": 1618677889.7422392, "checksum": 1671278491, "bids": [[1.591075, 0.0], [1.55565, 2.0]], "asks": [], "action": "update"}}
1618677889.840964: {"channel": "orderbook", "market": "AKRO/USD", "type": "update", "data": {"time": 1618677889.7608602, "checksum": 1603608369, "bids": [], "asks": [[0.06858, 140.0], [0.085, 0.0]], "action": "update"}}
1618677889.856972: {"channel": "orderbook", "market": "XRP/USD", "type": "update", "data": {"time": 1618677889.7786815, "checksum": 4272322383, "bids": [[1.5898, 3782.0], [1.55565, 0.0]], "asks": [[1.592625, 0.0], [1.59765, 0.0], [1.624325, 6.0], [1.6256, 1.0]], "action": "update"}}
1618677889.871302: {"channel": "orderbook", "market": "ZECBULL/USD", "type": "update", "data": {"time": 1618677889.79102, "checksum": 771395759, "bids": [[5822.5, 0.0]], "asks": [], "action": "update"}}
1618677889.871382: {"channel": "orderbook", "market": "BTC-MOVE-WK-0507", "type": "update", "data": {"time": 1618677889.7946262, "checksum": 901794806, "bids": [], "asks": [], "action": "update"}}
1618677889.871427: {"channel": "orderbook", "market": "XRP/USD", "type": "update", "data": {"time": 1618677889.793361, "checksum": 3873619806, "bids": [], "asks": [[1.5949, 3597.0], [1.6256, 0.0]], "action": "update"}}
1618677889.888021: {"channel": "orderbook", "market": "AKRO/USD", "type": "update", "data": {"time": 1618677889.8108685, "checksum": 726621347, "bids": [], "asks": [[0.06863, 0.0], [0.085, 1084.0]], "action": "update"}}
1618677889.9009018: {"channel": "orderbook", "market": "XRP/USD", "type": "update", "data": {"time": 1618677889.822775, "checksum": 771841629, "bids": [[1.590825, 0.0], [1.5882, 367192.0]], "asks": [], "action": "update"}}
1618677889.910729: {"channel": "orderbook", "market": "SXPBULL/USD", "type": "update", "data": {"time": 1618677889.8180888, "checksum": 2746347763, "bids": [[51.55, 0.0], [48.975, 5.546]], "asks": [], "action": "update"}}
1618677890.003416: {"channel": "orderbook", "market": "XRP/USD", "type": "update", "data": {"time": 1618677889.9278896, "checksum": 1472227672, "bids": [], "asks": [[1.59405, 0.0], [1.5957, 1685.0]], "action": "update"}}
1618677890.022654: {"channel": "orderbook", "market": "XRP/USD", "type": "update", "data": {"time": 1618677889.942315, "checksum": 1816527979, "bids": [[1.591225, 0.0], [1.55565, 2.0]], "asks": [], "action": "update"}}
1618677890.104939: {"channel": "orderbook", "market": "XRP/USD", "type": "update", "data": {"time": 1618677890.0213108, "checksum": 2606158887, "bids": [[1.590925, 1100.0], [1.58995, 0.0]], "asks": [], "action": "update"}}
1618677890.116662: {"channel": "orderbook", "market": "ZECBULL/USD", "type": "update", "data": {"time": 1618677890.0404541, "checksum": 1480987480, "bids": [[7205.0, 0.87355]], "asks": [], "action": "update"}}
1618677890.119679: {"channel": "orderbook", "market": "XRP/USD", "type": "update", "data": {"time": 1618677890.0472739, "checksum": 1537841677, "bids": [[1.569125, 229456.0], [1.55565, 0.0]], "asks": [[1.592775, 4141.0], [1.598775, 157.0], [1.624325, 0.0]], "action": "update"}}
1618677890.169316: {"channel": "orderbook", "market": "SXPBULL/USD", "type": "update", "data": {"time": 1618677890.0501232, "checksum": 4274031967, "bids": [[51.1, 0.441]], "asks": [[52.125, 41.207]], "action": "update"}}
1618677890.217119: {"channel": "orderbook", "market": "XRP/USD", "type": "update", "data": {"time": 1618677890.1068022, "checksum": 3449879391, "bids": [], "asks": [[1.592125, 2.0], [1.62425, 0.0]], "action": "update"}}
1618677890.2171981: {"channel": "orderbook", "market": "XRP/USD", "type": "update", "data": {"time": 1618677890.1310878, "checksum": 1183573703, "bids": [[1.590925, 0.0], [1.58905, 9000.0]], "asks": [], "action": "update"}}
1618677890.2172558: {"channel": "orderbook", "market": "NVDA-0625", "type": "update", "data": {"time": 1618677890.1398804, "checksum": 3644189371, "bids": [], "asks": [], "action": "update"}}
1618677890.236544: {"channel": "orderbook", "market": "XRP/USD", "type": "update", "data": {"time": 1618677890.1517296, "checksum": 2224776687, "bids": [], "asks": [[1.592525, 0.0], [1.598425, 0.0], [1.62425, 4.0], [1.624325, 6.0]], "action": "update"}}
1618677890.247951: {"channel": "orderbook", "market": "SUSHIBEAR/USD", "type": "update", "data": {"time": 1618677890.1692364, "checksum": 3853802005, "bids": [], "asks": [], "action": "update"}}
1618677890.249318: {"channel": "orderbook", "market": "AMD/USD", "type": "update", "data": {"time": 1618677890.1741261, "checksum": 1935389369, "bids": [], "asks": [], "action": "update"}}
1618677890.278471: {"channel": "orderbook", "market": "XRP/USD", "type": "update", "data": {"time": 1618677890.1979063, "checksum": 3813910907, "bids": [[1.58905, 0.0], [1.55565, 2.0]], "asks": [[1.591975, 1100.0], [1.624325, 0.0]], "action": "update"}}
1618677890.295912: {"channel": "orderbook", "market": "SXPBULL/USD", "type": "update", "data": {"time": 1618677890.20387, "checksum": 24066561, "bids": [[51.1, 122.593]], "asks": [], "action": "update"}}
1618677890.322786: {"channel": "orderbook", "market": "XRP/USD", "type": "update", "data": {"time": 1618677890.2415853, "checksum": 1470192358, "bids": [[1.58795, 0.0], [1.586, 1602.0], [1.56775, 0.0], [1.5554, 1.0]], "asks": [], "action": "update"}}
1618677890.3429608: {"channel": "orderbook", "market": "SXPBULL/USD", "type": "update", "data": {"time": 1618677890.2544036, "checksum": 3690071433, "bids": [[51.45, 0.0], [48.95, 4.196]], "asks": [[52.425, 2.095]], "action": "update"}}
1618677890.345074: {"channel": "orderbook", "market": "ZECBULL/USD", "type": "update", "data": {"time": 1618677890.265968, "checksum": 1480987480, "bids": [], "asks": [], "action": "update"}}
1618677890.34512: {"channel": "orderbook", "market": "XRP/USD", "type": "update", "data": {"time": 1618677890.267513, "checksum": 3486145348, "bids": [[1.581, 657.0]], "asks": [], "action": "update"}}
1618677890.3719208: {"channel": "orderbook", "market": "THETAHEDGE/USD", "type": "update", "data": {"time": 1618677890.2964942, "checksum": 2672103965, "bids": [[24.895, 168.69]], "asks": [], "action": "update"}}
1618677890.389977: {"channel": "orderbook", "market": "SXPBULL/USD", "type": "update", "data": {"time": 1618677890.3033946, "checksum": 296106424, "bids": [[51.1, 0.441]], "asks": [], "action": "update"}}
1618677890.400408: {"channel": "orderbook", "market": "XRP/USD", "type": "update", "data": {"time": 1618677890.324836, "checksum": 42045218, "bids": [], "asks": [[1.59385, 0.0], [1.594, 6539.0], [1.624325, 6.0]], "action": "update"}}
1618677890.425389: {"channel": "orderbook", "market": "XRP/USD", "type": "update", "data": {"time": 1618677890.34052, "checksum": 3163166034, "bids": [[1.590625, 2513.0], [1.5554, 0.0]], "asks": [], "action": "update"}}
1618677890.462946: {"channel": "orderbook", "market": "SXPBULL/USD", "type": "update", "data": {"time": 1618677890.3781486, "checksum": 3410520533, "bids": [[51.05, 169.776]], "asks": [], "action": "update"}}
1618677890.464088: {"channel": "orderbook", "market": "XRP/USD", "type": "update", "data": {"time": 1618677890.3879778, "checksum": 1237873936, "bids": [], "asks": [[1.598925, 190.0]], "action": "update"}}
1618677890.4926238: {"channel": "orderbook", "market": "AKRO/USD", "type": "update", "data": {"time": 1618677890.4103377, "checksum": 726621347, "bids": [], "asks": [], "action": "update"}}
1618677890.5326998: {"channel": "orderbook", "market": "XRP/USD", "type": "update", "data": {"time": 1618677890.4477549, "checksum": 3953555429, "bids": [], "asks": [[1.5928, 633.0], [1.5934, 0.0], [1.593675, 1446.0], [1.624325, 0.0]], "action": "update"}}
1618677890.5345678: {"channel": "orderbook", "market": "ZECBULL/USD", "type": "update", "data": {"time": 1618677890.4496667, "checksum": 4199809049, "bids": [[7195.0, 0.0], [6557.5, 12.1784]], "asks": [], "action": "update"}}
1618677890.550174: {"channel": "orderbook", "market": "THETAHEDGE/USD", "type": "update", "data": {"time": 1618677890.4606283, "checksum": 731073140, "bids": [], "asks": [[25.4225, 0.0]], "action": "update"}}
1618677890.550244: {"channel": "orderbook", "market": "PAXG/USD", "type": "update", "data": {"time": 1618677890.4605882, "checksum": 2811656200, "bids": [], "asks": [], "action": "update"}}
1618677890.5559309: {"channel": "orderbook", "market": "XRP/USD", "type": "update", "data": {"time": 1618677890.4643111, "checksum": 1668511633, "bids": [[1.590775, 1632.0]], "asks": [], "action": "update"}}
1618677890.5654552: {"channel": "orderbook", "market": "THETAHEDGE/USD", "type": "update", "data": {"time": 1618677890.479295, "checksum": 2433722445, "bids": [], "asks": [[25.4425, 131.19]], "action": "update"}}
1618677890.570613: {"channel": "orderbook", "market": "XRP/USD", "type": "update", "data": {"time": 1618677890.4878604, "checksum": 1052625575, "bids": [], "asks": [[1.5944, 1345.0], [1.62425, 0.0]], "action": "update"}}
1618677890.5977201: {"channel": "orderbook", "market": "XRP/USD", "type": "update", "data": {"time": 1618677890.520989, "checksum": 2771398795, "bids": [[1.5908, 1100.0], [1.55565, 0.0]], "asks": [], "action": "update"}}
1618677890.597802: {"channel": "orderbook", "market": "SXPBULL/USD", "type": "update", "data": {"time": 1618677890.5054245, "checksum": 3410520533, "bids": [], "asks": [], "action": "update"}}
1618677890.618727: {"channel": "orderbook", "market": "SUSHIBEAR/USD", "type": "update", "data": {"time": 1618677890.542201, "checksum": 2781540518, "bids": [], "asks": [[1.223e-05, 30000.0], [0.035, 0.0]], "action": "update"}}
1618677890.638934: {"channel": "orderbook", "market": "SUSHIBEAR/USD", "type": "update", "data": {"time": 1618677890.5621278, "checksum": 2338172525, "bids": [[1.165e-05, 0.0]], "asks": [[1.22e-05, 8660000.0]], "action": "update"}}
1618677890.639008: {"channel": "orderbook", "market": "ZECBULL/USD", "type": "update", "data": {"time": 1618677890.565851, "checksum": 580697051, "bids": [], "asks": [[7307.5, 0.0]], "action": "update"}}
1618677890.6487849: {"channel": "orderbook", "market": "SXPBULL/USD", "type": "update", "data": {"time": 1618677890.5610776, "checksum": 1334614614, "bids": [], "asks": [[52.025, 31.2], [54.275, 0.0]], "action": "update"}}
1618677890.667927: {"channel": "orderbook", "market": "XRP/USD", "type": "update", "data": {"time": 1618677890.5905015, "checksum": 3274193671, "bids": [[1.589325, 6474.0]], "asks": [[1.5926, 5.0], [1.5934, 2512.0], [1.5957, 0.0], [1.6239, 0.0]], "action": "update"}}
1618677890.735446: {"channel": "orderbook", "market": "SUSHIBEAR/USD", "type": "update", "data": {"time": 1618677890.6608613, "checksum": 3688622672, "bids": [[1.17e-05, 10760000.0]], "asks": [], "action": "update"}}
1618677890.7476108: {"channel": "orderbook", "market": "XRP/USD", "type": "update", "data": {"time": 1618677890.6686006, "checksum": 1439666322, "bids": [], "asks": [[1.5928, 0.0], [1.5934, 3145.0], [1.6239, 1.0]], "action": "update"}}
1618677890.747678: {"channel": "orderbook", "market": "SXPBULL/USD", "type": "update", "data": {"time": 1618677890.6632414, "checksum": 2110259244, "bids": [[51.05, 0.482]], "asks": [], "action": "update"}}
1618677890.772938: {"channel": "orderbook", "market": "XRP/USD", "type": "update", "data": {"time": 1618677890.6937659, "checksum": 3726632728, "bids": [[1.568575, 293.0], [1.5561, 0.0]], "asks": [[1.5945, 329029.0]], "action": "update"}}
1618677890.835211: {"channel": "orderbook", "market": "XRP/USD", "type": "update", "data": {"time": 1618677890.7546563, "checksum": 2429871143, "bids": [[1.590775, 532.0]], "asks": [[1.5934, 633.0]], "action": "update"}}
1618677890.844596: {"channel": "orderbook", "market": "XRP/USD", "type": "update", "data": {"time": 1618677890.7678819, "checksum": 3689951748, "bids": [], "asks": [[1.591975, 0.0], [1.62425, 4.0]], "action": "update"}}
1618677890.857514: {"channel": "orderbook", "market": "THETAHEDGE/USD", "type": "update", "data": {"time": 1618677890.7716422, "checksum": 309983746, "bids": [[24.8675, 0.0]], "asks": [], "action": "update"}}
1618677890.8776379: {"channel": "orderbook", "market": "XRP/USD", "type": "update", "data": {"time": 1618677890.7971888, "checksum": 2572111459, "bids": [], "asks": [[1.592775, 1.0]], "action": "update"}}
1618677890.887268: {"channel": "orderbook", "market": "SXPBULL/USD", "type": "update", "data": {"time": 1618677890.7893567, "checksum": 4049401148, "bids": [[51.05, 237.56]], "asks": [], "action": "update"}}
1618677890.901831: {"channel": "orderbook", "market": "XRP/USD", "type": "update", "data": {"time": 1618677890.8207955, "checksum": 1166187952, "bids": [[1.5908, 5240.0]], "asks": [[1.593675, 0.0], [1.595325, 4.0], [1.624325, 6.0]], "action": "update"}}
1618677890.9020002: {"channel": "orderbook", "market": "BTC-MOVE-WK-0507", "type": "update", "data": {"time": 1618677890.8228211, "checksum": 901794806, "bids": [], "asks": [], "action": "update"}}
1618677890.93172: {"channel": "orderbook", "market": "SXPBULL/USD", "type": "update", "data": {"time": 1618677890.8458288, "checksum": 2777196251, "bids": [[51.575, 28.2], [51.05, 0.482], [48.95, 0.0]], "asks": [[52.025, 0.0], [52.125, 1.107], [54.275, 7.631]], "action": "update"}}
1618677891.010231: {"channel": "orderbook", "market": "XRP/USD", "type": "update", "data": {"time": 1618677890.9239016, "checksum": 1530481721, "bids": [[1.590625, 0.0], [1.590175, 1407.0]], "asks": [], "action": "update"}}
1618677891.0268538: {"channel": "orderbook", "market": "SXPBULL/USD", "type": "update", "data": {"time": 1618677890.9398456, "checksum": 826273285, "bids": [[51.1, 24.126]], "asks": [], "action": "update"}}
1618677891.116416: {"channel": "orderbook", "market": "XRP/USD", "type": "update", "data": {"time": 1618677891.0265472, "checksum": 4181898781, "bids": [], "asks": [[1.5926, 0.0], [1.5944, 0.0], [1.595175, 1509.0], [1.6256, 1.0]], "action": "update"}}
1618677891.269151: {"channel": "orderbook", "market": "NVDA-0625", "type": "update", "data": {"time": 1618677891.1917202, "checksum": 3644189371, "bids": [], "asks": [], "action": "update"}}
1618677891.279291: {"channel": "orderbook", "market": "AMD/USD", "type": "update", "data": {"time": 1618677891.2022614, "checksum": 1935389369, "bids": [], "asks": [], "action": "update"}}
1618677891.284253: {"channel": "orderbook", "market": "SXPBULL/USD", "type": "update", "data": {"time": 1618677891.1967797, "checksum": 2777196251, "bids": [[51.1, 0.441]], "asks": [], "action": "update"}}
1618677891.329615: {"channel": "orderbook", "market": "ZECBULL/USD", "type": "update", "data": {"time": 1618677891.240034, "checksum": 507847906, "bids": [[6490.0, 0.0]], "asks": [], "action": "update"}}
1618677891.3296828: {"channel": "orderbook", "market": "SUSHIBEAR/USD", "type": "update", "data": {"time": 1618677891.2432127, "checksum": 3688622672, "bids": [], "asks": [], "action": "update"}}
1618677891.359147: {"channel": "orderbook", "market": "ZECBULL/USD", "type": "update", "data": {"time": 1618677891.27541, "checksum": 2603196908, "bids": [[7210.0, 0.40618]], "asks": [], "action": "update"}}
1618677891.4023628: {"channel": "orderbook", "market": "XRP/USD", "type": "update", "data": {"time": 1618677891.3243828, "checksum": 1399349814, "bids": [[1.591225, 2512.0], [1.556625, 0.0]], "asks": [[1.5943, 2510.0], [1.6256, 0.0]], "action": "update"}}
1618677891.460348: {"channel": "orderbook", "market": "XRP/USD", "type": "update", "data": {"time": 1618677891.379692, "checksum": 1423401024, "bids": [[1.5908, 4140.0]], "asks": [[1.5934, 0.0], [1.593625, 634.0], [1.6256, 1.0]], "action": "update"}}
1618677891.493303: {"channel": "orderbook", "market": "SXPBULL/USD", "type": "update", "data": {"time": 1618677891.3999968, "checksum": 1319717734, "bids": [[51.1, 2.809]], "asks": [], "action": "update"}}
1618677891.522963: {"channel": "orderbook", "market": "AKRO/USD", "type": "update", "data": {"time": 1618677891.4371102, "checksum": 726621347, "bids": [], "asks": [], "action": "update"}}
1618677891.523052: {"channel": "orderbook", "market": "XRP/USD", "type": "update", "data": {"time": 1618677891.4432013, "checksum": 92914842, "bids": [[1.591275, 1100.0], [1.5571, 0.0]], "asks": [[1.591975, 5.0], [1.6256, 0.0]], "action": "update"}}
1618677891.567682: {"channel": "orderbook", "market": "SXPBULL/USD", "type": "update", "data": {"time": 1618677891.4744294, "checksum": 2777196251, "bids": [[51.1, 0.441]], "asks": [], "action": "update"}}
1618677891.567747: {"channel": "orderbook", "market": "THETAHEDGE/USD", "type": "update", "data": {"time": 1618677891.4956365, "checksum": 309983746, "bids": [], "asks": [], "action": "update"}}
1618677891.6088588: {"channel": "orderbook", "market": "PAXG/USD", "type": "update", "data": {"time": 1618677891.52303, "checksum": 2811656200, "bids": [], "asks": [], "action": "update"}}
1618677891.6193511: {"channel": "orderbook", "market": "SXPBULL/USD", "type": "update", "data": {"time": 1618677891.5257525, "checksum": 2777196251, "bids": [], "asks": [], "action": "update"}}
1618677891.628831: {"channel": "orderbook", "market": "XRP/USD", "type": "update", "data": {"time": 1618677891.5506911, "checksum": 577952596, "bids": [], "asks": [[1.59445, 1435.0], [1.624325, 0.0]], "action": "update"}}
1618677891.643589: {"channel": "orderbook", "market": "SXPBULL/USD", "type": "update", "data": {"time": 1618677891.5593944, "checksum": 3983617535, "bids": [[51.125, 6.418]], "asks": [], "action": "update"}}
1618677891.6758232: {"channel": "orderbook", "market": "XRP/USD", "type": "update", "data": {"time": 1618677891.596844, "checksum": 4202062038, "bids": [[1.591225, 0.0], [1.568375, 0.0], [1.5571, 10.0], [1.556625, 1.0]], "asks": [[1.5943, 0.0], [1.624325, 6.0]], "action": "update"}}
1618677891.695626: {"channel": "orderbook", "market": "ZECBULL/USD", "type": "update", "data": {"time": 1618677891.6203547, "checksum": 4247921306, "bids": [[6560.0, 14.87671]], "asks": [], "action": "update"}}
1618677891.7182221: {"channel": "orderbook", "market": "XRP/USD", "type": "update", "data": {"time": 1618677891.6431932, "checksum": 3903251261, "bids": [[1.591275, 0.0], [1.5561, 4.0]], "asks": [], "action": "update"}}
1618677891.7658281: {"channel": "orderbook", "market": "SXPBULL/USD", "type": "update", "data": {"time": 1618677891.681366, "checksum": 710238303, "bids": [[51.125, 6.181]], "asks": [[52.2, 12.658]], "action": "update"}}
1618677891.766481: {"channel": "orderbook", "market": "XRP/USD", "type": "update", "data": {"time": 1618677891.6931443, "checksum": 1354776259, "bids": [[1.590975, 1100.0], [1.5561, 0.0]], "asks": [], "action": "update"}}
1618677891.798051: {"channel": "orderbook", "market": "ZECBULL/USD", "type": "update", "data": {"time": 1618677891.7149127, "checksum": 2194970148, "bids": [[7205.0, 0.38616]], "asks": [], "action": "update"}}
1618677891.841548: {"channel": "orderbook", "market": "SUSHIBEAR/USD", "type": "update", "data": {"time": 1618677891.7680845, "checksum": 1951180648, "bids": [], "asks": [[1.223e-05, 0.0], [0.035, 12000.0]], "action": "update"}}
1618677891.85065: {"channel": "orderbook", "market": "XRP/USD", "type": "update", "data": {"time": 1618677891.767531, "checksum": 3964576712, "bids": [], "asks": [[1.594, 9050.0]], "action": "update"}}
1618677891.924386: {"channel": "orderbook", "market": "BTC-MOVE-WK-0507", "type": "update", "data": {"time": 1618677891.8458338, "checksum": 901794806, "bids": [], "asks": [], "action": "update"}}
1618677891.924449: {"channel": "orderbook", "market": "SXPBULL/USD", "type": "update", "data": {"time": 1618677891.8335197, "checksum": 2753171849, "bids": [[51.125, 10.175]], "asks": [], "action": "update"}}
1618677891.9962409: {"channel": "orderbook", "market": "ZECBULL/USD", "type": "update", "data": {"time": 1618677891.9166415, "checksum": 3036937784, "bids": [], "asks": [[7312.5, 0.56116]], "action": "update"}}
1618677891.9963331: {"channel": "orderbook", "market": "XRP/USD", "type": "update", "data": {"time": 1618677891.9194355, "checksum": 673873617, "bids": [[1.56855, 351.0]], "asks": [[1.594, 6539.0]], "action": "update"}}
1618677891.999498: {"channel": "orderbook", "market": "SXPBULL/USD", "type": "update", "data": {"time": 1618677891.9143763, "checksum": 710238303, "bids": [[51.125, 6.181]], "asks": [], "action": "update"}}
1618677892.0411441: {"channel": "orderbook", "market": "ZECBULL/USD", "type": "update", "data": {"time": 1618677891.9648018, "checksum": 2532265552, "bids": [[7190.0, 0.0]], "asks": [], "action": "update"}}
1618677892.0456672: {"channel": "orderbook", "market": "XRP/USD", "type": "update", "data": {"time": 1618677891.969044, "checksum": 2934517810, "bids": [], "asks": [[1.593625, 1.0], [1.594025, 1352.0], [1.624325, 0.0]], "action": "update"}}
1618677892.084666: {"channel": "orderbook", "market": "XRP/USD", "type": "update", "data": {"time": 1618677891.9944003, "checksum": 3526419546, "bids": [[1.590175, 0.0], [1.5561, 4.0]], "asks": [[1.591975, 0.0], [1.59325, 633.0]], "action": "update"}}
1618677892.1209311: {"channel": "orderbook", "market": "SXPBULL/USD", "type": "update", "data": {"time": 1618677892.0396466, "checksum": 2753171849, "bids": [[51.125, 10.175]], "asks": [], "action": "update"}}
1618677892.13075: {"channel": "orderbook", "market": "XRP/USD", "type": "update", "data": {"time": 1618677892.052799, "checksum": 1949675989, "bids": [[1.590825, 2513.0], [1.589275, 9000.0], [1.556625, 0.0], [1.5561, 0.0]], "asks": [[1.5937, 2511.0], [1.62425, 0.0]], "action": "update"}}
1618677892.198498: {"channel": "orderbook", "market": "XRP/USD", "type": "update", "data": {"time": 1618677892.1244078, "checksum": 2221657496, "bids": [], "asks": [[1.593575, 1424.0], [1.6239, 0.0]], "action": "update"}}
1618677892.2661278: {"channel": "orderbook", "market": "ZECBULL/USD", "type": "update", "data": {"time": 1618677892.1928868, "checksum": 1364779984, "bids": [[7212.5, 1e-05]], "asks": [], "action": "update"}}
1618677892.271631: {"channel": "orderbook", "market": "XRP/USD", "type": "update", "data": {"time": 1618677892.1771562, "checksum": 945229360, "bids": [], "asks": [[1.593, 633.0], [1.59325, 0.0]], "action": "update"}}
1618677892.271789: {"channel": "orderbook", "market": "SXPBULL/USD", "type": "update", "data": {"time": 1618677892.1809394, "checksum": 710238303, "bids": [[51.125, 6.181]], "asks": [], "action": "update"}}
1618677892.293731: {"channel": "orderbook", "market": "XRP/USD", "type": "update", "data": {"time": 1618677892.215839, "checksum": 498504111, "bids": [[1.590825, 0.0], [1.589275, 0.0], [1.556625, 1.0], [1.5561, 4.0]], "asks": [[1.599, 1686.0], [1.6235, 0.0]], "action": "update"}}
1618677892.302048: {"channel": "orderbook", "market": "NVDA-0625", "type": "update", "data": {"time": 1618677892.2233744, "checksum": 3644189371, "bids": [], "asks": [], "action": "update"}}
1618677892.3119109: {"channel": "orderbook", "market": "AMD/USD", "type": "update", "data": {"time": 1618677892.2353067, "checksum": 1935389369, "bids": [], "asks": [], "action": "update"}}
1618677892.362186: {"channel": "orderbook", "market": "SUSHIBEAR/USD", "type": "update", "data": {"time": 1618677892.2742095, "checksum": 1951180648, "bids": [], "asks": [], "action": "update"}}
1618677892.374105: {"channel": "orderbook", "market": "ZECBULL/USD", "type": "update", "data": {"time": 1618677892.2966113, "checksum": 1364779984, "bids": [], "asks": [], "action": "update"}}
1618677892.387376: {"channel": "orderbook", "market": "XRP/USD", "type": "update", "data": {"time": 1618677892.3125448, "checksum": 367724053, "bids": [[1.590975, 0.0], [1.590525, 2514.0]], "asks": [[1.5921, 1100.0], [1.62335, 0.0]], "action": "update"}}
1618677892.427558: {"channel": "orderbook", "market": "SXPBULL/USD", "type": "update", "data": {"time": 1618677892.337117, "checksum": 2753171849, "bids": [[51.125, 10.175]], "asks": [], "action": "update"}}
1618677892.4431648: {"channel": "orderbook", "market": "XRP/USD", "type": "update", "data": {"time": 1618677892.3610582, "checksum": 4260937951, "bids": [[1.5908, 0.0], [1.589775, 0.0], [1.55565, 2.0], [1.5554, 1.0]], "asks": [], "action": "update"}}
1618677892.463893: {"channel": "orderbook", "market": "XRP/USD", "type": "update", "data": {"time": 1618677892.387412, "checksum": 3471030700, "bids": [[1.58995, 633.0], [1.5554, 0.0]], "asks": [], "action": "update"}}
1618677892.479264: {"channel": "orderbook", "market": "SXPBULL/USD", "type": "update", "data": {"time": 1618677892.3906815, "checksum": 302351609, "bids": [[51.675, 41.468]], "asks": [[52.25, 0.732]], "action": "update"}}
1618677892.517976: {"channel": "orderbook", "market": "XRP/USD", "type": "update", "data": {"time": 1618677892.4363143, "checksum": 1191959325, "bids": [], "asks": [[1.593225, 3480.0], [1.623175, 0.0]], "action": "update"}}
1618677892.518076: {"channel": "orderbook", "market": "SXPBULL/USD", "type": "update", "data": {"time": 1618677892.437174, "checksum": 1405373219, "bids": [], "asks": [[52.4, 45.122]], "action": "update"}}
1618677892.544922: {"channel": "orderbook", "market": "AKRO/USD", "type": "update", "data": {"time": 1618677892.4601555, "checksum": 726621347, "bids": [], "asks": [], "action": "update"}}
1618677892.595806: {"channel": "orderbook", "market": "ZECBULL/USD", "type": "update", "data": {"time": 1618677892.5182242, "checksum": 1448799361, "bids": [[7157.5, 2.38639]], "asks": [], "action": "update"}}
1618677892.621017: {"channel": "orderbook", "market": "XRP/USD", "type": "update", "data": {"time": 1618677892.5400422, "checksum": 952356619, "bids": [[1.590775, 1632.0]], "asks": [[1.592125, 7.0]], "action": "update"}}
1618677892.657139: {"channel": "orderbook", "market": "XRP/USD", "type": "update", "data": {"time": 1618677892.5635753, "checksum": 1226593742, "bids": [[1.590775, 532.0]], "asks": [], "action": "update"}}
1618677892.6572511: {"channel": "orderbook", "market": "PAXG/USD", "type": "update", "data": {"time": 1618677892.5678976, "checksum": 2811656200, "bids": [], "asks": [], "action": "update"}}
1618677892.6810749: {"channel": "orderbook", "market": "XRP/USD", "type": "update", "data": {"time": 1618677892.5876753, "checksum": 2643640240, "bids": [[1.5908, 1100.0], [1.55565, 0.0]], "asks": [], "action": "update"}}
1618677892.707119: {"channel": "orderbook", "market": "XRP/USD", "type": "update", "data": {"time": 1618677892.613362, "checksum": 3153993998, "bids": [], "asks": [[1.593575, 0.0], [1.5945, 1515.0], [1.623175, 2.0]], "action": "update"}}
1618677892.707296: {"channel": "orderbook", "market": "ZECBULL/USD", "type": "update", "data": {"time": 1618677892.62327, "checksum": 935696540, "bids": [[6557.5, 0.0]], "asks": [], "action": "update"}}
1618677892.721024: {"channel": "orderbook", "market": "XRP/USD", "type": "update", "data": {"time": 1618677892.6363702, "checksum": 1627380334, "bids": [], "asks": [[1.593225, 0.0], [1.62335, 8051.0]], "action": "update"}}
1618677892.750975: {"channel": "orderbook", "market": "XRP/USD", "type": "update", "data": {"time": 1618677892.6646423, "checksum": 2926010373, "bids": [[1.588925, 273237.0]], "asks": [[1.5921, 0.0], [1.593, 0.0], [1.594025, 0.0], [1.5942, 5390.0], [1.6235, 4.0], [1.6239, 1.0]], "action": "update"}}
1618677892.770498: {"channel": "orderbook", "market": "THETAHEDGE/USD", "type": "update", "data": {"time": 1618677892.6886725, "checksum": 309983746, "bids": [], "asks": [], "action": "update"}}
1618677892.784846: {"channel": "orderbook", "market": "XRP/USD", "type": "update", "data": {"time": 1618677892.70658, "checksum": 2100680901, "bids": [[1.59045, 4980.0], [1.5561, 0.0]], "asks": [[1.593225, 633.0], [1.6239, 0.0]], "action": "update"}}
1618677892.79992: {"channel": "orderbook", "market": "XRP/USD", "type": "update", "data": {"time": 1618677892.7241395, "checksum": 1697149549, "bids": [], "asks": [[1.5942, 0.0], [1.59445, 0.0], [1.6239, 1.0], [1.62425, 4.0]], "action": "update"}}
1618677892.94221: {"channel": "orderbook", "market": "BTC-MOVE-WK-0507", "type": "update", "data": {"time": 1618677892.8696556, "checksum": 901794806, "bids": [], "asks": [], "action": "update"}}
1618677892.947082: {"channel": "orderbook", "market": "XRP/USD", "type": "update", "data": {"time": 1618677892.8017497, "checksum": 2595804728, "bids": [], "asks": [[1.592125, 0.0], [1.595025, 264743.0]], "action": "update"}}
1618677892.960277: {"channel": "orderbook", "market": "SUSHIBEAR/USD", "type": "update", "data": {"time": 1618677892.8804648, "checksum": 2465841864, "bids": [[1.17e-05, 2100000.0]], "asks": [], "action": "update"}}
1618677892.965645: {"channel": "orderbook", "market": "XRP/USD", "type": "update", "data": {"time": 1618677892.8853588, "checksum": 2126526518, "bids": [[1.589325, 15474.0]], "asks": [[1.593225, 0.0], [1.593625, 634.0], [1.624325, 6.0]], "action": "update"}}
1618677892.989696: {"channel": "orderbook", "market": "XRP/USD", "type": "update", "data": {"time": 1618677892.9068007, "checksum": 752984745, "bids": [[1.590525, 0.0], [1.5561, 4.0]], "asks": [[1.5937, 0.0], [1.6256, 1.0]], "action": "update"}}
1618677893.0141702: {"channel": "orderbook", "market": "AKRO/USD", "type": "update", "data": {"time": 1618677892.9320717, "checksum": 179181705, "bids": [[0.068135, 0.0], [0.059365, 38.0]], "asks": [], "action": "update"}}
1618677893.0587158: {"channel": "orderbook", "market": "SUSHIBEAR/USD", "type": "update", "data": {"time": 1618677892.9810376, "checksum": 1734204273, "bids": [[1.165e-05, 8660000.0]], "asks": [], "action": "update"}}
1618677893.0619469: {"channel": "orderbook", "market": "XRP/USD", "type": "update", "data": {"time": 1618677892.9832575, "checksum": 3283871974, "bids": [], "asks": [[1.59275, 1100.0], [1.594, 4911.0], [1.6256, 0.0]], "action": "update"}}
1618677893.101362: {"channel": "orderbook", "market": "XRP/USD", "type": "update", "data": {"time": 1618677893.0189233, "checksum": 824974306, "bids": [[1.568575, 0.0], [1.55565, 2.0]], "asks": [], "action": "update"}}
1618677893.111098: {"channel": "orderbook", "market": "XRP/USD", "type": "update", "data": {"time": 1618677893.03553, "checksum": 1571339929, "bids": [[1.591325, 2512.0], [1.55565, 0.0]], "asks": [], "action": "update"}}
1618677893.1443782: {"channel": "orderbook", "market": "XRP/USD", "type": "update", "data": {"time": 1618677893.0590544, "checksum": 381540934, "bids": [], "asks": [[1.5942, 2510.0], [1.624325, 0.0]], "action": "update"}}
1618677893.158358: {"channel": "orderbook", "market": "XRP/USD", "type": "update", "data": {"time": 1618677893.0844486, "checksum": 1271489451, "bids": [[1.591175, 1453.0], [1.5908, 0.0]], "asks": [[1.59525, 5380.0], [1.62425, 0.0]], "action": "update"}}
1618677893.213792: {"channel": "orderbook", "market": "XRP/USD", "type": "update", "data": {"time": 1618677893.1348302, "checksum": 2575216594, "bids": [[1.5885, 329337.0], [1.5561, 0.0]], "asks": [[1.595925, 1332.0], [1.6239, 0.0]], "action": "update"}}
1618677893.279424: {"channel": "orderbook", "market": "XRP/USD", "type": "update", "data": {"time": 1618677893.176217, "checksum": 3904211598, "bids": [[1.59135, 1100.0], [1.58995, 0.0], [1.5882, 0.0], [1.5561, 4.0]], "asks": [], "action": "update"}}
1618677893.306957: {"channel": "orderbook", "market": "XRP/USD", "type": "update", "data": {"time": 1618677893.2213078, "checksum": 894132052, "bids": [[1.5909, 633.0], [1.5561, 0.0]], "asks": [], "action": "update"}}
1618677893.3294349: {"channel": "orderbook", "market": "AMD/USD", "type": "update", "data": {"time": 1618677893.2553298, "checksum": 1935389369, "bids": [], "asks": [], "action": "update"}}
1618677893.350927: {"channel": "orderbook", "market": "NVDA-0625", "type": "update", "data": {"time": 1618677893.2658308, "checksum": 3644189371, "bids": [], "asks": [], "action": "update"}}
1618677893.380826: {"channel": "orderbook", "market": "XRP/USD", "type": "update", "data": {"time": 1618677893.2891915, "checksum": 4195630797, "bids": [[1.58935, 36765.0], [1.589325, 6474.0], [1.588875, 0.0]], "asks": [], "action": "update"}}
1618677893.3809621: {"channel": "orderbook", "market": "SUSHIBEAR/USD", "type": "update", "data": {"time": 1618677893.297579, "checksum": 1734204273, "bids": [], "asks": [], "action": "update"}}
1618677893.392019: {"channel": "orderbook", "market": "XRP/USD", "type": "update", "data": {"time": 1618677893.3123713, "checksum": 2568364936, "bids": [[1.589325, 10149.0]], "asks": [], "action": "update"}}
1618677893.402303: {"channel": "orderbook", "market": "ZECBULL/USD", "type": "update", "data": {"time": 1618677893.3254905, "checksum": 935696540, "bids": [], "asks": [], "action": "update"}}
1618677893.435945: {"channel": "orderbook", "market": "XRP/USD", "type": "update", "data": {"time": 1618677893.362475, "checksum": 445779474, "bids": [[1.5909, 0.0], [1.5561, 4.0]], "asks": [], "action": "update"}}
1618677893.463945: {"channel": "orderbook", "market": "XRP/USD", "type": "update", "data": {"time": 1618677893.387839, "checksum": 2024164491, "bids": [[1.59005, 633.0], [1.58935, 0.0]], "asks": [], "action": "update"}}
1618677893.488158: {"channel": "orderbook", "market": "XRP/USD", "type": "update", "data": {"time": 1618677893.4120224, "checksum": 2234400708, "bids": [[1.571425, 292.0], [1.5561, 0.0]], "asks": [], "action": "update"}}
1618677893.509672: {"channel": "orderbook", "market": "SXPBULL/USD", "type": "update", "data": {"time": 1618677893.396447, "checksum": 1049501695, "bids": [[51.125, 6.181], [51.075, 8.484]], "asks": [[51.775, 0.0], [52.4, 45.316], [52.425, 2.327], [54.3, 6.23]], "action": "update"}}
1618677893.5764322: {"channel": "orderbook", "market": "AKRO/USD", "type": "update", "data": {"time": 1618677893.4848225, "checksum": 179181705, "bids": [], "asks": [], "action": "update"}}
1618677893.6751108: {"channel": "orderbook", "market": "PAXG/USD", "type": "update", "data": {"time": 1618677893.5960681, "checksum": 2811656200, "bids": [], "asks": [], "action": "update"}}
1618677893.744328: {"channel": "orderbook", "market": "ZECBULL/USD", "type": "update", "data": {"time": 1618677893.6665282, "checksum": 786604003, "bids": [[7147.5, 0.0]], "asks": [[7375.0, 0.0]], "action": "update"}}
1618677893.748307: {"channel": "orderbook", "market": "XRP/USD", "type": "update", "data": {"time": 1618677893.6675024, "checksum": 4097352595, "bids": [[1.59005, 0.0], [1.5561, 4.0]], "asks": [[1.593625, 1.0]], "action": "update"}}
1618677893.766486: {"channel": "orderbook", "market": "XRP/USD", "type": "update", "data": {"time": 1618677893.6893208, "checksum": 892707146, "bids": [[1.590475, 633.0], [1.5561, 0.0]], "asks": [[1.5934, 633.0], [1.6235, 0.0]], "action": "update"}}
1618677893.772164: {"channel": "orderbook", "market": "THETAHEDGE/USD", "type": "update", "data": {"time": 1618677893.6994703, "checksum": 309983746, "bids": [], "asks": [], "action": "update"}}
1618677893.790143: {"channel": "orderbook", "market": "XRP/USD", "type": "update", "data": {"time": 1618677893.7158687, "checksum": 2857144445, "bids": [], "asks": [[1.5921, 5.0], [1.62335, 0.0]], "action": "update"}}
1618677893.889251: {"channel": "orderbook", "market": "XRP/USD", "type": "update", "data": {"time": 1618677893.8121302, "checksum": 2857144445, "bids": [], "asks": [], "action": "update"}}
1618677893.9422321: {"channel": "orderbook", "market": "XRP/USD", "type": "update", "data": {"time": 1618677893.866459, "checksum": 607381097, "bids": [[1.591325, 0.0], [1.591175, 0.0], [1.5561, 4.0], [1.55565, 2.0]], "asks": [[1.5942, 0.0], [1.59455, 1394.0]], "action": "update"}}
1618677893.961791: {"channel": "orderbook", "market": "XRP/USD", "type": "update", "data": {"time": 1618677893.888001, "checksum": 4014551741, "bids": [[1.59135, 0.0], [1.5554, 1.0]], "asks": [[1.595925, 0.0], [1.62335, 8051.0]], "action": "update"}}
1618677893.963973: {"channel": "orderbook", "market": "ZECBULL/USD", "type": "update", "data": {"time": 1618677893.8907244, "checksum": 4201903391, "bids": [], "asks": [[7382.5, 0.02774]], "action": "update"}}
1618677893.967116: {"channel": "orderbook", "market": "BTC-MOVE-WK-0507", "type": "update", "data": {"time": 1618677893.8943539, "checksum": 901794806, "bids": [], "asks": [], "action": "update"}}
1618677893.986728: {"channel": "orderbook", "market": "XRP/USD", "type": "update", "data": {"time": 1618677893.913507, "checksum": 3456029368, "bids": [], "asks": [[1.5941, 4330.0], [1.62335, 0.0]], "action": "update"}}
1618677894.0039349: {"channel": "orderbook", "market": "SXPBULL/USD", "type": "update", "data": {"time": 1618677893.9247384, "checksum": 1992040503, "bids": [[51.125, 10.175]], "asks": [], "action": "update"}}
1618677894.024241: {"channel": "orderbook", "market": "XRP/USD", "type": "update", "data": {"time": 1618677893.9463913, "checksum": 2534707990, "bids": [[1.59045, 0.0], [1.5553, 6.0]], "asks": [[1.59275, 0.0], [1.594075, 1385.0]], "action": "update"}}
1618677894.040287: {"channel": "orderbook", "market": "XRP/USD", "type": "update", "data": {"time": 1618677893.963594, "checksum": 137266452, "bids": [[1.590475, 0.0], [1.589725, 0.0], [1.55525, 1.0], [1.5542, 1412.0]], "asks": [[1.5933, 2512.0], [1.5934, 0.0], [1.595025, 0.0], [1.62335, 8051.0]], "action": "update"}}
1618677894.0884259: {"channel": "orderbook", "market": "XRP/USD", "type": "update", "data": {"time": 1618677894.0025284, "checksum": 3583166393, "bids": [[1.590425, 2514.0], [1.58995, 633.0], [1.5898, 0.0], [1.588925, 4371.0], [1.5542, 0.0]], "asks": [[1.592025, 1100.0], [1.593025, 633.0], [1.623175, 0.0], [1.62335, 0.0]], "action": "update"}}
1618677894.10071: {"channel": "orderbook", "market": "XRP/USD", "type": "update", "data": {"time": 1618677894.019001, "checksum": 3765050092, "bids": [], "asks": [[1.595175, 0.0], [1.623175, 2.0]], "action": "update"}}
1618677894.13635: {"channel": "orderbook", "market": "SUSHIBEAR/USD", "type": "update", "data": {"time": 1618677894.0624995, "checksum": 2465841864, "bids": [[1.165e-05, 0.0]], "asks": [], "action": "update"}}
1618677894.146989: {"channel": "orderbook", "market": "XRP/USD", "type": "update", "data": {"time": 1618677894.0678163, "checksum": 1694920792, "bids": [], "asks": [[1.593025, 0.0], [1.5933, 0.0], [1.62335, 8051.0], [1.6235, 4.0]], "action": "update"}}
1618677894.1843379: {"channel": "orderbook", "market": "XRP/USD", "type": "update", "data": {"time": 1618677894.1075287, "checksum": 2176649757, "bids": [[1.590425, 0.0], [1.589325, 8765.0], [1.58895, 3527.0]], "asks": [], "action": "update"}}
1618677894.2175: {"channel": "orderbook", "market": "SUSHIBEAR/USD", "type": "update", "data": {"time": 1618677894.1430385, "checksum": 1951180648, "bids": [[1.17e-05, 10760000.0]], "asks": [], "action": "update"}}
1618677894.227395: {"channel": "orderbook", "market": "XRP/USD", "type": "update", "data": {"time": 1618677894.1502042, "checksum": 148441520, "bids": [], "asks": [[1.5921, 0.0], [1.5934, 633.0]], "action": "update"}}
1618677894.255352: {"channel": "orderbook", "market": "SXPBULL/USD", "type": "update", "data": {"time": 1618677894.1606026, "checksum": 1049501695, "bids": [[51.125, 6.181]], "asks": [], "action": "update"}}
1618677894.285794: {"channel": "orderbook", "market": "XRP/USD", "type": "update", "data": {"time": 1618677894.2095363, "checksum": 2832043132, "bids": [[1.589325, 5090.0]], "asks": [[1.592025, 0.0], [1.6239, 1.0]], "action": "update"}}
1618677894.308233: {"channel": "orderbook", "market": "XRP/USD", "type": "update", "data": {"time": 1618677894.229781, "checksum": 2551086686, "bids": [], "asks": [[1.5926, 1100.0], [1.5928, 2513.0], [1.5934, 0.0], [1.6239, 0.0]], "action": "update"}}
1618677894.324358: {"channel": "orderbook", "market": "XRP/USD", "type": "update", "data": {"time": 1618677894.250306, "checksum": 774324982, "bids": [[1.589925, 2514.0], [1.55525, 0.0]], "asks": [[1.5927, 4670.0], [1.6235, 0.0]], "action": "update"}}
1618677894.357022: {"channel": "orderbook", "market": "AMD/USD", "type": "update", "data": {"time": 1618677894.281813, "checksum": 1935389369, "bids": [], "asks": [], "action": "update"}}
1618677894.375144: {"channel": "orderbook", "market": "XRP/USD", "type": "update", "data": {"time": 1618677894.299084, "checksum": 871956427, "bids": [], "asks": [[1.595125, 3675.0], [1.62335, 0.0]], "action": "update"}}
1618677894.394944: {"channel": "orderbook", "market": "SUSHIBEAR/USD", "type": "update", "data": {"time": 1618677894.3195245, "checksum": 1951180648, "bids": [], "asks": [], "action": "update"}}
1618677894.3980339: {"channel": "orderbook", "market": "NVDA-0625", "type": "update", "data": {"time": 1618677894.3172324, "checksum": 3644189371, "bids": [], "asks": [], "action": "update"}}
1618677894.405487: {"channel": "orderbook", "market": "XRP/USD", "type": "update", "data": {"time": 1618677894.3281317, "checksum": 1452640145, "bids": [[1.588525, 3675.0], [1.5553, 0.0]], "asks": [[1.592575, 633.0], [1.623175, 0.0]], "action": "update"}}
1618677894.4524522: {"channel": "orderbook", "market": "XRP/USD", "type": "update", "data": {"time": 1618677894.3787887, "checksum": 2336363571, "bids": [[1.58915, 353444.0], [1.5554, 0.0]], "asks": [[1.5926, 0.0], [1.594, 6621.0], [1.623175, 2.0]], "action": "update"}}
1618677894.458414: {"channel": "orderbook", "market": "ZECBULL/USD", "type": "update", "data": {"time": 1618677894.3738291, "checksum": 3075484519, "bids": [[7205.0, 0.0]], "asks": [], "action": "update"}}
1618677894.47587: {"channel": "orderbook", "market": "XRP/USD", "type": "update", "data": {"time": 1618677894.3999145, "checksum": 1195776367, "bids": [], "asks": [[1.5924, 1100.0], [1.5986, 0.0]], "action": "update"}}
1618677894.5215979: {"channel": "orderbook", "market": "XRP/USD", "type": "update", "data": {"time": 1618677894.448056, "checksum": 208890569, "bids": [[1.58995, 0.0], [1.589925, 0.0], [1.5554, 1.0], [1.5553, 6.0]], "asks": [[1.5928, 0.0], [1.62335, 8051.0]], "action": "update"}}
1618677894.5364769: {"channel": "orderbook", "market": "SXPBULL/USD", "type": "update", "data": {"time": 1618677894.4450254, "checksum": 1049501695, "bids": [], "asks": [], "action": "update"}}
1618677894.556885: {"channel": "orderbook", "market": "XRP/USD", "type": "update", "data": {"time": 1618677894.4808948, "checksum": 2681607933, "bids": [[1.589725, 633.0], [1.5553, 0.0]], "asks": [[1.592575, 0.0], [1.5927, 0.0], [1.6235, 4.0], [1.6239, 1.0]], "action": "update"}}
1618677894.570862: {"channel": "orderbook", "market": "XRP/USD", "type": "update", "data": {"time": 1618677894.497745, "checksum": 573177570, "bids": [], "asks": [[1.592375, 633.0], [1.6239, 0.0]], "action": "update"}}
1618677894.59532: {"channel": "orderbook", "market": "AKRO/USD", "type": "update", "data": {"time": 1618677894.510963, "checksum": 179181705, "bids": [], "asks": [], "action": "update"}}
1618677894.60052: {"channel": "orderbook", "market": "XRP/USD", "type": "update", "data": {"time": 1618677894.5244637, "checksum": 2987821020, "bids": [[1.590425, 2514.0], [1.5554, 0.0]], "asks": [[1.5924, 0.0], [1.5934, 2512.0]], "action": "update"}}
1618677894.628576: {"channel": "orderbook", "market": "XRP/USD", "type": "update", "data": {"time": 1618677894.5528193, "checksum": 4170960512, "bids": [[1.5815, 0.0], [1.5554, 1.0]], "asks": [], "action": "update"}}
1618677894.654942: {"channel": "orderbook", "market": "XRP/USD", "type": "update", "data": {"time": 1618677894.5772784, "checksum": 2676131066, "bids": [], "asks": [[1.5922, 1100.0], [1.595125, 0.0]], "action": "update"}}
1618677894.69716: {"channel": "orderbook", "market": "XRP/USD", "type": "update", "data": {"time": 1618677894.622947, "checksum": 2574990469, "bids": [], "asks": [[1.59795, 188.0], [1.6235, 0.0]], "action": "update"}}
1618677894.7093: {"channel": "orderbook", "market": "PAXG/USD", "type": "update", "data": {"time": 1618677894.6314385, "checksum": 2811656200, "bids": [], "asks": [], "action": "update"}}
1618677894.724195: {"channel": "orderbook", "market": "XRP/USD", "type": "update", "data": {"time": 1618677894.647684, "checksum": 3155397063, "bids": [], "asks": [[1.592375, 0.0], [1.6235, 4.0]], "action": "update"}}
1618677894.727155: {"channel": "orderbook", "market": "SXPBULL/USD", "type": "update", "data": {"time": 1618677894.6474628, "checksum": 1992040503, "bids": [[51.125, 10.175]], "asks": [], "action": "update"}}
1618677894.747726: {"channel": "orderbook", "market": "XRP/USD", "type": "update", "data": {"time": 1618677894.6734774, "checksum": 4024995006, "bids": [[1.590775, 0.0], [1.5553, 6.0]], "asks": [[1.592175, 633.0], [1.5922, 0.0], [1.5934, 0.0], [1.598775, 0.0], [1.6239, 1.0], [1.62425, 4.0]], "action": "update"}}
1618677894.801097: {"channel": "orderbook", "market": "XRP/USD", "type": "update", "data": {"time": 1618677894.722583, "checksum": 1936530897, "bids": [], "asks": [[1.5926, 1100.0], [1.598925, 2.0], [1.62425, 0.0]], "action": "update"}}
1618677894.8012512: {"channel": "orderbook", "market": "THETAHEDGE/USD", "type": "update", "data": {"time": 1618677894.7273352, "checksum": 309983746, "bids": [], "asks": [], "action": "update"}}
1618677894.806199: {"channel": "orderbook", "market": "SXPBULL/USD", "type": "update", "data": {"time": 1618677894.7230206, "checksum": 1049501695, "bids": [[51.125, 6.181]], "asks": [], "action": "update"}}
1618677894.808185: {"channel": "orderbook", "market": "AKRO/USD", "type": "update", "data": {"time": 1618677894.7332819, "checksum": 902618223, "bids": [[0.068125, 38091.0], [0.059365, 0.0]], "asks": [], "action": "update"}}
1618677894.836119: {"channel": "orderbook", "market": "XRP/USD", "type": "update", "data": {"time": 1618677894.7568698, "checksum": 202274118, "bids": [[1.5906, 1100.0], [1.5865, 1634.0], [1.5554, 0.0], [1.5553, 0.0]], "asks": [[1.592, 1100.0], [1.592175, 0.0], [1.5926, 0.0], [1.5932, 2512.0], [1.59525, 272504.0]], "action": "update"}}
1618677894.851271: {"channel": "orderbook", "market": "XRP/USD", "type": "update", "data": {"time": 1618677894.775242, "checksum": 1573595837, "bids": [[1.589, 9000.0], [1.55565, 0.0]], "asks": [[1.599, 0.0], [1.62425, 4.0]], "action": "update"}}
1618677894.876279: {"channel": "orderbook", "market": "XRP/USD", "type": "update", "data": {"time": 1618677894.8002071, "checksum": 2662729556, "bids": [], "asks": [[1.592, 0.0], [1.59335, 633.0]], "action": "update"}}
1618677894.879672: {"channel": "orderbook", "market": "SXPBULL/USD", "type": "update", "data": {"time": 1618677894.7983215, "checksum": 2638630211, "bids": [[51.075, 39.982]], "asks": [], "action": "update"}}
1618677894.905261: {"channel": "orderbook", "market": "XRP/USD", "type": "update", "data": {"time": 1618677894.8243012, "checksum": 809205656, "bids": [[1.589, 0.0], [1.55565, 2.0]], "asks": [], "action": "update"}}
1618677894.933451: {"channel": "orderbook", "market": "XRP/USD", "type": "update", "data": {"time": 1618677894.8578148, "checksum": 156984931, "bids": [], "asks": [[1.5926, 1100.0], [1.62425, 0.0]], "action": "update"}}
1618677894.9497101: {"channel": "orderbook", "market": "ZECBULL/USD", "type": "update", "data": {"time": 1618677894.8710637, "checksum": 2277274239, "bids": [[7157.5, 4.87578]], "asks": [], "action": "update"}}
1618677894.972331: {"channel": "orderbook", "market": "SXPBULL/USD", "type": "update", "data": {"time": 1618677894.8719654, "checksum": 1049501695, "bids": [[51.075, 8.484]], "asks": [], "action": "update"}}
1618677894.974744: {"channel": "orderbook", "market": "XRP/USD", "type": "update", "data": {"time": 1618677894.8984518, "checksum": 2089810928, "bids": [[1.5906, 6690.0], [1.589575, 1391.0], [1.55565, 0.0]], "asks": [[1.598325, 157.0], [1.6239, 0.0]], "action": "update"}}
1618677894.986552: {"channel": "orderbook", "market": "BTC-MOVE-WK-0507", "type": "update", "data": {"time": 1618677894.910158, "checksum": 901794806, "bids": [], "asks": [], "action": "update"}}
1618677895.025701: {"channel": "orderbook", "market": "XRP/USD", "type": "update", "data": {"time": 1618677894.9509451, "checksum": 3017477261, "bids": [], "asks": [[1.59275, 5.0], [1.5932, 0.0], [1.59365, 1409.0], [1.59825, 188.0], [1.62335, 0.0], [1.6235, 0.0]], "action": "update"}}
1618677895.033003: {"channel": "orderbook", "market": "SXPBULL/USD", "type": "update", "data": {"time": 1618677894.9482596, "checksum": 2752926431, "bids": [[51.1, 122.593]], "asks": [], "action": "update"}}
1618677895.105417: {"channel": "orderbook", "market": "XRP/USD", "type": "update", "data": {"time": 1618677895.004431, "checksum": 2366247719, "bids": [[1.571425, 0.0], [1.55565, 2.0]], "asks": [], "action": "update"}}
1618677895.10553: {"channel": "orderbook", "market": "SXPBULL/USD", "type": "update", "data": {"time": 1618677895.0049365, "checksum": 1049501695, "bids": [[51.1, 0.441]], "asks": [], "action": "update"}}
1618677895.1556768: {"channel": "orderbook", "market": "XRP/USD", "type": "update", "data": {"time": 1618677895.0807729, "checksum": 2910991809, "bids": [], "asks": [[1.593075, 633.0], [1.59335, 0.0]], "action": "update"}}
1618677895.171489: {"channel": "orderbook", "market": "SXPBULL/USD", "type": "update", "data": {"time": 1618677895.0843055, "checksum": 1992040503, "bids": [[51.125, 10.175]], "asks": [], "action": "update"}}
1618677895.1841311: {"channel": "orderbook", "market": "XRP/USD", "type": "update", "data": {"time": 1618677895.1050205, "checksum": 1594991066, "bids": [], "asks": [[1.5935, 2512.0], [1.623175, 0.0]], "action": "update"}}
1618677895.208425: {"channel": "orderbook", "market": "XRP/USD", "type": "update", "data": {"time": 1618677895.1301687, "checksum": 394400031, "bids": [], "asks": [[1.60015, 0.0], [1.623175, 2.0]], "action": "update"}}
1618677895.259321: {"channel": "orderbook", "market": "SXPBULL/USD", "type": "update", "data": {"time": 1618677895.1690738, "checksum": 1049501695, "bids": [[51.125, 6.181]], "asks": [], "action": "update"}}
1618677895.298215: {"channel": "orderbook", "market": "XRP/USD", "type": "update", "data": {"time": 1618677895.2049143, "checksum": 933091860, "bids": [[1.589375, 633.0], [1.55565, 0.0]], "asks": [], "action": "update"}}
1618677895.3354602: {"channel": "orderbook", "market": "XRP/USD", "type": "update", "data": {"time": 1618677895.2580626, "checksum": 3835672573, "bids": [[1.589725, 0.0], [1.55565, 2.0]], "asks": [[1.595225, 1685.0], [1.623175, 0.0]], "action": "update"}}
1618677895.38306: {"channel": "orderbook", "market": "XRP/USD", "type": "update", "data": {"time": 1618677895.308236, "checksum": 2756550815, "bids": [[1.58875, 1382.0], [1.55565, 0.0]], "asks": [[1.5935, 0.0], [1.623175, 2.0]], "action": "update"}}
1618677895.3832588: {"channel": "orderbook", "market": "AMD/USD", "type": "update", "data": {"time": 1618677895.3093977, "checksum": 1935389369, "bids": [], "asks": [], "action": "update"}}
1618677895.389803: {"channel": "orderbook", "market": "SXPBULL/USD", "type": "update", "data": {"time": 1618677895.3037653, "checksum": 2752926431, "bids": [[51.1, 122.593]], "asks": [], "action": "update"}}
1618677895.3951092: {"channel": "orderbook", "market": "PAXG/USD", "type": "update", "data": {"time": 1618677895.3188303, "checksum": 318214429, "bids": [[1766.9, 1.4147]], "asks": [], "action": "update"}}
1618677895.421074: {"channel": "orderbook", "market": "SUSHIBEAR/USD", "type": "update", "data": {"time": 1618677895.3399324, "checksum": 1951180648, "bids": [], "asks": [], "action": "update"}}
1618677895.425879: {"channel": "orderbook", "market": "SXPBULL/USD", "type": "update", "data": {"time": 1618677895.3460498, "checksum": 1049501695, "bids": [[51.1, 0.441]], "asks": [], "action": "update"}}
1618677895.430434: {"channel": "orderbook", "market": "XRP/USD", "type": "update", "data": {"time": 1618677895.3544447, "checksum": 1608358416, "bids": [[1.573025, 292.0], [1.5561, 0.0]], "asks": [[1.59275, 0.0], [1.62335, 8051.0]], "action": "update"}}
1618677895.4346392: {"channel": "orderbook", "market": "NVDA-0625", "type": "update", "data": {"time": 1618677895.3574383, "checksum": 3644189371, "bids": [], "asks": [], "action": "update"}}
1618677895.475683: {"channel": "orderbook", "market": "XRP/USD", "type": "update", "data": {"time": 1618677895.400981, "checksum": 2050214131, "bids": [[1.589575, 0.0], [1.589, 9000.0]], "asks": [[1.593275, 1377.0], [1.62335, 0.0]], "action": "update"}}
1618677895.484921: {"channel": "orderbook", "market": "ZECBULL/USD", "type": "update", "data": {"time": 1618677895.4100928, "checksum": 2277274239, "bids": [], "asks": [], "action": "update"}}
1618677895.496913: {"channel": "orderbook", "market": "PAXG/USD", "type": "update", "data": {"time": 1618677895.4203424, "checksum": 852366897, "bids": [[1766.8, 0.06], [1729.6, 0.0]], "asks": [], "action": "update"}}
1618677895.504744: {"channel": "orderbook", "market": "XRP/USD", "type": "update", "data": {"time": 1618677895.4300017, "checksum": 87813584, "bids": [], "asks": [[1.600325, 20.0], [1.623175, 0.0]], "action": "update"}}
1618677895.537808: {"channel": "orderbook", "market": "XRP/USD", "type": "update", "data": {"time": 1618677895.4507937, "checksum": 3091670760, "bids": [[1.590425, 0.0], [1.5561, 4.0]], "asks": [], "action": "update"}}
1618677895.5629609: {"channel": "orderbook", "market": "XRP/USD", "type": "update", "data": {"time": 1618677895.4840662, "checksum": 1041615438, "bids": [[1.589, 0.0], [1.55565, 2.0]], "asks": [[1.592575, 633.0], [1.593075, 0.0], [1.5932, 2512.0], [1.623, 0.0]], "action": "update"}}
1618677895.596543: {"channel": "orderbook", "market": "XRP/USD", "type": "update", "data": {"time": 1618677895.5032377, "checksum": 4074316308, "bids": [[1.582, 0.0], [1.5554, 1.0]], "asks": [], "action": "update"}}
1618677895.596691: {"channel": "orderbook", "market": "SXPBULL/USD", "type": "update", "data": {"time": 1618677895.4757502, "checksum": 1992040503, "bids": [[51.125, 10.175]], "asks": [], "action": "update"}}
1618677895.615822: {"channel": "orderbook", "market": "XRP/USD", "type": "update", "data": {"time": 1618677895.525241, "checksum": 244277541, "bids": [[1.5906, 5590.0], [1.589375, 0.0], [1.5553, 6.0]], "asks": [[1.5926, 0.0], [1.623, 8078.0]], "action": "update"}}
1618677895.616054: {"channel": "orderbook", "market": "AKRO/USD", "type": "update", "data": {"time": 1618677895.5332193, "checksum": 902618223, "bids": [], "asks": [], "action": "update"}}
1618677895.622754: {"channel": "orderbook", "market": "SUSHIBEAR/USD", "type": "update", "data": {"time": 1618677895.5436559, "checksum": 3682397038, "bids": [], "asks": [[1.22e-05, 8690000.0]], "action": "update"}}
1618677895.644048: {"channel": "orderbook", "market": "XRP/USD", "type": "update", "data": {"time": 1618677895.5556111, "checksum": 1575765009, "bids": [], "asks": [[1.599, 1562.0], [1.623, 0.0]], "action": "update"}}
1618677895.661363: {"channel": "orderbook", "market": "XRP/USD", "type": "update", "data": {"time": 1618677895.5754018, "checksum": 446338892, "bids": [], "asks": [[1.5924, 1100.0], [1.6225, 0.0]], "action": "update"}}
1618677895.699826: {"channel": "orderbook", "market": "ZECBULL/USD", "type": "update", "data": {"time": 1618677895.6254613, "checksum": 1232781522, "bids": [[7157.5, 2.48939]], "asks": [], "action": "update"}}
1618677895.699936: {"channel": "orderbook", "market": "XRP/USD", "type": "update", "data": {"time": 1618677895.626057, "checksum": 1891913714, "bids": [[1.590025, 2514.0], [1.5553, 0.0]], "asks": [[1.593025, 4980.0], [1.6215, 0.0]], "action": "update"}}
1618677895.742526: {"channel": "orderbook", "market": "PAXG/USD", "type": "update", "data": {"time": 1618677895.6628065, "checksum": 852366897, "bids": [], "asks": [], "action": "update"}}
1618677895.7506392: {"channel": "orderbook", "market": "XRP/USD", "type": "update", "data": {"time": 1618677895.675866, "checksum": 2008298021, "bids": [], "asks": [[1.592375, 633.0], [1.592575, 0.0]], "action": "update"}}
1618677895.8021939: {"channel": "orderbook", "market": "XRP/USD", "type": "update", "data": {"time": 1618677895.7271476, "checksum": 1121119447, "bids": [[1.589375, 633.0], [1.5554, 0.0]], "asks": [[1.5924, 0.0], [1.5995, 1440.0]], "action": "update"}}
1618677895.818283: {"channel": "orderbook", "market": "SXPBULL/USD", "type": "update", "data": {"time": 1618677895.7312057, "checksum": 1049501695, "bids": [[51.125, 6.181]], "asks": [], "action": "update"}}
1618677895.8267698: {"channel": "orderbook", "market": "THETAHEDGE/USD", "type": "update", "data": {"time": 1618677895.7495084, "checksum": 309983746, "bids": [], "asks": [], "action": "update"}}
1618677895.829965: {"channel": "orderbook", "market": "XRP/USD", "type": "update", "data": {"time": 1618677895.7520294, "checksum": 3825094667, "bids": [], "asks": [[1.5926, 5.0], [1.620975, 0.0]], "action": "update"}}
1618677895.8623738: {"channel": "orderbook", "market": "XRP/USD", "type": "update", "data": {"time": 1618677895.7770526, "checksum": 1482881973, "bids": [], "asks": [[1.5922, 1100.0], [1.620775, 0.0]], "action": "update"}}
1618677895.9358678: {"channel": "orderbook", "market": "XRP/USD", "type": "update", "data": {"time": 1618677895.8503878, "checksum": 1045732590, "bids": [[1.590025, 0.0], [1.5554, 1.0]], "asks": [[1.592375, 0.0], [1.593275, 0.0], [1.620775, 2.0], [1.620975, 3.0]], "action": "update"}}
1618677895.961641: {"channel": "orderbook", "market": "XRP/USD", "type": "update", "data": {"time": 1618677895.876768, "checksum": 2057450245, "bids": [], "asks": [[1.5932, 0.0], [1.6215, 6.0]], "action": "update"}}
1618677895.9617019: {"channel": "orderbook", "market": "SXPBULL/USD", "type": "update", "data": {"time": 1618677895.8771222, "checksum": 1992040503, "bids": [[51.125, 10.175]], "asks": [], "action": "update"}}
1618677896.003243: {"channel": "orderbook", "market": "XRP/USD", "type": "update", "data": {"time": 1618677895.9282663, "checksum": 1631021261, "bids": [[1.589425, 1441.0], [1.5554, 0.0]], "asks": [], "action": "update"}}
1618677896.016542: {"channel": "orderbook", "market": "BTC-MOVE-WK-0507", "type": "update", "data": {"time": 1618677895.9411461, "checksum": 901794806, "bids": [], "asks": [], "action": "update"}}
1618677896.137314: {"channel": "orderbook", "market": "XRP/USD", "type": "update", "data": {"time": 1618677896.0533776, "checksum": 1068400848, "bids": [[1.590225, 2514.0], [1.55565, 0.0]], "asks": [[1.593, 2512.0], [1.59795, 0.0]], "action": "update"}}
1618677896.137507: {"channel": "orderbook", "market": "SXPBULL/USD", "type": "update", "data": {"time": 1618677896.0534873, "checksum": 1433462880, "bids": [[51.125, 6.181]], "asks": [[52.4, 4.016]], "action": "update"}}
1618677896.1568482: {"channel": "orderbook", "market": "XRP/USD", "type": "update", "data": {"time": 1618677896.076488, "checksum": 2585979847, "bids": [], "asks": [[1.595225, 294404.0]], "action": "update"}}
1618677896.207368: {"channel": "orderbook", "market": "SXPBULL/USD", "type": "update", "data": {"time": 1618677896.12756, "checksum": 2744761437, "bids": [], "asks": [[52.225, 1.583]], "action": "update"}}
1618677896.2335958: {"channel": "orderbook", "market": "XRP/USD", "type": "update", "data": {"time": 1618677896.1557045, "checksum": 55725666, "bids": [], "asks": [[1.5926, 0.0], [1.594, 4911.0], [1.5945, 0.0], [1.6225, 1413.0], [1.623, 8078.0]], "action": "update"}}
1618677896.289206: {"channel": "orderbook", "market": "XRP/USD", "type": "update", "data": {"time": 1618677896.2078495, "checksum": 1564505583, "bids": [[1.5885, 0.0], [1.587, 1428.0]], "asks": [[1.5922, 0.0], [1.623175, 2.0]], "action": "update"}}
1618677896.307372: {"channel": "orderbook", "market": "XRP/USD", "type": "update", "data": {"time": 1618677896.2280128, "checksum": 336848452, "bids": [], "asks": [[1.593, 0.0], [1.62335, 8051.0]], "action": "update"}}
1618677896.363692: {"channel": "orderbook", "market": "XRP/USD", "type": "update", "data": {"time": 1618677896.2771797, "checksum": 1300423816, "bids": [[1.590225, 0.0], [1.55565, 2.0]], "asks": [[1.5926, 1100.0], [1.593025, 0.0], [1.593075, 633.0], [1.597775, 188.0], [1.623175, 0.0], [1.62335, 0.0]], "action": "update"}}
1618677896.412735: {"channel": "orderbook", "market": "AMD/USD", "type": "update", "data": {"time": 1618677896.3369613, "checksum": 1935389369, "bids": [], "asks": [], "action": "update"}}
1618677896.439788: {"channel": "orderbook", "market": "SUSHIBEAR/USD", "type": "update", "data": {"time": 1618677896.3547838, "checksum": 3682397038, "bids": [], "asks": [], "action": "update"}}
1618677896.446827: {"channel": "orderbook", "market": "XRP/USD", "type": "update", "data": {"time": 1618677896.372228, "checksum": 1967232770, "bids": [[1.5906, 0.0], [1.5554, 1.0]], "asks": [], "action": "update"}}
1618677896.486381: {"channel": "orderbook", "market": "XRP/USD", "type": "update", "data": {"time": 1618677896.3999367, "checksum": 485651862, "bids": [[1.590425, 2514.0], [1.58475, 172315.0], [1.55565, 0.0], [1.5554, 0.0]], "asks": [], "action": "update"}}
1618677896.486558: {"channel": "orderbook", "market": "NVDA-0625", "type": "update", "data": {"time": 1618677896.4080105, "checksum": 3644189371, "bids": [], "asks": [], "action": "update"}}
1618677896.498506: {"channel": "orderbook", "market": "SXPBULL/USD", "type": "update", "data": {"time": 1618677896.4103534, "checksum": 2488438689, "bids": [[51.1, 122.593]], "asks": [[52.525, 3.909]], "action": "update"}}
1618677896.514957: {"channel": "orderbook", "market": "ZECBULL/USD", "type": "update", "data": {"time": 1618677896.4288914, "checksum": 1232781522, "bids": [], "asks": [], "action": "update"}}
1618677896.5150452: {"channel": "orderbook", "market": "XRP/USD", "type": "update", "data": {"time": 1618677896.4332612, "checksum": 656256928, "bids": [], "asks": [[1.5932, 2512.0], [1.623, 0.0]], "action": "update"}}
1618677896.5637681: {"channel": "orderbook", "market": "XRP/USD", "type": "update", "data": {"time": 1618677896.4735732, "checksum": 3527948186, "bids": [[1.590425, 3614.0]], "asks": [[1.593075, 4433.0], [1.598325, 0.0], [1.623, 8078.0]], "action": "update"}}
1618677896.605495: {"channel": "orderbook", "market": "XRP/USD", "type": "update", "data": {"time": 1618677896.5283945, "checksum": 712491194, "bids": [], "asks": [[1.592375, 5.0], [1.59325, 1375.0], [1.5945, 1681.0], [1.6215, 0.0], [1.6225, 0.0], [1.623, 0.0]], "action": "update"}}
1618677896.632664: {"channel": "orderbook", "market": "SXPBULL/USD", "type": "update", "data": {"time": 1618677896.5165255, "checksum": 248169089, "bids": [[51.1, 0.441]], "asks": [], "action": "update"}}
1618677896.638504: {"channel": "orderbook", "market": "AKRO/USD", "type": "update", "data": {"time": 1618677896.5570424, "checksum": 902618223, "bids": [], "asks": [], "action": "update"}}
1618677896.649207: {"channel": "orderbook", "market": "XRP/USD", "type": "update", "data": {"time": 1618677896.57298, "checksum": 3247010343, "bids": [], "asks": [[1.5926, 0.0], [1.594, 6591.0], [1.6215, 6.0]], "action": "update"}}
1618677896.689986: {"channel": "orderbook", "market": "XRP/USD", "type": "update", "data": {"time": 1618677896.6042554, "checksum": 2913803089, "bids": [[1.589325, 0.0], [1.55565, 2.0]], "asks": [[1.5922, 1100.0], [1.6215, 0.0]], "action": "update"}}
1618677896.7080598: {"channel": "orderbook", "market": "SXPBULL/USD", "type": "update", "data": {"time": 1618677896.6162255, "checksum": 2533813032, "bids": [[51.075, 46.281]], "asks": [], "action": "update"}}
1618677896.729451: {"channel": "orderbook", "market": "XRP/USD", "type": "update", "data": {"time": 1618677896.652708, "checksum": 1847489962, "bids": [[1.590425, 2514.0], [1.589425, 0.0], [1.5554, 1.0]], "asks": [[1.594675, 3675.0], [1.620975, 0.0]], "action": "update"}}
1618677896.797117: {"channel": "orderbook", "market": "PAXG/USD", "type": "update", "data": {"time": 1618677896.7088914, "checksum": 852366897, "bids": [], "asks": [], "action": "update"}}
1618677896.804733: {"channel": "orderbook", "market": "XRP/USD", "type": "update", "data": {"time": 1618677896.7276142, "checksum": 2002373154, "bids": [], "asks": [[1.597925, 157.0], [1.59825, 0.0]], "action": "update"}}
1618677896.812433: {"channel": "orderbook", "market": "SXPBULL/USD", "type": "update", "data": {"time": 1618677896.7270777, "checksum": 1199214682, "bids": [[51.1, 3.38]], "asks": [], "action": "update"}}
1618677896.846582: {"channel": "orderbook", "market": "THETAHEDGE/USD", "type": "update", "data": {"time": 1618677896.7737958, "checksum": 309983746, "bids": [], "asks": [], "action": "update"}}
1618677896.8773172: {"channel": "orderbook", "market": "XRP/USD", "type": "update", "data": {"time": 1618677896.7978013, "checksum": 1979543093, "bids": [[1.58825, 1427.0], [1.5554, 0.0]], "asks": [[1.592625, 633.0], [1.593075, 3800.0], [1.620775, 0.0]], "action": "update"}}
1618677896.921012: {"channel": "orderbook", "market": "ZECBULL/USD", "type": "update", "data": {"time": 1618677896.8470523, "checksum": 4293589033, "bids": [], "asks": [[7312.5, 0.0]], "action": "update"}}
1618677896.943018: {"channel": "orderbook", "market": "XRP/USD", "type": "update", "data": {"time": 1618677896.850276, "checksum": 722007348, "bids": [[1.588925, 0.0], [1.58885, 0.0], [1.5554, 1.0], [1.5553, 6.0]], "asks": [[1.59455, 0.0], [1.620775, 2.0]], "action": "update"}}
1618677896.973218: {"channel": "orderbook", "market": "XRP/USD", "type": "update", "data": {"time": 1618677896.883076, "checksum": 2176376974, "bids": [[1.589375, 0.0], [1.58875, 0.0], [1.5865, 0.0], [1.55525, 1.0], [1.5542, 1412.0], [1.5538, 1.0]], "asks": [[1.592625, 0.0], [1.620975, 3.0]], "action": "update"}}
1618677896.986151: {"channel": "orderbook", "market": "XRP/USD", "type": "update", "data": {"time": 1618677896.9002643, "checksum": 3371284072, "bids": [[1.588775, 633.0], [1.5538, 0.0]], "asks": [], "action": "update"}}
1618677897.0263622: {"channel": "orderbook", "market": "THETAHEDGE/USD", "type": "update", "data": {"time": 1618677896.9517763, "checksum": 4043617698, "bids": [], "asks": [[25.4425, 0.0]], "action": "update"}}
1618677897.0317628: {"channel": "orderbook", "market": "XRP/USD", "type": "update", "data": {"time": 1618677896.9338758, "checksum": 2571864208, "bids": [[1.590425, 28.0], [1.58895, 0.0], [1.5538, 1.0]], "asks": [[1.592375, 0.0], [1.6215, 6.0]], "action": "update"}}
1618677897.0318851: {"channel": "orderbook", "market": "BTC-MOVE-WK-0507", "type": "update", "data": {"time": 1618677896.9598243, "checksum": 901794806, "bids": [], "asks": [], "action": "update"}}
1618677897.047652: {"channel": "orderbook", "market": "XRP/USD", "type": "update", "data": {"time": 1618677896.966169, "checksum": 1030440454, "bids": [[1.590425, 0.0], [1.58915, 0.0], [1.588775, 0.0], [1.55285, 4.0], [1.5527, 4.0], [1.5521, 348866.0]], "asks": [[1.5978, 188.0], [1.6215, 0.0]], "action": "update"}}
1618677897.09378: {"channel": "orderbook", "market": "XRP/USD", "type": "update", "data": {"time": 1618677896.9912584, "checksum": 1513647070, "bids": [], "asks": [[1.592175, 633.0], [1.5922, 0.0], [1.594075, 0.0], [1.6215, 6.0]], "action": "update"}}
1618677897.105061: {"channel": "orderbook", "market": "XRP/USD", "type": "update", "data": {"time": 1618677897.0178518, "checksum": 702316975, "bids": [], "asks": [[1.5932, 0.0], [1.6225, 1413.0]], "action": "update"}}
1618677897.129036: {"channel": "orderbook", "market": "SXPBULL/USD", "type": "update", "data": {"time": 1618677897.029752, "checksum": 312952676, "bids": [[51.075, 8.484]], "asks": [], "action": "update"}}
1618677897.146194: {"channel": "orderbook", "market": "XRP/USD", "type": "update", "data": {"time": 1618677897.054083, "checksum": 797292905, "bids": [[1.58825, 0.0], [1.588025, 3535.0], [1.588, 0.0], [1.551675, 253436.0]], "asks": [[1.5926, 1100.0], [1.599, 0.0]], "action": "update"}}
1618677897.159926: {"channel": "orderbook", "market": "SXPBULL/USD", "type": "update", "data": {"time": 1618677897.075956, "checksum": 3650944135, "bids": [[51.675, 0.168]], "asks": [], "action": "update"}}
1618677897.172804: {"channel": "orderbook", "market": "XRP/USD", "type": "update", "data": {"time": 1618677897.089671, "checksum": 2996159081, "bids": [[1.58815, 633.0], [1.5875, 9488.0], [1.5815, 1590.0], [1.5527, 0.0], [1.5521, 0.0], [1.551675, 0.0]], "asks": [[1.5926, 0.0], [1.623, 8078.0]], "action": "update"}}
1618677897.184507: {"channel": "orderbook", "market": "XRP/USD", "type": "update", "data": {"time": 1618677897.1115534, "checksum": 626089809, "bids": [[1.591025, 1.0], [1.55285, 0.0]], "asks": [[1.592, 1100.0], [1.623, 0.0]], "action": "update"}}
1618677897.234745: {"channel": "orderbook", "market": "XRP/USD", "type": "update", "data": {"time": 1618677897.1577165, "checksum": 1215383414, "bids": [[1.588525, 0.0], [1.58815, 0.0], [1.55285, 4.0], [1.5527, 4.0]], "asks": [], "action": "update"}}
1618677897.259397: {"channel": "orderbook", "market": "SXPBULL/USD", "type": "update", "data": {"time": 1618677897.1696293, "checksum": 1063176809, "bids": [[51.575, 0.0], [51.05, 242.192], [48.95, 4.196]], "asks": [], "action": "update"}}
1618677897.307729: {"channel": "orderbook", "market": "XRP/USD", "type": "update", "data": {"time": 1618677897.2122138, "checksum": 211836282, "bids": [[1.591025, 0.0], [1.588775, 633.0], [1.587075, 0.0], [1.5521, 348866.0]], "asks": [[1.59095, 633.0], [1.592175, 0.0], [1.59365, 0.0], [1.5995, 0.0], [1.623, 8078.0], [1.623175, 2.0]], "action": "update"}}
1618677897.320574: {"channel": "orderbook", "market": "XRP/USD", "type": "update", "data": {"time": 1618677897.2423697, "checksum": 2204686948, "bids": [[1.589, 2516.0], [1.5521, 0.0]], "asks": [[1.591875, 2514.0], [1.623175, 0.0]], "action": "update"}}
1618677897.3548212: {"channel": "orderbook", "market": "XRP/USD", "type": "update", "data": {"time": 1618677897.2663774, "checksum": 1225668114, "bids": [[1.588775, 0.0], [1.5521, 348866.0]], "asks": [[1.592, 0.0], [1.623175, 2.0]], "action": "update"}}
1618677897.402281: {"channel": "orderbook", "market": "XRP/USD", "type": "update", "data": {"time": 1618677897.325447, "checksum": 3204154108, "bids": [[1.588275, 633.0], [1.58735, 3675.0], [1.581125, 0.0], [1.5521, 0.0]], "asks": [[1.590775, 1100.0], [1.59095, 4280.0], [1.5926, 5.0], [1.59525, 5380.0], [1.596325, 0.0], [1.623175, 0.0]], "action": "update"}}
1618677897.4065301: {"channel": "orderbook", "market": "SXPBULL/USD", "type": "update", "data": {"time": 1618677897.3231802, "checksum": 3850733848, "bids": [[51.05, 0.482]], "asks": [], "action": "update"}}
1618677897.465803: {"channel": "orderbook", "market": "XRP/USD", "type": "update", "data": {"time": 1618677897.3458874, "checksum": 2934923848, "bids": [[1.59025, 0.0], [1.587, 0.0], [1.5521, 348866.0], [1.551675, 253436.0]], "asks": [], "action": "update"}}
1618677897.485502: {"channel": "orderbook", "market": "SUSHIBEAR/USD", "type": "update", "data": {"time": 1618677897.4025126, "checksum": 3682397038, "bids": [], "asks": [], "action": "update"}}
1618677897.487541: {"channel": "orderbook", "market": "XRP/USD", "type": "update", "data": {"time": 1618677897.4091442, "checksum": 2144410402, "bids": [[1.588275, 311175.0]], "asks": [], "action": "update"}}
1618677897.532479: {"channel": "orderbook", "market": "XRP/USD", "type": "update", "data": {"time": 1618677897.449801, "checksum": 1604666836, "bids": [], "asks": [[1.591425, 633.0], [1.623, 0.0]], "action": "update"}}
1618677897.554045: {"channel": "orderbook", "market": "ZECBULL/USD", "type": "update", "data": {"time": 1618677897.4674056, "checksum": 3533768848, "bids": [], "asks": [[7322.5, 0.57725]], "action": "update"}}
1618677897.554111: {"channel": "orderbook", "market": "THETAHEDGE/USD", "type": "update", "data": {"time": 1618677897.4743328, "checksum": 3670658753, "bids": [], "asks": [[25.465, 144.41]], "action": "update"}}
1618677897.55416: {"channel": "orderbook", "market": "XRP/USD", "type": "update", "data": {"time": 1618677897.474506, "checksum": 3247126642, "bids": [[1.589125, 1100.0], [1.551675, 0.0]], "asks": [], "action": "update"}}
1618677897.554215: {"channel": "orderbook", "market": "NVDA-0625", "type": "update", "data": {"time": 1618677897.4749844, "checksum": 3644189371, "bids": [], "asks": [], "action": "update"}}
1618677897.579396: {"channel": "orderbook", "market": "XRP/USD", "type": "update", "data": {"time": 1618677897.497871, "checksum": 2371220838, "bids": [], "asks": [[1.5985, 1308.0]], "action": "update"}}
1618677897.602504: {"channel": "orderbook", "market": "SXPBULL/USD", "type": "update", "data": {"time": 1618677897.4854321, "checksum": 3583344675, "bids": [[51.05, 172.479]], "asks": [], "action": "update"}}
1618677897.645945: {"channel": "orderbook", "market": "XRP/USD", "type": "update", "data": {"time": 1618677897.548748, "checksum": 4264084380, "bids": [], "asks": [[1.59325, 0.0], [1.623, 8078.0]], "action": "update"}}
1618677897.6577: {"channel": "orderbook", "market": "SXPBULL/USD", "type": "update", "data": {"time": 1618677897.5429752, "checksum": 3850733848, "bids": [[51.05, 0.482]], "asks": [], "action": "update"}}
1618677897.657761: {"channel": "orderbook", "market": "XRP/USD", "type": "update", "data": {"time": 1618677897.576917, "checksum": 207877965, "bids": [[1.589, 0.0], [1.551675, 253436.0]], "asks": [[1.5935, 1659.0], [1.623, 0.0]], "action": "update"}}
1618677897.6793642: {"channel": "orderbook", "market": "AKRO/USD", "type": "update", "data": {"time": 1618677897.5815117, "checksum": 902618223, "bids": [], "asks": [], "action": "update"}}
1618677897.6794088: {"channel": "orderbook", "market": "AMD/USD", "type": "update", "data": {"time": 1618677897.357384, "checksum": 1935389369, "bids": [], "asks": [], "action": "update"}}
1618677897.701772: {"channel": "orderbook", "market": "XRP/USD", "type": "update", "data": {"time": 1618677897.6235902, "checksum": 3109678548, "bids": [[1.589125, 0.0], [1.5516, 2.0]], "asks": [], "action": "update"}}
1618677897.710266: {"channel": "orderbook", "market": "SXPBULL/USD", "type": "update", "data": {"time": 1618677897.6149886, "checksum": 211391032, "bids": [[51.05, 17.675]], "asks": [], "action": "update"}}
1618677897.755161: {"channel": "orderbook", "market": "SXPBULL/USD", "type": "update", "data": {"time": 1618677897.668423, "checksum": 2327733973, "bids": [[51.05, 0.482]], "asks": [[52.125, 1.187]], "action": "update"}}
1618677897.75936: {"channel": "orderbook", "market": "XRP/USD", "type": "update", "data": {"time": 1618677897.6764715, "checksum": 3225333303, "bids": [[1.588575, 1100.0], [1.5516, 0.0]], "asks": [], "action": "update"}}
1618677897.7764711: {"channel": "orderbook", "market": "XRP/USD", "type": "update", "data": {"time": 1618677897.6982472, "checksum": 2865364491, "bids": [[1.573025, 0.0], [1.5516, 2.0]], "asks": [], "action": "update"}}
1618677897.806359: {"channel": "orderbook", "market": "XRP/USD", "type": "update", "data": {"time": 1618677897.7239325, "checksum": 2948479348, "bids": [], "asks": [[1.597775, 0.0], [1.623, 8078.0]], "action": "update"}}
1618677897.829678: {"channel": "orderbook", "market": "XRP/USD", "type": "update", "data": {"time": 1618677897.7480981, "checksum": 1943055814, "bids": [], "asks": [[1.591425, 0.0], [1.591875, 0.0], [1.623175, 2.0], [1.62335, 8051.0]], "action": "update"}}
1618677897.841401: {"channel": "orderbook", "market": "SXPBULL/USD", "type": "update", "data": {"time": 1618677897.7482035, "checksum": 3946121065, "bids": [[51.1, 5.097]], "asks": [], "action": "update"}}
1618677897.844522: {"channel": "orderbook", "market": "PAXG/USD", "type": "update", "data": {"time": 1618677897.768184, "checksum": 852366897, "bids": [], "asks": [], "action": "update"}}
1618677897.8642108: {"channel": "orderbook", "market": "XRP/USD", "type": "update", "data": {"time": 1618677897.7765334, "checksum": 1896219083, "bids": [[1.586825, 9000.0], [1.584925, 1638.0], [1.551675, 0.0], [1.5516, 0.0]], "asks": [], "action": "update"}}
1618677897.878915: {"channel": "orderbook", "market": "THETAHEDGE/USD", "type": "update", "data": {"time": 1618677897.7981527, "checksum": 3670658753, "bids": [], "asks": [], "action": "update"}}
1618677897.8931909: {"channel": "orderbook", "market": "XRP/USD", "type": "update", "data": {"time": 1618677897.7982585, "checksum": 4144502364, "bids": [], "asks": [[1.59075, 633.0], [1.62335, 0.0]], "action": "update"}}
1618677897.898859: {"channel": "orderbook", "market": "XRP/USD", "type": "update", "data": {"time": 1618677897.823612, "checksum": 2375755190, "bids": [], "asks": [[1.5978, 0.0], [1.62335, 8051.0]], "action": "update"}}
1618677897.931225: {"channel": "orderbook", "market": "XRP/USD", "type": "update", "data": {"time": 1618677897.851192, "checksum": 727498943, "bids": [], "asks": [[1.590775, 0.0], [1.591075, 1437.0]], "action": "update"}}
1618677897.9635: {"channel": "orderbook", "market": "SXPBULL/USD", "type": "update", "data": {"time": 1618677897.8757963, "checksum": 2122197152, "bids": [[51.475, 30.1], [48.95, 0.0]], "asks": [], "action": "update"}}
1618677897.999715: {"channel": "orderbook", "market": "XRP/USD", "type": "update", "data": {"time": 1618677897.9014566, "checksum": 736364663, "bids": [[1.5886, 2517.0], [1.5521, 0.0]], "asks": [[1.590575, 1100.0], [1.59075, 0.0]], "action": "update"}}
1618677897.9998422: {"channel": "orderbook", "market": "XRP/USD", "type": "update", "data": {"time": 1618677897.9259691, "checksum": 2586498351, "bids": [[1.586975, 1452.0], [1.582, 1651.0], [1.55285, 0.0], [1.5527, 0.0]], "asks": [[1.59745, 188.0], [1.62335, 0.0]], "action": "update"}}
1618677898.043194: {"channel": "orderbook", "market": "XRP/USD", "type": "update", "data": {"time": 1618677897.9484758, "checksum": 1930530327, "bids": [[1.588575, 0.0], [1.55285, 4.0]], "asks": [], "action": "update"}}
1618677898.089976: {"channel": "orderbook", "market": "XRP/USD", "type": "update", "data": {"time": 1618677897.9729881, "checksum": 1970147826, "bids": [], "asks": [[1.5943, 267197.0], [1.623175, 0.0]], "action": "update"}}
1618677898.090143: {"channel": "orderbook", "market": "BTC-MOVE-WK-0507", "type": "update", "data": {"time": 1618677897.985293, "checksum": 901794806, "bids": [], "asks": [], "action": "update"}}
1618677898.090215: {"channel": "orderbook", "market": "XRP/USD", "type": "update", "data": {"time": 1618677898.0015302, "checksum": 4079784969, "bids": [[1.588775, 1100.0], [1.55285, 0.0]], "asks": [[1.591675, 3147.0], [1.623, 0.0]], "action": "update"}}
1618677898.1071239: {"channel": "orderbook", "market": "XRP/USD", "type": "update", "data": {"time": 1618677898.0230806, "checksum": 3200325850, "bids": [], "asks": [[1.594675, 0.0], [1.623, 8078.0]], "action": "update"}}
1618677898.1491368: {"channel": "orderbook", "market": "XRP/USD", "type": "update", "data": {"time": 1618677898.0624447, "checksum": 1257238456, "bids": [], "asks": [[1.5939, 7938.0], [1.5971, 188.0], [1.623, 0.0]], "action": "update"}}
1618677898.1565042: {"channel": "orderbook", "market": "XRP/USD", "type": "update", "data": {"time": 1618677898.0786543, "checksum": 2857540446, "bids": [[1.56915, 293.0], [1.5538, 0.0]], "asks": [], "action": "update"}}
1618677898.183104: {"channel": "orderbook", "market": "XRP/USD", "type": "update", "data": {"time": 1618677898.1019616, "checksum": 8574912, "bids": [[1.58645, 1334.0], [1.5542, 0.0]], "asks": [], "action": "update"}}
1618677898.252625: {"channel": "orderbook", "market": "XRP/USD", "type": "update", "data": {"time": 1618677898.176026, "checksum": 1237361489, "bids": [], "asks": [[1.591675, 2514.0]], "action": "update"}}
1618677898.293239: {"channel": "orderbook", "market": "SXPBULL/USD", "type": "update", "data": {"time": 1618677898.2051797, "checksum": 1627510410, "bids": [[51.1, 3.38]], "asks": [], "action": "update"}}
1618677898.293358: {"channel": "orderbook", "market": "XRP/USD", "type": "update", "data": {"time": 1618677898.2175486, "checksum": 2422638021, "bids": [[1.58685, 2179.0], [1.55525, 0.0]], "asks": [[1.59055, 633.0], [1.6225, 0.0]], "action": "update"}}
1618677898.315868: {"channel": "orderbook", "market": "AKRO/USD", "type": "update", "data": {"time": 1618677898.2351663, "checksum": 179181705, "bids": [[0.068125, 0.0], [0.059365, 38.0]], "asks": [], "action": "update"}}
1618677898.330635: {"channel": "orderbook", "market": "XRP/USD", "type": "update", "data": {"time": 1618677898.2553997, "checksum": 1883972282, "bids": [], "asks": [[1.590575, 0.0], [1.6225, 1413.0]], "action": "update"}}
1618677898.4034162: {"channel": "orderbook", "market": "XRP/USD", "type": "update", "data": {"time": 1618677898.3174021, "checksum": 2128030274, "bids": [], "asks": [[1.590375, 1100.0], [1.591925, 1344.0], [1.6215, 0.0], [1.6225, 0.0]], "action": "update"}}
1618677898.403608: {"channel": "orderbook", "market": "AKRO/USD", "type": "update", "data": {"time": 1618677898.330466, "checksum": 2221115935, "bids": [[0.06801, 0.0], [0.059205, 38.0]], "asks": [], "action": "update"}}
1618677898.4204621: {"channel": "orderbook", "market": "SXPBULL/USD", "type": "update", "data": {"time": 1618677898.3361182, "checksum": 2812417289, "bids": [[51.1, 102.647]], "asks": [], "action": "update"}}
1618677898.4320178: {"channel": "orderbook", "market": "AKRO/USD", "type": "update", "data": {"time": 1618677898.3565304, "checksum": 80518689, "bids": [], "asks": [[0.068525, 243.0], [0.085, 0.0]], "action": "update"}}
1618677898.453919: {"channel": "orderbook", "market": "AMD/USD", "type": "update", "data": {"time": 1618677898.3713155, "checksum": 1935389369, "bids": [], "asks": [], "action": "update"}}
1618677898.4569862: {"channel": "orderbook", "market": "AKRO/USD", "type": "update", "data": {"time": 1618677898.3815284, "checksum": 4118979057, "bids": [], "asks": [[0.06858, 0.0], [0.085, 1084.0]], "action": "update"}}
1618677898.470224: {"channel": "orderbook", "market": "XRP/USD", "type": "update", "data": {"time": 1618677898.3949337, "checksum": 3566188200, "bids": [[1.58685, 0.0], [1.55525, 1.0]], "asks": [[1.59055, 0.0], [1.591675, 3147.0], [1.5939, 3675.0], [1.6215, 6.0]], "action": "update"}}
1618677898.490745: {"channel": "orderbook", "market": "XRP/USD", "type": "update", "data": {"time": 1618677898.4137769, "checksum": 3061414331, "bids": [[1.5875, 61862.0]], "asks": [], "action": "update"}}
1618677898.5198421: {"channel": "orderbook", "market": "SXPBULL/USD", "type": "update", "data": {"time": 1618677898.4138317, "checksum": 1288148832, "bids": [[51.1, 99.708]], "asks": [], "action": "update"}}
1618677898.519918: {"channel": "orderbook", "market": "SUSHIBEAR/USD", "type": "update", "data": {"time": 1618677898.4289463, "checksum": 3682397038, "bids": [], "asks": [], "action": "update"}}
1618677898.519964: {"channel": "orderbook", "market": "XRP/USD", "type": "update", "data": {"time": 1618677898.439372, "checksum": 3812152158, "bids": [], "asks": [[1.590375, 0.0], [1.6225, 1413.0]], "action": "update"}}
1618677898.538201: {"channel": "orderbook", "market": "SXPBULL/USD", "type": "update", "data": {"time": 1618677898.4531791, "checksum": 2423139800, "bids": [[51.525, 35.9], [48.975, 0.0]], "asks": [], "action": "update"}}
1618677898.549403: {"channel": "orderbook", "market": "XRP/USD", "type": "update", "data": {"time": 1618677898.4728165, "checksum": 3697571887, "bids": [], "asks": [[1.591675, 2514.0], [1.597925, 0.0], [1.623, 8078.0]], "action": "update"}}
1618677898.572051: {"channel": "orderbook", "market": "XRP/USD", "type": "update", "data": {"time": 1618677898.4953547, "checksum": 3040686191, "bids": [[1.5875, 9488.0]], "asks": [[1.590775, 1100.0], [1.5912, 633.0], [1.6225, 0.0], [1.623, 0.0]], "action": "update"}}
1618677898.572593: {"channel": "orderbook", "market": "ZECBULL/USD", "type": "update", "data": {"time": 1618677898.4944692, "checksum": 3533768848, "bids": [], "asks": [], "action": "update"}}
1618677898.592297: {"channel": "orderbook", "market": "XRP/USD", "type": "update", "data": {"time": 1618677898.5139973, "checksum": 23800549, "bids": [], "asks": [[1.5926, 0.0], [1.6225, 1413.0]], "action": "update"}}
1618677898.618439: {"channel": "orderbook", "market": "XRP/USD", "type": "update", "data": {"time": 1618677898.540169, "checksum": 2493870952, "bids": [], "asks": [[1.592575, 4453.0], [1.5939, 0.0]], "action": "update"}}
1618677898.6443782: {"channel": "orderbook", "market": "NVDA-0625", "type": "update", "data": {"time": 1618677898.5576398, "checksum": 3644189371, "bids": [], "asks": [], "action": "update"}}
1618677898.644466: {"channel": "orderbook", "market": "XRP/USD", "type": "update", "data": {"time": 1618677898.5647483, "checksum": 1759199690, "bids": [[1.5888, 63.0], [1.55525, 0.0]], "asks": [[1.593475, 3675.0], [1.6225, 0.0]], "action": "update"}}
1618677898.6539142: {"channel": "orderbook", "market": "SXPBULL/USD", "type": "update", "data": {"time": 1618677898.5494552, "checksum": 574375543, "bids": [[51.1, 0.441]], "asks": [], "action": "update"}}
1618677898.6646872: {"channel": "orderbook", "market": "AKRO/USD", "type": "update", "data": {"time": 1618677898.582816, "checksum": 1299003101, "bids": [[0.06801, 7629.0], [0.059205, 0.0]], "asks": [], "action": "update"}}
1618677898.686489: {"channel": "orderbook", "market": "ZECBULL/USD", "type": "update", "data": {"time": 1618677898.6086388, "checksum": 1763748236, "bids": [[7220.0, 0.39876]], "asks": [], "action": "update"}}
1618677898.706454: {"channel": "orderbook", "market": "XRP/USD", "type": "update", "data": {"time": 1618677898.6212726, "checksum": 1428981136, "bids": [[1.588775, 0.0], [1.55525, 1.0]], "asks": [], "action": "update"}}
1618677898.714442: {"channel": "orderbook", "market": "XRP/USD", "type": "update", "data": {"time": 1618677898.6396062, "checksum": 2263350224, "bids": [[1.58895, 1100.0], [1.55525, 0.0]], "asks": [], "action": "update"}}
1618677898.750507: {"channel": "orderbook", "market": "SXPBULL/USD", "type": "update", "data": {"time": 1618677898.668026, "checksum": 23004544, "bids": [[51.125, 10.175]], "asks": [], "action": "update"}}
1618677898.783266: {"channel": "orderbook", "market": "XRP/USD", "type": "update", "data": {"time": 1618677898.6980145, "checksum": 1301877933, "bids": [], "asks": [[1.59095, 0.0], [1.591075, 0.0], [1.5963, 157.0], [1.6225, 1413.0]], "action": "update"}}
1618677898.8309162: {"channel": "orderbook", "market": "XRP/USD", "type": "update", "data": {"time": 1618677898.7475302, "checksum": 1937603768, "bids": [[1.587325, 1358.0], [1.5553, 0.0]], "asks": [[1.590775, 0.0], [1.623, 8078.0]], "action": "update"}}
1618677898.8590589: {"channel": "orderbook", "market": "SXPBULL/USD", "type": "update", "data": {"time": 1618677898.7699363, "checksum": 1051709250, "bids": [], "asks": [[52.25, 32.932]], "action": "update"}}
1618677898.873695: {"channel": "orderbook", "market": "XRP/USD", "type": "update", "data": {"time": 1618677898.7952259, "checksum": 2685232304, "bids": [], "asks": [[1.591025, 1100.0], [1.623, 0.0]], "action": "update"}}
1618677898.9048371: {"channel": "orderbook", "market": "PAXG/USD", "type": "update", "data": {"time": 1618677898.8242826, "checksum": 852366897, "bids": [], "asks": [], "action": "update"}}
1618677898.9049249: {"channel": "orderbook", "market": "THETAHEDGE/USD", "type": "update", "data": {"time": 1618677898.8293867, "checksum": 3670658753, "bids": [], "asks": [], "action": "update"}}
1618677898.914814: {"channel": "orderbook", "market": "XRP/USD", "type": "update", "data": {"time": 1618677898.8391056, "checksum": 1104933518, "bids": [], "asks": [[1.592775, 0.0], [1.623, 8078.0]], "action": "update"}}
1618677899.0127091: {"channel": "orderbook", "market": "XRP/USD", "type": "update", "data": {"time": 1618677898.9230938, "checksum": 3033727858, "bids": [[1.5886, 0.0], [1.5553, 6.0]], "asks": [[1.5935, 0.0], [1.593925, 0.0], [1.5971, 0.0], [1.5985, 2839.0], [1.623175, 2.0], [1.62335, 8051.0], [1.6235, 4.0]], "action": "update"}}
1618677899.012935: {"channel": "orderbook", "market": "SXPBULL/USD", "type": "update", "data": {"time": 1618677898.9257503, "checksum": 492161982, "bids": [[51.125, 6.181]], "asks": [], "action": "update"}}
1618677899.025652: {"channel": "orderbook", "market": "XRP/USD", "type": "update", "data": {"time": 1618677898.9495833, "checksum": 1359542473, "bids": [[1.586825, 0.0], [1.55525, 1.0]], "asks": [[1.59095, 5.0], [1.6235, 0.0]], "action": "update"}}
1618677899.042401: {"channel": "orderbook", "market": "SXPBULL/USD", "type": "update", "data": {"time": 1618677898.956136, "checksum": 2260092084, "bids": [[51.45, 1.751], [51.0, 11.999], [49.0, 0.0]], "asks": [], "action": "update"}}
1618677899.0866401: {"channel": "orderbook", "market": "XRP/USD", "type": "update", "data": {"time": 1618677899.0027277, "checksum": 1832971730, "bids": [[1.5888, 0.0], [1.5542, 1412.0]], "asks": [[1.591025, 0.0], [1.59135, 1415.0]], "action": "update"}}
1618677899.090076: {"channel": "orderbook", "market": "BTC-MOVE-WK-0507", "type": "update", "data": {"time": 1618677899.0096807, "checksum": 901794806, "bids": [], "asks": [], "action": "update"}}
1618677899.1162932: {"channel": "orderbook", "market": "SXPBULL/USD", "type": "update", "data": {"time": 1618677899.0292897, "checksum": 4282752781, "bids": [[50.275, 2.876]], "asks": [], "action": "update"}}
1618677899.1241632: {"channel": "orderbook", "market": "XRP/USD", "type": "update", "data": {"time": 1618677899.0448804, "checksum": 2731036906, "bids": [[1.58895, 0.0], [1.5538, 1.0]], "asks": [[1.59075, 1.0], [1.590775, 1100.0], [1.623175, 0.0], [1.62335, 0.0]], "action": "update"}}
1618677899.134754: {"channel": "orderbook", "market": "SXPBULL/USD", "type": "update", "data": {"time": 1618677899.0533924, "checksum": 3115705857, "bids": [[51.0, 34.916]], "asks": [], "action": "update"}}
1618677899.147573: {"channel": "orderbook", "market": "XRP/USD", "type": "update", "data": {"time": 1618677899.073692, "checksum": 4012335702, "bids": [[1.5888, 2516.0], [1.5538, 0.0]], "asks": [[1.590775, 0.0], [1.623175, 2.0]], "action": "update"}}
1618677899.1949172: {"channel": "orderbook", "market": "SXPBULL/USD", "type": "update", "data": {"time": 1618677899.1084733, "checksum": 3968471143, "bids": [[51.625, 28.4], [51.125, 10.175], [50.7, 1.677], [49.025, 0.0]], "asks": [], "action": "update"}}
1618677899.23055: {"channel": "orderbook", "market": "XRP/USD", "type": "update", "data": {"time": 1618677899.1456378, "checksum": 2195009823, "bids": [[1.586675, 9000.0], [1.5542, 0.0]], "asks": [[1.590575, 1100.0], [1.59165, 5188.0], [1.59635, 188.0], [1.6225, 0.0], [1.623, 0.0], [1.623175, 0.0]], "action": "update"}}
1618677899.245398: {"channel": "orderbook", "market": "XRP/USD", "type": "update", "data": {"time": 1618677899.169665, "checksum": 886314734, "bids": [[1.588975, 1100.0], [1.55525, 0.0]], "asks": [], "action": "update"}}
1618677899.245545: {"channel": "orderbook", "market": "SXPBULL/USD", "type": "update", "data": {"time": 1618677899.1629028, "checksum": 1224052979, "bids": [[51.125, 6.181]], "asks": [], "action": "update"}}
1618677899.286747: {"channel": "orderbook", "market": "XRP/USD", "type": "update", "data": {"time": 1618677899.2088914, "checksum": 3375516515, "bids": [[1.59035, 63.0], [1.5888, 0.0]], "asks": [[1.591975, 5580.0], [1.595225, 1685.0], [1.6215, 0.0]], "action": "update"}}
1618677899.3180852: {"channel": "orderbook", "market": "SXPBULL/USD", "type": "update", "data": {"time": 1618677899.2384877, "checksum": 52709494, "bids": [[51.15, 33.517]], "asks": [], "action": "update"}}
1618677899.3514812: {"channel": "orderbook", "market": "XRP/USD", "type": "update", "data": {"time": 1618677899.272891, "checksum": 776841997, "bids": [[1.5885, 2517.0], [1.587325, 0.0]], "asks": [[1.591675, 0.0], [1.6215, 6.0]], "action": "update"}}
1618677899.362676: {"channel": "orderbook", "market": "SXPBULL/USD", "type": "update", "data": {"time": 1618677899.282475, "checksum": 1224052979, "bids": [[51.15, 2.485]], "asks": [], "action": "update"}}
1618677899.419756: {"channel": "orderbook", "market": "XRP/USD", "type": "update", "data": {"time": 1618677899.298764, "checksum": 2977676893, "bids": [[1.59035, 0.0], [1.55525, 1.0]], "asks": [], "action": "update"}}
1618677899.4354172: {"channel": "orderbook", "market": "XRP/USD", "type": "update", "data": {"time": 1618677899.360891, "checksum": 2070127624, "bids": [[1.58765, 4800.0], [1.587525, 2179.0], [1.5553, 0.0], [1.55525, 0.0]], "asks": [[1.59095, 0.0], [1.6225, 1413.0]], "action": "update"}}
1618677899.438566: {"channel": "orderbook", "market": "SXPBULL/USD", "type": "update", "data": {"time": 1618677899.356032, "checksum": 3573152147, "bids": [[51.175, 89.993], [50.35, 321.447]], "asks": [], "action": "update"}}
1618677899.474119: {"channel": "orderbook", "market": "XRP/USD", "type": "update", "data": {"time": 1618677899.3923352, "checksum": 3821561449, "bids": [[1.588975, 0.0], [1.5553, 6.0]], "asks": [[1.590925, 633.0], [1.5912, 0.0], [1.591375, 2515.0], [1.6225, 0.0]], "action": "update"}}
1618677899.474318: {"channel": "orderbook", "market": "AMD/USD", "type": "update", "data": {"time": 1618677899.3960407, "checksum": 1935389369, "bids": [], "asks": [], "action": "update"}}
1618677899.486815: {"channel": "orderbook", "market": "XRP/USD", "type": "update", "data": {"time": 1618677899.4073544, "checksum": 995257300, "bids": [[1.587525, 0.0], [1.586675, 0.0], [1.55525, 1.0], [1.5542, 1412.0]], "asks": [], "action": "update"}}
1618677899.514252: {"channel": "orderbook", "market": "XRP/USD", "type": "update", "data": {"time": 1618677899.434858, "checksum": 4036143944, "bids": [[1.588675, 1100.0], [1.5542, 0.0]], "asks": [], "action": "update"}}
1618677899.55564: {"channel": "orderbook", "market": "SUSHIBEAR/USD", "type": "update", "data": {"time": 1618677899.4667885, "checksum": 3682397038, "bids": [], "asks": [], "action": "update"}}
1618677899.575022: {"channel": "orderbook", "market": "SXPBULL/USD", "type": "update", "data": {"time": 1618677899.4815707, "checksum": 2470060833, "bids": [], "asks": [[52.35, 34.27]], "action": "update"}}
1618677899.596349: {"channel": "orderbook", "market": "XRP/USD", "type": "update", "data": {"time": 1618677899.5087926, "checksum": 2706799923, "bids": [], "asks": [[1.59255, 3557.0], [1.6215, 0.0]], "action": "update"}}
1618677899.601511: {"channel": "orderbook", "market": "ZECBULL/USD", "type": "update", "data": {"time": 1618677899.5190742, "checksum": 1763748236, "bids": [], "asks": [], "action": "update"}}
1618677899.630358: {"channel": "orderbook", "market": "SXPBULL/USD", "type": "update", "data": {"time": 1618677899.5430067, "checksum": 1740032145, "bids": [], "asks": [[52.25, 0.732]], "action": "update"}}
