wss://ftexchange.com/ws/ <- 1626993903.8716521: {"channel":"orderbook","market":"CAD/USD","op":"subscribe"}
wss://ftexchange.com/ws/ <- 1626993903.871726: {"channel":"orderbook","market":"BNBBEAR/USDT","op":"subscribe"}
wss://ftexchange.com/ws/ <- 1626993903.871796: {"channel":"orderbook","market":"MKR-PERP","op":"subscribe"}
wss://ftexchange.com/ws/ <- 1626993903.871861: {"channel":"orderbook","market":"APHA/USD","op":"subscribe"}
wss://ftexchange.com/ws/ <- 1626993903.8719292: {"channel":"orderbook","market":"KNCBULL/USDT","op":"subscribe"}
wss://ftexchange.com/ws/ <- 1626993903.871996: {"channel":"orderbook","market":"BTC-1231","op":"subscribe"}
wss://ftexchange.com/ws/ <- 1626993903.8720589: {"channel":"orderbook","market":"FLOW-PERP","op":"subscribe"}
wss://ftexchange.com/ws/ <- 1626993903.872121: {"channel":"orderbook","market":"BB-0924","op":"subscribe"}
wss://ftexchange.com/ws/ <- 1626993903.872184: {"channel":"orderbook","market":"PFE/USD","op":"subscribe"}
wss://ftexchange.com/ws/ <- 1626993903.872245: {"channel":"orderbook","market":"CHZ/USDT","op":"subscribe"}
1626993904.265899: {"type": "subscribed", "channel": "orderbook", "market": "CAD/USD"}
1626993904.265932: {"type": "subscribed", "channel": "orderbook", "market": "BNBBEAR/USDT"}
1626993904.265944: {"type": "subscribed", "channel": "orderbook", "market": "MKR-PERP"}
1626993904.265953: {"type": "subscribed", "channel": "orderbook", "market": "APHA/USD"}
1626993904.265961: {"type": "subscribed", "channel": "orderbook", "market": "KNCBULL/USDT"}
1626993904.265968: {"channel": "orderbook", "market": "CAD/USD", "type": "partial", "data": {"time": 1626993904.1557314, "checksum": 706162672, "bids": [[0.7959, 83274.0], [0.7944, 146568.0], [0.7935, 138.0], [0.7934, 155176.0], [0.7924, 148616.0], [0.7914, 154491.0], [0.7904, 256214.0], [0.7894, 291120.0], [0.7893, 320009.0], [0.7891, 215.0], [0.7884, 8.0], [0.7875, 193593.0], [0.7869, 266145.0], [0.7858, 231805.0], [0.7855, 291467.0], [0.78, 5000.0], [0.7442, 80037.0], [0.7077, 75059.0], [0.7006, 88074.0], [0.6339, 148678.0], [0.6283, 166896.0], [0.6005, 143957.0], [0.4, 12.0], [0.04, 125.0], [0.001, 11000.0], [0.0002, 500000.0], [0.0001, 1110000.0]], "asks": [[0.7964, 104037.0], [0.7977, 135856.0], [0.7979, 132829.0], [0.7987, 225954.0], [0.7995, 2385.0], [0.7997, 232036.0], [0.8007, 253032.0], [0.8018, 261685.0], [0.8028, 319624.0], [0.8038, 314007.0], [0.8048, 263182.0], [0.805, 32.0], [0.8058, 284038.0], [0.8066, 963.0], [0.8068, 375322.0], [0.8453, 79261.0], [0.8716, 62412.0], [0.9207, 113713.0], [0.9603, 126690.0], [1.0, 142631.0], [1.0306, 174364.0]], "action": "partial"}}
1626993904.2663019: {"type": "subscribed", "channel": "orderbook", "market": "BTC-1231"}
1626993904.26632: {"type": "subscribed", "channel": "orderbook", "market": "FLOW-PERP"}
1626993904.266329: {"type": "subscribed", "channel": "orderbook", "market": "BB-0924"}
1626993904.266337: {"type": "subscribed", "channel": "orderbook", "market": "PFE/USD"}
1626993904.266345: {"type": "subscribed", "channel": "orderbook", "market": "CHZ/USDT"}
1626993904.2801971: {"channel": "orderbook", "market": "MKR-PERP", "type": "partial", "data": {"time": 1626993904.2528822, "checksum": 1581592315, "bids": [[2414.5, 0.568], [2414.0, 0.186], [2413.5, 3.283], [2413.0, 0.185], [2412.5, 0.858], [2412.0, 0.125], [2411.5, 1.393], [2411.0, 1.748], [2410.5, 1.946], [2410.0, 3.263], [2409.5, 4.261], [2409.0, 5.427], [2408.5, 0.086], [2408.0, 1.612], [2407.5, 0.001], [2407.0, 14.363], [2406.5, 2.069], [2406.0, 3.068], [2405.5, 0.732], [2405.0, 2.0], [2404.5, 0.455], [2404.0, 60.188], [2403.5, 0.5], [2403.0, 0.041], [2401.0, 24.242], [2400.5, 0.216], [2400.0, 0.865], [2399.5, 6.426], [2399.0, 5.463], [2398.5, 0.331], [2397.0, 0.455], [2391.5, 0.013], [2391.0, 10.693], [2390.5, 1.295], [2387.0, 0.457], [2386.5, 6.042], [2385.5, 12.576], [2385.0, 6.884], [2383.5, 0.332], [2382.0, 0.572], [2379.0, 7.561], [2375.0, 8.094], [2374.5, 5.84], [2372.0, 10.815], [2366.5, 0.014], [2363.0, 0.002], [2361.0, 3.0], [2360.5, 6.101], [2360.0, 8.749], [2357.5, 0.04], [2354.0, 9.594], [2351.0, 181.32], [2349.0, 0.001], [2348.0, 6.025], [2344.5, 1.464], [2342.0, 0.013], [2336.5, 6.093], [2336.0, 3.0], [2332.0, 0.001], [2317.5, 0.013], [2316.0, 0.002], [2315.0, 0.001], [2314.0, 0.04], [2312.0, 5.962], [2311.0, 0.202], [2310.0, 0.013], [2300.5, 4.643], [2297.5, 0.001], [2292.5, 0.014], [2291.0, 0.002], [2280.5, 0.001], [2279.0, 0.317], [2270.5, 0.04], [2269.0, 0.002], [2263.5, 0.001], [2246.5, 4.643], [2246.0, 0.001], [2244.5, 57.877], [2243.0, 0.321], [2234.0, 64.536], [2229.0, 0.001], [2227.5, 0.04], [2222.5, 48.093], [2222.0, 0.002], [2212.0, 0.001], [2194.5, 0.001], [2184.0, 0.04], [2181.0, 78.034], [2177.5, 0.001], [2175.0, 0.002], [2160.5, 0.001], [2143.0, 0.001], [2141.5, 4.643], [2140.5, 0.04], [2128.0, 0.002], [2126.0, 92.2], [2109.0, 0.001], [2105.5, 0.001], [2104.5, 0.006], [2103.0, 0.5]], "asks": [[2416.0, 0.389], [2416.5, 1.912], [2417.0, 0.404], [2417.5, 0.293], [2418.0, 0.58], [2418.5, 0.278], [2419.0, 2.132], [2419.5, 4.273], [2420.0, 4.996], [2420.5, 3.197], [2421.0, 5.121], [2421.5, 0.1], [2422.0, 0.086], [2422.5, 1.061], [2423.0, 8.22], [2423.5, 7.211], [2424.0, 2.525], [2424.5, 4.735], [2425.0, 60.924], [2426.0, 2.0], [2426.5, 0.432], [2428.0, 24.015], [2429.0, 5.967], [2429.5, 0.863], [2430.0, 0.5], [2430.5, 4.478], [2431.0, 0.331], [2432.0, 6.559], [2435.0, 0.001], [2436.5, 15.145], [2439.5, 8.953], [2442.5, 8.385], [2444.0, 1.653], [2445.0, 0.039], [2445.5, 70.267], [2449.5, 0.43], [2450.0, 0.861], [2452.5, 0.001], [2457.0, 7.887], [2460.5, 0.326], [2461.0, 6.024], [2462.0, 7.642], [2466.0, 0.326], [2467.0, 6.895], [2467.5, 0.326], [2469.5, 0.001], [2470.5, 11.706], [2471.5, 5.953], [2486.5, 0.001], [2490.0, 0.04], [2491.5, 0.013], [2495.0, 0.1], [2504.0, 0.003], [2510.0, 5.961], [2513.5, 0.012], [2516.0, 0.023], [2521.0, 0.001], [2526.0, 0.001], [2533.5, 0.04], [2534.0, 5.976], [2535.0, 0.012], [2538.0, 0.001], [2551.0, 0.002], [2555.5, 0.001], [2556.5, 0.012], [2558.5, 6.156], [2562.5, 0.023], [2572.5, 0.001], [2576.5, 0.04], [2578.5, 0.012], [2589.5, 0.001], [2598.0, 0.002], [2599.0, 65.266], [2602.0, 70.056], [2607.0, 0.001], [2620.0, 0.04], [2624.0, 0.001], [2631.0, 56.008], [2632.0, 71.549], [2641.0, 0.001], [2645.0, 0.002], [2653.5, 1.0], [2658.5, 0.001], [2663.5, 0.04], [2675.5, 0.007], [2679.0, 0.023], [2692.0, 0.002], [2692.5, 0.001], [2707.0, 0.04], [2710.0, 0.001], [2713.0, 65.718], [2722.5, 0.1], [2727.0, 0.001], [2739.0, 0.002], [2744.0, 0.001], [2750.0, 0.04], [2761.5, 0.001], [2778.5, 0.001], [2786.0, 0.002], [2793.5, 0.04]], "action": "partial"}}
1626993904.338005: {"channel": "orderbook", "market": "APHA/USD", "type": "partial", "data": {"time": 1626993904.314621, "checksum": 3920446499, "bids": [[11.834, 42.2], [11.58, 83.5], [11.55, 74.9], [11.51, 87.1], [11.462, 16.5], [11.461, 95.4], [11.422, 110.4], [11.382, 146.6], [11.344, 133.6], [11.308, 131.6], [11.268, 129.9], [11.231, 183.7], [11.2, 201.6], [10.974, 168.3], [10.473, 249.5], [10.022, 322.9], [9.609, 326.9], [9.233, 414.1], [8.881, 542.3]], "asks": [[11.835, 208.1], [11.869, 113.6], [11.896, 113.7], [11.952, 142.0], [11.978, 138.7], [12.035, 172.1], [12.059, 180.1], [12.1, 174.9], [12.348, 220.9], [12.944, 290.6], [13.512, 429.0], [14.11, 498.9], [14.692, 461.4], [14.758, 68.9], [15.273, 448.5]], "action": "partial"}}
1626993904.409796: {"channel": "orderbook", "market": "MKR-PERP", "type": "update", "data": {"time": 1626993904.3723018, "checksum": 640576598, "bids": [], "asks": [[2416.0, 0.755]], "action": "update"}}
1626993904.409937: {"channel": "orderbook", "market": "PFE/USD", "type": "partial", "data": {"time": 1626993904.3792233, "checksum": 825829276, "bids": [[41.44, 442.57], [41.41, 161.46], [41.37, 206.02], [41.35, 371.73], [41.31, 476.45], [41.25, 733.59], [41.18, 492.05], [41.16, 2.3], [41.15, 622.85], [41.12, 520.07], [41.08, 559.04], [41.05, 712.54], [41.02, 802.46], [40.77, 2.0], [39.1, 700.77], [37.31, 1222.8], [35.7, 1304.48], [34.23, 1300.52], [33.0, 115.67], [32.87, 1413.37], [32.81, 2.0], [31.62, 2299.29]], "asks": [[41.59, 404.18], [41.61, 173.21], [41.64, 242.02], [41.67, 396.65], [41.71, 837.14], [41.74, 437.29], [41.78, 398.38], [41.82, 459.06], [41.86, 719.23], [41.89, 496.38], [41.93, 534.78], [41.96, 772.71], [42.5, 0.99], [43.0, 0.58], [44.01, 919.44], [44.4, 0.09], [44.96, 0.55], [46.08, 1390.13], [48.2, 1230.62], [50.28, 1675.72], [52.35, 1645.27], [54.42, 1641.72], [150.0, 0.62]], "action": "partial"}}
1626993904.432244: {"channel": "orderbook", "market": "CHZ/USDT", "type": "partial", "data": {"time": 1626993904.4062684, "checksum": 66466742, "bids": [[0.228183, 50.0], [0.227931, 3610.0], [0.227888, 3850.0], [0.227887, 500.0], [0.227872, 3860.0], [0.227859, 9160.0], [0.227844, 9150.0], [0.227832, 2500.0], [0.227815, 4550.0], [0.227809, 4260.0], [0.227805, 9150.0], [0.227762, 9100.0], [0.227725, 50.0], [0.227704, 9150.0], [0.227645, 4570.0], [0.227612, 9140.0], [0.227268, 50.0], [0.226847, 5540.0], [0.226811, 50.0], [0.226655, 1000.0], [0.226354, 50.0], [0.225896, 50.0], [0.22557, 1510.0], [0.225439, 50.0], [0.225256, 3290.0], [0.225106, 20.0], [0.22368, 20.0], [0.222917, 11700.0], [0.222377, 1000.0], [0.221546, 14770.0], [0.220059, 17410.0], [0.220048, 20.0], [0.22, 40.0], [0.2181, 1000.0], [0.21657, 15240.0], [0.216497, 18680.0], [0.216, 1150.0], [0.215, 920.0], [0.21454, 1160.0], [0.214, 680.0], [0.213422, 20410.0], [0.213, 2340.0], [0.212107, 21520.0], [0.21, 230.0], [0.208666, 20780.0], [0.208441, 23700.0], [0.205979, 22580.0], [0.205, 970.0], [0.204884, 18370.0], [0.204872, 20.0], [0.204758, 25480.0], [0.202207, 22970.0], [0.200214, 10.0], [0.2, 1020.0], [0.195, 1520.0], [0.189998, 74810.0], [0.188935, 40940.0], [0.185, 1920.0], [0.184201, 220.0], [0.183478, 270.0], [0.182, 540.0], [0.176992, 3970.0], [0.175, 1130.0], [0.174222, 88270.0], [0.17396, 92650.0], [0.171, 580.0], [0.17, 630.0], [0.168, 590.0], [0.16, 100.0], [0.1545, 320.0], [0.151185, 90.0], [0.15, 1330.0], [0.131, 1590.0], [0.13, 380.0], [0.12, 410.0], [0.071, 1400.0], [0.053, 1530.0], [1e-06, 10000000.0]], "asks": [[0.2285, 500.0], [0.228701, 3860.0], [0.22873, 2500.0], [0.228788, 960.0], [0.229097, 50.0], [0.229139, 3820.0], [0.22914, 4100.0], [0.229228, 4040.0], [0.229292, 3770.0], [0.229353, 3760.0], [0.229555, 50.0], [0.229569, 8010.0], [0.230012, 50.0], [0.230468, 170.0], [0.230469, 50.0], [0.230926, 50.0], [0.231384, 50.0], [0.231841, 50.0], [0.232298, 50.0], [0.232868, 12460.0], [0.235211, 1000.0], [0.235223, 20.0], [0.235938, 10700.0], [0.236475, 12410.0], [0.236666, 40.0], [0.238399, 15840.0], [0.239488, 1000.0], [0.240282, 20.0], [0.2418, 30.0], [0.241805, 80.0], [0.2421, 50.0], [0.243685, 14020.0], [0.243766, 1000.0], [0.244999, 40.0], [0.24517, 16130.0], [0.245306, 30.0], [0.245341, 20.0], [0.245541, 14570.0], [0.248044, 1000.0], [0.248514, 28190.0], [0.248901, 16620.0], [0.249578, 27210.0], [0.250399, 20.0], [0.251217, 30.0], [0.251635, 20340.0], [0.252322, 1000.0], [0.253333, 40.0], [0.2566, 1000.0], [0.256665, 23130.0], [0.257128, 30.0], [0.257806, 27560.0], [0.259176, 20010.0], [0.261666, 40.0], [0.263039, 30.0], [0.263676, 62140.0], [0.26895, 30.0], [0.269999, 40.0], [0.274295, 670.0], [0.274861, 30.0], [0.277374, 65820.0], [0.277827, 10.0], [0.278333, 40.0], [0.280772, 30.0], [0.284162, 370.0], [0.285717, 20.0], [0.286666, 40.0], [0.286683, 30.0], [0.28694, 1650.0], [0.289068, 67420.0], [0.292594, 30.0], [0.294999, 40.0], [0.303333, 40.0], [0.311666, 40.0], [0.319999, 40.0], [0.32, 990.0], [0.328333, 40.0], [0.336666, 40.0], [0.343821, 210.0], [0.344999, 40.0], [0.346, 120.0], [0.353333, 40.0], [0.361666, 40.0], [0.369999, 40.0], [0.38, 70.0], [0.4, 9360.0], [0.401, 370.0], [0.42, 120.0], [0.428, 10.0], [0.429377, 370.0], [0.450121, 180.0], [0.456, 2070.0], [0.47, 1330.0], [0.49, 450.0], [0.495, 3030.0], [0.5, 1570.0], [0.51, 500.0], [0.515536, 400.0], [0.52, 30.0], [0.533, 20.0], [0.5421, 270.0]], "action": "partial"}}
1626993904.618277: {"channel": "orderbook", "market": "BTC-1231", "type": "partial", "data": {"time": 1626993904.5930948, "checksum": 1929775754, "bids": [[32815.0, 0.01], [32814.0, 7.7963], [32808.0, 0.6229], [32807.0, 0.0966], [32806.0, 0.012], [32805.0, 8.8813], [32803.0, 0.6719], [32802.0, 0.001], [32800.0, 0.5945], [32799.0, 0.0301], [32795.0, 0.0292], [32793.0, 0.025], [32791.0, 0.4913], [32787.0, 6.8704], [32785.0, 0.0153], [32782.0, 0.1054], [32780.0, 1.13], [32775.0, 1.0771], [32771.0, 0.0912], [32770.0, 0.005], [32768.0, 0.094], [32767.0, 0.594], [32757.0, 8.1878], [32751.0, 0.1], [32738.0, 0.587], [32734.0, 0.0149], [32728.0, 0.3386], [32725.0, 0.008], [32717.0, 8.4561], [32715.0, 0.0155], [32711.0, 0.6858], [32710.0, 0.604], [32707.0, 0.0002], [32706.0, 0.2293], [32705.0, 0.0099], [32697.0, 0.3719], [32696.0, 0.0002], [32695.0, 0.2353], [32687.0, 0.728], [32686.0, 0.0002], [32685.0, 0.2294], [32676.0, 0.2295], [32675.0, 0.008], [32665.0, 0.2296], [32657.0, 0.594], [32656.0, 0.2296], [32646.0, 0.0006], [32644.0, 0.3297], [32636.0, 0.477], [32634.0, 0.2297], [32626.0, 0.0002], [32611.0, 0.6151], [32609.0, 0.6858], [32606.0, 0.0005], [32591.0, 0.4881], [32585.0, 0.0002], [32581.0, 0.0002], [32575.0, 0.0007], [32571.0, 0.5992], [32565.0, 0.0001], [32555.0, 0.0006], [32548.0, 0.24], [32545.0, 0.0004], [32525.0, 0.0004], [32515.0, 0.0008], [32508.0, 0.1], [32507.0, 12.0322], [32505.0, 0.6091], [32503.0, 0.6858], [32501.0, 1.0], [32482.0, 0.4513], [32467.0, 0.5], [32464.0, 0.0002], [32454.0, 0.001], [32447.0, 0.1105], [32446.0, 0.649], [32444.0, 0.0006], [32438.0, 6.068], [32437.0, 2.0], [32424.0, 0.0002], [32414.0, 0.0004], [32412.0, 1.0], [32395.0, 0.121], [32383.0, 0.0004], [32373.0, 0.0001], [32367.0, 0.0002], [32363.0, 0.0002], [32348.0, 1.0], [32343.0, 0.0004], [32342.0, 0.1315], [32333.0, 0.0005], [32331.0, 2.458], [32328.0, 0.6172], [32318.0, 0.0002], [32303.0, 0.0015], [32300.0, 0.1], [32289.0, 0.1421], [32282.0, 0.0002], [32252.0, 0.0004], [32247.0, 0.0002]], "asks": [[32824.0, 0.0003], [32829.0, 0.0155], [32834.0, 0.6445], [32837.0, 0.0298], [32840.0, 0.0974], [32841.0, 12.189], [32844.0, 0.1056], [32847.0, 0.0153], [32848.0, 0.0004], [32849.0, 0.0914], [32850.0, 0.01], [32854.0, 0.0883], [32855.0, 0.7652], [32857.0, 0.2282], [32858.0, 0.0002], [32860.0, 0.025], [32861.0, 1.13], [32863.0, 6.118], [32865.0, 0.0001], [32866.0, 0.3373], [32868.0, 0.0002], [32875.0, 0.539], [32876.0, 0.2382], [32877.0, 0.005], [32886.0, 0.2282], [32888.0, 0.02], [32890.0, 7.5795], [32891.0, 0.006], [32895.0, 0.2282], [32896.0, 0.6151], [32897.0, 0.6858], [32900.0, 0.01], [32905.0, 0.2282], [32909.0, 0.0005], [32923.0, 0.1], [32927.0, 0.4451], [32929.0, 0.0002], [32933.0, 0.4192], [32935.0, 8.9306], [32939.0, 0.0013], [32949.0, 0.0005], [32950.0, 0.0112], [32979.0, 0.6858], [32988.0, 0.4466], [33000.0, 0.01], [33010.0, 0.0004], [33024.0, 1.544], [33030.0, 0.0002], [33040.0, 0.0004], [33043.0, 0.4371], [33050.0, 0.0106], [33058.0, 0.6858], [33059.0, 12.0322], [33060.0, 0.0016], [33061.0, 0.6195], [33090.0, 0.0002], [33100.0, 1.127], [33111.0, 0.0002], [33121.0, 0.0003], [33127.0, 6.175], [33141.0, 0.0001], [33150.0, 0.01], [33151.0, 0.0006], [33162.0, 0.7494], [33171.0, 0.0007], [33181.0, 0.0005], [33191.0, 0.0002], [33202.0, 0.0004], [33212.0, 0.0003], [33214.0, 0.45], [33224.0, 0.0002], [33232.0, 0.0002], [33242.0, 0.0001], [33250.0, 0.001], [33251.0, 0.6294], [33252.0, 0.0006], [33256.0, 0.5], [33262.0, 0.0002], [33267.0, 2.438], [33272.0, 0.0004], [33290.0, 0.6342], [33292.0, 0.0001], [33303.0, 0.0007], [33310.0, 0.24], [33313.0, 0.0006], [33318.0, 0.0002], [33327.0, 0.025], [33333.0, 0.0123], [33353.0, 0.0004], [33363.0, 0.0008], [33385.0, 0.025], [33388.0, 0.0002], [33391.0, 0.8454], [33398.0, 0.168], [33400.0, 0.095], [33413.0, 0.0001], [33414.0, 0.0002], [33424.0, 0.0005], [33434.0, 0.0004], [33438.0, 0.0002]], "action": "partial"}}
1626993904.641972: {"channel": "orderbook", "market": "FLOW-PERP", "type": "partial", "data": {"time": 1626993904.6113424, "checksum": 235358000, "bids": [[16.415, 3.88], [16.41, 401.61], [16.4, 244.0], [16.395, 684.25], [16.39, 644.34], [16.385, 6.1], [16.38, 218.0], [16.37, 207.0], [16.36, 218.0], [16.35, 69.76], [16.33, 70.7], [16.325, 182.16], [16.32, 143.7], [16.275, 3420.1], [16.255, 240.53], [16.25, 265.39], [16.24, 2843.6], [16.2, 4415.97], [16.19, 338.27], [16.18, 711.8], [16.155, 0.23], [16.15, 309.59], [16.145, 1238.62], [16.135, 1104.73], [16.115, 416.33], [16.11, 0.1], [16.1, 310.55], [16.085, 0.08], [16.07, 0.04], [16.065, 457.91], [16.06, 0.2], [16.015, 334.76], [16.0, 412.6], [15.975, 4197.96], [15.965, 716.8], [15.945, 357.07], [15.91, 0.32], [15.905, 699.7], [15.885, 511.12], [15.855, 0.1], [15.85, 0.12], [15.835, 567.16], [15.83, 0.32], [15.825, 697.6], [15.755, 0.2], [15.75, 0.32], [15.74, 706.6], [15.71, 0.26], [15.705, 0.1], [15.7, 4000.0], [15.67, 0.32], [15.61, 2.88], [15.6, 17.11], [15.59, 0.32], [15.51, 0.32], [15.505, 0.1], [15.495, 208.59], [15.48, 0.1], [15.45, 0.2], [15.43, 0.32], [15.37, 463.57], [15.35, 0.32], [15.34, 100.0], [15.325, 0.3], [15.3, 250.1], [15.27, 0.32], [15.22, 262.77], [15.2, 33.89], [15.19, 0.32], [15.15, 0.2], [15.11, 6.93], [15.105, 674.14], [15.1, 0.1], [15.03, 0.32], [14.99, 6.67], [14.97, 0.33], [14.96, 0.1], [14.95, 0.32], [14.9, 250.0], [14.895, 0.1], [14.87, 0.32], [14.845, 0.4], [14.84, 20.0], [14.79, 892.23], [14.735, 953.28], [14.71, 0.32], [14.695, 0.3], [14.665, 7.58], [14.645, 0.38], [14.63, 0.32], [14.595, 25.0], [14.55, 69.04], [14.545, 0.2], [14.54, 0.2], [14.49, 0.1], [14.46, 0.32], [14.44, 0.1], [14.4, 50.0], [14.39, 0.2], [14.38, 0.32]], "asks": [[16.425, 286.62], [16.44, 69.0], [16.445, 1050.0], [16.455, 91.31], [16.465, 292.7], [16.475, 74.51], [16.48, 365.7], [16.485, 213.26], [16.5, 219.21], [16.51, 3431.4], [16.515, 0.1], [16.555, 0.08], [16.565, 600.56], [16.575, 0.02], [16.58, 2781.1], [16.605, 1427.2], [16.625, 4476.51], [16.635, 309.3], [16.65, 395.94], [16.665, 0.2], [16.68, 1558.94], [16.715, 307.12], [16.72, 25.0], [16.725, 98.41], [16.73, 1.0], [16.775, 536.57], [16.78, 456.22], [16.8, 100.0], [16.815, 4276.7], [16.84, 355.85], [16.85, 686.4], [16.86, 0.2], [16.905, 700.6], [16.915, 0.1], [16.96, 336.88], [16.965, 0.2], [16.99, 717.2], [16.995, 419.8], [17.0, 205.0], [17.04, 0.1], [17.1, 500.0], [17.115, 5.84], [17.12, 0.1], [17.125, 116.8], [17.145, 46.64], [17.2, 11835.44], [17.21, 50.0], [17.27, 0.2], [17.3, 500.0], [17.305, 2.6], [17.32, 0.1], [17.335, 219.32], [17.37, 0.96], [17.38, 80.0], [17.4, 70.0], [17.465, 2862.86], [17.48, 686.3], [17.5, 1760.0], [17.525, 0.1], [17.56, 0.1], [17.565, 9.0], [17.575, 0.2], [17.6, 2.84], [17.62, 1046.53], [17.66, 12.57], [17.7, 510.0], [17.725, 0.1], [17.77, 50.0], [17.8, 22522.0], [17.85, 142.61], [17.855, 0.3], [17.875, 0.2], [17.9, 540.2], [17.925, 0.1], [18.0, 6520.0], [18.08, 110.71], [18.1, 725.0], [18.13, 0.1], [18.18, 0.2], [18.21, 0.3], [18.3, 605.58], [18.32, 1048.73], [18.33, 0.1], [18.35, 833.88], [18.4, 1630.43], [18.405, 996.86], [18.48, 0.2], [18.5, 1200.0], [18.535, 0.1], [18.54, 10.9], [18.57, 0.3], [18.6, 100.1], [18.645, 18.33], [18.7, 500.0], [18.735, 0.1], [18.77, 2.66], [18.78, 200.0], [18.785, 0.2], [18.9, 1500.0], [18.925, 0.3]], "action": "partial"}}
1626993904.655926: {"channel": "orderbook", "market": "BTC-1231", "type": "update", "data": {"time": 1626993904.6310446, "checksum": 2305092153, "bids": [[32815.0, 0.0], [32242.0, 0.0004]], "asks": [], "action": "update"}}
1626993904.66557: {"channel": "orderbook", "market": "CHZ/USDT", "type": "update", "data": {"time": 1626993904.6446614, "checksum": 3768252139, "bids": [], "asks": [[0.23521, 3840.0], [0.5421, 0.0]], "action": "update"}}
1626993904.687365: {"channel": "orderbook", "market": "FLOW-PERP", "type": "update", "data": {"time": 1626993904.6651385, "checksum": 2278874198, "bids": [[16.415, 0.0], [14.335, 0.42]], "asks": [], "action": "update"}}
1626993904.736119: {"channel": "orderbook", "market": "BTC-1231", "type": "update", "data": {"time": 1626993904.7070196, "checksum": 3713802530, "bids": [[32816.0, 0.25], [32242.0, 0.0]], "asks": [[32896.0, 1.742]], "action": "update"}}
1626993904.751251: {"channel": "orderbook", "market": "BTC-1231", "type": "update", "data": {"time": 1626993904.7303536, "checksum": 1625963359, "bids": [[32815.0, 0.01], [32247.0, 0.0]], "asks": [], "action": "update"}}
1626993904.758804: {"channel": "orderbook", "market": "FLOW-PERP", "type": "update", "data": {"time": 1626993904.7383533, "checksum": 2396844181, "bids": [[16.355, 72.39], [14.335, 0.0]], "asks": [], "action": "update"}}
1626993904.785961: {"channel": "orderbook", "market": "FLOW-PERP", "type": "update", "data": {"time": 1626993904.765475, "checksum": 1880684468, "bids": [[16.42, 3.88], [14.38, 0.0]], "asks": [], "action": "update"}}
1626993904.830837: {"channel": "orderbook", "market": "BTC-1231", "type": "update", "data": {"time": 1626993904.8059816, "checksum": 3713802530, "bids": [[32815.0, 0.0], [32247.0, 0.0002]], "asks": [], "action": "update"}}
1626993904.944593: {"channel": "orderbook", "market": "BTC-1231", "type": "update", "data": {"time": 1626993904.922806, "checksum": 3053796506, "bids": [[32817.0, 0.01], [32247.0, 0.0]], "asks": [], "action": "update"}}
1626993904.966329: {"channel": "orderbook", "market": "KNCBULL/USDT", "type": "partial", "data": {"time": 1626993904.9430172, "checksum": 4188723151, "bids": [[0.4536, 1051.1], [0.4517, 10143.5], [0.4455, 13358.4], [0.4451, 12504.1], [0.4437, 1673.4], [0.4231, 164.0], [0.423, 3856.3], [0.4042, 31053.6], [0.2, 300.0], [0.1, 100.0]], "asks": [[0.4646, 0.1], [0.4654, 43.4], [0.4656, 1365.7], [0.4681, 7841.8], [0.4693, 11552.2], [0.476, 9786.0], [0.4895, 4197.4], [0.5287, 34560.2], [0.661, 0.6], [0.673, 0.6], [0.67425, 56.3], [0.685, 0.6], [0.697, 0.6], [0.708, 0.6], [0.716, 73.4], [0.72, 0.6], [0.732, 0.6], [0.744, 0.6], [0.756, 0.6], [0.767, 0.6], [0.779, 144.2], [0.791, 0.6], [0.803, 0.6], [0.815, 0.6], [0.826, 0.6], [0.827, 64.2], [0.838, 0.6], [0.85, 0.6], [0.862, 0.6], [0.87375, 63.7], [0.874, 0.6], [0.885, 0.6], [0.8865, 63.3], [0.897, 0.6], [0.909, 0.6], [0.921, 0.6], [0.933, 0.6], [0.944, 0.6], [0.956, 0.6], [0.968, 0.6], [0.98, 0.6], [0.992, 0.6], [1.003, 0.6], [1.015, 0.6], [1.027, 0.6], [1.039, 0.6], [1.051, 0.6], [1.062, 0.6], [1.074, 0.6], [1.086, 0.6], [1.098, 0.6], [1.11, 0.6], [1.121, 0.6], [1.133, 0.6], [1.145, 0.6], [1.157, 0.6], [1.169, 0.6], [1.18, 0.6], [1.192, 0.6], [1.204, 0.6], [1.216, 0.6], [1.228, 0.6], [1.239, 0.6], [1.251, 0.6], [1.263, 0.6], [1.275, 0.6], [1.287, 0.6], [1.298, 0.6], [1.31, 0.6], [1.322, 0.6], [1.334, 0.6], [1.346, 0.6], [1.357, 0.6], [1.369, 0.6], [1.381, 0.6], [1.393, 0.6], [1.405, 0.6], [1.416, 0.6], [1.428, 0.6], [1.44, 0.6], [1.452, 0.6], [1.464, 0.6], [1.475, 0.6], [1.487, 0.6], [1.499, 0.6], [1.511, 0.6], [1.523, 0.6], [1.534, 0.6], [1.546, 0.6], [1.558, 0.6], [1.57, 0.6], [1.582, 0.6], [1.593, 0.6], [1.605, 0.6], [1.617, 0.6], [1.629, 0.6], [1.641, 0.6], [1.652, 0.6], [1.664, 0.6], [1.676, 0.6]], "action": "partial"}}
1626993904.9826539: {"channel": "orderbook", "market": "BNBBEAR/USDT", "type": "partial", "data": {"time": 1626993904.9529226, "checksum": 884149509, "bids": [[1.3e-07, 99000000.0], [1.2e-07, 882000000.0], [1e-07, 91000000.0], [9e-08, 199000000.0], [8e-08, 118000000.0], [7e-08, 120000000.0], [6e-08, 297000000.0], [5e-08, 199000000.0], [4e-08, 97000000.0], [3e-08, 96000000.0], [1e-08, 5251000000.0]], "asks": [[1.4e-07, 594000000.0], [1.9e-07, 450000000.0], [5e-07, 198000000.0], [6e-07, 134000000.0], [6.4e-07, 41500000.0], [7e-07, 99000000.0], [8e-07, 99000000.0], [1.1e-06, 22000000.0], [1.2e-06, 33000000.0], [1.25e-06, 21000000.0], [1.48e-06, 63000000.0], [1.49e-06, 23000000.0], [1.5e-06, 636100000.0], [1.7e-06, 663200000.0], [1.8e-06, 1018900000.0], [2.44e-06, 10000000.0], [2.75e-06, 23000000.0], [3.66e-06, 10000000.0], [4e-06, 100000.0], [4.01e-06, 23000000.0], [4.15e-06, 72200000.0], [4.94e-06, 20500000.0], [7.7e-06, 23000000.0], [9.08e-06, 92800000.0], [1e-05, 99900000.0], [1.066e-05, 4000000.0], [1.13e-05, 209000000.0], [1.15e-05, 9000000.0], [1.18e-05, 20000000.0], [1.24e-05, 5000000.0], [1.3e-05, 2000000.0], [1.6e-05, 10000.0], [1.7e-05, 10000.0], [1.8e-05, 10000.0], [1.9e-05, 10000.0], [2e-05, 10000.0], [2.089e-05, 25620000.0], [5e-05, 198000000.0], [6e-05, 15000000.0], [6.3e-05, 3700000.0], [6.98e-05, 48600000.0], [6.981e-05, 30700000.0], [6.982e-05, 324400000.0], [8.779e-05, 12820000.0], [0.0001, 4000000.0], [0.000123, 19300000.0], [0.00015, 5000.0], [0.00019069, 5000000.0], [0.0003, 3700000.0], [0.0006, 9900000.0], [0.00063, 2700000.0], [0.001, 89900000.0], [0.002, 90090000.0], [0.00235, 59400000.0], [0.003, 20100000.0], [0.0043, 5000000.0], [0.00458654, 10000000.0], [0.005, 19000000.0], [0.0058, 8400000.0], [0.006, 3700000.0], [0.0068, 2021000.0], [0.009, 3200000.0], [0.00947, 7565000.0], [0.0096271, 2121100.0], [0.01, 15900000.0], [0.01062374, 10000000.0], [0.02, 86900000.0], [0.0222045, 2357400.0], [0.02234, 64390000.0], [0.03, 2700000.0], [0.0375, 61170.0], [0.04382725, 1000000.0], [0.049425, 14000000.0], [0.05, 10100000.0], [0.05432889, 15000000.0], [0.06, 10800000.0], [0.07307273, 1000000.0], [0.084783, 2699300.0], [0.08947, 6266000.0], [0.09, 100000.0], [0.1, 29603000.0], [0.1095184, 10000000.0], [0.14783, 10568200.0], [0.15610369, 5000000.0], [0.16255, 2.0], [0.1823, 100.0], [0.23079123, 1000000.0], [0.3, 2100000.0], [0.35, 77600.0], [0.41326944, 5000000.0], [0.5, 10730000.0], [0.9, 101597.0], [0.99, 10090000.0], [1.0, 8065690.0], [1.2791, 50.0], [1.29, 10000.0], [1.3, 6000000.0], [1.49, 10000.0], [1.5, 200.0], [1.6, 4120.0]], "action": "partial"}}
1626993905.022295: {"channel": "orderbook", "market": "BB-0924", "type": "partial", "data": {"time": 1626993904.9873579, "checksum": 3017106946, "bids": [[10.3575, 3.7], [10.345, 11.8], [10.3375, 16.4], [10.3225, 20.9], [10.3075, 20.1], [10.29, 25.0], [10.2575, 23.9], [10.2375, 25.7], [10.2175, 30.1], [10.195, 34.1], [10.175, 24.8], [10.145, 32.4], [9.715, 32.6], [9.2825, 50.0], [9.28, 87.9], [8.8525, 155.8], [8.4325, 124.1], [8.0225, 146.1], [7.6225, 175.2]], "asks": [[10.4375, 4.7], [10.455, 12.3], [10.465, 19.1], [10.48, 23.3], [10.4825, 16.5], [10.49, 13.1], [10.51, 27.2], [10.53, 25.0], [10.55, 20.8], [10.56, 22.7], [10.5825, 29.2], [10.6075, 33.3], [10.68, 24.5], [11.0525, 24.9], [11.5725, 136.9], [12.12, 127.6], [12.1825, 162.4], [12.79, 182.6], [13.8, 40.0], [14.1325, 201.6], [15.0, 0.5], [15.335, 0.5], [15.6675, 0.5], [16.0, 0.5], [18.7, 50.0], [20.0, 11.1]], "action": "partial"}}
1626993905.022562: {"channel": "orderbook", "market": "FLOW-PERP", "type": "update", "data": {"time": 1626993904.9873195, "checksum": 1124404078, "bids": [[16.145, 0.0], [14.38, 0.32]], "asks": [[16.68, 359.76]], "action": "update"}}
1626993905.033233: {"channel": "orderbook", "market": "BTC-1231", "type": "update", "data": {"time": 1626993905.0125692, "checksum": 98596998, "bids": [[32817.0, 0.26]], "asks": [], "action": "update"}}
1626993905.06046: {"channel": "orderbook", "market": "BTC-1231", "type": "update", "data": {"time": 1626993905.0359733, "checksum": 1806724334, "bids": [[32816.0, 0.0], [32247.0, 0.0002]], "asks": [], "action": "update"}}
1626993905.1110458: {"channel": "orderbook", "market": "FLOW-PERP", "type": "update", "data": {"time": 1626993905.087185, "checksum": 2837658684, "bids": [], "asks": [[16.68, 0.0], [18.935, 0.1]], "action": "update"}}
1626993905.2359092: {"channel": "orderbook", "market": "CAD/USD", "type": "update", "data": {"time": 1626993905.2084248, "checksum": 706162672, "bids": [], "asks": [], "action": "update"}}
1626993905.237452: {"channel": "orderbook", "market": "BTC-1231", "type": "update", "data": {"time": 1626993905.2171366, "checksum": 2575035588, "bids": [], "asks": [[32829.0, 0.0], [33442.0, 0.025]], "action": "update"}}
1626993905.299478: {"channel": "orderbook", "market": "MKR-PERP", "type": "update", "data": {"time": 1626993905.2744951, "checksum": 640576598, "bids": [], "asks": [], "action": "update"}}
1626993905.3608902: {"channel": "orderbook", "market": "APHA/USD", "type": "update", "data": {"time": 1626993905.3383255, "checksum": 3920446499, "bids": [], "asks": [], "action": "update"}}
1626993905.404126: {"channel": "orderbook", "market": "BB-0924", "type": "update", "data": {"time": 1626993905.359921, "checksum": 3756443364, "bids": [[10.3725, 9.2]], "asks": [], "action": "update"}}
1626993905.404253: {"channel": "orderbook", "market": "MKR-PERP", "type": "update", "data": {"time": 1626993905.3702903, "checksum": 1581592315, "bids": [], "asks": [[2416.0, 0.389]], "action": "update"}}
1626993905.4371681: {"channel": "orderbook", "market": "PFE/USD", "type": "update", "data": {"time": 1626993905.4141052, "checksum": 825829276, "bids": [], "asks": [], "action": "update"}}
1626993905.4616508: {"channel": "orderbook", "market": "CHZ/USDT", "type": "update", "data": {"time": 1626993905.4371915, "checksum": 3768252139, "bids": [], "asks": [], "action": "update"}}
1626993905.476831: {"channel": "orderbook", "market": "BTC-1231", "type": "update", "data": {"time": 1626993905.4557447, "checksum": 4193995251, "bids": [], "asks": [[32840.0, 0.3257]], "action": "update"}}
1626993905.612247: {"channel": "orderbook", "market": "APHA/USD", "type": "update", "data": {"time": 1626993905.5862596, "checksum": 2192870037, "bids": [[11.633, 87.4]], "asks": [], "action": "update"}}
1626993905.635668: {"channel": "orderbook", "market": "APHA/USD", "type": "update", "data": {"time": 1626993905.6125593, "checksum": 2169097776, "bids": [[11.631, 47.4]], "asks": [], "action": "update"}}
1626993905.646328: {"channel": "orderbook", "market": "BTC-1231", "type": "update", "data": {"time": 1626993905.624814, "checksum": 4193995251, "bids": [], "asks": [], "action": "update"}}
1626993905.658478: {"channel": "orderbook", "market": "FLOW-PERP", "type": "update", "data": {"time": 1626993905.6368768, "checksum": 2837658684, "bids": [], "asks": [], "action": "update"}}
1626993905.711274: {"channel": "orderbook", "market": "FLOW-PERP", "type": "update", "data": {"time": 1626993905.691157, "checksum": 1984328050, "bids": [[16.155, 1609.44]], "asks": [], "action": "update"}}
1626993905.780836: {"channel": "orderbook", "market": "BB-0924", "type": "update", "data": {"time": 1626993905.7599683, "checksum": 3017106946, "bids": [[10.3725, 0.0]], "asks": [], "action": "update"}}
1626993905.788401: {"channel": "orderbook", "market": "FLOW-PERP", "type": "update", "data": {"time": 1626993905.7660728, "checksum": 3003810591, "bids": [], "asks": [[16.69, 1558.01], [18.935, 0.0]], "action": "update"}}
1626993905.8132439: {"channel": "orderbook", "market": "FLOW-PERP", "type": "update", "data": {"time": 1626993905.7901762, "checksum": 2438839051, "bids": [[16.375, 30.27], [14.38, 0.0]], "asks": [], "action": "update"}}
1626993905.819087: {"channel": "orderbook", "market": "BTC-1231", "type": "update", "data": {"time": 1626993905.7981443, "checksum": 2280546563, "bids": [], "asks": [[32824.0, 0.0], [33447.0, 0.168]], "action": "update"}}
1626993905.8505: {"channel": "orderbook", "market": "BTC-1231", "type": "update", "data": {"time": 1626993905.8261878, "checksum": 873145631, "bids": [[32817.0, 0.01]], "asks": [], "action": "update"}}
1626993905.87812: {"channel": "orderbook", "market": "MKR-PERP", "type": "update", "data": {"time": 1626993905.8519828, "checksum": 3519146848, "bids": [], "asks": [[2417.0, 0.0], [2445.5, 12.267], [2795.5, 0.024]], "action": "update"}}
1626993905.922816: {"channel": "orderbook", "market": "BTC-1231", "type": "update", "data": {"time": 1626993905.8998063, "checksum": 1401974672, "bids": [[32817.0, 0.0], [32242.0, 0.0004]], "asks": [[32826.0, 0.0003], [33447.0, 0.0]], "action": "update"}}
1626993905.955947: {"channel": "orderbook", "market": "APHA/USD", "type": "update", "data": {"time": 1626993905.9333522, "checksum": 2172402314, "bids": [[11.633, 0.0]], "asks": [], "action": "update"}}
1626993905.969575: {"channel": "orderbook", "market": "MKR-PERP", "type": "update", "data": {"time": 1626993905.942008, "checksum": 1912494857, "bids": [], "asks": [[2417.5, 0.868]], "action": "update"}}
1626993905.98573: {"channel": "orderbook", "market": "KNCBULL/USDT", "type": "update", "data": {"time": 1626993905.9646504, "checksum": 4188723151, "bids": [], "asks": [], "action": "update"}}
1626993905.995425: {"channel": "orderbook", "market": "BNBBEAR/USDT", "type": "update", "data": {"time": 1626993905.9744365, "checksum": 884149509, "bids": [], "asks": [], "action": "update"}}
1626993906.003357: {"channel": "orderbook", "market": "BTC-1231", "type": "update", "data": {"time": 1626993905.9799724, "checksum": 1500601693, "bids": [[32817.0, 0.25], [32242.0, 0.0]], "asks": [], "action": "update"}}
1626993906.022893: {"channel": "orderbook", "market": "MKR-PERP", "type": "update", "data": {"time": 1626993905.9894352, "checksum": 3782059678, "bids": [], "asks": [[2445.0, 58.039]], "action": "update"}}
1626993906.0438058: {"channel": "orderbook", "market": "BB-0924", "type": "update", "data": {"time": 1626993906.0224056, "checksum": 3017106946, "bids": [], "asks": [], "action": "update"}}
1626993906.064335: {"channel": "orderbook", "market": "BTC-1231", "type": "update", "data": {"time": 1626993906.0405107, "checksum": 2810731138, "bids": [[32815.0, 0.01], [32247.0, 0.0]], "asks": [], "action": "update"}}
1626993906.131541: {"channel": "orderbook", "market": "BTC-1231", "type": "update", "data": {"time": 1626993906.100179, "checksum": 306326140, "bids": [[32818.0, 0.25], [32815.0, 0.0]], "asks": [], "action": "update"}}
1626993906.180629: {"channel": "orderbook", "market": "BTC-1231", "type": "update", "data": {"time": 1626993906.153601, "checksum": 4226499431, "bids": [[32817.0, 0.0], [32247.0, 0.0002]], "asks": [], "action": "update"}}
1626993906.23087: {"channel": "orderbook", "market": "BTC-1231", "type": "update", "data": {"time": 1626993906.2062697, "checksum": 2242210883, "bids": [[32819.0, 0.26], [32247.0, 0.0]], "asks": [], "action": "update"}}
1626993906.274289: {"channel": "orderbook", "market": "BTC-1231", "type": "update", "data": {"time": 1626993906.2524512, "checksum": 1904980568, "bids": [[32818.0, 0.0], [32247.0, 0.0002]], "asks": [], "action": "update"}}
1626993906.295518: {"channel": "orderbook", "market": "CAD/USD", "type": "update", "data": {"time": 1626993906.270263, "checksum": 706162672, "bids": [], "asks": [], "action": "update"}}
1626993906.316685: {"channel": "orderbook", "market": "MKR-PERP", "type": "update", "data": {"time": 1626993906.2920766, "checksum": 3782059678, "bids": [], "asks": [], "action": "update"}}
1626993906.391616: {"channel": "orderbook", "market": "APHA/USD", "type": "update", "data": {"time": 1626993906.3703, "checksum": 2172402314, "bids": [], "asks": [], "action": "update"}}
1626993906.4124181: {"channel": "orderbook", "market": "BTC-1231", "type": "update", "data": {"time": 1626993906.381463, "checksum": 285939567, "bids": [], "asks": [[32840.0, 0.0974]], "action": "update"}}
1626993906.471227: {"channel": "orderbook", "market": "PFE/USD", "type": "update", "data": {"time": 1626993906.4491665, "checksum": 825829276, "bids": [], "asks": [], "action": "update"}}
1626993906.490852: {"channel": "orderbook", "market": "CHZ/USDT", "type": "update", "data": {"time": 1626993906.4635644, "checksum": 3768252139, "bids": [], "asks": [], "action": "update"}}
1626993906.5748749: {"channel": "orderbook", "market": "MKR-PERP", "type": "update", "data": {"time": 1626993906.5472329, "checksum": 1232212617, "bids": [], "asks": [[2416.0, 0.755]], "action": "update"}}
1626993906.678916: {"channel": "orderbook", "market": "FLOW-PERP", "type": "update", "data": {"time": 1626993906.650688, "checksum": 2438839051, "bids": [], "asks": [], "action": "update"}}
1626993906.713036: {"channel": "orderbook", "market": "FLOW-PERP", "type": "update", "data": {"time": 1626993906.6928756, "checksum": 3822013496, "bids": [[16.395, 705.16]], "asks": [], "action": "update"}}
1626993906.7320461: {"channel": "orderbook", "market": "BTC-1231", "type": "update", "data": {"time": 1626993906.7080052, "checksum": 2692291341, "bids": [[32819.0, 0.25]], "asks": [], "action": "update"}}
1626993906.7933178: {"channel": "orderbook", "market": "FLOW-PERP", "type": "update", "data": {"time": 1626993906.7727642, "checksum": 49939742, "bids": [], "asks": [[16.45, 75.59], [18.925, 0.0]], "action": "update"}}
1626993906.796691: {"channel": "orderbook", "market": "BTC-1231", "type": "update", "data": {"time": 1626993906.7749999, "checksum": 3707289079, "bids": [], "asks": [[32844.0, 12.7696]], "action": "update"}}
1626993906.829639: {"channel": "orderbook", "market": "BTC-1231", "type": "update", "data": {"time": 1626993906.8062494, "checksum": 1197843971, "bids": [[32820.0, 0.01], [32247.0, 0.0]], "asks": [[32841.0, 0.0276]], "action": "update"}}
1626993906.885391: {"channel": "orderbook", "market": "BTC-1231", "type": "update", "data": {"time": 1626993906.858158, "checksum": 2378020318, "bids": [[32819.0, 0.0], [32247.0, 0.0002]], "asks": [[32840.0, 0.095]], "action": "update"}}
1626993906.92534: {"channel": "orderbook", "market": "BTC-1231", "type": "update", "data": {"time": 1626993906.9035325, "checksum": 4029375003, "bids": [], "asks": [[32843.0, 0.0024], [33442.0, 0.0]], "action": "update"}}
1626993906.948813: {"channel": "orderbook", "market": "BTC-1231", "type": "update", "data": {"time": 1626993906.9278226, "checksum": 2394830834, "bids": [[32820.0, 0.0], [32242.0, 0.0004]], "asks": [], "action": "update"}}
1626993907.014478: {"channel": "orderbook", "market": "FLOW-PERP", "type": "update", "data": {"time": 1626993906.972954, "checksum": 1073803383, "bids": [], "asks": [[16.425, 356.8]], "action": "update"}}
1626993907.021294: {"channel": "orderbook", "market": "KNCBULL/USDT", "type": "update", "data": {"time": 1626993906.9937263, "checksum": 4188723151, "bids": [], "asks": [], "action": "update"}}
1626993907.024449: {"channel": "orderbook", "market": "BNBBEAR/USDT", "type": "update", "data": {"time": 1626993907.000379, "checksum": 884149509, "bids": [], "asks": [], "action": "update"}}
1626993907.034276: {"channel": "orderbook", "market": "BTC-1231", "type": "update", "data": {"time": 1626993907.010596, "checksum": 4196570297, "bids": [[32821.0, 0.01], [32817.0, 0.25], [32247.0, 0.0], [32242.0, 0.0]], "asks": [], "action": "update"}}
1626993907.077261: {"channel": "orderbook", "market": "BTC-1231", "type": "update", "data": {"time": 1626993907.055928, "checksum": 3061056192, "bids": [[32821.0, 0.0], [32817.0, 0.0], [32247.0, 0.0002], [32242.0, 0.0004]], "asks": [[32896.0, 0.6151]], "action": "update"}}
1626993907.119152: {"channel": "orderbook", "market": "BB-0924", "type": "update", "data": {"time": 1626993907.0719714, "checksum": 3017106946, "bids": [], "asks": [], "action": "update"}}
1626993907.129472: {"channel": "orderbook", "market": "BTC-1231", "type": "update", "data": {"time": 1626993907.1072059, "checksum": 3902007555, "bids": [[32808.0, 10.6615]], "asks": [], "action": "update"}}
1626993907.14854: {"channel": "orderbook", "market": "BTC-1231", "type": "update", "data": {"time": 1626993907.1268294, "checksum": 1517195094, "bids": [[32817.0, 0.25], [32805.0, 0.0]], "asks": [], "action": "update"}}
1626993907.186039: {"channel": "orderbook", "market": "BTC-1231", "type": "update", "data": {"time": 1626993907.1578586, "checksum": 469433806, "bids": [[32815.0, 0.01], [32242.0, 0.0]], "asks": [], "action": "update"}}
1626993907.227398: {"channel": "orderbook", "market": "CHZ/USDT", "type": "update", "data": {"time": 1626993907.2065768, "checksum": 479938036, "bids": [[0.228214, 2440.0]], "asks": [], "action": "update"}}
1626993907.247963: {"channel": "orderbook", "market": "BTC-1231", "type": "update", "data": {"time": 1626993907.2192934, "checksum": 2865331989, "bids": [[32818.0, 0.25], [32815.0, 0.0]], "asks": [[32908.0, 1.0983], [33438.0, 0.0]], "action": "update"}}
1626993907.27564: {"channel": "orderbook", "market": "CHZ/USDT", "type": "update", "data": {"time": 1626993907.2543309, "checksum": 3768252139, "bids": [[0.228214, 0.0]], "asks": [], "action": "update"}}
1626993907.290299: {"channel": "orderbook", "market": "BTC-1231", "type": "update", "data": {"time": 1626993907.2657552, "checksum": 2060159514, "bids": [[32817.0, 0.0], [32242.0, 0.0004]], "asks": [], "action": "update"}}
1626993907.3209238: {"channel": "orderbook", "market": "BTC-1231", "type": "update", "data": {"time": 1626993907.296701, "checksum": 3200135183, "bids": [[32819.0, 0.25], [32242.0, 0.0]], "asks": [], "action": "update"}}
1626993907.34429: {"channel": "orderbook", "market": "MKR-PERP", "type": "update", "data": {"time": 1626993907.3182018, "checksum": 1232212617, "bids": [], "asks": [], "action": "update"}}
1626993907.3518: {"channel": "orderbook", "market": "BTC-1231", "type": "update", "data": {"time": 1626993907.3264775, "checksum": 919215258, "bids": [[32819.0, 0.26], [32818.0, 0.0], [32242.0, 0.0004]], "asks": [[32841.0, 11.1974]], "action": "update"}}
1626993907.363494: {"channel": "orderbook", "market": "CAD/USD", "type": "update", "data": {"time": 1626993907.340532, "checksum": 706162672, "bids": [], "asks": [], "action": "update"}}
1626993907.373097: {"channel": "orderbook", "market": "BTC-1231", "type": "update", "data": {"time": 1626993907.3468359, "checksum": 448087427, "bids": [[32819.0, 0.01]], "asks": [[32844.0, 0.1056]], "action": "update"}}
1626993907.408396: {"channel": "orderbook", "market": "APHA/USD", "type": "update", "data": {"time": 1626993907.3887122, "checksum": 2172402314, "bids": [], "asks": [], "action": "update"}}
1626993907.4382432: {"channel": "orderbook", "market": "BTC-1231", "type": "update", "data": {"time": 1626993907.4105291, "checksum": 1572494344, "bids": [[32819.0, 0.0], [32237.0, 0.1526]], "asks": [[32840.0, 0.0974], [32843.0, 0.0], [33438.0, 0.0002]], "action": "update"}}
1626993907.45838: {"channel": "orderbook", "market": "MKR-PERP", "type": "update", "data": {"time": 1626993907.4171443, "checksum": 3436214991, "bids": [[2414.5, 0.0], [2099.0, 0.001]], "asks": [], "action": "update"}}
1626993907.5051131: {"channel": "orderbook", "market": "PFE/USD", "type": "update", "data": {"time": 1626993907.4840844, "checksum": 825829276, "bids": [], "asks": [], "action": "update"}}
1626993907.519369: {"channel": "orderbook", "market": "CHZ/USDT", "type": "update", "data": {"time": 1626993907.4976733, "checksum": 3768252139, "bids": [], "asks": [], "action": "update"}}
1626993907.526783: {"channel": "orderbook", "market": "MKR-PERP", "type": "update", "data": {"time": 1626993907.5034688, "checksum": 1696606473, "bids": [], "asks": [[2416.0, 0.389], [2420.0, 3.916]], "action": "update"}}
1626993907.5322502: {"channel": "orderbook", "market": "BTC-1231", "type": "update", "data": {"time": 1626993907.507355, "checksum": 437373918, "bids": [[32817.0, 0.25], [32815.0, 0.01], [32747.0, 0.005], [32247.0, 0.0], [32242.0, 0.0], [32237.0, 0.0]], "asks": [], "action": "update"}}
1626993907.5801442: {"channel": "orderbook", "market": "BTC-1231", "type": "update", "data": {"time": 1626993907.558556, "checksum": 1039986464, "bids": [[32815.0, 0.0], [32247.0, 0.0002]], "asks": [[32846.0, 0.2283], [33438.0, 0.0]], "action": "update"}}
1626993907.602932: {"channel": "orderbook", "market": "BTC-1231", "type": "update", "data": {"time": 1626993907.5794842, "checksum": 2119157283, "bids": [[32818.0, 0.25], [32247.0, 0.0]], "asks": [], "action": "update"}}
1626993907.6360152: {"channel": "orderbook", "market": "MKR-PERP", "type": "update", "data": {"time": 1626993907.609824, "checksum": 2421150104, "bids": [], "asks": [[2416.0, 0.779]], "action": "update"}}
1626993907.679569: {"channel": "orderbook", "market": "BTC-1231", "type": "update", "data": {"time": 1626993907.6539733, "checksum": 3308964062, "bids": [[32819.0, 0.25], [32818.0, 0.26], [32817.0, 0.0]], "asks": [], "action": "update"}}
1626993907.716317: {"channel": "orderbook", "market": "FLOW-PERP", "type": "update", "data": {"time": 1626993907.6815948, "checksum": 1073803383, "bids": [], "asks": [], "action": "update"}}
1626993907.724948: {"channel": "orderbook", "market": "BTC-1231", "type": "update", "data": {"time": 1626993907.6898649, "checksum": 2504761862, "bids": [[32819.0, 0.0], [32818.0, 0.01], [32247.0, 0.0002]], "asks": [], "action": "update"}}
1626993907.759062: {"channel": "orderbook", "market": "BTC-1231", "type": "update", "data": {"time": 1626993907.7303927, "checksum": 2504761862, "bids": [], "asks": [], "action": "update"}}
1626993907.795541: {"channel": "orderbook", "market": "CHZ/USDT", "type": "update", "data": {"time": 1626993907.7728276, "checksum": 3554660134, "bids": [[0.227612, 0.0]], "asks": [], "action": "update"}}
1626993907.795685: {"channel": "orderbook", "market": "BTC-1231", "type": "update", "data": {"time": 1626993907.7670686, "checksum": 3280833782, "bids": [[32819.0, 0.25], [32818.0, 0.0], [32812.0, 0.0309], [32247.0, 0.0]], "asks": [[32826.0, 0.0], [32837.0, 0.0], [32845.0, 12.6096], [33438.0, 0.0002]], "action": "update"}}
1626993907.830567: {"channel": "orderbook", "market": "BTC-1231", "type": "update", "data": {"time": 1626993907.8043687, "checksum": 3961401191, "bids": [[32819.0, 0.0013], [32811.0, 12.0314], [32252.0, 0.0]], "asks": [[32841.0, 0.0276]], "action": "update"}}
1626993907.8601768: {"channel": "orderbook", "market": "BTC-1231", "type": "update", "data": {"time": 1626993907.8353224, "checksum": 1151606345, "bids": [[32808.0, 0.6229]], "asks": [], "action": "update"}}
1626993907.874273: {"channel": "orderbook", "market": "BTC-1231", "type": "update", "data": {"time": 1626993907.8531928, "checksum": 1908092236, "bids": [[32791.0, 0.464]], "asks": [], "action": "update"}}
1626993907.925638: {"channel": "orderbook", "market": "BTC-1231", "type": "update", "data": {"time": 1626993907.8927777, "checksum": 1467903602, "bids": [], "asks": [[32840.0, 0.095], [32844.0, 0.108]], "action": "update"}}
1626993907.9368541: {"channel": "orderbook", "market": "CHZ/USDT", "type": "update", "data": {"time": 1626993907.9160166, "checksum": 2538723625, "bids": [[0.227645, 0.0]], "asks": [], "action": "update"}}
1626993907.958883: {"channel": "orderbook", "market": "BTC-1231", "type": "update", "data": {"time": 1626993907.9382021, "checksum": 1968070146, "bids": [[32820.0, 0.01], [32282.0, 0.0]], "asks": [], "action": "update"}}
1626993908.025953: {"channel": "orderbook", "market": "BTC-1231", "type": "update", "data": {"time": 1626993907.9991558, "checksum": 470200211, "bids": [[32820.0, 0.0], [32747.0, 0.0], [32282.0, 0.0002], [32252.0, 0.0004]], "asks": [], "action": "update"}}
1626993908.038977: {"channel": "orderbook", "market": "KNCBULL/USDT", "type": "update", "data": {"time": 1626993908.0161142, "checksum": 4188723151, "bids": [], "asks": [], "action": "update"}}
1626993908.045391: {"channel": "orderbook", "market": "BNBBEAR/USDT", "type": "update", "data": {"time": 1626993908.0232146, "checksum": 884149509, "bids": [], "asks": [], "action": "update"}}
1626993908.113251: {"channel": "orderbook", "market": "BTC-1231", "type": "update", "data": {"time": 1626993908.0705981, "checksum": 1395232171, "bids": [[32819.0, 0.25]], "asks": [], "action": "update"}}
1626993908.1451871: {"channel": "orderbook", "market": "BB-0924", "type": "update", "data": {"time": 1626993908.1152666, "checksum": 3017106946, "bids": [], "asks": [], "action": "update"}}
1626993908.151577: {"channel": "orderbook", "market": "BTC-1231", "type": "update", "data": {"time": 1626993908.1291533, "checksum": 14710316, "bids": [], "asks": [[32828.0, 0.0003], [33438.0, 0.0]], "action": "update"}}
1626993908.188801: {"channel": "orderbook", "market": "CHZ/USDT", "type": "update", "data": {"time": 1626993908.166882, "checksum": 2595529571, "bids": [[0.227682, 4570.0], [0.227655, 9140.0]], "asks": [], "action": "update"}}
1626993908.197194: {"channel": "orderbook", "market": "BTC-1231", "type": "update", "data": {"time": 1626993908.173973, "checksum": 647228857, "bids": [[32815.0, 0.01], [32252.0, 0.0]], "asks": [], "action": "update"}}
1626993908.250738: {"channel": "orderbook", "market": "BTC-1231", "type": "update", "data": {"time": 1626993908.22627, "checksum": 672149657, "bids": [[32820.0, 0.25], [32282.0, 0.0]], "asks": [], "action": "update"}}
1626993908.276854: {"channel": "orderbook", "market": "BTC-1231", "type": "update", "data": {"time": 1626993908.253051, "checksum": 2492224350, "bids": [[32815.0, 0.0], [32282.0, 0.0002]], "asks": [], "action": "update"}}
1626993908.286439: {"channel": "orderbook", "market": "FLOW-PERP", "type": "update", "data": {"time": 1626993908.2616532, "checksum": 1280458540, "bids": [[16.41, 99.61]], "asks": [], "action": "update"}}
1626993908.32685: {"channel": "orderbook", "market": "BTC-1231", "type": "update", "data": {"time": 1626993908.3004775, "checksum": 2962813172, "bids": [[32821.0, 0.25], [32819.0, 0.0]], "asks": [], "action": "update"}}
1626993908.36517: {"channel": "orderbook", "market": "BTC-1231", "type": "update", "data": {"time": 1626993908.3425565, "checksum": 1313637935, "bids": [[32821.0, 0.0], [32820.0, 0.0], [32252.0, 0.0004], [32247.0, 0.0002]], "asks": [], "action": "update"}}
1626993908.3657541: {"channel": "orderbook", "market": "MKR-PERP", "type": "update", "data": {"time": 1626993908.3428915, "checksum": 2421150104, "bids": [], "asks": [], "action": "update"}}
1626993908.4077818: {"channel": "orderbook", "market": "CAD/USD", "type": "update", "data": {"time": 1626993908.3839865, "checksum": 706162672, "bids": [], "asks": [], "action": "update"}}
1626993908.438117: {"channel": "orderbook", "market": "APHA/USD", "type": "update", "data": {"time": 1626993908.4106743, "checksum": 2172402314, "bids": [], "asks": [], "action": "update"}}
1626993908.4425752: {"channel": "orderbook", "market": "BTC-1231", "type": "update", "data": {"time": 1626993908.400448, "checksum": 3573581868, "bids": [[32821.0, 0.01], [32811.0, 0.0], [32808.0, 7.6163], [32713.0, 0.2292], [32247.0, 0.0]], "asks": [[32841.0, 12.1451]], "action": "update"}}
1626993908.48393: {"channel": "orderbook", "market": "BTC-1231", "type": "update", "data": {"time": 1626993908.459757, "checksum": 1955784712, "bids": [[32821.0, 0.0], [32818.0, 0.25]], "asks": [[32845.0, 0.0], [33438.0, 0.0002]], "action": "update"}}
1626993908.494099: {"channel": "orderbook", "market": "MKR-PERP", "type": "update", "data": {"time": 1626993908.4669158, "checksum": 836189698, "bids": [], "asks": [[2416.5, 1.546]], "action": "update"}}
1626993908.535498: {"channel": "orderbook", "market": "PFE/USD", "type": "update", "data": {"time": 1626993908.5146728, "checksum": 825829276, "bids": [], "asks": [], "action": "update"}}
1626993908.541145: {"channel": "orderbook", "market": "MKR-PERP", "type": "update", "data": {"time": 1626993908.512427, "checksum": 3678218304, "bids": [[2414.5, 0.617], [2099.0, 0.0]], "asks": [[2415.5, 0.414], [2795.5, 0.0]], "action": "update"}}
1626993908.549845: {"channel": "orderbook", "market": "CHZ/USDT", "type": "update", "data": {"time": 1626993908.5240855, "checksum": 2595529571, "bids": [], "asks": [], "action": "update"}}
1626993908.5583081: {"channel": "orderbook", "market": "BTC-1231", "type": "update", "data": {"time": 1626993908.522106, "checksum": 1219678527, "bids": [[32821.0, 0.25], [32818.0, 0.0], [32747.0, 0.005], [32252.0, 0.0]], "asks": [[32844.0, 0.1056]], "action": "update"}}
1626993908.586049: {"channel": "orderbook", "market": "BTC-1231", "type": "update", "data": {"time": 1626993908.564682, "checksum": 3982266385, "bids": [[32821.0, 0.0], [32252.0, 0.0004]], "asks": [[32840.0, 0.0974]], "action": "update"}}
1626993908.607475: {"channel": "orderbook", "market": "MKR-PERP", "type": "update", "data": {"time": 1626993908.5859785, "checksum": 2350410980, "bids": [], "asks": [[2415.5, 0.0], [2416.0, 0.389], [2795.5, 0.024]], "action": "update"}}
1626993908.641686: {"channel": "orderbook", "market": "BTC-1231", "type": "update", "data": {"time": 1626993908.6169956, "checksum": 288905166, "bids": [[32822.0, 0.01], [32713.0, 0.0]], "asks": [], "action": "update"}}
1626993908.6921139: {"channel": "orderbook", "market": "BTC-1231", "type": "update", "data": {"time": 1626993908.670077, "checksum": 3905761884, "bids": [[32822.0, 0.0], [32817.0, 0.25]], "asks": [], "action": "update"}}
1626993908.7196102: {"channel": "orderbook", "market": "MKR-PERP", "type": "update", "data": {"time": 1626993908.6982863, "checksum": 2466160578, "bids": [], "asks": [[2416.0, 0.761]], "action": "update"}}
1626993908.7420459: {"channel": "orderbook", "market": "FLOW-PERP", "type": "update", "data": {"time": 1626993908.7166724, "checksum": 1280458540, "bids": [], "asks": [], "action": "update"}}
1626993908.783938: {"channel": "orderbook", "market": "BTC-1231", "type": "update", "data": {"time": 1626993908.7599697, "checksum": 2119074192, "bids": [[32819.0, 0.25], [32818.0, 0.01], [32282.0, 0.0], [32252.0, 0.0]], "asks": [], "action": "update"}}
1626993908.832961: {"channel": "orderbook", "market": "BTC-1231", "type": "update", "data": {"time": 1626993908.8124366, "checksum": 860429682, "bids": [], "asks": [[32908.0, 0.0], [33442.0, 0.025]], "action": "update"}}
1626993908.853332: {"channel": "orderbook", "market": "BTC-1231", "type": "update", "data": {"time": 1626993908.8328102, "checksum": 2743992396, "bids": [[32818.0, 0.0], [32817.0, 0.0], [32282.0, 0.0002], [32252.0, 0.0004]], "asks": [], "action": "update"}}
1626993908.8895621: {"channel": "orderbook", "market": "BTC-1231", "type": "update", "data": {"time": 1626993908.8621843, "checksum": 1118697290, "bids": [[32820.0, 0.25], [32252.0, 0.0]], "asks": [], "action": "update"}}
1626993908.9061718: {"channel": "orderbook", "market": "BTC-1231", "type": "update", "data": {"time": 1626993908.882915, "checksum": 2774094180, "bids": [[32819.0, 0.0], [32252.0, 0.0004]], "asks": [], "action": "update"}}
1626993908.972289: {"channel": "orderbook", "market": "BTC-1231", "type": "update", "data": {"time": 1626993908.9499848, "checksum": 2925129233, "bids": [[32820.0, 0.26]], "asks": [[32899.0, 1.0844], [33442.0, 0.0]], "action": "update"}}
1626993909.04378: {"channel": "orderbook", "market": "BTC-1231", "type": "update", "data": {"time": 1626993909.0233948, "checksum": 2095554200, "bids": [[32747.0, 0.0], [32247.0, 0.0002]], "asks": [], "action": "update"}}
1626993909.067598: {"channel": "orderbook", "market": "KNCBULL/USDT", "type": "update", "data": {"time": 1626993909.0457716, "checksum": 4188723151, "bids": [], "asks": [], "action": "update"}}
1626993909.075555: {"channel": "orderbook", "market": "BNBBEAR/USDT", "type": "update", "data": {"time": 1626993909.048302, "checksum": 884149509, "bids": [], "asks": [], "action": "update"}}
1626993909.172595: {"channel": "orderbook", "market": "BB-0924", "type": "update", "data": {"time": 1626993909.1458855, "checksum": 3017106946, "bids": [], "asks": [], "action": "update"}}
1626993909.2086241: {"channel": "orderbook", "market": "FLOW-PERP", "type": "update", "data": {"time": 1626993909.1845038, "checksum": 227203440, "bids": [[16.36, 299.08]], "asks": [], "action": "update"}}
1626993909.214908: {"channel": "orderbook", "market": "CHZ/USDT", "type": "update", "data": {"time": 1626993909.1884162, "checksum": 1002070214, "bids": [[0.227762, 0.0]], "asks": [], "action": "update"}}
1626993909.2542279: {"channel": "orderbook", "market": "FLOW-PERP", "type": "update", "data": {"time": 1626993909.23281, "checksum": 2237234786, "bids": [], "asks": [[16.47, 83.04], [18.9, 0.0]], "action": "update"}}
1626993909.333616: {"channel": "orderbook", "market": "MKR-PERP", "type": "update", "data": {"time": 1626993909.308182, "checksum": 1053918350, "bids": [], "asks": [[2445.0, 0.039]], "action": "update"}}
1626993909.3419251: {"channel": "orderbook", "market": "BTC-1231", "type": "update", "data": {"time": 1626993909.3195522, "checksum": 826122436, "bids": [], "asks": [[32846.0, 0.0], [33442.0, 0.025]], "action": "update"}}
1626993909.386867: {"channel": "orderbook", "market": "MKR-PERP", "type": "update", "data": {"time": 1626993909.3633049, "checksum": 1053918350, "bids": [], "asks": [], "action": "update"}}
1626993909.452141: {"channel": "orderbook", "market": "CAD/USD", "type": "update", "data": {"time": 1626993909.4268918, "checksum": 706162672, "bids": [], "asks": [], "action": "update"}}
1626993909.460659: {"channel": "orderbook", "market": "APHA/USD", "type": "update", "data": {"time": 1626993909.4409633, "checksum": 2172402314, "bids": [], "asks": [], "action": "update"}}
1626993909.4614909: {"channel": "orderbook", "market": "CHZ/USDT", "type": "update", "data": {"time": 1626993909.4408798, "checksum": 334723797, "bids": [[0.227803, 9120.0]], "asks": [], "action": "update"}}
1626993909.573281: {"channel": "orderbook", "market": "PFE/USD", "type": "update", "data": {"time": 1626993909.5520144, "checksum": 825829276, "bids": [], "asks": [], "action": "update"}}
1626993909.5849102: {"channel": "orderbook", "market": "CHZ/USDT", "type": "update", "data": {"time": 1626993909.5538807, "checksum": 334723797, "bids": [], "asks": [], "action": "update"}}
1626993909.586996: {"channel": "orderbook", "market": "BTC-1231", "type": "update", "data": {"time": 1626993909.566778, "checksum": 3155164345, "bids": [[32747.0, 0.005], [32247.0, 0.0]], "asks": [], "action": "update"}}
1626993909.766678: {"channel": "orderbook", "market": "MKR-PERP", "type": "update", "data": {"time": 1626993909.7412045, "checksum": 172446671, "bids": [], "asks": [[2420.0, 4.996]], "action": "update"}}
1626993909.766795: {"channel": "orderbook", "market": "FLOW-PERP", "type": "update", "data": {"time": 1626993909.737125, "checksum": 2237234786, "bids": [], "asks": [], "action": "update"}}
1626993909.812196: {"channel": "orderbook", "market": "BTC-1231", "type": "update", "data": {"time": 1626993909.7889864, "checksum": 3155164345, "bids": [], "asks": [], "action": "update"}}
1626993909.886336: {"channel": "orderbook", "market": "MKR-PERP", "type": "update", "data": {"time": 1626993909.8582323, "checksum": 3980795229, "bids": [], "asks": [[2416.0, 0.389]], "action": "update"}}
1626993909.886455: {"channel": "orderbook", "market": "FLOW-PERP", "type": "update", "data": {"time": 1626993909.862124, "checksum": 1229357867, "bids": [[16.35, 0.0], [14.38, 0.32]], "asks": [], "action": "update"}}
1626993910.1039848: {"channel": "orderbook", "market": "BNBBEAR/USDT", "type": "update", "data": {"time": 1626993910.0792694, "checksum": 884149509, "bids": [], "asks": [], "action": "update"}}
1626993910.104104: {"channel": "orderbook", "market": "FLOW-PERP", "type": "update", "data": {"time": 1626993910.0794775, "checksum": 3954965117, "bids": [[16.415, 233.0], [14.38, 0.0]], "asks": [], "action": "update"}}
1626993910.112929: {"channel": "orderbook", "market": "KNCBULL/USDT", "type": "update", "data": {"time": 1626993910.0829778, "checksum": 4188723151, "bids": [], "asks": [], "action": "update"}}
1626993910.19441: {"channel": "orderbook", "market": "BB-0924", "type": "update", "data": {"time": 1626993910.171478, "checksum": 3017106946, "bids": [], "asks": [], "action": "update"}}
1626993910.198785: {"channel": "orderbook", "market": "FLOW-PERP", "type": "update", "data": {"time": 1626993910.176, "checksum": 4208947356, "bids": [[16.355, 0.0], [14.38, 0.32]], "asks": [], "action": "update"}}
1626993910.2387042: {"channel": "orderbook", "market": "FLOW-PERP", "type": "update", "data": {"time": 1626993910.2183874, "checksum": 1120805381, "bids": [], "asks": [[16.455, 0.0], [18.9, 1500.0]], "action": "update"}}
1626993910.3593228: {"channel": "orderbook", "market": "BB-0924", "type": "update", "data": {"time": 1626993910.3368926, "checksum": 361242497, "bids": [[10.3725, 12.6]], "asks": [], "action": "update"}}
1626993910.420916: {"channel": "orderbook", "market": "MKR-PERP", "type": "update", "data": {"time": 1626993910.3946154, "checksum": 3980795229, "bids": [], "asks": [], "action": "update"}}
1626993910.430014: {"channel": "orderbook", "market": "BTC-1231", "type": "update", "data": {"time": 1626993910.4017463, "checksum": 738085353, "bids": [], "asks": [[32844.0, 9.0911]], "action": "update"}}
1626993910.479049: {"channel": "orderbook", "market": "FLOW-PERP", "type": "update", "data": {"time": 1626993910.4477413, "checksum": 1507074303, "bids": [], "asks": [[16.775, 0.0], [18.925, 0.3]], "action": "update"}}
1626993910.4818702: {"channel": "orderbook", "market": "BTC-1231", "type": "update", "data": {"time": 1626993910.454423, "checksum": 307971008, "bids": [], "asks": [[32841.0, 0.0276]], "action": "update"}}
1626993910.4823549: {"channel": "orderbook", "market": "APHA/USD", "type": "update", "data": {"time": 1626993910.463374, "checksum": 2172402314, "bids": [], "asks": [], "action": "update"}}
1626993910.496421: {"channel": "orderbook", "market": "CAD/USD", "type": "update", "data": {"time": 1626993910.4756436, "checksum": 706162672, "bids": [], "asks": [], "action": "update"}}
1626993910.5442402: {"channel": "orderbook", "market": "BTC-1231", "type": "update", "data": {"time": 1626993910.5221186, "checksum": 4254737239, "bids": [], "asks": [[32840.0, 0.095]], "action": "update"}}
1626993910.57821: {"channel": "orderbook", "market": "BTC-1231", "type": "update", "data": {"time": 1626993910.553416, "checksum": 2021265585, "bids": [], "asks": [[32843.0, 0.0024], [33442.0, 0.0]], "action": "update"}}
1626993910.6081028: {"channel": "orderbook", "market": "CHZ/USDT", "type": "update", "data": {"time": 1626993910.5856104, "checksum": 334723797, "bids": [], "asks": [], "action": "update"}}
1626993910.6081998: {"channel": "orderbook", "market": "PFE/USD", "type": "update", "data": {"time": 1626993910.587223, "checksum": 825829276, "bids": [], "asks": [], "action": "update"}}
1626993910.65569: {"channel": "orderbook", "market": "APHA/USD", "type": "update", "data": {"time": 1626993910.6352868, "checksum": 2561926892, "bids": [[11.633, 118.5]], "asks": [], "action": "update"}}
1626993910.781826: {"channel": "orderbook", "market": "FLOW-PERP", "type": "update", "data": {"time": 1626993910.7443476, "checksum": 1507074303, "bids": [], "asks": [], "action": "update"}}
1626993910.8305779: {"channel": "orderbook", "market": "BTC-1231", "type": "update", "data": {"time": 1626993910.807137, "checksum": 27219594, "bids": [[32820.0, 0.25]], "asks": [], "action": "update"}}
1626993910.919505: {"channel": "orderbook", "market": "BTC-1231", "type": "update", "data": {"time": 1626993910.8978238, "checksum": 1757354884, "bids": [[32821.0, 0.01], [32252.0, 0.0]], "asks": [], "action": "update"}}
1626993910.924821: {"channel": "orderbook", "market": "MKR-PERP", "type": "update", "data": {"time": 1626993910.8909543, "checksum": 2381810485, "bids": [], "asks": [[2445.0, 58.039]], "action": "update"}}
1626993910.99667: {"channel": "orderbook", "market": "FLOW-PERP", "type": "update", "data": {"time": 1626993910.9720252, "checksum": 3193248345, "bids": [[16.28, 73.15], [14.38, 0.0]], "asks": [], "action": "update"}}
1626993911.040212: {"channel": "orderbook", "market": "BTC-1231", "type": "update", "data": {"time": 1626993911.0143874, "checksum": 2231903379, "bids": [[32821.0, 0.26]], "asks": [], "action": "update"}}
1626993911.082221: {"channel": "orderbook", "market": "BTC-1231", "type": "update", "data": {"time": 1626993911.0604708, "checksum": 78087569, "bids": [[32820.0, 0.0], [32252.0, 0.0004]], "asks": [], "action": "update"}}
1626993911.1247098: {"channel": "orderbook", "market": "BNBBEAR/USDT", "type": "update", "data": {"time": 1626993911.1000042, "checksum": 884149509, "bids": [], "asks": [], "action": "update"}}
1626993911.128979: {"channel": "orderbook", "market": "APHA/USD", "type": "update", "data": {"time": 1626993911.10968, "checksum": 2127808384, "bids": [], "asks": [[14.758, 0.0]], "action": "update"}}
1626993911.131226: {"channel": "orderbook", "market": "KNCBULL/USDT", "type": "update", "data": {"time": 1626993911.1058538, "checksum": 4188723151, "bids": [], "asks": [], "action": "update"}}
1626993911.167561: {"channel": "orderbook", "market": "BTC-1231", "type": "update", "data": {"time": 1626993911.1399372, "checksum": 646275586, "bids": [[32787.0, 0.0], [32247.0, 0.0002]], "asks": [], "action": "update"}}
1626993911.239001: {"channel": "orderbook", "market": "BB-0924", "type": "update", "data": {"time": 1626993911.213598, "checksum": 361242497, "bids": [], "asks": [], "action": "update"}}
1626993911.28328: {"channel": "orderbook", "market": "APHA/USD", "type": "update", "data": {"time": 1626993911.2613325, "checksum": 3065665871, "bids": [[11.462, 0.0]], "asks": [], "action": "update"}}
1626993911.317266: {"channel": "orderbook", "market": "MKR-PERP", "type": "update", "data": {"time": 1626993911.2876952, "checksum": 2632051678, "bids": [], "asks": [[2416.0, 0.0], [2800.0, 0.035]], "action": "update"}}
1626993911.354572: {"channel": "orderbook", "market": "FLOW-PERP", "type": "update", "data": {"time": 1626993911.3185225, "checksum": 2244822112, "bids": [[16.42, 0.0], [16.155, 1238.08], [14.38, 0.32]], "asks": [[16.69, 1198.47]], "action": "update"}}
1626993911.415997: {"channel": "orderbook", "market": "MKR-PERP", "type": "update", "data": {"time": 1626993911.384969, "checksum": 4266679368, "bids": [], "asks": [[2416.5, 1.936]], "action": "update"}}
1626993911.416115: {"channel": "orderbook", "market": "FLOW-PERP", "type": "update", "data": {"time": 1626993911.391653, "checksum": 4157475909, "bids": [], "asks": [[16.465, 70.7]], "action": "update"}}
1626993911.4325628: {"channel": "orderbook", "market": "MKR-PERP", "type": "update", "data": {"time": 1626993911.4071314, "checksum": 4266679368, "bids": [], "asks": [], "action": "update"}}
1626993911.432657: {"channel": "orderbook", "market": "BTC-1231", "type": "update", "data": {"time": 1626993911.4094067, "checksum": 3178185207, "bids": [], "asks": [[32828.0, 0.0], [32844.0, 9.3194], [33442.0, 0.025]], "action": "update"}}
1626993911.462332: {"channel": "orderbook", "market": "FLOW-PERP", "type": "update", "data": {"time": 1626993911.4427445, "checksum": 4016834892, "bids": [[16.42, 22.83], [14.38, 0.0]], "asks": [], "action": "update"}}
1626993911.475192: {"channel": "orderbook", "market": "BTC-1231", "type": "update", "data": {"time": 1626993911.4507349, "checksum": 3012971089, "bids": [[32821.0, 0.01]], "asks": [[32844.0, 9.0911], [32899.0, 0.0], [33447.0, 0.168]], "action": "update"}}
1626993911.517789: {"channel": "orderbook", "market": "APHA/USD", "type": "update", "data": {"time": 1626993911.4947538, "checksum": 3065665871, "bids": [], "asks": [], "action": "update"}}
1626993911.5606852: {"channel": "orderbook", "market": "CAD/USD", "type": "update", "data": {"time": 1626993911.5309222, "checksum": 706162672, "bids": [], "asks": [], "action": "update"}}
1626993911.566426: {"channel": "orderbook", "market": "BTC-1231", "type": "update", "data": {"time": 1626993911.5402815, "checksum": 427315027, "bids": [[32821.0, 0.0], [32242.0, 0.0004]], "asks": [[32830.0, 0.0003], [33447.0, 0.0]], "action": "update"}}
1626993911.636512: {"channel": "orderbook", "market": "CHZ/USDT", "type": "update", "data": {"time": 1626993911.6143675, "checksum": 334723797, "bids": [], "asks": [], "action": "update"}}
1626993911.639115: {"channel": "orderbook", "market": "PFE/USD", "type": "update", "data": {"time": 1626993911.6175845, "checksum": 825829276, "bids": [], "asks": [], "action": "update"}}
1626993911.6459122: {"channel": "orderbook", "market": "BTC-1231", "type": "update", "data": {"time": 1626993911.619332, "checksum": 3761344310, "bids": [[32818.0, 0.25], [32242.0, 0.0]], "asks": [[32834.0, 0.05], [32911.0, 1.077], [33442.0, 0.0]], "action": "update"}}
1626993911.66475: {"channel": "orderbook", "market": "BTC-1231", "type": "update", "data": {"time": 1626993911.638754, "checksum": 860218682, "bids": [[32815.0, 0.01], [32247.0, 0.0]], "asks": [], "action": "update"}}
1626993911.7126951: {"channel": "orderbook", "market": "FLOW-PERP", "type": "update", "data": {"time": 1626993911.6925163, "checksum": 3200377465, "bids": [], "asks": [[16.465, 96.94]], "action": "update"}}
1626993911.7163572: {"channel": "orderbook", "market": "APHA/USD", "type": "update", "data": {"time": 1626993911.6963465, "checksum": 611157873, "bids": [[11.511, 16.4]], "asks": [], "action": "update"}}
1626993911.7170408: {"channel": "orderbook", "market": "BTC-1231", "type": "update", "data": {"time": 1626993911.6922486, "checksum": 2448462455, "bids": [[32820.0, 0.25], [32815.0, 0.0]], "asks": [], "action": "update"}}
1626993911.7371352: {"channel": "orderbook", "market": "BTC-1231", "type": "update", "data": {"time": 1626993911.7166011, "checksum": 4055965735, "bids": [[32782.0, 9.05]], "asks": [], "action": "update"}}
1626993911.789291: {"channel": "orderbook", "market": "BTC-1231", "type": "update", "data": {"time": 1626993911.7672489, "checksum": 4085536128, "bids": [[32821.0, 0.25], [32818.0, 0.0]], "asks": [], "action": "update"}}
1626993911.793819: {"channel": "orderbook", "market": "FLOW-PERP", "type": "update", "data": {"time": 1626993911.7667887, "checksum": 3200377465, "bids": [], "asks": [], "action": "update"}}
1626993911.84109: {"channel": "orderbook", "market": "MKR-PERP", "type": "update", "data": {"time": 1626993911.8183007, "checksum": 3130020205, "bids": [], "asks": [[2416.5, 2.325]], "action": "update"}}
1626993911.850626: {"channel": "orderbook", "market": "BTC-1231", "type": "update", "data": {"time": 1626993911.8184552, "checksum": 3996471393, "bids": [[32821.0, 0.0], [32820.0, 0.0], [32819.0, 0.01], [32247.0, 0.0002]], "asks": [], "action": "update"}}
1626993911.8995042: {"channel": "orderbook", "market": "BTC-1231", "type": "update", "data": {"time": 1626993911.8672993, "checksum": 1549138772, "bids": [[32819.0, 0.0], [32242.0, 0.0004]], "asks": [], "action": "update"}}
1626993911.991634: {"channel": "orderbook", "market": "BTC-1231", "type": "update", "data": {"time": 1626993911.968947, "checksum": 3396962870, "bids": [[32817.0, 0.25], [32242.0, 0.0]], "asks": [], "action": "update"}}
1626993912.028109: {"channel": "orderbook", "market": "BTC-1231", "type": "update", "data": {"time": 1626993911.9936707, "checksum": 3212486295, "bids": [[32815.0, 0.01], [32247.0, 0.0]], "asks": [], "action": "update"}}
1626993912.065846: {"channel": "orderbook", "market": "FLOW-PERP", "type": "update", "data": {"time": 1626993912.044974, "checksum": 2441925215, "bids": [[16.155, 1609.44]], "asks": [], "action": "update"}}
1626993912.0760078: {"channel": "orderbook", "market": "BTC-1231", "type": "update", "data": {"time": 1626993912.0506136, "checksum": 924274741, "bids": [[32818.0, 0.25], [32815.0, 0.0]], "asks": [], "action": "update"}}
1626993912.1271539: {"channel": "orderbook", "market": "BTC-1231", "type": "update", "data": {"time": 1626993912.0981898, "checksum": 2295479149, "bids": [[32817.0, 0.0], [32247.0, 0.0002]], "asks": [], "action": "update"}}
1626993912.138861: {"channel": "orderbook", "market": "FLOW-PERP", "type": "update", "data": {"time": 1626993912.1176598, "checksum": 4141066462, "bids": [[16.28, 0.0], [14.38, 0.32]], "asks": [], "action": "update"}}
1626993912.15522: {"channel": "orderbook", "market": "KNCBULL/USDT", "type": "update", "data": {"time": 1626993912.1303205, "checksum": 4188723151, "bids": [], "asks": [], "action": "update"}}
1626993912.164406: {"channel": "orderbook", "market": "BNBBEAR/USDT", "type": "update", "data": {"time": 1626993912.132544, "checksum": 884149509, "bids": [], "asks": [], "action": "update"}}
1626993912.164466: {"channel": "orderbook", "market": "FLOW-PERP", "type": "update", "data": {"time": 1626993912.142469, "checksum": 204452194, "bids": [], "asks": [[16.69, 1558.01]], "action": "update"}}
1626993912.168391: {"channel": "orderbook", "market": "MKR-PERP", "type": "update", "data": {"time": 1626993912.1439998, "checksum": 4266679368, "bids": [], "asks": [[2416.5, 1.936]], "action": "update"}}
1626993912.171325: {"channel": "orderbook", "market": "BTC-1231", "type": "update", "data": {"time": 1626993912.147226, "checksum": 3309356219, "bids": [[32819.0, 0.25], [32818.0, 0.26], [32247.0, 0.0]], "asks": [], "action": "update"}}
1626993912.2421482: {"channel": "orderbook", "market": "BTC-1231", "type": "update", "data": {"time": 1626993912.2183986, "checksum": 1436311075, "bids": [[32820.0, 0.25], [32818.0, 0.0]], "asks": [], "action": "update"}}
1626993912.264447: {"channel": "orderbook", "market": "BTC-1231", "type": "update", "data": {"time": 1626993912.24003, "checksum": 3736842476, "bids": [[32819.0, 0.0], [32247.0, 0.0002]], "asks": [], "action": "update"}}
1626993912.2649028: {"channel": "orderbook", "market": "BB-0924", "type": "update", "data": {"time": 1626993912.2431629, "checksum": 361242497, "bids": [], "asks": [], "action": "update"}}
1626993912.2946: {"channel": "orderbook", "market": "BTC-1231", "type": "update", "data": {"time": 1626993912.2710028, "checksum": 1549138772, "bids": [[32820.0, 0.0], [32242.0, 0.0004]], "asks": [], "action": "update"}}
1626993912.363925: {"channel": "orderbook", "market": "BTC-1231", "type": "update", "data": {"time": 1626993912.3406622, "checksum": 2946490988, "bids": [[32821.0, 0.01], [32818.0, 0.25], [32247.0, 0.0], [32242.0, 0.0]], "asks": [], "action": "update"}}
1626993912.4384031: {"channel": "orderbook", "market": "BTC-1231", "type": "update", "data": {"time": 1626993912.3982866, "checksum": 2295479149, "bids": [[32821.0, 0.0], [32247.0, 0.0002]], "asks": [], "action": "update"}}
1626993912.4506721: {"channel": "orderbook", "market": "BTC-1231", "type": "update", "data": {"time": 1626993912.4238203, "checksum": 1130735116, "bids": [[32821.0, 0.25], [32818.0, 0.0]], "asks": [[32911.0, 0.0], [33442.0, 0.025]], "action": "update"}}
1626993912.469763: {"channel": "orderbook", "market": "BTC-1231", "type": "update", "data": {"time": 1626993912.4440126, "checksum": 1655238089, "bids": [[32821.0, 0.0], [32242.0, 0.0004]], "asks": [], "action": "update"}}
1626993912.4756072: {"channel": "orderbook", "market": "MKR-PERP", "type": "update", "data": {"time": 1626993912.449624, "checksum": 4266679368, "bids": [], "asks": [], "action": "update"}}
1626993912.540721: {"channel": "orderbook", "market": "APHA/USD", "type": "update", "data": {"time": 1626993912.5189345, "checksum": 611157873, "bids": [], "asks": [], "action": "update"}}
1626993912.555735: {"channel": "orderbook", "market": "BTC-1231", "type": "update", "data": {"time": 1626993912.5271442, "checksum": 2042732077, "bids": [[32821.0, 0.25], [32819.0, 0.01], [32247.0, 0.0], [32242.0, 0.0]], "asks": [[32846.0, 0.2283], [33442.0, 0.0]], "action": "update"}}
1626993912.58959: {"channel": "orderbook", "market": "BTC-1231", "type": "update", "data": {"time": 1626993912.5599475, "checksum": 1121729595, "bids": [[32819.0, 0.0], [32247.0, 0.0002]], "asks": [[32897.0, 1.778]], "action": "update"}}
1626993912.621473: {"channel": "orderbook", "market": "CAD/USD", "type": "update", "data": {"time": 1626993912.5946925, "checksum": 706162672, "bids": [], "asks": [], "action": "update"}}
1626993912.6401348: {"channel": "orderbook", "market": "MKR-PERP", "type": "update", "data": {"time": 1626993912.6190877, "checksum": 3130020205, "bids": [], "asks": [[2416.5, 2.325]], "action": "update"}}
1626993912.6654441: {"channel": "orderbook", "market": "CHZ/USDT", "type": "update", "data": {"time": 1626993912.6400535, "checksum": 334723797, "bids": [], "asks": [], "action": "update"}}
1626993912.6669629: {"channel": "orderbook", "market": "PFE/USD", "type": "update", "data": {"time": 1626993912.6452186, "checksum": 825829276, "bids": [], "asks": [], "action": "update"}}
1626993912.757406: {"channel": "orderbook", "market": "BTC-1231", "type": "update", "data": {"time": 1626993912.735217, "checksum": 1141767269, "bids": [[32822.0, 0.01], [32247.0, 0.0]], "asks": [], "action": "update"}}
1626993912.7575612: {"channel": "orderbook", "market": "CHZ/USDT", "type": "update", "data": {"time": 1626993912.7311382, "checksum": 617357651, "bids": [[0.227937, 11420.0]], "asks": [], "action": "update"}}
1626993912.819873: {"channel": "orderbook", "market": "BTC-1231", "type": "update", "data": {"time": 1626993912.789624, "checksum": 1356990808, "bids": [[32821.0, 0.0], [32247.0, 0.0002]], "asks": [], "action": "update"}}
1626993912.835791: {"channel": "orderbook", "market": "FLOW-PERP", "type": "update", "data": {"time": 1626993912.797021, "checksum": 204452194, "bids": [], "asks": [], "action": "update"}}
1626993912.856691: {"channel": "orderbook", "market": "BTC-1231", "type": "update", "data": {"time": 1626993912.8350663, "checksum": 2681674536, "bids": [[32715.0, 0.2447]], "asks": [], "action": "update"}}
1626993912.8868842: {"channel": "orderbook", "market": "BTC-1231", "type": "update", "data": {"time": 1626993912.8649683, "checksum": 4271504476, "bids": [[32822.0, 0.0], [32242.0, 0.0004]], "asks": [], "action": "update"}}
1626993912.894197: {"channel": "orderbook", "market": "FLOW-PERP", "type": "update", "data": {"time": 1626993912.8735135, "checksum": 3226855859, "bids": [], "asks": [[17.145, 0.0], [18.935, 0.1]], "action": "update"}}
1626993912.945676: {"channel": "orderbook", "market": "FLOW-PERP", "type": "update", "data": {"time": 1626993912.9250588, "checksum": 2724467888, "bids": [[16.365, 75.04], [14.38, 0.0]], "asks": [[17.145, 29.15], [18.935, 0.0]], "action": "update"}}
1626993912.954995: {"channel": "orderbook", "market": "BTC-1231", "type": "update", "data": {"time": 1626993912.9344137, "checksum": 577073818, "bids": [[32817.0, 0.25], [32815.0, 0.01], [32247.0, 0.0], [32242.0, 0.0]], "asks": [], "action": "update"}}
1626993912.955532: {"channel": "orderbook", "market": "MKR-PERP", "type": "update", "data": {"time": 1626993912.928891, "checksum": 4127452388, "bids": [], "asks": [[2445.0, 0.039]], "action": "update"}}
1626993913.0364149: {"channel": "orderbook", "market": "BTC-1231", "type": "update", "data": {"time": 1626993913.0128207, "checksum": 2192292305, "bids": [[32819.0, 0.25], [32815.0, 0.0]], "asks": [], "action": "update"}}
1626993913.082218: {"channel": "orderbook", "market": "BTC-1231", "type": "update", "data": {"time": 1626993913.0603454, "checksum": 347453370, "bids": [[32817.0, 0.0], [32715.0, 0.0155], [32247.0, 0.0002]], "asks": [], "action": "update"}}
1626993913.1406772: {"channel": "orderbook", "market": "BTC-1231", "type": "update", "data": {"time": 1626993913.1202598, "checksum": 1731012759, "bids": [[32820.0, 0.25], [32818.0, 0.01], [32252.0, 0.0], [32247.0, 0.0]], "asks": [], "action": "update"}}
1626993913.186551: {"channel": "orderbook", "market": "KNCBULL/USDT", "type": "update", "data": {"time": 1626993913.158335, "checksum": 4188723151, "bids": [], "asks": [], "action": "update"}}
1626993913.186618: {"channel": "orderbook", "market": "BNBBEAR/USDT", "type": "update", "data": {"time": 1626993913.1579628, "checksum": 884149509, "bids": [], "asks": [], "action": "update"}}
1626993913.196877: {"channel": "orderbook", "market": "BTC-1231", "type": "update", "data": {"time": 1626993913.1743975, "checksum": 975191349, "bids": [[32819.0, 0.0], [32818.0, 0.0], [32816.0, 0.0288], [32252.0, 0.0004]], "asks": [], "action": "update"}}
1626993913.2356632: {"channel": "orderbook", "market": "BTC-1231", "type": "update", "data": {"time": 1626993913.2078955, "checksum": 1720986788, "bids": [[32821.0, 0.25], [32811.0, 7.691], [32282.0, 0.0], [32252.0, 0.0]], "asks": [], "action": "update"}}
1626993913.2870169: {"channel": "orderbook", "market": "BTC-1231", "type": "update", "data": {"time": 1626993913.259393, "checksum": 2949522010, "bids": [[32820.0, 0.0], [32808.0, 0.6229], [32747.0, 0.0], [32282.0, 0.0002], [32252.0, 0.0004]], "asks": [], "action": "update"}}
1626993913.295126: {"channel": "orderbook", "market": "BB-0924", "type": "update", "data": {"time": 1626993913.273042, "checksum": 361242497, "bids": [], "asks": [], "action": "update"}}
1626993913.3086889: {"channel": "orderbook", "market": "BTC-1231", "type": "update", "data": {"time": 1626993913.2842994, "checksum": 813321785, "bids": [[32795.0, 0.0], [32247.0, 0.0002]], "asks": [], "action": "update"}}
1626993913.3903942: {"channel": "orderbook", "market": "MKR-PERP", "type": "update", "data": {"time": 1626993913.3621688, "checksum": 3130020205, "bids": [], "asks": [[2445.0, 58.039]], "action": "update"}}
1626993913.50961: {"channel": "orderbook", "market": "MKR-PERP", "type": "update", "data": {"time": 1626993913.4816594, "checksum": 3945870341, "bids": [[2409.5, 2.315]], "asks": [[2423.5, 6.347]], "action": "update"}}
1626993913.529182: {"channel": "orderbook", "market": "FLOW-PERP", "type": "update", "data": {"time": 1626993913.5034845, "checksum": 2344103749, "bids": [], "asks": [[16.76, 537.12], [18.925, 0.0]], "action": "update"}}
1626993913.529341: {"channel": "orderbook", "market": "MKR-PERP", "type": "update", "data": {"time": 1626993913.5038707, "checksum": 2460919519, "bids": [], "asks": [[2420.5, 1.252]], "action": "update"}}
1626993913.5648818: {"channel": "orderbook", "market": "BTC-1231", "type": "update", "data": {"time": 1626993913.5388682, "checksum": 696146579, "bids": [[32821.0, 0.26]], "asks": [], "action": "update"}}
1626993913.572052: {"channel": "orderbook", "market": "APHA/USD", "type": "update", "data": {"time": 1626993913.5473351, "checksum": 611157873, "bids": [], "asks": [], "action": "update"}}
1626993913.631003: {"channel": "orderbook", "market": "CHZ/USDT", "type": "update", "data": {"time": 1626993913.609775, "checksum": 2323701484, "bids": [], "asks": [[0.23521, 0.0], [0.5421, 270.0]], "action": "update"}}
1626993913.660579: {"channel": "orderbook", "market": "FLOW-PERP", "type": "update", "data": {"time": 1626993913.625088, "checksum": 658171741, "bids": [], "asks": [[17.145, 0.0], [18.925, 0.3]], "action": "update"}}
1626993913.6760309: {"channel": "orderbook", "market": "CAD/USD", "type": "update", "data": {"time": 1626993913.6530604, "checksum": 706162672, "bids": [], "asks": [], "action": "update"}}
1626993913.69572: {"channel": "orderbook", "market": "FLOW-PERP", "type": "update", "data": {"time": 1626993913.675043, "checksum": 1718600858, "bids": [], "asks": [[17.145, 17.49], [18.925, 0.0]], "action": "update"}}
1626993913.703813: {"channel": "orderbook", "market": "PFE/USD", "type": "update", "data": {"time": 1626993913.6820352, "checksum": 825829276, "bids": [], "asks": [], "action": "update"}}
1626993913.707802: {"channel": "orderbook", "market": "CHZ/USDT", "type": "update", "data": {"time": 1626993913.6774592, "checksum": 2323701484, "bids": [], "asks": [], "action": "update"}}
1626993913.756018: {"channel": "orderbook", "market": "MKR-PERP", "type": "update", "data": {"time": 1626993913.7336051, "checksum": 2416174468, "bids": [], "asks": [[2423.0, 8.004]], "action": "update"}}
1626993913.777384: {"channel": "orderbook", "market": "MKR-PERP", "type": "update", "data": {"time": 1626993913.755661, "checksum": 1065281001, "bids": [], "asks": [[2424.0, 3.389]], "action": "update"}}
1626993913.8018198: {"channel": "orderbook", "market": "BTC-1231", "type": "update", "data": {"time": 1626993913.7810347, "checksum": 906921875, "bids": [[32748.0, 0.005], [32247.0, 0.0]], "asks": [], "action": "update"}}
1626993913.853317: {"channel": "orderbook", "market": "FLOW-PERP", "type": "update", "data": {"time": 1626993913.8128724, "checksum": 1718600858, "bids": [], "asks": [], "action": "update"}}
1626993913.879669: {"channel": "orderbook", "market": "BTC-1231", "type": "update", "data": {"time": 1626993913.853032, "checksum": 906921875, "bids": [], "asks": [], "action": "update"}}
1626993913.9086552: {"channel": "orderbook", "market": "FLOW-PERP", "type": "update", "data": {"time": 1626993913.886856, "checksum": 658171741, "bids": [], "asks": [[17.145, 0.0], [18.925, 0.3]], "action": "update"}}
1626993913.925958: {"channel": "orderbook", "market": "MKR-PERP", "type": "update", "data": {"time": 1626993913.8929162, "checksum": 2416174468, "bids": [], "asks": [[2424.0, 2.525]], "action": "update"}}
1626993913.943082: {"channel": "orderbook", "market": "FLOW-PERP", "type": "update", "data": {"time": 1626993913.922476, "checksum": 2344239428, "bids": [], "asks": [[17.145, 5.83], [18.925, 0.0]], "action": "update"}}
1626993913.969514: {"channel": "orderbook", "market": "CHZ/USDT", "type": "update", "data": {"time": 1626993913.948453, "checksum": 3656609471, "bids": [], "asks": [[0.235937, 3840.0], [0.5421, 0.0]], "action": "update"}}
1626993914.1432378: {"channel": "orderbook", "market": "FLOW-PERP", "type": "update", "data": {"time": 1626993914.1225128, "checksum": 658171741, "bids": [], "asks": [[17.145, 0.0], [18.925, 0.3]], "action": "update"}}
1626993914.183789: {"channel": "orderbook", "market": "FLOW-PERP", "type": "update", "data": {"time": 1626993914.1550121, "checksum": 20100823, "bids": [], "asks": [[17.15, 5.83], [18.925, 0.0]], "action": "update"}}
1626993914.2054: {"channel": "orderbook", "market": "BNBBEAR/USDT", "type": "update", "data": {"time": 1626993914.1795304, "checksum": 884149509, "bids": [], "asks": [], "action": "update"}}
1626993914.205451: {"channel": "orderbook", "market": "KNCBULL/USDT", "type": "update", "data": {"time": 1626993914.1843698, "checksum": 4188723151, "bids": [], "asks": [], "action": "update"}}
1626993914.3006542: {"channel": "orderbook", "market": "MKR-PERP", "type": "update", "data": {"time": 1626993914.2647579, "checksum": 1687966375, "bids": [[2385.5, 8.384]], "asks": [[2445.5, 8.178]], "action": "update"}}
1626993914.32152: {"channel": "orderbook", "market": "BB-0924", "type": "update", "data": {"time": 1626993914.298622, "checksum": 361242497, "bids": [], "asks": [], "action": "update"}}
1626993914.523967: {"channel": "orderbook", "market": "MKR-PERP", "type": "update", "data": {"time": 1626993914.495731, "checksum": 2629332038, "bids": [[2385.5, 0.0], [2099.0, 0.001]], "asks": [[2445.5, 0.0], [2813.0, 0.001]], "action": "update"}}
1626993914.595527: {"channel": "orderbook", "market": "APHA/USD", "type": "update", "data": {"time": 1626993914.5754015, "checksum": 611157873, "bids": [], "asks": [], "action": "update"}}
1626993914.619424: {"channel": "orderbook", "market": "CHZ/USDT", "type": "update", "data": {"time": 1626993914.5957236, "checksum": 2751819102, "bids": [[0.227931, 0.0]], "asks": [], "action": "update"}}
1626993914.697066: {"channel": "orderbook", "market": "CHZ/USDT", "type": "update", "data": {"time": 1626993914.6747615, "checksum": 64198634, "bids": [[0.227937, 0.0]], "asks": [], "action": "update"}}
1626993914.714067: {"channel": "orderbook", "market": "CAD/USD", "type": "update", "data": {"time": 1626993914.678145, "checksum": 706162672, "bids": [], "asks": [], "action": "update"}}
1626993914.7258189: {"channel": "orderbook", "market": "PFE/USD", "type": "update", "data": {"time": 1626993914.706328, "checksum": 825829276, "bids": [], "asks": [], "action": "update"}}
1626993914.7379541: {"channel": "orderbook", "market": "CHZ/USDT", "type": "update", "data": {"time": 1626993914.7158194, "checksum": 1943068739, "bids": [[0.227755, 11430.0]], "asks": [], "action": "update"}}
1626993914.738108: {"channel": "orderbook", "market": "BTC-1231", "type": "update", "data": {"time": 1626993914.7098725, "checksum": 2200944976, "bids": [], "asks": [[32829.0, 0.0155], [32846.0, 0.0]], "action": "update"}}
1626993914.78543: {"channel": "orderbook", "market": "BTC-1231", "type": "update", "data": {"time": 1626993914.7595458, "checksum": 752821482, "bids": [], "asks": [[32890.0, 0.005]], "action": "update"}}
1626993914.808767: {"channel": "orderbook", "market": "BTC-1231", "type": "update", "data": {"time": 1626993914.782897, "checksum": 2020077938, "bids": [[32823.0, 0.25], [32252.0, 0.0]], "asks": [[32829.0, 0.0], [33442.0, 0.025]], "action": "update"}}
1626993914.8253021: {"channel": "orderbook", "market": "CHZ/USDT", "type": "update", "data": {"time": 1626993914.8023033, "checksum": 64198634, "bids": [[0.227755, 0.0]], "asks": [], "action": "update"}}
1626993914.844602: {"channel": "orderbook", "market": "FLOW-PERP", "type": "update", "data": {"time": 1626993914.823124, "checksum": 20100823, "bids": [], "asks": [], "action": "update"}}
1626993914.849934: {"channel": "orderbook", "market": "BTC-1231", "type": "update", "data": {"time": 1626993914.8292358, "checksum": 3128344342, "bids": [[32821.0, 0.01]], "asks": [[32877.0, 0.0], [33447.0, 0.168]], "action": "update"}}
1626993914.883699: {"channel": "orderbook", "market": "BTC-1231", "type": "update", "data": {"time": 1626993914.8605192, "checksum": 170952784, "bids": [[32824.0, 0.25], [32821.0, 0.0], [32771.0, 0.0], [32252.0, 0.0004]], "asks": [], "action": "update"}}
1626993914.92629: {"channel": "orderbook", "market": "BTC-1231", "type": "update", "data": {"time": 1626993914.9036658, "checksum": 989953198, "bids": [[32823.0, 0.0], [32247.0, 0.0002]], "asks": [], "action": "update"}}
1626993914.991702: {"channel": "orderbook", "market": "BTC-1231", "type": "update", "data": {"time": 1626993914.9566853, "checksum": 3573027572, "bids": [[32824.0, 0.26]], "asks": [[32897.0, 0.6858]], "action": "update"}}
1626993915.1001458: {"channel": "orderbook", "market": "BTC-1231", "type": "update", "data": {"time": 1626993915.070763, "checksum": 3712435623, "bids": [], "asks": [[32830.0, 0.0], [33454.0, 0.0004]], "action": "update"}}
1626993915.116323: {"channel": "orderbook", "market": "MKR-PERP", "type": "update", "data": {"time": 1626993915.0930169, "checksum": 2725733066, "bids": [[2385.5, 4.192], [2099.0, 0.0]], "asks": [], "action": "update"}}
1626993915.138803: {"channel": "orderbook", "market": "BTC-1231", "type": "update", "data": {"time": 1626993915.1111948, "checksum": 3796623452, "bids": [[32825.0, 0.25], [32824.0, 0.01], [32751.0, 0.0]], "asks": [[32834.0, 0.0], [32844.0, 0.0], [33458.0, 0.05], [33463.0, 1.5]], "action": "update"}}
1626993915.1622112: {"channel": "orderbook", "market": "BTC-1231", "type": "update", "data": {"time": 1626993915.1335273, "checksum": 1897775411, "bids": [[32825.0, 0.0], [32815.0, 8.0797]], "asks": [[32849.0, 7.4588], [32908.0, 1.0627], [33463.0, 0.0]], "action": "update"}}
1626993915.2023811: {"channel": "orderbook", "market": "BTC-1231", "type": "update", "data": {"time": 1626993915.1799247, "checksum": 2870039335, "bids": [[32824.0, 0.0], [32811.0, 0.0], [32806.0, 0.0], [32242.0, 0.0004], [32237.0, 0.1526], [32222.0, 0.0002]], "asks": [[32832.0, 0.0004], [32840.0, 0.6895], [32843.0, 0.0]], "action": "update"}}
1626993915.2297878: {"channel": "orderbook", "market": "MKR-PERP", "type": "update", "data": {"time": 1626993915.203965, "checksum": 524208669, "bids": [], "asks": [[2445.5, 4.089], [2813.0, 0.0]], "action": "update"}}
1626993915.2298932: {"channel": "orderbook", "market": "BNBBEAR/USDT", "type": "update", "data": {"time": 1626993915.203729, "checksum": 884149509, "bids": [], "asks": [], "action": "update"}}
1626993915.242563: {"channel": "orderbook", "market": "KNCBULL/USDT", "type": "update", "data": {"time": 1626993915.219159, "checksum": 4188723151, "bids": [], "asks": [], "action": "update"}}
1626993915.242628: {"channel": "orderbook", "market": "BTC-1231", "type": "update", "data": {"time": 1626993915.2089622, "checksum": 3124451374, "bids": [[32809.0, 0.012], [32222.0, 0.0]], "asks": [[32839.0, 0.05], [32849.0, 7.3674], [32855.0, 0.2282], [32860.0, 0.0274], [33458.0, 0.0]], "action": "update"}}
1626993915.271491: {"channel": "orderbook", "market": "MKR-PERP", "type": "update", "data": {"time": 1626993915.2506926, "checksum": 1562410029, "bids": [[2385.5, 12.576]], "asks": [], "action": "update"}}
1626993915.281013: {"channel": "orderbook", "market": "BTC-1231", "type": "update", "data": {"time": 1626993915.2524261, "checksum": 931733526, "bids": [[32821.0, 0.25], [32786.0, 0.0887], [32758.0, 0.1], [32247.0, 0.0], [32242.0, 0.0], [32237.0, 0.0]], "asks": [[32840.0, 0.5945], [32860.0, 0.025], [32905.0, 0.2292]], "action": "update"}}
1626993915.325176: {"channel": "orderbook", "market": "BTC-1231", "type": "update", "data": {"time": 1626993915.2995875, "checksum": 3981925073, "bids": [], "asks": [[32909.0, 8.3908]], "action": "update"}}
1626993915.3474529: {"channel": "orderbook", "market": "BB-0924", "type": "update", "data": {"time": 1626993915.32657, "checksum": 361242497, "bids": [], "asks": [], "action": "update"}}
1626993915.358164: {"channel": "orderbook", "market": "BB-0924", "type": "update", "data": {"time": 1626993915.338729, "checksum": 1359273830, "bids": [], "asks": [[10.425, 7.6]], "action": "update"}}
1626993915.362605: {"channel": "orderbook", "market": "BTC-1231", "type": "update", "data": {"time": 1626993915.3386045, "checksum": 2624231722, "bids": [[32823.0, 0.25], [32817.0, 0.01], [32282.0, 0.0], [32252.0, 0.0]], "asks": [[32839.0, 0.6445]], "action": "update"}}
1626993915.3628201: {"channel": "orderbook", "market": "MKR-PERP", "type": "update", "data": {"time": 1626993915.3380327, "checksum": 2416174468, "bids": [], "asks": [[2445.5, 12.267]], "action": "update"}}
1626993915.407277: {"channel": "orderbook", "market": "MKR-PERP", "type": "update", "data": {"time": 1626993915.3806682, "checksum": 178032927, "bids": [], "asks": [[2445.0, 0.039]], "action": "update"}}
1626993915.40941: {"channel": "orderbook", "market": "BTC-1231", "type": "update", "data": {"time": 1626993915.3867447, "checksum": 2470638916, "bids": [[32821.0, 0.0], [32817.0, 0.0], [32282.0, 0.0002], [32252.0, 0.0004]], "asks": [[32848.0, 0.0917]], "action": "update"}}
1626993915.434106: {"channel": "orderbook", "market": "BTC-1231", "type": "update", "data": {"time": 1626993915.4101338, "checksum": 1512226753, "bids": [[32824.0, 0.25], [32775.0, 0.008], [32252.0, 0.0]], "asks": [], "action": "update"}}
1626993915.477826: {"channel": "orderbook", "market": "BTC-1231", "type": "update", "data": {"time": 1626993915.4564567, "checksum": 1536101919, "bids": [[32824.0, 0.26], [32823.0, 0.0], [32252.0, 0.0004]], "asks": [[32877.0, 0.005], [33454.0, 0.0]], "action": "update"}}
1626993915.528: {"channel": "orderbook", "market": "BTC-1231", "type": "update", "data": {"time": 1626993915.4955542, "checksum": 4088946094, "bids": [[32824.0, 0.01]], "asks": [], "action": "update"}}
1626993915.5827231: {"channel": "orderbook", "market": "BTC-1231", "type": "update", "data": {"time": 1626993915.5493076, "checksum": 256797626, "bids": [[32777.0, 1.072], [32252.0, 0.0]], "asks": [], "action": "update"}}
1626993915.618905: {"channel": "orderbook", "market": "APHA/USD", "type": "update", "data": {"time": 1626993915.598885, "checksum": 611157873, "bids": [], "asks": [], "action": "update"}}
1626993915.6573381: {"channel": "orderbook", "market": "APHA/USD", "type": "update", "data": {"time": 1626993915.6379147, "checksum": 756393738, "bids": [], "asks": [[14.758, 93.9]], "action": "update"}}
1626993915.7020428: {"channel": "orderbook", "market": "MKR-PERP", "type": "update", "data": {"time": 1626993915.6688116, "checksum": 976469979, "bids": [[2414.5, 0.0], [2099.0, 0.001]], "asks": [[2445.5, 70.267]], "action": "update"}}
1626993915.75023: {"channel": "orderbook", "market": "MKR-PERP", "type": "update", "data": {"time": 1626993915.7276819, "checksum": 2988645002, "bids": [[2414.5, 0.524], [2099.0, 0.0]], "asks": [], "action": "update"}}
1626993915.765204: {"channel": "orderbook", "market": "CHZ/USDT", "type": "update", "data": {"time": 1626993915.7417953, "checksum": 1637124165, "bids": [], "asks": [[0.235937, 0.0], [0.5421, 270.0]], "action": "update"}}
1626993915.7695801: {"channel": "orderbook", "market": "PFE/USD", "type": "update", "data": {"time": 1626993915.746543, "checksum": 825829276, "bids": [], "asks": [], "action": "update"}}
1626993915.7748458: {"channel": "orderbook", "market": "CAD/USD", "type": "update", "data": {"time": 1626993915.745651, "checksum": 706162672, "bids": [], "asks": [], "action": "update"}}
1626993915.803925: {"channel": "orderbook", "market": "MKR-PERP", "type": "update", "data": {"time": 1626993915.7763302, "checksum": 352009873, "bids": [], "asks": [[2416.0, 0.438], [2800.0, 0.0]], "action": "update"}}
1626993915.868: {"channel": "orderbook", "market": "FLOW-PERP", "type": "update", "data": {"time": 1626993915.8468585, "checksum": 20100823, "bids": [], "asks": [], "action": "update"}}
1626993915.891287: {"channel": "orderbook", "market": "BTC-1231", "type": "update", "data": {"time": 1626993915.8589706, "checksum": 2981051213, "bids": [[32824.0, 0.25], [32734.0, 0.0], [32252.0, 0.0004]], "asks": [[32831.0, 0.0155], [32856.0, 0.0972], [32865.0, 0.0], [33447.0, 0.0]], "action": "update"}}
1626993915.908312: {"channel": "orderbook", "market": "BTC-1231", "type": "update", "data": {"time": 1626993915.886225, "checksum": 2981051213, "bids": [], "asks": [], "action": "update"}}
1626993915.908409: {"channel": "orderbook", "market": "CHZ/USDT", "type": "update", "data": {"time": 1626993915.8874655, "checksum": 2915450018, "bids": [[0.227859, 0.0]], "asks": [], "action": "update"}}
1626993915.957409: {"channel": "orderbook", "market": "BTC-1231", "type": "update", "data": {"time": 1626993915.9366288, "checksum": 3838867635, "bids": [], "asks": [[32876.0, 0.2282]], "action": "update"}}
1626993915.983: {"channel": "orderbook", "market": "BTC-1231", "type": "update", "data": {"time": 1626993915.9616625, "checksum": 127247465, "bids": [[32825.0, 0.26], [32252.0, 0.0]], "asks": [], "action": "update"}}
1626993916.036264: {"channel": "orderbook", "market": "BTC-1231", "type": "update", "data": {"time": 1626993915.9864624, "checksum": 704659470, "bids": [[32824.0, 0.0], [32252.0, 0.0004]], "asks": [], "action": "update"}}
1626993916.0789702: {"channel": "orderbook", "market": "BTC-1231", "type": "update", "data": {"time": 1626993916.0569122, "checksum": 984630666, "bids": [], "asks": [[32848.0, 0.0941], [32908.0, 0.0], [33447.0, 0.168]], "action": "update"}}
1626993916.101099: {"channel": "orderbook", "market": "CHZ/USDT", "type": "update", "data": {"time": 1626993916.0799062, "checksum": 1754082163, "bids": [], "asks": [[0.23521, 3840.0], [0.5421, 0.0]], "action": "update"}}
1626993916.126303: {"channel": "orderbook", "market": "BTC-1231", "type": "update", "data": {"time": 1626993916.1047966, "checksum": 1458338629, "bids": [], "asks": [[32831.0, 0.0], [33454.0, 0.0004]], "action": "update"}}
1626993916.183583: {"channel": "orderbook", "market": "BTC-1231", "type": "update", "data": {"time": 1626993916.15722, "checksum": 901725884, "bids": [], "asks": [[32890.0, 0.015]], "action": "update"}}
1626993916.191065: {"channel": "orderbook", "market": "MKR-PERP", "type": "update", "data": {"time": 1626993916.169607, "checksum": 1053089100, "bids": [], "asks": [[2418.5, 0.153]], "action": "update"}}
1626993916.193326: {"channel": "orderbook", "market": "FLOW-PERP", "type": "update", "data": {"time": 1626993916.173258, "checksum": 172603229, "bids": [[16.065, 359.56]], "asks": [[16.725, 0.06]], "action": "update"}}
1626993916.197286: {"channel": "orderbook", "market": "BTC-1231", "type": "update", "data": {"time": 1626993916.1767535, "checksum": 1461448083, "bids": [], "asks": [[32901.0, 1.0916], [33454.0, 0.0]], "action": "update"}}
1626993916.254614: {"channel": "orderbook", "market": "BNBBEAR/USDT", "type": "update", "data": {"time": 1626993916.2294614, "checksum": 884149509, "bids": [], "asks": [], "action": "update"}}
1626993916.2648551: {"channel": "orderbook", "market": "KNCBULL/USDT", "type": "update", "data": {"time": 1626993916.2406487, "checksum": 4188723151, "bids": [], "asks": [], "action": "update"}}
1626993916.264917: {"channel": "orderbook", "market": "MKR-PERP", "type": "update", "data": {"time": 1626993916.2345293, "checksum": 939556803, "bids": [], "asks": [[2420.0, 5.121]], "action": "update"}}
1626993916.350493: {"channel": "orderbook", "market": "BTC-1231", "type": "update", "data": {"time": 1626993916.3257246, "checksum": 1212749183, "bids": [[32759.0, 0.016], [32252.0, 0.0]], "asks": [[32846.0, 6.5519], [33447.0, 0.0]], "action": "update"}}
1626993916.375381: {"channel": "orderbook", "market": "BB-0924", "type": "update", "data": {"time": 1626993916.3527172, "checksum": 1359273830, "bids": [], "asks": [], "action": "update"}}
1626993916.399039: {"channel": "orderbook", "market": "MKR-PERP", "type": "update", "data": {"time": 1626993916.3664124, "checksum": 398138505, "bids": [], "asks": [[2417.0, 0.622], [2445.5, 12.267], [2795.5, 0.0]], "action": "update"}}
1626993916.4110148: {"channel": "orderbook", "market": "BTC-1231", "type": "update", "data": {"time": 1626993916.3863518, "checksum": 1906903686, "bids": [], "asks": [[32848.0, 0.0917], [32849.0, 0.0], [33447.0, 0.168]], "action": "update"}}
1626993916.421592: {"channel": "orderbook", "market": "BTC-1231", "type": "update", "data": {"time": 1626993916.4000034, "checksum": 1900089039, "bids": [], "asks": [[32845.0, 0.0024], [33447.0, 0.0]], "action": "update"}}
1626993916.445281: {"channel": "orderbook", "market": "BTC-1231", "type": "update", "data": {"time": 1626993916.4249432, "checksum": 3239370281, "bids": [], "asks": [[32890.0, 0.0151]], "action": "update"}}
1626993916.470926: {"channel": "orderbook", "market": "MKR-PERP", "type": "update", "data": {"time": 1626993916.4438114, "checksum": 2420820144, "bids": [], "asks": [[2417.5, 0.293]], "action": "update"}}
1626993916.509363: {"channel": "orderbook", "market": "MKR-PERP", "type": "update", "data": {"time": 1626993916.481293, "checksum": 278288196, "bids": [], "asks": [[2444.5, 58.0], [2793.5, 0.0]], "action": "update"}}
1626993916.5154119: {"channel": "orderbook", "market": "BTC-1231", "type": "update", "data": {"time": 1626993916.47554, "checksum": 766279008, "bids": [[32717.0, 8.6853]], "asks": [], "action": "update"}}
1626993916.623654: {"channel": "orderbook", "market": "BTC-1231", "type": "update", "data": {"time": 1626993916.5925179, "checksum": 3510830954, "bids": [[32811.0, 9.101], [32282.0, 0.0]], "asks": [], "action": "update"}}
1626993916.6417851: {"channel": "orderbook", "market": "BTC-1231", "type": "update", "data": {"time": 1626993916.619878, "checksum": 1572262261, "bids": [[32815.0, 0.0], [32282.0, 0.0002]], "asks": [], "action": "update"}}
1626993916.714066: {"channel": "orderbook", "market": "MKR-PERP", "type": "update", "data": {"time": 1626993916.6901317, "checksum": 278288196, "bids": [], "asks": [], "action": "update"}}
1626993916.722518: {"channel": "orderbook", "market": "FLOW-PERP", "type": "update", "data": {"time": 1626993916.7021265, "checksum": 4033968343, "bids": [[16.09, 98.2], [14.39, 0.0]], "asks": [], "action": "update"}}
1626993916.781198: {"channel": "orderbook", "market": "MKR-PERP", "type": "update", "data": {"time": 1626993916.7549982, "checksum": 3667819031, "bids": [], "asks": [[2416.0, 0.0], [2793.5, 0.04]], "action": "update"}}
1626993916.793997: {"channel": "orderbook", "market": "CHZ/USDT", "type": "update", "data": {"time": 1626993916.7684665, "checksum": 1754082163, "bids": [], "asks": [], "action": "update"}}
1626993916.794113: {"channel": "orderbook", "market": "PFE/USD", "type": "update", "data": {"time": 1626993916.7726703, "checksum": 825829276, "bids": [], "asks": [], "action": "update"}}
1626993916.799906: {"channel": "orderbook", "market": "FLOW-PERP", "type": "update", "data": {"time": 1626993916.7763202, "checksum": 3263494015, "bids": [], "asks": [[16.75, 98.2], [18.9, 0.0]], "action": "update"}}
1626993916.817224: {"channel": "orderbook", "market": "CAD/USD", "type": "update", "data": {"time": 1626993916.7918427, "checksum": 706162672, "bids": [], "asks": [], "action": "update"}}
1626993916.851246: {"channel": "orderbook", "market": "APHA/USD", "type": "update", "data": {"time": 1626993916.6289864, "checksum": 756393738, "bids": [], "asks": [], "action": "update"}}
1626993916.882783: {"channel": "orderbook", "market": "MKR-PERP", "type": "update", "data": {"time": 1626993916.8578205, "checksum": 3305112178, "bids": [], "asks": [[2417.0, 0.0], [2432.0, 7.423], [2444.5, 0.0], [2795.5, 0.024], [2800.0, 0.035]], "action": "update"}}
1626993916.894458: {"channel": "orderbook", "market": "BTC-1231", "type": "update", "data": {"time": 1626993916.8691177, "checksum": 898894563, "bids": [[32825.0, 0.25]], "asks": [], "action": "update"}}
1626993916.894942: {"channel": "orderbook", "market": "FLOW-PERP", "type": "update", "data": {"time": 1626993916.8732495, "checksum": 3263494015, "bids": [], "asks": [], "action": "update"}}
1626993916.9490209: {"channel": "orderbook", "market": "MKR-PERP", "type": "update", "data": {"time": 1626993916.9279032, "checksum": 2836042064, "bids": [], "asks": [[2419.0, 5.132]], "action": "update"}}
1626993916.952102: {"channel": "orderbook", "market": "BTC-1231", "type": "update", "data": {"time": 1626993916.9266462, "checksum": 3839726220, "bids": [[32825.0, 0.0], [32252.0, 0.0004]], "asks": [], "action": "update"}}
1626993916.9894788: {"channel": "orderbook", "market": "MKR-PERP", "type": "update", "data": {"time": 1626993916.9567616, "checksum": 3804400940, "bids": [], "asks": [[2444.5, 58.0], [2800.0, 0.0]], "action": "update"}}
1626993916.9991019: {"channel": "orderbook", "market": "BTC-1231", "type": "update", "data": {"time": 1626993916.9731796, "checksum": 686708241, "bids": [[32826.0, 0.01], [32252.0, 0.0]], "asks": [[32846.0, 6.7802]], "action": "update"}}
1626993917.040687: {"channel": "orderbook", "market": "BTC-1231", "type": "update", "data": {"time": 1626993917.0196903, "checksum": 1887173927, "bids": [[32826.0, 0.0], [32252.0, 0.0004]], "asks": [], "action": "update"}}
1626993917.06816: {"channel": "orderbook", "market": "MKR-PERP", "type": "update", "data": {"time": 1626993917.0367012, "checksum": 2836042064, "bids": [], "asks": [[2444.5, 0.0], [2800.0, 0.035]], "action": "update"}}
1626993917.082332: {"channel": "orderbook", "market": "BTC-1231", "type": "update", "data": {"time": 1626993917.0566037, "checksum": 2849339311, "bids": [[32820.0, 0.25], [32252.0, 0.0]], "asks": [], "action": "update"}}
1626993917.105101: {"channel": "orderbook", "market": "MKR-PERP", "type": "update", "data": {"time": 1626993917.0845983, "checksum": 1634684154, "bids": [], "asks": [[2422.5, 1.277]], "action": "update"}}
1626993917.148387: {"channel": "orderbook", "market": "BTC-1231", "type": "update", "data": {"time": 1626993917.1268406, "checksum": 1876740160, "bids": [[32817.0, 0.01], [32282.0, 0.0]], "asks": [], "action": "update"}}
1626993917.175621: {"channel": "orderbook", "market": "MKR-PERP", "type": "update", "data": {"time": 1626993917.149839, "checksum": 3933681160, "bids": [], "asks": [[2445.5, 70.267]], "action": "update"}}
1626993917.175741: {"channel": "orderbook", "market": "BTC-1231", "type": "update", "data": {"time": 1626993917.150745, "checksum": 2262234876, "bids": [[32821.0, 0.25], [32289.0, 0.0]], "asks": [], "action": "update"}}
1626993917.194199: {"channel": "orderbook", "market": "BTC-1231", "type": "update", "data": {"time": 1626993917.1732576, "checksum": 2626891015, "bids": [[32820.0, 0.0], [32817.0, 0.0], [32717.0, 8.4561], [32289.0, 0.1421], [32282.0, 0.0002]], "asks": [], "action": "update"}}
1626993917.242995: {"channel": "orderbook", "market": "BTC-1231", "type": "update", "data": {"time": 1626993917.2203395, "checksum": 362690626, "bids": [[32758.0, 0.0], [32252.0, 0.0004]], "asks": [], "action": "update"}}
1626993917.243496: {"channel": "orderbook", "market": "FLOW-PERP", "type": "update", "data": {"time": 1626993917.224039, "checksum": 357568391, "bids": [], "asks": [[17.15, 0.0], [18.9, 1500.0]], "action": "update"}}
1626993917.2805288: {"channel": "orderbook", "market": "BTC-1231", "type": "update", "data": {"time": 1626993917.2539046, "checksum": 154164743, "bids": [[32822.0, 0.01], [32252.0, 0.0]], "asks": [], "action": "update"}}
1626993917.280633: {"channel": "orderbook", "market": "BNBBEAR/USDT", "type": "update", "data": {"time": 1626993917.2567806, "checksum": 884149509, "bids": [], "asks": [], "action": "update"}}
1626993917.2806778: {"channel": "orderbook", "market": "KNCBULL/USDT", "type": "update", "data": {"time": 1626993917.2599533, "checksum": 4188723151, "bids": [], "asks": [], "action": "update"}}
1626993917.310169: {"channel": "orderbook", "market": "FLOW-PERP", "type": "update", "data": {"time": 1626993917.2742658, "checksum": 3658284887, "bids": [], "asks": [[17.145, 46.64], [18.9, 0.0]], "action": "update"}}
1626993917.370628: {"channel": "orderbook", "market": "MKR-PERP", "type": "update", "data": {"time": 1626993917.3430362, "checksum": 2725479002, "bids": [[2410.0, 3.133]], "asks": [], "action": "update"}}
1626993917.398284: {"channel": "orderbook", "market": "BB-0924", "type": "update", "data": {"time": 1626993917.378964, "checksum": 1359273830, "bids": [], "asks": [], "action": "update"}}
1626993917.416503: {"channel": "orderbook", "market": "BTC-1231", "type": "update", "data": {"time": 1626993917.3830833, "checksum": 1211644563, "bids": [[32822.0, 0.26], [32752.0, 0.1], [32282.0, 0.0]], "asks": [], "action": "update"}}
1626993917.4559538: {"channel": "orderbook", "market": "BTC-1231", "type": "update", "data": {"time": 1626993917.4333506, "checksum": 572706435, "bids": [[32821.0, 0.0], [32282.0, 0.0002]], "asks": [], "action": "update"}}
1626993917.465578: {"channel": "orderbook", "market": "MKR-PERP", "type": "update", "data": {"time": 1626993917.4157758, "checksum": 528268772, "bids": [[2410.0, 3.264]], "asks": [], "action": "update"}}
1626993917.518205: {"channel": "orderbook", "market": "BTC-1231", "type": "update", "data": {"time": 1626993917.4776373, "checksum": 341006429, "bids": [[32748.0, 0.0], [32252.0, 0.0004]], "asks": [], "action": "update"}}
1626993917.620211: {"channel": "orderbook", "market": "FLOW-PERP", "type": "update", "data": {"time": 1626993917.5988712, "checksum": 2726643993, "bids": [[16.155, 1238.08]], "asks": [[16.69, 1198.47]], "action": "update"}}
1626993917.699931: {"channel": "orderbook", "market": "APHA/USD", "type": "update", "data": {"time": 1626993917.6687663, "checksum": 756393738, "bids": [], "asks": [], "action": "update"}}
1626993917.760247: {"channel": "orderbook", "market": "MKR-PERP", "type": "update", "data": {"time": 1626993917.726932, "checksum": 528268772, "bids": [], "asks": [], "action": "update"}}
1626993917.815916: {"channel": "orderbook", "market": "PFE/USD", "type": "update", "data": {"time": 1626993917.7959933, "checksum": 825829276, "bids": [], "asks": [], "action": "update"}}
1626993917.8321059: {"channel": "orderbook", "market": "BTC-1231", "type": "update", "data": {"time": 1626993917.8096552, "checksum": 1438876754, "bids": [], "asks": [[32846.0, 6.5519]], "action": "update"}}
1626993917.8322291: {"channel": "orderbook", "market": "CHZ/USDT", "type": "update", "data": {"time": 1626993917.8094025, "checksum": 1754082163, "bids": [], "asks": [], "action": "update"}}
1626993917.8553731: {"channel": "orderbook", "market": "CAD/USD", "type": "update", "data": {"time": 1626993917.8340514, "checksum": 706162672, "bids": [], "asks": [], "action": "update"}}
1626993917.9162052: {"channel": "orderbook", "market": "CHZ/USDT", "type": "update", "data": {"time": 1626993917.8964493, "checksum": 4044402277, "bids": [[0.22786, 9160.0]], "asks": [], "action": "update"}}
1626993917.919282: {"channel": "orderbook", "market": "FLOW-PERP", "type": "update", "data": {"time": 1626993917.8983552, "checksum": 2726643993, "bids": [], "asks": [], "action": "update"}}
1626993917.95567: {"channel": "orderbook", "market": "BTC-1231", "type": "update", "data": {"time": 1626993917.9340854, "checksum": 1438876754, "bids": [], "asks": [], "action": "update"}}
1626993917.972652: {"channel": "orderbook", "market": "MKR-PERP", "type": "update", "data": {"time": 1626993917.9516072, "checksum": 4213261962, "bids": [], "asks": [[2417.0, 0.472], [2800.0, 0.0]], "action": "update"}}
1626993918.0069199: {"channel": "orderbook", "market": "BTC-1231", "type": "update", "data": {"time": 1626993917.98611, "checksum": 856050459, "bids": [[32750.0, 0.005], [32252.0, 0.0]], "asks": [], "action": "update"}}
1626993918.0202801: {"channel": "orderbook", "market": "FLOW-PERP", "type": "update", "data": {"time": 1626993917.9829192, "checksum": 2603606991, "bids": [], "asks": [[17.145, 0.0], [18.9, 1500.0]], "action": "update"}}
1626993918.030079: {"channel": "orderbook", "market": "FLOW-PERP", "type": "update", "data": {"time": 1626993918.0108163, "checksum": 59197154, "bids": [], "asks": [[17.15, 5.83], [18.9, 0.0]], "action": "update"}}
1626993918.191494: {"channel": "orderbook", "market": "BTC-1231", "type": "update", "data": {"time": 1626993918.1613612, "checksum": 3900388264, "bids": [], "asks": [[32842.0, 9.4882], [33442.0, 0.0]], "action": "update"}}
1626993918.225579: {"channel": "orderbook", "market": "BTC-1231", "type": "update", "data": {"time": 1626993918.2003407, "checksum": 4218264814, "bids": [], "asks": [[32846.0, 0.0], [33442.0, 0.025]], "action": "update"}}
1626993918.274112: {"channel": "orderbook", "market": "BTC-1231", "type": "update", "data": {"time": 1626993918.247919, "checksum": 1466073528, "bids": [[32714.0, 0.2292], [32282.0, 0.0]], "asks": [[32842.0, 9.4906], [32845.0, 0.0], [33447.0, 0.168]], "action": "update"}}
1626993918.3065898: {"channel": "orderbook", "market": "KNCBULL/USDT", "type": "update", "data": {"time": 1626993918.2852974, "checksum": 4188723151, "bids": [], "asks": [], "action": "update"}}
1626993918.3136158: {"channel": "orderbook", "market": "BTC-1231", "type": "update", "data": {"time": 1626993918.2934215, "checksum": 2819288938, "bids": [[32822.0, 0.25]], "asks": [], "action": "update"}}
1626993918.317801: {"channel": "orderbook", "market": "BNBBEAR/USDT", "type": "update", "data": {"time": 1626993918.2873452, "checksum": 884149509, "bids": [], "asks": [], "action": "update"}}
1626993918.344564: {"channel": "orderbook", "market": "BTC-1231", "type": "update", "data": {"time": 1626993918.3181937, "checksum": 4159088134, "bids": [[32822.0, 0.0], [32282.0, 0.0002]], "asks": [], "action": "update"}}
1626993918.382874: {"channel": "orderbook", "market": "FLOW-PERP", "type": "update", "data": {"time": 1626993918.358882, "checksum": 567011294, "bids": [[16.155, 1609.44]], "asks": [], "action": "update"}}
1626993918.4225159: {"channel": "orderbook", "market": "BTC-1231", "type": "update", "data": {"time": 1626993918.3988626, "checksum": 4214596415, "bids": [[32823.0, 0.01], [32818.0, 0.25], [32289.0, 0.0], [32282.0, 0.0]], "asks": [], "action": "update"}}
1626993918.42305: {"channel": "orderbook", "market": "BB-0924", "type": "update", "data": {"time": 1626993918.4024491, "checksum": 1359273830, "bids": [], "asks": [], "action": "update"}}
1626993918.454093: {"channel": "orderbook", "market": "FLOW-PERP", "type": "update", "data": {"time": 1626993918.4339986, "checksum": 3263494015, "bids": [], "asks": [[16.69, 1558.01]], "action": "update"}}
1626993918.479281: {"channel": "orderbook", "market": "BTC-1231", "type": "update", "data": {"time": 1626993918.4476368, "checksum": 4159088134, "bids": [[32823.0, 0.0], [32818.0, 0.0], [32289.0, 0.1421], [32282.0, 0.0002]], "asks": [], "action": "update"}}
1626993918.565844: {"channel": "orderbook", "market": "BTC-1231", "type": "update", "data": {"time": 1626993918.5437968, "checksum": 3891061063, "bids": [[32824.0, 0.01], [32819.0, 0.25], [32289.0, 0.0], [32282.0, 0.0]], "asks": [], "action": "update"}}
1626993918.593281: {"channel": "orderbook", "market": "BTC-1231", "type": "update", "data": {"time": 1626993918.5702326, "checksum": 1359072505, "bids": [[32819.0, 0.0], [32714.0, 0.0], [32289.0, 0.1421], [32282.0, 0.0002]], "asks": [], "action": "update"}}
1626993918.649544: {"channel": "orderbook", "market": "BTC-1231", "type": "update", "data": {"time": 1626993918.6266637, "checksum": 2824983956, "bids": [[32824.0, 0.0], [32252.0, 0.0004]], "asks": [], "action": "update"}}
1626993918.714379: {"channel": "orderbook", "market": "BTC-1231", "type": "update", "data": {"time": 1626993918.6942854, "checksum": 2194218109, "bids": [[32819.0, 0.25], [32252.0, 0.0]], "asks": [], "action": "update"}}
1626993918.7165911: {"channel": "orderbook", "market": "APHA/USD", "type": "update", "data": {"time": 1626993918.6944962, "checksum": 756393738, "bids": [], "asks": [], "action": "update"}}
1626993918.739976: {"channel": "orderbook", "market": "BTC-1231", "type": "update", "data": {"time": 1626993918.7188537, "checksum": 2708618, "bids": [[32817.0, 0.01], [32282.0, 0.0]], "asks": [], "action": "update"}}
1626993918.787888: {"channel": "orderbook", "market": "MKR-PERP", "type": "update", "data": {"time": 1626993918.7583582, "checksum": 4213261962, "bids": [], "asks": [], "action": "update"}}
1626993918.788498: {"channel": "orderbook", "market": "BTC-1231", "type": "update", "data": {"time": 1626993918.7684858, "checksum": 629828226, "bids": [[32820.0, 0.25], [32817.0, 0.0]], "asks": [[32846.0, 10.5595], [33447.0, 0.0]], "action": "update"}}
1626993918.838062: {"channel": "orderbook", "market": "BTC-1231", "type": "update", "data": {"time": 1626993918.817386, "checksum": 1009907080, "bids": [[32819.0, 0.0], [32282.0, 0.0002]], "asks": [[32842.0, 0.0024]], "action": "update"}}
1626993918.850563: {"channel": "orderbook", "market": "PFE/USD", "type": "update", "data": {"time": 1626993918.827715, "checksum": 825829276, "bids": [], "asks": [], "action": "update"}}
1626993918.859424: {"channel": "orderbook", "market": "CHZ/USDT", "type": "update", "data": {"time": 1626993918.8371801, "checksum": 4044402277, "bids": [], "asks": [], "action": "update"}}
1626993918.87765: {"channel": "orderbook", "market": "BTC-1231", "type": "update", "data": {"time": 1626993918.8499455, "checksum": 3030074339, "bids": [[32821.0, 0.26], [32750.0, 0.0]], "asks": [], "action": "update"}}
1626993918.8927412: {"channel": "orderbook", "market": "BTC-1231", "type": "update", "data": {"time": 1626993918.8716624, "checksum": 2505449453, "bids": [], "asks": [[32842.0, 0.0], [33447.0, 0.168]], "action": "update"}}
1626993918.927807: {"channel": "orderbook", "market": "BTC-1231", "type": "update", "data": {"time": 1626993918.8949125, "checksum": 1099853852, "bids": [[32820.0, 0.0], [32252.0, 0.0004]], "asks": [], "action": "update"}}
1626993918.933564: {"channel": "orderbook", "market": "FLOW-PERP", "type": "update", "data": {"time": 1626993918.9101384, "checksum": 3263494015, "bids": [], "asks": [], "action": "update"}}
1626993918.9568708: {"channel": "orderbook", "market": "BTC-1231", "type": "update", "data": {"time": 1626993918.9280553, "checksum": 2552445073, "bids": [], "asks": [[32845.0, 0.0024], [33447.0, 0.0]], "action": "update"}}
1626993918.9784021: {"channel": "orderbook", "market": "BTC-1231", "type": "update", "data": {"time": 1626993918.9532316, "checksum": 2552445073, "bids": [], "asks": [], "action": "update"}}
1626993919.0669398: {"channel": "orderbook", "market": "CAD/USD", "type": "update", "data": {"time": 1626993919.0400243, "checksum": 706162672, "bids": [], "asks": [], "action": "update"}}
1626993919.350184: {"channel": "orderbook", "market": "KNCBULL/USDT", "type": "update", "data": {"time": 1626993919.3136714, "checksum": 4188723151, "bids": [], "asks": [], "action": "update"}}
1626993919.350283: {"channel": "orderbook", "market": "BNBBEAR/USDT", "type": "update", "data": {"time": 1626993919.3199704, "checksum": 884149509, "bids": [], "asks": [], "action": "update"}}
1626993919.39555: {"channel": "orderbook", "market": "BTC-1231", "type": "update", "data": {"time": 1626993919.374923, "checksum": 79436782, "bids": [[32750.0, 0.005], [32252.0, 0.0]], "asks": [], "action": "update"}}
1626993919.4608052: {"channel": "orderbook", "market": "BB-0924", "type": "update", "data": {"time": 1626993919.4365063, "checksum": 1359273830, "bids": [], "asks": [], "action": "update"}}
1626993919.619044: {"channel": "orderbook", "market": "BTC-1231", "type": "update", "data": {"time": 1626993919.5981688, "checksum": 309055854, "bids": [], "asks": [[32853.0, 0.105], [33442.0, 0.0]], "action": "update"}}
1626993919.6297028: {"channel": "orderbook", "market": "MKR-PERP", "type": "update", "data": {"time": 1626993919.5964835, "checksum": 3120229140, "bids": [], "asks": [[2445.5, 12.267]], "action": "update"}}
1626993919.680784: {"channel": "orderbook", "market": "BTC-1231", "type": "update", "data": {"time": 1626993919.6561627, "checksum": 2313933110, "bids": [[32713.0, 0.2292], [32282.0, 0.0]], "asks": [], "action": "update"}}
1626993919.747755: {"channel": "orderbook", "market": "APHA/USD", "type": "update", "data": {"time": 1626993919.7214744, "checksum": 756393738, "bids": [], "asks": [], "action": "update"}}
1626993919.794796: {"channel": "orderbook", "market": "MKR-PERP", "type": "update", "data": {"time": 1626993919.7734416, "checksum": 3120229140, "bids": [], "asks": [], "action": "update"}}
1626993919.8672261: {"channel": "orderbook", "market": "PFE/USD", "type": "update", "data": {"time": 1626993919.847796, "checksum": 825829276, "bids": [], "asks": [], "action": "update"}}
1626993919.8842812: {"channel": "orderbook", "market": "CHZ/USDT", "type": "update", "data": {"time": 1626993919.8627093, "checksum": 4044402277, "bids": [], "asks": [], "action": "update"}}
1626993919.955255: {"channel": "orderbook", "market": "FLOW-PERP", "type": "update", "data": {"time": 1626993919.9333248, "checksum": 3263494015, "bids": [], "asks": [], "action": "update"}}
1626993919.999639: {"channel": "orderbook", "market": "BTC-1231", "type": "update", "data": {"time": 1626993919.9770727, "checksum": 2313933110, "bids": [], "asks": [], "action": "update"}}
1626993920.031567: {"channel": "orderbook", "market": "FLOW-PERP", "type": "update", "data": {"time": 1626993919.9876113, "checksum": 2756900453, "bids": [], "asks": [[16.48, 143.7]], "action": "update"}}
1626993920.106205: {"channel": "orderbook", "market": "CAD/USD", "type": "update", "data": {"time": 1626993920.0761018, "checksum": 706162672, "bids": [], "asks": [], "action": "update"}}
1626993920.4617128: {"channel": "orderbook", "market": "BTC-1231", "type": "update", "data": {"time": 1626993920.3276403, "checksum": 2306238103, "bids": [], "asks": [[32832.0, 0.0], [33442.0, 0.025]], "action": "update"}}
1626993920.4618812: {"channel": "orderbook", "market": "KNCBULL/USDT", "type": "update", "data": {"time": 1626993920.3379016, "checksum": 4188723151, "bids": [], "asks": [], "action": "update"}}
1626993920.4619288: {"channel": "orderbook", "market": "BNBBEAR/USDT", "type": "update", "data": {"time": 1626993920.347392, "checksum": 884149509, "bids": [], "asks": [], "action": "update"}}
1626993920.4619699: {"channel": "orderbook", "market": "BTC-1231", "type": "update", "data": {"time": 1626993920.3740633, "checksum": 3657073210, "bids": [[32821.0, 0.01]], "asks": [], "action": "update"}}
1626993920.462018: {"channel": "orderbook", "market": "BTC-1231", "type": "update", "data": {"time": 1626993920.427231, "checksum": 1024547394, "bids": [[32821.0, 0.0], [32282.0, 0.0002]], "asks": [[32832.0, 0.0004], [33442.0, 0.0]], "action": "update"}}
1626993920.4935732: {"channel": "orderbook", "market": "BB-0924", "type": "update", "data": {"time": 1626993920.4684465, "checksum": 1359273830, "bids": [], "asks": [], "action": "update"}}
1626993920.546761: {"channel": "orderbook", "market": "BTC-1231", "type": "update", "data": {"time": 1626993920.5255003, "checksum": 912798630, "bids": [[32822.0, 0.01], [32819.0, 0.25], [32289.0, 0.0], [32282.0, 0.0]], "asks": [[32852.0, 0.1028], [33438.0, 0.0]], "action": "update"}}
1626993920.5729809: {"channel": "orderbook", "market": "BTC-1231", "type": "update", "data": {"time": 1626993920.5494444, "checksum": 2106531339, "bids": [[32819.0, 0.0], [32289.0, 0.1421]], "asks": [], "action": "update"}}
1626993920.598409: {"channel": "orderbook", "market": "BTC-1231", "type": "update", "data": {"time": 1626993920.5750318, "checksum": 1853873805, "bids": [[32822.0, 0.0], [32282.0, 0.0002]], "asks": [], "action": "update"}}
1626993920.67051: {"channel": "orderbook", "market": "BTC-1231", "type": "update", "data": {"time": 1626993920.6388311, "checksum": 4007152503, "bids": [[32817.0, 0.25], [32713.0, 0.0]], "asks": [], "action": "update"}}
1626993920.707347: {"channel": "orderbook", "market": "BTC-1231", "type": "update", "data": {"time": 1626993920.6829216, "checksum": 668980068, "bids": [[32817.0, 0.26]], "asks": [[32842.0, 8.066], [32846.0, 0.0]], "action": "update"}}
1626993920.735574: {"channel": "orderbook", "market": "BTC-1231", "type": "update", "data": {"time": 1626993920.7131083, "checksum": 1587632011, "bids": [[32818.0, 0.25], [32817.0, 0.01], [32282.0, 0.0]], "asks": [], "action": "update"}}
1626993920.772086: {"channel": "orderbook", "market": "MKR-PERP", "type": "update", "data": {"time": 1626993920.748436, "checksum": 193201409, "bids": [], "asks": [[2444.0, 0.455]], "action": "update"}}
1626993920.772629: {"channel": "orderbook", "market": "APHA/USD", "type": "update", "data": {"time": 1626993920.7474778, "checksum": 756393738, "bids": [], "asks": [], "action": "update"}}
1626993920.78001: {"channel": "orderbook", "market": "BTC-1231", "type": "update", "data": {"time": 1626993920.758232, "checksum": 2580816550, "bids": [[32818.0, 0.0], [32282.0, 0.0002]], "asks": [[32845.0, 0.0], [33438.0, 0.0002]], "action": "update"}}
1626993920.8069508: {"channel": "orderbook", "market": "BTC-1231", "type": "update", "data": {"time": 1626993920.7855635, "checksum": 3052344232, "bids": [[32817.0, 0.0], [32252.0, 0.0004]], "asks": [[32842.0, 8.0684]], "action": "update"}}
1626993920.824964: {"channel": "orderbook", "market": "MKR-PERP", "type": "update", "data": {"time": 1626993920.791705, "checksum": 1185911315, "bids": [[2391.0, 9.469]], "asks": [], "action": "update"}}
1626993920.870938: {"channel": "orderbook", "market": "BTC-1231", "type": "update", "data": {"time": 1626993920.8497353, "checksum": 836277435, "bids": [[32818.0, 0.25], [32252.0, 0.0]], "asks": [], "action": "update"}}
1626993920.8993511: {"channel": "orderbook", "market": "PFE/USD", "type": "update", "data": {"time": 1626993920.8777888, "checksum": 825829276, "bids": [], "asks": [], "action": "update"}}
1626993920.9146519: {"channel": "orderbook", "market": "CHZ/USDT", "type": "update", "data": {"time": 1626993920.8915758, "checksum": 4044402277, "bids": [], "asks": [], "action": "update"}}
1626993920.929724: {"channel": "orderbook", "market": "BTC-1231", "type": "update", "data": {"time": 1626993920.9061463, "checksum": 2658986928, "bids": [[32817.0, 0.01], [32282.0, 0.0]], "asks": [], "action": "update"}}
1626993920.948863: {"channel": "orderbook", "market": "BTC-1231", "type": "update", "data": {"time": 1626993920.9242399, "checksum": 3922303895, "bids": [[32819.0, 0.25], [32289.0, 0.0]], "asks": [], "action": "update"}}
1626993920.957312: {"channel": "orderbook", "market": "CHZ/USDT", "type": "update", "data": {"time": 1626993920.9376023, "checksum": 1381092805, "bids": [[0.227951, 3890.0]], "asks": [], "action": "update"}}
1626993920.968844: {"channel": "orderbook", "market": "FLOW-PERP", "type": "update", "data": {"time": 1626993920.9446983, "checksum": 2756900453, "bids": [], "asks": [], "action": "update"}}
1626993920.990827: {"channel": "orderbook", "market": "BTC-1231", "type": "update", "data": {"time": 1626993920.9637434, "checksum": 3894832474, "bids": [[32818.0, 0.0], [32817.0, 0.0], [32289.0, 0.1421], [32282.0, 0.0002]], "asks": [], "action": "update"}}
1626993921.02288: {"channel": "orderbook", "market": "BTC-1231", "type": "update", "data": {"time": 1626993920.988893, "checksum": 3894832474, "bids": [], "asks": [], "action": "update"}}
1626993921.0685508: {"channel": "orderbook", "market": "BTC-1231", "type": "update", "data": {"time": 1626993921.0411549, "checksum": 122587664, "bids": [], "asks": [[32844.0, 0.2283], [33438.0, 0.0]], "action": "update"}}
1626993921.098212: {"channel": "orderbook", "market": "BTC-1231", "type": "update", "data": {"time": 1626993921.065845, "checksum": 2453234206, "bids": [[32820.0, 0.01], [32282.0, 0.0]], "asks": [], "action": "update"}}
1626993921.143559: {"channel": "orderbook", "market": "FLOW-PERP", "type": "update", "data": {"time": 1626993921.120818, "checksum": 3772156332, "bids": [], "asks": [[16.77, 81.86], [18.785, 0.0]], "action": "update"}}
1626993921.155169: {"channel": "orderbook", "market": "CAD/USD", "type": "update", "data": {"time": 1626993921.1269796, "checksum": 706162672, "bids": [], "asks": [], "action": "update"}}
1626993921.2060559: {"channel": "orderbook", "market": "BTC-1231", "type": "update", "data": {"time": 1626993921.1752052, "checksum": 2427509927, "bids": [[32820.0, 0.26]], "asks": [[32853.0, 0.0], [33438.0, 0.0002]], "action": "update"}}
1626993921.244413: {"channel": "orderbook", "market": "BTC-1231", "type": "update", "data": {"time": 1626993921.2242124, "checksum": 3272426792, "bids": [[32819.0, 0.0], [32282.0, 0.0002]], "asks": [], "action": "update"}}
1626993921.292923: {"channel": "orderbook", "market": "BTC-1231", "type": "update", "data": {"time": 1626993921.2718415, "checksum": 4210591176, "bids": [[32821.0, 0.25], [32282.0, 0.0]], "asks": [], "action": "update"}}
1626993921.319499: {"channel": "orderbook", "market": "BTC-1231", "type": "update", "data": {"time": 1626993921.2959788, "checksum": 2540170667, "bids": [[32820.0, 0.01]], "asks": [], "action": "update"}}
1626993921.345899: {"channel": "orderbook", "market": "BTC-1231", "type": "update", "data": {"time": 1626993921.3213778, "checksum": 232619413, "bids": [[32820.0, 0.0], [32282.0, 0.0002]], "asks": [], "action": "update"}}
1626993921.3894532: {"channel": "orderbook", "market": "BNBBEAR/USDT", "type": "update", "data": {"time": 1626993921.363619, "checksum": 884149509, "bids": [], "asks": [], "action": "update"}}
1626993921.389548: {"channel": "orderbook", "market": "KNCBULL/USDT", "type": "update", "data": {"time": 1626993921.3632174, "checksum": 4188723151, "bids": [], "asks": [], "action": "update"}}
1626993921.426235: {"channel": "orderbook", "market": "MKR-PERP", "type": "update", "data": {"time": 1626993921.4012344, "checksum": 2819150168, "bids": [[2383.5, 0.001]], "asks": [], "action": "update"}}
1626993921.456167: {"channel": "orderbook", "market": "BTC-1231", "type": "update", "data": {"time": 1626993921.42087, "checksum": 1652915787, "bids": [[32822.0, 0.01], [32282.0, 0.0]], "asks": [], "action": "update"}}
1626993921.522177: {"channel": "orderbook", "market": "BB-0924", "type": "update", "data": {"time": 1626993921.5002408, "checksum": 1359273830, "bids": [], "asks": [], "action": "update"}}
1626993921.551556: {"channel": "orderbook", "market": "BTC-1231", "type": "update", "data": {"time": 1626993921.5283473, "checksum": 3943755579, "bids": [[32822.0, 0.26]], "asks": [], "action": "update"}}
1626993921.612169: {"channel": "orderbook", "market": "BTC-1231", "type": "update", "data": {"time": 1626993921.583782, "checksum": 3084131143, "bids": [[32821.0, 0.0], [32282.0, 0.0002]], "asks": [], "action": "update"}}
1626993921.750774: {"channel": "orderbook", "market": "BTC-1231", "type": "update", "data": {"time": 1626993921.7290897, "checksum": 289202401, "bids": [[32712.0, 0.2292], [32282.0, 0.0]], "asks": [], "action": "update"}}
1626993921.793408: {"channel": "orderbook", "market": "APHA/USD", "type": "update", "data": {"time": 1626993921.7695653, "checksum": 756393738, "bids": [], "asks": [], "action": "update"}}
1626993921.8388789: {"channel": "orderbook", "market": "MKR-PERP", "type": "update", "data": {"time": 1626993921.815419, "checksum": 2819150168, "bids": [], "asks": [], "action": "update"}}
1626993921.892629: {"channel": "orderbook", "market": "MKR-PERP", "type": "update", "data": {"time": 1626993921.8701205, "checksum": 3844294218, "bids": [[2391.0, 10.693]], "asks": [], "action": "update"}}
1626993921.925764: {"channel": "orderbook", "market": "PFE/USD", "type": "update", "data": {"time": 1626993921.9053698, "checksum": 825829276, "bids": [], "asks": [], "action": "update"}}
1626993921.9396951: {"channel": "orderbook", "market": "CHZ/USDT", "type": "update", "data": {"time": 1626993921.914658, "checksum": 1381092805, "bids": [], "asks": [], "action": "update"}}
1626993921.97422: {"channel": "orderbook", "market": "MKR-PERP", "type": "update", "data": {"time": 1626993921.945218, "checksum": 1465755743, "bids": [], "asks": [[2444.0, 1.653]], "action": "update"}}
1626993922.000938: {"channel": "orderbook", "market": "FLOW-PERP", "type": "update", "data": {"time": 1626993921.9782104, "checksum": 3772156332, "bids": [], "asks": [], "action": "update"}}
1626993922.0265532: {"channel": "orderbook", "market": "BTC-1231", "type": "update", "data": {"time": 1626993922.0018775, "checksum": 289202401, "bids": [], "asks": [], "action": "update"}}
1626993922.105147: {"channel": "orderbook", "market": "MKR-PERP", "type": "update", "data": {"time": 1626993922.0778153, "checksum": 2079297677, "bids": [[2415.0, 0.631], [2103.0, 0.0]], "asks": [[2417.0, 0.0], [2445.5, 70.267], [2800.0, 0.035]], "action": "update"}}
1626993922.1947331: {"channel": "orderbook", "market": "CAD/USD", "type": "update", "data": {"time": 1626993922.1721866, "checksum": 706162672, "bids": [], "asks": [], "action": "update"}}
1626993922.3610141: {"channel": "orderbook", "market": "MKR-PERP", "type": "update", "data": {"time": 1626993922.3338282, "checksum": 681854917, "bids": [[2414.5, 0.0], [2103.0, 0.5]], "asks": [[2416.5, 1.935], [2417.5, 1.02]], "action": "update"}}
1626993922.4110239: {"channel": "orderbook", "market": "KNCBULL/USDT", "type": "update", "data": {"time": 1626993922.3886023, "checksum": 4188723151, "bids": [], "asks": [], "action": "update"}}
1626993922.4139452: {"channel": "orderbook", "market": "BNBBEAR/USDT", "type": "update", "data": {"time": 1626993922.3912196, "checksum": 884149509, "bids": [], "asks": [], "action": "update"}}
1626993922.4305038: {"channel": "orderbook", "market": "BTC-1231", "type": "update", "data": {"time": 1626993922.3910646, "checksum": 137950283, "bids": [[32822.0, 0.25]], "asks": [], "action": "update"}}
1626993922.4892879: {"channel": "orderbook", "market": "MKR-PERP", "type": "update", "data": {"time": 1626993922.4493504, "checksum": 2414243666, "bids": [], "asks": [[2418.0, 0.0], [2813.0, 0.001]], "action": "update"}}
1626993922.514969: {"channel": "orderbook", "market": "BTC-1231", "type": "update", "data": {"time": 1626993922.4942143, "checksum": 2097054012, "bids": [[32823.0, 0.26], [32289.0, 0.0]], "asks": [], "action": "update"}}
1626993922.558634: {"channel": "orderbook", "market": "BTC-1231", "type": "update", "data": {"time": 1626993922.53754, "checksum": 3337145590, "bids": [[32822.0, 0.0], [32289.0, 0.1421]], "asks": [], "action": "update"}}
1626993922.60791: {"channel": "orderbook", "market": "BB-0924", "type": "update", "data": {"time": 1626993922.5850263, "checksum": 1359273830, "bids": [], "asks": [], "action": "update"}}
1626993922.7471108: {"channel": "orderbook", "market": "MKR-PERP", "type": "update", "data": {"time": 1626993922.7172766, "checksum": 3116314036, "bids": [[2415.0, 0.0], [2099.0, 0.001]], "asks": [[2416.5, 2.301]], "action": "update"}}
1626993922.803027: {"channel": "orderbook", "market": "BTC-1231", "type": "update", "data": {"time": 1626993922.7820222, "checksum": 2260913995, "bids": [], "asks": [[32844.0, 0.0], [33442.0, 0.025]], "action": "update"}}
1626993922.8176389: {"channel": "orderbook", "market": "APHA/USD", "type": "update", "data": {"time": 1626993922.7964587, "checksum": 756393738, "bids": [], "asks": [], "action": "update"}}
1626993922.820927: {"channel": "orderbook", "market": "MKR-PERP", "type": "update", "data": {"time": 1626993922.797084, "checksum": 4053881508, "bids": [[2415.0, 0.464], [2099.0, 0.0]], "asks": [], "action": "update"}}
1626993922.857879: {"channel": "orderbook", "market": "MKR-PERP", "type": "update", "data": {"time": 1626993922.8298538, "checksum": 3227744616, "bids": [], "asks": [[2416.0, 0.426], [2813.0, 0.0]], "action": "update"}}
1626993922.927455: {"channel": "orderbook", "market": "MKR-PERP", "type": "update", "data": {"time": 1626993922.9022648, "checksum": 4053881508, "bids": [], "asks": [[2416.0, 0.0], [2813.0, 0.001]], "action": "update"}}
1626993922.952862: {"channel": "orderbook", "market": "BTC-1231", "type": "update", "data": {"time": 1626993922.9250085, "checksum": 234450717, "bids": [], "asks": [[32830.0, 0.0005], [33442.0, 0.0]], "action": "update"}}
1626993922.953015: {"channel": "orderbook", "market": "PFE/USD", "type": "update", "data": {"time": 1626993922.9286792, "checksum": 825829276, "bids": [], "asks": [], "action": "update"}}
1626993922.977558: {"channel": "orderbook", "market": "CHZ/USDT", "type": "update", "data": {"time": 1626993922.948969, "checksum": 1381092805, "bids": [], "asks": [], "action": "update"}}
1626993923.031233: {"channel": "orderbook", "market": "FLOW-PERP", "type": "update", "data": {"time": 1626993922.9983442, "checksum": 3772156332, "bids": [], "asks": [], "action": "update"}}
1626993923.031348: {"channel": "orderbook", "market": "BTC-1231", "type": "update", "data": {"time": 1626993922.9939506, "checksum": 560384565, "bids": [[32824.0, 0.25], [32289.0, 0.0]], "asks": [[32901.0, 0.0], [33442.0, 0.025]], "action": "update"}}
1626993923.05701: {"channel": "orderbook", "market": "BTC-1231", "type": "update", "data": {"time": 1626993923.0296798, "checksum": 1676296736, "bids": [[32823.0, 0.01]], "asks": [], "action": "update"}}
1626993923.12172: {"channel": "orderbook", "market": "BTC-1231", "type": "update", "data": {"time": 1626993923.0914254, "checksum": 1841537158, "bids": [[32823.0, 0.0], [32289.0, 0.1421]], "asks": [[32846.0, 7.5562], [33442.0, 0.0]], "action": "update"}}
1626993923.164893: {"channel": "orderbook", "market": "BTC-1231", "type": "update", "data": {"time": 1626993923.1288812, "checksum": 4060657276, "bids": [], "asks": [[32842.0, 0.0024]], "action": "update"}}
1626993923.223677: {"channel": "orderbook", "market": "BTC-1231", "type": "update", "data": {"time": 1626993923.1893573, "checksum": 2107061448, "bids": [[32825.0, 0.01], [32770.0, 0.0]], "asks": [[32842.0, 0.0], [32914.0, 1.0663]], "action": "update"}}
1626993923.229439: {"channel": "orderbook", "market": "CAD/USD", "type": "update", "data": {"time": 1626993923.2087317, "checksum": 706162672, "bids": [], "asks": [], "action": "update"}}
1626993923.2478359: {"channel": "orderbook", "market": "MKR-PERP", "type": "update", "data": {"time": 1626993923.220999, "checksum": 3116314036, "bids": [[2415.0, 0.0], [2099.0, 0.001]], "asks": [], "action": "update"}}
1626993923.2559931: {"channel": "orderbook", "market": "BTC-1231", "type": "update", "data": {"time": 1626993923.2299688, "checksum": 2820090444, "bids": [[32824.0, 0.0], [32282.0, 0.0002]], "asks": [[32845.0, 0.0024], [33438.0, 0.0]], "action": "update"}}
1626993923.3463: {"channel": "orderbook", "market": "BTC-1231", "type": "update", "data": {"time": 1626993923.3089018, "checksum": 3538993066, "bids": [[32825.0, 0.0], [32252.0, 0.0004]], "asks": [], "action": "update"}}
1626993923.346456: {"channel": "orderbook", "market": "MKR-PERP", "type": "update", "data": {"time": 1626993923.3219352, "checksum": 1563660653, "bids": [], "asks": [[2416.0, 0.42], [2813.0, 0.0]], "action": "update"}}
1626993923.4112: {"channel": "orderbook", "market": "BTC-1231", "type": "update", "data": {"time": 1626993923.390916, "checksum": 3225799779, "bids": [[32820.0, 0.25], [32252.0, 0.0]], "asks": [], "action": "update"}}
1626993923.4399638: {"channel": "orderbook", "market": "KNCBULL/USDT", "type": "update", "data": {"time": 1626993923.4166296, "checksum": 4188723151, "bids": [], "asks": [], "action": "update"}}
1626993923.446527: {"channel": "orderbook", "market": "BNBBEAR/USDT", "type": "update", "data": {"time": 1626993923.4189737, "checksum": 884149509, "bids": [], "asks": [], "action": "update"}}
1626993923.47315: {"channel": "orderbook", "market": "BTC-1231", "type": "update", "data": {"time": 1626993923.4482212, "checksum": 3653397885, "bids": [[32817.0, 0.01], [32282.0, 0.0]], "asks": [], "action": "update"}}
1626993923.479172: {"channel": "orderbook", "market": "MKR-PERP", "type": "update", "data": {"time": 1626993923.4510124, "checksum": 2502286354, "bids": [[2409.5, 3.395]], "asks": [], "action": "update"}}
1626993923.52704: {"channel": "orderbook", "market": "BTC-1231", "type": "update", "data": {"time": 1626993923.4994211, "checksum": 2527637915, "bids": [[32821.0, 0.25], [32817.0, 0.0]], "asks": [], "action": "update"}}
1626993923.557329: {"channel": "orderbook", "market": "BTC-1231", "type": "update", "data": {"time": 1626993923.5318403, "checksum": 4239520573, "bids": [[32820.0, 0.0], [32712.0, 0.0], [32282.0, 0.0002], [32252.0, 0.0004]], "asks": [], "action": "update"}}
1626993923.645998: {"channel": "orderbook", "market": "BB-0924", "type": "update", "data": {"time": 1626993923.6221786, "checksum": 1359273830, "bids": [], "asks": [], "action": "update"}}
1626993923.659263: {"channel": "orderbook", "market": "BTC-1231", "type": "update", "data": {"time": 1626993923.6359482, "checksum": 3726201044, "bids": [[32822.0, 0.01], [32252.0, 0.0]], "asks": [[32843.0, 12.4403], [33434.0, 0.0]], "action": "update"}}
1626993923.69972: {"channel": "orderbook", "market": "BTC-1231", "type": "update", "data": {"time": 1626993923.6681504, "checksum": 3698319296, "bids": [[32821.0, 0.0], [32252.0, 0.0004]], "asks": [[32846.0, 0.0], [33434.0, 0.0004]], "action": "update"}}
1626993923.745866: {"channel": "orderbook", "market": "BTC-1231", "type": "update", "data": {"time": 1626993923.7160814, "checksum": 559875019, "bids": [[32816.0, 0.0], [32777.0, 1.077], [32247.0, 0.0002]], "asks": [[32842.0, 0.0024], [32845.0, 0.0]], "action": "update"}}
1626993923.797733: {"channel": "orderbook", "market": "BTC-1231", "type": "update", "data": {"time": 1626993923.7649016, "checksum": 1664809434, "bids": [[32822.0, 0.0], [32242.0, 0.0004]], "asks": [], "action": "update"}}
1626993923.823539: {"channel": "orderbook", "market": "MKR-PERP", "type": "update", "data": {"time": 1626993923.8004344, "checksum": 2964860890, "bids": [], "asks": [[2417.0, 0.454], [2800.0, 0.0]], "action": "update"}}
1626993923.852375: {"channel": "orderbook", "market": "APHA/USD", "type": "update", "data": {"time": 1626993923.831222, "checksum": 756393738, "bids": [], "asks": [], "action": "update"}}
1626993923.857224: {"channel": "orderbook", "market": "MKR-PERP", "type": "update", "data": {"time": 1626993923.8267794, "checksum": 4029887268, "bids": [], "asks": [[2417.5, 0.293]], "action": "update"}}
1626993923.884628: {"channel": "orderbook", "market": "MKR-PERP", "type": "update", "data": {"time": 1626993923.8575175, "checksum": 4029887268, "bids": [], "asks": [], "action": "update"}}
1626993923.905771: {"channel": "orderbook", "market": "BTC-1231", "type": "update", "data": {"time": 1626993923.8798883, "checksum": 1224589168, "bids": [[32816.0, 0.25], [32815.0, 0.01], [32247.0, 0.0], [32242.0, 0.0]], "asks": [[32832.0, 0.0159]], "action": "update"}}
1626993923.954839: {"channel": "orderbook", "market": "BTC-1231", "type": "update", "data": {"time": 1626993923.927962, "checksum": 1268890141, "bids": [[32741.0, 0.01], [32252.0, 0.0]], "asks": [], "action": "update"}}
1626993923.962806: {"channel": "orderbook", "market": "MKR-PERP", "type": "update", "data": {"time": 1626993923.9353719, "checksum": 3743615378, "bids": [], "asks": [[2418.0, 0.47], [2795.5, 0.0]], "action": "update"}}
1626993923.9706318: {"channel": "orderbook", "market": "PFE/USD", "type": "update", "data": {"time": 1626993923.9512482, "checksum": 825829276, "bids": [], "asks": [], "action": "update"}}
1626993923.987984: {"channel": "orderbook", "market": "CHZ/USDT", "type": "update", "data": {"time": 1626993923.9671035, "checksum": 1381092805, "bids": [], "asks": [], "action": "update"}}
1626993924.000694: {"channel": "orderbook", "market": "BTC-1231", "type": "update", "data": {"time": 1626993923.9638615, "checksum": 171136964, "bids": [[32817.0, 0.25], [32815.0, 0.0]], "asks": [], "action": "update"}}
1626993924.028508: {"channel": "orderbook", "market": "FLOW-PERP", "type": "update", "data": {"time": 1626993924.0000134, "checksum": 1856595428, "bids": [[16.155, 1238.08]], "asks": [[16.69, 1198.47]], "action": "update"}}
1626993924.033963: {"channel": "orderbook", "market": "BTC-1231", "type": "update", "data": {"time": 1626993924.0020692, "checksum": 1412963753, "bids": [[32816.0, 0.0], [32252.0, 0.0004]], "asks": [[32832.0, 0.0155]], "action": "update"}}
1626993924.093753: {"channel": "orderbook", "market": "BTC-1231", "type": "update", "data": {"time": 1626993924.065433, "checksum": 3027577413, "bids": [], "asks": [[32832.0, 0.61]], "action": "update"}}
1626993924.141691: {"channel": "orderbook", "market": "BTC-1231", "type": "update", "data": {"time": 1626993924.109927, "checksum": 1965521427, "bids": [[32814.0, 0.726], [32811.0, 0.0], [32808.0, 8.75], [32247.0, 0.0002]], "asks": [[32828.0, 0.0004], [32837.0, 0.032], [32839.0, 0.5945], [32914.0, 0.0], [33434.0, 0.0]], "action": "update"}}
1626993924.150083: {"channel": "orderbook", "market": "BTC-1231", "type": "update", "data": {"time": 1626993924.1284714, "checksum": 1324694675, "bids": [[32818.0, 0.01], [32247.0, 0.0]], "asks": [], "action": "update"}}
1626993924.235261: {"channel": "orderbook", "market": "BTC-1231", "type": "update", "data": {"time": 1626993924.2097633, "checksum": 3059150661, "bids": [[32818.0, 0.26]], "asks": [[32834.0, 0.05], [32839.0, 11.5525], [32843.0, 0.0]], "action": "update"}}
1626993924.26657: {"channel": "orderbook", "market": "CAD/USD", "type": "update", "data": {"time": 1626993924.2390983, "checksum": 706162672, "bids": [], "asks": [], "action": "update"}}
1626993924.281153: {"channel": "orderbook", "market": "BTC-1231", "type": "update", "data": {"time": 1626993924.2498734, "checksum": 3036571256, "bids": [[32817.0, 0.0], [32247.0, 0.0002]], "asks": [[32855.0, 0.8122]], "action": "update"}}
1626993924.29422: {"channel": "orderbook", "market": "BTC-1231", "type": "update", "data": {"time": 1626993924.2737453, "checksum": 2377096123, "bids": [], "asks": [[32842.0, 0.0], [33434.0, 0.0004]], "action": "update"}}
1626993924.326785: {"channel": "orderbook", "market": "MKR-PERP", "type": "update", "data": {"time": 1626993924.2900906, "checksum": 3753075191, "bids": [[2414.5, 0.618], [2099.0, 0.0]], "asks": [[2445.5, 12.267]], "action": "update"}}
1626993924.355511: {"channel": "orderbook", "market": "BTC-1231", "type": "update", "data": {"time": 1626993924.326843, "checksum": 3526120619, "bids": [[32777.0, 0.005]], "asks": [[32839.0, 11.5549]], "action": "update"}}
1626993924.386698: {"channel": "orderbook", "market": "MKR-PERP", "type": "update", "data": {"time": 1626993924.3640318, "checksum": 2891256759, "bids": [], "asks": [[2416.0, 0.0], [2795.5, 0.024]], "action": "update"}}
1626993924.427289: {"channel": "orderbook", "market": "MKR-PERP", "type": "update", "data": {"time": 1626993924.403258, "checksum": 660489397, "bids": [], "asks": [[2444.5, 58.0], [2795.5, 0.0]], "action": "update"}}
1626993924.456044: {"channel": "orderbook", "market": "BTC-1231", "type": "update", "data": {"time": 1626993924.427376, "checksum": 3643275010, "bids": [[32741.0, 0.0], [32242.0, 0.0004]], "asks": [], "action": "update"}}
1626993924.462231: {"channel": "orderbook", "market": "BNBBEAR/USDT", "type": "update", "data": {"time": 1626993924.4412937, "checksum": 884149509, "bids": [], "asks": [], "action": "update"}}
1626993924.472768: {"channel": "orderbook", "market": "KNCBULL/USDT", "type": "update", "data": {"time": 1626993924.4476745, "checksum": 4188723151, "bids": [], "asks": [], "action": "update"}}
1626993924.4919732: {"channel": "orderbook", "market": "FLOW-PERP", "type": "update", "data": {"time": 1626993924.4710088, "checksum": 39611608, "bids": [], "asks": [[16.425, 32.19]], "action": "update"}}
1626993924.569859: {"channel": "orderbook", "market": "FLOW-PERP", "type": "update", "data": {"time": 1626993924.549914, "checksum": 2720425882, "bids": [], "asks": [[16.425, 275.26]], "action": "update"}}
1626993924.66519: {"channel": "orderbook", "market": "BTC-1231", "type": "update", "data": {"time": 1626993924.635392, "checksum": 4006378115, "bids": [[32777.0, 1.0917]], "asks": [[32898.0, 1.1121], [33434.0, 0.0]], "action": "update"}}
1626993924.684552: {"channel": "orderbook", "market": "BB-0924", "type": "update", "data": {"time": 1626993924.659533, "checksum": 1359273830, "bids": [], "asks": [], "action": "update"}}
1626993924.8441868: {"channel": "orderbook", "market": "MKR-PERP", "type": "update", "data": {"time": 1626993924.81957, "checksum": 2371344048, "bids": [[2414.5, 0.0], [2099.0, 0.001]], "asks": [[2444.5, 0.0], [2795.5, 0.024]], "action": "update"}}
1626993924.8623: {"channel": "orderbook", "market": "FLOW-PERP", "type": "update", "data": {"time": 1626993924.839244, "checksum": 2372622268, "bids": [[16.155, 1609.44]], "asks": [], "action": "update"}}
1626993924.872894: {"channel": "orderbook", "market": "APHA/USD", "type": "update", "data": {"time": 1626993924.8515584, "checksum": 756393738, "bids": [], "asks": [], "action": "update"}}
1626993924.9115: {"channel": "orderbook", "market": "FLOW-PERP", "type": "update", "data": {"time": 1626993924.8886244, "checksum": 2074898460, "bids": [], "asks": [[16.425, 337.32]], "action": "update"}}
1626993924.911616: {"channel": "orderbook", "market": "MKR-PERP", "type": "update", "data": {"time": 1626993924.8688052, "checksum": 3197141411, "bids": [[2413.5, 3.046]], "asks": [], "action": "update"}}
1626993924.971487: {"channel": "orderbook", "market": "MKR-PERP", "type": "update", "data": {"time": 1626993924.9396136, "checksum": 196760011, "bids": [[2414.0, 0.71]], "asks": [[2444.5, 58.0], [2795.5, 0.0]], "action": "update"}}
1626993925.0053499: {"channel": "orderbook", "market": "FLOW-PERP", "type": "update", "data": {"time": 1626993924.9620185, "checksum": 3667831922, "bids": [], "asks": [[16.69, 1558.01]], "action": "update"}}
1626993925.005426: {"channel": "orderbook", "market": "PFE/USD", "type": "update", "data": {"time": 1626993924.9829936, "checksum": 825829276, "bids": [], "asks": [], "action": "update"}}
1626993925.0288372: {"channel": "orderbook", "market": "MKR-PERP", "type": "update", "data": {"time": 1626993924.9849854, "checksum": 1256188560, "bids": [], "asks": [[2416.0, 0.45], [2416.5, 1.935], [2793.5, 0.0]], "action": "update"}}
1626993925.030855: {"channel": "orderbook", "market": "CHZ/USDT", "type": "update", "data": {"time": 1626993924.9980338, "checksum": 1381092805, "bids": [], "asks": [], "action": "update"}}
1626993925.0524402: {"channel": "orderbook", "market": "FLOW-PERP", "type": "update", "data": {"time": 1626993925.0132823, "checksum": 3939980155, "bids": [[16.415, 0.0], [14.39, 0.2]], "asks": [], "action": "update"}}
1626993925.068201: {"channel": "orderbook", "market": "MKR-PERP", "type": "update", "data": {"time": 1626993925.0475733, "checksum": 3338054928, "bids": [], "asks": [[2415.5, 0.468], [2786.0, 0.0]], "action": "update"}}
1626993925.152046: {"channel": "orderbook", "market": "MKR-PERP", "type": "update", "data": {"time": 1626993925.1152492, "checksum": 2936286183, "bids": [[2414.0, 0.0], [2413.5, 1.0], [2412.5, 0.358], [2097.0, 0.04]], "asks": [], "action": "update"}}
1626993925.1702342: {"channel": "orderbook", "market": "CHZ/USDT", "type": "update", "data": {"time": 1626993925.1437755, "checksum": 4044402277, "bids": [[0.227951, 0.0]], "asks": [], "action": "update"}}
1626993925.175015: {"channel": "orderbook", "market": "FLOW-PERP", "type": "update", "data": {"time": 1626993925.1294944, "checksum": 2350656654, "bids": [[16.42, 0.0], [16.4, 0.0], [14.38, 0.32], [14.335, 0.42]], "asks": [[16.46, 24.6], [18.78, 0.0]], "action": "update"}}
1626993925.224187: {"channel": "orderbook", "market": "MKR-PERP", "type": "update", "data": {"time": 1626993925.1743221, "checksum": 3399990277, "bids": [[2412.5, 2.404]], "asks": [[2414.5, 0.275], [2416.0, 1.102], [2416.5, 1.271], [2420.0, 4.996], [2778.5, 0.0]], "action": "update"}}
1626993925.269411: {"channel": "orderbook", "market": "BTC-1231", "type": "update", "data": {"time": 1626993925.2078187, "checksum": 4277265546, "bids": [[32818.0, 0.0376], [32814.0, 0.0], [32812.0, 0.0], [32809.0, 0.0], [32808.0, 0.0], [32807.0, 0.0], [32803.0, 0.0274], [32800.0, 0.0], [32797.0, 0.05], [32793.0, 0.0], [32786.0, 0.0], [32780.0, 0.0], [32777.0, 0.005], [32750.0, 0.0], [32712.0, 0.2292], [32237.0, 0.1526], [32222.0, 0.0002], [32212.0, 0.0005], [32202.0, 0.0004], [32200.0, 0.025], [32184.0, 0.1631], [32181.0, 0.0001], [32154.0, 0.6386]], "asks": [[32828.0, 0.0], [32830.0, 0.595], [32834.0, 0.0], [32835.0, 12.1167], [32838.0, 5.9785], [32839.0, 0.0024], [32840.0, 0.0], [32853.0, 1.13], [32861.0, 0.0], [33434.0, 0.0004]], "action": "update"}}
1626993925.294662: {"channel": "orderbook", "market": "MKR-PERP", "type": "update", "data": {"time": 1626993925.2634127, "checksum": 20981895, "bids": [[2409.5, 2.315]], "asks": [[2417.0, 0.0], [2417.5, 0.086], [2778.5, 0.001]], "action": "update"}}
1626993925.314173: {"channel": "orderbook", "market": "CAD/USD", "type": "update", "data": {"time": 1626993925.287214, "checksum": 706162672, "bids": [], "asks": [], "action": "update"}}
1626993925.338787: {"channel": "orderbook", "market": "CHZ/USDT", "type": "update", "data": {"time": 1626993925.3082273, "checksum": 3550713333, "bids": [[0.227872, 0.0]], "asks": [], "action": "update"}}
1626993925.353749: {"channel": "orderbook", "market": "FLOW-PERP", "type": "update", "data": {"time": 1626993925.3214447, "checksum": 708580978, "bids": [[16.39, 339.34]], "asks": [[16.415, 32.19], [16.425, 305.13], [16.45, 0.0], [16.465, 0.0], [18.78, 200.0]], "action": "update"}}
1626993925.357989: {"channel": "orderbook", "market": "MKR-PERP", "type": "update", "data": {"time": 1626993925.3284407, "checksum": 460397707, "bids": [], "asks": [[2419.0, 5.257]], "action": "update"}}
1626993925.4023528: {"channel": "orderbook", "market": "MKR-PERP", "type": "update", "data": {"time": 1626993925.3636422, "checksum": 1439784655, "bids": [], "asks": [[2416.0, 0.652], [2419.0, 3.211], [2426.0, 0.0], [2786.0, 0.002]], "action": "update"}}
1626993925.410285: {"channel": "orderbook", "market": "FLOW-PERP", "type": "update", "data": {"time": 1626993925.3782377, "checksum": 2263753939, "bids": [], "asks": [[16.49, 70.7], [18.78, 0.0]], "action": "update"}}
1626993925.457865: {"channel": "orderbook", "market": "FLOW-PERP", "type": "update", "data": {"time": 1626993925.4272172, "checksum": 1211720731, "bids": [[16.38, 0.0], [14.31, 69.88]], "asks": [], "action": "update"}}
1626993925.4610791: {"channel": "orderbook", "market": "BTC-1231", "type": "update", "data": {"time": 1626993925.4162197, "checksum": 2885433580, "bids": [[32818.0, 0.0], [32803.0, 0.0], [32781.0, 0.025], [32752.0, 0.0], [32611.0, 0.0], [32153.0, 0.0002], [32151.0, 0.0007], [32141.0, 0.0004]], "asks": [[32818.0, 1.89], [32822.0, 11.2563], [32827.0, 8.5897], [32833.0, 0.0273], [32835.0, 0.0], [32839.0, 0.0], [32896.0, 0.0], [32905.0, 0.2282], [32923.0, 0.0], [32950.0, 0.01]], "action": "update"}}
1626993925.487328: {"channel": "orderbook", "market": "MKR-PERP", "type": "update", "data": {"time": 1626993925.4613433, "checksum": 3418815307, "bids": [[2409.5, 0.37], [2385.5, 4.192]], "asks": [[2414.5, 0.664], [2418.0, 2.516], [2445.5, 4.089]], "action": "update"}}
1626993925.489793: {"channel": "orderbook", "market": "KNCBULL/USDT", "type": "update", "data": {"time": 1626993925.4678154, "checksum": 4188723151, "bids": [], "asks": [], "action": "update"}}
1626993925.514418: {"channel": "orderbook", "market": "MKR-PERP", "type": "update", "data": {"time": 1626993925.490142, "checksum": 2121917237, "bids": [[2410.5, 0.0], [2405.0, 0.0], [2092.5, 0.001], [2091.5, 0.001]], "asks": [[2444.5, 0.0], [2793.5, 0.04]], "action": "update"}}
1626993925.518686: {"channel": "orderbook", "market": "FLOW-PERP", "type": "update", "data": {"time": 1626993925.483327, "checksum": 47920551, "bids": [[16.395, 630.91]], "asks": [[16.46, 0.0], [18.78, 200.0]], "action": "update"}}
1626993925.523721: {"channel": "orderbook", "market": "BNBBEAR/USDT", "type": "update", "data": {"time": 1626993925.4967768, "checksum": 884149509, "bids": [], "asks": [], "action": "update"}}
1626993925.5484102: {"channel": "orderbook", "market": "FLOW-PERP", "type": "update", "data": {"time": 1626993925.5142622, "checksum": 2840216094, "bids": [[16.395, 610.0], [16.155, 371.59]], "asks": [[16.69, 359.54]], "action": "update"}}
1626993925.586505: {"channel": "orderbook", "market": "FLOW-PERP", "type": "update", "data": {"time": 1626993925.5495794, "checksum": 2592544539, "bids": [], "asks": [[16.44, 144.28]], "action": "update"}}
1626993925.6084638: {"channel": "orderbook", "market": "BTC-1231", "type": "update", "data": {"time": 1626993925.5670896, "checksum": 4168225107, "bids": [[32804.0, 0.01], [32803.0, 0.0014], [32799.0, 0.0], [32797.0, 0.0], [32791.0, 0.0], [32781.0, 0.0], [32777.0, 0.0], [32769.0, 0.0904], [32764.0, 1.13], [32753.0, 1.214], [32689.0, 8.4027], [32611.0, 0.6151], [32467.0, 0.0], [32141.0, 0.0]], "asks": [[32816.0, 0.212], [32818.0, 0.0], [32819.0, 0.0004], [32821.0, 0.05], [32823.0, 0.0325], [32827.0, 0.0], [32828.0, 0.0323], [32853.0, 0.0], [32860.0, 0.0], [32898.0, 0.0], [33256.0, 0.0], [33438.0, 0.0002]], "action": "update"}}
1626993925.6566038: {"channel": "orderbook", "market": "CHZ/USDT", "type": "update", "data": {"time": 1626993925.634577, "checksum": 3210230730, "bids": [[0.22786, 0.0]], "asks": [], "action": "update"}}
1626993925.6660092: {"channel": "orderbook", "market": "BTC-1231", "type": "update", "data": {"time": 1626993925.626037, "checksum": 3642456214, "bids": [[32804.0, 0.0], [32803.0, 0.0], [32141.0, 0.0004], [32132.0, 0.1736]], "asks": [[32819.0, 0.0], [32834.0, 0.0153], [32847.0, 0.0], [32883.0, 0.6151], [32895.0, 0.2292], [33002.0, 0.0012], [33438.0, 0.0]], "action": "update"}}
1626993925.671381: {"channel": "orderbook", "market": "MKR-PERP", "type": "update", "data": {"time": 1626993925.6393363, "checksum": 4111311903, "bids": [[2411.0, 0.52], [2408.0, 0.1]], "asks": [[2443.5, 58.0], [2793.5, 0.0]], "action": "update"}}
1626993925.7106292: {"channel": "orderbook", "market": "MKR-PERP", "type": "update", "data": {"time": 1626993925.6790335, "checksum": 3623872248, "bids": [[2409.0, 4.995]], "asks": [], "action": "update"}}
1626993925.7224162: {"channel": "orderbook", "market": "BTC-1231", "type": "update", "data": {"time": 1626993925.6924987, "checksum": 216130819, "bids": [[32768.0, 0.0], [32611.0, 0.0], [32583.0, 0.6151], [32130.0, 0.5664]], "asks": [[32841.0, 0.0], [32854.0, 0.0], [33438.0, 0.0002], [33442.0, 0.025]], "action": "update"}}
1626993925.7349749: {"channel": "orderbook", "market": "BB-0924", "type": "update", "data": {"time": 1626993925.7118604, "checksum": 1359273830, "bids": [], "asks": [], "action": "update"}}
1626993925.7676558: {"channel": "orderbook", "market": "BTC-1231", "type": "update", "data": {"time": 1626993925.741484, "checksum": 1182126018, "bids": [[32795.0, 0.0322], [32785.0, 0.6098], [32769.0, 0.0]], "asks": [[32812.0, 0.0002], [32814.0, 0.25], [32816.0, 0.0], [32832.0, 0.5945], [32888.0, 1.2679], [32890.0, 0.0051], [33243.0, 0.5], [33438.0, 0.0], [33442.0, 0.0]], "action": "update"}}
1626993925.774085: {"channel": "orderbook", "market": "FLOW-PERP", "type": "update", "data": {"time": 1626993925.7462869, "checksum": 1882750306, "bids": [[16.155, 0.23]], "asks": [[16.69, 0.0], [18.785, 0.2]], "action": "update"}}
1626993925.781106: {"channel": "orderbook", "market": "MKR-PERP", "type": "update", "data": {"time": 1626993925.7577467, "checksum": 2618460787, "bids": [[2385.5, 0.0], [2086.0, 0.001]], "asks": [[2445.5, 0.0], [2793.5, 0.04]], "action": "update"}}
1626993925.807445: {"channel": "orderbook", "market": "BTC-1231", "type": "update", "data": {"time": 1626993925.7667499, "checksum": 962520516, "bids": [[32802.0, 0.251], [32786.0, 0.01], [32130.0, 0.0]], "asks": [], "action": "update"}}
1626993925.814218: {"channel": "orderbook", "market": "FLOW-PERP", "type": "update", "data": {"time": 1626993925.7850266, "checksum": 3062447026, "bids": [], "asks": [[17.15, 0.0], [18.9, 1500.0]], "action": "update"}}
1626993925.828178: {"channel": "orderbook", "market": "MKR-PERP", "type": "update", "data": {"time": 1626993925.7979558, "checksum": 3562371271, "bids": [], "asks": [[2417.0, 0.207], [2793.5, 0.0]], "action": "update"}}
1626993925.84623: {"channel": "orderbook", "market": "BTC-1231", "type": "update", "data": {"time": 1626993925.8132038, "checksum": 3255259456, "bids": [], "asks": [[32814.0, 0.0], [33438.0, 0.0002]], "action": "update"}}
1626993925.892159: {"channel": "orderbook", "market": "BTC-1231", "type": "update", "data": {"time": 1626993925.8639703, "checksum": 2063278987, "bids": [[32803.0, 0.25], [32802.0, 0.001], [32795.0, 0.6267], [32772.0, 0.025], [32733.0, 0.1], [32730.0, 0.005], [32153.0, 0.0], [32151.0, 0.0], [32141.0, 0.0], [32132.0, 0.0]], "asks": [[32832.0, 0.6195], [32890.0, 0.0001], [32917.0, 0.1], [33438.0, 0.0]], "action": "update"}}
1626993925.903302: {"channel": "orderbook", "market": "APHA/USD", "type": "update", "data": {"time": 1626993925.8797157, "checksum": 756393738, "bids": [], "asks": [], "action": "update"}}
1626993925.926804: {"channel": "orderbook", "market": "MKR-PERP", "type": "update", "data": {"time": 1626993925.898126, "checksum": 1161324505, "bids": [], "asks": [[2414.5, 0.275]], "action": "update"}}
1626993925.937272: {"channel": "orderbook", "market": "BTC-1231", "type": "update", "data": {"time": 1626993925.9138024, "checksum": 3929076258, "bids": [[32803.0, 0.0], [32153.0, 0.0002]], "asks": [[32813.0, 0.0155], [32847.0, 0.0969], [33424.0, 0.0], [33434.0, 0.0]], "action": "update"}}
1626993926.0083451: {"channel": "orderbook", "market": "BTC-1231", "type": "update", "data": {"time": 1626993925.9814951, "checksum": 913016395, "bids": [[32804.0, 0.25], [32153.0, 0.0]], "asks": [], "action": "update"}}
1626993926.033313: {"channel": "orderbook", "market": "BTC-1231", "type": "update", "data": {"time": 1626993926.0051672, "checksum": 1061407542, "bids": [[32786.0, 0.0], [32153.0, 0.0002]], "asks": [], "action": "update"}}
1626993926.035767: {"channel": "orderbook", "market": "PFE/USD", "type": "update", "data": {"time": 1626993926.01527, "checksum": 825829276, "bids": [], "asks": [], "action": "update"}}
1626993926.059019: {"channel": "orderbook", "market": "FLOW-PERP", "type": "update", "data": {"time": 1626993926.0332243, "checksum": 3062447026, "bids": [], "asks": [], "action": "update"}}
1626993926.059113: {"channel": "orderbook", "market": "CHZ/USDT", "type": "update", "data": {"time": 1626993926.0347133, "checksum": 3210230730, "bids": [], "asks": [], "action": "update"}}
1626993926.0870578: {"channel": "orderbook", "market": "BTC-1231", "type": "update", "data": {"time": 1626993926.0504997, "checksum": 1797530590, "bids": [[32753.0, 0.0], [32723.0, 0.01]], "asks": [[32813.0, 0.0], [32821.0, 0.0], [32876.0, 0.2332], [32888.0, 0.02], [33424.0, 0.0005], [33434.0, 0.0004]], "action": "update"}}
1626993926.1215942: {"channel": "orderbook", "market": "BTC-1231", "type": "update", "data": {"time": 1626993926.0961475, "checksum": 1988683506, "bids": [[32805.0, 0.25], [32782.0, 9.1], [32153.0, 0.0]], "asks": [[32825.0, 12.1633], [32839.0, 1.13], [33424.0, 0.0], [33434.0, 0.0]], "action": "update"}}
1626993926.128078: {"channel": "orderbook", "market": "MKR-PERP", "type": "update", "data": {"time": 1626993926.0965185, "checksum": 933564442, "bids": [], "asks": [[2443.5, 0.0], [2793.5, 0.04]], "action": "update"}}
1626993926.163229: {"channel": "orderbook", "market": "MKR-PERP", "type": "update", "data": {"time": 1626993926.1433687, "checksum": 2358496894, "bids": [], "asks": [[2415.0, 0.389], [2793.5, 0.0]], "action": "update"}}
1626993926.199011: {"channel": "orderbook", "market": "BTC-1231", "type": "update", "data": {"time": 1626993926.1548653, "checksum": 2868210553, "bids": [[32786.0, 0.01], [32154.0, 0.0]], "asks": [[32816.0, 0.05], [32822.0, 0.0]], "action": "update"}}
1626993926.199199: {"channel": "orderbook", "market": "FLOW-PERP", "type": "update", "data": {"time": 1626993926.1667056, "checksum": 1251937913, "bids": [[16.375, 108.41]], "asks": [], "action": "update"}}
1626993926.246021: {"channel": "orderbook", "market": "MKR-PERP", "type": "update", "data": {"time": 1626993926.2220368, "checksum": 348479242, "bids": [[2413.0, 0.67], [2384.5, 8.388], [2086.0, 0.0]], "asks": [[2443.5, 58.0], [2786.0, 0.0]], "action": "update"}}
1626993926.25282: {"channel": "orderbook", "market": "BTC-1231", "type": "update", "data": {"time": 1626993926.2100902, "checksum": 2273096867, "bids": [[32806.0, 0.25], [32804.0, 0.0], [32786.0, 0.0], [32712.0, 0.0], [32706.0, 0.0], [32154.0, 0.6386], [32153.0, 0.0002], [32151.0, 0.0007]], "asks": [[32877.0, 0.0], [33424.0, 0.0005]], "action": "update"}}
1626993926.3026738: {"channel": "orderbook", "market": "BTC-1231", "type": "update", "data": {"time": 1626993926.2743173, "checksum": 841365973, "bids": [[32806.0, 0.0], [32805.0, 0.0], [32753.0, 1.2273], [32454.0, 0.501], [32141.0, 0.0004]], "asks": [[32885.0, 1.22], [33424.0, 0.0]], "action": "update"}}
1626993926.343524: {"channel": "orderbook", "market": "BTC-1231", "type": "update", "data": {"time": 1626993926.3200858, "checksum": 1664049677, "bids": [[32793.0, 8.878], [32141.0, 0.0]], "asks": [[32832.0, 0.5945], [32917.0, 0.0], [33424.0, 0.0005]], "action": "update"}}
1626993926.365788: {"channel": "orderbook", "market": "CAD/USD", "type": "update", "data": {"time": 1626993926.3305748, "checksum": 706162672, "bids": [], "asks": [], "action": "update"}}
1626993926.386118: {"channel": "orderbook", "market": "BTC-1231", "type": "update", "data": {"time": 1626993926.3552113, "checksum": 1582772710, "bids": [[32796.0, 0.01], [32151.0, 0.0]], "asks": [], "action": "update"}}
1626993926.462892: {"channel": "orderbook", "market": "BTC-1231", "type": "update", "data": {"time": 1626993926.4265473, "checksum": 1767581750, "bids": [[32755.0, 0.005], [32695.0, 0.006], [32685.0, 0.0]], "asks": [], "action": "update"}}
1626993926.554982: {"channel": "orderbook", "market": "KNCBULL/USDT", "type": "update", "data": {"time": 1626993926.4962194, "checksum": 4188723151, "bids": [], "asks": [], "action": "update"}}
1626993926.555043: {"channel": "orderbook", "market": "BTC-1231", "type": "update", "data": {"time": 1626993926.5069337, "checksum": 714614960, "bids": [], "asks": [[32904.0, 0.1], [33424.0, 0.0]], "action": "update"}}
1626993926.555131: {"channel": "orderbook", "market": "MKR-PERP", "type": "update", "data": {"time": 1626993926.5109618, "checksum": 1967763976, "bids": [], "asks": [[2424.5, 6.735]], "action": "update"}}
1626993926.5551832: {"channel": "orderbook", "market": "BNBBEAR/USDT", "type": "update", "data": {"time": 1626993926.5207322, "checksum": 884149509, "bids": [], "asks": [], "action": "update"}}
1626993926.608169: {"channel": "orderbook", "market": "BTC-1231", "type": "update", "data": {"time": 1626993926.5852609, "checksum": 3176855263, "bids": [], "asks": [[32872.0, 0.01], [33414.0, 0.0]], "action": "update"}}
1626993926.64286: {"channel": "orderbook", "market": "FLOW-PERP", "type": "update", "data": {"time": 1626993926.6156735, "checksum": 4208066940, "bids": [[16.145, 371.59], [14.31, 0.0]], "asks": [], "action": "update"}}
1626993926.699914: {"channel": "orderbook", "market": "MKR-PERP", "type": "update", "data": {"time": 1626993926.622566, "checksum": 2735910228, "bids": [], "asks": [[2415.0, 0.0], [2416.0, 0.0], [2443.5, 0.0], [2786.0, 0.002], [2793.5, 0.04], [2795.5, 0.024]], "action": "update"}}
1626993926.70012: {"channel": "orderbook", "market": "BTC-1231", "type": "update", "data": {"time": 1626993926.6526358, "checksum": 1228375114, "bids": [[32723.0, 0.0], [32151.0, 0.0007]], "asks": [], "action": "update"}}
1626993926.709344: {"channel": "orderbook", "market": "MKR-PERP", "type": "update", "data": {"time": 1626993926.6862438, "checksum": 2133493270, "bids": [[2413.5, 1.694]], "asks": [], "action": "update"}}
1626993926.7409868: {"channel": "orderbook", "market": "MKR-PERP", "type": "update", "data": {"time": 1626993926.7131994, "checksum": 4160320092, "bids": [[2413.0, 0.185]], "asks": [[2416.0, 0.724], [2795.5, 0.0]], "action": "update"}}
1626993926.769281: {"channel": "orderbook", "market": "MKR-PERP", "type": "update", "data": {"time": 1626993926.7418618, "checksum": 504233766, "bids": [[2409.5, 1.689]], "asks": [[2444.5, 58.0], [2793.5, 0.0]], "action": "update"}}
1626993926.7748082: {"channel": "orderbook", "market": "BB-0924", "type": "update", "data": {"time": 1626993926.7504933, "checksum": 1359273830, "bids": [], "asks": [], "action": "update"}}
1626993926.841801: {"channel": "orderbook", "market": "BTC-1231", "type": "update", "data": {"time": 1626993926.8191817, "checksum": 199052267, "bids": [], "asks": [[32812.0, 0.0], [33414.0, 0.0002]], "action": "update"}}
1626993926.904598: {"channel": "orderbook", "market": "BTC-1231", "type": "update", "data": {"time": 1626993926.884001, "checksum": 3726739841, "bids": [], "asks": [[32848.0, 0.0004]], "action": "update"}}
1626993926.906781: {"channel": "orderbook", "market": "MKR-PERP", "type": "update", "data": {"time": 1626993926.8763523, "checksum": 2922067520, "bids": [[2412.5, 2.641]], "asks": [], "action": "update"}}
1626993926.9261398: {"channel": "orderbook", "market": "APHA/USD", "type": "update", "data": {"time": 1626993926.9038491, "checksum": 756393738, "bids": [], "asks": [], "action": "update"}}
1626993926.9377139: {"channel": "orderbook", "market": "MKR-PERP", "type": "update", "data": {"time": 1626993926.9112308, "checksum": 2218815689, "bids": [], "asks": [[2414.5, 0.0], [2416.0, 0.999], [2793.5, 0.04]], "action": "update"}}
1626993926.951745: {"channel": "orderbook", "market": "BTC-1231", "type": "update", "data": {"time": 1626993926.925128, "checksum": 1970930498, "bids": [[32796.0, 0.6045], [32786.0, 0.0922], [32151.0, 0.0]], "asks": [[32815.0, 0.0002], [32840.0, 0.025], [33413.0, 0.0], [33414.0, 0.0]], "action": "update"}}
1626993926.977199: {"channel": "orderbook", "market": "BTC-1231", "type": "update", "data": {"time": 1626993926.9501226, "checksum": 2544406088, "bids": [], "asks": [[32866.0, 0.3423]], "action": "update"}}
1626993927.028451: {"channel": "orderbook", "market": "MKR-PERP", "type": "update", "data": {"time": 1626993927.0008547, "checksum": 2995726915, "bids": [[2410.0, 5.21]], "asks": [], "action": "update"}}
1626993927.067847: {"channel": "orderbook", "market": "PFE/USD", "type": "update", "data": {"time": 1626993927.0458753, "checksum": 825829276, "bids": [], "asks": [], "action": "update"}}
1626993927.095158: {"channel": "orderbook", "market": "CHZ/USDT", "type": "update", "data": {"time": 1626993927.0685873, "checksum": 3210230730, "bids": [], "asks": [], "action": "update"}}
1626993927.0952508: {"channel": "orderbook", "market": "BTC-1231", "type": "update", "data": {"time": 1626993927.0717173, "checksum": 3235880305, "bids": [[32803.0, 0.25], [32153.0, 0.0]], "asks": [], "action": "update"}}
1626993927.1100428: {"channel": "orderbook", "market": "FLOW-PERP", "type": "update", "data": {"time": 1626993927.084301, "checksum": 4208066940, "bids": [], "asks": [], "action": "update"}}
1626993927.159821: {"channel": "orderbook", "market": "MKR-PERP", "type": "update", "data": {"time": 1626993927.1306586, "checksum": 1670632034, "bids": [], "asks": [[2417.0, 0.0], [2795.5, 0.024]], "action": "update"}}
1626993927.183444: {"channel": "orderbook", "market": "BTC-1231", "type": "update", "data": {"time": 1626993927.155094, "checksum": 4207661333, "bids": [[32804.0, 0.25], [32796.0, 0.5945], [32793.0, 8.89], [32787.0, 0.657], [32782.0, 9.05], [32181.0, 0.0], [32154.0, 0.0]], "asks": [[32816.0, 0.0], [33413.0, 0.0001]], "action": "update"}}
1626993927.212244: {"channel": "orderbook", "market": "MKR-PERP", "type": "update", "data": {"time": 1626993927.1826842, "checksum": 3106257452, "bids": [], "asks": [[2415.0, 0.389], [2795.5, 0.0]], "action": "update"}}
1626993927.269024: {"channel": "orderbook", "market": "BTC-1231", "type": "update", "data": {"time": 1626993927.2264342, "checksum": 785045671, "bids": [[32803.0, 0.0], [32786.0, 0.1422], [32754.0, 0.0913]], "asks": [[32824.0, 0.0024], [32828.0, 9.9067], [32829.0, 0.0933], [33400.0, 0.0], [33413.0, 0.0]], "action": "update"}}
1626993927.281448: {"channel": "orderbook", "market": "CHZ/USDT", "type": "update", "data": {"time": 1626993927.2590382, "checksum": 633020125, "bids": [[0.227844, 0.0]], "asks": [], "action": "update"}}
1626993927.305297: {"channel": "orderbook", "market": "CHZ/USDT", "type": "update", "data": {"time": 1626993927.281418, "checksum": 1932124870, "bids": [[0.227805, 0.0]], "asks": [], "action": "update"}}
1626993927.3054311: {"channel": "orderbook", "market": "MKR-PERP", "type": "update", "data": {"time": 1626993927.2800417, "checksum": 1670632034, "bids": [], "asks": [[2415.0, 0.0], [2795.5, 0.024]], "action": "update"}}
1626993927.3252008: {"channel": "orderbook", "market": "BTC-1231", "type": "update", "data": {"time": 1626993927.273771, "checksum": 1350347291, "bids": [[32806.0, 0.25], [32768.0, 0.0903], [32753.0, 0.0], [32184.0, 0.0]], "asks": [[32815.0, 0.0], [32820.0, 0.05], [32825.0, 0.0], [32885.0, 0.0], [33400.0, 0.095], [33413.0, 0.0001]], "action": "update"}}
1626993927.358424: {"channel": "orderbook", "market": "CHZ/USDT", "type": "update", "data": {"time": 1626993927.337191, "checksum": 2306405362, "bids": [], "asks": [[0.22853, 2460.0], [0.533, 0.0]], "action": "update"}}
1626993927.3925068: {"channel": "orderbook", "market": "BTC-1231", "type": "update", "data": {"time": 1626993927.3554757, "checksum": 3382257899, "bids": [[32805.0, 0.01], [32804.0, 0.0], [32797.0, 12.2013], [32793.0, 0.012], [32200.0, 0.0]], "asks": [], "action": "update"}}
1626993927.4099011: {"channel": "orderbook", "market": "MKR-PERP", "type": "update", "data": {"time": 1626993927.386241, "checksum": 416827537, "bids": [[2413.0, 0.775], [2409.0, 6.941]], "asks": [], "action": "update"}}
1626993927.421619: {"channel": "orderbook", "market": "BTC-1231", "type": "update", "data": {"time": 1626993927.389123, "checksum": 4186577687, "bids": [[32805.0, 0.0], [32200.0, 0.025]], "asks": [[32840.0, 0.0], [33414.0, 0.0002]], "action": "update"}}
1626993927.429292: {"channel": "orderbook", "market": "CHZ/USDT", "type": "update", "data": {"time": 1626993927.4031537, "checksum": 2056261579, "bids": [[0.227861, 9160.0]], "asks": [], "action": "update"}}
1626993927.43297: {"channel": "orderbook", "market": "CAD/USD", "type": "update", "data": {"time": 1626993927.4038036, "checksum": 706162672, "bids": [], "asks": [], "action": "update"}}
1626993927.439462: {"channel": "orderbook", "market": "FLOW-PERP", "type": "update", "data": {"time": 1626993927.410339, "checksum": 2374042466, "bids": [], "asks": [[16.455, 225.0], [18.9, 0.0]], "action": "update"}}
1626993927.460684: {"channel": "orderbook", "market": "CHZ/USDT", "type": "update", "data": {"time": 1626993927.4390185, "checksum": 1610695438, "bids": [], "asks": [[0.228502, 2460.0], [0.22853, 0.0]], "action": "update"}}
1626993927.4759529: {"channel": "orderbook", "market": "BTC-1231", "type": "update", "data": {"time": 1626993927.445159, "checksum": 2934220132, "bids": [[32807.0, 0.25], [32800.0, 0.028], [32202.0, 0.0], [32200.0, 0.0]], "asks": [[32823.0, 0.0], [32824.0, 0.0], [32832.0, 8.4443], [32866.0, 0.3373], [33424.0, 0.0005], [33434.0, 0.0004]], "action": "update"}}
1626993927.4952111: {"channel": "orderbook", "market": "FLOW-PERP", "type": "update", "data": {"time": 1626993927.4725046, "checksum": 1171560551, "bids": [], "asks": [[16.415, 0.0], [18.9, 1500.0]], "action": "update"}}
1626993927.549619: {"channel": "orderbook", "market": "KNCBULL/USDT", "type": "update", "data": {"time": 1626993927.5250397, "checksum": 4188723151, "bids": [], "asks": [], "action": "update"}}
1626993927.579303: {"channel": "orderbook", "market": "BTC-1231", "type": "update", "data": {"time": 1626993927.5331674, "checksum": 2967247534, "bids": [[32807.0, 0.26], [32806.0, 0.0], [32802.0, 7.8968], [32797.0, 0.0], [32793.0, 0.0], [32763.0, 1.2343], [32202.0, 0.0004], [32200.0, 0.025]], "asks": [[32817.0, 0.0002], [32828.0, 0.0323], [32832.0, 0.5945], [32839.0, 0.0], [32899.0, 1.2617], [33434.0, 0.0]], "action": "update"}}
1626993927.584955: {"channel": "orderbook", "market": "BNBBEAR/USDT", "type": "update", "data": {"time": 1626993927.5449731, "checksum": 884149509, "bids": [], "asks": [], "action": "update"}}
1626993927.593683: {"channel": "orderbook", "market": "FLOW-PERP", "type": "update", "data": {"time": 1626993927.5651975, "checksum": 4283067284, "bids": [], "asks": [[16.455, 0.0], [18.925, 0.3]], "action": "update"}}
1626993927.62081: {"channel": "orderbook", "market": "CHZ/USDT", "type": "update", "data": {"time": 1626993927.589634, "checksum": 914383224, "bids": [], "asks": [[0.228502, 0.0], [0.533, 20.0]], "action": "update"}}
1626993927.6286569: {"channel": "orderbook", "market": "BTC-1231", "type": "update", "data": {"time": 1626993927.5905232, "checksum": 3950525194, "bids": [[32807.0, 0.547], [32785.0, 0.0153], [32583.0, 0.0], [32184.0, 0.1631]], "asks": [[32819.0, 0.0155], [32828.0, 0.6268], [32847.0, 0.1219], [33424.0, 0.0]], "action": "update"}}
1626993927.639424: {"channel": "orderbook", "market": "CHZ/USDT", "type": "update", "data": {"time": 1626993927.6181784, "checksum": 750416347, "bids": [], "asks": [[0.228445, 2460.0], [0.533, 0.0]], "action": "update"}}
1626993927.6777759: {"channel": "orderbook", "market": "FLOW-PERP", "type": "update", "data": {"time": 1626993927.6403763, "checksum": 3930515911, "bids": [], "asks": [[16.425, 0.0], [18.935, 0.1]], "action": "update"}}
1626993927.677941: {"channel": "orderbook", "market": "BTC-1231", "type": "update", "data": {"time": 1626993927.6387403, "checksum": 472426576, "bids": [[32802.0, 8.4913], [32601.0, 0.6151], [32184.0, 0.0]], "asks": [[32904.0, 0.0], [33424.0, 0.0005]], "action": "update"}}
1626993927.7157838: {"channel": "orderbook", "market": "CHZ/USDT", "type": "update", "data": {"time": 1626993927.6898427, "checksum": 3208625872, "bids": [], "asks": [[0.228445, 0.0], [0.229139, 0.0], [0.23521, 0.0], [0.533, 20.0], [0.5421, 270.0], [0.55, 610.0]], "action": "update"}}
1626993927.716022: {"channel": "orderbook", "market": "FLOW-PERP", "type": "update", "data": {"time": 1626993927.6943285, "checksum": 1744178340, "bids": [[16.39, 0.0], [14.31, 69.88]], "asks": [], "action": "update"}}
1626993927.72803: {"channel": "orderbook", "market": "BTC-1231", "type": "update", "data": {"time": 1626993927.6889465, "checksum": 1854616477, "bids": [[32810.0, 0.25], [32786.0, 0.0922], [32200.0, 0.0]], "asks": [[32819.0, 0.0], [33434.0, 0.0004]], "action": "update"}}
1626993927.7379682: {"channel": "orderbook", "market": "MKR-PERP", "type": "update", "data": {"time": 1626993927.6946926, "checksum": 708552623, "bids": [[2413.0, 1.012], [2412.5, 2.404]], "asks": [[2418.0, 2.046], [2418.5, 1.518]], "action": "update"}}
1626993927.768647: {"channel": "orderbook", "market": "BTC-1231", "type": "update", "data": {"time": 1626993927.7340772, "checksum": 3727831987, "bids": [[32730.0, 0.0], [32200.0, 0.025]], "asks": [[32817.0, 0.0], [33438.0, 0.0002]], "action": "update"}}
1626993927.77731: {"channel": "orderbook", "market": "MKR-PERP", "type": "update", "data": {"time": 1626993927.7449753, "checksum": 2978021224, "bids": [], "asks": [[2415.5, 0.0], [2416.0, 1.419], [2800.0, 0.035]], "action": "update"}}
1626993927.786004: {"channel": "orderbook", "market": "FLOW-PERP", "type": "update", "data": {"time": 1626993927.7573192, "checksum": 2031345317, "bids": [[16.41, 435.61], [16.365, 0.0], [14.3, 0.32]], "asks": [[16.44, 69.0]], "action": "update"}}
1626993927.8133602: {"channel": "orderbook", "market": "MKR-PERP", "type": "update", "data": {"time": 1626993927.7928214, "checksum": 3443595368, "bids": [], "asks": [[2415.5, 0.389], [2800.0, 0.0]], "action": "update"}}
1626993927.831053: {"channel": "orderbook", "market": "BB-0924", "type": "update", "data": {"time": 1626993927.7922904, "checksum": 1359273830, "bids": [], "asks": [], "action": "update"}}
1626993927.8311481: {"channel": "orderbook", "market": "CHZ/USDT", "type": "update", "data": {"time": 1626993927.8066957, "checksum": 2813101044, "bids": [], "asks": [[0.229139, 4160.0], [0.55, 0.0]], "action": "update"}}
1626993927.865088: {"channel": "orderbook", "market": "BTC-1231", "type": "update", "data": {"time": 1626993927.823769, "checksum": 1119361438, "bids": [[32812.0, 0.25], [32810.0, 0.0], [32807.0, 0.537], [32804.0, 0.0325], [32200.0, 0.0]], "asks": [[32820.0, 0.0], [32828.0, 0.5945], [32847.0, 1.2519], [32921.0, 0.1]], "action": "update"}}
1626993927.86532: {"channel": "orderbook", "market": "FLOW-PERP", "type": "update", "data": {"time": 1626993927.8351278, "checksum": 3638194475, "bids": [[16.395, 1070.69]], "asks": [[16.435, 410.83], [18.935, 0.0]], "action": "update"}}
1626993927.8694248: {"channel": "orderbook", "market": "MKR-PERP", "type": "update", "data": {"time": 1626993927.8474557, "checksum": 2299301996, "bids": [], "asks": [[2415.5, 0.785]], "action": "update"}}
1626993927.8962429: {"channel": "orderbook", "market": "BTC-1231", "type": "update", "data": {"time": 1626993927.8722832, "checksum": 2123403923, "bids": [[32790.0, 0.05], [32202.0, 0.0]], "asks": [[32819.0, 0.0003], [32825.0, 0.05], [32828.0, 0.0], [32832.0, 0.0]], "action": "update"}}
1626993927.9017549: {"channel": "orderbook", "market": "FLOW-PERP", "type": "update", "data": {"time": 1626993927.878618, "checksum": 1691372913, "bids": [[16.375, 183.0]], "asks": [[16.47, 159.78]], "action": "update"}}
1626993927.938935: {"channel": "orderbook", "market": "BTC-1231", "type": "update", "data": {"time": 1626993927.9062877, "checksum": 2283731348, "bids": [[32812.0, 0.0], [32786.0, 0.0], [32772.0, 0.0], [32202.0, 0.0004], [32200.0, 0.025], [32184.0, 0.1631]], "asks": [[32828.0, 0.25], [32829.0, 0.0], [32855.0, 0.2282]], "action": "update"}}
1626993927.9464698: {"channel": "orderbook", "market": "APHA/USD", "type": "update", "data": {"time": 1626993927.9271712, "checksum": 756393738, "bids": [], "asks": [], "action": "update"}}
1626993927.9718232: {"channel": "orderbook", "market": "MKR-PERP", "type": "update", "data": {"time": 1626993927.946955, "checksum": 2299301996, "bids": [], "asks": [], "action": "update"}}
1626993927.984989: {"channel": "orderbook", "market": "FLOW-PERP", "type": "update", "data": {"time": 1626993927.9595864, "checksum": 680906888, "bids": [], "asks": [[16.49, 284.7]], "action": "update"}}
1626993927.994791: {"channel": "orderbook", "market": "BTC-1231", "type": "update", "data": {"time": 1626993927.964985, "checksum": 642282745, "bids": [[32814.0, 0.25], [32813.0, 0.01], [32200.0, 0.0], [32184.0, 0.0]], "asks": [[32829.0, 0.5945], [33438.0, 0.0]], "action": "update"}}
1626993928.022254: {"channel": "orderbook", "market": "MKR-PERP", "type": "update", "data": {"time": 1626993927.9960551, "checksum": 2539136532, "bids": [], "asks": [[2416.5, 1.478]], "action": "update"}}
1626993928.030606: {"channel": "orderbook", "market": "BTC-1231", "type": "update", "data": {"time": 1626993928.0056815, "checksum": 1562053324, "bids": [], "asks": [[32825.0, 0.6445], [32847.0, 1.2269]], "action": "update"}}
1626993928.064393: {"channel": "orderbook", "market": "BTC-1231", "type": "update", "data": {"time": 1626993928.0346448, "checksum": 1956073866, "bids": [[32813.0, 0.0], [32689.0, 8.6321], [32200.0, 0.025]], "asks": [[32846.0, 0.0945], [33434.0, 0.0]], "action": "update"}}
1626993928.1038568: {"channel": "orderbook", "market": "CHZ/USDT", "type": "update", "data": {"time": 1626993928.0727298, "checksum": 1526312895, "bids": [], "asks": [[0.231383, 3840.0], [0.5421, 0.0]], "action": "update"}}
1626993928.1070132: {"channel": "orderbook", "market": "BTC-1231", "type": "update", "data": {"time": 1626993928.0758083, "checksum": 2908176946, "bids": [[32816.0, 0.25], [32797.0, 0.0933], [32792.0, 0.025], [32790.0, 0.0], [32754.0, 0.0], [32200.0, 0.0]], "asks": [[32825.0, 0.0], [33434.0, 0.0004]], "action": "update"}}
1626993928.11248: {"channel": "orderbook", "market": "PFE/USD", "type": "update", "data": {"time": 1626993928.0907407, "checksum": 825829276, "bids": [], "asks": [], "action": "update"}}
1626993928.1519501: {"channel": "orderbook", "market": "BTC-1231", "type": "update", "data": {"time": 1626993928.113975, "checksum": 1747086059, "bids": [], "asks": [[32819.0, 0.0], [32851.0, 0.025]], "action": "update"}}
1626993928.16804: {"channel": "orderbook", "market": "FLOW-PERP", "type": "update", "data": {"time": 1626993928.1289034, "checksum": 680906888, "bids": [], "asks": [], "action": "update"}}
1626993928.205704: {"channel": "orderbook", "market": "MKR-PERP", "type": "update", "data": {"time": 1626993928.1629071, "checksum": 1284040020, "bids": [[2413.0, 0.775]], "asks": [[2416.0, 0.695]], "action": "update"}}
1626993928.2057989: {"channel": "orderbook", "market": "BTC-1231", "type": "update", "data": {"time": 1626993928.1705585, "checksum": 2393058650, "bids": [[32817.0, 0.25], [32815.0, 0.01], [32814.0, 0.0], [32794.0, 0.05], [32733.0, 0.0], [32202.0, 0.0]], "asks": [], "action": "update"}}
1626993928.2374458: {"channel": "orderbook", "market": "MKR-PERP", "type": "update", "data": {"time": 1626993928.2111201, "checksum": 2864404374, "bids": [], "asks": [[2416.0, 0.42], [2420.0, 3.211]], "action": "update"}}
1626993928.249951: {"channel": "orderbook", "market": "BTC-1231", "type": "update", "data": {"time": 1626993928.2201934, "checksum": 2906896714, "bids": [[32817.0, 0.0], [32816.0, 0.0], [32806.0, 9.7558], [32454.0, 0.001], [32202.0, 0.0004]], "asks": [[32827.0, 0.2655], [32828.0, 0.5945], [33434.0, 0.0]], "action": "update"}}
1626993928.25992: {"channel": "orderbook", "market": "MKR-PERP", "type": "update", "data": {"time": 1626993928.237728, "checksum": 2477242131, "bids": [], "asks": [[2416.5, 2.177]], "action": "update"}}
1626993928.303584: {"channel": "orderbook", "market": "BTC-1231", "type": "update", "data": {"time": 1626993928.2710001, "checksum": 1924913271, "bids": [[32815.0, 0.0], [32802.0, 0.5955], [32765.0, 0.0899]], "asks": [[32822.0, 0.0003], [32830.0, 0.0005], [33424.0, 0.0]], "action": "update"}}
1626993928.344516: {"channel": "orderbook", "market": "CHZ/USDT", "type": "update", "data": {"time": 1626993928.3234806, "checksum": 309945381, "bids": [[0.227893, 9150.0]], "asks": [], "action": "update"}}
1626993928.347224: {"channel": "orderbook", "market": "BTC-1231", "type": "update", "data": {"time": 1626993928.3246372, "checksum": 2422215635, "bids": [[32815.0, 0.25], [32737.0, 0.1], [32463.0, 0.5], [32222.0, 0.0], [32212.0, 0.0], [32202.0, 0.0]], "asks": [[32827.0, 0.61]], "action": "update"}}
1626993928.3840818: {"channel": "orderbook", "market": "BTC-1231", "type": "update", "data": {"time": 1626993928.352868, "checksum": 636518443, "bids": [[32743.0, 0.005], [32237.0, 0.0]], "asks": [], "action": "update"}}
1626993928.40196: {"channel": "orderbook", "market": "MKR-PERP", "type": "update", "data": {"time": 1626993928.3674324, "checksum": 178094919, "bids": [[2404.5, 2.455]], "asks": [], "action": "update"}}
1626993928.4194372: {"channel": "orderbook", "market": "BTC-1231", "type": "update", "data": {"time": 1626993928.3934443, "checksum": 386833458, "bids": [[32808.0, 0.01], [32242.0, 0.0]], "asks": [[32829.0, 0.6445]], "action": "update"}}
1626993928.4480598: {"channel": "orderbook", "market": "BTC-1231", "type": "update", "data": {"time": 1626993928.4173756, "checksum": 4123290393, "bids": [[32816.0, 0.25], [32247.0, 0.0]], "asks": [[32851.0, 0.0], [33424.0, 0.0005]], "action": "update"}}
1626993928.478071: {"channel": "orderbook", "market": "CAD/USD", "type": "update", "data": {"time": 1626993928.4509077, "checksum": 706162672, "bids": [], "asks": [], "action": "update"}}
1626993928.482163: {"channel": "orderbook", "market": "FLOW-PERP", "type": "update", "data": {"time": 1626993928.4612405, "checksum": 3044566055, "bids": [[16.145, 0.0], [14.29, 0.1]], "asks": [], "action": "update"}}
1626993928.4928389: {"channel": "orderbook", "market": "BTC-1231", "type": "update", "data": {"time": 1626993928.457527, "checksum": 1417377358, "bids": [[32815.0, 0.0], [32808.0, 0.0], [32247.0, 0.0002], [32242.0, 0.0004]], "asks": [], "action": "update"}}
1626993928.550718: {"channel": "orderbook", "market": "BTC-1231", "type": "update", "data": {"time": 1626993928.523475, "checksum": 3776221070, "bids": [[32801.0, 0.012], [32242.0, 0.0]], "asks": [[32827.0, 0.0155], [32828.0, 0.0], [32838.0, 16.2049], [33434.0, 0.0004]], "action": "update"}}
1626993928.5533462: {"channel": "orderbook", "market": "MKR-PERP", "type": "update", "data": {"time": 1626993928.528444, "checksum": 2179262664, "bids": [], "asks": [[2415.5, 0.396]], "action": "update"}}
1626993928.572843: {"channel": "orderbook", "market": "KNCBULL/USDT", "type": "update", "data": {"time": 1626993928.5470805, "checksum": 4188723151, "bids": [], "asks": [], "action": "update"}}
1626993928.5814242: {"channel": "orderbook", "market": "BTC-1231", "type": "update", "data": {"time": 1626993928.5548818, "checksum": 1825547592, "bids": [[32815.0, 0.0013], [32710.0, 0.8332], [32692.0, 0.2292], [32252.0, 0.0], [32247.0, 0.0]], "asks": [[32822.0, 0.0], [33438.0, 0.0002]], "action": "update"}}
1626993928.59305: {"channel": "orderbook", "market": "BNBBEAR/USDT", "type": "update", "data": {"time": 1626993928.5641553, "checksum": 884149509, "bids": [], "asks": [], "action": "update"}}
1626993928.615005: {"channel": "orderbook", "market": "BTC-1231", "type": "update", "data": {"time": 1626993928.5862477, "checksum": 996836405, "bids": [[32817.0, 0.01], [32710.0, 0.604], [32282.0, 0.0]], "asks": [], "action": "update"}}
1626993928.6474712: {"channel": "orderbook", "market": "BTC-1231", "type": "update", "data": {"time": 1626993928.6199105, "checksum": 493352686, "bids": [[32815.0, 0.0], [32282.0, 0.0002]], "asks": [[32858.0, 0.0252]], "action": "update"}}
1626993928.666417: {"channel": "orderbook", "market": "MKR-PERP", "type": "update", "data": {"time": 1626993928.6403909, "checksum": 2295536957, "bids": [[2414.0, 0.186], [2091.5, 0.0]], "asks": [], "action": "update"}}
1626993928.694228: {"channel": "orderbook", "market": "BTC-1231", "type": "update", "data": {"time": 1626993928.6610909, "checksum": 3447377038, "bids": [[32816.0, 0.0], [32252.0, 0.0004]], "asks": [[32824.0, 0.0003], [32829.0, 0.05], [33438.0, 0.0]], "action": "update"}}
1626993928.737077: {"channel": "orderbook", "market": "BTC-1231", "type": "update", "data": {"time": 1626993928.7128026, "checksum": 203773634, "bids": [], "asks": [[32827.0, 0.2655], [32838.0, 10.2264]], "action": "update"}}
1626993928.7881129: {"channel": "orderbook", "market": "BTC-1231", "type": "update", "data": {"time": 1626993928.7613997, "checksum": 1624677080, "bids": [[32818.0, 0.25], [32817.0, 0.0], [32808.0, 0.0276], [32737.0, 0.0]], "asks": [[32824.0, 0.0], [33243.0, 0.0], [33438.0, 0.0002], [33442.0, 0.025]], "action": "update"}}
1626993928.824191: {"channel": "orderbook", "market": "BTC-1231", "type": "update", "data": {"time": 1626993928.796706, "checksum": 1824683770, "bids": [[32818.0, 0.0], [32247.0, 0.0002]], "asks": [], "action": "update"}}
1626993928.8711061: {"channel": "orderbook", "market": "MKR-PERP", "type": "update", "data": {"time": 1626993928.8496368, "checksum": 2844344311, "bids": [], "asks": [[2415.5, 0.0], [2800.0, 0.035]], "action": "update"}}
1626993928.881564: {"channel": "orderbook", "market": "BB-0924", "type": "update", "data": {"time": 1626993928.8537054, "checksum": 1359273830, "bids": [], "asks": [], "action": "update"}}
1626993928.883735: {"channel": "orderbook", "market": "BTC-1231", "type": "update", "data": {"time": 1626993928.856358, "checksum": 1564948215, "bids": [[32819.0, 0.01], [32247.0, 0.0]], "asks": [[32826.0, 0.0003], [33253.0, 0.5], [33438.0, 0.0], [33442.0, 0.0]], "action": "update"}}
1626993928.898813: {"channel": "orderbook", "market": "BTC-1231", "type": "update", "data": {"time": 1626993928.8781052, "checksum": 2843319949, "bids": [[32812.0, 0.25], [32252.0, 0.0]], "asks": [[32827.0, 0.0155]], "action": "update"}}
1626993928.905484: {"channel": "orderbook", "market": "MKR-PERP", "type": "update", "data": {"time": 1626993928.885555, "checksum": 2866489008, "bids": [[2413.5, 1.931]], "asks": [], "action": "update"}}
1626993928.93394: {"channel": "orderbook", "market": "BTC-1231", "type": "update", "data": {"time": 1626993928.9029555, "checksum": 1710940150, "bids": [[32748.0, 0.1], [32282.0, 0.0]], "asks": [], "action": "update"}}
1626993928.9511738: {"channel": "orderbook", "market": "BTC-1231", "type": "update", "data": {"time": 1626993928.928739, "checksum": 3325788040, "bids": [[32819.0, 0.0], [32282.0, 0.0002]], "asks": [[32826.0, 0.2503]], "action": "update"}}
1626993928.964148: {"channel": "orderbook", "market": "MKR-PERP", "type": "update", "data": {"time": 1626993928.9407775, "checksum": 532707423, "bids": [], "asks": [[2415.5, 0.39], [2417.0, 0.275], [2795.5, 0.0], [2800.0, 0.0]], "action": "update"}}
1626993928.9958029: {"channel": "orderbook", "market": "MKR-PERP", "type": "update", "data": {"time": 1626993928.9632702, "checksum": 4281883196, "bids": [[2414.0, 0.608]], "asks": [], "action": "update"}}
1626993928.9958951: {"channel": "orderbook", "market": "BTC-1231", "type": "update", "data": {"time": 1626993928.9543796, "checksum": 2177758539, "bids": [[32794.0, 0.0], [32764.0, 0.0], [32252.0, 0.0004], [32247.0, 0.0002]], "asks": [[32829.0, 0.0], [32847.0, 0.0969], [33438.0, 0.0002]], "action": "update"}}
1626993928.996039: {"channel": "orderbook", "market": "APHA/USD", "type": "update", "data": {"time": 1626993928.9689507, "checksum": 756393738, "bids": [], "asks": [], "action": "update"}}
1626993929.024374: {"channel": "orderbook", "market": "BTC-1231", "type": "update", "data": {"time": 1626993928.9934475, "checksum": 2266317500, "bids": [[32815.0, 0.25], [32247.0, 0.0]], "asks": [[32826.0, 0.0003]], "action": "update"}}
1626993929.041405: {"channel": "orderbook", "market": "MKR-PERP", "type": "update", "data": {"time": 1626993929.0183537, "checksum": 4153646531, "bids": [[2413.5, 1.237]], "asks": [], "action": "update"}}
1626993929.062058: {"channel": "orderbook", "market": "BTC-1231", "type": "update", "data": {"time": 1626993929.0354688, "checksum": 3955135496, "bids": [[32813.0, 0.01], [32776.0, 1.13], [32282.0, 0.0], [32252.0, 0.0]], "asks": [], "action": "update"}}
1626993929.1016169: {"channel": "orderbook", "market": "BTC-1231", "type": "update", "data": {"time": 1626993929.0755, "checksum": 2245318793, "bids": [[32816.0, 0.25], [32812.0, 0.0]], "asks": [[32856.0, 1.2272]], "action": "update"}}
1626993929.1243799: {"channel": "orderbook", "market": "BTC-1231", "type": "update", "data": {"time": 1626993929.098568, "checksum": 2284425669, "bids": [[32815.0, 0.0], [32813.0, 0.0], [32282.0, 0.0002], [32252.0, 0.0004]], "asks": [], "action": "update"}}
1626993929.1245599: {"channel": "orderbook", "market": "CHZ/USDT", "type": "update", "data": {"time": 1626993929.1036458, "checksum": 309945381, "bids": [], "asks": [], "action": "update"}}
1626993929.1289191: {"channel": "orderbook", "market": "MKR-PERP", "type": "update", "data": {"time": 1626993929.0910149, "checksum": 73968526, "bids": [], "asks": [[2415.5, 0.0], [2416.0, 0.0], [2795.5, 0.024], [2800.0, 0.035]], "action": "update"}}
1626993929.133059: {"channel": "orderbook", "market": "PFE/USD", "type": "update", "data": {"time": 1626993929.1135564, "checksum": 825829276, "bids": [], "asks": [], "action": "update"}}
1626993929.175582: {"channel": "orderbook", "market": "FLOW-PERP", "type": "update", "data": {"time": 1626993929.1477222, "checksum": 3044566055, "bids": [], "asks": [], "action": "update"}}
1626993929.1804001: {"channel": "orderbook", "market": "BTC-1231", "type": "update", "data": {"time": 1626993929.1493368, "checksum": 1955596043, "bids": [[32816.0, 0.0], [32247.0, 0.0002]], "asks": [[32837.0, 0.0344]], "action": "update"}}
1626993929.231256: {"channel": "orderbook", "market": "FLOW-PERP", "type": "update", "data": {"time": 1626993929.1993449, "checksum": 680906888, "bids": [[16.145, 371.59], [14.29, 0.0]], "asks": [], "action": "update"}}
1626993929.251631: {"channel": "orderbook", "market": "BTC-1231", "type": "update", "data": {"time": 1626993929.225169, "checksum": 1111028467, "bids": [[32817.0, 0.01], [32813.0, 0.25], [32252.0, 0.0], [32247.0, 0.0]], "asks": [], "action": "update"}}
1626993929.257932: {"channel": "orderbook", "market": "MKR-PERP", "type": "update", "data": {"time": 1626993929.232201, "checksum": 1270816794, "bids": [], "asks": [[2416.0, 0.42], [2800.0, 0.0]], "action": "update"}}
1626993929.323735: {"channel": "orderbook", "market": "BTC-1231", "type": "update", "data": {"time": 1626993929.2922606, "checksum": 3603339157, "bids": [[32817.0, 0.0], [32252.0, 0.0004]], "asks": [], "action": "update"}}
1626993929.335089: {"channel": "orderbook", "market": "MKR-PERP", "type": "update", "data": {"time": 1626993929.3069475, "checksum": 3445863798, "bids": [[2384.5, 0.0], [2091.5, 0.001]], "asks": [], "action": "update"}}
1626993929.361244: {"channel": "orderbook", "market": "BTC-1231", "type": "update", "data": {"time": 1626993929.3266573, "checksum": 2061689572, "bids": [[32817.0, 0.25], [32813.0, 0.0]], "asks": [[32895.0, 0.2282]], "action": "update"}}
1626993929.3943229: {"channel": "orderbook", "market": "BTC-1231", "type": "update", "data": {"time": 1626993929.3671818, "checksum": 3996301341, "bids": [[32817.0, 0.0], [32763.0, 0.0], [32247.0, 0.0002], [32242.0, 0.0004]], "asks": [], "action": "update"}}
1626993929.404438: {"channel": "orderbook", "market": "MKR-PERP", "type": "update", "data": {"time": 1626993929.3799994, "checksum": 3943650277, "bids": [], "asks": [[2418.5, 1.618]], "action": "update"}}
1626993929.442448: {"channel": "orderbook", "market": "BTC-1231", "type": "update", "data": {"time": 1626993929.4035597, "checksum": 1989038013, "bids": [[32799.0, 0.05], [32242.0, 0.0]], "asks": [[32833.0, 0.0773]], "action": "update"}}
1626993929.47375: {"channel": "orderbook", "market": "BTC-1231", "type": "update", "data": {"time": 1626993929.443392, "checksum": 3911914771, "bids": [[32817.0, 0.25], [32814.0, 0.01], [32252.0, 0.0], [32247.0, 0.0]], "asks": [], "action": "update"}}
1626993929.4756072: {"channel": "orderbook", "market": "FLOW-PERP", "type": "update", "data": {"time": 1626993929.4517753, "checksum": 2871246148, "bids": [], "asks": [[16.48, 403.7]], "action": "update"}}
1626993929.4849439: {"channel": "orderbook", "market": "BTC-1231", "type": "update", "data": {"time": 1626993929.4599376, "checksum": 3238012370, "bids": [[32814.0, 0.0], [32252.0, 0.0004]], "asks": [], "action": "update"}}
1626993929.515916: {"channel": "orderbook", "market": "CAD/USD", "type": "update", "data": {"time": 1626993929.4920783, "checksum": 706162672, "bids": [], "asks": [], "action": "update"}}
1626993929.5187871: {"channel": "orderbook", "market": "FLOW-PERP", "type": "update", "data": {"time": 1626993929.4975476, "checksum": 115849911, "bids": [], "asks": [[17.15, 23.32], [18.925, 0.0]], "action": "update"}}
