1626993929.553972: {"channel": "orderbook", "market": "BTC-1231", "type": "update", "data": {"time": 1626993929.5224755, "checksum": 562784430, "bids": [[32773.0, 1.2059], [32252.0, 0.0]], "asks": [], "action": "update"}}
1626993929.5952299: {"channel": "orderbook", "market": "KNCBULL/USDT", "type": "update", "data": {"time": 1626993929.5737236, "checksum": 4188723151, "bids": [], "asks": [], "action": "update"}}
1626993929.5953238: {"channel": "orderbook", "market": "BTC-1231", "type": "update", "data": {"time": 1626993929.5614636, "checksum": 2065509598, "bids": [[32818.0, 0.01], [32282.0, 0.0]], "asks": [], "action": "update"}}
1626993929.671099: {"channel": "orderbook", "market": "BTC-1231", "type": "update", "data": {"time": 1626993929.649761, "checksum": 1173324057, "bids": [[32817.0, 0.0], [32282.0, 0.0002]], "asks": [[32826.0, 0.2503]], "action": "update"}}
1626993929.766287: {"channel": "orderbook", "market": "BTC-1231", "type": "update", "data": {"time": 1626993929.7328022, "checksum": 1663097333, "bids": [[32818.0, 0.25]], "asks": [[32826.0, 0.0003]], "action": "update"}}
1626993929.813302: {"channel": "orderbook", "market": "CHZ/USDT", "type": "update", "data": {"time": 1626993929.792727, "checksum": 1019257027, "bids": [], "asks": [[0.231383, 0.0], [0.5421, 270.0]], "action": "update"}}
1626993929.838134: {"channel": "orderbook", "market": "BNBBEAR/USDT", "type": "update", "data": {"time": 1626993929.8057714, "checksum": 884149509, "bids": [], "asks": [], "action": "update"}}
1626993929.8686452: {"channel": "orderbook", "market": "BTC-1231", "type": "update", "data": {"time": 1626993929.8434033, "checksum": 3128067150, "bids": [[32819.0, 0.01], [32282.0, 0.0]], "asks": [], "action": "update"}}
1626993929.9263701: {"channel": "orderbook", "market": "BB-0924", "type": "update", "data": {"time": 1626993929.89168, "checksum": 1359273830, "bids": [], "asks": [], "action": "update"}}
1626993929.963424: {"channel": "orderbook", "market": "BTC-1231", "type": "update", "data": {"time": 1626993929.9375172, "checksum": 870782270, "bids": [[32819.0, 0.26]], "asks": [], "action": "update"}}
1626993929.9821901: {"channel": "orderbook", "market": "BTC-1231", "type": "update", "data": {"time": 1626993929.9589186, "checksum": 2918244680, "bids": [[32818.0, 0.0], [32282.0, 0.0002]], "asks": [], "action": "update"}}
1626993930.007862: {"channel": "orderbook", "market": "MKR-PERP", "type": "update", "data": {"time": 1626993929.9771416, "checksum": 3943650277, "bids": [], "asks": [], "action": "update"}}
1626993930.048316: {"channel": "orderbook", "market": "APHA/USD", "type": "update", "data": {"time": 1626993930.0227187, "checksum": 756393738, "bids": [], "asks": [], "action": "update"}}
1626993930.1332679: {"channel": "orderbook", "market": "BTC-1231", "type": "update", "data": {"time": 1626993930.1103382, "checksum": 865347567, "bids": [[32755.0, 0.0], [32252.0, 0.0004]], "asks": [], "action": "update"}}
1626993930.1507251: {"channel": "orderbook", "market": "CHZ/USDT", "type": "update", "data": {"time": 1626993930.1292105, "checksum": 1019257027, "bids": [], "asks": [], "action": "update"}}
1626993930.165706: {"channel": "orderbook", "market": "PFE/USD", "type": "update", "data": {"time": 1626993930.1455047, "checksum": 825829276, "bids": [], "asks": [], "action": "update"}}
1626993930.188421: {"channel": "orderbook", "market": "MKR-PERP", "type": "update", "data": {"time": 1626993930.1639144, "checksum": 2954167995, "bids": [[2414.0, 0.186], [2385.0, 15.27]], "asks": [], "action": "update"}}
1626993930.218831: {"channel": "orderbook", "market": "CHZ/USDT", "type": "update", "data": {"time": 1626993930.1787045, "checksum": 2548726725, "bids": [], "asks": [[0.23521, 3840.0], [0.5421, 0.0]], "action": "update"}}
1626993930.218996: {"channel": "orderbook", "market": "BTC-1231", "type": "update", "data": {"time": 1626993930.1766682, "checksum": 3882137888, "bids": [[32819.0, 0.25], [32743.0, 0.0], [32247.0, 0.0002]], "asks": [], "action": "update"}}
1626993930.219075: {"channel": "orderbook", "market": "FLOW-PERP", "type": "update", "data": {"time": 1626993930.175076, "checksum": 4279295874, "bids": [], "asks": [[16.47, 477.78], [17.15, 0.0], [18.925, 0.3]], "action": "update"}}
1626993930.2523699: {"channel": "orderbook", "market": "MKR-PERP", "type": "update", "data": {"time": 1626993930.2298725, "checksum": 1894100309, "bids": [[2414.0, 0.661]], "asks": [[2445.0, 8.219]], "action": "update"}}
1626993930.288948: {"channel": "orderbook", "market": "FLOW-PERP", "type": "update", "data": {"time": 1626993930.2386932, "checksum": 2089775923, "bids": [[16.395, 1096.23]], "asks": [], "action": "update"}}
1626993930.289065: {"channel": "orderbook", "market": "BTC-1231", "type": "update", "data": {"time": 1626993930.2587128, "checksum": 2990890808, "bids": [[32819.0, 0.0], [32242.0, 0.0004]], "asks": [[32837.0, 0.032], [32899.0, 0.0], [33442.0, 0.025]], "action": "update"}}
1626993930.344597: {"channel": "orderbook", "market": "BTC-1231", "type": "update", "data": {"time": 1626993930.308101, "checksum": 3323912919, "bids": [[32773.0, 0.0], [32237.0, 0.1526]], "asks": [[32826.0, 0.2503], [32872.0, 0.0], [33447.0, 0.168]], "action": "update"}}
1626993930.396696: {"channel": "orderbook", "market": "BTC-1231", "type": "update", "data": {"time": 1626993930.3664415, "checksum": 4004339321, "bids": [[32820.0, 0.01], [32813.0, 0.25], [32242.0, 0.0], [32237.0, 0.0]], "asks": [[32826.0, 0.0003]], "action": "update"}}
1626993930.428687: {"channel": "orderbook", "market": "BTC-1231", "type": "update", "data": {"time": 1626993930.4032235, "checksum": 1204355736, "bids": [[32801.0, 0.0], [32242.0, 0.0004]], "asks": [[32841.0, 7.594], [33447.0, 0.0]], "action": "update"}}
1626993930.457459: {"channel": "orderbook", "market": "BTC-1231", "type": "update", "data": {"time": 1626993930.428905, "checksum": 3204184277, "bids": [[32820.0, 0.0], [32813.0, 0.0], [32237.0, 0.1526], [32222.0, 0.0002]], "asks": [], "action": "update"}}
1626993930.47893: {"channel": "orderbook", "market": "BTC-1231", "type": "update", "data": {"time": 1626993930.4550402, "checksum": 1647386838, "bids": [], "asks": [[32826.0, 0.2503], [32837.0, 0.0344], [32838.0, 0.0], [33447.0, 0.168]], "action": "update"}}
1626993930.4948092: {"channel": "orderbook", "market": "MKR-PERP", "type": "update", "data": {"time": 1626993930.4704814, "checksum": 2344163256, "bids": [], "asks": [[2416.0, 0.0], [2416.5, 2.591], [2800.0, 0.035]], "action": "update"}}
1626993930.510019: {"channel": "orderbook", "market": "MKR-PERP", "type": "update", "data": {"time": 1626993930.489203, "checksum": 1085242486, "bids": [], "asks": [[2416.5, 1.892]], "action": "update"}}
1626993930.554762: {"channel": "orderbook", "market": "BTC-1231", "type": "update", "data": {"time": 1626993930.5286999, "checksum": 3866206846, "bids": [[32812.0, 0.25], [32809.0, 6.6923], [32773.0, 1.2232], [32242.0, 0.0], [32237.0, 0.0], [32222.0, 0.0]], "asks": [[32826.0, 0.0003], [32837.0, 0.032], [32886.0, 0.2382]], "action": "update"}}
1626993930.5549939: {"channel": "orderbook", "market": "CAD/USD", "type": "update", "data": {"time": 1626993930.5306587, "checksum": 706162672, "bids": [], "asks": [], "action": "update"}}
1626993930.5981429: {"channel": "orderbook", "market": "MKR-PERP", "type": "update", "data": {"time": 1626993930.5699193, "checksum": 2016453718, "bids": [], "asks": [[2416.0, 0.42], [2418.5, 5.722], [2800.0, 0.0]], "action": "update"}}
1626993930.601332: {"channel": "orderbook", "market": "BTC-1231", "type": "update", "data": {"time": 1626993930.5800512, "checksum": 470413597, "bids": [[32809.0, 6.6823], [32806.0, 0.0], [32242.0, 0.0004]], "asks": [[32899.0, 1.2589], [33447.0, 0.0]], "action": "update"}}
1626993930.627135: {"channel": "orderbook", "market": "MKR-PERP", "type": "update", "data": {"time": 1626993930.6009593, "checksum": 4260323897, "bids": [], "asks": [[2418.5, 1.618]], "action": "update"}}
1626993930.627601: {"channel": "orderbook", "market": "KNCBULL/USDT", "type": "update", "data": {"time": 1626993930.6032736, "checksum": 4188723151, "bids": [], "asks": [], "action": "update"}}
1626993930.645372: {"channel": "orderbook", "market": "MKR-PERP", "type": "update", "data": {"time": 1626993930.622309, "checksum": 1119071879, "bids": [[2414.5, 0.441], [2091.5, 0.0]], "asks": [], "action": "update"}}
1626993930.666811: {"channel": "orderbook", "market": "BTC-1231", "type": "update", "data": {"time": 1626993930.6389854, "checksum": 2185537279, "bids": [[32814.0, 0.25], [32242.0, 0.0]], "asks": [], "action": "update"}}
1626993930.707099: {"channel": "orderbook", "market": "MKR-PERP", "type": "update", "data": {"time": 1626993930.6770926, "checksum": 2172753848, "bids": [[2414.0, 0.186]], "asks": [], "action": "update"}}
1626993930.707217: {"channel": "orderbook", "market": "FLOW-PERP", "type": "update", "data": {"time": 1626993930.6855605, "checksum": 2954049252, "bids": [], "asks": [[16.44, 98.29]], "action": "update"}}
1626993930.7356129: {"channel": "orderbook", "market": "FLOW-PERP", "type": "update", "data": {"time": 1626993930.7101717, "checksum": 2876323778, "bids": [[16.4, 46.72], [14.3, 0.0]], "asks": [], "action": "update"}}
1626993930.744805: {"channel": "orderbook", "market": "BTC-1231", "type": "update", "data": {"time": 1626993930.714181, "checksum": 192146268, "bids": [[32812.0, 0.0], [32771.0, 0.005], [32743.0, 0.005], [32247.0, 0.0]], "asks": [], "action": "update"}}
1626993930.797396: {"channel": "orderbook", "market": "BTC-1231", "type": "update", "data": {"time": 1626993930.7580245, "checksum": 2269085979, "bids": [[32816.0, 0.25], [32813.0, 0.01], [32282.0, 0.0], [32252.0, 0.0]], "asks": [], "action": "update"}}
1626993930.8215559: {"channel": "orderbook", "market": "MKR-PERP", "type": "update", "data": {"time": 1626993930.7926593, "checksum": 3054233714, "bids": [], "asks": [[2418.0, 0.0], [2419.0, 5.257], [2800.0, 0.035]], "action": "update"}}
1626993930.840649: {"channel": "orderbook", "market": "MKR-PERP", "type": "update", "data": {"time": 1626993930.8174481, "checksum": 826526891, "bids": [], "asks": [[2420.0, 3.111]], "action": "update"}}
1626993930.8646872: {"channel": "orderbook", "market": "BNBBEAR/USDT", "type": "update", "data": {"time": 1626993930.8405678, "checksum": 884149509, "bids": [], "asks": [], "action": "update"}}
1626993930.95933: {"channel": "orderbook", "market": "BB-0924", "type": "update", "data": {"time": 1626993930.937197, "checksum": 1359273830, "bids": [], "asks": [], "action": "update"}}
1626993931.0039082: {"channel": "orderbook", "market": "MKR-PERP", "type": "update", "data": {"time": 1626993930.980144, "checksum": 4143691691, "bids": [[2414.5, 0.0], [2091.5, 0.001]], "asks": [], "action": "update"}}
1626993931.061654: {"channel": "orderbook", "market": "APHA/USD", "type": "update", "data": {"time": 1626993931.0414004, "checksum": 756393738, "bids": [], "asks": [], "action": "update"}}
1626993931.131894: {"channel": "orderbook", "market": "BTC-1231", "type": "update", "data": {"time": 1626993930.8248942, "checksum": 828148763, "bids": [[32813.0, 0.0], [32282.0, 0.0002]], "asks": [], "action": "update"}}
1626993931.175: {"channel": "orderbook", "market": "CHZ/USDT", "type": "update", "data": {"time": 1626993931.1464217, "checksum": 2548726725, "bids": [], "asks": [], "action": "update"}}
1626993931.18452: {"channel": "orderbook", "market": "BTC-1231", "type": "update", "data": {"time": 1626993931.1532578, "checksum": 446594460, "bids": [[32817.0, 0.25], [32814.0, 0.0], [32710.0, 0.8332]], "asks": [], "action": "update"}}
1626993931.1895099: {"channel": "orderbook", "market": "PFE/USD", "type": "update", "data": {"time": 1626993931.169885, "checksum": 825829276, "bids": [], "asks": [], "action": "update"}}
1626993931.237021: {"channel": "orderbook", "market": "BTC-1231", "type": "update", "data": {"time": 1626993931.204192, "checksum": 67891769, "bids": [[32817.0, 0.0], [32816.0, 0.0], [32815.0, 0.01], [32252.0, 0.0004]], "asks": [], "action": "update"}}
1626993931.258129: {"channel": "orderbook", "market": "MKR-PERP", "type": "update", "data": {"time": 1626993931.2276297, "checksum": 755797948, "bids": [[2410.0, 3.264]], "asks": [[2420.0, 1.166]], "action": "update"}}
1626993931.262166: {"channel": "orderbook", "market": "FLOW-PERP", "type": "update", "data": {"time": 1626993931.2194407, "checksum": 2876323778, "bids": [], "asks": [], "action": "update"}}
1626993931.2812438: {"channel": "orderbook", "market": "BTC-1231", "type": "update", "data": {"time": 1626993931.2541957, "checksum": 899148034, "bids": [[32815.0, 0.0], [32247.0, 0.0002]], "asks": [[32840.0, 0.0024], [33442.0, 0.0]], "action": "update"}}
1626993931.3256772: {"channel": "orderbook", "market": "BTC-1231", "type": "update", "data": {"time": 1626993931.3009295, "checksum": 4182582220, "bids": [[32807.0, 0.549]], "asks": [], "action": "update"}}
1626993931.352737: {"channel": "orderbook", "market": "BTC-1231", "type": "update", "data": {"time": 1626993931.3263526, "checksum": 4182582220, "bids": [], "asks": [], "action": "update"}}
1626993931.381013: {"channel": "orderbook", "market": "BTC-1231", "type": "update", "data": {"time": 1626993931.3564756, "checksum": 205016998, "bids": [[32816.0, 0.25], [32810.0, 0.01], [32252.0, 0.0], [32247.0, 0.0]], "asks": [], "action": "update"}}
1626993931.425359: {"channel": "orderbook", "market": "BTC-1231", "type": "update", "data": {"time": 1626993931.402155, "checksum": 3492485079, "bids": [[32773.0, 0.0], [32252.0, 0.0004]], "asks": [[32826.0, 0.0], [32899.0, 0.0], [33442.0, 0.025], [33447.0, 0.168]], "action": "update"}}
1626993931.4563289: {"channel": "orderbook", "market": "BTC-1231", "type": "update", "data": {"time": 1626993931.4289567, "checksum": 1150128977, "bids": [[32817.0, 0.25], [32816.0, 0.0], [32810.0, 0.0], [32247.0, 0.0002]], "asks": [[32827.0, 0.0], [33454.0, 0.0004]], "action": "update"}}
1626993931.477109: {"channel": "orderbook", "market": "MKR-PERP", "type": "update", "data": {"time": 1626993931.4511397, "checksum": 2702230761, "bids": [], "asks": [[2416.5, 1.685]], "action": "update"}}
1626993931.52469: {"channel": "orderbook", "market": "MKR-PERP", "type": "update", "data": {"time": 1626993931.502476, "checksum": 3689428054, "bids": [[2344.5, 0.0], [2086.0, 0.001]], "asks": [], "action": "update"}}
1626993931.527016: {"channel": "orderbook", "market": "BTC-1231", "type": "update", "data": {"time": 1626993931.478844, "checksum": 2399430445, "bids": [], "asks": [[32833.0, 0.05], [32844.0, 11.7229], [33454.0, 0.0]], "action": "update"}}
1626993931.562732: {"channel": "orderbook", "market": "BTC-1231", "type": "update", "data": {"time": 1626993931.5340016, "checksum": 1735658372, "bids": [[32817.0, 0.0], [32812.0, 8.7991], [32710.0, 0.604]], "asks": [[32828.0, 0.0003], [32830.0, 0.2505], [32833.0, 0.6445], [32834.0, 0.0], [32841.0, 0.0], [33454.0, 0.0004]], "action": "update"}}
1626993931.5865679: {"channel": "orderbook", "market": "BTC-1231", "type": "update", "data": {"time": 1626993931.5600617, "checksum": 11201807, "bids": [[32818.0, 0.01], [32809.0, 0.0]], "asks": [[32851.0, 0.0153], [33454.0, 0.0]], "action": "update"}}
1626993931.6153018: {"channel": "orderbook", "market": "MKR-PERP", "type": "update", "data": {"time": 1626993931.588397, "checksum": 532680628, "bids": [], "asks": [[2417.0, 0.974]], "action": "update"}}
1626993931.616935: {"channel": "orderbook", "market": "CAD/USD", "type": "update", "data": {"time": 1626993931.5841749, "checksum": 706162672, "bids": [], "asks": [], "action": "update"}}
1626993931.637776: {"channel": "orderbook", "market": "MKR-PERP", "type": "update", "data": {"time": 1626993931.6139853, "checksum": 2739672871, "bids": [[2385.0, 19.463]], "asks": [], "action": "update"}}
1626993931.638256: {"channel": "orderbook", "market": "BTC-1231", "type": "update", "data": {"time": 1626993931.6142275, "checksum": 2884198203, "bids": [[32815.0, 0.25], [32247.0, 0.0]], "asks": [[32830.0, 0.0005], [32840.0, 0.0], [33454.0, 0.0004]], "action": "update"}}
1626993931.652565: {"channel": "orderbook", "market": "KNCBULL/USDT", "type": "update", "data": {"time": 1626993931.6290717, "checksum": 4188723151, "bids": [], "asks": [], "action": "update"}}
1626993931.6708019: {"channel": "orderbook", "market": "BTC-1231", "type": "update", "data": {"time": 1626993931.6456609, "checksum": 702335674, "bids": [[32818.0, 0.0], [32776.0, 2.3417], [32247.0, 0.0002]], "asks": [[32876.0, 0.2382]], "action": "update"}}
1626993931.6892538: {"channel": "orderbook", "market": "FLOW-PERP", "type": "update", "data": {"time": 1626993931.6606262, "checksum": 3475406079, "bids": [[16.42, 79.97], [14.31, 0.0]], "asks": [], "action": "update"}}
1626993931.6959732: {"channel": "orderbook", "market": "MKR-PERP", "type": "update", "data": {"time": 1626993931.6652725, "checksum": 2596117618, "bids": [], "asks": [[2417.0, 1.181], [2445.0, 12.309]], "action": "update"}}
1626993931.703887: {"channel": "orderbook", "market": "BTC-1231", "type": "update", "data": {"time": 1626993931.6769714, "checksum": 2859758603, "bids": [[32818.0, 0.25], [32815.0, 0.0]], "asks": [[32900.0, 1.2316]], "action": "update"}}
1626993931.7314088: {"channel": "orderbook", "market": "BTC-1231", "type": "update", "data": {"time": 1626993931.7069776, "checksum": 2511329953, "bids": [[32818.0, 0.0], [32242.0, 0.0004]], "asks": [], "action": "update"}}
1626993931.751078: {"channel": "orderbook", "market": "FLOW-PERP", "type": "update", "data": {"time": 1626993931.7302976, "checksum": 4047132784, "bids": [], "asks": [[16.47, 159.78]], "action": "update"}}
1626993931.790386: {"channel": "orderbook", "market": "BTC-1231", "type": "update", "data": {"time": 1626993931.7612102, "checksum": 1325840548, "bids": [], "asks": [[32828.0, 0.2503]], "action": "update"}}
1626993931.806022: {"channel": "orderbook", "market": "BTC-1231", "type": "update", "data": {"time": 1626993931.782451, "checksum": 3335943467, "bids": [[32816.0, 0.01], [32242.0, 0.0]], "asks": [], "action": "update"}}
1626993931.808268: {"channel": "orderbook", "market": "FLOW-PERP", "type": "update", "data": {"time": 1626993931.7863538, "checksum": 2886062917, "bids": [[16.42, 304.97]], "asks": [], "action": "update"}}
1626993931.823736: {"channel": "orderbook", "market": "MKR-PERP", "type": "update", "data": {"time": 1626993931.7780719, "checksum": 3729358088, "bids": [], "asks": [[2419.5, 3.842]], "action": "update"}}
1626993931.837475: {"channel": "orderbook", "market": "BTC-1231", "type": "update", "data": {"time": 1626993931.8109787, "checksum": 478091054, "bids": [], "asks": [[32828.0, 0.0003]], "action": "update"}}
1626993931.8567061: {"channel": "orderbook", "market": "BTC-1231", "type": "update", "data": {"time": 1626993931.836262, "checksum": 1537514608, "bids": [[32816.0, 0.0], [32814.0, 0.25]], "asks": [[32843.0, 0.0024], [33454.0, 0.0]], "action": "update"}}
1626993931.908263: {"channel": "orderbook", "market": "BTC-1231", "type": "update", "data": {"time": 1626993931.8586662, "checksum": 1498526700, "bids": [[32816.0, 0.25], [32814.0, 0.0]], "asks": [], "action": "update"}}
1626993931.908417: {"channel": "orderbook", "market": "BNBBEAR/USDT", "type": "update", "data": {"time": 1626993931.8633287, "checksum": 884149509, "bids": [], "asks": [], "action": "update"}}
1626993931.908486: {"channel": "orderbook", "market": "BTC-1231", "type": "update", "data": {"time": 1626993931.8830638, "checksum": 1477873942, "bids": [[32816.0, 0.0], [32242.0, 0.0004]], "asks": [], "action": "update"}}
1626993931.913263: {"channel": "orderbook", "market": "MKR-PERP", "type": "update", "data": {"time": 1626993931.886463, "checksum": 1256384733, "bids": [[2341.5, 1.469], [2086.0, 0.0]], "asks": [], "action": "update"}}
1626993932.026529: {"channel": "orderbook", "market": "BB-0924", "type": "update", "data": {"time": 1626993931.9847481, "checksum": 1359273830, "bids": [], "asks": [], "action": "update"}}
1626993932.026628: {"channel": "orderbook", "market": "BTC-1231", "type": "update", "data": {"time": 1626993931.9839203, "checksum": 3760105039, "bids": [[32815.0, 0.01], [32242.0, 0.0]], "asks": [], "action": "update"}}
1626993932.0312169: {"channel": "orderbook", "market": "MKR-PERP", "type": "update", "data": {"time": 1626993932.004227, "checksum": 1256384733, "bids": [], "asks": [], "action": "update"}}
1626993932.0832481: {"channel": "orderbook", "market": "MKR-PERP", "type": "update", "data": {"time": 1626993932.054871, "checksum": 2587248237, "bids": [], "asks": [[2416.5, 2.421]], "action": "update"}}
1626993932.086897: {"channel": "orderbook", "market": "BTC-1231", "type": "update", "data": {"time": 1626993932.0653396, "checksum": 1524501438, "bids": [[32815.0, 0.25]], "asks": [], "action": "update"}}
1626993932.0927: {"channel": "orderbook", "market": "APHA/USD", "type": "update", "data": {"time": 1626993932.072456, "checksum": 756393738, "bids": [], "asks": [], "action": "update"}}
1626993932.116147: {"channel": "orderbook", "market": "MKR-PERP", "type": "update", "data": {"time": 1626993932.091359, "checksum": 370764531, "bids": [], "asks": [[2417.0, 0.482]], "action": "update"}}
1626993932.1330812: {"channel": "orderbook", "market": "MKR-PERP", "type": "update", "data": {"time": 1626993932.110965, "checksum": 990726676, "bids": [[2413.5, 1.962]], "asks": [], "action": "update"}}
1626993932.1650271: {"channel": "orderbook", "market": "BTC-1231", "type": "update", "data": {"time": 1626993932.1325114, "checksum": 2614324182, "bids": [[32799.0, 0.0], [32242.0, 0.0004]], "asks": [[32833.0, 0.5945]], "action": "update"}}
1626993932.192419: {"channel": "orderbook", "market": "CHZ/USDT", "type": "update", "data": {"time": 1626993932.171015, "checksum": 2548726725, "bids": [], "asks": [], "action": "update"}}
1626993932.215411: {"channel": "orderbook", "market": "BTC-1231", "type": "update", "data": {"time": 1626993932.1738958, "checksum": 3397295978, "bids": [[32816.0, 0.26], [32242.0, 0.0]], "asks": [], "action": "update"}}
1626993932.2270231: {"channel": "orderbook", "market": "PFE/USD", "type": "update", "data": {"time": 1626993932.207365, "checksum": 825829276, "bids": [], "asks": [], "action": "update"}}
1626993932.243104: {"channel": "orderbook", "market": "FLOW-PERP", "type": "update", "data": {"time": 1626993932.2149732, "checksum": 3182956314, "bids": [[16.42, 225.0]], "asks": [], "action": "update"}}
1626993932.256185: {"channel": "orderbook", "market": "BTC-1231", "type": "update", "data": {"time": 1626993932.2243762, "checksum": 2706878289, "bids": [[32815.0, 0.0], [32803.0, 0.05]], "asks": [[32837.0, 0.082]], "action": "update"}}
1626993932.2833102: {"channel": "orderbook", "market": "FLOW-PERP", "type": "update", "data": {"time": 1626993932.2600486, "checksum": 3182956314, "bids": [], "asks": [], "action": "update"}}
1626993932.297871: {"channel": "orderbook", "market": "MKR-PERP", "type": "update", "data": {"time": 1626993932.2762175, "checksum": 1160530162, "bids": [], "asks": [[2419.0, 5.688], [2419.5, 5.489]], "action": "update"}}
1626993932.3181372: {"channel": "orderbook", "market": "BTC-1231", "type": "update", "data": {"time": 1626993932.2966359, "checksum": 424463582, "bids": [], "asks": [[32827.0, 0.0155], [32900.0, 0.01], [33447.0, 0.0]], "action": "update"}}
1626993932.330636: {"channel": "orderbook", "market": "MKR-PERP", "type": "update", "data": {"time": 1626993932.3078985, "checksum": 2460174164, "bids": [], "asks": [[2419.5, 7.435]], "action": "update"}}
1626993932.358828: {"channel": "orderbook", "market": "FLOW-PERP", "type": "update", "data": {"time": 1626993932.3328626, "checksum": 2235615372, "bids": [[16.425, 79.97], [14.335, 0.0]], "asks": [], "action": "update"}}
1626993932.375803: {"channel": "orderbook", "market": "BTC-1231", "type": "update", "data": {"time": 1626993932.3477128, "checksum": 424463582, "bids": [], "asks": [], "action": "update"}}
1626993932.3776379: {"channel": "orderbook", "market": "MKR-PERP", "type": "update", "data": {"time": 1626993932.3512793, "checksum": 4202314418, "bids": [], "asks": [[2416.0, 0.809]], "action": "update"}}
1626993932.4304798: {"channel": "orderbook", "market": "BTC-1231", "type": "update", "data": {"time": 1626993932.3929055, "checksum": 1838335726, "bids": [[32817.0, 0.25], [32247.0, 0.0]], "asks": [], "action": "update"}}
1626993932.457629: {"channel": "orderbook", "market": "BTC-1231", "type": "update", "data": {"time": 1626993932.4359813, "checksum": 2119597201, "bids": [[32816.0, 0.01], [32743.0, 0.0], [32247.0, 0.0002]], "asks": [[32906.0, 1.2525], [33442.0, 0.0]], "action": "update"}}
1626993932.4726841: {"channel": "orderbook", "market": "MKR-PERP", "type": "update", "data": {"time": 1626993932.4482732, "checksum": 703292968, "bids": [], "asks": [[2415.5, 0.426], [2416.5, 2.007], [2417.0, 0.275], [2418.0, 0.4], [2795.5, 0.0], [2800.0, 0.0]], "action": "update"}}
1626993932.483364: {"channel": "orderbook", "market": "FLOW-PERP", "type": "update", "data": {"time": 1626993932.4574997, "checksum": 3050042263, "bids": [[16.395, 1070.69]], "asks": [], "action": "update"}}
1626993932.52103: {"channel": "orderbook", "market": "BTC-1231", "type": "update", "data": {"time": 1626993932.4986293, "checksum": 777124374, "bids": [[32816.0, 0.0], [32242.0, 0.0004]], "asks": [], "action": "update"}}
1626993932.559371: {"channel": "orderbook", "market": "MKR-PERP", "type": "update", "data": {"time": 1626993932.5342183, "checksum": 2891340535, "bids": [[2413.5, 1.237], [2410.5, 1.946], [2091.5, 0.0]], "asks": [[2419.0, 5.257]], "action": "update"}}
1626993932.605292: {"channel": "orderbook", "market": "MKR-PERP", "type": "update", "data": {"time": 1626993932.5767, "checksum": 1734192136, "bids": [], "asks": [[2444.5, 0.0], [2795.5, 0.024]], "action": "update"}}
1626993932.605414: {"channel": "orderbook", "market": "BTC-1231", "type": "update", "data": {"time": 1626993932.5696585, "checksum": 846034586, "bids": [], "asks": [[32876.0, 0.2332]], "action": "update"}}
1626993932.6055171: {"channel": "orderbook", "market": "FLOW-PERP", "type": "update", "data": {"time": 1626993932.5812967, "checksum": 1468163120, "bids": [[16.425, 0.0], [16.375, 152.73], [14.335, 0.42]], "asks": [], "action": "update"}}
1626993932.635183: {"channel": "orderbook", "market": "MKR-PERP", "type": "update", "data": {"time": 1626993932.6063788, "checksum": 2344385993, "bids": [[2414.0, 0.903]], "asks": [[2416.5, 1.478], [2419.5, 5.489]], "action": "update"}}
1626993932.641421: {"channel": "orderbook", "market": "BTC-1231", "type": "update", "data": {"time": 1626993932.6184177, "checksum": 1079667731, "bids": [[32710.0, 0.8332]], "asks": [], "action": "update"}}
1626993932.652085: {"channel": "orderbook", "market": "FLOW-PERP", "type": "update", "data": {"time": 1626993932.6301463, "checksum": 352998503, "bids": [[16.41, 99.61], [16.36, 329.37]], "asks": [], "action": "update"}}
1626993932.661737: {"channel": "orderbook", "market": "KNCBULL/USDT", "type": "update", "data": {"time": 1626993932.6403463, "checksum": 4188723151, "bids": [], "asks": [], "action": "update"}}
1626993932.678793: {"channel": "orderbook", "market": "CAD/USD", "type": "update", "data": {"time": 1626993932.6485898, "checksum": 706162672, "bids": [], "asks": [], "action": "update"}}
1626993932.680862: {"channel": "orderbook", "market": "MKR-PERP", "type": "update", "data": {"time": 1626993932.6567464, "checksum": 3800666080, "bids": [], "asks": [[2445.0, 70.309]], "action": "update"}}
1626993932.703197: {"channel": "orderbook", "market": "FLOW-PERP", "type": "update", "data": {"time": 1626993932.6800318, "checksum": 3717473795, "bids": [], "asks": [[16.47, 453.78]], "action": "update"}}
1626993932.709177: {"channel": "orderbook", "market": "MKR-PERP", "type": "update", "data": {"time": 1626993932.6815312, "checksum": 149534425, "bids": [], "asks": [[2415.5, 0.0], [2416.0, 0.389], [2416.5, 2.157], [2800.0, 0.035]], "action": "update"}}
1626993932.709344: {"channel": "orderbook", "market": "BTC-1231", "type": "update", "data": {"time": 1626993932.687733, "checksum": 3180736405, "bids": [[32818.0, 0.01], [32242.0, 0.0]], "asks": [], "action": "update"}}
1626993932.753518: {"channel": "orderbook", "market": "MKR-PERP", "type": "update", "data": {"time": 1626993932.7307246, "checksum": 387969919, "bids": [], "asks": [[2416.5, 1.478]], "action": "update"}}
1626993932.793204: {"channel": "orderbook", "market": "MKR-PERP", "type": "update", "data": {"time": 1626993932.761265, "checksum": 2499028248, "bids": [], "asks": [[2424.5, 4.735]], "action": "update"}}
1626993932.808308: {"channel": "orderbook", "market": "BTC-1231", "type": "update", "data": {"time": 1626993932.780659, "checksum": 1051204973, "bids": [[32818.0, 0.26]], "asks": [], "action": "update"}}
1626993932.812307: {"channel": "orderbook", "market": "MKR-PERP", "type": "update", "data": {"time": 1626993932.7915664, "checksum": 645714093, "bids": [], "asks": [[2416.0, 0.773], [2417.0, 0.768]], "action": "update"}}
1626993932.839222: {"channel": "orderbook", "market": "FLOW-PERP", "type": "update", "data": {"time": 1626993932.8121529, "checksum": 1968038926, "bids": [[16.42, 0.0], [14.31, 69.88]], "asks": [], "action": "update"}}
1626993932.83938: {"channel": "orderbook", "market": "BTC-1231", "type": "update", "data": {"time": 1626993932.8163502, "checksum": 1404206667, "bids": [[32817.0, 0.0], [32242.0, 0.0004]], "asks": [], "action": "update"}}
1626993932.8712058: {"channel": "orderbook", "market": "MKR-PERP", "type": "update", "data": {"time": 1626993932.8437552, "checksum": 452263496, "bids": [[2414.0, 0.186]], "asks": [], "action": "update"}}
1626993932.8916779: {"channel": "orderbook", "market": "FLOW-PERP", "type": "update", "data": {"time": 1626993932.8708868, "checksum": 4205734457, "bids": [[16.4, 0.0], [14.3, 0.32]], "asks": [], "action": "update"}}
1626993932.911489: {"channel": "orderbook", "market": "MKR-PERP", "type": "update", "data": {"time": 1626993932.884835, "checksum": 1702342648, "bids": [], "asks": [[2416.5, 2.2], [2419.5, 5.92], [2421.0, 5.021], [2425.5, 2.0], [2800.0, 0.0]], "action": "update"}}
1626993932.913933: {"channel": "orderbook", "market": "FLOW-PERP", "type": "update", "data": {"time": 1626993932.893806, "checksum": 1058383969, "bids": [[16.405, 46.72], [14.3, 0.0]], "asks": [[16.46, 281.0], [18.925, 0.0]], "action": "update"}}
1626993932.926315: {"channel": "orderbook", "market": "BNBBEAR/USDT", "type": "update", "data": {"time": 1626993932.9008462, "checksum": 884149509, "bids": [], "asks": [], "action": "update"}}
1626993932.9424288: {"channel": "orderbook", "market": "MKR-PERP", "type": "update", "data": {"time": 1626993932.9190123, "checksum": 2463687710, "bids": [[2414.0, 0.923]], "asks": [[2417.0, 0.275]], "action": "update"}}
1626993932.951963: {"channel": "orderbook", "market": "FLOW-PERP", "type": "update", "data": {"time": 1626993932.9301057, "checksum": 480799485, "bids": [], "asks": [[16.43, 1020.0], [18.9, 0.0]], "action": "update"}}
1626993932.952123: {"channel": "orderbook", "market": "BTC-1231", "type": "update", "data": {"time": 1626993932.9305913, "checksum": 2484588937, "bids": [[32750.0, 0.005], [32242.0, 0.0]], "asks": [], "action": "update"}}
1626993932.988672: {"channel": "orderbook", "market": "MKR-PERP", "type": "update", "data": {"time": 1626993932.9629872, "checksum": 1954566396, "bids": [], "asks": [[2415.5, 0.426], [2419.5, 7.865], [2795.5, 0.0]], "action": "update"}}
1626993932.9918: {"channel": "orderbook", "market": "BTC-1231", "type": "update", "data": {"time": 1626993932.9677987, "checksum": 3992098738, "bids": [[32818.0, 0.25]], "asks": [], "action": "update"}}
1626993933.000572: {"channel": "orderbook", "market": "FLOW-PERP", "type": "update", "data": {"time": 1626993932.978386, "checksum": 4127430827, "bids": [[16.405, 0.0], [14.3, 0.32]], "asks": [[16.44, 0.0], [18.9, 1500.0]], "action": "update"}}
1626993933.038916: {"channel": "orderbook", "market": "FLOW-PERP", "type": "update", "data": {"time": 1626993933.0191317, "checksum": 254969475, "bids": [[16.41, 146.33]], "asks": [[16.47, 377.04]], "action": "update"}}
1626993933.046261: {"channel": "orderbook", "market": "MKR-PERP", "type": "update", "data": {"time": 1626993933.0168574, "checksum": 1954566396, "bids": [], "asks": [], "action": "update"}}
1626993933.0678568: {"channel": "orderbook", "market": "MKR-PERP", "type": "update", "data": {"time": 1626993933.0437953, "checksum": 237190534, "bids": [], "asks": [[2418.5, 1.718]], "action": "update"}}
1626993933.078698: {"channel": "orderbook", "market": "BB-0924", "type": "update", "data": {"time": 1626993933.0358498, "checksum": 1359273830, "bids": [], "asks": [], "action": "update"}}
1626993933.102017: {"channel": "orderbook", "market": "MKR-PERP", "type": "update", "data": {"time": 1626993933.0668232, "checksum": 256728352, "bids": [], "asks": [[2419.5, 5.92]], "action": "update"}}
1626993933.104115: {"channel": "orderbook", "market": "FLOW-PERP", "type": "update", "data": {"time": 1626993933.0498092, "checksum": 987137179, "bids": [], "asks": [[16.43, 1089.0]], "action": "update"}}
1626993933.117235: {"channel": "orderbook", "market": "APHA/USD", "type": "update", "data": {"time": 1626993933.0973175, "checksum": 756393738, "bids": [], "asks": [], "action": "update"}}
1626993933.170408: {"channel": "orderbook", "market": "FLOW-PERP", "type": "update", "data": {"time": 1626993933.1476576, "checksum": 14491816, "bids": [], "asks": [[16.455, 73.13], [18.9, 0.0]], "action": "update"}}
1626993933.189792: {"channel": "orderbook", "market": "BTC-1231", "type": "update", "data": {"time": 1626993933.1628249, "checksum": 831328755, "bids": [[32819.0, 0.01], [32808.0, 6.5982], [32785.0, 0.0]], "asks": [[32827.0, 0.0], [33442.0, 0.025]], "action": "update"}}
1626993933.219766: {"channel": "orderbook", "market": "CHZ/USDT", "type": "update", "data": {"time": 1626993933.1979296, "checksum": 2548726725, "bids": [], "asks": [], "action": "update"}}
1626993933.2306728: {"channel": "orderbook", "market": "BTC-1231", "type": "update", "data": {"time": 1626993933.2052343, "checksum": 3935857033, "bids": [[32794.0, 0.0153], [32247.0, 0.0]], "asks": [], "action": "update"}}
1626993933.234367: {"channel": "orderbook", "market": "MKR-PERP", "type": "update", "data": {"time": 1626993933.2059276, "checksum": 2271089322, "bids": [], "asks": [[2418.5, 0.353]], "action": "update"}}
1626993933.249783: {"channel": "orderbook", "market": "PFE/USD", "type": "update", "data": {"time": 1626993933.231329, "checksum": 825829276, "bids": [], "asks": [], "action": "update"}}
1626993933.2948391: {"channel": "orderbook", "market": "BTC-1231", "type": "update", "data": {"time": 1626993933.2729993, "checksum": 3844365833, "bids": [[32819.0, 0.26]], "asks": [], "action": "update"}}
1626993933.3141172: {"channel": "orderbook", "market": "FLOW-PERP", "type": "update", "data": {"time": 1626993933.2707813, "checksum": 14491816, "bids": [], "asks": [], "action": "update"}}
1626993933.3147252: {"channel": "orderbook", "market": "CHZ/USDT", "type": "update", "data": {"time": 1626993933.2939067, "checksum": 3610972967, "bids": [[0.227893, 0.0]], "asks": [], "action": "update"}}
1626993933.336404: {"channel": "orderbook", "market": "BTC-1231", "type": "update", "data": {"time": 1626993933.302885, "checksum": 228791520, "bids": [[32818.0, 0.0], [32247.0, 0.0002]], "asks": [], "action": "update"}}
1626993933.3780322: {"channel": "orderbook", "market": "MKR-PERP", "type": "update", "data": {"time": 1626993933.3573542, "checksum": 1556116412, "bids": [], "asks": [[2419.5, 7.866]], "action": "update"}}
1626993933.4014819: {"channel": "orderbook", "market": "BTC-1231", "type": "update", "data": {"time": 1626993933.3745065, "checksum": 1406187201, "bids": [[32807.0, 0.537], [32463.0, 0.0], [32242.0, 0.0004]], "asks": [], "action": "update"}}
1626993933.473676: {"channel": "orderbook", "market": "MKR-PERP", "type": "update", "data": {"time": 1626993933.4468405, "checksum": 2271089322, "bids": [], "asks": [[2419.5, 5.92]], "action": "update"}}
1626993933.476289: {"channel": "orderbook", "market": "BTC-1231", "type": "update", "data": {"time": 1626993933.4536126, "checksum": 862989418, "bids": [[32810.0, 0.012], [32469.0, 0.5], [32247.0, 0.0], [32242.0, 0.0]], "asks": [], "action": "update"}}
1626993933.494515: {"channel": "orderbook", "market": "BTC-1231", "type": "update", "data": {"time": 1626993933.4743059, "checksum": 177798491, "bids": [], "asks": [[32876.0, 0.2382]], "action": "update"}}
1626993933.686833: {"channel": "orderbook", "market": "KNCBULL/USDT", "type": "update", "data": {"time": 1626993933.6650238, "checksum": 4188723151, "bids": [], "asks": [], "action": "update"}}
1626993933.708801: {"channel": "orderbook", "market": "CAD/USD", "type": "update", "data": {"time": 1626993933.6839995, "checksum": 706162672, "bids": [], "asks": [], "action": "update"}}
1626993933.820416: {"channel": "orderbook", "market": "MKR-PERP", "type": "update", "data": {"time": 1626993933.7855754, "checksum": 2416551339, "bids": [], "asks": [[2419.0, 7.203]], "action": "update"}}
1626993933.8489459: {"channel": "orderbook", "market": "MKR-PERP", "type": "update", "data": {"time": 1626993933.8210363, "checksum": 1446888402, "bids": [], "asks": [[2417.0, 0.0], [2795.5, 0.024]], "action": "update"}}
1626993933.90911: {"channel": "orderbook", "market": "BTC-1231", "type": "update", "data": {"time": 1626993933.883116, "checksum": 1378300927, "bids": [[32740.0, 0.01], [32252.0, 0.0]], "asks": [], "action": "update"}}
1626993933.9306371: {"channel": "orderbook", "market": "MKR-PERP", "type": "update", "data": {"time": 1626993933.8964105, "checksum": 3694416601, "bids": [], "asks": [[2416.5, 1.753]], "action": "update"}}
