1651237315.9230313: {"channel":"orderbook","market":"ETH/USD","type":"update","data":{"time":1651237315.793079,"checksum":3820703975,"bids":[],"asks":[[2861.6,40.354],[2865.8,0.001],[2866.6,0.748]],"action":"update"}}
1651237315.9390771: {"channel":"orderbook","market":"ETH/USDT","type":"update","data":{"time":1651237315.811575,"checksum":3685203131,"bids":[[2860.6,0.229],[2842.7,0.0]],"asks":[],"action":"update"}}
1651237315.9500303: {"channel":"orderbook","market":"LTC/USDT","type":"update","data":{"time":1651237315.81683,"checksum":3372046529,"bids":[[100.52,75.0],[96.5,0.0]],"asks":[],"action":"update"}}
1651237315.9500773: {"channel":"orderbook","market":"ETH/USD","type":"update","data":{"time":1651237315.8181942,"checksum":3020995422,"bids":[[2859.8,3.496]],"asks":[[2861.2,18.258]],"action":"update"}}
1651237315.9736924: {"channel":"orderbook","market":"ETH/USDT","type":"update","data":{"time":1651237315.8384829,"checksum":4283625470,"bids":[[2860.5,27.816]],"asks":[],"action":"update"}}
1651237315.977914: {"channel":"orderbook","market":"ETH/USD","type":"update","data":{"time":1651237315.84608,"checksum":1077802843,"bids":[],"asks":[[2860.7,7.45]],"action":"update"}}
1651237316.0192237: {"channel":"orderbook","market":"SOL/USD","type":"update","data":{"time":1651237315.856154,"checksum":3856014514,"bids":[],"asks":[[96.03,0.0],[96.3575,0.46]],"action":"update"}}
1651237316.0192683: {"channel":"orderbook","market":"SOL/USD","type":"update","data":{"time":1651237315.8821077,"checksum":3460665560,"bids":[[95.85,0.0],[95.44,1.0]],"asks":[],"action":"update"}}
1651237316.0192876: {"channel":"orderbook","market":"ETH/USD","type":"update","data":{"time":1651237315.8795748,"checksum":3953388557,"bids":[[2860.2,7.201],[2860.0,6.343]],"asks":[],"action":"update"}}
1651237316.0193064: {"channel":"orderbook","market":"FTT/BTC","type":"update","data":{"time":1651237315.8812172,"checksum":2177006148,"bids":[],"asks":[],"action":"update"}}
1651237316.0429077: {"channel":"orderbook","market":"SOL/USD","type":"update","data":{"time":1651237315.9098883,"checksum":2162204408,"bids":[[95.8425,0.0],[95.4375,0.01]],"asks":[[95.865,96.9],[95.975,62.64]],"action":"update"}}
1651237316.0548997: {"channel":"orderbook","market":"ETH/USD","type":"update","data":{"time":1651237315.9139767,"checksum":246425612,"bids":[[2859.1,38.047]],"asks":[[2863.8,0.307]],"action":"update"}}
1651237316.0642562: {"channel":"orderbook","market":"SOL/USD","type":"update","data":{"time":1651237315.9327114,"checksum":797103608,"bids":[[95.8125,0.68],[95.4375,0.0]],"asks":[[95.97,403.19]],"action":"update"}}
1651237316.0643167: {"channel":"orderbook","market":"ETH/USD","type":"update","data":{"time":1651237315.9305859,"checksum":2128426715,"bids":[[2855.4,6.448]],"asks":[[2867.3,3.037]],"action":"update"}}
1651237316.0888376: {"channel":"orderbook","market":"SHIB/USD","type":"update","data":{"time":1651237315.9559984,"checksum":1104960392,"bids":[],"asks":[[0.00002264,314400000.0]],"action":"update"}}
1651237316.0969465: {"channel":"orderbook","market":"ETH/USD","type":"update","data":{"time":1651237315.9623742,"checksum":53893336,"bids":[[2860.0,8.628],[2855.4,3.417]],"asks":[],"action":"update"}}
1651237316.1042726: {"channel":"orderbook","market":"SOL/USD","type":"update","data":{"time":1651237315.9722548,"checksum":624679260,"bids":[[95.845,51.5],[95.745,0.0]],"asks":[[95.8625,70.02],[95.945,0.03],[96.0475,52.3],[96.35,0.0],[96.3575,0.0]],"action":"update"}}
1651237316.1047647: {"channel":"orderbook","market":"ETH/USD","type":"update","data":{"time":1651237315.9777339,"checksum":4245141386,"bids":[[2860.3,1.862],[2855.4,2.417]],"asks":[],"action":"update"}}
1651237316.1081176: {"channel":"orderbook","market":"SOL/USD","type":"update","data":{"time":1651237315.9833288,"checksum":2921021432,"bids":[],"asks":[[95.93,0.69]],"action":"update"}}
1651237316.119733: {"channel":"orderbook","market":"ETH/USDT","type":"update","data":{"time":1651237315.9887984,"checksum":765112373,"bids":[[2859.5,0.292]],"asks":[],"action":"update"}}
1651237316.1385689: {"channel":"orderbook","market":"BTC/TRY","type":"update","data":{"time":1651237315.990652,"checksum":2549750460,"bids":[],"asks":[],"action":"update"}}
1651237316.138605: {"channel":"orderbook","market":"ETH/USD","type":"update","data":{"time":1651237316.003008,"checksum":1056263283,"bids":[[2860.2,3.751],[2860.0,6.343]],"asks":[[2864.4,0.349],[2873.6,0.0]],"action":"update"}}
1651237316.1386561: {"channel":"orderbook","market":"ETH/USDT","type":"update","data":{"time":1651237316.0115075,"checksum":1611785259,"bids":[[2859.9,6.279],[2858.3,0.0],[2842.7,0.018]],"asks":[],"action":"update"}}
1651237316.1467621: {"channel":"orderbook","market":"SHIB/USD","type":"update","data":{"time":1651237316.019534,"checksum":154411002,"bids":[],"asks":[[0.00002263,426100000.0]],"action":"update"}}
1651237316.1580205: {"channel":"orderbook","market":"ETH/USD","type":"update","data":{"time":1651237316.0271547,"checksum":2136640699,"bids":[[2858.1,4.372]],"asks":[[2863.8,0.298]],"action":"update"}}
1651237316.158081: {"channel":"orderbook","market":"FTT/BTC","type":"update","data":{"time":1651237316.0173836,"checksum":1518355175,"bids":[],"asks":[[0.0010102,66.6]],"action":"update"}}
1651237316.1746643: {"channel":"orderbook","market":"SOL/USD","type":"update","data":{"time":1651237316.0413013,"checksum":3060452893,"bids":[],"asks":[[95.8625,77.29]],"action":"update"}}
1651237316.174723: {"channel":"orderbook","market":"LTC/USDT","type":"update","data":{"time":1651237316.041719,"checksum":3488862198,"bids":[],"asks":[[100.6,12.0],[103.96,0.0]],"action":"update"}}
1651237316.18281: {"channel":"orderbook","market":"ETH/USD","type":"update","data":{"time":1651237316.054822,"checksum":3171150308,"bids":[[2860.6,9.078],[2859.1,38.364]],"asks":[],"action":"update"}}
1651237316.2048635: {"channel":"orderbook","market":"ETH/USD","type":"update","data":{"time":1651237316.077333,"checksum":1184291760,"bids":[[2859.1,38.498],[2855.8,8.017]],"asks":[[2862.4,20.343]],"action":"update"}}
1651237316.2151966: {"channel":"orderbook","market":"ETH/USDT","type":"update","data":{"time":1651237316.0769029,"checksum":997751034,"bids":[[2856.0,2.037]],"asks":[[2864.2,0.0],[2882.9,0.015]],"action":"update"}}
1651237316.2234473: {"channel":"orderbook","market":"SOL/USD","type":"update","data":{"time":1651237316.0765834,"checksum":2371311351,"bids":[[95.7025,0.97],[95.5975,36.84],[95.44,0.0]],"asks":[],"action":"update"}}
1651237316.2234967: {"channel":"orderbook","market":"FTT/BTC","type":"update","data":{"time":1651237316.0932984,"checksum":4220151585,"bids":[],"asks":[[0.00101,10.5],[0.0010101,16.8],[0.001024,0.0],[0.0010241,0.0]],"action":"update"}}
1651237316.2242904: {"channel":"orderbook","market":"SOL/USD","type":"update","data":{"time":1651237316.098811,"checksum":1686796805,"bids":[],"asks":[[96.0925,2.24],[96.3475,0.0]],"action":"update"}}
1651237316.2347107: {"channel":"orderbook","market":"ETH/USDT","type":"update","data":{"time":1651237316.1011853,"checksum":3626309757,"bids":[[2855.9,0.003]],"asks":[[2864.1,185.899]],"action":"update"}}
1651237316.2347782: {"channel":"orderbook","market":"ETH/USD","type":"update","data":{"time":1651237316.1017165,"checksum":3129833455,"bids":[[2854.1,0.013]],"asks":[],"action":"update"}}
1651237316.241461: {"channel":"orderbook","market":"WBTC/USD","type":"update","data":{"time":1651237316.1133192,"checksum":301397845,"bids":[],"asks":[],"action":"update"}}
1651237316.2509837: {"channel":"orderbook","market":"SOL/USD","type":"update","data":{"time":1651237316.1247604,"checksum":4088863817,"bids":[],"asks":[[95.985,0.06],[96.3425,0.0]],"action":"update"}}
1651237316.258579: {"channel":"orderbook","market":"ETH/USDT","type":"update","data":{"time":1651237316.1269236,"checksum":1960661371,"bids":[[2860.0,2.396]],"asks":[],"action":"update"}}
1651237316.2749703: {"channel":"orderbook","market":"SHIB/USD","type":"update","data":{"time":1651237316.1463757,"checksum":2158032098,"bids":[[0.00002207,36200000.0]],"asks":[],"action":"update"}}
1651237316.2776086: {"channel":"orderbook","market":"ETH/USDT","type":"update","data":{"time":1651237316.152148,"checksum":3127332856,"bids":[],"asks":[[2861.7,0.287]],"action":"update"}}
1651237316.2989829: {"channel":"orderbook","market":"SOL/USD","type":"update","data":{"time":1651237316.1741395,"checksum":3162491752,"bids":[],"asks":[[95.8625,7.29]],"action":"update"}}
1651237316.317285: {"channel":"orderbook","market":"LTC/USDT","type":"update","data":{"time":1651237316.1907468,"checksum":611600255,"bids":[],"asks":[[100.85,271.83]],"action":"update"}}
1651237316.3283923: {"channel":"orderbook","market":"SHIB/USD","type":"update","data":{"time":1651237316.1966782,"checksum":4187741993,"bids":[],"asks":[[0.00002263,326200000.0]],"action":"update"}}
1651237316.3284373: {"channel":"orderbook","market":"ETH/USD","type":"update","data":{"time":1651237316.2024937,"checksum":1986107539,"bids":[[2859.3,10.246]],"asks":[],"action":"update"}}
1651237316.3385172: {"channel":"orderbook","market":"SOL/USD","type":"update","data":{"time":1651237316.2029707,"checksum":4104028888,"bids":[[95.775,290.59]],"asks":[[95.945,0.0],[96.3425,0.05]],"action":"update"}}
1651237316.3464236: {"channel":"orderbook","market":"SHIB/USD","type":"update","data":{"time":1651237316.2176392,"checksum":2031949304,"bids":[[0.00002256,102200000.0]],"asks":[],"action":"update"}}
1651237316.358714: {"channel":"orderbook","market":"SOL/USD","type":"update","data":{"time":1651237316.2250726,"checksum":3819903296,"bids":[],"asks":[[95.9225,105.29],[96.3425,0.0]],"action":"update"}}
1651237316.3587525: {"channel":"orderbook","market":"ETH/USD","type":"update","data":{"time":1651237316.2281108,"checksum":594351309,"bids":[[2860.0,6.301],[2859.9,43.492],[2854.5,3.252]],"asks":[],"action":"update"}}
1651237316.3587828: {"channel":"orderbook","market":"ETH/USDT","type":"update","data":{"time":1651237316.2291017,"checksum":268517591,"bids":[[2860.6,6.672],[2860.5,2.5],[2860.1,6.163],[2842.7,0.0]],"asks":[[2861.7,23.305],[2864.0,11.807]],"action":"update"}}
1651237316.381098: {"channel":"orderbook","market":"FTT/BTC","type":"update","data":{"time":1651237316.2463737,"checksum":810585769,"bids":[],"asks":[[0.00101,0.0],[0.001024,0.1]],"action":"update"}}
1651237316.38116: {"channel":"orderbook","market":"ETH/USD","type":"update","data":{"time":1651237316.252165,"checksum":2755509249,"bids":[[2857.1,1.671]],"asks":[],"action":"update"}}
1651237316.3811996: {"channel":"orderbook","market":"ETH/USDT","type":"update","data":{"time":1651237316.253428,"checksum":128484409,"bids":[[2860.6,0.229],[2859.9,6.322]],"asks":[],"action":"update"}}
1651237316.3973255: {"channel":"orderbook","market":"LTC/USDT","type":"update","data":{"time":1651237316.2668667,"checksum":1100072874,"bids":[],"asks":[[100.75,41.59],[103.91,0.0]],"action":"update"}}
1651237316.408588: {"channel":"orderbook","market":"ETH/USDT","type":"update","data":{"time":1651237316.2824743,"checksum":679121645,"bids":[],"asks":[[2861.7,23.348]],"action":"update"}}
1651237316.4086258: {"channel":"orderbook","market":"ETH/USD","type":"update","data":{"time":1651237316.2795174,"checksum":1854168133,"bids":[[2860.0,18.235],[2859.4,15.185],[2849.5,0.0]],"asks":[],"action":"update"}}
1651237316.4294522: {"channel":"orderbook","market":"SOL/USD","type":"update","data":{"time":1651237316.3005846,"checksum":3736726857,"bids":[],"asks":[[95.86,55.0],[96.125,245.77],[96.3375,0.0]],"action":"update"}}
1651237316.4376686: {"channel":"orderbook","market":"ETH/USD","type":"update","data":{"time":1651237316.302667,"checksum":4110086943,"bids":[[2860.3,1.904]],"asks":[],"action":"update"}}
1651237316.454212: {"channel":"orderbook","market":"SOL/USD","type":"update","data":{"time":1651237316.323583,"checksum":1810390368,"bids":[[95.8475,55.0],[95.4475,0.0]],"asks":[],"action":"update"}}
1651237316.457751: {"channel":"orderbook","market":"ETH/USD","type":"update","data":{"time":1651237316.3293777,"checksum":2203066098,"bids":[[2860.1,6.306]],"asks":[[2863.8,0.307]],"action":"update"}}
1651237316.483924: {"channel":"orderbook","market":"SOL/USD","type":"update","data":{"time":1651237316.3548088,"checksum":451040770,"bids":[],"asks":[[95.86,0.0],[95.9225,0.0],[96.3375,0.29],[96.3425,0.05]],"action":"update"}}
1651237316.5190876: {"channel":"orderbook","market":"SOL/USD","type":"update","data":{"time":1651237316.3744347,"checksum":1891585991,"bids":[[95.805,0.0],[95.4475,0.03]],"asks":[],"action":"update"}}
1651237316.5191634: {"channel":"orderbook","market":"ETH/USD","type":"update","data":{"time":1651237316.3773954,"checksum":395307653,"bids":[[2860.6,9.408],[2858.1,4.381]],"asks":[],"action":"update"}}
1651237316.519205: {"channel":"orderbook","market":"LTC/USDT","type":"update","data":{"time":1651237316.3899612,"checksum":1100072874,"bids":[],"asks":[],"action":"update"}}
1651237316.530936: {"channel":"orderbook","market":"ETH/USDT","type":"update","data":{"time":1651237316.4018338,"checksum":2812908702,"bids":[[2860.8,2.0]],"asks":[],"action":"update"}}
1651237316.5383477: {"channel":"orderbook","market":"SHIB/USD","type":"update","data":{"time":1651237316.398469,"checksum":2031949304,"bids":[],"asks":[],"action":"update"}}
1651237316.5635934: {"channel":"orderbook","market":"ETH/USD","type":"update","data":{"time":1651237316.4268787,"checksum":175104992,"bids":[[2860.6,5.958],[2859.3,25.347],[2857.2,1.776]],"asks":[],"action":"update"}}
1651237316.572951: {"channel":"orderbook","market":"ETH/USDT","type":"update","data":{"time":1651237316.4280283,"checksum":3115519491,"bids":[[2860.8,0.0],[2859.1,5.175],[2842.7,0.018]],"asks":[],"action":"update"}}
1651237316.5762625: {"channel":"orderbook","market":"SOL/USD","type":"update","data":{"time":1651237316.4503639,"checksum":851736963,"bids":[[95.845,103.0]],"asks":[[95.93,105.97]],"action":"update"}}
1651237316.5778592: {"channel":"orderbook","market":"ETH/USD","type":"update","data":{"time":1651237316.450514,"checksum":1530372035,"bids":[[2859.2,3.472]],"asks":[],"action":"update"}}
1651237316.5991025: {"channel":"orderbook","market":"ETH/USDT","type":"update","data":{"time":1651237316.4627836,"checksum":1742927786,"bids":[[2859.9,2.313]],"asks":[[2860.9,2.05]],"action":"update"}}
1651237316.6081965: {"channel":"orderbook","market":"ETH/USD","type":"update","data":{"time":1651237316.4781334,"checksum":3476395708,"bids":[[2859.4,21.522]],"asks":[],"action":"update"}}
1651237316.6354475: {"channel":"orderbook","market":"ETH/USD","type":"update","data":{"time":1651237316.5017657,"checksum":1700773420,"bids":[[2859.3,25.529]],"asks":[],"action":"update"}}
1651237316.645717: {"channel":"orderbook","market":"ETH/USDT","type":"update","data":{"time":1651237316.511656,"checksum":3165234669,"bids":[[2859.8,13.056],[2859.7,0.0],[2842.5,835.588]],"asks":[],"action":"update"}}
1651237316.654538: {"channel":"orderbook","market":"ETH/USD","type":"update","data":{"time":1651237316.5280132,"checksum":798342847,"bids":[[2860.6,2.465],[2859.0,6.325]],"asks":[[2862.5,2.358],[2867.5,2.23]],"action":"update"}}
1651237316.6704633: {"channel":"orderbook","market":"ETH/USDT","type":"update","data":{"time":1651237316.5371377,"checksum":348568397,"bids":[],"asks":[[2860.7,2.0],[2862.5,8.01],[2882.9,0.0]],"action":"update"}}
1651237316.6776445: {"channel":"orderbook","market":"ETH/USD","type":"update","data":{"time":1651237316.5509448,"checksum":3703507398,"bids":[[2859.3,25.18],[2859.1,17.92]],"asks":[[2862.4,14.778],[2862.6,0.0],[2866.6,0.747],[2873.6,4.007]],"action":"update"}}
1651237316.686636: {"channel":"orderbook","market":"SOL/USD","type":"update","data":{"time":1651237316.5556817,"checksum":3880262954,"bids":[[95.845,51.5]],"asks":[[95.975,0.0],[96.3475,0.3]],"action":"update"}}
1651237316.6866846: {"channel":"orderbook","market":"ETH/USDT","type":"update","data":{"time":1651237316.5566587,"checksum":704916671,"bids":[[2859.8,7.505],[2859.7,6.92],[2842.5,0.0]],"asks":[],"action":"update"}}
1651237316.7071834: {"channel":"orderbook","market":"DAI/USD","type":"update","data":{"time":1651237316.577967,"checksum":2637841829,"bids":[],"asks":[],"action":"update"}}
1651237316.7072144: {"channel":"orderbook","market":"ETH/USD","type":"update","data":{"time":1651237316.5794683,"checksum":2132075346,"bids":[[2855.0,3.207]],"asks":[],"action":"update"}}
1651237316.7072496: {"channel":"orderbook","market":"ETH/USDT","type":"update","data":{"time":1651237316.5801845,"checksum":3269655643,"bids":[[2860.4,28.212]],"asks":[[2860.9,2.211],[2861.4,1.95],[2862.4,0.182]],"action":"update"}}
1651237316.739435: {"channel":"orderbook","market":"ETH/USD","type":"update","data":{"time":1651237316.6059856,"checksum":3891824138,"bids":[[2860.4,0.0],[2849.5,0.01]],"asks":[[2862.1,0.001],[2864.2,2.123]],"action":"update"}}
1651237316.75685: {"channel":"orderbook","market":"ETH/USDT","type":"update","data":{"time":1651237316.6312873,"checksum":3553954019,"bids":[[2860.6,2.279]],"asks":[],"action":"update"}}
1651237316.7608502: {"channel":"orderbook","market":"SOL/USD","type":"update","data":{"time":1651237316.6302671,"checksum":1146169362,"bids":[],"asks":[[96.035,220.63]],"action":"update"}}
1651237316.7832358: {"channel":"orderbook","market":"ETH/USDT","type":"update","data":{"time":1651237316.65497,"checksum":43272296,"bids":[[2859.9,5.809]],"asks":[[2861.6,42.115]],"action":"update"}}
1651237316.788996: {"channel":"orderbook","market":"ETH/USD","type":"update","data":{"time":1651237316.6529796,"checksum":516886229,"bids":[[2859.2,3.821]],"asks":[[2861.7,33.37]],"action":"update"}}
1651237316.8092759: {"channel":"orderbook","market":"ETH/USD","type":"update","data":{"time":1651237316.6767273,"checksum":3765926582,"bids":[[2860.6,0.566]],"asks":[[2863.5,147.894]],"action":"update"}}
1651237316.8093274: {"channel":"orderbook","market":"ETH/USDT","type":"update","data":{"time":1651237316.6814659,"checksum":2834997328,"bids":[[2860.5,9.556]],"asks":[[2861.6,47.956]],"action":"update"}}
1651237316.834552: {"channel":"orderbook","market":"ETH/USD","type":"update","data":{"time":1651237316.7020144,"checksum":1279570019,"bids":[[2860.3,1.862]],"asks":[[2861.6,48.698]],"action":"update"}}
1651237316.8672643: {"channel":"orderbook","market":"USD/TRY","type":"update","data":{"time":1651237316.7298846,"checksum":2845795420,"bids":[],"asks":[],"action":"update"}}
1651237316.8758106: {"channel":"orderbook","market":"ETH/USD","type":"update","data":{"time":1651237316.7463324,"checksum":2441398785,"bids":[[2859.2,3.472]],"asks":[[2866.2,0.001],[2873.6,0.0]],"action":"update"}}
1651237316.8858151: {"channel":"orderbook","market":"SHIB/USD","type":"update","data":{"time":1651237316.7491934,"checksum":1522942340,"bids":[[0.00002257,449700000.0]],"asks":[],"action":"update"}}
1651237316.914874: {"channel":"orderbook","market":"ETH/USD","type":"update","data":{"time":1651237316.784162,"checksum":3698369325,"bids":[[2860.3,1.904]],"asks":[],"action":"update"}}
1651237316.9341834: {"channel":"orderbook","market":"ETH/USDT","type":"update","data":{"time":1651237316.8085842,"checksum":2901365615,"bids":[],"asks":[[2860.7,4.05]],"action":"update"}}
1651237316.9444706: {"channel":"orderbook","market":"ETH/USD","type":"update","data":{"time":1651237316.8157127,"checksum":1599703700,"bids":[[2859.4,6.337]],"asks":[[2861.4,6.989],[2861.5,10.755]],"action":"update"}}
1651237316.950213: {"channel":"orderbook","market":"SHIB/USD","type":"update","data":{"time":1651237316.8239665,"checksum":168819504,"bids":[],"asks":[[0.00002264,378500000.0]],"action":"update"}}
1651237316.9611292: {"channel":"orderbook","market":"ETH/USD","type":"update","data":{"time":1651237316.833025,"checksum":3603119195,"bids":[[2859.6,6.989]],"asks":[],"action":"update"}}
1651237316.9867346: {"channel":"orderbook","market":"ETH/USDT","type":"update","data":{"time":1651237316.8555834,"checksum":2525952847,"bids":[[2860.2,3.683]],"asks":[],"action":"update"}}
1651237316.993462: {"channel":"orderbook","market":"ETH/USD","type":"update","data":{"time":1651237316.860487,"checksum":3258516018,"bids":[[2860.2,4.003]],"asks":[[2861.3,0.189]],"action":"update"}}
1651237317.0003874: {"channel":"orderbook","market":"SOL/USD","type":"update","data":{"time":1651237316.8662865,"checksum":2997728932,"bids":[],"asks":[[95.8625,36.02],[95.965,62.64],[96.0325,0.01],[96.3425,0.0],[96.3475,0.0]],"action":"update"}}
1651237317.03874: {"channel":"orderbook","market":"FTT/BTC","type":"update","data":{"time":1651237316.8986454,"checksum":810585769,"bids":[],"asks":[],"action":"update"}}
1651237317.0450828: {"channel":"orderbook","market":"SOL/USD","type":"update","data":{"time":1651237316.9096658,"checksum":3656579027,"bids":[[95.8025,105.28],[95.4475,0.0]],"asks":[],"action":"update"}}
1651237317.06668: {"channel":"orderbook","market":"SOL/USD","type":"update","data":{"time":1651237316.9380605,"checksum":712728410,"bids":[[95.845,0.0],[95.4475,0.03]],"asks":[],"action":"update"}}
1651237317.0693758: {"channel":"orderbook","market":"ETH/USD","type":"update","data":{"time":1651237316.9379447,"checksum":1465946117,"bids":[[2857.2,1.768]],"asks":[[2861.1,25.378],[2864.3,10.924]],"action":"update"}}
1651237317.1146123: {"channel":"orderbook","market":"SOL/USD","type":"update","data":{"time":1651237316.9588113,"checksum":401500329,"bids":[[95.845,51.5],[95.4475,0.0]],"asks":[[95.97,469.06]],"action":"update"}}
1651237317.114697: {"channel":"orderbook","market":"SHIB/USD","type":"update","data":{"time":1651237316.9754472,"checksum":1485937794,"bids":[[0.00002257,504300000.0]],"asks":[],"action":"update"}}
1651237317.1274877: {"channel":"orderbook","market":"ETH/USD","type":"update","data":{"time":1651237316.9838638,"checksum":1892956730,"bids":[],"asks":[[2861.0,10.862]],"action":"update"}}
1651237317.141979: {"channel":"orderbook","market":"SOL/USD","type":"update","data":{"time":1651237316.989442,"checksum":1579489820,"bids":[],"asks":[[95.9375,0.03],[96.0125,94.59],[96.3325,0.0],[96.3375,0.0]],"action":"update"}}
1651237317.1420348: {"channel":"orderbook","market":"ETH/USDT","type":"update","data":{"time":1651237316.991077,"checksum":3249229359,"bids":[[2859.8,3.496],[2859.7,18.136]],"asks":[],"action":"update"}}
1651237317.1513631: {"channel":"orderbook","market":"BTC/TRY","type":"update","data":{"time":1651237317.0249598,"checksum":2549750460,"bids":[],"asks":[],"action":"update"}}
1651237317.163089: {"channel":"orderbook","market":"ETH/USDT","type":"update","data":{"time":1651237317.0307937,"checksum":3758035425,"bids":[[2859.7,22.145]],"asks":[[2862.2,1.08]],"action":"update"}}
1651237317.166906: {"channel":"orderbook","market":"ETH/USD","type":"update","data":{"time":1651237317.0326877,"checksum":440275458,"bids":[],"asks":[[2860.9,9.903]],"action":"update"}}
1651237317.1761656: {"channel":"orderbook","market":"SOL/USD","type":"update","data":{"time":1651237317.0336838,"checksum":3066190221,"bids":[],"asks":[[95.9675,249.2],[95.98,97.52]],"action":"update"}}
1651237317.1856685: {"channel":"orderbook","market":"ETH/USDT","type":"update","data":{"time":1651237317.058919,"checksum":3012131273,"bids":[[2860.6,5.108]],"asks":[],"action":"update"}}
1651237317.2211173: {"channel":"orderbook","market":"ETH/USD","type":"update","data":{"time":1651237317.0900888,"checksum":528174632,"bids":[[2859.0,6.674]],"asks":[[2866.2,0.0],[2873.6,4.007]],"action":"update"}}
1651237317.2422354: {"channel":"orderbook","market":"ETH/USDT","type":"update","data":{"time":1651237317.1054096,"checksum":1317070404,"bids":[[2859.9,3.539]],"asks":[],"action":"update"}}
1651237317.2423227: {"channel":"orderbook","market":"ETH/USD","type":"update","data":{"time":1651237317.1098673,"checksum":456795190,"bids":[[2857.3,1.567]],"asks":[],"action":"update"}}
1651237317.2955983: {"channel":"orderbook","market":"WBTC/USD","type":"update","data":{"time":1651237317.1546183,"checksum":301397845,"bids":[],"asks":[],"action":"update"}}
1651237317.3109872: {"channel":"orderbook","market":"ETH/USDT","type":"update","data":{"time":1651237317.1805813,"checksum":625240647,"bids":[],"asks":[[2861.5,17.721]],"action":"update"}}
1651237317.3110347: {"channel":"orderbook","market":"ETH/USD","type":"update","data":{"time":1651237317.1825902,"checksum":172611847,"bids":[[2860.3,1.862]],"asks":[[2860.7,7.935]],"action":"update"}}
1651237317.3294814: {"channel":"orderbook","market":"SHIB/USD","type":"update","data":{"time":1651237317.2002847,"checksum":1721151741,"bids":[[0.00002259,403500000.0]],"asks":[],"action":"update"}}
1651237317.3419216: {"channel":"orderbook","market":"ETH/USD","type":"update","data":{"time":1651237317.2087307,"checksum":2259648142,"bids":[],"asks":[[2861.0,10.843],[2861.1,25.376],[2861.2,18.256]],"action":"update"}}
1651237317.3419783: {"channel":"orderbook","market":"SOL/USD","type":"update","data":{"time":1651237317.2088344,"checksum":3066190221,"bids":[],"asks":[],"action":"update"}}
1651237317.363448: {"channel":"orderbook","market":"ETH/USD","type":"update","data":{"time":1651237317.2327738,"checksum":1354573337,"bids":[[2860.3,1.904]],"asks":[[2861.5,7.259]],"action":"update"}}
1651237317.3680103: {"channel":"orderbook","market":"SOL/USD","type":"update","data":{"time":1651237317.2376075,"checksum":1338514647,"bids":[[95.8475,48.08]],"asks":[],"action":"update"}}
1651237317.3816738: {"channel":"orderbook","market":"SHIB/USD","type":"update","data":{"time":1651237317.2514381,"checksum":3726050366,"bids":[[0.00002257,569000000.0]],"asks":[],"action":"update"}}
1651237317.393657: {"channel":"orderbook","market":"SOL/USD","type":"update","data":{"time":1651237317.2652771,"checksum":2070966441,"bids":[[95.8475,18.79]],"asks":[],"action":"update"}}
1651237317.4122524: {"channel":"orderbook","market":"ETH/USD","type":"update","data":{"time":1651237317.2840137,"checksum":2956970685,"bids":[],"asks":[[2866.7,585.253],[2867.3,6.072]],"action":"update"}}
1651237317.4520445: {"channel":"orderbook","market":"SOL/USD","type":"update","data":{"time":1651237317.3232334,"checksum":234119102,"bids":[[95.66,70.82]],"asks":[],"action":"update"}}
1651237317.460144: {"channel":"orderbook","market":"ETH/USD","type":"update","data":{"time":1651237317.3320954,"checksum":3496704355,"bids":[],"asks":[[2861.1,27.124]],"action":"update"}}
1651237317.470451: {"channel":"orderbook","market":"SOL/USD","type":"update","data":{"time":1651237317.3407874,"checksum":3653951538,"bids":[],"asks":[[95.8875,0.67],[96.1925,0.0]],"action":"update"}}
1651237317.4808416: {"channel":"orderbook","market":"ETH/USDT","type":"update","data":{"time":1651237317.354828,"checksum":2410545141,"bids":[],"asks":[[2860.7,2.0]],"action":"update"}}
1651237317.4874246: {"channel":"orderbook","market":"ETH/USD","type":"update","data":{"time":1651237317.3591447,"checksum":401181864,"bids":[[2859.5,24.801]],"asks":[[2860.7,7.947]],"action":"update"}}
1651237317.515715: {"channel":"orderbook","market":"ETH/USD","type":"update","data":{"time":1651237317.3871932,"checksum":1368725975,"bids":[[2859.0,1.884]],"asks":[],"action":"update"}}
1651237317.5203538: {"channel":"orderbook","market":"SOL/USD","type":"update","data":{"time":1651237317.3932257,"checksum":3634971042,"bids":[[95.8475,11.84]],"asks":[],"action":"update"}}
1651237317.536741: {"channel":"orderbook","market":"ETH/USD","type":"update","data":{"time":1651237317.4085054,"checksum":2339959602,"bids":[[2859.6,13.194]],"asks":[],"action":"update"}}
1651237317.5425582: {"channel":"orderbook","market":"LTC/USDT","type":"update","data":{"time":1651237317.4161284,"checksum":1100072874,"bids":[],"asks":[],"action":"update"}}
1651237317.5588734: {"channel":"orderbook","market":"SHIB/USD","type":"update","data":{"time":1651237317.422835,"checksum":3726050366,"bids":[],"asks":[],"action":"update"}}
1651237317.5762935: {"channel":"orderbook","market":"ETH/USDT","type":"update","data":{"time":1651237317.4348044,"checksum":3387985021,"bids":[[2859.7,18.136]],"asks":[],"action":"update"}}
1651237317.5763721: {"channel":"orderbook","market":"SOL/USD","type":"update","data":{"time":1651237317.4432144,"checksum":3308473036,"bids":[[95.8475,0.0],[95.845,43.53],[95.8425,51.5]],"asks":[],"action":"update"}}
1651237317.6108985: {"channel":"orderbook","market":"ETH/USD","type":"update","data":{"time":1651237317.4815009,"checksum":1876272913,"bids":[],"asks":[[2866.7,585.252]],"action":"update"}}
1651237317.6203597: {"channel":"orderbook","market":"LTC/USDT","type":"update","data":{"time":1651237317.4917321,"checksum":1442697271,"bids":[[100.505,7.46],[96.55,0.0]],"asks":[],"action":"update"}}
1651237317.6204093: {"channel":"orderbook","market":"SOL/USD","type":"update","data":{"time":1651237317.4924107,"checksum":1234232627,"bids":[],"asks":[[95.86,55.0],[96.33,0.0]],"action":"update"}}
1651237317.6355069: {"channel":"orderbook","market":"ETH/USD","type":"update","data":{"time":1651237317.50794,"checksum":924374249,"bids":[],"asks":[[2860.9,9.907]],"action":"update"}}
1651237317.6406653: {"channel":"orderbook","market":"ETH/USDT","type":"update","data":{"time":1651237317.5131428,"checksum":1373968042,"bids":[[2859.7,22.145]],"asks":[[2861.6,37.144]],"action":"update"}}
1651237317.6476645: {"channel":"orderbook","market":"SOL/USD","type":"update","data":{"time":1651237317.5156765,"checksum":3434601637,"bids":[[95.845,0.0],[95.4475,0.03]],"asks":[[95.86,335.0],[95.8625,0.02]],"action":"update"}}
1651237317.6780846: {"channel":"orderbook","market":"SOL/USD","type":"update","data":{"time":1651237317.5425098,"checksum":1920325920,"bids":[[95.795,130.07]],"asks":[[95.965,125.03]],"action":"update"}}
1651237317.6781297: {"channel":"orderbook","market":"WBTC/USD","type":"update","data":{"time":1651237317.548545,"checksum":2326878283,"bids":[[38921.0,0.041],[35386.0,0.0]],"asks":[],"action":"update"}}
1651237317.6960175: {"channel":"orderbook","market":"SOL/USD","type":"update","data":{"time":1651237317.5661476,"checksum":584045082,"bids":[[95.6325,0.0],[95.44,1.0]],"asks":[[95.86,342.26],[95.93,0.69]],"action":"update"}}
1651237317.716186: {"channel":"orderbook","market":"ETH/USDT","type":"update","data":{"time":1651237317.583336,"checksum":1823388844,"bids":[[2859.8,9.039]],"asks":[],"action":"update"}}
1651237317.7336085: {"channel":"orderbook","market":"DAI/USD","type":"update","data":{"time":1651237317.6021364,"checksum":2637841829,"bids":[],"asks":[],"action":"update"}}
1651237317.7336426: {"channel":"orderbook","market":"ETH/USDT","type":"update","data":{"time":1651237317.6040862,"checksum":2328816695,"bids":[],"asks":[[2861.6,17.705]],"action":"update"}}
1651237317.7394: {"channel":"orderbook","market":"ETH/USD","type":"update","data":{"time":1651237317.608779,"checksum":3583749349,"bids":[[2860.3,1.862]],"asks":[[2861.7,14.405]],"action":"update"}}
1651237317.7710896: {"channel":"orderbook","market":"SOL/USD","type":"update","data":{"time":1651237317.627224,"checksum":612849068,"bids":[[95.8425,106.5]],"asks":[[95.86,335.0],[96.045,0.0],[96.33,0.26]],"action":"update"}}
1651237317.7711635: {"channel":"orderbook","market":"ETH/USDT","type":"update","data":{"time":1651237317.6307716,"checksum":3075341734,"bids":[],"asks":[[2861.4,4.438],[2861.5,13.494]],"action":"update"}}
1651237317.7712035: {"channel":"orderbook","market":"ETH/USD","type":"update","data":{"time":1651237317.6337416,"checksum":2641204868,"bids":[],"asks":[[2860.7,7.462],[2861.6,40.354]],"action":"update"}}
1651237317.7716086: {"channel":"orderbook","market":"SOL/USD","type":"update","data":{"time":1651237317.6431904,"checksum":2452520724,"bids":[[95.675,5.45]],"asks":[[95.97,403.19]],"action":"update"}}
1651237317.8158863: {"channel":"orderbook","market":"ETH/USDT","type":"update","data":{"time":1651237317.6820774,"checksum":2435904852,"bids":[],"asks":[[2860.7,0.0],[2860.9,0.161],[2882.9,0.015]],"action":"update"}}
1651237317.8219235: {"channel":"orderbook","market":"ETH/USD","type":"update","data":{"time":1651237317.690977,"checksum":507801454,"bids":[[2860.6,4.059],[2860.3,1.904]],"asks":[[2861.0,10.845],[2867.0,0.011]],"action":"update"}}
1651237317.8364952: {"channel":"orderbook","market":"ETH/USDT","type":"update","data":{"time":1651237317.7051437,"checksum":2971501679,"bids":[],"asks":[[2860.9,0.0],[2883.0,0.029]],"action":"update"}}
1651237317.846329: {"channel":"orderbook","market":"SOL/USD","type":"update","data":{"time":1651237317.7187288,"checksum":3392118878,"bids":[[95.79,2.42]],"asks":[[95.9225,105.29],[95.9675,315.07],[96.33,0.0]],"action":"update"}}
1651237317.8587716: {"channel":"orderbook","market":"ETH/USDT","type":"update","data":{"time":1651237317.730309,"checksum":3342470559,"bids":[[2860.6,7.108]],"asks":[],"action":"update"}}
1651237317.8824372: {"channel":"orderbook","market":"USD/TRY","type":"update","data":{"time":1651237317.7583516,"checksum":2845795420,"bids":[],"asks":[],"action":"update"}}
1651237317.8838208: {"channel":"orderbook","market":"ETH/USDT","type":"update","data":{"time":1651237317.7571917,"checksum":2549214955,"bids":[[2860.8,2.0],[2860.5,7.056],[2858.5,4.223],[2842.7,0.0]],"asks":[[2861.2,2.5],[2861.3,0.0],[2862.5,27.265]],"action":"update"}}
1651237317.8841467: {"channel":"orderbook","market":"ETH/USD","type":"update","data":{"time":1651237317.7575624,"checksum":4201941297,"bids":[[2860.6,7.509]],"asks":[[2860.9,7.454],[2861.1,9.824],[2862.5,22.094]],"action":"update"}}
1651237317.8966649: {"channel":"orderbook","market":"SOL/USD","type":"update","data":{"time":1651237317.7678409,"checksum":476347451,"bids":[[95.6825,26.1],[95.44,0.0]],"asks":[[95.9375,0.0],[96.1775,275.68],[96.33,0.26]],"action":"update"}}
1651237317.9084268: {"channel":"orderbook","market":"ETH/USDT","type":"update","data":{"time":1651237317.781287,"checksum":2006707122,"bids":[[2860.7,2.5],[2842.8,0.0]],"asks":[[2861.2,2.0],[2861.9,10.903],[2883.0,0.0]],"action":"update"}}
1651237317.9206023: {"channel":"orderbook","market":"ETH/USD","type":"update","data":{"time":1651237317.7932553,"checksum":1648929504,"bids":[],"asks":[[2861.0,6.787]],"action":"update"}}
1651237317.9221323: {"channel":"orderbook","market":"SOL/USD","type":"update","data":{"time":1651237317.7918437,"checksum":1701491454,"bids":[],"asks":[[95.8575,36.0],[96.33,0.0]],"action":"update"}}
1651237317.9314718: {"channel":"orderbook","market":"ETH/USDT","type":"update","data":{"time":1651237317.804951,"checksum":4289469654,"bids":[[2860.8,0.0],[2860.6,5.108],[2842.8,0.01]],"asks":[[2861.2,0.0],[2861.6,17.906],[2883.0,0.029]],"action":"update"}}
1651237317.9566991: {"channel":"orderbook","market":"ETH/USD","type":"update","data":{"time":1651237317.8214424,"checksum":2612759035,"bids":[],"asks":[[2862.4,20.307]],"action":"update"}}
1651237317.9567416: {"channel":"orderbook","market":"SOL/USD","type":"update","data":{"time":1651237317.8208544,"checksum":517632536,"bids":[[95.685,193.23]],"asks":[],"action":"update"}}
1651237317.9678974: {"channel":"orderbook","market":"ETH/USDT","type":"update","data":{"time":1651237317.830849,"checksum":4097586185,"bids":[],"asks":[[2860.9,2.0],[2861.2,2.05],[2861.3,2.5],[2861.4,0.0],[2882.9,0.0],[2883.0,0.0]],"action":"update"}}
1651237317.988613: {"channel":"orderbook","market":"ETH/USDT","type":"update","data":{"time":1651237317.8544486,"checksum":581395862,"bids":[],"asks":[[2860.9,0.0],[2861.1,1.361],[2861.3,0.0],[2882.9,0.015]],"action":"update"}}
1651237317.9991684: {"channel":"orderbook","market":"SOL/USD","type":"update","data":{"time":1651237317.8662279,"checksum":3490056560,"bids":[[95.8025,0.0],[95.44,1.0]],"asks":[],"action":"update"}}
1651237318.0047534: {"channel":"orderbook","market":"SHIB/USD","type":"update","data":{"time":1651237317.8753226,"checksum":2231341410,"bids":[[0.00002259,503400000.0]],"asks":[],"action":"update"}}
1651237318.0048995: {"channel":"orderbook","market":"ETH/USDT","type":"update","data":{"time":1651237317.8798816,"checksum":3676408569,"bids":[],"asks":[[2861.1,0.0],[2883.0,0.029]],"action":"update"}}
1651237318.0191317: {"channel":"orderbook","market":"SOL/USD","type":"update","data":{"time":1651237317.8904977,"checksum":3059697039,"bids":[[95.65,275.4]],"asks":[],"action":"update"}}
1651237318.0630925: {"channel":"orderbook","market":"ETH/USDT","type":"update","data":{"time":1651237317.905294,"checksum":2167247259,"bids":[[2860.6,3.058]],"asks":[[2861.2,0.0],[2883.1,0.3]],"action":"update"}}
1651237318.0631495: {"channel":"orderbook","market":"WBTC/USD","type":"update","data":{"time":1651237317.9025233,"checksum":301397845,"bids":[[38921.0,0.0],[35386.0,0.0017]],"asks":[],"action":"update"}}
1651237318.0631852: {"channel":"orderbook","market":"ETH/USD","type":"update","data":{"time":1651237317.910879,"checksum":3863180836,"bids":[],"asks":[[2863.5,147.793]],"action":"update"}}
1651237318.0632164: {"channel":"orderbook","market":"LTC/USDT","type":"update","data":{"time":1651237317.9159715,"checksum":3193710904,"bids":[[100.55,0.0],[96.55,0.23]],"asks":[[100.605,0.0],[103.91,0.02]],"action":"update"}}
1651237318.0632565: {"channel":"orderbook","market":"FTT/BTC","type":"update","data":{"time":1651237317.9157662,"checksum":2247498534,"bids":[[0.0010089,0.0],[0.0009964,8.8]],"asks":[[0.0010095,0.0],[0.0010241,2879.9]],"action":"update"}}
1651237318.0632958: {"channel":"orderbook","market":"ETH/USDT","type":"update","data":{"time":1651237317.931946,"checksum":872388300,"bids":[[2860.8,2.0],[2859.7,18.136],[2842.8,0.0]],"asks":[[2861.0,2.0],[2861.4,6.919],[2883.0,0.0],[2883.1,0.0]],"action":"update"}}
1651237318.063347: {"channel":"orderbook","market":"SOL/USD","type":"update","data":{"time":1651237317.9325135,"checksum":1115416125,"bids":[[95.8425,51.5]],"asks":[[95.86,280.0]],"action":"update"}}
1651237318.0848167: {"channel":"orderbook","market":"FTT/BTC","type":"update","data":{"time":1651237317.9408207,"checksum":2465518274,"bids":[],"asks":[[0.0010108,53.8]],"action":"update"}}
1651237318.084898: {"channel":"orderbook","market":"ETH/USD","type":"update","data":{"time":1651237317.9391544,"checksum":2759274276,"bids":[[2860.6,3.89],[2860.5,0.0],[2849.4,0.04]],"asks":[[2860.7,4.012],[2860.9,4.004],[2861.0,4.498],[2861.2,35.556]],"action":"update"}}
1651237318.084959: {"channel":"orderbook","market":"LTC/USDT","type":"update","data":{"time":1651237317.942963,"checksum":310937828,"bids":[[100.555,0.0],[96.5,0.06]],"asks":[[100.6,0.0],[103.96,0.29]],"action":"update"}}
1651237318.0931673: {"channel":"orderbook","market":"SOL/USD","type":"update","data":{"time":1651237317.9562368,"checksum":1320839552,"bids":[[95.8425,0.0],[95.8375,103.0]],"asks":[[95.8575,43.27],[96.06,137.66],[96.3275,0.0]],"action":"update"}}
1651237318.1028397: {"channel":"orderbook","market":"ETH/USD","type":"update","data":{"time":1651237317.965479,"checksum":3246562911,"bids":[],"asks":[[2861.2,18.256]],"action":"update"}}
1651237318.1028738: {"channel":"orderbook","market":"WBTC/USD","type":"update","data":{"time":1651237317.9746585,"checksum":1530166514,"bids":[],"asks":[[38972.0,0.8239],[39022.0,0.007],[44055.0,0.0],[44095.0,0.0]],"action":"update"}}
1651237318.1118917: {"channel":"orderbook","market":"FTT/BTC","type":"update","data":{"time":1651237317.975524,"checksum":627028379,"bids":[],"asks":[[0.00101,4.5],[0.0010241,0.0]],"action":"update"}}
1651237318.1119256: {"channel":"orderbook","market":"ETH/USDT","type":"update","data":{"time":1651237317.9565568,"checksum":2684878758,"bids":[[2860.8,0.0],[2842.8,0.01]],"asks":[[2861.0,0.0],[2861.1,1.361],[2861.6,11.859]],"action":"update"}}
1651237318.1245446: {"channel":"orderbook","market":"LTC/USDT","type":"update","data":{"time":1651237317.9922009,"checksum":2812153098,"bids":[],"asks":[[100.605,4.44],[103.96,0.0]],"action":"update"}}
1651237318.1324706: {"channel":"orderbook","market":"ETH/USD","type":"update","data":{"time":1651237317.995583,"checksum":2275746869,"bids":[[2855.4,0.361]],"asks":[],"action":"update"}}
1651237318.1362336: {"channel":"orderbook","market":"ETH/USDT","type":"update","data":{"time":1651237318.0069828,"checksum":3613588179,"bids":[[2860.8,2.05],[2859.7,22.145],[2842.8,0.0]],"asks":[[2860.9,0.322],[2861.1,0.0],[2861.4,9.419],[2861.5,10.158]],"action":"update"}}
1651237318.1490998: {"channel":"orderbook","market":"ETH/USDT","type":"update","data":{"time":1651237318.0203946,"checksum":1606212250,"bids":[],"asks":[[2861.4,6.919]],"action":"update"}}
1651237318.1491523: {"channel":"orderbook","market":"ETH/USD","type":"update","data":{"time":1651237318.018302,"checksum":3168372264,"bids":[[2860.6,3.823],[2855.8,7.017]],"asks":[],"action":"update"}}
1651237318.1511226: {"channel":"orderbook","market":"SOL/USD","type":"update","data":{"time":1651237318.0093908,"checksum":3459162372,"bids":[],"asks":[[95.9325,21.77],[95.94,0.03],[96.32,0.0],[96.3225,0.0]],"action":"update"}}
1651237318.1782627: {"channel":"orderbook","market":"LTC/USDT","type":"update","data":{"time":1651237318.041175,"checksum":2467246064,"bids":[[100.48,20.7],[96.5,0.0]],"asks":[],"action":"update"}}
1651237318.1783237: {"channel":"orderbook","market":"BTC/TRY","type":"update","data":{"time":1651237318.0442832,"checksum":2549750460,"bids":[],"asks":[],"action":"update"}}
1651237318.1783528: {"channel":"orderbook","market":"ETH/USDT","type":"update","data":{"time":1651237318.0463393,"checksum":2332446020,"bids":[[2860.8,0.0],[2859.7,27.133],[2842.8,0.01]],"asks":[],"action":"update"}}
1651237318.2025707: {"channel":"orderbook","market":"ETH/USDT","type":"update","data":{"time":1651237318.0706062,"checksum":933177479,"bids":[[2859.7,15.917]],"asks":[[2860.9,2.322],[2861.1,2.5],[2882.9,0.0]],"action":"update"}}
1651237318.20264: {"channel":"orderbook","market":"SHIB/USD","type":"update","data":{"time":1651237318.0742366,"checksum":2998990955,"bids":[[0.00002257,514400000.0]],"asks":[],"action":"update"}}
1651237318.2162514: {"channel":"orderbook","market":"LTC/USDT","type":"update","data":{"time":1651237318.090615,"checksum":3227808901,"bids":[[100.37,48.5]],"asks":[[100.78,0.01]],"action":"update"}}
1651237318.234639: {"channel":"orderbook","market":"ETH/USD","type":"update","data":{"time":1651237318.091536,"checksum":2279482993,"bids":[[2860.3,1.862],[2856.1,1.541]],"asks":[],"action":"update"}}
1651237318.234678: {"channel":"orderbook","market":"ETH/USDT","type":"update","data":{"time":1651237318.0974839,"checksum":2962074203,"bids":[],"asks":[[2860.9,0.322],[2861.1,0.0],[2861.3,2.5]],"action":"update"}}
1651237318.2656457: {"channel":"orderbook","market":"SOL/USD","type":"update","data":{"time":1651237318.1098974,"checksum":2129752095,"bids":[],"asks":[[95.9675,183.21]],"action":"update"}}
1651237318.265695: {"channel":"orderbook","market":"ETH/USDT","type":"update","data":{"time":1651237318.119952,"checksum":1325229948,"bids":[[2859.4,22.048]],"asks":[[2860.8,2.0],[2864.9,23.45],[2882.6,0.0]],"action":"update"}}
1651237318.2657683: {"channel":"orderbook","market":"ETH/USD","type":"update","data":{"time":1651237318.1277342,"checksum":145713672,"bids":[[2860.6,3.798],[2860.3,1.904]],"asks":[],"action":"update"}}
1651237318.2658036: {"channel":"orderbook","market":"SOL/USD","type":"update","data":{"time":1651237318.1321929,"checksum":3535915846,"bids":[],"asks":[[95.9325,0.0],[96.32,0.01]],"action":"update"}}
1651237318.2791746: {"channel":"orderbook","market":"ETH/USDT","type":"update","data":{"time":1651237318.1467078,"checksum":746358495,"bids":[[2859.7,26.96]],"asks":[],"action":"update"}}
1651237318.2976656: {"channel":"orderbook","market":"ETH/USDT","type":"update","data":{"time":1651237318.1699982,"checksum":580740907,"bids":[],"asks":[[2862.4,6.716]],"action":"update"}}
1651237318.3201265: {"channel":"orderbook","market":"LTC/USDT","type":"update","data":{"time":1651237318.1739905,"checksum":4253125557,"bids":[[100.505,8.77]],"asks":[],"action":"update"}}
1651237318.3202035: {"channel":"orderbook","market":"WBTC/USD","type":"update","data":{"time":1651237318.1772416,"checksum":1530166514,"bids":[],"asks":[],"action":"update"}}
1651237318.3428028: {"channel":"orderbook","market":"SOL/USD","type":"update","data":{"time":1651237318.1900313,"checksum":2117347341,"bids":[],"asks":[[96.0075,131.86],[96.32,0.0]],"action":"update"}}
1651237318.3428705: {"channel":"orderbook","market":"ETH/USD","type":"update","data":{"time":1651237318.1989152,"checksum":774821692,"bids":[[2860.6,4.115],[2859.6,9.698]],"asks":[[2860.7,4.497],[2860.8,0.162],[2873.6,0.0]],"action":"update"}}
1651237318.342933: {"channel":"orderbook","market":"ETH/USDT","type":"update","data":{"time":1651237318.1984758,"checksum":1411594660,"bids":[[2859.9,0.043]],"asks":[[2861.4,9.458]],"action":"update"}}
1651237318.3573344: {"channel":"orderbook","market":"WBTC/USD","type":"update","data":{"time":1651237318.2294924,"checksum":2371189051,"bids":[[38907.0,0.0107],[35386.0,0.0]],"asks":[],"action":"update"}}
1651237318.3715158: {"channel":"orderbook","market":"SOL/USD","type":"update","data":{"time":1651237318.233425,"checksum":1886520821,"bids":[],"asks":[[95.94,0.0],[96.32,0.01]],"action":"update"}}
1651237318.3878212: {"channel":"orderbook","market":"ETH/USDT","type":"update","data":{"time":1651237318.2507958,"checksum":1964595293,"bids":[[2860.0,5.892]],"asks":[],"action":"update"}}
1651237318.387859: {"channel":"orderbook","market":"ETH/USD","type":"update","data":{"time":1651237318.249994,"checksum":3777445033,"bids":[[2860.0,21.731]],"asks":[[2863.5,147.873]],"action":"update"}}
1651237318.3930123: {"channel":"orderbook","market":"WBTC/USD","type":"update","data":{"time":1651237318.2519352,"checksum":185899431,"bids":[[38901.0,0.0],[35386.0,0.0017]],"asks":[],"action":"update"}}
1651237318.4140959: {"channel":"orderbook","market":"ETH/USD","type":"update","data":{"time":1651237318.2857304,"checksum":2183269476,"bids":[],"asks":[[2861.1,8.076]],"action":"update"}}
1651237318.4600842: {"channel":"orderbook","market":"ETH/USD","type":"update","data":{"time":1651237318.3248024,"checksum":3326574684,"bids":[[2857.7,0.0],[2849.3,0.041]],"asks":[[2861.6,43.85],[2867.5,0.174]],"action":"update"}}
1651237318.5212717: {"channel":"orderbook","market":"ETH/USD","type":"update","data":{"time":1651237318.3745027,"checksum":3228322212,"bids":[],"asks":[[2860.7,4.012]],"action":"update"}}
1651237318.521349: {"channel":"orderbook","market":"SOL/USD","type":"update","data":{"time":1651237318.3884606,"checksum":2439505301,"bids":[],"asks":[[95.8575,29.92]],"action":"update"}}
1651237318.5280993: {"channel":"orderbook","market":"ETH/USD","type":"update","data":{"time":1651237318.3999348,"checksum":4173708058,"bids":[[2860.0,18.235],[2858.5,2.128]],"asks":[[2860.7,2.112],[2860.8,0.0],[2860.9,0.007],[2862.5,2.358],[2873.6,4.007]],"action":"update"}}
1651237318.544059: {"channel":"orderbook","market":"ETH/USDT","type":"update","data":{"time":1651237318.3960466,"checksum":2506552453,"bids":[[2860.0,2.396]],"asks":[[2860.8,0.0],[2860.9,0.0],[2862.5,8.01],[2882.6,0.1],[2882.9,0.015]],"action":"update"}}
1651237318.5455232: {"channel":"orderbook","market":"SOL/USD","type":"update","data":{"time":1651237318.4100335,"checksum":478602015,"bids":[],"asks":[[95.8575,22.65],[95.8625,0.0],[95.865,0.0],[95.8725,0.0],[96.3225,0.62],[96.3275,0.01],[96.33,0.26]],"action":"update"}}
1651237318.562693: {"channel":"orderbook","market":"ETH/USD","type":"update","data":{"time":1651237318.4253554,"checksum":1691816613,"bids":[[2860.3,17.759]],"asks":[[2860.7,0.012],[2862.4,14.778]],"action":"update"}}
1651237318.58866: {"channel":"orderbook","market":"SOL/USD","type":"update","data":{"time":1651237318.4362087,"checksum":1853702458,"bids":[[95.6825,0.0],[95.4375,0.01]],"asks":[],"action":"update"}}
1651237318.5887084: {"channel":"orderbook","market":"ETH/USD","type":"update","data":{"time":1651237318.4514139,"checksum":4170773524,"bids":[[2860.6,18.241],[2860.4,14.245],[2859.3,20.495],[2849.3,0.0]],"asks":[[2861.0,3.753],[2861.1,0.0],[2864.3,0.0],[2873.7,0.001],[2873.9,0.001]],"action":"update"}}
1651237318.588762: {"channel":"orderbook","market":"SHIB/USD","type":"update","data":{"time":1651237318.4493508,"checksum":2998990955,"bids":[],"asks":[],"action":"update"}}
1651237318.5887833: {"channel":"orderbook","market":"ETH/USDT","type":"update","data":{"time":1651237318.449831,"checksum":2213843128,"bids":[[2860.7,17.22],[2860.4,40.201],[2859.7,15.917]],"asks":[[2861.7,0.33],[2861.8,0.0],[2883.0,0.029]],"action":"update"}}
1651237318.6080904: {"channel":"orderbook","market":"SOL/USD","type":"update","data":{"time":1651237318.4613385,"checksum":2582733784,"bids":[[95.84,36.0],[95.8375,0.0]],"asks":[],"action":"update"}}
1651237318.608153: {"channel":"orderbook","market":"ETH/USDT","type":"update","data":{"time":1651237318.4728868,"checksum":1234029611,"bids":[[2860.7,19.22],[2860.6,18.455]],"asks":[[2861.2,1.361],[2861.6,6.018],[2862.2,0.175],[2862.8,4.37],[2883.0,0.0]],"action":"update"}}
1651237318.6082158: {"channel":"orderbook","market":"ETH/USD","type":"update","data":{"time":1651237318.4784498,"checksum":1906661880,"bids":[[2860.6,22.141],[2860.4,19.655],[2858.6,3.125]],"asks":[[2861.0,0.002],[2861.1,6.353],[2864.4,0.0]],"action":"update"}}
1651237318.643155: {"channel":"orderbook","market":"SOL/USD","type":"update","data":{"time":1651237318.4899666,"checksum":1862647073,"bids":[[95.835,51.5],[95.4375,0.0]],"asks":[[95.8725,96.9],[95.88,128.64],[96.3275,0.0],[96.33,0.0]],"action":"update"}}
1651237318.6432335: {"channel":"orderbook","market":"ETH/USD","type":"update","data":{"time":1651237318.5016088,"checksum":3684526301,"bids":[[2860.6,26.141],[2859.8,0.0],[2858.6,0.0],[2849.3,0.041],[2849.1,4.545]],"asks":[[2861.1,3.997],[2861.4,3.493],[2861.7,11.28]],"action":"update"}}
1651237318.643311: {"channel":"orderbook","market":"ETH/USDT","type":"update","data":{"time":1651237318.5067704,"checksum":203869229,"bids":[[2860.7,2.5],[2860.4,16.518],[2859.8,5.543],[2858.8,3.015]],"asks":[[2861.2,0.0],[2861.4,2.539],[2861.5,5.726],[2883.0,0.029]],"action":"update"}}
1651237318.657256: {"channel":"orderbook","market":"ETH/USDT","type":"update","data":{"time":1651237318.5204406,"checksum":2478140776,"bids":[[2860.8,4.806],[2860.2,0.187],[2842.8,0.0]],"asks":[],"action":"update"}}
1651237318.6634564: {"channel":"orderbook","market":"ETH/USD","type":"update","data":{"time":1651237318.525328,"checksum":3897489781,"bids":[[2860.6,12.015]],"asks":[[2861.2,22.007],[2862.7,27.476],[2865.7,10.924],[2873.9,0.0]],"action":"update"}}
1651237318.6635213: {"channel":"orderbook","market":"SHIB/USD","type":"update","data":{"time":1651237318.5246449,"checksum":3573234893,"bids":[[0.00002207,500000.0]],"asks":[],"action":"update"}}
1651237318.6635592: {"channel":"orderbook","market":"WBTC/USD","type":"update","data":{"time":1651237318.5328114,"checksum":2722195582,"bids":[],"asks":[[38972.0,0.0],[44055.0,0.0006]],"action":"update"}}
1651237318.6734478: {"channel":"orderbook","market":"ETH/USDT","type":"update","data":{"time":1651237318.5470076,"checksum":2639359083,"bids":[[2860.8,0.0],[2860.6,3.058],[2859.3,2.354]],"asks":[[2862.6,19.767],[2883.0,0.0]],"action":"update"}}
1651237318.6735494: {"channel":"orderbook","market":"SOL/USD","type":"update","data":{"time":1651237318.5411644,"checksum":4184671265,"bids":[],"asks":[[95.8575,21.69]],"action":"update"}}
1651237318.6799161: {"channel":"orderbook","market":"ETH/USD","type":"update","data":{"time":1651237318.549723,"checksum":720473183,"bids":[[2859.2,0.254],[2856.6,1.758]],"asks":[[2869.1,2.338]],"action":"update"}}
1651237318.7053158: {"channel":"orderbook","market":"SOL/USD","type":"update","data":{"time":1651237318.5689802,"checksum":2189583650,"bids":[[95.6825,26.1],[95.44,0.0]],"asks":[],"action":"update"}}
1651237318.7053773: {"channel":"orderbook","market":"ETH/USDT","type":"update","data":{"time":1651237318.5723715,"checksum":451485589,"bids":[[2861.1,2.0],[2860.7,0.0],[2860.6,4.806],[2859.7,11.908],[2854.5,15.267]],"asks":[],"action":"update"}}
1651237318.714062: {"channel":"orderbook","market":"ETH/USD","type":"update","data":{"time":1651237318.5753477,"checksum":761444161,"bids":[[2860.5,2.023],[2860.3,17.756],[2854.3,0.489],[2854.0,13.061],[2849.1,0.0]],"asks":[[2861.9,6.133],[2862.2,3.496],[2862.6,6.87],[2873.6,0.0],[2873.7,0.0]],"action":"update"}}
1651237318.7261176: {"channel":"orderbook","market":"ETH/USDT","type":"update","data":{"time":1651237318.597701,"checksum":3781618065,"bids":[[2861.1,0.0],[2860.9,2.5],[2860.1,9.659]],"asks":[[2861.8,2.727],[2882.9,0.0]],"action":"update"}}
1651237318.7316113: {"channel":"orderbook","market":"LTC/USDT","type":"update","data":{"time":1651237318.600969,"checksum":2391315389,"bids":[[100.505,9.11]],"asks":[[100.61,12.0],[100.675,0.34],[103.84,0.0],[103.91,0.0]],"action":"update"}}
1651237318.7470496: {"channel":"orderbook","market":"ETH/USD","type":"update","data":{"time":1651237318.6133409,"checksum":53775111,"bids":[[2860.6,24.479],[2860.4,19.658],[2860.3,21.252],[2860.2,0.252],[2858.8,9.19]],"asks":[[2861.5,11.32],[2861.7,7.784],[2863.1,0.002],[2863.2,29.118],[2864.5,1.924]],"action":"update"}}
1651237318.7520387: {"channel":"orderbook","market":"ETH/USDT","type":"update","data":{"time":1651237318.6217895,"checksum":3486002071,"bids":[[2860.9,0.0],[2860.7,2.5],[2860.4,4.529],[2859.7,15.917]],"asks":[[2861.6,0.201]],"action":"update"}}
1651237318.7676384: {"channel":"orderbook","market":"DAI/USD","type":"update","data":{"time":1651237318.6297114,"checksum":2637841829,"bids":[],"asks":[],"action":"update"}}
1651237318.7738688: {"channel":"orderbook","market":"ETH/USD","type":"update","data":{"time":1651237318.6345375,"checksum":3173049443,"bids":[[2860.6,28.23],[2855.0,9.207]],"asks":[[2861.5,29.918]],"action":"update"}}
1651237318.8053372: {"channel":"orderbook","market":"SOL/USD","type":"update","data":{"time":1651237318.647726,"checksum":286430569,"bids":[[95.81,52.68],[95.4475,0.0]],"asks":[],"action":"update"}}
1651237318.8054197: {"channel":"orderbook","market":"ETH/USDT","type":"update","data":{"time":1651237318.649604,"checksum":2679628067,"bids":[[2861.2,0.533],[2860.5,0.0],[2859.7,26.96],[2855.9,10.927]],"asks":[[2861.3,2.661],[2861.9,11.195]],"action":"update"}}
1651237318.80551: {"channel":"orderbook","market":"ETH/USD","type":"update","data":{"time":1651237318.6576378,"checksum":3510196236,"bids":[[2860.6,28.203]],"asks":[[2863.0,0.183],[2867.5,6.174]],"action":"update"}}
1651237318.8055542: {"channel":"orderbook","market":"ETH/USDT","type":"update","data":{"time":1651237318.6720657,"checksum":1087827827,"bids":[[2860.6,1.977]],"asks":[[2861.3,2.822],[2862.9,0.906],[2882.6,0.0]],"action":"update"}}
1651237318.8283896: {"channel":"orderbook","market":"ETH/USD","type":"update","data":{"time":1651237318.6822104,"checksum":3808112061,"bids":[[2855.7,10.93]],"asks":[[2861.4,10.975],[2862.0,10.256],[2862.5,0.085],[2863.1,7.283]],"action":"update"}}
1651237318.8284428: {"channel":"orderbook","market":"ETH/USDT","type":"update","data":{"time":1651237318.696578,"checksum":2832361861,"bids":[[2861.2,2.533],[2860.4,0.0],[2859.7,20.04],[2842.8,0.01]],"asks":[[2862.6,23.696]],"action":"update"}}
1651237318.8284793: {"channel":"orderbook","market":"SOL/USD","type":"update","data":{"time":1651237318.6954381,"checksum":1988420818,"bids":[[95.8275,49.0]],"asks":[],"action":"update"}}
1651237318.8359714: {"channel":"orderbook","market":"ETH/USD","type":"update","data":{"time":1651237318.7092223,"checksum":1217657682,"bids":[[2860.3,21.21],[2859.3,25.595]],"asks":[[2863.3,7.402]],"action":"update"}}
1651237318.8468435: {"channel":"orderbook","market":"ETH/USDT","type":"update","data":{"time":1651237318.7207174,"checksum":476665412,"bids":[[2860.7,7.029],[2858.7,0.0],[2842.7,0.018]],"asks":[],"action":"update"}}
1651237318.876122: {"channel":"orderbook","market":"ETH/USDT","type":"update","data":{"time":1651237318.7459583,"checksum":3917591653,"bids":[[2861.2,2.0],[2860.1,3.496],[2858.8,0.0],[2842.5,835.588]],"asks":[],"action":"update"}}
1651237318.876219: {"channel":"orderbook","market":"ETH/USD","type":"update","data":{"time":1651237318.7482057,"checksum":524561025,"bids":[[2860.4,19.7],[2860.3,5.355],[2858.8,6.065]],"asks":[[2861.3,2.936],[2861.7,7.435]],"action":"update"}}
1651237318.9017277: {"channel":"orderbook","market":"ETH/USDT","type":"update","data":{"time":1651237318.771137,"checksum":1483271276,"bids":[[2860.2,7.18]],"asks":[],"action":"update"}}
1651237318.904625: {"channel":"orderbook","market":"USD/TRY","type":"update","data":{"time":1651237318.779317,"checksum":2845795420,"bids":[],"asks":[],"action":"update"}}
1651237318.9198308: {"channel":"orderbook","market":"ETH/USD","type":"update","data":{"time":1651237318.7851117,"checksum":3224140330,"bids":[[2860.6,28.238],[2860.3,3.496]],"asks":[[2861.5,29.569]],"action":"update"}}
1651237318.9238155: {"channel":"orderbook","market":"ETH/USDT","type":"update","data":{"time":1651237318.7970812,"checksum":2369240871,"bids":[[2860.8,15.27],[2842.5,0.0]],"asks":[[2863.2,0.73],[2882.5,0.0]],"action":"update"}}
1651237318.9244413: {"channel":"orderbook","market":"SOL/USD","type":"update","data":{"time":1651237318.7978358,"checksum":3218292347,"bids":[],"asks":[[95.8575,12.15]],"action":"update"}}
1651237318.9405155: {"channel":"orderbook","market":"ETH/USD","type":"update","data":{"time":1651237318.8109095,"checksum":4189325649,"bids":[[2859.0,5.009],[2858.2,13.848]],"asks":[[2862.0,10.605],[2862.4,14.429]],"action":"update"}}
1651237318.9576519: {"channel":"orderbook","market":"WBTC/USD","type":"update","data":{"time":1651237318.830913,"checksum":3825775948,"bids":[],"asks":[[39219.0,0.0],[44095.0,0.0005]],"action":"update"}}
1651237318.9619179: {"channel":"orderbook","market":"ETH/USD","type":"update","data":{"time":1651237318.8347454,"checksum":3016939960,"bids":[[2859.9,26.193],[2859.3,10.494],[2858.2,12.072]],"asks":[[2861.6,44.85],[2862.0,7.109]],"action":"update"}}
1651237318.9874218: {"channel":"orderbook","market":"SOL/USD","type":"update","data":{"time":1651237318.8474593,"checksum":913973495,"bids":[[95.6825,0.0],[95.4475,0.03]],"asks":[],"action":"update"}}
1651237318.9875004: {"channel":"orderbook","market":"ETH/USD","type":"update","data":{"time":1651237318.861356,"checksum":1438963661,"bids":[[2859.4,0.0],[2849.1,0.004]],"asks":[],"action":"update"}}
1651237319.032449: {"channel":"orderbook","market":"USD/TRY","type":"update","data":{"time":1651237318.9024336,"checksum":2677111741,"bids":[],"asks":[[15.8807,2096.0]],"action":"update"}}
1651237319.0446966: {"channel":"orderbook","market":"ETH/USD","type":"update","data":{"time":1651237318.9118116,"checksum":2499280094,"bids":[[2858.8,7.83],[2850.2,4.671]],"asks":[[2861.8,12.98],[2862.6,7.219],[2863.7,2.128],[2863.8,0.01]],"action":"update"}}
1651237319.0718446: {"channel":"orderbook","market":"FTT/BTC","type":"update","data":{"time":1651237318.942335,"checksum":627028379,"bids":[],"asks":[],"action":"update"}}
1651237319.072028: {"channel":"orderbook","market":"SOL/USD","type":"update","data":{"time":1651237318.945975,"checksum":1491704848,"bids":[[95.8375,103.0],[95.835,0.0]],"asks":[[95.9425,61.33]],"action":"update"}}
1651237319.1110961: {"channel":"orderbook","market":"ETH/USD","type":"update","data":{"time":1651237318.975824,"checksum":1715789284,"bids":[[2859.4,26.177],[2855.0,3.207],[2849.1,0.0]],"asks":[[2867.5,0.174]],"action":"update"}}
1651237319.1195865: {"channel":"orderbook","market":"SOL/USD","type":"update","data":{"time":1651237318.9847376,"checksum":341183779,"bids":[[95.685,219.33]],"asks":[[95.8575,6.18]],"action":"update"}}
1651237319.1221032: {"channel":"orderbook","market":"ETH/USDT","type":"update","data":{"time":1651237318.9961033,"checksum":1519114667,"bids":[[2859.7,16.031]],"asks":[],"action":"update"}}
1651237319.1528037: {"channel":"orderbook","market":"ETH/USDT","type":"update","data":{"time":1651237319.0211642,"checksum":271407641,"bids":[],"asks":[[2861.4,0.0],[2862.7,4.203],[2882.5,0.01]],"action":"update"}}
1651237319.152866: {"channel":"orderbook","market":"ETH/USD","type":"update","data":{"time":1651237319.0232809,"checksum":3385038140,"bids":[],"asks":[[2861.3,0.189],[2861.7,5.876],[2862.6,6.87],[2867.3,3.041]],"action":"update"}}
1651237319.156848: {"channel":"orderbook","market":"SOL/USD","type":"update","data":{"time":1651237319.0274858,"checksum":2155120486,"bids":[[95.8225,70.0]],"asks":[],"action":"update"}}
1651237319.1828895: {"channel":"orderbook","market":"ETH/USD","type":"update","data":{"time":1651237319.0394633,"checksum":3856603869,"bids":[[2859.1,8.106],[2857.3,3.344]],"asks":[[2861.2,18.256],[2861.8,11.207],[2862.4,12.388],[2869.6,37.492]],"action":"update"}}
1651237319.1830037: {"channel":"orderbook","market":"SOL/USD","type":"update","data":{"time":1651237319.0431142,"checksum":2559919967,"bids":[[95.84,40.65]],"asks":[],"action":"update"}}
1651237319.1830692: {"channel":"orderbook","market":"ETH/USDT","type":"update","data":{"time":1651237319.047464,"checksum":1648368948,"bids":[[2860.9,3.82],[2842.7,0.0]],"asks":[[2861.3,0.0],[2882.6,0.1]],"action":"update"}}
1651237319.1831229: {"channel":"orderbook","market":"WBTC/USD","type":"update","data":{"time":1651237319.049628,"checksum":3689465497,"bids":[],"asks":[[39217.0,0.0009],[44095.0,0.0]],"action":"update"}}
1651237319.194326: {"channel":"orderbook","market":"BTC/TRY","type":"update","data":{"time":1651237319.068168,"checksum":2549750460,"bids":[],"asks":[],"action":"update"}}
1651237319.2036924: {"channel":"orderbook","market":"ETH/USDT","type":"update","data":{"time":1651237319.072813,"checksum":1112444371,"bids":[[2860.6,1.748],[2859.7,20.04]],"asks":[[2861.4,2.5],[2861.5,4.529],[2862.8,0.0],[2864.9,10.924]],"action":"update"}}
1651237319.2067747: {"channel":"orderbook","market":"ETH/USD","type":"update","data":{"time":1651237319.0719922,"checksum":1876957373,"bids":[[2859.7,15.307],[2858.2,0.001],[2858.0,14.097],[2857.3,3.336],[2857.1,13.551],[2849.3,0.0]],"asks":[[2860.9,0.004],[2862.3,0.001],[2862.7,23.922],[2864.0,2.452],[2867.7,2.057]],"action":"update"}}
1651237319.2231996: {"channel":"orderbook","market":"ETH/USD","type":"update","data":{"time":1651237319.0942457,"checksum":1772619873,"bids":[[2860.7,4.988],[2860.1,4.558],[2857.3,1.559],[2849.4,0.0]],"asks":[[2860.7,0.0],[2861.0,0.005],[2861.6,41.354],[2862.3,1.774],[2862.7,19.552],[2873.6,4.007]],"action":"update"}}
1651237319.2315776: {"channel":"orderbook","market":"ETH/USDT","type":"update","data":{"time":1651237319.0982273,"checksum":4214707490,"bids":[[2861.2,0.0],[2860.9,19.12],[2860.1,0.0],[2860.0,2.298],[2859.9,0.0],[2842.7,0.018],[2842.5,835.588],[2842.2,0.001]],"asks":[[2861.4,0.0],[2861.7,0.189],[2862.5,13.938],[2882.9,0.015]],"action":"update"}}
1651237319.2387557: {"channel":"orderbook","market":"SHIB/USD","type":"update","data":{"time":1651237319.1051612,"checksum":2295124359,"bids":[[0.00002258,187800000.0]],"asks":[[0.00002263,304000000.0],[0.00002266,186200000.0]],"action":"update"}}
1651237319.2536027: {"channel":"orderbook","market":"ETH/USDT","type":"update","data":{"time":1651237319.120741,"checksum":3512814455,"bids":[[2861.0,0.322],[2842.2,0.0]],"asks":[[2861.4,1.361],[2861.6,0.0]],"action":"update"}}
1651237319.253703: {"channel":"orderbook","market":"ETH/USD","type":"update","data":{"time":1651237319.1189773,"checksum":1690919975,"bids":[[2860.6,24.452],[2860.4,17.949],[2855.0,0.172]],"asks":[[2860.9,0.0],[2861.0,0.0],[2861.3,0.001],[2861.4,3.493],[2861.6,40.354],[2863.1,43.614],[2873.7,0.001],[2873.9,0.001]],"action":"update"}}
1651237319.2537668: {"channel":"orderbook","market":"SOL/USD","type":"update","data":{"time":1651237319.1171756,"checksum":1039417278,"bids":[[95.8425,280.0],[95.8175,51.29],[95.7825,106.76],[95.685,193.23],[95.4475,0.0]],"asks":[[95.8575,0.0],[96.3275,0.01]],"action":"update"}}
1651237319.2628477: {"channel":"orderbook","market":"SHIB/USD","type":"update","data":{"time":1651237319.124744,"checksum":188032645,"bids":[],"asks":[[0.00002262,18000000.0],[0.00002263,278900000.0],[0.00002264,372900000.0]],"action":"update"}}
1651237319.2802083: {"channel":"orderbook","market":"SOL/USD","type":"update","data":{"time":1651237319.1397614,"checksum":499209146,"bids":[],"asks":[[95.9675,117.34]],"action":"update"}}
1651237319.2802598: {"channel":"orderbook","market":"ETH/USDT","type":"update","data":{"time":1651237319.1470504,"checksum":3598487570,"bids":[[2861.4,2.0],[2860.9,20.868],[2860.8,0.0],[2860.7,4.529],[2860.4,0.098],[2842.5,0.0]],"asks":[[2861.4,0.0],[2861.5,7.029],[2861.9,10.903],[2863.5,5.099],[2865.0,12.582],[2883.0,0.029]],"action":"update"}}
1651237319.2928882: {"channel":"orderbook","market":"SHIB/USD","type":"update","data":{"time":1651237319.153518,"checksum":1489728089,"bids":[[0.00002261,152200000.0],[0.00002257,526900000.0]],"asks":[[0.00002262,0.0],[0.00002263,253200000.0],[0.00002265,280900000.0],[0.00002266,208400000.0],[0.00002375,2600000.0]],"action":"update"}}
1651237319.2929728: {"channel":"orderbook","market":"ETH/USD","type":"update","data":{"time":1651237319.1609418,"checksum":665884762,"bids":[[2860.7,9.258],[2860.6,15.957],[2860.4,3.704],[2860.3,0.0],[2859.3,5.394],[2858.7,0.0],[2849.4,0.04],[2849.3,0.041]],"asks":[[2861.1,0.0],[2861.5,1.3],[2862.0,6.76],[2862.7,19.901],[2863.2,3.682],[2863.3,11.772],[2863.4,35.091],[2864.5,1.575],[2874.0,2.281]],"action":"update"}}
1651237319.29566: {"channel":"orderbook","market":"SOL/USD","type":"update","data":{"time":1651237319.1691866,"checksum":3570667294,"bids":[[95.84,36.0]],"asks":[],"action":"update"}}
1651237319.3049517: {"channel":"orderbook","market":"ETH/USDT","type":"update","data":{"time":1651237319.1729124,"checksum":1356172802,"bids":[[2860.6,0.0],[2842.5,835.588]],"asks":[[2861.5,2.5],[2861.7,1.386],[2862.7,2.877]],"action":"update"}}
1651237319.32005: {"channel":"orderbook","market":"WBTC/USD","type":"update","data":{"time":1651237319.189235,"checksum":3689465497,"bids":[],"asks":[],"action":"update"}}
1651237319.3277283: {"channel":"orderbook","market":"ETH/USDT","type":"update","data":{"time":1651237319.1960106,"checksum":1010631679,"bids":[[2861.4,3.762],[2861.1,12.335],[2842.5,0.0]],"asks":[],"action":"update"}}
1651237319.3277726: {"channel":"orderbook","market":"ETH/USD","type":"update","data":{"time":1651237319.1908066,"checksum":1560076526,"bids":[[2860.8,31.204],[2860.7,12.025],[2860.1,4.6],[2849.3,0.0]],"asks":[[2861.2,4.236],[2862.5,3.58],[2862.9,2.273],[2863.5,147.793],[2874.0,0.0]],"action":"update"}}
1651237319.3340576: {"channel":"orderbook","market":"SHIB/USD","type":"update","data":{"time":1651237319.2014768,"checksum":3047151292,"bids":[[0.00002261,174400000.0],[0.0000226,141100000.0],[0.00002257,514400000.0]],"asks":[[0.00002263,213800000.0]],"action":"update"}}
1651237319.3394358: {"channel":"orderbook","market":"ETH/USD","type":"update","data":{"time":1651237319.211892,"checksum":294326384,"bids":[[2860.8,29.304]],"asks":[[2861.9,3.008],[2862.3,0.001],[2863.0,11.093]],"action":"update"}}
1651237319.348042: {"channel":"orderbook","market":"ETH/USDT","type":"update","data":{"time":1651237319.221321,"checksum":695873062,"bids":[[2860.7,0.189],[2860.4,6.229]],"asks":[[2861.5,0.0],[2861.9,0.0],[2864.9,0.0],[2883.1,0.3],[2883.5,0.032],[2883.6,0.001]],"action":"update"}}
1651237319.3506851: {"channel":"orderbook","market":"WBTC/USD","type":"update","data":{"time":1651237319.2245007,"checksum":1390530922,"bids":[[38905.0,0.0],[35385.0,0.0001]],"asks":[],"action":"update"}}
1651237319.3548717: {"channel":"orderbook","market":"SHIB/USD","type":"update","data":{"time":1651237319.225884,"checksum":108467975,"bids":[],"asks":[[0.00002265,380800000.0]],"action":"update"}}
1651237319.3653486: {"channel":"orderbook","market":"ETH/USD","type":"update","data":{"time":1651237319.2371569,"checksum":3501187854,"bids":[[2860.8,25.304],[2860.6,19.452],[2860.5,0.0],[2860.4,3.662],[2859.9,19.532],[2857.5,0.008]],"asks":[[2861.4,3.997],[2861.5,0.0],[2861.7,0.215],[2861.9,6.504],[2874.0,2.281]],"action":"update"}}
1651237319.370238: {"channel":"orderbook","market":"LTC/USDT","type":"update","data":{"time":1651237319.2419705,"checksum":1640758145,"bids":[[100.42,20.77]],"asks":[],"action":"update"}}
1651237319.3702862: {"channel":"orderbook","market":"SOL/USD","type":"update","data":{"time":1651237319.2375846,"checksum":3484306734,"bids":[],"asks":[[95.965,62.64]],"action":"update"}}
1651237319.3772635: {"channel":"orderbook","market":"ETH/USDT","type":"update","data":{"time":1651237319.2474494,"checksum":1117298360,"bids":[[2861.4,1.762],[2861.0,2.822]],"asks":[[2861.7,1.197],[2862.0,19.231],[2862.1,0.098],[2883.6,0.0]],"action":"update"}}
1651237319.3773508: {"channel":"orderbook","market":"WBTC/USD","type":"update","data":{"time":1651237319.251806,"checksum":3760889579,"bids":[[38597.0,0.0],[35275.0,0.0001]],"asks":[],"action":"update"}}
1651237319.3816075: {"channel":"orderbook","market":"SHIB/USD","type":"update","data":{"time":1651237319.251125,"checksum":10603193,"bids":[[0.00002261,192400000.0]],"asks":[[0.00002265,480700000.0]],"action":"update"}}
1651237319.3932571: {"channel":"orderbook","market":"ETH/USD","type":"update","data":{"time":1651237319.2652376,"checksum":2214699389,"bids":[[2861.0,3.9],[2860.8,27.072],[2849.4,0.0]],"asks":[[2861.4,0.0],[2862.3,1.909],[2863.7,26.789],[2864.6,0.659],[2867.6,10.024],[2874.1,472.803]],"action":"update"}}
1651237319.411669: {"channel":"orderbook","market":"ETH/USDT","type":"update","data":{"time":1651237319.2741659,"checksum":2730657134,"bids":[[2860.4,9.725],[2859.6,0.0],[2842.5,835.588]],"asks":[[2861.6,9.419],[2865.0,0.056],[2883.5,0.0]],"action":"update"}}
1651237319.4117246: {"channel":"orderbook","market":"SOL/USD","type":"update","data":{"time":1651237319.2697778,"checksum":3550808063,"bids":[[95.6875,119.91]],"asks":[[95.97,469.08]],"action":"update"}}
1651237319.4117537: {"channel":"orderbook","market":"SHIB/USD","type":"update","data":{"time":1651237319.2751682,"checksum":2098478724,"bids":[[0.00002257,471900000.0]],"asks":[],"action":"update"}}
1651237319.4225104: {"channel":"orderbook","market":"ETH/USD","type":"update","data":{"time":1651237319.288786,"checksum":4210021283,"bids":[[2861.0,0.0],[2860.8,23.558],[2860.7,14.545],[2860.2,10.27],[2859.4,2.273],[2849.4,0.04]],"asks":[[2861.2,0.0],[2861.9,3.008],[2874.2,0.146]],"action":"update"}}
1651237319.4275792: {"channel":"orderbook","market":"ETH/USDT","type":"update","data":{"time":1651237319.2967918,"checksum":15659874,"bids":[[2861.0,4.917],[2860.9,5.568],[2858.2,0.182]],"asks":[[2861.6,2.5]],"action":"update"}}
1651237319.445896: {"channel":"orderbook","market":"ETH/USD","type":"update","data":{"time":1651237319.3131971,"checksum":915469521,"bids":[[2861.1,5.842],[2861.0,4.383],[2860.8,25.88],[2860.6,3.493],[2857.6,0.374],[2849.5,0.0],[2849.4,0.0]],"asks":[[2861.8,10.858],[2862.7,19.552],[2862.9,4.046],[2863.1,7.283]],"action":"update"}}
1651237319.45224: {"channel":"orderbook","market":"ETH/USDT","type":"update","data":{"time":1651237319.321748,"checksum":4259893996,"bids":[[2861.1,0.0],[2861.0,2.417],[2859.7,15.052],[2842.2,0.001]],"asks":[[2861.9,4.529],[2862.7,0.523],[2866.3,10.924],[2883.0,0.0],[2883.1,0.0]],"action":"update"}}
1651237319.473207: {"channel":"orderbook","market":"SHIB/USD","type":"update","data":{"time":1651237319.337614,"checksum":2223255949,"bids":[],"asks":[[0.00002264,415800000.0]],"action":"update"}}
1651237319.4732418: {"channel":"orderbook","market":"ETH/USD","type":"update","data":{"time":1651237319.337972,"checksum":396659807,"bids":[[2861.1,3.746],[2861.0,4.637],[2860.9,3.751],[2860.7,10.247],[2860.4,0.0],[2860.0,13.654],[2859.9,0.001],[2854.5,0.221]],"asks":[[2861.6,33.287],[2861.7,0.0],[2862.2,6.621],[2863.8,3.564],[2864.6,0.31],[2874.3,0.235]],"action":"update"}}
1651237319.4732869: {"channel":"orderbook","market":"LTC/USDT","type":"update","data":{"time":1651237319.3431509,"checksum":2152562236,"bids":[],"asks":[[100.645,4.96],[103.79,0.0]],"action":"update"}}
1651237319.4907994: {"channel":"orderbook","market":"ETH/USDT","type":"update","data":{"time":1651237319.357603,"checksum":3960262252,"bids":[[2861.4,0.858],[2861.0,0.322],[2860.9,1.748],[2860.4,6.229]],"asks":[[2861.8,0.0],[2862.5,5.938],[2883.0,0.029]],"action":"update"}}
1651237319.4954221: {"channel":"orderbook","market":"ETH/USD","type":"update","data":{"time":1651237319.363533,"checksum":2729244506,"bids":[[2861.2,5.239],[2861.1,9.139],[2861.0,6.13],[2860.9,3.786],[2860.7,7.48],[2860.0,7.353],[2859.5,9.616],[2859.3,17.465],[2859.1,1.128],[2859.0,4.66],[2858.1,4.563],[2849.6,0.0]],"asks":[[2861.6,9.541],[2861.8,3.493],[2863.0,0.001],[2863.1,0.002],[2863.5,147.878]],"action":"update"}}
1651237319.5047207: {"channel":"orderbook","market":"ETH/USDT","type":"update","data":{"time":1651237319.37434,"checksum":1307806782,"bids":[[2861.1,4.529],[2860.2,26.733],[2842.2,0.0]],"asks":[[2862.0,1.963],[2863.2,0.0],[2883.1,0.3]],"action":"update"}}
1651237319.5206072: {"channel":"orderbook","market":"WBTC/USD","type":"update","data":{"time":1651237319.3795178,"checksum":4250360541,"bids":[[38913.0,0.0193],[35275.0,0.0]],"asks":[],"action":"update"}}
1651237319.5226693: {"channel":"orderbook","market":"SHIB/USD","type":"update","data":{"time":1651237319.3863358,"checksum":3725409297,"bids":[[0.00002258,204900000.0]],"asks":[[0.00002266,165900000.0],[0.00002268,123000000.0]],"action":"update"}}
1651237319.5227182: {"channel":"orderbook","market":"ETH/USD","type":"update","data":{"time":1651237319.3899672,"checksum":2883928053,"bids":[[2861.2,7.139],[2861.1,9.493],[2861.0,8.074],[2860.8,28.052],[2860.4,5.661],[2860.3,1.0],[2860.1,0.042],[2859.6,3.493],[2858.0,26.355],[2857.3,0.0],[2849.7,0.0]],"asks":[[2861.6,3.997],[2862.3,6.139]],"action":"update"}}
1651237319.522785: {"channel":"orderbook","market":"ETH/USDT","type":"update","data":{"time":1651237319.3960915,"checksum":3188451973,"bids":[[2858.9,4.37],[2842.5,0.0]],"asks":[[2863.3,2.354],[2883.1,0.0]],"action":"update"}}
1651237319.5456831: {"channel":"orderbook","market":"SOL/USD","type":"update","data":{"time":1651237319.413743,"checksum":3055946890,"bids":[],"asks":[[95.9275,52.68],[96.3275,0.0]],"action":"update"}}
1651237319.550665: {"channel":"orderbook","market":"ETH/USD","type":"update","data":{"time":1651237319.4149277,"checksum":4234208864,"bids":[[2861.2,7.454],[2861.1,5.493],[2861.0,8.226],[2860.8,10.873],[2860.0,24.645],[2857.3,1.777],[2849.8,0.0]],"asks":[[2862.2,3.496]],"action":"update"}}
1651237319.5533376: {"channel":"orderbook","market":"WBTC/USD","type":"update","data":{"time":1651237319.424515,"checksum":3316225564,"bids":[[38552.0,0.0804],[35385.0,0.0]],"asks":[],"action":"update"}}
1651237319.5585916: {"channel":"orderbook","market":"ETH/USDT","type":"update","data":{"time":1651237319.4309533,"checksum":1931459798,"bids":[[2861.2,1.748],[2860.8,3.495],[2842.8,0.0],[2842.7,0.0]],"asks":[],"action":"update"}}
1651237319.567901: {"channel":"orderbook","market":"ETH/USD","type":"update","data":{"time":1651237319.4385262,"checksum":2739492995,"bids":[[2861.2,9.454],[2860.9,3.751],[2858.1,11.154],[2856.0,6.148]],"asks":[[2862.1,0.35],[2862.9,4.395],[2863.6,7.611],[2864.8,0.349],[2874.3,0.0]],"action":"update"}}
1651237319.5864053: {"channel":"orderbook","market":"ETH/USDT","type":"update","data":{"time":1651237319.4536948,"checksum":805044045,"bids":[],"asks":[[2861.7,0.0],[2883.1,0.3]],"action":"update"}}
1651237319.5882816: {"channel":"orderbook","market":"SHIB/USD","type":"update","data":{"time":1651237319.456599,"checksum":2859852238,"bids":[[0.00002258,247400000.0]],"asks":[],"action":"update"}}
1651237319.590091: {"channel":"orderbook","market":"SOL/USD","type":"update","data":{"time":1651237319.4633996,"checksum":516729280,"bids":[[95.8375,0.0],[95.4475,0.03]],"asks":[[96.0325,0.0],[96.1775,0.36],[96.3275,0.01]],"action":"update"}}
1651237319.5915222: {"channel":"orderbook","market":"ETH/USD","type":"update","data":{"time":1651237319.4634209,"checksum":1102417922,"bids":[[2860.1,6.207]],"asks":[[2861.9,8.258],[2862.3,9.241],[2862.4,18.049],[2862.9,4.046],[2864.0,2.445]],"action":"update"}}
1651237319.618656: {"channel":"orderbook","market":"ETH/USD","type":"update","data":{"time":1651237319.4872615,"checksum":4110598513,"bids":[[2861.2,9.699],[2860.8,11.222],[2860.5,19.623],[2858.5,3.687],[2858.0,27.229],[2857.3,0.0]],"asks":[[2861.9,3.008],[2862.0,9.885],[2863.9,2.834]],"action":"update"}}
1651237319.618729: {"channel":"orderbook","market":"SOL/USD","type":"update","data":{"time":1651237319.4923716,"checksum":2482824220,"bids":[[95.8425,331.69],[95.8275,0.01]],"asks":[],"action":"update"}}
1651237319.6189175: {"channel":"orderbook","market":"LTC/USDT","type":"update","data":{"time":1651237319.493072,"checksum":2622555741,"bids":[[100.435,17.2],[96.55,0.0]],"asks":[],"action":"update"}}
1651237319.6346064: {"channel":"orderbook","market":"ETH/USDT","type":"update","data":{"time":1651237319.5060933,"checksum":1202424753,"bids":[[2861.1,18.001]],"asks":[[2861.6,0.0],[2883.5,0.032]],"action":"update"}}
1651237319.6346543: {"channel":"orderbook","market":"SHIB/USD","type":"update","data":{"time":1651237319.504514,"checksum":1990950982,"bids":[[0.00002261,131200000.0]],"asks":[],"action":"update"}}
1651237319.6421962: {"channel":"orderbook","market":"ETH/USD","type":"update","data":{"time":1651237319.5124724,"checksum":3239060413,"bids":[],"asks":[[2861.8,5.563],[2862.1,0.001]],"action":"update"}}
1651237319.6486256: {"channel":"orderbook","market":"ETH/USDT","type":"update","data":{"time":1651237319.520353,"checksum":1188256735,"bids":[],"asks":[[2861.8,2.5],[2883.5,0.0]],"action":"update"}}
1651237319.6605136: {"channel":"orderbook","market":"SOL/USD","type":"update","data":{"time":1651237319.523325,"checksum":2689904604,"bids":[[95.8425,324.74]],"asks":[],"action":"update"}}
1651237319.6694462: {"channel":"orderbook","market":"ETH/USD","type":"update","data":{"time":1651237319.5360873,"checksum":146862834,"bids":[[2861.2,11.699],[2855.3,4.983]],"asks":[[2861.8,3.493]],"action":"update"}}
1651237319.6761034: {"channel":"orderbook","market":"ETH/USDT","type":"update","data":{"time":1651237319.545779,"checksum":222612085,"bids":[[2861.5,2.0],[2860.3,12.353],[2843.0,0.0]],"asks":[[2863.9,2.958],[2883.1,0.0]],"action":"update"}}
1651237319.6762047: {"channel":"orderbook","market":"SOL/USD","type":"update","data":{"time":1651237319.5454135,"checksum":2416698751,"bids":[[95.8425,276.12]],"asks":[],"action":"update"}}
1651237319.681338: {"channel":"orderbook","market":"SHIB/USD","type":"update","data":{"time":1651237319.5548851,"checksum":3543469407,"bids":[],"asks":[[0.00002267,69000000.0]],"action":"update"}}
1651237319.692752: {"channel":"orderbook","market":"ETH/USD","type":"update","data":{"time":1651237319.5626118,"checksum":3385797013,"bids":[[2857.5,0.0],[2849.8,0.032]],"asks":[[2861.9,8.258]],"action":"update"}}
1651237319.699965: {"channel":"orderbook","market":"ETH/USDT","type":"update","data":{"time":1651237319.572368,"checksum":121036954,"bids":[[2859.7,11.043]],"asks":[[2862.6,19.767]],"action":"update"}}
1651237319.7000387: {"channel":"orderbook","market":"SOL/USD","type":"update","data":{"time":1651237319.5732968,"checksum":286882025,"bids":[[95.8425,280.77],[95.7675,91.55]],"asks":[],"action":"update"}}
1651237319.723936: {"channel":"orderbook","market":"SOL/USD","type":"update","data":{"time":1651237319.5925684,"checksum":2182715980,"bids":[[95.845,12.9],[95.8425,285.42],[95.6875,93.81],[95.4475,0.0]],"asks":[],"action":"update"}}
1651237319.7273016: {"channel":"orderbook","market":"ETH/USDT","type":"update","data":{"time":1651237319.6006134,"checksum":1271765084,"bids":[[2859.8,0.0],[2843.0,0.016]],"asks":[[2861.7,0.161],[2883.0,0.0]],"action":"update"}}
1651237319.7357764: {"channel":"orderbook","market":"ETH/USD","type":"update","data":{"time":1651237319.6020887,"checksum":1666304914,"bids":[[2861.0,5.589]],"asks":[],"action":"update"}}
1651237319.7519712: {"channel":"orderbook","market":"ETH/USD","type":"update","data":{"time":1651237319.6194692,"checksum":509981402,"bids":[],"asks":[[2862.1,0.35],[2864.3,0.298],[2874.2,0.0]],"action":"update"}}
1651237319.7520351: {"channel":"orderbook","market":"ETH/USDT","type":"update","data":{"time":1651237319.6245828,"checksum":144937480,"bids":[[2861.5,0.0],[2859.9,4.009],[2859.7,0.0],[2842.8,0.01]],"asks":[[2861.7,2.161],[2862.4,7.913]],"action":"update"}}
1651237319.7623875: {"channel":"orderbook","market":"LTC/USDT","type":"update","data":{"time":1651237319.62262,"checksum":2622555741,"bids":[],"asks":[],"action":"update"}}
1651237319.774281: {"channel":"orderbook","market":"SOL/USD","type":"update","data":{"time":1651237319.644427,"checksum":3028572153,"bids":[[95.7425,131.86],[95.45,0.0]],"asks":[[95.86,316.0],[95.9225,0.0],[96.33,0.26]],"action":"update"}}
1651237319.7785287: {"channel":"orderbook","market":"DAI/USD","type":"update","data":{"time":1651237319.6525776,"checksum":2637841829,"bids":[],"asks":[],"action":"update"}}
1651237319.800783: {"channel":"orderbook","market":"SOL/USD","type":"update","data":{"time":1651237319.6703956,"checksum":350860383,"bids":[[95.8275,0.0],[95.685,8.62],[95.45,0.39]],"asks":[[95.9425,61.3]],"action":"update"}}
1651237319.8008513: {"channel":"orderbook","market":"ETH/USD","type":"update","data":{"time":1651237319.6689684,"checksum":1999050458,"bids":[[2860.9,6.564]],"asks":[[2863.2,5.723],[2864.2,0.002]],"action":"update"}}
1651237319.8036256: {"channel":"orderbook","market":"ETH/USDT","type":"update","data":{"time":1651237319.6742578,"checksum":1117903728,"bids":[],"asks":[[2863.7,2.16]],"action":"update"}}
1651237319.8236609: {"channel":"orderbook","market":"SOL/USD","type":"update","data":{"time":1651237319.696523,"checksum":3278217498,"bids":[[95.8,105.28],[95.6875,119.91],[95.45,0.0]],"asks":[[96.0375,7.27]],"action":"update"}}
1651237319.8237412: {"channel":"orderbook","market":"ETH/USD","type":"update","data":{"time":1651237319.69385,"checksum":4130839860,"bids":[[2860.1,6.165],[2859.8,24.393],[2855.0,3.203],[2849.8,0.0]],"asks":[[2861.8,5.564],[2861.9,3.008],[2863.0,0.35],[2863.5,148.06]],"action":"update"}}
1651237319.8287408: {"channel":"orderbook","market":"ETH/USDT","type":"update","data":{"time":1651237319.7023218,"checksum":2130089164,"bids":[[2861.6,2.0],[2861.2,4.248],[2859.5,0.0]],"asks":[[2862.4,18.816]],"action":"update"}}
1651237319.8837306: {"channel":"orderbook","market":"ETH/USD","type":"update","data":{"time":1651237319.7448635,"checksum":442166306,"bids":[[2857.7,0.008],[2849.9,0.0]],"asks":[[2861.8,3.493],[2862.1,0.001]],"action":"update"}}
1651237319.8930147: {"channel":"orderbook","market":"ETH/USD","type":"update","data":{"time":1651237319.7665553,"checksum":4006939498,"bids":[[2860.7,5.184],[2860.6,3.535],[2859.9,6.108]],"asks":[[2861.3,0.003],[2864.8,2.47]],"action":"update"}}
1651237319.8982189: {"channel":"orderbook","market":"FTT/BTC","type":"update","data":{"time":1651237319.7721117,"checksum":526402248,"bids":[[0.0010063,0.4]],"asks":[[0.0010109,329.7]],"action":"update"}}
1651237319.899998: {"channel":"orderbook","market":"ETH/USDT","type":"update","data":{"time":1651237319.7742977,"checksum":1589845624,"bids":[],"asks":[[2862.2,0.0],[2883.0,0.029]],"action":"update"}}
1651237319.9296532: {"channel":"orderbook","market":"SHIB/USD","type":"update","data":{"time":1651237319.8006349,"checksum":2163896973,"bids":[[0.00002261,130700000.0],[0.00002209,35900000.0]],"asks":[[0.00002269,100000.0]],"action":"update"}}
1651237319.935472: {"channel":"orderbook","market":"USD/TRY","type":"update","data":{"time":1651237319.8041098,"checksum":2677111741,"bids":[],"asks":[],"action":"update"}}
1651237319.9433534: {"channel":"orderbook","market":"ETH/USD","type":"update","data":{"time":1651237319.8132153,"checksum":2166148515,"bids":[],"asks":[[2862.2,17.79]],"action":"update"}}
1651237319.9506779: {"channel":"orderbook","market":"SOL/USD","type":"update","data":{"time":1651237319.8198428,"checksum":2454054135,"bids":[[95.845,0.0],[95.8425,278.89],[95.45,0.39]],"asks":[],"action":"update"}}
1651237319.9669158: {"channel":"orderbook","market":"ETH/USD","type":"update","data":{"time":1651237319.837186,"checksum":738407191,"bids":[[2861.1,3.493]],"asks":[[2862.1,0.35]],"action":"update"}}
1651237319.9776828: {"channel":"orderbook","market":"ETH/USDT","type":"update","data":{"time":1651237319.849991,"checksum":3512824424,"bids":[[2860.2,27.025]],"asks":[[2862.3,25.331],[2883.0,0.0]],"action":"update"}}
1651237319.9777408: {"channel":"orderbook","market":"WBTC/USD","type":"update","data":{"time":1651237319.8501887,"checksum":3836332885,"bids":[[38876.0,0.0],[35385.0,0.0001]],"asks":[],"action":"update"}}
1651237319.9820428: {"channel":"orderbook","market":"SOL/USD","type":"update","data":{"time":1651237319.8487554,"checksum":4214937021,"bids":[[95.8425,269.59]],"asks":[[95.86,268.64]],"action":"update"}}
1651237319.9821215: {"channel":"orderbook","market":"SHIB/USD","type":"update","data":{"time":1651237319.851819,"checksum":255264911,"bids":[[0.00002262,61200000.0],[0.00002259,406800000.0],[0.00002161,0.0]],"asks":[[0.00002263,240600000.0],[0.00002267,140100000.0]],"action":"update"}}
1651237320.0059814: {"channel":"orderbook","market":"SHIB/USD","type":"update","data":{"time":1651237319.876809,"checksum":2031537973,"bids":[[0.00002258,230300000.0]],"asks":[],"action":"update"}}
1651237320.0128489: {"channel":"orderbook","market":"SOL/USD","type":"update","data":{"time":1651237319.8812377,"checksum":1936466261,"bids":[],"asks":[[95.8575,36.0],[95.86,0.0],[95.8725,0.0],[96.1925,275.32]],"action":"update"}}
1651237320.0154471: {"channel":"orderbook","market":"ETH/USD","type":"update","data":{"time":1651237319.8873515,"checksum":482721351,"bids":[],"asks":[[2861.7,17.297],[2862.1,4.448],[2874.1,0.0]],"action":"update"}}
1651237320.0268168: {"channel":"orderbook","market":"ETH/USDT","type":"update","data":{"time":1651237319.8965185,"checksum":2153139334,"bids":[[2861.4,0.0],[2842.7,0.018]],"asks":[],"action":"update"}}
1651237320.0321395: {"channel":"orderbook","market":"WBTC/USD","type":"update","data":{"time":1651237319.899453,"checksum":984896602,"bids":[[38892.0,0.0771],[35385.0,0.0]],"asks":[],"action":"update"}}
1651237320.0321903: {"channel":"orderbook","market":"SHIB/USD","type":"update","data":{"time":1651237319.9011207,"checksum":2495519463,"bids":[[0.00002261,40700000.0],[0.00002257,431900000.0],[0.00002255,139500000.0]],"asks":[],"action":"update"}}
1651237320.0322359: {"channel":"orderbook","market":"SOL/USD","type":"update","data":{"time":1651237319.9038234,"checksum":2914629603,"bids":[[95.6375,207.01]],"asks":[[95.8575,260.0],[95.9225,105.29],[96.33,0.0]],"action":"update"}}
1651237320.0411303: {"channel":"orderbook","market":"ETH/USD","type":"update","data":{"time":1651237319.9137805,"checksum":3828575838,"bids":[[2860.3,15.263],[2859.5,0.0],[2849.9,701.833]],"asks":[[2862.2,42.246]],"action":"update"}}
1651237320.058208: {"channel":"orderbook","market":"ETH/USDT","type":"update","data":{"time":1651237319.923779,"checksum":3880957808,"bids":[],"asks":[[2862.5,6.23]],"action":"update"}}
1651237320.0582416: {"channel":"orderbook","market":"SOL/USD","type":"update","data":{"time":1651237319.931435,"checksum":3198803063,"bids":[[95.6875,93.81]],"asks":[],"action":"update"}}
1651237320.1132576: {"channel":"orderbook","market":"SOL/USD","type":"update","data":{"time":1651237319.9563897,"checksum":1049009030,"bids":[[95.8425,217.9]],"asks":[[95.8625,104.16],[95.8775,36.0],[95.9375,0.03],[96.32,0.0],[96.3225,0.0],[96.3275,0.0]],"action":"update"}}
1651237320.1133413: {"channel":"orderbook","market":"FTT/BTC","type":"update","data":{"time":1651237319.9671395,"checksum":526402248,"bids":[],"asks":[],"action":"update"}}
1651237320.1133983: {"channel":"orderbook","market":"ETH/USD","type":"update","data":{"time":1651237319.9628696,"checksum":342515102,"bids":[[2861.0,3.493],[2860.5,26.622]],"asks":[[2861.4,0.002],[2861.6,6.483],[2861.7,0.0],[2862.2,51.751],[2862.4,32.416]],"action":"update"}}
1651237320.113458: {"channel":"orderbook","market":"SHIB/USD","type":"update","data":{"time":1651237319.9640338,"checksum":18915828,"bids":[[0.00002261,236200000.0],[0.00002257,447000000.0]],"asks":[[0.00002263,143100000.0],[0.00002267,113600000.0]],"action":"update"}}
1651237320.1135058: {"channel":"orderbook","market":"SOL/USD","type":"update","data":{"time":1651237319.983024,"checksum":3198356583,"bids":[[95.83,70.0]],"asks":[],"action":"update"}}
1651237320.1249547: {"channel":"orderbook","market":"ETH/USDT","type":"update","data":{"time":1651237319.988066,"checksum":1692405956,"bids":[],"asks":[[2862.2,0.174],[2882.9,0.0]],"action":"update"}}
1651237320.150774: {"channel":"orderbook","market":"ETH/USD","type":"update","data":{"time":1651237320.0161119,"checksum":647919822,"bids":[[2861.0,3.496],[2860.6,10.193],[2858.0,20.937]],"asks":[[2861.6,3.997],[2862.1,10.913],[2862.4,33.161],[2862.8,0.68],[2863.5,147.975],[2867.0,0.01],[2874.0,0.0]],"action":"update"}}
1651237320.1545954: {"channel":"orderbook","market":"LTC/USDT","type":"update","data":{"time":1651237320.0270598,"checksum":2892004509,"bids":[],"asks":[[100.585,63.87],[103.775,0.0]],"action":"update"}}
1651237320.1844425: {"channel":"orderbook","market":"ETH/USD","type":"update","data":{"time":1651237320.0517712,"checksum":1034439580,"bids":[[2856.1,0.541]],"asks":[],"action":"update"}}
1651237320.1887906: {"channel":"orderbook","market":"ETH/USDT","type":"update","data":{"time":1651237320.0598726,"checksum":1268357920,"bids":[[2859.9,0.0],[2842.5,835.588]],"asks":[],"action":"update"}}
1651237320.1991017: {"channel":"orderbook","market":"FTT/BTC","type":"update","data":{"time":1651237320.070937,"checksum":1450339144,"bids":[[0.0010063,23.2]],"asks":[],"action":"update"}}
1651237320.2115014: {"channel":"orderbook","market":"ETH/USD","type":"update","data":{"time":1651237320.0805523,"checksum":4080200586,"bids":[],"asks":[[2862.0,12.617],[2862.1,10.564],[2867.3,0.006]],"action":"update"}}
1651237320.2115471: {"channel":"orderbook","market":"WBTC/USD","type":"update","data":{"time":1651237320.0800865,"checksum":3816770541,"bids":[[38859.0,0.0016],[35386.0,0.0]],"asks":[],"action":"update"}}
1651237320.2224631: {"channel":"orderbook","market":"ETH/USDT","type":"update","data":{"time":1651237320.0837317,"checksum":1842307414,"bids":[[2861.2,8.756]],"asks":[[2862.2,6.515]],"action":"update"}}
1651237320.2290936: {"channel":"orderbook","market":"LTC/USDT","type":"update","data":{"time":1651237320.0949495,"checksum":2747078948,"bids":[],"asks":[[100.66,0.0],[103.775,0.71]],"action":"update"}}
1651237320.2291353: {"channel":"orderbook","market":"FTT/BTC","type":"update","data":{"time":1651237320.098615,"checksum":1256004237,"bids":[],"asks":[[0.0010105,22.8],[0.001024,0.0]],"action":"update"}}
1651237320.2291718: {"channel":"orderbook","market":"BTC/TRY","type":"update","data":{"time":1651237320.1018345,"checksum":2549750460,"bids":[],"asks":[],"action":"update"}}
1651237320.2484894: {"channel":"orderbook","market":"ETH/USD","type":"update","data":{"time":1651237320.111124,"checksum":1730798813,"bids":[[2861.2,11.686]],"asks":[[2861.9,8.258]],"action":"update"}}
1651237320.248531: {"channel":"orderbook","market":"ETH/USDT","type":"update","data":{"time":1651237320.111308,"checksum":1471119960,"bids":[[2859.9,4.009],[2842.5,0.0]],"asks":[[2862.5,6.273]],"action":"update"}}
1651237320.2485623: {"channel":"orderbook","market":"LTC/USDT","type":"update","data":{"time":1651237320.118373,"checksum":1680784308,"bids":[[100.455,174.09]],"asks":[],"action":"update"}}
1651237320.2560933: {"channel":"orderbook","market":"SOL/USD","type":"update","data":{"time":1651237320.1220322,"checksum":1188963625,"bids":[[95.8425,191.96],[95.75,8.62]],"asks":[],"action":"update"}}
1651237320.2561314: {"channel":"orderbook","market":"FTT/BTC","type":"update","data":{"time":1651237320.1253474,"checksum":1903143265,"bids":[],"asks":[[0.0010097,5.6]],"action":"update"}}
1651237320.2603874: {"channel":"orderbook","market":"ETH/USD","type":"update","data":{"time":1651237320.1334336,"checksum":2323431796,"bids":[[2856.7,1.034]],"asks":[],"action":"update"}}
1651237320.2674801: {"channel":"orderbook","market":"ETH/USDT","type":"update","data":{"time":1651237320.1311362,"checksum":2156901467,"bids":[[2860.7,0.232]],"asks":[[2862.6,23.696]],"action":"update"}}
1651237320.268615: {"channel":"orderbook","market":"LTC/USDT","type":"update","data":{"time":1651237320.141,"checksum":3699178130,"bids":[],"asks":[[100.645,0.0],[103.79,0.01]],"action":"update"}}
1651237320.2830212: {"channel":"orderbook","market":"SOL/USD","type":"update","data":{"time":1651237320.146496,"checksum":1658450341,"bids":[[95.8425,185.7],[95.685,34.72]],"asks":[[96.0125,0.0],[96.32,0.01]],"action":"update"}}
1651237320.2993143: {"channel":"orderbook","market":"ETH/USD","type":"update","data":{"time":1651237320.164772,"checksum":352773775,"bids":[[2860.6,10.151]],"asks":[[2861.8,5.562],[2861.9,3.008],[2863.7,25.915]],"action":"update"}}
1651237320.2993572: {"channel":"orderbook","market":"SOL/USD","type":"update","data":{"time":1651237320.171248,"checksum":2936013530,"bids":[[95.685,8.62]],"asks":[[95.8775,0.0],[96.3225,0.62]],"action":"update"}}
1651237320.3252742: {"channel":"orderbook","market":"ETH/USD","type":"update","data":{"time":1651237320.1831317,"checksum":358762780,"bids":[],"asks":[[2862.1,10.913],[2867.3,0.007]],"action":"update"}}
1651237320.3340812: {"channel":"orderbook","market":"USD/TRY","type":"update","data":{"time":1651237320.2030394,"checksum":1861656539,"bids":[[13.7167,2021.0]],"asks":[],"action":"update"}}
1651237320.3390713: {"channel":"orderbook","market":"ETH/USD","type":"update","data":{"time":1651237320.2079196,"checksum":2507739145,"bids":[[2860.6,10.193]],"asks":[[2861.8,3.493]],"action":"update"}}
1651237320.3391066: {"channel":"orderbook","market":"ETH/USDT","type":"update","data":{"time":1651237320.2077184,"checksum":3587779935,"bids":[[2860.9,0.0],[2860.3,23.396],[2842.5,835.588]],"asks":[[2862.0,8.881],[2863.1,0.175],[2864.1,0.0]],"action":"update"}}
1651237320.3391452: {"channel":"orderbook","market":"WBTC/USD","type":"update","data":{"time":1651237320.2113435,"checksum":3816770541,"bids":[],"asks":[],"action":"update"}}
1651237320.3489268: {"channel":"orderbook","market":"SOL/USD","type":"update","data":{"time":1651237320.22007,"checksum":1409378151,"bids":[],"asks":[[95.855,12.9],[95.8575,296.0],[96.3225,0.0]],"action":"update"}}
1651237320.3709733: {"channel":"orderbook","market":"ETH/USDT","type":"update","data":{"time":1651237320.2338464,"checksum":2365270323,"bids":[],"asks":[[2861.7,2.322],[2864.0,2.335]],"action":"update"}}
1651237320.384891: {"channel":"orderbook","market":"SOL/USD","type":"update","data":{"time":1651237320.2479374,"checksum":3753118384,"bids":[[95.8275,5.0],[95.45,0.0]],"asks":[],"action":"update"}}
1651237320.4007869: {"channel":"orderbook","market":"ETH/USD","type":"update","data":{"time":1651237320.25987,"checksum":2572836319,"bids":[[2861.2,8.206]],"asks":[[2862.3,12.736]],"action":"update"}}
1651237320.400832: {"channel":"orderbook","market":"ETH/USDT","type":"update","data":{"time":1651237320.262556,"checksum":4104150820,"bids":[[2861.6,0.0],[2842.2,0.001]],"asks":[[2863.9,0.0],[2882.9,0.015]],"action":"update"}}
1651237320.400868: {"channel":"orderbook","market":"SOL/USD","type":"update","data":{"time":1651237320.2703755,"checksum":746264771,"bids":[[95.8275,0.0],[95.6375,233.11],[95.45,0.39]],"asks":[[95.9225,0.0],[96.3225,0.62]],"action":"update"}}
1651237320.4131124: {"channel":"orderbook","market":"ETH/USD","type":"update","data":{"time":1651237320.2838292,"checksum":3839786315,"bids":[[2861.0,6.991],[2860.8,9.126],[2860.4,9.156]],"asks":[[2861.3,3.496],[2861.9,8.258],[2863.5,148.059]],"action":"update"}}
1651237320.4226625: {"channel":"orderbook","market":"ETH/USDT","type":"update","data":{"time":1651237320.2845507,"checksum":246079722,"bids":[[2857.6,11.039]],"asks":[[2862.2,9.837],[2865.1,153.206],[2882.9,0.0]],"action":"update"}}
1651237320.430676: {"channel":"orderbook","market":"SOL/USD","type":"update","data":{"time":1651237320.2970757,"checksum":355303589,"bids":[[95.8425,178.78],[95.83,0.0],[95.8,0.0],[95.6375,207.01],[95.4475,0.03],[95.44,1.0]],"asks":[],"action":"update"}}
1651237320.4333253: {"channel":"orderbook","market":"ETH/USDT","type":"update","data":{"time":1651237320.3053193,"checksum":1242007536,"bids":[[2861.2,7.008]],"asks":[[2861.7,0.322]],"action":"update"}}
1651237320.4336216: {"channel":"orderbook","market":"ETH/USD","type":"update","data":{"time":1651237320.3080063,"checksum":874691177,"bids":[],"asks":[[2862.3,9.241],[2863.9,3.708]],"action":"update"}}
1651237320.4688404: {"channel":"orderbook","market":"SOL/USD","type":"update","data":{"time":1651237320.3271575,"checksum":898902686,"bids":[],"asks":[[95.8575,260.0]],"action":"update"}}
1651237320.4688857: {"channel":"orderbook","market":"ETH/USDT","type":"update","data":{"time":1651237320.3332548,"checksum":3730781621,"bids":[[2860.5,3.495],[2842.2,0.0]],"asks":[[2861.5,2.0],[2862.3,28.826],[2862.4,7.913],[2882.6,0.0]],"action":"update"}}
1651237320.4689298: {"channel":"orderbook","market":"ETH/USD","type":"update","data":{"time":1651237320.3324687,"checksum":3253857336,"bids":[[2861.2,6.46]],"asks":[[2861.8,5.563],[2862.1,10.564]],"action":"update"}}
1651237320.4900742: {"channel":"orderbook","market":"SOL/USD","type":"update","data":{"time":1651237320.3496652,"checksum":91460197,"bids":[[95.84,0.0],[95.7825,63.36],[95.4375,0.01]],"asks":[],"action":"update"}}
1651237320.490125: {"channel":"orderbook","market":"ETH/USD","type":"update","data":{"time":1651237320.3585331,"checksum":2975651434,"bids":[],"asks":[[2861.3,3.981],[2861.9,3.008]],"action":"update"}}
1651237320.5075717: {"channel":"orderbook","market":"ETH/USDT","type":"update","data":{"time":1651237320.3724754,"checksum":400048902,"bids":[[2860.2,28.025]],"asks":[[2861.5,0.0],[2861.7,0.0],[2882.6,0.1],[2882.9,0.015]],"action":"update"}}
1651237320.5103595: {"channel":"orderbook","market":"ETH/USD","type":"update","data":{"time":1651237320.3838747,"checksum":1879271520,"bids":[],"asks":[[2861.3,5.981],[2861.7,5.25],[2861.9,4.756],[2863.5,161.544],[2867.3,0.006],[2873.9,0.0]],"action":"update"}}
1651237320.5208983: {"channel":"orderbook","market":"ETH/USDT","type":"update","data":{"time":1651237320.389693,"checksum":1783651960,"bids":[],"asks":[[2861.7,2.095],[2865.6,19.519],[2882.9,0.0]],"action":"update"}}
1651237320.5333211: {"channel":"orderbook","market":"SOL/USD","type":"update","data":{"time":1651237320.389684,"checksum":3274374222,"bids":[[95.6375,233.11]],"asks":[[95.855,48.9],[95.9375,0.0],[96.3275,0.01]],"action":"update"}}
1651237320.541052: {"channel":"orderbook","market":"ETH/USD","type":"update","data":{"time":1651237320.4080422,"checksum":4143996611,"bids":[[2860.4,19.293]],"asks":[[2863.7,1.254]],"action":"update"}}
1651237320.564627: {"channel":"orderbook","market":"SOL/USD","type":"update","data":{"time":1651237320.422851,"checksum":1182355743,"bids":[],"asks":[[95.855,43.7],[95.915,175.3],[96.0375,7.26]],"action":"update"}}
1651237320.5646753: {"channel":"orderbook","market":"ETH/USD","type":"update","data":{"time":1651237320.4329085,"checksum":990444352,"bids":[[2860.3,14.263],[2854.0,11.005]],"asks":[[2863.4,42.055],[2868.0,9.479]],"action":"update"}}
1651237320.5647092: {"channel":"orderbook","market":"SHIB/USD","type":"update","data":{"time":1651237320.4329069,"checksum":494993103,"bids":[[0.00002262,0.0],[0.00002161,100000.0]],"asks":[[0.00002264,505800000.0]],"action":"update"}}
1651237320.5647404: {"channel":"orderbook","market":"ETH/USDT","type":"update","data":{"time":1651237320.437401,"checksum":3611960151,"bids":[[2858.7,0.365],[2842.5,0.0]],"asks":[[2861.4,2.0],[2882.6,0.0]],"action":"update"}}
1651237320.593786: {"channel":"orderbook","market":"ETH/USD","type":"update","data":{"time":1651237320.457757,"checksum":3699458048,"bids":[],"asks":[[2862.1,10.913]],"action":"update"}}
1651237320.5938306: {"channel":"orderbook","market":"SHIB/USD","type":"update","data":{"time":1651237320.4622846,"checksum":2523035379,"bids":[[0.00002257,431900000.0]],"asks":[[0.00002265,570700000.0]],"action":"update"}}
1651237320.604829: {"channel":"orderbook","market":"ETH/USDT","type":"update","data":{"time":1651237320.4735465,"checksum":641850736,"bids":[],"asks":[[2861.4,0.0],[2861.7,3.456],[2862.3,25.331],[2862.6,3.929],[2882.6,0.1]],"action":"update"}}
1651237320.6092253: {"channel":"orderbook","market":"SHIB/USD","type":"update","data":{"time":1651237320.482553,"checksum":3448310402,"bids":[],"asks":[[0.00002263,187800000.0]],"action":"update"}}
1651237320.626767: {"channel":"orderbook","market":"ETH/USD","type":"update","data":{"time":1651237320.485118,"checksum":3582291323,"bids":[[2861.2,3.037],[2860.6,11.193]],"asks":[[2861.3,7.881],[2861.8,3.493],[2863.6,0.912]],"action":"update"}}
1651237320.6268566: {"channel":"orderbook","market":"SOL/USD","type":"update","data":{"time":1651237320.4892414,"checksum":2510498131,"bids":[[95.8425,158.97],[95.6375,207.01]],"asks":[],"action":"update"}}
1651237320.6448157: {"channel":"orderbook","market":"ETH/USD","type":"update","data":{"time":1651237320.509757,"checksum":2820001715,"bids":[[2861.2,1.037],[2860.8,8.777],[2857.7,0.0],[2849.8,0.032]],"asks":[],"action":"update"}}
1651237320.6449127: {"channel":"orderbook","market":"SHIB/USD","type":"update","data":{"time":1651237320.5116968,"checksum":242512453,"bids":[],"asks":[[0.00002262,19700000.0],[0.00002375,0.0]],"action":"update"}}
1651237320.644969: {"channel":"orderbook","market":"FTT/BTC","type":"update","data":{"time":1651237320.519088,"checksum":3048013507,"bids":[[0.0010077,26.5]],"asks":[],"action":"update"}}
1651237320.6674373: {"channel":"orderbook","market":"SOL/USD","type":"update","data":{"time":1651237320.5237064,"checksum":3297706969,"bids":[[95.8425,152.05],[95.8175,56.29]],"asks":[[95.97,216.63]],"action":"update"}}
1651237320.669619: {"channel":"orderbook","market":"ETH/USD","type":"update","data":{"time":1651237320.5342152,"checksum":1578591182,"bids":[[2861.2,1.011]],"asks":[],"action":"update"}}
1651237320.6698925: {"channel":"orderbook","market":"ETH/USDT","type":"update","data":{"time":1651237320.5239034,"checksum":4164360263,"bids":[[2861.1,4.529],[2861.0,13.457],[2860.4,12.078]],"asks":[[2861.7,2.095],[2861.8,0.0],[2861.9,6.75],[2862.2,20.74],[2862.4,7.731],[2862.5,0.345],[2863.0,0.055],[2869.9,0.089],[2882.9,0.015]],"action":"update"}}
1651237320.6699586: {"channel":"orderbook","market":"LTC/USDT","type":"update","data":{"time":1651237320.5413034,"checksum":4263471543,"bids":[],"asks":[[100.705,7.46],[103.79,0.0]],"action":"update"}}
1651237320.6795948: {"channel":"orderbook","market":"ETH/USDT","type":"update","data":{"time":1651237320.5475667,"checksum":3669119736,"bids":[],"asks":[[2862.5,3.84]],"action":"update"}}
1651237320.6914966: {"channel":"orderbook","market":"ETH/USD","type":"update","data":{"time":1651237320.5565624,"checksum":50379598,"bids":[[2861.1,0.0],[2849.7,0.01]],"asks":[],"action":"update"}}
1651237320.693014: {"channel":"orderbook","market":"SHIB/USD","type":"update","data":{"time":1651237320.5643077,"checksum":2961436314,"bids":[[0.00002257,491900000.0]],"asks":[[0.00002265,480700000.0]],"action":"update"}}
1651237320.708479: {"channel":"orderbook","market":"ETH/USDT","type":"update","data":{"time":1651237320.5741143,"checksum":2226851195,"bids":[[2859.9,0.0],[2842.5,835.588]],"asks":[[2861.9,8.498]],"action":"update"}}
1651237320.7085316: {"channel":"orderbook","market":"ETH/USD","type":"update","data":{"time":1651237320.5819728,"checksum":4224277216,"bids":[],"asks":[[2862.1,10.564]],"action":"update"}}
1651237320.7235193: {"channel":"orderbook","market":"LTC/USDT","type":"update","data":{"time":1651237320.591448,"checksum":3840777340,"bids":[[100.565,4.44],[96.635,0.0]],"asks":[],"action":"update"}}
1651237320.729751: {"channel":"orderbook","market":"ETH/USDT","type":"update","data":{"time":1651237320.5982528,"checksum":2802779313,"bids":[],"asks":[[2861.3,0.248],[2882.9,0.0]],"action":"update"}}
1651237320.749663: {"channel":"orderbook","market":"SHIB/USD","type":"update","data":{"time":1651237320.6075914,"checksum":2856005008,"bids":[[0.00002258,244700000.0]],"asks":[[0.00002269,26900000.0]],"action":"update"}}
1651237320.7497303: {"channel":"orderbook","market":"ETH/USD","type":"update","data":{"time":1651237320.6092467,"checksum":1465596106,"bids":[],"asks":[[2861.3,9.881],[2867.2,4.199]],"action":"update"}}
1651237320.749771: {"channel":"orderbook","market":"SOL/USD","type":"update","data":{"time":1651237320.6172245,"checksum":881037201,"bids":[[95.6375,233.11]],"asks":[[95.915,70.0],[95.9575,285.87],[95.995,711.68]],"action":"update"}}
1651237320.7648897: {"channel":"orderbook","market":"ETH/USDT","type":"update","data":{"time":1651237320.6248949,"checksum":3759183413,"bids":[[2860.2,32.034]],"asks":[[2861.3,0.161]],"action":"update"}}
1651237320.7779684: {"channel":"orderbook","market":"ETH/USD","type":"update","data":{"time":1651237320.6348243,"checksum":3098405703,"bids":[[2860.6,11.542]],"asks":[[2863.5,13.758]],"action":"update"}}
1651237320.7780187: {"channel":"orderbook","market":"ETH/USDT","type":"update","data":{"time":1651237320.646919,"checksum":3721036803,"bids":[[2861.2,2.5]],"asks":[[2862.3,0.0],[2882.9,0.015]],"action":"update"}}
1651237320.783402: {"channel":"orderbook","market":"LTC/USDT","type":"update","data":{"time":1651237320.651573,"checksum":3840777340,"bids":[],"asks":[],"action":"update"}}
1651237320.8002691: {"channel":"orderbook","market":"ETH/USD","type":"update","data":{"time":1651237320.6592362,"checksum":870662320,"bids":[],"asks":[[2861.5,17.298],[2863.4,1.662],[2873.7,0.0]],"action":"update"}}
1651237320.8003306: {"channel":"orderbook","market":"SHIB/USD","type":"update","data":{"time":1651237320.6605,"checksum":2714234374,"bids":[[0.00002258,230300000.0]],"asks":[[0.00002264,415800000.0],[0.00002267,210400000.0]],"action":"update"}}
1651237320.8073096: {"channel":"orderbook","market":"SOL/USD","type":"update","data":{"time":1651237320.6732547,"checksum":3310332149,"bids":[[95.6375,207.01]],"asks":[[95.955,71.46],[95.9675,63.17],[96.075,0.01],[96.3225,0.0],[96.3275,0.0]],"action":"update"}}
1651237320.8073745: {"channel":"orderbook","market":"ETH/USDT","type":"update","data":{"time":1651237320.6744335,"checksum":2304573324,"bids":[[2860.3,26.891],[2859.8,0.422],[2842.5,0.0]],"asks":[[2861.3,2.161],[2861.6,3.861],[2862.2,34.236],[2863.1,0.0]],"action":"update"}}
1651237320.807424: {"channel":"orderbook","market":"DAI/USD","type":"update","data":{"time":1651237320.679266,"checksum":2637841829,"bids":[],"asks":[],"action":"update"}}
1651237320.8199503: {"channel":"orderbook","market":"ETH/USD","type":"update","data":{"time":1651237320.6848938,"checksum":3769890569,"bids":[[2860.6,11.5],[2857.8,0.008],[2849.7,0.0]],"asks":[[2863.3,4.735]],"action":"update"}}
1651237320.8200002: {"channel":"orderbook","market":"SHIB/USD","type":"update","data":{"time":1651237320.6832702,"checksum":2941713321,"bids":[[0.00002259,506700000.0]],"asks":[[0.00002262,39400000.0]],"action":"update"}}
1651237320.8361654: {"channel":"orderbook","market":"ETH/USDT","type":"update","data":{"time":1651237320.6982467,"checksum":2174802284,"bids":[],"asks":[[2861.6,2.5]],"action":"update"}}
1651237320.8389256: {"channel":"orderbook","market":"SOL/USD","type":"update","data":{"time":1651237320.705361,"checksum":1954902676,"bids":[[95.7925,167.85]],"asks":[[95.95,31.29],[96.125,61.16],[96.32,0.0]],"action":"update"}}
1651237320.853041: {"channel":"orderbook","market":"ETH/USDT","type":"update","data":{"time":1651237320.7222433,"checksum":2830186794,"bids":[],"asks":[[2862.0,1.963]],"action":"update"}}
1651237320.8723989: {"channel":"orderbook","market":"ETH/USD","type":"update","data":{"time":1651237320.7101784,"checksum":1734380639,"bids":[[2860.6,11.151]],"asks":[[2861.7,0.0],[2862.1,10.913],[2867.6,6.993],[2873.7,0.001]],"action":"update"}}
1651237320.8785448: {"channel":"orderbook","market":"ETH/USDT","type":"update","data":{"time":1651237320.7472725,"checksum":1402052637,"bids":[],"asks":[[2861.9,6.277],[2862.2,53.589]],"action":"update"}}
1651237320.8894398: {"channel":"orderbook","market":"SOL/USD","type":"update","data":{"time":1651237320.7490249,"checksum":4228531586,"bids":[[95.8175,51.29]],"asks":[],"action":"update"}}
1651237320.8894813: {"channel":"orderbook","market":"SHIB/USD","type":"update","data":{"time":1651237320.7586358,"checksum":2296755367,"bids":[[0.00002261,137600000.0],[0.00002257,507300000.0]],"asks":[],"action":"update"}}
1651237320.9080508: {"channel":"orderbook","market":"ETH/USD","type":"update","data":{"time":1651237320.7665224,"checksum":920345090,"bids":[[2860.9,6.606]],"asks":[],"action":"update"}}
1651237320.9081097: {"channel":"orderbook","market":"WBTC/USD","type":"update","data":{"time":1651237320.776615,"checksum":2173158622,"bids":[[38867.0,11.5582],[35496.0,0.0]],"asks":[],"action":"update"}}
1651237320.9270425: {"channel":"orderbook","market":"ETH/USD","type":"update","data":{"time":1651237320.7886298,"checksum":3688075184,"bids":[[2858.7,173.191],[2849.8,0.0]],"asks":[[2861.4,4.025],[2862.1,10.564]],"action":"update"}}
1651237320.9271185: {"channel":"orderbook","market":"ETH/USDT","type":"update","data":{"time":1651237320.7980611,"checksum":2129653401,"bids":[[2861.1,7.895]],"asks":[],"action":"update"}}
1651237320.942743: {"channel":"orderbook","market":"SHIB/USD","type":"update","data":{"time":1651237320.808756,"checksum":816537842,"bids":[],"asks":[[0.00002265,280900000.0]],"action":"update"}}
1651237320.953225: {"channel":"orderbook","market":"USD/TRY","type":"update","data":{"time":1651237320.8260882,"checksum":1861656539,"bids":[],"asks":[],"action":"update"}}
1651237320.9728851: {"channel":"orderbook","market":"SHIB/USD","type":"update","data":{"time":1651237320.8344085,"checksum":3316277475,"bids":[[0.00002261,115400000.0],[0.0000226,136200000.0],[0.00002257,491900000.0]],"asks":[],"action":"update"}}
1651237320.972935: {"channel":"orderbook","market":"ETH/USD","type":"update","data":{"time":1651237320.8346372,"checksum":2228408770,"bids":[[2858.1,4.563],[2858.0,14.971]],"asks":[[2864.6,145.261],[2867.7,0.001]],"action":"update"}}
1651237320.9729698: {"channel":"orderbook","market":"SOL/USD","type":"update","data":{"time":1651237320.8391893,"checksum":3510649807,"bids":[],"asks":[[95.925,112.55]],"action":"update"}}
1651237320.9863877: {"channel":"orderbook","market":"SHIB/USD","type":"update","data":{"time":1651237320.8576334,"checksum":3178045474,"bids":[[0.00002261,18500000.0]],"asks":[],"action":"update"}}
1651237320.9900057: {"channel":"orderbook","market":"ETH/USD","type":"update","data":{"time":1651237320.8603597,"checksum":3674636024,"bids":[],"asks":[[2862.4,34.161]],"action":"update"}}
1651237321.0163715: {"channel":"orderbook","market":"ETH/USD","type":"update","data":{"time":1651237320.8838382,"checksum":3898584064,"bids":[],"asks":[[2862.7,0.528]],"action":"update"}}
1651237321.016415: {"channel":"orderbook","market":"SHIB/USD","type":"update","data":{"time":1651237320.8833506,"checksum":424891793,"bids":[[0.00002259,501000000.0]],"asks":[[0.00002264,505800000.0]],"action":"update"}}
1651237321.0224535: {"channel":"orderbook","market":"SOL/USD","type":"update","data":{"time":1651237320.8924878,"checksum":4225608181,"bids":[[95.82,5.0],[95.6825,26.1],[95.44,0.0],[95.4375,0.0]],"asks":[],"action":"update"}}
1651237321.0316532: {"channel":"orderbook","market":"ETH/USDT","type":"update","data":{"time":1651237320.8991237,"checksum":2804714296,"bids":[[2861.2,2.496]],"asks":[],"action":"update"}}
1651237321.040932: {"channel":"orderbook","market":"SHIB/USD","type":"update","data":{"time":1651237320.9081655,"checksum":1961299158,"bids":[[0.00002258,210000000.0],[0.00002256,119200000.0],[0.00002237,9400000.0]],"asks":[[0.00002263,277800000.0],[0.00002264,511200000.0]],"action":"update"}}
1651237321.0409844: {"channel":"orderbook","market":"ETH/USD","type":"update","data":{"time":1651237320.9095988,"checksum":2494134741,"bids":[[2861.0,3.496]],"asks":[[2862.1,10.913],[2862.3,14.679],[2862.6,0.0],[2864.5,37.899],[2867.2,4.198],[2873.9,0.001]],"action":"update"}}
1651237321.05004: {"channel":"orderbook","market":"ETH/USDT","type":"update","data":{"time":1651237320.9231493,"checksum":732524807,"bids":[],"asks":[[2862.5,0.345]],"action":"update"}}
1651237321.0767958: {"channel":"orderbook","market":"SOL/USD","type":"update","data":{"time":1651237320.9399164,"checksum":1660929355,"bids":[[95.845,0.01],[95.4475,0.0]],"asks":[],"action":"update"}}
1651237321.0769048: {"channel":"orderbook","market":"ETH/USD","type":"update","data":{"time":1651237320.9352849,"checksum":2217383382,"bids":[],"asks":[[2862.5,0.085]],"action":"update"}}
1651237321.080499: {"channel":"orderbook","market":"SHIB/USD","type":"update","data":{"time":1651237320.9436715,"checksum":72593759,"bids":[[0.0000226,233100000.0],[0.00002255,210900000.0]],"asks":[[0.00002262,57400000.0],[0.00002263,375600000.0],[0.00002267,140400000.0],[0.00002269,100000.0]],"action":"update"}}
1651237321.1099658: {"channel":"orderbook","market":"LTC/USDT","type":"update","data":{"time":1651237320.972711,"checksum":925183266,"bids":[],"asks":[[100.62,0.0],[103.79,0.01]],"action":"update"}}
1651237321.1252954: {"channel":"orderbook","market":"SHIB/USD","type":"update","data":{"time":1651237320.988217,"checksum":3231000005,"bids":[],"asks":[[0.00002264,404200000.0]],"action":"update"}}
1651237321.1253715: {"channel":"orderbook","market":"SOL/USD","type":"update","data":{"time":1651237320.991523,"checksum":4239207834,"bids":[[95.8375,51.69],[95.45,0.0]],"asks":[[95.9325,0.03],[96.3175,0.0]],"action":"update"}}
1651237321.1254249: {"channel":"orderbook","market":"ETH/USD","type":"update","data":{"time":1651237320.966518,"checksum":1949363037,"bids":[],"asks":[[2862.1,10.564],[2864.4,9.475],[2873.9,0.0]],"action":"update"}}
1651237321.128579: {"channel":"orderbook","market":"ETH/USDT","type":"update","data":{"time":1651237320.9957013,"checksum":1675042263,"bids":[[2861.1,8.753]],"asks":[[2862.0,5.459]],"action":"update"}}
1651237321.1286266: {"channel":"orderbook","market":"FTT/BTC","type":"update","data":{"time":1651237320.9940913,"checksum":3048013507,"bids":[],"asks":[],"action":"update"}}
1651237321.1757474: {"channel":"orderbook","market":"SHIB/USD","type":"update","data":{"time":1651237321.0384512,"checksum":3349829588,"bids":[[0.00002239,104000000.0]],"asks":[],"action":"update"}}
1651237321.1758087: {"channel":"orderbook","market":"ETH/USDT","type":"update","data":{"time":1651237321.0418818,"checksum":1693803800,"bids":[[2860.2,25.041]],"asks":[[2862.1,13.499]],"action":"update"}}
1651237321.1866148: {"channel":"orderbook","market":"SOL/USD","type":"update","data":{"time":1651237321.0496051,"checksum":950161299,"bids":[],"asks":[[96.105,288.9]],"action":"update"}}
1651237321.190935: {"channel":"orderbook","market":"ETH/USDT","type":"update","data":{"time":1651237321.0604742,"checksum":305975672,"bids":[[2861.2,4.687]],"asks":[],"action":"update"}}
1651237321.1963558: {"channel":"orderbook","market":"ETH/USD","type":"update","data":{"time":1651237321.0450854,"checksum":1770873357,"bids":[[2861.2,0.245],[2860.7,8.679],[2860.1,9.661],[2854.4,6.107]],"asks":[[2861.3,10.043],[2861.6,4.0],[2862.0,16.113],[2862.1,29.624],[2867.8,3.031],[2873.7,0.0]],"action":"update"}}
1651237321.2208285: {"channel":"orderbook","market":"SHIB/USD","type":"update","data":{"time":1651237321.0883539,"checksum":56326937,"bids":[[0.00002257,534400000.0]],"asks":[[0.00002262,136500000.0]],"action":"update"}}
1651237321.2209241: {"channel":"orderbook","market":"LTC/USDT","type":"update","data":{"time":1651237321.0922468,"checksum":469617040,"bids":[[100.505,8.77],[100.46,14.93],[96.845,0.0]],"asks":[[100.675,0.0],[103.84,0.18]],"action":"update"}}
1651237321.2227566: {"channel":"orderbook","market":"ETH/USDT","type":"update","data":{"time":1651237321.0905116,"checksum":2460593260,"bids":[[2861.1,7.895]],"asks":[],"action":"update"}}
1651237321.222805: {"channel":"orderbook","market":"SOL/USD","type":"update","data":{"time":1651237321.0942287,"checksum":2372524840,"bids":[],"asks":[[95.985,0.0],[96.3175,0.19]],"action":"update"}}
1651237321.2415562: {"channel":"orderbook","market":"SHIB/USD","type":"update","data":{"time":1651237321.1115773,"checksum":576471221,"bids":[],"asks":[[0.00002266,143700000.0]],"action":"update"}}
1651237321.24305: {"channel":"orderbook","market":"BTC/TRY","type":"update","data":{"time":1651237321.1197274,"checksum":2549750460,"bids":[],"asks":[],"action":"update"}}
1651237321.2435575: {"channel":"orderbook","market":"ETH/USD","type":"update","data":{"time":1651237321.1062486,"checksum":4125802663,"bids":[[2861.0,0.003],[2860.3,14.612],[2859.1,0.677]],"asks":[[2862.4,33.844],[2862.6,1.326],[2873.6,0.0]],"action":"update"}}
1651237321.2456791: {"channel":"orderbook","market":"SOL/USD","type":"update","data":{"time":1651237321.1184158,"checksum":1600673032,"bids":[[95.845,0.0],[95.8425,0.0],[95.775,152.93],[95.45,0.39],[95.4475,0.03]],"asks":[],"action":"update"}}
1651237321.2492235: {"channel":"orderbook","market":"USD/TRY","type":"update","data":{"time":1651237321.1257815,"checksum":1325857698,"bids":[],"asks":[[16.029,0.0]],"action":"update"}}
1651237321.2583473: {"channel":"orderbook","market":"ETH/USDT","type":"update","data":{"time":1651237321.1212277,"checksum":2421509333,"bids":[[2860.2,21.032],[2860.0,9.291]],"asks":[[2863.0,0.23],[2863.2,0.912],[2882.9,0.0]],"action":"update"}}
1651237321.266956: {"channel":"orderbook","market":"ETH/USDT","type":"update","data":{"time":1651237321.1380868,"checksum":2421509333,"bids":[],"asks":[],"action":"update"}}
1651237321.2695365: {"channel":"orderbook","market":"ETH/USD","type":"update","data":{"time":1651237321.135763,"checksum":3971690812,"bids":[[2859.7,15.441]],"asks":[[2862.1,29.973],[2866.8,0.002]],"action":"update"}}
1651237321.2922325: {"channel":"orderbook","market":"ETH/USD","type":"update","data":{"time":1651237321.1603556,"checksum":2205510402,"bids":[[2860.8,6.14],[2859.7,15.758]],"asks":[[2862.8,0.814],[2863.0,0.667]],"action":"update"}}
1651237321.2922852: {"channel":"orderbook","market":"ETH/USDT","type":"update","data":{"time":1651237321.1627238,"checksum":145904538,"bids":[[2860.2,25.041]],"asks":[[2861.7,9.013]],"action":"update"}}
1651237321.292317: {"channel":"orderbook","market":"SHIB/USD","type":"update","data":{"time":1651237321.1634839,"checksum":1651613655,"bids":[],"asks":[[0.00002263,397800000.0]],"action":"update"}}
1651237321.3050516: {"channel":"orderbook","market":"SOL/USD","type":"update","data":{"time":1651237321.1717782,"checksum":2427059517,"bids":[],"asks":[[95.8575,0.0],[95.925,7.26],[96.32,0.01]],"action":"update"}}
1651237321.3254125: {"channel":"orderbook","market":"ETH/USDT","type":"update","data":{"time":1651237321.1877265,"checksum":2021507983,"bids":[[2860.8,0.0],[2842.5,835.588]],"asks":[],"action":"update"}}
1651237321.3545337: {"channel":"orderbook","market":"SOL/USD","type":"update","data":{"time":1651237321.2009304,"checksum":1881473853,"bids":[],"asks":[[95.8525,290.0],[96.32,0.0]],"action":"update"}}
1651237321.3545818: {"channel":"orderbook","market":"ETH/USDT","type":"update","data":{"time":1651237321.2123885,"checksum":2803573405,"bids":[],"asks":[[2862.0,1.963]],"action":"update"}}
1651237321.3546076: {"channel":"orderbook","market":"SOL/USD","type":"update","data":{"time":1651237321.217751,"checksum":2672740533,"bids":[],"asks":[[95.9325,0.0],[96.32,0.01]],"action":"update"}}
1651237321.354637: {"channel":"orderbook","market":"ETH/USD","type":"update","data":{"time":1651237321.2170858,"checksum":3194090031,"bids":[[2858.5,1.566]],"asks":[[2861.9,3.008],[2862.0,12.617],[2862.1,29.624]],"action":"update"}}
1651237321.3635337: {"channel":"orderbook","market":"ETH/USD","type":"update","data":{"time":1651237321.228373,"checksum":3426036225,"bids":[[2858.4,0.001]],"asks":[[2862.4,28.183]],"action":"update"}}
1651237321.375013: {"channel":"orderbook","market":"SOL/USD","type":"update","data":{"time":1651237321.2429945,"checksum":2874491466,"bids":[[95.6825,0.0],[95.44,1.0]],"asks":[[95.855,0.0],[96.3225,0.62]],"action":"update"}}
1651237321.3750784: {"channel":"orderbook","market":"WBTC/USD","type":"update","data":{"time":1651237321.2405884,"checksum":2173158622,"bids":[],"asks":[],"action":"update"}}
1651237321.38552: {"channel":"orderbook","market":"ETH/USD","type":"update","data":{"time":1651237321.2556841,"checksum":3465537308,"bids":[[2861.0,0.0],[2849.8,0.032]],"asks":[[2861.3,10.044],[2861.6,3.997],[2862.3,14.33]],"action":"update"}}
1651237321.3971648: {"channel":"orderbook","market":"ETH/USDT","type":"update","data":{"time":1651237321.2665794,"checksum":3460614248,"bids":[[2861.0,0.322]],"asks":[[2861.6,4.248],[2862.4,6.534]],"action":"update"}}
1651237321.402292: {"channel":"orderbook","market":"SOL/USD","type":"update","data":{"time":1651237321.2691627,"checksum":2874491466,"bids":[],"asks":[],"action":"update"}}
1651237321.417005: {"channel":"orderbook","market":"ETH/USD","type":"update","data":{"time":1651237321.28329,"checksum":64058302,"bids":[[2858.8,9.603],[2858.1,6.684]],"asks":[[2861.9,9.969],[2863.4,54.909]],"action":"update"}}
1651237321.417081: {"channel":"orderbook","market":"ETH/USDT","type":"update","data":{"time":1651237321.2895908,"checksum":2869382422,"bids":[[2861.1,4.529],[2860.0,12.787]],"asks":[[2861.3,2.322],[2862.1,35.582]],"action":"update"}}
1651237321.4325402: {"channel":"orderbook","market":"SOL/USD","type":"update","data":{"time":1651237321.302551,"checksum":3618313651,"bids":[[95.7675,229.21]],"asks":[[95.85,36.0],[96.3225,0.0]],"action":"update"}}
1651237321.4326057: {"channel":"orderbook","market":"ETH/USD","type":"update","data":{"time":1651237321.3031237,"checksum":95309219,"bids":[[2860.9,2.813],[2860.3,14.263]],"asks":[[2862.1,10.564],[2863.5,0.273],[2864.5,1.575]],"action":"update"}}
1651237321.450343: {"channel":"orderbook","market":"ETH/USDT","type":"update","data":{"time":1651237321.3166254,"checksum":2462739047,"bids":[[2861.1,0.0],[2842.2,0.001]],"asks":[[2862.2,34.236]],"action":"update"}}
1651237321.4504085: {"channel":"orderbook","market":"SOL/USD","type":"update","data":{"time":1651237321.3183641,"checksum":831572338,"bids":[],"asks":[[95.915,175.3],[95.965,62.7]],"action":"update"}}
1651237321.457331: {"channel":"orderbook","market":"ETH/USD","type":"update","data":{"time":1651237321.3312287,"checksum":2606941667,"bids":[],"asks":[[2862.1,10.913],[2863.3,18.464],[2864.4,0.0],[2864.5,25.176],[2873.6,4.007]],"action":"update"}}
1651237321.4712865: {"channel":"orderbook","market":"LTC/USDT","type":"update","data":{"time":1651237321.3413877,"checksum":1645522160,"bids":[],"asks":[[100.705,0.0],[103.91,0.02]],"action":"update"}}
1651237321.4713447: {"channel":"orderbook","market":"SOL/USD","type":"update","data":{"time":1651237321.3431463,"checksum":610145592,"bids":[[95.68,26.1],[95.44,0.0]],"asks":[],"action":"update"}}
1651237321.4713857: {"channel":"orderbook","market":"ETH/USDT","type":"update","data":{"time":1651237321.3411667,"checksum":731230054,"bids":[[2861.2,2.496],[2860.4,5.947]],"asks":[[2862.2,3.496]],"action":"update"}}
1651237321.4870431: {"channel":"orderbook","market":"ETH/USD","type":"update","data":{"time":1651237321.3556917,"checksum":190508112,"bids":[[2861.2,0.056]],"asks":[[2861.6,5.745],[2861.8,6.989],[2861.9,10.318]],"action":"update"}}
1651237321.4939878: {"channel":"orderbook","market":"ETH/USDT","type":"update","data":{"time":1651237321.3628254,"checksum":1077450942,"bids":[],"asks":[[2862.1,22.181]],"action":"update"}}
1651237321.5050852: {"channel":"orderbook","market":"SOL/USD","type":"update","data":{"time":1651237321.3706121,"checksum":1037852285,"bids":[[95.7925,62.55],[95.7825,0.72]],"asks":[],"action":"update"}}
1651237321.5093687: {"channel":"orderbook","market":"ETH/USD","type":"update","data":{"time":1651237321.3783803,"checksum":3016067904,"bids":[[2860.9,2.855]],"asks":[[2862.1,10.564]],"action":"update"}}
1651237321.5170674: {"channel":"orderbook","market":"SOL/USD","type":"update","data":{"time":1651237321.3916693,"checksum":1785244877,"bids":[[95.7175,61.0],[95.4475,0.0]],"asks":[[95.8475,11.19],[96.32,0.0]],"action":"update"}}
1651237321.5403583: {"channel":"orderbook","market":"SHIB/USD","type":"update","data":{"time":1651237321.3926194,"checksum":308001842,"bids":[[0.00002257,434500000.0]],"asks":[],"action":"update"}}
1651237321.5404246: {"channel":"orderbook","market":"ETH/USDT","type":"update","data":{"time":1651237321.401955,"checksum":3458039038,"bids":[[2861.2,0.0],[2860.7,4.761],[2842.0,2.155]],"asks":[],"action":"update"}}
1651237321.5404792: {"channel":"orderbook","market":"ETH/USD","type":"update","data":{"time":1651237321.4041588,"checksum":1061553624,"bids":[[2860.5,43.921]],"asks":[[2864.4,6.298],[2873.6,0.0]],"action":"update"}}
1651237321.5524452: {"channel":"orderbook","market":"SOL/USD","type":"update","data":{"time":1651237321.4191184,"checksum":370660569,"bids":[[95.8225,0.0],[95.8175,31.29],[95.4475,0.03]],"asks":[[95.8625,7.26]],"action":"update"}}
1651237321.5642526: {"channel":"orderbook","market":"ETH/USD","type":"update","data":{"time":1651237321.4297452,"checksum":2036667801,"bids":[],"asks":[[2862.9,23.936]],"action":"update"}}
1651237321.5681593: {"channel":"orderbook","market":"LTC/USDT","type":"update","data":{"time":1651237321.4413383,"checksum":1931527408,"bids":[],"asks":[[100.665,4.96],[103.91,0.0]],"action":"update"}}
1651237321.5699923: {"channel":"orderbook","market":"ETH/USDT","type":"update","data":{"time":1651237321.4415622,"checksum":78611843,"bids":[[2861.0,2.822]],"asks":[[2861.3,0.322],[2861.7,2.095],[2863.3,0.0],[2882.9,0.015]],"action":"update"}}
1651237321.5796556: {"channel":"orderbook","market":"SOL/USD","type":"update","data":{"time":1651237321.4457877,"checksum":75911358,"bids":[[95.8375,0.0],[95.825,0.0],[95.44,1.0],[95.4375,0.01]],"asks":[[95.9575,33.42]],"action":"update"}}
1651237321.5857024: {"channel":"orderbook","market":"WBTC/USD","type":"update","data":{"time":1651237321.457358,"checksum":14008754,"bids":[[38914.0,0.0107],[35587.0,0.0]],"asks":[],"action":"update"}}
1651237321.5898235: {"channel":"orderbook","market":"ETH/USD","type":"update","data":{"time":1651237321.4566066,"checksum":1079261548,"bids":[[2858.1,6.502]],"asks":[],"action":"update"}}
1651237321.5984046: {"channel":"orderbook","market":"ETH/USDT","type":"update","data":{"time":1651237321.4688947,"checksum":1421568152,"bids":[[2860.4,12.229],[2860.3,21.227]],"asks":[],"action":"update"}}
1651237321.6082387: {"channel":"orderbook","market":"ETH/USD","type":"update","data":{"time":1651237321.4792733,"checksum":3651478528,"bids":[],"asks":[[2862.8,6.803]],"action":"update"}}
1651237321.6160316: {"channel":"orderbook","market":"SOL/USD","type":"update","data":{"time":1651237321.4812489,"checksum":1636395681,"bids":[[95.8125,0.0],[95.7525,0.0],[95.435,0.01],[95.43,0.25]],"asks":[[95.955,0.0],[96.32,0.01]],"action":"update"}}
1651237321.6252692: {"channel":"orderbook","market":"SHIB/USD","type":"update","data":{"time":1651237321.4926233,"checksum":308001842,"bids":[],"asks":[],"action":"update"}}
1651237321.6580827: {"channel":"orderbook","market":"SOL/USD","type":"update","data":{"time":1651237321.505654,"checksum":3594692868,"bids":[[95.8325,7.3],[95.83,51.69],[95.8075,90.0],[95.795,14.06],[95.435,0.0],[95.43,0.0]],"asks":[[95.85,132.9],[95.8775,56.93],[95.95,0.0],[95.995,607.4]],"action":"update"}}
1651237321.6581514: {"channel":"orderbook","market":"ETH/USDT","type":"update","data":{"time":1651237321.5122309,"checksum":3568322836,"bids":[[2860.3,10.184]],"asks":[[2861.2,2.0],[2862.0,3.16],[2862.7,2.877],[2862.9,20.007],[2882.9,0.0]],"action":"update"}}
1651237321.658198: {"channel":"orderbook","market":"ETH/USDT","type":"update","data":{"time":1651237321.5273294,"checksum":2093233476,"bids":[[2860.5,6.557]],"asks":[[2862.0,8.711],[2862.1,33.829],[2862.6,0.0],[2882.9,0.015]],"action":"update"}}
1651237321.6582384: {"channel":"orderbook","market":"WBTC/USD","type":"update","data":{"time":1651237321.5237675,"checksum":3912389601,"bids":[[38907.0,0.0],[38858.0,0.0],[35587.0,0.0016],[35496.0,0.0001]],"asks":[],"action":"update"}}
1651237321.6582766: {"channel":"orderbook","market":"ETH/USD","type":"update","data":{"time":1651237321.5302958,"checksum":3036606710,"bids":[],"asks":[[2862.1,10.913]],"action":"update"}}
1651237321.674294: {"channel":"orderbook","market":"ETH/USDT","type":"update","data":{"time":1651237321.5475073,"checksum":3511066490,"bids":[[2860.2,21.032]],"asks":[[2861.3,2.417]],"action":"update"}}
1651237321.68071: {"channel":"orderbook","market":"ETH/USD","type":"update","data":{"time":1651237321.5537145,"checksum":431289952,"bids":[[2860.0,24.994]],"asks":[],"action":"update"}}
1651237321.68601: {"channel":"orderbook","market":"SOL/USD","type":"update","data":{"time":1651237321.548096,"checksum":1123903191,"bids":[[95.8325,0.0],[95.82,0.0],[95.8075,0.0],[95.7875,0.0],[95.435,0.01],[95.43,0.25],[95.425,1.23],[95.4225,0.12]],"asks":[[95.85,205.35],[95.8625,60.46],[95.865,0.64],[95.965,0.06],[95.9725,540.15],[95.995,7.26],[96.32,0.0]],"action":"update"}}
1651237321.702374: {"channel":"orderbook","market":"ETH/USDT","type":"update","data":{"time":1651237321.5729358,"checksum":4019425418,"bids":[],"asks":[[2861.3,2.095]],"action":"update"}}
1651237321.7059033: {"channel":"orderbook","market":"SOL/USD","type":"update","data":{"time":1651237321.576721,"checksum":1831444096,"bids":[[95.8175,0.0],[95.795,8.62],[95.7925,0.0],[95.41,0.01],[95.4075,0.47]],"asks":[[95.88,0.0],[95.915,105.3],[95.945,252.45],[96.0075,0.0],[96.32,0.01]],"action":"update"}}
1651237321.711941: {"channel":"orderbook","market":"ETH/USD","type":"update","data":{"time":1651237321.5809019,"checksum":1964443494,"bids":[[2857.9,0.0],[2849.7,0.01]],"asks":[[2864.6,308.702]],"action":"update"}}
1651237321.71993: {"channel":"orderbook","market":"SOL/USD","type":"update","data":{"time":1651237321.5923133,"checksum":1738526442,"bids":[[95.725,33.8]],"asks":[],"action":"update"}}
1651237321.7302237: {"channel":"orderbook","market":"ETH/USDT","type":"update","data":{"time":1651237321.598398,"checksum":3701842540,"bids":[[2859.5,10.836],[2842.0,0.0]],"asks":[[2861.9,6.451]],"action":"update"}}
1651237321.73529: {"channel":"orderbook","market":"ETH/USD","type":"update","data":{"time":1651237321.6049545,"checksum":3474824607,"bids":[],"asks":[[2862.1,10.564],[2868.3,2.062]],"action":"update"}}
1651237321.750578: {"channel":"orderbook","market":"SOL/USD","type":"update","data":{"time":1651237321.6172104,"checksum":3849633276,"bids":[[95.81,0.0],[95.68,0.0],[95.4,43.17],[95.3975,0.17]],"asks":[[95.915,0.0],[95.9275,0.0],[95.945,0.0],[96.1925,0.0],[96.3225,0.62],[96.3275,0.01],[96.33,0.26],[96.3325,0.13]],"action":"update"}}
1651237321.7571526: {"channel":"orderbook","market":"ETH/USDT","type":"update","data":{"time":1651237321.623924,"checksum":4225451735,"bids":[[2861.1,0.745],[2860.4,6.38],[2842.2,0.0]],"asks":[[2863.1,0.182],[2882.9,0.0]],"action":"update"}}
1651237321.7572064: {"channel":"orderbook","market":"ETH/USD","type":"update","data":{"time":1651237321.6300228,"checksum":3292319067,"bids":[],"asks":[[2861.3,12.044]],"action":"update"}}
1651237321.7885358: {"channel":"orderbook","market":"SOL/USD","type":"update","data":{"time":1651237321.6445768,"checksum":1349515608,"bids":[[95.795,28.62],[95.7825,106.04],[95.765,474.09],[95.7425,0.0],[95.39,1459.97]],"asks":[[96.0,134.87]],"action":"update"}}
1651237321.788597: {"channel":"orderbook","market":"ETH/USDT","type":"update","data":{"time":1651237321.6500494,"checksum":2532550010,"bids":[[2861.1,2.745],[2861.0,3.68],[2860.8,24.65],[2842.5,0.0]],"asks":[[2865.0,0.143]],"action":"update"}}
1651237321.791583: {"channel":"orderbook","market":"ETH/USD","type":"update","data":{"time":1651237321.6539645,"checksum":3292319067,"bids":[],"asks":[],"action":"update"}}
1651237321.8081322: {"channel":"orderbook","market":"SOL/USD","type":"update","data":{"time":1651237321.6677008,"checksum":2098801005,"bids":[[95.7975,5.0],[95.39,0.0]],"asks":[[95.85,334.33],[95.9275,31.3],[95.9675,167.48],[96.065,0.0]],"action":"update"}}
1651237321.8175004: {"channel":"orderbook","market":"LTC/USDT","type":"update","data":{"time":1651237321.6769514,"checksum":1931527408,"bids":[],"asks":[],"action":"update"}}
1651237321.81753: {"channel":"orderbook","market":"SHIB/USD","type":"update","data":{"time":1651237321.6874793,"checksum":4078941944,"bids":[[0.00002255,189900000.0]],"asks":[],"action":"update"}}
1651237321.8372245: {"channel":"orderbook","market":"ETH/USDT","type":"update","data":{"time":1651237321.701071,"checksum":677886355,"bids":[[2861.1,2.0],[2860.2,25.041]],"asks":[[2861.3,0.0],[2861.9,6.277],[2882.9,0.015]],"action":"update"}}
1651237321.8372982: {"channel":"orderbook","market":"DAI/USD","type":"update","data":{"time":1651237321.7038178,"checksum":2637841829,"bids":[],"asks":[],"action":"update"}}
1651237321.83733: {"channel":"orderbook","market":"SOL/USD","type":"update","data":{"time":1651237321.7103496,"checksum":3395154701,"bids":[[95.795,98.62],[95.7725,169.05],[95.71,131.86],[95.685,19.14],[95.3975,0.0]],"asks":[[95.8775,0.0],[96.3375,0.29]],"action":"update"}}
1651237321.8409698: {"channel":"orderbook","market":"ETH/USD","type":"update","data":{"time":1651237321.7084177,"checksum":4190296006,"bids":[],"asks":[[2861.3,12.042],[2861.4,4.023]],"action":"update"}}
1651237321.8481107: {"channel":"orderbook","market":"SOL/USD","type":"update","data":{"time":1651237321.7194405,"checksum":2826338000,"bids":[[95.7975,0.0],[95.3975,0.17]],"asks":[],"action":"update"}}
1651237321.8666894: {"channel":"orderbook","market":"SHIB/USD","type":"update","data":{"time":1651237321.7379184,"checksum":2247033441,"bids":[],"asks":[[0.00002264,469700000.0]],"action":"update"}}
1651237321.8828635: {"channel":"orderbook","market":"SOL/USD","type":"update","data":{"time":1651237321.7499366,"checksum":3328305855,"bids":[[95.61,86.98]],"asks":[],"action":"update"}}
1651237321.887078: {"channel":"orderbook","market":"ETH/USD","type":"update","data":{"time":1651237321.7580361,"checksum":4131489770,"bids":[[2858.0,3.934]],"asks":[[2864.3,0.0],[2873.6,4.007]],"action":"update"}}
1651237321.901316: {"channel":"orderbook","market":"ETH/USDT","type":"update","data":{"time":1651237321.7734396,"checksum":220760107,"bids":[[2861.1,0.0],[2842.5,835.588]],"asks":[],"action":"update"}}
1651237321.9088638: {"channel":"orderbook","market":"ETH/USD","type":"update","data":{"time":1651237321.7774827,"checksum":1981400970,"bids":[[2860.9,2.813],[2860.0,24.645]],"asks":[],"action":"update"}}
1651237321.921728: {"channel":"orderbook","market":"SOL/USD","type":"update","data":{"time":1651237321.7849584,"checksum":2588893196,"bids":[[95.6625,10.89],[95.6375,22.4],[95.3975,0.0]],"asks":[],"action":"update"}}
1651237321.9249473: {"channel":"orderbook","market":"LTC/USDT","type":"update","data":{"time":1651237321.7957952,"checksum":233514344,"bids":[[100.565,17.66]],"asks":[],"action":"update"}}
1651237321.9319408: {"channel":"orderbook","market":"ETH/USDT","type":"update","data":{"time":1651237321.8021417,"checksum":3844112693,"bids":[[2861.0,2.822]],"asks":[[2861.2,2.161],[2862.2,0.0],[2883.0,0.029]],"action":"update"}}
1651237321.9320168: {"channel":"orderbook","market":"ETH/USD","type":"update","data":{"time":1651237321.8027036,"checksum":836324848,"bids":[[2860.7,5.184],[2858.8,20.642]],"asks":[[2861.6,1.748],[2862.1,10.913]],"action":"update"}}
1651237321.955007: {"channel":"orderbook","market":"ETH/USDT","type":"update","data":{"time":1651237321.8242264,"checksum":489065706,"bids":[[2860.8,0.0],[2860.0,5.794],[2842.2,0.001]],"asks":[[2861.2,0.161],[2862.1,11.746]],"action":"update"}}
1651237321.95506: {"channel":"orderbook","market":"SOL/USD","type":"update","data":{"time":1651237321.8256338,"checksum":2813175176,"bids":[],"asks":[[95.88,70.0],[96.025,26.13],[96.3375,0.0]],"action":"update"}}
