wss://ftxtr.com/ws/ <- 1651237298.0944762: {"channel":"orderbook","market":"USD/TRY","op":"subscribe"}
wss://ftxtr.com/ws/ <- 1651237298.0945063: {"channel":"orderbook","market":"ETH/USD","op":"subscribe"}
wss://ftxtr.com/ws/ <- 1651237298.0945346: {"channel":"orderbook","market":"DAI/USD","op":"subscribe"}
wss://ftxtr.com/ws/ <- 1651237298.0945625: {"channel":"orderbook","market":"FTT/BTC","op":"subscribe"}
wss://ftxtr.com/ws/ <- 1651237298.0945904: {"channel":"orderbook","market":"ETH/USDT","op":"subscribe"}
wss://ftxtr.com/ws/ <- 1651237298.094618: {"channel":"orderbook","market":"LTC/USDT","op":"subscribe"}
wss://ftxtr.com/ws/ <- 1651237298.0946455: {"channel":"orderbook","market":"SHIB/USD","op":"subscribe"}
wss://ftxtr.com/ws/ <- 1651237298.094673: {"channel":"orderbook","market":"SOL/USD","op":"subscribe"}
wss://ftxtr.com/ws/ <- 1651237298.0947006: {"channel":"orderbook","market":"WBTC/USD","op":"subscribe"}
wss://ftxtr.com/ws/ <- 1651237298.0947278: {"channel":"orderbook","market":"BTC/TRY","op":"subscribe"}
1651237298.5956185: {"type":"subscribed","channel":"orderbook","market":"USD/TRY"}
1651237298.5956542: {"type":"subscribed","channel":"orderbook","market":"ETH/USD"}
1651237298.5956633: {"type":"subscribed","channel":"orderbook","market":"DAI/USD"}
1651237298.5956707: {"type":"subscribed","channel":"orderbook","market":"FTT/BTC"}
1651237298.5956776: {"type":"subscribed","channel":"orderbook","market":"ETH/USDT"}
1651237298.5956848: {"type":"subscribed","channel":"orderbook","market":"LTC/USDT"}
1651237298.5956914: {"type":"subscribed","channel":"orderbook","market":"SHIB/USD"}
1651237298.5956984: {"type":"subscribed","channel":"orderbook","market":"SOL/USD"}
1651237298.595705: {"type":"subscribed","channel":"orderbook","market":"WBTC/USD"}
1651237298.595712: {"type":"subscribed","channel":"orderbook","market":"BTC/TRY"}
1651237298.5957747: {"channel":"orderbook","market":"ETH/USD","type":"partial","data":{"time":1651237298.3807747,"checksum":1804045357,"bids":[[2861.7,24.768],[2861.6,8.744],[2861.5,19.343],[2861.2,3.493],[2861.1,27.342],[2861.0,6.13],[2860.9,6.794],[2860.8,34.707],[2860.7,7.389],[2860.6,9.977],[2860.4,20.011],[2860.3,18.701],[2860.2,6.399],[2860.1,15.779],[2860.0,5.877],[2859.9,21.343],[2859.8,5.056],[2859.7,2.041],[2859.4,12.071],[2859.2,20.66],[2859.1,127.675],[2859.0,0.174],[2858.9,4.37],[2858.8,0.523],[2858.5,0.007],[2858.4,2.122],[2858.3,2.978],[2858.1,0.018],[2858.0,4.833],[2857.6,0.374],[2857.4,1.86],[2857.2,1.577],[2857.1,1.671],[2857.0,0.012],[2856.9,0.005],[2856.8,0.758],[2856.7,0.035],[2856.6,5.258],[2856.5,0.015],[2856.3,5.284],[2856.2,0.176],[2856.1,0.541],[2856.0,6.148],[2855.9,0.062],[2855.8,7.017],[2855.7,10.93],[2855.6,3.016],[2855.5,2.635],[2855.4,0.36],[2855.3,1.948],[2855.2,7.037],[2855.1,0.014],[2855.0,0.172],[2854.9,153.883],[2854.8,0.575],[2854.7,4.2],[2854.6,0.001],[2854.5,0.221],[2854.4,6.107],[2854.3,0.489],[2854.2,7.506],[2854.1,0.013],[2854.0,11.005],[2853.9,0.101],[2853.8,0.22],[2853.7,0.023],[2853.6,4.011],[2853.3,0.06],[2853.2,0.001],[2853.1,0.103],[2853.0,0.011],[2852.9,0.279],[2852.8,4.0],[2852.7,0.116],[2852.6,0.007],[2852.5,0.01],[2852.3,0.011],[2852.2,0.001],[2852.1,0.001],[2852.0,6.157],[2851.9,0.001],[2851.8,0.529],[2851.7,0.043],[2851.6,0.202],[2851.5,0.089],[2851.4,0.023],[2851.1,0.384],[2851.0,0.016],[2850.8,0.002],[2850.7,0.083],[2850.6,0.325],[2850.5,0.013],[2850.4,512.3],[2850.3,0.007],[2850.2,0.13],[2850.1,5.654],[2850.0,2.702],[2849.9,701.833],[2849.8,0.032],[2849.7,0.01]],"asks":[[2861.8,0.004],[2861.9,0.002],[2862.0,6.76],[2862.1,0.001],[2862.2,14.194],[2862.3,0.002],[2862.4,0.349],[2862.5,1.179],[2862.6,4.381],[2862.7,17.155],[2862.8,9.161],[2863.0,4.534],[2863.1,36.926],[2863.2,23.143],[2863.3,14.526],[2863.4,1.661],[2863.5,0.007],[2863.7,0.524],[2863.8,7.539],[2863.9,30.107],[2864.0,38.776],[2864.1,4.371],[2864.2,0.002],[2864.4,0.874],[2864.5,1.575],[2864.6,0.31],[2864.7,9.136],[2864.8,36.513],[2864.9,180.23],[2865.0,0.003],[2865.1,1.745],[2865.2,2.286],[2865.3,0.021],[2865.4,3.117],[2865.5,7.503],[2865.6,4.052],[2865.7,10.924],[2865.8,0.001],[2865.9,0.02],[2866.0,2.204],[2866.1,0.001],[2866.3,0.202],[2866.4,4.275],[2866.5,0.06],[2866.6,0.747],[2866.7,585.252],[2866.8,0.001],[2866.9,0.281],[2867.0,0.01],[2867.1,2.172],[2867.2,4.198],[2867.3,0.006],[2867.4,0.03],[2867.6,6.993],[2867.7,0.001],[2868.0,9.475],[2868.1,0.003],[2868.2,3.036],[2868.3,0.006],[2868.5,0.001],[2868.7,0.156],[2868.8,4.0],[2868.9,0.002],[2869.0,0.184],[2869.1,0.001],[2869.2,0.202],[2869.3,4.0],[2869.4,2.337],[2869.5,0.001],[2869.6,37.372],[2869.9,0.024],[2870.0,2.113],[2870.4,4.034],[2870.6,0.001],[2870.8,0.001],[2871.0,0.003],[2871.1,0.001],[2871.2,4.0],[2871.3,0.124],[2871.4,28.977],[2871.5,0.01],[2871.7,0.028],[2871.8,0.084],[2872.0,10.59],[2872.1,0.202],[2872.3,0.051],[2872.6,0.005],[2872.7,0.001],[2872.8,4.022],[2872.9,0.003],[2873.1,0.003],[2873.4,0.236],[2873.5,0.015],[2873.6,4.007],[2873.7,0.001],[2873.9,0.001],[2874.0,2.281],[2874.1,472.803],[2874.2,0.146],[2874.3,0.235]],"action":"partial"}}
1651237298.6011329: {"channel":"orderbook","market":"ETH/USD","type":"update","data":{"time":1651237298.406557,"checksum":2589859504,"bids":[[2861.2,10.332],[2860.5,16.405],[2859.8,8.181],[2849.7,0.0]],"asks":[[2862.5,0.83],[2863.1,33.431],[2865.5,7.851]],"action":"update"}}
1651237298.6011958: {"channel":"orderbook","market":"ETH/USD","type":"update","data":{"time":1651237298.4311998,"checksum":1021764896,"bids":[[2860.9,6.752],[2858.5,1.756]],"asks":[[2862.7,18.455],[2864.9,179.215],[2865.5,7.503]],"action":"update"}}
1651237298.6235209: {"channel":"orderbook","market":"FTT/BTC","type":"partial","data":{"time":1651237298.492442,"checksum":4243567543,"bids":[[0.0010089,13.5],[0.0010088,2.7],[0.0010087,7.7],[0.0010086,29.2],[0.0010085,116.2],[0.0010084,16.3],[0.0010083,35.2],[0.0010082,271.3],[0.0010081,1.5],[0.001008,3.8],[0.0010079,13.3],[0.0010078,0.8],[0.0010077,1.0],[0.0010076,25.6],[0.0010075,66.5],[0.0010074,4.7],[0.0010073,76.4],[0.0010072,15.6],[0.0010071,0.7],[0.0010069,6192.0],[0.0010068,0.1],[0.0010066,0.1],[0.0010064,4.8],[0.0010063,0.4],[0.0010062,0.4],[0.0010061,0.1],[0.0010059,1.1],[0.0010058,257.2],[0.0010057,0.1],[0.0010056,0.8],[0.0010055,0.3],[0.0010054,4.8],[0.0010053,0.1],[0.0010052,0.1],[0.0010051,0.2],[0.0010049,689.7],[0.0010048,0.3],[0.0010045,1.5],[0.0010044,1364.3],[0.0010041,1.0],[0.001004,1.4],[0.0010036,8.4],[0.0010035,0.1],[0.0010034,4.8],[0.0010033,0.8],[0.0010031,0.3],[0.001003,4.2],[0.0010029,2.0],[0.0010028,2792.3],[0.0010027,123.2],[0.0010026,1.6],[0.0010025,2276.6],[0.0010024,9.6],[0.0010022,0.8],[0.0010021,0.1],[0.001002,0.5],[0.0010019,0.9],[0.0010018,0.7],[0.0010017,6.2],[0.0010016,0.2],[0.0010015,0.1],[0.0010014,1.8],[0.0010013,4.9],[0.0010012,0.3],[0.0010011,789.0],[0.001001,21.0],[0.0010008,0.4],[0.0010007,0.2],[0.0010005,10.6],[0.0010004,0.1],[0.0010003,5.1],[0.0010001,1941.8],[0.001,610.6],[0.0009999,0.1],[0.0009995,0.4],[0.0009993,22.7],[0.0009992,13.2],[0.0009991,3389.1],[0.000999,50.9],[0.0009989,0.3],[0.0009987,0.8],[0.0009986,0.8],[0.0009983,5.0],[0.0009981,8.4],[0.000998,4.0],[0.0009979,1.6],[0.0009978,0.3],[0.0009977,4.0],[0.0009976,0.8],[0.0009975,0.1],[0.0009974,5.6],[0.0009973,0.1],[0.0009972,0.7],[0.0009971,1.4],[0.000997,2.0],[0.0009969,1.3],[0.0009968,0.2],[0.0009967,3354.4],[0.0009965,1.7],[0.0009964,8.8]],"asks":[[0.0010095,13.5],[0.0010096,1.7],[0.0010097,15.6],[0.0010098,8.5],[0.0010099,30.7],[0.00101,66.5],[0.0010102,0.1],[0.0010103,1.3],[0.0010104,4.7],[0.0010107,13.3],[0.0010108,56.8],[0.0010109,329.7],[0.0010111,0.4],[0.0010112,0.5],[0.0010114,6.5],[0.0010117,2.4],[0.001012,3978.2],[0.0010122,0.1],[0.0010124,5.6],[0.0010125,0.3],[0.0010126,0.3],[0.001013,0.2],[0.0010132,0.2],[0.0010134,4.9],[0.0010135,0.4],[0.0010136,1210.9],[0.0010138,0.4],[0.001014,0.4],[0.0010141,0.2],[0.0010142,0.1],[0.0010145,13.1],[0.0010147,2.8],[0.0010148,1.1],[0.0010151,0.3],[0.0010152,82.4],[0.0010153,1.0],[0.0010154,0.2],[0.0010155,4.7],[0.0010156,0.1],[0.0010158,35.6],[0.001016,0.1],[0.0010161,0.1],[0.0010163,0.8],[0.0010165,5.0],[0.0010167,0.3],[0.0010168,0.2],[0.001017,0.8],[0.0010171,0.6],[0.0010172,0.1],[0.0010173,690.8],[0.0010175,4.9],[0.0010176,2.2],[0.0010177,0.1],[0.0010178,0.3],[0.0010179,0.3],[0.001018,2471.4],[0.0010181,2.3],[0.0010182,33.8],[0.0010183,0.6],[0.0010184,1.3],[0.0010185,4.7],[0.0010186,708.4],[0.0010187,0.1],[0.001019,0.4],[0.0010191,1.1],[0.0010192,0.8],[0.0010193,2.3],[0.0010194,0.3],[0.0010195,5.0],[0.0010196,0.1],[0.0010197,0.2],[0.0010198,0.2],[0.00102,8.7],[0.0010201,0.1],[0.0010202,1883.5],[0.0010204,1.2],[0.0010205,2.3],[0.0010206,4.7],[0.0010207,30.0],[0.0010208,0.8],[0.001021,1.1],[0.0010213,50.9],[0.0010214,0.2],[0.0010215,0.8],[0.0010216,4.9],[0.0010218,0.4],[0.001022,1.2],[0.0010221,0.2],[0.0010222,0.5],[0.0010223,3326.3],[0.0010224,0.2],[0.0010225,737.3],[0.0010226,5.4],[0.0010228,2.1],[0.0010231,30.3],[0.0010232,0.1],[0.0010233,4.1],[0.0010234,0.1],[0.0010235,2.3],[0.0010238,0.8]],"action":"partial"}}
1651237298.6362274: {"channel":"orderbook","market":"ETH/USD","type":"update","data":{"time":1651237298.4917784,"checksum":1263556708,"bids":[[2861.1,27.384],[2854.4,4.051]],"asks":[[2873.1,0.002]],"action":"update"}}
1651237298.6438549: {"channel":"orderbook","market":"ETH/USD","type":"update","data":{"time":1651237298.5170043,"checksum":1842304219,"bids":[],"asks":[[2863.5,0.356],[2869.4,0.0],[2874.4,4.004]],"action":"update"}}
1651237298.669025: {"channel":"orderbook","market":"BTC/TRY","type":"partial","data":{"time":1651237298.5367668,"checksum":1840591949,"bids":[[580057.0,1.831936],[578134.0,2.266685],[577606.0,2.754282],[577202.0,3.712343],[576603.0,4.558157],[576462.0,3.567797],[573402.0,4.948742],[573310.0,5.76669],[568001.0,0.058062],[554189.0,0.000676],[553386.0,0.972219],[544904.0,1.711326],[537184.0,1.806238],[487088.0,0.003093]],"asks":[[581678.0,2.174938],[583043.0,2.521892],[583339.0,3.538207],[584690.0,3.926051],[587097.0,3.205426],[588056.0,3.989853],[590433.0,5.811851],[592153.0,4.801843],[593142.0,0.005324],[594000.0,0.006869],[596126.0,0.005325],[599000.0,0.003367],[602671.0,0.01916],[606047.0,4.978201],[607500.0,0.01047],[616366.0,6.48147],[621059.0,0.000331],[629348.0,11.459434]],"action":"partial"}}
1651237298.829649: {"channel":"orderbook","market":"ETH/USD","type":"update","data":{"time":1651237298.566552,"checksum":1479773264,"bids":[[2861.7,22.131],[2856.8,4.758]],"asks":[],"action":"update"}}
1651237298.829805: {"channel":"orderbook","market":"ETH/USD","type":"update","data":{"time":1651237298.605835,"checksum":775051117,"bids":[[2861.7,22.104],[2856.3,4.284],[2855.8,10.052]],"asks":[[2862.6,4.73],[2865.6,4.4]],"action":"update"}}
1651237298.8298535: {"channel":"orderbook","market":"ETH/USDT","type":"partial","data":{"time":1651237298.6103275,"checksum":1990313821,"bids":[[2861.9,4.05],[2861.7,5.87],[2861.6,13.45],[2861.5,12.882],[2861.4,11.9],[2861.2,6.843],[2861.1,0.184],[2860.8,19.634],[2860.6,6.917],[2860.5,11.447],[2860.4,9.969],[2860.3,2.386],[2860.2,5.0],[2860.0,1.979],[2859.7,0.175],[2859.6,11.363],[2859.5,28.6],[2859.4,5.0],[2859.3,0.807],[2859.1,5.0],[2859.0,0.011],[2858.6,11.793],[2858.5,157.797],[2858.4,0.526],[2858.3,2.354],[2858.2,2.162],[2858.0,2.306],[2857.7,5.0],[2857.6,0.365],[2857.5,4.967],[2857.4,5.0],[2857.1,0.002],[2857.0,0.038],[2856.9,0.003],[2856.8,0.75],[2856.7,0.015],[2856.5,0.333],[2856.4,1.852],[2856.3,5.207],[2856.1,0.054],[2856.0,12.961],[2855.9,0.003],[2855.8,0.918],[2855.7,0.731],[2855.5,1.49],[2855.4,7.068],[2855.0,0.103],[2854.8,1.706],[2854.4,2.363],[2854.2,0.023],[2854.0,1.948],[2853.9,0.1],[2853.7,0.001],[2853.0,0.056],[2852.7,0.011],[2852.6,0.001],[2852.5,0.021],[2852.2,15.666],[2852.1,0.001],[2852.0,2.172],[2851.9,0.001],[2851.7,0.002],[2851.5,0.116],[2851.4,0.003],[2851.3,0.011],[2851.0,483.224],[2850.5,0.001],[2850.3,0.034],[2850.1,0.013],[2850.0,2.345],[2849.5,0.035],[2849.3,0.019],[2849.1,68.276],[2849.0,610.841],[2848.3,0.002],[2848.0,2.093],[2847.9,0.048],[2847.5,0.02],[2847.4,0.001],[2847.0,0.003],[2846.9,0.005],[2846.6,0.009],[2846.3,0.059],[2846.2,0.054],[2846.0,92.245],[2845.5,1.0],[2845.4,0.013],[2845.3,0.001],[2845.0,0.022],[2844.9,0.003],[2844.7,0.006],[2844.4,0.004],[2844.2,692.689],[2844.1,0.005],[2844.0,2.126],[2843.5,0.019],[2843.4,1.166],[2843.3,0.022],[2843.0,0.016],[2842.8,0.01]],"asks":[[2862.0,2.061],[2862.3,2.543],[2862.5,4.077],[2862.6,11.445],[2862.7,11.309],[2862.8,1.747],[2862.9,3.495],[2863.0,0.347],[2863.2,9.978],[2863.3,0.175],[2863.4,0.365],[2863.5,0.729],[2863.7,1.248],[2863.8,19.835],[2863.9,2.354],[2864.0,2.335],[2864.4,4.37],[2864.7,0.055],[2864.8,136.435],[2865.0,0.056],[2865.4,11.91],[2865.6,6.993],[2865.9,15.698],[2866.0,2.149],[2866.3,10.924],[2866.5,15.267],[2866.6,1.45],[2867.0,0.028],[2867.5,0.01],[2867.7,0.438],[2868.0,2.211],[2868.3,0.018],[2868.7,0.001],[2869.0,0.028],[2869.9,0.042],[2870.0,35.399],[2870.2,0.004],[2870.4,497.404],[2870.5,0.009],[2871.0,0.029],[2871.9,0.001],[2872.0,1.942],[2872.5,1.947],[2872.6,0.01],[2873.0,0.03],[2873.7,1.166],[2874.0,1.995],[2874.3,0.001],[2874.5,0.078],[2874.7,0.009],[2875.0,0.049],[2875.1,0.001],[2875.3,667.127],[2875.6,0.15],[2876.0,2.079],[2876.2,0.014],[2876.3,0.038],[2876.4,0.009],[2876.5,46.836],[2876.6,783.807],[2876.8,0.003],[2876.9,0.056],[2877.0,0.032],[2877.1,0.006],[2877.2,0.01],[2877.3,0.005],[2877.5,0.054],[2877.9,0.056],[2878.0,2.129],[2878.6,0.15],[2878.9,0.002],[2879.0,0.034],[2879.1,1.705],[2879.3,0.016],[2879.4,0.005],[2879.5,0.01],[2879.6,0.003],[2879.7,0.003],[2879.8,0.399],[2879.9,0.002],[2880.0,2.422],[2880.1,0.003],[2880.2,0.004],[2880.5,0.009],[2880.9,0.024],[2881.0,1.767],[2881.2,0.019],[2881.4,58.5],[2881.6,0.177],[2881.8,0.004],[2882.0,0.049],[2882.1,0.011],[2882.2,0.011],[2882.4,0.035],[2882.5,0.01],[2882.6,0.1],[2882.9,0.015],[2883.0,0.029],[2883.1,0.3],[2883.5,0.032]],"action":"partial"}}
1651237298.8302734: {"channel":"orderbook","market":"ETH/USD","type":"update","data":{"time":1651237298.629846,"checksum":1918699918,"bids":[],"asks":[[2865.0,0.038]],"action":"update"}}
1651237298.8303237: {"channel":"orderbook","market":"ETH/USDT","type":"update","data":{"time":1651237298.6402538,"checksum":2695640017,"bids":[[2860.4,5.96]],"asks":[],"action":"update"}}
1651237298.8303733: {"channel":"orderbook","market":"ETH/USD","type":"update","data":{"time":1651237298.656622,"checksum":2140873851,"bids":[[2858.1,0.011]],"asks":[[2864.1,6.412],[2865.6,4.052]],"action":"update"}}
1651237298.8304377: {"channel":"orderbook","market":"WBTC/USD","type":"partial","data":{"time":1651237298.6662374,"checksum":2222418553,"bids":[[38943.0,0.0002],[38925.0,0.0193],[38920.0,0.0001],[38900.0,0.1114],[38899.0,0.0107],[38894.0,0.0771],[38879.0,0.0292],[38878.0,11.9535],[38846.0,0.007],[38815.0,0.0016],[38814.0,14.8212],[38809.0,0.0001],[38794.0,0.2569],[38779.0,23.8632],[38709.0,0.0148],[38708.0,20.2315],[38703.0,23.5473],[38699.0,0.0001],[38691.0,37.0203],[38665.0,42.8447],[38630.0,32.0292],[38625.0,34.4586],[38606.0,0.0005],[38603.0,0.0008],[38600.0,0.5],[38597.0,0.0803],[38596.0,35.1158],[38588.0,0.0001],[38551.0,43.7684],[38510.0,32.0236],[38500.0,0.5],[38478.0,0.0001],[38402.0,0.0008],[38400.0,0.7603],[38397.0,0.0133],[38368.0,0.0001],[38300.0,0.261],[38264.0,0.0002],[38257.0,0.0001],[38201.0,0.0009],[38200.0,0.2617],[38147.0,0.0001],[38100.0,0.2624],[38050.0,0.0001],[38036.0,0.0001],[38000.0,0.264],[37926.0,0.0001],[37900.0,0.2638],[37815.0,0.0001],[37801.0,0.0005],[37800.0,0.2645],[37799.0,0.001],[37705.0,0.0001],[37700.0,0.2652],[37600.0,0.2659],[37598.0,0.001],[37594.0,0.0001],[37552.0,0.0002],[37507.0,0.0005],[37500.0,0.2666],[37484.0,0.0001],[37400.0,0.2673],[37397.0,0.0011],[37374.0,0.0001],[37353.0,0.0009],[37300.0,0.268],[37263.0,0.0001],[37200.0,0.2687],[37196.0,0.0011],[37153.0,0.0001],[37100.0,0.2695],[37042.0,0.0001],[37026.0,0.0017],[37000.0,0.27],[36996.0,0.0036],[36995.0,0.0018],[36973.0,0.0017],[36932.0,0.0001],[36841.0,0.0002],[36821.0,0.0001],[36793.0,0.0012],[36711.0,0.0001],[36667.0,0.0017],[36600.0,0.0001],[36592.0,0.0013],[36490.0,0.0001],[36400.0,2.83],[36391.0,0.0013],[36379.0,0.0001],[36269.0,0.0001],[36190.0,0.0014],[36159.0,0.0001],[36048.0,0.0001],[35989.0,0.0015],[35938.0,0.0001],[35827.0,0.0001],[35788.0,0.0016],[35766.0,0.0017],[35717.0,0.0019],[35606.0,0.0001]],"asks":[[38982.0,0.1081],[39008.0,9.2309],[39028.0,17.6034],[39052.0,0.006],[39096.0,0.0004],[39097.0,18.6207],[39141.0,0.0001],[39177.0,20.4135],[39192.0,24.2268],[39219.0,0.0009],[39251.0,0.0001],[39264.0,22.9486],[39297.0,36.042],[39300.0,0.0005],[39327.0,0.0001],[39347.0,35.1694],[39350.0,33.9392],[39362.0,0.0001],[39443.0,46.0501],[39472.0,0.0001],[39497.0,43.6485],[39502.0,43.3389],[39573.0,0.0001],[39583.0,0.0001],[39594.0,0.0005],[39611.0,0.0005],[39685.0,0.0005],[39687.0,0.0002],[39693.0,0.0001],[39803.0,0.0001],[39914.0,0.0001],[39934.0,0.0005],[39935.0,0.0005],[40021.0,0.0005],[40024.0,0.0001],[40043.0,0.0051],[40135.0,0.0001],[40245.0,0.0001],[40319.0,0.0005],[40330.0,0.0005],[40356.0,0.0001],[40398.0,0.0002],[40432.0,0.0005],[40466.0,0.0001],[40496.0,0.0005],[40576.0,0.0047],[40577.0,0.0001],[40623.0,0.0005],[40644.0,0.0005],[40665.0,0.0005],[40672.0,0.0005],[40687.0,0.0001],[40735.0,0.0005],[40798.0,0.0001],[40839.0,0.0005],[40908.0,0.0001],[40909.0,0.0002],[41018.0,0.0001],[41110.0,0.0002],[41129.0,0.0001],[41239.0,0.0001],[41350.0,0.0001],[41422.0,2.3236],[41460.0,0.0001],[41571.0,0.0001],[41681.0,0.0001],[41792.0,0.0001],[41821.0,0.0002],[41873.0,0.0002],[41902.0,0.0001],[42012.0,0.0001],[42123.0,0.0001],[42233.0,0.0001],[42344.0,0.0001],[42354.0,0.0001],[42423.0,0.0224],[42454.0,0.0001],[42533.0,0.0002],[42546.0,0.0041],[42565.0,0.0001],[42675.0,0.0001],[42785.0,0.0002],[42786.0,0.0001],[42896.0,0.0001],[43007.0,0.0001],[43117.0,0.0001],[43227.0,0.0001],[43244.0,0.0002],[43338.0,0.0001],[43448.0,0.0001],[43475.0,0.0005],[43559.0,0.0001],[43618.0,0.004],[43669.0,0.0001],[43697.0,0.0002],[43780.0,0.0001],[43890.0,0.0001],[44001.0,0.0001],[44055.0,0.0006],[44095.0,0.0005]],"action":"partial"}}
1651237298.8308604: {"channel":"orderbook","market":"ETH/USD","type":"update","data":{"time":1651237298.6829736,"checksum":336936288,"bids":[[2857.1,2.671]],"asks":[[2862.6,4.381],[2863.2,23.244],[2866.4,4.276],[2872.7,2.338]],"action":"update"}}
1651237298.8309042: {"channel":"orderbook","market":"ETH/USDT","type":"update","data":{"time":1651237298.6885424,"checksum":3968889440,"bids":[[2861.1,4.193]],"asks":[],"action":"update"}}
1651237298.853833: {"channel":"orderbook","market":"ETH/USDT","type":"update","data":{"time":1651237298.723056,"checksum":2219200621,"bids":[],"asks":[[2862.5,2.88],[2863.3,0.0],[2865.9,16.063],[2883.6,0.001]],"action":"update"}}
1651237298.875536: {"channel":"orderbook","market":"ETH/USD","type":"update","data":{"time":1651237298.7450342,"checksum":2848583824,"bids":[[2861.7,23.404]],"asks":[[2861.8,3.454]],"action":"update"}}
1651237298.8789983: {"channel":"orderbook","market":"ETH/USDT","type":"update","data":{"time":1651237298.7500525,"checksum":2030373446,"bids":[[2861.9,17.383]],"asks":[],"action":"update"}}
1651237298.8801236: {"channel":"orderbook","market":"ETH/USD","type":"update","data":{"time":1651237298.7546666,"checksum":3518390443,"bids":[[2861.7,21.308]],"asks":[],"action":"update"}}
1651237298.8877356: {"channel":"orderbook","market":"ETH/USDT","type":"update","data":{"time":1651237298.76243,"checksum":3255002274,"bids":[[2861.5,9.388]],"asks":[],"action":"update"}}
1651237298.8976798: {"channel":"orderbook","market":"WBTC/USD","type":"update","data":{"time":1651237298.7690158,"checksum":328209251,"bids":[[38944.0,0.041],[35606.0,0.0]],"asks":[],"action":"update"}}
1651237298.910226: {"channel":"orderbook","market":"ETH/USD","type":"update","data":{"time":1651237298.7808633,"checksum":1446452508,"bids":[[2861.7,21.54],[2861.5,7.243]],"asks":[],"action":"update"}}
1651237298.9242392: {"channel":"orderbook","market":"ETH/USDT","type":"update","data":{"time":1651237298.7938557,"checksum":1010969592,"bids":[[2861.9,15.383],[2861.7,6.11],[2861.6,2.05],[2861.4,0.0],[2842.7,0.018]],"asks":[],"action":"update"}}
1651237298.9319394: {"channel":"orderbook","market":"ETH/USD","type":"update","data":{"time":1651237298.8050318,"checksum":3216844697,"bids":[[2861.4,3.494],[2849.8,0.0]],"asks":[],"action":"update"}}
1651237298.9418833: {"channel":"orderbook","market":"ETH/USDT","type":"update","data":{"time":1651237298.8165653,"checksum":3665731599,"bids":[[2861.7,2.74]],"asks":[[2862.0,4.061]],"action":"update"}}
1651237298.9453614: {"channel":"orderbook","market":"WBTC/USD","type":"update","data":{"time":1651237298.8201206,"checksum":2109421629,"bids":[[38943.0,0.0],[35606.0,0.0001]],"asks":[],"action":"update"}}
1651237298.9616413: {"channel":"orderbook","market":"ETH/USD","type":"update","data":{"time":1651237298.831136,"checksum":2123604085,"bids":[[2861.4,0.0],[2849.8,0.032]],"asks":[[2862.6,4.73],[2868.0,6.444]],"action":"update"}}
1651237298.9651523: {"channel":"orderbook","market":"ETH/USDT","type":"update","data":{"time":1651237298.8379264,"checksum":1749102397,"bids":[[2861.7,4.487]],"asks":[],"action":"update"}}
1651237299.0148842: {"channel":"orderbook","market":"ETH/USDT","type":"update","data":{"time":1651237298.8866339,"checksum":4187077924,"bids":[[2861.2,10.338],[2861.0,3.495],[2842.7,0.0]],"asks":[],"action":"update"}}
1651237299.0612152: {"channel":"orderbook","market":"ETH/USD","type":"update","data":{"time":1651237298.9064455,"checksum":2517780633,"bids":[[2860.9,10.247]],"asks":[[2866.4,4.275]],"action":"update"}}
1651237299.0679867: {"channel":"orderbook","market":"WBTC/USD","type":"update","data":{"time":1651237298.9413323,"checksum":865172533,"bids":[[38945.0,0.0002],[35606.0,0.0]],"asks":[],"action":"update"}}
1651237299.0762105: {"channel":"orderbook","market":"SOL/USD","type":"partial","data":{"time":1651237298.9475925,"checksum":3722671690,"bids":[[95.9175,8.62],[95.915,91.0],[95.9075,81.1],[95.8975,0.74],[95.895,125.0],[95.8925,9.29],[95.8875,5.0],[95.885,103.71],[95.8825,445.72],[95.8675,8.61],[95.865,5.44],[95.86,49.65],[95.8475,71.73],[95.845,749.43],[95.8425,213.47],[95.84,50.17],[95.8375,2.22],[95.835,137.66],[95.8325,96.28],[95.83,241.64],[95.8275,98.63],[95.825,8.62],[95.8225,57.57],[95.8175,114.29],[95.815,1.95],[95.8125,80.1],[95.8075,0.97],[95.8025,160.07],[95.7975,8.62],[95.7925,104.39],[95.79,0.2],[95.7875,8.16],[95.78,70.0],[95.7775,56.31],[95.77,220.58],[95.7675,59.0],[95.75,148.71],[95.7375,26.62],[95.735,47.04],[95.73,178.32],[95.7275,93.81],[95.7225,8.62],[95.71,41.75],[95.7,31.19],[95.695,0.55],[95.6925,178.86],[95.69,0.2],[95.675,5.45],[95.67,186.03],[95.6675,0.07],[95.665,39.1],[95.66,70.82],[95.655,21.79],[95.65,0.08],[95.645,0.32],[95.6425,0.01],[95.64,0.11],[95.6375,22.4],[95.63,0.01],[95.6275,0.16],[95.625,68.42],[95.62,0.57],[95.6175,373.1],[95.6125,0.5],[95.61,60.88],[95.605,1000.0],[95.6025,0.01],[95.6,22.71],[95.5975,34.6],[95.595,0.08],[95.5925,0.18],[95.59,5.78],[95.5825,0.62],[95.58,0.24],[95.5775,0.19],[95.5725,71.74],[95.57,0.21],[95.5625,0.33],[95.56,0.34],[95.555,2.4],[95.5525,0.07],[95.55,0.44],[95.5475,0.03],[95.5425,10.0],[95.535,0.02],[95.525,0.1],[95.5225,0.27],[95.5175,0.97],[95.515,0.03],[95.5125,0.55],[95.51,3.61],[95.5075,0.8],[95.505,0.25],[95.5025,47.31],[95.5,71.37],[95.4975,0.17],[95.495,2.67],[95.4925,92.21],[95.49,12.34],[95.4875,1.02]],"asks":[[95.925,45.47],[95.93,51.0],[95.9375,132.1],[95.945,55.0],[95.955,70.0],[95.9575,119.25],[95.96,215.16],[95.9625,407.96],[95.965,112.37],[95.98,0.05],[95.9825,0.05],[95.9875,128.78],[95.99,0.2],[95.995,7.26],[95.9975,0.03],[96.0,121.1],[96.015,63.11],[96.0175,252.45],[96.02,2.24],[96.0225,0.05],[96.025,62.67],[96.03,33.4],[96.0325,389.3],[96.035,178.86],[96.0375,111.49],[96.0475,52.3],[96.05,600.2],[96.0525,0.01],[96.055,0.03],[96.0625,164.08],[96.07,1.2],[96.0775,119.45],[96.08,0.57],[96.0825,0.05],[96.0875,143.28],[96.09,0.3],[96.0975,85.05],[96.1,26.13],[96.1025,0.08],[96.1075,510.76],[96.11,41.75],[96.125,61.16],[96.135,26.1],[96.1375,0.2],[96.145,1500.35],[96.16,0.47],[96.1625,104.22],[96.17,114.23],[96.175,1.43],[96.1775,186.39],[96.18,0.05],[96.19,0.2],[96.205,1459.27],[96.21,0.33],[96.2125,0.03],[96.2175,0.2],[96.22,0.64],[96.2225,0.05],[96.2275,0.03],[96.2375,50.12],[96.2425,25.98],[96.245,275.33],[96.25,61.45],[96.2575,0.01],[96.26,0.06],[96.265,0.03],[96.27,0.19],[96.2725,1.17],[96.275,0.85],[96.2775,115.91],[96.28,1.09],[96.2825,3.3],[96.2875,1.02],[96.29,0.38],[96.295,1.1],[96.3,180.0],[96.31,0.85],[96.3125,0.52],[96.315,0.03],[96.3175,0.19],[96.32,0.01],[96.3225,0.62],[96.3275,0.01],[96.33,0.26],[96.3325,0.13],[96.3375,0.29],[96.3425,0.05],[96.3475,0.3],[96.35,0.33],[96.3575,0.46],[96.36,0.03],[96.3625,0.38],[96.37,2.64],[96.375,68.15],[96.385,0.35],[96.39,0.21],[96.3925,0.18],[96.4,16.48],[96.405,19.0],[96.41,0.38]],"action":"partial"}}
1651237299.1022844: {"channel":"orderbook","market":"SOL/USD","type":"update","data":{"time":1651237298.9754388,"checksum":913022772,"bids":[[95.72,275.32],[95.4875,0.0]],"asks":[],"action":"update"}}
1651237299.1141133: {"channel":"orderbook","market":"ETH/USD","type":"update","data":{"time":1651237298.9800065,"checksum":3070882407,"bids":[],"asks":[[2862.5,18.122],[2869.4,2.056],[2874.4,0.0]],"action":"update"}}
1651237299.1602895: {"channel":"orderbook","market":"LTC/USDT","type":"partial","data":{"time":1651237299.0280302,"checksum":13691480,"bids":[[100.62,116.14],[100.61,50.13],[100.6,0.34],[100.585,72.0],[100.565,7.46],[100.56,59.47],[100.535,14.99],[100.53,2.74],[100.515,105.12],[100.5,61.29],[100.48,17.2],[100.465,11.12],[100.44,3.09],[100.42,20.77],[100.41,93.44],[100.405,70.1],[100.385,188.3],[100.375,362.56],[100.37,48.5],[100.35,65.0],[100.31,504.64],[100.265,74.74],[100.205,99.42],[100.2,809.18],[100.075,1023.27],[100.05,63.5],[100.025,0.01],[99.97,239.38],[99.965,1322.51],[99.945,257.0],[99.9,61.89],[99.895,0.24],[99.865,0.3],[99.825,210.97],[99.77,944.4],[99.75,54.37],[99.69,1111.91],[99.65,0.01],[99.64,1175.07],[99.625,0.18],[99.6,65.74],[99.53,0.3],[99.505,182.81],[99.5,0.01],[99.495,1404.92],[99.45,62.84],[99.41,1198.26],[99.4,123.1],[99.37,0.3],[99.305,29.67],[99.3,59.28],[99.27,0.01],[99.235,2.58],[99.23,1613.08],[99.205,1848.23],[99.185,0.6],[99.155,232.0],[99.145,60.24],[99.06,0.46],[99.0,0.01],[98.985,0.3],[98.98,4.96],[98.965,0.02],[98.895,0.01],[98.875,0.3],[98.83,0.03],[98.785,0.18],[98.77,1.24],[98.7,10.0],[98.69,0.01],[98.62,0.23],[98.52,0.01],[98.445,0.3],[98.395,0.6],[98.385,0.3],[98.375,0.01],[98.365,0.18],[98.32,0.12],[98.275,0.39],[98.17,300.0],[98.14,29.65],[98.005,30.3],[98.0,0.17],[97.91,0.3],[97.9,0.3],[97.89,0.01],[97.765,0.01],[97.615,0.6],[97.5,0.05],[97.415,0.3],[97.39,0.01],[97.38,0.3],[97.325,30.27],[97.17,500.0],[97.08,0.01],[97.03,0.39],[97.01,0.01],[97.0,3.2],[96.93,0.3],[96.845,0.3]],"asks":[[100.625,7.62],[100.64,0.34],[100.705,12.0],[100.71,4.96],[100.715,14.8],[100.725,92.25],[100.73,75.32],[100.74,24.0],[100.75,58.34],[100.755,48.49],[100.76,7.46],[100.765,35.15],[100.77,52.66],[100.78,0.01],[100.8,57.88],[100.815,29.81],[100.82,3.37],[100.825,289.44],[100.85,271.83],[100.87,254.39],[100.875,546.81],[100.89,0.18],[100.9,0.57],[100.905,0.29],[100.95,627.18],[100.955,65.99],[101.0,0.01],[101.04,99.36],[101.085,235.99],[101.105,59.23],[101.11,0.01],[101.145,1198.92],[101.155,0.01],[101.17,668.69],[101.185,0.37],[101.22,0.29],[101.245,235.0],[101.255,63.73],[101.28,2549.38],[101.31,0.18],[101.355,1828.12],[101.405,64.0],[101.41,0.29],[101.47,221.85],[101.495,1799.73],[101.53,0.01],[101.555,1703.1],[101.64,121.33],[101.695,22.89],[101.705,62.14],[101.735,0.18],[101.77,0.29],[101.79,1642.06],[101.85,1796.99],[101.855,55.58],[101.88,15.11],[101.905,0.01],[101.91,0.01],[101.915,0.29],[101.96,1.26],[102.0,0.32],[102.005,63.23],[102.015,0.39],[102.12,0.03],[102.155,56.06],[102.18,0.76],[102.24,0.16],[102.285,0.01],[102.33,0.29],[102.42,0.29],[102.52,0.23],[102.575,0.18],[102.595,0.04],[102.61,0.13],[102.66,0.01],[102.72,0.01],[102.75,7.62],[102.8,0.03],[102.85,92.19],[102.89,0.29],[102.91,0.03],[102.93,0.29],[102.995,0.18],[103.0,0.02],[103.035,0.01],[103.135,877.37],[103.145,0.16],[103.34,0.23],[103.415,0.01],[103.42,0.18],[103.445,0.29],[103.455,0.29],[103.48,0.03],[103.52,0.01],[103.71,0.46],[103.775,0.71],[103.79,0.01],[103.84,0.18],[103.91,0.02],[103.96,0.29]],"action":"partial"}}
1651237299.1607926: {"channel":"orderbook","market":"SOL/USD","type":"update","data":{"time":1651237299.02831,"checksum":2338582765,"bids":[],"asks":[[96.03,99.24]],"action":"update"}}
1651237299.1637783: {"channel":"orderbook","market":"ETH/USD","type":"update","data":{"time":1651237299.0327284,"checksum":1097870434,"bids":[[2861.1,27.342]],"asks":[[2861.8,3.616]],"action":"update"}}
1651237299.1934285: {"channel":"orderbook","market":"ETH/USD","type":"update","data":{"time":1651237299.0577986,"checksum":1596705179,"bids":[[2861.7,18.047],[2861.1,27.384],[2855.2,4.006]],"asks":[[2862.4,4.884],[2865.0,0.003]],"action":"update"}}
1651237299.199255: {"channel":"orderbook","market":"SHIB/USD","type":"partial","data":{"time":1651237299.0674508,"checksum":4233148178,"bids":[[0.00002262,61700000.0],[0.00002261,233000000.0],[0.0000226,407700000.0],[0.00002259,199200000.0],[0.00002258,303700000.0],[0.00002257,198100000.0],[0.00002256,102800000.0],[0.00002255,47400000.0],[0.00002254,264500000.0],[0.00002253,28500000.0],[0.00002252,600000.0],[0.00002251,34000000.0],[0.0000225,7500000.0],[0.00002249,100600000.0],[0.00002248,170100000.0],[0.00002247,400000.0],[0.00002246,171200000.0],[0.00002245,3400000.0],[0.00002244,300000.0],[0.00002243,800000.0],[0.00002242,1600000.0],[0.00002241,71400000.0],[0.0000224,100000000.0],[0.00002239,4100000.0],[0.00002238,109300000.0],[0.00002237,9400000.0],[0.00002236,10500000.0],[0.00002235,1600000.0],[0.00002234,101300000.0],[0.00002233,1300000.0],[0.00002232,1200000.0],[0.00002231,70500000.0],[0.0000223,4900000.0],[0.00002229,400000.0],[0.00002228,17500000.0],[0.00002227,4900000.0],[0.00002226,101000000.0],[0.00002225,3400000.0],[0.00002224,900000.0],[0.00002223,1300000.0],[0.00002222,200000.0],[0.00002221,400000.0],[0.0000222,100000.0],[0.00002219,71200000.0],[0.00002218,2100000.0],[0.00002217,2600000.0],[0.00002216,2100000.0],[0.00002215,102400000.0],[0.00002214,100000.0],[0.00002213,1700000.0],[0.00002212,400000.0],[0.00002211,900000.0],[0.0000221,900000.0],[0.00002209,200000.0],[0.00002208,100800000.0],[0.00002207,500000.0],[0.00002206,4300000.0],[0.00002205,1100000.0],[0.00002204,37900000.0],[0.00002203,103300000.0],[0.00002202,2300000.0],[0.00002201,91100000.0],[0.000022,344600000.0],[0.00002199,200000.0],[0.00002198,400000.0],[0.00002197,5500000.0],[0.00002196,4300000.0],[0.00002195,3200000.0],[0.00002194,1100000.0],[0.00002193,12400000.0],[0.00002192,1300000.0],[0.00002191,200000.0],[0.0000219,4300000.0],[0.00002189,600000.0],[0.00002188,200000.0],[0.00002187,14600000.0],[0.00002186,10200000.0],[0.00002185,6700000.0],[0.00002184,74600000.0],[0.00002183,500000.0],[0.00002182,100000.0],[0.00002181,3300000.0],[0.0000218,2800000.0],[0.00002179,38800000.0],[0.00002178,200000.0],[0.00002177,900000.0],[0.00002176,4300000.0],[0.00002175,9300000.0],[0.00002174,70100000.0],[0.00002173,6000000.0],[0.00002172,300000.0],[0.00002171,20500000.0],[0.0000217,1900000.0],[0.00002169,1300000.0],[0.00002168,1300000.0],[0.00002166,100000.0],[0.00002165,2800000.0],[0.00002164,2200000.0],[0.00002163,2100000.0],[0.00002162,2200000.0]],"asks":[[0.00002263,18000000.0],[0.00002264,243500000.0],[0.00002265,466900000.0],[0.00002266,382900000.0],[0.00002267,162300000.0],[0.00002268,97100000.0],[0.00002269,98200000.0],[0.0000227,27500000.0],[0.00002271,70800000.0],[0.00002272,100000000.0],[0.00002273,2400000.0],[0.00002275,73200000.0],[0.00002278,9200000.0],[0.00002279,9400000.0],[0.0000228,110000000.0],[0.00002281,101100000.0],[0.00002282,900000.0],[0.00002283,100000.0],[0.00002284,2400000.0],[0.00002285,5000000.0],[0.00002286,100000.0],[0.00002287,74500000.0],[0.00002289,1000000.0],[0.0000229,500000.0],[0.00002291,100900000.0],[0.00002292,100100000.0],[0.00002293,400000.0],[0.00002294,500000.0],[0.00002295,700000.0],[0.00002296,2500000.0],[0.00002297,2000000.0],[0.00002299,1000000.0],[0.000023,18900000.0],[0.00002301,100000.0],[0.00002302,8500000.0],[0.00002303,169700000.0],[0.00002304,1100000.0],[0.00002305,1400000.0],[0.00002306,100000.0],[0.00002307,102500000.0],[0.00002308,600000.0],[0.00002309,500000.0],[0.0000231,3700000.0],[0.00002312,1300000.0],[0.00002313,1000000.0],[0.00002314,101100000.0],[0.00002315,1000000.0],[0.00002317,71600000.0],[0.00002318,3200000.0],[0.00002319,800000.0],[0.0000232,1400000.0],[0.00002321,300000.0],[0.00002322,99900000.0],[0.00002323,103400000.0],[0.00002324,5600000.0],[0.00002325,2800000.0],[0.00002326,600000.0],[0.00002327,1100000.0],[0.00002328,2800000.0],[0.0000233,2700000.0],[0.00002331,70500000.0],[0.00002332,100100000.0],[0.00002333,300000.0],[0.00002335,600000.0],[0.00002336,2300000.0],[0.00002337,1600000.0],[0.00002338,100000.0],[0.0000234,69800000.0],[0.00002341,2000000.0],[0.00002342,800000.0],[0.00002343,1100000.0],[0.00002344,100000.0],[0.00002345,600000.0],[0.00002346,700000.0],[0.00002347,500000.0],[0.00002348,300000.0],[0.00002349,1600000.0],[0.0000235,3200000.0],[0.00002351,700000.0],[0.00002352,200000.0],[0.00002353,71900000.0],[0.00002354,500000.0],[0.00002355,20600000.0],[0.00002356,3000000.0],[0.00002357,300000.0],[0.00002359,300000.0],[0.0000236,400000.0],[0.00002361,2100000.0],[0.00002362,700000.0],[0.00002363,200000.0],[0.00002364,400000.0],[0.00002365,3400000.0],[0.00002366,1700000.0],[0.00002367,1600000.0],[0.0000237,100000.0],[0.00002371,5500000.0],[0.00002372,300000.0],[0.00002373,5900000.0],[0.00002374,700000.0],[0.00002375,2600000.0]],"action":"partial"}}
1651237299.213315: {"channel":"orderbook","market":"ETH/USD","type":"update","data":{"time":1651237299.0837917,"checksum":2619742609,"bids":[[2861.7,15.428],[2861.4,0.003],[2855.7,12.986],[2849.8,0.0]],"asks":[[2868.4,3.031],[2874.3,0.0]],"action":"update"}}
1651237299.2434027: {"channel":"orderbook","market":"ETH/USD","type":"update","data":{"time":1651237299.1059146,"checksum":560048054,"bids":[[2861.7,11.978]],"asks":[[2863.9,10.456]],"action":"update"}}
1651237299.2434502: {"channel":"orderbook","market":"SOL/USD","type":"update","data":{"time":1651237299.1029503,"checksum":1621808336,"bids":[[95.9175,0.01]],"asks":[],"action":"update"}}
1651237299.261738: {"channel":"orderbook","market":"SHIB/USD","type":"update","data":{"time":1651237299.1175153,"checksum":1314612665,"bids":[[0.0000224,100000.0]],"asks":[],"action":"update"}}
1651237299.2680678: {"channel":"orderbook","market":"ETH/USD","type":"update","data":{"time":1651237299.1354542,"checksum":1474008158,"bids":[],"asks":[[2862.7,15.33],[2863.8,0.01],[2866.2,0.001],[2874.2,0.0]],"action":"update"}}
1651237299.2801044: {"channel":"orderbook","market":"SOL/USD","type":"update","data":{"time":1651237299.149105,"checksum":2588129019,"bids":[],"asks":[[96.0375,111.5]],"action":"update"}}
1651237299.3004167: {"channel":"orderbook","market":"ETH/USD","type":"update","data":{"time":1651237299.1703403,"checksum":2878345829,"bids":[[2861.7,11.952],[2861.2,13.827]],"asks":[],"action":"update"}}
1651237299.3085382: {"channel":"orderbook","market":"DAI/USD","type":"partial","data":{"time":1651237299.1806493,"checksum":280434518,"bids":[[0.9998,11371.1],[0.9997,0.1],[0.9996,153426.0],[0.9992,0.1],[0.9991,0.1],[0.999,134012.3],[0.9989,25.4],[0.9986,393.4],[0.9981,1000.0],[0.998,40001.0],[0.9976,1000.0],[0.9971,1000.0],[0.997,1.0],[0.9966,1000.0],[0.9961,1000.0],[0.996,100236.4],[0.9956,1000.0],[0.9955,1.0],[0.995,1.0],[0.9934,151.2],[0.9933,21178.6],[0.9929,89322.7],[0.9908,10.1],[0.99,105977.5],[0.9871,22.3],[0.987,113636.3],[0.9851,3418.7],[0.9841,163615.1],[0.9812,125579.6],[0.9797,5.2],[0.9783,133386.8],[0.9767,15.4],[0.9754,139389.4],[0.9726,185425.1],[0.9703,13.4],[0.9697,206206.7],[0.9669,158945.7],[0.9546,5.5],[0.9509,52.6],[0.9501,50.0],[0.9417,124100.9],[0.9402,95255.4],[0.9294,6.0],[0.9028,10.0],[0.9008,55.6],[0.9005,2.3],[0.8996,136401.7],[0.8805,68.2],[0.8607,163353.9],[0.7926,210500.8],[0.7624,249486.5],[0.7604,157.9],[0.7404,0.5],[0.49,12.5],[0.1,377.0],[0.049,125.2],[0.0016,20000000.0],[0.0012,10000000.0],[0.0002,25000000.0],[0.0001,1.0]],"asks":[[0.9999,27441.1],[1.0,56161.4],[1.0001,33258.8],[1.0002,1900.0],[1.0003,2601.9],[1.0004,2124.5],[1.0005,1900.0],[1.0007,76653.7],[1.0009,10455.1],[1.001,10.0],[1.0011,101496.7],[1.0015,5000.0],[1.0017,205.1],[1.0019,500007.7],[1.002,5007.6],[1.0036,67962.6],[1.0049,2433.2],[1.005,0.5],[1.0061,20639.6],[1.0064,34.0],[1.0069,113620.7],[1.0096,93744.3],[1.01,12.5],[1.0111,6.6],[1.0123,1000.0],[1.0125,10.0],[1.0126,154210.3],[1.0149,48321.5],[1.015,2433.2],[1.0156,148505.8],[1.0176,1.0],[1.0188,156534.8],[1.0216,150615.1],[1.0217,50.0],[1.0246,147741.8],[1.0276,218381.6],[1.0307,150329.6],[1.0337,215178.4],[1.0499,1000.0],[1.0616,123513.1],[1.0799,1000.0],[1.0899,1000.0],[1.098,200000.0],[1.099,1000.0],[1.1,10.2],[1.1112,124384.6],[1.1124,0.1],[1.15,787.5],[1.161,181685.3],[1.211,253167.1],[1.311,236777.8],[1.3116,227339.7],[35000.0,1000.0],[45000.0,500.0],[125000.0,500.0]],"action":"partial"}}
1651237299.3286467: {"channel":"orderbook","market":"ETH/USD","type":"update","data":{"time":1651237299.1973393,"checksum":2665618193,"bids":[[2861.7,10.052],[2861.5,3.749]],"asks":[[2862.1,3.555],[2862.6,4.381]],"action":"update"}}
1651237299.3947275: {"channel":"orderbook","market":"SHIB/USD","type":"update","data":{"time":1651237299.217909,"checksum":759612596,"bids":[[0.00002239,104000000.0]],"asks":[],"action":"update"}}
1651237299.3947911: {"channel":"orderbook","market":"SOL/USD","type":"update","data":{"time":1651237299.2152998,"checksum":1051711032,"bids":[[95.7775,56.84]],"asks":[[95.9275,0.04],[96.1075,373.1],[96.41,0.0]],"action":"update"}}
1651237299.394885: {"channel":"orderbook","market":"ETH/USD","type":"update","data":{"time":1651237299.2369945,"checksum":3653308434,"bids":[[2861.7,10.039],[2861.6,4.993],[2859.8,5.056]],"asks":[[2861.8,4.101]],"action":"update"}}
1651237299.3949356: {"channel":"orderbook","market":"ETH/USD","type":"update","data":{"time":1651237299.2634857,"checksum":691736304,"bids":[[2860.6,13.472]],"asks":[[2862.5,21.247],[2862.8,28.236]],"action":"update"}}
1651237299.403358: {"channel":"orderbook","market":"WBTC/USD","type":"update","data":{"time":1651237299.2678685,"checksum":56148598,"bids":[[38944.0,0.0],[35606.0,0.0001]],"asks":[],"action":"update"}}
1651237299.4034035: {"channel":"orderbook","market":"SOL/USD","type":"update","data":{"time":1651237299.2674885,"checksum":1018862229,"bids":[[95.8875,0.0],[95.4875,1.02]],"asks":[],"action":"update"}}
1651237299.4088612: {"channel":"orderbook","market":"LTC/USDT","type":"update","data":{"time":1651237299.2809439,"checksum":1652069149,"bids":[[100.62,66.01],[100.61,0.0],[96.635,0.01]],"asks":[],"action":"update"}}
1651237299.4175344: {"channel":"orderbook","market":"ETH/USD","type":"update","data":{"time":1651237299.2860115,"checksum":1492950947,"bids":[],"asks":[[2864.8,25.985]],"action":"update"}}
1651237299.4243665: {"channel":"orderbook","market":"FTT/BTC","type":"update","data":{"time":1651237299.2899597,"checksum":2151910379,"bids":[[0.0010089,0.0],[0.0009962,0.3]],"asks":[[0.0010095,0.0],[0.0010097,2.1],[0.001024,0.1]],"action":"update"}}
1651237299.4384565: {"channel":"orderbook","market":"ETH/USD","type":"update","data":{"time":1651237299.3110273,"checksum":3835049642,"bids":[[2860.2,9.194]],"asks":[[2862.7,22.396]],"action":"update"}}
1651237299.4405377: {"channel":"orderbook","market":"FTT/BTC","type":"update","data":{"time":1651237299.3143966,"checksum":2903929790,"bids":[],"asks":[[0.0010096,0.0],[0.0010097,0.0],[0.0010098,3.9],[0.0010241,2879.9],[0.0010242,1.3]],"action":"update"}}
1651237299.4407272: {"channel":"orderbook","market":"USD/TRY","type":"partial","data":{"time":1651237299.3131113,"checksum":697568182,"bids":[[14.9131,750.0],[14.913,9185.0],[14.9087,13857.0],[14.9067,158.0],[14.9041,14319.0],[14.9,19854.0],[14.8918,27840.0],[14.8828,20209.0],[14.8717,21609.0],[14.8698,25096.0],[14.8532,35129.0],[14.8468,35881.0],[14.8376,32241.0],[14.832,31036.0],[14.8173,40541.0],[14.8101,42130.0],[14.8026,35088.0],[14.7953,32646.0],[14.7913,50075.0],[14.788,45367.0],[14.7869,41242.0],[14.7788,42342.0],[14.7739,38116.0],[14.7733,37837.0],[14.76,100.0],[14.7498,52200.0],[14.7494,57333.0],[14.734,53300.0],[14.71,200.0],[14.5,2.0],[14.4,50.0],[14.3,200.0],[14.1083,1906.0],[14.0,500.0],[13.9753,2120.0],[13.8448,2035.0],[13.7888,398505.0],[13.7167,2045.0],[13.591,1923.0],[13.4165,701540.0],[13.0587,941200.0],[12.7292,815340.0]],"asks":[[14.9272,9542.0],[14.928,14868.0],[14.93,10.0],[14.935,15069.0],[14.9391,22880.0],[14.94,10.0],[14.9465,29709.0],[14.954,23960.0],[14.9615,34242.0],[14.9689,25183.0],[14.9764,38138.0],[14.9838,33521.0],[14.9913,29757.0],[14.9987,41018.0],[15.0062,28234.0],[15.0136,34123.0],[15.0211,47667.0],[15.0286,49656.0],[15.036,39694.0],[15.0435,45876.0],[15.0598,58864.0],[15.0613,36855.0],[15.0621,43189.0],[15.0637,52281.0],[15.0892,46684.0],[15.0942,51338.0],[15.1088,46567.0],[15.5841,2123.0],[15.7324,1905.0],[15.8807,1963.0],[16.029,1849.0],[16.1259,551311.0],[16.1772,1936.0],[17.0069,781274.0],[17.4467,902170.0],[17.4694,772023.0]],"action":"partial"}}
1651237299.4432564: {"channel":"orderbook","market":"SHIB/USD","type":"update","data":{"time":1651237299.3170822,"checksum":3013044874,"bids":[],"asks":[[0.00002265,566800000.0]],"action":"update"}}
1651237299.4540584: {"channel":"orderbook","market":"SOL/USD","type":"update","data":{"time":1651237299.32326,"checksum":1910041464,"bids":[],"asks":[[95.945,122.57]],"action":"update"}}
1651237299.465136: {"channel":"orderbook","market":"ETH/USD","type":"update","data":{"time":1651237299.3372157,"checksum":1227025723,"bids":[[2861.5,0.299],[2859.6,3.125],[2855.6,6.047],[2849.9,0.0]],"asks":[[2861.8,0.651],[2862.6,4.73]],"action":"update"}}
1651237299.487608: {"channel":"orderbook","market":"ETH/USD","type":"update","data":{"time":1651237299.360592,"checksum":2770781000,"bids":[],"asks":[[2864.1,26.949],[2864.2,2.797]],"action":"update"}}
1651237299.517383: {"channel":"orderbook","market":"SOL/USD","type":"update","data":{"time":1651237299.3737628,"checksum":3320749158,"bids":[],"asks":[[95.925,44.44],[96.1775,0.36]],"action":"update"}}
1651237299.5279498: {"channel":"orderbook","market":"ETH/USD","type":"update","data":{"time":1651237299.3862894,"checksum":475566629,"bids":[],"asks":[[2862.5,3.955]],"action":"update"}}
1651237299.5379264: {"channel":"orderbook","market":"SOL/USD","type":"update","data":{"time":1651237299.4003935,"checksum":1595925858,"bids":[[95.865,0.0],[95.77,116.01],[95.485,4.58]],"asks":[],"action":"update"}}
1651237299.5461252: {"channel":"orderbook","market":"ETH/USD","type":"update","data":{"time":1651237299.4203665,"checksum":3661347235,"bids":[],"asks":[[2861.8,4.144],[2864.0,45.521]],"action":"update"}}
1651237299.566335: {"channel":"orderbook","market":"SOL/USD","type":"update","data":{"time":1651237299.434372,"checksum":2062154581,"bids":[[95.785,59.0],[95.7675,0.0]],"asks":[],"action":"update"}}
1651237299.574824: {"channel":"orderbook","market":"ETH/USD","type":"update","data":{"time":1651237299.448577,"checksum":2317323601,"bids":[[2861.7,7.939],[2859.3,1.765],[2850.0,0.0]],"asks":[[2862.4,0.349]],"action":"update"}}
1651237299.580659: {"channel":"orderbook","market":"SOL/USD","type":"update","data":{"time":1651237299.455534,"checksum":2134546021,"bids":[[95.86,0.68]],"asks":[[96.13,137.66],[96.405,0.0]],"action":"update"}}
1651237299.6060584: {"channel":"orderbook","market":"SOL/USD","type":"update","data":{"time":1651237299.4779005,"checksum":3227305534,"bids":[[95.915,36.0],[95.895,70.0]],"asks":[[95.925,0.0],[95.945,67.57],[96.405,19.0]],"action":"update"}}
1651237299.6161187: {"channel":"orderbook","market":"ETH/USD","type":"update","data":{"time":1651237299.4860535,"checksum":2973723210,"bids":[],"asks":[[2861.8,6.044],[2863.1,18.098],[2863.2,13.089]],"action":"update"}}
1651237299.6360536: {"channel":"orderbook","market":"ETH/USD","type":"update","data":{"time":1651237299.5097973,"checksum":3731835682,"bids":[[2861.4,0.0],[2861.1,27.342],[2850.0,2.702]],"asks":[[2861.8,2.551],[2863.1,7.417]],"action":"update"}}
1651237299.6487844: {"channel":"orderbook","market":"FTT/BTC","type":"update","data":{"time":1651237299.5212924,"checksum":2903929790,"bids":[],"asks":[],"action":"update"}}
1651237299.6647758: {"channel":"orderbook","market":"ETH/USD","type":"update","data":{"time":1651237299.537046,"checksum":1569522675,"bids":[],"asks":[[2862.6,4.381],[2862.8,9.161]],"action":"update"}}
1651237299.6903331: {"channel":"orderbook","market":"BTC/TRY","type":"update","data":{"time":1651237299.5609796,"checksum":1840591949,"bids":[],"asks":[],"action":"update"}}
1651237299.702826: {"channel":"orderbook","market":"LTC/USDT","type":"update","data":{"time":1651237299.578122,"checksum":3111272776,"bids":[[100.62,70.45]],"asks":[],"action":"update"}}
1651237299.7298512: {"channel":"orderbook","market":"LTC/USDT","type":"update","data":{"time":1651237299.6040084,"checksum":2969190233,"bids":[],"asks":[[100.7,2.44],[103.96,0.0]],"action":"update"}}
1651237299.7671828: {"channel":"orderbook","market":"ETH/USD","type":"update","data":{"time":1651237299.6399,"checksum":2552765819,"bids":[],"asks":[[2863.0,0.001],[2863.3,15.526]],"action":"update"}}
1651237299.7809522: {"channel":"orderbook","market":"LTC/USDT","type":"update","data":{"time":1651237299.6539357,"checksum":1366687495,"bids":[[100.54,1.31],[96.635,0.0]],"asks":[],"action":"update"}}
1651237299.789893: {"channel":"orderbook","market":"ETH/USD","type":"update","data":{"time":1651237299.661213,"checksum":1126978119,"bids":[],"asks":[[2862.7,15.33],[2863.9,30.152],[2864.8,34.875]],"action":"update"}}
1651237299.8048983: {"channel":"orderbook","market":"LTC/USDT","type":"update","data":{"time":1651237299.6780102,"checksum":2969190233,"bids":[[100.54,0.0],[96.635,0.01]],"asks":[],"action":"update"}}
1651237299.8151028: {"channel":"orderbook","market":"ETH/USD","type":"update","data":{"time":1651237299.6862648,"checksum":4207282442,"bids":[],"asks":[[2864.8,41.932]],"action":"update"}}
1651237299.8333306: {"channel":"orderbook","market":"SOL/USD","type":"update","data":{"time":1651237299.7024584,"checksum":3493145984,"bids":[],"asks":[[95.955,0.0],[96.03,33.4],[96.41,0.38]],"action":"update"}}
1651237299.8371625: {"channel":"orderbook","market":"WBTC/USD","type":"update","data":{"time":1651237299.700112,"checksum":56148598,"bids":[],"asks":[],"action":"update"}}
1651237299.839687: {"channel":"orderbook","market":"ETH/USD","type":"update","data":{"time":1651237299.7120547,"checksum":620464072,"bids":[],"asks":[[2863.8,7.549]],"action":"update"}}
1651237299.909148: {"channel":"orderbook","market":"ETH/USD","type":"update","data":{"time":1651237299.747416,"checksum":4234401763,"bids":[[2861.2,13.869]],"asks":[[2862.5,21.247],[2862.6,4.73]],"action":"update"}}
1651237299.9092135: {"channel":"orderbook","market":"SOL/USD","type":"update","data":{"time":1651237299.75441,"checksum":1585402090,"bids":[],"asks":[[96.0625,31.2]],"action":"update"}}
1651237299.9092407: {"channel":"orderbook","market":"ETH/USD","type":"update","data":{"time":1651237299.7707708,"checksum":1397989007,"bids":[],"asks":[[2864.8,34.875],[2865.0,0.01]],"action":"update"}}
1651237299.9212146: {"channel":"orderbook","market":"ETH/USD","type":"update","data":{"time":1651237299.794406,"checksum":2182749142,"bids":[],"asks":[[2861.8,2.547],[2861.9,0.0],[2862.6,4.381],[2866.0,2.378],[2874.2,0.146]],"action":"update"}}
1651237299.930535: {"channel":"orderbook","market":"SOL/USD","type":"update","data":{"time":1651237299.804194,"checksum":3730016877,"bids":[[95.67,0.0],[95.4825,2.08]],"asks":[],"action":"update"}}
1651237299.9544036: {"channel":"orderbook","market":"ETH/USD","type":"update","data":{"time":1651237299.8217256,"checksum":4143308816,"bids":[],"asks":[[2862.4,5.662],[2863.2,12.988]],"action":"update"}}
1651237299.9741933: {"channel":"orderbook","market":"ETH/USDT","type":"update","data":{"time":1651237299.835433,"checksum":166356696,"bids":[[2861.9,0.0],[2861.7,2.74],[2861.6,0.0],[2861.5,33.841],[2861.2,3.495],[2861.1,0.282],[2861.0,0.0],[2860.8,27.138],[2859.7,0.0],[2858.6,0.758],[2854.6,0.318],[2850.0,2.344],[2846.3,0.001],[2842.7,0.018],[2842.5,835.588],[2842.2,0.001]],"asks":[[2862.0,14.675],[2862.4,1.748],[2862.6,12.641],[2862.7,14.804],[2862.8,16.039],[2862.9,0.0],[2863.2,6.483],[2863.4,1.447],[2863.7,1.43],[2863.8,0.75],[2864.8,1.34],[2865.8,142.401],[2883.6,0.0]],"action":"update"}}
1651237299.989017: {"channel":"orderbook","market":"ETH/USD","type":"update","data":{"time":1651237299.8572996,"checksum":3695002502,"bids":[[2861.7,7.75]],"asks":[[2862.4,5.313]],"action":"update"}}
1651237300.0079288: {"channel":"orderbook","market":"LTC/USDT","type":"update","data":{"time":1651237299.880072,"checksum":1733476429,"bids":[[100.5,83.89]],"asks":[],"action":"update"}}
1651237300.0084918: {"channel":"orderbook","market":"SOL/USD","type":"update","data":{"time":1651237299.8818002,"checksum":3789753131,"bids":[[95.7975,43.62]],"asks":[],"action":"update"}}
1651237300.034166: {"channel":"orderbook","market":"USD/TRY","type":"update","data":{"time":1651237299.907733,"checksum":3174659845,"bids":[],"asks":[[15.5841,0.0]],"action":"update"}}
1651237300.034218: {"channel":"orderbook","market":"ETH/USDT","type":"update","data":{"time":1651237299.9038372,"checksum":2051416898,"bids":[],"asks":[[2862.0,12.675],[2862.6,5.725]],"action":"update"}}
1651237300.0415611: {"channel":"orderbook","market":"ETH/USD","type":"update","data":{"time":1651237299.9114811,"checksum":4147412132,"bids":[[2861.7,5.813],[2860.0,5.885]],"asks":[[2862.6,4.73]],"action":"update"}}
1651237300.0416026: {"channel":"orderbook","market":"ETH/USDT","type":"update","data":{"time":1651237299.9150891,"checksum":1350298773,"bids":[[2861.6,2.347],[2842.2,0.0]],"asks":[[2862.6,8.553]],"action":"update"}}
1651237300.0557513: {"channel":"orderbook","market":"SOL/USD","type":"update","data":{"time":1651237299.9254167,"checksum":3105231571,"bids":[],"asks":[[96.0325,455.15]],"action":"update"}}
1651237300.0609567: {"channel":"orderbook","market":"ETH/USD","type":"update","data":{"time":1651237299.934572,"checksum":1435777371,"bids":[[2861.7,4.513]],"asks":[[2861.8,2.552]],"action":"update"}}
1651237300.0679252: {"channel":"orderbook","market":"ETH/USDT","type":"update","data":{"time":1651237299.9415379,"checksum":490174347,"bids":[[2860.9,5.414],[2842.5,0.0]],"asks":[[2862.5,0.01],[2863.9,21.819],[2882.0,1.997]],"action":"update"}}
1651237300.0896716: {"channel":"orderbook","market":"SOL/USD","type":"update","data":{"time":1651237299.956963,"checksum":1479925716,"bids":[[95.87,52.64],[95.8025,27.19],[95.4825,0.0]],"asks":[[95.9625,477.96]],"action":"update"}}
1651237300.0904088: {"channel":"orderbook","market":"ETH/USD","type":"update","data":{"time":1651237299.963484,"checksum":1611522307,"bids":[[2861.4,0.003],[2850.0,0.0]],"asks":[[2862.6,4.381]],"action":"update"}}
1651237300.096016: {"channel":"orderbook","market":"SHIB/USD","type":"update","data":{"time":1651237299.9696925,"checksum":3391986333,"bids":[],"asks":[[0.00002268,122100000.0]],"action":"update"}}
1651237300.10381: {"channel":"orderbook","market":"SOL/USD","type":"update","data":{"time":1651237299.9788086,"checksum":2366568099,"bids":[],"asks":[[95.9275,0.0],[96.4125,0.36]],"action":"update"}}
1651237300.1332836: {"channel":"orderbook","market":"ETH/USDT","type":"update","data":{"time":1651237300.0054657,"checksum":2841817603,"bids":[],"asks":[[2861.8,2.0],[2862.7,20.258],[2883.5,0.0]],"action":"update"}}
1651237300.1347733: {"channel":"orderbook","market":"SOL/USD","type":"update","data":{"time":1651237300.0080626,"checksum":2228925597,"bids":[[95.855,5.44],[95.485,0.0]],"asks":[],"action":"update"}}
1651237300.1509817: {"channel":"orderbook","market":"ETH/USD","type":"update","data":{"time":1651237300.0221698,"checksum":548342667,"bids":[[2860.0,7.906]],"asks":[[2863.6,0.912],[2874.2,0.0]],"action":"update"}}
1651237300.1792026: {"channel":"orderbook","market":"ETH/USDT","type":"update","data":{"time":1651237300.0522609,"checksum":2121856730,"bids":[[2858.3,0.0],[2842.5,835.588]],"asks":[[2862.2,6.917],[2883.1,0.0]],"action":"update"}}
1651237300.1809764: {"channel":"orderbook","market":"SOL/USD","type":"update","data":{"time":1651237300.0553527,"checksum":3409221373,"bids":[],"asks":[[96.0225,62.6]],"action":"update"}}
1651237300.1811748: {"channel":"orderbook","market":"USD/TRY","type":"update","data":{"time":1651237300.0570443,"checksum":4178681994,"bids":[[13.9753,0.0]],"asks":[],"action":"update"}}
1651237300.1875753: {"channel":"orderbook","market":"LTC/USDT","type":"update","data":{"time":1651237300.0546024,"checksum":1733476429,"bids":[],"asks":[],"action":"update"}}
1651237300.1967573: {"channel":"orderbook","market":"ETH/USD","type":"update","data":{"time":1651237300.07057,"checksum":490713031,"bids":[],"asks":[[2867.5,0.174],[2874.1,0.0]],"action":"update"}}
1651237300.1976306: {"channel":"orderbook","market":"ETH/USDT","type":"update","data":{"time":1651237300.072864,"checksum":2057812260,"bids":[[2858.8,2.354],[2842.5,0.0]],"asks":[],"action":"update"}}
1651237300.2156837: {"channel":"orderbook","market":"ETH/USD","type":"update","data":{"time":1651237300.0887268,"checksum":3121443887,"bids":[[2860.4,36.065]],"asks":[[2861.9,0.002],[2863.2,13.068],[2874.0,0.0]],"action":"update"}}
1651237300.2282138: {"channel":"orderbook","market":"ETH/USDT","type":"update","data":{"time":1651237300.0940645,"checksum":2743606871,"bids":[[2860.5,11.445]],"asks":[],"action":"update"}}
1651237300.2282648: {"channel":"orderbook","market":"SHIB/USD","type":"update","data":{"time":1651237300.09457,"checksum":3391986333,"bids":[],"asks":[],"action":"update"}}
1651237300.2404516: {"channel":"orderbook","market":"ETH/USD","type":"update","data":{"time":1651237300.1128125,"checksum":3970241582,"bids":[[2860.5,0.0],[2860.2,2.795],[2850.0,2.702]],"asks":[[2862.6,4.73],[2863.5,1.915],[2865.0,0.003]],"action":"update"}}
1651237300.2429087: {"channel":"orderbook","market":"ETH/USDT","type":"update","data":{"time":1651237300.1175776,"checksum":3033058424,"bids":[[2860.8,23.129]],"asks":[[2865.8,272.867]],"action":"update"}}
1651237300.2540834: {"channel":"orderbook","market":"SOL/USD","type":"update","data":{"time":1651237300.126893,"checksum":2154514478,"bids":[[95.895,75.0]],"asks":[],"action":"update"}}
1651237300.2654116: {"channel":"orderbook","market":"ETH/USD","type":"update","data":{"time":1651237300.136567,"checksum":3969059556,"bids":[[2860.5,7.599],[2860.3,15.856],[2850.0,0.0]],"asks":[[2862.6,4.381]],"action":"update"}}
1651237300.2941701: {"channel":"orderbook","market":"ETH/USDT","type":"update","data":{"time":1651237300.1686168,"checksum":2652080315,"bids":[[2860.8,27.138],[2860.2,5.175],[2858.7,0.002],[2845.1,0.058],[2842.8,0.0],[2842.7,0.0]],"asks":[[2861.8,2.161]],"action":"update"}}
1651237300.3071434: {"channel":"orderbook","market":"SOL/USD","type":"update","data":{"time":1651237300.1817586,"checksum":717070235,"bids":[],"asks":[[95.93,87.0]],"action":"update"}}
1651237300.3131545: {"channel":"orderbook","market":"ETH/USD","type":"update","data":{"time":1651237300.1862948,"checksum":675853697,"bids":[[2861.2,13.827]],"asks":[[2862.7,15.679]],"action":"update"}}
1651237300.3199363: {"channel":"orderbook","market":"ETH/USDT","type":"update","data":{"time":1651237300.192752,"checksum":1838886169,"bids":[],"asks":[[2861.8,2.322]],"action":"update"}}
1651237300.3324044: {"channel":"orderbook","market":"DAI/USD","type":"update","data":{"time":1651237300.2023878,"checksum":280434518,"bids":[],"asks":[],"action":"update"}}
1651237300.349657: {"channel":"orderbook","market":"WBTC/USD","type":"update","data":{"time":1651237300.2244315,"checksum":3153251558,"bids":[[38908.0,1.02],[35606.0,0.0]],"asks":[],"action":"update"}}
1651237300.3595192: {"channel":"orderbook","market":"SOL/USD","type":"update","data":{"time":1651237300.2332306,"checksum":3642913905,"bids":[],"asks":[[95.97,0.05],[96.4125,0.0]],"action":"update"}}
1651237300.3744192: {"channel":"orderbook","market":"ETH/USDT","type":"update","data":{"time":1651237300.2476172,"checksum":3702987122,"bids":[],"asks":[[2862.0,0.011],[2862.1,1.748],[2883.0,0.0]],"action":"update"}}
1651237300.3840983: {"channel":"orderbook","market":"ETH/USD","type":"update","data":{"time":1651237300.2434452,"checksum":3753847813,"bids":[[2861.3,0.042],[2850.1,0.0]],"asks":[],"action":"update"}}
1651237300.3914547: {"channel":"orderbook","market":"ETH/USD","type":"update","data":{"time":1651237300.2644837,"checksum":2463614356,"bids":[],"asks":[[2862.0,6.762],[2862.6,4.73]],"action":"update"}}
1651237300.4009688: {"channel":"orderbook","market":"ETH/USDT","type":"update","data":{"time":1651237300.266712,"checksum":2057732067,"bids":[[2860.9,8.909]],"asks":[],"action":"update"}}
1651237300.4234526: {"channel":"orderbook","market":"SHIB/USD","type":"update","data":{"time":1651237300.2952042,"checksum":245653093,"bids":[],"asks":[[0.00002265,666700000.0]],"action":"update"}}
1651237300.4234974: {"channel":"orderbook","market":"ETH/USD","type":"update","data":{"time":1651237300.296299,"checksum":2054561756,"bids":[],"asks":[[2862.6,4.381],[2865.0,0.01]],"action":"update"}}
1651237300.4316905: {"channel":"orderbook","market":"WBTC/USD","type":"update","data":{"time":1651237300.3009028,"checksum":2538000153,"bids":[[38900.0,0.0],[35606.0,0.0001]],"asks":[],"action":"update"}}
1651237300.4640815: {"channel":"orderbook","market":"USD/TRY","type":"update","data":{"time":1651237300.3361967,"checksum":4178681994,"bids":[],"asks":[],"action":"update"}}
1651237300.4758224: {"channel":"orderbook","market":"SOL/USD","type":"update","data":{"time":1651237300.3436654,"checksum":2838045357,"bids":[[95.8825,425.72]],"asks":[],"action":"update"}}
1651237300.4877822: {"channel":"orderbook","market":"SOL/USD","type":"update","data":{"time":1651237300.3625398,"checksum":4164697099,"bids":[[95.915,0.0],[95.485,4.58]],"asks":[[95.93,51.0]],"action":"update"}}
1651237300.4960845: {"channel":"orderbook","market":"SHIB/USD","type":"update","data":{"time":1651237300.369376,"checksum":3060305217,"bids":[],"asks":[[0.00002266,382800000.0]],"action":"update"}}
1651237300.5182593: {"channel":"orderbook","market":"ETH/USDT","type":"update","data":{"time":1651237300.3920398,"checksum":2712600337,"bids":[],"asks":[[2863.9,2.354]],"action":"update"}}
1651237300.523285: {"channel":"orderbook","market":"ETH/USD","type":"update","data":{"time":1651237300.3899024,"checksum":3978743955,"bids":[],"asks":[[2863.9,10.456]],"action":"update"}}
1651237300.532906: {"channel":"orderbook","market":"LTC/USDT","type":"update","data":{"time":1651237300.4049673,"checksum":3567184416,"bids":[[100.48,0.0],[96.55,0.23]],"asks":[],"action":"update"}}
1651237300.5433533: {"channel":"orderbook","market":"ETH/USD","type":"update","data":{"time":1651237300.41396,"checksum":234233934,"bids":[],"asks":[[2863.8,0.01]],"action":"update"}}
1651237300.5442872: {"channel":"orderbook","market":"SOL/USD","type":"update","data":{"time":1651237300.41648,"checksum":2499981198,"bids":[[95.9075,117.1],[95.8775,20.0],[95.485,0.0]],"asks":[[95.9275,36.0],[96.41,0.0]],"action":"update"}}
1651237300.5673223: {"channel":"orderbook","market":"ETH/USD","type":"update","data":{"time":1651237300.438776,"checksum":1437136704,"bids":[],"asks":[[2863.2,13.25]],"action":"update"}}
1651237300.5726464: {"channel":"orderbook","market":"ETH/USDT","type":"update","data":{"time":1651237300.4464557,"checksum":3641455622,"bids":[[2861.6,4.521],[2860.4,0.0],[2842.8,0.01]],"asks":[[2862.5,2.151],[2862.7,8.949],[2863.2,0.0],[2883.0,0.029]],"action":"update"}}
1651237300.5991366: {"channel":"orderbook","market":"SOL/USD","type":"update","data":{"time":1651237300.4625401,"checksum":686189263,"bids":[],"asks":[[96.0225,0.05]],"action":"update"}}
1651237300.6117358: {"channel":"orderbook","market":"LTC/USDT","type":"update","data":{"time":1651237300.4796336,"checksum":647723362,"bids":[],"asks":[[100.7,0.0],[103.96,0.29]],"action":"update"}}
1651237300.648038: {"channel":"orderbook","market":"SOL/USD","type":"update","data":{"time":1651237300.5178478,"checksum":2035976717,"bids":[[95.835,0.0],[95.485,4.58]],"asks":[],"action":"update"}}
1651237300.6480873: {"channel":"orderbook","market":"ETH/USDT","type":"update","data":{"time":1651237300.5190496,"checksum":2855395394,"bids":[],"asks":[[2862.7,28.733]],"action":"update"}}
1651237300.6511426: {"channel":"orderbook","market":"ETH/USD","type":"update","data":{"time":1651237300.5090644,"checksum":531407476,"bids":[[2861.7,4.485]],"asks":[[2862.6,4.73]],"action":"update"}}
1651237300.6742966: {"channel":"orderbook","market":"FTT/BTC","type":"update","data":{"time":1651237300.5458689,"checksum":2903929790,"bids":[],"asks":[],"action":"update"}}
1651237300.6858008: {"channel":"orderbook","market":"ETH/USD","type":"update","data":{"time":1651237300.555694,"checksum":3827897278,"bids":[],"asks":[[2862.7,29.913],[2862.9,19.343],[2868.4,0.0]],"action":"update"}}
1651237300.7170467: {"channel":"orderbook","market":"BTC/TRY","type":"update","data":{"time":1651237300.5861793,"checksum":1840591949,"bids":[],"asks":[],"action":"update"}}
1651237300.7202191: {"channel":"orderbook","market":"ETH/USD","type":"update","data":{"time":1651237300.586623,"checksum":150323219,"bids":[[2859.6,4.486]],"asks":[],"action":"update"}}
1651237300.7346606: {"channel":"orderbook","market":"ETH/USD","type":"update","data":{"time":1651237300.6049879,"checksum":2133905421,"bids":[],"asks":[[2862.6,4.381]],"action":"update"}}
1651237300.7434123: {"channel":"orderbook","market":"ETH/USDT","type":"update","data":{"time":1651237300.6176035,"checksum":2877172706,"bids":[],"asks":[[2865.8,130.466]],"action":"update"}}
1651237300.7531116: {"channel":"orderbook","market":"SOL/USD","type":"update","data":{"time":1651237300.6255307,"checksum":1727879272,"bids":[],"asks":[[96.0325,389.3]],"action":"update"}}
1651237300.759185: {"channel":"orderbook","market":"LTC/USDT","type":"update","data":{"time":1651237300.6317441,"checksum":1592553808,"bids":[[100.495,17.2],[96.55,0.0]],"asks":[],"action":"update"}}
1651237300.7669575: {"channel":"orderbook","market":"ETH/USDT","type":"update","data":{"time":1651237300.641972,"checksum":2865720788,"bids":[[2860.8,23.129]],"asks":[],"action":"update"}}
1651237300.7772264: {"channel":"orderbook","market":"ETH/USD","type":"update","data":{"time":1651237300.6381726,"checksum":4202702670,"bids":[[2861.6,0.0],[2850.1,5.654]],"asks":[[2866.2,0.0],[2874.0,2.281]],"action":"update"}}
1651237300.777291: {"channel":"orderbook","market":"SHIB/USD","type":"update","data":{"time":1651237300.6448169,"checksum":2066847334,"bids":[[0.00002255,75400000.0]],"asks":[],"action":"update"}}
1651237300.8030336: {"channel":"orderbook","market":"SOL/USD","type":"update","data":{"time":1651237300.667199,"checksum":2294278743,"bids":[[95.9175,0.0],[95.5425,0.0],[95.4825,2.08],[95.48,0.2]],"asks":[[96.0375,111.49]],"action":"update"}}
1651237300.8093052: {"channel":"orderbook","market":"WBTC/USD","type":"update","data":{"time":1651237300.6792166,"checksum":528187821,"bids":[[38908.0,0.0],[35587.0,0.0016]],"asks":[],"action":"update"}}
1651237300.825935: {"channel":"orderbook","market":"ETH/USDT","type":"update","data":{"time":1651237300.6937704,"checksum":2904096482,"bids":[[2861.1,4.291],[2859.3,0.515]],"asks":[],"action":"update"}}
1651237300.8259952: {"channel":"orderbook","market":"SOL/USD","type":"update","data":{"time":1651237300.6980586,"checksum":2209629934,"bids":[[95.9075,81.1],[95.825,146.28],[95.7375,0.52]],"asks":[],"action":"update"}}
1651237300.8310175: {"channel":"orderbook","market":"LTC/USDT","type":"update","data":{"time":1651237300.7049391,"checksum":209246805,"bids":[[100.57,14.91],[96.635,0.0]],"asks":[],"action":"update"}}
1651237300.8490489: {"channel":"orderbook","market":"SHIB/USD","type":"update","data":{"time":1651237300.72119,"checksum":1650392601,"bids":[[0.00002262,61600000.0]],"asks":[],"action":"update"}}
1651237300.8559482: {"channel":"orderbook","market":"USD/TRY","type":"update","data":{"time":1651237300.73198,"checksum":2479525932,"bids":[[13.8448,0.0]],"asks":[],"action":"update"}}
1651237300.8622522: {"channel":"orderbook","market":"WBTC/USD","type":"update","data":{"time":1651237300.7320845,"checksum":528187821,"bids":[],"asks":[],"action":"update"}}
1651237300.8739688: {"channel":"orderbook","market":"ETH/USD","type":"update","data":{"time":1651237300.7192595,"checksum":1207305193,"bids":[[2861.3,0.0],[2850.0,2.702]],"asks":[],"action":"update"}}
1651237300.8740144: {"channel":"orderbook","market":"SOL/USD","type":"update","data":{"time":1651237300.7472045,"checksum":3929685764,"bids":[[95.9075,0.0],[95.72,0.0],[95.4775,27.14],[95.4725,0.03]],"asks":[],"action":"update"}}
1651237300.8947914: {"channel":"orderbook","market":"ETH/USD","type":"update","data":{"time":1651237300.762255,"checksum":997788839,"bids":[[2861.3,0.042],[2850.0,0.0]],"asks":[[2862.6,4.73],[2869.4,0.0],[2874.1,472.803]],"action":"update"}}
1651237300.90431: {"channel":"orderbook","market":"SOL/USD","type":"update","data":{"time":1651237300.7786849,"checksum":3003769011,"bids":[[95.895,5.0],[95.745,26.1],[95.4725,0.0]],"asks":[],"action":"update"}}
1651237300.9043624: {"channel":"orderbook","market":"LTC/USDT","type":"update","data":{"time":1651237300.7809663,"checksum":4121070661,"bids":[[100.54,1.31],[96.845,0.0]],"asks":[],"action":"update"}}
1651237300.9513862: {"channel":"orderbook","market":"ETH/USD","type":"update","data":{"time":1651237300.8083706,"checksum":1397786184,"bids":[],"asks":[[2861.8,6.045],[2862.6,4.381]],"action":"update"}}
1651237300.9514601: {"channel":"orderbook","market":"SOL/USD","type":"update","data":{"time":1651237300.8253489,"checksum":1247005313,"bids":[[95.8675,0.0],[95.4725,0.03]],"asks":[[95.9575,53.81],[96.03,99.25]],"action":"update"}}
1651237300.9602938: {"channel":"orderbook","market":"WBTC/USD","type":"update","data":{"time":1651237300.8294778,"checksum":1338497487,"bids":[[38900.0,0.1155],[35587.0,0.0]],"asks":[],"action":"update"}}
1651237300.9610872: {"channel":"orderbook","market":"ETH/USD","type":"update","data":{"time":1651237300.8327627,"checksum":4208788840,"bids":[],"asks":[[2866.8,3.032]],"action":"update"}}
1651237300.9794555: {"channel":"orderbook","market":"SOL/USD","type":"update","data":{"time":1651237300.8486397,"checksum":2948006025,"bids":[[95.8925,45.29]],"asks":[],"action":"update"}}
1651237300.9837787: {"channel":"orderbook","market":"ETH/USDT","type":"update","data":{"time":1651237300.8566275,"checksum":3474095665,"bids":[[2861.6,5.379],[2860.0,2.271]],"asks":[],"action":"update"}}
1651237300.9993813: {"channel":"orderbook","market":"SOL/USD","type":"update","data":{"time":1651237300.8742688,"checksum":2623810783,"bids":[[95.5375,10.0],[95.4725,0.0]],"asks":[[95.925,73.49],[96.1825,0.01],[96.4,0.0],[96.405,0.0]],"action":"update"}}
1651237301.0254881: {"channel":"orderbook","market":"ETH/USDT","type":"update","data":{"time":1651237300.8930852,"checksum":2268011150,"bids":[[2860.4,0.677],[2842.8,0.0]],"asks":[],"action":"update"}}
1651237301.0439904: {"channel":"orderbook","market":"ETH/USD","type":"update","data":{"time":1651237300.910403,"checksum":972752044,"bids":[[2861.7,0.513],[2860.3,0.22],[2855.7,10.93]],"asks":[[2862.2,10.197],[2871.6,0.001],[2874.1,0.0]],"action":"update"}}
1651237301.0624907: {"channel":"orderbook","market":"ETH/USD","type":"update","data":{"time":1651237300.9330719,"checksum":400606138,"bids":[],"asks":[[2861.8,10.145],[2864.9,177.094]],"action":"update"}}
1651237301.0764375: {"channel":"orderbook","market":"SOL/USD","type":"update","data":{"time":1651237300.9403348,"checksum":4023460373,"bids":[[95.8825,357.7],[95.8775,0.0],[95.4725,0.03]],"asks":[[95.925,80.75],[95.9275,0.0],[96.4,16.48]],"action":"update"}}
1651237301.0765002: {"channel":"orderbook","market":"ETH/USDT","type":"update","data":{"time":1651237300.944074,"checksum":1810252350,"bids":[[2861.7,0.24],[2860.9,14.695]],"asks":[[2862.6,12.913]],"action":"update"}}
1651237301.099861: {"channel":"orderbook","market":"SOL/USD","type":"update","data":{"time":1651237300.956928,"checksum":2218664249,"bids":[],"asks":[[95.9225,70.0],[95.9275,70.0],[95.93,0.0],[95.9375,0.0]],"action":"update"}}
1651237301.1088893: {"channel":"orderbook","market":"ETH/USD","type":"update","data":{"time":1651237300.9621282,"checksum":347811242,"bids":[[2861.4,0.0],[2850.0,2.702]],"asks":[[2862.5,18.122],[2863.2,13.17]],"action":"update"}}
1651237301.1236024: {"channel":"orderbook","market":"ETH/USD","type":"update","data":{"time":1651237300.9916613,"checksum":3774301173,"bids":[[2861.1,7.634],[2858.4,0.001]],"asks":[[2862.5,0.83],[2865.2,4.407]],"action":"update"}}
1651237301.129873: {"channel":"orderbook","market":"ETH/USDT","type":"update","data":{"time":1651237300.9953756,"checksum":1653110606,"bids":[[2861.6,4.521],[2860.8,3.495]],"asks":[[2862.8,0.098]],"action":"update"}}
1651237301.140962: {"channel":"orderbook","market":"SOL/USD","type":"update","data":{"time":1651237300.9971008,"checksum":2077689277,"bids":[[95.8975,0.0],[95.895,0.0],[95.8925,9.29],[95.8125,0.0],[95.47,1.12],[95.4675,0.19],[95.45,0.39]],"asks":[[95.925,10.75],[95.9275,0.0],[95.945,0.0],[95.96,109.91],[96.03,65.85],[96.405,19.0],[96.41,0.38]],"action":"update"}}
1651237301.1465867: {"channel":"orderbook","market":"ETH/USD","type":"update","data":{"time":1651237301.0167866,"checksum":1326347876,"bids":[[2861.3,3.793]],"asks":[[2861.8,12.145],[2862.6,4.73]],"action":"update"}}
1651237301.1692622: {"channel":"orderbook","market":"SOL/USD","type":"update","data":{"time":1651237301.0330613,"checksum":535171572,"bids":[[95.885,36.0],[95.855,0.0],[95.4475,0.03]],"asks":[[95.925,66.08],[95.93,57.99],[95.97,0.0]],"action":"update"}}
1651237301.1937854: {"channel":"orderbook","market":"ETH/USD","type":"update","data":{"time":1651237301.041224,"checksum":3809636757,"bids":[[2861.5,0.01],[2861.2,3.493]],"asks":[[2861.9,3.999],[2862.4,0.0],[2864.1,22.579],[2874.1,472.803]],"action":"update"}}
1651237301.1938467: {"channel":"orderbook","market":"ETH/USDT","type":"update","data":{"time":1651237301.0509472,"checksum":469491840,"bids":[[2861.7,0.0],[2861.6,0.0],[2861.0,6.16],[2860.9,5.414],[2860.4,0.0],[2859.6,6.993],[2842.8,0.01],[2842.7,0.018]],"asks":[[2862.6,8.384],[2862.7,35.229],[2864.4,0.0],[2883.1,0.3]],"action":"update"}}
1651237301.2021592: {"channel":"orderbook","market":"ETH/USD","type":"update","data":{"time":1651237301.0675638,"checksum":454532334,"bids":[[2861.3,0.042],[2860.4,20.011],[2855.8,7.017]],"asks":[[2862.0,12.015],[2862.6,4.381],[2863.7,1.254],[2863.9,32.642],[2864.8,42.125],[2865.7,17.247]],"action":"update"}}
1651237301.2074687: {"channel":"orderbook","market":"ETH/USDT","type":"update","data":{"time":1651237301.0774438,"checksum":2989515755,"bids":[[2861.5,9.388],[2861.4,25.886],[2861.2,3.816],[2860.5,11.402],[2842.7,0.0]],"asks":[[2861.7,5.0],[2862.3,7.029],[2883.1,0.0]],"action":"update"}}
1651237301.2077808: {"channel":"orderbook","market":"LTC/USDT","type":"update","data":{"time":1651237301.0800545,"checksum":4121070661,"bids":[],"asks":[],"action":"update"}}
1651237301.2361264: {"channel":"orderbook","market":"ETH/USD","type":"update","data":{"time":1651237301.0955644,"checksum":2306681125,"bids":[[2861.7,0.0],[2861.2,3.826],[2860.4,19.937],[2859.8,4.707],[2858.7,2.121],[2857.1,1.671],[2853.2,0.121]],"asks":[[2861.7,4.487],[2862.0,23.603],[2862.2,13.322],[2863.2,13.255],[2863.9,10.456],[2864.1,2.042],[2865.0,0.003],[2874.1,0.0]],"action":"update"}}
1651237301.2362356: {"channel":"orderbook","market":"ETH/USDT","type":"update","data":{"time":1651237301.0978415,"checksum":530049173,"bids":[[2861.4,0.0],[2842.7,0.018]],"asks":[[2861.8,0.322]],"action":"update"}}
1651237301.2362893: {"channel":"orderbook","market":"SOL/USD","type":"update","data":{"time":1651237301.0920901,"checksum":634562723,"bids":[[95.895,2.09],[95.8925,0.0],[95.8875,81.11],[95.8825,105.25],[95.87,0.0],[95.8675,20.0],[95.865,68.02],[95.45,0.0],[95.4475,0.0]],"asks":[[95.91,51.0],[95.9175,132.11],[95.92,89.74],[95.93,0.0],[95.9825,0.08],[95.9925,33.4],[96.0175,0.0],[96.03,163.2],[96.1825,0.0],[96.41,0.0]],"action":"update"}}
1651237301.2550309: {"channel":"orderbook","market":"ETH/USD","type":"update","data":{"time":1651237301.1224039,"checksum":2990876788,"bids":[[2861.2,0.333],[2860.4,38.964]],"asks":[[2861.8,25.366],[2861.9,3.01],[2862.0,35.648],[2863.4,6.031],[2864.0,38.776],[2864.8,34.875]],"action":"update"}}
1651237301.2551188: {"channel":"orderbook","market":"SOL/USD","type":"update","data":{"time":1651237301.1225307,"checksum":921425241,"bids":[[95.875,5.0],[95.845,149.29],[95.4675,0.0]],"asks":[[96.015,0.0],[96.41,0.38]],"action":"update"}}
1651237301.2653906: {"channel":"orderbook","market":"SHIB/USD","type":"update","data":{"time":1651237301.1205535,"checksum":1650392601,"bids":[],"asks":[],"action":"update"}}
1651237301.2654216: {"channel":"orderbook","market":"ETH/USDT","type":"update","data":{"time":1651237301.1334703,"checksum":3478069203,"bids":[[2861.5,4.859],[2861.2,0.321],[2860.4,3.495],[2860.1,19.659],[2858.8,6.724],[2842.8,0.0],[2842.7,0.0]],"asks":[[2861.8,0.0],[2862.2,0.0],[2862.3,4.529],[2862.7,31.734],[2863.6,4.37],[2883.1,0.3]],"action":"update"}}
1651237301.2810938: {"channel":"orderbook","market":"SOL/USD","type":"update","data":{"time":1651237301.1425135,"checksum":4199418330,"bids":[[95.8825,0.0],[95.875,0.0],[95.8425,150.83],[95.4675,0.19],[95.45,0.39]],"asks":[[95.92,53.74],[95.9225,0.0],[95.94,105.27],[96.05,0.06]],"action":"update"}}
1651237301.2811613: {"channel":"orderbook","market":"ETH/USD","type":"update","data":{"time":1651237301.1434586,"checksum":1987782718,"bids":[[2861.1,1.973],[2860.8,34.705],[2859.6,1.361]],"asks":[[2861.6,4.165],[2861.8,24.516],[2861.9,5.91],[2862.8,3.5],[2874.0,0.0]],"action":"update"}}
1651237301.3079278: {"channel":"orderbook","market":"ETH/USD","type":"update","data":{"time":1651237301.1693504,"checksum":2790775709,"bids":[[2861.2,0.335]],"asks":[[2861.6,10.165],[2862.3,5.663],[2862.7,39.271],[2868.2,0.001]],"action":"update"}}
1651237301.3080223: {"channel":"orderbook","market":"SOL/USD","type":"update","data":{"time":1651237301.169247,"checksum":1850491266,"bids":[[95.865,76.63],[95.8025,0.0],[95.7775,56.31],[95.4475,0.03]],"asks":[[95.925,10.75]],"action":"update"}}
1651237301.3137145: {"channel":"orderbook","market":"ETH/USDT","type":"update","data":{"time":1651237301.1788166,"checksum":1300341073,"bids":[[2861.5,0.0],[2861.1,0.098],[2842.8,0.01]],"asks":[[2861.6,2.0],[2861.8,2.5],[2862.1,0.0],[2883.1,0.0]],"action":"update"}}
1651237301.315507: {"channel":"orderbook","market":"LTC/USDT","type":"update","data":{"time":1651237301.1865096,"checksum":1432478490,"bids":[],"asks":[[100.75,0.0],[104.0,0.01]],"action":"update"}}
1651237301.3243778: {"channel":"orderbook","market":"SOL/USD","type":"update","data":{"time":1651237301.1937575,"checksum":2136194756,"bids":[[95.895,0.0],[95.8875,63.76],[95.885,0.0],[95.44,1.0],[95.4375,0.01]],"asks":[[95.9075,36.0],[95.94,0.0],[95.99,252.65]],"action":"update"}}
1651237301.3303897: {"channel":"orderbook","market":"ETH/USD","type":"update","data":{"time":1651237301.1950638,"checksum":3477671134,"bids":[[2860.9,6.752],[2860.2,0.0],[2859.8,5.056],[2849.9,701.833]],"asks":[[2861.6,20.041],[2861.8,23.263],[2864.2,0.002]],"action":"update"}}
1651237301.3370624: {"channel":"orderbook","market":"ETH/USDT","type":"update","data":{"time":1651237301.2087066,"checksum":723668852,"bids":[[2861.2,4.85],[2856.3,0.365]],"asks":[[2861.8,0.0],[2862.2,3.495],[2862.4,0.0],[2883.1,0.3]],"action":"update"}}
1651237301.347177: {"channel":"orderbook","market":"ETH/USD","type":"update","data":{"time":1651237301.2200549,"checksum":3440917572,"bids":[[2860.5,13.26],[2856.6,6.258]],"asks":[[2861.6,13.911],[2862.0,18.35],[2862.6,9.826]],"action":"update"}}
1651237301.3472378: {"channel":"orderbook","market":"ETH/USDT","type":"update","data":{"time":1651237301.2209997,"checksum":1489826052,"bids":[],"asks":[[2861.6,0.0],[2883.5,0.032]],"action":"update"}}
1651237301.3596725: {"channel":"orderbook","market":"DAI/USD","type":"update","data":{"time":1651237301.2287152,"checksum":280434518,"bids":[],"asks":[],"action":"update"}}
1651237301.3697724: {"channel":"orderbook","market":"SOL/USD","type":"update","data":{"time":1651237301.2380261,"checksum":2655989258,"bids":[[95.8875,34.47],[95.8675,28.13],[95.85,252.45],[95.4375,0.0]],"asks":[],"action":"update"}}
1651237301.3748267: {"channel":"orderbook","market":"ETH/USD","type":"update","data":{"time":1651237301.2446907,"checksum":1730759451,"bids":[[2861.3,0.0],[2849.8,0.032]],"asks":[[2862.4,0.349],[2862.7,37.971],[2873.9,0.0]],"action":"update"}}
1651237301.3751445: {"channel":"orderbook","market":"LTC/USDT","type":"update","data":{"time":1651237301.247926,"checksum":1320897715,"bids":[[100.62,66.01]],"asks":[],"action":"update"}}
1651237301.3795297: {"channel":"orderbook","market":"ETH/USDT","type":"update","data":{"time":1651237301.247753,"checksum":1802745088,"bids":[[2861.3,2.5],[2861.0,0.0],[2860.6,10.412]],"asks":[[2862.6,7.188]],"action":"update"}}
1651237301.4462304: {"channel":"orderbook","market":"ETH/USD","type":"update","data":{"time":1651237301.2686844,"checksum":2521301539,"bids":[[2861.1,0.0],[2859.2,27.477],[2849.7,0.01]],"asks":[[2861.7,15.553],[2865.0,0.01]],"action":"update"}}
1651237301.4463177: {"channel":"orderbook","market":"LTC/USDT","type":"update","data":{"time":1651237301.2737422,"checksum":252572099,"bids":[[100.5,61.29]],"asks":[],"action":"update"}}
1651237301.4463568: {"channel":"orderbook","market":"SOL/USD","type":"update","data":{"time":1651237301.2695227,"checksum":3182857346,"bids":[[95.8875,0.0],[95.8675,8.13],[95.865,68.02],[95.4375,0.01]],"asks":[[95.905,280.0],[95.91,0.0],[96.0375,7.26]],"action":"update"}}
1651237301.4464176: {"channel":"orderbook","market":"SHIB/USD","type":"update","data":{"time":1651237301.2715378,"checksum":2936530238,"bids":[[0.00002255,47400000.0]],"asks":[],"action":"update"}}
1651237301.4464543: {"channel":"orderbook","market":"ETH/USDT","type":"update","data":{"time":1651237301.2744281,"checksum":238898293,"bids":[[2860.8,7.504],[2859.4,10.9],[2857.3,4.842],[2842.8,0.0]],"asks":[[2861.6,6.919],[2883.5,0.0]],"action":"update"}}
1651237301.446507: {"channel":"orderbook","market":"SOL/USD","type":"update","data":{"time":1651237301.2835057,"checksum":49626059,"bids":[[95.8425,117.43]],"asks":[],"action":"update"}}
1651237301.4465432: {"channel":"orderbook","market":"ETH/USDT","type":"update","data":{"time":1651237301.2991908,"checksum":364833329,"bids":[[2860.6,6.917],[2859.4,5.0]],"asks":[[2861.8,1.748],[2862.3,15.722],[2883.1,0.0]],"action":"update"}}
1651237301.4466305: {"channel":"orderbook","market":"ETH/USD","type":"update","data":{"time":1651237301.2987335,"checksum":3284913857,"bids":[[2861.5,0.0],[2861.3,0.042],[2861.0,0.0],[2859.4,15.196],[2853.2,0.001],[2849.6,0.071]],"asks":[[2865.7,10.924]],"action":"update"}}
1651237301.4497287: {"channel":"orderbook","market":"SOL/USD","type":"update","data":{"time":1651237301.321878,"checksum":771658000,"bids":[[95.8525,63.15],[95.83,137.41],[95.705,275.32],[95.44,0.0],[95.4375,0.0]],"asks":[[96.2275,0.04]],"action":"update"}}
1651237301.458938: {"channel":"orderbook","market":"ETH/USD","type":"update","data":{"time":1651237301.326019,"checksum":2326880003,"bids":[[2861.3,0.0],[2861.2,0.0],[2860.8,17.412],[2859.8,4.707],[2849.5,0.01],[2849.4,0.04]],"asks":[[2861.7,10.303],[2861.8,19.266],[2864.8,25.985]],"action":"update"}}
1651237301.464058: {"channel":"orderbook","market":"ETH/USDT","type":"update","data":{"time":1651237301.328587,"checksum":626249438,"bids":[[2861.3,0.0],[2861.2,24.773],[2860.7,0.181],[2860.6,0.0],[2852.2,0.399],[2842.8,0.01]],"asks":[[2861.6,0.0],[2861.7,7.5],[2862.3,11.193],[2862.5,2.325],[2862.7,26.28],[2883.1,0.3]],"action":"update"}}
1651237301.464164: {"channel":"orderbook","market":"SHIB/USD","type":"update","data":{"time":1651237301.3250532,"checksum":614242623,"bids":[[0.00002262,500000.0]],"asks":[[0.00002264,271700000.0],[0.00002265,610700000.0]],"action":"update"}}
1651237301.4897408: {"channel":"orderbook","market":"ETH/USDT","type":"update","data":{"time":1651237301.3546183,"checksum":3650287925,"bids":[[2861.2,4.529]],"asks":[[2861.7,17.232],[2862.0,4.54],[2863.0,1.259]],"action":"update"}}
1651237301.4898293: {"channel":"orderbook","market":"ETH/USD","type":"update","data":{"time":1651237301.35291,"checksum":2132744365,"bids":[[2861.0,3.751],[2859.9,43.967],[2859.3,8.588],[2858.9,0.0],[2856.8,0.758]],"asks":[[2861.4,9.285],[2861.6,8.996],[2861.8,15.515],[2862.7,23.737],[2873.7,0.0]],"action":"update"}}
1651237301.4969132: {"channel":"orderbook","market":"USD/TRY","type":"update","data":{"time":1651237301.3654299,"checksum":2479525932,"bids":[],"asks":[],"action":"update"}}
1651237301.5047262: {"channel":"orderbook","market":"ETH/USDT","type":"update","data":{"time":1651237301.3742762,"checksum":2928734626,"bids":[[2860.8,7.743],[2860.1,23.155]],"asks":[[2861.6,2.5],[2861.9,11.695],[2862.5,2.151],[2863.4,0.54],[2883.0,0.0],[2883.1,0.0]],"action":"update"}}
1651237301.5078096: {"channel":"orderbook","market":"ETH/USD","type":"update","data":{"time":1651237301.377231,"checksum":3477164115,"bids":[[2861.0,0.0],[2860.7,6.389],[2859.2,18.29],[2856.6,5.258],[2849.3,0.041]],"asks":[[2861.4,0.0],[2861.5,5.0],[2861.6,14.806],[2861.8,22.206],[2863.2,8.609],[2863.7,4.049]],"action":"update"}}
1651237301.5093205: {"channel":"orderbook","market":"SOL/USD","type":"update","data":{"time":1651237301.370426,"checksum":6029238,"bids":[[95.8675,0.0],[95.865,0.0],[95.8225,90.97],[95.7975,8.62],[95.44,1.0],[95.4375,0.01]],"asks":[[95.89,131.26],[95.905,350.0],[95.9075,0.0],[95.915,62.78],[95.92,0.0],[95.925,7.26]],"action":"update"}}
1651237301.5100148: {"channel":"orderbook","market":"WBTC/USD","type":"update","data":{"time":1651237301.3798568,"checksum":691731534,"bids":[[38925.0,0.0],[35587.0,0.0016]],"asks":[],"action":"update"}}
1651237301.5278141: {"channel":"orderbook","market":"SHIB/USD","type":"update","data":{"time":1651237301.3969085,"checksum":3846370582,"bids":[[0.00002262,0.0],[0.00002161,100000.0]],"asks":[[0.00002263,59500000.0]],"action":"update"}}
1651237301.5354748: {"channel":"orderbook","market":"ETH/USDT","type":"update","data":{"time":1651237301.4048002,"checksum":1539926248,"bids":[[2860.8,4.248],[2854.5,15.267],[2842.8,0.0]],"asks":[[2861.4,2.095],[2861.5,1.361],[2862.2,0.0],[2865.3,0.077],[2882.6,0.0],[2882.9,0.0]],"action":"update"}}
1651237301.5380878: {"channel":"orderbook","market":"ETH/USD","type":"update","data":{"time":1651237301.4039812,"checksum":3144106356,"bids":[[2860.8,17.683],[2860.7,3.493],[2860.6,9.977],[2860.1,19.275],[2859.9,21.343],[2859.7,4.836]],"asks":[[2861.3,4.719],[2861.4,5.742],[2861.5,7.441],[2861.6,15.141],[2862.0,6.762],[2862.9,0.0],[2863.4,7.901],[2867.2,4.003],[2873.6,0.0]],"action":"update"}}
1651237301.5571878: {"channel":"orderbook","market":"SHIB/USD","type":"update","data":{"time":1651237301.4206097,"checksum":2961999423,"bids":[],"asks":[[0.00002264,243500000.0]],"action":"update"}}
1651237301.5624459: {"channel":"orderbook","market":"ETH/USD","type":"update","data":{"time":1651237301.4314501,"checksum":3764354091,"bids":[[2860.0,14.736],[2859.4,12.071],[2859.3,6.823],[2855.3,7.948]],"asks":[[2861.0,4.519],[2861.1,1.9],[2861.3,9.356],[2861.4,11.872],[2861.5,9.833],[2861.6,31.034],[2862.2,10.197],[2873.4,0.0],[2873.5,0.0]],"action":"update"}}
1651237301.568018: {"channel":"orderbook","market":"ETH/USDT","type":"update","data":{"time":1651237301.4319265,"checksum":3929878688,"bids":[[2860.9,7.296]],"asks":[[2861.4,2.0],[2861.6,6.815],[2862.0,11.231]],"action":"update"}}
1651237301.579376: {"channel":"orderbook","market":"SOL/USD","type":"update","data":{"time":1651237301.4382193,"checksum":2785437873,"bids":[[95.86,0.0],[95.8525,47.37],[95.435,0.01]],"asks":[[95.89,70.0],[95.9,97.64],[96.025,0.03],[96.41,0.0]],"action":"update"}}
1651237301.5886219: {"channel":"orderbook","market":"ETH/USD","type":"update","data":{"time":1651237301.452457,"checksum":3476727555,"bids":[[2860.8,17.412],[2860.3,0.0],[2859.6,8.561],[2858.1,4.381],[2849.1,0.004]],"asks":[[2861.1,3.646],[2861.3,7.256],[2861.4,13.476],[2861.5,7.441],[2861.6,21.787],[2861.9,3.01]],"action":"update"}}
1651237301.588716: {"channel":"orderbook","market":"ETH/USDT","type":"update","data":{"time":1651237301.4570677,"checksum":1586364589,"bids":[[2860.9,5.414]],"asks":[[2862.7,6.496]],"action":"update"}}
1651237301.594097: {"channel":"orderbook","market":"WBTC/USD","type":"update","data":{"time":1651237301.4564714,"checksum":3501912508,"bids":[[38916.0,0.0193],[35587.0,0.0]],"asks":[],"action":"update"}}
1651237301.6004033: {"channel":"orderbook","market":"SHIB/USD","type":"update","data":{"time":1651237301.471119,"checksum":2389982590,"bids":[[0.00002259,399000000.0]],"asks":[],"action":"update"}}
1651237301.6049376: {"channel":"orderbook","market":"FTT/BTC","type":"update","data":{"time":1651237301.4730625,"checksum":995968909,"bids":[[0.0010076,0.1]],"asks":[],"action":"update"}}
1651237301.611223: {"channel":"orderbook","market":"ETH/USD","type":"update","data":{"time":1651237301.4795604,"checksum":2393152842,"bids":[[2860.9,0.0],[2860.8,0.0],[2860.4,24.518],[2859.6,1.361],[2857.3,2.056],[2855.3,1.948],[2849.0,0.015]],"asks":[[2861.1,3.493],[2861.3,0.0],[2861.4,17.84],[2861.7,15.553],[2862.7,9.708],[2864.8,19.451],[2867.9,6.0]],"action":"update"}}
1651237301.6159017: {"channel":"orderbook","market":"ETH/USDT","type":"update","data":{"time":1651237301.4840593,"checksum":3053194293,"bids":[[2860.5,0.0],[2860.2,8.671],[2842.8,0.01]],"asks":[[2861.4,0.0],[2861.9,3.496],[2862.6,2.828],[2882.6,0.1]],"action":"update"}}
1651237301.6290581: {"channel":"orderbook","market":"SOL/USD","type":"update","data":{"time":1651237301.4985058,"checksum":2321730195,"bids":[[95.85,0.0],[95.825,208.92],[95.43,0.25]],"asks":[[95.89,77.26],[95.915,0.0],[96.41,0.38]],"action":"update"}}
1651237301.6291294: {"channel":"orderbook","market":"SHIB/USD","type":"update","data":{"time":1651237301.4972813,"checksum":369805709,"bids":[],"asks":[[0.00002262,100000.0],[0.00002263,83500000.0],[0.00002375,0.0]],"action":"update"}}
1651237301.6291747: {"channel":"orderbook","market":"LTC/USDT","type":"update","data":{"time":1651237301.4994886,"checksum":512356774,"bids":[],"asks":[[100.7,1.95],[104.0,0.0]],"action":"update"}}
1651237301.6419802: {"channel":"orderbook","market":"ETH/USDT","type":"update","data":{"time":1651237301.5103538,"checksum":3438066324,"bids":[[2861.2,0.0],[2860.7,0.0],[2860.2,5.175],[2842.7,0.018],[2842.5,835.588]],"asks":[[2861.3,2.0],[2861.9,0.0],[2862.5,0.01],[2862.7,12.379],[2863.4,0.365]],"action":"update"}}
1651237301.6611853: {"channel":"orderbook","market":"SOL/USD","type":"update","data":{"time":1651237301.5248287,"checksum":3394046250,"bids":[[95.855,126.59],[95.8525,0.0]],"asks":[[95.8875,70.0],[95.9375,105.27],[95.9625,407.96],[96.03,763.34],[96.405,0.0],[96.41,0.0]],"action":"update"}}
1651237301.675661: {"channel":"orderbook","market":"ETH/USDT","type":"update","data":{"time":1651237301.5407827,"checksum":1302237620,"bids":[[2860.6,6.16],[2842.5,0.0]],"asks":[],"action":"update"}}
1651237301.6757264: {"channel":"orderbook","market":"SHIB/USD","type":"update","data":{"time":1651237301.5455031,"checksum":383612119,"bids":[],"asks":[[0.00002262,19800000.0]],"action":"update"}}
1651237301.6950846: {"channel":"orderbook","market":"ETH/USDT","type":"update","data":{"time":1651237301.5584724,"checksum":3969361318,"bids":[],"asks":[[2861.3,1.748],[2861.5,0.0],[2882.9,0.015]],"action":"update"}}
1651237301.7003608: {"channel":"orderbook","market":"ETH/USD","type":"update","data":{"time":1651237301.5512135,"checksum":2943957052,"bids":[[2860.6,0.0],[2860.2,1.0],[2855.5,5.67]],"asks":[[2861.0,2.619],[2861.2,2.0],[2861.3,2.968],[2861.4,13.845],[2861.5,12.759],[2861.6,8.59],[2861.7,15.048],[2861.8,10.189],[2862.2,24.431],[2862.6,4.381],[2862.7,0.001],[2863.2,0.947],[2867.9,3.035],[2869.3,6.056],[2872.9,0.0],[2873.1,0.0]],"action":"update"}}
1651237301.7004907: {"channel":"orderbook","market":"SHIB/USD","type":"update","data":{"time":1651237301.5694604,"checksum":2739286686,"bids":[],"asks":[[0.00002262,39500000.0]],"action":"update"}}
1651237301.7053466: {"channel":"orderbook","market":"SOL/USD","type":"update","data":{"time":1651237301.566469,"checksum":3135205421,"bids":[[95.8175,714.43]],"asks":[[95.8875,69.99],[96.05,0.0],[96.405,19.0]],"action":"update"}}
1651237301.714136: {"channel":"orderbook","market":"ETH/USDT","type":"update","data":{"time":1651237301.5835376,"checksum":2829110779,"bids":[[2860.8,8.777]],"asks":[[2861.5,2.095],[2862.2,19.73],[2882.6,0.0],[2882.9,0.0]],"action":"update"}}
1651237301.724132: {"channel":"orderbook","market":"FTT/BTC","type":"update","data":{"time":1651237301.5837798,"checksum":1756738501,"bids":[[0.0010078,26.3]],"asks":[],"action":"update"}}
1651237301.727821: {"channel":"orderbook","market":"ETH/USD","type":"update","data":{"time":1651237301.5942478,"checksum":2101246614,"bids":[[2860.9,1.868],[2860.8,4.1],[2860.2,0.0],[2860.0,14.554],[2849.0,0.0]],"asks":[[2861.2,0.0],[2861.3,8.218],[2861.5,11.438],[2861.7,9.232],[2862.3,25.139],[2862.4,0.0],[2862.6,0.0],[2863.3,14.526],[2865.0,0.003],[2872.9,0.003],[2873.1,0.002],[2873.4,0.236]],"action":"update"}}
1651237301.7415116: {"channel":"orderbook","market":"BTC/TRY","type":"update","data":{"time":1651237301.615097,"checksum":1840591949,"bids":[],"asks":[],"action":"update"}}
1651237301.7531948: {"channel":"orderbook","market":"ETH/USD","type":"update","data":{"time":1651237301.6217573,"checksum":2168945641,"bids":[],"asks":[[2862.3,19.478]],"action":"update"}}
1651237301.7532961: {"channel":"orderbook","market":"SOL/USD","type":"update","data":{"time":1651237301.6190667,"checksum":1869108875,"bids":[[95.86,0.04],[95.855,0.0],[95.8475,324.18]],"asks":[[95.89,7.26],[95.9025,87.55],[95.955,11.32],[96.4,0.0],[96.405,0.0]],"action":"update"}}
1651237301.7640705: {"channel":"orderbook","market":"ETH/USDT","type":"update","data":{"time":1651237301.6322293,"checksum":3737102221,"bids":[[2859.7,3.496],[2857.5,16.004],[2842.7,0.0]],"asks":[[2861.2,2.0],[2865.9,15.698],[2882.5,0.0]],"action":"update"}}
1651237301.7667077: {"channel":"orderbook","market":"SOL/USD","type":"update","data":{"time":1651237301.6409392,"checksum":1477206298,"bids":[],"asks":[[95.885,70.0],[96.3925,0.0]],"action":"update"}}
1651237301.7736247: {"channel":"orderbook","market":"SHIB/USD","type":"update","data":{"time":1651237301.644741,"checksum":581198548,"bids":[[0.00002261,136400000.0]],"asks":[],"action":"update"}}
1651237301.780989: {"channel":"orderbook","market":"ETH/USD","type":"update","data":{"time":1651237301.6488793,"checksum":2835260011,"bids":[[2860.8,0.0],[2859.5,0.349],[2859.2,21.415]],"asks":[[2861.2,2.056],[2861.4,11.749],[2861.8,15.85],[2862.0,9.887],[2867.8,6.0],[2873.1,0.0],[2873.4,0.0]],"action":"update"}}
1651237301.7885787: {"channel":"orderbook","market":"ETH/USDT","type":"update","data":{"time":1651237301.65563,"checksum":2742300131,"bids":[[2860.7,13.238],[2842.8,0.0]],"asks":[],"action":"update"}}
1651237301.8183079: {"channel":"orderbook","market":"SOL/USD","type":"update","data":{"time":1651237301.6717906,"checksum":1850986525,"bids":[],"asks":[[95.8875,0.0],[95.905,70.0],[96.0,5.09],[96.3925,0.18]],"action":"update"}}
1651237301.8183892: {"channel":"orderbook","market":"ETH/USDT","type":"update","data":{"time":1651237301.685301,"checksum":3561729566,"bids":[[2859.6,18.981]],"asks":[[2861.6,10.311]],"action":"update"}}
1651237301.8184311: {"channel":"orderbook","market":"ETH/USD","type":"update","data":{"time":1651237301.674828,"checksum":3897618102,"bids":[[2859.6,26.794],[2855.3,7.948]],"asks":[],"action":"update"}}
1651237301.8295383: {"channel":"orderbook","market":"SOL/USD","type":"update","data":{"time":1651237301.6930346,"checksum":1303167966,"bids":[[95.85,57.06],[95.43,0.0]],"asks":[[95.9025,0.0],[96.4,16.48]],"action":"update"}}
1651237301.8296072: {"channel":"orderbook","market":"SHIB/USD","type":"update","data":{"time":1651237301.6945314,"checksum":805069541,"bids":[],"asks":[[0.00002267,119800000.0]],"action":"update"}}
1651237301.8520277: {"channel":"orderbook","market":"SOL/USD","type":"update","data":{"time":1651237301.7173448,"checksum":3696525610,"bids":[],"asks":[[95.9375,0.0],[95.9725,116.01]],"action":"update"}}
1651237301.8672621: {"channel":"orderbook","market":"ETH/USDT","type":"update","data":{"time":1651237301.7308788,"checksum":151606548,"bids":[[2860.8,4.768]],"asks":[],"action":"update"}}
1651237301.8709414: {"channel":"orderbook","market":"SOL/USD","type":"update","data":{"time":1651237301.7418814,"checksum":2199091969,"bids":[[95.86,51.54],[95.825,146.28]],"asks":[],"action":"update"}}
1651237301.8822236: {"channel":"orderbook","market":"ETH/USDT","type":"update","data":{"time":1651237301.753921,"checksum":1828589694,"bids":[[2859.7,7.505],[2858.8,2.354]],"asks":[[2863.6,0.0],[2882.5,0.01]],"action":"update"}}
1651237301.8869731: {"channel":"orderbook","market":"ETH/USD","type":"update","data":{"time":1651237301.7140844,"checksum":1326362796,"bids":[[2855.3,1.948]],"asks":[[2861.3,2.968],[2861.8,16.199],[2862.7,1.001],[2867.8,0.0],[2873.1,0.002]],"action":"update"}}
1651237301.8992732: {"channel":"orderbook","market":"WBTC/USD","type":"update","data":{"time":1651237301.7649908,"checksum":3501912508,"bids":[],"asks":[],"action":"update"}}
1651237301.8998175: {"channel":"orderbook","market":"LTC/USDT","type":"update","data":{"time":1651237301.7730012,"checksum":3335309554,"bids":[[100.565,0.0],[96.845,0.3]],"asks":[[100.76,0.0],[104.0,0.01]],"action":"update"}}
1651237301.9055436: {"channel":"orderbook","market":"ETH/USD","type":"update","data":{"time":1651237301.7751975,"checksum":2761572891,"bids":[[2859.7,11.539]],"asks":[[2861.6,6.59],[2863.4,3.531]],"action":"update"}}
1651237301.918376: {"channel":"orderbook","market":"SOL/USD","type":"update","data":{"time":1651237301.7935123,"checksum":699004751,"bids":[],"asks":[[96.0175,0.06],[96.4,0.0]],"action":"update"}}
1651237301.9273267: {"channel":"orderbook","market":"ETH/USD","type":"update","data":{"time":1651237301.7990513,"checksum":3321264977,"bids":[[2860.9,2.195]],"asks":[[2861.2,0.0],[2873.4,0.236]],"action":"update"}}
1651237301.948861: {"channel":"orderbook","market":"ETH/USD","type":"update","data":{"time":1651237301.8227854,"checksum":4039578721,"bids":[[2860.6,3.321],[2852.4,0.12],[2849.3,0.0],[2849.1,0.0]],"asks":[],"action":"update"}}
1651237301.9591832: {"channel":"orderbook","market":"ETH/USDT","type":"update","data":{"time":1651237301.829324,"checksum":3550962549,"bids":[[2858.2,6.532]],"asks":[[2861.5,0.0],[2882.6,0.1]],"action":"update"}}
1651237301.9592288: {"channel":"orderbook","market":"SOL/USD","type":"update","data":{"time":1651237301.824982,"checksum":1038511161,"bids":[],"asks":[[95.99,0.2]],"action":"update"}}
1651237301.9771018: {"channel":"orderbook","market":"LTC/USDT","type":"update","data":{"time":1651237301.8487244,"checksum":2035781755,"bids":[],"asks":[[100.725,150.1]],"action":"update"}}
1651237301.9855502: {"channel":"orderbook","market":"SHIB/USD","type":"update","data":{"time":1651237301.847415,"checksum":3085402865,"bids":[],"asks":[[0.00002266,425300000.0]],"action":"update"}}
1651237301.9855945: {"channel":"orderbook","market":"ETH/USD","type":"update","data":{"time":1651237301.8477962,"checksum":3039216949,"bids":[],"asks":[[2861.0,0.485],[2861.1,0.0],[2861.3,22.267],[2861.4,9.112],[2873.5,0.015]],"action":"update"}}
1651237301.9963682: {"channel":"orderbook","market":"SOL/USD","type":"update","data":{"time":1651237301.8587115,"checksum":3672626354,"bids":[[95.745,0.0],[95.43,0.25]],"asks":[[95.885,0.0],[95.92,105.29],[95.9275,70.0],[96.3925,0.0]],"action":"update"}}
1651237302.0046666: {"channel":"orderbook","market":"ETH/USD","type":"update","data":{"time":1651237301.874129,"checksum":9796778,"bids":[[2860.9,7.688],[2860.8,2.0],[2860.0,14.596],[2849.4,0.0]],"asks":[[2861.3,20.267],[2861.4,11.112],[2862.7,5.371],[2863.2,0.862],[2863.5,1.566],[2864.4,0.0],[2864.9,183.417],[2867.4,0.225],[2873.6,4.007]],"action":"update"}}
1651237302.0259454: {"channel":"orderbook","market":"ETH/USDT","type":"update","data":{"time":1651237301.8675568,"checksum":2852859880,"bids":[],"asks":[[2861.7,5.0],[2862.0,4.54],[2863.0,5.629]],"action":"update"}}
1651237302.0259988: {"channel":"orderbook","market":"ETH/USD","type":"update","data":{"time":1651237301.8970742,"checksum":2276438883,"bids":[[2860.9,10.325],[2859.5,0.0],[2849.4,0.04]],"asks":[[2861.3,2.968],[2864.7,10.151]],"action":"update"}}
1651237302.026045: {"channel":"orderbook","market":"LTC/USDT","type":"update","data":{"time":1651237301.9000034,"checksum":2383885077,"bids":[[100.54,8.77]],"asks":[],"action":"update"}}
1651237302.032257: {"channel":"orderbook","market":"SOL/USD","type":"update","data":{"time":1651237301.9048579,"checksum":2765414781,"bids":[],"asks":[[96.005,62.64],[96.39,0.0]],"action":"update"}}
1651237302.0492504: {"channel":"orderbook","market":"LTC/USDT","type":"update","data":{"time":1651237301.9235764,"checksum":3191033966,"bids":[],"asks":[[100.74,31.46]],"action":"update"}}
1651237302.0555825: {"channel":"orderbook","market":"ETH/USD","type":"update","data":{"time":1651237301.9233968,"checksum":2193248495,"bids":[[2860.9,7.688],[2860.8,0.0],[2852.4,0.0],[2849.3,0.041],[2849.1,0.004]],"asks":[[2861.4,9.112],[2861.8,16.194],[2861.9,3.008],[2862.0,9.885],[2864.8,32.803],[2864.9,177.094]],"action":"update"}}
1651237302.064903: {"channel":"orderbook","market":"SOL/USD","type":"update","data":{"time":1651237301.926844,"checksum":2413560261,"bids":[],"asks":[[95.9775,252.45],[96.385,0.0]],"action":"update"}}
1651237302.074713: {"channel":"orderbook","market":"ETH/USD","type":"update","data":{"time":1651237301.9475152,"checksum":989856133,"bids":[],"asks":[[2864.8,39.091]],"action":"update"}}
1651237302.0868587: {"channel":"orderbook","market":"ETH/USDT","type":"update","data":{"time":1651237301.9584558,"checksum":1006692516,"bids":[[2860.7,0.0],[2842.8,0.01]],"asks":[[2861.6,5.996],[2862.0,6.492]],"action":"update"}}
1651237302.0950005: {"channel":"orderbook","market":"SOL/USD","type":"update","data":{"time":1651237301.9596484,"checksum":3618467495,"bids":[],"asks":[[95.89,0.0],[96.385,0.35]],"action":"update"}}
1651237302.101452: {"channel":"orderbook","market":"ETH/USD","type":"update","data":{"time":1651237301.9724698,"checksum":1767842413,"bids":[[2860.7,3.496]],"asks":[],"action":"update"}}
1651237302.1293757: {"channel":"orderbook","market":"ETH/USD","type":"update","data":{"time":1651237301.9970965,"checksum":1733499987,"bids":[[2860.9,9.788]],"asks":[[2861.0,0.0],[2861.7,4.745],[2873.7,0.001]],"action":"update"}}
1651237302.1394768: {"channel":"orderbook","market":"SOL/USD","type":"update","data":{"time":1651237302.009928,"checksum":2943863068,"bids":[[95.8475,329.18]],"asks":[],"action":"update"}}
1651237302.1523542: {"channel":"orderbook","market":"ETH/USDT","type":"update","data":{"time":1651237302.0197337,"checksum":414489210,"bids":[[2860.8,19.612]],"asks":[[2861.5,2.586],[2862.4,1.326],[2882.5,0.0],[2882.6,0.0]],"action":"update"}}
1651237302.1524029: {"channel":"orderbook","market":"ETH/USD","type":"update","data":{"time":1651237302.0246975,"checksum":970106865,"bids":[[2860.9,7.92]],"asks":[[2861.6,2.059],[2863.3,29.109],[2867.8,6.0],[2873.7,0.0]],"action":"update"}}
1651237302.1554685: {"channel":"orderbook","market":"SOL/USD","type":"update","data":{"time":1651237302.0287905,"checksum":240144806,"bids":[[95.6925,0.0],[95.425,1.23]],"asks":[],"action":"update"}}
1651237302.1741965: {"channel":"orderbook","market":"ETH/USD","type":"update","data":{"time":1651237302.0468805,"checksum":3599467610,"bids":[[2860.9,5.82],[2859.9,36.877],[2858.0,3.06],[2855.3,7.948]],"asks":[[2861.7,23.923]],"action":"update"}}
1651237302.2035363: {"channel":"orderbook","market":"ETH/USD","type":"update","data":{"time":1651237302.0718246,"checksum":169604116,"bids":[[2861.0,2.1],[2860.2,7.056],[2859.3,7.172],[2858.3,2.104],[2849.3,0.0],[2849.1,0.0]],"asks":[[2863.2,8.139],[2872.7,0.001]],"action":"update"}}
1651237302.2044342: {"channel":"orderbook","market":"ETH/USDT","type":"update","data":{"time":1651237302.0706177,"checksum":4002515702,"bids":[[2860.2,5.218]],"asks":[[2862.9,0.175],[2882.4,0.0]],"action":"update"}}
1651237302.222584: {"channel":"orderbook","market":"ETH/USDT","type":"update","data":{"time":1651237302.0950713,"checksum":2145762574,"bids":[],"asks":[[2862.0,6.535]],"action":"update"}}
1651237302.2230074: {"channel":"orderbook","market":"ETH/USD","type":"update","data":{"time":1651237302.0961578,"checksum":663388273,"bids":[[2860.9,3.82]],"asks":[[2861.6,2.062],[2864.8,32.803]],"action":"update"}}
1651237302.2235966: {"channel":"orderbook","market":"LTC/USDT","type":"update","data":{"time":1651237302.0976653,"checksum":3191033966,"bids":[],"asks":[],"action":"update"}}
1651237302.2323914: {"channel":"orderbook","market":"SOL/USD","type":"update","data":{"time":1651237302.104408,"checksum":2279498581,"bids":[[95.8125,62.64],[95.425,0.0]],"asks":[[96.135,0.0],[96.39,0.21]],"action":"update"}}
1651237302.2704976: {"channel":"orderbook","market":"SHIB/USD","type":"update","data":{"time":1651237302.13896,"checksum":3085402865,"bids":[],"asks":[],"action":"update"}}
1651237302.2705467: {"channel":"orderbook","market":"ETH/USDT","type":"update","data":{"time":1651237302.1421545,"checksum":4039840976,"bids":[[2860.9,0.0],[2859.7,4.009],[2842.7,0.018]],"asks":[[2861.3,0.0],[2882.4,0.035]],"action":"update"}}
1651237302.278308: {"channel":"orderbook","market":"SOL/USD","type":"update","data":{"time":1651237302.1489024,"checksum":1897296522,"bids":[[95.8625,0.29],[95.43,0.0]],"asks":[[95.94,0.05],[96.39,0.0]],"action":"update"}}
1651237302.2814598: {"channel":"orderbook","market":"ETH/USD","type":"update","data":{"time":1651237302.1476853,"checksum":2106397127,"bids":[[2861.0,4.0]],"asks":[[2861.6,5.984],[2861.8,15.845],[2862.1,10.685]],"action":"update"}}
1651237302.2861063: {"channel":"orderbook","market":"ETH/USDT","type":"update","data":{"time":1651237302.1596856,"checksum":2552585247,"bids":[],"asks":[[2861.2,2.161]],"action":"update"}}
1651237302.2995236: {"channel":"orderbook","market":"ETH/USD","type":"update","data":{"time":1651237302.1724792,"checksum":337358718,"bids":[[2859.8,8.203]],"asks":[[2862.7,5.72],[2869.1,2.338]],"action":"update"}}
1651237302.3122776: {"channel":"orderbook","market":"ETH/USDT","type":"update","data":{"time":1651237302.185947,"checksum":4165567458,"bids":[],"asks":[[2862.1,3.496],[2862.7,5.883],[2864.5,0.365],[2882.2,0.0],[2882.4,0.0]],"action":"update"}}
1651237302.3252413: {"channel":"orderbook","market":"ETH/USD","type":"update","data":{"time":1651237302.1966133,"checksum":2059509205,"bids":[[2861.0,2.1],[2859.8,4.707]],"asks":[[2861.8,9.154],[2866.8,0.001]],"action":"update"}}
1651237302.3284826: {"channel":"orderbook","market":"SOL/USD","type":"update","data":{"time":1651237302.2028403,"checksum":4149777922,"bids":[],"asks":[[95.92,0.0],[95.975,63.17]],"action":"update"}}
1651237302.3558264: {"channel":"orderbook","market":"ETH/USD","type":"update","data":{"time":1651237302.2232802,"checksum":1912071016,"bids":[[2861.0,1.9],[2860.7,3.493]],"asks":[],"action":"update"}}
1651237302.3558884: {"channel":"orderbook","market":"SOL/USD","type":"update","data":{"time":1651237302.2225647,"checksum":3367197708,"bids":[[95.86,63.64]],"asks":[[96.245,0.01]],"action":"update"}}
1651237302.3750956: {"channel":"orderbook","market":"ETH/USD","type":"update","data":{"time":1651237302.2470434,"checksum":2781512069,"bids":[[2861.0,3.8]],"asks":[[2864.7,9.136]],"action":"update"}}
1651237302.3825355: {"channel":"orderbook","market":"ETH/USDT","type":"update","data":{"time":1651237302.2477007,"checksum":498112227,"bids":[[2860.3,5.882]],"asks":[[2861.3,6.919],[2882.0,0.049],[2882.1,0.0]],"action":"update"}}
1651237302.3825824: {"channel":"orderbook","market":"SOL/USD","type":"update","data":{"time":1651237302.2493298,"checksum":1652661852,"bids":[[95.865,70.0],[95.8625,70.29],[95.86,0.04],[95.8475,324.18],[95.74,178.86],[95.4375,0.0],[95.435,0.0]],"asks":[[96.03,697.49]],"action":"update"}}
1651237302.3826268: {"channel":"orderbook","market":"SHIB/USD","type":"update","data":{"time":1651237302.2402296,"checksum":4242628097,"bids":[[0.00002255,118100000.0]],"asks":[],"action":"update"}}
1651237302.3857446: {"channel":"orderbook","market":"DAI/USD","type":"update","data":{"time":1651237302.253331,"checksum":280434518,"bids":[],"asks":[],"action":"update"}}
1651237302.3939073: {"channel":"orderbook","market":"ETH/USDT","type":"update","data":{"time":1651237302.2621508,"checksum":3484452040,"bids":[],"asks":[[2863.9,0.0],[2882.1,0.011]],"action":"update"}}
1651237302.4075062: {"channel":"orderbook","market":"SOL/USD","type":"update","data":{"time":1651237302.2718503,"checksum":3395075679,"bids":[[95.8625,0.29]],"asks":[[95.9775,332.47],[96.13,0.0],[96.39,0.21]],"action":"update"}}
1651237302.4075735: {"channel":"orderbook","market":"ETH/USD","type":"update","data":{"time":1651237302.2747743,"checksum":3663124521,"bids":[[2860.3,3.496],[2849.4,0.0]],"asks":[[2862.3,27.078],[2862.7,5.371]],"action":"update"}}
1651237302.4156764: {"channel":"orderbook","market":"ETH/USDT","type":"update","data":{"time":1651237302.2891376,"checksum":80582206,"bids":[],"asks":[[2862.2,0.0],[2863.2,2.354]],"action":"update"}}
1651237302.4377506: {"channel":"orderbook","market":"SOL/USD","type":"update","data":{"time":1651237302.3030255,"checksum":1548683645,"bids":[[95.7325,26.1],[95.44,0.0]],"asks":[],"action":"update"}}
1651237302.437813: {"channel":"orderbook","market":"ETH/USD","type":"update","data":{"time":1651237302.2986,"checksum":190939060,"bids":[[2861.1,1.9],[2849.5,0.0]],"asks":[[2861.2,4.0],[2861.9,3.357],[2864.8,19.451],[2873.6,0.0]],"action":"update"}}
1651237302.467635: {"channel":"orderbook","market":"ETH/USD","type":"update","data":{"time":1651237302.324854,"checksum":202945538,"bids":[],"asks":[[2861.2,6.0],[2862.2,31.202]],"action":"update"}}
1651237302.4723494: {"channel":"orderbook","market":"ETH/USDT","type":"update","data":{"time":1651237302.338215,"checksum":1823397250,"bids":[[2860.9,2.5],[2842.7,0.0]],"asks":[[2862.1,26.788]],"action":"update"}}
1651237302.480667: {"channel":"orderbook","market":"ETH/USD","type":"update","data":{"time":1651237302.347996,"checksum":413315293,"bids":[[2861.0,0.0],[2849.5,0.01]],"asks":[[2861.7,23.925],[2863.7,4.923]],"action":"update"}}
1651237302.4999394: {"channel":"orderbook","market":"ETH/USDT","type":"update","data":{"time":1651237302.3690238,"checksum":346238004,"bids":[[2857.5,4.967]],"asks":[[2865.1,180.071],[2882.1,0.0]],"action":"update"}}
1651237302.5044954: {"channel":"orderbook","market":"ETH/USD","type":"update","data":{"time":1651237302.3739526,"checksum":1963030510,"bids":[],"asks":[[2862.3,27.427]],"action":"update"}}
1651237302.5088243: {"channel":"orderbook","market":"SOL/USD","type":"update","data":{"time":1651237302.3717735,"checksum":4171928843,"bids":[],"asks":[[95.93,0.69],[96.39,0.0]],"action":"update"}}
1651237302.5104935: {"channel":"orderbook","market":"USD/TRY","type":"update","data":{"time":1651237302.3814332,"checksum":2479525932,"bids":[],"asks":[],"action":"update"}}
1651237302.5260777: {"channel":"orderbook","market":"ETH/USD","type":"update","data":{"time":1651237302.398077,"checksum":1252715386,"bids":[[2860.2,23.47],[2855.6,3.016]],"asks":[],"action":"update"}}
1651237302.5414639: {"channel":"orderbook","market":"ETH/USDT","type":"update","data":{"time":1651237302.4138703,"checksum":1859494035,"bids":[[2860.9,7.403],[2859.7,0.0],[2842.7,0.018]],"asks":[[2862.0,13.233],[2862.8,19.186]],"action":"update"}}
1651237302.5532796: {"channel":"orderbook","market":"SOL/USD","type":"update","data":{"time":1651237302.4228337,"checksum":2760354821,"bids":[],"asks":[[95.935,105.27],[96.385,0.0]],"action":"update"}}
1651237302.5580995: {"channel":"orderbook","market":"ETH/USD","type":"update","data":{"time":1651237302.423574,"checksum":2669918851,"bids":[[2861.1,1.899]],"asks":[[2861.9,3.008],[2864.5,2.59]],"action":"update"}}
1651237302.5703096: {"channel":"orderbook","market":"SOL/USD","type":"update","data":{"time":1651237302.4436471,"checksum":2105808725,"bids":[],"asks":[[96.005,0.0],[96.385,0.35]],"action":"update"}}
1651237302.5787177: {"channel":"orderbook","market":"ETH/USD","type":"update","data":{"time":1651237302.451361,"checksum":1579906324,"bids":[[2860.3,9.366]],"asks":[[2862.8,3.849],[2867.9,6.066]],"action":"update"}}
1651237302.6029491: {"channel":"orderbook","market":"ETH/USDT","type":"update","data":{"time":1651237302.4669368,"checksum":484025539,"bids":[[2859.4,9.009]],"asks":[],"action":"update"}}
1651237302.6265228: {"channel":"orderbook","market":"LTC/USDT","type":"update","data":{"time":1651237302.497446,"checksum":1167156367,"bids":[],"asks":[[100.7,0.0],[104.02,0.28]],"action":"update"}}
1651237302.6310956: {"channel":"orderbook","market":"SOL/USD","type":"update","data":{"time":1651237302.496135,"checksum":2770137712,"bids":[],"asks":[[96.08,138.23]],"action":"update"}}
1651237302.6452925: {"channel":"orderbook","market":"SOL/USD","type":"update","data":{"time":1651237302.5179048,"checksum":1930218414,"bids":[],"asks":[[96.2275,0.03]],"action":"update"}}
1651237302.7117531: {"channel":"orderbook","market":"ETH/USD","type":"update","data":{"time":1651237302.5457811,"checksum":1436908474,"bids":[[2861.1,5.392],[2860.5,21.023],[2860.0,14.554],[2859.3,0.349]],"asks":[[2862.8,3.5],[2871.6,0.0],[2873.6,4.007]],"action":"update"}}
1651237302.7118897: {"channel":"orderbook","market":"SOL/USD","type":"update","data":{"time":1651237302.5781405,"checksum":2760338824,"bids":[[95.865,65.52]],"asks":[[95.9625,272.84]],"action":"update"}}
1651237302.7248561: {"channel":"orderbook","market":"ETH/USD","type":"update","data":{"time":1651237302.5785475,"checksum":1260676840,"bids":[[2860.4,24.56],[2857.9,0.874],[2849.5,0.0]],"asks":[[2861.8,9.156]],"action":"update"}}
1651237302.7257028: {"channel":"orderbook","market":"SOL/USD","type":"update","data":{"time":1651237302.5973198,"checksum":3426478493,"bids":[[95.865,45.71]],"asks":[],"action":"update"}}
1651237302.7386327: {"channel":"orderbook","market":"ETH/USD","type":"update","data":{"time":1651237302.6072447,"checksum":321797982,"bids":[],"asks":[[2862.0,10.234]],"action":"update"}}
1651237302.7515006: {"channel":"orderbook","market":"SHIB/USD","type":"update","data":{"time":1651237302.6170352,"checksum":3768087590,"bids":[[0.00002204,2200000.0]],"asks":[],"action":"update"}}
1651237302.751559: {"channel":"orderbook","market":"FTT/BTC","type":"update","data":{"time":1651237302.6174912,"checksum":1756738501,"bids":[],"asks":[],"action":"update"}}
1651237302.7645686: {"channel":"orderbook","market":"BTC/TRY","type":"update","data":{"time":1651237302.6381536,"checksum":1840591949,"bids":[],"asks":[],"action":"update"}}
1651237302.7708554: {"channel":"orderbook","market":"SOL/USD","type":"update","data":{"time":1651237302.6460834,"checksum":2105156005,"bids":[[95.85,62.06]],"asks":[[96.2,275.32],[96.385,0.0]],"action":"update"}}
1651237302.7859843: {"channel":"orderbook","market":"ETH/USD","type":"update","data":{"time":1651237302.6519487,"checksum":2121942196,"bids":[[2860.3,18.968]],"asks":[],"action":"update"}}
1651237302.795993: {"channel":"orderbook","market":"SOL/USD","type":"update","data":{"time":1651237302.6703334,"checksum":2630079285,"bids":[[95.8675,135.22],[95.4475,0.0]],"asks":[],"action":"update"}}
1651237302.819092: {"channel":"orderbook","market":"ETH/USDT","type":"update","data":{"time":1651237302.6836748,"checksum":364816556,"bids":[],"asks":[[2862.8,20.092],[2865.8,0.0],[2882.1,0.011]],"action":"update"}}
1651237302.826842: {"channel":"orderbook","market":"SOL/USD","type":"update","data":{"time":1651237302.6951659,"checksum":1734308389,"bids":[[95.865,0.0],[95.4475,0.03]],"asks":[[95.935,0.0],[96.385,0.35]],"action":"update"}}
1651237302.836164: {"channel":"orderbook","market":"ETH/USDT","type":"update","data":{"time":1651237302.7006652,"checksum":3380499128,"bids":[],"asks":[[2863.0,5.337]],"action":"update"}}
1651237302.8534153: {"channel":"orderbook","market":"SOL/USD","type":"update","data":{"time":1651237302.7266035,"checksum":3182502564,"bids":[[95.8675,143.83]],"asks":[[96.0375,7.27]],"action":"update"}}
1651237302.8765755: {"channel":"orderbook","market":"SOL/USD","type":"update","data":{"time":1651237302.7473667,"checksum":2052767352,"bids":[[95.87,70.0],[95.85,167.33],[95.4475,0.0]],"asks":[[96.0125,62.64],[96.0275,174.45],[96.375,0.0],[96.385,0.0]],"action":"update"}}
1651237302.8965492: {"channel":"orderbook","market":"ETH/USD","type":"update","data":{"time":1651237302.753827,"checksum":2336266398,"bids":[[2855.2,7.037]],"asks":[[2861.6,23.282],[2861.7,33.283],[2862.9,0.349],[2864.5,1.575],[2866.2,0.001],[2873.5,0.0],[2873.6,0.0]],"action":"update"}}
1651237302.9080164: {"channel":"orderbook","market":"ETH/USDT","type":"update","data":{"time":1651237302.7762592,"checksum":1837184125,"bids":[[2860.3,11.791]],"asks":[[2862.2,6.496],[2862.5,0.302],[2882.1,0.0]],"action":"update"}}
1651237302.91695: {"channel":"orderbook","market":"SOL/USD","type":"update","data":{"time":1651237302.7856584,"checksum":1328093559,"bids":[[95.8675,73.83],[95.8525,11.39],[95.85,221.49],[95.7325,0.0]],"asks":[[96.1275,26.1],[96.37,0.0]],"action":"update"}}
1651237302.9170218: {"channel":"orderbook","market":"SHIB/USD","type":"update","data":{"time":1651237302.7908473,"checksum":482833111,"bids":[[0.00002257,214000000.0]],"asks":[],"action":"update"}}
1651237302.9241977: {"channel":"orderbook","market":"WBTC/USD","type":"update","data":{"time":1651237302.7987778,"checksum":3501912508,"bids":[],"asks":[],"action":"update"}}
1651237302.9328468: {"channel":"orderbook","market":"SOL/USD","type":"update","data":{"time":1651237302.8042037,"checksum":2487788868,"bids":[[95.8675,0.0],[95.4475,0.03]],"asks":[],"action":"update"}}
1651237302.9565783: {"channel":"orderbook","market":"ETH/USDT","type":"update","data":{"time":1651237302.8249714,"checksum":319684881,"bids":[[2860.2,5.043]],"asks":[],"action":"update"}}
1651237302.984426: {"channel":"orderbook","market":"ETH/USD","type":"update","data":{"time":1651237302.8545575,"checksum":1126925197,"bids":[],"asks":[[2863.0,0.183]],"action":"update"}}
1651237303.0027857: {"channel":"orderbook","market":"ETH/USDT","type":"update","data":{"time":1651237302.8744388,"checksum":3146442272,"bids":[[2854.6,0.0],[2842.5,835.588]],"asks":[],"action":"update"}}
1651237303.0052488: {"channel":"orderbook","market":"SOL/USD","type":"update","data":{"time":1651237302.87656,"checksum":456442344,"bids":[[95.87,58.91]],"asks":[],"action":"update"}}
1651237303.0591488: {"channel":"orderbook","market":"ETH/USD","type":"update","data":{"time":1651237302.9315054,"checksum":375988404,"bids":[],"asks":[[2864.4,0.041],[2873.4,0.0]],"action":"update"}}
1651237303.0798955: {"channel":"orderbook","market":"ETH/USDT","type":"update","data":{"time":1651237302.952853,"checksum":287469504,"bids":[[2861.0,1.852],[2859.4,5.0],[2856.6,0.318],[2842.7,0.0],[2842.5,0.0]],"asks":[[2861.9,3.311],[2882.0,0.0]],"action":"update"}}
1651237303.083609: {"channel":"orderbook","market":"ETH/USD","type":"update","data":{"time":1651237302.9550636,"checksum":1821108871,"bids":[[2860.9,3.823]],"asks":[],"action":"update"}}
1651237303.1072946: {"channel":"orderbook","market":"SOL/USD","type":"update","data":{"time":1651237302.9786887,"checksum":886545956,"bids":[],"asks":[[95.94,105.32]],"action":"update"}}
1651237303.1115673: {"channel":"orderbook","market":"ETH/USD","type":"update","data":{"time":1651237302.9811957,"checksum":2470035661,"bids":[],"asks":[[2861.7,33.498]],"action":"update"}}
1651237303.1363742: {"channel":"orderbook","market":"SOL/USD","type":"update","data":{"time":1651237303.0012612,"checksum":1510727228,"bids":[[95.735,73.14]],"asks":[],"action":"update"}}
1651237303.1364186: {"channel":"orderbook","market":"ETH/USDT","type":"update","data":{"time":1651237303.0009563,"checksum":3330202195,"bids":[[2859.4,9.009]],"asks":[],"action":"update"}}
1651237303.1387231: {"channel":"orderbook","market":"ETH/USD","type":"update","data":{"time":1651237303.0064917,"checksum":3794589704,"bids":[[2860.4,24.518]],"asks":[[2863.1,0.002]],"action":"update"}}
1651237303.1792178: {"channel":"orderbook","market":"SOL/USD","type":"update","data":{"time":1651237303.031348,"checksum":1510727228,"bids":[],"asks":[],"action":"update"}}
1651237303.1956687: {"channel":"orderbook","market":"ETH/USD","type":"update","data":{"time":1651237303.05457,"checksum":374937120,"bids":[[2861.0,0.042],[2857.2,0.018],[2849.6,0.0]],"asks":[],"action":"update"}}
1651237303.2065809: {"channel":"orderbook","market":"SHIB/USD","type":"update","data":{"time":1651237303.0754964,"checksum":2320884286,"bids":[[0.00002201,126900000.0]],"asks":[],"action":"update"}}
1651237303.2066402: {"channel":"orderbook","market":"ETH/USD","type":"update","data":{"time":1651237303.0789697,"checksum":3108521536,"bids":[[2860.0,14.103]],"asks":[[2863.3,28.792]],"action":"update"}}
1651237303.239774: {"channel":"orderbook","market":"SOL/USD","type":"update","data":{"time":1651237303.1059003,"checksum":2486008809,"bids":[[95.825,8.62],[95.8175,712.19],[95.8075,0.0],[95.735,47.04],[95.705,0.0],[95.44,1.0],[95.4375,0.01]],"asks":[[96.02,0.0],[96.0275,240.31],[96.37,2.64]],"action":"update"}}
1651237303.251745: {"channel":"orderbook","market":"LTC/USDT","type":"update","data":{"time":1651237303.1225636,"checksum":1167156367,"bids":[],"asks":[],"action":"update"}}
1651237303.25179: {"channel":"orderbook","market":"SOL/USD","type":"update","data":{"time":1651237303.1254077,"checksum":2320972855,"bids":[[95.865,0.01],[95.65,2.32],[95.4375,0.0]],"asks":[[95.9275,218.21]],"action":"update"}}
1651237303.2572777: {"channel":"orderbook","market":"ETH/USD","type":"update","data":{"time":1651237303.1305685,"checksum":4101228687,"bids":[[2859.6,27.111]],"asks":[],"action":"update"}}
1651237303.278546: {"channel":"orderbook","market":"SOL/USD","type":"update","data":{"time":1651237303.1491702,"checksum":4001125765,"bids":[],"asks":[[96.1125,2.24],[96.37,0.0]],"action":"update"}}
1651237303.2969759: {"channel":"orderbook","market":"SHIB/USD","type":"update","data":{"time":1651237303.1673539,"checksum":2320884286,"bids":[],"asks":[],"action":"update"}}
1651237303.2983596: {"channel":"orderbook","market":"LTC/USDT","type":"update","data":{"time":1651237303.1502502,"checksum":1965959429,"bids":[[100.61,13.22],[96.845,0.0]],"asks":[],"action":"update"}}
1651237303.3317442: {"channel":"orderbook","market":"ETH/USD","type":"update","data":{"time":1651237303.205167,"checksum":3631368047,"bids":[[2861.1,1.899],[2859.6,27.245],[2858.3,3.663]],"asks":[],"action":"update"}}
1651237303.3318253: {"channel":"orderbook","market":"SOL/USD","type":"update","data":{"time":1651237303.2029653,"checksum":1510821663,"bids":[[95.87,0.0],[95.4375,0.01]],"asks":[],"action":"update"}}
1651237303.3387108: {"channel":"orderbook","market":"ETH/USDT","type":"update","data":{"time":1651237303.213528,"checksum":4048839978,"bids":[[2860.0,1.979]],"asks":[[2865.9,3.172]],"action":"update"}}
1651237303.3493888: {"channel":"orderbook","market":"SOL/USD","type":"update","data":{"time":1651237303.2227747,"checksum":1018362478,"bids":[[95.6425,0.98]],"asks":[[96.0125,0.0],[96.37,2.64]],"action":"update"}}
1651237303.359085: {"channel":"orderbook","market":"ETH/USD","type":"update","data":{"time":1651237303.2317781,"checksum":2637478974,"bids":[[2860.9,3.82]],"asks":[],"action":"update"}}
1651237303.3825703: {"channel":"orderbook","market":"ETH/USD","type":"update","data":{"time":1651237303.256796,"checksum":359610342,"bids":[[2856.6,1.758]],"asks":[[2863.2,8.223],[2869.3,4.0]],"action":"update"}}
1651237303.391597: {"channel":"orderbook","market":"SOL/USD","type":"update","data":{"time":1651237303.2520802,"checksum":3499699394,"bids":[[95.865,0.0],[95.8625,0.0],[95.86,0.0],[95.8525,4.72],[95.7,57.29],[95.435,0.01],[95.4325,44.74],[95.43,0.25]],"asks":[],"action":"update"}}
1651237303.4000232: {"channel":"orderbook","market":"ETH/USDT","type":"update","data":{"time":1651237303.2683675,"checksum":2116831331,"bids":[[2859.5,28.775]],"asks":[[2862.7,0.0],[2882.0,0.049]],"action":"update"}}
1651237303.409889: {"channel":"orderbook","market":"DAI/USD","type":"update","data":{"time":1651237303.2799063,"checksum":280434518,"bids":[],"asks":[],"action":"update"}}
1651237303.4505136: {"channel":"orderbook","market":"SOL/USD","type":"update","data":{"time":1651237303.2868197,"checksum":1656050231,"bids":[],"asks":[[95.8975,280.0],[96.37,0.0]],"action":"update"}}
1651237303.450611: {"channel":"orderbook","market":"ETH/USD","type":"update","data":{"time":1651237303.2820237,"checksum":831631976,"bids":[[2861.1,1.871]],"asks":[[2863.5,0.007]],"action":"update"}}
1651237303.4506578: {"channel":"orderbook","market":"ETH/USD","type":"update","data":{"time":1651237303.3067696,"checksum":3314442031,"bids":[[2860.8,0.316],[2849.7,0.0]],"asks":[[2862.9,0.666]],"action":"update"}}
1651237303.450711: {"channel":"orderbook","market":"SOL/USD","type":"update","data":{"time":1651237303.3148649,"checksum":3870295872,"bids":[[95.8125,125.19],[95.7875,145.82],[95.7,31.19]],"asks":[[96.03,600.14]],"action":"update"}}
1651237303.4507592: {"channel":"orderbook","market":"ETH/USDT","type":"update","data":{"time":1651237303.3160274,"checksum":2264752088,"bids":[[2859.8,0.292],[2842.8,0.0]],"asks":[[2862.6,0.0],[2882.1,0.011]],"action":"update"}}
1651237303.46531: {"channel":"orderbook","market":"SOL/USD","type":"update","data":{"time":1651237303.3379304,"checksum":2797908307,"bids":[[95.85,116.22]],"asks":[[95.9925,95.95],[96.05,0.52],[96.3625,0.0]],"action":"update"}}
1651237303.46628: {"channel":"orderbook","market":"ETH/USDT","type":"update","data":{"time":1651237303.338755,"checksum":888514547,"bids":[[2860.1,30.074]],"asks":[],"action":"update"}}
1651237303.496609: {"channel":"orderbook","market":"ETH/USD","type":"update","data":{"time":1651237303.365831,"checksum":1979167908,"bids":[[2857.3,0.0],[2856.4,1.0]],"asks":[],"action":"update"}}
1651237303.5019574: {"channel":"orderbook","market":"SOL/USD","type":"update","data":{"time":1651237303.3688848,"checksum":257207267,"bids":[[95.855,36.0],[95.8525,0.0],[95.85,113.64]],"asks":[[95.895,70.0],[95.8975,386.0],[95.9,167.64],[95.925,61.81],[96.36,0.0]],"action":"update"}}
1651237303.5117755: {"channel":"orderbook","market":"ETH/USD","type":"update","data":{"time":1651237303.378857,"checksum":1848787317,"bids":[[2860.1,20.275]],"asks":[],"action":"update"}}
1651237303.516952: {"channel":"orderbook","market":"ETH/USDT","type":"update","data":{"time":1651237303.391008,"checksum":2440138842,"bids":[],"asks":[[2862.9,6.175]],"action":"update"}}
1651237303.5317168: {"channel":"orderbook","market":"ETH/USD","type":"update","data":{"time":1651237303.4051802,"checksum":3646793824,"bids":[[2857.9,0.915]],"asks":[],"action":"update"}}
1651237303.5416534: {"channel":"orderbook","market":"USD/TRY","type":"update","data":{"time":1651237303.4109979,"checksum":2479525932,"bids":[],"asks":[],"action":"update"}}
1651237303.5416813: {"channel":"orderbook","market":"ETH/USDT","type":"update","data":{"time":1651237303.4156752,"checksum":2729060971,"bids":[[2859.4,5.0]],"asks":[],"action":"update"}}
1651237303.554833: {"channel":"orderbook","market":"SOL/USD","type":"update","data":{"time":1651237303.4231362,"checksum":1446305155,"bids":[[95.855,31.21]],"asks":[[95.8975,280.0],[95.9,97.64],[96.0275,65.86]],"action":"update"}}
1651237303.6999228: {"channel":"orderbook","market":"ETH/USD","type":"update","data":{"time":1651237303.431764,"checksum":980008408,"bids":[[2860.4,41.817]],"asks":[],"action":"update"}}
1651237303.6999683: {"channel":"orderbook","market":"ETH/USDT","type":"update","data":{"time":1651237303.4381604,"checksum":1837948145,"bids":[[2860.4,6.446]],"asks":[[2862.2,9.299],[2862.3,0.0],[2882.2,0.011]],"action":"update"}}
1651237303.7000027: {"channel":"orderbook","market":"SOL/USD","type":"update","data":{"time":1651237303.4499755,"checksum":2258051070,"bids":[[95.8525,132.28],[95.8125,62.55],[95.43,0.0]],"asks":[],"action":"update"}}
1651237303.7000334: {"channel":"orderbook","market":"ETH/USDT","type":"update","data":{"time":1651237303.4628537,"checksum":2588592376,"bids":[[2860.0,5.988]],"asks":[[2862.2,6.496]],"action":"update"}}
1651237303.7000587: {"channel":"orderbook","market":"SOL/USD","type":"update","data":{"time":1651237303.469863,"checksum":3605034218,"bids":[[95.8525,67.48],[95.845,140.16],[95.7875,137.66]],"asks":[],"action":"update"}}
1651237303.700086: {"channel":"orderbook","market":"ETH/USD","type":"update","data":{"time":1651237303.4809873,"checksum":2024991229,"bids":[[2854.7,4.375]],"asks":[[2864.4,0.0],[2873.4,0.236]],"action":"update"}}
1651237303.7001128: {"channel":"orderbook","market":"ETH/USDT","type":"update","data":{"time":1651237303.512855,"checksum":1504112878,"bids":[],"asks":[[2862.9,6.0]],"action":"update"}}
1651237303.700159: {"channel":"orderbook","market":"SOL/USD","type":"update","data":{"time":1651237303.5219507,"checksum":1191603355,"bids":[[95.855,24.91],[95.785,0.0],[95.43,0.25]],"asks":[[96.0025,62.64],[96.3575,0.0]],"action":"update"}}
1651237303.7001998: {"channel":"orderbook","market":"ETH/USD","type":"update","data":{"time":1651237303.530981,"checksum":3171370133,"bids":[],"asks":[[2862.8,0.0],[2873.5,0.015]],"action":"update"}}
1651237303.700225: {"channel":"orderbook","market":"FTT/BTC","type":"update","data":{"time":1651237303.5338566,"checksum":3289466996,"bids":[],"asks":[[0.0010097,10.5],[0.0010242,0.0]],"action":"update"}}
1651237303.7259183: {"channel":"orderbook","market":"ETH/USD","type":"update","data":{"time":1651237303.569524,"checksum":1976308296,"bids":[],"asks":[[2862.1,18.164]],"action":"update"}}
1651237303.7259703: {"channel":"orderbook","market":"FTT/BTC","type":"update","data":{"time":1651237303.5825942,"checksum":1311694593,"bids":[],"asks":[[0.0010096,1.1],[0.0010097,0.0]],"action":"update"}}
1651237303.740709: {"channel":"orderbook","market":"SOL/USD","type":"update","data":{"time":1651237303.6120307,"checksum":3015199922,"bids":[[95.85,108.64],[95.6925,26.1],[95.43,0.0]],"asks":[],"action":"update"}}
1651237303.7477567: {"channel":"orderbook","market":"ETH/USD","type":"update","data":{"time":1651237303.6194289,"checksum":950619416,"bids":[],"asks":[[2866.2,0.0],[2873.6,4.007]],"action":"update"}}
1651237303.7555358: {"channel":"orderbook","market":"SOL/USD","type":"update","data":{"time":1651237303.6306448,"checksum":1023982706,"bids":[],"asks":[[96.0175,104.31]],"action":"update"}}
1651237303.77007: {"channel":"orderbook","market":"ETH/USD","type":"update","data":{"time":1651237303.641389,"checksum":219840374,"bids":[[2861.0,0.0],[2849.7,0.01]],"asks":[[2862.7,4.371],[2864.4,1.015],[2873.6,0.0]],"action":"update"}}
1651237303.7804077: {"channel":"orderbook","market":"FTT/BTC","type":"update","data":{"time":1651237303.6436129,"checksum":1311694593,"bids":[],"asks":[],"action":"update"}}
1651237303.8008835: {"channel":"orderbook","market":"SOL/USD","type":"update","data":{"time":1651237303.6576552,"checksum":3852565850,"bids":[[95.8525,98.76],[95.8075,104.26],[95.4325,0.0]],"asks":[[95.965,143.65]],"action":"update"}}
1651237303.8009381: {"channel":"orderbook","market":"BTC/TRY","type":"update","data":{"time":1651237303.668069,"checksum":1840591949,"bids":[],"asks":[],"action":"update"}}
1651237303.8009617: {"channel":"orderbook","market":"ETH/USD","type":"update","data":{"time":1651237303.6663384,"checksum":2628752881,"bids":[],"asks":[[2863.2,8.324]],"action":"update"}}
1651237303.8377666: {"channel":"orderbook","market":"SOL/USD","type":"update","data":{"time":1651237303.708209,"checksum":2512950461,"bids":[[95.855,29.91],[95.6675,275.39]],"asks":[[95.895,69.99],[95.94,0.05]],"action":"update"}}
1651237303.867397: {"channel":"orderbook","market":"ETH/USDT","type":"update","data":{"time":1651237303.7390106,"checksum":3249975058,"bids":[],"asks":[[2867.7,0.0],[2882.4,0.035]],"action":"update"}}
1651237303.8674915: {"channel":"orderbook","market":"ETH/USD","type":"update","data":{"time":1651237303.7158635,"checksum":1366916887,"bids":[],"asks":[[2863.2,8.24]],"action":"update"}}
1651237303.889893: {"channel":"orderbook","market":"ETH/USD","type":"update","data":{"time":1651237303.7548006,"checksum":1875187717,"bids":[[2860.8,0.358]],"asks":[[2861.6,26.778],[2862.3,28.427],[2867.1,0.224]],"action":"update"}}
1651237303.8899624: {"channel":"orderbook","market":"SOL/USD","type":"update","data":{"time":1651237303.7597623,"checksum":3202376252,"bids":[[95.8525,31.28]],"asks":[[95.8925,36.0],[95.895,140.0],[96.35,0.0]],"action":"update"}}
1651237303.896265: {"channel":"orderbook","market":"SHIB/USD","type":"update","data":{"time":1651237303.767723,"checksum":2246082636,"bids":[],"asks":[[0.00002262,19800000.0]],"action":"update"}}
1651237303.9020755: {"channel":"orderbook","market":"ETH/USD","type":"update","data":{"time":1651237303.776369,"checksum":3130522410,"bids":[],"asks":[[2862.1,21.66],[2863.2,8.139]],"action":"update"}}
1651237303.9108148: {"channel":"orderbook","market":"SOL/USD","type":"update","data":{"time":1651237303.7856755,"checksum":4068457398,"bids":[[95.85,54.16],[95.795,62.64],[95.77,0.0]],"asks":[[95.8925,106.0],[95.895,70.01],[95.9175,0.0],[96.35,0.33]],"action":"update"}}
1651237303.9282808: {"channel":"orderbook","market":"SHIB/USD","type":"update","data":{"time":1651237303.7935123,"checksum":3297780241,"bids":[],"asks":[[0.00002262,100000.0]],"action":"update"}}
1651237303.9414883: {"channel":"orderbook","market":"WBTC/USD","type":"update","data":{"time":1651237303.813541,"checksum":3501912508,"bids":[],"asks":[],"action":"update"}}
1651237303.9415195: {"channel":"orderbook","market":"ETH/USDT","type":"update","data":{"time":1651237303.8160238,"checksum":2171921477,"bids":[],"asks":[[2862.1,30.875]],"action":"update"}}
1651237303.9420135: {"channel":"orderbook","market":"SOL/USD","type":"update","data":{"time":1651237303.8135731,"checksum":2004801358,"bids":[],"asks":[[95.94,0.0],[96.3575,0.46]],"action":"update"}}
1651237303.9566953: {"channel":"orderbook","market":"ETH/USD","type":"update","data":{"time":1651237303.8264382,"checksum":1660667964,"bids":[[2857.0,3.512]],"asks":[[2861.5,15.695],[2862.0,15.654],[2866.6,0.748]],"action":"update"}}
1651237303.959847: {"channel":"orderbook","market":"SOL/USD","type":"update","data":{"time":1651237303.8327656,"checksum":283498517,"bids":[[95.795,178.65]],"asks":[[95.8925,113.26],[96.1275,0.0],[96.36,0.03]],"action":"update"}}
1651237303.9683683: {"channel":"orderbook","market":"ETH/USDT","type":"update","data":{"time":1651237303.8402078,"checksum":3463032638,"bids":[[2860.0,1.979]],"asks":[[2865.5,0.438],[2882.4,0.0]],"action":"update"}}
1651237303.9784083: {"channel":"orderbook","market":"ETH/USD","type":"update","data":{"time":1651237303.8497508,"checksum":468482957,"bids":[[2861.1,0.0],[2849.6,0.071]],"asks":[],"action":"update"}}
1651237304.0140495: {"channel":"orderbook","market":"SOL/USD","type":"update","data":{"time":1651237303.869892,"checksum":870268562,"bids":[[95.84,120.17]],"asks":[[95.895,202.95],[95.9325,105.28],[96.36,0.0]],"action":"update"}}
1651237304.0141041: {"channel":"orderbook","market":"ETH/USD","type":"update","data":{"time":1651237303.876701,"checksum":4182631610,"bids":[[2858.7,0.0],[2849.5,0.01]],"asks":[[2861.2,8.0],[2865.1,3.693]],"action":"update"}}
1651237304.022019: {"channel":"orderbook","market":"ETH/USDT","type":"update","data":{"time":1651237303.8890498,"checksum":2481261884,"bids":[[2859.7,4.009],[2843.0,0.0]],"asks":[],"action":"update"}}
1651237304.045539: {"channel":"orderbook","market":"ETH/USD","type":"update","data":{"time":1651237303.9102626,"checksum":1266482423,"bids":[[2860.9,3.808],[2860.4,24.518],[2858.4,1.774]],"asks":[[2861.1,1.9],[2861.2,0.0]],"action":"update"}}
1651237304.045629: {"channel":"orderbook","market":"SOL/USD","type":"update","data":{"time":1651237303.9109056,"checksum":2702648534,"bids":[[95.855,23.6]],"asks":[[95.93,0.74]],"action":"update"}}
1651237304.0456746: {"channel":"orderbook","market":"ETH/USDT","type":"update","data":{"time":1651237303.9141493,"checksum":183581576,"bids":[[2845.1,0.0],[2843.0,0.016]],"asks":[[2861.9,14.252],[2862.4,1.508]],"action":"update"}}
1651237304.0633318: {"channel":"orderbook","market":"SOL/USD","type":"update","data":{"time":1651237303.9360495,"checksum":1758364999,"bids":[],"asks":[[96.1075,399.2]],"action":"update"}}
1651237304.065557: {"channel":"orderbook","market":"ETH/USD","type":"update","data":{"time":1651237303.9381473,"checksum":2951606532,"bids":[[2858.3,5.784],[2855.1,2.07],[2850.1,4.541]],"asks":[[2861.1,3.8],[2861.9,4.308]],"action":"update"}}
1651237304.0755136: {"channel":"orderbook","market":"ETH/USDT","type":"update","data":{"time":1651237303.9436383,"checksum":957387237,"bids":[[2860.2,12.567]],"asks":[[2862.7,5.03],[2882.2,0.0]],"action":"update"}}
1651237304.0922713: {"channel":"orderbook","market":"ETH/USD","type":"update","data":{"time":1651237303.963938,"checksum":3530505861,"bids":[[2860.7,3.496]],"asks":[[2861.0,2.0],[2861.1,5.7],[2861.4,11.173],[2861.6,26.775],[2861.7,33.496],[2861.8,9.154],[2863.2,8.223],[2873.5,0.0]],"action":"update"}}
1651237304.1137302: {"channel":"orderbook","market":"SOL/USD","type":"update","data":{"time":1651237303.9858997,"checksum":2935454534,"bids":[[95.6925,0.0],[95.4325,44.74]],"asks":[],"action":"update"}}
1651237304.1146686: {"channel":"orderbook","market":"ETH/USD","type":"update","data":{"time":1651237303.9869957,"checksum":848384077,"bids":[],"asks":[[2861.1,6.185],[2864.4,0.0],[2868.8,6.056],[2873.5,0.015]],"action":"update"}}
1651237304.1423461: {"channel":"orderbook","market":"ETH/USD","type":"update","data":{"time":1651237304.0129151,"checksum":1559906168,"bids":[],"asks":[[2861.1,4.485],[2862.8,1.326],[2873.5,0.0]],"action":"update"}}
1651237304.1476727: {"channel":"orderbook","market":"SOL/USD","type":"update","data":{"time":1651237304.0125186,"checksum":3132469664,"bids":[[95.8575,70.0],[95.4325,0.0]],"asks":[],"action":"update"}}
1651237304.1516788: {"channel":"orderbook","market":"ETH/USDT","type":"update","data":{"time":1651237304.0214465,"checksum":3860439780,"bids":[[2861.1,2.148]],"asks":[[2861.2,4.211],[2862.7,5.205]],"action":"update"}}
1651237304.1657789: {"channel":"orderbook","market":"ETH/USDT","type":"update","data":{"time":1651237304.038986,"checksum":3032189920,"bids":[],"asks":[[2861.7,5.189]],"action":"update"}}
1651237304.1658242: {"channel":"orderbook","market":"ETH/USD","type":"update","data":{"time":1651237304.0370872,"checksum":2796723596,"bids":[[2857.9,0.874]],"asks":[[2861.1,2.485],[2863.3,27.019]],"action":"update"}}
1651237304.1728034: {"channel":"orderbook","market":"SOL/USD","type":"update","data":{"time":1651237304.0389163,"checksum":4244708315,"bids":[[95.8575,65.21]],"asks":[],"action":"update"}}
1651237304.1798089: {"channel":"orderbook","market":"SHIB/USD","type":"update","data":{"time":1651237304.0501516,"checksum":3738365324,"bids":[],"asks":[[0.00002266,382800000.0]],"action":"update"}}
1651237304.1900525: {"channel":"orderbook","market":"ETH/USDT","type":"update","data":{"time":1651237304.0598931,"checksum":1790833797,"bids":[[2861.1,0.0],[2842.8,0.01]],"asks":[[2861.3,0.0],[2862.8,19.994],[2882.2,0.011]],"action":"update"}}
1651237304.19011: {"channel":"orderbook","market":"ETH/USD","type":"update","data":{"time":1651237304.0633893,"checksum":3455005868,"bids":[],"asks":[[2861.1,0.485],[2862.9,2.439],[2865.2,2.286]],"action":"update"}}
1651237304.212189: {"channel":"orderbook","market":"ETH/USD","type":"update","data":{"time":1651237304.0852456,"checksum":2786126686,"bids":[[2855.5,2.635]],"asks":[[2866.6,0.747]],"action":"update"}}
1651237304.219912: {"channel":"orderbook","market":"ETH/USDT","type":"update","data":{"time":1651237304.0843518,"checksum":799275950,"bids":[[2861.0,0.0],[2842.7,0.018]],"asks":[[2861.2,2.211]],"action":"update"}}
1651237304.2416732: {"channel":"orderbook","market":"ETH/USD","type":"update","data":{"time":1651237304.1115131,"checksum":1811308151,"bids":[],"asks":[[2863.2,11.723]],"action":"update"}}
1651237304.2417245: {"channel":"orderbook","market":"ETH/USDT","type":"update","data":{"time":1651237304.1122007,"checksum":2519775171,"bids":[[2859.5,0.175]],"asks":[[2865.4,7.068]],"action":"update"}}
1651237304.2599015: {"channel":"orderbook","market":"LTC/USDT","type":"update","data":{"time":1651237304.1329708,"checksum":1965959429,"bids":[],"asks":[],"action":"update"}}
1651237304.2612567: {"channel":"orderbook","market":"ETH/USD","type":"update","data":{"time":1651237304.1351855,"checksum":1440970575,"bids":[],"asks":[[2864.8,21.572]],"action":"update"}}
1651237304.273418: {"channel":"orderbook","market":"ETH/USDT","type":"update","data":{"time":1651237304.1344283,"checksum":4019694252,"bids":[[2860.3,11.889]],"asks":[[2864.4,4.842],[2882.2,0.0]],"action":"update"}}
1651237304.2873533: {"channel":"orderbook","market":"ETH/USDT","type":"update","data":{"time":1651237304.161062,"checksum":1469534194,"bids":[],"asks":[[2861.9,15.449],[2862.0,13.331]],"action":"update"}}
1651237304.2921228: {"channel":"orderbook","market":"SOL/USD","type":"update","data":{"time":1651237304.1629462,"checksum":1488915324,"bids":[[95.7125,26.1],[95.435,0.0]],"asks":[],"action":"update"}}
1651237304.3153868: {"channel":"orderbook","market":"ETH/USDT","type":"update","data":{"time":1651237304.1831713,"checksum":1306182314,"bids":[],"asks":[[2861.1,2.0],[2882.1,0.0]],"action":"update"}}
1651237304.3156872: {"channel":"orderbook","market":"ETH/USD","type":"update","data":{"time":1651237304.186981,"checksum":2198040262,"bids":[[2857.9,0.884]],"asks":[[2864.4,0.007],[2873.4,0.0]],"action":"update"}}
1651237304.325512: {"channel":"orderbook","market":"SHIB/USD","type":"update","data":{"time":1651237304.1931734,"checksum":3738365324,"bids":[],"asks":[],"action":"update"}}
1651237304.3372078: {"channel":"orderbook","market":"ETH/USDT","type":"update","data":{"time":1651237304.2083457,"checksum":1469534194,"bids":[],"asks":[[2861.1,0.0],[2882.1,0.011]],"action":"update"}}
1651237304.3372605: {"channel":"orderbook","market":"ETH/USD","type":"update","data":{"time":1651237304.2105377,"checksum":1685063146,"bids":[[2860.3,36.266]],"asks":[],"action":"update"}}
1651237304.3429072: {"channel":"orderbook","market":"SOL/USD","type":"update","data":{"time":1651237304.2146027,"checksum":2268533817,"bids":[[95.7725,98.39],[95.4375,0.0]],"asks":[],"action":"update"}}
1651237304.3641365: {"channel":"orderbook","market":"ETH/USD","type":"update","data":{"time":1651237304.2364204,"checksum":1575033286,"bids":[[2860.8,0.316],[2860.7,3.493]],"asks":[[2867.4,0.03]],"action":"update"}}
1651237304.3915157: {"channel":"orderbook","market":"ETH/USDT","type":"update","data":{"time":1651237304.2638328,"checksum":1459134244,"bids":[],"asks":[[2861.0,4.05],[2882.1,0.0]],"action":"update"}}
1651237304.4142587: {"channel":"orderbook","market":"ETH/USD","type":"update","data":{"time":1651237304.2858508,"checksum":1688219785,"bids":[[2860.4,24.56]],"asks":[],"action":"update"}}
1651237304.4143076: {"channel":"orderbook","market":"ETH/USDT","type":"update","data":{"time":1651237304.2843328,"checksum":749103312,"bids":[],"asks":[[2861.6,12.915]],"action":"update"}}
1651237304.4295988: {"channel":"orderbook","market":"SHIB/USD","type":"update","data":{"time":1651237304.2930293,"checksum":2399253942,"bids":[],"asks":[[0.00002267,162300000.0]],"action":"update"}}
1651237304.4296346: {"channel":"orderbook","market":"DAI/USD","type":"update","data":{"time":1651237304.3024058,"checksum":280434518,"bids":[],"asks":[],"action":"update"}}
1651237304.442466: {"channel":"orderbook","market":"ETH/USDT","type":"update","data":{"time":1651237304.310768,"checksum":4216296180,"bids":[],"asks":[[2861.9,4.508],[2862.9,0.0],[2882.1,0.011]],"action":"update"}}
1651237304.457819: {"channel":"orderbook","market":"ETH/USDT","type":"update","data":{"time":1651237304.3324032,"checksum":29261599,"bids":[],"asks":[[2861.2,2.05]],"action":"update"}}
1651237304.4631777: {"channel":"orderbook","market":"ETH/USD","type":"update","data":{"time":1651237304.3370733,"checksum":3964225907,"bids":[],"asks":[[2866.7,585.253],[2867.9,3.031]],"action":"update"}}
1651237304.4874117: {"channel":"orderbook","market":"ETH/USD","type":"update","data":{"time":1651237304.3602157,"checksum":3637106986,"bids":[[2859.6,27.427]],"asks":[],"action":"update"}}
1651237304.497394: {"channel":"orderbook","market":"SOL/USD","type":"update","data":{"time":1651237304.3633926,"checksum":2993955266,"bids":[[95.8025,27.21],[95.44,0.0]],"asks":[[96.0275,0.0],[96.2,0.0],[96.36,0.03],[96.3625,0.38]],"action":"update"}}
1651237304.536876: {"channel":"orderbook","market":"ETH/USDT","type":"update","data":{"time":1651237304.4093275,"checksum":2571277090,"bids":[[2860.8,20.47]],"asks":[[2861.1,0.161],[2862.7,5.728],[2882.1,0.0]],"action":"update"}}
1651237304.5583792: {"channel":"orderbook","market":"USD/TRY","type":"update","data":{"time":1651237304.4309614,"checksum":2479525932,"bids":[],"asks":[],"action":"update"}}
1651237304.5594823: {"channel":"orderbook","market":"ETH/USDT","type":"update","data":{"time":1651237304.433311,"checksum":3525652547,"bids":[[2859.7,0.0],[2842.5,835.588]],"asks":[],"action":"update"}}
1651237304.5675747: {"channel":"orderbook","market":"ETH/USD","type":"update","data":{"time":1651237304.4367607,"checksum":3748632847,"bids":[[2859.8,23.763],[2859.6,1.994]],"asks":[],"action":"update"}}
1651237304.587955: {"channel":"orderbook","market":"SOL/USD","type":"update","data":{"time":1651237304.448171,"checksum":1138315075,"bids":[[95.84,169.15],[95.8025,0.0],[95.44,1.0]],"asks":[],"action":"update"}}
1651237304.5880163: {"channel":"orderbook","market":"ETH/USDT","type":"update","data":{"time":1651237304.4602234,"checksum":2285261850,"bids":[[2844.5,0.058],[2842.5,0.0]],"asks":[],"action":"update"}}
1651237304.6150715: {"channel":"orderbook","market":"ETH/USD","type":"update","data":{"time":1651237304.4853303,"checksum":984670880,"bids":[[2859.7,4.836]],"asks":[],"action":"update"}}
1651237304.6214736: {"channel":"orderbook","market":"SOL/USD","type":"update","data":{"time":1651237304.4941392,"checksum":3977026165,"bids":[[95.8425,128.74]],"asks":[],"action":"update"}}
1651237304.6403098: {"channel":"orderbook","market":"ETH/USDT","type":"update","data":{"time":1651237304.5104728,"checksum":3634994614,"bids":[[2859.9,4.009],[2859.7,4.753],[2842.8,0.0],[2842.7,0.0]],"asks":[],"action":"update"}}
1651237304.6428318: {"channel":"orderbook","market":"ETH/USD","type":"update","data":{"time":1651237304.5121164,"checksum":554769596,"bids":[[2855.2,10.072]],"asks":[[2862.2,16.968]],"action":"update"}}
1651237304.6772108: {"channel":"orderbook","market":"ETH/USD","type":"update","data":{"time":1651237304.5475411,"checksum":598424357,"bids":[[2860.9,7.258]],"asks":[[2861.0,5.45],[2866.7,585.252]],"action":"update"}}
1651237304.7163575: {"channel":"orderbook","market":"ETH/USDT","type":"update","data":{"time":1651237304.5864744,"checksum":2990641492,"bids":[],"asks":[[2865.0,8.454]],"action":"update"}}
1651237304.7404866: {"channel":"orderbook","market":"ETH/USD","type":"update","data":{"time":1651237304.6138086,"checksum":261003208,"bids":[[2860.9,3.808],[2860.2,7.056]],"asks":[],"action":"update"}}
1651237304.7792575: {"channel":"orderbook","market":"ETH/USD","type":"update","data":{"time":1651237304.6512115,"checksum":1894447155,"bids":[[2860.3,30.396]],"asks":[],"action":"update"}}
1651237304.7883265: {"channel":"orderbook","market":"FTT/BTC","type":"update","data":{"time":1651237304.6458223,"checksum":1769014293,"bids":[],"asks":[[0.0010098,14.4]],"action":"update"}}
1651237304.792854: {"channel":"orderbook","market":"SOL/USD","type":"update","data":{"time":1651237304.6672955,"checksum":1585415049,"bids":[],"asks":[[96.0175,104.25]],"action":"update"}}
1651237304.8116663: {"channel":"orderbook","market":"ETH/USD","type":"update","data":{"time":1651237304.6802125,"checksum":2178528906,"bids":[[2859.9,42.513]],"asks":[[2867.5,3.209]],"action":"update"}}
1651237304.8153641: {"channel":"orderbook","market":"BTC/TRY","type":"update","data":{"time":1651237304.6919875,"checksum":1840591949,"bids":[],"asks":[],"action":"update"}}
1651237304.821464: {"channel":"orderbook","market":"SOL/USD","type":"update","data":{"time":1651237304.6925378,"checksum":1338413060,"bids":[],"asks":[[95.9,0.0],[96.37,2.64]],"action":"update"}}
1651237304.8338542: {"channel":"orderbook","market":"ETH/USD","type":"update","data":{"time":1651237304.7011979,"checksum":3517137706,"bids":[[2853.7,1.137]],"asks":[],"action":"update"}}
1651237304.8339124: {"channel":"orderbook","market":"FTT/BTC","type":"update","data":{"time":1651237304.6991193,"checksum":2205194620,"bids":[],"asks":[[0.0010096,0.0],[0.0010098,3.9],[0.0010108,52.5],[0.0010242,1.3]],"action":"update"}}
1651237304.853878: {"channel":"orderbook","market":"SOL/USD","type":"update","data":{"time":1651237304.720481,"checksum":2099879905,"bids":[[95.8575,0.0],[95.855,0.0],[95.8525,25.53],[95.84,99.15],[95.8225,57.57],[95.4375,0.01],[95.435,0.01]],"asks":[[95.93,0.69]],"action":"update"}}
1651237304.8814714: {"channel":"orderbook","market":"SOL/USD","type":"update","data":{"time":1651237304.7522185,"checksum":369170672,"bids":[[95.8475,252.45],[95.7725,0.0],[95.4325,44.74]],"asks":[[95.9825,0.05]],"action":"update"}}
1651237304.8815231: {"channel":"orderbook","market":"ETH/USD","type":"update","data":{"time":1651237304.7528927,"checksum":2174956833,"bids":[],"asks":[[2867.2,4.004]],"action":"update"}}
1651237304.8984945: {"channel":"orderbook","market":"FTT/BTC","type":"update","data":{"time":1651237304.7628665,"checksum":854212694,"bids":[],"asks":[[0.0010097,4.3],[0.0010242,0.0]],"action":"update"}}
1651237304.9031546: {"channel":"orderbook","market":"SOL/USD","type":"update","data":{"time":1651237304.7767413,"checksum":3892854959,"bids":[[95.7125,0.0],[95.43,0.25]],"asks":[[96.1925,275.32],[96.37,0.0]],"action":"update"}}
1651237304.932435: {"channel":"orderbook","market":"SOL/USD","type":"update","data":{"time":1651237304.8025486,"checksum":4273869137,"bids":[[95.8525,16.54]],"asks":[],"action":"update"}}
1651237304.9474726: {"channel":"orderbook","market":"LTC/USDT","type":"update","data":{"time":1651237304.809179,"checksum":1522603204,"bids":[[100.605,4.44],[96.93,0.0]],"asks":[],"action":"update"}}
1651237304.963366: {"channel":"orderbook","market":"SOL/USD","type":"update","data":{"time":1651237304.8280642,"checksum":2459658270,"bids":[[95.85,0.0],[95.835,5.0],[95.8175,112.05]],"asks":[[95.89,70.0],[95.895,70.01],[95.9925,33.4],[96.03,0.0]],"action":"update"}}
1651237304.9634678: {"channel":"orderbook","market":"WBTC/USD","type":"update","data":{"time":1651237304.8335302,"checksum":3501912508,"bids":[],"asks":[],"action":"update"}}
1651237304.9802463: {"channel":"orderbook","market":"ETH/USD","type":"update","data":{"time":1651237304.8497496,"checksum":2314086038,"bids":[],"asks":[[2861.8,12.65],[2862.3,28.078]],"action":"update"}}
1651237304.9810483: {"channel":"orderbook","market":"SOL/USD","type":"update","data":{"time":1651237304.856044,"checksum":2242405467,"bids":[[95.82,88.08],[95.43,0.0]],"asks":[[95.8925,7.26],[95.92,0.05],[96.3625,0.0]],"action":"update"}}
1651237305.0071204: {"channel":"orderbook","market":"SOL/USD","type":"update","data":{"time":1651237304.8799663,"checksum":3616285547,"bids":[[95.835,0.0],[95.82,0.0],[95.7375,0.0],[95.43,0.25],[95.425,1.23],[95.4225,0.12]],"asks":[[95.8775,97.64],[95.9075,0.69],[95.9775,80.02],[96.005,0.06],[96.35,0.0],[96.3575,0.0],[96.36,0.0]],"action":"update"}}
1651237305.0139444: {"channel":"orderbook","market":"ETH/USDT","type":"update","data":{"time":1651237304.8840585,"checksum":3821858040,"bids":[],"asks":[[2862.7,5.553],[2862.8,0.906]],"action":"update"}}
1651237305.03592: {"channel":"orderbook","market":"SOL/USD","type":"update","data":{"time":1651237304.9087107,"checksum":1572517691,"bids":[[95.7875,171.08]],"asks":[[95.875,132.95],[95.89,0.0],[96.005,600.2],[96.02,0.58],[96.3475,0.0]],"action":"update"}}
1651237305.0383344: {"channel":"orderbook","market":"ETH/USDT","type":"update","data":{"time":1651237304.9082103,"checksum":1322846394,"bids":[[2859.9,0.0],[2842.8,0.01]],"asks":[],"action":"update"}}
1651237305.057428: {"channel":"orderbook","market":"SOL/USD","type":"update","data":{"time":1651237304.9271877,"checksum":1429820506,"bids":[[95.84,50.17]],"asks":[[95.9625,162.26]],"action":"update"}}
1651237305.057482: {"channel":"orderbook","market":"ETH/USD","type":"update","data":{"time":1651237304.9269505,"checksum":815577576,"bids":[],"asks":[[2862.0,16.003]],"action":"update"}}
1651237305.0712197: {"channel":"orderbook","market":"ETH/USDT","type":"update","data":{"time":1651237304.9343643,"checksum":263947128,"bids":[],"asks":[[2862.2,0.0],[2865.0,13.475],[2882.1,0.011]],"action":"update"}}
1651237305.1044881: {"channel":"orderbook","market":"SOL/USD","type":"update","data":{"time":1651237304.962141,"checksum":1441370014,"bids":[[95.8575,0.01],[95.8475,0.0],[95.825,0.0],[95.8125,0.0],[95.41,0.01],[95.4075,0.47]],"asks":[[95.9325,0.0],[95.945,0.03],[95.96,7.87],[95.975,0.0],[96.3475,0.3]],"action":"update"}}
1651237305.1073186: {"channel":"orderbook","market":"ETH/USD","type":"update","data":{"time":1651237304.9772775,"checksum":3976547614,"bids":[[2860.6,3.324]],"asks":[[2862.7,4.875]],"action":"update"}}
1651237305.1236026: {"channel":"orderbook","market":"FTT/BTC","type":"update","data":{"time":1651237304.9889772,"checksum":3410496404,"bids":[[0.0010089,13.5],[0.0009962,0.0]],"asks":[],"action":"update"}}
1651237305.1500692: {"channel":"orderbook","market":"SOL/USD","type":"update","data":{"time":1651237305.0037603,"checksum":2034114377,"bids":[[95.8525,0.0],[95.845,0.0],[95.83,207.41],[95.82,105.28],[95.8075,0.0],[95.795,778.79],[95.73,74.11],[95.7,57.29],[95.4,43.17],[95.3975,0.17]],"asks":[[95.8725,36.0],[95.9575,0.0],[95.9625,414.71],[95.965,112.37],[95.975,62.55],[95.98,41.15],[95.9925,0.0],[96.0175,0.0],[96.1075,373.1],[96.1625,0.0],[96.35,0.33],[96.3575,0.46]],"action":"update"}}
1651237305.1579516: {"channel":"orderbook","market":"ETH/USDT","type":"update","data":{"time":1651237305.0202343,"checksum":3875505492,"bids":[[2859.7,8.762]],"asks":[[2861.7,11.13],[2862.7,0.523]],"action":"update"}}
1651237305.158001: {"channel":"orderbook","market":"SOL/USD","type":"update","data":{"time":1651237305.0254035,"checksum":2205962163,"bids":[],"asks":[[95.8775,0.0],[96.36,0.03]],"action":"update"}}
1651237305.1622086: {"channel":"orderbook","market":"ETH/USDT","type":"update","data":{"time":1651237305.0349364,"checksum":4057271008,"bids":[],"asks":[[2862.0,33.335]],"action":"update"}}
1651237305.1825242: {"channel":"orderbook","market":"ETH/USD","type":"update","data":{"time":1651237305.051471,"checksum":4225363049,"bids":[],"asks":[[2861.4,11.358]],"action":"update"}}
1651237305.202737: {"channel":"orderbook","market":"ETH/USD","type":"update","data":{"time":1651237305.0749238,"checksum":2539378776,"bids":[],"asks":[[2861.7,48.659]],"action":"update"}}
1651237305.213699: {"channel":"orderbook","market":"USD/TRY","type":"update","data":{"time":1651237305.0833256,"checksum":3407013395,"bids":[],"asks":[[14.9271,958.0]],"action":"update"}}
1651237305.2349474: {"channel":"orderbook","market":"SOL/USD","type":"update","data":{"time":1651237305.0597212,"checksum":3557228369,"bids":[[95.8425,117.43]],"asks":[[95.92,0.0],[95.96,111.57],[96.3625,0.38]],"action":"update"}}
1651237305.2597716: {"channel":"orderbook","market":"SOL/USD","type":"update","data":{"time":1651237305.1133575,"checksum":1671808087,"bids":[[95.82,244.77],[95.8125,5.0],[95.79,62.75],[95.4325,0.0]],"asks":[[95.875,199.99],[95.8925,124.15],[95.8975,0.0],[95.945,33.45],[95.955,0.0],[95.975,0.0],[96.0025,65.87],[96.37,2.64],[96.375,68.15],[96.385,0.35]],"action":"update"}}
1651237305.2795246: {"channel":"orderbook","market":"SOL/USD","type":"update","data":{"time":1651237305.1457012,"checksum":3790261268,"bids":[[95.8575,0.0],[95.83,137.41],[95.39,1459.97]],"asks":[[95.8675,97.64],[96.0825,26.15],[96.385,0.0]],"action":"update"}}
1651237305.2795894: {"channel":"orderbook","market":"ETH/USD","type":"update","data":{"time":1651237305.150971,"checksum":2810059934,"bids":[],"asks":[[2861.0,5.612]],"action":"update"}}
1651237305.2995877: {"channel":"orderbook","market":"LTC/USDT","type":"update","data":{"time":1651237305.1724725,"checksum":1522603204,"bids":[],"asks":[],"action":"update"}}
1651237305.311387: {"channel":"orderbook","market":"LTC/USDT","type":"update","data":{"time":1651237305.1842053,"checksum":1769968344,"bids":[],"asks":[[100.705,14.0]],"action":"update"}}
1651237305.3120987: {"channel":"orderbook","market":"SOL/USD","type":"update","data":{"time":1651237305.1765857,"checksum":2001948353,"bids":[[95.8325,0.0],[95.825,31.29],[95.82,139.49],[95.7825,104.29],[95.6675,379.68],[95.39,0.0]],"asks":[[95.895,0.0],[95.9175,105.29],[95.9475,31.29],[95.9875,233.07],[96.105,104.29],[96.37,0.0],[96.375,0.0]],"action":"update"}}
1651237305.3397677: {"channel":"orderbook","market":"SOL/USD","type":"update","data":{"time":1651237305.2054846,"checksum":2670525678,"bids":[[95.84,0.0],[95.8125,70.0],[95.7,31.19],[95.39,1459.97]],"asks":[[95.8725,0.0],[95.9275,148.21],[95.945,33.42],[95.9475,0.0],[96.37,2.64],[96.375,68.15]],"action":"update"}}
1651237305.3549984: {"channel":"orderbook","market":"SHIB/USD","type":"update","data":{"time":1651237305.2184825,"checksum":2399253942,"bids":[],"asks":[],"action":"update"}}
1651237305.3550353: {"channel":"orderbook","market":"SOL/USD","type":"update","data":{"time":1651237305.2228155,"checksum":2119659686,"bids":[[95.75,82.11]],"asks":[[95.9175,0.0],[95.9575,62.55]],"action":"update"}}
1651237305.3791778: {"channel":"orderbook","market":"SOL/USD","type":"update","data":{"time":1651237305.2527828,"checksum":3099678492,"bids":[[95.8425,0.0],[95.3875,0.37]],"asks":[[95.865,106.0],[96.375,0.0]],"action":"update"}}
1651237305.3990304: {"channel":"orderbook","market":"LTC/USDT","type":"update","data":{"time":1651237305.2599015,"checksum":2578138699,"bids":[],"asks":[[100.625,57.75],[100.705,12.0]],"action":"update"}}
1651237305.4142575: {"channel":"orderbook","market":"SOL/USD","type":"update","data":{"time":1651237305.2846599,"checksum":334061622,"bids":[],"asks":[[95.89,0.01],[96.37,0.0]],"action":"update"}}
1651237305.433838: {"channel":"orderbook","market":"ETH/USD","type":"update","data":{"time":1651237305.3006544,"checksum":2689389503,"bids":[[2857.9,0.874]],"asks":[],"action":"update"}}
1651237305.440965: {"channel":"orderbook","market":"LTC/USDT","type":"update","data":{"time":1651237305.3108785,"checksum":783899174,"bids":[[100.62,116.14]],"asks":[],"action":"update"}}
1651237305.4499893: {"channel":"orderbook","market":"SHIB/USD","type":"update","data":{"time":1651237305.3184652,"checksum":102316786,"bids":[[0.0000226,402700000.0]],"asks":[[0.00002265,540200000.0]],"action":"update"}}
1651237305.4500306: {"channel":"orderbook","market":"SOL/USD","type":"update","data":{"time":1651237305.3160975,"checksum":3094804707,"bids":[[95.7975,13.62],[95.795,178.65]],"asks":[[95.865,113.26],[95.9625,162.26],[96.005,0.06]],"action":"update"}}
1651237305.4559484: {"channel":"orderbook","market":"DAI/USD","type":"update","data":{"time":1651237305.3269734,"checksum":280434518,"bids":[],"asks":[],"action":"update"}}
1651237305.456589: {"channel":"orderbook","market":"ETH/USD","type":"update","data":{"time":1651237305.3262591,"checksum":4155499672,"bids":[],"asks":[[2861.4,7.429],[2862.3,8.602]],"action":"update"}}
1651237305.4715629: {"channel":"orderbook","market":"ETH/USDT","type":"update","data":{"time":1651237305.3451762,"checksum":1318483736,"bids":[],"asks":[[2861.5,0.0],[2862.0,13.331],[2862.6,0.175]],"action":"update"}}
1651237305.478302: {"channel":"orderbook","market":"SHIB/USD","type":"update","data":{"time":1651237305.3431695,"checksum":841427332,"bids":[[0.0000226,302800000.0]],"asks":[],"action":"update"}}
1651237305.4783537: {"channel":"orderbook","market":"LTC/USDT","type":"update","data":{"time":1651237305.3427896,"checksum":3525300323,"bids":[[100.62,54.01]],"asks":[],"action":"update"}}
1651237305.4784129: {"channel":"orderbook","market":"SOL/USD","type":"update","data":{"time":1651237305.3496714,"checksum":2779220598,"bids":[[95.8375,0.0],[95.83,0.0],[95.8,97.58],[95.795,116.01],[95.385,50.0]],"asks":[[95.96,7.87],[96.0625,0.0],[96.37,2.64]],"action":"update"}}
1651237305.478907: {"channel":"orderbook","market":"ETH/USD","type":"update","data":{"time":1651237305.3511367,"checksum":1885739979,"bids":[[2860.9,0.315],[2860.4,30.172]],"asks":[],"action":"update"}}
1651237305.5079818: {"channel":"orderbook","market":"SHIB/USD","type":"update","data":{"time":1651237305.36919,"checksum":2708045522,"bids":[],"asks":[[0.00002264,413900000.0]],"action":"update"}}
1651237305.5080311: {"channel":"orderbook","market":"ETH/USD","type":"update","data":{"time":1651237305.3746705,"checksum":833714588,"bids":[],"asks":[[2861.3,0.0],[2873.4,0.236]],"action":"update"}}
1651237305.5360677: {"channel":"orderbook","market":"SHIB/USD","type":"update","data":{"time":1651237305.393333,"checksum":2603798242,"bids":[[0.0000226,202900000.0],[0.00002259,339000000.0],[0.00002257,238100000.0],[0.00002254,193400000.0]],"asks":[[0.00002264,376400000.0],[0.00002265,440300000.0]],"action":"update"}}
1651237305.5361257: {"channel":"orderbook","market":"ETH/USD","type":"update","data":{"time":1651237305.401095,"checksum":389005405,"bids":[[2860.6,5.266]],"asks":[[2862.2,10.197]],"action":"update"}}
1651237305.5361552: {"channel":"orderbook","market":"SOL/USD","type":"update","data":{"time":1651237305.3940794,"checksum":3437707146,"bids":[[95.81,252.45],[95.7625,600.14],[95.3875,0.0],[95.385,0.0]],"asks":[[95.9225,105.29],[96.0,62.35],[96.025,31.23],[96.08,0.57],[96.37,0.0]],"action":"update"}}
1651237305.5491993: {"channel":"orderbook","market":"ETH/USDT","type":"update","data":{"time":1651237305.4161537,"checksum":248345023,"bids":[[2860.1,10.415]],"asks":[[2861.0,4.211],[2861.6,15.536]],"action":"update"}}
1651237305.5492516: {"channel":"orderbook","market":"SHIB/USD","type":"update","data":{"time":1651237305.4189866,"checksum":129917964,"bids":[[0.00002255,189200000.0]],"asks":[[0.00002262,28400000.0],[0.00002264,336600000.0]],"action":"update"}}
1651237305.5562294: {"channel":"orderbook","market":"ETH/USD","type":"update","data":{"time":1651237305.4272096,"checksum":4056519672,"bids":[[2860.4,11.145],[2855.3,1.948]],"asks":[[2861.6,9.477],[2867.8,0.0],[2873.5,0.015]],"action":"update"}}
1651237305.5562825: {"channel":"orderbook","market":"LTC/USDT","type":"update","data":{"time":1651237305.4258754,"checksum":1408100322,"bids":[],"asks":[[100.66,12.3],[104.02,0.0]],"action":"update"}}
1651237305.568936: {"channel":"orderbook","market":"LTC/USDT","type":"update","data":{"time":1651237305.4435759,"checksum":3009495785,"bids":[[100.57,0.0],[96.93,0.3]],"asks":[],"action":"update"}}
1651237305.5708206: {"channel":"orderbook","market":"SHIB/USD","type":"update","data":{"time":1651237305.4440842,"checksum":1162624490,"bids":[],"asks":[[0.00002262,57300000.0]],"action":"update"}}
1651237305.5807805: {"channel":"orderbook","market":"ETH/USD","type":"update","data":{"time":1651237305.4507596,"checksum":410298926,"bids":[],"asks":[[2861.5,11.438],[2862.7,24.204]],"action":"update"}}
1651237305.5878434: {"channel":"orderbook","market":"USD/TRY","type":"update","data":{"time":1651237305.4612896,"checksum":3407013395,"bids":[],"asks":[],"action":"update"}}
1651237305.596544: {"channel":"orderbook","market":"SOL/USD","type":"update","data":{"time":1651237305.4683003,"checksum":4007914277,"bids":[],"asks":[[95.8625,350.0],[95.875,132.95],[95.9225,0.0],[95.935,252.45],[95.9725,778.79],[96.3625,0.0]],"action":"update"}}
1651237305.5999858: {"channel":"orderbook","market":"ETH/USDT","type":"update","data":{"time":1651237305.4711065,"checksum":3813043332,"bids":[[2860.8,19.612],[2860.2,5.043],[2858.6,9.075]],"asks":[[2862.7,20.495]],"action":"update"}}
1651237305.6000333: {"channel":"orderbook","market":"SHIB/USD","type":"update","data":{"time":1651237305.4681807,"checksum":306297270,"bids":[],"asks":[[0.00002265,340400000.0],[0.00002269,71200000.0]],"action":"update"}}
1651237305.6059349: {"channel":"orderbook","market":"ETH/USD","type":"update","data":{"time":1651237305.4781046,"checksum":3888854049,"bids":[[2860.5,13.424],[2857.9,0.884]],"asks":[[2861.3,1.857],[2861.4,11.353],[2864.1,2.391],[2873.5,0.0]],"action":"update"}}
1651237305.626091: {"channel":"orderbook","market":"LTC/USDT","type":"update","data":{"time":1651237305.4933693,"checksum":1108074599,"bids":[[100.54,7.46]],"asks":[[100.71,0.0],[104.02,0.28]],"action":"update"}}
1651237305.6261435: {"channel":"orderbook","market":"SHIB/USD","type":"update","data":{"time":1651237305.4954858,"checksum":3346702560,"bids":[[0.00002258,169000000.0],[0.00002256,117700000.0]],"asks":[[0.00002263,181000000.0],[0.00002264,342200000.0],[0.00002265,141800000.0],[0.00002266,403800000.0],[0.00002267,92700000.0]],"action":"update"}}
1651237305.6273098: {"channel":"orderbook","market":"ETH/USD","type":"update","data":{"time":1651237305.500444,"checksum":800611937,"bids":[[2852.4,0.12],[2849.5,0.0]],"asks":[[2861.4,16.603],[2862.4,1.559],[2873.4,0.0]],"action":"update"}}
1651237305.632078: {"channel":"orderbook","market":"SOL/USD","type":"update","data":{"time":1651237305.4983692,"checksum":1251156131,"bids":[[95.8275,78.94],[95.685,26.1],[95.67,10.83],[95.6675,104.36],[95.3975,0.0],[95.39,0.0]],"asks":[[95.865,77.26],[95.9025,70.0],[96.36,0.0]],"action":"update"}}
1651237305.646326: {"channel":"orderbook","market":"SHIB/USD","type":"update","data":{"time":1651237305.5189648,"checksum":2757187233,"bids":[[0.00002261,114200000.0]],"asks":[],"action":"update"}}
1651237305.6570497: {"channel":"orderbook","market":"ETH/USD","type":"update","data":{"time":1651237305.5287306,"checksum":3040663937,"bids":[],"asks":[[2861.2,17.3],[2864.1,2.042],[2864.9,183.417],[2867.2,4.199],[2873.1,0.0]],"action":"update"}}
1651237305.6684697: {"channel":"orderbook","market":"LTC/USDT","type":"update","data":{"time":1651237305.543248,"checksum":4238589107,"bids":[[100.61,0.0],[96.845,0.3]],"asks":[],"action":"update"}}
1651237305.671326: {"channel":"orderbook","market":"SHIB/USD","type":"update","data":{"time":1651237305.5434914,"checksum":1940664231,"bids":[],"asks":[[0.00002267,74700000.0]],"action":"update"}}
1651237305.6814883: {"channel":"orderbook","market":"ETH/USD","type":"update","data":{"time":1651237305.5507336,"checksum":4080808550,"bids":[],"asks":[[2861.4,11.353],[2862.6,6.053],[2867.9,0.0]],"action":"update"}}
1651237305.689742: {"channel":"orderbook","market":"SOL/USD","type":"update","data":{"time":1651237305.556237,"checksum":1161924036,"bids":[[95.8175,0.0],[95.7975,8.62],[95.79,0.2],[95.685,0.0],[95.3975,0.17],[95.39,1459.97]],"asks":[[95.86,70.0],[95.865,7.26],[96.3575,0.0]],"action":"update"}}
1651237305.6899128: {"channel":"orderbook","market":"ETH/USDT","type":"update","data":{"time":1651237305.5603325,"checksum":1679354767,"bids":[],"asks":[[2862.0,19.28]],"action":"update"}}
1651237305.6987913: {"channel":"orderbook","market":"SHIB/USD","type":"update","data":{"time":1651237305.5698338,"checksum":2461291682,"bids":[[0.00002259,333500000.0],[0.00002258,191200000.0]],"asks":[],"action":"update"}}
1651237305.7132843: {"channel":"orderbook","market":"ETH/USD","type":"update","data":{"time":1651237305.5763166,"checksum":1823389168,"bids":[[2859.7,24.378]],"asks":[],"action":"update"}}
1651237305.7300735: {"channel":"orderbook","market":"LTC/USDT","type":"update","data":{"time":1651237305.595412,"checksum":2592256735,"bids":[[100.495,0.0],[96.635,0.01]],"asks":[],"action":"update"}}
1651237305.7301185: {"channel":"orderbook","market":"SHIB/USD","type":"update","data":{"time":1651237305.5946226,"checksum":1874772894,"bids":[],"asks":[[0.00002262,75300000.0]],"action":"update"}}
1651237305.7301445: {"channel":"orderbook","market":"SOL/USD","type":"update","data":{"time":1651237305.600022,"checksum":7396933,"bids":[],"asks":[[95.8625,280.0]],"action":"update"}}
1651237305.7498908: {"channel":"orderbook","market":"SHIB/USD","type":"update","data":{"time":1651237305.6189206,"checksum":4089235690,"bids":[[0.00002257,292700000.0]],"asks":[[0.00002266,381600000.0]],"action":"update"}}
1651237305.7750723: {"channel":"orderbook","market":"ETH/USD","type":"update","data":{"time":1651237305.6368084,"checksum":2154612554,"bids":[[2859.7,21.583]],"asks":[[2863.2,11.639],[2863.7,2.128],[2864.1,2.391]],"action":"update"}}
1651237305.7751396: {"channel":"orderbook","market":"SOL/USD","type":"update","data":{"time":1651237305.6411276,"checksum":4010912591,"bids":[],"asks":[[96.05,138.18]],"action":"update"}}
1651237305.7989705: {"channel":"orderbook","market":"FTT/BTC","type":"update","data":{"time":1651237305.6607487,"checksum":3410496404,"bids":[],"asks":[],"action":"update"}}
1651237305.799007: {"channel":"orderbook","market":"SHIB/USD","type":"update","data":{"time":1651237305.6689372,"checksum":2726472189,"bids":[[0.00002257,335200000.0]],"asks":[],"action":"update"}}
1651237305.802322: {"channel":"orderbook","market":"LTC/USDT","type":"update","data":{"time":1651237305.6739545,"checksum":3196411320,"bids":[[100.515,75.32]],"asks":[],"action":"update"}}
1651237305.8129783: {"channel":"orderbook","market":"ETH/USD","type":"update","data":{"time":1651237305.6844814,"checksum":4263297185,"bids":[[2860.4,7.65]],"asks":[[2862.1,18.164],[2862.3,7.602],[2864.1,2.042]],"action":"update"}}
1651237305.8130286: {"channel":"orderbook","market":"ETH/USDT","type":"update","data":{"time":1651237305.6872385,"checksum":2383542203,"bids":[[2860.4,2.951],[2859.7,4.753],[2859.4,24.327]],"asks":[[2862.1,27.379]],"action":"update"}}
1651237305.8203938: {"channel":"orderbook","market":"SOL/USD","type":"update","data":{"time":1651237305.690869,"checksum":755207800,"bids":[[95.8275,0.0],[95.825,0.0],[95.7875,33.42],[95.7675,62.64],[95.3875,0.37]],"asks":[[95.9325,63.16],[96.005,0.0]],"action":"update"}}
1651237305.8310075: {"channel":"orderbook","market":"ETH/USD","type":"update","data":{"time":1651237305.7013814,"checksum":273047771,"bids":[[2860.7,0.0],[2860.5,7.763],[2849.5,0.01]],"asks":[[2861.0,7.612],[2861.5,7.441],[2861.6,15.663]],"action":"update"}}
1651237305.83779: {"channel":"orderbook","market":"LTC/USDT","type":"update","data":{"time":1651237305.7053046,"checksum":1670992265,"bids":[[100.62,0.0],[96.55,0.23]],"asks":[],"action":"update"}}
1651237305.8390408: {"channel":"orderbook","market":"BTC/TRY","type":"update","data":{"time":1651237305.715375,"checksum":1840591949,"bids":[],"asks":[],"action":"update"}}
1651237305.8460002: {"channel":"orderbook","market":"ETH/USDT","type":"update","data":{"time":1651237305.7179983,"checksum":3159285461,"bids":[[2860.9,4.903],[2860.8,4.768],[2860.3,8.393],[2859.9,4.009],[2842.8,0.0]],"asks":[[2861.6,12.04],[2862.0,32.412],[2862.5,0.01]],"action":"update"}}
1651237305.855845: {"channel":"orderbook","market":"SHIB/USD","type":"update","data":{"time":1651237305.7192302,"checksum":239773156,"bids":[],"asks":[[0.00002263,203200000.0]],"action":"update"}}
1651237305.8567638: {"channel":"orderbook","market":"LTC/USDT","type":"update","data":{"time":1651237305.7304916,"checksum":552163047,"bids":[[100.465,40.94]],"asks":[],"action":"update"}}
1651237305.8739214: {"channel":"orderbook","market":"SOL/USD","type":"update","data":{"time":1651237305.7457013,"checksum":157350864,"bids":[],"asks":[[95.9625,70.0],[96.0025,0.0],[96.3575,0.46]],"action":"update"}}
1651237305.8739965: {"channel":"orderbook","market":"ETH/USDT","type":"update","data":{"time":1651237305.7465043,"checksum":927705591,"bids":[[2860.9,0.0],[2860.8,4.529],[2842.8,0.01]],"asks":[[2861.7,15.659],[2862.1,4.087]],"action":"update"}}
1651237305.887852: {"channel":"orderbook","market":"LTC/USDT","type":"update","data":{"time":1651237305.7577085,"checksum":1206933377,"bids":[[100.605,0.0],[100.585,0.0],[96.5,0.06],[96.45,1.02]],"asks":[],"action":"update"}}
1651237305.8969522: {"channel":"orderbook","market":"SOL/USD","type":"update","data":{"time":1651237305.7622454,"checksum":3836962092,"bids":[[95.7975,0.0],[95.78,122.69],[95.7675,125.19],[95.385,50.0]],"asks":[[95.9875,104.98]],"action":"update"}}
1651237305.9018593: {"channel":"orderbook","market":"ETH/USD","type":"update","data":{"time":1651237305.7704346,"checksum":103094617,"bids":[[2860.8,0.0],[2860.3,26.9],[2859.8,4.707],[2859.7,25.079],[2859.6,22.575],[2859.2,18.29],[2849.4,0.04]],"asks":[[2861.0,11.612],[2861.1,4.814],[2861.2,22.55],[2861.3,3.605],[2861.4,7.429],[2861.8,9.154],[2861.9,5.308],[2862.0,12.878],[2863.1,2.797],[2863.3,12.436],[2868.8,4.0]],"action":"update"}}
1651237305.9180546: {"channel":"orderbook","market":"ETH/USDT","type":"update","data":{"time":1651237305.7864137,"checksum":904628524,"bids":[[2860.4,3.265],[2860.1,6.919],[2859.7,8.249]],"asks":[[2861.0,2.211],[2861.1,0.0],[2861.8,0.0],[2862.0,25.714],[2882.2,0.011],[2882.4,0.035]],"action":"update"}}
1651237305.9280107: {"channel":"orderbook","market":"SOL/USD","type":"update","data":{"time":1651237305.7968333,"checksum":2327545312,"bids":[[95.805,31.3],[95.8025,112.88],[95.6325,26.1],[95.39,0.0],[95.3875,0.0],[95.385,0.0]],"asks":[],"action":"update"}}
1651237305.9405272: {"channel":"orderbook","market":"ETH/USD","type":"update","data":{"time":1651237305.79172,"checksum":3260983958,"bids":[[2860.9,0.0],[2860.4,7.954],[2859.9,48.174],[2859.6,0.633],[2856.4,0.0],[2855.2,7.041],[2855.1,0.014],[2849.3,0.041],[2849.1,0.004]],"asks":[[2861.3,14.951],[2863.2,10.959],[2864.1,2.391]],"action":"update"}}
1651237305.9406614: {"channel":"orderbook","market":"LTC/USDT","type":"update","data":{"time":1651237305.8049397,"checksum":4045864778,"bids":[[100.56,0.0],[96.43,0.03]],"asks":[],"action":"update"}}
1651237305.967577: {"channel":"orderbook","market":"ETH/USDT","type":"update","data":{"time":1651237305.8145692,"checksum":1259934448,"bids":[],"asks":[[2861.2,13.719],[2862.0,26.006]],"action":"update"}}
1651237305.9676313: {"channel":"orderbook","market":"SOL/USD","type":"update","data":{"time":1651237305.8179953,"checksum":1202833684,"bids":[],"asks":[[95.935,283.74]],"action":"update"}}
1651237305.9676762: {"channel":"orderbook","market":"SHIB/USD","type":"update","data":{"time":1651237305.819638,"checksum":46775126,"bids":[[0.00002257,427500000.0]],"asks":[],"action":"update"}}
1651237305.9677079: {"channel":"orderbook","market":"ETH/USD","type":"update","data":{"time":1651237305.8306859,"checksum":3435024741,"bids":[[2860.6,1.942],[2859.9,42.538],[2858.1,4.372],[2857.9,0.874]],"asks":[[2861.0,9.612],[2861.6,12.167],[2863.8,0.001],[2864.8,14.278]],"action":"update"}}
1651237305.96776: {"channel":"orderbook","market":"LTC/USDT","type":"update","data":{"time":1651237305.8367665,"checksum":289055445,"bids":[[100.555,70.0],[96.43,0.0]],"asks":[],"action":"update"}}
1651237305.99402: {"channel":"orderbook","market":"LTC/USDT","type":"update","data":{"time":1651237305.8552816,"checksum":4005752395,"bids":[],"asks":[[100.66,0.0],[104.085,0.69]],"action":"update"}}
1651237305.9940958: {"channel":"orderbook","market":"ETH/USD","type":"update","data":{"time":1651237305.8599424,"checksum":2687685476,"bids":[[2860.6,0.0],[2860.3,9.602],[2860.0,12.082],[2859.3,0.0],[2849.0,0.015],[2848.9,68.482]],"asks":[[2861.0,3.612],[2863.2,3.682],[2864.1,2.042],[2864.7,0.0],[2873.1,0.002]],"action":"update"}}
1651237305.9942021: {"channel":"orderbook","market":"SOL/USD","type":"update","data":{"time":1651237305.8624036,"checksum":3899656300,"bids":[[95.75,219.77]],"asks":[[95.86,69.99],[95.9875,0.69]],"action":"update"}}
1651237305.9980783: {"channel":"orderbook","market":"ETH/USDT","type":"update","data":{"time":1651237305.8636665,"checksum":3906795327,"bids":[[2860.8,0.0],[2842.7,0.018]],"asks":[[2861.7,11.13],[2862.0,8.345],[2864.5,0.0],[2865.3,0.0],[2882.5,0.01],[2882.6,0.1]],"action":"update"}}
1651237305.998184: {"channel":"orderbook","market":"WBTC/USD","type":"update","data":{"time":1651237305.8621917,"checksum":3501912508,"bids":[],"asks":[],"action":"update"}}
1651237306.0081685: {"channel":"orderbook","market":"ETH/USD","type":"update","data":{"time":1651237305.8792005,"checksum":868601783,"bids":[],"asks":[[2861.1,4.329],[2866.4,7.306]],"action":"update"}}
1651237306.024072: {"channel":"orderbook","market":"ETH/USDT","type":"update","data":{"time":1651237305.8944802,"checksum":1661465087,"bids":[[2859.9,5.009]],"asks":[[2861.3,1.748],[2882.6,0.0]],"action":"update"}}
1651237306.0241213: {"channel":"orderbook","market":"SOL/USD","type":"update","data":{"time":1651237305.8946633,"checksum":1759122080,"bids":[[95.82,0.0],[95.8125,133.17],[95.7825,0.0],[95.75,146.28],[95.39,1459.97],[95.3875,0.37]],"asks":[],"action":"update"}}
1651237306.0530972: {"channel":"orderbook","market":"ETH/USDT","type":"update","data":{"time":1651237305.9107242,"checksum":2857737274,"bids":[[2859.9,4.009]],"asks":[[2860.9,4.095],[2861.6,9.54],[2882.5,0.0]],"action":"update"}}
1651237306.0531595: {"channel":"orderbook","market":"LTC/USDT","type":"update","data":{"time":1651237305.9135327,"checksum":2277306061,"bids":[[100.46,17.2],[96.45,0.0]],"asks":[[100.62,230.0],[100.68,14.6],[104.02,0.0],[104.085,0.0]],"action":"update"}}
1651237306.0531933: {"channel":"orderbook","market":"ETH/USD","type":"update","data":{"time":1651237305.910961,"checksum":2884960011,"bids":[[2860.4,2.342],[2859.8,10.981],[2859.0,2.969],[2856.1,1.541]],"asks":[[2860.7,7.746],[2860.9,2.28],[2861.2,0.0],[2861.6,15.292],[2864.4,0.0]],"action":"update"}}
1651237306.0585415: {"channel":"orderbook","market":"SOL/USD","type":"update","data":{"time":1651237305.925818,"checksum":647781621,"bids":[[95.735,0.64],[95.6325,0.0],[95.385,50.0]],"asks":[[95.975,0.06],[96.3575,0.0]],"action":"update"}}
1651237306.0586002: {"channel":"orderbook","market":"LTC/USDT","type":"update","data":{"time":1651237305.9312148,"checksum":756319988,"bids":[[100.52,61.06],[96.5,0.0]],"asks":[],"action":"update"}}
1651237306.0639167: {"channel":"orderbook","market":"ETH/USD","type":"update","data":{"time":1651237305.9318376,"checksum":1854110860,"bids":[[2860.2,12.131],[2860.1,15.779],[2858.8,3.648]],"asks":[[2860.7,13.239],[2861.0,10.766],[2861.2,3.743],[2861.4,3.678],[2862.0,12.529],[2863.3,0.365],[2873.1,0.0]],"action":"update"}}
1651237306.070935: {"channel":"orderbook","market":"SOL/USD","type":"update","data":{"time":1651237305.9425218,"checksum":1782962572,"bids":[[95.8,102.58],[95.7275,0.0],[95.3825,0.01]],"asks":[],"action":"update"}}
1651237306.0762806: {"channel":"orderbook","market":"ETH/USDT","type":"update","data":{"time":1651237305.9433568,"checksum":29899675,"bids":[[2860.6,0.0],[2860.1,0.0],[2859.8,0.0],[2859.6,19.981],[2858.1,11.037],[2842.5,835.588],[2842.2,0.001]],"asks":[[2860.9,2.095],[2861.1,2.461],[2861.3,0.0],[2861.4,4.529],[2882.4,0.0]],"action":"update"}}
1651237306.0890765: {"channel":"orderbook","market":"LTC/USDT","type":"update","data":{"time":1651237305.95706,"checksum":496607676,"bids":[],"asks":[[100.705,0.0],[104.02,0.28]],"action":"update"}}
1651237306.1057677: {"channel":"orderbook","market":"ETH/USD","type":"update","data":{"time":1651237305.9572191,"checksum":3939921902,"bids":[[2858.5,0.007]],"asks":[[2860.7,7.646],[2860.8,1.9],[2860.9,0.0],[2861.0,10.604],[2861.1,8.326],[2861.5,2.441],[2861.7,52.155],[2862.3,0.002],[2862.4,13.63]],"action":"update"}}
1651237306.1058536: {"channel":"orderbook","market":"SOL/USD","type":"update","data":{"time":1651237305.972044,"checksum":4121098801,"bids":[],"asks":[[95.8575,70.0],[96.35,0.0]],"action":"update"}}
1651237306.1193116: {"channel":"orderbook","market":"ETH/USD","type":"update","data":{"time":1651237305.982224,"checksum":464814899,"bids":[[2860.5,0.0],[2860.1,15.976],[2859.9,27.004],[2848.7,0.04]],"asks":[[2860.6,2.0],[2860.8,0.0],[2861.7,48.659],[2864.2,0.351]],"action":"update"}}
1651237306.1193936: {"channel":"orderbook","market":"SHIB/USD","type":"update","data":{"time":1651237305.9831336,"checksum":476352824,"bids":[],"asks":[[0.00002264,442100000.0]],"action":"update"}}
1651237306.119433: {"channel":"orderbook","market":"FTT/BTC","type":"update","data":{"time":1651237305.9909074,"checksum":718245055,"bids":[],"asks":[[0.0010094,10.5],[0.0010241,0.0]],"action":"update"}}
1651237306.1291916: {"channel":"orderbook","market":"SOL/USD","type":"update","data":{"time":1651237305.9975917,"checksum":1355881039,"bids":[],"asks":[[95.9175,0.03],[96.3475,0.0]],"action":"update"}}
1651237306.1392365: {"channel":"orderbook","market":"ETH/USD","type":"update","data":{"time":1651237306.0090384,"checksum":1656215260,"bids":[[2860.3,0.0],[2858.8,3.997],[2857.9,2.64],[2857.2,1.768],[2848.6,0.198]],"asks":[[2860.6,5.935],[2860.7,2.0],[2861.3,3.605],[2864.2,0.002]],"action":"update"}}
1651237306.1558282: {"channel":"orderbook","market":"LTC/USDT","type":"update","data":{"time":1651237306.0188797,"checksum":1106364919,"bids":[],"asks":[[100.615,50.13],[100.74,24.0],[104.02,0.0]],"action":"update"}}
1651237306.1579092: {"channel":"orderbook","market":"SOL/USD","type":"update","data":{"time":1651237306.0248182,"checksum":1436425783,"bids":[[95.76,104.31],[95.67,36.93],[95.3825,0.0]],"asks":[[95.86,0.0],[95.9,105.31],[95.9675,104.31],[96.3425,0.0]],"action":"update"}}
1651237306.1621711: {"channel":"orderbook","market":"ETH/USD","type":"update","data":{"time":1651237306.0316648,"checksum":3403902016,"bids":[[2860.3,0.003],[2858.8,3.648],[2857.7,0.01],[2848.7,0.0],[2848.6,0.0]],"asks":[[2860.6,10.035],[2860.7,0.0],[2861.1,4.329],[2861.2,0.0],[2861.9,4.008],[2873.1,0.002],[2873.4,0.236]],"action":"update"}}
1651237306.1647806: {"channel":"orderbook","market":"FTT/BTC","type":"update","data":{"time":1651237306.0358813,"checksum":1966179612,"bids":[[0.0010083,30.8]],"asks":[[0.0010094,0.0],[0.0010241,2879.9]],"action":"update"}}
1651237306.6247747: {"channel":"orderbook","market":"ETH/USDT","type":"update","data":{"time":1651237306.0393414,"checksum":4210447080,"bids":[[2860.6,2.5],[2860.3,12.922],[2860.2,19.105],[2860.0,8.471],[2859.6,18.981],[2859.5,6.085],[2858.2,4.552],[2842.2,0.0]],"asks":[[2860.7,2.0],[2860.8,2.05],[2860.9,0.0],[2861.0,6.299],[2861.2,0.0],[2861.6,2.621],[2861.9,3.311],[2863.4,0.73],[2864.9,0.077],[2882.2,0.0]],"action":"update"}}
1651237306.624867: {"channel":"orderbook","market":"SHIB/USD","type":"update","data":{"time":1651237306.0503652,"checksum":1786310497,"bids":[],"asks":[[0.00002263,242200000.0],[0.00002264,414300000.0]],"action":"update"}}
1651237306.62497: {"channel":"orderbook","market":"LTC/USDT","type":"update","data":{"time":1651237306.0572696,"checksum":2252874827,"bids":[[100.59,62.01],[96.55,0.0]],"asks":[],"action":"update"}}
1651237306.6282685: {"channel":"orderbook","market":"ETH/USD","type":"update","data":{"time":1651237306.0556948,"checksum":1062873714,"bids":[[2860.4,0.346],[2859.6,0.316]],"asks":[[2860.6,8.035],[2861.1,0.0],[2861.3,1.748],[2861.6,15.641],[2862.9,2.122],[2863.8,0.01],[2873.5,0.015]],"action":"update"}}
1651237306.6283305: {"channel":"orderbook","market":"SHIB/USD","type":"update","data":{"time":1651237306.0819235,"checksum":354143995,"bids":[],"asks":[[0.00002263,340500000.0],[0.00002264,514200000.0]],"action":"update"}}
1651237306.6283588: {"channel":"orderbook","market":"ETH/USD","type":"update","data":{"time":1651237306.083234,"checksum":1969453418,"bids":[[2860.2,15.882],[2860.0,13.082],[2859.6,0.182],[2859.5,3.496],[2859.2,25.494],[2859.1,144.829],[2856.0,2.148],[2854.6,3.032],[2848.9,0.0]],"asks":[[2860.6,13.274],[2861.2,3.497],[2861.8,3.493],[2873.5,0.0]],"action":"update"}}
1651237306.6284096: {"channel":"orderbook","market":"ETH/USDT","type":"update","data":{"time":1651237306.089187,"checksum":1043154476,"bids":[[2859.9,7.505],[2859.3,4.012],[2858.6,14.975]],"asks":[[2861.1,0.0],[2861.2,3.497]],"action":"update"}}
1651237306.6284494: {"channel":"orderbook","market":"LTC/USDT","type":"update","data":{"time":1651237306.1099937,"checksum":893583760,"bids":[[100.6,0.0],[96.55,0.23]],"asks":[[100.64,0.0],[104.02,0.28]],"action":"update"}}
1651237306.6284852: {"channel":"orderbook","market":"ETH/USD","type":"update","data":{"time":1651237306.1067357,"checksum":3445198288,"bids":[[2860.5,1.9],[2860.2,8.826],[2859.8,6.274],[2849.0,0.0]],"asks":[[2860.6,9.781],[2860.9,3.997],[2861.1,1.748],[2861.3,7.409],[2864.1,2.391],[2864.8,26.633],[2873.1,0.0],[2873.4,0.0]],"action":"update"}}
1651237306.628535: {"channel":"orderbook","market":"SOL/USD","type":"update","data":{"time":1651237306.101768,"checksum":2786722952,"bids":[[95.65,0.08],[95.6425,0.01],[95.6275,275.48]],"asks":[[95.89,0.0],[95.9725,716.15],[96.1125,0.0],[96.3425,0.05],[96.3475,0.3]],"action":"update"}}
1651237306.6285772: {"channel":"orderbook","market":"FTT/BTC","type":"update","data":{"time":1651237306.1176252,"checksum":760413207,"bids":[[0.001007,3.8],[0.0009964,0.0]],"asks":[],"action":"update"}}
1651237306.6286035: {"channel":"orderbook","market":"ETH/USDT","type":"update","data":{"time":1651237306.1251795,"checksum":74020805,"bids":[[2859.8,6.92],[2858.6,9.075],[2842.5,0.0]],"asks":[[2860.7,4.05],[2860.8,0.0],[2861.0,4.249],[2882.2,0.011]],"action":"update"}}
1651237306.6286385: {"channel":"orderbook","market":"ETH/USD","type":"update","data":{"time":1651237306.13112,"checksum":2407519175,"bids":[[2859.9,12.263],[2859.8,13.351],[2859.5,13.118],[2859.3,6.375],[2858.1,4.381],[2849.1,0.0]],"asks":[[2860.6,7.781],[2861.4,8.928]],"action":"update"}}
1651237306.6286802: {"channel":"orderbook","market":"WBTC/USD","type":"update","data":{"time":1651237306.1380887,"checksum":4274245785,"bids":[],"asks":[[38971.0,0.7002],[44095.0,0.0]],"action":"update"}}
1651237306.6287048: {"channel":"orderbook","market":"ETH/USD","type":"update","data":{"time":1651237306.1556585,"checksum":3736695606,"bids":[[2860.0,6.252],[2859.3,21.859],[2857.9,1.766]],"asks":[[2860.6,5.681],[2861.0,8.7],[2861.4,3.678],[2872.0,6.049]],"action":"update"}}
1651237306.6287389: {"channel":"orderbook","market":"ETH/USDT","type":"update","data":{"time":1651237306.1712618,"checksum":3508089240,"bids":[[2858.1,0.0],[2842.5,835.588]],"asks":[],"action":"update"}}
1651237306.6287637: {"channel":"orderbook","market":"LTC/USDT","type":"update","data":{"time":1651237306.1756845,"checksum":3637179665,"bids":[[100.54,7.8]],"asks":[[100.625,50.13],[100.675,0.34],[104.02,0.0]],"action":"update"}}
1651237306.628793: {"channel":"orderbook","market":"SOL/USD","type":"update","data":{"time":1651237306.179455,"checksum":549269114,"bids":[[95.6775,93.81],[95.385,0.0]],"asks":[[95.86,70.07],[95.9,0.0]],"action":"update"}}
1651237306.628823: {"channel":"orderbook","market":"ETH/USD","type":"update","data":{"time":1651237306.181216,"checksum":1177592669,"bids":[[2860.5,2.132],[2860.4,2.442]],"asks":[[2861.3,5.661],[2861.6,16.941],[2864.1,2.042]],"action":"update"}}
1651237306.6288524: {"channel":"orderbook","market":"WBTC/USD","type":"update","data":{"time":1651237306.1943355,"checksum":869331473,"bids":[],"asks":[[38982.0,0.0],[44095.0,0.0005]],"action":"update"}}
1651237306.6288764: {"channel":"orderbook","market":"SOL/USD","type":"update","data":{"time":1651237306.2017136,"checksum":3652392192,"bids":[[95.67,26.1]],"asks":[],"action":"update"}}
1651237306.6288986: {"channel":"orderbook","market":"ETH/USD","type":"update","data":{"time":1651237306.2058442,"checksum":3018155126,"bids":[[2860.4,0.346],[2860.0,5.252],[2859.4,17.538]],"asks":[[2860.6,3.935]],"action":"update"}}
1651237306.6289291: {"channel":"orderbook","market":"LTC/USDT","type":"update","data":{"time":1651237306.2135077,"checksum":1318310005,"bids":[],"asks":[[100.85,313.42]],"action":"update"}}
1651237306.628951: {"channel":"orderbook","market":"ETH/USDT","type":"update","data":{"time":1651237306.2167854,"checksum":3055682260,"bids":[[2859.9,3.496]],"asks":[],"action":"update"}}
1651237306.6313853: {"channel":"orderbook","market":"SOL/USD","type":"update","data":{"time":1651237306.2311032,"checksum":2706326588,"bids":[],"asks":[[95.9175,0.0],[96.35,0.33]],"action":"update"}}
1651237306.6314645: {"channel":"orderbook","market":"SHIB/USD","type":"update","data":{"time":1651237306.2289193,"checksum":354143995,"bids":[],"asks":[],"action":"update"}}
1651237306.6314983: {"channel":"orderbook","market":"ETH/USD","type":"update","data":{"time":1651237306.2315247,"checksum":1677821362,"bids":[[2860.5,4.232]],"asks":[[2861.6,20.437],[2862.9,1.773]],"action":"update"}}
1651237306.6315413: {"channel":"orderbook","market":"ETH/USD","type":"update","data":{"time":1651237306.2557442,"checksum":1119431995,"bids":[[2860.0,7.0],[2857.6,1.248]],"asks":[],"action":"update"}}
1651237306.6315787: {"channel":"orderbook","market":"SOL/USD","type":"update","data":{"time":1651237306.280204,"checksum":2542595599,"bids":[[95.815,0.0],[95.8125,63.17],[95.385,50.0]],"asks":[[95.915,39.37],[96.35,0.0]],"action":"update"}}
1651237306.6316288: {"channel":"orderbook","market":"ETH/USD","type":"update","data":{"time":1651237306.2801397,"checksum":160845311,"bids":[],"asks":[[2864.1,2.391]],"action":"update"}}
1651237306.6316657: {"channel":"orderbook","market":"ETH/USDT","type":"update","data":{"time":1651237306.290973,"checksum":788256391,"bids":[[2859.4,28.336]],"asks":[],"action":"update"}}
1651237306.6316996: {"channel":"orderbook","market":"SOL/USD","type":"update","data":{"time":1651237306.3065464,"checksum":2053803077,"bids":[[95.795,0.0],[95.3825,0.01]],"asks":[[95.8675,0.0],[95.905,175.31],[96.35,0.33]],"action":"update"}}
1651237306.6317394: {"channel":"orderbook","market":"ETH/USD","type":"update","data":{"time":1651237306.328598,"checksum":3799040857,"bids":[[2859.6,0.0],[2849.1,0.004]],"asks":[[2861.0,3.45],[2864.1,2.042]],"action":"update"}}
1651237306.6317725: {"channel":"orderbook","market":"SHIB/USD","type":"update","data":{"time":1651237306.3285036,"checksum":1242627782,"bids":[[0.0000226,137300000.0]],"asks":[],"action":"update"}}
1651237306.6317956: {"channel":"orderbook","market":"SOL/USD","type":"update","data":{"time":1651237306.3296492,"checksum":2245534848,"bids":[[95.7975,139.24],[95.3825,0.0]],"asks":[],"action":"update"}}
1651237306.631821: {"channel":"orderbook","market":"DAI/USD","type":"update","data":{"time":1651237306.3334062,"checksum":280434518,"bids":[],"asks":[],"action":"update"}}
1651237306.6318402: {"channel":"orderbook","market":"ETH/USDT","type":"update","data":{"time":1651237306.3420718,"checksum":1091409663,"bids":[],"asks":[[2862.6,0.0],[2882.4,0.035]],"action":"update"}}
1651237306.6318638: {"channel":"orderbook","market":"ETH/USDT","type":"update","data":{"time":1651237306.3670032,"checksum":2344274247,"bids":[[2860.2,5.043]],"asks":[[2860.7,4.211],[2861.6,24.527],[2862.7,0.523]],"action":"update"}}
1651237306.631895: {"channel":"orderbook","market":"SOL/USD","type":"update","data":{"time":1651237306.371536,"checksum":4071251671,"bids":[[95.8,172.58],[95.7875,0.0],[95.71,0.0],[95.3825,0.01],[95.38,1.12]],"asks":[[95.89,97.21],[95.965,0.0]],"action":"update"}}
1651237306.6319504: {"channel":"orderbook","market":"ETH/USD","type":"update","data":{"time":1651237306.3804677,"checksum":2473110648,"bids":[[2860.4,0.304],[2857.7,0.0],[2849.0,0.015]],"asks":[[2861.1,6.998],[2862.7,4.875],[2870.9,4.541],[2872.9,0.0]],"action":"update"}}
1651237306.6320045: {"channel":"orderbook","market":"ETH/USDT","type":"update","data":{"time":1651237306.3925488,"checksum":3042986044,"bids":[[2859.5,6.377]],"asks":[[2862.6,5.128],[2882.4,0.0]],"action":"update"}}
1651237306.632047: {"channel":"orderbook","market":"SOL/USD","type":"update","data":{"time":1651237306.3974864,"checksum":3563544819,"bids":[[95.79,119.86]],"asks":[[95.8475,97.64],[95.9,128.59],[96.3475,0.0],[96.35,0.0]],"action":"update"}}
1651237306.6320965: {"channel":"orderbook","market":"ETH/USD","type":"update","data":{"time":1651237306.4052315,"checksum":137970818,"bids":[[2859.9,12.305],[2854.9,155.939]],"asks":[[2862.6,0.0],[2862.8,25.056],[2872.9,0.003]],"action":"update"}}
1651237306.6321456: {"channel":"orderbook","market":"SHIB/USD","type":"update","data":{"time":1651237306.4062946,"checksum":2627236493,"bids":[[0.00002256,117500000.0]],"asks":[],"action":"update"}}
1651237306.6321814: {"channel":"orderbook","market":"SOL/USD","type":"update","data":{"time":1651237306.4181876,"checksum":2466172537,"bids":[[95.76,220.32]],"asks":[[95.96,70.51],[95.97,65.88],[96.3425,0.0]],"action":"update"}}
1651237306.6322277: {"channel":"orderbook","market":"ETH/USD","type":"update","data":{"time":1651237306.4303246,"checksum":3162923859,"bids":[],"asks":[[2861.1,1.748]],"action":"update"}}
1651237306.6905935: {"channel":"orderbook","market":"ETH/USD","type":"update","data":{"time":1651237306.4552166,"checksum":616187070,"bids":[],"asks":[[2862.7,11.144]],"action":"update"}}
1651237306.6906378: {"channel":"orderbook","market":"SOL/USD","type":"update","data":{"time":1651237306.458774,"checksum":2156030309,"bids":[[95.67,38.71]],"asks":[[95.8575,0.0],[96.0825,0.05],[96.3425,0.05]],"action":"update"}}
1651237306.6906734: {"channel":"orderbook","market":"ETH/USD","type":"update","data":{"time":1651237306.4805682,"checksum":285947027,"bids":[[2859.1,127.675]],"asks":[[2864.2,0.351]],"action":"update"}}
1651237306.690699: {"channel":"orderbook","market":"USD/TRY","type":"update","data":{"time":1651237306.4852219,"checksum":3407013395,"bids":[],"asks":[],"action":"update"}}
1651237306.6909761: {"channel":"orderbook","market":"SOL/USD","type":"update","data":{"time":1651237306.4878259,"checksum":4252557553,"bids":[[95.7625,633.56]],"asks":[[95.8875,115.28],[95.9175,52.3],[96.01,75.59],[96.3325,0.0],[96.3375,0.0],[96.3425,0.0]],"action":"update"}}
1651237306.691047: {"channel":"orderbook","market":"ETH/USD","type":"update","data":{"time":1651237306.5036798,"checksum":2945666641,"bids":[],"asks":[[2861.1,6.998],[2862.3,0.351]],"action":"update"}}
1651237306.691094: {"channel":"orderbook","market":"ETH/USDT","type":"update","data":{"time":1651237306.5185351,"checksum":2289919875,"bids":[[2858.9,0.175],[2842.5,0.0]],"asks":[[2862.2,19.846],[2862.6,0.0]],"action":"update"}}
1651237306.6911476: {"channel":"orderbook","market":"SOL/USD","type":"update","data":{"time":1651237306.5280497,"checksum":918947466,"bids":[],"asks":[[95.875,0.0],[96.1925,0.0],[96.3325,0.13],[96.3375,0.29]],"action":"update"}}
1651237306.6912003: {"channel":"orderbook","market":"ETH/USD","type":"update","data":{"time":1651237306.5304227,"checksum":4290455313,"bids":[],"asks":[[2862.3,20.276],[2868.6,2.056],[2872.9,0.0]],"action":"update"}}
1651237306.708306: {"channel":"orderbook","market":"ETH/USD","type":"update","data":{"time":1651237306.553753,"checksum":2365217122,"bids":[],"asks":[[2861.0,5.205],[2861.1,1.748]],"action":"update"}}
1651237306.7143278: {"channel":"orderbook","market":"ETH/USD","type":"update","data":{"time":1651237306.5799956,"checksum":3264402075,"bids":[],"asks":[[2861.0,3.45]],"action":"update"}}
1651237306.7143734: {"channel":"orderbook","market":"SOL/USD","type":"update","data":{"time":1651237306.5802414,"checksum":158080432,"bids":[],"asks":[[95.8625,0.0],[96.3425,0.05]],"action":"update"}}
1651237306.7162526: {"channel":"orderbook","market":"LTC/USDT","type":"update","data":{"time":1651237306.5885193,"checksum":2627989962,"bids":[[100.595,50.13],[96.55,0.0]],"asks":[],"action":"update"}}
1651237306.7284808: {"channel":"orderbook","market":"ETH/USDT","type":"update","data":{"time":1651237306.5911067,"checksum":66396858,"bids":[],"asks":[[2861.7,0.189]],"action":"update"}}
1651237306.736491: {"channel":"orderbook","market":"SOL/USD","type":"update","data":{"time":1651237306.600662,"checksum":2778315482,"bids":[],"asks":[[95.855,131.24],[95.86,0.0],[96.0625,26.1],[96.3425,0.0]],"action":"update"}}
1651237306.7590792: {"channel":"orderbook","market":"SOL/USD","type":"update","data":{"time":1651237306.6259294,"checksum":345518595,"bids":[[95.8,167.58]],"asks":[],"action":"update"}}
1651237306.7726364: {"channel":"orderbook","market":"ETH/USDT","type":"update","data":{"time":1651237306.6417694,"checksum":195971408,"bids":[],"asks":[[2861.6,2.621]],"action":"update"}}
1651237306.77269: {"channel":"orderbook","market":"ETH/USD","type":"update","data":{"time":1651237306.6301796,"checksum":2865019669,"bids":[],"asks":[[2864.2,0.002]],"action":"update"}}
1651237306.8034737: {"channel":"orderbook","market":"LTC/USDT","type":"update","data":{"time":1651237306.6662884,"checksum":2742921460,"bids":[[100.47,1.31],[96.635,0.0]],"asks":[],"action":"update"}}
1651237306.8035328: {"channel":"orderbook","market":"ETH/USDT","type":"update","data":{"time":1651237306.667381,"checksum":115204668,"bids":[],"asks":[[2861.6,0.0],[2882.4,0.035]],"action":"update"}}
1651237306.8035686: {"channel":"orderbook","market":"ETH/USD","type":"update","data":{"time":1651237306.6692817,"checksum":3468147525,"bids":[[2860.1,6.327],[2859.8,20.396],[2859.5,31.998],[2858.0,4.836]],"asks":[[2860.6,3.45]],"action":"update"}}
1651237306.8036125: {"channel":"orderbook","market":"SOL/USD","type":"update","data":{"time":1651237306.674536,"checksum":1363098004,"bids":[],"asks":[[95.975,0.0],[96.3425,0.05]],"action":"update"}}
1651237306.8231535: {"channel":"orderbook","market":"ETH/USDT","type":"update","data":{"time":1651237306.6918797,"checksum":1564515594,"bids":[[2860.3,32.696]],"asks":[],"action":"update"}}
1651237306.8232052: {"channel":"orderbook","market":"FTT/BTC","type":"update","data":{"time":1651237306.6882584,"checksum":760413207,"bids":[],"asks":[],"action":"update"}}
1651237306.8421881: {"channel":"orderbook","market":"ETH/USDT","type":"update","data":{"time":1651237306.7155323,"checksum":443189559,"bids":[[2858.6,0.758]],"asks":[],"action":"update"}}
1651237306.8652086: {"channel":"orderbook","market":"BTC/TRY","type":"update","data":{"time":1651237306.740616,"checksum":1840591949,"bids":[],"asks":[],"action":"update"}}
1651237306.868334: {"channel":"orderbook","market":"ETH/USDT","type":"update","data":{"time":1651237306.7412403,"checksum":2144195008,"bids":[],"asks":[[2862.2,20.021]],"action":"update"}}
1651237306.8778055: {"channel":"orderbook","market":"SOL/USD","type":"update","data":{"time":1651237306.7490294,"checksum":504844792,"bids":[[95.6525,41.77],[95.38,0.0]],"asks":[[95.905,70.0]],"action":"update"}}
1651237306.8844745: {"channel":"orderbook","market":"ETH/USD","type":"update","data":{"time":1651237306.7518363,"checksum":919712336,"bids":[[2860.2,3.751],[2859.6,8.008],[2859.3,44.894],[2859.2,18.29],[2858.3,3.663],[2849.0,0.0]],"asks":[],"action":"update"}}
1651237306.902123: {"channel":"orderbook","market":"ETH/USDT","type":"update","data":{"time":1651237306.7669997,"checksum":4258935167,"bids":[[2860.4,8.494]],"asks":[],"action":"update"}}
1651237306.9043672: {"channel":"orderbook","market":"ETH/USD","type":"update","data":{"time":1651237306.773601,"checksum":3993509467,"bids":[[2860.0,10.083]],"asks":[[2860.7,0.162],[2862.8,1.326],[2864.3,0.349],[2872.7,0.0],[2872.8,0.0]],"action":"update"}}
1651237306.9193447: {"channel":"orderbook","market":"SHIB/USD","type":"update","data":{"time":1651237306.784206,"checksum":1904141023,"bids":[],"asks":[[0.00002262,75100000.0]],"action":"update"}}
1651237306.9309368: {"channel":"orderbook","market":"ETH/USD","type":"update","data":{"time":1651237306.7978663,"checksum":3941177080,"bids":[],"asks":[[2861.1,6.998],[2862.7,4.875]],"action":"update"}}
1651237306.9309864: {"channel":"orderbook","market":"SOL/USD","type":"update","data":{"time":1651237306.800734,"checksum":4184228460,"bids":[[95.7775,61.31],[95.7675,62.55]],"asks":[],"action":"update"}}
1651237306.9652092: {"channel":"orderbook","market":"SOL/USD","type":"update","data":{"time":1651237306.8284001,"checksum":1430532803,"bids":[[95.7825,105.32],[95.3825,0.0]],"asks":[],"action":"update"}}
1651237306.9652839: {"channel":"orderbook","market":"ETH/USD","type":"update","data":{"time":1651237306.8238842,"checksum":887784770,"bids":[[2860.1,8.077],[2859.9,17.412],[2857.6,3.369]],"asks":[],"action":"update"}}
1651237306.9653306: {"channel":"orderbook","market":"SHIB/USD","type":"update","data":{"time":1651237306.8332243,"checksum":1331028517,"bids":[],"asks":[[0.00002267,32200000.0]],"action":"update"}}
1651237306.9789517: {"channel":"orderbook","market":"SOL/USD","type":"update","data":{"time":1651237306.8493054,"checksum":517591243,"bids":[[95.8025,124.06]],"asks":[],"action":"update"}}
1651237306.9895217: {"channel":"orderbook","market":"ETH/USD","type":"update","data":{"time":1651237306.8561938,"checksum":4041684060,"bids":[[2858.4,2.123]],"asks":[[2861.0,5.2],[2861.1,1.748]],"action":"update"}}
1651237307.004312: {"channel":"orderbook","market":"ETH/USD","type":"update","data":{"time":1651237306.8732913,"checksum":2647372310,"bids":[[2856.1,0.541]],"asks":[],"action":"update"}}
1651237307.0151582: {"channel":"orderbook","market":"LTC/USDT","type":"update","data":{"time":1651237306.889415,"checksum":1778670624,"bids":[[100.515,0.0],[96.635,0.01]],"asks":[],"action":"update"}}
1651237307.0300605: {"channel":"orderbook","market":"WBTC/USD","type":"update","data":{"time":1651237306.893812,"checksum":869331473,"bids":[],"asks":[],"action":"update"}}
1651237307.033057: {"channel":"orderbook","market":"ETH/USDT","type":"update","data":{"time":1651237306.8916147,"checksum":2730850627,"bids":[[2859.4,24.327]],"asks":[],"action":"update"}}
1651237307.033103: {"channel":"orderbook","market":"SOL/USD","type":"update","data":{"time":1651237306.8996694,"checksum":3670047547,"bids":[],"asks":[[95.965,0.06],[96.3425,0.0]],"action":"update"}}
1651237307.0331326: {"channel":"orderbook","market":"ETH/USD","type":"update","data":{"time":1651237306.9034212,"checksum":3665701592,"bids":[],"asks":[[2861.0,3.45]],"action":"update"}}
1651237307.036015: {"channel":"orderbook","market":"WBTC/USD","type":"update","data":{"time":1651237306.9116983,"checksum":2184279905,"bids":[],"asks":[[38971.0,0.0],[44111.0,0.0001]],"action":"update"}}
1651237307.0460496: {"channel":"orderbook","market":"ETH/USDT","type":"update","data":{"time":1651237306.9151416,"checksum":2730850627,"bids":[],"asks":[],"action":"update"}}
1651237307.0714889: {"channel":"orderbook","market":"ETH/USDT","type":"update","data":{"time":1651237306.9424067,"checksum":1526919042,"bids":[[2859.5,10.386]],"asks":[],"action":"update"}}
1651237307.0860713: {"channel":"orderbook","market":"SOL/USD","type":"update","data":{"time":1651237306.9537961,"checksum":3914973770,"bids":[],"asks":[[95.91,0.03],[96.155,275.32],[96.3325,0.0],[96.3375,0.0]],"action":"update"}}
1651237307.095274: {"channel":"orderbook","market":"LTC/USDT","type":"update","data":{"time":1651237306.9664824,"checksum":290258179,"bids":[[100.49,75.32],[96.635,0.0]],"asks":[[100.64,6.15],[100.645,12.3],[103.96,0.0],[104.0,0.0]],"action":"update"}}
