1651237307.103382: {"channel":"orderbook","market":"ETH/USD","type":"update","data":{"time":1651237306.973544,"checksum":977512845,"bids":[],"asks":[[2860.8,0.003],[2862.3,0.351],[2872.6,0.0]],"action":"update"}}
1651237307.1078887: {"channel":"orderbook","market":"WBTC/USD","type":"update","data":{"time":1651237306.9755733,"checksum":344708201,"bids":[],"asks":[[38970.0,0.1137],[44111.0,0.0]],"action":"update"}}
1651237307.1090634: {"channel":"orderbook","market":"ETH/USDT","type":"update","data":{"time":1651237306.9842463,"checksum":849734959,"bids":[],"asks":[[2862.2,0.175]],"action":"update"}}
1651237307.1283245: {"channel":"orderbook","market":"ETH/USD","type":"update","data":{"time":1651237306.9978127,"checksum":2304772089,"bids":[],"asks":[[2862.3,1.031]],"action":"update"}}
1651237307.141495: {"channel":"orderbook","market":"LTC/USDT","type":"update","data":{"time":1651237307.0131783,"checksum":1047019050,"bids":[[99.235,0.0],[96.635,0.01]],"asks":[],"action":"update"}}
1651237307.1586673: {"channel":"orderbook","market":"ETH/USD","type":"update","data":{"time":1651237307.0247343,"checksum":3975790376,"bids":[[2859.9,17.37]],"asks":[[2864.1,3.057]],"action":"update"}}
1651237307.1587343: {"channel":"orderbook","market":"SOL/USD","type":"update","data":{"time":1651237307.02606,"checksum":1308799799,"bids":[],"asks":[[95.8475,96.9]],"action":"update"}}
1651237307.18314: {"channel":"orderbook","market":"ETH/USD","type":"update","data":{"time":1651237307.047747,"checksum":3947274405,"bids":[],"asks":[[2861.2,20.797]],"action":"update"}}
1651237307.1831741: {"channel":"orderbook","market":"SOL/USD","type":"update","data":{"time":1651237307.049209,"checksum":2936649155,"bids":[],"asks":[[95.9,233.9],[96.015,102.59],[96.33,0.0]],"action":"update"}}
1651237307.1980014: {"channel":"orderbook","market":"LTC/USDT","type":"update","data":{"time":1651237307.0671237,"checksum":3590409043,"bids":[[100.47,0.0],[96.55,0.23]],"asks":[],"action":"update"}}
1651237307.1980448: {"channel":"orderbook","market":"WBTC/USD","type":"update","data":{"time":1651237307.070867,"checksum":1797786893,"bids":[],"asks":[[38974.0,0.008],[44095.0,0.0]],"action":"update"}}
1651237307.2022805: {"channel":"orderbook","market":"ETH/USD","type":"update","data":{"time":1651237307.0759585,"checksum":1089630218,"bids":[[2860.0,10.125],[2859.0,3.286]],"asks":[[2861.1,6.998],[2862.3,1.348]],"action":"update"}}
1651237307.242393: {"channel":"orderbook","market":"ETH/USDT","type":"update","data":{"time":1651237307.0829425,"checksum":2412893070,"bids":[[2860.3,32.598],[2860.2,5.0]],"asks":[[2862.0,8.204],[2862.1,9.099]],"action":"update"}}
1651237307.2424715: {"channel":"orderbook","market":"ETH/USD","type":"update","data":{"time":1651237307.0979648,"checksum":2638253971,"bids":[[2859.0,3.42],[2855.2,4.006]],"asks":[[2863.0,25.941]],"action":"update"}}
1651237307.2425146: {"channel":"orderbook","market":"SOL/USD","type":"update","data":{"time":1651237307.1036682,"checksum":2186973046,"bids":[[95.67,12.61],[95.6375,24.64],[95.63,0.98]],"asks":[[95.8975,58.55],[96.0275,2.24],[96.3225,0.0],[96.3275,0.0]],"action":"update"}}
1651237307.253544: {"channel":"orderbook","market":"ETH/USDT","type":"update","data":{"time":1651237307.1241472,"checksum":1731684953,"bids":[[2859.7,8.292]],"asks":[[2861.7,19.913],[2861.8,15.872],[2862.1,4.087],[2862.8,1.636],[2882.4,0.0]],"action":"update"}}
1651237307.2535968: {"channel":"orderbook","market":"ETH/USD","type":"update","data":{"time":1651237307.1234953,"checksum":4023508731,"bids":[],"asks":[[2861.0,5.202],[2861.1,6.949],[2861.8,22.497]],"action":"update"}}
1651237307.2595417: {"channel":"orderbook","market":"SOL/USD","type":"update","data":{"time":1651237307.1335156,"checksum":1047240217,"bids":[[95.755,62.64],[95.385,0.0]],"asks":[],"action":"update"}}
1651237307.2727966: {"channel":"orderbook","market":"ETH/USDT","type":"update","data":{"time":1651237307.1443894,"checksum":372717911,"bids":[],"asks":[[2861.5,0.043],[2862.1,0.0]],"action":"update"}}
1651237307.2754312: {"channel":"orderbook","market":"ETH/USD","type":"update","data":{"time":1651237307.1471436,"checksum":2686396421,"bids":[[2859.3,21.859]],"asks":[],"action":"update"}}
1651237307.2754827: {"channel":"orderbook","market":"SHIB/USD","type":"update","data":{"time":1651237307.1434135,"checksum":262807933,"bids":[],"asks":[[0.00002266,424100000.0]],"action":"update"}}
1651237307.2970457: {"channel":"orderbook","market":"SOL/USD","type":"update","data":{"time":1651237307.1699812,"checksum":2143416602,"bids":[],"asks":[[95.9,128.59]],"action":"update"}}
1651237307.3038046: {"channel":"orderbook","market":"ETH/USD","type":"update","data":{"time":1651237307.174145,"checksum":2297759074,"bids":[[2860.5,7.682]],"asks":[[2862.9,8.262],[2864.8,24.512]],"action":"update"}}
1651237307.3129892: {"channel":"orderbook","market":"ETH/USDT","type":"update","data":{"time":1651237307.170777,"checksum":3513345536,"bids":[[2860.6,4.55]],"asks":[[2861.8,27.448]],"action":"update"}}
1651237307.3174832: {"channel":"orderbook","market":"LTC/USDT","type":"update","data":{"time":1651237307.1907187,"checksum":3590409043,"bids":[],"asks":[],"action":"update"}}
1651237307.321262: {"channel":"orderbook","market":"SOL/USD","type":"update","data":{"time":1651237307.1941166,"checksum":636453310,"bids":[[95.825,55.0],[95.6575,26.1],[95.39,0.0],[95.3875,0.0]],"asks":[],"action":"update"}}
1651237307.325621: {"channel":"orderbook","market":"ETH/USDT","type":"update","data":{"time":1651237307.1952484,"checksum":389354006,"bids":[[2860.3,12.824],[2859.3,0.515]],"asks":[[2861.1,6.92],[2861.2,0.0],[2861.8,11.576]],"action":"update"}}
1651237307.3465848: {"channel":"orderbook","market":"ETH/USDT","type":"update","data":{"time":1651237307.2189178,"checksum":136408128,"bids":[[2860.4,3.265]],"asks":[],"action":"update"}}
1651237307.3559208: {"channel":"orderbook","market":"ETH/USD","type":"update","data":{"time":1651237307.2228947,"checksum":2963441794,"bids":[],"asks":[[2863.0,0.183]],"action":"update"}}
1651237307.3560214: {"channel":"orderbook","market":"SOL/USD","type":"update","data":{"time":1651237307.2226872,"checksum":1403112829,"bids":[[95.825,0.0],[95.8225,0.0],[95.8125,0.0],[95.81,188.19],[95.39,1459.97],[95.3875,0.37],[95.385,50.0]],"asks":[[95.845,55.0],[95.91,0.0]],"action":"update"}}
1651237307.3685837: {"channel":"orderbook","market":"SHIB/USD","type":"update","data":{"time":1651237307.2379172,"checksum":262807933,"bids":[],"asks":[],"action":"update"}}
1651237307.3752909: {"channel":"orderbook","market":"ETH/USD","type":"update","data":{"time":1651237307.2476919,"checksum":939508396,"bids":[],"asks":[[2861.2,3.497],[2862.9,1.773],[2864.3,2.47],[2866.4,4.275]],"action":"update"}}
1651237307.3771632: {"channel":"orderbook","market":"SOL/USD","type":"update","data":{"time":1651237307.250197,"checksum":2733865066,"bids":[[95.81,68.19],[95.785,8.62],[95.385,0.0]],"asks":[],"action":"update"}}
1651237307.3978698: {"channel":"orderbook","market":"ETH/USD","type":"update","data":{"time":1651237307.2721899,"checksum":1417462317,"bids":[],"asks":[[2861.1,1.748]],"action":"update"}}
1651237307.399831: {"channel":"orderbook","market":"ETH/USDT","type":"update","data":{"time":1651237307.2698016,"checksum":2448426108,"bids":[[2860.6,2.5],[2859.8,10.416]],"asks":[],"action":"update"}}
1651237307.4325218: {"channel":"orderbook","market":"SOL/USD","type":"update","data":{"time":1651237307.3000557,"checksum":3823147995,"bids":[[95.8125,56.4],[95.7825,0.0],[95.6575,0.0],[95.385,50.0]],"asks":[],"action":"update"}}
1651237307.432571: {"channel":"orderbook","market":"ETH/USDT","type":"update","data":{"time":1651237307.2970312,"checksum":1439517071,"bids":[],"asks":[[2861.4,8.025],[2861.7,23.409]],"action":"update"}}
1651237307.4646204: {"channel":"orderbook","market":"ETH/USD","type":"update","data":{"time":1651237307.3234534,"checksum":2313142034,"bids":[[2860.5,4.232]],"asks":[[2862.0,12.18]],"action":"update"}}
1651237307.4646747: {"channel":"orderbook","market":"SOL/USD","type":"update","data":{"time":1651237307.3284812,"checksum":3431598478,"bids":[],"asks":[[95.8425,280.0],[95.91,105.3],[96.3175,0.0],[96.32,0.0]],"action":"update"}}
1651237307.478047: {"channel":"orderbook","market":"ETH/USD","type":"update","data":{"time":1651237307.3470683,"checksum":1153822252,"bids":[[2859.3,15.484]],"asks":[[2861.0,10.452]],"action":"update"}}
1651237307.4783974: {"channel":"orderbook","market":"SOL/USD","type":"update","data":{"time":1651237307.350964,"checksum":1795006439,"bids":[[95.685,8.62],[95.385,0.0]],"asks":[],"action":"update"}}
1651237307.4899094: {"channel":"orderbook","market":"ETH/USDT","type":"update","data":{"time":1651237307.350334,"checksum":2672751834,"bids":[[2859.8,3.496]],"asks":[],"action":"update"}}
1651237307.4917243: {"channel":"orderbook","market":"DAI/USD","type":"update","data":{"time":1651237307.358701,"checksum":280434518,"bids":[],"asks":[],"action":"update"}}
1651237307.5030317: {"channel":"orderbook","market":"ETH/USDT","type":"update","data":{"time":1651237307.3698797,"checksum":3942955866,"bids":[[2860.1,20.712],[2859.8,0.0]],"asks":[],"action":"update"}}
1651237307.5030792: {"channel":"orderbook","market":"ETH/USD","type":"update","data":{"time":1651237307.3741379,"checksum":419531809,"bids":[[2860.2,5.775],[2859.5,28.502],[2858.4,1.774]],"asks":[[2861.2,0.0],[2872.6,0.005]],"action":"update"}}
1651237307.5381863: {"channel":"orderbook","market":"SOL/USD","type":"update","data":{"time":1651237307.4055076,"checksum":3840093850,"bids":[],"asks":[[95.8475,0.0],[96.3175,0.19]],"action":"update"}}
1651237307.5524511: {"channel":"orderbook","market":"ETH/USD","type":"update","data":{"time":1651237307.4244754,"checksum":95238949,"bids":[[2859.9,20.866]],"asks":[[2861.0,8.7],[2861.4,8.928]],"action":"update"}}
1651237307.5817213: {"channel":"orderbook","market":"ETH/USD","type":"update","data":{"time":1651237307.448668,"checksum":1172342293,"bids":[[2858.0,3.06],[2855.4,0.012]],"asks":[[2861.4,9.277],[2861.5,5.937],[2863.7,1.254],[2864.1,1.016]],"action":"update"}}
1651237307.5817726: {"channel":"orderbook","market":"ETH/USDT","type":"update","data":{"time":1651237307.446563,"checksum":2928465531,"bids":[[2859.5,6.377]],"asks":[[2861.3,2.015],[2882.2,0.0]],"action":"update"}}
1651237307.5825713: {"channel":"orderbook","market":"SOL/USD","type":"update","data":{"time":1651237307.4521127,"checksum":2497713282,"bids":[[95.8125,0.0],[95.78,70.0],[95.385,50.0]],"asks":[],"action":"update"}}
1651237307.6116168: {"channel":"orderbook","market":"ETH/USD","type":"update","data":{"time":1651237307.474705,"checksum":4102553906,"bids":[[2859.7,24.399],[2858.9,26.161],[2854.6,0.001],[2849.1,0.0]],"asks":[[2861.0,3.45],[2867.5,0.174]],"action":"update"}}
1651237307.6125245: {"channel":"orderbook","market":"ETH/USDT","type":"update","data":{"time":1651237307.4796822,"checksum":920269673,"bids":[[2860.2,6.748],[2860.1,0.0],[2842.5,835.588]],"asks":[],"action":"update"}}
1651237307.627129: {"channel":"orderbook","market":"SOL/USD","type":"update","data":{"time":1651237307.4852304,"checksum":1653771277,"bids":[[95.81,38.85],[95.655,47.89]],"asks":[[95.84,55.0],[96.3175,0.0]],"action":"update"}}
1651237307.6271734: {"channel":"orderbook","market":"ETH/USD","type":"update","data":{"time":1651237307.4990566,"checksum":3378534304,"bids":[],"asks":[[2867.5,3.205]],"action":"update"}}
1651237307.6347458: {"channel":"orderbook","market":"USD/TRY","type":"update","data":{"time":1651237307.507521,"checksum":3407013395,"bids":[],"asks":[],"action":"update"}}
1651237307.6406195: {"channel":"orderbook","market":"ETH/USDT","type":"update","data":{"time":1651237307.5112276,"checksum":628676203,"bids":[[2859.6,22.99]],"asks":[],"action":"update"}}
1651237307.6499972: {"channel":"orderbook","market":"ETH/USD","type":"update","data":{"time":1651237307.522727,"checksum":1230589617,"bids":[[2854.7,7.41]],"asks":[[2861.2,5.25],[2872.6,0.0]],"action":"update"}}
1651237307.6624982: {"channel":"orderbook","market":"LTC/USDT","type":"update","data":{"time":1651237307.5272005,"checksum":1869798805,"bids":[[99.16,2.58],[96.55,0.0]],"asks":[],"action":"update"}}
1651237307.6893601: {"channel":"orderbook","market":"ETH/USD","type":"update","data":{"time":1651237307.5506818,"checksum":3097625691,"bids":[[2860.1,5.44],[2858.8,3.997],[2858.1,0.011]],"asks":[[2861.3,7.986]],"action":"update"}}
1651237307.6965666: {"channel":"orderbook","market":"SOL/USD","type":"update","data":{"time":1651237307.5671604,"checksum":3208523797,"bids":[[95.655,21.79]],"asks":[[95.8375,96.9],[96.315,0.0]],"action":"update"}}
1651237307.7041183: {"channel":"orderbook","market":"ETH/USD","type":"update","data":{"time":1651237307.5758226,"checksum":2426268043,"bids":[[2855.0,0.521]],"asks":[[2860.6,6.943],[2861.2,0.0],[2863.3,1.239],[2872.6,0.005]],"action":"update"}}
1651237307.7408116: {"channel":"orderbook","market":"ETH/USD","type":"update","data":{"time":1651237307.608489,"checksum":3779449007,"bids":[],"asks":[[2860.6,3.45],[2861.4,9.092]],"action":"update"}}
1651237307.7491379: {"channel":"orderbook","market":"WBTC/USD","type":"update","data":{"time":1651237307.6191173,"checksum":330337302,"bids":[[38916.0,0.0],[35587.0,0.0016]],"asks":[],"action":"update"}}
1651237307.7601252: {"channel":"orderbook","market":"ETH/USD","type":"update","data":{"time":1651237307.6282535,"checksum":3135256514,"bids":[],"asks":[[2860.8,5.253],[2861.2,2.003],[2872.6,0.0]],"action":"update"}}
1651237307.7981007: {"channel":"orderbook","market":"ETH/USD","type":"update","data":{"time":1651237307.656839,"checksum":2712724626,"bids":[[2859.9,17.37],[2857.5,4.37],[2849.3,0.0]],"asks":[[2861.5,2.441]],"action":"update"}}
1651237307.8042655: {"channel":"orderbook","market":"ETH/USDT","type":"update","data":{"time":1651237307.676942,"checksum":1102511811,"bids":[[2857.8,11.038],[2842.5,0.0]],"asks":[],"action":"update"}}
1651237307.810192: {"channel":"orderbook","market":"SOL/USD","type":"update","data":{"time":1651237307.670642,"checksum":3249363653,"bids":[[95.81,19.76],[95.8,169.64]],"asks":[[95.845,0.0],[95.865,0.0],[96.315,0.03],[96.3175,0.19]],"action":"update"}}
1651237307.8332264: {"channel":"orderbook","market":"ETH/USD","type":"update","data":{"time":1651237307.7027514,"checksum":989131575,"bids":[[2858.9,0.0],[2858.8,3.648],[2849.3,0.041]],"asks":[[2861.1,1.978]],"action":"update"}}
1651237307.85207: {"channel":"orderbook","market":"FTT/BTC","type":"update","data":{"time":1651237307.7165399,"checksum":760413207,"bids":[],"asks":[],"action":"update"}}
1651237307.8683581: {"channel":"orderbook","market":"SOL/USD","type":"update","data":{"time":1651237307.7252197,"checksum":2053568401,"bids":[[95.825,0.01],[95.81,0.33],[95.6775,0.0]],"asks":[[95.835,47.26],[95.91,0.0],[95.965,0.0],[96.01,0.0],[96.32,0.01],[96.3225,0.62]],"action":"update"}}
1651237307.8684537: {"channel":"orderbook","market":"ETH/USDT","type":"update","data":{"time":1651237307.7339816,"checksum":2664826248,"bids":[[2859.8,13.413],[2858.6,7.894],[2842.7,0.0]],"asks":[[2862.0,2.255]],"action":"update"}}
1651237307.8729508: {"channel":"orderbook","market":"ETH/USD","type":"update","data":{"time":1651237307.7199056,"checksum":837445017,"bids":[[2860.5,0.0],[2849.1,0.004]],"asks":[[2861.3,11.482]],"action":"update"}}
1651237307.8945928: {"channel":"orderbook","market":"WBTC/USD","type":"update","data":{"time":1651237307.7694433,"checksum":4032596662,"bids":[[38907.0,0.0193],[38878.0,0.0]],"asks":[],"action":"update"}}
1651237307.9020913: {"channel":"orderbook","market":"BTC/TRY","type":"update","data":{"time":1651237307.7749226,"checksum":1840591949,"bids":[],"asks":[],"action":"update"}}
1651237307.90212: {"channel":"orderbook","market":"ETH/USD","type":"update","data":{"time":1651237307.7741728,"checksum":973495144,"bids":[[2858.7,22.068],[2854.3,3.52],[2849.1,0.0]],"asks":[[2861.2,7.253],[2861.4,3.842],[2861.9,3.008],[2863.3,3.28]],"action":"update"}}
1651237307.9057503: {"channel":"orderbook","market":"ETH/USDT","type":"update","data":{"time":1651237307.778863,"checksum":715527225,"bids":[],"asks":[[2861.9,0.0],[2882.2,0.011]],"action":"update"}}
1651237307.9197102: {"channel":"orderbook","market":"ETH/USD","type":"update","data":{"time":1651237307.7923548,"checksum":386443820,"bids":[[2860.3,0.0],[2849.1,0.004]],"asks":[[2860.7,0.0],[2872.6,0.005]],"action":"update"}}
1651237307.9271572: {"channel":"orderbook","market":"WBTC/USD","type":"update","data":{"time":1651237307.8002505,"checksum":1306336592,"bids":[],"asks":[[39096.0,0.0],[44095.0,0.0005]],"action":"update"}}
1651237307.9538934: {"channel":"orderbook","market":"SOL/USD","type":"update","data":{"time":1651237307.8110914,"checksum":609057445,"bids":[[95.825,0.0],[95.8125,121.5],[95.81,0.0],[95.805,1.86],[95.7675,167.86],[95.76,277.21],[95.655,47.89],[95.3825,0.01]],"asks":[[95.8425,0.0],[95.845,70.0],[95.8575,7.27],[95.96,7.87],[96.3225,0.0]],"action":"update"}}
1651237307.9539764: {"channel":"orderbook","market":"WBTC/USD","type":"update","data":{"time":1651237307.8208072,"checksum":3554720861,"bids":[[38879.0,0.0],[35496.0,0.0001]],"asks":[],"action":"update"}}
1651237307.9559507: {"channel":"orderbook","market":"ETH/USD","type":"update","data":{"time":1651237307.8254247,"checksum":2978883426,"bids":[[2859.9,20.866]],"asks":[[2860.5,3.9],[2860.9,21.299],[2861.2,2.003],[2861.3,9.157],[2872.6,0.0]],"action":"update"}}
1651237307.9734848: {"channel":"orderbook","market":"ETH/USD","type":"update","data":{"time":1651237307.8444052,"checksum":3986068018,"bids":[],"asks":[[2860.5,40.9],[2860.6,5.55],[2867.1,3.259]],"action":"update"}}
1651237308.0110297: {"channel":"orderbook","market":"ETH/USD","type":"update","data":{"time":1651237307.8697314,"checksum":4204584070,"bids":[[2860.1,1.947],[2859.9,17.37],[2859.7,23.038],[2859.2,0.0],[2855.0,0.172],[2849.0,0.015]],"asks":[[2860.5,43.0],[2860.6,3.45]],"action":"update"}}
1651237308.0111191: {"channel":"orderbook","market":"ETH/USDT","type":"update","data":{"time":1651237307.8779225,"checksum":5562607,"bids":[[2860.6,0.0],[2842.7,0.018]],"asks":[],"action":"update"}}
1651237308.015098: {"channel":"orderbook","market":"SOL/USD","type":"update","data":{"time":1651237307.8817656,"checksum":4271221741,"bids":[[95.8125,117.95],[95.8,167.58],[95.7775,56.31],[95.7525,27.22],[95.655,21.79],[95.6275,0.16],[95.3825,0.0]],"asks":[[95.8325,207.54],[95.9025,0.0]],"action":"update"}}
1651237308.0205755: {"channel":"orderbook","market":"LTC/USDT","type":"update","data":{"time":1651237307.8932536,"checksum":3147086045,"bids":[[100.595,0.0],[96.55,0.23]],"asks":[[100.64,0.0],[100.645,0.0],[103.96,0.29],[104.0,0.01]],"action":"update"}}
1651237308.0369198: {"channel":"orderbook","market":"ETH/USD","type":"update","data":{"time":1651237307.894921,"checksum":2571138312,"bids":[[2860.2,3.751]],"asks":[[2860.5,49.13],[2860.9,3.997],[2861.0,0.0],[2861.3,14.407],[2861.7,49.659],[2862.5,0.085],[2865.1,1.948],[2872.6,0.005]],"action":"update"}}
1651237308.0369859: {"channel":"orderbook","market":"SHIB/USD","type":"update","data":{"time":1651237307.8888237,"checksum":539541447,"bids":[[0.00002261,18000000.0]],"asks":[],"action":"update"}}
1651237308.0370111: {"channel":"orderbook","market":"SOL/USD","type":"update","data":{"time":1651237307.9068794,"checksum":892272105,"bids":[[95.8,97.58]],"asks":[[95.835,117.26]],"action":"update"}}
1651237308.0370393: {"channel":"orderbook","market":"ETH/USDT","type":"update","data":{"time":1651237307.903073,"checksum":1856342008,"bids":[[2860.2,5.0]],"asks":[[2860.7,2.211],[2861.7,19.913]],"action":"update"}}
1651237308.0429819: {"channel":"orderbook","market":"LTC/USDT","type":"update","data":{"time":1651237307.9135711,"checksum":3617300717,"bids":[[100.54,0.34]],"asks":[[100.815,0.0],[104.02,0.28]],"action":"update"}}
1651237308.0615187: {"channel":"orderbook","market":"ETH/USDT","type":"update","data":{"time":1651237307.9268167,"checksum":4051550618,"bids":[[2860.4,5.765],[2859.6,15.997]],"asks":[[2861.6,5.853],[2882.2,0.0]],"action":"update"}}
1651237308.061598: {"channel":"orderbook","market":"WBTC/USD","type":"update","data":{"time":1651237307.9286094,"checksum":3018551141,"bids":[[38869.0,13.5598],[35496.0,0.0]],"asks":[],"action":"update"}}
1651237308.0616398: {"channel":"orderbook","market":"ETH/USD","type":"update","data":{"time":1651237307.9223511,"checksum":1929953532,"bids":[[2860.4,0.552],[2859.6,18.118]],"asks":[[2860.5,43.0],[2860.8,0.003],[2861.3,9.157],[2861.6,16.941]],"action":"update"}}
1651237308.0695722: {"channel":"orderbook","market":"LTC/USDT","type":"update","data":{"time":1651237307.9435232,"checksum":16337757,"bids":[],"asks":[[100.73,0.0],[104.085,0.69]],"action":"update"}}
1651237308.0813935: {"channel":"orderbook","market":"SOL/USD","type":"update","data":{"time":1651237307.9413378,"checksum":936078283,"bids":[[95.7675,62.55],[95.6875,93.81],[95.385,0.0]],"asks":[[95.8325,272.97],[95.835,47.26],[95.84,0.0],[95.905,175.31],[95.935,252.45],[95.9575,0.0],[96.3225,0.62],[96.3275,0.01]],"action":"update"}}
1651237308.0815122: {"channel":"orderbook","market":"ETH/USDT","type":"update","data":{"time":1651237307.9524438,"checksum":636708578,"bids":[[2858.2,0.182]],"asks":[[2861.4,3.496],[2862.8,0.73]],"action":"update"}}
1651237308.0878732: {"channel":"orderbook","market":"SHIB/USD","type":"update","data":{"time":1651237307.9535627,"checksum":1596308908,"bids":[[0.00002261,0.0],[0.0000216,58000000.0]],"asks":[],"action":"update"}}
1651237308.0939448: {"channel":"orderbook","market":"ETH/USD","type":"update","data":{"time":1651237307.9593015,"checksum":2124447138,"bids":[[2860.2,0.003],[2860.1,1.75],[2860.0,8.377],[2859.7,4.496],[2852.4,0.0],[2848.9,68.482]],"asks":[[2860.5,46.45],[2860.8,0.0],[2860.9,15.232],[2861.1,0.23],[2861.3,5.661],[2862.8,0.0],[2864.9,177.094],[2872.7,0.001],[2872.8,4.022]],"action":"update"}}
1651237308.1057208: {"channel":"orderbook","market":"FTT/BTC","type":"update","data":{"time":1651237307.9653718,"checksum":2536484892,"bids":[],"asks":[[0.0010096,13.5],[0.0010241,0.0]],"action":"update"}}
1651237308.1085382: {"channel":"orderbook","market":"ETH/USD","type":"update","data":{"time":1651237307.9782727,"checksum":1133847977,"bids":[[2859.9,11.709],[2856.0,3.148]],"asks":[],"action":"update"}}
1651237308.1248271: {"channel":"orderbook","market":"LTC/USDT","type":"update","data":{"time":1651237307.9932103,"checksum":2207243003,"bids":[[100.53,0.0],[96.5,0.06]],"asks":[[100.675,100.34]],"action":"update"}}
1651237308.1248913: {"channel":"orderbook","market":"SOL/USD","type":"update","data":{"time":1651237307.990852,"checksum":1628255737,"bids":[[95.8125,51.5],[95.805,0.0],[95.79,124.86],[95.385,50.0]],"asks":[[95.83,125.0],[95.8325,342.97],[95.955,0.06],[96.3225,0.0],[96.3275,0.0]],"action":"update"}}
1651237308.1273248: {"channel":"orderbook","market":"SHIB/USD","type":"update","data":{"time":1651237307.9978466,"checksum":74473573,"bids":[[0.00002256,102600000.0]],"asks":[[0.00002263,301500000.0]],"action":"update"}}
1651237308.1390002: {"channel":"orderbook","market":"SOL/USD","type":"update","data":{"time":1651237308.0105324,"checksum":3626930803,"bids":[],"asks":[[95.935,0.0],[96.3225,0.62]],"action":"update"}}
1651237308.1390572: {"channel":"orderbook","market":"ETH/USDT","type":"update","data":{"time":1651237308.0089157,"checksum":382789730,"bids":[[2860.4,3.265],[2860.3,8.295],[2859.9,0.0],[2859.4,5.0],[2859.3,0.0],[2842.5,835.588],[2842.2,0.001]],"asks":[[2860.5,2.095],[2861.4,0.0],[2862.4,0.182]],"action":"update"}}
1651237308.1650639: {"channel":"orderbook","market":"ETH/USD","type":"update","data":{"time":1651237308.027151,"checksum":2314612615,"bids":[[2859.9,11.468],[2858.8,0.523],[2856.0,2.148]],"asks":[[2861.6,13.467],[2864.1,0.001]],"action":"update"}}
1651237308.165114: {"channel":"orderbook","market":"SOL/USD","type":"update","data":{"time":1651237308.03795,"checksum":1042537572,"bids":[],"asks":[[95.9325,0.0],[96.3275,0.01]],"action":"update"}}
1651237308.1814966: {"channel":"orderbook","market":"LTC/USDT","type":"update","data":{"time":1651237308.043101,"checksum":2535821282,"bids":[[100.52,0.0],[99.505,0.0],[96.45,1.02],[96.43,0.03]],"asks":[],"action":"update"}}
1651237308.1815627: {"channel":"orderbook","market":"ETH/USD","type":"update","data":{"time":1651237308.0500183,"checksum":369754598,"bids":[[2859.0,0.625],[2858.7,0.0],[2858.3,2.104],[2848.7,0.04]],"asks":[[2862.7,4.371]],"action":"update"}}
1651237308.1930442: {"channel":"orderbook","market":"ETH/USDT","type":"update","data":{"time":1651237308.0532777,"checksum":3498396264,"bids":[[2859.6,11.988],[2857.6,4.735]],"asks":[[2860.7,12.857],[2861.3,0.0],[2861.5,14.743],[2862.0,1.963],[2882.2,0.011]],"action":"update"}}
1651237308.2048697: {"channel":"orderbook","market":"LTC/USDT","type":"update","data":{"time":1651237308.06876,"checksum":1970025296,"bids":[[100.59,11.31]],"asks":[],"action":"update"}}
1651237308.204926: {"channel":"orderbook","market":"SHIB/USD","type":"update","data":{"time":1651237308.0730577,"checksum":3012863586,"bids":[[0.0000226,233900000.0]],"asks":[],"action":"update"}}
1651237308.2069523: {"channel":"orderbook","market":"ETH/USD","type":"update","data":{"time":1651237308.0780816,"checksum":2985256436,"bids":[[2859.8,14.122],[2859.4,5.467],[2859.1,0.0],[2848.6,0.198]],"asks":[[2862.7,0.001],[2863.1,0.002],[2863.9,12.202]],"action":"update"}}
1651237308.218467: {"channel":"orderbook","market":"LTC/USDT","type":"update","data":{"time":1651237308.091493,"checksum":1501587671,"bids":[[100.535,0.0],[100.49,0.0],[96.4,792.77],[96.395,0.2]],"asks":[],"action":"update"}}
1651237308.2212057: {"channel":"orderbook","market":"SOL/USD","type":"update","data":{"time":1651237308.0929832,"checksum":3906574049,"bids":[[95.7925,0.0],[95.79,119.86],[95.7875,70.0],[95.755,0.0],[95.7525,0.0],[95.3825,0.01],[95.38,1.12]],"asks":[[95.8325,272.97],[95.845,132.25],[95.935,62.55],[96.0325,0.0],[96.145,0.0],[96.33,0.26]],"action":"update"}}
1651237308.2418883: {"channel":"orderbook","market":"ETH/USDT","type":"update","data":{"time":1651237308.094287,"checksum":1848020015,"bids":[[2860.4,0.314],[2860.3,2.386],[2859.8,0.0],[2859.5,0.292],[2842.0,2.155]],"asks":[[2860.9,11.985],[2861.0,10.94],[2861.1,11.449],[2861.5,0.043],[2863.0,0.967],[2882.2,0.0]],"action":"update"}}
1651237308.2419574: {"channel":"orderbook","market":"ETH/USD","type":"update","data":{"time":1651237308.101746,"checksum":3863885260,"bids":[[2859.4,8.963]],"asks":[],"action":"update"}}
1651237308.241985: {"channel":"orderbook","market":"SHIB/USD","type":"update","data":{"time":1651237308.1029396,"checksum":2684790185,"bids":[[0.00002257,386400000.0]],"asks":[[0.00002261,19700000.0],[0.00002374,0.0]],"action":"update"}}
1651237308.24378: {"channel":"orderbook","market":"SOL/USD","type":"update","data":{"time":1651237308.1110332,"checksum":1522540608,"bids":[[95.765,242.55],[95.38,0.0]],"asks":[[96.11,0.0],[96.3325,0.13]],"action":"update"}}
1651237308.2508337: {"channel":"orderbook","market":"SHIB/USD","type":"update","data":{"time":1651237308.122868,"checksum":811216801,"bids":[],"asks":[[0.00002261,39400000.0]],"action":"update"}}
1651237308.2580597: {"channel":"orderbook","market":"LTC/USDT","type":"update","data":{"time":1651237308.1274488,"checksum":852261590,"bids":[[100.59,0.0],[100.555,0.0],[96.32,0.31],[96.285,0.37]],"asks":[],"action":"update"}}
1651237308.2581282: {"channel":"orderbook","market":"ETH/USD","type":"update","data":{"time":1651237308.12719,"checksum":2389356580,"bids":[[2860.4,0.248],[2854.9,156.288]],"asks":[],"action":"update"}}
1651237308.2603395: {"channel":"orderbook","market":"ETH/USDT","type":"update","data":{"time":1651237308.122017,"checksum":128415891,"bids":[[2859.3,3.497],[2859.1,11.993],[2858.8,21.883],[2842.0,0.0]],"asks":[[2860.5,2.05],[2860.6,5.0],[2861.6,11.67],[2861.8,0.0]],"action":"update"}}
1651237308.2638507: {"channel":"orderbook","market":"SOL/USD","type":"update","data":{"time":1651237308.1346712,"checksum":850400815,"bids":[],"asks":[[95.905,70.0],[95.915,70.67],[95.9525,62.64],[96.0375,7.26],[96.3325,0.0]],"action":"update"}}
1651237308.2844472: {"channel":"orderbook","market":"SHIB/USD","type":"update","data":{"time":1651237308.1483428,"checksum":156706890,"bids":[[0.00002257,372900000.0]],"asks":[],"action":"update"}}
1651237308.2848508: {"channel":"orderbook","market":"ETH/USD","type":"update","data":{"time":1651237308.1534235,"checksum":3625801650,"bids":[[2859.3,21.145],[2859.1,19.983],[2858.8,19.408],[2857.6,2.495],[2848.6,0.0]],"asks":[[2867.1,9.259]],"action":"update"}}
1651237308.2849164: {"channel":"orderbook","market":"SOL/USD","type":"update","data":{"time":1651237308.1560097,"checksum":2712027362,"bids":[],"asks":[[95.8875,185.28]],"action":"update"}}
1651237308.3005195: {"channel":"orderbook","market":"ETH/USDT","type":"update","data":{"time":1651237308.1620648,"checksum":1929866696,"bids":[[2860.4,0.0],[2858.1,0.098]],"asks":[[2860.6,6.361],[2861.0,8.44],[2861.1,4.529],[2861.2,3.497],[2861.6,17.717],[2882.1,0.0]],"action":"update"}}
1651237308.301219: {"channel":"orderbook","market":"FTT/BTC","type":"update","data":{"time":1651237308.1716573,"checksum":1276019171,"bids":[],"asks":[[0.0010098,8.3],[0.0010108,53.8]],"action":"update"}}
1651237308.304308: {"channel":"orderbook","market":"LTC/USDT","type":"update","data":{"time":1651237308.1535723,"checksum":889599563,"bids":[[100.465,11.12],[100.405,34.95],[99.5,181.62]],"asks":[[100.695,75.32],[104.085,0.0]],"action":"update"}}
1651237308.3051543: {"channel":"orderbook","market":"SOL/USD","type":"update","data":{"time":1651237308.1809933,"checksum":3089992598,"bids":[[95.765,346.97]],"asks":[],"action":"update"}}
1651237308.310758: {"channel":"orderbook","market":"ETH/USD","type":"update","data":{"time":1651237308.1779501,"checksum":757118038,"bids":[[2854.5,6.221]],"asks":[[2862.0,16.55],[2867.1,3.259]],"action":"update"}}
1651237308.3157468: {"channel":"orderbook","market":"ETH/USDT","type":"update","data":{"time":1651237308.1859615,"checksum":1920442683,"bids":[[2860.0,13.301]],"asks":[[2860.4,2.744],[2860.5,4.05],[2861.0,6.691],[2863.0,1.065],[2882.0,0.0]],"action":"update"}}
1651237308.3372087: {"channel":"orderbook","market":"SHIB/USD","type":"update","data":{"time":1651237308.1805005,"checksum":3988807304,"bids":[[0.0000226,136800000.0],[0.00002258,209200000.0],[0.00002256,98000000.0],[0.00002253,500000.0]],"asks":[[0.00002262,105500000.0]],"action":"update"}}
1651237308.3372617: {"channel":"orderbook","market":"ETH/USD","type":"update","data":{"time":1651237308.2012887,"checksum":1860681272,"bids":[[2860.0,8.335],[2859.7,1.0],[2854.5,0.221]],"asks":[[2861.2,5.5]],"action":"update"}}
1651237308.3372946: {"channel":"orderbook","market":"SOL/USD","type":"update","data":{"time":1651237308.207408,"checksum":3781003908,"bids":[],"asks":[[96.0875,1643.63]],"action":"update"}}
1651237308.4256473: {"channel":"orderbook","market":"LTC/USDT","type":"update","data":{"time":1651237308.2205057,"checksum":3780651749,"bids":[[100.51,7.46],[100.47,58.43],[100.455,75.32],[100.36,35.15],[96.4,0.0],[96.395,0.0],[96.32,0.0],[96.285,0.0]],"asks":[[100.725,92.25]],"action":"update"}}
1651237308.4257388: {"channel":"orderbook","market":"ETH/USDT","type":"update","data":{"time":1651237308.2197611,"checksum":3278986911,"bids":[[2859.7,4.796],[2859.3,10.417]],"asks":[[2860.5,2.05],[2860.6,5.0],[2861.0,0.0],[2882.0,0.049]],"action":"update"}}
1651237308.4257946: {"channel":"orderbook","market":"ETH/USD","type":"update","data":{"time":1651237308.2270417,"checksum":2093128908,"bids":[[2858.4,4.899],[2854.9,154.232]],"asks":[[2861.3,8.786]],"action":"update"}}
1651237308.4258387: {"channel":"orderbook","market":"SOL/USD","type":"update","data":{"time":1651237308.232462,"checksum":2833872418,"bids":[[95.8125,0.0],[95.8075,51.5],[95.7775,61.31],[95.62,26.67]],"asks":[],"action":"update"}}
1651237308.425886: {"channel":"orderbook","market":"SHIB/USD","type":"update","data":{"time":1651237308.2360573,"checksum":1534379633,"bids":[[0.00002256,152600000.0]],"asks":[],"action":"update"}}
1651237308.4259217: {"channel":"orderbook","market":"ETH/USDT","type":"update","data":{"time":1651237308.2386205,"checksum":2917681654,"bids":[[2857.8,0.0],[2842.0,2.155]],"asks":[[2860.7,0.0],[2860.9,0.0],[2882.1,0.011],[2882.2,0.011]],"action":"update"}}
1651237308.4259753: {"channel":"orderbook","market":"LTC/USDT","type":"update","data":{"time":1651237308.2451093,"checksum":3273151418,"bids":[[100.515,85.0],[100.51,0.0],[100.405,15.55]],"asks":[[100.695,0.0],[101.695,0.0],[104.085,0.69],[104.16,0.03]],"action":"update"}}
1651237308.4260306: {"channel":"orderbook","market":"ETH/USD","type":"update","data":{"time":1651237308.2524536,"checksum":3626442926,"bids":[],"asks":[[2863.8,1.025]],"action":"update"}}
1651237308.4260776: {"channel":"orderbook","market":"SHIB/USD","type":"update","data":{"time":1651237308.2469451,"checksum":1534379633,"bids":[],"asks":[],"action":"update"}}
1651237308.426108: {"channel":"orderbook","market":"WBTC/USD","type":"update","data":{"time":1651237308.25922,"checksum":139668423,"bids":[[38846.0,0.0],[35496.0,0.0001]],"asks":[],"action":"update"}}
1651237308.4261465: {"channel":"orderbook","market":"SOL/USD","type":"update","data":{"time":1651237308.2611003,"checksum":1679160576,"bids":[[95.75,8.62]],"asks":[],"action":"update"}}
1651237308.42618: {"channel":"orderbook","market":"ETH/USDT","type":"update","data":{"time":1651237308.2626154,"checksum":3610508272,"bids":[],"asks":[[2860.8,3.497],[2882.2,0.0]],"action":"update"}}
1651237308.4262154: {"channel":"orderbook","market":"ETH/USD","type":"update","data":{"time":1651237308.2758582,"checksum":327304468,"bids":[],"asks":[[2868.6,0.0],[2872.9,0.003]],"action":"update"}}
1651237308.4262514: {"channel":"orderbook","market":"SOL/USD","type":"update","data":{"time":1651237308.280334,"checksum":2247064357,"bids":[],"asks":[[95.9675,0.0],[96.3325,0.13]],"action":"update"}}
1651237308.426288: {"channel":"orderbook","market":"ETH/USDT","type":"update","data":{"time":1651237308.2899148,"checksum":3510064011,"bids":[[2859.1,15.49]],"asks":[[2860.7,1.749],[2866.3,0.0]],"action":"update"}}
1651237308.4593306: {"channel":"orderbook","market":"LTC/USDT","type":"update","data":{"time":1651237308.3245091,"checksum":1625465225,"bids":[[100.545,50.13],[96.43,0.0]],"asks":[],"action":"update"}}
1651237308.4593847: {"channel":"orderbook","market":"ETH/USD","type":"update","data":{"time":1651237308.3256052,"checksum":1593633174,"bids":[],"asks":[[2861.2,2.003]],"action":"update"}}
1651237308.465055: {"channel":"orderbook","market":"SOL/USD","type":"update","data":{"time":1651237308.3381422,"checksum":3847694439,"bids":[],"asks":[[95.845,70.0]],"action":"update"}}
1651237308.4872186: {"channel":"orderbook","market":"ETH/USDT","type":"update","data":{"time":1651237308.340657,"checksum":1792967243,"bids":[[2860.1,2.119],[2842.0,0.0]],"asks":[[2860.4,4.05]],"action":"update"}}
1651237308.4872673: {"channel":"orderbook","market":"SOL/USD","type":"update","data":{"time":1651237308.35604,"checksum":1688692336,"bids":[],"asks":[[95.9,233.9],[96.2275,0.04]],"action":"update"}}
1651237308.4872937: {"channel":"orderbook","market":"ETH/USD","type":"update","data":{"time":1651237308.3529594,"checksum":2239906258,"bids":[[2859.7,0.0],[2848.6,0.198]],"asks":[[2861.3,5.661],[2861.6,12.167],[2861.8,3.493]],"action":"update"}}
1651237308.494072: {"channel":"orderbook","market":"ETH/USDT","type":"update","data":{"time":1651237308.3640606,"checksum":4269080311,"bids":[],"asks":[[2861.7,0.189]],"action":"update"}}
1651237308.510712: {"channel":"orderbook","market":"LTC/USDT","type":"update","data":{"time":1651237308.3742678,"checksum":2767791696,"bids":[],"asks":[[100.67,58.94],[101.55,22.8],[104.085,0.0],[104.16,0.0]],"action":"update"}}
1651237308.5107586: {"channel":"orderbook","market":"ETH/USD","type":"update","data":{"time":1651237308.3771725,"checksum":1320855989,"bids":[],"asks":[[2860.5,50.201]],"action":"update"}}
1651237308.515347: {"channel":"orderbook","market":"WBTC/USD","type":"update","data":{"time":1651237308.38411,"checksum":3597333277,"bids":[[38894.0,0.0],[35386.0,0.0017]],"asks":[],"action":"update"}}
1651237308.5154107: {"channel":"orderbook","market":"DAI/USD","type":"update","data":{"time":1651237308.3839502,"checksum":280434518,"bids":[],"asks":[],"action":"update"}}
1651237308.5154567: {"channel":"orderbook","market":"ETH/USDT","type":"update","data":{"time":1651237308.3881724,"checksum":686163532,"bids":[],"asks":[[2861.6,11.864],[2862.3,1.77],[2864.9,11.001],[2882.1,0.0]],"action":"update"}}
1651237308.5695117: {"channel":"orderbook","market":"SOL/USD","type":"update","data":{"time":1651237308.4089975,"checksum":3244420759,"bids":[],"asks":[[95.83,55.0],[95.9525,0.0],[96.05,0.52],[96.3375,0.29]],"action":"update"}}
1651237308.569582: {"channel":"orderbook","market":"ETH/USD","type":"update","data":{"time":1651237308.4268909,"checksum":69741816,"bids":[[2860.2,0.0],[2848.5,0.142]],"asks":[[2860.7,1.749],[2872.9,0.0]],"action":"update"}}
1651237308.56963: {"channel":"orderbook","market":"ETH/USDT","type":"update","data":{"time":1651237308.4375944,"checksum":1028261349,"bids":[],"asks":[[2861.5,4.475],[2863.2,0.0],[2882.1,0.011]],"action":"update"}}
1651237308.578161: {"channel":"orderbook","market":"ETH/USD","type":"update","data":{"time":1651237308.4518344,"checksum":3223684762,"bids":[[2859.1,23.48],[2858.1,0.36]],"asks":[[2860.8,3.497],[2862.4,29.558],[2872.8,0.0]],"action":"update"}}
1651237308.5915747: {"channel":"orderbook","market":"ETH/USDT","type":"update","data":{"time":1651237308.4649642,"checksum":683927664,"bids":[[2859.8,19.988],[2859.2,3.497],[2842.5,0.0],[2842.2,0.0]],"asks":[[2862.7,2.877]],"action":"update"}}
1651237308.5945663: {"channel":"orderbook","market":"SOL/USD","type":"update","data":{"time":1651237308.4632742,"checksum":1272217023,"bids":[[95.7275,137.66],[95.62,301.99],[95.3825,0.0]],"asks":[],"action":"update"}}
1651237308.6142: {"channel":"orderbook","market":"WBTC/USD","type":"update","data":{"time":1651237308.4714615,"checksum":1566635712,"bids":[[38876.0,0.0771],[35386.0,0.0]],"asks":[],"action":"update"}}
1651237308.6142592: {"channel":"orderbook","market":"ETH/USD","type":"update","data":{"time":1651237308.4758265,"checksum":1391189351,"bids":[[2858.6,17.823],[2858.1,0.011],[2848.5,0.0]],"asks":[[2862.4,27.999]],"action":"update"}}
1651237308.6143086: {"channel":"orderbook","market":"SOL/USD","type":"update","data":{"time":1651237308.479857,"checksum":804960338,"bids":[[95.75,71.26]],"asks":[],"action":"update"}}
1651237308.6154122: {"channel":"orderbook","market":"ETH/USDT","type":"update","data":{"time":1651237308.4883788,"checksum":1924679121,"bids":[[2859.2,0.0],[2842.5,835.588]],"asks":[[2861.2,4.693],[2861.9,19.975],[2882.1,0.0]],"action":"update"}}
1651237308.6324286: {"channel":"orderbook","market":"ETH/USD","type":"update","data":{"time":1651237308.5017633,"checksum":703233410,"bids":[[2859.2,3.497],[2848.6,0.0]],"asks":[[2860.9,3.997],[2862.0,36.403],[2862.3,8.746]],"action":"update"}}
1651237308.6405663: {"channel":"orderbook","market":"SOL/USD","type":"update","data":{"time":1651237308.5041728,"checksum":228479038,"bids":[[95.8075,31.82]],"asks":[],"action":"update"}}
1651237308.6445868: {"channel":"orderbook","market":"LTC/USDT","type":"update","data":{"time":1651237308.515842,"checksum":4221483686,"bids":[],"asks":[[100.675,0.34]],"action":"update"}}
1651237308.6547544: {"channel":"orderbook","market":"SHIB/USD","type":"update","data":{"time":1651237308.5229204,"checksum":3101908862,"bids":[],"asks":[[0.00002261,19700000.0]],"action":"update"}}
1651237308.6548035: {"channel":"orderbook","market":"ETH/USD","type":"update","data":{"time":1651237308.5258806,"checksum":4096973906,"bids":[[2857.2,2.642]],"asks":[[2861.1,3.355]],"action":"update"}}
1651237308.6559453: {"channel":"orderbook","market":"USD/TRY","type":"update","data":{"time":1651237308.5314074,"checksum":3407013395,"bids":[],"asks":[],"action":"update"}}
1651237308.6646304: {"channel":"orderbook","market":"SOL/USD","type":"update","data":{"time":1651237308.538066,"checksum":3734350768,"bids":[[95.62,275.89]],"asks":[],"action":"update"}}
1651237308.6814194: {"channel":"orderbook","market":"ETH/USD","type":"update","data":{"time":1651237308.550223,"checksum":4257588083,"bids":[],"asks":[[2861.9,9.1]],"action":"update"}}
1651237308.6941178: {"channel":"orderbook","market":"ETH/USDT","type":"update","data":{"time":1651237308.5628855,"checksum":676258159,"bids":[[2859.6,13.737]],"asks":[],"action":"update"}}
1651237308.704086: {"channel":"orderbook","market":"SOL/USD","type":"update","data":{"time":1651237308.5680299,"checksum":1259987477,"bids":[],"asks":[[95.95,104.33],[96.3375,0.0]],"action":"update"}}
1651237308.7041237: {"channel":"orderbook","market":"LTC/USDT","type":"update","data":{"time":1651237308.5723016,"checksum":3511106877,"bids":[],"asks":[[100.66,92.0],[104.02,0.0]],"action":"update"}}
1651237308.7041574: {"channel":"orderbook","market":"ETH/USD","type":"update","data":{"time":1651237308.574632,"checksum":2803362780,"bids":[],"asks":[[2863.8,0.01]],"action":"update"}}
1651237308.7202115: {"channel":"orderbook","market":"SOL/USD","type":"update","data":{"time":1651237308.5916455,"checksum":3355107014,"bids":[[95.81,71.16],[95.385,0.0]],"asks":[[95.925,314.26]],"action":"update"}}
1651237308.7285159: {"channel":"orderbook","market":"SHIB/USD","type":"update","data":{"time":1651237308.6001446,"checksum":1134349617,"bids":[[0.00002256,245600000.0]],"asks":[],"action":"update"}}
1651237308.7421207: {"channel":"orderbook","market":"ETH/USD","type":"update","data":{"time":1651237308.6017158,"checksum":985068192,"bids":[[2859.4,9.963],[2859.2,0.0],[2848.6,0.198]],"asks":[],"action":"update"}}
1651237308.7421772: {"channel":"orderbook","market":"SOL/USD","type":"update","data":{"time":1651237308.610487,"checksum":3307421790,"bids":[],"asks":[[95.9,128.59],[95.985,0.49],[96.3325,0.0]],"action":"update"}}
1651237308.7580805: {"channel":"orderbook","market":"ETH/USD","type":"update","data":{"time":1651237308.6256642,"checksum":3082308937,"bids":[],"asks":[[2860.9,0.0],[2872.8,4.022]],"action":"update"}}
1651237308.779751: {"channel":"orderbook","market":"ETH/USDT","type":"update","data":{"time":1651237308.640874,"checksum":769773769,"bids":[[2859.8,25.84]],"asks":[],"action":"update"}}
1651237308.7797956: {"channel":"orderbook","market":"LTC/USDT","type":"update","data":{"time":1651237308.6427803,"checksum":1662354213,"bids":[],"asks":[[100.61,2.01],[104.0,0.0]],"action":"update"}}
1651237308.781424: {"channel":"orderbook","market":"SHIB/USD","type":"update","data":{"time":1651237308.6480498,"checksum":3337533908,"bids":[[0.00002254,198000000.0]],"asks":[],"action":"update"}}
1651237308.7925568: {"channel":"orderbook","market":"ETH/USD","type":"update","data":{"time":1651237308.6515477,"checksum":2544918937,"bids":[],"asks":[[2860.8,20.799],[2861.0,3.497],[2867.2,4.198],[2872.8,0.0]],"action":"update"}}
1651237308.7926161: {"channel":"orderbook","market":"SOL/USD","type":"update","data":{"time":1651237308.653764,"checksum":617073018,"bids":[],"asks":[[95.9225,78.65],[96.025,0.03],[96.33,0.0]],"action":"update"}}
1651237308.7991683: {"channel":"orderbook","market":"SOL/USD","type":"update","data":{"time":1651237308.6735182,"checksum":3977787792,"bids":[[95.81,126.16]],"asks":[[96.02,138.24],[96.155,0.0],[96.33,0.26]],"action":"update"}}
1651237308.8133786: {"channel":"orderbook","market":"ETH/USD","type":"update","data":{"time":1651237308.679966,"checksum":273671370,"bids":[],"asks":[[2864.2,141.609]],"action":"update"}}
1651237308.847701: {"channel":"orderbook","market":"SOL/USD","type":"update","data":{"time":1651237308.706268,"checksum":3863802917,"bids":[],"asks":[[95.9925,31.2],[96.33,0.0]],"action":"update"}}
1651237308.8477542: {"channel":"orderbook","market":"ETH/USDT","type":"update","data":{"time":1651237308.7190495,"checksum":3837354111,"bids":[],"asks":[[2861.1,0.0],[2882.1,0.011]],"action":"update"}}
1651237308.8700888: {"channel":"orderbook","market":"SOL/USD","type":"update","data":{"time":1651237308.7242358,"checksum":616052118,"bids":[[95.8075,0.0],[95.385,50.0]],"asks":[],"action":"update"}}
1651237308.870144: {"channel":"orderbook","market":"FTT/BTC","type":"update","data":{"time":1651237308.7315598,"checksum":1276019171,"bids":[],"asks":[],"action":"update"}}
1651237308.8701763: {"channel":"orderbook","market":"BTC/TRY","type":"update","data":{"time":1651237308.741055,"checksum":806661441,"bids":[[580057.0,0.0]],"asks":[],"action":"update"}}
1651237308.8702118: {"channel":"orderbook","market":"ETH/USDT","type":"update","data":{"time":1651237308.7384636,"checksum":1401566233,"bids":[[2859.9,6.464],[2842.5,0.0]],"asks":[[2861.4,23.058],[2882.1,0.0]],"action":"update"}}
1651237308.8851027: {"channel":"orderbook","market":"SOL/USD","type":"update","data":{"time":1651237308.75567,"checksum":1839289040,"bids":[[95.81,71.16],[95.8075,51.5],[95.385,0.0]],"asks":[[95.935,125.19]],"action":"update"}}
1651237308.887265: {"channel":"orderbook","market":"ETH/USDT","type":"update","data":{"time":1651237308.7618074,"checksum":1403159283,"bids":[[2860.2,0.0],[2859.8,5.852],[2842.5,835.588]],"asks":[[2860.8,8.026]],"action":"update"}}
1651237308.8909228: {"channel":"orderbook","market":"LTC/USDT","type":"update","data":{"time":1651237308.7668338,"checksum":617006994,"bids":[],"asks":[[100.67,134.26]],"action":"update"}}
1651237308.9101336: {"channel":"orderbook","market":"BTC/TRY","type":"update","data":{"time":1651237308.7815971,"checksum":979955602,"bids":[[579803.0,1.454851]],"asks":[],"action":"update"}}
1651237308.910182: {"channel":"orderbook","market":"ETH/USD","type":"update","data":{"time":1651237308.7641563,"checksum":1289659751,"bids":[[2859.9,5.107]],"asks":[[2860.5,54.198],[2861.7,51.218],[2863.6,1.927],[2864.8,0.0],[2872.8,4.022]],"action":"update"}}
1651237308.917923: {"channel":"orderbook","market":"SOL/USD","type":"update","data":{"time":1651237308.7830858,"checksum":347725557,"bids":[[95.7525,27.22],[95.6475,26.1],[95.39,0.0],[95.3875,0.0]],"asks":[],"action":"update"}}
1651237308.9217818: {"channel":"orderbook","market":"ETH/USDT","type":"update","data":{"time":1651237308.789642,"checksum":2310788365,"bids":[[2860.3,0.0],[2859.9,0.0],[2859.1,8.497],[2842.2,0.001],[2842.0,2.155]],"asks":[],"action":"update"}}
1651237308.9305437: {"channel":"orderbook","market":"BTC/TRY","type":"update","data":{"time":1651237308.8072276,"checksum":1829248481,"bids":[],"asks":[[581426.0,1.875557]],"action":"update"}}
1651237308.9380143: {"channel":"orderbook","market":"ETH/USD","type":"update","data":{"time":1651237308.8070962,"checksum":1437916989,"bids":[[2860.4,0.0],[2860.1,0.0],[2860.0,5.252],[2859.1,3.497],[2858.0,3.409],[2855.0,11.211],[2848.5,0.142],[2848.4,0.059]],"asks":[[2860.4,5.0],[2861.2,2.352],[2872.8,0.0]],"action":"update"}}
1651237308.9482172: {"channel":"orderbook","market":"ETH/USDT","type":"update","data":{"time":1651237308.8197317,"checksum":1999979272,"bids":[[2858.8,2.354]],"asks":[[2860.3,5.0],[2882.0,0.0]],"action":"update"}}
1651237308.9613323: {"channel":"orderbook","market":"SOL/USD","type":"update","data":{"time":1651237308.82724,"checksum":3365824545,"bids":[],"asks":[[95.9025,105.31],[96.3275,0.0]],"action":"update"}}
1651237308.9613905: {"channel":"orderbook","market":"ETH/USDT","type":"update","data":{"time":1651237308.8353887,"checksum":1708277103,"bids":[],"asks":[[2860.4,2.05]],"action":"update"}}
1651237308.9783964: {"channel":"orderbook","market":"DAI/USD","type":"update","data":{"time":1651237308.841802,"checksum":2637841829,"bids":[[0.9998,11348.7]],"asks":[],"action":"update"}}
1651237308.978436: {"channel":"orderbook","market":"FTT/BTC","type":"update","data":{"time":1651237308.8433669,"checksum":2898572203,"bids":[[0.0010078,0.8]],"asks":[],"action":"update"}}
1651237308.9784627: {"channel":"orderbook","market":"SHIB/USD","type":"update","data":{"time":1651237308.8486538,"checksum":2616850145,"bids":[[0.00002259,133700000.0]],"asks":[],"action":"update"}}
1651237308.9786313: {"channel":"orderbook","market":"ETH/USD","type":"update","data":{"time":1651237308.8485854,"checksum":1960283463,"bids":[[2860.0,5.227],[2859.2,5.871],[2853.9,2.157],[2848.4,0.0]],"asks":[[2860.5,48.301]],"action":"update"}}
1651237309.0008264: {"channel":"orderbook","market":"LTC/USDT","type":"update","data":{"time":1651237308.8644574,"checksum":292512582,"bids":[[100.46,0.0],[96.43,0.03]],"asks":[],"action":"update"}}
1651237309.005983: {"channel":"orderbook","market":"ETH/USDT","type":"update","data":{"time":1651237308.8711097,"checksum":496153936,"bids":[[2859.5,0.0],[2858.7,0.0],[2841.6,0.333],[2841.5,62.202]],"asks":[[2860.2,2.0],[2860.5,0.0],[2861.4,0.0],[2882.0,0.049]],"action":"update"}}
1651237309.007951: {"channel":"orderbook","market":"SOL/USD","type":"update","data":{"time":1651237308.8761246,"checksum":347725557,"bids":[],"asks":[[95.9025,0.0],[96.3275,0.01]],"action":"update"}}
1651237309.023975: {"channel":"orderbook","market":"ETH/USDT","type":"update","data":{"time":1651237308.8892453,"checksum":3278303139,"bids":[[2860.0,6.809]],"asks":[],"action":"update"}}
1651237309.024031: {"channel":"orderbook","market":"SHIB/USD","type":"update","data":{"time":1651237308.8960757,"checksum":1626103975,"bids":[],"asks":[[0.00002264,414300000.0]],"action":"update"}}
1651237309.036192: {"channel":"orderbook","market":"SOL/USD","type":"update","data":{"time":1651237308.9056485,"checksum":782645781,"bids":[[95.7875,72.04]],"asks":[[96.035,220.63]],"action":"update"}}
1651237309.0444386: {"channel":"orderbook","market":"ETH/USD","type":"update","data":{"time":1651237308.8933854,"checksum":3525281098,"bids":[[2859.9,0.0],[2858.8,25.473],[2858.4,1.774],[2858.0,3.06],[2857.3,1.559]],"asks":[[2860.1,4.519],[2860.2,2.1],[2860.4,12.858],[2860.5,42.201],[2860.6,11.967],[2860.8,3.497],[2861.1,0.23],[2862.6,2.795],[2866.8,0.002],[2872.3,0.0],[2872.6,0.0],[2872.7,0.0]],"action":"update"}}
1651237309.0445325: {"channel":"orderbook","market":"ETH/USDT","type":"update","data":{"time":1651237308.9135983,"checksum":1691250172,"bids":[[2860.0,2.28],[2859.6,11.988]],"asks":[],"action":"update"}}
1651237309.044571: {"channel":"orderbook","market":"FTT/BTC","type":"update","data":{"time":1651237308.9147766,"checksum":1725794677,"bids":[[0.001008,29.3]],"asks":[[0.0010097,7.1]],"action":"update"}}
1651237309.0714595: {"channel":"orderbook","market":"ETH/USD","type":"update","data":{"time":1651237308.9362364,"checksum":830727428,"bids":[[2859.5,48.33],[2859.4,8.963],[2858.6,31.984]],"asks":[[2860.1,12.012],[2860.2,8.537],[2860.3,7.447],[2860.4,20.129],[2860.7,0.0],[2861.0,0.0],[2862.4,12.071],[2863.3,2.406],[2867.5,0.174],[2872.3,0.051]],"action":"update"}}
1651237309.0798576: {"channel":"orderbook","market":"ETH/USDT","type":"update","data":{"time":1651237308.9405584,"checksum":701758251,"bids":[[2860.1,0.0],[2859.2,19.802]],"asks":[[2860.7,0.0],[2861.2,1.196],[2882.1,0.011]],"action":"update"}}
1651237309.0825644: {"channel":"orderbook","market":"ETH/USD","type":"update","data":{"time":1651237308.9541676,"checksum":2954707840,"bids":[[2859.2,0.0],[2858.8,6.588],[2854.9,153.883],[2848.4,0.059]],"asks":[[2860.2,6.437],[2860.4,23.17]],"action":"update"}}
1651237309.0849514: {"channel":"orderbook","market":"SOL/USD","type":"update","data":{"time":1651237308.9571307,"checksum":1070853487,"bids":[[95.76,382.53]],"asks":[],"action":"update"}}
1651237309.0974553: {"channel":"orderbook","market":"WBTC/USD","type":"update","data":{"time":1651237308.9529347,"checksum":1566635712,"bids":[],"asks":[],"action":"update"}}
1651237309.1131527: {"channel":"orderbook","market":"ETH/USD","type":"update","data":{"time":1651237308.9791956,"checksum":3448595026,"bids":[[2859.8,7.045],[2859.5,33.834],[2859.3,5.661],[2858.9,6.372],[2858.6,14.161],[2857.9,0.0]],"asks":[[2860.2,5.256],[2860.4,34.282],[2860.5,38.751],[2861.7,36.055],[2862.3,1.348]],"action":"update"}}
1651237309.1393301: {"channel":"orderbook","market":"ETH/USDT","type":"update","data":{"time":1651237308.9971352,"checksum":1951355305,"bids":[[2860.0,0.301],[2858.5,2.851],[2857.2,0.002],[2841.5,0.0]],"asks":[[2860.2,4.145],[2860.7,2.011],[2882.1,0.0]],"action":"update"}}
1651237309.1441665: {"channel":"orderbook","market":"ETH/USD","type":"update","data":{"time":1651237309.0103598,"checksum":1137092904,"bids":[[2859.8,7.313],[2859.4,3.496],[2859.1,4.497],[2858.7,5.523],[2855.7,0.006],[2848.4,0.0]],"asks":[[2860.1,17.562],[2860.2,4.505],[2860.3,10.666],[2860.4,29.032],[2861.1,1.53],[2861.3,0.0],[2861.7,31.998],[2862.0,38.536],[2872.6,0.005]],"action":"update"}}
1651237309.1549876: {"channel":"orderbook","market":"ETH/USDT","type":"update","data":{"time":1651237309.0225434,"checksum":1750441963,"bids":[[2859.6,16.517],[2857.5,170.321],[2856.0,2.037]],"asks":[],"action":"update"}}
1651237309.1612937: {"channel":"orderbook","market":"WBTC/USD","type":"update","data":{"time":1651237309.0312388,"checksum":2897847326,"bids":[[38907.0,0.0],[35386.0,0.0017]],"asks":[],"action":"update"}}
1651237309.1613424: {"channel":"orderbook","market":"ETH/USD","type":"update","data":{"time":1651237309.0295649,"checksum":1982866826,"bids":[[2858.8,10.085]],"asks":[[2860.7,5.661],[2867.8,2.056],[2872.3,0.0],[2872.6,0.0]],"action":"update"}}
1651237309.1667826: {"channel":"orderbook","market":"SOL/USD","type":"update","data":{"time":1651237309.0296564,"checksum":1955001639,"bids":[[95.815,0.01],[95.3975,0.0]],"asks":[],"action":"update"}}
1651237309.1890514: {"channel":"orderbook","market":"ETH/USDT","type":"update","data":{"time":1651237309.053986,"checksum":857750231,"bids":[[2859.3,3.497]],"asks":[[2860.2,2.05],[2860.4,3.799],[2862.0,6.333]],"action":"update"}}
1651237309.189147: {"channel":"orderbook","market":"ETH/USD","type":"update","data":{"time":1651237309.0545588,"checksum":2386782852,"bids":[[2859.5,14.006],[2859.0,0.491]],"asks":[[2860.4,29.28],[2862.3,0.668]],"action":"update"}}
1651237309.2086878: {"channel":"orderbook","market":"ETH/USDT","type":"update","data":{"time":1651237309.0700524,"checksum":72431757,"bids":[[2859.2,34.183]],"asks":[[2860.1,2.0],[2882.0,0.0]],"action":"update"}}
1651237309.217049: {"channel":"orderbook","market":"ETH/USD","type":"update","data":{"time":1651237309.0800908,"checksum":2503660293,"bids":[[2860.0,5.45],[2859.6,10.11],[2859.4,0.0],[2859.0,0.174],[2858.9,0.0],[2848.4,0.059],[2848.2,0.701]],"asks":[[2862.3,0.351],[2862.8,0.874],[2872.1,0.0]],"action":"update"}}
1651237309.2264824: {"channel":"orderbook","market":"SHIB/USD","type":"update","data":{"time":1651237309.0856502,"checksum":2421906794,"bids":[[0.0000226,40200000.0],[0.00002258,204400000.0]],"asks":[[0.00002264,214500000.0]],"action":"update"}}
1651237309.22655: {"channel":"orderbook","market":"LTC/USDT","type":"update","data":{"time":1651237309.0960472,"checksum":4221257246,"bids":[[100.54,0.0],[100.42,37.97],[99.5,0.01],[96.4,792.77]],"asks":[[100.65,58.68],[100.675,0.0],[102.155,0.18]],"action":"update"}}
1651237309.2347603: {"channel":"orderbook","market":"ETH/USD","type":"update","data":{"time":1651237309.103191,"checksum":3394949951,"bids":[[2858.0,127.816]],"asks":[],"action":"update"}}
1651237309.2518759: {"channel":"orderbook","market":"ETH/USDT","type":"update","data":{"time":1651237309.123457,"checksum":555494444,"bids":[[2859.8,8.352],[2859.6,4.529],[2859.3,9.402]],"asks":[],"action":"update"}}
1651237309.258677: {"channel":"orderbook","market":"ETH/USD","type":"update","data":{"time":1651237309.127277,"checksum":617341709,"bids":[],"asks":[[2860.9,3.125],[2862.3,0.002],[2866.8,0.001],[2872.0,0.0]],"action":"update"}}
1651237309.2623997: {"channel":"orderbook","market":"SOL/USD","type":"update","data":{"time":1651237309.1210086,"checksum":473806103,"bids":[[95.6375,22.4],[95.63,0.01]],"asks":[[95.885,105.33],[96.0275,0.0],[96.15,275.32],[96.3275,0.0]],"action":"update"}}
1651237309.2624488: {"channel":"orderbook","market":"SHIB/USD","type":"update","data":{"time":1651237309.1331067,"checksum":1069081643,"bids":[[0.00002257,330400000.0],[0.00002256,191000000.0]],"asks":[[0.00002262,195500000.0],[0.00002263,367500000.0],[0.00002266,406100000.0]],"action":"update"}}
1651237309.2846096: {"channel":"orderbook","market":"ETH/USD","type":"update","data":{"time":1651237309.1532848,"checksum":1616238244,"bids":[[2859.5,9.622],[2858.6,0.0],[2848.1,0.101]],"asks":[[2861.2,0.349]],"action":"update"}}
1651237309.2861478: {"channel":"orderbook","market":"SHIB/USD","type":"update","data":{"time":1651237309.1544673,"checksum":3715202062,"bids":[],"asks":[[0.00002261,65900000.0],[0.00002263,326000000.0]],"action":"update"}}
1651237309.3062403: {"channel":"orderbook","market":"WBTC/USD","type":"update","data":{"time":1651237309.178297,"checksum":353555784,"bids":[[38877.0,0.0292],[35386.0,0.0]],"asks":[],"action":"update"}}
1651237309.3062997: {"channel":"orderbook","market":"ETH/USD","type":"update","data":{"time":1651237309.17774,"checksum":2747780440,"bids":[[2858.7,0.0],[2854.3,0.489],[2848.0,2.559]],"asks":[[2864.9,0.0],[2872.0,6.049]],"action":"update"}}
1651237309.307723: {"channel":"orderbook","market":"SHIB/USD","type":"update","data":{"time":1651237309.1791909,"checksum":1731836150,"bids":[[0.00002257,307300000.0]],"asks":[[0.00002261,46200000.0]],"action":"update"}}
1651237309.3088317: {"channel":"orderbook","market":"LTC/USDT","type":"update","data":{"time":1651237309.180035,"checksum":2547137335,"bids":[[100.42,17.2]],"asks":[],"action":"update"}}
1651237309.3104658: {"channel":"orderbook","market":"ETH/USDT","type":"update","data":{"time":1651237309.183015,"checksum":1537481917,"bids":[[2859.7,0.043],[2859.2,14.381],[2859.1,5.0],[2858.6,0.758]],"asks":[[2860.2,0.0],[2860.4,1.749],[2882.0,0.049]],"action":"update"}}
1651237309.3278115: {"channel":"orderbook","market":"SOL/USD","type":"update","data":{"time":1651237309.1989627,"checksum":1305239299,"bids":[[95.81,0.0],[95.3975,0.17]],"asks":[],"action":"update"}}
1651237309.327883: {"channel":"orderbook","market":"ETH/USD","type":"update","data":{"time":1651237309.2014265,"checksum":3844902269,"bids":[[2858.8,6.588]],"asks":[[2860.8,0.0],[2872.1,0.202]],"action":"update"}}
1651237309.3385296: {"channel":"orderbook","market":"SHIB/USD","type":"update","data":{"time":1651237309.2027984,"checksum":3023928818,"bids":[[0.00002257,215000000.0]],"asks":[],"action":"update"}}
1651237309.3443007: {"channel":"orderbook","market":"BTC/TRY","type":"update","data":{"time":1651237309.2197819,"checksum":2549750460,"bids":[],"asks":[[581678.0,0.0]],"action":"update"}}
1651237309.3531892: {"channel":"orderbook","market":"SOL/USD","type":"update","data":{"time":1651237309.2234797,"checksum":3502526151,"bids":[[95.8075,0.0],[95.39,1459.97]],"asks":[],"action":"update"}}
1651237309.3555784: {"channel":"orderbook","market":"ETH/USD","type":"update","data":{"time":1651237309.2264838,"checksum":3814119931,"bids":[[2855.2,0.006]],"asks":[],"action":"update"}}
1651237309.3820658: {"channel":"orderbook","market":"LTC/USDT","type":"update","data":{"time":1651237309.2466285,"checksum":1724088040,"bids":[[99.455,181.75],[96.4,0.0]],"asks":[],"action":"update"}}
1651237309.383944: {"channel":"orderbook","market":"ETH/USDT","type":"update","data":{"time":1651237309.2523673,"checksum":4185989734,"bids":[[2860.0,0.0],[2859.9,2.094],[2859.3,5.905],[2859.2,0.0],[2858.8,5.851],[2855.5,12.529],[2851.5,0.079],[2841.5,62.202]],"asks":[[2860.1,4.05],[2860.8,4.529]],"action":"update"}}
1651237309.3894653: {"channel":"orderbook","market":"SOL/USD","type":"update","data":{"time":1651237309.2525907,"checksum":3858643404,"bids":[[95.815,8.63],[95.7625,644.66]],"asks":[],"action":"update"}}
1651237309.3895342: {"channel":"orderbook","market":"ETH/USD","type":"update","data":{"time":1651237309.2555137,"checksum":1201849714,"bids":[[2860.0,5.422],[2858.9,19.157],[2858.2,3.125],[2858.1,25.375],[2854.2,7.855],[2848.1,0.0],[2848.0,0.0]],"asks":[],"action":"update"}}
1651237309.40272: {"channel":"orderbook","market":"SHIB/USD","type":"update","data":{"time":1651237309.2622578,"checksum":3246718137,"bids":[[0.0000226,18000000.0],[0.00002259,230300000.0]],"asks":[[0.00002261,69300000.0],[0.00002262,291900000.0],[0.00002264,246500000.0],[0.00002265,119700000.0]],"action":"update"}}
1651237309.4075222: {"channel":"orderbook","market":"SOL/USD","type":"update","data":{"time":1651237309.2802913,"checksum":1126976065,"bids":[[95.815,0.01]],"asks":[],"action":"update"}}
1651237309.408937: {"channel":"orderbook","market":"ETH/USD","type":"update","data":{"time":1651237309.280879,"checksum":3337001932,"bids":[],"asks":[[2866.9,3.312]],"action":"update"}}
1651237309.4100027: {"channel":"orderbook","market":"ETH/USDT","type":"update","data":{"time":1651237309.282004,"checksum":3771758579,"bids":[],"asks":[[2860.1,2.05],[2860.5,6.921],[2882.0,0.0]],"action":"update"}}
1651237309.4302166: {"channel":"orderbook","market":"ETH/USDT","type":"update","data":{"time":1651237309.3046474,"checksum":159736183,"bids":[],"asks":[[2861.2,0.0],[2882.0,0.049]],"action":"update"}}
1651237309.432356: {"channel":"orderbook","market":"ETH/USD","type":"update","data":{"time":1651237309.304875,"checksum":2346172616,"bids":[[2857.2,1.768]],"asks":[],"action":"update"}}
1651237309.4402356: {"channel":"orderbook","market":"SHIB/USD","type":"update","data":{"time":1651237309.313588,"checksum":1078169730,"bids":[[0.00002256,233500000.0],[0.00002239,4100000.0]],"asks":[[0.00002268,25000000.0]],"action":"update"}}
1651237309.4572635: {"channel":"orderbook","market":"ETH/USD","type":"update","data":{"time":1651237309.328245,"checksum":1702704763,"bids":[],"asks":[[2860.6,0.0],[2872.3,0.051]],"action":"update"}}
1651237309.45732: {"channel":"orderbook","market":"ETH/USDT","type":"update","data":{"time":1651237309.3285499,"checksum":1451705490,"bids":[],"asks":[[2860.5,0.0],[2882.1,0.011]],"action":"update"}}
1651237309.4981883: {"channel":"orderbook","market":"SOL/USD","type":"update","data":{"time":1651237309.36378,"checksum":3497487395,"bids":[],"asks":[[95.9275,0.0],[95.97,0.0],[96.3275,0.01],[96.33,0.26]],"action":"update"}}
1651237309.5158658: {"channel":"orderbook","market":"ETH/USDT","type":"update","data":{"time":1651237309.3845952,"checksum":3136557393,"bids":[[2858.6,20.117]],"asks":[],"action":"update"}}
1651237309.5427306: {"channel":"orderbook","market":"DAI/USD","type":"update","data":{"time":1651237309.413155,"checksum":2637841829,"bids":[],"asks":[],"action":"update"}}
1651237309.5822473: {"channel":"orderbook","market":"ETH/USDT","type":"update","data":{"time":1651237309.4532495,"checksum":3237755796,"bids":[],"asks":[[2861.9,0.0],[2882.2,0.011]],"action":"update"}}
1651237309.6317008: {"channel":"orderbook","market":"SHIB/USD","type":"update","data":{"time":1651237309.4997773,"checksum":1401890793,"bids":[[0.00002257,237200000.0]],"asks":[],"action":"update"}}
1651237309.6418939: {"channel":"orderbook","market":"ETH/USD","type":"update","data":{"time":1651237309.5071642,"checksum":4210496586,"bids":[[2859.0,4.964],[2858.2,28.735],[2857.0,5.279]],"asks":[[2860.3,14.77]],"action":"update"}}
1651237309.6437252: {"channel":"orderbook","market":"ETH/USDT","type":"update","data":{"time":1651237309.5135303,"checksum":251956271,"bids":[[2859.4,22.747],[2858.9,11.924],[2858.8,6.851]],"asks":[[2860.0,24.0],[2861.4,11.576],[2864.3,154.515],[2882.0,0.0],[2882.1,0.0],[2882.2,0.0]],"action":"update"}}
1651237309.66198: {"channel":"orderbook","market":"ETH/USD","type":"update","data":{"time":1651237309.5294578,"checksum":3848533189,"bids":[[2857.5,0.0],[2848.1,0.101]],"asks":[],"action":"update"}}
1651237309.6678576: {"channel":"orderbook","market":"WBTC/USD","type":"update","data":{"time":1651237309.5403776,"checksum":1352990957,"bids":[],"asks":[[38969.0,0.041],[44095.0,0.0]],"action":"update"}}
1651237309.670018: {"channel":"orderbook","market":"LTC/USDT","type":"update","data":{"time":1651237309.5452075,"checksum":3961441762,"bids":[[100.545,0.0],[96.4,792.77]],"asks":[[100.615,0.0],[100.625,0.0],[104.0,0.01],[104.02,0.28]],"action":"update"}}
1651237309.6871674: {"channel":"orderbook","market":"USD/TRY","type":"update","data":{"time":1651237309.5556471,"checksum":3407013395,"bids":[],"asks":[],"action":"update"}}
1651237309.6872208: {"channel":"orderbook","market":"SOL/USD","type":"update","data":{"time":1651237309.5419497,"checksum":3917738275,"bids":[],"asks":[[95.8275,0.01],[96.33,0.0]],"action":"update"}}
1651237309.687258: {"channel":"orderbook","market":"ETH/USDT","type":"update","data":{"time":1651237309.5550826,"checksum":988395174,"bids":[],"asks":[[2860.1,0.0],[2882.0,0.049]],"action":"update"}}
1651237309.6894867: {"channel":"orderbook","market":"ETH/USD","type":"update","data":{"time":1651237309.5558133,"checksum":3963278909,"bids":[[2858.1,5.525],[2854.2,7.506]],"asks":[[2860.1,14.112],[2860.3,11.32],[2865.7,0.0],[2872.6,0.005]],"action":"update"}}
1651237309.698567: {"channel":"orderbook","market":"FTT/BTC","type":"update","data":{"time":1651237309.5619957,"checksum":3452073527,"bids":[[0.0010089,0.0],[0.0009964,8.8]],"asks":[[0.0010096,0.0],[0.0010241,2879.9]],"action":"update"}}
1651237309.708372: {"channel":"orderbook","market":"WBTC/USD","type":"update","data":{"time":1651237309.5769475,"checksum":353555784,"bids":[],"asks":[[38969.0,0.0],[44095.0,0.0005]],"action":"update"}}
1651237309.7084203: {"channel":"orderbook","market":"ETH/USDT","type":"update","data":{"time":1651237309.580129,"checksum":3924811778,"bids":[[2859.8,2.5]],"asks":[[2865.0,0.056]],"action":"update"}}
1651237309.7084494: {"channel":"orderbook","market":"ETH/USD","type":"update","data":{"time":1651237309.579251,"checksum":4247242767,"bids":[[2859.8,0.268]],"asks":[[2862.0,18.683]],"action":"update"}}
1651237309.7411506: {"channel":"orderbook","market":"ETH/USD","type":"update","data":{"time":1651237309.6050603,"checksum":67692610,"bids":[[2858.2,22.39]],"asks":[[2863.6,0.912]],"action":"update"}}
1651237309.7411973: {"channel":"orderbook","market":"SOL/USD","type":"update","data":{"time":1651237309.6014879,"checksum":1837684861,"bids":[],"asks":[[95.83,0.0],[95.8325,70.0],[95.835,0.0],[96.0625,0.0],[96.33,0.26],[96.3325,0.13],[96.3375,0.29]],"action":"update"}}
1651237309.7530327: {"channel":"orderbook","market":"SOL/USD","type":"update","data":{"time":1651237309.6271346,"checksum":1792596976,"bids":[[95.74,0.0],[95.3875,0.37]],"asks":[[95.8375,0.0],[95.855,0.0],[96.3425,0.05],[96.3475,0.3]],"action":"update"}}
1651237309.7543678: {"channel":"orderbook","market":"ETH/USD","type":"update","data":{"time":1651237309.6277606,"checksum":1432959467,"bids":[[2855.0,0.172]],"asks":[],"action":"update"}}
1651237309.7666132: {"channel":"orderbook","market":"ETH/USDT","type":"update","data":{"time":1651237309.637963,"checksum":4215407634,"bids":[],"asks":[[2860.8,0.0],[2882.1,0.011]],"action":"update"}}
1651237309.7768574: {"channel":"orderbook","market":"SHIB/USD","type":"update","data":{"time":1651237309.650663,"checksum":2846224409,"bids":[[0.00002255,243900000.0]],"asks":[],"action":"update"}}
1651237309.7853792: {"channel":"orderbook","market":"SOL/USD","type":"update","data":{"time":1651237309.6505086,"checksum":2540344882,"bids":[[95.785,0.0],[95.765,104.42],[95.385,50.0]],"asks":[],"action":"update"}}
1651237309.7967136: {"channel":"orderbook","market":"ETH/USD","type":"update","data":{"time":1651237309.659256,"checksum":438986824,"bids":[[2859.0,19.496],[2858.3,23.804],[2857.8,16.081],[2857.6,0.374],[2857.2,2.117],[2856.9,0.013],[2854.3,11.413],[2853.8,3.251],[2848.1,0.0]],"asks":[[2860.8,14.747],[2861.4,4.522],[2861.8,3.842],[2861.9,30.475],[2866.9,3.313],[2872.6,0.0]],"action":"update"}}
1651237309.8080692: {"channel":"orderbook","market":"ETH/USDT","type":"update","data":{"time":1651237309.667266,"checksum":236640413,"bids":[[2854.5,26.191],[2851.4,0.044]],"asks":[[2860.0,24.248],[2860.5,4.529],[2860.9,19.826],[2882.0,0.0],[2882.1,0.0]],"action":"update"}}
1651237309.8155384: {"channel":"orderbook","market":"SHIB/USD","type":"update","data":{"time":1651237309.677184,"checksum":4222248745,"bids":[[0.00002257,337100000.0]],"asks":[[0.00002262,314100000.0]],"action":"update"}}
1651237309.8155887: {"channel":"orderbook","market":"WBTC/USD","type":"update","data":{"time":1651237309.6811566,"checksum":678525494,"bids":[[38946.0,0.041],[35496.0,0.0]],"asks":[],"action":"update"}}
1651237309.815629: {"channel":"orderbook","market":"SOL/USD","type":"update","data":{"time":1651237309.6772976,"checksum":2991002969,"bids":[[95.8075,51.5],[95.695,0.0],[95.6475,0.0],[95.3825,0.01]],"asks":[[95.8275,3.5]],"action":"update"}}
1651237309.8224814: {"channel":"orderbook","market":"ETH/USD","type":"update","data":{"time":1651237309.6818206,"checksum":938263843,"bids":[[2858.9,22.654],[2858.1,13.403],[2857.7,1.776],[2857.2,1.768],[2856.9,4.383],[2854.1,0.362],[2848.2,0.0]],"asks":[[2860.4,31.029],[2860.6,3.497],[2860.8,34.424],[2864.3,13.394],[2872.3,0.0]],"action":"update"}}
1651237309.8270192: {"channel":"orderbook","market":"ETH/USDT","type":"update","data":{"time":1651237309.6937478,"checksum":1626216399,"bids":[[2859.9,0.0],[2859.5,5.694]],"asks":[[2860.6,8.497],[2860.7,0.0],[2861.4,12.481],[2882.0,0.049]],"action":"update"}}
1651237309.835759: {"channel":"orderbook","market":"SHIB/USD","type":"update","data":{"time":1651237309.7001438,"checksum":277406981,"bids":[],"asks":[[0.00002266,363600000.0]],"action":"update"}}
1651237309.8357935: {"channel":"orderbook","market":"FTT/BTC","type":"update","data":{"time":1651237309.6935725,"checksum":2579701741,"bids":[],"asks":[[0.0010096,1.7],[0.0010241,0.0]],"action":"update"}}
1651237309.855892: {"channel":"orderbook","market":"SOL/USD","type":"update","data":{"time":1651237309.7237408,"checksum":1177145988,"bids":[[95.8075,0.0],[95.76,325.64],[95.38,1.12]],"asks":[[96.0,60.27]],"action":"update"}}
1651237309.8669314: {"channel":"orderbook","market":"ETH/USDT","type":"update","data":{"time":1651237309.7352855,"checksum":492178011,"bids":[],"asks":[[2860.0,22.248]],"action":"update"}}
1651237309.8692367: {"channel":"orderbook","market":"WBTC/USD","type":"update","data":{"time":1651237309.739123,"checksum":2164840588,"bids":[[38946.0,0.0],[38945.0,0.0],[35496.0,0.0001],[35386.0,0.0017]],"asks":[],"action":"update"}}
1651237309.881658: {"channel":"orderbook","market":"ETH/USD","type":"update","data":{"time":1651237309.7516367,"checksum":1047706041,"bids":[[2859.1,9.377],[2858.8,6.065],[2858.4,7.732],[2858.2,19.265],[2857.0,7.4],[2856.9,5.257],[2855.6,14.055]],"asks":[[2860.7,31.579],[2862.6,0.0],[2863.3,0.365],[2872.3,0.051]],"action":"update"}}
1651237309.8865733: {"channel":"orderbook","market":"FTT/BTC","type":"update","data":{"time":1651237309.7481134,"checksum":3452073527,"bids":[],"asks":[[0.0010096,0.0],[0.0010241,2879.9]],"action":"update"}}
1651237309.8912678: {"channel":"orderbook","market":"SOL/USD","type":"update","data":{"time":1651237309.7637262,"checksum":2423067039,"bids":[[95.8025,11.18],[95.7975,0.0],[95.7675,0.0],[95.7625,611.24],[95.7075,79.76],[95.3775,0.05]],"asks":[[95.825,96.9],[95.8325,201.39],[96.3475,0.0]],"action":"update"}}
1651237309.896905: {"channel":"orderbook","market":"ETH/USDT","type":"update","data":{"time":1651237309.766205,"checksum":3428451153,"bids":[],"asks":[[2859.9,0.461],[2882.0,0.0]],"action":"update"}}
1651237309.9176333: {"channel":"orderbook","market":"ETH/USD","type":"update","data":{"time":1651237309.787485,"checksum":2415337095,"bids":[[2860.0,0.0],[2859.8,0.0],[2857.7,0.0],[2848.2,0.701],[2848.1,0.101],[2848.0,2.559]],"asks":[[2860.4,30.781]],"action":"update"}}
1651237309.9301012: {"channel":"orderbook","market":"BTC/TRY","type":"update","data":{"time":1651237309.8010328,"checksum":2549750460,"bids":[],"asks":[],"action":"update"}}
1651237309.9301302: {"channel":"orderbook","market":"SOL/USD","type":"update","data":{"time":1651237309.797412,"checksum":616925271,"bids":[[95.8,0.0],[95.375,63.6]],"asks":[[95.885,0.0],[96.0425,26.1]],"action":"update"}}
1651237309.943015: {"channel":"orderbook","market":"ETH/USDT","type":"update","data":{"time":1651237309.8132808,"checksum":3364870348,"bids":[],"asks":[[2859.9,2.461],[2860.6,5.0],[2860.7,1.197],[2881.8,0.0]],"action":"update"}}
1651237309.9481328: {"channel":"orderbook","market":"SOL/USD","type":"update","data":{"time":1651237309.817262,"checksum":1839105076,"bids":[[95.7525,0.0],[95.3675,2.38]],"asks":[],"action":"update"}}
1651237309.9734228: {"channel":"orderbook","market":"SOL/USD","type":"update","data":{"time":1651237309.8392265,"checksum":3835872077,"bids":[[95.7875,2.04],[95.76,220.32]],"asks":[],"action":"update"}}
1651237309.98065: {"channel":"orderbook","market":"ETH/USD","type":"update","data":{"time":1651237309.845443,"checksum":3792329928,"bids":[[2854.1,0.013]],"asks":[[2860.1,6.112],[2860.4,19.669],[2860.5,3.751],[2861.4,4.173],[2861.7,27.253],[2862.1,10.685]],"action":"update"}}
1651237310.0014272: {"channel":"orderbook","market":"ETH/USDT","type":"update","data":{"time":1651237309.8639498,"checksum":699801169,"bids":[],"asks":[[2860.0,22.0],[2860.4,0.0],[2881.8,0.004]],"action":"update"}}
1651237310.0014756: {"channel":"orderbook","market":"ETH/USD","type":"update","data":{"time":1651237309.8632505,"checksum":4273700955,"bids":[[2859.5,0.0],[2859.1,5.88],[2847.9,459.852]],"asks":[[2860.6,0.0],[2861.7,17.895],[2872.6,0.005]],"action":"update"}}
1651237310.0230575: {"channel":"orderbook","market":"ETH/USD","type":"update","data":{"time":1651237309.8912222,"checksum":3936131036,"bids":[[2858.2,0.0],[2847.8,0.001]],"asks":[[2860.4,9.357],[2861.6,5.981],[2862.0,13.263]],"action":"update"}}
1651237310.0259273: {"channel":"orderbook","market":"SOL/USD","type":"update","data":{"time":1651237309.8919485,"checksum":1198411345,"bids":[[95.7775,56.31],[95.7625,11.1],[95.76,116.01],[95.75,8.62]],"asks":[[95.8275,0.01],[95.8875,115.28],[95.915,39.37],[95.935,62.55],[95.9725,116.01]],"action":"update"}}
1651237310.030333: {"channel":"orderbook","market":"USD/TRY","type":"update","data":{"time":1651237309.9065962,"checksum":3438925253,"bids":[],"asks":[[15.8807,0.0]],"action":"update"}}
1651237310.0412517: {"channel":"orderbook","market":"SOL/USD","type":"update","data":{"time":1651237309.9152153,"checksum":1591256957,"bids":[[95.8025,0.0],[95.365,0.03]],"asks":[[95.925,61.81]],"action":"update"}}
1651237310.0447373: {"channel":"orderbook","market":"ETH/USD","type":"update","data":{"time":1651237309.9176147,"checksum":3782209602,"bids":[[2858.3,16.617]],"asks":[[2860.7,14.276],[2861.9,24.383]],"action":"update"}}
1651237310.0675826: {"channel":"orderbook","market":"ETH/USDT","type":"update","data":{"time":1651237309.9351826,"checksum":1961657565,"bids":[[2855.5,1.49]],"asks":[[2860.6,0.0],[2882.0,0.049]],"action":"update"}}
1651237310.0676622: {"channel":"orderbook","market":"SOL/USD","type":"update","data":{"time":1651237309.9385889,"checksum":3370023758,"bids":[[95.7875,0.0],[95.3625,0.44]],"asks":[[95.9225,0.0],[95.925,7.26],[96.3475,0.3]],"action":"update"}}
1651237310.076063: {"channel":"orderbook","market":"ETH/USD","type":"update","data":{"time":1651237309.9399805,"checksum":584255471,"bids":[[2858.3,2.104],[2850.1,0.0],[2847.6,0.013]],"asks":[[2860.3,7.216],[2862.1,3.555]],"action":"update"}}
1651237310.1114967: {"channel":"orderbook","market":"SOL/USD","type":"update","data":{"time":1651237309.9667196,"checksum":695080764,"bids":[],"asks":[[95.915,0.0],[96.35,0.33]],"action":"update"}}
1651237310.111544: {"channel":"orderbook","market":"ETH/USD","type":"update","data":{"time":1651237309.9697843,"checksum":1875709585,"bids":[[2859.6,0.0],[2858.4,1.774],[2847.5,0.127]],"asks":[[2861.7,2.774],[2862.9,0.0],[2872.7,0.001]],"action":"update"}}
1651237310.1173763: {"channel":"orderbook","market":"ETH/USDT","type":"update","data":{"time":1651237309.9593985,"checksum":1961657565,"bids":[],"asks":[],"action":"update"}}
1651237310.1214635: {"channel":"orderbook","market":"WBTC/USD","type":"update","data":{"time":1651237309.9861577,"checksum":2164840588,"bids":[],"asks":[],"action":"update"}}
1651237310.1462066: {"channel":"orderbook","market":"ETH/USD","type":"update","data":{"time":1651237310.0151398,"checksum":1764541220,"bids":[],"asks":[[2861.1,0.23],[2861.6,0.0],[2872.8,4.022]],"action":"update"}}
1651237310.161654: {"channel":"orderbook","market":"ETH/USDT","type":"update","data":{"time":1651237310.0279717,"checksum":4105575383,"bids":[[2858.8,5.851]],"asks":[],"action":"update"}}
1651237310.1708486: {"channel":"orderbook","market":"ETH/USD","type":"update","data":{"time":1651237310.0409563,"checksum":2870782696,"bids":[[2859.2,7.541],[2859.1,12.858],[2855.0,1.172],[2847.5,0.0]],"asks":[[2859.7,2.1],[2859.8,1.9],[2859.9,3.8],[2860.0,35.0],[2860.6,7.894],[2861.5,0.0],[2861.8,11.468],[2861.9,3.008],[2862.2,0.0],[2863.4,4.546],[2872.6,0.0],[2872.7,0.0],[2872.8,0.0]],"action":"update"}}
1651237310.1711082: {"channel":"orderbook","market":"SOL/USD","type":"update","data":{"time":1651237310.041183,"checksum":3344842110,"bids":[[95.815,0.0],[95.7725,70.0],[95.7675,91.55],[95.6625,10.86],[95.365,0.0],[95.3625,0.0]],"asks":[[95.8425,67.57],[95.8775,105.34],[95.97,65.89],[96.3425,0.0],[96.3475,0.0],[96.35,0.0]],"action":"update"}}
1651237310.179159: {"channel":"orderbook","market":"SHIB/USD","type":"update","data":{"time":1651237310.050668,"checksum":1034167444,"bids":[],"asks":[[0.00002265,162200000.0]],"action":"update"}}
1651237310.2084382: {"channel":"orderbook","market":"ETH/USDT","type":"update","data":{"time":1651237310.060733,"checksum":639229926,"bids":[[2859.7,0.0],[2858.1,0.0],[2841.4,0.012],[2841.3,1174.404]],"asks":[[2860.7,19.074],[2860.8,4.965],[2861.5,4.432],[2863.0,0.967],[2882.0,0.0]],"action":"update"}}
1651237310.224757: {"channel":"orderbook","market":"WBTC/USD","type":"update","data":{"time":1651237310.0952897,"checksum":3443677836,"bids":[],"asks":[[38996.0,11.5528],[44095.0,0.0]],"action":"update"}}
1651237310.2329648: {"channel":"orderbook","market":"ETH/USD","type":"update","data":{"time":1651237310.0856397,"checksum":1091469940,"bids":[[2859.5,1.9],[2858.4,21.134],[2858.2,46.257],[2854.0,11.354],[2848.6,0.515],[2847.8,0.0],[2847.6,0.0]],"asks":[[2859.8,0.0],[2859.9,9.9],[2860.1,6.045],[2860.3,25.733],[2860.5,4.1],[2860.7,30.957],[2862.1,0.001],[2864.1,27.778],[2871.0,0.32],[2872.6,0.005]],"action":"update"}}
1651237310.2447567: {"channel":"orderbook","market":"SHIB/USD","type":"update","data":{"time":1651237310.111536,"checksum":804393621,"bids":[],"asks":[[0.00002263,331200000.0]],"action":"update"}}
1651237310.2503717: {"channel":"orderbook","market":"LTC/USDT","type":"update","data":{"time":1651237310.1186304,"checksum":1596168287,"bids":[[100.52,12.0],[100.265,75.08],[96.4,0.0]],"asks":[[100.85,313.76]],"action":"update"}}
1651237310.2617924: {"channel":"orderbook","market":"ETH/USDT","type":"update","data":{"time":1651237310.1157067,"checksum":1499028472,"bids":[[2859.4,5.0],[2858.9,15.421],[2858.7,6.993],[2858.6,23.614],[2857.5,181.36],[2841.3,0.0]],"asks":[[2860.3,8.498],[2860.7,1.197],[2860.8,24.509],[2864.1,185.899],[2865.1,0.0]],"action":"update"}}
1651237310.2619123: {"channel":"orderbook","market":"ETH/USD","type":"update","data":{"time":1651237310.1250553,"checksum":997096589,"bids":[[2859.5,3.787],[2859.4,2.1],[2859.3,7.549],[2859.2,3.472],[2859.1,11.858],[2859.0,4.964],[2858.5,3.505],[2856.9,5.249],[2854.7,4.375],[2854.0,11.005],[2848.6,0.649],[2847.9,0.0]],"asks":[[2860.3,29.231],[2860.4,9.109],[2860.6,0.0],[2860.8,19.677],[2861.6,7.067],[2861.8,3.842],[2863.5,147.793],[2864.0,2.445],[2864.1,35.405]],"action":"update"}}
1651237310.2879272: {"channel":"orderbook","market":"SOL/USD","type":"update","data":{"time":1651237310.1478553,"checksum":3904863508,"bids":[[95.7975,51.5],[95.745,62.55],[95.7375,33.42],[95.7325,600.14],[95.7275,138.63],[95.685,34.72],[95.38,0.0],[95.3775,0.0],[95.375,0.0],[95.3675,0.0]],"asks":[[95.8225,70.0],[95.8425,0.0],[95.855,142.81],[95.86,70.0],[95.8975,92.1],[95.9075,253.14],[95.945,600.14],[96.3325,0.0],[96.3375,0.0]],"action":"update"}}
1651237310.2880907: {"channel":"orderbook","market":"SHIB/USD","type":"update","data":{"time":1651237310.1548114,"checksum":1675290879,"bids":[],"asks":[[0.00002261,87300000.0]],"action":"update"}}
1651237310.2926452: {"channel":"orderbook","market":"WBTC/USD","type":"update","data":{"time":1651237310.1616457,"checksum":3196032477,"bids":[[38897.0,0.0193],[35386.0,0.0]],"asks":[],"action":"update"}}
1651237310.3068998: {"channel":"orderbook","market":"ETH/USD","type":"update","data":{"time":1651237310.1642888,"checksum":3854338638,"bids":[[2859.5,0.0],[2859.4,11.851],[2859.3,17.161],[2859.1,6.978],[2858.3,12.705],[2858.1,5.525],[2857.9,3.125]],"asks":[[2859.9,0.0],[2860.1,3.493],[2860.6,17.303],[2860.7,41.848],[2863.9,2.507],[2864.0,9.395],[2864.1,7.628],[2864.8,4.0],[2872.6,0.0]],"action":"update"}}
1651237310.3106039: {"channel":"orderbook","market":"USD/TRY","type":"update","data":{"time":1651237310.1794584,"checksum":1933757672,"bids":[],"asks":[[15.5841,2106.0]],"action":"update"}}
1651237310.31131: {"channel":"orderbook","market":"ETH/USDT","type":"update","data":{"time":1651237310.181637,"checksum":826550082,"bids":[[2859.8,0.057],[2859.5,0.0],[2859.2,5.852],[2858.3,0.175],[2841.4,0.0]],"asks":[[2860.0,23.749],[2860.6,6.921],[2881.8,0.0]],"action":"update"}}
1651237310.3171005: {"channel":"orderbook","market":"ETH/USD","type":"update","data":{"time":1651237310.186398,"checksum":2873525473,"bids":[[2853.8,3.6]],"asks":[[2860.2,13.449],[2860.6,0.0],[2872.6,0.005]],"action":"update"}}
1651237310.3370302: {"channel":"orderbook","market":"SOL/USD","type":"update","data":{"time":1651237310.2042243,"checksum":2029050165,"bids":[[95.7975,60.12],[95.685,8.62]],"asks":[],"action":"update"}}
1651237310.339109: {"channel":"orderbook","market":"ETH/USD","type":"update","data":{"time":1651237310.2116342,"checksum":2060698401,"bids":[[2859.4,3.751],[2858.7,3.498],[2853.8,3.251],[2848.0,0.0]],"asks":[[2859.7,0.0],[2863.4,29.149],[2864.0,2.445],[2864.3,13.045],[2872.7,0.001]],"action":"update"}}
1651237310.350079: {"channel":"orderbook","market":"SOL/USD","type":"update","data":{"time":1651237310.2205594,"checksum":1817660793,"bids":[[95.7975,51.5],[95.62,0.57]],"asks":[[95.9025,33.42],[95.905,133.28],[96.33,0.0]],"action":"update"}}
1651237310.3690484: {"channel":"orderbook","market":"ETH/USDT","type":"update","data":{"time":1651237310.223801,"checksum":953159525,"bids":[[2859.0,3.866]],"asks":[[2860.5,8.026]],"action":"update"}}
1651237310.3691025: {"channel":"orderbook","market":"LTC/USDT","type":"update","data":{"time":1651237310.2351165,"checksum":1967215462,"bids":[[100.395,26.0],[96.43,0.0]],"asks":[],"action":"update"}}
1651237310.3806393: {"channel":"orderbook","market":"SOL/USD","type":"update","data":{"time":1651237310.2462134,"checksum":3146868744,"bids":[[95.7425,62.64],[95.3825,0.0]],"asks":[[95.8775,0.0],[96.33,0.26]],"action":"update"}}
1651237310.380703: {"channel":"orderbook","market":"ETH/USD","type":"update","data":{"time":1651237310.2417693,"checksum":1081270198,"bids":[[2859.6,5.875],[2849.1,4.545],[2848.1,0.0]],"asks":[[2864.1,0.001]],"action":"update"}}
1651237310.3997025: {"channel":"orderbook","market":"LTC/USDT","type":"update","data":{"time":1651237310.2595124,"checksum":1967215462,"bids":[],"asks":[],"action":"update"}}
1651237310.3997374: {"channel":"orderbook","market":"ETH/USDT","type":"update","data":{"time":1651237310.2528028,"checksum":938059432,"bids":[],"asks":[[2860.6,0.0],[2881.8,0.004]],"action":"update"}}
1651237310.40261: {"channel":"orderbook","market":"ETH/USD","type":"update","data":{"time":1651237310.2706666,"checksum":4074731535,"bids":[[2858.3,14.481],[2858.2,32.339]],"asks":[],"action":"update"}}
1651237310.4026546: {"channel":"orderbook","market":"SOL/USD","type":"update","data":{"time":1651237310.273523,"checksum":604104017,"bids":[],"asks":[[95.9325,62.64],[96.33,0.0]],"action":"update"}}
1651237310.4221075: {"channel":"orderbook","market":"SHIB/USD","type":"update","data":{"time":1651237310.2790365,"checksum":1675290879,"bids":[],"asks":[],"action":"update"}}
1651237310.4221532: {"channel":"orderbook","market":"ETH/USD","type":"update","data":{"time":1651237310.2898102,"checksum":2369668608,"bids":[[2859.6,6.188],[2858.8,7.065],[2858.6,14.532],[2848.2,0.0]],"asks":[[2859.8,2.1],[2860.7,56.148],[2861.3,1.773],[2862.0,35.067],[2872.6,0.0],[2872.7,0.0]],"action":"update"}}
1651237310.4222312: {"channel":"orderbook","market":"SOL/USD","type":"update","data":{"time":1651237310.2956812,"checksum":1411292315,"bids":[[95.7475,105.35],[95.6375,48.5],[95.385,0.0]],"asks":[],"action":"update"}}
1651237310.4544191: {"channel":"orderbook","market":"ETH/USD","type":"update","data":{"time":1651237310.3204072,"checksum":2689581974,"bids":[[2859.6,4.213],[2859.5,4.0],[2856.7,0.043],[2848.4,0.0]],"asks":[[2859.8,0.0],[2859.9,2.0],[2864.3,10.924]],"action":"update"}}
1651237310.4754894: {"channel":"orderbook","market":"ETH/USD","type":"update","data":{"time":1651237310.3414068,"checksum":495553232,"bids":[[2859.6,2.313],[2859.5,0.0],[2848.4,0.059]],"asks":[[2859.9,5.7],[2860.6,6.291],[2872.3,0.0]],"action":"update"}}
1651237310.4972925: {"channel":"orderbook","market":"ETH/USD","type":"update","data":{"time":1651237310.3643205,"checksum":1866229275,"bids":[],"asks":[[2859.9,11.7],[2863.4,28.134]],"action":"update"}}
1651237310.5179622: {"channel":"orderbook","market":"SOL/USD","type":"update","data":{"time":1651237310.3864202,"checksum":1620253496,"bids":[[95.76,121.01]],"asks":[],"action":"update"}}
1651237310.5180218: {"channel":"orderbook","market":"ETH/USD","type":"update","data":{"time":1651237310.3885584,"checksum":2250544063,"bids":[],"asks":[[2859.9,3.8]],"action":"update"}}
1651237310.5343783: {"channel":"orderbook","market":"SOL/USD","type":"update","data":{"time":1651237310.4020364,"checksum":2461263295,"bids":[],"asks":[[95.8225,0.0],[96.33,0.26]],"action":"update"}}
1651237310.5472193: {"channel":"orderbook","market":"ETH/USD","type":"update","data":{"time":1651237310.415554,"checksum":1275265042,"bids":[[2859.3,5.661]],"asks":[[2859.7,2.1],[2859.9,1.9],[2863.7,1.603],[2872.1,0.0]],"action":"update"}}
1651237310.5495973: {"channel":"orderbook","market":"ETH/USDT","type":"update","data":{"time":1651237310.4220612,"checksum":2986719113,"bids":[],"asks":[[2862.2,0.0],[2882.0,0.049]],"action":"update"}}
1651237310.5624132: {"channel":"orderbook","market":"SOL/USD","type":"update","data":{"time":1651237310.4295514,"checksum":2961765985,"bids":[[95.7975,0.0],[95.385,50.0]],"asks":[],"action":"update"}}
1651237310.5682352: {"channel":"orderbook","market":"DAI/USD","type":"update","data":{"time":1651237310.4380357,"checksum":2637841829,"bids":[],"asks":[],"action":"update"}}
1651237310.5694637: {"channel":"orderbook","market":"ETH/USD","type":"update","data":{"time":1651237310.4407446,"checksum":3317246230,"bids":[],"asks":[[2859.9,0.0],[2861.9,8.769],[2872.1,0.202]],"action":"update"}}
1651237310.5981493: {"channel":"orderbook","market":"ETH/USD","type":"update","data":{"time":1651237310.4653673,"checksum":1213601174,"bids":[[2858.3,12.705],[2856.3,4.634],[2855.6,3.016]],"asks":[[2862.7,3.555]],"action":"update"}}
1651237310.6078134: {"channel":"orderbook","market":"ETH/USDT","type":"update","data":{"time":1651237310.4741623,"checksum":3412576417,"bids":[[2859.5,20.12],[2841.5,0.0]],"asks":[[2860.7,7.325]],"action":"update"}}
1651237310.639173: {"channel":"orderbook","market":"ETH/USD","type":"update","data":{"time":1651237310.491668,"checksum":2073673698,"bids":[[2856.3,4.284]],"asks":[[2859.8,3.8],[2863.3,7.402],[2863.4,30.255],[2863.7,1.254],[2864.2,0.002],[2872.1,0.0]],"action":"update"}}
1651237310.6392856: {"channel":"orderbook","market":"SOL/USD","type":"update","data":{"time":1651237310.4986393,"checksum":3912573007,"bids":[[95.69,179.06]],"asks":[[95.87,105.35],[96.33,0.0]],"action":"update"}}
1651237310.6393483: {"channel":"orderbook","market":"SHIB/USD","type":"update","data":{"time":1651237310.5041292,"checksum":1317776792,"bids":[],"asks":[[0.00002262,224100000.0],[0.00002267,26500000.0]],"action":"update"}}
1651237310.6611233: {"channel":"orderbook","market":"ETH/USD","type":"update","data":{"time":1651237310.5149515,"checksum":3806156031,"bids":[[2858.5,4.185]],"asks":[],"action":"update"}}
1651237310.6785648: {"channel":"orderbook","market":"SOL/USD","type":"update","data":{"time":1651237310.5363123,"checksum":3030744061,"bids":[[95.77,139.44],[95.765,246.72],[95.385,0.0]],"asks":[[95.9325,0.0],[96.33,0.26]],"action":"update"}}
1651237310.6868582: {"channel":"orderbook","market":"ETH/USD","type":"update","data":{"time":1651237310.552965,"checksum":1387680266,"bids":[],"asks":[[2859.7,5.593],[2859.8,8.0],[2860.6,14.042],[2863.3,8.417]],"action":"update"}}
1651237310.706089: {"channel":"orderbook","market":"USD/TRY","type":"update","data":{"time":1651237310.5727675,"checksum":1933757672,"bids":[],"asks":[],"action":"update"}}
1651237310.710205: {"channel":"orderbook","market":"LTC/USDT","type":"update","data":{"time":1651237310.5815763,"checksum":3410790265,"bids":[],"asks":[[100.605,12.0],[104.02,0.0]],"action":"update"}}
1651237310.710271: {"channel":"orderbook","market":"ETH/USD","type":"update","data":{"time":1651237310.5782943,"checksum":469772566,"bids":[[2858.3,17.305],[2853.9,5.541]],"asks":[[2859.8,6.0]],"action":"update"}}
1651237310.7288532: {"channel":"orderbook","market":"ETH/USD","type":"update","data":{"time":1651237310.5963535,"checksum":502259484,"bids":[[2858.9,39.949]],"asks":[[2859.8,0.0],[2861.7,1.774],[2872.1,0.202]],"action":"update"}}
1651237310.7534304: {"channel":"orderbook","market":"ETH/USD","type":"update","data":{"time":1651237310.6239524,"checksum":2363135435,"bids":[[2859.6,2.124]],"asks":[[2866.9,0.282]],"action":"update"}}
1651237310.7606094: {"channel":"orderbook","market":"SOL/USD","type":"update","data":{"time":1651237310.6241302,"checksum":2203718658,"bids":[],"asks":[[95.8225,36.0],[96.33,0.0]],"action":"update"}}
1651237310.760649: {"channel":"orderbook","market":"ETH/USDT","type":"update","data":{"time":1651237310.6309977,"checksum":3909852752,"bids":[],"asks":[[2864.3,0.0],[2882.1,0.011]],"action":"update"}}
1651237310.7807171: {"channel":"orderbook","market":"ETH/USD","type":"update","data":{"time":1651237310.646242,"checksum":1762797355,"bids":[[2859.0,10.167]],"asks":[[2860.3,25.733],[2867.1,0.224]],"action":"update"}}
1651237310.7807834: {"channel":"orderbook","market":"ETH/USDT","type":"update","data":{"time":1651237310.6472473,"checksum":2152287933,"bids":[[2858.8,2.354]],"asks":[[2860.0,22.0]],"action":"update"}}
1651237310.8103764: {"channel":"orderbook","market":"ETH/USD","type":"update","data":{"time":1651237310.672328,"checksum":962341700,"bids":[[2858.5,0.687],[2856.9,4.375],[2853.9,3.485]],"asks":[[2859.7,2.1],[2863.7,1.603]],"action":"update"}}
1651237310.8104315: {"channel":"orderbook","market":"ETH/USDT","type":"update","data":{"time":1651237310.6768265,"checksum":1917582959,"bids":[[2859.6,9.561]],"asks":[],"action":"update"}}
1651237310.810457: {"channel":"orderbook","market":"LTC/USDT","type":"update","data":{"time":1651237310.6825686,"checksum":858598568,"bids":[],"asks":[[100.665,20.2],[104.0,0.0]],"action":"update"}}
1651237310.8347042: {"channel":"orderbook","market":"SOL/USD","type":"update","data":{"time":1651237310.6918073,"checksum":2403115248,"bids":[[95.7425,0.0],[95.385,50.0]],"asks":[[95.97,0.0],[96.33,0.26]],"action":"update"}}
1651237310.8347626: {"channel":"orderbook","market":"ETH/USD","type":"update","data":{"time":1651237310.6955218,"checksum":3332879310,"bids":[],"asks":[[2863.7,1.254]],"action":"update"}}
1651237310.8347886: {"channel":"orderbook","market":"ETH/USDT","type":"update","data":{"time":1651237310.7021768,"checksum":2282062816,"bids":[],"asks":[[2860.8,28.006]],"action":"update"}}
1651237310.8348136: {"channel":"orderbook","market":"SHIB/USD","type":"update","data":{"time":1651237310.7026072,"checksum":3114432665,"bids":[],"asks":[[0.00002263,241200000.0]],"action":"update"}}
1651237310.8400102: {"channel":"orderbook","market":"LTC/USDT","type":"update","data":{"time":1651237310.711059,"checksum":3474152077,"bids":[[100.545,65.8],[96.45,0.0]],"asks":[],"action":"update"}}
1651237310.8525262: {"channel":"orderbook","market":"SOL/USD","type":"update","data":{"time":1651237310.7239888,"checksum":95673080,"bids":[[95.7075,0.0],[95.3825,0.01]],"asks":[],"action":"update"}}
1651237310.8714166: {"channel":"orderbook","market":"SOL/USD","type":"update","data":{"time":1651237310.7385247,"checksum":1004072284,"bids":[],"asks":[[95.8625,2.19],[96.33,0.0]],"action":"update"}}
1651237310.903191: {"channel":"orderbook","market":"ETH/USDT","type":"update","data":{"time":1651237310.749186,"checksum":3912181518,"bids":[[2859.2,7.601]],"asks":[],"action":"update"}}
1651237310.903243: {"channel":"orderbook","market":"ETH/USD","type":"update","data":{"time":1651237310.7568219,"checksum":1926275758,"bids":[[2859.6,7.517]],"asks":[],"action":"update"}}
1651237310.903286: {"channel":"orderbook","market":"FTT/BTC","type":"update","data":{"time":1651237310.7595491,"checksum":3452073527,"bids":[],"asks":[],"action":"update"}}
1651237310.9085252: {"channel":"orderbook","market":"SOL/USD","type":"update","data":{"time":1651237310.7745566,"checksum":2816552217,"bids":[[95.5925,275.5]],"asks":[],"action":"update"}}
1651237310.9376328: {"channel":"orderbook","market":"SHIB/USD","type":"update","data":{"time":1651237310.8037426,"checksum":1402917815,"bids":[],"asks":[[0.00002263,341100000.0]],"action":"update"}}
1651237310.937676: {"channel":"orderbook","market":"ETH/USD","type":"update","data":{"time":1651237310.803145,"checksum":3771900536,"bids":[[2859.1,9.526],[2858.8,10.562],[2856.5,0.889]],"asks":[[2859.7,0.0],[2867.8,0.0],[2872.3,0.051],[2872.6,0.005]],"action":"update"}}
1651237310.9554536: {"channel":"orderbook","market":"BTC/TRY","type":"update","data":{"time":1651237310.8193138,"checksum":2549750460,"bids":[],"asks":[],"action":"update"}}
1651237310.9554904: {"channel":"orderbook","market":"ETH/USD","type":"update","data":{"time":1651237310.8199997,"checksum":2572132149,"bids":[],"asks":[[2860.7,41.848],[2860.8,23.174],[2864.0,2.794]],"action":"update"}}
1651237310.9599347: {"channel":"orderbook","market":"SOL/USD","type":"update","data":{"time":1651237310.8265948,"checksum":3144354999,"bids":[[95.7275,0.97]],"asks":[[95.8275,0.0],[95.9425,65.89],[95.955,0.0],[96.33,0.26]],"action":"update"}}
1651237310.9675856: {"channel":"orderbook","market":"WBTC/USD","type":"update","data":{"time":1651237310.83488,"checksum":1346881008,"bids":[],"asks":[[39008.0,0.0],[44095.0,0.0005]],"action":"update"}}
1651237310.9879186: {"channel":"orderbook","market":"SHIB/USD","type":"update","data":{"time":1651237310.8537214,"checksum":4276557230,"bids":[[0.00002237,109300000.0]],"asks":[],"action":"update"}}
1651237310.9879625: {"channel":"orderbook","market":"ETH/USD","type":"update","data":{"time":1651237310.851532,"checksum":1872413875,"bids":[[2859.6,7.717],[2859.0,17.659],[2858.5,14.605]],"asks":[[2861.0,1.0],[2861.2,0.0]],"action":"update"}}
1651237310.9880013: {"channel":"orderbook","market":"SOL/USD","type":"update","data":{"time":1651237310.8577268,"checksum":1687564193,"bids":[],"asks":[[95.9225,62.64],[96.15,0.0]],"action":"update"}}
1651237310.9971602: {"channel":"orderbook","market":"WBTC/USD","type":"update","data":{"time":1651237310.8658998,"checksum":318948300,"bids":[[38858.0,13.329],[35496.0,0.0]],"asks":[],"action":"update"}}
1651237310.9978821: {"channel":"orderbook","market":"ETH/USD","type":"update","data":{"time":1651237310.8699477,"checksum":3503254732,"bids":[[2859.7,1.975],[2848.4,0.0]],"asks":[[2866.6,3.778]],"action":"update"}}
1651237311.0146885: {"channel":"orderbook","market":"ETH/USDT","type":"update","data":{"time":1651237310.8748946,"checksum":200829631,"bids":[[2859.5,20.339]],"asks":[],"action":"update"}}
1651237311.014752: {"channel":"orderbook","market":"SHIB/USD","type":"update","data":{"time":1651237310.8798766,"checksum":3867027627,"bids":[],"asks":[[0.00002261,41100000.0]],"action":"update"}}
1651237311.0251665: {"channel":"orderbook","market":"ETH/USD","type":"update","data":{"time":1651237310.895503,"checksum":4000955327,"bids":[[2859.9,1.9],[2859.6,3.806],[2857.9,133.005],[2856.7,0.042],[2848.5,0.0]],"asks":[[2860.5,21.404],[2860.6,28.342],[2863.3,7.402]],"action":"update"}}
1651237311.0528789: {"channel":"orderbook","market":"ETH/USD","type":"update","data":{"time":1651237310.9175386,"checksum":2632318306,"bids":[[2859.7,0.0],[2858.3,12.705],[2858.2,22.181],[2848.5,0.142]],"asks":[[2860.4,6.501],[2860.5,21.055]],"action":"update"}}
1651237311.0608878: {"channel":"orderbook","market":"ETH/USDT","type":"update","data":{"time":1651237310.9291248,"checksum":467611994,"bids":[],"asks":[[2859.9,0.0],[2860.0,0.0],[2861.4,12.656],[2882.2,0.011],[2882.4,0.035]],"action":"update"}}
1651237311.07924: {"channel":"orderbook","market":"SOL/USD","type":"update","data":{"time":1651237310.9455068,"checksum":481595540,"bids":[[95.7925,70.0],[95.6625,0.0]],"asks":[],"action":"update"}}
1651237311.0792918: {"channel":"orderbook","market":"SHIB/USD","type":"update","data":{"time":1651237310.9459796,"checksum":3933566027,"bids":[[0.00002255,189200000.0]],"asks":[],"action":"update"}}
1651237311.089556: {"channel":"orderbook","market":"ETH/USD","type":"update","data":{"time":1651237310.9497948,"checksum":555925298,"bids":[],"asks":[[2860.5,28.148]],"action":"update"}}
1651237311.0985687: {"channel":"orderbook","market":"SOL/USD","type":"update","data":{"time":1651237310.9706492,"checksum":4034997353,"bids":[[95.79,173.06]],"asks":[],"action":"update"}}
1651237311.1105125: {"channel":"orderbook","market":"ETH/USDT","type":"update","data":{"time":1651237310.9597363,"checksum":2600967492,"bids":[[2859.8,2.057]],"asks":[],"action":"update"}}
1651237311.1210468: {"channel":"orderbook","market":"SOL/USD","type":"update","data":{"time":1651237310.9959342,"checksum":481595540,"bids":[[95.79,119.86]],"asks":[],"action":"update"}}
1651237311.1334693: {"channel":"orderbook","market":"ETH/USDT","type":"update","data":{"time":1651237310.9995778,"checksum":3442043884,"bids":[[2859.8,0.057],[2857.5,170.321]],"asks":[[2860.4,2.009],[2882.4,0.0]],"action":"update"}}
1651237311.1424532: {"channel":"orderbook","market":"LTC/USDT","type":"update","data":{"time":1651237311.01336,"checksum":2898311479,"bids":[],"asks":[[100.81,335.3],[100.825,101.14],[103.96,0.0]],"action":"update"}}
1651237311.1442854: {"channel":"orderbook","market":"WBTC/USD","type":"update","data":{"time":1651237311.0129082,"checksum":318948300,"bids":[],"asks":[],"action":"update"}}
1651237311.1483893: {"channel":"orderbook","market":"ETH/USD","type":"update","data":{"time":1651237311.02171,"checksum":244846733,"bids":[[2859.6,3.493]],"asks":[[2866.4,7.31]],"action":"update"}}
1651237311.1695445: {"channel":"orderbook","market":"SHIB/USD","type":"update","data":{"time":1651237311.0339222,"checksum":3620406743,"bids":[[0.00002258,304300000.0]],"asks":[],"action":"update"}}
1651237311.1696048: {"channel":"orderbook","market":"SOL/USD","type":"update","data":{"time":1651237311.0358276,"checksum":3319130481,"bids":[[95.7625,106.27],[95.73,136.75],[95.7175,137.66],[95.67,23.48],[95.3825,0.0]],"asks":[[95.945,600.2]],"action":"update"}}
1651237311.1790633: {"channel":"orderbook","market":"ETH/USD","type":"update","data":{"time":1651237311.044962,"checksum":199195240,"bids":[],"asks":[[2860.8,23.523]],"action":"update"}}
1651237311.1895463: {"channel":"orderbook","market":"ETH/USDT","type":"update","data":{"time":1651237311.0536408,"checksum":4156320461,"bids":[],"asks":[[2860.3,10.998]],"action":"update"}}
1651237311.189591: {"channel":"orderbook","market":"SHIB/USD","type":"update","data":{"time":1651237311.0584102,"checksum":2843523464,"bids":[[0.00002258,404200000.0]],"asks":[],"action":"update"}}
1651237311.2038736: {"channel":"orderbook","market":"ETH/USDT","type":"update","data":{"time":1651237311.07212,"checksum":3836514754,"bids":[],"asks":[[2860.8,8.462],[2864.2,0.098],[2882.2,0.0]],"action":"update"}}
1651237311.2159703: {"channel":"orderbook","market":"ETH/USD","type":"update","data":{"time":1651237311.0794318,"checksum":3751736396,"bids":[[2859.9,2.199]],"asks":[[2861.0,0.0],[2863.3,7.507],[2872.7,0.001]],"action":"update"}}
1651237311.2160227: {"channel":"orderbook","market":"SOL/USD","type":"update","data":{"time":1651237311.056831,"checksum":2951813427,"bids":[],"asks":[[95.86,0.0],[95.8675,90.91]],"action":"update"}}
1651237311.2259789: {"channel":"orderbook","market":"ETH/USDT","type":"update","data":{"time":1651237311.0978417,"checksum":1379177366,"bids":[[2859.7,22.188],[2856.0,2.135],[2841.6,0.0]],"asks":[[2860.6,6.921],[2860.7,1.197],[2882.1,0.0]],"action":"update"}}
1651237311.2299328: {"channel":"orderbook","market":"SOL/USD","type":"update","data":{"time":1651237311.09784,"checksum":3783792780,"bids":[],"asks":[[95.87,0.0],[96.3325,0.13]],"action":"update"}}
1651237311.2384775: {"channel":"orderbook","market":"LTC/USDT","type":"update","data":{"time":1651237311.1082828,"checksum":3987354327,"bids":[],"asks":[[100.77,240.96]],"action":"update"}}
1651237311.2605765: {"channel":"orderbook","market":"USD/TRY","type":"update","data":{"time":1651237311.1220644,"checksum":2188252645,"bids":[[13.7167,0.0]],"asks":[],"action":"update"}}
1651237311.260628: {"channel":"orderbook","market":"ETH/USD","type":"update","data":{"time":1651237311.1177847,"checksum":3070278231,"bids":[],"asks":[[2860.0,37.1]],"action":"update"}}
1651237311.2631855: {"channel":"orderbook","market":"ETH/USDT","type":"update","data":{"time":1651237311.1336796,"checksum":912086263,"bids":[[2859.5,0.219],[2858.6,20.117]],"asks":[[2864.1,185.942]],"action":"update"}}
1651237311.2725732: {"channel":"orderbook","market":"ETH/USD","type":"update","data":{"time":1651237311.1418247,"checksum":3734049673,"bids":[[2858.9,36.452],[2858.7,0.0],[2848.4,0.059]],"asks":[[2860.2,9.951]],"action":"update"}}
1651237311.296904: {"channel":"orderbook","market":"SHIB/USD","type":"update","data":{"time":1651237311.1602015,"checksum":2458862315,"bids":[],"asks":[[0.00002264,214500000.0]],"action":"update"}}
1651237311.2969484: {"channel":"orderbook","market":"WBTC/USD","type":"update","data":{"time":1651237311.1633048,"checksum":3143369292,"bids":[[38869.0,0.0],[35496.0,0.0001]],"asks":[],"action":"update"}}
1651237311.300631: {"channel":"orderbook","market":"ETH/USD","type":"update","data":{"time":1651237311.170307,"checksum":1636943460,"bids":[[2859.9,2.432],[2858.5,39.386],[2858.4,6.115]],"asks":[[2860.4,13.547],[2861.0,0.745],[2862.0,13.263],[2872.7,0.0]],"action":"update"}}
1651237311.3138: {"channel":"orderbook","market":"SOL/USD","type":"update","data":{"time":1651237311.1790054,"checksum":2054739344,"bids":[[95.79,0.2],[95.775,119.51],[95.7325,627.35],[95.385,0.0]],"asks":[[95.87,0.05],[96.3325,0.0]],"action":"update"}}
1651237311.3388944: {"channel":"orderbook","market":"ETH/USDT","type":"update","data":{"time":1651237311.1864464,"checksum":1559740003,"bids":[[2860.1,2.0],[2859.8,5.608],[2859.6,4.529],[2855.9,0.046],[2842.0,0.0]],"asks":[],"action":"update"}}
1651237311.3435442: {"channel":"orderbook","market":"SHIB/USD","type":"update","data":{"time":1651237311.2098832,"checksum":4067123168,"bids":[[0.00002256,288200000.0]],"asks":[],"action":"update"}}
1651237311.3563993: {"channel":"orderbook","market":"SOL/USD","type":"update","data":{"time":1651237311.2159739,"checksum":1713408130,"bids":[[95.795,59.25],[95.7725,72.11],[95.3875,0.0]],"asks":[],"action":"update"}}
1651237311.3651276: {"channel":"orderbook","market":"ETH/USD","type":"update","data":{"time":1651237311.2292185,"checksum":141293850,"bids":[[2859.3,7.41],[2858.6,24.138],[2858.1,0.011]],"asks":[[2861.9,3.008]],"action":"update"}}
1651237311.3759966: {"channel":"orderbook","market":"ETH/USDT","type":"update","data":{"time":1651237311.2414904,"checksum":4151862298,"bids":[[2859.1,8.497]],"asks":[],"action":"update"}}
1651237311.3776298: {"channel":"orderbook","market":"ETH/USD","type":"update","data":{"time":1651237311.2480848,"checksum":3935437814,"bids":[[2859.1,13.023]],"asks":[[2860.6,31.839]],"action":"update"}}
1651237311.3873591: {"channel":"orderbook","market":"SOL/USD","type":"update","data":{"time":1651237311.2565494,"checksum":2481728557,"bids":[[95.7925,0.0],[95.7025,131.86],[95.5925,460.11]],"asks":[[96.1,210.74]],"action":"update"}}
1651237311.3998415: {"channel":"orderbook","market":"ETH/USD","type":"update","data":{"time":1651237311.2716491,"checksum":3867264372,"bids":[[2858.3,2.104]],"asks":[],"action":"update"}}
1651237311.3998787: {"channel":"orderbook","market":"LTC/USDT","type":"update","data":{"time":1651237311.2711399,"checksum":3987354327,"bids":[],"asks":[],"action":"update"}}
1651237311.4176078: {"channel":"orderbook","market":"WBTC/USD","type":"update","data":{"time":1651237311.28563,"checksum":3572266149,"bids":[[38858.0,23.0259]],"asks":[],"action":"update"}}
1651237311.4176507: {"channel":"orderbook","market":"SOL/USD","type":"update","data":{"time":1651237311.2873294,"checksum":4044420631,"bids":[[95.795,67.87],[95.76,116.01]],"asks":[],"action":"update"}}
1651237311.4265852: {"channel":"orderbook","market":"SHIB/USD","type":"update","data":{"time":1651237311.2825012,"checksum":2088611076,"bids":[[0.00002257,437000000.0]],"asks":[],"action":"update"}}
1651237311.431872: {"channel":"orderbook","market":"ETH/USD","type":"update","data":{"time":1651237311.2969887,"checksum":2770609172,"bids":[[2859.4,5.604]],"asks":[],"action":"update"}}
1651237311.4438622: {"channel":"orderbook","market":"SOL/USD","type":"update","data":{"time":1651237311.3091633,"checksum":681215074,"bids":[],"asks":[[95.8725,70.0],[95.895,105.32],[96.3275,0.0],[96.33,0.0]],"action":"update"}}
1651237311.450448: {"channel":"orderbook","market":"USD/TRY","type":"update","data":{"time":1651237311.3264964,"checksum":202005174,"bids":[[13.591,0.0]],"asks":[],"action":"update"}}
1651237311.456722: {"channel":"orderbook","market":"ETH/USD","type":"update","data":{"time":1651237311.323439,"checksum":414490511,"bids":[[2853.8,5.307]],"asks":[[2861.1,0.0],[2863.4,30.256],[2872.7,0.001]],"action":"update"}}
1651237311.4727018: {"channel":"orderbook","market":"SHIB/USD","type":"update","data":{"time":1651237311.3319116,"checksum":3117666530,"bids":[],"asks":[[0.00002263,441000000.0]],"action":"update"}}
1651237311.4826033: {"channel":"orderbook","market":"ETH/USD","type":"update","data":{"time":1651237311.3478434,"checksum":3312495652,"bids":[],"asks":[[2860.5,28.376]],"action":"update"}}
1651237311.4878402: {"channel":"orderbook","market":"SOL/USD","type":"update","data":{"time":1651237311.357307,"checksum":1262114720,"bids":[[95.7975,70.0],[95.68,51.0],[95.3975,0.0],[95.39,0.0]],"asks":[[96.13,275.32],[96.3225,0.0]],"action":"update"}}
1651237311.5039575: {"channel":"orderbook","market":"SHIB/USD","type":"update","data":{"time":1651237311.3759246,"checksum":2274575245,"bids":[],"asks":[[0.00002266,263700000.0]],"action":"update"}}
1651237311.5079682: {"channel":"orderbook","market":"SOL/USD","type":"update","data":{"time":1651237311.3813274,"checksum":2526488515,"bids":[],"asks":[[95.995,139.12]],"action":"update"}}
1651237311.513152: {"channel":"orderbook","market":"ETH/USD","type":"update","data":{"time":1651237311.3761992,"checksum":3058906820,"bids":[[2859.9,2.406],[2858.7,6.036],[2848.4,0.0]],"asks":[],"action":"update"}}
1651237311.5178297: {"channel":"orderbook","market":"ETH/USDT","type":"update","data":{"time":1651237311.3874607,"checksum":287945821,"bids":[],"asks":[[2860.2,2.0],[2882.0,0.0]],"action":"update"}}
1651237311.5360267: {"channel":"orderbook","market":"ETH/USD","type":"update","data":{"time":1651237311.401361,"checksum":3094028612,"bids":[],"asks":[[2863.3,7.402]],"action":"update"}}
1651237311.5565176: {"channel":"orderbook","market":"SHIB/USD","type":"update","data":{"time":1651237311.4262657,"checksum":1133361216,"bids":[],"asks":[[0.00002262,258100000.0]],"action":"update"}}
1651237311.5620756: {"channel":"orderbook","market":"ETH/USDT","type":"update","data":{"time":1651237311.4367342,"checksum":749744333,"bids":[],"asks":[[2860.6,0.0],[2861.0,19.651]],"action":"update"}}
1651237311.5715206: {"channel":"orderbook","market":"LTC/USDT","type":"update","data":{"time":1651237311.4407206,"checksum":1414580939,"bids":[[100.43,20.77],[96.5,0.0]],"asks":[],"action":"update"}}
1651237311.592971: {"channel":"orderbook","market":"DAI/USD","type":"update","data":{"time":1651237311.4640245,"checksum":2637841829,"bids":[],"asks":[],"action":"update"}}
1651237311.6013274: {"channel":"orderbook","market":"FTT/BTC","type":"update","data":{"time":1651237311.469101,"checksum":345187941,"bids":[[0.0010061,22.9]],"asks":[],"action":"update"}}
1651237311.602889: {"channel":"orderbook","market":"ETH/USD","type":"update","data":{"time":1651237311.4767013,"checksum":874219084,"bids":[[2858.2,22.182]],"asks":[[2862.2,23.993],[2862.3,0.001],[2872.7,0.0]],"action":"update"}}
1651237311.6114447: {"channel":"orderbook","market":"SOL/USD","type":"update","data":{"time":1651237311.4806705,"checksum":2790460912,"bids":[],"asks":[[96.02,0.58]],"action":"update"}}
1651237311.6250098: {"channel":"orderbook","market":"ETH/USDT","type":"update","data":{"time":1651237311.4911876,"checksum":1711843092,"bids":[],"asks":[[2860.2,5.075]],"action":"update"}}
1651237311.6250641: {"channel":"orderbook","market":"LTC/USDT","type":"update","data":{"time":1651237311.4959588,"checksum":3987354327,"bids":[[100.43,0.0],[96.5,0.06]],"asks":[],"action":"update"}}
1651237311.6420686: {"channel":"orderbook","market":"ETH/USD","type":"update","data":{"time":1651237311.5006795,"checksum":831204910,"bids":[[2859.9,2.407]],"asks":[],"action":"update"}}
1651237311.6447625: {"channel":"orderbook","market":"LTC/USDT","type":"update","data":{"time":1651237311.5175993,"checksum":621936063,"bids":[],"asks":[[100.61,0.0],[100.675,7.46],[100.735,29.84],[103.91,0.0]],"action":"update"}}
1651237311.6656811: {"channel":"orderbook","market":"ETH/USD","type":"update","data":{"time":1651237311.5286205,"checksum":401093214,"bids":[],"asks":[[2862.1,6.002]],"action":"update"}}
1651237311.6701214: {"channel":"orderbook","market":"FTT/BTC","type":"update","data":{"time":1651237311.5412898,"checksum":3818591,"bids":[],"asks":[[0.0010096,1.0],[0.0010241,0.0]],"action":"update"}}
1651237311.6771085: {"channel":"orderbook","market":"LTC/USDT","type":"update","data":{"time":1651237311.5464184,"checksum":2514352373,"bids":[],"asks":[[100.605,0.0],[103.91,0.02]],"action":"update"}}
1651237311.705288: {"channel":"orderbook","market":"ETH/USD","type":"update","data":{"time":1651237311.5777655,"checksum":4120070409,"bids":[[2859.9,2.395]],"asks":[[2861.0,1.094],[2867.4,2.086]],"action":"update"}}
1651237311.7216206: {"channel":"orderbook","market":"SOL/USD","type":"update","data":{"time":1651237311.595863,"checksum":1570669225,"bids":[[95.7825,9.59],[95.765,358.08],[95.4,0.0]],"asks":[[95.87,0.0],[96.3225,0.62]],"action":"update"}}
1651237311.7223833: {"channel":"orderbook","market":"USD/TRY","type":"update","data":{"time":1651237311.5983312,"checksum":202005174,"bids":[],"asks":[],"action":"update"}}
1651237311.7372277: {"channel":"orderbook","market":"ETH/USD","type":"update","data":{"time":1651237311.6035461,"checksum":3427839859,"bids":[],"asks":[[2863.2,4.697]],"action":"update"}}
1651237311.7421854: {"channel":"orderbook","market":"LTC/USDT","type":"update","data":{"time":1651237311.6182683,"checksum":1195311390,"bids":[],"asks":[[100.615,18.45],[100.87,0.0]],"action":"update"}}
1651237311.7612383: {"channel":"orderbook","market":"WBTC/USD","type":"update","data":{"time":1651237311.6328905,"checksum":2799955749,"bids":[[38858.0,9.6969]],"asks":[],"action":"update"}}
1651237311.7706041: {"channel":"orderbook","market":"SOL/USD","type":"update","data":{"time":1651237311.6420228,"checksum":1587167172,"bids":[],"asks":[[95.895,0.0],[96.3275,0.01]],"action":"update"}}
1651237311.777056: {"channel":"orderbook","market":"ETH/USD","type":"update","data":{"time":1651237311.6509523,"checksum":857970107,"bids":[],"asks":[[2862.4,14.112]],"action":"update"}}
1651237311.7975862: {"channel":"orderbook","market":"LTC/USDT","type":"update","data":{"time":1651237311.6654289,"checksum":86401767,"bids":[],"asks":[[100.615,20.35]],"action":"update"}}
1651237311.8089201: {"channel":"orderbook","market":"ETH/USD","type":"update","data":{"time":1651237311.6791682,"checksum":1745485711,"bids":[[2858.8,27.866],[2856.7,0.392]],"asks":[],"action":"update"}}
1651237311.8272822: {"channel":"orderbook","market":"SOL/USD","type":"update","data":{"time":1651237311.6948373,"checksum":3485470905,"bids":[],"asks":[[96.025,137.69]],"action":"update"}}
1651237311.8481581: {"channel":"orderbook","market":"SOL/USD","type":"update","data":{"time":1651237311.7159662,"checksum":235958177,"bids":[[95.77,144.44],[95.67,12.61]],"asks":[],"action":"update"}}
1651237311.8813949: {"channel":"orderbook","market":"ETH/USDT","type":"update","data":{"time":1651237311.756843,"checksum":2884875701,"bids":[[2857.6,15.774]],"asks":[],"action":"update"}}
1651237311.8930852: {"channel":"orderbook","market":"ETH/USD","type":"update","data":{"time":1651237311.7647839,"checksum":1660880442,"bids":[[2858.6,14.532]],"asks":[],"action":"update"}}
1651237311.9249792: {"channel":"orderbook","market":"FTT/BTC","type":"update","data":{"time":1651237311.786164,"checksum":3818591,"bids":[],"asks":[],"action":"update"}}
1651237311.9259276: {"channel":"orderbook","market":"SOL/USD","type":"update","data":{"time":1651237311.7983758,"checksum":3844786498,"bids":[],"asks":[[95.9,233.9]],"action":"update"}}
1651237311.9337978: {"channel":"orderbook","market":"ETH/USDT","type":"update","data":{"time":1651237311.8092368,"checksum":27876424,"bids":[[2858.7,12.028]],"asks":[],"action":"update"}}
1651237311.9602659: {"channel":"orderbook","market":"ETH/USDT","type":"update","data":{"time":1651237311.8338282,"checksum":3577872305,"bids":[],"asks":[[2861.4,1.08]],"action":"update"}}
1651237311.974683: {"channel":"orderbook","market":"BTC/TRY","type":"update","data":{"time":1651237311.8439324,"checksum":2549750460,"bids":[],"asks":[],"action":"update"}}
1651237312.0193267: {"channel":"orderbook","market":"ETH/USD","type":"update","data":{"time":1651237311.8786373,"checksum":398690245,"bids":[[2855.0,0.172]],"asks":[],"action":"update"}}
1651237312.0193706: {"channel":"orderbook","market":"SOL/USD","type":"update","data":{"time":1651237311.887743,"checksum":3582098430,"bids":[[95.77,139.44]],"asks":[[95.8725,0.0],[96.33,0.26]],"action":"update"}}
1651237312.0378861: {"channel":"orderbook","market":"ETH/USD","type":"update","data":{"time":1651237311.902434,"checksum":2028178059,"bids":[[2858.9,43.422]],"asks":[[2866.9,0.281]],"action":"update"}}
1651237312.0773945: {"channel":"orderbook","market":"SHIB/USD","type":"update","data":{"time":1651237311.9385183,"checksum":2250491302,"bids":[],"asks":[[0.00002263,341100000.0]],"action":"update"}}
1651237312.0956614: {"channel":"orderbook","market":"SOL/USD","type":"update","data":{"time":1651237311.9648826,"checksum":132236451,"bids":[[95.8,51.5],[95.775,139.51],[95.4075,0.0]],"asks":[[95.9025,33.45]],"action":"update"}}
1651237312.1079175: {"channel":"orderbook","market":"ETH/USD","type":"update","data":{"time":1651237311.9759588,"checksum":583374908,"bids":[[2859.8,0.035],[2848.5,0.0]],"asks":[],"action":"update"}}
1651237312.1155503: {"channel":"orderbook","market":"SOL/USD","type":"update","data":{"time":1651237311.988334,"checksum":472204005,"bids":[[95.7975,0.0],[95.7925,5.0]],"asks":[],"action":"update"}}
1651237312.1276424: {"channel":"orderbook","market":"ETH/USD","type":"update","data":{"time":1651237311.99989,"checksum":3091780108,"bids":[],"asks":[[2862.8,0.975]],"action":"update"}}
1651237312.129204: {"channel":"orderbook","market":"ETH/USDT","type":"update","data":{"time":1651237311.9976726,"checksum":3577872305,"bids":[],"asks":[],"action":"update"}}
1651237312.1585634: {"channel":"orderbook","market":"WBTC/USD","type":"update","data":{"time":1651237312.0323446,"checksum":2799955749,"bids":[],"asks":[],"action":"update"}}
1651237312.194447: {"channel":"orderbook","market":"LTC/USDT","type":"update","data":{"time":1651237312.0654263,"checksum":1502946355,"bids":[[100.265,74.74]],"asks":[[100.85,313.42]],"action":"update"}}
1651237312.2138155: {"channel":"orderbook","market":"ETH/USD","type":"update","data":{"time":1651237312.0761175,"checksum":3427099073,"bids":[[2848.6,0.198]],"asks":[[2871.0,0.003]],"action":"update"}}
1651237312.2237487: {"channel":"orderbook","market":"ETH/USDT","type":"update","data":{"time":1651237312.0921085,"checksum":3361493398,"bids":[],"asks":[[2861.0,19.943]],"action":"update"}}
1651237312.2237985: {"channel":"orderbook","market":"SOL/USD","type":"update","data":{"time":1651237312.0885425,"checksum":2912219581,"bids":[[95.7625,106.92],[95.7275,0.0],[95.4075,0.47]],"asks":[[95.9225,0.0],[96.0175,55.96]],"action":"update"}}
1651237312.2581325: {"channel":"orderbook","market":"SOL/USD","type":"update","data":{"time":1651237312.103857,"checksum":2229625962,"bids":[[95.7925,0.0],[95.4,43.17]],"asks":[],"action":"update"}}
1651237312.2581844: {"channel":"orderbook","market":"ETH/USD","type":"update","data":{"time":1651237312.1144016,"checksum":3427247066,"bids":[[2859.4,5.784]],"asks":[[2866.7,585.253]],"action":"update"}}
1651237312.321539: {"channel":"orderbook","market":"ETH/USDT","type":"update","data":{"time":1651237312.1428945,"checksum":2180362557,"bids":[],"asks":[[2860.9,24.818]],"action":"update"}}
1651237312.3215919: {"channel":"orderbook","market":"USD/TRY","type":"update","data":{"time":1651237312.1526043,"checksum":1815702991,"bids":[[13.9753,2029.0]],"asks":[],"action":"update"}}
1651237312.321626: {"channel":"orderbook","market":"SOL/USD","type":"update","data":{"time":1651237312.1546807,"checksum":3107713639,"bids":[],"asks":[[95.9,128.59]],"action":"update"}}
1651237312.3216584: {"channel":"orderbook","market":"ETH/USDT","type":"update","data":{"time":1651237312.166823,"checksum":4207640273,"bids":[],"asks":[[2860.7,8.118]],"action":"update"}}
1651237312.3216867: {"channel":"orderbook","market":"SOL/USD","type":"update","data":{"time":1651237312.1906981,"checksum":3107713639,"bids":[],"asks":[],"action":"update"}}
1651237312.3398163: {"channel":"orderbook","market":"ETH/USD","type":"update","data":{"time":1651237312.2035382,"checksum":1453062030,"bids":[[2859.5,0.003],[2855.2,1.006],[2848.6,0.0]],"asks":[],"action":"update"}}
1651237312.3654015: {"channel":"orderbook","market":"WBTC/USD","type":"update","data":{"time":1651237312.2181933,"checksum":2731108107,"bids":[[38889.0,0.6614],[35496.0,0.0]],"asks":[],"action":"update"}}
1651237312.365469: {"channel":"orderbook","market":"SOL/USD","type":"update","data":{"time":1651237312.2364848,"checksum":2533792650,"bids":[[95.73,74.11]],"asks":[[95.8425,0.66],[95.875,70.0],[95.8975,89.86],[96.3275,0.0],[96.33,0.0]],"action":"update"}}
1651237312.3835542: {"channel":"orderbook","market":"ETH/USD","type":"update","data":{"time":1651237312.2539535,"checksum":1120425224,"bids":[[2859.4,2.033]],"asks":[],"action":"update"}}
1651237312.4045732: {"channel":"orderbook","market":"ETH/USD","type":"update","data":{"time":1651237312.2779105,"checksum":1953164218,"bids":[[2859.6,7.244],[2858.0,3.06]],"asks":[],"action":"update"}}
1651237312.4196286: {"channel":"orderbook","market":"LTC/USDT","type":"update","data":{"time":1651237312.290095,"checksum":1502946355,"bids":[],"asks":[],"action":"update"}}
1651237312.4196584: {"channel":"orderbook","market":"ETH/USDT","type":"update","data":{"time":1651237312.2918458,"checksum":548408603,"bids":[[2858.6,0.758]],"asks":[],"action":"update"}}
1651237312.4363062: {"channel":"orderbook","market":"SHIB/USD","type":"update","data":{"time":1651237312.3006172,"checksum":2250491302,"bids":[],"asks":[],"action":"update"}}
1651237312.4439077: {"channel":"orderbook","market":"SOL/USD","type":"update","data":{"time":1651237312.308091,"checksum":2781813652,"bids":[],"asks":[[95.895,105.32],[96.3225,0.0]],"action":"update"}}
1651237312.4569867: {"channel":"orderbook","market":"ETH/USDT","type":"update","data":{"time":1651237312.3317235,"checksum":3473527073,"bids":[[2858.8,5.369],[2858.7,6.993]],"asks":[],"action":"update"}}
1651237312.458191: {"channel":"orderbook","market":"ETH/USD","type":"update","data":{"time":1651237312.330557,"checksum":815849649,"bids":[],"asks":[[2866.7,585.252]],"action":"update"}}
1651237312.467342: {"channel":"orderbook","market":"WBTC/USD","type":"update","data":{"time":1651237312.3368046,"checksum":2799955749,"bids":[[38889.0,0.0],[35496.0,0.0001]],"asks":[],"action":"update"}}
1651237312.4695635: {"channel":"orderbook","market":"ETH/USDT","type":"update","data":{"time":1651237312.3418765,"checksum":719375488,"bids":[[2859.5,0.0],[2842.0,2.155]],"asks":[],"action":"update"}}
1651237312.5201879: {"channel":"orderbook","market":"LTC/USDT","type":"update","data":{"time":1651237312.3908682,"checksum":3474919848,"bids":[[100.375,0.0],[96.45,1.02]],"asks":[[100.61,12.0],[103.91,0.0]],"action":"update"}}
1651237312.520255: {"channel":"orderbook","market":"ETH/USDT","type":"update","data":{"time":1651237312.393026,"checksum":3695721818,"bids":[],"asks":[[2860.9,36.334]],"action":"update"}}
1651237312.5763385: {"channel":"orderbook","market":"SOL/USD","type":"update","data":{"time":1651237312.4041924,"checksum":1874375830,"bids":[[95.8025,12.9],[95.4,0.0]],"asks":[[95.93,63.33]],"action":"update"}}
1651237312.5763915: {"channel":"orderbook","market":"ETH/USDT","type":"update","data":{"time":1651237312.4165967,"checksum":536373461,"bids":[[2859.0,23.814],[2858.9,15.713]],"asks":[],"action":"update"}}
1651237312.576419: {"channel":"orderbook","market":"ETH/USDT","type":"update","data":{"time":1651237312.4427197,"checksum":33886039,"bids":[[2859.6,8.538]],"asks":[],"action":"update"}}
1651237312.5889037: {"channel":"orderbook","market":"SOL/USD","type":"update","data":{"time":1651237312.4541717,"checksum":1540242104,"bids":[[95.8,0.0],[95.4,43.17]],"asks":[],"action":"update"}}
1651237312.5889447: {"channel":"orderbook","market":"ETH/USD","type":"update","data":{"time":1651237312.4540942,"checksum":565244089,"bids":[[2859.8,0.077]],"asks":[],"action":"update"}}
1651237312.6166885: {"channel":"orderbook","market":"DAI/USD","type":"update","data":{"time":1651237312.4870436,"checksum":2637841829,"bids":[],"asks":[],"action":"update"}}
1651237312.6362028: {"channel":"orderbook","market":"SHIB/USD","type":"update","data":{"time":1651237312.5024807,"checksum":3871856813,"bids":[[0.00002256,233500000.0]],"asks":[],"action":"update"}}
1651237312.6578243: {"channel":"orderbook","market":"ETH/USD","type":"update","data":{"time":1651237312.5283432,"checksum":4071907710,"bids":[[2859.8,0.042],[2857.0,5.279]],"asks":[],"action":"update"}}
1651237312.691843: {"channel":"orderbook","market":"SOL/USD","type":"update","data":{"time":1651237312.5541918,"checksum":853237464,"bids":[[95.8,51.5],[95.7425,62.64],[95.4075,0.0],[95.4,0.0]],"asks":[],"action":"update"}}
1651237312.6918952: {"channel":"orderbook","market":"ETH/USD","type":"update","data":{"time":1651237312.553326,"checksum":1620679905,"bids":[[2853.8,2.276]],"asks":[[2861.6,8.393],[2866.5,0.061]],"action":"update"}}
1651237312.7124465: {"channel":"orderbook","market":"SOL/USD","type":"update","data":{"time":1651237312.5840533,"checksum":3989115975,"bids":[[95.5925,184.79]],"asks":[],"action":"update"}}
1651237312.7425244: {"channel":"orderbook","market":"SOL/USD","type":"update","data":{"time":1651237312.6150813,"checksum":2455733547,"bids":[[95.7975,5.0],[95.41,0.0]],"asks":[[95.9025,33.42]],"action":"update"}}
1651237312.7697108: {"channel":"orderbook","market":"USD/TRY","type":"update","data":{"time":1651237312.6302319,"checksum":1815702991,"bids":[],"asks":[],"action":"update"}}
1651237312.76975: {"channel":"orderbook","market":"ETH/USD","type":"update","data":{"time":1651237312.6289184,"checksum":560946504,"bids":[[2857.8,18.202]],"asks":[],"action":"update"}}
1651237312.8105845: {"channel":"orderbook","market":"WBTC/USD","type":"update","data":{"time":1651237312.6837392,"checksum":657344097,"bids":[[38901.0,0.0107],[35496.0,0.0]],"asks":[],"action":"update"}}
1651237312.8106325: {"channel":"orderbook","market":"SOL/USD","type":"update","data":{"time":1651237312.6825123,"checksum":3827085681,"bids":[[95.705,11.33],[95.4225,0.0]],"asks":[[95.8625,0.0],[95.9075,0.69],[96.3225,0.62]],"action":"update"}}
1651237312.810671: {"channel":"orderbook","market":"ETH/USD","type":"update","data":{"time":1651237312.6819882,"checksum":2684766550,"bids":[[2856.5,0.015]],"asks":[[2861.7,2.774]],"action":"update"}}
1651237312.839885: {"channel":"orderbook","market":"SOL/USD","type":"update","data":{"time":1651237312.7087617,"checksum":3612780233,"bids":[[95.7975,0.0],[95.7325,27.21],[95.4225,0.12]],"asks":[[95.8225,0.0],[95.905,70.0],[96.3275,0.01]],"action":"update"}}
1651237312.8399758: {"channel":"orderbook","market":"WBTC/USD","type":"update","data":{"time":1651237312.7113638,"checksum":1496293980,"bids":[[38899.0,0.0],[35496.0,0.0001]],"asks":[],"action":"update"}}
1651237312.8815823: {"channel":"orderbook","market":"ETH/USD","type":"update","data":{"time":1651237312.7512453,"checksum":3200376442,"bids":[[2859.1,22.837]],"asks":[],"action":"update"}}
1651237312.8866456: {"channel":"orderbook","market":"SOL/USD","type":"update","data":{"time":1651237312.761764,"checksum":631748205,"bids":[],"asks":[[95.9225,252.45],[96.3275,0.0]],"action":"update"}}
1651237312.9068756: {"channel":"orderbook","market":"SHIB/USD","type":"update","data":{"time":1651237312.7775552,"checksum":845294988,"bids":[[0.00002201,91100000.0]],"asks":[],"action":"update"}}
1651237312.9125986: {"channel":"orderbook","market":"SOL/USD","type":"update","data":{"time":1651237312.7840729,"checksum":4254385533,"bids":[[95.805,70.0],[95.8025,12.91],[95.4225,0.0]],"asks":[],"action":"update"}}
1651237312.924549: {"channel":"orderbook","market":"ETH/USDT","type":"update","data":{"time":1651237312.793342,"checksum":2434249017,"bids":[[2860.0,2.298],[2842.0,0.0]],"asks":[],"action":"update"}}
1651237312.9286585: {"channel":"orderbook","market":"ETH/USD","type":"update","data":{"time":1651237312.798959,"checksum":3007130024,"bids":[[2856.8,1.632]],"asks":[],"action":"update"}}
1651237312.9374073: {"channel":"orderbook","market":"FTT/BTC","type":"update","data":{"time":1651237312.810179,"checksum":3818591,"bids":[],"asks":[],"action":"update"}}
1651237312.9507222: {"channel":"orderbook","market":"SOL/USD","type":"update","data":{"time":1651237312.8211277,"checksum":4150389841,"bids":[[95.8025,17.91],[95.79,49.2],[95.775,119.51],[95.7525,600.14],[95.425,0.0]],"asks":[[95.9425,215.95]],"action":"update"}}
1651237312.9688709: {"channel":"orderbook","market":"ETH/USDT","type":"update","data":{"time":1651237312.8419178,"checksum":1718317385,"bids":[[2859.1,14.459]],"asks":[[2860.8,12.58]],"action":"update"}}
1651237312.991717: {"channel":"orderbook","market":"SOL/USD","type":"update","data":{"time":1651237312.8641117,"checksum":3390508567,"bids":[[95.8025,5.01],[95.725,33.8],[95.43,0.0]],"asks":[],"action":"update"}}
1651237312.9978037: {"channel":"orderbook","market":"ETH/USD","type":"update","data":{"time":1651237312.8651633,"checksum":4014687752,"bids":[[2855.4,3.043]],"asks":[[2862.8,0.874]],"action":"update"}}
1651237313.0018632: {"channel":"orderbook","market":"BTC/TRY","type":"update","data":{"time":1651237312.8725908,"checksum":2549750460,"bids":[],"asks":[],"action":"update"}}
1651237313.0073557: {"channel":"orderbook","market":"ETH/USD","type":"update","data":{"time":1651237312.8784678,"checksum":1585676180,"bids":[[2859.9,2.363]],"asks":[],"action":"update"}}
1651237313.0238209: {"channel":"orderbook","market":"SOL/USD","type":"update","data":{"time":1651237312.890995,"checksum":2555737680,"bids":[[95.7825,29.59]],"asks":[],"action":"update"}}
1651237313.0407207: {"channel":"orderbook","market":"SOL/USD","type":"update","data":{"time":1651237312.9152045,"checksum":3933527263,"bids":[[95.8,0.0],[95.43,0.25]],"asks":[],"action":"update"}}
1651237313.0689015: {"channel":"orderbook","market":"ETH/USD","type":"update","data":{"time":1651237312.9316425,"checksum":2819760696,"bids":[],"asks":[[2861.3,1.774]],"action":"update"}}
1651237313.0689538: {"channel":"orderbook","market":"SOL/USD","type":"update","data":{"time":1651237312.9393165,"checksum":3272007171,"bids":[[95.7725,2.11]],"asks":[],"action":"update"}}
1651237313.0991: {"channel":"orderbook","market":"SOL/USD","type":"update","data":{"time":1651237312.9641273,"checksum":3105064292,"bids":[[95.805,121.5]],"asks":[[95.9075,0.72]],"action":"update"}}
1651237313.1046615: {"channel":"orderbook","market":"ETH/USD","type":"update","data":{"time":1651237312.956924,"checksum":4209788394,"bids":[[2858.8,26.866]],"asks":[],"action":"update"}}
1651237313.11879: {"channel":"orderbook","market":"SOL/USD","type":"update","data":{"time":1651237312.9887347,"checksum":2755480247,"bids":[],"asks":[[96.13,0.0],[96.3275,0.01]],"action":"update"}}
1651237313.1319494: {"channel":"orderbook","market":"LTC/USDT","type":"update","data":{"time":1651237313.0022333,"checksum":563395091,"bids":[[100.32,306.25],[96.45,0.0]],"asks":[],"action":"update"}}
1651237313.1405575: {"channel":"orderbook","market":"ETH/USD","type":"update","data":{"time":1651237313.0124702,"checksum":1024596294,"bids":[[2859.5,1.003]],"asks":[[2860.2,9.954]],"action":"update"}}
1651237313.1466343: {"channel":"orderbook","market":"SOL/USD","type":"update","data":{"time":1651237313.0212946,"checksum":2731762034,"bids":[[95.785,70.0],[95.43,0.0]],"asks":[],"action":"update"}}
1651237313.1566722: {"channel":"orderbook","market":"ETH/USDT","type":"update","data":{"time":1651237313.0165057,"checksum":1718317385,"bids":[],"asks":[],"action":"update"}}
1651237313.1736326: {"channel":"orderbook","market":"WBTC/USD","type":"update","data":{"time":1651237313.0389624,"checksum":1496293980,"bids":[],"asks":[],"action":"update"}}
1651237313.1930988: {"channel":"orderbook","market":"ETH/USDT","type":"update","data":{"time":1651237313.0669978,"checksum":1319232992,"bids":[[2859.6,4.529]],"asks":[],"action":"update"}}
1651237313.1956635: {"channel":"orderbook","market":"LTC/USDT","type":"update","data":{"time":1651237313.0702467,"checksum":2780643013,"bids":[[100.37,48.84]],"asks":[],"action":"update"}}
1651237313.2023451: {"channel":"orderbook","market":"ETH/USD","type":"update","data":{"time":1651237313.0763946,"checksum":1902886106,"bids":[[2858.4,6.249]],"asks":[[2861.5,0.134],[2861.7,3.091],[2872.6,0.0]],"action":"update"}}
1651237313.2141101: {"channel":"orderbook","market":"SOL/USD","type":"update","data":{"time":1651237313.089399,"checksum":3440893218,"bids":[[95.7575,52.71],[95.655,24.03],[95.645,1.29],[95.435,0.0]],"asks":[],"action":"update"}}
1651237313.22635: {"channel":"orderbook","market":"ETH/USD","type":"update","data":{"time":1651237313.0997462,"checksum":3737942121,"bids":[[2853.8,0.22]],"asks":[],"action":"update"}}
1651237313.2489896: {"channel":"orderbook","market":"ETH/USDT","type":"update","data":{"time":1651237313.1179926,"checksum":3326957442,"bids":[[2858.6,4.767]],"asks":[[2860.2,7.125]],"action":"update"}}
1651237313.2542403: {"channel":"orderbook","market":"ETH/USD","type":"update","data":{"time":1651237313.1260884,"checksum":2926019177,"bids":[[2858.0,4.421],[2853.9,0.45]],"asks":[],"action":"update"}}
1651237313.2697196: {"channel":"orderbook","market":"SOL/USD","type":"update","data":{"time":1651237313.1215312,"checksum":3045809784,"bids":[[95.7825,9.59]],"asks":[[95.825,0.0],[95.8325,70.0],[95.8975,58.55],[96.33,0.26]],"action":"update"}}
1651237313.2697968: {"channel":"orderbook","market":"SOL/USD","type":"update","data":{"time":1651237313.1415048,"checksum":505657026,"bids":[[95.61,336.2]],"asks":[[95.8325,0.0],[96.3325,0.13]],"action":"update"}}
1651237313.2841613: {"channel":"orderbook","market":"ETH/USDT","type":"update","data":{"time":1651237313.1472232,"checksum":3166904682,"bids":[[2858.7,13.914]],"asks":[],"action":"update"}}
1651237313.2983685: {"channel":"orderbook","market":"ETH/USDT","type":"update","data":{"time":1651237313.1670768,"checksum":3581365892,"bids":[[2860.1,4.05]],"asks":[[2860.2,7.286]],"action":"update"}}
1651237313.2984173: {"channel":"orderbook","market":"SOL/USD","type":"update","data":{"time":1651237313.169591,"checksum":3740437557,"bids":[[95.8075,70.0],[95.69,179.6],[95.6375,22.4],[95.4375,0.0]],"asks":[[95.845,0.0],[95.895,0.0],[95.97,3.21],[96.3375,0.29]],"action":"update"}}
1651237313.3021414: {"channel":"orderbook","market":"LTC/USDT","type":"update","data":{"time":1651237313.1773381,"checksum":2931017764,"bids":[],"asks":[[100.78,0.35]],"action":"update"}}
1651237313.3061018: {"channel":"orderbook","market":"ETH/USD","type":"update","data":{"time":1651237313.1776474,"checksum":2219566813,"bids":[[2858.4,6.566]],"asks":[],"action":"update"}}
1651237313.3654346: {"channel":"orderbook","market":"SHIB/USD","type":"update","data":{"time":1651237313.183969,"checksum":3233617208,"bids":[[0.00002256,233100000.0]],"asks":[],"action":"update"}}
1651237313.3654969: {"channel":"orderbook","market":"ETH/USDT","type":"update","data":{"time":1651237313.1921408,"checksum":1015449651,"bids":[[2859.7,40.775]],"asks":[],"action":"update"}}
1651237313.3655355: {"channel":"orderbook","market":"SOL/USD","type":"update","data":{"time":1651237313.191649,"checksum":3049471619,"bids":[[95.805,51.5],[95.79,69.2],[95.7475,0.0],[95.4375,0.01]],"asks":[[95.82,0.01],[95.8325,36.0],[95.8425,0.0],[95.9025,0.0]],"action":"update"}}
1651237313.3656015: {"channel":"orderbook","market":"ETH/USD","type":"update","data":{"time":1651237313.199881,"checksum":288488662,"bids":[[2859.8,0.0],[2848.6,0.198]],"asks":[],"action":"update"}}
1651237313.3656406: {"channel":"orderbook","market":"WBTC/USD","type":"update","data":{"time":1651237313.2034383,"checksum":3316773846,"bids":[[38815.0,0.0],[35386.0,0.0017]],"asks":[],"action":"update"}}
1651237313.3656778: {"channel":"orderbook","market":"SOL/USD","type":"update","data":{"time":1651237313.2182584,"checksum":1868283165,"bids":[],"asks":[[95.8325,0.0],[95.845,96.9],[95.8525,130.16],[95.8675,0.0],[95.915,31.3],[95.9425,688.26],[96.3375,0.0]],"action":"update"}}
1651237313.3944387: {"channel":"orderbook","market":"SOL/USD","type":"update","data":{"time":1651237313.2444515,"checksum":3302791967,"bids":[[95.785,0.0],[95.7825,10.31],[95.435,0.01]],"asks":[[95.875,0.0],[95.9675,100.05]],"action":"update"}}
1651237313.3945565: {"channel":"orderbook","market":"ETH/USD","type":"update","data":{"time":1651237313.2556539,"checksum":2185750823,"bids":[[2859.2,3.514]],"asks":[],"action":"update"}}
1651237313.3946238: {"channel":"orderbook","market":"SOL/USD","type":"update","data":{"time":1651237313.263161,"checksum":2052999427,"bids":[],"asks":[[95.92,63.13],[95.945,0.06],[96.0425,0.0]],"action":"update"}}
1651237313.4049706: {"channel":"orderbook","market":"SHIB/USD","type":"update","data":{"time":1651237313.2754393,"checksum":1586118874,"bids":[[0.00002204,37900000.0]],"asks":[],"action":"update"}}
1651237313.416758: {"channel":"orderbook","market":"ETH/USDT","type":"update","data":{"time":1651237313.2538724,"checksum":1404832164,"bids":[],"asks":[[2864.7,0.0],[2864.9,10.924],[2882.0,0.049]],"action":"update"}}
1651237313.439071: {"channel":"orderbook","market":"SOL/USD","type":"update","data":{"time":1651237313.293793,"checksum":3836149491,"bids":[[95.81,62.64],[95.7025,0.0],[95.655,50.13]],"asks":[[95.855,0.0],[95.8875,176.58],[95.93,96.75],[95.9425,538.2],[96.3375,0.29]],"action":"update"}}
1651237313.439161: {"channel":"orderbook","market":"ETH/USD","type":"update","data":{"time":1651237313.3000364,"checksum":3439150092,"bids":[],"asks":[[2867.4,0.03]],"action":"update"}}
1651237313.4391978: {"channel":"orderbook","market":"SOL/USD","type":"update","data":{"time":1651237313.3131528,"checksum":3540745170,"bids":[[95.8075,0.0],[95.43,0.25]],"asks":[[95.9075,106.03]],"action":"update"}}
1651237313.4744983: {"channel":"orderbook","market":"LTC/USDT","type":"update","data":{"time":1651237313.3158255,"checksum":2931017764,"bids":[],"asks":[],"action":"update"}}
1651237313.4745386: {"channel":"orderbook","market":"SHIB/USD","type":"update","data":{"time":1651237313.325473,"checksum":1586118874,"bids":[],"asks":[],"action":"update"}}
1651237313.4745662: {"channel":"orderbook","market":"ETH/USD","type":"update","data":{"time":1651237313.3270524,"checksum":1440353911,"bids":[],"asks":[[2862.7,4.082]],"action":"update"}}
1651237313.4746053: {"channel":"orderbook","market":"SOL/USD","type":"update","data":{"time":1651237313.3389008,"checksum":2776876089,"bids":[[95.8025,0.01]],"asks":[[95.9075,106.0],[95.9425,65.89],[95.965,600.14],[95.9675,0.0]],"action":"update"}}
1651237313.4746518: {"channel":"orderbook","market":"ETH/USDT","type":"update","data":{"time":1651237313.3394632,"checksum":3530716223,"bids":[[2859.2,11.216]],"asks":[[2860.7,11.265]],"action":"update"}}
1651237313.5107405: {"channel":"orderbook","market":"SOL/USD","type":"update","data":{"time":1651237313.3632226,"checksum":2418358337,"bids":[[95.655,24.03],[95.5925,0.18]],"asks":[],"action":"update"}}
1651237313.510803: {"channel":"orderbook","market":"ETH/USDT","type":"update","data":{"time":1651237313.370174,"checksum":4271610972,"bids":[],"asks":[[2860.2,7.447]],"action":"update"}}
1651237313.5281758: {"channel":"orderbook","market":"SOL/USD","type":"update","data":{"time":1651237313.3905885,"checksum":1078292960,"bids":[[95.7375,165.28],[95.7175,0.0],[95.425,1.23]],"asks":[[95.82,0.0],[95.9075,0.69],[95.93,34.11],[96.3425,0.05]],"action":"update"}}
1651237313.5336478: {"channel":"orderbook","market":"USD/TRY","type":"update","data":{"time":1651237313.40739,"checksum":2845795420,"bids":[[13.8448,2163.0]],"asks":[],"action":"update"}}
1651237313.553577: {"channel":"orderbook","market":"SOL/USD","type":"update","data":{"time":1651237313.4235232,"checksum":1807084019,"bids":[[95.805,0.0],[95.795,137.87],[95.4225,0.12]],"asks":[[96.0675,26.1],[96.15,275.32],[96.3375,0.0],[96.3425,0.0]],"action":"update"}}
1651237313.553643: {"channel":"orderbook","market":"ETH/USD","type":"update","data":{"time":1651237313.4260828,"checksum":3680168065,"bids":[],"asks":[[2863.4,28.135]],"action":"update"}}
1651237313.575112: {"channel":"orderbook","market":"ETH/USDT","type":"update","data":{"time":1651237313.4464846,"checksum":3341933934,"bids":[],"asks":[[2860.9,52.828]],"action":"update"}}
1651237313.58696: {"channel":"orderbook","market":"SOL/USD","type":"update","data":{"time":1651237313.4547966,"checksum":2294569760,"bids":[[95.8175,103.0],[95.81,0.0],[95.805,5.0],[95.795,78.62],[95.7425,0.0]],"asks":[],"action":"update"}}
1651237313.600281: {"channel":"orderbook","market":"ETH/USDT","type":"update","data":{"time":1651237313.4675407,"checksum":1947277161,"bids":[[2859.1,15.459]],"asks":[],"action":"update"}}
1651237313.6049342: {"channel":"orderbook","market":"SOL/USD","type":"update","data":{"time":1651237313.4728708,"checksum":644462615,"bids":[[95.8225,70.0],[95.81,54.0],[95.7475,105.3],[95.6925,26.1],[95.435,0.0],[95.43,0.0],[95.425,0.0],[95.4225,0.0]],"asks":[[95.9425,0.0],[96.3375,0.29]],"action":"update"}}
1651237313.6411154: {"channel":"orderbook","market":"ETH/USD","type":"update","data":{"time":1651237313.477205,"checksum":2606879942,"bids":[],"asks":[[2861.8,4.025]],"action":"update"}}
1651237313.6411614: {"channel":"orderbook","market":"SOL/USD","type":"update","data":{"time":1651237313.4987538,"checksum":2742097067,"bids":[[95.81,0.0],[95.7475,0.0],[95.435,0.01],[95.43,0.25]],"asks":[[95.8875,246.58],[95.9175,0.0],[96.3425,0.05]],"action":"update"}}
1651237313.6412072: {"channel":"orderbook","market":"ETH/USD","type":"update","data":{"time":1651237313.501198,"checksum":2547629231,"bids":[],"asks":[[2862.6,2.121],[2872.3,0.0]],"action":"update"}}
1651237313.641234: {"channel":"orderbook","market":"DAI/USD","type":"update","data":{"time":1651237313.5030112,"checksum":2637841829,"bids":[],"asks":[],"action":"update"}}
1651237313.6710382: {"channel":"orderbook","market":"SHIB/USD","type":"update","data":{"time":1651237313.528621,"checksum":3394019187,"bids":[],"asks":[[0.00002261,40700000.0]],"action":"update"}}
1651237313.6711023: {"channel":"orderbook","market":"ETH/USD","type":"update","data":{"time":1651237313.53136,"checksum":2709564021,"bids":[[2859.5,0.003]],"asks":[],"action":"update"}}
1651237313.671156: {"channel":"orderbook","market":"SOL/USD","type":"update","data":{"time":1651237313.5274744,"checksum":1997511569,"bids":[[95.745,0.0],[95.425,1.23]],"asks":[],"action":"update"}}
1651237313.671189: {"channel":"orderbook","market":"ETH/USDT","type":"update","data":{"time":1651237313.538768,"checksum":3341933934,"bids":[[2859.1,14.459]],"asks":[],"action":"update"}}
1651237313.6756039: {"channel":"orderbook","market":"SOL/USD","type":"update","data":{"time":1651237313.5485585,"checksum":1977782923,"bids":[[95.8225,78.62]],"asks":[[95.8575,0.0],[95.885,138.31]],"action":"update"}}
1651237313.6801863: {"channel":"orderbook","market":"ETH/USD","type":"update","data":{"time":1651237313.5530899,"checksum":2624041629,"bids":[[2854.1,3.048]],"asks":[],"action":"update"}}
1651237313.7016854: {"channel":"orderbook","market":"SOL/USD","type":"update","data":{"time":1651237313.5741446,"checksum":1110278743,"bids":[[95.79,71.42],[95.745,137.66],[95.6925,0.0]],"asks":[[95.97,69.09]],"action":"update"}}
1651237313.7204363: {"channel":"orderbook","market":"ETH/USD","type":"update","data":{"time":1651237313.5793314,"checksum":2624041629,"bids":[],"asks":[],"action":"update"}}
1651237313.7336526: {"channel":"orderbook","market":"SHIB/USD","type":"update","data":{"time":1651237313.6004314,"checksum":2352693208,"bids":[[0.00002253,23500000.0]],"asks":[],"action":"update"}}
1651237313.7337117: {"channel":"orderbook","market":"SOL/USD","type":"update","data":{"time":1651237313.605162,"checksum":3514117506,"bids":[[95.6325,184.61],[95.425,0.0]],"asks":[],"action":"update"}}
1651237313.74529: {"channel":"orderbook","market":"FTT/BTC","type":"update","data":{"time":1651237313.6153808,"checksum":3816379411,"bids":[],"asks":[[0.0010099,41.2]],"action":"update"}}
1651237313.7553432: {"channel":"orderbook","market":"SOL/USD","type":"update","data":{"time":1651237313.6277008,"checksum":3512449408,"bids":[],"asks":[[95.9025,105.31],[96.1,26.13],[96.3425,0.0]],"action":"update"}}
1651237313.7553887: {"channel":"orderbook","market":"ETH/USD","type":"update","data":{"time":1651237313.6278121,"checksum":1437910771,"bids":[],"asks":[[2862.8,0.954]],"action":"update"}}
1651237313.7671278: {"channel":"orderbook","market":"LTC/USDT","type":"update","data":{"time":1651237313.642266,"checksum":964231596,"bids":[],"asks":[[100.605,2.33],[103.84,0.0]],"action":"update"}}
1651237313.777562: {"channel":"orderbook","market":"USD/TRY","type":"update","data":{"time":1651237313.6510234,"checksum":2845795420,"bids":[],"asks":[],"action":"update"}}
1651237313.7984004: {"channel":"orderbook","market":"SOL/USD","type":"update","data":{"time":1651237313.6631985,"checksum":3281897552,"bids":[[95.805,0.0],[95.425,1.23]],"asks":[[95.845,0.0],[95.8525,0.0],[96.3425,0.05],[96.3475,0.3]],"action":"update"}}
1651237313.811459: {"channel":"orderbook","market":"ETH/USD","type":"update","data":{"time":1651237313.6806386,"checksum":47492545,"bids":[],"asks":[[2860.0,40.55]],"action":"update"}}
1651237313.8115149: {"channel":"orderbook","market":"FTT/BTC","type":"update","data":{"time":1651237313.6863368,"checksum":3818591,"bids":[],"asks":[[0.0010099,30.7]],"action":"update"}}
1651237313.8277974: {"channel":"orderbook","market":"SHIB/USD","type":"update","data":{"time":1651237313.7018986,"checksum":73744865,"bids":[],"asks":[[0.00002262,358000000.0]],"action":"update"}}
1651237313.828285: {"channel":"orderbook","market":"ETH/USD","type":"update","data":{"time":1651237313.7022598,"checksum":23056533,"bids":[[2859.9,5.813]],"asks":[],"action":"update"}}
1651237313.8285432: {"channel":"orderbook","market":"SOL/USD","type":"update","data":{"time":1651237313.7016406,"checksum":3253000400,"bids":[],"asks":[[95.9025,0.0],[96.35,0.33]],"action":"update"}}
1651237313.8719652: {"channel":"orderbook","market":"ETH/USD","type":"update","data":{"time":1651237313.7423546,"checksum":1747689073,"bids":[],"asks":[[2860.0,37.1]],"action":"update"}}
1651237313.8720253: {"channel":"orderbook","market":"SOL/USD","type":"update","data":{"time":1651237313.740713,"checksum":1331050455,"bids":[[95.865,70.0],[95.425,0.0]],"asks":[[95.8825,62.78],[95.8875,185.28],[96.35,0.0]],"action":"update"}}
1651237313.8788013: {"channel":"orderbook","market":"ETH/USD","type":"update","data":{"time":1651237313.7524524,"checksum":1320216850,"bids":[],"asks":[[2860.5,11.072]],"action":"update"}}
1651237313.906759: {"channel":"orderbook","market":"SOL/USD","type":"update","data":{"time":1651237313.7662237,"checksum":2746321514,"bids":[[95.8225,8.62],[95.8025,105.33]],"asks":[[95.8875,115.28],[96.0425,48.0],[96.3475,0.0]],"action":"update"}}
1651237313.915642: {"channel":"orderbook","market":"ETH/USD","type":"update","data":{"time":1651237313.777064,"checksum":1388528097,"bids":[],"asks":[[2860.4,6.501],[2866.4,4.275]],"action":"update"}}
1651237313.9293797: {"channel":"orderbook","market":"SOL/USD","type":"update","data":{"time":1651237313.7967951,"checksum":3657622659,"bids":[[95.865,0.0],[95.765,420.63],[95.7525,662.78],[95.68,0.0],[95.425,1.23],[95.4225,0.12]],"asks":[[95.8825,128.22],[95.885,208.31]],"action":"update"}}
1651237313.949397: {"channel":"orderbook","market":"ETH/USD","type":"update","data":{"time":1651237313.8208559,"checksum":3273021492,"bids":[[2855.4,5.099]],"asks":[],"action":"update"}}
1651237313.9607215: {"channel":"orderbook","market":"SOL/USD","type":"update","data":{"time":1651237313.8301532,"checksum":1033521868,"bids":[[95.8025,0.01],[95.66,96.92]],"asks":[[95.88,36.0],[95.8825,128.21],[95.885,269.98],[95.9,0.0],[95.955,62.64],[95.97,3.21],[96.3425,0.0]],"action":"update"}}
1651237313.9732766: {"channel":"orderbook","market":"FTT/BTC","type":"update","data":{"time":1651237313.8431497,"checksum":3818591,"bids":[],"asks":[],"action":"update"}}
1651237313.9984896: {"channel":"orderbook","market":"ETH/USD","type":"update","data":{"time":1651237313.8632627,"checksum":1107750030,"bids":[],"asks":[[2860.6,49.143]],"action":"update"}}
1651237314.008663: {"channel":"orderbook","market":"SOL/USD","type":"update","data":{"time":1651237313.8736992,"checksum":3353719988,"bids":[[95.8225,0.0],[95.41,0.01]],"asks":[[95.885,138.31],[95.8975,0.0],[95.9125,118.8],[95.9225,253.72],[95.9425,61.3],[95.945,0.0],[96.0675,0.0],[96.3425,0.05]],"action":"update"}}
1651237314.0087357: {"channel":"orderbook","market":"SHIB/USD","type":"update","data":{"time":1651237313.877885,"checksum":2142710658,"bids":[],"asks":[[0.00002266,196000000.0]],"action":"update"}}
1651237314.0207708: {"channel":"orderbook","market":"SOL/USD","type":"update","data":{"time":1651237313.891521,"checksum":4258754182,"bids":[],"asks":[[95.855,96.9],[95.9225,252.45],[96.3425,0.0]],"action":"update"}}
1651237314.020828: {"channel":"orderbook","market":"BTC/TRY","type":"update","data":{"time":1651237313.8932934,"checksum":2549750460,"bids":[],"asks":[],"action":"update"}}
1651237314.0539355: {"channel":"orderbook","market":"SOL/USD","type":"update","data":{"time":1651237313.9208367,"checksum":1448498042,"bids":[[95.8225,70.0],[95.8175,0.0]],"asks":[[95.8625,130.12],[95.88,0.0],[95.8825,198.21],[96.0425,0.0],[96.3425,0.05]],"action":"update"}}
1651237314.0704455: {"channel":"orderbook","market":"SHIB/USD","type":"update","data":{"time":1651237313.9401507,"checksum":1688712634,"bids":[],"asks":[[0.00002265,229900000.0]],"action":"update"}}
1651237314.0705004: {"channel":"orderbook","market":"ETH/USD","type":"update","data":{"time":1651237313.9387822,"checksum":1852113491,"bids":[[2855.2,0.006]],"asks":[],"action":"update"}}
1651237314.0889525: {"channel":"orderbook","market":"FTT/BTC","type":"update","data":{"time":1651237313.9532843,"checksum":3983242518,"bids":[[0.0010089,13.5],[0.0009964,0.0]],"asks":[],"action":"update"}}
1651237314.0889993: {"channel":"orderbook","market":"SOL/USD","type":"update","data":{"time":1651237313.9517653,"checksum":3909168327,"bids":[[95.8175,70.0],[95.7725,7.11],[95.41,0.0]],"asks":[[95.8525,36.0],[95.855,0.0],[95.86,70.0],[95.88,70.0],[95.8825,70.0],[95.9175,0.03],[96.0475,236.91],[96.3325,0.0],[96.3375,0.0],[96.3425,0.0]],"action":"update"}}
1651237314.1011817: {"channel":"orderbook","market":"SOL/USD","type":"update","data":{"time":1651237313.9758143,"checksum":4205764471,"bids":[[95.7725,2.11]],"asks":[[95.9,105.31],[95.9425,83.07],[96.33,0.0]],"action":"update"}}
1651237314.1104894: {"channel":"orderbook","market":"ETH/USD","type":"update","data":{"time":1651237313.9826033,"checksum":1233104811,"bids":[],"asks":[[2866.6,0.747]],"action":"update"}}
1651237314.1320274: {"channel":"orderbook","market":"SOL/USD","type":"update","data":{"time":1651237313.9983578,"checksum":2890007500,"bids":[[95.8175,0.0],[95.79,51.42],[95.41,0.01]],"asks":[[95.8525,0.0],[95.86,0.0],[95.88,0.0],[95.8825,0.0],[95.89,167.21],[96.33,0.26],[96.3325,0.13],[96.3375,0.29],[96.3425,0.05]],"action":"update"}}
1651237314.1386585: {"channel":"orderbook","market":"ETH/USD","type":"update","data":{"time":1651237314.008981,"checksum":878584331,"bids":[[2855.4,6.099]],"asks":[],"action":"update"}}
1651237314.1499357: {"channel":"orderbook","market":"SOL/USD","type":"update","data":{"time":1651237314.019992,"checksum":2613004044,"bids":[],"asks":[[95.8625,137.39]],"action":"update"}}
1651237314.1639678: {"channel":"orderbook","market":"ETH/USD","type":"update","data":{"time":1651237314.0320702,"checksum":1756383942,"bids":[],"asks":[[2865.8,2.057]],"action":"update"}}
1651237314.1662798: {"channel":"orderbook","market":"LTC/USDT","type":"update","data":{"time":1651237314.0410662,"checksum":3350239866,"bids":[[100.42,0.0],[96.45,1.02]],"asks":[],"action":"update"}}
1651237314.1766768: {"channel":"orderbook","market":"SOL/USD","type":"update","data":{"time":1651237314.0445476,"checksum":3919406353,"bids":[[95.75,112.94]],"asks":[[95.845,96.9],[95.8575,36.0],[95.9625,135.88],[96.065,26.1],[96.3325,0.0],[96.3375,0.0],[96.3425,0.0]],"action":"update"}}
1651237314.1784277: {"channel":"orderbook","market":"ETH/USDT","type":"update","data":{"time":1651237314.0508754,"checksum":3341933934,"bids":[],"asks":[],"action":"update"}}
1651237314.1829321: {"channel":"orderbook","market":"ETH/USD","type":"update","data":{"time":1651237314.0572417,"checksum":3698636641,"bids":[],"asks":[[2860.0,37.585]],"action":"update"}}
1651237314.1829796: {"channel":"orderbook","market":"WBTC/USD","type":"update","data":{"time":1651237314.0556717,"checksum":3316773846,"bids":[],"asks":[],"action":"update"}}
1651237314.2600365: {"channel":"orderbook","market":"SOL/USD","type":"update","data":{"time":1651237314.1105196,"checksum":3455951391,"bids":[[95.8025,31.31],[95.7975,20.0],[95.41,0.0]],"asks":[[95.8425,36.0],[95.8575,0.0],[95.9425,61.3],[95.955,0.0],[95.9575,257.6],[95.965,600.2]],"action":"update"}}
1651237314.260363: {"channel":"orderbook","market":"ETH/USD","type":"update","data":{"time":1651237314.133142,"checksum":1666695757,"bids":[],"asks":[[2864.3,13.959]],"action":"update"}}
1651237314.2769654: {"channel":"orderbook","market":"FTT/BTC","type":"update","data":{"time":1651237314.1418,"checksum":2986335209,"bids":[],"asks":[[0.0010095,13.5],[0.001024,0.0]],"action":"update"}}
1651237314.284264: {"channel":"orderbook","market":"ETH/USD","type":"update","data":{"time":1651237314.156634,"checksum":3381943654,"bids":[],"asks":[[2862.8,0.874]],"action":"update"}}
1651237314.3243134: {"channel":"orderbook","market":"SOL/USD","type":"update","data":{"time":1651237314.1967177,"checksum":3810901037,"bids":[[95.7825,0.72]],"asks":[],"action":"update"}}
1651237314.337252: {"channel":"orderbook","market":"ETH/USD","type":"update","data":{"time":1651237314.2085278,"checksum":1097380033,"bids":[],"asks":[[2862.8,0.959]],"action":"update"}}
1651237314.356915: {"channel":"orderbook","market":"SOL/USD","type":"update","data":{"time":1651237314.2240455,"checksum":1617007764,"bids":[[95.8,8.11],[95.7575,0.0]],"asks":[[95.9175,0.0],[96.015,0.0],[96.3325,0.13],[96.3375,0.29]],"action":"update"}}
1651237314.3616774: {"channel":"orderbook","market":"ETH/USDT","type":"update","data":{"time":1651237314.2310815,"checksum":4266938196,"bids":[],"asks":[[2860.2,5.397]],"action":"update"}}
1651237314.365016: {"channel":"orderbook","market":"ETH/USD","type":"update","data":{"time":1651237314.2335865,"checksum":501979132,"bids":[],"asks":[[2860.2,7.317],[2865.0,3.034]],"action":"update"}}
1651237314.3761861: {"channel":"orderbook","market":"SOL/USD","type":"update","data":{"time":1651237314.2415652,"checksum":3117839327,"bids":[[95.815,5.0],[95.8025,31.3],[95.4225,0.0]],"asks":[],"action":"update"}}
1651237314.3802948: {"channel":"orderbook","market":"WBTC/USD","type":"update","data":{"time":1651237314.2468083,"checksum":4288387767,"bids":[],"asks":[[39027.0,0.0004],[44095.0,0.0]],"action":"update"}}
1651237314.4003067: {"channel":"orderbook","market":"ETH/USD","type":"update","data":{"time":1651237314.2598035,"checksum":4164044378,"bids":[[2859.9,5.785]],"asks":[[2860.0,2.1]],"action":"update"}}
1651237314.4003494: {"channel":"orderbook","market":"LTC/USDT","type":"update","data":{"time":1651237314.2680168,"checksum":2136361037,"bids":[],"asks":[[100.605,0.0],[100.615,18.45],[103.84,0.18]],"action":"update"}}
1651237314.4235735: {"channel":"orderbook","market":"SOL/USD","type":"update","data":{"time":1651237314.2865887,"checksum":1118038145,"bids":[],"asks":[[95.9,0.0],[96.3425,0.05]],"action":"update"}}
1651237314.4236398: {"channel":"orderbook","market":"LTC/USDT","type":"update","data":{"time":1651237314.2916594,"checksum":413553879,"bids":[[100.42,17.2],[96.45,0.0]],"asks":[],"action":"update"}}
1651237314.4482055: {"channel":"orderbook","market":"ETH/USD","type":"update","data":{"time":1651237314.3101861,"checksum":1730319860,"bids":[],"asks":[[2860.1,5.327],[2864.0,2.445]],"action":"update"}}
1651237314.4482522: {"channel":"orderbook","market":"LTC/USDT","type":"update","data":{"time":1651237314.3158126,"checksum":2225278269,"bids":[],"asks":[[100.665,0.0],[103.91,0.02]],"action":"update"}}
1651237314.4678085: {"channel":"orderbook","market":"ETH/USD","type":"update","data":{"time":1651237314.3333406,"checksum":689636517,"bids":[],"asks":[[2860.6,31.839],[2861.3,8.074]],"action":"update"}}
1651237314.4678667: {"channel":"orderbook","market":"ETH/USDT","type":"update","data":{"time":1651237314.3415012,"checksum":2828905578,"bids":[[2859.3,8.712]],"asks":[[2860.6,2.82],[2882.0,0.0]],"action":"update"}}
1651237314.470604: {"channel":"orderbook","market":"LTC/USDT","type":"update","data":{"time":1651237314.3421693,"checksum":2225278269,"bids":[],"asks":[],"action":"update"}}
1651237314.4934359: {"channel":"orderbook","market":"SOL/USD","type":"update","data":{"time":1651237314.360338,"checksum":3557170259,"bids":[],"asks":[[95.955,64.44],[96.3425,0.0]],"action":"update"}}
1651237314.493503: {"channel":"orderbook","market":"SHIB/USD","type":"update","data":{"time":1651237314.3539577,"checksum":1688712634,"bids":[],"asks":[],"action":"update"}}
1651237314.523333: {"channel":"orderbook","market":"ETH/USD","type":"update","data":{"time":1651237314.3845,"checksum":1870034560,"bids":[[2858.9,24.265]],"asks":[],"action":"update"}}
1651237314.5356002: {"channel":"orderbook","market":"ETH/USDT","type":"update","data":{"time":1651237314.4042761,"checksum":2028002623,"bids":[],"asks":[[2860.2,5.075],[2860.3,5.998],[2860.9,33.002]],"action":"update"}}
1651237314.5452752: {"channel":"orderbook","market":"LTC/USDT","type":"update","data":{"time":1651237314.4155076,"checksum":1243329517,"bids":[],"asks":[[100.605,50.13],[103.91,0.0]],"action":"update"}}
1651237314.5453134: {"channel":"orderbook","market":"ETH/USD","type":"update","data":{"time":1651237314.4096117,"checksum":1314132985,"bids":[],"asks":[[2860.8,3.846],[2862.1,8.797],[2864.1,0.35]],"action":"update"}}
1651237314.548865: {"channel":"orderbook","market":"SOL/USD","type":"update","data":{"time":1651237314.4188664,"checksum":3938049603,"bids":[[95.8225,74.65],[95.7525,600.14]],"asks":[[95.95,166.97]],"action":"update"}}
1651237314.566014: {"channel":"orderbook","market":"ETH/USDT","type":"update","data":{"time":1651237314.435165,"checksum":2615764620,"bids":[[2859.2,9.467]],"asks":[[2860.2,0.0],[2860.3,2.5],[2882.0,0.049]],"action":"update"}}
1651237314.5661125: {"channel":"orderbook","market":"SHIB/USD","type":"update","data":{"time":1651237314.4359221,"checksum":335555237,"bids":[],"asks":[[0.00002261,18000000.0],[0.00002262,335800000.0]],"action":"update"}}
1651237314.5661848: {"channel":"orderbook","market":"ETH/USD","type":"update","data":{"time":1651237314.4348834,"checksum":585408975,"bids":[[2858.2,24.977]],"asks":[[2860.0,0.0],[2872.3,0.051]],"action":"update"}}
1651237314.5662625: {"channel":"orderbook","market":"LTC/USDT","type":"update","data":{"time":1651237314.440781,"checksum":4230329063,"bids":[],"asks":[[100.61,0.0],[103.91,0.02]],"action":"update"}}
1651237314.5842793: {"channel":"orderbook","market":"SHIB/USD","type":"update","data":{"time":1651237314.4530795,"checksum":275172007,"bids":[],"asks":[[0.00002263,380500000.0]],"action":"update"}}
1651237314.5843391: {"channel":"orderbook","market":"ETH/USDT","type":"update","data":{"time":1651237314.4555373,"checksum":2654878336,"bids":[[2860.1,2.05],[2858.9,12.216]],"asks":[[2860.3,0.0],[2882.1,0.011]],"action":"update"}}
1651237314.593189: {"channel":"orderbook","market":"ETH/USD","type":"update","data":{"time":1651237314.4596672,"checksum":1040617214,"bids":[[2859.9,3.983],[2859.7,0.324],[2858.8,23.369],[2848.6,0.0]],"asks":[[2860.1,3.493],[2860.4,4.752],[2860.7,33.233]],"action":"update"}}
1651237314.6079357: {"channel":"orderbook","market":"SOL/USD","type":"update","data":{"time":1651237314.4713132,"checksum":1268106356,"bids":[[95.8225,126.15]],"asks":[],"action":"update"}}
1651237314.6079915: {"channel":"orderbook","market":"LTC/USDT","type":"update","data":{"time":1651237314.4688091,"checksum":2182847815,"bids":[[100.55,50.13],[96.5,0.0]],"asks":[],"action":"update"}}
1651237314.6153598: {"channel":"orderbook","market":"SHIB/USD","type":"update","data":{"time":1651237314.4796436,"checksum":966910577,"bids":[[0.00002258,409800000.0],[0.00002257,314900000.0]],"asks":[[0.00002262,205500000.0]],"action":"update"}}
1651237314.6154149: {"channel":"orderbook","market":"ETH/USDT","type":"update","data":{"time":1651237314.480435,"checksum":2813924408,"bids":[[2859.7,41.018],[2859.1,10.962]],"asks":[[2860.5,4.529],[2860.9,16.508],[2861.0,43.262]],"action":"update"}}
1651237314.6341035: {"channel":"orderbook","market":"ETH/USD","type":"update","data":{"time":1651237314.486108,"checksum":1421804544,"bids":[[2859.9,6.083],[2859.3,5.661],[2859.1,19.34],[2856.7,0.384]],"asks":[[2860.1,0.0],[2860.2,1.868],[2860.6,28.342],[2863.4,36.961],[2864.1,0.001],[2872.6,0.005]],"action":"update"}}
1651237314.6341743: {"channel":"orderbook","market":"LTC/USDT","type":"update","data":{"time":1651237314.4925454,"checksum":3262366512,"bids":[[100.52,0.0],[100.485,7.46],[100.42,37.97]],"asks":[],"action":"update"}}
1651237314.634206: {"channel":"orderbook","market":"SOL/USD","type":"update","data":{"time":1651237314.4928458,"checksum":2564432814,"bids":[],"asks":[[95.9075,105.99]],"action":"update"}}
1651237314.6603322: {"channel":"orderbook","market":"SHIB/USD","type":"update","data":{"time":1651237314.5038047,"checksum":447770745,"bids":[[0.0000226,108000000.0]],"asks":[[0.00002261,0.0],[0.00002262,176600000.0],[0.00002265,252100000.0],[0.00002374,700000.0]],"action":"update"}}
1651237314.6603928: {"channel":"orderbook","market":"ETH/USD","type":"update","data":{"time":1651237314.5092244,"checksum":2734863947,"bids":[[2860.0,1.975],[2859.9,3.983],[2848.7,0.0]],"asks":[[2860.2,0.0],[2860.3,25.736],[2861.6,27.608],[2864.8,0.0],[2872.7,0.001],[2872.8,4.022]],"action":"update"}}
1651237314.6604443: {"channel":"orderbook","market":"ETH/USDT","type":"update","data":{"time":1651237314.5110023,"checksum":1666659609,"bids":[],"asks":[[2860.7,4.344],[2860.8,8.462],[2861.4,0.175],[2861.6,31.051]],"action":"update"}}
1651237314.680953: {"channel":"orderbook","market":"SHIB/USD","type":"update","data":{"time":1651237314.530622,"checksum":23227314,"bids":[[0.00002256,190600000.0]],"asks":[],"action":"update"}}
1651237314.6810012: {"channel":"orderbook","market":"DAI/USD","type":"update","data":{"time":1651237314.5299828,"checksum":2637841829,"bids":[],"asks":[],"action":"update"}}
1651237314.6810236: {"channel":"orderbook","market":"ETH/USD","type":"update","data":{"time":1651237314.5359242,"checksum":1904746414,"bids":[[2860.0,3.746],[2859.7,2.142]],"asks":[[2860.7,26.232],[2860.8,3.497],[2866.5,0.06]],"action":"update"}}
1651237314.6810603: {"channel":"orderbook","market":"ETH/USDT","type":"update","data":{"time":1651237314.5383072,"checksum":976171605,"bids":[[2859.5,1.749],[2842.2,0.0]],"asks":[[2860.4,4.509],[2860.6,0.0],[2882.2,0.011]],"action":"update"}}
1651237314.6810944: {"channel":"orderbook","market":"LTC/USDT","type":"update","data":{"time":1651237314.5513015,"checksum":3263671704,"bids":[[100.415,29.83],[96.55,0.0]],"asks":[],"action":"update"}}
1651237314.687107: {"channel":"orderbook","market":"SHIB/USD","type":"update","data":{"time":1651237314.552783,"checksum":3074608591,"bids":[[0.00002261,50000000.0],[0.0000226,130200000.0],[0.00002258,210000000.0],[0.0000216,0.0]],"asks":[[0.00002266,175000000.0]],"action":"update"}}
1651237314.689202: {"channel":"orderbook","market":"ETH/USD","type":"update","data":{"time":1651237314.5603137,"checksum":799854696,"bids":[[2860.0,7.646],[2859.2,7.011]],"asks":[[2860.3,22.517],[2860.6,14.042],[2861.2,3.497],[2861.4,3.493],[2861.5,7.044],[2872.8,0.0]],"action":"update"}}
1651237314.6950502: {"channel":"orderbook","market":"ETH/USDT","type":"update","data":{"time":1651237314.5618682,"checksum":4142432269,"bids":[[2859.5,0.0],[2859.3,12.209],[2842.2,0.001]],"asks":[[2860.4,2.5],[2861.1,3.497],[2882.2,0.0]],"action":"update"}}
1651237314.6952262: {"channel":"orderbook","market":"SOL/USD","type":"update","data":{"time":1651237314.5681925,"checksum":2669170084,"bids":[[95.815,0.0],[95.4225,0.12]],"asks":[[96.025,0.03]],"action":"update"}}
1651237314.7050977: {"channel":"orderbook","market":"WBTC/USD","type":"update","data":{"time":1651237314.571758,"checksum":2160524204,"bids":[[38897.0,0.0],[35385.0,0.0001]],"asks":[],"action":"update"}}
1651237314.7246068: {"channel":"orderbook","market":"ETH/USDT","type":"update","data":{"time":1651237314.5895226,"checksum":1513584225,"bids":[[2859.7,22.431]],"asks":[],"action":"update"}}
1651237314.7246578: {"channel":"orderbook","market":"SHIB/USD","type":"update","data":{"time":1651237314.58498,"checksum":1721286906,"bids":[[0.00002261,0.0],[0.00002255,210200000.0],[0.0000216,58000000.0]],"asks":[[0.00002262,114400000.0],[0.00002263,375300000.0],[0.00002266,215000000.0]],"action":"update"}}
1651237314.7247097: {"channel":"orderbook","market":"SOL/USD","type":"update","data":{"time":1651237314.5943267,"checksum":3181198418,"bids":[],"asks":[[96.2275,0.03]],"action":"update"}}
1651237314.7331612: {"channel":"orderbook","market":"ETH/USD","type":"update","data":{"time":1651237314.5920994,"checksum":1990710534,"bids":[[2860.2,1.746],[2860.1,7.196],[2860.0,1.746],[2859.9,3.684],[2859.5,0.0],[2858.5,25.468],[2858.2,14.867],[2848.9,0.0]],"asks":[[2860.3,8.484],[2860.5,3.979],[2860.6,6.291],[2861.8,3.842],[2863.2,3.682]],"action":"update"}}
1651237314.7352366: {"channel":"orderbook","market":"SHIB/USD","type":"update","data":{"time":1651237314.6075206,"checksum":640355798,"bids":[[0.00002261,500000.0],[0.0000226,40200000.0],[0.00002259,335900000.0],[0.00002254,193400000.0],[0.0000216,0.0]],"asks":[],"action":"update"}}
1651237314.7414708: {"channel":"orderbook","market":"ETH/USDT","type":"update","data":{"time":1651237314.6116848,"checksum":1522318285,"bids":[],"asks":[[2860.4,0.0],[2861.0,19.943],[2862.3,0.0],[2882.2,0.011],[2882.4,0.035]],"action":"update"}}
1651237314.7470915: {"channel":"orderbook","market":"LTC/USDT","type":"update","data":{"time":1651237314.6171856,"checksum":1696413162,"bids":[[100.555,12.0],[96.635,0.0]],"asks":[],"action":"update"}}
1651237314.7650206: {"channel":"orderbook","market":"ETH/USD","type":"update","data":{"time":1651237314.6209865,"checksum":4144653055,"bids":[[2860.2,2.079],[2860.1,9.096],[2859.9,3.451],[2859.1,20.34],[2858.8,6.065]],"asks":[[2862.4,37.66]],"action":"update"}}
1651237314.7651181: {"channel":"orderbook","market":"SOL/USD","type":"update","data":{"time":1651237314.6207542,"checksum":2344416357,"bids":[[95.825,70.0],[95.7375,131.86],[95.4225,0.0]],"asks":[[95.9075,0.69]],"action":"update"}}
1651237314.7652016: {"channel":"orderbook","market":"SHIB/USD","type":"update","data":{"time":1651237314.6327538,"checksum":155329497,"bids":[[0.00002261,61700000.0],[0.0000226,136200000.0],[0.00002256,102200000.0]],"asks":[],"action":"update"}}
1651237314.7797883: {"channel":"orderbook","market":"ETH/USDT","type":"update","data":{"time":1651237314.6417637,"checksum":3623211578,"bids":[[2860.2,2.0],[2859.7,22.188],[2858.7,6.993],[2842.2,0.0]],"asks":[],"action":"update"}}
1651237314.779839: {"channel":"orderbook","market":"WBTC/USD","type":"update","data":{"time":1651237314.6471417,"checksum":957467355,"bids":[],"asks":[[38974.0,0.0],[44095.0,0.0005]],"action":"update"}}
1651237314.7798684: {"channel":"orderbook","market":"ETH/USD","type":"update","data":{"time":1651237314.6471858,"checksum":2849636598,"bids":[[2860.2,4.179],[2860.1,3.45],[2860.0,0.0],[2859.9,0.001],[2859.7,3.567],[2859.3,25.444],[2858.9,17.295],[2848.9,68.482]],"asks":[[2860.7,43.535],[2861.0,4.591],[2862.1,6.002],[2862.2,0.0],[2872.8,4.022]],"action":"update"}}
1651237314.7984233: {"channel":"orderbook","market":"ETH/USDT","type":"update","data":{"time":1651237314.6653638,"checksum":3910190686,"bids":[[2859.8,5.551]],"asks":[[2860.5,7.029],[2860.8,11.886]],"action":"update"}}
1651237314.798483: {"channel":"orderbook","market":"SOL/USD","type":"update","data":{"time":1651237314.6615121,"checksum":1362029509,"bids":[[95.8225,51.5]],"asks":[[95.8425,0.0],[95.845,0.0],[95.995,7.26],[96.3425,0.05],[96.3475,0.3]],"action":"update"}}
1651237314.8056793: {"channel":"orderbook","market":"ETH/USD","type":"update","data":{"time":1651237314.669488,"checksum":3600700100,"bids":[[2859.2,3.514],[2857.0,3.512],[2856.8,1.64],[2856.7,0.034]],"asks":[[2860.5,7.498],[2860.7,26.232],[2860.8,0.0],[2860.9,0.0],[2861.0,1.094],[2872.9,0.003],[2873.1,0.002]],"action":"update"}}
1651237314.8057654: {"channel":"orderbook","market":"WBTC/USD","type":"update","data":{"time":1651237314.6742845,"checksum":301397845,"bids":[[38905.0,0.0193],[35385.0,0.0]],"asks":[],"action":"update"}}
1651237314.8058057: {"channel":"orderbook","market":"USD/TRY","type":"update","data":{"time":1651237314.677946,"checksum":2845795420,"bids":[],"asks":[],"action":"update"}}
1651237314.8201046: {"channel":"orderbook","market":"SOL/USD","type":"update","data":{"time":1651237314.6851244,"checksum":2634580898,"bids":[[95.825,78.62],[95.7975,0.0],[95.4225,0.12]],"asks":[[95.915,0.0],[95.9225,0.0],[95.95,62.64],[96.35,0.33],[96.3575,0.46]],"action":"update"}}
1651237314.8202245: {"channel":"orderbook","market":"ETH/USDT","type":"update","data":{"time":1651237314.6816506,"checksum":521269466,"bids":[[2860.2,0.0],[2842.2,0.001]],"asks":[],"action":"update"}}
1651237314.8282259: {"channel":"orderbook","market":"ETH/USD","type":"update","data":{"time":1651237314.6947243,"checksum":2482437017,"bids":[[2860.2,7.629],[2859.7,1.818],[2859.4,3.033],[2859.0,12.456]],"asks":[[2861.8,3.493],[2862.1,0.001],[2862.3,9.416]],"action":"update"}}
1651237314.8290458: {"channel":"orderbook","market":"SOL/USD","type":"update","data":{"time":1651237314.703421,"checksum":1088670405,"bids":[[95.825,141.8],[95.795,8.62],[95.775,224.82]],"asks":[[95.8625,130.12],[95.9575,0.0],[96.36,0.03]],"action":"update"}}
1651237314.848045: {"channel":"orderbook","market":"ETH/USDT","type":"update","data":{"time":1651237314.71295,"checksum":2683352055,"bids":[[2860.2,12.9],[2859.3,8.712],[2842.2,0.0]],"asks":[[2860.7,3.147],[2861.0,19.651],[2861.1,0.0],[2882.5,0.01]],"action":"update"}}
1651237314.8550925: {"channel":"orderbook","market":"FTT/BTC","type":"update","data":{"time":1651237314.7195241,"checksum":680806421,"bids":[],"asks":[[0.00101,77.0]],"action":"update"}}
1651237314.8681843: {"channel":"orderbook","market":"SOL/USD","type":"update","data":{"time":1651237314.7304664,"checksum":3892489459,"bids":[[95.7625,169.56]],"asks":[[95.8625,0.0],[95.92,0.0],[95.955,0.0],[96.3625,0.38],[96.37,2.64],[96.375,68.15]],"action":"update"}}
1651237314.868268: {"channel":"orderbook","market":"SHIB/USD","type":"update","data":{"time":1651237314.7339299,"checksum":3413701333,"bids":[[0.00002257,357400000.0]],"asks":[],"action":"update"}}
1651237314.8683066: {"channel":"orderbook","market":"ETH/USD","type":"update","data":{"time":1651237314.7350035,"checksum":3337760232,"bids":[[2860.2,9.529],[2859.4,6.542]],"asks":[[2860.3,10.584],[2860.4,0.0],[2860.7,24.932],[2861.1,0.349],[2861.2,10.862],[2861.7,2.091]],"action":"update"}}
1651237314.874704: {"channel":"orderbook","market":"ETH/USDT","type":"update","data":{"time":1651237314.745472,"checksum":1209699039,"bids":[[2860.3,2.05],[2860.1,0.0]],"asks":[[2860.5,4.529],[2862.2,0.905],[2882.5,0.0]],"action":"update"}}
1651237314.8847706: {"channel":"orderbook","market":"ETH/USD","type":"update","data":{"time":1651237314.751858,"checksum":2957286745,"bids":[[2858.5,0.687]],"asks":[[2866.2,0.001],[2873.1,0.0]],"action":"update"}}
1651237314.884813: {"channel":"orderbook","market":"LTC/USDT","type":"update","data":{"time":1651237314.753728,"checksum":1445485536,"bids":[[100.545,0.0],[96.635,0.01]],"asks":[],"action":"update"}}
1651237314.8949978: {"channel":"orderbook","market":"ETH/USDT","type":"update","data":{"time":1651237314.7631624,"checksum":3472579848,"bids":[[2860.4,2.0],[2860.3,5.28],[2860.0,2.598],[2842.5,0.0]],"asks":[[2860.8,4.965]],"action":"update"}}
1651237314.8950448: {"channel":"orderbook","market":"LTC/USDT","type":"update","data":{"time":1651237314.766718,"checksum":1069920492,"bids":[],"asks":[[100.6,12.0],[103.91,0.0]],"action":"update"}}
1651237314.8950722: {"channel":"orderbook","market":"SOL/USD","type":"update","data":{"time":1651237314.760477,"checksum":2578755185,"bids":[[95.8275,70.0],[95.805,20.0],[95.8025,0.0],[95.775,152.93],[95.7525,0.0],[95.75,8.62]],"asks":[[95.89,97.21],[95.8975,2.08],[95.935,0.0],[95.965,0.06],[95.9675,131.86],[96.375,0.0]],"action":"update"}}
1651237314.8951247: {"channel":"orderbook","market":"FTT/BTC","type":"update","data":{"time":1651237314.7689013,"checksum":430894559,"bids":[[0.001008,3.8]],"asks":[[0.00101,66.5]],"action":"update"}}
1651237314.9087408: {"channel":"orderbook","market":"ETH/USD","type":"update","data":{"time":1651237314.7760217,"checksum":1654799024,"bids":[[2857.9,133.354],[2856.9,0.005]],"asks":[[2860.3,8.481],[2860.5,3.979],[2860.6,0.0],[2860.7,19.271],[2861.0,2.842],[2861.3,6.301],[2862.4,14.112],[2863.6,0.919],[2873.1,0.002]],"action":"update"}}
1651237314.9088027: {"channel":"orderbook","market":"SHIB/USD","type":"update","data":{"time":1651237314.7793713,"checksum":1745321694,"bids":[],"asks":[[0.00002265,209600000.0]],"action":"update"}}
1651237314.9259593: {"channel":"orderbook","market":"ETH/USDT","type":"update","data":{"time":1651237314.7924602,"checksum":2598505317,"bids":[[2860.2,2.5]],"asks":[[2860.7,0.0],[2882.5,0.01]],"action":"update"}}
1651237314.9324293: {"channel":"orderbook","market":"ETH/USD","type":"update","data":{"time":1651237314.8021102,"checksum":1355985389,"bids":[[2860.0,0.241],[2855.2,4.006],[2848.9,0.0]],"asks":[[2860.6,2.732],[2861.1,3.474],[2862.3,0.001],[2873.1,0.0]],"action":"update"}}
1651237314.933465: {"channel":"orderbook","market":"SOL/USD","type":"update","data":{"time":1651237314.8028474,"checksum":824695768,"bids":[[95.825,71.8],[95.82,5.0],[95.81,70.0],[95.805,0.0],[95.725,34.3],[95.4225,0.0]],"asks":[[95.9375,252.45],[95.985,0.0],[96.035,220.64],[96.045,137.66],[96.37,0.0]],"action":"update"}}
1651237314.9335253: {"channel":"orderbook","market":"SHIB/USD","type":"update","data":{"time":1651237314.803864,"checksum":2343199819,"bids":[[0.00002256,156800000.0]],"asks":[],"action":"update"}}
1651237314.9431818: {"channel":"orderbook","market":"ETH/USDT","type":"update","data":{"time":1651237314.8081555,"checksum":1897291452,"bids":[[2860.4,2.745],[2860.0,22.07]],"asks":[[2861.3,0.292],[2861.5,7.768],[2882.5,0.0]],"action":"update"}}
1651237314.9799998: {"channel":"orderbook","market":"ETH/USDT","type":"update","data":{"time":1651237314.8366468,"checksum":3691889014,"bids":[[2860.3,2.05],[2859.6,0.0],[2858.9,0.292],[2842.5,835.588]],"asks":[[2860.5,0.0],[2861.1,1.197]],"action":"update"}}
1651237314.980045: {"channel":"orderbook","market":"LTC/USDT","type":"update","data":{"time":1651237314.8462439,"checksum":3928932319,"bids":[[100.485,0.0],[99.455,0.0],[96.55,0.23],[96.5,0.06]],"asks":[[100.675,0.0],[101.55,0.0],[103.91,0.02],[103.96,0.29]],"action":"update"}}
1651237314.9800758: {"channel":"orderbook","market":"ETH/USD","type":"update","data":{"time":1651237314.8299818,"checksum":1276167635,"bids":[[2860.2,21.629]],"asks":[[2860.3,4.484],[2860.6,0.0],[2861.6,26.282],[2861.8,5.266],[2867.0,6.01],[2873.1,0.002]],"action":"update"}}
1651237314.9856308: {"channel":"orderbook","market":"SOL/USD","type":"update","data":{"time":1651237314.84573,"checksum":2450794518,"bids":[[95.8275,74.18],[95.82,0.0],[95.765,358.08],[95.4225,0.12]],"asks":[[95.8825,70.0],[95.93,0.69],[95.9725,220.31],[96.3625,0.0]],"action":"update"}}
1651237314.992241: {"channel":"orderbook","market":"LTC/USDT","type":"update","data":{"time":1651237314.8659234,"checksum":84364717,"bids":[],"asks":[[100.6,0.0],[104.0,0.01]],"action":"update"}}
1651237314.9922996: {"channel":"orderbook","market":"ETH/USDT","type":"update","data":{"time":1651237314.865022,"checksum":2130683902,"bids":[[2860.4,4.05],[2860.0,2.598]],"asks":[[2862.0,1.963]],"action":"update"}}
1651237315.0100074: {"channel":"orderbook","market":"FTT/BTC","type":"update","data":{"time":1651237314.8669543,"checksum":430894559,"bids":[],"asks":[],"action":"update"}}
1651237315.0118937: {"channel":"orderbook","market":"SHIB/USD","type":"update","data":{"time":1651237314.8778925,"checksum":2923292676,"bids":[[0.00002261,62200000.0]],"asks":[],"action":"update"}}
1651237315.051533: {"channel":"orderbook","market":"ETH/USDT","type":"update","data":{"time":1651237314.913133,"checksum":1415263978,"bids":[[2860.3,14.25],[2860.1,13.548],[2859.2,3.615],[2842.5,0.0]],"asks":[[2860.7,2.5],[2860.8,0.0],[2861.1,5.726],[2861.3,0.0],[2882.5,0.01]],"action":"update"}}
1651237315.0516124: {"channel":"orderbook","market":"SOL/USD","type":"update","data":{"time":1651237314.9140747,"checksum":3356276356,"bids":[[95.83,64.82],[95.815,20.0],[95.7875,600.14],[95.43,0.0],[95.425,0.0],[95.4225,0.0]],"asks":[[95.885,208.31],[95.9375,0.0],[95.965,0.0],[95.995,607.4],[96.0325,55.2],[96.3625,0.38]],"action":"update"}}
1651237315.054224: {"channel":"orderbook","market":"ETH/USD","type":"update","data":{"time":1651237314.9119184,"checksum":3050012589,"bids":[[2860.2,9.529],[2859.8,3.496],[2859.3,19.783],[2859.2,3.472],[2857.9,130.229],[2857.8,2.121],[2857.5,4.37],[2854.5,6.221],[2849.1,0.0],[2849.0,0.0]],"asks":[[2860.5,0.0],[2861.0,2.493],[2861.1,3.125],[2861.2,16.523],[2861.5,10.54],[2862.0,11.479],[2862.1,2.274],[2862.8,0.874],[2873.4,0.236]],"action":"update"}}
1651237315.0691118: {"channel":"orderbook","market":"ETH/USDT","type":"update","data":{"time":1651237314.9326954,"checksum":382523214,"bids":[],"asks":[[2860.7,0.0],[2882.6,0.1]],"action":"update"}}
1651237315.0714374: {"channel":"orderbook","market":"ETH/USD","type":"update","data":{"time":1651237314.9428308,"checksum":1926568387,"bids":[[2860.2,13.529],[2859.4,6.584],[2856.8,0.766]],"asks":[[2860.6,3.997],[2861.2,7.365],[2861.5,7.044],[2862.0,7.109],[2867.0,0.01],[2873.4,0.0]],"action":"update"}}
1651237315.0894895: {"channel":"orderbook","market":"SHIB/USD","type":"update","data":{"time":1651237314.9530506,"checksum":2517859829,"bids":[],"asks":[[0.00002266,257500000.0]],"action":"update"}}
1651237315.0895338: {"channel":"orderbook","market":"BTC/TRY","type":"update","data":{"time":1651237314.9599066,"checksum":2549750460,"bids":[],"asks":[],"action":"update"}}
1651237315.0961056: {"channel":"orderbook","market":"SOL/USD","type":"update","data":{"time":1651237314.9563386,"checksum":1572175687,"bids":[[95.8475,70.0],[95.8225,0.0],[95.815,0.0],[95.81,0.0],[95.6925,10.82],[95.43,0.25]],"asks":[[95.885,138.31],[95.95,0.0],[95.9575,33.42]],"action":"update"}}
1651237315.1068618: {"channel":"orderbook","market":"ETH/USD","type":"update","data":{"time":1651237314.9735405,"checksum":234118145,"bids":[[2858.9,46.112],[2854.5,0.221]],"asks":[[2860.3,0.0],[2861.0,0.745],[2861.1,0.0],[2873.4,0.236],[2873.5,0.015]],"action":"update"}}
1651237315.1213908: {"channel":"orderbook","market":"ETH/USD","type":"update","data":{"time":1651237314.9920287,"checksum":2860742781,"bids":[[2860.2,26.129],[2859.6,3.493]],"asks":[[2860.7,9.68],[2861.1,4.133],[2861.3,9.797],[2862.3,0.681],[2873.5,0.0]],"action":"update"}}
1651237315.121451: {"channel":"orderbook","market":"LTC/USDT","type":"update","data":{"time":1651237314.994833,"checksum":650624216,"bids":[[99.5,182.17]],"asks":[[101.695,22.79],[104.0,0.0]],"action":"update"}}
1651237315.131696: {"channel":"orderbook","market":"SOL/USD","type":"update","data":{"time":1651237314.99245,"checksum":2025680378,"bids":[[95.8275,4.18],[95.76,0.0],[95.61,60.88],[95.425,1.23]],"asks":[[95.935,0.03],[95.9725,282.86],[96.0,3.01],[96.3625,0.0]],"action":"update"}}
1651237315.1318843: {"channel":"orderbook","market":"ETH/USDT","type":"update","data":{"time":1651237314.9940774,"checksum":3784726761,"bids":[[2860.2,0.0],[2860.1,6.277],[2859.3,5.905],[2857.6,11.404],[2842.5,835.588]],"asks":[[2860.9,0.0],[2862.8,5.1],[2882.9,0.015]],"action":"update"}}
1651237315.1438763: {"channel":"orderbook","market":"ETH/USD","type":"update","data":{"time":1651237315.0150518,"checksum":1201875165,"bids":[[2860.2,22.229],[2859.4,6.404]],"asks":[[2861.1,0.0],[2873.5,0.015]],"action":"update"}}
1651237315.1563704: {"channel":"orderbook","market":"SHIB/USD","type":"update","data":{"time":1651237315.027308,"checksum":2014644678,"bids":[],"asks":[[0.00002263,401000000.0]],"action":"update"}}
1651237315.1564226: {"channel":"orderbook","market":"ETH/USDT","type":"update","data":{"time":1651237315.02462,"checksum":3805046103,"bids":[[2860.5,12.2],[2859.8,9.047],[2858.6,0.758],[2842.5,0.0]],"asks":[[2860.9,2.5],[2861.6,31.343],[2882.9,0.0]],"action":"update"}}
1651237315.1722164: {"channel":"orderbook","market":"ETH/USDT","type":"update","data":{"time":1651237315.0421169,"checksum":1263011981,"bids":[[2860.5,14.7],[2860.0,2.298],[2857.2,0.0],[2842.5,835.588]],"asks":[],"action":"update"}}
1651237315.1768959: {"channel":"orderbook","market":"SOL/USD","type":"update","data":{"time":1651237315.0462308,"checksum":519830090,"bids":[[95.83,70.0],[95.825,8.62],[95.8225,70.0],[95.795,124.63],[95.7925,62.55],[95.43,0.0],[95.425,0.0]],"asks":[[95.865,96.9],[95.8725,130.11],[95.9625,70.0],[95.9725,178.56],[96.3575,0.0],[96.36,0.0]],"action":"update"}}
1651237315.1834347: {"channel":"orderbook","market":"ETH/USD","type":"update","data":{"time":1651237315.0495923,"checksum":2448308737,"bids":[[2860.2,21.88],[2860.1,5.198],[2860.0,0.0],[2859.9,0.004],[2859.7,0.0],[2859.0,19.081],[2849.1,4.545],[2849.0,0.015]],"asks":[[2861.3,3.497],[2861.7,7.752],[2862.0,6.76],[2862.7,8.452]],"action":"update"}}
1651237315.1984224: {"channel":"orderbook","market":"ETH/USD","type":"update","data":{"time":1651237315.0674145,"checksum":907695786,"bids":[[2860.5,9.621],[2860.2,22.117],[2859.7,1.0],[2859.2,18.732],[2858.5,0.007],[2858.4,6.115],[2858.3,5.229],[2857.5,0.0],[2849.0,0.0]],"asks":[[2861.2,39.663],[2861.5,6.91],[2861.7,7.435]],"action":"update"}}
1651237315.1984837: {"channel":"orderbook","market":"ETH/USDT","type":"update","data":{"time":1651237315.0662937,"checksum":839296293,"bids":[[2858.9,4.301],[2858.6,6.558]],"asks":[[2861.0,0.0],[2861.1,4.529],[2882.9,0.015]],"action":"update"}}
1651237315.2223616: {"channel":"orderbook","market":"ETH/USDT","type":"update","data":{"time":1651237315.0908885,"checksum":1750433524,"bids":[[2860.3,12.2],[2858.6,0.758],[2858.2,4.552]],"asks":[],"action":"update"}}
1651237315.222873: {"channel":"orderbook","market":"WBTC/USD","type":"update","data":{"time":1651237315.0944366,"checksum":301397845,"bids":[],"asks":[],"action":"update"}}
1651237315.228826: {"channel":"orderbook","market":"ETH/USD","type":"update","data":{"time":1651237315.0929284,"checksum":4217628246,"bids":[[2860.5,13.114],[2860.2,20.371]],"asks":[[2861.7,10.931]],"action":"update"}}
1651237315.248384: {"channel":"orderbook","market":"ETH/USDT","type":"update","data":{"time":1651237315.1194878,"checksum":4121806583,"bids":[[2859.4,16.216],[2858.4,0.528]],"asks":[[2860.9,0.0],[2861.6,42.155],[2862.5,8.01],[2864.8,13.866],[2883.0,0.029]],"action":"update"}}
1651237315.2484477: {"channel":"orderbook","market":"ETH/USD","type":"update","data":{"time":1651237315.1189353,"checksum":1940341257,"bids":[[2860.5,15.751],[2860.2,20.038],[2860.1,1.748],[2860.0,3.496],[2859.9,5.665],[2858.9,39.912],[2849.1,0.0]],"asks":[[2861.1,1.846],[2861.2,34.753],[2861.3,6.622],[2863.6,0.912],[2869.1,2.458],[2873.5,0.0]],"action":"update"}}
1651237315.269565: {"channel":"orderbook","market":"SOL/USD","type":"update","data":{"time":1651237315.1356792,"checksum":1144252975,"bids":[[95.8275,0.0],[95.8175,31.29],[95.7525,72.91],[95.69,0.74],[95.655,21.79],[95.645,0.32],[95.435,0.0]],"asks":[[95.8825,0.0],[95.8875,0.0],[95.97,252.45],[95.975,0.06],[96.03,65.87]],"action":"update"}}
1651237315.2725933: {"channel":"orderbook","market":"ETH/USD","type":"update","data":{"time":1651237315.1424096,"checksum":4219439155,"bids":[[2860.5,23.017],[2860.0,0.0],[2859.3,0.0],[2858.9,17.295],[2858.4,7.891],[2858.2,12.072],[2858.1,4.381],[2856.6,13.638],[2849.1,4.545],[2849.0,0.015]],"asks":[[2861.1,9.922],[2862.1,0.001],[2866.2,0.0],[2873.5,0.015]],"action":"update"}}
1651237315.2735114: {"channel":"orderbook","market":"ETH/USDT","type":"update","data":{"time":1651237315.1480563,"checksum":3989981503,"bids":[[2860.6,2.05],[2860.4,22.669],[2859.5,3.496],[2858.4,0.526],[2842.7,0.0],[2842.5,0.0]],"asks":[],"action":"update"}}
1651237315.2893035: {"channel":"orderbook","market":"SOL/USD","type":"update","data":{"time":1651237315.1553388,"checksum":888259602,"bids":[[95.66,70.82]],"asks":[[95.91,110.82],[95.9725,602.7],[96.15,0.0]],"action":"update"}}
1651237315.2965975: {"channel":"orderbook","market":"ETH/USD","type":"update","data":{"time":1651237315.1676998,"checksum":3660124562,"bids":[[2860.5,26.754],[2860.3,3.733],[2859.4,4.551],[2849.0,0.0]],"asks":[[2860.6,0.0],[2860.7,0.0],[2873.6,4.007],[2873.7,0.001]],"action":"update"}}
1651237315.3171446: {"channel":"orderbook","market":"SOL/USD","type":"update","data":{"time":1651237315.18548,"checksum":1771998023,"bids":[[95.85,12.9],[95.7725,106.41],[95.4375,0.0]],"asks":[[96.0325,0.0],[96.3575,0.46]],"action":"update"}}
1651237315.3282723: {"channel":"orderbook","market":"ETH/USD","type":"update","data":{"time":1651237315.1919289,"checksum":414957281,"bids":[[2860.5,24.658],[2859.7,0.0],[2858.3,2.104],[2857.2,2.642],[2849.0,0.015]],"asks":[],"action":"update"}}
1651237315.328351: {"channel":"orderbook","market":"ETH/USDT","type":"update","data":{"time":1651237315.1949937,"checksum":2258862516,"bids":[[2860.5,2.5]],"asks":[[2861.6,41.863],[2864.8,1.34]],"action":"update"}}
1651237315.334483: {"channel":"orderbook","market":"SOL/USD","type":"update","data":{"time":1651237315.2020886,"checksum":4244725214,"bids":[[95.805,105.28],[95.44,0.0]],"asks":[],"action":"update"}}
1651237315.3514614: {"channel":"orderbook","market":"ETH/USDT","type":"update","data":{"time":1651237315.216668,"checksum":3870566777,"bids":[[2860.3,0.0],[2842.7,0.018]],"asks":[],"action":"update"}}
1651237315.3515308: {"channel":"orderbook","market":"ETH/USD","type":"update","data":{"time":1651237315.217769,"checksum":3099936110,"bids":[[2860.5,11.383],[2860.2,7.438],[2859.5,3.496],[2858.4,1.774],[2853.9,0.101],[2849.0,0.0]],"asks":[[2862.8,0.0],[2873.9,0.001]],"action":"update"}}
1651237315.3718398: {"channel":"orderbook","market":"ETH/USD","type":"update","data":{"time":1651237315.2427428,"checksum":1721738349,"bids":[[2860.5,9.483],[2860.3,0.0],[2859.9,5.662],[2859.0,12.456],[2858.0,15.458],[2857.9,129.88],[2849.0,0.015]],"asks":[[2861.0,4.496],[2861.8,12.631]],"action":"update"}}
1651237315.3750143: {"channel":"orderbook","market":"SOL/USD","type":"update","data":{"time":1651237315.2406774,"checksum":3928913008,"bids":[[95.8475,0.0],[95.44,1.0]],"asks":[[95.935,0.0],[96.36,0.03]],"action":"update"}}
1651237315.3790817: {"channel":"orderbook","market":"FTT/BTC","type":"update","data":{"time":1651237315.2530403,"checksum":2016687871,"bids":[[0.0010061,0.1]],"asks":[],"action":"update"}}
1651237315.3890195: {"channel":"orderbook","market":"ETH/USDT","type":"update","data":{"time":1651237315.2606015,"checksum":1423583088,"bids":[[2860.5,8.174],[2860.4,20.669],[2860.0,2.3],[2859.3,0.0],[2859.0,3.866],[2842.5,835.588]],"asks":[[2861.3,1.197],[2861.4,2.125],[2883.0,0.0]],"action":"update"}}
1651237315.399296: {"channel":"orderbook","market":"ETH/USD","type":"update","data":{"time":1651237315.2670279,"checksum":1540096402,"bids":[[2859.9,25.193]],"asks":[[2860.9,5.35],[2861.2,20.711],[2861.5,10.406],[2861.6,35.986],[2862.7,44.783],[2873.9,0.0]],"action":"update"}}
1651237315.4288015: {"channel":"orderbook","market":"ETH/USD","type":"update","data":{"time":1651237315.2926962,"checksum":3504781380,"bids":[[2860.3,1.859],[2859.3,4.685],[2858.0,22.359],[2849.1,0.0],[2849.0,0.0]],"asks":[[2860.8,1.9],[2860.9,15.347],[2861.0,6.785],[2861.1,15.172],[2861.5,6.91],[2873.7,0.0]],"action":"update"}}
1651237315.4288976: {"channel":"orderbook","market":"SOL/USD","type":"update","data":{"time":1651237315.2882223,"checksum":3278001863,"bids":[[95.85,21.51],[95.7625,106.92]],"asks":[],"action":"update"}}
1651237315.431935: {"channel":"orderbook","market":"ETH/USDT","type":"update","data":{"time":1651237315.3010697,"checksum":2760929489,"bids":[[2860.8,2.0],[2860.1,1.748],[2859.1,5.0],[2859.0,0.011],[2858.9,4.009],[2842.5,0.0]],"asks":[[2861.0,4.05],[2861.3,0.0]],"action":"update"}}
1651237315.4445517: {"channel":"orderbook","market":"SOL/USD","type":"update","data":{"time":1651237315.3145645,"checksum":4105949150,"bids":[],"asks":[[95.975,62.7]],"action":"update"}}
1651237315.4446218: {"channel":"orderbook","market":"ETH/USD","type":"update","data":{"time":1651237315.316435,"checksum":3630088692,"bids":[[2860.6,1.9],[2859.1,40.918],[2856.8,0.758],[2849.3,0.0]],"asks":[[2860.9,13.447],[2861.3,6.81],[2862.3,1.03],[2862.6,13.32]],"action":"update"}}
1651237315.4609723: {"channel":"orderbook","market":"ETH/USDT","type":"update","data":{"time":1651237315.3230646,"checksum":298480262,"bids":[[2859.2,0.0],[2842.5,835.588]],"asks":[],"action":"update"}}
1651237315.4728448: {"channel":"orderbook","market":"LTC/USDT","type":"update","data":{"time":1651237315.3419545,"checksum":2919976528,"bids":[[100.58,60.06],[96.5,0.0]],"asks":[],"action":"update"}}
1651237315.4728918: {"channel":"orderbook","market":"ETH/USD","type":"update","data":{"time":1651237315.3413293,"checksum":1997691911,"bids":[[2860.5,5.737],[2859.5,13.112],[2859.4,4.509],[2858.7,8.309],[2858.6,17.657],[2858.0,15.458]],"asks":[[2860.8,0.0],[2860.9,7.447],[2861.1,9.922],[2861.6,45.527],[2866.7,585.253],[2873.7,0.001]],"action":"update"}}
1651237315.4812176: {"channel":"orderbook","market":"ETH/USDT","type":"update","data":{"time":1651237315.3528955,"checksum":352706737,"bids":[[2860.4,25.198]],"asks":[[2861.0,2.05]],"action":"update"}}
1651237315.4932213: {"channel":"orderbook","market":"LTC/USDT","type":"update","data":{"time":1651237315.365438,"checksum":2919976528,"bids":[],"asks":[],"action":"update"}}
1651237315.4961758: {"channel":"orderbook","market":"ETH/USD","type":"update","data":{"time":1651237315.3662927,"checksum":3493381890,"bids":[[2860.5,3.737],[2859.4,0.0],[2849.3,0.041]],"asks":[[2860.7,1.9],[2861.3,3.314],[2862.5,2.358],[2873.7,0.0]],"action":"update"}}
1651237315.5077298: {"channel":"orderbook","market":"ETH/USDT","type":"update","data":{"time":1651237315.3793828,"checksum":1888613171,"bids":[[2860.4,6.579],[2860.1,0.0],[2859.6,19.919],[2859.5,0.0],[2842.2,0.001]],"asks":[],"action":"update"}}
1651237315.5145698: {"channel":"orderbook","market":"SOL/USD","type":"update","data":{"time":1651237315.3841717,"checksum":775575313,"bids":[[95.83,75.0],[95.7375,178.86]],"asks":[[95.915,70.0],[95.9675,195.03],[96.36,0.0]],"action":"update"}}
1651237315.530285: {"channel":"orderbook","market":"LTC/USDT","type":"update","data":{"time":1651237315.3923569,"checksum":3196926589,"bids":[[100.515,0.0],[96.5,0.06]],"asks":[],"action":"update"}}
1651237315.5303621: {"channel":"orderbook","market":"SHIB/USD","type":"update","data":{"time":1651237315.3828576,"checksum":2014644678,"bids":[],"asks":[],"action":"update"}}
1651237315.5309162: {"channel":"orderbook","market":"ETH/USD","type":"update","data":{"time":1651237315.3944752,"checksum":2567981999,"bids":[[2860.0,6.301],[2859.5,9.616],[2859.2,25.748],[2849.3,0.0]],"asks":[[2860.7,4.0],[2860.8,1.9],[2860.9,11.547],[2861.4,21.14],[2863.7,1.261],[2873.6,0.0]],"action":"update"}}
1651237315.5482829: {"channel":"orderbook","market":"ETH/USD","type":"update","data":{"time":1651237315.4176612,"checksum":2154262719,"bids":[],"asks":[[2860.8,3.9],[2861.4,20.791],[2862.3,0.681],[2862.7,8.452]],"action":"update"}}
1651237315.5578065: {"channel":"orderbook","market":"ETH/USDT","type":"update","data":{"time":1651237315.4269934,"checksum":1737787605,"bids":[],"asks":[[2860.9,2.461],[2882.9,0.0]],"action":"update"}}
1651237315.55786: {"channel":"orderbook","market":"FTT/BTC","type":"update","data":{"time":1651237315.4325166,"checksum":3580624537,"bids":[],"asks":[[0.00101,0.0],[0.001024,0.1]],"action":"update"}}
1651237315.5740137: {"channel":"orderbook","market":"SOL/USD","type":"update","data":{"time":1651237315.441424,"checksum":2422764720,"bids":[[95.8225,90.0],[95.8,0.0],[95.4375,0.01]],"asks":[[95.93,105.97]],"action":"update"}}
1651237315.5873063: {"channel":"orderbook","market":"ETH/USD","type":"update","data":{"time":1651237315.4431744,"checksum":435284808,"bids":[[2859.8,3.538],[2857.8,0.0],[2849.3,0.041]],"asks":[[2860.8,6.0],[2860.9,7.447],[2861.0,6.804],[2862.6,2.121]],"action":"update"}}
1651237315.5873663: {"channel":"orderbook","market":"ETH/USDT","type":"update","data":{"time":1651237315.4458647,"checksum":3270772511,"bids":[[2860.4,8.327],[2860.3,0.26],[2860.0,2.298],[2842.2,0.0]],"asks":[],"action":"update"}}
1651237315.5873992: {"channel":"orderbook","market":"FTT/BTC","type":"update","data":{"time":1651237315.4513557,"checksum":3862737842,"bids":[],"asks":[[0.0010096,0.0],[0.0010241,2879.9]],"action":"update"}}
1651237315.6069047: {"channel":"orderbook","market":"SOL/USD","type":"update","data":{"time":1651237315.4595575,"checksum":1860053873,"bids":[[95.8325,8.37],[95.7675,223.41],[95.4375,0.0]],"asks":[],"action":"update"}}
1651237315.6069727: {"channel":"orderbook","market":"ETH/USDT","type":"update","data":{"time":1651237315.47361,"checksum":2109337001,"bids":[[2860.6,0.0],[2860.5,2.5],[2860.4,6.277],[2860.2,3.496],[2858.9,0.0],[2842.2,0.001]],"asks":[],"action":"update"}}
1651237315.6070437: {"channel":"orderbook","market":"FTT/BTC","type":"update","data":{"time":1651237315.478281,"checksum":830080006,"bids":[],"asks":[[0.0010099,13.3]],"action":"update"}}
1651237315.615603: {"channel":"orderbook","market":"SOL/USD","type":"update","data":{"time":1651237315.4893296,"checksum":1884961480,"bids":[[95.85,12.9]],"asks":[],"action":"update"}}
1651237315.6262355: {"channel":"orderbook","market":"ETH/USD","type":"update","data":{"time":1651237315.4937322,"checksum":3309940619,"bids":[[2859.3,5.365],[2858.7,2.273],[2857.1,1.679]],"asks":[[2860.8,0.0],[2861.2,18.256],[2861.6,26.312],[2861.7,11.28],[2863.3,8.276],[2873.6,4.007]],"action":"update"}}
1651237315.633117: {"channel":"orderbook","market":"ETH/USDT","type":"update","data":{"time":1651237315.4978163,"checksum":1461355072,"bids":[[2860.4,26.078],[2859.5,0.292],[2842.2,0.0]],"asks":[[2860.9,2.0],[2861.1,0.0],[2861.5,8.965],[2861.6,22.676],[2882.9,0.015]],"action":"update"}}
1651237315.6372516: {"channel":"orderbook","market":"FTT/BTC","type":"update","data":{"time":1651237315.5052493,"checksum":3389609952,"bids":[],"asks":[[0.0010109,352.5]],"action":"update"}}
1651237315.6372864: {"channel":"orderbook","market":"SOL/USD","type":"update","data":{"time":1651237315.5110805,"checksum":181526839,"bids":[[95.8425,103.0],[95.44,0.0]],"asks":[],"action":"update"}}
1651237315.6555128: {"channel":"orderbook","market":"FTT/BTC","type":"update","data":{"time":1651237315.5297182,"checksum":1235612775,"bids":[[0.0010063,23.2]],"asks":[],"action":"update"}}
1651237315.665753: {"channel":"orderbook","market":"ETH/USDT","type":"update","data":{"time":1651237315.53172,"checksum":3474402685,"bids":[[2858.5,2.853]],"asks":[[2860.9,4.05],[2861.0,0.0],[2883.0,0.029]],"action":"update"}}
1651237315.6702359: {"channel":"orderbook","market":"ETH/USD","type":"update","data":{"time":1651237315.5407338,"checksum":1801358212,"bids":[[2860.6,5.629],[2860.5,3.45],[2860.4,1.748],[2860.2,7.201],[2857.7,2.121],[2849.4,0.0],[2849.3,0.0]],"asks":[[2862.1,3.497],[2862.4,14.461]],"action":"update"}}
1651237315.6829011: {"channel":"orderbook","market":"ETH/USDT","type":"update","data":{"time":1651237315.55391,"checksum":2808961100,"bids":[[2860.8,4.05],[2859.5,4.301]],"asks":[],"action":"update"}}
1651237315.6829488: {"channel":"orderbook","market":"DAI/USD","type":"update","data":{"time":1651237315.5538898,"checksum":2637841829,"bids":[],"asks":[],"action":"update"}}
1651237315.6829705: {"channel":"orderbook","market":"SOL/USD","type":"update","data":{"time":1651237315.5585554,"checksum":1264927026,"bids":[[95.675,31.55]],"asks":[],"action":"update"}}
1651237315.6956582: {"channel":"orderbook","market":"ETH/USD","type":"update","data":{"time":1651237315.5649898,"checksum":881111733,"bids":[],"asks":[[2861.3,0.189],[2866.7,585.252]],"action":"update"}}
1651237315.7050297: {"channel":"orderbook","market":"ETH/USDT","type":"update","data":{"time":1651237315.5761845,"checksum":3949722446,"bids":[],"asks":[[2861.5,13.494]],"action":"update"}}
1651237315.7050655: {"channel":"orderbook","market":"FTT/BTC","type":"update","data":{"time":1651237315.579772,"checksum":884334042,"bids":[],"asks":[[0.0010097,4.3],[0.0010098,3.9]],"action":"update"}}
1651237315.7240381: {"channel":"orderbook","market":"SOL/USD","type":"update","data":{"time":1651237315.5867505,"checksum":2894388456,"bids":[[95.8275,0.01],[95.4475,0.0]],"asks":[[96.1925,275.32],[96.3575,0.0]],"action":"update"}}
1651237315.724141: {"channel":"orderbook","market":"ETH/USD","type":"update","data":{"time":1651237315.592621,"checksum":317422401,"bids":[[2859.1,39.918]],"asks":[[2861.1,8.076],[2861.5,7.259]],"action":"update"}}
1651237315.7543857: {"channel":"orderbook","market":"ETH/USD","type":"update","data":{"time":1651237315.6162426,"checksum":1715895328,"bids":[[2860.2,23.402],[2859.9,26.193]],"asks":[[2862.5,22.237]],"action":"update"}}
1651237315.754459: {"channel":"orderbook","market":"ETH/USDT","type":"update","data":{"time":1651237315.6183455,"checksum":1819650764,"bids":[],"asks":[[2861.3,6.919],[2883.0,0.0]],"action":"update"}}
1651237315.761482: {"channel":"orderbook","market":"SOL/USD","type":"update","data":{"time":1651237315.6324914,"checksum":1822937061,"bids":[[95.7825,63.36],[95.66,346.14]],"asks":[],"action":"update"}}
1651237315.7648635: {"channel":"orderbook","market":"ETH/USDT","type":"update","data":{"time":1651237315.6347697,"checksum":3934284325,"bids":[[2860.4,6.277],[2860.3,0.0],[2842.2,0.001]],"asks":[[2862.5,27.309]],"action":"update"}}
1651237315.7720222: {"channel":"orderbook","market":"FTT/BTC","type":"update","data":{"time":1651237315.6393485,"checksum":2177006148,"bids":[],"asks":[[0.0010108,66.3]],"action":"update"}}
1651237315.7720947: {"channel":"orderbook","market":"ETH/USD","type":"update","data":{"time":1651237315.6411664,"checksum":2175455081,"bids":[],"asks":[[2861.4,24.287],[2863.1,21.96]],"action":"update"}}
1651237315.7786076: {"channel":"orderbook","market":"SHIB/USD","type":"update","data":{"time":1651237315.6513627,"checksum":2861460789,"bids":[[0.00002204,2200000.0]],"asks":[],"action":"update"}}
1651237315.7984312: {"channel":"orderbook","market":"ETH/USDT","type":"update","data":{"time":1651237315.6635854,"checksum":4174602902,"bids":[],"asks":[[2861.8,0.292],[2882.9,0.0]],"action":"update"}}
1651237315.8002212: {"channel":"orderbook","market":"ETH/USD","type":"update","data":{"time":1651237315.6690025,"checksum":2040402396,"bids":[[2860.6,5.628],[2857.2,1.768]],"asks":[[2861.1,8.078],[2861.7,14.405],[2862.4,20.026],[2865.0,0.003]],"action":"update"}}
1651237315.809304: {"channel":"orderbook","market":"SOL/USD","type":"update","data":{"time":1651237315.68258,"checksum":1222645960,"bids":[[95.6925,0.0],[95.4475,0.03]],"asks":[],"action":"update"}}
1651237315.8225636: {"channel":"orderbook","market":"ETH/USD","type":"update","data":{"time":1651237315.695008,"checksum":1515775075,"bids":[],"asks":[[2861.3,6.267],[2863.0,5.681]],"action":"update"}}
1651237315.8252563: {"channel":"orderbook","market":"USD/TRY","type":"update","data":{"time":1651237315.7001264,"checksum":2845795420,"bids":[],"asks":[],"action":"update"}}
1651237315.8334434: {"channel":"orderbook","market":"SOL/USD","type":"update","data":{"time":1651237315.7065108,"checksum":671657129,"bids":[[95.75,72.18]],"asks":[],"action":"update"}}
1651237315.8704746: {"channel":"orderbook","market":"ETH/USDT","type":"update","data":{"time":1651237315.7342234,"checksum":2853714328,"bids":[[2860.3,5.664],[2859.9,2.27],[2859.4,5.0],[2842.5,0.0],[2842.2,0.0]],"asks":[[2860.9,2.0],[2862.4,7.009]],"action":"update"}}
1651237315.88007: {"channel":"orderbook","market":"ETH/USD","type":"update","data":{"time":1651237315.7504683,"checksum":3611456019,"bids":[[2859.3,9.897],[2859.2,10.488],[2859.0,4.964]],"asks":[[2863.7,1.254]],"action":"update"}}
1651237315.9006803: {"channel":"orderbook","market":"ETH/USD","type":"update","data":{"time":1651237315.7680879,"checksum":1572956882,"bids":[[2859.1,37.37],[2857.6,1.248]],"asks":[],"action":"update"}}
1651237315.9084394: {"channel":"orderbook","market":"SOL/USD","type":"update","data":{"time":1651237315.7827349,"checksum":2984027779,"bids":[],"asks":[[95.865,132.9]],"action":"update"}}
