wss://ftx.us/ws/ <- 1618677911.291866: {"channel":"orderbook","market":"USDT/USD","op":"subscribe"}
wss://ftx.us/ws/ <- 1618677911.291898: {"channel":"orderbook","market":"PAXG/USD","op":"subscribe"}
wss://ftx.us/ws/ <- 1618677911.291928: {"channel":"orderbook","market":"ETH/USD","op":"subscribe"}
wss://ftx.us/ws/ <- 1618677911.291958: {"channel":"orderbook","market":"AUD/USD","op":"subscribe"}
wss://ftx.us/ws/ <- 1618677911.291988: {"channel":"orderbook","market":"DAI/USD","op":"subscribe"}
wss://ftx.us/ws/ <- 1618677911.292017: {"channel":"orderbook","market":"SOL/USDT","op":"subscribe"}
wss://ftx.us/ws/ <- 1618677911.292047: {"channel":"orderbook","market":"PAXG/USDT","op":"subscribe"}
wss://ftx.us/ws/ <- 1618677911.292077: {"channel":"orderbook","market":"WBTC/USD","op":"subscribe"}
wss://ftx.us/ws/ <- 1618677911.292106: {"channel":"orderbook","market":"BRZ/USDT","op":"subscribe"}
wss://ftx.us/ws/ <- 1618677911.292135: {"channel":"orderbook","market":"UNI/USD","op":"subscribe"}
1618677911.469279: {"type": "subscribed", "channel": "orderbook", "market": "USDT/USD"}
1618677911.47715: {"type": "subscribed", "channel": "orderbook", "market": "PAXG/USD"}
1618677911.4824882: {"type": "subscribed", "channel": "orderbook", "market": "ETH/USD"}
1618677911.488982: {"type": "subscribed", "channel": "orderbook", "market": "AUD/USD"}
1618677911.4921658: {"type": "subscribed", "channel": "orderbook", "market": "DAI/USD"}
1618677911.501207: {"type": "subscribed", "channel": "orderbook", "market": "SOL/USDT"}
1618677911.5021398: {"type": "subscribed", "channel": "orderbook", "market": "PAXG/USDT"}
1618677911.5110478: {"type": "subscribed", "channel": "orderbook", "market": "WBTC/USD"}
1618677911.5163798: {"type": "subscribed", "channel": "orderbook", "market": "BRZ/USDT"}
1618677911.522885: {"type": "subscribed", "channel": "orderbook", "market": "UNI/USD"}
1618677911.562491: {"channel": "orderbook", "market": "PAXG/USD", "type": "partial", "data": {"time": 1618677911.5620055, "checksum": 3020203689, "bids": [[1781.1, 0.7656], [1776.3, 0.1919], [1775.7, 1.9907], [1773.0, 0.995], [1770.4, 1.571], [1767.8, 1.5724], [1767.4, 1.6806], [1766.6, 1.8363], [1766.5, 1.2522], [1766.4, 1.3963], [1764.8, 1.2676], [1764.2, 1.8327], [1764.0, 1.5462], [1763.8, 2.7587], [1762.5, 1.6322], [1761.2, 1.5156], [1745.6, 3.1767], [1739.3, 2.6595], [1736.7, 2.2351], [1693.5, 1.027], [1692.6, 1.1505], [1546.7, 2.0993], [1482.2, 3.1017], [1423.0, 2.4237], [1368.4, 3.8394], [1368.1, 2.7262], [1249.7, 0.0324], [1178.6, 0.0306], [1115.1, 0.0286], [1058.1, 0.0287], [1006.6, 0.0331]], "asks": [[1781.5, 0.6646], [1784.2, 0.7464], [1786.9, 1.0189], [1789.5, 0.9596], [1792.2, 1.5817], [1805.6, 2.4287], [1806.5, 1.3787], [1809.8, 0.1917], [1810.9, 2.278], [1813.6, 1.7501], [1816.3, 2.4869], [1818.9, 7.3403], [1821.6, 2.2779], [1829.6, 4.99], [1832.3, 8.9607], [1898.5, 1.3125], [1898.6, 1.1162], [1987.6, 1.4678], [1990.0, 0.0129], [2075.3, 2.3115], [2165.7, 2.0171], [2254.8, 2.3785], [2343.9, 3.6096], [2568.7, 0.0303], [2723.8, 0.031], [2878.8, 0.0334], [3033.9, 0.0314], [3188.9, 0.0313]], "action": "partial"}}
1618677911.562687: {"channel": "orderbook", "market": "DAI/USD", "type": "partial", "data": {"time": 1618677911.5646498, "checksum": 12838118, "bids": [[0.9989, 38303.7], [0.9985, 4467.6], [0.9938, 181.4], [0.9855, 2.1], [0.9835, 38331.4], [0.98, 100.0], [0.9685, 41123.5], [0.9662, 21.8], [0.9539, 68788.6], [0.9478, 96383.3], [0.9461, 23.4], [0.9398, 49416.1], [0.926, 25.1], [0.9257, 58350.8], [0.9126, 75612.2], [0.9058, 26.9], [0.9054, 121678.2], [0.8996, 97904.6], [0.8869, 99117.4], [0.8748, 85568.1], [0.8659, 165887.7], [0.864, 104095.0], [0.8525, 90559.6], [0.8303, 173207.1], [0.7972, 216825.3], [0.7667, 219085.7]], "asks": [[1.0044, 48936.8], [1.0093, 192.5], [1.0122, 34131.3], [1.0192, 3.0], [1.0256, 9.9], [1.0361, 64249.0], [1.0504, 63913.7], [1.0555, 79016.1], [1.0668, 75110.8], [1.0831, 54340.5], [1.098, 64708.2], [1.1147, 84615.7], [1.1296, 138889.8], [1.1626, 79466.1], [1.1641, 73405.0], [1.1778, 79980.4], [1.1781, 107562.6], [1.2069, 197449.7], [1.2582, 165353.2], [1.3083, 165245.4]], "action": "partial"}}
1618677911.768785: {"channel": "orderbook", "market": "BRZ/USDT", "type": "partial", "data": {"time": 1618677911.778886, "checksum": 2401773231, "bids": [[0.17783, 9279.0], [0.1778, 70039.0], [0.17759, 25866.0], [0.1773, 22313.0], [0.17716, 42590.0], [0.17698, 51513.0], [0.17649, 44550.0], [0.17643, 45511.0], [0.17592, 63170.0], [0.17563, 53400.0], [0.17538, 46460.0], [0.17523, 63406.0], [0.17486, 64600.0], [0.17388, 65978.0], [0.16637, 97692.0], [0.1611, 108155.0], [0.15383, 175996.0], [0.1476, 135435.0], [0.14179, 205846.0]], "asks": [[0.17874, 9224.0], [0.17877, 77070.0], [0.17901, 28802.0], [0.17936, 36049.0], [0.17949, 48337.0], [0.17986, 34229.0], [0.18005, 50557.0], [0.18033, 56428.0], [0.18059, 59642.0], [0.18086, 46706.0], [0.18096, 75114.0], [0.18142, 70066.0], [0.18167, 69295.0], [0.18294, 50347.0], [0.18796, 108027.0], [0.19687, 98144.0], [0.20578, 117294.0], [0.22359, 162274.0], [0.23172, 224188.0]], "action": "partial"}}
1618677912.0279622: {"channel": "orderbook", "market": "PAXG/USDT", "type": "partial", "data": {"time": 1618677912.0264564, "checksum": 3578414220, "bids": [[1780.1, 0.7818], [1777.5, 0.828], [1775.2, 0.1901], [1774.8, 1.0158], [1771.9, 1.5238], [1769.6, 1.3969], [1769.5, 1.0559], [1769.3, 1.362], [1766.7, 1.6263], [1766.6, 1.5057], [1764.4, 2.176], [1764.3, 5.2818], [1762.2, 1.4055], [1754.9, 2.1744], [1752.5, 2.6859], [1747.6, 3.1905], [1745.9, 2.8041], [1745.7, 2.3539], [1744.1, 2.0259], [1692.4, 1.11], [1692.2, 0.9689], [1615.3, 1.4689], [1481.9, 3.1577], [1481.5, 2.2088], [1422.6, 2.1927], [1249.7, 0.0322], [1178.6, 0.0295], [1115.1, 0.0335], [1058.1, 0.0289], [1006.6, 0.0303]], "asks": [[1780.6, 0.7366], [1783.3, 0.8958], [1786.0, 0.8231], [1788.6, 1.1585], [1791.3, 1.1734], [1796.7, 1.2674], [1804.4, 2.3779], [1806.2, 1.479], [1807.0, 1.8863], [1807.3, 2.3159], [1809.7, 4.1947], [1810.3, 0.2094], [1814.8, 2.2614], [1815.4, 1.972], [1818.0, 2.8347], [1822.8, 3.0628], [1823.1, 2.3554], [1823.3, 3.0832], [1826.0, 2.2762], [1828.7, 3.0445], [1898.4, 0.9746], [1899.0, 1.2286], [1988.0, 1.5896], [2076.1, 2.3923], [2165.1, 2.4569], [2254.1, 3.1481], [2568.7, 0.0309], [2723.8, 0.0323], [2878.8, 0.0343], [3033.9, 0.0334], [3188.9, 0.0334]], "action": "partial"}}
1618677912.0565891: {"channel": "orderbook", "market": "SOL/USDT", "type": "partial", "data": {"time": 1618677912.0641663, "checksum": 3788392910, "bids": [[25.9575, 696.5], [25.7475, 567.8], [25.68, 643.2], [25.5725, 1052.0], [25.39, 854.3], [25.3425, 980.2], [25.23, 1203.8], [25.115, 1182.9], [25.0575, 1153.8], [25.0, 12.7], [24.9925, 1214.2], [24.965, 1892.0], [24.7725, 1273.5], [24.77, 1145.1], [24.74, 0.4], [24.7375, 1.1], [24.4975, 10.0], [24.4, 32.2], [24.0, 1.0], [23.955, 3270.2], [23.53, 2459.0], [23.5, 5.0], [23.115, 4562.5], [23.11, 649.0], [21.92, 4701.7], [21.0, 50.0], [20.73, 50.6], [20.35, 850.0], [20.075, 920.0], [20.07, 5248.7], [19.92, 58.2], [19.1675, 56.1], [19.0, 50.0], [18.47, 51.6], [18.0, 60.0], [17.8225, 54.3], [8.0, 6.0]], "asks": [[26.21, 450.7], [26.255, 266.1], [26.325, 720.0], [26.3375, 1035.0], [26.3675, 1178.4], [26.395, 665.5], [26.675, 986.1], [26.695, 0.5], [26.9025, 1467.4], [26.9125, 1177.5], [26.96, 1343.9], [27.155, 5.1], [27.18, 1583.1], [27.2275, 1183.4], [27.5075, 1500.7], [28.075, 2717.4], [28.4725, 0.1], [28.71, 2.0], [29.5025, 2385.0], [30.285, 2890.1], [32.02, 3756.0], [32.8175, 53.8], [32.8925, 4351.9], [33.8575, 6304.4], [34.1625, 53.8], [35.5025, 48.9], [36.8425, 58.2], [38.185, 56.7], [39.99, 62.0]], "action": "partial"}}
1618677912.176748: {"channel": "orderbook", "market": "AUD/USD", "type": "partial", "data": {"time": 1618677912.1872625, "checksum": 663486434, "bids": [[0.7721, 141196.0], [0.7716, 186389.0], [0.7708, 5144.0], [0.7703, 304691.0], [0.7701, 225546.0], [0.7695, 291373.0], [0.7687, 272027.0], [0.7682, 431768.0], [0.7676, 14.0], [0.7667, 333744.0], [0.7664, 407248.0], [0.766, 421242.0], [0.7644, 462056.0], [0.7642, 400076.0], [0.7347, 114476.0], [0.7346, 122049.0], [0.7335, 84733.0], [0.6717, 150083.0], [0.6436, 182374.0], [0.6191, 256499.0]], "asks": [[0.7729, 126758.0], [0.7731, 177112.0], [0.7739, 255056.0], [0.7755, 263349.0], [0.7756, 261427.0], [0.7764, 474894.0], [0.7771, 356860.0], [0.7779, 545764.0], [0.7785, 581717.0], [0.7792, 387068.0], [0.7794, 362459.0], [0.7804, 441210.0], [0.812, 128008.0], [0.8121, 87292.0], [0.8519, 146749.0], [0.8894, 148357.0], [0.9285, 249903.0], [0.9293, 247047.0]], "action": "partial"}}
1618677912.225627: {"channel": "orderbook", "market": "USDT/USD", "type": "partial", "data": {"time": 1618677912.237015, "checksum": 2693766571, "bids": [[1.0003, 787.53], [1.0002, 172534.53], [1.0, 39781.51], [0.9999, 45093.42], [0.9998, 55649.24], [0.9996, 76271.39], [0.9995, 72042.36], [0.9993, 72701.28], [0.9991, 6504.5], [0.999, 99769.23], [0.9989, 223937.31], [0.9988, 125163.35], [0.9987, 98242.76], [0.9985, 302630.48], [0.998, 110076.46], [0.9976, 306682.31], [0.9975, 185664.11], [0.9974, 150527.25], [0.997, 160715.12], [0.9964, 125912.18], [0.9935, 5000.0], [0.9771, 8955.11], [0.9727, 8216.99], [0.9683, 8690.88], [0.964, 7821.68], [0.9597, 8304.41], [0.9524, 399655.15], [0.9091, 400466.04], [0.8695, 643393.31], [0.7998, 857006.38], [0.7698, 907579.01], [0.7693, 802564.66]], "asks": [[1.0006, 15678.05], [1.0009, 181099.34], [1.0011, 73182.56], [1.0012, 10188.31], [1.0014, 109054.68], [1.0016, 1599.22], [1.0017, 284375.58], [1.0018, 87249.04], [1.0022, 165722.94], [1.0024, 87591.53], [1.0029, 228102.69], [1.0031, 96033.45], [1.0035, 140634.18], [1.0036, 119826.42], [1.0037, 148904.86], [1.004, 142779.7], [1.0042, 160872.56], [1.0046, 162644.94], [1.0052, 5000.0], [1.007, 5000.0], [1.0253, 8886.56], [1.03, 8091.1], [1.0347, 8864.82], [1.0394, 8087.98], [1.044, 7942.67], [1.0512, 310313.17], [1.0525, 291605.12], [1.1016, 591004.43], [1.1526, 448189.78], [1.2026, 753673.91], [1.3028, 721853.96]], "action": "partial"}}
1618677912.284567: {"channel": "orderbook", "market": "WBTC/USD", "type": "partial", "data": {"time": 1618677912.2850788, "checksum": 3952158099, "bids": [[60432.0, 12.7814], [60409.0, 1.108], [60406.0, 9.7861], [60083.0, 18.635], [59913.0, 15.6794], [59744.0, 23.1723], [59576.0, 26.7212], [59409.0, 29.1769], [59243.0, 29.471], [59078.0, 38.3225], [58914.0, 42.3905], [58751.0, 44.7872], [58589.0, 39.4534], [58426.0, 37.2264], [57394.0, 1.6819], [54794.0, 2.1142], [52420.0, 2.4769], [52000.0, 0.0096], [50242.0, 3.3904], [48238.0, 3.5823], [46388.0, 3.8378], [6083.0, 0.1862]], "asks": [[60740.0, 9.924], [60743.0, 14.6064], [60916.0, 17.8764], [61088.0, 25.9124], [61261.0, 27.7297], [61433.0, 28.7018], [61606.0, 25.3925], [61778.0, 26.5523], [61951.0, 38.303], [62123.0, 44.9765], [62296.0, 46.8799], [62468.0, 34.4228], [63594.0, 1.3973], [66618.0, 1.7539], [70297.0, 1.8639], [73208.0, 3.395], [78588.0, 3.0369], [78770.0, 3.5411]], "action": "partial"}}
1618677912.291285: {"channel": "orderbook", "market": "WBTC/USD", "type": "update", "data": {"time": 1618677912.3052993, "checksum": 2295383514, "bids": [[60406.0, 0.0]], "asks": [], "action": "update"}}
1618677912.3330681: {"channel": "orderbook", "market": "UNI/USD", "type": "partial", "data": {"time": 1618677912.3410196, "checksum": 623633271, "bids": [[35.393, 3.5], [35.147, 1802.0], [35.144, 87.9], [34.712, 86.0], [34.5, 6.0], [34.479, 2.1], [34.401, 135.4], [34.245, 173.9], [34.192, 2.0], [34.124, 2.2], [34.111, 1.2], [34.101, 139.1], [33.951, 0.7], [33.898, 168.4], [33.587, 203.6], [33.5, 60.0], [33.318, 179.5], [33.194, 306.5], [33.034, 200.4], [32.942, 233.0], [32.8, 216.3], [32.452, 193.7], [32.387, 355.3], [32.0, 53.3], [31.267, 506.0], [30.9, 39.0], [30.541, 5.9], [29.76, 591.1], [29.731, 5.8], [28.969, 5.6], [28.763, 633.1], [28.239, 6.5], [28.0, 2.7], [27.9, 8.0], [27.84, 3.5], [27.81, 1.7], [27.542, 6.7], [27.5, 1.8], [27.34, 1.1], [27.25, 1.8], [27.239, 641.9], [27.0, 1.8], [26.689, 1.2], [26.0, 0.9], [25.033, 13.3], [25.0, 1.0], [23.18, 14.3], [20.123, 11.0], [18.001, 0.2]], "asks": [[35.677, 66.0], [35.888, 1825.3], [35.891, 104.0], [35.987, 119.6], [36.117, 129.0], [36.356, 114.8], [36.58, 2.1], [36.75, 1.3], [36.962, 163.1], [36.989, 208.2], [37.214, 192.8], [37.58, 2.8], [37.6, 11.4], [37.623, 215.6], [37.625, 187.0], [37.656, 6.1], [37.755, 6.1], [37.782, 4.2], [37.8, 0.4], [37.9, 5.4], [37.902, 260.6], [38.92, 7.9], [38.939, 259.9], [39.126, 256.1], [39.31, 6.3], [39.366, 227.0], [39.38, 2.2], [39.48, 2.8], [39.5, 327.0], [39.864, 90.8], [39.95, 11.6], [40.302, 343.5], [41.01, 6.3], [42.137, 6.3], [43.134, 443.4], [43.247, 6.3], [43.96, 621.3], [44.352, 6.4], [45.47, 5.7]], "action": "partial"}}
1618677912.455453: {"channel": "orderbook", "market": "ETH/USD", "type": "partial", "data": {"time": 1618677912.465761, "checksum": 2085101794, "bids": [[2363.9, 0.694], [2362.0, 0.76], [2361.1, 136.977], [2360.2, 124.458], [2358.9, 182.346], [2358.4, 151.83], [2354.6, 225.238], [2353.1, 186.839], [2352.6, 238.123], [2350.8, 231.981], [2347.0, 316.927], [2344.8, 359.58], [2344.1, 265.571], [2339.9, 431.641], [2337.4, 296.154], [2333.3, 353.314], [2331.6, 403.271], [2331.5, 429.598], [2329.5, 274.163], [2324.8, 319.987], [2324.1, 293.389], [2313.5, 0.024], [2313.0, 0.135], [2311.8, 306.833], [2306.3, 0.003], [2300.0, 12.764], [2298.2, 0.031], [2297.7, 0.016], [2293.0, 0.037], [2291.3, 0.011], [2288.5, 0.01], [2285.9, 0.022], [2285.1, 0.023], [2284.3, 0.046], [2276.9, 0.064], [2267.3, 0.134], [2251.0, 130.421], [2250.0, 15.444], [2240.0, 2.232], [2231.1, 870.752], [2210.1, 0.01], [2200.0, 25.0], [2174.0, 260.605], [2150.0, 2.325], [2147.0, 1387.685], [2139.3, 223.307], [2136.2, 1324.391], [2106.1, 242.549], [2100.0, 0.75], [2074.9, 0.011], [2074.4, 259.452], [2065.6, 0.5], [2043.2, 260.078], [2037.5, 1747.044], [2001.0, 0.529], [2000.0, 0.55], [1950.5, 0.5], [1938.4, 0.004], [1935.0, 0.025], [1931.4, 0.019], [1930.0, 0.063], [1925.3, 0.013], [1905.9, 0.008], [1900.0, 0.145], [1899.0, 2.106], [1888.5, 0.021], [1882.9, 0.144], [1882.5, 0.014], [1873.3, 0.008], [1860.0, 0.161], [1857.6, 1604.251], [1851.3, 0.072], [1845.5, 0.022], [1840.7, 0.008], [1839.7, 0.015], [1819.8, 0.072], [1818.2, 0.055], [1808.2, 0.012], [1805.5, 0.5], [1802.6, 0.024], [1797.0, 0.195], [1796.9, 0.016], [1788.2, 0.072], [1775.6, 0.008], [1759.7, 0.026], [1756.7, 0.072], [1754.1, 0.017], [1750.0, 0.177], [1743.0, 0.008], [1725.2, 0.144], [1716.8, 0.028], [1711.3, 0.019], [1710.5, 0.008], [1700.0, 0.588], [1693.6, 0.072], [1685.0, 0.059], [1680.0, 0.41], [1677.9, 0.008], [1668.5, 0.02], [1662.1, 0.072]], "asks": [[2369.0, 1.102], [2369.1, 135.97], [2371.2, 242.803], [2372.6, 226.859], [2372.7, 295.508], [2374.1, 206.159], [2374.2, 251.105], [2375.4, 376.321], [2376.5, 359.275], [2378.5, 301.376], [2379.2, 216.289], [2383.3, 475.317], [2384.2, 0.001], [2388.9, 344.157], [2390.6, 332.978], [2391.4, 339.556], [2392.5, 301.356], [2394.1, 443.585], [2395.8, 464.859], [2398.8, 2.25], [2399.4, 0.452], [2408.8, 2.249], [2418.8, 4.499], [2425.0, 2.8], [2430.3, 0.068], [2430.4, 0.244], [2434.8, 3.223], [2436.0, 0.142], [2436.1, 0.093], [2436.5, 0.022], [2439.2, 0.004], [2440.0, 3.0], [2440.4, 0.032], [2442.0, 2.881], [2448.5, 0.053], [2448.7, 0.023], [2449.8, 1.999], [2452.9, 0.048], [2453.4, 0.061], [2456.1, 1.875], [2457.4, 0.048], [2462.8, 1.999], [2466.3, 0.017], [2467.9, 4.0], [2475.0, 1.95], [2481.2, 0.029], [2483.5, 810.416], [2490.0, 1.9], [2500.0, 37.983], [2520.0, 0.049], [2525.2, 0.077], [2573.5, 239.499], [2601.6, 1164.799], [2614.1, 237.8], [2655.7, 226.429], [2660.0, 0.038], [2697.2, 231.483], [2700.0, 0.135], [2721.2, 1444.868], [2738.4, 245.345], [2770.0, 3.893], [2838.0, 1991.499], [2900.0, 0.179], [2956.2, 1601.507], [2981.0, 0.403], [3000.0, 4.705], [3074.4, 2034.701], [4275.0, 9.802], [5065.0, 12.506], [8435.0, 3.573], [10000.0, 0.411]], "action": "partial"}}
1618677912.561603: {"channel": "orderbook", "market": "ETH/USD", "type": "update", "data": {"time": 1618677912.5677662, "checksum": 2250332713, "bids": [], "asks": [[2378.5, 608.328]], "action": "update"}}
1618677912.585831: {"channel": "orderbook", "market": "PAXG/USD", "type": "update", "data": {"time": 1618677912.595705, "checksum": 3020203689, "bids": [], "asks": [], "action": "update"}}
1618677912.5900202: {"channel": "orderbook", "market": "DAI/USD", "type": "update", "data": {"time": 1618677912.5971508, "checksum": 12838118, "bids": [], "asks": [], "action": "update"}}
1618677912.868067: {"channel": "orderbook", "market": "BRZ/USDT", "type": "update", "data": {"time": 1618677912.8041537, "checksum": 2401773231, "bids": [], "asks": [], "action": "update"}}
1618677913.17715: {"channel": "orderbook", "market": "SOL/USDT", "type": "update", "data": {"time": 1618677913.0844505, "checksum": 3788392910, "bids": [], "asks": [], "action": "update"}}
1618677913.177236: {"channel": "orderbook", "market": "PAXG/USDT", "type": "update", "data": {"time": 1618677913.0824924, "checksum": 3578414220, "bids": [], "asks": [], "action": "update"}}
1618677913.1772978: {"channel": "orderbook", "market": "WBTC/USD", "type": "update", "data": {"time": 1618677913.1005147, "checksum": 2029076448, "bids": [], "asks": [[60740.0, 8.7479]], "action": "update"}}
1618677913.198452: {"channel": "orderbook", "market": "AUD/USD", "type": "update", "data": {"time": 1618677913.208735, "checksum": 663486434, "bids": [], "asks": [], "action": "update"}}
1618677913.204907: {"channel": "orderbook", "market": "WBTC/USD", "type": "update", "data": {"time": 1618677913.2143304, "checksum": 1405573081, "bids": [[60435.0, 1.1213]], "asks": [[60794.0, 1.1366]], "action": "update"}}
1618677913.2071: {"channel": "orderbook", "market": "UNI/USD", "type": "update", "data": {"time": 1618677913.2173576, "checksum": 2490358294, "bids": [], "asks": [[35.674, 1708.3]], "action": "update"}}
1618677913.219157: {"channel": "orderbook", "market": "WBTC/USD", "type": "update", "data": {"time": 1618677913.2314095, "checksum": 3380271470, "bids": [[60409.0, 0.0]], "asks": [], "action": "update"}}
1618677913.253506: {"channel": "orderbook", "market": "UNI/USD", "type": "update", "data": {"time": 1618677913.262703, "checksum": 265705221, "bids": [], "asks": [[35.888, 0.0]], "action": "update"}}
1618677913.25357: {"channel": "orderbook", "market": "USDT/USD", "type": "update", "data": {"time": 1618677913.266939, "checksum": 2693766571, "bids": [], "asks": [], "action": "update"}}
1618677913.321234: {"channel": "orderbook", "market": "WBTC/USD", "type": "update", "data": {"time": 1618677913.3210466, "checksum": 3380271470, "bids": [], "asks": [], "action": "update"}}
1618677913.357183: {"channel": "orderbook", "market": "UNI/USD", "type": "update", "data": {"time": 1618677913.361027, "checksum": 265705221, "bids": [], "asks": [], "action": "update"}}
1618677913.480783: {"channel": "orderbook", "market": "ETH/USD", "type": "update", "data": {"time": 1618677913.4906573, "checksum": 2250332713, "bids": [], "asks": [], "action": "update"}}
1618677913.626107: {"channel": "orderbook", "market": "PAXG/USD", "type": "update", "data": {"time": 1618677913.6308925, "checksum": 3020203689, "bids": [], "asks": [], "action": "update"}}
1618677913.6261601: {"channel": "orderbook", "market": "DAI/USD", "type": "update", "data": {"time": 1618677913.633457, "checksum": 12838118, "bids": [], "asks": [], "action": "update"}}
1618677913.8225: {"channel": "orderbook", "market": "BRZ/USDT", "type": "update", "data": {"time": 1618677913.8335123, "checksum": 2401773231, "bids": [], "asks": [], "action": "update"}}
1618677914.0937889: {"channel": "orderbook", "market": "ETH/USD", "type": "update", "data": {"time": 1618677914.0669181, "checksum": 2617321757, "bids": [[2365.6, 0.039], [1662.1, 0.0]], "asks": [], "action": "update"}}
1618677914.0941281: {"channel": "orderbook", "market": "SOL/USDT", "type": "update", "data": {"time": 1618677914.1087213, "checksum": 3788392910, "bids": [], "asks": [], "action": "update"}}
1618677914.133559: {"channel": "orderbook", "market": "PAXG/USDT", "type": "update", "data": {"time": 1618677914.1382802, "checksum": 3578414220, "bids": [], "asks": [], "action": "update"}}
1618677914.220491: {"channel": "orderbook", "market": "AUD/USD", "type": "update", "data": {"time": 1618677914.226412, "checksum": 663486434, "bids": [], "asks": [], "action": "update"}}
1618677914.275218: {"channel": "orderbook", "market": "USDT/USD", "type": "update", "data": {"time": 1618677914.2870862, "checksum": 2693766571, "bids": [], "asks": [], "action": "update"}}
1618677914.2791219: {"channel": "orderbook", "market": "ETH/USD", "type": "update", "data": {"time": 1618677914.2922056, "checksum": 3695443670, "bids": [[2365.3, 69.215], [1668.5, 0.0]], "asks": [], "action": "update"}}
1618677914.333358: {"channel": "orderbook", "market": "WBTC/USD", "type": "update", "data": {"time": 1618677914.3422537, "checksum": 3380271470, "bids": [], "asks": [], "action": "update"}}
1618677914.38358: {"channel": "orderbook", "market": "ETH/USD", "type": "update", "data": {"time": 1618677914.3920062, "checksum": 2724671866, "bids": [], "asks": [[2368.2, 116.275]], "action": "update"}}
1618677914.5032609: {"channel": "orderbook", "market": "ETH/USD", "type": "update", "data": {"time": 1618677914.5160043, "checksum": 2724671866, "bids": [], "asks": [], "action": "update"}}
1618677914.5758631: {"channel": "orderbook", "market": "UNI/USD", "type": "update", "data": {"time": 1618677914.5839767, "checksum": 265705221, "bids": [], "asks": [], "action": "update"}}
1618677914.7128708: {"channel": "orderbook", "market": "ETH/USD", "type": "update", "data": {"time": 1618677914.6668751, "checksum": 1171288949, "bids": [[2362.0, 0.0], [1668.5, 0.02]], "asks": [], "action": "update"}}
1618677914.7130508: {"channel": "orderbook", "market": "PAXG/USD", "type": "update", "data": {"time": 1618677914.6628835, "checksum": 3020203689, "bids": [], "asks": [], "action": "update"}}
1618677914.713096: {"channel": "orderbook", "market": "DAI/USD", "type": "update", "data": {"time": 1618677914.664337, "checksum": 12838118, "bids": [], "asks": [], "action": "update"}}
1618677914.847817: {"channel": "orderbook", "market": "BRZ/USDT", "type": "update", "data": {"time": 1618677914.8538554, "checksum": 2401773231, "bids": [], "asks": [], "action": "update"}}
1618677915.126873: {"channel": "orderbook", "market": "SOL/USDT", "type": "update", "data": {"time": 1618677915.1341064, "checksum": 3788392910, "bids": [], "asks": [], "action": "update"}}
1618677915.1882298: {"channel": "orderbook", "market": "PAXG/USDT", "type": "update", "data": {"time": 1618677915.1827466, "checksum": 3578414220, "bids": [], "asks": [], "action": "update"}}
1618677915.2517738: {"channel": "orderbook", "market": "AUD/USD", "type": "update", "data": {"time": 1618677915.2535415, "checksum": 663486434, "bids": [], "asks": [], "action": "update"}}
1618677915.261423: {"channel": "orderbook", "market": "ETH/USD", "type": "update", "data": {"time": 1618677915.2663345, "checksum": 1789635487, "bids": [], "asks": [[2368.2, 0.0]], "action": "update"}}
1618677915.3040771: {"channel": "orderbook", "market": "USDT/USD", "type": "update", "data": {"time": 1618677915.3133473, "checksum": 2693766571, "bids": [], "asks": [], "action": "update"}}
1618677915.340374: {"channel": "orderbook", "market": "ETH/USD", "type": "update", "data": {"time": 1618677915.3423615, "checksum": 1793192245, "bids": [], "asks": [[2372.7, 0.0]], "action": "update"}}
1618677915.363643: {"channel": "orderbook", "market": "WBTC/USD", "type": "update", "data": {"time": 1618677915.3699822, "checksum": 3380271470, "bids": [], "asks": [], "action": "update"}}
1618677915.535636: {"channel": "orderbook", "market": "ETH/USD", "type": "update", "data": {"time": 1618677915.5440059, "checksum": 1793192245, "bids": [], "asks": [], "action": "update"}}
1618677915.5890691: {"channel": "orderbook", "market": "UNI/USD", "type": "update", "data": {"time": 1618677915.6015685, "checksum": 265705221, "bids": [], "asks": [], "action": "update"}}
1618677915.689491: {"channel": "orderbook", "market": "PAXG/USD", "type": "update", "data": {"time": 1618677915.693546, "checksum": 3020203689, "bids": [], "asks": [], "action": "update"}}
1618677915.68958: {"channel": "orderbook", "market": "DAI/USD", "type": "update", "data": {"time": 1618677915.6998684, "checksum": 12838118, "bids": [], "asks": [], "action": "update"}}
1618677915.871016: {"channel": "orderbook", "market": "BRZ/USDT", "type": "update", "data": {"time": 1618677915.8836606, "checksum": 2401773231, "bids": [], "asks": [], "action": "update"}}
1618677916.1520588: {"channel": "orderbook", "market": "SOL/USDT", "type": "update", "data": {"time": 1618677916.1613991, "checksum": 3788392910, "bids": [], "asks": [], "action": "update"}}
1618677916.204275: {"channel": "orderbook", "market": "ETH/USD", "type": "update", "data": {"time": 1618677916.2091691, "checksum": 1040441016, "bids": [], "asks": [[2380.5, 302.356]], "action": "update"}}
1618677916.231152: {"channel": "orderbook", "market": "PAXG/USDT", "type": "update", "data": {"time": 1618677916.2330463, "checksum": 3578414220, "bids": [], "asks": [], "action": "update"}}
1618677916.270306: {"channel": "orderbook", "market": "AUD/USD", "type": "update", "data": {"time": 1618677916.2768054, "checksum": 663486434, "bids": [], "asks": [], "action": "update"}}
1618677916.329204: {"channel": "orderbook", "market": "USDT/USD", "type": "update", "data": {"time": 1618677916.342883, "checksum": 2693766571, "bids": [], "asks": [], "action": "update"}}
1618677916.393725: {"channel": "orderbook", "market": "WBTC/USD", "type": "update", "data": {"time": 1618677916.3943372, "checksum": 3380271470, "bids": [], "asks": [], "action": "update"}}
1618677916.5583181: {"channel": "orderbook", "market": "ETH/USD", "type": "update", "data": {"time": 1618677916.5706623, "checksum": 1040441016, "bids": [], "asks": [], "action": "update"}}
1618677916.6194181: {"channel": "orderbook", "market": "UNI/USD", "type": "update", "data": {"time": 1618677916.6259463, "checksum": 265705221, "bids": [], "asks": [], "action": "update"}}
1618677916.7154639: {"channel": "orderbook", "market": "PAXG/USD", "type": "update", "data": {"time": 1618677916.7231, "checksum": 3020203689, "bids": [], "asks": [], "action": "update"}}
1618677916.721895: {"channel": "orderbook", "market": "DAI/USD", "type": "update", "data": {"time": 1618677916.7283328, "checksum": 12838118, "bids": [], "asks": [], "action": "update"}}
1618677916.812495: {"channel": "orderbook", "market": "ETH/USD", "type": "update", "data": {"time": 1618677916.8220308, "checksum": 4249780659, "bids": [[2365.6, 0.0], [1662.1, 0.072]], "asks": [], "action": "update"}}
1618677916.8947809: {"channel": "orderbook", "market": "BRZ/USDT", "type": "update", "data": {"time": 1618677916.903956, "checksum": 2401773231, "bids": [], "asks": [], "action": "update"}}
1618677916.989672: {"channel": "orderbook", "market": "ETH/USD", "type": "update", "data": {"time": 1618677916.995887, "checksum": 1387120939, "bids": [[2365.3, 0.0], [1630.6, 0.072]], "asks": [], "action": "update"}}
1618677917.1744041: {"channel": "orderbook", "market": "SOL/USDT", "type": "update", "data": {"time": 1618677917.1869137, "checksum": 3788392910, "bids": [], "asks": [], "action": "update"}}
1618677917.2887008: {"channel": "orderbook", "market": "PAXG/USDT", "type": "update", "data": {"time": 1618677917.2906682, "checksum": 3578414220, "bids": [], "asks": [], "action": "update"}}
1618677917.30537: {"channel": "orderbook", "market": "AUD/USD", "type": "update", "data": {"time": 1618677917.3051045, "checksum": 663486434, "bids": [], "asks": [], "action": "update"}}
1618677917.33762: {"channel": "orderbook", "market": "ETH/USD", "type": "update", "data": {"time": 1618677917.3470795, "checksum": 2416089181, "bids": [[2362.3, 0.76], [1630.6, 0.0]], "asks": [], "action": "update"}}
1618677917.356331: {"channel": "orderbook", "market": "USDT/USD", "type": "update", "data": {"time": 1618677917.3664386, "checksum": 2693766571, "bids": [], "asks": [], "action": "update"}}
1618677917.42024: {"channel": "orderbook", "market": "WBTC/USD", "type": "update", "data": {"time": 1618677917.425662, "checksum": 3380271470, "bids": [], "asks": [], "action": "update"}}
1618677917.502625: {"channel": "orderbook", "market": "WBTC/USD", "type": "update", "data": {"time": 1618677917.5167942, "checksum": 2112709877, "bids": [], "asks": [[60743.0, 0.0]], "action": "update"}}
1618677917.5916438: {"channel": "orderbook", "market": "ETH/USD", "type": "update", "data": {"time": 1618677917.5964165, "checksum": 2416089181, "bids": [], "asks": [], "action": "update"}}
1618677917.6412091: {"channel": "orderbook", "market": "UNI/USD", "type": "update", "data": {"time": 1618677917.650935, "checksum": 265705221, "bids": [], "asks": [], "action": "update"}}
1618677917.7502432: {"channel": "orderbook", "market": "PAXG/USD", "type": "update", "data": {"time": 1618677917.7546403, "checksum": 3020203689, "bids": [], "asks": [], "action": "update"}}
1618677917.75028: {"channel": "orderbook", "market": "DAI/USD", "type": "update", "data": {"time": 1618677917.7561831, "checksum": 12838118, "bids": [], "asks": [], "action": "update"}}
1618677917.9184818: {"channel": "orderbook", "market": "BRZ/USDT", "type": "update", "data": {"time": 1618677917.9303927, "checksum": 2401773231, "bids": [], "asks": [], "action": "update"}}
1618677917.941739: {"channel": "orderbook", "market": "ETH/USD", "type": "update", "data": {"time": 1618677917.9464045, "checksum": 2291117718, "bids": [], "asks": [[2369.0, 0.0]], "action": "update"}}
1618677917.966932: {"channel": "orderbook", "market": "ETH/USD", "type": "update", "data": {"time": 1618677917.9721103, "checksum": 3045722183, "bids": [[2364.9, 1.217], [1662.1, 0.0]], "asks": [[2369.1, 0.0], [2370.0, 0.897]], "action": "update"}}
1618677918.040468: {"channel": "orderbook", "market": "ETH/USD", "type": "update", "data": {"time": 1618677918.047221, "checksum": 1930718962, "bids": [[2362.3, 0.0], [2361.2, 6.74]], "asks": [], "action": "update"}}
1618677918.092939: {"channel": "orderbook", "market": "ETH/USD", "type": "update", "data": {"time": 1618677918.0964234, "checksum": 3687090299, "bids": [[2366.4, 80.495], [2363.9, 0.0]], "asks": [], "action": "update"}}
1618677918.1287181: {"channel": "orderbook", "market": "UNI/USD", "type": "update", "data": {"time": 1618677918.1205661, "checksum": 3589950750, "bids": [[35.183, 55.2]], "asks": [], "action": "update"}}
1618677918.13409: {"channel": "orderbook", "market": "WBTC/USD", "type": "update", "data": {"time": 1618677918.143024, "checksum": 1659589269, "bids": [], "asks": [[60923.0, 13.8816]], "action": "update"}}
1618677918.1678789: {"channel": "orderbook", "market": "ETH/USD", "type": "update", "data": {"time": 1618677918.1723008, "checksum": 3681513046, "bids": [], "asks": [[2370.0, 0.0]], "action": "update"}}
1618677918.198826: {"channel": "orderbook", "market": "SOL/USDT", "type": "update", "data": {"time": 1618677918.2087595, "checksum": 3788392910, "bids": [], "asks": [], "action": "update"}}
1618677918.2940311: {"channel": "orderbook", "market": "ETH/USD", "type": "update", "data": {"time": 1618677918.3036737, "checksum": 1752815390, "bids": [[2361.2, 0.0], [1662.1, 0.072]], "asks": [], "action": "update"}}
1618677918.328573: {"channel": "orderbook", "market": "AUD/USD", "type": "update", "data": {"time": 1618677918.329534, "checksum": 663486434, "bids": [], "asks": [], "action": "update"}}
1618677918.3420439: {"channel": "orderbook", "market": "PAXG/USDT", "type": "update", "data": {"time": 1618677918.34449, "checksum": 3578414220, "bids": [], "asks": [], "action": "update"}}
1618677918.381972: {"channel": "orderbook", "market": "USDT/USD", "type": "update", "data": {"time": 1618677918.390256, "checksum": 2693766571, "bids": [], "asks": [], "action": "update"}}
1618677918.445034: {"channel": "orderbook", "market": "WBTC/USD", "type": "update", "data": {"time": 1618677918.4520712, "checksum": 1659589269, "bids": [], "asks": [], "action": "update"}}
1618677918.45765: {"channel": "orderbook", "market": "ETH/USD", "type": "update", "data": {"time": 1618677918.4688697, "checksum": 1576464896, "bids": [[2365.9, 0.906], [1662.1, 0.0]], "asks": [], "action": "update"}}
1618677918.461952: {"channel": "orderbook", "market": "UNI/USD", "type": "update", "data": {"time": 1618677918.4739106, "checksum": 2522869048, "bids": [[35.144, 0.0]], "asks": [], "action": "update"}}
1618677918.503863: {"channel": "orderbook", "market": "ETH/USD", "type": "update", "data": {"time": 1618677918.5167866, "checksum": 3552102128, "bids": [[2364.9, 0.0], [1662.1, 0.072]], "asks": [], "action": "update"}}
1618677918.607531: {"channel": "orderbook", "market": "ETH/USD", "type": "update", "data": {"time": 1618677918.6171381, "checksum": 3552102128, "bids": [], "asks": [], "action": "update"}}
1618677918.664741: {"channel": "orderbook", "market": "UNI/USD", "type": "update", "data": {"time": 1618677918.6766608, "checksum": 2522869048, "bids": [], "asks": [], "action": "update"}}
1618677918.77584: {"channel": "orderbook", "market": "PAXG/USD", "type": "update", "data": {"time": 1618677918.7819798, "checksum": 3020203689, "bids": [], "asks": [], "action": "update"}}
1618677918.775929: {"channel": "orderbook", "market": "DAI/USD", "type": "update", "data": {"time": 1618677918.7847455, "checksum": 12838118, "bids": [], "asks": [], "action": "update"}}
1618677918.934357: {"channel": "orderbook", "market": "ETH/USD", "type": "update", "data": {"time": 1618677918.9457126, "checksum": 2870448204, "bids": [[2364.1, 0.76], [1662.1, 0.0]], "asks": [], "action": "update"}}
1618677918.940227: {"channel": "orderbook", "market": "BRZ/USDT", "type": "update", "data": {"time": 1618677918.9546032, "checksum": 2401773231, "bids": [], "asks": [], "action": "update"}}
1618677918.954464: {"channel": "orderbook", "market": "ETH/USD", "type": "update", "data": {"time": 1618677918.9668, "checksum": 1828783174, "bids": [], "asks": [[2373.2, 7.498]], "action": "update"}}
1618677919.1360471: {"channel": "orderbook", "market": "ETH/USD", "type": "update", "data": {"time": 1618677919.1454635, "checksum": 3429902623, "bids": [[2364.1, 0.0], [1662.1, 0.072]], "asks": [], "action": "update"}}
1618677919.206296: {"channel": "orderbook", "market": "ETH/USD", "type": "update", "data": {"time": 1618677919.2176857, "checksum": 109946698, "bids": [], "asks": [[2370.8, 0.654]], "action": "update"}}
1618677919.222398: {"channel": "orderbook", "market": "SOL/USDT", "type": "update", "data": {"time": 1618677919.2344084, "checksum": 3788392910, "bids": [], "asks": [], "action": "update"}}
1618677919.348568: {"channel": "orderbook", "market": "AUD/USD", "type": "update", "data": {"time": 1618677919.3589382, "checksum": 663486434, "bids": [], "asks": [], "action": "update"}}
1618677919.389569: {"channel": "orderbook", "market": "PAXG/USDT", "type": "update", "data": {"time": 1618677919.3920286, "checksum": 3578414220, "bids": [], "asks": [], "action": "update"}}
1618677919.4068081: {"channel": "orderbook", "market": "USDT/USD", "type": "update", "data": {"time": 1618677919.4186163, "checksum": 2693766571, "bids": [], "asks": [], "action": "update"}}
1618677919.409596: {"channel": "orderbook", "market": "WBTC/USD", "type": "update", "data": {"time": 1618677919.4207122, "checksum": 633040566, "bids": [], "asks": [[60740.0, 0.0]], "action": "update"}}
1618677919.465438: {"channel": "orderbook", "market": "WBTC/USD", "type": "update", "data": {"time": 1618677919.4746866, "checksum": 633040566, "bids": [], "asks": [], "action": "update"}}
1618677919.634062: {"channel": "orderbook", "market": "ETH/USD", "type": "update", "data": {"time": 1618677919.6457536, "checksum": 109946698, "bids": [], "asks": [], "action": "update"}}
1618677919.6946769: {"channel": "orderbook", "market": "UNI/USD", "type": "update", "data": {"time": 1618677919.703774, "checksum": 2522869048, "bids": [], "asks": [], "action": "update"}}
1618677919.763437: {"channel": "orderbook", "market": "WBTC/USD", "type": "update", "data": {"time": 1618677919.7729025, "checksum": 2763376857, "bids": [], "asks": [[60756.0, 10.025]], "action": "update"}}
1618677919.8073442: {"channel": "orderbook", "market": "DAI/USD", "type": "update", "data": {"time": 1618677919.813232, "checksum": 12838118, "bids": [], "asks": [], "action": "update"}}
1618677919.807383: {"channel": "orderbook", "market": "PAXG/USD", "type": "update", "data": {"time": 1618677919.8143964, "checksum": 3020203689, "bids": [], "asks": [], "action": "update"}}
1618677919.968168: {"channel": "orderbook", "market": "BRZ/USDT", "type": "update", "data": {"time": 1618677919.9810312, "checksum": 2401773231, "bids": [], "asks": [], "action": "update"}}
1618677919.994714: {"channel": "orderbook", "market": "WBTC/USD", "type": "update", "data": {"time": 1618677919.9992523, "checksum": 2663998948, "bids": [[60277.0, 17.9441], [60083.0, 0.0]], "asks": [], "action": "update"}}
1618677920.2484102: {"channel": "orderbook", "market": "SOL/USDT", "type": "update", "data": {"time": 1618677920.2589743, "checksum": 3788392910, "bids": [], "asks": [], "action": "update"}}
1618677920.3763578: {"channel": "orderbook", "market": "AUD/USD", "type": "update", "data": {"time": 1618677920.3871315, "checksum": 663486434, "bids": [], "asks": [], "action": "update"}}
1618677920.4288158: {"channel": "orderbook", "market": "USDT/USD", "type": "update", "data": {"time": 1618677920.4404805, "checksum": 2693766571, "bids": [], "asks": [], "action": "update"}}
1618677920.4352949: {"channel": "orderbook", "market": "PAXG/USDT", "type": "update", "data": {"time": 1618677920.43471, "checksum": 3578414220, "bids": [], "asks": [], "action": "update"}}
1618677920.4851918: {"channel": "orderbook", "market": "ETH/USD", "type": "update", "data": {"time": 1618677920.4947536, "checksum": 3393112461, "bids": [[2363.9, 0.76], [1662.1, 0.0]], "asks": [], "action": "update"}}
1618677920.50425: {"channel": "orderbook", "market": "WBTC/USD", "type": "update", "data": {"time": 1618677920.5022378, "checksum": 2663998948, "bids": [], "asks": [], "action": "update"}}
1618677920.6653771: {"channel": "orderbook", "market": "ETH/USD", "type": "update", "data": {"time": 1618677920.6711009, "checksum": 3393112461, "bids": [], "asks": [], "action": "update"}}
1618677920.728145: {"channel": "orderbook", "market": "UNI/USD", "type": "update", "data": {"time": 1618677920.7249603, "checksum": 2522869048, "bids": [], "asks": [], "action": "update"}}
1618677920.8591628: {"channel": "orderbook", "market": "PAXG/USD", "type": "update", "data": {"time": 1618677920.8651128, "checksum": 3020203689, "bids": [], "asks": [], "action": "update"}}
1618677920.8592079: {"channel": "orderbook", "market": "DAI/USD", "type": "update", "data": {"time": 1618677920.8665736, "checksum": 12838118, "bids": [], "asks": [], "action": "update"}}
1618677920.9913821: {"channel": "orderbook", "market": "BRZ/USDT", "type": "update", "data": {"time": 1618677921.0049443, "checksum": 2401773231, "bids": [], "asks": [], "action": "update"}}
1618677921.311508: {"channel": "orderbook", "market": "SOL/USDT", "type": "update", "data": {"time": 1618677921.2848334, "checksum": 3788392910, "bids": [], "asks": [], "action": "update"}}
1618677921.410285: {"channel": "orderbook", "market": "AUD/USD", "type": "update", "data": {"time": 1618677921.417513, "checksum": 663486434, "bids": [], "asks": [], "action": "update"}}
1618677921.457155: {"channel": "orderbook", "market": "USDT/USD", "type": "update", "data": {"time": 1618677921.4661145, "checksum": 2693766571, "bids": [], "asks": [], "action": "update"}}
1618677921.480365: {"channel": "orderbook", "market": "PAXG/USDT", "type": "update", "data": {"time": 1618677921.4790237, "checksum": 3578414220, "bids": [], "asks": [], "action": "update"}}
1618677921.523197: {"channel": "orderbook", "market": "WBTC/USD", "type": "update", "data": {"time": 1618677921.5276406, "checksum": 2663998948, "bids": [], "asks": [], "action": "update"}}
1618677921.629133: {"channel": "orderbook", "market": "ETH/USD", "type": "update", "data": {"time": 1618677921.6378028, "checksum": 3011251322, "bids": [[2366.4, 0.0], [1662.1, 0.072]], "asks": [], "action": "update"}}
1618677921.6824079: {"channel": "orderbook", "market": "ETH/USD", "type": "update", "data": {"time": 1618677921.686483, "checksum": 3845083547, "bids": [], "asks": [[2373.2, 0.0]], "action": "update"}}
1618677921.682527: {"channel": "orderbook", "market": "WBTC/USD", "type": "update", "data": {"time": 1618677921.6950717, "checksum": 3234155762, "bids": [[60454.0, 14.149]], "asks": [], "action": "update"}}
1618677921.7447538: {"channel": "orderbook", "market": "UNI/USD", "type": "update", "data": {"time": 1618677921.7513115, "checksum": 2522869048, "bids": [], "asks": [], "action": "update"}}
1618677921.8305302: {"channel": "orderbook", "market": "ETH/USD", "type": "update", "data": {"time": 1618677921.836613, "checksum": 3973587191, "bids": [], "asks": [[2370.1, 130.865]], "action": "update"}}
1618677921.867789: {"channel": "orderbook", "market": "PAXG/USD", "type": "update", "data": {"time": 1618677921.878902, "checksum": 3020203689, "bids": [], "asks": [], "action": "update"}}
1618677921.8678331: {"channel": "orderbook", "market": "DAI/USD", "type": "update", "data": {"time": 1618677921.8804154, "checksum": 12838118, "bids": [], "asks": [], "action": "update"}}
1618677921.955696: {"channel": "orderbook", "market": "ETH/USD", "type": "update", "data": {"time": 1618677921.964263, "checksum": 539829845, "bids": [], "asks": [[2372.9, 6.949]], "action": "update"}}
1618677921.980154: {"channel": "orderbook", "market": "ETH/USD", "type": "update", "data": {"time": 1618677921.9928744, "checksum": 3964020569, "bids": [], "asks": [[2371.7, 118.585]], "action": "update"}}
1618677922.000789: {"channel": "orderbook", "market": "ETH/USD", "type": "update", "data": {"time": 1618677922.0128338, "checksum": 836829610, "bids": [], "asks": [[2371.2, 0.0]], "action": "update"}}
1618677922.0275252: {"channel": "orderbook", "market": "BRZ/USDT", "type": "update", "data": {"time": 1618677922.0324926, "checksum": 2401773231, "bids": [], "asks": [], "action": "update"}}
1618677922.1058261: {"channel": "orderbook", "market": "ETH/USD", "type": "update", "data": {"time": 1618677922.1155512, "checksum": 3357005458, "bids": [], "asks": [[2399.9, 310.269], [2483.5, 0.0]], "action": "update"}}
1618677922.167753: {"channel": "orderbook", "market": "ETH/USD", "type": "update", "data": {"time": 1618677922.1616218, "checksum": 4172264984, "bids": [], "asks": [[2487.6, 806.8]], "action": "update"}}
1618677922.180852: {"channel": "orderbook", "market": "ETH/USD", "type": "update", "data": {"time": 1618677922.187015, "checksum": 1517133214, "bids": [], "asks": [[2372.9, 0.0], [3079.6, 1594.544]], "action": "update"}}
1618677922.2554328: {"channel": "orderbook", "market": "WBTC/USD", "type": "update", "data": {"time": 1618677922.2689295, "checksum": 904394848, "bids": [[60432.0, 0.0]], "asks": [], "action": "update"}}
1618677922.2958531: {"channel": "orderbook", "market": "SOL/USDT", "type": "update", "data": {"time": 1618677922.3086808, "checksum": 3788392910, "bids": [], "asks": [], "action": "update"}}
1618677922.4511309: {"channel": "orderbook", "market": "AUD/USD", "type": "update", "data": {"time": 1618677922.4595723, "checksum": 663486434, "bids": [], "asks": [], "action": "update"}}
1618677922.483125: {"channel": "orderbook", "market": "USDT/USD", "type": "update", "data": {"time": 1618677922.4928489, "checksum": 2693766571, "bids": [], "asks": [], "action": "update"}}
1618677922.516122: {"channel": "orderbook", "market": "PAXG/USDT", "type": "update", "data": {"time": 1618677922.5250115, "checksum": 3578414220, "bids": [], "asks": [], "action": "update"}}
1618677922.556266: {"channel": "orderbook", "market": "WBTC/USD", "type": "update", "data": {"time": 1618677922.559353, "checksum": 904394848, "bids": [], "asks": [], "action": "update"}}
1618677922.63626: {"channel": "orderbook", "market": "WBTC/USD", "type": "update", "data": {"time": 1618677922.6489708, "checksum": 562115114, "bids": [[60457.0, 1.1364], [60435.0, 0.0]], "asks": [], "action": "update"}}
1618677922.70291: {"channel": "orderbook", "market": "ETH/USD", "type": "update", "data": {"time": 1618677922.7112665, "checksum": 1517133214, "bids": [], "asks": [], "action": "update"}}
1618677922.767915: {"channel": "orderbook", "market": "UNI/USD", "type": "update", "data": {"time": 1618677922.7752266, "checksum": 2522869048, "bids": [], "asks": [], "action": "update"}}
1618677922.9068081: {"channel": "orderbook", "market": "PAXG/USD", "type": "update", "data": {"time": 1618677922.9057515, "checksum": 3020203689, "bids": [], "asks": [], "action": "update"}}
1618677922.9068449: {"channel": "orderbook", "market": "DAI/USD", "type": "update", "data": {"time": 1618677922.9073782, "checksum": 12838118, "bids": [], "asks": [], "action": "update"}}
1618677923.0456672: {"channel": "orderbook", "market": "BRZ/USDT", "type": "update", "data": {"time": 1618677923.0550787, "checksum": 2401773231, "bids": [], "asks": [], "action": "update"}}
1618677923.056606: {"channel": "orderbook", "market": "ETH/USD", "type": "update", "data": {"time": 1618677923.0615678, "checksum": 2383008786, "bids": [], "asks": [[2601.6, 0.0]], "action": "update"}}
1618677923.1841018: {"channel": "orderbook", "market": "ETH/USD", "type": "update", "data": {"time": 1618677923.188218, "checksum": 1882680580, "bids": [[2363.9, 0.0], [1630.6, 0.072]], "asks": [], "action": "update"}}
1618677923.3228428: {"channel": "orderbook", "market": "SOL/USDT", "type": "update", "data": {"time": 1618677923.33367, "checksum": 3788392910, "bids": [], "asks": [], "action": "update"}}
1618677923.332984: {"channel": "orderbook", "market": "ETH/USD", "type": "update", "data": {"time": 1618677923.3394513, "checksum": 1983748023, "bids": [[2364.9, 0.939], [1630.6, 0.0]], "asks": [], "action": "update"}}
1618677923.351584: {"channel": "orderbook", "market": "ETH/USD", "type": "update", "data": {"time": 1618677923.3614733, "checksum": 3354167809, "bids": [[2365.9, 0.0], [1630.6, 0.072]], "asks": [], "action": "update"}}
1618677923.452519: {"channel": "orderbook", "market": "ETH/USD", "type": "update", "data": {"time": 1618677923.4616802, "checksum": 78269109, "bids": [[2363.6, 0.76], [1630.6, 0.0]], "asks": [], "action": "update"}}
1618677923.489311: {"channel": "orderbook", "market": "AUD/USD", "type": "update", "data": {"time": 1618677923.4952059, "checksum": 663486434, "bids": [], "asks": [], "action": "update"}}
1618677923.514823: {"channel": "orderbook", "market": "USDT/USD", "type": "update", "data": {"time": 1618677923.5223696, "checksum": 2693766571, "bids": [], "asks": [], "action": "update"}}
1618677923.562849: {"channel": "orderbook", "market": "PAXG/USDT", "type": "update", "data": {"time": 1618677923.5675166, "checksum": 3578414220, "bids": [], "asks": [], "action": "update"}}
1618677923.5734022: {"channel": "orderbook", "market": "WBTC/USD", "type": "update", "data": {"time": 1618677923.5801756, "checksum": 2690740212, "bids": [[60457.0, 0.0]], "asks": [], "action": "update"}}
1618677923.585577: {"channel": "orderbook", "market": "WBTC/USD", "type": "update", "data": {"time": 1618677923.5980535, "checksum": 2286273785, "bids": [[60457.0, 0.3016]], "asks": [], "action": "update"}}
1618677923.6830971: {"channel": "orderbook", "market": "ETH/USD", "type": "update", "data": {"time": 1618677923.6878083, "checksum": 1988543178, "bids": [], "asks": [[3079.5, 2100.605]], "action": "update"}}
1618677923.732963: {"channel": "orderbook", "market": "ETH/USD", "type": "update", "data": {"time": 1618677923.7404153, "checksum": 1988543178, "bids": [], "asks": [], "action": "update"}}
1618677923.789496: {"channel": "orderbook", "market": "UNI/USD", "type": "update", "data": {"time": 1618677923.8000724, "checksum": 2522869048, "bids": [], "asks": [], "action": "update"}}
1618677923.825978: {"channel": "orderbook", "market": "ETH/USD", "type": "update", "data": {"time": 1618677923.837063, "checksum": 3265158796, "bids": [], "asks": [[2369.7, 0.814]], "action": "update"}}
1618677923.851839: {"channel": "orderbook", "market": "ETH/USD", "type": "update", "data": {"time": 1618677923.8642411, "checksum": 3953439062, "bids": [], "asks": [[2370.8, 0.0]], "action": "update"}}
1618677923.933886: {"channel": "orderbook", "market": "PAXG/USD", "type": "update", "data": {"time": 1618677923.9327621, "checksum": 3020203689, "bids": [], "asks": [], "action": "update"}}
1618677923.9339762: {"channel": "orderbook", "market": "DAI/USD", "type": "update", "data": {"time": 1618677923.936208, "checksum": 12838118, "bids": [], "asks": [], "action": "update"}}
1618677924.0184: {"channel": "orderbook", "market": "WBTC/USD", "type": "update", "data": {"time": 1618677924.0225317, "checksum": 2690740212, "bids": [[60457.0, 0.0]], "asks": [], "action": "update"}}
1618677924.035748: {"channel": "orderbook", "market": "WBTC/USD", "type": "update", "data": {"time": 1618677924.0503137, "checksum": 1491410704, "bids": [[60411.0, 1.1942]], "asks": [], "action": "update"}}
1618677924.068497: {"channel": "orderbook", "market": "BRZ/USDT", "type": "update", "data": {"time": 1618677924.0802836, "checksum": 2401773231, "bids": [], "asks": [], "action": "update"}}
1618677924.0748448: {"channel": "orderbook", "market": "ETH/USD", "type": "update", "data": {"time": 1618677924.0868163, "checksum": 2773265486, "bids": [], "asks": [[3079.6, 0.0]], "action": "update"}}
1618677924.438147: {"channel": "orderbook", "market": "SOL/USDT", "type": "update", "data": {"time": 1618677924.3592494, "checksum": 3788392910, "bids": [], "asks": [], "action": "update"}}
1618677924.5191581: {"channel": "orderbook", "market": "AUD/USD", "type": "update", "data": {"time": 1618677924.525168, "checksum": 663486434, "bids": [], "asks": [], "action": "update"}}
1618677924.5412412: {"channel": "orderbook", "market": "USDT/USD", "type": "update", "data": {"time": 1618677924.5428438, "checksum": 2693766571, "bids": [], "asks": [], "action": "update"}}
1618677924.572238: {"channel": "orderbook", "market": "WBTC/USD", "type": "update", "data": {"time": 1618677924.5727088, "checksum": 2690740212, "bids": [[60411.0, 0.0]], "asks": [], "action": "update"}}
1618677924.606336: {"channel": "orderbook", "market": "WBTC/USD", "type": "update", "data": {"time": 1618677924.6130679, "checksum": 2162286215, "bids": [[60457.0, 1.153]], "asks": [], "action": "update"}}
1618677924.606464: {"channel": "orderbook", "market": "PAXG/USDT", "type": "update", "data": {"time": 1618677924.6054218, "checksum": 3578414220, "bids": [], "asks": [], "action": "update"}}
1618677924.757142: {"channel": "orderbook", "market": "ETH/USD", "type": "update", "data": {"time": 1618677924.7674754, "checksum": 2773265486, "bids": [], "asks": [], "action": "update"}}
1618677924.8174798: {"channel": "orderbook", "market": "UNI/USD", "type": "update", "data": {"time": 1618677924.8274083, "checksum": 2522869048, "bids": [], "asks": [], "action": "update"}}
1618677924.970491: {"channel": "orderbook", "market": "PAXG/USD", "type": "update", "data": {"time": 1618677924.971912, "checksum": 3020203689, "bids": [], "asks": [], "action": "update"}}
1618677924.9705799: {"channel": "orderbook", "market": "DAI/USD", "type": "update", "data": {"time": 1618677924.9762235, "checksum": 12838118, "bids": [], "asks": [], "action": "update"}}
1618677925.0022268: {"channel": "orderbook", "market": "ETH/USD", "type": "update", "data": {"time": 1618677925.0145044, "checksum": 1376587639, "bids": [[2361.2, 1.662], [1662.1, 0.0]], "asks": [], "action": "update"}}
1618677925.057866: {"channel": "orderbook", "market": "ETH/USD", "type": "update", "data": {"time": 1618677925.0642412, "checksum": 4111352541, "bids": [[2361.2, 4.958]], "asks": [], "action": "update"}}
1618677925.090754: {"channel": "orderbook", "market": "BRZ/USDT", "type": "update", "data": {"time": 1618677925.1046705, "checksum": 2401773231, "bids": [], "asks": [], "action": "update"}}
1618677925.100092: {"channel": "orderbook", "market": "ETH/USD", "type": "update", "data": {"time": 1618677925.1112525, "checksum": 1289597305, "bids": [[2361.2, 6.74]], "asks": [], "action": "update"}}
1618677925.2333708: {"channel": "orderbook", "market": "ETH/USD", "type": "update", "data": {"time": 1618677925.240991, "checksum": 3398882748, "bids": [[2361.2, 5.078]], "asks": [], "action": "update"}}
1618677925.5675788: {"channel": "orderbook", "market": "ETH/USD", "type": "update", "data": {"time": 1618677925.5125148, "checksum": 156023038, "bids": [[2337.3, 467.171], [1668.5, 0.0]], "asks": [], "action": "update"}}
1618677925.5677261: {"channel": "orderbook", "market": "ETH/USD", "type": "update", "data": {"time": 1618677925.536053, "checksum": 2051056699, "bids": [[2361.3, 1.662], [2324.1, 0.0]], "asks": [], "action": "update"}}
1618677925.5677938: {"channel": "orderbook", "market": "AUD/USD", "type": "update", "data": {"time": 1618677925.5548718, "checksum": 663486434, "bids": [], "asks": [], "action": "update"}}
1618677925.5678341: {"channel": "orderbook", "market": "USDT/USD", "type": "update", "data": {"time": 1618677925.565396, "checksum": 2693766571, "bids": [], "asks": [], "action": "update"}}
1618677925.567871: {"channel": "orderbook", "market": "WBTC/USD", "type": "update", "data": {"time": 1618677925.5751686, "checksum": 2690740212, "bids": [[60457.0, 0.0]], "asks": [], "action": "update"}}
1618677925.571295: {"channel": "orderbook", "market": "SOL/USDT", "type": "update", "data": {"time": 1618677925.5795968, "checksum": 3788392910, "bids": [], "asks": [], "action": "update"}}
1618677925.633225: {"channel": "orderbook", "market": "WBTC/USD", "type": "update", "data": {"time": 1618677925.6420043, "checksum": 4002822152, "bids": [[60405.0, 1.1241]], "asks": [], "action": "update"}}
1618677925.6423638: {"channel": "orderbook", "market": "PAXG/USDT", "type": "update", "data": {"time": 1618677925.6453433, "checksum": 3578414220, "bids": [], "asks": [], "action": "update"}}
1618677925.66385: {"channel": "orderbook", "market": "ETH/USD", "type": "update", "data": {"time": 1618677925.672449, "checksum": 2082236875, "bids": [[2361.2, 0.0], [1668.5, 0.02]], "asks": [], "action": "update"}}
1618677925.771604: {"channel": "orderbook", "market": "ETH/USD", "type": "update", "data": {"time": 1618677925.7838414, "checksum": 2082236875, "bids": [], "asks": [], "action": "update"}}
1618677925.848792: {"channel": "orderbook", "market": "UNI/USD", "type": "update", "data": {"time": 1618677925.8595622, "checksum": 2522869048, "bids": [], "asks": [], "action": "update"}}
1618677925.9593081: {"channel": "orderbook", "market": "ETH/USD", "type": "update", "data": {"time": 1618677925.9601786, "checksum": 1360626778, "bids": [[2361.3, 3.309]], "asks": [], "action": "update"}}
1618677926.002583: {"channel": "orderbook", "market": "PAXG/USD", "type": "update", "data": {"time": 1618677926.0024889, "checksum": 3020203689, "bids": [], "asks": [], "action": "update"}}
1618677926.002666: {"channel": "orderbook", "market": "DAI/USD", "type": "update", "data": {"time": 1618677926.0108125, "checksum": 12838118, "bids": [], "asks": [], "action": "update"}}
1618677926.098797: {"channel": "orderbook", "market": "BRZ/USDT", "type": "update", "data": {"time": 1618677926.1126726, "checksum": 2401773231, "bids": [], "asks": [], "action": "update"}}
1618677926.1764631: {"channel": "orderbook", "market": "ETH/USD", "type": "update", "data": {"time": 1618677926.1827512, "checksum": 2082236875, "bids": [[2361.3, 1.662]], "asks": [], "action": "update"}}
1618677926.2142699: {"channel": "orderbook", "market": "WBTC/USD", "type": "update", "data": {"time": 1618677926.2277565, "checksum": 2690740212, "bids": [[60405.0, 0.0]], "asks": [], "action": "update"}}
1618677926.2413719: {"channel": "orderbook", "market": "WBTC/USD", "type": "update", "data": {"time": 1618677926.2546713, "checksum": 4237238790, "bids": [[60454.0, 14.6711]], "asks": [], "action": "update"}}
1618677926.3267572: {"channel": "orderbook", "market": "ETH/USD", "type": "update", "data": {"time": 1618677926.3350244, "checksum": 824135713, "bids": [[2361.3, 0.0], [1662.1, 0.072]], "asks": [], "action": "update"}}
1618677926.6952682: {"channel": "orderbook", "market": "AUD/USD", "type": "update", "data": {"time": 1618677926.5912514, "checksum": 663486434, "bids": [], "asks": [], "action": "update"}}
1618677926.695329: {"channel": "orderbook", "market": "SOL/USDT", "type": "update", "data": {"time": 1618677926.5953972, "checksum": 3788392910, "bids": [], "asks": [], "action": "update"}}
1618677926.695372: {"channel": "orderbook", "market": "USDT/USD", "type": "update", "data": {"time": 1618677926.5953648, "checksum": 2693766571, "bids": [], "asks": [], "action": "update"}}
1618677926.69541: {"channel": "orderbook", "market": "ETH/USD", "type": "update", "data": {"time": 1618677926.6088002, "checksum": 3579318904, "bids": [[2361.2, 3.308], [1662.1, 0.0]], "asks": [], "action": "update"}}
1618677926.695499: {"channel": "orderbook", "market": "SOL/USDT", "type": "update", "data": {"time": 1618677926.6364841, "checksum": 3179134886, "bids": [[20.07, 0.0]], "asks": [], "action": "update"}}
1618677926.695553: {"channel": "orderbook", "market": "WBTC/USD", "type": "update", "data": {"time": 1618677926.6605287, "checksum": 4237238790, "bids": [], "asks": [], "action": "update"}}
1618677926.6955898: {"channel": "orderbook", "market": "PAXG/USDT", "type": "update", "data": {"time": 1618677926.6990044, "checksum": 3578414220, "bids": [], "asks": [], "action": "update"}}
1618677926.801117: {"channel": "orderbook", "market": "ETH/USD", "type": "update", "data": {"time": 1618677926.8083003, "checksum": 3579318904, "bids": [], "asks": [], "action": "update"}}
1618677926.86817: {"channel": "orderbook", "market": "UNI/USD", "type": "update", "data": {"time": 1618677926.8778415, "checksum": 2522869048, "bids": [], "asks": [], "action": "update"}}
1618677927.103025: {"channel": "orderbook", "market": "SOL/USDT", "type": "update", "data": {"time": 1618677927.0415456, "checksum": 2585594572, "bids": [[26.0, 487.4]], "asks": [], "action": "update"}}
1618677927.1030972: {"channel": "orderbook", "market": "DAI/USD", "type": "update", "data": {"time": 1618677927.0433738, "checksum": 12838118, "bids": [], "asks": [], "action": "update"}}
1618677927.103136: {"channel": "orderbook", "market": "PAXG/USD", "type": "update", "data": {"time": 1618677927.0448942, "checksum": 3020203689, "bids": [], "asks": [], "action": "update"}}
1618677927.103169: {"channel": "orderbook", "market": "ETH/USD", "type": "update", "data": {"time": 1618677927.062236, "checksum": 824135713, "bids": [[2361.2, 0.0], [1662.1, 0.072]], "asks": [], "action": "update"}}
1618677927.127137: {"channel": "orderbook", "market": "BRZ/USDT", "type": "update", "data": {"time": 1618677927.1383247, "checksum": 2401773231, "bids": [], "asks": [], "action": "update"}}
1618677927.1551628: {"channel": "orderbook", "market": "ETH/USD", "type": "update", "data": {"time": 1618677927.1590104, "checksum": 434095580, "bids": [[2361.1, 0.0], [1630.6, 0.072]], "asks": [], "action": "update"}}
1618677927.187904: {"channel": "orderbook", "market": "ETH/USD", "type": "update", "data": {"time": 1618677927.183946, "checksum": 655191289, "bids": [[2365.1, 153.732], [1630.6, 0.0]], "asks": [], "action": "update"}}
1618677927.3236961: {"channel": "orderbook", "market": "ETH/USD", "type": "update", "data": {"time": 1618677927.3334823, "checksum": 3644978121, "bids": [[2361.2, 3.304], [1662.1, 0.0]], "asks": [], "action": "update"}}
1618677927.5244591: {"channel": "orderbook", "market": "ETH/USD", "type": "update", "data": {"time": 1618677927.5324888, "checksum": 655191289, "bids": [[2361.2, 0.0], [1662.1, 0.072]], "asks": [], "action": "update"}}
1618677927.5969632: {"channel": "orderbook", "market": "SOL/USDT", "type": "update", "data": {"time": 1618677927.6046734, "checksum": 2585594572, "bids": [], "asks": [], "action": "update"}}
1618677927.60657: {"channel": "orderbook", "market": "USDT/USD", "type": "update", "data": {"time": 1618677927.6129997, "checksum": 2693766571, "bids": [], "asks": [], "action": "update"}}
1618677927.6102242: {"channel": "orderbook", "market": "AUD/USD", "type": "update", "data": {"time": 1618677927.6206446, "checksum": 663486434, "bids": [], "asks": [], "action": "update"}}
1618677927.682724: {"channel": "orderbook", "market": "WBTC/USD", "type": "update", "data": {"time": 1618677927.6844726, "checksum": 4237238790, "bids": [], "asks": [], "action": "update"}}
1618677927.727183: {"channel": "orderbook", "market": "PAXG/USDT", "type": "update", "data": {"time": 1618677927.7346392, "checksum": 3578414220, "bids": [], "asks": [], "action": "update"}}
1618677927.823657: {"channel": "orderbook", "market": "ETH/USD", "type": "update", "data": {"time": 1618677927.8338501, "checksum": 655191289, "bids": [], "asks": [], "action": "update"}}
1618677927.895116: {"channel": "orderbook", "market": "UNI/USD", "type": "update", "data": {"time": 1618677927.9044251, "checksum": 2522869048, "bids": [], "asks": [], "action": "update"}}
1618677928.037941: {"channel": "orderbook", "market": "WBTC/USD", "type": "update", "data": {"time": 1618677928.0526206, "checksum": 2690740212, "bids": [[60454.0, 14.149]], "asks": [], "action": "update"}}
1618677928.0685692: {"channel": "orderbook", "market": "PAXG/USD", "type": "update", "data": {"time": 1618677928.074079, "checksum": 3020203689, "bids": [], "asks": [], "action": "update"}}
1618677928.068615: {"channel": "orderbook", "market": "DAI/USD", "type": "update", "data": {"time": 1618677928.0753698, "checksum": 12838118, "bids": [], "asks": [], "action": "update"}}
1618677928.1571672: {"channel": "orderbook", "market": "BRZ/USDT", "type": "update", "data": {"time": 1618677928.162347, "checksum": 2401773231, "bids": [], "asks": [], "action": "update"}}
1618677928.164416: {"channel": "orderbook", "market": "WBTC/USD", "type": "update", "data": {"time": 1618677928.1790345, "checksum": 1192440041, "bids": [], "asks": [[60753.0, 1.1348], [60794.0, 0.0]], "action": "update"}}
1618677928.19337: {"channel": "orderbook", "market": "WBTC/USD", "type": "update", "data": {"time": 1618677928.207467, "checksum": 3405806964, "bids": [[60403.0, 1.1686]], "asks": [], "action": "update"}}
1618677928.63466: {"channel": "orderbook", "market": "SOL/USDT", "type": "update", "data": {"time": 1618677928.6298134, "checksum": 2585594572, "bids": [], "asks": [], "action": "update"}}
1618677928.634699: {"channel": "orderbook", "market": "USDT/USD", "type": "update", "data": {"time": 1618677928.6375325, "checksum": 2693766571, "bids": [], "asks": [], "action": "update"}}
1618677928.634727: {"channel": "orderbook", "market": "AUD/USD", "type": "update", "data": {"time": 1618677928.645667, "checksum": 663486434, "bids": [], "asks": [], "action": "update"}}
1618677928.711085: {"channel": "orderbook", "market": "WBTC/USD", "type": "update", "data": {"time": 1618677928.7171335, "checksum": 3405806964, "bids": [], "asks": [], "action": "update"}}
1618677928.781743: {"channel": "orderbook", "market": "PAXG/USDT", "type": "update", "data": {"time": 1618677928.7779331, "checksum": 3578414220, "bids": [], "asks": [], "action": "update"}}
1618677928.851553: {"channel": "orderbook", "market": "ETH/USD", "type": "update", "data": {"time": 1618677928.860299, "checksum": 655191289, "bids": [], "asks": [], "action": "update"}}
1618677928.9210088: {"channel": "orderbook", "market": "UNI/USD", "type": "update", "data": {"time": 1618677928.928753, "checksum": 2522869048, "bids": [], "asks": [], "action": "update"}}
1618677929.091945: {"channel": "orderbook", "market": "DAI/USD", "type": "update", "data": {"time": 1618677929.1008, "checksum": 12838118, "bids": [], "asks": [], "action": "update"}}
1618677929.091979: {"channel": "orderbook", "market": "PAXG/USD", "type": "update", "data": {"time": 1618677929.1020875, "checksum": 3020203689, "bids": [], "asks": [], "action": "update"}}
1618677929.17413: {"channel": "orderbook", "market": "BRZ/USDT", "type": "update", "data": {"time": 1618677929.1875021, "checksum": 2401773231, "bids": [], "asks": [], "action": "update"}}
1618677929.643383: {"channel": "orderbook", "market": "SOL/USDT", "type": "update", "data": {"time": 1618677929.6554465, "checksum": 2585594572, "bids": [], "asks": [], "action": "update"}}
1618677929.657623: {"channel": "orderbook", "market": "USDT/USD", "type": "update", "data": {"time": 1618677929.6681058, "checksum": 2693766571, "bids": [], "asks": [], "action": "update"}}
1618677929.670868: {"channel": "orderbook", "market": "AUD/USD", "type": "update", "data": {"time": 1618677929.6774242, "checksum": 663486434, "bids": [], "asks": [], "action": "update"}}
1618677929.7475982: {"channel": "orderbook", "market": "WBTC/USD", "type": "update", "data": {"time": 1618677929.7559872, "checksum": 3405806964, "bids": [], "asks": [], "action": "update"}}
1618677929.8134441: {"channel": "orderbook", "market": "PAXG/USDT", "type": "update", "data": {"time": 1618677929.8189752, "checksum": 3578414220, "bids": [], "asks": [], "action": "update"}}
1618677929.870174: {"channel": "orderbook", "market": "ETH/USD", "type": "update", "data": {"time": 1618677929.8825312, "checksum": 655191289, "bids": [], "asks": [], "action": "update"}}
1618677929.939733: {"channel": "orderbook", "market": "UNI/USD", "type": "update", "data": {"time": 1618677929.9532032, "checksum": 2522869048, "bids": [], "asks": [], "action": "update"}}
1618677929.981042: {"channel": "orderbook", "market": "WBTC/USD", "type": "update", "data": {"time": 1618677929.994589, "checksum": 1415504779, "bids": [], "asks": [[60753.0, 0.0]], "action": "update"}}
1618677930.0416908: {"channel": "orderbook", "market": "WBTC/USD", "type": "update", "data": {"time": 1618677930.04471, "checksum": 2676993089, "bids": [], "asks": [[60806.0, 1.1518]], "action": "update"}}
1618677930.128702: {"channel": "orderbook", "market": "DAI/USD", "type": "update", "data": {"time": 1618677930.1333847, "checksum": 12838118, "bids": [], "asks": [], "action": "update"}}
1618677930.128735: {"channel": "orderbook", "market": "PAXG/USD", "type": "update", "data": {"time": 1618677930.1348135, "checksum": 3020203689, "bids": [], "asks": [], "action": "update"}}
1618677930.2016158: {"channel": "orderbook", "market": "BRZ/USDT", "type": "update", "data": {"time": 1618677930.2152205, "checksum": 2401773231, "bids": [], "asks": [], "action": "update"}}
1618677930.668488: {"channel": "orderbook", "market": "SOL/USDT", "type": "update", "data": {"time": 1618677930.6794684, "checksum": 2585594572, "bids": [], "asks": [], "action": "update"}}
1618677930.683551: {"channel": "orderbook", "market": "USDT/USD", "type": "update", "data": {"time": 1618677930.6928425, "checksum": 2693766571, "bids": [], "asks": [], "action": "update"}}
1618677930.70001: {"channel": "orderbook", "market": "AUD/USD", "type": "update", "data": {"time": 1618677930.7092328, "checksum": 663486434, "bids": [], "asks": [], "action": "update"}}
1618677930.768058: {"channel": "orderbook", "market": "WBTC/USD", "type": "update", "data": {"time": 1618677930.777393, "checksum": 2676993089, "bids": [], "asks": [], "action": "update"}}
1618677930.86556: {"channel": "orderbook", "market": "PAXG/USDT", "type": "update", "data": {"time": 1618677930.8599617, "checksum": 3578414220, "bids": [], "asks": [], "action": "update"}}
1618677930.9706051: {"channel": "orderbook", "market": "UNI/USD", "type": "update", "data": {"time": 1618677930.9810286, "checksum": 2522869048, "bids": [], "asks": [], "action": "update"}}
1618677931.1008441: {"channel": "orderbook", "market": "ETH/USD", "type": "update", "data": {"time": 1618677931.1045728, "checksum": 655191289, "bids": [], "asks": [], "action": "update"}}
1618677931.152422: {"channel": "orderbook", "market": "DAI/USD", "type": "update", "data": {"time": 1618677931.1592238, "checksum": 12838118, "bids": [], "asks": [], "action": "update"}}
1618677931.152458: {"channel": "orderbook", "market": "PAXG/USD", "type": "update", "data": {"time": 1618677931.161029, "checksum": 3020203689, "bids": [], "asks": [], "action": "update"}}
1618677931.231345: {"channel": "orderbook", "market": "BRZ/USDT", "type": "update", "data": {"time": 1618677931.2385108, "checksum": 2401773231, "bids": [], "asks": [], "action": "update"}}
1618677931.314965: {"channel": "orderbook", "market": "ETH/USD", "type": "update", "data": {"time": 1618677931.3202748, "checksum": 1488829690, "bids": [[2366.4, 81.635], [1662.1, 0.0]], "asks": [], "action": "update"}}
1618677931.558389: {"channel": "orderbook", "market": "ETH/USD", "type": "update", "data": {"time": 1618677931.5702596, "checksum": 655191289, "bids": [[2366.4, 0.0], [1662.1, 0.072]], "asks": [], "action": "update"}}
1618677931.697521: {"channel": "orderbook", "market": "SOL/USDT", "type": "update", "data": {"time": 1618677931.7061145, "checksum": 2585594572, "bids": [], "asks": [], "action": "update"}}
1618677931.706362: {"channel": "orderbook", "market": "USDT/USD", "type": "update", "data": {"time": 1618677931.7186055, "checksum": 2693766571, "bids": [], "asks": [], "action": "update"}}
1618677931.736245: {"channel": "orderbook", "market": "AUD/USD", "type": "update", "data": {"time": 1618677931.7428446, "checksum": 663486434, "bids": [], "asks": [], "action": "update"}}
1618677931.800118: {"channel": "orderbook", "market": "WBTC/USD", "type": "update", "data": {"time": 1618677931.8026793, "checksum": 2676993089, "bids": [], "asks": [], "action": "update"}}
1618677931.852614: {"channel": "orderbook", "market": "USDT/USD", "type": "update", "data": {"time": 1618677931.8619163, "checksum": 3294085768, "bids": [[0.9683, 0.0]], "asks": [], "action": "update"}}
1618677931.8884091: {"channel": "orderbook", "market": "WBTC/USD", "type": "update", "data": {"time": 1618677931.8948712, "checksum": 1415504779, "bids": [], "asks": [[60806.0, 0.0]], "action": "update"}}
1618677931.8982139: {"channel": "orderbook", "market": "PAXG/USDT", "type": "update", "data": {"time": 1618677931.9044633, "checksum": 3578414220, "bids": [], "asks": [], "action": "update"}}
1618677931.9067378: {"channel": "orderbook", "market": "WBTC/USD", "type": "update", "data": {"time": 1618677931.920045, "checksum": 2458324956, "bids": [], "asks": [[60753.0, 1.1404]], "action": "update"}}
1618677931.994604: {"channel": "orderbook", "market": "UNI/USD", "type": "update", "data": {"time": 1618677932.0012124, "checksum": 2522869048, "bids": [], "asks": [], "action": "update"}}
1618677932.1480992: {"channel": "orderbook", "market": "ETH/USD", "type": "update", "data": {"time": 1618677932.152321, "checksum": 655191289, "bids": [], "asks": [], "action": "update"}}
1618677932.151822: {"channel": "orderbook", "market": "USDT/USD", "type": "update", "data": {"time": 1618677932.1643639, "checksum": 496226710, "bids": [], "asks": [[1.0347, 0.0]], "action": "update"}}
1618677932.181619: {"channel": "orderbook", "market": "DAI/USD", "type": "update", "data": {"time": 1618677932.1910508, "checksum": 12838118, "bids": [], "asks": [], "action": "update"}}
1618677932.184702: {"channel": "orderbook", "market": "PAXG/USD", "type": "update", "data": {"time": 1618677932.192144, "checksum": 3020203689, "bids": [], "asks": [], "action": "update"}}
1618677932.260494: {"channel": "orderbook", "market": "BRZ/USDT", "type": "update", "data": {"time": 1618677932.2626426, "checksum": 2401773231, "bids": [], "asks": [], "action": "update"}}
1618677932.397633: {"channel": "orderbook", "market": "USDT/USD", "type": "update", "data": {"time": 1618677932.411174, "checksum": 3973156794, "bids": [[0.964, 0.0]], "asks": [], "action": "update"}}
1618677932.735965: {"channel": "orderbook", "market": "SOL/USDT", "type": "update", "data": {"time": 1618677932.6578252, "checksum": 3466443085, "bids": [], "asks": [[26.255, 0.0]], "action": "update"}}
1618677932.736036: {"channel": "orderbook", "market": "SOL/USDT", "type": "update", "data": {"time": 1618677932.705939, "checksum": 3912667718, "bids": [], "asks": [[26.2775, 264.8]], "action": "update"}}
1618677932.736085: {"channel": "orderbook", "market": "SOL/USDT", "type": "update", "data": {"time": 1618677932.732483, "checksum": 3912667718, "bids": [], "asks": [], "action": "update"}}
1618677932.736116: {"channel": "orderbook", "market": "USDT/USD", "type": "update", "data": {"time": 1618677932.7420716, "checksum": 3973156794, "bids": [], "asks": [], "action": "update"}}
1618677932.769525: {"channel": "orderbook", "market": "AUD/USD", "type": "update", "data": {"time": 1618677932.7752516, "checksum": 663486434, "bids": [], "asks": [], "action": "update"}}
1618677932.775902: {"channel": "orderbook", "market": "USDT/USD", "type": "update", "data": {"time": 1618677932.7863808, "checksum": 3514288454, "bids": [], "asks": [[1.0394, 0.0]], "action": "update"}}
1618677932.82671: {"channel": "orderbook", "market": "WBTC/USD", "type": "update", "data": {"time": 1618677932.8327627, "checksum": 2458324956, "bids": [], "asks": [], "action": "update"}}
1618677932.93587: {"channel": "orderbook", "market": "PAXG/USDT", "type": "update", "data": {"time": 1618677932.9396963, "checksum": 3578414220, "bids": [], "asks": [], "action": "update"}}
1618677932.952662: {"channel": "orderbook", "market": "PAXG/USD", "type": "update", "data": {"time": 1618677932.9606845, "checksum": 620885589, "bids": [], "asks": [[1818.9, 4.7973]], "action": "update"}}
1618677933.02225: {"channel": "orderbook", "market": "PAXG/USD", "type": "update", "data": {"time": 1618677933.032419, "checksum": 1427873551, "bids": [], "asks": [[1808.2, 1.7198]], "action": "update"}}
1618677933.022326: {"channel": "orderbook", "market": "UNI/USD", "type": "update", "data": {"time": 1618677933.0304258, "checksum": 2522869048, "bids": [], "asks": [], "action": "update"}}
1618677933.0792608: {"channel": "orderbook", "market": "USDT/USD", "type": "update", "data": {"time": 1618677933.0874555, "checksum": 4159702115, "bids": [[0.9597, 0.0]], "asks": [], "action": "update"}}
1618677933.201584: {"channel": "orderbook", "market": "ETH/USD", "type": "update", "data": {"time": 1618677933.2063582, "checksum": 655191289, "bids": [], "asks": [], "action": "update"}}
1618677933.219296: {"channel": "orderbook", "market": "PAXG/USD", "type": "update", "data": {"time": 1618677933.2161758, "checksum": 1427873551, "bids": [], "asks": [], "action": "update"}}
1618677933.219328: {"channel": "orderbook", "market": "DAI/USD", "type": "update", "data": {"time": 1618677933.2175183, "checksum": 12838118, "bids": [], "asks": [], "action": "update"}}
1618677933.281145: {"channel": "orderbook", "market": "BRZ/USDT", "type": "update", "data": {"time": 1618677933.2901113, "checksum": 2401773231, "bids": [], "asks": [], "action": "update"}}
1618677933.372533: {"channel": "orderbook", "market": "USDT/USD", "type": "update", "data": {"time": 1618677933.386651, "checksum": 958656527, "bids": [], "asks": [[1.044, 0.0]], "action": "update"}}
1618677933.757596: {"channel": "orderbook", "market": "SOL/USDT", "type": "update", "data": {"time": 1618677933.757317, "checksum": 3912667718, "bids": [], "asks": [], "action": "update"}}
1618677933.757628: {"channel": "orderbook", "market": "USDT/USD", "type": "update", "data": {"time": 1618677933.7661884, "checksum": 958656527, "bids": [], "asks": [], "action": "update"}}
1618677933.7960992: {"channel": "orderbook", "market": "AUD/USD", "type": "update", "data": {"time": 1618677933.8032336, "checksum": 663486434, "bids": [], "asks": [], "action": "update"}}
1618677933.8586009: {"channel": "orderbook", "market": "WBTC/USD", "type": "update", "data": {"time": 1618677933.8631535, "checksum": 2458324956, "bids": [], "asks": [], "action": "update"}}
1618677933.977851: {"channel": "orderbook", "market": "PAXG/USDT", "type": "update", "data": {"time": 1618677933.9835525, "checksum": 3578414220, "bids": [], "asks": [], "action": "update"}}
1618677934.043144: {"channel": "orderbook", "market": "UNI/USD", "type": "update", "data": {"time": 1618677934.0543337, "checksum": 2522869048, "bids": [], "asks": [], "action": "update"}}
1618677934.244271: {"channel": "orderbook", "market": "DAI/USD", "type": "update", "data": {"time": 1618677934.2500756, "checksum": 12838118, "bids": [], "asks": [], "action": "update"}}
1618677934.24436: {"channel": "orderbook", "market": "PAXG/USD", "type": "update", "data": {"time": 1618677934.2526307, "checksum": 1427873551, "bids": [], "asks": [], "action": "update"}}
1618677934.259605: {"channel": "orderbook", "market": "ETH/USD", "type": "update", "data": {"time": 1618677934.260249, "checksum": 655191289, "bids": [], "asks": [], "action": "update"}}
1618677934.297337: {"channel": "orderbook", "market": "WBTC/USD", "type": "update", "data": {"time": 1618677934.3074236, "checksum": 1316049738, "bids": [[60454.0, 0.0]], "asks": [], "action": "update"}}
1618677934.298074: {"channel": "orderbook", "market": "BRZ/USDT", "type": "update", "data": {"time": 1618677934.31275, "checksum": 2401773231, "bids": [], "asks": [], "action": "update"}}
1618677934.6219351: {"channel": "orderbook", "market": "WBTC/USD", "type": "update", "data": {"time": 1618677934.6312673, "checksum": 4183353298, "bids": [[60440.0, 12.6207]], "asks": [], "action": "update"}}
1618677934.631901: {"channel": "orderbook", "market": "ETH/USD", "type": "update", "data": {"time": 1618677934.642745, "checksum": 636712704, "bids": [[2360.2, 0.0], [1630.6, 0.072]], "asks": [], "action": "update"}}
1618677934.67518: {"channel": "orderbook", "market": "ETH/USD", "type": "update", "data": {"time": 1618677934.6850414, "checksum": 2795574158, "bids": [[2363.6, 164.959]], "asks": [], "action": "update"}}
1618677934.775923: {"channel": "orderbook", "market": "SOL/USDT", "type": "update", "data": {"time": 1618677934.7812998, "checksum": 3912667718, "bids": [], "asks": [], "action": "update"}}
1618677934.7837949: {"channel": "orderbook", "market": "USDT/USD", "type": "update", "data": {"time": 1618677934.793783, "checksum": 958656527, "bids": [], "asks": [], "action": "update"}}
1618677934.832258: {"channel": "orderbook", "market": "AUD/USD", "type": "update", "data": {"time": 1618677934.8391874, "checksum": 663486434, "bids": [], "asks": [], "action": "update"}}
1618677934.880191: {"channel": "orderbook", "market": "WBTC/USD", "type": "update", "data": {"time": 1618677934.8881097, "checksum": 4183353298, "bids": [], "asks": [], "action": "update"}}
1618677935.029716: {"channel": "orderbook", "market": "PAXG/USDT", "type": "update", "data": {"time": 1618677935.0269907, "checksum": 3578414220, "bids": [], "asks": [], "action": "update"}}
1618677935.070109: {"channel": "orderbook", "market": "UNI/USD", "type": "update", "data": {"time": 1618677935.0775247, "checksum": 2522869048, "bids": [], "asks": [], "action": "update"}}
1618677935.075689: {"channel": "orderbook", "market": "USDT/USD", "type": "update", "data": {"time": 1618677935.087219, "checksum": 904328419, "bids": [[0.964, 9025.0]], "asks": [], "action": "update"}}
1618677935.157226: {"channel": "orderbook", "market": "USDT/USD", "type": "update", "data": {"time": 1618677935.1615858, "checksum": 150647490, "bids": [[0.9683, 7609.89]], "asks": [[1.0347, 8081.15]], "action": "update"}}
1618677935.2854002: {"channel": "orderbook", "market": "DAI/USD", "type": "update", "data": {"time": 1618677935.2868035, "checksum": 12838118, "bids": [], "asks": [], "action": "update"}}
1618677935.285485: {"channel": "orderbook", "market": "PAXG/USD", "type": "update", "data": {"time": 1618677935.2886631, "checksum": 1427873551, "bids": [], "asks": [], "action": "update"}}
1618677935.300286: {"channel": "orderbook", "market": "ETH/USD", "type": "update", "data": {"time": 1618677935.303827, "checksum": 2795574158, "bids": [], "asks": [], "action": "update"}}
1618677935.326268: {"channel": "orderbook", "market": "BRZ/USDT", "type": "update", "data": {"time": 1618677935.3384717, "checksum": 2401773231, "bids": [], "asks": [], "action": "update"}}
1618677935.795548: {"channel": "orderbook", "market": "SOL/USDT", "type": "update", "data": {"time": 1618677935.8053613, "checksum": 3912667718, "bids": [], "asks": [], "action": "update"}}
1618677935.805913: {"channel": "orderbook", "market": "USDT/USD", "type": "update", "data": {"time": 1618677935.816888, "checksum": 150647490, "bids": [], "asks": [], "action": "update"}}
1618677935.858609: {"channel": "orderbook", "market": "AUD/USD", "type": "update", "data": {"time": 1618677935.8682985, "checksum": 663486434, "bids": [], "asks": [], "action": "update"}}
1618677935.9083462: {"channel": "orderbook", "market": "WBTC/USD", "type": "update", "data": {"time": 1618677935.9160779, "checksum": 4183353298, "bids": [], "asks": [], "action": "update"}}
1618677936.064058: {"channel": "orderbook", "market": "PAXG/USDT", "type": "update", "data": {"time": 1618677936.061067, "checksum": 3578414220, "bids": [], "asks": [], "action": "update"}}
1618677936.0966258: {"channel": "orderbook", "market": "UNI/USD", "type": "update", "data": {"time": 1618677936.0985897, "checksum": 2522869048, "bids": [], "asks": [], "action": "update"}}
1618677936.282779: {"channel": "orderbook", "market": "PAXG/USD", "type": "update", "data": {"time": 1618677936.2817378, "checksum": 4129445060, "bids": [], "asks": [[1826.9, 2.2927]], "action": "update"}}
1618677936.323081: {"channel": "orderbook", "market": "DAI/USD", "type": "update", "data": {"time": 1618677936.3198738, "checksum": 12838118, "bids": [], "asks": [], "action": "update"}}
1618677936.323166: {"channel": "orderbook", "market": "PAXG/USD", "type": "update", "data": {"time": 1618677936.3218653, "checksum": 3905703799, "bids": [], "asks": [[1898.5, 0.0]], "action": "update"}}
1618677936.339562: {"channel": "orderbook", "market": "ETH/USD", "type": "update", "data": {"time": 1618677936.3396063, "checksum": 2795574158, "bids": [], "asks": [], "action": "update"}}
1618677936.358378: {"channel": "orderbook", "market": "BRZ/USDT", "type": "update", "data": {"time": 1618677936.3681777, "checksum": 2401773231, "bids": [], "asks": [], "action": "update"}}
1618677936.820081: {"channel": "orderbook", "market": "SOL/USDT", "type": "update", "data": {"time": 1618677936.8304317, "checksum": 3912667718, "bids": [], "asks": [], "action": "update"}}
1618677936.8332028: {"channel": "orderbook", "market": "USDT/USD", "type": "update", "data": {"time": 1618677936.8405604, "checksum": 150647490, "bids": [], "asks": [], "action": "update"}}
1618677936.899866: {"channel": "orderbook", "market": "AUD/USD", "type": "update", "data": {"time": 1618677936.8980408, "checksum": 663486434, "bids": [], "asks": [], "action": "update"}}
1618677936.943758: {"channel": "orderbook", "market": "WBTC/USD", "type": "update", "data": {"time": 1618677936.9499724, "checksum": 4183353298, "bids": [], "asks": [], "action": "update"}}
1618677937.096725: {"channel": "orderbook", "market": "PAXG/USDT", "type": "update", "data": {"time": 1618677937.103095, "checksum": 3578414220, "bids": [], "asks": [], "action": "update"}}
1618677937.119693: {"channel": "orderbook", "market": "UNI/USD", "type": "update", "data": {"time": 1618677937.1298704, "checksum": 2522869048, "bids": [], "asks": [], "action": "update"}}
1618677937.353605: {"channel": "orderbook", "market": "DAI/USD", "type": "update", "data": {"time": 1618677937.3584332, "checksum": 12838118, "bids": [], "asks": [], "action": "update"}}
1618677937.353643: {"channel": "orderbook", "market": "PAXG/USD", "type": "update", "data": {"time": 1618677937.3603587, "checksum": 3905703799, "bids": [], "asks": [], "action": "update"}}
1618677937.3716311: {"channel": "orderbook", "market": "ETH/USD", "type": "update", "data": {"time": 1618677937.3739839, "checksum": 2795574158, "bids": [], "asks": [], "action": "update"}}
1618677937.37984: {"channel": "orderbook", "market": "BRZ/USDT", "type": "update", "data": {"time": 1618677937.388375, "checksum": 2401773231, "bids": [], "asks": [], "action": "update"}}
1618677937.751893: {"channel": "orderbook", "market": "WBTC/USD", "type": "update", "data": {"time": 1618677937.6563954, "checksum": 2113039630, "bids": [[60440.0, 13.2031], [60403.0, 0.0]], "asks": [], "action": "update"}}
1618677937.781224: {"channel": "orderbook", "market": "USDT/USD", "type": "update", "data": {"time": 1618677937.7854183, "checksum": 3155350088, "bids": [], "asks": [[1.0394, 8505.5]], "action": "update"}}
1618677937.8539: {"channel": "orderbook", "market": "SOL/USDT", "type": "update", "data": {"time": 1618677937.8545005, "checksum": 3912667718, "bids": [], "asks": [], "action": "update"}}
1618677937.8585029: {"channel": "orderbook", "market": "USDT/USD", "type": "update", "data": {"time": 1618677937.8603475, "checksum": 1597738800, "bids": [[0.9597, 8692.1]], "asks": [[1.044, 8199.18]], "action": "update"}}
1618677937.943187: {"channel": "orderbook", "market": "AUD/USD", "type": "update", "data": {"time": 1618677937.951957, "checksum": 663486434, "bids": [], "asks": [], "action": "update"}}
1618677937.9805472: {"channel": "orderbook", "market": "WBTC/USD", "type": "update", "data": {"time": 1618677937.9878225, "checksum": 2113039630, "bids": [], "asks": [], "action": "update"}}
1618677938.139262: {"channel": "orderbook", "market": "PAXG/USDT", "type": "update", "data": {"time": 1618677938.1496909, "checksum": 3578414220, "bids": [], "asks": [], "action": "update"}}
1618677938.1592672: {"channel": "orderbook", "market": "UNI/USD", "type": "update", "data": {"time": 1618677938.1629138, "checksum": 2522869048, "bids": [], "asks": [], "action": "update"}}
1618677938.469741: {"channel": "orderbook", "market": "DAI/USD", "type": "update", "data": {"time": 1618677938.3936267, "checksum": 12838118, "bids": [], "asks": [], "action": "update"}}
1618677938.4698: {"channel": "orderbook", "market": "PAXG/USD", "type": "update", "data": {"time": 1618677938.4024022, "checksum": 3905703799, "bids": [], "asks": [], "action": "update"}}
1618677938.469841: {"channel": "orderbook", "market": "BRZ/USDT", "type": "update", "data": {"time": 1618677938.4133768, "checksum": 2401773231, "bids": [], "asks": [], "action": "update"}}
1618677938.4698792: {"channel": "orderbook", "market": "ETH/USD", "type": "update", "data": {"time": 1618677938.4204006, "checksum": 2795574158, "bids": [], "asks": [], "action": "update"}}
1618677938.981809: {"channel": "orderbook", "market": "WBTC/USD", "type": "update", "data": {"time": 1618677938.8060567, "checksum": 2712434787, "bids": [], "asks": [[60753.0, 0.0]], "action": "update"}}
1618677938.981861: {"channel": "orderbook", "market": "SOL/USDT", "type": "update", "data": {"time": 1618677938.8803518, "checksum": 3912667718, "bids": [], "asks": [], "action": "update"}}
1618677938.981885: {"channel": "orderbook", "market": "USDT/USD", "type": "update", "data": {"time": 1618677938.8812623, "checksum": 1597738800, "bids": [], "asks": [], "action": "update"}}
1618677938.985651: {"channel": "orderbook", "market": "AUD/USD", "type": "update", "data": {"time": 1618677938.9817739, "checksum": 663486434, "bids": [], "asks": [], "action": "update"}}
1618677939.005569: {"channel": "orderbook", "market": "WBTC/USD", "type": "update", "data": {"time": 1618677939.0142083, "checksum": 2712434787, "bids": [], "asks": [], "action": "update"}}
1618677939.019637: {"channel": "orderbook", "market": "WBTC/USD", "type": "update", "data": {"time": 1618677939.0299156, "checksum": 993279552, "bids": [], "asks": [[60804.0, 1.1759]], "action": "update"}}
1618677939.187551: {"channel": "orderbook", "market": "UNI/USD", "type": "update", "data": {"time": 1618677939.1843865, "checksum": 2522869048, "bids": [], "asks": [], "action": "update"}}
1618677939.187583: {"channel": "orderbook", "market": "PAXG/USDT", "type": "update", "data": {"time": 1618677939.183901, "checksum": 3578414220, "bids": [], "asks": [], "action": "update"}}
1618677939.493827: {"channel": "orderbook", "market": "DAI/USD", "type": "update", "data": {"time": 1618677939.426022, "checksum": 12838118, "bids": [], "asks": [], "action": "update"}}
1618677939.49386: {"channel": "orderbook", "market": "WBTC/USD", "type": "update", "data": {"time": 1618677939.429165, "checksum": 2066531641, "bids": [], "asks": [[60807.0, 1.1992]], "action": "update"}}
1618677939.493902: {"channel": "orderbook", "market": "PAXG/USD", "type": "update", "data": {"time": 1618677939.4274814, "checksum": 3905703799, "bids": [], "asks": [], "action": "update"}}
1618677939.4939241: {"channel": "orderbook", "market": "BRZ/USDT", "type": "update", "data": {"time": 1618677939.4399776, "checksum": 2401773231, "bids": [], "asks": [], "action": "update"}}
1618677939.4939451: {"channel": "orderbook", "market": "ETH/USD", "type": "update", "data": {"time": 1618677939.4625568, "checksum": 2795574158, "bids": [], "asks": [], "action": "update"}}
1618677939.616259: {"channel": "orderbook", "market": "WBTC/USD", "type": "update", "data": {"time": 1618677939.62874, "checksum": 2604359904, "bids": [], "asks": [[60804.0, 0.0]], "action": "update"}}
1618677939.6470132: {"channel": "orderbook", "market": "UNI/USD", "type": "update", "data": {"time": 1618677939.6582224, "checksum": 497832246, "bids": [[35.393, 0.0]], "asks": [], "action": "update"}}
1618677939.89634: {"channel": "orderbook", "market": "SOL/USDT", "type": "update", "data": {"time": 1618677939.9069622, "checksum": 3912667718, "bids": [], "asks": [], "action": "update"}}
1618677939.896373: {"channel": "orderbook", "market": "USDT/USD", "type": "update", "data": {"time": 1618677939.9075773, "checksum": 1597738800, "bids": [], "asks": [], "action": "update"}}
1618677940.011463: {"channel": "orderbook", "market": "AUD/USD", "type": "update", "data": {"time": 1618677940.0202389, "checksum": 663486434, "bids": [], "asks": [], "action": "update"}}
1618677940.030037: {"channel": "orderbook", "market": "WBTC/USD", "type": "update", "data": {"time": 1618677940.0367415, "checksum": 2604359904, "bids": [], "asks": [], "action": "update"}}
1618677940.210315: {"channel": "orderbook", "market": "UNI/USD", "type": "update", "data": {"time": 1618677940.2117796, "checksum": 1626188497, "bids": [[35.147, 0.0]], "asks": [], "action": "update"}}
1618677940.2139251: {"channel": "orderbook", "market": "PAXG/USDT", "type": "update", "data": {"time": 1618677940.2166567, "checksum": 3578414220, "bids": [], "asks": [], "action": "update"}}
1618677940.245847: {"channel": "orderbook", "market": "UNI/USD", "type": "update", "data": {"time": 1618677940.2559881, "checksum": 3264267844, "bids": [[35.186, 1724.4]], "asks": [], "action": "update"}}
1618677940.445815: {"channel": "orderbook", "market": "DAI/USD", "type": "update", "data": {"time": 1618677940.4550493, "checksum": 12838118, "bids": [], "asks": [], "action": "update"}}
1618677940.449677: {"channel": "orderbook", "market": "PAXG/USD", "type": "update", "data": {"time": 1618677940.4579077, "checksum": 3905703799, "bids": [], "asks": [], "action": "update"}}
1618677940.451113: {"channel": "orderbook", "market": "BRZ/USDT", "type": "update", "data": {"time": 1618677940.4638112, "checksum": 2401773231, "bids": [], "asks": [], "action": "update"}}
1618677940.4955509: {"channel": "orderbook", "market": "ETH/USD", "type": "update", "data": {"time": 1618677940.5016208, "checksum": 2795574158, "bids": [], "asks": [], "action": "update"}}
1618677941.028878: {"channel": "orderbook", "market": "USDT/USD", "type": "update", "data": {"time": 1618677940.931931, "checksum": 1597738800, "bids": [], "asks": [], "action": "update"}}
1618677941.028911: {"channel": "orderbook", "market": "SOL/USDT", "type": "update", "data": {"time": 1618677940.9330359, "checksum": 3912667718, "bids": [], "asks": [], "action": "update"}}
1618677941.0485928: {"channel": "orderbook", "market": "AUD/USD", "type": "update", "data": {"time": 1618677941.0523365, "checksum": 663486434, "bids": [], "asks": [], "action": "update"}}
1618677941.061734: {"channel": "orderbook", "market": "WBTC/USD", "type": "update", "data": {"time": 1618677941.0686958, "checksum": 2604359904, "bids": [], "asks": [], "action": "update"}}
1618677941.226858: {"channel": "orderbook", "market": "UNI/USD", "type": "update", "data": {"time": 1618677941.2346144, "checksum": 3264267844, "bids": [], "asks": [], "action": "update"}}
1618677941.3879209: {"channel": "orderbook", "market": "PAXG/USDT", "type": "update", "data": {"time": 1618677941.3926914, "checksum": 3578414220, "bids": [], "asks": [], "action": "update"}}
1618677941.3976781: {"channel": "orderbook", "market": "ETH/USD", "type": "update", "data": {"time": 1618677941.403432, "checksum": 2633000713, "bids": [[2174.0, 0.0], [1625.8, 0.022]], "asks": [], "action": "update"}}
1618677941.552365: {"channel": "orderbook", "market": "BRZ/USDT", "type": "update", "data": {"time": 1618677941.487988, "checksum": 2401773231, "bids": [], "asks": [], "action": "update"}}
1618677941.5523999: {"channel": "orderbook", "market": "DAI/USD", "type": "update", "data": {"time": 1618677941.4955847, "checksum": 12838118, "bids": [], "asks": [], "action": "update"}}
1618677941.5524218: {"channel": "orderbook", "market": "PAXG/USD", "type": "update", "data": {"time": 1618677941.4970884, "checksum": 3905703799, "bids": [], "asks": [], "action": "update"}}
1618677941.552442: {"channel": "orderbook", "market": "ETH/USD", "type": "update", "data": {"time": 1618677941.5394588, "checksum": 2633000713, "bids": [], "asks": [], "action": "update"}}
1618677941.7022982: {"channel": "orderbook", "market": "WBTC/USD", "type": "update", "data": {"time": 1618677941.706268, "checksum": 532508403, "bids": [[60460.0, 9.4989]], "asks": [], "action": "update"}}
1618677942.0523741: {"channel": "orderbook", "market": "SOL/USDT", "type": "update", "data": {"time": 1618677941.956028, "checksum": 3912667718, "bids": [], "asks": [], "action": "update"}}
1618677942.052408: {"channel": "orderbook", "market": "USDT/USD", "type": "update", "data": {"time": 1618677941.9697723, "checksum": 1597738800, "bids": [], "asks": [], "action": "update"}}
1618677942.073282: {"channel": "orderbook", "market": "AUD/USD", "type": "update", "data": {"time": 1618677942.081869, "checksum": 663486434, "bids": [], "asks": [], "action": "update"}}
1618677942.0903208: {"channel": "orderbook", "market": "WBTC/USD", "type": "update", "data": {"time": 1618677942.0976026, "checksum": 532508403, "bids": [], "asks": [], "action": "update"}}
