1618678295.595392: {"method": "depth.update", "params": [true, {"asks": [["0.0003805", "660.045"], ["0.0003807", "1035.866"], ["0.0003915", "560.432"], ["0.0004477", "469.743"], ["0.0004669", "654.989"], ["0.0004675", "766.932"], ["0.0004682", "478.728"], ["0.0004691", "849.265"], ["0.0004697", "491.87"], ["0.0004698", "460.616"], ["0.0004703", "687.819"], ["0.0004711", "816.012"], ["0.0004715", "442.25"], ["0.0007171", "424.74"], ["0.0008923", "249.684"], ["0.0009102", "266.416"], ["0.0009285", "250.562"], ["0.0009471", "352.529"], ["0.0009661", "324.171"], ["0.0009855", "402.924"]], "bids": [["0.0003555", "1205.252"], ["0.0003554", "691.468"], ["0.000351", "25.26113016"], ["0.0003501", "987.085"], ["0.000343", "1015.422"], ["0.000342", "951.094"], ["0.0003413", "1084.446"], ["0.0003412", "905.915"], ["0.0003411", "917.541"], ["0.0003404", "1150.952"], ["0.0003403", "1109.99"], ["0.0003401", "1161.939"], ["0.000339", "1173.783"], ["0.0003389", "832.411"], ["0.0003386", "948.495"], ["0.0003318", "1056.57"], ["0.0003317", "653.056"], ["0.0003248", "1210.424"], ["0.0003183", "871.093"], ["0.0003119", "902.991"], ["0.0003056", "833.488"], ["0.0002994", "1236.96"], ["0.0002934", "1110.889"], ["0.0001053", "94.966"], ["0.0000532", "187.969"], ["0.0000321", "311.526"], ["0.000021", "476.19"], ["0.0000106", "943.396"], ["0.0000063", "1587.301"], ["0.0000032", "3125"]], "id": 910753}, "VELO_ETH"], "id": null}
1618678295.600451: {"method": "depth.update", "params": [true, {"asks": [["0.00007822", "42.76790458"], ["0.00007823", "3152.93"], ["0.00007976", "2525.528"], ["0.00007983", "4644.353"], ["0.00007984", "2715.566"], ["0.00008043", "4707.613"], ["0.00008204", "4769.925"], ["0.00008369", "3981.558"], ["0.00008537", "4134.552"], ["0.00008708", "4184.577"], ["0.00008883", "2782.812"], ["0.00009061", "4167.38"], ["0.00009117", "2459.993"], ["0.00009243", "3955.211"], ["0.00009428", "3309.195"], ["0.00009617", "3953.317"], ["0.0000981", "3247.243"], ["0.00010007", "2765.44"], ["0.00010208", "3085.264"], ["0.00010413", "3601.708"], ["0.00010622", "3099.249"], ["0.00010835", "3071.235"], ["0.000125", "36.99067"], ["0.00019345", "2459.993"], ["0.0002", "998"], ["0.000249", "180"], ["0.00025", "1376.222"], ["0.00028", "97"], ["0.00029", "97"], ["0.0003", "97"]], "bids": [["0.0000742", "685.185"], ["0.00007318", "76.0207"], ["0.00007316", "328"], ["0.00007265", "3839.552"], ["0.00007259", "3684.39"], ["0.00007257", "3385.728"], ["0.00007253", "5465.83"], ["0.00007143", "3681.063"], ["0.00007108", "4567.975"], ["0.00007105", "2869.477"], ["0.00007096", "3741.758"], ["0.00007091", "4991.755"], ["0.00007003", "3141.299"], ["0.00006999", "4881.591"], ["0.00006996", "5567.196"], ["0.00006989", "4347.102"], ["0.00006987", "3470.092"], ["0.00006985", "5192.784"], ["0.00006981", "3666.234"], ["0.00006975", "5701.393"], ["0.00006969", "3813.088"], ["0.00006964", "3457.864"], ["0.00006899", "43.478"], ["0.00000511", "1956.947"], ["0.0000051", "43137.254"], ["0.00000301", "3322.259"], ["0.000003", "300"], ["0.00000201", "4975.124"], ["0.000002", "1800"], ["0.00000105", "9523.809"]], "id": 7237068}, "REQ_ETH"], "id": null}
1618678295.600767: {"method": "depth.update", "params": [true, {"asks": [["0.00000245", "1352.28"], ["0.000002454", "1020.1349"], ["0.000002468", "7509.59"], ["0.000002469", "5123.67"], ["0.000002471", "4450.99"], ["0.000002474", "5039.16"], ["0.000002477", "5578.76"], ["0.000002484", "746.86"], ["0.000002526", "6197.76"], ["0.000002577", "4152.1"], ["0.000002628", "4348.26"], ["0.000002629", "6422.72"], ["0.00000263", "6280.13"], ["0.000002633", "4850.19"], ["0.000002635", "4333.18"], ["0.000002636", "6858.09"], ["0.000002638", "5484.1"], ["0.000002643", "5859"], ["0.000002646", "6123.81"], ["0.00000268", "273.52377388"], ["0.000002699", "6968.53"], ["0.0000027", "6331.59"], ["0.000002754", "5150.21"], ["0.000002809", "145.14"], ["0.00000281", "6139.6"], ["0.00000399", "94.8"], ["0.000004", "248.502"], ["0.0000041", "50"], ["0.0000042", "374.06"], ["0.0000043", "50"]], "bids": [["0.00000238", "1666.66"], ["0.000002373", "381.77"], ["0.000002372", "16800"], ["0.000002309", "6961.86"], ["0.00000227", "1000"], ["0.000002262", "6050.37"], ["0.000002261", "8142.25"], ["0.00000226", "6120.87"], ["0.000002254", "4487.23"], ["0.000002248", "5485.2"], ["0.000002247", "8669.41"], ["0.00000224", "5071.49"], ["0.000002239", "7605.99"], ["0.000002237", "5469.7"], ["0.000002236", "7947.42"], ["0.000002235", "8026.27"], ["0.000002234", "4643.6"], ["0.000002189", "6092.54"], ["0.000002145", "6065.55"], ["0.00000211", "113.63636363"], ["0.000002102", "6557.85"], ["0.000002059", "5445.26"], ["0.000002017", "9204.13"], ["0.000001982", "151.36"], ["0.000001976", "6109.01"], ["0.000001936", "7029.1"], ["0.000001649", "30321.4"], ["0.00000095", "1000"], ["0.0000009", "1000"], ["0.00000085", "1000"]], "id": 27309478}, "BTS_BTC"], "id": null}
1618678295.60104: {"method": "depth.update", "params": [true, {"asks": [["0.000068", "46156.2880119575"], ["0.00006863", "6412.67"], ["0.00006874", "142468.9488065"], ["0.00007033", "4958.7"], ["0.00007034", "5280.74"], ["0.0000704", "4768.77"], ["0.00007043", "5246"], ["0.00007044", "5443.54"], ["0.00007048", "4460.4"], ["0.00007049", "4217.61"], ["0.00007055", "2920.09"], ["0.00007058", "4187.04"], ["0.00007059", "4095.31"], ["0.00007061", "5388.34"], ["0.00007063", "3972.71"], ["0.00007065", "7648.85"], ["0.00007066", "3051.3"], ["0.00007067", "3934.54"], ["0.00007069", "4801.32"], ["0.00007071", "2976.21"], ["0.00007077", "3300.15"], ["0.0000708", "3927.65"], ["0.00007222", "4997.49"], ["0.00007588", "2495"], ["0.00007933", "5353.1"], ["0.00008261", "838.59"], ["0.00008584", "2000"], ["0.00008784", "2000"], ["0.00009284", "2014.17"], ["0.0000959", "19987.33"]], "bids": [["0.0000673", "2898.03554"], ["0.00006724", "12983.77"], ["0.00006712", "73689.14427113"], ["0.00006701", "2895.22053113"], ["0.00006689", "2903.85371543"], ["0.00006665", "92000.2376571"], ["0.00006609", "3811.30793123"], ["0.00006564", "7065.40199733"], ["0.0000653", "4959.43"], ["0.00006525", "3277.75"], ["0.00006522", "4596.04"], ["0.00006517", "4982.49"], ["0.00006511", "3482.69"], ["0.00006505", "6037.58"], ["0.00006501", "5986.23"], ["0.00006487", "3959.16"], ["0.00006467", "3573.34"], ["0.00006464", "4808.79"], ["0.0000646", "5638.79"], ["0.00006456", "4165.22"], ["0.00006454", "5730.74"], ["0.00006404", "196.24"], ["0.00006324", "5314.49"], ["0.00006281", "76.45"], ["0.000062", "7091.29"], ["0.00006197", "3851.06"], ["0.00006073", "3912.52"], ["0.00005951", "6447.53"], ["0.00005831", "5497.92"], ["0.00005714", "6884.88"]], "id": 17758341}, "TRX_ETH"], "id": null}
1618678295.6012979: {"method": "depth.update", "params": [true, {"asks": [["0.18794", "483.172"], ["0.18795", "671.954"], ["0.18878", "36358.142"], ["0.18885", "671.954"], ["0.18916", "28307.525"], ["0.18954", "22001.485"], ["0.18966", "284.3484877"], ["0.18967", "23532.974"], ["0.18975", "671.954"], ["0.19005", "30906.983"], ["0.19011", "22010.622"], ["0.19016", "27733.946"], ["0.1905", "2427.134"], ["0.19055", "27862.635"], ["0.19065", "671.954"], ["0.19067", "28308.92"], ["0.19106", "35131.03"], ["0.19155", "671.954"], ["0.19191", "45.25"], ["0.19245", "671.954"], ["0.19335", "67907.986254"], ["0.19425", "671.954"], ["0.19515", "671.954"], ["0.19581", "177.808"], ["0.19605", "671.954"], ["0.19695", "671.954"], ["0.19785", "671.954"], ["0.19876", "671.954"], ["0.19878", "177.808"], ["0.19966", "671.954"]], "bids": [["0.18705", "130.046"], ["0.18614", "671.954"], ["0.18609", "36.1896045"], ["0.18608", "31221.205"], ["0.1857", "35605.897"], ["0.18532", "27003.712"], ["0.18524", "671.954"], ["0.18523", "35197.808"], ["0.185", "502.703"], ["0.18485", "27497.882"], ["0.18448", "40796.918"], ["0.18434", "671.954"], ["0.18425", "26324.066"], ["0.184", "100"], ["0.18388", "36126.218"], ["0.18355", "8553.217"], ["0.18351", "22069.194"], ["0.18348", "1295.988"], ["0.18344", "671.954"], ["0.18314", "29766.337"], ["0.1831", "109.229"], ["0.18254", "671.954"], ["0.18181", "200"], ["0.18164", "671.954"], ["0.18074", "671.954"], ["0.17984", "671.954"], ["0.17894", "671.954"], ["0.17804", "671.954"], ["0.178", "1974.864"], ["0.17786", "1549.39"]], "id": 3125225}, "RING_USDT"], "id": null}
1618678295.6015549: {"method": "depth.update", "params": [true, {"asks": [["1.9743", "441.59"], ["1.9776", "525.851"], ["1.9783", "292.364"], ["1.98", "191.981"], ["1.989", "552.232"], ["2.0324", "631.683"], ["2.0457", "261.317128"], ["2.0458", "347.957"], ["2.0558", "387.241"], ["2.0784", "1683.562"], ["2.117", "208.186"], ["2.1226", "390.2"], ["2.1344", "1342.122"], ["2.1368", "636.98"], ["2.1465", "780.726"], ["2.1729", "1029.57"], ["2.1756", "421.611"], ["2.176", "146.426"], ["2.1873", "490.653"], ["2.2198", "932.873"], ["2.2416", "671.078"], ["2.2523", "226.698"], ["2.291", "311.349"], ["2.3046", "1787.298"], ["2.3379", "347.245"], ["2.3558", "533.058"], ["2.3686", "373.53"], ["2.3801", "204.001"], ["2.3862", "270.586"], ["2.3972", "439.788"]], "bids": [["1.9082", "457.765"], ["1.9049", "525.838"], ["1.8712", "545.628"], ["1.8552", "594.646"], ["1.8547", "739.146"], ["1.8438", "496.621"], ["1.8381", "692.024"], ["1.8367", "825.694"], ["1.8318", "531.779"], ["1.82", "932.932"], ["1.8192", "355.246"], ["1.7882", "5.592"], ["1.7717", "643.388"], ["1.7662", "1696.988"], ["1.7425", "1114.722"], ["1.68", "1000"], ["1.6791", "456.114"], ["1.661", "637.632"], ["1.6565", "487.013"], ["1.6556", "675.511"], ["1.6419", "513.493"], ["1.6362", "749.739"], ["1.6228", "950.714"], ["1.6177", "1839.571"], ["1.5877", "535.21"], ["1.5603", "898.911"], ["1.5562", "319.292"], ["1.5515", "546.431"], ["1.5416", "573.919"], ["1.5396", "451.215"]], "id": 73649656}, "AVAX3L_USDT"], "id": null}
1618678295.601803: {"method": "depth.update", "params": [false, {"bids": [["0.00007318", "0"], ["0.00000065", "15384.615"]]}, "REQ_ETH"], "id": null}
1618678295.6018329: {"method": "depth.update", "params": [true, {"asks": [["0.5923", "0.008"], ["0.5961", "2.918"], ["0.5966", "8.04"], ["0.6009", "8.04"], ["0.6017", "2.918"], ["0.6053", "8.04"], ["0.6073", "2.918"], ["0.6075", "22.85"], ["0.6096", "0.001"], ["0.6129", "2.918"], ["0.6139", "8.04"], ["0.615", "22.85"], ["0.6161", "720.3217"], ["0.6166", "4.142"], ["0.6183", "8.04"], ["0.6186", "2.918"], ["0.62", "63.420637"], ["0.6225", "9.615545635"], ["0.6226", "8.04"], ["0.6231", "6.345"], ["0.6239", "4.142"], ["0.6244", "2.918"], ["0.6269", "8.04"], ["0.63", "22.85"], ["0.6302", "2.918"], ["0.6311", "4.142"], ["0.6313", "8.04"], ["0.6356", "8.04"], ["0.6361", "2.918"], ["0.6363", "240.929"]], "bids": [["0.592", "0.000384245"], ["0.591", "0.00457202"], ["0.588", "2.735"], ["0.5852", "2.918"], ["0.5836", "8.04"], ["0.5826", "235.09"], ["0.5825", "397.65105"], ["0.5824", "104.253"], ["0.58", "202.71"], ["0.5798", "2.918"], ["0.5793", "8.04"], ["0.5785", "398.87"], ["0.5783", "383.883"], ["0.5749", "8.04"], ["0.5745", "2.918"], ["0.5706", "8.04"], ["0.5692", "2.918"], ["0.5685", "6.345"], ["0.5663", "8.04"], ["0.5639", "2.918"], ["0.5619", "544.647"], ["0.56", "1079.662"], ["0.5593", "200"], ["0.5587", "2.918"], ["0.558", "500"], ["0.5576", "8.04"], ["0.5536", "2.918"], ["0.5535", "41.546"], ["0.5533", "8.04"], ["0.5529", "320.384"]], "id": 4200605}, "A5T_USDT"], "id": null}
1618678295.602078: {"method": "depth.update", "params": [true, {"asks": [["3.5841", "366.188"], ["3.5879", "179.68761478"], ["3.588", "139.933"], ["3.5902", "611.742"], ["3.5926", "436.288"], ["3.5962", "188.025"], ["3.6042", "723.415"], ["3.6049", "157.67"], ["3.7266", "215.662"], ["3.8272", "279.195"], ["3.8922", "461.682"], ["3.919", "334.517"], ["3.9221", "357.807"], ["4.0021", "214.555"], ["4.0086", "687.619"], ["4.0123", "266.678"], ["4.0726", "155.694"], ["4.1971", "170.876"], ["4.2239", "255.227"], ["4.2501", "238.404"], ["4.2844", "266.723"], ["4.2993", "229.322"], ["4.3515", "99.999"], ["4.3533", "340.81"], ["4.4075", "358.692"], ["4.4094", "204.43"], ["4.4211", "128.9"], ["4.4486", "173.211"], ["4.5201", "193.953"], ["4.5816", "137.95"]], "bids": [["3.531", "132.626"], ["3.5275", "634.411"], ["3.5271", "367.283"], ["3.527", "544.435"], ["3.4934", "356.51"], ["3.46", "243.645"], ["3.3361", "2.997"], ["3.2815", "313.89"], ["3.2459", "587.744"], ["3.2268", "381.458"], ["3.2168", "626.522"], ["3.1428", "221.582"], ["3.0727", "292.004"], ["3.0096", "224.44"], ["2.9719", "265.107"], ["2.966", "581.38"], ["2.9539", "888.881"], ["2.9501", "290.252"], ["2.9153", "483.026"], ["2.8801", "307.621"], ["2.8686", "625.804"], ["2.7964", "940.756"], ["2.7547", "304.074"], ["2.6904", "644.649"], ["2.6473", "580.821"], ["2.6158", "571.06"], ["2.5744", "178.951"], ["2.5604", "738.989"], ["2.4962", "262.286"], ["2.4837", "508.03"]], "id": 50720637}, "BAL3L_USDT"], "id": null}
1618678295.602323: {"method": "depth.update", "params": [true, {"asks": [["115.5155", "0.071"], ["115.6486", "20.143"], ["115.6946", "8.366"], ["116.5727", "7.268"], ["121.035", "13.959"], ["121.0776", "11.049"], ["121.4939", "6.521"], ["122.0497", "6.739"], ["124.2033", "2.983"], ["124.9493", "10.112"], ["125.2539", "20.859"], ["125.8616", "10.799"], ["126.9435", "8.291"], ["127.3426", "11.677"], ["128.3391", "7.556"], ["130.258", "20.401"], ["130.6246", "13.174"], ["130.7857", "12.543"], ["133.6174", "6.911"], ["133.8047", "11.457"], ["134.4671", "2.983"], ["135.4209", "9.651"], ["135.5466", "4.003"], ["136.1628", "10.062"], ["137.2777", "7.79"], ["137.6824", "4.409"], ["137.919", "7.18"], ["139.4737", "2.5"], ["139.9465", "10.039"], ["141.6675", "6.372"]], "bids": [["108.9554", "4.445"], ["108.9553", "0.9442"], ["108.9117", "53.864"], ["108.9107", "11.807"], ["108.9077", "0.083"], ["108.8688", "22.537"], ["108.7688", "6.21"], ["108.7495", "5.927"], ["106.4271", "7.231"], ["105.9663", "2.983"], ["105.12", "0.859"], ["104.165", "13.882"], ["103.2741", "8.687"], ["102.971", "5.832"], ["102.5789", "0.097"], ["101.4564", "45.595"], ["101.0846", "14.626"], ["100.8543", "13.209"], ["100.7848", "9.994"], ["100.1265", "9.941"], ["100.0137", "12.904"], ["99.2894", "12.71"], ["98.6798", "13.255"], ["98.1157", "6.303"], ["97.878", "1.346"], ["93.0272", "14.603"], ["92.7602", "17.323"], ["90.407", "2.983"], ["89.9636", "24.296"], ["87.4723", "20.566"]], "id": 48242050}, "SOL3L_USDT"], "id": null}
1618678295.602568: {"method": "depth.update", "params": [true, {"asks": [["1.1733", "844.26004677"], ["1.1734", "407.6887"], ["1.1735", "1516.27841202"], ["1.1736", "8.115"], ["1.2071", "302.97544767"], ["1.2072", "178.9399"], ["1.2085", "420.004"], ["1.2086", "2894.53"], ["1.2282", "1046.332"], ["1.2519", "964.82"], ["1.2619", "1130.723"], ["1.2689", "1243.301"], ["1.2922", "838.327"], ["1.299", "1903.737"], ["1.3085", "949.456"], ["1.3138", "875.731"], ["1.3383", "1352.704"], ["1.3487", "1304.022"], ["1.3736", "1441.776"], ["1.3743", "8.513259"], ["1.3746", "19.209274"], ["1.3801", "762.556"], ["1.3841", "894.274"], ["1.4093", "492.139"], ["1.4094", "864.402"], ["1.4283", "965.433"], ["1.45", "109.78358"], ["1.4569", "688.304"], ["1.5285", "449.811"], ["1.5531", "1159.199"]], "bids": [["1.1108", "8.105"], ["1.109", "20"], ["1.1001", "56"], ["1.1", "311.44326246"], ["1.096", "1"], ["1.0889", "49.31615233"], ["1.0888", "1646.123"], ["1.0883", "1704.34"], ["1.0879", "1514.62"], ["1.0875", "1083.484"], ["1.0871", "1078.547"], ["1.0867", "1396.706"], ["1.0862", "1386.495"], ["1.0848", "1610.873"], ["1.0844", "1105.874"], ["1.0806", "1174.689"], ["1.07", "637.319"], ["1.0589", "1782.725"], ["1.0584", "1360.811"], ["1.0579", "1370.267"], ["1.0367", "1111.582"], ["1.0366", "2.122"], ["1.025", "3050"], ["1.02", "62230.34"], ["1.0159", "1589.638"], ["1", "205"], ["0.99", "86.364"], ["0.88", "2"], ["0.5", "220"], ["0.1053", "9.496"]], "id": 161260}, "DUCK2_USDT"], "id": null}
1618678295.7782662: {"method": "depth.update", "params": [false, {"asks": [["3.5879", "0"], ["3.5901", "179.68761478"]]}, "BAL3L_USDT"], "id": null}
1618678295.798464: {"method": "depth.update", "params": [false, {"bids": [["0.00000238", "1805.54"]]}, "BTS_BTC"], "id": null}
1618678296.209611: {"method": "depth.update", "params": [false, {"bids": [["0.00006755", "13612.2494207526"], ["0.0000673", "0"], ["0.00006724", "6532.84"]]}, "TRX_ETH"], "id": null}
1618678296.236418: {"method": "depth.update", "params": [false, {"asks": [["3.5901", "0"], ["4.6315", "100.976"]]}, "BAL3L_USDT"], "id": null}
1618678296.251185: {"method": "depth.update", "params": [false, {"bids": [["0.00000238", "1666.66"]]}, "BTS_BTC"], "id": null}
1618678296.78021: {"method": "depth.update", "params": [false, {"asks": [["3.5879", "179.68761478"], ["4.6315", "0"]], "bids": [["3.5271", "786.173"]]}, "BAL3L_USDT"], "id": null}
1618678296.848008: {"method": "depth.update", "params": [false, {"asks": [["1.1734", "1502.16579138"], ["1.1735", "421.80132064"]]}, "DUCK2_USDT"], "id": null}
1618678297.229163: {"method": "depth.update", "params": [false, {"bids": [["0.00007434", "4574.985"], ["0.00007285", "3346.219"], ["0.00000105", "0"], ["0.00000065", "0"]]}, "REQ_ETH"], "id": null}
1618678297.241726: {"method": "depth.update", "params": [false, {"asks": [["3.584", "179.68761478"], ["3.5879", "0"]]}, "BAL3L_USDT"], "id": null}
1618678297.737529: {"method": "depth.update", "params": [false, {"bids": [["0.00007435", "700.524"], ["0.0000742", "0"]]}, "REQ_ETH"], "id": null}
1618678297.7486908: {"method": "depth.update", "params": [false, {"asks": [["3.584", "0"], ["4.6315", "100.976"]]}, "BAL3L_USDT"], "id": null}
1618678298.220499: {"method": "depth.update", "params": [false, {"bids": [["0.0003554", "0"], ["0.0000025", "4000"]]}, "VELO_ETH"], "id": null}
1618678298.236535: {"method": "depth.update", "params": [false, {"asks": [["3.5852", "189.876"], ["3.5878", "179.68761478"], ["4.5816", "0"], ["4.6315", "0"]], "bids": [["3.5281", "412.81"], ["2.4837", "0"]]}, "BAL3L_USDT"], "id": null}
1618678299.231427: {"method": "depth.update", "params": [false, {"asks": [["1.9721", "743.47"], ["2.3972", "0"]], "bids": [["1.906", "311.879"], ["1.5396", "0"]]}, "AVAX3L_USDT"], "id": null}
1618678299.247562: {"method": "depth.update", "params": [false, {"asks": [["3.5878", "0"], ["4.5816", "137.95"]]}, "BAL3L_USDT"], "id": null}
1618678299.2627048: {"method": "depth.update", "params": [false, {"bids": [["0.000002381", "3588.1"], ["0.00000085", "0"]]}, "BTS_BTC"], "id": null}
1618678299.8473222: {"method": "depth.update", "params": [false, {"asks": [["3.584", "179.68761478"], ["4.5816", "0"]], "bids": [["3.3361", "0"], ["2.4837", "508.03"]]}, "BAL3L_USDT"], "id": null}
1618678299.847451: {"method": "depth.update", "params": [false, {"bids": [["108.9553", "0"], ["84.8262", "10.654"]]}, "SOL3L_USDT"], "id": null}
1618678299.847497: {"method": "depth.update", "params": [false, {"bids": [["0.000002381", "2870.48"]]}, "BTS_BTC"], "id": null}
1618678299.847528: {"method": "depth.update", "params": [false, {"asks": [["1.1733", "1251.94874677"], ["1.1734", "1463.27841202"], ["1.1735", "53"]]}, "DUCK2_USDT"], "id": null}
1618678300.2548459: {"method": "depth.update", "params": [false, {"bids": [["0.00007434", "0"], ["0.00000105", "9523.809"]]}, "REQ_ETH"], "id": null}
1618678300.255007: {"method": "depth.update", "params": [false, {"asks": [["3.584", "0"], ["3.5851", "179.68761478"]], "bids": [["3.2814", "3.047"], ["2.4837", "0"]]}, "BAL3L_USDT"], "id": null}
1618678300.2551198: {"method": "depth.update", "params": [false, {"asks": [["115.6116", "16.923"], ["141.6675", "0"]], "bids": [["108.8768", "6.764"], ["93.3109", "15.093"], ["87.4723", "0"], ["84.8262", "0"]]}, "SOL3L_USDT"], "id": null}
1618678300.800514: {"method": "depth.update", "params": [false, {"bids": [["0.00007436", "317.0989363905"], ["0.00000105", "0"]]}, "REQ_ETH"], "id": null}
1618678300.8101199: {"method": "depth.update", "params": [false, {"asks": [["3.585", "167.819"], ["3.5851", "0"]], "bids": [["3.528", "134.403"], ["2.4962", "0"]]}, "BAL3L_USDT"], "id": null}
1618678300.8313658: {"method": "depth.update", "params": [false, {"bids": [["108.9557", "0.9436"], ["89.9636", "0"]]}, "SOL3L_USDT"], "id": null}
1618678301.246186: {"method": "depth.update", "params": [false, {"bids": [["0.00007437", "700.524"], ["0.00007436", "0"], ["0.00007435", "0"], ["0.00000105", "9523.809"]]}, "REQ_ETH"], "id": null}
1618678301.710624: {"method": "depth.update", "params": [false, {"bids": [["1.906", "965.481"]]}, "AVAX3L_USDT"], "id": null}
1618678301.751342: {"method": "depth.update", "params": [false, {"asks": [["3.5849", "179.68761478"], ["4.5201", "0"]]}, "BAL3L_USDT"], "id": null}
1618678301.765621: {"method": "depth.update", "params": [false, {"bids": [["104.4727", "6.384"], ["90.407", "0"]]}, "SOL3L_USDT"], "id": null}
1618678301.8189042: {"method": "depth.update", "params": [false, {"asks": [["1.1732", "8.115"], ["1.1736", "0"]], "bids": [["1.1108", "0"], ["1.1091", "8.105"]]}, "DUCK2_USDT"], "id": null}
1618678302.2484858: {"method": "depth.update", "params": [false, {"asks": [["3.5849", "0"], ["3.5866", "437.309"]], "bids": [["3.5296", "187.37"], ["2.5604", "0"]]}, "BAL3L_USDT"], "id": null}
1618678302.261149: {"method": "depth.update", "params": [false, {"bids": [["108.9558", "4.445"], ["108.9554", "0"]]}, "SOL3L_USDT"], "id": null}
1618678302.917994: {"method": "depth.update", "params": [false, {"asks": [["3.5849", "179.68761478"], ["4.4486", "0"]]}, "BAL3L_USDT"], "id": null}
1618678302.918141: {"method": "depth.update", "params": [false, {"bids": [["108.9558", "0"], ["90.407", "2.983"]]}, "SOL3L_USDT"], "id": null}
1618678303.838241: {"method": "depth.update", "params": [false, {"asks": [["0.6074", "102"], ["0.6363", "0"]]}, "A5T_USDT"], "id": null}
1618678303.8383439: {"method": "depth.update", "params": [false, {"asks": [["3.5849", "0"], ["4.4486", "173.211"]]}, "BAL3L_USDT"], "id": null}
1618678304.24798: {"method": "depth.update", "params": [false, {"asks": [["3.584", "179.68761478"], ["4.4486", "0"]]}, "BAL3L_USDT"], "id": null}
1618678304.744147: {"method": "depth.update", "params": [false, {"asks": [["3.584", "0"], ["3.5849", "179.68761478"], ["3.5861", "436.081"], ["4.4211", "0"]], "bids": [["3.5291", "262.476"], ["2.5744", "0"]]}, "BAL3L_USDT"], "id": null}
1618678305.2486122: {"method": "depth.update", "params": [false, {"bids": [["0.5827", "97"], ["0.5529", "0"]]}, "A5T_USDT"], "id": null}
1618678305.260402: {"method": "depth.update", "params": [false, {"asks": [["3.584", "179.68761478"], ["3.5849", "0"]]}, "BAL3L_USDT"], "id": null}
1618678305.275181: {"method": "depth.update", "params": [false, {"bids": [["108.9558", "4.445"], ["90.407", "0"]]}, "SOL3L_USDT"], "id": null}
1618678305.7827368: {"method": "depth.update", "params": [false, {"asks": [["3.584", "0"], ["3.5849", "179.68761478"]]}, "BAL3L_USDT"], "id": null}
1618678305.7966762: {"method": "depth.update", "params": [false, {"bids": [["108.9558", "0"], ["108.9555", "0.8481900281"]]}, "SOL3L_USDT"], "id": null}
1618678305.796746: {"method": "depth.update", "params": [false, {"bids": [["0.000002381", "2864.89"]]}, "BTS_BTC"], "id": null}
1618678306.220623: {"method": "depth.update", "params": [false, {"bids": [["0.0003555", "0"], ["0.000002", "5000"]]}, "VELO_ETH"], "id": null}
1618678306.2434938: {"method": "depth.update", "params": [false, {"asks": [["3.587", "275.587"], ["4.4094", "0"]], "bids": [["3.53", "177.291"], ["2.6158", "0"]]}, "BAL3L_USDT"], "id": null}
1618678306.261348: {"method": "depth.update", "params": [false, {"bids": [["108.9558", "4.445"], ["108.9555", "0"]]}, "SOL3L_USDT"], "id": null}
1618678306.7325928: {"method": "depth.update", "params": [false, {"bids": [["1.7882", "0"], ["1.5396", "451.215"]]}, "AVAX3L_USDT"], "id": null}
1618678306.7461572: {"method": "depth.update", "params": [false, {"bids": [["0.00006755", "10724.9680107526"], ["0.00006724", "0"], ["0.00006722", "6535.19"]]}, "TRX_ETH"], "id": null}
1618678306.761604: {"method": "depth.update", "params": [false, {"bids": [["0.0003556", "92.624"], ["0.000002", "0"]]}, "VELO_ETH"], "id": null}
1618678306.7859719: {"method": "depth.update", "params": [false, {"asks": [["3.5849", "0"], ["4.4094", "204.43"]]}, "BAL3L_USDT"], "id": null}
1618678306.805061: {"method": "depth.update", "params": [false, {"bids": [["108.9558", "0"], ["90.407", "2.983"]]}, "SOL3L_USDT"], "id": null}
1618678307.223969: {"method": "depth.update", "params": [false, {"bids": [["1.7717", "649.032"]]}, "AVAX3L_USDT"], "id": null}
1618678307.224086: {"method": "depth.update", "params": [false, {"bids": [["0.00006755", "13612.4289207526"]]}, "TRX_ETH"], "id": null}
1618678307.234772: {"method": "depth.update", "params": [false, {"asks": [["3.584", "179.68761478"], ["4.4094", "0"]]}, "BAL3L_USDT"], "id": null}
1618678307.2543519: {"method": "depth.update", "params": [false, {"bids": [["108.9557", "0"], ["89.9636", "24.296"]]}, "SOL3L_USDT"], "id": null}
1618678307.831593: {"method": "depth.update", "params": [false, {"asks": [["3.584", "0"], ["4.4094", "204.43"]]}, "BAL3L_USDT"], "id": null}
1618678307.831699: {"method": "depth.update", "params": [false, {"bids": [["108.9558", "4.445"], ["89.9636", "0"]]}, "SOL3L_USDT"], "id": null}
1618678308.209086: {"method": "depth.update", "params": [false, {"bids": [["0.0000669", "91694.0667479"], ["0.00006665", "0"]]}, "TRX_ETH"], "id": null}
1618678308.2337039: {"method": "depth.update", "params": [false, {"asks": [["3.584", "179.68761478"], ["4.4094", "0"]]}, "BAL3L_USDT"], "id": null}
1618678308.245894: {"method": "depth.update", "params": [false, {"bids": [["108.9561", "0.9432"], ["108.9558", "0"]]}, "SOL3L_USDT"], "id": null}
1618678308.7199402: {"method": "depth.update", "params": [false, {"asks": [["1.9722", "299.393"], ["2.3862", "0"]], "bids": [["1.9062", "264.75"], ["1.5396", "0"]]}, "AVAX3L_USDT"], "id": null}
1618678308.768064: {"method": "depth.update", "params": [false, {"asks": [["3.584", "0"], ["3.589", "305.61"]], "bids": [["3.5319", "239.91"], ["2.6473", "0"]]}, "BAL3L_USDT"], "id": null}
1618678308.7790039: {"method": "depth.update", "params": [false, {"bids": [["108.9556", "4.445"], ["90.407", "0"]]}, "SOL3L_USDT"], "id": null}
1618678308.779093: {"method": "depth.update", "params": [false, {"bids": [["0.000002382", "138.74"], ["0.0000009", "0"]]}, "BTS_BTC"], "id": null}
1618678309.263499: {"method": "depth.update", "params": [false, {"asks": [["0.000373", "725.528"]]}, "VELO_ETH"], "id": null}
1618678309.263579: {"method": "depth.update", "params": [false, {"bids": [["0.592", "0"], ["0.591", "0"], ["0.588", "0.000956265"], ["0.5529", "320.384"], ["0.55", "1353.47"]]}, "A5T_USDT"], "id": null}
1618678309.263638: {"method": "depth.update", "params": [false, {"asks": [["3.584", "179.68761478"], ["4.4075", "0"]]}, "BAL3L_USDT"], "id": null}
1618678309.263671: {"method": "depth.update", "params": [false, {"asks": [["115.6356", "17.325"], ["139.9465", "0"]], "bids": [["108.9556", "0"], ["108.9118", "4.445"], ["108.8994", "10.243"], ["92.7602", "0"]]}, "SOL3L_USDT"], "id": null}
1618678309.2637281: {"method": "depth.update", "params": [false, {"bids": [["0.000002381", "0"], ["0.0000009", "1000"]]}, "BTS_BTC"], "id": null}
1618678309.781297: {"method": "depth.update", "params": [false, {"asks": [["3.584", "0"], ["4.4075", "358.692"]]}, "BAL3L_USDT"], "id": null}
1618678309.799597: {"method": "depth.update", "params": [false, {"bids": [["108.9556", "4.445"], ["108.9118", "0"]]}, "SOL3L_USDT"], "id": null}
1618678309.7997: {"method": "depth.update", "params": [false, {"bids": [["0.000002382", "0"], ["0.00000085", "1000"]]}, "BTS_BTC"], "id": null}
1618678310.2860758: {"method": "depth.update", "params": [false, {"asks": [["3.584", "179.68761478"], ["3.5841", "0"], ["3.585", "0"], ["3.5852", "0"], ["3.5861", "0"], ["3.5866", "0"], ["3.587", "0"], ["3.588", "0"], ["3.6042", "0"], ["3.7266", "0"], ["4.4094", "204.43"], ["4.4211", "128.9"], ["4.4486", "173.211"], ["4.495", "315.593"], ["4.5201", "193.953"], ["4.5816", "137.95"], ["4.6315", "100.976"], ["4.6398", "684.006"]], "bids": [["3.5275", "0"], ["3.4934", "0"], ["2.6473", "580.821"], ["2.6158", "571.06"]]}, "BAL3L_USDT"], "id": null}
1618678310.286277: {"method": "depth.update", "params": [false, {"bids": [["108.9556", "0"], ["108.9118", "4.445"]]}, "SOL3L_USDT"], "id": null}
1618678310.766279: {"method": "depth.update", "params": [false, {"asks": [["3.584", "0"], ["4.7207", "175.057"]]}, "BAL3L_USDT"], "id": null}
1618678310.778615: {"method": "depth.update", "params": [false, {"asks": [["115.6116", "0"], ["121.4939", "0"], ["139.9465", "10.039"], ["141.6675", "6.372"]], "bids": [["108.9556", "4.445"], ["108.9118", "0"], ["108.9117", "0"], ["108.9107", "0"], ["102.971", "0"], ["92.7602", "17.323"], ["90.407", "2.983"], ["89.9636", "24.296"]]}, "SOL3L_USDT"], "id": null}
1618678310.8230941: {"method": "depth.update", "params": [false, {"asks": [["1.1735", "0"], ["1.5532", "2049.597967"]]}, "DUCK2_USDT"], "id": null}
1618678311.198379: {"method": "depth.update", "params": [false, {"asks": [["1.9721", "0"], ["2.0458", "0"], ["2.3862", "270.586"], ["2.3972", "439.788"]], "bids": [["1.9082", "0"], ["1.82", "0"], ["1.6565", "0"], ["1.5396", "451.215"], ["1.5106", "626.623"], ["1.4958", "878.403"]]}, "AVAX3L_USDT"], "id": null}
1618678311.24236: {"method": "depth.update", "params": [false, {"asks": [["3.5889", "464.171"], ["3.8811", "212.377"], ["4.1971", "0"], ["4.6398", "0"]], "bids": [["3.5319", "0"], ["3.5318", "329.892"], ["3.2815", "0"], ["3.1428", "0"], ["2.5744", "178.951"], ["2.5604", "738.989"]]}, "BAL3L_USDT"], "id": null}
1618678311.258443: {"method": "depth.update", "params": [false, {"bids": [["108.9556", "0"], ["108.9118", "0.8481997443"]]}, "SOL3L_USDT"], "id": null}
1618678311.759659: {"method": "depth.update", "params": [false, {"asks": [["3.584", "179.68761478"], ["4.7207", "0"]]}, "BAL3L_USDT"], "id": null}
1618678311.773862: {"method": "depth.update", "params": [false, {"bids": [["108.9556", "4.445"], ["108.9118", "0"]]}, "SOL3L_USDT"], "id": null}
1618678312.23194: {"method": "depth.update", "params": [false, {"asks": [["0.0009855", "0"]]}, "VELO_ETH"], "id": null}
1618678312.244257: {"method": "depth.update", "params": [false, {"asks": [["116.5727", "0"], ["123.971", "16.621"], ["130.6246", "0"], ["141.8206", "6.794"]], "bids": [["108.9556", "0"], ["106.4271", "0"], ["101.0846", "0"], ["87.6133", "27.67"], ["87.4723", "20.566"], ["84.8262", "10.654"]]}, "SOL3L_USDT"], "id": null}
1618678312.282563: {"method": "depth.update", "params": [false, {"asks": [["1.1732", "61.115"]]}, "DUCK2_USDT"], "id": null}
1618678312.744364: {"method": "depth.update", "params": [false, {"asks": [["2.0963", "154.315"], ["2.1226", "0"], ["2.3801", "0"], ["2.4089", "879.635"]], "bids": [["1.6791", "0"], ["1.4756", "1272.619"]]}, "AVAX3L_USDT"], "id": null}
1618678312.744438: {"method": "depth.update", "params": [false, {"asks": [["3.584", "0"], ["3.5886", "254.89"], ["3.6221", "404.69"], ["4.2993", "0"], ["4.3515", "0"], ["4.7207", "175.057"]], "bids": [["3.5318", "0"], ["3.5316", "259.88"], ["3.2268", "0"], ["2.8686", "0"], ["2.4962", "262.286"], ["2.4837", "508.03"]]}, "BAL3L_USDT"], "id": null}
1618678313.2500842: {"method": "depth.update", "params": [false, {"asks": [["120.6799", "8.049"], ["141.8206", "0"]], "bids": [["104.1697", "7.525"], ["100.7848", "0"], ["94.1876", "30.038"], ["93.0272", "0"]]}, "SOL3L_USDT"], "id": null}
1618678313.725279: {"method": "depth.update", "params": [false, {"asks": [["1.9783", "0"], ["2.1469", "1138.814"], ["2.1873", "0"], ["2.2377", "574.982"]], "bids": [["1.9062", "396.121"], ["1.8367", "0"], ["1.7301", "1333.384"]]}, "AVAX3L_USDT"], "id": null}
1618678313.776264: {"method": "depth.update", "params": [false, {"asks": [["3.5888", "179.68761478"], ["4.7207", "0"]]}, "BAL3L_USDT"], "id": null}
1618678314.2800379: {"method": "depth.update", "params": [false, {"asks": [["0.5851", "7.665349735"], ["0.5906", "2.918"], ["0.6356", "0"], ["0.6361", "0"]], "bids": [["0.588", "0"], ["0.5852", "0"], ["0.5489", "8.04"], ["0.5485", "2.918"]]}, "A5T_USDT"], "id": null}
1618678314.2801988: {"method": "depth.update", "params": [false, {"asks": [["3.5886", "0"], ["3.5889", "0"], ["3.9002", "283.873"], ["3.911", "259.76"], ["4.4075", "0"], ["4.5117", "188.501"]], "bids": [["3.532", "580.433"], ["3.5271", "418.89"], ["2.4837", "0"]]}, "BAL3L_USDT"], "id": null}
1618678314.280294: {"method": "depth.update", "params": [false, {"bids": [["108.9078", "4.445"], ["84.8262", "0"]]}, "SOL3L_USDT"], "id": null}
1618678314.79392: {"method": "depth.update", "params": [false, {"asks": [["3.5885", "179.68761478"], ["3.5888", "0"]]}, "BAL3L_USDT"], "id": null}
1618678314.7940779: {"method": "depth.update", "params": [false, {"asks": [["115.6486", "0"], ["121.0776", "0"], ["123.179", "10.142"], ["139.4217", "10.712"]], "bids": [["108.9562", "4.445"], ["108.9078", "0"], ["87.7254", "10.808"], ["87.4723", "0"]]}, "SOL3L_USDT"], "id": null}
1618678315.219403: {"method": "depth.update", "params": [false, {"asks": [["1.98", "0"], ["2.117", "0"], ["2.2646", "272.889"], ["2.3789", "299.952"]], "bids": [["1.6362", "0"], ["1.5562", "0"], ["1.525", "581.874"], ["1.5053", "501.533"]]}, "AVAX3L_USDT"], "id": null}
1618678315.273464: {"method": "depth.update", "params": [false, {"asks": [["3.5885", "0"], ["3.593", "859.182"], ["3.6049", "0"], ["4.0123", "0"], ["4.7207", "175.057"], ["4.7415", "285.79"]], "bids": [["2.7964", "0"], ["2.6904", "0"], ["2.4045", "405.462"], ["2.3749", "271.429"]]}, "BAL3L_USDT"], "id": null}
1618678315.2876182: {"method": "depth.update", "params": [false, {"bids": [["108.9562", "0"], ["87.4723", "20.566"]]}, "SOL3L_USDT"], "id": null}
1618678315.779385: {"method": "depth.update", "params": [false, {"asks": [["3.5888", "179.68761478"], ["4.7415", "0"]]}, "BAL3L_USDT"], "id": null}
1618678315.801367: {"method": "depth.update", "params": [false, {"bids": [["108.9562", "4.445"], ["87.4723", "0"]]}, "SOL3L_USDT"], "id": null}
1618678316.2197099: {"method": "depth.update", "params": [false, {"bids": [["0.00006712", "0"], ["0.00005599", "5719.49"]]}, "TRX_ETH"], "id": null}
1618678316.275437: {"method": "depth.update", "params": [false, {"asks": [["125.7348", "4.965"], ["126.6175", "6.499"], ["126.9435", "0"], ["141.6675", "0"]], "bids": [["108.9562", "0"], ["108.8768", "0"], ["96.2454", "14.046"], ["89.9636", "0"], ["87.4723", "20.566"], ["84.8262", "10.654"]]}, "SOL3L_USDT"], "id": null}
1618678316.707198: {"method": "depth.update", "params": [false, {"asks": [["2.0845", "812.645"], ["2.1729", "0"], ["2.1746", "1826.84"], ["2.3686", "0"]], "bids": [["1.906", "653.602"], ["1.6184", "268.631"], ["1.5312", "879.439"], ["1.5053", "0"], ["1.4756", "0"]]}, "AVAX3L_USDT"], "id": null}
1618678316.741578: {"method": "depth.update", "params": [false, {"asks": [["3.5885", "179.68761478"], ["3.5888", "0"], ["3.589", "0"], ["3.5891", "382.147"], ["4.115", "167.139"], ["4.7207", "0"]], "bids": [["3.532", "235.228"], ["2.7547", "0"], ["2.3731", "549.777"]]}, "BAL3L_USDT"], "id": null}
1618678316.755318: {"method": "depth.update", "params": [false, {"bids": [["108.9562", "0.8501451305"], ["84.8262", "0"]]}, "SOL3L_USDT"], "id": null}
1618678316.793578: {"method": "depth.update", "params": [false, {"asks": [["1.172", "0.922225895"], ["1.5532", "0"]]}, "DUCK2_USDT"], "id": null}
1618678317.253281: {"method": "depth.update", "params": [false, {"asks": [["3.5885", "0"], ["4.7415", "285.79"]]}, "BAL3L_USDT"], "id": null}
1618678317.253429: {"method": "depth.update", "params": [false, {"bids": [["108.9562", "0"], ["94.5167", "10.318"], ["88.5026", "17.494"], ["87.4723", "0"]]}, "SOL3L_USDT"], "id": null}
1618678317.764554: {"method": "depth.update", "params": [false, {"asks": [["2.0845", "0"], ["2.093", "685.1"], ["2.1756", "0"], ["2.406", "339.451"]], "bids": [["1.8712", "0"], ["1.8545", "1499.048"], ["1.8062", "543.489"], ["1.7662", "0"]]}, "AVAX3L_USDT"], "id": null}
1618678317.764711: {"method": "depth.update", "params": [false, {"asks": [["3.5901", "179.68761478"], ["4.7415", "0"]]}, "BAL3L_USDT"], "id": null}
1618678317.779588: {"method": "depth.update", "params": [false, {"asks": [["119.9693", "23.292"], ["126.6175", "0"], ["128.3391", "0"], ["133.0605", "7.868"]], "bids": [["108.9562", "4.445"], ["87.6133", "0"]]}, "SOL3L_USDT"], "id": null}
1618678318.2735722: {"method": "depth.update", "params": [false, {"asks": [["3.589", "179.68761478"], ["3.5901", "0"], ["3.8811", "0"], ["4.0086", "0"], ["4.016", "219.622"], ["4.6896", "232.683"]], "bids": [["3.532", "523.928"], ["3.528", "0"], ["2.6609", "590.922"]]}, "BAL3L_USDT"], "id": null}
1618678318.2780612: {"method": "depth.update", "params": [false, {"bids": [["108.9562", "0"], ["87.6133", "27.67"]]}, "SOL3L_USDT"], "id": null}
1618678318.7868202: {"method": "depth.update", "params": [false, {"asks": [["3.589", "0"], ["3.5901", "179.68761478"]]}, "BAL3L_USDT"], "id": null}
1618678318.8035939: {"method": "depth.update", "params": [false, {"asks": [["125.9346", "15.741"], ["136.1628", "0"]], "bids": [["108.9562", "4.445"], ["104.165", "0"], ["103.8404", "11.637"], ["102.9048", "14.637"], ["87.7254", "0"], ["87.6133", "0"]]}, "SOL3L_USDT"], "id": null}
1618678319.200906: {"method": "depth.update", "params": [false, {"asks": [["1.9717", "462.893"], ["1.9776", "0"], ["2.0527", "752.808"], ["2.093", "0"]], "bids": [["1.9062", "0"], ["1.906", "0"], ["1.9056", "872.393"], ["1.5943", "470.796"], ["1.5396", "0"], ["1.4756", "1272.619"]]}, "AVAX3L_USDT"], "id": null}
1618678319.238265: {"method": "depth.update", "params": [false, {"asks": [["3.589", "179.68761478"], ["3.5901", "0"]], "bids": [["2.5131", "177.947"], ["2.3731", "0"]]}, "BAL3L_USDT"], "id": null}
1618678319.250485: {"method": "depth.update", "params": [false, {"bids": [["108.9562", "0"], ["108.9078", "4.445"]]}, "SOL3L_USDT"], "id": null}
1618678319.7832131: {"method": "depth.update", "params": [false, {"asks": [["4.0635", "194.565"], ["4.1985", "371.111"], ["4.2501", "0"], ["4.495", "0"]], "bids": [["3.5316", "0"], ["2.6158", "0"], ["2.3922", "216.521"], ["2.3731", "549.777"]]}, "BAL3L_USDT"], "id": null}
1618678319.78764: {"method": "depth.update", "params": [false, {"bids": [["108.9562", "4.445"], ["108.9078", "0"]]}, "SOL3L_USDT"], "id": null}
1618678320.2215092: {"method": "depth.update", "params": [false, {"bids": [["0.00006706", "58634.24075161"], ["0.00005599", "0"]]}, "TRX_ETH"], "id": null}
1618678320.2453918: {"method": "depth.update", "params": [false, {"asks": [["0.5851", "0"], ["0.6356", "8.04"]]}, "A5T_USDT"], "id": null}
1618678320.275002: {"method": "depth.update", "params": [false, {"asks": [["125.9346", "0"], ["130.7857", "0"], ["131.79", "8.319"], ["141.8206", "6.794"]], "bids": [["104", "11.682"], ["98.1157", "0"], ["94.5167", "0"], ["87.7254", "10.808"]]}, "SOL3L_USDT"], "id": null}
1618678320.718386: {"method": "depth.update", "params": [false, {"asks": [["2.1757", "193.213"], ["2.2198", "0"], ["2.2411", "669.136"], ["2.3379", "0"]], "bids": [["1.8438", "0"], ["1.7234", "292.034"], ["1.6228", "0"], ["1.5739", "620.093"]]}, "AVAX3L_USDT"], "id": null}
1618678320.752759: {"method": "depth.update", "params": [false, {"asks": [["3.589", "0"], ["3.5891", "0"], ["3.5892", "384.056"], ["4.109", "159.288"], ["4.5201", "0"], ["4.7415", "285.79"]], "bids": [["3.5321", "602.14"], ["3.0727", "0"], ["2.6609", "0"], ["2.5208", "239.082"]]}, "BAL3L_USDT"], "id": null}
1618678320.7740521: {"method": "depth.update", "params": [false, {"bids": [["108.9562", "0"], ["108.9078", "4.451"]]}, "SOL3L_USDT"], "id": null}
1618678321.345851: {"method": "depth.update", "params": [false, {"asks": [["3.589", "179.68761478"], ["4.7415", "0"]]}, "BAL3L_USDT"], "id": null}
1618678321.345963: {"method": "depth.update", "params": [false, {"bids": [["108.9562", "4.451"], ["108.9078", "0"]]}, "SOL3L_USDT"], "id": null}
1618678321.748489: {"method": "depth.update", "params": [false, {"asks": [["115.6356", "0"], ["115.6616", "5.757"], ["123.9917", "13.886"], ["141.8206", "0"]], "bids": [["108.9239", "12.738"], ["108.7495", "0"], ["103.2741", "0"], ["87.6133", "27.67"]]}, "SOL3L_USDT"], "id": null}
1618678322.271678: {"method": "depth.update", "params": [false, {"asks": [["2.0976", "437.539"], ["2.1469", "0"], ["2.1757", "0"], ["2.4038", "437.356"]], "bids": [["1.9056", "903.555"], ["1.6502", "391.626"], ["1.6177", "0"]]}, "AVAX3L_USDT"], "id": null}
1618678322.271787: {"method": "depth.update", "params": [false, {"bids": [["0.00006725", "6536.72"], ["0.00006722", "0"]]}, "TRX_ETH"], "id": null}
1618678322.271819: {"method": "depth.update", "params": [false, {"asks": [["3.589", "0"], ["3.5892", "0"], ["3.5902", "0"], ["3.5926", "0"], ["3.593", "0"], ["3.5962", "0"], ["3.598", "179.68761478"], ["3.5981", "216.318"], ["3.6425", "844.398"], ["3.6581", "205.712"], ["3.9106", "358.023"], ["4.4094", "0"], ["4.5469", "147.359"], ["4.6014", "212.349"]], "bids": [["3.5409", "375.541"], ["2.6721", "498.892"], ["2.5604", "0"], ["2.4962", "0"]]}, "BAL3L_USDT"], "id": null}
1618678322.271918: {"method": "depth.update", "params": [false, {"bids": [["108.9563", "4.451"], ["108.9562", "0"]]}, "SOL3L_USDT"], "id": null}
1618678322.779728: {"method": "depth.update", "params": [false, {"asks": [["3.5889", "179.68761478"], ["3.598", "0"]]}, "BAL3L_USDT"], "id": null}
1618678322.779882: {"method": "depth.update", "params": [false, {"asks": [["116.1223", "14.204"], ["123.179", "0"], ["132.5931", "11.223"], ["135.4209", "0"]], "bids": [["105.351", "6.26"], ["102.7487", "3.937"], ["98.6798", "0"], ["87.6133", "0"]]}, "SOL3L_USDT"], "id": null}
1618678323.2063391: {"method": "depth.update", "params": [false, {"asks": [["2.1465", "0"], ["2.162", "476.73"], ["2.2568", "205.636"], ["2.3046", "363.644"], ["2.4089", "0"]], "bids": [["1.661", "0"], ["1.6304", "535.232"], ["1.5505", "1497.331"], ["1.4756", "0"]]}, "AVAX3L_USDT"], "id": null}
1618678323.7651331: {"method": "depth.update", "params": [false, {"asks": [["3.5889", "0"], ["3.5981", "0"], ["3.5991", "296.279"], ["3.919", "0"], ["4.3295", "1033.824"], ["4.7415", "285.79"]], "bids": [["3.5419", "149.881"], ["3.5409", "0"], ["3.527", "0"], ["2.8575", "271.651"]]}, "BAL3L_USDT"], "id": null}
1618678324.2516081: {"method": "depth.update", "params": [false, {"asks": [["3.598", "179.68761478"], ["4.7415", "0"]]}, "BAL3L_USDT"], "id": null}
1618678324.2684438: {"method": "depth.update", "params": [false, {"asks": [["135.5466", "0"], ["137.919", "0"], ["141.8206", "6.794"], ["142.1134", "2.286"]], "bids": [["98.3872", "16.523"], ["92.9654", "15.792"], ["88.5026", "0"], ["87.7254", "0"]]}, "SOL3L_USDT"], "id": null}
1618678324.720532: {"method": "depth.update", "params": [false, {"asks": [["2.1279", "610.747"], ["2.176", "0"], ["2.3558", "0"], ["2.3883", "179.521"]], "bids": [["1.9049", "0"], ["1.8318", "0"], ["1.521", "672.146"], ["1.478", "694.283"]]}, "AVAX3L_USDT"], "id": null}
1618678324.762068: {"method": "depth.update", "params": [false, {"asks": [["3.5971", "156.507"], ["3.598", "0"], ["3.622", "179.68761478"], ["4.109", "0"], ["4.5469", "0"], ["4.7415", "285.79"]], "bids": [["3.5419", "0"], ["3.5399", "187.719"], ["3.076", "628.259"], ["2.3731", "0"]]}, "BAL3L_USDT"], "id": null}
1618678324.810622: {"method": "depth.update", "params": [false, {"bids": [["1.0889", "117.26815233"]]}, "DUCK2_USDT"], "id": null}
