wss://api.gateio.ws/ws/v4/ <-> 1619093531.891181
wss://api.gateio.ws/ws/v4/ <- 1619093532.7708359: {"time":1619093532,"channel":"spot.trades","event":"subscribe","payload":["INK_USDT","HAI_ETH","BTC_USDC","NANO_USDT","QTUM3S_USDT","DIS_USDT","NEO_BTC","FAST_USDT","ZKS_ETH","OMG_USDT"]}
wss://api.gateio.ws/ws/v4/ <- 1619093532.771203: {"time":1619093532,"channel":"spot.order_book_update","event":"subscribe","payload":["INK_USDT","100ms"]}
wss://api.gateio.ws/ws/v4/ <- 1619093532.771306: {"time":1619093532,"channel":"spot.order_book_update","event":"subscribe","payload":["HAI_ETH","100ms"]}
wss://api.gateio.ws/ws/v4/ <- 1619093532.771392: {"time":1619093532,"channel":"spot.order_book_update","event":"subscribe","payload":["BTC_USDC","100ms"]}
wss://api.gateio.ws/ws/v4/ <- 1619093532.771471: {"time":1619093532,"channel":"spot.order_book_update","event":"subscribe","payload":["NANO_USDT","100ms"]}
wss://api.gateio.ws/ws/v4/ <- 1619093532.7715468: {"time":1619093532,"channel":"spot.order_book_update","event":"subscribe","payload":["QTUM3S_USDT","100ms"]}
wss://api.gateio.ws/ws/v4/ <- 1619093532.7716212: {"time":1619093532,"channel":"spot.order_book_update","event":"subscribe","payload":["DIS_USDT","100ms"]}
wss://api.gateio.ws/ws/v4/ <- 1619093532.771692: {"time":1619093532,"channel":"spot.order_book_update","event":"subscribe","payload":["NEO_BTC","100ms"]}
wss://api.gateio.ws/ws/v4/ <- 1619093532.7717628: {"time":1619093532,"channel":"spot.order_book_update","event":"subscribe","payload":["FAST_USDT","100ms"]}
wss://api.gateio.ws/ws/v4/ <- 1619093532.771832: {"time":1619093532,"channel":"spot.order_book_update","event":"subscribe","payload":["ZKS_ETH","100ms"]}
wss://api.gateio.ws/ws/v4/ <- 1619093532.771899: {"time":1619093532,"channel":"spot.order_book_update","event":"subscribe","payload":["OMG_USDT","100ms"]}
wss://api.gateio.ws/ws/v4/ <- 1619093532.771978: {"time":1619093532,"channel":"spot.candlesticks","event":"subscribe","payload":["1m","INK_USDT"]}
wss://api.gateio.ws/ws/v4/ <- 1619093532.7720509: {"time":1619093532,"channel":"spot.candlesticks","event":"subscribe","payload":["1m","HAI_ETH"]}
wss://api.gateio.ws/ws/v4/ <- 1619093532.77212: {"time":1619093532,"channel":"spot.candlesticks","event":"subscribe","payload":["1m","BTC_USDC"]}
wss://api.gateio.ws/ws/v4/ <- 1619093532.772188: {"time":1619093532,"channel":"spot.candlesticks","event":"subscribe","payload":["1m","NANO_USDT"]}
wss://api.gateio.ws/ws/v4/ <- 1619093532.772256: {"time":1619093532,"channel":"spot.candlesticks","event":"subscribe","payload":["1m","QTUM3S_USDT"]}
wss://api.gateio.ws/ws/v4/ <- 1619093532.772326: {"time":1619093532,"channel":"spot.candlesticks","event":"subscribe","payload":["1m","DIS_USDT"]}
wss://api.gateio.ws/ws/v4/ <- 1619093532.772394: {"time":1619093532,"channel":"spot.candlesticks","event":"subscribe","payload":["1m","NEO_BTC"]}
wss://api.gateio.ws/ws/v4/ <- 1619093532.772461: {"time":1619093532,"channel":"spot.candlesticks","event":"subscribe","payload":["1m","FAST_USDT"]}
wss://api.gateio.ws/ws/v4/ <- 1619093532.772529: {"time":1619093532,"channel":"spot.candlesticks","event":"subscribe","payload":["1m","ZKS_ETH"]}
wss://api.gateio.ws/ws/v4/ <- 1619093532.772596: {"time":1619093532,"channel":"spot.candlesticks","event":"subscribe","payload":["1m","OMG_USDT"]}
wss://api.gateio.ws/ws/v4/ <- 1619093532.77267: {"time":1619093532,"channel":"spot.tickers","event":"subscribe","payload":["INK_USDT","HAI_ETH","BTC_USDC","NANO_USDT","QTUM3S_USDT","DIS_USDT","NEO_BTC","FAST_USDT","ZKS_ETH","OMG_USDT"]}
1619093532.9598699: {"time":1619093532,"channel":"spot.trades","event":"subscribe","result":{"status":"success"}}
1619093532.9599402: {"time":1619093532,"channel":"spot.order_book_update","event":"subscribe","result":{"status":"success"}}
1619093532.9599612: {"time":1619093532,"channel":"spot.order_book_update","event":"subscribe","result":{"status":"success"}}
1619093532.959975: {"time":1619093532,"channel":"spot.order_book_update","event":"subscribe","result":{"status":"success"}}
1619093532.959987: {"time":1619093532,"channel":"spot.order_book_update","event":"subscribe","result":{"status":"success"}}
1619093532.959998: {"time":1619093532,"channel":"spot.order_book_update","event":"subscribe","result":{"status":"success"}}
1619093532.960015: {"time":1619093532,"channel":"spot.order_book_update","event":"subscribe","result":{"status":"success"}}
1619093532.960026: {"time":1619093532,"channel":"spot.order_book_update","event":"subscribe","result":{"status":"success"}}
1619093532.960053: {"time":1619093532,"channel":"spot.order_book_update","event":"subscribe","result":{"status":"success"}}
1619093532.96006: {"time":1619093532,"channel":"spot.order_book_update","event":"subscribe","result":{"status":"success"}}
1619093532.962128: {"time":1619093532,"channel":"spot.order_book_update","event":"subscribe","result":{"status":"success"}}
1619093532.9621708: {"time":1619093532,"channel":"spot.candlesticks","event":"subscribe","result":{"status":"success"}}
1619093532.962189: {"time":1619093532,"channel":"spot.candlesticks","event":"subscribe","result":{"status":"success"}}
1619093532.962201: {"time":1619093532,"channel":"spot.candlesticks","event":"subscribe","result":{"status":"success"}}
1619093532.962212: {"time":1619093532,"channel":"spot.candlesticks","event":"subscribe","result":{"status":"success"}}
1619093532.96223: {"time":1619093532,"channel":"spot.candlesticks","event":"subscribe","result":{"status":"success"}}
1619093532.962241: {"time":1619093532,"channel":"spot.candlesticks","event":"subscribe","result":{"status":"success"}}
1619093532.9622521: {"time":1619093532,"channel":"spot.candlesticks","event":"subscribe","result":{"status":"success"}}
1619093532.962278: {"time":1619093532,"channel":"spot.candlesticks","event":"subscribe","result":{"status":"success"}}
1619093532.962285: {"time":1619093532,"channel":"spot.candlesticks","event":"subscribe","result":{"status":"success"}}
1619093532.962292: {"time":1619093532,"channel":"spot.candlesticks","event":"subscribe","result":{"status":"success"}}
1619093532.9622982: {"time":1619093532,"channel":"spot.tickers","event":"subscribe","result":{"status":"success"}}
1619093532.995539: {"time":1619093532,"channel":"spot.order_book_update","event":"update","result":{"t":1619093532978,"e":"depthUpdate","E":1619093532,"s":"HAI_ETH","U":2691446,"u":2691446,"b":[["0.00010322","5360.209"],["0.00010276","20.80412499"],["0.00010218","17572.445"],["0.00010135","21747.969"],["0.00010007","2133.418"],["0.00009806","3038.272"],["0.00009609","2363.969"],["0.00009416","2604.776"],["0.00009227","2300.808"],["0.00009042","3775.948"],["0.00008861","3498.846"],["0.00008683","4242.045"],["0.00008509","3998.392"],["0.00008338","3606.274"],["0.00008171","4212.172"],["0.00008007","2559.142"],["0.00007846","3309.097"],["0.00007689","3841.862"],["0.00007535","5144.044"],["0.00007384","2721.047"],["0.00007236","2847.836"],["0.00007091","4415.687"],["0.00006949","5302.878"],["0.0000681","4139.937"],["0.00000532","1879.699"],["0.00000321","3115.264"],["0.0000021","4761.904"],["0.00000106","9433.962"],["0.00000063","15873.015"],["0.00000032","31250"],["0.0000002","50000"],["0.0000001","100000"],["0.00000005","200000"],["0.00000003","333333.333"],["0.00000001","1000000"]],"a":[["0.00010396","5876.967"],["0.0001052","16944.291"],["0.00010605","20939.078"],["0.00010616","20.51071557"],["0.00010677","3586.613"],["0.00010768","20.22164097"],["0.00010888","3124.5"],["0.00010898","3465.441"],["0.00010923","19.93502316"],["0.0001108","19.65280276"],["0.00011116","1916.893"],["0.00011216","2444.223"],["0.00011229","3004.282"],["0.00011238","19.37670519"],["0.00011399","90.2953"],["0.000114","19.10142855"],["0.00011454","3020.812"],["0.00011562","18.83386383"],["0.00011565","3134.613"],["0.0001158","3444.278"],["0.00011581","2308.243"],["0.00011726","18.57046459"],["0.00011813","2139.545"],["0.00011872","1851.76"],["0.00011875","2388.117"],["0.00011881","2641.821"],["0.00011893","18.30962559"],["0.00011897","552.2106"],["0.00012119","2958.132"],["0.00012143","1712.432"],["0.00012386","3012.773"],["0.00012634","2473.157"],["0.00012887","2681.278"],["0.00013145","1652.646"],["0.00018","10000"],["0.00019","4674.85237401"],["0.00025963","25000"],["0.007861","72"]]}}
1619093533.765146: {"time":1619093532,"channel":"spot.order_book_update","event":"update","result":{"t":1619093532988,"e":"depthUpdate","E":1619093532,"s":"QTUM3S_USDT","U":69526943,"u":69526943,"b":[["0.226779","15.48"],["0.225553","3469.02"],["0.223292","22.2015"],["0.221831","15.48"],["0.221589","7801.96"],["0.220237","1860.2968"],["0.218247","4761.35"],["0.216914","4822.17"],["0.216882","15.48"],["0.211934","15.48"],["0.211618","5979.16"],["0.21115","8756.38"],["0.210613","3097.29"],["0.209216","2597.88"],["0.208717","3773.37"],["0.208711","3486.91"],["0.206986","15.48"],["0.203803","1775.64"],["0.202636","7159.96"],["0.202037","15.48"],["0.198117","3419.95"],["0.19801","6758.87"],["0.197089","15.48"],["0.193989","4386.14"],["0.192141","15.48"],["0.187193","15.48"],["0.186024","5491.84"],["0.185253","3382.44"],["0.182244","15.48"],["0.182069","10442.79"],["0.180557","5517.94"],["0.178998","3352.36"],["0.177296","15.48"],["0.177206","5456.22"],["0.173083","5509.64"],["0.173002","6389.29"],["0.172348","15.48"],["0.171729","6313.48"],["0.170472","2413.06"],["0.169674","4885"],["0.167496","5699.85"],["0.1674","15.48"],["0.167179","2944.15"],["0.166057","5179.93"],["0.160364","5056.62"],["0.1288","170.8"],["0.102","215.68"],["0.1","30"],["0.082","268.29"],["0.08","37.5"],["0.06","50"],["0.04","75"],["0.02","150"],["0.01","300"],["0.008","375"],["0.006","500"],["0.004","750"],["0.002","1500"],["0.001","3000"],["0.0008","3750"],["0.0004","7500"],["0.0002","15000"],["0.0001","30000"],["0.00008","37499.99"],["0.00006","50000"],["0.00004","74999.99"],["0.00002","149999.99"],["0.00001","299999.99"],["0.000008","375000"],["0.000006","500000"],["0.000005","200000"],["0.000004","750000"],["0.000003","333333.33"],["0.000002","1500000"],["0.000001","4000000"]],"a":[["0.228734","4225.32"],["0.229291","5869.24"],["0.231375","15887.21"],["0.235959","5032.83"],["0.236675","15.48"],["0.238531","12512.46"],["0.238917","2013.01"],["0.24109","3147.14"],["0.241624","15.48"],["0.242479","6247.94"],["0.244061","8029.5"],["0.244474","1742.59"],["0.246011","6351.63"],["0.246572","15.48"],["0.247425","5289.27"],["0.249002","3450.08"],["0.249705","2393.68"],["0.250513","2893.85"],["0.251405","3120.67"],["0.25152","15.48"],["0.252243","5241.65"],["0.252535","3910.86"],["0.254631","4278.19"],["0.256468","15.48"],["0.256491","374.8992"],["0.259695","1339.7"],["0.261417","15.48"],["0.26215","2690.95"],["0.266365","15.48"],["0.267556","5582.8"],["0.267596","5309.35"],["0.26776","3695.6"],["0.268011","4870.03"],["0.269538","7325.1"],["0.271313","15.48"],["0.273276","1671.19"],["0.275914","2879"],["0.276262","15.48"],["0.278632","3841.24"],["0.28121","15.48"],["0.283373","3199.01"],["0.286158","15.48"],["0.291106","15.48"],["0.296055","15.48"],["0.301003","15.48"],["0.305951","15.48"],["0.3109","15.48"],["0.375","50"],["0.408","50"],["0.505","20"],["0.558","20"],["0.615","20"],["0.630709","1.61"],["0.672","20"],["0.73","10.14"],["0.738","20"],["0.808","20"],["0.888","20"],["1.111","3.992"],["1.731102","1.14"]]}}
1619093533.966201: {"time":1619093533,"channel":"spot.order_book_update","event":"update","result":{"t":1619093533020,"e":"depthUpdate","E":1619093533,"s":"FAST_USDT","U":1130669,"u":1138115,"b":[["10.28","36.50154112"],["10.23","0"],["10.22","0"],["10.21","0.2407"],["10.2","104.043"],["10.17","0"],["10.16","2"],["10.08","0.112"],["10.01","0.4880315"],["10","18.8414"],["9.99","124.449"],["9.98","176.723"],["9.97","147.111"],["9.95","0"],["9.94","99.046521"],["9.9","116.256"],["9.87","46.596"],["9.86","46.78493629"],["9.83","0"],["9.75","0"],["9.7","188.863"],["9.69","134.575"],["9.68","161.871"],["9.66","0"],["9.52","202.708"],["9.51","155.056"],["9.5","131.457"],["9.46","0"],["9.43","0"],["9.42","0"],["9.41","0"],["9.4","0"],["9.31","172.265"],["9.21","0"],["9.12","181.421"],["9.11","0.241"],["9.08","0"],["9.02","0"],["9","1.765"],["8.93","218.145"],["8.83","0"],["8.75","127.437"],["8.65","0"],["8.47","0"],["8.3","0"]],"a":[["10.36","0"],["10.63","5"],["10.69","0"],["10.7","0"],["10.71","0"],["10.72","86.32962138"],["10.79","56.26090596"],["10.8","13.32597"],["10.86","0"],["10.87","0"],["10.88","0"],["10.9","0"],["10.93","0"],["11.13","0"],["11.14","0"],["11.36","32.37142334"],["11.37","106.186"],["11.55","0"],["11.6","119.673"],["12.42","13.975"],["13.35","116.216"],["13.62","89.837"],["13.9","123.99"],["14.18","105.909"],["14.47","95.101"],["19","868.622652"],["20","549.76966"],["46.4","5.879398"],["46.79","0.037"]]}}
1619093534.154552: {"time":1619093533,"channel":"spot.order_book_update","event":"update","result":{"t":1619093533023,"e":"depthUpdate","E":1619093533,"s":"OMG_USDT","U":59231869,"u":59231869,"b":[["7.898","65.888"],["7.897","288"],["7.896","131.569"],["7.89","65.818"],["7.889","131.89"],["7.886","263.201"],["7.885","461.63"],["7.884","28.6"],["7.881","263.417"],["7.877","94.3"],["7.875","2279.247"],["7.872","774.62"],["7.871","855.424"],["7.859","372.161"],["7.855","752.699"],["7.854","848.258"],["7.853","486.087"],["7.84","280.006"],["7.838","1299.106"],["7.828","496.365"],["7.825","5.013"],["7.822","606.946"],["7.821","668.034"],["7.816","331.123"],["7.815","468.468"],["7.807","489.131"],["7.806","0.454"],["7.805","1142.789"],["7.801","152.9783789102"],["7.8","6.411"],["7.796","552.193"],["7.792","278.8"],["7.789","775.882"],["7.781","410.172"],["7.773","872.095"],["7.757","512.986"],["7.748","93.3"],["7.734","1044.296"],["7.733","278.868"],["7.723","5.013"],["7.697","91.2"],["7.689","0.638"],["7.652","321.243"],["7.64","30.3912"],["7.637","22.7992"],["7.621","355.664"],["7.618","331.419"],["7.616","422.938"],["7.615","679.659"],["7.612","429.322"],["7.609","674.712"],["7.606","919.009"],["7.605","349.447"],["7.603","339.892"],["7.602","427.139"],["7.601","703.591"],["7.6","466.832"],["7.598","0.315"],["7.597","380.193"],["7.586","405.396"],["7.585","595.643"],["7.575","100"],["7.57","155.79"],["7.569","783.743"],["7.553","632.608"],["7.537","758.379"],["7.519","5.013"],["7.417","5.013"],["7.416","2.426"],["7.38","0.315"],["7.36","216.398"],["7.314","5.013"],["7.231","28.31635652"],["7.212","5.013"],["7.162","0.315"],["7.11","5.013"],["7.1","48.241"],["7.099","0.338"],["7.008","5.013"],["7","1.571"],["6.998","0.7812"],["6.969","10"],["6.95","196.3"],["6.944","0.315"],["6.911","115.74"],["6.906","5.013"],["6.883","116.21"],["6.869","58.642"],["6.868","116.924"],["6.865","37.285"],["6.863","20.997"],["6.818","20"],["6.804","5.013"],["6.788","100"],["6.726","0.315"],["6.702","5.013"],["6.685","2"],["6.6","5.013"],["6.512","15.356"],["6.424","142.857"]],"a":[["7.927","316.6"],["7.939","94.3"],["7.94","898.109"],["7.941","808.405"],["7.942","981.91"],["7.944","792.813"],["7.956","573.407"],["7.957","991.435"],["7.96","1666.744"],["7.963","635"],["7.966","599.052"],["7.968","802.618"],["7.972","543.428"],["7.976","731.291"],["7.982","424.303"],["7.984","1861.69"],["7.986","301.642"],["7.99","339.036"],["7.992","993.754"],["7.996","409.293"],["7.997","251.8481948663"],["7.998","368.215"],["8","865.825"],["8.003","276"],["8.007","341.02"],["8.008","633.591"],["8.011","0.184"],["8.016","976.847"],["8.022","605.279"],["8.025","898.425"],["8.026","193.081"],["8.029","412.179"],["8.03","340.605"],["8.033","550.473"],["8.034","0.315"],["8.035","351.171"],["8.04","0.454"],["8.042","813.69"],["8.054","401.914"],["8.058","437.104"],["8.059","623.565"],["8.068","362.829"],["8.083","613.275"],["8.096","434.394"],["8.101","577.37"],["8.108","581.385"],["8.131","5.004"],["8.133","518.083"],["8.134","299.008"],["8.158","0.454"],["8.167","388.325"],["8.172","0.184"],["8.179","95.1"],["8.188","483.88"],["8.2","230.961113"],["8.234","5.003"],["8.252","0.315"],["8.275","0.454"],["8.3","0.127"],["8.334","0.184"],["8.336","5.004"],["8.392","0.454"],["8.4","38.766563"],["8.434","1"],["8.438","5.004"],["8.47","0.315"],["8.484","330.861976"],["8.495","0.184"],["8.5","6.771"],["8.505","0.21310307"],["8.51","0.454"],["8.54","5.013"],["8.627","0.454"],["8.642","5.013"],["8.649","299.623"],["8.656","0.184"],["8.688","0.315"],["8.744","5.467"],["8.799","36.00524961"],["8.8","962.923702"],["8.818","0.184"],["8.822","91.329892"],["8.846","5.013"],["8.862","0.454"],["8.875","23.211288"],["8.907","0.315"],["8.948","5.013"],["8.979","0.638"],["9","282.658823"],["9.051","10.026"],["9.096","0.454"],["9.125","0.315"],["9.14","0.184"],["9.153","5.013"],["9.2","51.469"],["9.214","0.454"],["9.255","5.013"],["9.302","0.184"],["9.331","0.454"],["9.343","0.315"]]}}
1619093534.348201: {"time":1619093533,"channel":"spot.order_book_update","event":"update","result":{"t":1619093533031,"e":"depthUpdate","E":1619093533,"s":"ZKS_ETH","U":11077661,"u":11077661,"b":[["0.001005","50.29"],["0.001001","423.873626"],["0.000986","4.996434"],["0.000981","369.322"],["0.00098","326.549"],["0.000978","371.801"],["0.000977","247.897"],["0.000975","298.478"],["0.000973","5.166414"],["0.000955","378.327"],["0.000935","388.733"],["0.000916","383.752"],["0.000897","293.607"],["0.000879","351.669"],["0.000861","411.266"],["0.000843","297.763"],["0.000809","298.607"],["0.000792","319.189"],["0.000783","6.385"],["0.000776","417.82"],["0.00076","355.527"],["0.000744","514.547"],["0.000729","369.199"],["0.000714","387.796"],["0.000699","563.052"],["0.000401","24.937"],["0.0004","38.44"],["0.000364","27.472"],["0.00021","47.619"],["0.000106","94.339"],["0.000063","158.73"],["0.000032","312.5"],["0.000011","909.09"],["0.00001063","940.733"],["0.000007","1428.571"],["0.00000632","1582.278"],["0.000002","5000"],["0.00000063","15873.015"],["0.00000032","31250"],["0.0000002","50000"],["0.0000001","100000"],["0.00000001","1000000"]],"a":[["0.001038","453.60214"],["0.001049","4.842781"],["0.001057","4.610919"],["0.001122","303.538"],["0.001143","274.738"],["0.001164","302.493"],["0.001186","253.473"],["0.001208","238.504"],["0.001209","187.058"],["0.001232","209.456"],["0.001255","228.135"],["0.001278","171.961"],["0.001283","242.893"],["0.001287","644.585"],["0.001295","724.674"],["0.001308","270.889"],["0.001332","233.507"],["0.001359","290.484"],["0.001362","160.599"],["0.001388","270.381"],["0.001395","644.585"],["0.001397","654.669"],["0.001414","324.79312"],["0.001415","271.458"],["0.001416","237.053"],["0.00142","144.115"],["0.001436","216.322"],["0.001465","271.345"],["0.001498","777.158"],["0.001509","33.001"],["0.001528","33.001"],["0.001547","33.001"],["0.001561","858"],["0.001567","33.001"],["0.001581","63.69"],["0.001586","33.001"],["0.001605","33.001"],["0.001624","33.001"],["0.001644","33.001"],["0.001654","55.822"],["0.001663","0.00074258"],["0.001672","600"],["0.001682","33.001"],["0.001693","688.776"],["0.001702","33.001"],["0.001721","33.001"],["0.001724","70.059"],["0.00174","33.001"],["0.001759","33.001"],["0.001779","33.001"],["0.001793","918.368"],["0.001798","33.001"],["0.001801","61.405"],["0.001817","33.001"],["0.001837","33.001"],["0.001856","33.001"],["0.001875","33.001"],["0.00188","77.065"],["0.001894","33.001"],["0.00191","35"],["0.001914","33.001"],["0.001933","33.001"],["0.001952","33.001"],["0.001956","289.266"],["0.00196","67.545"],["0.001972","33.001"],["0.002049","5.124"],["0.00205","84.772"],["0.002134","74.3"],["0.002195","434.56"],["0.002217","440.67"],["0.002236","93.249"],["0.002322","81.729"],["0.002383","832.026"],["0.0024","35"],["0.002428","15"],["0.002439","102.574"],["0.002528","89.902"],["0.00266","112.831"],["0.002736","545.183"],["0.002752","98.893"],["0.0029","124.114"],["0.002957","485.872"],["0.002996","108.782"],["0.00305","9.535"],["0.003163","136.526"],["0.00326","95.289"],["0.003261","119.66"],["0.003262","100.311"],["0.003295","491.94"],["0.003296","89.1297"],["0.003369","569.386"],["0.00345","150.178"],["0.00355","131.626"],["0.003681","1.415"],["0.003746","656.909"],["0.003808","627.94"],["0.003899","55.109"],["0.003957","916.429"],["0.003958","960.898"]]}}
1619093534.5403242: {"time":1619093533,"channel":"spot.tickers","event":"update","result":{"currency_pair":"NEO_BTC","last":"0.0018716","lowest_ask":"0.0018734","highest_bid":"0.0018697","change_percentage":"2.9256","base_volume":"1138.01640718","quote_volume":"2.048263365803126","high_24h":"0.0018754","low_24h":"0.0017148"}}
1619093534.540363: {"time":1619093533,"channel":"spot.order_book_update","event":"update","result":{"t":1619093533086,"e":"depthUpdate","E":1619093533,"s":"NEO_BTC","U":31244061,"u":31244061,"b":[["0.0018697","0.5"],["0.0018678","0.5"],["0.0018659","0.5"],["0.0018412","0.109"],["0.0018177","7.851"],["0.0018172","0.109"],["0.0017932","0.109"],["0.0017813","5.649"],["0.0017793","8.089"],["0.0017781","0.363"],["0.0017691","0.109"],["0.0017451","0.109"],["0.0017437","7.621"],["0.0017363","7.098"],["0.0017355","10.787"],["0.001734","11.516"],["0.0017329","9.688"],["0.0017315","9.04260734"],["0.0017211","0.109"],["0.001697","0.109"],["0.0016968","6.057"],["0.0016951","9.1"],["0.0016934","11.126"],["0.0016922","7.929"],["0.0016904","9.82"],["0.0016896","9.568"],["0.001688","7.864"],["0.0016861","6.009"],["0.0016851","8.079"],["0.0016841","10.156"],["0.0016833","10.552"],["0.001673","0.109"],["0.0016489","0.109"],["0.0016249","0.109"],["0.0016009","0.109"],["0.0015768","0.109"],["0.0015528","0.109"],["0.0015288","0.109"],["0.0015047","0.109"],["0.001504","0.5"],["0.0014807","0.109"],["0.0014567","0.109"],["0.0014326","0.109"],["0.0014086","0.109"],["0.0014","0.089"],["0.0013846","0.109"],["0.0013605","0.109"],["0.00135","0.09"],["0.0013365","0.109"],["0.0013124","0.109"],["0.0013","0.1"],["0.0012884","0.109"],["0.0012644","0.109"],["0.0012403","0.109"],["0.0012163","0.109"],["0.0011923","0.109"],["0.0011682","0.109"],["0.0011442","0.109"],["0.0011202","0.109"],["0.0010961","0.109"],["0.0010721","0.109"],["0.0010481","0.109"],["0.001024","0.109"],["0.001","0.109"],["0.000976","0.109"],["0.00095","1"],["0.0009","1"],["0.00085","1"],["0.0008","1"],["0.00075","1"],["0.0007","1"],["0.00065","1"],["0.000603","0.995"],["0.0006","1"],["0.00055","1"],["0.0005","1"],["0.0004","0.937"],["0.000127","3.937"],["0.0001001","4.995"],["0.0001","1"],["0.0000891","5.611"],["0.000089","3"],["0.0000503","9.94"],["0.00004802","10.412"],["0.00004601","10.867"],["0.000046","6"],["0.00002401","20.824"],["0.000024","10"],["0.00002111","23.685"],["0.0000148","33.783"],["0.0000111","45.045"],["0.00000895","55.865"],["0.0000089","30"],["0.00000465","107.526"],["0.0000046","60"],["0.0000025","200"],["0.0000024","100"],["0.000001","500"],["0.00000089","300"],["0.0000005","1000"]],"a":[["0.0018734","5.084"],["0.0018735","0.5"],["0.0018754","0.0293258"],["0.0018773","0.5"],["0.0018792","0.5"],["0.0018811","0.5"],["0.001883","0.5"],["0.0018849","0.5"],["0.0018868","0.5"],["0.0018887","0.5"],["0.0018893","0.109"],["0.0018906","0.5"],["0.0018925","0.5"],["0.0018944","0.5"],["0.0018963","0.5"],["0.0018982","0.5"],["0.0019002","0.5"],["0.0019022","0.5"],["0.0019042","0.5"],["0.0019062","0.5"],["0.0019073","7.338"],["0.0019082","0.5"],["0.0019102","0.5"],["0.0019122","0.5"],["0.0019133","0.109"],["0.0019142","0.5"],["0.0019162","0.5"],["0.0019182","0.5"],["0.0019202","0.5"],["0.0019222","0.5"],["0.0019242","0.5"],["0.0019262","0.5"],["0.0019282","0.5"],["0.0019302","0.5"],["0.0019322","0.5"],["0.0019342","0.5"],["0.0019362","0.5"],["0.0019374","0.109"],["0.0019382","0.5"],["0.0019402","0.5"],["0.0019422","0.5"],["0.0019442","0.5"],["0.0019455","6.915"],["0.001946","6.31"],["0.0019462","0.5"],["0.0019482","0.5"],["0.0019502","0.5"],["0.0019522","0.5"],["0.0019542","0.5"],["0.0019562","0.5"],["0.0019582","0.5"],["0.0019602","0.5"],["0.0019614","0.109"],["0.0019622","0.5"],["0.0019642","0.5"],["0.0019662","0.5"],["0.0019682","0.042"],["0.0019702","0.5"],["0.0019722","0.5"],["0.0019742","0.5"],["0.0019762","0.5"],["0.0019782","0.5"],["0.0019802","0.5"],["0.0019822","0.5"],["0.0019842","0.5"],["0.001985","5.381"],["0.0019854","0.109"],["0.0019862","0.5"],["0.0019882","0.5"],["0.0019902","0.5"],["0.0019922","0.5"],["0.0019942","0.5"],["0.0019962","0.5"],["0.0019982","0.5"],["0.0020003","0.5"],["0.0020024","0.5"],["0.0020045","0.5"],["0.0020066","0.5"],["0.0020087","0.5"],["0.0020095","0.109"],["0.0020108","0.5"],["0.0020129","0.5"],["0.002015","0.5"],["0.0020171","0.5"],["0.0020192","0.5"],["0.0020213","0.5"],["0.0020234","0.151691"],["0.0020247","9.47"],["0.0020255","0.5"],["0.0020276","0.5"],["0.0020297","0.5"],["0.0020318","0.5"],["0.0020335","0.109"],["0.0020339","0.5"],["0.002036","0.5"],["0.0020381","0.5"],["0.0020402","0.5"],["0.0020423","0.5"],["0.0020444","0.5"],["0.0020465","0.5"]]}}
1619093534.733676: {"time":1619093533,"channel":"spot.order_book_update","event":"update","result":{"t":1619093533115,"e":"depthUpdate","E":1619093533,"s":"INK_USDT","U":2509482,"u":2509482,"b":[["0.0028144","64918.872"],["0.0028143","14852"],["0.0028139","6025.5935054"],["0.0028008","3218.078"],["0.0027891","670556.995"],["0.002766","3000"],["0.0027659","1000"],["0.0027273","1000000"],["0.0027","38346.181"],["0.0026888","2000"],["0.0026381","18953.034"],["0.0025454","10124.4"],["0.0025","12880"],["0.0023164","566517.824"],["0.0022954","2000"],["0.0022121","874.79"],["0.0022","59645.454"],["0.0017501","31000"],["0.0015151","10000"],["0.00151","20000"],["0.0012121","3000"],["0.0012054","57242.409"],["0.0010606","3000"],["0.001","101000"],["0.0009724","68000"],["0.0009055","42000"],["0.000817","1906.152"],["0.0008165","54914.59504"],["0.0007575","60000"],["0.00072","3500"],["0.0007","3000"],["0.00069","1500"],["0.00062","1500"],["0.0005861","196613.461"],["0.0005454","773589.094"],["0.0005","35000"],["0.0004","67216.69"],["0.0002","5000"],["0.000102","1200000"],["0.0001002","9980.039"],["0.0001","132666.6666"],["0.0000501","19960.079"],["0.0000132","5075757.575"],["0.0000032","312500"],["0.000002","500000"],["0.000001","1000000"],["0.0000005","2000000"],["0.0000001","10000000"]],"a":[["0.0029543","70737.25"],["0.0029544","21154"],["0.0029683","2975.653"],["0.003","8902.795941"],["0.0033","7722.938508"],["0.0035389","12989.48"],["0.004","3967.186"],["0.0040909","132637.967"],["0.0042688","212605.36353"],["0.0042886","56727.009453"],["0.0042888","11477"],["0.0043888","205324.916876"],["0.0045","32351.147102"],["0.0045578","350247.746093"],["0.0046343","1044.779"],["0.004841","2461.9584"],["0.0049","6029.916"],["0.005","7120.532"],["0.0055415","2114.711532"],["0.0057575","32703.0252"],["0.0059999","11166.199926"],["0.006","58155.62485556"],["0.0060606","698569.687"],["0.0061","29616.079108195"],["0.0061999","100000"],["0.0062","122882.424716"],["0.0064","10000"],["0.006432","5670.086"],["0.0065","23261.092"],["0.0066666","13354.71"],["0.0067","10000"],["0.0068","27550.049"],["0.00689","100649.5"],["0.007","15349.556"],["0.0072","21932.288"],["0.0075","15000"],["0.0077","17198.102"],["0.0077777","10016.03"],["0.0078","151620.32"],["0.008","8233.742"],["0.0081061","79221"],["0.0082","20000"],["0.0084","10000"],["0.0085","10000"],["0.00869","8302.67"],["0.0087","1149.425"],["0.0088","59700.399"],["0.0088888","7512.02"],["0.00891","998"],["0.009","10121.489"],["0.0090909","9754.39"],["0.0091","10000"],["0.0092","50000"],["0.0094","70000"],["0.0095","40000"],["0.0095337","5444.999"],["0.0097","50000"],["0.0098","10000"],["0.009898","3500"],["0.01","110175.538"],["0.0100756","3345.973"],["0.0101","15928.712"],["0.0102","20000"],["0.0104","10000"],["0.0105","13457.402"],["0.010666","3648.125"],["0.0107","10000"],["0.0107535","10892"],["0.01079","1386.495"],["0.0108","10103"],["0.011","10000"],["0.0111","20000"],["0.0112","10000"],["0.0114","10000"],["0.0117","20000"],["0.0118","10698.4"],["0.0119","5126.05"],["0.012","66136.775512"],["0.0121","10000"],["0.012106","251794.5733"],["0.0122","30000"],["0.0124","12145.04"],["0.0125","32864"],["0.013","10726.026"],["0.0132","3780.302"],["0.0133","1127.819"],["0.0134","10000"],["0.013408","8043.126"],["0.0136","9711.762"],["0.0136363","10000"],["0.0139393","10000"],["0.014","20000"],["0.0140828","3540.011"],["0.0142","350"],["0.0142424","10000"],["0.0143626","2136.97"],["0.0144","3466.144"],["0.0145454","10000"],["0.0148","13660.717"],["0.0148484","10000"]]}}
1619093534.9237309: {"time":1619093533,"channel":"spot.order_book_update","event":"update","result":{"t":1619093533174,"e":"depthUpdate","E":1619093533,"s":"QTUM3S_USDT","U":69526944,"u":69526951,"b":[["0.216914","0"],["0.215708","2585.43"],["0.208711","0"],["0.202164","4674.47"]],"a":[["0.231375","0"],["0.268011","0"],["0.271111","12002.94"],["0.290094","6585.26"]]}}
1619093534.9237618: {"time":1619093533,"channel":"spot.order_book_update","event":"update","result":{"t":1619093533661,"e":"depthUpdate","E":1619093533,"s":"OMG_USDT","U":59231870,"u":59231873,"b":[["7.892","65.675"],["7.89","0"],["7.878","2185.647"],["7.875","0"]],"a":[]}}
1619093534.9238489: {"time":1619093533,"channel":"spot.order_book_update","event":"update","result":{"t":1619093533953,"e":"depthUpdate","E":1619093533,"s":"NEO_BTC","U":31244062,"u":31244064,"b":[],"a":[["0.0018734","0"],["0.0020486","0.5"]]}}
1619093534.923867: {"time":1619093534,"channel":"spot.candlesticks","event":"update","result":{"t":"1619093520","v":"0","c":"120.92","h":"120.92","l":"120.92","o":"120.92","n":"1m_DIS_USDT"}}
1619093534.923904: {"time":1619093534,"channel":"spot.candlesticks","event":"update","result":{"t":"1619093520","v":"0","c":"0.0018716","h":"0.0018716","l":"0.0018716","o":"0.0018716","n":"1m_NEO_BTC"}}
1619093534.9239302: {"time":1619093534,"channel":"spot.candlesticks","event":"update","result":{"t":"1619093520","v":"20.54344","c":"10.46","h":"10.46","l":"10.46","o":"10.46","n":"1m_FAST_USDT"}}
1619093534.9239528: {"time":1619093534,"channel":"spot.candlesticks","event":"update","result":{"t":"1619093520","v":"0","c":"0.001028","h":"0.001028","l":"0.001028","o":"0.001028","n":"1m_ZKS_ETH"}}
1619093534.923976: {"time":1619093534,"channel":"spot.candlesticks","event":"update","result":{"t":"1619093520","v":"0","c":"0.0027759","h":"0.0027759","l":"0.0027759","o":"0.0027759","n":"1m_INK_USDT"}}
1619093534.923997: {"time":1619093534,"channel":"spot.candlesticks","event":"update","result":{"t":"1619093520","v":"3.8010752","c":"8.8192","h":"8.8192","l":"8.8192","o":"8.8192","n":"1m_NANO_USDT"}}
1619093534.924018: {"time":1619093534,"channel":"spot.candlesticks","event":"update","result":{"t":"1619093520","v":"0","c":"0.00010346","h":"0.00010346","l":"0.00010346","o":"0.00010346","n":"1m_HAI_ETH"}}
1619093534.9240398: {"time":1619093534,"channel":"spot.candlesticks","event":"update","result":{"t":"1619093520","v":"0","c":"55251.44","h":"55251.44","l":"55251.44","o":"55251.44","n":"1m_BTC_USDC"}}
1619093534.9240608: {"time":1619093534,"channel":"spot.candlesticks","event":"update","result":{"t":"1619093520","v":"0","c":"0.230168","h":"0.230168","l":"0.230168","o":"0.230168","n":"1m_QTUM3S_USDT"}}
1619093534.924083: {"time":1619093534,"channel":"spot.candlesticks","event":"update","result":{"t":"1619093520","v":"0","c":"7.915","h":"7.915","l":"7.915","o":"7.915","n":"1m_OMG_USDT"}}
1619093534.924105: {"time":1619093534,"channel":"spot.tickers","event":"update","result":{"currency_pair":"NEO_BTC","last":"0.0018716","lowest_ask":"0.0018735","highest_bid":"0.0018697","change_percentage":"2.9256","base_volume":"1138.01640718","quote_volume":"2.048263365803126","high_24h":"0.0018754","low_24h":"0.0017148"}}
1619093534.924125: {"time":1619093534,"channel":"spot.order_book_update","event":"update","result":{"t":1619093534182,"e":"depthUpdate","E":1619093534,"s":"NEO_BTC","U":31244065,"u":31244065,"b":[],"a":[["0.0018734","5.084"],["0.0020486","0"]]}}
1619093534.924139: {"time":1619093534,"channel":"spot.order_book_update","event":"update","result":{"t":1619093534441,"e":"depthUpdate","E":1619093534,"s":"QTUM3S_USDT","U":69526952,"u":69526959,"b":[["0.214932","7871.91"],["0.21115","0"],["0.205578","3698.87"],["0.169674","0"]],"a":[["0.229291","0"],["0.278632","0"],["0.289862","3886.59"],["0.293693","3842.57"]]}}
1619093534.962755: {"time":1619093534,"channel":"spot.order_book_update","event":"update","result":{"t":1619093534945,"e":"depthUpdate","E":1619093534,"s":"NEO_BTC","U":31244066,"u":31244066,"b":[["0.0018697","5.37064"]],"a":[]}}
1619093535.055263: {"time":1619093535,"channel":"spot.tickers","event":"update","result":{"currency_pair":"OMG_USDT","last":"7.915","lowest_ask":"7.927","highest_bid":"7.899","change_percentage":"5.85","base_volume":"27799.8390372666","quote_volume":"215375.1010537074991","high_24h":"8.44","low_24h":"7.364"}}
1619093535.0575402: {"time":1619093535,"channel":"spot.tickers","event":"update","result":{"currency_pair":"NEO_BTC","last":"0.0018716","lowest_ask":"0.0018734","highest_bid":"0.0018697","change_percentage":"2.9256","base_volume":"1138.01640718","quote_volume":"2.048263365803126","high_24h":"0.0018754","low_24h":"0.0017148"}}
1619093535.0634398: {"time":1619093535,"channel":"spot.order_book_update","event":"update","result":{"t":1619093535048,"e":"depthUpdate","E":1619093535,"s":"NEO_BTC","U":31244067,"u":31244069,"b":[["0.0018697","0.5"]],"a":[]}}
1619093535.214025: {"time":1619093535,"channel":"spot.order_book_update","event":"update","result":{"t":1619093535198,"e":"depthUpdate","E":1619093535,"s":"OMG_USDT","U":59231874,"u":59231876,"b":[["7.899","1.2"],["6.424","0"]],"a":[]}}
1619093535.58812: {"time":1619093535,"channel":"spot.order_book_update","event":"update","result":{"t":1619093535554,"e":"depthUpdate","E":1619093535,"s":"OMG_USDT","U":59231877,"u":59231877,"b":[["7.899","0"],["6.424","142.857"]],"a":[]}}
1619093535.619532: {"time":1619093535,"channel":"spot.order_book_update","event":"update","result":{"t":1619093535601,"e":"depthUpdate","E":1619093535,"s":"DIS_USDT","U":1750469,"u":1750469,"b":[],"a":[["122","0"],["163.68","0.024"]]}}
1619093535.807075: {"time":1619093535,"channel":"spot.order_book_update","event":"update","result":{"t":1619093535779,"e":"depthUpdate","E":1619093535,"s":"ZKS_ETH","U":11077662,"u":11077662,"b":[["0.001005","88.613"]],"a":[]}}
1619093535.890193: {"time":1619093535,"channel":"spot.order_book_update","event":"update","result":{"t":1619093535873,"e":"depthUpdate","E":1619093535,"s":"QTUM3S_USDT","U":69526960,"u":69526967,"b":[["0.222313","3034.62"],["0.201747","6407.65"],["0.193989","0"],["0.166057","0"]],"a":[["0.24109","0"],["0.243195","4044.15"],["0.262328","5007.91"],["0.267556","0"]]}}
1619093536.0507882: {"time":1619093536,"channel":"spot.tickers","event":"update","result":{"currency_pair":"DIS_USDT","last":"120.92","lowest_ask":"122.36","highest_bid":"120.92","change_percentage":"-2.75","base_volume":"445.7202426988","quote_volume":"53729.49781346942","high_24h":"142.51","low_24h":"112.82"}}
1619093536.052219: {"time":1619093536,"channel":"spot.tickers","event":"update","result":{"currency_pair":"OMG_USDT","last":"7.915","lowest_ask":"7.927","highest_bid":"7.898","change_percentage":"5.85","base_volume":"27799.8390372666","quote_volume":"215375.1010537074991","high_24h":"8.44","low_24h":"7.364"}}
1619093536.7933881: {"time":1619093536,"channel":"spot.order_book_update","event":"update","result":{"t":1619093536691,"e":"depthUpdate","E":1619093536,"s":"OMG_USDT","U":59231878,"u":59231878,"b":[["7.899","4.199"],["6.424","0"]],"a":[]}}
1619093536.793548: {"time":1619093536,"channel":"spot.order_book_update","event":"update","result":{"t":1619093536756,"e":"depthUpdate","E":1619093536,"s":"OMG_USDT","U":59231879,"u":59231879,"b":[["7.899","0"],["6.424","142.857"]],"a":[]}}
1619093536.885453: {"time":1619093536,"channel":"spot.order_book_update","event":"update","result":{"t":1619093536855,"e":"depthUpdate","E":1619093536,"s":"OMG_USDT","U":59231880,"u":59231880,"b":[["7.899","6"],["6.424","0"]],"a":[]}}
1619093537.05998: {"time":1619093537,"channel":"spot.tickers","event":"update","result":{"currency_pair":"OMG_USDT","last":"7.915","lowest_ask":"7.927","highest_bid":"7.899","change_percentage":"5.85","base_volume":"27799.8390372666","quote_volume":"215375.1010537074991","high_24h":"8.44","low_24h":"7.364"}}
1619093537.085967: {"time":1619093537,"channel":"spot.order_book_update","event":"update","result":{"t":1619093537069,"e":"depthUpdate","E":1619093537,"s":"QTUM3S_USDT","U":69526968,"u":69526975,"b":[["0.204182","2108.65"],["0.19801","0"],["0.172484","3059.05"],["0.170472","0"]],"a":[["0.23615","3229.32"],["0.243388","10555.87"],["0.269538","0"],["0.275914","0"]]}}
1619093537.1103191: {"time":1619093537,"channel":"spot.order_book_update","event":"update","result":{"t":1619093537094,"e":"depthUpdate","E":1619093537,"s":"OMG_USDT","U":59231881,"u":59231883,"b":[["7.899","0.899"],["7.881","0"],["6.424","142.857"]],"a":[]}}
1619093537.2167208: {"time":1619093537,"channel":"spot.order_book_update","event":"update","result":{"t":1619093537200,"e":"depthUpdate","E":1619093537,"s":"NEO_BTC","U":31244070,"u":31244070,"b":[],"a":[["0.0019073","0"],["0.0020486","0.5"]]}}
1619093537.279425: {"time":1619093537,"channel":"spot.order_book_update","event":"update","result":{"t":1619093537263,"e":"depthUpdate","E":1619093537,"s":"OMG_USDT","U":59231884,"u":59231884,"b":[["7.882","263.327"],["6.424","0"]],"a":[]}}
1619093537.3514009: {"time":1619093537,"channel":"spot.order_book_update","event":"update","result":{"t":1619093537334,"e":"depthUpdate","E":1619093537,"s":"OMG_USDT","U":59231885,"u":59231885,"b":[["7.896","0"],["6.424","142.857"]],"a":[]}}
1619093538.034828: {"time":1619093538,"channel":"spot.order_book_update","event":"update","result":{"t":1619093538016,"e":"depthUpdate","E":1619093538,"s":"FAST_USDT","U":1138116,"u":1138117,"b":[["10","0"]],"a":[["10.79","54.37290596"]]}}
1619093538.041279: {"time":1619093538,"channel":"spot.order_book_update","event":"update","result":{"t":1619093538019,"e":"depthUpdate","E":1619093538,"s":"OMG_USDT","U":59231886,"u":59231889,"b":[["7.899","0"],["7.897","419.55"],["6.36","238"]],"a":[]}}
1619093538.663876: {"time":1619093538,"channel":"spot.order_book_update","event":"update","result":{"t":1619093538647,"e":"depthUpdate","E":1619093538,"s":"QTUM3S_USDT","U":69526976,"u":69526979,"b":[["0.198606","7529.54"],["0.164422","8583.65"]],"a":[["0.233883","6171.95"],["0.256202","2705.25"]]}}
1619093538.675104: {"time":1619093538,"channel":"spot.order_book_update","event":"update","result":{"t":1619093538656,"e":"depthUpdate","E":1619093538,"s":"FAST_USDT","U":1138118,"u":1138120,"b":[["10.01","0"],["10","18.8414"]],"a":[["11.36","28.27455094"]]}}
1619093538.7825332: {"time":1619093538,"channel":"spot.order_book_update","event":"update","result":{"t":1619093538766,"e":"depthUpdate","E":1619093538,"s":"HAI_ETH","U":2691447,"u":2691448,"b":[["0.00010322","0"]],"a":[["0.00010396","0"]]}}
1619093538.8933198: {"time":1619093538,"channel":"spot.order_book_update","event":"update","result":{"t":1619093538875,"e":"depthUpdate","E":1619093538,"s":"HAI_ETH","U":2691449,"u":2691452,"b":[["0.00010335","5997.415"]],"a":[["0.00010408","6120.906"]]}}
1619093538.92492: {"time":1619093538,"channel":"spot.order_book_update","event":"update","result":{"t":1619093538908,"e":"depthUpdate","E":1619093538,"s":"FAST_USDT","U":1138121,"u":1138121,"b":[],"a":[["10.78","1.888"],["46.79","0"]]}}
1619093538.9255302: {"time":1619093538,"channel":"spot.order_book_update","event":"update","result":{"t":1619093538909,"e":"depthUpdate","E":1619093538,"s":"OMG_USDT","U":59231890,"u":59231891,"b":[["7.886","724.741"],["7.885","0"],["6.3","61.746"]],"a":[]}}
1619093539.0533462: {"time":1619093539,"channel":"spot.tickers","event":"update","result":{"currency_pair":"OMG_USDT","last":"7.915","lowest_ask":"7.927","highest_bid":"7.898","change_percentage":"5.85","base_volume":"27799.8390372666","quote_volume":"215375.1010537074991","high_24h":"8.44","low_24h":"7.364"}}
1619093539.4565902: {"time":1619093539,"channel":"spot.order_book_update","event":"update","result":{"t":1619093539335,"e":"depthUpdate","E":1619093539,"s":"FAST_USDT","U":1138122,"u":1138122,"b":[],"a":[["10.71","4.0968724"],["46.4","0"]]}}
1619093539.65473: {"time":1619093539,"channel":"spot.order_book_update","event":"update","result":{"t":1619093539636,"e":"depthUpdate","E":1619093539,"s":"FAST_USDT","U":1138123,"u":1138123,"b":[["10.2","104.5310315"]],"a":[]}}
1619093539.8378491: {"time":1619093539,"channel":"spot.order_book_update","event":"update","result":{"t":1619093539822,"e":"depthUpdate","E":1619093539,"s":"QTUM3S_USDT","U":69526980,"u":69526981,"b":[["0.225236","3893.96"]],"a":[["0.228413","7500.78"]]}}
1619093540.1711638: {"time":1619093540,"channel":"spot.order_book_update","event":"update","result":{"t":1619093540131,"e":"depthUpdate","E":1619093540,"s":"NEO_BTC","U":31244071,"u":31244073,"b":[],"a":[["0.0018732","5.24738"],["0.0020486","0"]]}}
1619093540.333429: {"time":1619093540,"channel":"spot.order_book_update","event":"update","result":{"t":1619093540315,"e":"depthUpdate","E":1619093540,"s":"NEO_BTC","U":31244074,"u":31244075,"b":[],"a":[["0.0018732","0"],["0.0020486","0.5"]]}}
1619093540.5015092: {"time":1619093540,"channel":"spot.order_book_update","event":"update","result":{"t":1619093540484,"e":"depthUpdate","E":1619093540,"s":"OMG_USDT","U":59231892,"u":59231892,"b":[["7.892","0"],["6.258","0.24"]],"a":[]}}
1619093540.630938: {"time":1619093540,"channel":"spot.order_book_update","event":"update","result":{"t":1619093540613,"e":"depthUpdate","E":1619093540,"s":"OMG_USDT","U":59231893,"u":59231893,"b":[["7.891","65.72"],["6.258","0"]],"a":[]}}
1619093540.806925: {"time":1619093540,"channel":"spot.order_book_update","event":"update","result":{"t":1619093540791,"e":"depthUpdate","E":1619093540,"s":"NEO_BTC","U":31244076,"u":31244076,"b":[["0.0018461","22.5"],["0.0000005","0"]],"a":[]}}
1619093541.0941162: {"time":1619093541,"channel":"spot.order_book_update","event":"update","result":{"t":1619093541029,"e":"depthUpdate","E":1619093541,"s":"QTUM3S_USDT","U":69526982,"u":69526982,"b":[["0.220237","0"]],"a":[]}}
1619093541.2409909: {"time":1619093541,"channel":"spot.order_book_update","event":"update","result":{"t":1619093541223,"e":"depthUpdate","E":1619093541,"s":"OMG_USDT","U":59231894,"u":59231895,"b":[["7.891","65.545"]],"a":[]}}
1619093541.34602: {"time":1619093541,"channel":"spot.order_book_update","event":"update","result":{"t":1619093541330,"e":"depthUpdate","E":1619093541,"s":"QTUM3S_USDT","U":69526983,"u":69526983,"b":[["0.22759","1860.2968"]],"a":[]}}
1619093541.818066: {"time":1619093541,"channel":"spot.order_book_update","event":"update","result":{"t":1619093541798,"e":"depthUpdate","E":1619093541,"s":"NEO_BTC","U":31244077,"u":31244077,"b":[],"a":[["0.0018734","10.33138"]]}}
1619093542.3218648: {"time":1619093542,"channel":"spot.order_book_update","event":"update","result":{"t":1619093542217,"e":"depthUpdate","E":1619093542,"s":"OMG_USDT","U":59231896,"u":59231896,"b":[["7.882","0"],["6.258","0.24"]],"a":[]}}
1619093542.322028: {"time":1619093542,"channel":"spot.order_book_update","event":"update","result":{"t":1619093542289,"e":"depthUpdate","E":1619093542,"s":"NEO_BTC","U":31244078,"u":31244080,"b":[],"a":[["0.0018734","5.084"]]}}
1619093542.407136: {"time":1619093542,"channel":"spot.order_book_update","event":"update","result":{"t":1619093542391,"e":"depthUpdate","E":1619093542,"s":"OMG_USDT","U":59231897,"u":59231897,"b":[["7.883","263.375"],["6.258","0"]],"a":[]}}
1619093542.848963: {"time":1619093542,"channel":"spot.order_book_update","event":"update","result":{"t":1619093542833,"e":"depthUpdate","E":1619093542,"s":"OMG_USDT","U":59231898,"u":59231899,"b":[["7.889","0"],["7.886","461.54"],["6.258","0.24"]],"a":[]}}
1619093542.9350479: {"time":1619093542,"channel":"spot.order_book_update","event":"update","result":{"t":1619093542902,"e":"depthUpdate","E":1619093542,"s":"OMG_USDT","U":59231900,"u":59231901,"b":[["7.891","197.409"],["7.887","263.114"],["6.258","0"]],"a":[]}}
1619093543.448183: {"time":1619093543,"channel":"spot.order_book_update","event":"update","result":{"t":1619093543326,"e":"depthUpdate","E":1619093543,"s":"ZKS_ETH","U":11077663,"u":11077663,"b":[["0.001005","50.29"]],"a":[]}}
1619093543.755753: {"time":1619093543,"channel":"spot.trades","event":"update","result":{"id":816995772,"create_time":1619093543,"create_time_ms":"1619093543708.2642","side":"sell","currency_pair":"DIS_USDT","amount":"0.2010000000","price":"121.5800000000"}}
1619093543.755849: {"time":1619093543,"channel":"spot.order_book_update","event":"update","result":{"t":1619093543731,"e":"depthUpdate","E":1619093543,"s":"QTUM3S_USDT","U":69526984,"u":69526984,"b":[],"a":[["0.228413","12681.24"]]}}
1619093543.802228: {"time":1619093543,"channel":"spot.order_book_update","event":"update","result":{"t":1619093543784,"e":"depthUpdate","E":1619093543,"s":"ZKS_ETH","U":11077664,"u":11077664,"b":[["0.001005","289.221"]],"a":[]}}
1619093544.1658208: {"time":1619093544,"channel":"spot.tickers","event":"update","result":{"currency_pair":"DIS_USDT","last":"121.58","lowest_ask":"122.36","highest_bid":"120.92","change_percentage":"-2.2192","base_volume":"445.9212426988","quote_volume":"53753.93539346942","high_24h":"142.51","low_24h":"112.82"}}
1619093544.881406: {"time":1619093544,"channel":"spot.order_book_update","event":"update","result":{"t":1619093544762,"e":"depthUpdate","E":1619093544,"s":"DIS_USDT","U":1750470,"u":1750472,"b":[],"a":[["122.59","0"],["163.77","1"]]}}
1619093545.18624: {"time":1619093545,"channel":"spot.order_book_update","event":"update","result":{"t":1619093545085,"e":"depthUpdate","E":1619093545,"s":"OMG_USDT","U":59231902,"u":59231902,"b":[["7.891","131.864"]],"a":[]}}
1619093545.186364: {"time":1619093545,"channel":"spot.order_book_update","event":"update","result":{"t":1619093545149,"e":"depthUpdate","E":1619093545,"s":"NEO_BTC","U":31244081,"u":31244082,"b":[["0.0018697","5.37059"]],"a":[["0.0018734","0"],["0.0020507","0.5"]]}}
1619093545.214754: {"time":1619093545,"channel":"spot.order_book_update","event":"update","result":{"t":1619093545198,"e":"depthUpdate","E":1619093545,"s":"BTC_USDC","U":13035633,"u":13035633,"b":[],"a":[["58216.28","0"]]}}
1619093545.407517: {"time":1619093545,"channel":"spot.order_book_update","event":"update","result":{"t":1619093545238,"e":"depthUpdate","E":1619093545,"s":"BTC_USDC","U":13035634,"u":13035634,"b":[],"a":[["58237.5","0.021"]]}}
1619093545.4563699: {"time":1619093545,"channel":"spot.order_book_update","event":"update","result":{"t":1619093545440,"e":"depthUpdate","E":1619093545,"s":"NEO_BTC","U":31244083,"u":31244083,"b":[["0.0018461","0"],["0.0000005","1000"]],"a":[]}}
1619093545.659847: {"time":1619093545,"channel":"spot.order_book_update","event":"update","result":{"t":1619093545644,"e":"depthUpdate","E":1619093545,"s":"NEO_BTC","U":31244084,"u":31244084,"b":[["0.0018697","0.5"]],"a":[]}}
1619093545.905259: {"time":1619093545,"channel":"spot.order_book_update","event":"update","result":{"t":1619093545855,"e":"depthUpdate","E":1619093545,"s":"DIS_USDT","U":1750473,"u":1750473,"b":[["120.92","0.162821"]],"a":[]}}
1619093545.905344: {"time":1619093545,"channel":"spot.order_book_update","event":"update","result":{"t":1619093545858,"e":"depthUpdate","E":1619093545,"s":"NEO_BTC","U":31244085,"u":31244085,"b":[],"a":[["0.0018734","5.076"],["0.0020507","0"]]}}
1619093546.315535: {"time":1619093546,"channel":"spot.order_book_update","event":"update","result":{"t":1619093546272,"e":"depthUpdate","E":1619093546,"s":"NEO_BTC","U":31244086,"u":31244086,"b":[],"a":[["0.0018734","0"],["0.0020507","0.5"]]}}
1619093546.826968: {"time":1619093546,"channel":"spot.order_book_update","event":"update","result":{"t":1619093546749,"e":"depthUpdate","E":1619093546,"s":"OMG_USDT","U":59231903,"u":59231903,"b":[["7.892","65.791"],["6.3","0"]],"a":[]}}
1619093547.003896: {"time":1619093546,"channel":"spot.trades","event":"update","result":{"id":816995970,"create_time":1619093546,"create_time_ms":"1619093546958.116","side":"buy","currency_pair":"NEO_BTC","amount":"0.5000000000","price":"0.0018735000"}}
1619093547.051795: {"time":1619093547,"channel":"spot.tickers","event":"update","result":{"currency_pair":"NEO_BTC","last":"0.0018735","lowest_ask":"0.0018735","highest_bid":"0.0018697","change_percentage":"3.0301","base_volume":"1138.51640718","quote_volume":"2.049200115803126","high_24h":"0.0018754","low_24h":"0.0017148"}}
1619093547.1020951: {"time":1619093547,"channel":"spot.trades","event":"update","result":{"id":816995982,"create_time":1619093547,"create_time_ms":"1619093547078.008","side":"sell","currency_pair":"NEO_BTC","amount":"1.0700000000","price":"0.0018753000"}}
1619093547.180793: {"time":1619093547,"channel":"spot.order_book_update","event":"update","result":{"t":1619093547165,"e":"depthUpdate","E":1619093547,"s":"DIS_USDT","U":1750474,"u":1750474,"b":[["117.44","17.228745"]],"a":[]}}
1619093547.181395: {"time":1619093547,"channel":"spot.order_book_update","event":"update","result":{"t":1619093547166,"e":"depthUpdate","E":1619093547,"s":"NEO_BTC","U":31244087,"u":31244091,"b":[],"a":[["0.0018735","5.076"],["0.0018748","0.42431023"],["0.0020507","0"]]}}
1619093547.385785: {"time":1619093547,"channel":"spot.order_book_update","event":"update","result":{"t":1619093547369,"e":"depthUpdate","E":1619093547,"s":"NEO_BTC","U":31244092,"u":31244092,"b":[],"a":[["0.0018773","5.74738"]]}}
1619093547.419132: {"time":1619093547,"channel":"spot.order_book_update","event":"update","result":{"t":1619093547403,"e":"depthUpdate","E":1619093547,"s":"HAI_ETH","U":2691453,"u":2691453,"b":[["0.00010335","0"]],"a":[]}}
1619093547.453716: {"time":1619093547,"channel":"spot.order_book_update","event":"update","result":{"t":1619093547437,"e":"depthUpdate","E":1619093547,"s":"OMG_USDT","U":59231904,"u":59231904,"b":[["7.883","0"],["6.3","61.746"]],"a":[]}}
1619093547.500114: {"time":1619093547,"channel":"spot.order_book_update","event":"update","result":{"t":1619093547484,"e":"depthUpdate","E":1619093547,"s":"DIS_USDT","U":1750475,"u":1750475,"b":[["117.45","5.2147"],["73.5","0"]],"a":[]}}
1619093547.500725: {"time":1619093547,"channel":"spot.order_book_update","event":"update","result":{"t":1619093547485,"e":"depthUpdate","E":1619093547,"s":"NEO_BTC","U":31244093,"u":31244093,"b":[],"a":[["0.0018735","0"],["0.0020507","0.5"]]}}
1619093547.5298932: {"time":1619093547,"channel":"spot.order_book_update","event":"update","result":{"t":1619093547514,"e":"depthUpdate","E":1619093547,"s":"HAI_ETH","U":2691454,"u":2691454,"b":[["0.00010324","5997.415"]],"a":[]}}
1619093547.591816: {"time":1619093547,"channel":"spot.order_book_update","event":"update","result":{"t":1619093547575,"e":"depthUpdate","E":1619093547,"s":"OMG_USDT","U":59231905,"u":59231905,"b":[["7.884","291.951"]],"a":[]}}
1619093547.634869: {"time":1619093547,"channel":"spot.order_book_update","event":"update","result":{"t":1619093547619,"e":"depthUpdate","E":1619093547,"s":"DIS_USDT","U":1750476,"u":1750477,"b":[["117.44","13.1812"]],"a":[["124.89","0"],["164.34","0.202785"]]}}
1619093547.637998: {"time":1619093547,"channel":"spot.order_book_update","event":"update","result":{"t":1619093547622,"e":"depthUpdate","E":1619093547,"s":"NEO_BTC","U":31244094,"u":31244094,"b":[],"a":[["0.0018747","5.077"],["0.0020507","0"]]}}
1619093547.9534552: {"time":1619093547,"channel":"spot.order_book_update","event":"update","result":{"t":1619093547919,"e":"depthUpdate","E":1619093547,"s":"DIS_USDT","U":1750478,"u":1750478,"b":[["117.45","9.262245"]],"a":[]}}
1619093547.9535801: {"time":1619093547,"channel":"spot.order_book_update","event":"update","result":{"t":1619093547925,"e":"depthUpdate","E":1619093547,"s":"NEO_BTC","U":31244095,"u":31244095,"b":[],"a":[["0.0018773","0.5"]]}}
1619093548.044957: {"time":1619093548,"channel":"spot.candlesticks","event":"update","result":{"t":"1619093520","v":"24.43758","c":"121.58","h":"121.58","l":"121.58","o":"121.58","n":"1m_DIS_USDT"}}
1619093548.0497248: {"time":1619093548,"channel":"spot.tickers","event":"update","result":{"currency_pair":"NEO_BTC","last":"0.0018753","lowest_ask":"0.0018747","highest_bid":"0.0018697","change_percentage":"3.1291","base_volume":"1139.58640718","quote_volume":"2.051206686803126","high_24h":"0.0018754","low_24h":"0.0017148"}}
1619093548.192289: {"time":1619093548,"channel":"spot.order_book_update","event":"update","result":{"t":1619093548175,"e":"depthUpdate","E":1619093548,"s":"FAST_USDT","U":1138124,"u":1138125,"b":[["10.21","0"]],"a":[["11.36","19.26955094"]]}}
1619093548.246304: {"time":1619093548,"channel":"spot.order_book_update","event":"update","result":{"t":1619093548229,"e":"depthUpdate","E":1619093548,"s":"DIS_USDT","U":1750479,"u":1750479,"b":[],"a":[["124.89","0.515355"],["164.34","0"]]}}
1619093548.249158: {"time":1619093548,"channel":"spot.order_book_update","event":"update","result":{"t":1619093548232,"e":"depthUpdate","E":1619093548,"s":"NEO_BTC","U":31244096,"u":31244096,"b":[],"a":[["0.0018747","0"],["0.0020507","0.5"]]}}
1619093548.523925: {"time":1619093548,"channel":"spot.order_book_update","event":"update","result":{"t":1619093548507,"e":"depthUpdate","E":1619093548,"s":"FAST_USDT","U":1138126,"u":1138126,"b":[["10","19.0821"]],"a":[]}}
1619093548.8093839: {"time":1619093548,"channel":"spot.order_book_update","event":"update","result":{"t":1619093548793,"e":"depthUpdate","E":1619093548,"s":"NEO_BTC","U":31244097,"u":31244098,"b":[["0.0018716","0.5"],["0.0018601","5.077"],["0.00000089","0"],["0.0000005","0"]],"a":[]}}
1619093548.947469: {"time":1619093548,"channel":"spot.order_book_update","event":"update","result":{"t":1619093548914,"e":"depthUpdate","E":1619093548,"s":"FAST_USDT","U":1138127,"u":1138127,"b":[],"a":[["11.36","28.27455094"]]}}
1619093548.9533749: {"time":1619093548,"channel":"spot.order_book_update","event":"update","result":{"t":1619093548920,"e":"depthUpdate","E":1619093548,"s":"ZKS_ETH","U":11077665,"u":11077665,"b":[["0.001005","50.29"]],"a":[]}}
1619093549.011476: {"time":1619093548,"channel":"spot.order_book_update","event":"update","result":{"t":1619093548993,"e":"depthUpdate","E":1619093548,"s":"QTUM3S_USDT","U":69526985,"u":69526986,"b":[["0.225463","7576.77"]],"a":[["0.228643","5728.13"]]}}
1619093549.063391: {"time":1619093549,"channel":"spot.order_book_update","event":"update","result":{"t":1619093549045,"e":"depthUpdate","E":1619093549,"s":"OMG_USDT","U":59231906,"u":59231907,"b":[["7.884","28.6"],["7.883","263.412"],["6.3","0"]],"a":[]}}
1619093549.104274: {"time":1619093549,"channel":"spot.tickers","event":"update","result":{"currency_pair":"NEO_BTC","last":"0.0018753","lowest_ask":"0.0018748","highest_bid":"0.0018716","change_percentage":"3.1291","base_volume":"1139.58640718","quote_volume":"2.051206686803126","high_24h":"0.0018754","low_24h":"0.0017148"}}
1619093549.139304: {"time":1619093549,"channel":"spot.order_book_update","event":"update","result":{"t":1619093549122,"e":"depthUpdate","E":1619093549,"s":"DIS_USDT","U":1750480,"u":1750480,"b":[["117.44","9.6156"]],"a":[]}}
1619093549.139426: {"time":1619093549,"channel":"spot.order_book_update","event":"update","result":{"t":1619093549124,"e":"depthUpdate","E":1619093549,"s":"NEO_BTC","U":31244099,"u":31244099,"b":[["0.0018697","5.37068"]],"a":[]}}
1619093549.239064: {"time":1619093549,"channel":"spot.order_book_update","event":"update","result":{"t":1619093549223,"e":"depthUpdate","E":1619093549,"s":"NEO_BTC","U":31244100,"u":31244101,"b":[["0.0018697","0.5"],["0.0018659","0"],["0.00000089","300"]],"a":[]}}
1619093549.362289: {"time":1619093549,"channel":"spot.order_book_update","event":"update","result":{"t":1619093549345,"e":"depthUpdate","E":1619093549,"s":"OMG_USDT","U":59231908,"u":59231912,"b":[["7.899","288"],["7.897","131.55"],["6.36","0"]],"a":[["7.997","0"],["9.357","5.013"]]}}
1619093549.364552: {"time":1619093549,"channel":"spot.order_book_update","event":"update","result":{"t":1619093549349,"e":"depthUpdate","E":1619093549,"s":"ZKS_ETH","U":11077666,"u":11077666,"b":[["0.001006","47.904"]],"a":[]}}
1619093549.5525482: {"time":1619093549,"channel":"spot.order_book_update","event":"update","result":{"t":1619093549530,"e":"depthUpdate","E":1619093549,"s":"OMG_USDT","U":59231913,"u":59231917,"b":[["7.897","131.589"],["7.892","0"],["7.89","65.692"]],"a":[["8.005","349.0420934694"],["9.357","0"]]}}
1619093549.682324: {"time":1619093549,"channel":"spot.order_book_update","event":"update","result":{"t":1619093549666,"e":"depthUpdate","E":1619093549,"s":"DIS_USDT","U":1750481,"u":1750481,"b":[["117.45","13.719245"]],"a":[]}}
1619093549.684803: {"time":1619093549,"channel":"spot.order_book_update","event":"update","result":{"t":1619093549669,"e":"depthUpdate","E":1619093549,"s":"NEO_BTC","U":31244102,"u":31244102,"b":[["0.0018636","15.225"],["0.00000089","0"]],"a":[]}}
1619093550.001806: {"time":1619093549,"channel":"spot.order_book_update","event":"update","result":{"t":1619093549904,"e":"depthUpdate","E":1619093549,"s":"ZKS_ETH","U":11077667,"u":11077667,"b":[["0.001006","0"]],"a":[]}}
1619093550.026741: {"time":1619093550,"channel":"spot.order_book_update","event":"update","result":{"t":1619093550011,"e":"depthUpdate","E":1619093550,"s":"ZKS_ETH","U":11077668,"u":11077668,"b":[["0.001006","38.323"]],"a":[]}}
1619093550.045294: {"time":1619093550,"channel":"spot.candlesticks","event":"update","result":{"t":"1619093520","v":"0.002943321","c":"0.0018753","h":"0.0018753","l":"0.0018735","o":"0.0018735","n":"1m_NEO_BTC"}}
1619093550.048672: {"time":1619093550,"channel":"spot.tickers","event":"update","result":{"currency_pair":"OMG_USDT","last":"7.915","lowest_ask":"7.927","highest_bid":"7.899","change_percentage":"5.85","base_volume":"27799.8390372666","quote_volume":"215375.1010537074991","high_24h":"8.44","low_24h":"7.364"}}
1619093550.048747: {"time":1619093550,"channel":"spot.tickers","event":"update","result":{"currency_pair":"ZKS_ETH","last":"0.001028","lowest_ask":"0.001038","highest_bid":"0.001006","change_percentage":"-8.0501","base_volume":"10020.74875661","quote_volume":"10.8198456109701","high_24h":"0.001137","low_24h":"0.001019"}}
1619093550.309639: {"time":1619093550,"channel":"spot.order_book_update","event":"update","result":{"t":1619093550240,"e":"depthUpdate","E":1619093550,"s":"HAI_ETH","U":2691455,"u":2691456,"b":[],"a":[["0.00010397","5885.172"],["0.00010408","0"]]}}
1619093550.412194: {"time":1619093550,"channel":"spot.order_book_update","event":"update","result":{"t":1619093550394,"e":"depthUpdate","E":1619093550,"s":"DIS_USDT","U":1750482,"u":1750482,"b":[["120.92","0.014821"]],"a":[]}}
1619093550.6599271: {"time":1619093550,"channel":"spot.order_book_update","event":"update","result":{"t":1619093550643,"e":"depthUpdate","E":1619093550,"s":"OMG_USDT","U":59231918,"u":59231918,"b":[["7.652","0"],["6.36","238"]],"a":[]}}
1619093551.128382: {"time":1619093551,"channel":"spot.order_book_update","event":"update","result":{"t":1619093551031,"e":"depthUpdate","E":1619093551,"s":"OMG_USDT","U":59231919,"u":59231919,"b":[["7.555","281.331"],["6.36","0"]],"a":[]}}
1619093551.163831: {"time":1619093551,"channel":"spot.order_book_update","event":"update","result":{"t":1619093551147,"e":"depthUpdate","E":1619093551,"s":"OMG_USDT","U":59231920,"u":59231920,"b":[["7.801","0"],["6.36","238"]],"a":[]}}
1619093551.435807: {"time":1619093551,"channel":"spot.order_book_update","event":"update","result":{"t":1619093551395,"e":"depthUpdate","E":1619093551,"s":"OMG_USDT","U":59231921,"u":59231921,"b":[["7.804","153.1893464532"],["6.36","0"]],"a":[]}}
1619093553.528481: {"time":1619093553,"channel":"spot.trades","event":"update","result":{"id":816996516,"create_time":1619093553,"create_time_ms":"1619093553517.921","side":"sell","currency_pair":"FAST_USDT","amount":"1.7170000000","price":"10.4200000000"}}
1619093553.614992: {"time":1619093553,"channel":"spot.trades","event":"update","result":{"id":816996524,"create_time":1619093553,"create_time_ms":"1619093553605.789","side":"sell","currency_pair":"ZKS_ETH","amount":"12.1860000000","price":"0.0010210000"}}
1619093553.677731: {"time":1619093553,"channel":"spot.order_book_update","event":"update","result":{"t":1619093553653,"e":"depthUpdate","E":1619093553,"s":"OMG_USDT","U":59231922,"u":59231922,"b":[["7.231","0"],["6.36","238"]],"a":[]}}
1619093553.763416: {"time":1619093553,"channel":"spot.order_book_update","event":"update","result":{"t":1619093553748,"e":"depthUpdate","E":1619093553,"s":"FAST_USDT","U":1138128,"u":1138130,"b":[],"a":[["10.79","34.29795462"]]}}
1619093553.77457: {"time":1619093553,"channel":"spot.order_book_update","event":"update","result":{"t":1619093553758,"e":"depthUpdate","E":1619093553,"s":"OMG_USDT","U":59231923,"u":59231923,"b":[["7.232","27.75324569"],["6.36","0"]],"a":[]}}
1619093553.856089: {"time":1619093553,"channel":"spot.order_book_update","event":"update","result":{"t":1619093553840,"e":"depthUpdate","E":1619093553,"s":"FAST_USDT","U":1138131,"u":1138132,"b":[["10.28","0"]],"a":[["10.72","60.3616625"]]}}
1619093553.997034: {"time":1619093553,"channel":"spot.order_book_update","event":"update","result":{"t":1619093553981,"e":"depthUpdate","E":1619093553,"s":"ZKS_ETH","U":11077669,"u":11077671,"b":[["0.001006","0"]],"a":[]}}
1619093554.006284: {"time":1619093553,"channel":"spot.order_book_update","event":"update","result":{"t":1619093553991,"e":"depthUpdate","E":1619093553,"s":"FAST_USDT","U":1138133,"u":1138133,"b":[],"a":[["10.71","24.17182374"]]}}
1619093554.014394: {"time":1619093553,"channel":"spot.order_book_update","event":"update","result":{"t":1619093553998,"e":"depthUpdate","E":1619093553,"s":"OMG_USDT","U":59231924,"u":59231926,"b":[["7.891","0"],["6.36","238"]],"a":[]}}
1619093554.048894: {"time":1619093554,"channel":"spot.tickers","event":"update","result":{"currency_pair":"ZKS_ETH","last":"0.001021","lowest_ask":"0.001038","highest_bid":"0.001005","change_percentage":"-8.6762","base_volume":"10032.93475661","quote_volume":"10.8322875169701","high_24h":"0.001137","low_24h":"0.001019"}}
1619093554.048934: {"time":1619093554,"channel":"spot.tickers","event":"update","result":{"currency_pair":"FAST_USDT","last":"10.42","lowest_ask":"10.63","highest_bid":"10.2","change_percentage":"-5.6088","base_volume":"3832.335432775","quote_volume":"39909.05175673985","high_24h":"11.5","low_24h":"9.86"}}
1619093554.246817: {"time":1619093554,"channel":"spot.order_book_update","event":"update","result":{"t":1619093554231,"e":"depthUpdate","E":1619093554,"s":"QTUM3S_USDT","U":69526987,"u":69526993,"b":[["0.225553","0"],["0.185253","0"],["0.164422","0"]],"a":[["0.228413","0"],["0.235959","0"],["0.238917","0"]]}}
1619093554.2863228: {"time":1619093554,"channel":"spot.order_book_update","event":"update","result":{"t":1619093554265,"e":"depthUpdate","E":1619093554,"s":"FAST_USDT","U":1138134,"u":1138134,"b":[["10.2","104.043"]],"a":[]}}
1619093554.290159: {"time":1619093554,"channel":"spot.order_book_update","event":"update","result":{"t":1619093554274,"e":"depthUpdate","E":1619093554,"s":"OMG_USDT","U":59231927,"u":59231929,"b":[["7.888","131.905"],["7.883","0"],["7.881","263.48"],["6.36","0"]],"a":[]}}
1619093554.4227939: {"time":1619093554,"channel":"spot.order_book_update","event":"update","result":{"t":1619093554404,"e":"depthUpdate","E":1619093554,"s":"FAST_USDT","U":1138135,"u":1138135,"b":[["10.21","36.50154112"]],"a":[]}}
1619093554.428549: {"time":1619093554,"channel":"spot.order_book_update","event":"update","result":{"t":1619093554410,"e":"depthUpdate","E":1619093554,"s":"OMG_USDT","U":59231930,"u":59231931,"b":[["7.89","0"],["7.888","197.682"],["6.36","238"]],"a":[]}}
1619093554.7096179: {"time":1619093554,"channel":"spot.order_book_update","event":"update","result":{"t":1619093554655,"e":"depthUpdate","E":1619093554,"s":"FAST_USDT","U":1138136,"u":1138137,"b":[["10","19.5701315"]],"a":[["10.62","25.96795888"],["45","0"]]}}
1619093554.709784: {"time":1619093554,"channel":"spot.order_book_update","event":"update","result":{"t":1619093554666,"e":"depthUpdate","E":1619093554,"s":"OMG_USDT","U":59231932,"u":59231932,"b":[["7.897","0"],["6.3","61.746"]],"a":[]}}
1619093554.976668: {"time":1619093554,"channel":"spot.order_book_update","event":"update","result":{"t":1619093554919,"e":"depthUpdate","E":1619093554,"s":"OMG_USDT","U":59231933,"u":59231933,"b":[["7.897","131.586"],["6.3","0"]],"a":[]}}
1619093555.05249: {"time":1619093555,"channel":"spot.tickers","event":"update","result":{"currency_pair":"FAST_USDT","last":"10.42","lowest_ask":"10.62","highest_bid":"10.21","change_percentage":"-5.6088","base_volume":"3832.335432775","quote_volume":"39909.05175673985","high_24h":"11.5","low_24h":"9.86"}}
1619093555.332939: {"time":1619093555,"channel":"spot.order_book_update","event":"update","result":{"t":1619093555313,"e":"depthUpdate","E":1619093555,"s":"DIS_USDT","U":1750483,"u":1750483,"b":[["117.44","7.333"]],"a":[]}}
1619093555.4789078: {"time":1619093555,"channel":"spot.order_book_update","event":"update","result":{"t":1619093555462,"e":"depthUpdate","E":1619093555,"s":"DIS_USDT","U":1750484,"u":1750484,"b":[["117.45","16.001845"]],"a":[]}}
1619093555.688479: {"time":1619093555,"channel":"spot.order_book_update","event":"update","result":{"t":1619093555670,"e":"depthUpdate","E":1619093555,"s":"QTUM3S_USDT","U":69526994,"u":69526999,"b":[["0.202636","0"],["0.177603","3661.04"],["0.177206","0"]],"a":[["0.252535","0"],["0.271111","0"],["0.283535","2826.31"]]}}
1619093555.716565: {"time":1619093555,"channel":"spot.order_book_update","event":"update","result":{"t":1619093555701,"e":"depthUpdate","E":1619093555,"s":"OMG_USDT","U":59231934,"u":59231934,"b":[["7.878","0"],["6.3","61.746"]],"a":[]}}
1619093555.8745348: {"time":1619093555,"channel":"spot.order_book_update","event":"update","result":{"t":1619093555858,"e":"depthUpdate","E":1619093555,"s":"ZKS_ETH","U":11077672,"u":11077672,"b":[["0.001005","289.072"]],"a":[]}}
1619093556.005187: {"time":1619093555,"channel":"spot.order_book_update","event":"update","result":{"t":1619093555988,"e":"depthUpdate","E":1619093555,"s":"NEO_BTC","U":31244103,"u":31244104,"b":[["0.001863","5.073"],["0.0018601","0"]],"a":[]}}
1619093556.123161: {"time":1619093556,"channel":"spot.order_book_update","event":"update","result":{"t":1619093556105,"e":"depthUpdate","E":1619093556,"s":"OMG_USDT","U":59231935,"u":59231937,"b":[["7.888","659.281"],["7.886","0"],["7.878","2124.032"]],"a":[]}}
1619093556.4522738: {"time":1619093556,"channel":"spot.order_book_update","event":"update","result":{"t":1619093556405,"e":"depthUpdate","E":1619093556,"s":"OMG_USDT","U":59231938,"u":59231938,"b":[["7.888","197.682"]],"a":[]}}
1619093556.663856: {"time":1619093556,"channel":"spot.order_book_update","event":"update","result":{"t":1619093556648,"e":"depthUpdate","E":1619093556,"s":"NEO_BTC","U":31244105,"u":31244105,"b":[["0.0018636","0"],["0.00000089","300"]],"a":[]}}
1619093556.758948: {"time":1619093556,"channel":"spot.order_book_update","event":"update","result":{"t":1619093556742,"e":"depthUpdate","E":1619093556,"s":"DIS_USDT","U":1750485,"u":1750485,"b":[],"a":[["122.23","0.00896999"],["163.77","0"]]}}
1619093556.830695: {"time":1619093556,"channel":"spot.order_book_update","event":"update","result":{"t":1619093556815,"e":"depthUpdate","E":1619093556,"s":"NEO_BTC","U":31244106,"u":31244106,"b":[["0.001865","15.213"],["0.00000089","0"]],"a":[]}}
1619093556.947666: {"time":1619093556,"channel":"spot.order_book_update","event":"update","result":{"t":1619093556932,"e":"depthUpdate","E":1619093556,"s":"QTUM3S_USDT","U":69527000,"u":69527007,"b":[["0.205614","6572.36"],["0.202164","0"],["0.201747","0"],["0.19831","7889.58"]],"a":[["0.228734","0"],["0.249705","0"],["0.277823","4874.23"],["0.290329","2956.43"]]}}
1619093557.0587661: {"time":1619093557,"channel":"spot.tickers","event":"update","result":{"currency_pair":"DIS_USDT","last":"121.58","lowest_ask":"122.23","highest_bid":"120.92","change_percentage":"-2.2192","base_volume":"445.9212426988","quote_volume":"53753.93539346942","high_24h":"142.51","low_24h":"112.82"}}
1619093557.4779332: {"time":1619093557,"channel":"spot.order_book_update","event":"update","result":{"t":1619093557388,"e":"depthUpdate","E":1619093557,"s":"OMG_USDT","U":59231939,"u":59231939,"b":[["7.889","461.474"],["6.3","0"]],"a":[]}}
1619093557.927277: {"time":1619093557,"channel":"spot.order_book_update","event":"update","result":{"t":1619093557892,"e":"depthUpdate","E":1619093557,"s":"DIS_USDT","U":1750486,"u":1750486,"b":[["117.44","0"],["73.5","1"]],"a":[]}}
1619093557.981171: {"time":1619093557,"channel":"spot.order_book_update","event":"update","result":{"t":1619093557964,"e":"depthUpdate","E":1619093557,"s":"OMG_USDT","U":59231940,"u":59231940,"b":[["7.887","0"],["6.3","61.746"]],"a":[]}}
1619093558.04609: {"time":1619093558,"channel":"spot.candlesticks","event":"update","result":{"t":"1619093520","v":"38.43458","c":"10.42","h":"10.46","l":"10.42","o":"10.46","n":"1m_FAST_USDT"}}
1619093558.046197: {"time":1619093558,"channel":"spot.candlesticks","event":"update","result":{"t":"1619093520","v":"0.012441906","c":"0.001021","h":"0.001021","l":"0.001021","o":"0.001021","n":"1m_ZKS_ETH"}}
1619093558.2339442: {"time":1619093558,"channel":"spot.order_book_update","event":"update","result":{"t":1619093558214,"e":"depthUpdate","E":1619093558,"s":"QTUM3S_USDT","U":69527008,"u":69527015,"b":[["0.210613","0"],["0.207242","13208.41"],["0.203803","0"],["0.1646","2239.31"]],"a":[["0.232533","4919.59"],["0.23915","5400.83"],["0.251405","0"],["0.290094","0"]]}}
1619093558.318239: {"time":1619093558,"channel":"spot.order_book_update","event":"update","result":{"t":1619093558301,"e":"depthUpdate","E":1619093558,"s":"OMG_USDT","U":59231941,"u":59231941,"b":[["7.888","460.815"]],"a":[]}}
1619093558.331102: {"time":1619093558,"channel":"spot.order_book_update","event":"update","result":{"t":1619093558314,"e":"depthUpdate","E":1619093558,"s":"DIS_USDT","U":1750487,"u":1750487,"b":[["117.45","23.334845"]],"a":[]}}
1619093558.489483: {"time":1619093558,"channel":"spot.order_book_update","event":"update","result":{"t":1619093558472,"e":"depthUpdate","E":1619093558,"s":"NANO_USDT","U":8008158,"u":8008158,"b":[["8.6867","0"]],"a":[]}}
1619093558.737476: {"time":1619093558,"channel":"spot.order_book_update","event":"update","result":{"t":1619093558720,"e":"depthUpdate","E":1619093558,"s":"FAST_USDT","U":1138138,"u":1138138,"b":[],"a":[["10.79","0"],["45","11.164714"]]}}
1619093558.831326: {"time":1619093558,"channel":"spot.order_book_update","event":"update","result":{"t":1619093558813,"e":"depthUpdate","E":1619093558,"s":"NEO_BTC","U":31244107,"u":31244107,"b":[],"a":[["0.0018748","0"],["0.0020528","0.5"]]}}
1619093559.0172958: {"time":1619093558,"channel":"spot.order_book_update","event":"update","result":{"t":1619093558997,"e":"depthUpdate","E":1619093558,"s":"FAST_USDT","U":1138139,"u":1138139,"b":[],"a":[["10.71","58.46977836"]]}}
1619093559.022752: {"time":1619093559,"channel":"spot.order_book_update","event":"update","result":{"t":1619093559006,"e":"depthUpdate","E":1619093559,"s":"OMG_USDT","U":59231942,"u":59231942,"b":[["7.889","0"],["6.258","0.24"]],"a":[]}}
1619093559.056643: {"time":1619093559,"channel":"spot.tickers","event":"update","result":{"currency_pair":"NEO_BTC","last":"0.0018753","lowest_ask":"0.0018754","highest_bid":"0.0018716","change_percentage":"3.1291","base_volume":"1139.58640718","quote_volume":"2.051206686803126","high_24h":"0.0018754","low_24h":"0.0017148"}}
1619093559.143976: {"time":1619093559,"channel":"spot.order_book_update","event":"update","result":{"t":1619093559128,"e":"depthUpdate","E":1619093559,"s":"FAST_USDT","U":1138140,"u":1138140,"b":[],"a":[["10.71","54.37290596"]]}}
1619093559.154764: {"time":1619093559,"channel":"spot.order_book_update","event":"update","result":{"t":1619093559137,"e":"depthUpdate","E":1619093559,"s":"OMG_USDT","U":59231943,"u":59231943,"b":[["7.889","461.567"],["6.258","0"]],"a":[]}}
1619093559.2785459: {"time":1619093559,"channel":"spot.order_book_update","event":"update","result":{"t":1619093559261,"e":"depthUpdate","E":1619093559,"s":"NEO_BTC","U":31244108,"u":31244108,"b":[],"a":[["0.001877","5.24738"],["0.0020528","0"]]}}
1619093559.324131: {"time":1619093559,"channel":"spot.order_book_update","event":"update","result":{"t":1619093559307,"e":"depthUpdate","E":1619093559,"s":"ZKS_ETH","U":11077673,"u":11077673,"b":[["0.001005","50.29"]],"a":[]}}
1619093559.351619: {"time":1619093559,"channel":"spot.order_book_update","event":"update","result":{"t":1619093559334,"e":"depthUpdate","E":1619093559,"s":"OMG_USDT","U":59231944,"u":59231944,"b":[["7.881","0"],["6.258","0.24"]],"a":[]}}
1619093559.443881: {"time":1619093559,"channel":"spot.order_book_update","event":"update","result":{"t":1619093559425,"e":"depthUpdate","E":1619093559,"s":"ZKS_ETH","U":11077674,"u":11077674,"b":[["0.001005","88.613"]],"a":[]}}
1619093559.4847271: {"time":1619093559,"channel":"spot.order_book_update","event":"update","result":{"t":1619093559466,"e":"depthUpdate","E":1619093559,"s":"OMG_USDT","U":59231945,"u":59231945,"b":[["7.881","263.425"],["6.258","0"]],"a":[]}}
1619093559.618282: {"time":1619093559,"channel":"spot.order_book_update","event":"update","result":{"t":1619093559600,"e":"depthUpdate","E":1619093559,"s":"QTUM3S_USDT","U":69527016,"u":69527025,"b":[["0.225463","0"],["0.225236","0"],["0.225231","5610.08"],["0.218248","2410.62"],["0.211618","0"],["0.198332","5459.88"]],"a":[["0.228407","7344.33"],["0.23615","0"],["0.254399","17109.49"],["0.26215","0"]]}}
1619093559.686337: {"time":1619093559,"channel":"spot.order_book_update","event":"update","result":{"t":1619093559670,"e":"depthUpdate","E":1619093559,"s":"NANO_USDT","U":8008159,"u":8008160,"b":[["8.68","467.5556"]],"a":[["8.8908","0"],["11.9917","0.197"]]}}
1619093559.727912: {"time":1619093559,"channel":"spot.order_book_update","event":"update","result":{"t":1619093559710,"e":"depthUpdate","E":1619093559,"s":"FAST_USDT","U":1138141,"u":1138141,"b":[],"a":[["10.7","4.0968724"],["45","0"]]}}
1619093560.139986: {"time":1619093560,"channel":"spot.order_book_update","event":"update","result":{"t":1619093560052,"e":"depthUpdate","E":1619093560,"s":"OMG_USDT","U":59231946,"u":59231947,"b":[["7.897","131.562"]],"a":[]}}
1619093560.2849832: {"time":1619093560,"channel":"spot.order_book_update","event":"update","result":{"t":1619093560267,"e":"depthUpdate","E":1619093560,"s":"NANO_USDT","U":8008161,"u":8008161,"b":[],"a":[["8.8648","510.8701"],["11.9917","0"]]}}
1619093560.66651: {"time":1619093560,"channel":"spot.order_book_update","event":"update","result":{"t":1619093560635,"e":"depthUpdate","E":1619093560,"s":"NEO_BTC","U":31244109,"u":31244109,"b":[["0.001865","0"],["0.00000089","300"]],"a":[]}}
1619093560.73262: {"time":1619093560,"channel":"spot.trades","event":"update","result":{"id":816996977,"create_time":1619093560,"create_time_ms":"1619093560720.907","side":"buy","currency_pair":"NANO_USDT","amount":"0.3760000000","price":"8.7919000000"}}
1619093560.742131: {"time":1619093560,"channel":"spot.order_book_update","event":"update","result":{"t":1619093560724,"e":"depthUpdate","E":1619093560,"s":"OMG_USDT","U":59231948,"u":59231948,"b":[["7.889","0"],["6.258","0.24"]],"a":[]}}
1619093560.779128: {"time":1619093560,"channel":"spot.order_book_update","event":"update","result":{"t":1619093560760,"e":"depthUpdate","E":1619093560,"s":"NANO_USDT","U":8008162,"u":8008165,"b":[],"a":[["8.8542","51.62831"],["8.865","0"]]}}
1619093560.794347: {"time":1619093560,"channel":"spot.order_book_update","event":"update","result":{"t":1619093560776,"e":"depthUpdate","E":1619093560,"s":"NEO_BTC","U":31244110,"u":31244110,"b":[],"a":[["0.0018753","5.076"],["0.0020507","0"]]}}
1619093560.815145: {"time":1619093560,"channel":"spot.trades","event":"update","result":{"id":816996982,"create_time":1619093560,"create_time_ms":"1619093560801.34","side":"sell","currency_pair":"NEO_BTC","amount":"0.5000000000","price":"0.0018716000"}}
1619093560.815237: {"time":1619093560,"channel":"spot.trades","event":"update","result":{"id":816996983,"create_time":1619093560,"create_time_ms":"1619093560801.582","side":"sell","currency_pair":"NEO_BTC","amount":"0.5000000000","price":"0.0018697000"}}
1619093560.903816: {"time":1619093560,"channel":"spot.order_book_update","event":"update","result":{"t":1619093560878,"e":"depthUpdate","E":1619093560,"s":"QTUM3S_USDT","U":69527026,"u":69527033,"b":[["0.212695","5805.15"],["0.186024","0"],["0.181691","3212.87"],["0.178998","0"]],"a":[["0.233642","18415.53"],["0.24072","6092.11"],["0.26776","0"],["0.283535","0"]]}}
1619093560.9783528: {"time":1619093560,"channel":"spot.order_book_update","event":"update","result":{"t":1619093560953,"e":"depthUpdate","E":1619093560,"s":"NEO_BTC","U":31244111,"u":31244113,"b":[["0.0018716","0"],["0.0018697","0"],["0.001863","0"],["0.0000005","1000"],["0.00000046","600"],["0.0000003","1666.666"]],"a":[]}}
1619093561.063158: {"time":1619093561,"channel":"spot.tickers","event":"update","result":{"currency_pair":"NEO_BTC","last":"0.0018697","lowest_ask":"0.0018753","highest_bid":"0.0018678","change_percentage":"2.8212","base_volume":"1140.58640718","quote_volume":"2.053077336803126","high_24h":"0.0018754","low_24h":"0.0017148"}}
1619093561.0632489: {"time":1619093561,"channel":"spot.tickers","event":"update","result":{"currency_pair":"NANO_USDT","last":"8.7919","lowest_ask":"8.9167","highest_bid":"8.8685","change_percentage":"0.9319","base_volume":"11766.09092637","quote_volume":"104349.0283735200575","high_24h":"10.2","low_24h":"8.1722"}}
1619093561.370164: {"time":1619093561,"channel":"spot.order_book_update","event":"update","result":{"t":1619093561250,"e":"depthUpdate","E":1619093561,"s":"NEO_BTC","U":31244114,"u":31244115,"b":[],"a":[["0.0018746","5.24738"],["0.001877","0"]]}}
1619093561.549294: {"time":1619093561,"channel":"spot.order_book_update","event":"update","result":{"t":1619093561532,"e":"depthUpdate","E":1619093561,"s":"FAST_USDT","U":1138142,"u":1138142,"b":[],"a":[["10.72","0"],["45","11.164714"]]}}
1619093561.5560992: {"time":1619093561,"channel":"spot.order_book_update","event":"update","result":{"t":1619093561539,"e":"depthUpdate","E":1619093561,"s":"OMG_USDT","U":59231949,"u":59231949,"b":[["7.888","395.038"]],"a":[]}}
1619093561.6386309: {"time":1619093561,"channel":"spot.order_book_update","event":"update","result":{"t":1619093561622,"e":"depthUpdate","E":1619093561,"s":"NEO_BTC","U":31244116,"u":31244116,"b":[],"a":[["0.0018735","0.5"],["0.0020486","0"]]}}
1619093561.67988: {"time":1619093561,"channel":"spot.order_book_update","event":"update","result":{"t":1619093561661,"e":"depthUpdate","E":1619093561,"s":"OMG_USDT","U":59231950,"u":59231950,"b":[["7.889","65.638"],["6.258","0"]],"a":[]}}
1619093561.9830909: {"time":1619093561,"channel":"spot.order_book_update","event":"update","result":{"t":1619093561898,"e":"depthUpdate","E":1619093561,"s":"FAST_USDT","U":1138143,"u":1138143,"b":[],"a":[["10.71","114.73456846"]]}}
1619093561.983147: {"time":1619093561,"channel":"spot.order_book_update","event":"update","result":{"t":1619093561961,"e":"depthUpdate","E":1619093561,"s":"NEO_BTC","U":31244117,"u":31244118,"b":[],"a":[["0.001873","5.24738"],["0.0018746","0"]]}}
1619093562.049406: {"time":1619093562,"channel":"spot.tickers","event":"update","result":{"currency_pair":"NEO_BTC","last":"0.0018697","lowest_ask":"0.001873","highest_bid":"0.0018678","change_percentage":"2.8212","base_volume":"1140.58640718","quote_volume":"2.053077336803126","high_24h":"0.0018754","low_24h":"0.0017148"}}
1619093562.062164: {"time":1619093562,"channel":"spot.trades","event":"update","result":{"id":816997068,"create_time":1619093562,"create_time_ms":"1619093562050.3572","side":"sell","currency_pair":"NEO_BTC","amount":"0.5000000000","price":"0.0018678000"}}
1619093562.10512: {"time":1619093562,"channel":"spot.order_book_update","event":"update","result":{"t":1619093562087,"e":"depthUpdate","E":1619093562,"s":"NEO_BTC","U":31244119,"u":31244120,"b":[["0.0018678","0"],["0.0018659","0.5"]],"a":[]}}
1619093562.307627: {"time":1619093562,"channel":"spot.order_book_update","event":"update","result":{"t":1619093562291,"e":"depthUpdate","E":1619093562,"s":"QTUM3S_USDT","U":69527034,"u":69527041,"b":[["0.208717","0"],["0.198606","0"],["0.185388","10029.69"],["0.171979","5653.75"]],"a":[["0.23521","5366.68"],["0.247425","0"],["0.249002","0"],["0.28196","3815.41"]]}}
1619093562.672975: {"time":1619093562,"channel":"spot.order_book_update","event":"update","result":{"t":1619093562576,"e":"depthUpdate","E":1619093562,"s":"NEO_BTC","U":31244121,"u":31244121,"b":[],"a":[["0.0018734","9.561"],["0.0020465","0"]]}}
1619093562.882182: {"time":1619093562,"channel":"spot.order_book_update","event":"update","result":{"t":1619093562864,"e":"depthUpdate","E":1619093562,"s":"NANO_USDT","U":8008166,"u":8008166,"b":[],"a":[["8.8648","0"],["11.9917","0.197"]]}}
1619093563.016119: {"time":1619093562,"channel":"spot.order_book_update","event":"update","result":{"t":1619093562998,"e":"depthUpdate","E":1619093562,"s":"DIS_USDT","U":1750488,"u":1750488,"b":[["121.5","0.148"],["73.5","0"]],"a":[]}}

