wss://fx-ws.gateio.ws/v4/ws/usdt <-> 1684930163.9545715
wss://fx-ws.gateio.ws/v4/ws/usdt <- 1684930165.0856452: {"time":1684930165,"channel":"futures.candlesticks","event":"subscribe","payload":["1m","DIA_USDT"]}
wss://fx-ws.gateio.ws/v4/ws/usdt <- 1684930165.085738: {"time":1684930165,"channel":"futures.candlesticks","event":"subscribe","payload":["1m","RDNT_USDT"]}
wss://fx-ws.gateio.ws/v4/ws/usdt <- 1684930165.0857742: {"time":1684930165,"channel":"futures.candlesticks","event":"subscribe","payload":["1m","LIT_USDT"]}
wss://fx-ws.gateio.ws/v4/ws/usdt <- 1684930165.085801: {"time":1684930165,"channel":"futures.candlesticks","event":"subscribe","payload":["1m","ZRX_USDT"]}
wss://fx-ws.gateio.ws/v4/ws/usdt <- 1684930165.0858274: {"time":1684930165,"channel":"futures.candlesticks","event":"subscribe","payload":["1m","WOO_USDT"]}
wss://fx-ws.gateio.ws/v4/ws/usdt <- 1684930165.0858624: {"time":1684930165,"channel":"futures.candlesticks","event":"subscribe","payload":["1m","QUICK_USDT"]}
wss://fx-ws.gateio.ws/v4/ws/usdt <- 1684930165.085888: {"time":1684930165,"channel":"futures.candlesticks","event":"subscribe","payload":["1m","OMG_USDT"]}
wss://fx-ws.gateio.ws/v4/ws/usdt <- 1684930165.0859125: {"time":1684930165,"channel":"futures.candlesticks","event":"subscribe","payload":["1m","FRONT_USDT"]}
wss://fx-ws.gateio.ws/v4/ws/usdt <- 1684930165.0859373: {"time":1684930165,"channel":"futures.candlesticks","event":"subscribe","payload":["1m","PHB_USDT"]}
wss://fx-ws.gateio.ws/v4/ws/usdt <- 1684930165.0859601: {"time":1684930165,"channel":"futures.candlesticks","event":"subscribe","payload":["1m","SFP_USDT"]}
wss://fx-ws.gateio.ws/v4/ws/usdt <- 1684930165.0859876: {"time":1684930165,"channel":"futures.trades","event":"subscribe","payload":["DIA_USDT","RDNT_USDT","LIT_USDT","ZRX_USDT","WOO_USDT","QUICK_USDT","OMG_USDT","FRONT_USDT","PHB_USDT","SFP_USDT"]}
wss://fx-ws.gateio.ws/v4/ws/usdt <- 1684930165.086018: {"time":1684930165,"channel":"futures.order_book_update","event":"subscribe","payload":["DIA_USDT","100ms"]}
wss://fx-ws.gateio.ws/v4/ws/usdt <- 1684930165.0860443: {"time":1684930165,"channel":"futures.order_book_update","event":"subscribe","payload":["RDNT_USDT","100ms"]}
wss://fx-ws.gateio.ws/v4/ws/usdt <- 1684930165.086069: {"time":1684930165,"channel":"futures.order_book_update","event":"subscribe","payload":["LIT_USDT","100ms"]}
wss://fx-ws.gateio.ws/v4/ws/usdt <- 1684930165.086093: {"time":1684930165,"channel":"futures.order_book_update","event":"subscribe","payload":["ZRX_USDT","100ms"]}
wss://fx-ws.gateio.ws/v4/ws/usdt <- 1684930165.0861168: {"time":1684930165,"channel":"futures.order_book_update","event":"subscribe","payload":["WOO_USDT","100ms"]}
wss://fx-ws.gateio.ws/v4/ws/usdt <- 1684930165.0861409: {"time":1684930165,"channel":"futures.order_book_update","event":"subscribe","payload":["QUICK_USDT","100ms"]}
wss://fx-ws.gateio.ws/v4/ws/usdt <- 1684930165.0861647: {"time":1684930165,"channel":"futures.order_book_update","event":"subscribe","payload":["OMG_USDT","100ms"]}
wss://fx-ws.gateio.ws/v4/ws/usdt <- 1684930165.0861874: {"time":1684930165,"channel":"futures.order_book_update","event":"subscribe","payload":["FRONT_USDT","100ms"]}
wss://fx-ws.gateio.ws/v4/ws/usdt <- 1684930165.0862103: {"time":1684930165,"channel":"futures.order_book_update","event":"subscribe","payload":["PHB_USDT","100ms"]}
wss://fx-ws.gateio.ws/v4/ws/usdt <- 1684930165.0862331: {"time":1684930165,"channel":"futures.order_book_update","event":"subscribe","payload":["SFP_USDT","100ms"]}
wss://fx-ws.gateio.ws/v4/ws/usdt <- 1684930165.0862584: {"time":1684930165,"channel":"futures.book_ticker","event":"subscribe","payload":["DIA_USDT","RDNT_USDT","LIT_USDT","ZRX_USDT","WOO_USDT","QUICK_USDT","OMG_USDT","FRONT_USDT","PHB_USDT","SFP_USDT"]}
1684930165.3607924: {"time":1684930165,"time_ms":0,"channel":"futures.candlesticks","event":"subscribe","result":{"status":"success"}}
1684930165.3608162: {"time":1684930165,"time_ms":0,"channel":"futures.candlesticks","event":"subscribe","result":{"status":"success"}}
1684930165.3608246: {"time":1684930165,"time_ms":0,"channel":"futures.candlesticks","event":"subscribe","result":{"status":"success"}}
1684930165.3608308: {"time":1684930165,"time_ms":0,"channel":"futures.candlesticks","event":"subscribe","result":{"status":"success"}}
1684930165.3608365: {"time":1684930165,"time_ms":0,"channel":"futures.candlesticks","event":"subscribe","result":{"status":"success"}}
1684930165.3608422: {"time":1684930165,"time_ms":0,"channel":"futures.candlesticks","event":"subscribe","result":{"status":"success"}}
1684930165.361097: {"time":1684930165,"time_ms":0,"channel":"futures.candlesticks","event":"subscribe","result":{"status":"success"}}
1684930165.3611097: {"time":1684930165,"time_ms":0,"channel":"futures.candlesticks","event":"subscribe","result":{"status":"success"}}
1684930165.3611162: {"time":1684930165,"time_ms":0,"channel":"futures.candlesticks","event":"subscribe","result":{"status":"success"}}
1684930165.3613374: {"time":1684930165,"time_ms":0,"channel":"futures.candlesticks","event":"subscribe","result":{"status":"success"}}
1684930165.361349: {"time":1684930165,"time_ms":0,"channel":"futures.trades","event":"subscribe","result":{"status":"success"}}
1684930165.3613555: {"time":1684930165,"time_ms":0,"channel":"futures.order_book_update","event":"subscribe","result":{"status":"success"}}
1684930165.361362: {"time":1684930165,"time_ms":0,"channel":"futures.order_book_update","event":"subscribe","result":{"status":"success"}}
1684930165.3613675: {"time":1684930165,"time_ms":0,"channel":"futures.order_book_update","event":"subscribe","result":{"status":"success"}}
1684930165.3613734: {"time":1684930165,"time_ms":0,"channel":"futures.order_book_update","event":"subscribe","result":{"status":"success"}}
1684930165.3613791: {"time":1684930165,"time_ms":0,"channel":"futures.order_book_update","event":"subscribe","result":{"status":"success"}}
1684930165.3613846: {"time":1684930165,"time_ms":0,"channel":"futures.order_book_update","event":"subscribe","result":{"status":"success"}}
1684930165.3613904: {"time":1684930165,"time_ms":0,"channel":"futures.order_book_update","event":"subscribe","result":{"status":"success"}}
1684930165.3613963: {"time":1684930165,"time_ms":0,"channel":"futures.order_book_update","event":"subscribe","result":{"status":"success"}}
1684930165.3614018: {"time":1684930165,"time_ms":0,"channel":"futures.order_book_update","event":"subscribe","result":{"status":"success"}}
1684930165.3614073: {"time":1684930165,"time_ms":0,"channel":"futures.order_book_update","event":"subscribe","result":{"status":"success"}}
1684930165.3614128: {"time":1684930165,"time_ms":0,"channel":"futures.book_ticker","event":"subscribe","result":{"status":"success"}}
1684930165.40382: {"time":1684930165,"time_ms":1684930165254,"channel":"futures.order_book_update","event":"update","result":{"U":203083177,"a":[{"p":"0.2983","s":0}],"b":[],"s":"RDNT_USDT","t":1684930165217,"u":203083177}}
1684930166.5359373: {"time":1684930165,"time_ms":1684930165353,"channel":"futures.order_book_update","event":"update","result":{"U":203083178,"a":[{"p":"0.3047","s":8393},{"p":"0.2992","s":1336},{"p":"0.2983","s":1553},{"p":"0.3225","s":13}],"b":[],"s":"RDNT_USDT","t":1684930165247,"u":203083178}}
1684930166.5359688: {"time":1684930165,"time_ms":1684930165557,"channel":"futures.order_book_update","event":"update","result":{"U":203083179,"a":[{"p":"0.3004","s":36916}],"b":[{"p":"0.2943","s":0}],"s":"RDNT_USDT","t":1684930165459,"u":203083180}}
1684930166.5359862: {"time":1684930165,"time_ms":1684930165559,"channel":"futures.order_book_update","event":"update","result":{"U":3132789248,"a":[],"b":[{"p":"0.7696","s":1056}],"s":"OMG_USDT","t":1684930165498,"u":3132789248}}
1684930166.825836: {"time":1684930165,"time_ms":1684930165562,"channel":"futures.order_book_update","event":"update","result":{"U":6159963,"a":[{"p":"0.7394","s":1014}],"b":[{"p":"0.7376","s":962}],"s":"PHB_USDT","t":1684930165522,"u":6159966}}
1684930167.1087258: {"time":1684930165,"time_ms":1684930165631,"channel":"futures.book_ticker","event":"update","result":{"t":1684930165621,"u":6159967,"s":"PHB_USDT","b":"0.7379","B":814,"a":"0.739","A":677}}
1684930167.1087494: {"time":1684930165,"time_ms":1684930165655,"channel":"futures.order_book_update","event":"update","result":{"U":6159967,"a":[{"p":"0.739","s":677},{"p":"1.0147","s":12},{"p":"0.7543","s":90},{"p":"0.7442","s":312},{"p":"0.74","s":1403}],"b":[],"s":"PHB_USDT","t":1684930165621,"u":6159967}}
1684930167.1087644: {"time":1684930165,"time_ms":1684930165711,"channel":"futures.order_book_update","event":"update","result":{"U":244770079,"a":[],"b":[{"p":"0.1654","s":10717},{"p":"0.1662","s":15081},{"p":"0.1592","s":1}],"s":"FRONT_USDT","t":1684930165610,"u":244770079}}
1684930167.3935735: {"time":1684930165,"time_ms":1684930165752,"channel":"futures.order_book_update","event":"update","result":{"U":3132789249,"a":[],"b":[{"p":"0.7696","s":1921}],"s":"OMG_USDT","t":1684930165739,"u":3132789249}}
1684930167.3935926: {"time":1684930165,"time_ms":1684930165761,"channel":"futures.order_book_update","event":"update","result":{"U":203083181,"a":[{"p":"0.2998","s":562},{"p":"0.3004","s":37478},{"p":"0.3224","s":1},{"p":"0.3046","s":128}],"b":[{"p":"0.2916","s":2016},{"p":"0.2745","s":1},{"p":"0.2917","s":1007},{"p":"0.2943","s":562},{"p":"0.2965","s":4967},{"p":"0.2948","s":562},{"p":"0.2734","s":1}],"s":"RDNT_USDT","t":1684930165739,"u":203083185}}
1684930167.3936112: {"time":1684930165,"time_ms":1684930165851,"channel":"futures.order_book_update","event":"update","result":{"U":6159968,"a":[{"p":"0.991","s":11},{"p":"0.7542","s":44},{"p":"0.776","s":13},{"p":"0.7396","s":746},{"p":"0.7761","s":0},{"p":"0.7424","s":819},{"p":"0.7399","s":681}],"b":[],"s":"PHB_USDT","t":1684930165843,"u":6159970}}
1684930167.3936243: {"time":1684930165,"time_ms":1684930165934,"channel":"futures.candlesticks","event":"update","result":[{"t":1684930140,"v":0,"c":"0.1701","h":"0.1701","l":"0.1701","o":"0.1701","n":"1m_FRONT_USDT"}]}
1684930167.3936474: {"time":1684930165,"time_ms":1684930165956,"channel":"futures.order_book_update","event":"update","result":{"U":203083186,"a":[{"p":"0.3224","s":1},{"p":"0.3046","s":128},{"p":"0.298","s":5298},{"p":"0.2978","s":24799},{"p":"0.2992","s":1336},{"p":"0.2981","s":25777}],"b":[{"p":"0.2965","s":1338},{"p":"0.2745","s":1},{"p":"0.2917","s":1007},{"p":"0.2948","s":562},{"p":"0.2969","s":4751},{"p":"0.2968","s":11879},{"p":"0.297","s":4064}],"s":"RDNT_USDT","t":1684930165943,"u":203083193}}
1684930167.3936625: {"time":1684930165,"time_ms":1684930165959,"channel":"futures.order_book_update","event":"update","result":{"U":3132789250,"a":[{"p":"0.7717","s":677},{"p":"1.2532","s":0},{"p":"0.7728","s":50},{"p":"0.8126","s":177},{"p":"0.7774","s":2160},{"p":"0.7723","s":2689}],"b":[{"p":"0.7696","s":1056}],"s":"OMG_USDT","t":1684930165911,"u":3132789252}}
1684930167.3936765: {"time":1684930165,"time_ms":1684930165963,"channel":"futures.order_book_update","event":"update","result":{"U":6159971,"a":[{"p":"0.7908","s":25},{"p":"0.8056","s":41},{"p":"0.8057","s":0},{"p":"0.7909","s":0},{"p":"0.7394","s":1014},{"p":"0.991","s":11}],"b":[{"p":"0.7376","s":962}],"s":"PHB_USDT","t":1684930165893,"u":6159978}}
1684930167.3936875: {"time":1684930165,"time_ms":1684930165971,"channel":"futures.book_ticker","event":"update","result":{"t":1684930165960,"u":203083200,"s":"RDNT_USDT","b":"0.2972","B":5383,"a":"0.2976","A":8456}}
1684930167.3937016: {"time":1684930166,"time_ms":1684930166001,"channel":"futures.book_ticker","event":"update","result":{"t":1684930165991,"u":203083217,"s":"RDNT_USDT","b":"0.2972","B":5383,"a":"0.2976","A":10552}}
1684930167.3937123: {"time":1684930166,"time_ms":1684930166021,"channel":"futures.book_ticker","event":"update","result":{"t":1684930166009,"u":203083225,"s":"RDNT_USDT","b":"0.297","B":4064,"a":"0.2975","A":772}}
1684930167.3937223: {"time":1684930166,"time_ms":1684930166031,"channel":"futures.book_ticker","event":"update","result":{"t":1684930166020,"u":203083231,"s":"RDNT_USDT","b":"0.297","B":4064,"a":"0.2975","A":1917}}
1684930167.3937325: {"time":1684930166,"time_ms":1684930166041,"channel":"futures.book_ticker","event":"update","result":{"t":1684930166031,"u":203083233,"s":"RDNT_USDT","b":"0.297","B":4064,"a":"0.2975","A":3368}}
1684930167.3937428: {"time":1684930166,"time_ms":1684930166057,"channel":"futures.order_book_update","event":"update","result":{"U":203083194,"a":[{"p":"0.2982","s":3505},{"p":"0.2981","s":25215},{"p":"0.2975","s":3368},{"p":"0.2979","s":6969},{"p":"0.2977","s":335},{"p":"0.3067","s":0},{"p":"0.3038","s":0},{"p":"0.2983","s":0},{"p":"0.2992","s":1336},{"p":"0.2976","s":8456},{"p":"0.3047","s":8393},{"p":"0.298","s":5298},{"p":"0.3242","s":1}],"b":[{"p":"0.2964","s":0},{"p":"0.2965","s":1247},{"p":"0.292","s":133},{"p":"0.2888","s":0},{"p":"0.2972","s":0},{"p":"0.2948","s":0},{"p":"0.2966","s":24799},{"p":"0.2968","s":8393},{"p":"0.2943","s":0},{"p":"0.2953","s":42549},{"p":"0.2756","s":1},{"p":"0.2967","s":28283},{"p":"0.2963","s":7544},{"p":"0.2969","s":3504},{"p":"0.2917","s":0}],"s":"RDNT_USDT","t":1684930166047,"u":203083234}}
1684930167.393766: {"time":1684930166,"time_ms":1684930166060,"channel":"futures.order_book_update","event":"update","result":{"U":3132789253,"a":[{"p":"0.7717","s":2022},{"p":"0.7723","s":1345}],"b":[],"s":"OMG_USDT","t":1684930166016,"u":3132789254}}
1684930167.3937755: {"time":1684930166,"time_ms":1684930166071,"channel":"futures.book_ticker","event":"update","result":{"t":1684930166066,"u":203083249,"s":"RDNT_USDT","b":"0.297","B":4064,"a":"0.2974","A":63}}
1684930167.393786: {"time":1684930166,"time_ms":1684930166085,"channel":"futures.order_book_update","event":"update","result":{"U":124930260,"a":[{"p":"57.22","s":1745}],"b":[],"s":"QUICK_USDT","t":1684930166017,"u":124930260}}
1684930167.6760082: {"time":1684930166,"time_ms":1684930166157,"channel":"futures.order_book_update","event":"update","result":{"U":203083235,"a":[{"p":"0.3033","s":1009},{"p":"0.2986","s":87043},{"p":"0.298","s":0},{"p":"0.2974","s":63},{"p":"0.2979","s":3486},{"p":"0.2978","s":26895},{"p":"0.2977","s":5229},{"p":"0.2975","s":1272},{"p":"0.3063","s":1681},{"p":"0.2976","s":8393},{"p":"0.3225","s":13},{"p":"0.3046","s":128},{"p":"0.3224","s":1}],"b":[{"p":"0.2946","s":2714},{"p":"0.2967","s":31769},{"p":"0.2964","s":1338},{"p":"0.2906","s":8393},{"p":"0.271","s":3},{"p":"0.2963","s":13065},{"p":"0.2914","s":1009},{"p":"0.2719","s":1},{"p":"0.2968","s":9640},{"p":"0.2705","s":74},{"p":"0.29","s":20},{"p":"0.2944","s":34254},{"p":"0.2884","s":1681},{"p":"0.2969","s":8806},{"p":"0.2965","s":0}],"s":"RDNT_USDT","t":1684930166147,"u":203083258}}
1684930167.6760428: {"time":1684930166,"time_ms":1684930166160,"channel":"futures.order_book_update","event":"update","result":{"U":3132789255,"a":[],"b":[{"p":"0.7696","s":1056}],"s":"OMG_USDT","t":1684930166130,"u":3132789256}}
1684930167.6760578: {"time":1684930166,"time_ms":1684930166171,"channel":"futures.book_ticker","event":"update","result":{"t":1684930166163,"u":203083260,"s":"RDNT_USDT","b":"0.297","B":4064,"a":"0.2974","A":803}}
1684930167.6760745: {"time":1684930166,"time_ms":1684930166241,"channel":"futures.book_ticker","event":"update","result":{"t":1684930166224,"u":203083262,"s":"RDNT_USDT","b":"0.2969","B":5302,"a":"0.2974","A":803}}
1684930167.6760862: {"time":1684930166,"time_ms":1684930166271,"channel":"futures.order_book_update","event":"update","result":{"U":203083259,"a":[{"p":"0.3224","s":1},{"p":"0.3046","s":128},{"p":"0.3004","s":34816},{"p":"0.3017","s":4205},{"p":"0.2975","s":500},{"p":"0.2974","s":803},{"p":"0.2992","s":0},{"p":"0.3016","s":0}],"b":[{"p":"0.2969","s":5302},{"p":"0.2958","s":84389},{"p":"0.2946","s":1357},{"p":"0.297","s":0}],"s":"RDNT_USDT","t":1684930166263,"u":203083272}}
1684930167.6761014: {"time":1684930166,"time_ms":1684930166366,"channel":"futures.order_book_update","event":"update","result":{"U":203083273,"a":[{"p":"0.3036","s":2016},{"p":"0.3244","s":0},{"p":"0.3125","s":0}],"b":[{"p":"0.2899","s":17684},{"p":"0.2912","s":17803},{"p":"0.2967","s":35878},{"p":"0.2966","s":29644},{"p":"0.2964","s":0},{"p":"0.2934","s":0},{"p":"0.2946","s":0},{"p":"0.2701","s":1},{"p":"0.2931","s":80177},{"p":"0.2965","s":586},{"p":"0.2963","s":12511},{"p":"0.2823","s":0},{"p":"0.2704","s":0}],"s":"RDNT_USDT","t":1684930166326,"u":203083287}}
1684930167.6761167: {"time":1684930166,"time_ms":1684930166453,"channel":"futures.order_book_update","event":"update","result":{"U":203083288,"a":[{"p":"0.3013","s":5310},{"p":"0.3224","s":1},{"p":"0.3043","s":953},{"p":"0.2989","s":1338},{"p":"0.3001","s":2664},{"p":"0.3225","s":13},{"p":"0.3046","s":128},{"p":"0.322","s":1},{"p":"0.3036","s":2016},{"p":"0.2977","s":4894},{"p":"0.2975","s":835}],"b":[{"p":"0.2943","s":2718},{"p":"0.2705","s":74},{"p":"0.29","s":20},{"p":"0.2701","s":1},{"p":"0.2899","s":17684},{"p":"0.2931","s":80177},{"p":"0.2955","s":1352}],"s":"RDNT_USDT","t":1684930166441,"u":203083299}}
1684930167.676218: {"time":1684930166,"time_ms":1684930166456,"channel":"futures.order_book_update","event":"update","result":{"U":3132789257,"a":[],"b":[{"p":"0.7696","s":1921}],"s":"OMG_USDT","t":1684930166367,"u":3132789257}}
1684930167.6762307: {"time":1684930166,"time_ms":1684930166557,"channel":"futures.order_book_update","event":"update","result":{"U":203083300,"a":[],"b":[{"p":"0.2966","s":26137},{"p":"0.2931","s":85635}],"s":"RDNT_USDT","t":1684930166464,"u":203083302}}
1684930167.6762574: {"time":1684930166,"time_ms":1684930166562,"channel":"futures.order_book_update","event":"update","result":{"U":3132789258,"a":[],"b":[{"p":"0.7696","s":1056}],"s":"OMG_USDT","t":1684930166524,"u":3132789258}}
1684930167.6762679: {"time":1684930166,"time_ms":1684930166591,"channel":"futures.order_book_update","event":"update","result":{"U":536375571,"a":[{"p":"0.2112","s":15938}],"b":[{"p":"0.209","s":33726}],"s":"WOO_USDT","t":1684930166490,"u":536375572}}
1684930167.963558: {"time":1684930166,"time_ms":1684930166661,"channel":"futures.order_book_update","event":"update","result":{"U":3132789259,"a":[],"b":[{"p":"0.7696","s":1921}],"s":"OMG_USDT","t":1684930166585,"u":3132789259}}
1684930167.9635775: {"time":1684930166,"time_ms":1684930166756,"channel":"futures.order_book_update","event":"update","result":{"U":3132789260,"a":[],"b":[{"p":"0.7696","s":1921}],"s":"OMG_USDT","t":1684930166746,"u":3132789261}}
1684930167.9636319: {"time":1684930166,"time_ms":1684930166856,"channel":"futures.order_book_update","event":"update","result":{"U":3132789262,"a":[],"b":[{"p":"0.7696","s":1056},{"p":"0.7693","s":832},{"p":"0.769","s":1345},{"p":"0.73","s":1300},{"p":"0.765","s":1104},{"p":"0.7688","s":1345}],"s":"OMG_USDT","t":1684930166851,"u":3132789264}}
1684930167.9636703: {"time":1684930167,"time_ms":1684930167056,"channel":"futures.order_book_update","event":"update","result":{"U":203083303,"a":[],"b":[{"p":"0.2966","s":24799},{"p":"0.2968","s":10978}],"s":"RDNT_USDT","t":1684930166960,"u":203083304}}
1684930167.963693: {"time":1684930167,"time_ms":1684930167089,"channel":"futures.order_book_update","event":"update","result":{"U":124930261,"a":[{"p":"57.42","s":4572},{"p":"57.5","s":189},{"p":"83.87","s":500},{"p":"59.84","s":1},{"p":"57.83","s":481}],"b":[],"s":"QUICK_USDT","t":1684930167030,"u":124930261}}
1684930167.963706: {"time":1684930167,"time_ms":1684930167150,"channel":"futures.order_book_update","event":"update","result":{"U":203083305,"a":[],"b":[{"p":"0.2912","s":17803},{"p":"0.271","s":3},{"p":"0.2906","s":8393},{"p":"0.2938","s":562},{"p":"0.2933","s":562},{"p":"0.2719","s":1}],"s":"RDNT_USDT","t":1684930167132,"u":203083306}}
1684930167.9637382: {"time":1684930167,"time_ms":1684930167257,"channel":"futures.order_book_update","event":"update","result":{"U":203083307,"a":[{"p":"0.2998","s":0},{"p":"0.2976","s":11881}],"b":[],"s":"RDNT_USDT","t":1684930167215,"u":203083308}}
1684930167.9637606: {"time":1684930167,"time_ms":1684930167309,"channel":"futures.book_ticker","event":"update","result":{"t":1684930167295,"u":536375573,"s":"WOO_USDT","b":"0.21","B":3319,"a":"0.2102","A":748}}
1684930167.9637764: {"time":1684930167,"time_ms":1684930167329,"channel":"futures.book_ticker","event":"update","result":{"t":1684930167313,"u":536375574,"s":"WOO_USDT","b":"0.21","B":3319,"a":"0.2103","A":5247}}
1684930167.9637876: {"time":1684930167,"time_ms":1684930167360,"channel":"futures.book_ticker","event":"update","result":{"t":1684930167344,"u":536375575,"s":"WOO_USDT","b":"0.21","B":3319,"a":"0.2103","A":4625}}
1684930167.963798: {"time":1684930167,"time_ms":1684930167369,"channel":"futures.book_ticker","event":"update","result":{"t":1684930167359,"u":536375576,"s":"WOO_USDT","b":"0.21","B":3319,"a":"0.2103","A":5593}}
1684930167.9638083: {"time":1684930167,"time_ms":1684930167398,"channel":"futures.order_book_update","event":"update","result":{"U":536375573,"a":[{"p":"0.2123","s":18774},{"p":"0.2108","s":20080},{"p":"0.2103","s":5593},{"p":"0.2102","s":0},{"p":"0.2287","s":1},{"p":"0.2143","s":15150}],"b":[],"s":"WOO_USDT","t":1684930167359,"u":536375576}}
1684930167.96382: {"time":1684930167,"time_ms":1684930167562,"channel":"futures.order_book_update","event":"update","result":{"U":6159979,"a":[],"b":[{"p":"0.7377","s":53}],"s":"PHB_USDT","t":1684930167452,"u":6159979}}
1684930167.9638553: {"time":1684930167,"time_ms":1684930167584,"channel":"futures.order_book_update","event":"update","result":{"U":124930262,"a":[{"p":"57.41","s":189},{"p":"57.5","s":0},{"p":"57.42","s":4572},{"p":"83.87","s":500},{"p":"59.84","s":1},{"p":"57.83","s":481}],"b":[],"s":"QUICK_USDT","t":1684930167521,"u":124930263}}
1684930167.9638681: {"time":1684930167,"time_ms":1684930167600,"channel":"futures.book_ticker","event":"update","result":{"t":1684930167592,"u":536375578,"s":"WOO_USDT","b":"0.21","B":3319,"a":"0.2102","A":748}}
1684930167.9638793: {"time":1684930167,"time_ms":1684930167610,"channel":"futures.book_ticker","event":"update","result":{"t":1684930167603,"u":536375580,"s":"WOO_USDT","b":"0.21","B":3319,"a":"0.2103","A":5593}}
1684930167.963893: {"time":1684930167,"time_ms":1684930167689,"channel":"futures.order_book_update","event":"update","result":{"U":536375577,"a":[{"p":"0.2102","s":0},{"p":"0.2287","s":1},{"p":"0.2143","s":15150},{"p":"0.2123","s":18774},{"p":"0.2108","s":20080},{"p":"0.2112","s":20465}],"b":[{"p":"0.209","s":39418}],"s":"WOO_USDT","t":1684930167603,"u":536375580}}
1684930168.1090193: {"time":1684930167,"time_ms":1684930167959,"channel":"futures.order_book_update","event":"update","result":{"U":3132789265,"a":[],"b":[{"p":"0.7696","s":1921}],"s":"OMG_USDT","t":1684930167878,"u":3132789265}}
1684930168.3026562: {"time":1684930168,"time_ms":1684930168153,"channel":"futures.order_book_update","event":"update","result":{"U":3132789266,"a":[],"b":[{"p":"0.7696","s":1056}],"s":"OMG_USDT","t":1684930168120,"u":3132789266}}
1684930168.3137863: {"time":1684930168,"time_ms":1684930168164,"channel":"futures.order_book_update","event":"update","result":{"U":203083309,"a":[],"b":[{"p":"0.293","s":24799}],"s":"RDNT_USDT","t":1684930168065,"u":203083309}}
1684930168.4026766: {"time":1684930168,"time_ms":1684930168253,"channel":"futures.order_book_update","event":"update","result":{"U":203083310,"a":[{"p":"0.3004","s":34254}],"b":[{"p":"0.2938","s":0},{"p":"0.2729","s":1},{"p":"0.2914","s":1009},{"p":"0.2927","s":4205}],"s":"RDNT_USDT","t":1684930168226,"u":203083312}}
1684930168.4055543: {"time":1684930168,"time_ms":1684930168256,"channel":"futures.order_book_update","event":"update","result":{"U":3132789267,"a":[],"b":[{"p":"0.7696","s":1921}],"s":"OMG_USDT","t":1684930168151,"u":3132789267}}
1684930168.5073721: {"time":1684930168,"time_ms":1684930168357,"channel":"futures.order_book_update","event":"update","result":{"U":3132789268,"a":[],"b":[{"p":"0.7696","s":1056}],"s":"OMG_USDT","t":1684930168349,"u":3132789268}}
1684930168.7042248: {"time":1684930168,"time_ms":1684930168554,"channel":"futures.order_book_update","event":"update","result":{"U":203083313,"a":[{"p":"0.3001","s":3226},{"p":"0.322","s":1},{"p":"0.3036","s":2016},{"p":"0.2996","s":562}],"b":[{"p":"0.2963","s":12017}],"s":"RDNT_USDT","t":1684930168538,"u":203083315}}
1684930168.7071095: {"time":1684930168,"time_ms":1684930168557,"channel":"futures.order_book_update","event":"update","result":{"U":3132789269,"a":[],"b":[{"p":"0.7696","s":1921}],"s":"OMG_USDT","t":1684930168486,"u":3132789269}}
1684930168.7098417: {"time":1684930168,"time_ms":1684930168560,"channel":"futures.order_book_update","event":"update","result":{"U":6159980,"a":[],"b":[{"p":"0.7377","s":1465}],"s":"PHB_USDT","t":1684930168536,"u":6159980}}
1684930168.9084196: {"time":1684930168,"time_ms":1684930168759,"channel":"futures.order_book_update","event":"update","result":{"U":203083316,"a":[],"b":[{"p":"0.2933","s":0}],"s":"RDNT_USDT","t":1684930168716,"u":203083316}}
1684930169.0005784: {"time":1684930168,"time_ms":1684930168851,"channel":"futures.order_book_update","event":"update","result":{"U":203083317,"a":[{"p":"0.2981","s":24799}],"b":[{"p":"0.2963","s":13130}],"s":"RDNT_USDT","t":1684930168832,"u":203083318}}
1684930169.101963: {"time":1684930168,"time_ms":1684930168952,"channel":"futures.order_book_update","event":"update","result":{"U":3132789270,"a":[],"b":[{"p":"0.7696","s":1056}],"s":"OMG_USDT","t":1684930168851,"u":3132789270}}
1684930169.2049987: {"time":1684930169,"time_ms":1684930169055,"channel":"futures.order_book_update","event":"update","result":{"U":203083319,"a":[],"b":[{"p":"0.2944","s":34254},{"p":"0.2941","s":562},{"p":"0.2946","s":562},{"p":"0.2729","s":1},{"p":"0.2914","s":1009},{"p":"0.2719","s":1},{"p":"0.2912","s":17803}],"s":"RDNT_USDT","t":1684930168960,"u":203083320}}
1684930169.3031645: {"time":1684930169,"time_ms":1684930169153,"channel":"futures.order_book_update","event":"update","result":{"U":203083321,"a":[{"p":"0.2981","s":28161}],"b":[],"s":"RDNT_USDT","t":1684930169051,"u":203083321}}
1684930169.3319166: {"time":1684930169,"time_ms":1684930169182,"channel":"futures.order_book_update","event":"update","result":{"U":536375581,"a":[{"p":"0.2287","s":1},{"p":"0.2143","s":15150},{"p":"0.2123","s":18774},{"p":"0.2112","s":63995},{"p":"0.2113","s":12596}],"b":[{"p":"0.2088","s":1914},{"p":"0.2089","s":8151},{"p":"0.209","s":99413},{"p":"0.1931","s":1},{"p":"0.2062","s":7985}],"s":"WOO_USDT","t":1684930169134,"u":536375598}}
1684930169.5029297: {"time":1684930169,"time_ms":1684930169353,"channel":"futures.order_book_update","event":"update","result":{"U":6159981,"a":[{"p":"0.7394","s":807},{"p":"0.7543","s":90},{"p":"0.7398","s":682},{"p":"0.7393","s":272},{"p":"0.7401","s":0},{"p":"0.7399","s":0},{"p":"1.0147","s":12},{"p":"0.7442","s":312},{"p":"0.74","s":2124}],"b":[{"p":"0.7326","s":0},{"p":"0.7105","s":1},{"p":"0.7372","s":1404},{"p":"0.737","s":1507},{"p":"0.7377","s":1412},{"p":"0.7371","s":682},{"p":"0.7376","s":1015}],"s":"PHB_USDT","t":1684930169322,"u":6159997}}
1684930169.6068885: {"time":1684930169,"time_ms":1684930169457,"channel":"futures.order_book_update","event":"update","result":{"U":3132789271,"a":[],"b":[{"p":"0.7696","s":1921}],"s":"OMG_USDT","t":1684930169422,"u":3132789271}}
1684930169.6094358: {"time":1684930169,"time_ms":1684930169460,"channel":"futures.order_book_update","event":"update","result":{"U":6159998,"a":[{"p":"0.7394","s":96}],"b":[{"p":"0.7322","s":2032},{"p":"0.7105","s":1}],"s":"PHB_USDT","t":1684930169412,"u":6159999}}
1684930169.705517: {"time":1684930169,"time_ms":1684930169556,"channel":"futures.order_book_update","event":"update","result":{"U":203083322,"a":[{"p":"0.2996","s":0}],"b":[{"p":"0.2967","s":39385}],"s":"RDNT_USDT","t":1684930169473,"u":203083323}}
1684930169.788923: {"time":1684930169,"time_ms":1684930169639,"channel":"futures.book_ticker","event":"update","result":{"t":1684930169633,"u":536375600,"s":"WOO_USDT","b":"0.21","B":3319,"a":"0.2103","A":5292}}
1684930169.8362324: {"time":1684930169,"time_ms":1684930169687,"channel":"futures.order_book_update","event":"update","result":{"U":536375599,"a":[{"p":"0.2103","s":5292},{"p":"0.2105","s":58512}],"b":[],"s":"WOO_USDT","t":1684930169678,"u":536375601}}
1684930169.8601713: {"time":1684930169,"time_ms":1684930169711,"channel":"futures.order_book_update","event":"update","result":{"U":571312380,"a":[],"b":[{"p":"0.2217","s":0}],"s":"ZRX_USDT","t":1684930169680,"u":571312380}}
1684930170.1430142: {"time":1684930169,"time_ms":1684930169961,"channel":"futures.book_ticker","event":"update","result":{"t":1684930169952,"u":6160000,"s":"PHB_USDT","b":"0.7379","B":814,"a":"0.739","A":1354}}
1684930170.1430464: {"time":1684930169,"time_ms":1684930169973,"channel":"futures.order_book_update","event":"update","result":{"U":3132789272,"a":[],"b":[{"p":"0.7696","s":1921}],"s":"OMG_USDT","t":1684930169924,"u":3132789273}}
1684930170.1430824: {"time":1684930169,"time_ms":1684930169992,"channel":"futures.order_book_update","event":"update","result":{"U":536375602,"a":[],"b":[{"p":"0.209","s":89700}],"s":"WOO_USDT","t":1684930169905,"u":536375602}}
1684930170.1598945: {"time":1684930170,"time_ms":1684930170010,"channel":"futures.book_ticker","event":"update","result":{"t":1684930169995,"u":536375603,"s":"WOO_USDT","b":"0.21","B":3319,"a":"0.2102","A":708}}
1684930170.1788442: {"time":1684930170,"time_ms":1684930170029,"channel":"futures.book_ticker","event":"update","result":{"t":1684930170014,"u":536375604,"s":"WOO_USDT","b":"0.21","B":3319,"a":"0.2103","A":5292}}
1684930170.2056053: {"time":1684930170,"time_ms":1684930170056,"channel":"futures.order_book_update","event":"update","result":{"U":3132789274,"a":[],"b":[{"p":"0.7696","s":1056}],"s":"OMG_USDT","t":1684930170020,"u":3132789274}}
1684930170.2105272: {"time":1684930170,"time_ms":1684930170061,"channel":"futures.order_book_update","event":"update","result":{"U":6160000,"a":[{"p":"0.739","s":1354}],"b":[],"s":"PHB_USDT","t":1684930169952,"u":6160000}}
1684930170.2298973: {"time":1684930170,"time_ms":1684930170080,"channel":"futures.order_book_update","event":"update","result":{"U":536375603,"a":[{"p":"0.2102","s":0},{"p":"0.228","s":88},{"p":"0.2142","s":1687},{"p":"0.212","s":7757},{"p":"0.2108","s":20080}],"b":[],"s":"WOO_USDT","t":1684930170014,"u":536375604}}
1684930170.509122: {"time":1684930170,"time_ms":1684930170359,"channel":"futures.order_book_update","event":"update","result":{"U":6160001,"a":[{"p":"0.7395","s":0}],"b":[],"s":"PHB_USDT","t":1684930170297,"u":6160001}}
1684930170.5355022: {"time":1684930170,"time_ms":1684930170386,"channel":"futures.order_book_update","event":"update","result":{"U":536375605,"a":[],"b":[{"p":"0.2094","s":19417}],"s":"WOO_USDT","t":1684930170351,"u":536375606}}
1684930170.5688138: {"time":1684930170,"time_ms":1684930170419,"channel":"futures.book_ticker","event":"update","result":{"t":1684930170405,"u":536375609,"s":"WOO_USDT","b":"0.21","B":3319,"a":"0.2103","A":5593}}
1684930170.6012323: {"time":1684930170,"time_ms":1684930170451,"channel":"futures.order_book_update","event":"update","result":{"U":6160002,"a":[{"p":"0.7394","s":1412},{"p":"1.0147","s":12},{"p":"0.7543","s":90},{"p":"0.7442","s":312},{"p":"0.7398","s":682},{"p":"0.7392","s":96}],"b":[],"s":"PHB_USDT","t":1684930170389,"u":6160006}}
1684930170.6388032: {"time":1684930170,"time_ms":1684930170489,"channel":"futures.order_book_update","event":"update","result":{"U":536375607,"a":[{"p":"0.2103","s":5593}],"b":[{"p":"0.2094","s":24380}],"s":"WOO_USDT","t":1684930170405,"u":536375609}}
1684930170.6586175: {"time":1684930170,"time_ms":1684930170509,"channel":"futures.book_ticker","event":"update","result":{"t":1684930170493,"u":536375610,"s":"WOO_USDT","b":"0.21","B":3319,"a":"0.2102","A":708}}
1684930170.6787503: {"time":1684930170,"time_ms":1684930170529,"channel":"futures.book_ticker","event":"update","result":{"t":1684930170513,"u":536375611,"s":"WOO_USDT","b":"0.21","B":3319,"a":"0.2103","A":5593}}
1684930170.7001486: {"time":1684930170,"time_ms":1684930170550,"channel":"futures.order_book_update","event":"update","result":{"U":6160007,"a":[{"p":"0.7393","s":207},{"p":"0.7391","s":65},{"p":"0.991","s":11},{"p":"0.7542","s":44},{"p":"0.7424","s":819},{"p":"0.7396","s":746}],"b":[],"s":"PHB_USDT","t":1684930170472,"u":6160008}}
1684930170.711142: {"time":1684930170,"time_ms":1684930170561,"channel":"futures.order_book_update","event":"update","result":{"U":3132789275,"a":[],"b":[{"p":"0.7696","s":1056}],"s":"OMG_USDT","t":1684930170540,"u":3132789276}}
1684930170.7351124: {"time":1684930170,"time_ms":1684930170585,"channel":"futures.order_book_update","event":"update","result":{"U":536375610,"a":[{"p":"0.2102","s":0},{"p":"0.2108","s":20080},{"p":"0.228","s":88},{"p":"0.2142","s":1687},{"p":"0.212","s":7757},{"p":"0.2105","s":43842}],"b":[],"s":"WOO_USDT","t":1684930170560,"u":536375613}}
1684930170.8042984: {"time":1684930170,"time_ms":1684930170654,"channel":"futures.order_book_update","event":"update","result":{"U":203083324,"a":[],"b":[{"p":"0.2909","s":30},{"p":"0.2734","s":1}],"s":"RDNT_USDT","t":1684930170620,"u":203083324}}
1684930170.902396: {"time":1684930170,"time_ms":1684930170752,"channel":"futures.order_book_update","event":"update","result":{"U":203083325,"a":[{"p":"0.322","s":1},{"p":"0.3036","s":2016},{"p":"0.32","s":4},{"p":"0.3034","s":32},{"p":"0.3001","s":2664},{"p":"0.3242","s":97},{"p":"0.3123","s":71}],"b":[{"p":"0.2745","s":1},{"p":"0.2701","s":104},{"p":"0.282","s":67},{"p":"0.2946","s":0}],"s":"RDNT_USDT","t":1684930170714,"u":203083331}}
1684930171.0464952: {"time":1684930170,"time_ms":1684930170897,"channel":"futures.order_book_update","event":"update","result":{"U":536375614,"a":[{"p":"0.2105","s":50198}],"b":[],"s":"WOO_USDT","t":1684930170822,"u":536375614}}
1684930171.0702853: {"time":1684930170,"time_ms":1684930170919,"channel":"futures.book_ticker","event":"update","result":{"t":1684930170904,"u":536375616,"s":"WOO_USDT","b":"0.21","B":3319,"a":"0.2103","A":3110}}
1684930171.0788069: {"time":1684930170,"time_ms":1684930170929,"channel":"futures.book_ticker","event":"update","result":{"t":1684930170914,"u":536375617,"s":"WOO_USDT","b":"0.21","B":3319,"a":"0.2102","A":664}}
1684930171.0889554: {"time":1684930170,"time_ms":1684930170939,"channel":"futures.book_ticker","event":"update","result":{"t":1684930170926,"u":536375618,"s":"WOO_USDT","b":"0.21","B":3319,"a":"0.2103","A":3110}}
1684930171.115193: {"time":1684930170,"time_ms":1684930170965,"channel":"futures.order_book_update","event":"update","result":{"U":3132789277,"a":[],"b":[{"p":"0.7696","s":1921}],"s":"OMG_USDT","t":1684930170888,"u":3132789277}}
1684930171.1380763: {"time":1684930170,"time_ms":1684930170988,"channel":"futures.order_book_update","event":"update","result":{"U":536375615,"a":[{"p":"0.2103","s":3110},{"p":"0.2105","s":43842},{"p":"0.2102","s":0},{"p":"0.228","s":88},{"p":"0.2142","s":1687},{"p":"0.212","s":7757},{"p":"0.2108","s":20080},{"p":"0.2104","s":4831}],"b":[],"s":"WOO_USDT","t":1684930170939,"u":536375619}}
1684930171.2074938: {"time":1684930171,"time_ms":1684930171058,"channel":"futures.order_book_update","event":"update","result":{"U":203083332,"a":[{"p":"0.2996","s":562},{"p":"0.3001","s":3226},{"p":"0.3196","s":1},{"p":"0.3035","s":16846}],"b":[],"s":"RDNT_USDT","t":1684930170960,"u":203083333}}
1684930171.234984: {"time":1684930171,"time_ms":1684930171085,"channel":"futures.order_book_update","event":"update","result":{"U":536375620,"a":[{"p":"0.2105","s":52672}],"b":[],"s":"WOO_USDT","t":1684930170986,"u":536375620}}
1684930171.2787142: {"time":1684930171,"time_ms":1684930171129,"channel":"futures.book_ticker","event":"update","result":{"t":1684930171117,"u":536375621,"s":"WOO_USDT","b":"0.21","B":3319,"a":"0.2102","A":664}}
1684930171.2988303: {"time":1684930171,"time_ms":1684930171149,"channel":"futures.book_ticker","event":"update","result":{"t":1684930171133,"u":536375622,"s":"WOO_USDT","b":"0.21","B":3319,"a":"0.2103","A":3110}}
1684930171.3192677: {"time":1684930171,"time_ms":1684930171169,"channel":"futures.book_ticker","event":"update","result":{"t":1684930171164,"u":536375623,"s":"WOO_USDT","b":"0.21","B":3319,"a":"0.2103","A":2142}}
1684930171.328809: {"time":1684930171,"time_ms":1684930171179,"channel":"futures.book_ticker","event":"update","result":{"t":1684930171166,"u":536375624,"s":"WOO_USDT","b":"0.21","B":3319,"a":"0.2103","A":2818}}
1684930171.3500707: {"time":1684930171,"time_ms":1684930171201,"channel":"futures.order_book_update","event":"update","result":{"U":536375621,"a":[{"p":"0.228","s":88},{"p":"0.2142","s":1687},{"p":"0.212","s":7757},{"p":"0.2108","s":20080},{"p":"0.2103","s":2818},{"p":"0.2102","s":0}],"b":[],"s":"WOO_USDT","t":1684930171166,"u":536375624}}
1684930171.4033415: {"time":1684930171,"time_ms":1684930171253,"channel":"futures.order_book_update","event":"update","result":{"U":203083334,"a":[],"b":[{"p":"0.2941","s":0}],"s":"RDNT_USDT","t":1684930171207,"u":203083334}}
1684930171.406612: {"time":1684930171,"time_ms":1684930171257,"channel":"futures.order_book_update","event":"update","result":{"U":3132789278,"a":[],"b":[{"p":"0.7696","s":1056}],"s":"OMG_USDT","t":1684930171225,"u":3132789278}}
1684930171.409833: {"time":1684930171,"time_ms":1684930171260,"channel":"futures.order_book_update","event":"update","result":{"U":6160009,"a":[{"p":"0.74","s":721}],"b":[],"s":"PHB_USDT","t":1684930171238,"u":6160009}}
1684930171.5063775: {"time":1684930171,"time_ms":1684930171356,"channel":"futures.order_book_update","event":"update","result":{"U":6160010,"a":[{"p":"0.7394","s":2825}],"b":[],"s":"PHB_USDT","t":1684930171280,"u":6160010}}
1684930171.6059217: {"time":1684930171,"time_ms":1684930171456,"channel":"futures.order_book_update","event":"update","result":{"U":203083335,"a":[],"b":[{"p":"0.2963","s":12017}],"s":"RDNT_USDT","t":1684930171441,"u":203083335}}
1684930171.708141: {"time":1684930171,"time_ms":1684930171558,"channel":"futures.order_book_update","event":"update","result":{"U":203083336,"a":[{"p":"0.2981","s":24799}],"b":[{"p":"0.2946","s":562},{"p":"0.2941","s":562},{"p":"0.2734","s":1},{"p":"0.2912","s":17803},{"p":"0.2944","s":34254},{"p":"0.2914","s":1009},{"p":"0.2745","s":1}],"s":"RDNT_USDT","t":1684930171547,"u":203083338}}
1684930171.71107: {"time":1684930171,"time_ms":1684930171561,"channel":"futures.order_book_update","event":"update","result":{"U":3132789279,"a":[{"p":"0.7712","s":129}],"b":[],"s":"OMG_USDT","t":1684930171551,"u":3132789279}}
1684930171.8038275: {"time":1684930171,"time_ms":1684930171654,"channel":"futures.order_book_update","event":"update","result":{"U":3132789280,"a":[],"b":[{"p":"0.7696","s":1921}],"s":"OMG_USDT","t":1684930171595,"u":3132789280}}
1684930171.9098651: {"time":1684930171,"time_ms":1684930171760,"channel":"futures.order_book_update","event":"update","result":{"U":6160011,"a":[{"p":"0.7394","s":1412}],"b":[],"s":"PHB_USDT","t":1684930171727,"u":6160011}}
1684930171.9642274: {"time":1684930171,"time_ms":1684930171815,"channel":"futures.order_book_update","event":"update","result":{"U":536375625,"a":[{"p":"0.2108","s":10380}],"b":[],"s":"WOO_USDT","t":1684930171749,"u":536375625}}
1684930172.007228: {"time":1684930171,"time_ms":1684930171857,"channel":"futures.order_book_update","event":"update","result":{"U":3132789281,"a":[],"b":[{"p":"0.7696","s":1056}],"s":"OMG_USDT","t":1684930171820,"u":3132789281}}
1684930172.0104325: {"time":1684930171,"time_ms":1684930171860,"channel":"futures.order_book_update","event":"update","result":{"U":6160012,"a":[{"p":"0.7442","s":312},{"p":"0.7398","s":682},{"p":"1.0147","s":12},{"p":"0.7392","s":65},{"p":"0.7394","s":1508},{"p":"0.7391","s":0},{"p":"0.7543","s":90}],"b":[],"s":"PHB_USDT","t":1684930171830,"u":6160017}}
1684930172.1054797: {"time":1684930171,"time_ms":1684930171955,"channel":"futures.order_book_update","event":"update","result":{"U":203083339,"a":[{"p":"0.2985","s":9363}],"b":[],"s":"RDNT_USDT","t":1684930171945,"u":203083339}}
1684930172.1092794: {"time":1684930171,"time_ms":1684930171960,"channel":"futures.book_ticker","event":"update","result":{"t":1684930171947,"u":536375627,"s":"WOO_USDT","b":"0.21","B":3319,"a":"0.2102","A":641}}
1684930172.128907: {"time":1684930171,"time_ms":1684930171979,"channel":"futures.book_ticker","event":"update","result":{"t":1684930171964,"u":536375628,"s":"WOO_USDT","b":"0.21","B":3319,"a":"0.2103","A":2818}}
1684930172.1334794: {"time":1684930171,"time_ms":1684930171984,"channel":"futures.order_book_update","event":"update","result":{"U":536375626,"a":[{"p":"0.2105","s":62375},{"p":"0.228","s":88},{"p":"0.2142","s":1687},{"p":"0.212","s":7757},{"p":"0.2108","s":10380},{"p":"0.2102","s":0}],"b":[],"s":"WOO_USDT","t":1684930171964,"u":536375628}}
1684930172.21447: {"time":1684930172,"time_ms":1684930172064,"channel":"futures.order_book_update","event":"update","result":{"U":203083340,"a":[{"p":"0.2981","s":27028},{"p":"0.2996","s":0}],"b":[{"p":"0.2963","s":13130}],"s":"RDNT_USDT","t":1684930172018,"u":203083342}}
1684930172.3006382: {"time":1684930172,"time_ms":1684930172151,"channel":"futures.order_book_update","event":"update","result":{"U":203083343,"a":[{"p":"0.2981","s":35657}],"b":[],"s":"RDNT_USDT","t":1684930172086,"u":203083343}}
1684930172.3033993: {"time":1684930172,"time_ms":1684930172154,"channel":"futures.order_book_update","event":"update","result":{"U":3132789282,"a":[],"b":[{"p":"0.7696","s":1921}],"s":"OMG_USDT","t":1684930172049,"u":3132789282}}
1684930172.4096231: {"time":1684930172,"time_ms":1684930172260,"channel":"futures.order_book_update","event":"update","result":{"U":3132789283,"a":[],"b":[{"p":"0.7013","s":0}],"s":"OMG_USDT","t":1684930172193,"u":3132789284}}
1684930172.5039456: {"time":1684930172,"time_ms":1684930172354,"channel":"futures.order_book_update","event":"update","result":{"U":3132789285,"a":[],"b":[{"p":"0.7696","s":1056}],"s":"OMG_USDT","t":1684930172330,"u":3132789285}}
1684930172.6073847: {"time":1684930172,"time_ms":1684930172457,"channel":"futures.order_book_update","event":"update","result":{"U":3132789286,"a":[],"b":[{"p":"0.7696","s":1921}],"s":"OMG_USDT","t":1684930172420,"u":3132789286}}
1684930172.7482557: {"time":1684930172,"time_ms":1684930172599,"channel":"futures.order_book_update","event":"update","result":{"U":536375629,"a":[{"p":"0.212","s":7757},{"p":"0.2108","s":10380},{"p":"0.2102","s":641},{"p":"0.228","s":88},{"p":"0.2142","s":1687}],"b":[],"s":"WOO_USDT","t":1684930172588,"u":536375629}}
1684930172.7487068: {"time":1684930172,"time_ms":1684930172599,"channel":"futures.book_ticker","event":"update","result":{"t":1684930172588,"u":536375629,"s":"WOO_USDT","b":"0.21","B":3319,"a":"0.2102","A":641}}
1684930172.7686071: {"time":1684930172,"time_ms":1684930172619,"channel":"futures.book_ticker","event":"update","result":{"t":1684930172603,"u":536375630,"s":"WOO_USDT","b":"0.21","B":3319,"a":"0.2103","A":2818}}
1684930172.8416045: {"time":1684930172,"time_ms":1684930172692,"channel":"futures.order_book_update","event":"update","result":{"U":536375630,"a":[{"p":"0.2112","s":11411},{"p":"0.2102","s":0},{"p":"0.2113","s":0}],"b":[{"p":"0.209","s":18299},{"p":"0.2089","s":0}],"s":"WOO_USDT","t":1684930172639,"u":536375652}}
1684930172.8442278: {"time":1684930172,"time_ms":1684930172695,"channel":"futures.order_book_update","event":"update","result":{"U":124930264,"a":[],"b":[{"p":"55.87","s":175},{"p":"55.93","s":0},{"p":"53.89","s":1}],"s":"QUICK_USDT","t":1684930172596,"u":124930265}}
1684930172.9103026: {"time":1684930172,"time_ms":1684930172760,"channel":"futures.order_book_update","event":"update","result":{"U":3132789287,"a":[],"b":[{"p":"0.7696","s":1056}],"s":"OMG_USDT","t":1684930172658,"u":3132789287}}
1684930173.2040088: {"time":1684930173,"time_ms":1684930173054,"channel":"futures.order_book_update","event":"update","result":{"U":3132789288,"a":[],"b":[{"p":"0.7696","s":1921}],"s":"OMG_USDT","t":1684930173023,"u":3132789288}}
1684930173.3169627: {"time":1684930173,"time_ms":1684930173167,"channel":"futures.order_book_update","event":"update","result":{"U":3132789289,"a":[],"b":[{"p":"0.7696","s":1056}],"s":"OMG_USDT","t":1684930173146,"u":3132789289}}
1684930173.510034: {"time":1684930173,"time_ms":1684930173360,"channel":"futures.order_book_update","event":"update","result":{"U":6160018,"a":[],"b":[{"p":"0.737","s":721}],"s":"PHB_USDT","t":1684930173320,"u":6160018}}
1684930173.7088768: {"time":1684930173,"time_ms":1684930173559,"channel":"futures.order_book_update","event":"update","result":{"U":3132789290,"a":[],"b":[{"p":"0.7696","s":1921}],"s":"OMG_USDT","t":1684930173534,"u":3132789290}}
1684930173.8075244: {"time":1684930173,"time_ms":1684930173657,"channel":"futures.order_book_update","event":"update","result":{"U":3132789291,"a":[],"b":[{"p":"0.7696","s":1056}],"s":"OMG_USDT","t":1684930173599,"u":3132789291}}
1684930173.9099784: {"time":1684930173,"time_ms":1684930173760,"channel":"futures.order_book_update","event":"update","result":{"U":3132789292,"a":[],"b":[{"p":"0.7696","s":1921}],"s":"OMG_USDT","t":1684930173667,"u":3132789292}}
1684930174.0088353: {"time":1684930173,"time_ms":1684930173859,"channel":"futures.order_book_update","event":"update","result":{"U":3132789293,"a":[],"b":[{"p":"0.7696","s":1056}],"s":"OMG_USDT","t":1684930173805,"u":3132789293}}
1684930174.0114548: {"time":1684930173,"time_ms":1684930173862,"channel":"futures.order_book_update","event":"update","result":{"U":6160019,"a":[{"p":"0.991","s":11},{"p":"0.7542","s":44},{"p":"0.7424","s":819},{"p":"0.7397","s":1413}],"b":[{"p":"0.7376","s":1727}],"s":"PHB_USDT","t":1684930173829,"u":6160020}}
1684930174.1309342: {"time":1684930173,"time_ms":1684930173981,"channel":"futures.book_ticker","event":"update","result":{"t":1684930173971,"u":6160047,"s":"PHB_USDT","b":"0.7379","B":814,"a":"0.739","A":677}}
1684930174.1408322: {"time":1684930173,"time_ms":1684930173991,"channel":"futures.book_ticker","event":"update","result":{"t":1684930173980,"u":6160054,"s":"PHB_USDT","b":"0.7379","B":814,"a":"0.7392","A":65}}
1684930174.1514554: {"time":1684930174,"time_ms":1684930174002,"channel":"futures.order_book_update","event":"update","result":{"U":536375653,"a":[{"p":"0.2143","s":15150},{"p":"0.2112","s":69097},{"p":"0.2111","s":4269},{"p":"0.2123","s":18774},{"p":"0.2287","s":1}],"b":[{"p":"0.2062","s":7985},{"p":"0.2088","s":1914},{"p":"0.2089","s":74280},{"p":"0.209","s":24013},{"p":"0.1931","s":1}],"s":"WOO_USDT","t":1684930173980,"u":536375674}}
1684930174.17087: {"time":1684930174,"time_ms":1684930174021,"channel":"futures.book_ticker","event":"update","result":{"t":1684930174010,"u":6160056,"s":"PHB_USDT","b":"0.7379","B":136,"a":"0.7392","A":65}}
1684930174.2005677: {"time":1684930174,"time_ms":1684930174051,"channel":"futures.order_book_update","event":"update","result":{"U":6160021,"a":[{"p":"0.7402","s":721},{"p":"0.7398","s":0},{"p":"0.7524","s":98},{"p":"0.7542","s":44},{"p":"0.991","s":11},{"p":"0.7424","s":819},{"p":"0.7469","s":0},{"p":"0.739","s":0},{"p":"0.74","s":0},{"p":"0.7416","s":2156},{"p":"0.7396","s":746},{"p":"0.7401","s":682},{"p":"0.7442","s":102},{"p":"0.7393","s":0},{"p":"0.7397","s":0},{"p":"0.9672","s":10},{"p":"0.7394","s":1412},{"p":"0.7395","s":303},{"p":"0.7543","s":0},{"p":"1.0147","s":12}],"b":[{"p":"0.7315","s":233},{"p":"0.7372","s":1404},{"p":"0.7105","s":1},{"p":"0.7371","s":0},{"p":"0.7322","s":2032},{"p":"0.7165","s":16814},{"p":"0.7342","s":828},{"p":"0.7366","s":786},{"p":"0.7373","s":721},{"p":"0.7374","s":682},{"p":"0.7378","s":303},{"p":"0.737","s":0},{"p":"0.7051","s":1},{"p":"0.7379","s":136},{"p":"0.7376","s":712}],"s":"PHB_USDT","t":1684930174039,"u":6160060}}
1684930174.2075672: {"time":1684930174,"time_ms":1684930174058,"channel":"futures.order_book_update","event":"update","result":{"U":203083344,"a":[],"b":[{"p":"0.2963","s":12017}],"s":"RDNT_USDT","t":1684930174031,"u":203083344}}
1684930174.2111142: {"time":1684930174,"time_ms":1684930174061,"channel":"futures.order_book_update","event":"update","result":{"U":3132789294,"a":[],"b":[{"p":"0.7696","s":1921}],"s":"OMG_USDT","t":1684930174016,"u":3132789294}}
1684930174.3052638: {"time":1684930174,"time_ms":1684930174155,"channel":"futures.order_book_update","event":"update","result":{"U":6160061,"a":[{"p":"0.7547","s":384},{"p":"0.7462","s":0},{"p":"0.7436","s":0},{"p":"1.05","s":1},{"p":"0.7631","s":15349},{"p":"0.7442","s":102},{"p":"0.7394","s":0},{"p":"1.0385","s":13}],"b":[],"s":"PHB_USDT","t":1684930174128,"u":6160065}}
1684930174.337183: {"time":1684930174,"time_ms":1684930174187,"channel":"futures.order_book_update","event":"update","result":{"U":203083345,"a":[],"b":[{"p":"0.2963","s":13130}],"s":"RDNT_USDT","t":1684930174064,"u":203083345}}
1684930174.408054: {"time":1684930174,"time_ms":1684930174258,"channel":"futures.order_book_update","event":"update","result":{"U":203083346,"a":[{"p":"0.3001","s":2664}],"b":[{"p":"0.2941","s":0},{"p":"0.2946","s":0}],"s":"RDNT_USDT","t":1684930174221,"u":203083348}}
1684930174.4156325: {"time":1684930174,"time_ms":1684930174266,"channel":"futures.order_book_update","event":"update","result":{"U":6160066,"a":[{"p":"0.7503","s":161},{"p":"0.7477","s":550},{"p":"0.7537","s":0},{"p":"0.7639","s":1},{"p":"0.7631","s":15349},{"p":"0.7401","s":2311},{"p":"0.74","s":682},{"p":"0.7577","s":69},{"p":"0.7612","s":0},{"p":"1.0147","s":12},{"p":"1.0622","s":13},{"p":"0.7511","s":0},{"p":"0.7406","s":782},{"p":"1.0385","s":13},{"p":"1.05","s":1},{"p":"0.7416","s":2156},{"p":"0.745","s":857},{"p":"0.7407","s":1986},{"p":"0.7402","s":0},{"p":"0.7452","s":232},{"p":"0.7448","s":2033},{"p":"0.7547","s":384}],"b":[{"p":"0.7374","s":0},{"p":"0.7322","s":2032},{"p":"0.7105","s":1},{"p":"0.7373","s":682},{"p":"0.7372","s":2125}],"s":"PHB_USDT","t":1684930174256,"u":6160084}}
1684930174.5058417: {"time":1684930174,"time_ms":1684930174356,"channel":"futures.order_book_update","event":"update","result":{"U":203083349,"a":[{"p":"0.2996","s":562},{"p":"0.3001","s":3226},{"p":"0.3196","s":1},{"p":"0.3035","s":16846}],"b":[{"p":"0.2946","s":562},{"p":"0.2941","s":562},{"p":"0.2734","s":1},{"p":"0.2912","s":17803},{"p":"0.2944","s":34254},{"p":"0.2914","s":1009},{"p":"0.2745","s":1}],"s":"RDNT_USDT","t":1684930174271,"u":203083352}}
1684930174.51615: {"time":1684930174,"time_ms":1684930174366,"channel":"futures.order_book_update","event":"update","result":{"U":6160085,"a":[{"p":"0.7399","s":682},{"p":"0.7395","s":0},{"p":"0.7448","s":2033},{"p":"0.7406","s":782},{"p":"0.74","s":721},{"p":"0.7577","s":0},{"p":"0.7394","s":303},{"p":"0.7416","s":820},{"p":"0.7503","s":0},{"p":"0.7477","s":0},{"p":"0.991","s":11},{"p":"0.7442","s":102},{"p":"1.05","s":1},{"p":"0.7631","s":15349},{"p":"0.7734","s":43},{"p":"0.7761","s":43},{"p":"0.7401","s":1590},{"p":"1.0385","s":13},{"p":"0.7542","s":44},{"p":"1.0147","s":12},{"p":"0.7547","s":384},{"p":"0.7838","s":18}],"b":[{"p":"0.7376","s":1015},{"p":"0.7373","s":0},{"p":"0.7378","s":0},{"p":"0.7366","s":786},{"p":"0.7051","s":1},{"p":"0.7315","s":233},{"p":"0.7372","s":2086},{"p":"0.7371","s":721}],"s":"PHB_USDT","t":1684930174351,"u":6160115}}
1684930174.6143177: {"time":1684930174,"time_ms":1684930174464,"channel":"futures.order_book_update","event":"update","result":{"U":6160116,"a":[{"p":"0.7424","s":819},{"p":"0.7405","s":1336},{"p":"0.9672","s":10},{"p":"0.7547","s":384}],"b":[],"s":"PHB_USDT","t":1684930174405,"u":6160116}}
1684930174.652019: {"time":1684930174,"time_ms":1684930174502,"channel":"futures.order_book_update","event":"update","result":{"U":536375675,"a":[],"b":[{"p":"0.2099","s":550},{"p":"0.1931","s":1},{"p":"0.2062","s":7985},{"p":"0.2088","s":1914},{"p":"0.2095","s":7452}],"s":"WOO_USDT","t":1684930174462,"u":536375676}}
1684930174.7008047: {"time":1684930174,"time_ms":1684930174551,"channel":"futures.book_ticker","event":"update","result":{"t":1684930174544,"u":6160121,"s":"PHB_USDT","b":"0.7379","B":136,"a":"0.739","A":677}}
1684930174.717297: {"time":1684930174,"time_ms":1684930174567,"channel":"futures.order_book_update","event":"update","result":{"U":6160117,"a":[{"p":"0.7416","s":820},{"p":"0.7838","s":0},{"p":"0.7734","s":0},{"p":"0.7761","s":0},{"p":"0.7407","s":1986},{"p":"0.7399","s":682},{"p":"0.991","s":11},{"p":"0.739","s":677},{"p":"0.7393","s":711},{"p":"0.74","s":721},{"p":"1.0147","s":12},{"p":"0.7524","s":98},{"p":"0.7542","s":44}],"b":[],"s":"PHB_USDT","t":1684930174544,"u":6160121}}
1684930174.9080036: {"time":1684930174,"time_ms":1684930174758,"channel":"futures.order_book_update","event":"update","result":{"U":203083353,"a":[],"b":[{"p":"0.2931","s":5458},{"p":"0.2926","s":80445}],"s":"RDNT_USDT","t":1684930174692,"u":203083354}}
1684930174.9106662: {"time":1684930174,"time_ms":1684930174761,"channel":"futures.order_book_update","event":"update","result":{"U":3132789295,"a":[],"b":[{"p":"0.7696","s":1921}],"s":"OMG_USDT","t":1684930174676,"u":3132789296}}
1684930175.0034251: {"time":1684930174,"time_ms":1684930174853,"channel":"futures.order_book_update","event":"update","result":{"U":3132789297,"a":[],"b":[{"p":"0.7696","s":1056}],"s":"OMG_USDT","t":1684930174806,"u":3132789297}}
1684930175.0134735: {"time":1684930174,"time_ms":1684930174864,"channel":"futures.order_book_update","event":"update","result":{"U":203083355,"a":[{"p":"0.2981","s":33428}],"b":[],"s":"RDNT_USDT","t":1684930174769,"u":203083355}}
1684930175.0307803: {"time":1684930174,"time_ms":1684930174881,"channel":"futures.book_ticker","event":"update","result":{"t":1684930174867,"u":6160122,"s":"PHB_USDT","b":"0.7379","B":814,"a":"0.739","A":677}}
1684930175.1011057: {"time":1684930174,"time_ms":1684930174951,"channel":"futures.order_book_update","event":"update","result":{"U":6160122,"a":[{"p":"0.74","s":0},{"p":"0.7399","s":0},{"p":"0.7394","s":0},{"p":"0.9672","s":10},{"p":"0.7519","s":15530},{"p":"0.7406","s":782},{"p":"0.7396","s":746},{"p":"0.7395","s":303}],"b":[{"p":"0.7372","s":1404},{"p":"0.7379","s":814},{"p":"0.7371","s":0}],"s":"PHB_USDT","t":1684930174938,"u":6160134}}
1684930175.1562042: {"time":1684930175,"time_ms":1684930175007,"channel":"futures.order_book_update","event":"update","result":{"U":571312381,"a":[],"b":[{"p":"0.2231","s":23270}],"s":"ZRX_USDT","t":1684930174991,"u":571312382}}
1684930175.2017493: {"time":1684930175,"time_ms":1684930175052,"channel":"futures.order_book_update","event":"update","result":{"U":203083356,"a":[{"p":"0.2981","s":36097}],"b":[],"s":"RDNT_USDT","t":1684930175015,"u":203083356}}
1684930175.2077677: {"time":1684930175,"time_ms":1684930175058,"channel":"futures.order_book_update","event":"update","result":{"U":6160135,"a":[{"p":"0.74","s":682},{"p":"0.749","s":18},{"p":"0.9672","s":10},{"p":"0.7519","s":15530},{"p":"0.7542","s":44},{"p":"0.7401","s":2311},{"p":"0.7464","s":18},{"p":"0.991","s":11},{"p":"0.7524","s":98},{"p":"1.0147","s":12},{"p":"0.7416","s":820}],"b":[{"p":"0.7377","s":0},{"p":"0.7366","s":786},{"p":"0.7051","s":1},{"p":"0.7315","s":233},{"p":"0.7373","s":682},{"p":"0.7372","s":2125}],"s":"PHB_USDT","t":1684930175014,"u":6160141}}
1684930175.2104144: {"time":1684930175,"time_ms":1684930175060,"channel":"futures.order_book_update","event":"update","result":{"U":489455931,"a":[],"b":[{"p":"0.4066","s":0}],"s":"SFP_USDT","t":1684930175027,"u":489455931}}
1684930175.5027034: {"time":1684930175,"time_ms":1684930175091,"channel":"futures.book_ticker","event":"update","result":{"t":1684930175081,"u":6160144,"s":"PHB_USDT","b":"0.7379","B":814,"a":"0.7392","A":65}}
1684930175.5027297: {"time":1684930175,"time_ms":1684930175110,"channel":"futures.order_book_update","event":"update","result":{"U":244770080,"a":[{"p":"0.1737","s":871},{"p":"0.175","s":0},{"p":"0.1882","s":2},{"p":"0.1799","s":1},{"p":"0.1751","s":744}],"b":[],"s":"FRONT_USDT","t":1684930175066,"u":244770081}}
1684930175.5027776: {"time":1684930175,"time_ms":1684930175141,"channel":"futures.book_ticker","event":"update","result":{"t":1684930175121,"u":6160164,"s":"PHB_USDT","b":"0.7379","B":136,"a":"0.7392","A":65}}
1684930175.5027914: {"time":1684930175,"time_ms":1684930175156,"channel":"futures.order_book_update","event":"update","result":{"U":3132789298,"a":[],"b":[{"p":"0.7696","s":1921}],"s":"OMG_USDT","t":1684930175131,"u":3132789298}}
1684930175.5028121: {"time":1684930175,"time_ms":1684930175159,"channel":"futures.order_book_update","event":"update","result":{"U":6160142,"a":[{"p":"0.7467","s":388},{"p":"0.7401","s":2272},{"p":"0.7464","s":0},{"p":"0.74","s":0},{"p":"1.0147","s":12},{"p":"0.739","s":0},{"p":"0.9672","s":10},{"p":"1.0385","s":13},{"p":"0.7542","s":44},{"p":"0.7441","s":550},{"p":"0.749","s":0},{"p":"0.7524","s":98},{"p":"0.7547","s":384},{"p":"0.7541","s":166},{"p":"0.7402","s":721},{"p":"0.7424","s":819},{"p":"0.991","s":11}],"b":[{"p":"0.7366","s":786},{"p":"0.7105","s":1},{"p":"0.7322","s":2032},{"p":"0.7372","s":1404},{"p":"0.7373","s":721},{"p":"0.7378","s":303},{"p":"0.7379","s":0},{"p":"0.7315","s":233},{"p":"0.7376","s":712},{"p":"0.7374","s":682},{"p":"0.7051","s":1}],"s":"PHB_USDT","t":1684930175147,"u":6160165}}
1684930175.5029218: {"time":1684930175,"time_ms":1684930175161,"channel":"futures.book_ticker","event":"update","result":{"t":1684930175147,"u":6160165,"s":"PHB_USDT","b":"0.7378","B":303,"a":"0.7392","A":65}}
1684930175.502935: {"time":1684930175,"time_ms":1684930175162,"channel":"futures.order_book_update","event":"update","result":{"U":489455932,"a":[],"b":[{"p":"0.4067","s":8421}],"s":"SFP_USDT","t":1684930175063,"u":489455932}}
1684930175.5029461: {"time":1684930175,"time_ms":1684930175191,"channel":"futures.book_ticker","event":"update","result":{"t":1684930175182,"u":6160171,"s":"PHB_USDT","b":"0.7379","B":136,"a":"0.7392","A":65}}
1684930175.502957: {"time":1684930175,"time_ms":1684930175250,"channel":"futures.order_book_update","event":"update","result":{"U":3132789299,"a":[],"b":[{"p":"0.7696","s":1056}],"s":"OMG_USDT","t":1684930175187,"u":3132789299}}
1684930175.502974: {"time":1684930175,"time_ms":1684930175253,"channel":"futures.order_book_update","event":"update","result":{"U":6160166,"a":[{"p":"0.7908","s":0},{"p":"0.8056","s":0},{"p":"0.776","s":0},{"p":"0.9672","s":10},{"p":"0.791","s":25},{"p":"0.8058","s":41},{"p":"0.7762","s":13}],"b":[{"p":"0.7373","s":721},{"p":"0.7377","s":1412},{"p":"0.7379","s":136},{"p":"0.7105","s":1},{"p":"0.7322","s":2032},{"p":"0.7372","s":1404},{"p":"0.7165","s":16814},{"p":"0.7342","s":828}],"s":"PHB_USDT","t":1684930175227,"u":6160175}}
1684930175.6138647: {"time":1684930175,"time_ms":1684930175464,"channel":"futures.order_book_update","event":"update","result":{"U":3132789300,"a":[],"b":[{"p":"0.7696","s":1921}],"s":"OMG_USDT","t":1684930175378,"u":3132789300}}
1684930175.6180174: {"time":1684930175,"time_ms":1684930175468,"channel":"futures.order_book_update","event":"update","result":{"U":6160176,"a":[{"p":"0.7401","s":2311},{"p":"0.74","s":682},{"p":"0.7402","s":0},{"p":"0.9672","s":10},{"p":"0.7524","s":98},{"p":"0.7424","s":819}],"b":[{"p":"0.7373","s":682},{"p":"0.7372","s":2125},{"p":"0.7374","s":0},{"p":"0.7105","s":1},{"p":"0.7322","s":2032}],"s":"PHB_USDT","t":1684930175404,"u":6160183}}
1684930175.7587368: {"time":1684930175,"time_ms":1684930175609,"channel":"futures.order_book_update","event":"update","result":{"U":244770082,"a":[{"p":"0.1737","s":0},{"p":"0.1882","s":2},{"p":"0.1799","s":1},{"p":"0.1751","s":744},{"p":"0.175","s":871}],"b":[],"s":"FRONT_USDT","t":1684930175560,"u":244770083}}
1684930175.7710335: {"time":1684930175,"time_ms":1684930175621,"channel":"futures.book_ticker","event":"update","result":{"t":1684930175610,"u":6160225,"s":"PHB_USDT","b":"0.7379","B":136,"a":"0.7391","A":677}}
1684930175.8001091: {"time":1684930175,"time_ms":1684930175650,"channel":"futures.order_book_update","event":"update","result":{"U":6160184,"a":[{"p":"0.7519","s":15530},{"p":"0.9042","s":22},{"p":"0.7391","s":677},{"p":"0.74","s":721},{"p":"0.7401","s":1590},{"p":"0.7424","s":819},{"p":"0.7399","s":682},{"p":"0.7395","s":0},{"p":"0.9672","s":10},{"p":"0.7394","s":303},{"p":"0.9322","s":21},{"p":"0.7416","s":820},{"p":"0.7407","s":1986},{"p":"0.7473","s":942},{"p":"0.7524","s":98}],"b":[{"p":"0.7376","s":1015},{"p":"0.7051","s":1},{"p":"0.7315","s":233},{"p":"0.7373","s":0},{"p":"0.7366","s":786},{"p":"0.7377","s":2124},{"p":"0.7372","s":2086},{"p":"0.7371","s":721},{"p":"0.7378","s":0}],"s":"PHB_USDT","t":1684930175610,"u":6160225}}
1684930175.9140859: {"time":1684930175,"time_ms":1684930175764,"channel":"futures.order_book_update","event":"update","result":{"U":3132789301,"a":[],"b":[{"p":"0.7696","s":1056}],"s":"OMG_USDT","t":1684930175722,"u":3132789301}}
1684930175.918712: {"time":1684930175,"time_ms":1684930175769,"channel":"futures.order_book_update","event":"update","result":{"U":6160226,"a":[{"p":"0.7401","s":2311},{"p":"0.7395","s":303},{"p":"0.7519","s":15530},{"p":"0.7407","s":1986},{"p":"0.7399","s":0},{"p":"0.74","s":0},{"p":"0.7467","s":0},{"p":"0.7541","s":0},{"p":"0.7394","s":0},{"p":"0.7396","s":746},{"p":"0.9672","s":10},{"p":"0.7441","s":550}],"b":[{"p":"0.7376","s":712},{"p":"0.7372","s":2125},{"p":"0.7371","s":0},{"p":"0.7105","s":1},{"p":"0.7322","s":2032},{"p":"0.7378","s":303}],"s":"PHB_USDT","t":1684930175760,"u":6160251}}
1684930176.0064354: {"time":1684930175,"time_ms":1684930175856,"channel":"futures.order_book_update","event":"update","result":{"U":3132789302,"a":[],"b":[{"p":"0.7696","s":1921}],"s":"OMG_USDT","t":1684930175824,"u":3132789302}}
1684930176.009344: {"time":1684930175,"time_ms":1684930175859,"channel":"futures.order_book_update","event":"update","result":{"U":6160252,"a":[{"p":"0.74","s":682},{"p":"0.7416","s":820},{"p":"0.991","s":11},{"p":"0.7524","s":98}],"b":[{"p":"0.7372","s":2125},{"p":"0.7105","s":1},{"p":"0.7373","s":682},{"p":"0.7322","s":2032}],"s":"PHB_USDT","t":1684930175770,"u":6160253}}
1684930176.0309503: {"time":1684930175,"time_ms":1684930175881,"channel":"futures.book_ticker","event":"update","result":{"t":1684930175869,"u":6160254,"s":"PHB_USDT","b":"0.7381","B":678,"a":"0.7391","A":677}}
1684930176.107281: {"time":1684930175,"time_ms":1684930175957,"channel":"futures.order_book_update","event":"update","result":{"U":6160254,"a":[],"b":[{"p":"0.7381","s":678},{"p":"0.7165","s":16814},{"p":"0.7342","s":828},{"p":"0.7373","s":682},{"p":"0.7377","s":1412}],"s":"PHB_USDT","t":1684930175917,"u":6160255}}
1684930176.2306235: {"time":1684930176,"time_ms":1684930176081,"channel":"futures.book_ticker","event":"update","result":{"t":1684930176069,"u":6160256,"s":"PHB_USDT","b":"0.7379","B":136,"a":"0.7391","A":677}}
1684930176.3097463: {"time":1684930176,"time_ms":1684930176160,"channel":"futures.order_book_update","event":"update","result":{"U":3132789303,"a":[],"b":[{"p":"0.7696","s":1056}],"s":"OMG_USDT","t":1684930176053,"u":3132789303}}
1684930176.3126528: {"time":1684930176,"time_ms":1684930176163,"channel":"futures.order_book_update","event":"update","result":{"U":6160256,"a":[{"p":"0.7398","s":1412},{"p":"0.9672","s":10},{"p":"0.7519","s":15530},{"p":"0.7407","s":1986}],"b":[{"p":"0.7381","s":0}],"s":"PHB_USDT","t":1684930176139,"u":6160257}}
1684930176.406931: {"time":1684930176,"time_ms":1684930176257,"channel":"futures.order_book_update","event":"update","result":{"U":3132789304,"a":[],"b":[{"p":"0.7696","s":1921}],"s":"OMG_USDT","t":1684930176173,"u":3132789304}}
1684930176.4099517: {"time":1684930176,"time_ms":1684930176260,"channel":"futures.order_book_update","event":"update","result":{"U":6160258,"a":[{"p":"0.7395","s":1715}],"b":[],"s":"PHB_USDT","t":1684930176181,"u":6160258}}
1684930176.4377482: {"time":1684930176,"time_ms":1684930176288,"channel":"futures.order_book_update","event":"update","result":{"U":536375677,"a":[{"p":"0.2105","s":69945}],"b":[],"s":"WOO_USDT","t":1684930176200,"u":536375677}}
1684930176.6010916: {"time":1684930176,"time_ms":1684930176451,"channel":"futures.order_book_update","event":"update","result":{"U":203083357,"a":[],"b":[{"p":"0.2963","s":12017}],"s":"RDNT_USDT","t":1684930176353,"u":203083357}}
1684930176.7042081: {"time":1684930176,"time_ms":1684930176554,"channel":"futures.order_book_update","event":"update","result":{"U":6160259,"a":[{"p":"0.74","s":0},{"p":"0.9672","s":10},{"p":"0.7519","s":15530},{"p":"0.7407","s":1986},{"p":"0.7399","s":682}],"b":[{"p":"0.7372","s":2807},{"p":"0.7376","s":1015},{"p":"0.7378","s":0},{"p":"0.7373","s":0}],"s":"PHB_USDT","t":1684930176524,"u":6160270}}
1684930176.711761: {"time":1684930176,"time_ms":1684930176562,"channel":"futures.order_book_update","event":"update","result":{"U":203083358,"a":[{"p":"0.3001","s":2664},{"p":"0.2996","s":0}],"b":[{"p":"0.2946","s":0},{"p":"0.2941","s":0}],"s":"RDNT_USDT","t":1684930176476,"u":203083361}}
1684930176.7508514: {"time":1684930176,"time_ms":1684930176601,"channel":"futures.book_ticker","event":"update","result":{"t":1684930176589,"u":6160271,"s":"PHB_USDT","b":"0.738","B":678,"a":"0.7391","A":677}}
1684930176.8006563: {"time":1684930176,"time_ms":1684930176651,"channel":"futures.order_book_update","event":"update","result":{"U":6160271,"a":[],"b":[{"p":"0.738","s":678},{"p":"0.7051","s":1},{"p":"0.7315","s":233},{"p":"0.7366","s":786},{"p":"0.7105","s":1},{"p":"0.7322","s":2032},{"p":"0.7372","s":2807},{"p":"0.7374","s":748}],"s":"PHB_USDT","t":1684930176641,"u":6160272}}
1684930176.9057837: {"time":1684930176,"time_ms":1684930176756,"channel":"futures.order_book_update","event":"update","result":{"U":203083362,"a":[{"p":"0.3001","s":3226},{"p":"0.2996","s":562},{"p":"0.3196","s":1},{"p":"0.3035","s":16846}],"b":[{"p":"0.2912","s":17803},{"p":"0.2734","s":1},{"p":"0.2941","s":562},{"p":"0.2963","s":13052},{"p":"0.2946","s":562},{"p":"0.2914","s":1009},{"p":"0.2944","s":34254},{"p":"0.2745","s":1}],"s":"RDNT_USDT","t":1684930176743,"u":203083366}}
1684930177.1078787: {"time":1684930176,"time_ms":1684930176958,"channel":"futures.order_book_update","event":"update","result":{"U":3132789305,"a":[],"b":[{"p":"0.7696","s":1921}],"s":"OMG_USDT","t":1684930176931,"u":3132789306}}
1684930177.2025912: {"time":1684930177,"time_ms":1684930177053,"channel":"futures.order_book_update","event":"update","result":{"U":3132789307,"a":[],"b":[{"p":"0.7696","s":1056}],"s":"OMG_USDT","t":1684930177015,"u":3132789307}}
1684930177.303015: {"time":1684930177,"time_ms":1684930177153,"channel":"futures.order_book_update","event":"update","result":{"U":3132789308,"a":[],"b":[{"p":"0.7696","s":1921}],"s":"OMG_USDT","t":1684930177117,"u":3132789308}}
1684930177.3371632: {"time":1684930177,"time_ms":1684930177188,"channel":"futures.order_book_update","event":"update","result":{"U":536375678,"a":[{"p":"0.2112","s":62499}],"b":[{"p":"0.2089","s":65709}],"s":"WOO_USDT","t":1684930177123,"u":536375679}}
1684930177.3397293: {"time":1684930177,"time_ms":1684930177190,"channel":"futures.order_book_update","event":"update","result":{"U":124930266,"a":[{"p":"83.87","s":500},{"p":"59.84","s":1},{"p":"57.83","s":481},{"p":"57.41","s":189},{"p":"57.32","s":4576},{"p":"57.42","s":0}],"b":[],"s":"QUICK_USDT","t":1684930177128,"u":124930267}}
1684930177.4105682: {"time":1684930177,"time_ms":1684930177261,"channel":"futures.order_book_update","event":"update","result":{"U":3132789309,"a":[],"b":[{"p":"0.7696","s":1056}],"s":"OMG_USDT","t":1684930177209,"u":3132789309}}
1684930177.6062093: {"time":1684930177,"time_ms":1684930177456,"channel":"futures.order_book_update","event":"update","result":{"U":3132789310,"a":[],"b":[{"p":"0.7696","s":1921}],"s":"OMG_USDT","t":1684930177413,"u":3132789310}}
1684930177.8115952: {"time":1684930177,"time_ms":1684930177662,"channel":"futures.order_book_update","event":"update","result":{"U":3132789311,"a":[],"b":[{"p":"0.7696","s":1056}],"s":"OMG_USDT","t":1684930177621,"u":3132789311}}
1684930177.8145301: {"time":1684930177,"time_ms":1684930177665,"channel":"futures.order_book_update","event":"update","result":{"U":6160273,"a":[{"p":"0.74","s":721},{"p":"0.7401","s":1590},{"p":"0.7395","s":1412},{"p":"0.7468","s":102},{"p":"0.9322","s":21},{"p":"0.7394","s":303},{"p":"0.9042","s":22},{"p":"0.7405","s":1336},{"p":"0.7473","s":942},{"p":"0.7406","s":782},{"p":"0.7396","s":746}],"b":[{"p":"0.7371","s":721},{"p":"0.7372","s":2086},{"p":"0.7165","s":16814},{"p":"0.7342","s":828}],"s":"PHB_USDT","t":1684930177646,"u":6160284}}
1684930177.8411217: {"time":1684930177,"time_ms":1684930177691,"channel":"futures.order_book_update","event":"update","result":{"U":124930268,"a":[{"p":"83.87","s":500},{"p":"59.84","s":1},{"p":"57.83","s":481},{"p":"57.5","s":189},{"p":"57.41","s":0}],"b":[],"s":"QUICK_USDT","t":1684930177573,"u":124930269}}
1684930177.9048238: {"time":1684930177,"time_ms":1684930177755,"channel":"futures.order_book_update","event":"update","result":{"U":3132789312,"a":[],"b":[{"p":"0.7696","s":1921}],"s":"OMG_USDT","t":1684930177708,"u":3132789312}}
1684930178.1058989: {"time":1684930177,"time_ms":1684930177956,"channel":"futures.order_book_update","event":"update","result":{"U":203083367,"a":[{"p":"0.2981","s":33428}],"b":[],"s":"RDNT_USDT","t":1684930177911,"u":203083367}}
1684930178.2095504: {"time":1684930178,"time_ms":1684930178060,"channel":"futures.order_book_update","event":"update","result":{"U":203083368,"a":[{"p":"0.2996","s":0}],"b":[{"p":"0.2946","s":0}],"s":"RDNT_USDT","t":1684930177956,"u":203083369}}
1684930178.2509031: {"time":1684930178,"time_ms":1684930178101,"channel":"futures.book_ticker","event":"update","result":{"t":1684930178092,"u":6160298,"s":"PHB_USDT","b":"0.738","B":814,"a":"0.7391","A":677}}
1684930178.3038535: {"time":1684930178,"time_ms":1684930178154,"channel":"futures.order_book_update","event":"update","result":{"U":203083370,"a":[{"p":"0.2981","s":36104}],"b":[],"s":"RDNT_USDT","t":1684930178059,"u":203083370}}
1684930178.3099: {"time":1684930178,"time_ms":1684930178160,"channel":"futures.order_book_update","event":"update","result":{"U":6160285,"a":[{"p":"0.7395","s":1715},{"p":"0.7394","s":0},{"p":"0.7399","s":0},{"p":"0.9672","s":10},{"p":"0.7519","s":15530},{"p":"0.7407","s":1986},{"p":"0.74","s":682},{"p":"0.7401","s":2311}],"b":[{"p":"0.7373","s":682},{"p":"0.7379","s":0},{"p":"0.7165","s":16814},{"p":"0.7342","s":828},{"p":"0.7353","s":1415},{"p":"0.7374","s":748},{"p":"0.738","s":814},{"p":"0.7372","s":1404},{"p":"0.7376","s":0},{"p":"0.7187","s":16787},{"p":"0.7371","s":721},{"p":"0.7378","s":303}],"s":"PHB_USDT","t":1684930178128,"u":6160311}}
1684930178.510152: {"time":1684930178,"time_ms":1684930178360,"channel":"futures.order_book_update","event":"update","result":{"U":3132789313,"a":[],"b":[{"p":"0.7696","s":1056}],"s":"OMG_USDT","t":1684930178314,"u":3132789313}}
1684930178.5152934: {"time":1684930178,"time_ms":1684930178365,"channel":"futures.order_book_update","event":"update","result":{"U":6160312,"a":[{"p":"0.7761","s":14},{"p":"0.7762","s":0},{"p":"0.9672","s":10}],"b":[{"p":"0.6863","s":29},{"p":"0.6714","s":0},{"p":"0.6862","s":0},{"p":"0.6715","s":42}],"s":"PHB_USDT","t":1684930178353,"u":6160317}}
1684930178.607002: {"time":1684930178,"time_ms":1684930178457,"channel":"futures.order_book_update","event":"update","result":{"U":6160318,"a":[{"p":"0.8058","s":0},{"p":"0.9672","s":10},{"p":"0.8057","s":39},{"p":"0.7909","s":29},{"p":"0.791","s":0}],"b":[],"s":"PHB_USDT","t":1684930178374,"u":6160321}}
1684930178.705207: {"time":1684930178,"time_ms":1684930178555,"channel":"futures.order_book_update","event":"update","result":{"U":3132789314,"a":[{"p":"1.2532","s":2},{"p":"0.7723","s":0}],"b":[],"s":"OMG_USDT","t":1684930178522,"u":3132789314}}
1684930178.7192602: {"time":1684930178,"time_ms":1684930178569,"channel":"futures.order_book_update","event":"update","result":{"U":6160322,"a":[{"p":"0.9042","s":22},{"p":"0.7475","s":41},{"p":"0.7449","s":41},{"p":"0.7549","s":18},{"p":"0.7441","s":0},{"p":"0.9672","s":10},{"p":"0.9322","s":21},{"p":"0.7519","s":15530}],"b":[],"s":"PHB_USDT","t":1684930178497,"u":6160325}}
1684930178.8084314: {"time":1684930178,"time_ms":1684930178658,"channel":"futures.order_book_update","event":"update","result":{"U":3132789315,"a":[{"p":"0.7718","s":1353},{"p":"1.2532","s":0},{"p":"0.7728","s":50},{"p":"0.8126","s":177},{"p":"0.7774","s":2160}],"b":[{"p":"0.7696","s":1921}],"s":"OMG_USDT","t":1684930178569,"u":3132789316}}
1684930178.8116682: {"time":1684930178,"time_ms":1684930178662,"channel":"futures.order_book_update","event":"update","result":{"U":6160326,"a":[{"p":"0.9672","s":10},{"p":"0.7519","s":15530},{"p":"0.9322","s":21},{"p":"0.749","s":18},{"p":"0.7464","s":18},{"p":"0.7475","s":0},{"p":"0.7449","s":0},{"p":"0.7549","s":0}],"b":[],"s":"PHB_USDT","t":1684930178656,"u":6160330}}
1684930178.8211122: {"time":1684930178,"time_ms":1684930178671,"channel":"futures.book_ticker","event":"update","result":{"t":1684930178662,"u":6160331,"s":"PHB_USDT","b":"0.7381","B":678,"a":"0.7391","A":677}}
1684930178.9006805: {"time":1684930178,"time_ms":1684930178751,"channel":"futures.order_book_update","event":"update","result":{"U":6160331,"a":[],"b":[{"p":"0.7373","s":682},{"p":"0.7381","s":678},{"p":"0.7187","s":16787},{"p":"0.7353","s":1415}],"s":"PHB_USDT","t":1684930178662,"u":6160331}}
1684930178.9375196: {"time":1684930178,"time_ms":1684930178788,"channel":"futures.order_book_update","event":"update","result":{"U":536375680,"a":[],"b":[{"p":"0.2096","s":7273},{"p":"0.2095","s":4968}],"s":"WOO_USDT","t":1684930178719,"u":536375681}}
1684930179.114471: {"time":1684930178,"time_ms":1684930178964,"channel":"futures.order_book_update","event":"update","result":{"U":203083371,"a":[],"b":[{"p":"0.2963","s":12017}],"s":"RDNT_USDT","t":1684930178951,"u":203083371}}
1684930179.1492417: {"time":1684930178,"time_ms":1684930178999,"channel":"futures.order_book_update","event":"update","result":{"U":536375682,"a":[{"p":"0.2112","s":11411},{"p":"0.2111","s":0}],"b":[{"p":"0.209","s":18299},{"p":"0.2089","s":0}],"s":"WOO_USDT","t":1684930178908,"u":536375701}}
1684930179.3058581: {"time":1684930179,"time_ms":1684930179156,"channel":"futures.order_book_update","event":"update","result":{"U":3132789317,"a":[],"b":[{"p":"0.7696","s":1056}],"s":"OMG_USDT","t":1684930179083,"u":3132789317}}
1684930179.404768: {"time":1684930179,"time_ms":1684930179255,"channel":"futures.order_book_update","event":"update","result":{"U":203083372,"a":[{"p":"0.3001","s":2664}],"b":[{"p":"0.2941","s":0}],"s":"RDNT_USDT","t":1684930179216,"u":203083373}}
1684930179.5198238: {"time":1684930179,"time_ms":1684930179370,"channel":"futures.order_book_update","event":"update","result":{"U":3132789318,"a":[],"b":[{"p":"0.7696","s":1921}],"s":"OMG_USDT","t":1684930179300,"u":3132789318}}
1684930179.6126149: {"time":1684930179,"time_ms":1684930179463,"channel":"futures.order_book_update","event":"update","result":{"U":3132789319,"a":[],"b":[{"p":"0.7696","s":1056}],"s":"OMG_USDT","t":1684930179436,"u":3132789319}}
1684930179.6336002: {"time":1684930179,"time_ms":1684930179484,"channel":"futures.order_book_update","event":"update","result":{"U":536375702,"a":[],"b":[{"p":"0.2099","s":829},{"p":"0.193","s":5000},{"p":"0.206","s":7167},{"p":"0.2083","s":1850},{"p":"0.2095","s":4968}],"s":"WOO_USDT","t":1684930179414,"u":536375703}}
1684930179.64886: {"time":1684930179,"time_ms":1684930179499,"channel":"futures.book_ticker","event":"update","result":{"t":1684930179492,"u":536375710,"s":"WOO_USDT","b":"0.2101","B":1687,"a":"0.2103","A":676}}
1684930179.6587381: {"time":1684930179,"time_ms":1684930179509,"channel":"futures.book_ticker","event":"update","result":{"t":1684930179495,"u":536375715,"s":"WOO_USDT","b":"0.21","B":1632,"a":"0.2103","A":676}}
1684930179.6685834: {"time":1684930179,"time_ms":1684930179519,"channel":"futures.book_ticker","event":"update","result":{"t":1684930179509,"u":536375724,"s":"WOO_USDT","b":"0.21","B":4125,"a":"0.2104","A":4483}}
1684930179.6787558: {"time":1684930179,"time_ms":1684930179529,"channel":"futures.book_ticker","event":"update","result":{"t":1684930179518,"u":536375729,"s":"WOO_USDT","b":"0.21","B":3319,"a":"0.2104","A":4831}}
1684930179.6986935: {"time":1684930179,"time_ms":1684930179549,"channel":"futures.book_ticker","event":"update","result":{"t":1684930179538,"u":536375734,"s":"WOO_USDT","b":"0.21","B":4499,"a":"0.2104","A":4831}}
1684930179.7021759: {"time":1684930179,"time_ms":1684930179552,"channel":"futures.order_book_update","event":"update","result":{"U":6160332,"a":[{"p":"0.7439","s":550},{"p":"0.7464","s":0},{"p":"0.749","s":0},{"p":"0.9322","s":21},{"p":"0.9672","s":10},{"p":"0.7539","s":41},{"p":"0.7473","s":942},{"p":"0.7519","s":15530},{"p":"0.9042","s":22},{"p":"0.7465","s":96}],"b":[],"s":"PHB_USDT","t":1684930179472,"u":6160336}}
1684930179.7110014: {"time":1684930179,"time_ms":1684930179561,"channel":"futures.order_book_update","event":"update","result":{"U":203083374,"a":[{"p":"0.2996","s":562},{"p":"0.3001","s":3226},{"p":"0.3035","s":16846},{"p":"0.3196","s":1}],"b":[{"p":"0.2734","s":1},{"p":"0.2912","s":17803},{"p":"0.2944","s":34254},{"p":"0.2914","s":1009},{"p":"0.2745","s":1},{"p":"0.2946","s":562},{"p":"0.2941","s":562}],"s":"RDNT_USDT","t":1684930179482,"u":203083377}}
1684930179.7150352: {"time":1684930179,"time_ms":1684930179565,"channel":"futures.order_book_update","event":"update","result":{"U":3132789320,"a":[],"b":[{"p":"0.7696","s":1056}],"s":"OMG_USDT","t":1684930179547,"u":3132789321}}
1684930179.7187898: {"time":1684930179,"time_ms":1684930179569,"channel":"futures.book_ticker","event":"update","result":{"t":1684930179558,"u":536375735,"s":"WOO_USDT","b":"0.21","B":4499,"a":"0.2104","A":5798}}
1684930179.7357652: {"time":1684930179,"time_ms":1684930179586,"channel":"futures.order_book_update","event":"update","result":{"U":536375704,"a":[{"p":"0.2103","s":0},{"p":"0.2108","s":10380},{"p":"0.2287","s":1},{"p":"0.2143","s":15150},{"p":"0.2123","s":18774},{"p":"0.2104","s":5798},{"p":"0.2105","s":34625},{"p":"0.2107","s":1687},{"p":"0.2124","s":1837},{"p":"0.2112","s":11411},{"p":"0.2106","s":2142},{"p":"0.229","s":2168},{"p":"0.2146","s":14233}],"b":[{"p":"0.21","s":4499},{"p":"0.2098","s":6016},{"p":"0.2099","s":5190},{"p":"0.1931","s":1},{"p":"0.2062","s":7985},{"p":"0.2088","s":1914},{"p":"0.2096","s":7273},{"p":"0.2101","s":0}],"s":"WOO_USDT","t":1684930179577,"u":536375737}}
1684930180.0042086: {"time":1684930179,"time_ms":1684930179854,"channel":"futures.order_book_update","event":"update","result":{"U":3132789322,"a":[],"b":[{"p":"0.7696","s":1921}],"s":"OMG_USDT","t":1684930179785,"u":3132789322}}
1684930180.1089246: {"time":1684930179,"time_ms":1684930179955,"channel":"futures.order_book_update","event":"update","result":{"U":3132789323,"a":[],"b":[{"p":"0.7696","s":1056}],"s":"OMG_USDT","t":1684930179912,"u":3132789323}}
1684930180.3065538: {"time":1684930180,"time_ms":1684930180156,"channel":"futures.order_book_update","event":"update","result":{"U":3132789324,"a":[],"b":[{"p":"0.7696","s":1921}],"s":"OMG_USDT","t":1684930180056,"u":3132789324}}
1684930180.501793: {"time":1684930180,"time_ms":1684930180352,"channel":"futures.order_book_update","event":"update","result":{"U":203083378,"a":[{"p":"0.2981","s":33428}],"b":[],"s":"RDNT_USDT","t":1684930180330,"u":203083378}}
1684930180.5450516: {"time":1684930180,"time_ms":1684930180395,"channel":"futures.order_book_update","event":"update","result":{"U":536375738,"a":[{"p":"0.2105","s":24922},{"p":"0.2112","s":15678},{"p":"0.2113","s":56198},{"p":"0.2143","s":15150},{"p":"0.2123","s":18774},{"p":"0.2287","s":1}],"b":[{"p":"0.2094","s":14658},{"p":"0.2091","s":50379},{"p":"0.209","s":58390}],"s":"WOO_USDT","t":1684930180376,"u":536375761}}
1684930180.6048405: {"time":1684930180,"time_ms":1684930180455,"channel":"futures.order_book_update","event":"update","result":{"U":203083379,"a":[{"p":"0.2983","s":4396},{"p":"0.2985","s":4967},{"p":"0.2986","s":87043},{"p":"0.3195","s":14},{"p":"0.3034","s":32}],"b":[{"p":"0.2963","s":7621}],"s":"RDNT_USDT","t":1684930180386,"u":203083381}}
1684930180.62986: {"time":1684930180,"time_ms":1684930180480,"channel":"futures.order_book_update","event":"update","result":{"U":124930270,"a":[{"p":"58.62","s":0}],"b":[],"s":"QUICK_USDT","t":1684930180436,"u":124930270}}
1684930180.7029653: {"time":1684930180,"time_ms":1684930180553,"channel":"futures.order_book_update","event":"update","result":{"U":203083382,"a":[{"p":"0.2996","s":0}],"b":[{"p":"0.2756","s":1},{"p":"0.2916","s":2016},{"p":"0.2961","s":4396},{"p":"0.2946","s":0}],"s":"RDNT_USDT","t":1684930180462,"u":203083384}}
1684930180.7088418: {"time":1684930180,"time_ms":1684930180559,"channel":"futures.order_book_update","event":"update","result":{"U":6160337,"a":[{"p":"0.7395","s":1715}],"b":[{"p":"0.7378","s":277},{"p":"0.7377","s":1438}],"s":"PHB_USDT","t":1684930180545,"u":6160340}}
1684930180.742346: {"time":1684930180,"time_ms":1684930180593,"channel":"futures.order_book_update","event":"update","result":{"U":124930271,"a":[{"p":"57.32","s":4576},{"p":"83.87","s":500},{"p":"57.19","s":0},{"p":"59.84","s":1},{"p":"57.74","s":1745}],"b":[],"s":"QUICK_USDT","t":1684930180508,"u":124930272}}
1684930180.8088825: {"time":1684930180,"time_ms":1684930180659,"channel":"futures.order_book_update","event":"update","result":{"U":3132789325,"a":[],"b":[{"p":"0.7696","s":1056}],"s":"OMG_USDT","t":1684930180650,"u":3132789325}}
1684930180.8486073: {"time":1684930180,"time_ms":1684930180699,"channel":"futures.order_book_update","event":"update","result":{"U":536375762,"a":[],"b":[{"p":"0.2091","s":58146}],"s":"WOO_USDT","t":1684930180657,"u":536375762}}
1684930180.9483216: {"time":1684930180,"time_ms":1684930180799,"channel":"futures.order_book_update","event":"update","result":{"U":536375763,"a":[{"p":"0.2107","s":9514}],"b":[],"s":"WOO_USDT","t":1684930180783,"u":536375763}}
1684930181.0319433: {"time":1684930180,"time_ms":1684930180882,"channel":"futures.order_book_update","event":"update","result":{"U":536375764,"a":[{"p":"0.2113","s":0},{"p":"0.2106","s":3829},{"p":"0.2112","s":11411},{"p":"0.2107","s":7827}],"b":[{"p":"0.2091","s":25012},{"p":"0.209","s":18299}],"s":"WOO_USDT","t":1684930180834,"u":536375787}}
1684930181.1095858: {"time":1684930180,"time_ms":1684930180960,"channel":"futures.order_book_update","event":"update","result":{"U":3132789326,"a":[],"b":[{"p":"0.7696","s":1921}],"s":"OMG_USDT","t":1684930180880,"u":3132789326}}
1684930181.1125164: {"time":1684930180,"time_ms":1684930180963,"channel":"futures.order_book_update","event":"update","result":{"U":6160341,"a":[{"p":"0.7395","s":1715}],"b":[{"p":"0.7377","s":1508},{"p":"0.7378","s":207}],"s":"PHB_USDT","t":1684930180890,"u":6160344}}
1684930181.2092726: {"time":1684930181,"time_ms":1684930181059,"channel":"futures.order_book_update","event":"update","result":{"U":203083385,"a":[{"p":"0.2981","s":35664}],"b":[{"p":"0.2963","s":8656}],"s":"RDNT_USDT","t":1684930181017,"u":203083386}}
1684930181.4028006: {"time":1684930181,"time_ms":1684930181253,"channel":"futures.order_book_update","event":"update","result":{"U":6160345,"a":[],"b":[{"p":"0.7377","s":96}],"s":"PHB_USDT","t":1684930181205,"u":6160345}}
1684930181.4129066: {"time":1684930181,"time_ms":1684930181263,"channel":"futures.order_book_update","event":"update","result":{"U":3132789327,"a":[],"b":[{"p":"0.7696","s":1921}],"s":"OMG_USDT","t":1684930181190,"u":3132789328}}
1684930181.6058207: {"time":1684930181,"time_ms":1684930181456,"channel":"futures.order_book_update","event":"update","result":{"U":3132789329,"a":[],"b":[{"p":"0.7696","s":1921}],"s":"OMG_USDT","t":1684930181435,"u":3132789330}}
1684930181.6090226: {"time":1684930181,"time_ms":1684930181459,"channel":"futures.order_book_update","event":"update","result":{"U":6160346,"a":[],"b":[{"p":"0.701","s":0},{"p":"0.7011","s":13}],"s":"PHB_USDT","t":1684930181427,"u":6160347}}
1684930181.6708994: {"time":1684930181,"time_ms":1684930181521,"channel":"futures.book_ticker","event":"update","result":{"t":1684930181511,"u":203083391,"s":"RDNT_USDT","b":"0.2969","B":6549,"a":"0.2974","A":803}}
1684930181.6911075: {"time":1684930181,"time_ms":1684930181541,"channel":"futures.book_ticker","event":"update","result":{"t":1684930181527,"u":203083399,"s":"RDNT_USDT","b":"0.2969","B":7887,"a":"0.2974","A":803}}
1684930181.7013102: {"time":1684930181,"time_ms":1684930181551,"channel":"futures.order_book_update","event":"update","result":{"U":203083387,"a":[{"p":"0.2976","s":8393},{"p":"0.2978","s":25944},{"p":"0.3001","s":2664},{"p":"0.2982","s":5520},{"p":"0.2981","s":34379}],"b":[{"p":"0.2963","s":7621},{"p":"0.2969","s":7887},{"p":"0.2968","s":8393},{"p":"0.2964","s":406},{"p":"0.2941","s":0},{"p":"0.2756","s":1},{"p":"0.2916","s":2016},{"p":"0.2953","s":42549}],"s":"RDNT_USDT","t":1684930181527,"u":203083399}}
1684930181.7084112: {"time":1684930181,"time_ms":1684930181559,"channel":"futures.order_book_update","event":"update","result":{"U":6160348,"a":[{"p":"0.7395","s":1715}],"b":[{"p":"0.7378","s":154},{"p":"0.7377","s":149},{"p":"0.6864","s":29},{"p":"0.6863","s":0}],"s":"PHB_USDT","t":1684930181524,"u":6160353}}
1684930181.7107992: {"time":1684930181,"time_ms":1684930181561,"channel":"futures.book_ticker","event":"update","result":{"t":1684930181553,"u":203083404,"s":"RDNT_USDT","b":"0.297","B":500,"a":"0.2974","A":803}}
1684930181.736627: {"time":1684930181,"time_ms":1684930181587,"channel":"futures.order_book_update","event":"update","result":{"U":124930273,"a":[],"b":[{"p":"54.66","s":0}],"s":"QUICK_USDT","t":1684930181503,"u":124930273}}
1684930181.7780204: {"time":1684930181,"time_ms":1684930181628,"channel":"futures.order_book_update","event":"update","result":{"U":244770084,"a":[{"p":"0.175","s":0},{"p":"0.1882","s":2},{"p":"0.1799","s":1},{"p":"0.1751","s":744},{"p":"0.1737","s":871}],"b":[],"s":"FRONT_USDT","t":1684930181585,"u":244770085}}
1684930181.8039012: {"time":1684930181,"time_ms":1684930181654,"channel":"futures.order_book_update","event":"update","result":{"U":6160354,"a":[],"b":[{"p":"0.6716","s":42},{"p":"0.6715","s":0}],"s":"PHB_USDT","t":1684930181558,"u":6160355}}
1684930181.8120818: {"time":1684930181,"time_ms":1684930181662,"channel":"futures.order_book_update","event":"update","result":{"U":203083400,"a":[{"p":"0.318","s":204},{"p":"0.3033","s":1009},{"p":"0.3195","s":14},{"p":"0.3034","s":32},{"p":"0.2978","s":29451},{"p":"0.3002","s":562},{"p":"0.2997","s":562}],"b":[{"p":"0.2946","s":562},{"p":"0.297","s":500},{"p":"0.2756","s":1},{"p":"0.2766","s":1},{"p":"0.2955","s":1352},{"p":"0.2965","s":586},{"p":"0.2941","s":562},{"p":"0.2916","s":2016},{"p":"0.292","s":133},{"p":"0.2786","s":233},{"p":"0.2925","s":991}],"s":"RDNT_USDT","t":1684930181561,"u":203083405}}
1684930181.8987792: {"time":1684930181,"time_ms":1684930181749,"channel":"futures.book_ticker","event":"update","result":{"t":1684930181741,"u":536375793,"s":"WOO_USDT","b":"0.21","B":2812,"a":"0.2104","A":5798}}
1684930181.9185493: {"time":1684930181,"time_ms":1684930181769,"channel":"futures.book_ticker","event":"update","result":{"t":1684930181758,"u":536375795,"s":"WOO_USDT","b":"0.2101","B":1687,"a":"0.2104","A":5798}}
1684930181.94352: {"time":1684930181,"time_ms":1684930181794,"channel":"futures.order_book_update","event":"update","result":{"U":536375788,"a":[{"p":"0.2112","s":9519},{"p":"0.2107","s":9514},{"p":"0.212","s":3985},{"p":"0.2106","s":2142},{"p":"0.2129","s":0}],"b":[{"p":"0.1931","s":1},{"p":"0.2062","s":7985},{"p":"0.2088","s":957},{"p":"0.21","s":2812},{"p":"0.2101","s":1687},{"p":"0.2099","s":6016},{"p":"0.2098","s":5190},{"p":"0.2096","s":7273}],"s":"WOO_USDT","t":1684930181788,"u":536375802}}
1684930182.0299895: {"time":1684930181,"time_ms":1684930181880,"channel":"futures.order_book_update","event":"update","result":{"U":536375803,"a":[],"b":[{"p":"0.206","s":7167},{"p":"0.208","s":15869},{"p":"0.2074","s":5190},{"p":"0.2066","s":0},{"p":"0.2088","s":0},{"p":"0.2071","s":0},{"p":"0.193","s":5000}],"s":"WOO_USDT","t":1684930181804,"u":536375809}}
1684930182.1152563: {"time":1684930181,"time_ms":1684930181965,"channel":"futures.order_book_update","event":"update","result":{"U":203083406,"a":[{"p":"0.2981","s":33428},{"p":"0.2982","s":3505},{"p":"0.2978","s":30402}],"b":[{"p":"0.2963","s":9004},{"p":"0.2964","s":0}],"s":"RDNT_USDT","t":1684930181950,"u":203083412}}
1684930182.141035: {"time":1684930181,"time_ms":1684930181991,"channel":"futures.order_book_update","event":"update","result":{"U":536375810,"a":[{"p":"0.2114","s":19135},{"p":"0.229","s":2168},{"p":"0.2146","s":14233},{"p":"0.2123","s":18774},{"p":"0.2287","s":1},{"p":"0.2143","s":15150},{"p":"0.2122","s":3768},{"p":"0.2131","s":7506}],"b":[{"p":"0.209","s":20211},{"p":"0.2082","s":3840},{"p":"0.2091","s":17245},{"p":"0.193","s":5000},{"p":"0.206","s":7167},{"p":"0.1931","s":1},{"p":"0.2062","s":7985},{"p":"0.2073","s":7716}],"s":"WOO_USDT","t":1684930181965,"u":536375822}}
1684930182.2114928: {"time":1684930182,"time_ms":1684930182062,"channel":"futures.order_book_update","event":"update","result":{"U":203083413,"a":[{"p":"0.2981","s":33764}],"b":[],"s":"RDNT_USDT","t":1684930181960,"u":203083413}}
1684930182.2364602: {"time":1684930182,"time_ms":1684930182087,"channel":"futures.order_book_update","event":"update","result":{"U":536375823,"a":[],"b":[{"p":"0.2094","s":22475}],"s":"WOO_USDT","t":1684930182046,"u":536375823}}
1684930182.3386846: {"time":1684930182,"time_ms":1684930182189,"channel":"futures.order_book_update","event":"update","result":{"U":536375824,"a":[{"p":"0.221","s":28968},{"p":"0.2146","s":0},{"p":"0.2287","s":1},{"p":"0.2143","s":15150},{"p":"0.2147","s":14052},{"p":"0.2126","s":4582},{"p":"0.2125","s":0},{"p":"0.2209","s":0},{"p":"0.229","s":2168}],"b":[{"p":"0.1931","s":1},{"p":"0.2057","s":1410},{"p":"0.1995","s":28359},{"p":"0.2079","s":11965},{"p":"0.2058","s":14401},{"p":"0.1994","s":0},{"p":"0.2078","s":0}],"s":"WOO_USDT","t":1684930182163,"u":536375835}}
1684930182.405879: {"time":1684930182,"time_ms":1684930182256,"channel":"futures.order_book_update","event":"update","result":{"U":3132789331,"a":[],"b":[{"p":"0.7696","s":1056}],"s":"OMG_USDT","t":1684930182232,"u":3132789331}}
1684930182.5065079: {"time":1684930182,"time_ms":1684930182357,"channel":"futures.order_book_update","event":"update","result":{"U":6160356,"a":[],"b":[{"p":"0.7378","s":1568}],"s":"PHB_USDT","t":1684930182275,"u":6160356}}
1684930182.5089614: {"time":1684930182,"time_ms":1684930182359,"channel":"futures.order_book_update","event":"update","result":{"U":489455933,"a":[{"p":"0.4095","s":278},{"p":"0.4089","s":0},{"p":"0.4104","s":0},{"p":"0.4101","s":0},{"p":"0.4092","s":0},{"p":"0.421","s":1},{"p":"0.4204","s":7419},{"p":"0.411","s":287}],"b":[],"s":"SFP_USDT","t":1684930182311,"u":489455938}}
1684930182.606306: {"time":1684930182,"time_ms":1684930182456,"channel":"futures.order_book_update","event":"update","result":{"U":3132789332,"a":[],"b":[{"p":"0.7696","s":1056}],"s":"OMG_USDT","t":1684930182429,"u":3132789333}}
1684930182.611853: {"time":1684930182,"time_ms":1684930182462,"channel":"futures.order_book_update","event":"update","result":{"U":6160357,"a":[{"p":"0.7407","s":1986},{"p":"0.7399","s":681},{"p":"0.74","s":0},{"p":"0.9042","s":22},{"p":"0.7473","s":942}],"b":[{"p":"0.7374","s":748},{"p":"0.7372","s":2085},{"p":"0.7378","s":1550},{"p":"0.7376","s":154},{"p":"0.738","s":678},{"p":"0.7373","s":0},{"p":"0.7187","s":16787},{"p":"0.7353","s":1415}],"s":"PHB_USDT","t":1684930182442,"u":6160364}}
1684930182.6584656: {"time":1684930182,"time_ms":1684930182509,"channel":"futures.book_ticker","event":"update","result":{"t":1684930182501,"u":58251406,"s":"DIA_USDT","b":"0.285","B":1203,"a":"0.2891","A":1185}}
1684930182.7206712: {"time":1684930182,"time_ms":1684930182571,"channel":"futures.order_book_update","event":"update","result":{"U":3132789334,"a":[],"b":[{"p":"0.7696","s":1921}],"s":"OMG_USDT","t":1684930182522,"u":3132789334}}
1684930182.7399352: {"time":1684930182,"time_ms":1684930182590,"channel":"futures.order_book_update","event":"update","result":{"U":58251406,"a":[{"p":"0.2891","s":1185}],"b":[],"s":"DIA_USDT","t":1684930182501,"u":58251406}}
1684930183.0257869: {"time":1684930182,"time_ms":1684930182601,"channel":"futures.order_book_update","event":"update","result":{"U":124930274,"a":[{"p":"58.63","s":3667},{"p":"83.87","s":500},{"p":"59.84","s":1}],"b":[{"p":"56.69","s":3667},{"p":"53.89","s":1},{"p":"55.98","s":8667},{"p":"56.62","s":445}],"s":"QUICK_USDT","t":1684930182531,"u":124930275}}
1684930183.0258415: {"time":1684930182,"time_ms":1684930182618,"channel":"futures.order_book_update","event":"update","result":{"U":244770086,"a":[{"p":"0.1799","s":1},{"p":"0.1751","s":744},{"p":"0.175","s":871},{"p":"0.1737","s":0},{"p":"0.1882","s":2}],"b":[],"s":"FRONT_USDT","t":1684930182591,"u":244770087}}
1684930183.0258803: {"time":1684930182,"time_ms":1684930182655,"channel":"futures.order_book_update","event":"update","result":{"U":3132789335,"a":[],"b":[{"p":"0.7696","s":1056}],"s":"OMG_USDT","t":1684930182628,"u":3132789335}}
1684930183.025901: {"time":1684930182,"time_ms":1684930182661,"channel":"futures.order_book_update","event":"update","result":{"U":489455939,"a":[{"p":"0.411","s":0},{"p":"0.4095","s":0}],"b":[],"s":"SFP_USDT","t":1684930182601,"u":489455940}}
1684930183.0259268: {"time":1684930182,"time_ms":1684930182680,"channel":"futures.order_book_update","event":"update","result":{"U":124930276,"a":[],"b":[{"p":"53.89","s":1},{"p":"55.93","s":175},{"p":"55.87","s":0}],"s":"QUICK_USDT","t":1684930182637,"u":124930277}}
1684930183.0259523: {"time":1684930182,"time_ms":1684930182799,"channel":"futures.book_ticker","event":"update","result":{"t":1684930182787,"u":58251407,"s":"DIA_USDT","b":"0.285","B":1203,"a":"0.2891","A":2916}}
1684930183.0259683: {"time":1684930182,"time_ms":1684930182857,"channel":"futures.order_book_update","event":"update","result":{"U":3132789336,"a":[],"b":[{"p":"0.7696","s":1921}],"s":"OMG_USDT","t":1684930182786,"u":3132789336}}
1684930183.045055: {"time":1684930182,"time_ms":1684930182895,"channel":"futures.order_book_update","event":"update","result":{"U":58251407,"a":[{"p":"0.2891","s":2916}],"b":[],"s":"DIA_USDT","t":1684930182787,"u":58251407}}
1684930183.3059971: {"time":1684930183,"time_ms":1684930183156,"channel":"futures.order_book_update","event":"update","result":{"U":203083414,"a":[],"b":[{"p":"0.2966","s":28307},{"p":"0.2967","s":32415}],"s":"RDNT_USDT","t":1684930183131,"u":203083416}}
1684930183.3092856: {"time":1684930183,"time_ms":1684930183159,"channel":"futures.order_book_update","event":"update","result":{"U":3132789337,"a":[],"b":[{"p":"0.7696","s":1056}],"s":"OMG_USDT","t":1684930183119,"u":3132789337}}
1684930183.400351: {"time":1684930183,"time_ms":1684930183250,"channel":"futures.order_book_update","event":"update","result":{"U":203083417,"a":[{"p":"0.2997","s":0}],"b":[{"p":"0.2965","s":4094},{"p":"0.2946","s":0}],"s":"RDNT_USDT","t":1684930183222,"u":203083419}}
1684930183.6080346: {"time":1684930183,"time_ms":1684930183458,"channel":"futures.order_book_update","event":"update","result":{"U":203083420,"a":[],"b":[{"p":"0.282","s":0},{"p":"0.2756","s":1},{"p":"0.2821","s":72},{"p":"0.2702","s":98},{"p":"0.2701","s":1},{"p":"0.291","s":31},{"p":"0.2909","s":0}],"s":"RDNT_USDT","t":1684930183414,"u":203083425}}
1684930183.6114047: {"time":1684930183,"time_ms":1684930183461,"channel":"futures.order_book_update","event":"update","result":{"U":3132789338,"a":[],"b":[{"p":"0.7696","s":1921}],"s":"OMG_USDT","t":1684930183441,"u":3132789338}}
1684930184.1079936: {"time":1684930183,"time_ms":1684930183958,"channel":"futures.order_book_update","event":"update","result":{"U":3132789339,"a":[],"b":[{"p":"0.7696","s":1056}],"s":"OMG_USDT","t":1684930183881,"u":3132789339}}
1684930184.3123815: {"time":1684930184,"time_ms":1684930184162,"channel":"futures.order_book_update","event":"update","result":{"U":3132789340,"a":[],"b":[{"p":"0.7696","s":1921}],"s":"OMG_USDT","t":1684930184138,"u":3132789340}}
1684930184.4081042: {"time":1684930184,"time_ms":1684930184258,"channel":"futures.order_book_update","event":"update","result":{"U":3132789341,"a":[],"b":[{"p":"0.7696","s":1056}],"s":"OMG_USDT","t":1684930184194,"u":3132789341}}
1684930184.50415: {"time":1684930184,"time_ms":1684930184354,"channel":"futures.order_book_update","event":"update","result":{"U":3132789342,"a":[],"b":[{"p":"0.7696","s":1921}],"s":"OMG_USDT","t":1684930184319,"u":3132789342}}
1684930184.5317903: {"time":1684930184,"time_ms":1684930184382,"channel":"futures.order_book_update","event":"update","result":{"U":536375836,"a":[{"p":"0.2114","s":97968}],"b":[{"p":"0.2091","s":52951},{"p":"0.209","s":64400}],"s":"WOO_USDT","t":1684930184303,"u":536375857}}
1684930184.6067116: {"time":1684930184,"time_ms":1684930184457,"channel":"futures.order_book_update","event":"update","result":{"U":203083426,"a":[{"p":"0.2981","s":33428}],"b":[],"s":"RDNT_USDT","t":1684930184367,"u":203083426}}
1684930184.7057927: {"time":1684930184,"time_ms":1684930184556,"channel":"futures.order_book_update","event":"update","result":{"U":203083427,"a":[{"p":"0.3002","s":0}],"b":[{"p":"0.2963","s":7621},{"p":"0.2941","s":0}],"s":"RDNT_USDT","t":1684930184487,"u":203083429}}
1684930184.709379: {"time":1684930184,"time_ms":1684930184560,"channel":"futures.order_book_update","event":"update","result":{"U":3132789343,"a":[],"b":[{"p":"0.7696","s":1921}],"s":"OMG_USDT","t":1684930184489,"u":3132789344}}
1684930184.900875: {"time":1684930184,"time_ms":1684930184751,"channel":"futures.order_book_update","event":"update","result":{"U":203083430,"a":[{"p":"0.3001","s":3226},{"p":"0.2996","s":562},{"p":"0.3195","s":14},{"p":"0.3034","s":32}],"b":[{"p":"0.2946","s":562},{"p":"0.2941","s":562},{"p":"0.2745","s":1},{"p":"0.2916","s":2016},{"p":"0.292","s":133},{"p":"0.2756","s":1}],"s":"RDNT_USDT","t":1684930184743,"u":203083433}}
1684930185.0314124: {"time":1684930184,"time_ms":1684930184882,"channel":"futures.order_book_update","event":"update","result":{"U":536375858,"a":[{"p":"0.2114","s":19135}],"b":[{"p":"0.209","s":20211},{"p":"0.2091","s":17245}],"s":"WOO_USDT","t":1684930184860,"u":536375879}}
1684930185.1078792: {"time":1684930184,"time_ms":1684930184958,"channel":"futures.order_book_update","event":"update","result":{"U":3132789345,"a":[],"b":[{"p":"0.7696","s":1056}],"s":"OMG_USDT","t":1684930184886,"u":3132789345}}
1684930185.2060592: {"time":1684930185,"time_ms":1684930185056,"channel":"futures.order_book_update","event":"update","result":{"U":203083434,"a":[{"p":"0.2981","s":34886}],"b":[{"p":"0.2963","s":8987}],"s":"RDNT_USDT","t":1684930185032,"u":203083435}}
1684930185.3112512: {"time":1684930185,"time_ms":1684930185161,"channel":"futures.order_book_update","event":"update","result":{"U":943784226,"a":[],"b":[{"p":"0.8308","s":0}],"s":"LIT_USDT","t":1684930185121,"u":943784226}}
1684930185.592866: {"time":1684930185,"time_ms":1684930185257,"channel":"futures.order_book_update","event":"update","result":{"U":943784227,"a":[{"p":"0.8376","s":0}],"b":[{"p":"0.8299","s":1757},{"p":"0.8211","s":4805},{"p":"0.8214","s":2022},{"p":"0.8285","s":482},{"p":"0.8301","s":1757},{"p":"0.8122","s":80},{"p":"0.8252","s":484},{"p":"0.6306","s":16},{"p":"0.8137","s":3545}],"s":"LIT_USDT","t":1684930185240,"u":943784229}}
1684930185.5928984: {"time":1684930185,"time_ms":1684930185357,"channel":"futures.order_book_update","event":"update","result":{"U":3132789346,"a":[],"b":[{"p":"0.7696","s":1921}],"s":"OMG_USDT","t":1684930185298,"u":3132789346}}
1684930185.5929325: {"time":1684930185,"time_ms":1684930185360,"channel":"futures.order_book_update","event":"update","result":{"U":943784230,"a":[],"b":[{"p":"0.8317","s":3926}],"s":"LIT_USDT","t":1684930185272,"u":943784230}}
1684930185.5929477: {"time":1684930185,"time_ms":1684930185421,"channel":"futures.book_ticker","event":"update","result":{"t":1684930185388,"u":943784231,"s":"LIT_USDT","b":"0.8323","B":479,"a":"0.8362","A":3328}}
1684930185.592969: {"time":1684930185,"time_ms":1684930185441,"channel":"futures.book_ticker","event":"update","result":{"t":1684930185426,"u":943784233,"s":"LIT_USDT","b":"0.8323","B":479,"a":"0.8361","A":479}}
1684930185.603339: {"time":1684930185,"time_ms":1684930185453,"channel":"futures.order_book_update","event":"update","result":{"U":943784231,"a":[{"p":"0.8361","s":479},{"p":"0.8363","s":625},{"p":"0.839","s":1760},{"p":"0.8428","s":474},{"p":"0.8362","s":3328},{"p":"0.8601","s":75},{"p":"0.8429","s":474},{"p":"0.8389","s":1760},{"p":"0.8572","s":3692}],"b":[],"s":"LIT_USDT","t":1684930185426,"u":943784233}}
1684930185.6198936: {"time":1684930185,"time_ms":1684930185470,"channel":"futures.order_book_update","event":"update","result":{"U":3132789347,"a":[],"b":[{"p":"0.7696","s":1056}],"s":"OMG_USDT","t":1684930185389,"u":3132789347}}
1684930185.8006074: {"time":1684930185,"time_ms":1684930185650,"channel":"futures.order_book_update","event":"update","result":{"U":489455941,"a":[{"p":"0.4116","s":578},{"p":"0.4089","s":280},{"p":"0.4092","s":291},{"p":"0.4249","s":1},{"p":"0.4118","s":123},{"p":"0.409","s":2452},{"p":"0.4244","s":1}],"b":[],"s":"SFP_USDT","t":1684930185634,"u":489455942}}
1684930185.8097775: {"time":1684930185,"time_ms":1684930185660,"channel":"futures.order_book_update","event":"update","result":{"U":3132789348,"a":[],"b":[{"p":"0.7696","s":1921}],"s":"OMG_USDT","t":1684930185592,"u":3132789348}}
1684930186.0508041: {"time":1684930185,"time_ms":1684930185901,"channel":"futures.order_book_update","event":"update","result":{"U":536375880,"a":[{"p":"0.2113","s":54772},{"p":"0.2112","s":13654},{"p":"0.2287","s":1},{"p":"0.2142","s":1687},{"p":"0.2122","s":3768}],"b":[{"p":"0.1943","s":1},{"p":"0.2062","s":7985},{"p":"0.209","s":48778},{"p":"0.2089","s":51408}],"s":"WOO_USDT","t":1684930185894,"u":536375901}}
1684930186.2064216: {"time":1684930186,"time_ms":1684930186057,"channel":"futures.order_book_update","event":"update","result":{"U":3132789349,"a":[],"b":[{"p":"0.7696","s":1056}],"s":"OMG_USDT","t":1684930185957,"u":3132789349}}
1684930186.3037112: {"time":1684930186,"time_ms":1684930186154,"channel":"futures.order_book_update","event":"update","result":{"U":203083436,"a":[],"b":[{"p":"0.2967","s":33662},{"p":"0.2969","s":6640}],"s":"RDNT_USDT","t":1684930186064,"u":203083437}}
1684930186.3069398: {"time":1684930186,"time_ms":1684930186157,"channel":"futures.order_book_update","event":"update","result":{"U":3132789350,"a":[],"b":[{"p":"0.7696","s":1921}],"s":"OMG_USDT","t":1684930186085,"u":3132789350}}
1684930186.3392115: {"time":1684930186,"time_ms":1684930186190,"channel":"futures.order_book_update","event":"update","result":{"U":124930278,"a":[],"b":[{"p":"55.88","s":175},{"p":"55.93","s":0},{"p":"53.89","s":1}],"s":"QUICK_USDT","t":1684930186139,"u":124930279}}
1684930186.4042482: {"time":1684930186,"time_ms":1684930186254,"channel":"futures.order_book_update","event":"update","result":{"U":203083438,"a":[{"p":"0.2996","s":0}],"b":[{"p":"0.2946","s":0}],"s":"RDNT_USDT","t":1684930186217,"u":203083439}}
1684930186.4074965: {"time":1684930186,"time_ms":1684930186258,"channel":"futures.order_book_update","event":"update","result":{"U":3132789351,"a":[],"b":[{"p":"0.7696","s":1921}],"s":"OMG_USDT","t":1684930186247,"u":3132789352}}
1684930186.7118518: {"time":1684930186,"time_ms":1684930186562,"channel":"futures.order_book_update","event":"update","result":{"U":3132789353,"a":[],"b":[{"p":"0.7696","s":1056}],"s":"OMG_USDT","t":1684930186476,"u":3132789353}}
1684930186.9135635: {"time":1684930186,"time_ms":1684930186764,"channel":"futures.book_ticker","event":"update","result":{"t":1684930186744,"u":6160386,"s":"PHB_USDT","b":"0.7382","B":136,"a":"0.7391","A":677}}
1684930186.917751: {"time":1684930186,"time_ms":1684930186767,"channel":"futures.order_book_update","event":"update","result":{"U":6160365,"a":[{"p":"0.7392","s":0},{"p":"0.7398","s":1412},{"p":"0.7468","s":102},{"p":"0.7473","s":942},{"p":"0.9322","s":21},{"p":"0.7394","s":65},{"p":"0.7519","s":15530},{"p":"0.7396","s":900},{"p":"0.7401","s":1590},{"p":"0.7395","s":1561},{"p":"0.7399","s":0},{"p":"0.7407","s":1986},{"p":"0.7416","s":820},{"p":"0.7402","s":681},{"p":"0.7403","s":721},{"p":"0.8934","s":2},{"p":"0.7406","s":782},{"p":"0.9042","s":22}],"b":[{"p":"0.7353","s":1415},{"p":"0.7377","s":0},{"p":"0.7187","s":16787},{"p":"0.7105","s":1},{"p":"0.7322","s":2032},{"p":"0.7378","s":1414},{"p":"0.7382","s":136},{"p":"0.7376","s":0},{"p":"0.7371","s":0},{"p":"0.7165","s":16814},{"p":"0.7342","s":828},{"p":"0.7375","s":681},{"p":"0.738","s":981},{"p":"0.7373","s":721},{"p":"0.7372","s":1404},{"p":"0.7374","s":748}],"s":"PHB_USDT","t":1684930186744,"u":6160386}}
1684930186.9226987: {"time":1684930186,"time_ms":1684930186773,"channel":"futures.order_book_update","event":"update","result":{"U":489455943,"a":[{"p":"0.4101","s":276},{"p":"0.4104","s":271},{"p":"0.421","s":1},{"p":"0.4108","s":3678},{"p":"0.4204","s":7419}],"b":[],"s":"SFP_USDT","t":1684930186676,"u":489455944}}
1684930187.007834: {"time":1684930186,"time_ms":1684930186858,"channel":"futures.order_book_update","event":"update","result":{"U":6160387,"a":[{"p":"0.7395","s":149}],"b":[],"s":"PHB_USDT","t":1684930186832,"u":6160387}}
1684930187.1071503: {"time":1684930186,"time_ms":1684930186957,"channel":"futures.order_book_update","event":"update","result":{"U":3132789354,"a":[],"b":[{"p":"0.7696","s":1921}],"s":"OMG_USDT","t":1684930186887,"u":3132789354}}
1684930187.1104827: {"time":1684930186,"time_ms":1684930186961,"channel":"futures.order_book_update","event":"update","result":{"U":6160388,"a":[{"p":"0.7396","s":2313}],"b":[],"s":"PHB_USDT","t":1684930186869,"u":6160388}}
1684930187.4081597: {"time":1684930187,"time_ms":1684930187258,"channel":"futures.order_book_update","event":"update","result":{"U":203083440,"a":[{"p":"0.2981","s":33428},{"p":"0.3001","s":2664}],"b":[{"p":"0.2941","s":0}],"s":"RDNT_USDT","t":1684930187216,"u":203083442}}
1684930187.4292686: {"time":1684930187,"time_ms":1684930187280,"channel":"futures.order_book_update","event":"update","result":{"U":124930280,"a":[],"b":[{"p":"55.74","s":525},{"p":"54.14","s":1},{"p":"55.72","s":9681}],"s":"QUICK_USDT","t":1684930187257,"u":124930281}}
1684930187.5361667: {"time":1684930187,"time_ms":1684930187386,"channel":"futures.order_book_update","event":"update","result":{"U":536375902,"a":[{"p":"0.2112","s":9519},{"p":"0.2113","s":0}],"b":[{"p":"0.209","s":20211},{"p":"0.2089","s":0}],"s":"WOO_USDT","t":1684930187299,"u":536375923}}
1684930187.5388997: {"time":1684930187,"time_ms":1684930187389,"channel":"futures.order_book_update","event":"update","result":{"U":124930282,"a":[],"b":[{"p":"56.03","s":350},{"p":"56.01","s":0},{"p":"54.14","s":1},{"p":"55.98","s":8667}],"s":"QUICK_USDT","t":1684930187321,"u":124930283}}
1684930187.6064374: {"time":1684930187,"time_ms":1684930187456,"channel":"futures.order_book_update","event":"update","result":{"U":3132789355,"a":[],"b":[{"p":"0.7696","s":1056}],"s":"OMG_USDT","t":1684930187355,"u":3132789355}}
1684930187.7037122: {"time":1684930187,"time_ms":1684930187554,"channel":"futures.order_book_update","event":"update","result":{"U":3132789356,"a":[],"b":[{"p":"0.7696","s":1921}],"s":"OMG_USDT","t":1684930187455,"u":3132789356}}
1684930187.7153714: {"time":1684930187,"time_ms":1684930187565,"channel":"futures.order_book_update","event":"update","result":{"U":203083443,"a":[{"p":"0.2996","s":562},{"p":"0.3001","s":3226},{"p":"0.3195","s":14},{"p":"0.3034","s":32}],"b":[{"p":"0.2946","s":562},{"p":"0.2941","s":562},{"p":"0.2745","s":1},{"p":"0.2916","s":2016},{"p":"0.2756","s":1},{"p":"0.292","s":133}],"s":"RDNT_USDT","t":1684930187481,"u":203083446}}
1684930187.840058: {"time":1684930187,"time_ms":1684930187690,"channel":"futures.order_book_update","event":"update","result":{"U":124930284,"a":[],"b":[{"p":"55.75","s":175},{"p":"55.88","s":0},{"p":"54.14","s":1}],"s":"QUICK_USDT","t":1684930187637,"u":124930285}}
1684930188.0096688: {"time":1684930187,"time_ms":1684930187860,"channel":"futures.order_book_update","event":"update","result":{"U":6160389,"a":[],"b":[{"p":"0.7011","s":0},{"p":"0.6716","s":0},{"p":"0.6864","s":0},{"p":"0.6865","s":29},{"p":"0.6717","s":43},{"p":"0.7012","s":13}],"s":"PHB_USDT","t":1684930187851,"u":6160394}}
1684930188.2013316: {"time":1684930188,"time_ms":1684930188051,"channel":"futures.order_book_update","event":"update","result":{"U":203083447,"a":[],"b":[{"p":"0.2963","s":7621}],"s":"RDNT_USDT","t":1684930187982,"u":203083447}}
1684930188.2055335: {"time":1684930188,"time_ms":1684930188055,"channel":"futures.order_book_update","event":"update","result":{"U":3132789357,"a":[],"b":[{"p":"0.7696","s":1056}],"s":"OMG_USDT","t":1684930187958,"u":3132789357}}
1684930188.2712345: {"time":1684930188,"time_ms":1684930188121,"channel":"futures.book_ticker","event":"update","result":{"t":1684930188110,"u":6160395,"s":"PHB_USDT","b":"0.7382","B":136,"a":"0.7393","A":711}}
1684930188.3079352: {"time":1684930188,"time_ms":1684930188158,"channel":"futures.order_book_update","event":"update","result":{"U":3132789358,"a":[],"b":[{"p":"0.7696","s":1921}],"s":"OMG_USDT","t":1684930188064,"u":3132789358}}
1684930188.3130124: {"time":1684930188,"time_ms":1684930188163,"channel":"futures.order_book_update","event":"update","result":{"U":6160395,"a":[{"p":"0.7391","s":0}],"b":[{"p":"0.7374","s":0}],"s":"PHB_USDT","t":1684930188153,"u":6160396}}
1684930188.409718: {"time":1684930188,"time_ms":1684930188260,"channel":"futures.order_book_update","event":"update","result":{"U":3132789359,"a":[],"b":[{"p":"0.7696","s":1056}],"s":"OMG_USDT","t":1684930188178,"u":3132789359}}
1684930188.4127245: {"time":1684930188,"time_ms":1684930188263,"channel":"futures.order_book_update","event":"update","result":{"U":943784234,"a":[{"p":"0.878","s":6501},{"p":"0.8612","s":4694},{"p":"0.8782","s":0},{"p":"0.8614","s":0},{"p":"0.8531","s":0},{"p":"0.8572","s":3692},{"p":"0.8529","s":1106}],"b":[],"s":"LIT_USDT","t":1684930188229,"u":943784239}}
1684930188.4416091: {"time":1684930188,"time_ms":1684930188292,"channel":"futures.order_book_update","event":"update","result":{"U":536375924,"a":[{"p":"0.2131","s":18361}],"b":[],"s":"WOO_USDT","t":1684930188250,"u":536375924}}
1684930188.5038896: {"time":1684930188,"time_ms":1684930188354,"channel":"futures.order_book_update","event":"update","result":{"U":6160397,"a":[],"b":[{"p":"0.7378","s":0}],"s":"PHB_USDT","t":1684930188333,"u":6160397}}
1684930188.605954: {"time":1684930188,"time_ms":1684930188456,"channel":"futures.order_book_update","event":"update","result":{"U":3132789360,"a":[],"b":[{"p":"0.7696","s":1921}],"s":"OMG_USDT","t":1684930188424,"u":3132789360}}
1684930188.8207393: {"time":1684930188,"time_ms":1684930188671,"channel":"futures.book_ticker","event":"update","result":{"t":1684930188660,"u":6160399,"s":"PHB_USDT","b":"0.7383","B":678,"a":"0.7393","A":711}}
1684930188.9095294: {"time":1684930188,"time_ms":1684930188760,"channel":"futures.order_book_update","event":"update","result":{"U":6160398,"a":[{"p":"0.74","s":746},{"p":"0.7406","s":782},{"p":"0.8934","s":2},{"p":"0.7468","s":102}],"b":[{"p":"0.7383","s":678},{"p":"0.7342","s":828},{"p":"0.7373","s":721},{"p":"0.7165","s":16814}],"s":"PHB_USDT","t":1684930188660,"u":6160399}}
1684930189.1101916: {"time":1684930188,"time_ms":1684930188960,"channel":"futures.order_book_update","event":"update","result":{"U":3132789361,"a":[],"b":[{"p":"0.7696","s":1056}],"s":"OMG_USDT","t":1684930188949,"u":3132789361}}
1684930189.5046222: {"time":1684930189,"time_ms":1684930189355,"channel":"futures.order_book_update","event":"update","result":{"U":3132789362,"a":[],"b":[{"p":"0.7696","s":1921}],"s":"OMG_USDT","t":1684930189340,"u":3132789362}}
1684930189.6151023: {"time":1684930189,"time_ms":1684930189465,"channel":"futures.order_book_update","event":"update","result":{"U":3132789363,"a":[],"b":[{"p":"0.7696","s":1921}],"s":"OMG_USDT","t":1684930189413,"u":3132789364}}
1684930189.629672: {"time":1684930189,"time_ms":1684930189479,"channel":"futures.order_book_update","event":"update","result":{"U":6160400,"a":[],"b":[{"p":"0.738","s":2394}],"s":"PHB_USDT","t":1684930189382,"u":6160400}}
1684930190.1055493: {"time":1684930189,"time_ms":1684930189955,"channel":"futures.order_book_update","event":"update","result":{"U":6160401,"a":[{"p":"0.7396","s":900},{"p":"0.74","s":2158},{"p":"0.7398","s":0}],"b":[],"s":"PHB_USDT","t":1684930189923,"u":6160403}}
1684930190.140713: {"time":1684930189,"time_ms":1684930189991,"channel":"futures.book_ticker","event":"update","result":{"t":1684930189976,"u":6160404,"s":"PHB_USDT","b":"0.7383","B":678,"a":"0.7394","A":65}}
1684930190.2065263: {"time":1684930190,"time_ms":1684930190057,"channel":"futures.order_book_update","event":"update","result":{"U":3132789365,"a":[],"b":[{"p":"0.7696","s":1056}],"s":"OMG_USDT","t":1684930189960,"u":3132789365}}
1684930190.2091033: {"time":1684930190,"time_ms":1684930190059,"channel":"futures.order_book_update","event":"update","result":{"U":6160404,"a":[{"p":"0.7393","s":0}],"b":[{"p":"0.7356","s":0}],"s":"PHB_USDT","t":1684930190015,"u":6160405}}
1684930190.2350535: {"time":1684930190,"time_ms":1684930190085,"channel":"futures.order_book_update","event":"update","result":{"U":536375925,"a":[{"p":"0.2105","s":14832},{"p":"0.2123","s":6876},{"p":"0.2112","s":0}],"b":[{"p":"0.209","s":10692},{"p":"0.2094","s":17716},{"p":"0.2096","s":2483},{"p":"0.208","s":3971}],"s":"WOO_USDT","t":1684930190037,"u":536375931}}
1684930190.3083947: {"time":1684930190,"time_ms":1684930190158,"channel":"futures.order_book_update","event":"update","result":{"U":6160406,"a":[{"p":"0.7405","s":0}],"b":[],"s":"PHB_USDT","t":1684930190115,"u":6160406}}
1684930190.345424: {"time":1684930190,"time_ms":1684930190196,"channel":"futures.order_book_update","event":"update","result":{"U":536375932,"a":[{"p":"0.2113","s":9514},{"p":"0.2124","s":13730},{"p":"0.229","s":2168},{"p":"0.2143","s":15150},{"p":"0.2123","s":6876}],"b":[{"p":"0.2091","s":26759},{"p":"0.2081","s":11893},{"p":"0.1943","s":1},{"p":"0.2062","s":7985},{"p":"0.2095","s":9725},{"p":"0.2097","s":6820}],"s":"WOO_USDT","t":1684930190175,"u":536375937}}
1684930190.347798: {"time":1684930190,"time_ms":1684930190198,"channel":"futures.order_book_update","event":"update","result":{"U":124930286,"a":[],"b":[{"p":"54.67","s":0}],"s":"QUICK_USDT","t":1684930190099,"u":124930286}}
1684930190.4060276: {"time":1684930190,"time_ms":1684930190256,"channel":"futures.order_book_update","event":"update","result":{"U":6160407,"a":[{"p":"0.7424","s":2312}],"b":[],"s":"PHB_USDT","t":1684930190227,"u":6160407}}
1684930190.5114112: {"time":1684930190,"time_ms":1684930190361,"channel":"futures.order_book_update","event":"update","result":{"U":3132789366,"a":[],"b":[{"p":"0.7696","s":1921}],"s":"OMG_USDT","t":1684930190339,"u":3132789366}}
1684930190.5388167: {"time":1684930190,"time_ms":1684930190389,"channel":"futures.book_ticker","event":"update","result":{"t":1684930190380,"u":536375939,"s":"WOO_USDT","b":"0.2101","B":1687,"a":"0.2104","A":5450}}
1684930190.5509071: {"time":1684930190,"time_ms":1684930190401,"channel":"futures.order_book_update","event":"update","result":{"U":536375938,"a":[{"p":"0.2104","s":5450}],"b":[{"p":"0.2099","s":5668}],"s":"WOO_USDT","t":1684930190380,"u":536375939}}
1684930190.6288772: {"time":1684930190,"time_ms":1684930190479,"channel":"futures.order_book_update","event":"update","result":{"U":536375940,"a":[{"p":"0.2105","s":15180}],"b":[{"p":"0.2064","s":8971},{"p":"0.2099","s":6016},{"p":"0.2066","s":7129},{"p":"0.206","s":0},{"p":"0.1943","s":1}],"s":"WOO_USDT","t":1684930190409,"u":536375943}}
1684930190.7007692: {"time":1684930190,"time_ms":1684930190551,"channel":"futures.order_book_update","event":"update","result":{"U":6160408,"a":[{"p":"0.7395","s":826}],"b":[],"s":"PHB_USDT","t":1684930190509,"u":6160408}}
1684930190.8038003: {"time":1684930190,"time_ms":1684930190654,"channel":"futures.order_book_update","event":"update","result":{"U":3132789367,"a":[],"b":[{"p":"0.7696","s":1056}],"s":"OMG_USDT","t":1684930190558,"u":3132789367}}
1684930190.8065515: {"time":1684930190,"time_ms":1684930190657,"channel":"futures.order_book_update","event":"update","result":{"U":6160409,"a":[{"p":"0.7395","s":149}],"b":[{"p":"0.7371","s":786},{"p":"0.7165","s":16814},{"p":"0.7342","s":828}],"s":"PHB_USDT","t":1684930190597,"u":6160410}}
1684930190.8087926: {"time":1684930190,"time_ms":1684930190659,"channel":"futures.book_ticker","event":"update","result":{"t":1684930190651,"u":536375954,"s":"WOO_USDT","b":"0.21","B":8002,"a":"0.2104","A":5450}}
1684930190.8299074: {"time":1684930190,"time_ms":1684930190680,"channel":"futures.book_ticker","event":"update","result":{"t":1684930190672,"u":536375961,"s":"WOO_USDT","b":"0.2102","B":1687,"a":"0.2104","A":5450}}
1684930190.8370738: {"time":1684930190,"time_ms":1684930190687,"channel":"futures.order_book_update","event":"update","result":{"U":536375944,"a":[{"p":"0.2143","s":15150},{"p":"0.2123","s":6876},{"p":"0.2113","s":9514},{"p":"0.2106","s":2490},{"p":"0.211","s":5190},{"p":"0.2108","s":0},{"p":"0.2107","s":9514},{"p":"0.229","s":2168},{"p":"0.2105","s":14832},{"p":"0.2109","s":5190},{"p":"0.2287","s":1},{"p":"0.2142","s":1687},{"p":"0.2122","s":3768}],"b":[{"p":"0.2064","s":8971},{"p":"0.2083","s":1850},{"p":"0.2096","s":2483},{"p":"0.2099","s":348},{"p":"0.21","s":8002},{"p":"0.2102","s":1687},{"p":"0.2101","s":0},{"p":"0.1943","s":1}],"s":"WOO_USDT","t":1684930190679,"u":536375964}}
1684930190.8787498: {"time":1684930190,"time_ms":1684930190729,"channel":"futures.book_ticker","event":"update","result":{"t":1684930190718,"u":536375970,"s":"WOO_USDT","b":"0.2102","B":1687,"a":"0.2104","A":2967}}
1684930190.947819: {"time":1684930190,"time_ms":1684930190798,"channel":"futures.order_book_update","event":"update","result":{"U":536375965,"a":[{"p":"0.2105","s":17314},{"p":"0.2104","s":2967},{"p":"0.2108","s":1687},{"p":"0.2141","s":1750},{"p":"0.212","s":3985},{"p":"0.2109","s":5190},{"p":"0.228","s":88},{"p":"0.2107","s":7827}],"b":[{"p":"0.1945","s":200},{"p":"0.2066","s":7129},{"p":"0.209","s":10692},{"p":"0.2101","s":787},{"p":"0.21","s":6822},{"p":"0.2098","s":5190},{"p":"0.2099","s":348},{"p":"0.2097","s":6820}],"s":"WOO_USDT","t":1684930190770,"u":536375978}}
1684930190.9889474: {"time":1684930190,"time_ms":1684930190839,"channel":"futures.book_ticker","event":"update","result":{"t":1684930190823,"u":536375986,"s":"WOO_USDT","b":"0.2102","B":1687,"a":"0.2104","A":2000}}
1684930191.0144665: {"time":1684930190,"time_ms":1684930190865,"channel":"futures.order_book_update","event":"update","result":{"U":6160411,"a":[{"p":"0.7542","s":44},{"p":"0.7463","s":193},{"p":"0.7537","s":83},{"p":"0.7465","s":0},{"p":"0.7439","s":0},{"p":"0.9672","s":10},{"p":"0.7437","s":193},{"p":"0.7539","s":0},{"p":"0.7524","s":98},{"p":"1.0147","s":12},{"p":"0.991","s":11}],"b":[],"s":"PHB_USDT","t":1684930190786,"u":6160416}}
1684930191.0307577: {"time":1684930190,"time_ms":1684930190881,"channel":"futures.order_book_update","event":"update","result":{"U":536375979,"a":[{"p":"0.2104","s":2000},{"p":"0.2105","s":18118},{"p":"0.2107","s":0}],"b":[{"p":"0.2098","s":5668},{"p":"0.2027","s":0},{"p":"0.2099","s":348}],"s":"WOO_USDT","t":1684930190871,"u":536375989}}
1684930191.1083186: {"time":1684930190,"time_ms":1684930190958,"channel":"futures.order_book_update","event":"update","result":{"U":3132789368,"a":[],"b":[{"p":"0.7696","s":1921}],"s":"OMG_USDT","t":1684930190875,"u":3132789368}}
1684930191.1112497: {"time":1684930190,"time_ms":1684930190961,"channel":"futures.order_book_update","event":"update","result":{"U":6160417,"a":[{"p":"0.7396","s":2313},{"p":"0.7424","s":819}],"b":[{"p":"0.7013","s":13},{"p":"0.6866","s":29},{"p":"0.7012","s":0},{"p":"0.6865","s":0}],"s":"PHB_USDT","t":1684930190952,"u":6160422}}
1684930191.1432915: {"time":1684930190,"time_ms":1684930190994,"channel":"futures.order_book_update","event":"update","result":{"U":536375990,"a":[],"b":[{"p":"0.2099","s":826},{"p":"0.2098","s":5190}],"s":"WOO_USDT","t":1684930190942,"u":536375995}}
1684930191.207529: {"time":1684930191,"time_ms":1684930191058,"channel":"futures.order_book_update","event":"update","result":{"U":3132789369,"a":[],"b":[{"p":"0.7696","s":1056}],"s":"OMG_USDT","t":1684930191032,"u":3132789369}}
1684930191.2106712: {"time":1684930191,"time_ms":1684930191061,"channel":"futures.order_book_update","event":"update","result":{"U":6160423,"a":[{"p":"0.7909","s":0},{"p":"0.8057","s":0},{"p":"0.7761","s":0},{"p":"0.9672","s":10},{"p":"0.806","s":40},{"p":"0.7406","s":2270},{"p":"0.7912","s":25},{"p":"0.7764","s":14}],"b":[{"p":"0.6718","s":43},{"p":"0.6717","s":0}],"s":"PHB_USDT","t":1684930191033,"u":6160431}}
1684930191.2450686: {"time":1684930191,"time_ms":1684930191096,"channel":"futures.order_book_update","event":"update","result":{"U":536375996,"a":[{"p":"0.2109","s":12942},{"p":"0.2113","s":53099},{"p":"0.2114","s":44527}],"b":[{"p":"0.2091","s":56322},{"p":"0.2092","s":49973},{"p":"0.1952","s":1},{"p":"0.207","s":15},{"p":"0.2098","s":5190},{"p":"0.1945","s":200},{"p":"0.2067","s":19151},{"p":"0.2071","s":13461},{"p":"0.2099","s":826}],"s":"WOO_USDT","t":1684930191022,"u":536376023}}
1684930191.2807343: {"time":1684930191,"time_ms":1684930191131,"channel":"futures.book_ticker","event":"update","result":{"t":1684930191123,"u":6160432,"s":"PHB_USDT","b":"0.7383","B":678,"a":"0.7393","A":677}}
1684930191.3015206: {"time":1684930191,"time_ms":1684930191152,"channel":"futures.order_book_update","event":"update","result":{"U":6160432,"a":[{"p":"0.7519","s":15530},{"p":"0.7416","s":820},{"p":"0.7401","s":1590},{"p":"0.7393","s":677},{"p":"0.9322","s":21}],"b":[],"s":"PHB_USDT","t":1684930191123,"u":6160432}}
1684930191.5492175: {"time":1684930191,"time_ms":1684930191400,"channel":"futures.order_book_update","event":"update","result":{"U":536376024,"a":[{"p":"0.2113","s":9514},{"p":"0.2114","s":19135}],"b":[{"p":"0.2091","s":26759},{"p":"0.2092","s":0}],"s":"WOO_USDT","t":1684930191339,"u":536376045}}
1684930191.6112444: {"time":1684930191,"time_ms":1684930191461,"channel":"futures.order_book_update","event":"update","result":{"U":3132789370,"a":[],"b":[{"p":"0.7696","s":1921}],"s":"OMG_USDT","t":1684930191369,"u":3132789370}}
1684930191.7362902: {"time":1684930191,"time_ms":1684930191587,"channel":"futures.order_book_update","event":"update","result":{"U":536376046,"a":[],"b":[{"p":"0.1995","s":0},{"p":"0.1943","s":1},{"p":"0.208","s":9060},{"p":"0.1996","s":28359},{"p":"0.2059","s":16124},{"p":"0.2079","s":6876},{"p":"0.2058","s":0}],"s":"WOO_USDT","t":1684930191572,"u":536376051}}
1684930191.8436298: {"time":1684930191,"time_ms":1684930191694,"channel":"futures.order_book_update","event":"update","result":{"U":536376052,"a":[],"b":[{"p":"0.2097","s":6820},{"p":"0.2101","s":1116},{"p":"0.1943","s":1},{"p":"0.2067","s":19151},{"p":"0.209","s":10692}],"s":"WOO_USDT","t":1684930191621,"u":536376053}}
1684930192.0094423: {"time":1684930191,"time_ms":1684930191860,"channel":"futures.book_ticker","event":"update","result":{"t":1684930191850,"u":536376057,"s":"WOO_USDT","b":"0.2101","B":2803,"a":"0.2104","A":2000}}
1684930192.051993: {"time":1684930191,"time_ms":1684930191902,"channel":"futures.order_book_update","event":"update","result":{"U":536376054,"a":[{"p":"0.2142","s":1687},{"p":"0.2106","s":2142},{"p":"0.2107","s":1687},{"p":"0.2105","s":18466},{"p":"0.2108","s":0},{"p":"0.2122","s":3768},{"p":"0.211","s":5190},{"p":"0.2287","s":1}],"b":[{"p":"0.2101","s":2803},{"p":"0.2102","s":0}],"s":"WOO_USDT","t":1684930191879,"u":536376059}}
1684930192.4147408: {"time":1684930192,"time_ms":1684930192265,"channel":"futures.order_book_update","event":"update","result":{"U":3132789371,"a":[{"p":"0.772","s":1003},{"p":"1.2486","s":0},{"p":"0.8113","s":434},{"p":"0.7767","s":1104},{"p":"0.7726","s":2919}],"b":[{"p":"0.7703","s":42},{"p":"0.7696","s":918},{"p":"0.7695","s":15557}],"s":"OMG_USDT","t":1684930192249,"u":3132789379}}
1684930192.5088792: {"time":1684930192,"time_ms":1684930192359,"channel":"futures.order_book_update","event":"update","result":{"U":3132789380,"a":[],"b":[{"p":"0.7696","s":53}],"s":"OMG_USDT","t":1684930192333,"u":3132789380}}
1684930192.70768: {"time":1684930192,"time_ms":1684930192558,"channel":"futures.order_book_update","event":"update","result":{"U":3132789381,"a":[],"b":[{"p":"0.7696","s":918}],"s":"OMG_USDT","t":1684930192543,"u":3132789381}}
1684930192.748322: {"time":1684930192,"time_ms":1684930192599,"channel":"futures.order_book_update","event":"update","result":{"U":536376060,"a":[{"p":"0.228","s":88},{"p":"0.2141","s":1750},{"p":"0.212","s":3985},{"p":"0.2113","s":65462},{"p":"0.2112","s":4264}],"b":[{"p":"0.2091","s":54078},{"p":"0.2092","s":42969},{"p":"0.1943","s":1},{"p":"0.2067","s":19151},{"p":"0.209","s":10692}],"s":"WOO_USDT","t":1684930192585,"u":536376081}}
1684930192.9296553: {"time":1684930192,"time_ms":1684930192780,"channel":"futures.order_book_update","event":"update","result":{"U":536376082,"a":[{"p":"0.2113","s":9514},{"p":"0.2112","s":0}],"b":[{"p":"0.2092","s":0},{"p":"0.2091","s":26759}],"s":"WOO_USDT","t":1684930192704,"u":536376103}}
1684930193.1040313: {"time":1684930192,"time_ms":1684930192954,"channel":"futures.order_book_update","event":"update","result":{"U":3132789382,"a":[],"b":[{"p":"0.7696","s":53}],"s":"OMG_USDT","t":1684930192940,"u":3132789382}}
1684930193.1107016: {"time":1684930192,"time_ms":1684930192960,"channel":"futures.order_book_update","event":"update","result":{"U":489455945,"a":[{"p":"0.411","s":297},{"p":"0.4095","s":283},{"p":"0.4104","s":0},{"p":"0.4089","s":0},{"p":"0.4092","s":0},{"p":"0.4116","s":578},{"p":"0.4101","s":0},{"p":"0.4244","s":1},{"p":"0.421","s":1},{"p":"0.4108","s":3678}],"b":[],"s":"SFP_USDT","t":1684930192896,"u":489455950}}
1684930193.1907887: {"time":1684930193,"time_ms":1684930193041,"channel":"futures.book_ticker","event":"update","result":{"t":1684930193027,"u":203083458,"s":"RDNT_USDT","b":"0.297","B":500,"a":"0.2974","A":63}}
1684930193.2024508: {"time":1684930193,"time_ms":1684930193053,"channel":"futures.order_book_update","event":"update","result":{"U":203083448,"a":[{"p":"0.2978","s":28306},{"p":"0.2985","s":0},{"p":"0.2983","s":0},{"p":"0.2986","s":84389},{"p":"0.2974","s":63}],"b":[{"p":"0.2969","s":5302},{"p":"0.2965","s":3508},{"p":"0.2961","s":0},{"p":"0.2963","s":0},{"p":"0.2967","s":32415}],"s":"RDNT_USDT","t":1684930193032,"u":203083459}}
1684930193.2056062: {"time":1684930193,"time_ms":1684930193056,"channel":"futures.order_book_update","event":"update","result":{"U":3132789383,"a":[],"b":[{"p":"0.7696","s":918},{"p":"0.7699","s":748},{"p":"0.7697","s":0}],"s":"OMG_USDT","t":1684930193036,"u":3132789385}}
1684930193.3038104: {"time":1684930193,"time_ms":1684930193154,"channel":"futures.order_book_update","event":"update","result":{"U":203083460,"a":[{"p":"0.2977","s":6039},{"p":"0.2978","s":29257},{"p":"0.2975","s":1575},{"p":"0.2989","s":1338},{"p":"0.3035","s":16846},{"p":"0.2984","s":7050},{"p":"0.2982","s":8472},{"p":"0.2996","s":562},{"p":"0.3196","s":1},{"p":"0.3001","s":3226},{"p":"0.32","s":4},{"p":"0.3036","s":2016}],"b":[{"p":"0.2968","s":9640},{"p":"0.2969","s":6640},{"p":"0.2953","s":42549},{"p":"0.2962","s":4967},{"p":"0.2941","s":0},{"p":"0.2729","s":1},{"p":"0.2961","s":7050},{"p":"0.2946","s":562},{"p":"0.2944","s":34254},{"p":"0.2734","s":1},{"p":"0.2745","s":1},{"p":"0.2965","s":4094},{"p":"0.2912","s":17803},{"p":"0.2914","s":1009},{"p":"0.2916","s":2016}],"s":"RDNT_USDT","t":1684930193130,"u":203083478}}
1684930193.4143589: {"time":1684930193,"time_ms":1684930193264,"channel":"futures.order_book_update","event":"update","result":{"U":203083479,"a":[],"b":[{"p":"0.2941","s":562},{"p":"0.2756","s":1},{"p":"0.292","s":133}],"s":"RDNT_USDT","t":1684930193145,"u":203083479}}
1684930193.5118463: {"time":1684930193,"time_ms":1684930193358,"channel":"futures.order_book_update","event":"update","result":{"U":3132789386,"a":[],"b":[{"p":"0.7696","s":53}],"s":"OMG_USDT","t":1684930193311,"u":3132789386}}
1684930193.6373203: {"time":1684930193,"time_ms":1684930193487,"channel":"futures.order_book_update","event":"update","result":{"U":536376104,"a":[{"p":"0.2107","s":0},{"p":"0.211","s":5190},{"p":"0.2287","s":1},{"p":"0.2142","s":1687},{"p":"0.2122","s":3768},{"p":"0.2108","s":1687},{"p":"0.2105","s":18118},{"p":"0.2106","s":2490}],"b":[],"s":"WOO_USDT","t":1684930193386,"u":536376107}}
1684930194.0061524: {"time":1684930193,"time_ms":1684930193856,"channel":"futures.order_book_update","event":"update","result":{"U":489455951,"a":[{"p":"0.421","s":1},{"p":"0.4204","s":7419},{"p":"0.4108","s":3678},{"p":"0.4107","s":262},{"p":"0.4098","s":249},{"p":"0.411","s":297}],"b":[],"s":"SFP_USDT","t":1684930193788,"u":489455952}}
1684930194.1129444: {"time":1684930193,"time_ms":1684930193963,"channel":"futures.order_book_update","event":"update","result":{"U":489455953,"a":[{"p":"0.4098","s":0},{"p":"0.4107","s":0},{"p":"0.4095","s":0},{"p":"0.411","s":0}],"b":[],"s":"SFP_USDT","t":1684930193880,"u":489455956}}
1684930194.3128002: {"time":1684930194,"time_ms":1684930194163,"channel":"futures.order_book_update","event":"update","result":{"U":6160433,"a":[{"p":"0.806","s":0},{"p":"0.7764","s":0},{"p":"0.7912","s":0},{"p":"0.9322","s":21},{"p":"0.7911","s":25},{"p":"0.8059","s":40},{"p":"0.7763","s":14}],"b":[],"s":"PHB_USDT","t":1684930194141,"u":6160438}}
1684930194.641777: {"time":1684930194,"time_ms":1684930194492,"channel":"futures.order_book_update","event":"update","result":{"U":536376108,"a":[{"p":"0.228","s":88},{"p":"0.2141","s":1750},{"p":"0.212","s":3985},{"p":"0.2113","s":20499},{"p":"0.2112","s":4264}],"b":[{"p":"0.2092","s":17189},{"p":"0.1943","s":1},{"p":"0.2067","s":19151},{"p":"0.209","s":10692}],"s":"WOO_USDT","t":1684930194438,"u":536376113}}
1684930194.7100646: {"time":1684930194,"time_ms":1684930194560,"channel":"futures.order_book_update","event":"update","result":{"U":6160439,"a":[],"b":[{"p":"0.7374","s":1412},{"p":"0.7372","s":0},{"p":"0.7165","s":16814},{"p":"0.7342","s":828}],"s":"PHB_USDT","t":1684930194526,"u":6160440}}
1684930194.8396492: {"time":1684930194,"time_ms":1684930194690,"channel":"futures.order_book_update","event":"update","result":{"U":536376114,"a":[],"b":[{"p":"0.2059","s":1723},{"p":"0.2079","s":11366},{"p":"0.2058","s":15686},{"p":"0.208","s":3971},{"p":"0.1945","s":200}],"s":"WOO_USDT","t":1684930194679,"u":536376117}}
1684930194.8648517: {"time":1684930194,"time_ms":1684930194715,"channel":"futures.order_book_update","event":"update","result":{"U":244770088,"a":[{"p":"0.1737","s":871},{"p":"0.175","s":0},{"p":"0.1751","s":744},{"p":"0.1882","s":2},{"p":"0.1799","s":1}],"b":[],"s":"FRONT_USDT","t":1684930194604,"u":244770089}}
1684930194.930086: {"time":1684930194,"time_ms":1684930194780,"channel":"futures.order_book_update","event":"update","result":{"U":536376118,"a":[],"b":[{"p":"0.1995","s":27318},{"p":"0.1996","s":0},{"p":"0.1945","s":200}],"s":"WOO_USDT","t":1684930194699,"u":536376119}}
1684930195.1313558: {"time":1684930194,"time_ms":1684930194982,"channel":"futures.order_book_update","event":"update","result":{"U":536376120,"a":[{"p":"0.2141","s":1750},{"p":"0.212","s":3985},{"p":"0.211","s":5190},{"p":"0.228","s":88},{"p":"0.2107","s":1687},{"p":"0.2106","s":2142},{"p":"0.2105","s":18466},{"p":"0.2108","s":0}],"b":[],"s":"WOO_USDT","t":1684930194920,"u":536376123}}
