wss://api.gemini.com/v2/marketdata/ <-> 1624493666.4493928
wss://api.gemini.com/v2/marketdata/ <- 1624493666.602648: {"type":"subscribe","subscriptions":[{"name":"l2","symbols":["BTCGBP","LINKETH","FILUSD","ZECLTC","BATBTC","ETHEUR","LTCETH","GRTUSD","ANKRUSD","ALCXUSD"]}]}
1624493666.63848: {"type":"l2_updates","symbol":"ALCXUSD","changes":[["buy","302.75","0.00001"],["buy","302.32","2.445529"],["buy","302.15","6.589575"],["buy","301.64","16.466937"],["buy","301.21","16.490761"],["buy","301.05","0.00001"],["buy","300.98","4.153099"],["buy","299.86","0.00001"],["buy","299.60","4.172229"],["buy","299.42","4.174737"],["buy","299.34","4.175853"],["buy","298.91","8.36372"],["buy","298.89","4.18214"],["buy","298.85","0.00001"],["buy","298.83","4.287553"],["buy","298.36","0.00001"],["buy","298.33","4.18999"],["buy","298.16","0.00002"],["buy","298.13","4.192801"],["buy","297.88","4.19632"],["buy","297.55","4.200974"],["buy","297.33","0.00001"],["buy","297.24","0.00001"],["buy","297.06","4.207904"],["buy","297.01","4.208612"],["buy","296.67","4.213435"],["buy","296.63","4.214003"],["buy","296.41","82.408206"],["buy","296.04","0.00001"],["buy","295.96","4.223543"],["buy","295.77","4.226256"],["buy","295.44","4.230977"],["buy","295.35","7.547314"],["buy","295.09","5.994447"],["buy","294.40","4.245923"],["buy","294.37","4.246356"],["buy","294.14","0.288497"],["buy","294.03","4.251266"],["buy","293.90","4.253147"],["buy","293.70","0.00002"],["buy","293.68","0.00001"],["buy","293.55","4.258218"],["buy","293.40","4.260395"],["buy","293.16","0.068222"],["buy","293.08","4.265047"],["buy","292.96","0.097193"],["buy","292.92","0.00001"],["buy","292.85","4.268396"],["buy","292.70","4.270584"],["buy","292.51","5.253295"],["buy","292.49","4.27365"],["buy","292.45","4.274234"],["buy","292.43","0.00001"],["buy","292.27","0.00002"],["buy","292.25","0.00001"],["buy","292.16","6.454483"],["buy","292.12","0.00001"],["buy","292.00","0.1"],["buy","291.64","20.2032"],["buy","291.43","0.00001"],["buy","290.53","1.264708"],["buy","290.52","1.691868"],["buy","290.10","0.00005"],["buy","290.08","0.201148"],["buy","288.94","0.006921"],["buy","287.62","0.890755"],["buy","285.88","0.006995"],["buy","284.74","1.69586"],["buy","283.85","0.4363"],["buy","283.12","0.00001"],["buy","282.37","0.008853"],["buy","281.89","1.190361"],["buy","281.01","0.577228"],["buy","279.78","0.008935"],["buy","278.81","0.00001"],["buy","277.08","0.009022"],["buy","277.00","0.1"],["buy","275.42","0.486794"],["buy","275.00","3.25"],["buy","274.86","0.00001"],["buy","274.34","0.00001"],["buy","274.28","0.009114"],["buy","273.66","0.00001"],["buy","273.52","0.472597"],["buy","269.98","0.00001"],["buy","269.97","0.00001"],["buy","269.82","0.00001"],["buy","267.22","0.00001"],["buy","265.77","0.00001"],["buy","264.12","0.00001"],["buy","263.23","0.00001"],["buy","263.00","0.1"],["buy","262.63","0.00001"],["buy","261.46","0.00001"],["buy","257.47","0.00001"],["buy","256.96","0.00001"],["buy","256.62","0.00001"],["buy","255.55","0.3"],["buy","255.00","0.078431"],["buy","254.80","0.00001"],["buy","252.31","0.00001"],["buy","252.22","0.00001"],["buy","251.00","0.199601"],["buy","250.00","41.8"],["buy","249.48","0.040083"],["buy","249.28","0.2"],["buy","245.00","1"],["buy","237.00","0.1"],["buy","230.00","2.173913"],["buy","223.00","0.1"],["buy","220.00","0.5"],["buy","215.55","0.4"],["buy","215.00","0.1"],["buy","210.00","1"],["buy","207.00","0.1"],["buy","200.00","1.35"],["buy","199.00","0.5"],["buy","192.00","0.1"],["buy","185.00","0.1"],["buy","177.00","0.1"],["buy","175.55","0.5"],["buy","169.00","0.1"],["buy","159.00","1.07"],["buy","150.00","13.333333"],["buy","135.55","0.7"],["buy","120.00","60"],["buy","101.16","0.5"],["buy","100.01","0.09969"],["buy","100.00","0.25"],["buy","95.55","1"],["buy","65.55","2"],["buy","59.00","1"],["buy","35.55","4"],["sell","303.05","8.12974"],["sell","303.33","10.554763"],["sell","303.34","0.276424"],["sell","303.63","6.590505"],["sell","304.52","16.48243"],["sell","304.81","16.464171"],["sell","306.06","0.183647"],["sell","309.62","82.292105"],["sell","309.78","0.238312"],["sell","319.14","0.528977"],["sell","319.29","0.873924"],["sell","320.58","0.463857"],["sell","322.33","0.529934"],["sell","322.48","0.474488"],["sell","322.55","0.416526"],["sell","325.55","0.582153"],["sell","328.96","0.801833"],["sell","330.30","0.407164"],["sell","332.25","1.049612"],["sell","333.60","0.589544"],["sell","335.57","0.476757"],["sell","338.77","0.345067"],["sell","342.16","0.511203"],["sell","494.00","155"],["sell","600.00","0.05"],["sell","750.00","0.05"]],"trades":[{"type":"trade","symbol":"ALCXUSD","event_id":45465785975,"timestamp":1624493651491,"price":"302.53","quantity":"0.992143","side":"buy"},{"type":"trade","symbol":"ALCXUSD","event_id":45465785690,"timestamp":1624493651353,"price":"302.32","quantity":"4.140581","side":"sell"},{"type":"trade","symbol":"ALCXUSD","event_id":45465785411,"timestamp":1624493651198,"price":"302.56","quantity":"3.292266","side":"sell"},{"type":"trade","symbol":"ALCXUSD","event_id":45465784627,"timestamp":1624493650978,"price":"302.67","quantity":"4.12991","side":"buy"},{"type":"trade","symbol":"ALCXUSD","event_id":45465676104,"timestamp":1624493583877,"price":"301.17","quantity":"0.845491","side":"buy"},{"type":"trade","symbol":"ALCXUSD","event_id":45465675775,"timestamp":1624493583383,"price":"301.20","quantity":"0.00001","side":"sell"},{"type":"trade","symbol":"ALCXUSD","event_id":45465675773,"timestamp":1624493583383,"price":"301.30","quantity":"0.00001","side":"sell"},{"type":"trade","symbol":"ALCXUSD","event_id":45465675771,"timestamp":1624493583383,"price":"301.41","quantity":"0.00001","side":"sell"},{"type":"trade","symbol":"ALCXUSD","event_id":45465675769,"timestamp":1624493583383,"price":"301.46","quantity":"3.304958","side":"sell"},{"type":"trade","symbol":"ALCXUSD","event_id":45465675738,"timestamp":1624493583358,"price":"301.54","quantity":"4.145387","side":"buy"},{"type":"trade","symbol":"ALCXUSD","event_id":45465431462,"timestamp":1624493434546,"price":"301.19","quantity":"0.00001","side":"sell"},{"type":"trade","symbol":"ALCXUSD","event_id":45465431460,"timestamp":1624493434546,"price":"301.19","quantity":"0.00001","side":"sell"},{"type":"trade","symbol":"ALCXUSD","event_id":45465317844,"timestamp":1624493374987,"price":"301.19","quantity":"0.00001","side":"sell"},{"type":"trade","symbol":"ALCXUSD","event_id":45465009348,"timestamp":1624493230727,"price":"301.28","quantity":"0.00001","side":"sell"},{"type":"trade","symbol":"ALCXUSD","event_id":45464892765,"timestamp":1624493180325,"price":"300.45","quantity":"4.160376","side":"buy"},{"type":"trade","symbol":"ALCXUSD","event_id":45464829712,"timestamp":1624493149653,"price":"300.54","quantity":"0.00001","side":"sell"},{"type":"trade","symbol":"ALCXUSD","event_id":45464829710,"timestamp":1624493149653,"price":"300.61","quantity":"0.00001","side":"sell"},{"type":"trade","symbol":"ALCXUSD","event_id":45464829708,"timestamp":1624493149653,"price":"300.61","quantity":"0.00001","side":"sell"},{"type":"trade","symbol":"ALCXUSD","event_id":45464829706,"timestamp":1624493149653,"price":"300.61","quantity":"0.00001","side":"sell"},{"type":"trade","symbol":"ALCXUSD","event_id":45464829704,"timestamp":1624493149653,"price":"300.63","quantity":"0.00001","side":"sell"},{"type":"trade","symbol":"ALCXUSD","event_id":45464829356,"timestamp":1624493149370,"price":"300.92","quantity":"0.00001","side":"sell"},{"type":"trade","symbol":"ALCXUSD","event_id":45464811812,"timestamp":1624493139930,"price":"301.10","quantity":"0.00001","side":"sell"},{"type":"trade","symbol":"ALCXUSD","event_id":45464801580,"timestamp":1624493135999,"price":"301.10","quantity":"0.00001","side":"sell"},{"type":"trade","symbol":"ALCXUSD","event_id":45464757677,"timestamp":1624493116106,"price":"301.25","quantity":"0.00001","side":"sell"},{"type":"trade","symbol":"ALCXUSD","event_id":45464575311,"timestamp":1624493019362,"price":"301.26","quantity":"0.00001","side":"sell"},{"type":"trade","symbol":"ALCXUSD","event_id":45464482075,"timestamp":1624492974844,"price":"300.71","quantity":"0.042624","side":"sell"},{"type":"trade","symbol":"ALCXUSD","event_id":45464482073,"timestamp":1624492974844,"price":"300.86","quantity":"0.00001","side":"sell"},{"type":"trade","symbol":"ALCXUSD","event_id":45464482071,"timestamp":1624492974844,"price":"301.36","quantity":"0.00001","side":"sell"},{"type":"trade","symbol":"ALCXUSD","event_id":45464482069,"timestamp":1624492974844,"price":"301.36","quantity":"0.00001","side":"sell"},{"type":"trade","symbol":"ALCXUSD","event_id":45464482067,"timestamp":1624492974844,"price":"301.36","quantity":"0.00001","side":"sell"},{"type":"trade","symbol":"ALCXUSD","event_id":45464482065,"timestamp":1624492974844,"price":"301.38","quantity":"0.00001","side":"sell"},{"type":"trade","symbol":"ALCXUSD","event_id":45464415401,"timestamp":1624492950533,"price":"302.01","quantity":"0.00001","side":"sell"},{"type":"trade","symbol":"ALCXUSD","event_id":45464327236,"timestamp":1624492917728,"price":"302.31","quantity":"2.824964","side":"buy"},{"type":"trade","symbol":"ALCXUSD","event_id":45464090389,"timestamp":1624492849036,"price":"301.72","quantity":"0.00001","side":"sell"},{"type":"trade","symbol":"ALCXUSD","event_id":45464065397,"timestamp":1624492839530,"price":"301.72","quantity":"0.00001","side":"sell"},{"type":"trade","symbol":"ALCXUSD","event_id":45464051375,"timestamp":1624492830844,"price":"301.86","quantity":"0.00001","side":"sell"},{"type":"trade","symbol":"ALCXUSD","event_id":45464050441,"timestamp":1624492830329,"price":"301.99","quantity":"0.00001","side":"sell"},{"type":"trade","symbol":"ALCXUSD","event_id":45464045639,"timestamp":1624492828539,"price":"301.99","quantity":"0.00001","side":"sell"},{"type":"trade","symbol":"ALCXUSD","event_id":45463983049,"timestamp":1624492793517,"price":"301.99","quantity":"0.00001","side":"sell"},{"type":"trade","symbol":"ALCXUSD","event_id":45463909422,"timestamp":1624492730535,"price":"301.90","quantity":"0.00001","side":"sell"},{"type":"trade","symbol":"ALCXUSD","event_id":45463908555,"timestamp":1624492729987,"price":"301.91","quantity":"0.00001","side":"sell"},{"type":"trade","symbol":"ALCXUSD","event_id":45463791708,"timestamp":1624492612937,"price":"302.31","quantity":"0.022471","side":"buy"},{"type":"trade","symbol":"ALCXUSD","event_id":45463791706,"timestamp":1624492612937,"price":"302.16","quantity":"0.296819","side":"buy"},{"type":"trade","symbol":"ALCXUSD","event_id":45463712751,"timestamp":1624492548250,"price":"301.99","quantity":"0.00001","side":"sell"},{"type":"trade","symbol":"ALCXUSD","event_id":45463712749,"timestamp":1624492548250,"price":"301.99","quantity":"0.00001","side":"sell"},{"type":"trade","symbol":"ALCXUSD","event_id":45463712747,"timestamp":1624492548250,"price":"301.99","quantity":"0.00001","side":"sell"},{"type":"trade","symbol":"ALCXUSD","event_id":45463712745,"timestamp":1624492548250,"price":"301.99","quantity":"0.00001","side":"sell"},{"type":"trade","symbol":"ALCXUSD","event_id":45463712743,"timestamp":1624492548250,"price":"301.99","quantity":"0.00001","side":"sell"},{"type":"trade","symbol":"ALCXUSD","event_id":45463667517,"timestamp":1624492501297,"price":"302.31","quantity":"1.287393","side":"buy"},{"type":"trade","symbol":"ALCXUSD","event_id":45463667515,"timestamp":1624492501297,"price":"302.29","quantity":"0.277166","side":"buy"}],"auction_events":[]}
1624493666.672212: {"type":"l2_updates","symbol":"ANKRUSD","changes":[["buy","0.07929","14300"],["buy","0.07921","12596.614378"],["buy","0.07913","25206.464561"],["buy","0.07906","64350"],["buy","0.07904","44111.312982"],["buy","0.07897","62948.779671"],["buy","0.07888","63023.436658"],["buy","0.07879","1980.065617"],["buy","0.07867","5.449663"],["buy","0.07861","16275.658243"],["buy","0.07848","275000"],["buy","0.07836","2576.681869"],["buy","0.07829","3844.622289"],["buy","0.07794","5.500706"],["buy","0.07781","3073.624094"],["buy","0.07778","3869.831307"],["buy","0.07776","314673.660304"],["buy","0.07728","3894.869035"],["buy","0.07722","5.551994"],["buy","0.07686","3111.614503"],["buy","0.07678","3920.23286"],["buy","0.07651","5.603516"],["buy","0.07629","3945.411968"],["buy","0.07628","5980.162696"],["buy","0.07592","3150.140816"],["buy","0.0758","3976.572613"],["buy","0.07542","2568.850311"],["buy","0.07531","3996.753141"],["buy","0.0751","5.708722"],["buy","0.075","9855.449209"],["buy","0.07482","4022.928081"],["buy","0.07441","5.761659"],["buy","0.07434","4048.903404"],["buy","0.07386","4075.216342"],["buy","0.07372","5.815586"],["buy","0.07345","5000"],["buy","0.07339","4101.314607"],["buy","0.07304","5.869729"],["buy","0.07292","4127.749301"],["buy","0.07245","4154.526971"],["buy","0.07237","5.924071"],["buy","0.07198","4181.654335"],["buy","0.07177","5000"],["buy","0.0717","5.979428"],["buy","0.07152","4208.549763"],["buy","0.07104","6.03498"],["buy","0.07038","6.091574"],["buy","0.07","100"],["buy","0.06973","6.148358"],["buy","0.06909","6.205312"],["buy","0.06845","6.263331"],["buy","0.06781","6.322445"],["buy","0.06719","6.380786"],["buy","0.06657","6.440214"],["buy","0.06595","6.500758"],["buy","0.06534","6.561448"],["buy","0.065","100"],["buy","0.06474","6.622259"],["buy","0.06414","6.684207"],["buy","0.06355","6.746263"],["buy","0.06296","6.809482"],["buy","0.06238","6.872796"],["buy","0.06181","6.936176"],["buy","0.06124","7.000735"],["buy","0.06067","7.066508"],["buy","0.06011","7.132341"],["buy","0.06","5100"],["buy","0.05955","7.199413"],["buy","0.05904","13000"],["buy","0.059","7.266526"],["buy","0.05897","10000"],["buy","0.05846","7.333647"],["buy","0.05792","7.40202"],["buy","0.05738","7.47168"],["buy","0.05685","7.541337"],["buy","0.05633","7.610954"],["buy","0.05581","7.681867"],["buy","0.0555","14360.36036"],["buy","0.05529","7.754115"],["buy","0.055","54.363636"],["buy","0.05478","7.826306"],["buy","0.05428","7.898398"],["buy","0.054","18637.777777"],["buy","0.05378","7.97183"],["buy","0.05328","8.046641"],["buy","0.05323","1"],["buy","0.05279","8.12133"],["buy","0.0525","1500"],["buy","0.0523","8.197419"],["buy","0.05222","957.487552"],["buy","0.05182","8.27335"],["buy","0.05134","8.350702"],["buy","0.05086","8.429513"],["buy","0.05039","8.508137"],["buy","0.05005","7500"],["buy","0.05","53660"],["buy","0.04993","8.586522"],["buy","0.04947","8.666364"],["buy","0.04901","8.747705"],["buy","0.04856","8.828769"],["buy","0.04811","8.911349"],["buy","0.0479","3131.524008"],["buy","0.04767","8.993602"],["buy","0.04728","2000"],["buy","0.04722","9.07931"],["buy","0.04679","9.162749"],["buy","0.04636","9.247736"],["buy","0.04621","1000"],["buy","0.04593","9.334314"],["buy","0.0455","9.422528"],["buy","0.04511","221.680336"],["buy","0.04508","9.510316"],["buy","0.045","11118.888888"],["buy","0.04467","9.597605"],["buy","0.04426","9.686512"],["buy","0.0425","2000"],["buy","0.042","15476.190476"],["buy","0.04121","1000"],["buy","0.0412","703.883495"],["buy","0.04","59437.75"],["buy","0.03621","1000"],["buy","0.03501","28563.267637"],["buy","0.035","64642.857142"],["buy","0.03413","729.856431"],["buy","0.03333","1000"],["buy","0.03314","6035.003017"],["buy","0.0315","1000"],["buy","0.03121","1000"],["buy","0.03","105800"],["buy","0.0275","3500"],["buy","0.02621","2000"],["buy","0.026","3846.153846"],["buy","0.025","61500"],["buy","0.02121","2000"],["buy","0.021","5000"],["buy","0.0205","5000"],["buy","0.02","231120"],["buy","0.01621","5000"],["buy","0.0135","8000"],["buy","0.01121","5000"],["buy","0.0065","20000"],["buy","0.00621","10000"],["sell","0.07946","1020.482111"],["sell","0.07957","14300"],["sell","0.07963","44101.608839"],["sell","0.07968","63025.475739"],["sell","0.07978","62945.370808"],["sell","0.07981","64350"],["sell","0.07991","3036.164666"],["sell","0.07997","3795.655473"],["sell","0.08","169510.5"],["sell","0.08029","5.399559"],["sell","0.0805","3770.928076"],["sell","0.08089","2999.231135"],["sell","0.08102","3746.520775"],["sell","0.08104","5.349701"],["sell","0.08105","314905.93544"],["sell","0.08156","3721.967096"],["sell","0.0818","5.300099"],["sell","0.08189","2962.451266"],["sell","0.0825","10000"],["sell","0.08256","7.570634"],["sell","0.0829","3093.10257"],["sell","0.08333","7.570634"],["sell","0.08392","3093.10257"],["sell","0.0841","7.570634"],["sell","0.08454","28.661036"],["sell","0.08489","7.570634"],["sell","0.08497","3093.10257"],["sell","0.085","356.528153"],["sell","0.0852","6000"],["sell","0.08568","7.570634"],["sell","0.0862","632.62"],["sell","0.08648","7.570634"],["sell","0.08729","7.570634"],["sell","0.088","214544.965721"],["sell","0.0881","7.570634"],["sell","0.08892","7.570634"],["sell","0.08975","7.570634"],["sell","0.09059","7.570634"],["sell","0.09144","7.570634"],["sell","0.092","2018"],["sell","0.09229","7.570634"],["sell","0.093","20000"],["sell","0.09315","7.570634"],["sell","0.09402","7.570634"],["sell","0.09489","7.570634"],["sell","0.09578","7.570634"],["sell","0.09667","7.570634"],["sell","0.09757","7.570634"],["sell","0.09848","7.570634"],["sell","0.0994","7.570634"],["sell","0.10","255276.491386"],["sell","0.1002","4490.017965"],["sell","0.10033","7.570634"],["sell","0.10126","7.570634"],["sell","0.1022","7.570634"],["sell","0.10316","7.570634"],["sell","0.10412","7.570634"],["sell","0.10509","7.570634"],["sell","0.10606","7.570634"],["sell","0.1064","62225.720213"],["sell","0.10705","7.570634"],["sell","0.108","4925"],["sell","0.10805","7.570634"],["sell","0.10906","7.570634"],["sell","0.1099","3750"],["sell","0.11","20723.33"],["sell","0.11008","7.570634"],["sell","0.1111","7.570634"],["sell","0.15","2538.071065"],["sell","0.1599","12545.251509"],["sell","0.174","15440.899197"],["sell","0.25","200"],["sell","0.96","1115.983242"],["sell","1.00","200"],["sell","1.118","1789.549033"],["sell","3.30","600"],["sell","10.00","100"],["sell","75.08115","59.92093"],["sell","100.00","100"],["sell","250.00","100"],["sell","500.00","100"],["sell","1000.00","100"]],"trades":[{"type":"trade","symbol":"ANKRUSD","event_id":45465797135,"timestamp":1624493658905,"price":"0.07946","quantity":"2799.742271","side":"buy"},{"type":"trade","symbol":"ANKRUSD","event_id":45465766318,"timestamp":1624493646833,"price":"0.07896","quantity":"12974.531929","side":"sell"},{"type":"trade","symbol":"ANKRUSD","event_id":45465766316,"timestamp":1624493646833,"price":"0.07914","quantity":"249","side":"sell"},{"type":"trade","symbol":"ANKRUSD","event_id":45465766314,"timestamp":1624493646833,"price":"0.07914","quantity":"247","side":"sell"},{"type":"trade","symbol":"ANKRUSD","event_id":45465728642,"timestamp":1624493622767,"price":"0.07928","quantity":"295.500251","side":"buy"},{"type":"trade","symbol":"ANKRUSD","event_id":45465691281,"timestamp":1624493592390,"price":"0.079","quantity":"1.341864","side":"sell"},{"type":"trade","symbol":"ANKRUSD","event_id":45465679393,"timestamp":1624493586359,"price":"0.07897","quantity":"14300","side":"buy"},{"type":"trade","symbol":"ANKRUSD","event_id":45465670343,"timestamp":1624493579578,"price":"0.07881","quantity":"937.845095","side":"buy"},{"type":"trade","symbol":"ANKRUSD","event_id":45465670341,"timestamp":1624493579578,"price":"0.0788","quantity":"249","side":"buy"},{"type":"trade","symbol":"ANKRUSD","event_id":45465669443,"timestamp":1624493578935,"price":"0.07871","quantity":"16382.040883","side":"sell"},{"type":"trade","symbol":"ANKRUSD","event_id":45465667800,"timestamp":1624493578170,"price":"0.07877","quantity":"3036.164666","side":"sell"},{"type":"trade","symbol":"ANKRUSD","event_id":45465665607,"timestamp":1624493577542,"price":"0.07879","quantity":"3820.224382","side":"sell"},{"type":"trade","symbol":"ANKRUSD","event_id":45465659761,"timestamp":1624493573659,"price":"0.07901","quantity":"3002.711742","side":"buy"},{"type":"trade","symbol":"ANKRUSD","event_id":45465659194,"timestamp":1624493573270,"price":"0.07901","quantity":"2977.263163","side":"buy"},{"type":"trade","symbol":"ANKRUSD","event_id":45465640674,"timestamp":1624493567053,"price":"0.0791","quantity":"2780.344768","side":"buy"},{"type":"trade","symbol":"ANKRUSD","event_id":45465640672,"timestamp":1624493567053,"price":"0.07909","quantity":"12678.70733","side":"buy"},{"type":"trade","symbol":"ANKRUSD","event_id":45465639466,"timestamp":1624493566364,"price":"0.07898","quantity":"2438.45038","side":"sell"},{"type":"trade","symbol":"ANKRUSD","event_id":45465639464,"timestamp":1624493566364,"price":"0.07899","quantity":"239","side":"sell"},{"type":"trade","symbol":"ANKRUSD","event_id":45465639048,"timestamp":1624493566156,"price":"0.0793","quantity":"3795.655473","side":"sell"},{"type":"trade","symbol":"ANKRUSD","event_id":45465638925,"timestamp":1624493566055,"price":"0.0794","quantity":"14300","side":"sell"},{"type":"trade","symbol":"ANKRUSD","event_id":45465638923,"timestamp":1624493566055,"price":"0.0794","quantity":"5.399559","side":"sell"},{"type":"trade","symbol":"ANKRUSD","event_id":45465638921,"timestamp":1624493566055,"price":"0.07942","quantity":"8362.984455","side":"sell"},{"type":"trade","symbol":"ANKRUSD","event_id":45465638569,"timestamp":1624493565951,"price":"0.07943","quantity":"249","side":"sell"},{"type":"trade","symbol":"ANKRUSD","event_id":45465635495,"timestamp":1624493562901,"price":"0.07958","quantity":"6158.414603","side":"buy"},{"type":"trade","symbol":"ANKRUSD","event_id":45465607703,"timestamp":1624493546144,"price":"0.07958","quantity":"2889.97454","side":"buy"},{"type":"trade","symbol":"ANKRUSD","event_id":45465590219,"timestamp":1624493536179,"price":"0.07944","quantity":"42.335316","side":"buy"},{"type":"trade","symbol":"ANKRUSD","event_id":45465586885,"timestamp":1624493534793,"price":"0.07944","quantity":"2838.564493","side":"buy"},{"type":"trade","symbol":"ANKRUSD","event_id":45465585266,"timestamp":1624493533676,"price":"0.07944","quantity":"2895.294568","side":"buy"},{"type":"trade","symbol":"ANKRUSD","event_id":45465583479,"timestamp":1624493531735,"price":"0.07944","quantity":"231.838677","side":"buy"},{"type":"trade","symbol":"ANKRUSD","event_id":45465580576,"timestamp":1624493528874,"price":"0.07944","quantity":"4713.447054","side":"buy"},{"type":"trade","symbol":"ANKRUSD","event_id":45465578075,"timestamp":1624493528047,"price":"0.07944","quantity":"3578.519892","side":"buy"},{"type":"trade","symbol":"ANKRUSD","event_id":45465541225,"timestamp":1624493496724,"price":"0.07958","quantity":"15551.95809","side":"sell"},{"type":"trade","symbol":"ANKRUSD","event_id":45465532689,"timestamp":1624493492441,"price":"0.07974","quantity":"2999.231135","side":"sell"},{"type":"trade","symbol":"ANKRUSD","event_id":45465532285,"timestamp":1624493492192,"price":"0.07983","quantity":"1208.546156","side":"buy"},{"type":"trade","symbol":"ANKRUSD","event_id":45465531009,"timestamp":1624493491202,"price":"0.07982","quantity":"3770.928076","side":"sell"},{"type":"trade","symbol":"ANKRUSD","event_id":45465386669,"timestamp":1624493412899,"price":"0.07991","quantity":"1206.742132","side":"buy"},{"type":"trade","symbol":"ANKRUSD","event_id":45465377769,"timestamp":1624493408425,"price":"0.07999","quantity":"4938.366712","side":"buy"},{"type":"trade","symbol":"ANKRUSD","event_id":45465347805,"timestamp":1624493397424,"price":"0.08014","quantity":"5.349701","side":"sell"},{"type":"trade","symbol":"ANKRUSD","event_id":45465341164,"timestamp":1624493393141,"price":"0.08034","quantity":"3746.520775","side":"sell"},{"type":"trade","symbol":"ANKRUSD","event_id":45465318238,"timestamp":1624493375446,"price":"0.08123","quantity":"343.091621","side":"buy"},{"type":"trade","symbol":"ANKRUSD","event_id":45465309381,"timestamp":1624493368062,"price":"0.08153","quantity":"817.494205","side":"buy"},{"type":"trade","symbol":"ANKRUSD","event_id":45465301265,"timestamp":1624493363347,"price":"0.08104","quantity":"5.349701","side":"buy"},{"type":"trade","symbol":"ANKRUSD","event_id":45465301263,"timestamp":1624493363347,"price":"0.08102","quantity":"3746.520775","side":"buy"},{"type":"trade","symbol":"ANKRUSD","event_id":45465300324,"timestamp":1624493362716,"price":"0.08065","quantity":"8423.411758","side":"buy"},{"type":"trade","symbol":"ANKRUSD","event_id":45465270153,"timestamp":1624493350592,"price":"0.08065","quantity":"53868.815422","side":"buy"},{"type":"trade","symbol":"ANKRUSD","event_id":45465270151,"timestamp":1624493350592,"price":"0.08063","quantity":"64350","side":"buy"},{"type":"trade","symbol":"ANKRUSD","event_id":45465270149,"timestamp":1624493350592,"price":"0.08058","quantity":"43619.480212","side":"buy"},{"type":"trade","symbol":"ANKRUSD","event_id":45465270147,"timestamp":1624493350592,"price":"0.08054","quantity":"24906.336","side":"buy"},{"type":"trade","symbol":"ANKRUSD","event_id":45465270145,"timestamp":1624493350592,"price":"0.08049","quantity":"12453.794108","side":"buy"},{"type":"trade","symbol":"ANKRUSD","event_id":45465270143,"timestamp":1624493350592,"price":"0.08039","quantity":"14300","side":"buy"}],"auction_events":[]}
1624493666.707378: {"type":"l2_updates","symbol":"GRTUSD","changes":[["buy","0.6157","1499.409252"],["buy","0.6145","4050.276501"],["buy","0.6144","300"],["buy","0.6138","436"],["buy","0.6137","8101.173618"],["buy","0.6132","1405"],["buy","0.6131","8111.507292"],["buy","0.6129","4058.771933"],["buy","0.6126","12167.260938"],["buy","0.6124","0.626772"],["buy","0.612","2000"],["buy","0.6116","14060"],["buy","0.6091","5667"],["buy","0.609","140199.635016"],["buy","0.6083","0.630996"],["buy","0.6053","1413"],["buy","0.6041","0.635383"],["buy","0.6038","423"],["buy","0.6032","1414"],["buy","0.6001","0.639618"],["buy","0.599","1420"],["buy","0.5989","14866.086134"],["buy","0.596","0.644018"],["buy","0.592","0.64837"],["buy","0.5918","1375"],["buy","0.5912","1181.898064"],["buy","0.5879","0.652892"],["buy","0.5859","1.050142"],["buy","0.5855","735.787078"],["buy","0.584","0.657252"],["buy","0.5801","1.037148"],["buy","0.58","0.661784"],["buy","0.5761","0.666265"],["buy","0.5744","1.050157"],["buy","0.5722","0.670806"],["buy","0.5688","1.050138"],["buy","0.5683","0.675409"],["buy","0.5666","61.129526"],["buy","0.5645","0.679956"],["buy","0.564","61.046511"],["buy","0.5632","1.024436"],["buy","0.5606","0.684686"],["buy","0.5577","181.024416"],["buy","0.5568","0.689359"],["buy","0.5531","0.69397"],["buy","0.553","1808.318264"],["buy","0.5522","1.024397"],["buy","0.5517","180"],["buy","0.5493","0.698771"],["buy","0.5468","1.012121"],["buy","0.5456","0.70351"],["buy","0.5419","0.708313"],["buy","0.5414","1.012107"],["buy","0.54","50000"],["buy","0.5382","0.713183"],["buy","0.5373","200"],["buy","0.5361","1.02448"],["buy","0.5346","0.717985"],["buy","0.531","0.722853"],["buy","0.5308","1.02444"],["buy","0.53","943.396226"],["buy","0.5274","0.727787"],["buy","0.5256","1.012044"],["buy","0.525","476.190476"],["buy","0.5238","0.732789"],["buy","0.5204","1.02453"],["buy","0.5203","0.737719"],["buy","0.5196","500"],["buy","0.5167","0.742859"],["buy","0.5153","1.024469"],["buy","0.5132","0.747925"],["buy","0.5102","1.037073"],["buy","0.51","50000"],["buy","0.5098","0.752913"],["buy","0.5073","200"],["buy","0.5063","0.758118"],["buy","0.5052","1.037261"],["buy","0.5029","0.763243"],["buy","0.5002","1.037151"],["buy","0.50","3265.9"],["buy","0.4995","0.768439"],["buy","0.4961","0.773705"],["buy","0.4953","1.037327"],["buy","0.4927","0.779044"],["buy","0.4904","1.024488"],["buy","0.49","3000"],["buy","0.4894","0.784297"],["buy","0.4861","0.789622"],["buy","0.4856","1.024391"],["buy","0.485","50000"],["buy","0.4828","0.795019"],["buy","0.4808","1.024499"],["buy","0.48","550"],["buy","0.4795","0.80049"],["buy","0.4773","200"],["buy","0.4763","0.805868"],["buy","0.4761","1.024389"],["buy","0.473","0.811491"],["buy","0.4714","1.012091"],["buy","0.4698","0.817018"],["buy","0.468","4"],["buy","0.4668","1.012135"],["buy","0.4667","0.822445"],["buy","0.4635","0.828123"],["buy","0.4622","1.012075"],["buy","0.4604","0.833699"],["buy","0.46","50000"],["buy","0.4577","1.012113"],["buy","0.4572","0.839534"],["buy","0.4569","100"],["buy","0.4541","0.845266"],["buy","0.4532","1.012046"],["buy","0.4511","0.850887"],["buy","0.45","705.555555"],["buy","0.4488","1.012079"],["buy","0.448","0.856775"],["buy","0.445","0.862551"],["buy","0.4444","1.012114"],["buy","0.442","0.868405"],["buy","0.44","80.557492"],["buy","0.439","0.87434"],["buy","0.436","0.880356"],["buy","0.4357","1.012067"],["buy","0.435","150000"],["buy","0.4333","227.671359"],["buy","0.433","0.886455"],["buy","0.4314","1.012096"],["buy","0.4305","500"],["buy","0.4301","0.892432"],["buy","0.43","1580"],["buy","0.428","625.846411"],["buy","0.4272","1.89849"],["buy","0.426","23.474178"],["buy","0.425","100"],["buy","0.4243","0.904631"],["buy","0.423","1"],["buy","0.4214","0.910857"],["buy","0.42","446.095238"],["buy","0.4196","638.363339"],["buy","0.4189","1"],["buy","0.4186","0.91695"],["buy","0.4157","0.923346"],["buy","0.4148","1"],["buy","0.4129","0.929608"],["buy","0.4113","651.391162"],["buy","0.4107","1"],["buy","0.4101","0.935955"],["buy","0.408","8"],["buy","0.4074","0.942158"],["buy","0.4067","1"],["buy","0.404","2000"],["buy","0.4029","664.961811"],["buy","0.4027","1"],["buy","0.4018","24.888003"],["buy","0.4001","624.843789"],["buy","0.40","250737.5"],["buy","0.3988","1"],["buy","0.398","100"],["buy","0.3949","1"],["buy","0.3945","679.109935"],["buy","0.391","1"],["buy","0.39","1000"],["buy","0.3872","1"],["buy","0.3861","693.873194"],["buy","0.3834","1"],["buy","0.38","4763.157894"],["buy","0.3797","1"],["buy","0.3777","709.292599"],["buy","0.376","1"],["buy","0.3723","1"],["buy","0.3693","725.412885"],["buy","0.3687","1"],["buy","0.3651","1"],["buy","0.3615","1"],["buy","0.3609","742.282952"],["buy","0.358","1"],["buy","0.3545","1"],["buy","0.3525","3120.567376"],["buy","0.351","1"],["buy","0.35","4271.428569"],["buy","0.3476","1"],["buy","0.3442","1"],["buy","0.3408","1"],["buy","0.34","275"],["buy","0.3377","10000"],["buy","0.3375","1"],["buy","0.335","298.507462"],["buy","0.3342","1"],["buy","0.3309","1"],["buy","0.3277","1"],["buy","0.3245","1"],["buy","0.3213","1"],["buy","0.32","3125"],["buy","0.3182","1"],["buy","0.3151","1"],["buy","0.312","1"],["buy","0.31","500"],["buy","0.309","1"],["buy","0.306","1"],["buy","0.303","1"],["buy","0.30","41803.366665"],["buy","0.27","1300.925925"],["buy","0.26","2000"],["buy","0.25","43100"],["buy","0.235","638.297872"],["buy","0.21","3500"],["buy","0.20","5000"],["buy","0.16","4700"],["buy","0.11","5000"],["buy","0.10","15250"],["buy","0.0902","800"],["buy","0.06","10000"],["sell","0.6165","1282.599736"],["sell","0.6178","4058.535287"],["sell","0.6181","4058.535287"],["sell","0.6196","8088.706498"],["sell","0.6199","8088.706498"],["sell","0.6202","12133.059747"],["sell","0.6219","436"],["sell","0.622","0.715043"],["sell","0.6227","1405"],["sell","0.6228","1.052118"],["sell","0.624","2624"],["sell","0.6241","14407"],["sell","0.6243","79244.54271"],["sell","0.6246","38.5"],["sell","0.6262","0.715043"],["sell","0.6264","163.8"],["sell","0.629","1.025089"],["sell","0.6305","0.715043"],["sell","0.6313","38.5"],["sell","0.6315","0.534657"],["sell","0.6348","164.515043"],["sell","0.6379","39.020625"],["sell","0.6391","0.715043"],["sell","0.6433","163.8"],["sell","0.6435","0.715043"],["sell","0.6442","0.520593"],["sell","0.6446","38.5"],["sell","0.6478","0.715043"],["sell","0.65","6040.738506"],["sell","0.6506","0.520548"],["sell","0.6513","38.5"],["sell","0.6518","163.8"],["sell","0.6522","0.715043"],["sell","0.6555","3.270745"],["sell","0.6567","0.715043"],["sell","0.657","0.513645"],["sell","0.6579","38.5"],["sell","0.6595","1200"],["sell","0.6602","524.9"],["sell","0.6612","0.715043"],["sell","0.6635","0.527473"],["sell","0.6646","123.4"],["sell","0.6657","0.715043"],["sell","0.6702","1.257332"],["sell","0.6736","163.316985"],["sell","0.6748","0.715043"],["sell","0.6768","0.534783"],["sell","0.6794","0.715043"],["sell","0.68","1200"],["sell","0.6835","0.534678"],["sell","0.684","0.715043"],["sell","0.6888","0.715043"],["sell","0.69","500"],["sell","0.6903","0.534863"],["sell","0.6934","0.715043"],["sell","0.6971","0.542133"],["sell","0.6981","0.715043"],["sell","0.70","107.142858"],["sell","0.7025","3.270745"],["sell","0.7029","0.715043"],["sell","0.7041","0.549912"],["sell","0.7077","0.715043"],["sell","0.7079","1"],["sell","0.7097","2"],["sell","0.71","3508.771929"],["sell","0.711","0.542154"],["sell","0.7126","0.715043"],["sell","0.7174","0.715043"],["sell","0.7181","0.534894"],["sell","0.72","100"],["sell","0.7205","1200"],["sell","0.7223","0.715043"],["sell","0.7252","0.520495"],["sell","0.7272","0.715043"],["sell","0.7276","17.5"],["sell","0.7321","0.715043"],["sell","0.7324","0.513701"],["sell","0.7372","0.715043"],["sell","0.7396","0.513608"],["sell","0.7421","0.715043"],["sell","0.7447","3.270745"],["sell","0.747","0.536852"],["sell","0.7473","0.715043"],["sell","0.7523","0.715043"],["sell","0.7544","0.533994"],["sell","0.7575","0.715043"],["sell","0.7618","0.531452"],["sell","0.7626","0.715043"],["sell","0.765","372.789115"],["sell","0.7678","0.715043"],["sell","0.7694","0.535834"],["sell","0.7731","0.715043"],["sell","0.7769","7.8125"],["sell","0.7771","0.53476"],["sell","0.7783","0.715043"],["sell","0.7837","0.715043"],["sell","0.7848","0.534802"],["sell","0.7868","11.590843"],["sell","0.7889","0.715043"],["sell","0.7926","0.577039"],["sell","0.7944","0.715043"],["sell","0.795","138.367036"],["sell","0.7983","137.794482"],["sell","0.7985","1200"],["sell","0.7997","0.715043"],["sell","0.80","1162.288477"],["sell","0.8005","0.599512"],["sell","0.8011","40.335887"],["sell","0.8085","0.642904"],["sell","0.8165","0.638955"],["sell","0.82","3646.16946"],["sell","0.8236","39.230864"],["sell","0.8243","0.1"],["sell","0.8246","0.627362"],["sell","0.83","1000"],["sell","0.8328","0.608535"],["sell","0.8411","0.590613"],["sell","0.8422","1200"],["sell","0.845","307"],["sell","0.8468","38.156895"],["sell","0.8494","0.581952"],["sell","0.85","505"],["sell","0.851","1200"],["sell","0.8578","0.565345"],["sell","0.86","1150"],["sell","0.8664","0.527633"],["sell","0.87","1"],["sell","0.8707","37.109398"],["sell","0.875","0.534788"],["sell","0.88","842.956227"],["sell","0.8837","0.520475"],["sell","0.8925","0.527624"],["sell","0.8954","36.088783"],["sell","0.90","5555.555556"],["sell","0.9013","0.52051"],["sell","0.9103","0.513713"],["sell","0.9193","0.513651"],["sell","0.92","229.811426"],["sell","0.9206","35.099219"],["sell","0.9285","0.513701"],["sell","0.9377","0.513628"],["sell","0.9385","13.106021"],["sell","0.9466","34.136445"],["sell","0.9471","0.506969"],["sell","0.95","3"],["sell","0.9565","0.506995"],["sell","0.96","506"],["sell","0.9659","0.500412"],["sell","0.97","298.507462"],["sell","0.9732","33.200458"],["sell","0.9754","17.428748"],["sell","0.9755","0.494057"],["sell","0.98","6000"],["sell","0.9852","0.487845"],["sell","0.989","10111.223458"],["sell","0.99","99.0099"],["sell","0.995","0.487845"],["sell","0.9999","19.030993"],["sell","1.00","146.051811"],["sell","1.0007","40.134569"],["sell","1.0035","109.623614"],["sell","1.0049","0.487845"],["sell","1.0149","0.487845"],["sell","1.02","230"],["sell","1.025","0.487845"],["sell","1.0289","40.134569"],["sell","1.03","2000"],["sell","1.0352","0.487845"],["sell","1.0455","0.487845"],["sell","1.0559","0.487845"],["sell","1.0579","40.134569"],["sell","1.0664","0.487845"],["sell","1.07","1000"],["sell","1.0771","0.494063"],["sell","1.0877","40.134569"],["sell","1.0878","0.494055"],["sell","1.096","110.53809"],["sell","1.0986","0.487845"],["sell","1.10","500"],["sell","1.1096","0.487845"],["sell","1.115","37.7"],["sell","1.1157","6.292383"],["sell","1.12","4000"],["sell","1.1206","0.487845"],["sell","1.1295","6.215536"],["sell","1.1318","0.487845"],["sell","1.14","1000"],["sell","1.1431","0.487845"],["sell","1.1436","6.13891"],["sell","1.1443","23.150017"],["sell","1.15","3159.592564"],["sell","1.1544","0.487845"],["sell","1.1579","6.063088"],["sell","1.1599","15"],["sell","1.1659","0.487845"],["sell","1.17","235"],["sell","1.1723","5.770422"],["sell","1.1775","0.487845"],["sell","1.1869","5.914904"],["sell","1.1892","0.487845"],["sell","1.20","25"],["sell","1.201","0.487845"],["sell","1.2016","5.84251"],["sell","1.21","8.32486"],["sell","1.213","0.487845"],["sell","1.2166","5.770422"],["sell","1.2251","0.487845"],["sell","1.2317","5.699622"],["sell","1.2373","0.506972"],["sell","1.247","5.629623"],["sell","1.2496","0.513659"],["sell","1.25","795.21907"],["sell","1.262","0.500423"],["sell","1.2627","5.559982"],["sell","1.2745","0.494051"],["sell","1.2784","5.491607"],["sell","1.28","12.5"],["sell","1.2873","0.494064"],["sell","1.2943","5.424043"],["sell","1.3001","0.494055"],["sell","1.3103","1.444422"],["sell","1.313","0.494046"],["sell","1.32","10"],["sell","1.3261","0.494056"],["sell","1.3267","5.291759"],["sell","1.3393","0.509282"],["sell","1.34","37.7"],["sell","1.3432","5.226626"],["sell","1.35","30"],["sell","1.3526","0.506593"],["sell","1.3599","5.162307"],["sell","1.3645","15"],["sell","1.3661","0.503953"],["sell","1.37","144.529556"],["sell","1.3769","5.0988"],["sell","1.3797","0.501191"],["sell","1.3935","0.506972"],["sell","1.394","5.036104"],["sell","1.40","2134.523809"],["sell","1.4073","0.527465"],["sell","1.41","3390"],["sell","1.4113","4.974216"],["sell","1.4213","0.520447"],["sell","1.429","4.912784"],["sell","1.4356","0.527573"],["sell","1.4467","4.852511"],["sell","1.4499","0.53477"],["sell","1.4643","0.534742"],["sell","1.4648","4.792703"],["sell","1.4789","0.542085"],["sell","1.48","10"],["sell","1.483","4.734027"],["sell","1.4937","0.527573"],["sell","1.50","28331.170049"],["sell","1.5014","4.675823"],["sell","1.5085","0.527526"],["sell","1.5124","500"],["sell","1.52","1118.961713"],["sell","1.5202","4.618108"],["sell","1.5235","0.520448"],["sell","1.5285","16.859224"],["sell","1.5387","0.513632"],["sell","1.539","4.561501"],["sell","1.54","800"],["sell","1.5541","0.513655"],["sell","1.5582","4.998643"],["sell","1.5695","0.527475"],["sell","1.57","333.333333"],["sell","1.5777","4.998643"],["sell","1.5852","0.506932"],["sell","1.5973","4.998643"],["sell","1.60","363.75"],["sell","1.601","0.506938"],["sell","1.617","0.513625"],["sell","1.6171","4.998643"],["sell","1.63","93.926"],["sell","1.6331","0.534708"],["sell","1.6373","4.998643"],["sell","1.6494","0.520465"],["sell","1.65","407.276958"],["sell","1.6577","4.998643"],["sell","1.6658","0.513601"],["sell","1.67","3129"],["sell","1.6784","4.998643"],["sell","1.68","3390.002699"],["sell","1.6825","0.500425"],["sell","1.69","3000"],["sell","1.6992","0.500414"],["sell","1.6993","4.998643"],["sell","1.70","3463.738682"],["sell","1.71","2005.01"],["sell","1.7162","0.500431"],["sell","1.7204","4.998643"],["sell","1.725","20"],["sell","1.73","328.260372"],["sell","1.7333","0.487845"],["sell","1.7361","200"],["sell","1.7418","4.998643"],["sell","1.75","28.080441"],["sell","1.7506","0.487845"],["sell","1.7635","4.998643"],["sell","1.768","0.487845"],["sell","1.77","600"],["sell","1.78","64.045685"],["sell","1.7851","20"],["sell","1.7855","4.998643"],["sell","1.7856","0.487845"],["sell","1.79","37.7"],["sell","1.80","685.454843"],["sell","1.8034","0.487845"],["sell","1.8077","4.998643"],["sell","1.8214","0.487845"],["sell","1.8288","129.329292"],["sell","1.8303","4.998643"],["sell","1.8396","0.487845"],["sell","1.85","775.372859"],["sell","1.8531","4.998643"],["sell","1.8579","0.487845"],["sell","1.8682","143.394302"],["sell","1.8744","18.072289"],["sell","1.8761","4.998643"],["sell","1.8764","0.487845"],["sell","1.8888","10.480126"],["sell","1.8952","0.487845"],["sell","1.8994","4.998643"],["sell","1.90","115.789474"],["sell","1.9141","0.487845"],["sell","1.9332","0.487845"],["sell","1.95","792.435898"],["sell","1.9524","0.487845"],["sell","1.9719","0.487845"],["sell","1.9732","55"],["sell","1.98","1571.282051"],["sell","1.9916","0.487845"],["sell","2.00","31980.452453"],["sell","2.0115","0.487845"],["sell","2.0184","327.340998"],["sell","2.03","15"],["sell","2.0316","0.487845"],["sell","2.039","590.628302"],["sell","2.05","693.290773"],["sell","2.0519","0.487845"],["sell","2.0723","0.487845"],["sell","2.0733","47.798101"],["sell","2.08","60"],["sell","2.09","15"],["sell","2.0929","0.487845"],["sell","2.10","1303"],["sell","2.1138","0.487845"],["sell","2.12","170"],["sell","2.13","50"],["sell","2.1348","0.487845"],["sell","2.1561","0.487845"],["sell","2.1776","0.487845"],["sell","2.18","58"],["sell","2.1831","75.913889"],["sell","2.1992","0.487845"],["sell","2.20","19.363637"],["sell","2.2211","0.487845"],["sell","2.23","50"],["sell","2.24","3200"],["sell","2.2433","0.487845"],["sell","2.25","3968.304804"],["sell","2.2658","0.487845"],["sell","2.27","1"],["sell","2.28","50"],["sell","2.2884","0.487845"],["sell","2.3112","0.487845"],["sell","2.32","450"],["sell","2.3343","0.487845"],["sell","2.35","12.465872"],["sell","2.3575","0.487845"],["sell","2.37","20"],["sell","2.381","0.487845"],["sell","2.3911","32"],["sell","2.40","42.049351"],["sell","2.4048","0.487845"],["sell","2.4288","0.487845"],["sell","2.43","1.451802"],["sell","2.45","6"],["sell","2.453","0.487845"],["sell","2.46","15"],["sell","2.4775","0.487845"],["sell","2.49","92.24852"],["sell","2.50","632.508761"],["sell","2.5023","0.487845"],["sell","2.51","7.664247"],["sell","2.5272","0.487845"],["sell","2.53","235.161359"],["sell","2.55","24.607844"],["sell","2.5525","0.487845"],["sell","2.56","3.757926"],["sell","2.5779","0.487845"],["sell","2.6036","0.487845"],["sell","2.6211","30"],["sell","2.6296","0.487845"],["sell","2.6558","0.487845"],["sell","2.66","1.582326"],["sell","2.6758","947.35932"],["sell","2.68","1080"],["sell","2.6823","0.487845"],["sell","2.69","37.7"],["sell","2.7091","0.487845"],["sell","2.71","1.532706"],["sell","2.7361","0.487845"],["sell","2.77","20"],["sell","2.79","17.921147"],["sell","2.80","70"],["sell","2.85","65"],["sell","2.8811","1388.32"],["sell","2.95","1935"],["sell","2.98","40.877201"],["sell","3.00","1011"],["sell","3.08","4"],["sell","3.09","150"],["sell","3.15","40"],["sell","3.16","20"],["sell","3.28","304.878049"],["sell","3.40","11.725"],["sell","3.4801","947.35932"],["sell","3.50","80"],["sell","3.60","13.888889"],["sell","3.70","1004.215811"],["sell","3.75","160"],["sell","3.90","6"],["sell","4.00","430.312622"],["sell","4.15","60"],["sell","4.20","3.009762"],["sell","4.25","60"],["sell","4.41","2.979555"],["sell","4.49","37.7"],["sell","4.50","65"],["sell","4.75","125"],["sell","4.8106","947.35932"],["sell","4.90","125"],["sell","5.00","290"],["sell","5.05","125"],["sell","5.15","125"],["sell","5.27","300"],["sell","5.35","125"],["sell","5.45","75"],["sell","5.55","75"],["sell","5.75","75"],["sell","5.95","62"],["sell","6.06","100.5498"],["sell","6.66","10"],["sell","6.75","5"],["sell","6.76","32"],["sell","7.00","10"],["sell","7.36","516.304347"],["sell","9.00","5"],["sell","10.00","210"],["sell","10.20","1"],["sell","13.00","100"],["sell","14.87","33"],["sell","24.00","50.000449"],["sell","25.00","168.581035"],["sell","50.00","100"],["sell","75.00","100"],["sell","100.00","100"],["sell","133.00","2"],["sell","150.00","100"],["sell","236.00","1"],["sell","250.00","100"],["sell","687.00","1"],["sell","2345.00","1"],["sell","2359.9999","1"]],"trades":[{"type":"trade","symbol":"GRTUSD","event_id":45465693288,"timestamp":1624493594616,"price":"0.6183","quantity":"1.017123","side":"sell"},{"type":"trade","symbol":"GRTUSD","event_id":45465684220,"timestamp":1624493588234,"price":"0.62","quantity":"1415.394642","side":"sell"},{"type":"trade","symbol":"GRTUSD","event_id":45465667602,"timestamp":1624493578122,"price":"0.62","quantity":"964.066763","side":"buy"},{"type":"trade","symbol":"GRTUSD","event_id":45465659055,"timestamp":1624493573232,"price":"0.62","quantity":"235.933237","side":"buy"},{"type":"trade","symbol":"GRTUSD","event_id":45465544763,"timestamp":1624493500079,"price":"0.6194","quantity":"1000","side":"buy"},{"type":"trade","symbol":"GRTUSD","event_id":45465520812,"timestamp":1624493484482,"price":"0.6179","quantity":"38.5","side":"buy"},{"type":"trade","symbol":"GRTUSD","event_id":45465520810,"timestamp":1624493484482,"price":"0.6179","quantity":"163.8","side":"buy"},{"type":"trade","symbol":"GRTUSD","event_id":45465520243,"timestamp":1624493484345,"price":"0.6177","quantity":"0.715043","side":"buy"},{"type":"trade","symbol":"GRTUSD","event_id":45465484107,"timestamp":1624493464102,"price":"0.617","quantity":"0.1","side":"buy"},{"type":"trade","symbol":"GRTUSD","event_id":45465472297,"timestamp":1624493458343,"price":"0.6167","quantity":"1.012135","side":"buy"},{"type":"trade","symbol":"GRTUSD","event_id":45465434910,"timestamp":1624493436232,"price":"0.6136","quantity":"0.715043","side":"buy"},{"type":"trade","symbol":"GRTUSD","event_id":45465420998,"timestamp":1624493429271,"price":"0.6116","quantity":"1200","side":"buy"},{"type":"trade","symbol":"GRTUSD","event_id":45465416957,"timestamp":1624493427181,"price":"0.6113","quantity":"38.5","side":"buy"},{"type":"trade","symbol":"GRTUSD","event_id":45465407719,"timestamp":1624493421805,"price":"0.6106","quantity":"0.999456","side":"buy"},{"type":"trade","symbol":"GRTUSD","event_id":45465332057,"timestamp":1624493383741,"price":"0.6095","quantity":"163.8","side":"buy"},{"type":"trade","symbol":"GRTUSD","event_id":45465331910,"timestamp":1624493383624,"price":"0.6094","quantity":"0.715043","side":"buy"},{"type":"trade","symbol":"GRTUSD","event_id":45465331780,"timestamp":1624493383439,"price":"0.6093","quantity":"5991.178824","side":"buy"},{"type":"trade","symbol":"GRTUSD","event_id":45465316716,"timestamp":1624493374035,"price":"0.6092","quantity":"15.218723","side":"sell"},{"type":"trade","symbol":"GRTUSD","event_id":45465308925,"timestamp":1624493367803,"price":"0.6093","quantity":"89.82691","side":"buy"},{"type":"trade","symbol":"GRTUSD","event_id":45465293232,"timestamp":1624493359865,"price":"0.6074","quantity":"1069.234751","side":"buy"},{"type":"trade","symbol":"GRTUSD","event_id":45465052024,"timestamp":1624493252836,"price":"0.6038","quantity":"2390.10383","side":"buy"},{"type":"trade","symbol":"GRTUSD","event_id":45464966646,"timestamp":1624493207461,"price":"0.6038","quantity":"115.28075","side":"buy"},{"type":"trade","symbol":"GRTUSD","event_id":45464781093,"timestamp":1624493127445,"price":"0.6047","quantity":"39.669853","side":"buy"},{"type":"trade","symbol":"GRTUSD","event_id":45464758104,"timestamp":1624493116422,"price":"0.6015","quantity":"1494.160693","side":"buy"},{"type":"trade","symbol":"GRTUSD","event_id":45464261589,"timestamp":1624492900844,"price":"0.609","quantity":"204.377552","side":"buy"},{"type":"trade","symbol":"GRTUSD","event_id":45464261587,"timestamp":1624492900844,"price":"0.609","quantity":"1405","side":"buy"},{"type":"trade","symbol":"GRTUSD","event_id":45463926665,"timestamp":1624492747563,"price":"0.603","quantity":"907.890392","side":"buy"},{"type":"trade","symbol":"GRTUSD","event_id":45463800399,"timestamp":1624492617756,"price":"0.6058","quantity":"1482.213438","side":"buy"},{"type":"trade","symbol":"GRTUSD","event_id":45463652949,"timestamp":1624492491374,"price":"0.6072","quantity":"20.107896","side":"buy"},{"type":"trade","symbol":"GRTUSD","event_id":45463624303,"timestamp":1624492471469,"price":"0.6055","quantity":"1492.153039","side":"buy"},{"type":"trade","symbol":"GRTUSD","event_id":45463462291,"timestamp":1624492316342,"price":"0.6082","quantity":"93.275523","side":"buy"},{"type":"trade","symbol":"GRTUSD","event_id":45463368739,"timestamp":1624492253999,"price":"0.6093","quantity":"168.994266","side":"buy"},{"type":"trade","symbol":"GRTUSD","event_id":45463335179,"timestamp":1624492243879,"price":"0.606","quantity":"2000","side":"buy"},{"type":"trade","symbol":"GRTUSD","event_id":45463328175,"timestamp":1624492242348,"price":"0.6053","quantity":"0.639618","side":"buy"},{"type":"trade","symbol":"GRTUSD","event_id":45463302793,"timestamp":1624492227392,"price":"0.605","quantity":"323.923051","side":"buy"},{"type":"trade","symbol":"GRTUSD","event_id":45463240239,"timestamp":1624492172064,"price":"0.6046","quantity":"1.012146","side":"buy"},{"type":"trade","symbol":"GRTUSD","event_id":45463194178,"timestamp":1624492146691,"price":"0.604","quantity":"1648.9","side":"buy"},{"type":"trade","symbol":"GRTUSD","event_id":45463176586,"timestamp":1624492133754,"price":"0.604","quantity":"0.1","side":"buy"},{"type":"trade","symbol":"GRTUSD","event_id":45463030637,"timestamp":1624492020920,"price":"0.6019","quantity":"30.509312","side":"buy"},{"type":"trade","symbol":"GRTUSD","event_id":45462795403,"timestamp":1624491826815,"price":"0.6001","quantity":"0.106148","side":"buy"},{"type":"trade","symbol":"GRTUSD","event_id":45462781559,"timestamp":1624491813778,"price":"0.6017","quantity":"1983.05599919","side":"buy"},{"type":"trade","symbol":"GRTUSD","event_id":45462781557,"timestamp":1624491813778,"price":"0.6007","quantity":"1228.244823","side":"buy"},{"type":"trade","symbol":"GRTUSD","event_id":45462641000,"timestamp":1624491717538,"price":"0.6011","quantity":"1126.625208","side":"sell"},{"type":"trade","symbol":"GRTUSD","event_id":45462472016,"timestamp":1624491613663,"price":"0.6006","quantity":"160.692396","side":"buy"},{"type":"trade","symbol":"GRTUSD","event_id":45462459622,"timestamp":1624491606934,"price":"0.6021","quantity":"1275.893497","side":"sell"},{"type":"trade","symbol":"GRTUSD","event_id":45462412287,"timestamp":1624491575056,"price":"0.6038","quantity":"127.100181","side":"buy"},{"type":"trade","symbol":"GRTUSD","event_id":45462409598,"timestamp":1624491573798,"price":"0.6014","quantity":"1374.943899","side":"buy"},{"type":"trade","symbol":"GRTUSD","event_id":45462409381,"timestamp":1624491573659,"price":"0.6012","quantity":"0.644018","side":"buy"},{"type":"trade","symbol":"GRTUSD","event_id":45462358941,"timestamp":1624491537771,"price":"0.5987","quantity":"1.012132","side":"buy"},{"type":"trade","symbol":"GRTUSD","event_id":45462353387,"timestamp":1624491536031,"price":"0.5977","quantity":"1386.874662","side":"buy"}],"auction_events":[]}
1624493666.711471: {"type":"l2_updates","symbol":"LTCETH","changes":[["buy","0.0655","7.77054"],["buy","0.0654","15.54107"],["buy","0.0653","181.85422"],["buy","0.0652","38.85266"],["buy","0.0649","360.05034"],["buy","0.0647","99.26402"],["buy","0.0641","356.63147"],["buy","0.0639","112.01936"],["buy","0.0638","224.76415"],["buy","0.0637","109.96627"],["buy","0.0538","3"],["buy","0.0522","3"],["buy","0.0505","3"],["buy","0.0489","3"],["buy","0.0456","3"],["buy","0.0424","3"],["buy","0.0391","3"],["buy","0.0359","3"],["buy","0.0326","3"],["buy","0.0293","3"],["buy","0.0261","3"],["buy","0.0228","3"],["buy","0.0196","3"],["buy","0.0163","3"],["buy","0.013","3"],["buy","0.0111","10"],["buy","0.0098","3"],["buy","0.0065","3"],["buy","0.0033","3"],["buy","0.0001","2899"],["sell","0.0658","7.74742"],["sell","0.0659","15.49484"],["sell","0.066","106.83627"],["sell","0.0661","145.15788"],["sell","0.0663","82.96018"],["sell","0.0665","36.62699"],["sell","0.0667","277.79867"],["sell","0.067","43.86367"],["sell","0.07","0.5"],["sell","0.072","0.576"],["sell","0.0738","0.70599"],["sell","0.08","9.0909"],["sell","0.0801","4"],["sell","0.0876","0.5"],["sell","0.0898","1"],["sell","0.0935","0.34277"],["sell","0.0942","0.3402"],["sell","0.0949","0.33767"],["sell","0.095","5"],["sell","0.0955","0.33553"],["sell","0.0962","0.33307"],["sell","0.0969","0.33065"],["sell","0.0976","0.32826"],["sell","0.0983","0.3259"],["sell","0.0991","1.32358"],["sell","0.0998","0.32129"],["sell","0.1","11.5"],["sell","0.1005","0.31903"],["sell","0.1012","0.3168"],["sell","0.1019","0.3146"],["sell","0.102","0.01"],["sell","0.1026","0.31244"],["sell","0.1034","0.31"],["sell","0.1041","0.3079"],["sell","0.1048","0.30582"],["sell","0.1063","0.30147"],["sell","0.107","1"],["sell","0.1071","0.2992"],["sell","0.1078","0.29724"],["sell","0.1086","0.29503"],["sell","0.1094","0.29286"],["sell","0.11","0.02"],["sell","0.1102","0.29098"],["sell","0.111","0.28886"],["sell","0.1118","0.28678"],["sell","0.1123","13.84005"],["sell","0.1126","0.28472"],["sell","0.1134","0.2827"],["sell","0.1142","0.2807"],["sell","0.115","0.27873"],["sell","0.1158","0.27679"],["sell","0.1167","0.27463"],["sell","0.1175","0.27275"],["sell","0.1183","0.27089"],["sell","0.1192","0.26882"],["sell","0.12","21.26702"],["sell","0.1204","0.02"],["sell","0.1209","0.26501"],["sell","0.1218","0.26326"],["sell","0.1227","0.26131"],["sell","0.1233","0.01"],["sell","0.1235","0.2796"],["sell","0.1244","0.2577"],["sell","0.1253","0.25584"],["sell","0.1262","0.254"],["sell","0.1271","0.25218"],["sell","0.128","0.25039"],["sell","0.1289","0.24863"],["sell","0.129","1.02"],["sell","0.1298","0.24689"],["sell","0.1307","0.24518"],["sell","0.1317","0.2433"],["sell","0.1326","0.24182"],["sell","0.1333","0.01"],["sell","0.1334","0.24035"],["sell","0.135","0.23748"],["sell","0.1358","0.23607"],["sell","0.1366","0.23467"],["sell","0.1379","0.02"],["sell","0.1382","0.01"],["sell","0.14","1"],["sell","0.1425","0.03"],["sell","0.1427","0.01"],["sell","0.1475","0.01"],["sell","0.1476","0.01"],["sell","0.1483","0.01"],["sell","0.15","0.01"],["sell","0.1504","0.01"],["sell","0.1555","0.1"],["sell","0.1559","0.01"],["sell","0.1572","0.01"],["sell","0.1586","0.01"],["sell","0.1608","0.01"],["sell","0.1619","0.01"],["sell","0.164","0.01"],["sell","0.1656","32"],["sell","0.1673","3.4"],["sell","0.1697","0.02"],["sell","0.1713","0.02"],["sell","0.1762","0.01"],["sell","0.1777","0.1"],["sell","0.18","1"],["sell","0.1804","0.01"],["sell","0.1967","0.02"],["sell","0.1979","26"],["sell","0.1999","0.1"],["sell","0.2039","2.52747"],["sell","0.2111","0.1"],["sell","0.2333","0.05231"],["sell","0.2444","0.05"],["sell","0.2555","0.05"],["sell","0.2666","0.05"],["sell","0.2777","0.05"],["sell","0.2888","0.05"],["sell","0.2999","0.07"],["sell","0.3111","0.05"],["sell","0.3222","0.05"],["sell","0.3223","2.61467"],["sell","0.3272","3"],["sell","0.3333","0.05"],["sell","0.3999","0.02"],["sell","0.444","403.1"],["sell","0.4999","0.02"],["sell","0.5555","0.07565"],["sell","0.5999","0.01"],["sell","0.6","0.1"],["sell","0.6666","0.07"],["sell","0.6999","0.01"],["sell","0.7","0.1"],["sell","0.777","0.02"],["sell","0.7777","0.05"],["sell","0.7999","0.01"],["sell","0.8888","0.07"],["sell","0.8999","0.01"],["sell","0.9999","0.08"],["sell","1.1111","0.07"],["sell","1.2222","0.07"],["sell","1.3333","0.07"],["sell","1.337","0.1"],["sell","1.4444","0.07"],["sell","1.5555","0.07"],["sell","1.6666","0.05"],["sell","1.777","0.05"],["sell","1.8888","0.05"],["sell","1.9999","0.06"],["sell","2","1.1"],["sell","2.1111","0.05"],["sell","2.22","0.01"],["sell","2.2222","0.05"],["sell","2.9999","0.01"],["sell","3.33","0.06"],["sell","4.444","0.06"],["sell","5.5555","0.01"],["sell","6.777","0.01"],["sell","7.77","0.06"],["sell","8.777","0.01"],["sell","9.777","0.05"],["sell","10.777","0.01"],["sell","11.777","0.01"],["sell","9990","0.099"],["sell","99900","0.099"]],"trades":[{"type":"trade","symbol":"LTCETH","event_id":45455929968,"timestamp":1624486208562,"price":"0.0652","quantity":"0.16952","side":"buy"},{"type":"trade","symbol":"LTCETH","event_id":45448417925,"timestamp":1624480671189,"price":"0.065","quantity":"3.81335","side":"sell"},{"type":"trade","symbol":"LTCETH","event_id":45444880329,"timestamp":1624478776666,"price":"0.0651","quantity":"0.61444","side":"sell"},{"type":"trade","symbol":"LTCETH","event_id":45442645777,"timestamp":1624477611921,"price":"0.0641","quantity":"0.02707","side":"sell"},{"type":"trade","symbol":"LTCETH","event_id":45439232736,"timestamp":1624475423572,"price":"0.0644","quantity":"0.6","side":"sell"},{"type":"trade","symbol":"LTCETH","event_id":45435664719,"timestamp":1624473237492,"price":"0.0646","quantity":"0.56307","side":"buy"},{"type":"trade","symbol":"LTCETH","event_id":45434361550,"timestamp":1624472388414,"price":"0.0643","quantity":"0.25661","side":"sell"},{"type":"trade","symbol":"LTCETH","event_id":45432472013,"timestamp":1624471402672,"price":"0.0643","quantity":"0.8548","side":"sell"},{"type":"trade","symbol":"LTCETH","event_id":45428989040,"timestamp":1624469055870,"price":"0.0643","quantity":"0.85488","side":"sell"},{"type":"trade","symbol":"LTCETH","event_id":45417302938,"timestamp":1624462747249,"price":"0.0647","quantity":"0.17404","side":"sell"},{"type":"trade","symbol":"LTCETH","event_id":45414853313,"timestamp":1624461490394,"price":"0.065","quantity":"0.01003","side":"buy"},{"type":"trade","symbol":"LTCETH","event_id":45292324264,"timestamp":1624396172468,"price":"0.0634","quantity":"41.12057","side":"buy"},{"type":"trade","symbol":"LTCETH","event_id":45292324389,"timestamp":1624396172590,"price":"0.0634","quantity":"41.12057","side":"buy"},{"type":"trade","symbol":"LTCETH","event_id":45292324395,"timestamp":1624396172596,"price":"0.0634","quantity":"8.22438","side":"buy"},{"type":"trade","symbol":"LTCETH","event_id":45292324501,"timestamp":1624396172713,"price":"0.0634","quantity":"41.11916","side":"buy"},{"type":"trade","symbol":"LTCETH","event_id":45292324537,"timestamp":1624396172815,"price":"0.0634","quantity":"41.11916","side":"buy"},{"type":"trade","symbol":"LTCETH","event_id":45292324622,"timestamp":1624396172916,"price":"0.0634","quantity":"8.22438","side":"buy"},{"type":"trade","symbol":"LTCETH","event_id":45292324631,"timestamp":1624396172921,"price":"0.0634","quantity":"41.11916","side":"buy"},{"type":"trade","symbol":"LTCETH","event_id":45292324687,"timestamp":1624396173021,"price":"0.0634","quantity":"41.11651","side":"buy"},{"type":"trade","symbol":"LTCETH","event_id":45292324815,"timestamp":1624396173165,"price":"0.0634","quantity":"41.11705","side":"buy"},{"type":"trade","symbol":"LTCETH","event_id":45292324987,"timestamp":1624396173280,"price":"0.0634","quantity":"41.11705","side":"buy"},{"type":"trade","symbol":"LTCETH","event_id":45292325172,"timestamp":1624396173415,"price":"0.0634","quantity":"41.11705","side":"buy"},{"type":"trade","symbol":"LTCETH","event_id":45292325303,"timestamp":1624396173525,"price":"0.0634","quantity":"41.11705","side":"buy"},{"type":"trade","symbol":"LTCETH","event_id":45292325535,"timestamp":1624396173621,"price":"0.0634","quantity":"41.11568","side":"buy"},{"type":"trade","symbol":"LTCETH","event_id":45292326409,"timestamp":1624396173749,"price":"0.0634","quantity":"41.10277","side":"buy"},{"type":"trade","symbol":"LTCETH","event_id":45292327073,"timestamp":1624396173859,"price":"0.0634","quantity":"41.0924","side":"buy"},{"type":"trade","symbol":"LTCETH","event_id":45292327600,"timestamp":1624396174011,"price":"0.0634","quantity":"8.22342","side":"buy"},{"type":"trade","symbol":"LTCETH","event_id":45292328130,"timestamp":1624396174047,"price":"0.0634","quantity":"41.08756","side":"buy"},{"type":"trade","symbol":"LTCETH","event_id":45292329157,"timestamp":1624396174216,"price":"0.0634","quantity":"41.0822","side":"buy"},{"type":"trade","symbol":"LTCETH","event_id":45292329677,"timestamp":1624396174333,"price":"0.0634","quantity":"41.0809","side":"buy"},{"type":"trade","symbol":"LTCETH","event_id":45292330002,"timestamp":1624396174392,"price":"0.0634","quantity":"8.21619","side":"buy"},{"type":"trade","symbol":"LTCETH","event_id":45292330154,"timestamp":1624396174439,"price":"0.0634","quantity":"41.0809","side":"buy"},{"type":"trade","symbol":"LTCETH","event_id":45292330640,"timestamp":1624396174567,"price":"0.0634","quantity":"41.07836","side":"buy"},{"type":"trade","symbol":"LTCETH","event_id":45292331017,"timestamp":1624396174676,"price":"0.0634","quantity":"41.07706","side":"buy"},{"type":"trade","symbol":"LTCETH","event_id":45292331082,"timestamp":1624396174701,"price":"0.0634","quantity":"8.21619","side":"buy"},{"type":"trade","symbol":"LTCETH","event_id":45292331221,"timestamp":1624396174814,"price":"0.0634","quantity":"41.07706","side":"buy"},{"type":"trade","symbol":"LTCETH","event_id":45292331354,"timestamp":1624396174915,"price":"0.0634","quantity":"41.07706","side":"buy"},{"type":"trade","symbol":"LTCETH","event_id":45292331499,"timestamp":1624396174992,"price":"0.0634","quantity":"8.21619","side":"buy"},{"type":"trade","symbol":"LTCETH","event_id":45292331648,"timestamp":1624396175026,"price":"0.0634","quantity":"41.07862","side":"buy"},{"type":"trade","symbol":"LTCETH","event_id":45292331936,"timestamp":1624396175150,"price":"0.0634","quantity":"41.07849","side":"buy"},{"type":"trade","symbol":"LTCETH","event_id":45292332095,"timestamp":1624396175251,"price":"0.0634","quantity":"41.07708","side":"buy"},{"type":"trade","symbol":"LTCETH","event_id":45292332139,"timestamp":1624396175295,"price":"0.0634","quantity":"8.21619","side":"buy"},{"type":"trade","symbol":"LTCETH","event_id":45292332211,"timestamp":1624396175384,"price":"0.0634","quantity":"41.07708","side":"buy"},{"type":"trade","symbol":"LTCETH","event_id":45292332361,"timestamp":1624396175518,"price":"0.0634","quantity":"41.07708","side":"buy"},{"type":"trade","symbol":"LTCETH","event_id":45292332531,"timestamp":1624396175612,"price":"0.0634","quantity":"18.47381","side":"buy"},{"type":"trade","symbol":"LTCETH","event_id":45296413410,"timestamp":1624399371746,"price":"0.0639","quantity":"0.4","side":"buy"},{"type":"trade","symbol":"LTCETH","event_id":45298556949,"timestamp":1624400753874,"price":"0.0639","quantity":"0.50642","side":"sell"},{"type":"trade","symbol":"LTCETH","event_id":45307018377,"timestamp":1624405098049,"price":"0.0634","quantity":"0.74772","side":"sell"},{"type":"trade","symbol":"LTCETH","event_id":45316741965,"timestamp":1624408798870,"price":"0.0637","quantity":"0.05","side":"sell"},{"type":"trade","symbol":"LTCETH","event_id":45320859514,"timestamp":1624409963475,"price":"0.0638","quantity":"8.11777","side":"sell"}],"auction_events":[]}
1624493666.7124102: {"type":"l2_updates","symbol":"ETHEUR","changes":[["buy","1648.98","2.537003"],["buy","1648.97","2.537003"],["buy","1648.96","5.074006"],["buy","1648.95","10.148011"],["buy","1644.63","11.908281"],["buy","1640.09","14.959801"],["buy","1629.39","9.953317"],["buy","1623.28","4.038966"],["buy","1600.37","1.301"],["buy","1525.00","15"],["buy","1500.00","0.083099"],["buy","1490.00","0.133624"],["buy","1471.00","0.006023"],["buy","1450.00","0.017241"],["buy","1440.00","0.2"],["buy","1400.00","0.382614"],["buy","1375.00","0.58"],["buy","1300.00","0.076923"],["buy","1233.00","0.157"],["buy","1207.60","0.064"],["buy","1200.00","0.416666"],["buy","1111.00","0.737623"],["buy","1025.00","0.024292"],["buy","1015.00","2.463054"],["buy","1000.00","104"],["buy","970.00","2.577319"],["buy","950.70","1.051856"],["buy","950.00","3.4"],["buy","800.00","0.491"],["buy","2.59","0.6"],["buy","0.01","1249"],["sell","1656.75","1.263"],["sell","1656.77","2.531554"],["sell","1657.29","2.531146"],["sell","1657.46","5.062292"],["sell","1657.79","10.124583"],["sell","1660.74","13.910639"],["sell","1672.53","16.660662"],["sell","1823.47","0.25"],["sell","1950.00","10"],["sell","2005.82","0.25745"],["sell","2011.92","0.009931"],["sell","2086.00","0.047891"],["sell","2167.17","0.001305"],["sell","2203.00","0.384972"],["sell","2295.00","0.078679"],["sell","2300.00","0.312573"],["sell","2389.00","4.545537"],["sell","2414.00","0.009634"],["sell","2430.00","0.020577"],["sell","2450.00","227.526772"],["sell","2650.00","0.04"],["sell","2970.00","0.03"],["sell","2971.63","0.510202"],["sell","3500.00","0.140572"],["sell","3571.63","1.053323"],["sell","3607.00","0.936097"],["sell","3624.00","1"],["sell","3625.00","1"],["sell","3626.00","1"],["sell","3627.00","1"],["sell","3628.00","1"],["sell","3629.00","1"],["sell","3630.00","1"],["sell","3631.00","1"],["sell","3632.00","1"],["sell","3633.00","1"],["sell","3634.00","1"],["sell","3635.00","1"],["sell","3636.00","1"],["sell","3637.00","1"],["sell","3638.00","1"],["sell","3639.00","1"],["sell","3640.00","1"],["sell","3641.00","1"],["sell","3642.00","1"],["sell","3643.00","1"],["sell","3644.00","1"],["sell","3645.00","1"],["sell","3646.00","1"],["sell","3647.00","1"],["sell","3648.00","1"],["sell","3649.00","1"],["sell","3650.00","1"],["sell","3651.00","1"],["sell","3652.00","1"],["sell","3653.00","1"],["sell","3654.00","1"],["sell","3655.00","1"],["sell","3656.00","1"],["sell","3657.00","1"],["sell","3658.00","1"],["sell","3659.00","1"],["sell","3660.00","1.97211"],["sell","3661.00","1"],["sell","3662.00","1"],["sell","3663.00","1"],["sell","3664.00","1"],["sell","3665.00","1"],["sell","3666.00","1"],["sell","3667.00","1"],["sell","3668.00","1"],["sell","3669.00","1"],["sell","3670.00","1"],["sell","3671.00","1"],["sell","3672.00","1"],["sell","3673.00","1"],["sell","3674.00","1"],["sell","3675.00","1"],["sell","3676.00","1"],["sell","3677.00","1"],["sell","3678.00","1"],["sell","3679.00","1"],["sell","3680.00","1"],["sell","3681.00","1"],["sell","3682.00","1"],["sell","3683.00","1"],["sell","3684.00","1"],["sell","3685.00","1"],["sell","3686.00","1"],["sell","3687.00","1"],["sell","3688.00","1"],["sell","3689.00","1"],["sell","3690.00","1"],["sell","3691.00","1"],["sell","3692.00","1"],["sell","3693.00","1"],["sell","3694.00","1"],["sell","3695.00","1"],["sell","3696.00","1"],["sell","3697.00","1"],["sell","3698.00","1"],["sell","3699.00","1"],["sell","3700.00","1"],["sell","3701.00","1"],["sell","3702.00","1"],["sell","3703.00","1"],["sell","3704.00","1"],["sell","3705.00","1"],["sell","3706.00","1"],["sell","3707.00","1"],["sell","3708.00","1"],["sell","3709.00","1"],["sell","3710.00","1"],["sell","3711.00","1"],["sell","3712.00","1"],["sell","3713.00","1"],["sell","3714.00","1"],["sell","3715.00","1"],["sell","3716.00","1"],["sell","3717.00","1"],["sell","3718.00","1"],["sell","3719.00","1"],["sell","3720.00","1"],["sell","3721.00","1"],["sell","3722.00","1"],["sell","3723.00","1"],["sell","3724.00","1"],["sell","3725.00","1"],["sell","3726.00","1"],["sell","3727.00","1"],["sell","3728.00","1"],["sell","3729.00","1"],["sell","3730.00","1"],["sell","3731.00","1"],["sell","3732.00","1"],["sell","3733.00","1"],["sell","3734.00","1"],["sell","3735.00","1"],["sell","3736.00","1"],["sell","3737.00","1"],["sell","3738.00","1"],["sell","3739.00","1"],["sell","3740.00","1"],["sell","3741.00","1"],["sell","3742.00","1"],["sell","3743.00","1"],["sell","3744.00","1"],["sell","3745.00","1"],["sell","3746.00","1"],["sell","3747.00","1"],["sell","3748.00","1"],["sell","3749.00","1"],["sell","3750.00","1"],["sell","3751.00","1"],["sell","3752.00","1"],["sell","3753.00","1"],["sell","3754.00","1"],["sell","3755.00","1"],["sell","3756.00","1"],["sell","3757.00","1"],["sell","3758.00","1"],["sell","3759.00","1"],["sell","3760.00","1"],["sell","3761.00","1"],["sell","3762.00","1"],["sell","3763.00","1"],["sell","3764.00","1"],["sell","3765.00","1"],["sell","3766.00","1"],["sell","3767.00","1"],["sell","3768.00","1"],["sell","3769.00","1"],["sell","3770.00","1"],["sell","3771.00","1"],["sell","3772.00","1"],["sell","3773.00","1"],["sell","3774.00","1"],["sell","3775.00","1"],["sell","3776.00","1"],["sell","3777.00","1.001"],["sell","3778.00","1"],["sell","3779.00","1"],["sell","3780.00","1"],["sell","3781.00","1"],["sell","3782.00","1"],["sell","3783.00","1"],["sell","3784.00","1"],["sell","3785.00","1"],["sell","3786.00","1"],["sell","3787.00","1"],["sell","3788.00","1"],["sell","3789.00","1"],["sell","3790.00","1"],["sell","3791.00","1"],["sell","3792.00","1"],["sell","3793.00","1"],["sell","3794.00","1"],["sell","3795.00","1"],["sell","3796.00","1"],["sell","3797.00","1"],["sell","3798.00","1"],["sell","3799.00","1"],["sell","3800.00","1.168761"],["sell","3801.00","1"],["sell","4273.13","0.001"],["sell","4444.00","0.001"],["sell","4454.34","1"],["sell","4777.00","0.001"],["sell","4844.09","0.003"],["sell","4999.00","0.001"],["sell","5000.00","0.1"],["sell","5005.20","0.1"],["sell","5157.92","0.0013"],["sell","5213.05","0.0012"],["sell","5555.00","0.001"],["sell","5999.00","0.001"],["sell","6000.00","1"],["sell","6222.00","0.001"],["sell","6666.00","0.001"],["sell","6999.00","0.001"],["sell","7000.00","1"],["sell","7222.00","0.001"],["sell","7500.00","9"],["sell","7777.00","0.001"],["sell","7999.00","0.001"],["sell","8000.00","1"],["sell","8333.00","0.001"],["sell","8803.68","1"],["sell","8888.00","0.001"],["sell","8971.63","3.031212"],["sell","9000.00","1"],["sell","9222.00","0.001"],["sell","9777.00","0.001"],["sell","9999.00","0.001"],["sell","10000.00","1.3"],["sell","10777.00","0.001"],["sell","11000.00","1"],["sell","11111.00","0.001"],["sell","11777.00","0.001"],["sell","12000.00","1"],["sell","12003.68","1.04"],["sell","13000.00","1"],["sell","14000.00","1"],["sell","998889.00","0.1"]],"trades":[{"type":"trade","symbol":"ETHEUR","event_id":45463993949,"timestamp":1624492802863,"price":"1648.19","quantity":"0.05","side":"sell"},{"type":"trade","symbol":"ETHEUR","event_id":45462063037,"timestamp":1624491313277,"price":"1646.14","quantity":"0.114717","side":"buy"},{"type":"trade","symbol":"ETHEUR","event_id":45462025362,"timestamp":1624491290329,"price":"1648.16","quantity":"0.113795","side":"buy"},{"type":"trade","symbol":"ETHEUR","event_id":45461958262,"timestamp":1624491258447,"price":"1645.65","quantity":"0.056667","side":"buy"},{"type":"trade","symbol":"ETHEUR","event_id":45461284310,"timestamp":1624490773708,"price":"1640.06","quantity":"0.091856","side":"buy"},{"type":"trade","symbol":"ETHEUR","event_id":45461183357,"timestamp":1624490696455,"price":"1640.34","quantity":"0.09185","side":"buy"},{"type":"trade","symbol":"ETHEUR","event_id":45460096771,"timestamp":1624489810228,"price":"1634.35","quantity":"0.014307","side":"buy"},{"type":"trade","symbol":"ETHEUR","event_id":45459695223,"timestamp":1624489435532,"price":"1634.33","quantity":"0.010532","side":"buy"},{"type":"trade","symbol":"ETHEUR","event_id":45457990354,"timestamp":1624487726113,"price":"1631.00","quantity":"0.000262","side":"sell"},{"type":"trade","symbol":"ETHEUR","event_id":45457990170,"timestamp":1624487726080,"price":"1631.00","quantity":"0.012","side":"sell"},{"type":"trade","symbol":"ETHEUR","event_id":45457593503,"timestamp":1624487397361,"price":"1633.64","quantity":"0.480006","side":"buy"},{"type":"trade","symbol":"ETHEUR","event_id":45456903060,"timestamp":1624486828043,"price":"1632.55","quantity":"0.029255","side":"buy"},{"type":"trade","symbol":"ETHEUR","event_id":45456807455,"timestamp":1624486776956,"price":"1627.66","quantity":"0.031764","side":"sell"},{"type":"trade","symbol":"ETHEUR","event_id":45452192989,"timestamp":1624483232525,"price":"1637.81","quantity":"0.178221","side":"sell"},{"type":"trade","symbol":"ETHEUR","event_id":45451600288,"timestamp":1624482795170,"price":"1628.07","quantity":"0.45154","side":"buy"},{"type":"trade","symbol":"ETHEUR","event_id":45451103638,"timestamp":1624482392878,"price":"1627.33","quantity":"0.028279","side":"buy"},{"type":"trade","symbol":"ETHEUR","event_id":45451086278,"timestamp":1624482364716,"price":"1627.86","quantity":"0.541965","side":"buy"},{"type":"trade","symbol":"ETHEUR","event_id":45451066053,"timestamp":1624482339404,"price":"1627.57","quantity":"0.602459","side":"buy"},{"type":"trade","symbol":"ETHEUR","event_id":45450991736,"timestamp":1624482292396,"price":"1627.54","quantity":"0.054808","side":"buy"},{"type":"trade","symbol":"ETHEUR","event_id":45450862789,"timestamp":1624482218963,"price":"1626.35","quantity":"0.232249","side":"buy"},{"type":"trade","symbol":"ETHEUR","event_id":45450814454,"timestamp":1624482190720,"price":"1624.02","quantity":"0.20389","side":"buy"},{"type":"trade","symbol":"ETHEUR","event_id":45450323619,"timestamp":1624481916922,"price":"1618.90","quantity":"0.99971","side":"buy"},{"type":"trade","symbol":"ETHEUR","event_id":45449803018,"timestamp":1624481623620,"price":"1615.75","quantity":"0.338063","side":"sell"},{"type":"trade","symbol":"ETHEUR","event_id":45448755245,"timestamp":1624480892803,"price":"1629.30","quantity":"0.013848","side":"buy"},{"type":"trade","symbol":"ETHEUR","event_id":45446895188,"timestamp":1624479810163,"price":"1616.10","quantity":"0.087103","side":"buy"},{"type":"trade","symbol":"ETHEUR","event_id":45445160568,"timestamp":1624478876493,"price":"1614.05","quantity":"0.045785","side":"buy"},{"type":"trade","symbol":"ETHEUR","event_id":45444785221,"timestamp":1624478732550,"price":"1601.00","quantity":"0.06246","side":"sell"},{"type":"trade","symbol":"ETHEUR","event_id":45444060129,"timestamp":1624478411972,"price":"1613.77","quantity":"0.003095","side":"sell"},{"type":"trade","symbol":"ETHEUR","event_id":45442351466,"timestamp":1624477425932,"price":"1637.85","quantity":"0.190596","side":"buy"},{"type":"trade","symbol":"ETHEUR","event_id":45442315784,"timestamp":1624477396130,"price":"1637.85","quantity":"0.202151","side":"buy"},{"type":"trade","symbol":"ETHEUR","event_id":45442286707,"timestamp":1624477371493,"price":"1637.85","quantity":"0.086121","side":"buy"},{"type":"trade","symbol":"ETHEUR","event_id":45437172948,"timestamp":1624474240431,"price":"1627.58","quantity":"0.316362","side":"sell"},{"type":"trade","symbol":"ETHEUR","event_id":45432846740,"timestamp":1624471618181,"price":"1642.72","quantity":"0.0548","side":"sell"},{"type":"trade","symbol":"ETHEUR","event_id":45431322691,"timestamp":1624470650792,"price":"1653.19","quantity":"0.42","side":"sell"},{"type":"trade","symbol":"ETHEUR","event_id":45430865992,"timestamp":1624470381441,"price":"1661.56","quantity":"0.001745","side":"sell"},{"type":"trade","symbol":"ETHEUR","event_id":45428234998,"timestamp":1624468521210,"price":"1671.45","quantity":"0.001","side":"buy"},{"type":"trade","symbol":"ETHEUR","event_id":45424696649,"timestamp":1624466402330,"price":"1668.02","quantity":"0.011035","side":"buy"},{"type":"trade","symbol":"ETHEUR","event_id":45420958350,"timestamp":1624464385387,"price":"1659.10","quantity":"0.017473","side":"buy"},{"type":"trade","symbol":"ETHEUR","event_id":45420958043,"timestamp":1624464385274,"price":"1659.10","quantity":"2.520527","side":"buy"},{"type":"trade","symbol":"ETHEUR","event_id":45420810965,"timestamp":1624464333567,"price":"1644.84","quantity":"2.548512","side":"buy"},{"type":"trade","symbol":"ETHEUR","event_id":45418788836,"timestamp":1624463481421,"price":"1650.50","quantity":"0.11","side":"sell"},{"type":"trade","symbol":"ETHEUR","event_id":45416906001,"timestamp":1624462541601,"price":"1662.61","quantity":"0.011676","side":"buy"},{"type":"trade","symbol":"ETHEUR","event_id":45365522780,"timestamp":1624433165601,"price":"1681.96","quantity":"0.14827174","side":"buy"},{"type":"trade","symbol":"ETHEUR","event_id":45365805979,"timestamp":1624433392924,"price":"1685.08","quantity":"2.49034","side":"buy"},{"type":"trade","symbol":"ETHEUR","event_id":45365805981,"timestamp":1624433392924,"price":"1685.21","quantity":"1.243","side":"buy"},{"type":"trade","symbol":"ETHEUR","event_id":45365805983,"timestamp":1624433392924,"price":"1685.25","quantity":"4.98068","side":"buy"},{"type":"trade","symbol":"ETHEUR","event_id":45365805985,"timestamp":1624433392924,"price":"1685.27","quantity":"2.489814","side":"buy"},{"type":"trade","symbol":"ETHEUR","event_id":45365805987,"timestamp":1624433392924,"price":"1685.36","quantity":"0.428068","side":"buy"},{"type":"trade","symbol":"ETHEUR","event_id":45367240362,"timestamp":1624434310083,"price":"1695.74","quantity":"0.001","side":"buy"},{"type":"trade","symbol":"ETHEUR","event_id":45370566291,"timestamp":1624436007046,"price":"1684.60","quantity":"2.327424","side":"buy"}],"auction_events":[]}
1624493666.713963: {"type":"l2_updates","symbol":"BATBTC","changes":[["buy","0.00001613","65678.127884"],["buy","0.00001606","15210.037232"],["buy","0.00001588","7841.265447"],["buy","0.0000158","1422.511906"],["buy","0.00001572","8722.038636"],["buy","0.00001522","1005.256241"],["buy","0.000015","500"],["buy","0.00001123","10000"],["buy","0.000011","25000"],["buy","0.00000888","1000"],["buy","0.00000809","22"],["buy","0.00000695","28776.978417"],["buy","0.0000069","3000"],["buy","0.0000064","2008.90625"],["buy","0.00000003","229000"],["buy","0.00000001","1800000"],["sell","0.00001758","1431.750532"],["sell","0.0000197","150"],["sell","0.0000245","531.9141"],["sell","0.00002451","10"],["sell","0.000025","1580"],["sell","0.0000271","100.726258"],["sell","0.00002791","12"],["sell","0.0000286","2360.166464"],["sell","0.00002943","6"],["sell","0.00002994","8"],["sell","0.00002995","20"],["sell","0.00003","54.790259"],["sell","0.00003001","4"],["sell","0.00003041","6"],["sell","0.0000305","4"],["sell","0.000031","2"],["sell","0.00003184","1500"],["sell","0.00003206","4"],["sell","0.00003214","3"],["sell","0.0000325","10"],["sell","0.00003275","4"],["sell","0.00003279","4"],["sell","0.00003296","4"],["sell","0.00003299","4"],["sell","0.00003308","3"],["sell","0.00003312","4"],["sell","0.00003365","4"],["sell","0.00003367","4"],["sell","0.000034","153"],["sell","0.00003439","4"],["sell","0.00003484","4"],["sell","0.00003505","3"],["sell","0.00003548","156"],["sell","0.00003595","2.4"],["sell","0.000036","3"],["sell","0.00003604","4"],["sell","0.0000361","3"],["sell","0.00003629","4"],["sell","0.00003631","4"],["sell","0.00003632","5"],["sell","0.00003634","4"],["sell","0.00003637","3"],["sell","0.00003644","8"],["sell","0.00003656","3"],["sell","0.00003663","6"],["sell","0.00003691","4"],["sell","0.0000374","4"],["sell","0.00003991","265"],["sell","0.000041","2"],["sell","0.00004477","165"],["sell","0.00004572","228.825"],["sell","0.00005","306.647478"],["sell","0.000052","250"],["sell","0.00005437","156"],["sell","0.000056","102"],["sell","0.00006673","6.504"],["sell","0.00007","5000"],["sell","0.00007446","156"],["sell","0.00009272","156"],["sell","0.00010383","228.825"],["sell","0.0006837","228.825"],["sell","0.02088","69"],["sell","0.1289","99"],["sell","0.1791","260"],["sell","4.89","6"],["sell","7.84","22"]],"trades":[{"type":"trade","symbol":"BATBTC","event_id":45463611377,"timestamp":1624492451716,"price":"0.00001625","quantity":"12.078393","side":"buy"},{"type":"trade","symbol":"BATBTC","event_id":45452874262,"timestamp":1624483981889,"price":"0.00001631","quantity":"2.189076","side":"sell"},{"type":"trade","symbol":"BATBTC","event_id":45449876361,"timestamp":1624481672977,"price":"0.00001631","quantity":"5.264899","side":"sell"},{"type":"trade","symbol":"BATBTC","event_id":45442388865,"timestamp":1624477445789,"price":"0.00001636","quantity":"4.755826","side":"sell"},{"type":"trade","symbol":"BATBTC","event_id":45416695005,"timestamp":1624462377350,"price":"0.00001522","quantity":"2.091419","side":"sell"},{"type":"trade","symbol":"BATBTC","event_id":44289705488,"timestamp":1623727131654,"price":"0.00001687","quantity":"1.685579","side":"sell"},{"type":"trade","symbol":"BATBTC","event_id":44290856337,"timestamp":1623728036637,"price":"0.00001687","quantity":"12.195756","side":"sell"},{"type":"trade","symbol":"BATBTC","event_id":44292736677,"timestamp":1623729573348,"price":"0.00001836","quantity":"1.259736","side":"buy"},{"type":"trade","symbol":"BATBTC","event_id":44312342957,"timestamp":1623745134605,"price":"0.00001761","quantity":"7.217102","side":"buy"},{"type":"trade","symbol":"BATBTC","event_id":44319539406,"timestamp":1623749604485,"price":"0.00001836","quantity":"3.712993","side":"buy"},{"type":"trade","symbol":"BATBTC","event_id":44335019538,"timestamp":1623760805621,"price":"0.00001725","quantity":"10.165871","side":"buy"},{"type":"trade","symbol":"BATBTC","event_id":44337578233,"timestamp":1623762338113,"price":"0.0000176","quantity":"1.395666","side":"sell"},{"type":"trade","symbol":"BATBTC","event_id":44378879688,"timestamp":1623792839532,"price":"0.00001707","quantity":"2.389965","side":"buy"},{"type":"trade","symbol":"BATBTC","event_id":44388563426,"timestamp":1623801652778,"price":"0.00001695","quantity":"10.17303","side":"sell"},{"type":"trade","symbol":"BATBTC","event_id":44395625049,"timestamp":1623806539276,"price":"0.00001684","quantity":"297.441404","side":"sell"},{"type":"trade","symbol":"BATBTC","event_id":44396259169,"timestamp":1623806870413,"price":"0.00001684","quantity":"473.402473","side":"sell"},{"type":"trade","symbol":"BATBTC","event_id":44406738848,"timestamp":1623815845984,"price":"0.00001744","quantity":"11.433466","side":"buy"},{"type":"trade","symbol":"BATBTC","event_id":44409659099,"timestamp":1623818412327,"price":"0.00001702","quantity":"1.231866","side":"sell"},{"type":"trade","symbol":"BATBTC","event_id":44453769298,"timestamp":1623853845403,"price":"0.00001702","quantity":"90","side":"buy"},{"type":"trade","symbol":"BATBTC","event_id":44455137355,"timestamp":1623855069209,"price":"0.00001732","quantity":"1.869875","side":"sell"},{"type":"trade","symbol":"BATBTC","event_id":44491083041,"timestamp":1623875952109,"price":"0.00001725","quantity":"1.72259","side":"buy"},{"type":"trade","symbol":"BATBTC","event_id":44504312526,"timestamp":1623888220014,"price":"0.00001761","quantity":"8.877394","side":"buy"},{"type":"trade","symbol":"BATBTC","event_id":44504936350,"timestamp":1623888603446,"price":"0.00001722","quantity":"1.78988","side":"sell"},{"type":"trade","symbol":"BATBTC","event_id":44718992545,"timestamp":1624060738122,"price":"0.00001735","quantity":"2.793071","side":"sell"},{"type":"trade","symbol":"BATBTC","event_id":44739494073,"timestamp":1624075760351,"price":"0.00001723","quantity":"1211","side":"buy"},{"type":"trade","symbol":"BATBTC","event_id":44828042440,"timestamp":1624147467829,"price":"0.00001693","quantity":"1.005917","side":"sell"},{"type":"trade","symbol":"BATBTC","event_id":44938037851,"timestamp":1624234050826,"price":"0.0000169","quantity":"2.122721","side":"sell"},{"type":"trade","symbol":"BATBTC","event_id":44976638158,"timestamp":1624257007625,"price":"0.00001684","quantity":"2.082353","side":"sell"},{"type":"trade","symbol":"BATBTC","event_id":45040527641,"timestamp":1624280664652,"price":"0.00001611","quantity":"100","side":"sell"},{"type":"trade","symbol":"BATBTC","event_id":45060884992,"timestamp":1624289603103,"price":"0.00001691","quantity":"3.568778","side":"buy"},{"type":"trade","symbol":"BATBTC","event_id":45083486129,"timestamp":1624299305558,"price":"0.00001691","quantity":"685.224259","side":"buy"},{"type":"trade","symbol":"BATBTC","event_id":45083486205,"timestamp":1624299305582,"price":"0.00001691","quantity":"17.146738","side":"buy"},{"type":"trade","symbol":"BATBTC","event_id":45102346969,"timestamp":1624311201871,"price":"0.0000169","quantity":"1.519515","side":"buy"},{"type":"trade","symbol":"BATBTC","event_id":45119428154,"timestamp":1624319745405,"price":"0.00001575","quantity":"10.337239","side":"buy"},{"type":"trade","symbol":"BATBTC","event_id":45132943520,"timestamp":1624324696823,"price":"0.00001552","quantity":"8.882898","side":"sell"},{"type":"trade","symbol":"BATBTC","event_id":45173226139,"timestamp":1624349147023,"price":"0.00001551","quantity":"200","side":"sell"},{"type":"trade","symbol":"BATBTC","event_id":45184111934,"timestamp":1624354387411,"price":"0.00001585","quantity":"2.101137","side":"buy"},{"type":"trade","symbol":"BATBTC","event_id":45190397139,"timestamp":1624357106589,"price":"0.00001506","quantity":"139.442231","side":"sell"},{"type":"trade","symbol":"BATBTC","event_id":45190871616,"timestamp":1624357339374,"price":"0.00001501","quantity":"300","side":"sell"},{"type":"trade","symbol":"BATBTC","event_id":45229700568,"timestamp":1624370911725,"price":"0.00001482","quantity":"1.036255","side":"sell"},{"type":"trade","symbol":"BATBTC","event_id":45244512973,"timestamp":1624375787628,"price":"0.00001582","quantity":"1.164682","side":"sell"},{"type":"trade","symbol":"BATBTC","event_id":45273644558,"timestamp":1624386986607,"price":"0.000015","quantity":"6048","side":"buy"},{"type":"trade","symbol":"BATBTC","event_id":45288750493,"timestamp":1624394192821,"price":"0.00001515","quantity":"1.022152","side":"sell"},{"type":"trade","symbol":"BATBTC","event_id":45291675131,"timestamp":1624395785405,"price":"0.00001516","quantity":"1.467142","side":"sell"},{"type":"trade","symbol":"BATBTC","event_id":45293601478,"timestamp":1624397580217,"price":"0.00001483","quantity":"2.225015","side":"sell"},{"type":"trade","symbol":"BATBTC","event_id":45293861558,"timestamp":1624397797614,"price":"0.00001482","quantity":"700","side":"sell"},{"type":"trade","symbol":"BATBTC","event_id":45298138608,"timestamp":1624400528400,"price":"0.00001505","quantity":"1.269763","side":"buy"},{"type":"trade","symbol":"BATBTC","event_id":45310814735,"timestamp":1624406757703,"price":"0.00001522","quantity":"1.392612","side":"sell"},{"type":"trade","symbol":"BATBTC","event_id":45321560060,"timestamp":1624410199205,"price":"0.00001477","quantity":"1.396936","side":"buy"},{"type":"trade","symbol":"BATBTC","event_id":45342101125,"timestamp":1624419203436,"price":"0.00001539","quantity":"3.939631","side":"sell"}],"auction_events":[]}
1624493666.728491: {"type":"l2_updates","symbol":"ZECLTC","changes":[["buy","0.858","7.023773"],["buy","0.857","75.699286"],["buy","0.853","16.450222"],["buy","0.852","21.552324"],["buy","0.841","23.958683"],["buy","0.76","434.210526"],["buy","0.75","0.022"],["buy","0.662","0.022"],["buy","0.615","1.707317"],["buy","0.597","0.022"],["buy","0.553","0.022"],["buy","0.504","0.019841"],["buy","0.449","0.022"],["buy","0.388","0.11"],["buy","0.333","0.3003"],["buy","0.25","0.1"],["buy","0.222","0.45045"],["buy","0.213","5.620051"],["buy","0.2","0.1"],["buy","0.111","0.9009"],["buy","0.077","1.298701"],["buy","0.02","5"],["buy","0.01","50"],["buy","0.001","1491.11"],["sell","0.886","7.007149"],["sell","0.887","1.576919"],["sell","0.898","194.236805"],["sell","1.111","0.012612"],["sell","1.156","0.01"],["sell","1.184","0.01"],["sell","1.192","0.01"],["sell","1.204","0.02"],["sell","1.209","0.01"],["sell","1.223","0.01"],["sell","1.232","0.02"],["sell","1.25","3"],["sell","1.35","0.02"],["sell","1.354","0.02"],["sell","1.356","0.01"],["sell","1.361","0.02"],["sell","1.367","0.02"],["sell","1.382","0.01"],["sell","1.383","0.02"],["sell","1.388","0.01"],["sell","1.42","0.01"],["sell","1.435","0.02"],["sell","1.445","0.02"],["sell","1.457","0.02"],["sell","1.5","0.01"],["sell","1.67","50"],["sell","1.777","0.1287"],["sell","1.827","0.02"],["sell","1.881","0.01"],["sell","1.999","0.11"],["sell","2","0.1"],["sell","3","0.01"],["sell","6","0.01"],["sell","10","0.11"],["sell","14","0.1"],["sell","15","0.078285"],["sell","20","0.01"],["sell","99990","0.1"],["sell","999990","0.1"]],"trades":[{"type":"trade","symbol":"ZECLTC","event_id":44129108674,"timestamp":1623615527403,"price":"0.782","quantity":"67.722466","side":"sell"},{"type":"trade","symbol":"ZECLTC","event_id":44129109593,"timestamp":1623615527906,"price":"0.782","quantity":"6.703052","side":"sell"},{"type":"trade","symbol":"ZECLTC","event_id":44129109794,"timestamp":1623615528004,"price":"0.782","quantity":"82.46181","side":"sell"},{"type":"trade","symbol":"ZECLTC","event_id":44129110621,"timestamp":1623615528165,"price":"0.782","quantity":"6.70254","side":"sell"},{"type":"trade","symbol":"ZECLTC","event_id":44129110861,"timestamp":1623615528244,"price":"0.782","quantity":"6.702028","side":"sell"},{"type":"trade","symbol":"ZECLTC","event_id":44129112080,"timestamp":1623615528803,"price":"0.782","quantity":"6.699979","side":"sell"},{"type":"trade","symbol":"ZECLTC","event_id":44129112279,"timestamp":1623615528918,"price":"0.782","quantity":"6.699979","side":"sell"},{"type":"trade","symbol":"ZECLTC","event_id":44129113021,"timestamp":1623615529108,"price":"0.782","quantity":"6.699979","side":"sell"},{"type":"trade","symbol":"ZECLTC","event_id":44129113279,"timestamp":1623615529329,"price":"0.782","quantity":"6.697932","side":"sell"},{"type":"trade","symbol":"ZECLTC","event_id":44129113524,"timestamp":1623615529603,"price":"0.782","quantity":"6.695886","side":"sell"},{"type":"trade","symbol":"ZECLTC","event_id":44129113718,"timestamp":1623615529710,"price":"0.782","quantity":"6.695886","side":"sell"},{"type":"trade","symbol":"ZECLTC","event_id":44129113983,"timestamp":1623615529927,"price":"0.782","quantity":"4.284846","side":"sell"},{"type":"trade","symbol":"ZECLTC","event_id":44129115506,"timestamp":1623615530422,"price":"0.782","quantity":"6.693841","side":"sell"},{"type":"trade","symbol":"ZECLTC","event_id":44129117530,"timestamp":1623615531474,"price":"0.782","quantity":"0.824618","side":"sell"},{"type":"trade","symbol":"ZECLTC","event_id":44129118036,"timestamp":1623615531938,"price":"0.782","quantity":"0.75913","side":"sell"},{"type":"trade","symbol":"ZECLTC","event_id":44129119026,"timestamp":1623615532205,"price":"0.782","quantity":"6.693841","side":"sell"},{"type":"trade","symbol":"ZECLTC","event_id":44129119202,"timestamp":1623615532308,"price":"0.782","quantity":"6.691798","side":"sell"},{"type":"trade","symbol":"ZECLTC","event_id":44129119384,"timestamp":1623615532405,"price":"0.782","quantity":"6.612455","side":"sell"},{"type":"trade","symbol":"ZECLTC","event_id":44129119795,"timestamp":1623615532629,"price":"0.782","quantity":"6.691798","side":"sell"},{"type":"trade","symbol":"ZECLTC","event_id":44129119956,"timestamp":1623615532803,"price":"0.782","quantity":"6.691798","side":"sell"},{"type":"trade","symbol":"ZECLTC","event_id":44129120359,"timestamp":1623615533027,"price":"0.782","quantity":"5.715949","side":"sell"},{"type":"trade","symbol":"ZECLTC","event_id":44129121247,"timestamp":1623615533342,"price":"0.782","quantity":"22.44394","side":"sell"},{"type":"trade","symbol":"ZECLTC","event_id":44129122648,"timestamp":1623615533903,"price":"0.782","quantity":"6.687715","side":"sell"},{"type":"trade","symbol":"ZECLTC","event_id":44129123055,"timestamp":1623615534017,"price":"0.782","quantity":"6.616534","side":"sell"},{"type":"trade","symbol":"ZECLTC","event_id":44129124206,"timestamp":1623615534409,"price":"0.782","quantity":"0.581971","side":"sell"},{"type":"trade","symbol":"ZECLTC","event_id":44129124338,"timestamp":1623615534505,"price":"0.782","quantity":"6.691798","side":"sell"},{"type":"trade","symbol":"ZECLTC","event_id":44129124630,"timestamp":1623615534717,"price":"0.782","quantity":"6.685675","side":"sell"},{"type":"trade","symbol":"ZECLTC","event_id":44129125475,"timestamp":1623615535203,"price":"0.782","quantity":"0.871445","side":"sell"},{"type":"trade","symbol":"ZECLTC","event_id":44129125543,"timestamp":1623615535304,"price":"0.782","quantity":"6.685675","side":"sell"},{"type":"trade","symbol":"ZECLTC","event_id":44129126194,"timestamp":1623615535727,"price":"0.782","quantity":"6.685675","side":"sell"},{"type":"trade","symbol":"ZECLTC","event_id":44129126512,"timestamp":1623615536007,"price":"0.782","quantity":"6.686185","side":"sell"},{"type":"trade","symbol":"ZECLTC","event_id":44129127441,"timestamp":1623615536312,"price":"0.782","quantity":"6.684146","side":"sell"},{"type":"trade","symbol":"ZECLTC","event_id":44129127887,"timestamp":1623615536631,"price":"0.782","quantity":"6.676003","side":"sell"},{"type":"trade","symbol":"ZECLTC","event_id":44129128280,"timestamp":1623615536908,"price":"0.782","quantity":"6.676512","side":"sell"},{"type":"trade","symbol":"ZECLTC","event_id":44129129195,"timestamp":1623615537405,"price":"0.782","quantity":"6.676003","side":"sell"},{"type":"trade","symbol":"ZECLTC","event_id":44129129475,"timestamp":1623615537666,"price":"0.782","quantity":"7.685141","side":"sell"},{"type":"trade","symbol":"ZECLTC","event_id":44129129587,"timestamp":1623615537807,"price":"0.782","quantity":"0.995549","side":"sell"},{"type":"trade","symbol":"ZECLTC","event_id":44129130290,"timestamp":1623615538141,"price":"0.782","quantity":"6.676003","side":"sell"},{"type":"trade","symbol":"ZECLTC","event_id":44129130911,"timestamp":1623615538420,"price":"0.782","quantity":"6.628248","side":"sell"},{"type":"trade","symbol":"ZECLTC","event_id":44129131199,"timestamp":1623615538631,"price":"0.782","quantity":"6.676003","side":"sell"},{"type":"trade","symbol":"ZECLTC","event_id":44129131819,"timestamp":1623615539112,"price":"0.782","quantity":"2.04077","side":"sell"},{"type":"trade","symbol":"ZECLTC","event_id":44233418676,"timestamp":1623686140213,"price":"0.818","quantity":"0.60911503","side":"buy"},{"type":"trade","symbol":"ZECLTC","event_id":44281527479,"timestamp":1623720935033,"price":"0.818","quantity":"0.0609115","side":"buy"},{"type":"trade","symbol":"ZECLTC","event_id":44498286731,"timestamp":1623883290596,"price":"0.832","quantity":"7.231917","side":"buy"},{"type":"trade","symbol":"ZECLTC","event_id":44498397364,"timestamp":1623883385232,"price":"0.83","quantity":"0.378639","side":"sell"},{"type":"trade","symbol":"ZECLTC","event_id":44498409012,"timestamp":1623883394809,"price":"0.831","quantity":"6.85096","side":"sell"},{"type":"trade","symbol":"ZECLTC","event_id":44498409854,"timestamp":1623883395450,"price":"0.831","quantity":"7.213483","side":"buy"},{"type":"trade","symbol":"ZECLTC","event_id":44498409976,"timestamp":1623883395591,"price":"0.831","quantity":"339.400459","side":"buy"},{"type":"trade","symbol":"ZECLTC","event_id":44498413519,"timestamp":1623883398233,"price":"0.831","quantity":"39.26788","side":"buy"},{"type":"trade","symbol":"ZECLTC","event_id":44996234156,"timestamp":1624264385035,"price":"0.8","quantity":"0.168381","side":"sell"}],"auction_events":[]}
1624493666.7335732: {"type":"l2_updates","symbol":"FILUSD","changes":[["buy","58.387","56"],["buy","58.3841","213.824413"],["buy","58.3741","171.112412"],["buy","58.3628","256.557226"],["buy","58.3421","37.772"],["buy","58.339","13"],["buy","58.3389","256.668618"],["buy","58.3268","342.182975"],["buy","58.3251","46.201"],["buy","58.0285","13.9"],["buy","58.0284","40.8"],["buy","58.0283","134.3"],["buy","58.0282","2234.370617"],["buy","58.028","65.955136"],["buy","57.9945","1407.3"],["buy","57.9924","9.866276"],["buy","57.8555","585"],["buy","57.8068","538.9"],["buy","57.6217","579"],["buy","57.6155","4718.591007"],["buy","57.5724","134.5"],["buy","56.9657","136.7"],["buy","56.8609","223.271221"],["buy","56.834","691"],["buy","56.8115","135.7"],["buy","56.0462","1263"],["buy","55.8016","141.5"],["buy","55.3512","209.92557"],["buy","55.2584","437"],["buy","55.2092","298.143704"],["buy","54.9551","0.221359"],["buy","54.4156","230.40711"],["buy","54.2421","277.478183"],["buy","54.1757","368.258703"],["buy","53.9172","0.281081"],["buy","53.9171","0.639367"],["buy","53.917","0.169884"],["buy","53.8981","340.272852"],["buy","53.7492","291.201644"],["buy","53.56","186.706497"],["buy","53.2931","359.414383"],["buy","52.8831","0.283644"],["buy","52.00","5"],["buy","51.62","8.395785"],["buy","51.4577","0.279458"],["buy","51.2231","6.138518"],["buy","51.00","0.588235"],["buy","50.8262","6.186456"],["buy","50.4292","6.235149"],["buy","50.0323","6.284614"],["buy","50.0193","0.279458"],["buy","50.00","11"],["buy","49.9224","0.531155"],["buy","49.6354","6.334871"],["buy","49.2385","6.385938"],["buy","49.00","42.2"],["buy","48.8415","6.437835"],["buy","48.4446","6.490582"],["buy","48.0477","6.544201"],["buy","47.6508","6.598713"],["buy","47.4507","0.232993"],["buy","47.2538","6.654141"],["buy","47.252","0.225303"],["buy","47.119","0.314948"],["buy","47.111","2"],["buy","47.00","5"],["buy","46.8569","6.710508"],["buy","46.8473","0.225303"],["buy","46.46","25.652682"],["buy","46.00","0.543478"],["buy","45.80","5"],["buy","45.01","110.708731"],["buy","45.00","22"],["buy","44.75","0.000007"],["buy","44.44","3"],["buy","44.1085","0.335442"],["buy","44.00","0.222"],["buy","43.89","0.75"],["buy","43.50","20"],["buy","43.44","500"],["buy","43.13","1"],["buy","42.51","0.1"],["buy","42.50","1.17647"],["buy","42.20","44.312796"],["buy","42.113","2.2"],["buy","42.11","300"],["buy","42.0669","50"],["buy","42.0604","10"],["buy","42.00","3.521428"],["buy","41.65","1"],["buy","41.61","400"],["buy","41.22","400"],["buy","41.00","11.439024"],["buy","40.75","10"],["buy","40.66","400"],["buy","40.6563","0.122982"],["buy","40.431","2.15"],["buy","40.12","400"],["buy","40.10","0.1"],["buy","40.01","4.483129"],["buy","40.0001","0.124563"],["buy","40.00","32.975"],["buy","39.86","10"],["buy","39.61","1.11"],["buy","39.4043","0.62379"],["buy","39.0545","0.62379"],["buy","39.00","3"],["buy","38.80","5.154639"],["buy","38.6664","0.628161"],["buy","38.47","40"],["buy","38.00","34.273683"],["buy","37.87","6.601531"],["buy","37.77","11.1"],["buy","37.50","13.733333"],["buy","37.4688","10"],["buy","37.0655","1.13"],["buy","37.00","2.702702"],["buy","36.803","1.5"],["buy","36.44","3.5"],["buy","36.2289","20"],["buy","35.60","28"],["buy","35.00","119.878571"],["buy","34.56","7.233796"],["buy","34.1954","40"],["buy","34.00","100"],["buy","33.49","1"],["buy","33.24","20"],["buy","33.00","3"],["buy","32.55","100"],["buy","32.5482","100"],["buy","32.50","15.846153"],["buy","32.17","50"],["buy","31.6297","60"],["buy","31.00","25"],["buy","30.32","20"],["buy","30.0001","0.166084"],["buy","30.00","59.533332"],["buy","29.116","1.05"],["buy","28.50","3.5"],["buy","28.44","4.5"],["buy","28.00","6.771428"],["buy","27.6633","1"],["buy","27.21","75"],["buy","27.00","75.074074"],["buy","26.4227","1.75"],["buy","26.00","8"],["buy","25.64","1.25"],["buy","25.50","10"],["buy","25.2408","1.6"],["buy","25.0981","3.984365"],["buy","25.0001","0.199301"],["buy","25.00","18.04"],["buy","22.3676","200"],["buy","22.30","1.793721"],["buy","21.25","4.705882"],["buy","21.00","301"],["buy","20.44","6"],["buy","20.0001","0.249126"],["buy","20.00","51"],["buy","19.93","1"],["buy","18.00","71.444444"],["buy","15.0001","0.332168"],["buy","15.00","26"],["buy","13.00","1"],["buy","12.98","800"],["buy","12.44","10"],["buy","12.30","500"],["buy","12.00","27.45"],["buy","10.00","46"],["buy","6.44","20"],["buy","6.0986","20"],["buy","5.24","10"],["buy","3.44","50"],["buy","1.24","100"],["buy","0.05","10000"],["buy","0.021","1200"],["buy","0.0112","2000"],["buy","0.01","10"],["buy","0.002","20000"],["buy","0.0011","20000"],["buy","0.001","17100"],["buy","0.0001","110700"],["sell","58.4864","56"],["sell","58.4893","171.101437"],["sell","58.492","39.455"],["sell","58.4968","13.9"],["sell","58.4969","56"],["sell","58.4998","15.405377"],["sell","58.509","65.711"],["sell","58.5184","40.8"],["sell","58.5185","256.627294"],["sell","58.5429","13"],["sell","58.547","213.710645"],["sell","58.5733","256.440146"],["sell","58.5871","134.3"],["sell","58.5872","341.906156"],["sell","58.8335","1013.920555"],["sell","58.8337","1403.4"],["sell","58.9493","544.9"],["sell","59.1565","137.4"],["sell","59.1566","934.812391"],["sell","59.3685","73.67162"],["sell","59.4666","0.187927"],["sell","59.4667","0.1"],["sell","59.50","3"],["sell","59.5682","3.7"],["sell","59.60","0.6"],["sell","59.68","300"],["sell","59.75","5"],["sell","59.9311","1.1"],["sell","60.00","8.224194"],["sell","60.069","0.187927"],["sell","60.0691","3.7"],["sell","60.2622","1.1"],["sell","60.4271","157.935036"],["sell","60.57","10"],["sell","60.5933","1.1"],["sell","60.684","13.4"],["sell","60.9244","1.1"],["sell","61.00","3.344263"],["sell","61.1753","203.989028"],["sell","61.2556","1.1"],["sell","61.295","0.351396"],["sell","61.5867","1.1"],["sell","61.705","235.664041"],["sell","61.7821","30"],["sell","61.9178","1.1"],["sell","61.9861","204.968566"],["sell","62.00","500"],["sell","62.1915","258.627333"],["sell","62.22","400"],["sell","62.2489","1.1"],["sell","62.31","14.4"],["sell","62.4725","0.187927"],["sell","62.58","2.4"],["sell","62.873","2"],["sell","63.00","3.81519"],["sell","63.10","7"],["sell","63.15","0.114212"],["sell","63.179","0.187927"],["sell","63.2895","295.454769"],["sell","63.36","1"],["sell","63.7815","0.114212"],["sell","63.9319","256.804154"],["sell","64.00","0.46875"],["sell","64.11","200"],["sell","64.159","0.179899"],["sell","64.4194","0.11275"],["sell","64.9225","0.179899"],["sell","65.00","502"],["sell","65.0635","0.11275"],["sell","65.714","0.11275"],["sell","66.00","44.488546"],["sell","66.195","0.179899"],["sell","66.3711","0.11275"],["sell","67.0348","0.11275"],["sell","67.0995","0.238452"],["sell","67.4675","0.179899"],["sell","67.7052","0.11275"],["sell","68.231","0.179899"],["sell","68.3821","0.11275"],["sell","69.0659","0.11275"],["sell","69.29","0.179991"],["sell","69.7566","0.11275"],["sell","70.00","7.958147"],["sell","70.115","0.179991"],["sell","70.4541","0.11275"],["sell","70.8451","0.1"],["sell","70.9739","0.1"],["sell","71.1542","0.1"],["sell","71.1585","0.11275"],["sell","71.49","0.179991"],["sell","71.55","4"],["sell","71.87","0.11275"],["sell","72.00","30.74259"],["sell","72.5887","0.11275"],["sell","72.865","0.179991"],["sell","73.3145","0.11275"],["sell","73.3694","0.1"],["sell","73.69","0.179991"],["sell","74.0475","0.11275"],["sell","74.788","0.11275"],["sell","74.80","0.40107"],["sell","75.00","20.766667"],["sell","75.5358","0.11275"],["sell","76.291","0.11275"],["sell","77.00","111.538461"],["sell","77.0539","0.11275"],["sell","77.8244","0.11275"],["sell","78.00","8"],["sell","78.6026","0.11275"],["sell","79.3887","0.11275"],["sell","79.90","5"],["sell","79.98","1"],["sell","80.00","0.794424"],["sell","80.1824","0.11275"],["sell","80.9842","0.11275"],["sell","81.794","0.11275"],["sell","82.6119","0.11275"],["sell","82.922","2.7"],["sell","83.438","0.11275"],["sell","84.00","0.372201"],["sell","84.2724","0.11275"],["sell","84.93","0.555"],["sell","84.98","5"],["sell","85.00","5.089979"],["sell","85.115","0.11275"],["sell","85.966","0.11275"],["sell","86.00","100.348838"],["sell","86.8256","0.11275"],["sell","87.6938","0.11275"],["sell","88.00","0.875001"],["sell","88.5707","0.11275"],["sell","88.8366","29.566175"],["sell","89.4563","0.11275"],["sell","89.98","1"],["sell","90.00","2625.893156"],["sell","90.3358","1.6"],["sell","90.3485","1.6"],["sell","90.3509","0.11275"],["sell","91.00","31.085517"],["sell","91.2543","0.11275"],["sell","91.60","0.000008"],["sell","92.10","1.873506"],["sell","92.1668","0.11275"],["sell","92.2999","54.17"],["sell","93.00","100.169012"],["sell","93.0884","0.11275"],["sell","94.00","50"],["sell","94.0192","0.11275"],["sell","94.88","3"],["sell","95.00","597.55167"],["sell","95.7985","4"],["sell","96.60","5"],["sell","96.89","0.30963"],["sell","96.9574","1.031381"],["sell","97.00","3.194077"],["sell","97.4298","0.441344"],["sell","97.97","0.5"],["sell","98.00","101.622449"],["sell","98.053","390.22"],["sell","98.44","0.1"],["sell","99.00","16.482526"],["sell","99.1676","0.1"],["sell","99.21","0.127398"],["sell","99.45","5"],["sell","99.58","925"],["sell","99.99","0.626279"],["sell","100.00","1180.881252"],["sell","100.6453","7"],["sell","101.00","4.537368"],["sell","102.00","2"],["sell","102.54","0.142333"],["sell","103.00","0.291263"],["sell","103.76","333"],["sell","104.54","0.102568"],["sell","104.98","1"],["sell","105.10","0.666033"],["sell","105.32","0.1"],["sell","106.00","7.591434"],["sell","106.25","0.164245"],["sell","106.733","0.5"],["sell","107.00","0.40187"],["sell","108.986","739.45"],["sell","109.00","2"],["sell","110.32","0.1"],["sell","111.2779","1"],["sell","112.49","2"],["sell","112.96","0.116111"],["sell","113.0315","1025"],["sell","114.00","2"],["sell","114.32","0.1"],["sell","115.00","1.5"],["sell","115.60","25"],["sell","117.00","0.367522"],["sell","118.98","1"],["sell","119.32","0.1"],["sell","119.75","9.193783"],["sell","119.88","10"],["sell","120.00","16.858674"],["sell","120.63","8.772192"],["sell","121.00","0.173554"],["sell","123.98","1"],["sell","124.00","5.813953"],["sell","124.25","10"],["sell","125.00","362.397722"],["sell","126.00","2.488"],["sell","127.00","0.4645"],["sell","127.26","0.10725"],["sell","128.00","100"],["sell","128.72","0.100417"],["sell","128.76","1.689"],["sell","128.98","0.5"],["sell","129.3641","0.37"],["sell","129.60","1.548639"],["sell","130.00","856.160748"],["sell","131.00","0.328245"],["sell","135.00","10"],["sell","135.002","0.25"],["sell","138.00","0.16"],["sell","138.17","0.100908"],["sell","139.86","0.108019"],["sell","140.00","253.298276"],["sell","140.0201","0.6"],["sell","142.00","10"],["sell","143.11","0.286914"],["sell","145.00","6.89551"],["sell","145.46","0.106573"],["sell","146.9835","0.45"],["sell","148.00","2"],["sell","148.5253","5"],["sell","148.69","4"],["sell","148.8117","0.1"],["sell","148.97","0.104244"],["sell","149.00","20.402685"],["sell","149.16","0.1"],["sell","149.80","1"],["sell","149.87","6.786"],["sell","149.96","0.685521"],["sell","149.99","2"],["sell","149.999","1.01"],["sell","150.00","646.470567"],["sell","150.555","0.49"],["sell","151.00","0.1"],["sell","151.20","13"],["sell","151.60","1.273326"],["sell","152.00","30.393"],["sell","153.2407","0.1"],["sell","154.00","1"],["sell","155.00","45.546174"],["sell","155.12","0.1"],["sell","156.00","1.13"],["sell","156.72","2.9559"],["sell","157.61","3.995"],["sell","157.75","1.005087"],["sell","159.00","0.651708"],["sell","160.00","122.161906"],["sell","161.00","10.191557"],["sell","162.00","0.364198"],["sell","162.5476","20"],["sell","163.3125","0.1"],["sell","163.523","106.857119"],["sell","164.00","0.361286"],["sell","165.00","6.251332"],["sell","165.4672","1"],["sell","166.00","0.4787"],["sell","168.00","2.17"],["sell","168.60","0.3"],["sell","169.00","10.1"],["sell","169.40","0.177096"],["sell","170.00","3.870858"],["sell","170.40","0.21"],["sell","171.88","0.1"],["sell","172.00","50"],["sell","172.0247","0.1"],["sell","172.95","0.124235"],["sell","173.00","0.990579"],["sell","174.00","0.31"],["sell","174.45","1"],["sell","174.78","0.5"],["sell","175.00","19.169089"],["sell","175.13","0.109295"],["sell","176.00","0.517728"],["sell","178.00","0.15"],["sell","180.00","34.056761"],["sell","182.9437","0.64"],["sell","183.13","3.479249"],["sell","183.6702","3"],["sell","183.70","0.138041"],["sell","184.00","5.739283"],["sell","184.1875","0.118824"],["sell","185.00","22.740634"],["sell","185.81","0.670696"],["sell","185.99","0.670697"],["sell","186.00","0.537635"],["sell","186.0294","0.120439"],["sell","186.40","1"],["sell","187.21","165.69198"],["sell","187.50","2.043506"],["sell","187.8897","0.118824"],["sell","188.00","11.262045"],["sell","188.70","65.521626"],["sell","188.88","2000"],["sell","189.00","41"],["sell","189.30","1"],["sell","189.7685","0.122521"],["sell","189.95","0.516235"],["sell","190.00","5.267003"],["sell","190.42","1.807725"],["sell","191.00","4.688159"],["sell","191.6662","0.120439"],["sell","192.0237","1.05425"],["sell","192.5476","30"],["sell","192.5638","0.13"],["sell","193.00","13.457894"],["sell","193.5828","0.118824"],["sell","194.20","1.19798"],["sell","194.45","1"],["sell","194.9674","15.365838"],["sell","194.98","5.19862"],["sell","195.00","105.148718"],["sell","195.5186","0.118824"],["sell","196.13","0.174316"],["sell","196.79","255"],["sell","197.00","0.3"],["sell","197.4737","0.120439"],["sell","198.00","2.076012"],["sell","198.01","1"],["sell","198.72","20.284305"],["sell","199.00","110.125629"],["sell","199.4484","0.118824"],["sell","199.499","0.65"],["sell","199.99","68.7547"],["sell","200.00","592.639644"],["sell","201.00","5"],["sell","201.4428","0.118824"],["sell","202.00","1070"],["sell","203.00","5"],["sell","203.4571","0.117248"],["sell","204.30","186.637875"],["sell","205.00","1002"],["sell","205.4916","0.115711"],["sell","206.00","8.951212"],["sell","207.02","0.3108"],["sell","207.03","0.5"],["sell","207.3766","10.952543"],["sell","207.5465","0.114212"],["sell","208.00","13.685606"],["sell","208.36","0.100083"],["sell","209.6219","0.11275"],["sell","210.00","26"],["sell","211.56","0.594"],["sell","211.7181","0.114212"],["sell","212.00","8"],["sell","212.1514","0.1"],["sell","213.00","5"],["sell","213.8352","0.11275"],["sell","214.6981","0.470429"],["sell","214.94","0.4"],["sell","215.00","5.252186"],["sell","215.9735","0.11275"],["sell","218.1332","0.114212"],["sell","218.50","1.9481"],["sell","219.00","0.5"],["sell","219.1583","0.1"],["sell","220.00","1015"],["sell","220.3145","0.114212"],["sell","221.00","2"],["sell","222.00","9"],["sell","222.0628","0.2"],["sell","222.22","1500"],["sell","222.5176","0.114212"],["sell","223.00","13"],["sell","223.57","6"],["sell","223.7293","0.1"],["sell","224.00","100"],["sell","224.7427","0.114212"],["sell","224.99","23.599026"],["sell","225.00","1041.45"],["sell","225.624","0.1"],["sell","227.15","0.143745"],["sell","228.94","0.6"],["sell","230.00","55.493257"],["sell","231.00","1010"],["sell","232.58","41.748961"],["sell","233.98","0.7"],["sell","234.00","11.765909"],["sell","234.2782","0.1"],["sell","235.00","31"],["sell","235.70","1"],["sell","235.8219","47.688753"],["sell","236.00","96.1"],["sell","237.00","21.22526"],["sell","237.3671","1"],["sell","237.3809","1"],["sell","237.432","2"],["sell","237.9997","1"],["sell","238.00","1000.105042"],["sell","238.2652","0.1"],["sell","238.4997","1"],["sell","238.9997","1"],["sell","239.4997","1"],["sell","239.7267","35.750585"],["sell","239.9563","600"],["sell","239.9997","1"],["sell","240.00","200"],["sell","240.4997","1"],["sell","240.9997","1"],["sell","241.00","500"],["sell","242.65","7.10892"],["sell","244.98","0.8"],["sell","245.00","1506.59037"],["sell","247.98","1.4"],["sell","249.00","3.7"],["sell","250.00","507.286666"],["sell","259.00","250"],["sell","260.00","2"],["sell","261.00","1"],["sell","262.88","2000"],["sell","263.00","8"],["sell","264.9273","3.787878"],["sell","264.9672","0.377405"],["sell","269.00","40"],["sell","269.94","1.5"],["sell","273.6901","6"],["sell","274.90","250"],["sell","275.00","0.2"],["sell","276.00","4"],["sell","278.466","1"],["sell","283.00","4"],["sell","286.4904","0.1"],["sell","287.00","1"],["sell","288.00","40"],["sell","288.7015","0.1"],["sell","288.87","1500"],["sell","293.00","5"],["sell","294.50","3"],["sell","299.00","500"],["sell","300.00","203.92552"],["sell","303.00","9"],["sell","320.00","1.6"],["sell","322.00","1500"],["sell","329.00","3"],["sell","330.5223","0.1"],["sell","331.00","20"],["sell","333.00","4"],["sell","333.888","2.03485"],["sell","341.11","1500"],["sell","346.14","29"],["sell","350.00","0.1"],["sell","353.00","1.5361"],["sell","355.00","26.175753"],["sell","360.0866","0.956248"],["sell","368.69","2000"],["sell","374.99","2"],["sell","396.16","1"],["sell","398.00","1"],["sell","400.00","1.56"],["sell","498.00","1"],["sell","500.00","4000.7"],["sell","555.00","5.25"],["sell","598.00","1"],["sell","600.00","0.25"],["sell","750.00","0.3"],["sell","1000.00","0.4"],["sell","1500.00","0.2"],["sell","2000.00","0.25"],["sell","3000.00","0.1"],["sell","5000.00","5.2"],["sell","10100.00","2.519296"],["sell","10104.00","2.406492"],["sell","10109.00","2.303356"],["sell","10122.50","2.208698"],["sell","10127.50","2.121512"],["sell","10132.50","2.040949"],["sell","10137.50","1.96628"],["sell","13600.2574","3.2"],["sell","989999.00","0.2"]],"trades":[{"type":"trade","symbol":"FILUSD","event_id":45465772272,"timestamp":1624493647920,"price":"58.4388","quantity":"0.000004","side":"buy"},{"type":"trade","symbol":"FILUSD","event_id":45465767248,"timestamp":1624493647042,"price":"58.4388","quantity":"14.2865","side":"buy"},{"type":"trade","symbol":"FILUSD","event_id":45465657165,"timestamp":1624493572700,"price":"58.4072","quantity":"13.3313","side":"buy"},{"type":"trade","symbol":"FILUSD","event_id":45465331101,"timestamp":1624493382997,"price":"58.6427","quantity":"41.085186","side":"buy"},{"type":"trade","symbol":"FILUSD","event_id":45465331099,"timestamp":1624493382997,"price":"58.6336","quantity":"56.135","side":"buy"},{"type":"trade","symbol":"FILUSD","event_id":45465331097,"timestamp":1624493382997,"price":"58.6008","quantity":"13.927228","side":"buy"},{"type":"trade","symbol":"FILUSD","event_id":45465331095,"timestamp":1624493382997,"price":"58.5925","quantity":"56","side":"buy"},{"type":"trade","symbol":"FILUSD","event_id":45465297221,"timestamp":1624493361381,"price":"58.5475","quantity":"27.01056","side":"sell"},{"type":"trade","symbol":"FILUSD","event_id":45465297203,"timestamp":1624493361378,"price":"58.5475","quantity":"33.89029","side":"sell"},{"type":"trade","symbol":"FILUSD","event_id":45465297196,"timestamp":1624493361377,"price":"58.5475","quantity":"27.01056","side":"sell"},{"type":"trade","symbol":"FILUSD","event_id":45465273377,"timestamp":1624493352671,"price":"58.532","quantity":"2.416172","side":"buy"},{"type":"trade","symbol":"FILUSD","event_id":45465273371,"timestamp":1624493352670,"price":"58.532","quantity":"8.372801","side":"buy"},{"type":"trade","symbol":"FILUSD","event_id":45465273369,"timestamp":1624493352670,"price":"58.5029","quantity":"0.000099","side":"buy"},{"type":"trade","symbol":"FILUSD","event_id":45465273206,"timestamp":1624493352639,"price":"58.5029","quantity":"97.8506","side":"buy"},{"type":"trade","symbol":"FILUSD","event_id":45465091390,"timestamp":1624493271108,"price":"58.5331","quantity":"0.000008","side":"buy"},{"type":"trade","symbol":"FILUSD","event_id":45465088354,"timestamp":1624493270663,"price":"58.5331","quantity":"12.31541","side":"buy"},{"type":"trade","symbol":"FILUSD","event_id":45465002345,"timestamp":1624493226345,"price":"58.5218","quantity":"8.372927","side":"buy"},{"type":"trade","symbol":"FILUSD","event_id":45464939733,"timestamp":1624493198924,"price":"58.6901","quantity":"0.000007","side":"buy"},{"type":"trade","symbol":"FILUSD","event_id":45464939401,"timestamp":1624493198803,"price":"58.6901","quantity":"9.87521","side":"buy"},{"type":"trade","symbol":"FILUSD","event_id":45464920599,"timestamp":1624493194599,"price":"58.6105","quantity":"0.000001","side":"buy"},{"type":"trade","symbol":"FILUSD","event_id":45464920591,"timestamp":1624493194598,"price":"58.6105","quantity":"4.81994","side":"buy"},{"type":"trade","symbol":"FILUSD","event_id":45464920580,"timestamp":1624493194598,"price":"58.6105","quantity":"10.44496","side":"buy"},{"type":"trade","symbol":"FILUSD","event_id":45464876093,"timestamp":1624493174128,"price":"58.5546","quantity":"13.58296","side":"buy"},{"type":"trade","symbol":"FILUSD","event_id":45464823183,"timestamp":1624493145982,"price":"58.4448","quantity":"83.3","side":"buy"},{"type":"trade","symbol":"FILUSD","event_id":45464791727,"timestamp":1624493134131,"price":"58.6758","quantity":"0.000008","side":"sell"},{"type":"trade","symbol":"FILUSD","event_id":45464786202,"timestamp":1624493131153,"price":"58.6758","quantity":"0.17042","side":"sell"},{"type":"trade","symbol":"FILUSD","event_id":45464686661,"timestamp":1624493077478,"price":"58.7818","quantity":"11.4065","side":"buy"},{"type":"trade","symbol":"FILUSD","event_id":45464604856,"timestamp":1624493034011,"price":"58.6758","quantity":"76.89633","side":"buy"},{"type":"trade","symbol":"FILUSD","event_id":45464550038,"timestamp":1624493006953,"price":"58.8619","quantity":"51.481166","side":"sell"},{"type":"trade","symbol":"FILUSD","event_id":45464550036,"timestamp":1624493006953,"price":"58.865","quantity":"254.356622","side":"sell"},{"type":"trade","symbol":"FILUSD","event_id":45464550034,"timestamp":1624493006953,"price":"58.8758","quantity":"0.000012","side":"sell"},{"type":"trade","symbol":"FILUSD","event_id":45464549948,"timestamp":1624493006938,"price":"58.8758","quantity":"169.6689","side":"sell"},{"type":"trade","symbol":"FILUSD","event_id":45464485833,"timestamp":1624492976052,"price":"58.9695","quantity":"0.000078","side":"sell"},{"type":"trade","symbol":"FILUSD","event_id":45464484374,"timestamp":1624492975772,"price":"58.9695","quantity":"25.4368","side":"sell"},{"type":"trade","symbol":"FILUSD","event_id":45464470907,"timestamp":1624492972199,"price":"59.0097","quantity":"88.0266","side":"buy"},{"type":"trade","symbol":"FILUSD","event_id":45464448351,"timestamp":1624492961830,"price":"59.1082","quantity":"77.570786","side":"sell"},{"type":"trade","symbol":"FILUSD","event_id":45464443807,"timestamp":1624492960611,"price":"59.1345","quantity":"118.9374","side":"sell"},{"type":"trade","symbol":"FILUSD","event_id":45464443790,"timestamp":1624492960610,"price":"59.1345","quantity":"50","side":"sell"},{"type":"trade","symbol":"FILUSD","event_id":45464393441,"timestamp":1624492940660,"price":"59.1154","quantity":"9","side":"sell"},{"type":"trade","symbol":"FILUSD","event_id":45464365366,"timestamp":1624492930205,"price":"59.2754","quantity":"0.000009","side":"buy"},{"type":"trade","symbol":"FILUSD","event_id":45464363975,"timestamp":1624492930023,"price":"59.2754","quantity":"11.09965","side":"buy"},{"type":"trade","symbol":"FILUSD","event_id":45464310730,"timestamp":1624492910818,"price":"59.1845","quantity":"10.24134","side":"buy"},{"type":"trade","symbol":"FILUSD","event_id":45464239394,"timestamp":1624492895268,"price":"58.9794","quantity":"9.84492","side":"buy"},{"type":"trade","symbol":"FILUSD","event_id":45464183673,"timestamp":1624492883834,"price":"58.9695","quantity":"169.7691","side":"buy"},{"type":"trade","symbol":"FILUSD","event_id":45464183671,"timestamp":1624492883834,"price":"58.9694","quantity":"9","side":"buy"},{"type":"trade","symbol":"FILUSD","event_id":45464183669,"timestamp":1624492883834,"price":"58.9693","quantity":"13.9","side":"buy"},{"type":"trade","symbol":"FILUSD","event_id":45464171664,"timestamp":1624492881660,"price":"58.9363","quantity":"0.812514","side":"buy"},{"type":"trade","symbol":"FILUSD","event_id":45464150730,"timestamp":1624492876824,"price":"58.7887","quantity":"0.000052","side":"buy"},{"type":"trade","symbol":"FILUSD","event_id":45464150478,"timestamp":1624492876741,"price":"58.7887","quantity":"12.817","side":"buy"},{"type":"trade","symbol":"FILUSD","event_id":45464136405,"timestamp":1624492873316,"price":"58.7267","quantity":"10.21269","side":"buy"}],"auction_events":[]}
1624493666.7368472: {"type":"l2_updates","symbol":"LINKETH","changes":[["buy","0.0093213","54.210659"],["buy","0.0093212","108.421317"],["buy","0.0093204","189.737304"],["buy","0.0093177","271.053291"],["buy","0.0092698","3"],["buy","0.0092697","100"],["buy","0.0092696","559.277437"],["buy","0.0092441","10"],["buy","0.0092107","8"],["buy","0.0092106","561.786452"],["buy","0.009153","1937.03374"],["buy","0.0090813","1553.551659"],["buy","0.0090759","494.371081"],["buy","0.0090604","1056.490434"],["buy","0.0090113","756.352628"],["buy","0.008","20"],["buy","0.00723","2000"],["buy","0.00444","2000"],["buy","0.00333","2000"],["buy","0.0000311","3000"],["buy","0.0000121","8999"],["buy","0.00001","87"],["buy","0.0000011","98900"],["buy","0.000001","1000"],["buy","0.0000002","490000"],["buy","0.0000001","320398"],["sell","0.0093512","54.189994"],["sell","0.0093532","108.379988"],["sell","0.0093538","189.684255"],["sell","0.0093588","270.94997"],["sell","0.0093837","608.386637"],["sell","0.0094172","105"],["sell","0.009424","3"],["sell","0.0094241","10"],["sell","0.0094388","40"],["sell","0.0094389","585.54724"],["sell","0.0094912","20"],["sell","0.0094913","569.63652"],["sell","0.0095057","83.762301"],["sell","0.0096261","10"],["sell","0.0098299","10"],["sell","0.010997","111.489286"],["sell","0.012075","100"],["sell","0.0125","200"],["sell","0.0135","1"],["sell","0.015","4"],["sell","0.015764","93.485199"],["sell","0.01651","140"],["sell","0.0175","3"],["sell","0.0186906","29.504432"],["sell","0.02","4.4"],["sell","0.0233915","230"],["sell","0.03","120"],["sell","0.0369","120.669"],["sell","0.03978","5"],["sell","0.268","100"],["sell","0.98999","1"],["sell","61899","1"],["sell","90000","1"],["sell","1000000","1.501"]],"trades":[{"type":"trade","symbol":"LINKETH","event_id":45464081674,"timestamp":1624492845764,"price":"0.0093643","quantity":"8.720621","side":"buy"},{"type":"trade","symbol":"LINKETH","event_id":45458431282,"timestamp":1624488165157,"price":"0.0092527","quantity":"7","side":"sell"},{"type":"trade","symbol":"LINKETH","event_id":45445980003,"timestamp":1624479305362,"price":"0.0091597","quantity":"0.211849","side":"buy"},{"type":"trade","symbol":"LINKETH","event_id":45434422398,"timestamp":1624472431961,"price":"0.009094","quantity":"0.927629","side":"sell"},{"type":"trade","symbol":"LINKETH","event_id":45413395806,"timestamp":1624460899715,"price":"0.0093218","quantity":"5.319375","side":"buy"},{"type":"trade","symbol":"LINKETH","event_id":45133809279,"timestamp":1624325058177,"price":"0.0092402","quantity":"0.953322","side":"buy"},{"type":"trade","symbol":"LINKETH","event_id":45134421498,"timestamp":1624325371377,"price":"0.0092278","quantity":"5.296236","side":"buy"},{"type":"trade","symbol":"LINKETH","event_id":45145366766,"timestamp":1624331609422,"price":"0.0092966","quantity":"1.557622","side":"sell"},{"type":"trade","symbol":"LINKETH","event_id":45146494127,"timestamp":1624332328457,"price":"0.0092926","quantity":"5.638219","side":"sell"},{"type":"trade","symbol":"LINKETH","event_id":45153974677,"timestamp":1624337141282,"price":"0.0092669","quantity":"10","side":"sell"},{"type":"trade","symbol":"LINKETH","event_id":45157200747,"timestamp":1624339443950,"price":"0.0092927","quantity":"1.211042","side":"buy"},{"type":"trade","symbol":"LINKETH","event_id":45158754034,"timestamp":1624340386416,"price":"0.0092","quantity":"8.695652","side":"sell"},{"type":"trade","symbol":"LINKETH","event_id":45161768937,"timestamp":1624342400121,"price":"0.009203","quantity":"19.617003","side":"sell"},{"type":"trade","symbol":"LINKETH","event_id":45162917421,"timestamp":1624343109903,"price":"0.009268","quantity":"74.737678","side":"buy"},{"type":"trade","symbol":"LINKETH","event_id":45175094252,"timestamp":1624349963530,"price":"0.0090884","quantity":"55.78334","side":"buy"},{"type":"trade","symbol":"LINKETH","event_id":45183714547,"timestamp":1624354159498,"price":"0.009","quantity":"1","side":"sell"},{"type":"trade","symbol":"LINKETH","event_id":45189580056,"timestamp":1624356792162,"price":"0.0088","quantity":"6.818181","side":"sell"},{"type":"trade","symbol":"LINKETH","event_id":45204715123,"timestamp":1624363305836,"price":"0.00866","quantity":"18","side":"sell"},{"type":"trade","symbol":"LINKETH","event_id":45207018976,"timestamp":1624364077576,"price":"0.0086457","quantity":"63.094885","side":"sell"},{"type":"trade","symbol":"LINKETH","event_id":45207018978,"timestamp":1624364077576,"price":"0.0086444","quantity":"37.368433","side":"sell"},{"type":"trade","symbol":"LINKETH","event_id":45213257719,"timestamp":1624365928969,"price":"0.008771","quantity":"23.363761","side":"sell"},{"type":"trade","symbol":"LINKETH","event_id":45221726438,"timestamp":1624368423769,"price":"0.0088172","quantity":"2","side":"sell"},{"type":"trade","symbol":"LINKETH","event_id":45226170554,"timestamp":1624369911247,"price":"0.0087366","quantity":"4.477727","side":"buy"},{"type":"trade","symbol":"LINKETH","event_id":45227686919,"timestamp":1624370291701,"price":"0.0088203","quantity":"1.119359","side":"buy"},{"type":"trade","symbol":"LINKETH","event_id":45230794627,"timestamp":1624371263952,"price":"0.008818","quantity":"4.169741","side":"buy"},{"type":"trade","symbol":"LINKETH","event_id":45232649286,"timestamp":1624371863250,"price":"0.0088669","quantity":"55.513107","side":"buy"},{"type":"trade","symbol":"LINKETH","event_id":45233520131,"timestamp":1624372134819,"price":"0.0088669","quantity":"9.268133","side":"buy"},{"type":"trade","symbol":"LINKETH","event_id":45239330895,"timestamp":1624374145633,"price":"0.0090004","quantity":"10.199791","side":"buy"},{"type":"trade","symbol":"LINKETH","event_id":45244705159,"timestamp":1624375847518,"price":"0.0090884","quantity":"2.282279","side":"buy"},{"type":"trade","symbol":"LINKETH","event_id":45266467714,"timestamp":1624383805863,"price":"0.0091506","quantity":"11.778369","side":"buy"},{"type":"trade","symbol":"LINKETH","event_id":45270148803,"timestamp":1624385452437,"price":"0.0092086","quantity":"2.451731","side":"buy"},{"type":"trade","symbol":"LINKETH","event_id":45278586169,"timestamp":1624389367003,"price":"0.0090924","quantity":"7.2301","side":"sell"},{"type":"trade","symbol":"LINKETH","event_id":45280352580,"timestamp":1624390177278,"price":"0.0090946","quantity":"41.040886","side":"buy"},{"type":"trade","symbol":"LINKETH","event_id":45299144944,"timestamp":1624401116680,"price":"0.0089818","quantity":"9.270439","side":"buy"},{"type":"trade","symbol":"LINKETH","event_id":45301167356,"timestamp":1624402157073,"price":"0.0089177","quantity":"51","side":"sell"},{"type":"trade","symbol":"LINKETH","event_id":45311666889,"timestamp":1624407042565,"price":"0.0089177","quantity":"8.925604","side":"sell"},{"type":"trade","symbol":"LINKETH","event_id":45315825234,"timestamp":1624408451320,"price":"0.00893","quantity":"46.56215","side":"sell"},{"type":"trade","symbol":"LINKETH","event_id":45326864451,"timestamp":1624411836958,"price":"0.0090729","quantity":"0.362959","side":"sell"},{"type":"trade","symbol":"LINKETH","event_id":45330080633,"timestamp":1624413308154,"price":"0.0090579","quantity":"1.717391","side":"buy"},{"type":"trade","symbol":"LINKETH","event_id":45330217719,"timestamp":1624413386114,"price":"0.0090387","quantity":"1.717391","side":"sell"},{"type":"trade","symbol":"LINKETH","event_id":45333510893,"timestamp":1624414859239,"price":"0.0090946","quantity":"16.914813","side":"buy"},{"type":"trade","symbol":"LINKETH","event_id":45347956226,"timestamp":1624422701542,"price":"0.0091595","quantity":"1.088995","side":"sell"},{"type":"trade","symbol":"LINKETH","event_id":45348906573,"timestamp":1624423363176,"price":"0.0091869","quantity":"0.970053","side":"buy"},{"type":"trade","symbol":"LINKETH","event_id":45349425596,"timestamp":1624423789144,"price":"0.0091693","quantity":"8","side":"sell"},{"type":"trade","symbol":"LINKETH","event_id":45357288598,"timestamp":1624428018819,"price":"0.00938","quantity":"106.609808","side":"sell"},{"type":"trade","symbol":"LINKETH","event_id":45357384388,"timestamp":1624428059105,"price":"0.009351","quantity":"19.025705","side":"buy"},{"type":"trade","symbol":"LINKETH","event_id":45358873343,"timestamp":1624428940598,"price":"0.0093298","quantity":"53.16079","side":"buy"},{"type":"trade","symbol":"LINKETH","event_id":45358873345,"timestamp":1624428940598,"price":"0.0093299","quantity":"0.411929","side":"buy"},{"type":"trade","symbol":"LINKETH","event_id":45358877200,"timestamp":1624428944194,"price":"0.0093298","quantity":"53.16079","side":"buy"},{"type":"trade","symbol":"LINKETH","event_id":45358877202,"timestamp":1624428944194,"price":"0.0093299","quantity":"105.909651","side":"buy"}],"auction_events":[]}
1624493666.73722: {"type":"l2_updates","symbol":"BTCGBP","changes":[["buy","24090.28","0.14859662"],["buy","24085.49","0.14862409"],["buy","24084.23","0.04"],["buy","24080.43","0.29725132"],["buy","24080.38","0.59439258"],["buy","24078.56","1.18858406"],["buy","24073.52","0.91"],["buy","24032.00","0.083"],["buy","24031.99","3.2725"],["buy","23982.04","0.21"],["buy","23943.84","2.049"],["buy","23940.57","0.81715326"],["buy","23864.99","0.21"],["buy","23864.98","1.21744849"],["buy","23835.04","0.835"],["buy","23832.54","0.59483142"],["buy","23728.00","0.00209962"],["buy","23648.52","0.214"],["buy","23399.28","0.04766501"],["buy","23267.97","0.211"],["buy","23200.00","0.01288577"],["buy","23005.03","0.207"],["buy","23000.00","0.00008695"],["buy","22980.00","3"],["buy","22728.52","0.00219195"],["buy","22569.68","0.01"],["buy","22501.00","0.00222212"],["buy","22500.00","0.08866666"],["buy","22459.78","0.00919332"],["buy","22275.46","0.03"],["buy","22013.33","0.000545"],["buy","22011.00","0.00454318"],["buy","22000.00","0.15363636"],["buy","21755.00","0.00229004"],["buy","21550.00","0.00232018"],["buy","21501.00","0.00697641"],["buy","21500.00","0.11627906"],["buy","21480.00","0.00232774"],["buy","21390.26","0.00965346"],["buy","21250.00","0.00235294"],["buy","21050.00","0.00237529"],["buy","21011.00","0.00951882"],["buy","21000.00","0.02595237"],["buy","20800.00","0.00432691"],["buy","20773.00","0.0023983"],["buy","20500.00","0.00131463"],["buy","20400.00","0.00245098"],["buy","20309.65","0.00984753"],["buy","20203.00","0.00494975"],["buy","20111.00","0.00247725"],["buy","20065.00","0.0051373"],["buy","20020.00","0.01"],["buy","20017.00","0.00498925"],["buy","20000.00","0.269124"],["buy","19999.00","0.02493874"],["buy","19900.00","0.00251256"],["buy","19760.00","0.00506072"],["buy","19547.00","0.00253082"],["buy","19500.00","0.00256"],["buy","19400.00","0.0541237"],["buy","19345.00","0.00513052"],["buy","19258.20","0.02077037"],["buy","19252.00","0.00779139"],["buy","19001.00","0.1"],["buy","18900.00","0.0026455"],["buy","18660.00","0.0213612"],["buy","18500.00","0.04309405"],["buy","18400.00","0.00271739"],["buy","18275.00","0.01094391"],["buy","18000.00","0.01388888"],["buy","17981.34","0.1"],["buy","17900.00","0.00279329"],["buy","17500.00","0.0628377"],["buy","17400.00","0.00287356"],["buy","17383.00","0.01150549"],["buy","17330.00","0.0577034"],["buy","16900.00","0.00295857"],["buy","16561.00","0.0150957"],["buy","16400.00","0.00304878"],["buy","16001.00","0.06249609"],["buy","16000.00","0.005"],["buy","15900.00","0.00314465"],["buy","15824.00","0.01579878"],["buy","15400.00","0.00324675"],["buy","15206.00","0.01972905"],["buy","15001.50","0.332"],["buy","15000.00","0.00666"],["buy","14952.34","0.00333058"],["buy","14900.00","0.0033557"],["buy","14600.00","2.64726027"],["buy","14400.00","0.00347222"],["buy","13900.00","0.00359712"],["buy","10000.00","0.035"],["buy","9000.00","1"],["buy","7000.00","0.059"],["buy","2400.00","0.20802083"],["buy","1.11","0.153"],["buy","0.10","348.69999999"],["buy","0.01","89"],["sell","24113.48","0.04"],["sell","24113.49","0.91"],["sell","24124.78","0.14859974"],["sell","24131.33","0.021"],["sell","24131.34","0.14855947"],["sell","24136.16","0.59446885"],["sell","24136.31","0.29717727"],["sell","24144.45","0.062"],["sell","24159.16","1.18792559"],["sell","24167.26","0.21"],["sell","24167.27","3.2725"],["sell","24212.19","1.04452579"],["sell","24279.93","2.045"],["sell","24305.27","0.836"],["sell","24500.00","0.00008205"],["sell","24761.90","0.0087547"],["sell","25000.00","0.21090909"],["sell","26000.00","0.07277257"],["sell","26500.00","0.02114406"],["sell","26775.00","0.00937442"],["sell","27300.00","0.00769231"],["sell","28050.00","0.01789662"],["sell","28500.00","0.92387999"],["sell","29325.00","0.02567775"],["sell","30001.00","0.0198032"],["sell","30023.01","0.00337182"],["sell","30323.24","0.00335643"],["sell","30600.00","0.03281046"],["sell","30626.47","0.0033067"],["sell","30700.00","0.5"],["sell","30932.73","0.00327266"],["sell","31237.36","0.2"],["sell","31242.06","0.00325642"],["sell","31554.48","0.00322418"],["sell","31870.02","0.00319226"],["sell","32188.72","0.00065045"],["sell","32510.61","0.0006437"],["sell","32835.72","0.00063672"],["sell","33100.00","0.00302115"],["sell","33164.08","0.00063041"],["sell","33495.72","0.00062387"],["sell","33830.68","0.00061769"],["sell","33900.00","0.0037003"],["sell","34168.99","0.00061158"],["sell","34510.68","0.00060552"],["sell","34855.79","0.00059952"],["sell","35204.35","0.00059359"],["sell","35911.95","0.00058161"],["sell","36000.00","0.00108017"],["sell","36271.07","0.00057557"],["sell","36633.78","0.00056988"],["sell","36777.00","0.00001"],["sell","36900.00","0.00584666"],["sell","37000.00","0.00086414"],["sell","37370.12","0.00055811"],["sell","37743.82","0.00055258"],["sell","37773.00","0.00001"],["sell","38000.00","0.00138262"],["sell","38121.26","0.00054525"],["sell","38255.42","0.1"],["sell","38500.00","0.003"],["sell","38502.47","0.00054169"],["sell","38777.00","0.00001"],["sell","38887.49","0.00053633"],["sell","39000.00","0.00082128"],["sell","39050.00","0.00194889"],["sell","39276.36","0.00053102"],["sell","39669.12","0.00052551"],["sell","39777.00","0.00001"],["sell","40000.00","0.00049605"],["sell","40065.81","0.00052056"],["sell","40466.47","0.00051515"],["sell","40777.00","0.00001"],["sell","40871.13","0.00051005"],["sell","41000.00","0.04353161"],["sell","41261.70","0.05"],["sell","41279.84","0.00050476"],["sell","41567.02","0.05"],["sell","41692.64","0.00049928"],["sell","41777.00","0.00001"],["sell","41915.95","0.05"],["sell","42000.00","0.31159349"],["sell","42109.57","0.00049433"],["sell","42308.51","0.0525"],["sell","42469.00","0.3"],["sell","42530.67","0.00048944"],["sell","42744.68","0.055176"],["sell","42777.00","0.00001"],["sell","42800.00","0.00046729"],["sell","42955.98","0.00024641"],["sell","43000.00","0.00279071"],["sell","43268.08","0.058"],["sell","43385.54","0.00024397"],["sell","43777.00","0.00001"],["sell","43819.40","0.00024156"],["sell","43835.10","0.060832"],["sell","44000.00","0.00227273"],["sell","44257.59","0.00023916"],["sell","44445.74","0.061"],["sell","44700.17","0.0002368"],["sell","45000.00","1.829"],["sell","45100.00","0.06302711"],["sell","45147.17","0.00023445"],["sell","45598.64","0.00023213"],["sell","45777.00","0.00001"],["sell","46054.63","0.00045966"],["sell","46515.18","0.00045512"],["sell","46705.05","0.00107054"],["sell","47500.00","0.0931857"],["sell","47700.00","0.02096437"],["sell","47774.00","0.00001"],["sell","48000.00","0.05922309"],["sell","49000.00","0.0284082"],["sell","49566.14","0.01582643"],["sell","49777.00","0.00001"],["sell","50000.00","0.03021855"],["sell","51000.00","0.019608"],["sell","51777.00","0.00001"],["sell","52000.00","0.60660302"],["sell","52774.44","0.0001"],["sell","53000.00","0.025868"],["sell","53777.00","0.00001"],["sell","55777.00","0.00001"],["sell","57000.00","0.023544"],["sell","57775.00","0.00001"],["sell","59777.00","0.00001"],["sell","59793.69","0.0001"],["sell","59894.74","0.00009"],["sell","60000.00","0.0166667"],["sell","60065.81","0.00011"],["sell","60186.90","0.00011"],["sell","60376.35","0.000044"],["sell","61777.00","0.00001"],["sell","62436.87","0.00022"],["sell","63000.00","0.0208731"],["sell","63777.00","0.00001"],["sell","65000.00","0.0153847"],["sell","65777.00","0.00001"],["sell","67776.00","0.00001"],["sell","69000.00","0.004"],["sell","69696.00","0.01"],["sell","69777.00","0.00001"],["sell","70000.00","0.003"],["sell","71717.00","0.00001"],["sell","75000.00","0.005"],["sell","79797.00","0.00001"],["sell","88300.00","0.02723063"],["sell","98500.00","0.02"]],"trades":[{"type":"trade","symbol":"BTCGBP","event_id":45465309641,"timestamp":1624493368377,"price":"24046.83","quantity":"0.00001","side":"buy"},{"type":"trade","symbol":"BTCGBP","event_id":45465256456,"timestamp":1624493344395,"price":"24032.46","quantity":"0.00020906","side":"buy"},{"type":"trade","symbol":"BTCGBP","event_id":45464789491,"timestamp":1624493133858,"price":"24022.15","quantity":"0.1488616","side":"sell"},{"type":"trade","symbol":"BTCGBP","event_id":45464789489,"timestamp":1624493133858,"price":"24026.35","quantity":"0.0000384","side":"sell"},{"type":"trade","symbol":"BTCGBP","event_id":45464789458,"timestamp":1624493133855,"price":"24026.35","quantity":"0.1489","side":"sell"},{"type":"trade","symbol":"BTCGBP","event_id":45464752635,"timestamp":1624493113189,"price":"24074.76","quantity":"0.00001","side":"buy"},{"type":"trade","symbol":"BTCGBP","event_id":45464235821,"timestamp":1624492894619,"price":"24190.96","quantity":"0.91","side":"buy"},{"type":"trade","symbol":"BTCGBP","event_id":45464235819,"timestamp":1624492894619,"price":"24190.95","quantity":"0.04","side":"buy"},{"type":"trade","symbol":"BTCGBP","event_id":45464185869,"timestamp":1624492884099,"price":"24246.37","quantity":"0.14787373","side":"buy"},{"type":"trade","symbol":"BTCGBP","event_id":45464184597,"timestamp":1624492883948,"price":"24229.93","quantity":"0.021","side":"buy"},{"type":"trade","symbol":"BTCGBP","event_id":45464184595,"timestamp":1624492883948,"price":"24229.93","quantity":"0.062","side":"buy"},{"type":"trade","symbol":"BTCGBP","event_id":45464181105,"timestamp":1624492883473,"price":"24222.39","quantity":"0.59212167","side":"buy"},{"type":"trade","symbol":"BTCGBP","event_id":45464181103,"timestamp":1624492883473,"price":"24220.85","quantity":"0.00007833","side":"buy"},{"type":"trade","symbol":"BTCGBP","event_id":45464181096,"timestamp":1624492883472,"price":"24220.85","quantity":"0.03992167","side":"buy"},{"type":"trade","symbol":"BTCGBP","event_id":45464181094,"timestamp":1624492883472,"price":"24218.66","quantity":"0.00007833","side":"buy"},{"type":"trade","symbol":"BTCGBP","event_id":45464180987,"timestamp":1624492883465,"price":"24218.66","quantity":"0.14794609","side":"buy"},{"type":"trade","symbol":"BTCGBP","event_id":45464180985,"timestamp":1624492883465,"price":"24215.39","quantity":"0.00005391","side":"buy"},{"type":"trade","symbol":"BTCGBP","event_id":45464180809,"timestamp":1624492883459,"price":"24215.00","quantity":"0.04","side":"buy"},{"type":"trade","symbol":"BTCGBP","event_id":45464180721,"timestamp":1624492883456,"price":"24215.39","quantity":"0.06194609","side":"buy"},{"type":"trade","symbol":"BTCGBP","event_id":45464180719,"timestamp":1624492883456,"price":"24212.58","quantity":"0.00005391","side":"buy"},{"type":"trade","symbol":"BTCGBP","event_id":45464180659,"timestamp":1624492883452,"price":"24212.58","quantity":"0.148","side":"buy"},{"type":"trade","symbol":"BTCGBP","event_id":45464180657,"timestamp":1624492883452,"price":"24212.57","quantity":"0.021","side":"buy"},{"type":"trade","symbol":"BTCGBP","event_id":45463798143,"timestamp":1624492616743,"price":"24096.33","quantity":"0.00001","side":"buy"},{"type":"trade","symbol":"BTCGBP","event_id":45463676827,"timestamp":1624492507298,"price":"24123.58","quantity":"0.00001","side":"buy"},{"type":"trade","symbol":"BTCGBP","event_id":45462899221,"timestamp":1624491907538,"price":"24129.27","quantity":"0.00001","side":"buy"},{"type":"trade","symbol":"BTCGBP","event_id":45462679372,"timestamp":1624491755145,"price":"24130.68","quantity":"0.00295282","side":"buy"},{"type":"trade","symbol":"BTCGBP","event_id":45462460260,"timestamp":1624491607136,"price":"24127.66","quantity":"0.00001","side":"buy"},{"type":"trade","symbol":"BTCGBP","event_id":45462456764,"timestamp":1624491605942,"price":"24126.15","quantity":"0.04","side":"buy"},{"type":"trade","symbol":"BTCGBP","event_id":45462451063,"timestamp":1624491604961,"price":"24135.13","quantity":"0.14828587","side":"sell"},{"type":"trade","symbol":"BTCGBP","event_id":45462451061,"timestamp":1624491604961,"price":"24138.10","quantity":"0.14831684","side":"sell"},{"type":"trade","symbol":"BTCGBP","event_id":45461887939,"timestamp":1624491217148,"price":"24079.11","quantity":"0.00001","side":"buy"},{"type":"trade","symbol":"BTCGBP","event_id":45460941609,"timestamp":1624490514636,"price":"23946.92","quantity":"0.00001","side":"buy"},{"type":"trade","symbol":"BTCGBP","event_id":45460491289,"timestamp":1624490111114,"price":"23883.88","quantity":"0.00001","side":"buy"},{"type":"trade","symbol":"BTCGBP","event_id":45460104274,"timestamp":1624489821542,"price":"23897.77","quantity":"0.00001","side":"buy"},{"type":"trade","symbol":"BTCGBP","event_id":45459569241,"timestamp":1624489296138,"price":"23935.36","quantity":"0.0019","side":"sell"},{"type":"trade","symbol":"BTCGBP","event_id":45459467366,"timestamp":1624489149727,"price":"23985.35","quantity":"0.00001","side":"buy"},{"type":"trade","symbol":"BTCGBP","event_id":45459338805,"timestamp":1624489013675,"price":"23959.63","quantity":"0.02045371","side":"buy"},{"type":"trade","symbol":"BTCGBP","event_id":45459010183,"timestamp":1624488623905,"price":"23955.68","quantity":"0.00410168","side":"buy"},{"type":"trade","symbol":"BTCGBP","event_id":45459002878,"timestamp":1624488613810,"price":"23955.68","quantity":"0.00001","side":"buy"},{"type":"trade","symbol":"BTCGBP","event_id":45458888123,"timestamp":1624488483339,"price":"23970.15","quantity":"0.0149920461","side":"buy"},{"type":"trade","symbol":"BTCGBP","event_id":45458825550,"timestamp":1624488435881,"price":"23955.88","quantity":"0.00001","side":"buy"},{"type":"trade","symbol":"BTCGBP","event_id":45458782376,"timestamp":1624488406975,"price":"24007.91","quantity":"0.2431855759","side":"buy"},{"type":"trade","symbol":"BTCGBP","event_id":45458782374,"timestamp":1624488406975,"price":"23997.29","quantity":"1.19525132","side":"buy"},{"type":"trade","symbol":"BTCGBP","event_id":45458782372,"timestamp":1624488406975,"price":"23991.77","quantity":"0.29874933","side":"buy"},{"type":"trade","symbol":"BTCGBP","event_id":45458782370,"timestamp":1624488406975,"price":"23986.70","quantity":"0.1493763","side":"buy"},{"type":"trade","symbol":"BTCGBP","event_id":45458782368,"timestamp":1624488406975,"price":"23985.93","quantity":"0.91","side":"buy"},{"type":"trade","symbol":"BTCGBP","event_id":45458782366,"timestamp":1624488406975,"price":"23981.25","quantity":"0.14939639","side":"buy"},{"type":"trade","symbol":"BTCGBP","event_id":45458782364,"timestamp":1624488406975,"price":"23981.24","quantity":"0.04","side":"buy"},{"type":"trade","symbol":"BTCGBP","event_id":45458485127,"timestamp":1624488182574,"price":"24016.73","quantity":"0.91","side":"buy"},{"type":"trade","symbol":"BTCGBP","event_id":45458485125,"timestamp":1624488182574,"price":"24016.72","quantity":"0.04","side":"buy"}],"auction_events":[]}
1624493666.738247: {"type":"l2_updates","symbol":"ALCXUSD","changes":[["buy","301.66","11.538318"],["buy","302.16","3.296522"],["buy","301.96","0"],["buy","302.33","0"],["sell","303.55","0"],["sell","303.83","11.537827"],["sell","304.12","0"],["sell","303.39","3.296031"]]}
1624493666.863235: {"type":"l2_updates","symbol":"BTCGBP","changes":[["buy","24084.23","0"],["buy","24087.07","0.04"],["sell","24113.49","0"],["sell","24117.80","0.91"]]}
1624493666.865487: {"type":"l2_updates","symbol":"GRTUSD","changes":[["buy","0.6157","0"]]}
1624493666.865559: {"type":"heartbeat","timestamp":1624493666869}
1624493666.962976: {"type":"l2_updates","symbol":"GRTUSD","changes":[["buy","0.6146","179.98"],["buy","0.6116","0"],["buy","0.6096","14060"]]}
1624493667.06435: {"type":"l2_updates","symbol":"FILUSD","changes":[["buy","58.4033","84.272973"]]}
1624493667.161867: {"type":"l2_updates","symbol":"FILUSD","changes":[["sell","58.4969","0"],["sell","58.4863","79.844211"],["sell","58.4834","56"]]}
1624493667.162029: {"type":"l2_updates","symbol":"ANKRUSD","changes":[["buy","0.07913","0"]]}
1624493667.2665632: {"type":"l2_updates","symbol":"ANKRUSD","changes":[["buy","0.07919","25187.616024"],["sell","0.07958","25191.555468"],["sell","0.07954","12595.777734"]]}
1624493667.462656: {"type":"l2_updates","symbol":"BTCGBP","changes":[["buy","24083.96","0.04"],["buy","24087.07","0"]]}
1624493667.764352: {"type":"l2_updates","symbol":"ETHEUR","changes":[["buy","1647.74","1.844"],["sell","1657.29","0"]]}
1624493667.764451: {"type":"l2_updates","symbol":"BATBTC","changes":[["buy","0.0000158","1422.511906"]]}
1624493667.8640552: {"type":"l2_updates","symbol":"ETHEUR","changes":[["sell","1656.60","2.531993"]]}
1624493667.9649081: {"type":"l2_updates","symbol":"FILUSD","changes":[["buy","58.3421","0"],["buy","58.3251","0"],["buy","58.3447","62.09"],["buy","58.3277","44.963"],["sell","58.5042","43.425"],["sell","58.509","0"],["sell","58.5212","56.574"],["sell","58.492","0"]]}
1624493667.965146: {"type":"l2_updates","symbol":"ANKRUSD","changes":[["buy","0.07911","44073.626128"],["buy","0.07904","0"]]}
1624493668.065862: {"type":"l2_updates","symbol":"FILUSD","changes":[["sell","58.8334","134.3"],["sell","58.5871","0"]]}
1624493668.067123: {"type":"l2_updates","symbol":"ALCXUSD","changes":[["sell","304.81","0"]]}
1624493668.067173: {"type":"l2_updates","symbol":"ANKRUSD","changes":[["buy","0.07921","0"]]}
1624493668.1684039: {"type":"l2_updates","symbol":"ALCXUSD","changes":[["sell","304.10","16.484948"]]}
1624493668.1685271: {"type":"l2_updates","symbol":"ANKRUSD","changes":[["buy","0.0793","249"]]}
1624493668.265762: {"type":"l2_updates","symbol":"GRTUSD","changes":[["sell","0.6165","0"]]}
1624493668.464703: {"type":"l2_updates","symbol":"FILUSD","changes":[["buy","58.3107","42.205"],["buy","58.3447","0"],["buy","58.4033","0"],["sell","58.8334","0"],["sell","58.5212","0"],["sell","58.4872","40.879"]]}
1624493668.4648478: {"type":"l2_updates","symbol":"GRTUSD","changes":[["sell","0.6199","0"],["sell","0.6182","8118.186973"]]}
1624493668.564574: {"type":"l2_updates","symbol":"FILUSD","changes":[["sell","58.5429","0"],["sell","58.5922","134.3"],["sell","58.4864","0"],["sell","58.4863","0"]]}
1624493668.666909: {"type":"l2_updates","symbol":"BATBTC","changes":[["buy","0.0000158","1422.511906"]]}
1624493668.6669838: {"type":"l2_updates","symbol":"FILUSD","changes":[["sell","58.547","0"]]}
1624493668.764269: {"type":"l2_updates","symbol":"FILUSD","changes":[["buy","58.0285","0"],["buy","58.339","0"],["buy","58.3108","13.9"],["sell","58.5183","13"],["sell","58.4937","213.902655"],["sell","58.5357","219.792491"]]}
1624493668.96457: {"type":"l2_updates","symbol":"ANKRUSD","changes":[["buy","0.07888","0"],["buy","0.07925","12590.326304"],["buy","0.07907","62932.146947"],["sell","0.07972","44052.502863"],["sell","0.07958","0"],["sell","0.07968","0"],["sell","0.07954","0"],["sell","0.0796","12586.42939"],["sell","0.07988","62932.146947"],["sell","0.07963","25174.290962"]]}
1624493669.065815: {"type":"l2_updates","symbol":"GRTUSD","changes":[["buy","0.609","0"]]}
1624493669.06594: {"type":"l2_updates","symbol":"ANKRUSD","changes":[["buy","0.07919","0"]]}
1624493669.4635231: {"type":"l2_updates","symbol":"BATBTC","changes":[["buy","0.00001581","1422.511906"],["buy","0.0000158","0"]]}
1624493669.6644092: {"type":"l2_updates","symbol":"FILUSD","changes":[["buy","58.0285","13.9"],["buy","58.3108","0"]]}
1624493669.8649411: {"type":"l2_updates","symbol":"BATBTC","changes":[["buy","0.00001581","0"]]}
1624493669.963806: {"type":"l2_updates","symbol":"FILUSD","changes":[["buy","58.3107","0"],["buy","58.3447","59.631"],["sell","58.5212","59.144"],["sell","58.4872","0"]]}
1624493670.0660548: {"type":"l2_updates","symbol":"FILUSD","changes":[["buy","58.3963","84.272973"],["buy","58.3992","56"],["sell","58.5357","0"]]}
1624493670.165646: {"type":"l2_updates","symbol":"FILUSD","changes":[["buy","58.339","13"],["sell","58.4792","79.844211"]]}
1624493670.2636669: {"type":"l2_updates","symbol":"FILUSD","changes":[["sell","58.4763","56"]]}
1624493670.263802: {"type":"l2_updates","symbol":"ANKRUSD","changes":[["buy","0.07929","26883.487111"]]}
1624493670.3640928: {"type":"l2_updates","symbol":"FILUSD","changes":[["sell","58.5183","0"]]}
1624493670.4626079: {"type":"l2_updates","symbol":"ANKRUSD","changes":[["buy","0.07911","0"]]}
1624493670.563751: {"type":"l2_updates","symbol":"GRTUSD","changes":[["buy","0.6155","1491.068077"]]}
1624493670.563879: {"type":"l2_updates","symbol":"ANKRUSD","changes":[["buy","0.0793","498"]]}
1624493670.664358: {"type":"l2_updates","symbol":"BATBTC","changes":[["buy","0.0000158","1422.511906"]]}
1624493670.664452: {"type":"l2_updates","symbol":"FILUSD","changes":[["sell","58.5183","13"]]}
1624493670.664494: {"type":"l2_updates","symbol":"GRTUSD","changes":[["buy","0.609","140199.635016"],["sell","0.6164","1258.835256"]]}
1624493670.6645381: {"type":"l2_updates","symbol":"ANKRUSD","changes":[["buy","0.07929","14300"],["buy","0.07918","44036.215976"],["buy","0.07933","12577.671207"],["sell","0.07969","25154.403699"],["sell","0.07965","12577.671207"],["sell","0.0796","0"],["sell","0.07963","0"]]}
1624493670.760541: {"type":"trade","symbol":"ANKRUSD","event_id":45465818387,"timestamp":1624493670759,"price":"0.07946","quantity":"1020.482111","side":"buy"}
1624493670.764488: {"type":"l2_updates","symbol":"FILUSD","changes":[["buy","58.3107","46.501"],["buy","58.3447","0"],["sell","58.5212","0"],["sell","58.4872","48.617"]]}
1624493670.764608: {"type":"l2_updates","symbol":"ANKRUSD","changes":[["buy","0.07929","0"],["buy","0.0793","249"],["buy","0.07925","0"],["buy","0.07918","0"],["buy","0.07897","0"],["buy","0.07934","249"],["buy","0.07938","14300"],["sell","0.07978","0"],["sell","0.07972","0"],["sell","0.07981","0"],["sell","0.0799","64350"],["sell","0.07966","14300"],["sell","0.07969","0"],["sell","0.07965","0"],["sell","0.07957","0"],["sell","0.07946","0"]]}
1624493670.862922: {"type":"l2_updates","symbol":"BTCGBP","changes":[["sell","24118.18","0.14862575"],["sell","24131.34","0"]]}
1624493670.864026: {"type":"l2_updates","symbol":"FILUSD","changes":[["buy","58.339","0"]]}
1624493670.864131: {"type":"l2_updates","symbol":"ANKRUSD","changes":[["buy","0.07934","0"]]}
1624493670.964138: {"type":"l2_updates","symbol":"FILUSD","changes":[["buy","58.3841","0"]]}
1624493670.9658082: {"type":"l2_updates","symbol":"ANKRUSD","changes":[["buy","0.07939","249"]]}
1624493671.063637: {"type":"l2_updates","symbol":"BTCGBP","changes":[["buy","24073.52","0"],["buy","24083.96","0"],["buy","24069.92","0.91"],["buy","24080.76","0.04"],["sell","24113.48","0"],["sell","24131.33","0"],["sell","24118.17","0.021"],["sell","24111.96","0.91"],["sell","24117.80","0"]]}
1624493671.0665119: {"type":"l2_updates","symbol":"FILUSD","changes":[["buy","58.3547","213.918668"]]}
1624493671.066564: {"type":"l2_updates","symbol":"ANKRUSD","changes":[["buy","0.07917","62855.672316"],["buy","0.07925","43998.970621"],["buy","0.07941","12562.541503"],["sell","0.07976","12562.541503"],["sell","0.07998","62848.011895"],["sell","0.07981","43998.970621"],["sell","0.07974","0"]]}
1624493671.1634939: {"type":"l2_updates","symbol":"BTCGBP","changes":[["sell","24111.95","0.04"]]}
1624493671.163615: {"type":"l2_updates","symbol":"ETHEUR","changes":[["buy","1648.00","11.826251"]]}
1624493671.1636732: {"type":"l2_updates","symbol":"ZECLTC","changes":[["sell","0.887","0"]]}
1624493671.165635: {"type":"l2_updates","symbol":"ANKRUSD","changes":[["buy","0.07925","0"],["buy","0.07939","0"],["buy","0.07933","0"],["sell","0.07981","0"],["sell","0.07988","0"]]}
1624493671.2659578: {"type":"l2_updates","symbol":"ANKRUSD","changes":[["buy","0.07907","0"],["buy","0.07942","249"],["sell","0.07976","0"]]}
1624493671.363662: {"type":"l2_updates","symbol":"ETHEUR","changes":[["buy","1644.63","0"]]}
1624493671.463938: {"type":"l2_updates","symbol":"ZECLTC","changes":[["sell","0.897","6.97498"]]}
1624493671.563943: {"type":"l2_updates","symbol":"ZECLTC","changes":[["sell","0.886","0"]]}
1624493671.5640361: {"type":"l2_updates","symbol":"FILUSD","changes":[["buy","58.3963","0"],["buy","58.387","0"],["sell","58.4792","0"],["sell","58.4834","0"]]}
1624493671.762271: {"type":"l2_updates","symbol":"FILUSD","changes":[["buy","58.0285","0"],["buy","58.3108","13.9"]]}
1624493671.864094: {"type":"l2_updates","symbol":"BATBTC","changes":[["buy","0.00001581","1422.511906"]]}
1624493671.8641841: {"type":"l2_updates","symbol":"ANKRUSD","changes":[["buy","0.0793","0"],["buy","0.07942","498"]]}
1624493671.864237: {"type":"heartbeat","timestamp":1624493671867}
1624493671.963999: {"type":"l2_updates","symbol":"BATBTC","changes":[["buy","0.0000158","0"]]}
1624493671.964085: {"type":"l2_updates","symbol":"GRTUSD","changes":[["sell","0.6164","0"]]}
1624493672.0631151: {"type":"l2_updates","symbol":"ALCXUSD","changes":[["buy","302.15","0"],["buy","301.92","6.594909"]]}
1624493672.264562: {"type":"l2_updates","symbol":"ANKRUSD","changes":[["buy","0.07928","62760.08579"],["buy","0.07942","249"],["buy","0.07946","12554.828718"],["buy","0.07933","43941.900511"],["sell","0.07993","43941.900511"],["sell","0.07982","12552.017158"],["sell","0.08008","62774.143587"],["sell","0.07986","25106.275423"]]}
1624493672.46309: {"type":"l2_updates","symbol":"FILUSD","changes":[["sell","58.5183","0"]]}
1624493672.662907: {"type":"l2_updates","symbol":"BTCGBP","changes":[["buy","24080.76","0"],["buy","24084.28","0.04"]]}
1624493672.6683562: {"type":"l2_updates","symbol":"ZECLTC","changes":[["sell","0.897","13.94996"]]}
1624493672.6684318: {"type":"l2_updates","symbol":"FILUSD","changes":[["sell","58.5183","13"]]}
1624493672.6684768: {"type":"l2_updates","symbol":"ANKRUSD","changes":[["buy","0.07848","0"],["buy","0.07947","249"],["sell","0.08","0"]]}
1624493672.7656572: {"type":"l2_updates","symbol":"BTCGBP","changes":[["buy","24076.85","0.91"],["buy","24069.92","0"],["buy","24087.69","0"],["buy","24084.28","0"],["sell","24118.37","0.91"],["sell","24111.96","0"]]}
1624493672.7666812: {"type":"l2_updates","symbol":"ETHEUR","changes":[["sell","1656.75","0"]]}
1624493672.8627682: {"type":"l2_updates","symbol":"BTCGBP","changes":[["buy","24076.85","0"],["buy","24090.29","0.04"],["sell","24118.18","0"],["sell","24118.17","0"],["sell","24118.37","0"]]}
1624493672.86597: {"type":"l2_updates","symbol":"FILUSD","changes":[["sell","58.5732","40.8"],["sell","58.5184","0"]]}
1624493672.96285: {"type":"l2_updates","symbol":"BTCGBP","changes":[["buy","24083.33","0.91"],["buy","24085.49","0"],["sell","24129.52","0.14858635"],["sell","24125.08","0.91"],["sell","24136.15","0.021"]]}
1624493672.963031: {"type":"l2_updates","symbol":"ETHEUR","changes":[["sell","1656.58","1.262"]]}
1624493672.964735: {"type":"l2_updates","symbol":"FILUSD","changes":[["buy","58.3107","0"],["buy","58.3447","63.565"]]}
1624493672.967812: {"type":"l2_updates","symbol":"ANKRUSD","changes":[["buy","0.07946","0"]]}
1624493673.065828: {"type":"l2_updates","symbol":"BATBTC","changes":[["buy","0.0000158","1422.511906"]]}
1624493673.065959: {"type":"l2_updates","symbol":"FILUSD","changes":[["buy","58.339","13"],["buy","58.4133","84.272973"],["buy","58.4162","56"],["sell","58.4968","0"],["sell","58.4963","93.347032"],["sell","58.5922","0"],["sell","58.8334","134.3"],["sell","58.5212","64.672"],["sell","58.4872","0"]]}
1624493673.0703208: {"type":"l2_updates","symbol":"ANKRUSD","changes":[["buy","0.0795","12547.803745"]]}
1624493673.163135: {"type":"l2_updates","symbol":"BTCGBP","changes":[["sell","24144.45","0"],["sell","24167.26","0"],["sell","24159.15","0.062"]]}
1624493673.167163: {"type":"l2_updates","symbol":"BATBTC","changes":[["buy","0.00001581","0"]]}
1624493673.167229: {"type":"l2_updates","symbol":"FILUSD","changes":[["sell","58.5731","13.9"]]}
1624493673.1687748: {"type":"l2_updates","symbol":"ANKRUSD","changes":[["buy","0.07947","0"]]}
1624493673.263194: {"type":"l2_updates","symbol":"BTCGBP","changes":[["sell","24212.18","0.21"]]}
1624493673.266159: {"type":"l2_updates","symbol":"GRTUSD","changes":[["sell","0.6163","1258.835256"]]}
1624493673.365238: {"type":"l2_updates","symbol":"ANKRUSD","changes":[["buy","0.07938","0"],["sell","0.07981","249"],["sell","0.07966","0"]]}
1624493673.463725: {"type":"l2_updates","symbol":"BTCGBP","changes":[["sell","24111.95","0"],["sell","24117.20","0.04"]]}
1624493673.465183: {"type":"l2_updates","symbol":"ZECLTC","changes":[["sell","0.897","20.92494"]]}
1624493673.4652102: {"type":"l2_updates","symbol":"FILUSD","changes":[["sell","58.5183","0"]]}
1624493673.4672651: {"type":"l2_updates","symbol":"ANKRUSD","changes":[["buy","0.07906","0"],["buy","0.07951","249"],["buy","0.07947","25091.718922"],["buy","0.07941","0"],["sell","0.0799","0"]]}
1624493673.5667682: {"type":"l2_updates","symbol":"ANKRUSD","changes":[["buy","0.07885","275000"],["buy","0.07924","64350"],["sell","0.07981","0"],["sell","0.07999","64350"],["sell","0.08038","169510.5"]]}
1624493673.6663628: {"type":"l2_updates","symbol":"ANKRUSD","changes":[["buy","0.07933","0"],["sell","0.07982","0"],["sell","0.07986","0"]]}
1624493673.765364: {"type":"l2_updates","symbol":"ANKRUSD","changes":[["buy","0.07954","12541.002042"],["buy","0.07942","0"],["buy","0.07941","43898.821974"],["buy","0.0795","0"],["sell","0.07993","0"],["sell","0.07998","0"],["sell","0.0799","249"],["sell","0.07992","25085.041128"],["sell","0.07988","12542.520564"]]}
1624493673.866739: {"type":"l2_updates","symbol":"ANKRUSD","changes":[["buy","0.07951","0"]]}
1624493673.963229: {"type":"l2_updates","symbol":"BTCGBP","changes":[["buy","24083.33","0"],["buy","24089.73","0.91"],["sell","24131.41","0.91"],["sell","24125.08","0"],["sell","24120.56","0.04"],["sell","24124.78","0"],["sell","24117.20","0"]]}
1624493673.965964: {"type":"l2_updates","symbol":"BATBTC","changes":[["buy","0.0000158","0"]]}
1624493673.966052: {"type":"l2_updates","symbol":"FILUSD","changes":[["sell","58.5731","0"],["sell","58.8334","0"],["sell","58.5871","134.3"]]}
1624493673.968042: {"type":"l2_updates","symbol":"ANKRUSD","changes":[["buy","0.07955","249"]]}
1624493674.063215: {"type":"l2_updates","symbol":"BTCGBP","changes":[["buy","24090.28","0"],["buy","24096.65","0.04"],["buy","24096.64","0.14857489"],["buy","24090.29","0"],["sell","24136.07","0.14854438"]]}
1624493674.065535: {"type":"l2_updates","symbol":"FILUSD","changes":[["buy","58.4133","0"],["buy","58.3992","0"],["sell","58.4997","13.9"]]}
1624493674.0683079: {"type":"l2_updates","symbol":"ANKRUSD","changes":[["sell","0.08105","0"]]}
1624493674.1627898: {"type":"l2_updates","symbol":"BTCGBP","changes":[["sell","24136.15","0"],["sell","24159.14","0.021"]]}
1624493674.164675: {"type":"l2_updates","symbol":"FILUSD","changes":[["buy","58.4024","171.029719"],["buy","58.3741","0"],["sell","58.8334","134.3"],["sell","58.5871","0"]]}
1624493674.168284: {"type":"l2_updates","symbol":"ANKRUSD","changes":[["sell","0.08139","313480.020322"],["sell","0.08018","62695.839788"],["sell","0.08002","43887.087852"]]}
1624493674.263626: {"type":"l2_updates","symbol":"BTCGBP","changes":[["buy","24080.43","0"]]}
1624493674.264673: {"type":"l2_updates","symbol":"FILUSD","changes":[["sell","58.4963","0"]]}
1624493674.264748: {"type":"l2_updates","symbol":"GRTUSD","changes":[["buy","0.6146","89.99"],["sell","0.6163","0"]]}
1624493674.463019: {"type":"l2_updates","symbol":"BATBTC","changes":[["buy","0.0000158","1422.511906"]]}
1624493674.46314: {"type":"l2_updates","symbol":"FILUSD","changes":[["sell","58.5593","13"]]}
1624493674.564381: {"type":"l2_updates","symbol":"ETHEUR","changes":[["sell","1656.60","0"],["sell","1656.58","0"]]}
1624493674.6644108: {"type":"l2_updates","symbol":"ETHEUR","changes":[["sell","1657.22","2.530903"],["sell","1656.77","0"]]}
1624493674.664511: {"type":"l2_updates","symbol":"LINKETH","changes":[["buy","0.0092698","0"]]}
1624493674.76354: {"type":"l2_updates","symbol":"BTCGBP","changes":[["sell","24136.16","0"],["sell","24129.52","0"]]}
1624493674.767298: {"type":"l2_updates","symbol":"LINKETH","changes":[["buy","0.0092442","3"],["buy","0.0092697","0"],["buy","0.0092334","100"]]}
1624493674.767381: {"type":"l2_updates","symbol":"FILUSD","changes":[["sell","58.4893","0"]]}
1624493674.864343: {"type":"l2_updates","symbol":"BTCGBP","changes":[["buy","24103.02","0.14853638"],["buy","24096.65","0"],["buy","24094.59","0.29705777"],["sell","24145.81","0.29702855"],["sell","24140.71","0.14851591"],["sell","24123.25","0.04"],["sell","24136.31","0"],["sell","24120.56","0"],["sell","24212.19","0"],["sell","24150.38","0.59406362"]]}
1624493674.866957: {"type":"l2_updates","symbol":"FILUSD","changes":[["buy","58.4243","84.272973"],["buy","58.3617","45.601"],["buy","58.4272","56"],["buy","58.3277","0"],["sell","58.5176","171.017961"],["sell","58.5042","0"],["sell","58.5315","213.764792"],["sell","58.5382","36.771"],["sell","58.8334","0"],["sell","58.4937","0"]]}
1624493674.869015: {"type":"l2_updates","symbol":"GRTUSD","changes":[["buy","0.6155","0"]]}
1624493674.9633012: {"type":"l2_updates","symbol":"BTCGBP","changes":[["buy","24103.03","0.04"],["sell","24140.70","0.021"],["sell","24159.14","0"]]}
1624493674.9656022: {"type":"l2_updates","symbol":"FILUSD","changes":[["buy","58.339","0"],["sell","58.5073","93.347032"],["sell","58.5732","0"],["sell","58.5871","0"],["sell","58.5314","40.8"]]}
1624493674.968989: {"type":"l2_updates","symbol":"GRTUSD","changes":[["buy","0.6146","179.98"]]}
1624493674.9690611: {"type":"l2_updates","symbol":"ANKRUSD","changes":[["buy","0.07776","0"],["buy","0.07808","313408.799569"]]}
1624493675.064262: {"type":"l2_updates","symbol":"BTCGBP","changes":[["sell","24279.92","1.67322107"]]}
1624493675.067571: {"type":"l2_updates","symbol":"FILUSD","changes":[["buy","58.3629","13"],["sell","58.8334","134.3"]]}
1624493675.070953: {"type":"l2_updates","symbol":"ANKRUSD","changes":[["buy","0.07957","14300"],["buy","0.07924","0"],["sell","0.07999","0"],["sell","0.07985","14300"]]}
1624493675.165278: {"type":"l2_updates","symbol":"FILUSD","changes":[["sell","58.8334","0"],["sell","58.5871","134.3"]]}
1624493675.166555: {"type":"l2_updates","symbol":"GRTUSD","changes":[["buy","0.6129","0"]]}
1624493675.167165: {"type":"l2_updates","symbol":"ANKRUSD","changes":[["buy","0.07955","0"]]}
1624493675.263295: {"type":"l2_updates","symbol":"BTCGBP","changes":[["buy","24096.64","0"],["buy","24109.46","0.14850156"]]}
1624493675.2662132: {"type":"l2_updates","symbol":"GRTUSD","changes":[["buy","0.6144","4356.053724"]]}
1624493675.266269: {"type":"l2_updates","symbol":"ANKRUSD","changes":[["sell","0.0799","0"]]}
1624493675.361683: {"type":"l2_updates","symbol":"BATBTC","changes":[["buy","0.00001581","1422.511906"],["buy","0.0000158","0"]]}
1624493675.3618329: {"type":"l2_updates","symbol":"FILUSD","changes":[["buy","58.3547","0"],["buy","58.4069","213.737803"]]}
1624493675.3642812: {"type":"l2_updates","symbol":"ANKRUSD","changes":[["buy","0.07958","249"]]}
1624493675.5672781: {"type":"l2_updates","symbol":"ANKRUSD","changes":[["buy","0.07958","498"]]}
1624493675.665796: {"type":"l2_updates","symbol":"ALCXUSD","changes":[["sell","303.42","6.593938"],["sell","303.63","0"]]}
1624493675.7666519: {"type":"l2_updates","symbol":"GRTUSD","changes":[["buy","0.616","1491.068077"],["sell","0.6168","1258.835256"]]}
1624493675.766737: {"type":"l2_updates","symbol":"ANKRUSD","changes":[["buy","0.07947","0"],["sell","0.07988","0"]]}
1624493675.865877: {"type":"l2_updates","symbol":"ANKRUSD","changes":[["buy","0.07953","25070.482077"],["sell","0.07993","12535.241039"],["sell","0.07992","0"]]}
1624493675.963999: {"type":"l2_updates","symbol":"ETHEUR","changes":[["sell","1657.39","2.530644"],["sell","1657.20","1.263"]]}
1624493675.964103: {"type":"l2_updates","symbol":"FILUSD","changes":[["buy","58.4162","0"],["buy","58.4243","0"]]}
1624493675.964156: {"type":"l2_updates","symbol":"GRTUSD","changes":[["buy","0.6149","300"],["buy","0.6144","4056.053724"]]}
1624493675.965345: {"type":"l2_updates","symbol":"ANKRUSD","changes":[["buy","0.07917","0"],["buy","0.07954","0"]]}
1624493676.162818: {"type":"l2_updates","symbol":"BATBTC","changes":[["buy","0.00001581","1422.511906"]]}
1624493676.163939: {"type":"l2_updates","symbol":"ALCXUSD","changes":[["sell","303.25","3.29702"],["sell","303.39","0"]]}
1624493676.3643022: {"type":"l2_updates","symbol":"LINKETH","changes":[["buy","0.0092334","0"]]}
1624493676.4643252: {"type":"l2_updates","symbol":"LINKETH","changes":[["buy","0.0092697","100"]]}
1624493676.7637389: {"type":"l2_updates","symbol":"LINKETH","changes":[["buy","0.009234","100"],["buy","0.0092697","0"]]}
1624493676.76578: {"type":"l2_updates","symbol":"ANKRUSD","changes":[["buy","0.07958","13031.502419"],["buy","0.07939","62663.540493"],["buy","0.07949","43850.531895"],["buy","0.07941","0"],["sell","0.07993","0"],["sell","0.07998","25069.297198"],["sell","0.08002","0"]]}
1624493676.865739: {"type":"l2_updates","symbol":"ANKRUSD","changes":[["buy","0.07958","498"],["buy","0.07953","0"],["sell","0.07998","0"],["sell","0.08008","0"]]}
1624493676.865862: {"type":"heartbeat","timestamp":1624493676869}
1624493676.963914: {"type":"l2_updates","symbol":"BATBTC","changes":[["buy","0.00001581","0"]]}
1624493676.9640388: {"type":"l2_updates","symbol":"FILUSD","changes":[["sell","58.5073","0"]]}
1624493677.066869: {"type":"l2_updates","symbol":"BATBTC","changes":[["buy","0.00001581","1422.511906"]]}
1624493677.066941: {"type":"l2_updates","symbol":"GRTUSD","changes":[["buy","0.616","0"]]}
1624493677.1636229: {"type":"l2_updates","symbol":"BTCGBP","changes":[["buy","24103.03","0"],["buy","24109.47","0.04"],["buy","24106.42","0"],["buy","24095.57","0.91"],["buy","24089.73","0"],["sell","24126.44","0"],["sell","24129.49","0.04"],["sell","24123.25","0"],["sell","24131.41","0"],["sell","24137.29","0.91"]]}
1624493677.1676211: {"type":"l2_updates","symbol":"ETHEUR","changes":[["sell","1657.20","0"]]}
1624493677.167682: {"type":"l2_updates","symbol":"FILUSD","changes":[["sell","58.4763","0"]]}
1624493677.171326: {"type":"l2_updates","symbol":"GRTUSD","changes":[["buy","0.6146","89.99"],["sell","0.6168","0"]]}
1624493677.266909: {"type":"l2_updates","symbol":"BTCGBP","changes":[["buy","24080.38","0"]]}
1624493677.269641: {"type":"l2_updates","symbol":"GRTUSD","changes":[["buy","0.6146","0"]]}
1624493677.269727: {"type":"l2_updates","symbol":"ANKRUSD","changes":[["buy","0.07949","0"],["sell","0.08018","0"]]}
1624493677.3640902: {"type":"l2_updates","symbol":"BTCGBP","changes":[["buy","24098.64","0.59392369"],["buy","24103.02","0"],["buy","24101.70","0.91"],["buy","24095.57","0"],["sell","24129.49","0"],["sell","24143.43","0.91"],["sell","24136.07","0"],["sell","24132.58","0.04"],["sell","24137.29","0"]]}
1624493677.366146: {"type":"l2_updates","symbol":"ETHEUR","changes":[["sell","1657.20","1.263"]]}
1624493677.3707032: {"type":"l2_updates","symbol":"ANKRUSD","changes":[["buy","0.07928","0"],["buy","0.07951","62555.446989"],["buy","0.07971","14300"],["buy","0.07967","12518.266168"],["buy","0.07966","25024.609214"],["buy","0.07957","0"],["buy","0.07947","64350"],["sell","0.08028","62629.059355"],["sell","0.08009","25036.532335"],["sell","0.08022","43793.066125"],["sell","0.07999","14300"],["sell","0.08011","12511.089398"],["sell","0.08038","232072.023035"],["sell","0.07985","0"],["sell","0.08023","64350"]]}
1624493677.463871: {"type":"l2_updates","symbol":"BTCGBP","changes":[["sell","24140.70","0"]]}
1624493677.4640052: {"type":"l2_updates","symbol":"ETHEUR","changes":[["sell","1657.22","0"],["sell","1657.80","2.529892"]]}
1624493677.466938: {"type":"l2_updates","symbol":"FILUSD","changes":[["buy","58.3787","63.909"],["buy","58.3447","0"],["sell","58.8334","134.3"],["sell","58.5871","0"]]}
1624493677.469562: {"type":"l2_updates","symbol":"GRTUSD","changes":[["buy","0.615","179.98"]]}
1624493677.4711418: {"type":"l2_updates","symbol":"ANKRUSD","changes":[["buy","0.07957","43793.066125"]]}
1624493677.56271: {"type":"l2_updates","symbol":"BTCGBP","changes":[["sell","24150.37","0.021"]]}
1624493677.5628319: {"type":"l2_updates","symbol":"ETHEUR","changes":[["sell","1657.79","0"],["sell","1657.46","0"]]}
1624493677.567945: {"type":"l2_updates","symbol":"ANKRUSD","changes":[["buy","0.07958","249"]]}
1624493677.6629272: {"type":"l2_updates","symbol":"BTCGBP","changes":[["buy","24109.47","0"],["buy","24115.17","0.14846912"],["sell","24140.70","0.04"],["sell","24145.81","0"],["sell","24146.75","0.14847061"],["sell","24132.58","0"],["sell","24154.10","0.29691025"]]}
1624493677.668254: {"type":"l2_updates","symbol":"ANKRUSD","changes":[["buy","0.07972","249"]]}
1624493677.7633832: {"type":"l2_updates","symbol":"BTCGBP","changes":[["buy","24115.18","0.04"]]}
1624493677.764545: {"type":"l2_updates","symbol":"ETHEUR","changes":[["sell","1657.39","0"]]}
1624493677.766217: {"type":"l2_updates","symbol":"FILUSD","changes":[["sell","58.4997","0"],["sell","58.5313","13.9"]]}
1624493677.864084: {"type":"l2_updates","symbol":"ETHEUR","changes":[["sell","1658.40","10.118918"],["sell","1657.97","2.529642"],["sell","1658.05","5.059511"]]}
1624493677.868617: {"type":"l2_updates","symbol":"ANKRUSD","changes":[["buy","0.07958","0"]]}
1624493677.963828: {"type":"l2_updates","symbol":"BTCGBP","changes":[["buy","23982.04","0"],["buy","24032.01","0.21"]]}
1624493678.065779: {"type":"l2_updates","symbol":"FILUSD","changes":[["buy","58.4244","77.528852"],["sell","58.5175","0"],["sell","58.5073","93.347032"]]}
1624493678.266793: {"type":"l2_updates","symbol":"GRTUSD","changes":[["buy","0.616","1491.068077"],["sell","0.6171","1293.150839"]]}
1624493678.6645381: {"type":"l2_updates","symbol":"BATBTC","changes":[["buy","0.00001581","0"]]}
1624493678.764043: {"type":"l2_updates","symbol":"BATBTC","changes":[["buy","0.00001581","1422.511906"]]}
1624493678.7641332: {"type":"l2_updates","symbol":"FILUSD","changes":[["buy","58.3629","0"],["sell","58.5593","0"]]}
1624493678.866734: {"type":"l2_updates","symbol":"FILUSD","changes":[["sell","58.5313","0"]]}
1624493678.9628851: {"type":"l2_updates","symbol":"BTCGBP","changes":[["sell","24279.92","0"]]}
1624493678.963012: {"type":"l2_updates","symbol":"FILUSD","changes":[["buy","58.4244","0"],["buy","58.3788","13"],["sell","58.5072","13.9"]]}
1624493679.062745: {"type":"l2_updates","symbol":"BTCGBP","changes":[["sell","24279.91","1.38903833"]]}
1624493679.062878: {"type":"l2_updates","symbol":"ETHEUR","changes":[["buy","1647.74","0"],["buy","1648.17","1.997"]]}
1624493679.064724: {"type":"l2_updates","symbol":"FILUSD","changes":[["sell","58.5072","0"],["sell","58.5732","40.8"],["sell","58.5314","0"],["sell","58.5313","13.9"]]}
1624493679.162283: {"type":"l2_updates","symbol":"FILUSD","changes":[["sell","58.5073","0"]]}
1624493679.265847: {"type":"l2_updates","symbol":"FILUSD","changes":[["sell","58.5731","13"]]}
1624493679.265933: {"type":"l2_updates","symbol":"GRTUSD","changes":[["buy","0.616","0"]]}
1624493679.365126: {"type":"l2_updates","symbol":"GRTUSD","changes":[["sell","0.6185","12170.279562"],["sell","0.6183","8113.519708"],["sell","0.6196","0"],["sell","0.6202","0"],["sell","0.6171","0"]]}
1624493679.46442: {"type":"l2_updates","symbol":"FILUSD","changes":[["sell","59.3685","0"]]}
1624493679.5645509: {"type":"l2_updates","symbol":"BATBTC","changes":[["buy","0.00001581","0"]]}
1624493679.5647318: {"type":"l2_updates","symbol":"GRTUSD","changes":[["sell","0.6225","653.766422"]]}
1624493679.664154: {"type":"l2_updates","symbol":"BATBTC","changes":[["buy","0.00001581","1422.511906"]]}
1624493679.964109: {"type":"l2_updates","symbol":"FILUSD","changes":[["buy","58.4328","56"],["buy","58.4299","77.528852"],["sell","58.5129","95.560674"]]}
1624493680.068933: {"type":"l2_updates","symbol":"GRTUSD","changes":[["buy","0.616","1491.068077"]]}
1624493680.1649542: {"type":"l2_updates","symbol":"GRTUSD","changes":[["sell","0.6169","1272.169007"]]}
1624493680.2648408: {"type":"l2_updates","symbol":"FILUSD","changes":[["sell","59.1512","59.138703"]]}
1624493680.363337: {"type":"l2_updates","symbol":"BTCGBP","changes":[["buy","24032.01","0"],["sell","24150.37","0"],["sell","24159.15","0"]]}
1624493680.4670012: {"type":"l2_updates","symbol":"BTCGBP","changes":[["buy","24101.70","0"],["buy","24108.39","0.91"],["buy","23943.85","0.21"],["sell","24167.26","0.021"],["sell","24202.25","3.2725"],["sell","24143.43","0"],["sell","24153.99","0.91"],["sell","24212.17","0.062"],["sell","24150.38","0.59406362"],["sell","24167.27","0"]]}
1624493680.469097: {"type":"l2_updates","symbol":"BATBTC","changes":[["buy","0.00001581","0"],["buy","0.0000158","1422.511906"]]}
1624493680.469171: {"type":"l2_updates","symbol":"FILUSD","changes":[["buy","58.0285","13.9"],["buy","58.3108","0"],["sell","58.5732","0"],["sell","58.5313","0"]]}
1624493680.5801358: {"type":"l2_updates","symbol":"BTCGBP","changes":[["buy","24114.70","0.91"],["buy","24031.99","0"],["buy","24066.44","3.2725"],["buy","24108.39","0"],["sell","24140.70","0"],["sell","24140.71","0"],["sell","24146.35","0.04"],["sell","24150.38","0"]]}
1624493680.580378: {"type":"l2_updates","symbol":"ETHEUR","changes":[["sell","1657.20","0"]]}
1624493680.5834339: {"type":"l2_updates","symbol":"FILUSD","changes":[["sell","58.8333","40.8"],["sell","58.5552","60.985"],["sell","58.5212","0"],["sell","58.573","13.9"]]}
1624493680.663799: {"type":"l2_updates","symbol":"BTCGBP","changes":[["buy","24114.70","0"],["buy","24117.46","0.91"],["buy","24117.47","0.04"],["buy","24109.46","0"],["buy","24078.56","0"],["buy","24032.00","0.062"],["buy","24115.18","0"],["sell","24160.37","0.91"],["sell","24167.26","0"],["sell","24159.16","0"],["sell","24146.75","0"],["sell","24153.98","0.021"],["sell","24149.51","0.04"],["sell","24153.99","0"],["sell","24212.17","0"],["sell","24146.35","0"],["sell","24154.10","0"]]}
1624493680.764149: {"type":"l2_updates","symbol":"BTCGBP","changes":[["buy","24102.09","1.18742515"],["buy","24121.41","0.04"],["buy","24121.40","0.14842815"],["buy","24117.47","0"],["buy","24115.17","0"],["buy","24066.45","0.021"],["buy","23943.85","0"],["sell","24167.25","0.062"],["sell","24157.75","0.14840902"],["sell","24162.83","0.29681485"],["sell","24172.94","1.18723459"]]}
1624493680.768586: {"type":"l2_updates","symbol":"FILUSD","changes":[["sell","58.5722","53.74"],["sell","58.5382","0"],["sell","58.5734","256.432788"],["sell","58.5185","0"],["sell","58.573","0"]]}
1624493680.8638809: {"type":"l2_updates","symbol":"BTCGBP","changes":[["buy","24094.59","0"],["buy","24032.01","0.21"],["sell","24151.55","0.14844579"],["sell","24167.25","0"],["sell","24161.55","0.59377467"]]}
1624493680.864913: {"type":"l2_updates","symbol":"BATBTC","changes":[["buy","0.0000158","0"]]}
1624493680.864983: {"type":"l2_updates","symbol":"FILUSD","changes":[["buy","58.0285","0"],["buy","58.3389","0"],["buy","58.3617","0"],["buy","58.3957","62.475"],["sell","58.8333","0"],["sell","58.5176","0"],["sell","58.5551","40.8"],["sell","58.5315","0"],["sell","58.5314","13.9"]]}
1624493680.868895: {"type":"l2_updates","symbol":"GRTUSD","changes":[["buy","0.6144","0"]]}
1624493680.964586: {"type":"l2_updates","symbol":"BTCGBP","changes":[["sell","24151.55","0"],["sell","24172.93","0.062"],["sell","24161.55","0"]]}
1624493680.967666: {"type":"l2_updates","symbol":"FILUSD","changes":[["buy","58.3268","0"],["buy","58.3269","13.9"],["sell","58.5551","0"],["sell","58.5731","0"]]}
1624493680.969919: {"type":"l2_updates","symbol":"GRTUSD","changes":[["buy","0.615","89.99"],["buy","0.6143","8109.749898"],["buy","0.6151","4055.050691"],["buy","0.6131","0"]]}
1624493680.972213: {"type":"l2_updates","symbol":"ANKRUSD","changes":[["buy","0.07971","0"],["sell","0.08009","0"],["sell","0.07999","0"],["sell","0.08015","25030.053658"]]}
1624493681.0392818: {"type":"trade","symbol":"FILUSD","event_id":45465842999,"timestamp":1624493681030,"price":"58.4998","quantity":"15.4053","side":"buy"}
1624493681.039374: {"type":"trade","symbol":"FILUSD","event_id":45465843005,"timestamp":1624493681031,"price":"58.4998","quantity":"0.000077","side":"buy"}
1624493681.0394151: {"type":"trade","symbol":"FILUSD","event_id":45465843007,"timestamp":1624493681031,"price":"58.5129","quantity":"56.000023","side":"buy"}
1624493681.039447: {"type":"trade","symbol":"FILUSD","event_id":45465843014,"timestamp":1624493681031,"price":"58.5129","quantity":"39.560651","side":"buy"}
1624493681.066171: {"type":"l2_updates","symbol":"FILUSD","changes":[["buy","58.3788","0"],["sell","58.8333","40.8"],["sell","58.5129","0"],["sell","58.5871","13.9"],["sell","58.4998","0"],["sell","58.5314","0"]]}
1624493681.067411: {"type":"l2_updates","symbol":"GRTUSD","changes":[["buy","0.6126","0"]]}
1624493681.170274: {"type":"l2_updates","symbol":"FILUSD","changes":[["buy","58.3269","0"],["buy","58.4299","0"],["buy","58.4069","0"],["buy","58.4272","0"]]}
1624493681.172864: {"type":"l2_updates","symbol":"ANKRUSD","changes":[["buy","0.07967","0"],["buy","0.07966","0"],["sell","0.08139","0"],["sell","0.08028","0"],["sell","0.08022","0"],["sell","0.08011","0"],["sell","0.08015","0"]]}
1624493681.2656991: {"type":"l2_updates","symbol":"FILUSD","changes":[["buy","58.4025","13"],["buy","58.0285","2248.276298"],["buy","58.415","256.390505"],["buy","58.0282","0"],["buy","58.3787","0"],["buy","58.4127","50.591"],["buy","58.451","56"],["buy","58.4481","213.581386"],["buy","58.4045","341.777776"],["sell","58.5455","170.933089"],["sell","58.5594","213.658754"],["sell","58.5552","0"],["sell","58.5892","50.756"]]}
1624493681.2692149: {"type":"l2_updates","symbol":"ANKRUSD","changes":[["buy","0.07957","0"]]}
1624493681.3635788: {"type":"l2_updates","symbol":"BTCGBP","changes":[["buy","24121.41","0"],["buy","24123.10","0.91"],["buy","24121.40","0"],["buy","24117.46","0"],["buy","24123.11","0.04"],["sell","24160.37","0"],["sell","24166.06","0.91"],["sell","24155.20","0.04"],["sell","24153.98","0"],["sell","24149.51","0"],["sell","24172.93","0"]]}
1624493681.364597: {"type":"l2_updates","symbol":"BATBTC","changes":[["buy","0.0000158","1422.511906"]]}
1624493681.364641: {"type":"l2_updates","symbol":"FILUSD","changes":[["buy","58.3845","140.804948"],["sell","58.5455","0"],["sell","58.5594","0"],["sell","58.5871","0"],["sell","59.2047","544.9"],["sell","58.9493","0"]]}
1624493681.367774: {"type":"l2_updates","symbol":"GRTUSD","changes":[["buy","0.616","0"]]}
1624493681.367813: {"type":"l2_updates","symbol":"ANKRUSD","changes":[["buy","0.07952","249"]]}
1624493681.463534: {"type":"l2_updates","symbol":"BTCGBP","changes":[["sell","24157.75","0"],["sell","24162.83","0"],["sell","24172.92","0.021"],["sell","24202.24","0.062"]]}
1624493681.465378: {"type":"l2_updates","symbol":"LINKETH","changes":[["sell","0.0095056","10"],["sell","0.0094912","10"]]}
1624493681.4654431: {"type":"l2_updates","symbol":"FILUSD","changes":[["buy","58.4024","0"],["sell","58.8332","13.9"],["sell","58.5734","0"],["sell","58.5733","0"]]}
1624493681.468073: {"type":"l2_updates","symbol":"GRTUSD","changes":[["buy","0.615","0"],["sell","0.6169","0"]]}
1624493681.562969: {"type":"l2_updates","symbol":"BTCGBP","changes":[["buy","24127.83","0.14838679"],["buy","24133.97","0.04"],["buy","24118.53","0.29676944"],["buy","24134.22","0.14834801"],["buy","24123.11","0"],["sell","24172.43","0.5935129"],["sell","24174.03","0.29668921"],["sell","24162.50","0.14837998"],["sell","24168.93","0.14834628"]]}
1624493681.5665112: {"type":"l2_updates","symbol":"FILUSD","changes":[["buy","58.4692","170.83879"],["buy","58.4328","0"],["buy","58.4721","56"],["sell","58.6386","13"],["sell","58.8331","1013.927449"],["sell","58.6289","341.677579"],["sell","58.5878","213.565589"],["sell","59.1512","0"],["sell","58.5872","0"],["sell","58.5739","170.858978"],["sell","58.8335","0"],["sell","58.6173","256.258184"],["sell","58.6145","256.270368"]]}
1624493681.663417: {"type":"l2_updates","symbol":"BTCGBP","changes":[["buy","24133.97","0"],["buy","24132.40","0.04"]]}
1624493681.664505: {"type":"l2_updates","symbol":"FILUSD","changes":[["buy","58.3628","0"],["buy","58.3845","0"],["sell","58.5397","11.863847"],["sell","58.8333","0"],["sell","58.6385","40.8"],["sell","58.8332","0"],["sell","58.6144","13.9"]]}
1624493681.666847: {"type":"l2_updates","symbol":"GRTUSD","changes":[["buy","0.6152","89.99"]]}
1624493681.666906: {"type":"l2_updates","symbol":"ANKRUSD","changes":[["buy","0.07976","24985.324047"],["buy","0.0798","12492.662024"],["buy","0.07967","43724.317083"],["buy","0.07988","14300"],["buy","0.07885","0"],["buy","0.07947","0"],["buy","0.07926","275000"],["sell","0.08026","12492.662024"],["sell","0.0803","24984.340543"],["sell","0.08054","62463.310118"],["sell","0.08039","43724.317083"],["sell","0.08056","62441.362496"],["sell","0.08079","169510.5"],["sell","0.08016","14300"],["sell","0.08038","0"],["sell","0.08176","312316.550588"],["sell","0.08023","0"]]}
1624493681.764831: {"type":"l2_updates","symbol":"BATBTC","changes":[["buy","0.0000158","0"]]}
1624493681.767748: {"type":"l2_updates","symbol":"GRTUSD","changes":[["buy","0.6152","179.98"]]}
1624493681.7678: {"type":"l2_updates","symbol":"ANKRUSD","changes":[["buy","0.07939","0"]]}
1624493681.8207529: {"type":"trade","symbol":"ANKRUSD","event_id":45465846049,"timestamp":1624493681820,"price":"0.07991","quantity":"3036.164666","side":"buy"}
1624493681.864488: {"type":"l2_updates","symbol":"ETHEUR","changes":[["sell","1657.80","0"]]}
1624493681.868576: {"type":"l2_updates","symbol":"ANKRUSD","changes":[["sell","0.07991","0"]]}
1624493681.868633: {"type":"heartbeat","timestamp":1624493681872}
1624493681.964139: {"type":"l2_updates","symbol":"ETHEUR","changes":[["sell","1658.42","2.529115"],["sell","1657.95","1.261"]]}
1624493681.964277: {"type":"l2_updates","symbol":"FILUSD","changes":[["buy","58.4297","63.211"],["buy","58.3957","0"],["sell","58.5722","0"],["sell","58.6062","52.35"]]}
1624493681.966124: {"type":"l2_updates","symbol":"GRTUSD","changes":[["buy","0.6149","0"],["buy","0.614","12163.683348"],["buy","0.6155","300"]]}
1624493681.966262: {"type":"l2_updates","symbol":"ANKRUSD","changes":[["buy","0.07972","0"],["buy","0.07952","0"]]}
1624493682.064342: {"type":"l2_updates","symbol":"BTCGBP","changes":[["sell","24172.92","0"]]}
1624493682.068651: {"type":"l2_updates","symbol":"LINKETH","changes":[["sell","0.0095056","0"],["sell","0.0094912","20"]]}
1624493682.068789: {"type":"l2_updates","symbol":"ANKRUSD","changes":[["buy","0.07989","249"]]}
1624493682.164929: {"type":"l2_updates","symbol":"BTCGBP","changes":[["sell","24162.49","0.021"]]}
1624493682.165015: {"type":"l2_updates","symbol":"ETHEUR","changes":[["sell","1657.95","0"]]}
1624493682.166053: {"type":"l2_updates","symbol":"GRTUSD","changes":[["buy","0.6152","0"]]}
1624493682.166115: {"type":"l2_updates","symbol":"ANKRUSD","changes":[["buy","0.07989","498"]]}
1624493682.263175: {"type":"l2_updates","symbol":"BTCGBP","changes":[["sell","24174.02","0.062"],["sell","24202.24","0"]]}
1624493682.2633212: {"type":"l2_updates","symbol":"ETHEUR","changes":[["sell","1658.40","0"],["sell","1658.71","5.057837"],["sell","1658.05","0"]]}
1624493682.266264: {"type":"l2_updates","symbol":"BATBTC","changes":[["buy","0.0000158","1422.511906"]]}
1624493682.266356: {"type":"l2_updates","symbol":"GRTUSD","changes":[["buy","0.6156","89.99"]]}
1624493682.364204: {"type":"l2_updates","symbol":"ETHEUR","changes":[["sell","1659.06","10.115673"],["sell","1657.97","0"]]}
1624493682.366252: {"type":"l2_updates","symbol":"GRTUSD","changes":[["buy","0.6156","179.98"]]}
1624493682.465146: {"type":"l2_updates","symbol":"BTCGBP","changes":[["sell","24174.02","0"],["sell","24202.24","0.062"]]}
1624493682.5637271: {"type":"l2_updates","symbol":"FILUSD","changes":[["buy","58.4405","256.228079"]]}
1624493682.7651021: {"type":"l2_updates","symbol":"BTCGBP","changes":[["sell","24174.02","0.062"],["sell","24202.24","0"]]}
1624493682.7663202: {"type":"l2_updates","symbol":"BATBTC","changes":[["buy","0.0000158","0"]]}
1624493682.766382: {"type":"l2_updates","symbol":"FILUSD","changes":[["sell","58.6385","0"],["sell","58.833","40.8"]]}
1624493682.8637938: {"type":"l2_updates","symbol":"BTCGBP","changes":[["sell","24174.02","0"],["sell","24202.24","0.062"]]}
1624493682.963328: {"type":"l2_updates","symbol":"BTCGBP","changes":[["sell","24174.02","0.062"],["sell","24202.24","0"]]}
1624493682.967236: {"type":"l2_updates","symbol":"FILUSD","changes":[["buy","58.451","0"],["buy","58.4804","56"],["buy","58.4775","91.5495"],["sell","58.5738","9"]]}
1624493683.064627: {"type":"l2_updates","symbol":"FILUSD","changes":[["sell","58.5606","99.904487"]]}
1624493683.064786: {"type":"l2_updates","symbol":"ANKRUSD","changes":[["buy","0.07989","249"]]}
1624493683.1641228: {"type":"l2_updates","symbol":"BTCGBP","changes":[["buy","24123.10","0"],["buy","24132.40","0"],["sell","24166.06","0"]]}
1624493683.166116: {"type":"l2_updates","symbol":"BATBTC","changes":[["buy","0.0000158","1422.511906"]]}
1624493683.1661801: {"type":"l2_updates","symbol":"GRTUSD","changes":[["buy","0.6167","1239.722633"]]}
1624493683.166218: {"type":"l2_updates","symbol":"ANKRUSD","changes":[["buy","0.07964","64350"],["sell","0.0804","64350"]]}
1624493683.263962: {"type":"l2_updates","symbol":"BTCGBP","changes":[["buy","24129.11","0.04"],["buy","24118.25","0.91"],["sell","24160.21","0.91"]]}
1624493683.264071: {"type":"l2_updates","symbol":"ETHEUR","changes":[["sell","1672.53","0"]]}
1624493683.265839: {"type":"l2_updates","symbol":"FILUSD","changes":[["sell","59.1503","65.777774"]]}
1624493683.2672188: {"type":"l2_updates","symbol":"GRTUSD","changes":[["buy","0.6096","0"],["buy","0.6121","14060"],["sell","0.6175","1092.973123"]]}
1624493683.267305: {"type":"l2_updates","symbol":"ANKRUSD","changes":[["buy","0.07963","62441.959554"],["sell","0.08026","0"],["sell","0.08056","0"]]}
1624493683.364712: {"type":"l2_updates","symbol":"FILUSD","changes":[["buy","58.4025","0"]]}
1624493683.563945: {"type":"l2_updates","symbol":"BTCGBP","changes":[["buy","24129.11","0"],["buy","24132.41","0.04"]]}
1624493683.565967: {"type":"l2_updates","symbol":"FILUSD","changes":[["sell","58.6386","0"]]}
1624493683.663125: {"type":"l2_updates","symbol":"BTCGBP","changes":[["buy","24032.02","0.021"],["buy","24066.45","0"],["buy","24032.01","0"],["sell","24174.02","0"],["sell","24162.49","0"],["sell","24305.27","0"],["sell","24202.24","0.062"]]}
1624493683.663223: {"type":"l2_updates","symbol":"BATBTC","changes":[["buy","0.0000158","0"]]}
1624493683.764616: {"type":"l2_updates","symbol":"BTCGBP","changes":[["buy","24134.23","0.04"],["buy","24132.41","0"],["buy","24118.25","0"],["buy","24124.96","0.91"],["buy","23943.85","0.21"],["sell","24167.07","0.91"],["sell","24160.21","0"],["sell","24202.24","0.083"],["sell","24412.15","0.836"]]}
1624493683.768267: {"type":"l2_updates","symbol":"FILUSD","changes":[["sell","58.6144","0"]]}
1624493683.770305: {"type":"l2_updates","symbol":"ANKRUSD","changes":[["buy","0.07964","0"],["buy","0.07954","64350"],["buy","0.07988","0"],["sell","0.0804","0"],["sell","0.0803","0"]]}
1624493683.8641632: {"type":"l2_updates","symbol":"BTCGBP","changes":[["buy","24098.64","0"]]}
1624493683.868499: {"type":"l2_updates","symbol":"FILUSD","changes":[["sell","58.8329","13.9"]]}
1624493683.868564: {"type":"l2_updates","symbol":"ANKRUSD","changes":[["buy","0.07976","0"],["buy","0.0798","0"],["sell","0.08039","0"]]}
1624493683.963973: {"type":"l2_updates","symbol":"BTCGBP","changes":[["buy","24122.97","0.59331174"],["buy","24128.52","0.91"],["buy","24124.96","0"],["sell","24167.07","0"],["sell","24188.67","1.18653207"],["sell","24172.43","0"],["sell","24183.87","0.59326604"],["sell","24170.98","0.91"],["sell","24160.11","0.04"],["sell","24162.50","0"],["sell","24279.90","0.21"],["sell","24155.20","0"],["sell","24212.18","0"],["sell","24172.94","0"]]}
1624493683.9642508: {"type":"l2_updates","symbol":"ETHEUR","changes":[["sell","1658.62","2.528834"]]}
1624493683.967104: {"type":"l2_updates","symbol":"FILUSD","changes":[["buy","58.4298","13"]]}
1624493683.968375: {"type":"l2_updates","symbol":"ANKRUSD","changes":[["buy","0.07967","0"],["buy","0.07968","249"],["buy","0.07963","0"]]}
1624493684.0638669: {"type":"l2_updates","symbol":"BTCGBP","changes":[["buy","24127.83","0"],["buy","24032.02","0"],["buy","24032.00","0"],["sell","24173.87","0.14831837"]]}
1624493684.064044: {"type":"l2_updates","symbol":"ETHEUR","changes":[["buy","1648.17","0"]]}
1624493684.069796: {"type":"l2_updates","symbol":"ANKRUSD","changes":[["buy","0.07973","0"],["buy","0.07969","25008.346496"],["buy","0.07957","43785.191639"],["buy","0.07941","62550.27377"],["sell","0.08041","62493.788166"],["sell","0.0803","43764.606367"],["sell","0.08015","12509.322966"],["sell","0.08023","25006.366998"]]}
1624493684.163997: {"type":"l2_updates","symbol":"BTCGBP","changes":[["buy","24066.45","0.083"],["buy","24032.01","0.21"],["buy","23943.85","0"],["sell","24202.24","0.062"],["sell","24172.42","0.021"]]}
1624493684.1646779: {"type":"l2_updates","symbol":"BATBTC","changes":[["buy","0.00001579","1422.511906"]]}
1624493684.167084: {"type":"l2_updates","symbol":"ANKRUSD","changes":[["buy","0.07989","0"],["sell","0.08016","0"],["sell","0.08023","0"]]}
1624493684.267164: {"type":"l2_updates","symbol":"FILUSD","changes":[["buy","58.4721","0"],["buy","58.4775","0"],["sell","58.5738","0"]]}
1624493684.2695522: {"type":"l2_updates","symbol":"ANKRUSD","changes":[["buy","0.0797","249"],["sell","0.0803","108114.606367"]]}
1624493684.364225: {"type":"l2_updates","symbol":"BTCGBP","changes":[["buy","24032.01","0"],["sell","24202.24","0"]]}
1624493684.3652558: {"type":"l2_updates","symbol":"FILUSD","changes":[["sell","58.5738","9"],["sell","58.5606","0"]]}
1624493684.367598: {"type":"l2_updates","symbol":"GRTUSD","changes":[["buy","0.6167","0"]]}
1624493684.367687: {"type":"l2_updates","symbol":"ANKRUSD","changes":[["buy","0.07968","0"]]}
1624493684.464152: {"type":"l2_updates","symbol":"BTCGBP","changes":[["buy","23943.85","0.21"],["sell","24183.86","0.062"]]}
1624493684.464257: {"type":"l2_updates","symbol":"FILUSD","changes":[["sell","58.6288","13.9"],["sell","58.8329","0"]]}
1624493684.4672651: {"type":"l2_updates","symbol":"ANKRUSD","changes":[["buy","0.0797","498"]]}
1624493684.564584: {"type":"l2_updates","symbol":"GRTUSD","changes":[["sell","0.6175","0"]]}
1624493684.663828: {"type":"l2_updates","symbol":"BTCGBP","changes":[["buy","24128.52","0"],["buy","24122.89","0.91"],["sell","24170.98","0"],["sell","24164.72","0.91"]]}
1624493684.766447: {"type":"l2_updates","symbol":"FILUSD","changes":[["sell","59.1503","0"]]}
1624493684.867457: {"type":"l2_updates","symbol":"ANKRUSD","changes":[["buy","0.07966","12514.50686"],["buy","0.07969","0"],["buy","0.07963","25028.652432"],["sell","0.08016","25029.01372"]]}
1624493684.9630852: {"type":"l2_updates","symbol":"BTCGBP","changes":[["sell","24279.90","0"],["sell","24202.24","0.21"]]}
1624493684.9632351: {"type":"l2_updates","symbol":"BATBTC","changes":[["buy","0.00001579","0"],["buy","0.0000158","1422.511906"]]}
1624493685.063506: {"type":"l2_updates","symbol":"BTCGBP","changes":[["buy","24140.62","0.14830866"]]}
1624493685.1632588: {"type":"l2_updates","symbol":"BTCGBP","changes":[["sell","24279.91","0"]]}
1624493685.1633961: {"type":"l2_updates","symbol":"ETHEUR","changes":[["buy","1648.01","2.146"],["sell","1658.40","1.263"]]}
1624493685.1645892: {"type":"l2_updates","symbol":"FILUSD","changes":[["sell","58.6144","13"]]}
1624493685.262939: {"type":"l2_updates","symbol":"BTCGBP","changes":[["buy","24134.23","0"],["buy","24074.61","3.2637"],["buy","24066.44","0"],["buy","24122.89","0"],["sell","24160.11","0"],["sell","24164.72","0"],["sell","24212.99","3.2637"],["sell","24202.25","0"],["sell","24279.90","1.35722517"],["sell","24202.24","0"]]}
1624493685.363565: {"type":"l2_updates","symbol":"BTCGBP","changes":[["sell","24279.90","1.14722517"]]}
1624493685.3648262: {"type":"l2_updates","symbol":"BATBTC","changes":[["buy","0.0000158","0"]]}
1624493685.463733: {"type":"l2_updates","symbol":"BTCGBP","changes":[["sell","24212.98","0.21"]]}
1624493685.5637288: {"type":"l2_updates","symbol":"BTCGBP","changes":[["buy","24119.87","0.91"],["buy","24130.73","0.04"],["sell","24161.93","0.04"],["sell","24168.92","0"],["sell","24161.94","0.91"]]}
1624493685.6647959: {"type":"l2_updates","symbol":"FILUSD","changes":[["buy","58.472","91.5495"]]}
1624493685.763136: {"type":"l2_updates","symbol":"BTCGBP","changes":[["buy","24140.62","0"]]}
1624493685.765547: {"type":"l2_updates","symbol":"LINKETH","changes":[["sell","0.0095056","10"],["sell","0.0094912","10"]]}
1624493685.765622: {"type":"l2_updates","symbol":"FILUSD","changes":[["sell","58.5551","99.904487"],["sell","58.6288","0"],["sell","58.8329","13.9"]]}
1624493685.864577: {"type":"l2_updates","symbol":"BTCGBP","changes":[["buy","24129.03","0.14834708"]]}
1624493685.865862: {"type":"l2_updates","symbol":"BATBTC","changes":[["buy","0.0000158","1422.511906"]]}
1624493685.86598: {"type":"l2_updates","symbol":"GRTUSD","changes":[["buy","0.6168","1465.054443"],["sell","0.6175","1092.973123"]]}
1624493685.964109: {"type":"l2_updates","symbol":"BTCGBP","changes":[["sell","24172.42","0"]]}
1624493685.964214: {"type":"l2_updates","symbol":"FILUSD","changes":[["sell","58.6288","13.9"],["sell","58.8329","0"]]}
1624493686.063458: {"type":"l2_updates","symbol":"BTCGBP","changes":[["sell","24161.92","0.021"],["sell","24161.91","0.04"],["sell","24161.93","0"]]}
1624493686.065792: {"type":"l2_updates","symbol":"GRTUSD","changes":[["buy","0.6156","89.99"]]}
1624493686.164866: {"type":"l2_updates","symbol":"FILUSD","changes":[["sell","59.1493","67.546471"]]}
1624493686.164999: {"type":"l2_updates","symbol":"ANKRUSD","changes":[["buy","0.07978","14300"],["buy","0.07973","12505.325132"],["buy","0.07966","0"],["sell","0.08006","14300"]]}
1624493686.265463: {"type":"l2_updates","symbol":"BATBTC","changes":[["buy","0.0000158","0"]]}
1624493686.265551: {"type":"l2_updates","symbol":"ANKRUSD","changes":[["buy","0.0797","249"],["buy","0.07979","249"]]}
1624493686.3638709: {"type":"l2_updates","symbol":"BTCGBP","changes":[["buy","24133.87","0.04"],["buy","24130.73","0"]]}
1624493686.3661609: {"type":"l2_updates","symbol":"FILUSD","changes":[["sell","58.6288","0"]]}
1624493686.4640892: {"type":"l2_updates","symbol":"BTCGBP","changes":[["buy","24134.23","0.04"],["buy","24126.25","0.91"],["buy","24119.87","0"],["buy","24133.87","0"],["sell","24161.92","0"],["sell","24161.94","0"],["sell","24167.93","0.91"]]}
1624493686.464292: {"type":"l2_updates","symbol":"ETHEUR","changes":[["sell","1658.40","0"]]}
1624493686.4670012: {"type":"l2_updates","symbol":"FILUSD","changes":[["sell","58.8329","13.9"]]}
1624493686.564611: {"type":"l2_updates","symbol":"BTCGBP","changes":[["sell","24173.86","0.021"]]}
1624493686.663622: {"type":"l2_updates","symbol":"BTCGBP","changes":[["buy","23943.86","0.083"],["buy","24126.25","0"],["buy","24066.45","0"],["sell","24212.98","0"],["sell","24183.86","0"],["sell","24212.97","0.062"],["sell","24173.86","0"],["sell","24167.93","0"]]}
1624493686.6654599: {"type":"l2_updates","symbol":"BATBTC","changes":[["buy","0.0000158","1422.511906"]]}
1624493686.7649531: {"type":"l2_updates","symbol":"BTCGBP","changes":[["buy","24138.56","0.04"],["buy","24134.23","0"],["buy","24135.04","0"],["buy","24135.05","0"],["buy","24138.55","0.91"],["sell","24279.89","0.21"],["sell","24161.91","0"],["sell","24181.69","0.91"],["sell","24212.97","0.083"],["sell","24174.53","0"],["sell","24170.82","0.04"],["sell","24167.22","0"]]}
1624493686.767515: {"type":"l2_updates","symbol":"FILUSD","changes":[["sell","58.6288","13.9"],["sell","58.8329","0"]]}
1624493686.772916: {"type":"l2_updates","symbol":"ANKRUSD","changes":[["buy","0.07963","0"]]}
1624493686.871705: {"type":"l2_updates","symbol":"BTCGBP","changes":[["buy","24129.03","0"],["buy","24138.55","0"],["sell","24174.03","0"],["sell","24168.93","0"],["sell","24170.82","0"],["sell","24173.85","0.04"]]}
1624493686.871899: {"type":"l2_updates","symbol":"ETHEUR","changes":[["sell","1659.06","0"],["sell","1658.42","0"],["sell","1658.62","0"]]}
1624493686.872545: {"type":"l2_updates","symbol":"ANKRUSD","changes":[["buy","0.0797","25005.211736"]]}
1624493686.872629: {"type":"heartbeat","timestamp":1624493686873}
1624493686.963203: {"type":"l2_updates","symbol":"BTCGBP","changes":[["buy","24102.09","0"],["buy","24138.56","0"],["buy","24134.22","0"],["buy","24141.31","0.91"],["buy","24141.32","0.04"]]}
1624493686.964532: {"type":"l2_updates","symbol":"ETHEUR","changes":[["sell","1659.74","10.111771"],["sell","1659.07","2.528184"],["sell","1660.74","0"],["sell","1658.71","0"],["sell","1659.39","5.055957"],["sell","1659.28","2.527911"]]}
1624493686.966469: {"type":"l2_updates","symbol":"FILUSD","changes":[["buy","58.4338","62.767"],["buy","58.4127","0"],["buy","58.4168","47.037"],["buy","58.4297","0"],["sell","58.607","44.262"],["sell","58.59","65.388"],["sell","58.5892","0"],["sell","58.6288","54.7"],["sell","58.833","0"],["sell","58.6062","0"]]}
1624493686.9695969: {"type":"l2_updates","symbol":"ANKRUSD","changes":[["buy","0.07978","0"],["buy","0.07964","64350"],["buy","0.07954","0"],["buy","0.07988","14300"],["buy","0.07979","498"],["sell","0.0804","64350"],["sell","0.08006","0"],["sell","0.0803","43764.606367"],["sell","0.08016","39329.01372"]]}
1624493687.0653021: {"type":"l2_updates","symbol":"BTCGBP","changes":[["buy","24141.45","0.14829001"],["buy","24148.26","0.1482476"],["sell","24183.87","0"],["sell","24185.78","0.14824443"],["sell","24173.87","0"],["sell","24185.64","0.29654754"]]}
1624493687.065436: {"type":"l2_updates","symbol":"ETHEUR","changes":[["sell","1659.74","0"],["sell","1659.28","0"]]}
1624493687.068576: {"type":"l2_updates","symbol":"FILUSD","changes":[["buy","58.4508","54.815"],["buy","58.4168","0"],["sell","58.59","0"],["sell","58.624","55.383"],["sell","58.5878","0"],["sell","58.5739","0"]]}
1624493687.070973: {"type":"l2_updates","symbol":"ANKRUSD","changes":[["buy","0.07979","249"],["sell","0.08016","14300"]]}
1624493687.071064: {"type":"trade","symbol":"FILUSD","event_id":45465860431,"timestamp":1624493687069,"price":"58.5397","quantity":"11.8638","side":"buy"}
1624493687.071106: {"type":"trade","symbol":"FILUSD","event_id":45465860437,"timestamp":1624493687070,"price":"58.5397","quantity":"0.000047","side":"buy"}
1624493687.071129: {"type":"trade","symbol":"FILUSD","event_id":45465860439,"timestamp":1624493687070,"price":"58.5551","quantity":"99.904353","side":"buy"}
1624493687.163449: {"type":"l2_updates","symbol":"BTCGBP","changes":[["buy","24126.78","1.18609291"],["buy","24118.53","0"],["sell","24188.67","0"],["sell","24180.52","0.14827561"],["sell","24185.64","0"],["sell","24195.75","0.59297097"]]}
1624493687.165088: {"type":"l2_updates","symbol":"ETHEUR","changes":[["sell","1823.46","15.62279"],["sell","1823.45","3.788"],["sell","1659.07","0"],["sell","1659.39","0"]]}
1624493687.165198: {"type":"l2_updates","symbol":"ZECLTC","changes":[["sell","0.897","13.94996"]]}
1624493687.166272: {"type":"l2_updates","symbol":"FILUSD","changes":[["buy","58.4298","0"],["sell","58.5738","0"],["sell","58.5397","0"],["sell","58.6177","213.471636"],["sell","58.5551","0.000134"],["sell","58.604","170.782744"],["sell","58.6288","40.8"]]}
1624493687.170791: {"type":"l2_updates","symbol":"ALCXUSD","changes":[["sell","303.43","3.296174"],["sell","303.25","0"]]}
1624493687.264362: {"type":"l2_updates","symbol":"BTCGBP","changes":[["sell","24180.52","0"]]}
1624493687.2666938: {"type":"l2_updates","symbol":"FILUSD","changes":[["sell","58.6061","13.9"]]}
1624493687.27036: {"type":"l2_updates","symbol":"ALCXUSD","changes":[["sell","303.42","0"]]}
1624493687.364434: {"type":"l2_updates","symbol":"BTCGBP","changes":[["buy","23943.86","0.062"],["sell","24212.97","0.062"]]}
1624493687.3667421: {"type":"l2_updates","symbol":"FILUSD","changes":[["buy","58.4692","0"],["buy","58.4509","13"],["buy","58.4283","141.013431"],["buy","58.4177","95.401328"],["sell","58.6144","0"]]}
1624493687.3699222: {"type":"l2_updates","symbol":"ANKRUSD","changes":[["buy","0.07979","0"]]}
1624493687.464536: {"type":"l2_updates","symbol":"BTCGBP","changes":[["buy","24074.62","0.021"],["sell","24183.86","0.021"]]}
1624493687.466624: {"type":"l2_updates","symbol":"FILUSD","changes":[["buy","58.4481","0"],["buy","58.4177","100.32139"],["sell","58.607","0"],["sell","58.641","53.725"],["sell","58.6288","0"],["sell","58.833","40.8"],["sell","59.1566","0"]]}
1624493687.562882: {"type":"l2_updates","symbol":"BTCGBP","changes":[["sell","24212.97","0"]]}
1624493687.565922: {"type":"l2_updates","symbol":"FILUSD","changes":[["buy","58.4177","4.920062"]]}
1624493687.663372: {"type":"l2_updates","symbol":"BTCGBP","changes":[["sell","24195.74","0.062"]]}
1624493687.665889: {"type":"l2_updates","symbol":"FILUSD","changes":[["sell","58.6061","0"]]}
1624493687.763382: {"type":"l2_updates","symbol":"BTCGBP","changes":[["buy","24074.62","0.083"],["buy","23943.86","0"]]}
1624493687.7650719: {"type":"l2_updates","symbol":"FILUSD","changes":[["buy","58.4338","0"],["sell","58.604","0"],["sell","58.6239","13.9"],["sell","58.6173","0"],["sell","58.6145","0"]]}
1624493687.7717938: {"type":"l2_updates","symbol":"ANKRUSD","changes":[["sell","0.08015","0"]]}
1624493687.864473: {"type":"l2_updates","symbol":"BTCGBP","changes":[["sell","24183.86","0"],["sell","24195.74","0.021"]]}
1624493687.865958: {"type":"l2_updates","symbol":"FILUSD","changes":[["buy","58.472","0"],["buy","58.4917","213.411827"],["buy","58.5027","56"],["buy","58.4678","62.325"],["buy","58.4998","170.740295"],["sell","58.67","256.047103"],["sell","58.6794","13"],["sell","58.6289","0"],["sell","58.6346","170.698069"],["sell","58.6701","256.047103"]]}
1624493687.870674: {"type":"l2_updates","symbol":"ANKRUSD","changes":[["buy","0.07973","0"],["buy","0.07957","0"],["sell","0.08022","12497.953625"],["sell","0.08024","25000.812266"]]}
