1624493687.9635892: {"type":"l2_updates","symbol":"BTCGBP","changes":[["sell","24212.96","0.062"]]}
1624493687.9676108: {"type":"l2_updates","symbol":"FILUSD","changes":[["buy","58.4177","0"],["sell","58.6177","0"],["sell","58.6288","13.9"],["sell","58.833","0"],["sell","58.6239","0"]]}
1624493688.063842: {"type":"l2_updates","symbol":"BTCGBP","changes":[["buy","24143.70","0.29642969"],["buy","24141.31","0"],["buy","24141.32","0"],["sell","24192.34","0.14820656"],["sell","24181.69","0"],["sell","24195.21","0.29643469"],["sell","24205.23","1.18571876"],["sell","24173.85","0"]]}
1624493688.064064: {"type":"l2_updates","symbol":"ETHEUR","changes":[["sell","1823.45","0"]]}
1624493688.0668612: {"type":"l2_updates","symbol":"FILUSD","changes":[["sell","58.6345","9"],["sell","58.6699","40.8"],["sell","58.5551","0"],["sell","58.624","0"],["sell","58.6239","0"],["sell","58.658","47.734"]]}
1624493688.069937: {"type":"l2_updates","symbol":"GRTUSD","changes":[["buy","0.6168","0"]]}
1624493688.163264: {"type":"l2_updates","symbol":"BTCGBP","changes":[["buy","24148.27","0.04"],["buy","24147.47","0.91"],["buy","23943.84","0"],["sell","24189.68","0.91"],["sell","24178.81","0.04"]]}
1624493688.165094: {"type":"l2_updates","symbol":"BATBTC","changes":[["buy","0.00001579","1422.511906"],["buy","0.0000158","0"]]}
1624493688.165178: {"type":"l2_updates","symbol":"FILUSD","changes":[["buy","58.4283","0"],["buy","58.415","0"],["buy","58.4848","63.235"],["buy","58.4965","256.017463"],["buy","58.4508","0"],["sell","58.6699","0"],["sell","58.9896","1403.4"],["sell","59.1565","0"],["sell","58.6491","213.36352"],["sell","58.6816","341.396137"],["sell","58.6288","0"],["sell","58.833","54.7"],["sell","58.8337","0"]]}
1624493688.167138: {"type":"l2_updates","symbol":"GRTUSD","changes":[["buy","0.6155","0"],["buy","0.616","300"]]}
1624493688.1682932: {"type":"l2_updates","symbol":"ALCXUSD","changes":[["sell","303.60","6.592347"]]}
1624493688.168353: {"type":"l2_updates","symbol":"ANKRUSD","changes":[["buy","0.07989","249"]]}
1624493688.263725: {"type":"l2_updates","symbol":"BTCGBP","changes":[["buy","24148.27","0"],["buy","24141.45","0"],["buy","24150.69","0.04"],["buy","24150.68","0.91"],["buy","24147.47","0"],["buy","23992.38","2.049"],["buy","23943.85","0"],["sell","24178.81","0"],["sell","24185.77","0.04"]]}
1624493688.266103: {"type":"l2_updates","symbol":"FILUSD","changes":[["sell","58.6815","13.9"],["sell","58.833","40.8"],["sell","59.5759","137.4"]]}
1624493688.363186: {"type":"l2_updates","symbol":"BTCGBP","changes":[["buy","24156.31","0.14819907"],["buy","24150.69","0"],["buy","23992.39","0.21"],["sell","24185.78","0"],["sell","24197.89","0.14817862"]]}
1624493688.366529: {"type":"l2_updates","symbol":"FILUSD","changes":[["buy","57.6155","0"],["sell","85.9999","1013.925539"],["sell","59.1493","0"],["sell","58.686","268.092217"]]}
1624493688.46431: {"type":"l2_updates","symbol":"BTCGBP","changes":[["buy","24122.97","0"],["buy","24148.26","0"],["buy","24156.32","0.04"],["sell","24189.68","0"],["sell","24195.21","0"],["sell","24195.75","0"]]}
1624493688.467467: {"type":"l2_updates","symbol":"FILUSD","changes":[["sell","58.5837","12.415543"],["sell","58.8331","0"]]}
1624493688.470762: {"type":"l2_updates","symbol":"GRTUSD","changes":[["buy","0.6156","0"],["sell","0.6175","0"]]}
1624493688.56357: {"type":"l2_updates","symbol":"BTCGBP","changes":[["buy","24156.31","0"],["sell","24196.41","0.91"]]}
1624493688.5671911: {"type":"l2_updates","symbol":"LINKETH","changes":[["sell","0.0094912","50"],["sell","0.0094388","0"]]}
1624493688.567266: {"type":"l2_updates","symbol":"FILUSD","changes":[["sell","58.6815","0"],["sell","58.8329","13.9"],["sell","58.686","0"]]}
1624493688.5707269: {"type":"l2_updates","symbol":"GRTUSD","changes":[["buy","0.6161","89.99"]]}
1624493688.666593: {"type":"l2_updates","symbol":"FILUSD","changes":[["buy","58.5317","170.641467"],["buy","58.4804","0"],["buy","58.5346","56"],["buy","58.4998","0"]]}
1624493688.764538: {"type":"l2_updates","symbol":"BTCGBP","changes":[["sell","24279.90","0"]]}
1624493688.764627: {"type":"l2_updates","symbol":"FILUSD","changes":[["buy","58.4045","0"]]}
1624493688.770905: {"type":"l2_updates","symbol":"GRTUSD","changes":[["buy","0.6161","179.98"]]}
1624493688.8635242: {"type":"l2_updates","symbol":"BTCGBP","changes":[["buy","24074.62","0.062"],["buy","24154.97","0.91"],["buy","24150.68","0"],["buy","23992.40","0.021"],["sell","24212.96","0"],["sell","24279.88","0.021"],["sell","24195.74","0"]]}
1624493688.865175: {"type":"l2_updates","symbol":"FILUSD","changes":[["sell","58.8329","0"],["sell","58.6579","13.9"]]}
1624493688.964672: {"type":"l2_updates","symbol":"BTCGBP","changes":[["buy","24074.62","0"],["buy","24158.06","0.14815721"],["buy","24109.43","3.2637"],["buy","24156.32","0"],["buy","24154.97","0"],["buy","24157.79","0.04"],["buy","24074.61","0"],["buy","24157.78","0.91"],["buy","24165.20","0.14814281"],["sell","24210.14","0.59264706"],["sell","24196.41","0"],["sell","24279.89","1.15812812"],["sell","24205.06","0.29632652"],["sell","24192.34","0"],["sell","24279.88","0.083"],["sell","24212.99","0"],["sell","24248.71","3.2637"],["sell","24197.88","0.04"],["sell","24185.77","0"],["sell","24200.37","0.91"],["sell","24204.49","0.14813801"]]}
1624493688.965045: {"type":"l2_updates","symbol":"ETHEUR","changes":[["sell","1736.25","10.108814"],["sell","1736.24","5.054407"],["sell","1736.23","2.527204"],["sell","1736.22","2.527204"]]}
1624493688.9654222: {"type":"l2_updates","symbol":"FILUSD","changes":[["buy","58.4484","103.5308"]]}
1624493688.968383: {"type":"l2_updates","symbol":"GRTUSD","changes":[["buy","0.6145","0"],["sell","0.6185","0"],["sell","0.6178","0"],["sell","0.6183","0"]]}
1624493689.0633411: {"type":"l2_updates","symbol":"BTCGBP","changes":[["buy","24165.21","0.04"],["buy","24157.79","0"],["buy","24148.35","0.59262884"],["buy","23992.40","0.083"],["sell","24279.88","0.021"]]}
1624493689.06612: {"type":"l2_updates","symbol":"FILUSD","changes":[["sell","58.6579","0"]]}
1624493689.070508: {"type":"l2_updates","symbol":"GRTUSD","changes":[["buy","0.6154","4050.285251"],["sell","0.62","12149.960122"],["sell","0.6188","4050.160601"],["sell","0.6196","8099.973415"]]}
1624493689.16384: {"type":"l2_updates","symbol":"BTCGBP","changes":[["sell","24279.89","0.94812812"],["sell","24279.88","0"],["sell","24248.70","0.272"],["sell","24279.93","0"]]}
1624493689.1640162: {"type":"l2_updates","symbol":"ETHEUR","changes":[["sell","1823.46","0"]]}
1624493689.1668532: {"type":"l2_updates","symbol":"FILUSD","changes":[["buy","58.4484","0"],["sell","58.8329","13.9"]]}
1624493689.2632189: {"type":"l2_updates","symbol":"BTCGBP","changes":[["sell","24197.89","0"],["sell","24341.12","2.045"],["sell","24248.70","0.293"]]}
1624493689.263378: {"type":"l2_updates","symbol":"ETHEUR","changes":[["sell","1736.21","15.62279"]]}
1624493689.2692108: {"type":"l2_updates","symbol":"ANKRUSD","changes":[["buy","0.07978","12496.190524"],["buy","0.07977","24981.750544"],["buy","0.07966","43736.666831"],["buy","0.0797","0"]]}
1624493689.3637812: {"type":"l2_updates","symbol":"BTCGBP","changes":[["sell","24210.14","0"],["sell","24210.39","0.14810601"],["sell","24205.06","0"],["sell","24215.53","0.29620859"],["sell","24225.18","1.18483436"],["sell","24205.23","0"],["sell","24220.70","0.59240994"]]}
1624493689.363988: {"type":"l2_updates","symbol":"ETHEUR","changes":[["sell","1736.25","0"],["sell","1692.60","2.525825"],["sell","1736.24","0"],["sell","1736.23","0"],["sell","1736.22","0"],["sell","1692.61","2.525825"],["sell","1692.63","10.103299"],["sell","1692.62","5.05165"]]}
1624493689.369051: {"type":"l2_updates","symbol":"GRTUSD","changes":[["sell","0.6243","0"]]}
1624493689.370131: {"type":"l2_updates","symbol":"ANKRUSD","changes":[["buy","0.07941","0"]]}
1624493689.4646971: {"type":"l2_updates","symbol":"FILUSD","changes":[["buy","58.4509","0"]]}
1624493689.565668: {"type":"l2_updates","symbol":"FILUSD","changes":[["buy","58.4868","341.270974"],["buy","58.4918","13"]]}
1624493689.5667799: {"type":"l2_updates","symbol":"GRTUSD","changes":[["sell","0.6182","0"]]}
1624493689.6642828: {"type":"l2_updates","symbol":"BATBTC","changes":[["buy","0.00001581","1422.511906"]]}
1624493689.6666508: {"type":"l2_updates","symbol":"GRTUSD","changes":[["sell","0.6197","8098.146521"]]}
1624493689.7664351: {"type":"l2_updates","symbol":"BATBTC","changes":[["buy","0.00001579","0"]]}
1624493689.7665238: {"type":"l2_updates","symbol":"FILUSD","changes":[["sell","58.8329","0"]]}
1624493689.769192: {"type":"l2_updates","symbol":"GRTUSD","changes":[["sell","0.6181","0"]]}
1624493689.8651662: {"type":"l2_updates","symbol":"FILUSD","changes":[["sell","58.6793","13.9"]]}
1624493690.065412: {"type":"l2_updates","symbol":"FILUSD","changes":[["buy","57.9924","0"],["sell","58.6793","0"]]}
1624493690.0669692: {"type":"l2_updates","symbol":"ANKRUSD","changes":[["sell","0.0803","0"]]}
1624493690.16446: {"type":"l2_updates","symbol":"BTCGBP","changes":[["sell","24220.69","0.021"],["sell","24279.88","0.21"],["sell","24248.70","0.062"]]}
1624493690.16624: {"type":"l2_updates","symbol":"FILUSD","changes":[["sell","58.8329","13.9"]]}
1624493690.1683981: {"type":"l2_updates","symbol":"ANKRUSD","changes":[["buy","0.07963","62447.467477"],["sell","0.0804","108060.68121"]]}
1624493690.263395: {"type":"l2_updates","symbol":"BTCGBP","changes":[["sell","24225.17","0.062"],["sell","24279.88","0"],["sell","24248.70","0"],["sell","24248.69","0.21"]]}
1624493690.263587: {"type":"l2_updates","symbol":"FILUSD","changes":[["sell","59.148","61.457098"]]}
1624493690.665566: {"type":"l2_updates","symbol":"FILUSD","changes":[["buy","58.5027","0"],["buy","58.5607","56"],["buy","58.5578","97.34122"],["buy","57.8551","4318.492614"]]}
1624493690.763613: {"type":"l2_updates","symbol":"BTCGBP","changes":[["sell","24279.89","0"]]}
1624493690.763712: {"type":"l2_updates","symbol":"FILUSD","changes":[["sell","59.3506","841.832463"],["sell","58.6468","90.385579"],["sell","58.9895","1013.917646"]]}
1624493690.769127: {"type":"trade","symbol":"FILUSD","event_id":45465875276,"timestamp":1624493690768,"price":"58.5837","quantity":"12.4155","side":"buy"}
1624493690.864328: {"type":"l2_updates","symbol":"BTCGBP","changes":[["buy","24153.05","1.18471418"],["buy","24126.78","0"],["buy","24158.06","0"],["sell","24341.11","1.4175881"]]}
1624493690.864504: {"type":"l2_updates","symbol":"ETHEUR","changes":[["sell","1736.21","0"]]}
1624493690.865271: {"type":"l2_updates","symbol":"FILUSD","changes":[["sell","58.6345","0"],["sell","58.5837","0.000043"],["sell","85.9999","0"],["sell","58.8329","0"],["sell","58.6793","13.9"]]}
1624493690.963755: {"type":"l2_updates","symbol":"BATBTC","changes":[["buy","0.00001581","0"],["buy","0.00001583","1422.511906"]]}
1624493690.963899: {"type":"l2_updates","symbol":"LINKETH","changes":[["sell","0.0094912","10"],["sell","0.0094388","40"]]}
1624493690.9655921: {"type":"l2_updates","symbol":"GRTUSD","changes":[["sell","0.6191","4048.525486"]]}
1624493691.063633: {"type":"l2_updates","symbol":"ETHEUR","changes":[["sell","1692.59","15.62279"]]}
1624493691.066172: {"type":"l2_updates","symbol":"GRTUSD","changes":[["buy","0.6175","1365.169911"],["sell","0.6261","90299.262302"],["sell","0.6183","1244.022729"]]}
1624493691.1636999: {"type":"l2_updates","symbol":"ETHEUR","changes":[["sell","1692.60","0"],["sell","1692.57","3.785"],["sell","1670.80","2.525488"],["sell","1692.61","0"],["sell","1670.79","2.525488"],["sell","1670.82","10.10195"],["sell","1692.63","0"],["sell","1692.62","0"]]}
1624493691.2636192: {"type":"l2_updates","symbol":"BTCGBP","changes":[["sell","24248.69","0"],["sell","24341.10","0.21"]]}
1624493691.263763: {"type":"l2_updates","symbol":"ETHEUR","changes":[["sell","1670.81","5.050975"]]}
1624493691.265862: {"type":"l2_updates","symbol":"FILUSD","changes":[["buy","57.8555","0"],["buy","58.095","634"],["sell","58.6794","0"]]}
1624493691.363297: {"type":"l2_updates","symbol":"BTCGBP","changes":[["sell","24225.17","0"],["sell","24248.70","0.272"],["sell","24341.10","0"]]}
1624493691.46319: {"type":"l2_updates","symbol":"BTCGBP","changes":[["sell","24248.70","0"]]}
1624493691.465226: {"type":"l2_updates","symbol":"FILUSD","changes":[["buy","58.5018","41.257"],["buy","58.4678","0"],["sell","58.641","0"],["sell","59.148","0"],["sell","58.675","37.441"]]}
1624493691.563628: {"type":"l2_updates","symbol":"BTCGBP","changes":[["sell","24220.68","0.062"],["sell","24220.69","0"],["sell","24341.10","0.21"],["sell","24210.38","0.021"]]}
1624493691.5644941: {"type":"l2_updates","symbol":"FILUSD","changes":[["sell","58.667","170.612242"],["sell","58.6346","0"]]}
1624493691.763773: {"type":"l2_updates","symbol":"BTCGBP","changes":[["sell","24248.69","0.21"],["sell","24341.10","0"]]}
1624493691.765305: {"type":"l2_updates","symbol":"BATBTC","changes":[["buy","0.00001583","0"]]}
1624493691.864558: {"type":"l2_updates","symbol":"BATBTC","changes":[["buy","0.00001583","1422.511906"]]}
1624493691.8646872: {"type":"l2_updates","symbol":"FILUSD","changes":[["buy","58.0284","0"],["buy","58.0285","2234.376298"],["buy","58.0951","54.7"]]}
1624493691.865574: {"type":"l2_updates","symbol":"ANKRUSD","changes":[["buy","0.07978","0"]]}
1624493691.865637: {"type":"heartbeat","timestamp":1624493691869}
1624493691.9646661: {"type":"l2_updates","symbol":"ANKRUSD","changes":[["buy","0.07983","12488.640302"],["buy","0.07989","498"],["sell","0.08022","0"],["sell","0.08024","0"]]}
1624493692.064378: {"type":"l2_updates","symbol":"BTCGBP","changes":[["buy","24170.98","0.04"],["buy","24165.21","0"],["buy","24172.93","0.14808622"]]}
1624493692.165304: {"type":"l2_updates","symbol":"FILUSD","changes":[["buy","58.4918","0"]]}
1624493692.266088: {"type":"l2_updates","symbol":"BTCGBP","changes":[["buy","24170.98","0"],["buy","24169.23","0.91"],["buy","24157.78","0"],["buy","24172.94","0.04"],["buy","24163.13","0"],["sell","24220.68","0"],["sell","24212.46","0.91"],["sell","24197.88","0"],["sell","24248.69","0"],["sell","24205.58","0"],["sell","24200.37","0"],["sell","24201.58","0.04"],["sell","24210.38","0"]]}
1624493692.266264: {"type":"l2_updates","symbol":"LINKETH","changes":[["sell","0.0094388","0"]]}
1624493692.268596: {"type":"l2_updates","symbol":"GRTUSD","changes":[["buy","0.6137","0"],["buy","0.6156","8094.485321"]]}
1624493692.367184: {"type":"l2_updates","symbol":"BTCGBP","changes":[["buy","24175.01","0"],["buy","24178.51","0.91"],["buy","24169.23","0"],["buy","24172.94","0"],["buy","24175.02","0"],["sell","24219.20","0"],["sell","24208.32","0"],["sell","24212.46","0"],["sell","24212.14","0.04"],["sell","24205.11","0"],["sell","24223.03","0.91"],["sell","24201.58","0"],["sell","24248.68","0.083"]]}
1624493692.367349: {"type":"l2_updates","symbol":"LINKETH","changes":[["sell","0.0094912","50"]]}
1624493692.371624: {"type":"l2_updates","symbol":"GRTUSD","changes":[["buy","0.6166","300"],["buy","0.616","0"]]}
1624493692.4657228: {"type":"l2_updates","symbol":"BTCGBP","changes":[["buy","24178.52","0"],["buy","24178.51","0"],["buy","24183.28","0.91"],["sell","24227.78","0.91"],["sell","24212.14","0"],["sell","24223.03","0"],["sell","24216.90","0.04"],["sell","24341.10","0.21"],["sell","24204.49","0"]]}
1624493692.467826: {"type":"l2_updates","symbol":"FILUSD","changes":[["buy","58.5578","0"],["buy","58.5346","0"],["sell","58.6491","0"],["sell","58.6793","0"]]}
1624493692.565652: {"type":"l2_updates","symbol":"BTCGBP","changes":[["buy","24183.29","0.04"],["buy","24143.70","0"],["buy","24165.20","0"],["sell","24210.39","0"],["sell","24217.31","0.14806534"],["sell","24215.53","0"],["sell","24220.70","0"]]}
1624493692.568063: {"type":"l2_updates","symbol":"FILUSD","changes":[["buy","58.5019","13"],["sell","58.6805","213.262042"],["sell","58.8329","13.9"]]}
1624493692.663719: {"type":"l2_updates","symbol":"BTCGBP","changes":[["buy","24148.35","0"],["buy","24172.93","0"],["sell","24217.31","0"],["sell","24225.18","0"]]}
1624493692.667094: {"type":"l2_updates","symbol":"BATBTC","changes":[["buy","0.00001582","1422.511906"],["buy","0.00001583","0"]]}
1624493692.6671739: {"type":"l2_updates","symbol":"FILUSD","changes":[["buy","58.0952","2234.375732"],["sell","58.6468","0"]]}
1624493692.669993: {"type":"l2_updates","symbol":"GRTUSD","changes":[["buy","0.6166","0"],["buy","0.6172","300"]]}
1624493692.6710558: {"type":"l2_updates","symbol":"ANKRUSD","changes":[["buy","0.07966","0"],["sell","0.08029","12492.433029"],["sell","0.08033","24974.066939"]]}
1624493692.768106: {"type":"l2_updates","symbol":"BTCGBP","changes":[["sell","24220.69","0.021"],["sell","24248.68","0.062"]]}
1624493692.768203: {"type":"l2_updates","symbol":"ETHEUR","changes":[["sell","1692.59","0"]]}
1624493692.772821: {"type":"l2_updates","symbol":"ANKRUSD","changes":[["buy","0.07975","43689.635305"]]}
1624493692.849078: {"type":"trade","symbol":"FILUSD","event_id":45465883633,"timestamp":1624493692848,"price":"58.5837","quantity":"0.000043","side":"buy"}
1624493692.866045: {"type":"l2_updates","symbol":"ETHEUR","changes":[["sell","1670.78","15.62279"]]}
1624493692.8679638: {"type":"l2_updates","symbol":"FILUSD","changes":[["buy","58.0285","0"],["buy","58.4848","0"],["buy","58.5188","37.855"],["buy","58.4405","0"],["buy","58.5637","56"],["buy","58.5608","365"],["sell","58.67","0"],["sell","58.692","49.233"],["sell","58.709","49.448"],["sell","58.5837","0"],["sell","58.658","0"],["sell","58.6701","0"],["sell","58.675","0"]]}
1624493692.9011798: {"type":"trade","symbol":"FILUSD","event_id":45465883970,"timestamp":1624493692900,"price":"58.667","quantity":"170.6122","side":"buy"}
1624493692.903851: {"type":"trade","symbol":"FILUSD","event_id":45465883980,"timestamp":1624493692901,"price":"58.667","quantity":"0.000042","side":"buy"}
1624493692.903914: {"type":"trade","symbol":"FILUSD","event_id":45465883982,"timestamp":1624493692901,"price":"58.6805","quantity":"213.261958","side":"buy"}
1624493692.9645948: {"type":"l2_updates","symbol":"BTCGBP","changes":[["buy","24170.71","0.29606526"],["buy","24153.05","0"],["buy","24175.61","0.59187237"],["buy","24194.39","0.14792496"],["buy","24191.82","0.14795938"],["sell","24242.13","1.18404514"],["sell","24236.95","0.29595498"],["sell","24236.41","0.1479516"],["sell","24230.58","0.14798598"],["sell","24246.36","0.59180044"]]}
1624493692.969194: {"type":"l2_updates","symbol":"FILUSD","changes":[["buy","58.5018","0"],["buy","58.5317","0"],["buy","58.5358","65.132"],["buy","58.5607","0"],["buy","58.5268","255.806452"],["buy","58.5608","0"],["sell","58.7445","341.075269"],["sell","58.692","0"],["sell","58.726","52.775"],["sell","58.667","0"],["sell","58.7308","255.8172"],["sell","58.6816","0"],["sell","58.6805","0"],["sell","58.7331","255.806452"]]}
1624493692.9729338: {"type":"l2_updates","symbol":"ANKRUSD","changes":[["buy","0.07879","5800.289999"]]}
1624493693.0648088: {"type":"l2_updates","symbol":"BTCGBP","changes":[["buy","24183.28","0"]]}
1624493693.06494: {"type":"l2_updates","symbol":"ETHEUR","changes":[["sell","1662.43","2.523217"],["sell","1662.60","2.523217"],["sell","1670.81","0"],["sell","1670.80","0"],["sell","1670.79","0"],["sell","1670.82","0"]]}
1624493693.068044: {"type":"l2_updates","symbol":"FILUSD","changes":[["buy","58.5318","14.469264"],["sell","58.709","0"],["sell","58.8334","0"],["sell","58.743","55.994"]]}
1624493693.0710201: {"type":"l2_updates","symbol":"GRTUSD","changes":[["sell","0.6188","0"],["sell","0.6201","4044.792361"]]}
1624493693.07117: {"type":"l2_updates","symbol":"ANKRUSD","changes":[["buy","0.07977","0"],["buy","0.07983","0"]]}
1624493693.164696: {"type":"l2_updates","symbol":"BTCGBP","changes":[["sell","24242.13","0"],["sell","24236.95","0"],["sell","24230.58","0"],["sell","24248.68","0"]]}
1624493693.164845: {"type":"l2_updates","symbol":"ETHEUR","changes":[["sell","1662.76","5.046434"],["sell","1663.09","10.092867"]]}
1624493693.167066: {"type":"l2_updates","symbol":"FILUSD","changes":[["buy","58.4917","0"],["sell","58.7486","13"]]}
1624493693.263232: {"type":"l2_updates","symbol":"BTCGBP","changes":[["sell","24341.09","0.062"],["sell","24341.11","0"],["sell","24248.71","0"],["sell","24216.90","0"]]}
1624493693.267096: {"type":"l2_updates","symbol":"FILUSD","changes":[["buy","58.5188","0"],["buy","58.5528","55.719"],["buy","58.5359","232.646828"],["sell","58.76","60.54"],["sell","58.726","0"],["sell","58.9894","134.3"],["sell","58.7308","0"]]}
1624493693.360868: {"type":"l2_updates","symbol":"BTCGBP","changes":[["buy","24183.29","0"],["buy","24143.93","3.2637"],["buy","24109.43","0"],["buy","24192.35","0.91"],["buy","24194.40","0.04"],["sell","24248.67","0.021"],["sell","24227.78","0"],["sell","24237.82","0.91"],["sell","24220.69","0"],["sell","24286.24","3.2637"],["sell","24236.40","0.04"]]}
1624493693.363568: {"type":"l2_updates","symbol":"ETHEUR","changes":[["sell","1692.57","0"],["sell","1662.41","1.258"]]}
1624493693.364578: {"type":"l2_updates","symbol":"FILUSD","changes":[["buy","58.5248","27.221857"],["sell","58.7762","220"],["sell","58.7331","0"]]}
1624493693.36765: {"type":"l2_updates","symbol":"GRTUSD","changes":[["buy","0.6132","0"]]}
1624493693.464909: {"type":"l2_updates","symbol":"BTCGBP","changes":[["buy","24196.06","0.91"],["buy","24192.35","0"],["buy","24194.40","0"],["buy","24196.07","0.04"],["sell","24341.10","1.33273207"]]}
1624493693.470273: {"type":"l2_updates","symbol":"FILUSD","changes":[["buy","58.5318","0"],["buy","57.8068","0"],["buy","58.5669","170.524201"],["buy","58.5707","213.086794"],["buy","58.5359","0"],["buy","58.5736","56"],["sell","58.7445","0"],["sell","58.7556","213.019173"],["sell","58.7413","170.422527"],["sell","58.795","340.805339"],["sell","58.7817","255.612728"],["sell","58.7818","255.612728"],["sell","59.5759","0"]]}
1624493693.4705548: {"type":"l2_updates","symbol":"GRTUSD","changes":[["buy","0.612","0"],["buy","0.6161","89.99"],["buy","0.6144","3405"]]}
1624493693.4706402: {"type":"l2_updates","symbol":"ALCXUSD","changes":[["buy","301.64","0"]]}
1624493693.566556: {"type":"l2_updates","symbol":"BTCGBP","changes":[["buy","24199.09","0.91"],["buy","24196.06","0"],["buy","24202.98","0.14790174"],["buy","24180.34","1.18337393"],["buy","24196.07","0"],["buy","24202.99","0.04"],["buy","24199.10","0"],["buy","24191.82","0"],["sell","24243.89","0.91"],["sell","24237.82","0"],["sell","24248.90","0.29583705"],["sell","24244.04","0.14791853"],["sell","24258.81","1.18333618"]]}
1624493693.566737: {"type":"l2_updates","symbol":"ETHEUR","changes":[["sell","1662.41","0"]]}
1624493693.568453: {"type":"l2_updates","symbol":"FILUSD","changes":[["buy","57.8552","538.9"],["buy","58.5019","0"],["buy","58.4965","0"],["sell","59.3505","137.4"]]}
1624493693.57109: {"type":"l2_updates","symbol":"GRTUSD","changes":[["sell","0.6191","0"]]}
1624493693.5711832: {"type":"l2_updates","symbol":"ALCXUSD","changes":[["buy","300.83","16.482293"]]}
1624493693.638922: {"type":"trade","symbol":"ANKRUSD","event_id":45465887998,"timestamp":1624493693624,"price":"0.07997","quantity":"3795.655473","side":"buy"}
1624493693.663747: {"type":"l2_updates","symbol":"BTCGBP","changes":[["buy","24170.71","0"],["sell","24236.41","0"]]}
1624493693.6648471: {"type":"l2_updates","symbol":"ETHEUR","changes":[["sell","1662.43","0"]]}
1624493693.6649458: {"type":"l2_updates","symbol":"LTCETH","changes":[["sell","0.0661","38.73708"]]}
1624493693.666837: {"type":"l2_updates","symbol":"FILUSD","changes":[["buy","58.5248","0"],["sell","58.7486","0"]]}
1624493693.671314: {"type":"l2_updates","symbol":"GRTUSD","changes":[["buy","0.6175","0"],["buy","0.6173","89.99"],["sell","0.6197","0"],["sell","0.62","0"]]}
1624493693.6714969: {"type":"l2_updates","symbol":"ANKRUSD","changes":[["sell","0.07997","0"]]}
1624493693.765433: {"type":"l2_updates","symbol":"BTCGBP","changes":[["sell","24246.36","0"]]}
1624493693.765505: {"type":"l2_updates","symbol":"ETHEUR","changes":[["sell","1663.26","2.522347"]]}
1624493693.767472: {"type":"l2_updates","symbol":"FILUSD","changes":[["buy","58.4868","0"],["buy","58.5737","13"],["buy","58.5358","0"],["buy","58.5698","44.091"],["sell","58.777","36.627"],["sell","58.743","0"]]}
1624493693.769793: {"type":"l2_updates","symbol":"GRTUSD","changes":[["sell","0.6183","0"],["sell","0.6196","0"]]}
1624493693.771167: {"type":"l2_updates","symbol":"ANKRUSD","changes":[["sell","0.08041","0"]]}
1624493693.863165: {"type":"l2_updates","symbol":"BTCGBP","changes":[["sell","24248.67","0.083"],["sell","24341.09","0"],["sell","24412.93","2.045"],["sell","24341.12","0"],["sell","24412.15","0"]]}
1624493693.866226: {"type":"l2_updates","symbol":"FILUSD","changes":[["buy","58.5868","52.952"],["buy","58.5763","340.708498"],["buy","58.5897","56"],["buy","58.0824","13.74178"],["buy","58.5528","0"],["buy","58.5792","56"],["buy","58.5736","0"],["buy","58.5741","255.583041"],["buy","58.5637","0"],["sell","58.76","0"],["sell","58.8329","0"],["sell","58.794","52.37"],["sell","58.7761","13"]]}
1624493693.868261: {"type":"l2_updates","symbol":"GRTUSD","changes":[["sell","0.6212","8084.433855"],["sell","0.6211","8085.663353"],["sell","0.6203","4042.831677"]]}
1624493693.868302: {"type":"l2_updates","symbol":"ANKRUSD","changes":[["buy","0.07984","24962.149368"],["buy","0.07988","26781.074684"],["sell","0.08063","62386.872182"]]}
1624493693.962177: {"type":"l2_updates","symbol":"BTCGBP","changes":[["buy","24199.09","0"],["buy","24192.48","0.91"],["sell","24534.11","0.836"],["sell","24243.89","0"],["sell","24239.12","0.91"]]}
1624493693.9657118: {"type":"l2_updates","symbol":"FILUSD","changes":[["sell","59.1527","69.532509"],["sell","58.7599","13.9"]]}
1624493693.968273: {"type":"l2_updates","symbol":"GRTUSD","changes":[["buy","0.6161","0"]]}
1624493693.9696798: {"type":"l2_updates","symbol":"ALCXUSD","changes":[["buy","302.16","0"],["buy","301.92","0"],["sell","304.10","0"],["sell","303.83","0"],["sell","303.43","0"],["sell","303.60","0"]]}
1624493693.969729: {"type":"l2_updates","symbol":"ANKRUSD","changes":[["sell","0.08029","5.399559"],["sell","0.08033","0"]]}
1624493694.0544782: {"type":"trade","symbol":"ALCXUSD","event_id":45465890462,"timestamp":1624493694054,"price":"303.05","quantity":"8.12974","side":"buy"}
1624493694.063694: {"type":"l2_updates","symbol":"BTCGBP","changes":[["sell","24248.67","0.062"]]}
1624493694.0675478: {"type":"l2_updates","symbol":"FILUSD","changes":[["buy","58.536","360.804946"],["sell","58.7384","56"],["sell","58.7383","9"]]}
1624493694.0712268: {"type":"l2_updates","symbol":"ALCXUSD","changes":[["buy","302.61","3.289683"],["buy","301.66","0"],["buy","300.83","0"],["buy","301.75","16.448412"],["buy","302.53","6.57714"],["buy","302.08","11.513889"],["sell","304.52","0"],["sell","305.35","16.448412"],["sell","304.16","3.289683"],["sell","304.89","16.472871"],["sell","304.50","6.575898"],["sell","303.05","0"]]}
1624493694.0713952: {"type":"l2_updates","symbol":"ANKRUSD","changes":[["buy","0.07808","0"]]}
1624493694.163618: {"type":"l2_updates","symbol":"BTCGBP","changes":[["buy","24202.99","0"],["sell","24239.12","0"],["sell","24286.23","0.021"]]}
1624493694.165576: {"type":"l2_updates","symbol":"FILUSD","changes":[["buy","58.5898","7.999"]]}
1624493694.1677818: {"type":"l2_updates","symbol":"ALCXUSD","changes":[["sell","304.68","11.513889"]]}
1624493694.265471: {"type":"l2_updates","symbol":"BTCGBP","changes":[["buy","24192.48","0"],["buy","24187.14","0.29586533"],["sell","24249.71","0.14788914"],["sell","24260.11","0.59154541"]]}
1624493694.2685661: {"type":"l2_updates","symbol":"FILUSD","changes":[["buy","58.5737","0"],["buy","57.9945","0"],["buy","58.1471","1407.3"],["buy","58.536","32.399406"],["sell","58.9894","0"],["sell","58.7485","40.8"],["sell","58.833","0"],["sell","58.8329","134.3"]]}
1624493694.272075: {"type":"l2_updates","symbol":"ANKRUSD","changes":[["sell","0.0804","64350"]]}
1624493694.365792: {"type":"l2_updates","symbol":"LINKETH","changes":[["sell","0.0094172","0"],["sell","0.0094388","105"]]}
1624493694.365896: {"type":"l2_updates","symbol":"FILUSD","changes":[["buy","58.5868","0"],["buy","58.5528","49.175"],["buy","58.5792","0"],["buy","58.536","0"],["buy","58.0283","0"],["sell","58.7731","48.092217"],["sell","58.76","49.062"],["sell","58.794","0"]]}
1624493694.367108: {"type":"l2_updates","symbol":"GRTUSD","changes":[["buy","0.6152","436"],["buy","0.6138","0"],["buy","0.6173","179.98"]]}
1624493694.368223: {"type":"l2_updates","symbol":"ANKRUSD","changes":[["buy","0.07841","311902.98128"],["sell","0.08041","24952.238503"],["sell","0.08035","12476.497154"],["sell","0.08049","43663.198719"]]}
1624493694.462924: {"type":"l2_updates","symbol":"BTCGBP","changes":[["sell","24248.67","0"]]}
1624493694.4667652: {"type":"l2_updates","symbol":"FILUSD","changes":[["buy","58.0953","134.3"]]}
1624493694.469177: {"type":"l2_updates","symbol":"GRTUSD","changes":[["sell","0.626","2624"],["sell","0.624","0"]]}
1624493694.564033: {"type":"l2_updates","symbol":"BTCGBP","changes":[["buy","24196.08","0.04"],["buy","24185.18","0.91"],["sell","24249.71","0"],["sell","24230.35","0.04"],["sell","24236.40","0"],["sell","24286.23","0.083"],["sell","24230.36","0.91"],["sell","24235.41","0.14794096"]]}
1624493694.567081: {"type":"l2_updates","symbol":"FILUSD","changes":[["buy","58.5898","0"],["buy","58.6448","56"],["buy","58.1472","2234.372507"],["buy","58.6419","89.034211"],["buy","58.0952","0"],["sell","58.7315","96.669036"],["sell","58.7383","0"],["sell","58.7286","56"]]}
1624493694.5671868: {"type":"l2_updates","symbol":"GRTUSD","changes":[["buy","0.6091","7080"],["buy","0.6053","0"]]}
1624493694.6639428: {"type":"l2_updates","symbol":"BTCGBP","changes":[["buy","24194.22","0"],["buy","24202.98","0"],["buy","24196.08","0"],["buy","24185.18","0"],["sell","24230.35","0"],["sell","24230.36","0"],["sell","24227.01","0.04"],["sell","24227.02","0"]]}
1624493694.666829: {"type":"l2_updates","symbol":"BATBTC","changes":[["buy","0.00001582","0"],["buy","0.00001583","1422.511906"]]}
1624493694.6700318: {"type":"l2_updates","symbol":"ANKRUSD","changes":[["buy","0.07993","12473.053789"],["buy","0.07976","64350"],["buy","0.08","14300"],["buy","0.07964","0"],["buy","0.07988","0"],["sell","0.0804","0"],["sell","0.08028","14300"],["sell","0.08052","64350"],["sell","0.08016","0"]]}
1624493694.7638872: {"type":"l2_updates","symbol":"BTCGBP","changes":[["buy","24191.16","0.04"],["buy","24180.27","0.91"],["sell","24223.72","0.91"],["sell","24227.01","0"],["sell","24223.71","0.04"]]}
1624493694.7673118: {"type":"l2_updates","symbol":"FILUSD","changes":[["buy","58.1472","2248.272507"],["buy","58.0951","0"]]}
1624493694.7703922: {"type":"l2_updates","symbol":"ANKRUSD","changes":[["buy","0.07989","249"]]}
1624493694.8628922: {"type":"l2_updates","symbol":"BTCGBP","changes":[["sell","24258.80","0.021"],["sell","24286.23","0.062"]]}
1624493694.8657238: {"type":"l2_updates","symbol":"FILUSD","changes":[["buy","58.5708","13"],["buy","58.5528","0"],["sell","58.7285","13.9"],["sell","58.7731","0"],["sell","58.76","0"],["sell","58.7599","0"],["sell","58.8329","0"],["sell","58.7286","0"]]}
1624493694.867821: {"type":"l2_updates","symbol":"GRTUSD","changes":[["buy","0.6091","5667"]]}
1624493694.967508: {"type":"l2_updates","symbol":"FILUSD","changes":[["buy","58.5868","64.327"],["buy","58.1472","2289.072507"],["sell","58.8328","134.3"],["sell","58.794","38.675"]]}
1624493694.970567: {"type":"l2_updates","symbol":"GRTUSD","changes":[["buy","0.6038","1836"],["sell","0.6216","12127.946238"]]}
1624493694.971667: {"type":"l2_updates","symbol":"ANKRUSD","changes":[["buy","0.08001","249"]]}
1624493695.066478: {"type":"l2_updates","symbol":"BATBTC","changes":[["buy","0.00001583","0"]]}
1624493695.066566: {"type":"l2_updates","symbol":"FILUSD","changes":[["sell","58.7762","0"]]}
1624493695.168312: {"type":"l2_updates","symbol":"ALCXUSD","changes":[["sell","304.50","0"]]}
1624493695.266094: {"type":"l2_updates","symbol":"BTCGBP","changes":[["sell","24286.22","0.21"],["sell","24341.10","1.12273207"]]}
1624493695.268545: {"type":"l2_updates","symbol":"FILUSD","changes":[["sell","58.7413","0"],["sell","58.7781","170.341534"]]}
1624493695.271769: {"type":"l2_updates","symbol":"ALCXUSD","changes":[["buy","302.61","0"],["buy","302.53","0"],["sell","304.16","0"],["sell","304.21","6.582167"]]}
1624493695.364419: {"type":"l2_updates","symbol":"BTCGBP","changes":[["buy","24191.16","0"],["buy","24188.82","0"],["buy","24185.73","0.04"],["buy","24180.27","0"],["buy","24174.85","0.91"],["sell","24223.72","0"],["sell","24218.29","0.91"],["sell","24220.43","0"],["sell","24223.71","0"],["sell","24220.42","0"]]}
1624493695.3670201: {"type":"l2_updates","symbol":"ETHEUR","changes":[["buy","1648.70","2.56"],["buy","1648.01","0"],["sell","1662.58","1.259"]]}
1624493695.368799: {"type":"l2_updates","symbol":"ANKRUSD","changes":[["sell","0.08027","249"]]}
1624493695.46418: {"type":"l2_updates","symbol":"BTCGBP","changes":[["buy","24185.73","0"],["buy","24194.39","0"],["buy","24184.03","0.04"],["sell","24244.04","0"],["sell","24218.29","0"],["sell","24216.60","0.91"],["sell","24218.28","0.04"]]}
1624493695.467799: {"type":"l2_updates","symbol":"ETHEUR","changes":[["sell","1662.60","0"],["sell","1663.26","0"],["sell","1661.59","2.524634"],["sell","1661.76","2.524634"]]}
1624493695.4678771: {"type":"l2_updates","symbol":"FILUSD","changes":[["sell","58.8328","0"],["sell","58.76","41.517"],["sell","58.9894","134.3"],["sell","58.794","0"],["sell","58.7256","56"]]}
1624493695.563257: {"type":"l2_updates","symbol":"BTCGBP","changes":[["buy","24184.03","0"],["buy","24187.14","0"],["buy","24174.85","0"],["buy","24189.40","0.14794569"],["sell","24216.60","0"],["sell","24223.93","0.1480056"],["sell","24218.28","0"],["sell","24235.41","0"]]}
1624493695.565388: {"type":"l2_updates","symbol":"ETHEUR","changes":[["sell","1662.76","0"]]}
1624493695.5654578: {"type":"l2_updates","symbol":"BATBTC","changes":[["buy","0.00001583","1422.511906"]]}
1624493695.566427: {"type":"l2_updates","symbol":"FILUSD","changes":[["sell","58.9893","1013.921083"],["sell","58.7662","220"]]}
1624493695.664295: {"type":"l2_updates","symbol":"BTCGBP","changes":[["buy","24175.49","0.29599095"],["buy","24180.34","0"],["buy","24189.40","0"],["buy","24180.61","0.14799374"],["sell","24248.90","0"],["sell","24232.76","0.14798138"]]}
1624493695.666494: {"type":"l2_updates","symbol":"FILUSD","changes":[["sell","58.9895","0"]]}
1624493695.763415: {"type":"l2_updates","symbol":"BTCGBP","changes":[["buy","24166.46","0.91"],["buy","24177.34","0.04"],["sell","24211.08","0.91"],["sell","24223.92","0"],["sell","24211.07","0.04"],["sell","24260.11","0"]]}
1624493695.7672498: {"type":"l2_updates","symbol":"FILUSD","changes":[["sell","58.7285","0"],["sell","58.7485","0"]]}
1624493695.863776: {"type":"l2_updates","symbol":"BTCGBP","changes":[["buy","24177.34","0"],["sell","24211.08","0"],["sell","24232.76","0"],["sell","24286.23","0"]]}
1624493695.866283: {"type":"l2_updates","symbol":"ETHEUR","changes":[["sell","1663.09","0"]]}
1624493695.8687391: {"type":"l2_updates","symbol":"FILUSD","changes":[["buy","58.5708","0"],["sell","58.7949","40.8"],["sell","58.7599","13.9"],["sell","58.7762","48.092217"]]}
1624493695.8689191: {"type":"l2_updates","symbol":"GRTUSD","changes":[["buy","0.6167","300"],["buy","0.6172","0"],["sell","0.6261","0"]]}
1624493695.965159: {"type":"l2_updates","symbol":"BTCGBP","changes":[["buy","24175.82","0.14802333"],["buy","24175.61","0"],["buy","24158.51","0.59227963"],["buy","24163.16","1.18409384"],["buy","24173.83","0.04"],["sell","24231.53","0.29603721"],["sell","24260.10","0.062"],["sell","24208.56","0.91"],["sell","24232.12","0.59217913"]]}
1624493695.965373: {"type":"l2_updates","symbol":"ETHEUR","changes":[["sell","1661.65","5.050098"],["sell","1661.60","10.102515"]]}
1624493695.968408: {"type":"l2_updates","symbol":"FILUSD","changes":[["buy","58.5868","0"],["buy","58.5528","38.877"],["sell","58.7761","0"]]}
1624493695.972049: {"type":"l2_updates","symbol":"ALCXUSD","changes":[["sell","304.04","4.111301"]]}
1624493696.066591: {"type":"l2_updates","symbol":"BTCGBP","changes":[["sell","24215.20","0.14805892"]]}
1624493696.0690932: {"type":"l2_updates","symbol":"LINKETH","changes":[["sell","0.0094912","10"]]}
1624493696.06913: {"type":"l2_updates","symbol":"FILUSD","changes":[["sell","58.7949","0"],["sell","58.9894","0"],["sell","58.8096","134.3"],["sell","58.7599","0"],["sell","58.7555","40.8"]]}
1624493696.071003: {"type":"l2_updates","symbol":"ALCXUSD","changes":[["sell","304.21","0"]]}
1624493696.07104: {"type":"l2_updates","symbol":"ANKRUSD","changes":[["buy","0.07993","0"],["sell","0.08041","0"],["sell","0.08035","0"]]}
1624493696.16531: {"type":"l2_updates","symbol":"BTCGBP","changes":[["sell","24260.10","0"]]}
1624493696.1686778: {"type":"l2_updates","symbol":"LINKETH","changes":[["sell","0.0094388","145"]]}
1624493696.1687438: {"type":"l2_updates","symbol":"FILUSD","changes":[["sell","58.7255","13.9"]]}
1624493696.170772: {"type":"l2_updates","symbol":"ALCXUSD","changes":[["buy","302.47","6.578399"],["buy","302.79","3.287629"],["sell","304.14","3.28987"],["sell","304.50","6.575524"]]}
1624493696.170857: {"type":"l2_updates","symbol":"ANKRUSD","changes":[["buy","0.07986","12484.682331"],["sell","0.08029","12490.579468"],["sell","0.08034","24970.359817"]]}
1624493696.265415: {"type":"l2_updates","symbol":"BTCGBP","changes":[["buy","24173.83","0"],["sell","24286.21","0"],["sell","24211.07","0"]]}
1624493696.265516: {"type":"l2_updates","symbol":"ETHEUR","changes":[["buy","1648.70","0"]]}
1624493696.265724: {"type":"l2_updates","symbol":"FILUSD","changes":[["sell","58.8096","0"],["sell","58.8265","134.3"],["sell","58.7255","0"],["sell","58.7555","67.7"]]}
1624493696.268563: {"type":"l2_updates","symbol":"ANKRUSD","changes":[["buy","0.08001","0"],["buy","0.07989","0"],["sell","0.08049","0"]]}
1624493696.363872: {"type":"l2_updates","symbol":"BTCGBP","changes":[["sell","24258.79","0.062"]]}
1624493696.3673348: {"type":"l2_updates","symbol":"FILUSD","changes":[["sell","58.7314","13.9"],["sell","58.7555","53.8"]]}
1624493696.464819: {"type":"l2_updates","symbol":"BTCGBP","changes":[["buy","24174.01","0.04"],["sell","24206.51","0.91"],["sell","24208.56","0"],["sell","24206.50","0.04"],["sell","24208.55","0"]]}
1624493696.4670908: {"type":"l2_updates","symbol":"BATBTC","changes":[["buy","0.00001583","1417.55033"]]}
1624493696.46891: {"type":"l2_updates","symbol":"GRTUSD","changes":[["buy","0.6173","89.99"]]}
1624493696.56598: {"type":"l2_updates","symbol":"FILUSD","changes":[["sell","59.1527","0"]]}
1624493696.5685089: {"type":"l2_updates","symbol":"GRTUSD","changes":[["buy","0.6168","89.99"]]}
1624493696.568581: {"type":"l2_updates","symbol":"ALCXUSD","changes":[["buy","302.79","0"],["sell","304.50","0"]]}
1624493696.664414: {"type":"l2_updates","symbol":"BTCGBP","changes":[["buy","24174.01","0"],["buy","24170.71","0.04"],["buy","24166.46","0"],["buy","24159.83","0.91"],["buy","24175.49","0"],["buy","24180.61","0"],["sell","24204.05","0.91"],["sell","24286.24","0"],["sell","24206.51","0"],["sell","24206.50","0"],["sell","24252.41","3.2637"],["sell","24258.81","0"],["sell","24204.04","0.04"]]}
1624493696.670838: {"type":"l2_updates","symbol":"ALCXUSD","changes":[["buy","302.54","3.290316"],["sell","304.21","6.581816"]]}
1624493696.763714: {"type":"l2_updates","symbol":"BTCGBP","changes":[["buy","24167.09","0.14807396"],["buy","24161.96","0.29615124"],["sell","24230.54","1.18464677"]]}
1624493696.86654: {"type":"l2_updates","symbol":"FILUSD","changes":[["buy","58.5897","0"],["buy","58.6419","0"]]}
1624493696.869175: {"type":"heartbeat","timestamp":1624493696871}
1624493696.965716: {"type":"l2_updates","symbol":"FILUSD","changes":[["sell","58.7315","0"]]}
1624493697.2630029: {"type":"l2_updates","symbol":"LTCETH","changes":[["sell","0.0663","0"]]}
1624493697.2631261: {"type":"l2_updates","symbol":"BATBTC","changes":[["buy","0.00001584","1417.55033"]]}
1624493697.267694: {"type":"l2_updates","symbol":"ANKRUSD","changes":[["sell","0.0804","43702.978422"]]}
1624493697.365578: {"type":"l2_updates","symbol":"ETHEUR","changes":[["buy","1647.84","2.588"],["sell","1661.57","1.261"],["sell","1662.58","0"]]}
1624493697.365651: {"type":"l2_updates","symbol":"BATBTC","changes":[["buy","0.00001583","0"]]}
1624493697.365676: {"type":"l2_updates","symbol":"FILUSD","changes":[["sell","58.7762","0"]]}

