1618677986.297909: {"jsonrpc":"2.0","method":"updateOrderbook","params":{"ask":[{"price":"0.000039844","size":"0"},{"price":"0.000039850","size":"1150.2"},{"price":"0.000039915","size":"0"},{"price":"0.000039930","size":"3812.3"},{"price":"0.000040079","size":"0"},{"price":"0.000040106","size":"6736.1"}],"bid":[],"sequence":13026947,"timestamp":"2021-04-17T16:46:26.184Z","symbol":"STORJBTC"}}
1618677986.317378: {"jsonrpc":"2.0","method":"updateOrderbook","params":{"ask":[{"price":"0.00011696","size":"0"},{"price":"0.00011887","size":"29.1"},{"price":"0.00011954","size":"472.8"},{"price":"0.00011955","size":"0"},{"price":"0.00011984","size":"0"},{"price":"0.00011989","size":"1165.1"},{"price":"0.00012015","size":"0"},{"price":"0.00012019","size":"1550.2"}],"bid":[{"price":"0.00011515","size":"0"},{"price":"0.00011407","size":"40.5"}],"sequence":19113915,"timestamp":"2021-04-17T16:46:26.240Z","symbol":"XTZBTC"}}
1618677986.4125812: {"jsonrpc":"2.0","method":"updateOrderbook","params":{"ask":[{"price":"0.000026942","size":"0"}],"bid":[{"price":"0.000023963","size":"8.2"}],"sequence":1389843,"timestamp":"2021-04-17T16:46:26.276Z","symbol":"HEDGBTC"}}
1618677986.412734: {"jsonrpc":"2.0","method":"updateOrderbook","params":{"ask":[],"bid":[{"price":"0.00011514","size":"0"}],"sequence":19113916,"timestamp":"2021-04-17T16:46:26.316Z","symbol":"XTZBTC"}}
1618677986.415225: {"jsonrpc":"2.0","method":"updateOrderbook","params":{"ask":[{"price":"0.2201769","size":"0"},{"price":"0.2202894","size":"300.00"}],"bid":[],"sequence":4920740,"timestamp":"2021-04-17T16:46:26.264Z","symbol":"BNBETH"}}
1618677986.507477: {"jsonrpc":"2.0","method":"updateOrderbook","params":{"ask":[{"price":"0.000026940","size":"562.4"},{"price":"0.000026941","size":"0"},{"price":"0.000030785","size":"326.6"}],"bid":[],"sequence":1389844,"timestamp":"2021-04-17T16:46:26.410Z","symbol":"HEDGBTC"}}
1618677986.5076532: {"jsonrpc":"2.0","method":"updateOrderbook","params":{"ask":[{"price":"0.000039882","size":"2795.3"},{"price":"0.000039893","size":"0"},{"price":"0.000040106","size":"0"},{"price":"0.000040135","size":"6736.1"},{"price":"0.000040479","size":"0"},{"price":"0.000040516","size":"13527.3"}],"bid":[],"sequence":13026948,"timestamp":"2021-04-17T16:46:26.384Z","symbol":"STORJBTC"}}
1618677986.5077891: {"jsonrpc":"2.0","method":"updateOrderbook","params":{"ask":[],"bid":[{"price":"0.00011476","size":"40.5"},{"price":"0.00011407","size":"0"},{"price":"0.00011011","size":"0"},{"price":"0.00010924","size":"380.0"}],"sequence":19113917,"timestamp":"2021-04-17T16:46:26.439Z","symbol":"XTZBTC"}}
1618677986.6200051: {"jsonrpc":"2.0","method":"updateOrderbook","params":{"ask":[{"price":"0.00011954","size":"94.0"},{"price":"0.00011955","size":"378.8"}],"bid":[],"sequence":19113918,"timestamp":"2021-04-17T16:46:26.480Z","symbol":"XTZBTC"}}
1618677986.692675: {"jsonrpc":"2.0","method":"updateOrderbook","params":{"ask":[{"price":"0.000026939","size":"91.1"},{"price":"0.000030785","size":"0"}],"bid":[{"price":"0.000023964","size":"1.2"}],"sequence":1389845,"timestamp":"2021-04-17T16:46:26.630Z","symbol":"HEDGBTC"}}
1618677986.710409: {"jsonrpc":"2.0","method":"updateOrderbook","params":{"ask":[{"price":"0.00011986","size":"1545.1"},{"price":"0.00011989","size":"0"},{"price":"0.00012002","size":"1253.2"},{"price":"0.00012016","size":"1550.2"},{"price":"0.00012019","size":"0"},{"price":"0.00012020","size":"0"}],"bid":[{"price":"0.00010924","size":"0"},{"price":"0.00010670","size":"234.3"},{"price":"0.00010164","size":"380.0"}],"sequence":19113919,"timestamp":"2021-04-17T16:46:26.647Z","symbol":"XTZBTC"}}
1618677986.792167: {"jsonrpc":"2.0","method":"updateOrderbook","params":{"ask":[{"price":"0.000039913","size":"4004.1"},{"price":"0.000039930","size":"0"},{"price":"0.000040205","size":"9299.9"},{"price":"0.000040235","size":"0"}],"bid":[],"sequence":13026949,"timestamp":"2021-04-17T16:46:26.694Z","symbol":"STORJBTC"}}
1618677986.894985: {"jsonrpc":"2.0","method":"updateOrderbook","params":{"ask":[{"price":"0.000039823","size":"1829.4"},{"price":"0.000039827","size":"0"},{"price":"0.000039852","size":"2594.7"},{"price":"0.000039857","size":"0"},{"price":"0.000039894","size":"3024.0"},{"price":"0.000039895","size":"0"},{"price":"0.000039907","size":"3633.3"},{"price":"0.000039912","size":"0"},{"price":"0.000039957","size":"4569.9"},{"price":"0.000039962","size":"0"}],"bid":[],"sequence":13026950,"timestamp":"2021-04-17T16:46:26.842Z","symbol":"STORJBTC"}}
1618677986.90698: {"jsonrpc":"2.0","method":"updateOrderbook","params":{"ask":[{"price":"0.00015486","size":"0"},{"price":"0.00015654","size":"38237.8"}],"bid":[{"price":"0.00011514","size":"11.1"}],"sequence":19113920,"timestamp":"2021-04-17T16:46:26.802Z","symbol":"XTZBTC"}}
1618677986.991908: {"jsonrpc":"2.0","method":"updateOrderbook","params":{"ask":[],"bid":[{"price":"0.000023963","size":"0"}],"sequence":1389846,"timestamp":"2021-04-17T16:46:26.866Z","symbol":"HEDGBTC"}}
1618677986.995318: {"jsonrpc":"2.0","method":"updateOrderbook","params":{"ask":[{"price":"0.000040015","size":"5695.8"},{"price":"0.000040063","size":"0"}],"bid":[{"price":"0.000038346","size":"0"}],"sequence":13026951,"timestamp":"2021-04-17T16:46:26.936Z","symbol":"STORJBTC"}}
1618677987.005387: {"jsonrpc":"2.0","method":"updateOrderbook","params":{"ask":[{"price":"0.00011973","size":"2329.3"},{"price":"0.00011976","size":"2963.0"},{"price":"0.00011988","size":"0"},{"price":"0.00012026","size":"4416.4"}],"bid":[{"price":"0.00011515","size":"40.5"},{"price":"0.00011476","size":"0"}],"sequence":19113921,"timestamp":"2021-04-17T16:46:26.928Z","symbol":"XTZBTC"}}
1618677987.0265641: {"jsonrpc":"2.0","method":"updateOrderbook","params":{"ask":[],"bid":[{"price":"0.2153437","size":"7.00"},{"price":"0.2151180","size":"0"}],"sequence":4920741,"timestamp":"2021-04-17T16:46:26.877Z","symbol":"BNBETH"}}
1618677987.095328: {"jsonrpc":"2.0","method":"updateOrderbook","params":{"ask":[{"price":"0.000039817","size":"1829.4"},{"price":"0.000039823","size":"0"},{"price":"0.000039836","size":"2594.7"},{"price":"0.000039852","size":"0"},{"price":"0.000039863","size":"3024.0"},{"price":"0.000039894","size":"0"},{"price":"0.000039923","size":"3785.4"},{"price":"0.000039957","size":"784.5"},{"price":"0.000039979","size":"4153.1"},{"price":"0.000039991","size":"0"},{"price":"0.000040142","size":"5378.5"},{"price":"0.000040185","size":"0"}],"bid":[{"price":"0.000038348","size":"156.4"}],"sequence":13026952,"timestamp":"2021-04-17T16:46:27.048Z","symbol":"STORJBTC"}}
1618677987.1153631: {"jsonrpc":"2.0","method":"updateOrderbook","params":{"ask":[{"price":"0.00133401","size":"10.00"},{"price":"0.00133405","size":"0"}],"bid":[{"price":"0.00016202","size":"10.00"},{"price":"0.00016201","size":"0"}],"sequence":10038642,"timestamp":"2021-04-17T16:46:27.035Z","symbol":"SUNBTC"}}
1618677987.209622: {"jsonrpc":"2.0","method":"updateOrderbook","params":{"ask":[],"bid":[{"price":"0.000038348","size":"0"}],"sequence":13026953,"timestamp":"2021-04-17T16:46:27.133Z","symbol":"STORJBTC"}}
1618677987.20976: {"jsonrpc":"2.0","method":"updateOrderbook","params":{"ask":[{"price":"0.00011942","size":"286.5"},{"price":"0.00011944","size":"251.9"},{"price":"0.00011950","size":"0"},{"price":"0.00011952","size":"1337.8"},{"price":"0.00011957","size":"728.3"},{"price":"0.00011962","size":"2380.9"},{"price":"0.00012019","size":"1165.8"},{"price":"0.00012031","size":"0"}],"bid":[],"sequence":19113922,"timestamp":"2021-04-17T16:46:27.114Z","symbol":"XTZBTC"}}
1618677987.298025: {"jsonrpc":"2.0","method":"updateOrderbook","params":{"ask":[{"price":"0.000039817","size":"0"},{"price":"0.000039823","size":"1829.4"},{"price":"0.000039836","size":"0"},{"price":"0.000039852","size":"2594.7"},{"price":"0.000039863","size":"0"},{"price":"0.000039894","size":"3024.0"},{"price":"0.000039923","size":"0"},{"price":"0.000039957","size":"4569.9"},{"price":"0.000039979","size":"0"},{"price":"0.000039991","size":"4153.1"},{"price":"0.000040142","size":"0"},{"price":"0.000040177","size":"5378.5"}],"bid":[{"price":"0.000038352","size":"156.4"}],"sequence":13026954,"timestamp":"2021-04-17T16:46:27.238Z","symbol":"STORJBTC"}}
1618677987.314954: {"jsonrpc":"2.0","method":"updateOrderbook","params":{"ask":[{"price":"0.00011942","size":"1876.2"},{"price":"0.00011944","size":"0"},{"price":"0.00011950","size":"728.3"},{"price":"0.00011952","size":"565.8"},{"price":"0.00011957","size":"0"},{"price":"0.00011958","size":"345.5"},{"price":"0.00011961","size":"0"},{"price":"0.00011962","size":"1815.1"},{"price":"0.00011995","size":"3675.0"},{"price":"0.00012076","size":"0"},{"price":"0.00012077","size":"4799.2"},{"price":"0.00012087","size":"0"}],"bid":[],"sequence":19113923,"timestamp":"2021-04-17T16:46:27.237Z","symbol":"XTZBTC"}}
1618677987.3915899: {"jsonrpc":"2.0","method":"updateOrderbook","params":{"ask":[],"bid":[{"price":"0.000023964","size":"9.4"}],"sequence":1389847,"timestamp":"2021-04-17T16:46:27.261Z","symbol":"HEDGBTC"}}
1618677987.3968709: {"jsonrpc":"2.0","method":"updateOrderbook","params":{"ask":[{"price":"0.000039823","size":"0"},{"price":"0.000039828","size":"1829.4"},{"price":"0.000039852","size":"0"},{"price":"0.000039858","size":"2699.2"},{"price":"0.000039894","size":"0"},{"price":"0.000039895","size":"3024.0"},{"price":"0.000039907","size":"0"},{"price":"0.000039910","size":"3633.3"},{"price":"0.000039957","size":"784.5"},{"price":"0.000039962","size":"3785.4"}],"bid":[{"price":"0.000038352","size":"0"},{"price":"0.000038346","size":"156.4"}],"sequence":13026955,"timestamp":"2021-04-17T16:46:27.336Z","symbol":"STORJBTC"}}
1618677987.4912179: {"jsonrpc":"2.0","method":"updateOrderbook","params":{"ask":[{"price":"0.000039812","size":"261.3"},{"price":"0.000039825","size":"0"},{"price":"0.000039832","size":"1150.2"},{"price":"0.000039850","size":"0"},{"price":"0.000039854","size":"2594.7"},{"price":"0.000039858","size":"104.5"},{"price":"0.000039894","size":"3024.0"},{"price":"0.000039895","size":"0"},{"price":"0.000039907","size":"3633.3"},{"price":"0.000039910","size":"0"},{"price":"0.000039957","size":"4569.9"},{"price":"0.000039962","size":"0"}],"bid":[],"sequence":13026956,"timestamp":"2021-04-17T16:46:27.441Z","symbol":"STORJBTC"}}
1618677987.511394: {"jsonrpc":"2.0","method":"updateOrderbook","params":{"ask":[{"price":"0.00011696","size":"29.1"},{"price":"0.00011887","size":"0"}],"bid":[],"sequence":19113924,"timestamp":"2021-04-17T16:46:27.446Z","symbol":"XTZBTC"}}
1618677987.622724: {"jsonrpc":"2.0","method":"updateOrderbook","params":{"ask":[{"price":"0.00011696","size":"0"},{"price":"0.00011887","size":"29.1"},{"price":"0.00012095","size":"6070.5"},{"price":"0.00012170","size":"0"},{"price":"0.00012307","size":"8300.3"},{"price":"0.00012612","size":"0"}],"bid":[{"price":"0.00011516","size":"0.2"},{"price":"0.00011515","size":"0"},{"price":"0.00011407","size":"40.5"}],"sequence":19113925,"timestamp":"2021-04-17T16:46:27.517Z","symbol":"XTZBTC"}}
1618677987.62309: {"jsonrpc":"2.0","method":"updateOrderbook","params":{"ask":[],"bid":[{"price":"0.2178701","size":"100.00"},{"price":"0.2177505","size":"0"}],"sequence":4920742,"timestamp":"2021-04-17T16:46:27.455Z","symbol":"BNBETH"}}
1618677987.707614: {"jsonrpc":"2.0","method":"updateOrderbook","params":{"ask":[{"price":"0.000039783","size":"0"},{"price":"0.000039787","size":"431.7"},{"price":"0.000039822","size":"1829.4"},{"price":"0.000039828","size":"0"},{"price":"0.000039851","size":"2594.7"},{"price":"0.000039854","size":"0"},{"price":"0.000039894","size":"0"},{"price":"0.000039895","size":"3024.0"},{"price":"0.000039907","size":"0"},{"price":"0.000039909","size":"3633.3"},{"price":"0.000039957","size":"784.5"},{"price":"0.000039960","size":"3785.4"}],"bid":[],"sequence":13026957,"timestamp":"2021-04-17T16:46:27.640Z","symbol":"STORJBTC"}}
1618677987.707895: {"jsonrpc":"2.0","method":"updateOrderbook","params":{"ask":[{"price":"0.00012136","size":"4093.4"},{"price":"0.00012162","size":"0"}],"bid":[{"price":"0.00011515","size":"40.5"},{"price":"0.00011407","size":"0"},{"price":"0.00009295","size":"29124.7"},{"price":"0.00009277","size":"51349.1"}],"sequence":19113926,"timestamp":"2021-04-17T16:46:27.633Z","symbol":"XTZBTC"}}
1618677987.791164: {"jsonrpc":"2.0","method":"updateOrderbook","params":{"ask":[{"price":"0.000039822","size":"0"},{"price":"0.000039828","size":"1829.4"},{"price":"0.000039851","size":"0"},{"price":"0.000039858","size":"2699.2"},{"price":"0.000039909","size":"0"},{"price":"0.000039912","size":"3633.3"},{"price":"0.000039960","size":"0"},{"price":"0.000039965","size":"3785.4"},{"price":"0.000040036","size":"1123.9"},{"price":"0.000040205","size":"0"},{"price":"0.000040233","size":"9299.9"},{"price":"0.000040275","size":"0"}],"bid":[{"price":"0.000038348","size":"156.4"},{"price":"0.000038346","size":"0"}],"sequence":13026958,"timestamp":"2021-04-17T16:46:27.743Z","symbol":"STORJBTC"}}
1618677987.8167: {"jsonrpc":"2.0","method":"updateOrderbook","params":{"ask":[],"bid":[{"price":"0.2156391","size":"14.00"},{"price":"0.2155021","size":"0"}],"sequence":4920743,"timestamp":"2021-04-17T16:46:27.735Z","symbol":"BNBETH"}}
1618677987.888978: {"jsonrpc":"2.0","method":"updateOrderbook","params":{"ask":[{"price":"0.000026938","size":"562.4"},{"price":"0.000026940","size":"0"}],"bid":[],"sequence":1389848,"timestamp":"2021-04-17T16:46:27.823Z","symbol":"HEDGBTC"}}
1618677987.909085: {"jsonrpc":"2.0","method":"updateOrderbook","params":{"ask":[{"price":"0.00013172","size":"12500.4"},{"price":"0.00013626","size":"0"},{"price":"0.00014439","size":"17824.4"},{"price":"0.00014709","size":"0"}],"bid":[{"price":"0.00009341","size":"47395.1"},{"price":"0.00009277","size":"0"}],"sequence":19113927,"timestamp":"2021-04-17T16:46:27.819Z","symbol":"XTZBTC"}}
1618677987.992566: {"jsonrpc":"2.0","method":"updateOrderbook","params":{"ask":[{"price":"0.000026937","size":"91.1"},{"price":"0.000026939","size":"0"}],"bid":[],"sequence":1389849,"timestamp":"2021-04-17T16:46:27.896Z","symbol":"HEDGBTC"}}
1618677987.993122: {"jsonrpc":"2.0","method":"updateOrderbook","params":{"ask":[{"price":"0.000039870","size":"2795.3"},{"price":"0.000039882","size":"0"},{"price":"0.000039913","size":"3812.3"},{"price":"0.000039928","size":"0"},{"price":"0.000039933","size":"191.8"},{"price":"0.000039945","size":"253.5"},{"price":"0.000040111","size":"6736.1"},{"price":"0.000040135","size":"0"},{"price":"0.000040516","size":"0"},{"price":"0.000040523","size":"13527.3"}],"bid":[],"sequence":13026959,"timestamp":"2021-04-17T16:46:27.936Z","symbol":"STORJBTC"}}
1618677988.021465: {"jsonrpc":"2.0","method":"updateOrderbook","params":{"ask":[],"bid":[{"price":"0.2185536","size":"23.26"},{"price":"0.2184021","size":"0"},{"price":"0.2183236","size":"28.40"},{"price":"0.2181733","size":"0"},{"price":"0.2178678","size":"41.70"},{"price":"0.2176367","size":"0"}],"sequence":4920744,"timestamp":"2021-04-17T16:46:27.859Z","symbol":"BNBETH"}}
1618677988.108445: {"jsonrpc":"2.0","method":"updateOrderbook","params":{"ask":[{"price":"0.00011948","size":"183.3"},{"price":"0.00011952","size":"785.2"},{"price":"0.00011953","size":"0"},{"price":"0.00011959","size":"244.5"}],"bid":[],"sequence":19113928,"timestamp":"2021-04-17T16:46:27.992Z","symbol":"XTZBTC"}}
1618677988.217272: {"jsonrpc":"2.0","method":"updateOrderbook","params":{"ask":[{"price":"0.00011942","size":"286.5"},{"price":"0.00011944","size":"251.9"},{"price":"0.00011950","size":"0"},{"price":"0.00011952","size":"1557.2"},{"price":"0.00011957","size":"728.3"},{"price":"0.00011962","size":"2380.9"},{"price":"0.00012782","size":"7832.8"},{"price":"0.00012862","size":"0"}],"bid":[],"sequence":19113929,"timestamp":"2021-04-17T16:46:28.085Z","symbol":"XTZBTC"}}
1618677988.28999: {"jsonrpc":"2.0","method":"updateOrderbook","params":{"ask":[{"price":"0.000026938","size":"0"}],"bid":[],"sequence":1389850,"timestamp":"2021-04-17T16:46:28.241Z","symbol":"HEDGBTC"}}
1618677988.298762: {"jsonrpc":"2.0","method":"updateOrderbook","params":{"ask":[{"price":"0.00011948","size":"0"},{"price":"0.00011952","size":"1337.8"},{"price":"0.00011953","size":"183.3"},{"price":"0.00011958","size":"564.9"}],"bid":[{"price":"0.00011111","size":"380.0"},{"price":"0.00010164","size":"0"}],"sequence":19113930,"timestamp":"2021-04-17T16:46:28.210Z","symbol":"XTZBTC"}}
1618677988.323901: {"jsonrpc":"2.0","method":"updateOrderbook","params":{"ask":[{"price":"1.5381868","size":"0"}],"bid":[],"sequence":11642095,"timestamp":"2021-04-17T16:46:28.185Z","symbol":"MANAUSD"}}
1618677988.385352: {"jsonrpc":"2.0","method":"updateOrderbook","params":{"ask":[{"price":"0.000026936","size":"562.4"},{"price":"0.000026937","size":"0"},{"price":"0.000030785","size":"326.6"}],"bid":[],"sequence":1389851,"timestamp":"2021-04-17T16:46:28.328Z","symbol":"HEDGBTC"}}
1618677988.385529: {"jsonrpc":"2.0","method":"updateOrderbook","params":{"ask":[{"price":"0.00000001000","size":"1797000"}],"bid":[],"sequence":1757670,"timestamp":"2021-04-17T16:46:28.330Z","symbol":"BANCABTC"}}
1618677988.3928692: {"jsonrpc":"2.0","method":"updateOrderbook","params":{"ask":[{"price":"0.000039822","size":"1829.4"},{"price":"0.000039828","size":"0"},{"price":"0.000039850","size":"2594.7"},{"price":"0.000039858","size":"104.5"},{"price":"0.000039909","size":"3633.3"},{"price":"0.000039912","size":"0"},{"price":"0.000039960","size":"3785.4"},{"price":"0.000039965","size":"0"}],"bid":[],"sequence":13026960,"timestamp":"2021-04-17T16:46:28.344Z","symbol":"STORJBTC"}}
1618677988.409757: {"jsonrpc":"2.0","method":"updateOrderbook","params":{"ask":[{"price":"1.5363248","size":"5"}],"bid":[],"sequence":11642096,"timestamp":"2021-04-17T16:46:28.321Z","symbol":"MANAUSD"}}
1618677988.4871109: {"jsonrpc":"2.0","method":"updateOrderbook","params":{"ask":[{"price":"0.000026935","size":"91.1"},{"price":"0.000030785","size":"0"}],"bid":[],"sequence":1389852,"timestamp":"2021-04-17T16:46:28.389Z","symbol":"HEDGBTC"}}
1618677988.490807: {"jsonrpc":"2.0","method":"updateOrderbook","params":{"ask":[{"price":"0.000040233","size":"10542.7"},{"price":"0.000040289","size":"0"}],"bid":[],"sequence":13026961,"timestamp":"2021-04-17T16:46:28.382Z","symbol":"STORJBTC"}}
1618677988.5901902: {"jsonrpc":"2.0","method":"updateOrderbook","params":{"ask":[{"price":"0.00000001000","size":"2047000"}],"bid":[],"sequence":1757671,"timestamp":"2021-04-17T16:46:28.515Z","symbol":"BANCABTC"}}
1618677988.6051352: {"jsonrpc":"2.0","method":"updateOrderbook","params":{"ask":[{"price":"0.00133391","size":"10.00"},{"price":"0.00133401","size":"0"}],"bid":[],"sequence":10038643,"timestamp":"2021-04-17T16:46:28.484Z","symbol":"SUNBTC"}}
1618677988.605293: {"jsonrpc":"2.0","method":"updateOrderbook","params":{"ask":[{"price":"0.00011983","size":"1165.1"},{"price":"0.00011986","size":"380.0"}],"bid":[],"sequence":19113931,"timestamp":"2021-04-17T16:46:28.523Z","symbol":"XTZBTC"}}
1618677988.699285: {"jsonrpc":"2.0","method":"updateOrderbook","params":{"ask":[{"price":"0.00012782","size":"0"},{"price":"0.00012840","size":"7832.8"}],"bid":[],"sequence":19113932,"timestamp":"2021-04-17T16:46:28.629Z","symbol":"XTZBTC"}}
1618677988.707941: {"jsonrpc":"2.0","method":"updateOrderbook","params":{"ask":[],"bid":[],"sequence":11642097,"timestamp":"2021-04-17T16:46:28.576Z","symbol":"MANAUSD"}}
1618677988.800585: {"jsonrpc":"2.0","method":"updateOrderbook","params":{"ask":[{"price":"1.5363248","size":"0"}],"bid":[],"sequence":11642098,"timestamp":"2021-04-17T16:46:28.680Z","symbol":"MANAUSD"}}
1618677988.898328: {"jsonrpc":"2.0","method":"updateOrderbook","params":{"ask":[],"bid":[{"price":"0.00021367","size":"5.79"},{"price":"0.00014209","size":"0"}],"sequence":10038644,"timestamp":"2021-04-17T16:46:28.810Z","symbol":"SUNBTC"}}
1618677988.911057: {"jsonrpc":"2.0","method":"updateOrderbook","params":{"ask":[{"price":"1.5381567","size":"5"}],"bid":[],"sequence":11642099,"timestamp":"2021-04-17T16:46:28.844Z","symbol":"MANAUSD"}}
1618677988.98852: {"jsonrpc":"2.0","method":"updateOrderbook","params":{"ask":[{"price":"0.000026936","size":"0"}],"bid":[],"sequence":1389853,"timestamp":"2021-04-17T16:46:28.921Z","symbol":"HEDGBTC"}}
1618677988.992913: {"jsonrpc":"2.0","method":"updateOrderbook","params":{"ask":[{"price":"0.000039955","size":"3785.4"},{"price":"0.000039960","size":"0"},{"price":"0.000040157","size":"5378.5"},{"price":"0.000040177","size":"0"}],"bid":[],"sequence":13026962,"timestamp":"2021-04-17T16:46:28.933Z","symbol":"STORJBTC"}}
1618677989.001408: {"jsonrpc":"2.0","method":"updateOrderbook","params":{"ask":[],"bid":[],"sequence":19113933,"timestamp":"2021-04-17T16:46:28.850Z","symbol":"XTZBTC"}}
1618677989.1385212: {"jsonrpc":"2.0","method":"updateOrderbook","params":{"ask":[{"price":"0.000026934","size":"562.4"},{"price":"0.000026935","size":"0"},{"price":"0.000030785","size":"326.6"}],"bid":[],"sequence":1389854,"timestamp":"2021-04-17T16:46:28.998Z","symbol":"HEDGBTC"}}
1618677989.138695: {"jsonrpc":"2.0","method":"updateOrderbook","params":{"ask":[{"price":"0.00000000420","size":"811000"},{"price":"0.00000000450","size":"2001000"}],"bid":[],"sequence":1757672,"timestamp":"2021-04-17T16:46:28.956Z","symbol":"BANCABTC"}}
1618677989.1387782: {"jsonrpc":"2.0","method":"updateOrderbook","params":{"ask":[{"price":"0.000039870","size":"2919.5"},{"price":"0.000039874","size":"0"}],"bid":[{"price":"0.000039661","size":"0"},{"price":"0.000039649","size":"0"},{"price":"0.000039630","size":"441.5"},{"price":"0.000039603","size":"1262.0"}],"sequence":13026963,"timestamp":"2021-04-17T16:46:29.045Z","symbol":"STORJBTC"}}
1618677989.138981: {"jsonrpc":"2.0","method":"updateOrderbook","params":{"ask":[{"price":"0.00011886","size":"21.8"}],"bid":[],"sequence":19113934,"timestamp":"2021-04-17T16:46:29.015Z","symbol":"XTZBTC"}}
1618677989.139013: {"jsonrpc":"2.0","method":"updateOrderbook","params":{"ask":[{"price":"1.5393435","size":"294"},{"price":"1.5396719","size":"0"}],"bid":[],"sequence":11642100,"timestamp":"2021-04-17T16:46:29.035Z","symbol":"MANAUSD"}}
1618677989.1854951: {"jsonrpc":"2.0","method":"updateOrderbook","params":{"ask":[{"price":"0.000026933","size":"91.1"},{"price":"0.000030785","size":"0"}],"bid":[],"sequence":1389855,"timestamp":"2021-04-17T16:46:29.121Z","symbol":"HEDGBTC"}}
1618677989.192209: {"jsonrpc":"2.0","method":"updateOrderbook","params":{"ask":[],"bid":[{"price":"0.00000000369","size":"2749000"},{"price":"0.00000000359","size":"1000"},{"price":"0.00000000237","size":"11651000"},{"price":"0.00000000230","size":"1000"}],"sequence":1757673,"timestamp":"2021-04-17T16:46:29.076Z","symbol":"BANCABTC"}}
1618677989.196308: {"jsonrpc":"2.0","method":"updateOrderbook","params":{"ask":[{"price":"0.000039783","size":"431.7"},{"price":"0.000039787","size":"0"},{"price":"0.000039814","size":"1829.4"},{"price":"0.000039822","size":"0"},{"price":"0.000039847","size":"2594.7"},{"price":"0.000039850","size":"0"},{"price":"0.000039890","size":"3024.0"},{"price":"0.000039895","size":"0"},{"price":"0.000039949","size":"4605.4"},{"price":"0.000039955","size":"0"}],"bid":[{"price":"0.000039644","size":"441.5"},{"price":"0.000039630","size":"0"},{"price":"0.000039629","size":"1262.0"},{"price":"0.000039603","size":"0"}],"sequence":13026964,"timestamp":"2021-04-17T16:46:29.135Z","symbol":"STORJBTC"}}
1618677989.291317: {"jsonrpc":"2.0","method":"updateOrderbook","params":{"ask":[],"bid":[{"price":"0.000038349","size":"820.0"},{"price":"0.000038348","size":"0"},{"price":"0.000035192","size":"780.0"}],"sequence":13026965,"timestamp":"2021-04-17T16:46:29.234Z","symbol":"STORJBTC"}}
1618677989.438643: {"jsonrpc":"2.0","method":"updateOrderbook","params":{"ask":[],"bid":[{"price":"0.000038352","size":"156.4"}],"sequence":13026966,"timestamp":"2021-04-17T16:46:29.297Z","symbol":"STORJBTC"}}
1618677989.514347: {"jsonrpc":"2.0","method":"updateOrderbook","params":{"ask":[{"price":"0.00011942","size":"0"},{"price":"0.00011944","size":"0"},{"price":"0.00011951","size":"286.5"},{"price":"0.00011952","size":"1589.7"},{"price":"0.00011957","size":"0"},{"price":"0.00011962","size":"3109.2"},{"price":"0.00011965","size":"296.7"},{"price":"0.00011968","size":"1279.6"},{"price":"0.00011978","size":"0"},{"price":"0.00011980","size":"1752.5"},{"price":"0.00011982","size":"4183.7"},{"price":"0.00011984","size":"2797.0"},{"price":"0.00011986","size":"0"},{"price":"0.00011992","size":"3260.8"},{"price":"0.00012059","size":"0"},{"price":"0.00012066","size":"8993.7"},{"price":"0.00012094","size":"5302.5"},{"price":"0.00012102","size":"9834.8"}],"bid":[],"sequence":19113935,"timestamp":"2021-04-17T16:46:29.414Z","symbol":"XTZBTC"}}
1618677989.5164568: {"jsonrpc":"2.0","method":"updateOrderbook","params":{"ask":[{"price":"1.5381567","size":"0"},{"price":"1.8046111","size":"0"},{"price":"1.8188786","size":"16111"},{"price":"1.9765943","size":"0"},{"price":"2.0519829","size":"0"},{"price":"2.0529809","size":"120429"},{"price":"2.0623202","size":"39773"}],"bid":[],"sequence":11642101,"timestamp":"2021-04-17T16:46:29.429Z","symbol":"MANAUSD"}}
1618677989.5959492: {"jsonrpc":"2.0","method":"updateOrderbook","params":{"ask":[{"price":"0.000039779","size":"431.7"},{"price":"0.000039783","size":"0"},{"price":"0.000039805","size":"1829.4"},{"price":"0.000039814","size":"0"},{"price":"0.000039845","size":"2594.7"},{"price":"0.000039847","size":"0"},{"price":"0.000039886","size":"3024.0"},{"price":"0.000039890","size":"0"},{"price":"0.000039943","size":"3785.4"},{"price":"0.000039949","size":"820.0"}],"bid":[],"sequence":13026967,"timestamp":"2021-04-17T16:46:29.537Z","symbol":"STORJBTC"}}
1618677989.6065989: {"jsonrpc":"2.0","method":"updateOrderbook","params":{"ask":[{"price":"0.00011969","size":"1926.2"},{"price":"0.00011972","size":"0"},{"price":"0.00011983","size":"0"},{"price":"0.00011988","size":"1165.1"}],"bid":[{"price":"0.00011514","size":"0"}],"sequence":19113936,"timestamp":"2021-04-17T16:46:29.549Z","symbol":"XTZBTC"}}
1618677989.6166122: {"jsonrpc":"2.0","method":"updateOrderbook","params":{"ask":[{"price":"1.5362048","size":"5"},{"price":"1.5393435","size":"0"}],"bid":[],"sequence":11642102,"timestamp":"2021-04-17T16:46:29.535Z","symbol":"MANAUSD"}}
1618677989.7070348: {"jsonrpc":"2.0","method":"updateOrderbook","params":{"ask":[{"price":"0.000039882","size":"176.2"},{"price":"0.000039897","size":"191.8"},{"price":"0.000039901","size":"0"},{"price":"0.000039933","size":"0"}],"bid":[],"sequence":13026968,"timestamp":"2021-04-17T16:46:29.640Z","symbol":"STORJBTC"}}
1618677989.7072299: {"jsonrpc":"2.0","method":"updateOrderbook","params":{"ask":[{"price":"0.00011984","size":"3581.6"},{"price":"0.00011992","size":"2476.2"},{"price":"0.00012298","size":"8300.3"},{"price":"0.00012307","size":"0"},{"price":"0.00013170","size":"12500.4"},{"price":"0.00013172","size":"0"},{"price":"0.00014426","size":"17824.4"},{"price":"0.00014439","size":"0"}],"bid":[{"price":"0.00011517","size":"40.5"},{"price":"0.00011515","size":"0"}],"sequence":19113937,"timestamp":"2021-04-17T16:46:29.625Z","symbol":"XTZBTC"}}
1618677989.7089028: {"jsonrpc":"2.0","method":"updateOrderbook","params":{"ask":[{"price":"1.5393435","size":"295"}],"bid":[],"sequence":11642103,"timestamp":"2021-04-17T16:46:29.631Z","symbol":"MANAUSD"}}
1618677989.7942772: {"jsonrpc":"2.0","method":"updateOrderbook","params":{"ask":[{"price":"0.000026932","size":"562.4"},{"price":"0.000026934","size":"0"}],"bid":[],"sequence":1389856,"timestamp":"2021-04-17T16:46:29.727Z","symbol":"HEDGBTC"}}
1618677989.800653: {"jsonrpc":"2.0","method":"updateOrderbook","params":{"ask":[{"price":"0.000039942","size":"5302.1"},{"price":"0.000039958","size":"0"},{"price":"0.000040206","size":"9299.9"},{"price":"0.000040233","size":"1242.8"}],"bid":[],"sequence":13026969,"timestamp":"2021-04-17T16:46:29.677Z","symbol":"STORJBTC"}}
1618677989.818309: {"jsonrpc":"2.0","method":"updateOrderbook","params":{"ask":[{"price":"1.5639598","size":"33819"},{"price":"1.5644611","size":"0"},{"price":"1.5724304","size":"32731"},{"price":"1.5730725","size":"0"},{"price":"1.5927122","size":"36462"},{"price":"1.5933170","size":"0"},{"price":"1.6134394","size":"37094"},{"price":"1.6139945","size":"0"}],"bid":[],"sequence":11642104,"timestamp":"2021-04-17T16:46:29.736Z","symbol":"MANAUSD"}}
1618677989.886258: {"jsonrpc":"2.0","method":"updateOrderbook","params":{"ask":[{"price":"0.000026931","size":"91.1"},{"price":"0.000026933","size":"0"}],"bid":[],"sequence":1389857,"timestamp":"2021-04-17T16:46:29.779Z","symbol":"HEDGBTC"}}
1618677989.892143: {"jsonrpc":"2.0","method":"updateOrderbook","params":{"ask":[{"price":"0.000039739","size":"537.3"},{"price":"0.000039740","size":"532.1"},{"price":"0.000039749","size":"0"},{"price":"0.000039754","size":"0"},{"price":"0.000039766","size":"431.7"},{"price":"0.000039779","size":"0"},{"price":"0.000039802","size":"1829.4"},{"price":"0.000039805","size":"0"},{"price":"0.000039843","size":"2594.7"},{"price":"0.000039845","size":"0"},{"price":"0.000039884","size":"3024.0"},{"price":"0.000039886","size":"0"}],"bid":[{"price":"0.000039661","size":"441.5"},{"price":"0.000039649","size":"1262.0"},{"price":"0.000039644","size":"0"},{"price":"0.000039629","size":"0"}],"sequence":13026970,"timestamp":"2021-04-17T16:46:29.842Z","symbol":"STORJBTC"}}
1618677989.8964212: {"jsonrpc":"2.0","method":"updateOrderbook","params":{"ask":[{"price":"0.00011948","size":"183.3"},{"price":"0.00011953","size":"219.4"},{"price":"0.00011958","size":"345.5"}],"bid":[{"price":"0.00011111","size":"0"},{"price":"0.00010724","size":"380.0"}],"sequence":19113938,"timestamp":"2021-04-17T16:46:29.829Z","symbol":"XTZBTC"}}
1618677989.908139: {"jsonrpc":"2.0","method":"updateOrderbook","params":{"ask":[{"price":"1.5393435","size":"294"}],"bid":[],"sequence":11642105,"timestamp":"2021-04-17T16:46:29.825Z","symbol":"MANAUSD"}}
1618677989.911307: {"jsonrpc":"2.0","method":"updateOrderbook","params":{"ask":[],"bid":[{"price":"0.2155746","size":"7.00"},{"price":"0.2154061","size":"0"}],"sequence":4920745,"timestamp":"2021-04-17T16:46:29.797Z","symbol":"BNBETH"}}
1618677989.991963: {"jsonrpc":"2.0","method":"updateOrderbook","params":{"ask":[{"price":"0.000039766","size":"0"},{"price":"0.000039770","size":"431.7"},{"price":"0.000039802","size":"0"},{"price":"0.000039814","size":"1829.4"},{"price":"0.000039843","size":"0"},{"price":"0.000039847","size":"2594.7"},{"price":"0.000039884","size":"0"},{"price":"0.000039890","size":"3024.0"},{"price":"0.000039943","size":"0"},{"price":"0.000039949","size":"4605.4"},{"price":"0.000040206","size":"0"},{"price":"0.000040236","size":"9299.9"}],"bid":[{"price":"0.000039661","size":"0"},{"price":"0.000039649","size":"0"},{"price":"0.000039632","size":"441.5"},{"price":"0.000039591","size":"1262.0"}],"sequence":13026971,"timestamp":"2021-04-17T16:46:29.941Z","symbol":"STORJBTC"}}
1618677990.1368341: {"jsonrpc":"2.0","method":"updateOrderbook","params":{"ask":[{"price":"0.00011942","size":"538.4"},{"price":"0.00011951","size":"0"},{"price":"0.00011952","size":"1337.8"},{"price":"0.00011955","size":"1107.1"},{"price":"0.00011958","size":"0"},{"price":"0.00011960","size":"345.5"},{"price":"0.00011962","size":"2380.9"},{"price":"0.00011982","size":"6980.7"},{"price":"0.00011984","size":"784.6"},{"price":"0.00012002","size":"0"},{"price":"0.00012014","size":"1253.2"},{"price":"0.00012059","size":"8993.7"},{"price":"0.00012066","size":"0"},{"price":"0.00012094","size":"15137.3"},{"price":"0.00012102","size":"0"},{"price":"0.00012136","size":"0"},{"price":"0.00012148","size":"4093.4"},{"price":"0.00012840","size":"0"},{"price":"0.00012855","size":"7832.8"}],"bid":[],"sequence":19113939,"timestamp":"2021-04-17T16:46:30.028Z","symbol":"XTZBTC"}}
1618677990.3004742: {"jsonrpc":"2.0","method":"updateOrderbook","params":{"ask":[{"price":"0.000040206","size":"9299.9"},{"price":"0.000040236","size":"0"}],"bid":[{"price":"0.000039604","size":"1262.0"},{"price":"0.000039591","size":"0"}],"sequence":13026972,"timestamp":"2021-04-17T16:46:30.128Z","symbol":"STORJBTC"}}
1618677990.300669: {"jsonrpc":"2.0","method":"updateOrderbook","params":{"ask":[{"price":"0.00133390","size":"10.00"},{"price":"0.00133391","size":"0"}],"bid":[],"sequence":10038645,"timestamp":"2021-04-17T16:46:30.073Z","symbol":"SUNBTC"}}
1618677990.300746: {"jsonrpc":"2.0","method":"updateOrderbook","params":{"ask":[{"price":"0.00011942","size":"1876.2"},{"price":"0.00011949","size":"830.9"},{"price":"0.00011952","size":"565.8"},{"price":"0.00011955","size":"378.8"},{"price":"0.00011962","size":"1815.1"}],"bid":[],"sequence":19113940,"timestamp":"2021-04-17T16:46:30.061Z","symbol":"XTZBTC"}}
1618677990.300821: {"jsonrpc":"2.0","method":"updateOrderbook","params":{"ask":[{"price":"1.5393307","size":"294"},{"price":"1.5393435","size":"0"},{"price":"1.5451278","size":"0"},{"price":"1.5455289","size":"354"}],"bid":[{"price":"1.3092640","size":"5289"},{"price":"1.3086553","size":"0"}],"sequence":11642106,"timestamp":"2021-04-17T16:46:30.130Z","symbol":"MANAUSD"}}
1618677990.369846: {"jsonrpc":"2.0","method":"updateOrderbook","params":{"ask":[{"price":"0.000026930","size":"562.4"},{"price":"0.000026932","size":"0"}],"bid":[],"sequence":1389858,"timestamp":"2021-04-17T16:46:30.235Z","symbol":"HEDGBTC"}}
1618677990.3961: {"jsonrpc":"2.0","method":"updateOrderbook","params":{"ask":[{"price":"0.000026929","size":"91.1"},{"price":"0.000026931","size":"0"}],"bid":[],"sequence":1389859,"timestamp":"2021-04-17T16:46:30.279Z","symbol":"HEDGBTC"}}
1618677990.416107: {"jsonrpc":"2.0","method":"updateOrderbook","params":{"ask":[],"bid":[{"price":"0.000039644","size":"441.5"},{"price":"0.000039632","size":"0"},{"price":"0.000039629","size":"1262.0"},{"price":"0.000039604","size":"0"}],"sequence":13026973,"timestamp":"2021-04-17T16:46:30.339Z","symbol":"STORJBTC"}}
1618677990.429109: {"jsonrpc":"2.0","method":"updateOrderbook","params":{"ask":[{"price":"1.5362048","size":"0"},{"price":"1.5381067","size":"5"}],"bid":[],"sequence":11642107,"timestamp":"2021-04-17T16:46:30.313Z","symbol":"MANAUSD"}}
1618677990.5075579: {"jsonrpc":"2.0","method":"updateOrderbook","params":{"ask":[{"price":"0.000040457","size":"13527.3"},{"price":"0.000040523","size":"0"}],"bid":[],"sequence":13026974,"timestamp":"2021-04-17T16:46:30.443Z","symbol":"STORJBTC"}}
1618677990.5077178: {"jsonrpc":"2.0","method":"updateOrderbook","params":{"ask":[{"price":"0.00011961","size":"296.7"},{"price":"0.00011965","size":"0"}],"bid":[],"sequence":19113941,"timestamp":"2021-04-17T16:46:30.370Z","symbol":"XTZBTC"}}
1618677990.590854: {"jsonrpc":"2.0","method":"updateOrderbook","params":{"ask":[],"bid":[{"price":"0.000039661","size":"441.5"},{"price":"0.000039649","size":"1262.0"},{"price":"0.000039644","size":"0"},{"price":"0.000039629","size":"0"}],"sequence":13026975,"timestamp":"2021-04-17T16:46:30.493Z","symbol":"STORJBTC"}}
1618677990.7858062: {"jsonrpc":"2.0","method":"updateOrderbook","params":{"ask":[{"price":"0.00133311","size":"10.00"},{"price":"0.00133390","size":"0"}],"bid":[],"sequence":10038646,"timestamp":"2021-04-17T16:46:30.634Z","symbol":"SUNBTC"}}
1618677990.7985978: {"jsonrpc":"2.0","method":"updateOrderbook","params":{"ask":[{"price":"0.000026928","size":"562.4"},{"price":"0.000026930","size":"0"}],"bid":[],"sequence":1389860,"timestamp":"2021-04-17T16:46:30.732Z","symbol":"HEDGBTC"}}
1618677990.813697: {"jsonrpc":"2.0","method":"updateOrderbook","params":{"ask":[],"bid":[{"price":"0.000039661","size":"0"},{"price":"0.000039651","size":"441.5"},{"price":"0.000039649","size":"0"},{"price":"0.000039639","size":"1262.0"}],"sequence":13026976,"timestamp":"2021-04-17T16:46:30.696Z","symbol":"STORJBTC"}}
1618677990.8542342: {"jsonrpc":"2.0","method":"updateOrderbook","params":{"ask":[{"price":"0.00133310","size":"26.84"},{"price":"0.00133334","size":"0"}],"bid":[],"sequence":10038647,"timestamp":"2021-04-17T16:46:30.709Z","symbol":"SUNBTC"}}
1618677990.854392: {"jsonrpc":"2.0","method":"updateOrderbook","params":{"ask":[{"price":"0.00011985","size":"1165.1"},{"price":"0.00011988","size":"0"}],"bid":[],"sequence":19113942,"timestamp":"2021-04-17T16:46:30.699Z","symbol":"XTZBTC"}}
1618677990.912191: {"jsonrpc":"2.0","method":"updateOrderbook","params":{"ask":[{"price":"0.000026927","size":"91.1"},{"price":"0.000026929","size":"0"}],"bid":[],"sequence":1389861,"timestamp":"2021-04-17T16:46:30.785Z","symbol":"HEDGBTC"}}
1618677990.926517: {"jsonrpc":"2.0","method":"updateOrderbook","params":{"ask":[{"price":"0.000039739","size":"0"},{"price":"0.000039740","size":"0"},{"price":"0.000039749","size":"537.3"},{"price":"0.000039750","size":"532.1"},{"price":"0.000039770","size":"0"},{"price":"0.000039775","size":"431.7"},{"price":"0.000039890","size":"0"},{"price":"0.000039891","size":"3024.0"}],"bid":[],"sequence":13026977,"timestamp":"2021-04-17T16:46:30.826Z","symbol":"STORJBTC"}}
1618677991.033657: {"jsonrpc":"2.0","method":"updateOrderbook","params":{"ask":[{"price":"0.000039870","size":"124.2"},{"price":"0.000039880","size":"2795.3"},{"price":"0.000040313","size":"2058.7"},{"price":"0.000040442","size":"0"}],"bid":[{"price":"0.000038356","size":"156.4"},{"price":"0.000038352","size":"0"}],"sequence":13026978,"timestamp":"2021-04-17T16:46:30.948Z","symbol":"STORJBTC"}}
1618677991.1231601: {"jsonrpc":"2.0","method":"updateOrderbook","params":{"ask":[],"bid":[{"price":"0.000038356","size":"0"}],"sequence":13026979,"timestamp":"2021-04-17T16:46:31.046Z","symbol":"STORJBTC"}}
1618677991.1459079: {"jsonrpc":"2.0","method":"updateOrderbook","params":{"ask":[{"price":"0.00011962","size":"3094.7"},{"price":"0.00011968","size":"0"}],"bid":[],"sequence":19113943,"timestamp":"2021-04-17T16:46:31.022Z","symbol":"XTZBTC"}}
1618677991.2137651: {"jsonrpc":"2.0","method":"updateOrderbook","params":{"ask":[],"bid":[{"price":"0.000038351","size":"156.4"}],"sequence":13026980,"timestamp":"2021-04-17T16:46:31.098Z","symbol":"STORJBTC"}}
1618677991.223665: {"jsonrpc":"2.0","method":"updateOrderbook","params":{"ask":[],"bid":[{"price":"0.00016219","size":"10.00"},{"price":"0.00016202","size":"0"}],"sequence":10038648,"timestamp":"2021-04-17T16:46:31.075Z","symbol":"SUNBTC"}}
1618677991.223826: {"jsonrpc":"2.0","method":"updateOrderbook","params":{"ask":[{"price":"0.00011695","size":"0.4"},{"price":"0.00011954","size":"1018.8"},{"price":"0.00011962","size":"2169.9"}],"bid":[],"sequence":19113944,"timestamp":"2021-04-17T16:46:31.125Z","symbol":"XTZBTC"}}
1618677991.289254: {"jsonrpc":"2.0","method":"updateOrderbook","params":{"ask":[{"price":"0.000026928","size":"0"}],"bid":[],"sequence":1389862,"timestamp":"2021-04-17T16:46:31.154Z","symbol":"HEDGBTC"}}
1618677991.295582: {"jsonrpc":"2.0","method":"updateOrderbook","params":{"ask":[{"price":"0.000039847","size":"0"},{"price":"0.000039848","size":"2594.7"},{"price":"0.000039891","size":"0"},{"price":"0.000039895","size":"3024.0"},{"price":"0.000039949","size":"820.0"},{"price":"0.000039955","size":"3785.4"}],"bid":[{"price":"0.000039665","size":"441.5"},{"price":"0.000039651","size":"0"},{"price":"0.000038351","size":"0"}],"sequence":13026981,"timestamp":"2021-04-17T16:46:31.220Z","symbol":"STORJBTC"}}
1618677991.310348: {"jsonrpc":"2.0","method":"updateOrderbook","params":{"ask":[{"price":"0.00133311","size":"0"},{"price":"0.00133352","size":"10.00"}],"bid":[{"price":"0.00016259","size":"10.00"},{"price":"0.00016219","size":"0"}],"sequence":10038649,"timestamp":"2021-04-17T16:46:31.212Z","symbol":"SUNBTC"}}
1618677991.310534: {"jsonrpc":"2.0","method":"updateOrderbook","params":{"ask":[{"price":"0.00014144","size":"5178.3"},{"price":"0.00014777","size":"0"}],"bid":[],"sequence":19113945,"timestamp":"2021-04-17T16:46:31.231Z","symbol":"XTZBTC"}}
1618677991.325456: {"jsonrpc":"2.0","method":"updateOrderbook","params":{"ask":[],"bid":[{"price":"0.00000107772","size":"0"}],"sequence":5061566,"timestamp":"2021-04-17T16:46:31.203Z","symbol":"CELRBTC"}}
1618677991.325593: {"jsonrpc":"2.0","method":"updateOrderbook","params":{"ask":[],"bid":[{"price":"0.2177435","size":"200.00"},{"price":"0.2176143","size":"0"},{"price":"0.2175560","size":"300.00"},{"price":"0.2174423","size":"0"}],"sequence":4920746,"timestamp":"2021-04-17T16:46:31.155Z","symbol":"BNBETH"}}
1618677991.386841: {"jsonrpc":"2.0","method":"updateOrderbook","params":{"ask":[{"price":"0.000026926","size":"562.4"},{"price":"0.000026927","size":"0"},{"price":"0.000030785","size":"326.6"}],"bid":[],"sequence":1389863,"timestamp":"2021-04-17T16:46:31.281Z","symbol":"HEDGBTC"}}
1618677991.3986611: {"jsonrpc":"2.0","method":"updateOrderbook","params":{"ask":[],"bid":[{"price":"0.000039665","size":"0"},{"price":"0.000039651","size":"441.5"},{"price":"0.000038360","size":"156.4"}],"sequence":13026982,"timestamp":"2021-04-17T16:46:31.321Z","symbol":"STORJBTC"}}
1618677991.408345: {"jsonrpc":"2.0","method":"updateOrderbook","params":{"ask":[{"price":"0.00011958","size":"345.5"},{"price":"0.00011960","size":"0"}],"bid":[],"sequence":19113946,"timestamp":"2021-04-17T16:46:31.346Z","symbol":"XTZBTC"}}
1618677991.4158652: {"jsonrpc":"2.0","method":"updateOrderbook","params":{"ask":[],"bid":[{"price":"0.00000107774","size":"18900"}],"sequence":5061567,"timestamp":"2021-04-17T16:46:31.309Z","symbol":"CELRBTC"}}
1618677991.4899268: {"jsonrpc":"2.0","method":"updateOrderbook","params":{"ask":[{"price":"0.000026925","size":"91.1"},{"price":"0.000030785","size":"0"}],"bid":[],"sequence":1389864,"timestamp":"2021-04-17T16:46:31.377Z","symbol":"HEDGBTC"}}
1618677991.5161579: {"jsonrpc":"2.0","method":"updateOrderbook","params":{"ask":[{"price":"0.000039845","size":"2594.7"},{"price":"0.000039848","size":"0"},{"price":"0.000039891","size":"3024.0"},{"price":"0.000039895","size":"0"},{"price":"0.000039949","size":"4605.4"},{"price":"0.000039955","size":"0"},{"price":"0.000040890","size":"2812.0"},{"price":"0.000041371","size":"0"}],"bid":[{"price":"0.000038360","size":"0"},{"price":"0.000038351","size":"156.4"}],"sequence":13026983,"timestamp":"2021-04-17T16:46:31.445Z","symbol":"STORJBTC"}}
1618677991.516423: {"jsonrpc":"2.0","method":"updateOrderbook","params":{"ask":[],"bid":[{"price":"0.00000107773","size":"0"}],"sequence":5061568,"timestamp":"2021-04-17T16:46:31.410Z","symbol":"CELRBTC"}}
1618677991.60229: {"jsonrpc":"2.0","method":"updateOrderbook","params":{"ask":[{"price":"0.00011965","size":"1720.5"},{"price":"0.00011980","size":"32.0"},{"price":"0.00011993","size":"3485.4"},{"price":"0.00011998","size":"0"},{"price":"0.00014144","size":"1.9"},{"price":"0.00014253","size":"5176.4"}],"bid":[],"sequence":19113947,"timestamp":"2021-04-17T16:46:31.511Z","symbol":"XTZBTC"}}
1618677991.609731: {"jsonrpc":"2.0","method":"updateOrderbook","params":{"ask":[],"bid":[{"price":"0.00000107393","size":"2100"}],"sequence":5061569,"timestamp":"2021-04-17T16:46:31.472Z","symbol":"CELRBTC"}}
1618677991.7129831: {"jsonrpc":"2.0","method":"updateOrderbook","params":{"ask":[{"price":"0.00133352","size":"0"},{"price":"0.00133429","size":"10.00"}],"bid":[],"sequence":10038650,"timestamp":"2021-04-17T16:46:31.599Z","symbol":"SUNBTC"}}
1618677991.713482: {"jsonrpc":"2.0","method":"updateOrderbook","params":{"ask":[{"price":"0.00011979","size":"2053.5"},{"price":"0.00011982","size":"4927.2"},{"price":"0.00011984","size":"2880.8"},{"price":"0.00011992","size":"380.0"},{"price":"0.00012002","size":"1253.2"},{"price":"0.00012006","size":"3537.9"},{"price":"0.00012009","size":"0"},{"price":"0.00012014","size":"0"},{"price":"0.00012021","size":"4416.4"},{"price":"0.00012026","size":"0"},{"price":"0.00014426","size":"0"},{"price":"0.00014438","size":"17824.4"}],"bid":[],"sequence":19113948,"timestamp":"2021-04-17T16:46:31.638Z","symbol":"XTZBTC"}}
1618677991.791368: {"jsonrpc":"2.0","method":"updateOrderbook","params":{"ask":[{"price":"0.00000000420","size":"0"},{"price":"0.00000000450","size":"2812000"}],"bid":[],"sequence":1757674,"timestamp":"2021-04-17T16:46:31.685Z","symbol":"BANCABTC"}}
1618677991.79872: {"jsonrpc":"2.0","method":"updateOrderbook","params":{"ask":[],"bid":[{"price":"0.000038353","size":"156.4"},{"price":"0.000038351","size":"0"}],"sequence":13026984,"timestamp":"2021-04-17T16:46:31.713Z","symbol":"STORJBTC"}}
1618677991.8895638: {"jsonrpc":"2.0","method":"updateOrderbook","params":{"ask":[],"bid":[{"price":"0.00000000369","size":"310000"},{"price":"0.00000000359","size":"2440000"},{"price":"0.00000000237","size":"1000"},{"price":"0.00000000230","size":"11651000"}],"sequence":1757675,"timestamp":"2021-04-17T16:46:31.769Z","symbol":"BANCABTC"}}
1618677991.8897128: {"jsonrpc":"2.0","method":"updateOrderbook","params":{"ask":[{"price":"0.000040080","size":"6736.1"},{"price":"0.000040111","size":"0"}],"bid":[],"sequence":13026985,"timestamp":"2021-04-17T16:46:31.781Z","symbol":"STORJBTC"}}
1618677991.905897: {"jsonrpc":"2.0","method":"updateOrderbook","params":{"ask":[{"price":"0.00012002","size":"0"},{"price":"0.00012008","size":"1253.2"}],"bid":[],"sequence":19113949,"timestamp":"2021-04-17T16:46:31.772Z","symbol":"XTZBTC"}}
1618677991.9137092: {"jsonrpc":"2.0","method":"updateOrderbook","params":{"ask":[],"bid":[{"price":"0.00000107393","size":"0"}],"sequence":5061570,"timestamp":"2021-04-17T16:46:31.849Z","symbol":"CELRBTC"}}
1618677991.916867: {"jsonrpc":"2.0","method":"updateOrderbook","params":{"ask":[],"bid":[{"price":"0.2171957","size":"66.78"},{"price":"0.2168192","size":"0"}],"sequence":4920747,"timestamp":"2021-04-17T16:46:31.836Z","symbol":"BNBETH"}}
1618677992.030305: {"jsonrpc":"2.0","method":"updateOrderbook","params":{"ask":[],"bid":[{"price":"0.00016259","size":"0"},{"price":"0.00016257","size":"10.00"}],"sequence":10038651,"timestamp":"2021-04-17T16:46:31.858Z","symbol":"SUNBTC"}}
1618677992.030463: {"jsonrpc":"2.0","method":"updateOrderbook","params":{"ask":[{"price":"0.00012002","size":"1253.2"},{"price":"0.00012008","size":"0"}],"bid":[],"sequence":19113950,"timestamp":"2021-04-17T16:46:31.903Z","symbol":"XTZBTC"}}
1618677992.0305521: {"jsonrpc":"2.0","method":"updateOrderbook","params":{"ask":[],"bid":[{"price":"0.00000107775","size":"2100"}],"sequence":5061571,"timestamp":"2021-04-17T16:46:31.908Z","symbol":"CELRBTC"}}
1618677992.087759: {"jsonrpc":"2.0","method":"updateOrderbook","params":{"ask":[{"price":"0.0000017055","size":"341"},{"price":"0.0000017056","size":"0"}],"bid":[],"sequence":403551,"timestamp":"2021-04-17T16:46:32.009Z","symbol":"ACDBTC"}}
1618677992.087923: {"jsonrpc":"2.0","method":"updateOrderbook","params":{"ask":[{"price":"0.000026924","size":"562.4"},{"price":"0.000026926","size":"0"}],"bid":[{"price":"0.000023964","size":"8.2"}],"sequence":1389865,"timestamp":"2021-04-17T16:46:32.041Z","symbol":"HEDGBTC"}}
1618677992.096627: {"jsonrpc":"2.0","method":"updateOrderbook","params":{"ask":[{"price":"0.000039806","size":"1829.4"},{"price":"0.000039814","size":"0"},{"price":"0.000039843","size":"2594.7"},{"price":"0.000039845","size":"0"},{"price":"0.000039886","size":"3024.0"},{"price":"0.000039891","size":"0"},{"price":"0.000039942","size":"0"},{"price":"0.000039943","size":"3785.4"},{"price":"0.000039949","size":"820.0"},{"price":"0.000039958","size":"5302.1"},{"price":"0.000040080","size":"0"},{"price":"0.000040108","size":"6736.1"},{"price":"0.000040206","size":"0"},{"price":"0.000040238","size":"9299.9"},{"price":"0.000040457","size":"0"},{"price":"0.000040487","size":"13527.3"}],"bid":[],"sequence":13026986,"timestamp":"2021-04-17T16:46:32.046Z","symbol":"STORJBTC"}}
1618677992.106722: {"jsonrpc":"2.0","method":"updateOrderbook","params":{"ask":[],"bid":[{"price":"0.00011516","size":"0"},{"price":"0.00011163","size":"380.0"},{"price":"0.00010724","size":"0"}],"sequence":19113951,"timestamp":"2021-04-17T16:46:31.976Z","symbol":"XTZBTC"}}
1618677992.1852522: {"jsonrpc":"2.0","method":"updateOrderbook","params":{"ask":[{"price":"0.000026923","size":"91.1"},{"price":"0.000026925","size":"0"}],"bid":[],"sequence":1389866,"timestamp":"2021-04-17T16:46:32.079Z","symbol":"HEDGBTC"}}
1618677992.192794: {"jsonrpc":"2.0","method":"updateOrderbook","params":{"ask":[{"price":"0.000039913","size":"0"},{"price":"0.000039932","size":"3812.3"},{"price":"0.000040108","size":"0"},{"price":"0.000040153","size":"6736.1"},{"price":"0.000040487","size":"0"},{"price":"0.000040520","size":"13527.3"}],"bid":[],"sequence":13026987,"timestamp":"2021-04-17T16:46:32.068Z","symbol":"STORJBTC"}}
1618677992.2027268: {"jsonrpc":"2.0","method":"updateOrderbook","params":{"ask":[{"price":"0.00012172","size":"12140.3"},{"price":"0.00012186","size":"0"},{"price":"0.00012267","size":"11096.2"},{"price":"0.00012283","size":"0"}],"bid":[{"price":"0.00011517","size":"0"},{"price":"0.00011476","size":"40.5"}],"sequence":19113952,"timestamp":"2021-04-17T16:46:32.116Z","symbol":"XTZBTC"}}
1618677992.310833: {"jsonrpc":"2.0","method":"updateOrderbook","params":{"ask":[{"price":"0.00014438","size":"0"},{"price":"0.00014440","size":"19324.4"}],"bid":[],"sequence":19113953,"timestamp":"2021-04-17T16:46:32.191Z","symbol":"XTZBTC"}}
1618677992.403577: {"jsonrpc":"2.0","method":"updateOrderbook","params":{"ask":[],"bid":[{"price":"0.00011163","size":"0"},{"price":"0.00011108","size":"380.6"}],"sequence":19113954,"timestamp":"2021-04-17T16:46:32.292Z","symbol":"XTZBTC"}}
1618677992.505067: {"jsonrpc":"2.0","method":"updateOrderbook","params":{"ask":[{"price":"0.0000006164","size":"0"}],"bid":[],"sequence":403552,"timestamp":"2021-04-17T16:46:32.351Z","symbol":"ACDBTC"}}
1618677992.507325: {"jsonrpc":"2.0","method":"updateOrderbook","params":{"ask":[{"price":"0.000039921","size":"3812.3"},{"price":"0.000039932","size":"0"},{"price":"0.000040473","size":"13527.3"},{"price":"0.000040520","size":"0"}],"bid":[],"sequence":13026988,"timestamp":"2021-04-17T16:46:32.389Z","symbol":"STORJBTC"}}
1618677992.507612: {"jsonrpc":"2.0","method":"updateOrderbook","params":{"ask":[{"price":"0.00011947","size":"183.3"},{"price":"0.00011948","size":"0"}],"bid":[{"price":"0.00011108","size":"0.6"},{"price":"0.00010670","size":"614.3"}],"sequence":19113955,"timestamp":"2021-04-17T16:46:32.446Z","symbol":"XTZBTC"}}
1618677992.5883: {"jsonrpc":"2.0","method":"updateOrderbook","params":{"ask":[{"price":"0.000026922","size":"562.4"},{"price":"0.000026924","size":"0"}],"bid":[],"sequence":1389867,"timestamp":"2021-04-17T16:46:32.533Z","symbol":"HEDGBTC"}}
1618677992.60762: {"jsonrpc":"2.0","method":"updateOrderbook","params":{"ask":[{"price":"0.00014424","size":"17824.4"},{"price":"0.00014440","size":"1500.0"}],"bid":[{"price":"0.00011505","size":"0.1"},{"price":"0.00010670","size":"234.3"},{"price":"0.00010662","size":"380.0"}],"sequence":19113956,"timestamp":"2021-04-17T16:46:32.519Z","symbol":"XTZBTC"}}
1618677992.707674: {"jsonrpc":"2.0","method":"updateOrderbook","params":{"ask":[{"price":"0.0000006160","size":"217"}],"bid":[],"sequence":403553,"timestamp":"2021-04-17T16:46:32.590Z","symbol":"ACDBTC"}}
1618677992.707906: {"jsonrpc":"2.0","method":"updateOrderbook","params":{"ask":[{"price":"0.000026921","size":"91.1"},{"price":"0.000026923","size":"0"}],"bid":[{"price":"0.000023965","size":"1.2"}],"sequence":1389868,"timestamp":"2021-04-17T16:46:32.612Z","symbol":"HEDGBTC"}}
1618677992.708075: {"jsonrpc":"2.0","method":"updateOrderbook","params":{"ask":[{"price":"0.00011954","size":"924.8"},{"price":"0.00011955","size":"472.8"},{"price":"0.00011958","size":"0"},{"price":"0.00011960","size":"345.5"},{"price":"0.00012002","size":"0"},{"price":"0.00012012","size":"2137.2"},{"price":"0.00012141","size":"4093.4"},{"price":"0.00012148","size":"0"}],"bid":[{"price":"0.00011477","size":"20.2"},{"price":"0.00011475","size":"0"}],"sequence":19113957,"timestamp":"2021-04-17T16:46:32.643Z","symbol":"XTZBTC"}}
1618677992.795275: {"jsonrpc":"2.0","method":"updateOrderbook","params":{"ask":[{"price":"0.000040036","size":"0"},{"price":"0.000040219","size":"1123.9"},{"price":"0.000040233","size":"0"},{"price":"0.000040289","size":"1242.8"},{"price":"0.000040313","size":"0"},{"price":"0.000040438","size":"2058.7"},{"price":"0.000040890","size":"0"},{"price":"0.000041368","size":"2812.0"}],"bid":[],"sequence":13026989,"timestamp":"2021-04-17T16:46:32.716Z","symbol":"STORJBTC"}}
1618677992.806314: {"jsonrpc":"2.0","method":"updateOrderbook","params":{"ask":[{"price":"0.00012842","size":"7832.8"},{"price":"0.00012855","size":"0"}],"bid":[{"price":"0.00011478","size":"40.5"},{"price":"0.00011476","size":"0"}],"sequence":19113958,"timestamp":"2021-04-17T16:46:32.723Z","symbol":"XTZBTC"}}
1618677992.8879051: {"jsonrpc":"2.0","method":"updateOrderbook","params":{"ask":[],"bid":[{"price":"0.000023964","size":"0"}],"sequence":1389869,"timestamp":"2021-04-17T16:46:32.767Z","symbol":"HEDGBTC"}}
1618677992.900674: {"jsonrpc":"2.0","method":"updateOrderbook","params":{"ask":[{"price":"0.00011947","size":"0"},{"price":"0.00011951","size":"183.3"},{"price":"0.00011953","size":"0"},{"price":"0.00011958","size":"219.4"},{"price":"0.00011961","size":"0"},{"price":"0.00011965","size":"2017.2"},{"price":"0.00011984","size":"2096.2"},{"price":"0.00011994","size":"784.6"},{"price":"0.00014253","size":"0"},{"price":"0.00014678","size":"5176.4"}],"bid":[],"sequence":19113959,"timestamp":"2021-04-17T16:46:32.825Z","symbol":"XTZBTC"}}
1618677992.992841: {"jsonrpc":"2.0","method":"updateOrderbook","params":{"ask":[],"bid":[{"price":"0.000023965","size":"0"}],"sequence":1389870,"timestamp":"2021-04-17T16:46:32.893Z","symbol":"HEDGBTC"}}
1618677992.9930089: {"jsonrpc":"2.0","method":"updateOrderbook","params":{"ask":[{"price":"0.000039909","size":"7445.6"},{"price":"0.000039921","size":"0"},{"price":"0.000040212","size":"9299.9"},{"price":"0.000040238","size":"0"},{"price":"0.000040466","size":"13527.3"},{"price":"0.000040473","size":"0"}],"bid":[],"sequence":13026990,"timestamp":"2021-04-17T16:46:32.941Z","symbol":"STORJBTC"}}
1618677993.003847: {"jsonrpc":"2.0","method":"updateOrderbook","params":{"ask":[{"price":"0.00011948","size":"102.6"},{"price":"0.00011949","size":"728.3"},{"price":"0.00011952","size":"944.6"},{"price":"0.00011955","size":"94.0"}],"bid":[{"price":"0.00011505","size":"0"}],"sequence":19113960,"timestamp":"2021-04-17T16:46:32.886Z","symbol":"XTZBTC"}}
1618677993.096171: {"jsonrpc":"2.0","method":"updateOrderbook","params":{"ask":[],"bid":[{"price":"0.000038357","size":"156.4"},{"price":"0.000038353","size":"0"}],"sequence":13026991,"timestamp":"2021-04-17T16:46:33.004Z","symbol":"STORJBTC"}}
1618677993.1920059: {"jsonrpc":"2.0","method":"updateOrderbook","params":{"ask":[],"bid":[{"price":"0.000038357","size":"0"}],"sequence":13026992,"timestamp":"2021-04-17T16:46:33.112Z","symbol":"STORJBTC"}}
1618677993.206649: {"jsonrpc":"2.0","method":"updateOrderbook","params":{"ask":[{"price":"0.00133427","size":"10.00"},{"price":"0.00133429","size":"0"}],"bid":[],"sequence":10038652,"timestamp":"2021-04-17T16:46:33.062Z","symbol":"SUNBTC"}}
1618677993.206802: {"jsonrpc":"2.0","method":"updateOrderbook","params":{"ask":[{"price":"0.00011952","size":"565.8"},{"price":"0.00011957","size":"378.8"},{"price":"0.00012298","size":"0"},{"price":"0.00012312","size":"8300.3"},{"price":"0.00013170","size":"0"},{"price":"0.00013187","size":"12500.4"},{"price":"0.00014424","size":"0"},{"price":"0.00014451","size":"17824.4"}],"bid":[],"sequence":19113961,"timestamp":"2021-04-17T16:46:33.136Z","symbol":"XTZBTC"}}
1618677993.217298: {"jsonrpc":"2.0","method":"updateOrderbook","params":{"ask":[],"bid":[{"price":"1.3110032","size":"5289"},{"price":"1.3092640","size":"0"},{"price":"1.2505750","size":"8138"},{"price":"1.2498569","size":"0"}],"sequence":11642108,"timestamp":"2021-04-17T16:46:33.069Z","symbol":"MANAUSD"}}
1618677993.286839: {"jsonrpc":"2.0","method":"updateOrderbook","params":{"ask":[],"bid":[{"price":"0.000023962","size":"27.6"}],"sequence":1389871,"timestamp":"2021-04-17T16:46:33.164Z","symbol":"HEDGBTC"}}
1618677993.29145: {"jsonrpc":"2.0","method":"updateOrderbook","params":{"ask":[],"bid":[{"price":"0.000038351","size":"156.4"}],"sequence":13026993,"timestamp":"2021-04-17T16:46:33.161Z","symbol":"STORJBTC"}}
1618677993.4017768: {"jsonrpc":"2.0","method":"updateOrderbook","params":{"ask":[],"bid":[{"price":"0.000038353","size":"156.4"},{"price":"0.000038351","size":"0"}],"sequence":13026994,"timestamp":"2021-04-17T16:46:33.319Z","symbol":"STORJBTC"}}
1618677993.4916868: {"jsonrpc":"2.0","method":"updateOrderbook","params":{"ask":[{"price":"0.000026922","size":"0"}],"bid":[],"sequence":1389872,"timestamp":"2021-04-17T16:46:33.430Z","symbol":"HEDGBTC"}}
1618677993.4918249: {"jsonrpc":"2.0","method":"updateOrderbook","params":{"ask":[{"price":"0.000039827","size":"1150.2"},{"price":"0.000039832","size":"0"}],"bid":[],"sequence":13026995,"timestamp":"2021-04-17T16:46:33.351Z","symbol":"STORJBTC"}}
1618677993.505018: {"jsonrpc":"2.0","method":"updateOrderbook","params":{"ask":[{"price":"0.00014437","size":"17824.4"},{"price":"0.00014451","size":"0"}],"bid":[],"sequence":19113962,"timestamp":"2021-04-17T16:46:33.383Z","symbol":"XTZBTC"}}
1618677993.52413: {"jsonrpc":"2.0","method":"updateOrderbook","params":{"ask":[{"price":"0.2197315","size":"0"},{"price":"0.2198140","size":"23.26"}],"bid":[{"price":"0.2167761","size":"80.50"},{"price":"0.2162935","size":"0"}],"sequence":4920748,"timestamp":"2021-04-17T16:46:33.436Z","symbol":"BNBETH"}}
1618677993.588083: {"jsonrpc":"2.0","method":"updateOrderbook","params":{"ask":[{"price":"0.000026920","size":"562.4"},{"price":"0.000026921","size":"0"},{"price":"0.000030785","size":"326.6"}],"bid":[],"sequence":1389873,"timestamp":"2021-04-17T16:46:33.506Z","symbol":"HEDGBTC"}}
1618677993.604557: {"jsonrpc":"2.0","method":"updateOrderbook","params":{"ask":[],"bid":[{"price":"0.00011505","size":"0.1"}],"sequence":19113963,"timestamp":"2021-04-17T16:46:33.486Z","symbol":"XTZBTC"}}
1618677993.6205492: {"jsonrpc":"2.0","method":"updateOrderbook","params":{"ask":[{"price":"0.2200852","size":"0"},{"price":"0.2201955","size":"200.00"}],"bid":[{"price":"0.2157404","size":"14.00"},{"price":"0.2156391","size":"0"},{"price":"0.2155339","size":"7.00"},{"price":"0.2153437","size":"0"}],"sequence":4920749,"timestamp":"2021-04-17T16:46:33.525Z","symbol":"BNBETH"}}
1618677993.69058: {"jsonrpc":"2.0","method":"updateOrderbook","params":{"ask":[{"price":"0.000026919","size":"91.1"},{"price":"0.000030785","size":"0"}],"bid":[],"sequence":1389874,"timestamp":"2021-04-17T16:46:33.589Z","symbol":"HEDGBTC"}}
1618677993.699177: {"jsonrpc":"2.0","method":"updateOrderbook","params":{"ask":[{"price":"0.000039869","size":"2795.3"},{"price":"0.000039880","size":"0"}],"bid":[],"sequence":13026996,"timestamp":"2021-04-17T16:46:33.643Z","symbol":"STORJBTC"}}
1618677993.71377: {"jsonrpc":"2.0","method":"updateOrderbook","params":{"ask":[],"bid":[{"price":"0.00011479","size":"20.2"},{"price":"0.00011477","size":"0"}],"sequence":19113964,"timestamp":"2021-04-17T16:46:33.575Z","symbol":"XTZBTC"}}
1618677993.724046: {"jsonrpc":"2.0","method":"updateOrderbook","params":{"ask":[{"price":"0.2208698","size":"0"},{"price":"0.2212397","size":"66.77"}],"bid":[],"sequence":4920750,"timestamp":"2021-04-17T16:46:33.637Z","symbol":"BNBETH"}}
1618677993.78771: {"jsonrpc":"2.0","method":"updateOrderbook","params":{"ask":[],"bid":[{"price":"0.000023963","size":"1.2"}],"sequence":1389875,"timestamp":"2021-04-17T16:46:33.665Z","symbol":"HEDGBTC"}}
1618677993.7930188: {"jsonrpc":"2.0","method":"updateOrderbook","params":{"ask":[{"price":"0.000040431","size":"13527.3"},{"price":"0.000040466","size":"0"}],"bid":[],"sequence":13026997,"timestamp":"2021-04-17T16:46:33.705Z","symbol":"STORJBTC"}}
1618677993.8134458: {"jsonrpc":"2.0","method":"updateOrderbook","params":{"ask":[{"price":"0.00011955","size":"472.8"},{"price":"0.00011957","size":"0"}],"bid":[{"price":"0.00011480","size":"40.5"},{"price":"0.00011478","size":"0"}],"sequence":19113965,"timestamp":"2021-04-17T16:46:33.732Z","symbol":"XTZBTC"}}
1618677993.8202088: {"jsonrpc":"2.0","method":"updateOrderbook","params":{"ask":[{"price":"0.00000119569","size":"592740"},{"price":"0.00000119759","size":"0"},{"price":"0.00000120369","size":"694310"},{"price":"0.00000120446","size":"0"},{"price":"0.00000121364","size":"922200"},{"price":"0.00000121542","size":"0"}],"bid":[],"sequence":5061572,"timestamp":"2021-04-17T16:46:33.743Z","symbol":"CELRBTC"}}
1618677993.8233411: {"jsonrpc":"2.0","method":"updateOrderbook","params":{"ask":[{"price":"0.2199916","size":"0"},{"price":"0.2201111","size":"100.00"},{"price":"0.2202894","size":"0"},{"price":"0.2204040","size":"300.00"}],"bid":[],"sequence":4920751,"timestamp":"2021-04-17T16:46:33.741Z","symbol":"BNBETH"}}
1618677993.9094038: {"jsonrpc":"2.0","method":"updateOrderbook","params":{"ask":[{"price":"0.00011960","size":"0"},{"price":"0.00011962","size":"2515.4"},{"price":"0.00012012","size":"884.0"},{"price":"0.00012020","size":"1253.2"},{"price":"0.00012141","size":"0"},{"price":"0.00012154","size":"4093.4"},{"price":"0.00012842","size":"0"},{"price":"0.00012856","size":"7832.8"}],"bid":[],"sequence":19113966,"timestamp":"2021-04-17T16:46:33.790Z","symbol":"XTZBTC"}}
1618677993.9119492: {"jsonrpc":"2.0","method":"updateOrderbook","params":{"ask":[{"price":"1.5393307","size":"0"},{"price":"1.5398071","size":"294"}],"bid":[],"sequence":11642109,"timestamp":"2021-04-17T16:46:33.830Z","symbol":"MANAUSD"}}
1618677993.986301: {"jsonrpc":"2.0","method":"updateOrderbook","params":{"ask":[{"price":"0.000026920","size":"0"}],"bid":[],"sequence":1389876,"timestamp":"2021-04-17T16:46:33.939Z","symbol":"HEDGBTC"}}
1618677994.0044632: {"jsonrpc":"2.0","method":"updateOrderbook","params":{"ask":[{"price":"0.00133427","size":"0"},{"price":"0.00133434","size":"10.00"}],"bid":[],"sequence":10038653,"timestamp":"2021-04-17T16:46:33.937Z","symbol":"SUNBTC"}}
1618677994.021004: {"jsonrpc":"2.0","method":"updateOrderbook","params":{"ask":[{"price":"0.2202901","size":"0"},{"price":"0.2205283","size":"41.69"}],"bid":[],"sequence":4920752,"timestamp":"2021-04-17T16:46:33.931Z","symbol":"BNBETH"}}
1618677994.115409: {"jsonrpc":"2.0","method":"updateOrderbook","params":{"ask":[{"price":"0.000026918","size":"562.4"},{"price":"0.000026919","size":"0"},{"price":"0.000030785","size":"326.6"}],"bid":[],"sequence":1389877,"timestamp":"2021-04-17T16:46:34.017Z","symbol":"HEDGBTC"}}
1618677994.1155891: {"jsonrpc":"2.0","method":"updateOrderbook","params":{"ask":[],"bid":[{"price":"0.00016258","size":"10.00"},{"price":"0.00016257","size":"0"}],"sequence":10038654,"timestamp":"2021-04-17T16:46:34.004Z","symbol":"SUNBTC"}}
1618677994.133919: {"jsonrpc":"2.0","method":"updateOrderbook","params":{"ask":[],"bid":[{"price":"1.4800150","size":"0"}],"sequence":11642110,"timestamp":"2021-04-17T16:46:34.007Z","symbol":"MANAUSD"}}
1618677994.186949: {"jsonrpc":"2.0","method":"updateOrderbook","params":{"ask":[{"price":"0.000026917","size":"91.1"},{"price":"0.000030785","size":"0"}],"bid":[],"sequence":1389878,"timestamp":"2021-04-17T16:46:34.095Z","symbol":"HEDGBTC"}}
1618677994.198987: {"jsonrpc":"2.0","method":"updateOrderbook","params":{"ask":[{"price":"0.000040021","size":"6736.1"},{"price":"0.000040153","size":"0"}],"bid":[],"sequence":13026998,"timestamp":"2021-04-17T16:46:34.114Z","symbol":"STORJBTC"}}
1618677994.217149: {"jsonrpc":"2.0","method":"updateOrderbook","params":{"ask":[{"price":"0.00011969","size":"358.4"},{"price":"0.00011972","size":"1567.8"},{"price":"0.00011973","size":"483.6"},{"price":"0.00011976","size":"568.6"},{"price":"0.00011988","size":"1845.7"},{"price":"0.00011995","size":"0"},{"price":"0.00012026","size":"2394.4"},{"price":"0.00012076","size":"3675.0"},{"price":"0.00012077","size":"0"},{"price":"0.00012088","size":"4799.2"},{"price":"0.00012095","size":"0"},{"price":"0.00012173","size":"6070.5"},{"price":"0.00012312","size":"0"},{"price":"0.00012618","size":"8300.3"},{"price":"0.00013187","size":"0"},{"price":"0.00013637","size":"12500.4"},{"price":"0.00014437","size":"0"},{"price":"0.00014716","size":"17824.4"}],"bid":[{"price":"0.00011102","size":"380.0"},{"price":"0.00010662","size":"0"}],"sequence":19113967,"timestamp":"2021-04-17T16:46:34.129Z","symbol":"XTZBTC"}}
1618677994.24: {"jsonrpc":"2.0","method":"updateOrderbook","params":{"ask":[{"price":"0.2199706","size":"0"},{"price":"0.2201050","size":"28.39"}],"bid":[],"sequence":4920753,"timestamp":"2021-04-17T16:46:34.070Z","symbol":"BNBETH"}}
1618677994.290004: {"jsonrpc":"2.0","method":"updateOrderbook","params":{"ask":[],"bid":[{"price":"0.000023962","size":"19.4"}],"sequence":1389879,"timestamp":"2021-04-17T16:46:34.168Z","symbol":"HEDGBTC"}}
1618677994.2988858: {"jsonrpc":"2.0","method":"updateOrderbook","params":{"ask":[],"bid":[{"price":"0.000039660","size":"441.5"},{"price":"0.000039651","size":"0"}],"sequence":13026999,"timestamp":"2021-04-17T16:46:34.175Z","symbol":"STORJBTC"}}
1618677994.315508: {"jsonrpc":"2.0","method":"updateOrderbook","params":{"ask":[],"bid":[{"price":"0.00016259","size":"10.00"},{"price":"0.00016258","size":"0"}],"sequence":10038655,"timestamp":"2021-04-17T16:46:34.183Z","symbol":"SUNBTC"}}
1618677994.315666: {"jsonrpc":"2.0","method":"updateOrderbook","params":{"ask":[{"price":"0.00011963","size":"0"},{"price":"0.00011969","size":"1279.3"},{"price":"0.00011972","size":"0"},{"price":"0.00011983","size":"1567.8"},{"price":"0.00011988","size":"0"},{"price":"0.00011995","size":"1845.7"},{"price":"0.00012026","size":"0"},{"price":"0.00012070","size":"2394.4"},{"price":"0.00012088","size":"0"},{"price":"0.00012097","size":"4799.2"},{"price":"0.00012173","size":"0"},{"price":"0.00012239","size":"6070.5"},{"price":"0.00012618","size":"0"},{"price":"0.00012788","size":"8300.3"},{"price":"0.00013637","size":"0"},{"price":"0.00013704","size":"12500.4"},{"price":"0.00014716","size":"0"},{"price":"0.00014794","size":"17824.4"}],"bid":[{"price":"0.00011102","size":"0"},{"price":"0.00010657","size":"380.0"}],"sequence":19113968,"timestamp":"2021-04-17T16:46:34.244Z","symbol":"XTZBTC"}}
1618677994.335813: {"jsonrpc":"2.0","method":"updateOrderbook","params":{"ask":[{"price":"0.2201692","size":"0"},{"price":"0.2203511","size":"30.50"}],"bid":[],"sequence":4920754,"timestamp":"2021-04-17T16:46:34.227Z","symbol":"BNBETH"}}
1618677994.400379: {"jsonrpc":"2.0","method":"updateOrderbook","params":{"ask":[{"price":"0.000039775","size":"0"},{"price":"0.000039778","size":"431.7"},{"price":"0.000039806","size":"0"},{"price":"0.000039807","size":"1829.4"}],"bid":[],"sequence":13027000,"timestamp":"2021-04-17T16:46:34.332Z","symbol":"STORJBTC"}}
1618677994.500059: {"jsonrpc":"2.0","method":"updateOrderbook","params":{"ask":[{"price":"0.000039805","size":"261.3"},{"price":"0.000039812","size":"0"}],"bid":[{"price":"0.000039660","size":"0"},{"price":"0.000039651","size":"441.5"}],"sequence":13027001,"timestamp":"2021-04-17T16:46:34.360Z","symbol":"STORJBTC"}}
1618677994.539071: {"jsonrpc":"2.0","method":"updateOrderbook","params":{"ask":[],"bid":[{"price":"0.2160107","size":"110.02"},{"price":"0.2156634","size":"125.73"},{"price":"0.2153699","size":"0"},{"price":"0.2149490","size":"0"}],"sequence":4920755,"timestamp":"2021-04-17T16:46:34.361Z","symbol":"BNBETH"}}
1618677994.587787: {"jsonrpc":"2.0","method":"updateOrderbook","params":{"ask":[],"bid":[{"price":"0.000023963","size":"9.4"}],"sequence":1389880,"timestamp":"2021-04-17T16:46:34.464Z","symbol":"HEDGBTC"}}
1618677994.618975: {"jsonrpc":"2.0","method":"updateOrderbook","params":{"ask":[{"price":"0.00011946","size":"102.6"},{"price":"0.00011948","size":"0"},{"price":"0.00011951","size":"562.1"},{"price":"0.00011955","size":"94.0"}],"bid":[],"sequence":19113969,"timestamp":"2021-04-17T16:46:34.460Z","symbol":"XTZBTC"}}
1618677994.634061: {"jsonrpc":"2.0","method":"updateOrderbook","params":{"ask":[{"price":"1.5394719","size":"294"},{"price":"1.5398071","size":"0"}],"bid":[{"price":"1.4800150","size":"1"}],"sequence":11642111,"timestamp":"2021-04-17T16:46:34.542Z","symbol":"MANAUSD"}}
1618677994.6388721: {"jsonrpc":"2.0","method":"updateOrderbook","params":{"ask":[],"bid":[{"price":"0.2186536","size":"23.26"},{"price":"0.2185536","size":"0"},{"price":"0.2181859","size":"30.50"},{"price":"0.2179817","size":"0"},{"price":"0.2176103","size":"53.81"},{"price":"0.2172845","size":"0"}],"sequence":4920756,"timestamp":"2021-04-17T16:46:34.495Z","symbol":"BNBETH"}}
1618677994.720323: {"jsonrpc":"2.0","method":"updateOrderbook","params":{"ask":[{"price":"0.00011932","size":"933.9"},{"price":"0.00011941","size":"506.2"},{"price":"0.00011942","size":"436.1"},{"price":"0.00011943","size":"728.3"},{"price":"0.00011944","size":"565.8"},{"price":"0.00011949","size":"0"},{"price":"0.00011951","size":"183.3"},{"price":"0.00011952","size":"0"},{"price":"0.00011953","size":"378.8"},{"price":"0.00011991","size":"3485.4"},{"price":"0.00011993","size":"0"},{"price":"0.00012017","size":"4416.4"},{"price":"0.00012021","size":"0"},{"price":"0.00012037","size":"5128.5"},{"price":"0.00012042","size":"0"},{"price":"0.00012163","size":"12140.3"},{"price":"0.00012172","size":"0"},{"price":"0.00012435","size":"20099.1"},{"price":"0.00012449","size":"0"}],"bid":[{"price":"0.00011481","size":"20.2"},{"price":"0.00011479","size":"0"}],"sequence":19113970,"timestamp":"2021-04-17T16:46:34.633Z","symbol":"XTZBTC"}}
1618677994.839901: {"jsonrpc":"2.0","method":"updateOrderbook","params":{"ask":[{"price":"0.00011897","size":"2.3"},{"price":"0.00011907","size":"0"},{"price":"0.00011932","size":"538.4"},{"price":"0.00011933","size":"395.5"},{"price":"0.00011941","size":"0"},{"price":"0.00011942","size":"942.3"},{"price":"0.00011951","size":"0"},{"price":"0.00011952","size":"183.3"},{"price":"0.00011953","size":"0"},{"price":"0.00011954","size":"1303.6"},{"price":"0.00011965","size":"1720.5"},{"price":"0.00011967","size":"920.9"},{"price":"0.00011969","size":"0"},{"price":"0.00011973","size":"0"},{"price":"0.00011976","size":"0"},{"price":"0.00011979","size":"2350.2"},{"price":"0.00011991","size":"0"},{"price":"0.00011992","size":"738.4"},{"price":"0.00011993","size":"3485.4"},{"price":"0.00011994","size":"0"},{"price":"0.00012001","size":"483.6"},{"price":"0.00012009","size":"568.6"},{"price":"0.00012012","size":"0"},{"price":"0.00012019","size":"0"},{"price":"0.00012024","size":"784.6"},{"price":"0.00012033","size":"884.0"},{"price":"0.00012053","size":"0"},{"price":"0.00012075","size":"1165.8"},{"price":"0.00012078","size":"1629.2"},{"price":"0.00012182","size":"0"},{"price":"0.00012708","size":"3868.5"},{"price":"0.00012839","size":"7832.8"},{"price":"0.00012856","size":"0"},{"price":"0.00014678","size":"0"},{"price":"0.00017239","size":"5176.4"}],"bid":[{"price":"0.00011482","size":"40.5"},{"price":"0.00011480","size":"0"}],"sequence":19113971,"timestamp":"2021-04-17T16:46:34.742Z","symbol":"XTZBTC"}}
1618677994.84047: {"jsonrpc":"2.0","method":"updateOrderbook","params":{"ask":[{"price":"0.00000123868","size":"1107430"},{"price":"0.00000124063","size":"0"},{"price":"0.00000126876","size":"2245050"},{"price":"0.00000127074","size":"0"}],"bid":[],"sequence":5061573,"timestamp":"2021-04-17T16:46:34.748Z","symbol":"CELRBTC"}}
1618677994.8405812: {"jsonrpc":"2.0","method":"updateOrderbook","params":{"ask":[{"price":"0.2198140","size":"0"},{"price":"0.2199085","size":"23.25"}],"bid":[],"sequence":4920757,"timestamp":"2021-04-17T16:46:34.667Z","symbol":"BNBETH"}}
1618677994.901669: {"jsonrpc":"2.0","method":"updateOrderbook","params":{"ask":[{"price":"0.000039881","size":"3024.0"},{"price":"0.000039886","size":"0"},{"price":"0.000039925","size":"253.5"},{"price":"0.000039933","size":"3785.4"},{"price":"0.000039943","size":"0"},{"price":"0.000039945","size":"0"}],"bid":[],"sequence":13027002,"timestamp":"2021-04-17T16:46:34.840Z","symbol":"STORJBTC"}}
1618677994.90564: {"jsonrpc":"2.0","method":"updateOrderbook","params":{"ask":[],"bid":[{"price":"0.00016259","size":"0"},{"price":"0.00016258","size":"10.00"}],"sequence":10038656,"timestamp":"2021-04-17T16:46:34.831Z","symbol":"SUNBTC"}}
1618677994.905796: {"jsonrpc":"2.0","method":"updateOrderbook","params":{"ask":[{"price":"0.00011932","size":"933.9"},{"price":"0.00011933","size":"0"},{"price":"0.00011941","size":"506.2"},{"price":"0.00011942","size":"436.1"},{"price":"0.00011955","size":"0"},{"price":"0.00011962","size":"2169.9"},{"price":"0.00011964","size":"450.1"},{"price":"0.00011967","size":"1266.4"},{"price":"0.00011970","size":"1567.8"},{"price":"0.00011982","size":"7023.4"},{"price":"0.00011983","size":"0"},{"price":"0.00011984","size":"0"},{"price":"0.00011996","size":"911.8"},{"price":"0.00012017","size":"0"},{"price":"0.00012020","size":"0"},{"price":"0.00012021","size":"4416.4"},{"price":"0.00012038","size":"3286.7"},{"price":"0.00012044","size":"0"},{"price":"0.00012064","size":"1721.1"},{"price":"0.00012154","size":"0"},{"price":"0.00012244","size":"4093.4"},{"price":"0.00012532","size":"0"},{"price":"0.00012548","size":"5272.4"},{"price":"0.00012839","size":"0"},{"price":"0.00012886","size":"7832.8"}],"bid":[],"sequence":19113972,"timestamp":"2021-04-17T16:46:34.806Z","symbol":"XTZBTC"}}
1618677995.0019672: {"jsonrpc":"2.0","method":"updateOrderbook","params":{"ask":[],"bid":[{"price":"0.000038353","size":"0"}],"sequence":13027003,"timestamp":"2021-04-17T16:46:34.908Z","symbol":"STORJBTC"}}
1618677995.014074: {"jsonrpc":"2.0","method":"updateOrderbook","params":{"ask":[{"price":"0.00011942","size":"1001.9"},{"price":"0.00011944","size":"0"},{"price":"0.00011982","size":"4927.2"},{"price":"0.00011984","size":"2096.2"},{"price":"0.00011996","size":"0"},{"price":"0.00011999","size":"911.8"},{"price":"0.00012064","size":"0"},{"price":"0.00012072","size":"1721.1"},{"price":"0.00012163","size":"0"},{"price":"0.00012174","size":"12140.4"},{"price":"0.00012244","size":"0"},{"price":"0.00012254","size":"4093.4"},{"price":"0.00012548","size":"0"},{"price":"0.00012560","size":"5272.4"},{"price":"0.00012886","size":"0"},{"price":"0.00012903","size":"7832.8"}],"bid":[],"sequence":19113973,"timestamp":"2021-04-17T16:46:34.940Z","symbol":"XTZBTC"}}
1618677995.086721: {"jsonrpc":"2.0","method":"updateOrderbook","params":{"ask":[{"price":"0.000026916","size":"562.4"},{"price":"0.000026918","size":"0"}],"bid":[],"sequence":1389881,"timestamp":"2021-04-17T16:46:35.031Z","symbol":"HEDGBTC"}}
1618677995.099627: {"jsonrpc":"2.0","method":"updateOrderbook","params":{"ask":[],"bid":[{"price":"0.000038357","size":"156.4"}],"sequence":13027004,"timestamp":"2021-04-17T16:46:34.980Z","symbol":"STORJBTC"}}
1618677995.112677: {"jsonrpc":"2.0","method":"updateOrderbook","params":{"ask":[],"bid":[{"price":"0.00016258","size":"0"},{"price":"0.00016257","size":"10.00"}],"sequence":10038657,"timestamp":"2021-04-17T16:46:34.997Z","symbol":"SUNBTC"}}
1618677995.112841: {"jsonrpc":"2.0","method":"updateOrderbook","params":{"ask":[{"price":"0.00011922","size":"538.4"},{"price":"0.00011932","size":"901.7"},{"price":"0.00011936","size":"538.7"},{"price":"0.00011941","size":"0"},{"price":"0.00011942","size":"565.8"},{"price":"0.00011946","size":"378.8"},{"price":"0.00011954","size":"924.8"},{"price":"0.00011977","size":"2053.5"},{"price":"0.00011979","size":"296.7"},{"price":"0.00011982","size":"7023.4"},{"price":"0.00011984","size":"0"},{"price":"0.00011991","size":"3485.4"},{"price":"0.00011993","size":"0"},{"price":"0.00012021","size":"5300.4"},{"price":"0.00012033","size":"0"},{"price":"0.00012886","size":"7832.8"},{"price":"0.00012903","size":"0"}],"bid":[],"sequence":19113974,"timestamp":"2021-04-17T16:46:35.042Z","symbol":"XTZBTC"}}
1618677995.191594: {"jsonrpc":"2.0","method":"updateOrderbook","params":{"ask":[{"price":"0.000026915","size":"91.1"},{"price":"0.000026917","size":"0"}],"bid":[],"sequence":1389882,"timestamp":"2021-04-17T16:46:35.090Z","symbol":"HEDGBTC"}}
1618677995.195679: {"jsonrpc":"2.0","method":"updateOrderbook","params":{"ask":[],"bid":[{"price":"0.000038357","size":"0"}],"sequence":13027005,"timestamp":"2021-04-17T16:46:35.101Z","symbol":"STORJBTC"}}
1618677995.202997: {"jsonrpc":"2.0","method":"updateOrderbook","params":{"ask":[{"price":"0.00011973","size":"1845.7"},{"price":"0.00011980","size":"2426.4"},{"price":"0.00011995","size":"0"},{"price":"0.00012070","size":"0"}],"bid":[],"sequence":19113975,"timestamp":"2021-04-17T16:46:35.099Z","symbol":"XTZBTC"}}
1618677995.29333: {"jsonrpc":"2.0","method":"updateOrderbook","params":{"ask":[],"bid":[{"price":"0.000038351","size":"156.4"}],"sequence":13027006,"timestamp":"2021-04-17T16:46:35.155Z","symbol":"STORJBTC"}}
1618677995.310334: {"jsonrpc":"2.0","method":"updateOrderbook","params":{"ask":[],"bid":[{"price":"0.00016258","size":"10.00"},{"price":"0.00016257","size":"0"}],"sequence":10038658,"timestamp":"2021-04-17T16:46:35.160Z","symbol":"SUNBTC"}}
1618677995.310496: {"jsonrpc":"2.0","method":"updateOrderbook","params":{"ask":[{"price":"0.00011897","size":"0"},{"price":"0.00011980","size":"32.0"},{"price":"0.00011991","size":"5879.8"},{"price":"0.00012021","size":"884.0"},{"price":"0.00012027","size":"4416.4"},{"price":"0.00012037","size":"0"},{"price":"0.00012043","size":"5588.5"},{"price":"0.00012059","size":"0"},{"price":"0.00012066","size":"8993.7"},{"price":"0.00012094","size":"5302.5"},{"price":"0.00012102","size":"9834.8"},{"price":"0.00012174","size":"0.1"},{"price":"0.00012192","size":"12140.3"},{"price":"0.00012267","size":"0"},{"price":"0.00012284","size":"11096.2"},{"price":"0.00012435","size":"0"},{"price":"0.00012453","size":"20099.1"}],"bid":[],"sequence":19113976,"timestamp":"2021-04-17T16:46:35.211Z","symbol":"XTZBTC"}}
1618677995.3993988: {"jsonrpc":"2.0","method":"updateOrderbook","params":{"ask":[{"price":"0.000039859","size":"2795.3"},{"price":"0.000039869","size":"0"}],"bid":[{"price":"0.000038353","size":"156.4"},{"price":"0.000038351","size":"0"}],"sequence":13027007,"timestamp":"2021-04-17T16:46:35.341Z","symbol":"STORJBTC"}}
1618677995.4066129: {"jsonrpc":"2.0","method":"updateOrderbook","params":{"ask":[],"bid":[{"price":"0.00021367","size":"0"},{"price":"0.00019332","size":"5.79"}],"sequence":10038659,"timestamp":"2021-04-17T16:46:35.327Z","symbol":"SUNBTC"}}
1618677995.406771: {"jsonrpc":"2.0","method":"updateOrderbook","params":{"ask":[{"price":"0.00011930","size":"395.5"},{"price":"0.00011932","size":"506.2"},{"price":"0.00011934","size":"436.1"},{"price":"0.00011936","size":"102.6"},{"price":"0.00011958","size":"1140.3"},{"price":"0.00011967","size":"345.5"},{"price":"0.00011986","size":"380.0"},{"price":"0.00011992","size":"358.4"},{"price":"0.00012044","size":"4799.2"},{"price":"0.00012097","size":"0"}],"bid":[],"sequence":19113977,"timestamp":"2021-04-17T16:46:35.348Z","symbol":"XTZBTC"}}
1618677995.4964411: {"jsonrpc":"2.0","method":"updateOrderbook","params":{"ask":[{"price":"0.000039719","size":"537.3"},{"price":"0.000039720","size":"532.1"},{"price":"0.000039742","size":"431.7"},{"price":"0.000039749","size":"0"},{"price":"0.000039750","size":"0"},{"price":"0.000039778","size":"0"},{"price":"0.000039793","size":"1829.4"},{"price":"0.000039807","size":"0"},{"price":"0.000039836","size":"2594.7"},{"price":"0.000039843","size":"0"},{"price":"0.000039874","size":"3024.0"},{"price":"0.000039881","size":"0"},{"price":"0.000039929","size":"3785.4"},{"price":"0.000039933","size":"0"}],"bid":[{"price":"0.000039639","size":"0"},{"price":"0.000039629","size":"1262.0"}],"sequence":13027008,"timestamp":"2021-04-17T16:46:35.441Z","symbol":"STORJBTC"}}
1618677995.504398: {"jsonrpc":"2.0","method":"updateOrderbook","params":{"ask":[{"price":"0.00011967","size":"1913.3"},{"price":"0.00011970","size":"0"},{"price":"0.00012044","size":"0"},{"price":"0.00012079","size":"8087.3"}],"bid":[],"sequence":19113978,"timestamp":"2021-04-17T16:46:35.382Z","symbol":"XTZBTC"}}
1618677995.5934029: {"jsonrpc":"2.0","method":"updateOrderbook","params":{"ask":[{"price":"0.000039742","size":"0"},{"price":"0.000039743","size":"431.7"},{"price":"0.000039793","size":"0"},{"price":"0.000039801","size":"1829.4"},{"price":"0.000039836","size":"0"},{"price":"0.000039840","size":"2594.7"},{"price":"0.000039859","size":"0"},{"price":"0.000039869","size":"2795.3"},{"price":"0.000039874","size":"0"},{"price":"0.000039886","size":"3024.0"},{"price":"0.000039929","size":"0"},{"price":"0.000039942","size":"3785.4"},{"price":"0.000039968","size":"780.0"},{"price":"0.000040002","size":"0"},{"price":"0.000040021","size":"0"},{"price":"0.000040046","size":"6736.1"}],"bid":[{"price":"0.000039629","size":"0"},{"price":"0.000039588","size":"1262.0"}],"sequence":13027009,"timestamp":"2021-04-17T16:46:35.541Z","symbol":"STORJBTC"}}
1618677995.601965: {"jsonrpc":"2.0","method":"updateOrderbook","params":{"ask":[{"price":"0.00011886","size":"24.1"},{"price":"0.00011927","size":"102.6"},{"price":"0.00011936","size":"0"},{"price":"0.00011941","size":"378.8"},{"price":"0.00011946","size":"0"},{"price":"0.00011958","size":"219.4"},{"price":"0.00011960","size":"920.9"},{"price":"0.00011969","size":"1845.7"},{"price":"0.00011973","size":"0"},{"price":"0.00012021","size":"0"},{"price":"0.00012066","size":"9877.7"},{"price":"0.00012708","size":"0"},{"price":"0.00012973","size":"3868.5"},{"price":"0.00017239","size":"0"},{"price":"0.00018070","size":"5176.4"}],"bid":[],"sequence":19113979,"timestamp":"2021-04-17T16:46:35.543Z","symbol":"XTZBTC"}}
1618677995.687453: {"jsonrpc":"2.0","method":"updateOrderbook","params":{"ask":[{"price":"0.00000000420","size":"811000"},{"price":"0.00000000450","size":"2001000"}],"bid":[],"sequence":1757676,"timestamp":"2021-04-17T16:46:35.621Z","symbol":"BANCABTC"}}
1618677995.6936908: {"jsonrpc":"2.0","method":"updateOrderbook","params":{"ask":[{"price":"0.000039719","size":"0"},{"price":"0.000039720","size":"0"},{"price":"0.000039739","size":"537.3"},{"price":"0.000039740","size":"532.1"},{"price":"0.000039743","size":"0"},{"price":"0.000039754","size":"431.7"},{"price":"0.000039801","size":"0"},{"price":"0.000039805","size":"2090.7"},{"price":"0.000039840","size":"0"},{"price":"0.000039843","size":"2594.7"},{"price":"0.000039886","size":"0"},{"price":"0.000039888","size":"3024.0"},{"price":"0.000039942","size":"9087.5"},{"price":"0.000039958","size":"0"},{"price":"0.000040021","size":"6736.1"},{"price":"0.000040046","size":"0"}],"bid":[],"sequence":13027010,"timestamp":"2021-04-17T16:46:35.609Z","symbol":"STORJBTC"}}
1618677995.700354: {"jsonrpc":"2.0","method":"updateOrderbook","params":{"ask":[],"bid":[{"price":"0.00011483","size":"20.2"},{"price":"0.00011481","size":"0"}],"sequence":19113980,"timestamp":"2021-04-17T16:46:35.574Z","symbol":"XTZBTC"}}
1618677995.787743: {"jsonrpc":"2.0","method":"updateOrderbook","params":{"ask":[],"bid":[{"price":"0.00000000369","size":"2749000"},{"price":"0.00000000359","size":"1000"},{"price":"0.00000000237","size":"11651000"},{"price":"0.00000000230","size":"1000"}],"sequence":1757677,"timestamp":"2021-04-17T16:46:35.674Z","symbol":"BANCABTC"}}
1618677995.795321: {"jsonrpc":"2.0","method":"updateOrderbook","params":{"ask":[{"price":"0.000039719","size":"537.3"},{"price":"0.000039720","size":"532.1"},{"price":"0.000039739","size":"0"},{"price":"0.000039740","size":"0"},{"price":"0.000039741","size":"431.7"},{"price":"0.000039754","size":"0"},{"price":"0.000039800","size":"1829.4"},{"price":"0.000039805","size":"261.3"},{"price":"0.000039840","size":"2594.7"},{"price":"0.000039843","size":"0"},{"price":"0.000039886","size":"3024.0"},{"price":"0.000039888","size":"0"},{"price":"0.000040212","size":"0"},{"price":"0.000040217","size":"9299.9"}],"bid":[{"price":"0.000039651","size":"0"},{"price":"0.000039631","size":"441.5"},{"price":"0.000039619","size":"1262.0"},{"price":"0.000039588","size":"0"},{"price":"0.000038353","size":"0"},{"price":"0.000038349","size":"0"},{"price":"0.000038344","size":"0"},{"price":"0.000035192","size":"1600.0"}],"sequence":13027011,"timestamp":"2021-04-17T16:46:35.742Z","symbol":"STORJBTC"}}
1618677995.8102038: {"jsonrpc":"2.0","method":"updateOrderbook","params":{"ask":[{"price":"0.00011941","size":"0"},{"price":"0.00011942","size":"944.6"},{"price":"0.00011944","size":"924.8"},{"price":"0.00011952","size":"1073.6"},{"price":"0.00011954","size":"0"},{"price":"0.00011962","size":"1279.6"},{"price":"0.00012061","size":"3675.0"},{"price":"0.00012076","size":"0"},{"price":"0.00012139","size":"6070.5"},{"price":"0.00012239","size":"0"},{"price":"0.00012453","size":"28399.4"},{"price":"0.00012788","size":"0"}],"bid":[{"price":"0.00011484","size":"40.5"},{"price":"0.00011482","size":"0"}],"sequence":19113981,"timestamp":"2021-04-17T16:46:35.742Z","symbol":"XTZBTC"}}
1618677995.8133771: {"jsonrpc":"2.0","method":"updateOrderbook","params":{"ask":[{"price":"1.5394719","size":"0"},{"price":"1.5398081","size":"294"}],"bid":[],"sequence":11642112,"timestamp":"2021-04-17T16:46:35.697Z","symbol":"MANAUSD"}}
1618677995.887118: {"jsonrpc":"2.0","method":"updateOrderbook","params":{"ask":[{"price":"0.000026916","size":"0"}],"bid":[],"sequence":1389883,"timestamp":"2021-04-17T16:46:35.816Z","symbol":"HEDGBTC"}}
1618677995.8966541: {"jsonrpc":"2.0","method":"updateOrderbook","params":{"ask":[{"price":"0.000039924","size":"5302.1"},{"price":"0.000039942","size":"3785.4"}],"bid":[{"price":"0.000038357","size":"156.4"}],"sequence":13027012,"timestamp":"2021-04-17T16:46:35.828Z","symbol":"STORJBTC"}}
1618677995.901994: {"jsonrpc":"2.0","method":"updateOrderbook","params":{"ask":[{"price":"0.00011938","size":"277.3"},{"price":"0.00011944","size":"1144.2"},{"price":"0.00011952","size":"890.3"},{"price":"0.00011958","size":"0"},{"price":"0.00011964","size":"1923.9"},{"price":"0.00011967","size":"345.5"},{"price":"0.00014794","size":"0"},{"price":"0.00014809","size":"17824.4"}],"bid":[{"price":"0.00011128","size":"380.0"},{"price":"0.00010657","size":"0"}],"sequence":19113982,"timestamp":"2021-04-17T16:46:35.822Z","symbol":"XTZBTC"}}
1618677995.98962: {"jsonrpc":"2.0","method":"updateOrderbook","params":{"ask":[{"price":"0.000026914","size":"562.4"},{"price":"0.000026915","size":"0"},{"price":"0.000030785","size":"326.6"}],"bid":[],"sequence":1389884,"timestamp":"2021-04-17T16:46:35.890Z","symbol":"HEDGBTC"}}
1618677995.9958389: {"jsonrpc":"2.0","method":"updateOrderbook","params":{"ask":[{"price":"0.000039891","size":"3812.3"},{"price":"0.000039909","size":"3633.3"},{"price":"0.000040021","size":"0"},{"price":"0.000040055","size":"6736.1"},{"price":"0.000040186","size":"9299.9"},{"price":"0.000040217","size":"0"},{"price":"0.000040400","size":"13527.3"},{"price":"0.000040431","size":"0"}],"bid":[{"price":"0.000039631","size":"0"},{"price":"0.000039621","size":"441.5"},{"price":"0.000039619","size":"0"},{"price":"0.000039578","size":"1262.0"}],"sequence":13027013,"timestamp":"2021-04-17T16:46:35.948Z","symbol":"STORJBTC"}}
1618677996.009847: {"jsonrpc":"2.0","method":"updateOrderbook","params":{"ask":[{"price":"0.00011932","size":"942.3"},{"price":"0.00011934","size":"0"},{"price":"0.00011938","size":"183.3"},{"price":"0.00011939","size":"94.0"},{"price":"0.00011941","size":"728.3"},{"price":"0.00011943","size":"0"},{"price":"0.00011958","size":"345.5"},{"price":"0.00011961","size":"1567.8"},{"price":"0.00011964","size":"356.1"},{"price":"0.00011967","size":"0"},{"price":"0.00012061","size":"0"},{"price":"0.00012068","size":"3675.0"},{"price":"0.00012453","size":"20099.1"},{"price":"0.00012502","size":"8300.3"},{"price":"0.00013704","size":"0"},{"price":"0.00013746","size":"12500.4"},{"price":"0.00014809","size":"0"},{"price":"0.00014849","size":"17824.4"}],"bid":[],"sequence":19113983,"timestamp":"2021-04-17T16:46:35.947Z","symbol":"XTZBTC"}}
1618677996.087188: {"jsonrpc":"2.0","method":"updateOrderbook","params":{"ask":[{"price":"0.000026913","size":"91.1"},{"price":"0.000030785","size":"0"}],"bid":[],"sequence":1389885,"timestamp":"2021-04-17T16:46:35.989Z","symbol":"HEDGBTC"}}
1618677996.118027: {"jsonrpc":"2.0","method":"updateOrderbook","params":{"ask":[],"bid":[{"price":"0.00019332","size":"0"},{"price":"0.00014240","size":"5.79"}],"sequence":10038660,"timestamp":"2021-04-17T16:46:36.027Z","symbol":"SUNBTC"}}
1618677996.1181939: {"jsonrpc":"2.0","method":"updateOrderbook","params":{"ask":[{"price":"0.00011931","size":"378.8"},{"price":"0.00011942","size":"565.8"},{"price":"0.00011953","size":"1279.6"},{"price":"0.00011962","size":"0"},{"price":"0.00012065","size":"1721.1"},{"price":"0.00012072","size":"0"},{"price":"0.00012094","size":"2477.0"},{"price":"0.00012134","size":"2825.5"},{"price":"0.00012973","size":"0"},{"price":"0.00013457","size":"3868.5"},{"price":"0.00018070","size":"0"},{"price":"0.00019069","size":"5176.4"}],"bid":[],"sequence":19113984,"timestamp":"2021-04-17T16:46:36.038Z","symbol":"XTZBTC"}}
1618677996.1929212: {"jsonrpc":"2.0","method":"updateOrderbook","params":{"ask":[{"price":"0.000039800","size":"0"},{"price":"0.000039801","size":"1829.4"},{"price":"0.000039840","size":"0"},{"price":"0.000039846","size":"2594.7"},{"price":"0.000039886","size":"0"},{"price":"0.000039891","size":"6836.3"},{"price":"0.000039942","size":"0"},{"price":"0.000039950","size":"3785.4"}],"bid":[{"price":"0.000039631","size":"441.5"},{"price":"0.000039621","size":"0"},{"price":"0.000039619","size":"1262.0"},{"price":"0.000039578","size":"0"}],"sequence":13027014,"timestamp":"2021-04-17T16:46:36.056Z","symbol":"STORJBTC"}}
1618677996.208818: {"jsonrpc":"2.0","method":"updateOrderbook","params":{"ask":[{"price":"0.00011922","size":"1978.8"},{"price":"0.00011927","size":"0"},{"price":"0.00011929","size":"728.3"},{"price":"0.00011930","size":"0"},{"price":"0.00011931","size":"0"},{"price":"0.00011932","size":"565.8"},{"price":"0.00011934","size":"378.8"},{"price":"0.00011941","size":"0"},{"price":"0.00011942","size":"0"},{"price":"0.00011950","size":"1720.5"},{"price":"0.00011962","size":"356.1"},{"price":"0.00011964","size":"0"},{"price":"0.00011965","size":"0"}],"bid":[],"sequence":19113985,"timestamp":"2021-04-17T16:46:36.126Z","symbol":"XTZBTC"}}
1618677996.2091122: {"jsonrpc":"2.0","method":"updateOrderbook","params":{"ask":[],"bid":[{"price":"1.3123035","size":"5289"},{"price":"1.3110032","size":"0"},{"price":"1.2510955","size":"8138"},{"price":"1.2505750","size":"0"}],"sequence":11642113,"timestamp":"2021-04-17T16:46:36.074Z","symbol":"MANAUSD"}}
1618677996.285888: {"jsonrpc":"2.0","method":"updateOrderbook","params":{"ask":[{"price":"0.0000006161","size":"0"}],"bid":[],"sequence":403554,"timestamp":"2021-04-17T16:46:36.160Z","symbol":"ACDBTC"}}
1618677996.292941: {"jsonrpc":"2.0","method":"updateOrderbook","params":{"ask":[{"price":"0.000039699","size":"537.3"},{"price":"0.000039700","size":"532.1"},{"price":"0.000039719","size":"0"},{"price":"0.000039720","size":"0"},{"price":"0.000039730","size":"431.7"},{"price":"0.000039741","size":"0"},{"price":"0.000039796","size":"1829.4"},{"price":"0.000039801","size":"0"},{"price":"0.000039844","size":"2594.7"},{"price":"0.000039846","size":"0"},{"price":"0.000039890","size":"3024.0"},{"price":"0.000039891","size":"3812.3"},{"price":"0.000039924","size":"6122.1"},{"price":"0.000039937","size":"321.6"},{"price":"0.000039949","size":"0"},{"price":"0.000039957","size":"462.9"},{"price":"0.000040400","size":"0"},{"price":"0.000040434","size":"13527.3"}],"bid":[{"price":"0.000039631","size":"0"},{"price":"0.000039619","size":"0"},{"price":"0.000039601","size":"441.5"},{"price":"0.000039589","size":"1262.0"}],"sequence":13027015,"timestamp":"2021-04-17T16:46:36.238Z","symbol":"STORJBTC"}}
1618677996.311736: {"jsonrpc":"2.0","method":"updateOrderbook","params":{"ask":[{"price":"0.00011922","size":"641.0"},{"price":"0.00011929","size":"0"},{"price":"0.00011930","size":"395.5"},{"price":"0.00011932","size":"942.3"},{"price":"0.00011941","size":"728.3"},{"price":"0.00011942","size":"565.8"},{"price":"0.00011944","size":"219.4"},{"price":"0.00011948","size":"924.8"},{"price":"0.00011950","size":"0"},{"price":"0.00011953","size":"0"},{"price":"0.00011958","size":"1625.1"},{"price":"0.00011962","size":"2076.6"}],"bid":[],"sequence":19113986,"timestamp":"2021-04-17T16:46:36.157Z","symbol":"XTZBTC"}}
1618677996.397016: {"jsonrpc":"2.0","method":"updateOrderbook","params":{"ask":[{"price":"0.000039699","size":"0"},{"price":"0.000039700","size":"0"},{"price":"0.000039719","size":"537.3"},{"price":"0.000039720","size":"532.1"},{"price":"0.000039730","size":"0"},{"price":"0.000039741","size":"431.7"},{"price":"0.000039796","size":"0"},{"price":"0.000039801","size":"1829.4"},{"price":"0.000039844","size":"0"},{"price":"0.000039846","size":"2594.7"},{"price":"0.000039870","size":"0"},{"price":"0.000039874","size":"124.2"},{"price":"0.000039882","size":"0"},{"price":"0.000039890","size":"0"},{"price":"0.000039891","size":"6836.3"},{"price":"0.000039892","size":"176.2"},{"price":"0.000039939","size":"368.0"},{"price":"0.000039969","size":"0"},{"price":"0.000039973","size":"599.0"},{"price":"0.000040013","size":"0"},{"price":"0.000040055","size":"0"},{"price":"0.000040097","size":"6736.1"},{"price":"0.000040186","size":"0"},{"price":"0.000040248","size":"9299.9"},{"price":"0.000040434","size":"0"},{"price":"0.000040507","size":"13527.3"}],"bid":[],"sequence":13027016,"timestamp":"2021-04-17T16:46:36.333Z","symbol":"STORJBTC"}}
1618677996.492379: {"jsonrpc":"2.0","method":"updateOrderbook","params":{"ask":[{"price":"0.000039719","size":"0"},{"price":"0.000039720","size":"0"},{"price":"0.000039729","size":"537.3"},{"price":"0.000039730","size":"532.1"},{"price":"0.000039741","size":"0"},{"price":"0.000039742","size":"431.7"},{"price":"0.000039797","size":"1829.4"},{"price":"0.000039801","size":"0"},{"price":"0.000039845","size":"2594.7"},{"price":"0.000039846","size":"0"},{"price":"0.000039890","size":"3024.0"},{"price":"0.000039891","size":"3812.3"}],"bid":[],"sequence":13027017,"timestamp":"2021-04-17T16:46:36.424Z","symbol":"STORJBTC"}}
1618677996.502999: {"jsonrpc":"2.0","method":"updateOrderbook","params":{"ask":[{"price":"0.00011944","size":"1140.3"},{"price":"0.00011952","size":"1187.0"},{"price":"0.00011956","size":"559.1"},{"price":"0.00011960","size":"0"},{"price":"0.00011979","size":"0"},{"price":"0.00011992","size":"0"}],"bid":[],"sequence":19113987,"timestamp":"2021-04-17T16:46:36.366Z","symbol":"XTZBTC"}}
1618677996.513678: {"jsonrpc":"2.0","method":"updateOrderbook","params":{"ask":[],"bid":[{"price":"0.2180042","size":"100.00"},{"price":"0.2178701","size":"0"}],"sequence":4920758,"timestamp":"2021-04-17T16:46:36.376Z","symbol":"BNBETH"}}
1618677996.590545: {"jsonrpc":"2.0","method":"updateOrderbook","params":{"ask":[{"price":"0.000026914","size":"0"}],"bid":[],"sequence":1389886,"timestamp":"2021-04-17T16:46:36.509Z","symbol":"HEDGBTC"}}
1618677996.604841: {"jsonrpc":"2.0","method":"updateOrderbook","params":{"ask":[],"bid":[{"price":"0.00016258","size":"0"},{"price":"0.00016257","size":"10.00"}],"sequence":10038661,"timestamp":"2021-04-17T16:46:36.496Z","symbol":"SUNBTC"}}
1618677996.605004: {"jsonrpc":"2.0","method":"updateOrderbook","params":{"ask":[{"price":"0.00011922","size":"1876.2"},{"price":"0.00011923","size":"102.6"},{"price":"0.00011929","size":"728.3"},{"price":"0.00011930","size":"0"},{"price":"0.00011932","size":"565.8"},{"price":"0.00011934","size":"0"},{"price":"0.00011936","size":"378.8"},{"price":"0.00011941","size":"0"},{"price":"0.00011942","size":"0"},{"price":"0.00011946","size":"911.8"},{"price":"0.00011962","size":"4130.1"},{"price":"0.00011977","size":"0"},{"price":"0.00011999","size":"0"},{"price":"0.00012059","size":"8993.7"},{"price":"0.00012066","size":"884.0"},{"price":"0.00012439","size":"20099.1"},{"price":"0.00012453","size":"0"}],"bid":[],"sequence":19113988,"timestamp":"2021-04-17T16:46:36.521Z","symbol":"XTZBTC"}}
1618677996.687829: {"jsonrpc":"2.0","method":"updateOrderbook","params":{"ask":[{"price":"0.000026912","size":"562.4"},{"price":"0.000026913","size":"0"},{"price":"0.000030785","size":"326.6"}],"bid":[],"sequence":1389887,"timestamp":"2021-04-17T16:46:36.585Z","symbol":"HEDGBTC"}}
1618677996.687953: {"jsonrpc":"2.0","method":"updateOrderbook","params":{"ask":[{"price":"0.00000000420","size":"0"},{"price":"0.00000000450","size":"2812000"}],"bid":[{"price":"0.00000000369","size":"310000"},{"price":"0.00000000359","size":"2440000"},{"price":"0.00000000237","size":"1000"},{"price":"0.00000000230","size":"11651000"}],"sequence":1757678,"timestamp":"2021-04-17T16:46:36.649Z","symbol":"BANCABTC"}}
1618677996.6954272: {"jsonrpc":"2.0","method":"updateOrderbook","params":{"ask":[{"price":"0.000039739","size":"431.7"},{"price":"0.000039742","size":"0"},{"price":"0.000039781","size":"1829.4"},{"price":"0.000039782","size":"261.3"},{"price":"0.000039797","size":"0"},{"price":"0.000039805","size":"0"},{"price":"0.000039807","size":"1150.2"},{"price":"0.000039827","size":"0"},{"price":"0.000039838","size":"2594.7"},{"price":"0.000039845","size":"0"},{"price":"0.000039885","size":"3024.0"},{"price":"0.000039890","size":"0"},{"price":"0.000039939","size":"4153.4"},{"price":"0.000039950","size":"0"},{"price":"0.000040097","size":"0"},{"price":"0.000040134","size":"6736.1"}],"bid":[],"sequence":13027018,"timestamp":"2021-04-17T16:46:36.610Z","symbol":"STORJBTC"}}
1618677996.707055: {"jsonrpc":"2.0","method":"updateOrderbook","params":{"ask":[{"price":"0.00011922","size":"538.4"},{"price":"0.00011929","size":"0"},{"price":"0.00011932","size":"1337.8"},{"price":"0.00011941","size":"728.3"},{"price":"0.00011942","size":"565.8"},{"price":"0.00011947","size":"1567.8"},{"price":"0.00011961","size":"0"}],"bid":[{"price":"0.00011485","size":"20.2"},{"price":"0.00011483","size":"0"}],"sequence":19113989,"timestamp":"2021-04-17T16:46:36.631Z","symbol":"XTZBTC"}}
1618677996.7921531: {"jsonrpc":"2.0","method":"updateOrderbook","params":{"ask":[{"price":"0.000026911","size":"91.1"},{"price":"0.000030785","size":"0"}],"bid":[],"sequence":1389888,"timestamp":"2021-04-17T16:46:36.725Z","symbol":"HEDGBTC"}}
1618677996.794436: {"jsonrpc":"2.0","method":"updateOrderbook","params":{"ask":[{"price":"0.000039699","size":"537.3"},{"price":"0.000039700","size":"532.1"},{"price":"0.000039718","size":"431.7"},{"price":"0.000039729","size":"0"},{"price":"0.000039730","size":"0"},{"price":"0.000039739","size":"0"},{"price":"0.000040478","size":"13527.3"},{"price":"0.000040507","size":"0"}],"bid":[{"price":"0.000039589","size":"0"},{"price":"0.000039557","size":"1262.0"}],"sequence":13027019,"timestamp":"2021-04-17T16:46:36.744Z","symbol":"STORJBTC"}}
1618677996.799958: {"jsonrpc":"2.0","method":"updateOrderbook","params":{"ask":[{"price":"0.00011932","size":"901.7"},{"price":"0.00011937","size":"436.1"},{"price":"0.00011948","size":"0"},{"price":"0.00011951","size":"924.8"},{"price":"0.00011958","size":"345.5"},{"price":"0.00011961","size":"1279.6"},{"price":"0.00011962","size":"2076.6"},{"price":"0.00011964","size":"2053.5"},{"price":"0.00012059","size":"0"},{"price":"0.00012066","size":"9877.7"},{"price":"0.00012439","size":"0"},{"price":"0.00012452","size":"20099.1"}],"bid":[{"price":"0.00011486","size":"40.5"},{"price":"0.00011484","size":"0"}],"sequence":19113990,"timestamp":"2021-04-17T16:46:36.698Z","symbol":"XTZBTC"}}
1618677996.891177: {"jsonrpc":"2.0","method":"updateOrderbook","params":{"ask":[{"price":"0.000039699","size":"0"},{"price":"0.000039700","size":"0"},{"price":"0.000039718","size":"0"},{"price":"0.000039729","size":"537.3"},{"price":"0.000039730","size":"532.1"},{"price":"0.000039739","size":"431.7"},{"price":"0.000039781","size":"0"},{"price":"0.000039798","size":"1829.4"},{"price":"0.000039838","size":"0"},{"price":"0.000039848","size":"2594.7"},{"price":"0.000039885","size":"0"},{"price":"0.000039890","size":"3812.3"},{"price":"0.000039891","size":"0"},{"price":"0.000039892","size":"3200.2"},{"price":"0.000039939","size":"368.0"},{"price":"0.000039952","size":"3785.4"}],"bid":[],"sequence":13027020,"timestamp":"2021-04-17T16:46:36.847Z","symbol":"STORJBTC"}}
1618677996.904286: {"jsonrpc":"2.0","method":"updateOrderbook","params":{"ask":[{"price":"0.00011950","size":"1845.7"},{"price":"0.00011965","size":"2394.4"},{"price":"0.00011969","size":"0"},{"price":"0.00011974","size":"2130.2"},{"price":"0.00011975","size":"483.6"},{"price":"0.00011980","size":"600.6"},{"price":"0.00011982","size":"4893.2"},{"price":"0.00011991","size":"0"},{"price":"0.00011995","size":"3485.4"},{"price":"0.00012001","size":"0"},{"price":"0.00012006","size":"0"},{"price":"0.00012009","size":"3537.9"},{"price":"0.00012027","size":"0"},{"price":"0.00012036","size":"4416.4"},{"price":"0.00012066","size":"884.0"},{"price":"0.00012076","size":"8993.7"},{"price":"0.00012102","size":"0"},{"price":"0.00012116","size":"9834.8"},{"price":"0.00012192","size":"0"},{"price":"0.00012214","size":"12140.3"},{"price":"0.00012284","size":"0"},{"price":"0.00012304","size":"11096.2"},{"price":"0.00012452","size":"0"},{"price":"0.00012472","size":"20099.1"}],"bid":[],"sequence":19113991,"timestamp":"2021-04-17T16:46:36.848Z","symbol":"XTZBTC"}}
1618677997.006468: {"jsonrpc":"2.0","method":"updateOrderbook","params":{"ask":[{"price":"0.000039699","size":"537.3"},{"price":"0.000039700","size":"532.1"},{"price":"0.000039716","size":"431.7"},{"price":"0.000039729","size":"0"},{"price":"0.000039730","size":"0"},{"price":"0.000039739","size":"0"},{"price":"0.000039782","size":"2090.7"},{"price":"0.000039798","size":"0"},{"price":"0.000039844","size":"2594.7"},{"price":"0.000039848","size":"0"},{"price":"0.000039871","size":"3812.3"},{"price":"0.000039889","size":"3024.0"},{"price":"0.000039890","size":"0"},{"price":"0.000039892","size":"176.2"},{"price":"0.000039946","size":"3785.4"},{"price":"0.000039952","size":"0"},{"price":"0.000040134","size":"0"},{"price":"0.000040157","size":"12114.6"},{"price":"0.000040478","size":"0"},{"price":"0.000040550","size":"13527.3"}],"bid":[{"price":"0.000038357","size":"0"},{"price":"0.000038015","size":"157.8"}],"sequence":13027021,"timestamp":"2021-04-17T16:46:36.947Z","symbol":"STORJBTC"}}
1618677997.006952: {"jsonrpc":"2.0","method":"updateOrderbook","params":{"ask":[{"price":"0.00011923","size":"0"},{"price":"0.00011924","size":"102.6"},{"price":"0.00011936","size":"0"},{"price":"0.00011938","size":"562.1"},{"price":"0.00011977","size":"1165.1"},{"price":"0.00011985","size":"0"},{"price":"0.00012073","size":"4799.2"},{"price":"0.00012079","size":"3288.1"}],"bid":[],"sequence":19113992,"timestamp":"2021-04-17T16:46:36.913Z","symbol":"XTZBTC"}}
1618677997.0872488: {"jsonrpc":"2.0","method":"updateOrderbook","params":{"ask":[{"price":"0.000026912","size":"0"}],"bid":[],"sequence":1389889,"timestamp":"2021-04-17T16:46:37.027Z","symbol":"HEDGBTC"}}
1618677997.0934641: {"jsonrpc":"2.0","method":"updateOrderbook","params":{"ask":[{"price":"0.000039908","size":"5302.1"},{"price":"0.000039924","size":"820.0"},{"price":"0.000040519","size":"13527.3"},{"price":"0.000040550","size":"0"}],"bid":[],"sequence":13027022,"timestamp":"2021-04-17T16:46:36.977Z","symbol":"STORJBTC"}}
1618677997.108574: {"jsonrpc":"2.0","method":"updateOrderbook","params":{"ask":[{"price":"0.00011934","size":"94.0"},{"price":"0.00011939","size":"345.5"},{"price":"0.00011958","size":"0"}],"bid":[],"sequence":19113993,"timestamp":"2021-04-17T16:46:37.020Z","symbol":"XTZBTC"}}
1618677997.186396: {"jsonrpc":"2.0","method":"updateOrderbook","params":{"ask":[{"price":"0.000026910","size":"562.4"},{"price":"0.000026911","size":"0"},{"price":"0.000030785","size":"326.6"}],"bid":[],"sequence":1389890,"timestamp":"2021-04-17T16:46:37.104Z","symbol":"HEDGBTC"}}
1618677997.1885388: {"jsonrpc":"2.0","method":"updateOrderbook","params":{"ask":[{"price":"0.000039770","size":"1829.4"},{"price":"0.000039782","size":"261.3"},{"price":"0.000039820","size":"2795.3"},{"price":"0.000039838","size":"2594.7"},{"price":"0.000039844","size":"0"},{"price":"0.000039869","size":"0"},{"price":"0.000039884","size":"3024.0"},{"price":"0.000039889","size":"0"},{"price":"0.000039938","size":"3785.4"},{"price":"0.000039946","size":"0"},{"price":"0.000040519","size":"0"},{"price":"0.000040529","size":"13527.3"}],"bid":[{"price":"0.000038015","size":"0"}],"sequence":13027023,"timestamp":"2021-04-17T16:46:37.141Z","symbol":"STORJBTC"}}
1618677997.196203: {"jsonrpc":"2.0","method":"updateOrderbook","params":{"ask":[{"price":"0.00011954","size":"200.7"},{"price":"0.00011956","size":"358.4"},{"price":"0.00011974","size":"3295.3"},{"price":"0.00011977","size":"0"},{"price":"0.00011988","size":"3675.0"},{"price":"0.00012013","size":"1550.2"},{"price":"0.00012016","size":"0"},{"price":"0.00012068","size":"0"}],"bid":[],"sequence":19113994,"timestamp":"2021-04-17T16:46:37.140Z","symbol":"XTZBTC"}}
1618677997.209353: {"jsonrpc":"2.0","method":"updateOrderbook","params":{"ask":[{"price":"1.5393719","size":"294"},{"price":"1.5398081","size":"0"}],"bid":[],"sequence":11642114,"timestamp":"2021-04-17T16:46:37.074Z","symbol":"MANAUSD"}}
1618677997.285064: {"jsonrpc":"2.0","method":"updateOrderbook","params":{"ask":[{"price":"0.000026909","size":"91.1"},{"price":"0.000030785","size":"0"}],"bid":[],"sequence":1389891,"timestamp":"2021-04-17T16:46:37.174Z","symbol":"HEDGBTC"}}
1618677997.29024: {"jsonrpc":"2.0","method":"updateOrderbook","params":{"ask":[{"price":"0.000039938","size":"0"},{"price":"0.000039951","size":"3785.4"}],"bid":[{"price":"0.000039601","size":"0"},{"price":"0.000039581","size":"441.5"},{"price":"0.000039557","size":"0"},{"price":"0.000039541","size":"1262.0"},{"price":"0.000038354","size":"1564.3"},{"price":"0.000038017","size":"157.8"}],"sequence":13027024,"timestamp":"2021-04-17T16:46:37.238Z","symbol":"STORJBTC"}}
1618677997.297923: {"jsonrpc":"2.0","method":"updateOrderbook","params":{"ask":[{"price":"0.00011938","size":"183.3"},{"price":"0.00011941","size":"1107.1"},{"price":"0.00011979","size":"380.0"},{"price":"0.00011986","size":"0"},{"price":"0.00011988","size":"0"},{"price":"0.00011994","size":"3675.0"}],"bid":[{"price":"0.00010670","size":"0"}],"sequence":19113995,"timestamp":"2021-04-17T16:46:37.243Z","symbol":"XTZBTC"}}
1618677997.4061718: {"jsonrpc":"2.0","method":"updateOrderbook","params":{"ask":[{"price":"0.000039709","size":"431.7"},{"price":"0.000039716","size":"0"},{"price":"0.000039754","size":"1829.4"},{"price":"0.000039770","size":"0"},{"price":"0.000039833","size":"2594.7"},{"price":"0.000039838","size":"0"},{"price":"0.000039879","size":"3024.0"},{"price":"0.000039884","size":"0"},{"price":"0.000039945","size":"3785.4"},{"price":"0.000039951","size":"0"},{"price":"0.000040157","size":"6736.1"},{"price":"0.000040225","size":"5378.5"},{"price":"0.000040492","size":"13527.3"},{"price":"0.000040529","size":"0"}],"bid":[{"price":"0.000039589","size":"441.5"},{"price":"0.000039581","size":"0"},{"price":"0.000039569","size":"1262.0"},{"price":"0.000039541","size":"0"},{"price":"0.000038017","size":"0"}],"sequence":13027025,"timestamp":"2021-04-17T16:46:37.344Z","symbol":"STORJBTC"}}
1618677997.509879: {"jsonrpc":"2.0","method":"updateOrderbook","params":{"ask":[{"price":"0.000039679","size":"537.3"},{"price":"0.000039680","size":"532.1"},{"price":"0.000039693","size":"431.7"},{"price":"0.000039699","size":"0"},{"price":"0.000039700","size":"0"},{"price":"0.000039709","size":"0"},{"price":"0.000039752","size":"1829.4"},{"price":"0.000039754","size":"0"},{"price":"0.000039933","size":"599.0"},{"price":"0.000039936","size":"780.0"},{"price":"0.000039968","size":"0"},{"price":"0.000039971","size":"738.1"},{"price":"0.000039973","size":"0"},{"price":"0.000040015","size":"4957.7"},{"price":"0.000040146","size":"5378.5"},{"price":"0.000040225","size":"0"},{"price":"0.000040492","size":"0"},{"price":"0.000040529","size":"13527.3"}],"bid":[{"price":"0.000038356","size":"156.4"}],"sequence":13027026,"timestamp":"2021-04-17T16:46:37.444Z","symbol":"STORJBTC"}}
1618677997.510348: {"jsonrpc":"2.0","method":"updateOrderbook","params":{"ask":[{"price":"0.00011694","size":"29.1"},{"price":"0.00011887","size":"0"},{"price":"0.00011987","size":"784.6"},{"price":"0.00012024","size":"0"},{"price":"0.00012081","size":"6070.5"},{"price":"0.00012139","size":"0"},{"price":"0.00012178","size":"8300.3"},{"price":"0.00012502","size":"0"}],"bid":[],"sequence":19113996,"timestamp":"2021-04-17T16:46:37.439Z","symbol":"XTZBTC"}}
1618677997.602657: {"jsonrpc":"2.0","method":"updateOrderbook","params":{"ask":[{"price":"0.000039679","size":"0"},{"price":"0.000039680","size":"0"},{"price":"0.000039689","size":"537.3"},{"price":"0.000039693","size":"0"},{"price":"0.000039697","size":"532.1"},{"price":"0.000039710","size":"431.7"},{"price":"0.000039751","size":"1829.4"},{"price":"0.000039752","size":"0"},{"price":"0.000039830","size":"2594.7"},{"price":"0.000039833","size":"0"},{"price":"0.000039877","size":"3024.0"},{"price":"0.000039879","size":"0"},{"price":"0.000039943","size":"3785.4"},{"price":"0.000039945","size":"0"},{"price":"0.000040214","size":"9299.9"},{"price":"0.000040248","size":"0"},{"price":"0.000040495","size":"13527.3"},{"price":"0.000040529","size":"0"}],"bid":[],"sequence":13027027,"timestamp":"2021-04-17T16:46:37.542Z","symbol":"STORJBTC"}}
1618677997.603102: {"jsonrpc":"2.0","method":"updateOrderbook","params":{"ask":[{"price":"0.00011694","size":"0"},{"price":"0.00011887","size":"29.1"},{"price":"0.00012092","size":"4093.4"},{"price":"0.00012254","size":"0"}],"bid":[],"sequence":19113997,"timestamp":"2021-04-17T16:46:37.507Z","symbol":"XTZBTC"}}
1618677997.690444: {"jsonrpc":"2.0","method":"updateOrderbook","params":{"ask":[{"price":"0.000039690","size":"532.1"},{"price":"0.000039697","size":"0"},{"price":"0.000039702","size":"431.7"},{"price":"0.000039710","size":"0"},{"price":"0.000039743","size":"1829.4"},{"price":"0.000039751","size":"0"},{"price":"0.000039795","size":"1150.2"},{"price":"0.000039807","size":"0"},{"price":"0.000039811","size":"0"},{"price":"0.000039820","size":"0"},{"price":"0.000039821","size":"2594.7"},{"price":"0.000039829","size":"2795.3"},{"price":"0.000039830","size":"0"},{"price":"0.000039872","size":"3024.0"},{"price":"0.000039877","size":"0"},{"price":"0.000039896","size":"820.0"},{"price":"0.000039924","size":"0"},{"price":"0.000039936","size":"4565.4"},{"price":"0.000039943","size":"0"}],"bid":[{"price":"0.000038358","size":"156.4"},{"price":"0.000038356","size":"0"}],"sequence":13027028,"timestamp":"2021-04-17T16:46:37.636Z","symbol":"STORJBTC"}}
1618677997.707062: {"jsonrpc":"2.0","method":"updateOrderbook","params":{"ask":[{"price":"0.00011930","size":"395.5"},{"price":"0.00011932","size":"506.2"},{"price":"0.00011952","size":"1387.7"},{"price":"0.00011954","size":"0"},{"price":"0.00011955","size":"244.5"},{"price":"0.00011958","size":"1253.2"},{"price":"0.00011959","size":"356.1"},{"price":"0.00011962","size":"1720.5"},{"price":"0.00012038","size":"2033.5"}],"bid":[{"price":"0.00011487","size":"20.2"},{"price":"0.00011485","size":"0"},{"price":"0.00011128","size":"0"},{"price":"0.00011102","size":"380.0"}],"sequence":19113998,"timestamp":"2021-04-17T16:46:37.627Z","symbol":"XTZBTC"}}
1618677997.803493: {"jsonrpc":"2.0","method":"updateOrderbook","params":{"ask":[{"price":"0.00011958","size":"0"},{"price":"0.00012008","size":"1253.2"},{"price":"0.00012092","size":"0"},{"price":"0.00012144","size":"4093.4"},{"price":"0.00012178","size":"0"},{"price":"0.00012187","size":"8300.3"},{"price":"0.00012982","size":"12500.4"},{"price":"0.00013746","size":"0"},{"price":"0.00014112","size":"17824.4"},{"price":"0.00014849","size":"0"}],"bid":[{"price":"0.00011488","size":"40.5"},{"price":"0.00011486","size":"0"}],"sequence":19113999,"timestamp":"2021-04-17T16:46:37.711Z","symbol":"XTZBTC"}}
1618677997.811616: {"jsonrpc":"2.0","method":"updateOrderbook","params":{"ask":[{"price":"1.5393719","size":"295"}],"bid":[],"sequence":11642115,"timestamp":"2021-04-17T16:46:37.690Z","symbol":"MANAUSD"}}
1618677997.8917341: {"jsonrpc":"2.0","method":"updateOrderbook","params":{"ask":[{"price":"0.000039752","size":"261.3"},{"price":"0.000039782","size":"0"},{"price":"0.000040185","size":"9299.9"},{"price":"0.000040214","size":"0"},{"price":"0.000040410","size":"13527.3"},{"price":"0.000040495","size":"0"}],"bid":[],"sequence":13027029,"timestamp":"2021-04-17T16:46:37.812Z","symbol":"STORJBTC"}}
1618677997.905416: {"jsonrpc":"2.0","method":"updateOrderbook","params":{"ask":[{"price":"0.00011934","size":"0"},{"price":"0.00011935","size":"94.0"},{"price":"0.00011954","size":"2394.4"},{"price":"0.00011965","size":"0"},{"price":"0.00012008","size":"0"},{"price":"0.00012013","size":"2803.4"}],"bid":[],"sequence":19114000,"timestamp":"2021-04-17T16:46:37.837Z","symbol":"XTZBTC"}}
1618677997.9867609: {"jsonrpc":"2.0","method":"updateOrderbook","params":{"ask":[{"price":"0.000026910","size":"0"}],"bid":[],"sequence":1389892,"timestamp":"2021-04-17T16:46:37.880Z","symbol":"HEDGBTC"}}
1618677997.991891: {"jsonrpc":"2.0","method":"updateOrderbook","params":{"ask":[{"price":"0.000039659","size":"537.3"},{"price":"0.000039660","size":"532.1"},{"price":"0.000039678","size":"431.7"},{"price":"0.000039689","size":"0"},{"price":"0.000039690","size":"0"},{"price":"0.000039702","size":"0"},{"price":"0.000039771","size":"3.5"},{"price":"0.000039860","size":"3812.3"},{"price":"0.000039871","size":"0"},{"price":"0.000039936","size":"780.0"},{"price":"0.000039937","size":"4107.0"},{"price":"0.000040410","size":"0"},{"price":"0.000040445","size":"13527.3"}],"bid":[],"sequence":13027030,"timestamp":"2021-04-17T16:46:37.913Z","symbol":"STORJBTC"}}
1618677998.003573: {"jsonrpc":"2.0","method":"updateOrderbook","params":{"ask":[],"bid":[{"price":"0.00011102","size":"0"},{"price":"0.00010654","size":"380.0"}],"sequence":19114001,"timestamp":"2021-04-17T16:46:37.924Z","symbol":"XTZBTC"}}
1618677998.092299: {"jsonrpc":"2.0","method":"updateOrderbook","params":{"ask":[{"price":"0.000026908","size":"562.4"},{"price":"0.000026909","size":"0"},{"price":"0.000030785","size":"326.6"}],"bid":[],"sequence":1389893,"timestamp":"2021-04-17T16:46:37.978Z","symbol":"HEDGBTC"}}
1618677998.104086: {"jsonrpc":"2.0","method":"updateOrderbook","params":{"ask":[{"price":"0.00011950","size":"2046.4"},{"price":"0.00011952","size":"1187.0"},{"price":"0.00011953","size":"244.5"},{"price":"0.00011955","size":"0"},{"price":"0.00012176","size":"8300.3"},{"price":"0.00012187","size":"0"},{"price":"0.00012964","size":"12500.4"},{"price":"0.00012982","size":"0"},{"price":"0.00014094","size":"17824.4"},{"price":"0.00014112","size":"0"}],"bid":[],"sequence":19114002,"timestamp":"2021-04-17T16:46:38.005Z","symbol":"XTZBTC"}}
1618677998.1867049: {"jsonrpc":"2.0","method":"updateOrderbook","params":{"ask":[{"price":"0.000026907","size":"91.1"},{"price":"0.000030785","size":"0"}],"bid":[],"sequence":1389894,"timestamp":"2021-04-17T16:46:38.083Z","symbol":"HEDGBTC"}}
1618677998.190955: {"jsonrpc":"2.0","method":"updateOrderbook","params":{"ask":[{"price":"0.000039659","size":"0"},{"price":"0.000039660","size":"0"},{"price":"0.000039678","size":"0"},{"price":"0.000039699","size":"537.3"},{"price":"0.000039700","size":"532.1"},{"price":"0.000039711","size":"431.7"},{"price":"0.000039743","size":"0"},{"price":"0.000039751","size":"1829.4"},{"price":"0.000039821","size":"0"},{"price":"0.000039825","size":"2594.7"},{"price":"0.000039866","size":"3024.0"},{"price":"0.000039872","size":"0"},{"price":"0.000039931","size":"3785.4"},{"price":"0.000039937","size":"321.6"}],"bid":[{"price":"0.000039569","size":"0"},{"price":"0.000039525","size":"1262.0"}],"sequence":13027031,"timestamp":"2021-04-17T16:46:38.140Z","symbol":"STORJBTC"}}
1618677998.1962628: {"jsonrpc":"2.0","method":"updateOrderbook","params":{"ask":[{"price":"0.00011937","size":"814.9"},{"price":"0.00011941","size":"728.3"},{"price":"0.00011991","size":"1721.1"},{"price":"0.00012065","size":"0"}],"bid":[],"sequence":19114003,"timestamp":"2021-04-17T16:46:38.098Z","symbol":"XTZBTC"}}
1618677998.2950559: {"jsonrpc":"2.0","method":"updateOrderbook","params":{"ask":[{"price":"0.000039659","size":"537.3"},{"price":"0.000039660","size":"532.1"},{"price":"0.000039681","size":"431.7"},{"price":"0.000039699","size":"0"},{"price":"0.000039700","size":"0"},{"price":"0.000039711","size":"0"},{"price":"0.000039746","size":"1829.4"},{"price":"0.000039751","size":"0"},{"price":"0.000039825","size":"0"},{"price":"0.000039827","size":"2594.7"},{"price":"0.000039860","size":"0"},{"price":"0.000039866","size":"0"},{"price":"0.000039868","size":"3024.0"},{"price":"0.000039872","size":"3812.3"},{"price":"0.000039908","size":"0"},{"price":"0.000039934","size":"5302.1"},{"price":"0.000040185","size":"0"},{"price":"0.000040251","size":"9299.9"},{"price":"0.000040445","size":"0"},{"price":"0.000040516","size":"13527.3"}],"bid":[{"price":"0.000039559","size":"1262.0"},{"price":"0.000039525","size":"0"},{"price":"0.000028562","size":"43377.7"},{"price":"0.000028417","size":"0"}],"sequence":13027032,"timestamp":"2021-04-17T16:46:38.245Z","symbol":"STORJBTC"}}
1618677998.390007: {"jsonrpc":"2.0","method":"updateOrderbook","params":{"ask":[{"price":"0.000039828","size":"104.5"},{"price":"0.000039840","size":"124.2"},{"price":"0.000039858","size":"0"},{"price":"0.000039859","size":"3812.3"},{"price":"0.000039872","size":"0"},{"price":"0.000039874","size":"0"},{"price":"0.000039916","size":"5302.1"},{"price":"0.000039934","size":"0"},{"price":"0.000040223","size":"9299.9"},{"price":"0.000040251","size":"0"},{"price":"0.000040487","size":"13527.3"},{"price":"0.000040516","size":"0"}],"bid":[],"sequence":13027033,"timestamp":"2021-04-17T16:46:38.288Z","symbol":"STORJBTC"}}
1618677998.399998: {"jsonrpc":"2.0","method":"updateOrderbook","params":{"ask":[],"bid":[{"price":"0.00016258","size":"10.00"},{"price":"0.00016257","size":"0"}],"sequence":10038662,"timestamp":"2021-04-17T16:46:38.307Z","symbol":"SUNBTC"}}
1618677998.400125: {"jsonrpc":"2.0","method":"updateOrderbook","params":{"ask":[{"price":"0.00011923","size":"102.6"},{"price":"0.00011924","size":"0"},{"price":"0.00011937","size":"436.1"},{"price":"0.00011938","size":"562.1"}],"bid":[],"sequence":19114004,"timestamp":"2021-04-17T16:46:38.324Z","symbol":"XTZBTC"}}
1618677998.505028: {"jsonrpc":"2.0","method":"updateOrderbook","params":{"ask":[{"price":"0.000039659","size":"0"},{"price":"0.000039660","size":"0"},{"price":"0.000039681","size":"0"},{"price":"0.000039699","size":"537.3"},{"price":"0.000039700","size":"532.1"},{"price":"0.000039711","size":"431.7"},{"price":"0.000039746","size":"0"},{"price":"0.000039761","size":"1829.4"},{"price":"0.000039827","size":"0"},{"price":"0.000039831","size":"2594.7"},{"price":"0.000039868","size":"0"},{"price":"0.000039873","size":"3024.0"},{"price":"0.000039931","size":"0"},{"price":"0.000039938","size":"3785.4"}],"bid":[{"price":"0.000039559","size":"0"},{"price":"0.000039517","size":"1262.0"}],"sequence":13027034,"timestamp":"2021-04-17T16:46:38.445Z","symbol":"STORJBTC"}}
1618677998.5054662: {"jsonrpc":"2.0","method":"updateOrderbook","params":{"ask":[{"price":"0.00012952","size":"12500.4"},{"price":"0.00012964","size":"0"}],"bid":[],"sequence":19114005,"timestamp":"2021-04-17T16:46:38.388Z","symbol":"XTZBTC"}}
1618677998.5089788: {"jsonrpc":"2.0","method":"updateOrderbook","params":{"ask":[{"price":"1.5388721","size":"295"},{"price":"1.5393719","size":"0"}],"bid":[],"sequence":11642116,"timestamp":"2021-04-17T16:46:38.363Z","symbol":"MANAUSD"}}
1618677998.601412: {"jsonrpc":"2.0","method":"updateOrderbook","params":{"ask":[{"price":"0.000040218","size":"1551.8"},{"price":"0.000040301","size":"0"}],"bid":[{"price":"0.000031675","size":"2265.2"},{"price":"0.000031518","size":"0"}],"sequence":13027035,"timestamp":"2021-04-17T16:46:38.548Z","symbol":"STORJBTC"}}
1618677998.611788: {"jsonrpc":"2.0","method":"updateOrderbook","params":{"ask":[{"price":"0.00011962","size":"5904.2"},{"price":"0.00011964","size":"0"},{"price":"0.00011972","size":"2797.0"},{"price":"0.00011974","size":"0"},{"price":"0.00011982","size":"2096.2"},{"price":"0.00011983","size":"3485.4"},{"price":"0.00011984","size":"1165.1"},{"price":"0.00011995","size":"0"},{"price":"0.00012001","size":"3537.9"},{"price":"0.00012009","size":"0"},{"price":"0.00012013","size":"1253.2"},{"price":"0.00012019","size":"5966.6"},{"price":"0.00012036","size":"0"}],"bid":[],"sequence":19114006,"timestamp":"2021-04-17T16:46:38.543Z","symbol":"XTZBTC"}}
1618677998.619345: {"jsonrpc":"2.0","method":"updateOrderbook","params":{"ask":[],"bid":[{"price":"0.2186536","size":"0"},{"price":"0.2185672","size":"23.26"}],"sequence":4920759,"timestamp":"2021-04-17T16:46:38.474Z","symbol":"BNBETH"}}
1618677998.696667: {"jsonrpc":"2.0","method":"updateOrderbook","params":{"ask":[{"price":"0.000039689","size":"537.3"},{"price":"0.000039697","size":"532.1"},{"price":"0.000039699","size":"0"},{"price":"0.000039700","size":"0"},{"price":"0.000039710","size":"431.7"},{"price":"0.000039711","size":"0"},{"price":"0.000039760","size":"1829.4"},{"price":"0.000039761","size":"0"},{"price":"0.000039872","size":"3024.0"},{"price":"0.000039873","size":"0"}],"bid":[],"sequence":13027036,"timestamp":"2021-04-17T16:46:38.586Z","symbol":"STORJBTC"}}
1618677998.714668: {"jsonrpc":"2.0","method":"updateOrderbook","params":{"ask":[{"price":"0.00011695","size":"0"},{"price":"0.00011937","size":"619.4"},{"price":"0.00011938","size":"378.8"},{"price":"0.00011942","size":"785.2"},{"price":"0.00011944","size":"920.9"},{"price":"0.00011951","size":"1169.3"},{"price":"0.00011953","size":"0"},{"price":"0.00011956","size":"714.5"},{"price":"0.00011959","size":"0"},{"price":"0.00012006","size":"884.0"},{"price":"0.00012066","size":"0"}],"bid":[{"price":"0.00011487","size":"0"},{"price":"0.00011475","size":"20.2"}],"sequence":19114007,"timestamp":"2021-04-17T16:46:38.602Z","symbol":"XTZBTC"}}
1618677998.714997: {"jsonrpc":"2.0","method":"updateOrderbook","params":{"ask":[{"price":"0.00000119569","size":"0"},{"price":"0.00000119759","size":"592740"},{"price":"0.00000120369","size":"0"},{"price":"0.00000120446","size":"694310"},{"price":"0.00000121364","size":"0"},{"price":"0.00000121541","size":"922200"},{"price":"0.00000123868","size":"0"},{"price":"0.00000124063","size":"1107430"},{"price":"0.00000126876","size":"0"},{"price":"0.00000127073","size":"2245050"}],"bid":[],"sequence":5061574,"timestamp":"2021-04-17T16:46:38.579Z","symbol":"CELRBTC"}}
1618677998.802557: {"jsonrpc":"2.0","method":"updateOrderbook","params":{"ask":[{"price":"0.000039813","size":"2795.3"},{"price":"0.000039829","size":"0"},{"price":"0.000039872","size":"0"},{"price":"0.000039879","size":"3024.0"},{"price":"0.000039938","size":"0"},{"price":"0.000039946","size":"3785.4"}],"bid":[{"price":"0.000039533","size":"1262.0"},{"price":"0.000039517","size":"0"}],"sequence":13027037,"timestamp":"2021-04-17T16:46:38.707Z","symbol":"STORJBTC"}}
1618677998.802793: {"jsonrpc":"2.0","method":"updateOrderbook","params":{"ask":[{"price":"0.00011696","size":"29.1"},{"price":"0.00011887","size":"0"},{"price":"0.00011937","size":"998.2"},{"price":"0.00011938","size":"0"},{"price":"0.00011991","size":"0"},{"price":"0.00012044","size":"1721.1"}],"bid":[{"price":"0.00011488","size":"0"},{"price":"0.00011476","size":"40.5"},{"price":"0.00010658","size":"234.5"}],"sequence":19114008,"timestamp":"2021-04-17T16:46:38.749Z","symbol":"XTZBTC"}}
1618677998.885918: {"jsonrpc":"2.0","method":"updateOrderbook","params":{"ask":[{"price":"0.000026908","size":"0"}],"bid":[],"sequence":1389895,"timestamp":"2021-04-17T16:46:38.801Z","symbol":"HEDGBTC"}}
1618677998.89107: {"jsonrpc":"2.0","method":"updateOrderbook","params":{"ask":[{"price":"0.000039773","size":"1150.2"},{"price":"0.000039795","size":"0"},{"price":"0.000039851","size":"176.2"},{"price":"0.000039863","size":"191.8"},{"price":"0.000039892","size":"0"},{"price":"0.000039897","size":"0"}],"bid":[],"sequence":13027038,"timestamp":"2021-04-17T16:46:38.784Z","symbol":"STORJBTC"}}
1618677998.9084: {"jsonrpc":"2.0","method":"updateOrderbook","params":{"ask":[{"price":"0.00011696","size":"0"},{"price":"0.00011887","size":"29.1"},{"price":"0.00011932","size":"600.2"},{"price":"0.00011935","size":"0"}],"bid":[{"price":"0.00011476","size":"0"},{"price":"0.00011407","size":"40.5"}],"sequence":19114009,"timestamp":"2021-04-17T16:46:38.814Z","symbol":"XTZBTC"}}
1618677998.9866319: {"jsonrpc":"2.0","method":"updateOrderbook","params":{"ask":[{"price":"0.000026906","size":"562.4"},{"price":"0.000026907","size":"0"},{"price":"0.000030785","size":"326.6"}],"bid":[],"sequence":1389896,"timestamp":"2021-04-17T16:46:38.887Z","symbol":"HEDGBTC"}}
1618677998.9950662: {"jsonrpc":"2.0","method":"updateOrderbook","params":{"ask":[{"price":"0.000039739","size":"261.3"},{"price":"0.000039752","size":"0"},{"price":"0.000039813","size":"0"},{"price":"0.000039826","size":"2795.3"},{"price":"0.000039859","size":"0"},{"price":"0.000039870","size":"3812.3"},{"price":"0.000040079","size":"6736.1"},{"price":"0.000040157","size":"0"}],"bid":[{"price":"0.000038358","size":"0"}],"sequence":13027039,"timestamp":"2021-04-17T16:46:38.933Z","symbol":"STORJBTC"}}
1618677999.000932: {"jsonrpc":"2.0","method":"updateOrderbook","params":{"ask":[{"price":"0.00011948","size":"200.7"},{"price":"0.00011950","size":"1845.7"},{"price":"0.00012026","size":"1525.3"},{"price":"0.00012030","size":"1588.6"},{"price":"0.00012034","size":"1718.8"}],"bid":[{"price":"0.00011476","size":"40.5"},{"price":"0.00011407","size":"0"}],"sequence":19114010,"timestamp":"2021-04-17T16:46:38.912Z","symbol":"XTZBTC"}}
1618677999.124886: {"jsonrpc":"2.0","method":"updateOrderbook","params":{"ask":[{"price":"0.000026905","size":"91.1"},{"price":"0.000030785","size":"0"}],"bid":[],"sequence":1389897,"timestamp":"2021-04-17T16:46:38.986Z","symbol":"HEDGBTC"}}
1618677999.125047: {"jsonrpc":"2.0","method":"updateOrderbook","params":{"ask":[],"bid":[{"price":"0.000038362","size":"156.4"}],"sequence":13027040,"timestamp":"2021-04-17T16:46:38.953Z","symbol":"STORJBTC"}}
1618677999.125112: {"jsonrpc":"2.0","method":"updateOrderbook","params":{"ask":[{"price":"0.00012066","size":"8993.7"},{"price":"0.00012076","size":"0"},{"price":"0.00012101","size":"9834.8"},{"price":"0.00012116","size":"0"},{"price":"0.00012191","size":"12140.3"},{"price":"0.00012214","size":"0"},{"price":"0.00012283","size":"11096.2"},{"price":"0.00012304","size":"0"},{"price":"0.00012452","size":"20099.1"},{"price":"0.00012472","size":"0"}],"bid":[{"price":"0.00011406","size":"0"}],"sequence":19114011,"timestamp":"2021-04-17T16:46:39.012Z","symbol":"XTZBTC"}}
1618677999.1917608: {"jsonrpc":"2.0","method":"updateOrderbook","params":{"ask":[],"bid":[{"price":"0.000038362","size":"0"}],"sequence":13027041,"timestamp":"2021-04-17T16:46:39.081Z","symbol":"STORJBTC"}}
1618677999.198169: {"jsonrpc":"2.0","method":"updateOrderbook","params":{"ask":[],"bid":[{"price":"0.00021286","size":"5.79"},{"price":"0.00014240","size":"0"}],"sequence":10038663,"timestamp":"2021-04-17T16:46:39.072Z","symbol":"SUNBTC"}}
1618677999.198295: {"jsonrpc":"2.0","method":"updateOrderbook","params":{"ask":[{"price":"0.00012042","size":"1165.8"},{"price":"0.00012075","size":"0"},{"price":"0.00012536","size":"5272.4"},{"price":"0.00012560","size":"0"},{"price":"0.00012850","size":"7832.8"},{"price":"0.00012886","size":"0"}],"bid":[{"price":"0.00011408","size":"734.0"}],"sequence":19114012,"timestamp":"2021-04-17T16:46:39.105Z","symbol":"XTZBTC"}}
1618677999.2889578: {"jsonrpc":"2.0","method":"updateOrderbook","params":{"ask":[{"price":"0.000040218","size":"0"},{"price":"0.000040301","size":"1551.8"}],"bid":[{"price":"0.000038356","size":"156.4"}],"sequence":13027042,"timestamp":"2021-04-17T16:46:39.215Z","symbol":"STORJBTC"}}
1618677999.3011: {"jsonrpc":"2.0","method":"updateOrderbook","params":{"ask":[{"price":"0.00011930","size":"0"},{"price":"0.00011932","size":"901.7"},{"price":"0.00011935","size":"94.0"},{"price":"0.00011937","size":"562.1"},{"price":"0.00011939","size":"436.1"},{"price":"0.00011941","size":"1073.8"},{"price":"0.00011985","size":"3675.0"},{"price":"0.00011994","size":"0"}],"bid":[],"sequence":19114013,"timestamp":"2021-04-17T16:46:39.227Z","symbol":"XTZBTC"}}
1618677999.309267: {"jsonrpc":"2.0","method":"updateOrderbook","params":{"ask":[],"bid":[{"price":"1.4800150","size":"0"}],"sequence":11642117,"timestamp":"2021-04-17T16:46:39.185Z","symbol":"MANAUSD"}}
1618677999.399148: {"jsonrpc":"2.0","method":"updateOrderbook","params":{"ask":[{"price":"0.000039865","size":"253.5"},{"price":"0.000039877","size":"321.6"},{"price":"0.000039925","size":"0"},{"price":"0.000039937","size":"0"},{"price":"0.000040438","size":"0"},{"price":"0.000040512","size":"2058.7"},{"price":"0.000041368","size":"0"},{"price":"0.000041511","size":"2812.0"}],"bid":[{"price":"0.000038356","size":"0"}],"sequence":13027043,"timestamp":"2021-04-17T16:46:39.344Z","symbol":"STORJBTC"}}
1618677999.405797: {"jsonrpc":"2.0","method":"updateOrderbook","params":{"ask":[{"price":"0.00011968","size":"483.6"},{"price":"0.00011975","size":"0"}],"bid":[],"sequence":19114014,"timestamp":"2021-04-17T16:46:39.280Z","symbol":"XTZBTC"}}
1618677999.415106: {"jsonrpc":"2.0","method":"updateOrderbook","params":{"ask":[{"price":"1.5381067","size":"0"}],"bid":[{"price":"1.3123035","size":"0"},{"price":"1.3092160","size":"5289"},{"price":"1.2510955","size":"0"},{"price":"1.2498246","size":"8138"}],"sequence":11642118,"timestamp":"2021-04-17T16:46:39.346Z","symbol":"MANAUSD"}}
1618677999.51184: {"jsonrpc":"2.0","method":"updateOrderbook","params":{"ask":[],"bid":[{"price":"0.000038358","size":"156.4"}],"sequence":13027044,"timestamp":"2021-04-17T16:46:39.393Z","symbol":"STORJBTC"}}
1618677999.511955: {"jsonrpc":"2.0","method":"updateOrderbook","params":{"ask":[{"price":"0.00011958","size":"1253.2"},{"price":"0.00012013","size":"0"}],"bid":[],"sequence":19114015,"timestamp":"2021-04-17T16:46:39.373Z","symbol":"XTZBTC"}}
1618677999.519978: {"jsonrpc":"2.0","method":"updateOrderbook","params":{"ask":[{"price":"1.5367653","size":"5"},{"price":"1.5388721","size":"0"},{"price":"1.5394556","size":"294"}],"bid":[],"sequence":11642119,"timestamp":"2021-04-17T16:46:39.367Z","symbol":"MANAUSD"}}
1618677999.520118: {"jsonrpc":"2.0","method":"updateOrderbook","params":{"ask":[{"price":"0.2197710","size":"23.27"},{"price":"0.2199085","size":"0"}],"bid":[],"sequence":4920760,"timestamp":"2021-04-17T16:46:39.369Z","symbol":"BNBETH"}}
1618677999.593032: {"jsonrpc":"2.0","method":"updateOrderbook","params":{"ask":[{"price":"0.000039748","size":"1829.4"},{"price":"0.000039760","size":"0"},{"price":"0.000039823","size":"2594.7"},{"price":"0.000039831","size":"0"},{"price":"0.000039872","size":"3024.0"},{"price":"0.000039879","size":"0"},{"price":"0.000039937","size":"3785.4"},{"price":"0.000039946","size":"0"}],"bid":[],"sequence":13027045,"timestamp":"2021-04-17T16:46:39.540Z","symbol":"STORJBTC"}}
1618677999.610126: {"jsonrpc":"2.0","method":"updateOrderbook","params":{"ask":[{"price":"0.00011934","size":"378.8"},{"price":"0.00011937","size":"183.3"},{"price":"0.00011946","size":"1112.5"},{"price":"0.00011948","size":"0"},{"price":"0.00011949","size":"244.5"},{"price":"0.00011951","size":"924.8"},{"price":"0.00011954","size":"2750.5"},{"price":"0.00011956","size":"358.4"},{"price":"0.00012067","size":"7324.7"},{"price":"0.00012073","size":"0"}],"bid":[{"price":"0.00011090","size":"380.0"},{"price":"0.00010654","size":"0"}],"sequence":19114016,"timestamp":"2021-04-17T16:46:39.521Z","symbol":"XTZBTC"}}
1618677999.62042: {"jsonrpc":"2.0","method":"updateOrderbook","params":{"ask":[],"bid":[{"price":"1.4800150","size":"1"}],"sequence":11642120,"timestamp":"2021-04-17T16:46:39.536Z","symbol":"MANAUSD"}}
1618677999.704035: {"jsonrpc":"2.0","method":"updateOrderbook","params":{"ask":[{"price":"0.00011967","size":"1165.1"},{"price":"0.00011984","size":"0"},{"price":"0.00012008","size":"1550.2"},{"price":"0.00012019","size":"4416.4"}],"bid":[{"price":"0.00011477","size":"20.2"},{"price":"0.00011475","size":"0"}],"sequence":19114017,"timestamp":"2021-04-17T16:46:39.647Z","symbol":"XTZBTC"}}
1618677999.789312: {"jsonrpc":"2.0","method":"updateOrderbook","params":{"ask":[{"price":"0.000039859","size":"3812.3"},{"price":"0.000039870","size":"0"},{"price":"0.000040485","size":"13527.3"},{"price":"0.000040487","size":"0"}],"bid":[],"sequence":13027046,"timestamp":"2021-04-17T16:46:39.711Z","symbol":"STORJBTC"}}
1618677999.803657: {"jsonrpc":"2.0","method":"updateOrderbook","params":{"ask":[{"price":"0.00133411","size":"10.00"},{"price":"0.00133434","size":"0"}],"bid":[],"sequence":10038664,"timestamp":"2021-04-17T16:46:39.681Z","symbol":"SUNBTC"}}
1618677999.803781: {"jsonrpc":"2.0","method":"updateOrderbook","params":{"ask":[{"price":"0.00011934","size":"0"},{"price":"0.00011935","size":"472.8"},{"price":"0.00011948","size":"296.7"},{"price":"0.00011952","size":"890.3"},{"price":"0.00011958","size":"0"},{"price":"0.00011961","size":"1763.2"},{"price":"0.00011968","size":"0"},{"price":"0.00011997","size":"885.0"},{"price":"0.00011998","size":"1253.2"},{"price":"0.00012006","size":"0"},{"price":"0.00012029","size":"1165.8"},{"price":"0.00012042","size":"0"},{"price":"0.00012067","size":"2525.5"},{"price":"0.00012073","size":"4799.2"}],"bid":[{"price":"0.00011478","size":"40.5"},{"price":"0.00011476","size":"0"}],"sequence":19114018,"timestamp":"2021-04-17T16:46:39.731Z","symbol":"XTZBTC"}}
1618677999.886546: {"jsonrpc":"2.0","method":"updateOrderbook","params":{"ask":[{"price":"0.000026906","size":"0"}],"bid":[],"sequence":1389898,"timestamp":"2021-04-17T16:46:39.776Z","symbol":"HEDGBTC"}}
1618677999.9072158: {"jsonrpc":"2.0","method":"updateOrderbook","params":{"ask":[{"price":"0.000039709","size":"431.7"},{"price":"0.000039710","size":"0"},{"price":"0.000039738","size":"1829.4"},{"price":"0.000039748","size":"0"},{"price":"0.000039809","size":"2594.7"},{"price":"0.000039823","size":"0"},{"price":"0.000039866","size":"3024.0"},{"price":"0.000039872","size":"0"},{"price":"0.000039930","size":"3785.4"},{"price":"0.000039937","size":"0"}],"bid":[],"sequence":13027047,"timestamp":"2021-04-17T16:46:39.843Z","symbol":"STORJBTC"}}
1618677999.918348: {"jsonrpc":"2.0","method":"updateOrderbook","params":{"ask":[{"price":"0.00011696","size":"29.1"},{"price":"0.00011887","size":"0"},{"price":"0.00011948","size":"0"},{"price":"0.00011951","size":"1221.5"},{"price":"0.00011967","size":"0"},{"price":"0.00011972","size":"3962.1"},{"price":"0.00012008","size":"0"},{"price":"0.00012015","size":"1550.2"},{"price":"0.00012937","size":"12500.4"},{"price":"0.00012952","size":"0"}],"bid":[],"sequence":19114019,"timestamp":"2021-04-17T16:46:39.844Z","symbol":"XTZBTC"}}
1618677999.988874: {"jsonrpc":"2.0","method":"updateOrderbook","params":{"ask":[{"price":"0.000026904","size":"562.4"},{"price":"0.000026905","size":"0"},{"price":"0.000030785","size":"326.6"}],"bid":[],"sequence":1389899,"timestamp":"2021-04-17T16:46:39.877Z","symbol":"HEDGBTC"}}
1618677999.9918249: {"jsonrpc":"2.0","method":"updateOrderbook","params":{"ask":[{"price":"0.000039879","size":"368.0"},{"price":"0.000039900","size":"462.9"},{"price":"0.000039939","size":"0"},{"price":"0.000039957","size":"0"}],"bid":[],"sequence":13027048,"timestamp":"2021-04-17T16:46:39.935Z","symbol":"STORJBTC"}}
1618677999.99607: {"jsonrpc":"2.0","method":"updateOrderbook","params":{"ask":[{"price":"0.00011696","size":"0"},{"price":"0.00011887","size":"29.1"},{"price":"0.00011954","size":"2394.4"},{"price":"0.00011956","size":"714.5"},{"price":"0.00011972","size":"2797.0"},{"price":"0.00011975","size":"1165.1"},{"price":"0.00011998","size":"0"},{"price":"0.00012003","size":"1253.2"},{"price":"0.00012044","size":"3579.4"},{"price":"0.00012049","size":"0"}],"bid":[{"price":"0.00011478","size":"0"},{"price":"0.00011409","size":"40.5"}],"sequence":19114020,"timestamp":"2021-04-17T16:46:39.918Z","symbol":"XTZBTC"}}
1618678000.087134: {"jsonrpc":"2.0","method":"updateOrderbook","params":{"ask":[{"price":"0.000026903","size":"91.1"},{"price":"0.000030785","size":"0"}],"bid":[],"sequence":1389900,"timestamp":"2021-04-17T16:46:39.989Z","symbol":"HEDGBTC"}}
1618678000.091404: {"jsonrpc":"2.0","method":"updateOrderbook","params":{"ask":[{"price":"0.000039702","size":"261.3"},{"price":"0.000039738","size":"0"},{"price":"0.000039739","size":"0"},{"price":"0.000039740","size":"1829.4"},{"price":"0.000039749","size":"1150.2"},{"price":"0.000039773","size":"0"},{"price":"0.000039809","size":"0"},{"price":"0.000039823","size":"2594.7"},{"price":"0.000039866","size":"0"},{"price":"0.000039873","size":"3024.0"},{"price":"0.000039899","size":"780.0"},{"price":"0.000039930","size":"0"},{"price":"0.000039936","size":"0"},{"price":"0.000039937","size":"3785.4"},{"price":"0.000040079","size":"0"},{"price":"0.000040123","size":"6736.1"},{"price":"0.000040223","size":"0"},{"price":"0.000040253","size":"9299.9"},{"price":"0.000040485","size":"0"},{"price":"0.000040522","size":"13527.3"}],"bid":[{"price":"0.000039533","size":"0"},{"price":"0.000039517","size":"1262.0"}],"sequence":13027049,"timestamp":"2021-04-17T16:46:40.043Z","symbol":"STORJBTC"}}
1618678000.095825: {"jsonrpc":"2.0","method":"updateOrderbook","params":{"ask":[],"bid":[{"price":"0.00011478","size":"40.5"},{"price":"0.00011409","size":"0"}],"sequence":19114021,"timestamp":"2021-04-17T16:46:40.005Z","symbol":"XTZBTC"}}
1618678000.418554: {"jsonrpc":"2.0","method":"updateOrderbook","params":{"ask":[{"price":"0.00011885","size":"0.4"},{"price":"0.00012012","size":"1550.2"},{"price":"0.00012015","size":"0"},{"price":"0.00012091","size":"5104.8"},{"price":"0.00012134","size":"0"},{"price":"0.00012180","size":"3868.5"},{"price":"0.00013457","size":"0"}],"bid":[{"price":"0.00011408","size":"0"},{"price":"0.00011406","size":"734.1"}],"sequence":19114022,"timestamp":"2021-04-17T16:46:40.143Z","symbol":"XTZBTC"}}
1618678000.418806: {"jsonrpc":"2.0","method":"updateOrderbook","params":{"ask":[{"price":"0.000039808","size":"104.5"},{"price":"0.000039820","size":"124.2"},{"price":"0.000039828","size":"0"},{"price":"0.000039840","size":"0"}],"bid":[],"sequence":13027050,"timestamp":"2021-04-17T16:46:40.240Z","symbol":"STORJBTC"}}
1618678000.418916: {"jsonrpc":"2.0","method":"updateOrderbook","params":{"ask":[{"price":"0.00133411","size":"0"},{"price":"0.00133480","size":"10.00"}],"bid":[{"price":"0.00016273","size":"10.00"},{"price":"0.00016258","size":"0"}],"sequence":10038665,"timestamp":"2021-04-17T16:46:40.238Z","symbol":"SUNBTC"}}
1618678000.419007: {"jsonrpc":"2.0","method":"updateOrderbook","params":{"ask":[{"price":"0.00011939","size":"0"},{"price":"0.00011942","size":"1221.3"},{"price":"0.00012165","size":"8300.3"},{"price":"0.00012176","size":"0"},{"price":"0.00014073","size":"17824.4"},{"price":"0.00014094","size":"0"}],"bid":[],"sequence":19114023,"timestamp":"2021-04-17T16:46:40.178Z","symbol":"XTZBTC"}}
1618678000.4190772: {"jsonrpc":"2.0","method":"updateOrderbook","params":{"ask":[{"price":"0.00133480","size":"0"},{"price":"0.00133560","size":"10.00"}],"bid":[{"price":"0.00016274","size":"10.00"},{"price":"0.00016273","size":"0"}],"sequence":10038666,"timestamp":"2021-04-17T16:46:40.325Z","symbol":"SUNBTC"}}
1618678000.4191291: {"jsonrpc":"2.0","method":"updateOrderbook","params":{"ask":[{"price":"0.00011934","size":"94.0"},{"price":"0.00011935","size":"378.8"},{"price":"0.00011939","size":"345.5"},{"price":"0.00011941","size":"728.3"},{"price":"0.00012180","size":"0"},{"price":"0.00012290","size":"3868.5"}],"bid":[],"sequence":19114024,"timestamp":"2021-04-17T16:46:40.316Z","symbol":"XTZBTC"}}
1618678000.493448: {"jsonrpc":"2.0","method":"updateOrderbook","params":{"ask":[{"price":"0.000039639","size":"537.3"},{"price":"0.000039640","size":"532.1"},{"price":"0.000039662","size":"431.7"},{"price":"0.000039689","size":"0"},{"price":"0.000039697","size":"0"},{"price":"0.000039709","size":"0"},{"price":"0.000039732","size":"1829.4"},{"price":"0.000039740","size":"0"},{"price":"0.000039813","size":"2594.7"},{"price":"0.000039823","size":"0"},{"price":"0.000039867","size":"3024.0"},{"price":"0.000039873","size":"0"},{"price":"0.000039932","size":"3785.4"},{"price":"0.000039937","size":"0"}],"bid":[],"sequence":13027051,"timestamp":"2021-04-17T16:46:40.441Z","symbol":"STORJBTC"}}
1618678000.509381: {"jsonrpc":"2.0","method":"updateOrderbook","params":{"ask":[{"price":"0.00133560","size":"0"},{"price":"0.00133618","size":"10.00"}],"bid":[{"price":"0.00016274","size":"0"},{"price":"0.00016273","size":"10.00"}],"sequence":10038667,"timestamp":"2021-04-17T16:46:40.423Z","symbol":"SUNBTC"}}
1618678000.509544: {"jsonrpc":"2.0","method":"updateOrderbook","params":{"ask":[{"price":"0.00011937","size":"0"},{"price":"0.00011938","size":"183.3"},{"price":"0.00011942","size":"1001.9"},{"price":"0.00011944","size":"1140.3"},{"price":"0.00011961","size":"1279.6"},{"price":"0.00011970","size":"483.6"},{"price":"0.00012290","size":"0"},{"price":"0.00012418","size":"3868.5"}],"bid":[],"sequence":19114025,"timestamp":"2021-04-17T16:46:40.438Z","symbol":"XTZBTC"}}
1618678000.5927281: {"jsonrpc":"2.0","method":"updateOrderbook","params":{"ask":[{"price":"0.000026904","size":"0"}],"bid":[],"sequence":1389901,"timestamp":"2021-04-17T16:46:40.468Z","symbol":"HEDGBTC"}}
1618678000.592829: {"jsonrpc":"2.0","method":"updateOrderbook","params":{"ask":[{"price":"0.00000000420","size":"811000"},{"price":"0.00000000450","size":"2001000"}],"bid":[],"sequence":1757679,"timestamp":"2021-04-17T16:46:40.510Z","symbol":"BANCABTC"}}
1618678000.592887: {"jsonrpc":"2.0","method":"updateOrderbook","params":{"ask":[{"price":"0.000039639","size":"0"},{"price":"0.000039640","size":"0"},{"price":"0.000039662","size":"0"},{"price":"0.000039699","size":"537.3"},{"price":"0.000039700","size":"532.1"},{"price":"0.000039709","size":"431.7"},{"price":"0.000039732","size":"0"},{"price":"0.000039741","size":"1829.4"},{"price":"0.000039813","size":"0"},{"price":"0.000039824","size":"2594.7"},{"price":"0.000039842","size":"3812.3"},{"price":"0.000039859","size":"0"},{"price":"0.000039867","size":"0"},{"price":"0.000039873","size":"3024.0"},{"price":"0.000039932","size":"0"},{"price":"0.000039938","size":"3785.4"},{"price":"0.000040225","size":"9299.9"},{"price":"0.000040253","size":"0"},{"price":"0.000040464","size":"13527.3"},{"price":"0.000040522","size":"0"}],"bid":[],"sequence":13027052,"timestamp":"2021-04-17T16:46:40.541Z","symbol":"STORJBTC"}}
1618678000.605891: {"jsonrpc":"2.0","method":"updateOrderbook","params":{"ask":[{"price":"0.00011922","size":"641.0"},{"price":"0.00011923","size":"0"},{"price":"0.00012165","size":"0"},{"price":"0.00012174","size":"8300.4"},{"price":"0.00014073","size":"0"},{"price":"0.00014090","size":"17824.4"}],"bid":[],"sequence":19114026,"timestamp":"2021-04-17T16:46:40.532Z","symbol":"XTZBTC"}}
1618678000.6901371: {"jsonrpc":"2.0","method":"updateOrderbook","params":{"ask":[{"price":"0.000026902","size":"562.4"},{"price":"0.000026903","size":"0"},{"price":"0.000030785","size":"326.6"}],"bid":[],"sequence":1389902,"timestamp":"2021-04-17T16:46:40.581Z","symbol":"HEDGBTC"}}
1618678000.6902888: {"jsonrpc":"2.0","method":"updateOrderbook","params":{"ask":[],"bid":[{"price":"0.00000000369","size":"2749000"},{"price":"0.00000000359","size":"1000"},{"price":"0.00000000237","size":"11651000"},{"price":"0.00000000230","size":"1000"}],"sequence":1757680,"timestamp":"2021-04-17T16:46:40.603Z","symbol":"BANCABTC"}}
1618678000.700855: {"jsonrpc":"2.0","method":"updateOrderbook","params":{"ask":[{"price":"0.000039659","size":"537.3"},{"price":"0.000039660","size":"532.1"},{"price":"0.000039699","size":"0"},{"price":"0.000039700","size":"0"},{"price":"0.000039702","size":"0"},{"price":"0.000039707","size":"261.3"},{"price":"0.000039735","size":"1829.4"},{"price":"0.000039741","size":"0"},{"price":"0.000039823","size":"2594.7"},{"price":"0.000039824","size":"0"},{"price":"0.000039934","size":"3785.4"},{"price":"0.000039938","size":"0"}],"bid":[],"sequence":13027053,"timestamp":"2021-04-17T16:46:40.610Z","symbol":"STORJBTC"}}
1618678000.710242: {"jsonrpc":"2.0","method":"updateOrderbook","params":{"ask":[],"bid":[{"price":"0.00011479","size":"20.2"},{"price":"0.00011477","size":"0"}],"sequence":19114027,"timestamp":"2021-04-17T16:46:40.570Z","symbol":"XTZBTC"}}
1618678000.7246249: {"jsonrpc":"2.0","method":"updateOrderbook","params":{"ask":[],"bid":[{"price":"0.2185672","size":"0"},{"price":"0.2184764","size":"23.27"},{"price":"0.2180042","size":"0"},{"price":"0.2178941","size":"100.00"},{"price":"0.2157404","size":"0"},{"price":"0.2156041","size":"14.00"}],"sequence":4920761,"timestamp":"2021-04-17T16:46:40.649Z","symbol":"BNBETH"}}
1618678000.789612: {"jsonrpc":"2.0","method":"updateOrderbook","params":{"ask":[{"price":"0.000026901","size":"91.1"},{"price":"0.000030785","size":"0"}],"bid":[],"sequence":1389903,"timestamp":"2021-04-17T16:46:40.690Z","symbol":"HEDGBTC"}}
1618678000.804333: {"jsonrpc":"2.0","method":"updateOrderbook","params":{"ask":[{"price":"0.000039659","size":"0"},{"price":"0.000039660","size":"0"},{"price":"0.000039689","size":"537.3"},{"price":"0.000039697","size":"532.1"},{"price":"0.000039707","size":"0"},{"price":"0.000039709","size":"0"},{"price":"0.000039710","size":"431.7"},{"price":"0.000039732","size":"261.3"},{"price":"0.000039735","size":"0"},{"price":"0.000039740","size":"1829.4"},{"price":"0.000039749","size":"0"},{"price":"0.000039754","size":"1150.2"},{"price":"0.000039820","size":"0"},{"price":"0.000039823","size":"0"},{"price":"0.000039824","size":"124.2"},{"price":"0.000039831","size":"2594.7"},{"price":"0.000039873","size":"0"},{"price":"0.000039879","size":"3392.0"},{"price":"0.000039899","size":"0"},{"price":"0.000039932","size":"780.0"},{"price":"0.000039934","size":"0"},{"price":"0.000039941","size":"3785.4"},{"price":"0.000039971","size":"0"},{"price":"0.000040035","size":"738.1"},{"price":"0.000040219","size":"0"},{"price":"0.000040273","size":"1123.9"}],"bid":[],"sequence":13027054,"timestamp":"2021-04-17T16:46:40.692Z","symbol":"STORJBTC"}}
1618678000.814514: {"jsonrpc":"2.0","method":"updateOrderbook","params":{"ask":[{"price":"0.00011696","size":"29.1"},{"price":"0.00011887","size":"0"},{"price":"0.00012012","size":"0"},{"price":"0.00012017","size":"1550.2"},{"price":"0.00016147","size":"5176.4"},{"price":"0.00019069","size":"0"}],"bid":[{"price":"0.00011480","size":"40.5"},{"price":"0.00011478","size":"0"}],"sequence":19114028,"timestamp":"2021-04-17T16:46:40.746Z","symbol":"XTZBTC"}}
1618678000.888095: {"jsonrpc":"2.0","method":"updateOrderbook","params":{"ask":[{"price":"0.0000006157","size":"359"}],"bid":[],"sequence":403555,"timestamp":"2021-04-17T16:46:40.833Z","symbol":"ACDBTC"}}
1618678000.899402: {"jsonrpc":"2.0","method":"updateOrderbook","params":{"ask":[{"price":"0.000039740","size":"0"},{"price":"0.000039760","size":"1829.4"},{"price":"0.000039841","size":"176.2"},{"price":"0.000039851","size":"0"},{"price":"0.000039853","size":"191.8"},{"price":"0.000039863","size":"0"}],"bid":[],"sequence":13027055,"timestamp":"2021-04-17T16:46:40.807Z","symbol":"STORJBTC"}}
1618678000.908376: {"jsonrpc":"2.0","method":"updateOrderbook","params":{"ask":[{"price":"0.00011696","size":"0"},{"price":"0.00011887","size":"29.1"}],"bid":[{"price":"0.00011480","size":"0"},{"price":"0.00011407","size":"40.5"}],"sequence":19114029,"timestamp":"2021-04-17T16:46:40.813Z","symbol":"XTZBTC"}}
1618678000.911488: {"jsonrpc":"2.0","method":"updateOrderbook","params":{"ask":[{"price":"1.5367653","size":"0"}],"bid":[],"sequence":11642121,"timestamp":"2021-04-17T16:46:40.823Z","symbol":"MANAUSD"}}
1618678000.993515: {"jsonrpc":"2.0","method":"updateOrderbook","params":{"ask":[],"bid":[{"price":"0.000039528","size":"1262.0"},{"price":"0.000039517","size":"0"}],"sequence":13027056,"timestamp":"2021-04-17T16:46:40.850Z","symbol":"STORJBTC"}}
1618678001.006582: {"jsonrpc":"2.0","method":"updateOrderbook","params":{"ask":[{"price":"0.00011934","size":"472.8"},{"price":"0.00011935","size":"0"},{"price":"0.00011954","size":"356.1"},{"price":"0.00011956","size":"358.4"},{"price":"0.00011964","size":"2394.4"},{"price":"0.00011985","size":"0"},{"price":"0.00012019","size":"8091.4"},{"price":"0.00012174","size":"0.1"},{"price":"0.00012228","size":"8300.3"},{"price":"0.00012937","size":"0"},{"price":"0.00013097","size":"12500.4"},{"price":"0.00014090","size":"0"},{"price":"0.00014170","size":"17824.4"}],"bid":[{"price":"0.00011480","size":"40.5"},{"price":"0.00011407","size":"0"}],"sequence":19114030,"timestamp":"2021-04-17T16:46:40.909Z","symbol":"XTZBTC"}}
1618678001.016321: {"jsonrpc":"2.0","method":"updateOrderbook","params":{"ask":[{"price":"1.5639598","size":"0"},{"price":"1.5644120","size":"33819"},{"price":"1.5724304","size":"0"},{"price":"1.5729893","size":"32731"},{"price":"1.5927122","size":"0"},{"price":"1.5932338","size":"36462"},{"price":"1.6134394","size":"0"},{"price":"1.6139178","size":"37094"}],"bid":[],"sequence":11642122,"timestamp":"2021-04-17T16:46:40.939Z","symbol":"MANAUSD"}}
1618678001.0863519: {"jsonrpc":"2.0","method":"updateOrderbook","params":{"ask":[{"price":"0.00000000420","size":"0"},{"price":"0.00000000450","size":"2812000"}],"bid":[],"sequence":1757681,"timestamp":"2021-04-17T16:46:41.016Z","symbol":"BANCABTC"}}
1618678001.0897222: {"jsonrpc":"2.0","method":"updateOrderbook","params":{"ask":[{"price":"0.000039751","size":"1829.4"},{"price":"0.000039760","size":"0"},{"price":"0.000039824","size":"2718.9"},{"price":"0.000039829","size":"3812.3"},{"price":"0.000039831","size":"0"},{"price":"0.000039842","size":"0"},{"price":"0.000039873","size":"3024.0"},{"price":"0.000039879","size":"368.0"},{"price":"0.000039934","size":"3785.4"},{"price":"0.000039941","size":"0"},{"price":"0.000040196","size":"9299.9"},{"price":"0.000040225","size":"0"},{"price":"0.000040426","size":"13527.3"},{"price":"0.000040464","size":"0"}],"bid":[{"price":"0.000038358","size":"0"}],"sequence":13027057,"timestamp":"2021-04-17T16:46:41.044Z","symbol":"STORJBTC"}}
1618678001.10499: {"jsonrpc":"2.0","method":"updateOrderbook","params":{"ask":[{"price":"0.00000119569","size":"592740"},{"price":"0.00000119759","size":"0"},{"price":"0.00000120369","size":"694310"},{"price":"0.00000120446","size":"0"},{"price":"0.00000121365","size":"922200"},{"price":"0.00000121541","size":"0"}],"bid":[],"sequence":5061575,"timestamp":"2021-04-17T16:46:40.952Z","symbol":"CELRBTC"}}
1618678001.2046561: {"jsonrpc":"2.0","method":"updateOrderbook","params":{"ask":[],"bid":[{"price":"0.00000000369","size":"310000"},{"price":"0.00000000359","size":"2440000"},{"price":"0.00000000237","size":"1000"},{"price":"0.00000000230","size":"11651000"}],"sequence":1757682,"timestamp":"2021-04-17T16:46:41.088Z","symbol":"BANCABTC"}}
1618678001.2047842: {"jsonrpc":"2.0","method":"updateOrderbook","params":{"ask":[],"bid":[{"price":"0.000038362","size":"156.4"}],"sequence":13027058,"timestamp":"2021-04-17T16:46:41.050Z","symbol":"STORJBTC"}}
1618678001.2048562: {"jsonrpc":"2.0","method":"updateOrderbook","params":{"ask":[{"price":"0.00011932","size":"1337.8"},{"price":"0.00011934","size":"378.8"},{"price":"0.00011935","size":"94.0"},{"price":"0.00011936","size":"728.3"},{"price":"0.00011939","size":"0"},{"price":"0.00011941","size":"345.5"},{"price":"0.00011942","size":"565.8"},{"price":"0.00012003","size":"0"},{"price":"0.00012012","size":"1253.2"}],"bid":[],"sequence":19114031,"timestamp":"2021-04-17T16:46:41.053Z","symbol":"XTZBTC"}}
1618678001.292691: {"jsonrpc":"2.0","method":"updateOrderbook","params":{"ask":[{"price":"0.000039829","size":"0"},{"price":"0.000039840","size":"3812.3"}],"bid":[{"price":"0.000038362","size":"0"},{"price":"0.000038356","size":"156.4"},{"price":"0.000038355","size":"820.0"},{"price":"0.000035192","size":"780.0"}],"sequence":13027059,"timestamp":"2021-04-17T16:46:41.198Z","symbol":"STORJBTC"}}
1618678001.300055: {"jsonrpc":"2.0","method":"updateOrderbook","params":{"ask":[{"price":"0.00133618","size":"0"},{"price":"0.00133664","size":"10.00"}],"bid":[{"price":"0.00016319","size":"10.00"},{"price":"0.00016273","size":"0"}],"sequence":10038668,"timestamp":"2021-04-17T16:46:41.213Z","symbol":"SUNBTC"}}
1618678001.3982852: {"jsonrpc":"2.0","method":"updateOrderbook","params":{"ask":[{"price":"0.000026900","size":"562.4"},{"price":"0.000026902","size":"0"}],"bid":[],"sequence":1389904,"timestamp":"2021-04-17T16:46:41.337Z","symbol":"HEDGBTC"}}
1618678001.39845: {"jsonrpc":"2.0","method":"updateOrderbook","params":{"ask":[{"price":"0.000039732","size":"0"},{"price":"0.000039739","size":"261.3"},{"price":"0.000039754","size":"0"},{"price":"0.000039764","size":"1150.2"},{"price":"0.000040196","size":"0"},{"price":"0.000040230","size":"9299.9"},{"price":"0.000040426","size":"0"},{"price":"0.000040472","size":"13527.3"}],"bid":[{"price":"0.000038356","size":"0"}],"sequence":13027060,"timestamp":"2021-04-17T16:46:41.331Z","symbol":"STORJBTC"}}
1618678001.402675: {"jsonrpc":"2.0","method":"updateOrderbook","params":{"ask":[{"price":"0.00011932","size":"901.7"},{"price":"0.00011936","size":"0"},{"price":"0.00011942","size":"1730.2"},{"price":"0.00011950","size":"0"},{"price":"0.00011964","size":"0"},{"price":"0.00011978","size":"1845.7"},{"price":"0.00012011","size":"2394.4"},{"price":"0.00012019","size":"4416.4"},{"price":"0.00012073","size":"0"},{"price":"0.00012076","size":"3675.0"},{"price":"0.00012079","size":"8087.3"},{"price":"0.00012081","size":"0"},{"price":"0.00012108","size":"6070.5"},{"price":"0.00012228","size":"0"},{"price":"0.00012370","size":"8300.3"},{"price":"0.00013097","size":"0"},{"price":"0.00013480","size":"12500.4"},{"price":"0.00014170","size":"0"},{"price":"0.00014347","size":"17824.4"}],"bid":[],"sequence":19114032,"timestamp":"2021-04-17T16:46:41.268Z","symbol":"XTZBTC"}}
1618678001.4886541: {"jsonrpc":"2.0","method":"updateOrderbook","params":{"ask":[{"price":"0.000026899","size":"91.1"},{"price":"0.000026901","size":"0"}],"bid":[],"sequence":1389905,"timestamp":"2021-04-17T16:46:41.379Z","symbol":"HEDGBTC"}}
1618678001.503448: {"jsonrpc":"2.0","method":"updateOrderbook","params":{"ask":[{"price":"0.000039689","size":"0"},{"price":"0.000039697","size":"0"},{"price":"0.000039709","size":"537.3"},{"price":"0.000039710","size":"532.1"},{"price":"0.000039719","size":"431.7"},{"price":"0.000039751","size":"0"},{"price":"0.000039766","size":"1829.4"},{"price":"0.000039824","size":"0"},{"price":"0.000039830","size":"2594.7"},{"price":"0.000039834","size":"124.2"},{"price":"0.000039840","size":"0"},{"price":"0.000039841","size":"0"},{"price":"0.000039851","size":"3812.3"},{"price":"0.000039853","size":"0"},{"price":"0.000039861","size":"176.2"},{"price":"0.000039865","size":"0"},{"price":"0.000039873","size":"191.8"},{"price":"0.000039877","size":"0"},{"price":"0.000039879","size":"3024.0"},{"price":"0.000039885","size":"253.5"},{"price":"0.000039897","size":"321.6"},{"price":"0.000039909","size":"4001.3"},{"price":"0.000039934","size":"0"},{"price":"0.000039940","size":"3785.4"}],"bid":[{"price":"0.000038359","size":"156.4"}],"sequence":13027061,"timestamp":"2021-04-17T16:46:41.435Z","symbol":"STORJBTC"}}
1618678001.606833: {"jsonrpc":"2.0","method":"updateOrderbook","params":{"ask":[{"price":"0.000039699","size":"537.3"},{"price":"0.000039700","size":"532.1"},{"price":"0.000039709","size":"431.7"},{"price":"0.000039710","size":"0"},{"price":"0.000039719","size":"0"},{"price":"0.000039760","size":"1829.4"},{"price":"0.000039766","size":"0"},{"price":"0.000039830","size":"0"},{"price":"0.000039835","size":"2594.7"},{"price":"0.000039879","size":"0"},{"price":"0.000039886","size":"3024.0"},{"price":"0.000039932","size":"0"},{"price":"0.000039940","size":"0"},{"price":"0.000039948","size":"3785.4"},{"price":"0.000039990","size":"780.0"}],"bid":[],"sequence":13027062,"timestamp":"2021-04-17T16:46:41.544Z","symbol":"STORJBTC"}}
1618678001.607281: {"jsonrpc":"2.0","method":"updateOrderbook","params":{"ask":[],"bid":[{"price":"0.00016320","size":"10.00"},{"price":"0.00016319","size":"0"}],"sequence":10038669,"timestamp":"2021-04-17T16:46:41.459Z","symbol":"SUNBTC"}}
1618678001.691833: {"jsonrpc":"2.0","method":"updateOrderbook","params":{"ask":[{"price":"0.000039699","size":"0"},{"price":"0.000039700","size":"0"},{"price":"0.000039709","size":"0"},{"price":"0.000039729","size":"537.3"},{"price":"0.000039730","size":"532.1"},{"price":"0.000039739","size":"693.0"},{"price":"0.000039760","size":"0"},{"price":"0.000039774","size":"1829.4"},{"price":"0.000039798","size":"2795.3"},{"price":"0.000039826","size":"0"},{"price":"0.000039835","size":"0"},{"price":"0.000039843","size":"2594.7"},{"price":"0.000039886","size":"0"},{"price":"0.000039891","size":"3024.0"},{"price":"0.000039947","size":"780.0"},{"price":"0.000039948","size":"0"},{"price":"0.000039953","size":"3785.4"},{"price":"0.000039990","size":"0"}],"bid":[],"sequence":13027063,"timestamp":"2021-04-17T16:46:41.573Z","symbol":"STORJBTC"}}
1618678001.702702: {"jsonrpc":"2.0","method":"updateOrderbook","params":{"ask":[{"price":"0.00133542","size":"10.00"},{"price":"0.00133664","size":"0"}],"bid":[{"price":"0.00021286","size":"0"},{"price":"0.00019250","size":"5.79"}],"sequence":10038670,"timestamp":"2021-04-17T16:46:41.638Z","symbol":"SUNBTC"}}
1618678001.70289: {"jsonrpc":"2.0","method":"updateOrderbook","params":{"ask":[{"price":"0.00011931","size":"378.8"},{"price":"0.00011934","size":"0"},{"price":"0.00011968","size":"1165.1"},{"price":"0.00011975","size":"0"},{"price":"0.00012013","size":"1550.2"},{"price":"0.00012017","size":"0"}],"bid":[{"price":"0.00011481","size":"20.2"},{"price":"0.00011479","size":"0"}],"sequence":19114033,"timestamp":"2021-04-17T16:46:41.647Z","symbol":"XTZBTC"}}
1618678001.7161732: {"jsonrpc":"2.0","method":"updateOrderbook","params":{"ask":[],"bid":[{"price":"1.4800150","size":"0"}],"sequence":11642123,"timestamp":"2021-04-17T16:46:41.636Z","symbol":"MANAUSD"}}
1618678001.792732: {"jsonrpc":"2.0","method":"updateOrderbook","params":{"ask":[{"price":"0.000039719","size":"537.3"},{"price":"0.000039720","size":"532.1"},{"price":"0.000039729","size":"0"},{"price":"0.000039730","size":"0"},{"price":"0.000039736","size":"431.7"},{"price":"0.000039739","size":"261.3"},{"price":"0.000039769","size":"1829.4"},{"price":"0.000039774","size":"0"},{"price":"0.000039839","size":"2594.7"},{"price":"0.000039843","size":"0"},{"price":"0.000039889","size":"3024.0"},{"price":"0.000039891","size":"0"},{"price":"0.000039915","size":"780.0"},{"price":"0.000039947","size":"0"}],"bid":[],"sequence":13027064,"timestamp":"2021-04-17T16:46:41.695Z","symbol":"STORJBTC"}}
1618678001.807276: {"jsonrpc":"2.0","method":"updateOrderbook","params":{"ask":[{"price":"0.00011921","size":"102.6"},{"price":"0.00011922","size":"538.4"},{"price":"0.00011940","size":"438.1"},{"price":"0.00011942","size":"1294.1"}],"bid":[{"price":"0.00011482","size":"40.5"},{"price":"0.00011480","size":"0"}],"sequence":19114034,"timestamp":"2021-04-17T16:46:41.700Z","symbol":"XTZBTC"}}
1618678001.895564: {"jsonrpc":"2.0","method":"updateOrderbook","params":{"ask":[{"price":"0.000026900","size":"0"}],"bid":[],"sequence":1389906,"timestamp":"2021-04-17T16:46:41.844Z","symbol":"HEDGBTC"}}
1618678001.895707: {"jsonrpc":"2.0","method":"updateOrderbook","params":{"ask":[{"price":"0.000039709","size":"537.3"},{"price":"0.000039710","size":"532.1"},{"price":"0.000039719","size":"431.7"},{"price":"0.000039720","size":"0"},{"price":"0.000039736","size":"0"},{"price":"0.000039755","size":"1829.4"},{"price":"0.000039769","size":"0"},{"price":"0.000039831","size":"2594.7"},{"price":"0.000039839","size":"0"},{"price":"0.000039884","size":"3024.0"},{"price":"0.000039889","size":"0"},{"price":"0.000039945","size":"3785.4"},{"price":"0.000039953","size":"0"}],"bid":[],"sequence":13027065,"timestamp":"2021-04-17T16:46:41.797Z","symbol":"STORJBTC"}}
1618678001.8998551: {"jsonrpc":"2.0","method":"updateOrderbook","params":{"ask":[{"price":"0.00011941","size":"1266.4"},{"price":"0.00011944","size":"219.4"}],"bid":[{"price":"0.00011120","size":"380.0"},{"price":"0.00011090","size":"0"}],"sequence":19114035,"timestamp":"2021-04-17T16:46:41.844Z","symbol":"XTZBTC"}}
1618678001.9866939: {"jsonrpc":"2.0","method":"updateOrderbook","params":{"ask":[{"price":"0.000026898","size":"562.4"},{"price":"0.000026899","size":"0"},{"price":"0.000030785","size":"326.6"}],"bid":[],"sequence":1389907,"timestamp":"2021-04-17T16:46:41.916Z","symbol":"HEDGBTC"}}
1618678001.9926898: {"jsonrpc":"2.0","method":"updateOrderbook","params":{"ask":[{"price":"0.000039839","size":"3812.3"},{"price":"0.000039851","size":"0"}],"bid":[],"sequence":13027066,"timestamp":"2021-04-17T16:46:41.858Z","symbol":"STORJBTC"}}
1618678002.087508: {"jsonrpc":"2.0","method":"updateOrderbook","params":{"ask":[{"price":"0.000026897","size":"91.1"},{"price":"0.000030785","size":"0"}],"bid":[],"sequence":1389908,"timestamp":"2021-04-17T16:46:41.976Z","symbol":"HEDGBTC"}}
1618678002.1102972: {"jsonrpc":"2.0","method":"updateOrderbook","params":{"ask":[{"price":"0.00011921","size":"0"},{"price":"0.00011926","size":"102.6"},{"price":"0.00011931","size":"0"},{"price":"0.00011932","size":"1280.5"},{"price":"0.00011944","size":"420.1"},{"price":"0.00011946","size":"911.8"},{"price":"0.00011947","size":"1812.3"},{"price":"0.00011949","size":"0"},{"price":"0.00011952","size":"1246.4"},{"price":"0.00011954","size":"0"},{"price":"0.00012029","size":"0"},{"price":"0.00012041","size":"3419.4"},{"price":"0.00016147","size":"0"},{"price":"0.00016222","size":"5176.4"}],"bid":[],"sequence":19114036,"timestamp":"2021-04-17T16:46:42.042Z","symbol":"XTZBTC"}}
1618678002.116619: {"jsonrpc":"2.0","method":"updateOrderbook","params":{"ask":[{"price":"0.00000123868","size":"1107430"},{"price":"0.00000124063","size":"0"},{"price":"0.00000126876","size":"2245050"},{"price":"0.00000127073","size":"0"}],"bid":[],"sequence":5061576,"timestamp":"2021-04-17T16:46:42.021Z","symbol":"CELRBTC"}}
1618678002.1205492: {"jsonrpc":"2.0","method":"updateOrderbook","params":{"ask":[],"bid":[{"price":"0.2157052","size":"14.00"},{"price":"0.2156041","size":"0"}],"sequence":4920762,"timestamp":"2021-04-17T16:46:41.995Z","symbol":"BNBETH"}}
1618678002.189132: {"jsonrpc":"2.0","method":"updateOrderbook","params":{"ask":[{"price":"0.000039808","size":"0"},{"price":"0.000039831","size":"2699.2"},{"price":"0.000039834","size":"0"},{"price":"0.000039850","size":"124.2"}],"bid":[],"sequence":13027067,"timestamp":"2021-04-17T16:46:42.060Z","symbol":"STORJBTC"}}
1618678002.204779: {"jsonrpc":"2.0","method":"updateOrderbook","params":{"ask":[],"bid":[{"price":"0.00016320","size":"0"},{"price":"0.00016319","size":"10.00"}],"sequence":10038671,"timestamp":"2021-04-17T16:46:42.138Z","symbol":"SUNBTC"}}
1618678002.204938: {"jsonrpc":"2.0","method":"updateOrderbook","params":{"ask":[{"price":"0.00012025","size":"1165.8"},{"price":"0.00012041","size":"2253.6"}],"bid":[],"sequence":19114037,"timestamp":"2021-04-17T16:46:42.118Z","symbol":"XTZBTC"}}
1618678002.207506: {"jsonrpc":"2.0","method":"updateOrderbook","params":{"ask":[],"bid":[{"price":"0.00000107774","size":"0"}],"sequence":5061577,"timestamp":"2021-04-17T16:46:42.054Z","symbol":"CELRBTC"}}
1618678002.293568: {"jsonrpc":"2.0","method":"updateOrderbook","params":{"ask":[{"price":"0.000039699","size":"537.3"},{"price":"0.000039700","size":"532.1"},{"price":"0.000039709","size":"431.7"},{"price":"0.000039710","size":"0"},{"price":"0.000039719","size":"0"},{"price":"0.000039749","size":"1829.4"},{"price":"0.000039755","size":"0"},{"price":"0.000039820","size":"2594.7"},{"price":"0.000039831","size":"104.5"},{"price":"0.000039879","size":"3024.0"},{"price":"0.000039884","size":"0"},{"price":"0.000039937","size":"3785.4"},{"price":"0.000039945","size":"0"},{"price":"0.000040442","size":"13527.3"},{"price":"0.000040472","size":"0"}],"bid":[{"price":"0.000039539","size":"1262.0"},{"price":"0.000039528","size":"0"}],"sequence":13027068,"timestamp":"2021-04-17T16:46:42.246Z","symbol":"STORJBTC"}}
1618678002.320294: {"jsonrpc":"2.0","method":"updateOrderbook","params":{"ask":[{"price":"0.00011696","size":"29.1"},{"price":"0.00011887","size":"0"},{"price":"0.00011939","size":"345.5"},{"price":"0.00011940","size":"2.0"},{"price":"0.00011941","size":"920.9"},{"price":"0.00011942","size":"1730.2"},{"price":"0.00011944","size":"219.4"},{"price":"0.00011946","size":"1112.5"},{"price":"0.00011947","size":"1567.8"},{"price":"0.00011948","size":"1845.7"},{"price":"0.00011951","size":"3860.4"},{"price":"0.00011952","size":"890.3"},{"price":"0.00011957","size":"356.1"},{"price":"0.00011968","size":"0"},{"price":"0.00011978","size":"1165.1"},{"price":"0.00012011","size":"0"},{"price":"0.00012013","size":"0"},{"price":"0.00012017","size":"1550.2"}],"bid":[],"sequence":19114038,"timestamp":"2021-04-17T16:46:42.244Z","symbol":"XTZBTC"}}
1618678002.321703: {"jsonrpc":"2.0","method":"updateOrderbook","params":{"ask":[],"bid":[{"price":"0.00000107776","size":"18900"}],"sequence":5061578,"timestamp":"2021-04-17T16:46:42.168Z","symbol":"CELRBTC"}}
1618678002.390221: {"jsonrpc":"2.0","method":"updateOrderbook","params":{"ask":[{"price":"0.000039820","size":"0"},{"price":"0.000039823","size":"2594.7"},{"price":"0.000039879","size":"0"},{"price":"0.000039880","size":"3024.0"},{"price":"0.000039937","size":"0"},{"price":"0.000039941","size":"3785.4"}],"bid":[],"sequence":13027069,"timestamp":"2021-04-17T16:46:42.345Z","symbol":"STORJBTC"}}
1618678002.4078348: {"jsonrpc":"2.0","method":"updateOrderbook","params":{"ask":[{"price":"0.00011696","size":"0"},{"price":"0.00011887","size":"29.1"}],"bid":[{"price":"0.00011482","size":"0"},{"price":"0.00011407","size":"40.5"}],"sequence":19114039,"timestamp":"2021-04-17T16:46:42.296Z","symbol":"XTZBTC"}}
1618678002.492555: {"jsonrpc":"2.0","method":"updateOrderbook","params":{"ask":[{"price":"0.000039881","size":"5302.1"},{"price":"0.000039916","size":"0"},{"price":"0.000039996","size":"6736.1"},{"price":"0.000040123","size":"0"}],"bid":[],"sequence":13027070,"timestamp":"2021-04-17T16:46:42.352Z","symbol":"STORJBTC"}}
1618678002.504241: {"jsonrpc":"2.0","method":"updateOrderbook","params":{"ask":[],"bid":[{"price":"0.00016319","size":"0"},{"price":"0.00016318","size":"10.00"}],"sequence":10038672,"timestamp":"2021-04-17T16:46:42.365Z","symbol":"SUNBTC"}}
1618678002.506977: {"jsonrpc":"2.0","method":"updateOrderbook","params":{"ask":[{"price":"0.00011925","size":"102.6"},{"price":"0.00011926","size":"0"},{"price":"0.00011931","size":"378.8"},{"price":"0.00011932","size":"901.7"},{"price":"0.00011939","size":"0"},{"price":"0.00011941","size":"1266.4"}],"bid":[{"price":"0.00011482","size":"40.5"},{"price":"0.00011407","size":"0"}],"sequence":19114040,"timestamp":"2021-04-17T16:46:42.416Z","symbol":"XTZBTC"}}
1618678002.5951989: {"jsonrpc":"2.0","method":"updateOrderbook","params":{"ask":[{"price":"0.000026898","size":"0"}],"bid":[{"price":"0.000023963","size":"8.2"}],"sequence":1389909,"timestamp":"2021-04-17T16:46:42.510Z","symbol":"HEDGBTC"}}
1618678002.627755: {"jsonrpc":"2.0","method":"updateOrderbook","params":{"ask":[{"price":"0.00011939","size":"345.5"},{"price":"0.00011941","size":"920.9"},{"price":"0.00011983","size":"7160.4"},{"price":"0.00012067","size":"7324.7"},{"price":"0.00012076","size":"0"},{"price":"0.00012079","size":"3288.1"}],"bid":[{"price":"0.00011505","size":"0"}],"sequence":19114041,"timestamp":"2021-04-17T16:46:42.494Z","symbol":"XTZBTC"}}
1618678002.641888: {"jsonrpc":"2.0","method":"updateOrderbook","params":{"ask":[],"bid":[{"price":"0.00000107775","size":"0"}],"sequence":5061579,"timestamp":"2021-04-17T16:46:42.479Z","symbol":"CELRBTC"}}
1618678002.69292: {"jsonrpc":"2.0","method":"updateOrderbook","params":{"ask":[{"price":"0.000026896","size":"562.4"},{"price":"0.000026897","size":"0"},{"price":"0.000030785","size":"326.6"}],"bid":[],"sequence":1389910,"timestamp":"2021-04-17T16:46:42.592Z","symbol":"HEDGBTC"}}
1618678002.715364: {"jsonrpc":"2.0","method":"updateOrderbook","params":{"ask":[{"price":"0.000039669","size":"537.3"},{"price":"0.000039670","size":"532.1"},{"price":"0.000039699","size":"0"},{"price":"0.000039700","size":"431.7"},{"price":"0.000039709","size":"0"},{"price":"0.000039745","size":"1829.4"},{"price":"0.000039749","size":"0"},{"price":"0.000039823","size":"0"},{"price":"0.000039824","size":"2594.7"}],"bid":[],"sequence":13027071,"timestamp":"2021-04-17T16:46:42.590Z","symbol":"STORJBTC"}}
1618678002.7515059: {"jsonrpc":"2.0","method":"updateOrderbook","params":{"ask":[{"price":"0.00011939","size":"0"},{"price":"0.00011941","size":"1266.4"},{"price":"0.00011942","size":"1949.6"},{"price":"0.00011944","size":"0"},{"price":"0.00011951","size":"3615.9"},{"price":"0.00011955","size":"244.5"},{"price":"0.00011957","size":"0"},{"price":"0.00011963","size":"356.1"},{"price":"0.00011964","size":"483.6"},{"price":"0.00011970","size":"0"},{"price":"0.00011978","size":"0"},{"price":"0.00011992","size":"1165.1"}],"bid":[{"price":"0.00011481","size":"0"},{"price":"0.00011475","size":"20.2"}],"sequence":19114042,"timestamp":"2021-04-17T16:46:42.638Z","symbol":"XTZBTC"}}
1618678002.751808: {"jsonrpc":"2.0","method":"updateOrderbook","params":{"ask":[],"bid":[{"price":"0.00000107777","size":"2100"}],"sequence":5061580,"timestamp":"2021-04-17T16:46:42.569Z","symbol":"CELRBTC"}}
1618678002.7518778: {"jsonrpc":"2.0","method":"updateOrderbook","params":{"ask":[],"bid":[{"price":"1.4800150","size":"1"}],"sequence":11642124,"timestamp":"2021-04-17T16:46:42.640Z","symbol":"MANAUSD"}}
1618678002.790153: {"jsonrpc":"2.0","method":"updateOrderbook","params":{"ask":[{"price":"0.000026895","size":"91.1"},{"price":"0.000030785","size":"0"}],"bid":[],"sequence":1389911,"timestamp":"2021-04-17T16:46:42.704Z","symbol":"HEDGBTC"}}
1618678002.8025339: {"jsonrpc":"2.0","method":"updateOrderbook","params":{"ask":[{"price":"0.000039669","size":"0"},{"price":"0.000039670","size":"0"},{"price":"0.000039699","size":"537.3"},{"price":"0.000039700","size":"532.1"},{"price":"0.000039709","size":"431.7"},{"price":"0.000039745","size":"0"},{"price":"0.000039750","size":"1829.4"},{"price":"0.000039824","size":"0"},{"price":"0.000039826","size":"2594.7"},{"price":"0.000039872","size":"3844.0"},{"price":"0.000039880","size":"0"},{"price":"0.000039896","size":"0"},{"price":"0.000039933","size":"4384.4"},{"price":"0.000039941","size":"0"}],"bid":[],"sequence":13027072,"timestamp":"2021-04-17T16:46:42.747Z","symbol":"STORJBTC"}}
1618678002.8167381: {"jsonrpc":"2.0","method":"updateOrderbook","params":{"ask":[],"bid":[{"price":"0.00016319","size":"10.00"},{"price":"0.00016318","size":"0"}],"sequence":10038673,"timestamp":"2021-04-17T16:46:42.699Z","symbol":"SUNBTC"}}
1618678002.816894: {"jsonrpc":"2.0","method":"updateOrderbook","params":{"ask":[],"bid":[{"price":"0.00011482","size":"0"},{"price":"0.00011476","size":"40.5"}],"sequence":19114043,"timestamp":"2021-04-17T16:46:42.714Z","symbol":"XTZBTC"}}
1618678002.912149: {"jsonrpc":"2.0","method":"updateOrderbook","params":{"ask":[{"price":"0.000039689","size":"537.3"},{"price":"0.000039697","size":"532.1"},{"price":"0.000039699","size":"0"},{"price":"0.000039700","size":"0"},{"price":"0.000039749","size":"1829.4"},{"price":"0.000039750","size":"0"},{"price":"0.000039825","size":"2594.7"},{"price":"0.000039826","size":"0"},{"price":"0.000040223","size":"9299.9"},{"price":"0.000040230","size":"0"}],"bid":[{"price":"0.000039539","size":"0"},{"price":"0.000039525","size":"1262.0"}],"sequence":13027073,"timestamp":"2021-04-17T16:46:42.846Z","symbol":"STORJBTC"}}
1618678002.921529: {"jsonrpc":"2.0","method":"updateOrderbook","params":{"ask":[{"price":"0.00011942","size":"1730.2"},{"price":"0.00011944","size":"219.4"},{"price":"0.00011948","size":"2090.2"},{"price":"0.00011954","size":"356.1"},{"price":"0.00011955","size":"0"},{"price":"0.00011963","size":"0"},{"price":"0.00011964","size":"0"},{"price":"0.00011969","size":"483.6"},{"price":"0.00012025","size":"0"},{"price":"0.00012037","size":"1165.8"},{"price":"0.00012081","size":"6070.5"},{"price":"0.00012108","size":"0"},{"price":"0.00012155","size":"8300.3"},{"price":"0.00012370","size":"0"}],"bid":[],"sequence":19114044,"timestamp":"2021-04-17T16:46:42.817Z","symbol":"XTZBTC"}}
1618678003.012734: {"jsonrpc":"2.0","method":"updateOrderbook","params":{"ask":[{"price":"0.000039826","size":"3812.3"},{"price":"0.000039839","size":"0"}],"bid":[{"price":"0.000038359","size":"0"}],"sequence":13027074,"timestamp":"2021-04-17T16:46:42.901Z","symbol":"STORJBTC"}}
1618678003.121614: {"jsonrpc":"2.0","method":"updateOrderbook","params":{"ask":[],"bid":[{"price":"0.000038363","size":"156.4"}],"sequence":13027075,"timestamp":"2021-04-17T16:46:42.953Z","symbol":"STORJBTC"}}
1618678003.121753: {"jsonrpc":"2.0","method":"updateOrderbook","params":{"ask":[{"price":"0.00011925","size":"498.1"},{"price":"0.00011932","size":"506.2"},{"price":"0.00011935","size":"530.1"},{"price":"0.00011942","size":"1294.1"}],"bid":[],"sequence":19114045,"timestamp":"2021-04-17T16:46:42.968Z","symbol":"XTZBTC"}}
1618678003.199171: {"jsonrpc":"2.0","method":"updateOrderbook","params":{"ask":[{"price":"0.000040215","size":"9299.9"},{"price":"0.000040223","size":"0"}],"bid":[{"price":"0.000038363","size":"0"}],"sequence":13027076,"timestamp":"2021-04-17T16:46:43.124Z","symbol":"STORJBTC"}}
1618678003.215232: {"jsonrpc":"2.0","method":"updateOrderbook","params":{"ask":[{"price":"0.00012895","size":"12500.4"},{"price":"0.00013480","size":"0"},{"price":"0.00014059","size":"17824.4"},{"price":"0.00014347","size":"0"}],"bid":[],"sequence":19114046,"timestamp":"2021-04-17T16:46:43.125Z","symbol":"XTZBTC"}}
1618678003.296611: {"jsonrpc":"2.0","method":"updateOrderbook","params":{"ask":[{"price":"0.000039822","size":"2594.7"},{"price":"0.000039825","size":"0"},{"price":"0.000039870","size":"3024.0"},{"price":"0.000039872","size":"820.0"}],"bid":[{"price":"0.000038357","size":"156.4"}],"sequence":13027077,"timestamp":"2021-04-17T16:46:43.243Z","symbol":"STORJBTC"}}
1618678003.388491: {"jsonrpc":"2.0","method":"updateOrderbook","params":{"ask":[{"price":"0.000026896","size":"0"}],"bid":[],"sequence":1389912,"timestamp":"2021-04-17T16:46:43.313Z","symbol":"HEDGBTC"}}
1618678003.397544: {"jsonrpc":"2.0","method":"updateOrderbook","params":{"ask":[{"price":"0.000039798","size":"0"},{"price":"0.000039800","size":"2795.3"},{"price":"0.000039826","size":"0"},{"price":"0.000039844","size":"3812.3"},{"price":"0.000039881","size":"0"},{"price":"0.000039924","size":"5302.1"},{"price":"0.000039996","size":"0"},{"price":"0.000040126","size":"6736.1"},{"price":"0.000040215","size":"0"},{"price":"0.000040252","size":"9299.9"},{"price":"0.000040442","size":"0"},{"price":"0.000040519","size":"13527.3"}],"bid":[{"price":"0.000038359","size":"156.4"},{"price":"0.000038357","size":"0"}],"sequence":13027078,"timestamp":"2021-04-17T16:46:43.336Z","symbol":"STORJBTC"}}
1618678003.4914: {"jsonrpc":"2.0","method":"updateOrderbook","params":{"ask":[{"price":"0.000026894","size":"562.4"},{"price":"0.000026895","size":"0"},{"price":"0.000030785","size":"326.6"}],"bid":[],"sequence":1389913,"timestamp":"2021-04-17T16:46:43.390Z","symbol":"HEDGBTC"}}
1618678003.5016499: {"jsonrpc":"2.0","method":"updateOrderbook","params":{"ask":[{"price":"0.000039746","size":"1829.4"},{"price":"0.000039749","size":"0"},{"price":"0.000039817","size":"2594.7"},{"price":"0.000039822","size":"0"},{"price":"0.000039868","size":"3024.0"},{"price":"0.000039870","size":"0"},{"price":"0.000039924","size":"0"},{"price":"0.000039954","size":"5302.1"},{"price":"0.000040126","size":"0"},{"price":"0.000040156","size":"6736.1"}],"bid":[],"sequence":13027079,"timestamp":"2021-04-17T16:46:43.443Z","symbol":"STORJBTC"}}
1618678003.507745: {"jsonrpc":"2.0","method":"updateOrderbook","params":{"ask":[{"price":"0.00012006","size":"1550.2"},{"price":"0.00012011","size":"1525.3"},{"price":"0.00012017","size":"0"},{"price":"0.00012026","size":"0"}],"bid":[],"sequence":19114047,"timestamp":"2021-04-17T16:46:43.437Z","symbol":"XTZBTC"}}
1618678003.591989: {"jsonrpc":"2.0","method":"updateOrderbook","params":{"ask":[{"price":"0.000026893","size":"91.1"},{"price":"0.000030785","size":"0"}],"bid":[],"sequence":1389914,"timestamp":"2021-04-17T16:46:43.490Z","symbol":"HEDGBTC"}}
1618678003.604131: {"jsonrpc":"2.0","method":"updateOrderbook","params":{"ask":[{"price":"0.000039844","size":"0"},{"price":"0.000039861","size":"3988.5"},{"price":"0.000040519","size":"0"},{"price":"0.000040557","size":"13527.3"}],"bid":[],"sequence":13027080,"timestamp":"2021-04-17T16:46:43.491Z","symbol":"STORJBTC"}}
1618678003.6148212: {"jsonrpc":"2.0","method":"updateOrderbook","params":{"ask":[{"price":"0.00011997","size":"1.0"},{"price":"0.00012006","size":"2434.2"},{"price":"0.00012418","size":"0"},{"price":"0.00012459","size":"3868.5"},{"price":"0.00016222","size":"0"},{"price":"0.00016324","size":"5176.4"}],"bid":[],"sequence":19114048,"timestamp":"2021-04-17T16:46:43.527Z","symbol":"XTZBTC"}}
1618678003.695505: {"jsonrpc":"2.0","method":"updateOrderbook","params":{"ask":[],"bid":[{"price":"0.000023964","size":"1.2"}],"sequence":1389915,"timestamp":"2021-04-17T16:46:43.575Z","symbol":"HEDGBTC"}}
1618678003.695731: {"jsonrpc":"2.0","method":"updateOrderbook","params":{"ask":[{"price":"0.000040129","size":"6736.1"},{"price":"0.000040156","size":"0"}],"bid":[],"sequence":13027081,"timestamp":"2021-04-17T16:46:43.634Z","symbol":"STORJBTC"}}
1618678003.7191832: {"jsonrpc":"2.0","method":"updateOrderbook","params":{"ask":[],"bid":[{"price":"0.00011477","size":"20.2"},{"price":"0.00011475","size":"0"}],"sequence":19114049,"timestamp":"2021-04-17T16:46:43.569Z","symbol":"XTZBTC"}}
1618678003.72139: {"jsonrpc":"2.0","method":"updateOrderbook","params":{"ask":[{"price":"0.00000119569","size":"0"},{"price":"0.00000119759","size":"592740"},{"price":"0.00000120369","size":"0"},{"price":"0.00000120424","size":"694310"},{"price":"0.00000121365","size":"0"},{"price":"0.00000121524","size":"922200"},{"price":"0.00000123868","size":"0"},{"price":"0.00000124014","size":"1107430"},{"price":"0.00000126876","size":"0"},{"price":"0.00000127020","size":"2245050"}],"bid":[],"sequence":5061581,"timestamp":"2021-04-17T16:46:43.597Z","symbol":"CELRBTC"}}
1618678003.7906911: {"jsonrpc":"2.0","method":"updateOrderbook","params":{"ask":[],"bid":[{"price":"0.000023964","size":"0"}],"sequence":1389916,"timestamp":"2021-04-17T16:46:43.685Z","symbol":"HEDGBTC"}}
1618678003.805587: {"jsonrpc":"2.0","method":"updateOrderbook","params":{"ask":[],"bid":[{"price":"0.000038359","size":"0"}],"sequence":13027082,"timestamp":"2021-04-17T16:46:43.713Z","symbol":"STORJBTC"}}
1618678003.819678: {"jsonrpc":"2.0","method":"updateOrderbook","params":{"ask":[{"price":"0.00133477","size":"10.00"},{"price":"0.00133542","size":"0"}],"bid":[],"sequence":10038674,"timestamp":"2021-04-17T16:46:43.655Z","symbol":"SUNBTC"}}
1618678003.822798: {"jsonrpc":"2.0","method":"updateOrderbook","params":{"ask":[{"price":"0.00012884","size":"12500.4"},{"price":"0.00012895","size":"0"}],"bid":[{"price":"0.00011478","size":"40.5"},{"price":"0.00011476","size":"0"}],"sequence":19114050,"timestamp":"2021-04-17T16:46:43.702Z","symbol":"XTZBTC"}}
1618678003.888109: {"jsonrpc":"2.0","method":"updateOrderbook","params":{"ask":[],"bid":[{"price":"0.000023963","size":"0"}],"sequence":1389917,"timestamp":"2021-04-17T16:46:43.782Z","symbol":"HEDGBTC"}}
1618678003.8999438: {"jsonrpc":"2.0","method":"updateOrderbook","params":{"ask":[{"price":"0.000040224","size":"9299.9"},{"price":"0.000040252","size":"0"}],"bid":[{"price":"0.000038363","size":"156.4"}],"sequence":13027083,"timestamp":"2021-04-17T16:46:43.826Z","symbol":"STORJBTC"}}
1618678003.912549: {"jsonrpc":"2.0","method":"updateOrderbook","params":{"ask":[{"price":"0.00011939","size":"345.5"},{"price":"0.00011941","size":"920.9"},{"price":"0.00012437","size":"3868.5"},{"price":"0.00012459","size":"0"}],"bid":[],"sequence":19114051,"timestamp":"2021-04-17T16:46:43.789Z","symbol":"XTZBTC"}}
1618678004.015418: {"jsonrpc":"2.0","method":"updateOrderbook","params":{"ask":[{"price":"0.00011935","size":"713.4"},{"price":"0.00011938","size":"0"},{"price":"0.00011977","size":"1165.1"},{"price":"0.00011992","size":"0"}],"bid":[],"sequence":19114052,"timestamp":"2021-04-17T16:46:43.895Z","symbol":"XTZBTC"}}
1618678004.023983: {"jsonrpc":"2.0","method":"updateOrderbook","params":{"ask":[{"price":"0.00000119569","size":"592740"},{"price":"0.00000119759","size":"0"},{"price":"0.00000120369","size":"694310"},{"price":"0.00000120424","size":"0"},{"price":"0.00000121348","size":"922200"},{"price":"0.00000121524","size":"0"}],"bid":[],"sequence":5061582,"timestamp":"2021-04-17T16:46:43.945Z","symbol":"CELRBTC"}}
1618678004.1035361: {"jsonrpc":"2.0","method":"updateOrderbook","params":{"ask":[{"price":"0.00011942","size":"1494.8"},{"price":"0.00011946","size":"1156.3"},{"price":"0.00011948","size":"2770.5"},{"price":"0.00011951","size":"2691.1"},{"price":"0.00011952","size":"1246.4"},{"price":"0.00011954","size":"0"},{"price":"0.00011959","size":"1279.6"},{"price":"0.00011961","size":"0"},{"price":"0.00011996","size":"884.0"},{"price":"0.00012006","size":"1550.2"},{"price":"0.00012072","size":"3288.1"},{"price":"0.00012079","size":"0"},{"price":"0.00012884","size":"0"},{"price":"0.00012897","size":"12500.4"}],"bid":[],"sequence":19114053,"timestamp":"2021-04-17T16:46:44.007Z","symbol":"XTZBTC"}}
1618678004.187863: {"jsonrpc":"2.0","method":"updateOrderbook","params":{"ask":[{"price":"0.000026894","size":"0"}],"bid":[],"sequence":1389918,"timestamp":"2021-04-17T16:46:44.135Z","symbol":"HEDGBTC"}}
1618678004.193571: {"jsonrpc":"2.0","method":"updateOrderbook","params":{"ask":[{"price":"0.000039945","size":"738.1"},{"price":"0.000040035","size":"0"}],"bid":[],"sequence":13027084,"timestamp":"2021-04-17T16:46:44.131Z","symbol":"STORJBTC"}}
1618678004.2221591: {"jsonrpc":"2.0","method":"updateOrderbook","params":{"ask":[],"bid":[{"price":"0.00016319","size":"0"},{"price":"0.00016318","size":"10.00"}],"sequence":10038675,"timestamp":"2021-04-17T16:46:44.133Z","symbol":"SUNBTC"}}
1618678004.22232: {"jsonrpc":"2.0","method":"updateOrderbook","params":{"ask":[{"price":"0.00011939","size":"0"},{"price":"0.00011941","size":"1266.4"}],"bid":[],"sequence":19114054,"timestamp":"2021-04-17T16:46:44.099Z","symbol":"XTZBTC"}}
1618678004.292154: {"jsonrpc":"2.0","method":"updateOrderbook","params":{"ask":[{"price":"0.000026892","size":"562.4"},{"price":"0.000026893","size":"0"},{"price":"0.000030785","size":"326.6"}],"bid":[{"price":"0.000023962","size":"27.6"}],"sequence":1389919,"timestamp":"2021-04-17T16:46:44.234Z","symbol":"HEDGBTC"}}
1618678004.295381: {"jsonrpc":"2.0","method":"updateOrderbook","params":{"ask":[],"bid":[{"price":"0.000039549","size":"1262.0"},{"price":"0.000039525","size":"0"}],"sequence":13027085,"timestamp":"2021-04-17T16:46:44.150Z","symbol":"STORJBTC"}}
1618678004.306581: {"jsonrpc":"2.0","method":"updateOrderbook","params":{"ask":[{"price":"0.00133467","size":"10.00"},{"price":"0.00133477","size":"0"}],"bid":[],"sequence":10038676,"timestamp":"2021-04-17T16:46:44.222Z","symbol":"SUNBTC"}}
1618678004.306735: {"jsonrpc":"2.0","method":"updateOrderbook","params":{"ask":[{"price":"0.00011931","size":"0"},{"price":"0.00011933","size":"378.8"},{"price":"0.00011935","size":"530.1"},{"price":"0.00011938","size":"183.3"},{"price":"0.00011939","size":"345.5"},{"price":"0.00011941","size":"0"},{"price":"0.00011943","size":"920.9"},{"price":"0.00011988","size":"1253.2"},{"price":"0.00011996","size":"0"},{"price":"0.00012006","size":"2434.2"},{"price":"0.00012012","size":"0"},{"price":"0.00012067","size":"2525.5"},{"price":"0.00012073","size":"4799.2"},{"price":"0.00012155","size":"0"},{"price":"0.00012166","size":"8300.3"},{"price":"0.00012437","size":"0"},{"price":"0.00012466","size":"3868.5"},{"price":"0.00012897","size":"0"},{"price":"0.00012930","size":"12500.4"},{"price":"0.00014059","size":"0"},{"price":"0.00014086","size":"17824.4"},{"price":"0.00016324","size":"0"},{"price":"0.00016353","size":"12058.3"}],"bid":[],"sequence":19114055,"timestamp":"2021-04-17T16:46:44.211Z","symbol":"XTZBTC"}}
1618678004.390003: {"jsonrpc":"2.0","method":"updateOrderbook","params":{"ask":[{"price":"0.000026891","size":"91.1"},{"price":"0.000030785","size":"0"}],"bid":[],"sequence":1389920,"timestamp":"2021-04-17T16:46:44.282Z","symbol":"HEDGBTC"}}
1618678004.403096: {"jsonrpc":"2.0","method":"updateOrderbook","params":{"ask":[{"price":"0.00133461","size":"10.00"},{"price":"0.00133467","size":"0"}],"bid":[],"sequence":10038677,"timestamp":"2021-04-17T16:46:44.334Z","symbol":"SUNBTC"}}
1618678004.40717: {"jsonrpc":"2.0","method":"updateOrderbook","params":{"ask":[{"price":"0.00011922","size":"1876.2"},{"price":"0.00011925","size":"102.6"},{"price":"0.00011926","size":"728.3"},{"price":"0.00011932","size":"565.8"},{"price":"0.00011935","size":"94.0"},{"price":"0.00011939","size":"0"},{"price":"0.00011941","size":"345.5"},{"price":"0.00011942","size":"200.7"},{"price":"0.00011988","size":"0"},{"price":"0.00011992","size":"1253.2"}],"bid":[{"price":"0.00011549","size":"0.6"}],"sequence":19114056,"timestamp":"2021-04-17T16:46:44.338Z","symbol":"XTZBTC"}}
1618678004.500459: {"jsonrpc":"2.0","method":"updateOrderbook","params":{"ask":[{"price":"0.000039754","size":"1150.2"},{"price":"0.000039764","size":"0"},{"price":"0.000039818","size":"104.5"},{"price":"0.000039830","size":"124.2"},{"price":"0.000039831","size":"0"},{"price":"0.000039850","size":"0"}],"bid":[],"sequence":13027086,"timestamp":"2021-04-17T16:46:44.397Z","symbol":"STORJBTC"}}
1618678004.520211: {"jsonrpc":"2.0","method":"updateOrderbook","params":{"ask":[{"price":"0.00133458","size":"10.00"},{"price":"0.00133461","size":"0"}],"bid":[],"sequence":10038678,"timestamp":"2021-04-17T16:46:44.413Z","symbol":"SUNBTC"}}
1618678004.5203662: {"jsonrpc":"2.0","method":"updateOrderbook","params":{"ask":[{"price":"0.00011922","size":"538.4"},{"price":"0.00011925","size":"498.1"},{"price":"0.00011926","size":"0"},{"price":"0.00011932","size":"506.2"},{"price":"0.00011935","size":"530.1"},{"price":"0.00011942","size":"1494.8"},{"price":"0.00011970","size":"2797.0"},{"price":"0.00011972","size":"0"},{"price":"0.00012003","size":"1550.2"},{"price":"0.00012006","size":"884.0"},{"price":"0.00012059","size":"8993.7"},{"price":"0.00012066","size":"0"},{"price":"0.00012439","size":"20099.1"},{"price":"0.00012452","size":"0"}],"bid":[{"price":"0.00011550","size":"40.5"},{"price":"0.00011478","size":"0"}],"sequence":19114057,"timestamp":"2021-04-17T16:46:44.425Z","symbol":"XTZBTC"}}
1618678004.6042502: {"jsonrpc":"2.0","method":"updateOrderbook","params":{"ask":[{"price":"0.000039884","size":"780.0"},{"price":"0.000039915","size":"0"},{"price":"0.000040102","size":"6736.1"},{"price":"0.000040129","size":"0"},{"price":"0.000040224","size":"0"},{"price":"0.000040250","size":"9299.9"},{"price":"0.000040514","size":"13527.3"},{"price":"0.000040557","size":"0"}],"bid":[],"sequence":13027087,"timestamp":"2021-04-17T16:46:44.509Z","symbol":"STORJBTC"}}
1618678004.620178: {"jsonrpc":"2.0","method":"updateOrderbook","params":{"ask":[{"price":"0.00133456","size":"10.00"},{"price":"0.00133458","size":"0"}],"bid":[],"sequence":10038679,"timestamp":"2021-04-17T16:46:44.506Z","symbol":"SUNBTC"}}
1618678004.6963358: {"jsonrpc":"2.0","method":"updateOrderbook","params":{"ask":[],"bid":[{"price":"0.000023963","size":"1.2"}],"sequence":1389921,"timestamp":"2021-04-17T16:46:44.636Z","symbol":"HEDGBTC"}}
1618678004.701691: {"jsonrpc":"2.0","method":"updateOrderbook","params":{"ask":[{"price":"0.000039754","size":"0"},{"price":"0.000039761","size":"1150.2"},{"price":"0.000039800","size":"0"},{"price":"0.000039811","size":"2795.3"},{"price":"0.000039861","size":"176.2"},{"price":"0.000039879","size":"3812.3"},{"price":"0.000039884","size":"0"},{"price":"0.000039932","size":"780.0"},{"price":"0.000040102","size":"0"},{"price":"0.000040130","size":"6736.1"}],"bid":[],"sequence":13027088,"timestamp":"2021-04-17T16:46:44.619Z","symbol":"STORJBTC"}}
1618678004.731914: {"jsonrpc":"2.0","method":"updateOrderbook","params":{"ask":[{"price":"0.00133456","size":"0"},{"price":"0.00133476","size":"10.00"}],"bid":[],"sequence":10038680,"timestamp":"2021-04-17T16:46:44.624Z","symbol":"SUNBTC"}}
1618678004.732079: {"jsonrpc":"2.0","method":"updateOrderbook","params":{"ask":[{"price":"0.00011939","size":"345.5"},{"price":"0.00011941","size":"0"},{"price":"0.00011952","size":"890.3"},{"price":"0.00011957","size":"356.1"},{"price":"0.00011977","size":"0"},{"price":"0.00011985","size":"1165.1"},{"price":"0.00012003","size":"0"},{"price":"0.00012006","size":"2434.2"}],"bid":[{"price":"0.00011479","size":"20.2"},{"price":"0.00011477","size":"0"}],"sequence":19114058,"timestamp":"2021-04-17T16:46:44.649Z","symbol":"XTZBTC"}}
1618678004.7413619: {"jsonrpc":"2.0","method":"updateOrderbook","params":{"ask":[{"price":"0.2197710","size":"0"},{"price":"0.2198564","size":"23.26"}],"bid":[],"sequence":4920763,"timestamp":"2021-04-17T16:46:44.605Z","symbol":"BNBETH"}}
1618678004.7927659: {"jsonrpc":"2.0","method":"updateOrderbook","params":{"ask":[],"bid":[{"price":"0.000023963","size":"0"}],"sequence":1389922,"timestamp":"2021-04-17T16:46:44.714Z","symbol":"HEDGBTC"}}
1618678004.797057: {"jsonrpc":"2.0","method":"updateOrderbook","params":{"ask":[{"price":"0.000039669","size":"537.3"},{"price":"0.000039670","size":"532.1"},{"price":"0.000039689","size":"0"},{"price":"0.000039697","size":"0"},{"price":"0.000039700","size":"431.7"},{"price":"0.000039709","size":"0"},{"price":"0.000039743","size":"1829.4"},{"price":"0.000039746","size":"0"},{"price":"0.000039816","size":"2594.7"},{"price":"0.000039817","size":"0"},{"price":"0.000039867","size":"3024.0"},{"price":"0.000039868","size":"0"},{"price":"0.000040214","size":"9299.9"},{"price":"0.000040250","size":"0"},{"price":"0.000040470","size":"13527.3"},{"price":"0.000040514","size":"0"}],"bid":[],"sequence":13027089,"timestamp":"2021-04-17T16:46:44.748Z","symbol":"STORJBTC"}}
1618678004.8366349: {"jsonrpc":"2.0","method":"updateOrderbook","params":{"ask":[{"price":"0.00133476","size":"0"},{"price":"0.00133493","size":"10.00"}],"bid":[],"sequence":10038681,"timestamp":"2021-04-17T16:46:44.693Z","symbol":"SUNBTC"}}
1618678004.836791: {"jsonrpc":"2.0","method":"updateOrderbook","params":{"ask":[{"price":"0.00011939","size":"0"},{"price":"0.00011941","size":"345.5"}],"bid":[],"sequence":19114059,"timestamp":"2021-04-17T16:46:44.657Z","symbol":"XTZBTC"}}
1618678004.849445: {"jsonrpc":"2.0","method":"updateOrderbook","params":{"ask":[],"bid":[{"price":"1.4672448","size":"406"},{"price":"1.4667267","size":"0"}],"sequence":11642125,"timestamp":"2021-04-17T16:46:44.677Z","symbol":"MANAUSD"}}
1618678004.896893: {"jsonrpc":"2.0","method":"updateOrderbook","params":{"ask":[{"price":"0.000026892","size":"0"}],"bid":[],"sequence":1389923,"timestamp":"2021-04-17T16:46:44.835Z","symbol":"HEDGBTC"}}
1618678004.906829: {"jsonrpc":"2.0","method":"updateOrderbook","params":{"ask":[{"price":"0.000039669","size":"0"},{"price":"0.000039670","size":"0"},{"price":"0.000039699","size":"537.3"},{"price":"0.000039700","size":"532.1"},{"price":"0.000039709","size":"431.7"},{"price":"0.000039743","size":"0"},{"price":"0.000039747","size":"1829.4"},{"price":"0.000039816","size":"0"},{"price":"0.000039821","size":"2594.7"},{"price":"0.000039867","size":"0"},{"price":"0.000039870","size":"3024.0"}],"bid":[],"sequence":13027090,"timestamp":"2021-04-17T16:46:44.823Z","symbol":"STORJBTC"}}
