1618677975.0421572: {"jsonrpc":"2.0","method":"snapshotOrderbook","params":{"ask":[{"price":"0.00000000414","size":"10000"},{"price":"0.00000000418","size":"4646000"},{"price":"0.00000000422","size":"1662000"},{"price":"0.00000000423","size":"1000"},{"price":"0.00000000424","size":"1000"},{"price":"0.00000000425","size":"1000"},{"price":"0.00000000426","size":"1000"},{"price":"0.00000000427","size":"1000"},{"price":"0.00000000428","size":"1000"},{"price":"0.00000000429","size":"1000"},{"price":"0.00000000430","size":"1000"},{"price":"0.00000000431","size":"1000"},{"price":"0.00000000432","size":"1000"},{"price":"0.00000000433","size":"1000"},{"price":"0.00000000434","size":"1000"},{"price":"0.00000000435","size":"1000"},{"price":"0.00000000436","size":"1000"},{"price":"0.00000000437","size":"1000"},{"price":"0.00000000438","size":"2001000"},{"price":"0.00000000439","size":"30000"},{"price":"0.00000000440","size":"1000"},{"price":"0.00000000441","size":"1000"},{"price":"0.00000000442","size":"1000"},{"price":"0.00000000443","size":"1000"},{"price":"0.00000000444","size":"1000"},{"price":"0.00000000445","size":"1000"},{"price":"0.00000000446","size":"1000"},{"price":"0.00000000447","size":"1000"},{"price":"0.00000000448","size":"1000"},{"price":"0.00000000449","size":"1000"},{"price":"0.00000000450","size":"2812000"},{"price":"0.00000000451","size":"1000"},{"price":"0.00000000452","size":"501000"},{"price":"0.00000000453","size":"1000"},{"price":"0.00000000454","size":"1000"},{"price":"0.00000000455","size":"1000"},{"price":"0.00000000456","size":"59000"},{"price":"0.00000000457","size":"1000"},{"price":"0.00000000458","size":"1000"},{"price":"0.00000000459","size":"4252000"},{"price":"0.00000000460","size":"1000"},{"price":"0.00000000461","size":"1000"},{"price":"0.00000000462","size":"1000"},{"price":"0.00000000463","size":"1000"},{"price":"0.00000000464","size":"1000"},{"price":"0.00000000465","size":"1000"},{"price":"0.00000000466","size":"1000"},{"price":"0.00000000467","size":"1000"},{"price":"0.00000000468","size":"1000"},{"price":"0.00000000469","size":"1000"},{"price":"0.00000000470","size":"1000"},{"price":"0.00000000471","size":"1000"},{"price":"0.00000000472","size":"1000"},{"price":"0.00000000473","size":"1000"},{"price":"0.00000000474","size":"1000"},{"price":"0.00000000475","size":"1000"},{"price":"0.00000000476","size":"4000"},{"price":"0.00000000477","size":"1000"},{"price":"0.00000000478","size":"1000"},{"price":"0.00000000479","size":"1000"},{"price":"0.00000000480","size":"2001000"},{"price":"0.00000000481","size":"1000"},{"price":"0.00000000482","size":"1000"},{"price":"0.00000000483","size":"1000"},{"price":"0.00000000484","size":"1000"},{"price":"0.00000000485","size":"1000"},{"price":"0.00000000486","size":"1000"},{"price":"0.00000000487","size":"1000"},{"price":"0.00000000488","size":"1000"},{"price":"0.00000000489","size":"97000"},{"price":"0.00000000490","size":"1000"},{"price":"0.00000000491","size":"1000"},{"price":"0.00000000492","size":"1000"},{"price":"0.00000000493","size":"1000"},{"price":"0.00000000494","size":"1000"},{"price":"0.00000000495","size":"1000"},{"price":"0.00000000496","size":"501000"},{"price":"0.00000000497","size":"1000"},{"price":"0.00000000498","size":"1000"},{"price":"0.00000000499","size":"1000"},{"price":"0.00000000500","size":"2824000"},{"price":"0.00000000501","size":"1000"},{"price":"0.00000000502","size":"1000"},{"price":"0.00000000503","size":"1000"},{"price":"0.00000000504","size":"1000"},{"price":"0.00000000505","size":"6005000"},{"price":"0.00000000506","size":"1993000"},{"price":"0.00000000507","size":"1000"},{"price":"0.00000000508","size":"1000"},{"price":"0.00000000509","size":"1000"},{"price":"0.00000000510","size":"1000"},{"price":"0.00000000511","size":"1000"},{"price":"0.00000000512","size":"14038000"},{"price":"0.00000000513","size":"1000"},{"price":"0.00000000514","size":"1000"},{"price":"0.00000000515","size":"1000"},{"price":"0.00000000516","size":"1000"},{"price":"0.00000000517","size":"1000"},{"price":"0.00000000518","size":"1000"},{"price":"0.00000000519","size":"1000"},{"price":"0.00000000520","size":"450000"},{"price":"0.00000000521","size":"1000"},{"price":"0.00000000522","size":"1000"},{"price":"0.00000000523","size":"1000"},{"price":"0.00000000524","size":"1000"},{"price":"0.00000000525","size":"1000"},{"price":"0.00000000526","size":"1000"},{"price":"0.00000000527","size":"1000"},{"price":"0.00000000528","size":"1000"},{"price":"0.00000000529","size":"1000"},{"price":"0.00000000530","size":"23000"},{"price":"0.00000000531","size":"1000"},{"price":"0.00000000532","size":"1000"},{"price":"0.00000000533","size":"1000"},{"price":"0.00000000534","size":"1000"},{"price":"0.00000000535","size":"1000"},{"price":"0.00000000536","size":"1000"},{"price":"0.00000000537","size":"1000"},{"price":"0.00000000538","size":"1000"},{"price":"0.00000000539","size":"1000"},{"price":"0.00000000540","size":"501000"},{"price":"0.00000000541","size":"1000"},{"price":"0.00000000542","size":"1000"},{"price":"0.00000000543","size":"1000"},{"price":"0.00000000544","size":"1000"},{"price":"0.00000000545","size":"1000"},{"price":"0.00000000546","size":"1000"},{"price":"0.00000000547","size":"1000"},{"price":"0.00000000548","size":"1000"},{"price":"0.00000000549","size":"1000"},{"price":"0.00000000550","size":"1111000"},{"price":"0.00000000551","size":"1000"},{"price":"0.00000000552","size":"1000"},{"price":"0.00000000553","size":"1000"},{"price":"0.00000000554","size":"1000"},{"price":"0.00000000555","size":"452000"},{"price":"0.00000000556","size":"1000"},{"price":"0.00000000557","size":"1000"},{"price":"0.00000000558","size":"1000"},{"price":"0.00000000559","size":"1000"},{"price":"0.00000000560","size":"1000"},{"price":"0.00000000561","size":"1000"},{"price":"0.00000000562","size":"1000"},{"price":"0.00000000563","size":"1000"},{"price":"0.00000000564","size":"1000"},{"price":"0.00000000565","size":"1000"},{"price":"0.00000000566","size":"1000"},{"price":"0.00000000567","size":"1000"},{"price":"0.00000000568","size":"1000"},{"price":"0.00000000569","size":"1000"},{"price":"0.00000000570","size":"1000"},{"price":"0.00000000571","size":"1000"},{"price":"0.00000000572","size":"1000"},{"price":"0.00000000573","size":"1000"},{"price":"0.00000000574","size":"1000"},{"price":"0.00000000575","size":"1000"},{"price":"0.00000000576","size":"1000"},{"price":"0.00000000577","size":"1000"},{"price":"0.00000000578","size":"1000"},{"price":"0.00000000579","size":"1000"},{"price":"0.00000000580","size":"21000"},{"price":"0.00000000581","size":"1000"},{"price":"0.00000000582","size":"1000"},{"price":"0.00000000583","size":"501000"},{"price":"0.00000000584","size":"1000"},{"price":"0.00000000585","size":"1000"},{"price":"0.00000000586","size":"201000"},{"price":"0.00000000587","size":"367000"},{"price":"0.00000000588","size":"1000"},{"price":"0.00000000589","size":"1000"},{"price":"0.00000000590","size":"1000"},{"price":"0.00000000591","size":"1000"},{"price":"0.00000000592","size":"1000"},{"price":"0.00000000593","size":"1000"},{"price":"0.00000000594","size":"1000"},{"price":"0.00000000595","size":"1000"},{"price":"0.00000000596","size":"1000"},{"price":"0.00000000597","size":"1000"},{"price":"0.00000000598","size":"1000"},{"price":"0.00000000599","size":"1000"},{"price":"0.00000000600","size":"582000"},{"price":"0.00000000601","size":"1000"},{"price":"0.00000000602","size":"1000"},{"price":"0.00000000603","size":"1000"},{"price":"0.00000000604","size":"1000"},{"price":"0.00000000605","size":"1000"},{"price":"0.00000000606","size":"1000"},{"price":"0.00000000607","size":"1000"},{"price":"0.00000000608","size":"1000"},{"price":"0.00000000609","size":"1000"},{"price":"0.00000000610","size":"1000"},{"price":"0.00000000611","size":"1000"},{"price":"0.00000000612","size":"1000"},{"price":"0.00000000613","size":"1000"},{"price":"0.00000000614","size":"1000"},{"price":"0.00000000615","size":"1000"},{"price":"0.00000000616","size":"1000"},{"price":"0.00000000617","size":"1000"},{"price":"0.00000000618","size":"1000"},{"price":"0.00000000619","size":"1000"},{"price":"0.00000000620","size":"1000"},{"price":"0.00000000621","size":"1000"},{"price":"0.00000000622","size":"1000"},{"price":"0.00000000623","size":"1000"},{"price":"0.00000000624","size":"1000"},{"price":"0.00000000625","size":"1000"},{"price":"0.00000000626","size":"501000"},{"price":"0.00000000627","size":"1000"},{"price":"0.00000000628","size":"1000"},{"price":"0.00000000629","size":"1000"},{"price":"0.00000000630","size":"1000"},{"price":"0.00000000631","size":"1000"},{"price":"0.00000000632","size":"1000"},{"price":"0.00000000633","size":"1000"},{"price":"0.00000000634","size":"1000"},{"price":"0.00000000635","size":"1000"},{"price":"0.00000000636","size":"1000"},{"price":"0.00000000637","size":"1000"},{"price":"0.00000000638","size":"1000"},{"price":"0.00000000639","size":"1000"},{"price":"0.00000000640","size":"1000"},{"price":"0.00000000641","size":"1000"},{"price":"0.00000000642","size":"1000"},{"price":"0.00000000643","size":"1000"},{"price":"0.00000000644","size":"1000"},{"price":"0.00000000645","size":"1000"},{"price":"0.00000000646","size":"1000"},{"price":"0.00000000647","size":"1604000"},{"price":"0.00000000648","size":"2000"},{"price":"0.00000000649","size":"1000"},{"price":"0.00000000650","size":"1501000"},{"price":"0.00000000651","size":"1000"},{"price":"0.00000000652","size":"1000"},{"price":"0.00000000653","size":"1000"},{"price":"0.00000000654","size":"1000"},{"price":"0.00000000655","size":"1000"},{"price":"0.00000000656","size":"1000"},{"price":"0.00000000657","size":"1000"},{"price":"0.00000000658","size":"1000"},{"price":"0.00000000659","size":"1000"},{"price":"0.00000000660","size":"442000"},{"price":"0.00000000661","size":"1000"},{"price":"0.00000000662","size":"1000"},{"price":"0.00000000663","size":"1000"},{"price":"0.00000000664","size":"1000"},{"price":"0.00000000665","size":"1000"},{"price":"0.00000000666","size":"1000"},{"price":"0.00000000667","size":"14000"},{"price":"0.00000000668","size":"1000"},{"price":"0.00000000669","size":"1000"},{"price":"0.00000000670","size":"544000"},{"price":"0.00000000671","size":"1000"},{"price":"0.00000000672","size":"1000"},{"price":"0.00000000673","size":"1000"},{"price":"0.00000000674","size":"27000"},{"price":"0.00000000675","size":"31000"},{"price":"0.00000000676","size":"1000"},{"price":"0.00000000677","size":"1000"},{"price":"0.00000000678","size":"1000"},{"price":"0.00000000679","size":"807000"},{"price":"0.00000000680","size":"139000"},{"price":"0.00000000681","size":"1000"},{"price":"0.00000000682","size":"1000"},{"price":"0.00000000683","size":"1000"},{"price":"0.00000000684","size":"1000"},{"price":"0.00000000685","size":"60000"},{"price":"0.00000000686","size":"1000"},{"price":"0.00000000687","size":"1000"},{"price":"0.00000000688","size":"1000"},{"price":"0.00000000689","size":"1000"},{"price":"0.00000000690","size":"1000"},{"price":"0.00000000691","size":"1000"},{"price":"0.00000000692","size":"919000"},{"price":"0.00000000693","size":"1000"},{"price":"0.00000000694","size":"1000"},{"price":"0.00000000695","size":"1000"},{"price":"0.00000000696","size":"1000"},{"price":"0.00000000697","size":"1000"},{"price":"0.00000000698","size":"1000"},{"price":"0.00000000699","size":"11000"},{"price":"0.00000000700","size":"10698000"},{"price":"0.00000000701","size":"1000"},{"price":"0.00000000702","size":"1000"},{"price":"0.00000000703","size":"161000"},{"price":"0.00000000704","size":"1000"},{"price":"0.00000000705","size":"478000"},{"price":"0.00000000706","size":"1000"},{"price":"0.00000000707","size":"1000"},{"price":"0.00000000708","size":"1000"},{"price":"0.00000000709","size":"1000"},{"price":"0.00000000710","size":"21000"},{"price":"0.00000000711","size":"9001000"},{"price":"0.00000000712","size":"1000"},{"price":"0.00000000713","size":"1000"},{"price":"0.00000000714","size":"1000"},{"price":"0.00000000715","size":"960000"},{"price":"0.00000000716","size":"1000"},{"price":"0.00000000717","size":"1000"},{"price":"0.00000000718","size":"1000"},{"price":"0.00000000719","size":"1000"},{"price":"0.00000000720","size":"28000"},{"price":"0.00000000721","size":"1000"},{"price":"0.00000000722","size":"1000"},{"price":"0.00000000723","size":"1000"},{"price":"0.00000000724","size":"1000"},{"price":"0.00000000725","size":"51000"},{"price":"0.00000000726","size":"1000"},{"price":"0.00000000727","size":"1000"},{"price":"0.00000000728","size":"1000"},{"price":"0.00000000729","size":"1000"},{"price":"0.00000000730","size":"1000"},{"price":"0.00000000731","size":"1000"},{"price":"0.00000000732","size":"1000"},{"price":"0.00000000733","size":"1000"},{"price":"0.00000000734","size":"1000"},{"price":"0.00000000735","size":"1000"},{"price":"0.00000000736","size":"1000"},{"price":"0.00000000737","size":"1000"},{"price":"0.00000000738","size":"1000"},{"price":"0.00000000739","size":"1000"},{"price":"0.00000000740","size":"1000"},{"price":"0.00000000741","size":"1000"},{"price":"0.00000000742","size":"1000"},{"price":"0.00000000743","size":"1000"},{"price":"0.00000000744","size":"1000"},{"price":"0.00000000745","size":"1000"},{"price":"0.00000000746","size":"1000"},{"price":"0.00000000747","size":"44000"},{"price":"0.00000000748","size":"201000"},{"price":"0.00000000749","size":"1000"},{"price":"0.00000000750","size":"1000"},{"price":"0.00000000751","size":"13000"},{"price":"0.00000000752","size":"1000"},{"price":"0.00000000753","size":"1000"},{"price":"0.00000000754","size":"1000"},{"price":"0.00000000755","size":"1000"},{"price":"0.00000000756","size":"1000"},{"price":"0.00000000757","size":"1000"},{"price":"0.00000000758","size":"1000"},{"price":"0.00000000759","size":"1502000"},{"price":"0.00000000760","size":"1000"},{"price":"0.00000000761","size":"1000"},{"price":"0.00000000762","size":"1000"},{"price":"0.00000000763","size":"1000"},{"price":"0.00000000764","size":"1000"},{"price":"0.00000000765","size":"1000"},{"price":"0.00000000766","size":"26000"},{"price":"0.00000000767","size":"1000"},{"price":"0.00000000768","size":"1000"},{"price":"0.00000000769","size":"1000"},{"price":"0.00000000770","size":"1000"},{"price":"0.00000000771","size":"1000"},{"price":"0.00000000772","size":"1000"},{"price":"0.00000000773","size":"1000"},{"price":"0.00000000774","size":"1000"},{"price":"0.00000000775","size":"1000"},{"price":"0.00000000776","size":"1000"},{"price":"0.00000000777","size":"2000"},{"price":"0.00000000778","size":"1000"},{"price":"0.00000000779","size":"1000"},{"price":"0.00000000780","size":"1000"},{"price":"0.00000000781","size":"1000"},{"price":"0.00000000782","size":"1000"},{"price":"0.00000000783","size":"1000"},{"price":"0.00000000784","size":"1000"},{"price":"0.00000000785","size":"1000"},{"price":"0.00000000786","size":"1000"},{"price":"0.00000000787","size":"1000"},{"price":"0.00000000788","size":"1000"},{"price":"0.00000000789","size":"1000"},{"price":"0.00000000790","size":"2000"},{"price":"0.00000000791","size":"1000"},{"price":"0.00000000792","size":"1000"},{"price":"0.00000000793","size":"157000"},{"price":"0.00000000794","size":"1000"},{"price":"0.00000000795","size":"1000"},{"price":"0.00000000796","size":"1000"},{"price":"0.00000000797","size":"501000"},{"price":"0.00000000798","size":"1000"},{"price":"0.00000000799","size":"1000"},{"price":"0.00000000800","size":"1717000"},{"price":"0.00000000801","size":"1000"},{"price":"0.00000000802","size":"1000"},{"price":"0.00000000803","size":"1000"},{"price":"0.00000000804","size":"1000"},{"price":"0.00000000805","size":"79000"},{"price":"0.00000000806","size":"1000"},{"price":"0.00000000807","size":"2000"},{"price":"0.00000000808","size":"1000"},{"price":"0.00000000809","size":"1000"},{"price":"0.00000000810","size":"1000"},{"price":"0.00000000811","size":"1000"},{"price":"0.00000000812","size":"1000"},{"price":"0.00000000813","size":"1000"},{"price":"0.00000000814","size":"1000"},{"price":"0.00000000815","size":"1127000"},{"price":"0.00000000816","size":"1000"},{"price":"0.00000000817","size":"1000"},{"price":"0.00000000818","size":"1000"},{"price":"0.00000000819","size":"1000"},{"price":"0.00000000820","size":"1000"},{"price":"0.00000000821","size":"1000"},{"price":"0.00000000822","size":"1000"},{"price":"0.00000000823","size":"9001000"},{"price":"0.00000000824","size":"1000"},{"price":"0.00000000825","size":"1000"},{"price":"0.00000000826","size":"2000"},{"price":"0.00000000827","size":"6000"},{"price":"0.00000000828","size":"1000"},{"price":"0.00000000829","size":"1000"},{"price":"0.00000000830","size":"1000"},{"price":"0.00000000831","size":"1000"},{"price":"0.00000000832","size":"1000"},{"price":"0.00000000833","size":"1000"},{"price":"0.00000000834","size":"1000"},{"price":"0.00000000835","size":"1000"},{"price":"0.00000000836","size":"1000"},{"price":"0.00000000837","size":"1000"},{"price":"0.00000000838","size":"1000"},{"price":"0.00000000839","size":"1000"},{"price":"0.00000000840","size":"1000"},{"price":"0.00000000841","size":"101000"},{"price":"0.00000000842","size":"3000"},{"price":"0.00000000843","size":"1000"},{"price":"0.00000000844","size":"1000"},{"price":"0.00000000845","size":"21000"},{"price":"0.00000000846","size":"1000"},{"price":"0.00000000847","size":"1000"},{"price":"0.00000000848","size":"1000"},{"price":"0.00000000849","size":"1000"},{"price":"0.00000000850","size":"224000"},{"price":"0.00000000851","size":"1000"},{"price":"0.00000000852","size":"1000"},{"price":"0.00000000853","size":"1000"},{"price":"0.00000000854","size":"1000"},{"price":"0.00000000855","size":"1000"},{"price":"0.00000000856","size":"1000"},{"price":"0.00000000857","size":"1000"},{"price":"0.00000000858","size":"1000"},{"price":"0.00000000859","size":"1000"},{"price":"0.00000000860","size":"61000"},{"price":"0.00000000861","size":"1000"},{"price":"0.00000000862","size":"1000"},{"price":"0.00000000863","size":"1000"},{"price":"0.00000000864","size":"1000"},{"price":"0.00000000865","size":"1000"},{"price":"0.00000000866","size":"11000"},{"price":"0.00000000867","size":"1000"},{"price":"0.00000000868","size":"1000"},{"price":"0.00000000869","size":"1000"},{"price":"0.00000000870","size":"1000"},{"price":"0.00000000871","size":"1000"},{"price":"0.00000000872","size":"1000"},{"price":"0.00000000873","size":"1000"},{"price":"0.00000000874","size":"1000"},{"price":"0.00000000875","size":"1000"},{"price":"0.00000000876","size":"25000"},{"price":"0.00000000877","size":"1000"},{"price":"0.00000000878","size":"9001000"},{"price":"0.00000000879","size":"1000"},{"price":"0.00000000880","size":"1000"},{"price":"0.00000000881","size":"1000"},{"price":"0.00000000882","size":"1000"},{"price":"0.00000000883","size":"207000"},{"price":"0.00000000884","size":"14353000"},{"price":"0.00000000885","size":"1000"},{"price":"0.00000000886","size":"2000"},{"price":"0.00000000887","size":"1000"},{"price":"0.00000000888","size":"1000"},{"price":"0.00000000889","size":"1000"},{"price":"0.00000000890","size":"2000"},{"price":"0.00000000891","size":"10000"},{"price":"0.00000000892","size":"345000"},{"price":"0.00000000893","size":"1000"},{"price":"0.00000000894","size":"1000"},{"price":"0.00000000895","size":"661000"},{"price":"0.00000000896","size":"81000"},{"price":"0.00000000897","size":"501000"},{"price":"0.00000000898","size":"2000"},{"price":"0.00000000899","size":"1000"},{"price":"0.00000000900","size":"17000"},{"price":"0.00000000901","size":"1000"},{"price":"0.00000000902","size":"2000"},{"price":"0.00000000903","size":"140000"},{"price":"0.00000000904","size":"1000"},{"price":"0.00000000905","size":"64000"},{"price":"0.00000000906","size":"1000"},{"price":"0.00000000907","size":"45000"},{"price":"0.00000000908","size":"1000"},{"price":"0.00000000909","size":"1000"},{"price":"0.00000000910","size":"1000"},{"price":"0.00000000911","size":"56000"},{"price":"0.00000000912","size":"1000"},{"price":"0.00000000913","size":"1000"},{"price":"0.00000000914","size":"1000"},{"price":"0.00000000915","size":"1000"},{"price":"0.00000000916","size":"1000"},{"price":"0.00000000917","size":"1000"},{"price":"0.00000000918","size":"1000"},{"price":"0.00000000919","size":"1000"},{"price":"0.00000000920","size":"113000"},{"price":"0.00000000921","size":"1000"},{"price":"0.00000000922","size":"1000"},{"price":"0.00000000923","size":"1000"},{"price":"0.00000000924","size":"1000"},{"price":"0.00000000925","size":"1000"},{"price":"0.00000000926","size":"2000"},{"price":"0.00000000927","size":"1000"},{"price":"0.00000000928","size":"107000"},{"price":"0.00000000929","size":"3000"},{"price":"0.00000000930","size":"1000"},{"price":"0.00000000931","size":"1000"},{"price":"0.00000000932","size":"1000"},{"price":"0.00000000933","size":"1000"},{"price":"0.00000000934","size":"1000"},{"price":"0.00000000935","size":"1000"},{"price":"0.00000000936","size":"1000"},{"price":"0.00000000937","size":"1000"},{"price":"0.00000000938","size":"1000"},{"price":"0.00000000939","size":"1000"},{"price":"0.00000000940","size":"1000"},{"price":"0.00000000941","size":"201000"},{"price":"0.00000000942","size":"9001000"},{"price":"0.00000000943","size":"1000"},{"price":"0.00000000944","size":"1000"},{"price":"0.00000000945","size":"1000"},{"price":"0.00000000946","size":"474000"},{"price":"0.00000000947","size":"1000"},{"price":"0.00000000948","size":"201000"},{"price":"0.00000000949","size":"1000"},{"price":"0.00000000950","size":"16000"},{"price":"0.00000000951","size":"1000"},{"price":"0.00000000952","size":"14000"},{"price":"0.00000000953","size":"1000"},{"price":"0.00000000954","size":"1000"},{"price":"0.00000000955","size":"1000"},{"price":"0.00000000956","size":"10000"},{"price":"0.00000000957","size":"2000"},{"price":"0.00000000958","size":"1000"},{"price":"0.00000000959","size":"1000"},{"price":"0.00000000960","size":"11000"},{"price":"0.00000000961","size":"1000"},{"price":"0.00000000962","size":"51000"},{"price":"0.00000000963","size":"1000"},{"price":"0.00000000964","size":"1000"},{"price":"0.00000000965","size":"1000"},{"price":"0.00000000966","size":"17000"},{"price":"0.00000000967","size":"1000"},{"price":"0.00000000968","size":"1000"},{"price":"0.00000000969","size":"1000"},{"price":"0.00000000970","size":"1000"},{"price":"0.00000000971","size":"1000"},{"price":"0.00000000972","size":"1000"},{"price":"0.00000000973","size":"1000"},{"price":"0.00000000974","size":"1000"},{"price":"0.00000000975","size":"1000"},{"price":"0.00000000976","size":"1000"},{"price":"0.00000000977","size":"1000"},{"price":"0.00000000978","size":"3000"},{"price":"0.00000000979","size":"1000"},{"price":"0.00000000980","size":"1000"},{"price":"0.00000000981","size":"1000"},{"price":"0.00000000982","size":"1000"},{"price":"0.00000000983","size":"1001000"},{"price":"0.00000000984","size":"1000"},{"price":"0.00000000985","size":"1000"},{"price":"0.00000000986","size":"1000"},{"price":"0.00000000987","size":"1000"},{"price":"0.00000000988","size":"1000"},{"price":"0.00000000989","size":"1000"},{"price":"0.00000000990","size":"2000"},{"price":"0.00000000991","size":"1000"},{"price":"0.00000000992","size":"1000"},{"price":"0.00000000993","size":"1000"},{"price":"0.00000000994","size":"1000"},{"price":"0.00000000995","size":"1000"},{"price":"0.00000000996","size":"1000"},{"price":"0.00000000997","size":"501000"},{"price":"0.00000000998","size":"1000"},{"price":"0.00000000999","size":"1000"},{"price":"0.00000001000","size":"2047000"},{"price":"0.00000001007","size":"1000"},{"price":"0.00000001010","size":"18000"},{"price":"0.00000001016","size":"27000"},{"price":"0.00000001066","size":"10000"},{"price":"0.00000001078","size":"35000"},{"price":"0.00000001081","size":"393000"},{"price":"0.00000001088","size":"115000"},{"price":"0.00000001090","size":"47000"},{"price":"0.00000001100","size":"219000"},{"price":"0.00000001107","size":"1000"},{"price":"0.00000001112","size":"40000"},{"price":"0.00000001135","size":"1000"},{"price":"0.00000001142","size":"151000"},{"price":"0.00000001145","size":"20000"},{"price":"0.00000001149","size":"20000"},{"price":"0.00000001150","size":"20000"},{"price":"0.00000001156","size":"87000"},{"price":"0.00000001189","size":"40000"},{"price":"0.00000001190","size":"1000"},{"price":"0.00000001193","size":"29000"},{"price":"0.00000001194","size":"14220000"},{"price":"0.00000001197","size":"500000"},{"price":"0.00000001200","size":"400000"},{"price":"0.00000001207","size":"1000"},{"price":"0.00000001215","size":"50000"},{"price":"0.00000001221","size":"1000"},{"price":"0.00000001230","size":"35000"},{"price":"0.00000001234","size":"3000"},{"price":"0.00000001248","size":"2000"},{"price":"0.00000001250","size":"8000"},{"price":"0.00000001256","size":"30000"},{"price":"0.00000001280","size":"18000"},{"price":"0.00000001300","size":"320000"},{"price":"0.00000001305","size":"6828000"},{"price":"0.00000001307","size":"1000"},{"price":"0.00000001315","size":"10000"},{"price":"0.00000001328","size":"231000"},{"price":"0.00000001330","size":"22000"},{"price":"0.00000001366","size":"7000"},{"price":"0.00000001380","size":"60000"},{"price":"0.00000001390","size":"103000"},{"price":"0.00000001400","size":"512000"},{"price":"0.00000001407","size":"1000"},{"price":"0.00000001440","size":"974000"},{"price":"0.00000001450","size":"2000"},{"price":"0.00000001455","size":"1000"},{"price":"0.00000001458","size":"1000"},{"price":"0.00000001466","size":"9000"},{"price":"0.00000001479","size":"13000"},{"price":"0.00000001483","size":"934000"},{"price":"0.00000001487","size":"2000"},{"price":"0.00000001494","size":"1000"},{"price":"0.00000001497","size":"500000"},{"price":"0.00000001498","size":"152000"},{"price":"0.00000001500","size":"373000"},{"price":"0.00000001540","size":"9000"},{"price":"0.00000001550","size":"2000"},{"price":"0.00000001560","size":"10000"},{"price":"0.00000001566","size":"4000"},{"price":"0.00000001600","size":"121000"},{"price":"0.00000001625","size":"20000"},{"price":"0.00000001634","size":"111000"},{"price":"0.00000001639","size":"2000"},{"price":"0.00000001655","size":"10000"},{"price":"0.00000001660","size":"1000"},{"price":"0.00000001662","size":"50000"},{"price":"0.00000001666","size":"10000"},{"price":"0.00000001700","size":"5000"},{"price":"0.00000001730","size":"9000"},{"price":"0.00000001750","size":"18000"},{"price":"0.00000001754","size":"20000"},{"price":"0.00000001756","size":"30000"},{"price":"0.00000001766","size":"5000"},{"price":"0.00000001784","size":"176000"},{"price":"0.00000001792","size":"81000"},{"price":"0.00000001800","size":"3143000"},{"price":"0.00000001806","size":"5000"},{"price":"0.00000001820","size":"1000"},{"price":"0.00000001840","size":"104000"},{"price":"0.00000001843","size":"5134000"},{"price":"0.00000001859","size":"1000"},{"price":"0.00000001860","size":"1000"},{"price":"0.00000001866","size":"2000"},{"price":"0.00000001888","size":"81000"},{"price":"0.00000001890","size":"120000"},{"price":"0.00000001899","size":"1000"},{"price":"0.00000001900","size":"10000"},{"price":"0.00000001906","size":"4000"},{"price":"0.00000001916","size":"1000"},{"price":"0.00000001945","size":"27000"},{"price":"0.00000001953","size":"12000"},{"price":"0.00000001966","size":"2000"},{"price":"0.00000001986","size":"1000"},{"price":"0.00000001989","size":"100000"},{"price":"0.00000001990","size":"51000"},{"price":"0.00000001993","size":"1000000"},{"price":"0.00000001999","size":"5276000"},{"price":"0.00000002000","size":"2697000"},{"price":"0.00000002022","size":"10000"},{"price":"0.00000002040","size":"100000"},{"price":"0.00000002066","size":"519000"},{"price":"0.00000002078","size":"2000"},{"price":"0.00000002130","size":"30000"},{"price":"0.00000002142","size":"99000"},{"price":"0.00000002156","size":"16000"},{"price":"0.00000002160","size":"1000"},{"price":"0.00000002197","size":"104000"},{"price":"0.00000002200","size":"13000"},{"price":"0.00000002220","size":"20000"},{"price":"0.00000002223","size":"20000"},{"price":"0.00000002266","size":"2000"},{"price":"0.00000002271","size":"1000000"},{"price":"0.00000002296","size":"5000"},{"price":"0.00000002300","size":"25000"},{"price":"0.00000002310","size":"10000"},{"price":"0.00000002340","size":"24000"},{"price":"0.00000002350","size":"1000"},{"price":"0.00000002370","size":"10000"},{"price":"0.00000002375","size":"1000"},{"price":"0.00000002400","size":"102000"},{"price":"0.00000002418","size":"16000"},{"price":"0.00000002423","size":"20000"},{"price":"0.00000002429","size":"1000000"},{"price":"0.00000002455","size":"1000"},{"price":"0.00000002457","size":"1000"},{"price":"0.00000002465","size":"1000"},{"price":"0.00000002466","size":"2000"},{"price":"0.00000002470","size":"51000"},{"price":"0.00000002476","size":"1000"},{"price":"0.00000002490","size":"45000"},{"price":"0.00000002500","size":"621000"},{"price":"0.00000002550","size":"1000"},{"price":"0.00000002564","size":"417000"},{"price":"0.00000002572","size":"1000"},{"price":"0.00000002596","size":"1000"},{"price":"0.00000002600","size":"1013000"},{"price":"0.00000002656","size":"118000"},{"price":"0.00000002666","size":"2000"},{"price":"0.00000002688","size":"80000"},{"price":"0.00000002690","size":"1000"},{"price":"0.00000002700","size":"20000"},{"price":"0.00000002708","size":"1000"},{"price":"0.00000002723","size":"20000"},{"price":"0.00000002732","size":"1000"},{"price":"0.00000002800","size":"61000"},{"price":"0.00000002833","size":"1000"},{"price":"0.00000002866","size":"1000"},{"price":"0.00000002888","size":"364000"},{"price":"0.00000002900","size":"1000"},{"price":"0.00000002923","size":"20000"},{"price":"0.00000002965","size":"10000"},{"price":"0.00000003000","size":"196000"},{"price":"0.00000003023","size":"20000"},{"price":"0.00000003030","size":"959000"},{"price":"0.00000003078","size":"2000"},{"price":"0.00000003096","size":"5000"},{"price":"0.00000003099","size":"54000"},{"price":"0.00000003100","size":"1000"},{"price":"0.00000003188","size":"4000"},{"price":"0.00000003200","size":"236000"},{"price":"0.00000003210","size":"5940000"},{"price":"0.00000003220","size":"20000"},{"price":"0.00000003223","size":"20000"},{"price":"0.00000003291","size":"1000"},{"price":"0.00000003300","size":"68000"},{"price":"0.00000003305","size":"3000000"},{"price":"0.00000003368","size":"1000"},{"price":"0.00000003400","size":"474000"},{"price":"0.00000003423","size":"20000"},{"price":"0.00000003455","size":"1000"},{"price":"0.00000003483","size":"12000"},{"price":"0.00000003500","size":"76000"},{"price":"0.00000003560","size":"10000"},{"price":"0.00000003600","size":"80000"},{"price":"0.00000003620","size":"10000"},{"price":"0.00000003666","size":"5000"},{"price":"0.00000003700","size":"22000"},{"price":"0.00000003708","size":"1000"},{"price":"0.00000003750","size":"1000"},{"price":"0.00000003800","size":"80000"},{"price":"0.00000003888","size":"121000"},{"price":"0.00000003900","size":"114000"},{"price":"0.00000003999","size":"52000"},{"price":"0.00000004000","size":"396000"},{"price":"0.00000004078","size":"2000"},{"price":"0.00000004100","size":"251000"},{"price":"0.00000004200","size":"54000"},{"price":"0.00000004208","size":"1000"},{"price":"0.00000004220","size":"20000"},{"price":"0.00000004275","size":"10000"},{"price":"0.00000004300","size":"48000"},{"price":"0.00000004320","size":"10000"},{"price":"0.00000004340","size":"15000"},{"price":"0.00000004400","size":"173000"},{"price":"0.00000004424","size":"8000000"},{"price":"0.00000004452","size":"41000"},{"price":"0.00000004480","size":"80000"},{"price":"0.00000004494","size":"1000"},{"price":"0.00000004500","size":"804000"},{"price":"0.00000004600","size":"840000"},{"price":"0.00000004650","size":"37000"},{"price":"0.00000004666","size":"5000"},{"price":"0.00000004700","size":"1301000"},{"price":"0.00000004730","size":"1000"},{"price":"0.00000004800","size":"274000"},{"price":"0.00000004803","size":"1000"},{"price":"0.00000004888","size":"90000"},{"price":"0.00000004900","size":"1094000"},{"price":"0.00000004931","size":"10000"},{"price":"0.00000004950","size":"100000"},{"price":"0.00000005000","size":"8379000"},{"price":"0.00000005028","size":"50000"},{"price":"0.00000005078","size":"2000"},{"price":"0.00000005100","size":"80000"},{"price":"0.00000005125","size":"1000"},{"price":"0.00000005200","size":"5404000"},{"price":"0.00000005211","size":"80000"},{"price":"0.00000005300","size":"8000"},{"price":"0.00000005400","size":"2000"},{"price":"0.00000005500","size":"95000"},{"price":"0.00000005550","size":"1000"},{"price":"0.00000005583","size":"1000"},{"price":"0.00000005586","size":"10000"},{"price":"0.00000005600","size":"1000"},{"price":"0.00000005700","size":"1000"},{"price":"0.00000005800","size":"1000"},{"price":"0.00000005888","size":"104000"},{"price":"0.00000005900","size":"14000"},{"price":"0.00000005928","size":"10000"},{"price":"0.00000006000","size":"927000"},{"price":"0.00000006004","size":"1000000"},{"price":"0.00000006041","size":"1000"},{"price":"0.00000006078","size":"2000"},{"price":"0.00000006200","size":"1000"},{"price":"0.00000006241","size":"10000"},{"price":"0.00000006300","size":"2000"},{"price":"0.00000006400","size":"204000"},{"price":"0.00000006483","size":"11000"},{"price":"0.00000006500","size":"1978000"},{"price":"0.00000006600","size":"2000"},{"price":"0.00000006660","size":"5000"},{"price":"0.00000006800","size":"91000"},{"price":"0.00000006888","size":"4000"},{"price":"0.00000006900","size":"14000"},{"price":"0.00000006958","size":"1000"},{"price":"0.00000007000","size":"285000"},{"price":"0.00000007078","size":"2000"},{"price":"0.00000007200","size":"40000"},{"price":"0.00000007300","size":"1531000"},{"price":"0.00000007416","size":"1000"},{"price":"0.00000007500","size":"2000"},{"price":"0.00000007600","size":"12000"},{"price":"0.00000007700","size":"24027000"},{"price":"0.00000007800","size":"2000"},{"price":"0.00000007875","size":"1000"},{"price":"0.00000007888","size":"7000"},{"price":"0.00000007900","size":"12000"},{"price":"0.00000007965","size":"254000"},{"price":"0.00000008000","size":"36000"},{"price":"0.00000008078","size":"2000"},{"price":"0.00000008100","size":"79000"},{"price":"0.00000008200","size":"198000"},{"price":"0.00000008300","size":"10000"},{"price":"0.00000008333","size":"1000"},{"price":"0.00000008400","size":"368000"},{"price":"0.00000008483","size":"9000"},{"price":"0.00000008500","size":"12000"},{"price":"0.00000008666","size":"2000"},{"price":"0.00000008700","size":"38000"},{"price":"0.00000008791","size":"1000"},{"price":"0.00000008800","size":"15000"},{"price":"0.00000008888","size":"3000"},{"price":"0.00000008900","size":"11000"},{"price":"0.00000008990","size":"50000"},{"price":"0.00000009000","size":"177000"},{"price":"0.00000009100","size":"20000"},{"price":"0.00000009220","size":"1000"},{"price":"0.00000009250","size":"1000"},{"price":"0.00000009300","size":"837000"},{"price":"0.00000009400","size":"10000"},{"price":"0.00000009450","size":"2245000"},{"price":"0.00000009483","size":"11000"},{"price":"0.00000009500","size":"530000"},{"price":"0.00000009600","size":"52000"},{"price":"0.00000009666","size":"4000"},{"price":"0.00000009700","size":"35000"},{"price":"0.00000009708","size":"1000"},{"price":"0.00000009800","size":"169000"},{"price":"0.00000009900","size":"1204000"},{"price":"0.00000009905","size":"235000"},{"price":"0.00000009985","size":"200000"},{"price":"0.00000010000","size":"8831000"},{"price":"0.00000010027","size":"20000"},{"price":"0.00000010166","size":"1000"},{"price":"0.00000010180","size":"9000"},{"price":"0.00000010360","size":"1266000"},{"price":"0.00000010427","size":"20000"},{"price":"0.00000010500","size":"1000"},{"price":"0.00000010600","size":"25000"},{"price":"0.00000010625","size":"1000"},{"price":"0.00000010627","size":"20000"},{"price":"0.00000010644","size":"11000"},{"price":"0.00000010800","size":"4000"},{"price":"0.00000010827","size":"20000"},{"price":"0.00000010900","size":"8000"},{"price":"0.00000010927","size":"20000"},{"price":"0.00000010987","size":"20000"},{"price":"0.00000011000","size":"99000"},{"price":"0.00000011083","size":"1000"},{"price":"0.00000011100","size":"28000"},{"price":"0.00000011541","size":"1000"},{"price":"0.00000011600","size":"1000"},{"price":"0.00000011700","size":"13000"},{"price":"0.00000011800","size":"12000"},{"price":"0.00000012000","size":"204000"},{"price":"0.00000012200","size":"8000"},{"price":"0.00000012220","size":"20000"},{"price":"0.00000012300","size":"50000"},{"price":"0.00000012321","size":"203000"},{"price":"0.00000012483","size":"9000"},{"price":"0.00000012500","size":"200000"},{"price":"0.00000012606","size":"10000000"},{"price":"0.00000012700","size":"57000"},{"price":"0.00000012770","size":"1000"},{"price":"0.00000012800","size":"2000"},{"price":"0.00000012881","size":"1000"},{"price":"0.00000013000","size":"88000"},{"price":"0.00000013100","size":"1000"},{"price":"0.00000013200","size":"50000"},{"price":"0.00000013238","size":"1764000"},{"price":"0.00000013400","size":"11000"},{"price":"0.00000013500","size":"1000"},{"price":"0.00000013576","size":"10000000"},{"price":"0.00000013600","size":"2000"},{"price":"0.00000013800","size":"13000"},{"price":"0.00000013900","size":"16000"},{"price":"0.00000014000","size":"45000"},{"price":"0.00000014220","size":"20000"},{"price":"0.00000014300","size":"7000"},{"price":"0.00000014400","size":"50000"},{"price":"0.00000014483","size":"9000"},{"price":"0.00000014500","size":"5000"},{"price":"0.00000014576","size":"10000000"},{"price":"0.00000014800","size":"5000"},{"price":"0.00000014880","size":"300000"},{"price":"0.00000014900","size":"552000"},{"price":"0.00000015000","size":"855000"},{"price":"0.00000015100","size":"12000"},{"price":"0.00000015200","size":"27000"},{"price":"0.00000015400","size":"1000"},{"price":"0.00000015500","size":"1000"},{"price":"0.00000015600","size":"1000"},{"price":"0.00000015700","size":"7000"},{"price":"0.00000015800","size":"2000"},{"price":"0.00000015900","size":"7000"},{"price":"0.00000015990","size":"1000000"},{"price":"0.00000016000","size":"61000"},{"price":"0.00000016100","size":"1000"},{"price":"0.00000016220","size":"20000"},{"price":"0.00000016500","size":"10000"},{"price":"0.00000016600","size":"6000"},{"price":"0.00000016800","size":"18000"},{"price":"0.00000016950","size":"200000"},{"price":"0.00000017000","size":"471000"},{"price":"0.00000017200","size":"274000"},{"price":"0.00000017284","size":"1000"},{"price":"0.00000017434","size":"4637000"},{"price":"0.00000017483","size":"9000"},{"price":"0.00000017600","size":"3000"},{"price":"0.00000017900","size":"10000"},{"price":"0.00000018000","size":"19000"},{"price":"0.00000018004","size":"1763000"},{"price":"0.00000018078","size":"1000"},{"price":"0.00000018220","size":"20000"},{"price":"0.00000018500","size":"117000"},{"price":"0.00000018540","size":"148000"},{"price":"0.00000018666","size":"2000"},{"price":"0.00000019000","size":"52000"},{"price":"0.00000019066","size":"1000"},{"price":"0.00000019159","size":"20000"},{"price":"0.00000019200","size":"6000"},{"price":"0.00000019500","size":"19000"},{"price":"0.00000019800","size":"48000"},{"price":"0.00000019900","size":"277000"},{"price":"0.00000020000","size":"2743000"},{"price":"0.00000020060","size":"209000"},{"price":"0.00000020100","size":"1000"},{"price":"0.00000020200","size":"50000"},{"price":"0.00000020220","size":"20000"},{"price":"0.00000020500","size":"3000"},{"price":"0.00000020600","size":"5000"},{"price":"0.00000020700","size":"15000"},{"price":"0.00000020990","size":"1000000"},{"price":"0.00000021000","size":"42000"},{"price":"0.00000021170","size":"1000"},{"price":"0.00000021700","size":"57000"},{"price":"0.00000021800","size":"96000"},{"price":"0.00000021898","size":"407000"},{"price":"0.00000022000","size":"261000"},{"price":"0.00000022100","size":"1000"},{"price":"0.00000022220","size":"20000"},{"price":"0.00000022223","size":"20000"},{"price":"0.00000022300","size":"823000"},{"price":"0.00000022400","size":"10000"},{"price":"0.00000022500","size":"4000"},{"price":"0.00000022700","size":"95000"},{"price":"0.00000022800","size":"100000"},{"price":"0.00000022899","size":"395000"},{"price":"0.00000022900","size":"1000"},{"price":"0.00000023000","size":"1000"},{"price":"0.00000023100","size":"14000"},{"price":"0.00000023200","size":"316000"},{"price":"0.00000023400","size":"11000"},{"price":"0.00000023423","size":"20000"},{"price":"0.00000023483","size":"6000"},{"price":"0.00000023500","size":"66000"},{"price":"0.00000023600","size":"14000"},{"price":"0.00000023800","size":"40000"},{"price":"0.00000024000","size":"2380000"},{"price":"0.00000024200","size":"11000"},{"price":"0.00000024220","size":"20000"},{"price":"0.00000024400","size":"1000"},{"price":"0.00000024500","size":"50000"},{"price":"0.00000024600","size":"25000"},{"price":"0.00000024666","size":"2000"},{"price":"0.00000024700","size":"22000"},{"price":"0.00000024800","size":"59000"},{"price":"0.00000024900","size":"60000"},{"price":"0.00000025000","size":"6009000"},{"price":"0.00000025100","size":"7000"},{"price":"0.00000025200","size":"12000"},{"price":"0.00000025400","size":"10000"},{"price":"0.00000025500","size":"3000"},{"price":"0.00000025600","size":"14000"},{"price":"0.00000025700","size":"6000"},{"price":"0.00000025900","size":"10000"},{"price":"0.00000026000","size":"86000"},{"price":"0.00000026200","size":"18000"},{"price":"0.00000026220","size":"20000"},{"price":"0.00000026300","size":"50000"},{"price":"0.00000026400","size":"8000"},{"price":"0.00000026600","size":"12000"},{"price":"0.00000026700","size":"10000"},{"price":"0.00000026900","size":"1000"},{"price":"0.00000027000","size":"165000"},{"price":"0.00000027100","size":"25000"},{"price":"0.00000027110","size":"3049000"},{"price":"0.00000027300","size":"4000"},{"price":"0.00000027600","size":"33000"},{"price":"0.00000027700","size":"21000"},{"price":"0.00000027800","size":"6000"},{"price":"0.00000027900","size":"120000"},{"price":"0.00000028000","size":"530000"},{"price":"0.00000028100","size":"80000"},{"price":"0.00000028400","size":"260000"},{"price":"0.00000028500","size":"510000"},{"price":"0.00000028600","size":"1000"},{"price":"0.00000028700","size":"10000"},{"price":"0.00000028800","size":"10000"},{"price":"0.00000029000","size":"1217000"},{"price":"0.00000029220","size":"20000"},{"price":"0.00000029400","size":"20000"},{"price":"0.00000029430","size":"169000"},{"price":"0.00000029500","size":"20000"},{"price":"0.00000029600","size":"21000"},{"price":"0.00000029900","size":"60000"},{"price":"0.00000029990","size":"1000000"},{"price":"0.00000030000","size":"3135000"},{"price":"0.00000030100","size":"38000"},{"price":"0.00000030200","size":"50000"},{"price":"0.00000030220","size":"20000"},{"price":"0.00000030800","size":"205000"},{"price":"0.00000031000","size":"3000"},{"price":"0.00000031200","size":"5000"},{"price":"0.00000031400","size":"2000"},{"price":"0.00000031500","size":"516000"},{"price":"0.00000031600","size":"857000"},{"price":"0.00000031650","size":"775000"},{"price":"0.00000031700","size":"50000"},{"price":"0.00000032000","size":"35000"},{"price":"0.00000032400","size":"22000"},{"price":"0.00000032500","size":"12000"},{"price":"0.00000033000","size":"255000"},{"price":"0.00000033100","size":"30000"},{"price":"0.00000033220","size":"20000"},{"price":"0.00000033223","size":"20000"},{"price":"0.00000033300","size":"50000"},{"price":"0.00000033305","size":"3000000"},{"price":"0.00000033483","size":"3000"},{"price":"0.00000033500","size":"100000"},{"price":"0.00000033700","size":"10000"},{"price":"0.00000033800","size":"3000"},{"price":"0.00000033900","size":"312000"},{"price":"0.00000034000","size":"25000"},{"price":"0.00000034400","size":"20000"},{"price":"0.00000034700","size":"10000"},{"price":"0.00000034800","size":"10000"},{"price":"0.00000034900","size":"16000"},{"price":"0.00000035000","size":"843000"},{"price":"0.00000035200","size":"200000"},{"price":"0.00000035400","size":"10000"},{"price":"0.00000035600","size":"554000"},{"price":"0.00000035900","size":"10000"},{"price":"0.00000036000","size":"360000"},{"price":"0.00000036300","size":"50000"},{"price":"0.00000036500","size":"10000"},{"price":"0.00000036600","size":"2797000"},{"price":"0.00000036666","size":"2000"},{"price":"0.00000036900","size":"26000"},{"price":"0.00000037000","size":"17000"},{"price":"0.00000037100","size":"25000"},{"price":"0.00000037220","size":"20000"},{"price":"0.00000037500","size":"5000"},{"price":"0.00000037700","size":"51000"},{"price":"0.00000037900","size":"50000"},{"price":"0.00000038000","size":"103000"},{"price":"0.00000038200","size":"10000"},{"price":"0.00000038500","size":"10000"},{"price":"0.00000038600","size":"1000"},{"price":"0.00000039000","size":"937000"},{"price":"0.00000039220","size":"20000"},{"price":"0.00000039300","size":"1000"},{"price":"0.00000039430","size":"169000"},{"price":"0.00000039483","size":"3000"},{"price":"0.00000039500","size":"23000"},{"price":"0.00000039600","size":"100000"},{"price":"0.00000039700","size":"27000"},{"price":"0.00000039800","size":"62000"},{"price":"0.00000039900","size":"186000"},{"price":"0.00000040000","size":"4959000"},{"price":"0.00000040100","size":"10000"},{"price":"0.00000040200","size":"51000"},{"price":"0.00000040220","size":"20000"},{"price":"0.00000040900","size":"2000"},{"price":"0.00000041000","size":"118000"},{"price":"0.00000041100","size":"50000"},{"price":"0.00000041200","size":"16000"},{"price":"0.00000041600","size":"16000"},{"price":"0.00000041700","size":"65000"},{"price":"0.00000041800","size":"20000"},{"price":"0.00000042000","size":"39000"},{"price":"0.00000042200","size":"37000"},{"price":"0.00000042220","size":"20000"},{"price":"0.00000042300","size":"24000"},{"price":"0.00000042398","size":"180000"},{"price":"0.00000042400","size":"10000"},{"price":"0.00000042600","size":"5000"},{"price":"0.00000043000","size":"30000"},{"price":"0.00000043100","size":"10000"},{"price":"0.00000043200","size":"20000"},{"price":"0.00000043600","size":"1000"},{"price":"0.00000043700","size":"1000"},{"price":"0.00000043800","size":"48000"},{"price":"0.00000044000","size":"35000"},{"price":"0.00000044100","size":"4000"},{"price":"0.00000044200","size":"25000"},{"price":"0.00000044220","size":"20000"},{"price":"0.00000044400","size":"128000"},{"price":"0.00000044483","size":"3000"},{"price":"0.00000044800","size":"10000"},{"price":"0.00000044900","size":"19000"},{"price":"0.00000045000","size":"2215000"},{"price":"0.00000045100","size":"2000"},{"price":"0.00000045200","size":"74000"},{"price":"0.00000045400","size":"10000"},{"price":"0.00000045500","size":"101000"},{"price":"0.00000045600","size":"12000"},{"price":"0.00000045700","size":"331000"},{"price":"0.00000045800","size":"1000"},{"price":"0.00000045900","size":"10000"},{"price":"0.00000046000","size":"2178000"},{"price":"0.00000046493","size":"1000"},{"price":"0.00000046500","size":"178000"},{"price":"0.00000046666","size":"1000"},{"price":"0.00000046800","size":"626000"},{"price":"0.00000046900","size":"185000"},{"price":"0.00000047000","size":"798000"},{"price":"0.00000047100","size":"25000"},{"price":"0.00000047200","size":"68000"},{"price":"0.00000047300","size":"1000"},{"price":"0.00000047500","size":"251000"},{"price":"0.00000047600","size":"18000"},{"price":"0.00000047900","size":"20000"},{"price":"0.00000048000","size":"16000"},{"price":"0.00000048200","size":"3000"},{"price":"0.00000048220","size":"20000"},{"price":"0.00000048300","size":"74000"},{"price":"0.00000048325","size":"4000"},{"price":"0.00000048600","size":"21000"},{"price":"0.00000048900","size":"248000"},{"price":"0.00000049000","size":"121000"},{"price":"0.00000049200","size":"73000"},{"price":"0.00000049220","size":"20000"},{"price":"0.00000049300","size":"11000"},{"price":"0.00000049400","size":"70000"},{"price":"0.00000049430","size":"169000"},{"price":"0.00000049500","size":"813000"},{"price":"0.00000049700","size":"61000"},{"price":"0.00000049800","size":"21000"},{"price":"0.00000049900","size":"1049000"},{"price":"0.00000049999","size":"940000"},{"price":"0.00000050000","size":"7824000"},{"price":"0.00000050100","size":"1652000"},{"price":"0.00000050200","size":"69000"},{"price":"0.00000050400","size":"528000"},{"price":"0.00000050600","size":"20000"},{"price":"0.00000050700","size":"46000"},{"price":"0.00000050800","size":"1000"},{"price":"0.00000051000","size":"42000"},{"price":"0.00000051100","size":"10000"},{"price":"0.00000051400","size":"96000"},{"price":"0.00000051500","size":"609000"},{"price":"0.00000051600","size":"2715000"},{"price":"0.00000051611","size":"384000"},{"price":"0.00000051700","size":"50000"},{"price":"0.00000051800","size":"18000"},{"price":"0.00000052000","size":"84000"},{"price":"0.00000052159","size":"20000"},{"price":"0.00000052200","size":"19000"},{"price":"0.00000052300","size":"50000"},{"price":"0.00000052400","size":"20000"},{"price":"0.00000052500","size":"18000"},{"price":"0.00000052600","size":"16000"},{"price":"0.00000053000","size":"137000"},{"price":"0.00000053100","size":"10000"},{"price":"0.00000053300","size":"1000"},{"price":"0.00000053400","size":"18000"},{"price":"0.00000053600","size":"24000"},{"price":"0.00000053700","size":"51000"},{"price":"0.00000053800","size":"16000"},{"price":"0.00000053880","size":"977000"},{"price":"0.00000054000","size":"844000"},{"price":"0.00000054100","size":"1000"},{"price":"0.00000054200","size":"17000"},{"price":"0.00000054300","size":"151000"},{"price":"0.00000054400","size":"68000"},{"price":"0.00000054483","size":"1000"},{"price":"0.00000054500","size":"1000"},{"price":"0.00000054600","size":"32000"},{"price":"0.00000054700","size":"52000"},{"price":"0.00000054800","size":"284000"},{"price":"0.00000054900","size":"388000"},{"price":"0.00000055000","size":"2049000"},{"price":"0.00000055100","size":"10000"},{"price":"0.00000055200","size":"18000"},{"price":"0.00000055400","size":"60000"},{"price":"0.00000055500","size":"61000"},{"price":"0.00000055600","size":"21000"},{"price":"0.00000055700","size":"1000"},{"price":"0.00000055800","size":"58000"},{"price":"0.00000055900","size":"10000"},{"price":"0.00000056000","size":"3762000"},{"price":"0.00000056053","size":"1000"},{"price":"0.00000056200","size":"30000"},{"price":"0.00000056400","size":"18000"},{"price":"0.00000056500","size":"21000"},{"price":"0.00000056600","size":"1831000"},{"price":"0.00000056700","size":"26000"},{"price":"0.00000056800","size":"82000"},{"price":"0.00000056900","size":"46000"},{"price":"0.00000057000","size":"539000"},{"price":"0.00000057028","size":"2000"},{"price":"0.00000057100","size":"25000"},{"price":"0.00000057276","size":"7000"},{"price":"0.00000057400","size":"29000"},{"price":"0.00000057500","size":"184000"},{"price":"0.00000057600","size":"4000"},{"price":"0.00000057800","size":"12000"},{"price":"0.00000058000","size":"9134000"},{"price":"0.00000058100","size":"200000"},{"price":"0.00000058200","size":"10000"},{"price":"0.00000058300","size":"1000"},{"price":"0.00000058500","size":"10000"},{"price":"0.00000058600","size":"11000"},{"price":"0.00000058700","size":"50000"},{"price":"0.00000058900","size":"50000"},{"price":"0.00000059000","size":"339000"},{"price":"0.00000059033","size":"43000"},{"price":"0.00000059300","size":"22000"},{"price":"0.00000059400","size":"111000"},{"price":"0.00000059500","size":"1020000"},{"price":"0.00000059700","size":"1179000"},{"price":"0.00000059800","size":"43000"},{"price":"0.00000059900","size":"69000"},{"price":"0.00000060000","size":"4245000"},{"price":"0.00000060100","size":"49000"},{"price":"0.00000060200","size":"109000"},{"price":"0.00000060300","size":"13000"},{"price":"0.00000060513","size":"134000"},{"price":"0.00000060600","size":"1129000"},{"price":"0.00000060700","size":"2000"},{"price":"0.00000060839","size":"17000"},{"price":"0.00000061000","size":"156000"},{"price":"0.00000061100","size":"2000"},{"price":"0.00000061249","size":"65000"},{"price":"0.00000061400","size":"6000"},{"price":"0.00000061700","size":"50000"},{"price":"0.00000061800","size":"27000"},{"price":"0.00000062000","size":"66000"},{"price":"0.00000062200","size":"5000"},{"price":"0.00000062300","size":"30000"},{"price":"0.00000062400","size":"494000"},{"price":"0.00000062500","size":"45000"},{"price":"0.00000062600","size":"55000"},{"price":"0.00000062700","size":"5283000"},{"price":"0.00000063000","size":"38000"},{"price":"0.00000063100","size":"10000"},{"price":"0.00000063400","size":"94000"},{"price":"0.00000063500","size":"33000"},{"price":"0.00000063800","size":"5000"},{"price":"0.00000063830","size":"3000"},{"price":"0.00000064000","size":"40000"},{"price":"0.00000064100","size":"30000"},{"price":"0.00000064200","size":"3000"},{"price":"0.00000064300","size":"72000"},{"price":"0.00000064500","size":"155000"},{"price":"0.00000064600","size":"4000"},{"price":"0.00000064700","size":"10000"},{"price":"0.00000064900","size":"17000"},{"price":"0.00000065000","size":"3049000"},{"price":"0.00000065100","size":"20000"},{"price":"0.00000065400","size":"23000"},{"price":"0.00000065500","size":"25000"},{"price":"0.00000065800","size":"1000"},{"price":"0.00000066000","size":"138000"},{"price":"0.00000066200","size":"1000"},{"price":"0.00000066400","size":"1000"},{"price":"0.00000066500","size":"25000"},{"price":"0.00000066600","size":"199000"},{"price":"0.00000066900","size":"25000"},{"price":"0.00000067000","size":"264000"},{"price":"0.00000067100","size":"10000"},{"price":"0.00000067200","size":"1000"},{"price":"0.00000067500","size":"25000"},{"price":"0.00000067600","size":"50000"},{"price":"0.00000067900","size":"20000"},{"price":"0.00000068000","size":"33000"},{"price":"0.00000068100","size":"10000"},{"price":"0.00000068300","size":"416000"},{"price":"0.00000068400","size":"5283000"},{"price":"0.00000068500","size":"31000"},{"price":"0.00000068600","size":"20000"},{"price":"0.00000068700","size":"10000"},{"price":"0.00000068900","size":"70000"},{"price":"0.00000069000","size":"359000"},{"price":"0.00000069100","size":"9000"},{"price":"0.00000069159","size":"20000"},{"price":"0.00000069300","size":"50000"},{"price":"0.00000069400","size":"17000"},{"price":"0.00000069500","size":"45000"},{"price":"0.00000069600","size":"1416000"},{"price":"0.00000069700","size":"25000"},{"price":"0.00000069900","size":"267000"},{"price":"0.00000069959","size":"20000"},{"price":"0.00000070000","size":"1560000"},{"price":"0.00000070100","size":"196000"},{"price":"0.00000070200","size":"96000"},{"price":"0.00000070300","size":"5000"},{"price":"0.00000070500","size":"50000"},{"price":"0.00000070900","size":"10000"},{"price":"0.00000071000","size":"265000"},{"price":"0.00000071100","size":"125000"},{"price":"0.00000071159","size":"20000"},{"price":"0.00000071300","size":"10000"},{"price":"0.00000071500","size":"75000"},{"price":"0.00000071700","size":"50000"},{"price":"0.00000072000","size":"260000"},{"price":"0.00000072100","size":"125000"},{"price":"0.00000072200","size":"20000"},{"price":"0.00000072300","size":"40000"},{"price":"0.00000072500","size":"125000"},{"price":"0.00000072700","size":"25000"},{"price":"0.00000073000","size":"145000"},{"price":"0.00000073100","size":"25000"},{"price":"0.00000073300","size":"20000"},{"price":"0.00000073400","size":"1000"},{"price":"0.00000073500","size":"50000"},{"price":"0.00000073800","size":"223000"},{"price":"0.00000074000","size":"150000"},{"price":"0.00000074100","size":"5283000"},{"price":"0.00000074200","size":"69000"},{"price":"0.00000074300","size":"21000"},{"price":"0.00000074500","size":"64000"},{"price":"0.00000074700","size":"2000"},{"price":"0.00000074800","size":"12000"},{"price":"0.00000074900","size":"2000"},{"price":"0.00000075000","size":"415000"},{"price":"0.00000075100","size":"10000"},{"price":"0.00000075300","size":"20000"},{"price":"0.00000075500","size":"25000"},{"price":"0.00000076000","size":"55000"},{"price":"0.00000076300","size":"11000"},{"price":"0.00000076400","size":"1000"},{"price":"0.00000076500","size":"50000"},{"price":"0.00000076900","size":"25000"},{"price":"0.00000077000","size":"45000"},{"price":"0.00000077100","size":"25000"},{"price":"0.00000077400","size":"25000"},{"price":"0.00000077600","size":"75000"},{"price":"0.00000077700","size":"105000"},{"price":"0.00000078000","size":"42000"},{"price":"0.00000078700","size":"25000"},{"price":"0.00000078900","size":"38000"},{"price":"0.00000079000","size":"30000"},{"price":"0.00000079430","size":"169000"},{"price":"0.00000079800","size":"75000"},{"price":"0.00000079900","size":"58000"},{"price":"0.00000080000","size":"1687000"},{"price":"0.00000080100","size":"100000"},{"price":"0.00000081000","size":"25000"},{"price":"0.00000081100","size":"100000"},{"price":"0.00000082000","size":"10000"},{"price":"0.00000082500","size":"25000"},{"price":"0.00000084000","size":"5000"},{"price":"0.00000084400","size":"30000"},{"price":"0.00000084500","size":"142000"},{"price":"0.00000084880","size":"10000"},{"price":"0.00000085000","size":"66000"},{"price":"0.00000085100","size":"10000"},{"price":"0.00000086200","size":"4000"},{"price":"0.00000086400","size":"1000"},{"price":"0.00000087000","size":"7000"},{"price":"0.00000087600","size":"72000"},{"price":"0.00000088000","size":"33000"},{"price":"0.00000088200","size":"12000"},{"price":"0.00000089000","size":"10000"},{"price":"0.00000089900","size":"35000"},{"price":"0.00000090000","size":"545000"},{"price":"0.00000090100","size":"2000"},{"price":"0.00000091000","size":"39000"},{"price":"0.00000091100","size":"100000"},{"price":"0.00000091670","size":"10000"},{"price":"0.00000091700","size":"10000"},{"price":"0.00000092000","size":"1103000"},{"price":"0.00000092500","size":"20000"},{"price":"0.00000093000","size":"10000"},{"price":"0.00000094100","size":"1000"},{"price":"0.00000094730","size":"1000"},{"price":"0.00000095000","size":"501000"},{"price":"0.00000095100","size":"10000"},{"price":"0.00000095400","size":"1049000"},{"price":"0.00000096000","size":"50000"},{"price":"0.00000096200","size":"6000"},{"price":"0.00000096600","size":"1000"},{"price":"0.00000097500","size":"13000"},{"price":"0.00000097600","size":"50000"},{"price":"0.00000098000","size":"3000"},{"price":"0.00000098089","size":"100000"},{"price":"0.00000098700","size":"42000"},{"price":"0.00000099000","size":"254000"},{"price":"0.00000099500","size":"2000"},{"price":"0.00000099600","size":"20000"},{"price":"0.00000099800","size":"2000"},{"price":"0.00000099900","size":"157000"},{"price":"0.00000100000","size":"1339000"},{"price":"0.00000100300","size":"10000"},{"price":"0.00000100500","size":"2000"},{"price":"0.00000101100","size":"100000"},{"price":"0.00000102000","size":"648000"},{"price":"0.00000103200","size":"12000"},{"price":"0.00000105000","size":"954000"},{"price":"0.00000105100","size":"10000"},{"price":"0.00000105300","size":"10000"},{"price":"0.00000106000","size":"5283000"},{"price":"0.00000106800","size":"13000"},{"price":"0.00000106920","size":"10000"},{"price":"0.00000107600","size":"50000"},{"price":"0.00000108000","size":"4000"},{"price":"0.00000110000","size":"413000"},{"price":"0.00000114900","size":"30000"},{"price":"0.00000115000","size":"467000"},{"price":"0.00000115470","size":"10000"},{"price":"0.00000116010","size":"862000"},{"price":"0.00000116100","size":"12000"},{"price":"0.00000120000","size":"6000"},{"price":"0.00000121100","size":"100000"},{"price":"0.00000122000","size":"10000"},{"price":"0.00000124710","size":"10000"},{"price":"0.00000125000","size":"3000"},{"price":"0.00000125400","size":"13000"},{"price":"0.00000126600","size":"2000"},{"price":"0.00000126700","size":"2000"},{"price":"0.00000128000","size":"10000"},{"price":"0.00000129000","size":"1000"},{"price":"0.00000130000","size":"2000"},{"price":"0.00000131100","size":"100000"},{"price":"0.00000134300","size":"169000"},{"price":"0.00000134690","size":"10000"},{"price":"0.00000134700","size":"13000"},{"price":"0.00000140000","size":"2000"},{"price":"0.00000144000","size":"1291000"},{"price":"0.00000145460","size":"10000"},{"price":"0.00000145500","size":"9000"},{"price":"0.00000146400","size":"298000"},{"price":"0.00000147000","size":"36000"},{"price":"0.00000148089","size":"100000"},{"price":"0.00000149000","size":"50000"},{"price":"0.00000149100","size":"10000"},{"price":"0.00000149900","size":"2000"},{"price":"0.00000149980","size":"1333000"},{"price":"0.00000150000","size":"8165000"},{"price":"0.00000151100","size":"100000"},{"price":"0.00000152610","size":"2000000"},{"price":"0.00000153300","size":"13000"},{"price":"0.00000154000","size":"1000"},{"price":"0.00000154400","size":"9000"},{"price":"0.00000155000","size":"122000"},{"price":"0.00000155100","size":"10000"},{"price":"0.00000156100","size":"1000"},{"price":"0.00000157000","size":"1000"},{"price":"0.00000157089","size":"100000"},{"price":"0.00000157100","size":"10000"},{"price":"0.00000159980","size":"1764000"},{"price":"0.00000160000","size":"500000"},{"price":"0.00000162500","size":"13000"},{"price":"0.00000166600","size":"1000"},{"price":"0.00000167000","size":"584000"},{"price":"0.00000169670","size":"9000"},{"price":"0.00000169980","size":"1764000"},{"price":"0.00000170000","size":"500000"},{"price":"0.00000171619","size":"134000"},{"price":"0.00000171800","size":"12000"},{"price":"0.00000179000","size":"7000"},{"price":"0.00000180000","size":"511000"},{"price":"0.00000181100","size":"13000"},{"price":"0.00000183240","size":"10000"},{"price":"0.00000190000","size":"1875000"},{"price":"0.00000190400","size":"13000"},{"price":"0.00000192000","size":"1000"},{"price":"0.00000192300","size":"132000"},{"price":"0.00000194000","size":"220000"},{"price":"0.00000197900","size":"10000"},{"price":"0.00000198000","size":"1000"},{"price":"0.00000199000","size":"98000"},{"price":"0.00000199100","size":"10000"},{"price":"0.00000199700","size":"12000"},{"price":"0.00000199800","size":"162000"},{"price":"0.00000199900","size":"1000"},{"price":"0.00000200000","size":"3902000"},{"price":"0.00000200100","size":"100000"},{"price":"0.00000201357","size":"15000"},{"price":"0.00000205000","size":"5000"},{"price":"0.00000205100","size":"2000"},{"price":"0.00000209000","size":"13000"},{"price":"0.00000210000","size":"510000"},{"price":"0.00000214000","size":"1000"},{"price":"0.00000217089","size":"100000"},{"price":"0.00000218300","size":"13000"},{"price":"0.00000220000","size":"500000"},{"price":"0.00000222000","size":"951000"},{"price":"0.00000224350","size":"169000"},{"price":"0.00000227600","size":"12000"},{"price":"0.00000230000","size":"517000"},{"price":"0.00000232000","size":"174000"},{"price":"0.00000236900","size":"13000"},{"price":"0.00000237800","size":"205000"},{"price":"0.00000238000","size":"1167000"},{"price":"0.00000240000","size":"501000"},{"price":"0.00000246200","size":"13000"},{"price":"0.00000247089","size":"100000"},{"price":"0.00000249000","size":"46000"},{"price":"0.00000249800","size":"15000"},{"price":"0.00000250000","size":"4000"},{"price":"0.00000255500","size":"12000"},{"price":"0.00000264800","size":"13000"},{"price":"0.00000270000","size":"26000"},{"price":"0.00000274100","size":"13000"},{"price":"0.00000280000","size":"3000"},{"price":"0.00000283400","size":"12000"},{"price":"0.00000284350","size":"169000"},{"price":"0.00000292700","size":"13000"},{"price":"0.00000293800","size":"1000000"},{"price":"0.00000298000","size":"1000"},{"price":"0.00000299000","size":"38000"},{"price":"0.00000299100","size":"10000"},{"price":"0.00000299900","size":"1000"},{"price":"0.00000300000","size":"316000"},{"price":"0.00000302000","size":"13000"},{"price":"0.00000310200","size":"15000"},{"price":"0.00000311200","size":"12000"},{"price":"0.00000320000","size":"10000"},{"price":"0.00000320500","size":"13000"},{"price":"0.00000329800","size":"13000"},{"price":"0.00000330000","size":"10000"},{"price":"0.00000333000","size":"1000"},{"price":"0.00000333459","size":"22000"},{"price":"0.00000333800","size":"700000"},{"price":"0.00000339100","size":"12000"},{"price":"0.00000347000","size":"10000"},{"price":"0.00000348400","size":"13000"},{"price":"0.00000349000","size":"28000"},{"price":"0.00000350000","size":"201000"},{"price":"0.00000357700","size":"13000"},{"price":"0.00000360000","size":"20000"},{"price":"0.00000367000","size":"12000"},{"price":"0.00000376300","size":"13000"},{"price":"0.00000384350","size":"169000"},{"price":"0.00000385600","size":"13000"},{"price":"0.00000394900","size":"12000"},{"price":"0.00000398000","size":"1000"},{"price":"0.00000399000","size":"42000"},{"price":"0.00000399100","size":"10000"},{"price":"0.00000399800","size":"100000"},{"price":"0.00000400000","size":"618000"},{"price":"0.00000400100","size":"100000"},{"price":"0.00000404200","size":"13000"},{"price":"0.00000410000","size":"3000"},{"price":"0.00000413000","size":"8000"},{"price":"0.00000413500","size":"13000"},{"price":"0.00000422800","size":"12000"},{"price":"0.00000428600","size":"100000"},{"price":"0.00000428800","size":"76000"},{"price":"0.00000432100","size":"13000"},{"price":"0.00000440000","size":"152000"},{"price":"0.00000441400","size":"13000"},{"price":"0.00000443800","size":"35000"},{"price":"0.00000450100","size":"161000"},{"price":"0.00000450700","size":"12000"},{"price":"0.00000452564","size":"44000"},{"price":"0.00000452565","size":"44000"},{"price":"0.00000452567","size":"44000"},{"price":"0.00000452568","size":"44000"},{"price":"0.00000452570","size":"45000"},{"price":"0.00000460000","size":"15000"},{"price":"0.00000467000","size":"30000"},{"price":"0.00000473000","size":"1000"},{"price":"0.00000480000","size":"1000"},{"price":"0.00000490400","size":"178000"},{"price":"0.00000498000","size":"1000"},{"price":"0.00000499000","size":"100000"},{"price":"0.00000499100","size":"10000"},{"price":"0.00000499400","size":"10000"},{"price":"0.00000500000","size":"2320000"},{"price":"0.00000503000","size":"248000"},{"price":"0.00000510000","size":"5000"},{"price":"0.00000511000","size":"1000"},{"price":"0.00000520000","size":"4000"},{"price":"0.00000525090","size":"9000"},{"price":"0.00000525100","size":"500000"},{"price":"0.00000530000","size":"5283000"},{"price":"0.00000550100","size":"161000"},{"price":"0.00000555000","size":"1000"},{"price":"0.00000558000","size":"100000"},{"price":"0.00000590000","size":"1000"},{"price":"0.00000592470","size":"100000"},{"price":"0.00000599000","size":"22000"},{"price":"0.00000600000","size":"16000"},{"price":"0.00000601000","size":"187000"},{"price":"0.00000609756","size":"164000"},{"price":"0.00000650000","size":"22117000"},{"price":"0.00000656000","size":"20000"},{"price":"0.00000665900","size":"156000"},{"price":"0.00000680000","size":"50000"},{"price":"0.00000695000","size":"1000000"},{"price":"0.00000698000","size":"1000"},{"price":"0.00000700000","size":"1092000"},{"price":"0.00000712000","size":"13000"},{"price":"0.00000715100","size":"350000"},{"price":"0.00000768000","size":"1000"},{"price":"0.00000796400","size":"33000"},{"price":"0.00000798000","size":"1000"},{"price":"0.00000800000","size":"2000"},{"price":"0.00000820000","size":"1000"},{"price":"0.00000825100","size":"500000"},{"price":"0.00000868000","size":"50000"},{"price":"0.00000900000","size":"1394000"},{"price":"0.00000910000","size":"150000"},{"price":"0.00000947600","size":"35000"},{"price":"0.00000950100","size":"239000"},{"price":"0.00000960000","size":"1000"},{"price":"0.00000968130","size":"250000"},{"price":"0.00000970000","size":"100000"},{"price":"0.00000982099","size":"1190000"},{"price":"0.00000990000","size":"292000"},{"price":"0.00000996400","size":"95000"},{"price":"0.00000998000","size":"1000"},{"price":"0.00000998400","size":"53000"},{"price":"0.00000998600","size":"59000"},{"price":"0.00001000000","size":"3184000"},{"price":"0.00001100000","size":"5000"},{"price":"0.00001118078","size":"1000"},{"price":"0.00001150000","size":"2000"},{"price":"0.00001201357","size":"15000"},{"price":"0.00001400100","size":"50000"},{"price":"0.00001499100","size":"10000"},{"price":"0.00001500000","size":"103000"},{"price":"0.00001518000","size":"5000"},{"price":"0.00001540000","size":"1000"},{"price":"0.00001600000","size":"183000"},{"price":"0.00001700000","size":"100000"},{"price":"0.00001760000","size":"88000"},{"price":"0.00001790000","size":"4000"},{"price":"0.00001800000","size":"49000"},{"price":"0.00001847000","size":"10000"},{"price":"0.00001900000","size":"1000"},{"price":"0.00001940000","size":"15000"},{"price":"0.00001957000","size":"22000"},{"price":"0.00001999900","size":"1000"},{"price":"0.00002000000","size":"125000"},{"price":"0.00002040000","size":"2000"},{"price":"0.00002100000","size":"2000"},{"price":"0.00002200000","size":"2000"},{"price":"0.00002432100","size":"21000"},{"price":"0.00002499100","size":"10000"},{"price":"0.00002561000","size":"1000"},{"price":"0.00002760000","size":"28000"},{"price":"0.00002900000","size":"2000"},{"price":"0.00003000000","size":"1000"},{"price":"0.00003000631","size":"4000"},{"price":"0.00003100000","size":"1000"},{"price":"0.00003500000","size":"1000"},{"price":"0.00003560000","size":"10000"},{"price":"0.00003600000","size":"16000"},{"price":"0.00003680000","size":"50000"},{"price":"0.00004000000","size":"2000"},{"price":"0.00004000962","size":"1000"},{"price":"0.00004490000","size":"50000"},{"price":"0.00004499000","size":"1000"},{"price":"0.00004730000","size":"1000"},{"price":"0.00005000000","size":"68000"},{"price":"0.00005000095","size":"1000"},{"price":"0.00005061000","size":"1000"},{"price":"0.00005110000","size":"1000"},{"price":"0.00005250900","size":"2000"},{"price":"0.00005300000","size":"5283000"},{"price":"0.00006000000","size":"1000"},{"price":"0.00006043700","size":"1000"},{"price":"0.00007000000","size":"28000"},{"price":"0.00007999990","size":"2000"},{"price":"0.00008000000","size":"433000"},{"price":"0.00008100000","size":"61000"},{"price":"0.00009000000","size":"21000"},{"price":"0.00009690000","size":"6000"},{"price":"0.00009899000","size":"1000"},{"price":"0.00009900000","size":"4000"},{"price":"0.00010000000","size":"20619000"},{"price":"0.00010001390","size":"3000"},{"price":"0.00011111146","size":"108000"},{"price":"0.00011500000","size":"1000"},{"price":"0.00012320000","size":"100000"},{"price":"0.00012499100","size":"10000"},{"price":"0.00013000000","size":"610000"},{"price":"0.00013108000","size":"1000"},{"price":"0.00013370000","size":"3166000"},{"price":"0.00013590000","size":"13000"},{"price":"0.00015000000","size":"128000"},{"price":"0.00015340000","size":"2000"},{"price":"0.00015400000","size":"1000"},{"price":"0.00015878000","size":"250000"},{"price":"0.00016900000","size":"10000"},{"price":"0.00017000000","size":"6000"},{"price":"0.00017900000","size":"4000"},{"price":"0.00019000000","size":"5000"},{"price":"0.00019750000","size":"5000"},{"price":"0.00019899000","size":"1000"},{"price":"0.00020000000","size":"10000"},{"price":"0.00023000000","size":"2000"},{"price":"0.00025000000","size":"800000"},{"price":"0.00025500000","size":"124876000"},{"price":"0.00030000000","size":"1000"},{"price":"0.00040000000","size":"6000"},{"price":"0.00043220000","size":"5000"},{"price":"0.00045000000","size":"5000"},{"price":"0.00047000000","size":"14000"},{"price":"0.00049899000","size":"1000"},{"price":"0.00050000000","size":"16000"},{"price":"0.00050002500","size":"112000"},{"price":"0.00051000000","size":"5000"},{"price":"0.00053000000","size":"5283000"},{"price":"0.00056000000","size":"6000"},{"price":"0.00060000000","size":"1000"},{"price":"0.00065000000","size":"1000000"},{"price":"0.00066600000","size":"4000"},{"price":"0.00070000000","size":"1000"},{"price":"0.00075000000","size":"2700000"},{"price":"0.00080000000","size":"13000"},{"price":"0.00088968000","size":"1000"},{"price":"0.00090000000","size":"22000"},{"price":"0.00097500000","size":"5000"},{"price":"0.00097999800","size":"1000"},{"price":"0.00099000000","size":"7000"},{"price":"0.00099100000","size":"10000"},{"price":"0.00099899000","size":"6000"},{"price":"0.00100000000","size":"431000"},{"price":"0.00100000504","size":"91000"},{"price":"0.00100002500","size":"100000"},{"price":"0.00100005400","size":"1000"},{"price":"0.00102000000","size":"4000"},{"price":"0.00115000000","size":"1000"},{"price":"0.00146000000","size":"7000"},{"price":"0.00150000000","size":"20000"},{"price":"0.00154000000","size":"1000"},{"price":"0.00169000000","size":"10000"},{"price":"0.00179000000","size":"4000"},{"price":"0.00200000000","size":"3000"},{"price":"0.00280000000","size":"225000"},{"price":"0.00300000000","size":"10000"},{"price":"0.00400000000","size":"4000"},{"price":"0.00441000000","size":"22000"},{"price":"0.00500000000","size":"2000"},{"price":"0.00530000000","size":"5283000"},{"price":"0.00600000000","size":"3000"},{"price":"0.00800000000","size":"5000"},{"price":"0.00889000000","size":"450000"},{"price":"0.00900000000","size":"2000"},{"price":"0.00929998000","size":"1000"},{"price":"0.00990000000","size":"1000"},{"price":"0.00999000000","size":"1000"},{"price":"0.01000000000","size":"24000"},{"price":"0.01000005000","size":"1000"},{"price":"0.01050002500","size":"100000"},{"price":"0.01150000000","size":"1000"},{"price":"0.01540000000","size":"1000"},{"price":"0.02000000000","size":"2000"},{"price":"0.02778900000","size":"1000"},{"price":"0.03000000000","size":"3000"},{"price":"0.03100000504","size":"10000"},{"price":"0.05000000000","size":"6000"},{"price":"0.06100000504","size":"10000"},{"price":"0.07700013600","size":"1000"},{"price":"0.09000000000","size":"6000"},{"price":"0.09100000504","size":"10000"},{"price":"0.09900000000","size":"1000"},{"price":"0.09929198000","size":"1000"},{"price":"0.09990000000","size":"1000"},{"price":"0.10000000000","size":"24000"},{"price":"0.10000013300","size":"1000"},{"price":"0.10000016500","size":"1000"},{"price":"0.10100000504","size":"10000"},{"price":"0.15000000000","size":"1000"},{"price":"0.15400000000","size":"12000"},{"price":"0.20000000000","size":"1000"},{"price":"0.30000000000","size":"2000"},{"price":"0.39100000504","size":"10000"},{"price":"0.50000000000","size":"3000"},{"price":"0.72778900000","size":"1000"},{"price":"0.80000000000","size":"1000"},{"price":"0.89924198000","size":"1000"},{"price":"0.90000000000","size":"2000"},{"price":"0.99000000000","size":"1000"},{"price":"0.99900000000","size":"1000"},{"price":"0.99999999900","size":"2000"},{"price":"1.00000000000","size":"493000"},{"price":"1.79224198000","size":"1000"},{"price":"10.00000000000","size":"10000"},{"price":"24.99999999800","size":"1000"},{"price":"25.00000000000","size":"208000"},{"price":"26.00000000000","size":"1000"},{"price":"100.00000000000","size":"10000"},{"price":"400.00000000000","size":"11000"},{"price":"800.00000000000","size":"10000"},{"price":"1000.00000000000","size":"10000"},{"price":"200000.00000000000","size":"1000"},{"price":"999999.00000000000","size":"112000"}],"bid":[{"price":"0.00000000410","size":"454000"},{"price":"0.00000000398","size":"2220000"},{"price":"0.00000000397","size":"7793000"},{"price":"0.00000000396","size":"700000"},{"price":"0.00000000395","size":"51000"},{"price":"0.00000000390","size":"3932000"},{"price":"0.00000000381","size":"3526000"},{"price":"0.00000000380","size":"281000"},{"price":"0.00000000371","size":"6742000"},{"price":"0.00000000370","size":"3960000"},{"price":"0.00000000369","size":"310000"},{"price":"0.00000000368","size":"2000"},{"price":"0.00000000367","size":"501000"},{"price":"0.00000000366","size":"1000"},{"price":"0.00000000365","size":"1000"},{"price":"0.00000000364","size":"1000"},{"price":"0.00000000363","size":"1000"},{"price":"0.00000000362","size":"1000"},{"price":"0.00000000361","size":"1000"},{"price":"0.00000000360","size":"1000"},{"price":"0.00000000359","size":"1000"},{"price":"0.00000000358","size":"1000"},{"price":"0.00000000357","size":"1000"},{"price":"0.00000000356","size":"1000"},{"price":"0.00000000355","size":"2440000"},{"price":"0.00000000354","size":"1000"},{"price":"0.00000000353","size":"1000"},{"price":"0.00000000352","size":"9844000"},{"price":"0.00000000351","size":"1000"},{"price":"0.00000000350","size":"301000"},{"price":"0.00000000349","size":"1000"},{"price":"0.00000000348","size":"1000"},{"price":"0.00000000347","size":"1000"},{"price":"0.00000000346","size":"1000"},{"price":"0.00000000345","size":"1000"},{"price":"0.00000000344","size":"1000"},{"price":"0.00000000343","size":"1000"},{"price":"0.00000000342","size":"1000"},{"price":"0.00000000341","size":"1000"},{"price":"0.00000000340","size":"1000"},{"price":"0.00000000339","size":"1000"},{"price":"0.00000000338","size":"1000"},{"price":"0.00000000337","size":"1000"},{"price":"0.00000000336","size":"1000"},{"price":"0.00000000335","size":"1000"},{"price":"0.00000000334","size":"1000"},{"price":"0.00000000333","size":"1000"},{"price":"0.00000000332","size":"1000"},{"price":"0.00000000331","size":"1000"},{"price":"0.00000000330","size":"1000"},{"price":"0.00000000329","size":"1000"},{"price":"0.00000000328","size":"1000"},{"price":"0.00000000327","size":"3000"},{"price":"0.00000000326","size":"1000"},{"price":"0.00000000325","size":"1000"},{"price":"0.00000000324","size":"1000"},{"price":"0.00000000323","size":"501000"},{"price":"0.00000000322","size":"1000"},{"price":"0.00000000321","size":"100000"},{"price":"0.00000000320","size":"13000"},{"price":"0.00000000319","size":"1000"},{"price":"0.00000000318","size":"1137000"},{"price":"0.00000000317","size":"1000"},{"price":"0.00000000316","size":"1000"},{"price":"0.00000000315","size":"1000"},{"price":"0.00000000314","size":"1000"},{"price":"0.00000000313","size":"1000"},{"price":"0.00000000312","size":"1000"},{"price":"0.00000000311","size":"166000"},{"price":"0.00000000310","size":"1000"},{"price":"0.00000000309","size":"1000"},{"price":"0.00000000308","size":"1000"},{"price":"0.00000000307","size":"12024000"},{"price":"0.00000000306","size":"1000"},{"price":"0.00000000305","size":"1000"},{"price":"0.00000000304","size":"1140000"},{"price":"0.00000000303","size":"1000"},{"price":"0.00000000302","size":"34000"},{"price":"0.00000000301","size":"1000"},{"price":"0.00000000300","size":"1141000"},{"price":"0.00000000299","size":"1000"},{"price":"0.00000000298","size":"1000"},{"price":"0.00000000297","size":"1000"},{"price":"0.00000000296","size":"1000"},{"price":"0.00000000295","size":"1000"},{"price":"0.00000000294","size":"1000"},{"price":"0.00000000293","size":"1000"},{"price":"0.00000000292","size":"1000"},{"price":"0.00000000291","size":"1000"},{"price":"0.00000000290","size":"1000"},{"price":"0.00000000289","size":"1000"},{"price":"0.00000000288","size":"1000"},{"price":"0.00000000287","size":"1000"},{"price":"0.00000000286","size":"1000"},{"price":"0.00000000285","size":"1000"},{"price":"0.00000000284","size":"1000"},{"price":"0.00000000283","size":"1000"},{"price":"0.00000000282","size":"1000"},{"price":"0.00000000281","size":"1000"},{"price":"0.00000000280","size":"13000"},{"price":"0.00000000279","size":"711000"},{"price":"0.00000000278","size":"1000"},{"price":"0.00000000277","size":"1000"},{"price":"0.00000000276","size":"1000"},{"price":"0.00000000275","size":"1000"},{"price":"0.00000000274","size":"1000"},{"price":"0.00000000273","size":"1000"},{"price":"0.00000000272","size":"1000"},{"price":"0.00000000271","size":"1000"},{"price":"0.00000000270","size":"1112000"},{"price":"0.00000000269","size":"1000"},{"price":"0.00000000268","size":"1000"},{"price":"0.00000000267","size":"1000"},{"price":"0.00000000266","size":"1000"},{"price":"0.00000000265","size":"7000"},{"price":"0.00000000264","size":"1000"},{"price":"0.00000000263","size":"1000"},{"price":"0.00000000262","size":"1000"},{"price":"0.00000000261","size":"1000"},{"price":"0.00000000260","size":"1000"},{"price":"0.00000000259","size":"1000"},{"price":"0.00000000258","size":"1000"},{"price":"0.00000000257","size":"1000"},{"price":"0.00000000256","size":"392000"},{"price":"0.00000000255","size":"1000"},{"price":"0.00000000254","size":"1000"},{"price":"0.00000000253","size":"1000"},{"price":"0.00000000252","size":"1000"},{"price":"0.00000000251","size":"1000"},{"price":"0.00000000250","size":"19000"},{"price":"0.00000000249","size":"1000"},{"price":"0.00000000248","size":"1000"},{"price":"0.00000000247","size":"1000"},{"price":"0.00000000246","size":"1000"},{"price":"0.00000000245","size":"1000"},{"price":"0.00000000244","size":"1000"},{"price":"0.00000000243","size":"1000"},{"price":"0.00000000242","size":"1000"},{"price":"0.00000000241","size":"1000"},{"price":"0.00000000240","size":"2000"},{"price":"0.00000000239","size":"1000"},{"price":"0.00000000238","size":"1000"},{"price":"0.00000000237","size":"1000"},{"price":"0.00000000236","size":"501000"},{"price":"0.00000000235","size":"695000"},{"price":"0.00000000234","size":"1000"},{"price":"0.00000000233","size":"1000"},{"price":"0.00000000232","size":"1000"},{"price":"0.00000000231","size":"1000"},{"price":"0.00000000230","size":"1000"},{"price":"0.00000000229","size":"1000"},{"price":"0.00000000228","size":"11651000"},{"price":"0.00000000227","size":"1000"},{"price":"0.00000000226","size":"2000"},{"price":"0.00000000225","size":"1000"},{"price":"0.00000000224","size":"1000"},{"price":"0.00000000223","size":"1000"},{"price":"0.00000000222","size":"1000"},{"price":"0.00000000221","size":"1000"},{"price":"0.00000000220","size":"19000"},{"price":"0.00000000219","size":"1000"},{"price":"0.00000000218","size":"19373000"},{"price":"0.00000000217","size":"2000"},{"price":"0.00000000216","size":"1000"},{"price":"0.00000000215","size":"1000"},{"price":"0.00000000214","size":"2000"},{"price":"0.00000000213","size":"1000"},{"price":"0.00000000212","size":"1000"},{"price":"0.00000000211","size":"1000"},{"price":"0.00000000210","size":"9000"},{"price":"0.00000000209","size":"1000"},{"price":"0.00000000208","size":"292000"},{"price":"0.00000000207","size":"1000"},{"price":"0.00000000206","size":"1000"},{"price":"0.00000000205","size":"63000"},{"price":"0.00000000204","size":"105000"},{"price":"0.00000000203","size":"38000"},{"price":"0.00000000202","size":"1000"},{"price":"0.00000000201","size":"2000"},{"price":"0.00000000200","size":"5021000"},{"price":"0.00000000199","size":"1000"},{"price":"0.00000000198","size":"1000"},{"price":"0.00000000197","size":"1000"},{"price":"0.00000000196","size":"1000"},{"price":"0.00000000195","size":"4000"},{"price":"0.00000000194","size":"1000"},{"price":"0.00000000193","size":"1000"},{"price":"0.00000000192","size":"1000"},{"price":"0.00000000191","size":"1000"},{"price":"0.00000000190","size":"20000"},{"price":"0.00000000189","size":"1000"},{"price":"0.00000000188","size":"1000"},{"price":"0.00000000187","size":"1000"},{"price":"0.00000000186","size":"1000"},{"price":"0.00000000185","size":"1000"},{"price":"0.00000000184","size":"1000"},{"price":"0.00000000183","size":"1000"},{"price":"0.00000000182","size":"1000"},{"price":"0.00000000181","size":"1000"},{"price":"0.00000000180","size":"11000"},{"price":"0.00000000179","size":"1000"},{"price":"0.00000000178","size":"1000"},{"price":"0.00000000177","size":"1000"},{"price":"0.00000000176","size":"1000"},{"price":"0.00000000175","size":"1000"},{"price":"0.00000000174","size":"1000"},{"price":"0.00000000173","size":"1000"},{"price":"0.00000000172","size":"1000"},{"price":"0.00000000171","size":"1000"},{"price":"0.00000000170","size":"11000"},{"price":"0.00000000169","size":"1000"},{"price":"0.00000000168","size":"1000"},{"price":"0.00000000167","size":"1000"},{"price":"0.00000000166","size":"1000"},{"price":"0.00000000165","size":"70000"},{"price":"0.00000000164","size":"1000"},{"price":"0.00000000163","size":"1000"},{"price":"0.00000000162","size":"2000"},{"price":"0.00000000161","size":"1000"},{"price":"0.00000000160","size":"19000"},{"price":"0.00000000159","size":"1000"},{"price":"0.00000000158","size":"1000"},{"price":"0.00000000157","size":"1000"},{"price":"0.00000000156","size":"392000"},{"price":"0.00000000155","size":"1000"},{"price":"0.00000000154","size":"1000"},{"price":"0.00000000153","size":"1000"},{"price":"0.00000000152","size":"1000"},{"price":"0.00000000151","size":"1000"},{"price":"0.00000000150","size":"60000"},{"price":"0.00000000148","size":"2257000"},{"price":"0.00000000140","size":"218000"},{"price":"0.00000000139","size":"60000"},{"price":"0.00000000138","size":"10000"},{"price":"0.00000000137","size":"30000"},{"price":"0.00000000130","size":"27000"},{"price":"0.00000000128","size":"3000"},{"price":"0.00000000127","size":"45000"},{"price":"0.00000000125","size":"15000"},{"price":"0.00000000124","size":"3000"},{"price":"0.00000000120","size":"18000"},{"price":"0.00000000115","size":"199000"},{"price":"0.00000000112","size":"60000"},{"price":"0.00000000111","size":"1000"},{"price":"0.00000000110","size":"14000"},{"price":"0.00000000106","size":"57000"},{"price":"0.00000000105","size":"12000"},{"price":"0.00000000102","size":"602000"},{"price":"0.00000000100","size":"599000"},{"price":"0.00000000099","size":"1000"},{"price":"0.00000000098","size":"1016000"},{"price":"0.00000000095","size":"13000"},{"price":"0.00000000094","size":"200000"},{"price":"0.00000000090","size":"14000"},{"price":"0.00000000089","size":"1000"},{"price":"0.00000000085","size":"16000"},{"price":"0.00000000082","size":"220000"},{"price":"0.00000000080","size":"20000"},{"price":"0.00000000076","size":"27000"},{"price":"0.00000000075","size":"40000"},{"price":"0.00000000073","size":"931000"},{"price":"0.00000000070","size":"134000"},{"price":"0.00000000067","size":"19000"},{"price":"0.00000000066","size":"122000"},{"price":"0.00000000065","size":"23000"},{"price":"0.00000000063","size":"3000"},{"price":"0.00000000062","size":"19000"},{"price":"0.00000000061","size":"15000"},{"price":"0.00000000060","size":"522000"},{"price":"0.00000000058","size":"3776000"},{"price":"0.00000000057","size":"10000"},{"price":"0.00000000056","size":"18000"},{"price":"0.00000000055","size":"147000"},{"price":"0.00000000054","size":"19000"},{"price":"0.00000000053","size":"344000"},{"price":"0.00000000052","size":"20000"},{"price":"0.00000000051","size":"267000"},{"price":"0.00000000050","size":"4116000"},{"price":"0.00000000048","size":"21000"},{"price":"0.00000000047","size":"20000"},{"price":"0.00000000046","size":"22000"},{"price":"0.00000000045","size":"52000"},{"price":"0.00000000044","size":"22724000"},{"price":"0.00000000043","size":"24000"},{"price":"0.00000000042","size":"82000"},{"price":"0.00000000041","size":"25000"},{"price":"0.00000000040","size":"551000"},{"price":"0.00000000038","size":"427000"},{"price":"0.00000000037","size":"30000"},{"price":"0.00000000036","size":"28000"},{"price":"0.00000000035","size":"79000"},{"price":"0.00000000033","size":"1031000"},{"price":"0.00000000032","size":"32000"},{"price":"0.00000000030","size":"2681000"},{"price":"0.00000000029","size":"276000"},{"price":"0.00000000028","size":"37000"},{"price":"0.00000000027","size":"88000"},{"price":"0.00000000026","size":"40000"},{"price":"0.00000000025","size":"81000"},{"price":"0.00000000023","size":"156000"},{"price":"0.00000000020","size":"8552000"},{"price":"0.00000000017","size":"208000"},{"price":"0.00000000016","size":"172000"},{"price":"0.00000000015","size":"72000"},{"price":"0.00000000014","size":"22000"},{"price":"0.00000000013","size":"41000"},{"price":"0.00000000012","size":"2366000"},{"price":"0.00000000011","size":"621000"},{"price":"0.00000000010","size":"123000"},{"price":"0.00000000009","size":"121000"},{"price":"0.00000000008","size":"5677000"},{"price":"0.00000000007","size":"121000"},{"price":"0.00000000006","size":"142000"},{"price":"0.00000000005","size":"2200000"},{"price":"0.00000000004","size":"1500000"},{"price":"0.00000000003","size":"2067000"},{"price":"0.00000000002","size":"6114000"},{"price":"0.00000000001","size":"15843000"}],"sequence":1757663,"timestamp":"2021-04-17T16:46:12.146Z","symbol":"BANCABTC"}}
1618677975.051208: {"jsonrpc":"2.0","method":"updateOrderbook","params":{"ask":[{"price":"0.000026972","size":"562.4"},{"price":"0.000026973","size":"0"},{"price":"0.000030785","size":"326.6"}],"bid":[],"sequence":1389786,"timestamp":"2021-04-17T16:46:14.486Z","symbol":"HEDGBTC"}}
1618677975.051262: {"jsonrpc":"2.0","method":"updateOrderbook","params":{"ask":[{"price":"0.00011971","size":"1845.7"},{"price":"0.00011974","size":"2394.4"},{"price":"0.00012007","size":"0"},{"price":"0.00012062","size":"0"}],"bid":[],"sequence":19113810,"timestamp":"2021-04-17T16:46:14.485Z","symbol":"XTZBTC"}}
1618677975.051307: {"jsonrpc":"2.0","method":"updateOrderbook","params":{"ask":[{"price":"1.5338900","size":"296"}],"bid":[],"sequence":11642059,"timestamp":"2021-04-17T16:46:14.495Z","symbol":"MANAUSD"}}
1618677975.051327: {"jsonrpc":"2.0","method":"updateOrderbook","params":{"ask":[{"price":"0.000026971","size":"91.1"},{"price":"0.000030785","size":"0"}],"bid":[],"sequence":1389787,"timestamp":"2021-04-17T16:46:14.591Z","symbol":"HEDGBTC"}}
1618677975.051353: {"jsonrpc":"2.0","method":"updateOrderbook","params":{"ask":[{"price":"0.00078579","size":"0"}],"bid":[],"sequence":10038613,"timestamp":"2021-04-17T16:46:14.626Z","symbol":"SUNBTC"}}
1618677975.051414: {"jsonrpc":"2.0","method":"updateOrderbook","params":{"ask":[{"price":"0.00011953","size":"94.0"},{"price":"0.00011954","size":"0"},{"price":"0.00011958","size":"528.8"},{"price":"0.00011963","size":"244.5"}],"bid":[],"sequence":19113811,"timestamp":"2021-04-17T16:46:14.649Z","symbol":"XTZBTC"}}
1618677975.051451: {"jsonrpc":"2.0","method":"updateOrderbook","params":{"ask":[],"bid":[{"price":"0.000039644","size":"0"},{"price":"0.000039629","size":"0"},{"price":"0.000039623","size":"441.5"},{"price":"0.000039590","size":"1262.0"}],"sequence":13026882,"timestamp":"2021-04-17T16:46:14.742Z","symbol":"STORJBTC"}}
1618677975.0515141: {"jsonrpc":"2.0","method":"updateOrderbook","params":{"ask":[{"price":"0.00011942","size":"538.4"},{"price":"0.00011949","size":"0"},{"price":"0.00011951","size":"498.1"},{"price":"0.00011952","size":"942.3"},{"price":"0.00011956","size":"183.3"},{"price":"0.00011957","size":"728.3"},{"price":"0.00011958","size":"345.5"},{"price":"0.00011962","size":"2600.3"},{"price":"0.00011991","size":"3675.0"},{"price":"0.00012066","size":"4799.2"},{"price":"0.00012076","size":"0"},{"price":"0.00012093","size":"0"}],"bid":[],"sequence":19113812,"timestamp":"2021-04-17T16:46:14.749Z","symbol":"XTZBTC"}}
1618677975.051584: {"jsonrpc":"2.0","method":"updateOrderbook","params":{"ask":[{"price":"0.000039957","size":"784.5"},{"price":"0.000039973","size":"5901.1"},{"price":"0.000040213","size":"0"},{"price":"0.000040239","size":"9299.9"},{"price":"0.000040447","size":"0"},{"price":"0.000040487","size":"13527.3"}],"bid":[{"price":"0.000039644","size":"441.5"},{"price":"0.000039629","size":"1262.0"},{"price":"0.000039623","size":"0"},{"price":"0.000039590","size":"0"}],"sequence":13026883,"timestamp":"2021-04-17T16:46:14.838Z","symbol":"STORJBTC"}}
1618677975.0516732: {"jsonrpc":"2.0","method":"updateOrderbook","params":{"ask":[{"price":"0.00078479","size":"0.11"}],"bid":[],"sequence":10038614,"timestamp":"2021-04-17T16:46:14.797Z","symbol":"SUNBTC"}}
1618677975.051714: {"jsonrpc":"2.0","method":"updateOrderbook","params":{"ask":[{"price":"0.00011956","size":"0"},{"price":"0.00011957","size":"911.6"}],"bid":[],"sequence":19113813,"timestamp":"2021-04-17T16:46:14.791Z","symbol":"XTZBTC"}}
1618677975.051739: {"jsonrpc":"2.0","method":"updateOrderbook","params":{"ask":[{"price":"0.000026972","size":"0"}],"bid":[],"sequence":1389788,"timestamp":"2021-04-17T16:46:14.930Z","symbol":"HEDGBTC"}}
1618677975.051763: {"jsonrpc":"2.0","method":"updateOrderbook","params":{"ask":[{"price":"0.000039822","size":"261.3"},{"price":"0.000039827","size":"0"},{"price":"0.000039837","size":"1150.2"},{"price":"0.000039843","size":"0"}],"bid":[{"price":"0.000039661","size":"441.5"},{"price":"0.000039649","size":"1262.0"},{"price":"0.000039644","size":"0"},{"price":"0.000039629","size":"0"}],"sequence":13026884,"timestamp":"2021-04-17T16:46:14.926Z","symbol":"STORJBTC"}}
1618677975.051842: {"jsonrpc":"2.0","method":"updateOrderbook","params":{"ask":[{"price":"0.00011942","size":"1440.1"},{"price":"0.00011951","size":"102.6"},{"price":"0.00011952","size":"1164.4"},{"price":"0.00011954","size":"565.8"},{"price":"0.00011957","size":"0"},{"price":"0.00011958","size":"528.8"},{"price":"0.00011962","size":"2034.5"}],"bid":[{"price":"0.00011126","size":"0"},{"price":"0.00010669","size":"380.0"}],"sequence":19113814,"timestamp":"2021-04-17T16:46:14.875Z","symbol":"XTZBTC"}}
1618677975.085966: {"jsonrpc":"2.0","method":"updateOrderbook","params":{"ask":[{"price":"0.000026970","size":"562.4"},{"price":"0.000026971","size":"0"},{"price":"0.000030785","size":"326.6"}],"bid":[],"sequence":1389789,"timestamp":"2021-04-17T16:46:15.015Z","symbol":"HEDGBTC"}}
1618677975.102923: {"jsonrpc":"2.0","method":"updateOrderbook","params":{"ask":[],"bid":[{"price":"0.00016239","size":"10.00"},{"price":"0.00016223","size":"0"}],"sequence":10038615,"timestamp":"2021-04-17T16:46:15.008Z","symbol":"SUNBTC"}}
1618677975.1030788: {"jsonrpc":"2.0","method":"updateOrderbook","params":{"ask":[{"price":"0.00011942","size":"2604.5"},{"price":"0.00011946","size":"565.8"},{"price":"0.00011952","size":"0"},{"price":"0.00011954","size":"0"},{"price":"0.00012091","size":"8349.8"},{"price":"0.00012217","size":"0"},{"price":"0.00012266","size":"8300.3"},{"price":"0.00012742","size":"0"}],"bid":[],"sequence":19113815,"timestamp":"2021-04-17T16:46:15.006Z","symbol":"XTZBTC"}}
1618677975.1995652: {"jsonrpc":"2.0","method":"updateOrderbook","params":{"ask":[{"price":"0.000026969","size":"91.1"},{"price":"0.000030785","size":"0"}],"bid":[],"sequence":1389790,"timestamp":"2021-04-17T16:46:15.080Z","symbol":"HEDGBTC"}}
1618677975.210494: {"jsonrpc":"2.0","method":"updateOrderbook","params":{"ask":[{"price":"0.00011978","size":"1253.2"},{"price":"0.00012018","size":"1550.2"}],"bid":[],"sequence":19113816,"timestamp":"2021-04-17T16:46:15.131Z","symbol":"XTZBTC"}}
1618677975.301422: {"jsonrpc":"2.0","method":"updateOrderbook","params":{"ask":[{"price":"0.00000000420","size":"811000"},{"price":"0.00000000450","size":"2001000"}],"bid":[],"sequence":1757664,"timestamp":"2021-04-17T16:46:15.196Z","symbol":"BANCABTC"}}
1618677975.301573: {"jsonrpc":"2.0","method":"updateOrderbook","params":{"ask":[{"price":"0.000039837","size":"0"},{"price":"0.000039875","size":"1150.2"},{"price":"0.000039887","size":"0"},{"price":"0.000039905","size":"2795.3"},{"price":"0.000039923","size":"0"},{"price":"0.000039940","size":"3812.3"},{"price":"0.000040487","size":"0"},{"price":"0.000040524","size":"13527.3"}],"bid":[],"sequence":13026885,"timestamp":"2021-04-17T16:46:15.178Z","symbol":"STORJBTC"}}
1618677975.313362: {"jsonrpc":"2.0","method":"updateOrderbook","params":{"ask":[{"price":"1.5333498","size":"296"},{"price":"1.5338900","size":"0"}],"bid":[],"sequence":11642060,"timestamp":"2021-04-17T16:46:15.231Z","symbol":"MANAUSD"}}
1618677975.389368: {"jsonrpc":"2.0","method":"updateOrderbook","params":{"ask":[],"bid":[{"price":"0.00000000369","size":"2749000"},{"price":"0.00000000355","size":"1000"},{"price":"0.00000000237","size":"11651000"},{"price":"0.00000000228","size":"1000"}],"sequence":1757665,"timestamp":"2021-04-17T16:46:15.269Z","symbol":"BANCABTC"}}
1618677975.404958: {"jsonrpc":"2.0","method":"updateOrderbook","params":{"ask":[{"price":"0.00013119","size":"12500.4"},{"price":"0.00013441","size":"0"},{"price":"0.00013765","size":"17824.4"},{"price":"0.00014339","size":"0"}],"bid":[],"sequence":19113817,"timestamp":"2021-04-17T16:46:15.323Z","symbol":"XTZBTC"}}
1618677975.50611: {"jsonrpc":"2.0","method":"updateOrderbook","params":{"ask":[{"price":"0.00133377","size":"0"},{"price":"0.00133518","size":"10.00"}],"bid":[],"sequence":10038616,"timestamp":"2021-04-17T16:46:15.419Z","symbol":"SUNBTC"}}
1618677975.506263: {"jsonrpc":"2.0","method":"updateOrderbook","params":{"ask":[{"price":"0.00011942","size":"1440.1"},{"price":"0.00011946","size":"0"},{"price":"0.00011952","size":"1164.4"},{"price":"0.00011954","size":"565.8"}],"bid":[],"sequence":19113818,"timestamp":"2021-04-17T16:46:15.361Z","symbol":"XTZBTC"}}
1618677975.5114172: {"jsonrpc":"2.0","method":"updateOrderbook","params":{"ask":[{"price":"1.5333498","size":"0"},{"price":"1.5334740","size":"296"}],"bid":[],"sequence":11642061,"timestamp":"2021-04-17T16:46:15.446Z","symbol":"MANAUSD"}}
1618677975.5929449: {"jsonrpc":"2.0","method":"updateOrderbook","params":{"ask":[{"price":"0.000026968","size":"562.4"},{"price":"0.000026970","size":"0"}],"bid":[],"sequence":1389791,"timestamp":"2021-04-17T16:46:15.537Z","symbol":"HEDGBTC"}}
1618677975.607102: {"jsonrpc":"2.0","method":"updateOrderbook","params":{"ask":[{"price":"0.00011942","size":"2604.5"},{"price":"0.00011946","size":"565.8"},{"price":"0.00011952","size":"0"},{"price":"0.00011954","size":"0"},{"price":"0.00011978","size":"0"},{"price":"0.00012006","size":"1253.2"}],"bid":[],"sequence":19113819,"timestamp":"2021-04-17T16:46:15.523Z","symbol":"XTZBTC"}}
1618677975.6902468: {"jsonrpc":"2.0","method":"updateOrderbook","params":{"ask":[{"price":"0.000026967","size":"91.1"},{"price":"0.000026969","size":"0"}],"bid":[],"sequence":1389792,"timestamp":"2021-04-17T16:46:15.600Z","symbol":"HEDGBTC"}}
1618677975.707447: {"jsonrpc":"2.0","method":"updateOrderbook","params":{"ask":[{"price":"0.00011942","size":"1440.1"},{"price":"0.00011946","size":"0"},{"price":"0.00011952","size":"1164.4"},{"price":"0.00011953","size":"659.8"},{"price":"0.00012266","size":"0"},{"price":"0.00012278","size":"8300.3"},{"price":"0.00013119","size":"0"},{"price":"0.00013134","size":"12500.4"},{"price":"0.00013765","size":"0"},{"price":"0.00013781","size":"17824.4"}],"bid":[],"sequence":19113820,"timestamp":"2021-04-17T16:46:15.649Z","symbol":"XTZBTC"}}
1618677975.817936: {"jsonrpc":"2.0","method":"updateOrderbook","params":{"ask":[{"price":"0.00011968","size":"0"},{"price":"0.00011971","size":"0"},{"price":"0.00011974","size":"0"},{"price":"0.00011980","size":"1599.8"},{"price":"0.00011991","size":"0"},{"price":"0.00011993","size":"1845.7"},{"price":"0.00012057","size":"5319.7"},{"price":"0.00012066","size":"0"},{"price":"0.00012076","size":"3675.0"},{"price":"0.00012091","size":"2279.3"},{"price":"0.00012094","size":"19936.5"},{"price":"0.00012214","size":"6070.5"},{"price":"0.00012278","size":"0"},{"price":"0.00012735","size":"8300.3"},{"price":"0.00013134","size":"0"},{"price":"0.00013441","size":"12500.4"},{"price":"0.00013781","size":"0"},{"price":"0.00014333","size":"18324.4"}],"bid":[],"sequence":19113821,"timestamp":"2021-04-17T16:46:15.673Z","symbol":"XTZBTC"}}
1618677975.818239: {"jsonrpc":"2.0","method":"updateOrderbook","params":{"ask":[{"price":"0.00000119664","size":"0"},{"price":"0.00000119759","size":"592740"},{"price":"0.00000120369","size":"703720"},{"price":"0.00000120370","size":"0"},{"price":"0.00000121326","size":"0"},{"price":"0.00000121400","size":"922200"},{"price":"0.00000123804","size":"0"},{"price":"0.00000124056","size":"1107430"},{"price":"0.00000126813","size":"0"},{"price":"0.00000127069","size":"2245050"},{"price":"0.00000129199","size":"0"},{"price":"0.00000129330","size":"1868770"},{"price":"0.00000131551","size":"0"},{"price":"0.00000131735","size":"3920530"},{"price":"0.00000135084","size":"0"},{"price":"0.00000135239","size":"4623140"},{"price":"0.00000138821","size":"0"},{"price":"0.00000139048","size":"5277220"},{"price":"0.00000143469","size":"0"},{"price":"0.00000143663","size":"8627820"},{"price":"0.00000150728","size":"0"},{"price":"0.00000150945","size":"7719140"},{"price":"0.00000161522","size":"0"},{"price":"0.00000161827","size":"12549470"}],"bid":[],"sequence":5061552,"timestamp":"2021-04-17T16:46:15.744Z","symbol":"CELRBTC"}}
1618677975.903788: {"jsonrpc":"2.0","method":"updateOrderbook","params":{"ask":[],"bid":[{"price":"0.000039661","size":"0"},{"price":"0.000039649","size":"0"},{"price":"0.000039644","size":"441.5"},{"price":"0.000039629","size":"1262.0"}],"sequence":13026886,"timestamp":"2021-04-17T16:46:15.831Z","symbol":"STORJBTC"}}
1618677975.90407: {"jsonrpc":"2.0","method":"updateOrderbook","params":{"ask":[{"price":"0.00011942","size":"2604.5"},{"price":"0.00011946","size":"565.8"},{"price":"0.00011952","size":"0"},{"price":"0.00011953","size":"94.0"}],"bid":[],"sequence":19113822,"timestamp":"2021-04-17T16:46:15.842Z","symbol":"XTZBTC"}}
1618677976.00212: {"jsonrpc":"2.0","method":"updateOrderbook","params":{"ask":[{"price":"0.00011962","size":"3314.1"},{"price":"0.00011969","size":"714.5"}],"bid":[],"sequence":19113823,"timestamp":"2021-04-17T16:46:15.880Z","symbol":"XTZBTC"}}
1618677976.090791: {"jsonrpc":"2.0","method":"updateOrderbook","params":{"ask":[{"price":"0.000039766","size":"0"},{"price":"0.000039772","size":"431.7"},{"price":"0.000039800","size":"0"},{"price":"0.000039810","size":"1829.4"},{"price":"0.000039822","size":"0"},{"price":"0.000039831","size":"261.3"},{"price":"0.000039846","size":"0"},{"price":"0.000039855","size":"2594.7"},{"price":"0.000039908","size":"0"},{"price":"0.000039912","size":"3633.3"},{"price":"0.000039945","size":"0"},{"price":"0.000039950","size":"3785.4"},{"price":"0.000040493","size":"13527.3"},{"price":"0.000040524","size":"0"}],"bid":[],"sequence":13026887,"timestamp":"2021-04-17T16:46:16.033Z","symbol":"STORJBTC"}}
1618677976.1071842: {"jsonrpc":"2.0","method":"updateOrderbook","params":{"ask":[{"price":"1.5334740","size":"0"},{"price":"1.5345936","size":"296"}],"bid":[],"sequence":11642062,"timestamp":"2021-04-17T16:46:16.028Z","symbol":"MANAUSD"}}
1618677976.206262: {"jsonrpc":"2.0","method":"updateOrderbook","params":{"ask":[{"price":"0.00012084","size":"7381.5"},{"price":"0.00012150","size":"0"}],"bid":[],"sequence":19113824,"timestamp":"2021-04-17T16:46:16.127Z","symbol":"XTZBTC"}}
1618677976.215317: {"jsonrpc":"2.0","method":"updateOrderbook","params":{"ask":[{"price":"1.5324392","size":"0"},{"price":"1.5337035","size":"652"},{"price":"1.5345936","size":"0"},{"price":"1.5352736","size":"295"},{"price":"1.5425201","size":"355"}],"bid":[],"sequence":11642063,"timestamp":"2021-04-17T16:46:16.066Z","symbol":"MANAUSD"}}
1618677976.2870479: {"jsonrpc":"2.0","method":"updateOrderbook","params":{"ask":[{"price":"0.000026966","size":"562.4"},{"price":"0.000026968","size":"0"}],"bid":[],"sequence":1389793,"timestamp":"2021-04-17T16:46:16.238Z","symbol":"HEDGBTC"}}
1618677976.290849: {"jsonrpc":"2.0","method":"updateOrderbook","params":{"ask":[{"price":"0.000039973","size":"599.0"},{"price":"0.000039974","size":"5302.1"},{"price":"0.000040239","size":"0"},{"price":"0.000040248","size":"9299.9"},{"price":"0.000040493","size":"0"},{"price":"0.000040513","size":"13527.3"}],"bid":[{"price":"0.000032208","size":"22105.7"},{"price":"0.000032014","size":"0"}],"sequence":13026888,"timestamp":"2021-04-17T16:46:16.236Z","symbol":"STORJBTC"}}
1618677976.305897: {"jsonrpc":"2.0","method":"updateOrderbook","params":{"ask":[],"bid":[{"price":"0.00010787","size":"0"}],"sequence":19113825,"timestamp":"2021-04-17T16:46:16.226Z","symbol":"XTZBTC"}}
1618677976.387294: {"jsonrpc":"2.0","method":"updateOrderbook","params":{"ask":[{"price":"0.000026965","size":"91.1"},{"price":"0.000026967","size":"0"}],"bid":[],"sequence":1389794,"timestamp":"2021-04-17T16:46:16.279Z","symbol":"HEDGBTC"}}
1618677976.398033: {"jsonrpc":"2.0","method":"updateOrderbook","params":{"ask":[{"price":"0.00078479","size":"0"}],"bid":[],"sequence":10038617,"timestamp":"2021-04-17T16:46:16.271Z","symbol":"SUNBTC"}}
1618677976.398263: {"jsonrpc":"2.0","method":"updateOrderbook","params":{"ask":[{"price":"0.00011966","size":"1567.8"},{"price":"0.00011980","size":"32.0"}],"bid":[],"sequence":19113826,"timestamp":"2021-04-17T16:46:16.312Z","symbol":"XTZBTC"}}
1618677976.495818: {"jsonrpc":"2.0","method":"updateOrderbook","params":{"ask":[],"bid":[{"price":"0.00021345","size":"0"},{"price":"0.00019312","size":"5.79"}],"sequence":10038618,"timestamp":"2021-04-17T16:46:16.410Z","symbol":"SUNBTC"}}
1618677976.5007439: {"jsonrpc":"2.0","method":"updateOrderbook","params":{"ask":[{"price":"0.00011978","size":"1720.5"},{"price":"0.00011982","size":"7549.3"},{"price":"0.00011984","size":"0"},{"price":"0.00011990","size":"2100.1"},{"price":"0.00011992","size":"0"},{"price":"0.00011996","size":"3485.4"},{"price":"0.00011998","size":"0"},{"price":"0.00012005","size":"3537.9"},{"price":"0.00012010","size":"0"}],"bid":[{"price":"0.00011112","size":"380.0"},{"price":"0.00010685","size":"0"},{"price":"0.00010669","size":"0"}],"sequence":19113827,"timestamp":"2021-04-17T16:46:16.445Z","symbol":"XTZBTC"}}
1618677976.507159: {"jsonrpc":"2.0","method":"updateOrderbook","params":{"ask":[{"price":"1.5536150","size":"0"},{"price":"1.5540677","size":"36573"}],"bid":[],"sequence":11642064,"timestamp":"2021-04-17T16:46:16.410Z","symbol":"MANAUSD"}}
1618677976.605796: {"jsonrpc":"2.0","method":"updateOrderbook","params":{"ask":[{"price":"0.00078579","size":"0.11"}],"bid":[],"sequence":10038619,"timestamp":"2021-04-17T16:46:16.459Z","symbol":"SUNBTC"}}
1618677976.6116312: {"jsonrpc":"2.0","method":"updateOrderbook","params":{"ask":[{"price":"0.00011942","size":"1440.1"},{"price":"0.00011946","size":"0"},{"price":"0.00011952","size":"1164.4"},{"price":"0.00011953","size":"659.8"},{"price":"0.00012084","size":"3288.1"},{"price":"0.00012136","size":"4093.4"}],"bid":[],"sequence":19113828,"timestamp":"2021-04-17T16:46:16.546Z","symbol":"XTZBTC"}}
1618677976.696213: {"jsonrpc":"2.0","method":"updateOrderbook","params":{"ask":[],"bid":[{"price":"0.000023966","size":"8.2"}],"sequence":1389795,"timestamp":"2021-04-17T16:46:16.635Z","symbol":"HEDGBTC"}}
1618677976.708641: {"jsonrpc":"2.0","method":"updateOrderbook","params":{"ask":[{"price":"0.00011942","size":"2604.5"},{"price":"0.00011946","size":"565.8"},{"price":"0.00011952","size":"0"},{"price":"0.00011953","size":"94.0"},{"price":"0.00011969","size":"2560.2"},{"price":"0.00011972","size":"2394.4"},{"price":"0.00011993","size":"0"},{"price":"0.00012057","size":"2925.3"}],"bid":[],"sequence":19113829,"timestamp":"2021-04-17T16:46:16.618Z","symbol":"XTZBTC"}}
1618677976.716608: {"jsonrpc":"2.0","method":"updateOrderbook","params":{"ask":[{"price":"0.2199817","size":"30.52"},{"price":"0.2201635","size":"0"}],"bid":[],"sequence":4920723,"timestamp":"2021-04-17T16:46:16.595Z","symbol":"BNBETH"}}
1618677976.7879941: {"jsonrpc":"2.0","method":"updateOrderbook","params":{"ask":[{"price":"0.000026966","size":"0"}],"bid":[],"sequence":1389796,"timestamp":"2021-04-17T16:46:16.679Z","symbol":"HEDGBTC"}}
1618677976.802643: {"jsonrpc":"2.0","method":"updateOrderbook","params":{"ask":[{"price":"0.000039823","size":"1150.2"},{"price":"0.000039875","size":"0"}],"bid":[],"sequence":13026889,"timestamp":"2021-04-17T16:46:16.689Z","symbol":"STORJBTC"}}
1618677976.8113332: {"jsonrpc":"2.0","method":"updateOrderbook","params":{"ask":[{"price":"0.00011951","size":"0"},{"price":"0.00011955","size":"0"},{"price":"0.00011959","size":"102.6"},{"price":"0.00011961","size":"0"},{"price":"0.00011962","size":"3692.9"},{"price":"0.00011964","size":"920.9"},{"price":"0.00011972","size":"0"},{"price":"0.00011978","size":"4114.9"}],"bid":[{"price":"0.00010535","size":"0"}],"sequence":19113830,"timestamp":"2021-04-17T16:46:16.685Z","symbol":"XTZBTC"}}
1618677976.8868768: {"jsonrpc":"2.0","method":"updateOrderbook","params":{"ask":[{"price":"0.0000011774","size":"49"},{"price":"0.0000011775","size":"0"}],"bid":[],"sequence":403550,"timestamp":"2021-04-17T16:46:16.833Z","symbol":"ACDBTC"}}
1618677976.887038: {"jsonrpc":"2.0","method":"updateOrderbook","params":{"ask":[{"price":"0.000026964","size":"562.4"},{"price":"0.000026965","size":"0"},{"price":"0.000030785","size":"326.6"}],"bid":[],"sequence":1389797,"timestamp":"2021-04-17T16:46:16.788Z","symbol":"HEDGBTC"}}
1618677976.911288: {"jsonrpc":"2.0","method":"updateOrderbook","params":{"ask":[{"price":"0.00011988","size":"380.0"},{"price":"0.00011995","size":"0"}],"bid":[],"sequence":19113831,"timestamp":"2021-04-17T16:46:16.842Z","symbol":"XTZBTC"}}
1618677976.9142232: {"jsonrpc":"2.0","method":"updateOrderbook","params":{"ask":[{"price":"0.00000123905","size":"1107430"},{"price":"0.00000124056","size":"0"},{"price":"0.00000126913","size":"2245050"},{"price":"0.00000127069","size":"0"}],"bid":[],"sequence":5061553,"timestamp":"2021-04-17T16:46:16.770Z","symbol":"CELRBTC"}}
1618677976.9876149: {"jsonrpc":"2.0","method":"updateOrderbook","params":{"ask":[{"price":"0.000026963","size":"91.1"},{"price":"0.000030785","size":"0"}],"bid":[],"sequence":1389798,"timestamp":"2021-04-17T16:46:16.875Z","symbol":"HEDGBTC"}}
1618677976.997109: {"jsonrpc":"2.0","method":"updateOrderbook","params":{"ask":[{"price":"0.000039802","size":"1829.4"},{"price":"0.000039810","size":"0"},{"price":"0.000039847","size":"2594.7"},{"price":"0.000039855","size":"0"},{"price":"0.000039945","size":"3785.4"},{"price":"0.000039950","size":"0"}],"bid":[],"sequence":13026890,"timestamp":"2021-04-17T16:46:16.941Z","symbol":"STORJBTC"}}
1618677977.015363: {"jsonrpc":"2.0","method":"updateOrderbook","params":{"ask":[{"price":"0.00011942","size":"1876.2"},{"price":"0.00011946","size":"0"},{"price":"0.00011949","size":"728.3"},{"price":"0.00011952","size":"565.8"},{"price":"0.00012009","size":"3675.0"},{"price":"0.00012021","size":"4416.4"},{"price":"0.00012026","size":"0"},{"price":"0.00012076","size":"0"},{"price":"0.00012079","size":"4799.2"},{"price":"0.00012094","size":"15137.3"},{"price":"0.00012173","size":"12140.3"},{"price":"0.00012187","size":"0"}],"bid":[{"price":"0.00010342","size":"0"}],"sequence":19113832,"timestamp":"2021-04-17T16:46:16.914Z","symbol":"XTZBTC"}}
1618677977.020639: {"jsonrpc":"2.0","method":"updateOrderbook","params":{"ask":[{"price":"0.2221199","size":"14.00"},{"price":"0.2222420","size":"0"},{"price":"0.2224059","size":"7.00"},{"price":"0.2225952","size":"0"}],"bid":[],"sequence":4920724,"timestamp":"2021-04-17T16:46:16.927Z","symbol":"BNBETH"}}
1618677977.1046212: {"jsonrpc":"2.0","method":"updateOrderbook","params":{"ask":[{"price":"0.000039802","size":"2090.7"},{"price":"0.000039831","size":"0"}],"bid":[],"sequence":13026891,"timestamp":"2021-04-17T16:46:17.046Z","symbol":"STORJBTC"}}
1618677977.126494: {"jsonrpc":"2.0","method":"updateOrderbook","params":{"ask":[{"price":"0.00011942","size":"538.4"},{"price":"0.00011949","size":"0"},{"price":"0.00011951","size":"395.5"},{"price":"0.00011952","size":"942.3"},{"price":"0.00011954","size":"102.6"},{"price":"0.00011957","size":"728.3"},{"price":"0.00011959","size":"0"},{"price":"0.00011962","size":"2979.1"},{"price":"0.00011968","size":"1279.6"},{"price":"0.00011978","size":"2394.4"},{"price":"0.00011982","size":"9269.8"},{"price":"0.00011990","size":"3.9"},{"price":"0.00011992","size":"2096.2"},{"price":"0.00011996","size":"0"},{"price":"0.00011998","size":"3485.4"},{"price":"0.00012005","size":"0"},{"price":"0.00012009","size":"7212.9"},{"price":"0.00012014","size":"1550.2"},{"price":"0.00012018","size":"0"},{"price":"0.00012021","size":"0"},{"price":"0.00012026","size":"4416.4"},{"price":"0.00012173","size":"0"},{"price":"0.00012186","size":"12140.3"}],"bid":[],"sequence":19113833,"timestamp":"2021-04-17T16:46:17.039Z","symbol":"XTZBTC"}}
1618677977.2086332: {"jsonrpc":"2.0","method":"updateOrderbook","params":{"ask":[{"price":"0.000039845","size":"2594.7"},{"price":"0.000039847","size":"0"},{"price":"0.000039909","size":"3633.3"},{"price":"0.000039912","size":"0"}],"bid":[{"price":"0.000038341","size":"820.0"},{"price":"0.000035192","size":"780.0"}],"sequence":13026892,"timestamp":"2021-04-17T16:46:17.137Z","symbol":"STORJBTC"}}
1618677977.226841: {"jsonrpc":"2.0","method":"updateOrderbook","params":{"ask":[{"price":"0.00011942","size":"1876.2"},{"price":"0.00011949","size":"728.3"},{"price":"0.00011951","size":"0"},{"price":"0.00011952","size":"565.8"},{"price":"0.00011954","size":"0"},{"price":"0.00011955","size":"102.6"},{"price":"0.00011957","size":"0"},{"price":"0.00011962","size":"2413.3"},{"price":"0.00012009","size":"3537.9"},{"price":"0.00012015","size":"3675.0"}],"bid":[{"price":"0.00006083","size":"0"}],"sequence":19113834,"timestamp":"2021-04-17T16:46:17.142Z","symbol":"XTZBTC"}}
1618677977.288832: {"jsonrpc":"2.0","method":"updateOrderbook","params":{"ask":[{"price":"0.000026964","size":"0"}],"bid":[],"sequence":1389799,"timestamp":"2021-04-17T16:46:17.207Z","symbol":"HEDGBTC"}}
1618677977.308657: {"jsonrpc":"2.0","method":"updateOrderbook","params":{"ask":[{"price":"0.00012099","size":"6070.5"},{"price":"0.00012214","size":"0"},{"price":"0.00012346","size":"8300.3"},{"price":"0.00012735","size":"0"}],"bid":[],"sequence":19113835,"timestamp":"2021-04-17T16:46:17.203Z","symbol":"XTZBTC"}}
1618677977.410534: {"jsonrpc":"2.0","method":"updateOrderbook","params":{"ask":[{"price":"0.000026962","size":"562.4"},{"price":"0.000026963","size":"0"},{"price":"0.000030785","size":"326.6"}],"bid":[],"sequence":1389800,"timestamp":"2021-04-17T16:46:17.294Z","symbol":"HEDGBTC"}}
1618677977.410711: {"jsonrpc":"2.0","method":"updateOrderbook","params":{"ask":[{"price":"0.000039875","size":"2795.3"},{"price":"0.000039905","size":"0"},{"price":"0.000039922","size":"3812.3"},{"price":"0.000039940","size":"0"}],"bid":[],"sequence":13026893,"timestamp":"2021-04-17T16:46:17.283Z","symbol":"STORJBTC"}}
1618677977.4108212: {"jsonrpc":"2.0","method":"updateOrderbook","params":{"ask":[{"price":"0.00011984","size":"1165.1"},{"price":"0.00011987","size":"0"},{"price":"0.00012008","size":"3675.0"},{"price":"0.00012015","size":"0"},{"price":"0.00012335","size":"8300.3"},{"price":"0.00012346","size":"0"}],"bid":[],"sequence":19113836,"timestamp":"2021-04-17T16:46:17.311Z","symbol":"XTZBTC"}}
1618677977.410951: {"jsonrpc":"2.0","method":"updateOrderbook","params":{"ask":[{"price":"1.5352736","size":"0"},{"price":"1.5356085","size":"295"}],"bid":[],"sequence":11642065,"timestamp":"2021-04-17T16:46:17.325Z","symbol":"MANAUSD"}}
1618677977.484865: {"jsonrpc":"2.0","method":"updateOrderbook","params":{"ask":[{"price":"0.000026961","size":"91.1"},{"price":"0.000030785","size":"0"}],"bid":[],"sequence":1389801,"timestamp":"2021-04-17T16:46:17.378Z","symbol":"HEDGBTC"}}
1618677977.490518: {"jsonrpc":"2.0","method":"updateOrderbook","params":{"ask":[{"price":"0.000039739","size":"537.3"},{"price":"0.000039740","size":"532.1"},{"price":"0.000039749","size":"0"},{"price":"0.000039750","size":"0"},{"price":"0.000039768","size":"431.7"},{"price":"0.000039772","size":"0"},{"price":"0.000039844","size":"2594.7"},{"price":"0.000039845","size":"0"},{"price":"0.000039875","size":"0"},{"price":"0.000039888","size":"2795.3"}],"bid":[],"sequence":13026894,"timestamp":"2021-04-17T16:46:17.441Z","symbol":"STORJBTC"}}
1618677977.504122: {"jsonrpc":"2.0","method":"updateOrderbook","params":{"ask":[{"price":"0.00012192","size":"0"}],"bid":[],"sequence":19113837,"timestamp":"2021-04-17T16:46:17.357Z","symbol":"XTZBTC"}}
1618677977.51387: {"jsonrpc":"2.0","method":"updateOrderbook","params":{"ask":[{"price":"0.00000120369","size":"9410"},{"price":"0.00000120446","size":"694310"},{"price":"0.00000121400","size":"0"},{"price":"0.00000121542","size":"922200"},{"price":"0.00000123905","size":"0"},{"price":"0.00000124063","size":"1107430"},{"price":"0.00000126913","size":"0"},{"price":"0.00000127074","size":"2245050"}],"bid":[],"sequence":5061554,"timestamp":"2021-04-17T16:46:17.433Z","symbol":"CELRBTC"}}
1618677977.5141: {"jsonrpc":"2.0","method":"updateOrderbook","params":{"ask":[{"price":"1.5337035","size":"0"},{"price":"1.5340312","size":"651"},{"price":"1.5621625","size":"0"},{"price":"1.5627792","size":"33819"},{"price":"1.5706267","size":"0"},{"price":"1.5711940","size":"32731"},{"price":"1.5910600","size":"0"},{"price":"1.5915731","size":"36462"},{"price":"1.6119225","size":"0"},{"price":"1.6123949","size":"37094"}],"bid":[],"sequence":11642066,"timestamp":"2021-04-17T16:46:17.449Z","symbol":"MANAUSD"}}
1618677977.592198: {"jsonrpc":"2.0","method":"updateOrderbook","params":{"ask":[{"price":"0.000039763","size":"431.7"},{"price":"0.000039768","size":"0"},{"price":"0.000039794","size":"1829.4"},{"price":"0.000039802","size":"261.3"},{"price":"0.000039837","size":"2594.7"},{"price":"0.000039844","size":"0"},{"price":"0.000039891","size":"3024.0"},{"price":"0.000039895","size":"0"},{"price":"0.000040149","size":"5378.5"},{"price":"0.000040174","size":"0"}],"bid":[],"sequence":13026895,"timestamp":"2021-04-17T16:46:17.530Z","symbol":"STORJBTC"}}
1618677977.61004: {"jsonrpc":"2.0","method":"updateOrderbook","params":{"ask":[{"price":"0.00011953","size":"196.6"},{"price":"0.00011955","size":"0"},{"price":"0.00011958","size":"907.6"},{"price":"0.00011962","size":"2034.5"},{"price":"0.00011976","size":"568.6"},{"price":"0.00011982","size":"8701.2"},{"price":"0.00012002","size":"1253.2"},{"price":"0.00012006","size":"0"},{"price":"0.00012019","size":"1165.8"},{"price":"0.00012031","size":"0"},{"price":"0.00012840","size":"7832.8"},{"price":"0.00012854","size":"0"},{"price":"0.00013221","size":"12500.4"},{"price":"0.00013441","size":"0"},{"price":"0.00013875","size":"17824.4"},{"price":"0.00014333","size":"500.0"}],"bid":[],"sequence":19113838,"timestamp":"2021-04-17T16:46:17.546Z","symbol":"XTZBTC"}}
1618677977.616974: {"jsonrpc":"2.0","method":"updateOrderbook","params":{"ask":[{"price":"1.5356085","size":"0"}],"bid":[],"sequence":11642067,"timestamp":"2021-04-17T16:46:17.468Z","symbol":"MANAUSD"}}
1618677977.69075: {"jsonrpc":"2.0","method":"updateOrderbook","params":{"ask":[],"bid":[{"price":"0.000023967","size":"1.2"}],"sequence":1389802,"timestamp":"2021-04-17T16:46:17.571Z","symbol":"HEDGBTC"}}
1618677977.700522: {"jsonrpc":"2.0","method":"updateOrderbook","params":{"ask":[{"price":"0.00133507","size":"10.00"},{"price":"0.00133518","size":"0"}],"bid":[],"sequence":10038620,"timestamp":"2021-04-17T16:46:17.587Z","symbol":"SUNBTC"}}
1618677977.7006779: {"jsonrpc":"2.0","method":"updateOrderbook","params":{"ask":[{"price":"0.00011955","size":"183.3"},{"price":"0.00011958","size":"345.5"},{"price":"0.00011959","size":"378.8"},{"price":"0.00012308","size":"0"}],"bid":[],"sequence":19113839,"timestamp":"2021-04-17T16:46:17.587Z","symbol":"XTZBTC"}}
1618677977.7062242: {"jsonrpc":"2.0","method":"updateOrderbook","params":{"ask":[{"price":"1.5463098","size":"0"},{"price":"1.5467610","size":"38333"}],"bid":[],"sequence":11642068,"timestamp":"2021-04-17T16:46:17.551Z","symbol":"MANAUSD"}}
1618677977.7941859: {"jsonrpc":"2.0","method":"updateOrderbook","params":{"ask":[{"price":"0.000039823","size":"0"},{"price":"0.000039863","size":"1150.2"},{"price":"0.000039888","size":"0"},{"price":"0.000039902","size":"2795.3"},{"price":"0.000039922","size":"0"},{"price":"0.000039936","size":"3812.3"}],"bid":[],"sequence":13026896,"timestamp":"2021-04-17T16:46:17.679Z","symbol":"STORJBTC"}}
1618677977.808992: {"jsonrpc":"2.0","method":"updateOrderbook","params":{"ask":[{"price":"1.5340312","size":"0"},{"price":"1.5351040","size":"651"},{"price":"1.5425201","size":"0"}],"bid":[],"sequence":11642069,"timestamp":"2021-04-17T16:46:17.653Z","symbol":"MANAUSD"}}
1618677977.887342: {"jsonrpc":"2.0","method":"updateOrderbook","params":{"ask":[],"bid":[{"price":"0.000023966","size":"0"}],"sequence":1389803,"timestamp":"2021-04-17T16:46:17.770Z","symbol":"HEDGBTC"}}
1618677977.9125388: {"jsonrpc":"2.0","method":"updateOrderbook","params":{"ask":[{"price":"0.00012484","size":"0"}],"bid":[],"sequence":19113840,"timestamp":"2021-04-17T16:46:17.811Z","symbol":"XTZBTC"}}
1618677977.914736: {"jsonrpc":"2.0","method":"updateOrderbook","params":{"ask":[{"price":"1.5215165","size":"37409"},{"price":"1.5220058","size":"0"}],"bid":[],"sequence":11642070,"timestamp":"2021-04-17T16:46:17.832Z","symbol":"MANAUSD"}}
1618677977.989028: {"jsonrpc":"2.0","method":"updateOrderbook","params":{"ask":[{"price":"0.000026962","size":"0"}],"bid":[],"sequence":1389804,"timestamp":"2021-04-17T16:46:17.923Z","symbol":"HEDGBTC"}}
1618677978.012821: {"jsonrpc":"2.0","method":"updateOrderbook","params":{"ask":[{"price":"0.00011949","size":"830.9"},{"price":"0.00011953","size":"94.0"},{"price":"0.00011955","size":"0"},{"price":"0.00011958","size":"1108.3"},{"price":"0.00011959","size":"0"},{"price":"0.00011960","size":"0"},{"price":"0.00011961","size":"244.5"},{"price":"0.00011963","size":"0"},{"price":"0.00011966","size":"1923.9"},{"price":"0.00011969","size":"2204.1"},{"price":"0.00011976","size":"0"},{"price":"0.00011982","size":"9269.8"},{"price":"0.00012008","size":"0"},{"price":"0.00012015","size":"3675.0"},{"price":"0.00012019","size":"0"},{"price":"0.00012031","size":"1165.8"},{"price":"0.00012335","size":"0"},{"price":"0.00012357","size":"8300.3"},{"price":"0.00013221","size":"0"},{"price":"0.00013246","size":"12500.4"},{"price":"0.00013875","size":"0"},{"price":"0.00013924","size":"17824.4"}],"bid":[],"sequence":19113841,"timestamp":"2021-04-17T16:46:17.946Z","symbol":"XTZBTC"}}
1618677978.0190852: {"jsonrpc":"2.0","method":"updateOrderbook","params":{"ask":[{"price":"1.5203177","size":"2800"},{"price":"1.5203178","size":"33531"},{"price":"1.5208411","size":"0"},{"price":"1.5215246","size":"0"}],"bid":[],"sequence":11642071,"timestamp":"2021-04-17T16:46:17.878Z","symbol":"MANAUSD"}}
1618677978.089508: {"jsonrpc":"2.0","method":"updateOrderbook","params":{"ask":[{"price":"0.000026960","size":"562.4"},{"price":"0.000026961","size":"0"},{"price":"0.000030785","size":"326.6"}],"bid":[],"sequence":1389805,"timestamp":"2021-04-17T16:46:17.996Z","symbol":"HEDGBTC"}}
1618677978.1023629: {"jsonrpc":"2.0","method":"updateOrderbook","params":{"ask":[{"price":"0.00011949","size":"728.3"},{"price":"0.00011952","size":"668.4"},{"price":"0.00012717","size":"0"},{"price":"0.00013912","size":"17824.4"},{"price":"0.00013924","size":"0"}],"bid":[],"sequence":19113842,"timestamp":"2021-04-17T16:46:18.035Z","symbol":"XTZBTC"}}
1618677978.205718: {"jsonrpc":"2.0","method":"updateOrderbook","params":{"ask":[{"price":"0.000026959","size":"91.1"},{"price":"0.000030785","size":"0"}],"bid":[],"sequence":1389806,"timestamp":"2021-04-17T16:46:18.080Z","symbol":"HEDGBTC"}}
1618677978.205878: {"jsonrpc":"2.0","method":"updateOrderbook","params":{"ask":[],"bid":[{"price":"0.000039654","size":"441.5"},{"price":"0.000039644","size":"0"}],"sequence":13026897,"timestamp":"2021-04-17T16:46:18.094Z","symbol":"STORJBTC"}}
1618677978.2060559: {"jsonrpc":"2.0","method":"updateOrderbook","params":{"ask":[{"price":"0.00011966","size":"356.1"},{"price":"0.00011969","size":"358.4"},{"price":"0.00011978","size":"0"},{"price":"0.00011979","size":"1567.8"},{"price":"0.00011984","size":"0"},{"price":"0.00011990","size":"1169.0"},{"price":"0.00011992","size":"2880.8"},{"price":"0.00011994","size":"1845.7"},{"price":"0.00012003","size":"0"},{"price":"0.00012014","size":"0"},{"price":"0.00012015","size":"0"},{"price":"0.00012019","size":"1550.2"},{"price":"0.00012053","size":"1629.2"},{"price":"0.00012064","size":"5516.9"},{"price":"0.00012071","size":"0"},{"price":"0.00012077","size":"3675.0"},{"price":"0.00012079","size":"0"},{"price":"0.00012095","size":"4799.2"},{"price":"0.00012099","size":"0"},{"price":"0.00012226","size":"6070.5"},{"price":"0.00012357","size":"0"},{"price":"0.00012760","size":"8300.3"},{"price":"0.00013246","size":"0"},{"price":"0.00013441","size":"12500.4"},{"price":"0.00013912","size":"0"},{"price":"0.00014601","size":"17824.4"}],"bid":[],"sequence":19113843,"timestamp":"2021-04-17T16:46:18.135Z","symbol":"XTZBTC"}}
1618677978.2949939: {"jsonrpc":"2.0","method":"updateOrderbook","params":{"ask":[],"bid":[{"price":"0.000023967","size":"9.4"}],"sequence":1389807,"timestamp":"2021-04-17T16:46:18.162Z","symbol":"HEDGBTC"}}
1618677978.301697: {"jsonrpc":"2.0","method":"updateOrderbook","params":{"ask":[{"price":"0.000039794","size":"0"},{"price":"0.000039799","size":"1829.4"},{"price":"0.000039837","size":"0"},{"price":"0.000039842","size":"2594.7"},{"price":"0.000039891","size":"0"},{"price":"0.000039895","size":"3024.0"},{"price":"0.000040248","size":"0"},{"price":"0.000040257","size":"9299.9"}],"bid":[],"sequence":13026898,"timestamp":"2021-04-17T16:46:18.246Z","symbol":"STORJBTC"}}
1618677978.316273: {"jsonrpc":"2.0","method":"updateOrderbook","params":{"ask":[],"bid":[{"price":"0.00000512","size":"0"},{"price":"0.00000496","size":"20.06"},{"price":"0.00000056","size":"0"}],"sequence":10038621,"timestamp":"2021-04-17T16:46:18.245Z","symbol":"SUNBTC"}}
1618677978.316446: {"jsonrpc":"2.0","method":"updateOrderbook","params":{"ask":[{"price":"0.00011959","size":"244.5"},{"price":"0.00011961","size":"0"},{"price":"0.00011964","size":"1277.0"},{"price":"0.00011966","size":"0"}],"bid":[],"sequence":19113844,"timestamp":"2021-04-17T16:46:18.189Z","symbol":"XTZBTC"}}
1618677978.390591: {"jsonrpc":"2.0","method":"updateOrderbook","params":{"ask":[{"price":"0.00000000420","size":"0"},{"price":"0.00000000450","size":"2812000"}],"bid":[],"sequence":1757666,"timestamp":"2021-04-17T16:46:18.341Z","symbol":"BANCABTC"}}
1618677978.4264581: {"jsonrpc":"2.0","method":"updateOrderbook","params":{"ask":[],"bid":[{"price":"0.00000056","size":"296.13"}],"sequence":10038622,"timestamp":"2021-04-17T16:46:18.280Z","symbol":"SUNBTC"}}
1618677978.426595: {"jsonrpc":"2.0","method":"updateOrderbook","params":{"ask":[{"price":"0.00013441","size":"0"},{"price":"0.00013610","size":"12500.4"},{"price":"0.00014601","size":"0"},{"price":"0.00014867","size":"17824.4"}],"bid":[{"price":"0.00011127","size":"380.0"},{"price":"0.00011112","size":"0"},{"price":"0.00010798","size":"0.2"}],"sequence":19113845,"timestamp":"2021-04-17T16:46:18.322Z","symbol":"XTZBTC"}}
1618677978.498094: {"jsonrpc":"2.0","method":"updateOrderbook","params":{"ask":[],"bid":[{"price":"0.00000000369","size":"310000"},{"price":"0.00000000359","size":"2440000"},{"price":"0.00000000237","size":"1000"},{"price":"0.00000000230","size":"11651000"}],"sequence":1757667,"timestamp":"2021-04-17T16:46:18.442Z","symbol":"BANCABTC"}}
1618677978.6207428: {"jsonrpc":"2.0","method":"updateOrderbook","params":{"ask":[{"price":"0.00011956","size":"200.7"},{"price":"0.00011958","size":"562.1"},{"price":"0.00011960","size":"345.5"},{"price":"0.00012002","size":"0"},{"price":"0.00012017","size":"1253.2"},{"price":"0.00012136","size":"0"},{"price":"0.00012155","size":"4093.4"},{"price":"0.00012840","size":"0"},{"price":"0.00012859","size":"7832.8"}],"bid":[{"price":"0.00010695","size":"0.2"}],"sequence":19113846,"timestamp":"2021-04-17T16:46:18.546Z","symbol":"XTZBTC"}}
1618677978.7140968: {"jsonrpc":"2.0","method":"updateOrderbook","params":{"ask":[{"price":"0.000040220","size":"9299.9"},{"price":"0.000040257","size":"0"}],"bid":[{"price":"0.000039654","size":"0"},{"price":"0.000039629","size":"0"},{"price":"0.000039623","size":"441.5"},{"price":"0.000039590","size":"1262.0"}],"sequence":13026899,"timestamp":"2021-04-17T16:46:18.649Z","symbol":"STORJBTC"}}
1618677978.81564: {"jsonrpc":"2.0","method":"updateOrderbook","params":{"ask":[{"price":"0.000039802","size":"0"},{"price":"0.000039815","size":"261.3"},{"price":"0.000039853","size":"1150.2"},{"price":"0.000039863","size":"0"},{"price":"0.000039892","size":"2795.3"},{"price":"0.000039902","size":"0"},{"price":"0.000040220","size":"0"},{"price":"0.000040259","size":"9299.9"}],"bid":[{"price":"0.000039644","size":"441.5"},{"price":"0.000039629","size":"1262.0"},{"price":"0.000039623","size":"0"},{"price":"0.000039590","size":"0"}],"sequence":13026900,"timestamp":"2021-04-17T16:46:18.733Z","symbol":"STORJBTC"}}
1618677978.816355: {"jsonrpc":"2.0","method":"updateOrderbook","params":{"ask":[{"price":"0.00011975","size":"1567.8"},{"price":"0.00011979","size":"0"}],"bid":[{"price":"0.00010546","size":"0.2"}],"sequence":19113847,"timestamp":"2021-04-17T16:46:18.706Z","symbol":"XTZBTC"}}
1618677978.8947961: {"jsonrpc":"2.0","method":"updateOrderbook","params":{"ask":[{"price":"0.000026959","size":"82.3"},{"price":"0.000030786","size":"647.2"}],"bid":[],"sequence":1389808,"timestamp":"2021-04-17T16:46:18.779Z","symbol":"HEDGBTC"}}
1618677978.905823: {"jsonrpc":"2.0","method":"updateOrderbook","params":{"ask":[{"price":"0.00011955","size":"378.8"},{"price":"0.00011958","size":"183.3"}],"bid":[],"sequence":19113848,"timestamp":"2021-04-17T16:46:18.782Z","symbol":"XTZBTC"}}
1618677978.988981: {"jsonrpc":"2.0","method":"updateOrderbook","params":{"ask":[{"price":"0.000026960","size":"0"}],"bid":[],"sequence":1389809,"timestamp":"2021-04-17T16:46:18.907Z","symbol":"HEDGBTC"}}
1618677979.006528: {"jsonrpc":"2.0","method":"updateOrderbook","params":{"ask":[{"price":"0.000039815","size":"0"},{"price":"0.000039842","size":"2856.0"},{"price":"0.000040232","size":"9299.9"},{"price":"0.000040259","size":"0"},{"price":"0.000040513","size":"0"},{"price":"0.000040543","size":"13527.3"}],"bid":[],"sequence":13026901,"timestamp":"2021-04-17T16:46:18.932Z","symbol":"STORJBTC"}}
1618677979.006739: {"jsonrpc":"2.0","method":"updateOrderbook","params":{"ask":[{"price":"0.00014784","size":"0"},{"price":"0.00014817","size":"5176.4"}],"bid":[{"price":"0.00010352","size":"0.2"}],"sequence":19113849,"timestamp":"2021-04-17T16:46:18.926Z","symbol":"XTZBTC"}}
1618677979.091084: {"jsonrpc":"2.0","method":"updateOrderbook","params":{"ask":[{"price":"0.000026958","size":"562.4"},{"price":"0.000026959","size":"0"},{"price":"0.000030785","size":"326.6"}],"bid":[],"sequence":1389810,"timestamp":"2021-04-17T16:46:18.989Z","symbol":"HEDGBTC"}}
1618677979.112153: {"jsonrpc":"2.0","method":"updateOrderbook","params":{"ask":[{"price":"0.000039739","size":"0"},{"price":"0.000039740","size":"0"},{"price":"0.000039749","size":"537.3"},{"price":"0.000039754","size":"532.1"},{"price":"0.000039763","size":"0"},{"price":"0.000039769","size":"431.7"},{"price":"0.000039799","size":"0"},{"price":"0.000039802","size":"1829.4"},{"price":"0.000039842","size":"261.3"},{"price":"0.000039846","size":"2594.7"}],"bid":[],"sequence":13026902,"timestamp":"2021-04-17T16:46:19.045Z","symbol":"STORJBTC"}}
1618677979.112512: {"jsonrpc":"2.0","method":"updateOrderbook","params":{"ask":[{"price":"0.00012056","size":"4252.7"},{"price":"0.00012064","size":"3122.5"}],"bid":[],"sequence":19113850,"timestamp":"2021-04-17T16:46:18.993Z","symbol":"XTZBTC"}}
1618677979.188462: {"jsonrpc":"2.0","method":"updateOrderbook","params":{"ask":[{"price":"0.000026957","size":"82.3"},{"price":"0.000030785","size":"0"}],"bid":[],"sequence":1389811,"timestamp":"2021-04-17T16:46:19.085Z","symbol":"HEDGBTC"}}
1618677979.1980119: {"jsonrpc":"2.0","method":"updateOrderbook","params":{"ask":[{"price":"0.000039802","size":"0"},{"price":"0.000039809","size":"1829.4"},{"price":"0.000039846","size":"0"},{"price":"0.000039853","size":"3744.9"},{"price":"0.000039945","size":"0"},{"price":"0.000039965","size":"3785.4"},{"price":"0.000040149","size":"0"},{"price":"0.000040185","size":"5378.5"}],"bid":[],"sequence":13026903,"timestamp":"2021-04-17T16:46:19.137Z","symbol":"STORJBTC"}}
1618677979.2112: {"jsonrpc":"2.0","method":"updateOrderbook","params":{"ask":[{"price":"0.00011948","size":"183.3"},{"price":"0.00011955","size":"1303.6"},{"price":"0.00011957","size":"219.4"},{"price":"0.00011958","size":"0"},{"price":"0.00011962","size":"2169.9"},{"price":"0.00011968","size":"0"}],"bid":[],"sequence":19113851,"timestamp":"2021-04-17T16:46:19.137Z","symbol":"XTZBTC"}}
1618677979.293903: {"jsonrpc":"2.0","method":"updateOrderbook","params":{"ask":[{"price":"0.000039729","size":"537.3"},{"price":"0.000039730","size":"532.1"},{"price":"0.000039749","size":"0"},{"price":"0.000039754","size":"0"},{"price":"0.000039760","size":"431.7"},{"price":"0.000039769","size":"0"},{"price":"0.000039805","size":"1829.4"},{"price":"0.000039809","size":"0"},{"price":"0.000039850","size":"2594.7"},{"price":"0.000039853","size":"1150.2"},{"price":"0.000039880","size":"2795.3"},{"price":"0.000039892","size":"0"},{"price":"0.000039958","size":"5302.1"},{"price":"0.000039974","size":"0"}],"bid":[],"sequence":13026904,"timestamp":"2021-04-17T16:46:19.213Z","symbol":"STORJBTC"}}
1618677979.3126578: {"jsonrpc":"2.0","method":"updateOrderbook","params":{"ask":[],"bid":[{"price":"0.00006089","size":"0.3"}],"sequence":19113852,"timestamp":"2021-04-17T16:46:19.152Z","symbol":"XTZBTC"}}
1618677979.32882: {"jsonrpc":"2.0","method":"updateOrderbook","params":{"ask":[{"price":"0.2195408","size":"0"},{"price":"0.2196236","size":"23.27"}],"bid":[],"sequence":4920725,"timestamp":"2021-04-17T16:46:19.151Z","symbol":"BNBETH"}}
1618677979.3945448: {"jsonrpc":"2.0","method":"updateOrderbook","params":{"ask":[{"price":"0.000039729","size":"0"},{"price":"0.000039730","size":"0"},{"price":"0.000039749","size":"537.3"},{"price":"0.000039750","size":"532.1"},{"price":"0.000039760","size":"0"},{"price":"0.000039766","size":"431.7"},{"price":"0.000040043","size":"0"},{"price":"0.000040275","size":"1123.9"},{"price":"0.000040303","size":"0"},{"price":"0.000040369","size":"1242.8"},{"price":"0.000040393","size":"0"},{"price":"0.000040501","size":"2058.7"},{"price":"0.000040923","size":"0"},{"price":"0.000041368","size":"2812.0"}],"bid":[],"sequence":13026905,"timestamp":"2021-04-17T16:46:19.285Z","symbol":"STORJBTC"}}
1618677979.409748: {"jsonrpc":"2.0","method":"updateOrderbook","params":{"ask":[{"price":"0.00011942","size":"538.4"},{"price":"0.00011949","size":"0"},{"price":"0.00011951","size":"395.5"},{"price":"0.00011952","size":"1044.9"},{"price":"0.00011955","size":"378.8"},{"price":"0.00011957","size":"947.7"},{"price":"0.00011962","size":"2380.9"},{"price":"0.00011968","size":"1279.6"},{"price":"0.00011986","size":"1165.1"},{"price":"0.00011990","size":"3.9"},{"price":"0.00012016","size":"1550.2"},{"price":"0.00012019","size":"0"}],"bid":[],"sequence":19113853,"timestamp":"2021-04-17T16:46:19.346Z","symbol":"XTZBTC"}}
1618677979.414824: {"jsonrpc":"2.0","method":"updateOrderbook","params":{"ask":[{"price":"1.5351040","size":"0"},{"price":"1.5361662","size":"650"}],"bid":[],"sequence":11642072,"timestamp":"2021-04-17T16:46:19.326Z","symbol":"MANAUSD"}}
1618677979.504807: {"jsonrpc":"2.0","method":"updateOrderbook","params":{"ask":[{"price":"0.000039739","size":"537.3"},{"price":"0.000039740","size":"532.1"},{"price":"0.000039749","size":"0"},{"price":"0.000039750","size":"0"},{"price":"0.000039764","size":"431.7"},{"price":"0.000039766","size":"0"}],"bid":[],"sequence":13026906,"timestamp":"2021-04-17T16:46:19.446Z","symbol":"STORJBTC"}}
1618677979.513223: {"jsonrpc":"2.0","method":"updateOrderbook","params":{"ask":[{"price":"0.00011942","size":"1876.2"},{"price":"0.00011949","size":"728.3"},{"price":"0.00011951","size":"0"},{"price":"0.00011952","size":"668.4"},{"price":"0.00011957","size":"219.4"},{"price":"0.00011962","size":"1815.1"},{"price":"0.00012215","size":"0.4"}],"bid":[],"sequence":19113854,"timestamp":"2021-04-17T16:46:19.378Z","symbol":"XTZBTC"}}
1618677979.5991921: {"jsonrpc":"2.0","method":"updateOrderbook","params":{"ask":[],"bid":[{"price":"0.000039644","size":"0"},{"price":"0.000039632","size":"441.5"},{"price":"0.000039629","size":"0"},{"price":"0.000039597","size":"1262.0"}],"sequence":13026907,"timestamp":"2021-04-17T16:46:19.546Z","symbol":"STORJBTC"}}
1618677979.6205719: {"jsonrpc":"2.0","method":"updateOrderbook","params":{"ask":[],"bid":[{"price":"0.00021322","size":"5.79"},{"price":"0.00019312","size":"0"}],"sequence":10038623,"timestamp":"2021-04-17T16:46:19.469Z","symbol":"SUNBTC"}}
1618677979.620729: {"jsonrpc":"2.0","method":"updateOrderbook","params":{"ask":[{"price":"0.00011962","size":"2736.0"},{"price":"0.00011964","size":"356.1"}],"bid":[],"sequence":19113855,"timestamp":"2021-04-17T16:46:19.486Z","symbol":"XTZBTC"}}
1618677979.6207948: {"jsonrpc":"2.0","method":"updateOrderbook","params":{"ask":[{"price":"1.5385438","size":"295"},{"price":"1.5449773","size":"354"}],"bid":[],"sequence":11642073,"timestamp":"2021-04-17T16:46:19.452Z","symbol":"MANAUSD"}}
1618677979.710919: {"jsonrpc":"2.0","method":"updateOrderbook","params":{"ask":[],"bid":[{"price":"0.000039619","size":"1262.0"},{"price":"0.000039597","size":"0"}],"sequence":13026908,"timestamp":"2021-04-17T16:46:19.637Z","symbol":"STORJBTC"}}
1618677979.713515: {"jsonrpc":"2.0","method":"updateOrderbook","params":{"ask":[{"price":"0.00011957","size":"564.9"},{"price":"0.00011960","size":"0"},{"price":"0.00012016","size":"0"},{"price":"0.00012020","size":"1550.2"},{"price":"0.00012081","size":"6070.5"},{"price":"0.00012144","size":"8300.3"},{"price":"0.00012226","size":"0"},{"price":"0.00012332","size":"0.4"},{"price":"0.00012760","size":"0"}],"bid":[],"sequence":19113856,"timestamp":"2021-04-17T16:46:19.617Z","symbol":"XTZBTC"}}
1618677979.810482: {"jsonrpc":"2.0","method":"updateOrderbook","params":{"ask":[{"price":"0.00011948","size":"0"},{"price":"0.00011957","size":"528.8"},{"price":"0.00011962","size":"2955.4"}],"bid":[],"sequence":19113857,"timestamp":"2021-04-17T16:46:19.703Z","symbol":"XTZBTC"}}
1618677979.886806: {"jsonrpc":"2.0","method":"updateOrderbook","params":{"ask":[{"price":"0.000026958","size":"0"}],"bid":[],"sequence":1389812,"timestamp":"2021-04-17T16:46:19.826Z","symbol":"HEDGBTC"}}
1618677979.9103072: {"jsonrpc":"2.0","method":"updateOrderbook","params":{"ask":[{"price":"0.000039850","size":"0"},{"price":"0.000039852","size":"2594.7"}],"bid":[],"sequence":13026909,"timestamp":"2021-04-17T16:46:19.830Z","symbol":"STORJBTC"}}
1618677979.9104698: {"jsonrpc":"2.0","method":"updateOrderbook","params":{"ask":[{"price":"0.00011957","size":"345.5"},{"price":"0.00011958","size":"183.3"},{"price":"0.00011962","size":"2034.5"},{"price":"0.00011964","size":"1277.0"},{"price":"0.00011986","size":"0"},{"price":"0.00011991","size":"1165.1"},{"price":"0.00012507","size":"0.4"}],"bid":[],"sequence":19113858,"timestamp":"2021-04-17T16:46:19.837Z","symbol":"XTZBTC"}}
1618677979.9145222: {"jsonrpc":"2.0","method":"updateOrderbook","params":{"ask":[{"price":"0.2197707","size":"0"},{"price":"0.2198803","size":"100.00"}],"bid":[],"sequence":4920726,"timestamp":"2021-04-17T16:46:19.844Z","symbol":"BNBETH"}}
1618677979.9887118: {"jsonrpc":"2.0","method":"updateOrderbook","params":{"ask":[{"price":"0.000026956","size":"562.4"},{"price":"0.000026957","size":"0"},{"price":"0.000030785","size":"326.6"}],"bid":[],"sequence":1389813,"timestamp":"2021-04-17T16:46:19.901Z","symbol":"HEDGBTC"}}
1618677980.018406: {"jsonrpc":"2.0","method":"updateOrderbook","params":{"ask":[{"price":"0.000039812","size":"261.3"},{"price":"0.000039842","size":"0"}],"bid":[],"sequence":13026910,"timestamp":"2021-04-17T16:46:19.945Z","symbol":"STORJBTC"}}
1618677980.0185668: {"jsonrpc":"2.0","method":"updateOrderbook","params":{"ask":[{"price":"0.00011949","size":"0"},{"price":"0.00011950","size":"728.3"},{"price":"0.00011980","size":"1752.5"},{"price":"0.00011982","size":"7549.3"}],"bid":[],"sequence":19113859,"timestamp":"2021-04-17T16:46:19.876Z","symbol":"XTZBTC"}}
1618677980.018671: {"jsonrpc":"2.0","method":"updateOrderbook","params":{"ask":[{"price":"1.5361662","size":"0"},{"price":"1.5371824","size":"650"},{"price":"1.5385438","size":"0"},{"price":"1.5388893","size":"295"}],"bid":[],"sequence":11642074,"timestamp":"2021-04-17T16:46:19.865Z","symbol":"MANAUSD"}}
1618677980.089652: {"jsonrpc":"2.0","method":"updateOrderbook","params":{"ask":[{"price":"0.000026955","size":"82.3"},{"price":"0.000030785","size":"0"}],"bid":[],"sequence":1389814,"timestamp":"2021-04-17T16:46:19.981Z","symbol":"HEDGBTC"}}
1618677980.10656: {"jsonrpc":"2.0","method":"updateOrderbook","params":{"ask":[{"price":"0.00011966","size":"1567.8"},{"price":"0.00011969","size":"2204.1"},{"price":"0.00011974","size":"2394.4"},{"price":"0.00011975","size":"0"},{"price":"0.00011994","size":"0"},{"price":"0.00012056","size":"1858.3"},{"price":"0.00012144","size":"0"},{"price":"0.00012179","size":"8300.3"}],"bid":[],"sequence":19113860,"timestamp":"2021-04-17T16:46:19.996Z","symbol":"XTZBTC"}}
1618677980.194109: {"jsonrpc":"2.0","method":"updateOrderbook","params":{"ask":[],"bid":[{"price":"0.000039652","size":"441.5"},{"price":"0.000039632","size":"0"}],"sequence":13026911,"timestamp":"2021-04-17T16:46:20.086Z","symbol":"STORJBTC"}}
1618677980.210165: {"jsonrpc":"2.0","method":"updateOrderbook","params":{"ask":[{"price":"0.00012741","size":"0.4"}],"bid":[],"sequence":19113861,"timestamp":"2021-04-17T16:46:20.057Z","symbol":"XTZBTC"}}
1618677980.210305: {"jsonrpc":"2.0","method":"updateOrderbook","params":{"ask":[],"bid":[{"price":"0.2153771","size":"14.00"},{"price":"0.2152262","size":"0"},{"price":"0.2151180","size":"7.00"},{"price":"0.2149055","size":"0"}],"sequence":4920727,"timestamp":"2021-04-17T16:46:20.082Z","symbol":"BNBETH"}}
1618677980.3044329: {"jsonrpc":"2.0","method":"updateOrderbook","params":{"ask":[],"bid":[{"price":"0.00021322","size":"0"},{"price":"0.00019285","size":"5.79"}],"sequence":10038624,"timestamp":"2021-04-17T16:46:20.193Z","symbol":"SUNBTC"}}
1618677980.3045938: {"jsonrpc":"2.0","method":"updateOrderbook","params":{"ask":[{"price":"0.00011978","size":"1253.2"},{"price":"0.00012017","size":"0"},{"price":"0.00014458","size":"17824.4"},{"price":"0.00014867","size":"0"}],"bid":[],"sequence":19113862,"timestamp":"2021-04-17T16:46:20.177Z","symbol":"XTZBTC"}}
1618677980.396373: {"jsonrpc":"2.0","method":"updateOrderbook","params":{"ask":[{"price":"0.000039833","size":"1150.2"},{"price":"0.000039853","size":"0"},{"price":"0.000039916","size":"3812.3"},{"price":"0.000039936","size":"0"}],"bid":[{"price":"0.000039652","size":"0"},{"price":"0.000039636","size":"441.5"}],"sequence":13026912,"timestamp":"2021-04-17T16:46:20.312Z","symbol":"STORJBTC"}}
1618677980.399489: {"jsonrpc":"2.0","method":"updateOrderbook","params":{"ask":[{"price":"0.00011984","size":"3675.0"},{"price":"0.00012027","size":"4799.2"},{"price":"0.00012077","size":"0"},{"price":"0.00012095","size":"0"}],"bid":[],"sequence":19113863,"timestamp":"2021-04-17T16:46:20.282Z","symbol":"XTZBTC"}}
1618677980.40667: {"jsonrpc":"2.0","method":"updateOrderbook","params":{"ask":[{"price":"1.5388893","size":"0"},{"price":"1.5392721","size":"295"}],"bid":[],"sequence":11642075,"timestamp":"2021-04-17T16:46:20.328Z","symbol":"MANAUSD"}}
1618677980.494497: {"jsonrpc":"2.0","method":"updateOrderbook","params":{"ask":[{"price":"0.000039850","size":"2594.7"},{"price":"0.000039852","size":"0"}],"bid":[{"price":"0.000039644","size":"441.5"},{"price":"0.000039636","size":"0"},{"price":"0.000039629","size":"1262.0"},{"price":"0.000039619","size":"0"}],"sequence":13026913,"timestamp":"2021-04-17T16:46:20.349Z","symbol":"STORJBTC"}}
1618677980.51036: {"jsonrpc":"2.0","method":"updateOrderbook","params":{"ask":[{"price":"1.5392721","size":"0"},{"price":"1.5449773","size":"0"}],"bid":[],"sequence":11642076,"timestamp":"2021-04-17T16:46:20.401Z","symbol":"MANAUSD"}}
1618677980.593428: {"jsonrpc":"2.0","method":"updateOrderbook","params":{"ask":[{"price":"0.000039739","size":"0"},{"price":"0.000039740","size":"0"},{"price":"0.000039749","size":"537.3"},{"price":"0.000039754","size":"532.1"},{"price":"0.000039764","size":"0"},{"price":"0.000039769","size":"431.7"},{"price":"0.000039805","size":"0"},{"price":"0.000039809","size":"1829.4"},{"price":"0.000039850","size":"0"},{"price":"0.000039853","size":"2594.7"}],"bid":[],"sequence":13026914,"timestamp":"2021-04-17T16:46:20.463Z","symbol":"STORJBTC"}}
1618677980.6039748: {"jsonrpc":"2.0","method":"updateOrderbook","params":{"ask":[],"bid":[{"price":"0.00011510","size":"0"}],"sequence":19113864,"timestamp":"2021-04-17T16:46:20.453Z","symbol":"XTZBTC"}}
1618677980.608278: {"jsonrpc":"2.0","method":"updateOrderbook","params":{"ask":[{"price":"1.5396719","size":"294"},{"price":"1.5458307","size":"354"}],"bid":[],"sequence":11642077,"timestamp":"2021-04-17T16:46:20.540Z","symbol":"MANAUSD"}}
1618677980.6090298: {"jsonrpc":"2.0","method":"updateOrderbook","params":{"ask":[],"bid":[{"price":"0.2181733","size":"28.40"},{"price":"0.2179994","size":"0"}],"sequence":4920728,"timestamp":"2021-04-17T16:46:20.467Z","symbol":"BNBETH"}}
1618677980.69082: {"jsonrpc":"2.0","method":"updateOrderbook","params":{"ask":[{"price":"0.000039812","size":"0"},{"price":"0.000039822","size":"261.3"}],"bid":[],"sequence":13026915,"timestamp":"2021-04-17T16:46:20.562Z","symbol":"STORJBTC"}}
1618677980.704841: {"jsonrpc":"2.0","method":"updateOrderbook","params":{"ask":[{"price":"0.00011978","size":"0"},{"price":"0.00012002","size":"1253.2"}],"bid":[],"sequence":19113865,"timestamp":"2021-04-17T16:46:20.609Z","symbol":"XTZBTC"}}
1618677980.71748: {"jsonrpc":"2.0","method":"updateOrderbook","params":{"ask":[{"price":"1.5396719","size":"0"},{"price":"1.5458307","size":"0"}],"bid":[],"sequence":11642078,"timestamp":"2021-04-17T16:46:20.573Z","symbol":"MANAUSD"}}
1618677980.71764: {"jsonrpc":"2.0","method":"updateOrderbook","params":{"ask":[],"bid":[{"price":"0.2184021","size":"23.27"},{"price":"0.2182933","size":"0"}],"sequence":4920729,"timestamp":"2021-04-17T16:46:20.587Z","symbol":"BNBETH"}}
1618677980.787307: {"jsonrpc":"2.0","method":"updateOrderbook","params":{"ask":[{"price":"0.000026956","size":"0"}],"bid":[],"sequence":1389815,"timestamp":"2021-04-17T16:46:20.717Z","symbol":"HEDGBTC"}}
1618677980.79114: {"jsonrpc":"2.0","method":"updateOrderbook","params":{"ask":[{"price":"0.000039805","size":"1829.4"},{"price":"0.000039809","size":"0"},{"price":"0.000039822","size":"0"},{"price":"0.000039832","size":"261.3"},{"price":"0.000039833","size":"0"},{"price":"0.000039844","size":"1150.2"},{"price":"0.000039850","size":"2594.7"},{"price":"0.000039853","size":"0"},{"price":"0.000039880","size":"0"},{"price":"0.000039891","size":"2795.3"},{"price":"0.000039916","size":"0"},{"price":"0.000039929","size":"3812.3"}],"bid":[],"sequence":13026916,"timestamp":"2021-04-17T16:46:20.679Z","symbol":"STORJBTC"}}
1618677980.804926: {"jsonrpc":"2.0","method":"updateOrderbook","params":{"ask":[{"price":"0.00012949","size":"12500.4"},{"price":"0.00013610","size":"0"}],"bid":[],"sequence":19113866,"timestamp":"2021-04-17T16:46:20.714Z","symbol":"XTZBTC"}}
1618677980.8051012: {"jsonrpc":"2.0","method":"updateOrderbook","params":{"ask":[],"bid":[{"price":"0.00000107770","size":"0"}],"sequence":5061555,"timestamp":"2021-04-17T16:46:20.716Z","symbol":"CELRBTC"}}
1618677980.805661: {"jsonrpc":"2.0","method":"updateOrderbook","params":{"ask":[{"price":"1.5706704","size":"32731"},{"price":"1.5711940","size":"0"}],"bid":[],"sequence":11642079,"timestamp":"2021-04-17T16:46:20.671Z","symbol":"MANAUSD"}}
1618677980.888321: {"jsonrpc":"2.0","method":"updateOrderbook","params":{"ask":[{"price":"0.000026954","size":"562.4"},{"price":"0.000026955","size":"0"},{"price":"0.000030785","size":"326.6"}],"bid":[],"sequence":1389816,"timestamp":"2021-04-17T16:46:20.806Z","symbol":"HEDGBTC"}}
1618677980.892066: {"jsonrpc":"2.0","method":"updateOrderbook","params":{"ask":[{"price":"0.000040369","size":"0"},{"price":"0.000040381","size":"0"},{"price":"0.000040501","size":"0"},{"price":"0.000040510","size":"1242.8"},{"price":"0.000041224","size":"1551.8"},{"price":"0.000041368","size":"0"},{"price":"0.000041770","size":"2058.7"},{"price":"0.000042195","size":"2812.0"}],"bid":[],"sequence":13026917,"timestamp":"2021-04-17T16:46:20.839Z","symbol":"STORJBTC"}}
1618677980.907648: {"jsonrpc":"2.0","method":"updateOrderbook","params":{"ask":[],"bid":[{"price":"0.00000107772","size":"18900"}],"sequence":5061556,"timestamp":"2021-04-17T16:46:20.845Z","symbol":"CELRBTC"}}
1618677980.907794: {"jsonrpc":"2.0","method":"updateOrderbook","params":{"ask":[{"price":"1.5371824","size":"651"},{"price":"1.5910859","size":"36462"},{"price":"1.5915731","size":"0"}],"bid":[],"sequence":11642080,"timestamp":"2021-04-17T16:46:20.767Z","symbol":"MANAUSD"}}
1618677980.996962: {"jsonrpc":"2.0","method":"updateOrderbook","params":{"ask":[{"price":"0.000026953","size":"82.3"},{"price":"0.000030785","size":"0"}],"bid":[],"sequence":1389817,"timestamp":"2021-04-17T16:46:20.881Z","symbol":"HEDGBTC"}}
1618677980.997077: {"jsonrpc":"2.0","method":"updateOrderbook","params":{"ask":[{"price":"0.000039847","size":"2594.7"},{"price":"0.000039850","size":"0"},{"price":"0.000039892","size":"3024.0"},{"price":"0.000039895","size":"0"},{"price":"0.000039953","size":"3785.4"},{"price":"0.000039965","size":"0"},{"price":"0.000040052","size":"6736.1"},{"price":"0.000040153","size":"0"}],"bid":[],"sequence":13026918,"timestamp":"2021-04-17T16:46:20.941Z","symbol":"STORJBTC"}}
1618677981.009604: {"jsonrpc":"2.0","method":"updateOrderbook","params":{"ask":[{"price":"0.00011955","size":"1486.9"},{"price":"0.00011958","size":"0"},{"price":"0.00011962","size":"2389.3"},{"price":"0.00011968","size":"0"},{"price":"0.00011986","size":"1165.1"},{"price":"0.00011991","size":"0"},{"price":"0.00012016","size":"1550.2"},{"price":"0.00012020","size":"0"}],"bid":[],"sequence":19113867,"timestamp":"2021-04-17T16:46:20.901Z","symbol":"XTZBTC"}}
1618677981.103858: {"jsonrpc":"2.0","method":"updateOrderbook","params":{"ask":[{"price":"0.00011942","size":"286.5"},{"price":"0.00011944","size":"251.9"},{"price":"0.00011950","size":"0"},{"price":"0.00011952","size":"1440.4"},{"price":"0.00011955","size":"378.8"},{"price":"0.00011956","size":"929.0"},{"price":"0.00011957","size":"528.8"},{"price":"0.00011962","size":"2600.3"},{"price":"0.00011968","size":"1279.6"}],"bid":[],"sequence":19113868,"timestamp":"2021-04-17T16:46:20.977Z","symbol":"XTZBTC"}}
1618677981.108147: {"jsonrpc":"2.0","method":"updateOrderbook","params":{"ask":[],"bid":[{"price":"0.00000107773","size":"2100"},{"price":"0.00000107771","size":"0"}],"sequence":5061557,"timestamp":"2021-04-17T16:46:21.046Z","symbol":"CELRBTC"}}
1618677981.108326: {"jsonrpc":"2.0","method":"updateOrderbook","params":{"ask":[{"price":"0.2221199","size":"0"},{"price":"0.2222405","size":"14.00"}],"bid":[],"sequence":4920730,"timestamp":"2021-04-17T16:46:21.017Z","symbol":"BNBETH"}}
1618677981.202027: {"jsonrpc":"2.0","method":"updateOrderbook","params":{"ask":[{"price":"0.000039880","size":"2795.3"},{"price":"0.000039891","size":"0"}],"bid":[],"sequence":13026919,"timestamp":"2021-04-17T16:46:21.142Z","symbol":"STORJBTC"}}
1618677981.2069812: {"jsonrpc":"2.0","method":"updateOrderbook","params":{"ask":[{"price":"0.00011976","size":"568.6"},{"price":"0.00011982","size":"6980.7"},{"price":"0.00012089","size":"4093.4"},{"price":"0.00012155","size":"0"}],"bid":[],"sequence":19113869,"timestamp":"2021-04-17T16:46:21.090Z","symbol":"XTZBTC"}}
1618677981.28954: {"jsonrpc":"2.0","method":"updateOrderbook","params":{"ask":[{"price":"0.000030786","size":"656.0"}],"bid":[],"sequence":1389818,"timestamp":"2021-04-17T16:46:21.203Z","symbol":"HEDGBTC"}}
1618677981.296132: {"jsonrpc":"2.0","method":"updateOrderbook","params":{"ask":[{"price":"0.000039769","size":"0"},{"price":"0.000039779","size":"431.7"},{"price":"0.000039805","size":"0"},{"price":"0.000039816","size":"1829.4"},{"price":"0.000039847","size":"0"},{"price":"0.000039853","size":"2594.7"},{"price":"0.000039892","size":"0"},{"price":"0.000039895","size":"3024.0"},{"price":"0.000039915","size":"3812.3"},{"price":"0.000039929","size":"0"},{"price":"0.000039953","size":"0"},{"price":"0.000039960","size":"3785.4"},{"price":"0.000040206","size":"9299.9"},{"price":"0.000040232","size":"0"}],"bid":[],"sequence":13026920,"timestamp":"2021-04-17T16:46:21.243Z","symbol":"STORJBTC"}}
1618677981.307138: {"jsonrpc":"2.0","method":"updateOrderbook","params":{"ask":[{"price":"0.00133454","size":"10.00"},{"price":"0.00133507","size":"0"}],"bid":[{"price":"0.00016239","size":"0"},{"price":"0.00016186","size":"10.00"}],"sequence":10038625,"timestamp":"2021-04-17T16:46:21.209Z","symbol":"SUNBTC"}}
1618677981.307332: {"jsonrpc":"2.0","method":"updateOrderbook","params":{"ask":[{"price":"0.00011953","size":"0"},{"price":"0.00011955","size":"472.8"},{"price":"0.00011957","size":"183.3"},{"price":"0.00011963","size":"345.5"}],"bid":[],"sequence":19113870,"timestamp":"2021-04-17T16:46:21.170Z","symbol":"XTZBTC"}}
1618677981.317748: {"jsonrpc":"2.0","method":"updateOrderbook","params":{"ask":[{"price":"0.2199817","size":"0"},{"price":"0.2201692","size":"30.51"}],"bid":[],"sequence":4920731,"timestamp":"2021-04-17T16:46:21.182Z","symbol":"BNBETH"}}
1618677981.3905978: {"jsonrpc":"2.0","method":"updateOrderbook","params":{"ask":[],"bid":[{"price":"0.000039661","size":"441.5"},{"price":"0.000039649","size":"1262.0"},{"price":"0.000039644","size":"0"},{"price":"0.000039629","size":"0"}],"sequence":13026921,"timestamp":"2021-04-17T16:46:21.261Z","symbol":"STORJBTC"}}
1618677981.401344: {"jsonrpc":"2.0","method":"updateOrderbook","params":{"ask":[{"price":"0.00011961","size":"345.5"},{"price":"0.00011963","size":"0"},{"price":"0.00012949","size":"0"},{"price":"0.00012968","size":"12500.4"},{"price":"0.00014458","size":"0"},{"price":"0.00014471","size":"17824.4"}],"bid":[],"sequence":19113871,"timestamp":"2021-04-17T16:46:21.330Z","symbol":"XTZBTC"}}
1618677981.412269: {"jsonrpc":"2.0","method":"updateOrderbook","params":{"ask":[{"price":"1.5358029","size":"651"},{"price":"1.5371824","size":"0"}],"bid":[],"sequence":11642081,"timestamp":"2021-04-17T16:46:21.282Z","symbol":"MANAUSD"}}
1618677981.4124281: {"jsonrpc":"2.0","method":"updateOrderbook","params":{"ask":[{"price":"0.2224059","size":"0"},{"price":"0.2225768","size":"7.00"}],"bid":[],"sequence":4920732,"timestamp":"2021-04-17T16:46:21.309Z","symbol":"BNBETH"}}
1618677981.494396: {"jsonrpc":"2.0","method":"updateOrderbook","params":{"ask":[{"price":"0.000040441","size":"13527.3"},{"price":"0.000040543","size":"0"}],"bid":[],"sequence":13026922,"timestamp":"2021-04-17T16:46:21.449Z","symbol":"STORJBTC"}}
1618677981.508319: {"jsonrpc":"2.0","method":"updateOrderbook","params":{"ask":[],"bid":[{"price":"0.00016186","size":"0"},{"price":"0.00016182","size":"10.00"}],"sequence":10038626,"timestamp":"2021-04-17T16:46:21.386Z","symbol":"SUNBTC"}}
1618677981.508608: {"jsonrpc":"2.0","method":"updateOrderbook","params":{"ask":[{"price":"0.00011649","size":"0"},{"price":"0.00011988","size":"0"},{"price":"0.00011995","size":"380.0"},{"price":"0.00012019","size":"1165.8"},{"price":"0.00012031","size":"0"}],"bid":[{"price":"0.00011127","size":"0"},{"price":"0.00011121","size":"380.0"}],"sequence":19113872,"timestamp":"2021-04-17T16:46:21.395Z","symbol":"XTZBTC"}}
1618677981.521388: {"jsonrpc":"2.0","method":"updateOrderbook","params":{"ask":[{"price":"0.2196236","size":"0"},{"price":"0.2197315","size":"23.27"},{"price":"0.2198377","size":"0"},{"price":"0.2199706","size":"28.40"}],"bid":[],"sequence":4920733,"timestamp":"2021-04-17T16:46:21.363Z","symbol":"BNBETH"}}
1618677981.593623: {"jsonrpc":"2.0","method":"updateOrderbook","params":{"ask":[{"price":"0.000026954","size":"0"}],"bid":[{"price":"0.000023967","size":"8.2"}],"sequence":1389819,"timestamp":"2021-04-17T16:46:21.502Z","symbol":"HEDGBTC"}}
1618677981.5937269: {"jsonrpc":"2.0","method":"updateOrderbook","params":{"ask":[{"price":"0.000039816","size":"0"},{"price":"0.000039817","size":"1829.4"},{"price":"0.000039853","size":"0"},{"price":"0.000039855","size":"2594.7"}],"bid":[],"sequence":13026923,"timestamp":"2021-04-17T16:46:21.538Z","symbol":"STORJBTC"}}
1618677981.60727: {"jsonrpc":"2.0","method":"updateOrderbook","params":{"ask":[{"price":"0.00012271","size":"0"},{"price":"0.00012283","size":"11096.2"}],"bid":[],"sequence":19113873,"timestamp":"2021-04-17T16:46:21.539Z","symbol":"XTZBTC"}}
1618677981.695851: {"jsonrpc":"2.0","method":"updateOrderbook","params":{"ask":[{"price":"0.000026952","size":"562.4"},{"price":"0.000026953","size":"0"},{"price":"0.000030785","size":"326.6"}],"bid":[],"sequence":1389820,"timestamp":"2021-04-17T16:46:21.589Z","symbol":"HEDGBTC"}}
1618677981.6960251: {"jsonrpc":"2.0","method":"updateOrderbook","params":{"ask":[{"price":"0.000039853","size":"2594.7"},{"price":"0.000039855","size":"0"}],"bid":[{"price":"0.000038343","size":"156.4"}],"sequence":13026924,"timestamp":"2021-04-17T16:46:21.648Z","symbol":"STORJBTC"}}
1618677981.710909: {"jsonrpc":"2.0","method":"updateOrderbook","params":{"ask":[{"price":"0.00011696","size":"29.1"},{"price":"0.00011887","size":"0"},{"price":"0.00011948","size":"102.6"},{"price":"0.00011952","size":"1337.8"},{"price":"0.00011955","size":"94.0"},{"price":"0.00011958","size":"378.8"},{"price":"0.00012027","size":"0"},{"price":"0.00012035","size":"4799.2"},{"price":"0.00012089","size":"0"},{"price":"0.00012135","size":"4093.4"},{"price":"0.00012179","size":"0"},{"price":"0.00012192","size":"8300.3"},{"price":"0.00012844","size":"7832.8"},{"price":"0.00012859","size":"0"},{"price":"0.00012968","size":"0"},{"price":"0.00012997","size":"12500.4"},{"price":"0.00014177","size":"0"},{"price":"0.00014244","size":"124301.2"},{"price":"0.00014471","size":"0"},{"price":"0.00014487","size":"17824.4"}],"bid":[],"sequence":19113874,"timestamp":"2021-04-17T16:46:21.631Z","symbol":"XTZBTC"}}
1618677981.7181818: {"jsonrpc":"2.0","method":"updateOrderbook","params":{"ask":[],"bid":[{"price":"1.4800150","size":"0"}],"sequence":11642082,"timestamp":"2021-04-17T16:46:21.628Z","symbol":"MANAUSD"}}
1618677981.7859972: {"jsonrpc":"2.0","method":"updateOrderbook","params":{"ask":[{"price":"0.000026951","size":"91.1"},{"price":"0.000030785","size":"0"}],"bid":[],"sequence":1389821,"timestamp":"2021-04-17T16:46:21.732Z","symbol":"HEDGBTC"}}
1618677981.803635: {"jsonrpc":"2.0","method":"updateOrderbook","params":{"ask":[{"price":"0.00133454","size":"0"},{"price":"0.00133461","size":"10.00"}],"bid":[{"price":"0.00016183","size":"10.00"},{"price":"0.00016182","size":"0"}],"sequence":10038627,"timestamp":"2021-04-17T16:46:21.745Z","symbol":"SUNBTC"}}
1618677981.8038242: {"jsonrpc":"2.0","method":"updateOrderbook","params":{"ask":[{"price":"0.00011696","size":"0"},{"price":"0.00011887","size":"29.1"}],"bid":[{"price":"0.00011513","size":"0"},{"price":"0.00011407","size":"40.5"}],"sequence":19113875,"timestamp":"2021-04-17T16:46:21.716Z","symbol":"XTZBTC"}}
1618677981.9101639: {"jsonrpc":"2.0","method":"updateOrderbook","params":{"ask":[],"bid":[{"price":"0.00016184","size":"10.00"},{"price":"0.00016183","size":"0"}],"sequence":10038628,"timestamp":"2021-04-17T16:46:21.775Z","symbol":"SUNBTC"}}
1618677981.910322: {"jsonrpc":"2.0","method":"updateOrderbook","params":{"ask":[{"price":"0.00011948","size":"0"},{"price":"0.00011953","size":"102.6"},{"price":"0.00011958","size":"0"},{"price":"0.00011960","size":"378.8"}],"bid":[{"price":"0.00011513","size":"40.5"},{"price":"0.00011407","size":"0"}],"sequence":19113876,"timestamp":"2021-04-17T16:46:21.817Z","symbol":"XTZBTC"}}
1618677982.001029: {"jsonrpc":"2.0","method":"updateOrderbook","params":{"ask":[],"bid":[{"price":"0.00016185","size":"10.00"},{"price":"0.00016184","size":"0"}],"sequence":10038629,"timestamp":"2021-04-17T16:46:21.909Z","symbol":"SUNBTC"}}
1618677982.001185: {"jsonrpc":"2.0","method":"updateOrderbook","params":{"ask":[{"price":"0.00011696","size":"29.1"},{"price":"0.00011887","size":"0"},{"price":"0.00011942","size":"1876.2"},{"price":"0.00011944","size":"0"},{"price":"0.00011950","size":"728.3"},{"price":"0.00011952","size":"565.8"},{"price":"0.00011956","size":"200.7"},{"price":"0.00011962","size":"2034.5"}],"bid":[],"sequence":19113877,"timestamp":"2021-04-17T16:46:21.928Z","symbol":"XTZBTC"}}
1618677982.10735: {"jsonrpc":"2.0","method":"updateOrderbook","params":{"ask":[],"bid":[{"price":"0.00011513","size":"0"},{"price":"0.00011407","size":"40.5"},{"price":"0.00011121","size":"0"},{"price":"0.00010759","size":"380.0"}],"sequence":19113878,"timestamp":"2021-04-17T16:46:22.033Z","symbol":"XTZBTC"}}
1618677982.109986: {"jsonrpc":"2.0","method":"updateOrderbook","params":{"ask":[{"price":"0.00000120369","size":"0"}],"bid":[],"sequence":5061558,"timestamp":"2021-04-17T16:46:21.992Z","symbol":"CELRBTC"}}
1618677982.118599: {"jsonrpc":"2.0","method":"updateOrderbook","params":{"ask":[],"bid":[{"price":"0.2177505","size":"100.00"},{"price":"0.2176298","size":"0"},{"price":"0.2155021","size":"14.00"},{"price":"0.2154061","size":"7.00"},{"price":"0.2153771","size":"0"},{"price":"0.2152093","size":"0"}],"sequence":4920734,"timestamp":"2021-04-17T16:46:21.966Z","symbol":"BNBETH"}}
1618677982.1863859: {"jsonrpc":"2.0","method":"updateOrderbook","params":{"ask":[{"price":"0.000026952","size":"0"}],"bid":[],"sequence":1389822,"timestamp":"2021-04-17T16:46:22.103Z","symbol":"HEDGBTC"}}
1618677982.2015848: {"jsonrpc":"2.0","method":"updateOrderbook","params":{"ask":[],"bid":[{"price":"0.00016186","size":"10.00"},{"price":"0.00016185","size":"0"}],"sequence":10038630,"timestamp":"2021-04-17T16:46:22.059Z","symbol":"SUNBTC"}}
1618677982.201749: {"jsonrpc":"2.0","method":"updateOrderbook","params":{"ask":[{"price":"0.00011696","size":"0"},{"price":"0.00011887","size":"29.1"},{"price":"0.00011955","size":"277.3"},{"price":"0.00011957","size":"0"},{"price":"0.00011974","size":"0"},{"price":"0.00011981","size":"2394.4"},{"price":"0.00011984","size":"0"},{"price":"0.00011991","size":"3675.0"},{"price":"0.00012035","size":"0"},{"price":"0.00012059","size":"16285.6"},{"price":"0.00012081","size":"0"},{"price":"0.00012090","size":"6070.5"},{"price":"0.00012192","size":"0"},{"price":"0.00012253","size":"8300.3"},{"price":"0.00012997","size":"0"},{"price":"0.00013175","size":"12500.4"},{"price":"0.00014487","size":"0"},{"price":"0.00014572","size":"17824.4"}],"bid":[{"price":"0.00010759","size":"0"},{"price":"0.00010678","size":"380.0"}],"sequence":19113879,"timestamp":"2021-04-17T16:46:22.141Z","symbol":"XTZBTC"}}
1618677982.215389: {"jsonrpc":"2.0","method":"updateOrderbook","params":{"ask":[{"price":"1.8265956","size":"0"},{"price":"1.8360004","size":"9718"},{"price":"1.9511802","size":"0"},{"price":"1.9581138","size":"223070"},{"price":"1.9676432","size":"0"},{"price":"2.0519829","size":"42400"}],"bid":[],"sequence":11642083,"timestamp":"2021-04-17T16:46:22.129Z","symbol":"MANAUSD"}}
1618677982.215602: {"jsonrpc":"2.0","method":"updateOrderbook","params":{"ask":[],"bid":[{"price":"0.2179817","size":"30.51"},{"price":"0.2177557","size":"0"}],"sequence":4920735,"timestamp":"2021-04-17T16:46:22.113Z","symbol":"BNBETH"}}
1618677982.2873678: {"jsonrpc":"2.0","method":"updateOrderbook","params":{"ask":[{"price":"0.000026950","size":"562.4"},{"price":"0.000026951","size":"0"},{"price":"0.000030785","size":"326.6"}],"bid":[],"sequence":1389823,"timestamp":"2021-04-17T16:46:22.213Z","symbol":"HEDGBTC"}}
1618677982.308428: {"jsonrpc":"2.0","method":"updateOrderbook","params":{"ask":[{"price":"0.00011960","size":"0"},{"price":"0.00011963","size":"378.8"},{"price":"0.00011964","size":"356.1"},{"price":"0.00011966","size":"0"},{"price":"0.00011969","size":"358.4"},{"price":"0.00011973","size":"1404.5"},{"price":"0.00011977","size":"3413.5"},{"price":"0.00011981","size":"0"},{"price":"0.00011991","size":"0"},{"price":"0.00011997","size":"2395.4"},{"price":"0.00012059","size":"11486.4"},{"price":"0.00012074","size":"3675.0"},{"price":"0.00012082","size":"6840.5"},{"price":"0.00012090","size":"0"},{"price":"0.00012153","size":"6070.5"},{"price":"0.00012253","size":"0"},{"price":"0.00012510","size":"8300.3"},{"price":"0.00013175","size":"0"},{"price":"0.00013729","size":"12500.4"},{"price":"0.00014572","size":"0"},{"price":"0.00014839","size":"17824.4"}],"bid":[{"price":"0.00011513","size":"40.5"},{"price":"0.00011407","size":"0"}],"sequence":19113880,"timestamp":"2021-04-17T16:46:22.213Z","symbol":"XTZBTC"}}
1618677982.391701: {"jsonrpc":"2.0","method":"updateOrderbook","params":{"ask":[{"price":"0.000026949","size":"91.1"},{"price":"0.000030785","size":"0"}],"bid":[],"sequence":1389824,"timestamp":"2021-04-17T16:46:22.276Z","symbol":"HEDGBTC"}}
1618677982.401983: {"jsonrpc":"2.0","method":"updateOrderbook","params":{"ask":[{"price":"0.00011696","size":"29.1"},{"price":"0.00011887","size":"0"}],"bid":[],"sequence":19113881,"timestamp":"2021-04-17T16:46:22.347Z","symbol":"XTZBTC"}}
1618677982.503793: {"jsonrpc":"2.0","method":"updateOrderbook","params":{"ask":[],"bid":[{"price":"0.00016186","size":"0"},{"price":"0.00016185","size":"10.00"}],"sequence":10038631,"timestamp":"2021-04-17T16:46:22.384Z","symbol":"SUNBTC"}}
1618677982.503951: {"jsonrpc":"2.0","method":"updateOrderbook","params":{"ask":[],"bid":[{"price":"0.00011513","size":"0"},{"price":"0.00011407","size":"40.5"}],"sequence":19113882,"timestamp":"2021-04-17T16:46:22.411Z","symbol":"XTZBTC"}}
1618677982.6056771: {"jsonrpc":"2.0","method":"updateOrderbook","params":{"ask":[],"bid":[{"price":"0.00016185","size":"0"},{"price":"0.00016184","size":"10.00"}],"sequence":10038632,"timestamp":"2021-04-17T16:46:22.474Z","symbol":"SUNBTC"}}
1618677982.6058502: {"jsonrpc":"2.0","method":"updateOrderbook","params":{"ask":[{"price":"0.00011696","size":"0"},{"price":"0.00011887","size":"29.1"},{"price":"0.00011954","size":"200.7"},{"price":"0.00011956","size":"0"}],"bid":[],"sequence":19113883,"timestamp":"2021-04-17T16:46:22.532Z","symbol":"XTZBTC"}}
1618677982.6893928: {"jsonrpc":"2.0","method":"updateOrderbook","params":{"ask":[],"bid":[{"price":"0.000023968","size":"1.2"}],"sequence":1389825,"timestamp":"2021-04-17T16:46:22.646Z","symbol":"HEDGBTC"}}
1618677982.697727: {"jsonrpc":"2.0","method":"updateOrderbook","params":{"ask":[],"bid":[{"price":"0.000039661","size":"0"},{"price":"0.000039649","size":"0"},{"price":"0.000039632","size":"441.5"},{"price":"0.000039597","size":"1262.0"}],"sequence":13026925,"timestamp":"2021-04-17T16:46:22.634Z","symbol":"STORJBTC"}}
1618677982.715192: {"jsonrpc":"2.0","method":"updateOrderbook","params":{"ask":[],"bid":[{"price":"0.00016200","size":"10.00"},{"price":"0.00016184","size":"0"}],"sequence":10038633,"timestamp":"2021-04-17T16:46:22.594Z","symbol":"SUNBTC"}}
1618677982.71535: {"jsonrpc":"2.0","method":"updateOrderbook","params":{"ask":[{"price":"0.00011886","size":"0.4"},{"price":"0.00011962","size":"2413.3"},{"price":"0.00011963","size":"0"},{"price":"0.00012002","size":"0"},{"price":"0.00012017","size":"1253.2"},{"price":"0.00012135","size":"0"},{"price":"0.00012155","size":"4093.4"},{"price":"0.00012844","size":"0"},{"price":"0.00012859","size":"7832.8"}],"bid":[{"price":"0.00011513","size":"40.5"},{"price":"0.00011407","size":"0"},{"price":"0.00011302","size":"88.4"},{"price":"0.00011264","size":"0"}],"sequence":19113884,"timestamp":"2021-04-17T16:46:22.646Z","symbol":"XTZBTC"}}
1618677982.7203798: {"jsonrpc":"2.0","method":"updateOrderbook","params":{"ask":[],"bid":[{"price":"1.4800150","size":"1"}],"sequence":11642084,"timestamp":"2021-04-17T16:46:22.625Z","symbol":"MANAUSD"}}
1618677982.820244: {"jsonrpc":"2.0","method":"updateOrderbook","params":{"ask":[{"price":"0.00011962","size":"3692.9"},{"price":"0.00011968","size":"0"},{"price":"0.00012049","size":"1858.3"},{"price":"0.00012056","size":"0"},{"price":"0.00012059","size":"8993.7"},{"price":"0.00012064","size":"0"},{"price":"0.00012067","size":"0"},{"price":"0.00012072","size":"2492.7"},{"price":"0.00012084","size":"0"},{"price":"0.00012088","size":"3122.5"},{"price":"0.00012092","size":"2525.5"},{"price":"0.00012096","size":"6209.6"},{"price":"0.00012168","size":"3572.8"},{"price":"0.00012193","size":"0"}],"bid":[],"sequence":19113885,"timestamp":"2021-04-17T16:46:22.687Z","symbol":"XTZBTC"}}
1618677982.888449: {"jsonrpc":"2.0","method":"updateOrderbook","params":{"ask":[],"bid":[{"price":"0.000023968","size":"0"}],"sequence":1389826,"timestamp":"2021-04-17T16:46:22.774Z","symbol":"HEDGBTC"}}
1618677982.888685: {"jsonrpc":"2.0","method":"updateOrderbook","params":{"ask":[{"price":"0.00000000420","size":"811000"},{"price":"0.00000000450","size":"2001000"}],"bid":[{"price":"0.00000000369","size":"2749000"},{"price":"0.00000000359","size":"1000"},{"price":"0.00000000237","size":"11651000"},{"price":"0.00000000230","size":"1000"}],"sequence":1757668,"timestamp":"2021-04-17T16:46:22.809Z","symbol":"BANCABTC"}}
1618677982.91769: {"jsonrpc":"2.0","method":"updateOrderbook","params":{"ask":[{"price":"0.00011696","size":"29.1"},{"price":"0.00011887","size":"0"},{"price":"0.00011968","size":"920.9"},{"price":"0.00011973","size":"483.6"}],"bid":[],"sequence":19113886,"timestamp":"2021-04-17T16:46:22.838Z","symbol":"XTZBTC"}}
1618677982.9248378: {"jsonrpc":"2.0","method":"updateOrderbook","params":{"ask":[],"bid":[{"price":"0.00000117027","size":"0"}],"sequence":5061559,"timestamp":"2021-04-17T16:46:22.840Z","symbol":"CELRBTC"}}
1618677982.924978: {"jsonrpc":"2.0","method":"updateOrderbook","params":{"ask":[{"price":"1.5358029","size":"0"},{"price":"1.5364291","size":"650"},{"price":"1.5396719","size":"295"},{"price":"1.5451278","size":"354"}],"bid":[],"sequence":11642085,"timestamp":"2021-04-17T16:46:22.766Z","symbol":"MANAUSD"}}
1618677982.989641: {"jsonrpc":"2.0","method":"updateOrderbook","params":{"ask":[],"bid":[{"price":"0.000023967","size":"0"}],"sequence":1389827,"timestamp":"2021-04-17T16:46:22.864Z","symbol":"HEDGBTC"}}
1618677983.000208: {"jsonrpc":"2.0","method":"updateOrderbook","params":{"ask":[],"bid":[{"price":"0.000038345","size":"156.4"},{"price":"0.000038343","size":"0"}],"sequence":13026926,"timestamp":"2021-04-17T16:46:22.934Z","symbol":"STORJBTC"}}
1618677983.024343: {"jsonrpc":"2.0","method":"updateOrderbook","params":{"ask":[{"price":"0.00133449","size":"10.00"},{"price":"0.00133461","size":"0"}],"bid":[],"sequence":10038634,"timestamp":"2021-04-17T16:46:22.858Z","symbol":"SUNBTC"}}
1618677983.024501: {"jsonrpc":"2.0","method":"updateOrderbook","params":{"ask":[{"price":"0.00011696","size":"0"},{"price":"0.00011887","size":"29.1"},{"price":"0.00011954","size":"0"},{"price":"0.00011956","size":"200.7"},{"price":"0.00011970","size":"2479.6"},{"price":"0.00011977","size":"1845.7"},{"price":"0.00011986","size":"0"},{"price":"0.00011990","size":"1169.0"}],"bid":[{"price":"0.00011513","size":"0"},{"price":"0.00011407","size":"40.5"}],"sequence":19113887,"timestamp":"2021-04-17T16:46:22.943Z","symbol":"XTZBTC"}}
1618677983.024778: {"jsonrpc":"2.0","method":"updateOrderbook","params":{"ask":[{"price":"1.5364291","size":"0"},{"price":"1.5377321","size":"650"},{"price":"1.5386685","size":"0"},{"price":"1.5394968","size":"39348"},{"price":"1.5396719","size":"294"},{"price":"1.5467610","size":"0"},{"price":"1.5476108","size":"38333"},{"price":"1.5540677","size":"0"},{"price":"1.5555891","size":"36573"},{"price":"1.5627792","size":"0"},{"price":"1.5644611","size":"33819"},{"price":"1.5706704","size":"0"},{"price":"1.5730725","size":"32731"},{"price":"1.5910859","size":"0"},{"price":"1.5933170","size":"36462"},{"price":"1.6123949","size":"0"},{"price":"1.6139945","size":"37094"}],"bid":[],"sequence":11642086,"timestamp":"2021-04-17T16:46:22.948Z","symbol":"MANAUSD"}}
1618677983.117289: {"jsonrpc":"2.0","method":"updateOrderbook","params":{"ask":[{"price":"0.00011942","size":"286.5"},{"price":"0.00011944","size":"251.9"},{"price":"0.00011950","size":"0"},{"price":"0.00011952","size":"1337.8"},{"price":"0.00011956","size":"929.0"},{"price":"0.00011962","size":"2979.1"},{"price":"0.00011965","size":"1576.3"},{"price":"0.00011986","size":"380.0"},{"price":"0.00011995","size":"0"}],"bid":[{"price":"0.00011513","size":"40.5"},{"price":"0.00011407","size":"0"}],"sequence":19113888,"timestamp":"2021-04-17T16:46:23.046Z","symbol":"XTZBTC"}}
1618677983.194589: {"jsonrpc":"2.0","method":"updateOrderbook","params":{"ask":[{"price":"0.000026950","size":"0"}],"bid":[],"sequence":1389828,"timestamp":"2021-04-17T16:46:23.079Z","symbol":"HEDGBTC"}}
1618677983.2067719: {"jsonrpc":"2.0","method":"updateOrderbook","params":{"ask":[],"bid":[{"price":"0.000039632","size":"0"},{"price":"0.000039630","size":"441.5"},{"price":"0.000038345","size":"0"}],"sequence":13026927,"timestamp":"2021-04-17T16:46:23.128Z","symbol":"STORJBTC"}}
1618677983.2070441: {"jsonrpc":"2.0","method":"updateOrderbook","params":{"ask":[{"price":"0.00011978","size":"1720.5"},{"price":"0.00011980","size":"32.0"},{"price":"0.00011983","size":"2394.4"},{"price":"0.00011997","size":"1.0"}],"bid":[],"sequence":19113889,"timestamp":"2021-04-17T16:46:23.147Z","symbol":"XTZBTC"}}
1618677983.2135282: {"jsonrpc":"2.0","method":"updateOrderbook","params":{"ask":[],"bid":[{"price":"0.00000117031","size":"1490"},{"price":"0.00000117028","size":"0"},{"price":"0.00000115071","size":"810"}],"sequence":5061560,"timestamp":"2021-04-17T16:46:23.083Z","symbol":"CELRBTC"}}
1618677983.2969542: {"jsonrpc":"2.0","method":"updateOrderbook","params":{"ask":[{"price":"0.000026948","size":"562.4"},{"price":"0.000026949","size":"0"},{"price":"0.000030785","size":"326.6"}],"bid":[],"sequence":1389829,"timestamp":"2021-04-17T16:46:23.187Z","symbol":"HEDGBTC"}}
1618677983.297128: {"jsonrpc":"2.0","method":"updateOrderbook","params":{"ask":[],"bid":[{"price":"0.000039661","size":"441.5"},{"price":"0.000039649","size":"1262.0"},{"price":"0.000039630","size":"0"},{"price":"0.000039597","size":"0"},{"price":"0.000038349","size":"156.4"}],"sequence":13026928,"timestamp":"2021-04-17T16:46:23.220Z","symbol":"STORJBTC"}}
1618677983.313123: {"jsonrpc":"2.0","method":"updateOrderbook","params":{"ask":[],"bid":[],"sequence":11642087,"timestamp":"2021-04-17T16:46:23.237Z","symbol":"MANAUSD"}}
1618677983.387237: {"jsonrpc":"2.0","method":"updateOrderbook","params":{"ask":[{"price":"0.000026947","size":"91.1"},{"price":"0.000030785","size":"0"}],"bid":[{"price":"0.000023962","size":"27.6"}],"sequence":1389830,"timestamp":"2021-04-17T16:46:23.276Z","symbol":"HEDGBTC"}}
1618677983.4159381: {"jsonrpc":"2.0","method":"updateOrderbook","params":{"ask":[{"price":"0.000039853","size":"0"},{"price":"0.000039855","size":"2594.7"}],"bid":[{"price":"0.000038349","size":"0"},{"price":"0.000038343","size":"156.4"}],"sequence":13026929,"timestamp":"2021-04-17T16:46:23.336Z","symbol":"STORJBTC"}}
1618677983.4161391: {"jsonrpc":"2.0","method":"updateOrderbook","params":{"ask":[],"bid":[{"price":"0.00021324","size":"5.79"},{"price":"0.00019285","size":"0"}],"sequence":10038635,"timestamp":"2021-04-17T16:46:23.312Z","symbol":"SUNBTC"}}
1618677983.416219: {"jsonrpc":"2.0","method":"updateOrderbook","params":{"ask":[{"price":"0.00011949","size":"183.3"},{"price":"0.00011953","size":"322.0"},{"price":"0.00011955","size":"94.0"},{"price":"0.00011962","size":"2759.7"},{"price":"0.00011973","size":"2329.3"},{"price":"0.00011977","size":"0"}],"bid":[{"price":"0.00010678","size":"0"},{"price":"0.00010669","size":"380.0"}],"sequence":19113890,"timestamp":"2021-04-17T16:46:23.320Z","symbol":"XTZBTC"}}
1618677983.416351: {"jsonrpc":"2.0","method":"updateOrderbook","params":{"ask":[],"bid":[{"price":"0.00000117029","size":"790"},{"price":"0.00000115071","size":"0"}],"sequence":5061561,"timestamp":"2021-04-17T16:46:23.329Z","symbol":"CELRBTC"}}
1618677983.499797: {"jsonrpc":"2.0","method":"updateOrderbook","params":{"ask":[{"price":"0.00011952","size":"1431.8"},{"price":"0.00011953","size":"102.6"},{"price":"0.00011955","size":"219.4"},{"price":"0.00011986","size":"1545.1"},{"price":"0.00011990","size":"3.9"},{"price":"0.00012013","size":"1550.2"},{"price":"0.00012016","size":"0"},{"price":"0.00012026","size":"8091.4"},{"price":"0.00012074","size":"0"}],"bid":[],"sequence":19113891,"timestamp":"2021-04-17T16:46:23.420Z","symbol":"XTZBTC"}}
1618677983.508478: {"jsonrpc":"2.0","method":"updateOrderbook","params":{"ask":[{"price":"0.00000120445","size":"9410"}],"bid":[],"sequence":5061562,"timestamp":"2021-04-17T16:46:23.416Z","symbol":"CELRBTC"}}
1618677983.5979269: {"jsonrpc":"2.0","method":"updateOrderbook","params":{"ask":[{"price":"0.000040052","size":"0"},{"price":"0.000040079","size":"6736.1"},{"price":"0.000040206","size":"0"},{"price":"0.000040235","size":"9299.9"},{"price":"0.000040441","size":"0"},{"price":"0.000040479","size":"13527.3"}],"bid":[],"sequence":13026930,"timestamp":"2021-04-17T16:46:23.509Z","symbol":"STORJBTC"}}
1618677983.6040819: {"jsonrpc":"2.0","method":"updateOrderbook","params":{"ask":[{"price":"0.00011942","size":"1876.2"},{"price":"0.00011944","size":"0"},{"price":"0.00011950","size":"728.3"},{"price":"0.00011952","size":"659.8"},{"price":"0.00011956","size":"200.7"},{"price":"0.00011962","size":"2193.9"}],"bid":[{"price":"0.00011514","size":"0.2"}],"sequence":19113892,"timestamp":"2021-04-17T16:46:23.500Z","symbol":"XTZBTC"}}
1618677983.610889: {"jsonrpc":"2.0","method":"updateOrderbook","params":{"ask":[],"bid":[{"price":"0.00000117032","size":"780"},{"price":"0.00000117029","size":"0"}],"sequence":5061563,"timestamp":"2021-04-17T16:46:23.521Z","symbol":"CELRBTC"}}
1618677983.616287: {"jsonrpc":"2.0","method":"updateOrderbook","params":{"ask":[],"bid":[{"price":"0.2176143","size":"200.00"},{"price":"0.2174938","size":"0"}],"sequence":4920736,"timestamp":"2021-04-17T16:46:23.514Z","symbol":"BNBETH"}}
1618677983.690503: {"jsonrpc":"2.0","method":"updateOrderbook","params":{"ask":[],"bid":[{"price":"0.000023963","size":"1.2"}],"sequence":1389831,"timestamp":"2021-04-17T16:46:23.632Z","symbol":"HEDGBTC"}}
1618677983.6936781: {"jsonrpc":"2.0","method":"updateOrderbook","params":{"ask":[],"bid":[{"price":"0.000038343","size":"0"}],"sequence":13026931,"timestamp":"2021-04-17T16:46:23.596Z","symbol":"STORJBTC"}}
1618677983.710186: {"jsonrpc":"2.0","method":"updateOrderbook","params":{"ask":[{"price":"0.00011949","size":"0"},{"price":"0.00011952","size":"565.8"},{"price":"0.00011953","size":"285.9"},{"price":"0.00011955","size":"0"},{"price":"0.00011957","size":"94.0"},{"price":"0.00011959","size":"463.9"},{"price":"0.00012012","size":"2137.2"},{"price":"0.00012017","size":"0"},{"price":"0.00012019","size":"0"},{"price":"0.00012031","size":"1165.8"},{"price":"0.00012140","size":"4095.4"},{"price":"0.00012155","size":"0"},{"price":"0.00014777","size":"5176.4"},{"price":"0.00014817","size":"0"}],"bid":[],"sequence":19113893,"timestamp":"2021-04-17T16:46:23.649Z","symbol":"XTZBTC"}}
1618677983.8055649: {"jsonrpc":"2.0","method":"updateOrderbook","params":{"ask":[],"bid":[{"price":"0.000023963","size":"0"}],"sequence":1389832,"timestamp":"2021-04-17T16:46:23.739Z","symbol":"HEDGBTC"}}
1618677983.8058171: {"jsonrpc":"2.0","method":"updateOrderbook","params":{"ask":[],"bid":[{"price":"0.000038345","size":"156.4"},{"price":"0.000038341","size":"0"},{"price":"0.000038340","size":"0"},{"price":"0.000035192","size":"1600.0"}],"sequence":13026932,"timestamp":"2021-04-17T16:46:23.684Z","symbol":"STORJBTC"}}
1618677983.818002: {"jsonrpc":"2.0","method":"updateOrderbook","params":{"ask":[{"price":"0.00012034","size":"3307.4"},{"price":"0.00012038","size":"2033.5"},{"price":"0.00012041","size":"2253.6"},{"price":"0.00012042","size":"5128.5"},{"price":"0.00012046","size":"0"},{"price":"0.00012047","size":"6921.6"},{"price":"0.00012058","size":"2492.7"},{"price":"0.00012063","size":"3122.5"},{"price":"0.00012067","size":"2525.5"},{"price":"0.00012072","size":"0"},{"price":"0.00012079","size":"3288.1"},{"price":"0.00012088","size":"0"},{"price":"0.00012092","size":"0"},{"price":"0.00012096","size":"2921.5"},{"price":"0.00012108","size":"6070.5"},{"price":"0.00012153","size":"0"},{"price":"0.00012371","size":"8300.3"},{"price":"0.00012510","size":"0"}],"bid":[{"price":"0.00011514","size":"0"}],"sequence":19113894,"timestamp":"2021-04-17T16:46:23.735Z","symbol":"XTZBTC"}}
1618677983.8898811: {"jsonrpc":"2.0","method":"updateOrderbook","params":{"ask":[{"price":"0.000026948","size":"0"}],"bid":[],"sequence":1389833,"timestamp":"2021-04-17T16:46:23.846Z","symbol":"HEDGBTC"}}
1618677983.912731: {"jsonrpc":"2.0","method":"updateOrderbook","params":{"ask":[{"price":"0.00011886","size":"22.2"},{"price":"0.00011983","size":"3559.5"},{"price":"0.00011986","size":"380.0"},{"price":"0.00012845","size":"7832.8"},{"price":"0.00012859","size":"0"}],"bid":[],"sequence":19113895,"timestamp":"2021-04-17T16:46:23.835Z","symbol":"XTZBTC"}}
1618677983.917848: {"jsonrpc":"2.0","method":"updateOrderbook","params":{"ask":[],"bid":[{"price":"0.2174423","size":"300.00"},{"price":"0.2172831","size":"0"}],"sequence":4920737,"timestamp":"2021-04-17T16:46:23.797Z","symbol":"BNBETH"}}
1618677983.989407: {"jsonrpc":"2.0","method":"updateOrderbook","params":{"ask":[{"price":"0.000026946","size":"562.4"},{"price":"0.000026947","size":"0"},{"price":"0.000030785","size":"326.6"}],"bid":[],"sequence":1389834,"timestamp":"2021-04-17T16:46:23.928Z","symbol":"HEDGBTC"}}
1618677984.0117629: {"jsonrpc":"2.0","method":"updateOrderbook","params":{"ask":[{"price":"0.00011696","size":"29.1"},{"price":"0.00011887","size":"0"}],"bid":[],"sequence":19113896,"timestamp":"2021-04-17T16:46:23.928Z","symbol":"XTZBTC"}}
1618677984.168239: {"jsonrpc":"2.0","method":"updateOrderbook","params":{"ask":[{"price":"0.000026945","size":"91.1"},{"price":"0.000030785","size":"0"}],"bid":[],"sequence":1389835,"timestamp":"2021-04-17T16:46:23.992Z","symbol":"HEDGBTC"}}
1618677984.168399: {"jsonrpc":"2.0","method":"updateOrderbook","params":{"ask":[{"price":"0.000039973","size":"0"},{"price":"0.000039986","size":"0"},{"price":"0.000040013","size":"599.0"},{"price":"0.000040063","size":"738.1"}],"bid":[],"sequence":13026933,"timestamp":"2021-04-17T16:46:23.951Z","symbol":"STORJBTC"}}
1618677984.168509: {"jsonrpc":"2.0","method":"updateOrderbook","params":{"ask":[],"bid":[{"price":"0.00016201","size":"10.00"},{"price":"0.00016200","size":"0"}],"sequence":10038636,"timestamp":"2021-04-17T16:46:24.009Z","symbol":"SUNBTC"}}
1618677984.168581: {"jsonrpc":"2.0","method":"updateOrderbook","params":{"ask":[{"price":"0.00011696","size":"0"},{"price":"0.00011887","size":"29.1"},{"price":"0.00013152","size":"12500.4"},{"price":"0.00013729","size":"0"},{"price":"0.00014419","size":"17824.4"},{"price":"0.00014839","size":"0"}],"bid":[{"price":"0.00011513","size":"0"},{"price":"0.00011407","size":"40.5"}],"sequence":19113897,"timestamp":"2021-04-17T16:46:24.006Z","symbol":"XTZBTC"}}
1618677984.2095659: {"jsonrpc":"2.0","method":"updateOrderbook","params":{"ask":[{"price":"0.000039779","size":"0"},{"price":"0.000039783","size":"431.7"},{"price":"0.000039817","size":"0"},{"price":"0.000039824","size":"1829.4"},{"price":"0.000039855","size":"0"},{"price":"0.000039862","size":"2594.7"},{"price":"0.000039909","size":"0"},{"price":"0.000039912","size":"3633.3"},{"price":"0.000039960","size":"0"},{"price":"0.000039966","size":"3785.4"}],"bid":[],"sequence":13026934,"timestamp":"2021-04-17T16:46:24.065Z","symbol":"STORJBTC"}}
1618677984.216513: {"jsonrpc":"2.0","method":"updateOrderbook","params":{"ask":[{"price":"0.00012075","size":"4799.2"},{"price":"0.00012082","size":"2041.3"},{"price":"0.00013152","size":"0"},{"price":"0.00013163","size":"12500.4"},{"price":"0.00014419","size":"0"},{"price":"0.00014437","size":"17824.4"}],"bid":[{"price":"0.00011513","size":"40.5"},{"price":"0.00011407","size":"0"}],"sequence":19113898,"timestamp":"2021-04-17T16:46:24.143Z","symbol":"XTZBTC"}}
1618677984.3050969: {"jsonrpc":"2.0","method":"updateOrderbook","params":{"ask":[{"price":"0.00011949","size":"102.6"},{"price":"0.00011953","size":"183.3"},{"price":"0.00011954","size":"378.8"},{"price":"0.00011962","size":"1815.1"},{"price":"0.00011983","size":"2394.4"},{"price":"0.00011988","size":"1165.1"},{"price":"0.00012013","size":"0"},{"price":"0.00012018","size":"1550.2"}],"bid":[{"price":"0.00011406","size":"0"}],"sequence":19113899,"timestamp":"2021-04-17T16:46:24.239Z","symbol":"XTZBTC"}}
1618677984.398381: {"jsonrpc":"2.0","method":"updateOrderbook","params":{"ask":[{"price":"0.000039972","size":"0"},{"price":"0.000040002","size":"780.0"}],"bid":[],"sequence":13026935,"timestamp":"2021-04-17T16:46:24.333Z","symbol":"STORJBTC"}}
1618677984.405798: {"jsonrpc":"2.0","method":"updateOrderbook","params":{"ask":[],"bid":[{"price":"0.00011408","size":"734.0"}],"sequence":19113900,"timestamp":"2021-04-17T16:46:24.307Z","symbol":"XTZBTC"}}
1618677984.489441: {"jsonrpc":"2.0","method":"updateOrderbook","params":{"ask":[{"price":"0.000026946","size":"0"}],"bid":[],"sequence":1389836,"timestamp":"2021-04-17T16:46:24.442Z","symbol":"HEDGBTC"}}
1618677984.49774: {"jsonrpc":"2.0","method":"updateOrderbook","params":{"ask":[{"price":"0.000039855","size":"2594.7"},{"price":"0.000039862","size":"0"},{"price":"0.000039909","size":"3633.3"},{"price":"0.000039912","size":"0"},{"price":"0.000039961","size":"3785.4"},{"price":"0.000039966","size":"0"},{"price":"0.000040216","size":"1242.8"},{"price":"0.000040510","size":"0"}],"bid":[],"sequence":13026936,"timestamp":"2021-04-17T16:46:24.435Z","symbol":"STORJBTC"}}
1618677984.507806: {"jsonrpc":"2.0","method":"updateOrderbook","params":{"ask":[{"price":"0.00133449","size":"0"},{"price":"0.00133461","size":"10.00"}],"bid":[],"sequence":10038637,"timestamp":"2021-04-17T16:46:24.388Z","symbol":"SUNBTC"}}
1618677984.521902: {"jsonrpc":"2.0","method":"updateOrderbook","params":{"ask":[{"price":"1.5189249","size":"33335"},{"price":"1.5194321","size":"0"}],"bid":[],"sequence":11642088,"timestamp":"2021-04-17T16:46:24.418Z","symbol":"MANAUSD"}}
1618677984.588675: {"jsonrpc":"2.0","method":"updateOrderbook","params":{"ask":[{"price":"0.000026944","size":"562.4"},{"price":"0.000026945","size":"0"},{"price":"0.000030785","size":"326.6"}],"bid":[],"sequence":1389837,"timestamp":"2021-04-17T16:46:24.528Z","symbol":"HEDGBTC"}}
1618677984.594935: {"jsonrpc":"2.0","method":"updateOrderbook","params":{"ask":[{"price":"0.000039783","size":"0"},{"price":"0.000039790","size":"431.7"},{"price":"0.000039824","size":"0"},{"price":"0.000039831","size":"1829.4"},{"price":"0.000039855","size":"0"},{"price":"0.000039871","size":"2594.7"},{"price":"0.000039909","size":"0"},{"price":"0.000039915","size":"7445.6"},{"price":"0.000039961","size":"0"},{"price":"0.000039972","size":"3785.4"}],"bid":[],"sequence":13026937,"timestamp":"2021-04-17T16:46:24.473Z","symbol":"STORJBTC"}}
1618677984.615367: {"jsonrpc":"2.0","method":"updateOrderbook","params":{"ask":[],"bid":[{"price":"0.00016202","size":"10.00"},{"price":"0.00016201","size":"0"}],"sequence":10038638,"timestamp":"2021-04-17T16:46:24.482Z","symbol":"SUNBTC"}}
1618677984.615527: {"jsonrpc":"2.0","method":"updateOrderbook","params":{"ask":[{"price":"0.00011963","size":"920.9"},{"price":"0.00011968","size":"0"}],"bid":[{"price":"0.00011514","size":"0.2"},{"price":"0.00010669","size":"0"},{"price":"0.00010288","size":"380.0"},{"price":"0.00007346","size":"9174.5"},{"price":"0.00007269","size":"0"}],"sequence":19113901,"timestamp":"2021-04-17T16:46:24.547Z","symbol":"XTZBTC"}}
1618677984.69713: {"jsonrpc":"2.0","method":"updateOrderbook","params":{"ask":[{"price":"0.000026943","size":"91.1"},{"price":"0.000030785","size":"0"}],"bid":[{"price":"0.000023963","size":"1.2"}],"sequence":1389838,"timestamp":"2021-04-17T16:46:24.644Z","symbol":"HEDGBTC"}}
1618677984.729634: {"jsonrpc":"2.0","method":"updateOrderbook","params":{"ask":[{"price":"0.2199753","size":"0"},{"price":"0.2200852","size":"200.00"}],"bid":[],"sequence":4920738,"timestamp":"2021-04-17T16:46:24.571Z","symbol":"BNBETH"}}
1618677984.901512: {"jsonrpc":"2.0","method":"updateOrderbook","params":{"ask":[{"price":"0.000039825","size":"261.3"},{"price":"0.000039832","size":"0"}],"bid":[],"sequence":13026938,"timestamp":"2021-04-17T16:46:24.838Z","symbol":"STORJBTC"}}
1618677984.91013: {"jsonrpc":"2.0","method":"updateOrderbook","params":{"ask":[{"price":"0.00011955","size":"94.0"},{"price":"0.00011957","size":"0"},{"price":"0.00012015","size":"1550.2"},{"price":"0.00012018","size":"0"}],"bid":[],"sequence":19113902,"timestamp":"2021-04-17T16:46:24.829Z","symbol":"XTZBTC"}}
1618677985.004064: {"jsonrpc":"2.0","method":"updateOrderbook","params":{"ask":[],"bid":[{"price":"0.00016202","size":"0"},{"price":"0.00016201","size":"10.00"}],"sequence":10038639,"timestamp":"2021-04-17T16:46:24.927Z","symbol":"SUNBTC"}}
1618677985.004221: {"jsonrpc":"2.0","method":"updateOrderbook","params":{"ask":[{"price":"0.00011975","size":"2394.4"},{"price":"0.00011983","size":"0"}],"bid":[],"sequence":19113903,"timestamp":"2021-04-17T16:46:24.879Z","symbol":"XTZBTC"}}
1618677985.0159428: {"jsonrpc":"2.0","method":"updateOrderbook","params":{"ask":[],"bid":[{"price":"0.00000078330","size":"0"}],"sequence":5061564,"timestamp":"2021-04-17T16:46:24.933Z","symbol":"CELRBTC"}}
1618677985.0160818: {"jsonrpc":"2.0","method":"updateOrderbook","params":{"ask":[],"bid":[{"price":"1.3103854","size":"5289"},{"price":"1.3092753","size":"0"}],"sequence":11642089,"timestamp":"2021-04-17T16:46:24.902Z","symbol":"MANAUSD"}}
1618677985.087733: {"jsonrpc":"2.0","method":"updateOrderbook","params":{"ask":[],"bid":[{"price":"0.000023962","size":"19.4"}],"sequence":1389839,"timestamp":"2021-04-17T16:46:24.962Z","symbol":"HEDGBTC"}}
1618677985.0980082: {"jsonrpc":"2.0","method":"updateOrderbook","params":{"ask":[{"price":"0.000039865","size":"2594.7"},{"price":"0.000039871","size":"0"},{"price":"0.000039912","size":"3633.3"},{"price":"0.000039915","size":"3812.3"},{"price":"0.000039967","size":"3785.4"},{"price":"0.000039972","size":"0"},{"price":"0.000040301","size":"1551.8"},{"price":"0.000040313","size":"2058.7"},{"price":"0.000041224","size":"0"},{"price":"0.000041770","size":"0"}],"bid":[{"price":"0.000038349","size":"156.4"},{"price":"0.000038345","size":"0"}],"sequence":13026939,"timestamp":"2021-04-17T16:46:25.038Z","symbol":"STORJBTC"}}
1618677985.110341: {"jsonrpc":"2.0","method":"updateOrderbook","params":{"ask":[{"price":"0.00011961","size":"920.9"},{"price":"0.00011963","size":"345.5"},{"price":"0.00011973","size":"483.6"},{"price":"0.00011975","size":"0"},{"price":"0.00011988","size":"3010.8"},{"price":"0.00012012","size":"884.0"},{"price":"0.00012020","size":"1253.2"},{"price":"0.00012021","size":"2394.4"},{"price":"0.00012026","size":"4416.4"},{"price":"0.00012075","size":"0"},{"price":"0.00012076","size":"3675.0"},{"price":"0.00012087","size":"4799.2"},{"price":"0.00012108","size":"0"},{"price":"0.00012140","size":"2.0"},{"price":"0.00012162","size":"4093.4"},{"price":"0.00012170","size":"6070.5"},{"price":"0.00012371","size":"0"},{"price":"0.00012596","size":"8300.3"},{"price":"0.00012845","size":"0"},{"price":"0.00012862","size":"7832.8"},{"price":"0.00013163","size":"0"},{"price":"0.00013626","size":"12500.4"},{"price":"0.00014437","size":"0"},{"price":"0.00014709","size":"17824.4"}],"bid":[],"sequence":19113904,"timestamp":"2021-04-17T16:46:25.044Z","symbol":"XTZBTC"}}
1618677985.110754: {"jsonrpc":"2.0","method":"updateOrderbook","params":{"ask":[],"bid":[{"price":"1.4800150","size":"0"},{"price":"1.3103854","size":"0"},{"price":"1.3086553","size":"5290"}],"sequence":11642090,"timestamp":"2021-04-17T16:46:24.969Z","symbol":"MANAUSD"}}
1618677985.199848: {"jsonrpc":"2.0","method":"updateOrderbook","params":{"ask":[{"price":"0.00000000420","size":"0"},{"price":"0.00000000450","size":"2812000"}],"bid":[{"price":"0.00000000369","size":"310000"},{"price":"0.00000000359","size":"2440000"},{"price":"0.00000000237","size":"1000"},{"price":"0.00000000230","size":"11651000"}],"sequence":1757669,"timestamp":"2021-04-17T16:46:25.138Z","symbol":"BANCABTC"}}
1618677985.200037: {"jsonrpc":"2.0","method":"updateOrderbook","params":{"ask":[],"bid":[{"price":"0.000038349","size":"0"}],"sequence":13026940,"timestamp":"2021-04-17T16:46:25.133Z","symbol":"STORJBTC"}}
1618677985.21052: {"jsonrpc":"2.0","method":"updateOrderbook","params":{"ask":[],"bid":[{"price":"0.00010542","size":"0"}],"sequence":19113905,"timestamp":"2021-04-17T16:46:25.146Z","symbol":"XTZBTC"}}
1618677985.214166: {"jsonrpc":"2.0","method":"updateOrderbook","params":{"ask":[],"bid":[{"price":"0.00000044760","size":"0"}],"sequence":5061565,"timestamp":"2021-04-17T16:46:25.052Z","symbol":"CELRBTC"}}
1618677985.3063731: {"jsonrpc":"2.0","method":"updateOrderbook","params":{"ask":[],"bid":[{"price":"0.000038344","size":"1564.7"},{"price":"0.000038015","size":"157.8"}],"sequence":13026941,"timestamp":"2021-04-17T16:46:25.182Z","symbol":"STORJBTC"}}
1618677985.322151: {"jsonrpc":"2.0","method":"updateOrderbook","params":{"ask":[{"price":"0.00011955","size":"1018.8"},{"price":"0.00011962","size":"2169.9"},{"price":"0.00011965","size":"296.7"}],"bid":[{"price":"0.00011408","size":"0"}],"sequence":19113906,"timestamp":"2021-04-17T16:46:25.190Z","symbol":"XTZBTC"}}
1618677985.322324: {"jsonrpc":"2.0","method":"updateOrderbook","params":{"ask":[{"price":"1.5382969","size":"0"}],"bid":[],"sequence":11642091,"timestamp":"2021-04-17T16:46:25.203Z","symbol":"MANAUSD"}}
1618677985.389611: {"jsonrpc":"2.0","method":"updateOrderbook","params":{"ask":[{"price":"0.000026944","size":"0"}],"bid":[],"sequence":1389840,"timestamp":"2021-04-17T16:46:25.262Z","symbol":"HEDGBTC"}}
1618677985.394997: {"jsonrpc":"2.0","method":"updateOrderbook","params":{"ask":[{"price":"0.000039783","size":"431.7"},{"price":"0.000039790","size":"0"},{"price":"0.000039827","size":"1829.4"},{"price":"0.000039831","size":"0"},{"price":"0.000039857","size":"2594.7"},{"price":"0.000039865","size":"0"},{"price":"0.000039962","size":"3785.4"},{"price":"0.000039967","size":"0"}],"bid":[{"price":"0.000038017","size":"157.8"},{"price":"0.000038015","size":"0"}],"sequence":13026942,"timestamp":"2021-04-17T16:46:25.348Z","symbol":"STORJBTC"}}
1618677985.402803: {"jsonrpc":"2.0","method":"updateOrderbook","params":{"ask":[],"bid":[{"price":"0.00011512","size":"0"},{"price":"0.00011406","size":"734.1"}],"sequence":19113907,"timestamp":"2021-04-17T16:46:25.300Z","symbol":"XTZBTC"}}
1618677985.406333: {"jsonrpc":"2.0","method":"updateOrderbook","params":{"ask":[{"price":"1.5365551","size":"5"}],"bid":[],"sequence":11642092,"timestamp":"2021-04-17T16:46:25.267Z","symbol":"MANAUSD"}}
1618677985.488595: {"jsonrpc":"2.0","method":"updateOrderbook","params":{"ask":[{"price":"0.000026942","size":"562.4"}],"bid":[{"price":"0.000023963","size":"9.4"}],"sequence":1389841,"timestamp":"2021-04-17T16:46:25.360Z","symbol":"HEDGBTC"}}
1618677985.499907: {"jsonrpc":"2.0","method":"updateOrderbook","params":{"ask":[{"price":"0.000040945","size":"2812.0"},{"price":"0.000042195","size":"0"}],"bid":[],"sequence":13026943,"timestamp":"2021-04-17T16:46:25.395Z","symbol":"STORJBTC"}}
1618677985.505184: {"jsonrpc":"2.0","method":"updateOrderbook","params":{"ask":[],"bid":[{"price":"0.00011515","size":"40.5"},{"price":"0.00011513","size":"0"}],"sequence":19113908,"timestamp":"2021-04-17T16:46:25.401Z","symbol":"XTZBTC"}}
1618677985.58692: {"jsonrpc":"2.0","method":"updateOrderbook","params":{"ask":[{"price":"0.000026941","size":"91.1"},{"price":"0.000026943","size":"0"}],"bid":[],"sequence":1389842,"timestamp":"2021-04-17T16:46:25.516Z","symbol":"HEDGBTC"}}
1618677985.601704: {"jsonrpc":"2.0","method":"updateOrderbook","params":{"ask":[{"price":"0.00011984","size":"1165.1"},{"price":"0.00011988","size":"1845.7"}],"bid":[],"sequence":19113909,"timestamp":"2021-04-17T16:46:25.523Z","symbol":"XTZBTC"}}
1618677985.711521: {"jsonrpc":"2.0","method":"updateOrderbook","params":{"ask":[],"bid":[{"price":"0.000038017","size":"0"}],"sequence":13026944,"timestamp":"2021-04-17T16:46:25.647Z","symbol":"STORJBTC"}}
1618677985.711663: {"jsonrpc":"2.0","method":"updateOrderbook","params":{"ask":[{"price":"0.00133405","size":"10.00"},{"price":"0.00133461","size":"0"}],"bid":[],"sequence":10038640,"timestamp":"2021-04-17T16:46:25.587Z","symbol":"SUNBTC"}}
1618677985.7117498: {"jsonrpc":"2.0","method":"updateOrderbook","params":{"ask":[],"bid":[{"price":"1.4800150","size":"1"}],"sequence":11642093,"timestamp":"2021-04-17T16:46:25.552Z","symbol":"MANAUSD"}}
1618677985.7898262: {"jsonrpc":"2.0","method":"updateOrderbook","params":{"ask":[{"price":"0.000039880","size":"0"},{"price":"0.000039893","size":"2795.3"}],"bid":[{"price":"0.000038346","size":"156.4"}],"sequence":13026945,"timestamp":"2021-04-17T16:46:25.725Z","symbol":"STORJBTC"}}
1618677985.80271: {"jsonrpc":"2.0","method":"updateOrderbook","params":{"ask":[{"price":"0.00011964","size":"1923.9"},{"price":"0.00011965","size":"2017.2"},{"price":"0.00011970","size":"911.8"},{"price":"0.00011978","size":"0"},{"price":"0.00011979","size":"2053.5"},{"price":"0.00011982","size":"4927.2"},{"price":"0.00011984","size":"3261.3"},{"price":"0.00011992","size":"784.6"},{"price":"0.00011993","size":"3485.4"},{"price":"0.00011998","size":"0"},{"price":"0.00012006","size":"3537.9"},{"price":"0.00012009","size":"0"},{"price":"0.00012021","size":"6810.8"},{"price":"0.00012026","size":"0"}],"bid":[],"sequence":19113910,"timestamp":"2021-04-17T16:46:25.728Z","symbol":"XTZBTC"}}
1618677985.908851: {"jsonrpc":"2.0","method":"updateOrderbook","params":{"ask":[],"bid":[{"price":"0.00021324","size":"0"},{"price":"0.00014209","size":"5.79"}],"sequence":10038641,"timestamp":"2021-04-17T16:46:25.772Z","symbol":"SUNBTC"}}
1618677985.909013: {"jsonrpc":"2.0","method":"updateOrderbook","params":{"ask":[{"price":"0.00011948","size":"183.3"},{"price":"0.00011953","size":"0"}],"bid":[],"sequence":19113911,"timestamp":"2021-04-17T16:46:25.809Z","symbol":"XTZBTC"}}
1618677985.988797: {"jsonrpc":"2.0","method":"updateOrderbook","params":{"ask":[{"price":"0.000040216","size":"0"},{"price":"0.000040289","size":"1242.8"},{"price":"0.000040313","size":"0"},{"price":"0.000040442","size":"2058.7"},{"price":"0.000040945","size":"0"},{"price":"0.000041371","size":"2812.0"}],"bid":[],"sequence":13026946,"timestamp":"2021-04-17T16:46:25.948Z","symbol":"STORJBTC"}}
1618677985.996939: {"jsonrpc":"2.0","method":"updateOrderbook","params":{"ask":[{"price":"0.00011948","size":"0"},{"price":"0.00011953","size":"183.3"},{"price":"0.00011961","size":"0"},{"price":"0.00011963","size":"1266.4"},{"price":"0.00011964","size":"356.1"},{"price":"0.00011972","size":"1567.8"},{"price":"0.00012021","size":"4416.4"},{"price":"0.00012026","size":"2394.4"},{"price":"0.00012596","size":"0"},{"price":"0.00012612","size":"8300.3"}],"bid":[],"sequence":19113912,"timestamp":"2021-04-17T16:46:25.945Z","symbol":"XTZBTC"}}
1618677986.103182: {"jsonrpc":"2.0","method":"updateOrderbook","params":{"ask":[{"price":"0.00011955","size":"94.0"},{"price":"0.00011962","size":"1815.1"},{"price":"0.00011965","size":"1576.3"},{"price":"0.00011978","size":"1720.5"},{"price":"0.00011979","size":"0"},{"price":"0.00011982","size":"6980.7"},{"price":"0.00011984","size":"1165.1"},{"price":"0.00011992","size":"2880.8"},{"price":"0.00011993","size":"0"},{"price":"0.00011998","size":"3485.4"},{"price":"0.00012006","size":"0"},{"price":"0.00012009","size":"3537.9"},{"price":"0.00012021","size":"0"},{"price":"0.00012026","size":"6810.8"},{"price":"0.00012426","size":"0"},{"price":"0.00012449","size":"20099.1"}],"bid":[],"sequence":19113913,"timestamp":"2021-04-17T16:46:25.964Z","symbol":"XTZBTC"}}
1618677986.108361: {"jsonrpc":"2.0","method":"updateOrderbook","params":{"ask":[{"price":"1.5365551","size":"0"},{"price":"1.5381868","size":"5"}],"bid":[],"sequence":11642094,"timestamp":"2021-04-17T16:46:26.040Z","symbol":"MANAUSD"}}
1618677986.2021499: {"jsonrpc":"2.0","method":"updateOrderbook","params":{"ask":[{"price":"0.00011696","size":"29.1"},{"price":"0.00011887","size":"0"},{"price":"0.00011961","size":"345.5"},{"price":"0.00011963","size":"920.9"}],"bid":[{"price":"0.00011011","size":"380.0"},{"price":"0.00010288","size":"0"}],"sequence":19113914,"timestamp":"2021-04-17T16:46:26.147Z","symbol":"XTZBTC"}}
1618677986.2115169: {"jsonrpc":"2.0","method":"updateOrderbook","params":{"ask":[{"price":"0.2198803","size":"0"},{"price":"0.2199916","size":"100.00"}],"bid":[],"sequence":4920739,"timestamp":"2021-04-17T16:46:26.081Z","symbol":"BNBETH"}}
