1626318412.108578: {"jsonrpc":"2.0","method":"updateOrderbook","params":{"ask":[{"price":"0.000025993","size":"10.00"},{"price":"0.000026000","size":"0"}],"bid":[],"sequence":11276935,"timestamp":"2021-07-15T03:06:52.034Z","symbol":"GRTBTC"}}
1626318412.108595: {"jsonrpc":"2.0","method":"updateOrderbook","params":{"ask":[{"price":"0.0000022031","size":"10320"},{"price":"0.0000022032","size":"11840"},{"price":"0.0000022034","size":"0"},{"price":"0.0000022035","size":"0"},{"price":"0.0000024748","size":"0"},{"price":"0.0000024807","size":"806030"},{"price":"0.0000040937","size":"0"},{"price":"0.0000041006","size":"1121180"},{"price":"0.0000056236","size":"751190"},{"price":"0.0000056284","size":"0"}],"bid":[{"price":"0.0000022002","size":"0"},{"price":"0.0000022001","size":"0"},{"price":"0.0000022000","size":"10360"},{"price":"0.0000021999","size":"1650"},{"price":"0.0000021993","size":"0"},{"price":"0.0000021984","size":"4680"},{"price":"0.0000021912","size":"0"},{"price":"0.0000021874","size":"63220"}],"sequence":20309631,"timestamp":"2021-07-15T03:06:52.069Z","symbol":"VETBTC"}}
1626318412.21473: {"jsonrpc":"2.0","method":"updateOrderbook","params":{"ask":[{"price":"0.000019752","size":"22732.57"},{"price":"0.000026310","size":"0"}],"bid":[{"price":"0.000019343","size":"5.78"}],"sequence":11276936,"timestamp":"2021-07-15T03:06:52.115Z","symbol":"GRTBTC"}}
1626318412.218792: {"jsonrpc":"2.0","method":"updateOrderbook","params":{"ask":[{"price":"0.0000022031","size":"0"},{"price":"0.0000022032","size":"0"},{"price":"0.0000022034","size":"11840"},{"price":"0.0000022035","size":"10320"}],"bid":[{"price":"0.0000022000","size":"0"},{"price":"0.0000021998","size":"10360"},{"price":"0.0000021980","size":"0"},{"price":"0.0000021976","size":"6380"},{"price":"0.0000021705","size":"0"},{"price":"0.0000021658","size":"47000"}],"sequence":20309632,"timestamp":"2021-07-15T03:06:52.171Z","symbol":"VETBTC"}}
1626318412.294797: {"jsonrpc":"2.0","method":"updateOrderbook","params":{"ask":[{"price":"1.21890","size":"0"},{"price":"1.21908","size":"8320.00"},{"price":"1.21940","size":"0"},{"price":"1.21958","size":"15840.00"},{"price":"1.22010","size":"0"},{"price":"1.22028","size":"35680.00"},{"price":"1.22380","size":"0"},{"price":"1.22398","size":"33556.00"}],"bid":[{"price":"1.18787","size":"11596.00"},{"price":"1.18772","size":"0"},{"price":"1.18737","size":"23192.00"},{"price":"1.18722","size":"0"},{"price":"1.18667","size":"34788.00"},{"price":"1.18652","size":"0"},{"price":"1.18557","size":"52992.00"},{"price":"1.18539","size":"0"}],"sequence":7333527,"timestamp":"2021-07-15T03:06:52.203Z","symbol":"EURSUSD"}}
1626318412.34955: {"jsonrpc":"2.0","method":"updateOrderbook","params":{"ask":[{"price":"0.000023007","size":"0"},{"price":"0.000023011","size":"506.07"},{"price":"0.000025986","size":"10.00"},{"price":"0.000025993","size":"0"}],"bid":[{"price":"0.000019353","size":"0"},{"price":"0.000019333","size":"0.08"}],"sequence":11276937,"timestamp":"2021-07-15T03:06:52.272Z","symbol":"GRTBTC"}}
1626318412.349612: {"jsonrpc":"2.0","method":"updateOrderbook","params":{"ask":[{"price":"0.0000022032","size":"11840"},{"price":"0.0000022033","size":"10320"},{"price":"0.0000022034","size":"0"},{"price":"0.0000022035","size":"0"},{"price":"0.0000102429","size":"1402840"},{"price":"0.0000102543","size":"0"}],"bid":[{"price":"0.0000022000","size":"10360"},{"price":"0.0000021999","size":"0"},{"price":"0.0000021998","size":"0"},{"price":"0.0000021997","size":"5870"}],"sequence":20309633,"timestamp":"2021-07-15T03:06:52.268Z","symbol":"VETBTC"}}
1626318412.404722: {"jsonrpc":"2.0","method":"updateOrderbook","params":{"ask":[],"bid":[{"price":"1.18788","size":"11596.00"},{"price":"1.18787","size":"0"},{"price":"1.18738","size":"23192.00"},{"price":"1.18737","size":"0"},{"price":"1.18668","size":"34788.00"},{"price":"1.18667","size":"0"}],"sequence":7333528,"timestamp":"2021-07-15T03:06:52.306Z","symbol":"EURSUSD"}}
1626318412.41479: {"jsonrpc":"2.0","method":"updateOrderbook","params":{"ask":[{"price":"0.000019467","size":"526.56"},{"price":"0.000019476","size":"1958.07"},{"price":"0.000023021","size":"0"},{"price":"0.000023029","size":"6710.15"},{"price":"0.000034780","size":"69065.50"},{"price":"0.000046180","size":"83849.98"}],"bid":[{"price":"0.000019411","size":"0"},{"price":"0.000019405","size":"538.41"},{"price":"0.000019350","size":"0"},{"price":"0.000019342","size":"5196.30"},{"price":"0.000019333","size":"0.12"},{"price":"0.000016194","size":"0"},{"price":"0.000015908","size":"562.53"},{"price":"0.000015818","size":"0"},{"price":"0.000015804","size":"6152.86"}],"sequence":11276938,"timestamp":"2021-07-15T03:06:52.367Z","symbol":"GRTBTC"}}
1626318412.43539: {"jsonrpc":"2.0","method":"updateOrderbook","params":{"ask":[{"price":"0.0000022030","size":"11840"},{"price":"0.0000022031","size":"10320"},{"price":"0.0000022032","size":"0"},{"price":"0.0000022033","size":"0"},{"price":"0.0000022063","size":"0"},{"price":"0.0000022073","size":"58340"},{"price":"0.0000022086","size":"0"},{"price":"0.0000022100","size":"89640"},{"price":"0.0000102429","size":"0"},{"price":"0.0000102561","size":"1402840"}],"bid":[{"price":"0.0000022000","size":"0"},{"price":"0.0000021998","size":"10360"},{"price":"0.0000021997","size":"4220"},{"price":"0.0000021987","size":"1650"},{"price":"0.0000021983","size":"0"},{"price":"0.0000021977","size":"36300"},{"price":"0.0000021976","size":"0"},{"price":"0.0000021970","size":"6380"},{"price":"0.0000020516","size":"0"},{"price":"0.0000020412","size":"616380"},{"price":"0.0000006952","size":"0"},{"price":"0.0000006784","size":"842410"}],"sequence":20309634,"timestamp":"2021-07-15T03:06:52.356Z","symbol":"VETBTC"}}
1626318412.510205: {"jsonrpc":"2.0","method":"updateOrderbook","params":{"ask":[{"price":"0.000019633","size":"17592.22"},{"price":"0.000019682","size":"51682.70"},{"price":"0.000019731","size":"26391.19"},{"price":"0.000021127","size":"66111.26"},{"price":"0.000021147","size":"0"},{"price":"0.000032454","size":"0"}],"bid":[],"sequence":11276939,"timestamp":"2021-07-15T03:06:52.430Z","symbol":"GRTBTC"}}
1626318412.615008: {"jsonrpc":"2.0","method":"updateOrderbook","params":{"ask":[{"price":"0.0000022029","size":"10320"},{"price":"0.0000022031","size":"0"}],"bid":[{"price":"0.0000021999","size":"1650"},{"price":"0.0000021990","size":"4680"},{"price":"0.0000021987","size":"0"},{"price":"0.0000021984","size":"0"},{"price":"0.0000021648","size":"0"},{"price":"0.0000021570","size":"973430"}],"sequence":20309635,"timestamp":"2021-07-15T03:06:52.458Z","symbol":"VETBTC"}}
1626318412.6151428: {"jsonrpc":"2.0","method":"updateOrderbook","params":{"ask":[],"bid":[{"price":"1.18788","size":"0"},{"price":"1.18786","size":"11596.00"},{"price":"1.18738","size":"0"},{"price":"1.18736","size":"23192.00"},{"price":"1.18668","size":"0"},{"price":"1.18666","size":"34788.00"}],"sequence":7333529,"timestamp":"2021-07-15T03:06:52.559Z","symbol":"EURSUSD"}}
1626318412.615171: {"jsonrpc":"2.0","method":"updateOrderbook","params":{"ask":[{"price":"0.000019652","size":"51682.70"},{"price":"0.000019682","size":"0"}],"bid":[],"sequence":11276940,"timestamp":"2021-07-15T03:06:52.540Z","symbol":"GRTBTC"}}
1626318412.615188: {"jsonrpc":"2.0","method":"updateOrderbook","params":{"ask":[{"price":"0.0000022029","size":"0"},{"price":"0.0000022030","size":"0"},{"price":"0.0000022034","size":"11840"},{"price":"0.0000022035","size":"10320"}],"bid":[{"price":"0.0000021999","size":"0"},{"price":"0.0000021991","size":"1650"}],"sequence":20309636,"timestamp":"2021-07-15T03:06:52.519Z","symbol":"VETBTC"}}
1626318412.698005: {"jsonrpc":"2.0","method":"updateOrderbook","params":{"ask":[],"bid":[{"price":"1.18790","size":"11596.00"},{"price":"1.18786","size":"0"},{"price":"1.18740","size":"23192.00"},{"price":"1.18736","size":"0"},{"price":"1.18670","size":"34788.00"},{"price":"1.18666","size":"0"}],"sequence":7333530,"timestamp":"2021-07-15T03:06:52.661Z","symbol":"EURSUSD"}}
1626318412.7213418: {"jsonrpc":"2.0","method":"updateOrderbook","params":{"ask":[{"price":"0.000019526","size":"10604.13"},{"price":"0.000019536","size":"0"},{"price":"0.000019781","size":"37723.11"},{"price":"0.000021127","size":"0"},{"price":"0.000021153","size":"66111.26"},{"price":"0.000057521","size":"0"}],"bid":[],"sequence":11276941,"timestamp":"2021-07-15T03:06:52.648Z","symbol":"GRTBTC"}}
1626318412.7213728: {"jsonrpc":"2.0","method":"updateOrderbook","params":{"ask":[{"price":"0.0000022030","size":"11840"},{"price":"0.0000022031","size":"10320"},{"price":"0.0000022034","size":"0"},{"price":"0.0000022035","size":"0"},{"price":"0.0000023908","size":"0"},{"price":"0.0000024188","size":"434810"},{"price":"0.0000037538","size":"0"},{"price":"0.0000038114","size":"598830"},{"price":"0.0000056236","size":"0"},{"price":"0.0000056729","size":"751190"},{"price":"0.0000090600","size":"0"},{"price":"0.0000090941","size":"1665120"}],"bid":[{"price":"0.0000021979","size":"6380"},{"price":"0.0000021970","size":"0"},{"price":"0.0000021968","size":"204400"},{"price":"0.0000021959","size":"0"}],"sequence":20309637,"timestamp":"2021-07-15T03:06:52.664Z","symbol":"VETBTC"}}
1626318412.721689: {"jsonrpc":"2.0","method":"updateOrderbook","params":{"ask":[{"price":"0.000086648","size":"0"},{"price":"0.000086653","size":"1.98"}],"bid":[{"price":"0.000008665","size":"1.35"},{"price":"0.000008664","size":"0"}],"sequence":3128139,"timestamp":"2021-07-15T03:06:52.641Z","symbol":"INSURBTC"}}
1626318412.795576: {"jsonrpc":"2.0","method":"updateOrderbook","params":{"ask":[],"bid":[{"price":"1.18791","size":"11596.00"},{"price":"1.18790","size":"0"},{"price":"1.18741","size":"23192.00"},{"price":"1.18740","size":"0"},{"price":"1.18671","size":"34788.00"},{"price":"1.18670","size":"0"},{"price":"1.18261","size":"50334.00"},{"price":"1.18241","size":"0"}],"sequence":7333531,"timestamp":"2021-07-15T03:06:52.752Z","symbol":"EURSUSD"}}
1626318412.80288: {"jsonrpc":"2.0","method":"updateOrderbook","params":{"ask":[{"price":"0.000019490","size":"1989.87"},{"price":"0.000019495","size":"0"}],"bid":[],"sequence":11276942,"timestamp":"2021-07-15T03:06:52.709Z","symbol":"GRTBTC"}}
1626318412.8072362: {"jsonrpc":"2.0","method":"updateOrderbook","params":{"ask":[{"price":"0.0000022030","size":"0"},{"price":"0.0000022031","size":"0"},{"price":"0.0000022034","size":"11840"},{"price":"0.0000022035","size":"10320"}],"bid":[],"sequence":20309638,"timestamp":"2021-07-15T03:06:52.750Z","symbol":"VETBTC"}}
1626318412.9082391: {"jsonrpc":"2.0","method":"updateOrderbook","params":{"ask":[{"price":"0.0000022032","size":"11840"},{"price":"0.0000022033","size":"10320"},{"price":"0.0000022034","size":"0"},{"price":"0.0000022035","size":"0"}],"bid":[],"sequence":20309639,"timestamp":"2021-07-15T03:06:52.817Z","symbol":"VETBTC"}}
1626318413.0119748: {"jsonrpc":"2.0","method":"updateOrderbook","params":{"ask":[{"price":"0.0000022032","size":"0"},{"price":"0.0000022033","size":"0"},{"price":"0.0000022035","size":"10320"},{"price":"0.0000022036","size":"11840"}],"bid":[{"price":"0.0000021979","size":"0"},{"price":"0.0000021969","size":"6380"},{"price":"0.0000021968","size":"192540"},{"price":"0.0000021959","size":"11860"},{"price":"0.0000020446","size":"616380"},{"price":"0.0000020412","size":"0"}],"sequence":20309640,"timestamp":"2021-07-15T03:06:52.968Z","symbol":"VETBTC"}}
1626318413.112009: {"jsonrpc":"2.0","method":"updateOrderbook","params":{"ask":[{"price":"0.0000022032","size":"11840"},{"price":"0.0000022033","size":"10320"},{"price":"0.0000022035","size":"0"},{"price":"0.0000022036","size":"0"}],"bid":[{"price":"0.0000021978","size":"49210"},{"price":"0.0000021969","size":"0"}],"sequence":20309641,"timestamp":"2021-07-15T03:06:53.044Z","symbol":"VETBTC"}}
1626318413.200599: {"jsonrpc":"2.0","method":"updateOrderbook","params":{"ask":[{"price":"0.0000022029","size":"10320"},{"price":"0.0000022032","size":"0"},{"price":"0.0000022033","size":"0"},{"price":"0.0000022036","size":"11840"}],"bid":[],"sequence":20309642,"timestamp":"2021-07-15T03:06:53.169Z","symbol":"VETBTC"}}
1626318413.290153: {"jsonrpc":"2.0","method":"updateOrderbook","params":{"ask":[],"bid":[{"price":"1.18792","size":"11596.00"},{"price":"1.18791","size":"0"},{"price":"1.18742","size":"23192.00"},{"price":"1.18741","size":"0"},{"price":"1.18672","size":"34788.00"},{"price":"1.18671","size":"0"}],"sequence":7333532,"timestamp":"2021-07-15T03:06:53.193Z","symbol":"EURSUSD"}}
1626318413.30735: {"jsonrpc":"2.0","method":"updateOrderbook","params":{"ask":[{"price":"0.0000022029","size":"0"},{"price":"0.0000022032","size":"11840"},{"price":"0.0000022033","size":"10320"},{"price":"0.0000022036","size":"0"}],"bid":[],"sequence":20309643,"timestamp":"2021-07-15T03:06:53.244Z","symbol":"VETBTC"}}
1626318413.392765: {"jsonrpc":"2.0","method":"updateOrderbook","params":{"ask":[],"bid":[{"price":"1.18242","size":"0"}],"sequence":7333533,"timestamp":"2021-07-15T03:06:53.347Z","symbol":"EURSUSD"}}
1626318413.399308: {"jsonrpc":"2.0","method":"updateOrderbook","params":{"ask":[{"price":"0.000025986","size":"0"},{"price":"0.000025993","size":"10.00"},{"price":"0.000044211","size":"0"},{"price":"0.000046296","size":"43968.68"}],"bid":[],"sequence":11276943,"timestamp":"2021-07-15T03:06:53.317Z","symbol":"GRTBTC"}}
1626318413.3993332: {"jsonrpc":"2.0","method":"updateOrderbook","params":{"ask":[{"price":"0.0000022029","size":"10320"},{"price":"0.0000022030","size":"11840"},{"price":"0.0000022032","size":"0"},{"price":"0.0000022033","size":"0"},{"price":"0.0000022037","size":"9480"},{"price":"0.0000022038","size":"0"}],"bid":[{"price":"0.0000021990","size":"11060"},{"price":"0.0000021979","size":"11860"},{"price":"0.0000021978","size":"42830"},{"price":"0.0000021959","size":"0"}],"sequence":20309644,"timestamp":"2021-07-15T03:06:53.373Z","symbol":"VETBTC"}}
1626318413.488925: {"jsonrpc":"2.0","method":"updateOrderbook","params":{"ask":[],"bid":[{"price":"1.18262","size":"387.41"}],"sequence":7333534,"timestamp":"2021-07-15T03:06:53.435Z","symbol":"EURSUSD"}}
1626318413.499995: {"jsonrpc":"2.0","method":"updateOrderbook","params":{"ask":[{"price":"0.000005688","size":"3345.1"},{"price":"0.000005697","size":"0"}],"bid":[],"sequence":1875058,"timestamp":"2021-07-15T03:06:53.440Z","symbol":"POLYBTC"}}
1626318413.5000541: {"jsonrpc":"2.0","method":"updateOrderbook","params":{"ask":[{"price":"0.000019490","size":"0"},{"price":"0.000019496","size":"1989.87"},{"price":"0.000019652","size":"0"},{"price":"0.000019674","size":"51682.70"},{"price":"0.000025986","size":"10.00"},{"price":"0.000025993","size":"0"},{"price":"0.000034780","size":"0"},{"price":"0.000035010","size":"69065.50"},{"price":"0.000046180","size":"0"},{"price":"0.000046742","size":"83849.98"}],"bid":[],"sequence":11276944,"timestamp":"2021-07-15T03:06:53.417Z","symbol":"GRTBTC"}}
1626318413.500087: {"jsonrpc":"2.0","method":"updateOrderbook","params":{"ask":[{"price":"0.0000022029","size":"0"},{"price":"0.0000022030","size":"0"},{"price":"0.0000022032","size":"11840"},{"price":"0.0000022033","size":"10320"}],"bid":[{"price":"0.0000021991","size":"0"},{"price":"0.0000021990","size":"0"},{"price":"0.0000021987","size":"1650"},{"price":"0.0000021983","size":"4680"},{"price":"0.0000021979","size":"0"},{"price":"0.0000021976","size":"6380"},{"price":"0.0000021966","size":"11860"},{"price":"0.0000020446","size":"0"},{"price":"0.0000020395","size":"616380"}],"sequence":20309645,"timestamp":"2021-07-15T03:06:53.473Z","symbol":"VETBTC"}}
1626318413.599893: {"jsonrpc":"2.0","method":"updateOrderbook","params":{"ask":[{"price":"0.000019600","size":"14555.24"},{"price":"0.000019618","size":"0"}],"bid":[{"price":"0.000015908","size":"0"},{"price":"0.000015810","size":"562.68"},{"price":"0.000015804","size":"0"},{"price":"0.000015796","size":"6154.44"}],"sequence":11276945,"timestamp":"2021-07-15T03:06:53.559Z","symbol":"GRTBTC"}}
1626318413.6009102: {"jsonrpc":"2.0","method":"updateOrderbook","params":{"ask":[{"price":"0.0000022030","size":"11840"},{"price":"0.0000022031","size":"10320"},{"price":"0.0000022032","size":"0"},{"price":"0.0000022033","size":"0"}],"bid":[{"price":"0.0000021927","size":"124370"},{"price":"0.0000021910","size":"0"}],"sequence":20309646,"timestamp":"2021-07-15T03:06:53.547Z","symbol":"VETBTC"}}
1626318413.703706: {"jsonrpc":"2.0","method":"updateOrderbook","params":{"ask":[{"price":"0.0000022027","size":"10320"},{"price":"0.0000022028","size":"11840"},{"price":"0.0000022030","size":"0"},{"price":"0.0000022031","size":"0"},{"price":"0.0000024188","size":"0"},{"price":"0.0000024263","size":"434810"},{"price":"0.0000038114","size":"0"},{"price":"0.0000038244","size":"598830"},{"price":"0.0000056729","size":"0"},{"price":"0.0000056836","size":"751190"},{"price":"0.0000090941","size":"0"},{"price":"0.0000091021","size":"1665120"}],"bid":[{"price":"0.0000021989","size":"1650"},{"price":"0.0000021988","size":"6380"},{"price":"0.0000021987","size":"0"},{"price":"0.0000021976","size":"0"},{"price":"0.0000021927","size":"0"},{"price":"0.0000021910","size":"124370"},{"price":"0.0000020395","size":"0"},{"price":"0.0000020159","size":"616380"},{"price":"0.0000006784","size":"0"},{"price":"0.0000006377","size":"842410"}],"sequence":20309647,"timestamp":"2021-07-15T03:06:53.674Z","symbol":"VETBTC"}}
1626318413.7092009: {"jsonrpc":"2.0","method":"updateOrderbook","params":{"ask":[{"price":"0.000086653","size":"0"},{"price":"0.000086658","size":"1.45"}],"bid":[{"price":"0.000008665","size":"1.02"}],"sequence":3128140,"timestamp":"2021-07-15T03:06:53.641Z","symbol":"INSURBTC"}}
1626318413.7943192: {"jsonrpc":"2.0","method":"updateOrderbook","params":{"ask":[{"price":"1.21908","size":"0"},{"price":"1.21914","size":"8320.00"},{"price":"1.21958","size":"0"},{"price":"1.21964","size":"15840.00"},{"price":"1.22028","size":"0"},{"price":"1.22034","size":"35680.00"}],"bid":[{"price":"1.18793","size":"11596.00"},{"price":"1.18792","size":"0"},{"price":"1.18743","size":"23192.00"},{"price":"1.18742","size":"0"},{"price":"1.18673","size":"34788.00"},{"price":"1.18672","size":"0"}],"sequence":7333535,"timestamp":"2021-07-15T03:06:53.741Z","symbol":"EURSUSD"}}
1626318413.801198: {"jsonrpc":"2.0","method":"updateOrderbook","params":{"ask":[{"price":"0.0000022027","size":"0"},{"price":"0.0000022028","size":"0"},{"price":"0.0000022032","size":"11840"},{"price":"0.0000022033","size":"10320"},{"price":"0.0000022037","size":"4140"},{"price":"0.0000022038","size":"5340"},{"price":"0.0000022086","size":"47990"},{"price":"0.0000022094","size":"0"}],"bid":[{"price":"0.0000021998","size":"16740"},{"price":"0.0000021989","size":"0"},{"price":"0.0000021988","size":"0"},{"price":"0.0000021987","size":"1650"},{"price":"0.0000020159","size":"0"},{"price":"0.0000020039","size":"616380"},{"price":"0.0000006377","size":"0"},{"price":"0.0000006184","size":"842410"}],"sequence":20309648,"timestamp":"2021-07-15T03:06:53.768Z","symbol":"VETBTC"}}
1626318413.896716: {"jsonrpc":"2.0","method":"updateOrderbook","params":{"ask":[{"price":"0.000005704","size":"10739.0"},{"price":"0.000005713","size":"0"},{"price":"0.000005750","size":"19726.6"},{"price":"0.000005759","size":"0"},{"price":"0.000005859","size":"134538.9"},{"price":"0.000005867","size":"0"}],"bid":[],"sequence":1875059,"timestamp":"2021-07-15T03:06:53.865Z","symbol":"POLYBTC"}}
1626318413.9035342: {"jsonrpc":"2.0","method":"updateOrderbook","params":{"ask":[{"price":"0.0000022030","size":"11840"},{"price":"0.0000022031","size":"10320"},{"price":"0.0000022032","size":"0"},{"price":"0.0000022033","size":"0"},{"price":"0.0000022035","size":"5340"},{"price":"0.0000022038","size":"0"}],"bid":[{"price":"0.0000021999","size":"10360"},{"price":"0.0000021998","size":"6380"},{"price":"0.0000021986","size":"16510"},{"price":"0.0000021966","size":"0"}],"sequence":20309649,"timestamp":"2021-07-15T03:06:53.828Z","symbol":"VETBTC"}}
1626318414.0071921: {"jsonrpc":"2.0","method":"updateOrderbook","params":{"ask":[{"price":"0.0000022030","size":"0"},{"price":"0.0000022031","size":"0"},{"price":"0.0000022032","size":"11840"},{"price":"0.0000022033","size":"10320"}],"bid":[{"price":"0.0000021999","size":"0"},{"price":"0.0000021998","size":"10360"},{"price":"0.0000021988","size":"1650"},{"price":"0.0000021987","size":"6380"}],"sequence":20309650,"timestamp":"2021-07-15T03:06:53.974Z","symbol":"VETBTC"}}
1626318414.094526: {"jsonrpc":"2.0","method":"updateOrderbook","params":{"ask":[{"price":"0.000019467","size":"1082.66"},{"price":"0.000019472","size":"470.51"},{"price":"0.000035010","size":"0"},{"price":"0.000035053","size":"69065.50"},{"price":"0.000046742","size":"0"},{"price":"0.000046845","size":"83849.98"}],"bid":[],"sequence":11276946,"timestamp":"2021-07-15T03:06:54.011Z","symbol":"GRTBTC"}}
1626318414.100872: {"jsonrpc":"2.0","method":"updateOrderbook","params":{"ask":[{"price":"0.0000022030","size":"11840"},{"price":"0.0000022031","size":"10320"},{"price":"0.0000022032","size":"0"},{"price":"0.0000022033","size":"0"}],"bid":[{"price":"0.0000021996","size":"6380"},{"price":"0.0000021988","size":"0"},{"price":"0.0000021987","size":"1650"}],"sequence":20309651,"timestamp":"2021-07-15T03:06:54.033Z","symbol":"VETBTC"}}
1626318414.191945: {"jsonrpc":"2.0","method":"updateOrderbook","params":{"ask":[],"bid":[{"price":"1.18793","size":"0"},{"price":"1.18792","size":"11596.00"},{"price":"1.18743","size":"0"},{"price":"1.18742","size":"23192.00"},{"price":"1.18673","size":"0"},{"price":"1.18672","size":"34788.00"}],"sequence":7333536,"timestamp":"2021-07-15T03:06:54.134Z","symbol":"EURSUSD"}}
1626318414.197578: {"jsonrpc":"2.0","method":"updateOrderbook","params":{"ask":[{"price":"0.0000022027","size":"10320"},{"price":"0.0000022028","size":"11840"},{"price":"0.0000022030","size":"0"},{"price":"0.0000022031","size":"0"}],"bid":[],"sequence":20309652,"timestamp":"2021-07-15T03:06:54.173Z","symbol":"VETBTC"}}
1626318414.2955468: {"jsonrpc":"2.0","method":"updateOrderbook","params":{"ask":[{"price":"0.0000022027","size":"0"},{"price":"0.0000022028","size":"0"},{"price":"0.0000022030","size":"11840"},{"price":"0.0000022031","size":"10320"},{"price":"0.0000022048","size":"0"},{"price":"0.0000022049","size":"12910"}],"bid":[{"price":"0.0000021915","size":"0"},{"price":"0.0000021887","size":"4380"},{"price":"0.0000017972","size":"0"},{"price":"0.0000017909","size":"674780"}],"sequence":20309653,"timestamp":"2021-07-15T03:06:54.254Z","symbol":"VETBTC"}}
1626318414.401532: {"jsonrpc":"2.0","method":"updateOrderbook","params":{"ask":[{"price":"0.0000022028","size":"11840"},{"price":"0.0000022029","size":"10320"},{"price":"0.0000022030","size":"0"},{"price":"0.0000022031","size":"0"},{"price":"0.0000102561","size":"0"},{"price":"0.0000102764","size":"1402840"}],"bid":[],"sequence":20309654,"timestamp":"2021-07-15T03:06:54.328Z","symbol":"VETBTC"}}
1626318414.511712: {"jsonrpc":"2.0","method":"updateOrderbook","params":{"ask":[{"price":"0.0000022028","size":"0"},{"price":"0.0000022029","size":"0"},{"price":"0.0000022032","size":"11840"},{"price":"0.0000022033","size":"10320"},{"price":"0.0000022035","size":"0"},{"price":"0.0000022039","size":"5340"},{"price":"0.0000102764","size":"0"},{"price":"0.0000102862","size":"1402840"}],"bid":[{"price":"0.0000021996","size":"0"},{"price":"0.0000021988","size":"1650"},{"price":"0.0000021987","size":"6380"},{"price":"0.0000021986","size":"4650"},{"price":"0.0000021982","size":"22990"},{"price":"0.0000021977","size":"30260"},{"price":"0.0000021882","size":"4210"},{"price":"0.0000021877","size":"17900"}],"sequence":20309655,"timestamp":"2021-07-15T03:06:54.472Z","symbol":"VETBTC"}}
1626318414.602298: {"jsonrpc":"2.0","method":"updateOrderbook","params":{"ask":[{"price":"0.000019479","size":"5174.06"},{"price":"0.000019486","size":"0"},{"price":"0.000019488","size":"1989.87"},{"price":"0.000019496","size":"0"},{"price":"0.000019652","size":"51682.70"},{"price":"0.000019674","size":"0"},{"price":"0.000019781","size":"69534.30"},{"price":"0.000020121","size":"84536.43"},{"price":"0.000025986","size":"0"},{"price":"0.000025993","size":"10.00"},{"price":"0.000040061","size":"0"}],"bid":[],"sequence":11276947,"timestamp":"2021-07-15T03:06:54.573Z","symbol":"GRTBTC"}}
1626318414.6025758: {"jsonrpc":"2.0","method":"updateOrderbook","params":{"ask":[{"price":"0.0000022030","size":"11840"},{"price":"0.0000022031","size":"10320"},{"price":"0.0000022032","size":"0"},{"price":"0.0000022033","size":"0"},{"price":"0.0000022035","size":"5340"},{"price":"0.0000022039","size":"0"}],"bid":[{"price":"0.0000021996","size":"6380"},{"price":"0.0000021988","size":"0"},{"price":"0.0000021987","size":"1650"}],"sequence":20309656,"timestamp":"2021-07-15T03:06:54.530Z","symbol":"VETBTC"}}
1626318414.705439: {"jsonrpc":"2.0","method":"updateOrderbook","params":{"ask":[{"price":"0.000025986","size":"10.00"},{"price":"0.000025993","size":"0"}],"bid":[],"sequence":11276948,"timestamp":"2021-07-15T03:06:54.615Z","symbol":"GRTBTC"}}
1626318414.705454: {"jsonrpc":"2.0","method":"updateOrderbook","params":{"ask":[{"price":"0.0000022027","size":"10320"},{"price":"0.0000022030","size":"0"},{"price":"0.0000022031","size":"0"},{"price":"0.0000022034","size":"11840"},{"price":"0.0000022045","size":"12910"},{"price":"0.0000022049","size":"0"}],"bid":[],"sequence":20309657,"timestamp":"2021-07-15T03:06:54.670Z","symbol":"VETBTC"}}
1626318414.705489: {"jsonrpc":"2.0","method":"updateOrderbook","params":{"ask":[{"price":"0.000086656","size":"1.03"},{"price":"0.000086658","size":"0"}],"bid":[{"price":"0.000008665","size":"1.65"}],"sequence":3128141,"timestamp":"2021-07-15T03:06:54.642Z","symbol":"INSURBTC"}}
1626318414.817329: {"jsonrpc":"2.0","method":"updateOrderbook","params":{"ask":[{"price":"0.000020121","size":"0"}],"bid":[],"sequence":11276949,"timestamp":"2021-07-15T03:06:54.729Z","symbol":"GRTBTC"}}
1626318414.8173828: {"jsonrpc":"2.0","method":"updateOrderbook","params":{"ask":[{"price":"0.0000022027","size":"0"},{"price":"0.0000022030","size":"11840"},{"price":"0.0000022031","size":"10320"},{"price":"0.0000022034","size":"0"},{"price":"0.0000022045","size":"0"},{"price":"0.0000022049","size":"12910"},{"price":"0.0000022086","size":"70300"},{"price":"0.0000022087","size":"0"},{"price":"0.0000022103","size":"26220"},{"price":"0.0000022104","size":"0"}],"bid":[{"price":"0.0000021996","size":"6390"},{"price":"0.0000021984","size":"11870"},{"price":"0.0000021977","size":"18400"},{"price":"0.0000021939","size":"22050"},{"price":"0.0000021929","size":"0"},{"price":"0.0000021922","size":"25960"},{"price":"0.0000021906","size":"0"}],"sequence":20309658,"timestamp":"2021-07-15T03:06:54.745Z","symbol":"VETBTC"}}
1626318414.895593: {"jsonrpc":"2.0","method":"updateOrderbook","params":{"ask":[],"bid":[{"price":"0.000019388","size":"0"},{"price":"0.000019381","size":"2123.51"}],"sequence":11276950,"timestamp":"2021-07-15T03:06:54.792Z","symbol":"GRTBTC"}}
1626318414.900563: {"jsonrpc":"2.0","method":"updateOrderbook","params":{"ask":[{"price":"0.0000022027","size":"10320"},{"price":"0.0000022028","size":"11840"},{"price":"0.0000022030","size":"0"},{"price":"0.0000022031","size":"0"},{"price":"0.0000022035","size":"0"},{"price":"0.0000022036","size":"5340"}],"bid":[],"sequence":20309659,"timestamp":"2021-07-15T03:06:54.868Z","symbol":"VETBTC"}}
1626318415.0038521: {"jsonrpc":"2.0","method":"updateOrderbook","params":{"ask":[{"price":"0.000019516","size":"5580.35"},{"price":"0.000019547","size":"0"}],"bid":[],"sequence":11276951,"timestamp":"2021-07-15T03:06:54.894Z","symbol":"GRTBTC"}}
1626318415.0038688: {"jsonrpc":"2.0","method":"updateOrderbook","params":{"ask":[{"price":"0.0000022027","size":"0"},{"price":"0.0000022028","size":"0"},{"price":"0.0000022031","size":"11840"},{"price":"0.0000022032","size":"10320"},{"price":"0.0000022036","size":"0"},{"price":"0.0000022039","size":"5340"},{"price":"0.0000022379","size":"0"},{"price":"0.0000022615","size":"322860"},{"price":"0.0000068731","size":"0"},{"price":"0.0107905930","size":"441760"}],"bid":[{"price":"0.0000021997","size":"10610"},{"price":"0.0000021996","size":"0"}],"sequence":20309660,"timestamp":"2021-07-15T03:06:54.960Z","symbol":"VETBTC"}}
1626318415.116978: {"jsonrpc":"2.0","method":"updateOrderbook","params":{"ask":[{"price":"0.000019488","size":"4003.17"},{"price":"0.000019494","size":"0"}],"bid":[],"sequence":11276952,"timestamp":"2021-07-15T03:06:55.018Z","symbol":"GRTBTC"}}
1626318415.116991: {"jsonrpc":"2.0","method":"updateOrderbook","params":{"ask":[{"price":"0.0000022029","size":"11840"},{"price":"0.0000022030","size":"10320"},{"price":"0.0000022031","size":"0"},{"price":"0.0000022032","size":"0"},{"price":"0.0000022035","size":"5340"},{"price":"0.0000022039","size":"0"},{"price":"0.0000022137","size":"1055910"},{"price":"0.0000022203","size":"66490"},{"price":"0.0000022236","size":"292930"},{"price":"0.0000022240","size":"0"},{"price":"0.0000022257","size":"97560"},{"price":"0.0000022339","size":"23000"},{"price":"0.0000022340","size":"115440"},{"price":"0.0000022351","size":"24000"},{"price":"0.0000022615","size":"0"},{"price":"0.0000027836","size":"322860"},{"price":"0.0107905930","size":"0"}],"bid":[],"sequence":20309661,"timestamp":"2021-07-15T03:06:55.057Z","symbol":"VETBTC"}}
1626318415.3703659: {"jsonrpc":"2.0","method":"updateOrderbook","params":{"ask":[{"price":"0.00020152","size":"0"},{"price":"0.00020482","size":"1.00"}],"bid":[{"price":"0.00011042","size":"0"},{"price":"0.00010712","size":"2.00"}],"sequence":3153554,"timestamp":"2021-07-15T03:06:55.100Z","symbol":"ORNBTC"}}
1626318415.370424: {"jsonrpc":"2.0","method":"updateOrderbook","params":{"ask":[{"price":"0.000019475","size":"1974.35"},{"price":"0.000019481","size":"0"},{"price":"0.000025986","size":"0"},{"price":"0.000026412","size":"10.00"}],"bid":[],"sequence":11276953,"timestamp":"2021-07-15T03:06:55.106Z","symbol":"GRTBTC"}}
1626318415.370452: {"jsonrpc":"2.0","method":"updateOrderbook","params":{"ask":[{"price":"0.0000022029","size":"0"},{"price":"0.0000022030","size":"0"},{"price":"0.0000022032","size":"11840"},{"price":"0.0000022033","size":"10320"},{"price":"0.0000022035","size":"0"},{"price":"0.0000022039","size":"5340"}],"bid":[],"sequence":20309662,"timestamp":"2021-07-15T03:06:55.172Z","symbol":"VETBTC"}}
1626318415.3705401: {"jsonrpc":"2.0","method":"updateOrderbook","params":{"ask":[],"bid":[{"price":"1.18792","size":"0"},{"price":"1.18791","size":"11596.00"},{"price":"1.18742","size":"0"},{"price":"1.18741","size":"23192.00"},{"price":"1.18672","size":"0"},{"price":"1.18671","size":"34788.00"}],"sequence":7333537,"timestamp":"2021-07-15T03:06:55.201Z","symbol":"EURSUSD"}}
1626318415.3705652: {"jsonrpc":"2.0","method":"updateOrderbook","params":{"ask":[{"price":"0.0000022030","size":"11840"},{"price":"0.0000022031","size":"10320"},{"price":"0.0000022032","size":"0"},{"price":"0.0000022033","size":"0"},{"price":"0.0000022035","size":"5340"},{"price":"0.0000022039","size":"0"}],"bid":[],"sequence":20309663,"timestamp":"2021-07-15T03:06:55.264Z","symbol":"VETBTC"}}
1626318415.5673869: {"jsonrpc":"2.0","method":"updateOrderbook","params":{"ask":[{"price":"0.000019652","size":"0"},{"price":"0.000019674","size":"51682.70"},{"price":"0.000019786","size":"49194.04"},{"price":"0.000040066","size":"0"}],"bid":[],"sequence":11276954,"timestamp":"2021-07-15T03:06:55.348Z","symbol":"GRTBTC"}}
1626318415.567413: {"jsonrpc":"2.0","method":"updateOrderbook","params":{"ask":[{"price":"0.0000022030","size":"0"},{"price":"0.0000022031","size":"0"},{"price":"0.0000022032","size":"11840"},{"price":"0.0000022033","size":"10320"},{"price":"0.0000022035","size":"0"},{"price":"0.0000022039","size":"5340"}],"bid":[],"sequence":20309664,"timestamp":"2021-07-15T03:06:55.372Z","symbol":"VETBTC"}}
1626318415.5674639: {"jsonrpc":"2.0","method":"updateOrderbook","params":{"ask":[{"price":"0.0000022030","size":"11840"},{"price":"0.0000022031","size":"10320"},{"price":"0.0000022032","size":"0"},{"price":"0.0000022033","size":"0"},{"price":"0.0000022036","size":"5340"},{"price":"0.0000022039","size":"0"}],"bid":[],"sequence":20309665,"timestamp":"2021-07-15T03:06:55.466Z","symbol":"VETBTC"}}
1626318415.607441: {"jsonrpc":"2.0","method":"updateOrderbook","params":{"ask":[{"price":"0.0000022030","size":"0"},{"price":"0.0000022031","size":"0"},{"price":"0.0000022034","size":"10320"},{"price":"0.0000022035","size":"11840"}],"bid":[],"sequence":20309666,"timestamp":"2021-07-15T03:06:55.575Z","symbol":"VETBTC"}}
1626318415.7143319: {"jsonrpc":"2.0","method":"updateOrderbook","params":{"ask":[{"price":"0.000006927","size":"24796.2"},{"price":"0.000006951","size":"0"}],"bid":[],"sequence":1875060,"timestamp":"2021-07-15T03:06:55.668Z","symbol":"POLYBTC"}}
1626318415.714358: {"jsonrpc":"2.0","method":"updateOrderbook","params":{"ask":[{"price":"0.0000022031","size":"11840"},{"price":"0.0000022032","size":"10320"},{"price":"0.0000022034","size":"0"},{"price":"0.0000022035","size":"0"},{"price":"0.0000022036","size":"0"},{"price":"0.0000022038","size":"5340"}],"bid":[{"price":"0.0000020487","size":"616380"},{"price":"0.0000020039","size":"0"},{"price":"0.0000006906","size":"842410"},{"price":"0.0000006184","size":"0"}],"sequence":20309667,"timestamp":"2021-07-15T03:06:55.653Z","symbol":"VETBTC"}}
1626318415.714437: {"jsonrpc":"2.0","method":"updateOrderbook","params":{"ask":[{"price":"0.000086656","size":"1.09"}],"bid":[{"price":"0.000008665","size":"1.23"}],"sequence":3128142,"timestamp":"2021-07-15T03:06:55.645Z","symbol":"INSURBTC"}}
1626318415.807648: {"jsonrpc":"2.0","method":"updateOrderbook","params":{"ask":[{"price":"0.0000022028","size":"10320"},{"price":"0.0000022031","size":"0"},{"price":"0.0000022032","size":"0"},{"price":"0.0000022035","size":"11840"},{"price":"0.0000022036","size":"5340"},{"price":"0.0000022038","size":"0"}],"bid":[],"sequence":20309668,"timestamp":"2021-07-15T03:06:55.773Z","symbol":"VETBTC"}}
1626318415.898735: {"jsonrpc":"2.0","method":"updateOrderbook","params":{"ask":[{"price":"0.0000022028","size":"0"},{"price":"0.0000022031","size":"11840"},{"price":"0.0000022032","size":"10320"},{"price":"0.0000022035","size":"0"},{"price":"0.0000022036","size":"0"},{"price":"0.0000022038","size":"5340"}],"bid":[],"sequence":20309669,"timestamp":"2021-07-15T03:06:55.853Z","symbol":"VETBTC"}}
1626318415.996277: {"jsonrpc":"2.0","method":"updateOrderbook","params":{"ask":[{"price":"0.0000022028","size":"10320"},{"price":"0.0000022031","size":"0"},{"price":"0.0000022032","size":"0"},{"price":"0.0000022035","size":"11840"},{"price":"0.0000022036","size":"5340"},{"price":"0.0000022038","size":"0"},{"price":"0.0000023344","size":"0"},{"price":"0.0000023445","size":"570330"},{"price":"0.0000032636","size":"0"},{"price":"0.0000032723","size":"806300"},{"price":"0.0000039002","size":"0"},{"price":"0.0000039109","size":"1173990"},{"price":"0.0000060520","size":"0"},{"price":"0.0000060801","size":"1656660"}],"bid":[],"sequence":20309670,"timestamp":"2021-07-15T03:06:55.973Z","symbol":"VETBTC"}}
1626318416.106484: {"jsonrpc":"2.0","method":"updateOrderbook","params":{"ask":[],"bid":[{"price":"0.000004974","size":"3374.7"},{"price":"0.000004971","size":"0"}],"sequence":1875061,"timestamp":"2021-07-15T03:06:56.023Z","symbol":"POLYBTC"}}
1626318416.10654: {"jsonrpc":"2.0","method":"updateOrderbook","params":{"ask":[{"price":"0.0000022028","size":"0"},{"price":"0.0000022031","size":"11840"},{"price":"0.0000022032","size":"10320"},{"price":"0.0000022035","size":"0"},{"price":"0.0000022036","size":"0"},{"price":"0.0000022039","size":"5340"}],"bid":[],"sequence":20309671,"timestamp":"2021-07-15T03:06:56.064Z","symbol":"VETBTC"}}
1626318416.228648: {"jsonrpc":"2.0","method":"updateOrderbook","params":{"ask":[{"price":"0.000019674","size":"0"},{"price":"0.000019708","size":"51682.70"},{"price":"0.000021153","size":"0"},{"price":"0.000021274","size":"66111.26"}],"bid":[],"sequence":11276955,"timestamp":"2021-07-15T03:06:56.165Z","symbol":"GRTBTC"}}
1626318416.2286952: {"jsonrpc":"2.0","method":"updateOrderbook","params":{"ask":[{"price":"0.0000022029","size":"11840"},{"price":"0.0000022030","size":"10320"},{"price":"0.0000022031","size":"0"},{"price":"0.0000022032","size":"0"},{"price":"0.0000022036","size":"5340"},{"price":"0.0000022039","size":"0"}],"bid":[],"sequence":20309672,"timestamp":"2021-07-15T03:06:56.154Z","symbol":"VETBTC"}}
1626318416.2945092: {"jsonrpc":"2.0","method":"updateOrderbook","params":{"ask":[{"price":"1.21908","size":"8320.00"},{"price":"1.21914","size":"0"},{"price":"1.21958","size":"15840.00"},{"price":"1.21964","size":"0"},{"price":"1.22028","size":"35680.00"},{"price":"1.22034","size":"0"}],"bid":[{"price":"1.18791","size":"0"},{"price":"1.18787","size":"11596.00"},{"price":"1.18741","size":"0"},{"price":"1.18737","size":"23192.00"},{"price":"1.18671","size":"0"},{"price":"1.18667","size":"34788.00"}],"sequence":7333538,"timestamp":"2021-07-15T03:06:56.229Z","symbol":"EURSUSD"}}
1626318416.302571: {"jsonrpc":"2.0","method":"updateOrderbook","params":{"ask":[{"price":"0.000019488","size":"1989.87"},{"price":"0.000019494","size":"2013.30"},{"price":"0.000019516","size":"0"},{"price":"0.000019534","size":"5580.35"},{"price":"0.000026412","size":"0"},{"price":"0.000026419","size":"10.00"}],"bid":[{"price":"0.000019405","size":"0"},{"price":"0.000019389","size":"538.41"},{"price":"0.000019381","size":"0"},{"price":"0.000019369","size":"2123.51"},{"price":"0.000019342","size":"0"},{"price":"0.000019333","size":"5196.42"}],"sequence":11276956,"timestamp":"2021-07-15T03:06:56.213Z","symbol":"GRTBTC"}}
1626318416.3026402: {"jsonrpc":"2.0","method":"updateOrderbook","params":{"ask":[{"price":"0.0000022029","size":"0"},{"price":"0.0000022030","size":"0"},{"price":"0.0000022033","size":"11840"},{"price":"0.0000022034","size":"10320"},{"price":"0.0000022036","size":"0"},{"price":"0.0000022039","size":"5340"}],"bid":[],"sequence":20309673,"timestamp":"2021-07-15T03:06:56.204Z","symbol":"VETBTC"}}
1626318416.3965068: {"jsonrpc":"2.0","method":"updateOrderbook","params":{"ask":[{"price":"0.000021274","size":"0"},{"price":"0.000021322","size":"66111.26"},{"price":"0.000026412","size":"10.00"},{"price":"0.000026419","size":"0"},{"price":"0.000044127","size":"43968.68"},{"price":"0.000046296","size":"0"}],"bid":[],"sequence":11276957,"timestamp":"2021-07-15T03:06:56.373Z","symbol":"GRTBTC"}}
1626318416.396558: {"jsonrpc":"2.0","method":"updateOrderbook","params":{"ask":[{"price":"0.0000022029","size":"11840"},{"price":"0.0000022030","size":"10320"},{"price":"0.0000022033","size":"0"},{"price":"0.0000022034","size":"0"},{"price":"0.0000022036","size":"5340"},{"price":"0.0000022039","size":"0"}],"bid":[],"sequence":20309674,"timestamp":"2021-07-15T03:06:56.375Z","symbol":"VETBTC"}}
1626318416.494366: {"jsonrpc":"2.0","method":"updateOrderbook","params":{"ask":[{"price":"0.000019468","size":"527.13"},{"price":"0.000019474","size":"0"},{"price":"0.000019481","size":"1989.87"},{"price":"0.000019488","size":"0"}],"bid":[{"price":"0.000019333","size":"5231.26"}],"sequence":11276958,"timestamp":"2021-07-15T03:06:56.470Z","symbol":"GRTBTC"}}
1626318416.497349: {"jsonrpc":"2.0","method":"updateOrderbook","params":{"ask":[{"price":"0.0000022029","size":"0"},{"price":"0.0000022030","size":"0"},{"price":"0.0000022033","size":"11840"},{"price":"0.0000022034","size":"10320"},{"price":"0.0000022036","size":"0"},{"price":"0.0000022039","size":"5340"}],"bid":[],"sequence":20309675,"timestamp":"2021-07-15T03:06:56.434Z","symbol":"VETBTC"}}
1626318416.596384: {"jsonrpc":"2.0","method":"updateOrderbook","params":{"ask":[{"price":"0.0000022029","size":"11840"},{"price":"0.0000022030","size":"10320"},{"price":"0.0000022033","size":"0"},{"price":"0.0000022034","size":"0"},{"price":"0.0000022036","size":"5340"},{"price":"0.0000022039","size":"0"}],"bid":[],"sequence":20309676,"timestamp":"2021-07-15T03:06:56.566Z","symbol":"VETBTC"}}
1626318416.693831: {"jsonrpc":"2.0","method":"updateOrderbook","params":{"ask":[],"bid":[{"price":"1.18787","size":"0"},{"price":"1.18786","size":"11596.00"},{"price":"1.18737","size":"0"},{"price":"1.18736","size":"23192.00"},{"price":"1.18667","size":"0"},{"price":"1.18666","size":"34788.00"}],"sequence":7333539,"timestamp":"2021-07-15T03:06:56.665Z","symbol":"EURSUSD"}}
1626318416.706093: {"jsonrpc":"2.0","method":"updateOrderbook","params":{"ask":[{"price":"0.0000022029","size":"0"},{"price":"0.0000022030","size":"0"},{"price":"0.0000022033","size":"11840"},{"price":"0.0000022034","size":"10320"},{"price":"0.0000022036","size":"0"},{"price":"0.0000022039","size":"5340"}],"bid":[],"sequence":20309677,"timestamp":"2021-07-15T03:06:56.666Z","symbol":"VETBTC"}}
1626318416.7061388: {"jsonrpc":"2.0","method":"updateOrderbook","params":{"ask":[{"price":"0.000086656","size":"1.01"}],"bid":[{"price":"0.000008665","size":"1.03"}],"sequence":3128143,"timestamp":"2021-07-15T03:06:56.646Z","symbol":"INSURBTC"}}
1626318416.8032398: {"jsonrpc":"2.0","method":"updateOrderbook","params":{"ask":[{"price":"0.0000022029","size":"11840"},{"price":"0.0000022030","size":"10320"},{"price":"0.0000022033","size":"0"},{"price":"0.0000022034","size":"0"},{"price":"0.0000022036","size":"5340"},{"price":"0.0000022039","size":"0"}],"bid":[],"sequence":20309678,"timestamp":"2021-07-15T03:06:56.765Z","symbol":"VETBTC"}}
1626318416.896576: {"jsonrpc":"2.0","method":"updateOrderbook","params":{"ask":[{"price":"0.000019481","size":"0"},{"price":"0.000019486","size":"1989.87"}],"bid":[],"sequence":11276959,"timestamp":"2021-07-15T03:06:56.793Z","symbol":"GRTBTC"}}
1626318416.9017012: {"jsonrpc":"2.0","method":"updateOrderbook","params":{"ask":[{"price":"0.0000022029","size":"0"},{"price":"0.0000022030","size":"0"},{"price":"0.0000022033","size":"11840"},{"price":"0.0000022034","size":"10320"},{"price":"0.0000022036","size":"0"},{"price":"0.0000022039","size":"5340"}],"bid":[],"sequence":20309679,"timestamp":"2021-07-15T03:06:56.844Z","symbol":"VETBTC"}}
1626318416.996015: {"jsonrpc":"2.0","method":"updateOrderbook","params":{"ask":[{"price":"0.0000022029","size":"11840"},{"price":"0.0000022030","size":"10320"},{"price":"0.0000022033","size":"0"},{"price":"0.0000022034","size":"0"},{"price":"0.0000022038","size":"5340"},{"price":"0.0000022039","size":"0"}],"bid":[],"sequence":20309680,"timestamp":"2021-07-15T03:06:56.963Z","symbol":"VETBTC"}}
1626318417.107717: {"jsonrpc":"2.0","method":"updateOrderbook","params":{"ask":[{"price":"0.0000022027","size":"11840"},{"price":"0.0000022028","size":"10320"},{"price":"0.0000022029","size":"0"},{"price":"0.0000022030","size":"0"},{"price":"0.0000022036","size":"5340"},{"price":"0.0000022038","size":"0"},{"price":"0.0000022170","size":"0"},{"price":"0.0000022207","size":"112570"},{"price":"0.0000022309","size":"0"},{"price":"0.0000022336","size":"152760"},{"price":"0.0000023445","size":"0"},{"price":"0.0000023710","size":"570330"},{"price":"0.0000032723","size":"0"},{"price":"0.0000032921","size":"806300"},{"price":"0.0000039109","size":"0"},{"price":"0.0000039276","size":"1173990"},{"price":"0.0000060801","size":"0"},{"price":"0.0000061481","size":"1656660"}],"bid":[],"sequence":20309681,"timestamp":"2021-07-15T03:06:57.028Z","symbol":"VETBTC"}}
1626318417.1947699: {"jsonrpc":"2.0","method":"updateOrderbook","params":{"ask":[{"price":"0.000019486","size":"0"},{"price":"0.000019491","size":"1989.87"}],"bid":[],"sequence":11276960,"timestamp":"2021-07-15T03:06:57.094Z","symbol":"GRTBTC"}}
1626318417.197558: {"jsonrpc":"2.0","method":"updateOrderbook","params":{"ask":[{"price":"0.0000022027","size":"0"},{"price":"0.0000022028","size":"0"},{"price":"0.0000022031","size":"11840"},{"price":"0.0000022032","size":"10320"}],"bid":[{"price":"0.0000022000","size":"6390"},{"price":"0.0000021997","size":"4220"}],"sequence":20309682,"timestamp":"2021-07-15T03:06:57.172Z","symbol":"VETBTC"}}
1626318417.297407: {"jsonrpc":"2.0","method":"updateOrderbook","params":{"ask":[{"price":"0.0000022029","size":"11840"},{"price":"0.0000022030","size":"10320"},{"price":"0.0000022031","size":"0"},{"price":"0.0000022032","size":"0"}],"bid":[{"price":"0.0000022000","size":"0"},{"price":"0.0000021996","size":"6390"}],"sequence":20309683,"timestamp":"2021-07-15T03:06:57.237Z","symbol":"VETBTC"}}
1626318417.395424: {"jsonrpc":"2.0","method":"updateOrderbook","params":{"ask":[{"price":"0.000019478","size":"2013.30"},{"price":"0.000019494","size":"0"},{"price":"0.000044127","size":"0"},{"price":"0.000044329","size":"43968.68"}],"bid":[{"price":"0.000019376","size":"2123.51"},{"price":"0.000019369","size":"0"},{"price":"0.000019342","size":"5196.30"},{"price":"0.000019333","size":"34.96"}],"sequence":11276961,"timestamp":"2021-07-15T03:06:57.325Z","symbol":"GRTBTC"}}
1626318417.4002821: {"jsonrpc":"2.0","method":"updateOrderbook","params":{"ask":[{"price":"0.0000022029","size":"0"},{"price":"0.0000022030","size":"0"},{"price":"0.0000022031","size":"11840"},{"price":"0.0000022032","size":"10320"}],"bid":[{"price":"0.0000021997","size":"10610"},{"price":"0.0000021996","size":"0"}],"sequence":20309684,"timestamp":"2021-07-15T03:06:57.370Z","symbol":"VETBTC"}}
1626318417.497888: {"jsonrpc":"2.0","method":"updateOrderbook","params":{"ask":[{"price":"0.000026412","size":"0"},{"price":"0.000026419","size":"10.00"},{"price":"0.000044329","size":"0"},{"price":"0.000044635","size":"43968.68"}],"bid":[],"sequence":11276962,"timestamp":"2021-07-15T03:06:57.425Z","symbol":"GRTBTC"}}
1626318417.500565: {"jsonrpc":"2.0","method":"updateOrderbook","params":{"ask":[{"price":"0.0000022029","size":"11840"},{"price":"0.0000022030","size":"10320"},{"price":"0.0000022031","size":"0"},{"price":"0.0000022032","size":"0"}],"bid":[],"sequence":20309685,"timestamp":"2021-07-15T03:06:57.450Z","symbol":"VETBTC"}}
1626318417.5966232: {"jsonrpc":"2.0","method":"updateOrderbook","params":{"ask":[],"bid":[{"price":"1.18786","size":"0"},{"price":"1.18785","size":"11596.00"},{"price":"1.18736","size":"0"},{"price":"1.18735","size":"23192.00"},{"price":"1.18666","size":"0"},{"price":"1.18665","size":"34788.00"}],"sequence":7333540,"timestamp":"2021-07-15T03:06:57.557Z","symbol":"EURSUSD"}}
1626318417.596684: {"jsonrpc":"2.0","method":"updateOrderbook","params":{"ask":[{"price":"0.000026412","size":"10.00"},{"price":"0.000026419","size":"0"}],"bid":[],"sequence":11276963,"timestamp":"2021-07-15T03:06:57.510Z","symbol":"GRTBTC"}}
1626318417.59671: {"jsonrpc":"2.0","method":"updateOrderbook","params":{"ask":[{"price":"0.0000022029","size":"0"},{"price":"0.0000022030","size":"0"},{"price":"0.0000022031","size":"11840"},{"price":"0.0000022032","size":"10320"},{"price":"0.0000022036","size":"0"},{"price":"0.0000022038","size":"5340"}],"bid":[],"sequence":20309686,"timestamp":"2021-07-15T03:06:57.567Z","symbol":"VETBTC"}}
1626318417.704684: {"jsonrpc":"2.0","method":"updateOrderbook","params":{"ask":[{"price":"0.0000022029","size":"11840"},{"price":"0.0000022030","size":"10320"},{"price":"0.0000022031","size":"0"},{"price":"0.0000022032","size":"0"},{"price":"0.0000022036","size":"5340"},{"price":"0.0000022038","size":"0"}],"bid":[],"sequence":20309687,"timestamp":"2021-07-15T03:06:57.637Z","symbol":"VETBTC"}}
1626318417.704809: {"jsonrpc":"2.0","method":"updateOrderbook","params":{"ask":[{"price":"0.000086652","size":"1.77"},{"price":"0.000086656","size":"0"}],"bid":[{"price":"0.000008665","size":"1.63"}],"sequence":3128144,"timestamp":"2021-07-15T03:06:57.648Z","symbol":"INSURBTC"}}
1626318417.798013: {"jsonrpc":"2.0","method":"updateOrderbook","params":{"ask":[{"price":"0.0000022029","size":"0"},{"price":"0.0000022030","size":"0"},{"price":"0.0000022032","size":"10320"},{"price":"0.0000022033","size":"11840"},{"price":"0.0000022036","size":"0"},{"price":"0.0000022039","size":"5340"}],"bid":[{"price":"0.0000020592","size":"616380"},{"price":"0.0000020487","size":"0"},{"price":"0.0000007074","size":"842410"},{"price":"0.0000006906","size":"0"}],"sequence":20309688,"timestamp":"2021-07-15T03:06:57.772Z","symbol":"VETBTC"}}
1626318417.900577: {"jsonrpc":"2.0","method":"updateOrderbook","params":{"ask":[{"price":"0.000019525","size":"5580.35"},{"price":"0.000019534","size":"0"}],"bid":[],"sequence":11276964,"timestamp":"2021-07-15T03:06:57.815Z","symbol":"GRTBTC"}}
1626318417.909854: {"jsonrpc":"2.0","method":"updateOrderbook","params":{"ask":[{"price":"0.0000022029","size":"11840"},{"price":"0.0000022030","size":"10320"},{"price":"0.0000022032","size":"0"},{"price":"0.0000022033","size":"0"},{"price":"0.0000022036","size":"5340"},{"price":"0.0000022039","size":"0"}],"bid":[],"sequence":20309689,"timestamp":"2021-07-15T03:06:57.839Z","symbol":"VETBTC"}}
1626318417.997091: {"jsonrpc":"2.0","method":"updateOrderbook","params":{"ask":[{"price":"0.0000022029","size":"0"},{"price":"0.0000022030","size":"0"},{"price":"0.0000022033","size":"11840"},{"price":"0.0000022034","size":"10320"},{"price":"0.0000022036","size":"0"},{"price":"0.0000022039","size":"5340"}],"bid":[],"sequence":20309690,"timestamp":"2021-07-15T03:06:57.915Z","symbol":"VETBTC"}}
1626318418.1051: {"jsonrpc":"2.0","method":"updateOrderbook","params":{"ask":[{"price":"0.000019516","size":"10604.13"},{"price":"0.000019526","size":"0"}],"bid":[],"sequence":11276965,"timestamp":"2021-07-15T03:06:58.029Z","symbol":"GRTBTC"}}
1626318418.1051269: {"jsonrpc":"2.0","method":"updateOrderbook","params":{"ask":[{"price":"0.0000022029","size":"11840"},{"price":"0.0000022030","size":"10320"},{"price":"0.0000022033","size":"0"},{"price":"0.0000022034","size":"0"},{"price":"0.0000022038","size":"5340"},{"price":"0.0000022039","size":"0"}],"bid":[],"sequence":20309691,"timestamp":"2021-07-15T03:06:58.056Z","symbol":"VETBTC"}}
1626318418.19759: {"jsonrpc":"2.0","method":"updateOrderbook","params":{"ask":[{"price":"0.0000022029","size":"0"},{"price":"0.0000022030","size":"0"},{"price":"0.0000022033","size":"11840"},{"price":"0.0000022034","size":"10320"},{"price":"0.0000022038","size":"0"},{"price":"0.0000022039","size":"5340"}],"bid":[],"sequence":20309692,"timestamp":"2021-07-15T03:06:58.131Z","symbol":"VETBTC"}}
1626318418.305888: {"jsonrpc":"2.0","method":"updateOrderbook","params":{"ask":[{"price":"0.000019649","size":"51682.70"},{"price":"0.000019708","size":"0"},{"price":"0.000032939","size":"69065.50"},{"price":"0.000035053","size":"0"},{"price":"0.000042262","size":"83849.98"},{"price":"0.000046845","size":"0"}],"bid":[],"sequence":11276966,"timestamp":"2021-07-15T03:06:58.209Z","symbol":"GRTBTC"}}
1626318418.3059242: {"jsonrpc":"2.0","method":"updateOrderbook","params":{"ask":[{"price":"0.0000022029","size":"11840"},{"price":"0.0000022030","size":"10320"},{"price":"0.0000022033","size":"0"},{"price":"0.0000022034","size":"0"},{"price":"0.0000022036","size":"5340"},{"price":"0.0000022039","size":"0"}],"bid":[],"sequence":20309693,"timestamp":"2021-07-15T03:06:58.268Z","symbol":"VETBTC"}}
1626318418.392232: {"jsonrpc":"2.0","method":"updateOrderbook","params":{"ask":[{"price":"0.000019487","size":"4930.69"},{"price":"0.000019499","size":"0"},{"price":"0.000021089","size":"66111.26"},{"price":"0.000021322","size":"0"}],"bid":[{"price":"0.000019304","size":"0"},{"price":"0.000019292","size":"2607.01"}],"sequence":11276967,"timestamp":"2021-07-15T03:06:58.304Z","symbol":"GRTBTC"}}
1626318418.393856: {"jsonrpc":"2.0","method":"updateOrderbook","params":{"ask":[{"price":"0.0000022029","size":"0"},{"price":"0.0000022030","size":"0"},{"price":"0.0000022033","size":"11840"},{"price":"0.0000022034","size":"10320"},{"price":"0.0000022036","size":"0"},{"price":"0.0000022039","size":"5340"}],"bid":[],"sequence":20309694,"timestamp":"2021-07-15T03:06:58.333Z","symbol":"VETBTC"}}
1626318418.508517: {"jsonrpc":"2.0","method":"updateOrderbook","params":{"ask":[{"price":"0.0000022029","size":"11840"},{"price":"0.0000022030","size":"10320"},{"price":"0.0000022033","size":"0"},{"price":"0.0000022034","size":"0"},{"price":"0.0000022036","size":"5340"},{"price":"0.0000022039","size":"0"}],"bid":[],"sequence":20309695,"timestamp":"2021-07-15T03:06:58.475Z","symbol":"VETBTC"}}
1626318418.592059: {"jsonrpc":"2.0","method":"updateOrderbook","params":{"ask":[],"bid":[{"price":"1.18785","size":"0"},{"price":"1.18784","size":"11596.00"},{"price":"1.18735","size":"0"},{"price":"1.18734","size":"23192.00"},{"price":"1.18665","size":"0"},{"price":"1.18664","size":"34788.00"}],"sequence":7333541,"timestamp":"2021-07-15T03:06:58.543Z","symbol":"EURSUSD"}}
1626318418.603816: {"jsonrpc":"2.0","method":"updateOrderbook","params":{"ask":[{"price":"0.000021089","size":"0"},{"price":"0.000021119","size":"66111.26"}],"bid":[],"sequence":11276968,"timestamp":"2021-07-15T03:06:58.521Z","symbol":"GRTBTC"}}
1626318418.606126: {"jsonrpc":"2.0","method":"updateOrderbook","params":{"ask":[{"price":"0.0000022029","size":"0"},{"price":"0.0000022030","size":"0"},{"price":"0.0000022033","size":"11840"},{"price":"0.0000022034","size":"10320"},{"price":"0.0000022036","size":"0"},{"price":"0.0000022039","size":"5340"},{"price":"0.0000102203","size":"1402840"},{"price":"0.0000102862","size":"0"}],"bid":[],"sequence":20309696,"timestamp":"2021-07-15T03:06:58.532Z","symbol":"VETBTC"}}
1626318418.6979609: {"jsonrpc":"2.0","method":"updateOrderbook","params":{"ask":[{"price":"0.0000022029","size":"11840"},{"price":"0.0000022030","size":"10320"},{"price":"0.0000022033","size":"0"},{"price":"0.0000022034","size":"0"},{"price":"0.0000022035","size":"5340"},{"price":"0.0000022039","size":"0"}],"bid":[{"price":"0.0000021977","size":"0"},{"price":"0.0000021971","size":"62230"},{"price":"0.0000020592","size":"0"},{"price":"0.0000020548","size":"616380"},{"price":"0.0000007074","size":"0"},{"price":"0.0000007003","size":"842410"}],"sequence":20309697,"timestamp":"2021-07-15T03:06:58.661Z","symbol":"VETBTC"}}
1626318418.698314: {"jsonrpc":"2.0","method":"updateOrderbook","params":{"ask":[],"bid":[{"price":"0.000008665","size":"1.12"}],"sequence":3128145,"timestamp":"2021-07-15T03:06:58.647Z","symbol":"INSURBTC"}}
1626318418.795469: {"jsonrpc":"2.0","method":"updateOrderbook","params":{"ask":[{"price":"0.0000022029","size":"0"},{"price":"0.0000022030","size":"0"},{"price":"0.0000022032","size":"11840"},{"price":"0.0000022033","size":"10320"},{"price":"0.0000022035","size":"0"},{"price":"0.0000022039","size":"5340"}],"bid":[],"sequence":20309698,"timestamp":"2021-07-15T03:06:58.737Z","symbol":"VETBTC"}}
1626318418.9061499: {"jsonrpc":"2.0","method":"updateOrderbook","params":{"ask":[{"price":"0.0000022028","size":"11840"},{"price":"0.0000022029","size":"10320"},{"price":"0.0000022032","size":"0"},{"price":"0.0000022033","size":"0"},{"price":"0.0000022035","size":"5340"},{"price":"0.0000022039","size":"0"}],"bid":[],"sequence":20309699,"timestamp":"2021-07-15T03:06:58.866Z","symbol":"VETBTC"}}
1626318418.996842: {"jsonrpc":"2.0","method":"updateOrderbook","params":{"ask":[],"bid":[{"price":"1.18785","size":"11596.00"},{"price":"1.18784","size":"0"},{"price":"1.18735","size":"23192.00"},{"price":"1.18734","size":"0"},{"price":"1.18665","size":"34788.00"},{"price":"1.18664","size":"0"}],"sequence":7333542,"timestamp":"2021-07-15T03:06:58.895Z","symbol":"EURSUSD"}}
1626318419.0056489: {"jsonrpc":"2.0","method":"updateOrderbook","params":{"ask":[{"price":"0.0000022028","size":"0"},{"price":"0.0000022029","size":"0"},{"price":"0.0000022032","size":"11840"},{"price":"0.0000022033","size":"10320"},{"price":"0.0000022046","size":"12910"},{"price":"0.0000022049","size":"0"}],"bid":[{"price":"0.0000021997","size":"4220"},{"price":"0.0000021994","size":"1650"},{"price":"0.0000021993","size":"6390"},{"price":"0.0000021987","size":"0"}],"sequence":20309700,"timestamp":"2021-07-15T03:06:58.936Z","symbol":"VETBTC"}}
1626318419.110452: {"jsonrpc":"2.0","method":"updateOrderbook","params":{"ask":[{"price":"0.0000022028","size":"11840"},{"price":"0.0000022029","size":"10320"},{"price":"0.0000022032","size":"0"},{"price":"0.0000022033","size":"0"}],"bid":[{"price":"0.0000021977","size":"18400"},{"price":"0.0000021971","size":"43830"}],"sequence":20309701,"timestamp":"2021-07-15T03:06:59.067Z","symbol":"VETBTC"}}
1626318419.191176: {"jsonrpc":"2.0","method":"updateOrderbook","params":{"ask":[{"price":"0.00020482","size":"0"},{"price":"0.00021055","size":"1.00"}],"bid":[{"price":"0.00010712","size":"0"},{"price":"0.00010139","size":"2.00"}],"sequence":3153555,"timestamp":"2021-07-15T03:06:59.106Z","symbol":"ORNBTC"}}
1626318419.1913679: {"jsonrpc":"2.0","method":"updateOrderbook","params":{"ask":[],"bid":[{"price":"1.18785","size":"0"},{"price":"1.18784","size":"11596.00"},{"price":"1.18735","size":"0"},{"price":"1.18734","size":"23192.00"},{"price":"1.18665","size":"0"},{"price":"1.18664","size":"34788.00"}],"sequence":7333543,"timestamp":"2021-07-15T03:06:59.159Z","symbol":"EURSUSD"}}
1626318419.200385: {"jsonrpc":"2.0","method":"updateOrderbook","params":{"ask":[{"price":"0.000026412","size":"0"},{"price":"0.000027151","size":"10.00"}],"bid":[],"sequence":11276969,"timestamp":"2021-07-15T03:06:59.107Z","symbol":"GRTBTC"}}
1626318419.203572: {"jsonrpc":"2.0","method":"updateOrderbook","params":{"ask":[{"price":"0.0000022028","size":"0"},{"price":"0.0000022029","size":"0"},{"price":"0.0000022032","size":"11840"},{"price":"0.0000022033","size":"10320"},{"price":"0.0000022046","size":"0"},{"price":"0.0000022050","size":"12910"},{"price":"0.0000022170","size":"112570"},{"price":"0.0000022207","size":"0"}],"bid":[{"price":"0.0000021996","size":"8040"},{"price":"0.0000021994","size":"0"},{"price":"0.0000021993","size":"0"}],"sequence":20309702,"timestamp":"2021-07-15T03:06:59.173Z","symbol":"VETBTC"}}
1626318419.303636: {"jsonrpc":"2.0","method":"updateOrderbook","params":{"ask":[{"price":"0.0000022028","size":"11840"},{"price":"0.0000022029","size":"10320"},{"price":"0.0000022032","size":"0"},{"price":"0.0000022033","size":"0"}],"bid":[{"price":"0.0000021996","size":"6390"},{"price":"0.0000021987","size":"1650"}],"sequence":20309703,"timestamp":"2021-07-15T03:06:59.268Z","symbol":"VETBTC"}}
1626318419.3935978: {"jsonrpc":"2.0","method":"updateOrderbook","params":{"ask":[{"price":"0.000019481","size":"1989.87"},{"price":"0.000019491","size":"0"}],"bid":[],"sequence":11276970,"timestamp":"2021-07-15T03:06:59.302Z","symbol":"GRTBTC"}}
1626318419.393644: {"jsonrpc":"2.0","method":"updateOrderbook","params":{"ask":[{"price":"0.0000022028","size":"0"},{"price":"0.0000022029","size":"0"},{"price":"0.0000022033","size":"11840"},{"price":"0.0000022034","size":"10320"},{"price":"0.0000022035","size":"0"},{"price":"0.0000022040","size":"5340"},{"price":"0.0000022050","size":"0"},{"price":"0.0000022051","size":"12910"}],"bid":[{"price":"0.0000021996","size":"0"},{"price":"0.0000021989","size":"1650"},{"price":"0.0000021988","size":"6390"},{"price":"0.0000021987","size":"0"},{"price":"0.0000021977","size":"0"},{"price":"0.0000021971","size":"62230"}],"sequence":20309704,"timestamp":"2021-07-15T03:06:59.352Z","symbol":"VETBTC"}}
1626318419.500143: {"jsonrpc":"2.0","method":"updateOrderbook","params":{"ask":[{"price":"0.0000022029","size":"11840"},{"price":"0.0000022030","size":"10320"},{"price":"0.0000022033","size":"0"},{"price":"0.0000022034","size":"0"},{"price":"0.0000022036","size":"5340"},{"price":"0.0000022040","size":"0"}],"bid":[{"price":"0.0000021996","size":"6390"},{"price":"0.0000021989","size":"0"},{"price":"0.0000021988","size":"0"},{"price":"0.0000021987","size":"1650"}],"sequence":20309705,"timestamp":"2021-07-15T03:06:59.476Z","symbol":"VETBTC"}}
1626318419.590323: {"jsonrpc":"2.0","method":"updateOrderbook","params":{"ask":[],"bid":[{"price":"1.18784","size":"0"},{"price":"1.18783","size":"11596.00"},{"price":"1.18734","size":"0"},{"price":"1.18733","size":"23192.00"},{"price":"1.18664","size":"0"},{"price":"1.18663","size":"34788.00"}],"sequence":7333544,"timestamp":"2021-07-15T03:06:59.560Z","symbol":"EURSUSD"}}
1626318419.599076: {"jsonrpc":"2.0","method":"updateOrderbook","params":{"ask":[{"price":"0.0000022029","size":"0"},{"price":"0.0000022030","size":"0"},{"price":"0.0000022033","size":"11840"},{"price":"0.0000022034","size":"10320"},{"price":"0.0000022036","size":"0"},{"price":"0.0000022040","size":"5340"}],"bid":[{"price":"0.0000021996","size":"8040"},{"price":"0.0000021987","size":"0"}],"sequence":20309706,"timestamp":"2021-07-15T03:06:59.566Z","symbol":"VETBTC"}}
1626318419.69505: {"jsonrpc":"2.0","method":"updateOrderbook","params":{"ask":[{"price":"0.0000022031","size":"11840"},{"price":"0.0000022032","size":"10320"},{"price":"0.0000022033","size":"0"},{"price":"0.0000022034","size":"0"},{"price":"0.0000022036","size":"5340"},{"price":"0.0000022040","size":"0"},{"price":"0.0000022309","size":"152760"},{"price":"0.0000022336","size":"0"}],"bid":[{"price":"0.0000021996","size":"6390"},{"price":"0.0000021987","size":"1650"}],"sequence":20309707,"timestamp":"2021-07-15T03:06:59.633Z","symbol":"VETBTC"}}
1626318419.695384: {"jsonrpc":"2.0","method":"updateOrderbook","params":{"ask":[{"price":"0.000086652","size":"1.36"}],"bid":[{"price":"0.000008665","size":"1.42"}],"sequence":3128146,"timestamp":"2021-07-15T03:06:59.649Z","symbol":"INSURBTC"}}
1626318419.807821: {"jsonrpc":"2.0","method":"updateOrderbook","params":{"ask":[{"price":"0.0000022031","size":"0"},{"price":"0.0000022032","size":"0"},{"price":"0.0000022033","size":"11840"},{"price":"0.0000022034","size":"10320"},{"price":"0.0000022036","size":"0"},{"price":"0.0000022040","size":"5350"},{"price":"0.0000022051","size":"12920"},{"price":"0.0000022086","size":"70310"},{"price":"0.0000022103","size":"0"},{"price":"0.0000022108","size":"26230"}],"bid":[{"price":"0.0000021944","size":"114600"},{"price":"0.0000021939","size":"0"},{"price":"0.0000021922","size":"0"},{"price":"0.0000021919","size":"25970"}],"sequence":20309708,"timestamp":"2021-07-15T03:06:59.772Z","symbol":"VETBTC"}}
1626318419.896933: {"jsonrpc":"2.0","method":"updateOrderbook","params":{"ask":[{"price":"0.000019876","size":"84536.43"}],"bid":[],"sequence":11276971,"timestamp":"2021-07-15T03:06:59.815Z","symbol":"GRTBTC"}}
1626318419.900543: {"jsonrpc":"2.0","method":"updateOrderbook","params":{"ask":[{"price":"0.0000022031","size":"11840"},{"price":"0.0000022032","size":"10320"},{"price":"0.0000022033","size":"0"},{"price":"0.0000022034","size":"0"},{"price":"0.0000022036","size":"5350"},{"price":"0.0000022040","size":"0"}],"bid":[],"sequence":20309709,"timestamp":"2021-07-15T03:06:59.848Z","symbol":"VETBTC"}}
1626318419.9993012: {"jsonrpc":"2.0","method":"updateOrderbook","params":{"ask":[{"price":"0.000019876","size":"0"},{"price":"0.000019909","size":"84536.43"}],"bid":[],"sequence":11276972,"timestamp":"2021-07-15T03:06:59.935Z","symbol":"GRTBTC"}}
1626318420.0031202: {"jsonrpc":"2.0","method":"updateOrderbook","params":{"ask":[{"price":"0.0000022029","size":"11840"},{"price":"0.0000022030","size":"10320"},{"price":"0.0000022031","size":"0"},{"price":"0.0000022032","size":"0"},{"price":"0.0000022047","size":"12920"},{"price":"0.0000022051","size":"0"}],"bid":[],"sequence":20309710,"timestamp":"2021-07-15T03:06:59.961Z","symbol":"VETBTC"}}
1626318420.104479: {"jsonrpc":"2.0","method":"updateOrderbook","params":{"ask":[{"price":"1.21891","size":"8320.00"},{"price":"1.21908","size":"0"},{"price":"1.21941","size":"15840.00"},{"price":"1.21958","size":"0"},{"price":"1.22011","size":"35680.00"},{"price":"1.22028","size":"0"}],"bid":[{"price":"1.18783","size":"0"},{"price":"1.18772","size":"11596.00"},{"price":"1.18733","size":"0"},{"price":"1.18722","size":"23192.00"},{"price":"1.18663","size":"0"},{"price":"1.18652","size":"34788.00"},{"price":"1.18557","size":"0"},{"price":"1.18540","size":"52992.00"},{"price":"1.18261","size":"0"},{"price":"1.18240","size":"50334.00"}],"sequence":7333545,"timestamp":"2021-07-15T03:07:00.074Z","symbol":"EURSUSD"}}
1626318420.1045492: {"jsonrpc":"2.0","method":"updateOrderbook","params":{"ask":[{"price":"0.0000022029","size":"0"},{"price":"0.0000022030","size":"0"},{"price":"0.0000022031","size":"11840"},{"price":"0.0000022032","size":"10320"},{"price":"0.0000022047","size":"0"},{"price":"0.0000022050","size":"12920"}],"bid":[],"sequence":20309711,"timestamp":"2021-07-15T03:07:00.068Z","symbol":"VETBTC"}}
1626318420.19802: {"jsonrpc":"2.0","method":"updateOrderbook","params":{"ask":[{"price":"0.000019462","size":"470.51"},{"price":"0.000019466","size":"1958.07"},{"price":"0.000019472","size":"0"},{"price":"0.000019476","size":"0"}],"bid":[{"price":"0.000019395","size":"538.41"},{"price":"0.000019389","size":"0"}],"sequence":11276973,"timestamp":"2021-07-15T03:07:00.171Z","symbol":"GRTBTC"}}
1626318420.19815: {"jsonrpc":"2.0","method":"updateOrderbook","params":{"ask":[{"price":"0.0000022029","size":"11840"},{"price":"0.0000022030","size":"10320"},{"price":"0.0000022031","size":"0"},{"price":"0.0000022032","size":"0"},{"price":"0.0000102203","size":"0"},{"price":"0.0000102561","size":"1402840"}],"bid":[],"sequence":20309712,"timestamp":"2021-07-15T03:07:00.140Z","symbol":"VETBTC"}}
1626318420.304812: {"jsonrpc":"2.0","method":"updateOrderbook","params":{"ask":[{"price":"0.0000022029","size":"0"},{"price":"0.0000022030","size":"0"},{"price":"0.0000022033","size":"11840"},{"price":"0.0000022034","size":"10320"}],"bid":[],"sequence":20309713,"timestamp":"2021-07-15T03:07:00.253Z","symbol":"VETBTC"}}
1626318420.4043798: {"jsonrpc":"2.0","method":"updateOrderbook","params":{"ask":[{"price":"0.000027151","size":"0"},{"price":"0.000027158","size":"724.30"}],"bid":[],"sequence":11276974,"timestamp":"2021-07-15T03:07:00.362Z","symbol":"GRTBTC"}}
1626318420.4083278: {"jsonrpc":"2.0","method":"updateOrderbook","params":{"ask":[{"price":"0.0000022029","size":"11840"},{"price":"0.0000022030","size":"10320"},{"price":"0.0000022033","size":"0"},{"price":"0.0000022034","size":"0"},{"price":"0.0000022113","size":"4780"},{"price":"0.0000022122","size":"121980"},{"price":"0.0000024263","size":"0"},{"price":"0.0000024448","size":"434810"},{"price":"0.0000038244","size":"0"},{"price":"0.0000038480","size":"598830"},{"price":"0.0000056836","size":"0"},{"price":"0.0000057051","size":"751190"},{"price":"0.0000091021","size":"0"},{"price":"0.0000091183","size":"1665120"}],"bid":[],"sequence":20309714,"timestamp":"2021-07-15T03:07:00.359Z","symbol":"VETBTC"}}
1626318420.500382: {"jsonrpc":"2.0","method":"updateOrderbook","params":{"ask":[{"price":"0.000019517","size":"5580.35"},{"price":"0.000019525","size":"0"},{"price":"0.000027151","size":"10.00"},{"price":"0.000027158","size":"714.30"}],"bid":[{"price":"0.000019343","size":"40.59"}],"sequence":11276975,"timestamp":"2021-07-15T03:07:00.470Z","symbol":"GRTBTC"}}
1626318420.5119739: {"jsonrpc":"2.0","method":"updateOrderbook","params":{"ask":[{"price":"0.0000022029","size":"0"},{"price":"0.0000022030","size":"0"},{"price":"0.0000022033","size":"11840"},{"price":"0.0000022034","size":"10320"}],"bid":[],"sequence":20309715,"timestamp":"2021-07-15T03:07:00.476Z","symbol":"VETBTC"}}
1626318420.594531: {"jsonrpc":"2.0","method":"updateOrderbook","params":{"ask":[{"price":"0.000019481","size":"0"},{"price":"0.000019486","size":"1989.87"},{"price":"0.000032939","size":"0"},{"price":"0.000033283","size":"69065.50"},{"price":"0.000042262","size":"0"},{"price":"0.000042445","size":"83849.98"}],"bid":[{"price":"0.000019333","size":"35.05"}],"sequence":11276976,"timestamp":"2021-07-15T03:07:00.572Z","symbol":"GRTBTC"}}
1626318420.594761: {"jsonrpc":"2.0","method":"updateOrderbook","params":{"ask":[{"price":"0.0000022030","size":"10320"},{"price":"0.0000022031","size":"11840"},{"price":"0.0000022033","size":"0"},{"price":"0.0000022034","size":"0"}],"bid":[],"sequence":20309716,"timestamp":"2021-07-15T03:07:00.574Z","symbol":"VETBTC"}}
1626318420.691623: {"jsonrpc":"2.0","method":"updateOrderbook","params":{"ask":[],"bid":[{"price":"1.18262","size":"0"},{"price":"1.18241","size":"387.48"}],"sequence":7333546,"timestamp":"2021-07-15T03:07:00.672Z","symbol":"EURSUSD"}}
1626318420.695477: {"jsonrpc":"2.0","method":"updateOrderbook","params":{"ask":[],"bid":[{"price":"0.000019333","size":"35.14"}],"sequence":11276977,"timestamp":"2021-07-15T03:07:00.663Z","symbol":"GRTBTC"}}
1626318420.700108: {"jsonrpc":"2.0","method":"updateOrderbook","params":{"ask":[{"price":"0.0000022030","size":"0"},{"price":"0.0000022031","size":"0"},{"price":"0.0000022032","size":"11840"},{"price":"0.0000022033","size":"10320"},{"price":"0.0000022036","size":"0"},{"price":"0.0000022039","size":"5350"},{"price":"0.0000023283","size":"570330"},{"price":"0.0000023710","size":"0"},{"price":"0.0000032582","size":"806300"},{"price":"0.0000032921","size":"0"}],"bid":[{"price":"0.0000007011","size":"842410"},{"price":"0.0000007003","size":"0"}],"sequence":20309717,"timestamp":"2021-07-15T03:07:00.670Z","symbol":"VETBTC"}}
1626318420.700466: {"jsonrpc":"2.0","method":"updateOrderbook","params":{"ask":[{"price":"0.000086651","size":"1.14"},{"price":"0.000086652","size":"0"}],"bid":[{"price":"0.000008665","size":"1.00"}],"sequence":3128147,"timestamp":"2021-07-15T03:07:00.650Z","symbol":"INSURBTC"}}
1626318420.79467: {"jsonrpc":"2.0","method":"updateOrderbook","params":{"ask":[],"bid":[{"price":"0.000019333","size":"35.23"}],"sequence":11276978,"timestamp":"2021-07-15T03:07:00.758Z","symbol":"GRTBTC"}}
1626318420.7963881: {"jsonrpc":"2.0","method":"updateOrderbook","params":{"ask":[{"price":"0.0000022030","size":"11840"},{"price":"0.0000022031","size":"10320"},{"price":"0.0000022032","size":"0"},{"price":"0.0000022033","size":"0"},{"price":"0.0000022034","size":"5350"},{"price":"0.0000022039","size":"0"}],"bid":[{"price":"0.0000020548","size":"0"},{"price":"0.0000020475","size":"616380"},{"price":"0.0000007011","size":"0"},{"price":"0.0000006886","size":"842410"}],"sequence":20309718,"timestamp":"2021-07-15T03:07:00.740Z","symbol":"VETBTC"}}
1626318420.896618: {"jsonrpc":"2.0","method":"updateOrderbook","params":{"ask":[{"price":"0.000019478","size":"0"},{"price":"0.000019492","size":"2013.30"},{"price":"0.000019517","size":"0"},{"price":"0.000019534","size":"5580.35"},{"price":"0.000044635","size":"0"},{"price":"0.000045285","size":"43968.68"}],"bid":[],"sequence":11276979,"timestamp":"2021-07-15T03:07:00.831Z","symbol":"GRTBTC"}}
1626318420.901214: {"jsonrpc":"2.0","method":"updateOrderbook","params":{"ask":[{"price":"0.0000022027","size":"10320"},{"price":"0.0000022030","size":"0"},{"price":"0.0000022031","size":"0"},{"price":"0.0000022033","size":"11840"},{"price":"0.0000022044","size":"12920"},{"price":"0.0000022050","size":"0"}],"bid":[],"sequence":20309719,"timestamp":"2021-07-15T03:07:00.871Z","symbol":"VETBTC"}}
1626318421.001788: {"jsonrpc":"2.0","method":"updateOrderbook","params":{"ask":[],"bid":[{"price":"0.000019333","size":"35.29"}],"sequence":11276980,"timestamp":"2021-07-15T03:07:00.964Z","symbol":"GRTBTC"}}
1626318421.0018282: {"jsonrpc":"2.0","method":"updateOrderbook","params":{"ask":[{"price":"0.0000022027","size":"0"},{"price":"0.0000022029","size":"11840"},{"price":"0.0000022030","size":"10320"},{"price":"0.0000022033","size":"0"}],"bid":[],"sequence":20309720,"timestamp":"2021-07-15T03:07:00.955Z","symbol":"VETBTC"}}
1626318421.091717: {"jsonrpc":"2.0","method":"updateOrderbook","params":{"ask":[],"bid":[{"price":"1.18772","size":"0"},{"price":"1.18771","size":"11596.00"},{"price":"1.18722","size":"0"},{"price":"1.18721","size":"23192.00"},{"price":"1.18652","size":"0"},{"price":"1.18651","size":"34788.00"}],"sequence":7333547,"timestamp":"2021-07-15T03:07:00.977Z","symbol":"EURSUSD"}}
1626318421.093271: {"jsonrpc":"2.0","method":"updateOrderbook","params":{"ask":[],"bid":[{"price":"0.000019333","size":"35.38"}],"sequence":11276981,"timestamp":"2021-07-15T03:07:01.073Z","symbol":"GRTBTC"}}
1626318421.1027122: {"jsonrpc":"2.0","method":"updateOrderbook","params":{"ask":[{"price":"0.0000022027","size":"11840"},{"price":"0.0000022028","size":"10320"},{"price":"0.0000022029","size":"0"},{"price":"0.0000022030","size":"0"},{"price":"0.0000022050","size":"4540"},{"price":"0.0000022059","size":"0"},{"price":"0.0000022060","size":"16420"},{"price":"0.0000022074","size":"0"},{"price":"0.0107905930","size":"441760"}],"bid":[],"sequence":20309721,"timestamp":"2021-07-15T03:07:01.021Z","symbol":"VETBTC"}}
1626318421.1995342: {"jsonrpc":"2.0","method":"updateOrderbook","params":{"ask":[],"bid":[{"price":"0.000019333","size":"35.47"}],"sequence":11276982,"timestamp":"2021-07-15T03:07:01.168Z","symbol":"GRTBTC"}}
1626318421.199578: {"jsonrpc":"2.0","method":"updateOrderbook","params":{"ask":[{"price":"0.0000022027","size":"0"},{"price":"0.0000022028","size":"0"},{"price":"0.0000022029","size":"11840"},{"price":"0.0000022030","size":"10320"},{"price":"0.0000039002","size":"1173990"},{"price":"0.0000039276","size":"0"},{"price":"0.0000060344","size":"1656660"},{"price":"0.0000061481","size":"0"}],"bid":[],"sequence":20309722,"timestamp":"2021-07-15T03:07:01.165Z","symbol":"VETBTC"}}
1626318421.2962759: {"jsonrpc":"2.0","method":"updateOrderbook","params":{"ask":[{"price":"0.000019468","size":"0"},{"price":"0.000019474","size":"527.13"},{"price":"0.000019486","size":"0"},{"price":"0.000019487","size":"0"},{"price":"0.000019495","size":"6920.56"},{"price":"0.000027151","size":"0"},{"price":"0.000027158","size":"724.30"},{"price":"0.000033283","size":"0"},{"price":"0.000033654","size":"69065.50"},{"price":"0.000042445","size":"0"},{"price":"0.000042685","size":"83849.98"},{"price":"0.000045285","size":"0"},{"price":"0.000045792","size":"43968.68"}],"bid":[{"price":"0.000019333","size":"35.48"}],"sequence":11276983,"timestamp":"2021-07-15T03:07:01.273Z","symbol":"GRTBTC"}}
1626318421.296586: {"jsonrpc":"2.0","method":"updateOrderbook","params":{"ask":[{"price":"0.0000022027","size":"11840"},{"price":"0.0000022028","size":"10320"},{"price":"0.0000022029","size":"0"},{"price":"0.0000022030","size":"0"}],"bid":[],"sequence":20309723,"timestamp":"2021-07-15T03:07:01.231Z","symbol":"VETBTC"}}
1626318421.394531: {"jsonrpc":"2.0","method":"updateOrderbook","params":{"ask":[{"price":"0.000019462","size":"0"},{"price":"0.000019466","size":"0"},{"price":"0.000019471","size":"470.51"},{"price":"0.000019475","size":"0"},{"price":"0.000019476","size":"1958.07"},{"price":"0.000019479","size":"0"},{"price":"0.000019487","size":"1974.35"},{"price":"0.000019492","size":"7187.36"},{"price":"0.000019502","size":"0"},{"price":"0.000019511","size":"14681.06"},{"price":"0.000019516","size":"0"},{"price":"0.000019529","size":"10604.13"},{"price":"0.000019534","size":"0"},{"price":"0.000019544","size":"5580.35"},{"price":"0.000019549","size":"0"},{"price":"0.000019560","size":"13766.14"},{"price":"0.000019585","size":"0"},{"price":"0.000019607","size":"17918.70"},{"price":"0.000019649","size":"0"},{"price":"0.000019673","size":"51682.70"},{"price":"0.000019909","size":"0"},{"price":"0.000020006","size":"84536.43"},{"price":"0.000045792","size":"0"},{"price":"0.000045995","size":"43968.68"}],"bid":[{"price":"0.000019333","size":"35.49"}],"sequence":11276984,"timestamp":"2021-07-15T03:07:01.355Z","symbol":"GRTBTC"}}
1626318421.4016042: {"jsonrpc":"2.0","method":"updateOrderbook","params":{"ask":[{"price":"0.0000022027","size":"0"},{"price":"0.0000022028","size":"0"},{"price":"0.0000022029","size":"11840"},{"price":"0.0000022030","size":"10320"},{"price":"0.0000022075","size":"47990"},{"price":"0.0000022086","size":"22320"},{"price":"0.0000022110","size":"73040"},{"price":"0.0000022122","size":"48940"}],"bid":[],"sequence":20309724,"timestamp":"2021-07-15T03:07:01.374Z","symbol":"VETBTC"}}
1626318421.50159: {"jsonrpc":"2.0","method":"updateOrderbook","params":{"ask":[{"price":"0.000019467","size":"0"},{"price":"0.000019472","size":"556.10"},{"price":"0.000019476","size":"2484.63"},{"price":"0.000019495","size":"1989.87"},{"price":"0.000019504","size":"4930.69"},{"price":"0.000020006","size":"0"},{"price":"0.000020036","size":"84536.43"},{"price":"0.000027158","size":"714.30"},{"price":"0.000027165","size":"10.00"}],"bid":[],"sequence":11276985,"timestamp":"2021-07-15T03:07:01.455Z","symbol":"GRTBTC"}}
1626318421.501636: {"jsonrpc":"2.0","method":"updateOrderbook","params":{"ask":[{"price":"0.0000022027","size":"11840"},{"price":"0.0000022028","size":"10320"},{"price":"0.0000022029","size":"0"},{"price":"0.0000022030","size":"0"},{"price":"0.0000022170","size":"0"},{"price":"0.0000022207","size":"112570"},{"price":"0.0000022309","size":"0"},{"price":"0.0000022336","size":"152760"},{"price":"0.0000023283","size":"0"},{"price":"0.0000023710","size":"570330"},{"price":"0.0000032582","size":"0"},{"price":"0.0000032921","size":"806300"},{"price":"0.0000039002","size":"0"},{"price":"0.0000039276","size":"1173990"},{"price":"0.0000060344","size":"0"},{"price":"0.0000061481","size":"1656660"}],"bid":[],"sequence":20309725,"timestamp":"2021-07-15T03:07:01.443Z","symbol":"VETBTC"}}
1626318421.594215: {"jsonrpc":"2.0","method":"updateOrderbook","params":{"ask":[{"price":"0.000019474","size":"0"},{"price":"0.000019476","size":"526.56"},{"price":"0.000019483","size":"527.13"},{"price":"0.000019484","size":"1958.07"},{"price":"0.000019492","size":"2013.30"},{"price":"0.000019495","size":"0"},{"price":"0.000019500","size":"7163.93"},{"price":"0.000019511","size":"0"},{"price":"0.000019521","size":"7129.70"},{"price":"0.000019523","size":"7551.36"},{"price":"0.000019560","size":"0"},{"price":"0.000019573","size":"13766.14"},{"price":"0.000020036","size":"0"},{"price":"0.000020046","size":"84536.43"}],"bid":[],"sequence":11276986,"timestamp":"2021-07-15T03:07:01.567Z","symbol":"GRTBTC"}}
1626318421.5959208: {"jsonrpc":"2.0","method":"updateOrderbook","params":{"ask":[{"price":"0.0000022027","size":"0"},{"price":"0.0000022028","size":"0"},{"price":"0.0000022031","size":"11840"},{"price":"0.0000022032","size":"10320"},{"price":"0.0000022131","size":"198200"},{"price":"0.0000022203","size":"0"}],"bid":[],"sequence":20309726,"timestamp":"2021-07-15T03:07:01.525Z","symbol":"VETBTC"}}
1626318421.693556: {"jsonrpc":"2.0","method":"updateOrderbook","params":{"ask":[{"price":"0.00000267","size":"0.1"}],"bid":[],"sequence":1158485,"timestamp":"2021-07-15T03:07:01.632Z","symbol":"CRDTETH"}}
1626318421.6942568: {"jsonrpc":"2.0","method":"updateOrderbook","params":{"ask":[{"price":"0.000019751","size":"66111.26"},{"price":"0.000021119","size":"0"}],"bid":[],"sequence":11276987,"timestamp":"2021-07-15T03:07:01.626Z","symbol":"GRTBTC"}}
1626318421.700709: {"jsonrpc":"2.0","method":"updateOrderbook","params":{"ask":[{"price":"0.0000022027","size":"11840"},{"price":"0.0000022028","size":"10320"},{"price":"0.0000022031","size":"0"},{"price":"0.0000022032","size":"0"}],"bid":[],"sequence":20309727,"timestamp":"2021-07-15T03:07:01.675Z","symbol":"VETBTC"}}
1626318421.7007968: {"jsonrpc":"2.0","method":"updateOrderbook","params":{"ask":[{"price":"0.000086651","size":"1.34"}],"bid":[{"price":"0.000008665","size":"1.06"}],"sequence":3128148,"timestamp":"2021-07-15T03:07:01.652Z","symbol":"INSURBTC"}}
1626318421.786358: {"jsonrpc":"2.0","method":"updateOrderbook","params":{"ask":[{"price":"0.0000047049","size":"35966"},{"price":"0.0000049092","size":"0"}],"bid":[],"sequence":2357242,"timestamp":"2021-07-15T03:07:01.747Z","symbol":"DNTBTC"}}
1626318421.791906: {"jsonrpc":"2.0","method":"updateOrderbook","params":{"ask":[],"bid":[{"price":"1.18771","size":"0"},{"price":"1.18770","size":"11596.00"},{"price":"1.18721","size":"0"},{"price":"1.18720","size":"23192.00"},{"price":"1.18651","size":"0"},{"price":"1.18650","size":"34788.00"}],"sequence":7333548,"timestamp":"2021-07-15T03:07:01.697Z","symbol":"EURSUSD"}}
1626318421.793094: {"jsonrpc":"2.0","method":"updateOrderbook","params":{"ask":[{"price":"0.00000268","size":"5472.9"}],"bid":[],"sequence":1158486,"timestamp":"2021-07-15T03:07:01.678Z","symbol":"CRDTETH"}}
1626318421.8105128: {"jsonrpc":"2.0","method":"updateOrderbook","params":{"ask":[{"price":"0.000019476","size":"0"},{"price":"0.000019480","size":"526.56"}],"bid":[],"sequence":11276988,"timestamp":"2021-07-15T03:07:01.726Z","symbol":"GRTBTC"}}
1626318421.810567: {"jsonrpc":"2.0","method":"updateOrderbook","params":{"ask":[{"price":"0.0000022027","size":"0"},{"price":"0.0000022028","size":"0"},{"price":"0.0000022031","size":"11840"},{"price":"0.0000022032","size":"10320"}],"bid":[],"sequence":20309728,"timestamp":"2021-07-15T03:07:01.775Z","symbol":"VETBTC"}}
1626318421.901886: {"jsonrpc":"2.0","method":"updateOrderbook","params":{"ask":[],"bid":[{"price":"0.000015795","size":"0"},{"price":"0.000015779","size":"10112.20"},{"price":"0.000015761","size":"0"},{"price":"0.000015744","size":"0"},{"price":"0.000015697","size":"0"},{"price":"0.000015673","size":"134945.44"},{"price":"0.000015661","size":"0"},{"price":"0.000015633","size":"124590.00"},{"price":"0.000015625","size":"0"},{"price":"0.000015596","size":"148057.66"},{"price":"0.000015555","size":"0"},{"price":"0.000015519","size":"126158.18"},{"price":"0.000015489","size":"0"},{"price":"0.000015451","size":"135005.90"},{"price":"0.000015426","size":"0"},{"price":"0.000015374","size":"142493.65"},{"price":"0.000015342","size":"0"},{"price":"0.000015274","size":"147558.99"},{"price":"0.000015193","size":"123941.74"},{"price":"0.000015105","size":"135000.16"}],"sequence":11276989,"timestamp":"2021-07-15T03:07:01.811Z","symbol":"GRTBTC"}}
1626318421.9019608: {"jsonrpc":"2.0","method":"updateOrderbook","params":{"ask":[{"price":"0.0000022029","size":"11840"},{"price":"0.0000022030","size":"10320"},{"price":"0.0000022031","size":"0"},{"price":"0.0000022032","size":"0"},{"price":"0.0000022226","size":"97560"},{"price":"0.0000022240","size":"115440"},{"price":"0.0000022257","size":"0"},{"price":"0.0000022340","size":"0"}],"bid":[],"sequence":20309729,"timestamp":"2021-07-15T03:07:01.838Z","symbol":"VETBTC"}}
1626318422.005522: {"jsonrpc":"2.0","method":"updateOrderbook","params":{"ask":[{"price":"0.000019515","size":"15175.25"},{"price":"0.000019523","size":"0"},{"price":"0.000019562","size":"13766.14"},{"price":"0.000019573","size":"0"},{"price":"0.000020010","size":"84536.43"},{"price":"0.000020046","size":"0"},{"price":"0.000027165","size":"0"},{"price":"0.000027172","size":"10.00"}],"bid":[],"sequence":11276990,"timestamp":"2021-07-15T03:07:01.886Z","symbol":"GRTBTC"}}
1626318422.005567: {"jsonrpc":"2.0","method":"updateOrderbook","params":{"ask":[{"price":"0.0000022029","size":"0"},{"price":"0.0000022030","size":"0"},{"price":"0.0000022031","size":"11840"},{"price":"0.0000022032","size":"10320"},{"price":"0.0000023859","size":"434810"},{"price":"0.0000024448","size":"0"}],"bid":[],"sequence":20309730,"timestamp":"2021-07-15T03:07:01.970Z","symbol":"VETBTC"}}
1626318422.090754: {"jsonrpc":"2.0","method":"updateOrderbook","params":{"ask":[{"price":"0.000019551","size":"13766.14"},{"price":"0.000019562","size":"0"},{"price":"0.000019589","size":"17918.70"},{"price":"0.000019607","size":"0"}],"bid":[],"sequence":11276991,"timestamp":"2021-07-15T03:07:02.020Z","symbol":"GRTBTC"}}
1626318422.094667: {"jsonrpc":"2.0","method":"updateOrderbook","params":{"ask":[{"price":"0.0000022029","size":"11840"},{"price":"0.0000022030","size":"10320"},{"price":"0.0000022031","size":"0"},{"price":"0.0000022032","size":"0"}],"bid":[],"sequence":20309731,"timestamp":"2021-07-15T03:07:02.048Z","symbol":"VETBTC"}}
1626318422.2021801: {"jsonrpc":"2.0","method":"updateOrderbook","params":{"ask":[{"price":"0.000019492","size":"0"},{"price":"0.000019500","size":"9177.23"}],"bid":[],"sequence":11276992,"timestamp":"2021-07-15T03:07:02.156Z","symbol":"GRTBTC"}}
1626318422.2025611: {"jsonrpc":"2.0","method":"updateOrderbook","params":{"ask":[{"price":"0.0000022026","size":"10320"},{"price":"0.0000022027","size":"11840"},{"price":"0.0000022029","size":"0"},{"price":"0.0000022030","size":"0"}],"bid":[{"price":"0.0000021705","size":"23000"},{"price":"0.0000021658","size":"24000"}],"sequence":20309732,"timestamp":"2021-07-15T03:07:02.173Z","symbol":"VETBTC"}}
1626318422.294403: {"jsonrpc":"2.0","method":"updateOrderbook","params":{"ask":[{"price":"0.000019529","size":"0"},{"price":"0.000019541","size":"10604.13"},{"price":"0.000019551","size":"0"},{"price":"0.000019575","size":"13766.14"},{"price":"0.000019589","size":"0"},{"price":"0.000019615","size":"17918.70"},{"price":"0.000020010","size":"0"},{"price":"0.000020086","size":"84536.43"}],"bid":[],"sequence":11276993,"timestamp":"2021-07-15T03:07:02.255Z","symbol":"GRTBTC"}}
1626318422.2976482: {"jsonrpc":"2.0","method":"updateOrderbook","params":{"ask":[{"price":"0.0000022026","size":"0"},{"price":"0.0000022027","size":"0"},{"price":"0.0000022029","size":"11840"},{"price":"0.0000022030","size":"10320"},{"price":"0.0000037387","size":"598830"},{"price":"0.0000038480","size":"0"},{"price":"0.0000056163","size":"751190"},{"price":"0.0000057051","size":"0"}],"bid":[],"sequence":20309733,"timestamp":"2021-07-15T03:07:02.249Z","symbol":"VETBTC"}}
1626318422.398533: {"jsonrpc":"2.0","method":"updateOrderbook","params":{"ask":[{"price":"0.000019500","size":"7163.93"},{"price":"0.000019509","size":"2013.30"},{"price":"0.000019544","size":"0"},{"price":"0.000019579","size":"5580.35"}],"bid":[{"price":"0.000019333","size":"34.84"}],"sequence":11276994,"timestamp":"2021-07-15T03:07:02.323Z","symbol":"GRTBTC"}}
1626318422.3998442: {"jsonrpc":"2.0","method":"updateOrderbook","params":{"ask":[{"price":"0.0000022029","size":"0"},{"price":"0.0000022030","size":"0"},{"price":"0.0000022031","size":"11840"},{"price":"0.0000022032","size":"10320"},{"price":"0.0000022058","size":"58350"},{"price":"0.0000022073","size":"0"}],"bid":[],"sequence":20309734,"timestamp":"2021-07-15T03:07:02.329Z","symbol":"VETBTC"}}
1626318422.506784: {"jsonrpc":"2.0","method":"updateOrderbook","params":{"ask":[{"price":"0.000007762","size":"42099.4"},{"price":"0.000007779","size":"0"}],"bid":[],"sequence":1875062,"timestamp":"2021-07-15T03:07:02.453Z","symbol":"POLYBTC"}}
1626318422.506804: {"jsonrpc":"2.0","method":"updateOrderbook","params":{"ask":[{"price":"0.000019472","size":"0"},{"price":"0.000019480","size":"1082.66"},{"price":"0.000019509","size":"0"},{"price":"0.000019524","size":"2013.30"},{"price":"0.000045995","size":"0"},{"price":"0.000046330","size":"43968.68"}],"bid":[{"price":"0.000019405","size":"538.41"},{"price":"0.000019395","size":"0"}],"sequence":11276995,"timestamp":"2021-07-15T03:07:02.450Z","symbol":"GRTBTC"}}
1626318422.508852: {"jsonrpc":"2.0","method":"updateOrderbook","params":{"ask":[{"price":"0.0000022031","size":"0"},{"price":"0.0000022033","size":"11840"},{"price":"0.0000022380","size":"1174190"},{"price":"0.0000027836","size":"0"}],"bid":[],"sequence":20309735,"timestamp":"2021-07-15T03:07:02.471Z","symbol":"VETBTC"}}
1626318422.605702: {"jsonrpc":"2.0","method":"updateOrderbook","params":{"ask":[{"price":"0.000019553","size":"0"},{"price":"0.000019573","size":"13641.18"}],"bid":[],"sequence":11276996,"timestamp":"2021-07-15T03:07:02.512Z","symbol":"GRTBTC"}}
1626318422.60574: {"jsonrpc":"2.0","method":"updateOrderbook","params":{"ask":[{"price":"0.0000022029","size":"11840"},{"price":"0.0000022030","size":"10320"},{"price":"0.0000022032","size":"0"},{"price":"0.0000022033","size":"0"},{"price":"0.0000069037","size":"441760"},{"price":"0.0000090333","size":"1665120"},{"price":"0.0000091183","size":"0"},{"price":"0.0107905930","size":"0"}],"bid":[],"sequence":20309736,"timestamp":"2021-07-15T03:07:02.545Z","symbol":"VETBTC"}}
1626318422.697872: {"jsonrpc":"2.0","method":"updateOrderbook","params":{"ask":[{"price":"0.0000022025","size":"4140"},{"price":"0.0000022029","size":"0"},{"price":"0.0000022030","size":"0"},{"price":"0.0000022031","size":"11840"},{"price":"0.0000022032","size":"10320"},{"price":"0.0000022037","size":"0"},{"price":"0.0000022081","size":"89650"},{"price":"0.0000022100","size":"0"}],"bid":[],"sequence":20309737,"timestamp":"2021-07-15T03:07:02.628Z","symbol":"VETBTC"}}
1626318422.6979141: {"jsonrpc":"2.0","method":"updateOrderbook","params":{"ask":[{"price":"0.000086651","size":"1.28"}],"bid":[{"price":"0.000008665","size":"1.36"}],"sequence":3128149,"timestamp":"2021-07-15T03:07:02.655Z","symbol":"INSURBTC"}}
1626318422.806412: {"jsonrpc":"2.0","method":"updateOrderbook","params":{"ask":[{"price":"0.0000022024","size":"10320"},{"price":"0.0000022031","size":"0"},{"price":"0.0000022032","size":"0"},{"price":"0.0000022033","size":"11840"}],"bid":[],"sequence":20309738,"timestamp":"2021-07-15T03:07:02.688Z","symbol":"VETBTC"}}
1626318422.8933609: {"jsonrpc":"2.0","method":"updateOrderbook","params":{"ask":[{"price":"1.22380","size":"33556.00"},{"price":"1.22398","size":"0"}],"bid":[{"price":"1.18770","size":"0"},{"price":"1.18769","size":"11596.00"},{"price":"1.18720","size":"0"},{"price":"1.18719","size":"23192.00"},{"price":"1.18650","size":"0"},{"price":"1.18649","size":"34788.00"}],"sequence":7333549,"timestamp":"2021-07-15T03:07:02.786Z","symbol":"EURSUSD"}}
1626318423.213941: {"jsonrpc":"2.0","method":"updateOrderbook","params":{"ask":[{"price":"0.00020957","size":"1.00"},{"price":"0.00021055","size":"0"}],"bid":[{"price":"0.00010236","size":"2.00"},{"price":"0.00010139","size":"0"}],"sequence":3153556,"timestamp":"2021-07-15T03:07:03.110Z","symbol":"ORNBTC"}}
1626318423.213999: {"jsonrpc":"2.0","method":"updateOrderbook","params":{"ask":[{"price":"0.000027046","size":"10.00"},{"price":"0.000027172","size":"0"}],"bid":[],"sequence":11276997,"timestamp":"2021-07-15T03:07:03.110Z","symbol":"GRTBTC"}}
1626318423.299166: {"jsonrpc":"2.0","method":"updateOrderbook","params":{"ask":[{"price":"0.000019564","size":"13766.14"},{"price":"0.000019575","size":"0"}],"bid":[],"sequence":11276998,"timestamp":"2021-07-15T03:07:03.218Z","symbol":"GRTBTC"}}
1626318423.2991989: {"jsonrpc":"2.0","method":"updateOrderbook","params":{"ask":[],"bid":[{"price":"0.0000021705","size":"47000"},{"price":"0.0000021658","size":"0"}],"sequence":20309739,"timestamp":"2021-07-15T03:07:03.216Z","symbol":"VETBTC"}}
1626318423.505568: {"jsonrpc":"2.0","method":"updateOrderbook","params":{"ask":[{"price":"0.000019487","size":"0"},{"price":"0.000019494","size":"1974.35"}],"bid":[],"sequence":11276999,"timestamp":"2021-07-15T03:07:03.411Z","symbol":"GRTBTC"}}
1626318423.597731: {"jsonrpc":"2.0","method":"updateOrderbook","params":{"ask":[{"price":"0.000019591","size":"17918.70"},{"price":"0.000019615","size":"0"}],"bid":[],"sequence":11277000,"timestamp":"2021-07-15T03:07:03.546Z","symbol":"GRTBTC"}}
1626318423.604246: {"jsonrpc":"2.0","method":"updateOrderbook","params":{"ask":[{"price":"0.0000022168","size":"879930"},{"price":"0.0000022197","size":"220820"},{"price":"0.0000022301","size":"927570"},{"price":"0.0000022352","size":"0"}],"bid":[{"price":"0.0000021705","size":"23000"},{"price":"0.0000021658","size":"24000"}],"sequence":20309740,"timestamp":"2021-07-15T03:07:03.501Z","symbol":"VETBTC"}}
1626318423.702108: {"jsonrpc":"2.0","method":"updateOrderbook","params":{"ask":[],"bid":[{"price":"0.000019410","size":"538.41"},{"price":"0.000019405","size":"0"},{"price":"0.000015901","size":"562.39"},{"price":"0.000015810","size":"0"}],"sequence":11277001,"timestamp":"2021-07-15T03:07:03.635Z","symbol":"GRTBTC"}}
1626318423.702195: {"jsonrpc":"2.0","method":"updateOrderbook","params":{"ask":[{"price":"0.0000022170","size":"112570"},{"price":"0.0000022207","size":"0"}],"bid":[],"sequence":20309741,"timestamp":"2021-07-15T03:07:03.608Z","symbol":"VETBTC"}}
1626318423.7022111: {"jsonrpc":"2.0","method":"updateOrderbook","params":{"ask":[{"price":"0.000086650","size":"1.87"},{"price":"0.000086651","size":"0"}],"bid":[{"price":"0.000008665","size":"0"},{"price":"0.000008664","size":"1.84"}],"sequence":3128150,"timestamp":"2021-07-15T03:07:03.655Z","symbol":"INSURBTC"}}
1626318423.796469: {"jsonrpc":"2.0","method":"updateOrderbook","params":{"ask":[{"price":"0.000005656","size":"1856.1"},{"price":"0.000005660","size":"0"}],"bid":[],"sequence":1875063,"timestamp":"2021-07-15T03:07:03.754Z","symbol":"POLYBTC"}}
1626318423.895916: {"jsonrpc":"2.0","method":"updateOrderbook","params":{"ask":[],"bid":[{"price":"1.18769","size":"0"},{"price":"1.18768","size":"11596.00"},{"price":"1.18719","size":"0"},{"price":"1.18718","size":"23192.00"},{"price":"1.18649","size":"0"},{"price":"1.18648","size":"34788.00"}],"sequence":7333550,"timestamp":"2021-07-15T03:07:03.796Z","symbol":"EURSUSD"}}
1626318424.094191: {"jsonrpc":"2.0","method":"updateOrderbook","params":{"ask":[{"price":"1.26131","size":"0"},{"price":"1.33000","size":"164870.78"}],"bid":[{"price":"1.13830","size":"0"},{"price":"1.11703","size":"0"},{"price":"1.10962","size":"16460.07"},{"price":"0.98059","size":"16496.07"}],"sequence":7333551,"timestamp":"2021-07-15T03:07:03.980Z","symbol":"EURSUSD"}}
1626318424.21711: {"jsonrpc":"2.0","method":"updateOrderbook","params":{"ask":[{"price":"0.000019911","size":"84536.43"},{"price":"0.000020086","size":"0"}],"bid":[],"sequence":11277002,"timestamp":"2021-07-15T03:07:04.142Z","symbol":"GRTBTC"}}
1626318424.2171662: {"jsonrpc":"2.0","method":"updateOrderbook","params":{"ask":[{"price":"0.0000022309","size":"152760"},{"price":"0.0000022336","size":"0"}],"bid":[],"sequence":20309742,"timestamp":"2021-07-15T03:07:04.148Z","symbol":"VETBTC"}}
1626318424.319864: {"jsonrpc":"2.0","method":"updateOrderbook","params":{"ask":[{"price":"0.000006213","size":"0"}],"bid":[],"sequence":1875064,"timestamp":"2021-07-15T03:07:04.233Z","symbol":"POLYBTC"}}
1626318424.5053508: {"jsonrpc":"2.0","method":"updateOrderbook","params":{"ask":[{"price":"0.0000096370","size":"2748380"}],"bid":[],"sequence":20309743,"timestamp":"2021-07-15T03:07:04.431Z","symbol":"VETBTC"}}
1626318424.6099179: {"jsonrpc":"2.0","method":"updateOrderbook","params":{"ask":[{"price":"0.000033654","size":"0"},{"price":"0.000033919","size":"69065.50"},{"price":"0.000042685","size":"0"},{"price":"0.000044089","size":"83849.98"}],"bid":[],"sequence":11277003,"timestamp":"2021-07-15T03:07:04.568Z","symbol":"GRTBTC"}}
1626318424.741547: {"jsonrpc":"2.0","method":"updateOrderbook","params":{"ask":[{"price":"0.0000096370","size":"0"}],"bid":[],"sequence":20309744,"timestamp":"2021-07-15T03:07:04.643Z","symbol":"VETBTC"}}
1626318424.741587: {"jsonrpc":"2.0","method":"updateOrderbook","params":{"ask":[{"price":"0.000086650","size":"0"},{"price":"0.000086654","size":"1.58"}],"bid":[{"price":"0.000008665","size":"1.58"},{"price":"0.000008664","size":"0"}],"sequence":3128151,"timestamp":"2021-07-15T03:07:04.657Z","symbol":"INSURBTC"}}
1626318424.8875709: {"jsonrpc":"2.0","method":"updateOrderbook","params":{"ask":[{"price":"0.0000022044","size":"12930"},{"price":"0.0000022081","size":"111980"},{"price":"0.0000022086","size":"0"},{"price":"0.0000022098","size":"26250"},{"price":"0.0000022108","size":"0"}],"bid":[{"price":"0.0000021996","size":"0"},{"price":"0.0000021994","size":"8050"},{"price":"0.0000021987","size":"0"},{"price":"0.0000021984","size":"11880"},{"price":"0.0000021946","size":"22070"},{"price":"0.0000021944","size":"92540"},{"price":"0.0000021929","size":"25990"},{"price":"0.0000021919","size":"0"}],"sequence":20309745,"timestamp":"2021-07-15T03:07:04.737Z","symbol":"VETBTC"}}
1626318425.2063758: {"jsonrpc":"2.0","method":"updateOrderbook","params":{"ask":[{"price":"0.0000023282","size":"570330"},{"price":"0.0000023710","size":"0"},{"price":"0.0000032582","size":"806300"},{"price":"0.0000032921","size":"0"}],"bid":[],"sequence":20309746,"timestamp":"2021-07-15T03:07:05.148Z","symbol":"VETBTC"}}
1626318425.510349: {"jsonrpc":"2.0","method":"updateOrderbook","params":{"ask":[{"price":"0.000019751","size":"0"},{"price":"0.000019911","size":"0"},{"price":"0.000021186","size":"66111.26"}],"bid":[],"sequence":11277004,"timestamp":"2021-07-15T03:07:05.310Z","symbol":"GRTBTC"}}
1626318425.5103722: {"jsonrpc":"2.0","method":"updateOrderbook","params":{"ask":[],"bid":[{"price":"1.18769","size":"11596.00"},{"price":"1.18768","size":"0"},{"price":"1.18719","size":"23192.00"},{"price":"1.18718","size":"0"},{"price":"1.18649","size":"34788.00"},{"price":"1.18648","size":"0"}],"sequence":7333552,"timestamp":"2021-07-15T03:07:05.452Z","symbol":"EURSUSD"}}
1626318425.510387: {"jsonrpc":"2.0","method":"updateOrderbook","params":{"ask":[{"price":"0.000019673","size":"0"},{"price":"0.000019742","size":"51682.70"},{"price":"0.000019752","size":"0"},{"price":"0.000019781","size":"31811.19"},{"price":"0.000019938","size":"84536.43"},{"price":"0.000021186","size":"0"},{"price":"0.000021359","size":"66111.26"},{"price":"0.000027941","size":"22732.57"},{"price":"0.000046330","size":"0"},{"price":"0.000057521","size":"37723.11"}],"bid":[],"sequence":11277005,"timestamp":"2021-07-15T03:07:05.473Z","symbol":"GRTBTC"}}
1626318425.510401: {"jsonrpc":"2.0","method":"updateOrderbook","params":{"ask":[],"bid":[{"price":"0.0000021705","size":"47000"},{"price":"0.0000021658","size":"0"}],"sequence":20309747,"timestamp":"2021-07-15T03:07:05.439Z","symbol":"VETBTC"}}
1626318425.72644: {"jsonrpc":"2.0","method":"updateOrderbook","params":{"ask":[{"price":"0.000086654","size":"1.44"}],"bid":[{"price":"0.000008665","size":"1.16"}],"sequence":3128152,"timestamp":"2021-07-15T03:07:05.658Z","symbol":"INSURBTC"}}
1626318425.732943: {"jsonrpc":"2.0","method":"updateOrderbook","params":{"ask":[{"price":"0.0000039002","size":"1173990"},{"price":"0.0000039276","size":"0"},{"price":"0.0000060344","size":"1656660"},{"price":"0.0000061481","size":"0"}],"bid":[{"price":"0.0000021994","size":"6400"},{"price":"0.0000021987","size":"1650"}],"sequence":20309748,"timestamp":"2021-07-15T03:07:05.613Z","symbol":"VETBTC"}}
1626318425.899395: {"jsonrpc":"2.0","method":"updateOrderbook","params":{"ask":[{"price":"0.000006293","size":"1504.0"}],"bid":[],"sequence":1875065,"timestamp":"2021-07-15T03:07:05.793Z","symbol":"POLYBTC"}}
1626318425.903137: {"jsonrpc":"2.0","method":"updateOrderbook","params":{"ask":[{"price":"0.0000022032","size":"11840"},{"price":"0.0000022033","size":"5350"},{"price":"0.0000022034","size":"0"},{"price":"0.0000096370","size":"2748380"}],"bid":[{"price":"0.0000021995","size":"6400"},{"price":"0.0000021994","size":"0"}],"sequence":20309749,"timestamp":"2021-07-15T03:07:05.853Z","symbol":"VETBTC"}}
1626318426.120634: {"jsonrpc":"2.0","method":"updateOrderbook","params":{"ask":[],"bid":[{"price":"0.0000021705","size":"23000"},{"price":"0.0000021658","size":"24000"}],"sequence":20309750,"timestamp":"2021-07-15T03:07:06.068Z","symbol":"VETBTC"}}
1626318426.422837: {"jsonrpc":"2.0","method":"updateOrderbook","params":{"ask":[{"price":"0.000019531","size":"10604.13"},{"price":"0.000019541","size":"0"}],"bid":[{"price":"0.000019342","size":"0"},{"price":"0.000019331","size":"5196.30"}],"sequence":11277006,"timestamp":"2021-07-15T03:07:06.334Z","symbol":"GRTBTC"}}
1626318426.422868: {"jsonrpc":"2.0","method":"updateOrderbook","params":{"ask":[],"bid":[{"price":"0.0000020475","size":"0"},{"price":"0.0000020293","size":"616380"},{"price":"0.0000006886","size":"0"},{"price":"0.0000006574","size":"842410"}],"sequence":20309751,"timestamp":"2021-07-15T03:07:06.301Z","symbol":"VETBTC"}}
1626318426.523503: {"jsonrpc":"2.0","method":"updateOrderbook","params":{"ask":[{"price":"0.000046330","size":"43968.68"}],"bid":[],"sequence":11277007,"timestamp":"2021-07-15T03:07:06.454Z","symbol":"GRTBTC"}}
1626318426.600411: {"jsonrpc":"2.0","method":"updateOrderbook","params":{"ask":[{"price":"0.000019503","size":"2013.30"},{"price":"0.000019524","size":"0"}],"bid":[],"sequence":11277008,"timestamp":"2021-07-15T03:07:06.575Z","symbol":"GRTBTC"}}
1626318426.705271: {"jsonrpc":"2.0","method":"updateOrderbook","params":{"ask":[{"price":"0.000019571","size":"5580.35"},{"price":"0.000019579","size":"0"}],"bid":[],"sequence":11277009,"timestamp":"2021-07-15T03:07:06.643Z","symbol":"GRTBTC"}}
1626318426.705306: {"jsonrpc":"2.0","method":"updateOrderbook","params":{"ask":[{"price":"0.000086654","size":"0"},{"price":"0.000086656","size":"1.25"}],"bid":[{"price":"0.000008665","size":"1.71"}],"sequence":3128153,"timestamp":"2021-07-15T03:07:06.659Z","symbol":"INSURBTC"}}
1626318427.000457: {"jsonrpc":"2.0","method":"updateOrderbook","params":{"ask":[{"price":"0.0000023282","size":"0"},{"price":"0.0000023445","size":"570330"},{"price":"0.0000032582","size":"0"},{"price":"0.0000032723","size":"806300"},{"price":"0.0000039002","size":"0"},{"price":"0.0000039109","size":"1173990"},{"price":"0.0000060344","size":"0"},{"price":"0.0000060801","size":"1656660"}],"bid":[],"sequence":20309752,"timestamp":"2021-07-15T03:07:06.968Z","symbol":"VETBTC"}}
1626318427.09791: {"jsonrpc":"2.0","method":"updateOrderbook","params":{"ask":[{"price":"0.000019652","size":"51682.70"},{"price":"0.000019742","size":"0"}],"bid":[],"sequence":11277010,"timestamp":"2021-07-15T03:07:07.047Z","symbol":"GRTBTC"}}
1626318427.1927092: {"jsonrpc":"2.0","method":"updateOrderbook","params":{"ask":[{"price":"0.00020533","size":"1.00"},{"price":"0.00020957","size":"0"}],"bid":[{"price":"0.00010661","size":"2.00"},{"price":"0.00010236","size":"0"}],"sequence":3153557,"timestamp":"2021-07-15T03:07:07.111Z","symbol":"ORNBTC"}}
1626318427.196962: {"jsonrpc":"2.0","method":"updateOrderbook","params":{"ask":[{"price":"0.000026499","size":"10.00"},{"price":"0.000027046","size":"0"}],"bid":[],"sequence":11277011,"timestamp":"2021-07-15T03:07:07.111Z","symbol":"GRTBTC"}}
1626318427.407031: {"jsonrpc":"2.0","method":"updateOrderbook","params":{"ask":[{"price":"0.000019751","size":"66111.26"},{"price":"0.000021359","size":"0"}],"bid":[{"price":"0.000019408","size":"2123.51"},{"price":"0.000019376","size":"0"}],"sequence":11277012,"timestamp":"2021-07-15T03:07:07.317Z","symbol":"GRTBTC"}}
1626318427.407072: {"jsonrpc":"2.0","method":"updateOrderbook","params":{"ask":[{"price":"0.0000023642","size":"434810"},{"price":"0.0000023859","size":"0"}],"bid":[],"sequence":20309753,"timestamp":"2021-07-15T03:07:07.371Z","symbol":"VETBTC"}}
1626318427.602096: {"jsonrpc":"2.0","method":"updateOrderbook","params":{"ask":[],"bid":[{"price":"0.000019425","size":"538.41"},{"price":"0.000019410","size":"0"}],"sequence":11277013,"timestamp":"2021-07-15T03:07:07.531Z","symbol":"GRTBTC"}}
1626318427.6022232: {"jsonrpc":"2.0","method":"updateOrderbook","params":{"ask":[{"price":"0.0000023642","size":"0"},{"price":"0.0000023749","size":"434810"}],"bid":[],"sequence":20309754,"timestamp":"2021-07-15T03:07:07.558Z","symbol":"VETBTC"}}
1626318427.6918678: {"jsonrpc":"2.0","method":"updateOrderbook","params":{"ask":[{"price":"0.00015180","size":"0"},{"price":"0.00015200","size":"602.07"},{"price":"0.00015436","size":"0"},{"price":"0.00015494","size":"953.23"},{"price":"0.00015605","size":"0"},{"price":"0.00015621","size":"1320.35"},{"price":"0.00015945","size":"0"},{"price":"0.00015974","size":"1733.18"},{"price":"0.00016314","size":"0"},{"price":"0.00016347","size":"2890.66"},{"price":"0.00016958","size":"0"},{"price":"0.00016997","size":"4424.71"}],"bid":[],"sequence":3153558,"timestamp":"2021-07-15T03:07:07.626Z","symbol":"ORNBTC"}}
1626318427.697286: {"jsonrpc":"2.0","method":"updateOrderbook","params":{"ask":[{"price":"0.0000037125","size":"598830"},{"price":"0.0000037387","size":"0"},{"price":"0.0000055980","size":"751190"},{"price":"0.0000056163","size":"0"}],"bid":[],"sequence":20309755,"timestamp":"2021-07-15T03:07:07.663Z","symbol":"VETBTC"}}
1626318427.7004979: {"jsonrpc":"2.0","method":"updateOrderbook","params":{"ask":[{"price":"0.000086656","size":"1.33"}],"bid":[{"price":"0.000008665","size":"1.92"}],"sequence":3128154,"timestamp":"2021-07-15T03:07:07.660Z","symbol":"INSURBTC"}}
1626318427.8998861: {"jsonrpc":"2.0","method":"updateOrderbook","params":{"ask":[{"price":"0.0000022032","size":"0"},{"price":"0.0000022033","size":"11840"},{"price":"0.0000022034","size":"5350"},{"price":"0.0000023749","size":"0"},{"price":"0.0000023862","size":"434810"},{"price":"0.0000037125","size":"0"},{"price":"0.0000037394","size":"598830"},{"price":"0.0000055980","size":"0"},{"price":"0.0000056184","size":"751190"},{"price":"0.0000096370","size":"0"}],"bid":[],"sequence":20309756,"timestamp":"2021-07-15T03:07:07.828Z","symbol":"VETBTC"}}
1626318427.99792: {"jsonrpc":"2.0","method":"updateOrderbook","params":{"ask":[],"bid":[{"price":"0.000019355","size":"5196.30"},{"price":"0.000019331","size":"0"}],"sequence":11277014,"timestamp":"2021-07-15T03:07:07.968Z","symbol":"GRTBTC"}}
1626318427.9979498: {"jsonrpc":"2.0","method":"updateOrderbook","params":{"ask":[],"bid":[{"price":"0.0000021705","size":"47000"},{"price":"0.0000021658","size":"0"}],"sequence":20309757,"timestamp":"2021-07-15T03:07:07.974Z","symbol":"VETBTC"}}
1626318427.997965: {"jsonrpc":"2.0","method":"updateOrderbook","params":{"ask":[{"price":"0.000043703","size":"17473.19"},{"price":"0.000043781","size":"0"}],"bid":[],"sequence":3128155,"timestamp":"2021-07-15T03:07:07.879Z","symbol":"INSURBTC"}}
1626318428.1988978: {"jsonrpc":"2.0","method":"updateOrderbook","params":{"ask":[{"price":"0.000019891","size":"84536.43"},{"price":"0.000019938","size":"0"}],"bid":[],"sequence":11277015,"timestamp":"2021-07-15T03:07:08.172Z","symbol":"GRTBTC"}}
1626318428.203441: {"jsonrpc":"2.0","method":"updateOrderbook","params":{"ask":[],"bid":[{"price":"0.0000021977","size":"18400"},{"price":"0.0000021971","size":"43830"}],"sequence":20309758,"timestamp":"2021-07-15T03:07:08.122Z","symbol":"VETBTC"}}
1626318428.399353: {"jsonrpc":"2.0","method":"updateOrderbook","params":{"ask":[],"bid":[{"price":"0.0000021977","size":"0"},{"price":"0.0000021971","size":"62230"},{"price":"0.0000020547","size":"616380"},{"price":"0.0000020293","size":"0"},{"price":"0.0000007001","size":"842410"},{"price":"0.0000006574","size":"0"}],"sequence":20309759,"timestamp":"2021-07-15T03:07:08.305Z","symbol":"VETBTC"}}
1626318428.7011468: {"jsonrpc":"2.0","method":"updateOrderbook","params":{"ask":[{"price":"0.000086656","size":"1.84"}],"bid":[{"price":"0.000008665","size":"1.05"}],"sequence":3128156,"timestamp":"2021-07-15T03:07:08.661Z","symbol":"INSURBTC"}}
1626318428.9072158: {"jsonrpc":"2.0","method":"updateOrderbook","params":{"ask":[{"price":"0.0000037394","size":"0"},{"price":"0.0000037445","size":"598830"},{"price":"0.0000056184","size":"0"},{"price":"0.0000056222","size":"751190"},{"price":"0.0000090333","size":"0"},{"price":"0.0000090384","size":"1665120"}],"bid":[],"sequence":20309760,"timestamp":"2021-07-15T03:07:08.813Z","symbol":"VETBTC"}}
1626318429.0020952: {"jsonrpc":"2.0","method":"updateOrderbook","params":{"ask":[{"price":"0.000019766","size":"22732.57"},{"price":"0.000027941","size":"0"},{"price":"0.000032704","size":"69065.50"},{"price":"0.000033919","size":"0"},{"price":"0.000042756","size":"83849.98"},{"price":"0.000044089","size":"0"}],"bid":[],"sequence":11277016,"timestamp":"2021-07-15T03:07:08.958Z","symbol":"GRTBTC"}}
1626318429.594065: {"jsonrpc":"2.0","method":"updateOrderbook","params":{"ask":[],"bid":[{"price":"0.0000025437","size":"0"},{"price":"0.0000025294","size":"5805"}],"sequence":2357243,"timestamp":"2021-07-15T03:07:09.451Z","symbol":"DNTBTC"}}
1626318429.594081: {"jsonrpc":"2.0","method":"updateOrderbook","params":{"ask":[{"price":"0.000019553","size":"5580.35"},{"price":"0.000019571","size":"0"},{"price":"0.000019591","size":"0"},{"price":"0.000019606","size":"17918.70"},{"price":"0.000019891","size":"0"},{"price":"0.000019999","size":"84536.43"},{"price":"0.000032704","size":"0"},{"price":"0.000033511","size":"69065.50"},{"price":"0.000042756","size":"0"},{"price":"0.000043367","size":"83849.98"}],"bid":[],"sequence":11277017,"timestamp":"2021-07-15T03:07:09.429Z","symbol":"GRTBTC"}}
1626318429.5940962: {"jsonrpc":"2.0","method":"updateOrderbook","params":{"ask":[],"bid":[{"price":"0.0000021995","size":"0"},{"price":"0.0000021984","size":"0"},{"price":"0.0000021977","size":"6400"},{"price":"0.0000021968","size":"204420"}],"sequence":20309761,"timestamp":"2021-07-15T03:07:09.388Z","symbol":"VETBTC"}}
1626318429.598142: {"jsonrpc":"2.0","method":"updateOrderbook","params":{"ask":[],"bid":[{"price":"1.18769","size":"0"},{"price":"1.18768","size":"11596.00"},{"price":"1.18719","size":"0"},{"price":"1.18718","size":"23192.00"},{"price":"1.18649","size":"0"},{"price":"1.18648","size":"34788.00"}],"sequence":7333553,"timestamp":"2021-07-15T03:07:09.505Z","symbol":"EURSUSD"}}
1626318429.6034: {"jsonrpc":"2.0","method":"updateOrderbook","params":{"ask":[{"price":"0.000019801","size":"37723.11"},{"price":"0.000042945","size":"43968.68"},{"price":"0.000046330","size":"0"},{"price":"0.000057521","size":"0"}],"bid":[],"sequence":11277018,"timestamp":"2021-07-15T03:07:09.531Z","symbol":"GRTBTC"}}
1626318429.69437: {"jsonrpc":"2.0","method":"updateOrderbook","params":{"ask":[{"price":"0.00015181","size":"602.07"},{"price":"0.00015200","size":"0"},{"price":"0.00015436","size":"953.23"},{"price":"0.00015494","size":"0"}],"bid":[],"sequence":3153559,"timestamp":"2021-07-15T03:07:09.665Z","symbol":"ORNBTC"}}
1626318429.701621: {"jsonrpc":"2.0","method":"updateOrderbook","params":{"ask":[{"price":"0.0000102250","size":"1402840"},{"price":"0.0000102561","size":"0"}],"bid":[{"price":"0.0000021995","size":"6400"},{"price":"0.0000021977","size":"0"}],"sequence":20309762,"timestamp":"2021-07-15T03:07:09.629Z","symbol":"VETBTC"}}
1626318429.7016609: {"jsonrpc":"2.0","method":"updateOrderbook","params":{"ask":[{"price":"0.000086652","size":"1.40"},{"price":"0.000086656","size":"0"}],"bid":[{"price":"0.000008665","size":"1.23"}],"sequence":3128157,"timestamp":"2021-07-15T03:07:09.661Z","symbol":"INSURBTC"}}
1626318429.808241: {"jsonrpc":"2.0","method":"updateOrderbook","params":{"ask":[{"price":"0.0000022080","size":"22340"},{"price":"0.0000022081","size":"89650"},{"price":"0.0000022096","size":"26260"},{"price":"0.0000022098","size":"0"}],"bid":[{"price":"0.0000021968","size":"204430"},{"price":"0.0000021946","size":"0"},{"price":"0.0000021932","size":"22080"},{"price":"0.0000021929","size":"0"},{"price":"0.0000021916","size":"26000"}],"sequence":20309763,"timestamp":"2021-07-15T03:07:09.728Z","symbol":"VETBTC"}}
1626318429.898197: {"jsonrpc":"2.0","method":"updateOrderbook","params":{"ask":[],"bid":[{"price":"0.0000021986","size":"16540"},{"price":"0.0000021968","size":"192540"}],"sequence":20309764,"timestamp":"2021-07-15T03:07:09.813Z","symbol":"VETBTC"}}
1626318430.253948: {"jsonrpc":"2.0","method":"updateOrderbook","params":{"ask":[{"price":"0.00015605","size":"1320.35"},{"price":"0.00015621","size":"0"},{"price":"0.00015945","size":"1733.18"},{"price":"0.00015974","size":"0"}],"bid":[],"sequence":3153560,"timestamp":"2021-07-15T03:07:10.160Z","symbol":"ORNBTC"}}
1626318430.254008: {"jsonrpc":"2.0","method":"updateOrderbook","params":{"ask":[{"price":"0.000019511","size":"7129.70"},{"price":"0.000019521","size":"0"}],"bid":[],"sequence":11277019,"timestamp":"2021-07-15T03:07:10.111Z","symbol":"GRTBTC"}}
1626318430.4104362: {"jsonrpc":"2.0","method":"updateOrderbook","params":{"ask":[{"price":"0.000019551","size":"13641.18"},{"price":"0.000019573","size":"0"}],"bid":[],"sequence":11277020,"timestamp":"2021-07-15T03:07:10.317Z","symbol":"GRTBTC"}}
1626318430.509347: {"jsonrpc":"2.0","method":"updateOrderbook","params":{"ask":[{"price":"0.000019541","size":"13766.14"},{"price":"0.000019564","size":"0"},{"price":"0.000019652","size":"0"},{"price":"0.000019679","size":"51682.70"},{"price":"0.000019751","size":"0"},{"price":"0.000019764","size":"0"},{"price":"0.000019778","size":"0"},{"price":"0.000019896","size":"64509.44"},{"price":"0.000019999","size":"0"},{"price":"0.000021176","size":"79709.75"},{"price":"0.000021186","size":"66111.26"}],"bid":[],"sequence":11277021,"timestamp":"2021-07-15T03:07:10.421Z","symbol":"GRTBTC"}}
1626318430.596709: {"jsonrpc":"2.0","method":"updateOrderbook","params":{"ask":[{"price":"0.000019503","size":"0"},{"price":"0.000019509","size":"2013.30"},{"price":"0.000019553","size":"0"},{"price":"0.000019567","size":"5580.35"},{"price":"0.000019731","size":"0"},{"price":"0.000019766","size":"0"},{"price":"0.000019781","size":"0"},{"price":"0.000019786","size":"0"},{"price":"0.000019801","size":"0"},{"price":"0.000021679","size":"26391.19"},{"price":"0.000027941","size":"22732.57"},{"price":"0.000033511","size":"0"},{"price":"0.000039483","size":"31811.19"},{"price":"0.000040066","size":"49194.04"},{"price":"0.000042945","size":"0"},{"price":"0.000043367","size":"0"},{"price":"0.000057521","size":"37723.11"}],"bid":[{"price":"0.000019425","size":"0"},{"price":"0.000019421","size":"538.41"},{"price":"0.000019408","size":"0"},{"price":"0.000019387","size":"2123.51"},{"price":"0.000019355","size":"0"},{"price":"0.000019342","size":"5196.30"}],"sequence":11277022,"timestamp":"2021-07-15T03:07:10.550Z","symbol":"GRTBTC"}}
1626318430.6913931: {"jsonrpc":"2.0","method":"updateOrderbook","params":{"ask":[{"price":"0.00016314","size":"2890.66"},{"price":"0.00016347","size":"0"}],"bid":[],"sequence":3153561,"timestamp":"2021-07-15T03:07:10.664Z","symbol":"ORNBTC"}}
1626318430.696644: {"jsonrpc":"2.0","method":"updateOrderbook","params":{"ask":[{"price":"0.000019589","size":"17918.70"},{"price":"0.000019606","size":"0"}],"bid":[],"sequence":11277023,"timestamp":"2021-07-15T03:07:10.655Z","symbol":"GRTBTC"}}
1626318430.6966999: {"jsonrpc":"2.0","method":"updateOrderbook","params":{"ask":[{"price":"0.0000023862","size":"0"},{"price":"0.0000024160","size":"434810"},{"price":"0.0000037445","size":"0"},{"price":"0.0000038064","size":"598830"},{"price":"0.0000056222","size":"0"},{"price":"0.0000056697","size":"751190"},{"price":"0.0000090384","size":"0"},{"price":"0.0000090741","size":"1665120"}],"bid":[],"sequence":20309765,"timestamp":"2021-07-15T03:07:10.609Z","symbol":"VETBTC"}}
1626318430.696919: {"jsonrpc":"2.0","method":"updateOrderbook","params":{"ask":[{"price":"0.000086652","size":"1.63"}],"bid":[{"price":"0.000008665","size":"1.56"}],"sequence":3128158,"timestamp":"2021-07-15T03:07:10.661Z","symbol":"INSURBTC"}}
1626318430.792444: {"jsonrpc":"2.0","method":"updateOrderbook","params":{"ask":[],"bid":[{"price":"1.18768","size":"0"},{"price":"1.18767","size":"11596.00"},{"price":"1.18718","size":"0"},{"price":"1.18717","size":"23192.00"},{"price":"1.18648","size":"0"},{"price":"1.18647","size":"34788.00"}],"sequence":7333554,"timestamp":"2021-07-15T03:07:10.758Z","symbol":"EURSUSD"}}
1626318430.7970078: {"jsonrpc":"2.0","method":"updateOrderbook","params":{"ask":[{"price":"0.000019655","size":"51682.70"},{"price":"0.000019679","size":"0"},{"price":"0.000019999","size":"84536.43"}],"bid":[],"sequence":11277024,"timestamp":"2021-07-15T03:07:10.772Z","symbol":"GRTBTC"}}
1626318430.7996109: {"jsonrpc":"2.0","method":"updateOrderbook","params":{"ask":[{"price":"0.0000023283","size":"570330"},{"price":"0.0000023445","size":"0"},{"price":"0.0000032582","size":"806300"},{"price":"0.0000032723","size":"0"}],"bid":[],"sequence":20309766,"timestamp":"2021-07-15T03:07:10.714Z","symbol":"VETBTC"}}
1626318431.094935: {"jsonrpc":"2.0","method":"updateOrderbook","params":{"ask":[{"price":"0.00000267","size":"5472.9"},{"price":"0.00000268","size":"0.1"}],"bid":[],"sequence":1158487,"timestamp":"2021-07-15T03:07:11.037Z","symbol":"CRDTETH"}}
1626318431.094965: {"jsonrpc":"2.0","method":"updateOrderbook","params":{"ask":[{"price":"0.000033511","size":"69065.50"},{"price":"0.000043367","size":"83849.98"}],"bid":[],"sequence":11277025,"timestamp":"2021-07-15T03:07:11.043Z","symbol":"GRTBTC"}}
1626318431.097528: {"jsonrpc":"2.0","method":"updateOrderbook","params":{"ask":[],"bid":[{"price":"0.0000020585","size":"616380"},{"price":"0.0000020547","size":"0"},{"price":"0.0000007063","size":"842410"},{"price":"0.0000007001","size":"0"}],"sequence":20309767,"timestamp":"2021-07-15T03:07:11.018Z","symbol":"VETBTC"}}
1626318431.193471: {"jsonrpc":"2.0","method":"updateOrderbook","params":{"ask":[{"price":"0.00016958","size":"4424.71"},{"price":"0.00016997","size":"0"},{"price":"0.00019747","size":"1.00"},{"price":"0.00020533","size":"0"}],"bid":[{"price":"0.00011447","size":"2.00"},{"price":"0.00010661","size":"0"}],"sequence":3153562,"timestamp":"2021-07-15T03:07:11.160Z","symbol":"ORNBTC"}}
1626318431.205317: {"jsonrpc":"2.0","method":"updateOrderbook","params":{"ask":[{"price":"0.000025484","size":"10.00"},{"price":"0.000026499","size":"0"}],"bid":[],"sequence":11277026,"timestamp":"2021-07-15T03:07:11.112Z","symbol":"GRTBTC"}}
1626318431.205374: {"jsonrpc":"2.0","method":"updateOrderbook","params":{"ask":[{"price":"0.0000039002","size":"1173990"},{"price":"0.0000039109","size":"0"},{"price":"0.0000060344","size":"1656660"},{"price":"0.0000060801","size":"0"}],"bid":[],"sequence":20309768,"timestamp":"2021-07-15T03:07:11.148Z","symbol":"VETBTC"}}
1626318431.394777: {"jsonrpc":"2.0","method":"updateOrderbook","params":{"ask":[{"price":"0.000019913","size":"84536.43"},{"price":"0.000019999","size":"0"}],"bid":[],"sequence":11277027,"timestamp":"2021-07-15T03:07:11.316Z","symbol":"GRTBTC"}}
1626318431.593015: {"jsonrpc":"2.0","method":"updateOrderbook","params":{"ask":[{"price":"0.000033511","size":"0"},{"price":"0.000043367","size":"0"},{"price":"0.000068487","size":"69065.50"}],"bid":[],"sequence":11277028,"timestamp":"2021-07-15T03:07:11.574Z","symbol":"GRTBTC"}}
1626318431.692171: {"jsonrpc":"2.0","method":"updateOrderbook","params":{"ask":[{"price":"1.21885","size":"8320.00"},{"price":"1.21891","size":"0"},{"price":"1.21935","size":"15840.00"},{"price":"1.21941","size":"0"},{"price":"1.22005","size":"35680.00"},{"price":"1.22011","size":"0"}],"bid":[{"price":"1.18767","size":"0"},{"price":"1.18764","size":"11596.00"},{"price":"1.18717","size":"0"},{"price":"1.18714","size":"23192.00"},{"price":"1.18647","size":"0"},{"price":"1.18644","size":"34788.00"}],"sequence":7333555,"timestamp":"2021-07-15T03:07:11.616Z","symbol":"EURSUSD"}}
1626318431.703116: {"jsonrpc":"2.0","method":"updateOrderbook","params":{"ask":[{"price":"0.000019655","size":"0"},{"price":"0.000019679","size":"51682.70"},{"price":"0.000019913","size":"0"}],"bid":[],"sequence":11277029,"timestamp":"2021-07-15T03:07:11.602Z","symbol":"GRTBTC"}}
1626318431.703169: {"jsonrpc":"2.0","method":"updateOrderbook","params":{"ask":[],"bid":[{"price":"0.0000021995","size":"0"},{"price":"0.0000021993","size":"1650"},{"price":"0.0000021992","size":"6400"},{"price":"0.0000021987","size":"0"}],"sequence":20309769,"timestamp":"2021-07-15T03:07:11.661Z","symbol":"VETBTC"}}
1626318431.703209: {"jsonrpc":"2.0","method":"updateOrderbook","params":{"ask":[{"price":"0.000086652","size":"1.09"}],"bid":[{"price":"0.000008665","size":"1.39"}],"sequence":3128159,"timestamp":"2021-07-15T03:07:11.662Z","symbol":"INSURBTC"}}
1626318431.8041432: {"jsonrpc":"2.0","method":"updateOrderbook","params":{"ask":[{"price":"0.0000022032","size":"11840"},{"price":"0.0000022033","size":"5350"},{"price":"0.0000022034","size":"0"}],"bid":[{"price":"0.0000021994","size":"1650"},{"price":"0.0000021993","size":"6400"},{"price":"0.0000021992","size":"0"}],"sequence":20309770,"timestamp":"2021-07-15T03:07:11.731Z","symbol":"VETBTC"}}
1626318431.897433: {"jsonrpc":"2.0","method":"updateOrderbook","params":{"ask":[],"bid":[{"price":"0.000015556","size":"126158.52"},{"price":"0.000015519","size":"0"},{"price":"0.000015487","size":"135006.27"},{"price":"0.000015451","size":"0"},{"price":"0.000015423","size":"142494.04"},{"price":"0.000015374","size":"0"},{"price":"0.000015359","size":"147559.40"},{"price":"0.000015291","size":"123942.08"},{"price":"0.000015274","size":"0"},{"price":"0.000015217","size":"135000.54"},{"price":"0.000015193","size":"0"},{"price":"0.000015105","size":"0"}],"sequence":11277030,"timestamp":"2021-07-15T03:07:11.819Z","symbol":"GRTBTC"}}
1626318432.095007: {"jsonrpc":"2.0","method":"updateOrderbook","params":{"ask":[{"price":"0.0000022054","size":"16420"},{"price":"0.0000022060","size":"0"}],"bid":[],"sequence":20309771,"timestamp":"2021-07-15T03:07:12.018Z","symbol":"VETBTC"}}
1626318432.397982: {"jsonrpc":"2.0","method":"updateOrderbook","params":{"ask":[{"price":"0.000019679","size":"0"},{"price":"0.000019735","size":"51682.70"},{"price":"0.000021186","size":"0"},{"price":"0.000021343","size":"66111.26"},{"price":"0.000021679","size":"0"},{"price":"0.000021734","size":"26391.19"},{"price":"0.000042945","size":"43968.68"},{"price":"0.000068487","size":"0"}],"bid":[],"sequence":11277031,"timestamp":"2021-07-15T03:07:12.358Z","symbol":"GRTBTC"}}
1626318432.501552: {"jsonrpc":"2.0","method":"updateOrderbook","params":{"ask":[{"price":"0.000019471","size":"0"},{"price":"0.000019482","size":"470.51"},{"price":"0.000019483","size":"0"},{"price":"0.000019493","size":"527.13"},{"price":"0.000019776","size":"64509.44"},{"price":"0.000019798","size":"79709.75"},{"price":"0.000019896","size":"0"},{"price":"0.000021176","size":"0"},{"price":"0.000021734","size":"0"},{"price":"0.000021896","size":"26391.19"},{"price":"0.000039483","size":"0"},{"price":"0.000039582","size":"31811.19"}],"bid":[],"sequence":11277032,"timestamp":"2021-07-15T03:07:12.457Z","symbol":"GRTBTC"}}
1626318432.598628: {"jsonrpc":"2.0","method":"updateOrderbook","params":{"ask":[{"price":"0.000019480","size":"556.10"},{"price":"0.000019486","size":"526.56"},{"price":"0.000019507","size":"7551.36"},{"price":"0.000019515","size":"7623.89"},{"price":"0.000025484","size":"0"},{"price":"0.000025491","size":"10.00"}],"bid":[],"sequence":11277033,"timestamp":"2021-07-15T03:07:12.492Z","symbol":"GRTBTC"}}
1626318432.598648: {"jsonrpc":"2.0","method":"updateOrderbook","params":{"ask":[],"bid":[{"price":"0.0000021895","size":"0"},{"price":"0.0000021871","size":"146970"},{"price":"0.0000021862","size":"818910"},{"price":"0.0000021837","size":"1700840"},{"price":"0.0000021804","size":"0"},{"price":"0.0000021761","size":"378330"},{"price":"0.0000020585","size":"0"},{"price":"0.0000018373","size":"616380"},{"price":"0.0000007063","size":"0"},{"price":"0.0000003494","size":"842410"}],"sequence":20309772,"timestamp":"2021-07-15T03:07:12.501Z","symbol":"VETBTC"}}
1626318432.712898: {"jsonrpc":"2.0","method":"updateOrderbook","params":{"ask":[{"price":"0.000019470","size":"0"}],"bid":[],"sequence":11277034,"timestamp":"2021-07-15T03:07:12.652Z","symbol":"GRTBTC"}}
1626318432.71799: {"jsonrpc":"2.0","method":"updateOrderbook","params":{"ask":[{"price":"0.000086652","size":"1.01"}],"bid":[{"price":"0.000008665","size":"1.33"}],"sequence":3128160,"timestamp":"2021-07-15T03:07:12.672Z","symbol":"INSURBTC"}}
1626318432.796695: {"jsonrpc":"2.0","method":"updateOrderbook","params":{"ask":[],"bid":[{"price":"1.18764","size":"0"},{"price":"1.18763","size":"11596.00"},{"price":"1.18714","size":"0"},{"price":"1.18713","size":"23192.00"},{"price":"1.18644","size":"0"},{"price":"1.18643","size":"34788.00"}],"sequence":7333556,"timestamp":"2021-07-15T03:07:12.738Z","symbol":"EURSUSD"}}
1626318432.798393: {"jsonrpc":"2.0","method":"updateOrderbook","params":{"ask":[{"price":"0.000019490","size":"0.40"}],"bid":[],"sequence":11277035,"timestamp":"2021-07-15T03:07:12.695Z","symbol":"GRTBTC"}}
1626318432.901193: {"jsonrpc":"2.0","method":"updateOrderbook","params":{"ask":[{"price":"0.000021896","size":"0"},{"price":"0.000022460","size":"26391.19"},{"price":"0.000039582","size":"0"},{"price":"0.000039738","size":"31811.19"}],"bid":[],"sequence":11277036,"timestamp":"2021-07-15T03:07:12.784Z","symbol":"GRTBTC"}}
1626318433.094197: {"jsonrpc":"2.0","method":"updateOrderbook","params":{"ask":[{"price":"0.000022460","size":"0"},{"price":"0.000022634","size":"26391.19"},{"price":"0.000039738","size":"0"},{"price":"0.000039784","size":"31811.19"}],"bid":[],"sequence":11277037,"timestamp":"2021-07-15T03:07:13.053Z","symbol":"GRTBTC"}}
1626318433.095358: {"jsonrpc":"2.0","method":"updateOrderbook","params":{"ask":[],"bid":[{"price":"0.0000021994","size":"0"},{"price":"0.0000021993","size":"0"},{"price":"0.0000021987","size":"1650"},{"price":"0.0000021986","size":"4650"},{"price":"0.0000021978","size":"49230"},{"price":"0.0000021970","size":"11890"}],"sequence":20309773,"timestamp":"2021-07-15T03:07:12.997Z","symbol":"VETBTC"}}
1626318433.1984: {"jsonrpc":"2.0","method":"updateOrderbook","params":{"ask":[{"price":"0.000005672","size":"0"},{"price":"0.000005678","size":"7025.8"},{"price":"0.000005681","size":"0"},{"price":"0.000005688","size":"0"},{"price":"0.000005693","size":"3345.1"},{"price":"0.000005698","size":"18034.6"},{"price":"0.000005703","size":"0"},{"price":"0.000005704","size":"0"},{"price":"0.000005710","size":"27384.2"},{"price":"0.000005712","size":"10739.0"},{"price":"0.000005727","size":"0"},{"price":"0.000005742","size":"49214.5"},{"price":"0.000005750","size":"0"},{"price":"0.000005756","size":"19726.6"},{"price":"0.000005791","size":"0"},{"price":"0.000005809","size":"64524.9"},{"price":"0.000005906","size":"0"},{"price":"0.000005944","size":"92837.8"},{"price":"0.000006045","size":"0"},{"price":"0.000006073","size":"113703.3"},{"price":"0.000006214","size":"0"},{"price":"0.000006226","size":"160309.1"},{"price":"0.000006525","size":"0"},{"price":"0.000006547","size":"291646.2"}],"bid":[],"sequence":1875066,"timestamp":"2021-07-15T03:07:13.165Z","symbol":"POLYBTC"}}
1626318433.1984499: {"jsonrpc":"2.0","method":"updateOrderbook","params":{"ask":[{"price":"0.0000023857","size":"434810"},{"price":"0.0000024160","size":"0"},{"price":"0.0000102250","size":"0"},{"price":"0.0000102429","size":"1402840"}],"bid":[],"sequence":20309774,"timestamp":"2021-07-15T03:07:13.172Z","symbol":"VETBTC"}}
1626318433.29344: {"jsonrpc":"2.0","method":"updateOrderbook","params":{"ask":[{"price":"0.000005647","size":"106.7"},{"price":"0.000005657","size":"0"}],"bid":[],"sequence":1875067,"timestamp":"2021-07-15T03:07:13.271Z","symbol":"POLYBTC"}}
1626318433.494025: {"jsonrpc":"2.0","method":"updateOrderbook","params":{"ask":[{"price":"0.000019503","size":"2013.30"},{"price":"0.000019509","size":"0"}],"bid":[{"price":"0.000019402","size":"2123.51"},{"price":"0.000019387","size":"0"}],"sequence":11277038,"timestamp":"2021-07-15T03:07:13.431Z","symbol":"GRTBTC"}}
1626318433.6104581: {"jsonrpc":"2.0","method":"updateOrderbook","params":{"ask":[{"price":"0.0000037382","size":"598830"},{"price":"0.0000038064","size":"0"},{"price":"0.0000056160","size":"751190"},{"price":"0.0000056697","size":"0"}],"bid":[],"sequence":20309775,"timestamp":"2021-07-15T03:07:13.548Z","symbol":"VETBTC"}}
1626318433.7040808: {"jsonrpc":"2.0","method":"updateOrderbook","params":{"ask":[{"price":"0.0000022031","size":"11840"},{"price":"0.0000022032","size":"5350"},{"price":"0.0000022033","size":"0"}],"bid":[{"price":"0.0000021994","size":"1650"},{"price":"0.0000021993","size":"6400"},{"price":"0.0000021987","size":"0"},{"price":"0.0000021978","size":"42830"},{"price":"0.0000021925","size":"124370"},{"price":"0.0000021910","size":"0"}],"sequence":20309776,"timestamp":"2021-07-15T03:07:13.644Z","symbol":"VETBTC"}}
1626318433.704148: {"jsonrpc":"2.0","method":"updateOrderbook","params":{"ask":[{"price":"0.000086652","size":"1.27"}],"bid":[{"price":"0.000008665","size":"1.30"}],"sequence":3128161,"timestamp":"2021-07-15T03:07:13.674Z","symbol":"INSURBTC"}}
1626318433.804501: {"jsonrpc":"2.0","method":"updateOrderbook","params":{"ask":[{"price":"0.0000022031","size":"0"},{"price":"0.0000022043","size":"11840"}],"bid":[{"price":"0.0000021994","size":"0"},{"price":"0.0000021993","size":"0"},{"price":"0.0000021987","size":"1650"},{"price":"0.0000021979","size":"6400"}],"sequence":20309777,"timestamp":"2021-07-15T03:07:13.733Z","symbol":"VETBTC"}}
1626318433.906404: {"jsonrpc":"2.0","method":"updateOrderbook","params":{"ask":[{"price":"0.000019553","size":"5580.35"},{"price":"0.000019567","size":"0"}],"bid":[{"price":"0.000019359","size":"5196.30"},{"price":"0.000019342","size":"0"}],"sequence":11277039,"timestamp":"2021-07-15T03:07:13.869Z","symbol":"GRTBTC"}}
1626318433.906444: {"jsonrpc":"2.0","method":"updateOrderbook","params":{"ask":[{"price":"0.0000022054","size":"0"},{"price":"0.0000022060","size":"16420"},{"price":"0.0000023857","size":"0"},{"price":"0.0000024143","size":"434810"},{"price":"0.0000037382","size":"0"},{"price":"0.0000038035","size":"598830"},{"price":"0.0000056160","size":"0"},{"price":"0.0000056645","size":"751190"},{"price":"0.0000090687","size":"1665120"},{"price":"0.0000090741","size":"0"}],"bid":[{"price":"0.0000021915","size":"146970"},{"price":"0.0000021871","size":"0"}],"sequence":20309778,"timestamp":"2021-07-15T03:07:13.867Z","symbol":"VETBTC"}}
1626318434.011925: {"jsonrpc":"2.0","method":"updateOrderbook","params":{"ask":[{"price":"0.000019668","size":"51682.70"},{"price":"0.000019735","size":"0"}],"bid":[],"sequence":11277040,"timestamp":"2021-07-15T03:07:13.973Z","symbol":"GRTBTC"}}
1626318434.0119581: {"jsonrpc":"2.0","method":"updateOrderbook","params":{"ask":[{"price":"0.0000022060","size":"0"},{"price":"0.0000022067","size":"16420"},{"price":"0.0000022075","size":"0"},{"price":"0.0000022090","size":"47990"},{"price":"0.0000022110","size":"0"},{"price":"0.0000022123","size":"92250"},{"price":"0.0000024143","size":"0"},{"price":"0.0000024577","size":"434810"},{"price":"0.0000038035","size":"0"},{"price":"0.0000038586","size":"598830"},{"price":"0.0000056645","size":"0"},{"price":"0.0000057125","size":"751190"},{"price":"0.0000090687","size":"0"},{"price":"0.0000091035","size":"1665120"}],"bid":[{"price":"0.0000021977","size":"18400"},{"price":"0.0000021971","size":"43830"}],"sequence":20309779,"timestamp":"2021-07-15T03:07:13.940Z","symbol":"VETBTC"}}
1626318434.08911: {"jsonrpc":"2.0","method":"updateOrderbook","params":{"ask":[],"bid":[{"price":"0.0000025562","size":"0"},{"price":"0.0000025418","size":"8842"}],"sequence":2357244,"timestamp":"2021-07-15T03:07:14.059Z","symbol":"DNTBTC"}}
1626318434.093931: {"jsonrpc":"2.0","method":"updateOrderbook","params":{"ask":[{"price":"1.26132","size":"14865.71"},{"price":"1.33000","size":"150005.07"}],"bid":[{"price":"1.18763","size":"0"},{"price":"1.18762","size":"11596.00"},{"price":"1.18713","size":"0"},{"price":"1.18712","size":"23192.00"},{"price":"1.18643","size":"0"},{"price":"1.18642","size":"34788.00"},{"price":"1.13830","size":"16460.07"},{"price":"1.11703","size":"16496.07"},{"price":"1.10962","size":"0"},{"price":"0.98059","size":"0"}],"sequence":7333557,"timestamp":"2021-07-15T03:07:14.074Z","symbol":"EURSUSD"}}
1626318434.105875: {"jsonrpc":"2.0","method":"updateOrderbook","params":{"ask":[{"price":"0.000005647","size":"0"}],"bid":[{"price":"0.000005602","size":"0"},{"price":"0.000005592","size":"36.4"},{"price":"0.000004974","size":"0"},{"price":"0.000004970","size":"3374.7"}],"sequence":1875068,"timestamp":"2021-07-15T03:07:14.067Z","symbol":"POLYBTC"}}
1626318434.207593: {"jsonrpc":"2.0","method":"updateOrderbook","params":{"ask":[{"price":"0.000005637","size":"106.7"}],"bid":[],"sequence":1875069,"timestamp":"2021-07-15T03:07:14.081Z","symbol":"POLYBTC"}}
1626318434.207718: {"jsonrpc":"2.0","method":"updateOrderbook","params":{"ask":[{"price":"0.0000024577","size":"0"},{"price":"0.0000024602","size":"434810"},{"price":"0.0000057125","size":"0"},{"price":"0.0000057300","size":"751190"},{"price":"0.0000091035","size":"0"},{"price":"0.0000091489","size":"1665120"}],"bid":[{"price":"0.0000021862","size":"1096310"},{"price":"0.0000021837","size":"1423440"},{"price":"0.0000021809","size":"378330"},{"price":"0.0000021761","size":"0"}],"sequence":20309780,"timestamp":"2021-07-15T03:07:14.133Z","symbol":"VETBTC"}}
1626318434.299954: {"jsonrpc":"2.0","method":"updateOrderbook","params":{"ask":[{"price":"0.000021137","size":"66111.26"},{"price":"0.000021343","size":"0"}],"bid":[],"sequence":11277041,"timestamp":"2021-07-15T03:07:14.278Z","symbol":"GRTBTC"}}
1626318434.300571: {"jsonrpc":"2.0","method":"updateOrderbook","params":{"ask":[{"price":"0.0000022024","size":"0"},{"price":"0.0000022025","size":"0"},{"price":"0.0000022028","size":"10320"},{"price":"0.0000022029","size":"4140"}],"bid":[{"price":"0.0000021979","size":"0"},{"price":"0.0000021970","size":"6400"},{"price":"0.0000021961","size":"165100"}],"sequence":20309781,"timestamp":"2021-07-15T03:07:14.225Z","symbol":"VETBTC"}}
1626318434.416058: {"jsonrpc":"2.0","method":"updateOrderbook","params":{"ask":[{"price":"0.0000022028","size":"0"},{"price":"0.0000022029","size":"0"},{"price":"0.0000022031","size":"10320"},{"price":"0.0000022033","size":"4140"}],"bid":[{"price":"0.0000021999","size":"1650"},{"price":"0.0000021987","size":"0"}],"sequence":20309782,"timestamp":"2021-07-15T03:07:14.343Z","symbol":"VETBTC"}}
1626318434.496279: {"jsonrpc":"2.0","method":"updateOrderbook","params":{"ask":[],"bid":[{"price":"0.0000022001","size":"10360"},{"price":"0.0000021999","size":"0"},{"price":"0.0000021998","size":"1650"},{"price":"0.0000021973","size":"69150"},{"price":"0.0000021970","size":"0"},{"price":"0.0000020781","size":"616380"},{"price":"0.0000018373","size":"0"},{"price":"0.0000007378","size":"842410"},{"price":"0.0000003494","size":"0"}],"sequence":20309783,"timestamp":"2021-07-15T03:07:14.474Z","symbol":"VETBTC"}}
1626318434.597555: {"jsonrpc":"2.0","method":"updateOrderbook","params":{"ask":[{"price":"0.0000038586","size":"0"},{"price":"0.0000038618","size":"598830"}],"bid":[{"price":"0.0000022001","size":"0"},{"price":"0.0000022000","size":"1650"},{"price":"0.0000021999","size":"10360"},{"price":"0.0000021998","size":"0"}],"sequence":20309784,"timestamp":"2021-07-15T03:07:14.569Z","symbol":"VETBTC"}}
1626318434.693931: {"jsonrpc":"2.0","method":"updateOrderbook","params":{"ask":[],"bid":[{"price":"1.18762","size":"0"},{"price":"1.18761","size":"11596.00"},{"price":"1.18712","size":"0"},{"price":"1.18711","size":"23192.00"},{"price":"1.18642","size":"0"},{"price":"1.18641","size":"34788.00"}],"sequence":7333558,"timestamp":"2021-07-15T03:07:14.664Z","symbol":"EURSUSD"}}
1626318434.6966138: {"jsonrpc":"2.0","method":"updateOrderbook","params":{"ask":[],"bid":[{"price":"0.000004516","size":"0"},{"price":"0.000004496","size":"83653.6"},{"price":"0.000004485","size":"0"},{"price":"0.000004091","size":"5823.4"},{"price":"0.000003413","size":"0"},{"price":"0.000003395","size":"88185.5"}],"sequence":1875070,"timestamp":"2021-07-15T03:07:14.669Z","symbol":"POLYBTC"}}
1626318434.69778: {"jsonrpc":"2.0","method":"updateOrderbook","params":{"ask":[{"price":"0.000086652","size":"1.42"}],"bid":[{"price":"0.000008665","size":"1.78"}],"sequence":3128162,"timestamp":"2021-07-15T03:07:14.676Z","symbol":"INSURBTC"}}
1626318434.8007941: {"jsonrpc":"2.0","method":"updateOrderbook","params":{"ask":[{"price":"0.0000022031","size":"0"},{"price":"0.0000022032","size":"10320"},{"price":"0.0000022034","size":"5360"},{"price":"0.0000022044","size":"12940"},{"price":"0.0000022080","size":"22350"},{"price":"0.0000022096","size":"0"},{"price":"0.0000022097","size":"26280"}],"bid":[{"price":"0.0000022001","size":"10360"},{"price":"0.0000022000","size":"0"},{"price":"0.0000021999","size":"0"},{"price":"0.0000021998","size":"1650"},{"price":"0.0000021932","size":"0"},{"price":"0.0000021926","size":"22090"},{"price":"0.0000021916","size":"0"},{"price":"0.0000021908","size":"26010"}],"sequence":20309785,"timestamp":"2021-07-15T03:07:14.773Z","symbol":"VETBTC"}}
