1649023825.2023199: {"Channel":"orderbook-eth","Nonce":19522,"Data":{"OrderType":"LimitBid","OrderGuid":"cc031809-ff0a-405f-be0b-70367289a60c","Price":{"aud":4727.3,"usd":3523.72,"nzd":5087.52,"sgd":4791.11},"Volume":15.0},"Time":1649023825093,"Event":"NewOrder"}
1649023825.205575: {"Channel":"orderbook-eth","Nonce":19523,"Data":{"OrderType":"LimitOffer","OrderGuid":"7606aa1d-b59d-4709-ba38-0e4ca4187834"},"Time":1649023825093,"Event":"OrderCanceled"}
1649023825.205649: {"Channel":"orderbook-dot","Nonce":5017,"Data":{"OrderType":"LimitBid","OrderGuid":"e1c3bafd-572c-442a-80ed-5206470c2928","Price":{"aud":30.3741,"usd":22.6408,"nzd":32.6886,"sgd":30.7841},"Volume":25.08734},"Time":1649023825093,"Event":"NewOrder"}
1649023825.205697: {"Channel":"orderbook-eth","Nonce":19524,"Data":{"OrderType":"LimitBid","OrderGuid":"284e93ad-b85b-46bc-bf3f-880b9c659771","Price":{"aud":4703.96,"usd":3506.33,"nzd":5062.4,"sgd":4767.46},"Volume":0.38867649},"Time":1649023825093,"Event":"NewOrder"}
1649023825.2059772: {"Channel":"orderbook-eth","Nonce":19525,"Data":{"OrderType":"LimitBid","OrderGuid":"3dfba298-709d-44a3-beb4-01c57f09a7ac","Price":{"aud":4724.3,"usd":3521.49,"nzd":5084.29,"sgd":4788.07},"Volume":15.0},"Time":1649023825109,"Event":"NewOrder"}
1649023825.224722: {"Channel":"orderbook-matic","Nonce":5926,"Data":{"OrderType":"LimitOffer","OrderGuid":"ed947b7c-c027-4f34-b3cf-d3969ab41ac2"},"Time":1649023825125,"Event":"OrderCanceled"}
1649023825.227293: {"Channel":"orderbook-matic","Nonce":5927,"Data":{"OrderType":"LimitBid","OrderGuid":"3df48d66-5603-46aa-8b6e-eed4db773efd"},"Time":1649023825125,"Event":"OrderCanceled"}
1649023825.237259: {"Channel":"orderbook-eth","Nonce":19526,"Data":{"OrderType":"LimitOffer","OrderGuid":"447c5c11-bb7f-40e4-8427-6ee26a214dd0"},"Time":1649023825125,"Event":"OrderCanceled"}
1649023825.2373672: {"Channel":"orderbook-bch","Nonce":8348,"Data":{"OrderType":"LimitOffer","OrderGuid":"de7f00db-a5e4-43c0-a8a9-b887e8938ccf"},"Time":1649023825125,"Event":"OrderCanceled"}
1649023825.237427: {"Channel":"orderbook-eth","Nonce":19527,"Data":{"OrderType":"LimitOffer","OrderGuid":"ea0d8e8d-cae7-41b6-ada2-311916a71b5b","Price":{"aud":4737.5,"usd":3566.86,"nzd":5160.68,"sgd":4831.23},"Volume":15.0},"Time":1649023825125,"Event":"NewOrder"}
1649023825.237492: {"Channel":"orderbook-matic","Nonce":5928,"Data":{"OrderType":"LimitOffer","OrderGuid":"5e76b655-06e4-4acb-ba0d-2143cbed84bb"},"Time":1649023825125,"Event":"OrderCanceled"}
1649023825.2443688: {"Channel":"orderbook-matic","Nonce":5929,"Data":{"OrderType":"LimitOffer","OrderGuid":"16f1eb92-1b88-48cf-b1a4-b03f8503c668"},"Time":1649023825140,"Event":"OrderCanceled"}
1649023825.2884312: {"Channel":"orderbook-eth","Nonce":19528,"Data":{"OrderType":"LimitOffer","OrderGuid":"2c3107d5-4f9e-43fb-aaf6-68de5511031f","Price":{"aud":4794.92,"usd":3574.13,"nzd":5197.98,"sgd":4864.75},"Volume":0.56112841},"Time":1649023825187,"Event":"NewOrder"}
1649023825.299082: {"Channel":"orderbook-matic","Nonce":5930,"Data":{"OrderType":"LimitOffer","OrderGuid":"8c4ad6d7-8e3d-415b-9953-27a1deee0e00","Price":{"aud":2.27449,"usd":1.71247,"nzd":2.47766,"sgd":2.31949},"Volume":5303.63707},"Time":1649023825187,"Event":"NewOrder"}
1649023825.3254669: {"Channel":"orderbook-matic","Nonce":5931,"Data":{"OrderType":"LimitOffer","OrderGuid":"c9723b67-7f33-48c3-b447-69b6c7da4fb7","Price":{"aud":2.274,"usd":1.7121,"nzd":2.47713,"sgd":2.31899},"Volume":5583.0},"Time":1649023825218,"Event":"NewOrder"}
1649023825.3404229: {"Channel":"orderbook-eth","Nonce":19529,"Data":{"OrderType":"LimitOffer","OrderGuid":"a61fa3cc-f74d-4338-be1a-2e0e859e12ae","Price":{"aud":4734.5,"usd":3564.6,"nzd":5157.41,"sgd":4828.17},"Volume":15.0},"Time":1649023825234,"Event":"NewOrder"}
1649023825.363082: {"Channel":"orderbook-bch","Nonce":8349,"Data":{"OrderType":"LimitOffer","OrderGuid":"4b91dd63-310d-4934-aa24-089f33ca4e40"},"Time":1649023825265,"Event":"OrderCanceled"}
1649023825.3631868: {"Channel":"orderbook-eth","Nonce":19530,"Data":{"OrderType":"LimitOffer","OrderGuid":"ea0d8e8d-cae7-41b6-ada2-311916a71b5b"},"Time":1649023825265,"Event":"OrderCanceled"}
1649023825.363243: {"Channel":"orderbook-matic","Nonce":5932,"Data":{"OrderType":"LimitOffer","OrderGuid":"8c4ad6d7-8e3d-415b-9953-27a1deee0e00"},"Time":1649023825265,"Event":"OrderCanceled"}
1649023825.365155: {"Channel":"orderbook-eth","Nonce":19531,"Data":{"OrderType":"LimitBid","OrderGuid":"cc031809-ff0a-405f-be0b-70367289a60c"},"Time":1649023825265,"Event":"OrderCanceled"}
1649023825.3652601: {"Channel":"orderbook-bch","Nonce":8350,"Data":{"OrderType":"LimitOffer","OrderGuid":"a7a84d39-b976-49e2-8d02-d57755ec215d","Price":{"aud":510.72,"usd":384.53,"nzd":556.34,"sgd":520.83},"Volume":39.74331},"Time":1649023825265,"Event":"NewOrder"}
1649023825.407609: {"Channel":"orderbook-eth","Nonce":19532,"Data":{"OrderType":"LimitBid","OrderGuid":"ed2d96ee-aa4c-49c4-b1ea-fcef98ede073"},"Time":1649023825296,"Event":"OrderCanceled"}
1649023825.429512: {"Channel":"orderbook-matic","Nonce":5933,"Data":{"OrderType":"LimitBid","OrderGuid":"21db0ee9-7d36-4b52-a3cc-8821b75a3bd9"},"Time":1649023825328,"Event":"OrderCanceled"}
1649023825.433671: {"Channel":"orderbook-matic","Nonce":5934,"Data":{"OrderType":"LimitOffer","OrderGuid":"e9495589-326b-4f01-8b8e-7e62c23be044","Price":{"aud":2.27449,"usd":1.71247,"nzd":2.47766,"sgd":2.31949},"Volume":5381.42255},"Time":1649023825328,"Event":"NewOrder"}
1649023825.4343529: {"Channel":"orderbook-matic","Nonce":5935,"Data":{"OrderType":"LimitOffer","OrderGuid":"e6882c6b-82cd-4bc8-8be0-315777709fca","Price":{"aud":2.2725,"usd":1.71097,"nzd":2.4755,"sgd":2.31746},"Volume":5583.0},"Time":1649023825328,"Event":"NewOrder"}
1649023825.44457: {"Channel":"orderbook-eth","Nonce":19533,"Data":{"OrderType":"LimitBid","OrderGuid":"5864a977-2fcf-4b31-a9ca-b1b889869e1a","Price":{"aud":4678.13,"usd":3504.01,"nzd":5096.01,"sgd":4769.86},"Volume":0.57294409},"Time":1649023825343,"Event":"NewOrder"}
1649023825.452231: {"Channel":"orderbook-eth","Nonce":19534,"Data":{"OrderType":"LimitBid","OrderGuid":"eb756b58-bc15-4999-a9ed-3c12c38b752e","Price":{"aud":4724.63,"usd":3521.73,"nzd":5084.64,"sgd":4788.41},"Volume":14.14},"Time":1649023825343,"Event":"NewOrder"}
1649023825.4569302: {"Channel":"orderbook-eth","Nonce":19535,"Data":{"OrderType":"LimitBid","OrderGuid":"81a824f5-411d-4b55-a3d9-f5220c09040c"},"Time":1649023825359,"Event":"OrderCanceled"}
1649023825.476288: {"Channel":"orderbook-eth","Nonce":19536,"Data":{"OrderType":"LimitBid","OrderGuid":"3dfba298-709d-44a3-beb4-01c57f09a7ac"},"Time":1649023825375,"Event":"OrderCanceled"}
1649023825.476392: {"Channel":"orderbook-bch","Nonce":8351,"Data":{"OrderType":"LimitOffer","OrderGuid":"94a252d5-5675-4d19-a758-e6bf1cafa11e"},"Time":1649023825375,"Event":"OrderCanceled"}
1649023825.504328: {"Channel":"orderbook-eth","Nonce":19537,"Data":{"OrderType":"LimitBid","OrderGuid":"55ca5123-f1ee-463f-a381-2bb5d0805ba4","Price":{"aud":4724.92,"usd":3521.95,"nzd":5084.95,"sgd":4788.7},"Volume":14.14},"Time":1649023825406,"Event":"NewOrder"}
1649023825.508375: {"Channel":"orderbook-eth","Nonce":19538,"Data":{"OrderType":"LimitBid","OrderGuid":"eb756b58-bc15-4999-a9ed-3c12c38b752e"},"Time":1649023825406,"Event":"OrderCanceled"}
1649023825.508449: {"Channel":"orderbook-bch","Nonce":8352,"Data":{"OrderType":"LimitOffer","OrderGuid":"d96f892f-78c2-4a45-8f3f-a57faf6ae173","Price":{"aud":506.8,"usd":381.57,"nzd":552.07,"sgd":516.83},"Volume":6.0},"Time":1649023825406,"Event":"NewOrder"}
1649023825.508826: {"Channel":"orderbook-eth","Nonce":19539,"Data":{"OrderType":"LimitOffer","OrderGuid":"7c16c2e7-e0cb-49f3-bd74-0b589a02b9fd"},"Time":1649023825406,"Event":"OrderCanceled"}
1649023825.5127208: {"Channel":"orderbook-bch","Nonce":8353,"Data":{"OrderType":"LimitOffer","OrderGuid":"4e92afe0-d65e-441b-b7f2-b6c28daf2f78","Price":{"aud":507.5,"usd":382.1,"nzd":552.84,"sgd":517.55},"Volume":6.0},"Time":1649023825406,"Event":"NewOrder"}
1649023825.561704: {"Channel":"orderbook-eth","Nonce":19540,"Data":{"OrderType":"LimitOffer","OrderGuid":"5f705a13-41f8-4820-9b04-7bdba82eefb7"},"Time":1649023825453,"Event":"OrderCanceled"}
1649023825.59016: {"Channel":"orderbook-eth","Nonce":19541,"Data":{"OrderType":"LimitBid","OrderGuid":"c77afa92-c473-4886-9d15-b9fc33d24a9c","Price":{"aud":4727.6,"usd":3523.95,"nzd":5087.84,"sgd":4791.42},"Volume":15.0},"Time":1649023825484,"Event":"NewOrder"}
1649023825.590282: {"Channel":"orderbook-eth","Nonce":19542,"Data":{"OrderType":"LimitOffer","OrderGuid":"a61fa3cc-f74d-4338-be1a-2e0e859e12ae"},"Time":1649023825484,"Event":"OrderCanceled"}
1649023825.610017: {"Channel":"orderbook-matic","Nonce":5936,"Data":{"OrderType":"LimitBid","OrderGuid":"8b9082db-bf46-4a68-92eb-c462bbcc08e3","Price":{"aud":2.2605,"usd":1.68497,"nzd":2.43275,"sgd":2.29101},"Volume":5583.0},"Time":1649023825500,"Event":"NewOrder"}
1649023825.616626: {"Channel":"orderbook-matic","Nonce":5937,"Data":{"OrderType":"LimitOffer","OrderGuid":"c9723b67-7f33-48c3-b447-69b6c7da4fb7"},"Time":1649023825515,"Event":"OrderCanceled"}
1649023825.62847: {"Channel":"orderbook-eth","Nonce":19543,"Data":{"OrderType":"LimitOffer","OrderGuid":"2fcadcdf-4831-4a81-8aa1-76c89b0871f6","Price":{"aud":4737.68,"usd":3567.0,"nzd":5160.88,"sgd":4831.41},"Volume":4.47331033},"Time":1649023825531,"Event":"NewOrder"}
1649023825.679855: {"Channel":"orderbook-matic","Nonce":5938,"Data":{"OrderType":"LimitOffer","OrderGuid":"e6882c6b-82cd-4bc8-8be0-315777709fca"},"Time":1649023825578,"Event":"OrderCanceled"}
1649023825.67996: {"Channel":"orderbook-bch","Nonce":8354,"Data":{"OrderType":"LimitOffer","OrderGuid":"86f1e87a-7960-416c-926e-86a1d7a43fb2"},"Time":1649023825578,"Event":"OrderCanceled"}
1649023825.680015: {"Channel":"orderbook-eth","Nonce":19544,"Data":{"OrderType":"LimitOffer","OrderGuid":"1b2c2890-70cb-41ba-b1e9-2d13c9437b15","Price":{"aud":4742.03,"usd":3570.27,"nzd":5165.62,"sgd":4835.85},"Volume":1.01},"Time":1649023825578,"Event":"NewOrder"}
1649023825.680484: {"Channel":"orderbook-matic","Nonce":5939,"Data":{"OrderType":"LimitBid","OrderGuid":"3f8fd9e6-b149-410e-ba00-376aad95ebfe","Price":{"aud":2.262,"usd":1.68609,"nzd":2.43436,"sgd":2.29253},"Volume":5583.0},"Time":1649023825578,"Event":"NewOrder"}
1649023825.6926231: {"Channel":"orderbook-eth","Nonce":19545,"Data":{"OrderType":"LimitBid","OrderGuid":"c77afa92-c473-4886-9d15-b9fc33d24a9c"},"Time":1649023825593,"Event":"OrderCanceled"}
1649023825.692727: {"Channel":"orderbook-eth","Nonce":19546,"Data":{"OrderType":"LimitOffer","OrderGuid":"181961e8-1076-4289-9b4b-c15d7893fbff","Price":{"aud":4734.6,"usd":3564.68,"nzd":5157.52,"sgd":4828.27},"Volume":15.0},"Time":1649023825593,"Event":"NewOrder"}
1649023825.7257988: {"Channel":"orderbook-matic","Nonce":5940,"Data":{"OrderType":"LimitOffer","OrderGuid":"933249cb-fa57-487f-ba22-7dc62c19ecf0","Price":{"aud":2.273,"usd":1.71134,"nzd":2.47604,"sgd":2.31797},"Volume":5583.0},"Time":1649023825625,"Event":"NewOrder"}
1649023825.740635: {"Channel":"orderbook-matic","Nonce":5941,"Data":{"OrderType":"LimitOffer","OrderGuid":"b53c48bb-e083-4e55-a25c-5f1bfd7bdf9a","Price":{"aud":2.2745,"usd":1.71247,"nzd":2.47767,"sgd":2.3195},"Volume":5583.0},"Time":1649023825640,"Event":"NewOrder"}
1649023825.751225: {"Channel":"orderbook-dot","Nonce":5018,"Data":{"OrderType":"LimitBid","OrderGuid":"5269558c-abf4-4539-a64e-7d6fe86a3ab4"},"Time":1649023825640,"Event":"OrderCanceled"}
1649023825.7910762: {"Channel":"orderbook-eth","Nonce":19547,"Data":{"OrderType":"LimitBid","OrderGuid":"26d90137-ac3f-439a-a945-e970f85096d4","Price":{"aud":4724.4,"usd":3521.56,"nzd":5084.39,"sgd":4788.17},"Volume":15.0},"Time":1649023825687,"Event":"NewOrder"}
1649023825.795771: {"Channel":"orderbook-eth","Nonce":19548,"Data":{"OrderType":"LimitBid","OrderGuid":"e0da7b3d-e6f0-4a2e-bbed-9317fbe80903","Price":{"aud":4727.4,"usd":3523.8,"nzd":5087.62,"sgd":4791.21},"Volume":15.0},"Time":1649023825687,"Event":"NewOrder"}
1649023825.7962902: {"Channel":"orderbook-eth","Nonce":19549,"Data":{"OrderType":"LimitOffer","OrderGuid":"c516d9ee-d9ed-4756-823e-c7c40c50cf48","Price":{"aud":4737.6,"usd":3566.94,"nzd":5160.79,"sgd":4831.33},"Volume":15.0},"Time":1649023825687,"Event":"NewOrder"}
1649023825.833448: {"Channel":"orderbook-eth","Nonce":19550,"Data":{"OrderType":"LimitOffer","OrderGuid":"83e8081f-f82f-43f7-ba1f-d1f88eb235e3"},"Time":1649023825734,"Event":"OrderCanceled"}
1649023825.89661: {"Channel":"orderbook-eth","Nonce":19551,"Data":{"OrderType":"LimitBid","OrderGuid":"e0da7b3d-e6f0-4a2e-bbed-9317fbe80903"},"Time":1649023825797,"Event":"OrderCanceled"}
1649023825.914848: {"Channel":"orderbook-eth","Nonce":19552,"Data":{"OrderType":"LimitBid","OrderGuid":"26d90137-ac3f-439a-a945-e970f85096d4"},"Time":1649023825812,"Event":"OrderCanceled"}
1649023825.914952: {"Channel":"orderbook-eth","Nonce":19553,"Data":{"OrderType":"LimitOffer","OrderGuid":"181961e8-1076-4289-9b4b-c15d7893fbff"},"Time":1649023825812,"Event":"OrderCanceled"}
1649023825.9290519: {"Channel":"orderbook-eth","Nonce":19554,"Data":{"OrderType":"LimitOffer","OrderGuid":"c516d9ee-d9ed-4756-823e-c7c40c50cf48"},"Time":1649023825828,"Event":"OrderCanceled"}
1649023825.952182: {"Channel":"orderbook-eth","Nonce":19555,"Data":{"OrderType":"LimitBid","OrderGuid":"1994abdd-c6bc-4d59-be1d-5b60bf52613b","Price":{"aud":4724.6,"usd":3521.71,"nzd":5084.61,"sgd":4788.38},"Volume":15.0},"Time":1649023825843,"Event":"NewOrder"}
1649023825.956347: {"Channel":"orderbook-eth","Nonce":19556,"Data":{"OrderType":"LimitBid","OrderGuid":"93715c5e-66b4-4237-801b-08c39dcdbd10","Price":{"aud":4727.6,"usd":3523.95,"nzd":5087.84,"sgd":4791.42},"Volume":15.0},"Time":1649023825843,"Event":"NewOrder"}
1649023825.959596: {"Channel":"orderbook-eth","Nonce":19557,"Data":{"OrderType":"LimitOffer","OrderGuid":"2589c3cc-fa38-4b76-8568-d28eed54d2ed","Price":{"aud":4734.8,"usd":3564.83,"nzd":5157.74,"sgd":4828.48},"Volume":15.0},"Time":1649023825859,"Event":"NewOrder"}
1649023825.965732: {"Channel":"orderbook-eth","Nonce":19558,"Data":{"OrderType":"LimitOffer","OrderGuid":"a942bc21-931a-45d3-b61c-efc7a1c8b129","Price":{"aud":4737.8,"usd":3567.09,"nzd":5161.01,"sgd":4831.54},"Volume":15.0},"Time":1649023825859,"Event":"NewOrder"}
1649023825.968958: {"Channel":"orderbook-eth","Nonce":19559,"Data":{"OrderType":"LimitOffer","OrderGuid":"488ea36f-4216-4826-ba1a-2aa0ede418d7","Price":{"aud":4742.02,"usd":3570.27,"nzd":5165.6,"sgd":4835.84},"Volume":4.47331033},"Time":1649023825859,"Event":"NewOrder"}
1649023825.9741929: {"Channel":"orderbook-eth","Nonce":19560,"Data":{"OrderType":"LimitOffer","OrderGuid":"2fcadcdf-4831-4a81-8aa1-76c89b0871f6"},"Time":1649023825875,"Event":"OrderCanceled"}
1649023825.978681: {"Channel":"orderbook-bch","Nonce":8355,"Data":{"OrderType":"LimitOffer","OrderGuid":"cd3c6129-5cb6-4b8d-8e51-dc1ddd88f135","Price":{"aud":507.7,"usd":382.25,"nzd":553.06,"sgd":517.75},"Volume":1.0929415},"Time":1649023825875,"Event":"NewOrder"}
1649023826.0728698: {"Channel":"orderbook-bch","Nonce":8356,"Data":{"OrderType":"LimitOffer","OrderGuid":"701a10e1-c088-4ef1-96a7-0f52b47eac92"},"Time":1649023825969,"Event":"OrderCanceled"}
1649023826.106323: {"Channel":"orderbook-dot","Nonce":5019,"Data":{"OrderType":"LimitBid","OrderGuid":"8d03283f-aa79-4d97-8faf-4042c1f5ab3a"},"Time":1649023826000,"Event":"OrderCanceled"}
1649023826.131661: {"Channel":"orderbook-matic","Nonce":5942,"Data":{"OrderType":"LimitOffer","OrderGuid":"b53288d5-5e95-4245-8bfb-6d19edafea4b","Price":{"aud":2.3141,"usd":1.74229,"nzd":2.52081,"sgd":2.35989},"Volume":6000.0},"Time":1649023826032,"Event":"NewOrder"}
1649023826.1694431: {"Channel":"orderbook-eth","Nonce":19561,"Data":{"OrderType":"LimitBid","OrderGuid":"284e93ad-b85b-46bc-bf3f-880b9c659771"},"Time":1649023826063,"Event":"OrderCanceled"}
1649023826.1700292: {"Channel":"orderbook-eth","Nonce":19562,"Data":{"OrderType":"LimitOffer","OrderGuid":"a942bc21-931a-45d3-b61c-efc7a1c8b129"},"Time":1649023826063,"Event":"OrderCanceled"}
1649023826.178123: {"Channel":"orderbook-eth","Nonce":19563,"Data":{"OrderType":"LimitBid","OrderGuid":"93715c5e-66b4-4237-801b-08c39dcdbd10"},"Time":1649023826078,"Event":"OrderCanceled"}
1649023826.2016351: {"Channel":"orderbook-bch","Nonce":8357,"Data":{"OrderType":"LimitOffer","OrderGuid":"950adf20-1fd6-40f6-8a95-26735230ca28"},"Time":1649023826094,"Event":"OrderCanceled"}
1649023826.220525: {"Channel":"orderbook-bch","Nonce":8358,"Data":{"OrderType":"LimitOffer","OrderGuid":"af905f93-5807-4e74-a09b-4c3c8b0b7fb3","Price":{"aud":510.7,"usd":384.51,"nzd":556.32,"sgd":520.81},"Volume":2.93},"Time":1649023826110,"Event":"NewOrder"}
1649023826.221073: {"Channel":"orderbook-eth","Nonce":19564,"Data":{"OrderType":"LimitBid","OrderGuid":"77607e4d-e338-44d9-8743-1c3a35962a51","Price":{"aud":4703.97,"usd":3506.33,"nzd":5062.41,"sgd":4767.47},"Volume":0.34938378},"Time":1649023826125,"Event":"NewOrder"}
1649023826.232676: {"Channel":"orderbook-matic","Nonce":5943,"Data":{"OrderType":"LimitOffer","OrderGuid":"e9495589-326b-4f01-8b8e-7e62c23be044"},"Time":1649023826125,"Event":"OrderCanceled"}
1649023826.251819: {"Channel":"orderbook-dot","Nonce":5020,"Data":{"OrderType":"LimitBid","OrderGuid":"bad97b65-ae16-404c-b7a9-7f5953db1d02","Price":{"aud":30.803,"usd":22.9605,"nzd":33.1501,"sgd":31.2188},"Volume":69.2},"Time":1649023826141,"Event":"NewOrder"}
1649023826.2715259: {"Channel":"orderbook-eth","Nonce":19565,"Data":{"OrderType":"LimitOffer","OrderGuid":"2589c3cc-fa38-4b76-8568-d28eed54d2ed"},"Time":1649023826172,"Event":"OrderCanceled"}
1649023826.271599: {"Channel":"orderbook-eth","Nonce":19566,"Data":{"OrderType":"LimitBid","OrderGuid":"1994abdd-c6bc-4d59-be1d-5b60bf52613b"},"Time":1649023826172,"Event":"OrderCanceled"}
1649023826.271632: {"Channel":"orderbook-bch","Nonce":8359,"Data":{"OrderType":"LimitOffer","OrderGuid":"273efad7-2bdf-4749-b56b-ab8ca4032341","Price":{"aud":510.69,"usd":384.5,"nzd":556.31,"sgd":520.8},"Volume":21.20858658},"Time":1649023826172,"Event":"NewOrder"}
1649023826.2720692: {"Channel":"orderbook-bch","Nonce":8360,"Data":{"OrderType":"LimitOffer","OrderGuid":"618b9a18-6440-4280-8a9c-42731b3e657f"},"Time":1649023826172,"Event":"OrderCanceled"}
1649023826.287501: {"Channel":"orderbook-matic","Nonce":5944,"Data":{"OrderType":"LimitOffer","OrderGuid":"239f4026-f591-40a5-a436-5e3c16f23a80","Price":{"aud":2.27244,"usd":1.71092,"nzd":2.47543,"sgd":2.3174},"Volume":5613.51686},"Time":1649023826188,"Event":"NewOrder"}
1649023826.313051: {"Channel":"orderbook-eth","Nonce":19567,"Data":{"OrderType":"LimitBid","OrderGuid":"b3559332-3d3a-4076-a31b-05849c831287","Price":{"aud":4727.9,"usd":3524.17,"nzd":5088.16,"sgd":4791.72},"Volume":15.0},"Time":1649023826203,"Event":"NewOrder"}
1649023826.3131342: {"Channel":"orderbook-eth","Nonce":19568,"Data":{"OrderType":"LimitOffer","OrderGuid":"0e92baf0-8c7e-444a-9a93-dbb94c8b41e2","Price":{"aud":4735.1,"usd":3565.06,"nzd":5158.07,"sgd":4828.78},"Volume":15.0},"Time":1649023826203,"Event":"NewOrder"}
1649023826.339435: {"Channel":"orderbook-eth","Nonce":19569,"Data":{"OrderType":"LimitBid","OrderGuid":"3a235d28-96b2-474b-a933-10914c61d0b9","Price":{"aud":4696.28,"usd":3518.62,"nzd":5085.17,"sgd":4789.2},"Volume":22.338},"Time":1649023826235,"Event":"NewOrder"}
1649023826.34388: {"Channel":"orderbook-eth","Nonce":19570,"Data":{"OrderType":"LimitBid","OrderGuid":"64736f90-b4c2-40ff-a81b-d7c5b6164f85","Price":{"aud":4724.9,"usd":3521.94,"nzd":5084.93,"sgd":4788.68},"Volume":15.0},"Time":1649023826235,"Event":"NewOrder"}
1649023826.348068: {"Channel":"orderbook-matic","Nonce":5945,"Data":{"OrderType":"LimitOffer","OrderGuid":"239f4026-f591-40a5-a436-5e3c16f23a80"},"Time":1649023826250,"Event":"OrderCanceled"}
1649023826.4081862: {"Channel":"orderbook-bch","Nonce":8361,"Data":{"OrderType":"LimitOffer","OrderGuid":"a7a84d39-b976-49e2-8d02-d57755ec215d"},"Time":1649023826298,"Event":"OrderCanceled"}
1649023826.4203808: {"Channel":"orderbook-eth","Nonce":19571,"Data":{"OrderType":"LimitBid","OrderGuid":"b3559332-3d3a-4076-a31b-05849c831287"},"Time":1649023826314,"Event":"OrderCanceled"}
1649023826.432634: {"Channel":"orderbook-eth","Nonce":19572,"Data":{"OrderType":"LimitOffer","OrderGuid":"0e92baf0-8c7e-444a-9a93-dbb94c8b41e2"},"Time":1649023826329,"Event":"OrderCanceled"}
1649023826.4327402: {"Channel":"orderbook-eth","Nonce":19573,"Data":{"OrderType":"LimitBid","OrderGuid":"64736f90-b4c2-40ff-a81b-d7c5b6164f85"},"Time":1649023826329,"Event":"OrderCanceled"}
1649023826.43279: {"Channel":"orderbook-matic","Nonce":5946,"Data":{"OrderType":"LimitOffer","OrderGuid":"f0327dbe-641b-4235-a6d6-5779a2282754","Price":{"aud":2.27243,"usd":1.71091,"nzd":2.47542,"sgd":2.31739},"Volume":5058.86165},"Time":1649023826329,"Event":"NewOrder"}
1649023826.460952: {"Channel":"orderbook-eth","Nonce":19574,"Data":{"OrderType":"LimitOffer","OrderGuid":"a516ab21-eb74-4bde-94d1-92210fa2040d","Price":{"aud":4738.2,"usd":3567.39,"nzd":5161.44,"sgd":4831.94},"Volume":15.0},"Time":1649023826360,"Event":"NewOrder"}
1649023826.4768891: {"Channel":"orderbook-eth","Nonce":19575,"Data":{"OrderType":"LimitBid","OrderGuid":"5864a977-2fcf-4b31-a9ca-b1b889869e1a"},"Time":1649023826376,"Event":"OrderCanceled"}
1649023826.476993: {"Channel":"orderbook-eth","Nonce":19576,"Data":{"OrderType":"LimitOffer","OrderGuid":"8f9338aa-36bd-4947-b37a-5ef6c0e95469","Price":{"aud":4735.2,"usd":3565.13,"nzd":5158.17,"sgd":4828.89},"Volume":15.0},"Time":1649023826376,"Event":"NewOrder"}
1649023826.479357: {"Channel":"orderbook-eth","Nonce":19577,"Data":{"OrderType":"LimitBid","OrderGuid":"62e8dacb-e90d-41b3-8b6a-20e462168275","Price":{"aud":4728.0,"usd":3524.25,"nzd":5088.27,"sgd":4791.82},"Volume":15.0},"Time":1649023826376,"Event":"NewOrder"}
1649023826.481772: {"Channel":"orderbook-eth","Nonce":19578,"Data":{"OrderType":"LimitBid","OrderGuid":"8824d4f1-0d93-414e-9ab6-adf466272b5e","Price":{"aud":4725.0,"usd":3522.01,"nzd":5085.04,"sgd":4788.78},"Volume":15.0},"Time":1649023826376,"Event":"NewOrder"}
1649023826.496646: {"Channel":"orderbook-eth","Nonce":19579,"Data":{"OrderType":"LimitOffer","OrderGuid":"488ea36f-4216-4826-ba1a-2aa0ede418d7"},"Time":1649023826392,"Event":"OrderCanceled"}
1649023826.503503: {"Channel":"orderbook-eth","Nonce":19580,"Data":{"OrderType":"LimitBid","OrderGuid":"05a130d5-ec1f-4e0a-9a3b-b420e87c72e4","Price":{"aud":4724.63,"usd":3521.73,"nzd":5084.64,"sgd":4788.41},"Volume":14.14},"Time":1649023826392,"Event":"NewOrder"}
1649023826.507802: {"Channel":"orderbook-eth","Nonce":19581,"Data":{"OrderType":"LimitBid","OrderGuid":"55ca5123-f1ee-463f-a381-2bb5d0805ba4"},"Time":1649023826407,"Event":"OrderCanceled"}
1649023826.5108962: {"Channel":"orderbook-eth","Nonce":19582,"Data":{"OrderType":"LimitOffer","OrderGuid":"2a2395a7-0b2b-4966-83e3-7b21aef5c27e","Price":{"aud":4738.19,"usd":3567.38,"nzd":5161.43,"sgd":4831.93},"Volume":4.47331033},"Time":1649023826407,"Event":"NewOrder"}
1649023826.537709: {"Channel":"orderbook-bch","Nonce":8362,"Data":{"OrderType":"LimitOffer","OrderGuid":"95a24ecf-d5cc-4c04-bd28-eff5a93149fc","Price":{"aud":510.7,"usd":384.51,"nzd":556.32,"sgd":520.81},"Volume":39.74331},"Time":1649023826439,"Event":"NewOrder"}
1649023826.5378518: {"Channel":"orderbook-eth","Nonce":19583,"Data":{"OrderType":"LimitBid","OrderGuid":"9f881ecc-3365-4a6f-8167-8da914490a1c","Price":{"aud":4678.14,"usd":3504.02,"nzd":5096.02,"sgd":4769.87},"Volume":0.59937697},"Time":1649023826439,"Event":"NewOrder"}
1649023826.8400378: {"Channel":"orderbook-dot","Nonce":5021,"Data":{"OrderType":"LimitOffer","OrderGuid":"7502bccf-0812-41be-b6d1-5b3a73103326","Price":{"aud":31.3898,"usd":23.6334,"nzd":34.1937,"sgd":32.0109},"Volume":19.94108},"Time":1649023826691,"Event":"NewOrder"}
1649023826.8401651: {"Channel":"orderbook-bch","Nonce":8363,"Data":{"OrderType":"LimitOffer","OrderGuid":"8edc105a-2188-4a7c-a229-7bf437cacd65","Price":{"aud":507.78,"usd":382.31,"nzd":553.14,"sgd":517.83},"Volume":1.09290124},"Time":1649023826739,"Event":"NewOrder"}
1649023826.848035: {"Channel":"orderbook-dot","Nonce":5022,"Data":{"OrderType":"LimitOffer","OrderGuid":"d1c27af3-21b7-4c75-99ba-6d16257b8695"},"Time":1649023826739,"Event":"OrderCanceled"}
1649023827.008987: {"Channel":"orderbook-matic","Nonce":5947,"Data":{"OrderType":"LimitOffer","OrderGuid":"f0327dbe-641b-4235-a6d6-5779a2282754"},"Time":1649023826880,"Event":"OrderCanceled"}
1649023827.009077: {"Channel":"orderbook-bch","Nonce":8364,"Data":{"OrderType":"LimitOffer","OrderGuid":"cd3c6129-5cb6-4b8d-8e51-dc1ddd88f135"},"Time":1649023826895,"Event":"OrderCanceled"}
1649023827.009111: {"Channel":"orderbook-dot","Nonce":5023,"Data":{"OrderType":"LimitOffer","OrderGuid":"7c1bd995-acf5-4efa-98a1-f46a3177d8fe","Price":{"aud":31.3796,"usd":23.6257,"nzd":34.1826,"sgd":32.0005},"Volume":19.94108},"Time":1649023826911,"Event":"NewOrder"}
1649023827.064802: {"Channel":"orderbook-matic","Nonce":5948,"Data":{"OrderType":"LimitOffer","OrderGuid":"fa814b40-8149-4c6d-aff9-ad010ac8d671","Price":{"aud":2.27299,"usd":1.71134,"nzd":2.47603,"sgd":2.31796},"Volume":5217.1633},"Time":1649023826958,"Event":"NewOrder"}
1649023827.169823: {"Channel":"orderbook-eth","Nonce":19584,"Data":{"OrderType":"LimitOffer","OrderGuid":"495abeb9-e43e-4126-bede-a588718eef35","Price":{"aud":4762.61,"usd":3567.82,"nzd":5156.95,"sgd":4826.9},"Volume":21.062},"Time":1649023827067,"Event":"NewOrder"}
1649023827.2907698: {"Channel":"orderbook-eth","Nonce":19585,"Data":{"OrderType":"LimitBid","OrderGuid":"9e1179cf-72e9-47a4-a840-45efb62f3b0a"},"Time":1649023827192,"Event":"OrderCanceled"}
1649023827.3252301: {"Channel":"orderbook-eth","Nonce":19586,"Data":{"OrderType":"LimitBid","OrderGuid":"c9700b2b-0aee-48d3-bbe1-6d3c1f96952e","Price":{"aud":4698.86,"usd":3520.55,"nzd":5087.96,"sgd":4791.83},"Volume":3.14411358},"Time":1649023827224,"Event":"NewOrder"}
1649023827.644216: {"Channel":"orderbook-bch","Nonce":8365,"Data":{"OrderType":"LimitOffer","OrderGuid":"95a24ecf-d5cc-4c04-bd28-eff5a93149fc"},"Time":1649023827536,"Event":"OrderCanceled"}
1649023827.683722: {"Channel":"orderbook-bch","Nonce":8366,"Data":{"OrderType":"LimitOffer","OrderGuid":"af905f93-5807-4e74-a09b-4c3c8b0b7fb3"},"Time":1649023827583,"Event":"OrderCanceled"}
1649023827.694242: {"Channel":"orderbook-bch","Nonce":8367,"Data":{"OrderType":"LimitOffer","OrderGuid":"451d663f-0790-4598-9400-21866e61bd0a","Price":{"aud":507.68,"usd":382.24,"nzd":553.03,"sgd":517.73},"Volume":1.09290124},"Time":1649023827583,"Event":"NewOrder"}
1649023827.714894: {"Channel":"orderbook-bch","Nonce":8368,"Data":{"OrderType":"LimitOffer","OrderGuid":"273efad7-2bdf-4749-b56b-ab8ca4032341"},"Time":1649023827614,"Event":"OrderCanceled"}
1649023827.7288551: {"Channel":"orderbook-bch","Nonce":8369,"Data":{"OrderType":"LimitOffer","OrderGuid":"772809ac-e04e-411b-bd98-89318c0b67f6","Price":{"aud":535.87,"usd":403.46,"nzd":583.74,"sgd":546.48},"Volume":21.20858658},"Time":1649023827630,"Event":"NewOrder"}
1649023827.781238: {"Channel":"orderbook-eth","Nonce":19587,"Data":{"OrderType":"LimitBid","OrderGuid":"9f881ecc-3365-4a6f-8167-8da914490a1c"},"Time":1649023827677,"Event":"OrderCanceled"}
1649023827.7958028: {"Channel":"orderbook-eth","Nonce":19588,"Data":{"OrderType":"LimitOffer","OrderGuid":"a516ab21-eb74-4bde-94d1-92210fa2040d"},"Time":1649023827692,"Event":"OrderCanceled"}
1649023827.7959092: {"Channel":"orderbook-bch","Nonce":8370,"Data":{"OrderType":"LimitOffer","OrderGuid":"648ff05c-3c21-4d59-9522-79742526b3eb","Price":{"aud":510.68,"usd":384.5,"nzd":556.3,"sgd":520.79},"Volume":39.74331},"Time":1649023827692,"Event":"NewOrder"}
1649023827.807091: {"Channel":"orderbook-eth","Nonce":19589,"Data":{"OrderType":"LimitBid","OrderGuid":"62e8dacb-e90d-41b3-8b6a-20e462168275"},"Time":1649023827708,"Event":"OrderCanceled"}
1649023827.866245: {"Channel":"orderbook-bch","Nonce":8371,"Data":{"OrderType":"LimitOffer","OrderGuid":"9fb972d4-5eb4-4c4f-ac8a-8c7bed91262d","Price":{"aud":510.67,"usd":384.49,"nzd":556.29,"sgd":520.78},"Volume":21.20858658},"Time":1649023827755,"Event":"NewOrder"}
1649023827.881797: {"Channel":"orderbook-bch","Nonce":8372,"Data":{"OrderType":"LimitOffer","OrderGuid":"9a55a48a-daf5-4474-a571-1dc1340fe18a","Price":{"aud":510.68,"usd":384.5,"nzd":556.3,"sgd":520.79},"Volume":2.93},"Time":1649023827770,"Event":"NewOrder"}
1649023827.89447: {"Channel":"orderbook-eth","Nonce":19590,"Data":{"OrderType":"LimitBid","OrderGuid":"45ffdd71-5dad-4d3e-905a-e9b76a496b23","Price":{"aud":4678.15,"usd":3504.03,"nzd":5096.03,"sgd":4769.88},"Volume":0.56764005},"Time":1649023827786,"Event":"NewOrder"}
1649023827.894598: {"Channel":"orderbook-bch","Nonce":8373,"Data":{"OrderType":"LimitOffer","OrderGuid":"8edc105a-2188-4a7c-a229-7bf437cacd65"},"Time":1649023827786,"Event":"OrderCanceled"}
1649023827.894658: {"Channel":"orderbook-eth","Nonce":19591,"Data":{"OrderType":"LimitBid","OrderGuid":"8824d4f1-0d93-414e-9ab6-adf466272b5e"},"Time":1649023827786,"Event":"OrderCanceled"}
1649023827.8951209: {"Channel":"orderbook-eth","Nonce":19592,"Data":{"OrderType":"LimitOffer","OrderGuid":"8f9338aa-36bd-4947-b37a-5ef6c0e95469"},"Time":1649023827786,"Event":"OrderCanceled"}
1649023827.897579: {"Channel":"orderbook-eth","Nonce":19593,"Data":{"OrderType":"LimitBid","OrderGuid":"b8360322-cf18-4358-b495-2b0fd0ca6f4f","Price":{"aud":4725.01,"usd":3522.02,"nzd":5085.05,"sgd":4788.79},"Volume":14.14},"Time":1649023827786,"Event":"NewOrder"}
1649023827.8976681: {"Channel":"orderbook-bch","Nonce":8374,"Data":{"OrderType":"LimitOffer","OrderGuid":"772809ac-e04e-411b-bd98-89318c0b67f6"},"Time":1649023827786,"Event":"OrderCanceled"}
1649023827.934106: {"Channel":"orderbook-eth","Nonce":19594,"Data":{"OrderType":"LimitBid","OrderGuid":"05a130d5-ec1f-4e0a-9a3b-b420e87c72e4"},"Time":1649023827833,"Event":"OrderCanceled"}
1649023827.934162: {"Channel":"orderbook-dot","Nonce":5024,"Data":{"OrderType":"LimitOffer","OrderGuid":"7502bccf-0812-41be-b6d1-5b3a73103326"},"Time":1649023827833,"Event":"OrderCanceled"}
1649023827.9556448: {"Channel":"orderbook-eth","Nonce":19595,"Data":{"OrderType":"LimitOffer","OrderGuid":"525f8d87-57ca-480c-a519-b1afa848c57b","Price":{"aud":4734.9,"usd":3564.9,"nzd":5157.85,"sgd":4828.58},"Volume":15.0},"Time":1649023827849,"Event":"NewOrder"}
1649023827.9577248: {"Channel":"orderbook-eth","Nonce":19596,"Data":{"OrderType":"LimitBid","OrderGuid":"be76377a-f594-4380-a6b2-12c9b4c259fc","Price":{"aud":4727.7,"usd":3524.02,"nzd":5087.95,"sgd":4791.52},"Volume":15.0},"Time":1649023827849,"Event":"NewOrder"}
1649023827.96596: {"Channel":"orderbook-eth","Nonce":19597,"Data":{"OrderType":"LimitOffer","OrderGuid":"fde3421c-57c1-461a-81e7-1aac06d4572f","Price":{"aud":4737.9,"usd":3567.16,"nzd":5161.12,"sgd":4831.64},"Volume":15.0},"Time":1649023827864,"Event":"NewOrder"}
1649023827.9693491: {"Channel":"orderbook-eth","Nonce":19598,"Data":{"OrderType":"LimitOffer","OrderGuid":"2a2395a7-0b2b-4966-83e3-7b21aef5c27e"},"Time":1649023827864,"Event":"OrderCanceled"}
1649023828.025198: {"Channel":"orderbook-eth","Nonce":19599,"Data":{"OrderType":"LimitOffer","OrderGuid":"207b5fdd-af95-4ea5-83cc-da45d83b0db1","Price":{"aud":4742.02,"usd":3570.27,"nzd":5165.6,"sgd":4835.84},"Volume":4.47331033},"Time":1649023827927,"Event":"NewOrder"}
1649023828.043297: {"Channel":"orderbook-eth","Nonce":19600,"Data":{"OrderType":"LimitBid","OrderGuid":"bcec9227-3008-4ccc-87e3-1d7b2550d690","Price":{"aud":4724.7,"usd":3521.79,"nzd":5084.72,"sgd":4788.48},"Volume":15.0},"Time":1649023827942,"Event":"NewOrder"}
1649023828.309206: {"Channel":"orderbook-eth","Nonce":19601,"Data":{"OrderType":"LimitOffer","OrderGuid":"fde3421c-57c1-461a-81e7-1aac06d4572f"},"Time":1649023828208,"Event":"OrderCanceled"}
1649023828.3211899: {"Channel":"orderbook-eth","Nonce":19602,"Data":{"OrderType":"LimitBid","OrderGuid":"bcec9227-3008-4ccc-87e3-1d7b2550d690"},"Time":1649023828224,"Event":"OrderCanceled"}
1649023828.3263109: {"Channel":"orderbook-eth","Nonce":19603,"Data":{"OrderType":"LimitBid","OrderGuid":"be76377a-f594-4380-a6b2-12c9b4c259fc"},"Time":1649023828224,"Event":"OrderCanceled"}
1649023828.344098: {"Channel":"orderbook-bch","Nonce":8375,"Data":{"OrderType":"LimitOffer","OrderGuid":"8d51ff15-c587-4f3e-8113-9f5d1cf837db","Price":{"aud":507.78,"usd":382.31,"nzd":553.14,"sgd":517.83},"Volume":1.09287184},"Time":1649023828239,"Event":"NewOrder"}
1649023828.42512: {"Channel":"orderbook-eth","Nonce":19604,"Data":{"OrderType":"LimitOffer","OrderGuid":"525f8d87-57ca-480c-a519-b1afa848c57b"},"Time":1649023828317,"Event":"OrderCanceled"}
1649023828.427469: {"Channel":"orderbook-eth","Nonce":19605,"Data":{"OrderType":"LimitBid","OrderGuid":"72fa65b1-0a6c-493d-a004-136ff19cd61f","Price":{"aud":4724.9,"usd":3521.94,"nzd":5084.93,"sgd":4788.68},"Volume":15.0},"Time":1649023828317,"Event":"NewOrder"}
1649023828.427542: {"Channel":"orderbook-dot","Nonce":5025,"Data":{"OrderType":"LimitOffer","OrderGuid":"b4979f27-5737-47b7-af2f-ada8fce60acc","Price":{"aud":31.3896,"usd":23.6332,"nzd":34.1935,"sgd":32.0107},"Volume":19.94071},"Time":1649023828317,"Event":"NewOrder"}
1649023828.513058: {"Channel":"orderbook-eth","Nonce":19606,"Data":{"OrderType":"LimitOffer","OrderGuid":"cfe42207-5b8a-434d-89d2-a2aa831d974d","Price":{"aud":4735.1,"usd":3565.06,"nzd":5158.07,"sgd":4828.78},"Volume":15.0},"Time":1649023828411,"Event":"NewOrder"}
1649023828.527421: {"Channel":"orderbook-eth","Nonce":19607,"Data":{"OrderType":"LimitBid","OrderGuid":"d9dc524c-462a-4b95-b090-999deff81823","Price":{"aud":4727.9,"usd":3524.17,"nzd":5088.16,"sgd":4791.72},"Volume":15.0},"Time":1649023828427,"Event":"NewOrder"}
1649023828.527565: {"Channel":"orderbook-eth","Nonce":19608,"Data":{"OrderType":"LimitOffer","OrderGuid":"e6629204-7114-4974-bf31-b9ea155a7e8f","Price":{"aud":4738.1,"usd":3567.31,"nzd":5161.33,"sgd":4831.84},"Volume":15.0},"Time":1649023828427,"Event":"NewOrder"}
1649023828.5388732: {"Channel":"orderbook-dot","Nonce":5026,"Data":{"OrderType":"LimitOffer","OrderGuid":"7c1bd995-acf5-4efa-98a1-f46a3177d8fe"},"Time":1649023828427,"Event":"OrderCanceled"}
1649023828.671218: {"Channel":"orderbook-eth","Nonce":19609,"Data":{"OrderType":"LimitBid","OrderGuid":"45ffdd71-5dad-4d3e-905a-e9b76a496b23"},"Time":1649023828567,"Event":"OrderCanceled"}
1649023828.728425: {"Channel":"orderbook-eth","Nonce":19610,"Data":{"OrderType":"LimitBid","OrderGuid":"d511c219-05d1-4bd0-8072-d1531b4ab806","Price":{"aud":4678.16,"usd":3504.03,"nzd":5096.04,"sgd":4769.89},"Volume":0.42676828},"Time":1649023828630,"Event":"NewOrder"}
1649023828.7492921: {"Channel":"orderbook-bch","Nonce":8376,"Data":{"OrderType":"LimitOffer","OrderGuid":"451d663f-0790-4598-9400-21866e61bd0a"},"Time":1649023828645,"Event":"OrderCanceled"}
1649023828.84974: {"Channel":"orderbook-eth","Nonce":19611,"Data":{"OrderType":"LimitBid","OrderGuid":"d9dc524c-462a-4b95-b090-999deff81823"},"Time":1649023828739,"Event":"OrderCanceled"}
1649023828.850253: {"Channel":"orderbook-eth","Nonce":19612,"Data":{"OrderType":"LimitOffer","OrderGuid":"cfe42207-5b8a-434d-89d2-a2aa831d974d"},"Time":1649023828739,"Event":"OrderCanceled"}
1649023828.853951: {"Channel":"orderbook-eth","Nonce":19613,"Data":{"OrderType":"LimitBid","OrderGuid":"72fa65b1-0a6c-493d-a004-136ff19cd61f"},"Time":1649023828755,"Event":"OrderCanceled"}
1649023828.856226: {"Channel":"orderbook-eth","Nonce":19614,"Data":{"OrderType":"LimitOffer","OrderGuid":"e6629204-7114-4974-bf31-b9ea155a7e8f"},"Time":1649023828755,"Event":"OrderCanceled"}
1649023828.903483: {"Channel":"orderbook-eth","Nonce":19615,"Data":{"OrderType":"LimitBid","OrderGuid":"7189c196-8de7-4185-87e7-775120fc9a5f","Price":{"aud":4724.91,"usd":3521.94,"nzd":5084.94,"sgd":4788.69},"Volume":14.14},"Time":1649023828802,"Event":"NewOrder"}
1649023828.903546: {"Channel":"orderbook-eth","Nonce":19616,"Data":{"OrderType":"LimitOffer","OrderGuid":"56bb5d1a-c3b8-4a8c-9ad6-bd7085ed350b","Price":{"aud":4735.0,"usd":3564.98,"nzd":5157.96,"sgd":4828.68},"Volume":15.0},"Time":1649023828802,"Event":"NewOrder"}
1649023828.903573: {"Channel":"orderbook-eth","Nonce":19617,"Data":{"OrderType":"LimitOffer","OrderGuid":"f3b7215f-2a95-4bc8-9276-f1d0d205ac7c","Price":{"aud":4738.09,"usd":3567.31,"nzd":5161.32,"sgd":4831.83},"Volume":4.47331033},"Time":1649023828802,"Event":"NewOrder"}
1649023828.9036102: {"Channel":"orderbook-eth","Nonce":19618,"Data":{"OrderType":"LimitBid","OrderGuid":"ddee911b-5a6f-4a8c-a67b-ecb83bc2ec18","Price":{"aud":4724.8,"usd":3521.86,"nzd":5084.82,"sgd":4788.58},"Volume":15.0},"Time":1649023828802,"Event":"NewOrder"}
1649023828.906719: {"Channel":"orderbook-eth","Nonce":19619,"Data":{"OrderType":"LimitOffer","OrderGuid":"6a652e44-13e0-435b-9d85-8a874d3edba9","Price":{"aud":4738.0,"usd":3567.24,"nzd":5161.23,"sgd":4831.74},"Volume":15.0},"Time":1649023828802,"Event":"NewOrder"}
1649023828.908737: {"Channel":"orderbook-eth","Nonce":19620,"Data":{"OrderType":"LimitOffer","OrderGuid":"207b5fdd-af95-4ea5-83cc-da45d83b0db1"},"Time":1649023828802,"Event":"OrderCanceled"}
1649023828.924368: {"Channel":"orderbook-eth","Nonce":19621,"Data":{"OrderType":"LimitBid","OrderGuid":"b8360322-cf18-4358-b495-2b0fd0ca6f4f"},"Time":1649023828819,"Event":"OrderCanceled"}
1649023828.958859: {"Channel":"orderbook-eth","Nonce":19622,"Data":{"OrderType":"LimitOffer","OrderGuid":"2c3107d5-4f9e-43fb-aaf6-68de5511031f"},"Time":1649023828850,"Event":"OrderCanceled"}
1649023828.963228: {"Channel":"orderbook-eth","Nonce":19623,"Data":{"OrderType":"LimitBid","OrderGuid":"c9700b2b-0aee-48d3-bbe1-6d3c1f96952e"},"Time":1649023828865,"Event":"OrderCanceled"}
1649023828.992246: {"Channel":"orderbook-bch","Nonce":8377,"Data":{"OrderType":"LimitOffer","OrderGuid":"648ff05c-3c21-4d59-9522-79742526b3eb"},"Time":1649023828881,"Event":"OrderCanceled"}
1649023829.000344: {"Channel":"orderbook-eth","Nonce":19624,"Data":{"OrderType":"LimitBid","OrderGuid":"60f4a6c9-d384-4008-b590-77d5bcd77f91","Price":{"aud":4727.8,"usd":3524.1,"nzd":5088.05,"sgd":4791.62},"Volume":15.0},"Time":1649023828897,"Event":"NewOrder"}
1649023829.000472: {"Channel":"orderbook-eth","Nonce":19625,"Data":{"OrderType":"LimitBid","OrderGuid":"22e3d921-f584-4d67-8e4e-56117af1ee87","Price":{"aud":4698.57,"usd":3520.33,"nzd":5087.64,"sgd":4791.53},"Volume":3.14505434},"Time":1649023828897,"Event":"NewOrder"}
1649023829.022078: {"Channel":"orderbook-eth","Nonce":19626,"Data":{"OrderType":"LimitOffer","OrderGuid":"07f60687-f552-49a0-9034-4ae794c64923","Price":{"aud":4794.21,"usd":3573.6,"nzd":5197.21,"sgd":4864.03},"Volume":0.54023486},"Time":1649023828912,"Event":"NewOrder"}
1649023829.1053271: {"Channel":"orderbook-eth","Nonce":19627,"Data":{"OrderType":"LimitBid","OrderGuid":"60f4a6c9-d384-4008-b590-77d5bcd77f91"},"Time":1649023829007,"Event":"OrderCanceled"}
1649023829.10539: {"Channel":"orderbook-eth","Nonce":19628,"Data":{"OrderType":"LimitOffer","OrderGuid":"56bb5d1a-c3b8-4a8c-9ad6-bd7085ed350b"},"Time":1649023829007,"Event":"OrderCanceled"}
1649023829.1109362: {"Channel":"orderbook-eth","Nonce":19629,"Data":{"OrderType":"LimitOffer","OrderGuid":"6a652e44-13e0-435b-9d85-8a874d3edba9"},"Time":1649023829007,"Event":"OrderCanceled"}
1649023829.125335: {"Channel":"orderbook-bch","Nonce":8378,"Data":{"OrderType":"LimitOffer","OrderGuid":"a3a8c3aa-6dec-49ff-ac78-c25c9b9f82f3","Price":{"aud":510.66,"usd":384.48,"nzd":556.28,"sgd":520.77},"Volume":39.74331},"Time":1649023829023,"Event":"NewOrder"}
1649023829.150523: {"Channel":"orderbook-eth","Nonce":19630,"Data":{"OrderType":"LimitOffer","OrderGuid":"356cfabc-5c68-4ad6-81e6-8921301514c0","Price":{"aud":4737.99,"usd":3567.23,"nzd":5161.21,"sgd":4831.73},"Volume":4.47331033},"Time":1649023829039,"Event":"NewOrder"}
1649023829.154829: {"Channel":"orderbook-eth","Nonce":19631,"Data":{"OrderType":"LimitOffer","OrderGuid":"f3b7215f-2a95-4bc8-9276-f1d0d205ac7c"},"Time":1649023829054,"Event":"OrderCanceled"}
1649023829.163439: {"Channel":"orderbook-bch","Nonce":8379,"Data":{"OrderType":"LimitOffer","OrderGuid":"bf5c2952-90a8-421c-b6b1-a2e38f9ee799","Price":{"aud":510.65,"usd":384.47,"nzd":556.27,"sgd":520.76},"Volume":21.20858658},"Time":1649023829054,"Event":"NewOrder"}
1649023829.168886: {"Channel":"orderbook-bch","Nonce":8380,"Data":{"OrderType":"LimitOffer","OrderGuid":"9fb972d4-5eb4-4c4f-ac8a-8c7bed91262d"},"Time":1649023829070,"Event":"OrderCanceled"}
1649023829.206825: {"Channel":"orderbook-eth","Nonce":19632,"Data":{"OrderType":"LimitOffer","OrderGuid":"ff38fec4-01cd-44fc-8738-0f7e61dcb625","Price":{"aud":4737.4,"usd":3566.79,"nzd":5160.57,"sgd":4831.13},"Volume":15.0},"Time":1649023829101,"Event":"NewOrder"}
1649023829.231957: {"Channel":"orderbook-matic","Nonce":5949,"Data":{"OrderType":"LimitOffer","OrderGuid":"b53c48bb-e083-4e55-a25c-5f1bfd7bdf9a"},"Time":1649023829132,"Event":"OrderCanceled"}
1649023829.3163211: {"Channel":"orderbook-eth","Nonce":19633,"Data":{"OrderType":"LimitBid","OrderGuid":"ddee911b-5a6f-4a8c-a67b-ecb83bc2ec18"},"Time":1649023829210,"Event":"OrderCanceled"}
1649023829.334935: {"Channel":"orderbook-eth","Nonce":19634,"Data":{"OrderType":"LimitOffer","OrderGuid":"218bc01c-2901-4745-b150-f9cc72d250a9","Price":{"aud":4734.4,"usd":3564.53,"nzd":5157.3,"sgd":4828.07},"Volume":15.0},"Time":1649023829226,"Event":"NewOrder"}
1649023829.342129: {"Channel":"orderbook-matic","Nonce":5950,"Data":{"OrderType":"LimitOffer","OrderGuid":"933249cb-fa57-487f-ba22-7dc62c19ecf0"},"Time":1649023829242,"Event":"OrderCanceled"}
1649023829.3422332: {"Channel":"orderbook-matic","Nonce":5951,"Data":{"OrderType":"LimitBid","OrderGuid":"3f8fd9e6-b149-410e-ba00-376aad95ebfe"},"Time":1649023829242,"Event":"OrderCanceled"}
1649023829.346633: {"Channel":"orderbook-matic","Nonce":5952,"Data":{"OrderType":"LimitBid","OrderGuid":"8b9082db-bf46-4a68-92eb-c462bbcc08e3"},"Time":1649023829242,"Event":"OrderCanceled"}
1649023829.3579571: {"Channel":"orderbook-eth","Nonce":19635,"Data":{"OrderType":"LimitBid","OrderGuid":"464e4b1e-ae4e-4d78-8a69-19ec807bbd65","Price":{"aud":4727.2,"usd":3523.65,"nzd":5087.41,"sgd":4791.01},"Volume":15.0},"Time":1649023829257,"Event":"NewOrder"}
1649023829.358044: {"Channel":"orderbook-eth","Nonce":19636,"Data":{"OrderType":"LimitOffer","OrderGuid":"ff38fec4-01cd-44fc-8738-0f7e61dcb625"},"Time":1649023829257,"Event":"OrderCanceled"}
1649023829.372106: {"Channel":"orderbook-matic","Nonce":5953,"Data":{"OrderType":"LimitOffer","OrderGuid":"9682a6ef-1dbe-45de-91e0-aa86583ff3a2","Price":{"aud":2.2735,"usd":1.71172,"nzd":2.47658,"sgd":2.31848},"Volume":5583.0},"Time":1649023829273,"Event":"NewOrder"}
1649023829.376235: {"Channel":"orderbook-matic","Nonce":5954,"Data":{"OrderType":"LimitBid","OrderGuid":"770b2b51-91f7-4126-b291-9523a280d2ad","Price":{"aud":2.2625,"usd":1.68646,"nzd":2.4349,"sgd":2.29304},"Volume":5583.0},"Time":1649023829273,"Event":"NewOrder"}
1649023829.4030561: {"Channel":"orderbook-matic","Nonce":5955,"Data":{"OrderType":"LimitBid","OrderGuid":"cc51af04-2019-419e-a59f-6766ec13fb57","Price":{"aud":2.261,"usd":1.68534,"nzd":2.43328,"sgd":2.29152},"Volume":5583.0},"Time":1649023829304,"Event":"NewOrder"}
1649023829.4616709: {"Channel":"orderbook-eth","Nonce":19637,"Data":{"OrderType":"LimitBid","OrderGuid":"464e4b1e-ae4e-4d78-8a69-19ec807bbd65"},"Time":1649023829351,"Event":"OrderCanceled"}
1649023829.4661708: {"Channel":"orderbook-eth","Nonce":19638,"Data":{"OrderType":"LimitOffer","OrderGuid":"218bc01c-2901-4745-b150-f9cc72d250a9"},"Time":1649023829367,"Event":"OrderCanceled"}
1649023829.4667552: {"Channel":"orderbook-eth","Nonce":19639,"Data":{"OrderType":"LimitBid","OrderGuid":"77607e4d-e338-44d9-8743-1c3a35962a51"},"Time":1649023829367,"Event":"OrderCanceled"}
1649023829.4806132: {"Channel":"orderbook-matic","Nonce":5956,"Data":{"OrderType":"LimitOffer","OrderGuid":"05c2b43c-b024-47d7-96ba-83285a2ec86a","Price":{"aud":2.275,"usd":1.71285,"nzd":2.47822,"sgd":2.32001},"Volume":5583.0},"Time":1649023829382,"Event":"NewOrder"}
1649023829.49491: {"Channel":"orderbook-eth","Nonce":19640,"Data":{"OrderType":"LimitBid","OrderGuid":"7ed623f4-49a5-4ebc-992a-1e7e2a2f7963","Price":{"aud":4727.3,"usd":3523.72,"nzd":5087.52,"sgd":4791.11},"Volume":15.0},"Time":1649023829382,"Event":"NewOrder"}
1649023829.4964092: {"Channel":"orderbook-eth","Nonce":19641,"Data":{"OrderType":"LimitOffer","OrderGuid":"cd64f0c2-9041-4677-9d37-ebf6abb53017","Price":{"aud":4734.5,"usd":3564.6,"nzd":5157.41,"sgd":4828.17},"Volume":15.0},"Time":1649023829398,"Event":"NewOrder"}
1649023829.538729: {"Channel":"orderbook-eth","Nonce":19642,"Data":{"OrderType":"LimitOffer","OrderGuid":"486e04d7-6417-49cc-9987-badd11f2a9a2","Price":{"aud":4737.5,"usd":3566.86,"nzd":5160.68,"sgd":4831.23},"Volume":15.0},"Time":1649023829429,"Event":"NewOrder"}
1649023829.55625: {"Channel":"orderbook-eth","Nonce":19643,"Data":{"OrderType":"LimitBid","OrderGuid":"3072078c-00f3-4f59-9a60-74907710c5f6","Price":{"aud":4703.98,"usd":3506.34,"nzd":5062.42,"sgd":4767.48},"Volume":0.35177517},"Time":1649023829445,"Event":"NewOrder"}
1649023829.6274822: {"Channel":"orderbook-matic","Nonce":5957,"Data":{"OrderType":"LimitBid","OrderGuid":"fc6b4097-b7db-44cb-a0a8-17d35229e6ff"},"Time":1649023829523,"Event":"OrderCanceled"}
1649023829.6280608: {"Channel":"orderbook-matic","Nonce":5958,"Data":{"OrderType":"LimitOffer","OrderGuid":"fa814b40-8149-4c6d-aff9-ad010ac8d671"},"Time":1649023829523,"Event":"OrderCanceled"}
1649023829.6325738: {"Channel":"orderbook-eth","Nonce":19644,"Data":{"OrderType":"LimitBid","OrderGuid":"1d2d300c-91cb-45d0-8a8e-009ddec7b040","Price":{"aud":4724.3,"usd":3521.49,"nzd":5084.29,"sgd":4788.07},"Volume":15.0},"Time":1649023829523,"Event":"NewOrder"}
1649023829.6834729: {"Channel":"orderbook-matic","Nonce":5959,"Data":{"OrderType":"LimitOffer","OrderGuid":"995f3c3e-82a1-43cb-ac85-9d80ebac0e84","Price":{"aud":2.27298,"usd":1.71133,"nzd":2.47602,"sgd":2.31795},"Volume":5325.40684},"Time":1649023829585,"Event":"NewOrder"}
1649023829.6855838: {"Channel":"orderbook-matic","Nonce":5960,"Data":{"OrderType":"LimitBid","OrderGuid":"a4ea67d4-c57a-4f3a-8d66-86ed2b1eb44c","Price":{"aud":2.26251,"usd":1.68647,"nzd":2.43491,"sgd":2.29305},"Volume":5854.26118},"Time":1649023829585,"Event":"NewOrder"}
1649023829.7505548: {"Channel":"orderbook-eth","Nonce":19645,"Data":{"OrderType":"LimitBid","OrderGuid":"d511c219-05d1-4bd0-8072-d1531b4ab806"},"Time":1649023829649,"Event":"OrderCanceled"}
1649023829.756225: {"Channel":"orderbook-matic","Nonce":5961,"Data":{"OrderType":"LimitOffer","OrderGuid":"05c2b43c-b024-47d7-96ba-83285a2ec86a"},"Time":1649023829649,"Event":"OrderCanceled"}
1649023829.817062: {"Channel":"orderbook-eth","Nonce":19646,"Data":{"OrderType":"LimitBid","OrderGuid":"b4bbb9e5-57e1-45ae-b919-0a8efd73dc9c","Price":{"aud":4678.17,"usd":3504.04,"nzd":5096.05,"sgd":4769.9},"Volume":0.44839412},"Time":1649023829711,"Event":"NewOrder"}
1649023829.857997: {"Channel":"orderbook-matic","Nonce":5962,"Data":{"OrderType":"LimitBid","OrderGuid":"770b2b51-91f7-4126-b291-9523a280d2ad"},"Time":1649023829758,"Event":"OrderCanceled"}
1649023829.8630369: {"Channel":"orderbook-matic","Nonce":5963,"Data":{"OrderType":"LimitOffer","OrderGuid":"9682a6ef-1dbe-45de-91e0-aa86583ff3a2"},"Time":1649023829758,"Event":"OrderCanceled"}
1649023829.863112: {"Channel":"orderbook-matic","Nonce":5964,"Data":{"OrderType":"LimitBid","OrderGuid":"cc51af04-2019-419e-a59f-6766ec13fb57"},"Time":1649023829758,"Event":"OrderCanceled"}
1649023829.8911371: {"Channel":"orderbook-matic","Nonce":5965,"Data":{"OrderType":"LimitOffer","OrderGuid":"e2ff5a44-4e87-441f-8b2f-ccc40cad4b60","Price":{"aud":2.273,"usd":1.71134,"nzd":2.47604,"sgd":2.31797},"Volume":5583.0},"Time":1649023829789,"Event":"NewOrder"}
1649023829.894272: {"Channel":"orderbook-matic","Nonce":5966,"Data":{"OrderType":"LimitBid","OrderGuid":"3cc2a204-00bb-4ddb-b864-e40bf20eab1e","Price":{"aud":2.262,"usd":1.68609,"nzd":2.43436,"sgd":2.29253},"Volume":5583.0},"Time":1649023829789,"Event":"NewOrder"}
1649023829.9034328: {"Channel":"orderbook-eth","Nonce":19647,"Data":{"OrderType":"LimitOffer","OrderGuid":"07f60687-f552-49a0-9034-4ae794c64923"},"Time":1649023829805,"Event":"OrderCanceled"}
1649023829.9209542: {"Channel":"orderbook-matic","Nonce":5967,"Data":{"OrderType":"LimitBid","OrderGuid":"2d1e847a-c39a-423b-a50f-9299d28db660","Price":{"aud":2.2605,"usd":1.68497,"nzd":2.43275,"sgd":2.29101},"Volume":5583.0},"Time":1649023829821,"Event":"NewOrder"}
1649023829.9474938: {"Channel":"orderbook-eth","Nonce":19648,"Data":{"OrderType":"LimitOffer","OrderGuid":"98c7ab46-61fe-4099-b4f6-5ea9b2f71d39","Price":{"aud":4794.65,"usd":3573.93,"nzd":5197.69,"sgd":4864.48},"Volume":0.53607392},"Time":1649023829836,"Event":"NewOrder"}
1649023829.951644: {"Channel":"orderbook-dot","Nonce":5027,"Data":{"OrderType":"LimitBid","OrderGuid":"453d8e08-3c15-45c3-ba7b-b8470d2e1fdb","Price":{"aud":30.7995,"usd":22.9579,"nzd":33.1464,"sgd":31.2152},"Volume":24.76507},"Time":1649023829852,"Event":"NewOrder"}
1649023830.0015192: {"Channel":"orderbook-matic","Nonce":5968,"Data":{"OrderType":"LimitOffer","OrderGuid":"ec4a8122-012f-40f8-b1a9-b5a3115f3f62","Price":{"aud":2.2745,"usd":1.71247,"nzd":2.47767,"sgd":2.3195},"Volume":5583.0},"Time":1649023829899,"Event":"NewOrder"}
1649023830.0039868: {"Channel":"orderbook-eth","Nonce":19649,"Data":{"OrderType":"LimitBid","OrderGuid":"36abe9a7-4615-4613-9390-0ccf03f96ba2","Price":{"aud":4668.81,"usd":3480.13,"nzd":5024.57,"sgd":4731.83},"Volume":0.19519746},"Time":1649023829899,"Event":"NewOrder"}
1649023830.009696: {"Channel":"orderbook-dot","Nonce":5028,"Data":{"OrderType":"LimitBid","OrderGuid":"e1c3bafd-572c-442a-80ed-5206470c2928"},"Time":1649023829899,"Event":"OrderCanceled"}
1649023830.10768: {"Channel":"orderbook-eth","Nonce":19650,"Data":{"OrderType":"LimitBid","OrderGuid":"9686ce63-afc9-43cc-b162-05283eb98a7d"},"Time":1649023830010,"Event":"OrderCanceled"}
1649023830.1642098: {"Channel":"orderbook-eth","Nonce":19651,"Data":{"OrderType":"LimitOffer","OrderGuid":"cd64f0c2-9041-4677-9d37-ebf6abb53017"},"Time":1649023830057,"Event":"OrderCanceled"}
1649023830.16431: {"Channel":"orderbook-eth","Nonce":19652,"Data":{"OrderType":"LimitBid","OrderGuid":"7ed623f4-49a5-4ebc-992a-1e7e2a2f7963"},"Time":1649023830057,"Event":"OrderCanceled"}
1649023830.1939242: {"Channel":"orderbook-eth","Nonce":19653,"Data":{"OrderType":"LimitOffer","OrderGuid":"486e04d7-6417-49cc-9987-badd11f2a9a2"},"Time":1649023830088,"Event":"OrderCanceled"}
1649023830.210054: {"Channel":"orderbook-bch","Nonce":8381,"Data":{"OrderType":"LimitOffer","OrderGuid":"a3a8c3aa-6dec-49ff-ac78-c25c9b9f82f3"},"Time":1649023830104,"Event":"OrderCanceled"}
1649023830.214274: {"Channel":"orderbook-eth","Nonce":19654,"Data":{"OrderType":"LimitOffer","OrderGuid":"5210f521-4666-4462-8367-fb0b33f293d5","Price":{"aud":4737.49,"usd":3566.85,"nzd":5160.67,"sgd":4831.22},"Volume":4.47331033},"Time":1649023830104,"Event":"NewOrder"}
1649023830.216376: {"Channel":"orderbook-eth","Nonce":19655,"Data":{"OrderType":"LimitBid","OrderGuid":"2f5122b8-975f-4575-8257-98766f444be2","Price":{"aud":4724.63,"usd":3521.73,"nzd":5084.64,"sgd":4788.41},"Volume":14.14},"Time":1649023830119,"Event":"NewOrder"}
1649023830.2203531: {"Channel":"orderbook-eth","Nonce":19656,"Data":{"OrderType":"LimitOffer","OrderGuid":"356cfabc-5c68-4ad6-81e6-8921301514c0"},"Time":1649023830119,"Event":"OrderCanceled"}
1649023830.220458: {"Channel":"orderbook-eth","Nonce":19657,"Data":{"OrderType":"LimitBid","OrderGuid":"7189c196-8de7-4185-87e7-775120fc9a5f"},"Time":1649023830119,"Event":"OrderCanceled"}
1649023830.268831: {"Channel":"orderbook-eth","Nonce":19658,"Data":{"OrderType":"LimitOffer","OrderGuid":"75503b2b-2c10-4f8a-b9fd-2dc61379ad2e","Price":{"aud":4737.3,"usd":3566.71,"nzd":5160.46,"sgd":4831.03},"Volume":15.0},"Time":1649023830166,"Event":"NewOrder"}
1649023830.28266: {"Channel":"orderbook-bch","Nonce":8382,"Data":{"OrderType":"LimitOffer","OrderGuid":"4d45a6df-796c-4ceb-8971-8476b82b6e95","Price":{"aud":510.67,"usd":384.49,"nzd":556.29,"sgd":520.78},"Volume":21.20858658},"Time":1649023830182,"Event":"NewOrder"}
1649023830.2961438: {"Channel":"orderbook-eth","Nonce":19659,"Data":{"OrderType":"LimitBid","OrderGuid":"1d2d300c-91cb-45d0-8a8e-009ddec7b040"},"Time":1649023830198,"Event":"OrderCanceled"}
1649023830.3103092: {"Channel":"orderbook-bch","Nonce":8383,"Data":{"OrderType":"LimitOffer","OrderGuid":"bf5c2952-90a8-421c-b6b1-a2e38f9ee799"},"Time":1649023830213,"Event":"OrderCanceled"}
1649023830.327389: {"Channel":"orderbook-matic","Nonce":5969,"Data":{"OrderType":"LimitBid","OrderGuid":"3cc2a204-00bb-4ddb-b864-e40bf20eab1e"},"Time":1649023830229,"Event":"OrderCanceled"}
1649023830.336498: {"Channel":"orderbook-matic","Nonce":5970,"Data":{"OrderType":"LimitBid","OrderGuid":"2d1e847a-c39a-423b-a50f-9299d28db660"},"Time":1649023830229,"Event":"OrderCanceled"}
1649023830.349697: {"Channel":"orderbook-bch","Nonce":8384,"Data":{"OrderType":"LimitOffer","OrderGuid":"c3c85444-c7fb-42dc-9287-c7f8b7b7f61c","Price":{"aud":510.64,"usd":384.47,"nzd":556.26,"sgd":520.75},"Volume":39.74331},"Time":1649023830244,"Event":"NewOrder"}
1649023830.3659258: {"Channel":"orderbook-eth","Nonce":19660,"Data":{"OrderType":"LimitBid","OrderGuid":"7e7ff48f-6e78-4557-bda9-178e736108cc","Price":{"aud":4727.1,"usd":3523.58,"nzd":5087.3,"sgd":4790.91},"Volume":15.0},"Time":1649023830260,"Event":"NewOrder"}
1649023830.3692732: {"Channel":"orderbook-eth","Nonce":19661,"Data":{"OrderType":"LimitBid","OrderGuid":"dded3307-e583-4ee3-a736-07a0d6ac1551","Price":{"aud":4724.1,"usd":3521.34,"nzd":5084.07,"sgd":4787.87},"Volume":15.0},"Time":1649023830260,"Event":"NewOrder"}
1649023830.390173: {"Channel":"orderbook-bch","Nonce":8385,"Data":{"OrderType":"LimitOffer","OrderGuid":"70eed5bd-9be0-4dde-ab27-3aff26a71ab9","Price":{"aud":510.63,"usd":384.46,"nzd":556.25,"sgd":520.74},"Volume":21.20858658},"Time":1649023830291,"Event":"NewOrder"}
1649023830.394536: {"Channel":"orderbook-matic","Nonce":5971,"Data":{"OrderType":"LimitOffer","OrderGuid":"ec4a8122-012f-40f8-b1a9-b5a3115f3f62"},"Time":1649023830291,"Event":"OrderCanceled"}
1649023830.3946419: {"Channel":"orderbook-bch","Nonce":8386,"Data":{"OrderType":"LimitOffer","OrderGuid":"4d45a6df-796c-4ceb-8971-8476b82b6e95"},"Time":1649023830291,"Event":"OrderCanceled"}
1649023830.401058: {"Channel":"orderbook-matic","Nonce":5972,"Data":{"OrderType":"LimitBid","OrderGuid":"313e1cfe-d3fc-4bb8-bb74-2abe5588389f","Price":{"aud":2.261,"usd":1.68534,"nzd":2.43328,"sgd":2.29152},"Volume":5583.0},"Time":1649023830291,"Event":"NewOrder"}
1649023830.404381: {"Channel":"orderbook-matic","Nonce":5973,"Data":{"OrderType":"LimitBid","OrderGuid":"e5275220-9b6d-44b2-854d-d485aef2b05f","Price":{"aud":2.2625,"usd":1.68646,"nzd":2.4349,"sgd":2.29304},"Volume":5583.0},"Time":1649023830307,"Event":"NewOrder"}
1649023830.466227: {"Channel":"orderbook-dot","Nonce":5029,"Data":{"OrderType":"LimitBid","OrderGuid":"2fff6403-5933-47c6-a92e-d7a9df4fbdc5","Price":{"aud":30.3741,"usd":22.6408,"nzd":32.6886,"sgd":30.7841},"Volume":25.08731},"Time":1649023830354,"Event":"NewOrder"}
1649023830.489454: {"Channel":"orderbook-eth","Nonce":19662,"Data":{"OrderType":"LimitBid","OrderGuid":"dded3307-e583-4ee3-a736-07a0d6ac1551"},"Time":1649023830385,"Event":"OrderCanceled"}
1649023830.494656: {"Channel":"orderbook-eth","Nonce":19663,"Data":{"OrderType":"LimitBid","OrderGuid":"7e7ff48f-6e78-4557-bda9-178e736108cc"},"Time":1649023830385,"Event":"OrderCanceled"}
1649023830.4969752: {"Channel":"orderbook-eth","Nonce":19664,"Data":{"OrderType":"LimitOffer","OrderGuid":"75503b2b-2c10-4f8a-b9fd-2dc61379ad2e"},"Time":1649023830385,"Event":"OrderCanceled"}
1649023830.501516: {"Channel":"orderbook-matic","Nonce":5974,"Data":{"OrderType":"LimitOffer","OrderGuid":"e2ff5a44-4e87-441f-8b2f-ccc40cad4b60"},"Time":1649023830401,"Event":"OrderCanceled"}
1649023830.5288079: {"Channel":"orderbook-eth","Nonce":19665,"Data":{"OrderType":"LimitBid","OrderGuid":"3b80b9b0-93d4-4bd3-baef-0ec1f3d04f81","Price":{"aud":4726.9,"usd":3523.43,"nzd":5087.08,"sgd":4790.71},"Volume":15.0},"Time":1649023830432,"Event":"NewOrder"}
1649023830.540163: {"Channel":"orderbook-eth","Nonce":19666,"Data":{"OrderType":"LimitOffer","OrderGuid":"c8e5994d-92ae-4343-bf29-c7f2242c89c5","Price":{"aud":4734.1,"usd":3564.3,"nzd":5156.98,"sgd":4827.76},"Volume":15.0},"Time":1649023830432,"Event":"NewOrder"}
1649023830.540295: {"Channel":"orderbook-matic","Nonce":5975,"Data":{"OrderType":"LimitOffer","OrderGuid":"3b5770c3-7c45-44c9-8572-628f4e8d353b","Price":{"aud":2.2735,"usd":1.71172,"nzd":2.47658,"sgd":2.31848},"Volume":5583.0},"Time":1649023830432,"Event":"NewOrder"}
1649023830.544209: {"Channel":"orderbook-matic","Nonce":5976,"Data":{"OrderType":"LimitOffer","OrderGuid":"ac8fc01f-28b1-4be8-b564-ea18df4448eb","Price":{"aud":2.275,"usd":1.71285,"nzd":2.47822,"sgd":2.32001},"Volume":5583.0},"Time":1649023830448,"Event":"NewOrder"}
1649023830.544271: {"Channel":"orderbook-eth","Nonce":19667,"Data":{"OrderType":"LimitOffer","OrderGuid":"0a85008f-beb5-4847-9dbc-ba134a59aa39","Price":{"aud":4737.1,"usd":3566.56,"nzd":5160.24,"sgd":4830.82},"Volume":15.0},"Time":1649023830448,"Event":"NewOrder"}
1649023830.549839: {"Channel":"orderbook-eth","Nonce":19668,"Data":{"OrderType":"LimitBid","OrderGuid":"3072078c-00f3-4f59-9a60-74907710c5f6"},"Time":1649023830448,"Event":"OrderCanceled"}
1649023830.638962: {"Channel":"orderbook-eth","Nonce":19669,"Data":{"OrderType":"LimitBid","OrderGuid":"5dd6bac5-a033-4e0c-b95a-a6f2cdde258d","Price":{"aud":4703.99,"usd":3506.35,"nzd":5062.43,"sgd":4767.49},"Volume":0.31595963},"Time":1649023830541,"Event":"NewOrder"}
1649023830.639085: {"Channel":"orderbook-eth","Nonce":19670,"Data":{"OrderType":"LimitBid","OrderGuid":"c00b7d77-2c2c-4dfb-b5e8-85ad9496fd09","Price":{"aud":4723.9,"usd":3521.19,"nzd":5083.86,"sgd":4787.67},"Volume":15.0},"Time":1649023830541,"Event":"NewOrder"}
1649023830.695861: {"Channel":"orderbook-matic","Nonce":5977,"Data":{"OrderType":"LimitOffer","OrderGuid":"995f3c3e-82a1-43cb-ac85-9d80ebac0e84"},"Time":1649023830588,"Event":"OrderCanceled"}
1649023830.706881: {"Channel":"orderbook-eth","Nonce":19671,"Data":{"OrderType":"LimitOffer","OrderGuid":"0a85008f-beb5-4847-9dbc-ba134a59aa39"},"Time":1649023830604,"Event":"OrderCanceled"}
1649023830.706986: {"Channel":"orderbook-eth","Nonce":19672,"Data":{"OrderType":"LimitBid","OrderGuid":"c00b7d77-2c2c-4dfb-b5e8-85ad9496fd09"},"Time":1649023830604,"Event":"OrderCanceled"}
1649023830.7121122: {"Channel":"orderbook-eth","Nonce":19673,"Data":{"OrderType":"LimitBid","OrderGuid":"3b80b9b0-93d4-4bd3-baef-0ec1f3d04f81"},"Time":1649023830604,"Event":"OrderCanceled"}
1649023830.745885: {"Channel":"orderbook-matic","Nonce":5978,"Data":{"OrderType":"LimitOffer","OrderGuid":"29e83b53-2c19-4e1d-a244-cb625b6cd902","Price":{"aud":2.27297,"usd":1.71132,"nzd":2.47601,"sgd":2.31794},"Volume":5589.31808},"Time":1649023830635,"Event":"NewOrder"}
1649023830.803154: {"Channel":"orderbook-eth","Nonce":19674,"Data":{"OrderType":"LimitOffer","OrderGuid":"c8e5994d-92ae-4343-bf29-c7f2242c89c5"},"Time":1649023830698,"Event":"OrderCanceled"}
1649023830.803256: {"Channel":"orderbook-eth","Nonce":19675,"Data":{"OrderType":"LimitBid","OrderGuid":"804898e0-3feb-40a8-86de-5935db8e5253","Price":{"aud":4724.0,"usd":3521.26,"nzd":5083.96,"sgd":4787.77},"Volume":15.0},"Time":1649023830698,"Event":"NewOrder"}
1649023830.878976: {"Channel":"orderbook-eth","Nonce":19676,"Data":{"OrderType":"LimitBid","OrderGuid":"b4bbb9e5-57e1-45ae-b919-0a8efd73dc9c"},"Time":1649023830776,"Event":"OrderCanceled"}
1649023830.914253: {"Channel":"orderbook-eth","Nonce":19677,"Data":{"OrderType":"LimitOffer","OrderGuid":"fa5decd8-da71-4e52-9a0c-71356e720ee4","Price":{"aud":4734.2,"usd":3564.38,"nzd":5157.09,"sgd":4827.87},"Volume":15.0},"Time":1649023830807,"Event":"NewOrder"}
1649023830.918622: {"Channel":"orderbook-eth","Nonce":19678,"Data":{"OrderType":"LimitOffer","OrderGuid":"bb7aff2c-6ba6-43c4-b606-69418680e0c6","Price":{"aud":4737.2,"usd":3566.64,"nzd":5160.35,"sgd":4830.92},"Volume":15.0},"Time":1649023830807,"Event":"NewOrder"}
1649023830.9374678: {"Channel":"orderbook-eth","Nonce":19679,"Data":{"OrderType":"LimitBid","OrderGuid":"0be9cbde-28bb-48b0-bfaa-ec9f130f72d1","Price":{"aud":4678.18,"usd":3504.05,"nzd":5096.06,"sgd":4769.91},"Volume":0.56082453},"Time":1649023830838,"Event":"NewOrder"}
1649023830.953731: {"Channel":"orderbook-eth","Nonce":19680,"Data":{"OrderType":"LimitBid","OrderGuid":"80ddeafb-ed63-4a23-ad8d-272cc4835472","Price":{"aud":4727.0,"usd":3523.5,"nzd":5087.19,"sgd":4790.81},"Volume":15.0},"Time":1649023830855,"Event":"NewOrder"}
1649023830.968719: {"Channel":"orderbook-eth","Nonce":19681,"Data":{"OrderType":"LimitOffer","OrderGuid":"fa5decd8-da71-4e52-9a0c-71356e720ee4"},"Time":1649023830871,"Event":"OrderCanceled"}
1649023830.968823: {"Channel":"orderbook-eth","Nonce":19682,"Data":{"OrderType":"LimitBid","OrderGuid":"804898e0-3feb-40a8-86de-5935db8e5253"},"Time":1649023830871,"Event":"OrderCanceled"}
1649023830.972967: {"Channel":"orderbook-eth","Nonce":19683,"Data":{"OrderType":"LimitOffer","OrderGuid":"bb7aff2c-6ba6-43c4-b606-69418680e0c6"},"Time":1649023830871,"Event":"OrderCanceled"}
1649023830.994516: {"Channel":"orderbook-eth","Nonce":19684,"Data":{"OrderType":"LimitBid","OrderGuid":"77e45a65-1b03-4c6f-bceb-3e50fef4ad3a","Price":{"aud":4665.82,"usd":3477.9,"nzd":5021.35,"sgd":4728.8},"Volume":0.19519557},"Time":1649023830886,"Event":"NewOrder"}
1649023831.00493: {"Channel":"orderbook-dot","Nonce":5030,"Data":{"OrderType":"LimitBid","OrderGuid":"453d8e08-3c15-45c3-ba7b-b8470d2e1fdb"},"Time":1649023830902,"Event":"OrderCanceled"}
1649023831.0049999: {"Channel":"orderbook-eth","Nonce":19685,"Data":{"OrderType":"LimitBid","OrderGuid":"80ddeafb-ed63-4a23-ad8d-272cc4835472"},"Time":1649023830902,"Event":"OrderCanceled"}
1649023831.011509: {"Channel":"orderbook-eth","Nonce":19686,"Data":{"OrderType":"LimitOffer","OrderGuid":"bf75101d-0f63-4f05-b2bc-a5e0f2cfa9ef","Price":{"aud":4734.3,"usd":3564.45,"nzd":5157.19,"sgd":4827.97},"Volume":15.0},"Time":1649023830902,"Event":"NewOrder"}
1649023831.0156941: {"Channel":"orderbook-eth","Nonce":19687,"Data":{"OrderType":"LimitOffer","OrderGuid":"481a2f32-6c42-4410-aa44-8676881bcb96","Price":{"aud":4737.3,"usd":3566.71,"nzd":5160.46,"sgd":4831.03},"Volume":15.0},"Time":1649023830918,"Event":"NewOrder"}
1649023831.036321: {"Channel":"orderbook-eth","Nonce":19688,"Data":{"OrderType":"LimitBid","OrderGuid":"8c4ac525-e9ac-4c25-8c52-68a273da4fb9","Price":{"aud":4727.1,"usd":3523.58,"nzd":5087.3,"sgd":4790.91},"Volume":15.0},"Time":1649023830933,"Event":"NewOrder"}
1649023831.0404449: {"Channel":"orderbook-eth","Nonce":19689,"Data":{"OrderType":"LimitBid","OrderGuid":"80b2b00b-9fdb-4571-a6f0-2b2fb8acab83","Price":{"aud":4724.1,"usd":3521.34,"nzd":5084.07,"sgd":4787.87},"Volume":15.0},"Time":1649023830933,"Event":"NewOrder"}
1649023831.060371: {"Channel":"orderbook-eth","Nonce":19690,"Data":{"OrderType":"LimitBid","OrderGuid":"36abe9a7-4615-4613-9390-0ccf03f96ba2"},"Time":1649023830949,"Event":"OrderCanceled"}
1649023831.640235: {"Channel":"orderbook-eth","Nonce":19691,"Data":{"OrderType":"LimitBid","OrderGuid":"5dd6bac5-a033-4e0c-b95a-a6f2cdde258d"},"Time":1649023831530,"Event":"OrderCanceled"}
1649023831.690617: {"Channel":"orderbook-eth","Nonce":19692,"Data":{"OrderType":"LimitBid","OrderGuid":"2519648f-16fc-4692-9dde-02e9700a8b0d","Price":{"aud":4704.0,"usd":3506.36,"nzd":5062.44,"sgd":4767.5},"Volume":0.34227544},"Time":1649023831592,"Event":"NewOrder"}
1649023831.7359731: {"Channel":"orderbook-matic","Nonce":5979,"Data":{"OrderType":"LimitOffer","OrderGuid":"29e83b53-2c19-4e1d-a244-cb625b6cd902"},"Time":1649023831639,"Event":"OrderCanceled"}
1649023831.797819: {"Channel":"orderbook-matic","Nonce":5980,"Data":{"OrderType":"LimitOffer","OrderGuid":"a20e5959-0071-4d5b-bb8b-539cb6133ab4","Price":{"aud":2.27296,"usd":1.71131,"nzd":2.476,"sgd":2.31793},"Volume":5616.92995},"Time":1649023831687,"Event":"NewOrder"}
1649023831.966413: {"Channel":"orderbook-eth","Nonce":19693,"Data":{"OrderType":"LimitOffer","OrderGuid":"98c7ab46-61fe-4099-b4f6-5ea9b2f71d39"},"Time":1649023831859,"Event":"OrderCanceled"}
1649023831.973577: {"Channel":"orderbook-eth","Nonce":19694,"Data":{"OrderType":"LimitBid","OrderGuid":"0be9cbde-28bb-48b0-bfaa-ec9f130f72d1"},"Time":1649023831875,"Event":"OrderCanceled"}
1649023832.018327: {"Channel":"orderbook-eth","Nonce":19695,"Data":{"OrderType":"LimitOffer","OrderGuid":"cfb48f5a-5cb4-468b-a6fc-a36ccebddffa","Price":{"aud":4793.99,"usd":3573.44,"nzd":5196.98,"sgd":4863.81},"Volume":0.51617638},"Time":1649023831922,"Event":"NewOrder"}
1649023832.0320861: {"Channel":"orderbook-eth","Nonce":19696,"Data":{"OrderType":"LimitBid","OrderGuid":"ffe796e9-a273-4e35-92ea-38d7aa30e391","Price":{"aud":4678.19,"usd":3504.05,"nzd":5096.07,"sgd":4769.92},"Volume":0.42705796},"Time":1649023831922,"Event":"NewOrder"}
1649023832.165018: {"Channel":"orderbook-eth","Nonce":19697,"Data":{"OrderType":"LimitBid","OrderGuid":"22e3d921-f584-4d67-8e4e-56117af1ee87"},"Time":1649023832062,"Event":"OrderCanceled"}
1649023832.216249: {"Channel":"orderbook-eth","Nonce":19698,"Data":{"OrderType":"LimitBid","OrderGuid":"5ba9d983-520b-4740-a32e-8d42cacb6bf6","Price":{"aud":4697.97,"usd":3519.88,"nzd":5086.99,"sgd":4790.92},"Volume":3.10841961},"Time":1649023832109,"Event":"NewOrder"}
1649023832.2599502: {"Channel":"orderbook-bch","Nonce":8387,"Data":{"OrderType":"LimitOffer","OrderGuid":"d96f892f-78c2-4a45-8f3f-a57faf6ae173"},"Time":1649023832156,"Event":"OrderCanceled"}
1649023832.2622368: {"Channel":"orderbook-bch","Nonce":8388,"Data":{"OrderType":"LimitBid","OrderGuid":"70ee4b46-25bd-4293-82d7-f9f4ec460edc"},"Time":1649023832156,"Event":"OrderCanceled"}
1649023832.27009: {"Channel":"orderbook-eth","Nonce":19699,"Data":{"OrderType":"LimitOffer","OrderGuid":"bf75101d-0f63-4f05-b2bc-a5e0f2cfa9ef"},"Time":1649023832172,"Event":"OrderCanceled"}
1649023832.27013: {"Channel":"orderbook-bch","Nonce":8389,"Data":{"OrderType":"LimitBid","OrderGuid":"55713c8c-e760-4a21-9443-512e2cfc22db"},"Time":1649023832172,"Event":"OrderCanceled"}
1649023832.2710578: {"Channel":"orderbook-bch","Nonce":8390,"Data":{"OrderType":"LimitOffer","OrderGuid":"4e92afe0-d65e-441b-b7f2-b6c28daf2f78"},"Time":1649023832172,"Event":"OrderCanceled"}
1649023832.278731: {"Channel":"orderbook-eth","Nonce":19700,"Data":{"OrderType":"LimitOffer","OrderGuid":"481a2f32-6c42-4410-aa44-8676881bcb96"},"Time":1649023832172,"Event":"OrderCanceled"}
1649023832.3113759: {"Channel":"orderbook-bch","Nonce":8391,"Data":{"OrderType":"LimitOffer","OrderGuid":"be797ceb-49af-4e8c-8398-78ae66702d58","Price":{"aud":506.7,"usd":381.5,"nzd":551.97,"sgd":516.73},"Volume":6.0},"Time":1649023832203,"Event":"NewOrder"}
1649023832.311737: {"Channel":"orderbook-eth","Nonce":19701,"Data":{"OrderType":"LimitOffer","OrderGuid":"5210f521-4666-4462-8367-fb0b33f293d5"},"Time":1649023832203,"Event":"OrderCanceled"}
1649023832.3225322: {"Channel":"orderbook-bch","Nonce":8392,"Data":{"OrderType":"LimitBid","OrderGuid":"58aa6b23-2745-4324-9b80-3bec0e97c667","Price":{"aud":503.9,"usd":375.6,"nzd":542.29,"sgd":510.7},"Volume":6.0},"Time":1649023832219,"Event":"NewOrder"}
1649023832.323204: {"Channel":"orderbook-bch","Nonce":8393,"Data":{"OrderType":"LimitOffer","OrderGuid":"c3c04d69-298a-466e-a0a4-bde32e170bd9","Price":{"aud":507.4,"usd":382.03,"nzd":552.73,"sgd":517.44},"Volume":6.0},"Time":1649023832219,"Event":"NewOrder"}
1649023832.327083: {"Channel":"orderbook-bch","Nonce":8394,"Data":{"OrderType":"LimitBid","OrderGuid":"2e4b7c84-c0a7-4d1c-ac3e-7cd2c1098a5d","Price":{"aud":503.2,"usd":375.08,"nzd":541.54,"sgd":509.99},"Volume":6.0},"Time":1649023832219,"Event":"NewOrder"}
1649023832.3276658: {"Channel":"orderbook-eth","Nonce":19702,"Data":{"OrderType":"LimitOffer","OrderGuid":"7c6b0cbd-ae08-4a36-954f-e05ca39b51d4","Price":{"aud":4737.29,"usd":3566.7,"nzd":5160.45,"sgd":4831.02},"Volume":4.47331033},"Time":1649023832219,"Event":"NewOrder"}
1649023832.3543339: {"Channel":"orderbook-eth","Nonce":19703,"Data":{"OrderType":"LimitOffer","OrderGuid":"726fa243-7ab9-48a6-893a-069b8b318abb","Price":{"aud":4733.8,"usd":3564.08,"nzd":5156.65,"sgd":4827.46},"Volume":15.0},"Time":1649023832250,"Event":"NewOrder"}
1649023832.356857: {"Channel":"orderbook-eth","Nonce":19704,"Data":{"OrderType":"LimitBid","OrderGuid":"8c4ac525-e9ac-4c25-8c52-68a273da4fb9"},"Time":1649023832250,"Event":"OrderCanceled"}
1649023832.36148: {"Channel":"orderbook-eth","Nonce":19705,"Data":{"OrderType":"LimitBid","OrderGuid":"80b2b00b-9fdb-4571-a6f0-2b2fb8acab83"},"Time":1649023832250,"Event":"OrderCanceled"}
1649023832.364749: {"Channel":"orderbook-eth","Nonce":19706,"Data":{"OrderType":"LimitOffer","OrderGuid":"85767048-f58f-4144-911d-0d27d809a550","Price":{"aud":4736.8,"usd":3566.34,"nzd":5159.92,"sgd":4830.52},"Volume":15.0},"Time":1649023832265,"Event":"NewOrder"}
1649023832.381214: {"Channel":"orderbook-matic","Nonce":5981,"Data":{"OrderType":"LimitBid","OrderGuid":"e5275220-9b6d-44b2-854d-d485aef2b05f"},"Time":1649023832281,"Event":"OrderCanceled"}
1649023832.381283: {"Channel":"orderbook-matic","Nonce":5982,"Data":{"OrderType":"LimitOffer","OrderGuid":"3b5770c3-7c45-44c9-8572-628f4e8d353b"},"Time":1649023832281,"Event":"OrderCanceled"}
1649023832.3852649: {"Channel":"orderbook-matic","Nonce":5983,"Data":{"OrderType":"LimitOffer","OrderGuid":"ac8fc01f-28b1-4be8-b564-ea18df4448eb"},"Time":1649023832281,"Event":"OrderCanceled"}
1649023832.429365: {"Channel":"orderbook-matic","Nonce":5984,"Data":{"OrderType":"LimitBid","OrderGuid":"313e1cfe-d3fc-4bb8-bb74-2abe5588389f"},"Time":1649023832328,"Event":"OrderCanceled"}
1649023832.43839: {"Channel":"orderbook-matic","Nonce":5985,"Data":{"OrderType":"LimitOffer","OrderGuid":"e80cba95-2605-4184-84f2-cc87969f4961","Price":{"aud":2.273,"usd":1.71134,"nzd":2.47604,"sgd":2.31797},"Volume":5583.0},"Time":1649023832328,"Event":"NewOrder"}
1649023832.4567208: {"Channel":"orderbook-eth","Nonce":19707,"Data":{"OrderType":"LimitBid","OrderGuid":"57fccd64-1c1f-497e-a092-7b67f89f7342","Price":{"aud":4723.6,"usd":3520.97,"nzd":5083.53,"sgd":4787.36},"Volume":15.0},"Time":1649023832359,"Event":"NewOrder"}
1649023832.466296: {"Channel":"orderbook-matic","Nonce":5986,"Data":{"OrderType":"LimitOffer","OrderGuid":"3441c245-a2a9-4abe-9781-73fbd65e17b8","Price":{"aud":2.2745,"usd":1.71247,"nzd":2.47767,"sgd":2.3195},"Volume":5583.0},"Time":1649023832359,"Event":"NewOrder"}
1649023832.481045: {"Channel":"orderbook-matic","Nonce":5987,"Data":{"OrderType":"LimitBid","OrderGuid":"8d229cc5-bd05-4a08-8871-17b0d6b64e54","Price":{"aud":2.262,"usd":1.68609,"nzd":2.43436,"sgd":2.29253},"Volume":5583.0},"Time":1649023832375,"Event":"NewOrder"}
1649023832.5068228: {"Channel":"orderbook-matic","Nonce":5988,"Data":{"OrderType":"LimitBid","OrderGuid":"071bb1a8-df15-4c1b-8c4b-6b4bc046a63a","Price":{"aud":2.2605,"usd":1.68497,"nzd":2.43275,"sgd":2.29101},"Volume":5583.0},"Time":1649023832406,"Event":"NewOrder"}
1649023832.539186: {"Channel":"orderbook-eth","Nonce":19708,"Data":{"OrderType":"LimitOffer","OrderGuid":"726fa243-7ab9-48a6-893a-069b8b318abb"},"Time":1649023832437,"Event":"OrderCanceled"}
1649023832.54799: {"Channel":"orderbook-eth","Nonce":19709,"Data":{"OrderType":"LimitOffer","OrderGuid":"85767048-f58f-4144-911d-0d27d809a550"},"Time":1649023832437,"Event":"OrderCanceled"}
1649023832.548092: {"Channel":"orderbook-bch","Nonce":8395,"Data":{"OrderType":"LimitOffer","OrderGuid":"be797ceb-49af-4e8c-8398-78ae66702d58"},"Time":1649023832437,"Event":"OrderCanceled"}
1649023832.5592241: {"Channel":"orderbook-eth","Nonce":19710,"Data":{"OrderType":"LimitBid","OrderGuid":"25837348-26ed-48c8-8ae9-b0971b194fcb","Price":{"aud":4726.6,"usd":3523.2,"nzd":5086.76,"sgd":4790.4},"Volume":15.0},"Time":1649023832453,"Event":"NewOrder"}
1649023832.562485: {"Channel":"orderbook-bch","Nonce":8396,"Data":{"OrderType":"LimitOffer","OrderGuid":"c3c85444-c7fb-42dc-9287-c7f8b7b7f61c"},"Time":1649023832453,"Event":"OrderCanceled"}
1649023832.5625868: {"Channel":"orderbook-eth","Nonce":19711,"Data":{"OrderType":"LimitBid","OrderGuid":"57fccd64-1c1f-497e-a092-7b67f89f7342"},"Time":1649023832453,"Event":"OrderCanceled"}
1649023832.566889: {"Channel":"orderbook-bch","Nonce":8397,"Data":{"OrderType":"LimitOffer","OrderGuid":"c3c04d69-298a-466e-a0a4-bde32e170bd9"},"Time":1649023832469,"Event":"OrderCanceled"}
1649023832.566998: {"Channel":"orderbook-bch","Nonce":8398,"Data":{"OrderType":"LimitBid","OrderGuid":"2e4b7c84-c0a7-4d1c-ac3e-7cd2c1098a5d"},"Time":1649023832469,"Event":"OrderCanceled"}
1649023832.576279: {"Channel":"orderbook-eth","Nonce":19712,"Data":{"OrderType":"LimitOffer","OrderGuid":"b7cfc46c-02d3-4868-ab9f-d748c3b4edf2","Price":{"aud":4733.9,"usd":3564.15,"nzd":5156.76,"sgd":4827.56},"Volume":15.0},"Time":1649023832469,"Event":"NewOrder"}
1649023832.604393: {"Channel":"orderbook-bch","Nonce":8399,"Data":{"OrderType":"LimitOffer","OrderGuid":"a1ab8a20-e903-4a40-b3bd-e412ee57feef","Price":{"aud":510.67,"usd":384.49,"nzd":556.29,"sgd":520.78},"Volume":21.20858658},"Time":1649023832500,"Event":"NewOrder"}
1649023832.6085062: {"Channel":"orderbook-bch","Nonce":8400,"Data":{"OrderType":"LimitOffer","OrderGuid":"70eed5bd-9be0-4dde-ab27-3aff26a71ab9"},"Time":1649023832500,"Event":"OrderCanceled"}
1649023832.624106: {"Channel":"orderbook-eth","Nonce":19713,"Data":{"OrderType":"LimitBid","OrderGuid":"25837348-26ed-48c8-8ae9-b0971b194fcb"},"Time":1649023832515,"Event":"OrderCanceled"}
1649023832.634961: {"Channel":"orderbook-bch","Nonce":8401,"Data":{"OrderType":"LimitOffer","OrderGuid":"4894596a-2eee-42d8-86ef-7fb4f2671504","Price":{"aud":506.8,"usd":381.57,"nzd":552.07,"sgd":516.83},"Volume":6.0},"Time":1649023832531,"Event":"NewOrder"}
1649023832.6394072: {"Channel":"orderbook-bch","Nonce":8402,"Data":{"OrderType":"LimitOffer","OrderGuid":"1d4fe14a-0db0-4f3d-8ab8-030498f43430","Price":{"aud":507.5,"usd":382.1,"nzd":552.84,"sgd":517.55},"Volume":6.0},"Time":1649023832531,"Event":"NewOrder"}
1649023832.648159: {"Channel":"orderbook-bch","Nonce":8403,"Data":{"OrderType":"LimitBid","OrderGuid":"58aa6b23-2745-4324-9b80-3bec0e97c667"},"Time":1649023832547,"Event":"OrderCanceled"}
1649023832.6779258: {"Channel":"orderbook-bch","Nonce":8404,"Data":{"OrderType":"LimitBid","OrderGuid":"dcb5bcf3-01b6-4d1b-86d2-50dbc03d3400","Price":{"aud":504.1,"usd":375.75,"nzd":542.51,"sgd":510.9},"Volume":6.0},"Time":1649023832578,"Event":"NewOrder"}
1649023832.681639: {"Channel":"orderbook-bch","Nonce":8405,"Data":{"OrderType":"LimitBid","OrderGuid":"927b4170-e3b3-4885-922f-36298d4c3b73","Price":{"aud":503.4,"usd":375.23,"nzd":541.75,"sgd":510.19},"Volume":6.0},"Time":1649023832578,"Event":"NewOrder"}
1649023832.698739: {"Channel":"orderbook-eth","Nonce":19714,"Data":{"OrderType":"LimitOffer","OrderGuid":"2ae1f6c4-5f83-46ae-b424-64c57c42dbe5","Price":{"aud":4736.9,"usd":3566.41,"nzd":5160.03,"sgd":4830.62},"Volume":15.0},"Time":1649023832594,"Event":"NewOrder"}
1649023832.701044: {"Channel":"orderbook-eth","Nonce":19715,"Data":{"OrderType":"LimitBid","OrderGuid":"93a035fa-555b-46a3-a3b1-5d5fb2adb3fd","Price":{"aud":4723.7,"usd":3521.04,"nzd":5083.64,"sgd":4787.46},"Volume":15.0},"Time":1649023832594,"Event":"NewOrder"}
1649023832.7043: {"Channel":"orderbook-bch","Nonce":8406,"Data":{"OrderType":"LimitOffer","OrderGuid":"21888c77-6639-454b-b53e-864a7fedc0de","Price":{"aud":510.62,"usd":384.45,"nzd":556.24,"sgd":520.73},"Volume":39.74331},"Time":1649023832594,"Event":"NewOrder"}
1649023832.7294521: {"Channel":"orderbook-eth","Nonce":19716,"Data":{"OrderType":"LimitBid","OrderGuid":"96f1fd9a-340a-4e80-80c1-66ca61be21f6","Price":{"aud":4726.7,"usd":3523.28,"nzd":5086.87,"sgd":4790.51},"Volume":15.0},"Time":1649023832625,"Event":"NewOrder"}
1649023832.7690291: {"Channel":"orderbook-bch","Nonce":8407,"Data":{"OrderType":"LimitOffer","OrderGuid":"c95fa547-d3f0-4bde-8b1e-93bbbf2feec8","Price":{"aud":510.61,"usd":384.44,"nzd":556.23,"sgd":520.72},"Volume":21.20858658},"Time":1649023832672,"Event":"NewOrder"}
1649023832.774291: {"Channel":"orderbook-bch","Nonce":8408,"Data":{"OrderType":"LimitOffer","OrderGuid":"a1ab8a20-e903-4a40-b3bd-e412ee57feef"},"Time":1649023832672,"Event":"OrderCanceled"}
1649023832.7916071: {"Channel":"orderbook-eth","Nonce":19717,"Data":{"OrderType":"LimitBid","OrderGuid":"2519648f-16fc-4692-9dde-02e9700a8b0d"},"Time":1649023832687,"Event":"OrderCanceled"}
1649023832.807917: {"Channel":"orderbook-eth","Nonce":19718,"Data":{"OrderType":"LimitBid","OrderGuid":"5e76a2df-4bac-4fff-b42d-7259133f7d4c","Price":{"aud":4668.81,"usd":3480.13,"nzd":5024.57,"sgd":4731.83},"Volume":0.19518981},"Time":1649023832703,"Event":"NewOrder"}
1649023832.834993: {"Channel":"orderbook-eth","Nonce":19719,"Data":{"OrderType":"LimitBid","OrderGuid":"1f52d8ef-e610-4e1e-846d-8b399dbfbb0c","Price":{"aud":4704.01,"usd":3506.36,"nzd":5062.45,"sgd":4767.51},"Volume":0.35904149},"Time":1649023832734,"Event":"NewOrder"}
1649023832.839479: {"Channel":"orderbook-matic","Nonce":5989,"Data":{"OrderType":"LimitBid","OrderGuid":"a4ea67d4-c57a-4f3a-8d66-86ed2b1eb44c"},"Time":1649023832734,"Event":"OrderCanceled"}
1649023832.8924642: {"Channel":"orderbook-matic","Nonce":5990,"Data":{"OrderType":"LimitBid","OrderGuid":"e6602a77-7562-4578-96d8-402936461555","Price":{"aud":2.26252,"usd":1.68648,"nzd":2.43492,"sgd":2.29306},"Volume":5574.37553},"Time":1649023832781,"Event":"NewOrder"}
1649023832.908569: {"Channel":"orderbook-eth","Nonce":19720,"Data":{"OrderType":"LimitBid","OrderGuid":"77e45a65-1b03-4c6f-bceb-3e50fef4ad3a"},"Time":1649023832797,"Event":"OrderCanceled"}
1649023833.0608692: {"Channel":"orderbook-bch","Nonce":8409,"Data":{"OrderType":"LimitOffer","OrderGuid":"9a55a48a-daf5-4474-a571-1dc1340fe18a"},"Time":1649023832953,"Event":"OrderCanceled"}
1649023833.091917: {"Channel":"orderbook-eth","Nonce":19721,"Data":{"OrderType":"LimitBid","OrderGuid":"ffe796e9-a273-4e35-92ea-38d7aa30e391"},"Time":1649023832984,"Event":"OrderCanceled"}
1649023833.177259: {"Channel":"orderbook-eth","Nonce":19722,"Data":{"OrderType":"LimitBid","OrderGuid":"86a51ba0-fba6-467f-af1e-dbdc5eed5adf","Price":{"aud":4678.2,"usd":3504.06,"nzd":5096.08,"sgd":4769.93},"Volume":0.59467258},"Time":1649023833078,"Event":"NewOrder"}
1649023833.199536: {"Channel":"orderbook-eth","Nonce":19723,"Data":{"OrderType":"LimitBid","OrderGuid":"f3126780-c4f1-4732-99be-37e083f1c5cc"},"Time":1649023833094,"Event":"OrderCanceled"}
1649023833.239409: {"Channel":"orderbook-bch","Nonce":8410,"Data":{"OrderType":"LimitOffer","OrderGuid":"420e8f4a-cbf3-4ba7-a7ee-655aef251633","Price":{"aud":510.62,"usd":384.45,"nzd":556.24,"sgd":520.73},"Volume":2.93},"Time":1649023833140,"Event":"NewOrder"}
1649023833.2820108: {"Channel":"orderbook-eth","Nonce":19724,"Data":{"OrderType":"LimitBid","OrderGuid":"c38369c8-1895-446b-b5a7-0150be37e845","Price":{"aud":4665.82,"usd":3477.9,"nzd":5021.35,"sgd":4728.8},"Volume":0.19518981},"Time":1649023833172,"Event":"NewOrder"}
1649023833.301444: {"Channel":"orderbook-bch","Nonce":8411,"Data":{"OrderType":"LimitOffer","OrderGuid":"e89a081c-41ca-4370-a7ed-eaeadbe6feb4","Price":{"aud":507.79,"usd":382.32,"nzd":553.15,"sgd":517.84},"Volume":1.09288254},"Time":1649023833188,"Event":"NewOrder"}
1649023833.33858: {"Channel":"orderbook-eth","Nonce":19725,"Data":{"OrderType":"LimitOffer","OrderGuid":"cfb48f5a-5cb4-468b-a6fc-a36ccebddffa"},"Time":1649023833235,"Event":"OrderCanceled"}
1649023833.355189: {"Channel":"orderbook-bch","Nonce":8412,"Data":{"OrderType":"LimitOffer","OrderGuid":"4894596a-2eee-42d8-86ef-7fb4f2671504"},"Time":1649023833251,"Event":"OrderCanceled"}
1649023833.3814: {"Channel":"orderbook-bch","Nonce":8413,"Data":{"OrderType":"LimitOffer","OrderGuid":"1d4fe14a-0db0-4f3d-8ab8-030498f43430"},"Time":1649023833282,"Event":"OrderCanceled"}
1649023833.423786: {"Channel":"orderbook-bch","Nonce":8414,"Data":{"OrderType":"LimitOffer","OrderGuid":"10f0a05b-3914-4ac6-936a-26ae26969212","Price":{"aud":506.7,"usd":381.5,"nzd":551.97,"sgd":516.73},"Volume":6.0},"Time":1649023833314,"Event":"NewOrder"}
1649023833.428045: {"Channel":"orderbook-bch","Nonce":8415,"Data":{"OrderType":"LimitOffer","OrderGuid":"8d51ff15-c587-4f3e-8113-9f5d1cf837db"},"Time":1649023833329,"Event":"OrderCanceled"}
1649023833.431303: {"Channel":"orderbook-eth","Nonce":19726,"Data":{"OrderType":"LimitOffer","OrderGuid":"ee59921b-5c64-46b6-a82f-ef0e357c608d","Price":{"aud":4794.65,"usd":3573.93,"nzd":5197.69,"sgd":4864.48},"Volume":0.53118054},"Time":1649023833329,"Event":"NewOrder"}
1649023833.4367192: {"Channel":"orderbook-bch","Nonce":8416,"Data":{"OrderType":"LimitBid","OrderGuid":"927b4170-e3b3-4885-922f-36298d4c3b73"},"Time":1649023833329,"Event":"OrderCanceled"}
1649023833.4459531: {"Channel":"orderbook-bch","Nonce":8417,"Data":{"OrderType":"LimitOffer","OrderGuid":"11c1aea0-5b9a-4ea6-9031-578c8a0fb7d7","Price":{"aud":507.4,"usd":382.03,"nzd":552.73,"sgd":517.44},"Volume":6.0},"Time":1649023833345,"Event":"NewOrder"}
1649023833.5185978: {"Channel":"orderbook-bch","Nonce":8418,"Data":{"OrderType":"LimitBid","OrderGuid":"dcb5bcf3-01b6-4d1b-86d2-50dbc03d3400"},"Time":1649023833407,"Event":"OrderCanceled"}
1649023833.5557: {"Channel":"orderbook-bch","Nonce":8419,"Data":{"OrderType":"LimitBid","OrderGuid":"e960650d-095c-4907-bdde-02e3a8cdd0c6","Price":{"aud":503.9,"usd":375.6,"nzd":542.29,"sgd":510.7},"Volume":6.0},"Time":1649023833455,"Event":"NewOrder"}
1649023833.560012: {"Channel":"orderbook-bch","Nonce":8420,"Data":{"OrderType":"LimitBid","OrderGuid":"a4ee3fe0-f7aa-4fe6-b613-e52cbb7dcc36","Price":{"aud":503.2,"usd":375.08,"nzd":541.54,"sgd":509.99},"Volume":6.0},"Time":1649023833455,"Event":"NewOrder"}
1649023833.577661: {"Channel":"orderbook-eth","Nonce":19727,"Data":{"OrderType":"LimitOffer","OrderGuid":"2ae1f6c4-5f83-46ae-b424-64c57c42dbe5"},"Time":1649023833471,"Event":"OrderCanceled"}
1649023833.678408: {"Channel":"orderbook-eth","Nonce":19728,"Data":{"OrderType":"LimitBid","OrderGuid":"96f1fd9a-340a-4e80-80c1-66ca61be21f6"},"Time":1649023833580,"Event":"OrderCanceled"}
1649023833.687063: {"Channel":"orderbook-eth","Nonce":19729,"Data":{"OrderType":"LimitBid","OrderGuid":"93a035fa-555b-46a3-a3b1-5d5fb2adb3fd"},"Time":1649023833580,"Event":"OrderCanceled"}
1649023833.6890738: {"Channel":"orderbook-eth","Nonce":19730,"Data":{"OrderType":"LimitOffer","OrderGuid":"b7cfc46c-02d3-4868-ab9f-d748c3b4edf2"},"Time":1649023833580,"Event":"OrderCanceled"}
1649023833.709352: {"Channel":"orderbook-matic","Nonce":5991,"Data":{"OrderType":"LimitOffer","OrderGuid":"e80cba95-2605-4184-84f2-cc87969f4961"},"Time":1649023833612,"Event":"OrderCanceled"}
1649023833.713637: {"Channel":"orderbook-matic","Nonce":5992,"Data":{"OrderType":"LimitOffer","OrderGuid":"3441c245-a2a9-4abe-9781-73fbd65e17b8"},"Time":1649023833612,"Event":"OrderCanceled"}
1649023833.724332: {"Channel":"orderbook-eth","Nonce":19731,"Data":{"OrderType":"LimitOffer","OrderGuid":"39504aaa-b629-449d-a96a-81073eaed07d","Price":{"aud":4734.3,"usd":3564.45,"nzd":5157.19,"sgd":4827.97},"Volume":15.0},"Time":1649023833612,"Event":"NewOrder"}
1649023833.727617: {"Channel":"orderbook-matic","Nonce":5993,"Data":{"OrderType":"LimitBid","OrderGuid":"071bb1a8-df15-4c1b-8c4b-6b4bc046a63a"},"Time":1649023833627,"Event":"OrderCanceled"}
1649023833.72772: {"Channel":"orderbook-eth","Nonce":19732,"Data":{"OrderType":"LimitOffer","OrderGuid":"74b87e3c-357e-4e56-ace8-493f36e451a1","Price":{"aud":4742.02,"usd":3570.27,"nzd":5165.6,"sgd":4835.84},"Volume":4.47331033},"Time":1649023833627,"Event":"NewOrder"}
1649023833.729743: {"Channel":"orderbook-eth","Nonce":19733,"Data":{"OrderType":"LimitOffer","OrderGuid":"2935dedf-1340-405e-a92c-48481229fd70","Price":{"aud":4737.3,"usd":3566.71,"nzd":5160.46,"sgd":4831.03},"Volume":15.0},"Time":1649023833627,"Event":"NewOrder"}
1649023833.740298: {"Channel":"orderbook-eth","Nonce":19734,"Data":{"OrderType":"LimitOffer","OrderGuid":"7c6b0cbd-ae08-4a36-954f-e05ca39b51d4"},"Time":1649023833643,"Event":"OrderCanceled"}
1649023833.753252: {"Channel":"orderbook-eth","Nonce":19735,"Data":{"OrderType":"LimitBid","OrderGuid":"53e474ee-7c17-4ab3-91a3-18049975b0d2","Price":{"aud":4727.1,"usd":3523.58,"nzd":5087.3,"sgd":4790.91},"Volume":15.0},"Time":1649023833643,"Event":"NewOrder"}
1649023833.7598238: {"Channel":"orderbook-dot","Nonce":5031,"Data":{"OrderType":"LimitOffer","OrderGuid":"132cf01e-e26e-4ae8-b3a7-eae3d95c6a1c","Price":{"aud":31.3796,"usd":23.6257,"nzd":34.1826,"sgd":32.0005},"Volume":19.94125},"Time":1649023833658,"Event":"NewOrder"}
1649023833.807421: {"Channel":"orderbook-matic","Nonce":5994,"Data":{"OrderType":"LimitBid","OrderGuid":"8d229cc5-bd05-4a08-8871-17b0d6b64e54"},"Time":1649023833705,"Event":"OrderCanceled"}
1649023833.821762: {"Channel":"orderbook-matic","Nonce":5995,"Data":{"OrderType":"LimitOffer","OrderGuid":"f2dbd480-07d9-46f6-8cdf-c509a88698a7","Price":{"aud":2.275,"usd":1.71285,"nzd":2.47822,"sgd":2.32001},"Volume":5583.0},"Time":1649023833721,"Event":"NewOrder"}
1649023833.831299: {"Channel":"orderbook-matic","Nonce":5996,"Data":{"OrderType":"LimitOffer","OrderGuid":"44551226-0e97-4cdc-b37b-049c869ed632","Price":{"aud":2.2735,"usd":1.71172,"nzd":2.47658,"sgd":2.31848},"Volume":5583.0},"Time":1649023833721,"Event":"NewOrder"}
1649023833.8490372: {"Channel":"orderbook-dot","Nonce":5032,"Data":{"OrderType":"LimitOffer","OrderGuid":"b4979f27-5737-47b7-af2f-ada8fce60acc"},"Time":1649023833737,"Event":"OrderCanceled"}
1649023833.85226: {"Channel":"orderbook-eth","Nonce":19736,"Data":{"OrderType":"LimitBid","OrderGuid":"47f4b0b0-0a18-4dab-a8b0-0ebe351c3fae","Price":{"aud":4724.1,"usd":3521.34,"nzd":5084.07,"sgd":4787.87},"Volume":15.0},"Time":1649023833752,"Event":"NewOrder"}
1649023833.866448: {"Channel":"orderbook-eth","Nonce":19737,"Data":{"OrderType":"LimitBid","OrderGuid":"5e76a2df-4bac-4fff-b42d-7259133f7d4c"},"Time":1649023833768,"Event":"OrderCanceled"}
1649023833.907014: {"Channel":"orderbook-eth","Nonce":19738,"Data":{"OrderType":"LimitBid","OrderGuid":"1f52d8ef-e610-4e1e-846d-8b399dbfbb0c"},"Time":1649023833799,"Event":"OrderCanceled"}
1649023833.907072: {"Channel":"orderbook-matic","Nonce":5997,"Data":{"OrderType":"LimitBid","OrderGuid":"23d56631-758e-4149-ac1e-5b4b0d8da170","Price":{"aud":2.2625,"usd":1.68646,"nzd":2.4349,"sgd":2.29304},"Volume":5583.0},"Time":1649023833799,"Event":"NewOrder"}
1649023833.948473: {"Channel":"orderbook-matic","Nonce":5998,"Data":{"OrderType":"LimitBid","OrderGuid":"60982977-c7aa-4c87-9552-4e45bf16a885","Price":{"aud":2.261,"usd":1.68534,"nzd":2.43328,"sgd":2.29152},"Volume":5583.0},"Time":1649023833846,"Event":"NewOrder"}
1649023833.957746: {"Channel":"orderbook-eth","Nonce":19739,"Data":{"OrderType":"LimitBid","OrderGuid":"742363fd-970b-4af0-816a-36f82d8aca16","Price":{"aud":4695.42,"usd":3499.96,"nzd":5053.21,"sgd":4758.8},"Volume":4.261},"Time":1649023833846,"Event":"NewOrder"}
1649023833.97344: {"Channel":"orderbook-matic","Nonce":5999,"Data":{"OrderType":"LimitBid","OrderGuid":"e6602a77-7562-4578-96d8-402936461555"},"Time":1649023833862,"Event":"OrderCanceled"}
1649023833.973539: {"Channel":"orderbook-matic","Nonce":6000,"Data":{"OrderType":"LimitOffer","OrderGuid":"a20e5959-0071-4d5b-bb8b-539cb6133ab4"},"Time":1649023833862,"Event":"OrderCanceled"}
1649023834.004837: {"Channel":"orderbook-eth","Nonce":19740,"Data":{"OrderType":"LimitBid","OrderGuid":"6b702afb-4901-4169-9075-b83092d0cc38","Price":{"aud":4704.02,"usd":3506.37,"nzd":5062.46,"sgd":4767.52},"Volume":0.37026025},"Time":1649023833893,"Event":"NewOrder"}
1649023834.0405161: {"Channel":"orderbook-eth","Nonce":19741,"Data":{"OrderType":"LimitBid","OrderGuid":"bbcd9901-45c5-4d5c-bc99-944358c0580b","Price":{"aud":4668.81,"usd":3480.13,"nzd":5024.57,"sgd":4731.83},"Volume":0.19518981},"Time":1649023833940,"Event":"NewOrder"}
1649023834.04422: {"Channel":"orderbook-matic","Nonce":6001,"Data":{"OrderType":"LimitOffer","OrderGuid":"d926a67a-99a9-4335-b843-8335935b9ce6","Price":{"aud":2.27295,"usd":1.71131,"nzd":2.47599,"sgd":2.31792},"Volume":5560.90932},"Time":1649023833940,"Event":"NewOrder"}
1649023834.068911: {"Channel":"orderbook-matic","Nonce":6002,"Data":{"OrderType":"LimitBid","OrderGuid":"a981e001-79d5-468b-b64a-5d6df2c6aa31","Price":{"aud":2.26253,"usd":1.68648,"nzd":2.43493,"sgd":2.29307},"Volume":5223.23562},"Time":1649023833971,"Event":"NewOrder"}
1649023834.1576462: {"Channel":"orderbook-eth","Nonce":19742,"Data":{"OrderType":"LimitBid","OrderGuid":"86a51ba0-fba6-467f-af1e-dbdc5eed5adf"},"Time":1649023834049,"Event":"OrderCanceled"}
1649023834.1658602: {"Channel":"orderbook-pmgt","Nonce":450,"Data":{"OrderType":"LimitOffer","OrderGuid":"281f6bbc-ad41-4374-be40-ea9eff9f357e","Price":{"aud":2591.25,"usd":1950.95,"nzd":2822.72,"sgd":2642.52},"Volume":10.0},"Time":1649023834065,"Event":"NewOrder"}
1649023834.213224: {"Channel":"orderbook-eth","Nonce":19743,"Data":{"OrderType":"LimitBid","OrderGuid":"ad4792c5-d573-42a6-8f22-0c3048cd36cd","Price":{"aud":4678.21,"usd":3504.07,"nzd":5096.09,"sgd":4769.94},"Volume":0.48351795},"Time":1649023834112,"Event":"NewOrder"}
1649023834.226889: {"Channel":"orderbook-pmgt","Nonce":451,"Data":{"OrderType":"LimitOffer","OrderGuid":"115f75f5-ca71-456c-a46f-93fcc737752e"},"Time":1649023834127,"Event":"OrderCanceled"}
1649023834.26916: {"Channel":"orderbook-pmgt","Nonce":452,"Data":{"OrderType":"LimitOffer","OrderGuid":"f8e57491-24dd-472d-99c1-f78c011b245b","Price":{"aud":2595.05,"usd":1953.81,"nzd":2826.86,"sgd":2646.39},"Volume":3.0},"Time":1649023834158,"Event":"NewOrder"}
1649023834.2911649: {"Channel":"orderbook-bch","Nonce":8421,"Data":{"OrderType":"LimitOffer","OrderGuid":"420e8f4a-cbf3-4ba7-a7ee-655aef251633"},"Time":1649023834190,"Event":"OrderCanceled"}
1649023834.299753: {"Channel":"orderbook-pmgt","Nonce":453,"Data":{"OrderType":"LimitOffer","OrderGuid":"dcc9e852-0766-432e-ba0d-788a5a6a2e49"},"Time":1649023834190,"Event":"OrderCanceled"}
1649023834.3145769: {"Channel":"orderbook-eth","Nonce":19744,"Data":{"OrderType":"LimitBid","OrderGuid":"c38369c8-1895-446b-b5a7-0150be37e845"},"Time":1649023834205,"Event":"OrderCanceled"}
1649023834.316517: {"Channel":"orderbook-bch","Nonce":8422,"Data":{"OrderType":"LimitOffer","OrderGuid":"bd7eb910-7df7-40f3-a2a8-84ba7d535de6","Price":{"aud":507.78,"usd":382.31,"nzd":553.14,"sgd":517.83},"Volume":1.09306259},"Time":1649023834205,"Event":"NewOrder"}
1649023834.3406641: {"Channel":"orderbook-pmgt","Nonce":454,"Data":{"OrderType":"LimitOffer","OrderGuid":"8389e9cf-344f-401d-ac29-dabdafa0675a","Price":{"aud":2598.85,"usd":1956.68,"nzd":2831.0,"sgd":2650.27},"Volume":3.0},"Time":1649023834237,"Event":"NewOrder"}
1649023834.3589299: {"Channel":"orderbook-eth","Nonce":19745,"Data":{"OrderType":"LimitBid","OrderGuid":"53e474ee-7c17-4ab3-91a3-18049975b0d2"},"Time":1649023834252,"Event":"OrderCanceled"}
1649023834.3589818: {"Channel":"orderbook-eth","Nonce":19746,"Data":{"OrderType":"LimitOffer","OrderGuid":"39504aaa-b629-449d-a96a-81073eaed07d"},"Time":1649023834252,"Event":"OrderCanceled"}
1649023834.362286: {"Channel":"orderbook-eth","Nonce":19747,"Data":{"OrderType":"LimitOffer","OrderGuid":"2935dedf-1340-405e-a92c-48481229fd70"},"Time":1649023834252,"Event":"OrderCanceled"}
1649023834.378133: {"Channel":"orderbook-bch","Nonce":8423,"Data":{"OrderType":"LimitOffer","OrderGuid":"e89a081c-41ca-4370-a7ed-eaeadbe6feb4"},"Time":1649023834268,"Event":"OrderCanceled"}
1649023834.378722: {"Channel":"orderbook-pmgt","Nonce":455,"Data":{"OrderType":"LimitOffer","OrderGuid":"63c7ad20-3b60-4cf7-84de-2f6b28c65ffb"},"Time":1649023834268,"Event":"OrderCanceled"}
1649023834.422789: {"Channel":"orderbook-pmgt","Nonce":456,"Data":{"OrderType":"LimitOffer","OrderGuid":"85417a53-1ad4-4d5c-9172-9e547a63d30e","Price":{"aud":2602.65,"usd":1959.54,"nzd":2835.14,"sgd":2654.15},"Volume":3.0},"Time":1649023834315,"Event":"NewOrder"}
1649023834.443208: {"Channel":"orderbook-eth","Nonce":19748,"Data":{"OrderType":"LimitBid","OrderGuid":"7d7f559e-bc61-4a6d-bb5c-0f1727965710","Price":{"aud":4665.82,"usd":3477.9,"nzd":5021.35,"sgd":4728.8},"Volume":0.1952169},"Time":1649023834346,"Event":"NewOrder"}
1649023834.453696: {"Channel":"orderbook-bch","Nonce":8424,"Data":{"OrderType":"LimitOffer","OrderGuid":"d0849d3c-6a88-4c4a-929b-f877139933e8","Price":{"aud":510.6,"usd":384.44,"nzd":556.21,"sgd":520.71},"Volume":2.93},"Time":1649023834346,"Event":"NewOrder"}
1649023834.463639: {"Channel":"orderbook-pmgt","Nonce":457,"Data":{"OrderType":"LimitOffer","OrderGuid":"581457fd-6f3d-434f-b140-4c9e43947c34"},"Time":1649023834362,"Event":"OrderCanceled"}
1649023834.463692: {"Channel":"orderbook-eth","Nonce":19749,"Data":{"OrderType":"LimitOffer","OrderGuid":"24025fff-0e1d-4a64-807b-29357022fe12","Price":{"aud":4734.5,"usd":3564.6,"nzd":5157.41,"sgd":4828.17},"Volume":15.0},"Time":1649023834362,"Event":"NewOrder"}
1649023834.4643111: {"Channel":"orderbook-eth","Nonce":19750,"Data":{"OrderType":"LimitBid","OrderGuid":"47f4b0b0-0a18-4dab-a8b0-0ebe351c3fae"},"Time":1649023834362,"Event":"OrderCanceled"}
1649023834.483045: {"Channel":"orderbook-eth","Nonce":19751,"Data":{"OrderType":"LimitOffer","OrderGuid":"57df445f-8511-451f-ac3c-92ca0272a74f","Price":{"aud":4737.5,"usd":3566.86,"nzd":5160.68,"sgd":4831.23},"Volume":15.0},"Time":1649023834377,"Event":"NewOrder"}
1649023834.491837: {"Channel":"orderbook-bch","Nonce":8425,"Data":{"OrderType":"LimitOffer","OrderGuid":"01878960-1178-45af-860b-c25663bedaa6","Price":{"aud":510.59,"usd":384.43,"nzd":556.2,"sgd":520.7},"Volume":21.20858658},"Time":1649023834393,"Event":"NewOrder"}
1649023834.495072: {"Channel":"orderbook-bch","Nonce":8426,"Data":{"OrderType":"LimitOffer","OrderGuid":"c95fa547-d3f0-4bde-8b1e-93bbbf2feec8"},"Time":1649023834393,"Event":"OrderCanceled"}
1649023834.516921: {"Channel":"orderbook-eth","Nonce":19752,"Data":{"OrderType":"LimitBid","OrderGuid":"339eaf2a-f68c-4512-b8e4-ad0a31ad29ac","Price":{"aud":4727.2,"usd":3523.65,"nzd":5087.41,"sgd":4791.01},"Volume":15.0},"Time":1649023834408,"Event":"NewOrder"}
1649023834.5231192: {"Channel":"orderbook-pmgt","Nonce":458,"Data":{"OrderType":"LimitBid","OrderGuid":"c0cb7182-ad2c-4870-ae9d-306c7904514b","Price":{"aud":2557.85,"usd":1906.62,"nzd":2752.75,"sgd":2592.38},"Volume":10.0},"Time":1649023834424,"Event":"NewOrder"}
1649023834.5232158: {"Channel":"orderbook-eth","Nonce":19753,"Data":{"OrderType":"LimitBid","OrderGuid":"d612062a-ea69-4f95-8718-e3865bdb2f82","Price":{"aud":4724.2,"usd":3521.41,"nzd":5084.18,"sgd":4787.97},"Volume":15.0},"Time":1649023834424,"Event":"NewOrder"}
1649023834.570055: {"Channel":"orderbook-pmgt","Nonce":459,"Data":{"OrderType":"LimitBid","OrderGuid":"74e05fb5-4455-4fc9-b0af-ff525782467a"},"Time":1649023834471,"Event":"OrderCanceled"}
1649023834.601057: {"Channel":"orderbook-pmgt","Nonce":460,"Data":{"OrderType":"LimitBid","OrderGuid":"2facafc1-8f60-4eca-b4bc-7e05cb8d8150","Price":{"aud":2554.05,"usd":1903.78,"nzd":2748.66,"sgd":2588.52},"Volume":3.0},"Time":1649023834502,"Event":"NewOrder"}
1649023834.63486: {"Channel":"orderbook-pmgt","Nonce":461,"Data":{"OrderType":"LimitBid","OrderGuid":"fd5f7e24-427a-4d5b-a444-b36e948c310e"},"Time":1649023834533,"Event":"OrderCanceled"}
1649023834.648628: {"Channel":"orderbook-dot","Nonce":5033,"Data":{"OrderType":"LimitOffer","OrderGuid":"6979c753-a29a-44ea-85e2-39acc16edaf4","Price":{"aud":31.3897,"usd":23.6333,"nzd":34.1936,"sgd":32.0108},"Volume":19.9437},"Time":1649023834549,"Event":"NewOrder"}
1649023834.663289: {"Channel":"orderbook-eth","Nonce":19754,"Data":{"OrderType":"LimitOffer","OrderGuid":"57df445f-8511-451f-ac3c-92ca0272a74f"},"Time":1649023834565,"Event":"OrderCanceled"}
1649023834.672392: {"Channel":"orderbook-eth","Nonce":19755,"Data":{"OrderType":"LimitOffer","OrderGuid":"24025fff-0e1d-4a64-807b-29357022fe12"},"Time":1649023834565,"Event":"OrderCanceled"}
1649023834.672519: {"Channel":"orderbook-pmgt","Nonce":462,"Data":{"OrderType":"LimitBid","OrderGuid":"049ffe4a-0311-4936-9e52-f5ca9f8039da","Price":{"aud":2550.25,"usd":1900.95,"nzd":2744.57,"sgd":2584.67},"Volume":3.0},"Time":1649023834565,"Event":"NewOrder"}
1649023834.6725938: {"Channel":"orderbook-bch","Nonce":8427,"Data":{"OrderType":"LimitOffer","OrderGuid":"9ddb6b0a-d6d2-4dfb-99fc-4be3a756beff","Price":{"aud":507.77,"usd":382.3,"nzd":553.13,"sgd":517.82},"Volume":1.09306259},"Time":1649023834565,"Event":"NewOrder"}
1649023834.673028: {"Channel":"orderbook-eth","Nonce":19756,"Data":{"OrderType":"LimitOffer","OrderGuid":"ee59921b-5c64-46b6-a82f-ef0e357c608d"},"Time":1649023834565,"Event":"OrderCanceled"}
1649023834.696058: {"Channel":"orderbook-dot","Nonce":5034,"Data":{"OrderType":"LimitOffer","OrderGuid":"2280e9c4-0d0a-464c-bc7f-1abe6bcfa27e"},"Time":1649023834596,"Event":"OrderCanceled"}
1649023834.7076852: {"Channel":"orderbook-pmgt","Nonce":463,"Data":{"OrderType":"LimitBid","OrderGuid":"fdecec48-f73e-4f2d-94fc-31df63efe7ee"},"Time":1649023834596,"Event":"OrderCanceled"}
1649023834.7077608: {"Channel":"orderbook-eth","Nonce":19757,"Data":{"OrderType":"LimitOffer","OrderGuid":"36821e4d-cc41-4720-8bde-829b359a6ca0","Price":{"aud":4737.4,"usd":3566.79,"nzd":5160.57,"sgd":4831.13},"Volume":15.0},"Time":1649023834596,"Event":"NewOrder"}
1649023834.711526: {"Channel":"orderbook-eth","Nonce":19758,"Data":{"OrderType":"LimitOffer","OrderGuid":"3db2ce56-5a11-479d-9c6b-c5170821e671","Price":{"aud":4793.99,"usd":3573.44,"nzd":5196.98,"sgd":4863.81},"Volume":0.54720407},"Time":1649023834613,"Event":"NewOrder"}
1649023834.730517: {"Channel":"orderbook-eth","Nonce":19759,"Data":{"OrderType":"LimitOffer","OrderGuid":"f1e9a76b-2c57-4cd8-8907-952bc82e8197","Price":{"aud":4734.4,"usd":3564.53,"nzd":5157.3,"sgd":4828.07},"Volume":15.0},"Time":1649023834628,"Event":"NewOrder"}
1649023834.792931: {"Channel":"orderbook-eth","Nonce":19760,"Data":{"OrderType":"LimitOffer","OrderGuid":"3db2ce56-5a11-479d-9c6b-c5170821e671"},"Time":1649023834691,"Event":"OrderCanceled"}
1649023834.804754: {"Channel":"orderbook-matic","Nonce":6003,"Data":{"OrderType":"LimitOffer","OrderGuid":"f2dbd480-07d9-46f6-8cdf-c509a88698a7"},"Time":1649023834707,"Event":"OrderCanceled"}
1649023834.804856: {"Channel":"orderbook-matic","Nonce":6004,"Data":{"OrderType":"LimitBid","OrderGuid":"23d56631-758e-4149-ac1e-5b4b0d8da170"},"Time":1649023834707,"Event":"OrderCanceled"}
1649023834.806964: {"Channel":"orderbook-dot","Nonce":5035,"Data":{"OrderType":"LimitOffer","OrderGuid":"132cf01e-e26e-4ae8-b3a7-eae3d95c6a1c"},"Time":1649023834707,"Event":"OrderCanceled"}
1649023834.8235679: {"Channel":"orderbook-dot","Nonce":5036,"Data":{"OrderType":"LimitOffer","OrderGuid":"5bce869f-a994-4fce-9d26-4d5a8443af6e","Price":{"aud":31.4349,"usd":23.6673,"nzd":34.2429,"sgd":32.0569},"Volume":23.08848},"Time":1649023834722,"Event":"NewOrder"}
1649023834.8393972: {"Channel":"orderbook-matic","Nonce":6005,"Data":{"OrderType":"LimitBid","OrderGuid":"a981e001-79d5-468b-b64a-5d6df2c6aa31"},"Time":1649023834738,"Event":"OrderCanceled"}
1649023834.862987: {"Channel":"orderbook-eth","Nonce":19761,"Data":{"OrderType":"LimitOffer","OrderGuid":"8c8cf6b3-ef56-494c-9283-24d7ac59a78e","Price":{"aud":4797.78,"usd":3576.26,"nzd":5201.08,"sgd":4867.65},"Volume":0.54824879},"Time":1649023834755,"Event":"NewOrder"}
1649023834.86818: {"Channel":"orderbook-bch","Nonce":8428,"Data":{"OrderType":"LimitOffer","OrderGuid":"21888c77-6639-454b-b53e-864a7fedc0de"},"Time":1649023834771,"Event":"OrderCanceled"}
1649023834.9298549: {"Channel":"orderbook-matic","Nonce":6006,"Data":{"OrderType":"LimitBid","OrderGuid":"60982977-c7aa-4c87-9552-4e45bf16a885"},"Time":1649023834818,"Event":"OrderCanceled"}
1649023834.9299572: {"Channel":"orderbook-matic","Nonce":6007,"Data":{"OrderType":"LimitOffer","OrderGuid":"44551226-0e97-4cdc-b37b-049c869ed632"},"Time":1649023834818,"Event":"OrderCanceled"}
1649023834.960809: {"Channel":"orderbook-eth","Nonce":19762,"Data":{"OrderType":"LimitBid","OrderGuid":"339eaf2a-f68c-4512-b8e4-ad0a31ad29ac"},"Time":1649023834834,"Event":"OrderCanceled"}
1649023834.960914: {"Channel":"orderbook-eth","Nonce":19763,"Data":{"OrderType":"LimitOffer","OrderGuid":"36821e4d-cc41-4720-8bde-829b359a6ca0"},"Time":1649023834849,"Event":"OrderCanceled"}
1649023834.976228: {"Channel":"orderbook-eth","Nonce":19764,"Data":{"OrderType":"LimitBid","OrderGuid":"d612062a-ea69-4f95-8718-e3865bdb2f82"},"Time":1649023834865,"Event":"OrderCanceled"}
1649023834.976288: {"Channel":"orderbook-eth","Nonce":19765,"Data":{"OrderType":"LimitOffer","OrderGuid":"f1e9a76b-2c57-4cd8-8907-952bc82e8197"},"Time":1649023834865,"Event":"OrderCanceled"}
1649023834.976313: {"Channel":"orderbook-matic","Nonce":6008,"Data":{"OrderType":"LimitOffer","OrderGuid":"976d6dbc-ba89-480e-bbe3-3f92ddbdc4c9","Price":{"aud":2.273,"usd":1.71134,"nzd":2.47604,"sgd":2.31797},"Volume":5583.0},"Time":1649023834865,"Event":"NewOrder"}
1649023834.9992058: {"Channel":"orderbook-matic","Nonce":6009,"Data":{"OrderType":"LimitBid","OrderGuid":"8d3c8af2-4734-4449-aa2d-6d0712ee0b7c","Price":{"aud":2.26124,"usd":1.68552,"nzd":2.43354,"sgd":2.29176},"Volume":5149.43877},"Time":1649023834896,"Event":"NewOrder"}
1649023835.0032089: {"Channel":"orderbook-matic","Nonce":6010,"Data":{"OrderType":"LimitBid","OrderGuid":"7d2f8889-1485-4794-8d63-9cb18507323a","Price":{"aud":2.262,"usd":1.68609,"nzd":2.43436,"sgd":2.29253},"Volume":5583.0},"Time":1649023834896,"Event":"NewOrder"}
1649023835.013493: {"Channel":"orderbook-matic","Nonce":6011,"Data":{"OrderType":"LimitOffer","OrderGuid":"d926a67a-99a9-4335-b843-8335935b9ce6"},"Time":1649023834912,"Event":"OrderCanceled"}
1649023835.0135958: {"Channel":"orderbook-matic","Nonce":6012,"Data":{"OrderType":"LimitBid","OrderGuid":"5e360d43-a9f5-4ff6-a9b5-8e940edfff0f","Price":{"aud":2.2605,"usd":1.68497,"nzd":2.43275,"sgd":2.29101},"Volume":5583.0},"Time":1649023834912,"Event":"NewOrder"}
1649023835.013671: {"Channel":"orderbook-bch","Nonce":8429,"Data":{"OrderType":"LimitOffer","OrderGuid":"c90cebce-2d0a-478d-9828-db28cad8c821","Price":{"aud":510.58,"usd":384.42,"nzd":556.19,"sgd":520.69},"Volume":39.74331},"Time":1649023834912,"Event":"NewOrder"}
1649023835.018517: {"Channel":"orderbook-dot","Nonce":5037,"Data":{"OrderType":"LimitOffer","OrderGuid":"5bce869f-a994-4fce-9d26-4d5a8443af6e"},"Time":1649023834912,"Event":"OrderCanceled"}
1649023835.0185878: {"Channel":"orderbook-eth","Nonce":19766,"Data":{"OrderType":"LimitOffer","OrderGuid":"7c8e7f12-c95b-4ce7-958f-86f973c93250","Price":{"aud":4734.1,"usd":3564.3,"nzd":5156.98,"sgd":4827.76},"Volume":15.0},"Time":1649023834912,"Event":"NewOrder"}
1649023835.018637: {"Channel":"orderbook-eth","Nonce":19767,"Data":{"OrderType":"LimitBid","OrderGuid":"5ba9d983-520b-4740-a32e-8d42cacb6bf6"},"Time":1649023834912,"Event":"OrderCanceled"}
1649023835.036437: {"Channel":"orderbook-eth","Nonce":19768,"Data":{"OrderType":"LimitBid","OrderGuid":"6b702afb-4901-4169-9075-b83092d0cc38"},"Time":1649023834927,"Event":"OrderCanceled"}
1649023835.036514: {"Channel":"orderbook-eth","Nonce":19769,"Data":{"OrderType":"LimitOffer","OrderGuid":"88bf0bb0-a5c7-41c4-9016-88d606b8f832","Price":{"aud":4737.1,"usd":3566.56,"nzd":5160.24,"sgd":4830.82},"Volume":15.0},"Time":1649023834927,"Event":"NewOrder"}
1649023835.036563: {"Channel":"orderbook-eth","Nonce":19770,"Data":{"OrderType":"LimitBid","OrderGuid":"61fe3b9d-0cc3-441e-9759-b35b00b78a03","Price":{"aud":4723.9,"usd":3521.19,"nzd":5083.86,"sgd":4787.67},"Volume":15.0},"Time":1649023834927,"Event":"NewOrder"}
1649023835.0654268: {"Channel":"orderbook-eth","Nonce":19771,"Data":{"OrderType":"LimitBid","OrderGuid":"d61ebc0b-8a48-4186-8999-662f7f7ecb34","Price":{"aud":4696.29,"usd":3518.63,"nzd":5085.18,"sgd":4789.21},"Volume":3.19767498},"Time":1649023834959,"Event":"NewOrder"}
1649023835.077207: {"Channel":"orderbook-matic","Nonce":6013,"Data":{"OrderType":"LimitOffer","OrderGuid":"665b7b2f-3d6f-4efd-845d-80c7cbc869d5","Price":{"aud":2.27294,"usd":1.7113,"nzd":2.47597,"sgd":2.31791},"Volume":5817.04406},"Time":1649023834974,"Event":"NewOrder"}
1649023835.086496: {"Channel":"orderbook-matic","Nonce":6014,"Data":{"OrderType":"LimitOffer","OrderGuid":"4ec727b3-b995-41b7-a612-8e2f5ab051a1","Price":{"aud":2.2745,"usd":1.71247,"nzd":2.47767,"sgd":2.3195},"Volume":5583.0},"Time":1649023834974,"Event":"NewOrder"}
1649023835.086617: {"Channel":"orderbook-bch","Nonce":8430,"Data":{"OrderType":"LimitOffer","OrderGuid":"099ebaca-10e4-465a-8c4f-f3070f46c6a9","Price":{"aud":510.57,"usd":384.41,"nzd":556.18,"sgd":520.68},"Volume":21.20858658},"Time":1649023834974,"Event":"NewOrder"}
1649023835.102744: {"Channel":"orderbook-dot","Nonce":5038,"Data":{"OrderType":"LimitBid","OrderGuid":"b15d76c3-89cf-4383-90fb-214bf313adac"},"Time":1649023834990,"Event":"OrderCanceled"}
1649023835.102817: {"Channel":"orderbook-eth","Nonce":19772,"Data":{"OrderType":"LimitBid","OrderGuid":"bbcd9901-45c5-4d5c-bc99-944358c0580b"},"Time":1649023834990,"Event":"OrderCanceled"}
1649023835.10285: {"Channel":"orderbook-bch","Nonce":8431,"Data":{"OrderType":"LimitOffer","OrderGuid":"01878960-1178-45af-860b-c25663bedaa6"},"Time":1649023834990,"Event":"OrderCanceled"}
1649023835.1028779: {"Channel":"orderbook-eth","Nonce":19773,"Data":{"OrderType":"LimitBid","OrderGuid":"1587ee01-1133-4b7b-8a35-2906a7d3f430","Price":{"aud":4704.03,"usd":3506.38,"nzd":5062.47,"sgd":4767.53},"Volume":0.35419549},"Time":1649023834990,"Event":"NewOrder"}
1649023835.105736: {"Channel":"orderbook-dot","Nonce":5039,"Data":{"OrderType":"LimitBid","OrderGuid":"bbf385b5-7a9d-4783-a417-0c80a62c8a8e"},"Time":1649023835005,"Event":"OrderCanceled"}
1649023835.10945: {"Channel":"orderbook-dot","Nonce":5040,"Data":{"OrderType":"LimitOffer","OrderGuid":"cb5f6089-a479-454f-94fb-c7346ce1a9eb","Price":{"aud":31.5094,"usd":23.7234,"nzd":34.324,"sgd":32.1328},"Volume":28.2697},"Time":1649023835005,"Event":"NewOrder"}
1649023835.1127229: {"Channel":"orderbook-eth","Nonce":19774,"Data":{"OrderType":"LimitOffer","OrderGuid":"8a2e161f-7589-4d65-8f01-d4689438fe4b"},"Time":1649023835005,"Event":"OrderCanceled"}
1649023835.130309: {"Channel":"orderbook-eth","Nonce":19775,"Data":{"OrderType":"LimitBid","OrderGuid":"59b627ea-995b-4f74-aa0b-7f48f65c2c2e","Price":{"aud":4726.9,"usd":3523.43,"nzd":5087.08,"sgd":4790.71},"Volume":15.0},"Time":1649023835021,"Event":"NewOrder"}
1649023835.157712: {"Channel":"orderbook-dot","Nonce":5041,"Data":{"OrderType":"LimitBid","OrderGuid":"5f0da27f-7b7e-4c6b-a911-c54452806f12","Price":{"aud":30.8031,"usd":22.9606,"nzd":33.1502,"sgd":31.2189},"Volume":457.6},"Time":1649023835052,"Event":"NewOrder"}
1649023835.1578329: {"Channel":"orderbook-eth","Nonce":19776,"Data":{"OrderType":"LimitOffer","OrderGuid":"ea89c630-ca4b-4fbc-af9a-1693cffb6748","Price":{"aud":4757.26,"usd":3563.82,"nzd":5151.16,"sgd":4821.48},"Volume":1.13532866},"Time":1649023835052,"Event":"NewOrder"}
1649023835.167239: {"Channel":"orderbook-dot","Nonce":5042,"Data":{"OrderType":"LimitBid","OrderGuid":"8e687480-302b-4f5a-9686-5c9133639232"},"Time":1649023835068,"Event":"OrderCanceled"}
1649023835.16734: {"Channel":"orderbook-dot","Nonce":5043,"Data":{"OrderType":"LimitBid","OrderGuid":"6b8dba6e-0867-46fc-ac6b-1979415fed45","Price":{"aud":31.14,"usd":23.2117,"nzd":33.5128,"sgd":31.5603},"Volume":80.0},"Time":1649023835068,"Event":"NewOrder"}
1649023835.182534: {"Channel":"orderbook-dot","Nonce":5044,"Data":{"OrderType":"LimitBid","OrderGuid":"bcbe0023-62f4-41fe-aa0c-ac82bbe012db","Price":{"aud":31.18,"usd":23.2415,"nzd":33.5559,"sgd":31.6009},"Volume":80.0},"Time":1649023835084,"Event":"NewOrder"}
1649023835.182661: {"Channel":"orderbook-dot","Nonce":5045,"Data":{"OrderType":"LimitOffer","OrderGuid":"13c60e80-8296-43ba-a36d-34070c06ff2c","Price":{"aud":31.5093,"usd":23.7234,"nzd":34.3239,"sgd":32.1327},"Volume":14.72539},"Time":1649023835084,"Event":"NewOrder"}
1649023835.1963892: {"Channel":"orderbook-dot","Nonce":5046,"Data":{"OrderType":"LimitOffer","OrderGuid":"b4e0108e-25c0-4c35-99b7-f9b0dd939ee9"},"Time":1649023835084,"Event":"OrderCanceled"}
1649023835.211324: {"Channel":"orderbook-dot","Nonce":5047,"Data":{"OrderType":"LimitOffer","OrderGuid":"cb5f6089-a479-454f-94fb-c7346ce1a9eb"},"Time":1649023835115,"Event":"OrderCanceled"}
1649023835.218772: {"Channel":"orderbook-eth","Nonce":19777,"Data":{"OrderType":"LimitBid","OrderGuid":"59b627ea-995b-4f74-aa0b-7f48f65c2c2e"},"Time":1649023835115,"Event":"OrderCanceled"}
1649023835.2193642: {"Channel":"orderbook-eth","Nonce":19778,"Data":{"OrderType":"LimitOffer","OrderGuid":"88bf0bb0-a5c7-41c4-9016-88d606b8f832"},"Time":1649023835115,"Event":"OrderCanceled"}
1649023835.2389052: {"Channel":"orderbook-eth","Nonce":19779,"Data":{"OrderType":"LimitBid","OrderGuid":"ad4792c5-d573-42a6-8f22-0c3048cd36cd"},"Time":1649023835130,"Event":"OrderCanceled"}
1649023835.239006: {"Channel":"orderbook-bch","Nonce":8432,"Data":{"OrderType":"LimitBid","OrderGuid":"e960650d-095c-4907-bdde-02e3a8cdd0c6"},"Time":1649023835130,"Event":"OrderCanceled"}
1649023835.241385: {"Channel":"orderbook-bch","Nonce":8433,"Data":{"OrderType":"LimitOffer","OrderGuid":"10f0a05b-3914-4ac6-936a-26ae26969212"},"Time":1649023835130,"Event":"OrderCanceled"}
1649023835.2571032: {"Channel":"orderbook-bch","Nonce":8434,"Data":{"OrderType":"LimitBid","OrderGuid":"a4ee3fe0-f7aa-4fe6-b613-e52cbb7dcc36"},"Time":1649023835146,"Event":"OrderCanceled"}
1649023835.292799: {"Channel":"orderbook-eth","Nonce":19780,"Data":{"OrderType":"LimitBid","OrderGuid":"553c20d4-08d6-40bb-b9dc-c5e27ca9f68e","Price":{"aud":4678.21,"usd":3504.07,"nzd":5096.1,"sgd":4769.94},"Volume":0.52417832},"Time":1649023835193,"Event":"NewOrder"}
1649023835.296205: {"Channel":"orderbook-dot","Nonce":5048,"Data":{"OrderType":"LimitOffer","OrderGuid":"4075855f-57c1-48a2-8f6b-6d3302117839","Price":{"aud":31.4348,"usd":23.6673,"nzd":34.2428,"sgd":32.0567},"Volume":26.99726},"Time":1649023835193,"Event":"NewOrder"}
1649023835.326406: {"Channel":"orderbook-eth","Nonce":19781,"Data":{"OrderType":"LimitBid","OrderGuid":"61fe3b9d-0cc3-441e-9759-b35b00b78a03"},"Time":1649023835225,"Event":"OrderCanceled"}
1649023835.3265111: {"Channel":"orderbook-eth","Nonce":19782,"Data":{"OrderType":"LimitOffer","OrderGuid":"7c8e7f12-c95b-4ce7-958f-86f973c93250"},"Time":1649023835225,"Event":"OrderCanceled"}
1649023835.350639: {"Channel":"orderbook-bch","Nonce":8435,"Data":{"OrderType":"LimitOffer","OrderGuid":"bd7eb910-7df7-40f3-a2a8-84ba7d535de6"},"Time":1649023835241,"Event":"OrderCanceled"}
1649023835.350743: {"Channel":"orderbook-bch","Nonce":8436,"Data":{"OrderType":"LimitOffer","OrderGuid":"11c1aea0-5b9a-4ea6-9031-578c8a0fb7d7"},"Time":1649023835241,"Event":"OrderCanceled"}
1649023835.350792: {"Channel":"orderbook-bch","Nonce":8437,"Data":{"OrderType":"LimitBid","OrderGuid":"536547ab-98f8-42e8-b751-d25fe6698117","Price":{"aud":503.4,"usd":375.23,"nzd":541.75,"sgd":510.19},"Volume":6.0},"Time":1649023835241,"Event":"NewOrder"}
1649023835.379264: {"Channel":"orderbook-eth","Nonce":19783,"Data":{"OrderType":"LimitBid","OrderGuid":"57596736-82a2-4d55-a026-e9ac8f4b563c","Price":{"aud":4726.4,"usd":3523.05,"nzd":5086.55,"sgd":4790.2},"Volume":15.0},"Time":1649023835272,"Event":"NewOrder"}
1649023835.4324: {"Channel":"orderbook-bch","Nonce":8438,"Data":{"OrderType":"LimitBid","OrderGuid":"92eb52cd-9aaa-4b32-a4c1-f6319be34080","Price":{"aud":504.1,"usd":375.75,"nzd":542.51,"sgd":510.9},"Volume":6.0},"Time":1649023835335,"Event":"NewOrder"}
1649023835.444393: {"Channel":"orderbook-bch","Nonce":8439,"Data":{"OrderType":"LimitOffer","OrderGuid":"03c1d67e-236d-416b-9158-7eb21e74d19f","Price":{"aud":506.8,"usd":381.57,"nzd":552.07,"sgd":516.83},"Volume":6.0},"Time":1649023835335,"Event":"NewOrder"}
1649023835.456527: {"Channel":"orderbook-bch","Nonce":8440,"Data":{"OrderType":"LimitOffer","OrderGuid":"13a96e09-04ea-464c-8dae-42899df0813f","Price":{"aud":507.5,"usd":382.1,"nzd":552.84,"sgd":517.55},"Volume":6.0},"Time":1649023835350,"Event":"NewOrder"}
1649023835.475817: {"Channel":"orderbook-eth","Nonce":19784,"Data":{"OrderType":"LimitOffer","OrderGuid":"246462af-4bb3-41f4-8d4a-cc5b14598160","Price":{"aud":4733.6,"usd":3563.93,"nzd":5156.43,"sgd":4827.25},"Volume":15.0},"Time":1649023835366,"Event":"NewOrder"}
1649023835.481336: {"Channel":"orderbook-eth","Nonce":19785,"Data":{"OrderType":"LimitOffer","OrderGuid":"390057e4-6f2e-465b-aa9d-620f477a1780","Price":{"aud":4736.6,"usd":3566.18,"nzd":5159.7,"sgd":4830.31},"Volume":15.0},"Time":1649023835382,"Event":"NewOrder"}
1649023835.494682: {"Channel":"orderbook-bch","Nonce":8441,"Data":{"OrderType":"LimitOffer","OrderGuid":"d0849d3c-6a88-4c4a-929b-f877139933e8"},"Time":1649023835397,"Event":"OrderCanceled"}
1649023835.494744: {"Channel":"orderbook-bch","Nonce":8442,"Data":{"OrderType":"LimitOffer","OrderGuid":"13a96e09-04ea-464c-8dae-42899df0813f"},"Time":1649023835397,"Event":"OrderCanceled"}
1649023835.4989061: {"Channel":"orderbook-bch","Nonce":8443,"Data":{"OrderType":"LimitOffer","OrderGuid":"03c1d67e-236d-416b-9158-7eb21e74d19f"},"Time":1649023835397,"Event":"OrderCanceled"}
1649023835.503305: {"Channel":"orderbook-dot","Nonce":5049,"Data":{"OrderType":"LimitOffer","OrderGuid":"4075855f-57c1-48a2-8f6b-6d3302117839"},"Time":1649023835397,"Event":"OrderCanceled"}
1649023835.539783: {"Channel":"orderbook-bch","Nonce":8444,"Data":{"OrderType":"LimitOffer","OrderGuid":"cc130fd4-258b-4aad-bc45-5463907218a3","Price":{"aud":506.7,"usd":381.5,"nzd":551.97,"sgd":516.73},"Volume":6.0},"Time":1649023835429,"Event":"NewOrder"}
1649023835.55266: {"Channel":"orderbook-bch","Nonce":8445,"Data":{"OrderType":"LimitOffer","OrderGuid":"54486d6f-7050-4b92-a8e8-c6052f5a7dc7","Price":{"aud":507.4,"usd":382.03,"nzd":552.73,"sgd":517.44},"Volume":6.0},"Time":1649023835444,"Event":"NewOrder"}
1649023835.584259: {"Channel":"orderbook-bch","Nonce":8446,"Data":{"OrderType":"LimitOffer","OrderGuid":"1cb1a050-f870-41da-9164-5d702848ea68","Price":{"aud":507.78,"usd":382.31,"nzd":553.14,"sgd":517.83},"Volume":1.09306259},"Time":1649023835477,"Event":"NewOrder"}
1649023835.584831: {"Channel":"orderbook-eth","Nonce":19786,"Data":{"OrderType":"LimitOffer","OrderGuid":"390057e4-6f2e-465b-aa9d-620f477a1780"},"Time":1649023835477,"Event":"OrderCanceled"}
1649023835.6057842: {"Channel":"orderbook-eth","Nonce":19787,"Data":{"OrderType":"LimitBid","OrderGuid":"57596736-82a2-4d55-a026-e9ac8f4b563c"},"Time":1649023835508,"Event":"OrderCanceled"}
1649023835.605886: {"Channel":"orderbook-dot","Nonce":5050,"Data":{"OrderType":"LimitOffer","OrderGuid":"6aa80248-c87c-46be-82a6-a51d558b62f5","Price":{"aud":31.5094,"usd":23.7234,"nzd":34.324,"sgd":32.1328},"Volume":21.98115},"Time":1649023835508,"Event":"NewOrder"}
1649023835.6228569: {"Channel":"orderbook-matic","Nonce":6015,"Data":{"OrderType":"LimitOffer","OrderGuid":"4ec727b3-b995-41b7-a612-8e2f5ab051a1"},"Time":1649023835524,"Event":"OrderCanceled"}
1649023835.637792: {"Channel":"orderbook-matic","Nonce":6016,"Data":{"OrderType":"LimitOffer","OrderGuid":"976d6dbc-ba89-480e-bbe3-3f92ddbdc4c9"},"Time":1649023835539,"Event":"OrderCanceled"}
1649023835.6505868: {"Channel":"orderbook-bch","Nonce":8447,"Data":{"OrderType":"LimitOffer","OrderGuid":"1998b9ef-7d5b-49aa-88de-2f44d23b2990","Price":{"aud":510.58,"usd":384.42,"nzd":556.19,"sgd":520.69},"Volume":2.93},"Time":1649023835539,"Event":"NewOrder"}
1649023835.665941: {"Channel":"orderbook-matic","Nonce":6017,"Data":{"OrderType":"LimitBid","OrderGuid":"7d2f8889-1485-4794-8d63-9cb18507323a"},"Time":1649023835555,"Event":"OrderCanceled"}
1649023835.675004: {"Channel":"orderbook-matic","Nonce":6018,"Data":{"OrderType":"LimitOffer","OrderGuid":"993018a2-368d-4e0a-935b-0cac3e4881a7","Price":{"aud":2.2725,"usd":1.71097,"nzd":2.4755,"sgd":2.31746},"Volume":5583.0},"Time":1649023835570,"Event":"NewOrder"}
1649023835.675128: {"Channel":"orderbook-matic","Nonce":6019,"Data":{"OrderType":"LimitBid","OrderGuid":"5e360d43-a9f5-4ff6-a9b5-8e940edfff0f"},"Time":1649023835570,"Event":"OrderCanceled"}
1649023835.689832: {"Channel":"orderbook-matic","Nonce":6020,"Data":{"OrderType":"LimitOffer","OrderGuid":"50c4dc26-131f-432a-8248-8cbd5e1d1c8f","Price":{"aud":2.274,"usd":1.7121,"nzd":2.47713,"sgd":2.31899},"Volume":5583.0},"Time":1649023835586,"Event":"NewOrder"}
1649023835.6926908: {"Channel":"orderbook-eth","Nonce":19788,"Data":{"OrderType":"LimitOffer","OrderGuid":"246462af-4bb3-41f4-8d4a-cc5b14598160"},"Time":1649023835586,"Event":"OrderCanceled"}
1649023835.698981: {"Channel":"orderbook-eth","Nonce":19789,"Data":{"OrderType":"LimitBid","OrderGuid":"5dab94f1-d8bf-4579-b8a5-23082958c65a","Price":{"aud":4726.1,"usd":3522.83,"nzd":5086.22,"sgd":4789.9},"Volume":15.0},"Time":1649023835602,"Event":"NewOrder"}
1649023835.7046669: {"Channel":"orderbook-eth","Nonce":19790,"Data":{"OrderType":"LimitBid","OrderGuid":"9c31b824-271c-4af3-afd2-da63c3534ff8","Price":{"aud":4723.1,"usd":3520.59,"nzd":5083.0,"sgd":4786.86},"Volume":15.0},"Time":1649023835602,"Event":"NewOrder"}
1649023835.7062101: {"Channel":"orderbook-matic","Nonce":6021,"Data":{"OrderType":"LimitBid","OrderGuid":"dd6f89d3-2ca1-4b1b-a45e-8a5f5006c170","Price":{"aud":2.2615,"usd":1.68572,"nzd":2.43382,"sgd":2.29203},"Volume":5583.0},"Time":1649023835602,"Event":"NewOrder"}
1649023835.711387: {"Channel":"orderbook-matic","Nonce":6022,"Data":{"OrderType":"LimitBid","OrderGuid":"5a2cd6b3-d355-46dc-b858-749567e32899","Price":{"aud":2.26,"usd":1.6846,"nzd":2.43221,"sgd":2.29051},"Volume":5583.0},"Time":1649023835602,"Event":"NewOrder"}
1649023835.713214: {"Channel":"orderbook-bch","Nonce":8448,"Data":{"OrderType":"LimitOffer","OrderGuid":"9ddb6b0a-d6d2-4dfb-99fc-4be3a756beff"},"Time":1649023835602,"Event":"OrderCanceled"}
1649023835.733276: {"Channel":"orderbook-eth","Nonce":19791,"Data":{"OrderType":"LimitOffer","OrderGuid":"5df46f77-4504-414c-ad4a-9dfdcd2cc03b","Price":{"aud":4736.3,"usd":3565.96,"nzd":5159.37,"sgd":4830.01},"Volume":15.0},"Time":1649023835633,"Event":"NewOrder"}
1649023835.766911: {"Channel":"orderbook-bch","Nonce":8449,"Data":{"OrderType":"LimitBid","OrderGuid":"536547ab-98f8-42e8-b751-d25fe6698117"},"Time":1649023835664,"Event":"OrderCanceled"}
1649023835.823951: {"Channel":"orderbook-eth","Nonce":19792,"Data":{"OrderType":"LimitOffer","OrderGuid":"8c8cf6b3-ef56-494c-9283-24d7ac59a78e"},"Time":1649023835727,"Event":"OrderCanceled"}
1649023835.837821: {"Channel":"orderbook-eth","Nonce":19793,"Data":{"OrderType":"LimitBid","OrderGuid":"9c31b824-271c-4af3-afd2-da63c3534ff8"},"Time":1649023835727,"Event":"OrderCanceled"}
1649023835.8485959: {"Channel":"orderbook-eth","Nonce":19794,"Data":{"OrderType":"LimitOffer","OrderGuid":"5df46f77-4504-414c-ad4a-9dfdcd2cc03b"},"Time":1649023835742,"Event":"OrderCanceled"}
1649023835.8487082: {"Channel":"orderbook-bch","Nonce":8450,"Data":{"OrderType":"LimitOffer","OrderGuid":"5760736f-b672-4064-9d53-df51fc4ec98e","Price":{"aud":507.68,"usd":382.24,"nzd":553.03,"sgd":517.73},"Volume":1.09306259},"Time":1649023835742,"Event":"NewOrder"}
1649023835.8603861: {"Channel":"orderbook-eth","Nonce":19795,"Data":{"OrderType":"LimitOffer","OrderGuid":"be74b1b4-b7d3-4e98-893c-e7f88dd80426","Price":{"aud":4792.99,"usd":3572.69,"nzd":5195.89,"sgd":4862.79},"Volume":0.53345276},"Time":1649023835758,"Event":"NewOrder"}
1649023835.882072: {"Channel":"orderbook-bch","Nonce":8451,"Data":{"OrderType":"LimitBid","OrderGuid":"92eb52cd-9aaa-4b32-a4c1-f6319be34080"},"Time":1649023835774,"Event":"OrderCanceled"}
1649023835.886168: {"Channel":"orderbook-dot","Nonce":5051,"Data":{"OrderType":"LimitBid","OrderGuid":"6b8dba6e-0867-46fc-ac6b-1979415fed45"},"Time":1649023835789,"Event":"OrderCanceled"}
1649023835.890584: {"Channel":"orderbook-dot","Nonce":5052,"Data":{"OrderType":"LimitBid","OrderGuid":"bcbe0023-62f4-41fe-aa0c-ac82bbe012db"},"Time":1649023835789,"Event":"OrderCanceled"}
1649023835.9209468: {"Channel":"orderbook-bch","Nonce":8452,"Data":{"OrderType":"LimitBid","OrderGuid":"a3eaf6f1-733d-4702-b1c4-0108e88d6cbf","Price":{"aud":503.9,"usd":375.6,"nzd":542.29,"sgd":510.7},"Volume":6.0},"Time":1649023835820,"Event":"NewOrder"}
1649023835.925015: {"Channel":"orderbook-bch","Nonce":8453,"Data":{"OrderType":"LimitBid","OrderGuid":"d4a04c01-8ef7-4add-b098-1bbd67d7a901","Price":{"aud":503.2,"usd":375.08,"nzd":541.54,"sgd":509.99},"Volume":6.0},"Time":1649023835820,"Event":"NewOrder"}
1649023835.9292438: {"Channel":"orderbook-dot","Nonce":5053,"Data":{"OrderType":"LimitBid","OrderGuid":"02f4f664-eaa8-4b8e-9f9a-1c2c7be62115","Price":{"aud":31.15,"usd":23.2192,"nzd":33.5236,"sgd":31.5705},"Volume":80.0},"Time":1649023835820,"Event":"NewOrder"}
1649023835.93694: {"Channel":"orderbook-eth","Nonce":19796,"Data":{"OrderType":"LimitOffer","OrderGuid":"39e96e1a-4278-4164-8c7e-7ad7e1bccfec","Price":{"aud":4736.1,"usd":3565.81,"nzd":5159.16,"sgd":4829.8},"Volume":15.0},"Time":1649023835836,"Event":"NewOrder"}
1649023835.93989: {"Channel":"orderbook-eth","Nonce":19797,"Data":{"OrderType":"LimitBid","OrderGuid":"5dab94f1-d8bf-4579-b8a5-23082958c65a"},"Time":1649023835836,"Event":"OrderCanceled"}
1649023835.957957: {"Channel":"orderbook-eth","Nonce":19798,"Data":{"OrderType":"LimitBid","OrderGuid":"af05a967-8272-4709-9132-089010b66598","Price":{"aud":4668.81,"usd":3480.13,"nzd":5024.57,"sgd":4731.83},"Volume":0.1952151},"Time":1649023835852,"Event":"NewOrder"}
1649023836.008469: {"Channel":"orderbook-eth","Nonce":19799,"Data":{"OrderType":"LimitBid","OrderGuid":"7d7f559e-bc61-4a6d-bb5c-0f1727965710"},"Time":1649023835899,"Event":"OrderCanceled"}
1649023836.022049: {"Channel":"orderbook-dot","Nonce":5054,"Data":{"OrderType":"LimitBid","OrderGuid":"7b46bfc7-2742-4047-8469-7313ead95f00","Price":{"aud":31.19,"usd":23.249,"nzd":33.5666,"sgd":31.611},"Volume":80.0},"Time":1649023835914,"Event":"NewOrder"}
1649023836.038441: {"Channel":"orderbook-matic","Nonce":6023,"Data":{"OrderType":"LimitBid","OrderGuid":"8d3c8af2-4734-4449-aa2d-6d0712ee0b7c"},"Time":1649023835930,"Event":"OrderCanceled"}
1649023836.048032: {"Channel":"orderbook-matic","Nonce":6024,"Data":{"OrderType":"LimitOffer","OrderGuid":"665b7b2f-3d6f-4efd-845d-80c7cbc869d5"},"Time":1649023835945,"Event":"OrderCanceled"}
1649023836.050251: {"Channel":"orderbook-eth","Nonce":19800,"Data":{"OrderType":"LimitOffer","OrderGuid":"39e96e1a-4278-4164-8c7e-7ad7e1bccfec"},"Time":1649023835945,"Event":"OrderCanceled"}
1649023836.0528011: {"Channel":"orderbook-eth","Nonce":19801,"Data":{"OrderType":"LimitBid","OrderGuid":"2f7c8058-e6b2-401b-af5d-9fdf955022bf","Price":{"aud":4726.0,"usd":3522.76,"nzd":5086.12,"sgd":4789.8},"Volume":15.0},"Time":1649023835945,"Event":"NewOrder"}
1649023836.058173: {"Channel":"orderbook-eth","Nonce":19802,"Data":{"OrderType":"LimitBid","OrderGuid":"e46a2e73-edbf-45ba-9d73-7800a6b82a8e","Price":{"aud":4723.0,"usd":3520.52,"nzd":5082.89,"sgd":4786.76},"Volume":15.0},"Time":1649023835945,"Event":"NewOrder"}
1649023836.092513: {"Channel":"orderbook-matic","Nonce":6025,"Data":{"OrderType":"LimitBid","OrderGuid":"fa53555a-981a-4b0a-bcf5-2ed95a199ace","Price":{"aud":2.26151,"usd":1.68572,"nzd":2.43383,"sgd":2.29204},"Volume":5378.31665},"Time":1649023835993,"Event":"NewOrder"}
1649023836.092575: {"Channel":"orderbook-matic","Nonce":6026,"Data":{"OrderType":"LimitOffer","OrderGuid":"05e31390-f756-4a24-b3a4-062332dc43c7","Price":{"aud":2.27249,"usd":1.71096,"nzd":2.47548,"sgd":2.31745},"Volume":5012.30746},"Time":1649023835993,"Event":"NewOrder"}
1649023836.0957341: {"Channel":"orderbook-eth","Nonce":19803,"Data":{"OrderType":"LimitOffer","OrderGuid":"2c52519b-9fab-4686-86c0-25a9a3d455d1","Price":{"aud":4736.2,"usd":3565.88,"nzd":5159.26,"sgd":4829.91},"Volume":15.0},"Time":1649023835993,"Event":"NewOrder"}
1649023836.100221: {"Channel":"orderbook-eth","Nonce":19804,"Data":{"OrderType":"LimitBid","OrderGuid":"1587ee01-1133-4b7b-8a35-2906a7d3f430"},"Time":1649023835993,"Event":"OrderCanceled"}
1649023836.115183: {"Channel":"orderbook-eth","Nonce":19805,"Data":{"OrderType":"LimitBid","OrderGuid":"d61ebc0b-8a48-4186-8999-662f7f7ecb34"},"Time":1649023836009,"Event":"OrderCanceled"}
1649023836.156945: {"Channel":"orderbook-eth","Nonce":19806,"Data":{"OrderType":"LimitBid","OrderGuid":"95af8981-5364-4c0b-b714-8556e8fd8c20","Price":{"aud":4704.04,"usd":3506.39,"nzd":5062.48,"sgd":4767.54},"Volume":0.39393589},"Time":1649023836056,"Event":"NewOrder"}
1649023836.157003: {"Channel":"orderbook-eth","Nonce":19807,"Data":{"OrderType":"LimitBid","OrderGuid":"18b2275a-bf72-4f50-a742-8e9ce4b65365","Price":{"aud":4696.88,"usd":3519.07,"nzd":5085.82,"sgd":4789.81},"Volume":3.0133277},"Time":1649023836056,"Event":"NewOrder"}
1649023836.16887: {"Channel":"orderbook-matic","Nonce":6027,"Data":{"OrderType":"LimitBid","OrderGuid":"dd6f89d3-2ca1-4b1b-a45e-8a5f5006c170"},"Time":1649023836071,"Event":"OrderCanceled"}
1649023836.177661: {"Channel":"orderbook-matic","Nonce":6028,"Data":{"OrderType":"LimitBid","OrderGuid":"5a2cd6b3-d355-46dc-b858-749567e32899"},"Time":1649023836071,"Event":"OrderCanceled"}
1649023836.191543: {"Channel":"orderbook-eth","Nonce":19808,"Data":{"OrderType":"LimitOffer","OrderGuid":"6b4d5095-4b09-443d-ac63-58798921aca6","Price":{"aud":4733.2,"usd":3563.62,"nzd":5156.0,"sgd":4826.85},"Volume":15.0},"Time":1649023836087,"Event":"NewOrder"}
1649023836.206739: {"Channel":"orderbook-matic","Nonce":6029,"Data":{"OrderType":"LimitBid","OrderGuid":"bb5163ea-eb36-418d-9b44-35877fd06ba6","Price":{"aud":2.262,"usd":1.68609,"nzd":2.43436,"sgd":2.29253},"Volume":5583.0},"Time":1649023836102,"Event":"NewOrder"}
1649023836.232388: {"Channel":"orderbook-matic","Nonce":6030,"Data":{"OrderType":"LimitBid","OrderGuid":"b2648004-aa50-4391-be94-29763abba54f","Price":{"aud":2.2605,"usd":1.68497,"nzd":2.43275,"sgd":2.29101},"Volume":5583.0},"Time":1649023836134,"Event":"NewOrder"}
1649023836.299856: {"Channel":"orderbook-dot","Nonce":5055,"Data":{"OrderType":"LimitOffer","OrderGuid":"70dab49b-45df-4a60-8b2b-c889e3f2b1e8","Price":{"aud":31.3898,"usd":23.6334,"nzd":34.1937,"sgd":32.0109},"Volume":19.94376},"Time":1649023836196,"Event":"NewOrder"}
1649023836.345902: {"Channel":"orderbook-eth","Nonce":19809,"Data":{"OrderType":"LimitBid","OrderGuid":"553c20d4-08d6-40bb-b9dc-c5e27ca9f68e"},"Time":1649023836243,"Event":"OrderCanceled"}
1649023836.41678: {"Channel":"orderbook-dot","Nonce":5056,"Data":{"OrderType":"LimitOffer","OrderGuid":"6aa80248-c87c-46be-82a6-a51d558b62f5"},"Time":1649023836306,"Event":"OrderCanceled"}
1649023836.4285922: {"Channel":"orderbook-dot","Nonce":5057,"Data":{"OrderType":"LimitOffer","OrderGuid":"13c60e80-8296-43ba-a36d-34070c06ff2c"},"Time":1649023836322,"Event":"OrderCanceled"}
1649023836.42864: {"Channel":"orderbook-eth","Nonce":19810,"Data":{"OrderType":"LimitBid","OrderGuid":"cdab9a69-7ef8-4501-ad76-3d5e59ec0ab5","Price":{"aud":4678.22,"usd":3504.08,"nzd":5096.11,"sgd":4769.95},"Volume":0.51637766},"Time":1649023836322,"Event":"NewOrder"}
1649023836.438209: {"Channel":"orderbook-eth","Nonce":19811,"Data":{"OrderType":"LimitOffer","OrderGuid":"8d0346f2-cbf4-4f7e-9f46-93478f1a254f","Price":{"aud":4755.06,"usd":3562.17,"nzd":5148.78,"sgd":4819.25},"Volume":4.561},"Time":1649023836338,"Event":"NewOrder"}
1649023836.4412549: {"Channel":"orderbook-matic","Nonce":6031,"Data":{"OrderType":"LimitBid","OrderGuid":"b2648004-aa50-4391-be94-29763abba54f"},"Time":1649023836338,"Event":"OrderCanceled"}
1649023836.443409: {"Channel":"orderbook-eth","Nonce":19812,"Data":{"OrderType":"LimitOffer","OrderGuid":"3fb2a7fa-94ab-4b31-a03a-e6bba641a695","Price":{"aud":4736.29,"usd":3565.95,"nzd":5159.36,"sgd":4830.0},"Volume":4.47331033},"Time":1649023836338,"Event":"NewOrder"}
1649023836.445795: {"Channel":"orderbook-matic","Nonce":6032,"Data":{"OrderType":"LimitBid","OrderGuid":"bb5163ea-eb36-418d-9b44-35877fd06ba6"},"Time":1649023836338,"Event":"OrderCanceled"}
1649023836.4479659: {"Channel":"orderbook-eth","Nonce":19813,"Data":{"OrderType":"LimitOffer","OrderGuid":"74b87e3c-357e-4e56-ace8-493f36e451a1"},"Time":1649023836338,"Event":"OrderCanceled"}
1649023836.448769: {"Channel":"orderbook-dot","Nonce":5058,"Data":{"OrderType":"LimitOffer","OrderGuid":"eb1c2f47-d9e5-4428-9397-0a1fa3b0b2b9","Price":{"aud":31.5095,"usd":23.7235,"nzd":34.3241,"sgd":32.1329},"Volume":14.72539},"Time":1649023836338,"Event":"NewOrder"}
1649023836.470134: {"Channel":"orderbook-dot","Nonce":5059,"Data":{"OrderType":"LimitOffer","OrderGuid":"6979c753-a29a-44ea-85e2-39acc16edaf4"},"Time":1649023836369,"Event":"OrderCanceled"}
1649023836.4788501: {"Channel":"orderbook-matic","Nonce":6033,"Data":{"OrderType":"LimitBid","OrderGuid":"ecb23b2f-2005-4a5d-a498-5fad5a47084d","Price":{"aud":2.2615,"usd":1.68572,"nzd":2.43382,"sgd":2.29203},"Volume":5583.0},"Time":1649023836369,"Event":"NewOrder"}
1649023836.485461: {"Channel":"orderbook-matic","Nonce":6034,"Data":{"OrderType":"LimitBid","OrderGuid":"d80f9ae8-d644-4116-b50a-32159a2cd16f","Price":{"aud":2.26,"usd":1.6846,"nzd":2.43221,"sgd":2.29051},"Volume":5583.0},"Time":1649023836384,"Event":"NewOrder"}
1649023836.5352662: {"Channel":"orderbook-dot","Nonce":5060,"Data":{"OrderType":"LimitOffer","OrderGuid":"7512f459-075f-416d-b176-4109eb4f787e","Price":{"aud":31.4349,"usd":23.6673,"nzd":34.2429,"sgd":32.0569},"Volume":28.9554},"Time":1649023836431,"Event":"NewOrder"}
1649023836.569498: {"Channel":"orderbook-eth","Nonce":19814,"Data":{"OrderType":"LimitBid","OrderGuid":"18b2275a-bf72-4f50-a742-8e9ce4b65365"},"Time":1649023836462,"Event":"OrderCanceled"}
1649023836.5695539: {"Channel":"orderbook-eth","Nonce":19815,"Data":{"OrderType":"LimitBid","OrderGuid":"e46a2e73-edbf-45ba-9d73-7800a6b82a8e"},"Time":1649023836462,"Event":"OrderCanceled"}
1649023836.583373: {"Channel":"orderbook-eth","Nonce":19816,"Data":{"OrderType":"LimitOffer","OrderGuid":"2c52519b-9fab-4686-86c0-25a9a3d455d1"},"Time":1649023836478,"Event":"OrderCanceled"}
1649023836.593238: {"Channel":"orderbook-eth","Nonce":19817,"Data":{"OrderType":"LimitOffer","OrderGuid":"ea89c630-ca4b-4fbc-af9a-1693cffb6748"},"Time":1649023836494,"Event":"OrderCanceled"}
1649023836.596363: {"Channel":"orderbook-eth","Nonce":19818,"Data":{"OrderType":"LimitOffer","OrderGuid":"be74b1b4-b7d3-4e98-893c-e7f88dd80426"},"Time":1649023836494,"Event":"OrderCanceled"}
1649023836.604864: {"Channel":"orderbook-eth","Nonce":19819,"Data":{"OrderType":"LimitOffer","OrderGuid":"7e31d3d7-603b-4518-9e2c-351238d71dbc"},"Time":1649023836494,"Event":"OrderCanceled"}
1649023836.604917: {"Channel":"orderbook-bch","Nonce":8454,"Data":{"OrderType":"LimitOffer","OrderGuid":"1cb1a050-f870-41da-9164-5d702848ea68"},"Time":1649023836494,"Event":"OrderCanceled"}
1649023836.6068459: {"Channel":"orderbook-eth","Nonce":19820,"Data":{"OrderType":"LimitBid","OrderGuid":"7eaf5ea5-485c-4e5a-a2c6-327fc02c6f84","Price":{"aud":4696.3,"usd":3518.63,"nzd":5085.19,"sgd":4789.22},"Volume":3.05073616},"Time":1649023836494,"Event":"NewOrder"}
1649023836.630883: {"Channel":"orderbook-eth","Nonce":19821,"Data":{"OrderType":"LimitOffer","OrderGuid":"4347d8fd-f75b-4cd7-946d-4a7cb2f0f720","Price":{"aud":4756.08,"usd":3562.93,"nzd":5149.88,"sgd":4820.28},"Volume":1.05465041},"Time":1649023836525,"Event":"NewOrder"}
1649023836.647369: {"Channel":"orderbook-eth","Nonce":19822,"Data":{"OrderType":"LimitBid","OrderGuid":"7eaf5ea5-485c-4e5a-a2c6-327fc02c6f84"},"Time":1649023836541,"Event":"OrderCanceled"}
1649023836.647476: {"Channel":"orderbook-eth","Nonce":19823,"Data":{"OrderType":"LimitOffer","OrderGuid":"e7b54e09-596f-4c5a-9abf-74f10827d1bd","Price":{"aud":4792.37,"usd":3572.23,"nzd":5195.22,"sgd":4862.17},"Volume":0.57594827},"Time":1649023836541,"Event":"NewOrder"}
1649023836.66715: {"Channel":"orderbook-eth","Nonce":19824,"Data":{"OrderType":"LimitOffer","OrderGuid":"6b4d5095-4b09-443d-ac63-58798921aca6"},"Time":1649023836556,"Event":"OrderCanceled"}
1649023836.667212: {"Channel":"orderbook-eth","Nonce":19825,"Data":{"OrderType":"LimitBid","OrderGuid":"2f7c8058-e6b2-401b-af5d-9fdf955022bf"},"Time":1649023836556,"Event":"OrderCanceled"}
1649023836.681199: {"Channel":"orderbook-eth","Nonce":19826,"Data":{"OrderType":"LimitBid","OrderGuid":"a406a29c-04fb-476b-a499-e6677b28fe87","Price":{"aud":4696.88,"usd":3519.07,"nzd":5085.82,"sgd":4789.81},"Volume":3.14242249},"Time":1649023836572,"Event":"NewOrder"}
1649023836.697928: {"Channel":"orderbook-matic","Nonce":6035,"Data":{"OrderType":"LimitBid","OrderGuid":"fa53555a-981a-4b0a-bcf5-2ed95a199ace"},"Time":1649023836587,"Event":"OrderCanceled"}
1649023836.6980338: {"Channel":"orderbook-bch","Nonce":8455,"Data":{"OrderType":"LimitOffer","OrderGuid":"1998b9ef-7d5b-49aa-88de-2f44d23b2990"},"Time":1649023836587,"Event":"OrderCanceled"}
1649023836.718354: {"Channel":"orderbook-eth","Nonce":19827,"Data":{"OrderType":"LimitBid","OrderGuid":"daf45e61-484a-4a5b-8c87-89be54e16058","Price":{"aud":4726.1,"usd":3522.83,"nzd":5086.22,"sgd":4789.9},"Volume":15.0},"Time":1649023836619,"Event":"NewOrder"}
1649023836.7351449: {"Channel":"orderbook-eth","Nonce":19828,"Data":{"OrderType":"LimitBid","OrderGuid":"bb015837-f38a-41d0-982d-f77d36ae233d","Price":{"aud":4723.1,"usd":3520.59,"nzd":5083.0,"sgd":4786.86},"Volume":15.0},"Time":1649023836634,"Event":"NewOrder"}
1649023836.735266: {"Channel":"orderbook-dot","Nonce":5061,"Data":{"OrderType":"LimitBid","OrderGuid":"bad97b65-ae16-404c-b7a9-7f5953db1d02"},"Time":1649023836634,"Event":"OrderCanceled"}
1649023836.7726111: {"Channel":"orderbook-eth","Nonce":19829,"Data":{"OrderType":"LimitOffer","OrderGuid":"027b3b6b-a497-415d-a36d-5d04a0238a9c","Price":{"aud":4756.07,"usd":3580.84,"nzd":5180.91,"sgd":4850.17},"Volume":7.96},"Time":1649023836666,"Event":"NewOrder"}
1649023836.782358: {"Channel":"orderbook-dot","Nonce":5062,"Data":{"OrderType":"LimitOffer","OrderGuid":"83f929f1-42fa-4832-9a2d-4996270b9631","Price":{"aud":31.3696,"usd":23.6182,"nzd":34.1717,"sgd":31.9903},"Volume":19.94376},"Time":1649023836681,"Event":"NewOrder"}
1649023836.782419: {"Channel":"orderbook-matic","Nonce":6036,"Data":{"OrderType":"LimitBid","OrderGuid":"04838ada-4922-40ec-9cbe-e7609c4d89e7","Price":{"aud":2.26001,"usd":1.68461,"nzd":2.43222,"sgd":2.29052},"Volume":5236.76149},"Time":1649023836681,"Event":"NewOrder"}
1649023836.826998: {"Channel":"orderbook-eth","Nonce":19830,"Data":{"OrderType":"LimitBid","OrderGuid":"daf45e61-484a-4a5b-8c87-89be54e16058"},"Time":1649023836729,"Event":"OrderCanceled"}
1649023836.830988: {"Channel":"orderbook-bch","Nonce":8456,"Data":{"OrderType":"LimitOffer","OrderGuid":"cc130fd4-258b-4aad-bc45-5463907218a3"},"Time":1649023836729,"Event":"OrderCanceled"}
1649023836.8346071: {"Channel":"orderbook-eth","Nonce":19831,"Data":{"OrderType":"LimitOffer","OrderGuid":"969073b2-48fc-4bcc-a5ed-695e48709b41","Price":{"aud":4736.3,"usd":3565.96,"nzd":5159.37,"sgd":4830.01},"Volume":15.0},"Time":1649023836729,"Event":"NewOrder"}
1649023836.8346722: {"Channel":"orderbook-bch","Nonce":8457,"Data":{"OrderType":"LimitOffer","OrderGuid":"54486d6f-7050-4b92-a8e8-c6052f5a7dc7"},"Time":1649023836729,"Event":"OrderCanceled"}
1649023836.837017: {"Channel":"orderbook-bch","Nonce":8458,"Data":{"OrderType":"LimitOffer","OrderGuid":"ea56987f-7c49-4faa-ba7a-e96b11bef95d","Price":{"aud":507.78,"usd":382.31,"nzd":553.14,"sgd":517.83},"Volume":1.09306807},"Time":1649023836729,"Event":"NewOrder"}
1649023836.84269: {"Channel":"orderbook-bch","Nonce":8459,"Data":{"OrderType":"LimitOffer","OrderGuid":"95d25186-c9e4-42cf-b0d6-d11ba4432d5b","Price":{"aud":510.56,"usd":384.4,"nzd":556.17,"sgd":520.67},"Volume":2.93},"Time":1649023836745,"Event":"NewOrder"}
1649023836.859957: {"Channel":"orderbook-eth","Nonce":19832,"Data":{"OrderType":"LimitOffer","OrderGuid":"c95bc5de-30e5-4c5a-a0c3-2a5cfdcddd27","Price":{"aud":4733.3,"usd":3563.7,"nzd":5156.11,"sgd":4826.95},"Volume":15.0},"Time":1649023836761,"Event":"NewOrder"}
1649023836.867531: {"Channel":"orderbook-dot","Nonce":5063,"Data":{"OrderType":"LimitBid","OrderGuid":"e2eac989-6539-41b4-942b-e7213f52b13b","Price":{"aud":30.8032,"usd":22.9607,"nzd":33.1504,"sgd":31.219},"Volume":69.2},"Time":1649023836761,"Event":"NewOrder"}
1649023836.873387: {"Channel":"orderbook-bch","Nonce":8460,"Data":{"OrderType":"LimitOffer","OrderGuid":"099ebaca-10e4-465a-8c4f-f3070f46c6a9"},"Time":1649023836776,"Event":"OrderCanceled"}
1649023836.884725: {"Channel":"orderbook-bch","Nonce":8461,"Data":{"OrderType":"LimitOffer","OrderGuid":"8927c0ed-5d62-4bac-8bde-e9f25dfa5647","Price":{"aud":507.3,"usd":381.95,"nzd":552.62,"sgd":517.34},"Volume":6.0},"Time":1649023836776,"Event":"NewOrder"}
1649023836.88479: {"Channel":"orderbook-bch","Nonce":8462,"Data":{"OrderType":"LimitOffer","OrderGuid":"56f3e1ff-ded9-4cbd-82ba-61f9182f069f","Price":{"aud":510.55,"usd":384.4,"nzd":556.16,"sgd":520.66},"Volume":21.20858658},"Time":1649023836776,"Event":"NewOrder"}
1649023836.912975: {"Channel":"orderbook-bch","Nonce":8463,"Data":{"OrderType":"LimitOffer","OrderGuid":"5760736f-b672-4064-9d53-df51fc4ec98e"},"Time":1649023836808,"Event":"OrderCanceled"}
1649023836.931455: {"Channel":"orderbook-eth","Nonce":19833,"Data":{"OrderType":"LimitBid","OrderGuid":"bb015837-f38a-41d0-982d-f77d36ae233d"},"Time":1649023836823,"Event":"OrderCanceled"}
1649023836.9315279: {"Channel":"orderbook-eth","Nonce":19834,"Data":{"OrderType":"LimitOffer","OrderGuid":"c95bc5de-30e5-4c5a-a0c3-2a5cfdcddd27"},"Time":1649023836823,"Event":"OrderCanceled"}
1649023836.9368262: {"Channel":"orderbook-eth","Nonce":19835,"Data":{"OrderType":"LimitOffer","OrderGuid":"969073b2-48fc-4bcc-a5ed-695e48709b41"},"Time":1649023836839,"Event":"OrderCanceled"}
1649023836.953482: {"Channel":"orderbook-eth","Nonce":19836,"Data":{"OrderType":"LimitBid","OrderGuid":"a406a29c-04fb-476b-a499-e6677b28fe87"},"Time":1649023836854,"Event":"OrderCanceled"}
1649023836.956502: {"Channel":"orderbook-eth","Nonce":19837,"Data":{"OrderType":"LimitOffer","OrderGuid":"495abeb9-e43e-4126-bede-a588718eef35"},"Time":1649023836854,"Event":"OrderCanceled"}
1649023836.9594848: {"Channel":"orderbook-dot","Nonce":5064,"Data":{"OrderType":"LimitOffer","OrderGuid":"e88b65ac-ed8c-4e75-b858-1ce8fca6a328"},"Time":1649023836854,"Event":"OrderCanceled"}
1649023836.963748: {"Channel":"orderbook-dot","Nonce":5065,"Data":{"OrderType":"LimitOffer","OrderGuid":"2e0e899b-c45f-41ac-84e6-8e0f4afb8cbe"},"Time":1649023836854,"Event":"OrderCanceled"}
1649023836.9693289: {"Channel":"orderbook-bch","Nonce":8464,"Data":{"OrderType":"LimitOffer","OrderGuid":"457af996-6d28-4a8c-89bf-1103ed9301a5","Price":{"aud":506.6,"usd":381.42,"nzd":551.86,"sgd":516.63},"Volume":6.0},"Time":1649023836870,"Event":"NewOrder"}
1649023836.9713962: {"Channel":"orderbook-eth","Nonce":19838,"Data":{"OrderType":"LimitBid","OrderGuid":"2f5122b8-975f-4575-8257-98766f444be2"},"Time":1649023836870,"Event":"OrderCanceled"}
1649023836.976095: {"Channel":"orderbook-eth","Nonce":19839,"Data":{"OrderType":"LimitOffer","OrderGuid":"356ad2a5-a768-40bc-b682-31da56037fbe","Price":{"aud":4733.0,"usd":3563.47,"nzd":5155.78,"sgd":4826.64},"Volume":15.0},"Time":1649023836870,"Event":"NewOrder"}
1649023836.978899: {"Channel":"orderbook-eth","Nonce":19840,"Data":{"OrderType":"LimitOffer","OrderGuid":"6ffd1628-685f-4828-80fd-d7ca47aff2a2","Price":{"aud":4736.0,"usd":3565.73,"nzd":5159.05,"sgd":4829.7},"Volume":15.0},"Time":1649023836870,"Event":"NewOrder"}
1649023837.018913: {"Channel":"orderbook-bch","Nonce":8465,"Data":{"OrderType":"LimitOffer","OrderGuid":"d9d124b6-dc74-4c92-a0ad-c1a60c4c34ce","Price":{"aud":507.77,"usd":382.3,"nzd":553.13,"sgd":517.82},"Volume":1.09306807},"Time":1649023836917,"Event":"NewOrder"}
1649023837.019039: {"Channel":"orderbook-dot","Nonce":5066,"Data":{"OrderType":"LimitOffer","OrderGuid":"dbddb349-e797-4d38-abd8-c4be48f59de9","Price":{"aud":31.42,"usd":23.6561,"nzd":34.2266,"sgd":32.0417},"Volume":80.0},"Time":1649023836917,"Event":"NewOrder"}
1649023837.0327208: {"Channel":"orderbook-dot","Nonce":5067,"Data":{"OrderType":"LimitOffer","OrderGuid":"02ef0228-037f-42fc-bd35-4aa297bd5bbe","Price":{"aud":31.38,"usd":23.626,"nzd":34.1831,"sgd":32.0009},"Volume":80.0},"Time":1649023836933,"Event":"NewOrder"}
1649023837.032845: {"Channel":"orderbook-eth","Nonce":19841,"Data":{"OrderType":"LimitBid","OrderGuid":"f29919e8-a287-4baa-9654-84ebe4839885","Price":{"aud":4723.99,"usd":3521.26,"nzd":5083.95,"sgd":4787.76},"Volume":14.14},"Time":1649023836933,"Event":"NewOrder"}
1649023837.03332: {"Channel":"orderbook-eth","Nonce":19842,"Data":{"OrderType":"LimitBid","OrderGuid":"135ccfd6-a918-4931-9d51-d69da7a2e40f","Price":{"aud":4695.52,"usd":3518.05,"nzd":5084.34,"sgd":4788.42},"Volume":3.11752276},"Time":1649023836933,"Event":"NewOrder"}
1649023837.092266: {"Channel":"orderbook-matic","Nonce":6037,"Data":{"OrderType":"LimitBid","OrderGuid":"651689d9-dd0d-4509-8dba-e69238e3f22e"},"Time":1649023836979,"Event":"OrderCanceled"}
1649023837.092368: {"Channel":"orderbook-eth","Nonce":19843,"Data":{"OrderType":"LimitBid","OrderGuid":"f29919e8-a287-4baa-9654-84ebe4839885"},"Time":1649023836979,"Event":"OrderCanceled"}
1649023837.0924191: {"Channel":"orderbook-eth","Nonce":19844,"Data":{"OrderType":"LimitBid","OrderGuid":"2c92bf95-e312-44de-ad9e-3c29a9ccae1c","Price":{"aud":4722.8,"usd":3520.37,"nzd":5082.67,"sgd":4786.55},"Volume":15.0},"Time":1649023836979,"Event":"NewOrder"}
1649023837.103942: {"Channel":"orderbook-eth","Nonce":19845,"Data":{"OrderType":"LimitBid","OrderGuid":"135ccfd6-a918-4931-9d51-d69da7a2e40f"},"Time":1649023836995,"Event":"OrderCanceled"}
1649023837.104044: {"Channel":"orderbook-eth","Nonce":19846,"Data":{"OrderType":"LimitBid","OrderGuid":"baa51cdc-d583-4489-a7a8-306c94a5d983","Price":{"aud":4725.8,"usd":3522.61,"nzd":5085.9,"sgd":4789.59},"Volume":15.0},"Time":1649023836995,"Event":"NewOrder"}
1649023837.1104882: {"Channel":"orderbook-eth","Nonce":19847,"Data":{"OrderType":"LimitOffer","OrderGuid":"356ad2a5-a768-40bc-b682-31da56037fbe"},"Time":1649023837011,"Event":"OrderCanceled"}
1649023837.110592: {"Channel":"orderbook-bch","Nonce":8466,"Data":{"OrderType":"LimitBid","OrderGuid":"a3eaf6f1-733d-4702-b1c4-0108e88d6cbf"},"Time":1649023837011,"Event":"OrderCanceled"}
1649023837.110645: {"Channel":"orderbook-eth","Nonce":19848,"Data":{"OrderType":"LimitBid","OrderGuid":"7845bf49-ccfc-4f6c-ab6e-faab0ddebd41","Price":{"aud":4722.51,"usd":3520.15,"nzd":5082.36,"sgd":4786.26},"Volume":14.14},"Time":1649023837011,"Event":"NewOrder"}
1649023837.119976: {"Channel":"orderbook-eth","Nonce":19849,"Data":{"OrderType":"LimitOffer","OrderGuid":"6ffd1628-685f-4828-80fd-d7ca47aff2a2"},"Time":1649023837011,"Event":"OrderCanceled"}
1649023837.120099: {"Channel":"orderbook-bch","Nonce":8467,"Data":{"OrderType":"LimitBid","OrderGuid":"d4a04c01-8ef7-4add-b098-1bbd67d7a901"},"Time":1649023837011,"Event":"OrderCanceled"}
1649023837.151126: {"Channel":"orderbook-eth","Nonce":19850,"Data":{"OrderType":"LimitBid","OrderGuid":"2c92bf95-e312-44de-ad9e-3c29a9ccae1c"},"Time":1649023837042,"Event":"OrderCanceled"}
1649023837.151228: {"Channel":"orderbook-eth","Nonce":19851,"Data":{"OrderType":"LimitOffer","OrderGuid":"4b10d662-42cf-4600-93e9-8f9a050eb8db","Price":{"aud":4735.99,"usd":3565.73,"nzd":5159.04,"sgd":4829.69},"Volume":4.47331033},"Time":1649023837042,"Event":"NewOrder"}
1649023837.153814: {"Channel":"orderbook-eth","Nonce":19852,"Data":{"OrderType":"LimitBid","OrderGuid":"802776da-ef10-444e-878c-e6494de6d793","Price":{"aud":4696.3,"usd":3518.63,"nzd":5085.19,"sgd":4789.22},"Volume":3.14748046},"Time":1649023837042,"Event":"NewOrder"}
1649023837.15664: {"Channel":"orderbook-eth","Nonce":19853,"Data":{"OrderType":"LimitBid","OrderGuid":"baa51cdc-d583-4489-a7a8-306c94a5d983"},"Time":1649023837058,"Event":"OrderCanceled"}
1649023837.160044: {"Channel":"orderbook-bch","Nonce":8468,"Data":{"OrderType":"LimitBid","OrderGuid":"ae6f7be1-e0be-4581-8cfa-13477298da83","Price":{"aud":503.9,"usd":375.6,"nzd":542.29,"sgd":510.7},"Volume":6.0},"Time":1649023837058,"Event":"NewOrder"}
1649023837.1675909: {"Channel":"orderbook-bch","Nonce":8469,"Data":{"OrderType":"LimitBid","OrderGuid":"ee436e3b-6e26-4312-b993-fa634e16d16a","Price":{"aud":503.1,"usd":375.01,"nzd":541.43,"sgd":509.89},"Volume":6.0},"Time":1649023837058,"Event":"NewOrder"}
1649023837.1777039: {"Channel":"orderbook-eth","Nonce":19854,"Data":{"OrderType":"LimitBid","OrderGuid":"95af8981-5364-4c0b-b714-8556e8fd8c20"},"Time":1649023837073,"Event":"OrderCanceled"}
1649023837.2433121: {"Channel":"orderbook-eth","Nonce":19855,"Data":{"OrderType":"LimitOffer","OrderGuid":"3fb2a7fa-94ab-4b31-a03a-e6bba641a695"},"Time":1649023837136,"Event":"OrderCanceled"}
1649023837.252188: {"Channel":"orderbook-matic","Nonce":6038,"Data":{"OrderType":"LimitOffer","OrderGuid":"50c4dc26-131f-432a-8248-8cbd5e1d1c8f"},"Time":1649023837151,"Event":"OrderCanceled"}
1649023837.26604: {"Channel":"orderbook-matic","Nonce":6039,"Data":{"OrderType":"LimitOffer","OrderGuid":"993018a2-368d-4e0a-935b-0cac3e4881a7"},"Time":1649023837167,"Event":"OrderCanceled"}
1649023837.266103: {"Channel":"orderbook-matic","Nonce":6040,"Data":{"OrderType":"LimitBid","OrderGuid":"d80f9ae8-d644-4116-b50a-32159a2cd16f"},"Time":1649023837167,"Event":"OrderCanceled"}
1649023837.292989: {"Channel":"orderbook-eth","Nonce":19856,"Data":{"OrderType":"LimitBid","OrderGuid":"ddc2295b-7bc6-41e8-9419-2c52e11bba22","Price":{"aud":4704.05,"usd":3506.39,"nzd":5062.49,"sgd":4767.55},"Volume":0.38318652},"Time":1649023837167,"Event":"NewOrder"}
1649023837.293078: {"Channel":"orderbook-eth","Nonce":19857,"Data":{"OrderType":"LimitOffer","OrderGuid":"05645723-75d9-44f9-85f3-c2b17d886604","Price":{"aud":4735.0,"usd":3564.98,"nzd":5157.96,"sgd":4828.68},"Volume":15.0},"Time":1649023837167,"Event":"NewOrder"}
1649023837.293118: {"Channel":"orderbook-eth","Nonce":19858,"Data":{"OrderType":"LimitBid","OrderGuid":"9a34fe02-631a-48f8-8ae8-353393d4de27","Price":{"aud":4724.8,"usd":3521.86,"nzd":5084.82,"sgd":4788.58},"Volume":15.0},"Time":1649023837183,"Event":"NewOrder"}
1649023837.306568: {"Channel":"orderbook-eth","Nonce":19859,"Data":{"OrderType":"LimitOffer","OrderGuid":"c54b1b88-1457-4d50-a66b-dfea7080b7a7","Price":{"aud":4732.0,"usd":3562.72,"nzd":5154.69,"sgd":4825.62},"Volume":15.0},"Time":1649023837198,"Event":"NewOrder"}
1649023837.3179252: {"Channel":"orderbook-eth","Nonce":19860,"Data":{"OrderType":"LimitBid","OrderGuid":"aa0216bc-f30b-4d2b-9d6d-748b126d7567","Price":{"aud":4721.8,"usd":3519.62,"nzd":5081.6,"sgd":4785.54},"Volume":15.0},"Time":1649023837214,"Event":"NewOrder"}
1649023837.342504: {"Channel":"orderbook-eth","Nonce":19861,"Data":{"OrderType":"LimitOffer","OrderGuid":"ee7906b6-3c9c-4c65-9a1a-8db708211ddf","Price":{"aud":4734.99,"usd":3564.97,"nzd":5157.95,"sgd":4828.67},"Volume":4.47331033},"Time":1649023837229,"Event":"NewOrder"}
1649023837.351561: {"Channel":"orderbook-eth","Nonce":19862,"Data":{"OrderType":"LimitOffer","OrderGuid":"4b10d662-42cf-4600-93e9-8f9a050eb8db"},"Time":1649023837245,"Event":"OrderCanceled"}
1649023837.3572748: {"Channel":"orderbook-matic","Nonce":6041,"Data":{"OrderType":"LimitBid","OrderGuid":"ecb23b2f-2005-4a5d-a498-5fad5a47084d"},"Time":1649023837245,"Event":"OrderCanceled"}
1649023837.3573818: {"Channel":"orderbook-dot","Nonce":5068,"Data":{"OrderType":"LimitOffer","OrderGuid":"70dab49b-45df-4a60-8b2b-c889e3f2b1e8"},"Time":1649023837245,"Event":"OrderCanceled"}
1649023837.369261: {"Channel":"orderbook-matic","Nonce":6042,"Data":{"OrderType":"LimitOffer","OrderGuid":"965486fd-fb11-46e7-981c-44c9cfe434b3","Price":{"aud":2.2715,"usd":1.71021,"nzd":2.47441,"sgd":2.31644},"Volume":5583.0},"Time":1649023837261,"Event":"NewOrder"}
1649023837.3869781: {"Channel":"orderbook-eth","Nonce":19863,"Data":{"OrderType":"LimitBid","OrderGuid":"cdab9a69-7ef8-4501-ad76-3d5e59ec0ab5"},"Time":1649023837276,"Event":"OrderCanceled"}
1649023837.395604: {"Channel":"orderbook-bch","Nonce":8470,"Data":{"OrderType":"LimitOffer","OrderGuid":"c90cebce-2d0a-478d-9828-db28cad8c821"},"Time":1649023837292,"Event":"OrderCanceled"}
1649023837.397835: {"Channel":"orderbook-matic","Nonce":6043,"Data":{"OrderType":"LimitOffer","OrderGuid":"0680519b-345d-44da-9cdd-1655ba119145","Price":{"aud":2.273,"usd":1.71134,"nzd":2.47604,"sgd":2.31797},"Volume":5583.0},"Time":1649023837292,"Event":"NewOrder"}
1649023837.403241: {"Channel":"orderbook-matic","Nonce":6044,"Data":{"OrderType":"LimitBid","OrderGuid":"68ae6046-e673-4af7-9f24-280ace70023a","Price":{"aud":2.2605,"usd":1.68497,"nzd":2.43275,"sgd":2.29101},"Volume":5583.0},"Time":1649023837308,"Event":"NewOrder"}
1649023838.358977: {"Channel":"orderbook-matic","Nonce":6045,"Data":{"OrderType":"LimitBid","OrderGuid":"9e473ecd-e27b-4d04-b4af-06808a62cda0","Price":{"aud":2.259,"usd":1.68385,"nzd":2.43113,"sgd":2.28949},"Volume":5583.0},"Time":1649023837308,"Event":"NewOrder"}
1649023838.359052: {"Channel":"orderbook-eth","Nonce":19864,"Data":{"OrderType":"LimitBid","OrderGuid":"22fb768c-cdde-4346-98a1-6bef4d28512b","Price":{"aud":4678.23,"usd":3504.09,"nzd":5096.12,"sgd":4769.96},"Volume":0.47651058},"Time":1649023837323,"Event":"NewOrder"}
1649023838.359085: {"Channel":"orderbook-eth","Nonce":19865,"Data":{"OrderType":"LimitBid","OrderGuid":"a3571bed-8ed4-4424-99e6-a4ed1457ba8d"},"Time":1649023837323,"Event":"OrderCanceled"}
1649023838.3591192: {"Channel":"orderbook-bch","Nonce":8471,"Data":{"OrderType":"LimitOffer","OrderGuid":"24ef4f2e-2842-4e6e-8143-d81d03e7638a","Price":{"aud":508.84,"usd":383.11,"nzd":554.3,"sgd":518.91},"Volume":39.74331},"Time":1649023837417,"Event":"NewOrder"}
1649023838.359154: {"Channel":"orderbook-matic","Nonce":6046,"Data":{"OrderType":"LimitOffer","OrderGuid":"b53288d5-5e95-4245-8bfb-6d19edafea4b"},"Time":1649023837526,"Event":"OrderCanceled"}
1649023838.359176: {"Channel":"orderbook-eth","Nonce":19866,"Data":{"OrderType":"LimitBid","OrderGuid":"802776da-ef10-444e-878c-e6494de6d793"},"Time":1649023837715,"Event":"OrderCanceled"}
1649023838.3592: {"Channel":"orderbook-eth","Nonce":19867,"Data":{"OrderType":"LimitOffer","OrderGuid":"027b3b6b-a497-415d-a36d-5d04a0238a9c"},"Time":1649023837715,"Event":"OrderCanceled"}
1649023838.3592598: {"Channel":"orderbook-eth","Nonce":19868,"Data":{"OrderType":"LimitOffer","OrderGuid":"05645723-75d9-44f9-85f3-c2b17d886604"},"Time":1649023837810,"Event":"OrderCanceled"}
1649023838.359307: {"Channel":"orderbook-eth","Nonce":19869,"Data":{"OrderType":"LimitBid","OrderGuid":"9a34fe02-631a-48f8-8ae8-353393d4de27"},"Time":1649023837826,"Event":"OrderCanceled"}
1649023838.3593311: {"Channel":"orderbook-eth","Nonce":19870,"Data":{"OrderType":"LimitOffer","OrderGuid":"c54b1b88-1457-4d50-a66b-dfea7080b7a7"},"Time":1649023837826,"Event":"OrderCanceled"}
1649023838.359352: {"Channel":"orderbook-eth","Nonce":19871,"Data":{"OrderType":"LimitBid","OrderGuid":"dd13bd26-a6ea-47a3-a8af-45143bb979aa","Price":{"aud":4665.82,"usd":3477.9,"nzd":5021.35,"sgd":4728.8},"Volume":0.19522201},"Time":1649023837826,"Event":"NewOrder"}
1649023838.359381: {"Channel":"orderbook-eth","Nonce":19872,"Data":{"OrderType":"LimitOffer","OrderGuid":"4347d8fd-f75b-4cd7-946d-4a7cb2f0f720"},"Time":1649023837826,"Event":"OrderCanceled"}
1649023838.359402: {"Channel":"orderbook-eth","Nonce":19873,"Data":{"OrderType":"LimitBid","OrderGuid":"72c2627f-76a3-46bf-9c34-113baa5f9be9","Price":{"aud":4695.51,"usd":3518.04,"nzd":5084.33,"sgd":4788.41},"Volume":3.01386155},"Time":1649023837841,"Event":"NewOrder"}
1649023838.359425: {"Channel":"orderbook-eth","Nonce":19874,"Data":{"OrderType":"LimitOffer","OrderGuid":"ee5f9218-bfe6-4143-a218-c4452692e652","Price":{"aud":4753.93,"usd":3561.32,"nzd":5147.55,"sgd":4818.1},"Volume":4.563},"Time":1649023837888,"Event":"NewOrder"}
1649023838.359447: {"Channel":"orderbook-bch","Nonce":8472,"Data":{"OrderType":"LimitOffer","OrderGuid":"ea56987f-7c49-4faa-ba7a-e96b11bef95d"},"Time":1649023837888,"Event":"OrderCanceled"}
1649023838.359467: {"Channel":"orderbook-eth","Nonce":19875,"Data":{"OrderType":"LimitOffer","OrderGuid":"8fb1ea92-5dfb-4678-9ffe-521e12622aa1","Price":{"aud":4749.99,"usd":3576.27,"nzd":5174.29,"sgd":4843.97},"Volume":7.96},"Time":1649023837904,"Event":"NewOrder"}
1649023838.359488: {"Channel":"orderbook-eth","Nonce":19876,"Data":{"OrderType":"LimitOffer","OrderGuid":"16187e49-5055-43bb-8639-4b8705480e78","Price":{"aud":4755.05,"usd":3562.16,"nzd":5148.77,"sgd":4819.24},"Volume":1.17886075},"Time":1649023837919,"Event":"NewOrder"}
1649023838.359509: {"Channel":"orderbook-eth","Nonce":19877,"Data":{"OrderType":"LimitBid","OrderGuid":"72c2627f-76a3-46bf-9c34-113baa5f9be9"},"Time":1649023837919,"Event":"OrderCanceled"}
1649023838.359526: {"Channel":"orderbook-eth","Nonce":19878,"Data":{"OrderType":"LimitOffer","OrderGuid":"73abf2ea-a008-412a-93fb-581e846c26c0","Price":{"aud":4734.9,"usd":3564.9,"nzd":5157.85,"sgd":4828.58},"Volume":15.0},"Time":1649023837919,"Event":"NewOrder"}
1649023838.359547: {"Channel":"orderbook-eth","Nonce":19879,"Data":{"OrderType":"LimitBid","OrderGuid":"aa0216bc-f30b-4d2b-9d6d-748b126d7567"},"Time":1649023837919,"Event":"OrderCanceled"}
1649023838.359565: {"Channel":"orderbook-eth","Nonce":19880,"Data":{"OrderType":"LimitBid","OrderGuid":"af05a967-8272-4709-9132-089010b66598"},"Time":1649023837919,"Event":"OrderCanceled"}
1649023838.359584: {"Channel":"orderbook-eth","Nonce":19881,"Data":{"OrderType":"LimitBid","OrderGuid":"4ef6bdfc-a28a-4622-8029-a115242cd5aa"},"Time":1649023837935,"Event":"OrderCanceled"}
1649023838.3596: {"Channel":"orderbook-dot","Nonce":5069,"Data":{"OrderType":"LimitBid","OrderGuid":"7b46bfc7-2742-4047-8469-7313ead95f00"},"Time":1649023837951,"Event":"OrderCanceled"}
1649023838.359618: {"Channel":"orderbook-dot","Nonce":5070,"Data":{"OrderType":"LimitBid","OrderGuid":"02f4f664-eaa8-4b8e-9f9a-1c2c7be62115"},"Time":1649023837966,"Event":"OrderCanceled"}
1649023838.359636: {"Channel":"orderbook-eth","Nonce":19882,"Data":{"OrderType":"LimitBid","OrderGuid":"bb85fc5d-3733-43eb-b502-bbc766313258","Price":{"aud":4693.7,"usd":3516.68,"nzd":5082.36,"sgd":4786.56},"Volume":3.14929954},"Time":1649023837966,"Event":"NewOrder"}
1649023838.3596559: {"Channel":"orderbook-bch","Nonce":8473,"Data":{"OrderType":"LimitOffer","OrderGuid":"e15e912a-ee80-40eb-961b-8b36dc7852f4","Price":{"aud":507.78,"usd":382.31,"nzd":553.14,"sgd":517.83},"Volume":1.0931247},"Time":1649023837982,"Event":"NewOrder"}
1649023838.359678: {"Channel":"orderbook-eth","Nonce":19883,"Data":{"OrderType":"LimitBid","OrderGuid":"742363fd-970b-4af0-816a-36f82d8aca16"},"Time":1649023837982,"Event":"OrderCanceled"}
1649023838.359696: {"Channel":"orderbook-dot","Nonce":5071,"Data":{"OrderType":"LimitBid","OrderGuid":"199276f3-9316-42b6-a754-e77b05877ebe"},"Time":1649023838013,"Event":"OrderCanceled"}
1649023838.359712: {"Channel":"orderbook-dot","Nonce":5072,"Data":{"OrderType":"LimitBid","OrderGuid":"50acf7b9-851e-4926-a3dd-bf9bf297ed97","Price":{"aud":31.18,"usd":23.2415,"nzd":33.5559,"sgd":31.6009},"Volume":80.0},"Time":1649023838013,"Event":"NewOrder"}
1649023838.359733: {"Channel":"orderbook-eth","Nonce":19884,"Data":{"OrderType":"LimitOffer","OrderGuid":"f18e7ae5-fb3a-40de-8fbf-8549a00e720e","Price":{"aud":4731.9,"usd":3562.65,"nzd":5154.58,"sgd":4825.52},"Volume":15.0},"Time":1649023838013,"Event":"NewOrder"}
1649023838.359754: {"Channel":"orderbook-dot","Nonce":5073,"Data":{"OrderType":"LimitBid","OrderGuid":"c8d3019f-d713-4d13-ab9c-483c520017db","Price":{"aud":31.14,"usd":23.2117,"nzd":33.5128,"sgd":31.5603},"Volume":80.0},"Time":1649023838029,"Event":"NewOrder"}
1649023838.3597739: {"Channel":"orderbook-eth","Nonce":19885,"Data":{"OrderType":"LimitBid","OrderGuid":"71bc7da2-0924-49b8-b8e6-9340f1ce1efb","Price":{"aud":4691.7,"usd":3497.19,"nzd":5049.2,"sgd":4755.03},"Volume":4.261},"Time":1649023838029,"Event":"NewOrder"}
1649023838.3597949: {"Channel":"orderbook-eth","Nonce":19886,"Data":{"OrderType":"LimitBid","OrderGuid":"9753002a-6933-4acf-abde-549b92a31c9a","Price":{"aud":4724.7,"usd":3521.79,"nzd":5084.72,"sgd":4788.48},"Volume":15.0},"Time":1649023838029,"Event":"NewOrder"}
1649023838.3598201: {"Channel":"orderbook-eth","Nonce":19887,"Data":{"OrderType":"LimitBid","OrderGuid":"2da22a2f-3a95-4a28-93e8-e4366ec72391","Price":{"aud":4721.7,"usd":3519.55,"nzd":5081.49,"sgd":4785.44},"Volume":15.0},"Time":1649023838029,"Event":"NewOrder"}
1649023838.359841: {"Channel":"orderbook-dot","Nonce":5074,"Data":{"OrderType":"LimitOffer","OrderGuid":"bfd4e9b7-6e49-4056-b01b-db02962e6bb4"},"Time":1649023838076,"Event":"OrderCanceled"}
1649023838.359858: {"Channel":"orderbook-bch","Nonce":8474,"Data":{"OrderType":"LimitOffer","OrderGuid":"d9d124b6-dc74-4c92-a0ad-c1a60c4c34ce"},"Time":1649023838076,"Event":"OrderCanceled"}
1649023838.3598762: {"Channel":"orderbook-eth","Nonce":19888,"Data":{"OrderType":"LimitBid","OrderGuid":"4154bc64-4810-400a-b74b-17a6de763995","Price":{"aud":4726.35,"usd":3523.02,"nzd":5086.49,"sgd":4790.15},"Volume":1.01},"Time":1649023838091,"Event":"NewOrder"}
1649023838.3598971: {"Channel":"orderbook-dot","Nonce":5075,"Data":{"OrderType":"LimitOffer","OrderGuid":"ff2dc40b-a142-45e2-b980-2209004e3004"},"Time":1649023838091,"Event":"OrderCanceled"}
1649023838.359914: {"Channel":"orderbook-matic","Nonce":6047,"Data":{"OrderType":"LimitBid","OrderGuid":"64d93b10-3be5-4d1e-8b89-d56f3edf176d","Price":{"aud":2.22101,"usd":1.65554,"nzd":2.39025,"sgd":2.25099},"Volume":1727.0},"Time":1649023838091,"Event":"NewOrder"}
1649023838.359936: {"Channel":"orderbook-dot","Nonce":5076,"Data":{"OrderType":"LimitBid","OrderGuid":"c5d49998-081b-475a-a442-9bf319934ab7"},"Time":1649023838091,"Event":"OrderCanceled"}
1649023838.359956: {"Channel":"orderbook-eth","Nonce":19889,"Data":{"OrderType":"LimitOffer","OrderGuid":"f18e7ae5-fb3a-40de-8fbf-8549a00e720e"},"Time":1649023838107,"Event":"OrderCanceled"}
1649023838.3599732: {"Channel":"orderbook-eth","Nonce":19890,"Data":{"OrderType":"LimitBid","OrderGuid":"9753002a-6933-4acf-abde-549b92a31c9a"},"Time":1649023838123,"Event":"OrderCanceled"}
1649023838.359989: {"Channel":"orderbook-eth","Nonce":19891,"Data":{"OrderType":"LimitOffer","OrderGuid":"73abf2ea-a008-412a-93fb-581e846c26c0"},"Time":1649023838123,"Event":"OrderCanceled"}
1649023838.3600051: {"Channel":"orderbook-bch","Nonce":8475,"Data":{"OrderType":"LimitBid","OrderGuid":"ee436e3b-6e26-4312-b993-fa634e16d16a"},"Time":1649023838123,"Event":"OrderCanceled"}
1649023838.360022: {"Channel":"orderbook-dot","Nonce":5077,"Data":{"OrderType":"LimitBid","OrderGuid":"5fbe02b1-aad5-4a03-9889-c1f6845baaea"},"Time":1649023838123,"Event":"OrderCanceled"}
1649023838.360037: {"Channel":"orderbook-bch","Nonce":8476,"Data":{"OrderType":"LimitOffer","OrderGuid":"457af996-6d28-4a8c-89bf-1103ed9301a5"},"Time":1649023838123,"Event":"OrderCanceled"}
1649023838.360053: {"Channel":"orderbook-matic","Nonce":6048,"Data":{"OrderType":"LimitBid","OrderGuid":"04838ada-4922-40ec-9cbe-e7609c4d89e7"},"Time":1649023838123,"Event":"OrderCanceled"}
1649023838.360071: {"Channel":"orderbook-matic","Nonce":6049,"Data":{"OrderType":"LimitOffer","OrderGuid":"05e31390-f756-4a24-b3a4-062332dc43c7"},"Time":1649023838138,"Event":"OrderCanceled"}
1649023838.360088: {"Channel":"orderbook-bch","Nonce":8477,"Data":{"OrderType":"LimitOffer","OrderGuid":"8c070bb2-969d-48ac-8e82-671720104012"},"Time":1649023838138,"Event":"OrderCanceled"}
1649023838.3601038: {"Channel":"orderbook-dot","Nonce":5078,"Data":{"OrderType":"LimitBid","OrderGuid":"0a04921b-8c08-4919-9655-c914f16f3002","Price":{"aud":31.2002,"usd":23.2566,"nzd":33.5776,"sgd":31.6214},"Volume":21.74432},"Time":1649023838138,"Event":"NewOrder"}
1649023838.3601248: {"Channel":"orderbook-bch","Nonce":8478,"Data":{"OrderType":"LimitBid","OrderGuid":"ae6f7be1-e0be-4581-8cfa-13477298da83"},"Time":1649023838138,"Event":"OrderCanceled"}
1649023838.360142: {"Channel":"orderbook-bch","Nonce":8479,"Data":{"OrderType":"LimitOffer","OrderGuid":"95d25186-c9e4-42cf-b0d6-d11ba4432d5b"},"Time":1649023838154,"Event":"OrderCanceled"}
1649023838.360158: {"Channel":"orderbook-matic","Nonce":6050,"Data":{"OrderType":"LimitOffer","OrderGuid":"36836ac1-b839-40d0-8cf2-71a45408f4cf","Price":{"aud":2.27149,"usd":1.71021,"nzd":2.47439,"sgd":2.31643},"Volume":5437.31311},"Time":1649023838185,"Event":"NewOrder"}
1649023838.36018: {"Channel":"orderbook-matic","Nonce":6051,"Data":{"OrderType":"LimitBid","OrderGuid":"85a51723-c4e6-4379-93e0-a2616d72cd5b","Price":{"aud":2.26051,"usd":1.68498,"nzd":2.43276,"sgd":2.29102},"Volume":5714.79399},"Time":1649023838185,"Event":"NewOrder"}
1649023838.360201: {"Channel":"orderbook-eth","Nonce":19892,"Data":{"OrderType":"LimitOffer","OrderGuid":"daa2e42f-047d-486b-92f9-3193712943f5","Price":{"aud":4731.1,"usd":3562.04,"nzd":5153.71,"sgd":4824.7},"Volume":15.0},"Time":1649023838201,"Event":"NewOrder"}
1649023838.3602219: {"Channel":"orderbook-eth","Nonce":19893,"Data":{"OrderType":"LimitBid","OrderGuid":"2da22a2f-3a95-4a28-93e8-e4366ec72391"},"Time":1649023838201,"Event":"OrderCanceled"}
1649023838.3602402: {"Channel":"orderbook-eth","Nonce":19894,"Data":{"OrderType":"LimitOffer","OrderGuid":"ef4f3f84-ca91-423e-80d3-180fe58cf849","Price":{"aud":4734.1,"usd":3564.3,"nzd":5156.98,"sgd":4827.76},"Volume":15.0},"Time":1649023838201,"Event":"NewOrder"}
1649023838.36026: {"Channel":"orderbook-bch","Nonce":8480,"Data":{"OrderType":"LimitOffer","OrderGuid":"8927c0ed-5d62-4bac-8bde-e9f25dfa5647"},"Time":1649023838216,"Event":"OrderCanceled"}
1649023838.3602839: {"Channel":"orderbook-dot","Nonce":5079,"Data":{"OrderType":"LimitOffer","OrderGuid":"dbddb349-e797-4d38-abd8-c4be48f59de9"},"Time":1649023838216,"Event":"OrderCanceled"}
1649023838.360302: {"Channel":"orderbook-eth","Nonce":19895,"Data":{"OrderType":"LimitBid","OrderGuid":"7845bf49-ccfc-4f6c-ab6e-faab0ddebd41"},"Time":1649023838216,"Event":"OrderCanceled"}
1649023838.360319: {"Channel":"orderbook-bch","Nonce":8481,"Data":{"OrderType":"LimitBid","OrderGuid":"259d3e08-c6d9-4e6f-86e8-4fa690e796d0","Price":{"aud":503.8,"usd":375.53,"nzd":542.18,"sgd":510.6},"Volume":6.0},"Time":1649023838216,"Event":"NewOrder"}
1649023838.5827131: {"Channel":"orderbook-bch","Nonce":8482,"Data":{"OrderType":"LimitBid","OrderGuid":"57304ea2-6bd0-43ab-882f-d229958fad6d","Price":{"aud":503.1,"usd":375.01,"nzd":541.43,"sgd":509.89},"Volume":6.0},"Time":1649023838216,"Event":"NewOrder"}
1649023838.5827992: {"Channel":"orderbook-eth","Nonce":19896,"Data":{"OrderType":"LimitBid","OrderGuid":"ddc2295b-7bc6-41e8-9419-2c52e11bba22"},"Time":1649023838232,"Event":"OrderCanceled"}
1649023838.582836: {"Channel":"orderbook-dot","Nonce":5080,"Data":{"OrderType":"LimitOffer","OrderGuid":"50c83e6b-8607-4dd5-894f-981d8f0dfbc0","Price":{"aud":31.4622,"usd":23.6879,"nzd":34.2726,"sgd":32.0847},"Volume":27.7},"Time":1649023838232,"Event":"NewOrder"}
1649023838.58287: {"Channel":"orderbook-eth","Nonce":19897,"Data":{"OrderType":"LimitBid","OrderGuid":"22fb768c-cdde-4346-98a1-6bef4d28512b"},"Time":1649023838248,"Event":"OrderCanceled"}
1649023838.582906: {"Channel":"orderbook-dot","Nonce":5081,"Data":{"OrderType":"LimitOffer","OrderGuid":"77bf4836-831e-408c-9244-f743c49a13a8","Price":{"aud":31.6105,"usd":23.7996,"nzd":34.4341,"sgd":32.2359},"Volume":287.7},"Time":1649023838248,"Event":"NewOrder"}
1649023838.582936: {"Channel":"orderbook-eth","Nonce":19898,"Data":{"OrderType":"LimitBid","OrderGuid":"a7b9f4d9-dfc0-42f4-8b7c-81b7fba3541f","Price":{"aud":4723.9,"usd":3521.19,"nzd":5083.86,"sgd":4787.67},"Volume":15.0},"Time":1649023838248,"Event":"NewOrder"}
1649023838.582965: {"Channel":"orderbook-bch","Nonce":8483,"Data":{"OrderType":"LimitOffer","OrderGuid":"6b0a36a8-6071-4cb6-a8c1-d360923678a2","Price":{"aud":507.2,"usd":381.88,"nzd":552.51,"sgd":517.24},"Volume":6.0},"Time":1649023838248,"Event":"NewOrder"}
1649023838.582994: {"Channel":"orderbook-eth","Nonce":19899,"Data":{"OrderType":"LimitBid","OrderGuid":"4f49d775-6159-4355-94a7-ece6d52273cc","Price":{"aud":4720.9,"usd":3518.95,"nzd":5080.63,"sgd":4784.63},"Volume":15.0},"Time":1649023838248,"Event":"NewOrder"}
1649023838.583026: {"Channel":"orderbook-dot","Nonce":5082,"Data":{"OrderType":"LimitOffer","OrderGuid":"1cb8be0a-e6fd-4752-9870-2e5d396ce428"},"Time":1649023838263,"Event":"OrderCanceled"}
1649023838.58305: {"Channel":"orderbook-dot","Nonce":5083,"Data":{"OrderType":"LimitBid","OrderGuid":"88f430e2-1cd7-49bc-95c4-262df22e7f04","Price":{"aud":31.2093,"usd":23.2634,"nzd":33.5874,"sgd":31.6306},"Volume":27.7},"Time":1649023838263,"Event":"NewOrder"}
1649023838.583076: {"Channel":"orderbook-dot","Nonce":5084,"Data":{"OrderType":"LimitBid","OrderGuid":"5d105063-e7f3-4540-87fc-82eeabcbd8cb","Price":{"aud":31.1501,"usd":23.2192,"nzd":33.5237,"sgd":31.5706},"Volume":52.9},"Time":1649023838294,"Event":"NewOrder"}
1649023838.583102: {"Channel":"orderbook-eth","Nonce":19900,"Data":{"OrderType":"LimitBid","OrderGuid":"ae1b2ad8-aa8c-4acc-b2a5-1df4305fa236","Price":{"aud":4722.09,"usd":3519.84,"nzd":5081.91,"sgd":4785.83},"Volume":14.14},"Time":1649023838294,"Event":"NewOrder"}
1649023838.583127: {"Channel":"orderbook-eth","Nonce":19901,"Data":{"OrderType":"LimitBid","OrderGuid":"0d9d0972-0164-49a6-a9de-1d06b927a6f2","Price":{"aud":4674.45,"usd":3501.25,"nzd":5092.0,"sgd":4766.11},"Volume":0.51086614},"Time":1649023838294,"Event":"NewOrder"}
1649023838.583154: {"Channel":"orderbook-bch","Nonce":8484,"Data":{"OrderType":"LimitOffer","OrderGuid":"180fb6e2-f095-46cb-afd6-087daaf6678c","Price":{"aud":508.83,"usd":383.1,"nzd":554.29,"sgd":518.9},"Volume":7.47},"Time":1649023838310,"Event":"NewOrder"}
1649023838.5831811: {"Channel":"orderbook-eth","Nonce":19902,"Data":{"OrderType":"LimitOffer","OrderGuid":"16187e49-5055-43bb-8639-4b8705480e78"},"Time":1649023838310,"Event":"OrderCanceled"}
1649023838.5832052: {"Channel":"orderbook-bch","Nonce":8485,"Data":{"OrderType":"LimitOffer","OrderGuid":"a2f749b7-c2b2-41ea-b3bf-9da0f838a63b","Price":{"aud":510.54,"usd":384.39,"nzd":556.15,"sgd":520.65},"Volume":2.93},"Time":1649023838326,"Event":"NewOrder"}
1649023838.58323: {"Channel":"orderbook-eth","Nonce":19903,"Data":{"OrderType":"LimitBid","OrderGuid":"13cdf292-9422-4afe-8bc0-c475a7f12e32","Price":{"aud":4704.06,"usd":3506.4,"nzd":5062.5,"sgd":4767.56},"Volume":0.35004634},"Time":1649023838326,"Event":"NewOrder"}
1649023838.583256: {"Channel":"orderbook-dot","Nonce":5085,"Data":{"OrderType":"LimitOffer","OrderGuid":"02ef0228-037f-42fc-bd35-4aa297bd5bbe"},"Time":1649023838326,"Event":"OrderCanceled"}
1649023838.5832791: {"Channel":"orderbook-eth","Nonce":19904,"Data":{"OrderType":"LimitOffer","OrderGuid":"0e4c6fd5-6ab4-4cdf-9fe4-cf25234e63a3","Price":{"aud":4742.02,"usd":3570.27,"nzd":5165.6,"sgd":4835.84},"Volume":4.47331033},"Time":1649023838341,"Event":"NewOrder"}
1649023838.583305: {"Channel":"orderbook-eth","Nonce":19905,"Data":{"OrderType":"LimitOffer","OrderGuid":"ee7906b6-3c9c-4c65-9a1a-8db708211ddf"},"Time":1649023838341,"Event":"OrderCanceled"}
1649023838.5833259: {"Channel":"orderbook-dot","Nonce":5086,"Data":{"OrderType":"LimitOffer","OrderGuid":"7512f459-075f-416d-b176-4109eb4f787e"},"Time":1649023838357,"Event":"OrderCanceled"}
1649023838.5833468: {"Channel":"orderbook-bch","Nonce":8486,"Data":{"OrderType":"LimitOffer","OrderGuid":"ff599412-10a5-4daf-9631-3fce5f6c0794","Price":{"aud":506.5,"usd":381.35,"nzd":551.75,"sgd":516.53},"Volume":6.0},"Time":1649023838373,"Event":"NewOrder"}
1649023838.583373: {"Channel":"orderbook-dot","Nonce":5087,"Data":{"OrderType":"LimitOffer","OrderGuid":"f209dcd0-99f7-434a-ae08-0b1b90e8a61b","Price":{"aud":31.37,"usd":23.6185,"nzd":34.1722,"sgd":31.9907},"Volume":80.0},"Time":1649023838388,"Event":"NewOrder"}
1649023838.5833979: {"Channel":"orderbook-eth","Nonce":19906,"Data":{"OrderType":"LimitOffer","OrderGuid":"ef4f3f84-ca91-423e-80d3-180fe58cf849"},"Time":1649023838388,"Event":"OrderCanceled"}
1649023838.5834198: {"Channel":"orderbook-eth","Nonce":19907,"Data":{"OrderType":"LimitBid","OrderGuid":"4f49d775-6159-4355-94a7-ece6d52273cc"},"Time":1649023838388,"Event":"OrderCanceled"}
1649023838.5834398: {"Channel":"orderbook-bch","Nonce":8487,"Data":{"OrderType":"LimitOffer","OrderGuid":"6b0a36a8-6071-4cb6-a8c1-d360923678a2"},"Time":1649023838404,"Event":"OrderCanceled"}
1649023838.58346: {"Channel":"orderbook-eth","Nonce":19908,"Data":{"OrderType":"LimitOffer","OrderGuid":"daa2e42f-047d-486b-92f9-3193712943f5"},"Time":1649023838404,"Event":"OrderCanceled"}
1649023838.583481: {"Channel":"orderbook-eth","Nonce":19909,"Data":{"OrderType":"LimitOffer","OrderGuid":"99a2a03e-8305-428d-81f2-b8c732dc7afa","Price":{"aud":4753.92,"usd":3561.31,"nzd":5147.54,"sgd":4818.09},"Volume":1.14878071},"Time":1649023838404,"Event":"NewOrder"}
1649023838.5835059: {"Channel":"orderbook-bch","Nonce":8488,"Data":{"OrderType":"LimitBid","OrderGuid":"259d3e08-c6d9-4e6f-86e8-4fa690e796d0"},"Time":1649023838404,"Event":"OrderCanceled"}
1649023838.583528: {"Channel":"orderbook-dot","Nonce":5088,"Data":{"OrderType":"LimitOffer","OrderGuid":"6a852ec9-c309-4eb1-85b0-f350e2b5f54c","Price":{"aud":31.3798,"usd":23.6259,"nzd":34.1828,"sgd":32.0007},"Volume":19.94421},"Time":1649023838419,"Event":"NewOrder"}
1649023838.583554: {"Channel":"orderbook-dot","Nonce":5089,"Data":{"OrderType":"LimitOffer","OrderGuid":"1dbfdfee-bf82-4be4-833f-a2e1458d1619","Price":{"aud":31.6104,"usd":23.7995,"nzd":34.434,"sgd":32.2358},"Volume":14.72539},"Time":1649023838419,"Event":"NewOrder"}
1649023838.583584: {"Channel":"orderbook-matic","Nonce":6052,"Data":{"OrderType":"LimitBid","OrderGuid":"85a51723-c4e6-4379-93e0-a2616d72cd5b"},"Time":1649023838435,"Event":"OrderCanceled"}
1649023838.58361: {"Channel":"orderbook-dot","Nonce":5090,"Data":{"OrderType":"LimitOffer","OrderGuid":"3175a001-0836-45c4-8bc1-a2a1bb9cec33","Price":{"aud":35.3231,"usd":26.5948,"nzd":38.4784,"sgd":36.022},"Volume":52.9},"Time":1649023838435,"Event":"NewOrder"}
1649023838.5836349: {"Channel":"orderbook-eth","Nonce":19910,"Data":{"OrderType":"LimitBid","OrderGuid":"ae1b2ad8-aa8c-4acc-b2a5-1df4305fa236"},"Time":1649023838435,"Event":"OrderCanceled"}
1649023838.583657: {"Channel":"orderbook-dot","Nonce":5091,"Data":{"OrderType":"LimitOffer","OrderGuid":"c06a25b8-7757-4da4-9ad2-a485c416f80d","Price":{"aud":31.4199,"usd":23.6561,"nzd":34.2265,"sgd":32.0416},"Volume":27.28397},"Time":1649023838435,"Event":"NewOrder"}
1649023838.583682: {"Channel":"orderbook-eth","Nonce":19911,"Data":{"OrderType":"LimitOffer","OrderGuid":"e7b54e09-596f-4c5a-9abf-74f10827d1bd"},"Time":1649023838435,"Event":"OrderCanceled"}
1649023838.583704: {"Channel":"orderbook-dot","Nonce":5092,"Data":{"OrderType":"LimitOffer","OrderGuid":"eb1c2f47-d9e5-4428-9397-0a1fa3b0b2b9"},"Time":1649023838451,"Event":"OrderCanceled"}
1649023838.583725: {"Channel":"orderbook-dot","Nonce":5093,"Data":{"OrderType":"LimitBid","OrderGuid":"d1677340-fd6f-4118-8d02-d3566643b533","Price":{"aud":30.8033,"usd":22.9607,"nzd":33.1505,"sgd":31.2191},"Volume":457.6},"Time":1649023838451,"Event":"NewOrder"}
1649023838.5837498: {"Channel":"orderbook-dot","Nonce":5094,"Data":{"OrderType":"LimitBid","OrderGuid":"5f0da27f-7b7e-4c6b-a911-c54452806f12"},"Time":1649023838451,"Event":"OrderCanceled"}
1649023838.583771: {"Channel":"orderbook-eth","Nonce":19912,"Data":{"OrderType":"LimitBid","OrderGuid":"0943e28e-f4f3-40fa-85b9-5171589d9aff","Price":{"aud":4721.33,"usd":3519.27,"nzd":5081.09,"sgd":4785.06},"Volume":14.14},"Time":1649023838466,"Event":"NewOrder"}
1649023838.5903392: {"Channel":"orderbook-dot","Nonce":5095,"Data":{"OrderType":"LimitOffer","OrderGuid":"54a807e8-6e01-4495-8c99-87b85b33348a","Price":{"aud":31.41,"usd":23.6486,"nzd":34.2157,"sgd":32.0315},"Volume":80.0},"Time":1649023838482,"Event":"NewOrder"}
1649023838.590466: {"Channel":"orderbook-eth","Nonce":19913,"Data":{"OrderType":"LimitOffer","OrderGuid":"1fbbd8d9-4b46-4aa3-b894-2650ec3ffa19","Price":{"aud":4733.6,"usd":3563.93,"nzd":5156.43,"sgd":4827.25},"Volume":15.0},"Time":1649023838482,"Event":"NewOrder"}
1649023838.590531: {"Channel":"orderbook-eth","Nonce":19914,"Data":{"OrderType":"LimitBid","OrderGuid":"a7b9f4d9-dfc0-42f4-8b7c-81b7fba3541f"},"Time":1649023838482,"Event":"OrderCanceled"}
1649023838.5944588: {"Channel":"orderbook-eth","Nonce":19915,"Data":{"OrderType":"LimitOffer","OrderGuid":"16223eed-54d9-4c67-bc0c-8a5191111b66","Price":{"aud":4789.73,"usd":3570.26,"nzd":5192.36,"sgd":4859.49},"Volume":0.56398015},"Time":1649023838498,"Event":"NewOrder"}
1649023838.597619: {"Channel":"orderbook-bch","Nonce":8489,"Data":{"OrderType":"LimitBid","OrderGuid":"57304ea2-6bd0-43ab-882f-d229958fad6d"},"Time":1649023838498,"Event":"OrderCanceled"}
1649023838.60591: {"Channel":"orderbook-eth","Nonce":19916,"Data":{"OrderType":"LimitOffer","OrderGuid":"11545f25-8d5e-41c8-99df-aa7e456dcea8"},"Time":1649023838498,"Event":"OrderCanceled"}
1649023838.605984: {"Channel":"orderbook-bch","Nonce":8490,"Data":{"OrderType":"LimitOffer","OrderGuid":"ff599412-10a5-4daf-9631-3fce5f6c0794"},"Time":1649023838498,"Event":"OrderCanceled"}
1649023838.606875: {"Channel":"orderbook-eth","Nonce":19917,"Data":{"OrderType":"LimitBid","OrderGuid":"0d9d0972-0164-49a6-a9de-1d06b927a6f2"},"Time":1649023838498,"Event":"OrderCanceled"}
1649023838.611603: {"Channel":"orderbook-dot","Nonce":5096,"Data":{"OrderType":"LimitOffer","OrderGuid":"77b78367-8560-4c88-ad34-d2ff6a57a84f","Price":{"aud":31.5094,"usd":23.7234,"nzd":34.324,"sgd":32.1328},"Volume":14.72539},"Time":1649023838513,"Event":"NewOrder"}
1649023838.62951: {"Channel":"orderbook-dot","Nonce":5097,"Data":{"OrderType":"LimitOffer","OrderGuid":"1dbfdfee-bf82-4be4-833f-a2e1458d1619"},"Time":1649023838529,"Event":"OrderCanceled"}
1649023838.629612: {"Channel":"orderbook-matic","Nonce":6053,"Data":{"OrderType":"LimitBid","OrderGuid":"92620b25-6d3d-4622-82d9-04acc1117ca8","Price":{"aud":2.25901,"usd":1.68386,"nzd":2.43114,"sgd":2.2895},"Volume":5770.14294},"Time":1649023838529,"Event":"NewOrder"}
1649023838.634551: {"Channel":"orderbook-dot","Nonce":5098,"Data":{"OrderType":"LimitOffer","OrderGuid":"83f929f1-42fa-4832-9a2d-4996270b9631"},"Time":1649023838529,"Event":"OrderCanceled"}
1649023838.647808: {"Channel":"orderbook-bch","Nonce":8491,"Data":{"OrderType":"LimitBid","OrderGuid":"a65ea2ec-b9f1-4638-8d3e-ace720b53b25","Price":{"aud":503.6,"usd":375.38,"nzd":541.97,"sgd":510.39},"Volume":6.0},"Time":1649023838544,"Event":"NewOrder"}
1649023838.647881: {"Channel":"orderbook-eth","Nonce":19918,"Data":{"OrderType":"LimitOffer","OrderGuid":"ba6b11ab-89d6-452f-9dd0-0cd6b24daf0f","Price":{"aud":4733.59,"usd":3563.92,"nzd":5156.42,"sgd":4827.24},"Volume":4.47331033},"Time":1649023838544,"Event":"NewOrder"}
1649023838.653381: {"Channel":"orderbook-eth","Nonce":19919,"Data":{"OrderType":"LimitOffer","OrderGuid":"0e4c6fd5-6ab4-4cdf-9fe4-cf25234e63a3"},"Time":1649023838544,"Event":"OrderCanceled"}
1649023838.653436: {"Channel":"orderbook-bch","Nonce":8492,"Data":{"OrderType":"LimitBid","OrderGuid":"c4757336-ed4b-4dd9-b032-eef18b88d05a","Price":{"aud":502.9,"usd":374.86,"nzd":541.22,"sgd":509.68},"Volume":6.0},"Time":1649023838544,"Event":"NewOrder"}
1649023838.653472: {"Channel":"orderbook-bch","Nonce":8493,"Data":{"OrderType":"LimitOffer","OrderGuid":"5a86c8ae-6afe-4216-97a2-05e7be46eef8","Price":{"aud":507.1,"usd":381.8,"nzd":552.4,"sgd":517.14},"Volume":6.0},"Time":1649023838544,"Event":"NewOrder"}
1649023838.65925: {"Channel":"orderbook-bch","Nonce":8494,"Data":{"OrderType":"LimitOffer","OrderGuid":"66e40a4b-b498-45fd-ab71-82666665dcd0","Price":{"aud":506.4,"usd":381.27,"nzd":551.64,"sgd":516.42},"Volume":6.0},"Time":1649023838560,"Event":"NewOrder"}
1649023838.65931: {"Channel":"orderbook-eth","Nonce":19920,"Data":{"OrderType":"LimitOffer","OrderGuid":"2f1dabba-bec8-4cbf-a18a-8af099503a4c","Price":{"aud":4783.07,"usd":3582.89,"nzd":5147.53,"sgd":4847.93},"Volume":0.46747764},"Time":1649023838560,"Event":"NewOrder"}
1649023838.6646888: {"Channel":"orderbook-eth","Nonce":19921,"Data":{"OrderType":"LimitOffer","OrderGuid":"f9ec5ac0-bce3-40a6-aabb-c8fce14cdb86"},"Time":1649023838560,"Event":"OrderCanceled"}
1649023838.664762: {"Channel":"orderbook-eth","Nonce":19922,"Data":{"OrderType":"LimitBid","OrderGuid":"12531a3e-8dc1-44d8-93a9-82621f256362","Price":{"aud":4674.46,"usd":3501.26,"nzd":5092.01,"sgd":4766.12},"Volume":0.42137606},"Time":1649023838560,"Event":"NewOrder"}
1649023838.672639: {"Channel":"orderbook-matic","Nonce":6054,"Data":{"OrderType":"LimitBid","OrderGuid":"92620b25-6d3d-4622-82d9-04acc1117ca8"},"Time":1649023838560,"Event":"OrderCanceled"}
1649023838.6726882: {"Channel":"orderbook-eth","Nonce":19923,"Data":{"OrderType":"LimitBid","OrderGuid":"a7e3e1db-2f7f-479a-b9b9-90f2fd795d6c","Price":{"aud":4694.51,"usd":3517.29,"nzd":5083.25,"sgd":4787.39},"Volume":23.181},"Time":1649023838576,"Event":"NewOrder"}
1649023838.681039: {"Channel":"orderbook-eth","Nonce":19924,"Data":{"OrderType":"LimitOffer","OrderGuid":"a6eafcc4-d785-4bc3-b12a-218604707b5b","Price":{"aud":4730.6,"usd":3561.67,"nzd":5153.16,"sgd":4824.19},"Volume":15.0},"Time":1649023838576,"Event":"NewOrder"}
1649023838.6811242: {"Channel":"orderbook-eth","Nonce":19925,"Data":{"OrderType":"LimitBid","OrderGuid":"7d4d7478-3a77-4f29-a0b3-178819dfe925","Price":{"aud":4723.4,"usd":3520.82,"nzd":5083.32,"sgd":4787.16},"Volume":15.0},"Time":1649023838576,"Event":"NewOrder"}
1649023838.723914: {"Channel":"orderbook-matic","Nonce":6055,"Data":{"OrderType":"LimitBid","OrderGuid":"b3cec09f-e0d2-4f7a-8bd0-ba41ff0eea5e","Price":{"aud":2.26002,"usd":1.68461,"nzd":2.43223,"sgd":2.29053},"Volume":5242.15901},"Time":1649023838623,"Event":"NewOrder"}
1649023838.7822871: {"Channel":"orderbook-eth","Nonce":19926,"Data":{"OrderType":"LimitBid","OrderGuid":"7d4d7478-3a77-4f29-a0b3-178819dfe925"},"Time":1649023838669,"Event":"OrderCanceled"}
1649023838.78561: {"Channel":"orderbook-eth","Nonce":19927,"Data":{"OrderType":"LimitOffer","OrderGuid":"1fbbd8d9-4b46-4aa3-b894-2650ec3ffa19"},"Time":1649023838685,"Event":"OrderCanceled"}
1649023838.88542: {"Channel":"orderbook-eth","Nonce":19928,"Data":{"OrderType":"LimitOffer","OrderGuid":"a6eafcc4-d785-4bc3-b12a-218604707b5b"},"Time":1649023838779,"Event":"OrderCanceled"}
1649023838.890858: {"Channel":"orderbook-eth","Nonce":19929,"Data":{"OrderType":"LimitBid","OrderGuid":"51de7451-b901-439a-ab9e-0c5533ef0b47","Price":{"aud":4722.5,"usd":3520.15,"nzd":5082.35,"sgd":4786.25},"Volume":15.0},"Time":1649023838779,"Event":"NewOrder"}
1649023838.901608: {"Channel":"orderbook-eth","Nonce":19930,"Data":{"OrderType":"LimitBid","OrderGuid":"b3b9c9e9-19e6-42f8-9e73-93941e99ab90","Price":{"aud":4719.5,"usd":3517.91,"nzd":5079.12,"sgd":4783.21},"Volume":15.0},"Time":1649023838794,"Event":"NewOrder"}
1649023838.9051461: {"Channel":"orderbook-matic","Nonce":6056,"Data":{"OrderType":"LimitOffer","OrderGuid":"0680519b-345d-44da-9cdd-1655ba119145"},"Time":1649023838794,"Event":"OrderCanceled"}
1649023838.905251: {"Channel":"orderbook-dot","Nonce":5099,"Data":{"OrderType":"LimitBid","OrderGuid":"c8d3019f-d713-4d13-ab9c-483c520017db"},"Time":1649023838794,"Event":"OrderCanceled"}
1649023838.915147: {"Channel":"orderbook-matic","Nonce":6057,"Data":{"OrderType":"LimitBid","OrderGuid":"9e473ecd-e27b-4d04-b4af-06808a62cda0"},"Time":1649023838810,"Event":"OrderCanceled"}
1649023838.926296: {"Channel":"orderbook-eth","Nonce":19931,"Data":{"OrderType":"LimitBid","OrderGuid":"5556ebf9-9e17-4267-933d-2a98f3c22040","Price":{"aud":4668.81,"usd":3480.13,"nzd":5024.57,"sgd":4731.83},"Volume":0.19522201},"Time":1649023838810,"Event":"NewOrder"}
1649023838.934572: {"Channel":"orderbook-eth","Nonce":19932,"Data":{"OrderType":"LimitOffer","OrderGuid":"20f1e3f5-b9a7-446b-8ece-96d264df1d4b","Price":{"aud":4732.7,"usd":3563.25,"nzd":5155.45,"sgd":4826.34},"Volume":15.0},"Time":1649023838826,"Event":"NewOrder"}
1649023838.938236: {"Channel":"orderbook-eth","Nonce":19933,"Data":{"OrderType":"LimitOffer","OrderGuid":"52db62a0-bdc8-4d7e-8d87-d0aa64f6f62c","Price":{"aud":4729.7,"usd":3560.99,"nzd":5152.18,"sgd":4823.28},"Volume":15.0},"Time":1649023838826,"Event":"NewOrder"}
1649023838.9531221: {"Channel":"orderbook-eth","Nonce":19934,"Data":{"OrderType":"LimitBid","OrderGuid":"9239020d-12f1-433d-a244-7d37b57c1762"},"Time":1649023838841,"Event":"OrderCanceled"}
1649023838.993386: {"Channel":"orderbook-dot","Nonce":5100,"Data":{"OrderType":"LimitBid","OrderGuid":"50acf7b9-851e-4926-a3dd-bf9bf297ed97"},"Time":1649023838888,"Event":"OrderCanceled"}
