wss://websockets.independentreserve.com <-> 1649023807.984895
wss://websockets.independentreserve.com <- 1649023809.052978: {"Event":"Subscribe","Data":["ticker-pmgt-nzd","ticker-etc-aud","ticker-eos-nzd","ticker-snx-aud","ticker-bch-sgd","ticker-eos-sgd","ticker-eth-aud","ticker-etc-sgd","ticker-matic-usd","ticker-dot-nzd","orderbook-eth","orderbook-dot","orderbook-matic","orderbook-bch","orderbook-snx","orderbook-etc","orderbook-eos","orderbook-pmgt"]}
1649023809.126495: {"Time":1649023809081,"Event":"Heartbeat"}
1649023809.280087: {"Data":["orderbook-etc","ticker-etc-sgd","ticker-eos-sgd","ticker-bch-sgd","ticker-pmgt-nzd","ticker-eth-aud","ticker-eos-nzd","orderbook-pmgt","ticker-etc-aud","orderbook-snx","orderbook-matic","ticker-dot-nzd","orderbook-eth","orderbook-dot","orderbook-bch","ticker-snx-aud","ticker-matic-usd","orderbook-eos"],"Time":1649023809221,"Event":"Subscriptions"}
1649023809.313331: {"Channel":"orderbook-dot","Nonce":4908,"Data":{"OrderType":"LimitOffer","OrderGuid":"be3c69b7-1c5e-446f-b80d-8398aae065c5","Price":{"aud":31.5105,"usd":23.7243,"nzd":34.3252,"sgd":32.1339},"Volume":14.72539},"Time":1649023809209,"Event":"NewOrder"}
1649023811.25681: {"Channel":"orderbook-dot","Nonce":4909,"Data":{"OrderType":"LimitOffer","OrderGuid":"932878ac-3794-4163-8753-363fb433dbd3"},"Time":1649023809209,"Event":"OrderCanceled"}
1649023811.256854: {"Channel":"orderbook-dot","Nonce":4910,"Data":{"OrderType":"LimitOffer","OrderGuid":"b72a92e7-d1e0-4ada-a99e-43b2acde724d"},"Time":1649023809209,"Event":"OrderCanceled"}
1649023811.256874: {"Channel":"orderbook-matic","Nonce":5851,"Data":{"OrderType":"LimitBid","OrderGuid":"a156c907-d546-4cc6-862c-999bad5b01cf","Price":{"aud":2.261,"usd":1.68534,"nzd":2.43328,"sgd":2.29152},"Volume":5583.0},"Time":1649023809225,"Event":"NewOrder"}
1649023812.507345: {"Channel":"orderbook-eth","Nonce":18986,"Data":{"OrderType":"LimitOffer","OrderGuid":"7927afb4-66dd-4870-9332-77197ad850a2"},"Time":1649023809256,"Event":"OrderCanceled"}
1649023813.9942: {"Channel":"orderbook-dot","Nonce":4911,"Data":{"OrderType":"LimitOffer","OrderGuid":"f0e2e76e-4e7f-4ae6-9893-95ed22f7c393","Price":{"aud":31.5102,"usd":23.724,"nzd":34.3249,"sgd":32.1336},"Volume":14.72539},"Time":1649023809256,"Event":"NewOrder"}
1649023813.99425: {"Channel":"orderbook-dot","Nonce":4912,"Data":{"OrderType":"LimitOffer","OrderGuid":"be3c69b7-1c5e-446f-b80d-8398aae065c5"},"Time":1649023809271,"Event":"OrderCanceled"}
1649023813.9942772: {"Channel":"orderbook-dot","Nonce":4913,"Data":{"OrderType":"LimitOffer","OrderGuid":"242290c3-19e2-4567-afa9-41458c7b1d61"},"Time":1649023809287,"Event":"OrderCanceled"}
1649023813.994293: {"Channel":"orderbook-eth","Nonce":18987,"Data":{"OrderType":"LimitOffer","OrderGuid":"4896b70e-2ee5-4adc-9182-2194cc3659e8","Price":{"aud":4731.7,"usd":3562.5,"nzd":5154.36,"sgd":4825.32},"Volume":15.0},"Time":1649023809287,"Event":"NewOrder"}
1649023813.9943879: {"Channel":"orderbook-eth","Nonce":18988,"Data":{"OrderType":"LimitOffer","OrderGuid":"8e02da3b-c4a8-4b83-81cc-1bc2ff6e194a","Price":{"aud":4734.7,"usd":3564.75,"nzd":5157.63,"sgd":4828.38},"Volume":15.0},"Time":1649023809303,"Event":"NewOrder"}
1649023813.994421: {"Channel":"orderbook-dot","Nonce":4914,"Data":{"OrderType":"LimitOffer","OrderGuid":"ab9ce435-4a59-4cb8-82e1-dde2900f5fad","Price":{"aud":31.5102,"usd":23.724,"nzd":34.3249,"sgd":32.1336},"Volume":24.01253},"Time":1649023809412,"Event":"NewOrder"}
1649023813.994446: {"Channel":"orderbook-eth","Nonce":18989,"Data":{"OrderType":"LimitBid","OrderGuid":"26232b15-21df-473c-b815-6c08fa13f162","Price":{"aud":4694.85,"usd":3517.55,"nzd":5083.62,"sgd":4787.74},"Volume":21.69},"Time":1649023809443,"Event":"NewOrder"}
1649023813.99447: {"Channel":"orderbook-bch","Nonce":8209,"Data":{"OrderType":"LimitOffer","OrderGuid":"7ccb7ebd-0a8e-4369-b1fe-6f9fc9b12e14"},"Time":1649023809490,"Event":"OrderCanceled"}
1649023815.245505: {"Channel":"orderbook-eth","Nonce":18990,"Data":{"OrderType":"LimitOffer","OrderGuid":"0ac1af7b-dfd9-44c9-9138-983f9f6b76f6"},"Time":1649023809490,"Event":"OrderCanceled"}
1649023815.245546: {"Channel":"orderbook-dot","Nonce":4915,"Data":{"OrderType":"LimitBid","OrderGuid":"ab205f97-ca82-4055-b833-ff35fe1c6e25"},"Time":1649023809506,"Event":"OrderCanceled"}
1649023815.245567: {"Channel":"orderbook-eth","Nonce":18991,"Data":{"OrderType":"LimitBid","OrderGuid":"5d9244bb-edb9-4f94-a52d-33e3fadd9941"},"Time":1649023809521,"Event":"OrderCanceled"}
1649023815.2455838: {"Channel":"orderbook-eth","Nonce":18992,"Data":{"OrderType":"LimitOffer","OrderGuid":"18333ced-6696-491f-91f2-4b75384d8a51","Price":{"aud":4792.02,"usd":3571.97,"nzd":5194.84,"sgd":4861.81},"Volume":0.52249257},"Time":1649023809537,"Event":"NewOrder"}
1649023815.245622: {"Channel":"orderbook-eth","Nonce":18993,"Data":{"OrderType":"LimitOffer","OrderGuid":"8272acd7-bbc2-4e52-b51d-6f6f67a790a8","Price":{"aud":4753.51,"usd":3561.01,"nzd":5147.1,"sgd":4817.68},"Volume":4.126},"Time":1649023809553,"Event":"NewOrder"}
1649023815.245654: {"Channel":"orderbook-eth","Nonce":18994,"Data":{"OrderType":"LimitOffer","OrderGuid":"8e02da3b-c4a8-4b83-81cc-1bc2ff6e194a"},"Time":1649023809600,"Event":"OrderCanceled"}
1649023815.2456808: {"Channel":"orderbook-eth","Nonce":18995,"Data":{"OrderType":"LimitBid","OrderGuid":"7d0c4692-9d58-4ad2-949b-deef9ae55f5e"},"Time":1649023809600,"Event":"OrderCanceled"}
1649023815.245697: {"Channel":"orderbook-eth","Nonce":18996,"Data":{"OrderType":"LimitOffer","OrderGuid":"4896b70e-2ee5-4adc-9182-2194cc3659e8"},"Time":1649023809600,"Event":"OrderCanceled"}
1649023815.245721: {"Channel":"orderbook-eth","Nonce":18997,"Data":{"OrderType":"LimitOffer","OrderGuid":"2660efbf-faed-4539-9896-ffb01e54c3b8"},"Time":1649023809616,"Event":"OrderCanceled"}
1649023815.245737: {"Channel":"orderbook-eth","Nonce":18998,"Data":{"OrderType":"LimitOffer","OrderGuid":"18333ced-6696-491f-91f2-4b75384d8a51"},"Time":1649023809632,"Event":"OrderCanceled"}
1649023815.245758: {"Channel":"orderbook-bch","Nonce":8210,"Data":{"OrderType":"LimitOffer","OrderGuid":"7dfe9736-3753-4240-b947-6f3cc77f5cb3","Price":{"aud":510.85,"usd":384.62,"nzd":556.49,"sgd":520.96},"Volume":2.93},"Time":1649023809647,"Event":"NewOrder"}
1649023815.2458072: {"Channel":"orderbook-dot","Nonce":4916,"Data":{"OrderType":"LimitOffer","OrderGuid":"0c882014-2e49-4adb-8d70-ce24d5e3af68","Price":{"aud":31.4099,"usd":23.6485,"nzd":34.2156,"sgd":32.0314},"Volume":19.93895},"Time":1649023809647,"Event":"NewOrder"}
1649023815.2458398: {"Channel":"orderbook-dot","Nonce":4917,"Data":{"OrderType":"LimitBid","OrderGuid":"5a53f6ee-73df-48d3-bee1-c241b6eaa12c","Price":{"aud":30.8022,"usd":22.9599,"nzd":33.1493,"sgd":31.218},"Volume":69.2},"Time":1649023809663,"Event":"NewOrder"}
1649023815.24587: {"Channel":"orderbook-eth","Nonce":18999,"Data":{"OrderType":"LimitBid","OrderGuid":"0b8fc4de-d1da-453d-aba1-d07b0dae946a"},"Time":1649023809663,"Event":"OrderCanceled"}
1649023815.245887: {"Channel":"orderbook-eth","Nonce":19000,"Data":{"OrderType":"LimitOffer","OrderGuid":"845aa0aa-9f0b-4c44-91b4-fe49ba913eb1","Price":{"aud":4791.33,"usd":3571.45,"nzd":5194.09,"sgd":4861.1},"Volume":0.57384257},"Time":1649023809678,"Event":"NewOrder"}
1649023815.245913: {"Channel":"orderbook-bch","Nonce":8211,"Data":{"OrderType":"LimitOffer","OrderGuid":"16fe4e3c-06e0-41d0-8caa-aed34b27dda6","Price":{"aud":510.84,"usd":384.62,"nzd":556.48,"sgd":520.95},"Volume":21.20858658},"Time":1649023809678,"Event":"NewOrder"}
1649023815.245941: {"Channel":"orderbook-bch","Nonce":8212,"Data":{"OrderType":"LimitOffer","OrderGuid":"4b95b151-809e-4cfe-bcf3-62c82836482c"},"Time":1649023809694,"Event":"OrderCanceled"}
1649023815.2459571: {"Channel":"orderbook-eth","Nonce":19001,"Data":{"OrderType":"LimitOffer","OrderGuid":"50e71db6-49d9-4dd8-a1b4-5c89b85fa3d0","Price":{"aud":4731.9,"usd":3562.65,"nzd":5154.58,"sgd":4825.52},"Volume":15.0},"Time":1649023809725,"Event":"NewOrder"}
1649023815.245983: {"Channel":"orderbook-eth","Nonce":19002,"Data":{"OrderType":"LimitOffer","OrderGuid":"da52a114-13ba-4755-a4c1-b9e7c63c653d","Price":{"aud":4734.9,"usd":3564.9,"nzd":5157.85,"sgd":4828.58},"Volume":15.0},"Time":1649023809725,"Event":"NewOrder"}
1649023815.2460082: {"Channel":"orderbook-eth","Nonce":19003,"Data":{"OrderType":"LimitBid","OrderGuid":"6dd9a868-109d-4267-9fd6-b06e3fd187b7","Price":{"aud":4703.68,"usd":3506.12,"nzd":5062.1,"sgd":4767.17},"Volume":0.31513973},"Time":1649023809741,"Event":"NewOrder"}
1649023815.2460349: {"Channel":"orderbook-dot","Nonce":4918,"Data":{"OrderType":"LimitOffer","OrderGuid":"8fe0f95d-a750-43a1-906e-7cd7764052ad"},"Time":1649023809757,"Event":"OrderCanceled"}
1649023815.246051: {"Channel":"orderbook-eth","Nonce":19004,"Data":{"OrderType":"LimitBid","OrderGuid":"59985c43-e9b0-4c81-b86f-160f9d3e8e93"},"Time":1649023809803,"Event":"OrderCanceled"}
1649023815.246065: {"Channel":"orderbook-eth","Nonce":19005,"Data":{"OrderType":"LimitBid","OrderGuid":"947beb89-73c5-4b90-9634-53fe70a81b5e"},"Time":1649023809835,"Event":"OrderCanceled"}
1649023815.246079: {"Channel":"orderbook-eth","Nonce":19006,"Data":{"OrderType":"LimitBid","OrderGuid":"6820f9dc-2a90-458b-9a6f-1648ba3897bf","Price":{"aud":4724.7,"usd":3521.79,"nzd":5084.72,"sgd":4788.48},"Volume":15.0},"Time":1649023809835,"Event":"NewOrder"}
1649023815.246112: {"Channel":"orderbook-eth","Nonce":19007,"Data":{"OrderType":"LimitBid","OrderGuid":"82d3f9c1-8d35-434e-a520-ba6d283e4573","Price":{"aud":4721.7,"usd":3519.55,"nzd":5081.49,"sgd":4785.44},"Volume":15.0},"Time":1649023809866,"Event":"NewOrder"}
1649023815.246138: {"Channel":"orderbook-eth","Nonce":19008,"Data":{"OrderType":"LimitOffer","OrderGuid":"54b96eaa-e29a-496a-a5ba-e9bc38e9b652"},"Time":1649023809882,"Event":"OrderCanceled"}
1649023815.246154: {"Channel":"orderbook-eth","Nonce":19009,"Data":{"OrderType":"LimitBid","OrderGuid":"48278813-44f1-4494-b817-add4f83f50c4"},"Time":1649023809897,"Event":"OrderCanceled"}
1649023815.2461681: {"Channel":"orderbook-eth","Nonce":19010,"Data":{"OrderType":"LimitBid","OrderGuid":"6820f9dc-2a90-458b-9a6f-1648ba3897bf"},"Time":1649023809897,"Event":"OrderCanceled"}
1649023815.24619: {"Channel":"orderbook-eth","Nonce":19011,"Data":{"OrderType":"LimitOffer","OrderGuid":"da52a114-13ba-4755-a4c1-b9e7c63c653d"},"Time":1649023809913,"Event":"OrderCanceled"}
1649023815.246212: {"Channel":"orderbook-eth","Nonce":19012,"Data":{"OrderType":"LimitBid","OrderGuid":"82d3f9c1-8d35-434e-a520-ba6d283e4573"},"Time":1649023809913,"Event":"OrderCanceled"}
1649023815.246232: {"Channel":"orderbook-eth","Nonce":19013,"Data":{"OrderType":"LimitOffer","OrderGuid":"ecb563e4-93eb-4050-a4ea-68ecef3d4010","Price":{"aud":4782.66,"usd":3582.58,"nzd":5147.09,"sgd":4847.52},"Volume":0.57699188},"Time":1649023809928,"Event":"NewOrder"}
1649023815.24626: {"Channel":"orderbook-eth","Nonce":19014,"Data":{"OrderType":"LimitOffer","OrderGuid":"50e71db6-49d9-4dd8-a1b4-5c89b85fa3d0"},"Time":1649023809944,"Event":"OrderCanceled"}
1649023815.246282: {"Channel":"orderbook-eth","Nonce":19015,"Data":{"OrderType":"LimitBid","OrderGuid":"148a5590-d4a2-4b1b-a3a4-6ffd0fd9b769","Price":{"aud":4721.8,"usd":3519.62,"nzd":5081.6,"sgd":4785.54},"Volume":15.0},"Time":1649023809944,"Event":"NewOrder"}
1649023815.246309: {"Channel":"orderbook-eth","Nonce":19016,"Data":{"OrderType":"LimitBid","OrderGuid":"25d27390-72bf-4093-8d21-e18fa9d4366a","Price":{"aud":4724.8,"usd":3521.86,"nzd":5084.82,"sgd":4788.58},"Volume":15.0},"Time":1649023809960,"Event":"NewOrder"}
1649023815.246342: {"Channel":"orderbook-eth","Nonce":19017,"Data":{"OrderType":"LimitBid","OrderGuid":"5ca5e2ef-3265-4e2d-8838-8c4241bb0197","Price":{"aud":4678.0,"usd":3503.92,"nzd":5095.87,"sgd":4769.73},"Volume":0.4667395},"Time":1649023809975,"Event":"NewOrder"}
1649023815.246368: {"Channel":"orderbook-eth","Nonce":19018,"Data":{"OrderType":"LimitOffer","OrderGuid":"b0e6b269-d245-4d49-b74f-6b30b8f6f938","Price":{"aud":4732.0,"usd":3562.72,"nzd":5154.69,"sgd":4825.62},"Volume":15.0},"Time":1649023809975,"Event":"NewOrder"}
1649023815.2463942: {"Channel":"orderbook-eth","Nonce":19019,"Data":{"OrderType":"LimitOffer","OrderGuid":"40e23b37-d748-45cc-8604-90f01b24d532","Price":{"aud":4735.0,"usd":3564.98,"nzd":5157.96,"sgd":4828.68},"Volume":15.0},"Time":1649023809975,"Event":"NewOrder"}
1649023815.246418: {"Channel":"orderbook-eth","Nonce":19020,"Data":{"OrderType":"LimitOffer","OrderGuid":"13d0a07d-a634-4e07-b42e-3c4959c5e9ef","Price":{"aud":4742.37,"usd":3570.53,"nzd":5165.99,"sgd":4836.2},"Volume":3.57864852},"Time":1649023809975,"Event":"NewOrder"}
1649023815.246444: {"Channel":"orderbook-eth","Nonce":19021,"Data":{"OrderType":"LimitOffer","OrderGuid":"9e513805-1752-4663-8b97-74e3c6c76bde"},"Time":1649023809991,"Event":"OrderCanceled"}
1649023815.2464588: {"Channel":"orderbook-matic","Nonce":5852,"Data":{"OrderType":"LimitOffer","OrderGuid":"babdc163-8793-4a6d-bd5a-61c6f4d3a1d4"},"Time":1649023810009,"Event":"OrderCanceled"}
1649023815.246474: {"Channel":"orderbook-matic","Nonce":5853,"Data":{"OrderType":"LimitBid","OrderGuid":"660f3a62-f05c-4567-b0ae-3c56ce9b3b29"},"Time":1649023810025,"Event":"OrderCanceled"}
1649023815.246489: {"Channel":"orderbook-matic","Nonce":5854,"Data":{"OrderType":"LimitOffer","OrderGuid":"6b7753f3-9082-494a-96b0-bcde84833e6f","Price":{"aud":2.31242,"usd":1.74102,"nzd":2.51898,"sgd":2.35817},"Volume":6000.0},"Time":1649023810040,"Event":"NewOrder"}
1649023815.246517: {"Channel":"orderbook-matic","Nonce":5855,"Data":{"OrderType":"LimitBid","OrderGuid":"56b6beab-61da-4474-9b51-62ce55ab44af","Price":{"aud":2.26124,"usd":1.68552,"nzd":2.43354,"sgd":2.29176},"Volume":5503.83706},"Time":1649023810072,"Event":"NewOrder"}
1649023815.246544: {"Channel":"orderbook-matic","Nonce":5856,"Data":{"OrderType":"LimitOffer","OrderGuid":"03201890-b4b7-4b8e-b2f4-bb80c3564aef","Price":{"aud":2.27199,"usd":1.71058,"nzd":2.47494,"sgd":2.31694},"Volume":5377.98385},"Time":1649023810072,"Event":"NewOrder"}
1649023815.246572: {"Channel":"orderbook-eth","Nonce":19022,"Data":{"OrderType":"LimitBid","OrderGuid":"305eff77-d791-45d1-a9da-cd6e6fbbe279","Price":{"aud":4693.11,"usd":3516.24,"nzd":5081.73,"sgd":4785.96},"Volume":23.027},"Time":1649023810134,"Event":"NewOrder"}
1649023815.246599: {"Channel":"orderbook-bch","Nonce":8213,"Data":{"OrderType":"LimitBid","OrderGuid":"cd39d9c2-f80e-461f-8c72-3ee05172307d"},"Time":1649023810165,"Event":"OrderCanceled"}
1649023815.246615: {"Channel":"orderbook-matic","Nonce":5857,"Data":{"OrderType":"LimitOffer","OrderGuid":"e4f73ded-e9f9-4428-856c-ef2a2eaecf14","Price":{"aud":2.29363,"usd":1.72688,"nzd":2.49851,"sgd":2.33901},"Volume":181.7839},"Time":1649023810197,"Event":"NewOrder"}
1649023815.246641: {"Channel":"orderbook-bch","Nonce":8214,"Data":{"OrderType":"LimitBid","OrderGuid":"56520f31-8e66-4030-8441-8130ae1693c0"},"Time":1649023810275,"Event":"OrderCanceled"}
1649023815.246658: {"Channel":"orderbook-matic","Nonce":5858,"Data":{"OrderType":"LimitOffer","OrderGuid":"c7e9815d-1ee5-4151-ba02-e698b817e623"},"Time":1649023810275,"Event":"OrderCanceled"}
1649023815.246672: {"Channel":"orderbook-bch","Nonce":8215,"Data":{"OrderType":"LimitBid","OrderGuid":"dfd40687-3167-4968-ad69-5f00e0a2847c","Price":{"aud":503.9,"usd":375.6,"nzd":542.29,"sgd":510.7},"Volume":6.0},"Time":1649023810306,"Event":"NewOrder"}
1649023815.246698: {"Channel":"orderbook-bch","Nonce":8216,"Data":{"OrderType":"LimitBid","OrderGuid":"746587e6-7b02-4d6f-9790-fabc2709ec0b","Price":{"aud":503.2,"usd":375.08,"nzd":541.54,"sgd":509.99},"Volume":6.0},"Time":1649023810306,"Event":"NewOrder"}
1649023815.2467241: {"Channel":"orderbook-eth","Nonce":19023,"Data":{"OrderType":"LimitOffer","OrderGuid":"6738439b-98e2-4849-87a9-260b1e35b2ee"},"Time":1649023810306,"Event":"OrderCanceled"}
1649023815.246746: {"Channel":"orderbook-eth","Nonce":19024,"Data":{"OrderType":"LimitOffer","OrderGuid":"40e23b37-d748-45cc-8604-90f01b24d532"},"Time":1649023810431,"Event":"OrderCanceled"}
1649023815.246783: {"Channel":"orderbook-eth","Nonce":19025,"Data":{"OrderType":"LimitBid","OrderGuid":"25d27390-72bf-4093-8d21-e18fa9d4366a"},"Time":1649023810462,"Event":"OrderCanceled"}
1649023815.246801: {"Channel":"orderbook-eth","Nonce":19026,"Data":{"OrderType":"LimitBid","OrderGuid":"148a5590-d4a2-4b1b-a3a4-6ffd0fd9b769"},"Time":1649023810462,"Event":"OrderCanceled"}
1649023815.246818: {"Channel":"orderbook-eth","Nonce":19027,"Data":{"OrderType":"LimitBid","OrderGuid":"26232b15-21df-473c-b815-6c08fa13f162"},"Time":1649023810478,"Event":"OrderCanceled"}
1649023815.2468338: {"Channel":"orderbook-eth","Nonce":19028,"Data":{"OrderType":"LimitOffer","OrderGuid":"845aa0aa-9f0b-4c44-91b4-fe49ba913eb1"},"Time":1649023810525,"Event":"OrderCanceled"}
1649023815.246851: {"Channel":"orderbook-eth","Nonce":19029,"Data":{"OrderType":"LimitBid","OrderGuid":"ab699de3-4b6d-4ca1-9293-8a6fae9213e5","Price":{"aud":4721.7,"usd":3519.55,"nzd":5081.49,"sgd":4785.44},"Volume":15.0},"Time":1649023810540,"Event":"NewOrder"}
1649023815.2468748: {"Channel":"orderbook-eth","Nonce":19030,"Data":{"OrderType":"LimitOffer","OrderGuid":"b0e6b269-d245-4d49-b74f-6b30b8f6f938"},"Time":1649023810556,"Event":"OrderCanceled"}
1649023815.2468932: {"Channel":"orderbook-eth","Nonce":19031,"Data":{"OrderType":"LimitOffer","OrderGuid":"f2cbe3af-f524-426b-88cb-53de3afc06c6","Price":{"aud":4792.12,"usd":3572.04,"nzd":5194.94,"sgd":4861.91},"Volume":0.55171306},"Time":1649023810573,"Event":"NewOrder"}
1649023815.246916: {"Channel":"orderbook-eth","Nonce":19032,"Data":{"OrderType":"LimitBid","OrderGuid":"731232f4-a4b0-4b83-ba7d-92d70c9a80ae"},"Time":1649023810604,"Event":"OrderCanceled"}
1649023815.246928: {"Channel":"orderbook-eth","Nonce":19033,"Data":{"OrderType":"LimitOffer","OrderGuid":"b90ba4b5-32c3-4a22-bbd1-6db9c63105cb"},"Time":1649023810604,"Event":"OrderCanceled"}
1649023815.24694: {"Channel":"orderbook-eth","Nonce":19034,"Data":{"OrderType":"LimitOffer","OrderGuid":"f2cbe3af-f524-426b-88cb-53de3afc06c6"},"Time":1649023810620,"Event":"OrderCanceled"}
1649023815.246956: {"Channel":"orderbook-eth","Nonce":19035,"Data":{"OrderType":"LimitBid","OrderGuid":"6cb6ae59-506f-47ef-9c37-c360d2472a5d"},"Time":1649023810635,"Event":"OrderCanceled"}
1649023815.246968: {"Channel":"orderbook-eth","Nonce":19036,"Data":{"OrderType":"LimitBid","OrderGuid":"691f36bf-579e-461c-968f-63c793449521","Price":{"aud":4696.67,"usd":3518.91,"nzd":5085.58,"sgd":4789.59},"Volume":3.11202104},"Time":1649023810635,"Event":"NewOrder"}
1649023815.246988: {"Channel":"orderbook-eth","Nonce":19037,"Data":{"OrderType":"LimitOffer","OrderGuid":"305731c3-262f-47d2-b94a-30d7821bd223","Price":{"aud":4731.9,"usd":3562.65,"nzd":5154.58,"sgd":4825.52},"Volume":15.0},"Time":1649023810635,"Event":"NewOrder"}
1649023815.247009: {"Channel":"orderbook-eth","Nonce":19038,"Data":{"OrderType":"LimitOffer","OrderGuid":"11a9df87-c98f-40e6-8e75-c7c86e142a5c","Price":{"aud":4734.9,"usd":3564.9,"nzd":5157.85,"sgd":4828.58},"Volume":15.0},"Time":1649023810651,"Event":"NewOrder"}
1649023815.247029: {"Channel":"orderbook-eth","Nonce":19039,"Data":{"OrderType":"LimitBid","OrderGuid":"869c9719-7e49-4ddc-80f5-30c1b833f4ae","Price":{"aud":4724.7,"usd":3521.79,"nzd":5084.72,"sgd":4788.48},"Volume":15.0},"Time":1649023810651,"Event":"NewOrder"}
1649023815.2470489: {"Channel":"orderbook-eth","Nonce":19040,"Data":{"OrderType":"LimitOffer","OrderGuid":"29290efd-2cb4-4a0b-9a61-0778845ac8cd","Price":{"aud":4757.26,"usd":3563.82,"nzd":5151.16,"sgd":4821.48},"Volume":1.04647813},"Time":1649023810651,"Event":"NewOrder"}
1649023815.247069: {"Channel":"orderbook-eth","Nonce":19041,"Data":{"OrderType":"LimitOffer","OrderGuid":"5e0b8ac1-21fe-4110-ab8c-b84d6eea34c8","Price":{"aud":4792.59,"usd":3572.39,"nzd":5195.45,"sgd":4862.38},"Volume":0.55026929},"Time":1649023810667,"Event":"NewOrder"}
1649023815.2470899: {"Channel":"orderbook-eth","Nonce":19042,"Data":{"OrderType":"LimitBid","OrderGuid":"c8c65b36-fa31-4786-9ef1-43ef76e50303","Price":{"aud":4724.63,"usd":3521.73,"nzd":5084.64,"sgd":4788.41},"Volume":14.14},"Time":1649023810667,"Event":"NewOrder"}
1649023815.2471108: {"Channel":"orderbook-eth","Nonce":19043,"Data":{"OrderType":"LimitBid","OrderGuid":"691f36bf-579e-461c-968f-63c793449521"},"Time":1649023810682,"Event":"OrderCanceled"}
1649023815.247128: {"Channel":"orderbook-eth","Nonce":19044,"Data":{"OrderType":"LimitBid","OrderGuid":"38aeb572-ed74-4c09-9c5d-ebee630fd08a","Price":{"aud":4724.71,"usd":3521.79,"nzd":5084.73,"sgd":4788.49},"Volume":14.14},"Time":1649023810714,"Event":"NewOrder"}
1649023815.247148: {"Channel":"orderbook-eth","Nonce":19045,"Data":{"OrderType":"LimitBid","OrderGuid":"ab699de3-4b6d-4ca1-9293-8a6fae9213e5"},"Time":1649023810714,"Event":"OrderCanceled"}
1649023815.247165: {"Channel":"orderbook-eth","Nonce":19046,"Data":{"OrderType":"LimitOffer","OrderGuid":"11a9df87-c98f-40e6-8e75-c7c86e142a5c"},"Time":1649023810714,"Event":"OrderCanceled"}
1649023815.2471821: {"Channel":"orderbook-eth","Nonce":19047,"Data":{"OrderType":"LimitBid","OrderGuid":"869c9719-7e49-4ddc-80f5-30c1b833f4ae"},"Time":1649023810714,"Event":"OrderCanceled"}
1649023815.2472: {"Channel":"orderbook-eth","Nonce":19048,"Data":{"OrderType":"LimitOffer","OrderGuid":"305731c3-262f-47d2-b94a-30d7821bd223"},"Time":1649023810714,"Event":"OrderCanceled"}
1649023815.2472162: {"Channel":"orderbook-eth","Nonce":19049,"Data":{"OrderType":"LimitBid","OrderGuid":"c8c65b36-fa31-4786-9ef1-43ef76e50303"},"Time":1649023810729,"Event":"OrderCanceled"}
1649023815.247233: {"Channel":"orderbook-eth","Nonce":19050,"Data":{"OrderType":"LimitBid","OrderGuid":"0f8ed366-8889-4799-aab5-b58759553688","Price":{"aud":4724.9,"usd":3521.94,"nzd":5084.93,"sgd":4788.68},"Volume":15.0},"Time":1649023810760,"Event":"NewOrder"}
1649023815.247253: {"Channel":"orderbook-eth","Nonce":19051,"Data":{"OrderType":"LimitBid","OrderGuid":"8fc29670-d34d-44b8-904a-c047e64f27a4","Price":{"aud":4721.9,"usd":3519.7,"nzd":5081.7,"sgd":4785.64},"Volume":15.0},"Time":1649023810760,"Event":"NewOrder"}
1649023815.247273: {"Channel":"orderbook-eth","Nonce":19052,"Data":{"OrderType":"LimitOffer","OrderGuid":"245a07af-c8f4-46c7-9520-7fceb588e52f","Price":{"aud":4732.1,"usd":3562.8,"nzd":5154.8,"sgd":4825.72},"Volume":15.0},"Time":1649023810760,"Event":"NewOrder"}
1649023815.247293: {"Channel":"orderbook-eth","Nonce":19053,"Data":{"OrderType":"LimitOffer","OrderGuid":"880332b6-2f67-4cfd-b774-2a12a948ce78","Price":{"aud":4735.1,"usd":3565.06,"nzd":5158.07,"sgd":4828.78},"Volume":15.0},"Time":1649023810777,"Event":"NewOrder"}
1649023815.2473128: {"Channel":"orderbook-eth","Nonce":19054,"Data":{"OrderType":"LimitBid","OrderGuid":"6dd9a868-109d-4267-9fd6-b06e3fd187b7"},"Time":1649023810793,"Event":"OrderCanceled"}
1649023815.2473311: {"Channel":"orderbook-eth","Nonce":19055,"Data":{"OrderType":"LimitBid","OrderGuid":"fbd2f7a9-5d49-45c8-8fea-c20f68931362","Price":{"aud":4693.41,"usd":3516.47,"nzd":5082.06,"sgd":4786.27},"Volume":3.13981672},"Time":1649023810809,"Event":"NewOrder"}
1649023815.247351: {"Channel":"orderbook-eth","Nonce":19056,"Data":{"OrderType":"LimitBid","OrderGuid":"fbf71d6b-282a-43ad-9d10-84e9d72dc5ac","Price":{"aud":4703.69,"usd":3506.13,"nzd":5062.11,"sgd":4767.18},"Volume":0.30338857},"Time":1649023810887,"Event":"NewOrder"}
1649023815.2473722: {"Channel":"orderbook-eth","Nonce":19057,"Data":{"OrderType":"LimitOffer","OrderGuid":"5e0b8ac1-21fe-4110-ab8c-b84d6eea34c8"},"Time":1649023810918,"Event":"OrderCanceled"}
1649023815.2473888: {"Channel":"orderbook-eth","Nonce":19058,"Data":{"OrderType":"LimitOffer","OrderGuid":"70291e73-9e9d-4394-82ed-d740e5b03917","Price":{"aud":4792.98,"usd":3572.68,"nzd":5195.87,"sgd":4862.78},"Volume":0.5788926},"Time":1649023810965,"Event":"NewOrder"}
1649023815.247411: {"Channel":"orderbook-eth","Nonce":19059,"Data":{"OrderType":"LimitBid","OrderGuid":"5ca5e2ef-3265-4e2d-8838-8c4241bb0197"},"Time":1649023810965,"Event":"OrderCanceled"}
1649023815.2474282: {"Channel":"orderbook-eth","Nonce":19060,"Data":{"OrderType":"LimitOffer","OrderGuid":"880332b6-2f67-4cfd-b774-2a12a948ce78"},"Time":1649023810997,"Event":"OrderCanceled"}
1649023815.247445: {"Channel":"orderbook-matic","Nonce":5859,"Data":{"OrderType":"LimitOffer","OrderGuid":"796147f2-025e-4d76-b105-bd5efcdbfdef"},"Time":1649023810997,"Event":"OrderCanceled"}
1649023815.247457: {"Channel":"orderbook-dot","Nonce":4919,"Data":{"OrderType":"LimitOffer","OrderGuid":"b55a9987-fb2e-41c3-8066-537b3cdd14de"},"Time":1649023810997,"Event":"OrderCanceled"}
1649023815.247475: {"Channel":"orderbook-eth","Nonce":19061,"Data":{"OrderType":"LimitBid","OrderGuid":"8fc29670-d34d-44b8-904a-c047e64f27a4"},"Time":1649023810997,"Event":"OrderCanceled"}
1649023815.247494: {"Channel":"orderbook-dot","Nonce":4920,"Data":{"OrderType":"LimitOffer","OrderGuid":"f4a54b32-32dc-4b44-997b-dc5c39393a80"},"Time":1649023810997,"Event":"OrderCanceled"}
1649023815.24751: {"Channel":"orderbook-eth","Nonce":19062,"Data":{"OrderType":"LimitBid","OrderGuid":"1642b60e-6a7b-4706-9005-2d915febe21e","Price":{"aud":4678.01,"usd":3503.92,"nzd":5095.88,"sgd":4769.74},"Volume":0.56383114},"Time":1649023810997,"Event":"NewOrder"}
1649023815.2475321: {"Channel":"orderbook-eth","Nonce":19063,"Data":{"OrderType":"LimitBid","OrderGuid":"0f8ed366-8889-4799-aab5-b58759553688"},"Time":1649023811028,"Event":"OrderCanceled"}
1649023815.24755: {"Channel":"orderbook-matic","Nonce":5860,"Data":{"OrderType":"LimitBid","OrderGuid":"3a7531f9-a5a7-4919-8280-6bcbe408dd85"},"Time":1649023811044,"Event":"OrderCanceled"}
1649023815.247562: {"Channel":"orderbook-eth","Nonce":19064,"Data":{"OrderType":"LimitBid","OrderGuid":"8eba081a-3e74-4323-afc0-7b1e08e41111","Price":{"aud":4699.9,"usd":3521.33,"nzd":5089.09,"sgd":4792.89},"Volume":4.421},"Time":1649023811059,"Event":"NewOrder"}
1649023815.247583: {"Channel":"orderbook-eth","Nonce":19065,"Data":{"OrderType":"LimitOffer","OrderGuid":"245a07af-c8f4-46c7-9520-7fceb588e52f"},"Time":1649023811091,"Event":"OrderCanceled"}
1649023815.2476008: {"Channel":"orderbook-eth","Nonce":19066,"Data":{"OrderType":"LimitBid","OrderGuid":"eba22d90-d774-4f44-901d-061d0fb974aa","Price":{"aud":4725.7,"usd":3522.53,"nzd":5085.79,"sgd":4789.49},"Volume":15.0},"Time":1649023811106,"Event":"NewOrder"}
1649023815.2476218: {"Channel":"orderbook-bch","Nonce":8217,"Data":{"OrderType":"LimitOffer","OrderGuid":"7dfe9736-3753-4240-b947-6f3cc77f5cb3"},"Time":1649023811106,"Event":"OrderCanceled"}
1649023815.2476401: {"Channel":"orderbook-dot","Nonce":4921,"Data":{"OrderType":"LimitOffer","OrderGuid":"a3ba0a82-b842-43b5-abc5-c033f026852c","Price":{"aud":31.4,"usd":23.6411,"nzd":34.2048,"sgd":32.0213},"Volume":80.0},"Time":1649023811122,"Event":"NewOrder"}
1649023815.247661: {"Channel":"orderbook-eth","Nonce":19067,"Data":{"OrderType":"LimitBid","OrderGuid":"45b5b329-0061-462a-bf5c-eab7fafba685","Price":{"aud":4722.7,"usd":3520.3,"nzd":5082.56,"sgd":4786.45},"Volume":15.0},"Time":1649023811122,"Event":"NewOrder"}
1649023815.2476811: {"Channel":"orderbook-eth","Nonce":19068,"Data":{"OrderType":"LimitOffer","OrderGuid":"b9cfc2fe-b0b6-466c-b921-824cb2bf05b6","Price":{"aud":4732.9,"usd":3563.4,"nzd":5155.67,"sgd":4826.54},"Volume":15.0},"Time":1649023811122,"Event":"NewOrder"}
1649023815.247701: {"Channel":"orderbook-dot","Nonce":4922,"Data":{"OrderType":"LimitBid","OrderGuid":"84f1757e-60ac-4b3b-bc37-dddd38e1cb12"},"Time":1649023811137,"Event":"OrderCanceled"}
1649023815.2477188: {"Channel":"orderbook-dot","Nonce":4923,"Data":{"OrderType":"LimitOffer","OrderGuid":"4f2f6c4e-7163-4477-a828-75ea3c9aba11","Price":{"aud":31.44,"usd":23.6712,"nzd":34.2484,"sgd":32.0621},"Volume":80.0},"Time":1649023811137,"Event":"NewOrder"}
1649023815.247741: {"Channel":"orderbook-eth","Nonce":19069,"Data":{"OrderType":"LimitBid","OrderGuid":"55337241-aefa-40b2-b39b-1fc7afa1c644","Price":{"aud":4698.1,"usd":3519.98,"nzd":5087.13,"sgd":4791.05},"Volume":5.223},"Time":1649023811137,"Event":"NewOrder"}
1649023815.247762: {"Channel":"orderbook-matic","Nonce":5861,"Data":{"OrderType":"LimitBid","OrderGuid":"a156c907-d546-4cc6-862c-999bad5b01cf"},"Time":1649023811153,"Event":"OrderCanceled"}
1649023815.24778: {"Channel":"orderbook-bch","Nonce":8218,"Data":{"OrderType":"LimitOffer","OrderGuid":"d3e7cf8a-0a89-4a41-8eaa-5d45b840bd7c","Price":{"aud":510.86,"usd":384.63,"nzd":556.5,"sgd":520.97},"Volume":21.20858658},"Time":1649023811153,"Event":"NewOrder"}
1649023815.247801: {"Channel":"orderbook-eth","Nonce":19070,"Data":{"OrderType":"LimitOffer","OrderGuid":"ba940496-1c3e-423b-8aaf-180c54c86029","Price":{"aud":4735.9,"usd":3565.66,"nzd":5158.94,"sgd":4829.6},"Volume":15.0},"Time":1649023811153,"Event":"NewOrder"}
1649023815.247822: {"Channel":"orderbook-eth","Nonce":19071,"Data":{"OrderType":"LimitBid","OrderGuid":"305eff77-d791-45d1-a9da-cd6e6fbbe279"},"Time":1649023811169,"Event":"OrderCanceled"}
1649023815.247839: {"Channel":"orderbook-bch","Nonce":8219,"Data":{"OrderType":"LimitOffer","OrderGuid":"16fe4e3c-06e0-41d0-8caa-aed34b27dda6"},"Time":1649023811169,"Event":"OrderCanceled"}
1649023815.2478569: {"Channel":"orderbook-dot","Nonce":4924,"Data":{"OrderType":"LimitOffer","OrderGuid":"7aff3221-224e-416e-bc6a-7bb82b2aebe6","Price":{"aud":31.3798,"usd":23.6259,"nzd":34.1828,"sgd":32.0007},"Volume":19.93895},"Time":1649023811184,"Event":"NewOrder"}
1649023815.247879: {"Channel":"orderbook-dot","Nonce":4925,"Data":{"OrderType":"LimitBid","OrderGuid":"f1f7e29d-6dae-4ee1-9e23-a41695538a81"},"Time":1649023811200,"Event":"OrderCanceled"}
1649023815.2478971: {"Channel":"orderbook-matic","Nonce":5862,"Data":{"OrderType":"LimitOffer","OrderGuid":"fe2e8fdd-1e29-456b-a975-a7183fc589cf"},"Time":1649023811200,"Event":"OrderCanceled"}
1649023815.247909: {"Channel":"orderbook-matic","Nonce":5863,"Data":{"OrderType":"LimitBid","OrderGuid":"3e9a5a09-0061-4e53-accf-6e8408568ee0","Price":{"aud":2.26,"usd":1.6846,"nzd":2.43221,"sgd":2.29051},"Volume":5583.0},"Time":1649023811200,"Event":"NewOrder"}
1649023815.2479308: {"Channel":"orderbook-dot","Nonce":4926,"Data":{"OrderType":"LimitBid","OrderGuid":"cb52a29c-96d4-4e27-8283-6e6bd9a9cc9c","Price":{"aud":31.16,"usd":23.2266,"nzd":33.5343,"sgd":31.5806},"Volume":80.0},"Time":1649023811231,"Event":"NewOrder"}
1649023815.247953: {"Channel":"orderbook-dot","Nonce":4927,"Data":{"OrderType":"LimitBid","OrderGuid":"5badbb30-c597-40da-91c3-7014ec3ea7a4"},"Time":1649023811231,"Event":"OrderCanceled"}
1649023815.247971: {"Channel":"orderbook-dot","Nonce":4928,"Data":{"OrderType":"LimitBid","OrderGuid":"b3e9ecd3-dc44-4184-9564-0798ea011456","Price":{"aud":31.2,"usd":23.2564,"nzd":33.5774,"sgd":31.6212},"Volume":80.0},"Time":1649023811231,"Event":"NewOrder"}
1649023815.247991: {"Channel":"orderbook-dot","Nonce":4929,"Data":{"OrderType":"LimitBid","OrderGuid":"71bec59f-b921-4f35-97e2-bb42ce881913","Price":{"aud":30.8023,"usd":22.96,"nzd":33.1494,"sgd":31.2181},"Volume":457.6},"Time":1649023811262,"Event":"NewOrder"}
1649023815.248012: {"Channel":"orderbook-bch","Nonce":8220,"Data":{"OrderType":"LimitBid","OrderGuid":"746587e6-7b02-4d6f-9790-fabc2709ec0b"},"Time":1649023811262,"Event":"OrderCanceled"}
1649023815.248029: {"Channel":"orderbook-dot","Nonce":4930,"Data":{"OrderType":"LimitOffer","OrderGuid":"0c882014-2e49-4adb-8d70-ce24d5e3af68"},"Time":1649023811262,"Event":"OrderCanceled"}
1649023815.248047: {"Channel":"orderbook-bch","Nonce":8221,"Data":{"OrderType":"LimitOffer","OrderGuid":"379637cd-aa61-44b6-8403-153baa0d3360"},"Time":1649023811262,"Event":"OrderCanceled"}
1649023815.2480588: {"Channel":"orderbook-bch","Nonce":8222,"Data":{"OrderType":"LimitOffer","OrderGuid":"ff75a18d-5671-4674-9da6-f036bf87f8b8","Price":{"aud":510.83,"usd":384.61,"nzd":556.46,"sgd":520.94},"Volume":2.93},"Time":1649023811262,"Event":"NewOrder"}
1649023815.2480798: {"Channel":"orderbook-eth","Nonce":19072,"Data":{"OrderType":"LimitOffer","OrderGuid":"70291e73-9e9d-4394-82ed-d740e5b03917"},"Time":1649023811310,"Event":"OrderCanceled"}
1649023815.248099: {"Channel":"orderbook-eth","Nonce":19073,"Data":{"OrderType":"LimitOffer","OrderGuid":"29290efd-2cb4-4a0b-9a61-0778845ac8cd"},"Time":1649023811310,"Event":"OrderCanceled"}
1649023815.248116: {"Channel":"orderbook-matic","Nonce":5864,"Data":{"OrderType":"LimitOffer","OrderGuid":"9c391355-7f6f-4629-843a-0d134b8b2261","Price":{"aud":2.2725,"usd":1.71097,"nzd":2.4755,"sgd":2.31746},"Volume":5583.0},"Time":1649023811310,"Event":"NewOrder"}
1649023815.248138: {"Channel":"orderbook-matic","Nonce":5865,"Data":{"OrderType":"LimitOffer","OrderGuid":"1a4d4d2e-80df-4142-9579-2f7a90f6ee52","Price":{"aud":2.274,"usd":1.7121,"nzd":2.47713,"sgd":2.31899},"Volume":5583.0},"Time":1649023811326,"Event":"NewOrder"}
1649023815.24816: {"Channel":"orderbook-bch","Nonce":8223,"Data":{"OrderType":"LimitOffer","OrderGuid":"8344b8b8-d265-4c75-9f21-6e1bcf2154d7","Price":{"aud":510.82,"usd":384.6,"nzd":556.45,"sgd":520.93},"Volume":21.20858658},"Time":1649023811326,"Event":"NewOrder"}
1649023815.248181: {"Channel":"orderbook-eth","Nonce":19074,"Data":{"OrderType":"LimitBid","OrderGuid":"e1d8dd7b-b07a-4a56-be3a-6f54f16ce6e3","Price":{"aud":4696.26,"usd":3518.6,"nzd":5085.14,"sgd":4789.17},"Volume":13.181},"Time":1649023811341,"Event":"NewOrder"}
1649023815.248202: {"Channel":"orderbook-bch","Nonce":8224,"Data":{"OrderType":"LimitOffer","OrderGuid":"d3e7cf8a-0a89-4a41-8eaa-5d45b840bd7c"},"Time":1649023811357,"Event":"OrderCanceled"}
1649023815.24822: {"Channel":"orderbook-eth","Nonce":19075,"Data":{"OrderType":"LimitOffer","OrderGuid":"7adc3467-2adf-461c-a332-cf4264cb5c1a","Price":{"aud":4793.67,"usd":3573.2,"nzd":5196.63,"sgd":4863.49},"Volume":0.60019034},"Time":1649023811357,"Event":"NewOrder"}
1649023815.248241: {"Channel":"orderbook-bch","Nonce":8225,"Data":{"OrderType":"LimitOffer","OrderGuid":"c3123421-97f9-4a82-8531-34d5278c3120"},"Time":1649023811357,"Event":"OrderCanceled"}
1649023815.248254: {"Channel":"orderbook-eth","Nonce":19076,"Data":{"OrderType":"LimitOffer","OrderGuid":"b78c1ce0-70bc-408b-a7ee-334376064e5f","Price":{"aud":4757.4,"usd":3563.92,"nzd":5151.31,"sgd":4821.62},"Volume":1.19191779},"Time":1649023811373,"Event":"NewOrder"}
1649023815.2482738: {"Channel":"orderbook-matic","Nonce":5866,"Data":{"OrderType":"LimitBid","OrderGuid":"8a1f3514-1436-4de4-a7f6-87db75ef5036","Price":{"aud":2.2615,"usd":1.68572,"nzd":2.43382,"sgd":2.29203},"Volume":5583.0},"Time":1649023811435,"Event":"NewOrder"}
1649023815.248296: {"Channel":"orderbook-bch","Nonce":8226,"Data":{"OrderType":"LimitOffer","OrderGuid":"9f57c1d2-e02a-4049-a224-89cb6a980efd"},"Time":1649023811498,"Event":"OrderCanceled"}
1649023815.248308: {"Channel":"orderbook-bch","Nonce":8227,"Data":{"OrderType":"LimitBid","OrderGuid":"dfd40687-3167-4968-ad69-5f00e0a2847c"},"Time":1649023811529,"Event":"OrderCanceled"}
1649023815.248325: {"Channel":"orderbook-eth","Nonce":19077,"Data":{"OrderType":"LimitOffer","OrderGuid":"b9cfc2fe-b0b6-466c-b921-824cb2bf05b6"},"Time":1649023811576,"Event":"OrderCanceled"}
1649023815.248341: {"Channel":"orderbook-eth","Nonce":19078,"Data":{"OrderType":"LimitBid","OrderGuid":"45b5b329-0061-462a-bf5c-eab7fafba685"},"Time":1649023811591,"Event":"OrderCanceled"}
1649023815.2483578: {"Channel":"orderbook-eth","Nonce":19079,"Data":{"OrderType":"LimitBid","OrderGuid":"eba22d90-d774-4f44-901d-061d0fb974aa"},"Time":1649023811607,"Event":"OrderCanceled"}
1649023815.248375: {"Channel":"orderbook-bch","Nonce":8228,"Data":{"OrderType":"LimitOffer","OrderGuid":"5ba6ce84-ac9b-43e7-ae4b-b5ee56a28efb","Price":{"aud":507.5,"usd":382.1,"nzd":552.84,"sgd":517.55},"Volume":6.0},"Time":1649023811607,"Event":"NewOrder"}
1649023815.248396: {"Channel":"orderbook-eth","Nonce":19080,"Data":{"OrderType":"LimitOffer","OrderGuid":"ba940496-1c3e-423b-8aaf-180c54c86029"},"Time":1649023811607,"Event":"OrderCanceled"}
1649023815.2484128: {"Channel":"orderbook-bch","Nonce":8229,"Data":{"OrderType":"LimitBid","OrderGuid":"7a17009a-67e4-455e-9c97-829362dad836","Price":{"aud":504.1,"usd":375.75,"nzd":542.51,"sgd":510.9},"Volume":6.0},"Time":1649023811623,"Event":"NewOrder"}
1649023815.2484338: {"Channel":"orderbook-bch","Nonce":8230,"Data":{"OrderType":"LimitBid","OrderGuid":"151828d2-685e-460d-b7a3-f1461b5bf8d6","Price":{"aud":503.4,"usd":375.23,"nzd":541.75,"sgd":510.19},"Volume":6.0},"Time":1649023811638,"Event":"NewOrder"}
1649023815.2484539: {"Channel":"orderbook-bch","Nonce":8231,"Data":{"OrderType":"LimitOffer","OrderGuid":"edf4f41b-ef10-4d01-aef3-1f4e7b2ee583","Price":{"aud":506.8,"usd":381.57,"nzd":552.07,"sgd":516.83},"Volume":6.0},"Time":1649023811638,"Event":"NewOrder"}
1649023815.2484748: {"Channel":"orderbook-eth","Nonce":19081,"Data":{"OrderType":"LimitOffer","OrderGuid":"f9c02d7e-6248-42fd-9e57-cef3bc2a2dbd","Price":{"aud":4735.89,"usd":3565.65,"nzd":5158.93,"sgd":4829.59},"Volume":3.57864852},"Time":1649023811638,"Event":"NewOrder"}
1649023815.248496: {"Channel":"orderbook-eth","Nonce":19082,"Data":{"OrderType":"LimitOffer","OrderGuid":"13d0a07d-a634-4e07-b42e-3c4959c5e9ef"},"Time":1649023811654,"Event":"OrderCanceled"}
1649023815.248514: {"Channel":"orderbook-bch","Nonce":8232,"Data":{"OrderType":"LimitOffer","OrderGuid":"ff22afa0-0be8-45ec-a0a1-8e4d4de99d31","Price":{"aud":508.86,"usd":383.13,"nzd":554.32,"sgd":518.93},"Volume":39.74331},"Time":1649023811670,"Event":"NewOrder"}
1649023815.248534: {"Channel":"orderbook-eth","Nonce":19083,"Data":{"OrderType":"LimitOffer","OrderGuid":"7a7495fe-2c00-4fc5-9bef-2b87258d3396","Price":{"aud":4733.2,"usd":3563.62,"nzd":5156.0,"sgd":4826.85},"Volume":15.0},"Time":1649023811670,"Event":"NewOrder"}
1649023815.248554: {"Channel":"orderbook-eth","Nonce":19084,"Data":{"OrderType":"LimitBid","OrderGuid":"e3043717-4cf4-458b-9700-0bc3aaf9aa0c","Price":{"aud":4726.0,"usd":3522.76,"nzd":5086.12,"sgd":4789.8},"Volume":15.0},"Time":1649023811686,"Event":"NewOrder"}
1649023815.248574: {"Channel":"orderbook-eth","Nonce":19085,"Data":{"OrderType":"LimitBid","OrderGuid":"77c1e4db-e049-4281-a430-ea4e4930e7b2","Price":{"aud":4723.0,"usd":3520.52,"nzd":5082.89,"sgd":4786.76},"Volume":15.0},"Time":1649023811686,"Event":"NewOrder"}
1649023815.2485938: {"Channel":"orderbook-eth","Nonce":19086,"Data":{"OrderType":"LimitOffer","OrderGuid":"53cbe912-dc82-4ab6-a286-b74e6511881b","Price":{"aud":4736.2,"usd":3565.88,"nzd":5159.26,"sgd":4829.91},"Volume":15.0},"Time":1649023811686,"Event":"NewOrder"}
1649023815.248615: {"Channel":"orderbook-eth","Nonce":19087,"Data":{"OrderType":"LimitOffer","OrderGuid":"b78c1ce0-70bc-408b-a7ee-334376064e5f"},"Time":1649023811718,"Event":"OrderCanceled"}
1649023815.248632: {"Channel":"orderbook-eth","Nonce":19088,"Data":{"OrderType":"LimitBid","OrderGuid":"5beeb649-77c4-4149-9a13-f5bb239b5f4e","Price":{"aud":4724.63,"usd":3521.73,"nzd":5084.64,"sgd":4788.41},"Volume":14.14},"Time":1649023811733,"Event":"NewOrder"}
1649023815.2486532: {"Channel":"orderbook-eth","Nonce":19089,"Data":{"OrderType":"LimitBid","OrderGuid":"fbd2f7a9-5d49-45c8-8fea-c20f68931362"},"Time":1649023811749,"Event":"OrderCanceled"}
1649023815.248669: {"Channel":"orderbook-eth","Nonce":19090,"Data":{"OrderType":"LimitBid","OrderGuid":"38aeb572-ed74-4c09-9c5d-ebee630fd08a"},"Time":1649023811749,"Event":"OrderCanceled"}
1649023815.2486851: {"Channel":"orderbook-eth","Nonce":19091,"Data":{"OrderType":"LimitOffer","OrderGuid":"118588d0-b7a5-4429-bc30-11fc298da569","Price":{"aud":4759.12,"usd":3565.21,"nzd":5153.17,"sgd":4823.36},"Volume":1.13310866},"Time":1649023811749,"Event":"NewOrder"}
1649023815.248707: {"Channel":"orderbook-eth","Nonce":19092,"Data":{"OrderType":"LimitBid","OrderGuid":"72ba0c5a-7af7-4e08-b80a-f1db78432a04","Price":{"aud":4696.26,"usd":3518.61,"nzd":5085.15,"sgd":4789.18},"Volume":3.07585089},"Time":1649023811796,"Event":"NewOrder"}
1649023815.248728: {"Channel":"orderbook-eth","Nonce":19093,"Data":{"OrderType":"LimitOffer","OrderGuid":"53cbe912-dc82-4ab6-a286-b74e6511881b"},"Time":1649023811812,"Event":"OrderCanceled"}
1649023815.248745: {"Channel":"orderbook-eth","Nonce":19094,"Data":{"OrderType":"LimitBid","OrderGuid":"e3043717-4cf4-458b-9700-0bc3aaf9aa0c"},"Time":1649023811812,"Event":"OrderCanceled"}
1649023815.2487612: {"Channel":"orderbook-eth","Nonce":19095,"Data":{"OrderType":"LimitBid","OrderGuid":"fbf71d6b-282a-43ad-9d10-84e9d72dc5ac"},"Time":1649023811827,"Event":"OrderCanceled"}
1649023815.248777: {"Channel":"orderbook-eth","Nonce":19096,"Data":{"OrderType":"LimitOffer","OrderGuid":"7a7495fe-2c00-4fc5-9bef-2b87258d3396"},"Time":1649023811905,"Event":"OrderCanceled"}
1649023815.248794: {"Channel":"orderbook-eth","Nonce":19097,"Data":{"OrderType":"LimitBid","OrderGuid":"77c1e4db-e049-4281-a430-ea4e4930e7b2"},"Time":1649023811921,"Event":"OrderCanceled"}
1649023815.24881: {"Channel":"orderbook-eth","Nonce":19098,"Data":{"OrderType":"LimitBid","OrderGuid":"1aad0e1f-5b81-4dd4-ab21-c24a8e3127d4","Price":{"aud":4703.7,"usd":3506.13,"nzd":5062.12,"sgd":4767.19},"Volume":0.3746707},"Time":1649023811937,"Event":"NewOrder"}
1649023815.248831: {"Channel":"orderbook-eth","Nonce":19099,"Data":{"OrderType":"LimitBid","OrderGuid":"72ba0c5a-7af7-4e08-b80a-f1db78432a04"},"Time":1649023811937,"Event":"OrderCanceled"}
1649023815.248848: {"Channel":"orderbook-eth","Nonce":19100,"Data":{"OrderType":"LimitOffer","OrderGuid":"3683b0cd-9982-41dd-98b2-c09adc30a972","Price":{"aud":4733.4,"usd":3563.78,"nzd":5156.21,"sgd":4827.05},"Volume":15.0},"Time":1649023811937,"Event":"NewOrder"}
1649023815.248868: {"Channel":"orderbook-eth","Nonce":19101,"Data":{"OrderType":"LimitOffer","OrderGuid":"4cbc9bb1-511b-4e6c-bb5b-4b0a5a02a521","Price":{"aud":4736.4,"usd":3566.03,"nzd":5159.48,"sgd":4830.11},"Volume":15.0},"Time":1649023811952,"Event":"NewOrder"}
1649023815.248889: {"Channel":"orderbook-eth","Nonce":19102,"Data":{"OrderType":"LimitBid","OrderGuid":"64a241cf-0c9b-46f0-87cf-5696daee96ca","Price":{"aud":4726.2,"usd":3522.9,"nzd":5086.33,"sgd":4790.0},"Volume":15.0},"Time":1649023811968,"Event":"NewOrder"}
1649023815.248909: {"Channel":"orderbook-eth","Nonce":19103,"Data":{"OrderType":"LimitBid","OrderGuid":"7ba8e047-7cf7-4c37-8f05-ded06d448af9","Price":{"aud":4723.2,"usd":3520.67,"nzd":5083.1,"sgd":4786.96},"Volume":15.0},"Time":1649023811968,"Event":"NewOrder"}
1649023815.24893: {"Channel":"orderbook-eth","Nonce":19104,"Data":{"OrderType":"LimitBid","OrderGuid":"c71e95de-b58f-4d71-9e34-687a2bf93a42","Price":{"aud":4698.11,"usd":3519.99,"nzd":5087.14,"sgd":4791.06},"Volume":3.04477982},"Time":1649023811983,"Event":"NewOrder"}
1649023815.24895: {"Channel":"orderbook-matic","Nonce":5867,"Data":{"OrderType":"LimitBid","OrderGuid":"9a8944fa-d4e5-45c0-a911-3fd0d462f05b"},"Time":1649023812015,"Event":"OrderCanceled"}
1649023815.248969: {"Channel":"orderbook-eth","Nonce":19105,"Data":{"OrderType":"LimitBid","OrderGuid":"1642b60e-6a7b-4706-9005-2d915febe21e"},"Time":1649023812046,"Event":"OrderCanceled"}
1649023815.248986: {"Channel":"orderbook-eth","Nonce":19106,"Data":{"OrderType":"LimitBid","OrderGuid":"69659fca-4322-4eb5-b207-333ba979a73b","Price":{"aud":4678.02,"usd":3503.93,"nzd":5095.89,"sgd":4769.75},"Volume":0.41272162},"Time":1649023812093,"Event":"NewOrder"}
1649023815.249007: {"Channel":"orderbook-eth","Nonce":19107,"Data":{"OrderType":"LimitBid","OrderGuid":"9239020d-12f1-433d-a244-7d37b57c1762","Price":{"aud":4701.04,"usd":3522.18,"nzd":5090.32,"sgd":4794.05},"Volume":4.55},"Time":1649023812124,"Event":"NewOrder"}
1649023815.2490282: {"Channel":"orderbook-matic","Nonce":5868,"Data":{"OrderType":"LimitBid","OrderGuid":"56b6beab-61da-4474-9b51-62ce55ab44af"},"Time":1649023812171,"Event":"OrderCanceled"}
1649023815.249046: {"Channel":"orderbook-matic","Nonce":5869,"Data":{"OrderType":"LimitOffer","OrderGuid":"03201890-b4b7-4b8e-b2f4-bb80c3564aef"},"Time":1649023812187,"Event":"OrderCanceled"}
1649023815.249063: {"Channel":"orderbook-matic","Nonce":5870,"Data":{"OrderType":"LimitBid","OrderGuid":"02c34d70-918b-4c78-9f8c-4c7440347294","Price":{"aud":2.26151,"usd":1.68572,"nzd":2.43383,"sgd":2.29204},"Volume":5924.16859},"Time":1649023812265,"Event":"NewOrder"}
1649023815.249084: {"Channel":"orderbook-matic","Nonce":5871,"Data":{"OrderType":"LimitOffer","OrderGuid":"42052134-da27-4b72-b280-911dee98a136","Price":{"aud":2.27198,"usd":1.71058,"nzd":2.47493,"sgd":2.31693},"Volume":5779.34788},"Time":1649023812358,"Event":"NewOrder"}
1649023815.249106: {"Channel":"orderbook-eth","Nonce":19108,"Data":{"OrderType":"LimitOffer","OrderGuid":"8272acd7-bbc2-4e52-b51d-6f6f67a790a8"},"Time":1649023812437,"Event":"OrderCanceled"}
1649023815.249124: {"Channel":"orderbook-dot","Nonce":4931,"Data":{"OrderType":"LimitBid","OrderGuid":"5a53f6ee-73df-48d3-bee1-c241b6eaa12c"},"Time":1649023812562,"Event":"OrderCanceled"}
1649023815.249142: {"Channel":"orderbook-dot","Nonce":4932,"Data":{"OrderType":"LimitBid","OrderGuid":"182771b2-5dc1-4546-82d7-879fb4f164cb","Price":{"aud":30.8024,"usd":22.9601,"nzd":33.1495,"sgd":31.2182},"Volume":69.2},"Time":1649023812718,"Event":"NewOrder"}
1649023815.249163: {"Channel":"orderbook-eth","Nonce":19109,"Data":{"OrderType":"LimitOffer","OrderGuid":"4cbc9bb1-511b-4e6c-bb5b-4b0a5a02a521"},"Time":1649023812891,"Event":"OrderCanceled"}
1649023815.249181: {"Channel":"orderbook-eth","Nonce":19110,"Data":{"OrderType":"LimitBid","OrderGuid":"64a241cf-0c9b-46f0-87cf-5696daee96ca"},"Time":1649023812907,"Event":"OrderCanceled"}
1649023815.2491992: {"Channel":"orderbook-eth","Nonce":19111,"Data":{"OrderType":"LimitBid","OrderGuid":"7ba8e047-7cf7-4c37-8f05-ded06d448af9"},"Time":1649023812907,"Event":"OrderCanceled"}
1649023815.249216: {"Channel":"orderbook-eth","Nonce":19112,"Data":{"OrderType":"LimitBid","OrderGuid":"12bd1f5b-7d79-4e6f-b288-746669e8b4dc","Price":{"aud":4694.5,"usd":3517.28,"nzd":5083.24,"sgd":4787.38},"Volume":20.945},"Time":1649023812953,"Event":"NewOrder"}
1649023815.249237: {"Channel":"orderbook-eth","Nonce":19113,"Data":{"OrderType":"LimitBid","OrderGuid":"1aad0e1f-5b81-4dd4-ab21-c24a8e3127d4"},"Time":1649023812969,"Event":"OrderCanceled"}
1649023815.249255: {"Channel":"orderbook-eth","Nonce":19114,"Data":{"OrderType":"LimitBid","OrderGuid":"74db6513-0c80-46ca-91b1-a007cf53bee5","Price":{"aud":4723.5,"usd":3520.89,"nzd":5083.43,"sgd":4787.26},"Volume":15.0},"Time":1649023813000,"Event":"NewOrder"}
1649023815.249275: {"Channel":"orderbook-eth","Nonce":19115,"Data":{"OrderType":"LimitOffer","OrderGuid":"3683b0cd-9982-41dd-98b2-c09adc30a972"},"Time":1649023813000,"Event":"OrderCanceled"}
1649023815.249293: {"Channel":"orderbook-matic","Nonce":5872,"Data":{"OrderType":"LimitOffer","OrderGuid":"6b7753f3-9082-494a-96b0-bcde84833e6f"},"Time":1649023813032,"Event":"OrderCanceled"}
1649023815.249311: {"Channel":"orderbook-eth","Nonce":19116,"Data":{"OrderType":"LimitOffer","OrderGuid":"da4682d8-7d0e-4e57-8211-96db7d8ed6d2","Price":{"aud":4742.37,"usd":3570.53,"nzd":5165.99,"sgd":4836.2},"Volume":3.57864852},"Time":1649023813032,"Event":"NewOrder"}
1649023815.249332: {"Channel":"orderbook-eth","Nonce":19117,"Data":{"OrderType":"LimitOffer","OrderGuid":"f9c02d7e-6248-42fd-9e57-cef3bc2a2dbd"},"Time":1649023813047,"Event":"OrderCanceled"}
1649023815.2493498: {"Channel":"orderbook-eth","Nonce":19118,"Data":{"OrderType":"LimitBid","OrderGuid":"7f6cb875-78a0-46c4-989f-73e7aa80c3ab","Price":{"aud":4703.71,"usd":3506.14,"nzd":5062.13,"sgd":4767.21},"Volume":0.32671396},"Time":1649023813047,"Event":"NewOrder"}
1649023815.2493708: {"Channel":"orderbook-eth","Nonce":19119,"Data":{"OrderType":"LimitOffer","OrderGuid":"b6ebf31e-88f6-4bf1-82e2-ef55e4b90863","Price":{"aud":4736.7,"usd":3566.26,"nzd":5159.81,"sgd":4830.41},"Volume":15.0},"Time":1649023813094,"Event":"NewOrder"}
1649023815.249392: {"Channel":"orderbook-eth","Nonce":19120,"Data":{"OrderType":"LimitBid","OrderGuid":"55315af3-ff75-4ae3-a419-71f05ca8a805","Price":{"aud":4726.5,"usd":3523.13,"nzd":5086.65,"sgd":4790.3},"Volume":15.0},"Time":1649023813094,"Event":"NewOrder"}
1649023815.249412: {"Channel":"orderbook-eth","Nonce":19121,"Data":{"OrderType":"LimitOffer","OrderGuid":"72ed7280-6b80-401c-9b96-aca1878d6687","Price":{"aud":4733.7,"usd":3564.0,"nzd":5156.54,"sgd":4827.36},"Volume":15.0},"Time":1649023813094,"Event":"NewOrder"}
1649023815.249433: {"Channel":"orderbook-eth","Nonce":19122,"Data":{"OrderType":"LimitOffer","OrderGuid":"da4682d8-7d0e-4e57-8211-96db7d8ed6d2"},"Time":1649023813141,"Event":"OrderCanceled"}
1649023815.24945: {"Channel":"orderbook-eth","Nonce":19123,"Data":{"OrderType":"LimitOffer","OrderGuid":"6cfb8c4d-7878-44b6-9ee5-4e33e5670c3b","Price":{"aud":4736.69,"usd":3566.25,"nzd":5159.8,"sgd":4830.4},"Volume":3.57864852},"Time":1649023813157,"Event":"NewOrder"}
1649023815.249471: {"Channel":"orderbook-eth","Nonce":19124,"Data":{"OrderType":"LimitBid","OrderGuid":"69659fca-4322-4eb5-b207-333ba979a73b"},"Time":1649023813188,"Event":"OrderCanceled"}
1649023815.2494879: {"Channel":"orderbook-eth","Nonce":19125,"Data":{"OrderType":"LimitBid","OrderGuid":"bf6e2433-69ac-46c8-95b2-fabba8f3db85","Price":{"aud":4678.03,"usd":3503.94,"nzd":5095.9,"sgd":4769.76},"Volume":0.54077092},"Time":1649023813236,"Event":"NewOrder"}
1649023815.249509: {"Channel":"orderbook-matic","Nonce":5873,"Data":{"OrderType":"LimitOffer","OrderGuid":"42052134-da27-4b72-b280-911dee98a136"},"Time":1649023813283,"Event":"OrderCanceled"}
1649023815.249527: {"Channel":"orderbook-matic","Nonce":5874,"Data":{"OrderType":"LimitOffer","OrderGuid":"0466304a-d73c-4015-b03a-d8067a4b9f2a","Price":{"aud":2.27197,"usd":1.71057,"nzd":2.47492,"sgd":2.31692},"Volume":5091.18086},"Time":1649023813392,"Event":"NewOrder"}
1649023815.24955: {"Channel":"orderbook-eth","Nonce":19126,"Data":{"OrderType":"LimitBid","OrderGuid":"c71e95de-b58f-4d71-9e34-687a2bf93a42"},"Time":1649023813533,"Event":"OrderCanceled"}
1649023815.249568: {"Channel":"orderbook-eth","Nonce":19127,"Data":{"OrderType":"LimitBid","OrderGuid":"14da795e-d669-4fcd-8c8e-3b5fddffb078","Price":{"aud":4697.08,"usd":3519.22,"nzd":5086.03,"sgd":4790.01},"Volume":3.19969965},"Time":1649023813580,"Event":"NewOrder"}
1649023815.249589: {"Channel":"orderbook-eth","Nonce":19128,"Data":{"OrderType":"LimitBid","OrderGuid":"55315af3-ff75-4ae3-a419-71f05ca8a805"},"Time":1649023813595,"Event":"OrderCanceled"}
1649023815.2496068: {"Channel":"orderbook-eth","Nonce":19129,"Data":{"OrderType":"LimitBid","OrderGuid":"74db6513-0c80-46ca-91b1-a007cf53bee5"},"Time":1649023813595,"Event":"OrderCanceled"}
1649023815.249624: {"Channel":"orderbook-eth","Nonce":19130,"Data":{"OrderType":"LimitOffer","OrderGuid":"b6ebf31e-88f6-4bf1-82e2-ef55e4b90863"},"Time":1649023813705,"Event":"OrderCanceled"}
1649023815.249641: {"Channel":"orderbook-eth","Nonce":19131,"Data":{"OrderType":"LimitBid","OrderGuid":"a887c328-691e-42af-8ca4-0dcbbf0ead39","Price":{"aud":4726.8,"usd":3523.35,"nzd":5086.98,"sgd":4790.61},"Volume":15.0},"Time":1649023813720,"Event":"NewOrder"}
1649023815.249662: {"Channel":"orderbook-eth","Nonce":19132,"Data":{"OrderType":"LimitOffer","OrderGuid":"72ed7280-6b80-401c-9b96-aca1878d6687"},"Time":1649023813736,"Event":"OrderCanceled"}
1649023815.249679: {"Channel":"orderbook-eth","Nonce":19133,"Data":{"OrderType":"LimitBid","OrderGuid":"51029f3a-c687-4982-affe-f6239eeafbba","Price":{"aud":4723.8,"usd":3521.12,"nzd":5083.75,"sgd":4787.57},"Volume":15.0},"Time":1649023813752,"Event":"NewOrder"}
1649023815.249699: {"Channel":"orderbook-eth","Nonce":19134,"Data":{"OrderType":"LimitOffer","OrderGuid":"dab8c721-52c3-4f6a-92d7-dcc9c68d8a94","Price":{"aud":4737.0,"usd":3566.49,"nzd":5160.14,"sgd":4830.72},"Volume":15.0},"Time":1649023813783,"Event":"NewOrder"}
1649023815.24972: {"Channel":"orderbook-eth","Nonce":19135,"Data":{"OrderType":"LimitOffer","OrderGuid":"ca99451b-fb87-4b21-918a-18f6776925f2","Price":{"aud":4734.0,"usd":3564.23,"nzd":5156.87,"sgd":4827.66},"Volume":15.0},"Time":1649023813783,"Event":"NewOrder"}
1649023815.2497401: {"Channel":"orderbook-eth","Nonce":19136,"Data":{"OrderType":"LimitOffer","OrderGuid":"f9ec5ac0-bce3-40a6-aabb-c8fce14cdb86","Price":{"aud":4760.86,"usd":3566.51,"nzd":5155.06,"sgd":4825.13},"Volume":22.473},"Time":1649023813830,"Event":"NewOrder"}
1649023815.249761: {"Channel":"orderbook-eth","Nonce":19137,"Data":{"OrderType":"LimitBid","OrderGuid":"14da795e-d669-4fcd-8c8e-3b5fddffb078"},"Time":1649023813845,"Event":"OrderCanceled"}
1649023815.249779: {"Channel":"orderbook-eth","Nonce":19138,"Data":{"OrderType":"LimitOffer","OrderGuid":"118588d0-b7a5-4429-bc30-11fc298da569"},"Time":1649023813845,"Event":"OrderCanceled"}
1649023815.2497962: {"Channel":"orderbook-eth","Nonce":19139,"Data":{"OrderType":"LimitBid","OrderGuid":"51029f3a-c687-4982-affe-f6239eeafbba"},"Time":1649023813861,"Event":"OrderCanceled"}
1649023815.249813: {"Channel":"orderbook-eth","Nonce":19140,"Data":{"OrderType":"LimitOffer","OrderGuid":"7adc3467-2adf-461c-a332-cf4264cb5c1a"},"Time":1649023813861,"Event":"OrderCanceled"}
1649023815.2498298: {"Channel":"orderbook-eth","Nonce":19141,"Data":{"OrderType":"LimitBid","OrderGuid":"a887c328-691e-42af-8ca4-0dcbbf0ead39"},"Time":1649023813861,"Event":"OrderCanceled"}
1649023815.249847: {"Channel":"orderbook-eth","Nonce":19142,"Data":{"OrderType":"LimitOffer","OrderGuid":"dab8c721-52c3-4f6a-92d7-dcc9c68d8a94"},"Time":1649023813892,"Event":"OrderCanceled"}
1649023815.2498639: {"Channel":"orderbook-dot","Nonce":4933,"Data":{"OrderType":"LimitOffer","OrderGuid":"01555611-0da9-4ad3-aa56-99aea07a770d","Price":{"aud":31.4099,"usd":23.6485,"nzd":34.2156,"sgd":32.0314},"Volume":19.94006},"Time":1649023813939,"Event":"NewOrder"}
1649023815.249886: {"Channel":"orderbook-eth","Nonce":19143,"Data":{"OrderType":"LimitOffer","OrderGuid":"bf3dd3c0-e8d0-4139-a0e2-422836137415","Price":{"aud":4757.26,"usd":3563.82,"nzd":5151.16,"sgd":4821.48},"Volume":1.03090664},"Time":1649023813955,"Event":"NewOrder"}
1649023815.249907: {"Channel":"orderbook-eth","Nonce":19144,"Data":{"OrderType":"LimitOffer","OrderGuid":"ae47317e-c382-49b3-8a94-c6071ebd997f","Price":{"aud":4793.66,"usd":3573.19,"nzd":5196.62,"sgd":4863.47},"Volume":0.54152953},"Time":1649023813955,"Event":"NewOrder"}
1649023815.249928: {"Channel":"orderbook-eth","Nonce":19145,"Data":{"OrderType":"LimitBid","OrderGuid":"528cb1a2-6d94-492e-8d27-37e8c4110027","Price":{"aud":4723.2,"usd":3520.67,"nzd":5083.1,"sgd":4786.96},"Volume":15.0},"Time":1649023813970,"Event":"NewOrder"}
1649023815.249949: {"Channel":"orderbook-eth","Nonce":19146,"Data":{"OrderType":"LimitBid","OrderGuid":"6596fd38-ec76-4212-9ec3-ee1d3a5b1902","Price":{"aud":4696.26,"usd":3518.61,"nzd":5085.15,"sgd":4789.18},"Volume":3.10819217},"Time":1649023813970,"Event":"NewOrder"}
1649023815.249969: {"Channel":"orderbook-eth","Nonce":19147,"Data":{"OrderType":"LimitOffer","OrderGuid":"bf3dd3c0-e8d0-4139-a0e2-422836137415"},"Time":1649023814048,"Event":"OrderCanceled"}
1649023815.2499871: {"Channel":"orderbook-eth","Nonce":19148,"Data":{"OrderType":"LimitOffer","OrderGuid":"ae47317e-c382-49b3-8a94-c6071ebd997f"},"Time":1649023814048,"Event":"OrderCanceled"}
1649023815.2500029: {"Channel":"orderbook-bch","Nonce":8233,"Data":{"OrderType":"LimitOffer","OrderGuid":"e7f70df0-3f16-40ba-b1fe-322c72a07178"},"Time":1649023814048,"Event":"OrderCanceled"}
1649023815.250016: {"Channel":"orderbook-dot","Nonce":4934,"Data":{"OrderType":"LimitOffer","OrderGuid":"7aff3221-224e-416e-bc6a-7bb82b2aebe6"},"Time":1649023814048,"Event":"OrderCanceled"}
1649023815.250033: {"Channel":"orderbook-eth","Nonce":19149,"Data":{"OrderType":"LimitBid","OrderGuid":"6596fd38-ec76-4212-9ec3-ee1d3a5b1902"},"Time":1649023814064,"Event":"OrderCanceled"}
1649023815.250049: {"Channel":"orderbook-bch","Nonce":8234,"Data":{"OrderType":"LimitOffer","OrderGuid":"ff75a18d-5671-4674-9da6-f036bf87f8b8"},"Time":1649023814064,"Event":"OrderCanceled"}
1649023815.250067: {"Channel":"orderbook-eth","Nonce":19150,"Data":{"OrderType":"LimitOffer","OrderGuid":"ca99451b-fb87-4b21-918a-18f6776925f2"},"Time":1649023814064,"Event":"OrderCanceled"}
1649023815.2500842: {"Channel":"orderbook-eth","Nonce":19151,"Data":{"OrderType":"LimitBid","OrderGuid":"f41ced81-6bd4-483e-8f54-46d6c228c16b","Price":{"aud":4726.2,"usd":3522.9,"nzd":5086.33,"sgd":4790.0},"Volume":15.0},"Time":1649023814064,"Event":"NewOrder"}
1649023815.2501051: {"Channel":"orderbook-eth","Nonce":19152,"Data":{"OrderType":"LimitOffer","OrderGuid":"c7be1d1f-1666-4876-86b0-a821604bef70","Price":{"aud":4797.78,"usd":3576.26,"nzd":5201.08,"sgd":4867.65},"Volume":0.59563862},"Time":1649023814095,"Event":"NewOrder"}
1649023815.2501261: {"Channel":"orderbook-eth","Nonce":19153,"Data":{"OrderType":"LimitOffer","OrderGuid":"f1b358dc-db70-40ed-919f-5a6551cd022a","Price":{"aud":4757.41,"usd":3563.93,"nzd":5151.32,"sgd":4821.63},"Volume":1.04056301},"Time":1649023814095,"Event":"NewOrder"}
1649023815.250148: {"Channel":"orderbook-eth","Nonce":19154,"Data":{"OrderType":"LimitBid","OrderGuid":"55a055c0-20e1-42b2-bdd9-c1763e9555a8","Price":{"aud":4698.11,"usd":3519.99,"nzd":5087.14,"sgd":4791.06},"Volume":3.086311},"Time":1649023814142,"Event":"NewOrder"}
1649023815.2501702: {"Channel":"orderbook-eth","Nonce":19155,"Data":{"OrderType":"LimitOffer","OrderGuid":"d0a83e85-a04a-458c-96b8-6348f888894e","Price":{"aud":4733.4,"usd":3563.78,"nzd":5156.21,"sgd":4827.05},"Volume":15.0},"Time":1649023814142,"Event":"NewOrder"}
1649023815.25019: {"Channel":"orderbook-eth","Nonce":19156,"Data":{"OrderType":"LimitBid","OrderGuid":"528cb1a2-6d94-492e-8d27-37e8c4110027"},"Time":1649023814173,"Event":"OrderCanceled"}
1649023815.250211: {"Channel":"orderbook-eth","Nonce":19157,"Data":{"OrderType":"LimitOffer","OrderGuid":"b54bff35-316f-4ea7-a116-643bd9c66ae9","Price":{"aud":4742.37,"usd":3570.53,"nzd":5165.99,"sgd":4836.2},"Volume":3.57864852},"Time":1649023814173,"Event":"NewOrder"}
1649023815.250331: {"Channel":"orderbook-eth","Nonce":19158,"Data":{"OrderType":"LimitOffer","OrderGuid":"f1b358dc-db70-40ed-919f-5a6551cd022a"},"Time":1649023814189,"Event":"OrderCanceled"}
1649023815.2503731: {"Channel":"orderbook-eth","Nonce":19159,"Data":{"OrderType":"LimitBid","OrderGuid":"7f6cb875-78a0-46c4-989f-73e7aa80c3ab"},"Time":1649023814189,"Event":"OrderCanceled"}
1649023815.2503948: {"Channel":"orderbook-eth","Nonce":19160,"Data":{"OrderType":"LimitOffer","OrderGuid":"6cfb8c4d-7878-44b6-9ee5-4e33e5670c3b"},"Time":1649023814205,"Event":"OrderCanceled"}
1649023815.2504141: {"Channel":"orderbook-bch","Nonce":8235,"Data":{"OrderType":"LimitOffer","OrderGuid":"8c070bb2-969d-48ac-8e82-671720104012","Price":{"aud":508.85,"usd":383.12,"nzd":554.31,"sgd":518.92},"Volume":7.47},"Time":1649023814220,"Event":"NewOrder"}
1649023815.250439: {"Channel":"orderbook-bch","Nonce":8236,"Data":{"OrderType":"LimitOffer","OrderGuid":"0533ed27-b34d-4d9f-a69d-7a70a4c0f9c9","Price":{"aud":510.81,"usd":384.59,"nzd":556.44,"sgd":520.92},"Volume":2.93},"Time":1649023814236,"Event":"NewOrder"}
1649023815.2504609: {"Channel":"orderbook-eth","Nonce":19161,"Data":{"OrderType":"LimitOffer","OrderGuid":"d0a83e85-a04a-458c-96b8-6348f888894e"},"Time":1649023814252,"Event":"OrderCanceled"}
1649023815.250478: {"Channel":"orderbook-eth","Nonce":19162,"Data":{"OrderType":"LimitOffer","OrderGuid":"bdba2cc0-677c-440d-98c1-2bcb2f990dc4","Price":{"aud":4759.12,"usd":3565.21,"nzd":5153.17,"sgd":4823.36},"Volume":1.07422511},"Time":1649023814267,"Event":"NewOrder"}
1649023815.250499: {"Channel":"orderbook-eth","Nonce":19163,"Data":{"OrderType":"LimitBid","OrderGuid":"13492d50-d64a-44ac-a194-eae073f7c1b0","Price":{"aud":4703.72,"usd":3506.15,"nzd":5062.14,"sgd":4767.22},"Volume":0.39930686},"Time":1649023814283,"Event":"NewOrder"}
1649023815.250519: {"Channel":"orderbook-eth","Nonce":19164,"Data":{"OrderType":"LimitOffer","OrderGuid":"81d5dd70-6592-4e4d-af36-12f281ddfb8e","Price":{"aud":4733.3,"usd":3563.7,"nzd":5156.11,"sgd":4826.95},"Volume":15.0},"Time":1649023814314,"Event":"NewOrder"}
1649023815.250539: {"Channel":"orderbook-eth","Nonce":19165,"Data":{"OrderType":"LimitBid","OrderGuid":"55a055c0-20e1-42b2-bdd9-c1763e9555a8"},"Time":1649023814314,"Event":"OrderCanceled"}
1649023815.250556: {"Channel":"orderbook-eth","Nonce":19166,"Data":{"OrderType":"LimitOffer","OrderGuid":"d017d4b3-fedf-4be6-b399-a2119e06f94a","Price":{"aud":4736.3,"usd":3565.96,"nzd":5159.37,"sgd":4830.01},"Volume":15.0},"Time":1649023814314,"Event":"NewOrder"}
1649023815.250575: {"Channel":"orderbook-matic","Nonce":5875,"Data":{"OrderType":"LimitOffer","OrderGuid":"0466304a-d73c-4015-b03a-d8067a4b9f2a"},"Time":1649023814345,"Event":"OrderCanceled"}
1649023815.250593: {"Channel":"orderbook-eth","Nonce":19167,"Data":{"OrderType":"LimitBid","OrderGuid":"bf6e2433-69ac-46c8-95b2-fabba8f3db85"},"Time":1649023814345,"Event":"OrderCanceled"}
1649023815.250609: {"Channel":"orderbook-eth","Nonce":19168,"Data":{"OrderType":"LimitBid","OrderGuid":"56507aed-abde-478f-950b-317e8bafe8b3","Price":{"aud":4696.26,"usd":3518.61,"nzd":5085.15,"sgd":4789.18},"Volume":3.11482681},"Time":1649023814361,"Event":"NewOrder"}
1649023815.2506292: {"Channel":"orderbook-eth","Nonce":19169,"Data":{"OrderType":"LimitBid","OrderGuid":"63d561da-f4b7-4f38-8dad-dfff146412b7","Price":{"aud":4678.04,"usd":3503.94,"nzd":5095.91,"sgd":4769.77},"Volume":0.57211011},"Time":1649023814377,"Event":"NewOrder"}
1649023815.250649: {"Channel":"orderbook-matic","Nonce":5876,"Data":{"OrderType":"LimitOffer","OrderGuid":"5050ff1b-4208-469e-806e-693140aeaae1","Price":{"aud":2.27196,"usd":1.71056,"nzd":2.47491,"sgd":2.31691},"Volume":5139.64717},"Time":1649023814423,"Event":"NewOrder"}
1649023815.2506711: {"Channel":"orderbook-eth","Nonce":19170,"Data":{"OrderType":"LimitOffer","OrderGuid":"81d5dd70-6592-4e4d-af36-12f281ddfb8e"},"Time":1649023814423,"Event":"OrderCanceled"}
1649023815.250687: {"Channel":"orderbook-eth","Nonce":19171,"Data":{"OrderType":"LimitOffer","OrderGuid":"d017d4b3-fedf-4be6-b399-a2119e06f94a"},"Time":1649023814423,"Event":"OrderCanceled"}
1649023815.250703: {"Channel":"orderbook-eth","Nonce":19172,"Data":{"OrderType":"LimitBid","OrderGuid":"f41ced81-6bd4-483e-8f54-46d6c228c16b"},"Time":1649023814455,"Event":"OrderCanceled"}
1649023815.2507179: {"Channel":"orderbook-eth","Nonce":19173,"Data":{"OrderType":"LimitOffer","OrderGuid":"30caedc7-fe84-4a4e-b48e-7260f809938e","Price":{"aud":4736.29,"usd":3565.95,"nzd":5159.36,"sgd":4830.0},"Volume":3.57864852},"Time":1649023814470,"Event":"NewOrder"}
1649023815.250738: {"Channel":"orderbook-eth","Nonce":19174,"Data":{"OrderType":"LimitOffer","OrderGuid":"c5b499d5-aa6c-4e81-a0b5-ef3eb5b8a24b","Price":{"aud":4734.0,"usd":3564.23,"nzd":5156.87,"sgd":4827.66},"Volume":15.0},"Time":1649023814470,"Event":"NewOrder"}
1649023815.2507572: {"Channel":"orderbook-eth","Nonce":19175,"Data":{"OrderType":"LimitOffer","OrderGuid":"b54bff35-316f-4ea7-a116-643bd9c66ae9"},"Time":1649023814470,"Event":"OrderCanceled"}
1649023815.250773: {"Channel":"orderbook-eth","Nonce":19176,"Data":{"OrderType":"LimitOffer","OrderGuid":"b7d46244-b00d-440c-8548-07f20d18e191","Price":{"aud":4737.0,"usd":3566.49,"nzd":5160.14,"sgd":4830.72},"Volume":15.0},"Time":1649023814470,"Event":"NewOrder"}
1649023815.250792: {"Channel":"orderbook-eth","Nonce":19177,"Data":{"OrderType":"LimitBid","OrderGuid":"934c2d9f-7760-4ba0-864c-bc26c0f9e50f","Price":{"aud":4726.8,"usd":3523.35,"nzd":5086.98,"sgd":4790.61},"Volume":15.0},"Time":1649023814486,"Event":"NewOrder"}
1649023815.2508109: {"Channel":"orderbook-eth","Nonce":19178,"Data":{"OrderType":"LimitBid","OrderGuid":"602565e6-f0ce-40ae-8d39-3121e6105189","Price":{"aud":4723.8,"usd":3521.12,"nzd":5083.75,"sgd":4787.57},"Volume":15.0},"Time":1649023814502,"Event":"NewOrder"}
1649023815.2508302: {"Channel":"orderbook-eth","Nonce":19179,"Data":{"OrderType":"LimitOffer","OrderGuid":"ecb563e4-93eb-4050-a4ea-68ecef3d4010"},"Time":1649023814548,"Event":"OrderCanceled"}
1649023815.2508469: {"Channel":"orderbook-eth","Nonce":19180,"Data":{"OrderType":"LimitOffer","OrderGuid":"3160cff2-b4d2-4ee2-a51a-53b51664f816","Price":{"aud":4785.24,"usd":3584.52,"nzd":5149.87,"sgd":4850.14},"Volume":0.47943716},"Time":1649023814596,"Event":"NewOrder"}
1649023815.250867: {"Channel":"orderbook-eth","Nonce":19181,"Data":{"OrderType":"LimitOffer","OrderGuid":"c5b499d5-aa6c-4e81-a0b5-ef3eb5b8a24b"},"Time":1649023814690,"Event":"OrderCanceled"}
1649023815.250883: {"Channel":"orderbook-eth","Nonce":19182,"Data":{"OrderType":"LimitOffer","OrderGuid":"b7d46244-b00d-440c-8548-07f20d18e191"},"Time":1649023814740,"Event":"OrderCanceled"}
1649023815.250898: {"Channel":"orderbook-eth","Nonce":19183,"Data":{"OrderType":"LimitBid","OrderGuid":"602565e6-f0ce-40ae-8d39-3121e6105189"},"Time":1649023814818,"Event":"OrderCanceled"}
1649023815.250914: {"Channel":"orderbook-eth","Nonce":19184,"Data":{"OrderType":"LimitBid","OrderGuid":"934c2d9f-7760-4ba0-864c-bc26c0f9e50f"},"Time":1649023814818,"Event":"OrderCanceled"}
1649023815.2509289: {"Channel":"orderbook-eth","Nonce":19185,"Data":{"OrderType":"LimitOffer","OrderGuid":"945c921e-ce5d-4602-b31f-3da111c09b50","Price":{"aud":4734.3,"usd":3564.45,"nzd":5157.19,"sgd":4827.97},"Volume":15.0},"Time":1649023814818,"Event":"NewOrder"}
1649023815.250947: {"Channel":"orderbook-eth","Nonce":19186,"Data":{"OrderType":"LimitOffer","OrderGuid":"c7be1d1f-1666-4876-86b0-a821604bef70"},"Time":1649023814880,"Event":"OrderCanceled"}
1649023815.250963: {"Channel":"orderbook-dot","Nonce":4935,"Data":{"OrderType":"LimitOffer","OrderGuid":"3f254167-cb46-40ba-9884-5cd2a237700a","Price":{"aud":31.3896,"usd":23.6332,"nzd":34.1935,"sgd":32.0107},"Volume":19.94006},"Time":1649023814896,"Event":"NewOrder"}
1649023815.250983: {"Channel":"orderbook-eth","Nonce":19187,"Data":{"OrderType":"LimitBid","OrderGuid":"318c0771-e1cd-4632-824c-b0c8b80e222b","Price":{"aud":4727.1,"usd":3523.58,"nzd":5087.3,"sgd":4790.91},"Volume":15.0},"Time":1649023814912,"Event":"NewOrder"}
1649023815.251002: {"Channel":"orderbook-eth","Nonce":19188,"Data":{"OrderType":"LimitOffer","OrderGuid":"465e1c31-9297-406a-a1b4-c7f63abfa7de","Price":{"aud":4737.3,"usd":3566.71,"nzd":5160.46,"sgd":4831.03},"Volume":15.0},"Time":1649023814927,"Event":"NewOrder"}
1649023815.2510211: {"Channel":"orderbook-eth","Nonce":19189,"Data":{"OrderType":"LimitBid","OrderGuid":"40c3b71e-e8b6-40db-8e29-8dd093fddd28","Price":{"aud":4724.1,"usd":3521.34,"nzd":5084.07,"sgd":4787.87},"Volume":15.0},"Time":1649023814927,"Event":"NewOrder"}
1649023815.25104: {"Channel":"orderbook-eth","Nonce":19190,"Data":{"OrderType":"LimitOffer","OrderGuid":"2a6b845e-9acf-4271-9f06-1ca87cdfe191","Price":{"aud":4794.16,"usd":3573.56,"nzd":5197.15,"sgd":4863.98},"Volume":0.5362896},"Time":1649023814927,"Event":"NewOrder"}
1649023815.251059: {"Channel":"orderbook-eth","Nonce":19191,"Data":{"OrderType":"LimitOffer","OrderGuid":"465e1c31-9297-406a-a1b4-c7f63abfa7de"},"Time":1649023814990,"Event":"OrderCanceled"}
1649023815.251075: {"Channel":"orderbook-dot","Nonce":4936,"Data":{"OrderType":"LimitOffer","OrderGuid":"01555611-0da9-4ad3-aa56-99aea07a770d"},"Time":1649023815005,"Event":"OrderCanceled"}
1649023815.251091: {"Channel":"orderbook-eth","Nonce":19192,"Data":{"OrderType":"LimitBid","OrderGuid":"318c0771-e1cd-4632-824c-b0c8b80e222b"},"Time":1649023815005,"Event":"OrderCanceled"}
1649023815.251107: {"Channel":"orderbook-eth","Nonce":19193,"Data":{"OrderType":"LimitBid","OrderGuid":"40c3b71e-e8b6-40db-8e29-8dd093fddd28"},"Time":1649023815005,"Event":"OrderCanceled"}
1649023815.251122: {"Channel":"orderbook-eth","Nonce":19194,"Data":{"OrderType":"LimitBid","OrderGuid":"56507aed-abde-478f-950b-317e8bafe8b3"},"Time":1649023815005,"Event":"OrderCanceled"}
1649023815.251137: {"Channel":"orderbook-matic","Nonce":5877,"Data":{"OrderType":"LimitBid","OrderGuid":"94b32d40-c197-40b9-ae6a-e238d6912d36","Price":{"aud":2.22101,"usd":1.65554,"nzd":2.39025,"sgd":2.25099},"Volume":1727.0},"Time":1649023815021,"Event":"NewOrder"}
1649023815.251158: {"Channel":"orderbook-eth","Nonce":19195,"Data":{"OrderType":"LimitBid","OrderGuid":"2b36a2f5-8e27-4179-9d12-03359f45fc0a","Price":{"aud":4698.11,"usd":3519.99,"nzd":5087.14,"sgd":4791.06},"Volume":3.14426509},"Time":1649023815069,"Event":"NewOrder"}
1649023815.251177: {"Channel":"orderbook-eth","Nonce":19196,"Data":{"OrderType":"LimitOffer","OrderGuid":"945c921e-ce5d-4602-b31f-3da111c09b50"},"Time":1649023815085,"Event":"OrderCanceled"}
1649023815.251193: {"Channel":"orderbook-eth","Nonce":19197,"Data":{"OrderType":"LimitBid","OrderGuid":"66ed841e-5a18-419e-bc3e-70aa89fc195d","Price":{"aud":4723.8,"usd":3521.12,"nzd":5083.75,"sgd":4787.57},"Volume":15.0},"Time":1649023815100,"Event":"NewOrder"}
1649023815.2512121: {"Channel":"orderbook-eth","Nonce":19198,"Data":{"OrderType":"LimitBid","OrderGuid":"2b36a2f5-8e27-4179-9d12-03359f45fc0a"},"Time":1649023815116,"Event":"OrderCanceled"}
1649023815.251601: {"Channel":"orderbook-eth","Nonce":19199,"Data":{"OrderType":"LimitBid","OrderGuid":"e98041ea-2ac9-454c-a5da-d8ea96818bf0","Price":{"aud":4698.11,"usd":3519.99,"nzd":5087.14,"sgd":4791.06},"Volume":3.10608308},"Time":1649023815147,"Event":"NewOrder"}
1649023815.291456: {"Channel":"orderbook-dot","Nonce":4937,"Data":{"OrderType":"LimitOffer","OrderGuid":"ab9ce435-4a59-4cb8-82e1-dde2900f5fad"},"Time":1649023815178,"Event":"OrderCanceled"}
1649023815.291568: {"Channel":"orderbook-eth","Nonce":19200,"Data":{"OrderType":"LimitBid","OrderGuid":"c7804aaa-3fd5-4fbf-9a35-1ca2abadc300","Price":{"aud":4726.8,"usd":3523.35,"nzd":5086.98,"sgd":4790.61},"Volume":15.0},"Time":1649023815178,"Event":"NewOrder"}
1649023815.304188: {"Channel":"orderbook-eth","Nonce":19201,"Data":{"OrderType":"LimitOffer","OrderGuid":"d7287672-eb0e-4f55-a9a0-8448c76a1dbe","Price":{"aud":4737.0,"usd":3566.49,"nzd":5160.14,"sgd":4830.72},"Volume":15.0},"Time":1649023815194,"Event":"NewOrder"}
1649023815.347102: {"Channel":"orderbook-eth","Nonce":19202,"Data":{"OrderType":"LimitBid","OrderGuid":"13492d50-d64a-44ac-a194-eae073f7c1b0"},"Time":1649023815241,"Event":"OrderCanceled"}
1649023815.352391: {"Channel":"orderbook-dot","Nonce":4938,"Data":{"OrderType":"LimitOffer","OrderGuid":"09a3609f-dee9-4774-8f45-2afe6571c29c","Price":{"aud":31.5105,"usd":23.7243,"nzd":34.3252,"sgd":32.1339},"Volume":14.72539},"Time":1649023815241,"Event":"NewOrder"}
1649023815.361139: {"Channel":"orderbook-dot","Nonce":4939,"Data":{"OrderType":"LimitOffer","OrderGuid":"f0e2e76e-4e7f-4ae6-9893-95ed22f7c393"},"Time":1649023815257,"Event":"OrderCanceled"}
1649023815.389376: {"Channel":"orderbook-eth","Nonce":19203,"Data":{"OrderType":"LimitOffer","OrderGuid":"d7287672-eb0e-4f55-a9a0-8448c76a1dbe"},"Time":1649023815288,"Event":"OrderCanceled"}
1649023815.393651: {"Channel":"orderbook-dot","Nonce":4940,"Data":{"OrderType":"LimitOffer","OrderGuid":"09a3609f-dee9-4774-8f45-2afe6571c29c"},"Time":1649023815288,"Event":"OrderCanceled"}
1649023815.407564: {"Channel":"orderbook-dot","Nonce":4941,"Data":{"OrderType":"LimitOffer","OrderGuid":"3a2e24fc-c170-4c55-bdf1-57ecce8f2ccd","Price":{"aud":31.5101,"usd":23.724,"nzd":34.3248,"sgd":32.1335},"Volume":14.72539},"Time":1649023815303,"Event":"NewOrder"}
1649023815.428163: {"Channel":"orderbook-eth","Nonce":19204,"Data":{"OrderType":"LimitBid","OrderGuid":"66ed841e-5a18-419e-bc3e-70aa89fc195d"},"Time":1649023815319,"Event":"OrderCanceled"}
1649023815.461222: {"Channel":"orderbook-dot","Nonce":4942,"Data":{"OrderType":"LimitOffer","OrderGuid":"002d0d15-481c-47da-94dd-3c4768649507","Price":{"aud":31.4399,"usd":23.6711,"nzd":34.2483,"sgd":32.062},"Volume":23.96827},"Time":1649023815350,"Event":"NewOrder"}
1649023815.461778: {"Channel":"orderbook-eth","Nonce":19205,"Data":{"OrderType":"LimitBid","OrderGuid":"923d81e5-e2aa-4bae-b363-33cb6c1f2b48","Price":{"aud":4703.73,"usd":3506.16,"nzd":5062.15,"sgd":4767.23},"Volume":0.39966033},"Time":1649023815350,"Event":"NewOrder"}
1649023815.503754: {"Channel":"orderbook-eth","Nonce":19206,"Data":{"OrderType":"LimitOffer","OrderGuid":"d6f51f4b-cc47-4c16-9aeb-65b915c07edf","Price":{"aud":4734.2,"usd":3564.38,"nzd":5157.09,"sgd":4827.87},"Volume":15.0},"Time":1649023815397,"Event":"NewOrder"}
1649023815.521228: {"Channel":"orderbook-eth","Nonce":19207,"Data":{"OrderType":"LimitBid","OrderGuid":"63d561da-f4b7-4f38-8dad-dfff146412b7"},"Time":1649023815413,"Event":"OrderCanceled"}
1649023815.521301: {"Channel":"orderbook-eth","Nonce":19208,"Data":{"OrderType":"LimitOffer","OrderGuid":"7a116543-2839-4def-87f4-0597d2009d5a","Price":{"aud":4737.2,"usd":3566.64,"nzd":5160.35,"sgd":4830.92},"Volume":15.0},"Time":1649023815413,"Event":"NewOrder"}
1649023815.5222888: {"Channel":"orderbook-eth","Nonce":19209,"Data":{"OrderType":"LimitBid","OrderGuid":"c7804aaa-3fd5-4fbf-9a35-1ca2abadc300"},"Time":1649023815413,"Event":"OrderCanceled"}
1649023815.544169: {"Channel":"orderbook-eth","Nonce":19210,"Data":{"OrderType":"LimitOffer","OrderGuid":"3160cff2-b4d2-4ee2-a51a-53b51664f816"},"Time":1649023815444,"Event":"OrderCanceled"}
1649023815.560194: {"Channel":"orderbook-matic","Nonce":5878,"Data":{"OrderType":"LimitOffer","OrderGuid":"5050ff1b-4208-469e-806e-693140aeaae1"},"Time":1649023815460,"Event":"OrderCanceled"}
1649023815.5761678: {"Channel":"orderbook-eth","Nonce":19211,"Data":{"OrderType":"LimitBid","OrderGuid":"b4104234-8528-47d6-b312-5cb6c1e2957c","Price":{"aud":4724.0,"usd":3521.26,"nzd":5083.96,"sgd":4787.77},"Volume":15.0},"Time":1649023815475,"Event":"NewOrder"}
1649023815.58691: {"Channel":"orderbook-eth","Nonce":19212,"Data":{"OrderType":"LimitBid","OrderGuid":"fc7531e2-e27a-445e-b3df-9d03290d0e13","Price":{"aud":4727.0,"usd":3523.5,"nzd":5087.19,"sgd":4790.81},"Volume":15.0},"Time":1649023815475,"Event":"NewOrder"}
1649023815.590318: {"Channel":"orderbook-eth","Nonce":19213,"Data":{"OrderType":"LimitBid","OrderGuid":"b64219e2-9833-46a5-bc15-f2edf021483a","Price":{"aud":4678.05,"usd":3503.95,"nzd":5095.92,"sgd":4769.78},"Volume":0.48195666},"Time":1649023815491,"Event":"NewOrder"}
1649023815.6058822: {"Channel":"orderbook-dot","Nonce":4943,"Data":{"OrderType":"LimitOffer","OrderGuid":"002d0d15-481c-47da-94dd-3c4768649507"},"Time":1649023815508,"Event":"OrderCanceled"}
1649023815.606884: {"Channel":"orderbook-eth","Nonce":19214,"Data":{"OrderType":"LimitOffer","OrderGuid":"be7f865a-b956-447d-bdd1-ce87ecbf42de","Price":{"aud":4783.65,"usd":3583.33,"nzd":5148.16,"sgd":4848.53},"Volume":0.48065804},"Time":1649023815508,"Event":"NewOrder"}
1649023815.619466: {"Channel":"orderbook-matic","Nonce":5879,"Data":{"OrderType":"LimitOffer","OrderGuid":"03418f1f-298d-41de-aea0-fa1eaf916b58","Price":{"aud":2.27195,"usd":1.71055,"nzd":2.4749,"sgd":2.3169},"Volume":5745.95682},"Time":1649023815508,"Event":"NewOrder"}
1649023815.631325: {"Channel":"orderbook-bch","Nonce":8237,"Data":{"OrderType":"LimitOffer","OrderGuid":"3245556d-5c03-49ff-aaf1-c98859f63ade","Price":{"aud":508.69,"usd":383.0,"nzd":554.13,"sgd":518.76},"Volume":1.09307485},"Time":1649023815523,"Event":"NewOrder"}
1649023815.637269: {"Channel":"orderbook-bch","Nonce":8238,"Data":{"OrderType":"LimitOffer","OrderGuid":"ff22afa0-0be8-45ec-a0a1-8e4d4de99d31"},"Time":1649023815539,"Event":"OrderCanceled"}
1649023815.6373818: {"Channel":"orderbook-dot","Nonce":4944,"Data":{"OrderType":"LimitBid","OrderGuid":"86bcc2dc-63b9-4a51-97a7-188c6b7dd90b","Price":{"aud":30.7042,"usd":22.8869,"nzd":33.0438,"sgd":31.1187},"Volume":24.76459},"Time":1649023815539,"Event":"NewOrder"}
1649023815.656418: {"Channel":"orderbook-dot","Nonce":4945,"Data":{"OrderType":"LimitOffer","OrderGuid":"a3ba0a82-b842-43b5-abc5-c033f026852c"},"Time":1649023815555,"Event":"OrderCanceled"}
1649023815.658965: {"Channel":"orderbook-dot","Nonce":4946,"Data":{"OrderType":"LimitBid","OrderGuid":"b3e9ecd3-dc44-4184-9564-0798ea011456"},"Time":1649023815555,"Event":"OrderCanceled"}
1649023815.6753101: {"Channel":"orderbook-dot","Nonce":4947,"Data":{"OrderType":"LimitOffer","OrderGuid":"4f2f6c4e-7163-4477-a828-75ea3c9aba11"},"Time":1649023815570,"Event":"OrderCanceled"}
1649023815.675415: {"Channel":"orderbook-bch","Nonce":8239,"Data":{"OrderType":"LimitOffer","OrderGuid":"8c614446-8f9f-4e78-ad03-ecab60629649","Price":{"aud":510.8,"usd":384.59,"nzd":556.43,"sgd":520.91},"Volume":21.20858658},"Time":1649023815570,"Event":"NewOrder"}
1649023815.678526: {"Channel":"orderbook-bch","Nonce":8240,"Data":{"OrderType":"LimitOffer","OrderGuid":"8344b8b8-d265-4c75-9f21-6e1bcf2154d7"},"Time":1649023815570,"Event":"OrderCanceled"}
1649023815.7373009: {"Channel":"orderbook-dot","Nonce":4948,"Data":{"OrderType":"LimitOffer","OrderGuid":"462adea3-468d-4f5c-b9d9-f266a1e91ec9","Price":{"aud":31.51,"usd":23.7239,"nzd":34.3247,"sgd":32.1334},"Volume":22.02329},"Time":1649023815633,"Event":"NewOrder"}
1649023815.741444: {"Channel":"orderbook-bch","Nonce":8241,"Data":{"OrderType":"LimitOffer","OrderGuid":"e269849c-3d8b-4a1c-9fca-390a271b6538"},"Time":1649023815633,"Event":"OrderCanceled"}
1649023815.744662: {"Channel":"orderbook-dot","Nonce":4949,"Data":{"OrderType":"LimitBid","OrderGuid":"147c0e0c-4e68-4837-9c15-46a4043a257d"},"Time":1649023815648,"Event":"OrderCanceled"}
1649023815.768194: {"Channel":"orderbook-dot","Nonce":4950,"Data":{"OrderType":"LimitOffer","OrderGuid":"eab84159-618b-4ff5-bd66-56ea3de948ac","Price":{"aud":31.43,"usd":23.6637,"nzd":34.2375,"sgd":32.0519},"Volume":80.0},"Time":1649023815664,"Event":"NewOrder"}
1649023815.785908: {"Channel":"orderbook-dot","Nonce":4951,"Data":{"OrderType":"LimitOffer","OrderGuid":"62ffb140-5526-43e1-b241-9a9cd4723d74","Price":{"aud":31.5099,"usd":23.7238,"nzd":34.3246,"sgd":32.1333},"Volume":14.72539},"Time":1649023815680,"Event":"NewOrder"}
1649023815.797597: {"Channel":"orderbook-dot","Nonce":4952,"Data":{"OrderType":"LimitOffer","OrderGuid":"3a2e24fc-c170-4c55-bdf1-57ecce8f2ccd"},"Time":1649023815695,"Event":"OrderCanceled"}
1649023815.798275: {"Channel":"orderbook-eth","Nonce":19215,"Data":{"OrderType":"LimitBid","OrderGuid":"4e24aa5c-1f02-49d1-9c20-c4de9e2c24eb","Price":{"aud":4660.31,"usd":3473.79,"nzd":5015.42,"sgd":4723.22},"Volume":0.19525734},"Time":1649023815695,"Event":"NewOrder"}
1649023815.80086: {"Channel":"orderbook-bch","Nonce":8242,"Data":{"OrderType":"LimitOffer","OrderGuid":"5498e6f8-c9f7-4d7a-9cbf-36d807aa7a84","Price":{"aud":510.8,"usd":384.59,"nzd":556.43,"sgd":520.91},"Volume":39.74331},"Time":1649023815695,"Event":"NewOrder"}
1649023815.8625221: {"Channel":"orderbook-eth","Nonce":19216,"Data":{"OrderType":"LimitBid","OrderGuid":"f705cd37-c10f-4be5-bbda-936e60ed44fa"},"Time":1649023815758,"Event":"OrderCanceled"}
1649023815.864755: {"Channel":"orderbook-dot","Nonce":4953,"Data":{"OrderType":"LimitBid","OrderGuid":"cb52a29c-96d4-4e27-8283-6e6bd9a9cc9c"},"Time":1649023815758,"Event":"OrderCanceled"}
1649023815.8688278: {"Channel":"orderbook-dot","Nonce":4954,"Data":{"OrderType":"LimitOffer","OrderGuid":"2d5bdd00-9192-4f4f-ba16-dad561f844e5","Price":{"aud":31.39,"usd":23.6335,"nzd":34.1939,"sgd":32.0111},"Volume":80.0},"Time":1649023815758,"Event":"NewOrder"}
1649023815.904196: {"Channel":"orderbook-dot","Nonce":4955,"Data":{"OrderType":"LimitBid","OrderGuid":"15bcd9f0-0399-4c9f-a823-1209eb415457","Price":{"aud":30.8025,"usd":22.9601,"nzd":33.1496,"sgd":31.2183},"Volume":457.6},"Time":1649023815805,"Event":"NewOrder"}
1649023815.9051049: {"Channel":"orderbook-dot","Nonce":4956,"Data":{"OrderType":"LimitBid","OrderGuid":"bc58af76-aa5b-4fa1-a756-0e076a7840bc","Price":{"aud":31.19,"usd":23.249,"nzd":33.5666,"sgd":31.611},"Volume":80.0},"Time":1649023815805,"Event":"NewOrder"}
1649023815.9056268: {"Channel":"orderbook-bch","Nonce":8243,"Data":{"OrderType":"LimitOffer","OrderGuid":"26bde143-1b9d-4f10-b2b9-a1b0247bbe5d","Price":{"aud":508.68,"usd":382.99,"nzd":554.12,"sgd":518.75},"Volume":1.09307485},"Time":1649023815805,"Event":"NewOrder"}
1649023815.9094348: {"Channel":"orderbook-dot","Nonce":4957,"Data":{"OrderType":"LimitBid","OrderGuid":"71bec59f-b921-4f35-97e2-bb42ce881913"},"Time":1649023815805,"Event":"OrderCanceled"}
1649023815.909508: {"Channel":"orderbook-dot","Nonce":4958,"Data":{"OrderType":"LimitBid","OrderGuid":"0e4068fd-cb9b-49f1-a6f8-005d4bbb5e76","Price":{"aud":31.15,"usd":23.2192,"nzd":33.5236,"sgd":31.5705},"Volume":80.0},"Time":1649023815805,"Event":"NewOrder"}
1649023816.116811: {"Channel":"orderbook-matic","Nonce":5880,"Data":{"OrderType":"LimitOffer","OrderGuid":"1b3cd32b-7713-4720-af89-10346b1e71b7","Price":{"aud":2.31273,"usd":1.74126,"nzd":2.51932,"sgd":2.35849},"Volume":6000.0},"Time":1649023816008,"Event":"NewOrder"}
1649023816.1801028: {"Channel":"orderbook-dot","Nonce":4959,"Data":{"OrderType":"LimitBid","OrderGuid":"d72aec0a-1b11-41d1-a7db-d059d141d9c3","Price":{"aud":30.801,"usd":22.959,"nzd":33.148,"sgd":31.2168},"Volume":24.76459},"Time":1649023816071,"Event":"NewOrder"}
1649023816.237368: {"Channel":"orderbook-eth","Nonce":19217,"Data":{"OrderType":"LimitBid","OrderGuid":"6decf620-c0d9-498f-a03d-7d17d025079c","Price":{"aud":4665.81,"usd":3477.89,"nzd":5021.34,"sgd":4728.79},"Volume":0.19525734},"Time":1649023816133,"Event":"NewOrder"}
1649023816.406052: {"Channel":"orderbook-eth","Nonce":19218,"Data":{"OrderType":"LimitBid","OrderGuid":"923d81e5-e2aa-4bae-b363-33cb6c1f2b48"},"Time":1649023816306,"Event":"OrderCanceled"}
1649023816.442125: {"Channel":"orderbook-dot","Nonce":4960,"Data":{"OrderType":"LimitOffer","OrderGuid":"462adea3-468d-4f5c-b9d9-f266a1e91ec9"},"Time":1649023816337,"Event":"OrderCanceled"}
1649023816.472152: {"Channel":"orderbook-eth","Nonce":19219,"Data":{"OrderType":"LimitBid","OrderGuid":"b4f2f2bc-1647-4f08-a343-4ee93c5a2a8a","Price":{"aud":4703.74,"usd":3506.16,"nzd":5062.16,"sgd":4767.24},"Volume":0.32868264},"Time":1649023816368,"Event":"NewOrder"}
1649023816.528301: {"Channel":"orderbook-dot","Nonce":4961,"Data":{"OrderType":"LimitOffer","OrderGuid":"8a5921dd-b3a4-4584-bae2-02656a56314a","Price":{"aud":31.4399,"usd":23.6711,"nzd":34.2483,"sgd":32.062},"Volume":28.64834},"Time":1649023816431,"Event":"NewOrder"}
1649023816.575707: {"Channel":"orderbook-matic","Nonce":5881,"Data":{"OrderType":"LimitOffer","OrderGuid":"03418f1f-298d-41de-aea0-fa1eaf916b58"},"Time":1649023816478,"Event":"OrderCanceled"}
1649023816.596013: {"Channel":"orderbook-dot","Nonce":4962,"Data":{"OrderType":"LimitOffer","OrderGuid":"8a5921dd-b3a4-4584-bae2-02656a56314a"},"Time":1649023816493,"Event":"OrderCanceled"}
1649023816.611949: {"Channel":"orderbook-matic","Nonce":5882,"Data":{"OrderType":"LimitOffer","OrderGuid":"f3824a6a-114a-434c-82f5-71903aabadb4","Price":{"aud":2.27194,"usd":1.71055,"nzd":2.47489,"sgd":2.31689},"Volume":5529.2409},"Time":1649023816509,"Event":"NewOrder"}
1649023816.627507: {"Channel":"orderbook-dot","Nonce":4963,"Data":{"OrderType":"LimitOffer","OrderGuid":"2280e9c4-0d0a-464c-bc7f-1abe6bcfa27e","Price":{"aud":31.5098,"usd":23.7237,"nzd":34.3245,"sgd":32.1332},"Volume":21.50378},"Time":1649023816525,"Event":"NewOrder"}
1649023816.642259: {"Channel":"orderbook-eth","Nonce":19220,"Data":{"OrderType":"LimitBid","OrderGuid":"b64219e2-9833-46a5-bc15-f2edf021483a"},"Time":1649023816540,"Event":"OrderCanceled"}
1649023816.669764: {"Channel":"orderbook-dot","Nonce":4964,"Data":{"OrderType":"LimitOffer","OrderGuid":"2c29bdf8-401d-4ee6-b4a6-084284d81b53","Price":{"aud":31.5097,"usd":23.7237,"nzd":34.3243,"sgd":32.1331},"Volume":14.72539},"Time":1649023816572,"Event":"NewOrder"}
1649023816.672003: {"Channel":"orderbook-dot","Nonce":4965,"Data":{"OrderType":"LimitBid","OrderGuid":"86bcc2dc-63b9-4a51-97a7-188c6b7dd90b"},"Time":1649023816572,"Event":"OrderCanceled"}
1649023816.673599: {"Channel":"orderbook-dot","Nonce":4966,"Data":{"OrderType":"LimitOffer","OrderGuid":"62ffb140-5526-43e1-b241-9a9cd4723d74"},"Time":1649023816572,"Event":"OrderCanceled"}
1649023816.673706: {"Channel":"orderbook-bch","Nonce":8244,"Data":{"OrderType":"LimitOffer","OrderGuid":"3245556d-5c03-49ff-aaf1-c98859f63ade"},"Time":1649023816572,"Event":"OrderCanceled"}
1649023816.6880682: {"Channel":"orderbook-eth","Nonce":19221,"Data":{"OrderType":"LimitBid","OrderGuid":"e9c41776-8abf-4899-8e2f-94c454a86a60","Price":{"aud":4678.06,"usd":3503.96,"nzd":5095.93,"sgd":4769.79},"Volume":0.56968347},"Time":1649023816587,"Event":"NewOrder"}
1649023816.783732: {"Channel":"orderbook-eth","Nonce":19222,"Data":{"OrderType":"LimitBid","OrderGuid":"e98041ea-2ac9-454c-a5da-d8ea96818bf0"},"Time":1649023816681,"Event":"OrderCanceled"}
1649023816.788571: {"Channel":"orderbook-bch","Nonce":8245,"Data":{"OrderType":"LimitOffer","OrderGuid":"57ee6e89-74bd-4689-ac75-530eac865b63","Price":{"aud":508.67,"usd":382.98,"nzd":554.11,"sgd":518.74},"Volume":1.09307485},"Time":1649023816681,"Event":"NewOrder"}
1649023816.826973: {"Channel":"orderbook-eth","Nonce":19223,"Data":{"OrderType":"LimitBid","OrderGuid":"175a1b7b-912f-4604-9757-9fb0a251185c","Price":{"aud":4696.26,"usd":3518.61,"nzd":5085.15,"sgd":4789.18},"Volume":3.01413612},"Time":1649023816713,"Event":"NewOrder"}
1649023816.8731341: {"Channel":"orderbook-eth","Nonce":19224,"Data":{"OrderType":"LimitBid","OrderGuid":"4e24aa5c-1f02-49d1-9c20-c4de9e2c24eb"},"Time":1649023816776,"Event":"OrderCanceled"}
1649023816.9589388: {"Channel":"orderbook-bch","Nonce":8246,"Data":{"OrderType":"LimitOffer","OrderGuid":"26bde143-1b9d-4f10-b2b9-a1b0247bbe5d"},"Time":1649023816854,"Event":"OrderCanceled"}
1649023816.981718: {"Channel":"orderbook-eth","Nonce":19225,"Data":{"OrderType":"LimitBid","OrderGuid":"fc7531e2-e27a-445e-b3df-9d03290d0e13"},"Time":1649023816885,"Event":"OrderCanceled"}
1649023816.986885: {"Channel":"orderbook-eth","Nonce":19226,"Data":{"OrderType":"LimitBid","OrderGuid":"b4104234-8528-47d6-b312-5cb6c1e2957c"},"Time":1649023816885,"Event":"OrderCanceled"}
1649023817.082044: {"Channel":"orderbook-eth","Nonce":19227,"Data":{"OrderType":"LimitOffer","OrderGuid":"d6f51f4b-cc47-4c16-9aeb-65b915c07edf"},"Time":1649023816979,"Event":"OrderCanceled"}
1649023817.085234: {"Channel":"orderbook-eth","Nonce":19228,"Data":{"OrderType":"LimitOffer","OrderGuid":"30caedc7-fe84-4a4e-b48e-7260f809938e"},"Time":1649023816979,"Event":"OrderCanceled"}
1649023817.0858471: {"Channel":"orderbook-eth","Nonce":19229,"Data":{"OrderType":"LimitOffer","OrderGuid":"7a116543-2839-4def-87f4-0597d2009d5a"},"Time":1649023816979,"Event":"OrderCanceled"}
1649023817.102752: {"Channel":"orderbook-eth","Nonce":19230,"Data":{"OrderType":"LimitBid","OrderGuid":"44a30001-4da5-4f19-b348-41fba8f5afb7","Price":{"aud":4723.6,"usd":3520.97,"nzd":5083.53,"sgd":4787.36},"Volume":15.0},"Time":1649023816995,"Event":"NewOrder"}
1649023817.128632: {"Channel":"orderbook-eth","Nonce":19231,"Data":{"OrderType":"LimitBid","OrderGuid":"750ec276-733b-4407-b662-0455e3c2ec0d","Price":{"aud":4726.6,"usd":3523.2,"nzd":5086.76,"sgd":4790.4},"Volume":15.0},"Time":1649023817026,"Event":"NewOrder"}
1649023817.163868: {"Channel":"orderbook-eth","Nonce":19232,"Data":{"OrderType":"LimitOffer","OrderGuid":"f842f1ae-a223-428b-8aa5-eae91278e618","Price":{"aud":4733.8,"usd":3564.08,"nzd":5156.65,"sgd":4827.46},"Volume":15.0},"Time":1649023817057,"Event":"NewOrder"}
1649023817.178713: {"Channel":"orderbook-eth","Nonce":19233,"Data":{"OrderType":"LimitBid","OrderGuid":"175a1b7b-912f-4604-9757-9fb0a251185c"},"Time":1649023817073,"Event":"OrderCanceled"}
1649023817.181959: {"Channel":"orderbook-eth","Nonce":19234,"Data":{"OrderType":"LimitOffer","OrderGuid":"6a3625d2-30c7-46b6-a682-3ccea8d50740","Price":{"aud":4742.37,"usd":3570.53,"nzd":5165.99,"sgd":4836.2},"Volume":1.78932362},"Time":1649023817073,"Event":"NewOrder"}
1649023817.184223: {"Channel":"orderbook-eth","Nonce":19235,"Data":{"OrderType":"LimitOffer","OrderGuid":"2a6b845e-9acf-4271-9f06-1ca87cdfe191"},"Time":1649023817073,"Event":"OrderCanceled"}
1649023817.2369459: {"Channel":"orderbook-eth","Nonce":19236,"Data":{"OrderType":"LimitOffer","OrderGuid":"3fc42df9-70a4-4021-87e7-eaf3b9b6fb5c","Price":{"aud":4794.16,"usd":3573.56,"nzd":5197.15,"sgd":4863.98},"Volume":0.54951619},"Time":1649023817135,"Event":"NewOrder"}
1649023817.249221: {"Channel":"orderbook-eth","Nonce":19237,"Data":{"OrderType":"LimitBid","OrderGuid":"97249c34-46b9-4395-8095-91d820a9698e","Price":{"aud":4698.12,"usd":3519.99,"nzd":5087.15,"sgd":4791.07},"Volume":3.00352777},"Time":1649023817151,"Event":"NewOrder"}
1649023817.254966: {"Channel":"orderbook-eth","Nonce":19238,"Data":{"OrderType":"LimitOffer","OrderGuid":"8ee4b1b5-7104-432d-a7e8-516062f22a6b","Price":{"aud":4736.8,"usd":3566.34,"nzd":5159.92,"sgd":4830.52},"Volume":15.0},"Time":1649023817151,"Event":"NewOrder"}
1649023817.2770472: {"Channel":"orderbook-eth","Nonce":19239,"Data":{"OrderType":"LimitOffer","OrderGuid":"f842f1ae-a223-428b-8aa5-eae91278e618"},"Time":1649023817167,"Event":"OrderCanceled"}
1649023817.280473: {"Channel":"orderbook-eth","Nonce":19240,"Data":{"OrderType":"LimitBid","OrderGuid":"750ec276-733b-4407-b662-0455e3c2ec0d"},"Time":1649023817182,"Event":"OrderCanceled"}
1649023817.2811048: {"Channel":"orderbook-eth","Nonce":19241,"Data":{"OrderType":"LimitOffer","OrderGuid":"3fc42df9-70a4-4021-87e7-eaf3b9b6fb5c"},"Time":1649023817182,"Event":"OrderCanceled"}
1649023817.295867: {"Channel":"orderbook-eth","Nonce":19242,"Data":{"OrderType":"LimitOffer","OrderGuid":"8ee4b1b5-7104-432d-a7e8-516062f22a6b"},"Time":1649023817198,"Event":"OrderCanceled"}
1649023817.295979: {"Channel":"orderbook-dot","Nonce":4967,"Data":{"OrderType":"LimitBid","OrderGuid":"2d3ac644-1e66-4a97-951c-44cedf4ce222","Price":{"aud":30.7042,"usd":22.8869,"nzd":33.0438,"sgd":31.1187},"Volume":24.79202},"Time":1649023817198,"Event":"NewOrder"}
1649023817.296055: {"Channel":"orderbook-eth","Nonce":19243,"Data":{"OrderType":"LimitBid","OrderGuid":"44a30001-4da5-4f19-b348-41fba8f5afb7"},"Time":1649023817198,"Event":"OrderCanceled"}
1649023817.320965: {"Channel":"orderbook-bch","Nonce":8247,"Data":{"OrderType":"LimitOffer","OrderGuid":"82a29b89-4729-4f58-a902-816193a6e5f4","Price":{"aud":507.78,"usd":382.31,"nzd":553.14,"sgd":517.83},"Volume":1.09429089},"Time":1649023817213,"Event":"NewOrder"}
1649023817.3210912: {"Channel":"orderbook-eth","Nonce":19244,"Data":{"OrderType":"LimitOffer","OrderGuid":"89f2576b-1947-4ccf-a242-caaeb0741474","Price":{"aud":4794.16,"usd":3573.56,"nzd":5197.15,"sgd":4863.98},"Volume":0.53348547},"Time":1649023817213,"Event":"NewOrder"}
1649023817.324342: {"Channel":"orderbook-eth","Nonce":19245,"Data":{"OrderType":"LimitOffer","OrderGuid":"5f5815f5-0726-4c9f-b6f8-934ef540160c","Price":{"aud":4736.79,"usd":3566.33,"nzd":5159.91,"sgd":4830.51},"Volume":1.78932362},"Time":1649023817213,"Event":"NewOrder"}
1649023817.406671: {"Channel":"orderbook-eth","Nonce":19246,"Data":{"OrderType":"LimitOffer","OrderGuid":"4d13123a-5ba2-4333-bea9-4f95f1cf36eb","Price":{"aud":4736.6,"usd":3566.18,"nzd":5159.7,"sgd":4830.31},"Volume":15.0},"Time":1649023817229,"Event":"NewOrder"}
1649023817.406803: {"Channel":"orderbook-eth","Nonce":19247,"Data":{"OrderType":"LimitOffer","OrderGuid":"6a3625d2-30c7-46b6-a682-3ccea8d50740"},"Time":1649023817229,"Event":"OrderCanceled"}
1649023817.40686: {"Channel":"orderbook-eth","Nonce":19248,"Data":{"OrderType":"LimitOffer","OrderGuid":"e7e23ccf-85a5-40a6-9235-9b63c35f91d8","Price":{"aud":4733.6,"usd":3563.93,"nzd":5156.43,"sgd":4827.25},"Volume":15.0},"Time":1649023817229,"Event":"NewOrder"}
1649023817.406912: {"Channel":"orderbook-eth","Nonce":19249,"Data":{"OrderType":"LimitBid","OrderGuid":"199935ef-faf0-4252-8c86-636ecbb9644d","Price":{"aud":4726.4,"usd":3523.05,"nzd":5086.55,"sgd":4790.2},"Volume":15.0},"Time":1649023817245,"Event":"NewOrder"}
1649023817.40696: {"Channel":"orderbook-eth","Nonce":19250,"Data":{"OrderType":"LimitBid","OrderGuid":"77f5ea6f-5522-4a33-a039-d534a95adbed","Price":{"aud":4723.4,"usd":3520.82,"nzd":5083.32,"sgd":4787.16},"Volume":15.0},"Time":1649023817260,"Event":"NewOrder"}
1649023817.407006: {"Channel":"orderbook-eth","Nonce":19251,"Data":{"OrderType":"LimitOffer","OrderGuid":"4e00f568-8215-4d8a-8310-05062e69e571","Price":{"aud":4736.59,"usd":3566.18,"nzd":5159.69,"sgd":4830.3},"Volume":1.78932362},"Time":1649023817292,"Event":"NewOrder"}
1649023817.407079: {"Channel":"orderbook-eth","Nonce":19252,"Data":{"OrderType":"LimitOffer","OrderGuid":"5f5815f5-0726-4c9f-b6f8-934ef540160c"},"Time":1649023817307,"Event":"OrderCanceled"}
1649023817.4128551: {"Channel":"orderbook-eth","Nonce":19253,"Data":{"OrderType":"LimitBid","OrderGuid":"ee467e9a-7d21-4b9d-b375-7b2793873e0d","Price":{"aud":4660.31,"usd":3473.79,"nzd":5015.42,"sgd":4723.22},"Volume":0.19547021},"Time":1649023817307,"Event":"NewOrder"}
1649023817.433934: {"Channel":"orderbook-dot","Nonce":4968,"Data":{"OrderType":"LimitBid","OrderGuid":"d72aec0a-1b11-41d1-a7db-d059d141d9c3"},"Time":1649023817324,"Event":"OrderCanceled"}
1649023817.482031: {"Channel":"orderbook-eth","Nonce":19254,"Data":{"OrderType":"LimitBid","OrderGuid":"b4f2f2bc-1647-4f08-a343-4ee93c5a2a8a"},"Time":1649023817371,"Event":"OrderCanceled"}
1649023817.488402: {"Channel":"orderbook-eth","Nonce":19255,"Data":{"OrderType":"LimitBid","OrderGuid":"6decf620-c0d9-498f-a03d-7d17d025079c"},"Time":1649023817387,"Event":"OrderCanceled"}
1649023817.526129: {"Channel":"orderbook-eth","Nonce":19256,"Data":{"OrderType":"LimitOffer","OrderGuid":"4e00f568-8215-4d8a-8310-05062e69e571"},"Time":1649023817418,"Event":"OrderCanceled"}
1649023817.5520399: {"Channel":"orderbook-eth","Nonce":19257,"Data":{"OrderType":"LimitBid","OrderGuid":"28123440-62cf-4127-a8c9-dc9991dd1b7f","Price":{"aud":4703.75,"usd":3506.17,"nzd":5062.17,"sgd":4767.25},"Volume":0.32273242},"Time":1649023817449,"Event":"NewOrder"}
1649023817.561944: {"Channel":"orderbook-bch","Nonce":8248,"Data":{"OrderType":"LimitOffer","OrderGuid":"5ba6ce84-ac9b-43e7-ae4b-b5ee56a28efb"},"Time":1649023817465,"Event":"OrderCanceled"}
1649023817.576402: {"Channel":"orderbook-eth","Nonce":19258,"Data":{"OrderType":"LimitOffer","OrderGuid":"e7e23ccf-85a5-40a6-9235-9b63c35f91d8"},"Time":1649023817480,"Event":"OrderCanceled"}
1649023817.602734: {"Channel":"orderbook-eth","Nonce":19259,"Data":{"OrderType":"LimitOffer","OrderGuid":"4d13123a-5ba2-4333-bea9-4f95f1cf36eb"},"Time":1649023817496,"Event":"OrderCanceled"}
1649023817.614721: {"Channel":"orderbook-matic","Nonce":5883,"Data":{"OrderType":"LimitOffer","OrderGuid":"f3824a6a-114a-434c-82f5-71903aabadb4"},"Time":1649023817512,"Event":"OrderCanceled"}
1649023817.655595: {"Channel":"orderbook-eth","Nonce":19260,"Data":{"OrderType":"LimitBid","OrderGuid":"77f5ea6f-5522-4a33-a039-d534a95adbed"},"Time":1649023817543,"Event":"OrderCanceled"}
1649023817.6651158: {"Channel":"orderbook-bch","Nonce":8249,"Data":{"OrderType":"LimitOffer","OrderGuid":"edf4f41b-ef10-4d01-aef3-1f4e7b2ee583"},"Time":1649023817558,"Event":"OrderCanceled"}
1649023817.674165: {"Channel":"orderbook-eth","Nonce":19261,"Data":{"OrderType":"LimitOffer","OrderGuid":"529e280b-b96c-49d9-a7dc-89562a7206fd","Price":{"aud":4733.9,"usd":3564.15,"nzd":5156.76,"sgd":4827.56},"Volume":15.0},"Time":1649023817574,"Event":"NewOrder"}
1649023817.696817: {"Channel":"orderbook-eth","Nonce":19262,"Data":{"OrderType":"LimitOffer","OrderGuid":"4aeb3e61-b525-4c20-bc9a-01bcfc769cd6","Price":{"aud":4736.9,"usd":3566.41,"nzd":5160.03,"sgd":4830.62},"Volume":15.0},"Time":1649023817590,"Event":"NewOrder"}
1649023817.703298: {"Channel":"orderbook-bch","Nonce":8250,"Data":{"OrderType":"LimitBid","OrderGuid":"151828d2-685e-460d-b7a3-f1461b5bf8d6"},"Time":1649023817605,"Event":"OrderCanceled"}
1649023817.7637818: {"Channel":"orderbook-matic","Nonce":5884,"Data":{"OrderType":"LimitOffer","OrderGuid":"bbd208d7-d470-40a1-a390-de8bedb93a61","Price":{"aud":2.27193,"usd":1.71054,"nzd":2.47487,"sgd":2.31688},"Volume":5089.99632},"Time":1649023817652,"Event":"NewOrder"}
1649023817.768904: {"Channel":"orderbook-eth","Nonce":19263,"Data":{"OrderType":"LimitBid","OrderGuid":"199935ef-faf0-4252-8c86-636ecbb9644d"},"Time":1649023817668,"Event":"OrderCanceled"}
1649023817.781261: {"Channel":"orderbook-bch","Nonce":8251,"Data":{"OrderType":"LimitBid","OrderGuid":"7a17009a-67e4-455e-9c97-829362dad836"},"Time":1649023817684,"Event":"OrderCanceled"}
1649023817.7855208: {"Channel":"orderbook-bch","Nonce":8252,"Data":{"OrderType":"LimitOffer","OrderGuid":"122f42fb-b9e5-4f7f-a157-b42356fd0db0","Price":{"aud":506.9,"usd":381.65,"nzd":552.18,"sgd":516.93},"Volume":6.0},"Time":1649023817684,"Event":"NewOrder"}
1649023817.81335: {"Channel":"orderbook-bch","Nonce":8253,"Data":{"OrderType":"LimitOffer","OrderGuid":"c7afd25e-ec2c-423e-a703-87c6de7bb9c9","Price":{"aud":507.6,"usd":382.18,"nzd":552.95,"sgd":517.65},"Volume":6.0},"Time":1649023817699,"Event":"NewOrder"}
1649023817.821378: {"Channel":"orderbook-eth","Nonce":19264,"Data":{"OrderType":"LimitBid","OrderGuid":"d78a7878-2447-4453-8dc8-6b94cd68a338","Price":{"aud":4726.7,"usd":3523.28,"nzd":5086.87,"sgd":4790.51},"Volume":15.0},"Time":1649023817715,"Event":"NewOrder"}
1649023817.8381262: {"Channel":"orderbook-bch","Nonce":8254,"Data":{"OrderType":"LimitOffer","OrderGuid":"122f42fb-b9e5-4f7f-a157-b42356fd0db0"},"Time":1649023817731,"Event":"OrderCanceled"}
1649023817.838204: {"Channel":"orderbook-eth","Nonce":19265,"Data":{"OrderType":"LimitBid","OrderGuid":"755d67ef-2c2f-429a-8d25-59abbd58cdcb","Price":{"aud":4723.7,"usd":3521.04,"nzd":5083.64,"sgd":4787.46},"Volume":15.0},"Time":1649023817731,"Event":"NewOrder"}
1649023817.917471: {"Channel":"orderbook-eth","Nonce":19266,"Data":{"OrderType":"LimitBid","OrderGuid":"e9c41776-8abf-4899-8e2f-94c454a86a60"},"Time":1649023817809,"Event":"OrderCanceled"}
1649023817.922518: {"Channel":"orderbook-eth","Nonce":19267,"Data":{"OrderType":"LimitBid","OrderGuid":"a028abbb-c2f0-46a8-afa7-7092ab4f13cc","Price":{"aud":4665.81,"usd":3477.89,"nzd":5021.34,"sgd":4728.79},"Volume":0.19547021},"Time":1649023817809,"Event":"NewOrder"}
1649023817.940373: {"Channel":"orderbook-bch","Nonce":8255,"Data":{"OrderType":"LimitOffer","OrderGuid":"c7afd25e-ec2c-423e-a703-87c6de7bb9c9"},"Time":1649023817840,"Event":"OrderCanceled"}
1649023817.940792: {"Channel":"orderbook-bch","Nonce":8256,"Data":{"OrderType":"LimitOffer","OrderGuid":"57ee6e89-74bd-4689-ac75-530eac865b63"},"Time":1649023817840,"Event":"OrderCanceled"}
1649023817.940842: {"Channel":"orderbook-bch","Nonce":8257,"Data":{"OrderType":"LimitBid","OrderGuid":"86d14e50-1dd1-45a8-9d7b-7b258acb9a07","Price":{"aud":503.4,"usd":375.23,"nzd":541.75,"sgd":510.19},"Volume":6.0},"Time":1649023817840,"Event":"NewOrder"}
1649023817.970669: {"Channel":"orderbook-eth","Nonce":19268,"Data":{"OrderType":"LimitBid","OrderGuid":"0a9108c7-913e-47fd-95ec-f78937afb6f5","Price":{"aud":4678.07,"usd":3503.96,"nzd":5095.94,"sgd":4769.79},"Volume":0.58011757},"Time":1649023817871,"Event":"NewOrder"}
1649023817.983563: {"Channel":"orderbook-dot","Nonce":4969,"Data":{"OrderType":"LimitOffer","OrderGuid":"7673402f-d498-4c35-9e0b-44c87eb74d1f","Price":{"aud":31.3997,"usd":23.6408,"nzd":34.2045,"sgd":32.021},"Volume":19.96241},"Time":1649023817887,"Event":"NewOrder"}
1649023818.020629: {"Channel":"orderbook-bch","Nonce":8258,"Data":{"OrderType":"LimitOffer","OrderGuid":"af494809-9769-4fc4-9aab-c544198bf835","Price":{"aud":506.8,"usd":381.57,"nzd":552.07,"sgd":516.83},"Volume":6.0},"Time":1649023817918,"Event":"NewOrder"}
1649023818.0335119: {"Channel":"orderbook-bch","Nonce":8259,"Data":{"OrderType":"LimitOffer","OrderGuid":"a750ff4f-a17d-4788-a9f5-f1548d8c4027","Price":{"aud":507.5,"usd":382.1,"nzd":552.84,"sgd":517.55},"Volume":6.0},"Time":1649023817934,"Event":"NewOrder"}
1649023818.0520792: {"Channel":"orderbook-bch","Nonce":8260,"Data":{"OrderType":"LimitOffer","OrderGuid":"0533ed27-b34d-4d9f-a69d-7a70a4c0f9c9"},"Time":1649023817949,"Event":"OrderCanceled"}
1649023818.071139: {"Channel":"orderbook-dot","Nonce":4970,"Data":{"OrderType":"LimitOffer","OrderGuid":"3f254167-cb46-40ba-9884-5cd2a237700a"},"Time":1649023817966,"Event":"OrderCanceled"}
1649023818.0712209: {"Channel":"orderbook-eth","Nonce":19269,"Data":{"OrderType":"LimitBid","OrderGuid":"d78a7878-2447-4453-8dc8-6b94cd68a338"},"Time":1649023817966,"Event":"OrderCanceled"}
1649023818.09241: {"Channel":"orderbook-eth","Nonce":19270,"Data":{"OrderType":"LimitOffer","OrderGuid":"4aeb3e61-b525-4c20-bc9a-01bcfc769cd6"},"Time":1649023817982,"Event":"OrderCanceled"}
1649023818.092486: {"Channel":"orderbook-eth","Nonce":19271,"Data":{"OrderType":"LimitBid","OrderGuid":"755d67ef-2c2f-429a-8d25-59abbd58cdcb"},"Time":1649023817982,"Event":"OrderCanceled"}
1649023818.094614: {"Channel":"orderbook-dot","Nonce":4971,"Data":{"OrderType":"LimitBid","OrderGuid":"182771b2-5dc1-4546-82d7-879fb4f164cb"},"Time":1649023817982,"Event":"OrderCanceled"}
1649023818.13159: {"Channel":"orderbook-bch","Nonce":8261,"Data":{"OrderType":"LimitBid","OrderGuid":"c7f332af-c6da-4a1e-b405-abb118948b83","Price":{"aud":504.1,"usd":375.75,"nzd":542.51,"sgd":510.9},"Volume":6.0},"Time":1649023818029,"Event":"NewOrder"}
1649023818.184884: {"Channel":"orderbook-eth","Nonce":19272,"Data":{"OrderType":"LimitOffer","OrderGuid":"529e280b-b96c-49d9-a7dc-89562a7206fd"},"Time":1649023818075,"Event":"OrderCanceled"}
1649023818.185431: {"Channel":"orderbook-eth","Nonce":19273,"Data":{"OrderType":"LimitBid","OrderGuid":"8bc767b1-a1e6-4d4a-9a7f-89cd158da578","Price":{"aud":4726.6,"usd":3523.2,"nzd":5086.76,"sgd":4790.4},"Volume":15.0},"Time":1649023818075,"Event":"NewOrder"}
1649023818.1989398: {"Channel":"orderbook-eth","Nonce":19274,"Data":{"OrderType":"LimitBid","OrderGuid":"e5981ce5-3b01-4d51-9c1a-dde49d0237ad","Price":{"aud":4723.6,"usd":3520.97,"nzd":5083.53,"sgd":4787.36},"Volume":15.0},"Time":1649023818091,"Event":"NewOrder"}
1649023818.20977: {"Channel":"orderbook-bch","Nonce":8262,"Data":{"OrderType":"LimitOffer","OrderGuid":"1b3acfc2-a031-4581-91df-d4ef9e09d358","Price":{"aud":510.79,"usd":384.58,"nzd":556.42,"sgd":520.9},"Volume":2.93},"Time":1649023818107,"Event":"NewOrder"}
1649023818.222582: {"Channel":"orderbook-eth","Nonce":19275,"Data":{"OrderType":"LimitOffer","OrderGuid":"c224efec-990f-4e54-b34a-f673f3677100","Price":{"aud":4742.37,"usd":3570.53,"nzd":5165.99,"sgd":4836.2},"Volume":1.78932362},"Time":1649023818122,"Event":"NewOrder"}
1649023818.235492: {"Channel":"orderbook-eth","Nonce":19276,"Data":{"OrderType":"LimitOffer","OrderGuid":"c97fefb4-6cd8-4a0c-8393-dedf52342a4d","Price":{"aud":4733.8,"usd":3564.08,"nzd":5156.65,"sgd":4827.46},"Volume":15.0},"Time":1649023818138,"Event":"NewOrder"}
1649023818.2365718: {"Channel":"orderbook-dot","Nonce":4972,"Data":{"OrderType":"LimitBid","OrderGuid":"105bc15b-1d9e-441e-9bce-641ee209238b","Price":{"aud":30.8026,"usd":22.9602,"nzd":33.1497,"sgd":31.2184},"Volume":69.2},"Time":1649023818138,"Event":"NewOrder"}
1649023818.250284: {"Channel":"orderbook-eth","Nonce":19277,"Data":{"OrderType":"LimitOffer","OrderGuid":"194229d8-2098-4536-8a90-d6ffa8ddf14d"},"Time":1649023818138,"Event":"OrderCanceled"}
1649023818.250365: {"Channel":"orderbook-eth","Nonce":19278,"Data":{"OrderType":"LimitOffer","OrderGuid":"51097e2e-b970-412d-aa6f-64ba8170690e","Price":{"aud":4736.8,"usd":3566.34,"nzd":5159.92,"sgd":4830.52},"Volume":15.0},"Time":1649023818138,"Event":"NewOrder"}
1649023818.326389: {"Channel":"orderbook-eth","Nonce":19279,"Data":{"OrderType":"LimitOffer","OrderGuid":"c97fefb4-6cd8-4a0c-8393-dedf52342a4d"},"Time":1649023818216,"Event":"OrderCanceled"}
1649023818.336357: {"Channel":"orderbook-eth","Nonce":19280,"Data":{"OrderType":"LimitOffer","OrderGuid":"51097e2e-b970-412d-aa6f-64ba8170690e"},"Time":1649023818232,"Event":"OrderCanceled"}
1649023818.427152: {"Channel":"orderbook-eth","Nonce":19281,"Data":{"OrderType":"LimitOffer","OrderGuid":"b032cfe9-db28-4d82-b7e5-b03adb0f6fcc","Price":{"aud":4734.0,"usd":3564.23,"nzd":5156.87,"sgd":4827.66},"Volume":15.0},"Time":1649023818325,"Event":"NewOrder"}
1649023818.4417129: {"Channel":"orderbook-eth","Nonce":19282,"Data":{"OrderType":"LimitBid","OrderGuid":"8bc767b1-a1e6-4d4a-9a7f-89cd158da578"},"Time":1649023818341,"Event":"OrderCanceled"}
1649023818.4418209: {"Channel":"orderbook-eth","Nonce":19283,"Data":{"OrderType":"LimitOffer","OrderGuid":"ad8a0985-09ed-4410-9f08-c8aefbe543ec","Price":{"aud":4737.0,"usd":3566.49,"nzd":5160.14,"sgd":4830.72},"Volume":15.0},"Time":1649023818341,"Event":"NewOrder"}
1649023818.4750621: {"Channel":"orderbook-eth","Nonce":19284,"Data":{"OrderType":"LimitBid","OrderGuid":"ee467e9a-7d21-4b9d-b375-7b2793873e0d"},"Time":1649023818372,"Event":"OrderCanceled"}
1649023818.527631: {"Channel":"orderbook-eth","Nonce":19285,"Data":{"OrderType":"LimitBid","OrderGuid":"e5981ce5-3b01-4d51-9c1a-dde49d0237ad"},"Time":1649023818419,"Event":"OrderCanceled"}
1649023818.561686: {"Channel":"orderbook-eth","Nonce":19286,"Data":{"OrderType":"LimitBid","OrderGuid":"928e8f10-54b8-4a02-b1ff-274e8773248f","Price":{"aud":4726.8,"usd":3523.35,"nzd":5086.98,"sgd":4790.61},"Volume":15.0},"Time":1649023818450,"Event":"NewOrder"}
1649023818.565587: {"Channel":"orderbook-eth","Nonce":19287,"Data":{"OrderType":"LimitBid","OrderGuid":"e6da868b-cbff-470a-ae7e-052507a140a7","Price":{"aud":4723.8,"usd":3521.12,"nzd":5083.75,"sgd":4787.57},"Volume":15.0},"Time":1649023818466,"Event":"NewOrder"}
1649023818.620654: {"Channel":"orderbook-eth","Nonce":19288,"Data":{"OrderType":"LimitOffer","OrderGuid":"b032cfe9-db28-4d82-b7e5-b03adb0f6fcc"},"Time":1649023818513,"Event":"OrderCanceled"}
1649023818.6207309: {"Channel":"orderbook-bch","Nonce":8263,"Data":{"OrderType":"LimitOffer","OrderGuid":"b783f577-7b5a-46ee-9b47-829cdd39a32d","Price":{"aud":507.22,"usd":381.89,"nzd":552.53,"sgd":517.26},"Volume":1.09429089},"Time":1649023818513,"Event":"NewOrder"}
1649023818.63555: {"Channel":"orderbook-eth","Nonce":19289,"Data":{"OrderType":"LimitOffer","OrderGuid":"ad8a0985-09ed-4410-9f08-c8aefbe543ec"},"Time":1649023818529,"Event":"OrderCanceled"}
1649023818.6473129: {"Channel":"orderbook-eth","Nonce":19290,"Data":{"OrderType":"LimitBid","OrderGuid":"ad853f17-7db7-4136-86d0-b56ad913381c","Price":{"aud":4660.31,"usd":3473.79,"nzd":5015.42,"sgd":4723.22},"Volume":0.19547021},"Time":1649023818544,"Event":"NewOrder"}
1649023818.661412: {"Channel":"orderbook-eth","Nonce":19291,"Data":{"OrderType":"LimitBid","OrderGuid":"928e8f10-54b8-4a02-b1ff-274e8773248f"},"Time":1649023818560,"Event":"OrderCanceled"}
1649023818.6667929: {"Channel":"orderbook-eth","Nonce":19292,"Data":{"OrderType":"LimitBid","OrderGuid":"e6da868b-cbff-470a-ae7e-052507a140a7"},"Time":1649023818560,"Event":"OrderCanceled"}
1649023818.666902: {"Channel":"orderbook-eth","Nonce":19293,"Data":{"OrderType":"LimitOffer","OrderGuid":"829d7c89-62fe-4acd-a7de-284f0b18e12a","Price":{"aud":4736.99,"usd":3566.48,"nzd":5160.12,"sgd":4830.71},"Volume":1.78932362},"Time":1649023818560,"Event":"NewOrder"}
1649023818.6733031: {"Channel":"orderbook-eth","Nonce":19294,"Data":{"OrderType":"LimitOffer","OrderGuid":"c224efec-990f-4e54-b34a-f673f3677100"},"Time":1649023818560,"Event":"OrderCanceled"}
1649023818.673412: {"Channel":"orderbook-eth","Nonce":19295,"Data":{"OrderType":"LimitOffer","OrderGuid":"331a536c-5cba-4963-a6c0-3d3996558479","Price":{"aud":4734.1,"usd":3564.3,"nzd":5156.98,"sgd":4827.76},"Volume":15.0},"Time":1649023818560,"Event":"NewOrder"}
1649023818.688315: {"Channel":"orderbook-bch","Nonce":8264,"Data":{"OrderType":"LimitOffer","OrderGuid":"82a29b89-4729-4f58-a902-816193a6e5f4"},"Time":1649023818575,"Event":"OrderCanceled"}
1649023818.688421: {"Channel":"orderbook-eth","Nonce":19296,"Data":{"OrderType":"LimitBid","OrderGuid":"28123440-62cf-4127-a8c9-dc9991dd1b7f"},"Time":1649023818575,"Event":"OrderCanceled"}
1649023818.6999848: {"Channel":"orderbook-eth","Nonce":19297,"Data":{"OrderType":"LimitOffer","OrderGuid":"829d7c89-62fe-4acd-a7de-284f0b18e12a"},"Time":1649023818591,"Event":"OrderCanceled"}
1649023818.737196: {"Channel":"orderbook-eth","Nonce":19298,"Data":{"OrderType":"LimitBid","OrderGuid":"a3571bed-8ed4-4424-99e6-a4ed1457ba8d","Price":{"aud":4702.59,"usd":3523.34,"nzd":5091.99,"sgd":4795.63},"Volume":4.796},"Time":1649023818638,"Event":"NewOrder"}
1649023818.749929: {"Channel":"orderbook-matic","Nonce":5885,"Data":{"OrderType":"LimitOffer","OrderGuid":"bbd208d7-d470-40a1-a390-de8bedb93a61"},"Time":1649023818638,"Event":"OrderCanceled"}
1649023818.76103: {"Channel":"orderbook-eth","Nonce":19299,"Data":{"OrderType":"LimitBid","OrderGuid":"98521381-d75b-451a-8828-c74ab829b82d","Price":{"aud":4703.76,"usd":3506.18,"nzd":5062.18,"sgd":4767.26},"Volume":0.37545302},"Time":1649023818654,"Event":"NewOrder"}
1649023818.7665129: {"Channel":"orderbook-bch","Nonce":8265,"Data":{"OrderType":"LimitOffer","OrderGuid":"5498e6f8-c9f7-4d7a-9cbf-36d807aa7a84"},"Time":1649023818669,"Event":"OrderCanceled"}
1649023818.7941902: {"Channel":"orderbook-eth","Nonce":19300,"Data":{"OrderType":"LimitBid","OrderGuid":"1162513c-1672-4b71-869e-806c2f5ea829","Price":{"aud":4723.9,"usd":3521.19,"nzd":5083.86,"sgd":4787.67},"Volume":15.0},"Time":1649023818685,"Event":"NewOrder"}
1649023818.794333: {"Channel":"orderbook-eth","Nonce":19301,"Data":{"OrderType":"LimitOffer","OrderGuid":"f83785c9-595f-4d54-ba89-226e9f2e66dd","Price":{"aud":4737.1,"usd":3566.56,"nzd":5160.24,"sgd":4830.82},"Volume":15.0},"Time":1649023818685,"Event":"NewOrder"}
1649023818.796211: {"Channel":"orderbook-eth","Nonce":19302,"Data":{"OrderType":"LimitBid","OrderGuid":"da8719b3-5eb1-4cbd-9be6-88d7680116ad","Price":{"aud":4726.9,"usd":3523.43,"nzd":5087.08,"sgd":4790.71},"Volume":15.0},"Time":1649023818685,"Event":"NewOrder"}
1649023818.820231: {"Channel":"orderbook-matic","Nonce":5886,"Data":{"OrderType":"LimitOffer","OrderGuid":"c3aea261-0f37-4bf0-9990-c33aaa85a857","Price":{"aud":2.27192,"usd":1.71053,"nzd":2.47486,"sgd":2.31687},"Volume":5323.76633},"Time":1649023818716,"Event":"NewOrder"}
1649023818.834242: {"Channel":"orderbook-eth","Nonce":19303,"Data":{"OrderType":"LimitBid","OrderGuid":"0a9108c7-913e-47fd-95ec-f78937afb6f5"},"Time":1649023818732,"Event":"OrderCanceled"}
1649023818.8343208: {"Channel":"orderbook-eth","Nonce":19304,"Data":{"OrderType":"LimitOffer","OrderGuid":"be7f865a-b956-447d-bdd1-ce87ecbf42de"},"Time":1649023818732,"Event":"OrderCanceled"}
1649023818.854738: {"Channel":"orderbook-bch","Nonce":8266,"Data":{"OrderType":"LimitOffer","OrderGuid":"c901e65f-8982-4480-9481-275111006f2c","Price":{"aud":507.19,"usd":381.87,"nzd":552.5,"sgd":517.23},"Volume":1.09429089},"Time":1649023818747,"Event":"NewOrder"}
1649023818.872431: {"Channel":"orderbook-eth","Nonce":19305,"Data":{"OrderType":"LimitOffer","OrderGuid":"7233fabe-c115-4621-96ba-d40e3abef17b","Price":{"aud":4783.64,"usd":3583.32,"nzd":5148.15,"sgd":4848.52},"Volume":0.51823437},"Time":1649023818763,"Event":"NewOrder"}
1649023818.8948212: {"Channel":"orderbook-eth","Nonce":19306,"Data":{"OrderType":"LimitBid","OrderGuid":"1e92c94d-a358-41e6-9317-59c95b426a17","Price":{"aud":4678.08,"usd":3503.97,"nzd":5095.95,"sgd":4769.8},"Volume":0.54073896},"Time":1649023818794,"Event":"NewOrder"}
1649023818.897677: {"Channel":"orderbook-bch","Nonce":8267,"Data":{"OrderType":"LimitOffer","OrderGuid":"6fce2e54-7ea8-4a2f-bd4e-d6e078fd20a8","Price":{"aud":510.78,"usd":384.57,"nzd":556.41,"sgd":520.89},"Volume":39.74331},"Time":1649023818794,"Event":"NewOrder"}
1649023818.935443: {"Channel":"orderbook-eth","Nonce":19307,"Data":{"OrderType":"LimitBid","OrderGuid":"a028abbb-c2f0-46a8-afa7-7092ab4f13cc"},"Time":1649023818825,"Event":"OrderCanceled"}
1649023819.075103: {"Channel":"orderbook-dot","Nonce":4973,"Data":{"OrderType":"LimitOffer","OrderGuid":"1914ce79-c6a9-4bdd-91d7-2f2e0f58ea7d","Price":{"aud":31.3998,"usd":23.6409,"nzd":34.2046,"sgd":32.0211},"Volume":19.96241},"Time":1649023818966,"Event":"NewOrder"}
1649023819.154316: {"Channel":"orderbook-dot","Nonce":4974,"Data":{"OrderType":"LimitOffer","OrderGuid":"7673402f-d498-4c35-9e0b-44c87eb74d1f"},"Time":1649023819044,"Event":"OrderCanceled"}
1649023819.188273: {"Channel":"orderbook-eth","Nonce":19308,"Data":{"OrderType":"LimitOffer","OrderGuid":"7233fabe-c115-4621-96ba-d40e3abef17b"},"Time":1649023819075,"Event":"OrderCanceled"}
1649023819.240459: {"Channel":"orderbook-eth","Nonce":19309,"Data":{"OrderType":"LimitOffer","OrderGuid":"60fc6b1d-5878-4a08-948e-98c0a46ba3f4","Price":{"aud":4783.64,"usd":3583.32,"nzd":5148.15,"sgd":4848.52},"Volume":0.5655279},"Time":1649023819138,"Event":"NewOrder"}
1649023819.278275: {"Channel":"orderbook-eth","Nonce":19310,"Data":{"OrderType":"LimitOffer","OrderGuid":"2b86c705-6d62-405b-9b63-9a51e615fed2","Price":{"aud":4736.87,"usd":3566.39,"nzd":5159.99,"sgd":4830.59},"Volume":4.47331033},"Time":1649023819169,"Event":"NewOrder"}
1649023819.300715: {"Channel":"orderbook-pmgt","Nonce":436,"Data":{"OrderType":"LimitOffer","OrderGuid":"115f75f5-ca71-456c-a46f-93fcc737752e","Price":{"aud":2590.78,"usd":1950.6,"nzd":2822.21,"sgd":2642.04},"Volume":10.0},"Time":1649023819200,"Event":"NewOrder"}
1649023820.549566: {"Channel":"orderbook-eth","Nonce":19311,"Data":{"OrderType":"LimitBid","OrderGuid":"12bd1f5b-7d79-4e6f-b288-746669e8b4dc"},"Time":1649023819216,"Event":"OrderCanceled"}
1649023820.549655: {"Channel":"orderbook-pmgt","Nonce":437,"Data":{"OrderType":"LimitOffer","OrderGuid":"10ad95b4-59c0-4b97-a702-4df92bab0185"},"Time":1649023819232,"Event":"OrderCanceled"}
1649023820.549697: {"Channel":"orderbook-dot","Nonce":4975,"Data":{"OrderType":"LimitOffer","OrderGuid":"d1c27af3-21b7-4c75-99ba-6d16257b8695","Price":{"aud":31.3896,"usd":23.6332,"nzd":34.1935,"sgd":32.0107},"Volume":19.96241},"Time":1649023819247,"Event":"NewOrder"}
1649023820.549731: {"Channel":"orderbook-eth","Nonce":19312,"Data":{"OrderType":"LimitOffer","OrderGuid":"f83785c9-595f-4d54-ba89-226e9f2e66dd"},"Time":1649023819279,"Event":"OrderCanceled"}
1649023820.549759: {"Channel":"orderbook-pmgt","Nonce":438,"Data":{"OrderType":"LimitOffer","OrderGuid":"dcc9e852-0766-432e-ba0d-788a5a6a2e49","Price":{"aud":2594.58,"usd":1953.46,"nzd":2826.34,"sgd":2645.92},"Volume":3.0},"Time":1649023819279,"Event":"NewOrder"}
1649023820.54979: {"Channel":"orderbook-eth","Nonce":19313,"Data":{"OrderType":"LimitBid","OrderGuid":"da8719b3-5eb1-4cbd-9be6-88d7680116ad"},"Time":1649023819310,"Event":"OrderCanceled"}
1649023820.549815: {"Channel":"orderbook-pmgt","Nonce":439,"Data":{"OrderType":"LimitOffer","OrderGuid":"d7602257-9314-4556-ba71-2c80e7ef8aac"},"Time":1649023819310,"Event":"OrderCanceled"}
1649023820.549831: {"Channel":"orderbook-eth","Nonce":19314,"Data":{"OrderType":"LimitBid","OrderGuid":"965d109e-22e1-4a31-b8b7-7e51537f9022","Price":{"aud":4665.81,"usd":3477.89,"nzd":5021.34,"sgd":4728.79},"Volume":0.19523509},"Time":1649023819341,"Event":"NewOrder"}
1649023820.5498612: {"Channel":"orderbook-pmgt","Nonce":440,"Data":{"OrderType":"LimitOffer","OrderGuid":"63c7ad20-3b60-4cf7-84de-2f6b28c65ffb","Price":{"aud":2598.38,"usd":1956.32,"nzd":2830.48,"sgd":2649.79},"Volume":3.0},"Time":1649023819341,"Event":"NewOrder"}
1649023820.54989: {"Channel":"orderbook-eth","Nonce":19315,"Data":{"OrderType":"LimitBid","OrderGuid":"1162513c-1672-4b71-869e-806c2f5ea829"},"Time":1649023819372,"Event":"OrderCanceled"}
1649023820.5499148: {"Channel":"orderbook-pmgt","Nonce":441,"Data":{"OrderType":"LimitOffer","OrderGuid":"9029a4f8-efc5-4a08-a08b-6f06d3a4c3a2"},"Time":1649023819372,"Event":"OrderCanceled"}
1649023820.549931: {"Channel":"orderbook-eth","Nonce":19316,"Data":{"OrderType":"LimitOffer","OrderGuid":"331a536c-5cba-4963-a6c0-3d3996558479"},"Time":1649023819372,"Event":"OrderCanceled"}
1649023820.549954: {"Channel":"orderbook-pmgt","Nonce":442,"Data":{"OrderType":"LimitOffer","OrderGuid":"581457fd-6f3d-434f-b140-4c9e43947c34","Price":{"aud":2602.18,"usd":1959.18,"nzd":2834.62,"sgd":2653.67},"Volume":3.0},"Time":1649023819419,"Event":"NewOrder"}
1649023820.549982: {"Channel":"orderbook-eth","Nonce":19317,"Data":{"OrderType":"LimitOffer","OrderGuid":"017d7b0d-892f-4c7d-8468-fa443f70486b","Price":{"aud":4734.0,"usd":3564.23,"nzd":5156.87,"sgd":4827.66},"Volume":15.0},"Time":1649023819435,"Event":"NewOrder"}
1649023820.5500102: {"Channel":"orderbook-eth","Nonce":19318,"Data":{"OrderType":"LimitOffer","OrderGuid":"c184a194-bf1e-4b3b-8449-5781e195c429","Price":{"aud":4737.0,"usd":3566.49,"nzd":5160.14,"sgd":4830.72},"Volume":15.0},"Time":1649023819435,"Event":"NewOrder"}
1649023820.550037: {"Channel":"orderbook-pmgt","Nonce":443,"Data":{"OrderType":"LimitOffer","OrderGuid":"d6e51515-c27b-4d19-9dd2-ddadf4de9b8c"},"Time":1649023819450,"Event":"OrderCanceled"}
1649023820.550061: {"Channel":"orderbook-eth","Nonce":19319,"Data":{"OrderType":"LimitOffer","OrderGuid":"60fc6b1d-5878-4a08-948e-98c0a46ba3f4"},"Time":1649023819466,"Event":"OrderCanceled"}
1649023820.550085: {"Channel":"orderbook-eth","Nonce":19320,"Data":{"OrderType":"LimitOffer","OrderGuid":"83e8081f-f82f-43f7-ba1f-d1f88eb235e3","Price":{"aud":4754.97,"usd":3562.1,"nzd":5148.68,"sgd":4819.16},"Volume":4.135},"Time":1649023819466,"Event":"NewOrder"}
1649023820.550112: {"Channel":"orderbook-matic","Nonce":5887,"Data":{"OrderType":"LimitOffer","OrderGuid":"c3aea261-0f37-4bf0-9990-c33aaa85a857"},"Time":1649023819497,"Event":"OrderCanceled"}
1649023820.550137: {"Channel":"orderbook-eth","Nonce":19321,"Data":{"OrderType":"LimitOffer","OrderGuid":"89f2576b-1947-4ccf-a242-caaeb0741474"},"Time":1649023819497,"Event":"OrderCanceled"}
1649023820.5501618: {"Channel":"orderbook-pmgt","Nonce":444,"Data":{"OrderType":"LimitBid","OrderGuid":"74e05fb5-4455-4fc9-b0af-ff525782467a","Price":{"aud":2557.39,"usd":1906.27,"nzd":2752.26,"sgd":2591.91},"Volume":10.0},"Time":1649023819497,"Event":"NewOrder"}
1649023820.55019: {"Channel":"orderbook-eth","Nonce":19322,"Data":{"OrderType":"LimitOffer","OrderGuid":"4bfc2958-2656-48de-83a4-2913baeaaca1","Price":{"aud":4785.24,"usd":3584.52,"nzd":5149.87,"sgd":4850.14},"Volume":0.50076634},"Time":1649023819513,"Event":"NewOrder"}
1649023820.5502179: {"Channel":"orderbook-eth","Nonce":19323,"Data":{"OrderType":"LimitBid","OrderGuid":"0eca6075-96cd-45f1-9f6c-e9a48a63e57d","Price":{"aud":4726.8,"usd":3523.35,"nzd":5086.98,"sgd":4790.61},"Volume":15.0},"Time":1649023819529,"Event":"NewOrder"}
1649023820.550246: {"Channel":"orderbook-eth","Nonce":19324,"Data":{"OrderType":"LimitBid","OrderGuid":"bb746a03-6b06-44b6-be9c-6d3c41c2b314","Price":{"aud":4723.8,"usd":3521.12,"nzd":5083.75,"sgd":4787.57},"Volume":15.0},"Time":1649023819544,"Event":"NewOrder"}
1649023820.550273: {"Channel":"orderbook-pmgt","Nonce":445,"Data":{"OrderType":"LimitBid","OrderGuid":"0d2448c0-cfd3-4a1e-8e56-6dc6c976e4ff"},"Time":1649023819560,"Event":"OrderCanceled"}
1649023820.550296: {"Channel":"orderbook-eth","Nonce":19325,"Data":{"OrderType":"LimitOffer","OrderGuid":"6f5e7da0-4445-4333-bdb0-93973a9850e4","Price":{"aud":4795.07,"usd":3574.24,"nzd":5198.14,"sgd":4864.9},"Volume":0.50047478},"Time":1649023819575,"Event":"NewOrder"}
1649023820.550324: {"Channel":"orderbook-eth","Nonce":19326,"Data":{"OrderType":"LimitBid","OrderGuid":"ad853f17-7db7-4136-86d0-b56ad913381c"},"Time":1649023819575,"Event":"OrderCanceled"}
1649023820.550347: {"Channel":"orderbook-bch","Nonce":8268,"Data":{"OrderType":"LimitOffer","OrderGuid":"b783f577-7b5a-46ee-9b47-829cdd39a32d"},"Time":1649023819575,"Event":"OrderCanceled"}
1649023820.5503712: {"Channel":"orderbook-matic","Nonce":5888,"Data":{"OrderType":"LimitOffer","OrderGuid":"66d595bb-76e8-4eed-95e6-7d13a927975a","Price":{"aud":2.27249,"usd":1.71096,"nzd":2.47548,"sgd":2.31745},"Volume":5055.09664},"Time":1649023819575,"Event":"NewOrder"}
1649023820.550401: {"Channel":"orderbook-pmgt","Nonce":446,"Data":{"OrderType":"LimitBid","OrderGuid":"fd5f7e24-427a-4d5b-a444-b36e948c310e","Price":{"aud":2553.59,"usd":1903.44,"nzd":2748.17,"sgd":2588.06},"Volume":3.0},"Time":1649023819607,"Event":"NewOrder"}
1649023820.5504289: {"Channel":"orderbook-pmgt","Nonce":447,"Data":{"OrderType":"LimitBid","OrderGuid":"f7bc0acd-2dc8-4a12-9f93-7a342ab769fe"},"Time":1649023819638,"Event":"OrderCanceled"}
1649023820.550452: {"Channel":"orderbook-eth","Nonce":19327,"Data":{"OrderType":"LimitBid","OrderGuid":"98521381-d75b-451a-8828-c74ab829b82d"},"Time":1649023819638,"Event":"OrderCanceled"}
1649023820.550474: {"Channel":"orderbook-pmgt","Nonce":448,"Data":{"OrderType":"LimitBid","OrderGuid":"fdecec48-f73e-4f2d-94fc-31df63efe7ee","Price":{"aud":2549.79,"usd":1900.61,"nzd":2744.08,"sgd":2584.21},"Volume":3.0},"Time":1649023819685,"Event":"NewOrder"}
1649023820.5505002: {"Channel":"orderbook-eth","Nonce":19328,"Data":{"OrderType":"LimitBid","OrderGuid":"5311f541-ac34-4512-85a6-18bc0051e46a","Price":{"aud":4703.77,"usd":3506.19,"nzd":5062.19,"sgd":4767.27},"Volume":0.33682242},"Time":1649023819700,"Event":"NewOrder"}
1649023820.5505269: {"Channel":"orderbook-bch","Nonce":8269,"Data":{"OrderType":"LimitOffer","OrderGuid":"9c909661-ec3d-4d41-9036-f8f33c071ce3","Price":{"aud":507.77,"usd":382.3,"nzd":553.13,"sgd":517.82},"Volume":1.09301185},"Time":1649023819716,"Event":"NewOrder"}
1649023820.550554: {"Channel":"orderbook-pmgt","Nonce":449,"Data":{"OrderType":"LimitBid","OrderGuid":"2a918150-ffcf-430d-88f9-c07c42459212"},"Time":1649023819747,"Event":"OrderCanceled"}
1649023820.5505762: {"Channel":"orderbook-eth","Nonce":19329,"Data":{"OrderType":"LimitOffer","OrderGuid":"017d7b0d-892f-4c7d-8468-fa443f70486b"},"Time":1649023819827,"Event":"OrderCanceled"}
1649023820.5505989: {"Channel":"orderbook-eth","Nonce":19330,"Data":{"OrderType":"LimitOffer","OrderGuid":"c184a194-bf1e-4b3b-8449-5781e195c429"},"Time":1649023819842,"Event":"OrderCanceled"}
1649023820.550621: {"Channel":"orderbook-eth","Nonce":19331,"Data":{"OrderType":"LimitBid","OrderGuid":"0eca6075-96cd-45f1-9f6c-e9a48a63e57d"},"Time":1649023819858,"Event":"OrderCanceled"}
1649023820.550643: {"Channel":"orderbook-eth","Nonce":19332,"Data":{"OrderType":"LimitBid","OrderGuid":"1e92c94d-a358-41e6-9317-59c95b426a17"},"Time":1649023819858,"Event":"OrderCanceled"}
1649023820.550665: {"Channel":"orderbook-bch","Nonce":8270,"Data":{"OrderType":"LimitBid","OrderGuid":"ea9709fd-98eb-4af7-b83f-e80c208b39b6","Price":{"aud":493.75,"usd":368.04,"nzd":531.37,"sgd":500.41},"Volume":1.53021659},"Time":1649023819858,"Event":"NewOrder"}
1649023820.550695: {"Channel":"orderbook-eth","Nonce":19333,"Data":{"OrderType":"LimitBid","OrderGuid":"bb746a03-6b06-44b6-be9c-6d3c41c2b314"},"Time":1649023819874,"Event":"OrderCanceled"}
1649023820.550718: {"Channel":"orderbook-eth","Nonce":19334,"Data":{"OrderType":"LimitOffer","OrderGuid":"b62678a7-722b-4a41-887e-03017082db28","Price":{"aud":4734.7,"usd":3564.75,"nzd":5157.63,"sgd":4828.38},"Volume":15.0},"Time":1649023819889,"Event":"NewOrder"}
1649023820.550745: {"Channel":"orderbook-eth","Nonce":19335,"Data":{"OrderType":"LimitOffer","OrderGuid":"18a3da11-e6a1-415b-b13e-a1e876c076a1","Price":{"aud":4736.99,"usd":3566.48,"nzd":5160.12,"sgd":4830.71},"Volume":4.47331033},"Time":1649023819889,"Event":"NewOrder"}
1649023820.550772: {"Channel":"orderbook-eth","Nonce":19336,"Data":{"OrderType":"LimitOffer","OrderGuid":"2b86c705-6d62-405b-9b63-9a51e615fed2"},"Time":1649023819905,"Event":"OrderCanceled"}
1649023820.550795: {"Channel":"orderbook-eth","Nonce":19337,"Data":{"OrderType":"LimitOffer","OrderGuid":"24922ec5-0d39-4ec0-9b59-26697bfe4330","Price":{"aud":4737.7,"usd":3567.01,"nzd":5160.9,"sgd":4831.43},"Volume":15.0},"Time":1649023819905,"Event":"NewOrder"}
1649023820.550821: {"Channel":"orderbook-eth","Nonce":19338,"Data":{"OrderType":"LimitBid","OrderGuid":"02cf8c1b-20fc-4a35-abb2-41b7c4a609f7","Price":{"aud":4678.09,"usd":3503.98,"nzd":5095.96,"sgd":4769.81},"Volume":0.46864943},"Time":1649023819905,"Event":"NewOrder"}
1649023820.550848: {"Channel":"orderbook-eth","Nonce":19339,"Data":{"OrderType":"LimitBid","OrderGuid":"d52eb9f3-b4df-4461-b5f2-7610274d0abb","Price":{"aud":4724.5,"usd":3521.64,"nzd":5084.5,"sgd":4788.28},"Volume":15.0},"Time":1649023819920,"Event":"NewOrder"}
1649023820.550874: {"Channel":"orderbook-eth","Nonce":19340,"Data":{"OrderType":"LimitBid","OrderGuid":"c13c3f28-6c05-4474-89a4-dd2a002ca69f","Price":{"aud":4665.82,"usd":3477.9,"nzd":5021.35,"sgd":4728.8},"Volume":0.19523509},"Time":1649023819920,"Event":"NewOrder"}
1649023820.5509: {"Channel":"orderbook-bch","Nonce":8271,"Data":{"OrderType":"LimitOffer","OrderGuid":"c901e65f-8982-4480-9481-275111006f2c"},"Time":1649023819952,"Event":"OrderCanceled"}
1649023820.550924: {"Channel":"orderbook-eth","Nonce":19341,"Data":{"OrderType":"LimitOffer","OrderGuid":"18a3da11-e6a1-415b-b13e-a1e876c076a1"},"Time":1649023819999,"Event":"OrderCanceled"}
1649023820.550946: {"Channel":"orderbook-dot","Nonce":4976,"Data":{"OrderType":"LimitOffer","OrderGuid":"1914ce79-c6a9-4bdd-91d7-2f2e0f58ea7d"},"Time":1649023820016,"Event":"OrderCanceled"}
1649023820.5509682: {"Channel":"orderbook-bch","Nonce":8272,"Data":{"OrderType":"LimitBid","OrderGuid":"a129163e-30be-4815-bd00-16e011bce152"},"Time":1649023820018,"Event":"OrderCanceled"}
1649023820.55099: {"Channel":"orderbook-eth","Nonce":19342,"Data":{"OrderType":"LimitBid","OrderGuid":"7691e691-2c8a-4e90-a720-7a75b3a41a78","Price":{"aud":4727.5,"usd":3523.87,"nzd":5087.73,"sgd":4791.32},"Volume":15.0},"Time":1649023820018,"Event":"NewOrder"}
1649023820.5510159: {"Channel":"orderbook-eth","Nonce":19343,"Data":{"OrderType":"LimitOffer","OrderGuid":"bdba2cc0-677c-440d-98c1-2bcb2f990dc4"},"Time":1649023820033,"Event":"OrderCanceled"}
1649023820.551038: {"Channel":"orderbook-bch","Nonce":8273,"Data":{"OrderType":"LimitOffer","OrderGuid":"1b3acfc2-a031-4581-91df-d4ef9e09d358"},"Time":1649023820033,"Event":"OrderCanceled"}
1649023820.55106: {"Channel":"orderbook-eth","Nonce":19344,"Data":{"OrderType":"LimitOffer","OrderGuid":"8e863664-4b77-4d25-9a56-d7859740de92","Price":{"aud":4760.85,"usd":3566.51,"nzd":5155.05,"sgd":4825.12},"Volume":1.13636356},"Time":1649023820082,"Event":"NewOrder"}
1649023820.5510871: {"Channel":"orderbook-eth","Nonce":19345,"Data":{"OrderType":"LimitOffer","OrderGuid":"6f5e7da0-4445-4333-bdb0-93973a9850e4"},"Time":1649023820097,"Event":"OrderCanceled"}
1649023820.5511098: {"Channel":"orderbook-eth","Nonce":19346,"Data":{"OrderType":"LimitOffer","OrderGuid":"24922ec5-0d39-4ec0-9b59-26697bfe4330"},"Time":1649023820097,"Event":"OrderCanceled"}
1649023820.5511308: {"Channel":"orderbook-eth","Nonce":19347,"Data":{"OrderType":"LimitBid","OrderGuid":"7691e691-2c8a-4e90-a720-7a75b3a41a78"},"Time":1649023820097,"Event":"OrderCanceled"}
1649023820.5511522: {"Channel":"orderbook-matic","Nonce":5889,"Data":{"OrderType":"LimitBid","OrderGuid":"3e9a5a09-0061-4e53-accf-6e8408568ee0"},"Time":1649023820097,"Event":"OrderCanceled"}
1649023820.5511749: {"Channel":"orderbook-eth","Nonce":19348,"Data":{"OrderType":"LimitBid","OrderGuid":"97249c34-46b9-4395-8095-91d820a9698e"},"Time":1649023820128,"Event":"OrderCanceled"}
1649023820.551198: {"Channel":"orderbook-dot","Nonce":4977,"Data":{"OrderType":"LimitBid","OrderGuid":"95259bd6-2186-488c-b593-727f94ec7eae","Price":{"aud":30.7996,"usd":22.958,"nzd":33.1465,"sgd":31.2153},"Volume":24.76409},"Time":1649023820128,"Event":"NewOrder"}
1649023820.5512261: {"Channel":"orderbook-eth","Nonce":19349,"Data":{"OrderType":"LimitOffer","OrderGuid":"5c758334-e874-4a56-bd51-faffc5ceb056","Price":{"aud":4795.85,"usd":3574.82,"nzd":5198.99,"sgd":4865.69},"Volume":0.54893091},"Time":1649023820144,"Event":"NewOrder"}
1649023820.551253: {"Channel":"orderbook-bch","Nonce":8274,"Data":{"OrderType":"LimitBid","OrderGuid":"cabf0695-fa5f-405e-97b2-29e5fcdd388e","Price":{"aud":497.82,"usd":371.07,"nzd":535.75,"sgd":504.54},"Volume":1.53021659},"Time":1649023820160,"Event":"NewOrder"}
1649023820.551279: {"Channel":"orderbook-bch","Nonce":8275,"Data":{"OrderType":"LimitOffer","OrderGuid":"acf2f4b5-51a3-4a76-8a56-bd5f0f15f5f7","Price":{"aud":510.77,"usd":384.56,"nzd":556.4,"sgd":520.88},"Volume":2.93},"Time":1649023820175,"Event":"NewOrder"}
1649023820.551305: {"Channel":"orderbook-eth","Nonce":19350,"Data":{"OrderType":"LimitBid","OrderGuid":"05d1ba0e-a47f-4a9a-8f94-aad06a5ce25a","Price":{"aud":4699.91,"usd":3521.34,"nzd":5089.1,"sgd":4792.9},"Volume":3.14627999},"Time":1649023820175,"Event":"NewOrder"}
1649023820.551331: {"Channel":"orderbook-eth","Nonce":19351,"Data":{"OrderType":"LimitOffer","OrderGuid":"b62678a7-722b-4a41-887e-03017082db28"},"Time":1649023820191,"Event":"OrderCanceled"}
1649023820.5513542: {"Channel":"orderbook-eth","Nonce":19352,"Data":{"OrderType":"LimitBid","OrderGuid":"d52eb9f3-b4df-4461-b5f2-7610274d0abb"},"Time":1649023820191,"Event":"OrderCanceled"}
1649023820.5513752: {"Channel":"orderbook-eth","Nonce":19353,"Data":{"OrderType":"LimitBid","OrderGuid":"5311f541-ac34-4512-85a6-18bc0051e46a"},"Time":1649023820207,"Event":"OrderCanceled"}
1649023820.551397: {"Channel":"orderbook-dot","Nonce":4978,"Data":{"OrderType":"LimitBid","OrderGuid":"2d3ac644-1e66-4a97-951c-44cedf4ce222"},"Time":1649023820207,"Event":"OrderCanceled"}
1649023820.551418: {"Channel":"orderbook-matic","Nonce":5890,"Data":{"OrderType":"LimitBid","OrderGuid":"8a1f3514-1436-4de4-a7f6-87db75ef5036"},"Time":1649023820207,"Event":"OrderCanceled"}
1649023820.5514398: {"Channel":"orderbook-bch","Nonce":8276,"Data":{"OrderType":"LimitOffer","OrderGuid":"eae718c2-a477-4255-bfe8-27325fdc9f5a","Price":{"aud":510.77,"usd":384.56,"nzd":556.4,"sgd":520.88},"Volume":21.20858658},"Time":1649023820207,"Event":"NewOrder"}
1649023820.5514681: {"Channel":"orderbook-bch","Nonce":8277,"Data":{"OrderType":"LimitOffer","OrderGuid":"8c614446-8f9f-4e78-ad03-ecab60629649"},"Time":1649023820222,"Event":"OrderCanceled"}
1649023820.55149: {"Channel":"orderbook-eth","Nonce":19354,"Data":{"OrderType":"LimitOffer","OrderGuid":"a5a020cb-1897-4aaf-a690-a4c4364de33d","Price":{"aud":4738.55,"usd":3567.65,"nzd":5161.82,"sgd":4832.3},"Volume":4.47331033},"Time":1649023820222,"Event":"NewOrder"}
1649023820.551517: {"Channel":"orderbook-matic","Nonce":5891,"Data":{"OrderType":"LimitOffer","OrderGuid":"66d595bb-76e8-4eed-95e6-7d13a927975a"},"Time":1649023820222,"Event":"OrderCanceled"}
1649023820.55154: {"Channel":"orderbook-eth","Nonce":19355,"Data":{"OrderType":"LimitBid","OrderGuid":"8c1b9361-37a9-4014-88f4-6aa718c8974c","Price":{"aud":4727.6,"usd":3523.95,"nzd":5087.84,"sgd":4791.42},"Volume":15.0},"Time":1649023820238,"Event":"NewOrder"}
1649023820.5515661: {"Channel":"orderbook-matic","Nonce":5892,"Data":{"OrderType":"LimitBid","OrderGuid":"3df48d66-5603-46aa-8b6e-eed4db773efd","Price":{"aud":2.2605,"usd":1.68497,"nzd":2.43275,"sgd":2.29101},"Volume":5583.0},"Time":1649023820254,"Event":"NewOrder"}
1649023820.551593: {"Channel":"orderbook-matic","Nonce":5893,"Data":{"OrderType":"LimitBid","OrderGuid":"21db0ee9-7d36-4b52-a3cc-8821b75a3bd9","Price":{"aud":2.262,"usd":1.68609,"nzd":2.43436,"sgd":2.29253},"Volume":5583.0},"Time":1649023820254,"Event":"NewOrder"}
1649023820.55162: {"Channel":"orderbook-eth","Nonce":19356,"Data":{"OrderType":"LimitBid","OrderGuid":"c4b16a4b-a422-4357-b86f-6688676560ff","Price":{"aud":4721.33,"usd":3519.27,"nzd":5081.09,"sgd":4785.06},"Volume":0.35153326},"Time":1649023820254,"Event":"NewOrder"}
1649023820.551646: {"Channel":"orderbook-eth","Nonce":19357,"Data":{"OrderType":"LimitBid","OrderGuid":"5523a2a8-fd78-4a37-91b5-8a90ba6e1dba","Price":{"aud":4727.61,"usd":3523.96,"nzd":5087.85,"sgd":4791.43},"Volume":14.14},"Time":1649023820269,"Event":"NewOrder"}
1649023820.551672: {"Channel":"orderbook-eth","Nonce":19358,"Data":{"OrderType":"LimitBid","OrderGuid":"5beeb649-77c4-4149-9a13-f5bb239b5f4e"},"Time":1649023820285,"Event":"OrderCanceled"}
1649023820.551695: {"Channel":"orderbook-matic","Nonce":5894,"Data":{"OrderType":"LimitOffer","OrderGuid":"0cddda9f-bb4a-4ebf-afc8-c512d2e62128","Price":{"aud":2.27399,"usd":1.71209,"nzd":2.47712,"sgd":2.31898},"Volume":5995.80913},"Time":1649023820300,"Event":"NewOrder"}
1649023820.551722: {"Channel":"orderbook-eth","Nonce":19359,"Data":{"OrderType":"LimitOffer","OrderGuid":"cf264a75-5993-494b-ba7e-c7545e4d40ed","Price":{"aud":4737.8,"usd":3567.09,"nzd":5161.01,"sgd":4831.54},"Volume":15.0},"Time":1649023820347,"Event":"NewOrder"}
1649023820.551748: {"Channel":"orderbook-eth","Nonce":19360,"Data":{"OrderType":"LimitBid","OrderGuid":"71e51340-460c-4d16-958a-168101cfbf04","Price":{"aud":4724.6,"usd":3521.71,"nzd":5084.61,"sgd":4788.38},"Volume":15.0},"Time":1649023820347,"Event":"NewOrder"}
1649023820.551774: {"Channel":"orderbook-matic","Nonce":5895,"Data":{"OrderType":"LimitOffer","OrderGuid":"0cddda9f-bb4a-4ebf-afc8-c512d2e62128"},"Time":1649023820363,"Event":"OrderCanceled"}
1649023820.551797: {"Channel":"orderbook-eth","Nonce":19361,"Data":{"OrderType":"LimitBid","OrderGuid":"965d109e-22e1-4a31-b8b7-7e51537f9022"},"Time":1649023820378,"Event":"OrderCanceled"}
1649023820.551819: {"Channel":"orderbook-matic","Nonce":5896,"Data":{"OrderType":"LimitOffer","OrderGuid":"1a4d4d2e-80df-4142-9579-2f7a90f6ee52"},"Time":1649023820410,"Event":"OrderCanceled"}
1649023820.551842: {"Channel":"orderbook-bch","Nonce":8278,"Data":{"OrderType":"LimitBid","OrderGuid":"c7f332af-c6da-4a1e-b405-abb118948b83"},"Time":1649023820410,"Event":"OrderCanceled"}
1649023820.5518641: {"Channel":"orderbook-matic","Nonce":5897,"Data":{"OrderType":"LimitOffer","OrderGuid":"9c391355-7f6f-4629-843a-0d134b8b2261"},"Time":1649023820410,"Event":"OrderCanceled"}
1649023820.551886: {"Channel":"orderbook-bch","Nonce":8279,"Data":{"OrderType":"LimitBid","OrderGuid":"86d14e50-1dd1-45a8-9d7b-7b258acb9a07"},"Time":1649023820410,"Event":"OrderCanceled"}
1649023820.551907: {"Channel":"orderbook-matic","Nonce":5898,"Data":{"OrderType":"LimitOffer","OrderGuid":"e76fe70c-5acb-498d-be3a-895b3b5d8342","Price":{"aud":2.27399,"usd":1.71209,"nzd":2.47712,"sgd":2.31898},"Volume":5100.97296},"Time":1649023820410,"Event":"NewOrder"}
1649023820.551935: {"Channel":"orderbook-dot","Nonce":4979,"Data":{"OrderType":"LimitBid","OrderGuid":"0e4068fd-cb9b-49f1-a6f8-005d4bbb5e76"},"Time":1649023820425,"Event":"OrderCanceled"}
1649023820.5525582: {"Channel":"orderbook-eth","Nonce":19362,"Data":{"OrderType":"LimitOffer","OrderGuid":"cf264a75-5993-494b-ba7e-c7545e4d40ed"},"Time":1649023820441,"Event":"OrderCanceled"}
1649023820.571672: {"Channel":"orderbook-matic","Nonce":5899,"Data":{"OrderType":"LimitOffer","OrderGuid":"e76fe70c-5acb-498d-be3a-895b3b5d8342"},"Time":1649023820472,"Event":"OrderCanceled"}
1649023820.571777: {"Channel":"orderbook-matic","Nonce":5900,"Data":{"OrderType":"LimitOffer","OrderGuid":"2fe1a346-51c6-4e04-a3bf-c6feafccfc7b","Price":{"aud":2.2745,"usd":1.71247,"nzd":2.47767,"sgd":2.3195},"Volume":5583.0},"Time":1649023820472,"Event":"NewOrder"}
1649023820.593808: {"Channel":"orderbook-eth","Nonce":19363,"Data":{"OrderType":"LimitBid","OrderGuid":"8c1b9361-37a9-4014-88f4-6aa718c8974c"},"Time":1649023820488,"Event":"OrderCanceled"}
1649023820.6011388: {"Channel":"orderbook-dot","Nonce":4980,"Data":{"OrderType":"LimitOffer","OrderGuid":"2d5bdd00-9192-4f4f-ba16-dad561f844e5"},"Time":1649023820503,"Event":"OrderCanceled"}
1649023820.601245: {"Channel":"orderbook-bch","Nonce":8280,"Data":{"OrderType":"LimitOffer","OrderGuid":"a750ff4f-a17d-4788-a9f5-f1548d8c4027"},"Time":1649023820503,"Event":"OrderCanceled"}
1649023820.612759: {"Channel":"orderbook-bch","Nonce":8281,"Data":{"OrderType":"LimitOffer","OrderGuid":"af494809-9769-4fc4-9aab-c544198bf835"},"Time":1649023820503,"Event":"OrderCanceled"}
1649023820.613309: {"Channel":"orderbook-matic","Nonce":5901,"Data":{"OrderType":"LimitOffer","OrderGuid":"5fa47d29-2750-475a-a6da-e09ef8d90d51","Price":{"aud":2.27248,"usd":1.71095,"nzd":2.47547,"sgd":2.31744},"Volume":5628.85749},"Time":1649023820503,"Event":"NewOrder"}
1649023820.6653461: {"Channel":"orderbook-matic","Nonce":5902,"Data":{"OrderType":"LimitOffer","OrderGuid":"e4c3efd6-3ddd-483a-bed5-c6451548e229","Price":{"aud":2.273,"usd":1.71134,"nzd":2.47604,"sgd":2.31797},"Volume":5583.0},"Time":1649023820566,"Event":"NewOrder"}
1649023820.6808572: {"Channel":"orderbook-eth","Nonce":19364,"Data":{"OrderType":"LimitOffer","OrderGuid":"46653d16-2429-49bb-942a-dca47b02b3e8","Price":{"aud":4735.8,"usd":3565.58,"nzd":5158.83,"sgd":4829.5},"Volume":15.0},"Time":1649023820582,"Event":"NewOrder"}
1649023820.685063: {"Channel":"orderbook-eth","Nonce":19365,"Data":{"OrderType":"LimitOffer","OrderGuid":"a469acca-01da-4f68-9915-d4e6579aadbd","Price":{"aud":4738.8,"usd":3567.84,"nzd":5162.1,"sgd":4832.56},"Volume":15.0},"Time":1649023820582,"Event":"NewOrder"}
1649023820.69052: {"Channel":"orderbook-eth","Nonce":19366,"Data":{"OrderType":"LimitBid","OrderGuid":"71e51340-460c-4d16-958a-168101cfbf04"},"Time":1649023820582,"Event":"OrderCanceled"}
1649023820.702415: {"Channel":"orderbook-dot","Nonce":4981,"Data":{"OrderType":"LimitOffer","OrderGuid":"eab84159-618b-4ff5-bd66-56ea3de948ac"},"Time":1649023820597,"Event":"OrderCanceled"}
1649023820.710967: {"Channel":"orderbook-bch","Nonce":8282,"Data":{"OrderType":"LimitBid","OrderGuid":"db359962-0071-4aa7-86bd-4e42417d7c06","Price":{"aud":504.1,"usd":375.75,"nzd":542.51,"sgd":510.9},"Volume":6.0},"Time":1649023820613,"Event":"NewOrder"}
1649023820.717327: {"Channel":"orderbook-bch","Nonce":8283,"Data":{"OrderType":"LimitBid","OrderGuid":"530dc2e6-f9b3-4275-8eb3-ed5fbd99cc43","Price":{"aud":503.4,"usd":375.23,"nzd":541.75,"sgd":510.19},"Volume":6.0},"Time":1649023820613,"Event":"NewOrder"}
1649023820.717845: {"Channel":"orderbook-bch","Nonce":8284,"Data":{"OrderType":"LimitOffer","OrderGuid":"04ec1964-d5b3-4e83-85f5-29f7c6370e81","Price":{"aud":506.9,"usd":381.65,"nzd":552.18,"sgd":516.93},"Volume":6.0},"Time":1649023820613,"Event":"NewOrder"}
1649023820.731454: {"Channel":"orderbook-bch","Nonce":8285,"Data":{"OrderType":"LimitOffer","OrderGuid":"b28108fd-b791-4be4-9eff-559df103ee3a","Price":{"aud":507.6,"usd":382.18,"nzd":552.95,"sgd":517.65},"Volume":6.0},"Time":1649023820629,"Event":"NewOrder"}
1649023820.741164: {"Channel":"orderbook-eth","Nonce":19367,"Data":{"OrderType":"LimitBid","OrderGuid":"c229c8ab-c83d-4bd6-b871-2f8ad95ee5f9","Price":{"aud":4725.6,"usd":3522.46,"nzd":5085.69,"sgd":4789.39},"Volume":15.0},"Time":1649023820644,"Event":"NewOrder"}
1649023820.810548: {"Channel":"orderbook-dot","Nonce":4982,"Data":{"OrderType":"LimitBid","OrderGuid":"bc58af76-aa5b-4fa1-a756-0e076a7840bc"},"Time":1649023820707,"Event":"OrderCanceled"}
1649023820.8111: {"Channel":"orderbook-dot","Nonce":4983,"Data":{"OrderType":"LimitOffer","OrderGuid":"ed815b0e-128a-439b-9d34-1923d50563c0","Price":{"aud":31.4,"usd":23.6411,"nzd":34.2048,"sgd":32.0213},"Volume":80.0},"Time":1649023820707,"Event":"NewOrder"}
1649023820.8168871: {"Channel":"orderbook-dot","Nonce":4984,"Data":{"OrderType":"LimitOffer","OrderGuid":"9bf82d15-45ab-4f77-86aa-20341795cd0e","Price":{"aud":31.44,"usd":23.6712,"nzd":34.2484,"sgd":32.0621},"Volume":80.0},"Time":1649023820707,"Event":"NewOrder"}
1649023820.817583: {"Channel":"orderbook-dot","Nonce":4985,"Data":{"OrderType":"LimitBid","OrderGuid":"ca34e78f-243c-4b66-ab2f-c34053448572","Price":{"aud":30.801,"usd":22.959,"nzd":33.148,"sgd":31.2168},"Volume":24.76409},"Time":1649023820722,"Event":"NewOrder"}
1649023820.834471: {"Channel":"orderbook-eth","Nonce":19368,"Data":{"OrderType":"LimitOffer","OrderGuid":"a469acca-01da-4f68-9915-d4e6579aadbd"},"Time":1649023820722,"Event":"OrderCanceled"}
1649023820.837635: {"Channel":"orderbook-eth","Nonce":19369,"Data":{"OrderType":"LimitBid","OrderGuid":"c229c8ab-c83d-4bd6-b871-2f8ad95ee5f9"},"Time":1649023820738,"Event":"OrderCanceled"}
1649023820.838151: {"Channel":"orderbook-eth","Nonce":19370,"Data":{"OrderType":"LimitOffer","OrderGuid":"46653d16-2429-49bb-942a-dca47b02b3e8"},"Time":1649023820738,"Event":"OrderCanceled"}
1649023820.846256: {"Channel":"orderbook-dot","Nonce":4986,"Data":{"OrderType":"LimitBid","OrderGuid":"83fb9a15-8656-4cdd-ac67-2abbe083056a","Price":{"aud":31.16,"usd":23.2266,"nzd":33.5343,"sgd":31.5806},"Volume":80.0},"Time":1649023820738,"Event":"NewOrder"}
1649023820.848563: {"Channel":"orderbook-dot","Nonce":4987,"Data":{"OrderType":"LimitBid","OrderGuid":"933cb3b7-0408-40f9-aa4b-e076191f58e2","Price":{"aud":30.8027,"usd":22.9603,"nzd":33.1498,"sgd":31.2185},"Volume":457.6},"Time":1649023820738,"Event":"NewOrder"}
1649023820.851209: {"Channel":"orderbook-dot","Nonce":4988,"Data":{"OrderType":"LimitBid","OrderGuid":"999c80dc-70e9-44cc-b8c6-25e5cb1fcd65","Price":{"aud":31.2,"usd":23.2564,"nzd":33.5774,"sgd":31.6212},"Volume":80.0},"Time":1649023820754,"Event":"NewOrder"}
1649023820.851707: {"Channel":"orderbook-dot","Nonce":4989,"Data":{"OrderType":"LimitBid","OrderGuid":"15bcd9f0-0399-4c9f-a823-1209eb415457"},"Time":1649023820754,"Event":"OrderCanceled"}
1649023820.872816: {"Channel":"orderbook-eth","Nonce":19371,"Data":{"OrderType":"LimitBid","OrderGuid":"a23168f8-e914-4ccf-84df-49692ca9d994","Price":{"aud":4728.8,"usd":3524.84,"nzd":5089.13,"sgd":4792.63},"Volume":15.0},"Time":1649023820769,"Event":"NewOrder"}
1649023820.873336: {"Channel":"orderbook-matic","Nonce":5903,"Data":{"OrderType":"LimitBid","OrderGuid":"02c34d70-918b-4c78-9f8c-4c7440347294"},"Time":1649023820769,"Event":"OrderCanceled"}
1649023820.8738172: {"Channel":"orderbook-matic","Nonce":5904,"Data":{"OrderType":"LimitOffer","OrderGuid":"5fa47d29-2750-475a-a6da-e09ef8d90d51"},"Time":1649023820769,"Event":"OrderCanceled"}
1649023820.8775182: {"Channel":"orderbook-eth","Nonce":19372,"Data":{"OrderType":"LimitOffer","OrderGuid":"0cca0778-a904-4159-a87a-92c586814d62","Price":{"aud":4736.0,"usd":3565.73,"nzd":5159.05,"sgd":4829.7},"Volume":15.0},"Time":1649023820769,"Event":"NewOrder"}
1649023820.8850482: {"Channel":"orderbook-eth","Nonce":19373,"Data":{"OrderType":"LimitOffer","OrderGuid":"cdd02b27-810b-4104-8546-19c6a549869b","Price":{"aud":4739.0,"usd":3567.99,"nzd":5162.31,"sgd":4832.76},"Volume":15.0},"Time":1649023820785,"Event":"NewOrder"}
1649023820.963634: {"Channel":"orderbook-matic","Nonce":5905,"Data":{"OrderType":"LimitBid","OrderGuid":"1f9abd74-948a-4c77-a97d-2fcd46458d77","Price":{"aud":2.26201,"usd":1.6861,"nzd":2.43437,"sgd":2.29254},"Volume":5123.33674},"Time":1649023820863,"Event":"NewOrder"}
1649023820.9806988: {"Channel":"orderbook-matic","Nonce":5906,"Data":{"OrderType":"LimitOffer","OrderGuid":"480b8f0f-8904-4300-84bb-62b910a1c0f0","Price":{"aud":2.27247,"usd":1.71094,"nzd":2.47546,"sgd":2.31743},"Volume":5365.79256},"Time":1649023820878,"Event":"NewOrder"}
1649023820.995487: {"Channel":"orderbook-eth","Nonce":19374,"Data":{"OrderType":"LimitBid","OrderGuid":"0adef420-392e-4f66-8054-6cd9e448e812","Price":{"aud":4725.8,"usd":3522.61,"nzd":5085.9,"sgd":4789.59},"Volume":15.0},"Time":1649023820894,"Event":"NewOrder"}
1649023821.0139341: {"Channel":"orderbook-eth","Nonce":19375,"Data":{"OrderType":"LimitBid","OrderGuid":"02cf8c1b-20fc-4a35-abb2-41b7c4a609f7"},"Time":1649023820910,"Event":"OrderCanceled"}
1649023821.0140438: {"Channel":"orderbook-eth","Nonce":19376,"Data":{"OrderType":"LimitBid","OrderGuid":"a23168f8-e914-4ccf-84df-49692ca9d994"},"Time":1649023820910,"Event":"OrderCanceled"}
1649023821.014099: {"Channel":"orderbook-eth","Nonce":19377,"Data":{"OrderType":"LimitOffer","OrderGuid":"cdd02b27-810b-4104-8546-19c6a549869b"},"Time":1649023820910,"Event":"OrderCanceled"}
1649023821.044429: {"Channel":"orderbook-bch","Nonce":8286,"Data":{"OrderType":"LimitBid","OrderGuid":"ea9709fd-98eb-4af7-b83f-e80c208b39b6"},"Time":1649023820941,"Event":"OrderCanceled"}
1649023821.058004: {"Channel":"orderbook-eth","Nonce":19378,"Data":{"OrderType":"LimitBid","OrderGuid":"e2d639b6-68ad-4745-a8f9-094a5a43175c","Price":{"aud":4678.1,"usd":3503.98,"nzd":5095.97,"sgd":4769.82},"Volume":0.56971406},"Time":1649023820957,"Event":"NewOrder"}
1649023821.146466: {"Channel":"orderbook-eth","Nonce":19379,"Data":{"OrderType":"LimitBid","OrderGuid":"0adef420-392e-4f66-8054-6cd9e448e812"},"Time":1649023821035,"Event":"OrderCanceled"}
1649023821.149643: {"Channel":"orderbook-eth","Nonce":19380,"Data":{"OrderType":"LimitBid","OrderGuid":"ad594b4d-d975-41e4-8d16-c464f081860c","Price":{"aud":4703.94,"usd":3524.36,"nzd":5093.46,"sgd":4797.01},"Volume":4.208},"Time":1649023821051,"Event":"NewOrder"}
1649023821.20454: {"Channel":"orderbook-bch","Nonce":8287,"Data":{"OrderType":"LimitOffer","OrderGuid":"9f3eefab-6148-4ac4-a643-8560e13d3e36","Price":{"aud":507.68,"usd":382.24,"nzd":553.03,"sgd":517.73},"Volume":1.09301185},"Time":1649023821098,"Event":"NewOrder"}
1649023821.239358: {"Channel":"orderbook-eth","Nonce":19381,"Data":{"OrderType":"LimitBid","OrderGuid":"93de8108-9a84-4589-84ef-a38614540913","Price":{"aud":4728.3,"usd":3524.47,"nzd":5088.59,"sgd":4792.13},"Volume":15.0},"Time":1649023821129,"Event":"NewOrder"}
1649023821.24365: {"Channel":"orderbook-eth","Nonce":19382,"Data":{"OrderType":"LimitBid","OrderGuid":"d29ec2ce-5cbe-450e-8859-904a99259954","Price":{"aud":4725.3,"usd":3522.23,"nzd":5085.36,"sgd":4789.09},"Volume":15.0},"Time":1649023821145,"Event":"NewOrder"}
1649023821.2865732: {"Channel":"orderbook-eth","Nonce":19383,"Data":{"OrderType":"LimitOffer","OrderGuid":"0cca0778-a904-4159-a87a-92c586814d62"},"Time":1649023821176,"Event":"OrderCanceled"}
1649023821.330676: {"Channel":"orderbook-dot","Nonce":4990,"Data":{"OrderType":"LimitBid","OrderGuid":"95259bd6-2186-488c-b593-727f94ec7eae"},"Time":1649023821223,"Event":"OrderCanceled"}
1649023821.343348: {"Channel":"orderbook-eth","Nonce":19384,"Data":{"OrderType":"LimitOffer","OrderGuid":"8d82b9b7-687f-4ec4-8b21-7ab9fe16a5c7","Price":{"aud":4735.5,"usd":3565.36,"nzd":5158.5,"sgd":4829.19},"Volume":15.0},"Time":1649023821239,"Event":"NewOrder"}
1649023821.346825: {"Channel":"orderbook-eth","Nonce":19385,"Data":{"OrderType":"LimitOffer","OrderGuid":"f106d05f-66ac-4d22-977b-8987ea3264bb","Price":{"aud":4738.5,"usd":3567.62,"nzd":5161.77,"sgd":4832.25},"Volume":15.0},"Time":1649023821239,"Event":"NewOrder"}
1649023821.346957: {"Channel":"orderbook-eth","Nonce":19386,"Data":{"OrderType":"LimitOffer","OrderGuid":"cd0f68c7-0aba-419c-8b96-cdea7053e889","Price":{"aud":4742.37,"usd":3570.53,"nzd":5165.99,"sgd":4836.2},"Volume":4.47331033},"Time":1649023821239,"Event":"NewOrder"}
1649023821.353502: {"Channel":"orderbook-eth","Nonce":19387,"Data":{"OrderType":"LimitOffer","OrderGuid":"a5a020cb-1897-4aaf-a690-a4c4364de33d"},"Time":1649023821254,"Event":"OrderCanceled"}
1649023821.381323: {"Channel":"orderbook-bch","Nonce":8288,"Data":{"OrderType":"LimitBid","OrderGuid":"08124eac-0710-46c9-b93a-099b74c35c95","Price":{"aud":497.83,"usd":371.08,"nzd":535.76,"sgd":504.55},"Volume":1.53021659},"Time":1649023821270,"Event":"NewOrder"}
1649023821.506567: {"Channel":"orderbook-bch","Nonce":8289,"Data":{"OrderType":"LimitOffer","OrderGuid":"9c909661-ec3d-4d41-9036-f8f33c071ce3"},"Time":1649023821396,"Event":"OrderCanceled"}
1649023821.5066729: {"Channel":"orderbook-bch","Nonce":8290,"Data":{"OrderType":"LimitOffer","OrderGuid":"6fce2e54-7ea8-4a2f-bd4e-d6e078fd20a8"},"Time":1649023821396,"Event":"OrderCanceled"}
1649023821.538733: {"Channel":"orderbook-eth","Nonce":19388,"Data":{"OrderType":"LimitOffer","OrderGuid":"8d82b9b7-687f-4ec4-8b21-7ab9fe16a5c7"},"Time":1649023821427,"Event":"OrderCanceled"}
1649023821.538839: {"Channel":"orderbook-eth","Nonce":19389,"Data":{"OrderType":"LimitBid","OrderGuid":"93de8108-9a84-4589-84ef-a38614540913"},"Time":1649023821427,"Event":"OrderCanceled"}
1649023821.541526: {"Channel":"orderbook-eth","Nonce":19390,"Data":{"OrderType":"LimitBid","OrderGuid":"d29ec2ce-5cbe-450e-8859-904a99259954"},"Time":1649023821442,"Event":"OrderCanceled"}
1649023821.5450282: {"Channel":"orderbook-eth","Nonce":19391,"Data":{"OrderType":"LimitOffer","OrderGuid":"f106d05f-66ac-4d22-977b-8987ea3264bb"},"Time":1649023821442,"Event":"OrderCanceled"}
1649023821.5454679: {"Channel":"orderbook-eth","Nonce":19392,"Data":{"OrderType":"LimitBid","OrderGuid":"f966e06a-3eb2-4313-bbcf-0ee0e06771b9","Price":{"aud":4665.81,"usd":3477.89,"nzd":5021.34,"sgd":4728.79},"Volume":0.19523509},"Time":1649023821442,"Event":"NewOrder"}
1649023821.570456: {"Channel":"orderbook-bch","Nonce":8291,"Data":{"OrderType":"LimitBid","OrderGuid":"cabf0695-fa5f-405e-97b2-29e5fcdd388e"},"Time":1649023821474,"Event":"OrderCanceled"}
1649023821.578652: {"Channel":"orderbook-eth","Nonce":19393,"Data":{"OrderType":"LimitBid","OrderGuid":"56013c12-a195-4cf3-a321-b321eac6ae85","Price":{"aud":4725.31,"usd":3522.24,"nzd":5085.37,"sgd":4789.1},"Volume":14.14},"Time":1649023821474,"Event":"NewOrder"}
1649023821.582884: {"Channel":"orderbook-eth","Nonce":19394,"Data":{"OrderType":"LimitBid","OrderGuid":"5523a2a8-fd78-4a37-91b5-8a90ba6e1dba"},"Time":1649023821474,"Event":"OrderCanceled"}
1649023821.595941: {"Channel":"orderbook-eth","Nonce":19395,"Data":{"OrderType":"LimitOffer","OrderGuid":"7d0193a2-c0c2-41bf-831c-b578e9d9164c","Price":{"aud":4735.7,"usd":3565.51,"nzd":5158.72,"sgd":4829.4},"Volume":15.0},"Time":1649023821489,"Event":"NewOrder"}
1649023821.599946: {"Channel":"orderbook-eth","Nonce":19396,"Data":{"OrderType":"LimitOffer","OrderGuid":"d6be056c-499d-405f-8df3-c47edbd58a17","Price":{"aud":4738.7,"usd":3567.77,"nzd":5161.99,"sgd":4832.45},"Volume":15.0},"Time":1649023821489,"Event":"NewOrder"}
1649023821.6045: {"Channel":"orderbook-eth","Nonce":19397,"Data":{"OrderType":"LimitBid","OrderGuid":"7472f8cd-27e2-45e6-a41c-8107b5d2af70","Price":{"aud":4725.5,"usd":3522.38,"nzd":5085.58,"sgd":4789.29},"Volume":15.0},"Time":1649023821505,"Event":"NewOrder"}
1649023821.6090722: {"Channel":"orderbook-eth","Nonce":19398,"Data":{"OrderType":"LimitBid","OrderGuid":"3f925269-ba08-40a7-859a-5610c9fb7589","Price":{"aud":4728.5,"usd":3524.62,"nzd":5088.81,"sgd":4792.33},"Volume":15.0},"Time":1649023821505,"Event":"NewOrder"}
1649023821.616846: {"Channel":"orderbook-eth","Nonce":19399,"Data":{"OrderType":"LimitBid","OrderGuid":"56013c12-a195-4cf3-a321-b321eac6ae85"},"Time":1649023821505,"Event":"OrderCanceled"}
1649023821.6305192: {"Channel":"orderbook-eth","Nonce":19400,"Data":{"OrderType":"LimitBid","OrderGuid":"3a080b59-ebc8-4a7d-bd0d-ac2a8f07c1a9","Price":{"aud":4727.62,"usd":3523.96,"nzd":5087.86,"sgd":4791.44},"Volume":14.14},"Time":1649023821521,"Event":"NewOrder"}
1649023821.636822: {"Channel":"orderbook-bch","Nonce":8292,"Data":{"OrderType":"LimitOffer","OrderGuid":"7d03d294-2f30-4f64-bfa7-ea225e04554e","Price":{"aud":510.76,"usd":384.56,"nzd":556.39,"sgd":520.87},"Volume":39.74331},"Time":1649023821536,"Event":"NewOrder"}
1649023821.676161: {"Channel":"orderbook-bch","Nonce":8293,"Data":{"OrderType":"LimitOffer","OrderGuid":"484c30b5-aec6-4be9-98ba-1b4a7acfd5fa","Price":{"aud":510.75,"usd":384.55,"nzd":556.38,"sgd":520.86},"Volume":21.20858658},"Time":1649023821567,"Event":"NewOrder"}
1649023821.679317: {"Channel":"orderbook-bch","Nonce":8294,"Data":{"OrderType":"LimitOffer","OrderGuid":"eae718c2-a477-4255-bfe8-27325fdc9f5a"},"Time":1649023821583,"Event":"OrderCanceled"}
1649023821.7073338: {"Channel":"orderbook-eth","Nonce":19401,"Data":{"OrderType":"LimitBid","OrderGuid":"c13c3f28-6c05-4474-89a4-dd2a002ca69f"},"Time":1649023821599,"Event":"OrderCanceled"}
1649023821.723922: {"Channel":"orderbook-eth","Nonce":19402,"Data":{"OrderType":"LimitBid","OrderGuid":"e1d8dd7b-b07a-4a56-be3a-6f54f16ce6e3"},"Time":1649023821614,"Event":"OrderCanceled"}
1649023821.804492: {"Channel":"orderbook-eth","Nonce":19403,"Data":{"OrderType":"LimitBid","OrderGuid":"7472f8cd-27e2-45e6-a41c-8107b5d2af70"},"Time":1649023821694,"Event":"OrderCanceled"}
1649023821.8046029: {"Channel":"orderbook-eth","Nonce":19404,"Data":{"OrderType":"LimitOffer","OrderGuid":"d6be056c-499d-405f-8df3-c47edbd58a17"},"Time":1649023821694,"Event":"OrderCanceled"}
1649023821.815607: {"Channel":"orderbook-bch","Nonce":8295,"Data":{"OrderType":"LimitBid","OrderGuid":"db359962-0071-4aa7-86bd-4e42417d7c06"},"Time":1649023821710,"Event":"OrderCanceled"}
1649023821.815685: {"Channel":"orderbook-bch","Nonce":8296,"Data":{"OrderType":"LimitOffer","OrderGuid":"04ec1964-d5b3-4e83-85f5-29f7c6370e81"},"Time":1649023821710,"Event":"OrderCanceled"}
1649023821.821228: {"Channel":"orderbook-bch","Nonce":8297,"Data":{"OrderType":"LimitBid","OrderGuid":"530dc2e6-f9b3-4275-8eb3-ed5fbd99cc43"},"Time":1649023821710,"Event":"OrderCanceled"}
1649023821.821337: {"Channel":"orderbook-bch","Nonce":8298,"Data":{"OrderType":"LimitOffer","OrderGuid":"b28108fd-b791-4be4-9eff-559df103ee3a"},"Time":1649023821710,"Event":"OrderCanceled"}
1649023821.85377: {"Channel":"orderbook-bch","Nonce":8299,"Data":{"OrderType":"LimitBid","OrderGuid":"bf3bf433-7604-4b60-b5c6-5f255061e63c","Price":{"aud":504.1,"usd":375.75,"nzd":542.51,"sgd":510.9},"Volume":6.0},"Time":1649023821741,"Event":"NewOrder"}
1649023821.868257: {"Channel":"orderbook-bch","Nonce":8300,"Data":{"OrderType":"LimitBid","OrderGuid":"f90b9421-c351-42c6-8a77-9975124ff874","Price":{"aud":503.4,"usd":375.23,"nzd":541.75,"sgd":510.19},"Volume":6.0},"Time":1649023821757,"Event":"NewOrder"}
1649023821.874856: {"Channel":"orderbook-bch","Nonce":8301,"Data":{"OrderType":"LimitOffer","OrderGuid":"a944466f-59fa-4363-b9e4-ba2a0fbf78e3","Price":{"aud":507.5,"usd":382.1,"nzd":552.84,"sgd":517.55},"Volume":6.0},"Time":1649023821773,"Event":"NewOrder"}
1649023821.900453: {"Channel":"orderbook-eth","Nonce":19405,"Data":{"OrderType":"LimitOffer","OrderGuid":"7d0193a2-c0c2-41bf-831c-b578e9d9164c"},"Time":1649023821788,"Event":"OrderCanceled"}
1649023821.90056: {"Channel":"orderbook-bch","Nonce":8302,"Data":{"OrderType":"LimitOffer","OrderGuid":"cc5d41e6-80b2-4ec4-b48d-a99bf4da8850","Price":{"aud":506.8,"usd":381.57,"nzd":552.07,"sgd":516.83},"Volume":6.0},"Time":1649023821788,"Event":"NewOrder"}
1649023821.9160802: {"Channel":"orderbook-eth","Nonce":19406,"Data":{"OrderType":"LimitBid","OrderGuid":"3f925269-ba08-40a7-859a-5610c9fb7589"},"Time":1649023821804,"Event":"OrderCanceled"}
1649023821.944641: {"Channel":"orderbook-eth","Nonce":19407,"Data":{"OrderType":"LimitBid","OrderGuid":"e2945536-8c15-42e2-95ae-d59b2c021072","Price":{"aud":4728.3,"usd":3524.47,"nzd":5088.59,"sgd":4792.13},"Volume":15.0},"Time":1649023821835,"Event":"NewOrder"}
1649023821.944731: {"Channel":"orderbook-eth","Nonce":19408,"Data":{"OrderType":"LimitOffer","OrderGuid":"d029839b-7f96-4a02-ad9a-b194850b96a8","Price":{"aud":4735.5,"usd":3565.36,"nzd":5158.5,"sgd":4829.19},"Volume":15.0},"Time":1649023821835,"Event":"NewOrder"}
1649023821.94784: {"Channel":"orderbook-eth","Nonce":19409,"Data":{"OrderType":"LimitOffer","OrderGuid":"c2b80329-77f8-4f56-b563-482ef13ecb22","Price":{"aud":4738.5,"usd":3567.62,"nzd":5161.77,"sgd":4832.25},"Volume":15.0},"Time":1649023821851,"Event":"NewOrder"}
1649023821.966023: {"Channel":"orderbook-eth","Nonce":19410,"Data":{"OrderType":"LimitBid","OrderGuid":"e5cd3e0e-559a-48c8-9921-4cae5f85731a","Price":{"aud":4725.3,"usd":3522.23,"nzd":5085.36,"sgd":4789.09},"Volume":15.0},"Time":1649023821866,"Event":"NewOrder"}
1649023821.969564: {"Channel":"orderbook-matic","Nonce":5907,"Data":{"OrderType":"LimitOffer","OrderGuid":"480b8f0f-8904-4300-84bb-62b910a1c0f0"},"Time":1649023821866,"Event":"OrderCanceled"}
1649023822.057014: {"Channel":"orderbook-matic","Nonce":5908,"Data":{"OrderType":"LimitOffer","OrderGuid":"48a5a255-e48d-4bab-966e-0d091932b384","Price":{"aud":2.27246,"usd":1.71094,"nzd":2.47545,"sgd":2.31742},"Volume":5565.38397},"Time":1649023821960,"Event":"NewOrder"}
1649023822.057523: {"Channel":"orderbook-eth","Nonce":19411,"Data":{"OrderType":"LimitBid","OrderGuid":"05d1ba0e-a47f-4a9a-8f94-aad06a5ce25a"},"Time":1649023821960,"Event":"OrderCanceled"}
1649023822.074977: {"Channel":"orderbook-eth","Nonce":19412,"Data":{"OrderType":"LimitBid","OrderGuid":"e2d639b6-68ad-4745-a8f9-094a5a43175c"},"Time":1649023821976,"Event":"OrderCanceled"}
1649023822.0943072: {"Channel":"orderbook-bch","Nonce":8303,"Data":{"OrderType":"LimitOffer","OrderGuid":"3907dba7-881e-41a5-a76e-4387f639c039","Price":{"aud":507.78,"usd":382.31,"nzd":553.14,"sgd":517.83},"Volume":1.09302385},"Time":1649023821991,"Event":"NewOrder"}
1649023822.124234: {"Channel":"orderbook-eth","Nonce":19413,"Data":{"OrderType":"LimitBid","OrderGuid":"20916216-0323-450c-b51a-ecedb380aa6c","Price":{"aud":4699.36,"usd":3520.93,"nzd":5088.5,"sgd":4792.34},"Volume":3.15247339},"Time":1649023822024,"Event":"NewOrder"}
1649023822.149049: {"Channel":"orderbook-matic","Nonce":5909,"Data":{"OrderType":"LimitBid","OrderGuid":"94b32d40-c197-40b9-ae6a-e238d6912d36"},"Time":1649023822039,"Event":"OrderCanceled"}
1649023822.16524: {"Channel":"orderbook-eth","Nonce":19414,"Data":{"OrderType":"LimitBid","OrderGuid":"dc942238-5e66-469f-b98e-3a42455c9f86","Price":{"aud":4678.1,"usd":3503.99,"nzd":5095.98,"sgd":4769.83},"Volume":0.46035193},"Time":1649023822055,"Event":"NewOrder"}
1649023822.175051: {"Channel":"orderbook-eth","Nonce":19415,"Data":{"OrderType":"LimitBid","OrderGuid":"20916216-0323-450c-b51a-ecedb380aa6c"},"Time":1649023822071,"Event":"OrderCanceled"}
1649023822.1819441: {"Channel":"orderbook-eth","Nonce":19416,"Data":{"OrderType":"LimitOffer","OrderGuid":"5c758334-e874-4a56-bd51-faffc5ceb056"},"Time":1649023822071,"Event":"OrderCanceled"}
1649023822.185992: {"Channel":"orderbook-eth","Nonce":19417,"Data":{"OrderType":"LimitOffer","OrderGuid":"8e863664-4b77-4d25-9a56-d7859740de92"},"Time":1649023822086,"Event":"OrderCanceled"}
1649023822.2132108: {"Channel":"orderbook-eth","Nonce":19418,"Data":{"OrderType":"LimitBid","OrderGuid":"43ed1031-74cd-4955-87a0-05db79205498","Price":{"aud":4698.49,"usd":3520.27,"nzd":5087.56,"sgd":4791.45},"Volume":3.08353512},"Time":1649023822102,"Event":"NewOrder"}
1649023822.220714: {"Channel":"orderbook-eth","Nonce":19419,"Data":{"OrderType":"LimitOffer","OrderGuid":"a6a49a1e-95c6-4c14-a7cd-bc9bb8fe0fe5","Price":{"aud":4795.04,"usd":3574.22,"nzd":5198.11,"sgd":4864.88},"Volume":0.52794626},"Time":1649023822117,"Event":"NewOrder"}
1649023822.2251809: {"Channel":"orderbook-eth","Nonce":19420,"Data":{"OrderType":"LimitOffer","OrderGuid":"2cf2a2c0-9d35-425b-b964-6d983742ba49","Price":{"aud":4759.12,"usd":3565.21,"nzd":5153.17,"sgd":4823.36},"Volume":1.15222162},"Time":1649023822117,"Event":"NewOrder"}
1649023822.2550259: {"Channel":"orderbook-bch","Nonce":8304,"Data":{"OrderType":"LimitOffer","OrderGuid":"9f3eefab-6148-4ac4-a643-8560e13d3e36"},"Time":1649023822149,"Event":"OrderCanceled"}
1649023822.2728162: {"Channel":"orderbook-eth","Nonce":19421,"Data":{"OrderType":"LimitOffer","OrderGuid":"4bfc2958-2656-48de-83a4-2913baeaaca1"},"Time":1649023822164,"Event":"OrderCanceled"}
1649023822.314293: {"Channel":"orderbook-eth","Nonce":19422,"Data":{"OrderType":"LimitOffer","OrderGuid":"11545f25-8d5e-41c8-99df-aa7e456dcea8","Price":{"aud":4784.13,"usd":3583.68,"nzd":5148.67,"sgd":4849.01},"Volume":0.52533157},"Time":1649023822211,"Event":"NewOrder"}
1649023822.339177: {"Channel":"orderbook-bch","Nonce":8305,"Data":{"OrderType":"LimitBid","OrderGuid":"776ccbb9-7a62-4c84-b46f-7d9b6d174475","Price":{"aud":493.75,"usd":368.04,"nzd":531.37,"sgd":500.41},"Volume":1.53023339},"Time":1649023822242,"Event":"NewOrder"}
1649023822.356704: {"Channel":"orderbook-eth","Nonce":19423,"Data":{"OrderType":"LimitBid","OrderGuid":"e2945536-8c15-42e2-95ae-d59b2c021072"},"Time":1649023822258,"Event":"OrderCanceled"}
1649023822.360932: {"Channel":"orderbook-eth","Nonce":19424,"Data":{"OrderType":"LimitOffer","OrderGuid":"c2b80329-77f8-4f56-b563-482ef13ecb22"},"Time":1649023822258,"Event":"OrderCanceled"}
1649023822.3950331: {"Channel":"orderbook-eth","Nonce":19425,"Data":{"OrderType":"LimitBid","OrderGuid":"c4b16a4b-a422-4357-b86f-6688676560ff"},"Time":1649023822291,"Event":"OrderCanceled"}
1649023822.4437912: {"Channel":"orderbook-dot","Nonce":4991,"Data":{"OrderType":"LimitBid","OrderGuid":"105bc15b-1d9e-441e-9bce-641ee209238b"},"Time":1649023822338,"Event":"OrderCanceled"}
1649023822.44698: {"Channel":"orderbook-bch","Nonce":8306,"Data":{"OrderType":"LimitBid","OrderGuid":"08124eac-0710-46c9-b93a-099b74c35c95"},"Time":1649023822338,"Event":"OrderCanceled"}
1649023822.460893: {"Channel":"orderbook-eth","Nonce":19426,"Data":{"OrderType":"LimitBid","OrderGuid":"e5cd3e0e-559a-48c8-9921-4cae5f85731a"},"Time":1649023822353,"Event":"OrderCanceled"}
1649023822.46147: {"Channel":"orderbook-eth","Nonce":19427,"Data":{"OrderType":"LimitBid","OrderGuid":"a4d1032c-3440-4d49-bacb-47f4b94bf1d9","Price":{"aud":4703.95,"usd":3506.32,"nzd":5062.39,"sgd":4767.45},"Volume":0.3325246},"Time":1649023822353,"Event":"NewOrder"}
1649023822.477931: {"Channel":"orderbook-eth","Nonce":19428,"Data":{"OrderType":"LimitOffer","OrderGuid":"d029839b-7f96-4a02-ad9a-b194850b96a8"},"Time":1649023822369,"Event":"OrderCanceled"}
1649023822.500055: {"Channel":"orderbook-eth","Nonce":19429,"Data":{"OrderType":"LimitBid","OrderGuid":"e091eb8d-f639-4ef8-8575-229a6d1ab458","Price":{"aud":4728.2,"usd":3524.4,"nzd":5088.48,"sgd":4792.03},"Volume":15.0},"Time":1649023822400,"Event":"NewOrder"}
1649023822.508642: {"Channel":"orderbook-eth","Nonce":19430,"Data":{"OrderType":"LimitBid","OrderGuid":"3a080b59-ebc8-4a7d-bd0d-ac2a8f07c1a9"},"Time":1649023822400,"Event":"OrderCanceled"}
1649023822.5118122: {"Channel":"orderbook-eth","Nonce":19431,"Data":{"OrderType":"LimitBid","OrderGuid":"8e6d85ad-13ab-4e7c-8295-1013387a89b9","Price":{"aud":4725.2,"usd":3522.16,"nzd":5085.26,"sgd":4788.99},"Volume":15.0},"Time":1649023822400,"Event":"NewOrder"}
1649023822.5142589: {"Channel":"orderbook-eth","Nonce":19432,"Data":{"OrderType":"LimitOffer","OrderGuid":"1676e425-f5b8-4e4a-91db-723a5b7ed3b2","Price":{"aud":4735.4,"usd":3565.28,"nzd":5158.39,"sgd":4829.09},"Volume":15.0},"Time":1649023822416,"Event":"NewOrder"}
1649023822.5404851: {"Channel":"orderbook-eth","Nonce":19433,"Data":{"OrderType":"LimitOffer","OrderGuid":"678bd431-9e88-4ea7-90e5-0488cdce9952","Price":{"aud":4738.4,"usd":3567.54,"nzd":5161.66,"sgd":4832.15},"Volume":15.0},"Time":1649023822431,"Event":"NewOrder"}
1649023822.5603998: {"Channel":"orderbook-eth","Nonce":19434,"Data":{"OrderType":"LimitBid","OrderGuid":"e091eb8d-f639-4ef8-8575-229a6d1ab458"},"Time":1649023822463,"Event":"OrderCanceled"}
1649023822.564996: {"Channel":"orderbook-eth","Nonce":19435,"Data":{"OrderType":"LimitBid","OrderGuid":"8e6d85ad-13ab-4e7c-8295-1013387a89b9"},"Time":1649023822463,"Event":"OrderCanceled"}
1649023822.573696: {"Channel":"orderbook-eth","Nonce":19436,"Data":{"OrderType":"LimitBid","OrderGuid":"669d0758-8e1e-4175-92cd-c3e940b3a735","Price":{"aud":4727.09,"usd":3523.57,"nzd":5087.29,"sgd":4790.9},"Volume":14.14},"Time":1649023822463,"Event":"NewOrder"}
1649023822.589246: {"Channel":"orderbook-eth","Nonce":19437,"Data":{"OrderType":"LimitOffer","OrderGuid":"1676e425-f5b8-4e4a-91db-723a5b7ed3b2"},"Time":1649023822478,"Event":"OrderCanceled"}
1649023822.633836: {"Channel":"orderbook-eth","Nonce":19438,"Data":{"OrderType":"LimitOffer","OrderGuid":"8fa4f6cd-956c-43ff-a92d-71da97ff9c9e","Price":{"aud":4738.39,"usd":3567.53,"nzd":5161.65,"sgd":4832.14},"Volume":4.47331033},"Time":1649023822525,"Event":"NewOrder"}
1649023822.63396: {"Channel":"orderbook-eth","Nonce":19439,"Data":{"OrderType":"LimitBid","OrderGuid":"92e5eb83-2ac6-4ff3-a683-d624abc05d5c","Price":{"aud":4724.63,"usd":3521.73,"nzd":5084.64,"sgd":4788.41},"Volume":14.14},"Time":1649023822525,"Event":"NewOrder"}
1649023822.636705: {"Channel":"orderbook-eth","Nonce":19440,"Data":{"OrderType":"LimitOffer","OrderGuid":"cd0f68c7-0aba-419c-8b96-cdea7053e889"},"Time":1649023822525,"Event":"OrderCanceled"}
1649023822.6466272: {"Channel":"orderbook-eth","Nonce":19441,"Data":{"OrderType":"LimitBid","OrderGuid":"669d0758-8e1e-4175-92cd-c3e940b3a735"},"Time":1649023822541,"Event":"OrderCanceled"}
1649023822.673159: {"Channel":"orderbook-dot","Nonce":4992,"Data":{"OrderType":"LimitBid","OrderGuid":"8d03283f-aa79-4d97-8faf-4042c1f5ab3a","Price":{"aud":30.8028,"usd":22.9604,"nzd":33.1499,"sgd":31.2186},"Volume":69.2},"Time":1649023822572,"Event":"NewOrder"}
1649023822.681935: {"Channel":"orderbook-eth","Nonce":19442,"Data":{"OrderType":"LimitOffer","OrderGuid":"678bd431-9e88-4ea7-90e5-0488cdce9952"},"Time":1649023822572,"Event":"OrderCanceled"}
1649023822.68204: {"Channel":"orderbook-eth","Nonce":19443,"Data":{"OrderType":"LimitBid","OrderGuid":"591b3bf6-617a-412a-bcde-a69728d799ef","Price":{"aud":4725.0,"usd":3522.01,"nzd":5085.04,"sgd":4788.78},"Volume":15.0},"Time":1649023822572,"Event":"NewOrder"}
1649023822.724716: {"Channel":"orderbook-eth","Nonce":19444,"Data":{"OrderType":"LimitBid","OrderGuid":"9d0e6614-0a96-4d8d-a4c0-663f3c9233af","Price":{"aud":4725.01,"usd":3522.02,"nzd":5085.05,"sgd":4788.79},"Volume":14.14},"Time":1649023822619,"Event":"NewOrder"}
1649023822.738113: {"Channel":"orderbook-eth","Nonce":19445,"Data":{"OrderType":"LimitBid","OrderGuid":"92e5eb83-2ac6-4ff3-a683-d624abc05d5c"},"Time":1649023822634,"Event":"OrderCanceled"}
1649023822.7382212: {"Channel":"orderbook-eth","Nonce":19446,"Data":{"OrderType":"LimitBid","OrderGuid":"9686ce63-afc9-43cc-b162-05283eb98a7d","Price":{"aud":4665.82,"usd":3477.9,"nzd":5021.35,"sgd":4728.8},"Volume":0.19523767},"Time":1649023822634,"Event":"NewOrder"}
1649023822.8009741: {"Channel":"orderbook-eth","Nonce":19447,"Data":{"OrderType":"LimitOffer","OrderGuid":"f3c3b140-abf5-448c-990b-a66c6f52b312","Price":{"aud":4735.2,"usd":3565.13,"nzd":5158.17,"sgd":4828.89},"Volume":15.0},"Time":1649023822697,"Event":"NewOrder"}
1649023822.8033762: {"Channel":"orderbook-eth","Nonce":19448,"Data":{"OrderType":"LimitOffer","OrderGuid":"1160450b-d0ce-4c45-bf97-d9af5a87a288","Price":{"aud":4738.2,"usd":3567.39,"nzd":5161.44,"sgd":4831.94},"Volume":15.0},"Time":1649023822697,"Event":"NewOrder"}
1649023822.826571: {"Channel":"orderbook-matic","Nonce":5910,"Data":{"OrderType":"LimitOffer","OrderGuid":"e4c3efd6-3ddd-483a-bed5-c6451548e229"},"Time":1649023822728,"Event":"OrderCanceled"}
1649023822.826679: {"Channel":"orderbook-bch","Nonce":8307,"Data":{"OrderType":"LimitOffer","OrderGuid":"a944466f-59fa-4363-b9e4-ba2a0fbf78e3"},"Time":1649023822728,"Event":"OrderCanceled"}
1649023822.826734: {"Channel":"orderbook-bch","Nonce":8308,"Data":{"OrderType":"LimitBid","OrderGuid":"bf3bf433-7604-4b60-b5c6-5f255061e63c"},"Time":1649023822728,"Event":"OrderCanceled"}
1649023822.826777: {"Channel":"orderbook-dot","Nonce":4993,"Data":{"OrderType":"LimitOffer","OrderGuid":"ed815b0e-128a-439b-9d34-1923d50563c0"},"Time":1649023822728,"Event":"OrderCanceled"}
1649023822.831775: {"Channel":"orderbook-eth","Nonce":19449,"Data":{"OrderType":"LimitBid","OrderGuid":"f966e06a-3eb2-4313-bbcf-0ee0e06771b9"},"Time":1649023822728,"Event":"OrderCanceled"}
1649023822.83185: {"Channel":"orderbook-dot","Nonce":4994,"Data":{"OrderType":"LimitOffer","OrderGuid":"9bf82d15-45ab-4f77-86aa-20341795cd0e"},"Time":1649023822728,"Event":"OrderCanceled"}
1649023822.8318841: {"Channel":"orderbook-bch","Nonce":8309,"Data":{"OrderType":"LimitBid","OrderGuid":"f90b9421-c351-42c6-8a77-9975124ff874"},"Time":1649023822728,"Event":"OrderCanceled"}
1649023822.831914: {"Channel":"orderbook-matic","Nonce":5911,"Data":{"OrderType":"LimitOffer","OrderGuid":"2fe1a346-51c6-4e04-a3bf-c6feafccfc7b"},"Time":1649023822728,"Event":"OrderCanceled"}
1649023822.8651369: {"Channel":"orderbook-matic","Nonce":5912,"Data":{"OrderType":"LimitOffer","OrderGuid":"c8e075aa-0518-4310-bf38-1e225f34a872","Price":{"aud":2.2725,"usd":1.71097,"nzd":2.4755,"sgd":2.31746},"Volume":5583.0},"Time":1649023822759,"Event":"NewOrder"}
1649023822.8820171: {"Channel":"orderbook-dot","Nonce":4995,"Data":{"OrderType":"LimitOffer","OrderGuid":"9fba6343-22e7-4293-b0fd-00b1dd46e770","Price":{"aud":31.43,"usd":23.6637,"nzd":34.2375,"sgd":32.0519},"Volume":80.0},"Time":1649023822775,"Event":"NewOrder"}
1649023822.90621: {"Channel":"orderbook-eth","Nonce":19450,"Data":{"OrderType":"LimitOffer","OrderGuid":"f3c3b140-abf5-448c-990b-a66c6f52b312"},"Time":1649023822806,"Event":"OrderCanceled"}
1649023822.915849: {"Channel":"orderbook-eth","Nonce":19451,"Data":{"OrderType":"LimitOffer","OrderGuid":"1160450b-d0ce-4c45-bf97-d9af5a87a288"},"Time":1649023822806,"Event":"OrderCanceled"}
1649023822.929971: {"Channel":"orderbook-bch","Nonce":8310,"Data":{"OrderType":"LimitBid","OrderGuid":"ab8de208-f3e6-4c2c-b087-c60edaef8f40","Price":{"aud":503.9,"usd":375.6,"nzd":542.29,"sgd":510.7},"Volume":6.0},"Time":1649023822822,"Event":"NewOrder"}
1649023822.941837: {"Channel":"orderbook-bch","Nonce":8311,"Data":{"OrderType":"LimitBid","OrderGuid":"b63c6017-3056-44b8-b566-b7e31545bfd8","Price":{"aud":503.2,"usd":375.08,"nzd":541.54,"sgd":509.99},"Volume":6.0},"Time":1649023822838,"Event":"NewOrder"}
1649023822.954218: {"Channel":"orderbook-eth","Nonce":19452,"Data":{"OrderType":"LimitOffer","OrderGuid":"8fa4f6cd-956c-43ff-a92d-71da97ff9c9e"},"Time":1649023822853,"Event":"OrderCanceled"}
1649023822.966114: {"Channel":"orderbook-eth","Nonce":19453,"Data":{"OrderType":"LimitBid","OrderGuid":"591b3bf6-617a-412a-bcde-a69728d799ef"},"Time":1649023822853,"Event":"OrderCanceled"}
1649023822.9662158: {"Channel":"orderbook-eth","Nonce":19454,"Data":{"OrderType":"LimitOffer","OrderGuid":"68223d08-5e36-417e-aa66-44487f1464bd","Price":{"aud":4734.9,"usd":3564.9,"nzd":5157.85,"sgd":4828.58},"Volume":15.0},"Time":1649023822853,"Event":"NewOrder"}
1649023822.969333: {"Channel":"orderbook-dot","Nonce":4996,"Data":{"OrderType":"LimitOffer","OrderGuid":"269ab3aa-f43b-40c2-a65b-c5202e8b7643","Price":{"aud":31.39,"usd":23.6335,"nzd":34.1939,"sgd":32.0111},"Volume":80.0},"Time":1649023822869,"Event":"NewOrder"}
1649023822.9694562: {"Channel":"orderbook-matic","Nonce":5913,"Data":{"OrderType":"LimitOffer","OrderGuid":"d5fd25b9-97e1-4c8c-8a29-c389b62ca662","Price":{"aud":2.274,"usd":1.7121,"nzd":2.47713,"sgd":2.31899},"Volume":5583.0},"Time":1649023822869,"Event":"NewOrder"}
1649023822.969907: {"Channel":"orderbook-eth","Nonce":19455,"Data":{"OrderType":"LimitOffer","OrderGuid":"6ec4debc-5b9f-4645-a6e9-8f025025a114","Price":{"aud":4738.19,"usd":3567.38,"nzd":5161.43,"sgd":4831.93},"Volume":4.47331033},"Time":1649023822869,"Event":"NewOrder"}
1649023823.0165818: {"Channel":"orderbook-bch","Nonce":8312,"Data":{"OrderType":"LimitOffer","OrderGuid":"cc5d41e6-80b2-4ec4-b48d-a99bf4da8850"},"Time":1649023822916,"Event":"OrderCanceled"}
1649023823.0298822: {"Channel":"orderbook-bch","Nonce":8313,"Data":{"OrderType":"LimitOffer","OrderGuid":"3f19cf00-df02-4444-a8da-ed05ad93fd25","Price":{"aud":507.67,"usd":382.23,"nzd":553.02,"sgd":517.72},"Volume":1.09302385},"Time":1649023822931,"Event":"NewOrder"}
1649023823.047154: {"Channel":"orderbook-bch","Nonce":8314,"Data":{"OrderType":"LimitOffer","OrderGuid":"0a7f78e5-be97-4f1a-ab4d-6fb2ee30e8cf","Price":{"aud":506.7,"usd":381.5,"nzd":551.97,"sgd":516.73},"Volume":6.0},"Time":1649023822947,"Event":"NewOrder"}
1649023823.070173: {"Channel":"orderbook-bch","Nonce":8315,"Data":{"OrderType":"LimitOffer","OrderGuid":"8d9eab99-b362-4284-a41d-5ebed2a0f8de","Price":{"aud":507.4,"usd":382.03,"nzd":552.73,"sgd":517.44},"Volume":6.0},"Time":1649023822963,"Event":"NewOrder"}
1649023823.070299: {"Channel":"orderbook-eth","Nonce":19456,"Data":{"OrderType":"LimitOffer","OrderGuid":"07e69fd5-7857-4ecf-973a-72bfceb3a0d3","Price":{"aud":4737.9,"usd":3567.16,"nzd":5161.12,"sgd":4831.64},"Volume":15.0},"Time":1649023822963,"Event":"NewOrder"}
1649023823.086035: {"Channel":"orderbook-eth","Nonce":19457,"Data":{"OrderType":"LimitBid","OrderGuid":"3e7161ce-1223-46e0-ac21-f15dcd3065e8","Price":{"aud":4727.7,"usd":3524.02,"nzd":5087.95,"sgd":4791.52},"Volume":15.0},"Time":1649023822978,"Event":"NewOrder"}
1649023823.095585: {"Channel":"orderbook-matic","Nonce":5914,"Data":{"OrderType":"LimitOffer","OrderGuid":"c8e075aa-0518-4310-bf38-1e225f34a872"},"Time":1649023822994,"Event":"OrderCanceled"}
1649023823.096142: {"Channel":"orderbook-eth","Nonce":19458,"Data":{"OrderType":"LimitOffer","OrderGuid":"c19d45a2-149e-4f91-a3e3-4d8d6b82e1d9"},"Time":1649023822994,"Event":"OrderCanceled"}
1649023823.106524: {"Channel":"orderbook-matic","Nonce":5915,"Data":{"OrderType":"LimitOffer","OrderGuid":"d5fd25b9-97e1-4c8c-8a29-c389b62ca662"},"Time":1649023822994,"Event":"OrderCanceled"}
1649023823.126283: {"Channel":"orderbook-matic","Nonce":5916,"Data":{"OrderType":"LimitOffer","OrderGuid":"1b3cd32b-7713-4720-af89-10346b1e71b7"},"Time":1649023823025,"Event":"OrderCanceled"}
1649023823.129817: {"Channel":"orderbook-bch","Nonce":8316,"Data":{"OrderType":"LimitOffer","OrderGuid":"acf2f4b5-51a3-4a76-8a56-bd5f0f15f5f7"},"Time":1649023823025,"Event":"OrderCanceled"}
1649023823.144521: {"Channel":"orderbook-bch","Nonce":8317,"Data":{"OrderType":"LimitOffer","OrderGuid":"3907dba7-881e-41a5-a76e-4387f639c039"},"Time":1649023823041,"Event":"OrderCanceled"}
1649023823.14892: {"Channel":"orderbook-matic","Nonce":5917,"Data":{"OrderType":"LimitOffer","OrderGuid":"ed947b7c-c027-4f34-b3cf-d3969ab41ac2","Price":{"aud":2.273,"usd":1.71134,"nzd":2.47604,"sgd":2.31797},"Volume":5583.0},"Time":1649023823041,"Event":"NewOrder"}
1649023823.154165: {"Channel":"orderbook-matic","Nonce":5918,"Data":{"OrderType":"LimitOffer","OrderGuid":"5e76b655-06e4-4acb-ba0d-2143cbed84bb","Price":{"aud":2.2745,"usd":1.71247,"nzd":2.47767,"sgd":2.3195},"Volume":5583.0},"Time":1649023823056,"Event":"NewOrder"}
1649023823.171672: {"Channel":"orderbook-eth","Nonce":19459,"Data":{"OrderType":"LimitBid","OrderGuid":"be3035dd-7630-403a-bcd9-795abbeac4a5","Price":{"aud":4724.7,"usd":3521.79,"nzd":5084.72,"sgd":4788.48},"Volume":15.0},"Time":1649023823072,"Event":"NewOrder"}
1649023823.23741: {"Channel":"orderbook-eth","Nonce":19460,"Data":{"OrderType":"LimitOffer","OrderGuid":"a7130a04-afa7-4079-bd03-ec9f6812d023","Price":{"aud":4754.96,"usd":3580.01,"nzd":5179.7,"sgd":4849.04},"Volume":7.96},"Time":1649023823134,"Event":"NewOrder"}
1649023823.2403688: {"Channel":"orderbook-bch","Nonce":8318,"Data":{"OrderType":"LimitOffer","OrderGuid":"1656825a-025b-4529-986c-a43a27a2d7d9","Price":{"aud":507.68,"usd":382.24,"nzd":553.03,"sgd":517.73},"Volume":1.092961},"Time":1649023823134,"Event":"NewOrder"}
1649023823.286151: {"Channel":"orderbook-eth","Nonce":19461,"Data":{"OrderType":"LimitBid","OrderGuid":"dc942238-5e66-469f-b98e-3a42455c9f86"},"Time":1649023823181,"Event":"OrderCanceled"}
1649023823.299062: {"Channel":"orderbook-bch","Nonce":8319,"Data":{"OrderType":"LimitOffer","OrderGuid":"8c61283c-a7a5-4325-af4c-c1a8ade9454c","Price":{"aud":510.74,"usd":384.54,"nzd":556.37,"sgd":520.85},"Volume":2.93},"Time":1649023823197,"Event":"NewOrder"}
1649023823.351843: {"Channel":"orderbook-bch","Nonce":8320,"Data":{"OrderType":"LimitOffer","OrderGuid":"484c30b5-aec6-4be9-98ba-1b4a7acfd5fa"},"Time":1649023823244,"Event":"OrderCanceled"}
1649023823.3519518: {"Channel":"orderbook-eth","Nonce":19462,"Data":{"OrderType":"LimitBid","OrderGuid":"0c04df22-a15f-4edd-8a85-7c96cc9293b5","Price":{"aud":4678.11,"usd":3504.0,"nzd":5095.99,"sgd":4769.84},"Volume":0.44530379},"Time":1649023823244,"Event":"NewOrder"}
1649023823.381948: {"Channel":"orderbook-bch","Nonce":8321,"Data":{"OrderType":"LimitOffer","OrderGuid":"e190e060-5fed-4880-ae60-99c33e902b61","Price":{"aud":510.73,"usd":384.53,"nzd":556.36,"sgd":520.84},"Volume":21.20858658},"Time":1649023823275,"Event":"NewOrder"}
1649023823.9778671: {"Channel":"orderbook-eth","Nonce":19463,"Data":{"OrderType":"LimitOffer","OrderGuid":"68223d08-5e36-417e-aa66-44487f1464bd"},"Time":1649023823759,"Event":"OrderCanceled"}
1649023823.977931: {"Channel":"orderbook-eth","Nonce":19464,"Data":{"OrderType":"LimitBid","OrderGuid":"be3035dd-7630-403a-bcd9-795abbeac4a5"},"Time":1649023823759,"Event":"OrderCanceled"}
1649023823.977958: {"Channel":"orderbook-eth","Nonce":19465,"Data":{"OrderType":"LimitOffer","OrderGuid":"07e69fd5-7857-4ecf-973a-72bfceb3a0d3"},"Time":1649023823759,"Event":"OrderCanceled"}
1649023823.9779809: {"Channel":"orderbook-eth","Nonce":19466,"Data":{"OrderType":"LimitOffer","OrderGuid":"6ec4debc-5b9f-4645-a6e9-8f025025a114"},"Time":1649023823791,"Event":"OrderCanceled"}
1649023823.9780018: {"Channel":"orderbook-eth","Nonce":19467,"Data":{"OrderType":"LimitOffer","OrderGuid":"d2152e2e-40cd-4cab-8660-82ef19f704d8","Price":{"aud":4738.1,"usd":3567.31,"nzd":5161.33,"sgd":4831.84},"Volume":15.0},"Time":1649023823853,"Event":"NewOrder"}
1649023823.9780328: {"Channel":"orderbook-eth","Nonce":19468,"Data":{"OrderType":"LimitBid","OrderGuid":"3e7161ce-1223-46e0-ac21-f15dcd3065e8"},"Time":1649023823853,"Event":"OrderCanceled"}
1649023823.978053: {"Channel":"orderbook-eth","Nonce":19469,"Data":{"OrderType":"LimitOffer","OrderGuid":"eedc00c0-3694-4118-b0aa-d83dd6d8eeb5","Price":{"aud":4735.1,"usd":3565.06,"nzd":5158.07,"sgd":4828.78},"Volume":15.0},"Time":1649023823853,"Event":"NewOrder"}
1649023823.983374: {"Channel":"orderbook-eth","Nonce":19470,"Data":{"OrderType":"LimitBid","OrderGuid":"1e04ec5b-e468-4cf6-a173-ecd570aec089","Price":{"aud":4727.9,"usd":3524.17,"nzd":5088.16,"sgd":4791.72},"Volume":15.0},"Time":1649023823884,"Event":"NewOrder"}
1649023823.992841: {"Channel":"orderbook-eth","Nonce":19471,"Data":{"OrderType":"LimitBid","OrderGuid":"07e2b159-b117-4592-a8a2-618b3dba9bd6","Price":{"aud":4724.63,"usd":3521.73,"nzd":5084.64,"sgd":4788.41},"Volume":14.14},"Time":1649023823884,"Event":"NewOrder"}
1649023823.992933: {"Channel":"orderbook-eth","Nonce":19472,"Data":{"OrderType":"LimitBid","OrderGuid":"e47e0e21-9bc3-42dc-9a20-056064caad1a","Price":{"aud":4724.9,"usd":3521.94,"nzd":5084.93,"sgd":4788.68},"Volume":15.0},"Time":1649023823884,"Event":"NewOrder"}
1649023823.9969769: {"Channel":"orderbook-eth","Nonce":19473,"Data":{"OrderType":"LimitBid","OrderGuid":"9d0e6614-0a96-4d8d-a4c0-663f3c9233af"},"Time":1649023823900,"Event":"OrderCanceled"}
1649023824.051782: {"Channel":"orderbook-bch","Nonce":8322,"Data":{"OrderType":"LimitOffer","OrderGuid":"7d03d294-2f30-4f64-bfa7-ea225e04554e"},"Time":1649023823947,"Event":"OrderCanceled"}
1649023824.051889: {"Channel":"orderbook-bch","Nonce":8323,"Data":{"OrderType":"LimitOffer","OrderGuid":"3f19cf00-df02-4444-a8da-ed05ad93fd25"},"Time":1649023823947,"Event":"OrderCanceled"}
1649023824.1004422: {"Channel":"orderbook-eth","Nonce":19474,"Data":{"OrderType":"LimitOffer","OrderGuid":"2b8856b1-f126-4292-b394-ac0d1959744a","Price":{"aud":4737.89,"usd":3567.16,"nzd":5161.11,"sgd":4831.63},"Volume":4.47331033},"Time":1649023823994,"Event":"NewOrder"}
1649023824.157877: {"Channel":"orderbook-dot","Nonce":4997,"Data":{"OrderType":"LimitOffer","OrderGuid":"3986bab6-d153-40c1-9f27-fbcabf6dbb8a"},"Time":1649023824056,"Event":"OrderCanceled"}
1649023824.1790872: {"Channel":"orderbook-dot","Nonce":4998,"Data":{"OrderType":"LimitOffer","OrderGuid":"269ab3aa-f43b-40c2-a65b-c5202e8b7643"},"Time":1649023824072,"Event":"OrderCanceled"}
1649023824.185657: {"Channel":"orderbook-dot","Nonce":4999,"Data":{"OrderType":"LimitOffer","OrderGuid":"9fba6343-22e7-4293-b0fd-00b1dd46e770"},"Time":1649023824088,"Event":"OrderCanceled"}
1649023824.18573: {"Channel":"orderbook-bch","Nonce":8324,"Data":{"OrderType":"LimitOffer","OrderGuid":"de7f00db-a5e4-43c0-a8a9-b887e8938ccf","Price":{"aud":510.74,"usd":384.54,"nzd":556.37,"sgd":520.85},"Volume":39.74331},"Time":1649023824088,"Event":"NewOrder"}
1649023824.185781: {"Channel":"orderbook-matic","Nonce":5919,"Data":{"OrderType":"LimitBid","OrderGuid":"1f9abd74-948a-4c77-a97d-2fcd46458d77"},"Time":1649023824088,"Event":"OrderCanceled"}
1649023824.202464: {"Channel":"orderbook-matic","Nonce":5920,"Data":{"OrderType":"LimitOffer","OrderGuid":"48a5a255-e48d-4bab-966e-0d091932b384"},"Time":1649023824103,"Event":"OrderCanceled"}
1649023824.214875: {"Channel":"orderbook-dot","Nonce":5000,"Data":{"OrderType":"LimitOffer","OrderGuid":"8aed598c-c6f7-4a04-879c-fb1a06952e49","Price":{"aud":31.4,"usd":23.6411,"nzd":34.2048,"sgd":32.0213},"Volume":80.0},"Time":1649023824103,"Event":"NewOrder"}
1649023824.219396: {"Channel":"orderbook-dot","Nonce":5001,"Data":{"OrderType":"LimitOffer","OrderGuid":"da3ac42a-2ee6-4794-a640-5df15ba40da8","Price":{"aud":31.44,"usd":23.6712,"nzd":34.2484,"sgd":32.0621},"Volume":80.0},"Time":1649023824119,"Event":"NewOrder"}
1649023824.258806: {"Channel":"orderbook-eth","Nonce":19475,"Data":{"OrderType":"LimitOffer","OrderGuid":"a6a49a1e-95c6-4c14-a7cd-bc9bb8fe0fe5"},"Time":1649023824150,"Event":"OrderCanceled"}
1649023824.2588842: {"Channel":"orderbook-matic","Nonce":5921,"Data":{"OrderType":"LimitBid","OrderGuid":"085edc5b-61fc-40ff-b2a1-6099b8e7c72e","Price":{"aud":2.26124,"usd":1.68552,"nzd":2.43354,"sgd":2.29176},"Volume":5622.39399},"Time":1649023824150,"Event":"NewOrder"}
1649023824.264153: {"Channel":"orderbook-matic","Nonce":5922,"Data":{"OrderType":"LimitOffer","OrderGuid":"16f1eb92-1b88-48cf-b1a4-b03f8503c668","Price":{"aud":2.27245,"usd":1.71093,"nzd":2.47544,"sgd":2.31741},"Volume":5884.1725},"Time":1649023824166,"Event":"NewOrder"}
1649023824.3015711: {"Channel":"orderbook-eth","Nonce":19476,"Data":{"OrderType":"LimitOffer","OrderGuid":"551238f5-3d7a-418e-bb44-d8e483560dd7","Price":{"aud":4794.44,"usd":3573.77,"nzd":5197.46,"sgd":4864.26},"Volume":0.58186027},"Time":1649023824197,"Event":"NewOrder"}
1649023824.3059258: {"Channel":"orderbook-dot","Nonce":5002,"Data":{"OrderType":"LimitOffer","OrderGuid":"1cb8be0a-e6fd-4752-9870-2e5d396ce428","Price":{"aud":31.5096,"usd":23.7236,"nzd":34.3242,"sgd":32.133},"Volume":52.9},"Time":1649023824197,"Event":"NewOrder"}
1649023824.3142242: {"Channel":"orderbook-eth","Nonce":19477,"Data":{"OrderType":"LimitOffer","OrderGuid":"2375ebb2-559b-4e44-8130-b28f11d2bbef"},"Time":1649023824213,"Event":"OrderCanceled"}
1649023824.3175411: {"Channel":"orderbook-eth","Nonce":19478,"Data":{"OrderType":"LimitBid","OrderGuid":"0c04df22-a15f-4edd-8a85-7c96cc9293b5"},"Time":1649023824213,"Event":"OrderCanceled"}
1649023824.38384: {"Channel":"orderbook-eth","Nonce":19479,"Data":{"OrderType":"LimitOffer","OrderGuid":"d2152e2e-40cd-4cab-8660-82ef19f704d8"},"Time":1649023824275,"Event":"OrderCanceled"}
1649023824.383958: {"Channel":"orderbook-dot","Nonce":5003,"Data":{"OrderType":"LimitBid","OrderGuid":"83fb9a15-8656-4cdd-ac67-2abbe083056a"},"Time":1649023824275,"Event":"OrderCanceled"}
1649023824.385754: {"Channel":"orderbook-bch","Nonce":8325,"Data":{"OrderType":"LimitOffer","OrderGuid":"8d9eab99-b362-4284-a41d-5ebed2a0f8de"},"Time":1649023824275,"Event":"OrderCanceled"}
1649023824.389847: {"Channel":"orderbook-eth","Nonce":19480,"Data":{"OrderType":"LimitOffer","OrderGuid":"551238f5-3d7a-418e-bb44-d8e483560dd7"},"Time":1649023824291,"Event":"OrderCanceled"}
1649023824.389929: {"Channel":"orderbook-bch","Nonce":8326,"Data":{"OrderType":"LimitOffer","OrderGuid":"0a7f78e5-be97-4f1a-ab4d-6fb2ee30e8cf"},"Time":1649023824291,"Event":"OrderCanceled"}
1649023824.389977: {"Channel":"orderbook-eth","Nonce":19481,"Data":{"OrderType":"LimitBid","OrderGuid":"1e04ec5b-e468-4cf6-a173-ecd570aec089"},"Time":1649023824291,"Event":"OrderCanceled"}
1649023824.392235: {"Channel":"orderbook-dot","Nonce":5004,"Data":{"OrderType":"LimitOffer","OrderGuid":"b4e0108e-25c0-4c35-99b7-f9b0dd939ee9","Price":{"aud":31.5095,"usd":23.7235,"nzd":34.3241,"sgd":32.1329},"Volume":14.72539},"Time":1649023824291,"Event":"NewOrder"}
1649023824.397357: {"Channel":"orderbook-dot","Nonce":5005,"Data":{"OrderType":"LimitOffer","OrderGuid":"2c29bdf8-401d-4ee6-b4a6-084284d81b53"},"Time":1649023824291,"Event":"OrderCanceled"}
1649023824.407286: {"Channel":"orderbook-eth","Nonce":19482,"Data":{"OrderType":"LimitBid","OrderGuid":"ed2d96ee-aa4c-49c4-b1ea-fcef98ede073","Price":{"aud":4678.12,"usd":3504.0,"nzd":5096.0,"sgd":4769.85},"Volume":0.40373135},"Time":1649023824308,"Event":"NewOrder"}
1649023824.426229: {"Channel":"orderbook-bch","Nonce":8327,"Data":{"OrderType":"LimitOffer","OrderGuid":"96fda58d-c2c6-4a6c-913a-abedd6ca3548","Price":{"aud":507.3,"usd":381.95,"nzd":552.62,"sgd":517.34},"Volume":6.0},"Time":1649023824323,"Event":"NewOrder"}
1649023824.426303: {"Channel":"orderbook-eth","Nonce":19483,"Data":{"OrderType":"LimitOffer","OrderGuid":"2cf2a2c0-9d35-425b-b964-6d983742ba49"},"Time":1649023824323,"Event":"OrderCanceled"}
1649023824.436822: {"Channel":"orderbook-eth","Nonce":19484,"Data":{"OrderType":"LimitBid","OrderGuid":"81a824f5-411d-4b55-a3d9-f5220c09040c","Price":{"aud":4724.91,"usd":3521.94,"nzd":5084.94,"sgd":4788.69},"Volume":14.14},"Time":1649023824323,"Event":"NewOrder"}
1649023824.4400482: {"Channel":"orderbook-eth","Nonce":19485,"Data":{"OrderType":"LimitBid","OrderGuid":"07e2b159-b117-4592-a8a2-618b3dba9bd6"},"Time":1649023824339,"Event":"OrderCanceled"}
1649023824.453834: {"Channel":"orderbook-eth","Nonce":19486,"Data":{"OrderType":"LimitBid","OrderGuid":"43ed1031-74cd-4955-87a0-05db79205498"},"Time":1649023824354,"Event":"OrderCanceled"}
1649023824.465843: {"Channel":"orderbook-eth","Nonce":19487,"Data":{"OrderType":"LimitBid","OrderGuid":"e47e0e21-9bc3-42dc-9a20-056064caad1a"},"Time":1649023824354,"Event":"OrderCanceled"}
1649023824.46592: {"Channel":"orderbook-eth","Nonce":19488,"Data":{"OrderType":"LimitOffer","OrderGuid":"eedc00c0-3694-4118-b0aa-d83dd6d8eeb5"},"Time":1649023824354,"Event":"OrderCanceled"}
1649023824.475196: {"Channel":"orderbook-eth","Nonce":19489,"Data":{"OrderType":"LimitOffer","OrderGuid":"b1f49238-5e31-4f68-92c6-c2535f7495cb","Price":{"aud":4793.51,"usd":3573.08,"nzd":5196.46,"sgd":4863.32},"Volume":0.61053343},"Time":1649023824370,"Event":"NewOrder"}
1649023824.47532: {"Channel":"orderbook-dot","Nonce":5006,"Data":{"OrderType":"LimitOffer","OrderGuid":"8aed598c-c6f7-4a04-879c-fb1a06952e49"},"Time":1649023824370,"Event":"OrderCanceled"}
1649023824.478653: {"Channel":"orderbook-dot","Nonce":5007,"Data":{"OrderType":"LimitOffer","OrderGuid":"da3ac42a-2ee6-4794-a640-5df15ba40da8"},"Time":1649023824370,"Event":"OrderCanceled"}
1649023824.4793038: {"Channel":"orderbook-dot","Nonce":5008,"Data":{"OrderType":"LimitBid","OrderGuid":"999c80dc-70e9-44cc-b8c6-25e5cb1fcd65"},"Time":1649023824370,"Event":"OrderCanceled"}
1649023824.479368: {"Channel":"orderbook-eth","Nonce":19490,"Data":{"OrderType":"LimitOffer","OrderGuid":"d3d3e339-3931-4c6f-a024-5026690d0df7","Price":{"aud":4757.26,"usd":3563.82,"nzd":5151.16,"sgd":4821.48},"Volume":1.17885189},"Time":1649023824370,"Event":"NewOrder"}
1649023824.489435: {"Channel":"orderbook-eth","Nonce":19491,"Data":{"OrderType":"LimitOffer","OrderGuid":"7c16c2e7-e0cb-49f3-bd74-0b589a02b9fd","Price":{"aud":4744.29,"usd":3571.97,"nzd":5168.08,"sgd":4838.16},"Volume":1.01},"Time":1649023824386,"Event":"NewOrder"}
1649023824.499104: {"Channel":"orderbook-eth","Nonce":19492,"Data":{"OrderType":"LimitBid","OrderGuid":"04926c95-f7b3-47a0-973e-1fad611c419c","Price":{"aud":4695.78,"usd":3518.25,"nzd":5084.63,"sgd":4788.69},"Volume":3.04005087},"Time":1649023824401,"Event":"NewOrder"}
1649023824.509789: {"Channel":"orderbook-eth","Nonce":19493,"Data":{"OrderType":"LimitOffer","OrderGuid":"e7d0e3dd-c14e-48f5-9c61-abf8f69fc503","Price":{"aud":4734.4,"usd":3564.53,"nzd":5157.3,"sgd":4828.07},"Volume":15.0},"Time":1649023824401,"Event":"NewOrder"}
1649023824.5204291: {"Channel":"orderbook-dot","Nonce":5009,"Data":{"OrderType":"LimitBid","OrderGuid":"933cb3b7-0408-40f9-aa4b-e076191f58e2"},"Time":1649023824417,"Event":"OrderCanceled"}
1649023824.52049: {"Channel":"orderbook-dot","Nonce":5010,"Data":{"OrderType":"LimitBid","OrderGuid":"bbf385b5-7a9d-4783-a417-0c80a62c8a8e","Price":{"aud":31.19,"usd":23.249,"nzd":33.5666,"sgd":31.611},"Volume":80.0},"Time":1649023824417,"Event":"NewOrder"}
1649023824.5262542: {"Channel":"orderbook-dot","Nonce":5011,"Data":{"OrderType":"LimitBid","OrderGuid":"b15d76c3-89cf-4383-90fb-214bf313adac","Price":{"aud":31.15,"usd":23.2192,"nzd":33.5236,"sgd":31.5705},"Volume":80.0},"Time":1649023824417,"Event":"NewOrder"}
1649023824.530891: {"Channel":"orderbook-dot","Nonce":5012,"Data":{"OrderType":"LimitOffer","OrderGuid":"e88b65ac-ed8c-4e75-b858-1ce8fca6a328","Price":{"aud":31.39,"usd":23.6335,"nzd":34.1939,"sgd":32.0111},"Volume":80.0},"Time":1649023824433,"Event":"NewOrder"}
1649023824.531012: {"Channel":"orderbook-bch","Nonce":8328,"Data":{"OrderType":"LimitOffer","OrderGuid":"d74d9b65-92e7-47b3-8c88-58adb7d13173","Price":{"aud":506.6,"usd":381.42,"nzd":551.86,"sgd":516.63},"Volume":6.0},"Time":1649023824433,"Event":"NewOrder"}
1649023824.5344372: {"Channel":"orderbook-dot","Nonce":5013,"Data":{"OrderType":"LimitBid","OrderGuid":"8e687480-302b-4f5a-9686-5c9133639232","Price":{"aud":30.8029,"usd":22.9604,"nzd":33.15,"sgd":31.2187},"Volume":457.6},"Time":1649023824433,"Event":"NewOrder"}
1649023824.59164: {"Channel":"orderbook-eth","Nonce":19494,"Data":{"OrderType":"LimitOffer","OrderGuid":"a7130a04-afa7-4079-bd03-ec9f6812d023"},"Time":1649023824479,"Event":"OrderCanceled"}
1649023824.6044428: {"Channel":"orderbook-bch","Nonce":8329,"Data":{"OrderType":"LimitOffer","OrderGuid":"8c61283c-a7a5-4325-af4c-c1a8ade9454c"},"Time":1649023824495,"Event":"OrderCanceled"}
1649023824.623755: {"Channel":"orderbook-bch","Nonce":8330,"Data":{"OrderType":"LimitOffer","OrderGuid":"86f1e87a-7960-416c-926e-86a1d7a43fb2","Price":{"aud":507.69,"usd":382.24,"nzd":553.04,"sgd":517.74},"Volume":1.092961},"Time":1649023824526,"Event":"NewOrder"}
1649023824.628114: {"Channel":"orderbook-dot","Nonce":5014,"Data":{"OrderType":"LimitOffer","OrderGuid":"2e0e899b-c45f-41ac-84e6-8e0f4afb8cbe","Price":{"aud":31.43,"usd":23.6637,"nzd":34.2375,"sgd":32.0519},"Volume":80.0},"Time":1649023824526,"Event":"NewOrder"}
1649023824.6282141: {"Channel":"orderbook-eth","Nonce":19495,"Data":{"OrderType":"LimitBid","OrderGuid":"f85b47fe-24ac-4b36-9248-1ca0b51a200d","Price":{"aud":4727.2,"usd":3523.65,"nzd":5087.41,"sgd":4791.01},"Volume":15.0},"Time":1649023824526,"Event":"NewOrder"}
1649023824.6327949: {"Channel":"orderbook-eth","Nonce":19496,"Data":{"OrderType":"LimitOffer","OrderGuid":"d55ea71e-28a7-4f31-8e44-edc6aac1f6b2","Price":{"aud":4737.4,"usd":3566.79,"nzd":5160.57,"sgd":4831.13},"Volume":15.0},"Time":1649023824526,"Event":"NewOrder"}
1649023824.652519: {"Channel":"orderbook-eth","Nonce":19497,"Data":{"OrderType":"LimitBid","OrderGuid":"ff5f7975-2957-42ec-84b6-061f76430f02","Price":{"aud":4724.2,"usd":3521.41,"nzd":5084.18,"sgd":4787.97},"Volume":15.0},"Time":1649023824542,"Event":"NewOrder"}
1649023824.65786: {"Channel":"orderbook-eth","Nonce":19498,"Data":{"OrderType":"LimitOffer","OrderGuid":"e7d0e3dd-c14e-48f5-9c61-abf8f69fc503"},"Time":1649023824558,"Event":"OrderCanceled"}
1649023824.6689532: {"Channel":"orderbook-bch","Nonce":8331,"Data":{"OrderType":"LimitBid","OrderGuid":"b63c6017-3056-44b8-b566-b7e31545bfd8"},"Time":1649023824558,"Event":"OrderCanceled"}
1649023824.6733801: {"Channel":"orderbook-bch","Nonce":8332,"Data":{"OrderType":"LimitBid","OrderGuid":"ab8de208-f3e6-4c2c-b087-c60edaef8f40"},"Time":1649023824573,"Event":"OrderCanceled"}
1649023824.68048: {"Channel":"orderbook-bch","Nonce":8333,"Data":{"OrderType":"LimitOffer","OrderGuid":"1656825a-025b-4529-986c-a43a27a2d7d9"},"Time":1649023824573,"Event":"OrderCanceled"}
1649023824.682973: {"Channel":"orderbook-eth","Nonce":19499,"Data":{"OrderType":"LimitBid","OrderGuid":"f85b47fe-24ac-4b36-9248-1ca0b51a200d"},"Time":1649023824573,"Event":"OrderCanceled"}
1649023824.694668: {"Channel":"orderbook-eth","Nonce":19500,"Data":{"OrderType":"LimitOffer","OrderGuid":"d55ea71e-28a7-4f31-8e44-edc6aac1f6b2"},"Time":1649023824589,"Event":"OrderCanceled"}
1649023824.70127: {"Channel":"orderbook-dot","Nonce":5015,"Data":{"OrderType":"LimitBid","OrderGuid":"5269558c-abf4-4539-a64e-7d6fe86a3ab4","Price":{"aud":30.7996,"usd":22.958,"nzd":33.1465,"sgd":31.2153},"Volume":24.76571},"Time":1649023824604,"Event":"NewOrder"}
1649023824.706989: {"Channel":"orderbook-eth","Nonce":19501,"Data":{"OrderType":"LimitOffer","OrderGuid":"6f4f303b-d535-4f9f-98af-bdbdc6fc42ec","Price":{"aud":4737.39,"usd":3566.78,"nzd":5160.56,"sgd":4831.12},"Volume":4.47331033},"Time":1649023824606,"Event":"NewOrder"}
1649023824.711164: {"Channel":"orderbook-eth","Nonce":19502,"Data":{"OrderType":"LimitOffer","OrderGuid":"2b8856b1-f126-4292-b394-ac0d1959744a"},"Time":1649023824606,"Event":"OrderCanceled"}
1649023824.728707: {"Channel":"orderbook-eth","Nonce":19503,"Data":{"OrderType":"LimitOffer","OrderGuid":"0f2d1bd3-3c40-42d0-a6eb-3af1d6a25658","Price":{"aud":4737.0,"usd":3566.49,"nzd":5160.14,"sgd":4830.72},"Volume":15.0},"Time":1649023824621,"Event":"NewOrder"}
1649023824.7350888: {"Channel":"orderbook-eth","Nonce":19504,"Data":{"OrderType":"LimitOffer","OrderGuid":"7606aa1d-b59d-4709-ba38-0e4ca4187834","Price":{"aud":4734.0,"usd":3564.23,"nzd":5156.87,"sgd":4827.66},"Volume":15.0},"Time":1649023824621,"Event":"NewOrder"}
1649023824.735137: {"Channel":"orderbook-bch","Nonce":8334,"Data":{"OrderType":"LimitBid","OrderGuid":"12eedaa3-9be1-4336-aba0-f1be80e76492","Price":{"aud":503.9,"usd":375.6,"nzd":542.29,"sgd":510.7},"Volume":6.0},"Time":1649023824637,"Event":"NewOrder"}
1649023824.7618508: {"Channel":"orderbook-eth","Nonce":19505,"Data":{"OrderType":"LimitBid","OrderGuid":"ff5f7975-2957-42ec-84b6-061f76430f02"},"Time":1649023824653,"Event":"OrderCanceled"}
1649023824.783307: {"Channel":"orderbook-eth","Nonce":19506,"Data":{"OrderType":"LimitOffer","OrderGuid":"5f705a13-41f8-4820-9b04-7bdba82eefb7","Price":{"aud":4736.99,"usd":3566.48,"nzd":5160.12,"sgd":4830.71},"Volume":4.47331033},"Time":1649023824684,"Event":"NewOrder"}
1649023824.7881868: {"Channel":"orderbook-eth","Nonce":19507,"Data":{"OrderType":"LimitOffer","OrderGuid":"6f4f303b-d535-4f9f-98af-bdbdc6fc42ec"},"Time":1649023824684,"Event":"OrderCanceled"}
1649023824.798221: {"Channel":"orderbook-eth","Nonce":19508,"Data":{"OrderType":"LimitOffer","OrderGuid":"7e31d3d7-603b-4518-9e2c-351238d71dbc","Price":{"aud":4749.99,"usd":3576.27,"nzd":5174.29,"sgd":4843.97},"Volume":7.96},"Time":1649023824700,"Event":"NewOrder"}
1649023824.7983098: {"Channel":"orderbook-bch","Nonce":8335,"Data":{"OrderType":"LimitBid","OrderGuid":"311fcbdd-8e1b-4bb2-baec-9bb6987afc24","Price":{"aud":503.1,"usd":375.01,"nzd":541.43,"sgd":509.89},"Volume":6.0},"Time":1649023824700,"Event":"NewOrder"}
1649023824.8201568: {"Channel":"orderbook-bch","Nonce":8336,"Data":{"OrderType":"LimitOffer","OrderGuid":"701a10e1-c088-4ef1-96a7-0f52b47eac92","Price":{"aud":510.72,"usd":384.53,"nzd":556.34,"sgd":520.83},"Volume":2.93},"Time":1649023824716,"Event":"NewOrder"}
1649023824.820726: {"Channel":"orderbook-eth","Nonce":19509,"Data":{"OrderType":"LimitBid","OrderGuid":"db3b88ec-774f-4b15-b452-a163caaa36a7","Price":{"aud":4726.8,"usd":3523.35,"nzd":5086.98,"sgd":4790.61},"Volume":15.0},"Time":1649023824716,"Event":"NewOrder"}
1649023824.8318841: {"Channel":"orderbook-dot","Nonce":5016,"Data":{"OrderType":"LimitBid","OrderGuid":"ca34e78f-243c-4b66-ab2f-c34053448572"},"Time":1649023824732,"Event":"OrderCanceled"}
1649023824.831939: {"Channel":"orderbook-eth","Nonce":19510,"Data":{"OrderType":"LimitBid","OrderGuid":"acf1d245-9f8e-4e66-8abf-7de3bf27eb3c","Price":{"aud":4723.8,"usd":3521.12,"nzd":5083.75,"sgd":4787.57},"Volume":15.0},"Time":1649023824732,"Event":"NewOrder"}
1649023824.868027: {"Channel":"orderbook-bch","Nonce":8337,"Data":{"OrderType":"LimitOffer","OrderGuid":"618b9a18-6440-4280-8a9c-42731b3e657f","Price":{"aud":510.71,"usd":384.52,"nzd":556.33,"sgd":520.82},"Volume":21.20858658},"Time":1649023824765,"Event":"NewOrder"}
1649023824.8779469: {"Channel":"orderbook-bch","Nonce":8338,"Data":{"OrderType":"LimitOffer","OrderGuid":"e190e060-5fed-4880-ae60-99c33e902b61"},"Time":1649023824765,"Event":"OrderCanceled"}
1649023824.888576: {"Channel":"orderbook-eth","Nonce":19511,"Data":{"OrderType":"LimitOffer","OrderGuid":"d3d3e339-3931-4c6f-a024-5026690d0df7"},"Time":1649023824781,"Event":"OrderCanceled"}
1649023824.8943932: {"Channel":"orderbook-eth","Nonce":19512,"Data":{"OrderType":"LimitOffer","OrderGuid":"b1f49238-5e31-4f68-92c6-c2535f7495cb"},"Time":1649023824796,"Event":"OrderCanceled"}
1649023824.894473: {"Channel":"orderbook-eth","Nonce":19513,"Data":{"OrderType":"LimitBid","OrderGuid":"04926c95-f7b3-47a0-973e-1fad611c419c"},"Time":1649023824796,"Event":"OrderCanceled"}
1649023824.917779: {"Channel":"orderbook-matic","Nonce":5923,"Data":{"OrderType":"LimitBid","OrderGuid":"085edc5b-61fc-40ff-b2a1-6099b8e7c72e"},"Time":1649023824812,"Event":"OrderCanceled"}
1649023824.939726: {"Channel":"orderbook-bch","Nonce":8339,"Data":{"OrderType":"LimitOffer","OrderGuid":"d74d9b65-92e7-47b3-8c88-58adb7d13173"},"Time":1649023824828,"Event":"OrderCanceled"}
1649023824.939837: {"Channel":"orderbook-eth","Nonce":19514,"Data":{"OrderType":"LimitOffer","OrderGuid":"447c5c11-bb7f-40e4-8427-6ee26a214dd0","Price":{"aud":4794.44,"usd":3573.77,"nzd":5197.46,"sgd":4864.26},"Volume":0.56392814},"Time":1649023824828,"Event":"NewOrder"}
1649023824.9509041: {"Channel":"orderbook-bch","Nonce":8340,"Data":{"OrderType":"LimitOffer","OrderGuid":"96fda58d-c2c6-4a6c-913a-abedd6ca3548"},"Time":1649023824843,"Event":"OrderCanceled"}
1649023824.951033: {"Channel":"orderbook-bch","Nonce":8341,"Data":{"OrderType":"LimitBid","OrderGuid":"12eedaa3-9be1-4336-aba0-f1be80e76492"},"Time":1649023824843,"Event":"OrderCanceled"}
1649023824.953693: {"Channel":"orderbook-bch","Nonce":8342,"Data":{"OrderType":"LimitBid","OrderGuid":"311fcbdd-8e1b-4bb2-baec-9bb6987afc24"},"Time":1649023824843,"Event":"OrderCanceled"}
1649023824.965919: {"Channel":"orderbook-eth","Nonce":19515,"Data":{"OrderType":"LimitOffer","OrderGuid":"8a2e161f-7589-4d65-8f01-d4689438fe4b","Price":{"aud":4759.11,"usd":3565.2,"nzd":5153.16,"sgd":4823.35},"Volume":1.13087495},"Time":1649023824859,"Event":"NewOrder"}
1649023824.973194: {"Channel":"orderbook-eth","Nonce":19516,"Data":{"OrderType":"LimitBid","OrderGuid":"9e1179cf-72e9-47a4-a840-45efb62f3b0a","Price":{"aud":4698.11,"usd":3519.99,"nzd":5087.14,"sgd":4791.06},"Volume":3.09167807},"Time":1649023824875,"Event":"NewOrder"}
1649023824.978676: {"Channel":"orderbook-bch","Nonce":8343,"Data":{"OrderType":"LimitOffer","OrderGuid":"94a252d5-5675-4d19-a758-e6bf1cafa11e","Price":{"aud":506.7,"usd":381.5,"nzd":551.97,"sgd":516.73},"Volume":6.0},"Time":1649023824875,"Event":"NewOrder"}
1649023824.9962099: {"Channel":"orderbook-bch","Nonce":8344,"Data":{"OrderType":"LimitBid","OrderGuid":"55713c8c-e760-4a21-9443-512e2cfc22db","Price":{"aud":504.1,"usd":375.75,"nzd":542.51,"sgd":510.9},"Volume":6.0},"Time":1649023824890,"Event":"NewOrder"}
1649023825.000148: {"Channel":"orderbook-matic","Nonce":5924,"Data":{"OrderType":"LimitBid","OrderGuid":"fc6b4097-b7db-44cb-a0a8-17d35229e6ff","Price":{"aud":2.26202,"usd":1.6861,"nzd":2.43438,"sgd":2.29255},"Volume":5500.21073},"Time":1649023824890,"Event":"NewOrder"}
1649023825.014603: {"Channel":"orderbook-bch","Nonce":8345,"Data":{"OrderType":"LimitBid","OrderGuid":"70ee4b46-25bd-4293-82d7-f9f4ec460edc","Price":{"aud":503.4,"usd":375.23,"nzd":541.75,"sgd":510.19},"Volume":6.0},"Time":1649023824906,"Event":"NewOrder"}
1649023825.053928: {"Channel":"orderbook-eth","Nonce":19517,"Data":{"OrderType":"LimitBid","OrderGuid":"ad594b4d-d975-41e4-8d16-c464f081860c"},"Time":1649023824953,"Event":"OrderCanceled"}
1649023825.0936918: {"Channel":"orderbook-bch","Nonce":8346,"Data":{"OrderType":"LimitOffer","OrderGuid":"4b91dd63-310d-4934-aa24-089f33ca4e40","Price":{"aud":507.4,"usd":382.03,"nzd":552.73,"sgd":517.44},"Volume":6.0},"Time":1649023824984,"Event":"NewOrder"}
1649023825.096704: {"Channel":"orderbook-eth","Nonce":19518,"Data":{"OrderType":"LimitBid","OrderGuid":"db3b88ec-774f-4b15-b452-a163caaa36a7"},"Time":1649023825000,"Event":"OrderCanceled"}
1649023825.110861: {"Channel":"orderbook-eth","Nonce":19519,"Data":{"OrderType":"LimitBid","OrderGuid":"acf1d245-9f8e-4e66-8abf-7de3bf27eb3c"},"Time":1649023825015,"Event":"OrderCanceled"}
1649023825.112781: {"Channel":"orderbook-eth","Nonce":19520,"Data":{"OrderType":"LimitOffer","OrderGuid":"0f2d1bd3-3c40-42d0-a6eb-3af1d6a25658"},"Time":1649023825015,"Event":"OrderCanceled"}
1649023825.130065: {"Channel":"orderbook-eth","Nonce":19521,"Data":{"OrderType":"LimitBid","OrderGuid":"a4d1032c-3440-4d49-bacb-47f4b94bf1d9"},"Time":1649023825031,"Event":"OrderCanceled"}
1649023825.1373591: {"Channel":"orderbook-matic","Nonce":5925,"Data":{"OrderType":"LimitBid","OrderGuid":"651689d9-dd0d-4509-8dba-e69238e3f22e","Price":{"aud":2.22232,"usd":1.65651,"nzd":2.39166,"sgd":2.25232},"Volume":1727.0},"Time":1649023825031,"Event":"NewOrder"}
1649023825.177414: {"Channel":"orderbook-bch","Nonce":8347,"Data":{"OrderType":"LimitOffer","OrderGuid":"950adf20-1fd6-40f6-8a95-26735230ca28","Price":{"aud":507.68,"usd":382.24,"nzd":553.03,"sgd":517.73},"Volume":1.0929415},"Time":1649023825078,"Event":"NewOrder"}
