1626994947.7538712: {"feed":"book","product_id":"PI_ETHUSD","side":"buy","seq":26662935,"price":1985.1,"qty":0.0,"timestamp":1626994947765}
1626994947.7539961: {"feed":"book","product_id":"PI_ETHUSD","side":"buy","seq":26662936,"price":1985.1,"qty":66950.0,"timestamp":1626994947765}
1626994947.754061: {"feed":"book","product_id":"PI_ETHUSD","side":"sell","seq":26662937,"price":2021.45,"qty":0.0,"timestamp":1626994947765}
1626994947.754116: {"feed":"book","product_id":"PI_ETHUSD","side":"sell","seq":26662938,"price":2021.45,"qty":67947.0,"timestamp":1626994947765}
1626994947.767971: {"feed":"book","product_id":"PI_LTCUSD","side":"buy","seq":3423327,"price":119.28,"qty":29047.0,"timestamp":1626994947788}
1626994947.768081: {"feed":"book","product_id":"PI_LTCUSD","side":"buy","seq":3423328,"price":119.38,"qty":8271.0,"timestamp":1626994947789}
1626994947.76813: {"feed":"book","product_id":"PI_LTCUSD","side":"buy","seq":3423329,"price":119.36,"qty":3811.0,"timestamp":1626994947789}
1626994947.768411: {"feed":"book","product_id":"PI_LTCUSD","side":"buy","seq":3423330,"price":119.33,"qty":11997.0,"timestamp":1626994947789}
1626994947.8947358: {"feed":"book","product_id":"FI_XBTUSD_210924","side":"sell","seq":13502288,"price":32229.0,"qty":0.0,"timestamp":1626994947914}
1626994947.8948638: {"feed":"book","product_id":"FI_XBTUSD_210924","side":"sell","seq":13502289,"price":32233.0,"qty":1009.0,"timestamp":1626994947914}
1626994947.8949308: {"feed":"book","product_id":"PI_LTCUSD","side":"sell","seq":3423331,"price":119.65,"qty":0.0,"timestamp":1626994947915}
1626994947.894988: {"feed":"book","product_id":"PI_LTCUSD","side":"sell","seq":3423332,"price":119.61,"qty":4175.0,"timestamp":1626994947915}
1626994947.898457: {"feed":"book","product_id":"PI_LTCUSD","side":"sell","seq":3423333,"price":119.63,"qty":12832.0,"timestamp":1626994947916}
1626994947.898565: {"feed":"book","product_id":"PI_LTCUSD","side":"sell","seq":3423334,"price":119.7,"qty":19821.0,"timestamp":1626994947916}
1626994947.898622: {"feed":"book","product_id":"FI_XBTUSD_210924","side":"buy","seq":13502290,"price":32039.0,"qty":0.0,"timestamp":1626994947917}
1626994947.89868: {"feed":"book","product_id":"FI_XBTUSD_210924","side":"buy","seq":13502291,"price":32077.0,"qty":108000.0,"timestamp":1626994947917}
1626994947.9056242: {"feed":"book","product_id":"FI_XBTUSD_210924","side":"sell","seq":13502292,"price":32237.0,"qty":0.0,"timestamp":1626994947925}
1626994947.905746: {"feed":"book","product_id":"FI_XBTUSD_210924","side":"sell","seq":13502293,"price":32245.5,"qty":925.0,"timestamp":1626994947925}
1626994947.9057999: {"feed":"book","product_id":"FI_XBTUSD_210924","side":"buy","seq":13502294,"price":32039.5,"qty":0.0,"timestamp":1626994947925}
1626994947.9058502: {"feed":"book","product_id":"FI_XBTUSD_210924","side":"buy","seq":13502295,"price":32019.0,"qty":250002.0,"timestamp":1626994947925}
1626994947.9059: {"feed":"book","product_id":"PI_ETHUSD","side":"sell","seq":26662939,"price":2013.6,"qty":0.0,"timestamp":1626994947926}
1626994947.9059489: {"feed":"book","product_id":"PI_ETHUSD","side":"sell","seq":26662940,"price":2013.5,"qty":500002.0,"timestamp":1626994947926}
1626994947.905993: {"feed":"book","product_id":"FI_ETHUSD_211231","side":"sell","seq":2199150,"price":2048.55,"qty":0.0,"timestamp":1626994947926}
1626994947.9060469: {"feed":"book","product_id":"FI_ETHUSD_211231","side":"sell","seq":2199151,"price":2048.45,"qty":250002.0,"timestamp":1626994947926}
1626994947.912972: {"feed":"book","product_id":"FI_XBTUSD_210924","side":"sell","seq":13502296,"price":32285.0,"qty":0.0,"timestamp":1626994947932}
1626994947.9130938: {"feed":"book","product_id":"FI_XBTUSD_210924","side":"sell","seq":13502297,"price":32289.0,"qty":23000.0,"timestamp":1626994947932}
1626994947.913147: {"feed":"book","product_id":"PI_ETHUSD","side":"buy","seq":26662941,"price":2003.1,"qty":14983.0,"timestamp":1626994947932}
1626994947.921661: {"feed":"book","product_id":"FI_ETHUSD_210730","side":"buy","seq":2138820,"price":1999.75,"qty":0.0,"timestamp":1626994947942}
1626994947.9217842: {"feed":"book","product_id":"FI_XBTUSD_210730","side":"buy","seq":5160185,"price":32152.0,"qty":0.0,"timestamp":1626994947942}
1626994947.962703: {"feed":"book","product_id":"FI_XBTUSD_210924","side":"sell","seq":13502298,"price":32246.0,"qty":0.0,"timestamp":1626994947983}
1626994947.962827: {"feed":"book","product_id":"FI_XBTUSD_210924","side":"sell","seq":13502299,"price":32246.0,"qty":14929.0,"timestamp":1626994947983}
1626994947.9633331: {"feed":"book","product_id":"FI_XBTUSD_210924","side":"buy","seq":13502300,"price":32195.5,"qty":0.0,"timestamp":1626994947983}
1626994947.963392: {"feed":"book","product_id":"FI_XBTUSD_210924","side":"buy","seq":13502301,"price":32195.5,"qty":17463.0,"timestamp":1626994947983}
1626994947.963428: {"feed":"book","product_id":"FI_XBTUSD_210924","side":"buy","seq":13502302,"price":32174.0,"qty":3000.0,"timestamp":1626994947983}
1626994947.963454: {"feed":"book","product_id":"FI_XBTUSD_210924","side":"buy","seq":13502303,"price":32174.0,"qty":23909.0,"timestamp":1626994947983}
1626994947.963476: {"feed":"book","product_id":"FI_XBTUSD_210924","side":"sell","seq":13502304,"price":32281.5,"qty":0.0,"timestamp":1626994947983}
1626994947.9635048: {"feed":"book","product_id":"FI_XBTUSD_210924","side":"sell","seq":13502305,"price":32281.5,"qty":20966.0,"timestamp":1626994947983}
1626994947.966911: {"feed":"book","product_id":"PI_ETHUSD","side":"sell","seq":26662942,"price":2007.1,"qty":5000.0,"timestamp":1626994947986}
1626994947.966986: {"feed":"book","product_id":"PI_ETHUSD","side":"sell","seq":26662943,"price":2007.1,"qty":18414.0,"timestamp":1626994947986}
1626994947.967018: {"feed":"book","product_id":"PI_ETHUSD","side":"buy","seq":26662944,"price":2001.85,"qty":5005.0,"timestamp":1626994947986}
1626994947.967045: {"feed":"book","product_id":"PI_ETHUSD","side":"buy","seq":26662945,"price":2001.85,"qty":18919.0,"timestamp":1626994947986}
1626994947.9670668: {"feed":"book","product_id":"FI_XBTUSD_210924","side":"sell","seq":13502306,"price":32289.0,"qty":3000.0,"timestamp":1626994947987}
1626994947.96709: {"feed":"book","product_id":"FI_XBTUSD_210924","side":"sell","seq":13502307,"price":32285.0,"qty":20000.0,"timestamp":1626994947987}
1626994947.9671302: {"feed":"book","product_id":"PI_ETHUSD","side":"buy","seq":26662946,"price":2001.5,"qty":0.0,"timestamp":1626994947986}
1626994947.967166: {"feed":"book","product_id":"PI_ETHUSD","side":"buy","seq":26662947,"price":2001.5,"qty":15952.0,"timestamp":1626994947986}
1626994947.9671931: {"feed":"book","product_id":"PI_ETHUSD","side":"sell","seq":26662948,"price":2007.7,"qty":8742.0,"timestamp":1626994947986}
1626994947.967215: {"feed":"book","product_id":"PI_ETHUSD","side":"sell","seq":26662949,"price":2007.7,"qty":26045.0,"timestamp":1626994947986}
1626994947.967235: {"feed":"book","product_id":"PI_ETHUSD","side":"sell","seq":26662950,"price":2008.45,"qty":0.0,"timestamp":1626994947986}
1626994947.967263: {"feed":"book","product_id":"PI_ETHUSD","side":"sell","seq":26662951,"price":2008.45,"qty":23265.0,"timestamp":1626994947986}
1626994947.967289: {"feed":"book","product_id":"PI_ETHUSD","side":"buy","seq":26662952,"price":2000.55,"qty":0.0,"timestamp":1626994947986}
1626994947.967316: {"feed":"book","product_id":"PI_ETHUSD","side":"buy","seq":26662953,"price":2000.55,"qty":23426.0,"timestamp":1626994947986}
1626994947.96734: {"feed":"book","product_id":"PI_ETHUSD","side":"buy","seq":26662954,"price":1996.5,"qty":0.0,"timestamp":1626994947986}
1626994947.967367: {"feed":"book","product_id":"PI_ETHUSD","side":"buy","seq":26662955,"price":1996.5,"qty":45483.0,"timestamp":1626994947986}
1626994948.0929012: {"feed":"book","product_id":"FI_XBTUSD_210924","side":"buy","seq":13502308,"price":32182.5,"qty":3000.0,"timestamp":1626994948112}
1626994948.093025: {"feed":"book","product_id":"FI_ETHUSD_210730","side":"buy","seq":2138821,"price":1997.7,"qty":0.0,"timestamp":1626994948112}
1626994948.0930932: {"feed":"book","product_id":"FI_ETHUSD_210730","side":"buy","seq":2138822,"price":1998.4,"qty":2057.0,"timestamp":1626994948112}
1626994948.0931442: {"feed":"book","product_id":"PI_ETHUSD","side":"buy","seq":26662956,"price":2001.2,"qty":150000.0,"timestamp":1626994948112}
1626994948.093185: {"feed":"book","product_id":"PI_ETHUSD","side":"buy","seq":26662957,"price":2001.85,"qty":23638.0,"timestamp":1626994948112}
1626994948.0957: {"feed":"book","product_id":"PI_ETHUSD","side":"sell","seq":26662958,"price":2008.5,"qty":150000.0,"timestamp":1626994948113}
1626994948.095775: {"feed":"book","product_id":"PI_ETHUSD","side":"buy","seq":26662959,"price":2003.65,"qty":3866.0,"timestamp":1626994948114}
1626994948.095807: {"feed":"book","product_id":"PI_ETHUSD","side":"buy","seq":26662960,"price":2003.75,"qty":20000.0,"timestamp":1626994948114}
1626994948.095843: {"feed":"book","product_id":"PI_ETHUSD","side":"buy","seq":26662961,"price":2003.7,"qty":0.0,"timestamp":1626994948114}
1626994948.095878: {"feed":"book","product_id":"PI_ETHUSD","side":"buy","seq":26662962,"price":2003.8,"qty":15826.0,"timestamp":1626994948114}
1626994948.112351: {"feed":"book","product_id":"PI_ETHUSD","side":"sell","seq":26662963,"price":2008.5,"qty":157310.0,"timestamp":1626994948132}
1626994948.124328: {"feed":"book","product_id":"PI_ETHUSD","side":"buy","seq":26662964,"price":2003.1,"qty":10000.0,"timestamp":1626994948145}
1626994948.199271: {"feed":"book","product_id":"PI_ETHUSD","side":"sell","seq":26662965,"price":2013.55,"qty":0.0,"timestamp":1626994948219}
1626994948.199399: {"feed":"book","product_id":"PI_ETHUSD","side":"sell","seq":26662966,"price":2013.45,"qty":48795.0,"timestamp":1626994948219}
1626994948.199465: {"feed":"book","product_id":"PI_ETHUSD","side":"sell","seq":26662967,"price":2007.1,"qty":5000.0,"timestamp":1626994948219}
1626994948.199508: {"feed":"book","product_id":"PI_ETHUSD","side":"sell","seq":26662968,"price":2007.1,"qty":18416.0,"timestamp":1626994948219}
1626994948.199543: {"feed":"book","product_id":"PI_ETHUSD","side":"buy","seq":26662969,"price":2001.85,"qty":9724.0,"timestamp":1626994948219}
1626994948.199577: {"feed":"book","product_id":"PI_ETHUSD","side":"buy","seq":26662970,"price":2001.85,"qty":23636.0,"timestamp":1626994948219}
1626994948.202198: {"feed":"book","product_id":"PI_ETHUSD","side":"buy","seq":26662971,"price":2001.5,"qty":0.0,"timestamp":1626994948219}
1626994948.2023292: {"feed":"book","product_id":"PI_ETHUSD","side":"buy","seq":26662972,"price":2001.5,"qty":15950.0,"timestamp":1626994948219}
1626994948.202419: {"feed":"book","product_id":"PI_ETHUSD","side":"sell","seq":26662973,"price":2007.7,"qty":8742.0,"timestamp":1626994948219}
1626994948.202462: {"feed":"book","product_id":"PI_ETHUSD","side":"sell","seq":26662974,"price":2007.7,"qty":26047.0,"timestamp":1626994948219}
1626994948.202529: {"feed":"book","product_id":"PI_ETHUSD","side":"sell","seq":26662975,"price":2008.45,"qty":0.0,"timestamp":1626994948219}
1626994948.202563: {"feed":"book","product_id":"PI_ETHUSD","side":"sell","seq":26662976,"price":2008.45,"qty":23267.0,"timestamp":1626994948219}
1626994948.202592: {"feed":"book","product_id":"PI_ETHUSD","side":"buy","seq":26662977,"price":2000.55,"qty":0.0,"timestamp":1626994948219}
1626994948.2026198: {"feed":"book","product_id":"PI_ETHUSD","side":"buy","seq":26662978,"price":2000.55,"qty":23425.0,"timestamp":1626994948219}
1626994948.212864: {"feed":"book","product_id":"PI_ETHUSD","side":"buy","seq":26662979,"price":2003.3,"qty":4253.0,"timestamp":1626994948234}
1626994948.257805: {"feed":"book","product_id":"FI_XBTUSD_210924","side":"sell","seq":13502309,"price":32246.0,"qty":0.0,"timestamp":1626994948276}
1626994948.257928: {"feed":"book","product_id":"FI_XBTUSD_210924","side":"sell","seq":13502310,"price":32246.0,"qty":14658.0,"timestamp":1626994948276}
1626994948.2579908: {"feed":"book","product_id":"FI_XBTUSD_210924","side":"buy","seq":13502311,"price":32195.5,"qty":0.0,"timestamp":1626994948276}
1626994948.258045: {"feed":"book","product_id":"FI_XBTUSD_210924","side":"buy","seq":13502312,"price":32195.5,"qty":17733.0,"timestamp":1626994948276}
1626994948.25809: {"feed":"book","product_id":"FI_XBTUSD_210924","side":"buy","seq":13502313,"price":32174.0,"qty":3000.0,"timestamp":1626994948277}
1626994948.2581272: {"feed":"book","product_id":"FI_XBTUSD_210924","side":"buy","seq":13502314,"price":32174.0,"qty":23910.0,"timestamp":1626994948277}
1626994948.2611158: {"feed":"book","product_id":"FI_XBTUSD_210924","side":"sell","seq":13502315,"price":32281.5,"qty":0.0,"timestamp":1626994948277}
1626994948.261238: {"feed":"book","product_id":"FI_XBTUSD_210924","side":"sell","seq":13502316,"price":32281.5,"qty":20967.0,"timestamp":1626994948277}
1626994948.2613: {"feed":"book","product_id":"FI_XBTUSD_210924","side":"sell","seq":13502317,"price":32285.0,"qty":0.0,"timestamp":1626994948280}
1626994948.2613492: {"feed":"book","product_id":"FI_XBTUSD_210924","side":"sell","seq":13502318,"price":32289.0,"qty":23000.0,"timestamp":1626994948280}
1626994948.301451: {"feed":"book","product_id":"FI_XBTUSD_210924","side":"sell","seq":13502319,"price":32245.5,"qty":924.0,"timestamp":1626994948322}
1626994948.301559: {"feed":"book","product_id":"FI_XBTUSD_210924","side":"sell","seq":13502320,"price":32236.5,"qty":1.0,"timestamp":1626994948322}
1626994948.312852: {"feed":"book","product_id":"PI_ETHUSD","side":"sell","seq":26662980,"price":2013.5,"qty":0.0,"timestamp":1626994948328}
1626994948.3129432: {"feed":"book","product_id":"PI_ETHUSD","side":"sell","seq":26662981,"price":2013.4,"qty":500002.0,"timestamp":1626994948328}
1626994948.3161511: {"feed":"book","product_id":"FI_ETHUSD_210730","side":"buy","seq":2138823,"price":1999.7,"qty":273.0,"timestamp":1626994948336}
1626994948.404136: {"feed":"book","product_id":"PI_ETHUSD","side":"buy","seq":26662982,"price":2001.5,"qty":0.0,"timestamp":1626994948423}
1626994948.404261: {"feed":"book","product_id":"PI_ETHUSD","side":"buy","seq":26662983,"price":2001.5,"qty":15958.0,"timestamp":1626994948423}
1626994948.4043279: {"feed":"book","product_id":"PI_ETHUSD","side":"sell","seq":26662984,"price":2007.7,"qty":8742.0,"timestamp":1626994948423}
1626994948.4043698: {"feed":"book","product_id":"PI_ETHUSD","side":"sell","seq":26662985,"price":2007.7,"qty":26039.0,"timestamp":1626994948423}
1626994948.404414: {"feed":"book","product_id":"PI_ETHUSD","side":"sell","seq":26662986,"price":2007.1,"qty":5000.0,"timestamp":1626994948423}
1626994948.404456: {"feed":"book","product_id":"PI_ETHUSD","side":"sell","seq":26662987,"price":2007.1,"qty":18410.0,"timestamp":1626994948423}
1626994948.404476: {"feed":"book","product_id":"PI_ETHUSD","side":"buy","seq":26662988,"price":2001.85,"qty":9724.0,"timestamp":1626994948423}
1626994948.404497: {"feed":"book","product_id":"PI_ETHUSD","side":"buy","seq":26662989,"price":2001.85,"qty":23642.0,"timestamp":1626994948423}
1626994948.404843: {"feed":"book","product_id":"PI_ETHUSD","side":"sell","seq":26662990,"price":2008.45,"qty":0.0,"timestamp":1626994948423}
1626994948.4048982: {"feed":"book","product_id":"PI_ETHUSD","side":"sell","seq":26662991,"price":2008.45,"qty":23261.0,"timestamp":1626994948423}
1626994948.404931: {"feed":"book","product_id":"PI_ETHUSD","side":"buy","seq":26662992,"price":2000.55,"qty":0.0,"timestamp":1626994948423}
1626994948.404962: {"feed":"book","product_id":"PI_ETHUSD","side":"buy","seq":26662993,"price":2000.55,"qty":23430.0,"timestamp":1626994948423}
1626994948.405201: {"feed":"book","product_id":"PI_ETHUSD","side":"buy","seq":26662994,"price":1996.5,"qty":0.0,"timestamp":1626994948423}
1626994948.405249: {"feed":"book","product_id":"PI_ETHUSD","side":"buy","seq":26662995,"price":1996.5,"qty":45486.0,"timestamp":1626994948423}
1626994948.407412: {"feed":"book","product_id":"PI_ETHUSD","side":"sell","seq":26662996,"price":2013.45,"qty":0.0,"timestamp":1626994948423}
1626994948.4075341: {"feed":"book","product_id":"PI_ETHUSD","side":"sell","seq":26662997,"price":2013.45,"qty":48792.0,"timestamp":1626994948423}
1626994948.4837298: {"feed":"book","product_id":"PI_ETHUSD","side":"sell","seq":26662998,"price":2006.2,"qty":0.0,"timestamp":1626994948503}
1626994948.485142: {"feed":"book","product_id":"PI_ETHUSD","side":"sell","seq":26662999,"price":2006.4,"qty":90543.0,"timestamp":1626994948504}
1626994948.490398: {"feed":"book","product_id":"FI_XBTUSD_210924","side":"sell","seq":13502321,"price":32246.0,"qty":0.0,"timestamp":1626994948511}
1626994948.490497: {"feed":"book","product_id":"FI_XBTUSD_210924","side":"sell","seq":13502322,"price":32246.0,"qty":14627.0,"timestamp":1626994948511}
1626994948.490575: {"feed":"book","product_id":"FI_XBTUSD_210924","side":"buy","seq":13502323,"price":32195.5,"qty":0.0,"timestamp":1626994948511}
1626994948.490628: {"feed":"book","product_id":"FI_XBTUSD_210924","side":"buy","seq":13502324,"price":32195.5,"qty":17764.0,"timestamp":1626994948511}
1626994948.607717: {"feed":"book","product_id":"PI_ETHUSD","side":"buy","seq":26663000,"price":2001.85,"qty":9724.0,"timestamp":1626994948627}
1626994948.60783: {"feed":"book","product_id":"PI_ETHUSD","side":"buy","seq":26663001,"price":2001.9,"qty":13948.0,"timestamp":1626994948627}
1626994948.610303: {"feed":"book","product_id":"PI_ETHUSD","side":"sell","seq":26663002,"price":2013.45,"qty":0.0,"timestamp":1626994948627}
1626994948.610443: {"feed":"book","product_id":"PI_ETHUSD","side":"sell","seq":26663003,"price":2013.35,"qty":48287.0,"timestamp":1626994948627}
1626994948.610487: {"feed":"book","product_id":"PI_ETHUSD","side":"buy","seq":26663004,"price":2001.5,"qty":0.0,"timestamp":1626994948627}
1626994948.610522: {"feed":"book","product_id":"PI_ETHUSD","side":"buy","seq":26663005,"price":2001.5,"qty":16423.0,"timestamp":1626994948627}
1626994948.610551: {"feed":"book","product_id":"PI_ETHUSD","side":"sell","seq":26663006,"price":2007.7,"qty":8742.0,"timestamp":1626994948628}
1626994948.610574: {"feed":"book","product_id":"PI_ETHUSD","side":"sell","seq":26663007,"price":2007.7,"qty":25570.0,"timestamp":1626994948628}
1626994948.610594: {"feed":"book","product_id":"PI_ETHUSD","side":"sell","seq":26663008,"price":2007.1,"qty":5000.0,"timestamp":1626994948628}
1626994948.610615: {"feed":"book","product_id":"PI_ETHUSD","side":"sell","seq":26663009,"price":2007.1,"qty":18098.0,"timestamp":1626994948628}
1626994948.610635: {"feed":"book","product_id":"PI_ETHUSD","side":"sell","seq":26663010,"price":2008.45,"qty":0.0,"timestamp":1626994948628}
1626994948.610661: {"feed":"book","product_id":"PI_ETHUSD","side":"sell","seq":26663011,"price":2008.45,"qty":22948.0,"timestamp":1626994948628}
1626994948.610687: {"feed":"book","product_id":"PI_ETHUSD","side":"buy","seq":26663012,"price":2000.55,"qty":0.0,"timestamp":1626994948628}
1626994948.6107142: {"feed":"book","product_id":"PI_ETHUSD","side":"buy","seq":26663013,"price":2000.55,"qty":23739.0,"timestamp":1626994948628}
1626994948.610739: {"feed":"book","product_id":"PI_ETHUSD","side":"buy","seq":26663014,"price":1996.5,"qty":0.0,"timestamp":1626994948628}
1626994948.610764: {"feed":"book","product_id":"PI_ETHUSD","side":"buy","seq":26663015,"price":1996.5,"qty":45661.0,"timestamp":1626994948628}
1626994948.610789: {"feed":"book","product_id":"PI_ETHUSD","side":"buy","seq":26663016,"price":1985.1,"qty":0.0,"timestamp":1626994948628}
1626994948.610813: {"feed":"book","product_id":"PI_ETHUSD","side":"buy","seq":26663017,"price":1985.1,"qty":66952.0,"timestamp":1626994948628}
1626994948.610837: {"feed":"book","product_id":"PI_ETHUSD","side":"sell","seq":26663018,"price":2021.45,"qty":0.0,"timestamp":1626994948628}
1626994948.610862: {"feed":"book","product_id":"PI_ETHUSD","side":"sell","seq":26663019,"price":2021.45,"qty":67949.0,"timestamp":1626994948628}
1626994948.6108868: {"feed":"book","product_id":"PI_ETHUSD","side":"buy","seq":26663020,"price":2001.85,"qty":5005.0,"timestamp":1626994948632}
1626994948.6162748: {"feed":"book","product_id":"PI_ETHUSD","side":"buy","seq":26663021,"price":2001.85,"qty":9723.0,"timestamp":1626994948637}
1626994948.621645: {"feed":"book","product_id":"PI_LTCUSD","side":"buy","seq":3423335,"price":119.33,"qty":21596.0,"timestamp":1626994948642}
1626994948.7074711: {"feed":"book","product_id":"FI_ETHUSD_211231","side":"buy","seq":2199152,"price":2028.45,"qty":150.0,"timestamp":1626994948728}
1626994948.744086: {"feed":"book","product_id":"FI_XBTUSD_210924","side":"sell","seq":13502325,"price":32246.0,"qty":0.0,"timestamp":1626994948764}
1626994948.744172: {"feed":"book","product_id":"FI_XBTUSD_210924","side":"sell","seq":13502326,"price":32246.0,"qty":14658.0,"timestamp":1626994948764}
1626994948.744214: {"feed":"book","product_id":"FI_XBTUSD_210924","side":"buy","seq":13502327,"price":32195.5,"qty":0.0,"timestamp":1626994948764}
1626994948.7442482: {"feed":"book","product_id":"FI_XBTUSD_210924","side":"buy","seq":13502328,"price":32195.5,"qty":17733.0,"timestamp":1626994948764}
1626994948.786409: {"feed":"book","product_id":"PI_ETHUSD","side":"buy","seq":26663022,"price":2003.75,"qty":0.0,"timestamp":1626994948806}
1626994948.786533: {"feed":"book","product_id":"PI_ETHUSD","side":"buy","seq":26663023,"price":2003.6,"qty":20000.0,"timestamp":1626994948806}
1626994948.786598: {"feed":"book","product_id":"PI_ETHUSD","side":"buy","seq":26663024,"price":2003.8,"qty":0.0,"timestamp":1626994948807}
1626994948.786647: {"feed":"book","product_id":"PI_ETHUSD","side":"buy","seq":26663025,"price":2003.7,"qty":15826.0,"timestamp":1626994948807}
1626994948.811177: {"feed":"book","product_id":"FI_ETHUSD_211231","side":"sell","seq":2199153,"price":2048.5,"qty":44305.0,"timestamp":1626994948831}
1626994948.811285: {"feed":"book","product_id":"FI_ETHUSD_211231","side":"sell","seq":2199154,"price":2048.4,"qty":45099.0,"timestamp":1626994948831}
1626994948.811348: {"feed":"book","product_id":"FI_ETHUSD_211231","side":"sell","seq":2199155,"price":2048.5,"qty":0.0,"timestamp":1626994948831}
1626994948.811404: {"feed":"book","product_id":"FI_ETHUSD_211231","side":"sell","seq":2199156,"price":2048.4,"qty":89404.0,"timestamp":1626994948831}
1626994948.8173718: {"feed":"book","product_id":"PI_ETHUSD","side":"buy","seq":26663026,"price":2003.6,"qty":0.0,"timestamp":1626994948838}
1626994948.817496: {"feed":"book","product_id":"PI_ETHUSD","side":"buy","seq":26663027,"price":2003.7,"qty":35826.0,"timestamp":1626994948838}
1626994948.842328: {"feed":"book","product_id":"PI_ETHUSD","side":"buy","seq":26663028,"price":2001.5,"qty":0.0,"timestamp":1626994948862}
1626994948.842458: {"feed":"book","product_id":"PI_ETHUSD","side":"buy","seq":26663029,"price":2001.5,"qty":16385.0,"timestamp":1626994948862}
1626994948.8425221: {"feed":"book","product_id":"PI_ETHUSD","side":"sell","seq":26663030,"price":2007.7,"qty":8742.0,"timestamp":1626994948862}
1626994948.842564: {"feed":"book","product_id":"PI_ETHUSD","side":"sell","seq":26663031,"price":2007.7,"qty":25609.0,"timestamp":1626994948862}
1626994948.8425999: {"feed":"book","product_id":"PI_ETHUSD","side":"sell","seq":26663032,"price":2007.1,"qty":5000.0,"timestamp":1626994948862}
1626994948.842634: {"feed":"book","product_id":"PI_ETHUSD","side":"sell","seq":26663033,"price":2007.1,"qty":18124.0,"timestamp":1626994948862}
1626994948.842667: {"feed":"book","product_id":"PI_ETHUSD","side":"buy","seq":26663034,"price":2001.9,"qty":0.0,"timestamp":1626994948862}
1626994948.842711: {"feed":"book","product_id":"PI_ETHUSD","side":"buy","seq":26663035,"price":2001.9,"qty":13923.0,"timestamp":1626994948862}
1626994948.8444202: {"feed":"book","product_id":"PI_ETHUSD","side":"sell","seq":26663036,"price":2008.45,"qty":0.0,"timestamp":1626994948862}
1626994948.844544: {"feed":"book","product_id":"PI_ETHUSD","side":"sell","seq":26663037,"price":2008.45,"qty":22974.0,"timestamp":1626994948862}
1626994948.8446112: {"feed":"book","product_id":"PI_ETHUSD","side":"buy","seq":26663038,"price":2000.55,"qty":0.0,"timestamp":1626994948862}
1626994948.844666: {"feed":"book","product_id":"PI_ETHUSD","side":"buy","seq":26663039,"price":2000.55,"qty":23714.0,"timestamp":1626994948862}
1626994948.8447201: {"feed":"book","product_id":"PI_ETHUSD","side":"sell","seq":26663040,"price":2013.35,"qty":0.0,"timestamp":1626994948862}
1626994948.844773: {"feed":"book","product_id":"PI_ETHUSD","side":"sell","seq":26663041,"price":2013.35,"qty":48302.0,"timestamp":1626994948862}
1626994948.8448: {"feed":"book","product_id":"PI_ETHUSD","side":"buy","seq":26663042,"price":1996.5,"qty":0.0,"timestamp":1626994948862}
1626994948.844827: {"feed":"book","product_id":"PI_ETHUSD","side":"buy","seq":26663043,"price":1996.5,"qty":45647.0,"timestamp":1626994948862}
1626994948.852559: {"feed":"book","product_id":"PI_XRPUSD","side":"buy","seq":3456234,"price":0.5881,"qty":22186.0,"timestamp":1626994948873}
1626994948.855777: {"feed":"book","product_id":"PI_XRPUSD","side":"buy","seq":3456235,"price":0.588,"qty":8922.0,"timestamp":1626994948876}
1626994948.855884: {"feed":"book","product_id":"PI_XRPUSD","side":"buy","seq":3456236,"price":0.5881,"qty":32136.0,"timestamp":1626994948876}
1626994948.876029: {"feed":"book","product_id":"PI_ETHUSD","side":"buy","seq":26663044,"price":2003.7,"qty":20000.0,"timestamp":1626994948897}
1626994948.8761358: {"feed":"book","product_id":"PI_ETHUSD","side":"buy","seq":26663045,"price":2003.8,"qty":15826.0,"timestamp":1626994948897}
1626994948.885348: {"feed":"book","product_id":"PI_ETHUSD","side":"buy","seq":26663046,"price":2003.8,"qty":0.0,"timestamp":1626994948904}
1626994948.885472: {"feed":"book","product_id":"PI_ETHUSD","side":"buy","seq":26663047,"price":2003.7,"qty":35826.0,"timestamp":1626994948904}
1626994948.8966222: {"feed":"book","product_id":"FI_ETHUSD_211231","side":"sell","seq":2199157,"price":2034.85,"qty":0.0,"timestamp":1626994948917}
1626994948.896748: {"feed":"book","product_id":"PI_ETHUSD","side":"buy","seq":26663048,"price":2003.7,"qty":20000.0,"timestamp":1626994948917}
1626994948.896805: {"feed":"book","product_id":"PI_ETHUSD","side":"buy","seq":26663049,"price":2003.8,"qty":15826.0,"timestamp":1626994948917}
1626994948.8968582: {"feed":"book","product_id":"FI_ETHUSD_211231","side":"buy","seq":2199158,"price":2027.0,"qty":757.0,"timestamp":1626994948917}
1626994948.978164: {"feed":"book","product_id":"FI_XBTUSD_210924","side":"sell","seq":13502329,"price":32246.0,"qty":0.0,"timestamp":1626994948998}
1626994948.978289: {"feed":"book","product_id":"FI_XBTUSD_210924","side":"sell","seq":13502330,"price":32246.0,"qty":14627.0,"timestamp":1626994948998}
1626994948.978354: {"feed":"book","product_id":"FI_XBTUSD_210924","side":"buy","seq":13502331,"price":32195.5,"qty":0.0,"timestamp":1626994948998}
1626994948.9784079: {"feed":"book","product_id":"FI_XBTUSD_210924","side":"buy","seq":13502332,"price":32195.5,"qty":17764.0,"timestamp":1626994948998}
1626994949.068591: {"feed":"book","product_id":"PI_XRPUSD","side":"sell","seq":3456237,"price":0.5896,"qty":8816.0,"timestamp":1626994949090}
1626994949.068712: {"feed":"book","product_id":"PI_XRPUSD","side":"sell","seq":3456238,"price":0.5894,"qty":9116.0,"timestamp":1626994949090}
1626994949.0691252: {"feed":"book","product_id":"PI_XRPUSD","side":"buy","seq":3456239,"price":0.5875,"qty":0.0,"timestamp":1626994949090}
1626994949.0691872: {"feed":"book","product_id":"PI_XRPUSD","side":"buy","seq":3456240,"price":0.5877,"qty":1385.0,"timestamp":1626994949090}
1626994949.070378: {"feed":"book","product_id":"PI_ETHUSD","side":"buy","seq":26663050,"price":2001.5,"qty":0.0,"timestamp":1626994949090}
1626994949.070463: {"feed":"book","product_id":"PI_ETHUSD","side":"buy","seq":26663051,"price":2001.5,"qty":16148.0,"timestamp":1626994949090}
1626994949.072012: {"feed":"book","product_id":"PI_ETHUSD","side":"sell","seq":26663052,"price":2007.7,"qty":8742.0,"timestamp":1626994949091}
1626994949.072097: {"feed":"book","product_id":"PI_ETHUSD","side":"sell","seq":26663053,"price":2007.7,"qty":25848.0,"timestamp":1626994949091}
1626994949.072129: {"feed":"book","product_id":"PI_ETHUSD","side":"sell","seq":26663054,"price":2007.1,"qty":5000.0,"timestamp":1626994949091}
1626994949.072154: {"feed":"book","product_id":"PI_ETHUSD","side":"sell","seq":26663055,"price":2007.1,"qty":18283.0,"timestamp":1626994949091}
1626994949.0721762: {"feed":"book","product_id":"PI_ETHUSD","side":"buy","seq":26663056,"price":2001.9,"qty":0.0,"timestamp":1626994949091}
1626994949.0722141: {"feed":"book","product_id":"PI_ETHUSD","side":"buy","seq":26663057,"price":2001.9,"qty":13765.0,"timestamp":1626994949091}
1626994949.072245: {"feed":"book","product_id":"PI_ETHUSD","side":"sell","seq":26663058,"price":2008.45,"qty":0.0,"timestamp":1626994949091}
1626994949.0722759: {"feed":"book","product_id":"PI_ETHUSD","side":"sell","seq":26663059,"price":2008.45,"qty":23134.0,"timestamp":1626994949091}
1626994949.072598: {"feed":"book","product_id":"PI_ETHUSD","side":"buy","seq":26663060,"price":2000.55,"qty":0.0,"timestamp":1626994949091}
1626994949.07265: {"feed":"book","product_id":"PI_ETHUSD","side":"buy","seq":26663061,"price":2000.55,"qty":23556.0,"timestamp":1626994949091}
1626994949.072702: {"feed":"book","product_id":"PI_ETHUSD","side":"buy","seq":26663062,"price":1996.5,"qty":0.0,"timestamp":1626994949091}
1626994949.072732: {"feed":"book","product_id":"PI_ETHUSD","side":"buy","seq":26663063,"price":1996.5,"qty":45557.0,"timestamp":1626994949091}
1626994949.073018: {"feed":"book","product_id":"PI_ETHUSD","side":"sell","seq":26663064,"price":2013.35,"qty":0.0,"timestamp":1626994949091}
1626994949.073065: {"feed":"book","product_id":"PI_ETHUSD","side":"sell","seq":26663065,"price":2013.35,"qty":48394.0,"timestamp":1626994949091}
1626994949.076172: {"feed":"book","product_id":"PI_ETHUSD","side":"buy","seq":26663066,"price":1985.1,"qty":0.0,"timestamp":1626994949091}
1626994949.076262: {"feed":"book","product_id":"PI_ETHUSD","side":"buy","seq":26663067,"price":1985.1,"qty":66951.0,"timestamp":1626994949091}
1626994949.076307: {"feed":"book","product_id":"PI_ETHUSD","side":"sell","seq":26663068,"price":2021.45,"qty":0.0,"timestamp":1626994949091}
1626994949.076344: {"feed":"book","product_id":"PI_ETHUSD","side":"sell","seq":26663069,"price":2021.45,"qty":67948.0,"timestamp":1626994949091}
1626994949.151814: {"feed":"book","product_id":"FI_XBTUSD_210730","side":"sell","seq":5160186,"price":32253.0,"qty":580.0,"timestamp":1626994949173}
1626994949.2155252: {"feed":"book","product_id":"FI_XBTUSD_210924","side":"sell","seq":13502333,"price":32246.0,"qty":0.0,"timestamp":1626994949233}
1626994949.21565: {"feed":"book","product_id":"FI_XBTUSD_210924","side":"sell","seq":13502334,"price":32246.0,"qty":14650.0,"timestamp":1626994949233}
1626994949.215712: {"feed":"book","product_id":"FI_XBTUSD_210924","side":"buy","seq":13502335,"price":32195.5,"qty":0.0,"timestamp":1626994949233}
1626994949.215762: {"feed":"book","product_id":"FI_XBTUSD_210924","side":"buy","seq":13502336,"price":32195.5,"qty":17741.0,"timestamp":1626994949233}
1626994949.2889512: {"feed":"book","product_id":"PI_ETHUSD","side":"buy","seq":26663070,"price":2003.8,"qty":0.0,"timestamp":1626994949308}
1626994949.2890382: {"feed":"book","product_id":"PI_ETHUSD","side":"buy","seq":26663071,"price":2003.7,"qty":35826.0,"timestamp":1626994949308}
1626994949.3078039: {"feed":"book","product_id":"PI_ETHUSD","side":"buy","seq":26663072,"price":2001.5,"qty":0.0,"timestamp":1626994949325}
1626994949.307891: {"feed":"book","product_id":"PI_ETHUSD","side":"buy","seq":26663073,"price":2001.5,"qty":16349.0,"timestamp":1626994949325}
1626994949.307932: {"feed":"book","product_id":"PI_ETHUSD","side":"sell","seq":26663074,"price":2007.7,"qty":8742.0,"timestamp":1626994949325}
1626994949.307959: {"feed":"book","product_id":"PI_ETHUSD","side":"sell","seq":26663075,"price":2007.7,"qty":25645.0,"timestamp":1626994949325}
1626994949.307981: {"feed":"book","product_id":"PI_ETHUSD","side":"sell","seq":26663076,"price":2007.1,"qty":5000.0,"timestamp":1626994949325}
1626994949.308002: {"feed":"book","product_id":"PI_ETHUSD","side":"sell","seq":26663077,"price":2007.1,"qty":18148.0,"timestamp":1626994949325}
1626994949.308022: {"feed":"book","product_id":"PI_ETHUSD","side":"buy","seq":26663078,"price":2001.9,"qty":0.0,"timestamp":1626994949325}
1626994949.30805: {"feed":"book","product_id":"PI_ETHUSD","side":"buy","seq":26663079,"price":2001.9,"qty":13899.0,"timestamp":1626994949325}
1626994949.3080761: {"feed":"book","product_id":"PI_ETHUSD","side":"sell","seq":26663080,"price":2008.45,"qty":0.0,"timestamp":1626994949325}
1626994949.308105: {"feed":"book","product_id":"PI_ETHUSD","side":"sell","seq":26663081,"price":2008.45,"qty":22998.0,"timestamp":1626994949325}
1626994949.308131: {"feed":"book","product_id":"PI_ETHUSD","side":"buy","seq":26663082,"price":2000.55,"qty":0.0,"timestamp":1626994949325}
1626994949.308161: {"feed":"book","product_id":"PI_ETHUSD","side":"buy","seq":26663083,"price":2000.55,"qty":23690.0,"timestamp":1626994949325}
1626994949.31006: {"feed":"book","product_id":"PI_ETHUSD","side":"buy","seq":26663084,"price":1996.5,"qty":0.0,"timestamp":1626994949325}
1626994949.310109: {"feed":"book","product_id":"PI_ETHUSD","side":"buy","seq":26663085,"price":1996.5,"qty":45633.0,"timestamp":1626994949325}
1626994949.310152: {"feed":"book","product_id":"PI_ETHUSD","side":"sell","seq":26663086,"price":2013.35,"qty":0.0,"timestamp":1626994949325}
1626994949.3101811: {"feed":"book","product_id":"PI_ETHUSD","side":"sell","seq":26663087,"price":2013.35,"qty":48316.0,"timestamp":1626994949325}
1626994949.310205: {"feed":"book","product_id":"PI_ETHUSD","side":"buy","seq":26663088,"price":1985.1,"qty":0.0,"timestamp":1626994949325}
1626994949.3102279: {"feed":"book","product_id":"PI_ETHUSD","side":"buy","seq":26663089,"price":1985.1,"qty":66952.0,"timestamp":1626994949325}
1626994949.31025: {"feed":"book","product_id":"PI_ETHUSD","side":"sell","seq":26663090,"price":2021.45,"qty":0.0,"timestamp":1626994949325}
1626994949.310272: {"feed":"book","product_id":"PI_ETHUSD","side":"sell","seq":26663091,"price":2021.45,"qty":67949.0,"timestamp":1626994949325}
1626994949.337434: {"feed":"book","product_id":"PI_ETHUSD","side":"buy","seq":26663092,"price":2003.7,"qty":15826.0,"timestamp":1626994949357}
1626994949.337545: {"feed":"book","product_id":"PI_ETHUSD","side":"buy","seq":26663093,"price":2003.6,"qty":20000.0,"timestamp":1626994949357}
1626994949.352366: {"feed":"book","product_id":"FI_ETHUSD_211231","side":"sell","seq":2199159,"price":2033.8,"qty":0.0,"timestamp":1626994949372}
1626994949.3524952: {"feed":"book","product_id":"FI_ETHUSD_211231","side":"buy","seq":2199160,"price":2026.45,"qty":0.0,"timestamp":1626994949372}
1626994949.4096498: {"feed":"book","product_id":"PI_ETHUSD","side":"buy","seq":26663094,"price":2003.6,"qty":0.0,"timestamp":1626994949430}
1626994949.409775: {"feed":"book","product_id":"PI_ETHUSD","side":"buy","seq":26663095,"price":2003.7,"qty":35826.0,"timestamp":1626994949430}
1626994949.44924: {"feed":"book","product_id":"FI_XBTUSD_210924","side":"sell","seq":13502337,"price":32246.0,"qty":0.0,"timestamp":1626994949469}
1626994949.449364: {"feed":"book","product_id":"FI_XBTUSD_210924","side":"sell","seq":13502338,"price":32246.0,"qty":14627.0,"timestamp":1626994949469}
1626994949.449451: {"feed":"book","product_id":"FI_XBTUSD_210924","side":"buy","seq":13502339,"price":32195.5,"qty":0.0,"timestamp":1626994949469}
1626994949.449506: {"feed":"book","product_id":"FI_XBTUSD_210924","side":"buy","seq":13502340,"price":32195.5,"qty":17764.0,"timestamp":1626994949469}
1626994949.4955251: {"feed":"book","product_id":"FI_XBTUSD_210924","side":"buy","seq":13502341,"price":31605.0,"qty":0.0,"timestamp":1626994949516}
1626994949.495648: {"feed":"book","product_id":"FI_XBTUSD_210924","side":"buy","seq":13502342,"price":30924.0,"qty":0.0,"timestamp":1626994949516}
1626994949.495709: {"feed":"book","product_id":"FI_XBTUSD_210924","side":"buy","seq":13502343,"price":30243.0,"qty":0.0,"timestamp":1626994949516}
1626994949.5401258: {"feed":"book","product_id":"PI_ETHUSD","side":"buy","seq":26663096,"price":2001.5,"qty":0.0,"timestamp":1626994949560}
1626994949.5402539: {"feed":"book","product_id":"PI_ETHUSD","side":"buy","seq":26663097,"price":2001.5,"qty":16186.0,"timestamp":1626994949560}
1626994949.54032: {"feed":"book","product_id":"PI_ETHUSD","side":"sell","seq":26663098,"price":2007.7,"qty":8742.0,"timestamp":1626994949560}
1626994949.540361: {"feed":"book","product_id":"PI_ETHUSD","side":"sell","seq":26663099,"price":2007.7,"qty":25809.0,"timestamp":1626994949560}
1626994949.542606: {"feed":"book","product_id":"PI_ETHUSD","side":"sell","seq":26663100,"price":2007.1,"qty":5000.0,"timestamp":1626994949560}
1626994949.5427241: {"feed":"book","product_id":"PI_ETHUSD","side":"sell","seq":26663101,"price":2007.1,"qty":18257.0,"timestamp":1626994949560}
1626994949.5427752: {"feed":"book","product_id":"PI_ETHUSD","side":"buy","seq":26663102,"price":2001.9,"qty":0.0,"timestamp":1626994949560}
1626994949.542836: {"feed":"book","product_id":"PI_ETHUSD","side":"buy","seq":26663103,"price":2001.9,"qty":13790.0,"timestamp":1626994949560}
1626994949.542895: {"feed":"book","product_id":"PI_ETHUSD","side":"sell","seq":26663104,"price":2008.45,"qty":0.0,"timestamp":1626994949560}
1626994949.542943: {"feed":"book","product_id":"PI_ETHUSD","side":"sell","seq":26663105,"price":2008.45,"qty":23108.0,"timestamp":1626994949560}
1626994949.542986: {"feed":"book","product_id":"PI_ETHUSD","side":"buy","seq":26663106,"price":2000.55,"qty":0.0,"timestamp":1626994949560}
1626994949.543029: {"feed":"book","product_id":"PI_ETHUSD","side":"buy","seq":26663107,"price":2000.55,"qty":23582.0,"timestamp":1626994949560}
1626994949.543433: {"feed":"book","product_id":"PI_ETHUSD","side":"buy","seq":26663108,"price":1996.5,"qty":0.0,"timestamp":1626994949560}
1626994949.543482: {"feed":"book","product_id":"PI_ETHUSD","side":"buy","seq":26663109,"price":1996.5,"qty":45572.0,"timestamp":1626994949560}
1626994949.545357: {"feed":"book","product_id":"PI_ETHUSD","side":"sell","seq":26663110,"price":2013.35,"qty":0.0,"timestamp":1626994949560}
1626994949.5454452: {"feed":"book","product_id":"PI_ETHUSD","side":"sell","seq":26663111,"price":2013.35,"qty":48379.0,"timestamp":1626994949560}
1626994949.5454888: {"feed":"book","product_id":"PI_ETHUSD","side":"buy","seq":26663112,"price":1985.1,"qty":0.0,"timestamp":1626994949560}
1626994949.545526: {"feed":"book","product_id":"PI_ETHUSD","side":"buy","seq":26663113,"price":1985.1,"qty":66951.0,"timestamp":1626994949560}
1626994949.5455549: {"feed":"book","product_id":"PI_ETHUSD","side":"sell","seq":26663114,"price":2021.45,"qty":0.0,"timestamp":1626994949560}
1626994949.545585: {"feed":"book","product_id":"PI_ETHUSD","side":"sell","seq":26663115,"price":2021.45,"qty":67948.0,"timestamp":1626994949560}
1626994949.587774: {"feed":"book","product_id":"FI_XBTUSD_210924","side":"buy","seq":13502344,"price":31605.0,"qty":356.0,"timestamp":1626994949607}
1626994949.629049: {"feed":"book","product_id":"PI_ETHUSD","side":"buy","seq":26663116,"price":2003.7,"qty":20000.0,"timestamp":1626994949647}
1626994949.629157: {"feed":"book","product_id":"PI_ETHUSD","side":"buy","seq":26663117,"price":2003.8,"qty":15826.0,"timestamp":1626994949647}
1626994949.681174: {"feed":"book","product_id":"FI_XBTUSD_210924","side":"buy","seq":13502345,"price":30924.0,"qty":712.0,"timestamp":1626994949701}
1626994949.683805: {"feed":"book","product_id":"FI_XBTUSD_210924","side":"sell","seq":13502346,"price":32246.0,"qty":0.0,"timestamp":1626994949703}
1626994949.683934: {"feed":"book","product_id":"FI_XBTUSD_210924","side":"sell","seq":13502347,"price":32246.0,"qty":14890.0,"timestamp":1626994949703}
1626994949.6839979: {"feed":"book","product_id":"FI_XBTUSD_210924","side":"buy","seq":13502348,"price":32195.5,"qty":0.0,"timestamp":1626994949703}
1626994949.6840498: {"feed":"book","product_id":"FI_XBTUSD_210924","side":"buy","seq":13502349,"price":32195.5,"qty":17501.0,"timestamp":1626994949703}
1626994949.684094: {"feed":"book","product_id":"FI_XBTUSD_210924","side":"buy","seq":13502350,"price":32174.0,"qty":3000.0,"timestamp":1626994949703}
1626994949.6841311: {"feed":"book","product_id":"FI_XBTUSD_210924","side":"buy","seq":13502351,"price":32174.0,"qty":23909.0,"timestamp":1626994949703}
1626994949.684163: {"feed":"book","product_id":"FI_XBTUSD_210924","side":"sell","seq":13502352,"price":32281.5,"qty":0.0,"timestamp":1626994949703}
1626994949.684237: {"feed":"book","product_id":"FI_XBTUSD_210924","side":"sell","seq":13502353,"price":32281.5,"qty":20966.0,"timestamp":1626994949703}
1626994949.686399: {"feed":"book","product_id":"FI_XBTUSD_210924","side":"sell","seq":13502354,"price":32289.0,"qty":3000.0,"timestamp":1626994949707}
1626994949.686476: {"feed":"book","product_id":"FI_XBTUSD_210924","side":"sell","seq":13502355,"price":32285.0,"qty":20000.0,"timestamp":1626994949707}
1626994949.772366: {"feed":"book","product_id":"FI_XBTUSD_210924","side":"buy","seq":13502356,"price":30243.0,"qty":1424.0,"timestamp":1626994949792}
1626994949.7787871: {"feed":"book","product_id":"PI_ETHUSD","side":"sell","seq":26663118,"price":2008.45,"qty":0.0,"timestamp":1626994949794}
1626994949.778914: {"feed":"book","product_id":"PI_ETHUSD","side":"sell","seq":26663119,"price":2008.4,"qty":22826.0,"timestamp":1626994949794}
1626994949.77898: {"feed":"book","product_id":"PI_ETHUSD","side":"sell","seq":26663120,"price":2013.35,"qty":0.0,"timestamp":1626994949794}
1626994949.7790341: {"feed":"book","product_id":"PI_ETHUSD","side":"sell","seq":26663121,"price":2013.3,"qty":48216.0,"timestamp":1626994949794}
1626994949.890015: {"feed":"book","product_id":"FI_XBTUSD_210924","side":"sell","seq":13502357,"price":32246.0,"qty":0.0,"timestamp":1626994949907}
1626994949.890141: {"feed":"book","product_id":"FI_XBTUSD_210924","side":"sell","seq":13502358,"price":32246.0,"qty":14940.0,"timestamp":1626994949907}
1626994949.890204: {"feed":"book","product_id":"FI_XBTUSD_210924","side":"buy","seq":13502359,"price":32195.5,"qty":0.0,"timestamp":1626994949907}
1626994949.890254: {"feed":"book","product_id":"FI_XBTUSD_210924","side":"buy","seq":13502360,"price":32195.5,"qty":17452.0,"timestamp":1626994949907}
1626994949.9781609: {"feed":"book","product_id":"PI_ETHUSD","side":"sell","seq":26663122,"price":2008.4,"qty":0.0,"timestamp":1626994949998}
1626994949.978285: {"feed":"book","product_id":"PI_ETHUSD","side":"sell","seq":26663123,"price":2008.45,"qty":23244.0,"timestamp":1626994949998}
1626994950.1232069: {"feed":"book","product_id":"FI_XBTUSD_210924","side":"sell","seq":13502361,"price":32246.0,"qty":0.0,"timestamp":1626994950141}
1626994950.123331: {"feed":"book","product_id":"FI_XBTUSD_210924","side":"sell","seq":13502362,"price":32246.0,"qty":14971.0,"timestamp":1626994950141}
1626994950.1233962: {"feed":"book","product_id":"FI_XBTUSD_210924","side":"buy","seq":13502363,"price":32195.5,"qty":0.0,"timestamp":1626994950141}
1626994950.123449: {"feed":"book","product_id":"FI_XBTUSD_210924","side":"buy","seq":13502364,"price":32195.5,"qty":17421.0,"timestamp":1626994950141}
1626994950.1804118: {"feed":"book","product_id":"PI_ETHUSD","side":"sell","seq":26663124,"price":2006.5,"qty":42876.0,"timestamp":1626994950200}
1626994950.180522: {"feed":"book","product_id":"PI_ETHUSD","side":"sell","seq":26663125,"price":2007.1,"qty":13257.0,"timestamp":1626994950201}
1626994950.1805708: {"feed":"book","product_id":"PI_ETHUSD","side":"buy","seq":26663126,"price":2003.0,"qty":0.0,"timestamp":1626994950201}
1626994950.180632: {"feed":"book","product_id":"PI_ETHUSD","side":"buy","seq":26663127,"price":2001.05,"qty":0.0,"timestamp":1626994950201}
1626994950.1835651: {"feed":"book","product_id":"PI_ETHUSD","side":"sell","seq":26663128,"price":2013.3,"qty":0.0,"timestamp":1626994950201}
1626994950.183691: {"feed":"book","product_id":"PI_ETHUSD","side":"sell","seq":26663129,"price":2013.35,"qty":48467.0,"timestamp":1626994950201}
1626994950.183756: {"feed":"book","product_id":"PI_ETHUSD","side":"buy","seq":26663130,"price":2001.5,"qty":0.0,"timestamp":1626994950201}
1626994950.1838112: {"feed":"book","product_id":"PI_ETHUSD","side":"buy","seq":26663131,"price":2001.5,"qty":15958.0,"timestamp":1626994950201}
1626994950.183865: {"feed":"book","product_id":"PI_ETHUSD","side":"sell","seq":26663132,"price":2007.7,"qty":8742.0,"timestamp":1626994950201}
1626994950.183906: {"feed":"book","product_id":"PI_ETHUSD","side":"sell","seq":26663133,"price":2007.7,"qty":26039.0,"timestamp":1626994950201}
1626994950.183927: {"feed":"book","product_id":"PI_ETHUSD","side":"sell","seq":26663134,"price":2007.1,"qty":0.0,"timestamp":1626994950201}
1626994950.183954: {"feed":"book","product_id":"PI_ETHUSD","side":"sell","seq":26663135,"price":2007.1,"qty":13411.0,"timestamp":1626994950201}
1626994950.184818: {"feed":"book","product_id":"PI_ETHUSD","side":"buy","seq":26663136,"price":2001.9,"qty":0.0,"timestamp":1626994950201}
1626994950.1849039: {"feed":"book","product_id":"PI_ETHUSD","side":"buy","seq":26663137,"price":2001.9,"qty":13638.0,"timestamp":1626994950201}
1626994950.184962: {"feed":"book","product_id":"PI_ETHUSD","side":"buy","seq":26663138,"price":2000.55,"qty":0.0,"timestamp":1626994950201}
1626994950.1849961: {"feed":"book","product_id":"PI_ETHUSD","side":"buy","seq":26663139,"price":2000.55,"qty":23430.0,"timestamp":1626994950201}
1626994950.185026: {"feed":"book","product_id":"PI_ETHUSD","side":"buy","seq":26663140,"price":1996.5,"qty":0.0,"timestamp":1626994950202}
1626994950.185055: {"feed":"book","product_id":"PI_ETHUSD","side":"buy","seq":26663141,"price":1996.5,"qty":45486.0,"timestamp":1626994950202}
1626994950.186904: {"feed":"book","product_id":"PI_ETHUSD","side":"sell","seq":26663142,"price":2008.45,"qty":0.0,"timestamp":1626994950202}
1626994950.18699: {"feed":"book","product_id":"PI_ETHUSD","side":"sell","seq":26663143,"price":2008.45,"qty":23262.0,"timestamp":1626994950202}
1626994950.1870341: {"feed":"book","product_id":"PI_ETHUSD","side":"buy","seq":26663144,"price":1985.1,"qty":0.0,"timestamp":1626994950202}
1626994950.18707: {"feed":"book","product_id":"PI_ETHUSD","side":"buy","seq":26663145,"price":1985.1,"qty":66950.0,"timestamp":1626994950202}
1626994950.187099: {"feed":"book","product_id":"PI_ETHUSD","side":"sell","seq":26663146,"price":2021.45,"qty":0.0,"timestamp":1626994950202}
1626994950.187129: {"feed":"book","product_id":"PI_ETHUSD","side":"sell","seq":26663147,"price":2021.45,"qty":67947.0,"timestamp":1626994950202}
1626994950.202684: {"feed":"book","product_id":"PI_ETHUSD","side":"sell","seq":26663148,"price":2006.75,"qty":5000.0,"timestamp":1626994950223}
1626994950.202809: {"feed":"book","product_id":"PI_ETHUSD","side":"buy","seq":26663149,"price":2002.15,"qty":11415.0,"timestamp":1626994950223}
1626994950.204679: {"feed":"book","product_id":"PI_ETHUSD","side":"sell","seq":26663150,"price":2006.2,"qty":2500.0,"timestamp":1626994950225}
1626994950.204801: {"feed":"book","product_id":"PI_ETHUSD","side":"buy","seq":26663151,"price":2003.45,"qty":34466.0,"timestamp":1626994950226}
1626994950.214483: {"feed":"book","product_id":"PI_ETHUSD","side":"buy","seq":26663152,"price":2003.7,"qty":0.0,"timestamp":1626994950234}
1626994950.214608: {"feed":"book","product_id":"PI_ETHUSD","side":"buy","seq":26663153,"price":2003.8,"qty":35826.0,"timestamp":1626994950234}
1626994950.285297: {"feed":"book","product_id":"PI_ETHUSD","side":"sell","seq":26663154,"price":2007.15,"qty":9967.0,"timestamp":1626994950305}
1626994950.2853749: {"feed":"book","product_id":"PI_ETHUSD","side":"sell","seq":26663155,"price":2006.05,"qty":4078.0,"timestamp":1626994950306}
1626994950.2854211: {"feed":"book","product_id":"PI_ETHUSD","side":"sell","seq":26663156,"price":2006.8,"qty":4147.0,"timestamp":1626994950307}
1626994950.2875268: {"feed":"book","product_id":"PI_ETHUSD","side":"buy","seq":26663157,"price":2003.9,"qty":12008.0,"timestamp":1626994950308}
1626994950.289022: {"feed":"book","product_id":"PI_ETHUSD","side":"sell","seq":26663158,"price":2006.4,"qty":86728.0,"timestamp":1626994950309}
1626994950.289099: {"feed":"book","product_id":"PI_ETHUSD","side":"buy","seq":26663159,"price":2004.1,"qty":600.0,"timestamp":1626994950310}
1626994950.365364: {"feed":"book","product_id":"FI_XBTUSD_210924","side":"sell","seq":13502365,"price":32246.0,"qty":0.0,"timestamp":1626994950386}
1626994950.3654962: {"feed":"book","product_id":"FI_XBTUSD_210924","side":"sell","seq":13502366,"price":32246.0,"qty":14968.0,"timestamp":1626994950386}
1626994950.3673: {"feed":"book","product_id":"FI_XBTUSD_210924","side":"buy","seq":13502367,"price":32195.5,"qty":0.0,"timestamp":1626994950386}
1626994950.367423: {"feed":"book","product_id":"FI_XBTUSD_210924","side":"buy","seq":13502368,"price":32195.5,"qty":17424.0,"timestamp":1626994950386}
1626994950.417304: {"feed":"book","product_id":"PI_ETHUSD","side":"sell","seq":26663160,"price":2007.1,"qty":0.0,"timestamp":1626994950437}
1626994950.417429: {"feed":"book","product_id":"PI_ETHUSD","side":"sell","seq":26663161,"price":2007.1,"qty":13410.0,"timestamp":1626994950437}
1626994950.417493: {"feed":"book","product_id":"PI_ETHUSD","side":"buy","seq":26663162,"price":2001.5,"qty":0.0,"timestamp":1626994950437}
1626994950.4175448: {"feed":"book","product_id":"PI_ETHUSD","side":"buy","seq":26663163,"price":2001.5,"qty":15959.0,"timestamp":1626994950437}
1626994950.418041: {"feed":"book","product_id":"PI_ETHUSD","side":"sell","seq":26663164,"price":2008.45,"qty":0.0,"timestamp":1626994950437}
1626994950.418112: {"feed":"book","product_id":"PI_ETHUSD","side":"sell","seq":26663165,"price":2008.45,"qty":23261.0,"timestamp":1626994950437}
1626994950.4186702: {"feed":"book","product_id":"PI_ETHUSD","side":"buy","seq":26663166,"price":2000.55,"qty":0.0,"timestamp":1626994950437}
1626994950.418747: {"feed":"book","product_id":"PI_ETHUSD","side":"buy","seq":26663167,"price":2000.55,"qty":23431.0,"timestamp":1626994950437}
1626994950.4755142: {"feed":"book","product_id":"PI_LTCUSD","side":"sell","seq":3423336,"price":119.53,"qty":0.0,"timestamp":1626994950495}
1626994950.478148: {"feed":"book","product_id":"PI_LTCUSD","side":"buy","seq":3423337,"price":119.26,"qty":8979.0,"timestamp":1626994950499}
1626994950.478257: {"feed":"book","product_id":"PI_LTCUSD","side":"buy","seq":3423338,"price":119.3,"qty":10893.0,"timestamp":1626994950499}
1626994950.480177: {"feed":"book","product_id":"PI_ETHUSD","side":"buy","seq":26663168,"price":2004.45,"qty":0.0,"timestamp":1626994950501}
1626994950.4845371: {"feed":"book","product_id":"PI_ETHUSD","side":"buy","seq":26663169,"price":2003.85,"qty":0.0,"timestamp":1626994950505}
1626994950.4866931: {"feed":"book","product_id":"PI_ETHUSD","side":"buy","seq":26663170,"price":2003.45,"qty":38303.0,"timestamp":1626994950507}
1626994950.4910731: {"feed":"book","product_id":"PI_ETHUSD","side":"buy","seq":26663171,"price":2003.8,"qty":20000.0,"timestamp":1626994950512}
1626994950.491194: {"feed":"book","product_id":"PI_ETHUSD","side":"buy","seq":26663172,"price":2004.0,"qty":110044.0,"timestamp":1626994950512}
1626994950.49166: {"feed":"book","product_id":"PI_ETHUSD","side":"buy","seq":26663173,"price":2003.8,"qty":0.0,"timestamp":1626994950512}
1626994950.491738: {"feed":"book","product_id":"PI_ETHUSD","side":"buy","seq":26663174,"price":2003.95,"qty":20000.0,"timestamp":1626994950512}
1626994950.494058: {"feed":"book","product_id":"PI_ETHUSD","side":"buy","seq":26663175,"price":2003.45,"qty":20857.0,"timestamp":1626994950515}
1626994950.494132: {"feed":"book","product_id":"PI_ETHUSD","side":"buy","seq":26663176,"price":2004.0,"qty":94218.0,"timestamp":1626994950515}
1626994950.494164: {"feed":"book","product_id":"PI_ETHUSD","side":"buy","seq":26663177,"price":2003.85,"qty":15826.0,"timestamp":1626994950515}
1626994950.4945211: {"feed":"book","product_id":"PI_ETHUSD","side":"buy","seq":26663178,"price":2003.95,"qty":0.0,"timestamp":1626994950516}
1626994950.4945889: {"feed":"book","product_id":"PI_ETHUSD","side":"buy","seq":26663179,"price":2003.8,"qty":20000.0,"timestamp":1626994950516}
1626994950.508034: {"feed":"book","product_id":"PI_ETHUSD","side":"buy","seq":26663180,"price":2003.8,"qty":0.0,"timestamp":1626994950528}
1626994950.50812: {"feed":"book","product_id":"PI_ETHUSD","side":"buy","seq":26663181,"price":2003.95,"qty":20000.0,"timestamp":1626994950528}
1626994950.508178: {"feed":"book","product_id":"PI_ETHUSD","side":"buy","seq":26663182,"price":2003.85,"qty":0.0,"timestamp":1626994950530}
1626994950.5082219: {"feed":"book","product_id":"PI_ETHUSD","side":"buy","seq":26663183,"price":2004.0,"qty":110044.0,"timestamp":1626994950530}
1626994950.508518: {"feed":"book","product_id":"PI_ETHUSD","side":"buy","seq":26663184,"price":2003.45,"qty":38303.0,"timestamp":1626994950530}
1626994950.5130382: {"feed":"book","product_id":"PI_ETHUSD","side":"buy","seq":26663185,"price":2003.45,"qty":20857.0,"timestamp":1626994950533}
1626994950.5195892: {"feed":"book","product_id":"PI_ETHUSD","side":"buy","seq":26663186,"price":2004.0,"qty":94218.0,"timestamp":1626994950538}
1626994950.519666: {"feed":"book","product_id":"PI_ETHUSD","side":"buy","seq":26663187,"price":2003.85,"qty":15826.0,"timestamp":1626994950538}
1626994950.519711: {"feed":"book","product_id":"PI_ETHUSD","side":"buy","seq":26663188,"price":2003.95,"qty":0.0,"timestamp":1626994950539}
1626994950.5197492: {"feed":"book","product_id":"PI_ETHUSD","side":"buy","seq":26663189,"price":2003.8,"qty":20000.0,"timestamp":1626994950539}
1626994950.5450728: {"feed":"book","product_id":"PI_ETHUSD","side":"buy","seq":26663190,"price":2004.05,"qty":43594.0,"timestamp":1626994950564}
1626994950.575209: {"feed":"book","product_id":"PI_ETHUSD","side":"sell","seq":26663191,"price":2005.9,"qty":25282.0,"timestamp":1626994950593}
1626994950.575318: {"feed":"book","product_id":"PI_ETHUSD","side":"sell","seq":26663192,"price":2006.15,"qty":0.0,"timestamp":1626994950595}
1626994950.584243: {"feed":"book","product_id":"PI_ETHUSD","side":"buy","seq":26663193,"price":2003.9,"qty":10700.0,"timestamp":1626994950604}
1626994950.587146: {"feed":"book","product_id":"PI_ETHUSD","side":"buy","seq":26663194,"price":2003.65,"qty":0.0,"timestamp":1626994950607}
1626994950.58768: {"feed":"book","product_id":"PI_ETHUSD","side":"buy","seq":26663195,"price":2003.1,"qty":13899.0,"timestamp":1626994950608}
1626994950.59605: {"feed":"book","product_id":"PI_ETHUSD","side":"buy","seq":26663196,"price":2003.8,"qty":0.0,"timestamp":1626994950615}
1626994950.596174: {"feed":"book","product_id":"PI_ETHUSD","side":"buy","seq":26663197,"price":2003.65,"qty":20000.0,"timestamp":1626994950615}
1626994950.596239: {"feed":"book","product_id":"PI_ETHUSD","side":"buy","seq":26663198,"price":2003.85,"qty":0.0,"timestamp":1626994950615}
1626994950.59629: {"feed":"book","product_id":"PI_ETHUSD","side":"buy","seq":26663199,"price":2003.7,"qty":15826.0,"timestamp":1626994950615}
1626994950.6012568: {"feed":"book","product_id":"PI_ETHUSD","side":"sell","seq":26663200,"price":2007.9,"qty":0.0,"timestamp":1626994950622}
1626994950.60138: {"feed":"book","product_id":"PI_ETHUSD","side":"sell","seq":26663201,"price":2007.45,"qty":42541.0,"timestamp":1626994950622}
1626994950.604456: {"feed":"book","product_id":"PI_LTCUSD","side":"buy","seq":3423339,"price":119.38,"qty":4235.0,"timestamp":1626994950625}
1626994950.622253: {"feed":"book","product_id":"PI_LTCUSD","side":"sell","seq":3423340,"price":119.6,"qty":4145.0,"timestamp":1626994950626}
1626994950.6223738: {"feed":"book","product_id":"PI_LTCUSD","side":"sell","seq":3423341,"price":119.63,"qty":9022.0,"timestamp":1626994950627}
1626994950.622426: {"feed":"book","product_id":"PI_LTCUSD","side":"buy","seq":3423342,"price":119.35,"qty":3924.0,"timestamp":1626994950627}
1626994950.622497: {"feed":"book","product_id":"PI_LTCUSD","side":"buy","seq":3423343,"price":119.3,"qty":9893.0,"timestamp":1626994950628}
1626994950.622535: {"feed":"book","product_id":"PI_LTCUSD","side":"buy","seq":3423344,"price":119.29,"qty":1000.0,"timestamp":1626994950628}
1626994950.622575: {"feed":"book","product_id":"FI_XBTUSD_210730","side":"sell","seq":5160187,"price":32214.0,"qty":0.0,"timestamp":1626994950631}
1626994950.62263: {"feed":"book","product_id":"FI_XBTUSD_210730","side":"sell","seq":5160188,"price":32213.0,"qty":1.0,"timestamp":1626994950631}
1626994950.622677: {"feed":"book","product_id":"PI_ETHUSD","side":"buy","seq":26663202,"price":2001.5,"qty":0.0,"timestamp":1626994950641}
1626994950.622733: {"feed":"book","product_id":"PI_ETHUSD","side":"buy","seq":26663203,"price":2001.3,"qty":17205.0,"timestamp":1626994950641}
1626994950.625171: {"feed":"book","product_id":"PI_ETHUSD","side":"buy","seq":26663204,"price":2001.9,"qty":0.0,"timestamp":1626994950641}
1626994950.625259: {"feed":"book","product_id":"PI_ETHUSD","side":"buy","seq":26663205,"price":2002.2,"qty":18228.0,"timestamp":1626994950641}
1626994950.651233: {"feed":"book","product_id":"PI_LTCUSD","side":"sell","seq":3423345,"price":119.54,"qty":21362.0,"timestamp":1626994950670}
1626994950.653675: {"feed":"book","product_id":"PI_ETHUSD","side":"buy","seq":26663206,"price":2003.3,"qty":0.0,"timestamp":1626994950672}
1626994950.6537988: {"feed":"book","product_id":"PI_LTCUSD","side":"buy","seq":3423346,"price":119.29,"qty":0.0,"timestamp":1626994950674}
1626994950.653861: {"feed":"book","product_id":"PI_LTCUSD","side":"buy","seq":3423347,"price":119.26,"qty":9979.0,"timestamp":1626994950674}
1626994950.6542132: {"feed":"book","product_id":"PI_ETHUSD","side":"buy","seq":26663207,"price":2003.9,"qty":6649.0,"timestamp":1626994950676}
1626994950.6588001: {"feed":"book","product_id":"PI_ETHUSD","side":"sell","seq":26663208,"price":2005.9,"qty":21379.0,"timestamp":1626994950677}
1626994950.6589088: {"feed":"book","product_id":"PI_ETHUSD","side":"sell","seq":26663209,"price":2006.2,"qty":0.0,"timestamp":1626994950678}
1626994950.6610901: {"feed":"book","product_id":"PI_ETHUSD","side":"buy","seq":26663210,"price":2003.65,"qty":24176.0,"timestamp":1626994950681}
1626994950.661196: {"feed":"book","product_id":"FI_ETHUSD_211231","side":"buy","seq":2199161,"price":2027.35,"qty":2000.0,"timestamp":1626994950682}
1626994950.663334: {"feed":"book","product_id":"FI_ETHUSD_211231","side":"sell","seq":2199162,"price":2034.65,"qty":2000.0,"timestamp":1626994950682}
1626994950.6634529: {"feed":"book","product_id":"PI_ETHUSD","side":"buy","seq":26663211,"price":2003.65,"qty":4176.0,"timestamp":1626994950682}
1626994950.663507: {"feed":"book","product_id":"PI_ETHUSD","side":"buy","seq":26663212,"price":2003.55,"qty":20000.0,"timestamp":1626994950682}
1626994950.663557: {"feed":"book","product_id":"PI_ETHUSD","side":"buy","seq":26663213,"price":2003.7,"qty":0.0,"timestamp":1626994950683}
1626994950.663611: {"feed":"book","product_id":"PI_ETHUSD","side":"buy","seq":26663214,"price":2003.6,"qty":15826.0,"timestamp":1626994950683}
1626994950.669947: {"feed":"book","product_id":"PI_ETHUSD","side":"buy","seq":26663215,"price":2003.4,"qty":0.0,"timestamp":1626994950689}
1626994950.670072: {"feed":"book","product_id":"PI_ETHUSD","side":"buy","seq":26663216,"price":2003.1,"qty":28899.0,"timestamp":1626994950689}
1626994950.670126: {"feed":"book","product_id":"PI_ETHUSD","side":"sell","seq":26663217,"price":2005.4,"qty":1532.0,"timestamp":1626994950689}
1626994950.670167: {"feed":"book","product_id":"PI_ETHUSD","side":"sell","seq":26663218,"price":2005.15,"qty":2692.0,"timestamp":1626994950689}
1626994950.670202: {"feed":"book","product_id":"PI_ETHUSD","side":"buy","seq":26663219,"price":2004.1,"qty":0.0,"timestamp":1626994950689}
1626994950.67027: {"feed":"book","product_id":"PI_ETHUSD","side":"buy","seq":26663220,"price":2003.8,"qty":600.0,"timestamp":1626994950689}
1626994950.671909: {"feed":"book","product_id":"PI_XRPUSD","side":"buy","seq":3456241,"price":0.5881,"qty":15337.0,"timestamp":1626994950692}
1626994950.6720169: {"feed":"book","product_id":"PI_ETHUSD","side":"sell","seq":26663221,"price":2006.05,"qty":6578.0,"timestamp":1626994950693}
1626994950.677286: {"feed":"book","product_id":"PI_XRPUSD","side":"buy","seq":3456242,"price":0.5881,"qty":5387.0,"timestamp":1626994950695}
1626994950.677394: {"feed":"book","product_id":"PI_XRPUSD","side":"buy","seq":3456243,"price":0.588,"qty":18872.0,"timestamp":1626994950695}
1626994950.6774452: {"feed":"book","product_id":"FI_BCHUSD_210924","side":"sell","seq":402248,"price":442.1,"qty":19843.0,"timestamp":1626994950698}
1626994950.680741: {"feed":"book","product_id":"PI_ETHUSD","side":"buy","seq":26663222,"price":2002.2,"qty":11672.0,"timestamp":1626994950701}
1626994950.6808488: {"feed":"book","product_id":"FI_ETHUSD_211231","side":"buy","seq":2199163,"price":2028.45,"qty":0.0,"timestamp":1626994950701}
1626994950.680919: {"feed":"book","product_id":"FI_ETHUSD_211231","side":"sell","seq":2199164,"price":2036.35,"qty":175.0,"timestamp":1626994950701}
1626994950.680973: {"feed":"book","product_id":"FI_ETHUSD_210730","side":"buy","seq":2138824,"price":1999.3,"qty":0.0,"timestamp":1626994950701}
1626994950.6810439: {"feed":"book","product_id":"FI_XBTUSD_210730","side":"sell","seq":5160189,"price":32246.5,"qty":445.0,"timestamp":1626994950701}
1626994950.681088: {"feed":"book","product_id":"FI_ETHUSD_210730","side":"buy","seq":2138825,"price":1999.7,"qty":0.0,"timestamp":1626994950701}
1626994950.6811311: {"feed":"book","product_id":"PI_LTCUSD","side":"sell","seq":3423348,"price":119.69,"qty":914.0,"timestamp":1626994950701}
1626994950.682694: {"feed":"book","product_id":"FI_ETHUSD_211231","side":"buy","seq":2199165,"price":2028.0,"qty":0.0,"timestamp":1626994950702}
1626994950.68282: {"feed":"book","product_id":"PI_ETHUSD","side":"sell","seq":26663223,"price":2007.35,"qty":6687.0,"timestamp":1626994950702}
1626994950.68289: {"feed":"book","product_id":"FI_XBTUSD_210924","side":"buy","seq":13502369,"price":32184.0,"qty":0.0,"timestamp":1626994950703}
1626994950.6829581: {"feed":"book","product_id":"PI_LTCUSD","side":"buy","seq":3423349,"price":119.25,"qty":0.0,"timestamp":1626994950702}
1626994950.684581: {"feed":"book","product_id":"PI_ETHUSD","side":"buy","seq":26663224,"price":2003.0,"qty":4470.0,"timestamp":1626994950705}
1626994950.6846652: {"feed":"book","product_id":"FI_XRPUSD_210924","side":"buy","seq":602296,"price":0.5838,"qty":0.0,"timestamp":1626994950704}
1626994950.687944: {"feed":"book","product_id":"PI_ETHUSD","side":"buy","seq":26663225,"price":2003.9,"qty":2500.0,"timestamp":1626994950707}
1626994950.688019: {"feed":"book","product_id":"PI_ETHUSD","side":"sell","seq":26663226,"price":2007.7,"qty":21891.0,"timestamp":1626994950707}
1626994950.690287: {"feed":"book","product_id":"PI_ETHUSD","side":"sell","seq":26663227,"price":2006.05,"qty":2500.0,"timestamp":1626994950709}
1626994950.690361: {"feed":"book","product_id":"PI_ETHUSD","side":"sell","seq":26663228,"price":2007.1,"qty":17599.0,"timestamp":1626994950711}
1626994950.7023869: {"feed":"book","product_id":"PI_ETHUSD","side":"buy","seq":26663229,"price":2003.6,"qty":0.0,"timestamp":1626994950722}
1626994950.70251: {"feed":"book","product_id":"PI_ETHUSD","side":"buy","seq":26663230,"price":2003.5,"qty":15826.0,"timestamp":1626994950722}
1626994950.705471: {"feed":"book","product_id":"PI_ETHUSD","side":"buy","seq":26663231,"price":2003.55,"qty":0.0,"timestamp":1626994950723}
1626994950.705596: {"feed":"book","product_id":"PI_ETHUSD","side":"buy","seq":26663232,"price":2003.45,"qty":40857.0,"timestamp":1626994950723}
1626994950.7056499: {"feed":"book","product_id":"PI_ETHUSD","side":"buy","seq":26663233,"price":2000.4,"qty":19199.0,"timestamp":1626994950726}
1626994950.70986: {"feed":"book","product_id":"PI_ETHUSD","side":"buy","seq":26663234,"price":1996.95,"qty":38399.0,"timestamp":1626994950729}
1626994950.71944: {"feed":"book","product_id":"FI_XBTUSD_210730","side":"sell","seq":5160190,"price":32213.0,"qty":0.0,"timestamp":1626994950738}
1626994950.719574: {"feed":"book","product_id":"FI_XBTUSD_210730","side":"sell","seq":5160191,"price":32214.5,"qty":1.0,"timestamp":1626994950738}
1626994950.720083: {"feed":"book","product_id":"FI_XBTUSD_210924","side":"buy","seq":13502370,"price":31616.0,"qty":0.0,"timestamp":1626994950737}
1626994950.7201412: {"feed":"book","product_id":"FI_XBTUSD_210924","side":"buy","seq":13502371,"price":30935.0,"qty":0.0,"timestamp":1626994950737}
1626994950.720175: {"feed":"book","product_id":"FI_XBTUSD_210924","side":"buy","seq":13502372,"price":30254.0,"qty":0.0,"timestamp":1626994950737}
1626994950.720203: {"feed":"book","product_id":"PI_ETHUSD","side":"sell","seq":26663235,"price":2005.5,"qty":110087.0,"timestamp":1626994950741}
1626994950.722659: {"feed":"book","product_id":"FI_XBTUSD_210924","side":"sell","seq":13502373,"price":32236.5,"qty":0.0,"timestamp":1626994950743}
1626994950.722744: {"feed":"book","product_id":"FI_XBTUSD_210924","side":"sell","seq":13502374,"price":32235.5,"qty":1.0,"timestamp":1626994950743}
1626994950.724681: {"feed":"book","product_id":"PI_ETHUSD","side":"buy","seq":26663236,"price":2003.35,"qty":0.0,"timestamp":1626994950746}
1626994950.725545: {"feed":"book","product_id":"PI_ETHUSD","side":"sell","seq":26663237,"price":2006.2,"qty":4196.0,"timestamp":1626994950746}
1626994950.725631: {"feed":"book","product_id":"PI_ETHUSD","side":"sell","seq":26663238,"price":2006.6,"qty":0.0,"timestamp":1626994950747}
1626994950.7291589: {"feed":"book","product_id":"PI_ETHUSD","side":"buy","seq":26663239,"price":2002.95,"qty":7746.0,"timestamp":1626994950747}
1626994950.73776: {"feed":"book","product_id":"FI_XBTUSD_210730","side":"sell","seq":5160192,"price":32204.5,"qty":140606.0,"timestamp":1626994950758}
1626994950.741972: {"feed":"book","product_id":"PI_ETHUSD","side":"buy","seq":26663240,"price":2003.9,"qty":0.0,"timestamp":1626994950762}
1626994950.750245: {"feed":"book","product_id":"FI_XBTUSD_210924","side":"sell","seq":13502375,"price":32246.0,"qty":0.0,"timestamp":1626994950769}
1626994950.750371: {"feed":"book","product_id":"FI_XBTUSD_210924","side":"sell","seq":13502376,"price":32246.0,"qty":15033.0,"timestamp":1626994950769}
1626994950.750432: {"feed":"book","product_id":"FI_XBTUSD_210924","side":"buy","seq":13502377,"price":32195.5,"qty":0.0,"timestamp":1626994950769}
1626994950.750483: {"feed":"book","product_id":"FI_XBTUSD_210924","side":"buy","seq":13502378,"price":32195.5,"qty":17359.0,"timestamp":1626994950769}
1626994950.750527: {"feed":"book","product_id":"PI_ETHUSD","side":"buy","seq":26663241,"price":2001.4,"qty":0.0,"timestamp":1626994950770}
1626994950.750575: {"feed":"book","product_id":"PI_ETHUSD","side":"sell","seq":26663242,"price":2006.75,"qty":13625.0,"timestamp":1626994950770}
1626994950.750908: {"feed":"book","product_id":"PI_XRPUSD","side":"buy","seq":3456244,"price":0.5874,"qty":15671.0,"timestamp":1626994950772}
1626994950.753303: {"feed":"book","product_id":"PI_XRPUSD","side":"buy","seq":3456245,"price":0.588,"qty":13867.0,"timestamp":1626994950773}
1626994950.759914: {"feed":"book","product_id":"FI_XBTUSD_210924","side":"sell","seq":13502379,"price":32235.5,"qty":0.0,"timestamp":1626994950780}
1626994950.76: {"feed":"book","product_id":"FI_XBTUSD_210924","side":"sell","seq":13502380,"price":32234.5,"qty":1.0,"timestamp":1626994950780}
1626994950.7649212: {"feed":"book","product_id":"PI_XRPUSD","side":"sell","seq":3456246,"price":0.5893,"qty":23183.0,"timestamp":1626994950785}
1626994950.765006: {"feed":"book","product_id":"PI_XRPUSD","side":"buy","seq":3456247,"price":0.5873,"qty":8073.0,"timestamp":1626994950785}
1626994950.7669818: {"feed":"book","product_id":"PI_ETHUSD","side":"buy","seq":26663243,"price":2004.05,"qty":0.0,"timestamp":1626994950787}
1626994950.770516: {"feed":"book","product_id":"PI_XRPUSD","side":"buy","seq":3456248,"price":0.5882,"qty":0.0,"timestamp":1626994950788}
1626994950.770645: {"feed":"book","product_id":"PI_XRPUSD","side":"buy","seq":3456249,"price":0.5881,"qty":5707.0,"timestamp":1626994950788}
1626994950.770699: {"feed":"book","product_id":"PI_XRPUSD","side":"buy","seq":3456250,"price":0.5879,"qty":8233.0,"timestamp":1626994950789}
1626994950.770738: {"feed":"book","product_id":"PI_XRPUSD","side":"buy","seq":3456251,"price":0.5878,"qty":22955.0,"timestamp":1626994950789}
1626994950.770773: {"feed":"book","product_id":"PI_XRPUSD","side":"sell","seq":3456252,"price":0.589,"qty":0.0,"timestamp":1626994950789}
1626994950.770818: {"feed":"book","product_id":"PI_XRPUSD","side":"sell","seq":3456253,"price":0.5889,"qty":7943.0,"timestamp":1626994950789}
1626994950.770862: {"feed":"book","product_id":"FI_XBTUSD_210730","side":"buy","seq":5160193,"price":32145.0,"qty":0.0,"timestamp":1626994950790}
1626994950.77092: {"feed":"book","product_id":"PI_LTCUSD","side":"buy","seq":3423350,"price":119.21,"qty":3851.0,"timestamp":1626994950791}
1626994950.771135: {"feed":"book","product_id":"PI_LTCUSD","side":"sell","seq":3423351,"price":119.64,"qty":30528.0,"timestamp":1626994950791}
1626994950.771362: {"feed":"book","product_id":"FI_XBTUSD_210730","side":"sell","seq":5160194,"price":32237.5,"qty":147175.0,"timestamp":1626994950792}
1626994950.773351: {"feed":"book","product_id":"FI_XBTUSD_210924","side":"buy","seq":13502381,"price":32177.0,"qty":0.0,"timestamp":1626994950793}
1626994950.774683: {"feed":"book","product_id":"FI_XBTUSD_210730","side":"buy","seq":5160195,"price":32131.5,"qty":0.0,"timestamp":1626994950795}
1626994950.7748108: {"feed":"book","product_id":"FI_XBTUSD_210730","side":"buy","seq":5160196,"price":32128.5,"qty":2047.0,"timestamp":1626994950795}
1626994950.779249: {"feed":"book","product_id":"PI_ETHUSD","side":"sell","seq":26663244,"price":2006.05,"qty":0.0,"timestamp":1626994950798}
1626994950.779377: {"feed":"book","product_id":"PI_ETHUSD","side":"sell","seq":26663245,"price":2006.75,"qty":8625.0,"timestamp":1626994950798}
1626994950.779434: {"feed":"book","product_id":"PI_ETHUSD","side":"sell","seq":26663246,"price":2008.5,"qty":7310.0,"timestamp":1626994950799}
1626994950.779514: {"feed":"book","product_id":"PI_ETHUSD","side":"sell","seq":26663247,"price":2008.05,"qty":159049.0,"timestamp":1626994950799}
1626994950.7795389: {"feed":"book","product_id":"PI_ETHUSD","side":"buy","seq":26663248,"price":2002.35,"qty":0.0,"timestamp":1626994950800}
1626994950.779572: {"feed":"book","product_id":"PI_ETHUSD","side":"sell","seq":26663249,"price":2005.75,"qty":61.0,"timestamp":1626994950800}
1626994950.7822511: {"feed":"book","product_id":"FI_XBTUSD_210924","side":"sell","seq":13502382,"price":32418.0,"qty":0.0,"timestamp":1626994950801}
1626994950.782341: {"feed":"book","product_id":"FI_XBTUSD_210924","side":"sell","seq":13502383,"price":32359.0,"qty":250002.0,"timestamp":1626994950801}
1626994950.7823842: {"feed":"book","product_id":"FI_ETHUSD_210730","side":"sell","seq":2138826,"price":2010.6,"qty":0.0,"timestamp":1626994950801}
1626994950.782419: {"feed":"book","product_id":"FI_ETHUSD_210730","side":"sell","seq":2138827,"price":2009.1,"qty":250001.0,"timestamp":1626994950801}
1626994950.782447: {"feed":"book","product_id":"FI_ETHUSD_211231","side":"sell","seq":2199166,"price":2041.65,"qty":0.0,"timestamp":1626994950801}
1626994950.782476: {"feed":"book","product_id":"FI_ETHUSD_211231","side":"sell","seq":2199167,"price":2038.25,"qty":258749.0,"timestamp":1626994950801}
1626994950.7825: {"feed":"book","product_id":"PI_ETHUSD","side":"sell","seq":26663250,"price":2013.4,"qty":0.0,"timestamp":1626994950801}
1626994950.78253: {"feed":"book","product_id":"PI_ETHUSD","side":"sell","seq":26663251,"price":2013.3,"qty":500002.0,"timestamp":1626994950801}
1626994950.782557: {"feed":"book","product_id":"FI_ETHUSD_211231","side":"sell","seq":2199168,"price":2048.45,"qty":0.0,"timestamp":1626994950801}
1626994950.782584: {"feed":"book","product_id":"FI_ETHUSD_211231","side":"sell","seq":2199169,"price":2048.35,"qty":250002.0,"timestamp":1626994950801}
1626994950.78261: {"feed":"book","product_id":"FI_ETHUSD_211231","side":"sell","seq":2199170,"price":2035.25,"qty":137.0,"timestamp":1626994950802}
1626994950.783691: {"feed":"book","product_id":"FI_ETHUSD_211231","side":"buy","seq":2199171,"price":2027.1,"qty":0.0,"timestamp":1626994950802}
1626994950.785836: {"feed":"book","product_id":"PI_ETHUSD","side":"buy","seq":26663252,"price":2003.5,"qty":0.0,"timestamp":1626994950803}
1626994950.785931: {"feed":"book","product_id":"PI_ETHUSD","side":"buy","seq":26663253,"price":2003.35,"qty":15826.0,"timestamp":1626994950803}
1626994950.7859762: {"feed":"book","product_id":"FI_XBTUSD_210924","side":"buy","seq":13502384,"price":32152.0,"qty":0.0,"timestamp":1626994950803}
1626994950.7860138: {"feed":"book","product_id":"FI_XBTUSD_210924","side":"buy","seq":13502385,"price":32149.0,"qty":1500.0,"timestamp":1626994950803}
1626994950.786058: {"feed":"book","product_id":"PI_ETHUSD","side":"buy","seq":26663254,"price":2003.45,"qty":20857.0,"timestamp":1626994950804}
1626994950.786083: {"feed":"book","product_id":"PI_ETHUSD","side":"buy","seq":26663255,"price":2003.3,"qty":20000.0,"timestamp":1626994950804}
1626994950.786109: {"feed":"book","product_id":"PI_ETHUSD","side":"buy","seq":26663256,"price":2003.65,"qty":0.0,"timestamp":1626994950805}
1626994950.786138: {"feed":"book","product_id":"PI_ETHUSD","side":"sell","seq":26663257,"price":2006.1,"qty":12554.0,"timestamp":1626994950805}
1626994950.78643: {"feed":"book","product_id":"FI_XBTUSD_210730","side":"buy","seq":5160197,"price":32128.5,"qty":547.0,"timestamp":1626994950807}
1626994950.786475: {"feed":"book","product_id":"FI_XBTUSD_210730","side":"buy","seq":5160198,"price":32125.5,"qty":1500.0,"timestamp":1626994950807}
1626994950.7894762: {"feed":"book","product_id":"FI_XBTUSD_210730","side":"buy","seq":5160199,"price":32169.5,"qty":0.0,"timestamp":1626994950809}
1626994950.789568: {"feed":"book","product_id":"FI_XBTUSD_210730","side":"buy","seq":5160200,"price":32164.5,"qty":30000.0,"timestamp":1626994950809}
1626994950.789609: {"feed":"book","product_id":"PI_ETHUSD","side":"buy","seq":26663258,"price":2003.8,"qty":0.0,"timestamp":1626994950808}
1626994950.7896461: {"feed":"book","product_id":"PI_ETHUSD","side":"buy","seq":26663259,"price":2003.5,"qty":600.0,"timestamp":1626994950808}
1626994950.789674: {"feed":"book","product_id":"PI_ETHUSD","side":"sell","seq":26663260,"price":2006.8,"qty":64.0,"timestamp":1626994950809}
1626994950.7900648: {"feed":"book","product_id":"FI_XBTUSD_210924","side":"buy","seq":13502386,"price":32207.0,"qty":50.0,"timestamp":1626994950809}
1626994950.790111: {"feed":"book","product_id":"FI_XBTUSD_210924","side":"buy","seq":13502387,"price":32202.5,"qty":1080.0,"timestamp":1626994950809}
1626994950.790144: {"feed":"book","product_id":"PI_ETHUSD","side":"buy","seq":26663261,"price":2003.0,"qty":0.0,"timestamp":1626994950810}
1626994950.790176: {"feed":"book","product_id":"PI_ETHUSD","side":"buy","seq":26663262,"price":2003.45,"qty":17020.0,"timestamp":1626994950811}
1626994950.7902: {"feed":"book","product_id":"PI_ETHUSD","side":"sell","seq":26663263,"price":2008.2,"qty":30000.0,"timestamp":1626994950811}
1626994950.7902222: {"feed":"book","product_id":"FI_XBTUSD_210730","side":"buy","seq":5160201,"price":32183.0,"qty":50.0,"timestamp":1626994950810}
1626994950.7902431: {"feed":"book","product_id":"FI_XBTUSD_210730","side":"buy","seq":5160202,"price":32178.5,"qty":1200.0,"timestamp":1626994950810}
1626994950.790267: {"feed":"book","product_id":"PI_ETHUSD","side":"sell","seq":26663264,"price":2007.4,"qty":4157.0,"timestamp":1626994950811}
1626994950.791554: {"feed":"book","product_id":"FI_XBTUSD_210924","side":"sell","seq":13502388,"price":32237.0,"qty":175783.0,"timestamp":1626994950810}
1626994950.791638: {"feed":"book","product_id":"FI_ETHUSD_211231","side":"buy","seq":2199172,"price":2028.85,"qty":96340.0,"timestamp":1626994950811}
1626994950.7916732: {"feed":"book","product_id":"FI_ETHUSD_211231","side":"buy","seq":2199173,"price":2028.3,"qty":10500.0,"timestamp":1626994950811}
1626994950.792068: {"feed":"book","product_id":"FI_XBTUSD_210924","side":"buy","seq":13502389,"price":32149.0,"qty":0.0,"timestamp":1626994950811}
1626994950.7921438: {"feed":"book","product_id":"FI_XBTUSD_210924","side":"buy","seq":13502390,"price":32146.0,"qty":22365.0,"timestamp":1626994950811}
1626994950.79409: {"feed":"book","product_id":"PI_ETHUSD","side":"sell","seq":26663265,"price":2005.9,"qty":6379.0,"timestamp":1626994950812}
1626994950.794183: {"feed":"book","product_id":"PI_ETHUSD","side":"sell","seq":26663266,"price":2005.55,"qty":15000.0,"timestamp":1626994950812}
1626994950.794228: {"feed":"book","product_id":"FI_XBTUSD_210730","side":"buy","seq":5160203,"price":32125.5,"qty":0.0,"timestamp":1626994950813}
1626994950.7942688: {"feed":"book","product_id":"FI_XBTUSD_210730","side":"buy","seq":5160204,"price":32128.5,"qty":2047.0,"timestamp":1626994950813}
1626994950.794295: {"feed":"book","product_id":"FI_ETHUSD_210730","side":"buy","seq":2138828,"price":2001.1,"qty":0.0,"timestamp":1626994950811}
1626994950.794327: {"feed":"book","product_id":"FI_ETHUSD_210730","side":"buy","seq":2138829,"price":2000.5,"qty":15000.0,"timestamp":1626994950811}
1626994950.794354: {"feed":"book","product_id":"PI_ETHUSD","side":"buy","seq":26663267,"price":2003.1,"qty":13899.0,"timestamp":1626994950812}
1626994950.794379: {"feed":"book","product_id":"PI_ETHUSD","side":"buy","seq":26663268,"price":2002.8,"qty":110775.0,"timestamp":1626994950812}
1626994950.800164: {"feed":"book","product_id":"PI_ETHUSD","side":"buy","seq":26663269,"price":2003.3,"qty":0.0,"timestamp":1626994950815}
1626994950.800321: {"feed":"book","product_id":"PI_ETHUSD","side":"buy","seq":26663270,"price":2003.2,"qty":20000.0,"timestamp":1626994950815}
1626994950.800365: {"feed":"book","product_id":"PI_LTCUSD","side":"buy","seq":3423352,"price":119.35,"qty":8023.0,"timestamp":1626994950814}
1626994950.8003929: {"feed":"book","product_id":"PI_ETHUSD","side":"buy","seq":26663271,"price":2003.35,"qty":0.0,"timestamp":1626994950815}
1626994950.8004239: {"feed":"book","product_id":"PI_ETHUSD","side":"buy","seq":26663272,"price":2003.25,"qty":15826.0,"timestamp":1626994950815}
1626994950.800468: {"feed":"book","product_id":"PI_LTCUSD","side":"buy","seq":3423353,"price":119.38,"qty":320.0,"timestamp":1626994950815}
1626994950.800491: {"feed":"book","product_id":"PI_ETHUSD","side":"sell","seq":26663273,"price":2005.9,"qty":8879.0,"timestamp":1626994950816}
1626994950.800513: {"feed":"book","product_id":"FI_ETHUSD_210730","side":"buy","seq":2138830,"price":1997.7,"qty":433.0,"timestamp":1626994950816}
1626994950.80054: {"feed":"book","product_id":"FI_ETHUSD_210730","side":"buy","seq":2138831,"price":1998.15,"qty":91407.0,"timestamp":1626994950816}
1626994950.800562: {"feed":"book","product_id":"FI_ETHUSD_210730","side":"buy","seq":2138832,"price":1998.55,"qty":0.0,"timestamp":1626994950816}
1626994950.800589: {"feed":"book","product_id":"PI_ETHUSD","side":"sell","seq":26663274,"price":2006.45,"qty":5000.0,"timestamp":1626994950817}
1626994950.800617: {"feed":"book","product_id":"FI_ETHUSD_210730","side":"sell","seq":2138833,"price":2005.35,"qty":433.0,"timestamp":1626994950817}
1626994950.800642: {"feed":"book","product_id":"PI_LTCUSD","side":"buy","seq":3423354,"price":119.26,"qty":8979.0,"timestamp":1626994950817}
1626994950.800664: {"feed":"book","product_id":"PI_LTCUSD","side":"buy","seq":3423355,"price":119.27,"qty":1000.0,"timestamp":1626994950817}
1626994950.800694: {"feed":"book","product_id":"PI_LTCUSD","side":"buy","seq":3423356,"price":119.27,"qty":0.0,"timestamp":1626994950820}
1626994950.800722: {"feed":"book","product_id":"PI_LTCUSD","side":"buy","seq":3423357,"price":119.26,"qty":9979.0,"timestamp":1626994950820}
1626994950.803068: {"feed":"book","product_id":"PI_ETHUSD","side":"buy","seq":26663275,"price":2003.2,"qty":0.0,"timestamp":1626994950823}
1626994950.803158: {"feed":"book","product_id":"PI_ETHUSD","side":"buy","seq":26663276,"price":2002.95,"qty":27746.0,"timestamp":1626994950823}
1626994950.803194: {"feed":"book","product_id":"PI_ETHUSD","side":"buy","seq":26663277,"price":2002.95,"qty":7746.0,"timestamp":1626994950823}
1626994950.80322: {"feed":"book","product_id":"PI_ETHUSD","side":"buy","seq":26663278,"price":2003.1,"qty":33899.0,"timestamp":1626994950823}
1626994950.803244: {"feed":"book","product_id":"PI_ETHUSD","side":"buy","seq":26663279,"price":2003.25,"qty":0.0,"timestamp":1626994950823}
1626994950.803282: {"feed":"book","product_id":"PI_ETHUSD","side":"buy","seq":26663280,"price":2003.15,"qty":15826.0,"timestamp":1626994950823}
1626994950.803636: {"feed":"book","product_id":"FI_XBTUSD_210924","side":"buy","seq":13502391,"price":32146.0,"qty":20865.0,"timestamp":1626994950824}
1626994950.803682: {"feed":"book","product_id":"FI_XBTUSD_210924","side":"buy","seq":13502392,"price":32149.0,"qty":1500.0,"timestamp":1626994950824}
1626994950.8037162: {"feed":"book","product_id":"PI_ETHUSD","side":"buy","seq":26663281,"price":2003.65,"qty":2500.0,"timestamp":1626994950824}
1626994950.808553: {"feed":"book","product_id":"FI_XBTUSD_210924","side":"buy","seq":13502393,"price":31616.0,"qty":5000.0,"timestamp":1626994950829}
1626994950.809058: {"feed":"book","product_id":"FI_XBTUSD_210924","side":"sell","seq":13502394,"price":32285.0,"qty":0.0,"timestamp":1626994950830}
1626994950.809123: {"feed":"book","product_id":"FI_XBTUSD_210924","side":"sell","seq":13502395,"price":32267.0,"qty":20000.0,"timestamp":1626994950830}
1626994950.810913: {"feed":"book","product_id":"PI_ETHUSD","side":"buy","seq":26663282,"price":2002.55,"qty":5171.0,"timestamp":1626994950830}
1626994950.811015: {"feed":"book","product_id":"FI_XBTUSD_210730","side":"buy","seq":5160205,"price":32118.0,"qty":0.0,"timestamp":1626994950830}
1626994950.811062: {"feed":"book","product_id":"FI_XBTUSD_210730","side":"buy","seq":5160206,"price":32111.5,"qty":250001.0,"timestamp":1626994950830}
1626994950.811095: {"feed":"book","product_id":"FI_XBTUSD_210924","side":"buy","seq":13502396,"price":32136.5,"qty":0.0,"timestamp":1626994950830}
1626994950.811127: {"feed":"book","product_id":"FI_XBTUSD_210924","side":"buy","seq":13502397,"price":32133.5,"qty":252401.0,"timestamp":1626994950830}
1626994950.812772: {"feed":"book","product_id":"PI_ETHUSD","side":"buy","seq":26663283,"price":2003.15,"qty":0.0,"timestamp":1626994950831}
1626994950.812858: {"feed":"book","product_id":"PI_ETHUSD","side":"buy","seq":26663284,"price":2003.0,"qty":15826.0,"timestamp":1626994950831}
1626994950.81291: {"feed":"book","product_id":"FI_XBTUSD_210730","side":"buy","seq":5160207,"price":32128.5,"qty":547.0,"timestamp":1626994950831}
1626994950.812938: {"feed":"book","product_id":"FI_XBTUSD_210730","side":"buy","seq":5160208,"price":32126.0,"qty":1500.0,"timestamp":1626994950831}
1626994950.812968: {"feed":"book","product_id":"PI_ETHUSD","side":"sell","seq":26663285,"price":2006.25,"qty":62.0,"timestamp":1626994950832}
1626994950.813316: {"feed":"book","product_id":"PI_ETHUSD","side":"buy","seq":26663286,"price":2001.25,"qty":5068.0,"timestamp":1626994950833}
1626994950.813361: {"feed":"book","product_id":"PI_ETHUSD","side":"buy","seq":26663287,"price":2000.8,"qty":158400.0,"timestamp":1626994950833}
1626994950.813388: {"feed":"book","product_id":"FI_XBTUSD_210730","side":"buy","seq":5160209,"price":32126.0,"qty":0.0,"timestamp":1626994950833}
1626994950.813422: {"feed":"book","product_id":"FI_XBTUSD_210730","side":"buy","seq":5160210,"price":32123.5,"qty":1500.0,"timestamp":1626994950833}
1626994950.8138628: {"feed":"book","product_id":"PI_ETHUSD","side":"buy","seq":26663288,"price":2003.1,"qty":13899.0,"timestamp":1626994950835}
1626994950.813916: {"feed":"book","product_id":"PI_ETHUSD","side":"buy","seq":26663289,"price":2003.05,"qty":20000.0,"timestamp":1626994950835}
1626994950.814894: {"feed":"book","product_id":"FI_XBTUSD_210924","side":"buy","seq":13502398,"price":32149.0,"qty":0.0,"timestamp":1626994950835}
1626994950.8149812: {"feed":"book","product_id":"FI_XBTUSD_210924","side":"buy","seq":13502399,"price":32146.5,"qty":1500.0,"timestamp":1626994950835}
1626994950.815039: {"feed":"book","product_id":"FI_XBTUSD_210730","side":"buy","seq":5160211,"price":32123.5,"qty":0.0,"timestamp":1626994950836}
1626994950.815074: {"feed":"book","product_id":"FI_XBTUSD_210730","side":"buy","seq":5160212,"price":32125.0,"qty":1500.0,"timestamp":1626994950836}
1626994950.818902: {"feed":"book","product_id":"PI_ETHUSD","side":"buy","seq":26663290,"price":2003.0,"qty":0.0,"timestamp":1626994950839}
1626994950.819026: {"feed":"book","product_id":"PI_ETHUSD","side":"buy","seq":26663291,"price":2003.1,"qty":29725.0,"timestamp":1626994950839}
1626994950.8209448: {"feed":"book","product_id":"PI_ETHUSD","side":"buy","seq":26663292,"price":2001.45,"qty":0.0,"timestamp":1626994950840}
1626994950.821034: {"feed":"book","product_id":"PI_ETHUSD","side":"buy","seq":26663293,"price":2001.0,"qty":125638.0,"timestamp":1626994950840}
1626994950.821077: {"feed":"book","product_id":"FI_XBTUSD_210924","side":"sell","seq":13502400,"price":32234.5,"qty":0.0,"timestamp":1626994950841}
1626994950.821121: {"feed":"book","product_id":"FI_XBTUSD_210924","side":"sell","seq":13502401,"price":32236.0,"qty":1.0,"timestamp":1626994950841}
1626994950.821152: {"feed":"book","product_id":"PI_ETHUSD","side":"buy","seq":26663294,"price":2003.05,"qty":0.0,"timestamp":1626994950842}
1626994950.821184: {"feed":"book","product_id":"PI_ETHUSD","side":"buy","seq":26663295,"price":2003.0,"qty":20000.0,"timestamp":1626994950842}
1626994950.821496: {"feed":"book","product_id":"FI_XBTUSD_210924","side":"buy","seq":13502402,"price":32146.5,"qty":0.0,"timestamp":1626994950842}
1626994950.8215501: {"feed":"book","product_id":"FI_XBTUSD_210924","side":"buy","seq":13502403,"price":32144.0,"qty":1500.0,"timestamp":1626994950842}
1626994950.821584: {"feed":"book","product_id":"FI_ETHUSD_211231","side":"buy","seq":2199174,"price":2027.35,"qty":0.0,"timestamp":1626994950843}
1626994950.8265522: {"feed":"book","product_id":"FI_XBTUSD_210924","side":"buy","seq":13502404,"price":32144.0,"qty":0.0,"timestamp":1626994950845}
1626994950.826676: {"feed":"book","product_id":"FI_XBTUSD_210924","side":"buy","seq":13502405,"price":32145.5,"qty":1500.0,"timestamp":1626994950845}
1626994950.830104: {"feed":"book","product_id":"PI_ETHUSD","side":"buy","seq":26663296,"price":1996.5,"qty":0.0,"timestamp":1626994950847}
1626994950.8302279: {"feed":"book","product_id":"PI_ETHUSD","side":"buy","seq":26663297,"price":1993.2,"qty":55157.0,"timestamp":1626994950847}
1626994950.830293: {"feed":"book","product_id":"PI_ETHUSD","side":"sell","seq":26663298,"price":2007.1,"qty":4189.0,"timestamp":1626994950847}
1626994950.830336: {"feed":"book","product_id":"PI_ETHUSD","side":"sell","seq":26663299,"price":2006.35,"qty":10534.0,"timestamp":1626994950847}
1626994950.830841: {"feed":"book","product_id":"PI_ETHUSD","side":"buy","seq":26663300,"price":2000.55,"qty":0.0,"timestamp":1626994950847}
1626994950.830894: {"feed":"book","product_id":"PI_ETHUSD","side":"buy","seq":26663301,"price":2000.05,"qty":24889.0,"timestamp":1626994950847}
1626994950.8309288: {"feed":"book","product_id":"PI_ETHUSD","side":"sell","seq":26663302,"price":2013.35,"qty":0.0,"timestamp":1626994950847}
1626994950.830962: {"feed":"book","product_id":"PI_ETHUSD","side":"sell","seq":26663303,"price":2012.15,"qty":45338.0,"timestamp":1626994950847}
1626994950.830991: {"feed":"book","product_id":"PI_ETHUSD","side":"sell","seq":26663304,"price":2008.45,"qty":0.0,"timestamp":1626994950847}
1626994950.831019: {"feed":"book","product_id":"PI_ETHUSD","side":"sell","seq":26663305,"price":2008.15,"qty":27904.0,"timestamp":1626994950847}
1626994950.831042: {"feed":"book","product_id":"PI_ETHUSD","side":"buy","seq":26663306,"price":2001.3,"qty":0.0,"timestamp":1626994950847}
1626994950.83107: {"feed":"book","product_id":"PI_ETHUSD","side":"buy","seq":26663307,"price":2001.25,"qty":21125.0,"timestamp":1626994950847}
1626994950.831092: {"feed":"book","product_id":"PI_ETHUSD","side":"buy","seq":26663308,"price":2003.1,"qty":13899.0,"timestamp":1626994950847}
1626994950.831112: {"feed":"book","product_id":"PI_ETHUSD","side":"buy","seq":26663309,"price":2003.05,"qty":15826.0,"timestamp":1626994950847}
1626994950.8311522: {"feed":"book","product_id":"PI_ETHUSD","side":"buy","seq":26663310,"price":2003.45,"qty":12020.0,"timestamp":1626994950851}
1626994950.838475: {"feed":"book","product_id":"FI_XBTUSD_210924","side":"buy","seq":13502406,"price":32192.0,"qty":0.0,"timestamp":1626994950856}
1626994950.8386: {"feed":"book","product_id":"PI_ETHUSD","side":"buy","seq":26663311,"price":2003.05,"qty":0.0,"timestamp":1626994950857}
1626994950.838666: {"feed":"book","product_id":"PI_ETHUSD","side":"buy","seq":26663312,"price":2003.0,"qty":35826.0,"timestamp":1626994950857}
1626994950.838728: {"feed":"book","product_id":"PI_LTCUSD","side":"buy","seq":3423358,"price":119.37,"qty":0.0,"timestamp":1626994950858}
1626994950.8387609: {"feed":"book","product_id":"FI_XRPUSD_210924","side":"buy","seq":602297,"price":0.5836,"qty":0.0,"timestamp":1626994950859}
1626994950.842388: {"feed":"book","product_id":"FI_BCHUSD_210924","side":"buy","seq":402249,"price":440.3,"qty":0.0,"timestamp":1626994950861}
1626994950.842474: {"feed":"book","product_id":"FI_XRPUSD_210924","side":"sell","seq":602298,"price":0.5872,"qty":49.0,"timestamp":1626994950862}
1626994950.842517: {"feed":"book","product_id":"FI_BCHUSD_210924","side":"buy","seq":402250,"price":440.1,"qty":61.0,"timestamp":1626994950862}
1626994950.8428512: {"feed":"book","product_id":"PI_ETHUSD","side":"buy","seq":26663313,"price":1993.15,"qty":0.0,"timestamp":1626994950862}
1626994950.84291: {"feed":"book","product_id":"PI_ETHUSD","side":"buy","seq":26663314,"price":1993.25,"qty":500002.0,"timestamp":1626994950862}
1626994950.842946: {"feed":"book","product_id":"PI_XRPUSD","side":"buy","seq":3456254,"price":0.5881,"qty":4205.0,"timestamp":1626994950862}
1626994950.842973: {"feed":"book","product_id":"PI_ETHUSD","side":"sell","seq":26663315,"price":2013.3,"qty":0.0,"timestamp":1626994950862}
1626994950.843005: {"feed":"book","product_id":"PI_ETHUSD","side":"sell","seq":26663316,"price":2013.7,"qty":500002.0,"timestamp":1626994950862}
1626994950.8430321: {"feed":"book","product_id":"FI_BCHUSD_210924","side":"sell","seq":402251,"price":442.7,"qty":61.0,"timestamp":1626994950864}
1626994950.845792: {"feed":"book","product_id":"FI_XBTUSD_210730","side":"buy","seq":5160213,"price":32111.5,"qty":0.0,"timestamp":1626994950864}
1626994950.8458922: {"feed":"book","product_id":"FI_XBTUSD_210730","side":"buy","seq":5160214,"price":32091.5,"qty":250001.0,"timestamp":1626994950864}
1626994950.845936: {"feed":"book","product_id":"FI_XBTUSD_210924","side":"buy","seq":13502407,"price":32133.5,"qty":2400.0,"timestamp":1626994950864}
1626994950.845964: {"feed":"book","product_id":"FI_XBTUSD_210924","side":"buy","seq":13502408,"price":32118.0,"qty":250001.0,"timestamp":1626994950864}
1626994950.845993: {"feed":"book","product_id":"PI_ETHUSD","side":"buy","seq":26663317,"price":2003.0,"qty":15826.0,"timestamp":1626994950867}
1626994950.846018: {"feed":"book","product_id":"PI_ETHUSD","side":"buy","seq":26663318,"price":2002.9,"qty":20000.0,"timestamp":1626994950867}
1626994950.847491: {"feed":"book","product_id":"PI_ETHUSD","side":"buy","seq":26663319,"price":2003.0,"qty":0.0,"timestamp":1626994950867}
1626994950.8475552: {"feed":"book","product_id":"PI_ETHUSD","side":"buy","seq":26663320,"price":2002.95,"qty":23572.0,"timestamp":1626994950867}
1626994950.84759: {"feed":"book","product_id":"PI_ETHUSD","side":"buy","seq":26663321,"price":2003.1,"qty":3899.0,"timestamp":1626994950868}
1626994950.849809: {"feed":"book","product_id":"FI_ETHUSD_211231","side":"buy","seq":2199175,"price":2027.05,"qty":5000.0,"timestamp":1626994950870}
1626994950.849898: {"feed":"book","product_id":"FI_ETHUSD_211231","side":"sell","seq":2199176,"price":2033.8,"qty":5000.0,"timestamp":1626994950870}
1626994950.85289: {"feed":"book","product_id":"PI_ETHUSD","side":"buy","seq":26663322,"price":2002.9,"qty":0.0,"timestamp":1626994950873}
1626994950.8529549: {"feed":"book","product_id":"PI_ETHUSD","side":"buy","seq":26663323,"price":2002.75,"qty":20000.0,"timestamp":1626994950873}
1626994950.852996: {"feed":"book","product_id":"PI_ETHUSD","side":"buy","seq":26663324,"price":2002.95,"qty":7746.0,"timestamp":1626994950874}
1626994950.853023: {"feed":"book","product_id":"PI_ETHUSD","side":"buy","seq":26663325,"price":2002.8,"qty":126601.0,"timestamp":1626994950874}
1626994950.859398: {"feed":"book","product_id":"PI_LTCUSD","side":"buy","seq":3423359,"price":119.36,"qty":0.0,"timestamp":1626994950878}
1626994950.859522: {"feed":"book","product_id":"PI_LTCUSD","side":"buy","seq":3423360,"price":119.31,"qty":7962.0,"timestamp":1626994950878}
1626994950.8652658: {"feed":"book","product_id":"PI_XRPUSD","side":"sell","seq":3456255,"price":0.5894,"qty":5224.0,"timestamp":1626994950885}
1626994950.865381: {"feed":"book","product_id":"PI_XRPUSD","side":"sell","seq":3456256,"price":0.5892,"qty":7943.0,"timestamp":1626994950885}
1626994950.8658931: {"feed":"book","product_id":"PI_XRPUSD","side":"buy","seq":3456257,"price":0.5881,"qty":3885.0,"timestamp":1626994950887}
1626994950.86597: {"feed":"book","product_id":"PI_XRPUSD","side":"buy","seq":3456258,"price":0.588,"qty":14187.0,"timestamp":1626994950887}
1626994950.866014: {"feed":"book","product_id":"PI_XRPUSD","side":"buy","seq":3456259,"price":0.5877,"qty":5199.0,"timestamp":1626994950887}
1626994950.86876: {"feed":"book","product_id":"PI_XRPUSD","side":"buy","seq":3456260,"price":0.5878,"qty":14955.0,"timestamp":1626994950888}
1626994950.868872: {"feed":"book","product_id":"PI_XRPUSD","side":"buy","seq":3456261,"price":0.5877,"qty":13199.0,"timestamp":1626994950888}
1626994950.868945: {"feed":"book","product_id":"PI_XRPUSD","side":"sell","seq":3456262,"price":0.5889,"qty":2.0,"timestamp":1626994950888}
1626994950.868971: {"feed":"book","product_id":"PI_XRPUSD","side":"sell","seq":3456263,"price":0.5888,"qty":8261.0,"timestamp":1626994950888}
1626994950.868994: {"feed":"book","product_id":"PI_XRPUSD","side":"buy","seq":3456264,"price":0.5876,"qty":15078.0,"timestamp":1626994950888}
1626994950.869015: {"feed":"book","product_id":"PI_XRPUSD","side":"sell","seq":3456265,"price":0.589,"qty":4072.0,"timestamp":1626994950889}
1626994950.869047: {"feed":"book","product_id":"PI_XRPUSD","side":"buy","seq":3456266,"price":0.5879,"qty":4197.0,"timestamp":1626994950889}
1626994950.869069: {"feed":"book","product_id":"PI_XRPUSD","side":"sell","seq":3456267,"price":0.5891,"qty":4037.0,"timestamp":1626994950890}
1626994950.871535: {"feed":"book","product_id":"FI_ETHUSD_210730","side":"sell","seq":2138834,"price":2002.9,"qty":88530.0,"timestamp":1626994950891}
1626994950.871626: {"feed":"book","product_id":"PI_LTCUSD","side":"sell","seq":3423361,"price":119.54,"qty":56720.0,"timestamp":1626994950891}
1626994950.8716621: {"feed":"book","product_id":"PI_ETHUSD","side":"buy","seq":26663326,"price":2004.0,"qty":0.0,"timestamp":1626994950891}
1626994950.871702: {"feed":"book","product_id":"PI_XRPUSD","side":"buy","seq":3456268,"price":0.5879,"qty":0.0,"timestamp":1626994950891}
1626994950.876116: {"feed":"book","product_id":"PI_XRPUSD","side":"buy","seq":3456269,"price":0.588,"qty":4237.0,"timestamp":1626994950893}
1626994950.8762271: {"feed":"book","product_id":"PI_XRPUSD","side":"buy","seq":3456270,"price":0.5882,"qty":9950.0,"timestamp":1626994950893}
1626994950.87629: {"feed":"book","product_id":"PI_ETHUSD","side":"sell","seq":26663327,"price":2006.1,"qty":0.0,"timestamp":1626994950897}
1626994950.876699: {"feed":"book","product_id":"PI_LTCUSD","side":"sell","seq":3423362,"price":119.7,"qty":16000.0,"timestamp":1626994950898}
1626994950.8784509: {"feed":"book","product_id":"PI_LTCUSD","side":"sell","seq":3423363,"price":119.65,"qty":4198.0,"timestamp":1626994950899}
1626994950.878539: {"feed":"book","product_id":"PI_LTCUSD","side":"sell","seq":3423364,"price":119.61,"qty":4235.0,"timestamp":1626994950899}
1626994950.8842418: {"feed":"book","product_id":"PI_ETHUSD","side":"buy","seq":26663328,"price":2002.75,"qty":0.0,"timestamp":1626994950904}
1626994950.8843699: {"feed":"book","product_id":"PI_ETHUSD","side":"buy","seq":26663329,"price":2002.95,"qty":27746.0,"timestamp":1626994950904}
1626994950.884425: {"feed":"book","product_id":"PI_ETHUSD","side":"sell","seq":26663330,"price":2008.7,"qty":13111.0,"timestamp":1626994950904}
1626994950.884492: {"feed":"book","product_id":"PI_ETHUSD","side":"sell","seq":26663331,"price":2007.4,"qty":504158.0,"timestamp":1626994950904}
1626994950.886536: {"feed":"book","product_id":"FI_ETHUSD_210730","side":"buy","seq":2138835,"price":1996.65,"qty":0.0,"timestamp":1626994950904}
1626994950.886624: {"feed":"book","product_id":"FI_ETHUSD_210730","side":"buy","seq":2138836,"price":1995.5,"qty":250001.0,"timestamp":1626994950904}
1626994950.886667: {"feed":"book","product_id":"PI_ETHUSD","side":"sell","seq":26663332,"price":2013.7,"qty":0.0,"timestamp":1626994950905}
1626994950.886705: {"feed":"book","product_id":"PI_ETHUSD","side":"sell","seq":26663333,"price":2012.1,"qty":500002.0,"timestamp":1626994950905}
1626994950.886736: {"feed":"book","product_id":"PI_ETHUSD","side":"sell","seq":26663334,"price":2005.55,"qty":19219.0,"timestamp":1626994950906}
1626994950.88676: {"feed":"book","product_id":"FI_XBTUSD_210730","side":"buy","seq":5160215,"price":32125.0,"qty":0.0,"timestamp":1626994950905}
1626994950.8867898: {"feed":"book","product_id":"FI_XBTUSD_210730","side":"buy","seq":5160216,"price":32121.0,"qty":1500.0,"timestamp":1626994950905}
1626994950.886817: {"feed":"book","product_id":"FI_XBTUSD_210924","side":"buy","seq":13502409,"price":32145.5,"qty":0.0,"timestamp":1626994950905}
1626994950.886846: {"feed":"book","product_id":"FI_XBTUSD_210924","side":"buy","seq":13502410,"price":32141.5,"qty":1500.0,"timestamp":1626994950905}
1626994950.886871: {"feed":"book","product_id":"PI_XRPUSD","side":"buy","seq":3456271,"price":0.5881,"qty":0.0,"timestamp":1626994950907}
1626994950.8896809: {"feed":"book","product_id":"PI_LTCUSD","side":"sell","seq":3423365,"price":119.66,"qty":1062.0,"timestamp":1626994950907}
1626994950.8897998: {"feed":"book","product_id":"PI_LTCUSD","side":"sell","seq":3423366,"price":119.61,"qty":60.0,"timestamp":1626994950907}
1626994950.8898518: {"feed":"book","product_id":"PI_LTCUSD","side":"sell","seq":3423367,"price":119.58,"qty":4064.0,"timestamp":1626994950909}
1626994950.889888: {"feed":"book","product_id":"PI_ETHUSD","side":"buy","seq":26663335,"price":2002.55,"qty":0.0,"timestamp":1626994950907}
1626994950.89437: {"feed":"book","product_id":"PI_XRPUSD","side":"sell","seq":3456272,"price":0.5896,"qty":4987.0,"timestamp":1626994950908}
1626994950.8944929: {"feed":"book","product_id":"FI_XBTUSD_210924","side":"buy","seq":13502411,"price":32202.5,"qty":0.0,"timestamp":1626994950908}
1626994950.894573: {"feed":"book","product_id":"FI_XBTUSD_210924","side":"buy","seq":13502412,"price":32197.5,"qty":1080.0,"timestamp":1626994950908}
1626994950.894607: {"feed":"book","product_id":"PI_XRPUSD","side":"buy","seq":3456273,"price":0.5879,"qty":3932.0,"timestamp":1626994950908}
1626994950.894638: {"feed":"book","product_id":"FI_XBTUSD_210730","side":"buy","seq":5160217,"price":32178.5,"qty":0.0,"timestamp":1626994950909}
1626994950.89467: {"feed":"book","product_id":"FI_XBTUSD_210730","side":"buy","seq":5160218,"price":32173.5,"qty":1200.0,"timestamp":1626994950909}
1626994950.894696: {"feed":"book","product_id":"FI_XBTUSD_210730","side":"sell","seq":5160219,"price":32215.0,"qty":0.0,"timestamp":1626994950909}
1626994950.8947241: {"feed":"book","product_id":"FI_XBTUSD_210730","side":"sell","seq":5160220,"price":32209.0,"qty":30000.0,"timestamp":1626994950909}
1626994950.8947499: {"feed":"book","product_id":"FI_XBTUSD_210730","side":"buy","seq":5160221,"price":32164.5,"qty":0.0,"timestamp":1626994950909}
1626994950.8947752: {"feed":"book","product_id":"FI_XBTUSD_210730","side":"buy","seq":5160222,"price":32159.5,"qty":30000.0,"timestamp":1626994950909}
1626994950.8948: {"feed":"book","product_id":"FI_XBTUSD_210730","side":"buy","seq":5160223,"price":32121.0,"qty":0.0,"timestamp":1626994950911}
1626994950.894825: {"feed":"book","product_id":"FI_XBTUSD_210730","side":"buy","seq":5160224,"price":32123.5,"qty":1500.0,"timestamp":1626994950911}
1626994950.894848: {"feed":"book","product_id":"PI_ETHUSD","side":"sell","seq":26663336,"price":2007.75,"qty":175154.0,"timestamp":1626994950910}
1626994950.894872: {"feed":"book","product_id":"PI_ETHUSD","side":"sell","seq":26663337,"price":2007.25,"qty":153830.0,"timestamp":1626994950910}
1626994950.8948932: {"feed":"book","product_id":"PI_ETHUSD","side":"buy","seq":26663338,"price":2003.1,"qty":0.0,"timestamp":1626994950911}
1626994950.902184: {"feed":"book","product_id":"PI_XRPUSD","side":"buy","seq":3456274,"price":0.5878,"qty":18837.0,"timestamp":1626994950909}
1626994950.90231: {"feed":"book","product_id":"FI_XBTUSD_210924","side":"buy","seq":13502413,"price":32141.5,"qty":0.0,"timestamp":1626994950914}
1626994950.902357: {"feed":"book","product_id":"FI_XBTUSD_210924","side":"buy","seq":13502414,"price":32144.0,"qty":1500.0,"timestamp":1626994950914}
1626994950.9023921: {"feed":"book","product_id":"PI_XRPUSD","side":"buy","seq":3456275,"price":0.5882,"qty":0.0,"timestamp":1626994950910}
1626994950.902427: {"feed":"book","product_id":"PI_XRPUSD","side":"buy","seq":3456276,"price":0.5881,"qty":9950.0,"timestamp":1626994950910}
1626994950.902455: {"feed":"book","product_id":"PI_ETHUSD","side":"buy","seq":26663339,"price":2002.8,"qty":110775.0,"timestamp":1626994950914}
1626994950.9024808: {"feed":"book","product_id":"PI_ETHUSD","side":"buy","seq":26663340,"price":2002.6,"qty":15826.0,"timestamp":1626994950914}
1626994950.902509: {"feed":"book","product_id":"PI_XRPUSD","side":"sell","seq":3456277,"price":0.618,"qty":0.0,"timestamp":1626994950910}
1626994950.902538: {"feed":"book","product_id":"PI_XRPUSD","side":"sell","seq":3456278,"price":0.6179,"qty":50.0,"timestamp":1626994950910}
1626994950.902564: {"feed":"book","product_id":"PI_XRPUSD","side":"sell","seq":3456279,"price":0.5893,"qty":27111.0,"timestamp":1626994950910}
1626994950.9025862: {"feed":"book","product_id":"PI_ETHUSD","side":"buy","seq":26663341,"price":2002.95,"qty":7746.0,"timestamp":1626994950914}
1626994950.9026072: {"feed":"book","product_id":"PI_ETHUSD","side":"buy","seq":26663342,"price":2002.65,"qty":31528.0,"timestamp":1626994950914}
1626994950.9026282: {"feed":"book","product_id":"PI_XRPUSD","side":"buy","seq":3456280,"price":0.5879,"qty":5433.0,"timestamp":1626994950910}
1626994950.9026618: {"feed":"book","product_id":"PI_XRPUSD","side":"buy","seq":3456281,"price":0.588,"qty":320.0,"timestamp":1626994950912}
1626994950.9026828: {"feed":"book","product_id":"PI_ETHUSD","side":"buy","seq":26663343,"price":2002.65,"qty":11528.0,"timestamp":1626994950915}
1626994950.902703: {"feed":"book","product_id":"PI_ETHUSD","side":"buy","seq":26663344,"price":2002.55,"qty":20000.0,"timestamp":1626994950915}
1626994950.902727: {"feed":"book","product_id":"PI_XRPUSD","side":"buy","seq":3456282,"price":0.5881,"qty":0.0,"timestamp":1626994950913}
1626994950.902754: {"feed":"book","product_id":"PI_XRPUSD","side":"buy","seq":3456283,"price":0.5882,"qty":9950.0,"timestamp":1626994950913}
1626994950.9027789: {"feed":"book","product_id":"FI_XBTUSD_210924","side":"buy","seq":13502415,"price":30935.0,"qty":10000.0,"timestamp":1626994950917}
1626994950.904027: {"feed":"book","product_id":"PI_XRPUSD","side":"sell","seq":3456284,"price":0.6179,"qty":0.0,"timestamp":1626994950913}
1626994950.904115: {"feed":"book","product_id":"PI_XRPUSD","side":"sell","seq":3456285,"price":0.618,"qty":50.0,"timestamp":1626994950913}
1626994950.9041579: {"feed":"book","product_id":"PI_ETHUSD","side":"sell","seq":26663345,"price":2005.5,"qty":103824.0,"timestamp":1626994950918}
1626994950.904188: {"feed":"book","product_id":"PI_XRPUSD","side":"buy","seq":3456286,"price":0.5882,"qty":0.0,"timestamp":1626994950916}
1626994950.9042208: {"feed":"book","product_id":"PI_XRPUSD","side":"buy","seq":3456287,"price":0.5881,"qty":9950.0,"timestamp":1626994950916}
1626994950.9042492: {"feed":"book","product_id":"PI_XRPUSD","side":"sell","seq":3456288,"price":0.618,"qty":0.0,"timestamp":1626994950916}
1626994950.904277: {"feed":"book","product_id":"PI_XRPUSD","side":"sell","seq":3456289,"price":0.6179,"qty":50.0,"timestamp":1626994950916}
1626994950.904304: {"feed":"book","product_id":"FI_ETHUSD_210730","side":"sell","seq":2138837,"price":2005.6,"qty":0.0,"timestamp":1626994950918}
1626994950.904333: {"feed":"book","product_id":"FI_ETHUSD_210730","side":"sell","seq":2138838,"price":2005.35,"qty":4233.0,"timestamp":1626994950918}
1626994950.904363: {"feed":"book","product_id":"FI_ETHUSD_210730","side":"sell","seq":2138839,"price":2011.2,"qty":15307.0,"timestamp":1626994950918}
1626994950.9043999: {"feed":"book","product_id":"FI_ETHUSD_210730","side":"sell","seq":2138840,"price":2008.35,"qty":3600.0,"timestamp":1626994950918}
1626994950.904421: {"feed":"book","product_id":"FI_ETHUSD_210730","side":"sell","seq":2138841,"price":2008.35,"qty":400.0,"timestamp":1626994950918}
1626994950.904442: {"feed":"book","product_id":"FI_ETHUSD_210730","side":"sell","seq":2138842,"price":2007.15,"qty":245045.0,"timestamp":1626994950918}
1626994950.904462: {"feed":"book","product_id":"FI_XBTUSD_210730","side":"buy","seq":5160225,"price":32123.5,"qty":0.0,"timestamp":1626994950918}
1626994950.904489: {"feed":"book","product_id":"FI_XBTUSD_210730","side":"buy","seq":5160226,"price":32121.0,"qty":1500.0,"timestamp":1626994950918}
1626994950.909128: {"feed":"book","product_id":"PI_ETHUSD","side":"buy","seq":26663346,"price":2003.45,"qty":5963.0,"timestamp":1626994950921}
1626994950.909238: {"feed":"book","product_id":"PI_ETHUSD","side":"buy","seq":26663347,"price":2002.3,"qty":3928.0,"timestamp":1626994950923}
1626994950.909312: {"feed":"book","product_id":"PI_ETHUSD","side":"buy","seq":26663348,"price":2002.95,"qty":3825.0,"timestamp":1626994950924}
1626994950.909371: {"feed":"book","product_id":"PI_ETHUSD","side":"buy","seq":26663349,"price":2002.55,"qty":0.0,"timestamp":1626994950925}
1626994950.909406: {"feed":"book","product_id":"PI_ETHUSD","side":"buy","seq":26663350,"price":2002.5,"qty":20000.0,"timestamp":1626994950925}
1626994950.909434: {"feed":"book","product_id":"PI_XRPUSD","side":"sell","seq":3456290,"price":0.5893,"qty":25565.0,"timestamp":1626994950921}
1626994950.9094589: {"feed":"book","product_id":"FI_XBTUSD_210924","side":"buy","seq":13502416,"price":32144.0,"qty":0.0,"timestamp":1626994950923}
1626994950.909491: {"feed":"book","product_id":"FI_XBTUSD_210924","side":"buy","seq":13502417,"price":32141.5,"qty":1500.0,"timestamp":1626994950923}
1626994950.909518: {"feed":"book","product_id":"PI_ETHUSD","side":"buy","seq":26663351,"price":2002.6,"qty":0.0,"timestamp":1626994950925}
1626994950.909545: {"feed":"book","product_id":"PI_ETHUSD","side":"buy","seq":26663352,"price":2003.0,"qty":15826.0,"timestamp":1626994950925}
1626994950.90957: {"feed":"book","product_id":"PI_ETHUSD","side":"sell","seq":26663353,"price":2005.9,"qty":16388.0,"timestamp":1626994950926}
1626994950.909591: {"feed":"book","product_id":"PI_ETHUSD","side":"buy","seq":26663354,"price":2000.8,"qty":150063.0,"timestamp":1626994950927}
1626994950.909612: {"feed":"book","product_id":"PI_LTCUSD","side":"sell","seq":3423368,"price":119.62,"qty":3993.0,"timestamp":1626994950909}
1626994950.9144: {"feed":"book","product_id":"PI_ETHUSD","side":"buy","seq":26663355,"price":2003.5,"qty":0.0,"timestamp":1626994950930}
1626994950.9145222: {"feed":"book","product_id":"PI_ETHUSD","side":"buy","seq":26663356,"price":2003.25,"qty":600.0,"timestamp":1626994950930}
1626994950.914588: {"feed":"book","product_id":"PI_ETHUSD","side":"buy","seq":26663357,"price":2001.1,"qty":0.0,"timestamp":1626994950931}
1626994950.914638: {"feed":"book","product_id":"PI_ETHUSD","side":"buy","seq":26663358,"price":2000.2,"qty":30000.0,"timestamp":1626994950931}
1626994950.9146821: {"feed":"book","product_id":"FI_ETHUSD_210730","side":"sell","seq":2138843,"price":2004.3,"qty":0.0,"timestamp":1626994950931}
1626994950.914737: {"feed":"book","product_id":"FI_ETHUSD_210730","side":"sell","seq":2138844,"price":2003.75,"qty":15000.0,"timestamp":1626994950931}
1626994950.914787: {"feed":"book","product_id":"PI_ETHUSD","side":"buy","seq":26663359,"price":2002.8,"qty":95775.0,"timestamp":1626994950931}
1626994950.914809: {"feed":"book","product_id":"PI_ETHUSD","side":"buy","seq":26663360,"price":2002.5,"qty":35000.0,"timestamp":1626994950931}
1626994950.914829: {"feed":"book","product_id":"PI_ETHUSD","side":"sell","seq":26663361,"price":2005.35,"qty":0.0,"timestamp":1626994950931}
1626994950.914857: {"feed":"book","product_id":"FI_ETHUSD_211231","side":"sell","seq":2199177,"price":2048.4,"qty":44305.0,"timestamp":1626994950932}
1626994950.914879: {"feed":"book","product_id":"FI_ETHUSD_211231","side":"sell","seq":2199178,"price":2048.3,"qty":45099.0,"timestamp":1626994950932}
1626994950.914903: {"feed":"book","product_id":"FI_ETHUSD_211231","side":"sell","seq":2199179,"price":2048.4,"qty":0.0,"timestamp":1626994950932}
1626994950.914929: {"feed":"book","product_id":"FI_ETHUSD_211231","side":"sell","seq":2199180,"price":2048.3,"qty":89404.0,"timestamp":1626994950932}
1626994950.9196138: {"feed":"book","product_id":"PI_ETHUSD","side":"buy","seq":26663362,"price":2002.45,"qty":8327.0,"timestamp":1626994950936}
1626994950.919722: {"feed":"book","product_id":"PI_XRPUSD","side":"buy","seq":3456291,"price":0.5871,"qty":0.0,"timestamp":1626994950939}
1626994950.9197922: {"feed":"book","product_id":"PI_ETHUSD","side":"buy","seq":26663363,"price":2003.45,"qty":0.0,"timestamp":1626994950938}
1626994950.919847: {"feed":"book","product_id":"PI_XRPUSD","side":"sell","seq":3456292,"price":0.589,"qty":4759.0,"timestamp":1626994950939}
1626994950.919889: {"feed":"book","product_id":"PI_ETHUSD","side":"buy","seq":26663364,"price":2003.0,"qty":0.0,"timestamp":1626994950939}
1626994950.919934: {"feed":"book","product_id":"PI_ETHUSD","side":"buy","seq":26663365,"price":2002.45,"qty":24153.0,"timestamp":1626994950939}
1626994950.9224179: {"feed":"book","product_id":"FI_XBTUSD_210730","side":"buy","seq":5160227,"price":32117.5,"qty":60633.0,"timestamp":1626994950942}
1626994950.9224918: {"feed":"book","product_id":"FI_XBTUSD_210730","side":"buy","seq":5160228,"price":32136.0,"qty":0.0,"timestamp":1626994950942}
1626994950.922543: {"feed":"book","product_id":"FI_XBTUSD_210730","side":"sell","seq":5160229,"price":32223.0,"qty":633.0,"timestamp":1626994950942}
1626994950.9230132: {"feed":"book","product_id":"FI_XBTUSD_210730","side":"buy","seq":5160230,"price":32128.5,"qty":0.0,"timestamp":1626994950942}
1626994950.923079: {"feed":"book","product_id":"PI_ETHUSD","side":"sell","seq":26663366,"price":2007.4,"qty":4157.0,"timestamp":1626994950943}
1626994950.9231129: {"feed":"book","product_id":"PI_ETHUSD","side":"sell","seq":26663367,"price":2007.2,"qty":500001.0,"timestamp":1626994950943}
1626994950.923147: {"feed":"book","product_id":"FI_XBTUSD_210730","side":"buy","seq":5160231,"price":32030.5,"qty":0.0,"timestamp":1626994950942}
1626994950.923192: {"feed":"book","product_id":"FI_XBTUSD_210730","side":"buy","seq":5160232,"price":32001.0,"qty":250002.0,"timestamp":1626994950942}
1626994950.923219: {"feed":"book","product_id":"PI_ETHUSD","side":"buy","seq":26663368,"price":2002.5,"qty":15000.0,"timestamp":1626994950943}
1626994950.923242: {"feed":"book","product_id":"PI_ETHUSD","side":"buy","seq":26663369,"price":2002.3,"qty":23928.0,"timestamp":1626994950943}
1626994950.92327: {"feed":"book","product_id":"FI_ETHUSD_210730","side":"sell","seq":2138845,"price":2014.9,"qty":0.0,"timestamp":1626994950943}
1626994950.923299: {"feed":"book","product_id":"FI_ETHUSD_210730","side":"sell","seq":2138846,"price":2013.6,"qty":250002.0,"timestamp":1626994950943}
1626994950.9233239: {"feed":"book","product_id":"FI_ETHUSD_211231","side":"sell","seq":2199181,"price":2048.35,"qty":0.0,"timestamp":1626994950943}
1626994950.923352: {"feed":"book","product_id":"FI_ETHUSD_211231","side":"sell","seq":2199182,"price":2048.25,"qty":250002.0,"timestamp":1626994950943}
1626994950.927157: {"feed":"book","product_id":"PI_XRPUSD","side":"sell","seq":3456293,"price":0.5893,"qty":8766.0,"timestamp":1626994950944}
1626994950.927264: {"feed":"book","product_id":"FI_XBTUSD_210924","side":"buy","seq":13502418,"price":32161.0,"qty":0.0,"timestamp":1626994950944}
1626994950.927335: {"feed":"book","product_id":"PI_ETHUSD","side":"buy","seq":26663370,"price":2002.3,"qty":3928.0,"timestamp":1626994950943}
1626994950.927379: {"feed":"book","product_id":"PI_ETHUSD","side":"buy","seq":26663371,"price":2002.45,"qty":44153.0,"timestamp":1626994950943}
1626994950.927418: {"feed":"book","product_id":"FI_XBTUSD_210924","side":"buy","seq":13502419,"price":32151.5,"qty":735.0,"timestamp":1626994950944}
1626994950.927464: {"feed":"book","product_id":"PI_LTCUSD","side":"sell","seq":3423369,"price":119.56,"qty":787.0,"timestamp":1626994950943}
1626994950.927509: {"feed":"book","product_id":"FI_XBTUSD_210924","side":"buy","seq":13502420,"price":32168.0,"qty":0.0,"timestamp":1626994950944}
1626994950.927561: {"feed":"book","product_id":"PI_LTCUSD","side":"buy","seq":3423370,"price":119.18,"qty":0.0,"timestamp":1626994950943}
1626994950.927616: {"feed":"book","product_id":"PI_LTCUSD","side":"buy","seq":3423371,"price":119.15,"qty":16000.0,"timestamp":1626994950943}
1626994950.927653: {"feed":"book","product_id":"PI_LTCUSD","side":"buy","seq":3423372,"price":119.08,"qty":787.0,"timestamp":1626994950944}
1626994950.927969: {"feed":"book","product_id":"FI_ETHUSD_211231","side":"buy","seq":2199183,"price":2025.1,"qty":184.0,"timestamp":1626994950948}
1626994950.928016: {"feed":"book","product_id":"PI_ETHUSD","side":"buy","seq":26663372,"price":2002.45,"qty":28327.0,"timestamp":1626994950946}
1626994950.928042: {"feed":"book","product_id":"PI_ETHUSD","side":"buy","seq":26663373,"price":2002.35,"qty":15826.0,"timestamp":1626994950946}
1626994950.9280698: {"feed":"book","product_id":"FI_ETHUSD_211231","side":"buy","seq":2199184,"price":2026.6,"qty":0.0,"timestamp":1626994950948}
1626994950.9281: {"feed":"book","product_id":"FI_ETHUSD_211231","side":"sell","seq":2199185,"price":2033.8,"qty":5184.0,"timestamp":1626994950948}
1626994950.9343061: {"feed":"book","product_id":"FI_ETHUSD_211231","side":"buy","seq":2199186,"price":2029.65,"qty":0.0,"timestamp":1626994950954}
1626994950.93443: {"feed":"book","product_id":"FI_ETHUSD_211231","side":"sell","seq":2199187,"price":2032.65,"qty":50.0,"timestamp":1626994950954}
1626994950.934499: {"feed":"book","product_id":"PI_ETHUSD","side":"buy","seq":26663374,"price":2002.35,"qty":0.0,"timestamp":1626994950954}
1626994950.9345589: {"feed":"book","product_id":"PI_ETHUSD","side":"buy","seq":26663375,"price":2002.55,"qty":15826.0,"timestamp":1626994950954}
1626994950.934608: {"feed":"book","product_id":"PI_ETHUSD","side":"buy","seq":26663376,"price":2002.55,"qty":0.0,"timestamp":1626994950954}
1626994950.9346519: {"feed":"book","product_id":"PI_ETHUSD","side":"buy","seq":26663377,"price":2002.25,"qty":15826.0,"timestamp":1626994950954}
1626994950.935022: {"feed":"book","product_id":"PI_ETHUSD","side":"buy","seq":26663378,"price":2002.45,"qty":23939.0,"timestamp":1626994950955}
1626994950.937535: {"feed":"book","product_id":"FI_ETHUSD_210730","side":"buy","seq":2138847,"price":1996.5,"qty":276.0,"timestamp":1626994950956}
1626994950.93762: {"feed":"book","product_id":"FI_ETHUSD_210730","side":"sell","seq":2138848,"price":2004.1,"qty":276.0,"timestamp":1626994950956}
1626994950.9376562: {"feed":"book","product_id":"PI_ETHUSD","side":"sell","seq":26663379,"price":2005.55,"qty":15000.0,"timestamp":1626994950956}
1626994950.937684: {"feed":"book","product_id":"FI_ETHUSD_210730","side":"buy","seq":2138849,"price":1997.7,"qty":0.0,"timestamp":1626994950956}
1626994950.9377332: {"feed":"book","product_id":"PI_ETHUSD","side":"buy","seq":26663380,"price":2002.45,"qty":3939.0,"timestamp":1626994950957}
1626994950.937759: {"feed":"book","product_id":"PI_ETHUSD","side":"buy","seq":26663381,"price":2002.35,"qty":20000.0,"timestamp":1626994950957}
1626994950.9379652: {"feed":"book","product_id":"PI_ETHUSD","side":"buy","seq":26663382,"price":2002.35,"qty":0.0,"timestamp":1626994950958}
1626994950.938011: {"feed":"book","product_id":"PI_ETHUSD","side":"buy","seq":26663383,"price":2002.15,"qty":31415.0,"timestamp":1626994950958}
1626994950.944959: {"feed":"book","product_id":"PI_ETHUSD","side":"buy","seq":26663384,"price":2002.25,"qty":0.0,"timestamp":1626994950965}
1626994950.945096: {"feed":"book","product_id":"PI_ETHUSD","side":"buy","seq":26663385,"price":2002.2,"qty":27498.0,"timestamp":1626994950965}
1626994950.945531: {"feed":"book","product_id":"PI_LTCUSD","side":"buy","seq":3423373,"price":119.28,"qty":33246.0,"timestamp":1626994950967}
1626994950.946872: {"feed":"book","product_id":"PI_ETHUSD","side":"buy","seq":26663386,"price":2003.65,"qty":60470.0,"timestamp":1626994950967}
1626994950.946948: {"feed":"book","product_id":"PI_LTCUSD","side":"buy","seq":3423374,"price":119.33,"qty":17599.0,"timestamp":1626994950967}
1626994950.9507961: {"feed":"book","product_id":"PI_ETHUSD","side":"buy","seq":26663387,"price":2002.2,"qty":11672.0,"timestamp":1626994950970}
1626994950.9509041: {"feed":"book","product_id":"PI_ETHUSD","side":"buy","seq":26663388,"price":2002.15,"qty":47241.0,"timestamp":1626994950970}
1626994950.952783: {"feed":"book","product_id":"FI_XBTUSD_210924","side":"sell","seq":13502421,"price":32281.5,"qty":0.0,"timestamp":1626994950973}
1626994950.9533482: {"feed":"book","product_id":"FI_XBTUSD_210924","side":"sell","seq":13502422,"price":32264.5,"qty":20963.0,"timestamp":1626994950973}
1626994950.953415: {"feed":"book","product_id":"FI_XBTUSD_210924","side":"buy","seq":13502423,"price":32195.5,"qty":0.0,"timestamp":1626994950973}
1626994950.9534569: {"feed":"book","product_id":"FI_XBTUSD_210924","side":"buy","seq":13502424,"price":32195.5,"qty":16164.0,"timestamp":1626994950973}
1626994950.9545321: {"feed":"book","product_id":"FI_XBTUSD_210924","side":"sell","seq":13502425,"price":32246.0,"qty":0.0,"timestamp":1626994950973}
1626994950.954619: {"feed":"book","product_id":"PI_ETHUSD","side":"buy","seq":26663389,"price":2000.8,"qty":63.0,"timestamp":1626994950975}
1626994950.954655: {"feed":"book","product_id":"PI_ETHUSD","side":"buy","seq":26663390,"price":2000.2,"qty":180000.0,"timestamp":1626994950975}
1626994950.9546812: {"feed":"book","product_id":"FI_XBTUSD_210924","side":"sell","seq":13502426,"price":32246.0,"qty":16233.0,"timestamp":1626994950973}
1626994950.9578931: {"feed":"book","product_id":"FI_XBTUSD_210924","side":"buy","seq":13502427,"price":32174.0,"qty":3000.0,"timestamp":1626994950973}
1626994950.9579678: {"feed":"book","product_id":"FI_XBTUSD_210924","side":"buy","seq":13502428,"price":32174.0,"qty":23906.0,"timestamp":1626994950973}
1626994950.9580002: {"feed":"book","product_id":"FI_XBTUSD_210924","side":"sell","seq":13502429,"price":32267.0,"qty":0.0,"timestamp":1626994950976}
1626994950.958039: {"feed":"book","product_id":"FI_XBTUSD_210924","side":"sell","seq":13502430,"price":32265.0,"qty":30000.0,"timestamp":1626994950976}
1626994950.960001: {"feed":"book","product_id":"PI_ETHUSD","side":"buy","seq":26663391,"price":2001.0,"qty":0.0,"timestamp":1626994950977}
1626994950.960088: {"feed":"book","product_id":"PI_ETHUSD","side":"buy","seq":26663392,"price":2000.35,"qty":125638.0,"timestamp":1626994950977}
1626994950.9601321: {"feed":"book","product_id":"PI_ETHUSD","side":"buy","seq":26663393,"price":2002.15,"qty":31415.0,"timestamp":1626994950980}
1626994950.96016: {"feed":"book","product_id":"PI_ETHUSD","side":"buy","seq":26663394,"price":2002.0,"qty":15826.0,"timestamp":1626994950980}
1626994950.9601889: {"feed":"book","product_id":"PI_ETHUSD","side":"buy","seq":26663395,"price":2002.15,"qty":11415.0,"timestamp":1626994950980}
1626994950.960211: {"feed":"book","product_id":"PI_ETHUSD","side":"buy","seq":26663396,"price":2001.95,"qty":20000.0,"timestamp":1626994950980}
1626994950.9635122: {"feed":"book","product_id":"PI_XRPUSD","side":"buy","seq":3456294,"price":0.5878,"qty":13830.0,"timestamp":1626994950983}
1626994950.9636202: {"feed":"book","product_id":"PI_ETHUSD","side":"buy","seq":26663397,"price":2002.0,"qty":0.0,"timestamp":1626994950983}
1626994950.963705: {"feed":"book","product_id":"PI_ETHUSD","side":"buy","seq":26663398,"price":2002.4,"qty":15826.0,"timestamp":1626994950983}
1626994950.9678369: {"feed":"book","product_id":"PI_ETHUSD","side":"sell","seq":26663399,"price":2005.9,"qty":13888.0,"timestamp":1626994950988}
1626994950.97688: {"feed":"book","product_id":"FI_XBTUSD_210924","side":"buy","seq":13502431,"price":32197.5,"qty":0.0,"timestamp":1626994950994}
1626994950.9770072: {"feed":"book","product_id":"FI_XBTUSD_210924","side":"buy","seq":13502432,"price":32193.0,"qty":1080.0,"timestamp":1626994950994}
1626994950.977049: {"feed":"book","product_id":"FI_XBTUSD_210730","side":"buy","seq":5160233,"price":32173.5,"qty":0.0,"timestamp":1626994950994}
1626994950.977083: {"feed":"book","product_id":"FI_XBTUSD_210730","side":"buy","seq":5160234,"price":32169.0,"qty":1200.0,"timestamp":1626994950994}
1626994950.9771252: {"feed":"book","product_id":"FI_XBTUSD_210924","side":"sell","seq":13502433,"price":32246.5,"qty":0.0,"timestamp":1626994950994}
1626994950.977155: {"feed":"book","product_id":"FI_XBTUSD_210924","side":"sell","seq":13502434,"price":32236.5,"qty":27000.0,"timestamp":1626994950994}
1626994950.977182: {"feed":"book","product_id":"FI_XBTUSD_210924","side":"buy","seq":13502435,"price":32185.5,"qty":0.0,"timestamp":1626994950994}
1626994950.9772081: {"feed":"book","product_id":"FI_XBTUSD_210924","side":"buy","seq":13502436,"price":32175.5,"qty":27000.0,"timestamp":1626994950994}
1626994950.977233: {"feed":"book","product_id":"FI_ETHUSD_211231","side":"sell","seq":2199188,"price":2038.25,"qty":8748.0,"timestamp":1626994950995}
1626994950.9772558: {"feed":"book","product_id":"FI_ETHUSD_211231","side":"sell","seq":2199189,"price":2038.7,"qty":250001.0,"timestamp":1626994950995}
1626994950.977281: {"feed":"book","product_id":"FI_XBTUSD_210730","side":"sell","seq":5160235,"price":32209.0,"qty":0.0,"timestamp":1626994950995}
1626994950.9773068: {"feed":"book","product_id":"FI_XBTUSD_210730","side":"sell","seq":5160236,"price":32204.5,"qty":170606.0,"timestamp":1626994950995}
1626994950.977328: {"feed":"book","product_id":"FI_XRPUSD_210924","side":"buy","seq":602299,"price":0.5848,"qty":0.0,"timestamp":1626994950996}
1626994950.977355: {"feed":"book","product_id":"FI_XRPUSD_210924","side":"buy","seq":602300,"price":0.5846,"qty":7200.0,"timestamp":1626994950996}
1626994950.977379: {"feed":"book","product_id":"FI_XRPUSD_210924","side":"sell","seq":602301,"price":0.5864,"qty":0.0,"timestamp":1626994950996}
1626994950.9774048: {"feed":"book","product_id":"FI_XRPUSD_210924","side":"sell","seq":602302,"price":0.5862,"qty":7200.0,"timestamp":1626994950996}
1626994950.977429: {"feed":"book","product_id":"FI_XRPUSD_210924","side":"sell","seq":602303,"price":0.5868,"qty":42.0,"timestamp":1626994950996}
1626994950.977452: {"feed":"book","product_id":"FI_XRPUSD_210924","side":"buy","seq":602304,"price":0.583,"qty":42.0,"timestamp":1626994950996}
1626994950.9774752: {"feed":"book","product_id":"FI_XRPUSD_210924","side":"buy","seq":602305,"price":0.5833,"qty":6149.0,"timestamp":1626994950997}
1626994950.97776: {"feed":"book","product_id":"FI_BCHUSD_210924","side":"buy","seq":402252,"price":440.2,"qty":0.0,"timestamp":1626994950998}
1626994950.980535: {"feed":"book","product_id":"FI_BCHUSD_210924","side":"sell","seq":402253,"price":442.5,"qty":26135.0,"timestamp":1626994950999}
1626994950.980609: {"feed":"book","product_id":"FI_BCHUSD_210924","side":"sell","seq":402254,"price":443.1,"qty":0.0,"timestamp":1626994950999}
1626994950.980654: {"feed":"book","product_id":"FI_BCHUSD_210924","side":"buy","seq":402255,"price":440.1,"qty":0.0,"timestamp":1626994950999}
1626994950.9806871: {"feed":"book","product_id":"FI_BCHUSD_210924","side":"buy","seq":402256,"price":439.9,"qty":84.0,"timestamp":1626994951000}
1626994950.983859: {"feed":"book","product_id":"PI_ETHUSD","side":"buy","seq":26663400,"price":2003.1,"qty":5000.0,"timestamp":1626994951004}
1626994950.99106: {"feed":"book","product_id":"PI_XRPUSD","side":"sell","seq":3456295,"price":0.5893,"qty":4580.0,"timestamp":1626994951008}
1626994950.991168: {"feed":"book","product_id":"FI_XBTUSD_210924","side":"buy","seq":13502437,"price":32194.0,"qty":0.0,"timestamp":1626994951006}
1626994950.9912388: {"feed":"book","product_id":"FI_XBTUSD_210924","side":"sell","seq":13502438,"price":32254.0,"qty":0.0,"timestamp":1626994951006}
1626994950.991316: {"feed":"book","product_id":"FI_XBTUSD_210924","side":"buy","seq":13502439,"price":32175.0,"qty":0.0,"timestamp":1626994951006}
1626994950.991345: {"feed":"book","product_id":"FI_XBTUSD_210924","side":"buy","seq":13502440,"price":32167.0,"qty":0.0,"timestamp":1626994951008}
1626994950.9913878: {"feed":"book","product_id":"PI_ETHUSD","side":"sell","seq":26663401,"price":2006.5,"qty":0.0,"timestamp":1626994951009}
1626994950.9914181: {"feed":"book","product_id":"FI_XBTUSD_210924","side":"buy","seq":13502441,"price":32124.5,"qty":0.0,"timestamp":1626994951008}
1626994950.9914439: {"feed":"book","product_id":"FI_XBTUSD_210924","side":"buy","seq":13502442,"price":32118.0,"qty":0.0,"timestamp":1626994951010}
1626994950.99147: {"feed":"book","product_id":"FI_XBTUSD_210924","side":"buy","seq":13502443,"price":32130.0,"qty":250001.0,"timestamp":1626994951010}
1626994950.992094: {"feed":"book","product_id":"PI_ETHUSD","side":"sell","seq":26663402,"price":2007.1,"qty":0.0,"timestamp":1626994951013}
1626994950.9921558: {"feed":"book","product_id":"PI_XRPUSD","side":"sell","seq":3456296,"price":0.5891,"qty":8109.0,"timestamp":1626994951013}
1626994950.992192: {"feed":"book","product_id":"FI_XBTUSD_210924","side":"buy","seq":13502444,"price":30254.0,"qty":20000.0,"timestamp":1626994951013}
1626994950.9960241: {"feed":"book","product_id":"FI_ETHUSD_210730","side":"sell","seq":2138850,"price":2009.1,"qty":0.0,"timestamp":1626994951016}
1626994950.996109: {"feed":"book","product_id":"FI_ETHUSD_210730","side":"sell","seq":2138851,"price":2010.6,"qty":250001.0,"timestamp":1626994951016}
1626994950.999949: {"feed":"book","product_id":"PI_ETHUSD","side":"buy","seq":26663403,"price":2003.65,"qty":57970.0,"timestamp":1626994951018}
1626994951.0000541: {"feed":"book","product_id":"PI_XRPUSD","side":"buy","seq":3456297,"price":0.5879,"qty":3932.0,"timestamp":1626994951018}
1626994951.000107: {"feed":"book","product_id":"PI_ETHUSD","side":"buy","seq":26663404,"price":2002.5,"qty":19424.0,"timestamp":1626994951019}
1626994951.000148: {"feed":"book","product_id":"PI_ETHUSD","side":"sell","seq":26663405,"price":2005.75,"qty":2561.0,"timestamp":1626994951019}
1626994951.000185: {"feed":"book","product_id":"PI_ETHUSD","side":"sell","seq":26663406,"price":2005.45,"qty":4043.0,"timestamp":1626994951019}
1626994951.0081751: {"feed":"book","product_id":"FI_XBTUSD_210924","side":"sell","seq":13502445,"price":32262.5,"qty":0.0,"timestamp":1626994951028}
1626994951.0083032: {"feed":"book","product_id":"PI_ETHUSD","side":"buy","seq":26663407,"price":2003.65,"qty":0.0,"timestamp":1626994951028}
1626994951.008368: {"feed":"book","product_id":"FI_XBTUSD_210924","side":"buy","seq":13502446,"price":32174.0,"qty":20906.0,"timestamp":1626994951028}
1626994951.0084128: {"feed":"book","product_id":"FI_XBTUSD_210924","side":"sell","seq":13502447,"price":32295.0,"qty":0.0,"timestamp":1626994951028}
1626994951.0232692: {"feed":"book","product_id":"PI_ETHUSD","side":"sell","seq":26663408,"price":2005.1,"qty":5804.0,"timestamp":1626994951043}
1626994951.02564: {"feed":"book","product_id":"PI_ETHUSD","side":"buy","seq":26663409,"price":2003.0,"qty":5954.0,"timestamp":1626994951046}
1626994951.0257: {"feed":"book","product_id":"PI_ETHUSD","side":"sell","seq":26663410,"price":2005.9,"qty":7509.0,"timestamp":1626994951047}
1626994951.032897: {"feed":"book","product_id":"PI_ETHUSD","side":"buy","seq":26663411,"price":2002.85,"qty":5803.0,"timestamp":1626994951051}
1626994951.0330229: {"feed":"book","product_id":"PI_ETHUSD","side":"buy","seq":26663412,"price":2002.2,"qty":0.0,"timestamp":1626994951051}
1626994951.03309: {"feed":"book","product_id":"PI_ETHUSD","side":"buy","seq":26663413,"price":2001.9,"qty":11748.0,"timestamp":1626994951051}
1626994951.03314: {"feed":"book","product_id":"PI_ETHUSD","side":"sell","seq":26663414,"price":2007.7,"qty":4594.0,"timestamp":1626994951051}
1626994951.0331788: {"feed":"book","product_id":"PI_ETHUSD","side":"sell","seq":26663415,"price":2007.4,"qty":21775.0,"timestamp":1626994951051}
1626994951.033213: {"feed":"book","product_id":"PI_ETHUSD","side":"buy","seq":26663416,"price":2001.25,"qty":5068.0,"timestamp":1626994951051}
1626994951.033247: {"feed":"book","product_id":"PI_ETHUSD","side":"buy","seq":26663417,"price":2001.15,"qty":16062.0,"timestamp":1626994951051}
1626994951.033607: {"feed":"book","product_id":"PI_ETHUSD","side":"buy","seq":26663418,"price":2002.4,"qty":0.0,"timestamp":1626994951053}
1626994951.033655: {"feed":"book","product_id":"PI_ETHUSD","side":"buy","seq":26663419,"price":2002.2,"qty":15826.0,"timestamp":1626994951053}
1626994951.033687: {"feed":"book","product_id":"PI_ETHUSD","side":"buy","seq":26663420,"price":2000.2,"qty":30000.0,"timestamp":1626994951055}
1626994951.0337112: {"feed":"book","product_id":"PI_ETHUSD","side":"buy","seq":26663421,"price":1999.75,"qty":150000.0,"timestamp":1626994951055}
1626994951.039971: {"feed":"book","product_id":"PI_ETHUSD","side":"buy","seq":26663422,"price":2002.5,"qty":15000.0,"timestamp":1626994951061}
1626994951.044151: {"feed":"book","product_id":"PI_ETHUSD","side":"sell","seq":26663423,"price":2008.25,"qty":0.0,"timestamp":1626994951064}
1626994951.0462878: {"feed":"book","product_id":"PI_ETHUSD","side":"sell","seq":26663424,"price":2005.75,"qty":61.0,"timestamp":1626994951066}
1626994951.052774: {"feed":"book","product_id":"FI_XBTUSD_210924","side":"sell","seq":13502448,"price":32265.0,"qty":20000.0,"timestamp":1626994951072}
1626994951.052885: {"feed":"book","product_id":"PI_ETHUSD","side":"sell","seq":26663425,"price":2006.45,"qty":0.0,"timestamp":1626994951072}
1626994951.052958: {"feed":"book","product_id":"FI_XBTUSD_210924","side":"buy","seq":13502449,"price":32173.5,"qty":0.0,"timestamp":1626994951072}
1626994951.053012: {"feed":"book","product_id":"FI_XBTUSD_210924","side":"buy","seq":13502450,"price":32136.0,"qty":0.0,"timestamp":1626994951072}
1626994951.0795178: {"feed":"book","product_id":"PI_ETHUSD","side":"buy","seq":26663426,"price":2002.4,"qty":4991.0,"timestamp":1626994951100}
1626994951.079647: {"feed":"book","product_id":"PI_ETHUSD","side":"sell","seq":26663427,"price":2005.45,"qty":1.0,"timestamp":1626994951101}
1626994951.082585: {"feed":"book","product_id":"PI_XRPUSD","side":"buy","seq":3456298,"price":0.5881,"qty":0.0,"timestamp":1626994951102}
1626994951.082707: {"feed":"book","product_id":"PI_XRPUSD","side":"buy","seq":3456299,"price":0.5589,"qty":9950.0,"timestamp":1626994951102}
1626994951.082773: {"feed":"book","product_id":"PI_XRPUSD","side":"sell","seq":3456300,"price":0.6179,"qty":0.0,"timestamp":1626994951102}
1626994951.082826: {"feed":"book","product_id":"PI_XRPUSD","side":"sell","seq":3456301,"price":0.5892,"qty":7993.0,"timestamp":1626994951102}
1626994951.084542: {"feed":"book","product_id":"PI_XRPUSD","side":"buy","seq":3456302,"price":0.5878,"qty":9946.0,"timestamp":1626994951105}
1626994951.084617: {"feed":"book","product_id":"PI_ETHUSD","side":"buy","seq":26663428,"price":2001.2,"qty":0.0,"timestamp":1626994951105}
1626994951.0846632: {"feed":"book","product_id":"PI_ETHUSD","side":"buy","seq":26663429,"price":2000.35,"qty":275638.0,"timestamp":1626994951105}
1626994951.0866911: {"feed":"book","product_id":"FI_XBTUSD_210924","side":"buy","seq":13502451,"price":32171.5,"qty":0.0,"timestamp":1626994951107}
1626994951.086775: {"feed":"book","product_id":"PI_XRPUSD","side":"buy","seq":3456303,"price":0.5875,"qty":4032.0,"timestamp":1626994951108}
1626994951.087699: {"feed":"book","product_id":"PI_XRPUSD","side":"sell","seq":3456304,"price":0.5894,"qty":1385.0,"timestamp":1626994951108}
1626994951.0877771: {"feed":"book","product_id":"PI_XRPUSD","side":"sell","seq":3456305,"price":0.5892,"qty":7943.0,"timestamp":1626994951108}
1626994951.087808: {"feed":"book","product_id":"PI_XRPUSD","side":"sell","seq":3456306,"price":0.5891,"qty":8159.0,"timestamp":1626994951108}
1626994951.088164: {"feed":"book","product_id":"FI_XBTUSD_210924","side":"buy","seq":13502452,"price":32182.5,"qty":0.0,"timestamp":1626994951109}
1626994951.0882251: {"feed":"book","product_id":"PI_XRPUSD","side":"sell","seq":3456307,"price":0.5892,"qty":12101.0,"timestamp":1626994951110}
1626994951.095097: {"feed":"book","product_id":"PI_XRPUSD","side":"sell","seq":3456308,"price":0.5891,"qty":8109.0,"timestamp":1626994951114}
1626994951.095204: {"feed":"book","product_id":"PI_XRPUSD","side":"sell","seq":3456309,"price":0.5892,"qty":12151.0,"timestamp":1626994951114}
1626994951.0952551: {"feed":"book","product_id":"FI_ETHUSD_210730","side":"sell","seq":2138852,"price":2013.65,"qty":0.0,"timestamp":1626994951115}
1626994951.095316: {"feed":"book","product_id":"FI_ETHUSD_210730","side":"sell","seq":2138853,"price":2013.55,"qty":45421.0,"timestamp":1626994951115}
1626994951.095388: {"feed":"book","product_id":"FI_ETHUSD_211231","side":"sell","seq":2199190,"price":2048.3,"qty":44305.0,"timestamp":1626994951115}
1626994951.0954251: {"feed":"book","product_id":"FI_ETHUSD_211231","side":"sell","seq":2199191,"price":2048.2,"qty":45099.0,"timestamp":1626994951115}
1626994951.095465: {"feed":"book","product_id":"FI_ETHUSD_211231","side":"sell","seq":2199192,"price":2048.3,"qty":0.0,"timestamp":1626994951115}
1626994951.0955148: {"feed":"book","product_id":"FI_ETHUSD_211231","side":"sell","seq":2199193,"price":2048.2,"qty":89404.0,"timestamp":1626994951115}
1626994951.1016068: {"feed":"book","product_id":"PI_XRPUSD","side":"sell","seq":3456310,"price":0.5889,"qty":1466.0,"timestamp":1626994951122}
1626994951.105964: {"feed":"book","product_id":"PI_XRPUSD","side":"buy","seq":3456311,"price":0.5878,"qty":11545.0,"timestamp":1626994951126}
1626994951.111119: {"feed":"book","product_id":"PI_ETHUSD","side":"buy","seq":26663430,"price":2003.1,"qty":0.0,"timestamp":1626994951130}
1626994951.115718: {"feed":"book","product_id":"FI_XBTUSD_210924","side":"buy","seq":13502453,"price":32130.0,"qty":0.0,"timestamp":1626994951135}
1626994951.115841: {"feed":"book","product_id":"FI_XBTUSD_210924","side":"buy","seq":13502454,"price":32118.0,"qty":250001.0,"timestamp":1626994951135}
1626994951.115905: {"feed":"book","product_id":"PI_ETHUSD","side":"buy","seq":26663431,"price":1999.6,"qty":0.0,"timestamp":1626994951135}
1626994951.1159601: {"feed":"book","product_id":"PI_ETHUSD","side":"buy","seq":26663432,"price":1999.8,"qty":500001.0,"timestamp":1626994951135}
1626994951.116032: {"feed":"book","product_id":"FI_ETHUSD_210730","side":"sell","seq":2138854,"price":2013.6,"qty":0.0,"timestamp":1626994951135}
1626994951.116065: {"feed":"book","product_id":"FI_ETHUSD_210730","side":"sell","seq":2138855,"price":2013.5,"qty":250002.0,"timestamp":1626994951135}
1626994951.116092: {"feed":"book","product_id":"FI_ETHUSD_211231","side":"sell","seq":2199194,"price":2048.25,"qty":0.0,"timestamp":1626994951135}
1626994951.11612: {"feed":"book","product_id":"FI_ETHUSD_211231","side":"sell","seq":2199195,"price":2048.15,"qty":250002.0,"timestamp":1626994951135}
1626994951.1221068: {"feed":"book","product_id":"PI_ETHUSD","side":"buy","seq":26663433,"price":2002.65,"qty":0.0,"timestamp":1626994951142}
1626994951.122232: {"feed":"book","product_id":"FI_XBTUSD_210730","side":"sell","seq":5160237,"price":32214.5,"qty":0.0,"timestamp":1626994951143}
1626994951.1222951: {"feed":"book","product_id":"FI_XBTUSD_210730","side":"sell","seq":5160238,"price":32211.5,"qty":1.0,"timestamp":1626994951143}
1626994951.125983: {"feed":"book","product_id":"PI_ETHUSD","side":"sell","seq":26663434,"price":2005.4,"qty":4032.0,"timestamp":1626994951146}
1626994951.1289558: {"feed":"book","product_id":"PI_ETHUSD","side":"sell","seq":26663435,"price":2006.1,"qty":5000.0,"timestamp":1626994951150}
1626994951.133603: {"feed":"book","product_id":"FI_ETHUSD_211231","side":"sell","seq":2199196,"price":2036.85,"qty":0.0,"timestamp":1626994951153}
1626994951.133688: {"feed":"book","product_id":"FI_ETHUSD_211231","side":"buy","seq":2199197,"price":2025.1,"qty":0.0,"timestamp":1626994951153}
1626994951.133726: {"feed":"book","product_id":"FI_ETHUSD_211231","side":"sell","seq":2199198,"price":2032.9,"qty":136.0,"timestamp":1626994951153}
1626994951.133759: {"feed":"book","product_id":"FI_ETHUSD_211231","side":"buy","seq":2199199,"price":2024.35,"qty":136.0,"timestamp":1626994951154}
1626994951.1337879: {"feed":"book","product_id":"PI_LTCUSD","side":"buy","seq":3423375,"price":119.3,"qty":4886.0,"timestamp":1626994951154}
1626994951.133812: {"feed":"book","product_id":"PI_LTCUSD","side":"buy","seq":3423376,"price":119.18,"qty":5012.0,"timestamp":1626994951154}
1626994951.136193: {"feed":"book","product_id":"PI_ETHUSD","side":"sell","seq":26663436,"price":2005.35,"qty":5971.0,"timestamp":1626994951155}
1626994951.1362822: {"feed":"book","product_id":"PI_ETHUSD","side":"buy","seq":26663437,"price":2003.4,"qty":2500.0,"timestamp":1626994951156}
1626994951.136321: {"feed":"book","product_id":"PI_XRPUSD","side":"buy","seq":3456312,"price":0.5877,"qty":5199.0,"timestamp":1626994951156}
1626994951.13635: {"feed":"book","product_id":"PI_XRPUSD","side":"buy","seq":3456313,"price":0.5876,"qty":23078.0,"timestamp":1626994951156}
1626994951.136375: {"feed":"book","product_id":"FI_XBTUSD_210924","side":"buy","seq":13502455,"price":32193.0,"qty":0.0,"timestamp":1626994951155}
1626994951.136412: {"feed":"book","product_id":"FI_XBTUSD_210924","side":"buy","seq":13502456,"price":32188.5,"qty":1080.0,"timestamp":1626994951155}
1626994951.136457: {"feed":"book","product_id":"PI_XRPUSD","side":"buy","seq":3456314,"price":0.588,"qty":0.0,"timestamp":1626994951156}
1626994951.136487: {"feed":"book","product_id":"PI_XRPUSD","side":"buy","seq":3456315,"price":0.5879,"qty":4252.0,"timestamp":1626994951156}
1626994951.136511: {"feed":"book","product_id":"FI_XBTUSD_210730","side":"buy","seq":5160239,"price":32169.0,"qty":0.0,"timestamp":1626994951155}
1626994951.136539: {"feed":"book","product_id":"FI_XBTUSD_210730","side":"buy","seq":5160240,"price":32164.5,"qty":1200.0,"timestamp":1626994951155}
1626994951.139346: {"feed":"book","product_id":"FI_XBTUSD_210924","side":"sell","seq":13502457,"price":32236.5,"qty":0.0,"timestamp":1626994951157}
1626994951.1394382: {"feed":"book","product_id":"FI_XBTUSD_210924","side":"sell","seq":13502458,"price":32233.0,"qty":28009.0,"timestamp":1626994951157}
1626994951.139473: {"feed":"book","product_id":"PI_ETHUSD","side":"buy","seq":26663438,"price":2003.25,"qty":0.0,"timestamp":1626994951156}
1626994951.139508: {"feed":"book","product_id":"PI_ETHUSD","side":"buy","seq":26663439,"price":2003.0,"qty":6554.0,"timestamp":1626994951156}
1626994951.139532: {"feed":"book","product_id":"PI_ETHUSD","side":"buy","seq":26663440,"price":2002.75,"qty":5000.0,"timestamp":1626994951157}
1626994951.139562: {"feed":"book","product_id":"FI_ETHUSD_210730","side":"buy","seq":2138856,"price":2001.2,"qty":50.0,"timestamp":1626994951157}
1626994951.139586: {"feed":"book","product_id":"FI_ETHUSD_210730","side":"buy","seq":2138857,"price":2000.95,"qty":600.0,"timestamp":1626994951157}
1626994951.1396108: {"feed":"book","product_id":"FI_ETHUSD_211231","side":"sell","seq":2199200,"price":2034.1,"qty":0.0,"timestamp":1626994951158}
1626994951.139641: {"feed":"book","product_id":"FI_ETHUSD_211231","side":"sell","seq":2199201,"price":2033.35,"qty":10500.0,"timestamp":1626994951158}
1626994951.1396658: {"feed":"book","product_id":"FI_XBTUSD_210730","side":"sell","seq":5160241,"price":32204.5,"qty":140606.0,"timestamp":1626994951158}
1626994951.139688: {"feed":"book","product_id":"FI_XBTUSD_210730","side":"sell","seq":5160242,"price":32201.0,"qty":30000.0,"timestamp":1626994951158}
1626994951.139711: {"feed":"book","product_id":"PI_XRPUSD","side":"buy","seq":3456316,"price":0.5589,"qty":0.0,"timestamp":1626994951159}
1626994951.13974: {"feed":"book","product_id":"PI_XRPUSD","side":"buy","seq":3456317,"price":0.5588,"qty":9950.0,"timestamp":1626994951159}
1626994951.139765: {"feed":"book","product_id":"FI_XBTUSD_210730","side":"buy","seq":5160243,"price":32159.5,"qty":0.0,"timestamp":1626994951159}
1626994951.139791: {"feed":"book","product_id":"FI_XBTUSD_210730","side":"buy","seq":5160244,"price":32151.0,"qty":152259.0,"timestamp":1626994951159}
1626994951.140078: {"feed":"book","product_id":"PI_ETHUSD","side":"sell","seq":26663441,"price":2005.55,"qty":0.0,"timestamp":1626994951160}
1626994951.140127: {"feed":"book","product_id":"PI_ETHUSD","side":"sell","seq":26663442,"price":2005.05,"qty":15000.0,"timestamp":1626994951160}
1626994951.142355: {"feed":"book","product_id":"FI_ETHUSD_210730","side":"buy","seq":2138858,"price":1998.0,"qty":0.0,"timestamp":1626994951160}
1626994951.142446: {"feed":"book","product_id":"FI_ETHUSD_210730","side":"buy","seq":2138859,"price":1996.9,"qty":30000.0,"timestamp":1626994951160}
1626994951.142488: {"feed":"book","product_id":"FI_ETHUSD_210730","side":"sell","seq":2138860,"price":2003.75,"qty":0.0,"timestamp":1626994951160}
1626994951.142522: {"feed":"book","product_id":"FI_ETHUSD_210730","side":"sell","seq":2138861,"price":2003.5,"qty":15000.0,"timestamp":1626994951160}
1626994951.1425521: {"feed":"book","product_id":"FI_ETHUSD_210730","side":"buy","seq":2138862,"price":2000.5,"qty":0.0,"timestamp":1626994951160}
1626994951.14258: {"feed":"book","product_id":"FI_ETHUSD_210730","side":"buy","seq":2138863,"price":2000.0,"qty":15000.0,"timestamp":1626994951160}
1626994951.142623: {"feed":"book","product_id":"PI_ETHUSD","side":"sell","seq":26663443,"price":2007.3,"qty":7500.0,"timestamp":1626994951162}
1626994951.142653: {"feed":"book","product_id":"PI_ETHUSD","side":"sell","seq":26663444,"price":2005.4,"qty":8349.0,"timestamp":1626994951162}
1626994951.146497: {"feed":"book","product_id":"FI_ETHUSD_210730","side":"sell","seq":2138864,"price":2003.6,"qty":263.0,"timestamp":1626994951167}
1626994951.148813: {"feed":"book","product_id":"PI_ETHUSD","side":"sell","seq":26663445,"price":2005.15,"qty":2092.0,"timestamp":1626994951169}
1626994951.148923: {"feed":"book","product_id":"PI_ETHUSD","side":"sell","seq":26663446,"price":2005.0,"qty":600.0,"timestamp":1626994951169}
1626994951.14899: {"feed":"book","product_id":"PI_ETHUSD","side":"buy","seq":26663447,"price":2002.2,"qty":0.0,"timestamp":1626994951170}
1626994951.149049: {"feed":"book","product_id":"PI_ETHUSD","side":"buy","seq":26663448,"price":2002.1,"qty":15826.0,"timestamp":1626994951170}
1626994951.153132: {"feed":"book","product_id":"FI_XBTUSD_210730","side":"sell","seq":5160245,"price":32215.0,"qty":524.0,"timestamp":1626994951173}
1626994951.153257: {"feed":"book","product_id":"FI_ETHUSD_210730","side":"buy","seq":2138865,"price":1996.5,"qty":0.0,"timestamp":1626994951173}
1626994951.1533241: {"feed":"book","product_id":"FI_XBTUSD_210730","side":"buy","seq":5160246,"price":32117.5,"qty":60000.0,"timestamp":1626994951173}
1626994951.153367: {"feed":"book","product_id":"FI_XBTUSD_210730","side":"sell","seq":5160247,"price":32253.0,"qty":0.0,"timestamp":1626994951174}
1626994951.155039: {"feed":"book","product_id":"PI_LTCUSD","side":"buy","seq":3423377,"price":119.33,"qty":8000.0,"timestamp":1626994951176}
1626994951.157417: {"feed":"book","product_id":"FI_BCHUSD_210924","side":"sell","seq":402257,"price":442.4,"qty":60.0,"timestamp":1626994951177}
1626994951.157505: {"feed":"book","product_id":"FI_XBTUSD_210924","side":"buy","seq":13502459,"price":32142.5,"qty":947.0,"timestamp":1626994951177}
1626994951.1575449: {"feed":"book","product_id":"FI_BCHUSD_210924","side":"buy","seq":402258,"price":439.8,"qty":60.0,"timestamp":1626994951177}
1626994951.1575758: {"feed":"book","product_id":"FI_XBTUSD_210924","side":"buy","seq":13502460,"price":32151.5,"qty":0.0,"timestamp":1626994951177}
1626994951.157611: {"feed":"book","product_id":"FI_BCHUSD_210924","side":"sell","seq":402259,"price":443.0,"qty":0.0,"timestamp":1626994951177}
1626994951.15764: {"feed":"book","product_id":"FI_XBTUSD_210924","side":"buy","seq":13502461,"price":32195.5,"qty":0.0,"timestamp":1626994951177}
1626994951.1576672: {"feed":"book","product_id":"FI_XBTUSD_210924","side":"buy","seq":13502462,"price":32188.5,"qty":16859.0,"timestamp":1626994951177}
1626994951.1576982: {"feed":"book","product_id":"FI_XBTUSD_210730","side":"sell","seq":5160248,"price":32211.5,"qty":0.0,"timestamp":1626994951177}
1626994951.157727: {"feed":"book","product_id":"FI_XBTUSD_210730","side":"sell","seq":5160249,"price":32210.5,"qty":1.0,"timestamp":1626994951177}
1626994951.157752: {"feed":"book","product_id":"FI_XBTUSD_210924","side":"buy","seq":13502463,"price":32174.0,"qty":0.0,"timestamp":1626994951177}
1626994951.157778: {"feed":"book","product_id":"FI_XBTUSD_210924","side":"buy","seq":13502464,"price":32166.0,"qty":20900.0,"timestamp":1626994951177}
1626994951.157803: {"feed":"book","product_id":"FI_XBTUSD_210924","side":"sell","seq":13502465,"price":32246.0,"qty":0.0,"timestamp":1626994951178}
1626994951.157831: {"feed":"book","product_id":"FI_XBTUSD_210924","side":"sell","seq":13502466,"price":32236.5,"qty":15969.0,"timestamp":1626994951178}
1626994951.157856: {"feed":"book","product_id":"FI_XBTUSD_210924","side":"sell","seq":13502467,"price":32264.5,"qty":0.0,"timestamp":1626994951178}
1626994951.157881: {"feed":"book","product_id":"FI_XBTUSD_210924","side":"sell","seq":13502468,"price":32256.5,"qty":20957.0,"timestamp":1626994951178}
1626994951.1627688: {"feed":"book","product_id":"PI_ETHUSD","side":"sell","seq":26663449,"price":2005.4,"qty":4032.0,"timestamp":1626994951183}
1626994951.1628811: {"feed":"book","product_id":"FI_XBTUSD_210924","side":"sell","seq":13502469,"price":32265.0,"qty":0.0,"timestamp":1626994951183}
1626994951.162951: {"feed":"book","product_id":"FI_XBTUSD_210924","side":"sell","seq":13502470,"price":32259.5,"qty":20000.0,"timestamp":1626994951183}
1626994951.163002: {"feed":"book","product_id":"FI_XBTUSD_210924","side":"buy","seq":13502471,"price":32133.5,"qty":0.0,"timestamp":1626994951183}
1626994951.163051: {"feed":"book","product_id":"FI_XBTUSD_210924","side":"buy","seq":13502472,"price":32142.0,"qty":4300.0,"timestamp":1626994951183}
1626994951.165118: {"feed":"book","product_id":"FI_XBTUSD_210924","side":"buy","seq":13502473,"price":32117.5,"qty":20865.0,"timestamp":1626994951183}
1626994951.16523: {"feed":"book","product_id":"FI_XBTUSD_210924","side":"buy","seq":13502474,"price":32118.0,"qty":256401.0,"timestamp":1626994951183}
1626994951.16528: {"feed":"book","product_id":"FI_XBTUSD_210924","side":"sell","seq":13502475,"price":32300.0,"qty":3000.0,"timestamp":1626994951183}
1626994951.165319: {"feed":"book","product_id":"FI_XBTUSD_210924","side":"sell","seq":13502476,"price":32288.5,"qty":3488.0,"timestamp":1626994951183}
1626994951.165364: {"feed":"book","product_id":"FI_XBTUSD_210924","side":"sell","seq":13502477,"price":32338.0,"qty":3000.0,"timestamp":1626994951183}
1626994951.165406: {"feed":"book","product_id":"FI_XBTUSD_210924","side":"sell","seq":13502478,"price":32323.5,"qty":16910.0,"timestamp":1626994951183}
1626994951.165427: {"feed":"book","product_id":"FI_XBTUSD_210924","side":"sell","seq":13502479,"price":32316.0,"qty":3000.0,"timestamp":1626994951183}
1626994951.165455: {"feed":"book","product_id":"FI_XBTUSD_210924","side":"sell","seq":13502480,"price":32302.5,"qty":27280.0,"timestamp":1626994951183}
1626994951.168053: {"feed":"book","product_id":"PI_XRPUSD","side":"buy","seq":3456318,"price":0.5872,"qty":18155.0,"timestamp":1626994951185}
1626994951.168132: {"feed":"book","product_id":"FI_XBTUSD_210924","side":"sell","seq":13502481,"price":32259.5,"qty":0.0,"timestamp":1626994951187}
1626994951.16818: {"feed":"book","product_id":"FI_XBTUSD_210924","side":"sell","seq":13502482,"price":32238.0,"qty":20000.0,"timestamp":1626994951187}
1626994951.168214: {"feed":"book","product_id":"PI_XRPUSD","side":"sell","seq":3456319,"price":0.5893,"qty":9574.0,"timestamp":1626994951185}
1626994951.16824: {"feed":"book","product_id":"PI_XRPUSD","side":"sell","seq":3456320,"price":0.5895,"qty":8989.0,"timestamp":1626994951185}
1626994951.168263: {"feed":"book","product_id":"PI_XRPUSD","side":"sell","seq":3456321,"price":0.5897,"qty":9948.0,"timestamp":1626994951185}
1626994951.168284: {"feed":"book","product_id":"FI_XBTUSD_210924","side":"sell","seq":13502483,"price":32257.0,"qty":0.0,"timestamp":1626994951189}
1626994951.170051: {"feed":"book","product_id":"FI_XBTUSD_210730","side":"sell","seq":5160250,"price":32210.5,"qty":0.0,"timestamp":1626994951190}
1626994951.1701388: {"feed":"book","product_id":"FI_XBTUSD_210730","side":"sell","seq":5160251,"price":32209.0,"qty":1.0,"timestamp":1626994951190}
1626994951.174158: {"feed":"book","product_id":"PI_ETHUSD","side":"sell","seq":26663450,"price":2006.1,"qty":0.0,"timestamp":1626994951192}
1626994951.174284: {"feed":"book","product_id":"PI_ETHUSD","side":"buy","seq":26663451,"price":2003.4,"qty":0.0,"timestamp":1626994951194}
1626994951.19269: {"feed":"book","product_id":"FI_XBTUSD_210730","side":"sell","seq":5160252,"price":32204.5,"qty":139406.0,"timestamp":1626994951200}
1626994951.192804: {"feed":"book","product_id":"FI_XBTUSD_210730","side":"sell","seq":5160253,"price":32200.5,"qty":1200.0,"timestamp":1626994951200}
1626994951.192888: {"feed":"book","product_id":"FI_ETHUSD_211231","side":"sell","seq":2199202,"price":2032.7,"qty":0.0,"timestamp":1626994951201}
1626994951.192945: {"feed":"book","product_id":"FI_ETHUSD_211231","side":"sell","seq":2199203,"price":2032.6,"qty":420.0,"timestamp":1626994951201}
1626994951.19299: {"feed":"book","product_id":"FI_ETHUSD_210730","side":"sell","seq":2138866,"price":2003.55,"qty":0.0,"timestamp":1626994951202}
1626994951.193037: {"feed":"book","product_id":"FI_ETHUSD_210730","side":"sell","seq":2138867,"price":2002.85,"qty":600.0,"timestamp":1626994951202}
1626994951.2160058: {"feed":"book","product_id":"PI_ETHUSD","side":"sell","seq":26663452,"price":2005.35,"qty":10062.0,"timestamp":1626994951237}
1626994951.218173: {"feed":"book","product_id":"FI_XBTUSD_210924","side":"sell","seq":13502484,"price":32310.5,"qty":0.0,"timestamp":1626994951237}
1626994951.218297: {"feed":"book","product_id":"FI_XBTUSD_210924","side":"buy","seq":13502485,"price":32159.0,"qty":3000.0,"timestamp":1626994951237}
1626994951.218362: {"feed":"book","product_id":"FI_XBTUSD_210924","side":"buy","seq":13502486,"price":32116.5,"qty":18960.0,"timestamp":1626994951237}
1626994951.220882: {"feed":"book","product_id":"FI_XRPUSD_210924","side":"buy","seq":602306,"price":0.5828,"qty":41.0,"timestamp":1626994951237}
1626994951.221002: {"feed":"book","product_id":"FI_XBTUSD_210730","side":"buy","seq":5160254,"price":32001.0,"qty":0.0,"timestamp":1626994951237}
1626994951.221092: {"feed":"book","product_id":"FI_XBTUSD_210730","side":"buy","seq":5160255,"price":32030.5,"qty":250002.0,"timestamp":1626994951237}
1626994951.2211242: {"feed":"book","product_id":"FI_XRPUSD_210924","side":"buy","seq":602307,"price":0.583,"qty":0.0,"timestamp":1626994951237}
1626994951.221153: {"feed":"book","product_id":"FI_XRPUSD_210924","side":"sell","seq":602308,"price":0.5866,"qty":41.0,"timestamp":1626994951237}
1626994951.221181: {"feed":"book","product_id":"FI_XBTUSD_210924","side":"sell","seq":13502487,"price":32323.5,"qty":800.0,"timestamp":1626994951237}
1626994951.221205: {"feed":"book","product_id":"FI_XRPUSD_210924","side":"sell","seq":602309,"price":0.5878,"qty":0.0,"timestamp":1626994951237}
1626994951.2212312: {"feed":"book","product_id":"PI_ETHUSD","side":"buy","seq":26663453,"price":2001.95,"qty":0.0,"timestamp":1626994951238}
1626994951.221262: {"feed":"book","product_id":"PI_ETHUSD","side":"buy","seq":26663454,"price":2002.4,"qty":24991.0,"timestamp":1626994951238}
1626994951.221285: {"feed":"book","product_id":"FI_ETHUSD_211231","side":"sell","seq":2199204,"price":2048.2,"qty":44305.0,"timestamp":1626994951238}
1626994951.221306: {"feed":"book","product_id":"PI_XRPUSD","side":"buy","seq":3456322,"price":0.5878,"qty":5481.0,"timestamp":1626994951241}
1626994951.2213278: {"feed":"book","product_id":"FI_ETHUSD_211231","side":"sell","seq":2199205,"price":2048.1,"qty":45099.0,"timestamp":1626994951238}
1626994951.2213519: {"feed":"book","product_id":"PI_XRPUSD","side":"sell","seq":3456323,"price":0.5892,"qty":7001.0,"timestamp":1626994951241}
1626994951.221374: {"feed":"book","product_id":"FI_ETHUSD_211231","side":"sell","seq":2199206,"price":2048.2,"qty":0.0,"timestamp":1626994951238}
1626994951.221398: {"feed":"book","product_id":"FI_ETHUSD_211231","side":"sell","seq":2199207,"price":2048.1,"qty":89404.0,"timestamp":1626994951238}
1626994951.223603: {"feed":"book","product_id":"FI_XBTUSD_210730","side":"sell","seq":5160256,"price":32209.0,"qty":0.0,"timestamp":1626994951243}
1626994951.223706: {"feed":"book","product_id":"FI_XBTUSD_210730","side":"sell","seq":5160257,"price":32208.0,"qty":1.0,"timestamp":1626994951243}
1626994951.223746: {"feed":"book","product_id":"PI_XRPUSD","side":"sell","seq":3456324,"price":0.5892,"qty":6951.0,"timestamp":1626994951244}
1626994951.223775: {"feed":"book","product_id":"PI_XRPUSD","side":"sell","seq":3456325,"price":0.5891,"qty":8159.0,"timestamp":1626994951244}
1626994951.244972: {"feed":"book","product_id":"FI_XBTUSD_210924","side":"sell","seq":13502488,"price":32236.0,"qty":0.0,"timestamp":1626994951264}
1626994951.245095: {"feed":"book","product_id":"FI_XBTUSD_210924","side":"sell","seq":13502489,"price":32233.0,"qty":28010.0,"timestamp":1626994951264}
1626994951.248327: {"feed":"book","product_id":"PI_ETHUSD","side":"sell","seq":26663455,"price":2005.4,"qty":1532.0,"timestamp":1626994951264}
1626994951.248435: {"feed":"book","product_id":"PI_ETHUSD","side":"buy","seq":26663456,"price":2001.15,"qty":0.0,"timestamp":1626994951264}
1626994951.248505: {"feed":"book","product_id":"PI_ETHUSD","side":"buy","seq":26663457,"price":2000.55,"qty":18977.0,"timestamp":1626994951264}
1626994951.248557: {"feed":"book","product_id":"PI_ETHUSD","side":"sell","seq":26663458,"price":2007.4,"qty":4157.0,"timestamp":1626994951264}
1626994951.2485929: {"feed":"book","product_id":"PI_ETHUSD","side":"sell","seq":26663459,"price":2007.15,"qty":27610.0,"timestamp":1626994951264}
1626994951.248628: {"feed":"book","product_id":"PI_ETHUSD","side":"sell","seq":26663460,"price":2008.15,"qty":4990.0,"timestamp":1626994951264}
1626994951.248659: {"feed":"book","product_id":"PI_ETHUSD","side":"sell","seq":26663461,"price":2008.0,"qty":24055.0,"timestamp":1626994951264}
1626994951.2544918: {"feed":"book","product_id":"FI_ETHUSD_210730","side":"sell","seq":2138868,"price":2013.55,"qty":0.0,"timestamp":1626994951272}
1626994951.254616: {"feed":"book","product_id":"FI_ETHUSD_210730","side":"sell","seq":2138869,"price":2013.45,"qty":45421.0,"timestamp":1626994951272}
1626994951.257848: {"feed":"book","product_id":"PI_ETHUSD","side":"sell","seq":26663462,"price":2006.85,"qty":0.0,"timestamp":1626994951278}
1626994951.257972: {"feed":"book","product_id":"PI_ETHUSD","side":"sell","seq":26663463,"price":2006.3,"qty":4046.0,"timestamp":1626994951278}
1626994951.2609532: {"feed":"book","product_id":"PI_XRPUSD","side":"buy","seq":3456326,"price":0.5876,"qty":18933.0,"timestamp":1626994951282}
1626994951.2615192: {"feed":"book","product_id":"PI_XRPUSD","side":"sell","seq":3456327,"price":0.5899,"qty":27287.0,"timestamp":1626994951283}
1626994951.263102: {"feed":"book","product_id":"PI_XRPUSD","side":"buy","seq":3456328,"price":0.5873,"qty":11890.0,"timestamp":1626994951283}
1626994951.263211: {"feed":"book","product_id":"PI_XRPUSD","side":"sell","seq":3456329,"price":0.5895,"qty":12989.0,"timestamp":1626994951283}
1626994951.266379: {"feed":"book","product_id":"PI_ETHUSD","side":"sell","seq":26663464,"price":2005.25,"qty":2500.0,"timestamp":1626994951286}
1626994951.2665012: {"feed":"book","product_id":"PI_ETHUSD","side":"buy","seq":26663465,"price":2003.2,"qty":2500.0,"timestamp":1626994951286}
1626994951.266559: {"feed":"book","product_id":"PI_ETHUSD","side":"sell","seq":26663466,"price":2005.8,"qty":5000.0,"timestamp":1626994951287}
1626994951.273731: {"feed":"book","product_id":"PI_ETHUSD","side":"sell","seq":26663467,"price":2008.05,"qty":9049.0,"timestamp":1626994951294}
1626994951.273839: {"feed":"book","product_id":"PI_ETHUSD","side":"sell","seq":26663468,"price":2007.55,"qty":154989.0,"timestamp":1626994951294}
1626994951.279029: {"feed":"book","product_id":"PI_ETHUSD","side":"sell","seq":26663469,"price":2008.75,"qty":4989.0,"timestamp":1626994951300}
1626994951.285494: {"feed":"book","product_id":"PI_ETHUSD","side":"buy","seq":26663470,"price":2002.4,"qty":20000.0,"timestamp":1626994951305}
1626994951.2856011: {"feed":"book","product_id":"PI_ETHUSD","side":"sell","seq":26663471,"price":2005.3,"qty":3926.0,"timestamp":1626994951306}
1626994951.2856672: {"feed":"book","product_id":"PI_ETHUSD","side":"sell","seq":26663472,"price":2006.05,"qty":3973.0,"timestamp":1626994951306}
1626994951.2894: {"feed":"book","product_id":"PI_ETHUSD","side":"buy","seq":26663473,"price":2003.15,"qty":3970.0,"timestamp":1626994951307}
1626994951.289523: {"feed":"book","product_id":"PI_XRPUSD","side":"buy","seq":3456330,"price":0.5878,"qty":1599.0,"timestamp":1626994951308}
1626994951.292701: {"feed":"book","product_id":"PI_XRPUSD","side":"buy","seq":3456331,"price":0.5879,"qty":320.0,"timestamp":1626994951309}
1626994951.292809: {"feed":"book","product_id":"PI_ETHUSD","side":"sell","seq":26663474,"price":2005.3,"qty":0.0,"timestamp":1626994951310}
1626994951.292883: {"feed":"book","product_id":"PI_ETHUSD","side":"sell","seq":26663475,"price":2006.2,"qty":0.0,"timestamp":1626994951311}
1626994951.296126: {"feed":"book","product_id":"FI_XBTUSD_210730","side":"buy","seq":5160258,"price":32121.0,"qty":0.0,"timestamp":1626994951311}
1626994951.296248: {"feed":"book","product_id":"FI_XBTUSD_210730","side":"buy","seq":5160259,"price":32119.5,"qty":1500.0,"timestamp":1626994951311}
1626994951.296312: {"feed":"book","product_id":"PI_ETHUSD","side":"buy","seq":26663476,"price":2002.95,"qty":0.0,"timestamp":1626994951314}
1626994951.29637: {"feed":"book","product_id":"FI_XBTUSD_210924","side":"buy","seq":13502490,"price":32141.5,"qty":0.0,"timestamp":1626994951314}
1626994951.296427: {"feed":"book","product_id":"FI_XBTUSD_210924","side":"buy","seq":13502491,"price":32140.0,"qty":1500.0,"timestamp":1626994951314}
1626994951.296486: {"feed":"book","product_id":"PI_ETHUSD","side":"buy","seq":26663477,"price":2003.15,"qty":0.0,"timestamp":1626994951315}
1626994951.2965162: {"feed":"book","product_id":"FI_XBTUSD_210730","side":"buy","seq":5160260,"price":32119.5,"qty":0.0,"timestamp":1626994951316}
1626994951.296542: {"feed":"book","product_id":"FI_XBTUSD_210730","side":"buy","seq":5160261,"price":32117.5,"qty":61500.0,"timestamp":1626994951316}
1626994951.2993238: {"feed":"book","product_id":"FI_XBTUSD_210924","side":"buy","seq":13502492,"price":32140.0,"qty":0.0,"timestamp":1626994951316}
1626994951.299447: {"feed":"book","product_id":"FI_XBTUSD_210924","side":"buy","seq":13502493,"price":32138.5,"qty":1500.0,"timestamp":1626994951316}
1626994951.3027048: {"feed":"book","product_id":"PI_ETHUSD","side":"buy","seq":26663478,"price":2002.15,"qty":16150.0,"timestamp":1626994951324}
1626994951.303704: {"feed":"book","product_id":"PI_ETHUSD","side":"sell","seq":26663479,"price":2005.35,"qty":5971.0,"timestamp":1626994951325}
1626994951.308257: {"feed":"book","product_id":"PI_XRPUSD","side":"sell","seq":3456332,"price":0.5889,"qty":2.0,"timestamp":1626994951328}
1626994951.3203468: {"feed":"book","product_id":"FI_XBTUSD_210730","side":"buy","seq":5160262,"price":32117.5,"qty":60000.0,"timestamp":1626994951339}
1626994951.320457: {"feed":"book","product_id":"FI_XBTUSD_210730","side":"buy","seq":5160263,"price":32114.5,"qty":1500.0,"timestamp":1626994951339}
1626994951.32054: {"feed":"book","product_id":"FI_XBTUSD_210924","side":"buy","seq":13502494,"price":32138.5,"qty":0.0,"timestamp":1626994951340}
1626994951.320599: {"feed":"book","product_id":"FI_XBTUSD_210924","side":"buy","seq":13502495,"price":32135.0,"qty":1500.0,"timestamp":1626994951340}
1626994951.333987: {"feed":"book","product_id":"PI_ETHUSD","side":"buy","seq":26663480,"price":2002.4,"qty":0.0,"timestamp":1626994951351}
1626994951.3341131: {"feed":"book","product_id":"PI_ETHUSD","side":"buy","seq":26663481,"price":2002.3,"qty":23928.0,"timestamp":1626994951351}
1626994951.334167: {"feed":"book","product_id":"FI_XBTUSD_210730","side":"buy","seq":5160264,"price":32170.0,"qty":0.0,"timestamp":1626994951352}
1626994951.3365152: {"feed":"book","product_id":"FI_XBTUSD_210730","side":"buy","seq":5160265,"price":32154.0,"qty":0.0,"timestamp":1626994951356}
1626994951.3365812: {"feed":"book","product_id":"FI_XBTUSD_210730","side":"buy","seq":5160266,"price":32154.5,"qty":4688.0,"timestamp":1626994951356}
1626994951.342334: {"feed":"book","product_id":"FI_ETHUSD_210730","side":"sell","seq":2138870,"price":2013.5,"qty":0.0,"timestamp":1626994951360}
1626994951.342457: {"feed":"book","product_id":"FI_ETHUSD_210730","side":"sell","seq":2138871,"price":2013.4,"qty":250002.0,"timestamp":1626994951360}
1626994951.342519: {"feed":"book","product_id":"FI_ETHUSD_211231","side":"sell","seq":2199208,"price":2048.15,"qty":0.0,"timestamp":1626994951360}
1626994951.3425741: {"feed":"book","product_id":"FI_ETHUSD_211231","side":"sell","seq":2199209,"price":2048.05,"qty":250002.0,"timestamp":1626994951360}
1626994951.344366: {"feed":"book","product_id":"PI_ETHUSD","side":"sell","seq":26663482,"price":2005.4,"qty":56910.0,"timestamp":1626994951364}
1626994951.353219: {"feed":"book","product_id":"FI_XBTUSD_210730","side":"buy","seq":5160267,"price":32112.5,"qty":0.0,"timestamp":1626994951372}
1626994951.3533041: {"feed":"book","product_id":"FI_XBTUSD_210730","side":"buy","seq":5160268,"price":32091.5,"qty":252401.0,"timestamp":1626994951372}
1626994951.353338: {"feed":"book","product_id":"FI_XBTUSD_210730","side":"buy","seq":5160269,"price":32100.5,"qty":0.0,"timestamp":1626994951372}
1626994951.353369: {"feed":"book","product_id":"FI_XBTUSD_210730","side":"buy","seq":5160270,"price":32052.0,"qty":7200.0,"timestamp":1626994951372}
1626994951.3533921: {"feed":"book","product_id":"PI_LTCUSD","side":"sell","seq":3423378,"price":119.63,"qty":18621.0,"timestamp":1626994951373}
1626994951.359854: {"feed":"book","product_id":"PI_ETHUSD","side":"buy","seq":26663483,"price":2002.3,"qty":3928.0,"timestamp":1626994951379}
1626994951.359964: {"feed":"book","product_id":"PI_ETHUSD","side":"buy","seq":26663484,"price":2002.15,"qty":36150.0,"timestamp":1626994951379}
1626994951.3621042: {"feed":"book","product_id":"FI_XBTUSD_210924","side":"buy","seq":13502496,"price":32188.5,"qty":1080.0,"timestamp":1626994951382}
1626994951.362174: {"feed":"book","product_id":"FI_XBTUSD_210924","side":"buy","seq":13502497,"price":32195.5,"qty":14549.0,"timestamp":1626994951382}
1626994951.3645608: {"feed":"book","product_id":"FI_XBTUSD_210924","side":"sell","seq":13502498,"price":32256.5,"qty":0.0,"timestamp":1626994951382}
1626994951.3646479: {"feed":"book","product_id":"FI_XBTUSD_210924","side":"sell","seq":13502499,"price":32258.5,"qty":20959.0,"timestamp":1626994951382}
1626994951.364754: {"feed":"book","product_id":"FI_XBTUSD_210924","side":"sell","seq":13502500,"price":32236.5,"qty":0.0,"timestamp":1626994951382}
1626994951.3647842: {"feed":"book","product_id":"FI_XBTUSD_210924","side":"sell","seq":13502501,"price":32236.0,"qty":15270.0,"timestamp":1626994951382}
1626994951.3648472: {"feed":"book","product_id":"FI_XBTUSD_210924","side":"buy","seq":13502502,"price":32166.0,"qty":0.0,"timestamp":1626994951382}
1626994951.364876: {"feed":"book","product_id":"FI_XBTUSD_210924","side":"buy","seq":13502503,"price":32166.0,"qty":20902.0,"timestamp":1626994951382}
1626994951.3649018: {"feed":"book","product_id":"FI_XBTUSD_210924","side":"sell","seq":13502504,"price":32238.0,"qty":0.0,"timestamp":1626994951385}
1626994951.364928: {"feed":"book","product_id":"FI_XBTUSD_210924","side":"sell","seq":13502505,"price":32238.5,"qty":20000.0,"timestamp":1626994951385}
1626994951.367243: {"feed":"book","product_id":"PI_ETHUSD","side":"buy","seq":26663485,"price":1999.75,"qty":0.0,"timestamp":1626994951387}
1626994951.367332: {"feed":"book","product_id":"PI_ETHUSD","side":"buy","seq":26663486,"price":1999.3,"qty":150000.0,"timestamp":1626994951387}
1626994951.372823: {"feed":"book","product_id":"PI_ETHUSD","side":"sell","seq":26663487,"price":2012.2,"qty":0.0,"timestamp":1626994951391}
1626994951.3729541: {"feed":"book","product_id":"PI_ETHUSD","side":"buy","seq":26663488,"price":2002.15,"qty":28650.0,"timestamp":1626994951394}
1626994951.378346: {"feed":"book","product_id":"FI_ETHUSD_210730","side":"sell","seq":2138872,"price":2010.6,"qty":0.0,"timestamp":1626994951398}
1626994951.378473: {"feed":"book","product_id":"FI_ETHUSD_210730","side":"sell","seq":2138873,"price":2009.1,"qty":250001.0,"timestamp":1626994951398}
1626994951.378537: {"feed":"book","product_id":"PI_ETHUSD","side":"buy","seq":26663489,"price":1999.8,"qty":0.0,"timestamp":1626994951398}
1626994951.3785942: {"feed":"book","product_id":"PI_ETHUSD","side":"buy","seq":26663490,"price":1999.6,"qty":500001.0,"timestamp":1626994951398}
1626994951.378651: {"feed":"book","product_id":"FI_ETHUSD_211231","side":"sell","seq":2199210,"price":2038.7,"qty":0.0,"timestamp":1626994951398}
1626994951.3787038: {"feed":"book","product_id":"FI_ETHUSD_211231","side":"sell","seq":2199211,"price":2038.25,"qty":258749.0,"timestamp":1626994951398}
1626994951.383449: {"feed":"book","product_id":"PI_ETHUSD","side":"sell","seq":26663491,"price":2005.1,"qty":10624.0,"timestamp":1626994951403}
1626994951.383952: {"feed":"book","product_id":"FI_XBTUSD_210924","side":"sell","seq":13502506,"price":32241.0,"qty":2440.0,"timestamp":1626994951405}
1626994951.384046: {"feed":"book","product_id":"FI_XBTUSD_210924","side":"sell","seq":13502507,"price":32260.0,"qty":2440.0,"timestamp":1626994951405}
1626994951.384117: {"feed":"book","product_id":"FI_XBTUSD_210924","side":"buy","seq":13502508,"price":32178.0,"qty":1900.0,"timestamp":1626994951405}
1626994951.384384: {"feed":"book","product_id":"FI_XBTUSD_210924","side":"buy","seq":13502509,"price":32121.5,"qty":1900.0,"timestamp":1626994951405}
1626994951.384445: {"feed":"book","product_id":"PI_ETHUSD","side":"buy","seq":26663492,"price":2002.8,"qty":91958.0,"timestamp":1626994951405}
1626994951.386807: {"feed":"book","product_id":"FI_XBTUSD_210730","side":"sell","seq":5160271,"price":32246.5,"qty":0.0,"timestamp":1626994951407}
1626994951.386896: {"feed":"book","product_id":"PI_ETHUSD","side":"buy","seq":26663493,"price":2002.0,"qty":3989.0,"timestamp":1626994951407}
1626994951.386942: {"feed":"book","product_id":"FI_XBTUSD_210730","side":"sell","seq":5160272,"price":32207.5,"qty":630.0,"timestamp":1626994951407}
1626994951.389781: {"feed":"book","product_id":"PI_ETHUSD","side":"buy","seq":26663494,"price":2001.3,"qty":7500.0,"timestamp":1626994951409}
1626994951.3915892: {"feed":"book","product_id":"FI_XBTUSD_210924","side":"buy","seq":13502510,"price":32135.0,"qty":2559.0,"timestamp":1626994951411}
1626994951.396124: {"feed":"book","product_id":"FI_XBTUSD_210924","side":"buy","seq":13502511,"price":32142.5,"qty":0.0,"timestamp":1626994951417}
1626994951.399482: {"feed":"book","product_id":"FI_XBTUSD_210730","side":"buy","seq":5160273,"price":32030.5,"qty":0.0,"timestamp":1626994951419}
1626994951.399626: {"feed":"book","product_id":"FI_XBTUSD_210730","side":"buy","seq":5160274,"price":32001.0,"qty":250002.0,"timestamp":1626994951419}
1626994951.401831: {"feed":"book","product_id":"FI_ETHUSD_211231","side":"buy","seq":2199212,"price":2024.35,"qty":0.0,"timestamp":1626994951422}
1626994951.408445: {"feed":"book","product_id":"FI_XBTUSD_210924","side":"sell","seq":13502512,"price":32302.5,"qty":6400.0,"timestamp":1626994951429}
1626994951.4088142: {"feed":"book","product_id":"FI_XBTUSD_210924","side":"sell","seq":13502513,"price":32340.5,"qty":0.0,"timestamp":1626994951429}
1626994951.4089: {"feed":"book","product_id":"FI_XBTUSD_210924","side":"buy","seq":13502514,"price":32098.5,"qty":0.0,"timestamp":1626994951429}
1626994951.412761: {"feed":"book","product_id":"FI_XBTUSD_210924","side":"buy","seq":13502515,"price":32061.0,"qty":0.0,"timestamp":1626994951430}
1626994951.416118: {"feed":"book","product_id":"PI_ETHUSD","side":"buy","seq":26663495,"price":2002.15,"qty":38650.0,"timestamp":1626994951436}
1626994951.416228: {"feed":"book","product_id":"PI_ETHUSD","side":"sell","seq":26663496,"price":2004.35,"qty":10000.0,"timestamp":1626994951436}
1626994951.4162939: {"feed":"book","product_id":"PI_XRPUSD","side":"sell","seq":3456333,"price":0.5888,"qty":12803.0,"timestamp":1626994951437}
1626994951.419434: {"feed":"book","product_id":"PI_LTCUSD","side":"sell","seq":3423379,"price":119.63,"qty":9022.0,"timestamp":1626994951440}
1626994951.426614: {"feed":"book","product_id":"PI_ETHUSD","side":"buy","seq":26663497,"price":2003.2,"qty":0.0,"timestamp":1626994951444}
1626994951.426739: {"feed":"book","product_id":"FI_XBTUSD_210924","side":"buy","seq":13502516,"price":32159.0,"qty":0.0,"timestamp":1626994951445}
1626994951.426827: {"feed":"book","product_id":"FI_XBTUSD_210924","side":"buy","seq":13502517,"price":32082.0,"qty":0.0,"timestamp":1626994951445}
1626994951.426878: {"feed":"book","product_id":"FI_XBTUSD_210924","side":"buy","seq":13502518,"price":32042.0,"qty":0.0,"timestamp":1626994951445}
1626994951.428312: {"feed":"book","product_id":"PI_ETHUSD","side":"sell","seq":26663498,"price":2005.25,"qty":0.0,"timestamp":1626994951449}
1626994951.4378932: {"feed":"book","product_id":"PI_ETHUSD","side":"buy","seq":26663499,"price":2003.0,"qty":600.0,"timestamp":1626994951458}
1626994951.442483: {"feed":"book","product_id":"PI_ETHUSD","side":"buy","seq":26663500,"price":2002.75,"qty":0.0,"timestamp":1626994951463}
1626994951.4485319: {"feed":"book","product_id":"PI_ETHUSD","side":"sell","seq":26663501,"price":2006.35,"qty":0.0,"timestamp":1626994951468}
1626994951.4486232: {"feed":"book","product_id":"PI_ETHUSD","side":"sell","seq":26663502,"price":2005.85,"qty":10154.0,"timestamp":1626994951468}
1626994951.448687: {"feed":"book","product_id":"PI_ETHUSD","side":"buy","seq":26663503,"price":2001.9,"qty":0.0,"timestamp":1626994951468}
1626994951.448739: {"feed":"book","product_id":"PI_ETHUSD","side":"buy","seq":26663504,"price":2001.85,"qty":19888.0,"timestamp":1626994951468}
1626994951.448778: {"feed":"book","product_id":"PI_ETHUSD","side":"sell","seq":26663505,"price":2008.0,"qty":0.0,"timestamp":1626994951468}
1626994951.448821: {"feed":"book","product_id":"PI_ETHUSD","side":"sell","seq":26663506,"price":2007.7,"qty":27408.0,"timestamp":1626994951468}
1626994951.455173: {"feed":"book","product_id":"PI_ETHUSD","side":"buy","seq":26663507,"price":2002.85,"qty":0.0,"timestamp":1626994951475}
1626994951.458289: {"feed":"book","product_id":"FI_XBTUSD_210924","side":"buy","seq":13502519,"price":32146.0,"qty":0.0,"timestamp":1626994951478}
1626994951.460437: {"feed":"book","product_id":"FI_ETHUSD_211231","side":"buy","seq":2199213,"price":2026.2,"qty":2000.0,"timestamp":1626994951480}
1626994951.468072: {"feed":"book","product_id":"PI_ETHUSD","side":"buy","seq":26663508,"price":2000.35,"qty":150000.0,"timestamp":1626994951488}
1626994951.468182: {"feed":"book","product_id":"PI_ETHUSD","side":"buy","seq":26663509,"price":1999.9,"qty":134147.0,"timestamp":1626994951488}
1626994951.48303: {"feed":"book","product_id":"PI_ETHUSD","side":"buy","seq":26663510,"price":2003.55,"qty":2424.0,"timestamp":1626994951502}
1626994951.483152: {"feed":"book","product_id":"PI_ETHUSD","side":"sell","seq":26663511,"price":2004.05,"qty":2510.0,"timestamp":1626994951502}
1626994951.485153: {"feed":"book","product_id":"PI_XRPUSD","side":"buy","seq":3456334,"price":0.5877,"qty":11421.0,"timestamp":1626994951505}
1626994951.485266: {"feed":"book","product_id":"PI_ETHUSD","side":"sell","seq":26663512,"price":2005.15,"qty":0.0,"timestamp":1626994951505}
1626994951.4877691: {"feed":"book","product_id":"PI_ETHUSD","side":"buy","seq":26663513,"price":2002.65,"qty":4181.0,"timestamp":1626994951506}
1626994951.487895: {"feed":"book","product_id":"PI_ETHUSD","side":"sell","seq":26663514,"price":2010.3,"qty":0.0,"timestamp":1626994951508}
1626994951.491748: {"feed":"book","product_id":"PI_ETHUSD","side":"buy","seq":26663515,"price":2002.1,"qty":0.0,"timestamp":1626994951512}
1626994951.4918761: {"feed":"book","product_id":"PI_ETHUSD","side":"buy","seq":26663516,"price":2002.4,"qty":15826.0,"timestamp":1626994951512}
1626994951.49382: {"feed":"book","product_id":"PI_ETHUSD","side":"buy","seq":26663517,"price":2002.15,"qty":18650.0,"timestamp":1626994951514}
1626994951.493927: {"feed":"book","product_id":"PI_ETHUSD","side":"buy","seq":26663518,"price":2002.1,"qty":20000.0,"timestamp":1626994951514}
1626994951.496337: {"feed":"book","product_id":"PI_ETHUSD","side":"buy","seq":26663519,"price":2002.1,"qty":0.0,"timestamp":1626994951514}
1626994951.496466: {"feed":"book","product_id":"PI_ETHUSD","side":"buy","seq":26663520,"price":2002.35,"qty":20000.0,"timestamp":1626994951514}
1626994951.4965289: {"feed":"book","product_id":"PI_ETHUSD","side":"buy","seq":26663521,"price":2002.4,"qty":0.0,"timestamp":1626994951515}
1626994951.496578: {"feed":"book","product_id":"PI_ETHUSD","side":"buy","seq":26663522,"price":2002.15,"qty":34476.0,"timestamp":1626994951515}
1626994951.496616: {"feed":"book","product_id":"PI_ETHUSD","side":"buy","seq":26663523,"price":2002.35,"qty":0.0,"timestamp":1626994951517}
1626994951.497141: {"feed":"book","product_id":"PI_ETHUSD","side":"buy","seq":26663524,"price":2002.0,"qty":23989.0,"timestamp":1626994951517}
1626994951.497227: {"feed":"book","product_id":"PI_ETHUSD","side":"buy","seq":26663525,"price":2002.15,"qty":18650.0,"timestamp":1626994951517}
1626994951.4972758: {"feed":"book","product_id":"PI_ETHUSD","side":"buy","seq":26663526,"price":2002.05,"qty":19709.0,"timestamp":1626994951517}
1626994951.499551: {"feed":"book","product_id":"PI_ETHUSD","side":"buy","seq":26663527,"price":2002.35,"qty":6044.0,"timestamp":1626994951520}
1626994951.507329: {"feed":"book","product_id":"PI_ETHUSD","side":"buy","seq":26663528,"price":2002.05,"qty":3883.0,"timestamp":1626994951524}
1626994951.507403: {"feed":"book","product_id":"PI_ETHUSD","side":"buy","seq":26663529,"price":2002.0,"qty":39815.0,"timestamp":1626994951524}
1626994951.507435: {"feed":"book","product_id":"PI_ETHUSD","side":"buy","seq":26663530,"price":2002.0,"qty":19815.0,"timestamp":1626994951526}
1626994951.50746: {"feed":"book","product_id":"PI_ETHUSD","side":"buy","seq":26663531,"price":2001.95,"qty":20000.0,"timestamp":1626994951526}
1626994951.508375: {"feed":"book","product_id":"PI_ETHUSD","side":"buy","seq":26663532,"price":2001.95,"qty":0.0,"timestamp":1626994951529}
1626994951.508461: {"feed":"book","product_id":"PI_ETHUSD","side":"buy","seq":26663533,"price":2002.15,"qty":38650.0,"timestamp":1626994951529}
1626994951.513273: {"feed":"book","product_id":"PI_ETHUSD","side":"buy","seq":26663534,"price":2002.0,"qty":3989.0,"timestamp":1626994951530}
1626994951.513381: {"feed":"book","product_id":"PI_ETHUSD","side":"buy","seq":26663535,"price":2002.1,"qty":15826.0,"timestamp":1626994951530}
1626994951.5134459: {"feed":"book","product_id":"PI_ETHUSD","side":"buy","seq":26663536,"price":2002.1,"qty":0.0,"timestamp":1626994951530}
1626994951.513503: {"feed":"book","product_id":"PI_ETHUSD","side":"buy","seq":26663537,"price":2002.2,"qty":15826.0,"timestamp":1626994951530}
1626994951.513549: {"feed":"book","product_id":"PI_ETHUSD","side":"buy","seq":26663538,"price":2002.15,"qty":18650.0,"timestamp":1626994951531}
1626994951.5135849: {"feed":"book","product_id":"PI_ETHUSD","side":"buy","seq":26663539,"price":2002.05,"qty":23883.0,"timestamp":1626994951531}
1626994951.513619: {"feed":"book","product_id":"PI_ETHUSD","side":"sell","seq":26663540,"price":2004.05,"qty":0.0,"timestamp":1626994951532}
1626994951.51521: {"feed":"book","product_id":"FI_BCHUSD_210924","side":"sell","seq":402260,"price":442.9,"qty":37229.0,"timestamp":1626994951536}
1626994951.515285: {"feed":"book","product_id":"FI_BCHUSD_210924","side":"buy","seq":402261,"price":439.9,"qty":0.0,"timestamp":1626994951536}
1626994951.517309: {"feed":"book","product_id":"FI_BCHUSD_210924","side":"sell","seq":402262,"price":442.3,"qty":65.0,"timestamp":1626994951538}
1626994951.519474: {"feed":"book","product_id":"PI_ETHUSD","side":"buy","seq":26663541,"price":2002.05,"qty":3883.0,"timestamp":1626994951540}
1626994951.519549: {"feed":"book","product_id":"PI_ETHUSD","side":"buy","seq":26663542,"price":2002.0,"qty":23989.0,"timestamp":1626994951540}
1626994951.521811: {"feed":"book","product_id":"PI_XRPUSD","side":"sell","seq":3456335,"price":0.59,"qty":3855.0,"timestamp":1626994951542}
1626994951.521885: {"feed":"book","product_id":"PI_XRPUSD","side":"sell","seq":3456336,"price":0.5896,"qty":0.0,"timestamp":1626994951543}
1626994951.521929: {"feed":"book","product_id":"PI_ETHUSD","side":"buy","seq":26663543,"price":2002.0,"qty":3989.0,"timestamp":1626994951543}
1626994951.5219579: {"feed":"book","product_id":"PI_ETHUSD","side":"buy","seq":26663544,"price":2001.95,"qty":20000.0,"timestamp":1626994951543}
1626994951.52376: {"feed":"book","product_id":"PI_ETHUSD","side":"buy","seq":26663545,"price":2002.2,"qty":0.0,"timestamp":1626994951544}
1626994951.523846: {"feed":"book","product_id":"PI_ETHUSD","side":"buy","seq":26663546,"price":2002.0,"qty":19815.0,"timestamp":1626994951544}
1626994951.523881: {"feed":"book","product_id":"PI_XRPUSD","side":"sell","seq":3456337,"price":0.5898,"qty":3905.0,"timestamp":1626994951545}
1626994951.52594: {"feed":"book","product_id":"PI_XRPUSD","side":"sell","seq":3456338,"price":0.5891,"qty":8109.0,"timestamp":1626994951546}
1626994951.526016: {"feed":"book","product_id":"PI_XRPUSD","side":"sell","seq":3456339,"price":0.5889,"qty":52.0,"timestamp":1626994951546}
1626994951.526464: {"feed":"book","product_id":"PI_ETHUSD","side":"buy","seq":26663547,"price":2002.5,"qty":20883.0,"timestamp":1626994951548}
1626994951.527553: {"feed":"book","product_id":"PI_ETHUSD","side":"buy","seq":26663548,"price":2002.15,"qty":13915.0,"timestamp":1626994951549}
1626994951.529121: {"feed":"book","product_id":"PI_XRPUSD","side":"sell","seq":3456340,"price":0.5889,"qty":2.0,"timestamp":1626994951549}
1626994951.529197: {"feed":"book","product_id":"PI_XRPUSD","side":"sell","seq":3456341,"price":0.5892,"qty":7001.0,"timestamp":1626994951549}
1626994951.529228: {"feed":"book","product_id":"PI_ETHUSD","side":"sell","seq":26663549,"price":2005.8,"qty":0.0,"timestamp":1626994951550}
1626994951.531064: {"feed":"book","product_id":"FI_XBTUSD_210730","side":"buy","seq":5160275,"price":32114.5,"qty":0.0,"timestamp":1626994951552}
1626994951.5311308: {"feed":"book","product_id":"FI_XBTUSD_210730","side":"buy","seq":5160276,"price":32121.0,"qty":1500.0,"timestamp":1626994951552}
1626994951.533195: {"feed":"book","product_id":"PI_XRPUSD","side":"buy","seq":3456342,"price":0.5877,"qty":5199.0,"timestamp":1626994951554}
1626994951.5332532: {"feed":"book","product_id":"FI_XBTUSD_210924","side":"buy","seq":13502520,"price":32135.0,"qty":1059.0,"timestamp":1626994951554}
1626994951.5332859: {"feed":"book","product_id":"FI_XBTUSD_210924","side":"buy","seq":13502521,"price":32141.5,"qty":1500.0,"timestamp":1626994951554}
1626994951.5367239: {"feed":"book","product_id":"PI_XRPUSD","side":"sell","seq":3456343,"price":0.5892,"qty":6951.0,"timestamp":1626994951557}
1626994951.536812: {"feed":"book","product_id":"PI_XRPUSD","side":"sell","seq":3456344,"price":0.5891,"qty":8159.0,"timestamp":1626994951557}
1626994951.545759: {"feed":"book","product_id":"FI_XBTUSD_210924","side":"buy","seq":13502522,"price":32141.5,"qty":0.0,"timestamp":1626994951566}
1626994951.5458822: {"feed":"book","product_id":"FI_XBTUSD_210924","side":"buy","seq":13502523,"price":32142.0,"qty":5800.0,"timestamp":1626994951566}
1626994951.548129: {"feed":"book","product_id":"PI_ETHUSD","side":"buy","seq":26663550,"price":2003.0,"qty":3100.0,"timestamp":1626994951568}
1626994951.548237: {"feed":"book","product_id":"PI_ETHUSD","side":"sell","seq":26663551,"price":2005.1,"qty":13124.0,"timestamp":1626994951568}
1626994951.548286: {"feed":"book","product_id":"FI_ETHUSD_211231","side":"sell","seq":2199214,"price":2032.65,"qty":0.0,"timestamp":1626994951568}
1626994951.548348: {"feed":"book","product_id":"FI_ETHUSD_211231","side":"sell","seq":2199215,"price":2032.6,"qty":470.0,"timestamp":1626994951568}
1626994951.5510242: {"feed":"book","product_id":"PI_ETHUSD","side":"sell","seq":26663552,"price":2005.55,"qty":5000.0,"timestamp":1626994951571}
1626994951.551147: {"feed":"book","product_id":"PI_ETHUSD","side":"buy","seq":26663553,"price":2002.4,"qty":5000.0,"timestamp":1626994951571}
1626994951.55643: {"feed":"book","product_id":"PI_ETHUSD","side":"buy","seq":26663554,"price":2002.15,"qty":3915.0,"timestamp":1626994951576}
1626994951.5606542: {"feed":"book","product_id":"PI_ETHUSD","side":"sell","seq":26663555,"price":2004.35,"qty":0.0,"timestamp":1626994951581}
1626994951.561161: {"feed":"book","product_id":"PI_ETHUSD","side":"sell","seq":26663556,"price":2005.3,"qty":61.0,"timestamp":1626994951582}
1626994951.563898: {"feed":"book","product_id":"PI_ETHUSD","side":"sell","seq":26663557,"price":2005.35,"qty":18525.0,"timestamp":1626994951584}
1626994951.564427: {"feed":"book","product_id":"FI_XBTUSD_210924","side":"buy","seq":13502524,"price":32195.5,"qty":0.0,"timestamp":1626994951585}
1626994951.564521: {"feed":"book","product_id":"FI_XBTUSD_210924","side":"buy","seq":13502525,"price":32188.5,"qty":16707.0,"timestamp":1626994951585}
1626994951.5663202: {"feed":"book","product_id":"FI_XBTUSD_210924","side":"sell","seq":13502526,"price":32236.0,"qty":0.0,"timestamp":1626994951586}
1626994951.566442: {"feed":"book","product_id":"FI_XBTUSD_210924","side":"sell","seq":13502527,"price":32232.5,"qty":15088.0,"timestamp":1626994951586}
1626994951.566505: {"feed":"book","product_id":"FI_XBTUSD_210924","side":"buy","seq":13502528,"price":32166.0,"qty":0.0,"timestamp":1626994951586}
1626994951.566558: {"feed":"book","product_id":"FI_XBTUSD_210924","side":"buy","seq":13502529,"price":32166.0,"qty":20900.0,"timestamp":1626994951586}
1626994951.5665998: {"feed":"book","product_id":"FI_XBTUSD_210924","side":"sell","seq":13502530,"price":32258.5,"qty":0.0,"timestamp":1626994951586}
1626994951.5666418: {"feed":"book","product_id":"FI_XBTUSD_210924","side":"sell","seq":13502531,"price":32258.5,"qty":20957.0,"timestamp":1626994951586}
1626994951.5683122: {"feed":"book","product_id":"FI_XBTUSD_210924","side":"buy","seq":13502532,"price":32142.0,"qty":4300.0,"timestamp":1626994951589}
1626994951.5684: {"feed":"book","product_id":"FI_XBTUSD_210924","side":"buy","seq":13502533,"price":32141.5,"qty":1500.0,"timestamp":1626994951589}
1626994951.568442: {"feed":"book","product_id":"FI_XBTUSD_210924","side":"sell","seq":13502534,"price":32238.5,"qty":0.0,"timestamp":1626994951589}
1626994951.56848: {"feed":"book","product_id":"FI_XBTUSD_210924","side":"sell","seq":13502535,"price":32237.5,"qty":20000.0,"timestamp":1626994951589}
1626994951.572868: {"feed":"book","product_id":"PI_ETHUSD","side":"sell","seq":26663558,"price":2005.4,"qty":60771.0,"timestamp":1626994951593}
1626994951.572974: {"feed":"book","product_id":"FI_XBTUSD_210924","side":"sell","seq":13502536,"price":32233.0,"qty":28009.0,"timestamp":1626994951594}
1626994951.573025: {"feed":"book","product_id":"FI_XBTUSD_210924","side":"sell","seq":13502537,"price":32232.0,"qty":1.0,"timestamp":1626994951594}
1626994951.575705: {"feed":"book","product_id":"PI_ETHUSD","side":"buy","seq":26663559,"price":2002.1,"qty":4947.0,"timestamp":1626994951596}
1626994951.5799282: {"feed":"book","product_id":"FI_XBTUSD_210730","side":"sell","seq":5160277,"price":32208.0,"qty":0.0,"timestamp":1626994951601}
1626994951.58005: {"feed":"book","product_id":"FI_XBTUSD_210730","side":"sell","seq":5160278,"price":32206.5,"qty":1.0,"timestamp":1626994951601}
1626994951.586405: {"feed":"book","product_id":"PI_ETHUSD","side":"buy","seq":26663560,"price":2002.45,"qty":7746.0,"timestamp":1626994951607}
1626994951.586518: {"feed":"book","product_id":"PI_ETHUSD","side":"buy","seq":26663561,"price":2002.35,"qty":0.0,"timestamp":1626994951607}
1626994951.5869792: {"feed":"book","product_id":"FI_XBTUSD_210924","side":"buy","seq":13502538,"price":32161.5,"qty":0.0,"timestamp":1626994951608}
1626994951.589813: {"feed":"book","product_id":"PI_ETHUSD","side":"sell","seq":26663562,"price":2004.55,"qty":1518.0,"timestamp":1626994951610}
1626994951.589938: {"feed":"book","product_id":"PI_ETHUSD","side":"buy","seq":26663563,"price":2003.3,"qty":1503.0,"timestamp":1626994951611}
1626994951.5930712: {"feed":"book","product_id":"PI_ETHUSD","side":"sell","seq":26663564,"price":2005.4,"qty":59239.0,"timestamp":1626994951614}
1626994951.593179: {"feed":"book","product_id":"PI_ETHUSD","side":"sell","seq":26663565,"price":2005.35,"qty":5971.0,"timestamp":1626994951614}
1626994951.6178071: {"feed":"book","product_id":"PI_ETHUSD","side":"buy","seq":26663566,"price":1999.9,"qty":8509.0,"timestamp":1626994951638}
1626994951.6179168: {"feed":"book","product_id":"PI_ETHUSD","side":"buy","seq":26663567,"price":2000.35,"qty":275638.0,"timestamp":1626994951638}
1626994951.617965: {"feed":"book","product_id":"FI_XBTUSD_210924","side":"buy","seq":13502539,"price":32157.5,"qty":3000.0,"timestamp":1626994951638}
1626994951.618019: {"feed":"book","product_id":"FI_XBTUSD_210924","side":"buy","seq":13502540,"price":32072.5,"qty":18973.0,"timestamp":1626994951638}
1626994951.618061: {"feed":"book","product_id":"FI_XBTUSD_210924","side":"buy","seq":13502541,"price":32030.5,"qty":18973.0,"timestamp":1626994951638}
1626994951.618484: {"feed":"book","product_id":"PI_ETHUSD","side":"buy","seq":26663568,"price":2003.0,"qty":600.0,"timestamp":1626994951639}
1626994951.626902: {"feed":"book","product_id":"PI_ETHUSD","side":"buy","seq":26663569,"price":2001.8,"qty":85949.0,"timestamp":1626994951647}
1626994951.637883: {"feed":"book","product_id":"PI_ETHUSD","side":"buy","seq":26663570,"price":2002.4,"qty":0.0,"timestamp":1626994951658}
1626994951.655684: {"feed":"book","product_id":"PI_ETHUSD","side":"buy","seq":26663571,"price":2001.85,"qty":9723.0,"timestamp":1626994951672}
1626994951.65579: {"feed":"book","product_id":"PI_ETHUSD","side":"buy","seq":26663572,"price":2001.35,"qty":16359.0,"timestamp":1626994951672}
1626994951.6558368: {"feed":"book","product_id":"PI_ETHUSD","side":"buy","seq":26663573,"price":2000.05,"qty":0.0,"timestamp":1626994951672}
1626994951.6558971: {"feed":"book","product_id":"PI_ETHUSD","side":"buy","seq":26663574,"price":1999.65,"qty":24053.0,"timestamp":1626994951672}
1626994951.655945: {"feed":"book","product_id":"PI_ETHUSD","side":"buy","seq":26663575,"price":2002.95,"qty":4009.0,"timestamp":1626994951677}
1626994951.658394: {"feed":"book","product_id":"FI_XBTUSD_210924","side":"sell","seq":13502542,"price":32248.5,"qty":3000.0,"timestamp":1626994951678}
1626994951.6585228: {"feed":"book","product_id":"FI_XBTUSD_210924","side":"buy","seq":13502543,"price":32162.5,"qty":3000.0,"timestamp":1626994951678}
1626994951.658582: {"feed":"book","product_id":"FI_XBTUSD_210924","side":"sell","seq":13502544,"price":32276.5,"qty":16110.0,"timestamp":1626994951678}
1626994951.6586292: {"feed":"book","product_id":"FI_XBTUSD_210924","side":"buy","seq":13502545,"price":32134.5,"qty":20865.0,"timestamp":1626994951678}
1626994951.658669: {"feed":"book","product_id":"FI_XBTUSD_210924","side":"sell","seq":13502546,"price":32305.0,"qty":16110.0,"timestamp":1626994951679}
1626994951.6619751: {"feed":"book","product_id":"FI_XBTUSD_210924","side":"sell","seq":13502547,"price":32378.0,"qty":0.0,"timestamp":1626994951683}
1626994951.662548: {"feed":"book","product_id":"PI_ETHUSD","side":"sell","seq":26663576,"price":2005.35,"qty":18525.0,"timestamp":1626994951684}
1626994951.670974: {"feed":"book","product_id":"PI_ETHUSD","side":"sell","seq":26663577,"price":2005.35,"qty":5971.0,"timestamp":1626994951690}
1626994951.6806479: {"feed":"book","product_id":"FI_XBTUSD_210924","side":"sell","seq":13502548,"price":32245.5,"qty":0.0,"timestamp":1626994951700}
1626994951.6858912: {"feed":"book","product_id":"PI_LTCUSD","side":"sell","seq":3423380,"price":119.58,"qty":0.0,"timestamp":1626994951706}
1626994951.6880069: {"feed":"book","product_id":"PI_ETHUSD","side":"sell","seq":26663578,"price":2006.5,"qty":4009.0,"timestamp":1626994951708}
1626994951.7042801: {"feed":"book","product_id":"FI_ETHUSD_211231","side":"sell","seq":2199216,"price":2048.1,"qty":44305.0,"timestamp":1626994951725}
1626994951.7043881: {"feed":"book","product_id":"FI_ETHUSD_211231","side":"sell","seq":2199217,"price":2048.0,"qty":45099.0,"timestamp":1626994951725}
1626994951.704452: {"feed":"book","product_id":"FI_ETHUSD_211231","side":"sell","seq":2199218,"price":2048.1,"qty":0.0,"timestamp":1626994951725}
1626994951.7045078: {"feed":"book","product_id":"FI_ETHUSD_211231","side":"sell","seq":2199219,"price":2048.0,"qty":89404.0,"timestamp":1626994951725}
1626994951.717149: {"feed":"book","product_id":"PI_ETHUSD","side":"buy","seq":26663579,"price":2002.1,"qty":0.0,"timestamp":1626994951736}
1626994951.7245922: {"feed":"book","product_id":"PI_ETHUSD","side":"buy","seq":26663580,"price":2002.6,"qty":3818.0,"timestamp":1626994951744}
1626994951.725179: {"feed":"book","product_id":"PI_ETHUSD","side":"sell","seq":26663581,"price":2005.85,"qty":14079.0,"timestamp":1626994951745}
1626994951.7290082: {"feed":"book","product_id":"PI_ETHUSD","side":"buy","seq":26663582,"price":2002.65,"qty":9181.0,"timestamp":1626994951748}
1626994951.7291148: {"feed":"book","product_id":"PI_ETHUSD","side":"buy","seq":26663583,"price":2003.3,"qty":4003.0,"timestamp":1626994951749}
1626994951.731043: {"feed":"book","product_id":"PI_ETHUSD","side":"buy","seq":26663584,"price":2002.15,"qty":8489.0,"timestamp":1626994951751}
1626994951.74464: {"feed":"book","product_id":"PI_ETHUSD","side":"sell","seq":26663585,"price":2005.4,"qty":55378.0,"timestamp":1626994951765}
1626994951.772916: {"feed":"book","product_id":"FI_XBTUSD_210924","side":"buy","seq":13502549,"price":32166.0,"qty":0.0,"timestamp":1626994951790}
1626994951.773045: {"feed":"book","product_id":"FI_XBTUSD_210924","side":"buy","seq":13502550,"price":32154.0,"qty":20899.0,"timestamp":1626994951790}
1626994951.773119: {"feed":"book","product_id":"FI_XBTUSD_210924","side":"buy","seq":13502551,"price":32188.5,"qty":1080.0,"timestamp":1626994951790}
1626994951.77318: {"feed":"book","product_id":"FI_XBTUSD_210924","side":"buy","seq":13502552,"price":32188.5,"qty":16136.0,"timestamp":1626994951790}
1626994951.773203: {"feed":"book","product_id":"FI_XBTUSD_210924","side":"sell","seq":13502553,"price":32232.5,"qty":0.0,"timestamp":1626994951790}
1626994951.773233: {"feed":"book","product_id":"FI_XBTUSD_210924","side":"sell","seq":13502554,"price":32232.5,"qty":15661.0,"timestamp":1626994951790}
1626994951.77326: {"feed":"book","product_id":"FI_XBTUSD_210924","side":"sell","seq":13502555,"price":32258.5,"qty":0.0,"timestamp":1626994951790}
1626994951.7732868: {"feed":"book","product_id":"FI_XBTUSD_210924","side":"sell","seq":13502556,"price":32258.5,"qty":20955.0,"timestamp":1626994951790}
1626994951.7955468: {"feed":"book","product_id":"PI_ETHUSD","side":"sell","seq":26663586,"price":2005.9,"qty":0.0,"timestamp":1626994951816}
1626994951.8047009: {"feed":"book","product_id":"PI_ETHUSD","side":"buy","seq":26663587,"price":2001.95,"qty":0.0,"timestamp":1626994951823}
1626994951.804831: {"feed":"book","product_id":"PI_ETHUSD","side":"buy","seq":26663588,"price":2002.55,"qty":20000.0,"timestamp":1626994951823}
1626994951.804896: {"feed":"book","product_id":"PI_ETHUSD","side":"buy","seq":26663589,"price":2002.0,"qty":3989.0,"timestamp":1626994951823}
1626994951.804938: {"feed":"book","product_id":"PI_ETHUSD","side":"buy","seq":26663590,"price":2002.6,"qty":19644.0,"timestamp":1626994951823}
1626994951.807636: {"feed":"book","product_id":"PI_ETHUSD","side":"buy","seq":26663591,"price":2000.35,"qty":125638.0,"timestamp":1626994951827}
1626994951.807759: {"feed":"book","product_id":"PI_ETHUSD","side":"buy","seq":26663592,"price":2000.8,"qty":150063.0,"timestamp":1626994951827}
1626994951.8121002: {"feed":"book","product_id":"PI_ETHUSD","side":"sell","seq":26663593,"price":2005.1,"qty":10624.0,"timestamp":1626994951832}
1626994951.832584: {"feed":"book","product_id":"PI_XRPUSD","side":"sell","seq":3456345,"price":0.589,"qty":4072.0,"timestamp":1626994951853}
1626994951.844453: {"feed":"book","product_id":"FI_XBTUSD_210730","side":"sell","seq":5160279,"price":32207.5,"qty":0.0,"timestamp":1626994951863}
1626994951.8445911: {"feed":"book","product_id":"FI_XBTUSD_210730","side":"sell","seq":5160280,"price":32215.0,"qty":0.0,"timestamp":1626994951863}
1626994951.8486679: {"feed":"book","product_id":"PI_LTCUSD","side":"sell","seq":3423381,"price":119.56,"qty":0.0,"timestamp":1626994951868}
1626994951.84879: {"feed":"book","product_id":"PI_LTCUSD","side":"buy","seq":3423382,"price":119.16,"qty":1792.0,"timestamp":1626994951868}
1626994951.852: {"feed":"book","product_id":"FI_XBTUSD_210924","side":"buy","seq":13502557,"price":32149.0,"qty":983.0,"timestamp":1626994951872}
1626994951.852121: {"feed":"book","product_id":"PI_XRPUSD","side":"sell","seq":3456346,"price":0.5887,"qty":1578.0,"timestamp":1626994951872}
1626994951.8563042: {"feed":"book","product_id":"PI_ETHUSD","side":"buy","seq":26663594,"price":1999.65,"qty":0.0,"timestamp":1626994951876}
1626994951.85643: {"feed":"book","product_id":"PI_ETHUSD","side":"buy","seq":26663595,"price":1999.95,"qty":22748.0,"timestamp":1626994951876}
1626994951.871042: {"feed":"book","product_id":"FI_ETHUSD_211231","side":"sell","seq":2199220,"price":2032.9,"qty":0.0,"timestamp":1626994951890}
1626994951.888282: {"feed":"book","product_id":"PI_XRPUSD","side":"buy","seq":3456347,"price":0.5877,"qty":9113.0,"timestamp":1626994951907}
1626994951.8883898: {"feed":"book","product_id":"PI_XRPUSD","side":"buy","seq":3456348,"price":0.5876,"qty":22912.0,"timestamp":1626994951908}
1626994951.888909: {"feed":"book","product_id":"PI_LTCUSD","side":"sell","seq":3423383,"price":119.61,"qty":3901.0,"timestamp":1626994951910}
1626994951.88896: {"feed":"book","product_id":"FI_XBTUSD_210730","side":"sell","seq":5160281,"price":32206.5,"qty":0.0,"timestamp":1626994951910}
1626994951.889003: {"feed":"book","product_id":"FI_XBTUSD_210730","side":"sell","seq":5160282,"price":32205.5,"qty":1.0,"timestamp":1626994951910}
1626994951.9030411: {"feed":"book","product_id":"FI_ETHUSD_210730","side":"sell","seq":2138874,"price":2003.6,"qty":0.0,"timestamp":1626994951923}
1626994951.940481: {"feed":"book","product_id":"FI_XBTUSD_210924","side":"buy","seq":13502558,"price":32178.0,"qty":6900.0,"timestamp":1626994951961}
1626994951.940589: {"feed":"book","product_id":"FI_XBTUSD_210924","side":"sell","seq":13502559,"price":32243.0,"qty":5000.0,"timestamp":1626994951961}
1626994951.954378: {"feed":"book","product_id":"FI_XBTUSD_210730","side":"sell","seq":5160283,"price":32205.5,"qty":0.0,"timestamp":1626994951974}
1626994951.9545012: {"feed":"book","product_id":"FI_XBTUSD_210730","side":"sell","seq":5160284,"price":32206.5,"qty":1.0,"timestamp":1626994951974}
1626994951.974344: {"feed":"book","product_id":"FI_XBTUSD_210924","side":"buy","seq":13502560,"price":32154.0,"qty":0.0,"timestamp":1626994951993}
1626994951.974466: {"feed":"book","product_id":"FI_XBTUSD_210924","side":"buy","seq":13502561,"price":32166.0,"qty":20899.0,"timestamp":1626994951993}
1626994951.9959948: {"feed":"book","product_id":"PI_ETHUSD","side":"buy","seq":26663596,"price":2002.55,"qty":0.0,"timestamp":1626994952015}
1626994951.99612: {"feed":"book","product_id":"PI_ETHUSD","side":"buy","seq":26663597,"price":2002.65,"qty":29181.0,"timestamp":1626994952015}
1626994951.996175: {"feed":"book","product_id":"PI_ETHUSD","side":"buy","seq":26663598,"price":2002.6,"qty":3818.0,"timestamp":1626994952016}
1626994951.996216: {"feed":"book","product_id":"PI_ETHUSD","side":"buy","seq":26663599,"price":2002.7,"qty":15826.0,"timestamp":1626994952016}
1626994952.042134: {"feed":"book","product_id":"PI_ETHUSD","side":"buy","seq":26663600,"price":2002.65,"qty":9181.0,"timestamp":1626994952062}
1626994952.042249: {"feed":"book","product_id":"PI_ETHUSD","side":"buy","seq":26663601,"price":2002.55,"qty":20000.0,"timestamp":1626994952062}
1626994952.042312: {"feed":"book","product_id":"PI_ETHUSD","side":"buy","seq":26663602,"price":2002.7,"qty":0.0,"timestamp":1626994952062}
1626994952.042368: {"feed":"book","product_id":"PI_ETHUSD","side":"buy","seq":26663603,"price":2002.6,"qty":19644.0,"timestamp":1626994952062}
1626994952.054059: {"feed":"book","product_id":"FI_XRPUSD_210924","side":"sell","seq":602310,"price":0.5866,"qty":0.0,"timestamp":1626994952075}
1626994952.0541859: {"feed":"book","product_id":"FI_XRPUSD_210924","side":"buy","seq":602311,"price":0.583,"qty":60.0,"timestamp":1626994952075}
