wss://futures.kraken.com/ws/v1 <- 1626994927.582819: {"event":"subscribe","feed":"book","product_ids":["fi_ethusd_211231","pi_xrpusd","pi_ltcusd","fi_bchusd_210730","pi_ethusd","fi_xbtusd_210924","fi_ethusd_210730","fi_bchusd_210924","fi_xrpusd_210924","fi_xbtusd_210730"]}
1626994927.6892228: {"event":"subscribed","feed":"book","product_ids":["FI_ETHUSD_211231"]}
1626994927.6892538: {"event":"subscribed","feed":"book","product_ids":["PI_XRPUSD"]}
1626994927.689264: {"event":"subscribed","feed":"book","product_ids":["PI_LTCUSD"]}
1626994927.6892722: {"event":"subscribed","feed":"book","product_ids":["FI_BCHUSD_210730"]}
1626994927.68928: {"event":"subscribed","feed":"book","product_ids":["PI_ETHUSD"]}
1626994927.689287: {"event":"subscribed","feed":"book","product_ids":["FI_XBTUSD_210924"]}
1626994927.6892931: {"event":"subscribed","feed":"book","product_ids":["FI_ETHUSD_210730"]}
1626994927.6893: {"event":"subscribed","feed":"book","product_ids":["FI_BCHUSD_210924"]}
1626994927.689307: {"event":"subscribed","feed":"book","product_ids":["FI_XRPUSD_210924"]}
1626994927.689313: {"event":"subscribed","feed":"book","product_ids":["FI_XBTUSD_210730"]}
1626994927.690547: {"feed":"book_snapshot","product_id":"FI_BCHUSD_210730","timestamp":1626994925378,"seq":91192,"tickSize":null,"bids":[{"price":439.3,"qty":20108.0},{"price":438.9,"qty":23706.0},{"price":438.5,"qty":30511.0},{"price":438.0,"qty":33349.0},{"price":435.5,"qty":7954.0},{"price":434.7,"qty":79088.0},{"price":434.2,"qty":40266.0},{"price":433.4,"qty":4794.0},{"price":433.2,"qty":40841.0},{"price":431.8,"qty":48120.0},{"price":423.6,"qty":23755.0}],"asks":[{"price":439.6,"qty":50.0},{"price":439.9,"qty":21692.0},{"price":440.2,"qty":7954.0},{"price":440.3,"qty":24200.0},{"price":440.7,"qty":18940.0},{"price":443.2,"qty":78441.0},{"price":443.6,"qty":39149.0},{"price":443.7,"qty":4872.0},{"price":444.3,"qty":40026.0},{"price":444.5,"qty":24521.0},{"price":445.6,"qty":24584.0},{"price":453.1,"qty":23452.0}]}
1626994927.690798: {"feed":"book_snapshot","product_id":"FI_XBTUSD_210730","timestamp":1626994927654,"seq":5159966,"tickSize":null,"bids":[{"price":32170.5,"qty":1200.0},{"price":32170.0,"qty":130775.0},{"price":32159.0,"qty":50.0},{"price":32157.0,"qty":30000.0},{"price":32152.0,"qty":4688.0},{"price":32151.0,"qty":122259.0},{"price":32136.0,"qty":644.0},{"price":32135.0,"qty":266701.0},{"price":32128.5,"qty":547.0},{"price":32121.5,"qty":1500.0},{"price":32120.0,"qty":618.0},{"price":32112.5,"qty":2894.0},{"price":32111.0,"qty":263464.0},{"price":32100.5,"qty":6400.0},{"price":32098.0,"qty":250001.0},{"price":32097.5,"qty":60000.0},{"price":32091.0,"qty":271424.0},{"price":32052.0,"qty":800.0},{"price":32051.5,"qty":120000.0},{"price":32030.5,"qty":250002.0},{"price":32030.0,"qty":240000.0},{"price":32016.5,"qty":14850.0},{"price":32000.5,"qty":77164.0},{"price":31993.5,"qty":40144.0},{"price":31952.0,"qty":75648.0},{"price":31930.5,"qty":73843.0},{"price":31690.0,"qty":44296.0},{"price":31654.0,"qty":45792.0},{"price":31514.0,"qty":11000.0},{"price":31412.0,"qty":44644.0},{"price":30833.0,"qty":22000.0},{"price":30152.0,"qty":44000.0},{"price":29601.0,"qty":202269.0},{"price":21222.5,"qty":203321.0},{"price":18420.0,"qty":61000.0}],"asks":[{"price":32192.5,"qty":1200.0},{"price":32200.5,"qty":251.0},{"price":32201.0,"qty":163931.0},{"price":32206.5,"qty":30000.0},{"price":32219.5,"qty":149559.0},{"price":32235.5,"qty":60000.0},{"price":32237.5,"qty":146744.0},{"price":32243.0,"qty":512.0},{"price":32254.0,"qty":2400.0},{"price":32259.0,"qty":250001.0},{"price":32259.5,"qty":257216.0},{"price":32264.5,"qty":4688.0},{"price":32267.5,"qty":14850.0},{"price":32277.5,"qty":6400.0},{"price":32278.0,"qty":120000.0},{"price":32297.5,"qty":51206.0},{"price":32349.0,"qty":250002.0},{"price":32349.5,"qty":240000.0},{"price":32416.5,"qty":75820.0},{"price":32429.0,"qty":77140.0},{"price":32517.5,"qty":72789.0},{"price":32550.0,"qty":10000.0},{"price":32620.0,"qty":43854.0},{"price":32851.0,"qty":43723.0},{"price":33306.0,"qty":46342.0},{"price":35700.0,"qty":130.0},{"price":79000.0,"qty":250000.0}]}
1626994927.780458: {"feed":"book_snapshot","product_id":"FI_XBTUSD_210924","timestamp":1626994927655,"seq":13501560,"tickSize":null,"bids":[{"price":32189.5,"qty":1130.0},{"price":32188.5,"qty":15741.0},{"price":32188.0,"qty":168386.0},{"price":32181.5,"qty":3000.0},{"price":32180.0,"qty":3639.0},{"price":32177.5,"qty":27000.0},{"price":32176.5,"qty":1900.0},{"price":32174.5,"qty":10198.0},{"price":32171.5,"qty":8000.0},{"price":32168.0,"qty":1079.0},{"price":32165.5,"qty":211781.0},{"price":32161.5,"qty":3000.0},{"price":32161.0,"qty":1000.0},{"price":32155.5,"qty":3000.0},{"price":32155.0,"qty":3000.0},{"price":32154.0,"qty":1900.0},{"price":32153.0,"qty":20901.0},{"price":32152.5,"qty":10000.0},{"price":32150.5,"qty":789.0},{"price":32147.0,"qty":3000.0},{"price":32145.0,"qty":19460.0},{"price":32142.5,"qty":5000.0},{"price":32141.5,"qty":1500.0},{"price":32139.5,"qty":3908.0},{"price":32133.5,"qty":2400.0},{"price":32130.0,"qty":250001.0},{"price":32129.5,"qty":303499.0},{"price":32127.5,"qty":20865.0},{"price":32117.5,"qty":6400.0},{"price":32116.5,"qty":1900.0},{"price":32115.0,"qty":26093.0},{"price":32112.5,"qty":18960.0},{"price":32110.0,"qty":54000.0},{"price":32102.0,"qty":100.0},{"price":32100.5,"qty":21665.0},{"price":32097.5,"qty":260321.0},{"price":32079.5,"qty":102974.0},{"price":32077.5,"qty":26093.0},{"price":32068.5,"qty":18960.0},{"price":32040.0,"qty":26093.0},{"price":32039.5,"qty":250002.0},{"price":32039.0,"qty":108000.0},{"price":32029.0,"qty":18960.0},{"price":32018.5,"qty":216000.0},{"price":32016.0,"qty":101572.0},{"price":32000.0,"qty":200.0},{"price":31995.0,"qty":99286.0},{"price":31936.0,"qty":25261.0},{"price":31933.5,"qty":25263.0},{"price":31895.5,"qty":23526.0},{"price":31889.0,"qty":58696.0},{"price":31740.5,"qty":58990.0},{"price":31616.0,"qty":5000.0},{"price":31605.0,"qty":356.0},{"price":31498.0,"qty":60614.0},{"price":31039.0,"qty":31000.0},{"price":30935.0,"qty":10000.0},{"price":30924.0,"qty":712.0},{"price":30895.0,"qty":250.0},{"price":30885.0,"qty":30000.0},{"price":30254.0,"qty":20000.0},{"price":30243.0,"qty":1424.0},{"price":30025.0,"qty":2500.0},{"price":29901.0,"qty":12500.0},{"price":29200.0,"qty":21.0},{"price":29100.0,"qty":5000.0},{"price":29022.5,"qty":2000.0},{"price":29014.0,"qty":20000.0},{"price":29000.0,"qty":55000.0},{"price":28977.0,"qty":100.0},{"price":28900.0,"qty":5000.0},{"price":28800.0,"qty":5000.0},{"price":28751.0,"qty":5000.0},{"price":28500.0,"qty":250000.0},{"price":28343.0,"qty":2100.0},{"price":28000.0,"qty":5000.0},{"price":27875.0,"qty":5000.0},{"price":27123.0,"qty":25000.0},{"price":27068.0,"qty":200.0},{"price":27000.0,"qty":27100.0},{"price":26000.0,"qty":50100.0},{"price":25200.0,"qty":250000.0},{"price":25000.0,"qty":100.0},{"price":24475.0,"qty":60000.0},{"price":24000.0,"qty":5100.0},{"price":23969.0,"qty":500.0},{"price":23475.0,"qty":60000.0},{"price":21788.5,"qty":60000.0},{"price":20669.0,"qty":500.0},{"price":20420.0,"qty":65000.0},{"price":20000.0,"qty":10001.0},{"price":19475.0,"qty":160000.0},{"price":18000.0,"qty":10000.0},{"price":16915.5,"qty":100000.0},{"price":16501.0,"qty":1000.0},{"price":15000.0,"qty":208200.0},{"price":14555.0,"qty":1000.0},{"price":9888.0,"qty":1000000.0}],"asks":[{"price":32221.0,"qty":1009.0},{"price":32223.5,"qty":251.0},{"price":32228.0,"qty":943.0},{"price":32234.0,"qty":2430.0},{"price":32235.5,"qty":16638.0},{"price":32236.0,"qty":141173.0},{"price":32237.5,"qty":5000.0},{"price":32238.0,"qty":27000.0},{"price":32240.5,"qty":3000.0},{"price":32245.0,"qty":10000.0},{"price":32252.5,"qty":5000.0},{"price":32258.5,"qty":23958.0},{"price":32259.0,"qty":159260.0},{"price":32265.0,"qty":1000.0},{"price":32269.5,"qty":16095.0},{"price":32270.0,"qty":20000.0},{"price":32277.5,"qty":2430.0},{"price":32280.5,"qty":250001.0},{"price":32281.0,"qty":23267.0},{"price":32282.0,"qty":146559.0},{"price":32284.5,"qty":3000.0},{"price":32290.5,"qty":54000.0},{"price":32296.5,"qty":2430.0},{"price":32298.0,"qty":22495.0},{"price":32300.0,"qty":3000.0},{"price":32303.5,"qty":100.0},{"price":32307.5,"qty":247018.0},{"price":32309.0,"qty":24909.0},{"price":32309.5,"qty":10198.0},{"price":32311.5,"qty":24907.0},{"price":32316.0,"qty":3000.0},{"price":32320.0,"qty":21667.0},{"price":32321.5,"qty":108000.0},{"price":32327.5,"qty":3000.0},{"price":32330.0,"qty":11613.0},{"price":32338.0,"qty":3000.0},{"price":32348.0,"qty":3000.0},{"price":32358.0,"qty":20866.0},{"price":32362.0,"qty":19460.0},{"price":32372.5,"qty":11613.0},{"price":32400.0,"qty":200.0},{"price":32415.0,"qty":11613.0},{"price":32418.0,"qty":250002.0},{"price":32418.5,"qty":216000.0},{"price":32432.0,"qty":99688.0},{"price":32439.0,"qty":33522.0},{"price":32464.0,"qty":97050.0},{"price":32501.5,"qty":101774.0},{"price":32750.0,"qty":30000.0},{"price":32791.0,"qty":59962.0},{"price":32794.0,"qty":50000.0},{"price":32890.0,"qty":30000.0},{"price":32927.5,"qty":61302.0},{"price":32990.0,"qty":30000.0},{"price":33170.0,"qty":58500.0},{"price":33300.0,"qty":2000.0},{"price":33755.0,"qty":2.0},{"price":33938.0,"qty":2.0},{"price":34112.0,"qty":2.0},{"price":34299.0,"qty":2.0},{"price":34609.5,"qty":2000.0},{"price":34995.0,"qty":30000.0},{"price":35574.0,"qty":2000.0},{"price":36010.0,"qty":2500.0},{"price":36291.0,"qty":2000.0},{"price":36425.0,"qty":2500.0},{"price":36952.0,"qty":10.0},{"price":37046.5,"qty":2500.0},{"price":37234.0,"qty":2000.0},{"price":37250.0,"qty":5000.0},{"price":37410.0,"qty":100.0},{"price":37550.0,"qty":5000.0},{"price":37650.0,"qty":5000.0},{"price":37750.0,"qty":5000.0},{"price":38077.5,"qty":2000.0},{"price":38400.0,"qty":20000.0},{"price":38418.0,"qty":200.0},{"price":38750.0,"qty":50000.0},{"price":38800.0,"qty":68400.0},{"price":39079.0,"qty":2000.0},{"price":39817.5,"qty":60050.0},{"price":39950.0,"qty":1000.0},{"price":40265.0,"qty":2000.0},{"price":40950.0,"qty":1000.0},{"price":41254.5,"qty":2000.0},{"price":41949.0,"qty":50.0},{"price":42000.0,"qty":15000.0},{"price":43500.0,"qty":5000.0},{"price":43900.0,"qty":5000.0},{"price":44000.0,"qty":1.0},{"price":44200.0,"qty":1.0},{"price":44817.5,"qty":90050.0},{"price":46491.5,"qty":50.0},{"price":46910.5,"qty":971.0},{"price":46950.0,"qty":50000.0},{"price":47150.0,"qty":50000.0},{"price":47234.0,"qty":100000.0},{"price":47500.0,"qty":2.0},{"price":48000.0,"qty":5000.0},{"price":50000.0,"qty":500.0},{"price":50611.0,"qty":4800.0},{"price":50999.0,"qty":4800.0},{"price":51371.0,"qty":4800.0},{"price":51385.0,"qty":50.0},{"price":51716.0,"qty":4800.0},{"price":51871.0,"qty":4800.0},{"price":52271.0,"qty":4800.0},{"price":52527.0,"qty":6000.0},{"price":52771.0,"qty":4800.0},{"price":53249.5,"qty":50.0},{"price":53271.0,"qty":6000.0},{"price":57468.5,"qty":800.0},{"price":59034.5,"qty":50.0},{"price":62423.5,"qty":50.0},{"price":63107.5,"qty":500.0},{"price":63400.0,"qty":225969.0},{"price":67137.5,"qty":1000.0},{"price":68000.0,"qty":1.0},{"price":70787.5,"qty":1500.0},{"price":79000.0,"qty":200000.0}]}
1626994927.865605: {"feed":"book_snapshot","product_id":"PI_XRPUSD","timestamp":1626994927035,"seq":3456139,"tickSize":null,"bids":[{"price":0.5881,"qty":320.0},{"price":0.588,"qty":17745.0},{"price":0.5879,"qty":4189.0},{"price":0.5878,"qty":19333.0},{"price":0.5877,"qty":9177.0},{"price":0.5876,"qty":6145.0},{"price":0.5875,"qty":5006.0},{"price":0.5874,"qty":10661.0},{"price":0.5873,"qty":14112.0},{"price":0.5872,"qty":13144.0},{"price":0.5871,"qty":1012.0},{"price":0.587,"qty":20000.0},{"price":0.5867,"qty":8024.0},{"price":0.5866,"qty":632.0},{"price":0.5863,"qty":3863.0},{"price":0.5862,"qty":3171.0},{"price":0.586,"qty":50000.0},{"price":0.5859,"qty":4058.0},{"price":0.5856,"qty":3911.0},{"price":0.5852,"qty":69176.0},{"price":0.5851,"qty":65932.0},{"price":0.5849,"qty":158599.0},{"price":0.5848,"qty":69453.0},{"price":0.5831,"qty":52499.0},{"price":0.5816,"qty":40154.0},{"price":0.58,"qty":502.0},{"price":0.5759,"qty":40747.0},{"price":0.575,"qty":1000.0},{"price":0.5721,"qty":41247.0},{"price":0.57,"qty":2000.0},{"price":0.5688,"qty":2.0},{"price":0.5681,"qty":2.0},{"price":0.5671,"qty":2.0},{"price":0.5667,"qty":2.0},{"price":0.5666,"qty":2.0},{"price":0.5665,"qty":2.0},{"price":0.5662,"qty":2.0},{"price":0.5654,"qty":2.0},{"price":0.565,"qty":50000.0},{"price":0.5645,"qty":2.0},{"price":0.5644,"qty":4.0},{"price":0.5638,"qty":2.0},{"price":0.5635,"qty":2.0},{"price":0.56,"qty":50002.0},{"price":0.5555,"qty":50000.0},{"price":0.554,"qty":140.0},{"price":0.55,"qty":150000.0},{"price":0.549,"qty":500.0},{"price":0.545,"qty":100.0},{"price":0.5425,"qty":7000.0},{"price":0.54,"qty":502.0},{"price":0.5326,"qty":500.0},{"price":0.525,"qty":250.0},{"price":0.52,"qty":252.0},{"price":0.5152,"qty":20.0},{"price":0.515,"qty":250.0},{"price":0.51,"qty":250.0},{"price":0.505,"qty":250.0},{"price":0.5,"qty":32559.0},{"price":0.495,"qty":250.0},{"price":0.494,"qty":500.0},{"price":0.49,"qty":250.0},{"price":0.4866,"qty":500.0},{"price":0.485,"qty":250.0},{"price":0.48,"qty":302.0},{"price":0.475,"qty":250.0},{"price":0.47,"qty":250.0},{"price":0.465,"qty":250.0},{"price":0.46,"qty":254.0},{"price":0.455,"qty":250.0},{"price":0.451,"qty":50.0},{"price":0.45,"qty":1450.0},{"price":0.4472,"qty":10.0},{"price":0.445,"qty":250.0},{"price":0.44,"qty":252.0},{"price":0.435,"qty":250.0},{"price":0.4321,"qty":100.0},{"price":0.43,"qty":250.0},{"price":0.425,"qty":10250.0},{"price":0.42,"qty":254.0},{"price":0.4157,"qty":100.0},{"price":0.415,"qty":250.0},{"price":0.41,"qty":250.0},{"price":0.405,"qty":250.0},{"price":0.401,"qty":50.0},{"price":0.4,"qty":552.0},{"price":0.395,"qty":250.0},{"price":0.39,"qty":260.0},{"price":0.385,"qty":250.0},{"price":0.38,"qty":1262.0},{"price":0.375,"qty":250.0},{"price":0.372,"qty":400.0},{"price":0.3709,"qty":1500.0},{"price":0.37,"qty":250.0},{"price":0.365,"qty":250.0},{"price":0.36,"qty":252.0},{"price":0.357,"qty":1000.0},{"price":0.355,"qty":250.0},{"price":0.351,"qty":50.0},{"price":0.35,"qty":20450.0},{"price":0.345,"qty":250.0},{"price":0.3433,"qty":1000.0},{"price":0.34,"qty":650.0},{"price":0.335,"qty":250.0},{"price":0.331,"qty":100.0},{"price":0.33,"qty":250.0},{"price":0.325,"qty":775.0},{"price":0.32,"qty":252.0},{"price":0.315,"qty":250.0},{"price":0.31,"qty":250.0},{"price":0.305,"qty":555.0},{"price":0.301,"qty":50.0},{"price":0.3,"qty":655.0},{"price":0.275,"qty":100.0},{"price":0.273,"qty":273.0},{"price":0.251,"qty":50.0},{"price":0.25,"qty":300.0},{"price":0.23,"qty":2100.0},{"price":0.225,"qty":100.0},{"price":0.215,"qty":100.0},{"price":0.21,"qty":20.0},{"price":0.201,"qty":50.0},{"price":0.2,"qty":151620.0},{"price":0.196,"qty":20.0},{"price":0.195,"qty":20.0},{"price":0.194,"qty":20.0},{"price":0.192,"qty":20.0},{"price":0.19,"qty":20.0},{"price":0.18,"qty":20.0},{"price":0.178,"qty":20.0},{"price":0.176,"qty":20.0},{"price":0.174,"qty":20.0},{"price":0.172,"qty":20.0},{"price":0.171,"qty":20.0},{"price":0.17,"qty":20.0},{"price":0.16,"qty":20.0},{"price":0.1597,"qty":160.0},{"price":0.1,"qty":100.0},{"price":0.085,"qty":250.0},{"price":0.0666,"qty":50.0}],"asks":[{"price":0.5888,"qty":320.0},{"price":0.5889,"qty":2.0},{"price":0.589,"qty":7941.0},{"price":0.5892,"qty":28716.0},{"price":0.5893,"qty":5571.0},{"price":0.5894,"qty":12719.0},{"price":0.5895,"qty":3997.0},{"price":0.5896,"qty":8816.0},{"price":0.5897,"qty":4942.0},{"price":0.5898,"qty":8891.0},{"price":0.5899,"qty":31174.0},{"price":0.59,"qty":3855.0},{"price":0.5904,"qty":12076.0},{"price":0.5905,"qty":13144.0},{"price":0.5906,"qty":50000.0},{"price":0.5907,"qty":3809.0},{"price":0.5912,"qty":125000.0},{"price":0.5915,"qty":33599.0},{"price":0.5923,"qty":68428.0},{"price":0.5929,"qty":67899.0},{"price":0.5934,"qty":52499.0},{"price":0.5937,"qty":2353.0},{"price":0.594,"qty":68586.0},{"price":0.6005,"qty":40119.0},{"price":0.6025,"qty":2000.0},{"price":0.6038,"qty":41358.0},{"price":0.6048,"qty":10.0},{"price":0.605,"qty":3000.0},{"price":0.6075,"qty":1000.0},{"price":0.61,"qty":1000.0},{"price":0.6161,"qty":41426.0},{"price":0.618,"qty":50.0},{"price":0.62,"qty":12.0},{"price":0.625,"qty":1000.0},{"price":0.6325,"qty":65.0},{"price":0.6355,"qty":50000.0},{"price":0.64,"qty":2.0},{"price":0.6411,"qty":25000.0},{"price":0.645,"qty":10.0},{"price":0.65,"qty":1000.0},{"price":0.6519,"qty":7000.0},{"price":0.66,"qty":2.0},{"price":0.675,"qty":500.0},{"price":0.6759,"qty":10.0},{"price":0.68,"qty":2.0},{"price":0.685,"qty":10.0},{"price":0.7,"qty":2002.0},{"price":0.7005,"qty":2000.0},{"price":0.71,"qty":10.0},{"price":0.72,"qty":2.0},{"price":0.74,"qty":2.0},{"price":0.745,"qty":10.0},{"price":0.75,"qty":1750.0},{"price":0.76,"qty":2.0},{"price":0.8,"qty":1375.0},{"price":0.81,"qty":3459.0},{"price":0.85,"qty":1000.0},{"price":0.9,"qty":1500.0},{"price":0.93,"qty":200.0},{"price":0.95,"qty":1000.0},{"price":0.985,"qty":10.0},{"price":1.0,"qty":1600.0},{"price":1.05,"qty":1000.0},{"price":1.066,"qty":100.0},{"price":1.09,"qty":200.0},{"price":1.1,"qty":1500.0},{"price":1.2,"qty":1100.0},{"price":1.214,"qty":100.0},{"price":1.225,"qty":5.0},{"price":1.3,"qty":1000.0},{"price":1.3425,"qty":400.0},{"price":1.45,"qty":240.0},{"price":1.495,"qty":5.0},{"price":1.65,"qty":100.0},{"price":1.7,"qty":2600.0},{"price":1.7155,"qty":5.0},{"price":1.8,"qty":200.0},{"price":1.85,"qty":100.0},{"price":1.9,"qty":4900.0},{"price":1.95,"qty":100.0},{"price":2.0,"qty":250.0},{"price":3.0,"qty":5050.0},{"price":3.5,"qty":30000.0},{"price":4.0,"qty":50.0},{"price":5.0,"qty":50.0},{"price":6.0,"qty":50.0},{"price":7.0,"qty":50.0},{"price":8.0,"qty":50.0},{"price":9.0,"qty":50.0},{"price":10.0,"qty":50.0},{"price":148.88,"qty":5000.0}]}
1626994927.866443: {"feed":"book_snapshot","product_id":"FI_ETHUSD_210730","timestamp":1626994927583,"seq":2138663,"tickSize":null,"bids":[{"price":2000.9,"qty":600.0},{"price":2000.85,"qty":102934.0},{"price":2000.25,"qty":15000.0},{"price":2000.0,"qty":50.0},{"price":1999.5,"qty":98537.0},{"price":1998.55,"qty":339.0},{"price":1998.15,"qty":91709.0},{"price":1997.75,"qty":273.0},{"price":1997.25,"qty":356.0},{"price":1996.9,"qty":30000.0},{"price":1996.65,"qty":250001.0},{"price":1996.6,"qty":177965.0},{"price":1996.45,"qty":2058.0},{"price":1995.45,"qty":221794.0},{"price":1993.45,"qty":15307.0},{"price":1992.35,"qty":60000.0},{"price":1991.45,"qty":23734.0},{"price":1991.25,"qty":250002.0},{"price":1991.2,"qty":44704.0},{"price":1989.7,"qty":120000.0},{"price":1987.45,"qty":153024.0},{"price":1985.8,"qty":74644.0},{"price":1973.8,"qty":29422.0},{"price":1972.45,"qty":29472.0},{"price":1959.15,"qty":29514.0}],"asks":[{"price":2002.75,"qty":600.0},{"price":2003.15,"qty":86023.0},{"price":2003.4,"qty":15000.0},{"price":2004.2,"qty":103685.0},{"price":2005.6,"qty":3800.0},{"price":2005.75,"qty":177061.0},{"price":2006.8,"qty":31200.0},{"price":2007.15,"qty":241845.0},{"price":2008.35,"qty":253201.0},{"price":2008.4,"qty":60000.0},{"price":2011.15,"qty":45421.0},{"price":2011.2,"qty":15707.0},{"price":2011.35,"qty":72991.0},{"price":2011.75,"qty":120000.0},{"price":2014.15,"qty":23526.0},{"price":2014.9,"qty":250002.0},{"price":2014.95,"qty":148258.0},{"price":2028.2,"qty":29973.0},{"price":2030.0,"qty":500.0},{"price":2040.0,"qty":500.0},{"price":2040.1,"qty":29379.0},{"price":2050.0,"qty":1000.0},{"price":2057.8,"qty":29515.0},{"price":2060.0,"qty":500.0},{"price":2070.0,"qty":500.0},{"price":2080.0,"qty":500.0},{"price":2090.0,"qty":500.0},{"price":2100.0,"qty":500.0}]}
1626994927.87009: {"feed":"book_snapshot","product_id":"PI_LTCUSD","timestamp":1626994927711,"seq":3423035,"tickSize":null,"bids":[{"price":119.31,"qty":320.0},{"price":119.3,"qty":900.0},{"price":119.29,"qty":7736.0},{"price":119.28,"qty":3994.0},{"price":119.26,"qty":3892.0},{"price":119.25,"qty":4221.0},{"price":119.24,"qty":8000.0},{"price":119.23,"qty":5097.0},{"price":119.22,"qty":36370.0},{"price":119.21,"qty":25508.0},{"price":119.19,"qty":3891.0},{"price":119.18,"qty":5561.0},{"price":119.17,"qty":4066.0},{"price":119.15,"qty":708.0},{"price":119.14,"qty":5007.0},{"price":119.13,"qty":2096.0},{"price":119.12,"qty":5974.0},{"price":119.11,"qty":65682.0},{"price":119.1,"qty":5008.0},{"price":119.09,"qty":659.0},{"price":119.08,"qty":16000.0},{"price":118.99,"qty":10531.0},{"price":118.98,"qty":53824.0},{"price":118.94,"qty":8055.0},{"price":118.87,"qty":32000.0},{"price":118.86,"qty":45924.0},{"price":118.79,"qty":58804.0},{"price":118.78,"qty":3992.0},{"price":118.69,"qty":19199.0},{"price":118.62,"qty":65200.0},{"price":118.6,"qty":53910.0},{"price":118.42,"qty":52951.0},{"price":118.3,"qty":29999.0},{"price":118.04,"qty":32101.0},{"price":117.53,"qty":1200.0},{"price":116.21,"qty":31709.0},{"price":115.15,"qty":33340.0},{"price":113.78,"qty":80.0},{"price":100.35,"qty":200.0},{"price":100.0,"qty":11123.0},{"price":99.0,"qty":100.0},{"price":96.5,"qty":200.0},{"price":92.98,"qty":200.0},{"price":91.0,"qty":3.0},{"price":90.0,"qty":100.0},{"price":89.0,"qty":3.0},{"price":88.97,"qty":200.0},{"price":88.0,"qty":4.0},{"price":87.0,"qty":4.0},{"price":86.0,"qty":3.0},{"price":85.97,"qty":200.0},{"price":83.0,"qty":300.0},{"price":82.0,"qty":100.0},{"price":81.0,"qty":100.0},{"price":80.0,"qty":203.0},{"price":79.5,"qty":50.0},{"price":78.97,"qty":200.0},{"price":73.97,"qty":200.0},{"price":73.0,"qty":3.0},{"price":71.0,"qty":3.0},{"price":70.0,"qty":100.0},{"price":69.0,"qty":150.0},{"price":65.27,"qty":200.0},{"price":63.0,"qty":50.0},{"price":62.63,"qty":100.0},{"price":62.46,"qty":200.0},{"price":60.0,"qty":100.0},{"price":59.0,"qty":1.0},{"price":57.63,"qty":100.0},{"price":55.7,"qty":1189.0},{"price":54.93,"qty":1113.0},{"price":53.16,"qty":1067.0},{"price":52.63,"qty":100.0},{"price":51.0,"qty":100.0},{"price":50.88,"qty":1020.0},{"price":50.0,"qty":200.0},{"price":49.78,"qty":1005.0},{"price":48.18,"qty":985.0},{"price":47.65,"qty":961.0},{"price":47.13,"qty":952.0},{"price":46.0,"qty":11.0},{"price":45.0,"qty":100.0},{"price":44.62,"qty":905.0},{"price":43.66,"qty":887.0},{"price":42.5,"qty":425.0},{"price":42.25,"qty":854.0},{"price":42.0,"qty":1000.0},{"price":41.79,"qty":842.0},{"price":41.33,"qty":835.0},{"price":41.0,"qty":410.0},{"price":40.88,"qty":823.0},{"price":40.0,"qty":650.0},{"price":30.0,"qty":135.0},{"price":20.0,"qty":100.0},{"price":10.0,"qty":100.0},{"price":0.01,"qty":117.0}],"asks":[{"price":119.42,"qty":320.0},{"price":119.48,"qty":8000.0},{"price":119.5,"qty":1062.0},{"price":119.54,"qty":12351.0},{"price":119.55,"qty":4989.0},{"price":119.56,"qty":6053.0},{"price":119.57,"qty":5337.0},{"price":119.58,"qty":27737.0},{"price":119.59,"qty":4988.0},{"price":119.6,"qty":7983.0},{"price":119.63,"qty":32596.0},{"price":119.67,"qty":11878.0},{"price":119.68,"qty":652.0},{"price":119.73,"qty":10531.0},{"price":119.74,"qty":4185.0},{"price":119.76,"qty":3972.0},{"price":119.77,"qty":34123.0},{"price":119.83,"qty":32000.0},{"price":119.9,"qty":64000.0},{"price":120.0,"qty":55362.0},{"price":120.03,"qty":19199.0},{"price":120.23,"qty":52436.0},{"price":120.32,"qty":52640.0},{"price":120.4,"qty":29999.0},{"price":120.41,"qty":2795.0},{"price":120.63,"qty":280.0},{"price":121.29,"qty":32117.0},{"price":122.23,"qty":1500.0},{"price":122.82,"qty":32246.0},{"price":123.95,"qty":31514.0},{"price":124.0,"qty":200.0},{"price":125.0,"qty":700.0},{"price":127.38,"qty":1000.0},{"price":129.88,"qty":500.0},{"price":132.48,"qty":500.0},{"price":135.0,"qty":1050.0},{"price":137.5,"qty":50.0},{"price":140.0,"qty":1050.0},{"price":142.5,"qty":50.0},{"price":145.0,"qty":1101.0},{"price":150.0,"qty":1075.0},{"price":155.0,"qty":75.0},{"price":156.8,"qty":300.0},{"price":160.0,"qty":1050.0},{"price":165.0,"qty":50.0},{"price":167.5,"qty":1000.0},{"price":170.0,"qty":50.0},{"price":175.0,"qty":1000.0},{"price":175.6,"qty":500.0},{"price":182.5,"qty":1000.0},{"price":190.0,"qty":1000.0},{"price":200.0,"qty":1000.0},{"price":206.0,"qty":120000.0},{"price":210.0,"qty":1000.0},{"price":214.81,"qty":500.0},{"price":218.05,"qty":25.0},{"price":220.0,"qty":1000.0},{"price":220.16,"qty":1000.0},{"price":224.0,"qty":70000.0},{"price":235.84,"qty":950.0},{"price":275.0,"qty":7500.0},{"price":288.88,"qty":20000.0},{"price":300.0,"qty":15000.0},{"price":302.0,"qty":299.0},{"price":309.41,"qty":50.0},{"price":321.0,"qty":300.0},{"price":330.0,"qty":15000.0},{"price":360.0,"qty":10000.0},{"price":400.0,"qty":15055.0},{"price":404.78,"qty":100.0},{"price":411.0,"qty":200.0},{"price":425.0,"qty":7500.0},{"price":450.0,"qty":2500.0},{"price":475.0,"qty":5000.0},{"price":500.0,"qty":5.0},{"price":800.0,"qty":20.0},{"price":4000.0,"qty":450.0},{"price":4900.0,"qty":21200.0},{"price":9999999.99,"qty":2000000.0}]}
1626994927.9524539: {"feed":"book_snapshot","product_id":"FI_BCHUSD_210924","timestamp":1626994926802,"seq":402227,"tickSize":null,"bids":[{"price":441.1,"qty":25401.0},{"price":440.6,"qty":21036.0},{"price":440.3,"qty":59.0},{"price":440.2,"qty":63.0},{"price":440.1,"qty":81.0},{"price":440.0,"qty":37757.0},{"price":439.3,"qty":38342.0},{"price":435.0,"qty":8055.0},{"price":434.9,"qty":39268.0},{"price":433.0,"qty":39715.0},{"price":432.8,"qty":40382.0},{"price":430.5,"qty":1284.0},{"price":429.7,"qty":23355.0},{"price":423.1,"qty":23692.0},{"price":418.7,"qty":23486.0},{"price":388.9,"qty":20.0},{"price":380.0,"qty":1500.0}],"asks":[{"price":441.8,"qty":50.0},{"price":441.9,"qty":8055.0},{"price":442.0,"qty":21552.0},{"price":442.5,"qty":26051.0},{"price":442.8,"qty":67.0},{"price":442.9,"qty":37303.0},{"price":446.3,"qty":1484.0},{"price":447.2,"qty":38906.0},{"price":448.2,"qty":40965.0},{"price":450.8,"qty":39370.0},{"price":454.1,"qty":24321.0},{"price":460.8,"qty":24336.0},{"price":465.2,"qty":24707.0},{"price":550.0,"qty":1200.0},{"price":700.0,"qty":50000.0}]}
1626994927.952589: {"feed":"book_snapshot","product_id":"FI_ETHUSD_211231","timestamp":1626994927583,"seq":2198963,"tickSize":null,"bids":[{"price":2028.9,"qty":420.0},{"price":2028.85,"qty":96340.0},{"price":2028.3,"qty":50.0},{"price":2027.7,"qty":10500.0},{"price":2027.25,"qty":120.0},{"price":2026.6,"qty":132.0},{"price":2026.3,"qty":99256.0},{"price":2026.2,"qty":2000.0},{"price":2025.95,"qty":146.0},{"price":2025.6,"qty":5000.0},{"price":2025.45,"qty":114.0},{"price":2025.2,"qty":757.0},{"price":2023.9,"qty":250001.0},{"price":2023.85,"qty":173114.0},{"price":2022.8,"qty":21000.0},{"price":2021.05,"qty":240466.0},{"price":2019.0,"qty":100.0},{"price":2017.5,"qty":8748.0},{"price":2017.45,"qty":196736.0},{"price":2015.85,"qty":42000.0},{"price":2013.15,"qty":84000.0},{"price":2009.8,"qty":45500.0},{"price":1994.9,"qty":45649.0},{"price":1987.0,"qty":45948.0},{"price":1965.4,"qty":27099.0},{"price":1964.6,"qty":27211.0},{"price":1949.0,"qty":3000.0},{"price":1944.1,"qty":26214.0},{"price":1925.0,"qty":1000.0},{"price":1922.0,"qty":2000.0},{"price":1912.0,"qty":50000.0},{"price":1880.0,"qty":500.0},{"price":1869.0,"qty":2000.0},{"price":1794.4,"qty":57000.0},{"price":1725.0,"qty":180.0},{"price":1710.0,"qty":500.0},{"price":1575.0,"qty":400.0},{"price":1570.0,"qty":50000.0},{"price":1560.0,"qty":1000.0},{"price":1550.0,"qty":25.0},{"price":1480.0,"qty":2000.0},{"price":1470.0,"qty":2000.0},{"price":1420.0,"qty":50000.0},{"price":1370.35,"qty":100.0},{"price":1329.0,"qty":150001.0},{"price":1312.0,"qty":20000.0},{"price":1280.0,"qty":50000.0},{"price":1212.0,"qty":20000.0},{"price":1150.0,"qty":50000.0},{"price":1112.0,"qty":30000.0},{"price":1030.0,"qty":50000.0},{"price":1012.0,"qty":30000.0},{"price":910.0,"qty":50000.0},{"price":810.0,"qty":50000.0},{"price":710.0,"qty":50000.0},{"price":610.0,"qty":50000.0}],"asks":[{"price":2031.9,"qty":420.0},{"price":2033.5,"qty":10500.0},{"price":2034.0,"qty":112732.0},{"price":2034.2,"qty":2000.0},{"price":2036.1,"qty":102731.0},{"price":2038.25,"qty":258749.0},{"price":2038.3,"qty":103606.0},{"price":2038.55,"qty":100.0},{"price":2038.75,"qty":21000.0},{"price":2041.7,"qty":223920.0},{"price":2042.25,"qty":250002.0},{"price":2042.3,"qty":45099.0},{"price":2042.4,"qty":42000.0},{"price":2050.2,"qty":84000.0},{"price":2056.7,"qty":44305.0},{"price":2075.0,"qty":8192.0},{"price":2080.85,"qty":45733.0},{"price":2088.0,"qty":2000.0},{"price":2088.55,"qty":27643.0},{"price":2100.0,"qty":2045.0},{"price":2107.35,"qty":25.0},{"price":2137.95,"qty":27437.0},{"price":2158.5,"qty":26863.0},{"price":2162.75,"qty":50.0},{"price":2180.0,"qty":200.0},{"price":2205.0,"qty":600.0},{"price":3028.0,"qty":400.0}]}
1626994927.9607801: {"feed":"book_snapshot","product_id":"FI_XRPUSD_210924","timestamp":1626994924579,"seq":602276,"tickSize":null,"bids":[{"price":0.585,"qty":338.0},{"price":0.5848,"qty":7200.0},{"price":0.5838,"qty":59.0},{"price":0.5836,"qty":50.0},{"price":0.5833,"qty":6191.0},{"price":0.5832,"qty":18000.0},{"price":0.5828,"qty":44.0},{"price":0.5822,"qty":45000.0},{"price":0.5818,"qty":400.0},{"price":0.5814,"qty":29643.0},{"price":0.5813,"qty":112500.0},{"price":0.5795,"qty":29452.0},{"price":0.5728,"qty":29394.0},{"price":0.5688,"qty":17461.0},{"price":0.5598,"qty":17868.0},{"price":0.5544,"qty":17565.0},{"price":0.546,"qty":500.0},{"price":0.47,"qty":50.0},{"price":0.45,"qty":60.0},{"price":0.43,"qty":100.0},{"price":0.4,"qty":100.0},{"price":0.375,"qty":200.0}],"asks":[{"price":0.586,"qty":288.0},{"price":0.5864,"qty":7200.0},{"price":0.5874,"qty":6149.0},{"price":0.5875,"qty":18000.0},{"price":0.5876,"qty":51.0},{"price":0.5878,"qty":49.0},{"price":0.589,"qty":45000.0},{"price":0.5907,"qty":112500.0},{"price":0.5915,"qty":30655.0},{"price":0.5949,"qty":29993.0},{"price":0.5969,"qty":29233.0},{"price":0.6013,"qty":18092.0},{"price":0.6107,"qty":18439.0},{"price":0.6166,"qty":17798.0},{"price":0.65,"qty":25.0},{"price":0.72,"qty":50.0},{"price":0.8915,"qty":300.0},{"price":1.05,"qty":100.0},{"price":1.6212,"qty":500.0}]}
1626994928.034643: {"feed":"book_snapshot","product_id":"PI_ETHUSD","timestamp":1626994927674,"seq":26660859,"tickSize":null,"bids":[{"price":2003.9,"qty":2234.0},{"price":2003.3,"qty":35826.0},{"price":2003.25,"qty":600.0},{"price":2003.15,"qty":7855.0},{"price":2003.05,"qty":1312.0},{"price":2002.95,"qty":5493.0},{"price":2002.9,"qty":43610.0},{"price":2002.85,"qty":3858.0},{"price":2002.8,"qty":91958.0},{"price":2002.6,"qty":6536.0},{"price":2002.55,"qty":15000.0},{"price":2002.45,"qty":3931.0},{"price":2002.4,"qty":6375.0},{"price":2002.15,"qty":4858.0},{"price":2002.1,"qty":5000.0},{"price":2002.05,"qty":3806.0},{"price":2001.85,"qty":5005.0},{"price":2001.8,"qty":89845.0},{"price":2001.4,"qty":4053.0},{"price":2001.25,"qty":5068.0},{"price":2001.15,"qty":4090.0},{"price":2000.95,"qty":14093.0},{"price":2000.9,"qty":9013.0},{"price":2000.8,"qty":12519.0},{"price":2000.65,"qty":5748.0},{"price":2000.55,"qty":16642.0},{"price":2000.5,"qty":223695.0},{"price":2000.35,"qty":150000.0},{"price":2000.3,"qty":150000.0},{"price":2000.25,"qty":30062.0},{"price":2000.0,"qty":83351.0},{"price":1999.95,"qty":4300.0},{"price":1999.9,"qty":8509.0},{"price":1999.85,"qty":7500.0},{"price":1999.75,"qty":63.0},{"price":1999.7,"qty":23328.0},{"price":1999.65,"qty":500001.0},{"price":1999.6,"qty":3885.0},{"price":1999.55,"qty":129543.0},{"price":1999.4,"qty":6630.0},{"price":1999.25,"qty":8775.0},{"price":1999.15,"qty":3826.0},{"price":1999.05,"qty":22203.0},{"price":1998.95,"qty":8367.0},{"price":1998.6,"qty":153360.0},{"price":1997.6,"qty":740.0},{"price":1997.35,"qty":60000.0},{"price":1996.65,"qty":3813.0},{"price":1996.45,"qty":3997.0},{"price":1996.4,"qty":14115.0},{"price":1996.2,"qty":13603.0},{"price":1995.0,"qty":47486.0},{"price":1994.95,"qty":500002.0},{"price":1994.85,"qty":38399.0},{"price":1994.75,"qty":100.0},{"price":1993.95,"qty":120000.0},{"price":1993.1,"qty":223290.0},{"price":1992.3,"qty":225328.0},{"price":1992.0,"qty":930.0},{"price":1990.0,"qty":33100.0},{"price":1989.05,"qty":10.0},{"price":1988.85,"qty":59999.0},{"price":1987.85,"qty":56.0},{"price":1987.65,"qty":25.0},{"price":1987.5,"qty":750.0},{"price":1987.0,"qty":2500.0},{"price":1986.15,"qty":38.0},{"price":1985.1,"qty":66946.0},{"price":1985.05,"qty":219289.0},{"price":1985.0,"qty":1000.0},{"price":1984.8,"qty":39.0},{"price":1984.0,"qty":4.0},{"price":1980.2,"qty":200003.0},{"price":1980.15,"qty":50159.0},{"price":1980.0,"qty":850.0},{"price":1979.0,"qty":200.0},{"price":1975.0,"qty":51059.0},{"price":1974.25,"qty":50234.0},{"price":1973.0,"qty":333.0},{"price":1972.05,"qty":24.0},{"price":1970.25,"qty":131966.0},{"price":1970.0,"qty":3750.0},{"price":1968.2,"qty":41.0},{"price":1967.5,"qty":20.0},{"price":1967.25,"qty":12.0},{"price":1966.6,"qty":24.0},{"price":1965.0,"qty":4000.0},{"price":1964.55,"qty":90.0},{"price":1963.0,"qty":444.0},{"price":1960.0,"qty":2000.0},{"price":1957.0,"qty":333.0},{"price":1955.1,"qty":95541.0},{"price":1954.5,"qty":5000.0},{"price":1953.0,"qty":555.0},{"price":1952.85,"qty":1.0},{"price":1952.1,"qty":131517.0},{"price":1951.0,"qty":1.0},{"price":1950.0,"qty":100475.0},{"price":1949.45,"qty":41.0},{"price":1948.35,"qty":19.0},{"price":1947.45,"qty":1.0},{"price":1945.0,"qty":38525.0},{"price":1943.0,"qty":666.0},{"price":1941.4,"qty":133947.0},{"price":1940.0,"qty":20250.0},{"price":1935.2,"qty":1.0},{"price":1935.1,"qty":1.0},{"price":1935.0,"qty":10000.0},{"price":1934.5,"qty":5000.0},{"price":1933.65,"qty":777.0},{"price":1930.0,"qty":103000.0},{"price":1923.0,"qty":888.0},{"price":1922.0,"qty":666.0},{"price":1920.0,"qty":1000.0},{"price":1915.7,"qty":95541.0},{"price":1913.0,"qty":999.0},{"price":1910.0,"qty":500.0},{"price":1904.0,"qty":666.0},{"price":1900.0,"qty":3391.0},{"price":1895.0,"qty":750.0},{"price":1885.0,"qty":150.0},{"price":1884.0,"qty":200.0},{"price":1877.2,"qty":5000.0},{"price":1876.0,"qty":150000.0},{"price":1871.35,"qty":95541.0},{"price":1870.0,"qty":2000.0},{"price":1866.0,"qty":100000.0},{"price":1862.5,"qty":5000.0},{"price":1850.0,"qty":225.0},{"price":1842.5,"qty":5000.0},{"price":1840.0,"qty":2200.0},{"price":1819.0,"qty":10000.0},{"price":1800.0,"qty":4325.0},{"price":1780.0,"qty":200.0},{"price":1750.0,"qty":13125.0},{"price":1748.55,"qty":500.0},{"price":1740.0,"qty":200.0},{"price":1735.0,"qty":10000.0},{"price":1732.0,"qty":95541.0},{"price":1730.0,"qty":2000.0},{"price":1727.9,"qty":500.0},{"price":1720.0,"qty":5000.0},{"price":1717.0,"qty":2248.0},{"price":1716.0,"qty":2222.0},{"price":1715.0,"qty":2222.0},{"price":1714.0,"qty":2222.0},{"price":1713.0,"qty":2222.0},{"price":1712.5,"qty":2000.0},{"price":1712.0,"qty":2222.0},{"price":1711.0,"qty":2222.0},{"price":1710.75,"qty":5000.0},{"price":1710.0,"qty":3388.0},{"price":1709.0,"qty":2222.0},{"price":1708.0,"qty":3222.0},{"price":1707.0,"qty":2222.0},{"price":1706.0,"qty":2222.0},{"price":1705.0,"qty":2722.0},{"price":1704.0,"qty":2722.0},{"price":1703.0,"qty":2222.0},{"price":1702.0,"qty":2222.0},{"price":1701.0,"qty":5222.0},{"price":1700.05,"qty":172713.0},{"price":1700.0,"qty":20973.0},{"price":1699.5,"qty":500.0},{"price":1699.0,"qty":2222.0},{"price":1698.0,"qty":2222.0},{"price":1697.0,"qty":2222.0},{"price":1696.0,"qty":2222.0},{"price":1695.0,"qty":3222.0},{"price":1694.0,"qty":3333.0},{"price":1693.0,"qty":3333.0},{"price":1692.0,"qty":3333.0},{"price":1691.0,"qty":3333.0},{"price":1690.05,"qty":200000.0},{"price":1690.0,"qty":4499.0},{"price":1689.15,"qty":100.0},{"price":1689.0,"qty":3333.0},{"price":1688.0,"qty":3333.0},{"price":1687.0,"qty":3333.0},{"price":1686.0,"qty":3333.0},{"price":1685.0,"qty":8333.0},{"price":1684.0,"qty":4444.0},{"price":1683.0,"qty":4444.0},{"price":1682.0,"qty":4444.0},{"price":1681.0,"qty":17537.0},{"price":1680.05,"qty":200000.0},{"price":1680.0,"qty":4944.0},{"price":1676.0,"qty":1000.0},{"price":1675.0,"qty":1000.0},{"price":1670.05,"qty":200000.0},{"price":1670.0,"qty":500.0},{"price":1666.0,"qty":6666.0},{"price":1660.05,"qty":200000.0},{"price":1652.0,"qty":100.0},{"price":1651.0,"qty":10500.0},{"price":1650.05,"qty":200000.0},{"price":1644.95,"qty":100.0},{"price":1644.5,"qty":200.0},{"price":1640.05,"qty":200000.0},{"price":1640.0,"qty":400.0},{"price":1638.0,"qty":10000.0},{"price":1631.0,"qty":20000.0},{"price":1630.05,"qty":200000.0},{"price":1625.0,"qty":8000.0},{"price":1620.05,"qty":200000.0},{"price":1620.0,"qty":400.0},{"price":1610.05,"qty":200000.0},{"price":1604.0,"qty":500.0},{"price":1600.05,"qty":200000.0},{"price":1600.0,"qty":42335.0},{"price":1572.0,"qty":6000.0},{"price":1571.0,"qty":1571.0},{"price":1564.65,"qty":100.0},{"price":1562.0,"qty":5000.0},{"price":1558.0,"qty":1500000.0},{"price":1555.4,"qty":500.0},{"price":1551.55,"qty":20000.0},{"price":1550.0,"qty":400.0},{"price":1544.5,"qty":200.0},{"price":1532.0,"qty":6000.0},{"price":1530.0,"qty":500.0},{"price":1525.0,"qty":2000.0},{"price":1502.0,"qty":6000.0},{"price":1501.4,"qty":5000.0},{"price":1500.0,"qty":10200.0},{"price":1477.0,"qty":2.0},{"price":1474.25,"qty":600.0},{"price":1468.0,"qty":200.0},{"price":1450.0,"qty":22000.0},{"price":1444.5,"qty":200.0},{"price":1420.0,"qty":115500.0},{"price":1402.0,"qty":10934.0},{"price":1400.0,"qty":21400.0},{"price":1388.0,"qty":1000.0},{"price":1381.5,"qty":200.0},{"price":1368.0,"qty":2500.0},{"price":1358.25,"qty":1000.0},{"price":1351.0,"qty":500.0},{"price":1350.0,"qty":1500.0},{"price":1345.5,"qty":200.0},{"price":1344.0,"qty":10000.0},{"price":1335.0,"qty":250.0},{"price":1331.5,"qty":200.0},{"price":1325.0,"qty":4000.0},{"price":1311.0,"qty":215001.0},{"price":1300.0,"qty":200.0},{"price":1287.0,"qty":1000.0},{"price":1278.0,"qty":10000.0},{"price":1255.0,"qty":10000.0},{"price":1250.0,"qty":81000.0},{"price":1244.5,"qty":200.0},{"price":1234.0,"qty":3000000.0},{"price":1233.0,"qty":1500.0},{"price":1228.0,"qty":10000.0},{"price":1200.0,"qty":21200.0},{"price":1181.5,"qty":200.0},{"price":1180.0,"qty":1000.0},{"price":1175.0,"qty":10000.0},{"price":1155.0,"qty":10000.0},{"price":1150.0,"qty":74000.0},{"price":1144.0,"qty":100.0},{"price":1130.0,"qty":1000.0},{"price":1101.5,"qty":200.0},{"price":1100.0,"qty":2200.0},{"price":1080.0,"qty":1000.0},{"price":1067.95,"qty":400.0},{"price":1055.0,"qty":10000.0},{"price":1050.0,"qty":1000.0},{"price":1040.0,"qty":100.0},{"price":1001.5,"qty":200.0},{"price":1000.0,"qty":40301.0},{"price":997.8,"qty":1449.0},{"price":996.0,"qty":1000.0},{"price":992.0,"qty":20000.0},{"price":981.5,"qty":200.0},{"price":980.0,"qty":40.0},{"price":971.5,"qty":200.0},{"price":938.55,"qty":95541.0},{"price":933.0,"qty":2500.0},{"price":900.0,"qty":36160.0},{"price":810.6,"qty":100.0},{"price":800.0,"qty":30100.0},{"price":773.0,"qty":20000.0},{"price":761.3,"qty":1000.0},{"price":751.0,"qty":75000.0},{"price":750.0,"qty":1.0},{"price":749.5,"qty":1000.0},{"price":741.5,"qty":13410.0},{"price":732.4,"qty":1000.0},{"price":730.0,"qty":21.0},{"price":725.0,"qty":200000.0},{"price":716.0,"qty":1000.0},{"price":700.0,"qty":201100.0},{"price":675.0,"qty":200000.0},{"price":667.0,"qty":2000.0},{"price":660.0,"qty":20.0},{"price":637.0,"qty":50.0},{"price":602.0,"qty":2000.0},{"price":600.0,"qty":115.0},{"price":555.0,"qty":2002.0},{"price":505.8,"qty":2000.0},{"price":500.0,"qty":30100.0},{"price":480.0,"qty":2.0},{"price":461.0,"qty":200.0},{"price":441.0,"qty":200.0},{"price":425.55,"qty":200.0},{"price":421.0,"qty":200.0},{"price":420.0,"qty":2000.0},{"price":415.0,"qty":3.0},{"price":401.0,"qty":200.0},{"price":400.0,"qty":100.0},{"price":385.85,"qty":100.0},{"price":381.0,"qty":200.0},{"price":380.5,"qty":1143.0},{"price":380.0,"qty":1.0},{"price":361.0,"qty":200.0},{"price":345.2,"qty":1069.0},{"price":341.0,"qty":200.0},{"price":338.45,"qty":200.0},{"price":330.0,"qty":10.0},{"price":321.0,"qty":200.0},{"price":304.65,"qty":928.0},{"price":301.0,"qty":400.0},{"price":300.45,"qty":907.0},{"price":300.0,"qty":101.0},{"price":269.0,"qty":1000.0},{"price":261.5,"qty":789.0},{"price":254.6,"qty":400.0},{"price":247.4,"qty":744.0},{"price":244.0,"qty":763.0},{"price":240.65,"qty":757.0},{"price":237.35,"qty":743.0},{"price":234.05,"qty":719.0},{"price":230.8,"qty":716.0},{"price":227.6,"qty":689.0},{"price":224.45,"qty":684.0},{"price":221.35,"qty":674.0},{"price":218.3,"qty":663.0},{"price":211.0,"qty":1500.0},{"price":209.4,"qty":630.0},{"price":206.5,"qty":623.0},{"price":203.65,"qty":631.0},{"price":200.85,"qty":625.0},{"price":200.0,"qty":100.0},{"price":198.1,"qty":600.0},{"price":194.0,"qty":599.0},{"price":190.0,"qty":576.0},{"price":186.0,"qty":564.0},{"price":182.0,"qty":551.0},{"price":180.0,"qty":500.0},{"price":172.0,"qty":179.0},{"price":165.4,"qty":1000.0},{"price":100.0,"qty":100.0},{"price":22.0,"qty":450.0},{"price":5.0,"qty":50000.0},{"price":2.0,"qty":20000.0},{"price":0.25,"qty":20000.0},{"price":0.1,"qty":10000.0},{"price":0.05,"qty":10000.0}],"asks":[{"price":2004.6,"qty":600.0},{"price":2004.7,"qty":5990.0},{"price":2005.3,"qty":19485.0},{"price":2005.45,"qty":114385.0},{"price":2005.5,"qty":3796.0},{"price":2005.65,"qty":59.0},{"price":2005.7,"qty":10385.0},{"price":2005.75,"qty":4112.0},{"price":2005.8,"qty":47980.0},{"price":2005.95,"qty":8396.0},{"price":2006.25,"qty":3939.0},{"price":2006.3,"qty":27967.0},{"price":2006.35,"qty":4990.0},{"price":2006.4,"qty":90636.0},{"price":2006.5,"qty":8964.0},{"price":2006.65,"qty":3836.0},{"price":2006.7,"qty":16136.0},{"price":2006.75,"qty":150000.0},{"price":2006.8,"qty":42541.0},{"price":2006.85,"qty":4183.0},{"price":2006.9,"qty":9013.0},{"price":2006.95,"qty":5090.0},{"price":2007.05,"qty":30000.0},{"price":2007.2,"qty":4061.0},{"price":2007.25,"qty":500001.0},{"price":2007.3,"qty":22203.0},{"price":2007.35,"qty":4164.0},{"price":2007.4,"qty":4037.0},{"price":2007.55,"qty":4989.0},{"price":2007.6,"qty":23333.0},{"price":2007.65,"qty":150000.0},{"price":2007.7,"qty":3970.0},{"price":2007.75,"qty":175154.0},{"price":2008.3,"qty":45949.0},{"price":2008.45,"qty":4023.0},{"price":2008.55,"qty":100.0},{"price":2008.7,"qty":3878.0},{"price":2009.1,"qty":38399.0},{"price":2009.15,"qty":197293.0},{"price":2009.35,"qty":60000.0},{"price":2009.5,"qty":18645.0},{"price":2010.8,"qty":120000.0},{"price":2011.25,"qty":12561.0},{"price":2013.15,"qty":50628.0},{"price":2013.2,"qty":500002.0},{"price":2013.75,"qty":218763.0},{"price":2015.15,"qty":59999.0},{"price":2017.0,"qty":10000.0},{"price":2017.2,"qty":221656.0},{"price":2018.15,"qty":2500.0},{"price":2021.45,"qty":67943.0},{"price":2021.5,"qty":220410.0},{"price":2032.0,"qty":306.0},{"price":2033.0,"qty":71.0},{"price":2035.0,"qty":71.0},{"price":2036.0,"qty":37.0},{"price":2037.0,"qty":786.0},{"price":2042.4,"qty":175003.0},{"price":2042.45,"qty":131958.0},{"price":2043.0,"qty":38.0},{"price":2044.0,"qty":734.0},{"price":2046.0,"qty":749.0},{"price":2048.0,"qty":70.0},{"price":2049.0,"qty":153.0},{"price":2050.0,"qty":11608.0},{"price":2052.0,"qty":136898.0},{"price":2053.0,"qty":34.0},{"price":2054.0,"qty":111.0},{"price":2055.0,"qty":267.0},{"price":2058.0,"qty":70.0},{"price":2059.0,"qty":39.0},{"price":2060.0,"qty":2010.0},{"price":2064.0,"qty":43.0},{"price":2069.0,"qty":48.0},{"price":2074.0,"qty":53.0},{"price":2075.0,"qty":1500.0},{"price":2079.0,"qty":59.0},{"price":2095.55,"qty":136165.0},{"price":2100.0,"qty":2225.0},{"price":2110.0,"qty":50.0},{"price":2125.0,"qty":100.0},{"price":2127.0,"qty":15000.0},{"price":2128.0,"qty":50000.0},{"price":2130.0,"qty":400.0},{"price":2136.5,"qty":500.0},{"price":2139.55,"qty":150.0},{"price":2143.25,"qty":300.0},{"price":2150.0,"qty":121436.0},{"price":2151.35,"qty":300.0},{"price":2153.05,"qty":95541.0},{"price":2157.25,"qty":1111.0},{"price":2157.5,"qty":1411.0},{"price":2158.0,"qty":1111.0},{"price":2159.0,"qty":1111.0},{"price":2160.0,"qty":50.0},{"price":2167.75,"qty":95541.0},{"price":2175.0,"qty":1191.0},{"price":2176.8,"qty":95541.0},{"price":2178.0,"qty":1111.0},{"price":2180.9,"qty":1223.0},{"price":2181.0,"qty":1111.0},{"price":2183.5,"qty":1000.0},{"price":2183.75,"qty":300.0},{"price":2184.0,"qty":1111.0},{"price":2187.0,"qty":1111.0},{"price":2188.0,"qty":10000.0},{"price":2190.0,"qty":1111.0},{"price":2193.0,"qty":1111.0},{"price":2196.0,"qty":1111.0},{"price":2197.0,"qty":1111.0},{"price":2198.0,"qty":1111.0},{"price":2199.0,"qty":1111.0},{"price":2199.3,"qty":150.0},{"price":2200.0,"qty":8336.0},{"price":2201.0,"qty":1111.0},{"price":2202.0,"qty":1111.0},{"price":2203.0,"qty":1111.0},{"price":2204.0,"qty":1111.0},{"price":2205.0,"qty":1111.0},{"price":2206.0,"qty":1111.0},{"price":2207.0,"qty":22222.0},{"price":2208.0,"qty":2222.0},{"price":2209.0,"qty":2222.0},{"price":2210.0,"qty":2222.0},{"price":2210.2,"qty":300.0},{"price":2211.0,"qty":2222.0},{"price":2212.0,"qty":2222.0},{"price":2213.0,"qty":1111.0},{"price":2213.35,"qty":300.0},{"price":2214.0,"qty":1111.0},{"price":2215.0,"qty":1111.0},{"price":2222.0,"qty":20000.0},{"price":2233.0,"qty":20000.0},{"price":2244.0,"qty":20000.0},{"price":2249.0,"qty":1111.0},{"price":2250.0,"qty":1111.0},{"price":2251.0,"qty":1111.0},{"price":2252.0,"qty":1111.0},{"price":2253.0,"qty":2222.0},{"price":2254.0,"qty":2222.0},{"price":2255.0,"qty":2222.0},{"price":2256.0,"qty":2222.0},{"price":2257.0,"qty":2222.0},{"price":2258.0,"qty":2222.0},{"price":2259.0,"qty":2222.0},{"price":2260.0,"qty":2222.0},{"price":2262.95,"qty":125000.0},{"price":2269.35,"qty":222.0},{"price":2278.3,"qty":20000.0},{"price":2282.5,"qty":150.0},{"price":2300.0,"qty":2200.0},{"price":2319.7,"qty":300.0},{"price":2329.0,"qty":300.0},{"price":2333.0,"qty":2686.0},{"price":2343.35,"qty":300.0},{"price":2350.0,"qty":1000.0},{"price":2351.6,"qty":150.0},{"price":2355.95,"qty":300.0},{"price":2360.0,"qty":7500.0},{"price":2368.65,"qty":300.0},{"price":2375.7,"qty":300.0},{"price":2378.0,"qty":40000.0},{"price":2382.0,"qty":108917.0},{"price":2386.3,"qty":300.0},{"price":2396.8,"qty":300.0},{"price":2400.0,"qty":87500.0},{"price":2410.0,"qty":350.0},{"price":2411.45,"qty":7500.0},{"price":2444.35,"qty":2800.0},{"price":2447.0,"qty":20000.0},{"price":2489.55,"qty":3000.0},{"price":2490.0,"qty":350.0},{"price":2495.0,"qty":15000.0},{"price":2500.0,"qty":3775.0},{"price":2532.0,"qty":2000.0},{"price":2550.0,"qty":8000.0},{"price":2571.3,"qty":150.0},{"price":2595.0,"qty":20000.0},{"price":2600.0,"qty":5000.0},{"price":2645.0,"qty":5000.0},{"price":2646.0,"qty":55300.0},{"price":2650.0,"qty":1000.0},{"price":2666.0,"qty":100.0},{"price":2666.6,"qty":50.0},{"price":2675.0,"qty":666.0},{"price":2682.0,"qty":1000.0},{"price":2690.0,"qty":1000.0},{"price":2695.0,"qty":10000.0},{"price":2700.0,"qty":4100.0},{"price":2712.0,"qty":600.0},{"price":2724.0,"qty":600.0},{"price":2748.0,"qty":600.0},{"price":2769.0,"qty":600.0},{"price":2784.0,"qty":600.0},{"price":2795.0,"qty":5000.0},{"price":2796.0,"qty":600.0},{"price":2800.0,"qty":1250.0},{"price":2812.0,"qty":600.0},{"price":2845.0,"qty":5000.0},{"price":2848.0,"qty":600.0},{"price":2868.0,"qty":1200.0},{"price":2895.0,"qty":5000.0},{"price":2900.0,"qty":3900.0},{"price":2949.9,"qty":1750.0},{"price":2969.0,"qty":600.0},{"price":2970.0,"qty":50000.0},{"price":2984.0,"qty":600.0},{"price":2995.0,"qty":10000.0},{"price":2999.95,"qty":200000.0},{"price":3000.0,"qty":4000.0},{"price":3004.0,"qty":5000.0},{"price":3009.95,"qty":200000.0},{"price":3010.1,"qty":9000.0},{"price":3019.95,"qty":200000.0},{"price":3029.95,"qty":200000.0},{"price":3039.95,"qty":200000.0},{"price":3049.95,"qty":200000.0},{"price":3059.95,"qty":200000.0},{"price":3069.95,"qty":200000.0},{"price":3079.95,"qty":200000.0},{"price":3089.95,"qty":200000.0},{"price":3099.95,"qty":200000.0},{"price":3109.95,"qty":200000.0},{"price":3119.95,"qty":200000.0},{"price":3129.95,"qty":200000.0},{"price":3139.95,"qty":200000.0},{"price":3145.0,"qty":200.0},{"price":3149.95,"qty":200000.0},{"price":3159.95,"qty":200000.0},{"price":3169.95,"qty":200000.0},{"price":3179.95,"qty":200000.0},{"price":3189.95,"qty":200000.0},{"price":3199.95,"qty":200000.0},{"price":3209.95,"qty":200000.0},{"price":3219.95,"qty":200000.0},{"price":3229.95,"qty":200000.0},{"price":3239.95,"qty":200000.0},{"price":3249.95,"qty":200000.0},{"price":3259.95,"qty":200000.0},{"price":3269.95,"qty":200000.0},{"price":3279.95,"qty":200000.0},{"price":3282.0,"qty":500.0},{"price":3289.95,"qty":200000.0},{"price":3299.95,"qty":200000.0},{"price":3309.95,"qty":200000.0},{"price":3319.95,"qty":200000.0},{"price":3329.95,"qty":200000.0},{"price":3339.95,"qty":200000.0},{"price":3348.15,"qty":100.0},{"price":3349.95,"qty":200000.0},{"price":3359.95,"qty":200000.0},{"price":3369.95,"qty":200000.0},{"price":3379.95,"qty":200000.0},{"price":3389.95,"qty":200000.0},{"price":3399.95,"qty":200000.0},{"price":3408.15,"qty":100.0},{"price":3409.95,"qty":200000.0},{"price":3434.45,"qty":1000.0},{"price":3438.75,"qty":9000.0},{"price":3450.0,"qty":50.0},{"price":3460.0,"qty":50.0},{"price":3498.15,"qty":100.0},{"price":3500.0,"qty":80.0},{"price":3555.0,"qty":50.0},{"price":3580.0,"qty":200000.0},{"price":3600.0,"qty":3000.0},{"price":3602.0,"qty":1800.0},{"price":3700.0,"qty":10000.0},{"price":3850.0,"qty":3850.0},{"price":3900.0,"qty":1000.0},{"price":4179.5,"qty":500.0},{"price":4200.0,"qty":50.0},{"price":4235.0,"qty":500.0},{"price":4267.75,"qty":5000.0},{"price":4305.3,"qty":500.0},{"price":4324.35,"qty":10000.0},{"price":4400.0,"qty":1000.0},{"price":4500.0,"qty":50.0},{"price":4643.0,"qty":8000.0},{"price":4643.5,"qty":390000.0},{"price":5000.0,"qty":1051.0},{"price":5600.0,"qty":500.0},{"price":5700.0,"qty":500.0},{"price":6000.0,"qty":50.0},{"price":6771.95,"qty":5.0},{"price":7000.0,"qty":50.0},{"price":7500.0,"qty":50.0},{"price":8000.0,"qty":50.0},{"price":9000.0,"qty":50.0},{"price":10000.0,"qty":50.0},{"price":20000.0,"qty":114000.0},{"price":49081.0,"qty":100.0},{"price":51000.0,"qty":4000.0},{"price":9999999.95,"qty":4500000.0}]}
1626994928.037677: {"feed":"book","product_id":"PI_ETHUSD","side":"sell","seq":26660860,"price":2004.85,"qty":4787.0,"timestamp":1626994927744}
1626994928.03772: {"feed":"book","product_id":"PI_LTCUSD","side":"sell","seq":3423036,"price":119.46,"qty":21884.0,"timestamp":1626994927748}
1626994928.0377479: {"feed":"book","product_id":"PI_LTCUSD","side":"buy","seq":3423037,"price":119.21,"qty":24508.0,"timestamp":1626994927751}
1626994928.037768: {"feed":"book","product_id":"PI_LTCUSD","side":"buy","seq":3423038,"price":119.18,"qty":6561.0,"timestamp":1626994927751}
1626994928.037786: {"feed":"book","product_id":"FI_ETHUSD_211231","side":"sell","seq":2198964,"price":2033.8,"qty":5000.0,"timestamp":1626994927762}
1626994928.037809: {"feed":"book","product_id":"PI_ETHUSD","side":"sell","seq":26660861,"price":2005.25,"qty":5864.0,"timestamp":1626994927765}
1626994928.0378299: {"feed":"book","product_id":"PI_ETHUSD","side":"buy","seq":26660862,"price":2002.4,"qty":0.0,"timestamp":1626994927766}
1626994928.037857: {"feed":"book","product_id":"FI_XBTUSD_210730","side":"sell","seq":5159967,"price":32200.5,"qty":0.0,"timestamp":1626994927856}
1626994928.0378802: {"feed":"book","product_id":"FI_XBTUSD_210730","side":"sell","seq":5159968,"price":32199.5,"qty":251.0,"timestamp":1626994927856}
1626994928.0379: {"feed":"book","product_id":"FI_XRPUSD_210924","side":"sell","seq":602277,"price":0.5876,"qty":0.0,"timestamp":1626994927858}
1626994928.037923: {"feed":"book","product_id":"FI_XBTUSD_210924","side":"sell","seq":13501561,"price":32223.5,"qty":0.0,"timestamp":1626994927859}
1626994928.037945: {"feed":"book","product_id":"FI_XBTUSD_210924","side":"sell","seq":13501562,"price":32222.5,"qty":251.0,"timestamp":1626994927859}
1626994928.037966: {"feed":"book","product_id":"PI_ETHUSD","side":"buy","seq":26660863,"price":2002.6,"qty":16536.0,"timestamp":1626994927862}
1626994928.037983: {"feed":"book","product_id":"PI_ETHUSD","side":"sell","seq":26660864,"price":2004.8,"qty":10000.0,"timestamp":1626994927862}
1626994928.038003: {"feed":"book","product_id":"FI_BCHUSD_210924","side":"sell","seq":402228,"price":442.8,"qty":0.0,"timestamp":1626994927863}
1626994928.038024: {"feed":"book","product_id":"PI_ETHUSD","side":"sell","seq":26660865,"price":2005.3,"qty":15000.0,"timestamp":1626994927877}
1626994928.038041: {"feed":"book","product_id":"PI_ETHUSD","side":"sell","seq":26660866,"price":2005.7,"qty":0.0,"timestamp":1626994927885}
1626994928.0380611: {"feed":"book","product_id":"PI_ETHUSD","side":"sell","seq":26660867,"price":2005.75,"qty":14519.0,"timestamp":1626994927885}
1626994928.038078: {"feed":"book","product_id":"PI_ETHUSD","side":"sell","seq":26660868,"price":2006.7,"qty":0.0,"timestamp":1626994927885}
1626994928.0380979: {"feed":"book","product_id":"PI_ETHUSD","side":"sell","seq":26660869,"price":2006.75,"qty":166169.0,"timestamp":1626994927885}
1626994928.038114: {"feed":"book","product_id":"PI_ETHUSD","side":"buy","seq":26660870,"price":2000.55,"qty":0.0,"timestamp":1626994927885}
1626994928.038134: {"feed":"book","product_id":"PI_ETHUSD","side":"buy","seq":26660871,"price":2000.55,"qty":17029.0,"timestamp":1626994927885}
1626994928.038154: {"feed":"book","product_id":"PI_ETHUSD","side":"buy","seq":26660872,"price":2000.95,"qty":0.0,"timestamp":1626994927885}
1626994928.038174: {"feed":"book","product_id":"PI_ETHUSD","side":"buy","seq":26660873,"price":2000.95,"qty":14351.0,"timestamp":1626994927885}
1626994928.038193: {"feed":"book","product_id":"PI_ETHUSD","side":"sell","seq":26660874,"price":2007.6,"qty":0.0,"timestamp":1626994927885}
1626994928.038213: {"feed":"book","product_id":"PI_ETHUSD","side":"sell","seq":26660875,"price":2007.6,"qty":23073.0,"timestamp":1626994927885}
1626994928.038232: {"feed":"book","product_id":"PI_ETHUSD","side":"buy","seq":26660876,"price":1999.7,"qty":0.0,"timestamp":1626994927885}
1626994928.038252: {"feed":"book","product_id":"PI_ETHUSD","side":"buy","seq":26660877,"price":1999.7,"qty":23586.0,"timestamp":1626994927885}
1626994928.038272: {"feed":"book","product_id":"PI_ETHUSD","side":"buy","seq":26660878,"price":1995.0,"qty":0.0,"timestamp":1626994927885}
1626994928.038292: {"feed":"book","product_id":"PI_ETHUSD","side":"buy","seq":26660879,"price":1995.0,"qty":47632.0,"timestamp":1626994927885}
1626994928.038312: {"feed":"book","product_id":"PI_ETHUSD","side":"sell","seq":26660880,"price":2013.15,"qty":0.0,"timestamp":1626994927885}
1626994928.038332: {"feed":"book","product_id":"PI_ETHUSD","side":"sell","seq":26660881,"price":2013.15,"qty":50478.0,"timestamp":1626994927885}
1626994928.038351: {"feed":"book","product_id":"PI_ETHUSD","side":"buy","seq":26660882,"price":1985.1,"qty":0.0,"timestamp":1626994927885}
1626994928.038371: {"feed":"book","product_id":"PI_ETHUSD","side":"buy","seq":26660883,"price":1985.1,"qty":66948.0,"timestamp":1626994927885}
1626994928.03839: {"feed":"book","product_id":"PI_ETHUSD","side":"sell","seq":26660884,"price":2021.45,"qty":0.0,"timestamp":1626994927885}
1626994928.03841: {"feed":"book","product_id":"PI_ETHUSD","side":"sell","seq":26660885,"price":2021.45,"qty":67945.0,"timestamp":1626994927885}
1626994928.03843: {"feed":"book","product_id":"PI_ETHUSD","side":"sell","seq":26660886,"price":2006.4,"qty":86728.0,"timestamp":1626994927994}
1626994928.0384462: {"feed":"book","product_id":"PI_ETHUSD","side":"buy","seq":26660887,"price":2003.15,"qty":3844.0,"timestamp":1626994927995}
1626994928.038462: {"feed":"book","product_id":"PI_ETHUSD","side":"buy","seq":26660888,"price":2003.15,"qty":0.0,"timestamp":1626994927996}
1626994928.038482: {"feed":"book","product_id":"PI_ETHUSD","side":"sell","seq":26660889,"price":2006.25,"qty":0.0,"timestamp":1626994927997}
1626994928.038502: {"feed":"book","product_id":"PI_ETHUSD","side":"buy","seq":26660890,"price":2002.75,"qty":3806.0,"timestamp":1626994927998}
1626994928.038521: {"feed":"book","product_id":"PI_ETHUSD","side":"sell","seq":26660891,"price":2005.85,"qty":3717.0,"timestamp":1626994928003}
1626994928.038541: {"feed":"book","product_id":"PI_ETHUSD","side":"sell","seq":26660892,"price":2005.25,"qty":10570.0,"timestamp":1626994928010}
1626994928.05896: {"feed":"book","product_id":"PI_ETHUSD","side":"sell","seq":26660893,"price":2005.25,"qty":5864.0,"timestamp":1626994928084}
1626994928.059319: {"feed":"book","product_id":"PI_ETHUSD","side":"sell","seq":26660894,"price":2005.85,"qty":0.0,"timestamp":1626994928087}
1626994928.063122: {"feed":"book","product_id":"PI_ETHUSD","side":"sell","seq":26660895,"price":2005.75,"qty":4112.0,"timestamp":1626994928089}
1626994928.063234: {"feed":"book","product_id":"PI_ETHUSD","side":"sell","seq":26660896,"price":2005.9,"qty":10792.0,"timestamp":1626994928089}
1626994928.063326: {"feed":"book","product_id":"PI_ETHUSD","side":"sell","seq":26660897,"price":2006.75,"qty":150000.0,"timestamp":1626994928089}
1626994928.063354: {"feed":"book","product_id":"PI_ETHUSD","side":"sell","seq":26660898,"price":2007.0,"qty":17590.0,"timestamp":1626994928089}
1626994928.063382: {"feed":"book","product_id":"PI_ETHUSD","side":"buy","seq":26660899,"price":1985.1,"qty":0.0,"timestamp":1626994928089}
1626994928.0634172: {"feed":"book","product_id":"PI_ETHUSD","side":"buy","seq":26660900,"price":1988.9,"qty":66950.0,"timestamp":1626994928089}
1626994928.065873: {"feed":"book","product_id":"PI_ETHUSD","side":"buy","seq":26660901,"price":2002.75,"qty":0.0,"timestamp":1626994928094}
1626994928.073954: {"feed":"book","product_id":"PI_ETHUSD","side":"sell","seq":26660902,"price":2004.75,"qty":1529.0,"timestamp":1626994928101}
1626994928.074083: {"feed":"book","product_id":"PI_ETHUSD","side":"sell","seq":26660903,"price":2004.5,"qty":2338.0,"timestamp":1626994928102}
1626994928.090167: {"feed":"book","product_id":"PI_ETHUSD","side":"sell","seq":26660904,"price":2005.35,"qty":4989.0,"timestamp":1626994928116}
1626994928.1003032: {"feed":"book","product_id":"FI_XBTUSD_210924","side":"sell","seq":13501563,"price":32228.0,"qty":0.0,"timestamp":1626994928127}
1626994928.127914: {"feed":"book","product_id":"PI_ETHUSD","side":"sell","seq":26660905,"price":2004.5,"qty":0.0,"timestamp":1626994928153}
1626994928.145483: {"feed":"book","product_id":"PI_ETHUSD","side":"buy","seq":26660906,"price":2003.3,"qty":20000.0,"timestamp":1626994928172}
1626994928.1455941: {"feed":"book","product_id":"PI_ETHUSD","side":"buy","seq":26660907,"price":2003.4,"qty":15826.0,"timestamp":1626994928172}
1626994928.14566: {"feed":"book","product_id":"FI_ETHUSD_210730","side":"sell","seq":2138664,"price":2002.75,"qty":0.0,"timestamp":1626994928172}
1626994928.145719: {"feed":"book","product_id":"PI_ETHUSD","side":"sell","seq":26660908,"price":2004.6,"qty":0.0,"timestamp":1626994928172}
1626994928.145768: {"feed":"book","product_id":"PI_ETHUSD","side":"sell","seq":26660909,"price":2004.85,"qty":5387.0,"timestamp":1626994928172}
1626994928.145804: {"feed":"book","product_id":"FI_ETHUSD_210730","side":"sell","seq":2138665,"price":2003.0,"qty":600.0,"timestamp":1626994928172}
1626994928.1461709: {"feed":"book","product_id":"PI_ETHUSD","side":"buy","seq":26660910,"price":2003.25,"qty":0.0,"timestamp":1626994928172}
1626994928.146261: {"feed":"book","product_id":"PI_ETHUSD","side":"buy","seq":26660911,"price":2003.5,"qty":600.0,"timestamp":1626994928172}
1626994928.1463208: {"feed":"book","product_id":"FI_ETHUSD_210730","side":"sell","seq":2138666,"price":2003.4,"qty":0.0,"timestamp":1626994928174}
1626994928.1463501: {"feed":"book","product_id":"FI_ETHUSD_210730","side":"sell","seq":2138667,"price":2003.95,"qty":15000.0,"timestamp":1626994928174}
1626994928.147674: {"feed":"book","product_id":"PI_ETHUSD","side":"sell","seq":26660912,"price":2005.3,"qty":0.0,"timestamp":1626994928175}
1626994928.147807: {"feed":"book","product_id":"PI_ETHUSD","side":"sell","seq":26660913,"price":2005.55,"qty":15000.0,"timestamp":1626994928175}
1626994928.147874: {"feed":"book","product_id":"FI_ETHUSD_211231","side":"buy","seq":2198965,"price":2027.7,"qty":0.0,"timestamp":1626994928174}
1626994928.147928: {"feed":"book","product_id":"PI_ETHUSD","side":"buy","seq":26660914,"price":2002.55,"qty":0.0,"timestamp":1626994928175}
1626994928.147975: {"feed":"book","product_id":"FI_ETHUSD_211231","side":"buy","seq":2198966,"price":2028.25,"qty":10500.0,"timestamp":1626994928174}
1626994928.1480188: {"feed":"book","product_id":"PI_ETHUSD","side":"buy","seq":26660915,"price":2002.8,"qty":106958.0,"timestamp":1626994928175}
1626994928.148341: {"feed":"book","product_id":"PI_ETHUSD","side":"sell","seq":26660916,"price":2005.5,"qty":0.0,"timestamp":1626994928175}
1626994928.148421: {"feed":"book","product_id":"PI_XRPUSD","side":"sell","seq":3456140,"price":0.5897,"qty":3929.0,"timestamp":1626994928175}
1626994928.149606: {"feed":"book","product_id":"PI_ETHUSD","side":"buy","seq":26660917,"price":2002.4,"qty":3884.0,"timestamp":1626994928176}
1626994928.1496918: {"feed":"book","product_id":"PI_ETHUSD","side":"buy","seq":26660918,"price":2001.8,"qty":86012.0,"timestamp":1626994928177}
1626994928.1571221: {"feed":"book","product_id":"FI_ETHUSD_210730","side":"buy","seq":2138668,"price":1996.45,"qty":0.0,"timestamp":1626994928183}
1626994928.157253: {"feed":"book","product_id":"FI_ETHUSD_210730","side":"buy","seq":2138669,"price":1997.05,"qty":2058.0,"timestamp":1626994928183}
1626994928.15732: {"feed":"book","product_id":"PI_ETHUSD","side":"buy","seq":26660919,"price":1999.95,"qty":0.0,"timestamp":1626994928183}
1626994928.157376: {"feed":"book","product_id":"PI_ETHUSD","side":"buy","seq":26660920,"price":2000.6,"qty":4304.0,"timestamp":1626994928183}
1626994928.157432: {"feed":"book","product_id":"FI_ETHUSD_211231","side":"buy","seq":2198967,"price":2025.2,"qty":0.0,"timestamp":1626994928184}
1626994928.157481: {"feed":"book","product_id":"FI_ETHUSD_211231","side":"buy","seq":2198968,"price":2025.85,"qty":757.0,"timestamp":1626994928184}
1626994928.160042: {"feed":"book","product_id":"PI_ETHUSD","side":"buy","seq":26660921,"price":2003.3,"qty":0.0,"timestamp":1626994928187}
1626994928.1601322: {"feed":"book","product_id":"PI_ETHUSD","side":"buy","seq":26660922,"price":2003.4,"qty":35826.0,"timestamp":1626994928187}
1626994928.160169: {"feed":"book","product_id":"PI_ETHUSD","side":"sell","seq":26660923,"price":2005.35,"qty":0.0,"timestamp":1626994928188}
1626994928.1614249: {"feed":"book","product_id":"PI_ETHUSD","side":"buy","seq":26660924,"price":1998.6,"qty":45949.0,"timestamp":1626994928189}
1626994928.161501: {"feed":"book","product_id":"PI_LTCUSD","side":"buy","seq":3423039,"price":118.86,"qty":0.0,"timestamp":1626994928189}
1626994928.1775072: {"feed":"book","product_id":"PI_ETHUSD","side":"buy","seq":26660925,"price":1999.75,"qty":0.0,"timestamp":1626994928202}
1626994928.177635: {"feed":"book","product_id":"PI_ETHUSD","side":"sell","seq":26660926,"price":2006.8,"qty":42605.0,"timestamp":1626994928202}
1626994928.210154: {"feed":"book","product_id":"FI_XBTUSD_210730","side":"sell","seq":5159969,"price":32199.5,"qty":0.0,"timestamp":1626994928235}
1626994928.210277: {"feed":"book","product_id":"FI_XBTUSD_210730","side":"sell","seq":5159970,"price":32200.5,"qty":251.0,"timestamp":1626994928235}
1626994928.2103412: {"feed":"book","product_id":"PI_ETHUSD","side":"sell","seq":26660927,"price":2005.75,"qty":8224.0,"timestamp":1626994928236}
1626994928.2190368: {"feed":"book","product_id":"PI_ETHUSD","side":"buy","seq":26660928,"price":2003.4,"qty":20000.0,"timestamp":1626994928244}
1626994928.219145: {"feed":"book","product_id":"PI_ETHUSD","side":"buy","seq":26660929,"price":2003.5,"qty":16426.0,"timestamp":1626994928244}
1626994928.229758: {"feed":"book","product_id":"FI_XBTUSD_210924","side":"sell","seq":13501564,"price":32222.5,"qty":0.0,"timestamp":1626994928256}
1626994928.229881: {"feed":"book","product_id":"FI_XBTUSD_210924","side":"sell","seq":13501565,"price":32223.5,"qty":251.0,"timestamp":1626994928256}
1626994928.23296: {"feed":"book","product_id":"PI_ETHUSD","side":"buy","seq":26660930,"price":2003.4,"qty":0.0,"timestamp":1626994928259}
1626994928.233085: {"feed":"book","product_id":"PI_ETHUSD","side":"buy","seq":26660931,"price":2003.5,"qty":36426.0,"timestamp":1626994928259}
1626994928.234999: {"feed":"book","product_id":"PI_ETHUSD","side":"buy","seq":26660932,"price":1994.85,"qty":0.0,"timestamp":1626994928262}
1626994928.238354: {"feed":"book","product_id":"PI_ETHUSD","side":"buy","seq":26660933,"price":2003.0,"qty":5828.0,"timestamp":1626994928265}
1626994928.250162: {"feed":"book","product_id":"PI_ETHUSD","side":"sell","seq":26660934,"price":2005.8,"qty":0.0,"timestamp":1626994928276}
1626994928.257719: {"feed":"book","product_id":"FI_XBTUSD_210924","side":"buy","seq":13501566,"price":32153.0,"qty":0.0,"timestamp":1626994928283}
1626994928.257843: {"feed":"book","product_id":"FI_XBTUSD_210924","side":"buy","seq":13501567,"price":32166.0,"qty":20902.0,"timestamp":1626994928283}
1626994928.260963: {"feed":"book","product_id":"PI_ETHUSD","side":"buy","seq":26660935,"price":1999.65,"qty":0.0,"timestamp":1626994928286}
1626994928.261017: {"feed":"book","product_id":"PI_ETHUSD","side":"buy","seq":26660936,"price":1999.75,"qty":500001.0,"timestamp":1626994928286}
1626994928.2610502: {"feed":"book","product_id":"PI_ETHUSD","side":"buy","seq":26660937,"price":1994.95,"qty":0.0,"timestamp":1626994928286}
1626994928.2610781: {"feed":"book","product_id":"PI_ETHUSD","side":"buy","seq":26660938,"price":1995.05,"qty":500002.0,"timestamp":1626994928286}
1626994928.2611048: {"feed":"book","product_id":"FI_ETHUSD_211231","side":"sell","seq":2198969,"price":2042.25,"qty":0.0,"timestamp":1626994928286}
1626994928.261131: {"feed":"book","product_id":"PI_ETHUSD","side":"sell","seq":26660939,"price":2013.2,"qty":0.0,"timestamp":1626994928286}
1626994928.2611551: {"feed":"book","product_id":"PI_ETHUSD","side":"sell","seq":26660940,"price":2013.1,"qty":500002.0,"timestamp":1626994928286}
1626994928.261177: {"feed":"book","product_id":"FI_ETHUSD_211231","side":"sell","seq":2198970,"price":2050.15,"qty":250002.0,"timestamp":1626994928286}
1626994928.261197: {"feed":"book","product_id":"PI_ETHUSD","side":"sell","seq":26660941,"price":2005.35,"qty":4951.0,"timestamp":1626994928287}
1626994928.265857: {"feed":"book","product_id":"PI_ETHUSD","side":"sell","seq":26660942,"price":2005.9,"qty":0.0,"timestamp":1626994928292}
1626994928.2659001: {"feed":"book","product_id":"PI_ETHUSD","side":"sell","seq":26660943,"price":2005.75,"qty":18544.0,"timestamp":1626994928292}
1626994928.2659252: {"feed":"book","product_id":"PI_ETHUSD","side":"sell","seq":26660944,"price":2007.0,"qty":0.0,"timestamp":1626994928292}
1626994928.2659478: {"feed":"book","product_id":"PI_ETHUSD","side":"sell","seq":26660945,"price":2006.75,"qty":166038.0,"timestamp":1626994928292}
1626994928.2679539: {"feed":"book","product_id":"PI_XRPUSD","side":"buy","seq":3456141,"price":0.588,"qty":13867.0,"timestamp":1626994928295}
1626994928.2726321: {"feed":"book","product_id":"PI_XRPUSD","side":"buy","seq":3456142,"price":0.5882,"qty":4134.0,"timestamp":1626994928297}
1626994928.272726: {"feed":"book","product_id":"PI_XRPUSD","side":"buy","seq":3456143,"price":0.588,"qty":3917.0,"timestamp":1626994928298}
1626994928.2727659: {"feed":"book","product_id":"PI_XRPUSD","side":"buy","seq":3456144,"price":0.5879,"qty":14139.0,"timestamp":1626994928298}
1626994928.27299: {"feed":"book","product_id":"PI_XRPUSD","side":"buy","seq":3456145,"price":0.5879,"qty":4189.0,"timestamp":1626994928301}
1626994928.273035: {"feed":"book","product_id":"PI_XRPUSD","side":"buy","seq":3456146,"price":0.588,"qty":13867.0,"timestamp":1626994928301}
1626994928.292141: {"feed":"book","product_id":"PI_XRPUSD","side":"buy","seq":3456147,"price":0.5882,"qty":4334.0,"timestamp":1626994928319}
1626994928.3190742: {"feed":"book","product_id":"PI_ETHUSD","side":"buy","seq":26660946,"price":2003.5,"qty":16426.0,"timestamp":1626994928346}
1626994928.319137: {"feed":"book","product_id":"PI_ETHUSD","side":"buy","seq":26660947,"price":2003.4,"qty":20000.0,"timestamp":1626994928346}
1626994928.338736: {"feed":"book","product_id":"PI_ETHUSD","side":"buy","seq":26660948,"price":2003.4,"qty":0.0,"timestamp":1626994928366}
1626994928.3388648: {"feed":"book","product_id":"PI_ETHUSD","side":"buy","seq":26660949,"price":2003.5,"qty":36426.0,"timestamp":1626994928366}
1626994928.3429928: {"feed":"book","product_id":"PI_ETHUSD","side":"buy","seq":26660950,"price":2003.5,"qty":20600.0,"timestamp":1626994928369}
1626994928.343105: {"feed":"book","product_id":"PI_ETHUSD","side":"buy","seq":26660951,"price":2003.6,"qty":15826.0,"timestamp":1626994928369}
1626994928.345109: {"feed":"book","product_id":"PI_ETHUSD","side":"buy","seq":26660952,"price":2002.85,"qty":0.0,"timestamp":1626994928372}
1626994928.346217: {"feed":"book","product_id":"PI_ETHUSD","side":"sell","seq":26660953,"price":2005.75,"qty":14432.0,"timestamp":1626994928373}
1626994928.346328: {"feed":"book","product_id":"PI_ETHUSD","side":"buy","seq":26660954,"price":2003.1,"qty":4083.0,"timestamp":1626994928373}
1626994928.34741: {"feed":"book","product_id":"PI_ETHUSD","side":"buy","seq":26660955,"price":2002.45,"qty":0.0,"timestamp":1626994928374}
1626994928.377347: {"feed":"book","product_id":"PI_ETHUSD","side":"buy","seq":26660956,"price":2002.85,"qty":4077.0,"timestamp":1626994928404}
1626994928.3774679: {"feed":"book","product_id":"PI_ETHUSD","side":"sell","seq":26660957,"price":2006.1,"qty":3831.0,"timestamp":1626994928404}
1626994928.3775291: {"feed":"book","product_id":"PI_ETHUSD","side":"buy","seq":26660958,"price":2003.5,"qty":600.0,"timestamp":1626994928404}
1626994928.3775702: {"feed":"book","product_id":"PI_ETHUSD","side":"buy","seq":26660959,"price":2003.6,"qty":35826.0,"timestamp":1626994928404}
1626994928.3829: {"feed":"book","product_id":"PI_ETHUSD","side":"sell","seq":26660960,"price":2004.75,"qty":0.0,"timestamp":1626994928404}
1626994928.383022: {"feed":"book","product_id":"PI_ETHUSD","side":"sell","seq":26660961,"price":2006.3,"qty":31944.0,"timestamp":1626994928404}
1626994928.3830578: {"feed":"book","product_id":"PI_ETHUSD","side":"buy","seq":26660962,"price":2003.05,"qty":5199.0,"timestamp":1626994928404}
1626994928.383085: {"feed":"book","product_id":"FI_XBTUSD_210730","side":"sell","seq":5159971,"price":32200.5,"qty":0.0,"timestamp":1626994928404}
1626994928.383117: {"feed":"book","product_id":"FI_XBTUSD_210730","side":"sell","seq":5159972,"price":32201.5,"qty":251.0,"timestamp":1626994928404}
1626994928.3880022: {"feed":"book","product_id":"PI_ETHUSD","side":"sell","seq":26660963,"price":2007.65,"qty":0.0,"timestamp":1626994928404}
1626994928.3880901: {"feed":"book","product_id":"PI_ETHUSD","side":"sell","seq":26660964,"price":2008.4,"qty":150000.0,"timestamp":1626994928404}
1626994928.388133: {"feed":"book","product_id":"PI_ETHUSD","side":"buy","seq":26660965,"price":2002.6,"qty":14036.0,"timestamp":1626994928411}
1626994928.4020832: {"feed":"book","product_id":"PI_ETHUSD","side":"sell","seq":26660966,"price":2006.0,"qty":2500.0,"timestamp":1626994928428}
1626994928.402206: {"feed":"book","product_id":"PI_ETHUSD","side":"sell","seq":26660967,"price":2008.25,"qty":7500.0,"timestamp":1626994928428}
1626994928.406324: {"feed":"book","product_id":"PI_ETHUSD","side":"buy","seq":26660968,"price":2002.85,"qty":6577.0,"timestamp":1626994928430}
1626994928.412971: {"feed":"book","product_id":"FI_XBTUSD_210924","side":"sell","seq":13501568,"price":32234.0,"qty":0.0,"timestamp":1626994928440}
1626994928.4134872: {"feed":"book","product_id":"FI_XBTUSD_210924","side":"buy","seq":13501569,"price":32154.0,"qty":0.0,"timestamp":1626994928440}
1626994928.414324: {"feed":"book","product_id":"FI_XBTUSD_210924","side":"buy","seq":13501570,"price":32116.5,"qty":0.0,"timestamp":1626994928440}
1626994928.417054: {"feed":"book","product_id":"FI_XBTUSD_210924","side":"sell","seq":13501571,"price":32223.5,"qty":0.0,"timestamp":1626994928445}
1626994928.4171772: {"feed":"book","product_id":"FI_XBTUSD_210924","side":"sell","seq":13501572,"price":32224.5,"qty":251.0,"timestamp":1626994928445}
1626994928.419183: {"feed":"book","product_id":"FI_ETHUSD_211231","side":"sell","seq":2198971,"price":2050.15,"qty":0.0,"timestamp":1626994928446}
1626994928.419308: {"feed":"book","product_id":"FI_ETHUSD_211231","side":"sell","seq":2198972,"price":2042.35,"qty":250002.0,"timestamp":1626994928446}
1626994928.430937: {"feed":"book","product_id":"FI_XBTUSD_210924","side":"sell","seq":13501573,"price":32235.5,"qty":17578.0,"timestamp":1626994928458}
1626994928.441617: {"feed":"book","product_id":"PI_ETHUSD","side":"sell","seq":26660969,"price":2006.75,"qty":16038.0,"timestamp":1626994928469}
1626994928.441726: {"feed":"book","product_id":"PI_ETHUSD","side":"sell","seq":26660970,"price":2007.2,"qty":154061.0,"timestamp":1626994928469}
1626994928.4490829: {"feed":"book","product_id":"FI_ETHUSD_211231","side":"sell","seq":2198973,"price":2042.35,"qty":0.0,"timestamp":1626994928474}
1626994928.449208: {"feed":"book","product_id":"FI_ETHUSD_211231","side":"sell","seq":2198974,"price":2050.15,"qty":250002.0,"timestamp":1626994928474}
1626994928.455447: {"feed":"book","product_id":"FI_ETHUSD_211231","side":"sell","seq":2198975,"price":2034.2,"qty":0.0,"timestamp":1626994928482}
1626994928.464525: {"feed":"book","product_id":"PI_ETHUSD","side":"sell","seq":26660971,"price":2007.25,"qty":0.0,"timestamp":1626994928490}
1626994928.464651: {"feed":"book","product_id":"PI_ETHUSD","side":"sell","seq":26660972,"price":2007.55,"qty":504990.0,"timestamp":1626994928490}
1626994928.466588: {"feed":"book","product_id":"PI_XRPUSD","side":"buy","seq":3456148,"price":0.5882,"qty":200.0,"timestamp":1626994928494}
1626994928.473532: {"feed":"book","product_id":"PI_ETHUSD","side":"sell","seq":26660973,"price":2005.35,"qty":0.0,"timestamp":1626994928496}
1626994928.4736562: {"feed":"book","product_id":"PI_ETHUSD","side":"buy","seq":26660974,"price":2000.95,"qty":0.0,"timestamp":1626994928496}
1626994928.4737191: {"feed":"book","product_id":"PI_ETHUSD","side":"buy","seq":26660975,"price":2001.85,"qty":15274.0,"timestamp":1626994928496}
1626994928.473763: {"feed":"book","product_id":"PI_ETHUSD","side":"sell","seq":26660976,"price":2005.75,"qty":4112.0,"timestamp":1626994928496}
1626994928.4737978: {"feed":"book","product_id":"PI_ETHUSD","side":"sell","seq":26660977,"price":2005.9,"qty":10289.0,"timestamp":1626994928496}
1626994928.473862: {"feed":"book","product_id":"PI_ETHUSD","side":"sell","seq":26660978,"price":2006.75,"qty":0.0,"timestamp":1626994928496}
1626994928.47389: {"feed":"book","product_id":"PI_ETHUSD","side":"sell","seq":26660979,"price":2007.0,"qty":16836.0,"timestamp":1626994928496}
1626994928.4739158: {"feed":"book","product_id":"PI_ETHUSD","side":"buy","seq":26660980,"price":2000.55,"qty":0.0,"timestamp":1626994928496}
1626994928.473943: {"feed":"book","product_id":"PI_ETHUSD","side":"buy","seq":26660981,"price":2000.85,"qty":15945.0,"timestamp":1626994928496}
1626994928.473968: {"feed":"book","product_id":"PI_ETHUSD","side":"buy","seq":26660982,"price":1999.7,"qty":0.0,"timestamp":1626994928497}
1626994928.473993: {"feed":"book","product_id":"PI_ETHUSD","side":"buy","seq":26660983,"price":2000.05,"qty":22587.0,"timestamp":1626994928497}
1626994928.474018: {"feed":"book","product_id":"PI_ETHUSD","side":"sell","seq":26660984,"price":2007.6,"qty":0.0,"timestamp":1626994928497}
1626994928.474043: {"feed":"book","product_id":"PI_ETHUSD","side":"sell","seq":26660985,"price":2007.7,"qty":26643.0,"timestamp":1626994928497}
1626994928.4740639: {"feed":"book","product_id":"PI_XRPUSD","side":"buy","seq":3456149,"price":0.588,"qty":3917.0,"timestamp":1626994928497}
1626994928.474085: {"feed":"book","product_id":"PI_XRPUSD","side":"buy","seq":3456150,"price":0.5879,"qty":14139.0,"timestamp":1626994928497}
1626994928.4778209: {"feed":"book","product_id":"PI_ETHUSD","side":"buy","seq":26660986,"price":1999.75,"qty":0.0,"timestamp":1626994928505}
1626994928.477952: {"feed":"book","product_id":"PI_ETHUSD","side":"buy","seq":26660987,"price":1999.6,"qty":503886.0,"timestamp":1626994928505}
1626994928.4780102: {"feed":"book","product_id":"PI_ETHUSD","side":"sell","seq":26660988,"price":2007.55,"qty":4989.0,"timestamp":1626994928505}
1626994928.4780538: {"feed":"book","product_id":"PI_ETHUSD","side":"sell","seq":26660989,"price":2007.65,"qty":500001.0,"timestamp":1626994928505}
1626994928.478372: {"feed":"book","product_id":"PI_ETHUSD","side":"buy","seq":26660990,"price":2002.15,"qty":8773.0,"timestamp":1626994928506}
1626994928.479502: {"feed":"book","product_id":"PI_ETHUSD","side":"buy","seq":26660991,"price":2001.4,"qty":0.0,"timestamp":1626994928507}
1626994928.483856: {"feed":"book","product_id":"PI_XRPUSD","side":"buy","seq":3456151,"price":0.5882,"qty":0.0,"timestamp":1626994928511}
1626994928.499012: {"feed":"book","product_id":"PI_ETHUSD","side":"sell","seq":26660992,"price":2005.45,"qty":119535.0,"timestamp":1626994928519}
1626994928.504406: {"feed":"book","product_id":"PI_ETHUSD","side":"buy","seq":26660993,"price":2003.6,"qty":15826.0,"timestamp":1626994928531}
1626994928.504492: {"feed":"book","product_id":"PI_ETHUSD","side":"buy","seq":26660994,"price":2003.5,"qty":20600.0,"timestamp":1626994928531}
1626994928.5073678: {"feed":"book","product_id":"PI_ETHUSD","side":"buy","seq":26660995,"price":2003.6,"qty":0.0,"timestamp":1626994928535}
1626994928.507456: {"feed":"book","product_id":"PI_ETHUSD","side":"buy","seq":26660996,"price":2003.7,"qty":15826.0,"timestamp":1626994928535}
1626994928.507499: {"feed":"book","product_id":"PI_LTCUSD","side":"sell","seq":3423040,"price":119.54,"qty":8227.0,"timestamp":1626994928535}
1626994928.507925: {"feed":"book","product_id":"PI_LTCUSD","side":"sell","seq":3423041,"price":119.58,"qty":31610.0,"timestamp":1626994928536}
1626994928.510525: {"feed":"book","product_id":"PI_LTCUSD","side":"buy","seq":3423042,"price":119.25,"qty":63.0,"timestamp":1626994928537}
1626994928.512668: {"feed":"book","product_id":"PI_LTCUSD","side":"buy","seq":3423043,"price":119.29,"qty":11807.0,"timestamp":1626994928539}
1626994928.512722: {"feed":"book","product_id":"PI_ETHUSD","side":"buy","seq":26660997,"price":2003.7,"qty":0.0,"timestamp":1626994928539}
1626994928.5127628: {"feed":"book","product_id":"PI_ETHUSD","side":"buy","seq":26660998,"price":2003.55,"qty":15826.0,"timestamp":1626994928539}
1626994928.515053: {"feed":"book","product_id":"PI_LTCUSD","side":"buy","seq":3423044,"price":119.18,"qty":5561.0,"timestamp":1626994928542}
1626994928.5151339: {"feed":"book","product_id":"PI_LTCUSD","side":"buy","seq":3423045,"price":119.19,"qty":4891.0,"timestamp":1626994928542}
1626994928.520417: {"feed":"book","product_id":"FI_XBTUSD_210730","side":"buy","seq":5159973,"price":30833.0,"qty":12000.0,"timestamp":1626994928547}
1626994928.5204961: {"feed":"book","product_id":"FI_XBTUSD_210730","side":"buy","seq":5159974,"price":31514.0,"qty":6000.0,"timestamp":1626994928547}
1626994928.5205278: {"feed":"book","product_id":"FI_XBTUSD_210730","side":"buy","seq":5159975,"price":30152.0,"qty":24000.0,"timestamp":1626994928547}
1626994928.52269: {"feed":"book","product_id":"FI_XBTUSD_210924","side":"buy","seq":13501574,"price":32188.5,"qty":881.0,"timestamp":1626994928549}
1626994928.52277: {"feed":"book","product_id":"FI_XBTUSD_210924","side":"buy","seq":13501575,"price":32188.5,"qty":16511.0,"timestamp":1626994928549}
1626994928.5228019: {"feed":"book","product_id":"FI_XBTUSD_210924","side":"sell","seq":13501576,"price":32235.5,"qty":940.0,"timestamp":1626994928549}
1626994928.522828: {"feed":"book","product_id":"FI_XBTUSD_210924","side":"sell","seq":13501577,"price":32235.5,"qty":16805.0,"timestamp":1626994928549}
1626994928.522867: {"feed":"book","product_id":"FI_XBTUSD_210924","side":"sell","seq":13501578,"price":32258.5,"qty":3000.0,"timestamp":1626994928549}
1626994928.522889: {"feed":"book","product_id":"FI_XBTUSD_210924","side":"sell","seq":13501579,"price":32258.5,"qty":23960.0,"timestamp":1626994928549}
1626994928.5229099: {"feed":"book","product_id":"FI_XBTUSD_210924","side":"buy","seq":13501580,"price":32166.0,"qty":0.0,"timestamp":1626994928549}
1626994928.5229461: {"feed":"book","product_id":"FI_XBTUSD_210924","side":"buy","seq":13501581,"price":32166.0,"qty":20903.0,"timestamp":1626994928549}
1626994928.52322: {"feed":"book","product_id":"PI_ETHUSD","side":"buy","seq":26660999,"price":2003.55,"qty":0.0,"timestamp":1626994928549}
1626994928.523274: {"feed":"book","product_id":"PI_ETHUSD","side":"buy","seq":26661000,"price":2003.6,"qty":15826.0,"timestamp":1626994928549}
1626994928.528532: {"feed":"book","product_id":"PI_ETHUSD","side":"buy","seq":26661001,"price":2003.5,"qty":600.0,"timestamp":1626994928553}
1626994928.528645: {"feed":"book","product_id":"PI_ETHUSD","side":"buy","seq":26661002,"price":2003.6,"qty":35826.0,"timestamp":1626994928553}
1626994928.528695: {"feed":"book","product_id":"PI_ETHUSD","side":"buy","seq":26661003,"price":2003.6,"qty":20000.0,"timestamp":1626994928553}
1626994928.528733: {"feed":"book","product_id":"PI_ETHUSD","side":"buy","seq":26661004,"price":2003.7,"qty":15826.0,"timestamp":1626994928553}
1626994928.5537689: {"feed":"book","product_id":"PI_LTCUSD","side":"sell","seq":3423046,"price":119.54,"qty":8166.0,"timestamp":1626994928579}
1626994928.577903: {"feed":"book","product_id":"FI_XBTUSD_210924","side":"buy","seq":13501582,"price":32155.0,"qty":0.0,"timestamp":1626994928604}
1626994928.6113029: {"feed":"book","product_id":"FI_XBTUSD_210730","side":"buy","seq":5159976,"price":31514.0,"qty":11000.0,"timestamp":1626994928638}
1626994928.668309: {"feed":"book","product_id":"PI_LTCUSD","side":"buy","seq":3423047,"price":119.34,"qty":28233.0,"timestamp":1626994928695}
1626994928.668394: {"feed":"book","product_id":"PI_ETHUSD","side":"buy","seq":26661005,"price":2004.0,"qty":94218.0,"timestamp":1626994928695}
1626994928.672908: {"feed":"book","product_id":"PI_LTCUSD","side":"buy","seq":3423048,"price":119.19,"qty":3891.0,"timestamp":1626994928699}
1626994928.672987: {"feed":"book","product_id":"PI_LTCUSD","side":"buy","seq":3423049,"price":119.22,"qty":37370.0,"timestamp":1626994928699}
1626994928.6730208: {"feed":"book","product_id":"PI_ETHUSD","side":"buy","seq":26661006,"price":2001.85,"qty":5005.0,"timestamp":1626994928700}
1626994928.673048: {"feed":"book","product_id":"PI_ETHUSD","side":"buy","seq":26661007,"price":2000.95,"qty":14986.0,"timestamp":1626994928700}
1626994928.6751418: {"feed":"book","product_id":"PI_ETHUSD","side":"buy","seq":26661008,"price":2000.85,"qty":0.0,"timestamp":1626994928700}
1626994928.6751978: {"feed":"book","product_id":"PI_ETHUSD","side":"buy","seq":26661009,"price":2000.55,"qty":17979.0,"timestamp":1626994928700}
1626994928.675231: {"feed":"book","product_id":"PI_ETHUSD","side":"buy","seq":26661010,"price":2000.05,"qty":0.0,"timestamp":1626994928700}
1626994928.6752582: {"feed":"book","product_id":"PI_ETHUSD","side":"buy","seq":26661011,"price":1999.8,"qty":23660.0,"timestamp":1626994928700}
1626994928.687493: {"feed":"book","product_id":"PI_ETHUSD","side":"buy","seq":26661012,"price":2002.9,"qty":49941.0,"timestamp":1626994928714}
1626994928.691742: {"feed":"book","product_id":"FI_XBTUSD_210924","side":"sell","seq":13501583,"price":32240.0,"qty":2430.0,"timestamp":1626994928718}
1626994928.6918342: {"feed":"book","product_id":"FI_XBTUSD_210924","side":"buy","seq":13501584,"price":32160.5,"qty":1900.0,"timestamp":1626994928718}
1626994928.691871: {"feed":"book","product_id":"FI_XBTUSD_210924","side":"buy","seq":13501585,"price":32142.0,"qty":1900.0,"timestamp":1626994928718}
1626994928.699902: {"feed":"book","product_id":"FI_XBTUSD_210730","side":"buy","seq":5159977,"price":30833.0,"qty":22000.0,"timestamp":1626994928726}
1626994928.761014: {"feed":"book","product_id":"PI_ETHUSD","side":"sell","seq":26661013,"price":2006.5,"qty":3964.0,"timestamp":1626994928787}
1626994928.768948: {"feed":"book","product_id":"PI_LTCUSD","side":"sell","seq":3423050,"price":119.59,"qty":9133.0,"timestamp":1626994928795}
1626994928.7690299: {"feed":"book","product_id":"PI_LTCUSD","side":"sell","seq":3423051,"price":119.56,"qty":2096.0,"timestamp":1626994928796}
1626994928.773431: {"feed":"book","product_id":"PI_ETHUSD","side":"sell","seq":26661014,"price":2007.0,"qty":21836.0,"timestamp":1626994928801}
1626994928.793331: {"feed":"book","product_id":"FI_XBTUSD_210730","side":"buy","seq":5159978,"price":30152.0,"qty":44000.0,"timestamp":1626994928820}
1626994928.817764: {"feed":"book","product_id":"PI_XRPUSD","side":"buy","seq":3456152,"price":0.5877,"qty":5005.0,"timestamp":1626994928845}
1626994928.818523: {"feed":"book","product_id":"PI_XRPUSD","side":"buy","seq":3456153,"price":0.5879,"qty":18336.0,"timestamp":1626994928847}
1626994928.861969: {"feed":"book","product_id":"PI_XRPUSD","side":"buy","seq":3456154,"price":0.5878,"qty":11333.0,"timestamp":1626994928889}
1626994928.862077: {"feed":"book","product_id":"PI_XRPUSD","side":"buy","seq":3456155,"price":0.5879,"qty":26336.0,"timestamp":1626994928889}
1626994928.86544: {"feed":"book","product_id":"PI_XRPUSD","side":"buy","seq":3456156,"price":0.5879,"qty":16386.0,"timestamp":1626994928892}
1626994928.865557: {"feed":"book","product_id":"PI_XRPUSD","side":"buy","seq":3456157,"price":0.588,"qty":13867.0,"timestamp":1626994928892}
1626994928.8773189: {"feed":"book","product_id":"PI_ETHUSD","side":"buy","seq":26661015,"price":2000.95,"qty":0.0,"timestamp":1626994928904}
1626994928.877412: {"feed":"book","product_id":"PI_ETHUSD","side":"buy","seq":26661016,"price":2001.85,"qty":15123.0,"timestamp":1626994928904}
1626994928.877447: {"feed":"book","product_id":"PI_ETHUSD","side":"buy","seq":26661017,"price":2000.55,"qty":0.0,"timestamp":1626994928904}
1626994928.8774788: {"feed":"book","product_id":"PI_ETHUSD","side":"buy","seq":26661018,"price":2000.85,"qty":15718.0,"timestamp":1626994928904}
1626994928.8777962: {"feed":"book","product_id":"PI_ETHUSD","side":"buy","seq":26661019,"price":1999.8,"qty":0.0,"timestamp":1626994928904}
1626994928.8778481: {"feed":"book","product_id":"PI_ETHUSD","side":"buy","seq":26661020,"price":1999.65,"qty":24668.0,"timestamp":1626994928904}
1626994928.880173: {"feed":"book","product_id":"PI_ETHUSD","side":"buy","seq":26661021,"price":2003.7,"qty":0.0,"timestamp":1626994928905}
1626994928.880262: {"feed":"book","product_id":"PI_ETHUSD","side":"buy","seq":26661022,"price":2003.6,"qty":35826.0,"timestamp":1626994928905}
1626994928.92674: {"feed":"book","product_id":"PI_ETHUSD","side":"sell","seq":26661023,"price":2018.15,"qty":0.0,"timestamp":1626994928952}
1626994928.92683: {"feed":"book","product_id":"PI_ETHUSD","side":"sell","seq":26661024,"price":2019.2,"qty":2500.0,"timestamp":1626994928952}
1626994928.9691079: {"feed":"book","product_id":"FI_ETHUSD_210730","side":"sell","seq":2138670,"price":2011.15,"qty":0.0,"timestamp":1626994928993}
1626994928.969197: {"feed":"book","product_id":"FI_ETHUSD_210730","side":"sell","seq":2138671,"price":2014.85,"qty":45421.0,"timestamp":1626994928993}
1626994928.9692411: {"feed":"book","product_id":"FI_ETHUSD_211231","side":"sell","seq":2198976,"price":2042.3,"qty":0.0,"timestamp":1626994928993}
1626994928.9692779: {"feed":"book","product_id":"FI_ETHUSD_211231","side":"sell","seq":2198977,"price":2050.1,"qty":45099.0,"timestamp":1626994928993}
1626994928.9693062: {"feed":"book","product_id":"PI_ETHUSD","side":"sell","seq":26661025,"price":2007.3,"qty":0.0,"timestamp":1626994928993}
1626994928.9693382: {"feed":"book","product_id":"PI_ETHUSD","side":"sell","seq":26661026,"price":2009.7,"qty":22203.0,"timestamp":1626994928993}
1626994928.969366: {"feed":"book","product_id":"FI_ETHUSD_210730","side":"buy","seq":2138672,"price":1991.2,"qty":0.0,"timestamp":1626994928993}
1626994928.969394: {"feed":"book","product_id":"FI_ETHUSD_210730","side":"buy","seq":2138673,"price":1991.3,"qty":44704.0,"timestamp":1626994928993}
1626994928.96942: {"feed":"book","product_id":"FI_ETHUSD_211231","side":"sell","seq":2198978,"price":2056.7,"qty":0.0,"timestamp":1626994928993}
1626994928.969446: {"feed":"book","product_id":"FI_ETHUSD_211231","side":"sell","seq":2198979,"price":2050.1,"qty":89404.0,"timestamp":1626994928993}
1626994928.9694679: {"feed":"book","product_id":"PI_ETHUSD","side":"sell","seq":26661027,"price":2008.3,"qty":0.0,"timestamp":1626994928993}
1626994928.969494: {"feed":"book","product_id":"PI_ETHUSD","side":"sell","seq":26661028,"price":2010.7,"qty":45949.0,"timestamp":1626994928993}
1626994928.9695191: {"feed":"book","product_id":"PI_ETHUSD","side":"sell","seq":26661029,"price":2006.9,"qty":0.0,"timestamp":1626994928993}
1626994928.969544: {"feed":"book","product_id":"PI_ETHUSD","side":"sell","seq":26661030,"price":2008.7,"qty":12891.0,"timestamp":1626994928993}
1626994928.9695659: {"feed":"book","product_id":"PI_ETHUSD","side":"buy","seq":26661031,"price":2000.9,"qty":0.0,"timestamp":1626994928993}
1626994928.969593: {"feed":"book","product_id":"PI_ETHUSD","side":"buy","seq":26661032,"price":1999.35,"qty":9013.0,"timestamp":1626994928993}
1626994928.969619: {"feed":"book","product_id":"PI_ETHUSD","side":"sell","seq":26661033,"price":2006.3,"qty":27350.0,"timestamp":1626994928993}
1626994928.96964: {"feed":"book","product_id":"PI_ETHUSD","side":"sell","seq":26661034,"price":2007.7,"qty":31237.0,"timestamp":1626994928993}
1626994928.9696598: {"feed":"book","product_id":"PI_ETHUSD","side":"buy","seq":26661035,"price":2003.3,"qty":4086.0,"timestamp":1626994928995}
1626994928.969959: {"feed":"book","product_id":"PI_ETHUSD","side":"sell","seq":26661036,"price":2005.75,"qty":7896.0,"timestamp":1626994928996}
1626994928.978255: {"feed":"book","product_id":"PI_ETHUSD","side":"buy","seq":26661037,"price":2000.3,"qty":0.0,"timestamp":1626994929004}
1626994928.9783459: {"feed":"book","product_id":"PI_ETHUSD","side":"buy","seq":26661038,"price":2000.75,"qty":150000.0,"timestamp":1626994929004}
1626994929.015193: {"feed":"book","product_id":"FI_XRPUSD_210924","side":"buy","seq":602278,"price":0.5828,"qty":0.0,"timestamp":1626994929042}
1626994929.01532: {"feed":"book","product_id":"FI_XRPUSD_210924","side":"buy","seq":602279,"price":0.584,"qty":61.0,"timestamp":1626994929042}
1626994929.023097: {"feed":"book","product_id":"PI_ETHUSD","side":"buy","seq":26661039,"price":2002.9,"qty":6331.0,"timestamp":1626994929050}
1626994929.100687: {"feed":"book","product_id":"PI_ETHUSD","side":"sell","seq":26661040,"price":2005.9,"qty":0.0,"timestamp":1626994929108}
1626994929.1007822: {"feed":"book","product_id":"PI_ETHUSD","side":"sell","seq":26661041,"price":2006.25,"qty":11905.0,"timestamp":1626994929108}
1626994929.100825: {"feed":"book","product_id":"PI_ETHUSD","side":"sell","seq":26661042,"price":2007.7,"qty":8564.0,"timestamp":1626994929108}
1626994929.100855: {"feed":"book","product_id":"PI_ETHUSD","side":"sell","seq":26661043,"price":2008.25,"qty":32923.0,"timestamp":1626994929108}
1626994929.100877: {"feed":"book","product_id":"PI_ETHUSD","side":"buy","seq":26661044,"price":1999.65,"qty":0.0,"timestamp":1626994929108}
1626994929.100908: {"feed":"book","product_id":"PI_ETHUSD","side":"buy","seq":26661045,"price":2000.05,"qty":22937.0,"timestamp":1626994929108}
1626994929.100935: {"feed":"book","product_id":"PI_ETHUSD","side":"sell","seq":26661046,"price":2007.65,"qty":0.0,"timestamp":1626994929119}
1626994929.100961: {"feed":"book","product_id":"PI_ETHUSD","side":"sell","seq":26661047,"price":2007.7,"qty":508565.0,"timestamp":1626994929119}
1626994929.100982: {"feed":"book","product_id":"FI_ETHUSD_210730","side":"buy","seq":2138674,"price":1996.65,"qty":0.0,"timestamp":1626994929119}
1626994929.101012: {"feed":"book","product_id":"FI_ETHUSD_210730","side":"buy","seq":2138675,"price":1996.95,"qty":250001.0,"timestamp":1626994929119}
1626994929.101037: {"feed":"book","product_id":"FI_ETHUSD_210730","side":"buy","seq":2138676,"price":1991.25,"qty":0.0,"timestamp":1626994929119}
1626994929.1010618: {"feed":"book","product_id":"FI_ETHUSD_210730","side":"buy","seq":2138677,"price":1991.35,"qty":250002.0,"timestamp":1626994929119}
1626994929.101087: {"feed":"book","product_id":"FI_ETHUSD_210730","side":"sell","seq":2138678,"price":2014.9,"qty":0.0,"timestamp":1626994929119}
1626994929.101113: {"feed":"book","product_id":"FI_ETHUSD_210730","side":"sell","seq":2138679,"price":2014.8,"qty":250002.0,"timestamp":1626994929119}
1626994929.101137: {"feed":"book","product_id":"FI_ETHUSD_211231","side":"sell","seq":2198980,"price":2050.15,"qty":0.0,"timestamp":1626994929119}
1626994929.101164: {"feed":"book","product_id":"FI_ETHUSD_211231","side":"sell","seq":2198981,"price":2050.05,"qty":250002.0,"timestamp":1626994929119}
1626994929.125957: {"feed":"book","product_id":"FI_ETHUSD_211231","side":"sell","seq":2198982,"price":2034.7,"qty":2000.0,"timestamp":1626994929152}
1626994929.126046: {"feed":"book","product_id":"PI_ETHUSD","side":"sell","seq":26661048,"price":2004.5,"qty":2246.0,"timestamp":1626994929153}
1626994929.132652: {"feed":"book","product_id":"PI_XRPUSD","side":"sell","seq":3456158,"price":0.5892,"qty":24742.0,"timestamp":1626994929159}
1626994929.132735: {"feed":"book","product_id":"PI_XRPUSD","side":"sell","seq":3456159,"price":0.5894,"qty":16649.0,"timestamp":1626994929159}
1626994929.132769: {"feed":"book","product_id":"PI_XRPUSD","side":"buy","seq":3456160,"price":0.5879,"qty":12197.0,"timestamp":1626994929160}
1626994929.1336992: {"feed":"book","product_id":"PI_XRPUSD","side":"buy","seq":3456161,"price":0.5881,"qty":4303.0,"timestamp":1626994929162}
1626994929.1347442: {"feed":"book","product_id":"PI_XRPUSD","side":"buy","seq":3456162,"price":0.588,"qty":3917.0,"timestamp":1626994929163}
1626994929.134798: {"feed":"book","product_id":"PI_XRPUSD","side":"buy","seq":3456163,"price":0.5879,"qty":22147.0,"timestamp":1626994929163}
1626994929.140071: {"feed":"book","product_id":"PI_XRPUSD","side":"buy","seq":3456164,"price":0.5879,"qty":12197.0,"timestamp":1626994929166}
1626994929.140151: {"feed":"book","product_id":"PI_XRPUSD","side":"buy","seq":3456165,"price":0.588,"qty":13867.0,"timestamp":1626994929166}
1626994929.1491652: {"feed":"book","product_id":"PI_ETHUSD","side":"sell","seq":26661049,"price":2005.45,"qty":114385.0,"timestamp":1626994929172}
1626994929.14928: {"feed":"book","product_id":"FI_ETHUSD_210730","side":"buy","seq":2138680,"price":1997.25,"qty":0.0,"timestamp":1626994929173}
1626994929.149375: {"feed":"book","product_id":"FI_ETHUSD_210730","side":"buy","seq":2138681,"price":1999.0,"qty":400.0,"timestamp":1626994929173}
1626994929.149413: {"feed":"book","product_id":"PI_LTCUSD","side":"buy","seq":3423052,"price":119.09,"qty":0.0,"timestamp":1626994929174}
1626994929.1494532: {"feed":"book","product_id":"PI_LTCUSD","side":"buy","seq":3423053,"price":119.21,"qty":25320.0,"timestamp":1626994929174}
1626994929.1494799: {"feed":"book","product_id":"PI_LTCUSD","side":"sell","seq":3423054,"price":119.42,"qty":0.0,"timestamp":1626994929175}
1626994929.1495092: {"feed":"book","product_id":"PI_LTCUSD","side":"sell","seq":3423055,"price":119.44,"qty":320.0,"timestamp":1626994929175}
1626994929.149536: {"feed":"book","product_id":"PI_LTCUSD","side":"buy","seq":3423056,"price":119.24,"qty":0.0,"timestamp":1626994929177}
1626994929.1495628: {"feed":"book","product_id":"PI_LTCUSD","side":"buy","seq":3423057,"price":119.27,"qty":8000.0,"timestamp":1626994929177}
1626994929.149975: {"feed":"book","product_id":"PI_LTCUSD","side":"sell","seq":3423058,"price":119.48,"qty":0.0,"timestamp":1626994929177}
1626994929.150025: {"feed":"book","product_id":"PI_LTCUSD","side":"sell","seq":3423059,"price":119.5,"qty":9062.0,"timestamp":1626994929177}
1626994929.150053: {"feed":"book","product_id":"PI_XRPUSD","side":"buy","seq":3456166,"price":0.5881,"qty":5805.0,"timestamp":1626994929177}
1626994929.172116: {"feed":"book","product_id":"PI_LTCUSD","side":"buy","seq":3423060,"price":119.31,"qty":0.0,"timestamp":1626994929198}
1626994929.1722481: {"feed":"book","product_id":"PI_LTCUSD","side":"buy","seq":3423061,"price":119.32,"qty":320.0,"timestamp":1626994929198}
1626994929.197866: {"feed":"book","product_id":"PI_ETHUSD","side":"buy","seq":26661050,"price":2003.45,"qty":39316.0,"timestamp":1626994929223}
1626994929.225674: {"feed":"book","product_id":"PI_XRPUSD","side":"sell","seq":3456167,"price":0.5895,"qty":5579.0,"timestamp":1626994929251}
1626994929.2273269: {"feed":"book","product_id":"PI_ETHUSD","side":"buy","seq":26661051,"price":2003.6,"qty":20000.0,"timestamp":1626994929254}
1626994929.2274072: {"feed":"book","product_id":"PI_ETHUSD","side":"buy","seq":26661052,"price":2003.5,"qty":16426.0,"timestamp":1626994929254}
1626994929.2274392: {"feed":"book","product_id":"PI_ETHUSD","side":"buy","seq":26661053,"price":2003.6,"qty":0.0,"timestamp":1626994929254}
1626994929.2274802: {"feed":"book","product_id":"PI_ETHUSD","side":"buy","seq":26661054,"price":2003.5,"qty":36426.0,"timestamp":1626994929254}
1626994929.268339: {"feed":"book","product_id":"FI_ETHUSD_210730","side":"buy","seq":2138682,"price":1997.05,"qty":0.0,"timestamp":1626994929295}
1626994929.26843: {"feed":"book","product_id":"PI_XRPUSD","side":"buy","seq":3456168,"price":0.5881,"qty":9690.0,"timestamp":1626994929296}
1626994929.270902: {"feed":"book","product_id":"FI_ETHUSD_210730","side":"buy","seq":2138683,"price":1997.05,"qty":2057.0,"timestamp":1626994929298}
1626994929.285953: {"feed":"book","product_id":"PI_ETHUSD","side":"sell","seq":26661055,"price":2008.25,"qty":7500.0,"timestamp":1626994929312}
1626994929.28603: {"feed":"book","product_id":"PI_ETHUSD","side":"sell","seq":26661056,"price":2008.35,"qty":25728.0,"timestamp":1626994929312}
1626994929.295823: {"feed":"book","product_id":"PI_ETHUSD","side":"sell","seq":26661057,"price":2005.4,"qty":4854.0,"timestamp":1626994929322}
1626994929.3072488: {"feed":"book","product_id":"PI_ETHUSD","side":"sell","seq":26661058,"price":2007.2,"qty":4061.0,"timestamp":1626994929334}
1626994929.3073149: {"feed":"book","product_id":"PI_ETHUSD","side":"sell","seq":26661059,"price":2007.75,"qty":325154.0,"timestamp":1626994929334}
1626994929.307341: {"feed":"book","product_id":"PI_ETHUSD","side":"sell","seq":26661060,"price":2006.8,"qty":64.0,"timestamp":1626994929335}
1626994929.30736: {"feed":"book","product_id":"PI_ETHUSD","side":"sell","seq":26661061,"price":2007.4,"qty":46578.0,"timestamp":1626994929335}
1626994929.3161469: {"feed":"book","product_id":"PI_ETHUSD","side":"buy","seq":26661062,"price":2003.5,"qty":20600.0,"timestamp":1626994929342}
1626994929.3162649: {"feed":"book","product_id":"PI_ETHUSD","side":"buy","seq":26661063,"price":2003.15,"qty":15826.0,"timestamp":1626994929342}
1626994929.3163362: {"feed":"book","product_id":"PI_ETHUSD","side":"buy","seq":26661064,"price":2003.5,"qty":600.0,"timestamp":1626994929343}
1626994929.3163772: {"feed":"book","product_id":"PI_ETHUSD","side":"buy","seq":26661065,"price":2003.1,"qty":24083.0,"timestamp":1626994929343}
1626994929.3257651: {"feed":"book","product_id":"PI_ETHUSD","side":"buy","seq":26661066,"price":2003.1,"qty":4083.0,"timestamp":1626994929352}
1626994929.3258822: {"feed":"book","product_id":"PI_ETHUSD","side":"buy","seq":26661067,"price":2003.2,"qty":20000.0,"timestamp":1626994929352}
1626994929.326379: {"feed":"book","product_id":"PI_ETHUSD","side":"buy","seq":26661068,"price":2003.15,"qty":0.0,"timestamp":1626994929353}
1626994929.32647: {"feed":"book","product_id":"PI_ETHUSD","side":"buy","seq":26661069,"price":2003.25,"qty":15826.0,"timestamp":1626994929353}
1626994929.329185: {"feed":"book","product_id":"PI_XRPUSD","side":"sell","seq":3456169,"price":0.5893,"qty":4186.0,"timestamp":1626994929354}
1626994929.3293: {"feed":"book","product_id":"PI_XRPUSD","side":"sell","seq":3456170,"price":0.5896,"qty":10201.0,"timestamp":1626994929354}
1626994929.329352: {"feed":"book","product_id":"PI_ETHUSD","side":"buy","seq":26661070,"price":2003.2,"qty":0.0,"timestamp":1626994929355}
1626994929.3294148: {"feed":"book","product_id":"PI_ETHUSD","side":"buy","seq":26661071,"price":2003.25,"qty":35826.0,"timestamp":1626994929355}
1626994929.344141: {"feed":"book","product_id":"PI_ETHUSD","side":"buy","seq":26661072,"price":2003.25,"qty":15826.0,"timestamp":1626994929369}
1626994929.344259: {"feed":"book","product_id":"PI_ETHUSD","side":"buy","seq":26661073,"price":2003.15,"qty":20000.0,"timestamp":1626994929369}
1626994929.344324: {"feed":"book","product_id":"PI_ETHUSD","side":"buy","seq":26661074,"price":2003.25,"qty":0.0,"timestamp":1626994929370}
1626994929.34438: {"feed":"book","product_id":"PI_ETHUSD","side":"buy","seq":26661075,"price":2003.35,"qty":15826.0,"timestamp":1626994929370}
1626994929.344691: {"feed":"book","product_id":"PI_ETHUSD","side":"buy","seq":26661076,"price":2003.35,"qty":0.0,"timestamp":1626994929370}
1626994929.3447628: {"feed":"book","product_id":"PI_ETHUSD","side":"buy","seq":26661077,"price":2003.2,"qty":15826.0,"timestamp":1626994929370}
1626994929.346981: {"feed":"book","product_id":"PI_ETHUSD","side":"buy","seq":26661078,"price":2003.15,"qty":0.0,"timestamp":1626994929373}
1626994929.347111: {"feed":"book","product_id":"PI_ETHUSD","side":"buy","seq":26661079,"price":2003.3,"qty":24086.0,"timestamp":1626994929373}
1626994929.349084: {"feed":"book","product_id":"PI_ETHUSD","side":"buy","seq":26661080,"price":2003.9,"qty":0.0,"timestamp":1626994929376}
1626994929.3518: {"feed":"book","product_id":"FI_XBTUSD_210924","side":"buy","seq":13501586,"price":32188.5,"qty":881.0,"timestamp":1626994929377}
1626994929.3519108: {"feed":"book","product_id":"FI_XBTUSD_210924","side":"buy","seq":13501587,"price":32188.5,"qty":16179.0,"timestamp":1626994929377}
1626994929.3519628: {"feed":"book","product_id":"FI_XBTUSD_210924","side":"sell","seq":13501588,"price":32235.5,"qty":940.0,"timestamp":1626994929377}
1626994929.352013: {"feed":"book","product_id":"FI_XBTUSD_210924","side":"sell","seq":13501589,"price":32235.5,"qty":17138.0,"timestamp":1626994929377}
1626994929.352056: {"feed":"book","product_id":"FI_XBTUSD_210924","side":"buy","seq":13501590,"price":32166.0,"qty":0.0,"timestamp":1626994929377}
1626994929.3520918: {"feed":"book","product_id":"FI_XBTUSD_210924","side":"buy","seq":13501591,"price":32166.0,"qty":20902.0,"timestamp":1626994929377}
1626994929.3521228: {"feed":"book","product_id":"FI_XBTUSD_210924","side":"sell","seq":13501592,"price":32258.5,"qty":3000.0,"timestamp":1626994929377}
1626994929.352145: {"feed":"book","product_id":"FI_XBTUSD_210924","side":"sell","seq":13501593,"price":32258.5,"qty":23959.0,"timestamp":1626994929377}
1626994929.3717172: {"feed":"book","product_id":"PI_ETHUSD","side":"buy","seq":26661081,"price":2003.3,"qty":4086.0,"timestamp":1626994929380}
1626994929.371835: {"feed":"book","product_id":"PI_ETHUSD","side":"buy","seq":26661082,"price":2003.35,"qty":20000.0,"timestamp":1626994929380}
1626994929.3719838: {"feed":"book","product_id":"PI_ETHUSD","side":"sell","seq":26661083,"price":2004.7,"qty":7603.0,"timestamp":1626994929385}
1626994929.37201: {"feed":"book","product_id":"PI_ETHUSD","side":"buy","seq":26661084,"price":2003.35,"qty":0.0,"timestamp":1626994929386}
1626994929.372052: {"feed":"book","product_id":"PI_ETHUSD","side":"buy","seq":26661085,"price":2003.15,"qty":20000.0,"timestamp":1626994929386}
1626994929.372082: {"feed":"book","product_id":"FI_XBTUSD_210730","side":"sell","seq":5159979,"price":32201.5,"qty":0.0,"timestamp":1626994929396}
1626994929.3721118: {"feed":"book","product_id":"FI_XBTUSD_210730","side":"sell","seq":5159980,"price":32200.5,"qty":251.0,"timestamp":1626994929396}
1626994929.372138: {"feed":"book","product_id":"FI_XBTUSD_210924","side":"sell","seq":13501594,"price":32224.5,"qty":0.0,"timestamp":1626994929396}
1626994929.3721669: {"feed":"book","product_id":"FI_XBTUSD_210924","side":"sell","seq":13501595,"price":32223.5,"qty":251.0,"timestamp":1626994929396}
1626994929.424999: {"feed":"book","product_id":"FI_ETHUSD_210730","side":"buy","seq":2138684,"price":1991.3,"qty":0.0,"timestamp":1626994929440}
1626994929.425123: {"feed":"book","product_id":"FI_ETHUSD_210730","side":"buy","seq":2138685,"price":1991.4,"qty":44704.0,"timestamp":1626994929440}
1626994929.425188: {"feed":"book","product_id":"FI_ETHUSD_211231","side":"sell","seq":2198983,"price":2050.1,"qty":44305.0,"timestamp":1626994929440}
1626994929.4252338: {"feed":"book","product_id":"FI_ETHUSD_211231","side":"sell","seq":2198984,"price":2050.0,"qty":45099.0,"timestamp":1626994929440}
1626994929.4252858: {"feed":"book","product_id":"FI_ETHUSD_210730","side":"sell","seq":2138686,"price":2014.85,"qty":0.0,"timestamp":1626994929440}
1626994929.425339: {"feed":"book","product_id":"FI_ETHUSD_210730","side":"sell","seq":2138687,"price":2014.75,"qty":45421.0,"timestamp":1626994929440}
1626994929.425366: {"feed":"book","product_id":"FI_ETHUSD_211231","side":"sell","seq":2198985,"price":2050.1,"qty":0.0,"timestamp":1626994929440}
1626994929.4253929: {"feed":"book","product_id":"FI_ETHUSD_211231","side":"sell","seq":2198986,"price":2050.0,"qty":89404.0,"timestamp":1626994929440}
1626994929.43881: {"feed":"book","product_id":"PI_XRPUSD","side":"sell","seq":3456171,"price":0.59,"qty":8842.0,"timestamp":1626994929464}
1626994929.4389188: {"feed":"book","product_id":"PI_XRPUSD","side":"sell","seq":3456172,"price":0.5894,"qty":11661.0,"timestamp":1626994929464}
1626994929.438972: {"feed":"book","product_id":"PI_XRPUSD","side":"buy","seq":3456173,"price":0.5873,"qty":9104.0,"timestamp":1626994929464}
1626994929.439012: {"feed":"book","product_id":"PI_XRPUSD","side":"buy","seq":3456174,"price":0.5877,"qty":0.0,"timestamp":1626994929464}
1626994929.4390678: {"feed":"book","product_id":"PI_XRPUSD","side":"buy","seq":3456175,"price":0.5875,"qty":0.0,"timestamp":1626994929464}
1626994929.46987: {"feed":"book","product_id":"PI_ETHUSD","side":"buy","seq":26661086,"price":2003.3,"qty":0.0,"timestamp":1626994929496}
1626994929.4720519: {"feed":"book","product_id":"PI_ETHUSD","side":"sell","seq":26661087,"price":2005.75,"qty":4112.0,"timestamp":1626994929497}
1626994929.484013: {"feed":"book","product_id":"PI_ETHUSD","side":"sell","seq":26661088,"price":2005.4,"qty":0.0,"timestamp":1626994929510}
1626994929.500978: {"feed":"book","product_id":"PI_ETHUSD","side":"sell","seq":26661089,"price":2005.4,"qty":4693.0,"timestamp":1626994929527}
1626994929.510371: {"feed":"book","product_id":"PI_ETHUSD","side":"buy","seq":26661090,"price":1995.0,"qty":0.0,"timestamp":1626994929536}
1626994929.510447: {"feed":"book","product_id":"PI_ETHUSD","side":"buy","seq":26661091,"price":1995.1,"qty":47959.0,"timestamp":1626994929536}
1626994929.5104809: {"feed":"book","product_id":"PI_ETHUSD","side":"sell","seq":26661092,"price":2013.15,"qty":0.0,"timestamp":1626994929536}
1626994929.510509: {"feed":"book","product_id":"PI_ETHUSD","side":"sell","seq":26661093,"price":2013.05,"qty":49496.0,"timestamp":1626994929536}
1626994929.510533: {"feed":"book","product_id":"PI_ETHUSD","side":"buy","seq":26661094,"price":2001.85,"qty":5005.0,"timestamp":1626994929536}
1626994929.5105522: {"feed":"book","product_id":"PI_ETHUSD","side":"buy","seq":26661095,"price":2001.85,"qty":15452.0,"timestamp":1626994929536}
1626994929.5105689: {"feed":"book","product_id":"PI_ETHUSD","side":"buy","seq":26661096,"price":2000.85,"qty":0.0,"timestamp":1626994929536}
1626994929.5105898: {"feed":"book","product_id":"PI_ETHUSD","side":"buy","seq":26661097,"price":2000.85,"qty":16211.0,"timestamp":1626994929536}
1626994929.510611: {"feed":"book","product_id":"PI_ETHUSD","side":"sell","seq":26661098,"price":2008.35,"qty":0.0,"timestamp":1626994929536}
1626994929.510633: {"feed":"book","product_id":"PI_ETHUSD","side":"sell","seq":26661099,"price":2008.35,"qty":26163.0,"timestamp":1626994929536}
1626994929.510654: {"feed":"book","product_id":"PI_ETHUSD","side":"sell","seq":26661100,"price":2007.0,"qty":5000.0,"timestamp":1626994929536}
1626994929.5106711: {"feed":"book","product_id":"PI_ETHUSD","side":"sell","seq":26661101,"price":2007.0,"qty":21568.0,"timestamp":1626994929536}
1626994929.5106869: {"feed":"book","product_id":"PI_ETHUSD","side":"sell","seq":26661102,"price":2006.25,"qty":0.0,"timestamp":1626994929536}
1626994929.5107079: {"feed":"book","product_id":"PI_ETHUSD","side":"sell","seq":26661103,"price":2006.25,"qty":12080.0,"timestamp":1626994929536}
1626994929.51349: {"feed":"book","product_id":"PI_ETHUSD","side":"buy","seq":26661104,"price":2000.05,"qty":0.0,"timestamp":1626994929536}
1626994929.513552: {"feed":"book","product_id":"PI_ETHUSD","side":"buy","seq":26661105,"price":2000.05,"qty":22764.0,"timestamp":1626994929536}
1626994929.513592: {"feed":"book","product_id":"PI_ETHUSD","side":"sell","seq":26661106,"price":2021.45,"qty":0.0,"timestamp":1626994929536}
1626994929.513626: {"feed":"book","product_id":"PI_ETHUSD","side":"sell","seq":26661107,"price":2021.45,"qty":67952.0,"timestamp":1626994929536}
1626994929.5136561: {"feed":"book","product_id":"PI_ETHUSD","side":"buy","seq":26661108,"price":1988.9,"qty":0.0,"timestamp":1626994929536}
1626994929.513685: {"feed":"book","product_id":"PI_ETHUSD","side":"buy","seq":26661109,"price":1988.9,"qty":66954.0,"timestamp":1626994929536}
1626994929.5137122: {"feed":"book","product_id":"PI_ETHUSD","side":"buy","seq":26661110,"price":2003.2,"qty":0.0,"timestamp":1626994929537}
1626994929.513739: {"feed":"book","product_id":"PI_ETHUSD","side":"buy","seq":26661111,"price":2003.5,"qty":16426.0,"timestamp":1626994929537}
1626994929.520104: {"feed":"book","product_id":"FI_XBTUSD_210924","side":"buy","seq":13501596,"price":32159.5,"qty":3000.0,"timestamp":1626994929546}
1626994929.52804: {"feed":"book","product_id":"PI_ETHUSD","side":"buy","seq":26661112,"price":2003.15,"qty":0.0,"timestamp":1626994929553}
1626994929.5281641: {"feed":"book","product_id":"PI_ETHUSD","side":"buy","seq":26661113,"price":2003.45,"qty":59316.0,"timestamp":1626994929553}
1626994929.535848: {"feed":"book","product_id":"PI_XRPUSD","side":"buy","seq":3456176,"price":0.5878,"qty":9948.0,"timestamp":1626994929561}
1626994929.5359669: {"feed":"book","product_id":"PI_XRPUSD","side":"buy","seq":3456177,"price":0.5875,"qty":1385.0,"timestamp":1626994929561}
1626994929.556067: {"feed":"book","product_id":"FI_XBTUSD_210924","side":"buy","seq":13501597,"price":32166.0,"qty":0.0,"timestamp":1626994929581}
1626994929.5562031: {"feed":"book","product_id":"FI_XBTUSD_210924","side":"buy","seq":13501598,"price":32153.0,"qty":20901.0,"timestamp":1626994929581}
1626994929.567107: {"feed":"book","product_id":"PI_LTCUSD","side":"buy","seq":3423062,"price":119.29,"qty":7736.0,"timestamp":1626994929592}
1626994929.5672152: {"feed":"book","product_id":"PI_LTCUSD","side":"buy","seq":3423063,"price":119.26,"qty":7760.0,"timestamp":1626994929592}
1626994929.648695: {"feed":"book","product_id":"PI_XRPUSD","side":"sell","seq":3456178,"price":0.5892,"qty":7943.0,"timestamp":1626994929674}
1626994929.650729: {"feed":"book","product_id":"PI_XRPUSD","side":"buy","seq":3456179,"price":0.588,"qty":18872.0,"timestamp":1626994929676}
1626994929.6508439: {"feed":"book","product_id":"PI_XRPUSD","side":"buy","seq":3456180,"price":0.5876,"qty":11154.0,"timestamp":1626994929676}
1626994929.650893: {"feed":"book","product_id":"PI_XRPUSD","side":"buy","seq":3456181,"price":0.5878,"qty":14955.0,"timestamp":1626994929676}
1626994929.65093: {"feed":"book","product_id":"PI_XRPUSD","side":"buy","seq":3456182,"price":0.588,"qty":8922.0,"timestamp":1626994929678}
1626994929.650964: {"feed":"book","product_id":"PI_XRPUSD","side":"buy","seq":3456183,"price":0.5882,"qty":9950.0,"timestamp":1626994929678}
1626994929.6701272: {"feed":"book","product_id":"PI_ETHUSD","side":"sell","seq":26661114,"price":2008.7,"qty":9013.0,"timestamp":1626994929694}
1626994929.670235: {"feed":"book","product_id":"PI_ETHUSD","side":"buy","seq":26661115,"price":2002.8,"qty":110775.0,"timestamp":1626994929695}
1626994929.670285: {"feed":"book","product_id":"PI_ETHUSD","side":"buy","seq":26661116,"price":2001.15,"qty":0.0,"timestamp":1626994929695}
1626994929.670348: {"feed":"book","product_id":"PI_ETHUSD","side":"buy","seq":26661117,"price":1996.65,"qty":0.0,"timestamp":1626994929696}
1626994929.670397: {"feed":"book","product_id":"PI_ETHUSD","side":"buy","seq":26661118,"price":2002.45,"qty":3939.0,"timestamp":1626994929696}
1626994929.672899: {"feed":"book","product_id":"PI_ETHUSD","side":"buy","seq":26661119,"price":2002.05,"qty":0.0,"timestamp":1626994929698}
1626994929.682067: {"feed":"book","product_id":"PI_ETHUSD","side":"sell","seq":26661120,"price":2011.1,"qty":3903.0,"timestamp":1626994929708}
1626994929.682202: {"feed":"book","product_id":"PI_ETHUSD","side":"buy","seq":26661121,"price":1999.0,"qty":3878.0,"timestamp":1626994929708}
1626994929.704274: {"feed":"book","product_id":"PI_ETHUSD","side":"sell","seq":26661122,"price":2005.4,"qty":0.0,"timestamp":1626994929731}
1626994929.747054: {"feed":"book","product_id":"PI_ETHUSD","side":"buy","seq":26661123,"price":2001.85,"qty":5005.0,"timestamp":1626994929771}
1626994929.7471628: {"feed":"book","product_id":"PI_ETHUSD","side":"buy","seq":26661124,"price":2001.85,"qty":15508.0,"timestamp":1626994929771}
1626994929.747214: {"feed":"book","product_id":"PI_ETHUSD","side":"buy","seq":26661125,"price":2000.85,"qty":0.0,"timestamp":1626994929771}
1626994929.747275: {"feed":"book","product_id":"PI_ETHUSD","side":"buy","seq":26661126,"price":2000.85,"qty":16295.0,"timestamp":1626994929771}
1626994929.747326: {"feed":"book","product_id":"PI_ETHUSD","side":"buy","seq":26661127,"price":2000.05,"qty":0.0,"timestamp":1626994929771}
1626994929.747373: {"feed":"book","product_id":"PI_ETHUSD","side":"buy","seq":26661128,"price":2000.05,"qty":22815.0,"timestamp":1626994929771}
1626994929.747414: {"feed":"book","product_id":"PI_ETHUSD","side":"sell","seq":26661129,"price":2007.0,"qty":5000.0,"timestamp":1626994929771}
1626994929.7474492: {"feed":"book","product_id":"PI_ETHUSD","side":"sell","seq":26661130,"price":2007.0,"qty":21534.0,"timestamp":1626994929771}
1626994929.747828: {"feed":"book","product_id":"PI_ETHUSD","side":"sell","seq":26661131,"price":2006.25,"qty":0.0,"timestamp":1626994929771}
1626994929.7478778: {"feed":"book","product_id":"PI_ETHUSD","side":"sell","seq":26661132,"price":2006.25,"qty":12057.0,"timestamp":1626994929771}
1626994929.7479098: {"feed":"book","product_id":"PI_ETHUSD","side":"sell","seq":26661133,"price":2008.35,"qty":0.0,"timestamp":1626994929771}
1626994929.747939: {"feed":"book","product_id":"PI_ETHUSD","side":"sell","seq":26661134,"price":2008.35,"qty":26135.0,"timestamp":1626994929771}
1626994929.7502568: {"feed":"book","product_id":"PI_ETHUSD","side":"sell","seq":26661135,"price":2013.05,"qty":0.0,"timestamp":1626994929771}
1626994929.750347: {"feed":"book","product_id":"PI_ETHUSD","side":"sell","seq":26661136,"price":2013.05,"qty":49467.0,"timestamp":1626994929771}
1626994929.75039: {"feed":"book","product_id":"PI_ETHUSD","side":"sell","seq":26661137,"price":2021.45,"qty":0.0,"timestamp":1626994929771}
1626994929.750423: {"feed":"book","product_id":"PI_ETHUSD","side":"sell","seq":26661138,"price":2021.45,"qty":67926.0,"timestamp":1626994929771}
1626994929.750453: {"feed":"book","product_id":"PI_ETHUSD","side":"buy","seq":26661139,"price":1988.9,"qty":0.0,"timestamp":1626994929771}
1626994929.750484: {"feed":"book","product_id":"PI_ETHUSD","side":"buy","seq":26661140,"price":1988.9,"qty":66930.0,"timestamp":1626994929771}
1626994929.7505112: {"feed":"book","product_id":"PI_ETHUSD","side":"buy","seq":26661141,"price":1995.1,"qty":0.0,"timestamp":1626994929771}
1626994929.750537: {"feed":"book","product_id":"PI_ETHUSD","side":"buy","seq":26661142,"price":1995.1,"qty":47975.0,"timestamp":1626994929771}
1626994929.782967: {"feed":"book","product_id":"PI_ETHUSD","side":"buy","seq":26661143,"price":2003.5,"qty":600.0,"timestamp":1626994929808}
1626994929.783076: {"feed":"book","product_id":"PI_ETHUSD","side":"buy","seq":26661144,"price":2003.65,"qty":15826.0,"timestamp":1626994929808}
1626994929.789462: {"feed":"book","product_id":"FI_XBTUSD_210924","side":"buy","seq":13501599,"price":32188.5,"qty":881.0,"timestamp":1626994929815}
1626994929.78957: {"feed":"book","product_id":"FI_XBTUSD_210924","side":"buy","seq":13501600,"price":32188.5,"qty":15901.0,"timestamp":1626994929815}
1626994929.7896209: {"feed":"book","product_id":"FI_XBTUSD_210924","side":"sell","seq":13501601,"price":32235.5,"qty":940.0,"timestamp":1626994929815}
1626994929.789662: {"feed":"book","product_id":"FI_XBTUSD_210924","side":"sell","seq":13501602,"price":32235.5,"qty":17417.0,"timestamp":1626994929815}
1626994929.789696: {"feed":"book","product_id":"FI_XBTUSD_210924","side":"sell","seq":13501603,"price":32258.5,"qty":3000.0,"timestamp":1626994929815}
1626994929.789729: {"feed":"book","product_id":"FI_XBTUSD_210924","side":"sell","seq":13501604,"price":32258.5,"qty":23958.0,"timestamp":1626994929815}
1626994929.798521: {"feed":"book","product_id":"PI_ETHUSD","side":"sell","seq":26661145,"price":2005.3,"qty":4438.0,"timestamp":1626994929824}
1626994929.8200672: {"feed":"book","product_id":"PI_ETHUSD","side":"buy","seq":26661146,"price":2003.65,"qty":0.0,"timestamp":1626994929845}
1626994929.8201962: {"feed":"book","product_id":"PI_ETHUSD","side":"buy","seq":26661147,"price":2003.55,"qty":15826.0,"timestamp":1626994929845}
1626994929.831037: {"feed":"book","product_id":"PI_XRPUSD","side":"buy","seq":3456184,"price":0.588,"qty":13926.0,"timestamp":1626994929856}
1626994929.831145: {"feed":"book","product_id":"PI_XRPUSD","side":"buy","seq":3456185,"price":0.5876,"qty":16162.0,"timestamp":1626994929856}
1626994929.8311949: {"feed":"book","product_id":"PI_XRPUSD","side":"buy","seq":3456186,"price":0.5878,"qty":19961.0,"timestamp":1626994929856}
1626994929.831233: {"feed":"book","product_id":"PI_XRPUSD","side":"sell","seq":3456187,"price":0.59,"qty":13829.0,"timestamp":1626994929856}
1626994929.864786: {"feed":"book","product_id":"PI_LTCUSD","side":"sell","seq":3423064,"price":119.46,"qty":0.0,"timestamp":1626994929891}
1626994929.8679318: {"feed":"book","product_id":"PI_LTCUSD","side":"buy","seq":3423065,"price":119.22,"qty":36370.0,"timestamp":1626994929894}
1626994929.867987: {"feed":"book","product_id":"PI_LTCUSD","side":"buy","seq":3423066,"price":119.25,"qty":1063.0,"timestamp":1626994929894}
1626994929.868018: {"feed":"book","product_id":"PI_LTCUSD","side":"buy","seq":3423067,"price":119.29,"qty":3829.0,"timestamp":1626994929895}
1626994929.8685288: {"feed":"book","product_id":"PI_LTCUSD","side":"sell","seq":3423068,"price":119.67,"qty":7776.0,"timestamp":1626994929896}
1626994929.868591: {"feed":"book","product_id":"PI_LTCUSD","side":"buy","seq":3423069,"price":119.17,"qty":0.0,"timestamp":1626994929896}
1626994929.868632: {"feed":"book","product_id":"PI_LTCUSD","side":"sell","seq":3423070,"price":119.76,"qty":0.0,"timestamp":1626994929896}
1626994929.8719711: {"feed":"book","product_id":"PI_LTCUSD","side":"buy","seq":3423071,"price":119.28,"qty":63.0,"timestamp":1626994929896}
1626994929.872094: {"feed":"book","product_id":"PI_LTCUSD","side":"buy","seq":3423072,"price":119.22,"qty":32175.0,"timestamp":1626994929897}
1626994929.872128: {"feed":"book","product_id":"PI_LTCUSD","side":"sell","seq":3423073,"price":119.54,"qty":4021.0,"timestamp":1626994929897}
1626994929.872154: {"feed":"book","product_id":"PI_LTCUSD","side":"buy","seq":3423074,"price":118.94,"qty":3933.0,"timestamp":1626994929897}
1626994929.87358: {"feed":"book","product_id":"PI_LTCUSD","side":"buy","seq":3423075,"price":119.31,"qty":60.0,"timestamp":1626994929897}
1626994929.8736682: {"feed":"book","product_id":"PI_LTCUSD","side":"sell","seq":3423076,"price":119.71,"qty":3962.0,"timestamp":1626994929898}
1626994929.873707: {"feed":"book","product_id":"PI_LTCUSD","side":"buy","seq":3423077,"price":119.28,"qty":4107.0,"timestamp":1626994929898}
1626994929.873734: {"feed":"book","product_id":"PI_LTCUSD","side":"buy","seq":3423078,"price":119.0,"qty":4028.0,"timestamp":1626994929899}
1626994929.873761: {"feed":"book","product_id":"PI_LTCUSD","side":"sell","seq":3423079,"price":119.63,"qty":28789.0,"timestamp":1626994929900}
1626994929.873784: {"feed":"book","product_id":"PI_LTCUSD","side":"sell","seq":3423080,"price":119.96,"qty":3853.0,"timestamp":1626994929901}
1626994929.878796: {"feed":"book","product_id":"PI_LTCUSD","side":"buy","seq":3423081,"price":119.3,"qty":4886.0,"timestamp":1626994929903}
1626994929.878907: {"feed":"book","product_id":"PI_LTCUSD","side":"buy","seq":3423082,"price":118.79,"qty":54806.0,"timestamp":1626994929904}
1626994929.8820841: {"feed":"book","product_id":"PI_LTCUSD","side":"buy","seq":3423083,"price":119.33,"qty":3844.0,"timestamp":1626994929908}
1626994929.882211: {"feed":"book","product_id":"PI_LTCUSD","side":"sell","seq":3423084,"price":119.59,"qty":13259.0,"timestamp":1626994929908}
1626994929.882265: {"feed":"book","product_id":"PI_LTCUSD","side":"sell","seq":3423085,"price":119.82,"qty":3883.0,"timestamp":1626994929909}
1626994929.8845649: {"feed":"book","product_id":"PI_LTCUSD","side":"buy","seq":3423086,"price":119.34,"qty":32055.0,"timestamp":1626994929910}
1626994929.884676: {"feed":"book","product_id":"PI_LTCUSD","side":"buy","seq":3423087,"price":119.1,"qty":9111.0,"timestamp":1626994929910}
1626994929.890493: {"feed":"book","product_id":"PI_XRPUSD","side":"buy","seq":3456188,"price":0.5881,"qty":9370.0,"timestamp":1626994929917}
1626994929.890605: {"feed":"book","product_id":"PI_XRPUSD","side":"buy","seq":3456189,"price":0.5882,"qty":10270.0,"timestamp":1626994929917}
1626994929.894942: {"feed":"book","product_id":"PI_XRPUSD","side":"buy","seq":3456190,"price":0.5882,"qty":320.0,"timestamp":1626994929920}
1626994929.895055: {"feed":"book","product_id":"PI_XRPUSD","side":"buy","seq":3456191,"price":0.5883,"qty":9950.0,"timestamp":1626994929920}
1626994929.9125571: {"feed":"book","product_id":"PI_ETHUSD","side":"sell","seq":26661148,"price":2005.3,"qty":0.0,"timestamp":1626994929938}
1626994929.929548: {"feed":"book","product_id":"PI_LTCUSD","side":"sell","seq":3423088,"price":119.44,"qty":0.0,"timestamp":1626994929946}
1626994929.9296372: {"feed":"book","product_id":"FI_ETHUSD_211231","side":"buy","seq":2198987,"price":2019.0,"qty":0.0,"timestamp":1626994929947}
1626994929.929697: {"feed":"book","product_id":"PI_LTCUSD","side":"buy","seq":3423089,"price":119.25,"qty":63.0,"timestamp":1626994929949}
1626994929.929742: {"feed":"book","product_id":"PI_LTCUSD","side":"buy","seq":3423090,"price":119.26,"qty":8760.0,"timestamp":1626994929949}
1626994929.929779: {"feed":"book","product_id":"PI_ETHUSD","side":"sell","seq":26661149,"price":2005.4,"qty":4850.0,"timestamp":1626994929953}
1626994929.9307678: {"feed":"book","product_id":"FI_XBTUSD_210730","side":"buy","seq":5159981,"price":31514.0,"qty":5000.0,"timestamp":1626994929955}
1626994929.930832: {"feed":"book","product_id":"FI_XBTUSD_210730","side":"buy","seq":5159982,"price":30833.0,"qty":10000.0,"timestamp":1626994929955}
1626994929.930864: {"feed":"book","product_id":"FI_XBTUSD_210730","side":"buy","seq":5159983,"price":30152.0,"qty":20000.0,"timestamp":1626994929955}
1626994929.9506712: {"feed":"book","product_id":"PI_ETHUSD","side":"sell","seq":26661150,"price":2006.25,"qty":0.0,"timestamp":1626994929975}
1626994929.9507358: {"feed":"book","product_id":"PI_ETHUSD","side":"sell","seq":26661151,"price":2005.9,"qty":10460.0,"timestamp":1626994929975}
1626994929.950777: {"feed":"book","product_id":"PI_ETHUSD","side":"sell","seq":26661152,"price":2008.35,"qty":0.0,"timestamp":1626994929975}
1626994929.9508119: {"feed":"book","product_id":"PI_ETHUSD","side":"sell","seq":26661153,"price":2007.65,"qty":22558.0,"timestamp":1626994929975}
1626994929.9508412: {"feed":"book","product_id":"FI_ETHUSD_211231","side":"buy","seq":2198988,"price":2021.5,"qty":100.0,"timestamp":1626994929975}
1626994929.95087: {"feed":"book","product_id":"PI_ETHUSD","side":"buy","seq":26661154,"price":2001.85,"qty":5005.0,"timestamp":1626994929975}
1626994929.950894: {"feed":"book","product_id":"PI_ETHUSD","side":"buy","seq":26661155,"price":2001.85,"qty":15138.0,"timestamp":1626994929975}
1626994929.950921: {"feed":"book","product_id":"PI_ETHUSD","side":"buy","seq":26661156,"price":2000.85,"qty":0.0,"timestamp":1626994929975}
1626994929.950956: {"feed":"book","product_id":"PI_ETHUSD","side":"buy","seq":26661157,"price":2000.85,"qty":15741.0,"timestamp":1626994929975}
1626994929.950985: {"feed":"book","product_id":"PI_ETHUSD","side":"sell","seq":26661158,"price":2007.0,"qty":5000.0,"timestamp":1626994929975}
1626994929.951016: {"feed":"book","product_id":"PI_ETHUSD","side":"sell","seq":26661159,"price":2007.0,"qty":22092.0,"timestamp":1626994929975}
1626994929.951037: {"feed":"book","product_id":"PI_ETHUSD","side":"buy","seq":26661160,"price":2000.05,"qty":0.0,"timestamp":1626994929975}
1626994929.951065: {"feed":"book","product_id":"PI_ETHUSD","side":"buy","seq":26661161,"price":2000.05,"qty":22447.0,"timestamp":1626994929975}
1626994929.951091: {"feed":"book","product_id":"PI_ETHUSD","side":"buy","seq":26661162,"price":1995.1,"qty":0.0,"timestamp":1626994929975}
1626994929.951127: {"feed":"book","product_id":"PI_ETHUSD","side":"buy","seq":26661163,"price":1995.1,"qty":47766.0,"timestamp":1626994929975}
1626994929.951152: {"feed":"book","product_id":"PI_ETHUSD","side":"sell","seq":26661164,"price":2013.05,"qty":0.0,"timestamp":1626994929975}
1626994929.951178: {"feed":"book","product_id":"PI_ETHUSD","side":"sell","seq":26661165,"price":2013.05,"qty":49681.0,"timestamp":1626994929975}
1626994929.951496: {"feed":"book","product_id":"PI_ETHUSD","side":"buy","seq":26661166,"price":1988.9,"qty":0.0,"timestamp":1626994929975}
1626994929.951539: {"feed":"book","product_id":"PI_ETHUSD","side":"buy","seq":26661167,"price":1988.9,"qty":66927.0,"timestamp":1626994929975}
1626994929.951565: {"feed":"book","product_id":"PI_ETHUSD","side":"sell","seq":26661168,"price":2021.45,"qty":0.0,"timestamp":1626994929975}
1626994929.951589: {"feed":"book","product_id":"PI_ETHUSD","side":"sell","seq":26661169,"price":2021.45,"qty":67924.0,"timestamp":1626994929975}
1626994929.9678788: {"feed":"book","product_id":"PI_ETHUSD","side":"buy","seq":26661170,"price":2003.3,"qty":3807.0,"timestamp":1626994929994}
1626994929.970112: {"feed":"book","product_id":"PI_LTCUSD","side":"buy","seq":3423091,"price":119.26,"qty":4868.0,"timestamp":1626994929997}
1626994929.970146: {"feed":"book","product_id":"PI_LTCUSD","side":"buy","seq":3423092,"price":119.31,"qty":4067.0,"timestamp":1626994929997}
1626994929.970165: {"feed":"book","product_id":"PI_ETHUSD","side":"sell","seq":26661171,"price":2005.9,"qty":14523.0,"timestamp":1626994929998}
1626994929.974335: {"feed":"book","product_id":"PI_LTCUSD","side":"sell","seq":3423093,"price":119.59,"qty":9114.0,"timestamp":1626994930001}
1626994929.9786508: {"feed":"book","product_id":"PI_LTCUSD","side":"sell","seq":3423094,"price":119.63,"qty":32833.0,"timestamp":1626994930006}
1626994929.985465: {"feed":"book","product_id":"PI_XRPUSD","side":"buy","seq":3456192,"price":0.588,"qty":30725.0,"timestamp":1626994930010}
1626994929.993133: {"feed":"book","product_id":"FI_XBTUSD_210924","side":"buy","seq":13501605,"price":32153.0,"qty":0.0,"timestamp":1626994930018}
1626994929.993258: {"feed":"book","product_id":"FI_XBTUSD_210924","side":"buy","seq":13501606,"price":32166.0,"qty":20902.0,"timestamp":1626994930018}
1626994930.009166: {"feed":"book","product_id":"PI_XRPUSD","side":"sell","seq":3456193,"price":0.5895,"qty":3997.0,"timestamp":1626994930036}
1626994930.024868: {"feed":"book","product_id":"FI_XBTUSD_210730","side":"buy","seq":5159984,"price":31514.0,"qty":11000.0,"timestamp":1626994930052}
1626994930.04844: {"feed":"book","product_id":"PI_LTCUSD","side":"sell","seq":3423095,"price":119.48,"qty":31744.0,"timestamp":1626994930072}
1626994930.048566: {"feed":"book","product_id":"PI_LTCUSD","side":"buy","seq":3423096,"price":119.26,"qty":3868.0,"timestamp":1626994930075}
1626994930.04862: {"feed":"book","product_id":"PI_LTCUSD","side":"buy","seq":3423097,"price":119.23,"qty":6097.0,"timestamp":1626994930075}
1626994930.05309: {"feed":"book","product_id":"PI_LTCUSD","side":"buy","seq":3423098,"price":119.32,"qty":0.0,"timestamp":1626994930079}
1626994930.053241: {"feed":"book","product_id":"PI_LTCUSD","side":"buy","seq":3423099,"price":119.34,"qty":32375.0,"timestamp":1626994930079}
1626994930.0532968: {"feed":"book","product_id":"PI_LTCUSD","side":"sell","seq":3423100,"price":119.46,"qty":320.0,"timestamp":1626994930080}
1626994930.053621: {"feed":"book","product_id":"PI_LTCUSD","side":"buy","seq":3423101,"price":119.26,"qty":0.0,"timestamp":1626994930081}
1626994930.057902: {"feed":"book","product_id":"PI_LTCUSD","side":"sell","seq":3423102,"price":119.56,"qty":5915.0,"timestamp":1626994930083}
1626994930.057982: {"feed":"book","product_id":"PI_LTCUSD","side":"buy","seq":3423103,"price":119.29,"qty":0.0,"timestamp":1626994930084}
1626994930.0580301: {"feed":"book","product_id":"PI_LTCUSD","side":"buy","seq":3423104,"price":119.31,"qty":8186.0,"timestamp":1626994930085}
1626994930.058066: {"feed":"book","product_id":"PI_LTCUSD","side":"sell","seq":3423105,"price":119.54,"qty":0.0,"timestamp":1626994930085}
1626994930.0630112: {"feed":"book","product_id":"PI_LTCUSD","side":"buy","seq":3423106,"price":119.19,"qty":3832.0,"timestamp":1626994930089}
1626994930.069806: {"feed":"book","product_id":"PI_LTCUSD","side":"sell","seq":3423107,"price":119.68,"qty":4522.0,"timestamp":1626994930097}
1626994930.0719: {"feed":"book","product_id":"PI_LTCUSD","side":"sell","seq":3423108,"price":119.77,"qty":38222.0,"timestamp":1626994930097}
1626994930.071981: {"feed":"book","product_id":"PI_LTCUSD","side":"sell","seq":3423109,"price":119.63,"qty":28837.0,"timestamp":1626994930098}
1626994930.0720131: {"feed":"book","product_id":"PI_LTCUSD","side":"sell","seq":3423110,"price":119.67,"qty":3901.0,"timestamp":1626994930098}
1626994930.0920372: {"feed":"book","product_id":"PI_LTCUSD","side":"buy","seq":3423111,"price":119.21,"qty":29171.0,"timestamp":1626994930118}
1626994930.092148: {"feed":"book","product_id":"PI_LTCUSD","side":"buy","seq":3423112,"price":119.11,"qty":61778.0,"timestamp":1626994930118}
1626994930.100833: {"feed":"book","product_id":"PI_XRPUSD","side":"buy","seq":3456194,"price":0.588,"qty":25721.0,"timestamp":1626994930127}
1626994930.100945: {"feed":"book","product_id":"PI_XRPUSD","side":"buy","seq":3456195,"price":0.5878,"qty":14955.0,"timestamp":1626994930127}
1626994930.101241: {"feed":"book","product_id":"PI_XRPUSD","side":"buy","seq":3456196,"price":0.5876,"qty":11154.0,"timestamp":1626994930128}
1626994930.101835: {"feed":"book","product_id":"PI_XRPUSD","side":"sell","seq":3456197,"price":0.59,"qty":8842.0,"timestamp":1626994930128}
1626994930.118827: {"feed":"book","product_id":"PI_ETHUSD","side":"sell","seq":26661172,"price":2005.4,"qty":0.0,"timestamp":1626994930142}
1626994930.118915: {"feed":"book","product_id":"FI_XBTUSD_210730","side":"buy","seq":5159985,"price":30833.0,"qty":22000.0,"timestamp":1626994930142}
1626994930.1189508: {"feed":"book","product_id":"PI_LTCUSD","side":"buy","seq":3423113,"price":119.2,"qty":5008.0,"timestamp":1626994930145}
1626994930.119002: {"feed":"book","product_id":"PI_LTCUSD","side":"buy","seq":3423114,"price":119.24,"qty":5006.0,"timestamp":1626994930145}
1626994930.1190321: {"feed":"book","product_id":"PI_LTCUSD","side":"buy","seq":3423115,"price":119.16,"qty":5009.0,"timestamp":1626994930145}
1626994930.119067: {"feed":"book","product_id":"PI_LTCUSD","side":"buy","seq":3423116,"price":119.18,"qty":556.0,"timestamp":1626994930146}
1626994930.1209102: {"feed":"book","product_id":"PI_LTCUSD","side":"buy","seq":3423117,"price":119.1,"qty":4103.0,"timestamp":1626994930147}
1626994930.1209931: {"feed":"book","product_id":"PI_LTCUSD","side":"buy","seq":3423118,"price":119.14,"qty":0.0,"timestamp":1626994930147}
1626994930.121026: {"feed":"book","product_id":"PI_LTCUSD","side":"buy","seq":3423119,"price":119.21,"qty":4663.0,"timestamp":1626994930148}
1626994930.148905: {"feed":"book","product_id":"PI_XRPUSD","side":"buy","seq":3456198,"price":0.5875,"qty":2238.0,"timestamp":1626994930175}
1626994930.149017: {"feed":"book","product_id":"PI_LTCUSD","side":"sell","seq":3423120,"price":119.68,"qty":3870.0,"timestamp":1626994930175}
1626994930.183151: {"feed":"book","product_id":"PI_ETHUSD","side":"buy","seq":26661173,"price":2001.85,"qty":5005.0,"timestamp":1626994930209}
1626994930.18326: {"feed":"book","product_id":"PI_ETHUSD","side":"buy","seq":26661174,"price":2001.85,"qty":15139.0,"timestamp":1626994930209}
1626994930.2016141: {"feed":"book","product_id":"FI_XBTUSD_210730","side":"buy","seq":5159986,"price":30152.0,"qty":44000.0,"timestamp":1626994930227}
1626994930.227563: {"feed":"book","product_id":"FI_XBTUSD_210924","side":"buy","seq":13501607,"price":32188.5,"qty":881.0,"timestamp":1626994930253}
1626994930.227672: {"feed":"book","product_id":"FI_XBTUSD_210924","side":"buy","seq":13501608,"price":32188.5,"qty":16241.0,"timestamp":1626994930253}
1626994930.227722: {"feed":"book","product_id":"FI_XBTUSD_210924","side":"sell","seq":13501609,"price":32235.5,"qty":940.0,"timestamp":1626994930253}
1626994930.2277608: {"feed":"book","product_id":"FI_XBTUSD_210924","side":"sell","seq":13501610,"price":32235.5,"qty":17076.0,"timestamp":1626994930253}
1626994930.227797: {"feed":"book","product_id":"FI_XBTUSD_210924","side":"sell","seq":13501611,"price":32258.5,"qty":3000.0,"timestamp":1626994930253}
1626994930.22783: {"feed":"book","product_id":"FI_XBTUSD_210924","side":"sell","seq":13501612,"price":32258.5,"qty":23959.0,"timestamp":1626994930253}
1626994930.305142: {"feed":"book","product_id":"PI_LTCUSD","side":"buy","seq":3423121,"price":119.28,"qty":29047.0,"timestamp":1626994930330}
1626994930.323231: {"feed":"book","product_id":"FI_ETHUSD_211231","side":"sell","seq":2198989,"price":2034.7,"qty":0.0,"timestamp":1626994930350}
1626994930.351186: {"feed":"book","product_id":"PI_ETHUSD","side":"buy","seq":26661175,"price":2003.45,"qty":39316.0,"timestamp":1626994930351}
1626994930.351305: {"feed":"book","product_id":"PI_ETHUSD","side":"buy","seq":26661176,"price":2003.55,"qty":35826.0,"timestamp":1626994930351}
1626994930.3513541: {"feed":"book","product_id":"PI_ETHUSD","side":"sell","seq":26661177,"price":2005.35,"qty":4435.0,"timestamp":1626994930365}
1626994930.364144: {"feed":"book","product_id":"PI_LTCUSD","side":"sell","seq":3423122,"price":119.5,"qty":8000.0,"timestamp":1626994930379}
1626994930.3642519: {"feed":"book","product_id":"PI_LTCUSD","side":"sell","seq":3423123,"price":119.54,"qty":1062.0,"timestamp":1626994930379}
1626994930.364392: {"feed":"book","product_id":"PI_ETHUSD","side":"buy","seq":26661178,"price":2003.95,"qty":1914.0,"timestamp":1626994930392}
1626994930.384414: {"feed":"book","product_id":"PI_ETHUSD","side":"buy","seq":26661179,"price":2003.55,"qty":20000.0,"timestamp":1626994930409}
1626994930.38452: {"feed":"book","product_id":"PI_ETHUSD","side":"buy","seq":26661180,"price":2003.65,"qty":15826.0,"timestamp":1626994930409}
1626994930.386595: {"feed":"book","product_id":"PI_ETHUSD","side":"sell","seq":26661181,"price":2005.9,"qty":4063.0,"timestamp":1626994930412}
1626994930.3867059: {"feed":"book","product_id":"PI_ETHUSD","side":"sell","seq":26661182,"price":2006.25,"qty":12034.0,"timestamp":1626994930412}
1626994930.386784: {"feed":"book","product_id":"PI_ETHUSD","side":"sell","seq":26661183,"price":2007.65,"qty":0.0,"timestamp":1626994930412}
1626994930.386855: {"feed":"book","product_id":"PI_ETHUSD","side":"sell","seq":26661184,"price":2008.35,"qty":26112.0,"timestamp":1626994930412}
1626994930.399127: {"feed":"book","product_id":"PI_ETHUSD","side":"buy","seq":26661185,"price":2003.55,"qty":0.0,"timestamp":1626994930425}
1626994930.399213: {"feed":"book","product_id":"PI_ETHUSD","side":"buy","seq":26661186,"price":2003.65,"qty":35826.0,"timestamp":1626994930425}
1626994930.4205089: {"feed":"book","product_id":"PI_ETHUSD","side":"buy","seq":26661187,"price":2003.65,"qty":15826.0,"timestamp":1626994930446}
1626994930.420619: {"feed":"book","product_id":"PI_ETHUSD","side":"buy","seq":26661188,"price":2003.55,"qty":20000.0,"timestamp":1626994930446}
1626994930.4524312: {"feed":"book","product_id":"PI_ETHUSD","side":"buy","seq":26661189,"price":1953.65,"qty":1.0,"timestamp":1626994930477}
1626994930.452559: {"feed":"book","product_id":"FI_XBTUSD_210924","side":"buy","seq":13501613,"price":32166.0,"qty":0.0,"timestamp":1626994930477}
1626994930.452628: {"feed":"book","product_id":"FI_XBTUSD_210924","side":"buy","seq":13501614,"price":32153.0,"qty":20901.0,"timestamp":1626994930477}
1626994930.567544: {"feed":"book","product_id":"PI_LTCUSD","side":"buy","seq":3423124,"price":119.28,"qty":33237.0,"timestamp":1626994930591}
1626994930.640061: {"feed":"book","product_id":"PI_ETHUSD","side":"buy","seq":26661190,"price":2001.85,"qty":5005.0,"timestamp":1626994930666}
1626994930.64017: {"feed":"book","product_id":"PI_ETHUSD","side":"buy","seq":26661191,"price":2001.85,"qty":15553.0,"timestamp":1626994930666}
1626994930.64022: {"feed":"book","product_id":"PI_ETHUSD","side":"sell","seq":26661192,"price":2007.0,"qty":5000.0,"timestamp":1626994930666}
1626994930.64026: {"feed":"book","product_id":"PI_ETHUSD","side":"sell","seq":26661193,"price":2007.0,"qty":21466.0,"timestamp":1626994930666}
1626994930.6402938: {"feed":"book","product_id":"PI_ETHUSD","side":"buy","seq":26661194,"price":2000.85,"qty":0.0,"timestamp":1626994930666}
1626994930.6403499: {"feed":"book","product_id":"PI_ETHUSD","side":"buy","seq":26661195,"price":2000.85,"qty":16362.0,"timestamp":1626994930666}
1626994930.643272: {"feed":"book","product_id":"PI_ETHUSD","side":"buy","seq":26661196,"price":2000.05,"qty":0.0,"timestamp":1626994930666}
1626994930.6433952: {"feed":"book","product_id":"PI_ETHUSD","side":"buy","seq":26661197,"price":2000.05,"qty":22860.0,"timestamp":1626994930666}
1626994930.643462: {"feed":"book","product_id":"PI_ETHUSD","side":"buy","seq":26661198,"price":1995.1,"qty":0.0,"timestamp":1626994930666}
1626994930.643523: {"feed":"book","product_id":"PI_ETHUSD","side":"buy","seq":26661199,"price":1995.1,"qty":48001.0,"timestamp":1626994930666}
1626994930.6435719: {"feed":"book","product_id":"PI_ETHUSD","side":"sell","seq":26661200,"price":2013.05,"qty":0.0,"timestamp":1626994930666}
1626994930.643602: {"feed":"book","product_id":"PI_ETHUSD","side":"sell","seq":26661201,"price":2013.05,"qty":49441.0,"timestamp":1626994930666}
1626994930.6436281: {"feed":"book","product_id":"PI_ETHUSD","side":"sell","seq":26661202,"price":2006.25,"qty":0.0,"timestamp":1626994930666}
1626994930.6436548: {"feed":"book","product_id":"PI_ETHUSD","side":"sell","seq":26661203,"price":2006.25,"qty":12012.0,"timestamp":1626994930666}
1626994930.643681: {"feed":"book","product_id":"PI_ETHUSD","side":"sell","seq":26661204,"price":2008.35,"qty":0.0,"timestamp":1626994930666}
1626994930.643706: {"feed":"book","product_id":"PI_ETHUSD","side":"sell","seq":26661205,"price":2008.35,"qty":26090.0,"timestamp":1626994930666}
1626994930.643732: {"feed":"book","product_id":"PI_ETHUSD","side":"buy","seq":26661206,"price":1988.9,"qty":0.0,"timestamp":1626994930666}
1626994930.643758: {"feed":"book","product_id":"PI_ETHUSD","side":"buy","seq":26661207,"price":1988.9,"qty":66930.0,"timestamp":1626994930666}
1626994930.643782: {"feed":"book","product_id":"PI_ETHUSD","side":"sell","seq":26661208,"price":2021.45,"qty":0.0,"timestamp":1626994930666}
1626994930.643807: {"feed":"book","product_id":"PI_ETHUSD","side":"sell","seq":26661209,"price":2021.45,"qty":67927.0,"timestamp":1626994930666}
1626994930.656072: {"feed":"book","product_id":"FI_XBTUSD_210924","side":"buy","seq":13501615,"price":32153.0,"qty":0.0,"timestamp":1626994930680}
1626994930.656159: {"feed":"book","product_id":"FI_XBTUSD_210924","side":"buy","seq":13501616,"price":32166.0,"qty":20902.0,"timestamp":1626994930680}
1626994930.656201: {"feed":"book","product_id":"PI_ETHUSD","side":"sell","seq":26661210,"price":2005.35,"qty":0.0,"timestamp":1626994930682}
1626994930.690007: {"feed":"book","product_id":"PI_XRPUSD","side":"buy","seq":3456199,"price":0.5883,"qty":10150.0,"timestamp":1626994930716}
1626994930.694509: {"feed":"book","product_id":"PI_XRPUSD","side":"sell","seq":3456200,"price":0.618,"qty":0.0,"timestamp":1626994930721}
1626994930.694632: {"feed":"book","product_id":"PI_XRPUSD","side":"sell","seq":3456201,"price":0.6181,"qty":50.0,"timestamp":1626994930721}
1626994930.7099159: {"feed":"book","product_id":"PI_XRPUSD","side":"sell","seq":3456202,"price":0.5893,"qty":5732.0,"timestamp":1626994930735}
1626994930.759238: {"feed":"book","product_id":"PI_ETHUSD","side":"buy","seq":26661211,"price":2003.55,"qty":0.0,"timestamp":1626994930784}
1626994930.7593641: {"feed":"book","product_id":"PI_ETHUSD","side":"buy","seq":26661212,"price":2003.65,"qty":35826.0,"timestamp":1626994930784}
1626994930.7735198: {"feed":"book","product_id":"PI_LTCUSD","side":"sell","seq":3423125,"price":119.59,"qty":4988.0,"timestamp":1626994930798}
1626994930.773601: {"feed":"book","product_id":"PI_LTCUSD","side":"buy","seq":3423126,"price":119.34,"qty":28553.0,"timestamp":1626994930799}
1626994930.7738812: {"feed":"book","product_id":"PI_ETHUSD","side":"sell","seq":26661213,"price":2005.35,"qty":4976.0,"timestamp":1626994930801}
1626994930.8220139: {"feed":"book","product_id":"PI_ETHUSD","side":"sell","seq":26661214,"price":2005.35,"qty":0.0,"timestamp":1626994930847}
1626994930.8442628: {"feed":"book","product_id":"PI_ETHUSD","side":"sell","seq":26661215,"price":2006.25,"qty":0.0,"timestamp":1626994930870}
1626994930.8443499: {"feed":"book","product_id":"PI_ETHUSD","side":"sell","seq":26661216,"price":2005.9,"qty":14348.0,"timestamp":1626994930870}
1626994930.844386: {"feed":"book","product_id":"PI_ETHUSD","side":"sell","seq":26661217,"price":2008.35,"qty":0.0,"timestamp":1626994930870}
1626994930.844419: {"feed":"book","product_id":"PI_ETHUSD","side":"sell","seq":26661218,"price":2007.7,"qty":531229.0,"timestamp":1626994930870}
1626994930.864296: {"feed":"book","product_id":"PI_LTCUSD","side":"sell","seq":3423127,"price":119.56,"qty":2096.0,"timestamp":1626994930889}
1626994930.864404: {"feed":"book","product_id":"PI_LTCUSD","side":"buy","seq":3423128,"price":119.31,"qty":4067.0,"timestamp":1626994930890}
1626994930.8707929: {"feed":"book","product_id":"PI_LTCUSD","side":"sell","seq":3423129,"price":119.63,"qty":24793.0,"timestamp":1626994930896}
1626994930.870904: {"feed":"book","product_id":"PI_LTCUSD","side":"buy","seq":3423130,"price":119.33,"qty":0.0,"timestamp":1626994930897}
1626994930.875917: {"feed":"book","product_id":"FI_ETHUSD_211231","side":"sell","seq":2198990,"price":2034.85,"qty":2000.0,"timestamp":1626994930899}
1626994930.87606: {"feed":"book","product_id":"FI_XBTUSD_210730","side":"sell","seq":5159987,"price":32200.5,"qty":0.0,"timestamp":1626994930900}
1626994930.876129: {"feed":"book","product_id":"FI_XBTUSD_210730","side":"sell","seq":5159988,"price":32199.5,"qty":251.0,"timestamp":1626994930900}
1626994930.8816488: {"feed":"book","product_id":"PI_LTCUSD","side":"buy","seq":3423131,"price":119.29,"qty":4028.0,"timestamp":1626994930907}
1626994930.88396: {"feed":"book","product_id":"PI_LTCUSD","side":"sell","seq":3423132,"price":119.55,"qty":8835.0,"timestamp":1626994930909}
1626994930.884068: {"feed":"book","product_id":"PI_LTCUSD","side":"buy","seq":3423133,"price":119.3,"qty":8945.0,"timestamp":1626994930909}
1626994930.886716: {"feed":"book","product_id":"FI_XBTUSD_210924","side":"buy","seq":13501617,"price":32166.0,"qty":0.0,"timestamp":1626994930913}
1626994930.8868392: {"feed":"book","product_id":"FI_XBTUSD_210924","side":"buy","seq":13501618,"price":32153.0,"qty":20901.0,"timestamp":1626994930913}
1626994930.9014988: {"feed":"book","product_id":"FI_XBTUSD_210924","side":"sell","seq":13501619,"price":32223.5,"qty":0.0,"timestamp":1626994930927}
1626994930.901624: {"feed":"book","product_id":"FI_XBTUSD_210924","side":"sell","seq":13501620,"price":32222.5,"qty":251.0,"timestamp":1626994930927}
1626994930.971404: {"feed":"book","product_id":"PI_ETHUSD","side":"buy","seq":26661219,"price":2003.3,"qty":0.0,"timestamp":1626994930997}
1626994930.973726: {"feed":"book","product_id":"PI_ETHUSD","side":"sell","seq":26661220,"price":2006.15,"qty":3867.0,"timestamp":1626994930999}
1626994930.97385: {"feed":"book","product_id":"PI_ETHUSD","side":"sell","seq":26661221,"price":2005.9,"qty":10285.0,"timestamp":1626994930999}
1626994930.973901: {"feed":"book","product_id":"PI_ETHUSD","side":"buy","seq":26661222,"price":2003.55,"qty":3980.0,"timestamp":1626994931000}
1626994930.9865391: {"feed":"book","product_id":"PI_ETHUSD","side":"sell","seq":26661223,"price":2005.35,"qty":4187.0,"timestamp":1626994931012}
1626994931.0589771: {"feed":"book","product_id":"PI_LTCUSD","side":"buy","seq":3423134,"price":119.31,"qty":8187.0,"timestamp":1626994931082}
1626994931.059087: {"feed":"book","product_id":"PI_LTCUSD","side":"sell","seq":3423135,"price":119.56,"qty":6084.0,"timestamp":1626994931083}
1626994931.070123: {"feed":"book","product_id":"PI_ETHUSD","side":"sell","seq":26661224,"price":2006.15,"qty":0.0,"timestamp":1626994931094}
1626994931.071137: {"feed":"book","product_id":"PI_LTCUSD","side":"sell","seq":3423136,"price":119.55,"qty":3846.0,"timestamp":1626994931096}
1626994931.0711958: {"feed":"book","product_id":"PI_LTCUSD","side":"sell","seq":3423137,"price":119.67,"qty":8889.0,"timestamp":1626994931096}
1626994931.08053: {"feed":"book","product_id":"PI_ETHUSD","side":"sell","seq":26661225,"price":2007.7,"qty":508565.0,"timestamp":1626994931104}
1626994931.080637: {"feed":"book","product_id":"PI_ETHUSD","side":"sell","seq":26661226,"price":2007.65,"qty":22554.0,"timestamp":1626994931104}
1626994931.080704: {"feed":"book","product_id":"PI_ETHUSD","side":"buy","seq":26661227,"price":2001.85,"qty":5005.0,"timestamp":1626994931104}
1626994931.080745: {"feed":"book","product_id":"PI_ETHUSD","side":"buy","seq":26661228,"price":2001.85,"qty":15142.0,"timestamp":1626994931104}
1626994931.080779: {"feed":"book","product_id":"PI_ETHUSD","side":"buy","seq":26661229,"price":2000.85,"qty":0.0,"timestamp":1626994931104}
1626994931.0808299: {"feed":"book","product_id":"PI_ETHUSD","side":"buy","seq":26661230,"price":2000.85,"qty":15747.0,"timestamp":1626994931104}
1626994931.0808718: {"feed":"book","product_id":"PI_ETHUSD","side":"sell","seq":26661231,"price":2007.0,"qty":5000.0,"timestamp":1626994931104}
1626994931.080906: {"feed":"book","product_id":"PI_ETHUSD","side":"sell","seq":26661232,"price":2007.0,"qty":22086.0,"timestamp":1626994931104}
1626994931.080947: {"feed":"book","product_id":"PI_LTCUSD","side":"sell","seq":3423138,"price":119.59,"qty":9037.0,"timestamp":1626994931105}
1626994931.081377: {"feed":"book","product_id":"PI_ETHUSD","side":"buy","seq":26661233,"price":2000.05,"qty":0.0,"timestamp":1626994931104}
1626994931.0814562: {"feed":"book","product_id":"PI_ETHUSD","side":"buy","seq":26661234,"price":2000.05,"qty":22451.0,"timestamp":1626994931104}
1626994931.081507: {"feed":"book","product_id":"PI_ETHUSD","side":"sell","seq":26661235,"price":2005.9,"qty":0.0,"timestamp":1626994931104}
1626994931.081538: {"feed":"book","product_id":"PI_ETHUSD","side":"sell","seq":26661236,"price":2005.9,"qty":10457.0,"timestamp":1626994931104}
1626994931.081564: {"feed":"book","product_id":"PI_ETHUSD","side":"buy","seq":26661237,"price":1995.1,"qty":0.0,"timestamp":1626994931104}
1626994931.081592: {"feed":"book","product_id":"PI_ETHUSD","side":"buy","seq":26661238,"price":1995.1,"qty":47768.0,"timestamp":1626994931104}
1626994931.0816169: {"feed":"book","product_id":"PI_ETHUSD","side":"sell","seq":26661239,"price":2013.05,"qty":0.0,"timestamp":1626994931104}
1626994931.081644: {"feed":"book","product_id":"PI_ETHUSD","side":"sell","seq":26661240,"price":2013.05,"qty":49679.0,"timestamp":1626994931104}
1626994931.0868921: {"feed":"book","product_id":"PI_ETHUSD","side":"buy","seq":26661241,"price":1988.9,"qty":0.0,"timestamp":1626994931104}
1626994931.087018: {"feed":"book","product_id":"PI_ETHUSD","side":"buy","seq":26661242,"price":1988.9,"qty":66927.0,"timestamp":1626994931104}
1626994931.087083: {"feed":"book","product_id":"PI_ETHUSD","side":"sell","seq":26661243,"price":2021.45,"qty":0.0,"timestamp":1626994931105}
1626994931.0871391: {"feed":"book","product_id":"PI_ETHUSD","side":"sell","seq":26661244,"price":2021.45,"qty":67924.0,"timestamp":1626994931105}
1626994931.087185: {"feed":"book","product_id":"PI_ETHUSD","side":"buy","seq":26661245,"price":2003.65,"qty":15826.0,"timestamp":1626994931109}
1626994931.087222: {"feed":"book","product_id":"PI_ETHUSD","side":"buy","seq":26661246,"price":2003.55,"qty":23980.0,"timestamp":1626994931109}
1626994931.0913322: {"feed":"book","product_id":"FI_XBTUSD_210924","side":"buy","seq":13501621,"price":32153.0,"qty":0.0,"timestamp":1626994931116}
1626994931.091466: {"feed":"book","product_id":"FI_XBTUSD_210924","side":"buy","seq":13501622,"price":32166.0,"qty":20902.0,"timestamp":1626994931116}
1626994931.1318579: {"feed":"book","product_id":"PI_LTCUSD","side":"sell","seq":3423139,"price":119.57,"qty":5275.0,"timestamp":1626994931158}
1626994931.217498: {"feed":"book","product_id":"FI_XBTUSD_210924","side":"buy","seq":13501623,"price":32130.0,"qty":0.0,"timestamp":1626994931239}
1626994931.21763: {"feed":"book","product_id":"FI_XBTUSD_210924","side":"buy","seq":13501624,"price":32128.0,"qty":250001.0,"timestamp":1626994931239}
1626994931.217696: {"feed":"book","product_id":"PI_ETHUSD","side":"sell","seq":26661247,"price":2007.7,"qty":8564.0,"timestamp":1626994931239}
1626994931.217726: {"feed":"book","product_id":"PI_ETHUSD","side":"sell","seq":26661248,"price":2007.35,"qty":504165.0,"timestamp":1626994931239}
1626994931.2177489: {"feed":"book","product_id":"PI_ETHUSD","side":"buy","seq":26661249,"price":1995.05,"qty":0.0,"timestamp":1626994931239}
1626994931.217782: {"feed":"book","product_id":"PI_ETHUSD","side":"buy","seq":26661250,"price":1995.15,"qty":500002.0,"timestamp":1626994931239}
1626994931.21781: {"feed":"book","product_id":"FI_ETHUSD_210730","side":"buy","seq":2138688,"price":1991.35,"qty":0.0,"timestamp":1626994931239}
1626994931.2178528: {"feed":"book","product_id":"FI_ETHUSD_210730","side":"buy","seq":2138689,"price":1991.45,"qty":273736.0,"timestamp":1626994931239}
1626994931.217877: {"feed":"book","product_id":"FI_ETHUSD_211231","side":"sell","seq":2198991,"price":2050.05,"qty":0.0,"timestamp":1626994931239}
1626994931.2179048: {"feed":"book","product_id":"FI_ETHUSD_211231","side":"sell","seq":2198992,"price":2049.95,"qty":250002.0,"timestamp":1626994931239}
1626994931.217932: {"feed":"book","product_id":"FI_ETHUSD_210730","side":"sell","seq":2138690,"price":2014.8,"qty":0.0,"timestamp":1626994931239}
1626994931.217959: {"feed":"book","product_id":"FI_ETHUSD_210730","side":"sell","seq":2138691,"price":2014.7,"qty":250002.0,"timestamp":1626994931239}
1626994931.217983: {"feed":"book","product_id":"PI_ETHUSD","side":"sell","seq":26661251,"price":2013.1,"qty":0.0,"timestamp":1626994931239}
1626994931.218011: {"feed":"book","product_id":"PI_ETHUSD","side":"sell","seq":26661252,"price":2013.0,"qty":500002.0,"timestamp":1626994931239}
1626994931.219161: {"feed":"book","product_id":"PI_LTCUSD","side":"sell","seq":3423140,"price":119.6,"qty":3865.0,"timestamp":1626994931245}
1626994931.219266: {"feed":"book","product_id":"PI_LTCUSD","side":"sell","seq":3423141,"price":119.94,"qty":4004.0,"timestamp":1626994931245}
1626994931.21973: {"feed":"book","product_id":"PI_LTCUSD","side":"sell","seq":3423142,"price":119.67,"qty":12699.0,"timestamp":1626994931246}
1626994931.219789: {"feed":"book","product_id":"PI_LTCUSD","side":"sell","seq":3423143,"price":119.74,"qty":0.0,"timestamp":1626994931246}
1626994931.227731: {"feed":"book","product_id":"PI_ETHUSD","side":"sell","seq":26661253,"price":2005.35,"qty":0.0,"timestamp":1626994931254}
1626994931.253463: {"feed":"book","product_id":"PI_LTCUSD","side":"buy","seq":3423144,"price":118.94,"qty":0.0,"timestamp":1626994931278}
1626994931.25359: {"feed":"book","product_id":"PI_LTCUSD","side":"buy","seq":3423145,"price":118.78,"qty":0.0,"timestamp":1626994931279}
1626994931.2536929: {"feed":"book","product_id":"PI_LTCUSD","side":"buy","seq":3423146,"price":119.26,"qty":3970.0,"timestamp":1626994931279}
1626994931.2537322: {"feed":"book","product_id":"PI_LTCUSD","side":"buy","seq":3423147,"price":119.09,"qty":3907.0,"timestamp":1626994931280}
1626994931.254018: {"feed":"book","product_id":"PI_LTCUSD","side":"buy","seq":3423148,"price":118.98,"qty":57678.0,"timestamp":1626994931280}
1626994931.254074: {"feed":"book","product_id":"PI_LTCUSD","side":"buy","seq":3423149,"price":119.19,"qty":0.0,"timestamp":1626994931280}
1626994931.285828: {"feed":"book","product_id":"PI_ETHUSD","side":"sell","seq":26661254,"price":2007.65,"qty":0.0,"timestamp":1626994931310}
1626994931.285954: {"feed":"book","product_id":"PI_ETHUSD","side":"sell","seq":26661255,"price":2007.7,"qty":31206.0,"timestamp":1626994931310}
1626994931.290406: {"feed":"book","product_id":"PI_ETHUSD","side":"buy","seq":26661256,"price":2003.55,"qty":3980.0,"timestamp":1626994931315}
1626994931.290514: {"feed":"book","product_id":"PI_ETHUSD","side":"buy","seq":26661257,"price":2003.45,"qty":59316.0,"timestamp":1626994931315}
1626994931.290565: {"feed":"book","product_id":"PI_ETHUSD","side":"buy","seq":26661258,"price":2003.65,"qty":0.0,"timestamp":1626994931316}
1626994931.290625: {"feed":"book","product_id":"PI_ETHUSD","side":"buy","seq":26661259,"price":2003.55,"qty":19806.0,"timestamp":1626994931316}
1626994931.318049: {"feed":"book","product_id":"FI_XBTUSD_210924","side":"buy","seq":13501625,"price":32188.5,"qty":881.0,"timestamp":1626994931341}
1626994931.318136: {"feed":"book","product_id":"FI_XBTUSD_210924","side":"buy","seq":13501626,"price":32188.5,"qty":16231.0,"timestamp":1626994931341}
1626994931.318169: {"feed":"book","product_id":"FI_XBTUSD_210924","side":"sell","seq":13501627,"price":32235.5,"qty":940.0,"timestamp":1626994931341}
1626994931.3181949: {"feed":"book","product_id":"FI_XBTUSD_210924","side":"sell","seq":13501628,"price":32235.5,"qty":17086.0,"timestamp":1626994931341}
1626994931.3182158: {"feed":"book","product_id":"PI_LTCUSD","side":"buy","seq":3423150,"price":119.31,"qty":4067.0,"timestamp":1626994931345}
1626994931.319221: {"feed":"book","product_id":"PI_LTCUSD","side":"buy","seq":3423151,"price":119.28,"qty":37384.0,"timestamp":1626994931345}
1626994931.319883: {"feed":"book","product_id":"PI_LTCUSD","side":"sell","seq":3423152,"price":119.82,"qty":7743.0,"timestamp":1626994931346}
1626994931.3199518: {"feed":"book","product_id":"PI_LTCUSD","side":"buy","seq":3423153,"price":119.23,"qty":2062.0,"timestamp":1626994931346}
1626994931.320986: {"feed":"book","product_id":"PI_LTCUSD","side":"sell","seq":3423154,"price":119.67,"qty":8798.0,"timestamp":1626994931347}
1626994931.3487191: {"feed":"book","product_id":"FI_BCHUSD_210924","side":"sell","seq":402229,"price":442.8,"qty":74.0,"timestamp":1626994931375}
1626994931.369167: {"feed":"book","product_id":"PI_ETHUSD","side":"sell","seq":26661260,"price":2004.5,"qty":0.0,"timestamp":1626994931394}
1626994931.38484: {"feed":"book","product_id":"PI_ETHUSD","side":"sell","seq":26661261,"price":2005.45,"qty":119062.0,"timestamp":1626994931410}
1626994931.3923998: {"feed":"book","product_id":"PI_ETHUSD","side":"buy","seq":26661262,"price":2003.45,"qty":39316.0,"timestamp":1626994931417}
1626994931.392512: {"feed":"book","product_id":"PI_ETHUSD","side":"buy","seq":26661263,"price":2003.35,"qty":20000.0,"timestamp":1626994931417}
1626994931.3925781: {"feed":"book","product_id":"PI_ETHUSD","side":"buy","seq":26661264,"price":2003.55,"qty":3980.0,"timestamp":1626994931417}
1626994931.392621: {"feed":"book","product_id":"PI_ETHUSD","side":"buy","seq":26661265,"price":2003.4,"qty":15826.0,"timestamp":1626994931417}
1626994931.4036841: {"feed":"book","product_id":"PI_ETHUSD","side":"buy","seq":26661266,"price":2003.35,"qty":0.0,"timestamp":1626994931429}
1626994931.403818: {"feed":"book","product_id":"PI_ETHUSD","side":"buy","seq":26661267,"price":2003.45,"qty":59316.0,"timestamp":1626994931429}
1626994931.4038742: {"feed":"book","product_id":"PI_ETHUSD","side":"buy","seq":26661268,"price":2003.4,"qty":0.0,"timestamp":1626994931429}
1626994931.403925: {"feed":"book","product_id":"PI_ETHUSD","side":"buy","seq":26661269,"price":2003.5,"qty":16426.0,"timestamp":1626994931429}
1626994931.41503: {"feed":"book","product_id":"PI_ETHUSD","side":"buy","seq":26661270,"price":2003.5,"qty":600.0,"timestamp":1626994931440}
1626994931.415141: {"feed":"book","product_id":"PI_ETHUSD","side":"buy","seq":26661271,"price":2003.4,"qty":15826.0,"timestamp":1626994931440}
1626994931.4169002: {"feed":"book","product_id":"PI_ETHUSD","side":"buy","seq":26661272,"price":2003.45,"qty":39316.0,"timestamp":1626994931441}
1626994931.4170089: {"feed":"book","product_id":"PI_ETHUSD","side":"buy","seq":26661273,"price":2003.35,"qty":20000.0,"timestamp":1626994931441}
1626994931.494538: {"feed":"book","product_id":"PI_ETHUSD","side":"buy","seq":26661274,"price":2003.4,"qty":0.0,"timestamp":1626994931516}
1626994931.494663: {"feed":"book","product_id":"PI_ETHUSD","side":"buy","seq":26661275,"price":2003.5,"qty":16426.0,"timestamp":1626994931516}
1626994931.494719: {"feed":"book","product_id":"PI_ETHUSD","side":"buy","seq":26661276,"price":2001.85,"qty":5005.0,"timestamp":1626994931516}
1626994931.494761: {"feed":"book","product_id":"PI_ETHUSD","side":"buy","seq":26661277,"price":2000.8,"qty":28359.0,"timestamp":1626994931516}
1626994931.494804: {"feed":"book","product_id":"PI_ETHUSD","side":"buy","seq":26661278,"price":2000.05,"qty":0.0,"timestamp":1626994931516}
1626994931.4948611: {"feed":"book","product_id":"PI_ETHUSD","side":"buy","seq":26661279,"price":1999.65,"qty":24464.0,"timestamp":1626994931516}
1626994931.4948921: {"feed":"book","product_id":"PI_ETHUSD","side":"sell","seq":26661280,"price":2005.95,"qty":60474.0,"timestamp":1626994931516}
1626994931.494915: {"feed":"book","product_id":"PI_ETHUSD","side":"buy","seq":26661281,"price":2003.35,"qty":0.0,"timestamp":1626994931517}
1626994931.494943: {"feed":"book","product_id":"PI_ETHUSD","side":"buy","seq":26661282,"price":2003.45,"qty":59316.0,"timestamp":1626994931517}
1626994931.494965: {"feed":"book","product_id":"FI_XBTUSD_210924","side":"buy","seq":13501629,"price":32181.5,"qty":0.0,"timestamp":1626994931515}
1626994931.5115259: {"feed":"book","product_id":"PI_ETHUSD","side":"buy","seq":26661283,"price":2003.5,"qty":600.0,"timestamp":1626994931532}
1626994931.5116348: {"feed":"book","product_id":"PI_ETHUSD","side":"buy","seq":26661284,"price":2003.3,"qty":15826.0,"timestamp":1626994931532}
1626994931.511703: {"feed":"book","product_id":"PI_ETHUSD","side":"buy","seq":26661285,"price":2003.45,"qty":39316.0,"timestamp":1626994931532}
1626994931.511745: {"feed":"book","product_id":"PI_ETHUSD","side":"buy","seq":26661286,"price":2003.25,"qty":20000.0,"timestamp":1626994931532}
1626994931.511789: {"feed":"book","product_id":"PI_ETHUSD","side":"buy","seq":26661287,"price":2003.3,"qty":0.0,"timestamp":1626994931532}
1626994931.511868: {"feed":"book","product_id":"PI_ETHUSD","side":"buy","seq":26661288,"price":2003.2,"qty":15826.0,"timestamp":1626994931532}
1626994931.5118961: {"feed":"book","product_id":"PI_ETHUSD","side":"buy","seq":26661289,"price":2003.25,"qty":0.0,"timestamp":1626994931532}
1626994931.511926: {"feed":"book","product_id":"PI_ETHUSD","side":"buy","seq":26661290,"price":2003.15,"qty":20000.0,"timestamp":1626994931532}
1626994931.520451: {"feed":"book","product_id":"PI_ETHUSD","side":"buy","seq":26661291,"price":2003.15,"qty":0.0,"timestamp":1626994931545}
1626994931.5205781: {"feed":"book","product_id":"PI_ETHUSD","side":"buy","seq":26661292,"price":2003.25,"qty":20000.0,"timestamp":1626994931545}
1626994931.522837: {"feed":"book","product_id":"PI_ETHUSD","side":"buy","seq":26661293,"price":2003.2,"qty":0.0,"timestamp":1626994931547}
1626994931.522963: {"feed":"book","product_id":"PI_ETHUSD","side":"buy","seq":26661294,"price":2003.3,"qty":15826.0,"timestamp":1626994931547}
1626994931.523029: {"feed":"book","product_id":"PI_ETHUSD","side":"buy","seq":26661295,"price":1955.05,"qty":1.0,"timestamp":1626994931548}
1626994931.5508108: {"feed":"book","product_id":"FI_XBTUSD_210924","side":"buy","seq":13501630,"price":32188.5,"qty":881.0,"timestamp":1626994931575}
1626994931.5509388: {"feed":"book","product_id":"FI_XBTUSD_210924","side":"buy","seq":13501631,"price":32188.5,"qty":16154.0,"timestamp":1626994931575}
1626994931.5509918: {"feed":"book","product_id":"FI_XBTUSD_210924","side":"sell","seq":13501632,"price":32235.5,"qty":940.0,"timestamp":1626994931575}
1626994931.551033: {"feed":"book","product_id":"FI_XBTUSD_210924","side":"sell","seq":13501633,"price":32235.5,"qty":17163.0,"timestamp":1626994931575}
1626994931.561116: {"feed":"book","product_id":"PI_LTCUSD","side":"sell","seq":3423155,"price":119.64,"qty":61.0,"timestamp":1626994931586}
1626994931.6104362: {"feed":"book","product_id":"PI_LTCUSD","side":"sell","seq":3423156,"price":119.57,"qty":5337.0,"timestamp":1626994931635}
1626994931.672489: {"feed":"book","product_id":"PI_ETHUSD","side":"sell","seq":26661296,"price":2005.75,"qty":0.0,"timestamp":1626994931698}
1626994931.6815171: {"feed":"book","product_id":"PI_ETHUSD","side":"sell","seq":26661297,"price":2005.55,"qty":18818.0,"timestamp":1626994931699}
1626994931.6939452: {"feed":"book","product_id":"PI_ETHUSD","side":"buy","seq":26661298,"price":2000.8,"qty":12519.0,"timestamp":1626994931719}
1626994931.6940548: {"feed":"book","product_id":"PI_ETHUSD","side":"buy","seq":26661299,"price":2000.55,"qty":17189.0,"timestamp":1626994931719}
1626994931.738393: {"feed":"book","product_id":"PI_ETHUSD","side":"buy","seq":26661300,"price":2003.3,"qty":0.0,"timestamp":1626994931762}
1626994931.738521: {"feed":"book","product_id":"PI_ETHUSD","side":"buy","seq":26661301,"price":2003.4,"qty":15826.0,"timestamp":1626994931762}
1626994931.75755: {"feed":"book","product_id":"PI_ETHUSD","side":"buy","seq":26661302,"price":2003.25,"qty":0.0,"timestamp":1626994931781}
1626994931.757675: {"feed":"book","product_id":"PI_ETHUSD","side":"buy","seq":26661303,"price":2003.35,"qty":20000.0,"timestamp":1626994931781}
1626994931.7836401: {"feed":"book","product_id":"FI_XBTUSD_210924","side":"buy","seq":13501634,"price":32188.5,"qty":881.0,"timestamp":1626994931808}
1626994931.783764: {"feed":"book","product_id":"FI_XBTUSD_210924","side":"buy","seq":13501635,"price":32188.5,"qty":16229.0,"timestamp":1626994931808}
1626994931.783817: {"feed":"book","product_id":"FI_XBTUSD_210924","side":"sell","seq":13501636,"price":32235.5,"qty":940.0,"timestamp":1626994931808}
1626994931.7838569: {"feed":"book","product_id":"FI_XBTUSD_210924","side":"sell","seq":13501637,"price":32235.5,"qty":17088.0,"timestamp":1626994931808}
1626994931.814195: {"feed":"book","product_id":"PI_XRPUSD","side":"buy","seq":3456203,"price":0.5875,"qty":1385.0,"timestamp":1626994931839}
1626994931.869865: {"feed":"book","product_id":"FI_ETHUSD_211231","side":"buy","seq":2198993,"price":2027.25,"qty":0.0,"timestamp":1626994931892}
1626994931.8720589: {"feed":"book","product_id":"PI_LTCUSD","side":"buy","seq":3423157,"price":119.3,"qty":4886.0,"timestamp":1626994931896}
1626994931.8721678: {"feed":"book","product_id":"PI_LTCUSD","side":"sell","seq":3423158,"price":119.55,"qty":0.0,"timestamp":1626994931898}
1626994931.885668: {"feed":"book","product_id":"PI_LTCUSD","side":"sell","seq":3423159,"price":119.58,"qty":35790.0,"timestamp":1626994931909}
1626994931.887786: {"feed":"book","product_id":"PI_LTCUSD","side":"buy","seq":3423160,"price":119.33,"qty":3816.0,"timestamp":1626994931909}
1626994931.915093: {"feed":"book","product_id":"PI_ETHUSD","side":"buy","seq":26661304,"price":2003.4,"qty":0.0,"timestamp":1626994931940}
1626994931.9152188: {"feed":"book","product_id":"PI_ETHUSD","side":"buy","seq":26661305,"price":2003.5,"qty":16426.0,"timestamp":1626994931940}
1626994931.9187331: {"feed":"book","product_id":"FI_ETHUSD_210730","side":"buy","seq":2138692,"price":1999.0,"qty":0.0,"timestamp":1626994931943}
1626994931.927896: {"feed":"book","product_id":"PI_ETHUSD","side":"buy","seq":26661306,"price":2000.55,"qty":0.0,"timestamp":1626994931953}
1626994931.928021: {"feed":"book","product_id":"PI_ETHUSD","side":"buy","seq":26661307,"price":2001.85,"qty":15118.0,"timestamp":1626994931953}
1626994931.930033: {"feed":"book","product_id":"PI_ETHUSD","side":"buy","seq":26661308,"price":2003.5,"qty":600.0,"timestamp":1626994931954}
1626994931.930141: {"feed":"book","product_id":"PI_ETHUSD","side":"buy","seq":26661309,"price":2003.2,"qty":15826.0,"timestamp":1626994931954}
1626994931.9322119: {"feed":"book","product_id":"PI_ETHUSD","side":"buy","seq":26661310,"price":2003.35,"qty":0.0,"timestamp":1626994931956}
1626994931.932336: {"feed":"book","product_id":"PI_ETHUSD","side":"buy","seq":26661311,"price":2003.15,"qty":20000.0,"timestamp":1626994931956}
1626994931.948552: {"feed":"book","product_id":"FI_ETHUSD_211231","side":"sell","seq":2198994,"price":2050.0,"qty":44305.0,"timestamp":1626994931973}
1626994931.948659: {"feed":"book","product_id":"FI_ETHUSD_211231","side":"sell","seq":2198995,"price":2049.9,"qty":45099.0,"timestamp":1626994931973}
1626994931.948722: {"feed":"book","product_id":"FI_ETHUSD_211231","side":"sell","seq":2198996,"price":2050.0,"qty":0.0,"timestamp":1626994931973}
1626994931.948777: {"feed":"book","product_id":"FI_ETHUSD_211231","side":"sell","seq":2198997,"price":2049.9,"qty":89404.0,"timestamp":1626994931973}
1626994931.9708228: {"feed":"book","product_id":"PI_ETHUSD","side":"sell","seq":26661312,"price":2005.85,"qty":3836.0,"timestamp":1626994931995}
1626994931.9740028: {"feed":"book","product_id":"PI_LTCUSD","side":"sell","seq":3423161,"price":119.59,"qty":4988.0,"timestamp":1626994931999}
1626994931.9745102: {"feed":"book","product_id":"FI_XBTUSD_210730","side":"sell","seq":5159989,"price":32199.5,"qty":0.0,"timestamp":1626994932000}
1626994931.974613: {"feed":"book","product_id":"FI_XBTUSD_210730","side":"sell","seq":5159990,"price":32198.5,"qty":251.0,"timestamp":1626994932000}
1626994931.974689: {"feed":"book","product_id":"PI_LTCUSD","side":"buy","seq":3423162,"price":119.29,"qty":0.0,"timestamp":1626994932001}
1626994931.980496: {"feed":"book","product_id":"PI_LTCUSD","side":"buy","seq":3423163,"price":119.34,"qty":32655.0,"timestamp":1626994932005}
1626994931.986133: {"feed":"book","product_id":"FI_XBTUSD_210730","side":"sell","seq":5159991,"price":32198.5,"qty":0.0,"timestamp":1626994932010}
1626994931.986258: {"feed":"book","product_id":"FI_XBTUSD_210730","side":"sell","seq":5159992,"price":32200.0,"qty":251.0,"timestamp":1626994932010}
1626994931.99009: {"feed":"book","product_id":"FI_XBTUSD_210924","side":"sell","seq":13501638,"price":32222.5,"qty":0.0,"timestamp":1626994932013}
1626994931.990218: {"feed":"book","product_id":"FI_XBTUSD_210924","side":"sell","seq":13501639,"price":32221.5,"qty":251.0,"timestamp":1626994932013}
1626994931.990283: {"feed":"book","product_id":"FI_XBTUSD_210924","side":"sell","seq":13501640,"price":32221.5,"qty":0.0,"timestamp":1626994932014}
1626994931.990334: {"feed":"book","product_id":"FI_XBTUSD_210924","side":"sell","seq":13501641,"price":32223.0,"qty":251.0,"timestamp":1626994932014}
1626994931.99922: {"feed":"book","product_id":"PI_XRPUSD","side":"buy","seq":3456204,"price":0.5881,"qty":5387.0,"timestamp":1626994932024}
1626994932.001426: {"feed":"book","product_id":"PI_XRPUSD","side":"buy","seq":3456205,"price":0.5879,"qty":16233.0,"timestamp":1626994932026}
1626994932.001899: {"feed":"book","product_id":"PI_XRPUSD","side":"sell","seq":3456206,"price":0.5894,"qty":7731.0,"timestamp":1626994932028}
1626994932.004808: {"feed":"book","product_id":"PI_XRPUSD","side":"sell","seq":3456207,"price":0.5892,"qty":11944.0,"timestamp":1626994932029}
1626994932.018837: {"feed":"book","product_id":"FI_XBTUSD_210924","side":"buy","seq":13501642,"price":32188.5,"qty":881.0,"timestamp":1626994932042}
1626994932.018912: {"feed":"book","product_id":"FI_XBTUSD_210924","side":"buy","seq":13501643,"price":32188.5,"qty":16507.0,"timestamp":1626994932042}
1626994932.018938: {"feed":"book","product_id":"FI_XBTUSD_210924","side":"sell","seq":13501644,"price":32235.5,"qty":940.0,"timestamp":1626994932042}
1626994932.018959: {"feed":"book","product_id":"FI_XBTUSD_210924","side":"sell","seq":13501645,"price":32235.5,"qty":16809.0,"timestamp":1626994932042}
1626994932.018976: {"feed":"book","product_id":"FI_XBTUSD_210924","side":"buy","seq":13501646,"price":32166.0,"qty":0.0,"timestamp":1626994932042}
1626994932.0190048: {"feed":"book","product_id":"FI_XBTUSD_210924","side":"buy","seq":13501647,"price":32166.0,"qty":20903.0,"timestamp":1626994932042}
1626994932.019029: {"feed":"book","product_id":"FI_XBTUSD_210924","side":"sell","seq":13501648,"price":32258.5,"qty":3000.0,"timestamp":1626994932042}
1626994932.0190458: {"feed":"book","product_id":"FI_XBTUSD_210924","side":"sell","seq":13501649,"price":32258.5,"qty":23960.0,"timestamp":1626994932042}
1626994932.036386: {"feed":"book","product_id":"PI_XRPUSD","side":"buy","seq":3456208,"price":0.5688,"qty":0.0,"timestamp":1626994932062}
1626994932.05617: {"feed":"book","product_id":"PI_LTCUSD","side":"buy","seq":3423164,"price":119.31,"qty":8217.0,"timestamp":1626994932081}
1626994932.059961: {"feed":"book","product_id":"FI_ETHUSD_210730","side":"buy","seq":2138693,"price":1991.4,"qty":0.0,"timestamp":1626994932084}
1626994932.060085: {"feed":"book","product_id":"FI_ETHUSD_210730","side":"buy","seq":2138694,"price":1991.5,"qty":44704.0,"timestamp":1626994932084}
1626994932.060148: {"feed":"book","product_id":"FI_ETHUSD_210730","side":"sell","seq":2138695,"price":2014.75,"qty":0.0,"timestamp":1626994932084}
1626994932.0602: {"feed":"book","product_id":"FI_ETHUSD_210730","side":"sell","seq":2138696,"price":2014.65,"qty":45421.0,"timestamp":1626994932084}
1626994932.078791: {"feed":"book","product_id":"PI_LTCUSD","side":"sell","seq":3423165,"price":119.63,"qty":28633.0,"timestamp":1626994932104}
1626994932.122486: {"feed":"book","product_id":"FI_ETHUSD_211231","side":"sell","seq":2198998,"price":2035.65,"qty":140.0,"timestamp":1626994932146}
1626994932.1226308: {"feed":"book","product_id":"FI_XRPUSD_210924","side":"buy","seq":602280,"price":0.584,"qty":0.0,"timestamp":1626994932147}
1626994932.135744: {"feed":"book","product_id":"PI_ETHUSD","side":"buy","seq":26661313,"price":2001.85,"qty":5005.0,"timestamp":1626994932156}
1626994932.1358552: {"feed":"book","product_id":"PI_ETHUSD","side":"buy","seq":26661314,"price":2000.55,"qty":17091.0,"timestamp":1626994932156}
1626994932.13592: {"feed":"book","product_id":"PI_ETHUSD","side":"buy","seq":26661315,"price":1988.9,"qty":0.0,"timestamp":1626994932156}
1626994932.135978: {"feed":"book","product_id":"PI_ETHUSD","side":"buy","seq":26661316,"price":1985.1,"qty":66923.0,"timestamp":1626994932156}
1626994932.150591: {"feed":"book","product_id":"PI_ETHUSD","side":"buy","seq":26661317,"price":1999.25,"qty":27974.0,"timestamp":1626994932176}
1626994932.238227: {"feed":"book","product_id":"FI_XBTUSD_210730","side":"buy","seq":5159993,"price":32121.5,"qty":0.0,"timestamp":1626994932261}
1626994932.238357: {"feed":"book","product_id":"FI_XBTUSD_210730","side":"buy","seq":5159994,"price":32122.0,"qty":1500.0,"timestamp":1626994932261}
1626994932.238424: {"feed":"book","product_id":"FI_XBTUSD_210924","side":"buy","seq":13501650,"price":32141.5,"qty":0.0,"timestamp":1626994932262}
1626994932.2384791: {"feed":"book","product_id":"FI_XBTUSD_210924","side":"buy","seq":13501651,"price":32143.0,"qty":1500.0,"timestamp":1626994932262}
1626994932.274585: {"feed":"book","product_id":"FI_XBTUSD_210924","side":"buy","seq":13501652,"price":32166.0,"qty":0.0,"timestamp":1626994932297}
1626994932.274718: {"feed":"book","product_id":"FI_XBTUSD_210924","side":"buy","seq":13501653,"price":32166.5,"qty":20903.0,"timestamp":1626994932297}
1626994932.370713: {"feed":"book","product_id":"PI_ETHUSD","side":"sell","seq":26661318,"price":2006.3,"qty":23373.0,"timestamp":1626994932396}
1626994932.373016: {"feed":"book","product_id":"PI_ETHUSD","side":"buy","seq":26661319,"price":2003.75,"qty":3908.0,"timestamp":1626994932397}
1626994932.373141: {"feed":"book","product_id":"PI_ETHUSD","side":"sell","seq":26661320,"price":2006.65,"qty":8028.0,"timestamp":1626994932397}
1626994932.373194: {"feed":"book","product_id":"PI_ETHUSD","side":"buy","seq":26661321,"price":2003.05,"qty":1312.0,"timestamp":1626994932398}
1626994932.391556: {"feed":"book","product_id":"PI_ETHUSD","side":"buy","seq":26661322,"price":2003.1,"qty":7945.0,"timestamp":1626994932399}
1626994932.3916311: {"feed":"book","product_id":"PI_ETHUSD","side":"buy","seq":26661323,"price":2003.55,"qty":0.0,"timestamp":1626994932399}
1626994932.391679: {"feed":"book","product_id":"PI_ETHUSD","side":"sell","seq":26661324,"price":2006.65,"qty":4192.0,"timestamp":1626994932399}
1626994932.391708: {"feed":"book","product_id":"PI_ETHUSD","side":"buy","seq":26661325,"price":2002.6,"qty":10000.0,"timestamp":1626994932400}
1626994932.391732: {"feed":"book","product_id":"PI_ETHUSD","side":"buy","seq":26661326,"price":1985.1,"qty":0.0,"timestamp":1626994932400}
1626994932.3917608: {"feed":"book","product_id":"PI_ETHUSD","side":"buy","seq":26661327,"price":1988.9,"qty":66923.0,"timestamp":1626994932400}
1626994932.3917902: {"feed":"book","product_id":"PI_ETHUSD","side":"buy","seq":26661328,"price":1995.1,"qty":0.0,"timestamp":1626994932400}
1626994932.3918169: {"feed":"book","product_id":"PI_ETHUSD","side":"buy","seq":26661329,"price":1995.2,"qty":47033.0,"timestamp":1626994932400}
1626994932.391843: {"feed":"book","product_id":"PI_ETHUSD","side":"sell","seq":26661330,"price":2013.05,"qty":0.0,"timestamp":1626994932400}
1626994932.391871: {"feed":"book","product_id":"PI_ETHUSD","side":"sell","seq":26661331,"price":2012.95,"qty":49782.0,"timestamp":1626994932400}
1626994932.3918972: {"feed":"book","product_id":"PI_ETHUSD","side":"sell","seq":26661332,"price":2005.9,"qty":0.0,"timestamp":1626994932400}
1626994932.391924: {"feed":"book","product_id":"PI_ETHUSD","side":"sell","seq":26661333,"price":2005.9,"qty":11200.0,"timestamp":1626994932400}
1626994932.391949: {"feed":"book","product_id":"PI_ETHUSD","side":"sell","seq":26661334,"price":2007.0,"qty":5000.0,"timestamp":1626994932400}
1626994932.3919702: {"feed":"book","product_id":"PI_ETHUSD","side":"sell","seq":26661335,"price":2007.0,"qty":23203.0,"timestamp":1626994932400}
1626994932.39199: {"feed":"book","product_id":"PI_ETHUSD","side":"buy","seq":26661336,"price":2000.85,"qty":0.0,"timestamp":1626994932400}
1626994932.392017: {"feed":"book","product_id":"PI_ETHUSD","side":"buy","seq":26661337,"price":2000.85,"qty":14995.0,"timestamp":1626994932400}
1626994932.392042: {"feed":"book","product_id":"PI_ETHUSD","side":"sell","seq":26661338,"price":2007.7,"qty":8564.0,"timestamp":1626994932400}
1626994932.392063: {"feed":"book","product_id":"PI_ETHUSD","side":"sell","seq":26661339,"price":2007.7,"qty":32146.0,"timestamp":1626994932400}
1626994932.392082: {"feed":"book","product_id":"PI_ETHUSD","side":"buy","seq":26661340,"price":1999.65,"qty":0.0,"timestamp":1626994932400}
1626994932.392108: {"feed":"book","product_id":"PI_ETHUSD","side":"buy","seq":26661341,"price":1999.65,"qty":23945.0,"timestamp":1626994932400}
1626994932.3921332: {"feed":"book","product_id":"PI_ETHUSD","side":"buy","seq":26661342,"price":2000.55,"qty":0.0,"timestamp":1626994932400}
1626994932.392158: {"feed":"book","product_id":"PI_ETHUSD","side":"buy","seq":26661343,"price":2000.55,"qty":17156.0,"timestamp":1626994932400}
1626994932.392182: {"feed":"book","product_id":"PI_ETHUSD","side":"sell","seq":26661344,"price":2021.45,"qty":0.0,"timestamp":1626994932400}
1626994932.3922071: {"feed":"book","product_id":"PI_ETHUSD","side":"sell","seq":26661345,"price":2021.45,"qty":67920.0,"timestamp":1626994932400}
1626994932.392232: {"feed":"book","product_id":"PI_ETHUSD","side":"sell","seq":26661346,"price":2007.15,"qty":4132.0,"timestamp":1626994932400}
1626994932.392256: {"feed":"book","product_id":"PI_ETHUSD","side":"buy","seq":26661347,"price":2003.4,"qty":3844.0,"timestamp":1626994932401}
1626994932.39228: {"feed":"book","product_id":"PI_ETHUSD","side":"sell","seq":26661348,"price":2004.5,"qty":2066.0,"timestamp":1626994932404}
1626994932.3923042: {"feed":"book","product_id":"PI_ETHUSD","side":"sell","seq":26661349,"price":2005.45,"qty":114385.0,"timestamp":1626994932410}
1626994932.4084558: {"feed":"book","product_id":"PI_ETHUSD","side":"sell","seq":26661350,"price":2005.5,"qty":4078.0,"timestamp":1626994932432}
1626994932.408581: {"feed":"book","product_id":"PI_ETHUSD","side":"buy","seq":26661351,"price":2003.2,"qty":0.0,"timestamp":1626994932433}
1626994932.40865: {"feed":"book","product_id":"PI_ETHUSD","side":"buy","seq":26661352,"price":2003.75,"qty":19734.0,"timestamp":1626994932433}
1626994932.408695: {"feed":"book","product_id":"PI_ETHUSD","side":"buy","seq":26661353,"price":2003.15,"qty":0.0,"timestamp":1626994932434}
1626994932.408742: {"feed":"book","product_id":"PI_ETHUSD","side":"buy","seq":26661354,"price":2003.7,"qty":20000.0,"timestamp":1626994932434}
1626994932.412692: {"feed":"book","product_id":"FI_ETHUSD_211231","side":"buy","seq":2198999,"price":2025.6,"qty":0.0,"timestamp":1626994932438}
1626994932.47877: {"feed":"book","product_id":"FI_XBTUSD_210924","side":"buy","seq":13501654,"price":32166.5,"qty":0.0,"timestamp":1626994932501}
1626994932.478894: {"feed":"book","product_id":"FI_XBTUSD_210924","side":"buy","seq":13501655,"price":32166.0,"qty":20903.0,"timestamp":1626994932501}
1626994932.4935849: {"feed":"book","product_id":"PI_ETHUSD","side":"buy","seq":26661355,"price":1999.6,"qty":3885.0,"timestamp":1626994932516}
1626994932.493694: {"feed":"book","product_id":"PI_ETHUSD","side":"buy","seq":26661356,"price":1999.7,"qty":500001.0,"timestamp":1626994932516}
1626994932.493763: {"feed":"book","product_id":"FI_ETHUSD_210730","side":"buy","seq":2138697,"price":1991.45,"qty":23734.0,"timestamp":1626994932516}
1626994932.493828: {"feed":"book","product_id":"FI_ETHUSD_210730","side":"buy","seq":2138698,"price":1989.75,"qty":250002.0,"timestamp":1626994932516}
1626994932.493875: {"feed":"book","product_id":"PI_ETHUSD","side":"sell","seq":26661357,"price":2007.35,"qty":4164.0,"timestamp":1626994932516}
1626994932.49392: {"feed":"book","product_id":"PI_ETHUSD","side":"sell","seq":26661358,"price":2007.7,"qty":532147.0,"timestamp":1626994932516}
1626994932.493966: {"feed":"book","product_id":"FI_ETHUSD_210730","side":"sell","seq":2138699,"price":2014.7,"qty":0.0,"timestamp":1626994932516}
1626994932.4940002: {"feed":"book","product_id":"FI_ETHUSD_210730","side":"sell","seq":2138700,"price":2014.6,"qty":250002.0,"timestamp":1626994932516}
1626994932.494026: {"feed":"book","product_id":"PI_ETHUSD","side":"buy","seq":26661359,"price":1995.15,"qty":0.0,"timestamp":1626994932516}
1626994932.4940548: {"feed":"book","product_id":"PI_ETHUSD","side":"buy","seq":26661360,"price":1995.25,"qty":500002.0,"timestamp":1626994932516}
1626994932.494082: {"feed":"book","product_id":"PI_ETHUSD","side":"sell","seq":26661361,"price":2013.0,"qty":0.0,"timestamp":1626994932516}
1626994932.4941099: {"feed":"book","product_id":"PI_ETHUSD","side":"sell","seq":26661362,"price":2012.9,"qty":500002.0,"timestamp":1626994932516}
1626994932.494136: {"feed":"book","product_id":"FI_ETHUSD_211231","side":"sell","seq":2199000,"price":2049.95,"qty":0.0,"timestamp":1626994932516}
1626994932.494169: {"feed":"book","product_id":"FI_ETHUSD_211231","side":"sell","seq":2199001,"price":2049.85,"qty":250002.0,"timestamp":1626994932516}
1626994932.528345: {"feed":"book","product_id":"PI_ETHUSD","side":"sell","seq":26661363,"price":2005.5,"qty":0.0,"timestamp":1626994932552}
1626994932.556447: {"feed":"book","product_id":"PI_ETHUSD","side":"buy","seq":26661364,"price":2003.7,"qty":0.0,"timestamp":1626994932581}
1626994932.556577: {"feed":"book","product_id":"PI_ETHUSD","side":"buy","seq":26661365,"price":2003.6,"qty":20000.0,"timestamp":1626994932581}
1626994932.556643: {"feed":"book","product_id":"PI_ETHUSD","side":"buy","seq":26661366,"price":2003.75,"qty":3908.0,"timestamp":1626994932581}
1626994932.5566862: {"feed":"book","product_id":"PI_ETHUSD","side":"buy","seq":26661367,"price":2003.65,"qty":15826.0,"timestamp":1626994932581}
1626994932.580309: {"feed":"book","product_id":"PI_ETHUSD","side":"sell","seq":26661368,"price":2005.9,"qty":0.0,"timestamp":1626994932604}
1626994932.580437: {"feed":"book","product_id":"PI_ETHUSD","side":"sell","seq":26661369,"price":2005.9,"qty":10894.0,"timestamp":1626994932604}
1626994932.5805042: {"feed":"book","product_id":"PI_ETHUSD","side":"buy","seq":26661370,"price":2000.55,"qty":0.0,"timestamp":1626994932604}
1626994932.5805628: {"feed":"book","product_id":"PI_ETHUSD","side":"buy","seq":26661371,"price":2000.55,"qty":17613.0,"timestamp":1626994932604}
1626994932.580619: {"feed":"book","product_id":"PI_ETHUSD","side":"sell","seq":26661372,"price":2007.0,"qty":5000.0,"timestamp":1626994932604}
1626994932.580673: {"feed":"book","product_id":"PI_ETHUSD","side":"sell","seq":26661373,"price":2007.0,"qty":22743.0,"timestamp":1626994932604}
1626994932.5806952: {"feed":"book","product_id":"PI_ETHUSD","side":"buy","seq":26661374,"price":2000.85,"qty":0.0,"timestamp":1626994932604}
1626994932.580723: {"feed":"book","product_id":"PI_ETHUSD","side":"buy","seq":26661375,"price":2000.85,"qty":15300.0,"timestamp":1626994932604}
1626994932.580749: {"feed":"book","product_id":"PI_ETHUSD","side":"sell","seq":26661376,"price":2007.7,"qty":508565.0,"timestamp":1626994932604}
1626994932.580771: {"feed":"book","product_id":"PI_ETHUSD","side":"sell","seq":26661377,"price":2007.7,"qty":531840.0,"timestamp":1626994932604}
1626994932.5836742: {"feed":"book","product_id":"PI_ETHUSD","side":"buy","seq":26661378,"price":1999.65,"qty":0.0,"timestamp":1626994932604}
1626994932.583763: {"feed":"book","product_id":"PI_ETHUSD","side":"buy","seq":26661379,"price":1999.65,"qty":24248.0,"timestamp":1626994932604}
1626994932.583807: {"feed":"book","product_id":"PI_ETHUSD","side":"buy","seq":26661380,"price":1995.2,"qty":0.0,"timestamp":1626994932604}
1626994932.583843: {"feed":"book","product_id":"PI_ETHUSD","side":"buy","seq":26661381,"price":1995.2,"qty":47206.0,"timestamp":1626994932604}
1626994932.583873: {"feed":"book","product_id":"PI_ETHUSD","side":"sell","seq":26661382,"price":2012.95,"qty":0.0,"timestamp":1626994932604}
1626994932.583905: {"feed":"book","product_id":"PI_ETHUSD","side":"sell","seq":26661383,"price":2012.95,"qty":49606.0,"timestamp":1626994932604}
1626994932.583932: {"feed":"book","product_id":"PI_ETHUSD","side":"buy","seq":26661384,"price":1988.9,"qty":0.0,"timestamp":1626994932604}
1626994932.583959: {"feed":"book","product_id":"PI_ETHUSD","side":"buy","seq":26661385,"price":1988.9,"qty":66925.0,"timestamp":1626994932604}
1626994932.5839849: {"feed":"book","product_id":"PI_ETHUSD","side":"sell","seq":26661386,"price":2021.45,"qty":0.0,"timestamp":1626994932604}
1626994932.584012: {"feed":"book","product_id":"PI_ETHUSD","side":"sell","seq":26661387,"price":2021.45,"qty":67922.0,"timestamp":1626994932604}
1626994932.611495: {"feed":"book","product_id":"PI_ETHUSD","side":"buy","seq":26661388,"price":2002.15,"qty":3915.0,"timestamp":1626994932636}
1626994932.611603: {"feed":"book","product_id":"PI_ETHUSD","side":"sell","seq":26661389,"price":2005.45,"qty":119370.0,"timestamp":1626994932637}
1626994932.627472: {"feed":"book","product_id":"PI_ETHUSD","side":"buy","seq":26661390,"price":2002.3,"qty":4605.0,"timestamp":1626994932652}
1626994932.661674: {"feed":"book","product_id":"FI_ETHUSD_211231","side":"sell","seq":2199002,"price":2049.9,"qty":44305.0,"timestamp":1626994932686}
1626994932.6617851: {"feed":"book","product_id":"FI_ETHUSD_211231","side":"sell","seq":2199003,"price":2049.8,"qty":45099.0,"timestamp":1626994932686}
1626994932.6618502: {"feed":"book","product_id":"FI_ETHUSD_211231","side":"sell","seq":2199004,"price":2049.9,"qty":0.0,"timestamp":1626994932686}
1626994932.661906: {"feed":"book","product_id":"FI_ETHUSD_211231","side":"sell","seq":2199005,"price":2049.8,"qty":89404.0,"timestamp":1626994932686}
1626994932.671886: {"feed":"book","product_id":"PI_ETHUSD","side":"buy","seq":26661391,"price":2003.75,"qty":0.0,"timestamp":1626994932696}
1626994932.672011: {"feed":"book","product_id":"PI_LTCUSD","side":"buy","seq":3423166,"price":119.34,"qty":28553.0,"timestamp":1626994932698}
1626994932.6888902: {"feed":"book","product_id":"PI_LTCUSD","side":"sell","seq":3423167,"price":119.59,"qty":14587.0,"timestamp":1626994932714}
1626994932.6945632: {"feed":"book","product_id":"FI_BCHUSD_210730","side":"sell","seq":91193,"price":439.6,"qty":0.0,"timestamp":1626994932720}
1626994932.6946821: {"feed":"book","product_id":"FI_BCHUSD_210730","side":"sell","seq":91194,"price":439.8,"qty":50.0,"timestamp":1626994932720}
1626994932.709286: {"feed":"book","product_id":"FI_BCHUSD_210730","side":"sell","seq":91195,"price":439.8,"qty":0.0,"timestamp":1626994932732}
1626994932.709409: {"feed":"book","product_id":"FI_BCHUSD_210730","side":"sell","seq":91196,"price":439.5,"qty":50.0,"timestamp":1626994932732}
1626994932.725651: {"feed":"book","product_id":"PI_LTCUSD","side":"sell","seq":3423168,"price":119.56,"qty":2096.0,"timestamp":1626994932750}
1626994932.726102: {"feed":"book","product_id":"PI_LTCUSD","side":"sell","seq":3423169,"price":119.54,"qty":5250.0,"timestamp":1626994932751}
1626994932.7517529: {"feed":"book","product_id":"FI_XBTUSD_210924","side":"buy","seq":13501656,"price":32166.0,"qty":0.0,"timestamp":1626994932775}
1626994932.751841: {"feed":"book","product_id":"FI_XBTUSD_210924","side":"buy","seq":13501657,"price":32167.0,"qty":20903.0,"timestamp":1626994932775}
1626994932.784234: {"feed":"book","product_id":"PI_ETHUSD","side":"buy","seq":26661392,"price":1999.65,"qty":0.0,"timestamp":1626994932809}
1626994932.784362: {"feed":"book","product_id":"PI_ETHUSD","side":"buy","seq":26661393,"price":1999.75,"qty":23452.0,"timestamp":1626994932809}
1626994932.784427: {"feed":"book","product_id":"PI_ETHUSD","side":"sell","seq":26661394,"price":2007.7,"qty":508565.0,"timestamp":1626994932809}
1626994932.78447: {"feed":"book","product_id":"PI_ETHUSD","side":"sell","seq":26661395,"price":2007.65,"qty":23234.0,"timestamp":1626994932809}
1626994932.788683: {"feed":"book","product_id":"PI_ETHUSD","side":"buy","seq":26661396,"price":1995.2,"qty":0.0,"timestamp":1626994932809}
1626994932.788824: {"feed":"book","product_id":"PI_ETHUSD","side":"buy","seq":26661397,"price":1995.3,"qty":46754.0,"timestamp":1626994932809}
1626994932.7888691: {"feed":"book","product_id":"PI_ETHUSD","side":"sell","seq":26661398,"price":2012.95,"qty":0.0,"timestamp":1626994932809}
1626994932.788907: {"feed":"book","product_id":"PI_ETHUSD","side":"sell","seq":26661399,"price":2012.85,"qty":49420.0,"timestamp":1626994932809}
1626994932.788938: {"feed":"book","product_id":"PI_ETHUSD","side":"sell","seq":26661400,"price":2005.9,"qty":0.0,"timestamp":1626994932809}
1626994932.788967: {"feed":"book","product_id":"PI_ETHUSD","side":"sell","seq":26661401,"price":2005.9,"qty":11135.0,"timestamp":1626994932809}
1626994932.788994: {"feed":"book","product_id":"PI_ETHUSD","side":"buy","seq":26661402,"price":2000.55,"qty":0.0,"timestamp":1626994932809}
1626994932.789022: {"feed":"book","product_id":"PI_ETHUSD","side":"buy","seq":26661403,"price":2000.55,"qty":17253.0,"timestamp":1626994932809}
1626994932.7890491: {"feed":"book","product_id":"PI_ETHUSD","side":"sell","seq":26661404,"price":2007.0,"qty":5000.0,"timestamp":1626994932809}
1626994932.789071: {"feed":"book","product_id":"PI_ETHUSD","side":"sell","seq":26661405,"price":2007.0,"qty":23105.0,"timestamp":1626994932809}
1626994932.789092: {"feed":"book","product_id":"PI_ETHUSD","side":"buy","seq":26661406,"price":2000.85,"qty":0.0,"timestamp":1626994932809}
1626994932.789118: {"feed":"book","product_id":"PI_ETHUSD","side":"buy","seq":26661407,"price":2000.85,"qty":15060.0,"timestamp":1626994932809}
1626994932.789143: {"feed":"book","product_id":"PI_ETHUSD","side":"buy","seq":26661408,"price":1988.9,"qty":0.0,"timestamp":1626994932809}
1626994932.7891688: {"feed":"book","product_id":"PI_ETHUSD","side":"buy","seq":26661409,"price":1988.9,"qty":66923.0,"timestamp":1626994932809}
1626994932.7891939: {"feed":"book","product_id":"PI_ETHUSD","side":"sell","seq":26661410,"price":2021.45,"qty":0.0,"timestamp":1626994932809}
1626994932.78922: {"feed":"book","product_id":"PI_ETHUSD","side":"sell","seq":26661411,"price":2021.45,"qty":67920.0,"timestamp":1626994932809}
1626994932.801259: {"feed":"book","product_id":"PI_ETHUSD","side":"buy","seq":26661412,"price":2003.65,"qty":0.0,"timestamp":1626994932826}
1626994932.801388: {"feed":"book","product_id":"PI_ETHUSD","side":"buy","seq":26661413,"price":2003.75,"qty":15826.0,"timestamp":1626994932826}
1626994932.801455: {"feed":"book","product_id":"PI_ETHUSD","side":"buy","seq":26661414,"price":2003.6,"qty":0.0,"timestamp":1626994932826}
1626994932.801507: {"feed":"book","product_id":"PI_ETHUSD","side":"buy","seq":26661415,"price":2003.7,"qty":20000.0,"timestamp":1626994932826}
1626994932.8131788: {"feed":"book","product_id":"PI_ETHUSD","side":"buy","seq":26661416,"price":2002.3,"qty":0.0,"timestamp":1626994932838}
1626994932.856266: {"feed":"book","product_id":"PI_LTCUSD","side":"buy","seq":3423170,"price":119.31,"qty":4067.0,"timestamp":1626994932880}
1626994932.955623: {"feed":"book","product_id":"FI_XBTUSD_210924","side":"buy","seq":13501658,"price":32167.0,"qty":0.0,"timestamp":1626994932979}
1626994932.955746: {"feed":"book","product_id":"FI_XBTUSD_210924","side":"buy","seq":13501659,"price":32166.0,"qty":20903.0,"timestamp":1626994932979}
1626994932.9810739: {"feed":"book","product_id":"PI_LTCUSD","side":"buy","seq":3423171,"price":119.32,"qty":4082.0,"timestamp":1626994933005}
1626994933.0204852: {"feed":"book","product_id":"PI_ETHUSD","side":"sell","seq":26661417,"price":2005.9,"qty":0.0,"timestamp":1626994933043}
1626994933.020618: {"feed":"book","product_id":"PI_ETHUSD","side":"sell","seq":26661418,"price":2005.9,"qty":11178.0,"timestamp":1626994933043}
1626994933.0206988: {"feed":"book","product_id":"PI_ETHUSD","side":"buy","seq":26661419,"price":2000.55,"qty":0.0,"timestamp":1626994933043}
1626994933.020736: {"feed":"book","product_id":"PI_ETHUSD","side":"buy","seq":26661420,"price":2000.55,"qty":17189.0,"timestamp":1626994933043}
1626994933.0207648: {"feed":"book","product_id":"PI_ETHUSD","side":"sell","seq":26661421,"price":2007.0,"qty":5000.0,"timestamp":1626994933043}
1626994933.020789: {"feed":"book","product_id":"PI_ETHUSD","side":"sell","seq":26661422,"price":2007.0,"qty":23170.0,"timestamp":1626994933043}
1626994933.020809: {"feed":"book","product_id":"PI_ETHUSD","side":"buy","seq":26661423,"price":2000.85,"qty":0.0,"timestamp":1626994933043}
1626994933.020836: {"feed":"book","product_id":"PI_ETHUSD","side":"buy","seq":26661424,"price":2000.85,"qty":15016.0,"timestamp":1626994933043}
1626994933.0211809: {"feed":"book","product_id":"PI_ETHUSD","side":"sell","seq":26661425,"price":2007.65,"qty":0.0,"timestamp":1626994933043}
1626994933.0212321: {"feed":"book","product_id":"PI_ETHUSD","side":"sell","seq":26661426,"price":2007.65,"qty":23278.0,"timestamp":1626994933043}
1626994933.021266: {"feed":"book","product_id":"PI_ETHUSD","side":"buy","seq":26661427,"price":1999.75,"qty":0.0,"timestamp":1626994933043}
1626994933.021303: {"feed":"book","product_id":"PI_ETHUSD","side":"buy","seq":26661428,"price":1999.75,"qty":23409.0,"timestamp":1626994933043}
1626994933.021333: {"feed":"book","product_id":"PI_ETHUSD","side":"buy","seq":26661429,"price":1995.3,"qty":0.0,"timestamp":1626994933043}
1626994933.0213609: {"feed":"book","product_id":"PI_ETHUSD","side":"buy","seq":26661430,"price":1995.3,"qty":46729.0,"timestamp":1626994933043}
1626994933.0216079: {"feed":"book","product_id":"PI_ETHUSD","side":"sell","seq":26661431,"price":2012.85,"qty":0.0,"timestamp":1626994933043}
1626994933.0216541: {"feed":"book","product_id":"PI_ETHUSD","side":"sell","seq":26661432,"price":2012.85,"qty":49445.0,"timestamp":1626994933043}
1626994933.025095: {"feed":"book","product_id":"PI_ETHUSD","side":"buy","seq":26661433,"price":2002.5,"qty":4874.0,"timestamp":1626994933049}
1626994933.035527: {"feed":"book","product_id":"FI_XRPUSD_210924","side":"sell","seq":602281,"price":0.5876,"qty":45.0,"timestamp":1626994933061}
1626994933.045043: {"feed":"book","product_id":"FI_BCHUSD_210924","side":"sell","seq":402230,"price":442.7,"qty":81.0,"timestamp":1626994933070}
1626994933.0451672: {"feed":"book","product_id":"FI_BCHUSD_210924","side":"buy","seq":402231,"price":440.3,"qty":0.0,"timestamp":1626994933070}
1626994933.055543: {"feed":"book","product_id":"PI_ETHUSD","side":"buy","seq":26661434,"price":2003.75,"qty":0.0,"timestamp":1626994933079}
1626994933.0556731: {"feed":"book","product_id":"PI_ETHUSD","side":"buy","seq":26661435,"price":2003.65,"qty":15826.0,"timestamp":1626994933079}
1626994933.0557408: {"feed":"book","product_id":"PI_ETHUSD","side":"buy","seq":26661436,"price":2003.7,"qty":0.0,"timestamp":1626994933079}
1626994933.0557928: {"feed":"book","product_id":"PI_ETHUSD","side":"buy","seq":26661437,"price":2003.6,"qty":20000.0,"timestamp":1626994933079}
1626994933.056152: {"feed":"book","product_id":"PI_LTCUSD","side":"buy","seq":3423172,"price":119.3,"qty":8934.0,"timestamp":1626994933082}
1626994933.079351: {"feed":"book","product_id":"PI_ETHUSD","side":"sell","seq":26661438,"price":2004.7,"qty":5990.0,"timestamp":1626994933103}
1626994933.080579: {"feed":"book","product_id":"PI_ETHUSD","side":"sell","seq":26661439,"price":2004.5,"qty":0.0,"timestamp":1626994933106}
1626994933.093045: {"feed":"book","product_id":"PI_ETHUSD","side":"buy","seq":26661440,"price":2003.65,"qty":0.0,"timestamp":1626994933117}
1626994933.093172: {"feed":"book","product_id":"PI_ETHUSD","side":"buy","seq":26661441,"price":2003.75,"qty":15826.0,"timestamp":1626994933117}
1626994933.093241: {"feed":"book","product_id":"PI_ETHUSD","side":"buy","seq":26661442,"price":2003.6,"qty":0.0,"timestamp":1626994933118}
1626994933.093295: {"feed":"book","product_id":"PI_ETHUSD","side":"buy","seq":26661443,"price":2003.7,"qty":20000.0,"timestamp":1626994933118}
1626994933.097447: {"feed":"book","product_id":"PI_ETHUSD","side":"sell","seq":26661444,"price":2004.85,"qty":600.0,"timestamp":1626994933122}
1626994933.126954: {"feed":"book","product_id":"FI_XBTUSD_210924","side":"sell","seq":13501660,"price":32223.0,"qty":0.0,"timestamp":1626994933152}
1626994933.1270819: {"feed":"book","product_id":"FI_XBTUSD_210924","side":"sell","seq":13501661,"price":32224.0,"qty":103.0,"timestamp":1626994933152}
1626994933.139269: {"feed":"book","product_id":"FI_XBTUSD_210924","side":"sell","seq":13501662,"price":32224.0,"qty":0.0,"timestamp":1626994933163}
1626994933.139394: {"feed":"book","product_id":"FI_XBTUSD_210924","side":"sell","seq":13501663,"price":32225.0,"qty":103.0,"timestamp":1626994933163}
1626994933.144128: {"feed":"book","product_id":"PI_ETHUSD","side":"buy","seq":26661445,"price":2003.75,"qty":0.0,"timestamp":1626994933169}
1626994933.1442602: {"feed":"book","product_id":"PI_ETHUSD","side":"buy","seq":26661446,"price":2003.85,"qty":15826.0,"timestamp":1626994933169}
1626994933.1461241: {"feed":"book","product_id":"PI_ETHUSD","side":"buy","seq":26661447,"price":2003.7,"qty":0.0,"timestamp":1626994933170}
1626994933.146261: {"feed":"book","product_id":"PI_ETHUSD","side":"buy","seq":26661448,"price":2003.8,"qty":20000.0,"timestamp":1626994933170}
1626994933.1506119: {"feed":"book","product_id":"FI_XBTUSD_210730","side":"sell","seq":5159995,"price":32200.0,"qty":0.0,"timestamp":1626994933175}
1626994933.150743: {"feed":"book","product_id":"FI_XBTUSD_210730","side":"sell","seq":5159996,"price":32201.0,"qty":164034.0,"timestamp":1626994933175}
1626994933.151158: {"feed":"book","product_id":"FI_XBTUSD_210730","side":"sell","seq":5159997,"price":32201.0,"qty":163931.0,"timestamp":1626994933176}
1626994933.151228: {"feed":"book","product_id":"FI_XBTUSD_210730","side":"sell","seq":5159998,"price":32202.0,"qty":103.0,"timestamp":1626994933176}
1626994933.151287: {"feed":"book","product_id":"FI_ETHUSD_211231","side":"buy","seq":2199006,"price":2027.1,"qty":123.0,"timestamp":1626994933176}
1626994933.151335: {"feed":"book","product_id":"PI_ETHUSD","side":"buy","seq":26661449,"price":1998.95,"qty":0.0,"timestamp":1626994933176}
1626994933.151391: {"feed":"book","product_id":"PI_ETHUSD","side":"buy","seq":26661450,"price":2001.4,"qty":5695.0,"timestamp":1626994933176}
1626994933.187093: {"feed":"book","product_id":"FI_XBTUSD_210924","side":"sell","seq":13501664,"price":32225.0,"qty":0.0,"timestamp":1626994933210}
1626994933.1872241: {"feed":"book","product_id":"FI_XBTUSD_210924","side":"sell","seq":13501665,"price":32226.0,"qty":103.0,"timestamp":1626994933210}
1626994933.191356: {"feed":"book","product_id":"FI_XBTUSD_210924","side":"buy","seq":13501666,"price":32188.5,"qty":881.0,"timestamp":1626994933213}
1626994933.191475: {"feed":"book","product_id":"FI_XBTUSD_210924","side":"buy","seq":13501667,"price":32188.5,"qty":16515.0,"timestamp":1626994933213}
1626994933.191526: {"feed":"book","product_id":"FI_XBTUSD_210924","side":"sell","seq":13501668,"price":32235.5,"qty":940.0,"timestamp":1626994933213}
1626994933.191566: {"feed":"book","product_id":"FI_XBTUSD_210924","side":"sell","seq":13501669,"price":32235.5,"qty":16801.0,"timestamp":1626994933213}
1626994933.191963: {"feed":"book","product_id":"FI_XBTUSD_210730","side":"sell","seq":5159999,"price":32202.0,"qty":0.0,"timestamp":1626994933217}
1626994933.192018: {"feed":"book","product_id":"FI_XBTUSD_210730","side":"sell","seq":5160000,"price":32203.0,"qty":103.0,"timestamp":1626994933217}
1626994933.2159412: {"feed":"book","product_id":"PI_ETHUSD","side":"buy","seq":26661451,"price":2003.85,"qty":0.0,"timestamp":1626994933240}
1626994933.216068: {"feed":"book","product_id":"PI_ETHUSD","side":"buy","seq":26661452,"price":2003.75,"qty":15826.0,"timestamp":1626994933240}
1626994933.2161338: {"feed":"book","product_id":"FI_XBTUSD_210730","side":"sell","seq":5160001,"price":32203.0,"qty":0.0,"timestamp":1626994933240}
1626994933.2161868: {"feed":"book","product_id":"FI_XBTUSD_210730","side":"sell","seq":5160002,"price":32204.0,"qty":103.0,"timestamp":1626994933240}
1626994933.216576: {"feed":"book","product_id":"PI_ETHUSD","side":"buy","seq":26661453,"price":2003.8,"qty":0.0,"timestamp":1626994933240}
1626994933.216627: {"feed":"book","product_id":"PI_ETHUSD","side":"buy","seq":26661454,"price":2003.7,"qty":20000.0,"timestamp":1626994933240}
1626994933.220175: {"feed":"book","product_id":"PI_ETHUSD","side":"buy","seq":26661455,"price":2003.75,"qty":0.0,"timestamp":1626994933244}
1626994933.220302: {"feed":"book","product_id":"PI_ETHUSD","side":"buy","seq":26661456,"price":2003.85,"qty":15826.0,"timestamp":1626994933244}
1626994933.2245271: {"feed":"book","product_id":"PI_ETHUSD","side":"buy","seq":26661457,"price":2003.7,"qty":0.0,"timestamp":1626994933248}
1626994933.224659: {"feed":"book","product_id":"PI_ETHUSD","side":"buy","seq":26661458,"price":2003.8,"qty":20000.0,"timestamp":1626994933248}
1626994933.225106: {"feed":"book","product_id":"FI_XBTUSD_210924","side":"sell","seq":13501670,"price":32258.5,"qty":20960.0,"timestamp":1626994933249}
1626994933.2266629: {"feed":"book","product_id":"PI_ETHUSD","side":"sell","seq":26661459,"price":2005.25,"qty":0.0,"timestamp":1626994933251}
