1618678115.773524: {"feed":"book","product_id":"FI_ETHUSD_210625","side":"sell","seq":12455727,"price":2515.85,"qty":0.0,"timestamp":1618678115736}
1618678115.773551: {"feed":"book","product_id":"PI_BCHUSD","side":"buy","seq":16259100,"price":1057.7,"qty":19659.0,"timestamp":1618678115743}
1618678115.7735748: {"feed":"book","product_id":"FI_XBTUSD_210924","side":"sell","seq":13850960,"price":68281.0,"qty":23999.0,"timestamp":1618678115742}
1618678115.773597: {"feed":"book","product_id":"FI_XBTUSD_210924","side":"sell","seq":13850961,"price":68280.5,"qty":10000.0,"timestamp":1618678115742}
1618678115.7775328: {"feed":"book","product_id":"FI_ETHUSD_210625","side":"sell","seq":12455728,"price":2508.0,"qty":0.0,"timestamp":1618678115750}
1618678115.777622: {"feed":"book","product_id":"FI_ETHUSD_210625","side":"sell","seq":12455729,"price":2505.45,"qty":12246.0,"timestamp":1618678115750}
1618678115.777664: {"feed":"book","product_id":"FI_ETHUSD_210625","side":"buy","seq":12455730,"price":2495.15,"qty":0.0,"timestamp":1618678115750}
1618678115.777697: {"feed":"book","product_id":"FI_ETHUSD_210625","side":"buy","seq":12455731,"price":2497.5,"qty":351.0,"timestamp":1618678115750}
1618678115.791381: {"feed":"book","product_id":"PI_BCHUSD","side":"sell","seq":16259101,"price":1067.5,"qty":14641.0,"timestamp":1618678115756}
1618678115.7915058: {"feed":"book","product_id":"PI_BCHUSD","side":"sell","seq":16259102,"price":1080.3,"qty":112508.0,"timestamp":1618678115756}
1618678115.7915561: {"feed":"book","product_id":"PI_BCHUSD","side":"sell","seq":16259103,"price":1083.4,"qty":14641.0,"timestamp":1618678115757}
1618678115.791599: {"feed":"book","product_id":"PI_BCHUSD","side":"sell","seq":16259104,"price":1099.4,"qty":14641.0,"timestamp":1618678115757}
1618678115.791637: {"feed":"book","product_id":"PI_BCHUSD","side":"buy","seq":16259105,"price":1054.8,"qty":19802.0,"timestamp":1618678115757}
1618678115.79167: {"feed":"book","product_id":"PI_BCHUSD","side":"buy","seq":16259106,"price":1048.1,"qty":267883.0,"timestamp":1618678115757}
1618678115.791701: {"feed":"book","product_id":"PI_BCHUSD","side":"buy","seq":16259107,"price":1034.0,"qty":14741.0,"timestamp":1618678115757}
1618678115.791738: {"feed":"book","product_id":"PI_BCHUSD","side":"buy","seq":16259108,"price":1021.1,"qty":40056.0,"timestamp":1618678115757}
1618678115.7918022: {"feed":"book","product_id":"PI_BCHUSD","side":"sell","seq":16259109,"price":1061.0,"qty":0.0,"timestamp":1618678115757}
1618678115.7918541: {"feed":"book","product_id":"FI_XRPUSD_210625","side":"sell","seq":3631632,"price":1.6974,"qty":0.0,"timestamp":1618678115764}
1618678115.791882: {"feed":"book","product_id":"FI_XRPUSD_210625","side":"sell","seq":3631633,"price":1.6972,"qty":50.0,"timestamp":1618678115764}
1618678115.7989419: {"feed":"book","product_id":"FI_XBTUSD_210625","side":"sell","seq":21455238,"price":64249.5,"qty":0.0,"timestamp":1618678115770}
1618678115.799071: {"feed":"book","product_id":"FI_XBTUSD_210625","side":"sell","seq":21455239,"price":64255.5,"qty":125003.0,"timestamp":1618678115770}
1618678115.822152: {"feed":"book","product_id":"FI_XRPUSD_210625","side":"sell","seq":3631634,"price":1.6973,"qty":0.0,"timestamp":1618678115776}
1618678115.8222022: {"feed":"book","product_id":"FI_XRPUSD_210625","side":"sell","seq":3631635,"price":1.6971,"qty":768.0,"timestamp":1618678115776}
1618678115.8222332: {"feed":"book","product_id":"FI_XBTUSD_210924","side":"sell","seq":13850962,"price":68515.0,"qty":47999.0,"timestamp":1618678115794}
1618678115.822258: {"feed":"book","product_id":"FI_XBTUSD_210924","side":"buy","seq":13850963,"price":67676.0,"qty":47999.0,"timestamp":1618678115794}
1618678115.8441558: {"feed":"book","product_id":"FI_XRPUSD_210625","side":"sell","seq":3631636,"price":1.6972,"qty":0.0,"timestamp":1618678115802}
1618678115.844245: {"feed":"book","product_id":"FI_XRPUSD_210625","side":"sell","seq":3631637,"price":1.697,"qty":50.0,"timestamp":1618678115802}
1618678115.8443232: {"feed":"book","product_id":"FI_XBTUSD_210625","side":"buy","seq":21455240,"price":63728.0,"qty":3266.0,"timestamp":1618678115807}
1618678115.844356: {"feed":"book","product_id":"FI_XBTUSD_210625","side":"buy","seq":21455241,"price":63773.5,"qty":250001.0,"timestamp":1618678115807}
1618678115.844385: {"feed":"book","product_id":"FI_XBTUSD_210924","side":"buy","seq":13850964,"price":68051.0,"qty":0.0,"timestamp":1618678115807}
1618678115.844415: {"feed":"book","product_id":"FI_XBTUSD_210924","side":"buy","seq":13850965,"price":68071.5,"qty":250001.0,"timestamp":1618678115807}
1618678115.8444622: {"feed":"book","product_id":"FI_XRPUSD_210625","side":"sell","seq":3631638,"price":1.6971,"qty":0.0,"timestamp":1618678115810}
1618678115.8444889: {"feed":"book","product_id":"FI_XRPUSD_210625","side":"sell","seq":3631639,"price":1.6969,"qty":768.0,"timestamp":1618678115810}
1618678115.8545349: {"feed":"book","product_id":"PI_BCHUSD","side":"sell","seq":16259110,"price":1061.1,"qty":50.0,"timestamp":1618678115823}
1618678115.856718: {"feed":"book","product_id":"PI_BCHUSD","side":"sell","seq":16259111,"price":1061.8,"qty":0.0,"timestamp":1618678115833}
1618678115.857334: {"feed":"book","product_id":"PI_BCHUSD","side":"sell","seq":16259112,"price":1062.8,"qty":11056.0,"timestamp":1618678115834}
1618678115.866281: {"feed":"book","product_id":"FI_ETHUSD_210625","side":"sell","seq":12455732,"price":2518.4,"qty":26620.0,"timestamp":1618678115843}
1618678115.866413: {"feed":"book","product_id":"FI_ETHUSD_210625","side":"sell","seq":12455733,"price":2529.2,"qty":26620.0,"timestamp":1618678115843}
1618678115.866467: {"feed":"book","product_id":"FI_ETHUSD_210625","side":"sell","seq":12455734,"price":2543.75,"qty":26620.0,"timestamp":1618678115843}
1618678115.8670878: {"feed":"book","product_id":"FI_ETHUSD_210625","side":"sell","seq":12455735,"price":2572.8,"qty":26620.0,"timestamp":1618678115843}
1618678115.8671842: {"feed":"book","product_id":"FI_ETHUSD_210625","side":"buy","seq":12455736,"price":2488.85,"qty":26620.0,"timestamp":1618678115843}
1618678115.872098: {"feed":"book","product_id":"FI_ETHUSD_210625","side":"buy","seq":12455737,"price":2477.25,"qty":27499.0,"timestamp":1618678115843}
1618678115.87221: {"feed":"book","product_id":"FI_ETHUSD_210625","side":"buy","seq":12455738,"price":2466.25,"qty":154870.0,"timestamp":1618678115843}
1618678115.8722591: {"feed":"book","product_id":"FI_ETHUSD_210625","side":"buy","seq":12455739,"price":2445.15,"qty":26620.0,"timestamp":1618678115843}
1618678115.872316: {"feed":"book","product_id":"FI_ETHUSD_210625","side":"buy","seq":12455740,"price":2412.25,"qty":26620.0,"timestamp":1618678115843}
1618678115.8723571: {"feed":"book","product_id":"FI_XBTUSD_210924","side":"sell","seq":13850966,"price":68281.0,"qty":0.0,"timestamp":1618678115848}
1618678115.883105: {"feed":"book","product_id":"FI_XBTUSD_210924","side":"sell","seq":13850967,"price":68280.5,"qty":0.0,"timestamp":1618678115858}
1618678115.883239: {"feed":"book","product_id":"FI_XBTUSD_210924","side":"sell","seq":13850968,"price":68281.0,"qty":10000.0,"timestamp":1618678115858}
1618678115.887126: {"feed":"book","product_id":"FI_XRPUSD_210625","side":"buy","seq":3631640,"price":1.691,"qty":16799.0,"timestamp":1618678115864}
1618678115.888366: {"feed":"book","product_id":"FI_XBTUSD_210430","side":"buy","seq":12237612,"price":59445.5,"qty":52610.0,"timestamp":1618678115864}
1618678115.91168: {"feed":"book","product_id":"FI_XBTUSD_210625","side":"sell","seq":21455242,"price":63956.0,"qty":10005.0,"timestamp":1618678115887}
1618678115.93251: {"feed":"book","product_id":"FI_XBTUSD_210924","side":"buy","seq":13850969,"price":68038.0,"qty":0.0,"timestamp":1618678115907}
1618678115.936657: {"feed":"book","product_id":"PI_BCHUSD","side":"buy","seq":16259113,"price":1058.0,"qty":3582.0,"timestamp":1618678115910}
1618678115.9418418: {"feed":"book","product_id":"FI_XBTUSD_210430","side":"sell","seq":12237613,"price":61235.5,"qty":0.0,"timestamp":1618678115915}
1618678115.941967: {"feed":"book","product_id":"FI_XBTUSD_210625","side":"sell","seq":21455243,"price":63937.0,"qty":3000.0,"timestamp":1618678115916}
1618678115.946323: {"feed":"book","product_id":"FI_XBTUSD_210625","side":"buy","seq":21455244,"price":57200.5,"qty":45028.0,"timestamp":1618678115919}
1618678115.9526331: {"feed":"book","product_id":"FI_XBTUSD_210625","side":"sell","seq":21455245,"price":63960.5,"qty":1000.0,"timestamp":1618678115929}
1618678115.964928: {"feed":"book","product_id":"PI_BCHUSD","side":"buy","seq":16259114,"price":1057.8,"qty":24939.0,"timestamp":1618678115940}
1618678115.983306: {"feed":"book","product_id":"FI_XRPUSD_210625","side":"sell","seq":3631641,"price":1.697,"qty":0.0,"timestamp":1618678115959}
1618678115.994619: {"feed":"book","product_id":"FI_XBTUSD_210625","side":"buy","seq":21455246,"price":57321.5,"qty":4215.0,"timestamp":1618678115971}
1618678115.995126: {"feed":"book","product_id":"PI_BCHUSD","side":"sell","seq":16259115,"price":1061.8,"qty":20443.0,"timestamp":1618678115973}
1618678116.0227158: {"feed":"book","product_id":"FI_XBTUSD_210625","side":"sell","seq":21455247,"price":64098.0,"qty":0.0,"timestamp":1618678115998}
1618678116.022848: {"feed":"book","product_id":"FI_XBTUSD_210625","side":"sell","seq":21455248,"price":64118.5,"qty":29842.0,"timestamp":1618678115998}
1618678116.022911: {"feed":"book","product_id":"FI_XBTUSD_210625","side":"buy","seq":21455249,"price":63826.5,"qty":0.0,"timestamp":1618678115999}
1618678116.022964: {"feed":"book","product_id":"FI_XBTUSD_210625","side":"buy","seq":21455250,"price":63879.0,"qty":1489.0,"timestamp":1618678115999}
1618678116.030453: {"feed":"book","product_id":"PI_BCHUSD","side":"sell","seq":16259116,"price":1061.1,"qty":2586.0,"timestamp":1618678116002}
1618678116.030564: {"feed":"book","product_id":"PI_BCHUSD","side":"sell","seq":16259117,"price":1061.1,"qty":4867.0,"timestamp":1618678116006}
1618678116.052712: {"feed":"book","product_id":"PI_BCHUSD","side":"sell","seq":16259118,"price":1061.1,"qty":2586.0,"timestamp":1618678116024}
1618678116.0528262: {"feed":"book","product_id":"PI_BCHUSD","side":"sell","seq":16259119,"price":1061.1,"qty":50.0,"timestamp":1618678116024}
1618678116.1154602: {"feed":"book","product_id":"FI_ETHUSD_210924","side":"sell","seq":3859215,"price":2662.05,"qty":38399.0,"timestamp":1618678116092}
1618678116.117552: {"feed":"book","product_id":"FI_ETHUSD_210625","side":"sell","seq":12455741,"price":2528.85,"qty":0.0,"timestamp":1618678116093}
1618678116.117682: {"feed":"book","product_id":"FI_ETHUSD_210625","side":"sell","seq":12455742,"price":2527.4,"qty":47825.0,"timestamp":1618678116093}
1618678116.1332211: {"feed":"book","product_id":"PI_BCHUSD","side":"sell","seq":16259120,"price":1062.4,"qty":8806.0,"timestamp":1618678116107}
1618678116.133329: {"feed":"book","product_id":"FI_ETHUSD_210625","side":"sell","seq":12455743,"price":2507.85,"qty":4561.0,"timestamp":1618678116109}
1618678116.204231: {"feed":"book","product_id":"FI_ETHUSD_210924","side":"buy","seq":3859216,"price":2641.65,"qty":2000.0,"timestamp":1618678116178}
1618678116.204319: {"feed":"book","product_id":"FI_ETHUSD_210924","side":"sell","seq":3859217,"price":2660.1,"qty":2000.0,"timestamp":1618678116178}
1618678116.213768: {"feed":"book","product_id":"FI_ETHUSD_210625","side":"sell","seq":12455744,"price":2503.4,"qty":3000.0,"timestamp":1618678116182}
1618678116.2138932: {"feed":"book","product_id":"FI_XBTUSD_210625","side":"sell","seq":21455251,"price":64001.0,"qty":0.0,"timestamp":1618678116182}
1618678116.213961: {"feed":"book","product_id":"FI_ETHUSD_210625","side":"sell","seq":12455745,"price":2507.05,"qty":36880.0,"timestamp":1618678116182}
1618678116.214009: {"feed":"book","product_id":"FI_ETHUSD_210625","side":"buy","seq":12455746,"price":2494.3,"qty":3000.0,"timestamp":1618678116182}
1618678116.214051: {"feed":"book","product_id":"FI_ETHUSD_210625","side":"sell","seq":12455747,"price":2510.7,"qty":36880.0,"timestamp":1618678116182}
1618678116.214117: {"feed":"book","product_id":"FI_ETHUSD_210625","side":"buy","seq":12455748,"price":2490.65,"qty":8893.0,"timestamp":1618678116182}
1618678116.214143: {"feed":"book","product_id":"FI_ETHUSD_210625","side":"sell","seq":12455749,"price":2514.35,"qty":36880.0,"timestamp":1618678116182}
1618678116.214166: {"feed":"book","product_id":"FI_XBTUSD_210924","side":"sell","seq":13850970,"price":68333.0,"qty":3000.0,"timestamp":1618678116187}
1618678116.2141929: {"feed":"book","product_id":"FI_XBTUSD_210924","side":"buy","seq":13850971,"price":68049.0,"qty":3000.0,"timestamp":1618678116187}
1618678116.2242198: {"feed":"book","product_id":"FI_ETHUSD_210924","side":"sell","seq":3859218,"price":2658.6,"qty":20039.0,"timestamp":1618678116196}
1618678116.22433: {"feed":"book","product_id":"FI_XRPUSD_210625","side":"buy","seq":3631642,"price":1.693,"qty":0.0,"timestamp":1618678116191}
1618678116.224424: {"feed":"book","product_id":"FI_XRPUSD_210625","side":"buy","seq":3631643,"price":1.6934,"qty":118.0,"timestamp":1618678116191}
1618678116.231699: {"feed":"book","product_id":"FI_XRPUSD_210625","side":"sell","seq":3631644,"price":1.6978,"qty":0.0,"timestamp":1618678116194}
1618678116.2318258: {"feed":"book","product_id":"FI_XRPUSD_210625","side":"sell","seq":3631645,"price":1.6986,"qty":18968.0,"timestamp":1618678116194}
1618678116.2318878: {"feed":"book","product_id":"FI_XRPUSD_210625","side":"buy","seq":3631646,"price":1.6909,"qty":0.0,"timestamp":1618678116194}
1618678116.231939: {"feed":"book","product_id":"FI_XRPUSD_210625","side":"buy","seq":3631647,"price":1.6917,"qty":19200.0,"timestamp":1618678116194}
1618678116.2642639: {"feed":"book","product_id":"FI_ETHUSD_210625","side":"sell","seq":12455750,"price":2514.5,"qty":0.0,"timestamp":1618678116236}
1618678116.264395: {"feed":"book","product_id":"FI_ETHUSD_210625","side":"sell","seq":12455751,"price":2514.3,"qty":25003.0,"timestamp":1618678116236}
1618678116.273752: {"feed":"book","product_id":"PI_BCHUSD","side":"sell","seq":16259121,"price":1062.1,"qty":40007.0,"timestamp":1618678116236}
1618678116.27386: {"feed":"book","product_id":"FI_XBTUSD_210430","side":"buy","seq":12237614,"price":61036.0,"qty":0.0,"timestamp":1618678116236}
1618678116.2739332: {"feed":"book","product_id":"FI_XBTUSD_210430","side":"buy","seq":12237615,"price":61055.0,"qty":250001.0,"timestamp":1618678116236}
1618678116.273983: {"feed":"book","product_id":"FI_ETHUSD_210924","side":"sell","seq":3859219,"price":2662.1,"qty":0.0,"timestamp":1618678116236}
1618678116.2740312: {"feed":"book","product_id":"FI_ETHUSD_210924","side":"sell","seq":3859220,"price":2662.0,"qty":225001.0,"timestamp":1618678116236}
1618678116.274071: {"feed":"book","product_id":"FI_XBTUSD_210924","side":"buy","seq":13850972,"price":67951.0,"qty":0.0,"timestamp":1618678116236}
1618678116.274121: {"feed":"book","product_id":"FI_XBTUSD_210924","side":"buy","seq":13850973,"price":67988.0,"qty":250002.0,"timestamp":1618678116236}
1618678116.274176: {"feed":"book","product_id":"FI_XBTUSD_210625","side":"sell","seq":21455252,"price":64041.5,"qty":0.0,"timestamp":1618678116236}
1618678116.2742028: {"feed":"book","product_id":"FI_XBTUSD_210625","side":"sell","seq":21455253,"price":64053.0,"qty":13897.0,"timestamp":1618678116236}
1618678116.274227: {"feed":"book","product_id":"FI_XBTUSD_210625","side":"buy","seq":21455254,"price":63773.5,"qty":0.0,"timestamp":1618678116236}
1618678116.2742531: {"feed":"book","product_id":"FI_XBTUSD_210625","side":"buy","seq":21455255,"price":63785.0,"qty":250001.0,"timestamp":1618678116236}
1618678116.2829728: {"feed":"book","product_id":"FI_XBTUSD_210430","side":"buy","seq":12237616,"price":59445.5,"qty":48172.0,"timestamp":1618678116243}
1618678116.311718: {"feed":"book","product_id":"FI_XBTUSD_210430","side":"buy","seq":12237617,"price":59445.5,"qty":48416.0,"timestamp":1618678116287}
1618678116.318134: {"feed":"book","product_id":"PI_BCHUSD","side":"sell","seq":16259122,"price":1062.0,"qty":39053.0,"timestamp":1618678116294}
1618678116.3235068: {"feed":"book","product_id":"FI_ETHUSD_210625","side":"sell","seq":12455752,"price":2503.8,"qty":0.0,"timestamp":1618678116300}
1618678116.323634: {"feed":"book","product_id":"FI_ETHUSD_210625","side":"sell","seq":12455753,"price":2505.45,"qty":23858.0,"timestamp":1618678116300}
1618678116.3312619: {"feed":"book","product_id":"PI_BCHUSD","side":"sell","seq":16259123,"price":1061.1,"qty":2485.0,"timestamp":1618678116301}
1618678116.334389: {"feed":"book","product_id":"FI_XBTUSD_210430","side":"buy","seq":12237618,"price":60662.5,"qty":500.0,"timestamp":1618678116308}
1618678116.334513: {"feed":"book","product_id":"FI_XBTUSD_210430","side":"sell","seq":12237619,"price":61941.0,"qty":500.0,"timestamp":1618678116308}
1618678116.359191: {"feed":"book","product_id":"FI_XBTUSD_210625","side":"buy","seq":21455256,"price":57321.5,"qty":2497.0,"timestamp":1618678116334}
1618678116.359301: {"feed":"book","product_id":"FI_XBTUSD_210625","side":"buy","seq":21455257,"price":57321.5,"qty":0.0,"timestamp":1618678116334}
1618678116.3660202: {"feed":"book","product_id":"PI_BCHUSD","side":"sell","seq":16259124,"price":1062.1,"qty":43612.0,"timestamp":1618678116340}
1618678116.366129: {"feed":"book","product_id":"FI_XBTUSD_210625","side":"buy","seq":21455258,"price":57200.5,"qty":49507.0,"timestamp":1618678116340}
1618678116.399164: {"feed":"book","product_id":"PI_BCHUSD","side":"buy","seq":16259125,"price":1058.6,"qty":33253.0,"timestamp":1618678116374}
1618678116.402726: {"feed":"book","product_id":"FI_XBTUSD_210924","side":"sell","seq":13850974,"price":68507.5,"qty":0.0,"timestamp":1618678116378}
1618678116.402853: {"feed":"book","product_id":"FI_XBTUSD_210924","side":"sell","seq":13850975,"price":68474.0,"qty":355466.0,"timestamp":1618678116378}
1618678116.4029179: {"feed":"book","product_id":"FI_XBTUSD_210625","side":"sell","seq":21455259,"price":64187.0,"qty":0.0,"timestamp":1618678116378}
1618678116.40297: {"feed":"book","product_id":"FI_XBTUSD_210625","side":"sell","seq":21455260,"price":64170.0,"qty":504470.0,"timestamp":1618678116378}
1618678116.4058151: {"feed":"book","product_id":"FI_XBTUSD_210430","side":"buy","seq":12237620,"price":60271.5,"qty":0.0,"timestamp":1618678116382}
1618678116.407021: {"feed":"book","product_id":"PI_BCHUSD","side":"buy","seq":16259126,"price":1058.6,"qty":33167.0,"timestamp":1618678116384}
1618678116.417993: {"feed":"book","product_id":"PI_BCHUSD","side":"buy","seq":16259127,"price":1058.6,"qty":33253.0,"timestamp":1618678116394}
1618678116.4186702: {"feed":"book","product_id":"FI_XBTUSD_210924","side":"buy","seq":13850976,"price":52552.5,"qty":58638.0,"timestamp":1618678116394}
1618678116.418756: {"feed":"book","product_id":"PI_BCHUSD","side":"sell","seq":16259128,"price":1062.5,"qty":0.0,"timestamp":1618678116394}
1618678116.4188259: {"feed":"book","product_id":"PI_BCHUSD","side":"sell","seq":16259129,"price":1062.4,"qty":19431.0,"timestamp":1618678116394}
1618678116.418868: {"feed":"book","product_id":"PI_BCHUSD","side":"buy","seq":16259130,"price":1057.8,"qty":3788.0,"timestamp":1618678116395}
1618678116.421742: {"feed":"book","product_id":"PI_BCHUSD","side":"buy","seq":16259131,"price":1056.9,"qty":3780.0,"timestamp":1618678116397}
1618678116.4218502: {"feed":"book","product_id":"PI_BCHUSD","side":"buy","seq":16259132,"price":1057.7,"qty":5015.0,"timestamp":1618678116397}
1618678116.421898: {"feed":"book","product_id":"PI_BCHUSD","side":"sell","seq":16259133,"price":1062.1,"qty":30069.0,"timestamp":1618678116397}
1618678116.421938: {"feed":"book","product_id":"PI_BCHUSD","side":"buy","seq":16259134,"price":1055.0,"qty":39826.0,"timestamp":1618678116397}
1618678116.431871: {"feed":"book","product_id":"PI_BCHUSD","side":"buy","seq":16259135,"price":1058.0,"qty":0.0,"timestamp":1618678116403}
1618678116.431998: {"feed":"book","product_id":"PI_BCHUSD","side":"buy","seq":16259136,"price":1057.4,"qty":0.0,"timestamp":1618678116404}
1618678116.432055: {"feed":"book","product_id":"PI_BCHUSD","side":"buy","seq":16259137,"price":1055.7,"qty":3563.0,"timestamp":1618678116405}
1618678116.450998: {"feed":"book","product_id":"PI_BCHUSD","side":"sell","seq":16259138,"price":1061.1,"qty":50.0,"timestamp":1618678116428}
1618678116.460006: {"feed":"book","product_id":"FI_XBTUSD_210924","side":"buy","seq":13850977,"price":52552.5,"qty":58776.0,"timestamp":1618678116437}
1618678116.465506: {"feed":"book","product_id":"PI_BCHUSD","side":"buy","seq":16259139,"price":1058.6,"qty":33167.0,"timestamp":1618678116442}
1618678116.473402: {"feed":"book","product_id":"FI_XBTUSD_210625","side":"buy","seq":21455261,"price":62982.0,"qty":0.0,"timestamp":1618678116449}
1618678116.4735308: {"feed":"book","product_id":"FI_XBTUSD_210625","side":"buy","seq":21455262,"price":62958.0,"qty":10000.0,"timestamp":1618678116449}
1618678116.473928: {"feed":"book","product_id":"FI_XBTUSD_210625","side":"sell","seq":21455263,"price":64001.0,"qty":10000.0,"timestamp":1618678116451}
1618678116.4986482: {"feed":"book","product_id":"FI_ETHUSD_210430","side":"sell","seq":4780918,"price":2414.65,"qty":0.0,"timestamp":1618678116474}
1618678116.502031: {"feed":"book","product_id":"FI_BCHUSD_210625","side":"sell","seq":2240258,"price":1138.8,"qty":0.0,"timestamp":1618678116477}
1618678116.5021582: {"feed":"book","product_id":"FI_BCHUSD_210625","side":"sell","seq":2240259,"price":1142.9,"qty":4513.0,"timestamp":1618678116477}
1618678116.502221: {"feed":"book","product_id":"PI_BCHUSD","side":"buy","seq":16259140,"price":1057.0,"qty":9892.0,"timestamp":1618678116477}
1618678116.502265: {"feed":"book","product_id":"PI_BCHUSD","side":"buy","seq":16259141,"price":1054.9,"qty":4937.0,"timestamp":1618678116477}
1618678116.5023081: {"feed":"book","product_id":"PI_BCHUSD","side":"sell","seq":16259142,"price":1062.4,"qty":8806.0,"timestamp":1618678116478}
1618678116.502344: {"feed":"book","product_id":"PI_BCHUSD","side":"sell","seq":16259143,"price":1062.3,"qty":15640.0,"timestamp":1618678116478}
1618678116.5136: {"feed":"book","product_id":"PI_BCHUSD","side":"buy","seq":16259144,"price":1057.9,"qty":7194.0,"timestamp":1618678116490}
1618678116.5140421: {"feed":"book","product_id":"PI_BCHUSD","side":"sell","seq":16259145,"price":1062.0,"qty":35634.0,"timestamp":1618678116491}
1618678116.515409: {"feed":"book","product_id":"PI_BCHUSD","side":"buy","seq":16259146,"price":1057.5,"qty":7163.0,"timestamp":1618678116493}
1618678116.524107: {"feed":"book","product_id":"PI_BCHUSD","side":"buy","seq":16259147,"price":1057.5,"qty":3327.0,"timestamp":1618678116499}
1618678116.5242162: {"feed":"book","product_id":"PI_BCHUSD","side":"buy","seq":16259148,"price":1057.9,"qty":3639.0,"timestamp":1618678116499}
1618678116.5242639: {"feed":"book","product_id":"PI_BCHUSD","side":"buy","seq":16259149,"price":1057.4,"qty":3650.0,"timestamp":1618678116500}
1618678116.531895: {"feed":"book","product_id":"FI_XBTUSD_210625","side":"sell","seq":21455264,"price":64255.5,"qty":0.0,"timestamp":1618678116505}
1618678116.532023: {"feed":"book","product_id":"FI_XBTUSD_210625","side":"sell","seq":21455265,"price":64249.5,"qty":125003.0,"timestamp":1618678116505}
1618678116.532087: {"feed":"book","product_id":"FI_ETHUSD_210924","side":"sell","seq":3859221,"price":2662.0,"qty":0.0,"timestamp":1618678116505}
1618678116.532139: {"feed":"book","product_id":"FI_ETHUSD_210924","side":"sell","seq":3859222,"price":2662.1,"qty":225001.0,"timestamp":1618678116505}
1618678116.542311: {"feed":"book","product_id":"FI_ETHUSD_210625","side":"sell","seq":12455754,"price":2505.45,"qty":12246.0,"timestamp":1618678116513}
1618678116.54242: {"feed":"book","product_id":"FI_ETHUSD_210625","side":"sell","seq":12455755,"price":2503.8,"qty":7194.0,"timestamp":1618678116513}
1618678116.542464: {"feed":"book","product_id":"FI_XBTUSD_210625","side":"sell","seq":21455266,"price":64901.0,"qty":0.0,"timestamp":1618678116513}
1618678116.5425012: {"feed":"book","product_id":"FI_XBTUSD_210625","side":"sell","seq":21455267,"price":64875.0,"qty":10000.0,"timestamp":1618678116513}
1618678116.542527: {"feed":"book","product_id":"FI_ETHUSD_210625","side":"sell","seq":12455756,"price":2507.95,"qty":0.0,"timestamp":1618678116513}
1618678116.5425541: {"feed":"book","product_id":"FI_ETHUSD_210625","side":"sell","seq":12455757,"price":2507.0,"qty":16519.0,"timestamp":1618678116513}
1618678116.565224: {"feed":"book","product_id":"FI_ETHUSD_210625","side":"sell","seq":12455758,"price":2507.9,"qty":0.0,"timestamp":1618678116540}
1618678116.565314: {"feed":"book","product_id":"FI_ETHUSD_210625","side":"sell","seq":12455759,"price":2508.7,"qty":225001.0,"timestamp":1618678116540}
1618678116.6305642: {"feed":"book","product_id":"PI_BCHUSD","side":"buy","seq":16259150,"price":1056.9,"qty":7364.0,"timestamp":1618678116605}
1618678116.63985: {"feed":"book","product_id":"FI_XBTUSD_210430","side":"buy","seq":12237621,"price":59445.5,"qty":48172.0,"timestamp":1618678116612}
1618678116.652069: {"feed":"book","product_id":"FI_XBTUSD_210924","side":"sell","seq":13850978,"price":68298.0,"qty":5000.0,"timestamp":1618678116628}
1618678116.685076: {"feed":"book","product_id":"FI_XBTUSD_210430","side":"buy","seq":12237622,"price":59445.5,"qty":52651.0,"timestamp":1618678116661}
1618678116.700612: {"feed":"book","product_id":"PI_BCHUSD","side":"sell","seq":16259151,"price":1060.9,"qty":2839.0,"timestamp":1618678116674}
1618678116.717209: {"feed":"book","product_id":"PI_BCHUSD","side":"sell","seq":16259152,"price":1060.9,"qty":0.0,"timestamp":1618678116691}
1618678116.746252: {"feed":"book","product_id":"FI_XBTUSD_210625","side":"buy","seq":21455268,"price":57321.5,"qty":729.0,"timestamp":1618678116712}
1618678116.746379: {"feed":"book","product_id":"PI_BCHUSD","side":"sell","seq":16259153,"price":1062.0,"qty":39171.0,"timestamp":1618678116713}
1618678116.768915: {"feed":"book","product_id":"PI_BCHUSD","side":"buy","seq":16259154,"price":1057.5,"qty":17692.0,"timestamp":1618678116743}
1618678116.7822988: {"feed":"book","product_id":"PI_BCHUSD","side":"sell","seq":16259155,"price":1062.0,"qty":35634.0,"timestamp":1618678116757}
1618678116.7824068: {"feed":"book","product_id":"PI_BCHUSD","side":"sell","seq":16259156,"price":1062.1,"qty":26464.0,"timestamp":1618678116759}
1618678116.7824562: {"feed":"book","product_id":"PI_BCHUSD","side":"sell","seq":16259157,"price":1062.1,"qty":31455.0,"timestamp":1618678116759}
1618678116.782494: {"feed":"book","product_id":"PI_BCHUSD","side":"sell","seq":16259158,"price":1061.3,"qty":4995.0,"timestamp":1618678116759}
1618678116.7825449: {"feed":"book","product_id":"PI_BCHUSD","side":"sell","seq":16259159,"price":1061.7,"qty":6144.0,"timestamp":1618678116759}
1618678116.783015: {"feed":"book","product_id":"FI_ETHUSD_210430","side":"buy","seq":4780919,"price":2350.1,"qty":99600.0,"timestamp":1618678116759}
1618678116.783066: {"feed":"book","product_id":"PI_BCHUSD","side":"sell","seq":16259160,"price":1062.4,"qty":3813.0,"timestamp":1618678116759}
1618678116.783092: {"feed":"book","product_id":"PI_BCHUSD","side":"sell","seq":16259161,"price":1062.0,"qty":30641.0,"timestamp":1618678116759}
1618678116.783114: {"feed":"book","product_id":"PI_BCHUSD","side":"sell","seq":16259162,"price":1062.8,"qty":6065.0,"timestamp":1618678116759}
1618678116.783134: {"feed":"book","product_id":"PI_BCHUSD","side":"sell","seq":16259163,"price":1062.3,"qty":5015.0,"timestamp":1618678116760}
1618678116.783154: {"feed":"book","product_id":"PI_BCHUSD","side":"sell","seq":16259164,"price":1062.1,"qty":42080.0,"timestamp":1618678116760}
1618678116.791401: {"feed":"book","product_id":"PI_BCHUSD","side":"buy","seq":16259165,"price":1058.5,"qty":0.0,"timestamp":1618678116768}
1618678116.7915251: {"feed":"book","product_id":"FI_XBTUSD_210924","side":"buy","seq":13850979,"price":52552.5,"qty":58638.0,"timestamp":1618678116768}
1618678116.808595: {"feed":"book","product_id":"FI_ETHUSD_210625","side":"sell","seq":12455760,"price":2518.4,"qty":0.0,"timestamp":1618678116783}
1618678116.8087199: {"feed":"book","product_id":"FI_ETHUSD_210625","side":"sell","seq":12455761,"price":2529.2,"qty":0.0,"timestamp":1618678116783}
1618678116.808778: {"feed":"book","product_id":"FI_ETHUSD_210625","side":"sell","seq":12455762,"price":2543.75,"qty":0.0,"timestamp":1618678116783}
1618678116.8088262: {"feed":"book","product_id":"FI_ETHUSD_210625","side":"sell","seq":12455763,"price":2572.8,"qty":0.0,"timestamp":1618678116783}
1618678116.808867: {"feed":"book","product_id":"FI_ETHUSD_210625","side":"buy","seq":12455764,"price":2488.85,"qty":0.0,"timestamp":1618678116783}
1618678116.8089101: {"feed":"book","product_id":"FI_ETHUSD_210625","side":"buy","seq":12455765,"price":2477.25,"qty":879.0,"timestamp":1618678116783}
1618678116.811583: {"feed":"book","product_id":"FI_ETHUSD_210625","side":"buy","seq":12455766,"price":2466.25,"qty":128250.0,"timestamp":1618678116783}
1618678116.811637: {"feed":"book","product_id":"FI_ETHUSD_210625","side":"buy","seq":12455767,"price":2445.15,"qty":0.0,"timestamp":1618678116783}
1618678116.811678: {"feed":"book","product_id":"FI_ETHUSD_210625","side":"buy","seq":12455768,"price":2412.25,"qty":0.0,"timestamp":1618678116783}
1618678116.811709: {"feed":"book","product_id":"FI_BCHUSD_210430","side":"sell","seq":1411907,"price":1083.0,"qty":0.0,"timestamp":1618678116786}
1618678116.8399098: {"feed":"book","product_id":"FI_XBTUSD_210924","side":"buy","seq":13850980,"price":52552.5,"qty":58854.0,"timestamp":1618678116811}
1618678116.8612921: {"feed":"book","product_id":"PI_BCHUSD","side":"sell","seq":16259166,"price":1061.2,"qty":86.0,"timestamp":1618678116837}
1618678116.86444: {"feed":"book","product_id":"FI_XRPUSD_210625","side":"sell","seq":3631648,"price":1.6971,"qty":299.0,"timestamp":1618678116842}
1618678116.867906: {"feed":"book","product_id":"FI_BCHUSD_210625","side":"buy","seq":2240260,"price":1127.4,"qty":82.0,"timestamp":1618678116845}
1618678116.8761868: {"feed":"book","product_id":"PI_BCHUSD","side":"sell","seq":16259167,"price":1062.8,"qty":0.0,"timestamp":1618678116852}
1618678116.8763158: {"feed":"book","product_id":"FI_XBTUSD_210924","side":"sell","seq":13850981,"price":68292.5,"qty":23999.0,"timestamp":1618678116852}
1618678116.8785028: {"feed":"book","product_id":"FI_ETHUSD_210625","side":"sell","seq":12455769,"price":2508.7,"qty":0.0,"timestamp":1618678116854}
1618678116.878635: {"feed":"book","product_id":"FI_ETHUSD_210625","side":"sell","seq":12455770,"price":2508.45,"qty":225001.0,"timestamp":1618678116854}
1618678116.880715: {"feed":"book","product_id":"FI_ETHUSD_210625","side":"sell","seq":12455771,"price":2514.3,"qty":0.0,"timestamp":1618678116854}
1618678116.880845: {"feed":"book","product_id":"FI_ETHUSD_210625","side":"sell","seq":12455772,"price":2514.5,"qty":25003.0,"timestamp":1618678116854}
1618678116.889028: {"feed":"book","product_id":"FI_XRPUSD_210625","side":"buy","seq":3631649,"price":1.691,"qty":0.0,"timestamp":1618678116864}
1618678116.9366882: {"feed":"book","product_id":"PI_BCHUSD","side":"buy","seq":16259168,"price":1057.8,"qty":7068.0,"timestamp":1618678116908}
1618678116.942883: {"feed":"book","product_id":"PI_BCHUSD","side":"sell","seq":16259169,"price":1063.0,"qty":6065.0,"timestamp":1618678116916}
1618678116.966043: {"feed":"book","product_id":"PI_BCHUSD","side":"sell","seq":16259170,"price":1062.4,"qty":0.0,"timestamp":1618678116939}
1618678116.96617: {"feed":"book","product_id":"PI_BCHUSD","side":"buy","seq":16259171,"price":1057.4,"qty":0.0,"timestamp":1618678116940}
1618678116.96623: {"feed":"book","product_id":"PI_BCHUSD","side":"buy","seq":16259172,"price":1057.5,"qty":37468.0,"timestamp":1618678116940}
1618678116.9672918: {"feed":"book","product_id":"PI_BCHUSD","side":"buy","seq":16259173,"price":1057.5,"qty":34141.0,"timestamp":1618678116943}
1618678116.9823449: {"feed":"book","product_id":"PI_BCHUSD","side":"buy","seq":16259174,"price":1057.5,"qty":19776.0,"timestamp":1618678116957}
1618678116.982456: {"feed":"book","product_id":"PI_BCHUSD","side":"buy","seq":16259175,"price":1057.9,"qty":0.0,"timestamp":1618678116957}
1618678116.9825249: {"feed":"book","product_id":"PI_BCHUSD","side":"buy","seq":16259176,"price":1057.8,"qty":3788.0,"timestamp":1618678116957}
1618678116.9825659: {"feed":"book","product_id":"PI_BCHUSD","side":"buy","seq":16259177,"price":1058.3,"qty":3585.0,"timestamp":1618678116958}
1618678116.986866: {"feed":"book","product_id":"PI_BCHUSD","side":"sell","seq":16259178,"price":1061.2,"qty":0.0,"timestamp":1618678116963}
1618678116.989215: {"feed":"book","product_id":"PI_BCHUSD","side":"sell","seq":16259179,"price":1061.1,"qty":2876.0,"timestamp":1618678116965}
1618678117.0197601: {"feed":"book","product_id":"FI_XBTUSD_210430","side":"buy","seq":12237623,"price":59445.5,"qty":48172.0,"timestamp":1618678116996}
1618678117.031436: {"feed":"book","product_id":"PI_BCHUSD","side":"sell","seq":16259180,"price":1061.1,"qty":5630.0,"timestamp":1618678117003}
1618678117.031543: {"feed":"book","product_id":"PI_BCHUSD","side":"sell","seq":16259181,"price":1061.1,"qty":8165.0,"timestamp":1618678117005}
1618678117.046412: {"feed":"book","product_id":"FI_XBTUSD_210924","side":"sell","seq":13850982,"price":68360.0,"qty":0.0,"timestamp":1618678117019}
1618678117.0465379: {"feed":"book","product_id":"FI_XBTUSD_210924","side":"sell","seq":13850983,"price":68277.5,"qty":2536.0,"timestamp":1618678117019}
1618678117.046602: {"feed":"book","product_id":"PI_BCHUSD","side":"sell","seq":16259182,"price":1061.1,"qty":5339.0,"timestamp":1618678117023}
1618678117.0507278: {"feed":"book","product_id":"PI_BCHUSD","side":"sell","seq":16259183,"price":1061.1,"qty":2585.0,"timestamp":1618678117023}
1618678117.050837: {"feed":"book","product_id":"FI_XBTUSD_210924","side":"sell","seq":13850984,"price":68281.0,"qty":0.0,"timestamp":1618678117023}
1618678117.05091: {"feed":"book","product_id":"FI_XBTUSD_210924","side":"sell","seq":13850985,"price":68277.0,"qty":10000.0,"timestamp":1618678117023}
1618678117.050962: {"feed":"book","product_id":"PI_BCHUSD","side":"buy","seq":16259184,"price":1057.5,"qty":0.0,"timestamp":1618678117023}
1618678117.051011: {"feed":"book","product_id":"PI_BCHUSD","side":"sell","seq":16259185,"price":1061.1,"qty":50.0,"timestamp":1618678117023}
1618678117.060509: {"feed":"book","product_id":"FI_ETHUSD_210430","side":"sell","seq":4780920,"price":2389.4,"qty":2605.0,"timestamp":1618678117035}
1618678117.06062: {"feed":"book","product_id":"FI_ETHUSD_210430","side":"sell","seq":4780921,"price":2393.9,"qty":0.0,"timestamp":1618678117035}
1618678117.062618: {"feed":"book","product_id":"FI_XBTUSD_210430","side":"buy","seq":12237624,"price":59445.5,"qty":48416.0,"timestamp":1618678117039}
1618678117.0659058: {"feed":"book","product_id":"FI_ETHUSD_210625","side":"sell","seq":12455773,"price":2502.4,"qty":2504.0,"timestamp":1618678117041}
1618678117.066017: {"feed":"book","product_id":"FI_ETHUSD_210625","side":"sell","seq":12455774,"price":2506.95,"qty":0.0,"timestamp":1618678117041}
1618678117.120266: {"feed":"book","product_id":"FI_XBTUSD_210625","side":"buy","seq":21455269,"price":57200.5,"qty":46553.0,"timestamp":1618678117093}
1618678117.121931: {"feed":"book","product_id":"FI_ETHUSD_210924","side":"sell","seq":3859223,"price":2658.6,"qty":20401.0,"timestamp":1618678117096}
1618678117.122041: {"feed":"book","product_id":"FI_XBTUSD_210625","side":"buy","seq":21455270,"price":57200.5,"qty":43056.0,"timestamp":1618678117093}
1618678117.122092: {"feed":"book","product_id":"FI_XBTUSD_210625","side":"buy","seq":21455271,"price":57200.5,"qty":38577.0,"timestamp":1618678117093}
1618678117.1221309: {"feed":"book","product_id":"FI_XBTUSD_210625","side":"buy","seq":21455272,"price":57200.5,"qty":29165.0,"timestamp":1618678117093}
1618678117.122165: {"feed":"book","product_id":"FI_XBTUSD_210625","side":"sell","seq":21455273,"price":63940.5,"qty":6672.0,"timestamp":1618678117098}
1618678117.1233332: {"feed":"book","product_id":"PI_BCHUSD","side":"sell","seq":16259186,"price":1061.3,"qty":0.0,"timestamp":1618678117099}
1618678117.129208: {"feed":"book","product_id":"PI_BCHUSD","side":"sell","seq":16259187,"price":1062.1,"qty":31455.0,"timestamp":1618678117101}
1618678117.1426592: {"feed":"book","product_id":"FI_XBTUSD_210625","side":"buy","seq":21455274,"price":63879.0,"qty":0.0,"timestamp":1618678117112}
1618678117.1427882: {"feed":"book","product_id":"FI_XBTUSD_210625","side":"buy","seq":21455275,"price":63881.0,"qty":1508.0,"timestamp":1618678117112}
1618678117.142852: {"feed":"book","product_id":"FI_XBTUSD_210625","side":"sell","seq":21455276,"price":64081.5,"qty":250001.0,"timestamp":1618678117112}
1618678117.142936: {"feed":"book","product_id":"FI_XBTUSD_210625","side":"sell","seq":21455277,"price":64081.0,"qty":19081.0,"timestamp":1618678117112}
1618678117.142965: {"feed":"book","product_id":"FI_XBTUSD_210625","side":"sell","seq":21455278,"price":64250.0,"qty":0.0,"timestamp":1618678117112}
1618678117.142994: {"feed":"book","product_id":"FI_XBTUSD_210625","side":"sell","seq":21455279,"price":64249.0,"qty":56743.0,"timestamp":1618678117112}
1618678117.143019: {"feed":"book","product_id":"FI_XBTUSD_210625","side":"sell","seq":21455280,"price":64118.5,"qty":0.0,"timestamp":1618678117112}
1618678117.143044: {"feed":"book","product_id":"FI_XBTUSD_210625","side":"sell","seq":21455281,"price":64118.5,"qty":28458.0,"timestamp":1618678117112}
1618678117.1430678: {"feed":"book","product_id":"FI_XBTUSD_210625","side":"buy","seq":21455282,"price":63896.0,"qty":1320.0,"timestamp":1618678117112}
1618678117.1430888: {"feed":"book","product_id":"FI_XBTUSD_210625","side":"buy","seq":21455283,"price":63896.0,"qty":2612.0,"timestamp":1618678117112}
1618678117.1517298: {"feed":"book","product_id":"FI_XBTUSD_210625","side":"buy","seq":21455284,"price":63896.0,"qty":1292.0,"timestamp":1618678117112}
1618678117.151807: {"feed":"book","product_id":"FI_XBTUSD_210625","side":"buy","seq":21455285,"price":63896.0,"qty":2584.0,"timestamp":1618678117112}
1618678117.151839: {"feed":"book","product_id":"FI_XBTUSD_210625","side":"buy","seq":21455286,"price":63489.0,"qty":0.0,"timestamp":1618678117112}
1618678117.1518788: {"feed":"book","product_id":"FI_XBTUSD_210625","side":"buy","seq":21455287,"price":63489.0,"qty":4327.0,"timestamp":1618678117112}
1618678117.1519098: {"feed":"book","product_id":"PI_BCHUSD","side":"sell","seq":16259188,"price":1061.8,"qty":24072.0,"timestamp":1618678117112}
1618678117.151934: {"feed":"book","product_id":"FI_XBTUSD_210625","side":"buy","seq":21455288,"price":63728.0,"qty":0.0,"timestamp":1618678117112}
1618678117.151968: {"feed":"book","product_id":"FI_XBTUSD_210625","side":"buy","seq":21455289,"price":63728.0,"qty":3300.0,"timestamp":1618678117112}
1618678117.1519942: {"feed":"book","product_id":"FI_ETHUSD_210625","side":"buy","seq":12455775,"price":2492.15,"qty":0.0,"timestamp":1618678117112}
1618678117.152023: {"feed":"book","product_id":"FI_ETHUSD_210625","side":"buy","seq":12455776,"price":2492.45,"qty":637.0,"timestamp":1618678117112}
1618678117.152048: {"feed":"book","product_id":"FI_XBTUSD_210625","side":"sell","seq":21455290,"price":64053.0,"qty":0.0,"timestamp":1618678117112}
1618678117.152075: {"feed":"book","product_id":"FI_XBTUSD_210625","side":"sell","seq":21455291,"price":64053.0,"qty":13765.0,"timestamp":1618678117112}
1618678117.152098: {"feed":"book","product_id":"FI_XBTUSD_210625","side":"sell","seq":21455292,"price":64529.5,"qty":0.0,"timestamp":1618678117112}
1618678117.152123: {"feed":"book","product_id":"FI_XBTUSD_210625","side":"sell","seq":21455293,"price":64529.5,"qty":76454.0,"timestamp":1618678117112}
1618678117.1521459: {"feed":"book","product_id":"FI_ETHUSD_210625","side":"buy","seq":12455777,"price":2499.35,"qty":239.0,"timestamp":1618678117112}
1618678117.1521668: {"feed":"book","product_id":"FI_ETHUSD_210625","side":"buy","seq":12455778,"price":2499.35,"qty":487.0,"timestamp":1618678117112}
1618678117.1521869: {"feed":"book","product_id":"FI_ETHUSD_210625","side":"buy","seq":12455779,"price":2499.35,"qty":248.0,"timestamp":1618678117112}
1618678117.1522062: {"feed":"book","product_id":"FI_ETHUSD_210625","side":"buy","seq":12455780,"price":2499.35,"qty":496.0,"timestamp":1618678117112}
1618678117.152226: {"feed":"book","product_id":"FI_ETHUSD_210625","side":"buy","seq":12455781,"price":2477.25,"qty":0.0,"timestamp":1618678117112}
1618678117.1522508: {"feed":"book","product_id":"FI_ETHUSD_210625","side":"buy","seq":12455782,"price":2477.25,"qty":912.0,"timestamp":1618678117112}
1618678117.152274: {"feed":"book","product_id":"FI_ETHUSD_210625","side":"sell","seq":12455783,"price":2505.45,"qty":0.0,"timestamp":1618678117112}
1618678117.152301: {"feed":"book","product_id":"FI_ETHUSD_210625","side":"sell","seq":12455784,"price":2505.45,"qty":12227.0,"timestamp":1618678117112}
1618678117.1523252: {"feed":"book","product_id":"FI_ETHUSD_210625","side":"sell","seq":12455785,"price":2503.8,"qty":0.0,"timestamp":1618678117112}
1618678117.15235: {"feed":"book","product_id":"FI_ETHUSD_210625","side":"sell","seq":12455786,"price":2503.8,"qty":7203.0,"timestamp":1618678117112}
1618678117.152373: {"feed":"book","product_id":"FI_ETHUSD_210625","side":"sell","seq":12455787,"price":2507.0,"qty":0.0,"timestamp":1618678117112}
1618678117.1523972: {"feed":"book","product_id":"FI_ETHUSD_210625","side":"sell","seq":12455788,"price":2507.0,"qty":16528.0,"timestamp":1618678117112}
1618678117.15242: {"feed":"book","product_id":"FI_ETHUSD_210625","side":"sell","seq":12455789,"price":2513.2,"qty":0.0,"timestamp":1618678117112}
1618678117.152443: {"feed":"book","product_id":"FI_ETHUSD_210625","side":"sell","seq":12455790,"price":2513.2,"qty":34316.0,"timestamp":1618678117112}
1618678117.1524658: {"feed":"book","product_id":"PI_BCHUSD","side":"sell","seq":16259189,"price":1062.6,"qty":25025.0,"timestamp":1618678117123}
1618678117.161526: {"feed":"book","product_id":"FI_XBTUSD_210625","side":"buy","seq":21455294,"price":57321.5,"qty":15161.0,"timestamp":1618678117136}
1618678117.175224: {"feed":"book","product_id":"FI_BCHUSD_210430","side":"sell","seq":1411908,"price":1081.3,"qty":0.0,"timestamp":1618678117151}
1618678117.17535: {"feed":"book","product_id":"FI_BCHUSD_210430","side":"sell","seq":1411909,"price":1083.6,"qty":4590.0,"timestamp":1618678117151}
1618678117.1849751: {"feed":"book","product_id":"PI_BCHUSD","side":"buy","seq":16259190,"price":1057.3,"qty":5014.0,"timestamp":1618678117160}
1618678117.20953: {"feed":"book","product_id":"FI_XBTUSD_210924","side":"buy","seq":13850986,"price":52552.5,"qty":58638.0,"timestamp":1618678117185}
1618678117.2096388: {"feed":"book","product_id":"FI_XBTUSD_210430","side":"buy","seq":12237625,"price":60255.5,"qty":298741.0,"timestamp":1618678117185}
1618678117.21791: {"feed":"book","product_id":"PI_BCHUSD","side":"sell","seq":16259191,"price":1062.8,"qty":3626.0,"timestamp":1618678117193}
1618678117.218037: {"feed":"book","product_id":"PI_BCHUSD","side":"sell","seq":16259192,"price":1064.7,"qty":3949.0,"timestamp":1618678117194}
1618678117.218088: {"feed":"book","product_id":"PI_BCHUSD","side":"sell","seq":16259193,"price":1061.6,"qty":0.0,"timestamp":1618678117194}
1618678117.222671: {"feed":"book","product_id":"PI_BCHUSD","side":"sell","seq":16259194,"price":1064.1,"qty":0.0,"timestamp":1618678117194}
1618678117.222798: {"feed":"book","product_id":"PI_BCHUSD","side":"sell","seq":16259195,"price":1061.2,"qty":3525.0,"timestamp":1618678117195}
1618678117.222859: {"feed":"book","product_id":"PI_BCHUSD","side":"sell","seq":16259196,"price":1063.2,"qty":7683.0,"timestamp":1618678117195}
1618678117.222899: {"feed":"book","product_id":"FI_ETHUSD_210625","side":"buy","seq":12455791,"price":2496.05,"qty":2000.0,"timestamp":1618678117197}
1618678117.2838368: {"feed":"book","product_id":"PI_BCHUSD","side":"sell","seq":16259197,"price":1061.5,"qty":14659.0,"timestamp":1618678117258}
1618678117.2873092: {"feed":"book","product_id":"FI_BCHUSD_210430","side":"buy","seq":1411910,"price":1074.9,"qty":0.0,"timestamp":1618678117258}
1618678117.289681: {"feed":"book","product_id":"FI_ETHUSD_210924","side":"buy","seq":3859224,"price":2640.85,"qty":2000.0,"timestamp":1618678117262}
1618678117.289786: {"feed":"book","product_id":"PI_BCHUSD","side":"sell","seq":16259198,"price":1061.4,"qty":21745.0,"timestamp":1618678117262}
1618678117.2898371: {"feed":"book","product_id":"FI_XBTUSD_210924","side":"buy","seq":13850987,"price":52552.5,"qty":58776.0,"timestamp":1618678117262}
1618678117.289879: {"feed":"book","product_id":"PI_BCHUSD","side":"sell","seq":16259199,"price":1061.8,"qty":3629.0,"timestamp":1618678117262}
1618678117.2899132: {"feed":"book","product_id":"PI_BCHUSD","side":"sell","seq":16259200,"price":1061.2,"qty":10707.0,"timestamp":1618678117262}
1618678117.289946: {"feed":"book","product_id":"FI_ETHUSD_210924","side":"buy","seq":3859225,"price":2614.3,"qty":15000.0,"timestamp":1618678117262}
1618678117.320651: {"feed":"book","product_id":"FI_ETHUSD_210924","side":"sell","seq":3859226,"price":2662.1,"qty":0.0,"timestamp":1618678117294}
1618678117.3237388: {"feed":"book","product_id":"FI_ETHUSD_210924","side":"sell","seq":3859227,"price":2662.0,"qty":225001.0,"timestamp":1618678117294}
1618678117.3238652: {"feed":"book","product_id":"FI_BCHUSD_210430","side":"buy","seq":1411911,"price":1073.7,"qty":50.0,"timestamp":1618678117294}
1618678117.325264: {"feed":"book","product_id":"FI_ETHUSD_210625","side":"sell","seq":12455792,"price":2514.5,"qty":0.0,"timestamp":1618678117294}
1618678117.325391: {"feed":"book","product_id":"PI_BCHUSD","side":"sell","seq":16259201,"price":1063.9,"qty":0.0,"timestamp":1618678117294}
1618678117.325454: {"feed":"book","product_id":"FI_ETHUSD_210625","side":"sell","seq":12455793,"price":2514.3,"qty":25003.0,"timestamp":1618678117294}
1618678117.325508: {"feed":"book","product_id":"FI_XBTUSD_210625","side":"sell","seq":21455295,"price":64081.5,"qty":0.0,"timestamp":1618678117294}
1618678117.325564: {"feed":"book","product_id":"FI_XBTUSD_210625","side":"sell","seq":21455296,"price":64080.5,"qty":250001.0,"timestamp":1618678117294}
1618678117.325623: {"feed":"book","product_id":"PI_BCHUSD","side":"sell","seq":16259202,"price":1062.5,"qty":27509.0,"timestamp":1618678117294}
1618678117.3256488: {"feed":"book","product_id":"FI_XBTUSD_210625","side":"sell","seq":21455297,"price":64249.5,"qty":0.0,"timestamp":1618678117294}
1618678117.325675: {"feed":"book","product_id":"FI_XBTUSD_210625","side":"sell","seq":21455298,"price":64248.5,"qty":125003.0,"timestamp":1618678117294}
1618678117.325699: {"feed":"book","product_id":"PI_BCHUSD","side":"sell","seq":16259203,"price":1061.2,"qty":14234.0,"timestamp":1618678117294}
1618678117.3309078: {"feed":"book","product_id":"PI_BCHUSD","side":"sell","seq":16259204,"price":1060.7,"qty":2763.0,"timestamp":1618678117301}
1618678117.330994: {"feed":"book","product_id":"PI_BCHUSD","side":"sell","seq":16259205,"price":1062.6,"qty":14399.0,"timestamp":1618678117302}
1618678117.331038: {"feed":"book","product_id":"PI_BCHUSD","side":"sell","seq":16259206,"price":1062.5,"qty":38135.0,"timestamp":1618678117302}
1618678117.331073: {"feed":"book","product_id":"PI_BCHUSD","side":"sell","seq":16259207,"price":1062.5,"qty":27509.0,"timestamp":1618678117306}
1618678117.331104: {"feed":"book","product_id":"PI_BCHUSD","side":"sell","seq":16259208,"price":1062.3,"qty":15641.0,"timestamp":1618678117306}
1618678117.339565: {"feed":"book","product_id":"PI_BCHUSD","side":"sell","seq":16259209,"price":1060.7,"qty":3638.0,"timestamp":1618678117311}
1618678117.339673: {"feed":"book","product_id":"PI_BCHUSD","side":"sell","seq":16259210,"price":1064.4,"qty":0.0,"timestamp":1618678117311}
1618678117.339745: {"feed":"book","product_id":"FI_XBTUSD_210430","side":"sell","seq":12237626,"price":61239.0,"qty":3599.0,"timestamp":1618678117313}
1618678117.362976: {"feed":"book","product_id":"PI_BCHUSD","side":"sell","seq":16259211,"price":1061.4,"qty":25231.0,"timestamp":1618678117339}
1618678117.381068: {"feed":"book","product_id":"FI_ETHUSD_210924","side":"sell","seq":3859228,"price":2660.1,"qty":0.0,"timestamp":1618678117357}
1618678117.384564: {"feed":"book","product_id":"PI_BCHUSD","side":"sell","seq":16259212,"price":1060.7,"qty":875.0,"timestamp":1618678117360}
1618678117.4702668: {"feed":"book","product_id":"FI_XBTUSD_210430","side":"buy","seq":12237627,"price":59445.5,"qty":52895.0,"timestamp":1618678117445}
1618678117.4908092: {"feed":"book","product_id":"FI_XBTUSD_210625","side":"sell","seq":21455299,"price":64081.0,"qty":0.0,"timestamp":1618678117457}
1618678117.490968: {"feed":"book","product_id":"FI_XBTUSD_210625","side":"sell","seq":21455300,"price":64081.0,"qty":19892.0,"timestamp":1618678117457}
1618678117.491008: {"feed":"book","product_id":"FI_XBTUSD_210625","side":"sell","seq":21455301,"price":64053.0,"qty":0.0,"timestamp":1618678117457}
1618678117.491037: {"feed":"book","product_id":"FI_XBTUSD_210625","side":"sell","seq":21455302,"price":64053.0,"qty":14332.0,"timestamp":1618678117457}
1618678117.491063: {"feed":"book","product_id":"FI_XBTUSD_210625","side":"buy","seq":21455303,"price":63896.0,"qty":1292.0,"timestamp":1618678117458}
1618678117.491085: {"feed":"book","product_id":"FI_XBTUSD_210625","side":"buy","seq":21455304,"price":63896.0,"qty":2553.0,"timestamp":1618678117458}
1618678117.491105: {"feed":"book","product_id":"FI_XBTUSD_210625","side":"buy","seq":21455305,"price":63896.0,"qty":1261.0,"timestamp":1618678117458}
1618678117.491124: {"feed":"book","product_id":"FI_XBTUSD_210625","side":"buy","seq":21455306,"price":63896.0,"qty":2522.0,"timestamp":1618678117458}
1618678117.491143: {"feed":"book","product_id":"FI_XBTUSD_210625","side":"sell","seq":21455307,"price":64118.5,"qty":0.0,"timestamp":1618678117458}
1618678117.491167: {"feed":"book","product_id":"FI_XBTUSD_210625","side":"sell","seq":21455308,"price":64118.5,"qty":29155.0,"timestamp":1618678117458}
1618678117.49119: {"feed":"book","product_id":"FI_XBTUSD_210625","side":"buy","seq":21455309,"price":63881.0,"qty":0.0,"timestamp":1618678117458}
1618678117.491216: {"feed":"book","product_id":"FI_XBTUSD_210625","side":"buy","seq":21455310,"price":63881.0,"qty":1487.0,"timestamp":1618678117458}
1618678117.4912388: {"feed":"book","product_id":"FI_XBTUSD_210625","side":"buy","seq":21455311,"price":63489.0,"qty":0.0,"timestamp":1618678117458}
1618678117.491262: {"feed":"book","product_id":"FI_XBTUSD_210625","side":"buy","seq":21455312,"price":63489.0,"qty":4382.0,"timestamp":1618678117458}
1618678117.491285: {"feed":"book","product_id":"FI_XBTUSD_210625","side":"buy","seq":21455313,"price":63728.0,"qty":0.0,"timestamp":1618678117458}
1618678117.491308: {"feed":"book","product_id":"FI_XBTUSD_210625","side":"buy","seq":21455314,"price":63728.0,"qty":3326.0,"timestamp":1618678117458}
1618678117.4913301: {"feed":"book","product_id":"FI_XBTUSD_210625","side":"sell","seq":21455315,"price":64249.0,"qty":0.0,"timestamp":1618678117458}
1618678117.491353: {"feed":"book","product_id":"FI_XBTUSD_210625","side":"sell","seq":21455316,"price":64249.0,"qty":57024.0,"timestamp":1618678117458}
1618678117.4913752: {"feed":"book","product_id":"FI_XBTUSD_210625","side":"sell","seq":21455317,"price":64529.5,"qty":0.0,"timestamp":1618678117458}
1618678117.4913979: {"feed":"book","product_id":"FI_XBTUSD_210625","side":"sell","seq":21455318,"price":64529.5,"qty":76451.0,"timestamp":1618678117458}
1618678117.5065558: {"feed":"book","product_id":"FI_ETHUSD_210625","side":"sell","seq":12455794,"price":2514.55,"qty":333570.0,"timestamp":1618678117482}
1618678117.5072598: {"feed":"book","product_id":"FI_ETHUSD_210625","side":"sell","seq":12455795,"price":2529.05,"qty":26620.0,"timestamp":1618678117482}
1618678117.507325: {"feed":"book","product_id":"FI_ETHUSD_210625","side":"sell","seq":12455796,"price":2543.6,"qty":26620.0,"timestamp":1618678117482}
1618678117.50736: {"feed":"book","product_id":"FI_ETHUSD_210625","side":"sell","seq":12455797,"price":2572.65,"qty":26620.0,"timestamp":1618678117483}
1618678117.5073888: {"feed":"book","product_id":"FI_ETHUSD_210625","side":"buy","seq":12455798,"price":2488.85,"qty":26620.0,"timestamp":1618678117483}
1618678117.507424: {"feed":"book","product_id":"FI_ETHUSD_210625","side":"buy","seq":12455799,"price":2477.25,"qty":27532.0,"timestamp":1618678117483}
1618678117.507447: {"feed":"book","product_id":"FI_ETHUSD_210625","side":"buy","seq":12455800,"price":2466.9,"qty":26620.0,"timestamp":1618678117483}
1618678117.507471: {"feed":"book","product_id":"FI_ETHUSD_210625","side":"buy","seq":12455801,"price":2445.0,"qty":26620.0,"timestamp":1618678117483}
1618678117.509095: {"feed":"book","product_id":"FI_ETHUSD_210625","side":"buy","seq":12455802,"price":2412.15,"qty":26620.0,"timestamp":1618678117483}
1618678117.516417: {"feed":"book","product_id":"PI_BCHUSD","side":"sell","seq":16259213,"price":1061.2,"qty":10707.0,"timestamp":1618678117491}
1618678117.516532: {"feed":"book","product_id":"PI_BCHUSD","side":"buy","seq":16259214,"price":1056.9,"qty":3780.0,"timestamp":1618678117491}
1618678117.516581: {"feed":"book","product_id":"FI_XBTUSD_210625","side":"buy","seq":21455319,"price":57200.5,"qty":35956.0,"timestamp":1618678117493}
1618678117.516621: {"feed":"book","product_id":"PI_BCHUSD","side":"buy","seq":16259215,"price":1058.1,"qty":8730.0,"timestamp":1618678117493}
1618678117.523681: {"feed":"book","product_id":"PI_BCHUSD","side":"buy","seq":16259216,"price":1058.1,"qty":12445.0,"timestamp":1618678117500}
1618678117.567543: {"feed":"book","product_id":"FI_XBTUSD_210924","side":"buy","seq":13850988,"price":52552.5,"qty":58990.0,"timestamp":1618678117544}
1618678117.585768: {"feed":"book","product_id":"PI_BCHUSD","side":"sell","seq":16259217,"price":1062.5,"qty":32497.0,"timestamp":1618678117562}
1618678117.5890381: {"feed":"book","product_id":"FI_ETHUSD_210625","side":"sell","seq":12455803,"price":2503.8,"qty":0.0,"timestamp":1618678117565}
1618678117.58917: {"feed":"book","product_id":"FI_ETHUSD_210625","side":"sell","seq":12455804,"price":2503.8,"qty":7725.0,"timestamp":1618678117565}
1618678117.5892322: {"feed":"book","product_id":"FI_ETHUSD_210625","side":"sell","seq":12455805,"price":2505.45,"qty":0.0,"timestamp":1618678117565}
1618678117.58928: {"feed":"book","product_id":"FI_ETHUSD_210625","side":"sell","seq":12455806,"price":2505.45,"qty":12676.0,"timestamp":1618678117565}
1618678117.589346: {"feed":"book","product_id":"FI_ETHUSD_210625","side":"sell","seq":12455807,"price":2507.0,"qty":0.0,"timestamp":1618678117565}
1618678117.589372: {"feed":"book","product_id":"FI_ETHUSD_210625","side":"sell","seq":12455808,"price":2507.0,"qty":17052.0,"timestamp":1618678117565}
1618678117.5897238: {"feed":"book","product_id":"FI_ETHUSD_210625","side":"buy","seq":12455809,"price":2499.35,"qty":248.0,"timestamp":1618678117566}
1618678117.589767: {"feed":"book","product_id":"FI_ETHUSD_210625","side":"buy","seq":12455810,"price":2499.35,"qty":491.0,"timestamp":1618678117566}
1618678117.589791: {"feed":"book","product_id":"FI_ETHUSD_210625","side":"buy","seq":12455811,"price":2499.35,"qty":243.0,"timestamp":1618678117566}
1618678117.589813: {"feed":"book","product_id":"FI_ETHUSD_210625","side":"buy","seq":12455812,"price":2499.35,"qty":486.0,"timestamp":1618678117566}
1618678117.592522: {"feed":"book","product_id":"FI_ETHUSD_210625","side":"buy","seq":12455813,"price":2497.5,"qty":0.0,"timestamp":1618678117566}
1618678117.592614: {"feed":"book","product_id":"FI_ETHUSD_210625","side":"buy","seq":12455814,"price":2497.5,"qty":346.0,"timestamp":1618678117566}
1618678117.592656: {"feed":"book","product_id":"FI_ETHUSD_210625","side":"buy","seq":12455815,"price":2477.25,"qty":26620.0,"timestamp":1618678117566}
1618678117.592684: {"feed":"book","product_id":"FI_ETHUSD_210625","side":"buy","seq":12455816,"price":2477.25,"qty":27545.0,"timestamp":1618678117566}
1618678117.592706: {"feed":"book","product_id":"FI_ETHUSD_210625","side":"sell","seq":12455817,"price":2513.2,"qty":0.0,"timestamp":1618678117566}
1618678117.592735: {"feed":"book","product_id":"FI_ETHUSD_210625","side":"sell","seq":12455818,"price":2513.2,"qty":34618.0,"timestamp":1618678117566}
1618678117.592761: {"feed":"book","product_id":"FI_ETHUSD_210625","side":"buy","seq":12455819,"price":2492.45,"qty":0.0,"timestamp":1618678117566}
1618678117.592787: {"feed":"book","product_id":"FI_ETHUSD_210625","side":"buy","seq":12455820,"price":2492.45,"qty":640.0,"timestamp":1618678117566}
1618678117.592812: {"feed":"book","product_id":"FI_ETHUSD_210625","side":"sell","seq":12455821,"price":2527.4,"qty":0.0,"timestamp":1618678117566}
1618678117.592837: {"feed":"book","product_id":"FI_ETHUSD_210625","side":"sell","seq":12455822,"price":2527.4,"qty":47822.0,"timestamp":1618678117566}
1618678117.614679: {"feed":"book","product_id":"PI_BCHUSD","side":"sell","seq":16259218,"price":1061.2,"qty":7182.0,"timestamp":1618678117590}
1618678117.614787: {"feed":"book","product_id":"PI_BCHUSD","side":"sell","seq":16259219,"price":1061.5,"qty":0.0,"timestamp":1618678117591}
1618678117.614856: {"feed":"book","product_id":"PI_BCHUSD","side":"sell","seq":16259220,"price":1061.4,"qty":4827.0,"timestamp":1618678117591}
1618678117.6156569: {"feed":"book","product_id":"PI_BCHUSD","side":"sell","seq":16259221,"price":1061.4,"qty":1341.0,"timestamp":1618678117593}
1618678117.616392: {"feed":"book","product_id":"PI_BCHUSD","side":"buy","seq":16259222,"price":1057.1,"qty":3622.0,"timestamp":1618678117594}
1618678117.6164942: {"feed":"book","product_id":"PI_BCHUSD","side":"buy","seq":16259223,"price":1055.7,"qty":0.0,"timestamp":1618678117594}
1618678117.630262: {"feed":"book","product_id":"PI_BCHUSD","side":"buy","seq":16259224,"price":1057.6,"qty":3602.0,"timestamp":1618678117605}
1618678117.6383429: {"feed":"book","product_id":"PI_BCHUSD","side":"sell","seq":16259225,"price":1062.3,"qty":5015.0,"timestamp":1618678117608}
1618678117.664798: {"feed":"book","product_id":"FI_ETHUSD_210625","side":"sell","seq":12455823,"price":2506.5,"qty":0.0,"timestamp":1618678117638}
1618678117.664928: {"feed":"book","product_id":"FI_ETHUSD_210625","side":"sell","seq":12455824,"price":2506.2,"qty":441.0,"timestamp":1618678117638}
1618678117.667979: {"feed":"book","product_id":"FI_ETHUSD_210430","side":"sell","seq":4780922,"price":2394.3,"qty":0.0,"timestamp":1618678117638}
1618678117.668107: {"feed":"book","product_id":"FI_ETHUSD_210430","side":"sell","seq":4780923,"price":2393.8,"qty":578.0,"timestamp":1618678117638}
1618678117.668169: {"feed":"book","product_id":"FI_ETHUSD_210924","side":"sell","seq":3859229,"price":2670.0,"qty":0.0,"timestamp":1618678117638}
1618678117.6682189: {"feed":"book","product_id":"FI_ETHUSD_210924","side":"sell","seq":3859230,"price":2669.7,"qty":219.0,"timestamp":1618678117638}
1618678117.6991591: {"feed":"book","product_id":"PI_BCHUSD","side":"sell","seq":16259226,"price":1061.1,"qty":2896.0,"timestamp":1618678117675}
1618678117.7140539: {"feed":"book","product_id":"PI_BCHUSD","side":"sell","seq":16259227,"price":1061.2,"qty":0.0,"timestamp":1618678117690}
1618678117.737385: {"feed":"book","product_id":"PI_BCHUSD","side":"sell","seq":16259228,"price":1061.7,"qty":9533.0,"timestamp":1618678117713}
1618678117.756854: {"feed":"book","product_id":"FI_XBTUSD_210430","side":"buy","seq":12237628,"price":59445.5,"qty":52651.0,"timestamp":1618678117732}
1618678117.771193: {"feed":"book","product_id":"PI_BCHUSD","side":"buy","seq":16259229,"price":1057.9,"qty":14550.0,"timestamp":1618678117744}
1618678117.7713192: {"feed":"book","product_id":"FI_XRPUSD_210625","side":"sell","seq":3631650,"price":1.6971,"qty":0.0,"timestamp":1618678117747}
1618678117.7713878: {"feed":"book","product_id":"FI_XRPUSD_210625","side":"sell","seq":3631651,"price":1.6983,"qty":334.0,"timestamp":1618678117747}
1618678117.773651: {"feed":"book","product_id":"FI_BCHUSD_210625","side":"buy","seq":2240261,"price":1128.0,"qty":74.0,"timestamp":1618678117749}
1618678117.781729: {"feed":"book","product_id":"PI_BCHUSD","side":"buy","seq":16259230,"price":1057.9,"qty":0.0,"timestamp":1618678117755}
1618678117.7818172: {"feed":"book","product_id":"PI_BCHUSD","side":"buy","seq":16259231,"price":1058.3,"qty":0.0,"timestamp":1618678117756}
1618678117.7818549: {"feed":"book","product_id":"PI_BCHUSD","side":"sell","seq":16259232,"price":1061.1,"qty":50.0,"timestamp":1618678117757}
1618678117.781882: {"feed":"book","product_id":"PI_BCHUSD","side":"sell","seq":16259233,"price":1061.7,"qty":6144.0,"timestamp":1618678117757}
1618678117.781904: {"feed":"book","product_id":"PI_BCHUSD","side":"buy","seq":16259234,"price":1057.0,"qty":6084.0,"timestamp":1618678117757}
1618678117.78607: {"feed":"book","product_id":"PI_BCHUSD","side":"buy","seq":16259235,"price":1057.9,"qty":3750.0,"timestamp":1618678117758}
1618678117.9180632: {"feed":"book","product_id":"FI_XBTUSD_210430","side":"buy","seq":12237629,"price":59445.5,"qty":52895.0,"timestamp":1618678117894}
1618678117.933702: {"feed":"book","product_id":"PI_BCHUSD","side":"buy","seq":16259236,"price":1058.5,"qty":3565.0,"timestamp":1618678117908}
1618678117.946259: {"feed":"book","product_id":"FI_XBTUSD_210625","side":"sell","seq":21455320,"price":64081.0,"qty":0.0,"timestamp":1618678117921}
1618678117.946384: {"feed":"book","product_id":"FI_XBTUSD_210625","side":"sell","seq":21455321,"price":64080.0,"qty":19578.0,"timestamp":1618678117921}
1618678117.9464471: {"feed":"book","product_id":"PI_BCHUSD","side":"buy","seq":16259237,"price":1058.6,"qty":33253.0,"timestamp":1618678117922}
1618678117.956786: {"feed":"book","product_id":"PI_BCHUSD","side":"buy","seq":16259238,"price":1058.6,"qty":33167.0,"timestamp":1618678117933}
1618678117.963413: {"feed":"book","product_id":"PI_BCHUSD","side":"buy","seq":16259239,"price":1058.0,"qty":20927.0,"timestamp":1618678117940}
1618678117.982296: {"feed":"book","product_id":"PI_BCHUSD","side":"buy","seq":16259240,"price":1058.5,"qty":7201.0,"timestamp":1618678117958}
1618678118.015933: {"feed":"book","product_id":"FI_ETHUSD_210924","side":"sell","seq":3859231,"price":2660.0,"qty":2000.0,"timestamp":1618678117991}
1618678118.028401: {"feed":"book","product_id":"PI_BCHUSD","side":"sell","seq":16259241,"price":1061.2,"qty":2875.0,"timestamp":1618678118003}
1618678118.032785: {"feed":"book","product_id":"PI_BCHUSD","side":"sell","seq":16259242,"price":1061.2,"qty":5467.0,"timestamp":1618678118007}
1618678118.0328598: {"feed":"book","product_id":"PI_BCHUSD","side":"sell","seq":16259243,"price":1061.2,"qty":8198.0,"timestamp":1618678118007}
1618678118.055359: {"feed":"book","product_id":"FI_ETHUSD_210625","side":"sell","seq":12455825,"price":2503.8,"qty":0.0,"timestamp":1618678118029}
1618678118.055437: {"feed":"book","product_id":"FI_ETHUSD_210625","side":"sell","seq":12455826,"price":2503.8,"qty":7470.0,"timestamp":1618678118029}
1618678118.05547: {"feed":"book","product_id":"FI_ETHUSD_210625","side":"sell","seq":12455827,"price":2505.45,"qty":0.0,"timestamp":1618678118029}
1618678118.055495: {"feed":"book","product_id":"FI_ETHUSD_210625","side":"sell","seq":12455828,"price":2505.45,"qty":12457.0,"timestamp":1618678118029}
1618678118.055517: {"feed":"book","product_id":"FI_ETHUSD_210625","side":"sell","seq":12455829,"price":2507.0,"qty":0.0,"timestamp":1618678118029}
1618678118.055537: {"feed":"book","product_id":"FI_ETHUSD_210625","side":"sell","seq":12455830,"price":2507.0,"qty":16796.0,"timestamp":1618678118029}
1618678118.0559192: {"feed":"book","product_id":"FI_ETHUSD_210625","side":"buy","seq":12455831,"price":2499.35,"qty":243.0,"timestamp":1618678118029}
1618678118.055966: {"feed":"book","product_id":"FI_ETHUSD_210625","side":"buy","seq":12455832,"price":2499.35,"qty":489.0,"timestamp":1618678118029}
1618678118.055989: {"feed":"book","product_id":"FI_ETHUSD_210625","side":"buy","seq":12455833,"price":2499.35,"qty":246.0,"timestamp":1618678118029}
1618678118.056007: {"feed":"book","product_id":"FI_ETHUSD_210625","side":"buy","seq":12455834,"price":2499.35,"qty":492.0,"timestamp":1618678118029}
1618678118.0560231: {"feed":"book","product_id":"FI_ETHUSD_210625","side":"buy","seq":12455835,"price":2477.25,"qty":26620.0,"timestamp":1618678118029}
1618678118.0560389: {"feed":"book","product_id":"FI_ETHUSD_210625","side":"buy","seq":12455836,"price":2477.25,"qty":27538.0,"timestamp":1618678118029}
1618678118.0594711: {"feed":"book","product_id":"FI_ETHUSD_210625","side":"buy","seq":12455837,"price":2497.5,"qty":0.0,"timestamp":1618678118029}
1618678118.059563: {"feed":"book","product_id":"FI_ETHUSD_210625","side":"buy","seq":12455838,"price":2497.5,"qty":348.0,"timestamp":1618678118029}
1618678118.059603: {"feed":"book","product_id":"FI_ETHUSD_210625","side":"sell","seq":12455839,"price":2513.2,"qty":0.0,"timestamp":1618678118029}
1618678118.0596359: {"feed":"book","product_id":"FI_ETHUSD_210625","side":"sell","seq":12455840,"price":2513.2,"qty":34471.0,"timestamp":1618678118029}
1618678118.059663: {"feed":"book","product_id":"FI_ETHUSD_210625","side":"buy","seq":12455841,"price":2492.45,"qty":0.0,"timestamp":1618678118029}
1618678118.059689: {"feed":"book","product_id":"FI_ETHUSD_210625","side":"buy","seq":12455842,"price":2492.45,"qty":638.0,"timestamp":1618678118029}
1618678118.0597131: {"feed":"book","product_id":"FI_ETHUSD_210625","side":"sell","seq":12455843,"price":2527.4,"qty":0.0,"timestamp":1618678118029}
1618678118.0597382: {"feed":"book","product_id":"FI_ETHUSD_210625","side":"sell","seq":12455844,"price":2527.4,"qty":47823.0,"timestamp":1618678118029}
1618678118.0630982: {"feed":"book","product_id":"PI_BCHUSD","side":"sell","seq":16259244,"price":1062.3,"qty":3807.0,"timestamp":1618678118038}
1618678118.063178: {"feed":"book","product_id":"PI_BCHUSD","side":"sell","seq":16259245,"price":1061.0,"qty":952.0,"timestamp":1618678118038}
1618678118.070333: {"feed":"book","product_id":"FI_XBTUSD_210430","side":"buy","seq":12237630,"price":59445.5,"qty":52651.0,"timestamp":1618678118046}
1618678118.070443: {"feed":"book","product_id":"FI_XBTUSD_210430","side":"buy","seq":12237631,"price":61097.0,"qty":0.0,"timestamp":1618678118047}
1618678118.071993: {"feed":"book","product_id":"FI_XBTUSD_210625","side":"buy","seq":21455322,"price":63895.5,"qty":0.0,"timestamp":1618678118048}
1618678118.148541: {"feed":"book","product_id":"FI_XRPUSD_210625","side":"sell","seq":3631652,"price":1.697,"qty":292.0,"timestamp":1618678118119}
1618678118.179532: {"feed":"book","product_id":"PI_BCHUSD","side":"sell","seq":16259246,"price":1061.2,"qty":5606.0,"timestamp":1618678118153}
1618678118.17964: {"feed":"book","product_id":"PI_BCHUSD","side":"buy","seq":16259247,"price":1058.5,"qty":3565.0,"timestamp":1618678118155}
1618678118.17969: {"feed":"book","product_id":"PI_BCHUSD","side":"sell","seq":16259248,"price":1064.7,"qty":0.0,"timestamp":1618678118156}
1618678118.181122: {"feed":"book","product_id":"PI_BCHUSD","side":"sell","seq":16259249,"price":1063.2,"qty":11529.0,"timestamp":1618678118157}
1618678118.18123: {"feed":"book","product_id":"PI_BCHUSD","side":"buy","seq":16259250,"price":1058.5,"qty":0.0,"timestamp":1618678118157}
1618678118.216545: {"feed":"book","product_id":"PI_BCHUSD","side":"sell","seq":16259251,"price":1061.5,"qty":3738.0,"timestamp":1618678118193}
1618678118.2251992: {"feed":"book","product_id":"PI_BCHUSD","side":"sell","seq":16259252,"price":1061.6,"qty":14861.0,"timestamp":1618678118202}
1618678118.2342532: {"feed":"book","product_id":"FI_ETHUSD_210625","side":"sell","seq":12455845,"price":2505.8,"qty":3000.0,"timestamp":1618678118209}
1618678118.240546: {"feed":"book","product_id":"FI_XBTUSD_210625","side":"buy","seq":21455323,"price":63896.5,"qty":2145.0,"timestamp":1618678118211}
1618678118.2457669: {"feed":"book","product_id":"PI_BCHUSD","side":"sell","seq":16259253,"price":1061.6,"qty":36190.0,"timestamp":1618678118222}
1618678118.2490041: {"feed":"book","product_id":"FI_XBTUSD_210430","side":"buy","seq":12237632,"price":61071.5,"qty":25378.0,"timestamp":1618678118224}
1618678118.253224: {"feed":"book","product_id":"FI_XBTUSD_210430","side":"buy","seq":12237633,"price":59445.5,"qty":52895.0,"timestamp":1618678118230}
1618678118.257774: {"feed":"book","product_id":"FI_XBTUSD_210625","side":"buy","seq":21455324,"price":63881.0,"qty":0.0,"timestamp":1618678118233}
1618678118.257904: {"feed":"book","product_id":"FI_XBTUSD_210625","side":"buy","seq":21455325,"price":63826.5,"qty":2056.0,"timestamp":1618678118233}
1618678118.2579682: {"feed":"book","product_id":"FI_XBTUSD_210625","side":"sell","seq":21455326,"price":64053.0,"qty":0.0,"timestamp":1618678118233}
1618678118.2580202: {"feed":"book","product_id":"FI_XBTUSD_210625","side":"sell","seq":21455327,"price":64041.5,"qty":12890.0,"timestamp":1618678118233}
1618678118.258063: {"feed":"book","product_id":"FI_XBTUSD_210625","side":"sell","seq":21455328,"price":64118.5,"qty":0.0,"timestamp":1618678118233}
1618678118.258104: {"feed":"book","product_id":"FI_XBTUSD_210625","side":"sell","seq":21455329,"price":64098.5,"qty":25457.0,"timestamp":1618678118233}
1618678118.258549: {"feed":"book","product_id":"FI_ETHUSD_210625","side":"sell","seq":12455846,"price":2503.8,"qty":0.0,"timestamp":1618678118235}
1618678118.258629: {"feed":"book","product_id":"FI_ETHUSD_210625","side":"sell","seq":12455847,"price":2503.55,"qty":7255.0,"timestamp":1618678118235}
1618678118.274765: {"feed":"book","product_id":"FI_XRPUSD_210625","side":"buy","seq":3631653,"price":1.6934,"qty":50.0,"timestamp":1618678118251}
1618678118.274875: {"feed":"book","product_id":"FI_XRPUSD_210625","side":"buy","seq":3631654,"price":1.6926,"qty":68.0,"timestamp":1618678118251}
1618678118.275459: {"feed":"book","product_id":"FI_XRPUSD_210625","side":"sell","seq":3631655,"price":1.6986,"qty":0.0,"timestamp":1618678118253}
1618678118.2755258: {"feed":"book","product_id":"FI_XRPUSD_210625","side":"sell","seq":3631656,"price":1.6978,"qty":18968.0,"timestamp":1618678118253}
1618678118.2755651: {"feed":"book","product_id":"FI_XRPUSD_210625","side":"buy","seq":3631657,"price":1.6917,"qty":0.0,"timestamp":1618678118253}
1618678118.275597: {"feed":"book","product_id":"FI_XRPUSD_210625","side":"buy","seq":3631658,"price":1.691,"qty":19200.0,"timestamp":1618678118253}
1618678118.366186: {"feed":"book","product_id":"PI_BCHUSD","side":"sell","seq":16259254,"price":1061.5,"qty":7160.0,"timestamp":1618678118338}
1618678118.3662982: {"feed":"book","product_id":"PI_BCHUSD","side":"sell","seq":16259255,"price":1061.0,"qty":3655.0,"timestamp":1618678118338}
1618678118.3685381: {"feed":"book","product_id":"FI_ETHUSD_210625","side":"sell","seq":12455848,"price":2505.35,"qty":2000.0,"timestamp":1618678118338}
1618678118.368663: {"feed":"book","product_id":"FI_ETHUSD_210625","side":"buy","seq":12455849,"price":2481.6,"qty":5000.0,"timestamp":1618678118338}
1618678118.3687198: {"feed":"book","product_id":"FI_ETHUSD_210625","side":"buy","seq":12455850,"price":2469.1,"qty":15000.0,"timestamp":1618678118338}
1618678118.371663: {"feed":"book","product_id":"PI_BCHUSD","side":"sell","seq":16259256,"price":1061.7,"qty":9799.0,"timestamp":1618678118345}
1618678118.38019: {"feed":"book","product_id":"PI_BCHUSD","side":"sell","seq":16259257,"price":1061.0,"qty":952.0,"timestamp":1618678118356}
1618678118.4233768: {"feed":"book","product_id":"FI_XBTUSD_210625","side":"buy","seq":21455330,"price":63896.5,"qty":1920.0,"timestamp":1618678118395}
1618678118.4501219: {"feed":"book","product_id":"FI_BCHUSD_210625","side":"sell","seq":2240262,"price":1138.8,"qty":14399.0,"timestamp":1618678118424}
1618678118.450249: {"feed":"book","product_id":"FI_BCHUSD_210625","side":"buy","seq":2240263,"price":1121.3,"qty":44999.0,"timestamp":1618678118426}
1618678118.464482: {"feed":"book","product_id":"FI_XBTUSD_210625","side":"sell","seq":21455331,"price":64041.5,"qty":0.0,"timestamp":1618678118439}
1618678118.464614: {"feed":"book","product_id":"FI_XBTUSD_210625","side":"sell","seq":21455332,"price":64053.0,"qty":14344.0,"timestamp":1618678118439}
1618678118.4646862: {"feed":"book","product_id":"FI_ETHUSD_210625","side":"sell","seq":12455851,"price":2503.55,"qty":0.0,"timestamp":1618678118440}
1618678118.464745: {"feed":"book","product_id":"FI_ETHUSD_210625","side":"sell","seq":12455852,"price":2503.8,"qty":7201.0,"timestamp":1618678118440}
1618678118.4647732: {"feed":"book","product_id":"FI_XBTUSD_210625","side":"sell","seq":21455333,"price":64098.5,"qty":0.0,"timestamp":1618678118439}
1618678118.4648: {"feed":"book","product_id":"FI_XBTUSD_210625","side":"sell","seq":21455334,"price":64118.5,"qty":29170.0,"timestamp":1618678118439}
1618678118.4665442: {"feed":"book","product_id":"FI_XBTUSD_210625","side":"buy","seq":21455335,"price":63826.5,"qty":0.0,"timestamp":1618678118439}
1618678118.4666371: {"feed":"book","product_id":"FI_XBTUSD_210625","side":"buy","seq":21455336,"price":63881.0,"qty":1431.0,"timestamp":1618678118439}
1618678118.46668: {"feed":"book","product_id":"FI_XBTUSD_210625","side":"buy","seq":21455337,"price":63896.0,"qty":1261.0,"timestamp":1618678118439}
1618678118.466707: {"feed":"book","product_id":"FI_XBTUSD_210625","side":"buy","seq":21455338,"price":63881.0,"qty":2862.0,"timestamp":1618678118439}
1618678118.466728: {"feed":"book","product_id":"FI_XBTUSD_210625","side":"buy","seq":21455339,"price":63896.0,"qty":0.0,"timestamp":1618678118439}
1618678118.4667552: {"feed":"book","product_id":"FI_XBTUSD_210625","side":"buy","seq":21455340,"price":63881.0,"qty":4293.0,"timestamp":1618678118439}
1618678118.486349: {"feed":"book","product_id":"FI_XBTUSD_210430","side":"buy","seq":12237634,"price":59445.5,"qty":52651.0,"timestamp":1618678118460}
1618678118.513348: {"feed":"book","product_id":"FI_XBTUSD_210625","side":"buy","seq":21455341,"price":63865.5,"qty":17908.0,"timestamp":1618678118486}
1618678118.537629: {"feed":"book","product_id":"PI_BCHUSD","side":"sell","seq":16259258,"price":1062.2,"qty":10622.0,"timestamp":1618678118513}
1618678118.554223: {"feed":"book","product_id":"FI_XRPUSD_210625","side":"buy","seq":3631659,"price":1.6866,"qty":33599.0,"timestamp":1618678118527}
1618678118.5543392: {"feed":"book","product_id":"FI_XRPUSD_210625","side":"buy","seq":3631660,"price":1.6823,"qty":2955.0,"timestamp":1618678118527}
1618678118.599039: {"feed":"book","product_id":"FI_XRPUSD_210625","side":"sell","seq":3631661,"price":1.6968,"qty":50.0,"timestamp":1618678118574}
1618678118.599489: {"feed":"book","product_id":"PI_BCHUSD","side":"buy","seq":16259259,"price":1050.7,"qty":44999.0,"timestamp":1618678118574}
1618678118.607502: {"feed":"book","product_id":"FI_XRPUSD_210625","side":"sell","seq":3631662,"price":1.6969,"qty":0.0,"timestamp":1618678118581}
1618678118.607591: {"feed":"book","product_id":"FI_XRPUSD_210625","side":"sell","seq":3631663,"price":1.6967,"qty":768.0,"timestamp":1618678118581}
1618678118.623934: {"feed":"book","product_id":"FI_XRPUSD_210625","side":"buy","seq":3631664,"price":1.6926,"qty":0.0,"timestamp":1618678118593}
1618678118.624068: {"feed":"book","product_id":"FI_XRPUSD_210625","side":"buy","seq":3631665,"price":1.6921,"qty":68.0,"timestamp":1618678118593}
1618678118.624129: {"feed":"book","product_id":"FI_XRPUSD_210625","side":"buy","seq":3631666,"price":1.6822,"qty":0.0,"timestamp":1618678118595}
1618678118.624177: {"feed":"book","product_id":"FI_XRPUSD_210625","side":"buy","seq":3631667,"price":1.68,"qty":172800.0,"timestamp":1618678118595}
1618678118.627904: {"feed":"book","product_id":"FI_XRPUSD_210625","side":"sell","seq":3631668,"price":1.6968,"qty":0.0,"timestamp":1618678118599}
1618678118.627993: {"feed":"book","product_id":"FI_XRPUSD_210625","side":"sell","seq":3631669,"price":1.6967,"qty":818.0,"timestamp":1618678118599}
1618678118.66513: {"feed":"book","product_id":"FI_ETHUSD_210430","side":"sell","seq":4780924,"price":2393.8,"qty":0.0,"timestamp":1618678118640}
1618678118.6652632: {"feed":"book","product_id":"FI_ETHUSD_210430","side":"sell","seq":4780925,"price":2393.3,"qty":578.0,"timestamp":1618678118640}
1618678118.665326: {"feed":"book","product_id":"FI_ETHUSD_210924","side":"sell","seq":3859232,"price":2669.7,"qty":0.0,"timestamp":1618678118640}
1618678118.6653771: {"feed":"book","product_id":"FI_ETHUSD_210924","side":"sell","seq":3859233,"price":2669.1,"qty":219.0,"timestamp":1618678118640}
1618678118.665714: {"feed":"book","product_id":"FI_ETHUSD_210625","side":"sell","seq":12455853,"price":2506.2,"qty":0.0,"timestamp":1618678118642}
1618678118.6658309: {"feed":"book","product_id":"FI_ETHUSD_210625","side":"sell","seq":12455854,"price":2505.65,"qty":441.0,"timestamp":1618678118642}
1618678118.672309: {"feed":"book","product_id":"FI_XBTUSD_210625","side":"sell","seq":21455342,"price":64053.0,"qty":0.0,"timestamp":1618678118648}
1618678118.672441: {"feed":"book","product_id":"FI_XBTUSD_210625","side":"sell","seq":21455343,"price":64041.5,"qty":12747.0,"timestamp":1618678118648}
1618678118.6864588: {"feed":"book","product_id":"FI_BCHUSD_210430","side":"buy","seq":1411912,"price":1065.2,"qty":44999.0,"timestamp":1618678118662}
1618678118.691231: {"feed":"book","product_id":"PI_BCHUSD","side":"sell","seq":16259260,"price":1061.6,"qty":21329.0,"timestamp":1618678118666}
1618678118.691342: {"feed":"book","product_id":"PI_BCHUSD","side":"buy","seq":16259261,"price":1058.0,"qty":0.0,"timestamp":1618678118667}
1618678118.691735: {"feed":"book","product_id":"PI_BCHUSD","side":"sell","seq":16259262,"price":1061.7,"qty":6144.0,"timestamp":1618678118668}
1618678118.698667: {"feed":"book","product_id":"PI_BCHUSD","side":"sell","seq":16259263,"price":1060.6,"qty":2896.0,"timestamp":1618678118674}
1618678118.725253: {"feed":"book","product_id":"PI_BCHUSD","side":"sell","seq":16259264,"price":1060.6,"qty":0.0,"timestamp":1618678118700}
1618678118.728532: {"feed":"book","product_id":"FI_ETHUSD_210625","side":"sell","seq":12455855,"price":2505.45,"qty":0.0,"timestamp":1618678118704}
1618678118.7286642: {"feed":"book","product_id":"FI_ETHUSD_210625","side":"sell","seq":12455856,"price":2505.45,"qty":12226.0,"timestamp":1618678118704}
1618678118.729305: {"feed":"book","product_id":"FI_ETHUSD_210625","side":"sell","seq":12455857,"price":2507.0,"qty":0.0,"timestamp":1618678118704}
1618678118.729402: {"feed":"book","product_id":"FI_ETHUSD_210625","side":"sell","seq":12455858,"price":2507.0,"qty":16526.0,"timestamp":1618678118704}
1618678118.729463: {"feed":"book","product_id":"FI_ETHUSD_210625","side":"buy","seq":12455859,"price":2497.5,"qty":0.0,"timestamp":1618678118705}
1618678118.729512: {"feed":"book","product_id":"FI_ETHUSD_210625","side":"buy","seq":12455860,"price":2497.5,"qty":351.0,"timestamp":1618678118705}
1618678118.73182: {"feed":"book","product_id":"FI_ETHUSD_210625","side":"buy","seq":12455861,"price":2499.35,"qty":246.0,"timestamp":1618678118705}
1618678118.731931: {"feed":"book","product_id":"FI_ETHUSD_210625","side":"buy","seq":12455862,"price":2499.35,"qty":494.0,"timestamp":1618678118705}
1618678118.73199: {"feed":"book","product_id":"FI_ETHUSD_210625","side":"buy","seq":12455863,"price":2499.35,"qty":248.0,"timestamp":1618678118705}
1618678118.7320268: {"feed":"book","product_id":"FI_ETHUSD_210625","side":"buy","seq":12455864,"price":2499.35,"qty":496.0,"timestamp":1618678118705}
1618678118.73206: {"feed":"book","product_id":"FI_ETHUSD_210625","side":"buy","seq":12455865,"price":2477.25,"qty":26620.0,"timestamp":1618678118705}
1618678118.732092: {"feed":"book","product_id":"FI_ETHUSD_210625","side":"buy","seq":12455866,"price":2477.25,"qty":27532.0,"timestamp":1618678118705}
1618678118.7324958: {"feed":"book","product_id":"FI_ETHUSD_210625","side":"sell","seq":12455867,"price":2513.2,"qty":0.0,"timestamp":1618678118705}
1618678118.7325509: {"feed":"book","product_id":"FI_ETHUSD_210625","side":"sell","seq":12455868,"price":2513.2,"qty":34315.0,"timestamp":1618678118705}
1618678118.732585: {"feed":"book","product_id":"FI_ETHUSD_210625","side":"buy","seq":12455869,"price":2492.45,"qty":0.0,"timestamp":1618678118705}
1618678118.732615: {"feed":"book","product_id":"FI_ETHUSD_210625","side":"buy","seq":12455870,"price":2492.45,"qty":637.0,"timestamp":1618678118705}
1618678118.732641: {"feed":"book","product_id":"FI_XBTUSD_210430","side":"buy","seq":12237635,"price":59445.5,"qty":48172.0,"timestamp":1618678118708}
1618678118.7326632: {"feed":"book","product_id":"FI_ETHUSD_210625","side":"sell","seq":12455871,"price":2527.4,"qty":0.0,"timestamp":1618678118705}
1618678118.732689: {"feed":"book","product_id":"FI_ETHUSD_210625","side":"sell","seq":12455872,"price":2527.4,"qty":47825.0,"timestamp":1618678118705}
1618678118.7392: {"feed":"book","product_id":"PI_BCHUSD","side":"sell","seq":16259265,"price":1061.3,"qty":3414.0,"timestamp":1618678118713}
1618678118.747939: {"feed":"book","product_id":"FI_ETHUSD_210625","side":"sell","seq":12455873,"price":2505.8,"qty":0.0,"timestamp":1618678118722}
1618678118.759514: {"feed":"book","product_id":"PI_BCHUSD","side":"sell","seq":16259266,"price":1062.2,"qty":0.0,"timestamp":1618678118735}
1618678118.759639: {"feed":"book","product_id":"PI_BCHUSD","side":"sell","seq":16259267,"price":1062.1,"qty":42077.0,"timestamp":1618678118735}
1618678118.767133: {"feed":"book","product_id":"PI_BCHUSD","side":"buy","seq":16259268,"price":1057.6,"qty":19574.0,"timestamp":1618678118743}
1618678118.7747278: {"feed":"book","product_id":"FI_BCHUSD_210625","side":"buy","seq":2240264,"price":1126.9,"qty":96.0,"timestamp":1618678118751}
1618678118.774851: {"feed":"book","product_id":"FI_BCHUSD_210625","side":"buy","seq":2240265,"price":1127.4,"qty":0.0,"timestamp":1618678118751}
1618678118.774913: {"feed":"book","product_id":"FI_BCHUSD_210625","side":"buy","seq":2240266,"price":1128.0,"qty":0.0,"timestamp":1618678118751}
1618678118.774959: {"feed":"book","product_id":"FI_XBTUSD_210430","side":"buy","seq":12237636,"price":59445.5,"qty":48416.0,"timestamp":1618678118752}
1618678118.7798898: {"feed":"book","product_id":"FI_XRPUSD_210625","side":"buy","seq":3631670,"price":1.6916,"qty":0.0,"timestamp":1618678118756}
1618678118.783063: {"feed":"book","product_id":"FI_XRPUSD_210625","side":"buy","seq":3631671,"price":1.6921,"qty":0.0,"timestamp":1618678118758}
1618678118.783194: {"feed":"book","product_id":"FI_XRPUSD_210625","side":"buy","seq":3631672,"price":1.6917,"qty":68.0,"timestamp":1618678118758}
1618678118.786222: {"feed":"book","product_id":"FI_XRPUSD_210625","side":"sell","seq":3631673,"price":1.719,"qty":0.0,"timestamp":1618678118759}
1618678118.793971: {"feed":"book","product_id":"FI_XRPUSD_210625","side":"sell","seq":3631674,"price":1.6978,"qty":0.0,"timestamp":1618678118764}
1618678118.794102: {"feed":"book","product_id":"FI_XRPUSD_210625","side":"sell","seq":3631675,"price":1.6968,"qty":18968.0,"timestamp":1618678118764}
1618678118.794189: {"feed":"book","product_id":"FI_XRPUSD_210625","side":"buy","seq":3631676,"price":1.691,"qty":0.0,"timestamp":1618678118764}
1618678118.794223: {"feed":"book","product_id":"FI_XRPUSD_210625","side":"buy","seq":3631677,"price":1.69,"qty":19200.0,"timestamp":1618678118764}
1618678118.794251: {"feed":"book","product_id":"FI_XRPUSD_210625","side":"buy","seq":3631678,"price":1.6865,"qty":0.0,"timestamp":1618678118764}
1618678118.794278: {"feed":"book","product_id":"FI_XRPUSD_210625","side":"buy","seq":3631679,"price":1.6848,"qty":57600.0,"timestamp":1618678118764}
1618678118.794302: {"feed":"book","product_id":"FI_XRPUSD_210625","side":"sell","seq":3631680,"price":1.7096,"qty":0.0,"timestamp":1618678118764}
1618678118.794334: {"feed":"book","product_id":"FI_XRPUSD_210625","side":"sell","seq":3631681,"price":1.7073,"qty":172800.0,"timestamp":1618678118764}
1618678118.794359: {"feed":"book","product_id":"PI_BCHUSD","side":"sell","seq":16259269,"price":1061.6,"qty":0.0,"timestamp":1618678118767}
1618678118.7943869: {"feed":"book","product_id":"PI_BCHUSD","side":"buy","seq":16259270,"price":1057.0,"qty":9993.0,"timestamp":1618678118769}
1618678118.800338: {"feed":"book","product_id":"PI_BCHUSD","side":"buy","seq":16259271,"price":1057.9,"qty":0.0,"timestamp":1618678118770}
1618678118.8004649: {"feed":"book","product_id":"FI_XRPUSD_210625","side":"sell","seq":3631682,"price":1.7095,"qty":0.0,"timestamp":1618678118771}
1618678118.8109372: {"feed":"book","product_id":"PI_BCHUSD","side":"buy","seq":16259272,"price":1054.8,"qty":14641.0,"timestamp":1618678118784}
1618678118.816942: {"feed":"book","product_id":"FI_BCHUSD_210430","side":"buy","seq":1411913,"price":1072.1,"qty":0.0,"timestamp":1618678118793}
1618678118.8363268: {"feed":"book","product_id":"FI_XRPUSD_210625","side":"buy","seq":3631683,"price":1.6866,"qty":0.0,"timestamp":1618678118812}
1618678118.855406: {"feed":"book","product_id":"PI_BCHUSD","side":"sell","seq":16259273,"price":1061.2,"qty":2875.0,"timestamp":1618678118832}
1618678118.85973: {"feed":"book","product_id":"PI_BCHUSD","side":"sell","seq":16259274,"price":1062.3,"qty":0.0,"timestamp":1618678118835}
1618678118.859862: {"feed":"book","product_id":"PI_BCHUSD","side":"sell","seq":16259275,"price":1061.7,"qty":10107.0,"timestamp":1618678118835}
1618678118.8782551: {"feed":"book","product_id":"FI_XBTUSD_210625","side":"sell","seq":21455344,"price":64041.5,"qty":0.0,"timestamp":1618678118854}
1618678118.878387: {"feed":"book","product_id":"FI_XBTUSD_210625","side":"sell","seq":21455345,"price":64053.0,"qty":14725.0,"timestamp":1618678118854}
1618678118.878452: {"feed":"book","product_id":"FI_XBTUSD_210625","side":"buy","seq":21455346,"price":63881.0,"qty":2862.0,"timestamp":1618678118854}
1618678118.8784928: {"feed":"book","product_id":"FI_XBTUSD_210625","side":"buy","seq":21455347,"price":63879.0,"qty":1439.0,"timestamp":1618678118854}
1618678118.934755: {"feed":"book","product_id":"PI_BCHUSD","side":"buy","seq":16259276,"price":1057.8,"qty":7340.0,"timestamp":1618678118909}
1618678118.967058: {"feed":"book","product_id":"PI_BCHUSD","side":"buy","seq":16259277,"price":1057.4,"qty":19976.0,"timestamp":1618678118941}
1618678118.979349: {"feed":"book","product_id":"FI_XBTUSD_210430","side":"buy","seq":12237637,"price":59445.5,"qty":48172.0,"timestamp":1618678118955}
1618678118.982319: {"feed":"book","product_id":"PI_BCHUSD","side":"buy","seq":16259278,"price":1057.8,"qty":10835.0,"timestamp":1618678118959}
1618678119.0180259: {"feed":"book","product_id":"FI_XRPUSD_210625","side":"buy","seq":3631684,"price":1.6901,"qty":1838.0,"timestamp":1618678118994}
1618678119.023499: {"feed":"book","product_id":"PI_BCHUSD","side":"buy","seq":16259279,"price":1057.0,"qty":11215.0,"timestamp":1618678118998}
1618678119.02361: {"feed":"book","product_id":"FI_XBTUSD_210430","side":"buy","seq":12237638,"price":59445.5,"qty":52651.0,"timestamp":1618678118998}
1618678119.034409: {"feed":"book","product_id":"PI_BCHUSD","side":"sell","seq":16259280,"price":1060.6,"qty":2825.0,"timestamp":1618678119005}
1618678119.034496: {"feed":"book","product_id":"PI_BCHUSD","side":"sell","seq":16259281,"price":1060.6,"qty":5459.0,"timestamp":1618678119006}
1618678119.050045: {"feed":"book","product_id":"PI_BCHUSD","side":"sell","seq":16259282,"price":1062.1,"qty":31455.0,"timestamp":1618678119026}
1618678119.050113: {"feed":"book","product_id":"PI_BCHUSD","side":"sell","seq":16259283,"price":1062.0,"qty":41263.0,"timestamp":1618678119026}
1618678119.062145: {"feed":"book","product_id":"PI_BCHUSD","side":"sell","seq":16259284,"price":1060.6,"qty":2634.0,"timestamp":1618678119035}
1618678119.062308: {"feed":"book","product_id":"PI_BCHUSD","side":"sell","seq":16259285,"price":1060.6,"qty":0.0,"timestamp":1618678119035}
1618678119.06482: {"feed":"book","product_id":"PI_BCHUSD","side":"buy","seq":16259286,"price":1057.8,"qty":7283.0,"timestamp":1618678119037}
1618678119.088342: {"feed":"book","product_id":"FI_XBTUSD_210625","side":"buy","seq":21455348,"price":63879.0,"qty":0.0,"timestamp":1618678119060}
1618678119.088477: {"feed":"book","product_id":"FI_XBTUSD_210625","side":"buy","seq":21455349,"price":63866.0,"qty":1571.0,"timestamp":1618678119060}
1618678119.0885398: {"feed":"book","product_id":"FI_XBTUSD_210625","side":"sell","seq":21455350,"price":64053.0,"qty":0.0,"timestamp":1618678119060}
1618678119.088591: {"feed":"book","product_id":"FI_XBTUSD_210625","side":"sell","seq":21455351,"price":64041.5,"qty":12890.0,"timestamp":1618678119060}
1618678119.088634: {"feed":"book","product_id":"FI_XBTUSD_210625","side":"sell","seq":21455352,"price":64118.5,"qty":0.0,"timestamp":1618678119060}
1618678119.088675: {"feed":"book","product_id":"FI_XBTUSD_210625","side":"sell","seq":21455353,"price":64098.5,"qty":25458.0,"timestamp":1618678119060}
1618678119.1424599: {"feed":"book","product_id":"FI_BCHUSD_210430","side":"buy","seq":1411914,"price":950.1,"qty":4590.0,"timestamp":1618678119114}
1618678119.1425679: {"feed":"book","product_id":"FI_BCHUSD_210430","side":"buy","seq":1411915,"price":1065.3,"qty":14770.0,"timestamp":1618678119114}
1618678119.142634: {"feed":"book","product_id":"FI_BCHUSD_210430","side":"buy","seq":1411916,"price":950.1,"qty":0.0,"timestamp":1618678119114}
1618678119.142687: {"feed":"book","product_id":"FI_BCHUSD_210430","side":"buy","seq":1411917,"price":1065.3,"qty":19360.0,"timestamp":1618678119114}
1618678119.187649: {"feed":"book","product_id":"FI_ETHUSD_210924","side":"sell","seq":3859234,"price":2659.2,"qty":0.0,"timestamp":1618678119160}
1618678119.187739: {"feed":"book","product_id":"FI_ETHUSD_210924","side":"sell","seq":3859235,"price":2658.5,"qty":50.0,"timestamp":1618678119160}
1618678119.187795: {"feed":"book","product_id":"PI_BCHUSD","side":"buy","seq":16259287,"price":1057.8,"qty":3788.0,"timestamp":1618678119162}
1618678119.1941178: {"feed":"book","product_id":"FI_ETHUSD_210625","side":"sell","seq":12455874,"price":2503.8,"qty":0.0,"timestamp":1618678119169}
1618678119.1942441: {"feed":"book","product_id":"FI_ETHUSD_210625","side":"sell","seq":12455875,"price":2503.8,"qty":7216.0,"timestamp":1618678119169}
1618678119.197608: {"feed":"book","product_id":"FI_ETHUSD_210625","side":"sell","seq":12455876,"price":2505.45,"qty":0.0,"timestamp":1618678119169}
1618678119.197736: {"feed":"book","product_id":"FI_ETHUSD_210625","side":"sell","seq":12455877,"price":2505.45,"qty":12239.0,"timestamp":1618678119169}
1618678119.197802: {"feed":"book","product_id":"FI_ETHUSD_210625","side":"sell","seq":12455878,"price":2507.0,"qty":0.0,"timestamp":1618678119170}
1618678119.19786: {"feed":"book","product_id":"FI_ETHUSD_210625","side":"sell","seq":12455879,"price":2507.0,"qty":16541.0,"timestamp":1618678119170}
1618678119.19791: {"feed":"book","product_id":"FI_ETHUSD_210625","side":"sell","seq":12455880,"price":2513.2,"qty":0.0,"timestamp":1618678119170}
1618678119.197937: {"feed":"book","product_id":"FI_ETHUSD_210625","side":"sell","seq":12455881,"price":2513.2,"qty":34324.0,"timestamp":1618678119170}
1618678119.1979892: {"feed":"book","product_id":"FI_ETHUSD_210924","side":"sell","seq":3859236,"price":2658.6,"qty":19561.0,"timestamp":1618678119173}
1618678119.1980119: {"feed":"book","product_id":"FI_ETHUSD_210924","side":"sell","seq":3859237,"price":2658.45,"qty":840.0,"timestamp":1618678119173}
1618678119.203845: {"feed":"book","product_id":"FI_XBTUSD_210430","side":"buy","seq":12237639,"price":59445.5,"qty":48172.0,"timestamp":1618678119182}
1618678119.2180722: {"feed":"book","product_id":"PI_BCHUSD","side":"sell","seq":16259288,"price":1062.0,"qty":30641.0,"timestamp":1618678119193}
1618678119.222456: {"feed":"book","product_id":"PI_BCHUSD","side":"buy","seq":16259289,"price":1057.4,"qty":0.0,"timestamp":1618678119197}
1618678119.222584: {"feed":"book","product_id":"PI_BCHUSD","side":"sell","seq":16259290,"price":1061.3,"qty":0.0,"timestamp":1618678119197}
1618678119.231976: {"feed":"book","product_id":"PI_BCHUSD","side":"sell","seq":16259291,"price":1061.6,"qty":15664.0,"timestamp":1618678119205}
1618678119.232063: {"feed":"book","product_id":"FI_ETHUSD_210924","side":"sell","seq":3859238,"price":2658.5,"qty":0.0,"timestamp":1618678119205}
1618678119.232125: {"feed":"book","product_id":"FI_ETHUSD_210924","side":"sell","seq":3859239,"price":2658.4,"qty":50.0,"timestamp":1618678119205}
1618678119.249302: {"feed":"book","product_id":"FI_ETHUSD_210924","side":"sell","seq":3859240,"price":2658.45,"qty":0.0,"timestamp":1618678119218}
1618678119.249391: {"feed":"book","product_id":"FI_ETHUSD_210924","side":"sell","seq":3859241,"price":2658.35,"qty":840.0,"timestamp":1618678119218}
1618678119.2494562: {"feed":"book","product_id":"PI_BCHUSD","side":"sell","seq":16259292,"price":1061.6,"qty":35632.0,"timestamp":1618678119219}
1618678119.255738: {"feed":"book","product_id":"FI_XBTUSD_210430","side":"buy","seq":12237640,"price":59445.5,"qty":48416.0,"timestamp":1618678119231}
1618678119.269939: {"feed":"book","product_id":"FI_ETHUSD_210924","side":"sell","seq":3859242,"price":2658.4,"qty":0.0,"timestamp":1618678119238}
1618678119.270027: {"feed":"book","product_id":"FI_ETHUSD_210924","side":"sell","seq":3859243,"price":2658.3,"qty":50.0,"timestamp":1618678119238}
1618678119.2715971: {"feed":"book","product_id":"FI_ETHUSD_210924","side":"sell","seq":3859244,"price":2658.35,"qty":0.0,"timestamp":1618678119246}
1618678119.271687: {"feed":"book","product_id":"FI_ETHUSD_210924","side":"sell","seq":3859245,"price":2658.25,"qty":840.0,"timestamp":1618678119246}
1618678119.300231: {"feed":"book","product_id":"FI_ETHUSD_210924","side":"sell","seq":3859246,"price":2658.3,"qty":0.0,"timestamp":1618678119275}
1618678119.300292: {"feed":"book","product_id":"FI_ETHUSD_210924","side":"sell","seq":3859247,"price":2658.2,"qty":50.0,"timestamp":1618678119275}
1618678119.3086221: {"feed":"book","product_id":"FI_ETHUSD_210924","side":"sell","seq":3859248,"price":2658.25,"qty":0.0,"timestamp":1618678119283}
1618678119.308713: {"feed":"book","product_id":"FI_ETHUSD_210924","side":"sell","seq":3859249,"price":2658.15,"qty":840.0,"timestamp":1618678119283}
1618678119.315032: {"feed":"book","product_id":"PI_BCHUSD","side":"buy","seq":16259293,"price":1057.3,"qty":6337.0,"timestamp":1618678119291}
1618678119.325085: {"feed":"book","product_id":"PI_BCHUSD","side":"sell","seq":16259294,"price":1061.0,"qty":3707.0,"timestamp":1618678119301}
1618678119.338284: {"feed":"book","product_id":"FI_ETHUSD_210924","side":"sell","seq":3859250,"price":2658.2,"qty":0.0,"timestamp":1618678119309}
1618678119.338372: {"feed":"book","product_id":"FI_ETHUSD_210924","side":"sell","seq":3859251,"price":2658.1,"qty":50.0,"timestamp":1618678119309}
1618678119.349678: {"feed":"book","product_id":"FI_ETHUSD_210924","side":"sell","seq":3859252,"price":2658.15,"qty":0.0,"timestamp":1618678119316}
1618678119.3497689: {"feed":"book","product_id":"FI_ETHUSD_210924","side":"sell","seq":3859253,"price":2658.05,"qty":840.0,"timestamp":1618678119316}
1618678119.349828: {"feed":"book","product_id":"FI_ETHUSD_210924","side":"sell","seq":3859254,"price":2658.05,"qty":1140.0,"timestamp":1618678119320}
1618678119.349865: {"feed":"book","product_id":"FI_ETHUSD_210924","side":"sell","seq":3859255,"price":2662.2,"qty":0.0,"timestamp":1618678119320}
1618678119.3576682: {"feed":"book","product_id":"PI_BCHUSD","side":"sell","seq":16259295,"price":1061.0,"qty":952.0,"timestamp":1618678119333}
1618678119.362881: {"feed":"book","product_id":"PI_BCHUSD","side":"sell","seq":16259296,"price":1061.7,"qty":13773.0,"timestamp":1618678119339}
1618678119.370661: {"feed":"book","product_id":"FI_ETHUSD_210924","side":"sell","seq":3859256,"price":2658.1,"qty":0.0,"timestamp":1618678119343}
1618678119.370749: {"feed":"book","product_id":"FI_ETHUSD_210924","side":"sell","seq":3859257,"price":2658.0,"qty":50.0,"timestamp":1618678119343}
1618678119.374222: {"feed":"book","product_id":"FI_ETHUSD_210924","side":"sell","seq":3859258,"price":2658.05,"qty":300.0,"timestamp":1618678119348}
1618678119.374291: {"feed":"book","product_id":"FI_ETHUSD_210924","side":"sell","seq":3859259,"price":2657.95,"qty":840.0,"timestamp":1618678119348}
1618678119.382765: {"feed":"book","product_id":"FI_BCHUSD_210625","side":"buy","seq":2240267,"price":1127.4,"qty":62.0,"timestamp":1618678119359}
1618678119.46835: {"feed":"book","product_id":"FI_ETHUSD_210625","side":"sell","seq":12455882,"price":2503.8,"qty":0.0,"timestamp":1618678119430}
1618678119.468477: {"feed":"book","product_id":"FI_ETHUSD_210625","side":"sell","seq":12455883,"price":2503.55,"qty":7223.0,"timestamp":1618678119430}
1618678119.47488: {"feed":"book","product_id":"PI_BCHUSD","side":"buy","seq":16259297,"price":1057.6,"qty":3602.0,"timestamp":1618678119430}
1618678119.474989: {"feed":"book","product_id":"PI_BCHUSD","side":"sell","seq":16259298,"price":1061.7,"qty":9810.0,"timestamp":1618678119430}
1618678119.475036: {"feed":"book","product_id":"FI_XBTUSD_210430","side":"buy","seq":12237641,"price":61071.5,"qty":0.0,"timestamp":1618678119430}
1618678119.515337: {"feed":"book","product_id":"FI_XBTUSD_210625","side":"sell","seq":21455354,"price":64249.0,"qty":0.0,"timestamp":1618678119490}
1618678119.515466: {"feed":"book","product_id":"FI_XBTUSD_210625","side":"sell","seq":21455355,"price":64248.0,"qty":57268.0,"timestamp":1618678119490}
1618678119.515529: {"feed":"book","product_id":"FI_XBTUSD_210625","side":"sell","seq":21455356,"price":64080.0,"qty":0.0,"timestamp":1618678119490}
1618678119.51558: {"feed":"book","product_id":"FI_XBTUSD_210625","side":"sell","seq":21455357,"price":64080.0,"qty":20600.0,"timestamp":1618678119490}
1618678119.5191529: {"feed":"book","product_id":"FI_XBTUSD_210625","side":"buy","seq":21455358,"price":63728.0,"qty":0.0,"timestamp":1618678119490}
1618678119.5192802: {"feed":"book","product_id":"FI_XBTUSD_210625","side":"buy","seq":21455359,"price":63728.0,"qty":3179.0,"timestamp":1618678119490}
1618678119.5193431: {"feed":"book","product_id":"FI_XBTUSD_210625","side":"buy","seq":21455360,"price":63489.0,"qty":0.0,"timestamp":1618678119490}
1618678119.519392: {"feed":"book","product_id":"FI_XBTUSD_210625","side":"buy","seq":21455361,"price":63489.0,"qty":4212.0,"timestamp":1618678119490}
1618678119.522764: {"feed":"book","product_id":"FI_XBTUSD_210625","side":"buy","seq":21455362,"price":63881.0,"qty":1431.0,"timestamp":1618678119490}
1618678119.5228732: {"feed":"book","product_id":"FI_XBTUSD_210625","side":"buy","seq":21455363,"price":63881.0,"qty":2809.0,"timestamp":1618678119490}
1618678119.5229208: {"feed":"book","product_id":"FI_XBTUSD_210625","side":"buy","seq":21455364,"price":63881.0,"qty":1378.0,"timestamp":1618678119490}
1618678119.522957: {"feed":"book","product_id":"FI_XBTUSD_210625","side":"buy","seq":21455365,"price":63881.0,"qty":2756.0,"timestamp":1618678119490}
1618678119.52299: {"feed":"book","product_id":"FI_XBTUSD_210625","side":"sell","seq":21455366,"price":64529.5,"qty":0.0,"timestamp":1618678119490}
1618678119.5230458: {"feed":"book","product_id":"FI_XBTUSD_210625","side":"sell","seq":21455367,"price":64529.5,"qty":76446.0,"timestamp":1618678119490}
1618678119.548147: {"feed":"book","product_id":"PI_BCHUSD","side":"sell","seq":16259299,"price":1062.4,"qty":10624.0,"timestamp":1618678119522}
1618678119.559444: {"feed":"book","product_id":"FI_XBTUSD_210430","side":"buy","seq":12237642,"price":59445.5,"qty":52895.0,"timestamp":1618678119535}
1618678119.629886: {"feed":"book","product_id":"FI_ETHUSD_210625","side":"sell","seq":12455884,"price":2505.8,"qty":3000.0,"timestamp":1618678119606}
1618678119.634059: {"feed":"book","product_id":"PI_BCHUSD","side":"sell","seq":16259300,"price":1061.6,"qty":19968.0,"timestamp":1618678119607}
1618678119.634169: {"feed":"book","product_id":"PI_BCHUSD","side":"sell","seq":16259301,"price":1061.7,"qty":6144.0,"timestamp":1618678119607}
1618678119.657364: {"feed":"book","product_id":"FI_ETHUSD_210625","side":"sell","seq":12455885,"price":2503.55,"qty":0.0,"timestamp":1618678119633}
1618678119.6574929: {"feed":"book","product_id":"FI_ETHUSD_210625","side":"sell","seq":12455886,"price":2503.8,"qty":7200.0,"timestamp":1618678119633}
1618678119.657558: {"feed":"book","product_id":"FI_ETHUSD_210625","side":"sell","seq":12455887,"price":2505.45,"qty":0.0,"timestamp":1618678119633}
1618678119.657608: {"feed":"book","product_id":"FI_ETHUSD_210625","side":"sell","seq":12455888,"price":2505.45,"qty":12225.0,"timestamp":1618678119633}
1618678119.658096: {"feed":"book","product_id":"FI_ETHUSD_210625","side":"sell","seq":12455889,"price":2507.0,"qty":0.0,"timestamp":1618678119633}
1618678119.658147: {"feed":"book","product_id":"FI_ETHUSD_210625","side":"sell","seq":12455890,"price":2507.0,"qty":16525.0,"timestamp":1618678119633}
1618678119.658179: {"feed":"book","product_id":"FI_ETHUSD_210625","side":"sell","seq":12455891,"price":2513.2,"qty":0.0,"timestamp":1618678119633}
1618678119.658207: {"feed":"book","product_id":"FI_ETHUSD_210625","side":"sell","seq":12455892,"price":2513.2,"qty":34315.0,"timestamp":1618678119633}
1618678119.696589: {"feed":"book","product_id":"FI_XBTUSD_210430","side":"sell","seq":12237643,"price":61941.0,"qty":0.0,"timestamp":1618678119672}
1618678119.696713: {"feed":"book","product_id":"FI_XBTUSD_210430","side":"buy","seq":12237644,"price":60662.5,"qty":0.0,"timestamp":1618678119672}
1618678119.700531: {"feed":"book","product_id":"PI_BCHUSD","side":"sell","seq":16259302,"price":1060.7,"qty":3820.0,"timestamp":1618678119675}
1618678119.7143528: {"feed":"book","product_id":"FI_ETHUSD_210430","side":"sell","seq":4780926,"price":2400.85,"qty":0.0,"timestamp":1618678119690}
1618678119.723509: {"feed":"book","product_id":"FI_ETHUSD_210430","side":"sell","seq":4780927,"price":2393.3,"qty":0.0,"timestamp":1618678119698}
1618678119.723638: {"feed":"book","product_id":"FI_ETHUSD_210430","side":"sell","seq":4780928,"price":2392.25,"qty":578.0,"timestamp":1618678119698}
1618678119.7237: {"feed":"book","product_id":"FI_XBTUSD_210625","side":"sell","seq":21455368,"price":64098.5,"qty":0.0,"timestamp":1618678119698}
1618678119.723752: {"feed":"book","product_id":"FI_XBTUSD_210625","side":"sell","seq":21455369,"price":64118.5,"qty":29814.0,"timestamp":1618678119698}
1618678119.723796: {"feed":"book","product_id":"FI_XBTUSD_210625","side":"buy","seq":21455370,"price":63866.0,"qty":0.0,"timestamp":1618678119698}
1618678119.723855: {"feed":"book","product_id":"FI_XBTUSD_210625","side":"buy","seq":21455371,"price":63879.0,"qty":1433.0,"timestamp":1618678119698}
1618678119.742045: {"feed":"book","product_id":"FI_ETHUSD_210625","side":"sell","seq":12455893,"price":2505.65,"qty":0.0,"timestamp":1618678119706}
1618678119.742172: {"feed":"book","product_id":"FI_ETHUSD_210625","side":"sell","seq":12455894,"price":2504.6,"qty":441.0,"timestamp":1618678119706}
1618678119.742249: {"feed":"book","product_id":"FI_ETHUSD_210924","side":"sell","seq":3859260,"price":2682.5,"qty":0.0,"timestamp":1618678119706}
1618678119.742302: {"feed":"book","product_id":"FI_ETHUSD_210924","side":"sell","seq":3859261,"price":2669.1,"qty":0.0,"timestamp":1618678119706}
1618678119.7423449: {"feed":"book","product_id":"FI_ETHUSD_210924","side":"sell","seq":3859262,"price":2668.0,"qty":219.0,"timestamp":1618678119706}
1618678119.7423859: {"feed":"book","product_id":"PI_BCHUSD","side":"sell","seq":16259303,"price":1061.3,"qty":3665.0,"timestamp":1618678119713}
1618678119.7539551: {"feed":"book","product_id":"FI_ETHUSD_210430","side":"sell","seq":4780929,"price":2391.5,"qty":19199.0,"timestamp":1618678119726}
1618678119.754081: {"feed":"book","product_id":"PI_BCHUSD","side":"buy","seq":16259304,"price":1055.5,"qty":14399.0,"timestamp":1618678119730}
1618678119.7541409: {"feed":"book","product_id":"FI_XBTUSD_210430","side":"buy","seq":12237645,"price":59445.5,"qty":52651.0,"timestamp":1618678119731}
1618678119.758167: {"feed":"book","product_id":"FI_XBTUSD_210430","side":"buy","seq":12237646,"price":61077.5,"qty":23999.0,"timestamp":1618678119733}
1618678119.766647: {"feed":"book","product_id":"PI_BCHUSD","side":"buy","seq":16259305,"price":1057.5,"qty":15673.0,"timestamp":1618678119743}
1618678119.7730749: {"feed":"book","product_id":"FI_XBTUSD_210924","side":"sell","seq":13850989,"price":68271.0,"qty":3000.0,"timestamp":1618678119748}
1618678119.77896: {"feed":"book","product_id":"FI_XBTUSD_210924","side":"sell","seq":13850990,"price":68277.0,"qty":0.0,"timestamp":1618678119755}
1618678119.779087: {"feed":"book","product_id":"FI_XBTUSD_210924","side":"sell","seq":13850991,"price":68270.5,"qty":10000.0,"timestamp":1618678119755}
1618678119.849375: {"feed":"book","product_id":"FI_ETHUSD_210430","side":"buy","seq":4780930,"price":2382.4,"qty":19199.0,"timestamp":1618678119818}
1618678119.858755: {"feed":"book","product_id":"PI_BCHUSD","side":"sell","seq":16259306,"price":1061.9,"qty":3608.0,"timestamp":1618678119833}
1618678119.88968: {"feed":"book","product_id":"FI_ETHUSD_210430","side":"sell","seq":4780931,"price":2405.25,"qty":0.0,"timestamp":1618678119866}
1618678119.8984692: {"feed":"book","product_id":"FI_XBTUSD_210625","side":"sell","seq":21455372,"price":64080.5,"qty":0.0,"timestamp":1618678119872}
1618678119.8986082: {"feed":"book","product_id":"FI_XBTUSD_210625","side":"sell","seq":21455373,"price":64079.5,"qty":250001.0,"timestamp":1618678119872}
1618678119.8986702: {"feed":"book","product_id":"FI_ETHUSD_210430","side":"sell","seq":4780932,"price":2405.2,"qty":0.0,"timestamp":1618678119872}
1618678119.89872: {"feed":"book","product_id":"FI_ETHUSD_210430","side":"sell","seq":4780933,"price":2408.3,"qty":25003.0,"timestamp":1618678119872}
1618678119.898761: {"feed":"book","product_id":"FI_XBTUSD_210625","side":"sell","seq":21455374,"price":64248.5,"qty":0.0,"timestamp":1618678119872}
1618678119.8988008: {"feed":"book","product_id":"FI_XBTUSD_210625","side":"sell","seq":21455375,"price":64247.5,"qty":125003.0,"timestamp":1618678119872}
1618678119.91215: {"feed":"book","product_id":"FI_XBTUSD_210430","side":"buy","seq":12237647,"price":59445.5,"qty":52895.0,"timestamp":1618678119888}
1618678119.9200242: {"feed":"book","product_id":"FI_BCHUSD_210625","side":"buy","seq":2240268,"price":1128.5,"qty":50.0,"timestamp":1618678119896}
1618678119.920146: {"feed":"book","product_id":"PI_BCHUSD","side":"sell","seq":16259307,"price":1061.5,"qty":3738.0,"timestamp":1618678119897}
1618678119.920531: {"feed":"book","product_id":"PI_BCHUSD","side":"buy","seq":16259308,"price":1058.1,"qty":8728.0,"timestamp":1618678119898}
1618678119.923111: {"feed":"book","product_id":"PI_BCHUSD","side":"buy","seq":16259309,"price":1057.8,"qty":7507.0,"timestamp":1618678119899}
1618678119.92319: {"feed":"book","product_id":"FI_BCHUSD_210625","side":"buy","seq":2240269,"price":1127.4,"qty":0.0,"timestamp":1618678119899}
1618678119.925168: {"feed":"book","product_id":"PI_BCHUSD","side":"sell","seq":16259310,"price":1061.2,"qty":6427.0,"timestamp":1618678119900}
1618678119.929715: {"feed":"book","product_id":"FI_XBTUSD_210625","side":"buy","seq":21455376,"price":63879.0,"qty":0.0,"timestamp":1618678119903}
1618678119.929847: {"feed":"book","product_id":"FI_XBTUSD_210625","side":"buy","seq":21455377,"price":63866.0,"qty":1570.0,"timestamp":1618678119903}
1618678119.939394: {"feed":"book","product_id":"PI_BCHUSD","side":"buy","seq":16259311,"price":1057.9,"qty":3418.0,"timestamp":1618678119909}
1618678119.94366: {"feed":"book","product_id":"FI_XRPUSD_210625","side":"buy","seq":3631685,"price":1.6934,"qty":0.0,"timestamp":1618678119918}
1618678119.95213: {"feed":"book","product_id":"PI_BCHUSD","side":"sell","seq":16259312,"price":1062.4,"qty":0.0,"timestamp":1618678119928}
1618678119.952259: {"feed":"book","product_id":"PI_BCHUSD","side":"sell","seq":16259313,"price":1061.9,"qty":14232.0,"timestamp":1618678119928}
1618678119.9553092: {"feed":"book","product_id":"PI_BCHUSD","side":"sell","seq":16259314,"price":1061.9,"qty":3608.0,"timestamp":1618678119931}
1618678119.95542: {"feed":"book","product_id":"PI_BCHUSD","side":"sell","seq":16259315,"price":1061.8,"qty":14253.0,"timestamp":1618678119931}
1618678119.961674: {"feed":"book","product_id":"PI_BCHUSD","side":"sell","seq":16259316,"price":1061.8,"qty":3629.0,"timestamp":1618678119937}
1618678119.964086: {"feed":"book","product_id":"PI_BCHUSD","side":"buy","seq":16259317,"price":1057.4,"qty":20704.0,"timestamp":1618678119940}
1618678119.968148: {"feed":"book","product_id":"FI_ETHUSD_210625","side":"sell","seq":12455895,"price":2503.8,"qty":0.0,"timestamp":1618678119943}
1618678119.968286: {"feed":"book","product_id":"FI_ETHUSD_210625","side":"sell","seq":12455896,"price":2503.55,"qty":7338.0,"timestamp":1618678119943}
1618678119.968747: {"feed":"book","product_id":"FI_ETHUSD_210625","side":"sell","seq":12455897,"price":2507.0,"qty":0.0,"timestamp":1618678119943}
1618678119.968812: {"feed":"book","product_id":"FI_ETHUSD_210625","side":"sell","seq":12455898,"price":2506.5,"qty":15871.0,"timestamp":1618678119943}
1618678119.9690921: {"feed":"book","product_id":"PI_BCHUSD","side":"buy","seq":16259318,"price":1057.3,"qty":5014.0,"timestamp":1618678119945}
1618678119.976732: {"feed":"book","product_id":"PI_BCHUSD","side":"sell","seq":16259319,"price":1061.6,"qty":0.0,"timestamp":1618678119951}
1618678119.981001: {"feed":"book","product_id":"PI_BCHUSD","side":"buy","seq":16259320,"price":1057.8,"qty":11038.0,"timestamp":1618678119958}
1618678120.030771: {"feed":"book","product_id":"PI_BCHUSD","side":"sell","seq":16259321,"price":1060.5,"qty":2902.0,"timestamp":1618678120005}
1618678120.030858: {"feed":"book","product_id":"PI_BCHUSD","side":"sell","seq":16259322,"price":1060.5,"qty":5446.0,"timestamp":1618678120006}
1618678120.041968: {"feed":"book","product_id":"PI_BCHUSD","side":"buy","seq":16259323,"price":1056.4,"qty":0.0,"timestamp":1618678120018}
1618678120.061242: {"feed":"book","product_id":"PI_BCHUSD","side":"buy","seq":16259324,"price":1056.3,"qty":42662.0,"timestamp":1618678120038}
1618678120.072722: {"feed":"book","product_id":"PI_BCHUSD","side":"sell","seq":16259325,"price":1062.5,"qty":27509.0,"timestamp":1618678120048}
1618678120.072835: {"feed":"book","product_id":"PI_BCHUSD","side":"sell","seq":16259326,"price":1061.7,"qty":1151.0,"timestamp":1618678120049}
1618678120.072883: {"feed":"book","product_id":"PI_BCHUSD","side":"sell","seq":16259327,"price":1061.9,"qty":8598.0,"timestamp":1618678120049}
1618678120.075812: {"feed":"book","product_id":"PI_BCHUSD","side":"sell","seq":16259328,"price":1061.1,"qty":5044.0,"timestamp":1618678120049}
1618678120.075891: {"feed":"book","product_id":"PI_BCHUSD","side":"sell","seq":16259329,"price":1061.5,"qty":8730.0,"timestamp":1618678120049}
1618678120.075922: {"feed":"book","product_id":"PI_BCHUSD","side":"sell","seq":16259330,"price":1062.1,"qty":26464.0,"timestamp":1618678120049}
1618678120.1345458: {"feed":"book","product_id":"FI_XBTUSD_210625","side":"sell","seq":21455378,"price":64118.5,"qty":0.0,"timestamp":1618678120109}
1618678120.134675: {"feed":"book","product_id":"FI_XBTUSD_210625","side":"sell","seq":21455379,"price":64098.5,"qty":25486.0,"timestamp":1618678120109}
1618678120.1377332: {"feed":"book","product_id":"FI_ETHUSD_210625","side":"sell","seq":12455899,"price":2505.8,"qty":0.0,"timestamp":1618678120114}
1618678120.149972: {"feed":"book","product_id":"PI_BCHUSD","side":"sell","seq":16259331,"price":1060.5,"qty":2544.0,"timestamp":1618678120124}
1618678120.150136: {"feed":"book","product_id":"PI_BCHUSD","side":"sell","seq":16259332,"price":1060.5,"qty":0.0,"timestamp":1618678120124}
1618678120.150202: {"feed":"book","product_id":"FI_XBTUSD_210430","side":"buy","seq":12237648,"price":59445.5,"qty":52651.0,"timestamp":1618678120124}
1618678120.151534: {"feed":"book","product_id":"PI_BCHUSD","side":"buy","seq":16259333,"price":1057.0,"qty":9993.0,"timestamp":1618678120128}
1618678120.177071: {"feed":"book","product_id":"FI_ETHUSD_210625","side":"sell","seq":12455900,"price":2503.55,"qty":0.0,"timestamp":1618678120152}
1618678120.1771631: {"feed":"book","product_id":"FI_ETHUSD_210625","side":"sell","seq":12455901,"price":2503.8,"qty":7458.0,"timestamp":1618678120152}
1618678120.177203: {"feed":"book","product_id":"FI_ETHUSD_210625","side":"sell","seq":12455902,"price":2506.5,"qty":0.0,"timestamp":1618678120152}
1618678120.177233: {"feed":"book","product_id":"FI_ETHUSD_210625","side":"sell","seq":12455903,"price":2507.0,"qty":16784.0,"timestamp":1618678120152}
1618678120.2214222: {"feed":"book","product_id":"PI_BCHUSD","side":"buy","seq":16259334,"price":1057.5,"qty":0.0,"timestamp":1618678120196}
1618678120.2215528: {"feed":"book","product_id":"PI_BCHUSD","side":"sell","seq":16259335,"price":1062.9,"qty":3668.0,"timestamp":1618678120196}
1618678120.221608: {"feed":"book","product_id":"PI_BCHUSD","side":"buy","seq":16259336,"price":1057.8,"qty":7250.0,"timestamp":1618678120196}
1618678120.221648: {"feed":"book","product_id":"PI_BCHUSD","side":"buy","seq":16259337,"price":1057.9,"qty":0.0,"timestamp":1618678120196}
1618678120.2216918: {"feed":"book","product_id":"PI_BCHUSD","side":"sell","seq":16259338,"price":1062.0,"qty":58041.0,"timestamp":1618678120197}
1618678120.221726: {"feed":"book","product_id":"PI_BCHUSD","side":"buy","seq":16259339,"price":1057.2,"qty":30783.0,"timestamp":1618678120198}
1618678120.2325919: {"feed":"book","product_id":"PI_BCHUSD","side":"sell","seq":16259340,"price":1061.0,"qty":16610.0,"timestamp":1618678120202}
1618678120.242191: {"feed":"book","product_id":"FI_ETHUSD_210625","side":"sell","seq":12455904,"price":2519.0,"qty":0.0,"timestamp":1618678120217}
1618678120.24233: {"feed":"book","product_id":"FI_XBTUSD_210430","side":"buy","seq":12237649,"price":61124.5,"qty":2715.0,"timestamp":1618678120217}
1618678120.24281: {"feed":"book","product_id":"PI_BCHUSD","side":"sell","seq":16259341,"price":1061.0,"qty":36382.0,"timestamp":1618678120220}
1618678120.261597: {"feed":"book","product_id":"FI_BCHUSD_210625","side":"sell","seq":2240270,"price":1142.9,"qty":0.0,"timestamp":1618678120236}
1618678120.261722: {"feed":"book","product_id":"FI_BCHUSD_210625","side":"sell","seq":2240271,"price":1138.8,"qty":18912.0,"timestamp":1618678120236}
1618678120.278541: {"feed":"book","product_id":"FI_ETHUSD_210430","side":"buy","seq":4780934,"price":2383.45,"qty":1706.0,"timestamp":1618678120250}
1618678120.286176: {"feed":"book","product_id":"PI_BCHUSD","side":"buy","seq":16259342,"price":1057.0,"qty":11133.0,"timestamp":1618678120261}
1618678120.320968: {"feed":"book","product_id":"FI_XBTUSD_210430","side":"buy","seq":12237650,"price":59445.5,"qty":52895.0,"timestamp":1618678120298}
1618678120.328892: {"feed":"book","product_id":"PI_BCHUSD","side":"sell","seq":16259343,"price":1060.3,"qty":2816.0,"timestamp":1618678120301}
1618678120.3290172: {"feed":"book","product_id":"PI_BCHUSD","side":"sell","seq":16259344,"price":1061.7,"qty":0.0,"timestamp":1618678120305}
1618678120.336558: {"feed":"book","product_id":"PI_BCHUSD","side":"sell","seq":16259345,"price":1060.3,"qty":4132.0,"timestamp":1618678120306}
1618678120.3493: {"feed":"book","product_id":"PI_BCHUSD","side":"buy","seq":16259346,"price":1056.3,"qty":36635.0,"timestamp":1618678120326}
1618678120.3541918: {"feed":"book","product_id":"FI_ETHUSD_210625","side":"sell","seq":12455905,"price":2513.45,"qty":38399.0,"timestamp":1618678120329}
1618678120.3636448: {"feed":"book","product_id":"PI_BCHUSD","side":"sell","seq":16259347,"price":1061.0,"qty":40132.0,"timestamp":1618678120339}
1618678120.409527: {"feed":"book","product_id":"FI_BCHUSD_210625","side":"sell","seq":2240272,"price":1138.8,"qty":14399.0,"timestamp":1618678120385}
1618678120.409638: {"feed":"book","product_id":"FI_BCHUSD_210625","side":"sell","seq":2240273,"price":1142.9,"qty":4513.0,"timestamp":1618678120385}
1618678120.411606: {"feed":"book","product_id":"FI_BCHUSD_210625","side":"sell","seq":2240274,"price":1142.9,"qty":49512.0,"timestamp":1618678120387}
1618678120.420745: {"feed":"book","product_id":"PI_BCHUSD","side":"sell","seq":16259348,"price":1060.3,"qty":1316.0,"timestamp":1618678120396}
1618678120.448549: {"feed":"book","product_id":"FI_XBTUSD_210430","side":"buy","seq":12237651,"price":61066.5,"qty":25718.0,"timestamp":1618678120422}
1618678120.478899: {"feed":"book","product_id":"FI_XBTUSD_210924","side":"buy","seq":13850992,"price":68049.0,"qty":0.0,"timestamp":1618678120455}
1618678120.54069: {"feed":"book","product_id":"PI_BCHUSD","side":"sell","seq":16259349,"price":1061.0,"qty":24474.0,"timestamp":1618678120514}
1618678120.5482082: {"feed":"book","product_id":"PI_BCHUSD","side":"sell","seq":16259350,"price":1061.0,"qty":20724.0,"timestamp":1618678120516}
1618678120.5483189: {"feed":"book","product_id":"FI_XBTUSD_210924","side":"buy","seq":13850993,"price":68144.0,"qty":3361.0,"timestamp":1618678120516}
1618678120.5483892: {"feed":"book","product_id":"PI_BCHUSD","side":"sell","seq":16259351,"price":1068.7,"qty":44999.0,"timestamp":1618678120516}
1618678120.548438: {"feed":"book","product_id":"FI_XBTUSD_210625","side":"buy","seq":21455380,"price":63831.5,"qty":5375.0,"timestamp":1618678120516}
1618678120.548491: {"feed":"book","product_id":"FI_XBTUSD_210430","side":"buy","seq":12237652,"price":59445.5,"qty":52651.0,"timestamp":1618678120516}
1618678120.548532: {"feed":"book","product_id":"FI_XBTUSD_210430","side":"buy","seq":12237653,"price":60659.5,"qty":500.0,"timestamp":1618678120516}
1618678120.548556: {"feed":"book","product_id":"FI_XBTUSD_210430","side":"sell","seq":12237654,"price":61941.0,"qty":500.0,"timestamp":1618678120516}
1618678120.5485811: {"feed":"book","product_id":"FI_XBTUSD_210625","side":"sell","seq":21455381,"price":64080.0,"qty":0.0,"timestamp":1618678120516}
1618678120.548613: {"feed":"book","product_id":"FI_XBTUSD_210625","side":"sell","seq":21455382,"price":64079.0,"qty":20402.0,"timestamp":1618678120516}
1618678120.556915: {"feed":"book","product_id":"FI_XRPUSD_210625","side":"buy","seq":3631686,"price":1.6918,"qty":50.0,"timestamp":1618678120530}
1618678120.605658: {"feed":"book","product_id":"FI_ETHUSD_210625","side":"sell","seq":12455906,"price":2505.45,"qty":0.0,"timestamp":1618678120563}
1618678120.605747: {"feed":"book","product_id":"FI_ETHUSD_210625","side":"sell","seq":12455907,"price":2505.45,"qty":12513.0,"timestamp":1618678120563}
1618678120.605789: {"feed":"book","product_id":"FI_XRPUSD_210625","side":"buy","seq":3631687,"price":1.6917,"qty":0.0,"timestamp":1618678120563}
1618678120.605823: {"feed":"book","product_id":"FI_XRPUSD_210625","side":"buy","seq":3631688,"price":1.6919,"qty":68.0,"timestamp":1618678120563}
1618678120.605851: {"feed":"book","product_id":"FI_BCHUSD_210625","side":"sell","seq":2240275,"price":1142.9,"qty":44999.0,"timestamp":1618678120563}
1618678120.6058738: {"feed":"book","product_id":"FI_BCHUSD_210625","side":"sell","seq":2240276,"price":1138.8,"qty":18912.0,"timestamp":1618678120563}
1618678120.6058948: {"feed":"book","product_id":"FI_ETHUSD_210625","side":"buy","seq":12455908,"price":2499.35,"qty":248.0,"timestamp":1618678120563}
1618678120.6059158: {"feed":"book","product_id":"FI_ETHUSD_210625","side":"buy","seq":12455909,"price":2499.35,"qty":493.0,"timestamp":1618678120563}
1618678120.605936: {"feed":"book","product_id":"FI_ETHUSD_210625","side":"buy","seq":12455910,"price":2499.35,"qty":245.0,"timestamp":1618678120563}
1618678120.605956: {"feed":"book","product_id":"FI_ETHUSD_210625","side":"buy","seq":12455911,"price":2499.35,"qty":490.0,"timestamp":1618678120563}
1618678120.6059809: {"feed":"book","product_id":"FI_ETHUSD_210625","side":"sell","seq":12455912,"price":2503.8,"qty":0.0,"timestamp":1618678120563}
1618678120.606009: {"feed":"book","product_id":"FI_ETHUSD_210625","side":"sell","seq":12455913,"price":2503.8,"qty":7535.0,"timestamp":1618678120563}
1618678120.606032: {"feed":"book","product_id":"FI_ETHUSD_210625","side":"buy","seq":12455914,"price":2477.25,"qty":26620.0,"timestamp":1618678120563}
1618678120.6060522: {"feed":"book","product_id":"FI_ETHUSD_210625","side":"buy","seq":12455915,"price":2477.25,"qty":27540.0,"timestamp":1618678120563}
1618678120.606071: {"feed":"book","product_id":"FI_ETHUSD_210625","side":"buy","seq":12455916,"price":2497.5,"qty":0.0,"timestamp":1618678120563}
1618678120.606097: {"feed":"book","product_id":"FI_ETHUSD_210625","side":"buy","seq":12455917,"price":2497.5,"qty":348.0,"timestamp":1618678120563}
1618678120.6061199: {"feed":"book","product_id":"FI_ETHUSD_210625","side":"sell","seq":12455918,"price":2513.2,"qty":0.0,"timestamp":1618678120563}
1618678120.606144: {"feed":"book","product_id":"FI_ETHUSD_210625","side":"sell","seq":12455919,"price":2513.2,"qty":34508.0,"timestamp":1618678120563}
1618678120.606167: {"feed":"book","product_id":"FI_ETHUSD_210625","side":"sell","seq":12455920,"price":2507.0,"qty":0.0,"timestamp":1618678120563}
1618678120.6061912: {"feed":"book","product_id":"FI_ETHUSD_210625","side":"sell","seq":12455921,"price":2507.0,"qty":16861.0,"timestamp":1618678120563}
1618678120.6062138: {"feed":"book","product_id":"FI_ETHUSD_210625","side":"buy","seq":12455922,"price":2492.45,"qty":0.0,"timestamp":1618678120563}
1618678120.606238: {"feed":"book","product_id":"FI_ETHUSD_210625","side":"buy","seq":12455923,"price":2492.45,"qty":639.0,"timestamp":1618678120563}
1618678120.606261: {"feed":"book","product_id":"FI_ETHUSD_210625","side":"sell","seq":12455924,"price":2527.4,"qty":0.0,"timestamp":1618678120563}
1618678120.606286: {"feed":"book","product_id":"FI_ETHUSD_210625","side":"sell","seq":12455925,"price":2527.4,"qty":47823.0,"timestamp":1618678120563}
1618678120.609643: {"feed":"book","product_id":"FI_XBTUSD_210625","side":"sell","seq":21455383,"price":64079.5,"qty":0.0,"timestamp":1618678120581}
1618678120.609772: {"feed":"book","product_id":"FI_XBTUSD_210625","side":"sell","seq":21455384,"price":64078.5,"qty":250001.0,"timestamp":1618678120581}
1618678120.609851: {"feed":"book","product_id":"FI_XBTUSD_210924","side":"sell","seq":13850994,"price":68422.5,"qty":0.0,"timestamp":1618678120581}
1618678120.609885: {"feed":"book","product_id":"FI_XBTUSD_210924","side":"sell","seq":13850995,"price":68374.0,"qty":250001.0,"timestamp":1618678120581}
1618678120.632246: {"feed":"book","product_id":"PI_BCHUSD","side":"sell","seq":16259352,"price":1062.3,"qty":4988.0,"timestamp":1618678120601}
1618678120.632371: {"feed":"book","product_id":"PI_BCHUSD","side":"sell","seq":16259353,"price":1061.1,"qty":50.0,"timestamp":1618678120601}
1618678120.632421: {"feed":"book","product_id":"FI_XRPUSD_210625","side":"buy","seq":3631689,"price":1.6881,"qty":351.0,"timestamp":1618678120605}
1618678120.709908: {"feed":"book","product_id":"FI_XBTUSD_210430","side":"buy","seq":12237655,"price":59445.5,"qty":48172.0,"timestamp":1618678120685}
1618678120.7310421: {"feed":"book","product_id":"FI_XBTUSD_210924","side":"sell","seq":13850996,"price":68333.0,"qty":0.0,"timestamp":1618678120705}
1618678120.752352: {"feed":"book","product_id":"FI_XBTUSD_210430","side":"buy","seq":12237656,"price":59445.5,"qty":48401.0,"timestamp":1618678120728}
1618678120.7524621: {"feed":"book","product_id":"PI_BCHUSD","side":"buy","seq":16259354,"price":1055.5,"qty":0.0,"timestamp":1618678120728}
1618678120.76949: {"feed":"book","product_id":"PI_BCHUSD","side":"buy","seq":16259355,"price":1057.4,"qty":36129.0,"timestamp":1618678120743}
1618678120.769599: {"feed":"book","product_id":"FI_ETHUSD_210625","side":"sell","seq":12455926,"price":2505.8,"qty":3000.0,"timestamp":1618678120745}
1618678120.774067: {"feed":"book","product_id":"FI_XBTUSD_210430","side":"sell","seq":12237657,"price":61941.0,"qty":0.0,"timestamp":1618678120749}
1618678120.774196: {"feed":"book","product_id":"FI_XBTUSD_210430","side":"buy","seq":12237658,"price":60659.5,"qty":0.0,"timestamp":1618678120749}
1618678120.778193: {"feed":"book","product_id":"FI_XBTUSD_210924","side":"sell","seq":13850997,"price":68271.0,"qty":0.0,"timestamp":1618678120754}
1618678120.784708: {"feed":"book","product_id":"FI_XBTUSD_210924","side":"sell","seq":13850998,"price":68270.5,"qty":0.0,"timestamp":1618678120760}
1618678120.784839: {"feed":"book","product_id":"FI_XBTUSD_210924","side":"sell","seq":13850999,"price":68277.0,"qty":10000.0,"timestamp":1618678120760}
1618678120.791911: {"feed":"book","product_id":"FI_ETHUSD_210625","side":"sell","seq":12455927,"price":2503.8,"qty":0.0,"timestamp":1618678120767}
1618678120.792001: {"feed":"book","product_id":"FI_ETHUSD_210625","side":"sell","seq":12455928,"price":2503.55,"qty":7226.0,"timestamp":1618678120767}
1618678120.800688: {"feed":"book","product_id":"FI_XBTUSD_210625","side":"buy","seq":21455385,"price":57200.5,"qty":29165.0,"timestamp":1618678120777}
1618678120.806187: {"feed":"book","product_id":"FI_XRPUSD_210625","side":"buy","seq":3631690,"price":1.6918,"qty":0.0,"timestamp":1618678120781}
1618678120.806276: {"feed":"book","product_id":"FI_XRPUSD_210625","side":"buy","seq":3631691,"price":1.692,"qty":50.0,"timestamp":1618678120781}
1618678120.806669: {"feed":"book","product_id":"FI_XRPUSD_210625","side":"buy","seq":3631692,"price":1.6886,"qty":234.0,"timestamp":1618678120784}
1618678120.812041: {"feed":"book","product_id":"FI_XRPUSD_210625","side":"buy","seq":3631693,"price":1.6919,"qty":0.0,"timestamp":1618678120789}
1618678120.812095: {"feed":"book","product_id":"FI_XRPUSD_210625","side":"buy","seq":3631694,"price":1.692,"qty":118.0,"timestamp":1618678120789}
1618678120.819871: {"feed":"book","product_id":"FI_BCHUSD_210625","side":"sell","seq":2240277,"price":1142.9,"qty":0.0,"timestamp":1618678120796}
1618678120.85028: {"feed":"book","product_id":"FI_XBTUSD_210924","side":"buy","seq":13851000,"price":52552.5,"qty":58852.0,"timestamp":1618678120823}
1618678120.8503911: {"feed":"book","product_id":"PI_BCHUSD","side":"sell","seq":16259356,"price":1061.9,"qty":3608.0,"timestamp":1618678120826}
1618678120.850442: {"feed":"book","product_id":"PI_BCHUSD","side":"sell","seq":16259357,"price":1061.5,"qty":3738.0,"timestamp":1618678120826}
1618678120.85048: {"feed":"book","product_id":"PI_BCHUSD","side":"sell","seq":16259358,"price":1062.3,"qty":0.0,"timestamp":1618678120826}
1618678120.8544261: {"feed":"book","product_id":"FI_XBTUSD_210430","side":"buy","seq":12237659,"price":61150.5,"qty":2223.0,"timestamp":1618678120829}
1618678120.8545542: {"feed":"book","product_id":"FI_XBTUSD_210625","side":"buy","seq":21455386,"price":63849.5,"qty":4425.0,"timestamp":1618678120829}
1618678120.864071: {"feed":"book","product_id":"FI_XBTUSD_210924","side":"buy","seq":13851001,"price":68165.5,"qty":2309.0,"timestamp":1618678120840}
1618678120.8984818: {"feed":"book","product_id":"FI_ETHUSD_210430","side":"buy","seq":4780935,"price":2384.2,"qty":1499.0,"timestamp":1618678120874}
1618678120.933544: {"feed":"book","product_id":"FI_XBTUSD_210625","side":"sell","seq":21455387,"price":64079.0,"qty":0.0,"timestamp":1618678120905}
1618678120.933673: {"feed":"book","product_id":"FI_XBTUSD_210625","side":"sell","seq":21455388,"price":64078.0,"qty":20139.0,"timestamp":1618678120905}
1618678120.93748: {"feed":"book","product_id":"PI_BCHUSD","side":"buy","seq":16259359,"price":1057.8,"qty":10958.0,"timestamp":1618678120909}
1618678120.966588: {"feed":"book","product_id":"FI_XBTUSD_210924","side":"sell","seq":13851002,"price":68327.0,"qty":45000.0,"timestamp":1618678120943}
1618678120.9666948: {"feed":"book","product_id":"FI_XBTUSD_210924","side":"buy","seq":13851003,"price":68040.0,"qty":3000.0,"timestamp":1618678120943}
1618678120.985763: {"feed":"book","product_id":"PI_BCHUSD","side":"sell","seq":16259360,"price":1061.8,"qty":14247.0,"timestamp":1618678120962}
1618678120.988943: {"feed":"book","product_id":"FI_XRPUSD_210625","side":"buy","seq":3631695,"price":1.6886,"qty":0.0,"timestamp":1618678120965}
1618678120.98958: {"feed":"book","product_id":"FI_BCHUSD_210625","side":"buy","seq":2240278,"price":1127.2,"qty":64.0,"timestamp":1618678120966}
1618678121.000994: {"feed":"book","product_id":"FI_XBTUSD_210430","side":"buy","seq":12237660,"price":59445.5,"qty":48172.0,"timestamp":1618678120974}
1618678121.0011032: {"feed":"book","product_id":"FI_ETHUSD_210625","side":"sell","seq":12455929,"price":2503.55,"qty":0.0,"timestamp":1618678120974}
1618678121.001174: {"feed":"book","product_id":"FI_ETHUSD_210625","side":"sell","seq":12455930,"price":2503.8,"qty":7743.0,"timestamp":1618678120974}
1618678121.022078: {"feed":"book","product_id":"PI_BCHUSD","side":"buy","seq":16259361,"price":1057.7,"qty":8559.0,"timestamp":1618678120996}
1618678121.024087: {"feed":"book","product_id":"PI_BCHUSD","side":"buy","seq":16259362,"price":1058.1,"qty":5013.0,"timestamp":1618678120997}
1618678121.032568: {"feed":"book","product_id":"PI_BCHUSD","side":"sell","seq":16259363,"price":1061.5,"qty":0.0,"timestamp":1618678121003}
1618678121.032646: {"feed":"book","product_id":"PI_BCHUSD","side":"sell","seq":16259364,"price":1061.1,"qty":3560.0,"timestamp":1618678121005}
1618678121.032674: {"feed":"book","product_id":"PI_BCHUSD","side":"sell","seq":16259365,"price":1060.6,"qty":2823.0,"timestamp":1618678121005}
1618678121.032701: {"feed":"book","product_id":"PI_BCHUSD","side":"sell","seq":16259366,"price":1060.6,"qty":5400.0,"timestamp":1618678121006}
1618678121.043489: {"feed":"book","product_id":"FI_XBTUSD_210430","side":"buy","seq":12237661,"price":59445.5,"qty":52651.0,"timestamp":1618678121017}
1618678121.0505788: {"feed":"book","product_id":"PI_BCHUSD","side":"sell","seq":16259367,"price":1060.9,"qty":4995.0,"timestamp":1618678121027}
1618678121.053774: {"feed":"book","product_id":"PI_BCHUSD","side":"sell","seq":16259368,"price":1061.3,"qty":8658.0,"timestamp":1618678121027}
1618678121.053859: {"feed":"book","product_id":"PI_BCHUSD","side":"sell","seq":16259369,"price":1061.7,"qty":4991.0,"timestamp":1618678121027}
1618678121.102318: {"feed":"book","product_id":"FI_XBTUSD_210625","side":"buy","seq":21455389,"price":57200.5,"qty":35941.0,"timestamp":1618678121077}
1618678121.12093: {"feed":"book","product_id":"FI_XRPUSD_210625","side":"sell","seq":3631696,"price":1.7034,"qty":0.0,"timestamp":1618678121094}
1618678121.121063: {"feed":"book","product_id":"FI_XRPUSD_210625","side":"sell","seq":3631697,"price":1.702,"qty":57600.0,"timestamp":1618678121094}
1618678121.1494138: {"feed":"book","product_id":"FI_XBTUSD_210924","side":"buy","seq":13851004,"price":52552.5,"qty":58638.0,"timestamp":1618678121124}
1618678121.1630259: {"feed":"book","product_id":"PI_BCHUSD","side":"buy","seq":16259370,"price":1056.2,"qty":6027.0,"timestamp":1618678121138}
1618678121.175565: {"feed":"book","product_id":"PI_BCHUSD","side":"buy","seq":16259371,"price":1057.8,"qty":7250.0,"timestamp":1618678121142}
1618678121.1756759: {"feed":"book","product_id":"FI_XBTUSD_210625","side":"sell","seq":21455390,"price":64078.5,"qty":0.0,"timestamp":1618678121142}
1618678121.1757529: {"feed":"book","product_id":"FI_XBTUSD_210625","side":"sell","seq":21455391,"price":64077.5,"qty":250001.0,"timestamp":1618678121142}
1618678121.175806: {"feed":"book","product_id":"FI_XBTUSD_210924","side":"sell","seq":13851005,"price":68374.0,"qty":0.0,"timestamp":1618678121142}
1618678121.175853: {"feed":"book","product_id":"FI_XBTUSD_210924","side":"sell","seq":13851006,"price":68422.5,"qty":250001.0,"timestamp":1618678121142}
1618678121.175903: {"feed":"book","product_id":"PI_BCHUSD","side":"sell","seq":16259372,"price":1061.4,"qty":29856.0,"timestamp":1618678121142}
1618678121.175949: {"feed":"book","product_id":"PI_BCHUSD","side":"sell","seq":16259373,"price":1062.1,"qty":0.0,"timestamp":1618678121142}
1618678121.1799738: {"feed":"book","product_id":"PI_BCHUSD","side":"sell","seq":16259374,"price":1061.8,"qty":3629.0,"timestamp":1618678121155}
1618678121.180085: {"feed":"book","product_id":"PI_BCHUSD","side":"sell","seq":16259375,"price":1061.6,"qty":10618.0,"timestamp":1618678121155}
1618678121.190021: {"feed":"book","product_id":"FI_XBTUSD_210924","side":"buy","seq":13851007,"price":52552.5,"qty":58757.0,"timestamp":1618678121166}
1618678121.190625: {"feed":"book","product_id":"PI_BCHUSD","side":"buy","seq":16259376,"price":1057.4,"qty":20704.0,"timestamp":1618678121168}
1618678121.1955829: {"feed":"book","product_id":"PI_BCHUSD","side":"buy","seq":16259377,"price":1057.2,"qty":3835.0,"timestamp":1618678121169}
1618678121.195693: {"feed":"book","product_id":"PI_BCHUSD","side":"buy","seq":16259378,"price":1056.4,"qty":28452.0,"timestamp":1618678121170}
1618678121.19576: {"feed":"book","product_id":"PI_BCHUSD","side":"sell","seq":16259379,"price":1060.7,"qty":875.0,"timestamp":1618678121170}
1618678121.195801: {"feed":"book","product_id":"PI_BCHUSD","side":"sell","seq":16259380,"price":1060.3,"qty":4138.0,"timestamp":1618678121170}
1618678121.200634: {"feed":"book","product_id":"FI_XBTUSD_210625","side":"sell","seq":21455392,"price":64248.0,"qty":0.0,"timestamp":1618678121173}
1618678121.200762: {"feed":"book","product_id":"FI_XBTUSD_210625","side":"sell","seq":21455393,"price":64247.0,"qty":57188.0,"timestamp":1618678121173}
1618678121.200855: {"feed":"book","product_id":"FI_XBTUSD_210625","side":"sell","seq":21455394,"price":64041.5,"qty":0.0,"timestamp":1618678121173}
1618678121.200887: {"feed":"book","product_id":"FI_XBTUSD_210625","side":"sell","seq":21455395,"price":64041.5,"qty":12913.0,"timestamp":1618678121173}
1618678121.200917: {"feed":"book","product_id":"FI_XBTUSD_210625","side":"sell","seq":21455396,"price":64078.0,"qty":0.0,"timestamp":1618678121173}
1618678121.200943: {"feed":"book","product_id":"FI_XBTUSD_210625","side":"sell","seq":21455397,"price":64078.0,"qty":20106.0,"timestamp":1618678121173}
1618678121.200968: {"feed":"book","product_id":"FI_XBTUSD_210625","side":"buy","seq":21455398,"price":63881.0,"qty":1378.0,"timestamp":1618678121173}
1618678121.20099: {"feed":"book","product_id":"FI_XBTUSD_210625","side":"buy","seq":21455399,"price":63881.0,"qty":2755.0,"timestamp":1618678121173}
1618678121.2010088: {"feed":"book","product_id":"FI_XBTUSD_210625","side":"buy","seq":21455400,"price":63881.0,"qty":1377.0,"timestamp":1618678121173}
1618678121.201029: {"feed":"book","product_id":"FI_XBTUSD_210625","side":"buy","seq":21455401,"price":63881.0,"qty":2754.0,"timestamp":1618678121173}
1618678121.2010481: {"feed":"book","product_id":"FI_XBTUSD_210625","side":"buy","seq":21455402,"price":63489.0,"qty":0.0,"timestamp":1618678121173}
1618678121.201073: {"feed":"book","product_id":"FI_XBTUSD_210625","side":"buy","seq":21455403,"price":63489.0,"qty":4214.0,"timestamp":1618678121173}
1618678121.2010958: {"feed":"book","product_id":"FI_XBTUSD_210625","side":"buy","seq":21455404,"price":63728.0,"qty":0.0,"timestamp":1618678121173}
1618678121.20112: {"feed":"book","product_id":"FI_XBTUSD_210625","side":"buy","seq":21455405,"price":63728.0,"qty":3180.0,"timestamp":1618678121173}
1618678121.2325041: {"feed":"book","product_id":"FI_ETHUSD_210625","side":"buy","seq":12455931,"price":2496.7,"qty":1541.0,"timestamp":1618678121200}
1618678121.232633: {"feed":"book","product_id":"PI_BCHUSD","side":"sell","seq":16259381,"price":1061.0,"qty":36264.0,"timestamp":1618678121202}
1618678121.232685: {"feed":"book","product_id":"PI_BCHUSD","side":"sell","seq":16259382,"price":1060.6,"qty":2823.0,"timestamp":1618678121205}
1618678121.232724: {"feed":"book","product_id":"FI_XBTUSD_210924","side":"buy","seq":13851008,"price":68040.0,"qty":0.0,"timestamp":1618678121205}
1618678121.232779: {"feed":"book","product_id":"PI_BCHUSD","side":"buy","seq":16259383,"price":1056.9,"qty":23801.0,"timestamp":1618678121205}
1618678121.232815: {"feed":"book","product_id":"PI_BCHUSD","side":"buy","seq":16259384,"price":1057.4,"qty":0.0,"timestamp":1618678121206}
1618678121.239209: {"feed":"book","product_id":"PI_BCHUSD","side":"buy","seq":16259385,"price":1057.4,"qty":3729.0,"timestamp":1618678121208}
1618678121.2393348: {"feed":"book","product_id":"PI_BCHUSD","side":"buy","seq":16259386,"price":1057.8,"qty":3719.0,"timestamp":1618678121208}
1618678121.244341: {"feed":"book","product_id":"PI_BCHUSD","side":"sell","seq":16259387,"price":1067.5,"qty":0.0,"timestamp":1618678121215}
1618678121.244469: {"feed":"book","product_id":"PI_BCHUSD","side":"sell","seq":16259388,"price":1080.3,"qty":97867.0,"timestamp":1618678121215}
1618678121.244521: {"feed":"book","product_id":"PI_BCHUSD","side":"sell","seq":16259389,"price":1083.4,"qty":0.0,"timestamp":1618678121215}
