1626994938.3466072: {"feed":"book","product_id":"PI_ETHUSD","side":"sell","seq":26662195,"price":2021.45,"qty":0.0,"timestamp":1626994938365}
1626994938.3466449: {"feed":"book","product_id":"PI_ETHUSD","side":"sell","seq":26662196,"price":2021.45,"qty":67942.0,"timestamp":1626994938365}
1626994938.3615701: {"feed":"book","product_id":"PI_ETHUSD","side":"buy","seq":26662197,"price":2003.85,"qty":8207.0,"timestamp":1626994938384}
1626994938.3616798: {"feed":"book","product_id":"PI_ETHUSD","side":"buy","seq":26662198,"price":2004.0,"qty":110044.0,"timestamp":1626994938384}
1626994938.361729: {"feed":"book","product_id":"PI_ETHUSD","side":"buy","seq":26662199,"price":2003.8,"qty":0.0,"timestamp":1626994938384}
1626994938.36179: {"feed":"book","product_id":"PI_ETHUSD","side":"buy","seq":26662200,"price":2003.95,"qty":20000.0,"timestamp":1626994938384}
1626994938.362198: {"feed":"book","product_id":"FI_ETHUSD_210730","side":"buy","seq":2138780,"price":1991.9,"qty":0.0,"timestamp":1626994938384}
1626994938.362252: {"feed":"book","product_id":"FI_ETHUSD_210730","side":"buy","seq":2138781,"price":1992.0,"qty":44704.0,"timestamp":1626994938384}
1626994938.3857129: {"feed":"book","product_id":"FI_XBTUSD_210924","side":"sell","seq":13501940,"price":32273.0,"qty":0.0,"timestamp":1626994938408}
1626994938.385835: {"feed":"book","product_id":"FI_XBTUSD_210924","side":"sell","seq":13501941,"price":32268.5,"qty":21791.0,"timestamp":1626994938408}
1626994938.392368: {"feed":"book","product_id":"FI_ETHUSD_210730","side":"buy","seq":2138782,"price":1991.95,"qty":0.0,"timestamp":1626994938414}
1626994938.39249: {"feed":"book","product_id":"FI_ETHUSD_210730","side":"buy","seq":2138783,"price":1992.05,"qty":250002.0,"timestamp":1626994938414}
1626994938.392552: {"feed":"book","product_id":"FI_XBTUSD_210924","side":"sell","seq":13501942,"price":32273.5,"qty":0.0,"timestamp":1626994938414}
1626994938.392607: {"feed":"book","product_id":"FI_XBTUSD_210924","side":"sell","seq":13501943,"price":32281.5,"qty":250001.0,"timestamp":1626994938414}
1626994938.392652: {"feed":"book","product_id":"FI_ETHUSD_211231","side":"sell","seq":2199095,"price":2049.15,"qty":0.0,"timestamp":1626994938414}
1626994938.3926988: {"feed":"book","product_id":"FI_ETHUSD_211231","side":"sell","seq":2199096,"price":2049.05,"qty":250002.0,"timestamp":1626994938414}
1626994938.3942919: {"feed":"book","product_id":"PI_ETHUSD","side":"sell","seq":26662201,"price":2013.6,"qty":0.0,"timestamp":1626994938414}
1626994938.394418: {"feed":"book","product_id":"PI_ETHUSD","side":"sell","seq":26662202,"price":2013.5,"qty":500002.0,"timestamp":1626994938414}
1626994938.482661: {"feed":"book","product_id":"PI_ETHUSD","side":"sell","seq":26662203,"price":2008.2,"qty":33894.0,"timestamp":1626994938504}
1626994938.48277: {"feed":"book","product_id":"PI_ETHUSD","side":"sell","seq":26662204,"price":2007.75,"qty":331961.0,"timestamp":1626994938504}
1626994938.4992971: {"feed":"book","product_id":"PI_ETHUSD","side":"buy","seq":26662205,"price":2003.0,"qty":9214.0,"timestamp":1626994938520}
1626994938.5170271: {"feed":"book","product_id":"PI_ETHUSD","side":"buy","seq":26662206,"price":1989.9,"qty":59999.0,"timestamp":1626994938539}
1626994938.5459409: {"feed":"book","product_id":"FI_ETHUSD_210730","side":"sell","seq":2138784,"price":2014.9,"qty":0.0,"timestamp":1626994938566}
1626994938.54607: {"feed":"book","product_id":"FI_ETHUSD_210730","side":"sell","seq":2138785,"price":2014.1,"qty":250002.0,"timestamp":1626994938566}
1626994938.546135: {"feed":"book","product_id":"PI_ETHUSD","side":"buy","seq":26662207,"price":1996.5,"qty":0.0,"timestamp":1626994938569}
1626994938.5461938: {"feed":"book","product_id":"PI_ETHUSD","side":"buy","seq":26662208,"price":1993.2,"qty":55166.0,"timestamp":1626994938569}
1626994938.552174: {"feed":"book","product_id":"PI_ETHUSD","side":"sell","seq":26662209,"price":2007.1,"qty":0.0,"timestamp":1626994938569}
1626994938.552288: {"feed":"book","product_id":"PI_ETHUSD","side":"sell","seq":26662210,"price":2006.35,"qty":10515.0,"timestamp":1626994938569}
1626994938.552332: {"feed":"book","product_id":"PI_ETHUSD","side":"buy","seq":26662211,"price":2000.55,"qty":0.0,"timestamp":1626994938569}
1626994938.5523672: {"feed":"book","product_id":"PI_ETHUSD","side":"buy","seq":26662212,"price":2000.05,"qty":24905.0,"timestamp":1626994938569}
1626994938.552396: {"feed":"book","product_id":"PI_ETHUSD","side":"sell","seq":26662213,"price":2008.4,"qty":0.0,"timestamp":1626994938569}
1626994938.552425: {"feed":"book","product_id":"PI_ETHUSD","side":"sell","seq":26662214,"price":2008.15,"qty":27885.0,"timestamp":1626994938569}
1626994938.552449: {"feed":"book","product_id":"PI_ETHUSD","side":"buy","seq":26662215,"price":2001.3,"qty":0.0,"timestamp":1626994938569}
1626994938.552475: {"feed":"book","product_id":"PI_ETHUSD","side":"buy","seq":26662216,"price":2001.25,"qty":171148.0,"timestamp":1626994938569}
1626994938.552497: {"feed":"book","product_id":"PI_ETHUSD","side":"sell","seq":26662217,"price":2007.4,"qty":0.0,"timestamp":1626994938569}
1626994938.552523: {"feed":"book","product_id":"PI_ETHUSD","side":"sell","seq":26662218,"price":2007.4,"qty":16750.0,"timestamp":1626994938569}
1626994938.5525482: {"feed":"book","product_id":"PI_ETHUSD","side":"buy","seq":26662219,"price":2001.85,"qty":5005.0,"timestamp":1626994938569}
1626994938.55257: {"feed":"book","product_id":"PI_ETHUSD","side":"buy","seq":26662220,"price":2001.85,"qty":17605.0,"timestamp":1626994938569}
1626994938.5525901: {"feed":"book","product_id":"PI_ETHUSD","side":"sell","seq":26662221,"price":2013.55,"qty":0.0,"timestamp":1626994938569}
1626994938.552616: {"feed":"book","product_id":"PI_ETHUSD","side":"sell","seq":26662222,"price":2013.55,"qty":49879.0,"timestamp":1626994938569}
1626994938.552642: {"feed":"book","product_id":"PI_ETHUSD","side":"buy","seq":26662223,"price":1985.1,"qty":0.0,"timestamp":1626994938569}
1626994938.5526679: {"feed":"book","product_id":"PI_ETHUSD","side":"buy","seq":26662224,"price":1985.1,"qty":66942.0,"timestamp":1626994938569}
1626994938.552693: {"feed":"book","product_id":"PI_ETHUSD","side":"sell","seq":26662225,"price":2021.45,"qty":0.0,"timestamp":1626994938569}
1626994938.552719: {"feed":"book","product_id":"PI_ETHUSD","side":"sell","seq":26662226,"price":2021.45,"qty":67939.0,"timestamp":1626994938569}
1626994938.552743: {"feed":"book","product_id":"PI_ETHUSD","side":"buy","seq":26662227,"price":2004.0,"qty":94218.0,"timestamp":1626994938569}
1626994938.552765: {"feed":"book","product_id":"PI_ETHUSD","side":"buy","seq":26662228,"price":2003.85,"qty":24033.0,"timestamp":1626994938569}
1626994938.552785: {"feed":"book","product_id":"PI_ETHUSD","side":"buy","seq":26662229,"price":2003.95,"qty":0.0,"timestamp":1626994938571}
1626994938.55281: {"feed":"book","product_id":"PI_ETHUSD","side":"buy","seq":26662230,"price":2003.8,"qty":20000.0,"timestamp":1626994938571}
1626994938.603671: {"feed":"book","product_id":"PI_ETHUSD","side":"buy","seq":26662231,"price":2003.85,"qty":8207.0,"timestamp":1626994938623}
1626994938.603777: {"feed":"book","product_id":"PI_ETHUSD","side":"buy","seq":26662232,"price":2003.95,"qty":15826.0,"timestamp":1626994938623}
1626994938.603843: {"feed":"book","product_id":"PI_ETHUSD","side":"buy","seq":26662233,"price":2003.8,"qty":0.0,"timestamp":1626994938624}
1626994938.603901: {"feed":"book","product_id":"PI_ETHUSD","side":"buy","seq":26662234,"price":2003.9,"qty":21308.0,"timestamp":1626994938624}
1626994938.606239: {"feed":"book","product_id":"PI_ETHUSD","side":"buy","seq":26662235,"price":2003.9,"qty":1308.0,"timestamp":1626994938627}
1626994938.606345: {"feed":"book","product_id":"PI_ETHUSD","side":"buy","seq":26662236,"price":2004.05,"qty":68019.0,"timestamp":1626994938627}
1626994938.606394: {"feed":"book","product_id":"PI_ETHUSD","side":"buy","seq":26662237,"price":2003.95,"qty":0.0,"timestamp":1626994938629}
1626994938.606453: {"feed":"book","product_id":"PI_ETHUSD","side":"buy","seq":26662238,"price":2004.1,"qty":16426.0,"timestamp":1626994938629}
1626994938.608636: {"feed":"book","product_id":"PI_ETHUSD","side":"buy","seq":26662239,"price":2004.05,"qty":48019.0,"timestamp":1626994938631}
1626994938.608743: {"feed":"book","product_id":"PI_ETHUSD","side":"buy","seq":26662240,"price":2003.9,"qty":21308.0,"timestamp":1626994938631}
1626994938.608792: {"feed":"book","product_id":"PI_ETHUSD","side":"buy","seq":26662241,"price":2004.1,"qty":600.0,"timestamp":1626994938631}
1626994938.60883: {"feed":"book","product_id":"PI_ETHUSD","side":"buy","seq":26662242,"price":2003.95,"qty":15826.0,"timestamp":1626994938631}
1626994938.6201339: {"feed":"book","product_id":"FI_XBTUSD_210924","side":"sell","seq":13501944,"price":32245.5,"qty":2430.0,"timestamp":1626994938641}
1626994938.6202428: {"feed":"book","product_id":"FI_XBTUSD_210924","side":"sell","seq":13501945,"price":32245.5,"qty":18556.0,"timestamp":1626994938641}
1626994938.620291: {"feed":"book","product_id":"FI_XBTUSD_210924","side":"buy","seq":13501946,"price":32188.5,"qty":881.0,"timestamp":1626994938641}
1626994938.620331: {"feed":"book","product_id":"FI_XBTUSD_210924","side":"buy","seq":13501947,"price":32188.5,"qty":18825.0,"timestamp":1626994938641}
1626994938.620366: {"feed":"book","product_id":"FI_XBTUSD_210924","side":"sell","seq":13501948,"price":32268.5,"qty":825.0,"timestamp":1626994938641}
1626994938.620398: {"feed":"book","product_id":"FI_XBTUSD_210924","side":"sell","seq":13501949,"price":32268.5,"qty":21790.0,"timestamp":1626994938641}
1626994938.6217852: {"feed":"book","product_id":"PI_ETHUSD","side":"buy","seq":26662243,"price":2003.4,"qty":15000.0,"timestamp":1626994938645}
1626994938.6242628: {"feed":"book","product_id":"PI_ETHUSD","side":"buy","seq":26662244,"price":2003.9,"qty":1308.0,"timestamp":1626994938647}
1626994938.624338: {"feed":"book","product_id":"PI_ETHUSD","side":"buy","seq":26662245,"price":2004.05,"qty":68019.0,"timestamp":1626994938647}
1626994938.624371: {"feed":"book","product_id":"PI_ETHUSD","side":"buy","seq":26662246,"price":2003.95,"qty":0.0,"timestamp":1626994938647}
1626994938.6244118: {"feed":"book","product_id":"PI_ETHUSD","side":"buy","seq":26662247,"price":2004.05,"qty":83845.0,"timestamp":1626994938647}
1626994938.666002: {"feed":"book","product_id":"FI_XBTUSD_210730","side":"sell","seq":5160094,"price":32208.5,"qty":0.0,"timestamp":1626994938687}
1626994938.666125: {"feed":"book","product_id":"FI_XBTUSD_210730","side":"sell","seq":5160095,"price":32207.0,"qty":103.0,"timestamp":1626994938687}
1626994938.687096: {"feed":"book","product_id":"FI_XBTUSD_210730","side":"sell","seq":5160096,"price":32207.0,"qty":0.0,"timestamp":1626994938703}
1626994938.6872199: {"feed":"book","product_id":"FI_XBTUSD_210730","side":"sell","seq":5160097,"price":32208.5,"qty":103.0,"timestamp":1626994938703}
1626994938.692207: {"feed":"book","product_id":"FI_XBTUSD_210924","side":"sell","seq":13501950,"price":32231.5,"qty":0.0,"timestamp":1626994938714}
1626994938.69233: {"feed":"book","product_id":"FI_XBTUSD_210924","side":"sell","seq":13501951,"price":32230.0,"qty":103.0,"timestamp":1626994938714}
1626994938.701409: {"feed":"book","product_id":"FI_XBTUSD_210924","side":"sell","seq":13501952,"price":32230.0,"qty":0.0,"timestamp":1626994938721}
1626994938.7015328: {"feed":"book","product_id":"FI_XBTUSD_210924","side":"sell","seq":13501953,"price":32231.5,"qty":103.0,"timestamp":1626994938721}
1626994938.758092: {"feed":"book","product_id":"PI_ETHUSD","side":"buy","seq":26662248,"price":2003.0,"qty":5000.0,"timestamp":1626994938779}
1626994938.758167: {"feed":"book","product_id":"PI_XRPUSD","side":"buy","seq":3456217,"price":0.5682,"qty":0.0,"timestamp":1626994938779}
1626994938.758228: {"feed":"book","product_id":"PI_ETHUSD","side":"buy","seq":26662249,"price":2001.25,"qty":155068.0,"timestamp":1626994938779}
1626994938.758257: {"feed":"book","product_id":"PI_ETHUSD","side":"buy","seq":26662250,"price":2001.3,"qty":15726.0,"timestamp":1626994938779}
1626994938.7600892: {"feed":"book","product_id":"PI_ETHUSD","side":"sell","seq":26662251,"price":2013.55,"qty":0.0,"timestamp":1626994938779}
1626994938.760153: {"feed":"book","product_id":"PI_ETHUSD","side":"sell","seq":26662252,"price":2013.45,"qty":49529.0,"timestamp":1626994938779}
1626994938.760194: {"feed":"book","product_id":"PI_ETHUSD","side":"sell","seq":26662253,"price":2006.35,"qty":0.0,"timestamp":1626994938779}
1626994938.760227: {"feed":"book","product_id":"PI_ETHUSD","side":"sell","seq":26662254,"price":2006.35,"qty":10471.0,"timestamp":1626994938779}
1626994938.7602549: {"feed":"book","product_id":"PI_ETHUSD","side":"sell","seq":26662255,"price":2007.4,"qty":0.0,"timestamp":1626994938779}
1626994938.760283: {"feed":"book","product_id":"PI_ETHUSD","side":"sell","seq":26662256,"price":2007.4,"qty":16684.0,"timestamp":1626994938779}
1626994938.760309: {"feed":"book","product_id":"PI_ETHUSD","side":"buy","seq":26662257,"price":2001.85,"qty":5005.0,"timestamp":1626994938779}
1626994938.760331: {"feed":"book","product_id":"PI_ETHUSD","side":"buy","seq":26662258,"price":2001.85,"qty":17648.0,"timestamp":1626994938779}
1626994938.760352: {"feed":"book","product_id":"PI_ETHUSD","side":"sell","seq":26662259,"price":2008.15,"qty":4990.0,"timestamp":1626994938779}
1626994938.760372: {"feed":"book","product_id":"PI_ETHUSD","side":"sell","seq":26662260,"price":2008.15,"qty":27841.0,"timestamp":1626994938779}
1626994938.760391: {"feed":"book","product_id":"PI_ETHUSD","side":"buy","seq":26662261,"price":2000.05,"qty":0.0,"timestamp":1626994938779}
1626994938.760424: {"feed":"book","product_id":"PI_ETHUSD","side":"buy","seq":26662262,"price":2000.05,"qty":24948.0,"timestamp":1626994938779}
1626994938.760449: {"feed":"book","product_id":"PI_ETHUSD","side":"buy","seq":26662263,"price":1993.2,"qty":0.0,"timestamp":1626994938779}
1626994938.760482: {"feed":"book","product_id":"PI_ETHUSD","side":"buy","seq":26662264,"price":1993.2,"qty":55191.0,"timestamp":1626994938779}
1626994938.7785192: {"feed":"book","product_id":"FI_XBTUSD_210924","side":"buy","seq":13501954,"price":32207.0,"qty":0.0,"timestamp":1626994938796}
1626994938.778645: {"feed":"book","product_id":"PI_ETHUSD","side":"buy","seq":26662265,"price":2003.3,"qty":4011.0,"timestamp":1626994938797}
1626994938.789113: {"feed":"book","product_id":"FI_XBTUSD_210924","side":"buy","seq":13501955,"price":32204.0,"qty":0.0,"timestamp":1626994938810}
1626994938.789241: {"feed":"book","product_id":"FI_XBTUSD_210924","side":"buy","seq":13501956,"price":32203.5,"qty":50.0,"timestamp":1626994938810}
1626994938.802887: {"feed":"book","product_id":"PI_ETHUSD","side":"sell","seq":26662266,"price":2012.2,"qty":38399.0,"timestamp":1626994938825}
1626994938.805156: {"feed":"book","product_id":"PI_ETHUSD","side":"buy","seq":26662267,"price":1996.2,"qty":52002.0,"timestamp":1626994938827}
1626994938.817815: {"feed":"book","product_id":"PI_XRPUSD","side":"buy","seq":3456218,"price":0.5881,"qty":22186.0,"timestamp":1626994938840}
1626994938.821099: {"feed":"book","product_id":"PI_XRPUSD","side":"buy","seq":3456219,"price":0.588,"qty":8922.0,"timestamp":1626994938843}
1626994938.821206: {"feed":"book","product_id":"PI_XRPUSD","side":"buy","seq":3456220,"price":0.5881,"qty":32136.0,"timestamp":1626994938843}
1626994938.8232691: {"feed":"book","product_id":"FI_XBTUSD_210924","side":"sell","seq":13501957,"price":32245.5,"qty":2430.0,"timestamp":1626994938845}
1626994938.8233778: {"feed":"book","product_id":"FI_XBTUSD_210924","side":"sell","seq":13501958,"price":32237.0,"qty":14286.0,"timestamp":1626994938845}
1626994938.839257: {"feed":"book","product_id":"PI_XRPUSD","side":"buy","seq":3456221,"price":0.5883,"qty":0.0,"timestamp":1626994938862}
1626994938.8450701: {"feed":"book","product_id":"PI_XRPUSD","side":"sell","seq":3456222,"price":0.6181,"qty":0.0,"timestamp":1626994938866}
1626994938.8451579: {"feed":"book","product_id":"PI_XRPUSD","side":"sell","seq":3456223,"price":0.618,"qty":50.0,"timestamp":1626994938866}
1626994938.882817: {"feed":"book","product_id":"PI_ETHUSD","side":"sell","seq":26662268,"price":2008.75,"qty":24188.0,"timestamp":1626994938904}
1626994938.882924: {"feed":"book","product_id":"PI_ETHUSD","side":"buy","seq":26662269,"price":1999.75,"qty":19199.0,"timestamp":1626994938904}
1626994938.9545548: {"feed":"book","product_id":"FI_XBTUSD_210924","side":"buy","seq":13501959,"price":32130.0,"qty":0.0,"timestamp":1626994938977}
1626994938.954677: {"feed":"book","product_id":"FI_XBTUSD_210924","side":"buy","seq":13501960,"price":32138.0,"qty":250001.0,"timestamp":1626994938977}
1626994938.954742: {"feed":"book","product_id":"PI_ETHUSD","side":"buy","seq":26662270,"price":1993.15,"qty":0.0,"timestamp":1626994938977}
1626994938.954796: {"feed":"book","product_id":"PI_ETHUSD","side":"buy","seq":26662271,"price":1993.25,"qty":500002.0,"timestamp":1626994938977}
1626994938.954842: {"feed":"book","product_id":"PI_ETHUSD","side":"sell","seq":26662272,"price":2013.5,"qty":0.0,"timestamp":1626994938977}
1626994938.9548879: {"feed":"book","product_id":"PI_ETHUSD","side":"sell","seq":26662273,"price":2013.4,"qty":500002.0,"timestamp":1626994938977}
1626994938.957851: {"feed":"book","product_id":"FI_XBTUSD_210924","side":"buy","seq":13501961,"price":32150.0,"qty":0.0,"timestamp":1626994938979}
1626994938.957977: {"feed":"book","product_id":"FI_XBTUSD_210924","side":"buy","seq":13501962,"price":32152.0,"qty":1500.0,"timestamp":1626994938979}
1626994938.95804: {"feed":"book","product_id":"FI_XBTUSD_210730","side":"buy","seq":5160098,"price":32129.5,"qty":0.0,"timestamp":1626994938980}
1626994938.958092: {"feed":"book","product_id":"FI_XBTUSD_210730","side":"buy","seq":5160099,"price":32131.5,"qty":1500.0,"timestamp":1626994938980}
1626994938.960929: {"feed":"book","product_id":"PI_ETHUSD","side":"buy","seq":26662274,"price":2001.3,"qty":0.0,"timestamp":1626994938983}
1626994938.961018: {"feed":"book","product_id":"PI_ETHUSD","side":"buy","seq":26662275,"price":2001.25,"qty":171149.0,"timestamp":1626994938983}
1626994938.961052: {"feed":"book","product_id":"PI_ETHUSD","side":"sell","seq":26662276,"price":2006.35,"qty":0.0,"timestamp":1626994938983}
1626994938.961086: {"feed":"book","product_id":"PI_ETHUSD","side":"sell","seq":26662277,"price":2006.35,"qty":10515.0,"timestamp":1626994938983}
1626994938.961118: {"feed":"book","product_id":"PI_ETHUSD","side":"sell","seq":26662278,"price":2007.4,"qty":0.0,"timestamp":1626994938983}
1626994938.961144: {"feed":"book","product_id":"PI_ETHUSD","side":"sell","seq":26662279,"price":2007.4,"qty":16750.0,"timestamp":1626994938983}
1626994938.96117: {"feed":"book","product_id":"PI_ETHUSD","side":"buy","seq":26662280,"price":2001.85,"qty":5005.0,"timestamp":1626994938983}
1626994938.961192: {"feed":"book","product_id":"PI_ETHUSD","side":"buy","seq":26662281,"price":2001.85,"qty":17605.0,"timestamp":1626994938983}
1626994938.961212: {"feed":"book","product_id":"PI_ETHUSD","side":"sell","seq":26662282,"price":2008.15,"qty":4990.0,"timestamp":1626994938983}
1626994938.961232: {"feed":"book","product_id":"PI_ETHUSD","side":"sell","seq":26662283,"price":2008.15,"qty":27885.0,"timestamp":1626994938983}
1626994938.961251: {"feed":"book","product_id":"PI_ETHUSD","side":"buy","seq":26662284,"price":2000.05,"qty":0.0,"timestamp":1626994938983}
1626994938.9612758: {"feed":"book","product_id":"PI_ETHUSD","side":"buy","seq":26662285,"price":2000.05,"qty":24905.0,"timestamp":1626994938983}
1626994938.961513: {"feed":"book","product_id":"PI_ETHUSD","side":"sell","seq":26662286,"price":2013.45,"qty":0.0,"timestamp":1626994938983}
1626994938.961559: {"feed":"book","product_id":"PI_ETHUSD","side":"sell","seq":26662287,"price":2013.45,"qty":49554.0,"timestamp":1626994938983}
1626994938.96159: {"feed":"book","product_id":"PI_ETHUSD","side":"buy","seq":26662288,"price":1993.2,"qty":0.0,"timestamp":1626994938983}
1626994938.961619: {"feed":"book","product_id":"PI_ETHUSD","side":"buy","seq":26662289,"price":1993.2,"qty":55166.0,"timestamp":1626994938983}
1626994938.962738: {"feed":"book","product_id":"FI_XBTUSD_210730","side":"sell","seq":5160100,"price":32254.5,"qty":0.0,"timestamp":1626994938985}
1626994938.962825: {"feed":"book","product_id":"FI_XBTUSD_210730","side":"sell","seq":5160101,"price":32259.0,"qty":250001.0,"timestamp":1626994938985}
1626994938.9628649: {"feed":"book","product_id":"FI_XBTUSD_210924","side":"sell","seq":13501963,"price":32281.5,"qty":0.0,"timestamp":1626994938985}
1626994938.962899: {"feed":"book","product_id":"FI_XBTUSD_210924","side":"sell","seq":13501964,"price":32290.0,"qty":250001.0,"timestamp":1626994938985}
1626994938.976507: {"feed":"book","product_id":"FI_XBTUSD_210924","side":"buy","seq":13501965,"price":32152.0,"qty":0.0,"timestamp":1626994938998}
1626994938.97663: {"feed":"book","product_id":"FI_XBTUSD_210924","side":"buy","seq":13501966,"price":32149.5,"qty":1500.0,"timestamp":1626994938998}
1626994938.9831371: {"feed":"book","product_id":"FI_XBTUSD_210730","side":"buy","seq":5160102,"price":32131.5,"qty":0.0,"timestamp":1626994938999}
1626994938.98326: {"feed":"book","product_id":"FI_XBTUSD_210730","side":"buy","seq":5160103,"price":32129.0,"qty":1500.0,"timestamp":1626994938999}
1626994938.983325: {"feed":"book","product_id":"PI_ETHUSD","side":"buy","seq":26662290,"price":2003.85,"qty":4162.0,"timestamp":1626994939000}
1626994938.98337: {"feed":"book","product_id":"PI_ETHUSD","side":"buy","seq":26662291,"price":2004.1,"qty":4566.0,"timestamp":1626994939001}
1626994938.987593: {"feed":"book","product_id":"FI_BCHUSD_210730","side":"sell","seq":91201,"price":439.8,"qty":0.0,"timestamp":1626994939009}
1626994938.9877179: {"feed":"book","product_id":"FI_BCHUSD_210730","side":"sell","seq":91202,"price":439.9,"qty":50.0,"timestamp":1626994939009}
1626994938.997257: {"feed":"book","product_id":"PI_ETHUSD","side":"buy","seq":26662292,"price":2004.05,"qty":68019.0,"timestamp":1626994939020}
1626994938.9973671: {"feed":"book","product_id":"PI_ETHUSD","side":"buy","seq":26662293,"price":2004.15,"qty":15826.0,"timestamp":1626994939020}
1626994939.000319: {"feed":"book","product_id":"FI_XBTUSD_210730","side":"sell","seq":5160104,"price":32208.5,"qty":0.0,"timestamp":1626994939022}
1626994939.000444: {"feed":"book","product_id":"FI_XBTUSD_210730","side":"sell","seq":5160105,"price":32210.0,"qty":103.0,"timestamp":1626994939022}
1626994939.0059168: {"feed":"book","product_id":"PI_ETHUSD","side":"sell","seq":26662294,"price":2006.65,"qty":0.0,"timestamp":1626994939029}
1626994939.008034: {"feed":"book","product_id":"PI_ETHUSD","side":"buy","seq":26662295,"price":2004.15,"qty":0.0,"timestamp":1626994939031}
1626994939.008157: {"feed":"book","product_id":"PI_ETHUSD","side":"buy","seq":26662296,"price":2004.05,"qty":83845.0,"timestamp":1626994939031}
1626994939.011297: {"feed":"book","product_id":"FI_XBTUSD_210730","side":"sell","seq":5160106,"price":32210.0,"qty":0.0,"timestamp":1626994939033}
1626994939.011422: {"feed":"book","product_id":"FI_XBTUSD_210730","side":"sell","seq":5160107,"price":32211.0,"qty":103.0,"timestamp":1626994939033}
1626994939.020719: {"feed":"book","product_id":"FI_XBTUSD_210924","side":"sell","seq":13501967,"price":32231.5,"qty":0.0,"timestamp":1626994939043}
1626994939.0208042: {"feed":"book","product_id":"FI_XBTUSD_210924","side":"sell","seq":13501968,"price":32232.5,"qty":103.0,"timestamp":1626994939043}
1626994939.0211189: {"feed":"book","product_id":"FI_XBTUSD_210924","side":"sell","seq":13501969,"price":32232.5,"qty":0.0,"timestamp":1626994939044}
1626994939.02117: {"feed":"book","product_id":"FI_XBTUSD_210924","side":"sell","seq":13501970,"price":32234.0,"qty":103.0,"timestamp":1626994939044}
1626994939.021205: {"feed":"book","product_id":"FI_XBTUSD_210730","side":"sell","seq":5160108,"price":32211.0,"qty":0.0,"timestamp":1626994939045}
1626994939.021237: {"feed":"book","product_id":"FI_XBTUSD_210730","side":"sell","seq":5160109,"price":32213.5,"qty":103.0,"timestamp":1626994939045}
1626994939.027523: {"feed":"book","product_id":"FI_XBTUSD_210924","side":"sell","seq":13501971,"price":32237.0,"qty":0.0,"timestamp":1626994939049}
1626994939.027651: {"feed":"book","product_id":"FI_XBTUSD_210924","side":"sell","seq":13501972,"price":32245.5,"qty":18905.0,"timestamp":1626994939049}
1626994939.033768: {"feed":"book","product_id":"PI_ETHUSD","side":"sell","seq":26662297,"price":2005.35,"qty":10000.0,"timestamp":1626994939056}
1626994939.03905: {"feed":"book","product_id":"FI_XBTUSD_210924","side":"sell","seq":13501973,"price":32234.0,"qty":0.0,"timestamp":1626994939058}
1626994939.0391748: {"feed":"book","product_id":"FI_XBTUSD_210924","side":"sell","seq":13501974,"price":32237.0,"qty":103.0,"timestamp":1626994939058}
1626994939.039241: {"feed":"book","product_id":"FI_XBTUSD_210730","side":"buy","seq":5160110,"price":32145.0,"qty":500.0,"timestamp":1626994939059}
1626994939.043821: {"feed":"book","product_id":"FI_XBTUSD_210924","side":"sell","seq":13501975,"price":32268.5,"qty":20965.0,"timestamp":1626994939066}
1626994939.043933: {"feed":"book","product_id":"FI_XBTUSD_210924","side":"buy","seq":13501976,"price":32177.0,"qty":708.0,"timestamp":1626994939066}
1626994939.057848: {"feed":"book","product_id":"FI_ETHUSD_211231","side":"buy","seq":2199097,"price":2028.0,"qty":177.0,"timestamp":1626994939080}
1626994939.067222: {"feed":"book","product_id":"FI_XBTUSD_210730","side":"sell","seq":5160111,"price":32213.5,"qty":0.0,"timestamp":1626994939089}
1626994939.067351: {"feed":"book","product_id":"FI_XBTUSD_210730","side":"sell","seq":5160112,"price":32215.0,"qty":30103.0,"timestamp":1626994939089}
1626994939.074601: {"feed":"book","product_id":"FI_XBTUSD_210924","side":"sell","seq":13501977,"price":32246.0,"qty":0.0,"timestamp":1626994939097}
1626994939.077879: {"feed":"book","product_id":"FI_ETHUSD_210730","side":"buy","seq":2138786,"price":1999.3,"qty":352.0,"timestamp":1626994939100}
1626994939.077965: {"feed":"book","product_id":"FI_XBTUSD_210730","side":"sell","seq":5160113,"price":32202.0,"qty":0.0,"timestamp":1626994939101}
1626994939.092269: {"feed":"book","product_id":"FI_XBTUSD_210924","side":"sell","seq":13501978,"price":32237.0,"qty":0.0,"timestamp":1626994939114}
1626994939.092392: {"feed":"book","product_id":"FI_XBTUSD_210924","side":"sell","seq":13501979,"price":32237.5,"qty":169673.0,"timestamp":1626994939114}
1626994939.102156: {"feed":"book","product_id":"FI_XBTUSD_210730","side":"buy","seq":5160114,"price":32147.5,"qty":0.0,"timestamp":1626994939124}
1626994939.10228: {"feed":"book","product_id":"FI_XBTUSD_210730","side":"buy","seq":5160115,"price":32154.0,"qty":4688.0,"timestamp":1626994939124}
1626994939.102345: {"feed":"book","product_id":"FI_XBTUSD_210924","side":"buy","seq":13501980,"price":32175.5,"qty":0.0,"timestamp":1626994939125}
1626994939.1023989: {"feed":"book","product_id":"FI_XBTUSD_210924","side":"buy","seq":13501981,"price":32182.0,"qty":3639.0,"timestamp":1626994939125}
1626994939.10889: {"feed":"book","product_id":"PI_ETHUSD","side":"buy","seq":26662298,"price":2003.7,"qty":4146.0,"timestamp":1626994939132}
1626994939.141037: {"feed":"book","product_id":"FI_BCHUSD_210924","side":"sell","seq":402234,"price":442.0,"qty":0.0,"timestamp":1626994939164}
1626994939.143135: {"feed":"book","product_id":"FI_XBTUSD_210924","side":"sell","seq":13501982,"price":32237.5,"qty":103.0,"timestamp":1626994939165}
1626994939.146399: {"feed":"book","product_id":"FI_XBTUSD_210924","side":"sell","seq":13501983,"price":32269.0,"qty":0.0,"timestamp":1626994939168}
1626994939.146522: {"feed":"book","product_id":"FI_XBTUSD_210924","side":"sell","seq":13501984,"price":32282.5,"qty":20000.0,"timestamp":1626994939168}
1626994939.154015: {"feed":"book","product_id":"PI_ETHUSD","side":"sell","seq":26662299,"price":2007.3,"qty":0.0,"timestamp":1626994939176}
1626994939.154102: {"feed":"book","product_id":"FI_BCHUSD_210924","side":"sell","seq":402235,"price":442.8,"qty":0.0,"timestamp":1626994939176}
1626994939.154143: {"feed":"book","product_id":"FI_BCHUSD_210924","side":"buy","seq":402236,"price":440.4,"qty":58.0,"timestamp":1626994939176}
1626994939.154179: {"feed":"book","product_id":"FI_BCHUSD_210924","side":"buy","seq":402237,"price":440.0,"qty":37701.0,"timestamp":1626994939176}
1626994939.154203: {"feed":"book","product_id":"PI_LTCUSD","side":"buy","seq":3423271,"price":119.25,"qty":830.0,"timestamp":1626994939176}
1626994939.154233: {"feed":"book","product_id":"PI_ETHUSD","side":"buy","seq":26662300,"price":2002.2,"qty":6556.0,"timestamp":1626994939177}
1626994939.170712: {"feed":"book","product_id":"PI_ETHUSD","side":"sell","seq":26662301,"price":2006.35,"qty":0.0,"timestamp":1626994939186}
1626994939.170845: {"feed":"book","product_id":"PI_ETHUSD","side":"sell","seq":26662302,"price":2007.1,"qty":13988.0,"timestamp":1626994939186}
1626994939.170937: {"feed":"book","product_id":"PI_ETHUSD","side":"buy","seq":26662303,"price":1993.2,"qty":0.0,"timestamp":1626994939186}
1626994939.170976: {"feed":"book","product_id":"PI_ETHUSD","side":"buy","seq":26662304,"price":1996.5,"qty":45159.0,"timestamp":1626994939186}
1626994939.171006: {"feed":"book","product_id":"PI_ETHUSD","side":"sell","seq":26662305,"price":2007.4,"qty":0.0,"timestamp":1626994939187}
1626994939.171036: {"feed":"book","product_id":"PI_ETHUSD","side":"sell","seq":26662306,"price":2007.7,"qty":26906.0,"timestamp":1626994939187}
1626994939.171058: {"feed":"book","product_id":"PI_ETHUSD","side":"sell","seq":26662307,"price":2008.15,"qty":4990.0,"timestamp":1626994939187}
1626994939.171081: {"feed":"book","product_id":"PI_ETHUSD","side":"sell","seq":26662308,"price":2008.4,"qty":23559.0,"timestamp":1626994939187}
1626994939.171106: {"feed":"book","product_id":"FI_XRPUSD_210924","side":"buy","seq":602287,"price":0.5839,"qty":48.0,"timestamp":1626994939188}
1626994939.171134: {"feed":"book","product_id":"PI_ETHUSD","side":"buy","seq":26662309,"price":2000.05,"qty":0.0,"timestamp":1626994939187}
1626994939.1711621: {"feed":"book","product_id":"PI_ETHUSD","side":"buy","seq":26662310,"price":2000.55,"qty":22855.0,"timestamp":1626994939187}
1626994939.1711879: {"feed":"book","product_id":"FI_XRPUSD_210924","side":"sell","seq":602288,"price":0.5876,"qty":0.0,"timestamp":1626994939188}
1626994939.1712158: {"feed":"book","product_id":"FI_BCHUSD_210924","side":"sell","seq":402238,"price":443.0,"qty":67.0,"timestamp":1626994939191}
1626994939.173068: {"feed":"book","product_id":"PI_ETHUSD","side":"buy","seq":26662311,"price":1993.25,"qty":0.0,"timestamp":1626994939194}
1626994939.173163: {"feed":"book","product_id":"PI_ETHUSD","side":"buy","seq":26662312,"price":1993.15,"qty":500002.0,"timestamp":1626994939194}
1626994939.173538: {"feed":"book","product_id":"FI_XBTUSD_210924","side":"sell","seq":13501985,"price":32251.5,"qty":0.0,"timestamp":1626994939197}
1626994939.1736052: {"feed":"book","product_id":"FI_XBTUSD_210924","side":"sell","seq":13501986,"price":32279.5,"qty":0.0,"timestamp":1626994939197}
1626994939.175526: {"feed":"book","product_id":"FI_XBTUSD_210924","side":"sell","seq":13501987,"price":32298.0,"qty":0.0,"timestamp":1626994939197}
1626994939.180765: {"feed":"book","product_id":"PI_ETHUSD","side":"buy","seq":26662313,"price":2004.1,"qty":600.0,"timestamp":1626994939200}
1626994939.180844: {"feed":"book","product_id":"FI_ETHUSD_211231","side":"buy","seq":2199098,"price":2029.4,"qty":0.0,"timestamp":1626994939201}
1626994939.1808908: {"feed":"book","product_id":"FI_ETHUSD_211231","side":"buy","seq":2199099,"price":2029.5,"qty":420.0,"timestamp":1626994939201}
1626994939.180925: {"feed":"book","product_id":"FI_XBTUSD_210730","side":"buy","seq":5160116,"price":32175.5,"qty":0.0,"timestamp":1626994939201}
1626994939.180958: {"feed":"book","product_id":"FI_XBTUSD_210730","side":"buy","seq":5160117,"price":32176.5,"qty":1200.0,"timestamp":1626994939201}
1626994939.180984: {"feed":"book","product_id":"FI_XBTUSD_210924","side":"sell","seq":13501988,"price":32282.5,"qty":0.0,"timestamp":1626994939201}
1626994939.181015: {"feed":"book","product_id":"FI_XBTUSD_210924","side":"sell","seq":13501989,"price":32290.5,"qty":74000.0,"timestamp":1626994939201}
1626994939.1827579: {"feed":"book","product_id":"FI_XBTUSD_210730","side":"buy","seq":5160118,"price":32129.0,"qty":0.0,"timestamp":1626994939205}
1626994939.182849: {"feed":"book","product_id":"FI_XBTUSD_210730","side":"buy","seq":5160119,"price":32130.0,"qty":1500.0,"timestamp":1626994939205}
1626994939.2051609: {"feed":"book","product_id":"FI_XBTUSD_210730","side":"buy","seq":5160120,"price":32176.0,"qty":0.0,"timestamp":1626994939227}
1626994939.205291: {"feed":"book","product_id":"FI_XBTUSD_210730","side":"buy","seq":5160121,"price":32177.0,"qty":50.0,"timestamp":1626994939227}
1626994939.230628: {"feed":"book","product_id":"FI_XBTUSD_210924","side":"sell","seq":13501990,"price":32268.5,"qty":0.0,"timestamp":1626994939252}
1626994939.2307541: {"feed":"book","product_id":"FI_XBTUSD_210924","side":"sell","seq":13501991,"price":32279.0,"qty":20969.0,"timestamp":1626994939252}
1626994939.2308202: {"feed":"book","product_id":"FI_XBTUSD_210924","side":"buy","seq":13501992,"price":32175.0,"qty":0.0,"timestamp":1626994939252}
1626994939.230874: {"feed":"book","product_id":"FI_XBTUSD_210924","side":"buy","seq":13501993,"price":32181.5,"qty":20912.0,"timestamp":1626994939252}
1626994939.244069: {"feed":"book","product_id":"FI_XBTUSD_210924","side":"sell","seq":13501994,"price":32257.5,"qty":0.0,"timestamp":1626994939265}
1626994939.244155: {"feed":"book","product_id":"FI_XBTUSD_210924","side":"buy","seq":13501995,"price":32077.5,"qty":0.0,"timestamp":1626994939265}
1626994939.244195: {"feed":"book","product_id":"FI_XBTUSD_210924","side":"sell","seq":13501996,"price":32358.0,"qty":0.0,"timestamp":1626994939265}
1626994939.261513: {"feed":"book","product_id":"FI_ETHUSD_211231","side":"sell","seq":2199100,"price":2049.1,"qty":44305.0,"timestamp":1626994939283}
1626994939.261622: {"feed":"book","product_id":"FI_ETHUSD_211231","side":"sell","seq":2199101,"price":2049.0,"qty":45099.0,"timestamp":1626994939283}
1626994939.261686: {"feed":"book","product_id":"FI_ETHUSD_211231","side":"sell","seq":2199102,"price":2049.1,"qty":0.0,"timestamp":1626994939283}
1626994939.261764: {"feed":"book","product_id":"FI_ETHUSD_211231","side":"sell","seq":2199103,"price":2049.0,"qty":89404.0,"timestamp":1626994939283}
1626994939.2709289: {"feed":"book","product_id":"FI_XBTUSD_210924","side":"buy","seq":13501997,"price":32206.5,"qty":3000.0,"timestamp":1626994939293}
1626994939.2750862: {"feed":"book","product_id":"FI_XBTUSD_210924","side":"buy","seq":13501998,"price":32149.5,"qty":0.0,"timestamp":1626994939297}
1626994939.275143: {"feed":"book","product_id":"FI_XBTUSD_210924","side":"buy","seq":13501999,"price":32150.5,"qty":2289.0,"timestamp":1626994939297}
1626994939.284151: {"feed":"book","product_id":"PI_ETHUSD","side":"buy","seq":26662314,"price":2004.05,"qty":68019.0,"timestamp":1626994939305}
1626994939.284262: {"feed":"book","product_id":"PI_ETHUSD","side":"buy","seq":26662315,"price":2003.75,"qty":15826.0,"timestamp":1626994939305}
1626994939.284329: {"feed":"book","product_id":"PI_ETHUSD","side":"buy","seq":26662316,"price":2004.05,"qty":48019.0,"timestamp":1626994939306}
1626994939.2843678: {"feed":"book","product_id":"PI_ETHUSD","side":"buy","seq":26662317,"price":2003.7,"qty":24146.0,"timestamp":1626994939306}
1626994939.294253: {"feed":"book","product_id":"FI_BCHUSD_210730","side":"sell","seq":91203,"price":440.0,"qty":0.0,"timestamp":1626994939316}
1626994939.298003: {"feed":"book","product_id":"PI_LTCUSD","side":"sell","seq":3423272,"price":119.58,"qty":0.0,"timestamp":1626994939315}
1626994939.2981288: {"feed":"book","product_id":"PI_LTCUSD","side":"buy","seq":3423273,"price":119.28,"qty":33194.0,"timestamp":1626994939319}
1626994939.2981849: {"feed":"book","product_id":"PI_LTCUSD","side":"buy","seq":3423274,"price":119.29,"qty":1000.0,"timestamp":1626994939319}
1626994939.306654: {"feed":"book","product_id":"FI_XBTUSD_210924","side":"sell","seq":13502000,"price":32359.0,"qty":0.0,"timestamp":1626994939328}
1626994939.306784: {"feed":"book","product_id":"FI_XBTUSD_210924","side":"sell","seq":13502001,"price":32418.0,"qty":250002.0,"timestamp":1626994939328}
1626994939.30685: {"feed":"book","product_id":"FI_XBTUSD_210730","side":"sell","seq":5160122,"price":32259.0,"qty":0.0,"timestamp":1626994939328}
1626994939.3069031: {"feed":"book","product_id":"FI_XBTUSD_210730","side":"sell","seq":5160123,"price":32277.5,"qty":256401.0,"timestamp":1626994939328}
1626994939.306942: {"feed":"book","product_id":"FI_ETHUSD_211231","side":"sell","seq":2199104,"price":2049.05,"qty":0.0,"timestamp":1626994939328}
1626994939.307009: {"feed":"book","product_id":"FI_ETHUSD_211231","side":"sell","seq":2199105,"price":2048.95,"qty":250002.0,"timestamp":1626994939328}
1626994939.3103108: {"feed":"book","product_id":"FI_XBTUSD_210924","side":"sell","seq":13502002,"price":32245.5,"qty":16475.0,"timestamp":1626994939332}
1626994939.310436: {"feed":"book","product_id":"FI_XBTUSD_210924","side":"buy","seq":13502003,"price":32183.5,"qty":0.0,"timestamp":1626994939332}
1626994939.310485: {"feed":"book","product_id":"FI_XBTUSD_210924","side":"sell","seq":13502004,"price":32259.0,"qty":156830.0,"timestamp":1626994939332}
1626994939.310512: {"feed":"book","product_id":"FI_XBTUSD_210924","side":"buy","seq":13502005,"price":32160.5,"qty":0.0,"timestamp":1626994939332}
1626994939.310542: {"feed":"book","product_id":"PI_ETHUSD","side":"sell","seq":26662318,"price":2005.25,"qty":2250.0,"timestamp":1626994939334}
1626994939.313416: {"feed":"book","product_id":"FI_XBTUSD_210924","side":"buy","seq":13502006,"price":32206.5,"qty":0.0,"timestamp":1626994939335}
1626994939.326253: {"feed":"book","product_id":"FI_XBTUSD_210924","side":"buy","seq":13502007,"price":32203.5,"qty":0.0,"timestamp":1626994939347}
1626994939.32638: {"feed":"book","product_id":"FI_XBTUSD_210924","side":"buy","seq":13502008,"price":32207.0,"qty":50.0,"timestamp":1626994939347}
1626994939.3614972: {"feed":"book","product_id":"FI_XBTUSD_210924","side":"buy","seq":13502009,"price":32165.5,"qty":211781.0,"timestamp":1626994939383}
1626994939.36154: {"feed":"book","product_id":"FI_XBTUSD_210924","side":"buy","seq":13502010,"price":32137.5,"qty":0.0,"timestamp":1626994939383}
1626994939.3615801: {"feed":"book","product_id":"FI_XBTUSD_210924","side":"buy","seq":13502011,"price":32100.5,"qty":800.0,"timestamp":1626994939383}
1626994939.362175: {"feed":"book","product_id":"PI_ETHUSD","side":"sell","seq":26662319,"price":2006.5,"qty":45376.0,"timestamp":1626994939385}
1626994939.368119: {"feed":"book","product_id":"PI_ETHUSD","side":"buy","seq":26662320,"price":2001.25,"qty":155068.0,"timestamp":1626994939390}
1626994939.368226: {"feed":"book","product_id":"PI_ETHUSD","side":"buy","seq":26662321,"price":2001.5,"qty":15938.0,"timestamp":1626994939390}
1626994939.371234: {"feed":"book","product_id":"FI_XBTUSD_210924","side":"buy","seq":13502012,"price":32138.0,"qty":0.0,"timestamp":1626994939393}
1626994939.371357: {"feed":"book","product_id":"FI_XBTUSD_210924","side":"buy","seq":13502013,"price":32130.0,"qty":250001.0,"timestamp":1626994939393}
1626994939.374437: {"feed":"book","product_id":"FI_XBTUSD_210730","side":"sell","seq":5160124,"price":32201.0,"qty":0.0,"timestamp":1626994939397}
1626994939.37456: {"feed":"book","product_id":"FI_XBTUSD_210730","side":"sell","seq":5160125,"price":32204.5,"qty":1200.0,"timestamp":1626994939397}
1626994939.374623: {"feed":"book","product_id":"FI_XBTUSD_210924","side":"buy","seq":13502014,"price":32203.0,"qty":0.0,"timestamp":1626994939396}
1626994939.374677: {"feed":"book","product_id":"FI_XBTUSD_210924","side":"buy","seq":13502015,"price":32204.0,"qty":1080.0,"timestamp":1626994939396}
1626994939.378847: {"feed":"book","product_id":"FI_XBTUSD_210924","side":"buy","seq":13502016,"price":32110.0,"qty":0.0,"timestamp":1626994939398}
1626994939.3789709: {"feed":"book","product_id":"FI_XBTUSD_210924","side":"buy","seq":13502017,"price":32133.0,"qty":54000.0,"timestamp":1626994939398}
1626994939.379034: {"feed":"book","product_id":"FI_XBTUSD_210730","side":"buy","seq":5160126,"price":32162.0,"qty":0.0,"timestamp":1626994939401}
1626994939.379085: {"feed":"book","product_id":"FI_XBTUSD_210730","side":"buy","seq":5160127,"price":32169.5,"qty":30000.0,"timestamp":1626994939401}
1626994939.3841689: {"feed":"book","product_id":"PI_ETHUSD","side":"sell","seq":26662322,"price":2005.25,"qty":0.0,"timestamp":1626994939406}
1626994939.3842938: {"feed":"book","product_id":"PI_ETHUSD","side":"sell","seq":26662323,"price":2005.45,"qty":1.0,"timestamp":1626994939406}
1626994939.3866339: {"feed":"book","product_id":"FI_XBTUSD_210924","side":"buy","seq":13502018,"price":32130.0,"qty":0.0,"timestamp":1626994939408}
1626994939.3867579: {"feed":"book","product_id":"FI_XBTUSD_210924","side":"buy","seq":13502019,"price":32133.5,"qty":252401.0,"timestamp":1626994939408}
1626994939.3868108: {"feed":"book","product_id":"FI_XBTUSD_210924","side":"sell","seq":13502020,"price":32235.5,"qty":0.0,"timestamp":1626994939409}
1626994939.4185941: {"feed":"book","product_id":"FI_XBTUSD_210730","side":"sell","seq":5160128,"price":32253.5,"qty":0.0,"timestamp":1626994939441}
1626994939.4187179: {"feed":"book","product_id":"FI_XBTUSD_210730","side":"buy","seq":5160129,"price":32120.0,"qty":0.0,"timestamp":1626994939442}
1626994939.419307: {"feed":"book","product_id":"FI_XBTUSD_210730","side":"buy","seq":5160130,"price":32152.5,"qty":433.0,"timestamp":1626994939442}
1626994939.422585: {"feed":"book","product_id":"FI_XBTUSD_210924","side":"sell","seq":13502021,"price":32277.0,"qty":0.0,"timestamp":1626994939445}
1626994939.422682: {"feed":"book","product_id":"FI_XBTUSD_210924","side":"sell","seq":13502022,"price":32288.5,"qty":1088.0,"timestamp":1626994939446}
1626994939.433561: {"feed":"book","product_id":"FI_XBTUSD_210924","side":"sell","seq":13502023,"price":32245.5,"qty":0.0,"timestamp":1626994939456}
1626994939.4336882: {"feed":"book","product_id":"FI_XBTUSD_210924","side":"sell","seq":13502024,"price":32246.0,"qty":14960.0,"timestamp":1626994939456}
1626994939.4337542: {"feed":"book","product_id":"FI_XBTUSD_210924","side":"buy","seq":13502025,"price":32162.0,"qty":0.0,"timestamp":1626994939456}
1626994939.4338062: {"feed":"book","product_id":"FI_XBTUSD_210924","side":"sell","seq":13502026,"price":32295.0,"qty":0.0,"timestamp":1626994939457}
1626994939.433849: {"feed":"book","product_id":"FI_XBTUSD_210924","side":"buy","seq":13502027,"price":32124.5,"qty":18973.0,"timestamp":1626994939457}
1626994939.4338849: {"feed":"book","product_id":"FI_XBTUSD_210924","side":"buy","seq":13502028,"price":32040.0,"qty":0.0,"timestamp":1626994939457}
1626994939.451676: {"feed":"book","product_id":"FI_ETHUSD_210730","side":"buy","seq":2138787,"price":1999.8,"qty":433.0,"timestamp":1626994939474}
1626994939.451802: {"feed":"book","product_id":"FI_XBTUSD_210924","side":"sell","seq":13502029,"price":32245.5,"qty":924.0,"timestamp":1626994939474}
1626994939.4762099: {"feed":"book","product_id":"PI_LTCUSD","side":"sell","seq":3423275,"price":119.73,"qty":4118.0,"timestamp":1626994939498}
1626994939.476318: {"feed":"book","product_id":"PI_LTCUSD","side":"sell","seq":3423276,"price":119.93,"qty":10531.0,"timestamp":1626994939498}
1626994939.50578: {"feed":"book","product_id":"FI_XBTUSD_210924","side":"sell","seq":13502030,"price":32237.5,"qty":0.0,"timestamp":1626994939528}
1626994939.505866: {"feed":"book","product_id":"FI_XBTUSD_210924","side":"sell","seq":13502031,"price":32238.5,"qty":103.0,"timestamp":1626994939528}
1626994939.5209239: {"feed":"book","product_id":"FI_XBTUSD_210730","side":"sell","seq":5160131,"price":32215.0,"qty":30000.0,"timestamp":1626994939544}
1626994939.521031: {"feed":"book","product_id":"FI_XBTUSD_210730","side":"sell","seq":5160132,"price":32216.5,"qty":103.0,"timestamp":1626994939544}
1626994939.53166: {"feed":"book","product_id":"FI_BCHUSD_210924","side":"buy","seq":402239,"price":440.1,"qty":0.0,"timestamp":1626994939552}
1626994939.5317838: {"feed":"book","product_id":"FI_BCHUSD_210924","side":"sell","seq":402240,"price":442.9,"qty":37229.0,"timestamp":1626994939552}
1626994939.531841: {"feed":"book","product_id":"FI_BCHUSD_210924","side":"buy","seq":402241,"price":440.5,"qty":62.0,"timestamp":1626994939552}
1626994939.5318909: {"feed":"book","product_id":"FI_BCHUSD_210924","side":"sell","seq":402242,"price":443.1,"qty":62.0,"timestamp":1626994939552}
1626994939.571109: {"feed":"book","product_id":"PI_ETHUSD","side":"buy","seq":26662324,"price":2001.5,"qty":0.0,"timestamp":1626994939594}
1626994939.5712352: {"feed":"book","product_id":"PI_ETHUSD","side":"buy","seq":26662325,"price":2001.3,"qty":17005.0,"timestamp":1626994939594}
1626994939.583835: {"feed":"book","product_id":"FI_XBTUSD_210730","side":"sell","seq":5160133,"price":32216.5,"qty":0.0,"timestamp":1626994939606}
1626994939.583958: {"feed":"book","product_id":"FI_XBTUSD_210730","side":"sell","seq":5160134,"price":32218.5,"qty":103.0,"timestamp":1626994939606}
1626994939.6019251: {"feed":"book","product_id":"FI_XBTUSD_210924","side":"sell","seq":13502032,"price":32290.0,"qty":0.0,"timestamp":1626994939624}
1626994939.60205: {"feed":"book","product_id":"FI_XBTUSD_210924","side":"sell","seq":13502033,"price":32307.0,"qty":250001.0,"timestamp":1626994939624}
1626994939.6042619: {"feed":"book","product_id":"FI_XBTUSD_210924","side":"sell","seq":13502034,"price":32238.5,"qty":0.0,"timestamp":1626994939624}
1626994939.604386: {"feed":"book","product_id":"FI_XBTUSD_210924","side":"sell","seq":13502035,"price":32241.0,"qty":103.0,"timestamp":1626994939624}
1626994939.6044512: {"feed":"book","product_id":"FI_XBTUSD_210924","side":"sell","seq":13502036,"price":32277.5,"qty":0.0,"timestamp":1626994939625}
1626994939.6044989: {"feed":"book","product_id":"FI_XBTUSD_210924","side":"buy","seq":13502037,"price":32129.5,"qty":301599.0,"timestamp":1626994939625}
1626994939.604539: {"feed":"book","product_id":"FI_XBTUSD_210924","side":"sell","seq":13502038,"price":32290.5,"qty":54000.0,"timestamp":1626994939628}
1626994939.6045718: {"feed":"book","product_id":"FI_XBTUSD_210924","side":"sell","seq":13502039,"price":32291.0,"qty":20000.0,"timestamp":1626994939628}
1626994939.609399: {"feed":"book","product_id":"FI_ETHUSD_211231","side":"buy","seq":2199106,"price":2029.45,"qty":0.0,"timestamp":1626994939631}
1626994939.609525: {"feed":"book","product_id":"FI_ETHUSD_211231","side":"buy","seq":2199107,"price":2029.55,"qty":50.0,"timestamp":1626994939631}
1626994939.6245198: {"feed":"book","product_id":"FI_ETHUSD_210730","side":"buy","seq":2138788,"price":1992.0,"qty":0.0,"timestamp":1626994939647}
1626994939.6246452: {"feed":"book","product_id":"FI_ETHUSD_210730","side":"buy","seq":2138789,"price":1992.1,"qty":44704.0,"timestamp":1626994939647}
1626994939.6247108: {"feed":"book","product_id":"FI_ETHUSD_210730","side":"sell","seq":2138790,"price":2014.15,"qty":0.0,"timestamp":1626994939647}
1626994939.6247659: {"feed":"book","product_id":"FI_ETHUSD_210730","side":"sell","seq":2138791,"price":2014.05,"qty":45421.0,"timestamp":1626994939647}
1626994939.624813: {"feed":"book","product_id":"FI_XBTUSD_210924","side":"buy","seq":13502040,"price":32182.5,"qty":0.0,"timestamp":1626994939648}
1626994939.6264262: {"feed":"book","product_id":"FI_XBTUSD_210924","side":"buy","seq":13502041,"price":32181.0,"qty":0.0,"timestamp":1626994939649}
1626994939.634348: {"feed":"book","product_id":"PI_LTCUSD","side":"buy","seq":3423277,"price":119.22,"qty":37124.0,"timestamp":1626994939656}
1626994939.634457: {"feed":"book","product_id":"PI_LTCUSD","side":"buy","seq":3423278,"price":119.26,"qty":8979.0,"timestamp":1626994939656}
1626994939.634506: {"feed":"book","product_id":"PI_LTCUSD","side":"buy","seq":3423279,"price":119.3,"qty":9893.0,"timestamp":1626994939656}
1626994939.6345441: {"feed":"book","product_id":"PI_LTCUSD","side":"buy","seq":3423280,"price":119.24,"qty":0.0,"timestamp":1626994939656}
1626994939.634617: {"feed":"book","product_id":"PI_LTCUSD","side":"buy","seq":3423281,"price":119.16,"qty":0.0,"timestamp":1626994939657}
1626994939.634645: {"feed":"book","product_id":"PI_LTCUSD","side":"buy","seq":3423282,"price":119.2,"qty":0.0,"timestamp":1626994939657}
1626994939.6346722: {"feed":"book","product_id":"FI_XBTUSD_210924","side":"sell","seq":13502042,"price":32260.0,"qty":0.0,"timestamp":1626994939657}
1626994939.6383119: {"feed":"book","product_id":"FI_XBTUSD_210924","side":"sell","seq":13502043,"price":32279.0,"qty":0.0,"timestamp":1626994939660}
1626994939.638436: {"feed":"book","product_id":"FI_XBTUSD_210924","side":"sell","seq":13502044,"price":32281.5,"qty":20967.0,"timestamp":1626994939660}
1626994939.645865: {"feed":"book","product_id":"FI_XBTUSD_210924","side":"buy","seq":13502045,"price":32150.5,"qty":789.0,"timestamp":1626994939668}
1626994939.645973: {"feed":"book","product_id":"FI_XBTUSD_210924","side":"buy","seq":13502046,"price":32152.0,"qty":1500.0,"timestamp":1626994939668}
1626994939.646038: {"feed":"book","product_id":"FI_XBTUSD_210730","side":"buy","seq":5160135,"price":32130.0,"qty":0.0,"timestamp":1626994939667}
1626994939.646095: {"feed":"book","product_id":"FI_XBTUSD_210730","side":"buy","seq":5160136,"price":32131.0,"qty":1500.0,"timestamp":1626994939667}
1626994939.721511: {"feed":"book","product_id":"FI_XBTUSD_210924","side":"buy","seq":13502047,"price":32174.0,"qty":3000.0,"timestamp":1626994939744}
1626994939.721631: {"feed":"book","product_id":"FI_XBTUSD_210924","side":"sell","seq":13502048,"price":32267.0,"qty":3000.0,"timestamp":1626994939744}
1626994939.721691: {"feed":"book","product_id":"FI_XBTUSD_210924","side":"buy","seq":13502049,"price":32146.0,"qty":20865.0,"timestamp":1626994939744}
1626994939.72239: {"feed":"book","product_id":"FI_XBTUSD_210924","side":"sell","seq":13502050,"price":32295.0,"qty":16110.0,"timestamp":1626994939744}
1626994939.72249: {"feed":"book","product_id":"FI_XBTUSD_210924","side":"buy","seq":13502051,"price":32117.5,"qty":27265.0,"timestamp":1626994939744}
1626994939.722553: {"feed":"book","product_id":"FI_XBTUSD_210924","side":"sell","seq":13502052,"price":32323.5,"qty":16110.0,"timestamp":1626994939744}
1626994939.795269: {"feed":"book","product_id":"PI_ETHUSD","side":"buy","seq":26662326,"price":2001.3,"qty":0.0,"timestamp":1626994939816}
1626994939.795397: {"feed":"book","product_id":"PI_ETHUSD","side":"buy","seq":26662327,"price":2001.5,"qty":15938.0,"timestamp":1626994939816}
1626994939.798404: {"feed":"book","product_id":"PI_LTCUSD","side":"sell","seq":3423283,"price":119.64,"qty":33707.0,"timestamp":1626994939821}
1626994939.814421: {"feed":"book","product_id":"FI_XBTUSD_210924","side":"sell","seq":13502053,"price":32333.0,"qty":0.0,"timestamp":1626994939837}
1626994939.818228: {"feed":"book","product_id":"FI_XBTUSD_210924","side":"buy","seq":13502054,"price":32029.0,"qty":0.0,"timestamp":1626994939839}
1626994939.852107: {"feed":"book","product_id":"FI_XBTUSD_210924","side":"sell","seq":13502055,"price":32246.0,"qty":0.0,"timestamp":1626994939874}
1626994939.852231: {"feed":"book","product_id":"FI_XBTUSD_210924","side":"sell","seq":13502056,"price":32258.5,"qty":17495.0,"timestamp":1626994939874}
1626994939.858607: {"feed":"book","product_id":"FI_XBTUSD_210924","side":"buy","seq":13502057,"price":32194.0,"qty":1900.0,"timestamp":1626994939881}
1626994939.858727: {"feed":"book","product_id":"FI_XBTUSD_210924","side":"sell","seq":13502058,"price":32254.0,"qty":2440.0,"timestamp":1626994939881}
1626994939.858783: {"feed":"book","product_id":"FI_XBTUSD_210924","side":"buy","seq":13502059,"price":32175.0,"qty":1900.0,"timestamp":1626994939881}
1626994939.859297: {"feed":"book","product_id":"FI_XBTUSD_210924","side":"sell","seq":13502060,"price":32273.0,"qty":2440.0,"timestamp":1626994939881}
1626994939.8593469: {"feed":"book","product_id":"FI_ETHUSD_211231","side":"sell","seq":2199108,"price":2049.0,"qty":44305.0,"timestamp":1626994939882}
1626994939.8593762: {"feed":"book","product_id":"FI_ETHUSD_211231","side":"sell","seq":2199109,"price":2048.9,"qty":45099.0,"timestamp":1626994939882}
1626994939.859405: {"feed":"book","product_id":"FI_XBTUSD_210924","side":"buy","seq":13502061,"price":32156.5,"qty":1900.0,"timestamp":1626994939881}
1626994939.8594298: {"feed":"book","product_id":"FI_ETHUSD_211231","side":"sell","seq":2199110,"price":2049.0,"qty":0.0,"timestamp":1626994939882}
1626994939.859463: {"feed":"book","product_id":"FI_ETHUSD_211231","side":"sell","seq":2199111,"price":2048.9,"qty":89404.0,"timestamp":1626994939882}
1626994939.859484: {"feed":"book","product_id":"FI_XBTUSD_210924","side":"sell","seq":13502062,"price":32310.5,"qty":2440.0,"timestamp":1626994939881}
1626994939.926839: {"feed":"book","product_id":"PI_LTCUSD","side":"sell","seq":3423284,"price":119.53,"qty":22446.0,"timestamp":1626994939949}
1626994939.930783: {"feed":"book","product_id":"PI_LTCUSD","side":"buy","seq":3423285,"price":119.29,"qty":0.0,"timestamp":1626994939952}
1626994939.930912: {"feed":"book","product_id":"PI_LTCUSD","side":"buy","seq":3423286,"price":119.26,"qty":9979.0,"timestamp":1626994939952}
1626994939.939608: {"feed":"book","product_id":"PI_XRPUSD","side":"buy","seq":3456224,"price":0.5688,"qty":2.0,"timestamp":1626994939962}
1626994939.978775: {"feed":"book","product_id":"PI_ETHUSD","side":"buy","seq":26662328,"price":2004.1,"qty":4396.0,"timestamp":1626994940000}
1626994939.991951: {"feed":"book","product_id":"FI_XBTUSD_210730","side":"sell","seq":5160137,"price":32218.5,"qty":0.0,"timestamp":1626994940013}
1626994939.992078: {"feed":"book","product_id":"FI_XBTUSD_210730","side":"sell","seq":5160138,"price":32217.5,"qty":103.0,"timestamp":1626994940013}
1626994939.992424: {"feed":"book","product_id":"PI_ETHUSD","side":"buy","seq":26662329,"price":2003.3,"qty":0.0,"timestamp":1626994940015}
1626994939.994802: {"feed":"book","product_id":"FI_XBTUSD_210924","side":"sell","seq":13502063,"price":32267.0,"qty":0.0,"timestamp":1626994940017}
1626994940.0089989: {"feed":"book","product_id":"FI_XBTUSD_210924","side":"sell","seq":13502064,"price":32241.0,"qty":0.0,"timestamp":1626994940031}
1626994940.009124: {"feed":"book","product_id":"FI_XBTUSD_210924","side":"sell","seq":13502065,"price":32240.0,"qty":103.0,"timestamp":1626994940031}
1626994940.016188: {"feed":"book","product_id":"FI_XBTUSD_210924","side":"buy","seq":13502066,"price":32188.5,"qty":17944.0,"timestamp":1626994940039}
1626994940.016265: {"feed":"book","product_id":"PI_ETHUSD","side":"sell","seq":26662330,"price":2013.45,"qty":0.0,"timestamp":1626994940039}
1626994940.016314: {"feed":"book","product_id":"PI_ETHUSD","side":"sell","seq":26662331,"price":2013.35,"qty":48475.0,"timestamp":1626994940039}
1626994940.0167758: {"feed":"book","product_id":"PI_ETHUSD","side":"buy","seq":26662332,"price":2001.85,"qty":5005.0,"timestamp":1626994940039}
1626994940.016832: {"feed":"book","product_id":"PI_ETHUSD","side":"buy","seq":26662333,"price":2001.85,"qty":18907.0,"timestamp":1626994940039}
1626994940.016864: {"feed":"book","product_id":"PI_ETHUSD","side":"sell","seq":26662334,"price":2007.7,"qty":8742.0,"timestamp":1626994940039}
1626994940.0168881: {"feed":"book","product_id":"PI_ETHUSD","side":"sell","seq":26662335,"price":2007.7,"qty":26059.0,"timestamp":1626994940039}
1626994940.019834: {"feed":"book","product_id":"PI_ETHUSD","side":"sell","seq":26662336,"price":2007.1,"qty":0.0,"timestamp":1626994940040}
1626994940.019884: {"feed":"book","product_id":"PI_ETHUSD","side":"sell","seq":26662337,"price":2007.1,"qty":13424.0,"timestamp":1626994940040}
1626994940.019915: {"feed":"book","product_id":"PI_ETHUSD","side":"sell","seq":26662338,"price":2008.4,"qty":0.0,"timestamp":1626994940040}
1626994940.0199418: {"feed":"book","product_id":"PI_ETHUSD","side":"sell","seq":26662339,"price":2008.4,"qty":22993.0,"timestamp":1626994940040}
1626994940.019965: {"feed":"book","product_id":"PI_ETHUSD","side":"buy","seq":26662340,"price":2000.55,"qty":0.0,"timestamp":1626994940040}
1626994940.019989: {"feed":"book","product_id":"PI_ETHUSD","side":"buy","seq":26662341,"price":2000.55,"qty":23414.0,"timestamp":1626994940040}
1626994940.02001: {"feed":"book","product_id":"PI_ETHUSD","side":"buy","seq":26662342,"price":1996.5,"qty":0.0,"timestamp":1626994940040}
1626994940.020032: {"feed":"book","product_id":"PI_ETHUSD","side":"buy","seq":26662343,"price":1996.5,"qty":45477.0,"timestamp":1626994940040}
1626994940.020051: {"feed":"book","product_id":"PI_ETHUSD","side":"buy","seq":26662344,"price":2001.5,"qty":0.0,"timestamp":1626994940040}
1626994940.020072: {"feed":"book","product_id":"PI_ETHUSD","side":"buy","seq":26662345,"price":2001.5,"qty":15934.0,"timestamp":1626994940040}
1626994940.0200908: {"feed":"book","product_id":"PI_ETHUSD","side":"buy","seq":26662346,"price":1985.1,"qty":0.0,"timestamp":1626994940040}
1626994940.020111: {"feed":"book","product_id":"PI_ETHUSD","side":"buy","seq":26662347,"price":1985.1,"qty":66950.0,"timestamp":1626994940040}
1626994940.0201302: {"feed":"book","product_id":"PI_ETHUSD","side":"sell","seq":26662348,"price":2021.45,"qty":0.0,"timestamp":1626994940040}
1626994940.0201511: {"feed":"book","product_id":"PI_ETHUSD","side":"sell","seq":26662349,"price":2021.45,"qty":67947.0,"timestamp":1626994940040}
1626994940.055788: {"feed":"book","product_id":"FI_XBTUSD_210924","side":"buy","seq":13502067,"price":32181.5,"qty":0.0,"timestamp":1626994940077}
1626994940.0559201: {"feed":"book","product_id":"FI_XBTUSD_210924","side":"buy","seq":13502068,"price":32175.0,"qty":22811.0,"timestamp":1626994940077}
1626994940.075111: {"feed":"book","product_id":"FI_XBTUSD_210730","side":"sell","seq":5160139,"price":32217.5,"qty":0.0,"timestamp":1626994940097}
1626994940.075238: {"feed":"book","product_id":"FI_XBTUSD_210730","side":"sell","seq":5160140,"price":32216.5,"qty":103.0,"timestamp":1626994940097}
1626994940.0825658: {"feed":"book","product_id":"PI_ETHUSD","side":"sell","seq":26662350,"price":2005.4,"qty":2132.0,"timestamp":1626994940105}
1626994940.099026: {"feed":"book","product_id":"PI_ETHUSD","side":"buy","seq":26662351,"price":2003.3,"qty":4067.0,"timestamp":1626994940120}
1626994940.1305542: {"feed":"book","product_id":"FI_XBTUSD_210730","side":"buy","seq":5160141,"price":32176.5,"qty":0.0,"timestamp":1626994940152}
1626994940.130678: {"feed":"book","product_id":"FI_XBTUSD_210730","side":"buy","seq":5160142,"price":32177.5,"qty":1200.0,"timestamp":1626994940152}
1626994940.130741: {"feed":"book","product_id":"FI_ETHUSD_211231","side":"buy","seq":2199112,"price":2029.5,"qty":0.0,"timestamp":1626994940152}
1626994940.130816: {"feed":"book","product_id":"FI_ETHUSD_211231","side":"buy","seq":2199113,"price":2029.6,"qty":420.0,"timestamp":1626994940152}
1626994940.132641: {"feed":"book","product_id":"PI_ETHUSD","side":"buy","seq":26662352,"price":2003.75,"qty":0.0,"timestamp":1626994940153}
1626994940.13273: {"feed":"book","product_id":"PI_ETHUSD","side":"buy","seq":26662353,"price":2003.65,"qty":22192.0,"timestamp":1626994940153}
1626994940.132766: {"feed":"book","product_id":"PI_ETHUSD","side":"buy","seq":26662354,"price":2003.7,"qty":4146.0,"timestamp":1626994940154}
1626994940.132791: {"feed":"book","product_id":"PI_ETHUSD","side":"buy","seq":26662355,"price":2003.6,"qty":20000.0,"timestamp":1626994940154}
1626994940.132822: {"feed":"book","product_id":"FI_XBTUSD_210924","side":"buy","seq":13502069,"price":32204.0,"qty":0.0,"timestamp":1626994940155}
1626994940.132855: {"feed":"book","product_id":"FI_XBTUSD_210924","side":"buy","seq":13502070,"price":32207.0,"qty":1130.0,"timestamp":1626994940155}
1626994940.134746: {"feed":"book","product_id":"FI_XBTUSD_210730","side":"buy","seq":5160143,"price":32131.0,"qty":0.0,"timestamp":1626994940156}
1626994940.1348321: {"feed":"book","product_id":"FI_XBTUSD_210730","side":"buy","seq":5160144,"price":32131.5,"qty":1500.0,"timestamp":1626994940156}
1626994940.143355: {"feed":"book","product_id":"FI_XBTUSD_210730","side":"buy","seq":5160145,"price":32177.0,"qty":0.0,"timestamp":1626994940165}
1626994940.143479: {"feed":"book","product_id":"FI_XBTUSD_210730","side":"buy","seq":5160146,"price":32178.0,"qty":50.0,"timestamp":1626994940165}
1626994940.152085: {"feed":"book","product_id":"FI_XBTUSD_210924","side":"buy","seq":13502071,"price":32186.5,"qty":729.0,"timestamp":1626994940174}
1626994940.1522071: {"feed":"book","product_id":"FI_XBTUSD_210924","side":"buy","seq":13502072,"price":32150.5,"qty":0.0,"timestamp":1626994940174}
1626994940.152273: {"feed":"book","product_id":"PI_XRPUSD","side":"sell","seq":3456225,"price":0.5897,"qty":3929.0,"timestamp":1626994940174}
1626994940.154562: {"feed":"book","product_id":"FI_ETHUSD_211231","side":"buy","seq":2199114,"price":2025.95,"qty":0.0,"timestamp":1626994940176}
1626994940.154685: {"feed":"book","product_id":"FI_ETHUSD_211231","side":"buy","seq":2199115,"price":2028.55,"qty":134.0,"timestamp":1626994940176}
1626994940.154749: {"feed":"book","product_id":"FI_ETHUSD_211231","side":"buy","seq":2199116,"price":2029.55,"qty":0.0,"timestamp":1626994940178}
1626994940.154798: {"feed":"book","product_id":"FI_ETHUSD_211231","side":"buy","seq":2199117,"price":2029.65,"qty":50.0,"timestamp":1626994940178}
1626994940.173193: {"feed":"book","product_id":"FI_XBTUSD_210730","side":"sell","seq":5160147,"price":32216.5,"qty":0.0,"timestamp":1626994940194}
1626994940.1733189: {"feed":"book","product_id":"FI_XBTUSD_210730","side":"sell","seq":5160148,"price":32215.5,"qty":103.0,"timestamp":1626994940194}
1626994940.1776268: {"feed":"book","product_id":"FI_XBTUSD_210730","side":"buy","seq":5160149,"price":32177.5,"qty":0.0,"timestamp":1626994940200}
1626994940.177752: {"feed":"book","product_id":"FI_XBTUSD_210730","side":"buy","seq":5160150,"price":32178.5,"qty":1200.0,"timestamp":1626994940200}
1626994940.180328: {"feed":"book","product_id":"FI_ETHUSD_211231","side":"buy","seq":2199118,"price":2029.6,"qty":0.0,"timestamp":1626994940200}
1626994940.180453: {"feed":"book","product_id":"FI_ETHUSD_211231","side":"buy","seq":2199119,"price":2029.7,"qty":420.0,"timestamp":1626994940200}
1626994940.188812: {"feed":"book","product_id":"FI_XBTUSD_210924","side":"sell","seq":13502073,"price":32240.0,"qty":0.0,"timestamp":1626994940210}
1626994940.188902: {"feed":"book","product_id":"FI_XBTUSD_210924","side":"sell","seq":13502074,"price":32238.5,"qty":103.0,"timestamp":1626994940210}
1626994940.1889439: {"feed":"book","product_id":"PI_ETHUSD","side":"buy","seq":26662356,"price":2003.3,"qty":0.0,"timestamp":1626994940212}
1626994940.190685: {"feed":"book","product_id":"FI_XBTUSD_210730","side":"buy","seq":5160151,"price":32178.0,"qty":0.0,"timestamp":1626994940213}
1626994940.190745: {"feed":"book","product_id":"FI_XBTUSD_210730","side":"buy","seq":5160152,"price":32179.0,"qty":50.0,"timestamp":1626994940213}
1626994940.190783: {"feed":"book","product_id":"FI_XBTUSD_210730","side":"sell","seq":5160153,"price":32215.5,"qty":0.0,"timestamp":1626994940213}
1626994940.190816: {"feed":"book","product_id":"FI_XBTUSD_210730","side":"sell","seq":5160154,"price":32216.5,"qty":103.0,"timestamp":1626994940213}
1626994940.1908438: {"feed":"book","product_id":"FI_XBTUSD_210730","side":"sell","seq":5160155,"price":32216.5,"qty":0.0,"timestamp":1626994940213}
1626994940.190871: {"feed":"book","product_id":"FI_XBTUSD_210730","side":"sell","seq":5160156,"price":32217.5,"qty":103.0,"timestamp":1626994940213}
1626994940.193204: {"feed":"book","product_id":"FI_XBTUSD_210924","side":"sell","seq":13502075,"price":32238.5,"qty":0.0,"timestamp":1626994940216}
1626994940.193291: {"feed":"book","product_id":"FI_XBTUSD_210924","side":"sell","seq":13502076,"price":32240.5,"qty":103.0,"timestamp":1626994940216}
1626994940.205398: {"feed":"book","product_id":"PI_ETHUSD","side":"buy","seq":26662357,"price":2003.0,"qty":9844.0,"timestamp":1626994940227}
1626994940.222543: {"feed":"book","product_id":"PI_ETHUSD","side":"sell","seq":26662358,"price":2007.1,"qty":0.0,"timestamp":1626994940244}
1626994940.222668: {"feed":"book","product_id":"PI_ETHUSD","side":"sell","seq":26662359,"price":2006.45,"qty":10142.0,"timestamp":1626994940244}
1626994940.2227352: {"feed":"book","product_id":"PI_ETHUSD","side":"buy","seq":26662360,"price":2001.5,"qty":0.0,"timestamp":1626994940244}
1626994940.22279: {"feed":"book","product_id":"PI_ETHUSD","side":"buy","seq":26662361,"price":2001.3,"qty":17056.0,"timestamp":1626994940244}
1626994940.2228348: {"feed":"book","product_id":"PI_ETHUSD","side":"sell","seq":26662362,"price":2007.7,"qty":8742.0,"timestamp":1626994940244}
1626994940.222881: {"feed":"book","product_id":"PI_ETHUSD","side":"sell","seq":26662363,"price":2007.7,"qty":26619.0,"timestamp":1626994940244}
1626994940.223287: {"feed":"book","product_id":"PI_ETHUSD","side":"buy","seq":26662364,"price":2001.85,"qty":5005.0,"timestamp":1626994940245}
1626994940.223341: {"feed":"book","product_id":"PI_ETHUSD","side":"buy","seq":26662365,"price":2001.85,"qty":18536.0,"timestamp":1626994940245}
1626994940.223372: {"feed":"book","product_id":"PI_ETHUSD","side":"buy","seq":26662366,"price":2000.55,"qty":0.0,"timestamp":1626994940245}
1626994940.223407: {"feed":"book","product_id":"PI_ETHUSD","side":"buy","seq":26662367,"price":2000.55,"qty":23044.0,"timestamp":1626994940245}
1626994940.226676: {"feed":"book","product_id":"PI_ETHUSD","side":"sell","seq":26662368,"price":2008.4,"qty":0.0,"timestamp":1626994940245}
1626994940.226762: {"feed":"book","product_id":"PI_ETHUSD","side":"sell","seq":26662369,"price":2008.4,"qty":23367.0,"timestamp":1626994940245}
1626994940.226806: {"feed":"book","product_id":"PI_ETHUSD","side":"buy","seq":26662370,"price":1996.5,"qty":0.0,"timestamp":1626994940245}
1626994940.22684: {"feed":"book","product_id":"PI_ETHUSD","side":"buy","seq":26662371,"price":1996.5,"qty":45266.0,"timestamp":1626994940245}
1626994940.226871: {"feed":"book","product_id":"PI_ETHUSD","side":"sell","seq":26662372,"price":2013.35,"qty":0.0,"timestamp":1626994940245}
1626994940.2268999: {"feed":"book","product_id":"PI_ETHUSD","side":"sell","seq":26662373,"price":2013.35,"qty":48690.0,"timestamp":1626994940245}
1626994940.226927: {"feed":"book","product_id":"PI_ETHUSD","side":"buy","seq":26662374,"price":1985.1,"qty":0.0,"timestamp":1626994940245}
1626994940.226954: {"feed":"book","product_id":"PI_ETHUSD","side":"buy","seq":26662375,"price":1985.1,"qty":66948.0,"timestamp":1626994940245}
1626994940.226979: {"feed":"book","product_id":"PI_ETHUSD","side":"sell","seq":26662376,"price":2021.45,"qty":0.0,"timestamp":1626994940245}
1626994940.227005: {"feed":"book","product_id":"PI_ETHUSD","side":"sell","seq":26662377,"price":2021.45,"qty":67945.0,"timestamp":1626994940245}
1626994940.232345: {"feed":"book","product_id":"FI_XBTUSD_210730","side":"buy","seq":5160157,"price":32111.5,"qty":0.0,"timestamp":1626994940253}
1626994940.23247: {"feed":"book","product_id":"FI_XBTUSD_210730","side":"buy","seq":5160158,"price":32118.0,"qty":250001.0,"timestamp":1626994940253}
1626994940.232533: {"feed":"book","product_id":"PI_ETHUSD","side":"sell","seq":26662378,"price":2013.4,"qty":0.0,"timestamp":1626994940253}
1626994940.232587: {"feed":"book","product_id":"PI_ETHUSD","side":"sell","seq":26662379,"price":2013.3,"qty":500002.0,"timestamp":1626994940253}
1626994940.232633: {"feed":"book","product_id":"FI_ETHUSD_211231","side":"sell","seq":2199120,"price":2048.95,"qty":0.0,"timestamp":1626994940253}
1626994940.2326798: {"feed":"book","product_id":"FI_ETHUSD_211231","side":"sell","seq":2199121,"price":2048.85,"qty":250002.0,"timestamp":1626994940253}
1626994940.2330391: {"feed":"book","product_id":"FI_ETHUSD_210730","side":"buy","seq":2138792,"price":1992.05,"qty":0.0,"timestamp":1626994940253}
1626994940.233112: {"feed":"book","product_id":"FI_ETHUSD_210730","side":"buy","seq":2138793,"price":1992.15,"qty":250002.0,"timestamp":1626994940253}
1626994940.23317: {"feed":"book","product_id":"FI_ETHUSD_210730","side":"sell","seq":2138794,"price":2014.1,"qty":0.0,"timestamp":1626994940253}
1626994940.23322: {"feed":"book","product_id":"FI_ETHUSD_210730","side":"sell","seq":2138795,"price":2014.0,"qty":250002.0,"timestamp":1626994940253}
1626994940.3300219: {"feed":"book","product_id":"FI_XBTUSD_210924","side":"buy","seq":13502077,"price":32188.5,"qty":0.0,"timestamp":1626994940351}
1626994940.3301492: {"feed":"book","product_id":"FI_XBTUSD_210924","side":"buy","seq":13502078,"price":32188.5,"qty":20023.0,"timestamp":1626994940351}
1626994940.3302221: {"feed":"book","product_id":"FI_XBTUSD_210924","side":"sell","seq":13502079,"price":32258.5,"qty":0.0,"timestamp":1626994940351}
1626994940.330276: {"feed":"book","product_id":"FI_XBTUSD_210924","side":"sell","seq":13502080,"price":32258.5,"qty":17394.0,"timestamp":1626994940351}
1626994940.3303208: {"feed":"book","product_id":"FI_XBTUSD_210924","side":"sell","seq":13502081,"price":32281.5,"qty":0.0,"timestamp":1626994940351}
1626994940.330364: {"feed":"book","product_id":"FI_XBTUSD_210924","side":"sell","seq":13502082,"price":32281.5,"qty":20968.0,"timestamp":1626994940351}
1626994940.3575082: {"feed":"book","product_id":"FI_XBTUSD_210924","side":"buy","seq":13502083,"price":32173.5,"qty":10000.0,"timestamp":1626994940378}
1626994940.357634: {"feed":"book","product_id":"FI_XBTUSD_210924","side":"sell","seq":13502084,"price":32265.0,"qty":10000.0,"timestamp":1626994940378}
1626994940.357694: {"feed":"book","product_id":"FI_XBTUSD_210924","side":"buy","seq":13502085,"price":32136.0,"qty":26107.0,"timestamp":1626994940378}
1626994940.357739: {"feed":"book","product_id":"FI_XBTUSD_210924","side":"sell","seq":13502086,"price":32302.5,"qty":20880.0,"timestamp":1626994940378}
1626994940.3577878: {"feed":"book","product_id":"FI_XBTUSD_210924","side":"buy","seq":13502087,"price":32098.5,"qty":26107.0,"timestamp":1626994940378}
1626994940.357831: {"feed":"book","product_id":"FI_XBTUSD_210924","side":"sell","seq":13502088,"price":32340.5,"qty":20880.0,"timestamp":1626994940378}
1626994940.358761: {"feed":"book","product_id":"FI_XBTUSD_210924","side":"buy","seq":13502089,"price":32061.0,"qty":26106.0,"timestamp":1626994940378}
1626994940.358849: {"feed":"book","product_id":"FI_XBTUSD_210924","side":"sell","seq":13502090,"price":32378.0,"qty":20880.0,"timestamp":1626994940378}
1626994940.390662: {"feed":"book","product_id":"FI_XBTUSD_210924","side":"buy","seq":13502091,"price":32042.0,"qty":18973.0,"timestamp":1626994940412}
1626994940.3907819: {"feed":"book","product_id":"FI_XBTUSD_210924","side":"sell","seq":13502092,"price":32262.5,"qty":3000.0,"timestamp":1626994940412}
1626994940.390841: {"feed":"book","product_id":"PI_ETHUSD","side":"sell","seq":26662380,"price":2005.0,"qty":1817.0,"timestamp":1626994940413}
1626994940.390893: {"feed":"book","product_id":"PI_ETHUSD","side":"buy","seq":26662381,"price":2004.6,"qty":0.0,"timestamp":1626994940413}
1626994940.395936: {"feed":"book","product_id":"PI_ETHUSD","side":"buy","seq":26662382,"price":2003.5,"qty":17446.0,"timestamp":1626994940417}
1626994940.401526: {"feed":"book","product_id":"PI_ETHUSD","side":"buy","seq":26662383,"price":2003.65,"qty":6366.0,"timestamp":1626994940424}
1626994940.401633: {"feed":"book","product_id":"PI_ETHUSD","side":"buy","seq":26662384,"price":2003.9,"qty":17134.0,"timestamp":1626994940424}
1626994940.4034472: {"feed":"book","product_id":"PI_ETHUSD","side":"buy","seq":26662385,"price":2003.6,"qty":0.0,"timestamp":1626994940426}
1626994940.403573: {"feed":"book","product_id":"PI_ETHUSD","side":"buy","seq":26662386,"price":2003.8,"qty":20000.0,"timestamp":1626994940426}
1626994940.453269: {"feed":"book","product_id":"PI_ETHUSD","side":"sell","seq":26662387,"price":2007.7,"qty":8742.0,"timestamp":1626994940475}
1626994940.453377: {"feed":"book","product_id":"PI_ETHUSD","side":"sell","seq":26662388,"price":2007.7,"qty":26621.0,"timestamp":1626994940475}
1626994940.453425: {"feed":"book","product_id":"PI_ETHUSD","side":"sell","seq":26662389,"price":2006.45,"qty":0.0,"timestamp":1626994940475}
1626994940.453506: {"feed":"book","product_id":"PI_ETHUSD","side":"sell","seq":26662390,"price":2006.45,"qty":10143.0,"timestamp":1626994940475}
1626994940.453541: {"feed":"book","product_id":"PI_ETHUSD","side":"buy","seq":26662391,"price":2001.85,"qty":5005.0,"timestamp":1626994940475}
1626994940.4535658: {"feed":"book","product_id":"PI_ETHUSD","side":"buy","seq":26662392,"price":2001.85,"qty":18535.0,"timestamp":1626994940475}
1626994940.453587: {"feed":"book","product_id":"PI_ETHUSD","side":"buy","seq":26662393,"price":2001.3,"qty":0.0,"timestamp":1626994940475}
1626994940.4536169: {"feed":"book","product_id":"PI_ETHUSD","side":"buy","seq":26662394,"price":2001.3,"qty":17055.0,"timestamp":1626994940475}
1626994940.453644: {"feed":"book","product_id":"PI_ETHUSD","side":"buy","seq":26662395,"price":2000.55,"qty":0.0,"timestamp":1626994940475}
1626994940.453671: {"feed":"book","product_id":"PI_ETHUSD","side":"buy","seq":26662396,"price":2000.55,"qty":23043.0,"timestamp":1626994940475}
1626994940.4539971: {"feed":"book","product_id":"PI_ETHUSD","side":"sell","seq":26662397,"price":2008.4,"qty":0.0,"timestamp":1626994940475}
1626994940.454046: {"feed":"book","product_id":"PI_ETHUSD","side":"sell","seq":26662398,"price":2008.4,"qty":23368.0,"timestamp":1626994940475}
1626994940.4775739: {"feed":"book","product_id":"PI_LTCUSD","side":"sell","seq":3423287,"price":119.62,"qty":0.0,"timestamp":1626994940500}
1626994940.4780102: {"feed":"book","product_id":"PI_LTCUSD","side":"buy","seq":3423288,"price":119.36,"qty":3959.0,"timestamp":1626994940501}
1626994940.478515: {"feed":"book","product_id":"PI_LTCUSD","side":"buy","seq":3423289,"price":119.32,"qty":4183.0,"timestamp":1626994940502}
1626994940.479059: {"feed":"book","product_id":"PI_LTCUSD","side":"sell","seq":3423290,"price":119.59,"qty":3961.0,"timestamp":1626994940502}
1626994940.534168: {"feed":"book","product_id":"FI_XBTUSD_210924","side":"sell","seq":13502093,"price":32258.5,"qty":0.0,"timestamp":1626994940555}
1626994940.534292: {"feed":"book","product_id":"FI_XBTUSD_210924","side":"sell","seq":13502094,"price":32258.5,"qty":17487.0,"timestamp":1626994940555}
1626994940.534357: {"feed":"book","product_id":"FI_XBTUSD_210924","side":"buy","seq":13502095,"price":32188.5,"qty":0.0,"timestamp":1626994940555}
1626994940.534409: {"feed":"book","product_id":"FI_XBTUSD_210924","side":"buy","seq":13502096,"price":32188.5,"qty":19930.0,"timestamp":1626994940555}
1626994940.534453: {"feed":"book","product_id":"PI_ETHUSD","side":"buy","seq":26662399,"price":2003.8,"qty":0.0,"timestamp":1626994940557}
1626994940.5345018: {"feed":"book","product_id":"PI_ETHUSD","side":"buy","seq":26662400,"price":2003.65,"qty":26366.0,"timestamp":1626994940557}
1626994940.534838: {"feed":"book","product_id":"PI_ETHUSD","side":"buy","seq":26662401,"price":2003.9,"qty":1308.0,"timestamp":1626994940557}
1626994940.534878: {"feed":"book","product_id":"PI_ETHUSD","side":"buy","seq":26662402,"price":2003.7,"qty":19972.0,"timestamp":1626994940557}
1626994940.5444758: {"feed":"book","product_id":"FI_XBTUSD_210924","side":"buy","seq":13502097,"price":32133.5,"qty":2400.0,"timestamp":1626994940565}
1626994940.544589: {"feed":"book","product_id":"FI_XBTUSD_210924","side":"buy","seq":13502098,"price":32136.5,"qty":250001.0,"timestamp":1626994940565}
1626994940.544652: {"feed":"book","product_id":"FI_XBTUSD_210924","side":"sell","seq":13502099,"price":32307.0,"qty":0.0,"timestamp":1626994940565}
1626994940.54471: {"feed":"book","product_id":"FI_XBTUSD_210924","side":"sell","seq":13502100,"price":32302.0,"qty":250001.0,"timestamp":1626994940565}
1626994940.544754: {"feed":"book","product_id":"PI_ETHUSD","side":"sell","seq":26662403,"price":2008.45,"qty":0.0,"timestamp":1626994940565}
1626994940.544804: {"feed":"book","product_id":"PI_ETHUSD","side":"sell","seq":26662404,"price":2008.7,"qty":513112.0,"timestamp":1626994940565}
1626994940.5519738: {"feed":"book","product_id":"FI_XBTUSD_210924","side":"buy","seq":13502101,"price":32194.5,"qty":880.0,"timestamp":1626994940574}
1626994940.5802739: {"feed":"book","product_id":"PI_ETHUSD","side":"buy","seq":26662405,"price":2003.7,"qty":4146.0,"timestamp":1626994940599}
1626994940.580381: {"feed":"book","product_id":"PI_ETHUSD","side":"buy","seq":26662406,"price":2003.55,"qty":15826.0,"timestamp":1626994940599}
1626994940.580447: {"feed":"book","product_id":"PI_ETHUSD","side":"buy","seq":26662407,"price":2003.65,"qty":6366.0,"timestamp":1626994940603}
1626994940.580488: {"feed":"book","product_id":"PI_ETHUSD","side":"buy","seq":26662408,"price":2003.5,"qty":37446.0,"timestamp":1626994940603}
1626994940.593639: {"feed":"book","product_id":"FI_XBTUSD_210730","side":"sell","seq":5160159,"price":32217.5,"qty":0.0,"timestamp":1626994940614}
1626994940.59376: {"feed":"book","product_id":"FI_XBTUSD_210730","side":"sell","seq":5160160,"price":32216.5,"qty":103.0,"timestamp":1626994940614}
1626994940.626415: {"feed":"book","product_id":"FI_XBTUSD_210924","side":"sell","seq":13502102,"price":32240.5,"qty":0.0,"timestamp":1626994940647}
1626994940.626539: {"feed":"book","product_id":"FI_XBTUSD_210924","side":"sell","seq":13502103,"price":32239.5,"qty":103.0,"timestamp":1626994940647}
1626994940.6402209: {"feed":"book","product_id":"PI_ETHUSD","side":"buy","seq":26662409,"price":2003.55,"qty":0.0,"timestamp":1626994940661}
1626994940.640351: {"feed":"book","product_id":"PI_ETHUSD","side":"buy","seq":26662410,"price":2003.65,"qty":22192.0,"timestamp":1626994940661}
1626994940.640403: {"feed":"book","product_id":"PI_ETHUSD","side":"buy","seq":26662411,"price":2003.5,"qty":17446.0,"timestamp":1626994940662}
1626994940.6404421: {"feed":"book","product_id":"PI_ETHUSD","side":"buy","seq":26662412,"price":2003.6,"qty":20000.0,"timestamp":1626994940662}
1626994940.6422982: {"feed":"book","product_id":"PI_XRPUSD","side":"sell","seq":3456226,"price":0.5897,"qty":4958.0,"timestamp":1626994940664}
1626994940.657824: {"feed":"book","product_id":"PI_ETHUSD","side":"sell","seq":26662413,"price":2007.7,"qty":8742.0,"timestamp":1626994940679}
1626994940.6579359: {"feed":"book","product_id":"PI_ETHUSD","side":"sell","seq":26662414,"price":2007.4,"qty":15838.0,"timestamp":1626994940679}
1626994940.6595469: {"feed":"book","product_id":"FI_XBTUSD_210730","side":"sell","seq":5160161,"price":32216.5,"qty":0.0,"timestamp":1626994940682}
1626994940.659675: {"feed":"book","product_id":"FI_XBTUSD_210730","side":"sell","seq":5160162,"price":32215.0,"qty":30103.0,"timestamp":1626994940682}
1626994940.6637492: {"feed":"book","product_id":"FI_XBTUSD_210924","side":"sell","seq":13502104,"price":32239.5,"qty":0.0,"timestamp":1626994940685}
1626994940.663875: {"feed":"book","product_id":"FI_XBTUSD_210924","side":"sell","seq":13502105,"price":32238.0,"qty":103.0,"timestamp":1626994940685}
1626994940.663937: {"feed":"book","product_id":"FI_XBTUSD_210924","side":"buy","seq":13502106,"price":32186.5,"qty":0.0,"timestamp":1626994940686}
1626994940.677672: {"feed":"book","product_id":"PI_LTCUSD","side":"buy","seq":3423291,"price":119.38,"qty":320.0,"timestamp":1626994940700}
1626994940.6828952: {"feed":"book","product_id":"PI_ETHUSD","side":"buy","seq":26662415,"price":2003.6,"qty":0.0,"timestamp":1626994940705}
1626994940.6830232: {"feed":"book","product_id":"PI_ETHUSD","side":"buy","seq":26662416,"price":2003.7,"qty":24146.0,"timestamp":1626994940705}
1626994940.68481: {"feed":"book","product_id":"PI_ETHUSD","side":"buy","seq":26662417,"price":2003.65,"qty":6366.0,"timestamp":1626994940706}
1626994940.684921: {"feed":"book","product_id":"PI_ETHUSD","side":"buy","seq":26662418,"price":2003.75,"qty":15826.0,"timestamp":1626994940706}
1626994940.685324: {"feed":"book","product_id":"PI_LTCUSD","side":"buy","seq":3423292,"price":119.35,"qty":3870.0,"timestamp":1626994940708}
1626994940.712418: {"feed":"book","product_id":"PI_ETHUSD","side":"buy","seq":26662419,"price":2003.75,"qty":0.0,"timestamp":1626994940725}
1626994940.712544: {"feed":"book","product_id":"PI_ETHUSD","side":"buy","seq":26662420,"price":2003.65,"qty":22192.0,"timestamp":1626994940725}
1626994940.712598: {"feed":"book","product_id":"PI_ETHUSD","side":"buy","seq":26662421,"price":2003.7,"qty":4146.0,"timestamp":1626994940726}
1626994940.712638: {"feed":"book","product_id":"PI_ETHUSD","side":"buy","seq":26662422,"price":2003.6,"qty":20000.0,"timestamp":1626994940726}
1626994940.712686: {"feed":"book","product_id":"FI_XBTUSD_210924","side":"buy","seq":13502107,"price":32192.0,"qty":5000.0,"timestamp":1626994940734}
1626994940.7127302: {"feed":"book","product_id":"FI_XBTUSD_210924","side":"sell","seq":13502108,"price":32257.0,"qty":5000.0,"timestamp":1626994940734}
1626994940.718826: {"feed":"book","product_id":"FI_XBTUSD_210924","side":"sell","seq":13502109,"price":32291.0,"qty":0.0,"timestamp":1626994940741}
1626994940.718951: {"feed":"book","product_id":"FI_XBTUSD_210924","side":"sell","seq":13502110,"price":32289.5,"qty":20000.0,"timestamp":1626994940741}
1626994940.735902: {"feed":"book","product_id":"FI_XBTUSD_210924","side":"sell","seq":13502111,"price":32258.5,"qty":0.0,"timestamp":1626994940758}
1626994940.7360241: {"feed":"book","product_id":"FI_XBTUSD_210924","side":"sell","seq":13502112,"price":32246.0,"qty":14618.0,"timestamp":1626994940758}
1626994940.740671: {"feed":"book","product_id":"FI_XBTUSD_210924","side":"sell","seq":13502113,"price":32289.5,"qty":0.0,"timestamp":1626994940762}
1626994940.740797: {"feed":"book","product_id":"FI_XBTUSD_210924","side":"sell","seq":13502114,"price":32291.0,"qty":20000.0,"timestamp":1626994940762}
1626994940.750607: {"feed":"book","product_id":"FI_ETHUSD_210730","side":"sell","seq":2138796,"price":2006.8,"qty":31549.0,"timestamp":1626994940772}
1626994940.750716: {"feed":"book","product_id":"PI_ETHUSD","side":"sell","seq":26662423,"price":2005.0,"qty":0.0,"timestamp":1626994940773}
1626994940.859682: {"feed":"book","product_id":"PI_ETHUSD","side":"sell","seq":26662424,"price":2008.4,"qty":0.0,"timestamp":1626994940882}
1626994940.859746: {"feed":"book","product_id":"PI_ETHUSD","side":"sell","seq":26662425,"price":2008.45,"qty":23935.0,"timestamp":1626994940882}
1626994940.861058: {"feed":"book","product_id":"PI_ETHUSD","side":"buy","seq":26662426,"price":2003.65,"qty":6366.0,"timestamp":1626994940883}
1626994940.861094: {"feed":"book","product_id":"PI_ETHUSD","side":"buy","seq":26662427,"price":2003.75,"qty":15826.0,"timestamp":1626994940883}
1626994940.863772: {"feed":"book","product_id":"PI_ETHUSD","side":"buy","seq":26662428,"price":2003.6,"qty":0.0,"timestamp":1626994940887}
1626994940.863816: {"feed":"book","product_id":"PI_ETHUSD","side":"buy","seq":26662429,"price":2003.7,"qty":24146.0,"timestamp":1626994940887}
1626994940.917494: {"feed":"book","product_id":"FI_XRPUSD_210924","side":"buy","seq":602289,"price":0.5839,"qty":0.0,"timestamp":1626994940939}
1626994940.91756: {"feed":"book","product_id":"FI_XRPUSD_210924","side":"sell","seq":602290,"price":0.5876,"qty":64.0,"timestamp":1626994940940}
1626994940.920765: {"feed":"book","product_id":"FI_BCHUSD_210924","side":"buy","seq":402243,"price":440.5,"qty":0.0,"timestamp":1626994940943}
1626994940.9208362: {"feed":"book","product_id":"FI_BCHUSD_210924","side":"sell","seq":402244,"price":442.9,"qty":37297.0,"timestamp":1626994940943}
1626994940.926293: {"feed":"book","product_id":"FI_ETHUSD_210730","side":"buy","seq":2138797,"price":1992.1,"qty":0.0,"timestamp":1626994940947}
1626994940.926338: {"feed":"book","product_id":"FI_ETHUSD_210730","side":"buy","seq":2138798,"price":1992.2,"qty":44704.0,"timestamp":1626994940947}
1626994940.9263601: {"feed":"book","product_id":"FI_ETHUSD_210730","side":"sell","seq":2138799,"price":2014.05,"qty":0.0,"timestamp":1626994940947}
1626994940.92638: {"feed":"book","product_id":"FI_ETHUSD_210730","side":"sell","seq":2138800,"price":2013.95,"qty":45421.0,"timestamp":1626994940947}
1626994940.934161: {"feed":"book","product_id":"FI_ETHUSD_210730","side":"buy","seq":2138801,"price":1992.15,"qty":0.0,"timestamp":1626994940956}
1626994940.934217: {"feed":"book","product_id":"FI_ETHUSD_210730","side":"buy","seq":2138802,"price":1989.75,"qty":250002.0,"timestamp":1626994940956}
1626994940.934241: {"feed":"book","product_id":"FI_ETHUSD_210730","side":"sell","seq":2138803,"price":2014.0,"qty":0.0,"timestamp":1626994940956}
1626994940.93426: {"feed":"book","product_id":"FI_ETHUSD_210730","side":"sell","seq":2138804,"price":2013.9,"qty":250002.0,"timestamp":1626994940956}
1626994940.971684: {"feed":"book","product_id":"FI_XBTUSD_210924","side":"sell","seq":13502115,"price":32246.0,"qty":0.0,"timestamp":1626994940994}
1626994940.971806: {"feed":"book","product_id":"FI_XBTUSD_210924","side":"sell","seq":13502116,"price":32246.0,"qty":14412.0,"timestamp":1626994940994}
1626994940.972526: {"feed":"book","product_id":"FI_XBTUSD_210924","side":"buy","seq":13502117,"price":32188.5,"qty":0.0,"timestamp":1626994940994}
1626994940.9726279: {"feed":"book","product_id":"FI_XBTUSD_210924","side":"buy","seq":13502118,"price":32188.5,"qty":19775.0,"timestamp":1626994940994}
1626994940.9727051: {"feed":"book","product_id":"FI_XBTUSD_210924","side":"buy","seq":13502119,"price":32175.0,"qty":1900.0,"timestamp":1626994940994}
1626994940.972747: {"feed":"book","product_id":"FI_XBTUSD_210924","side":"buy","seq":13502120,"price":32175.0,"qty":22810.0,"timestamp":1626994940994}
1626994940.97278: {"feed":"book","product_id":"FI_XBTUSD_210924","side":"sell","seq":13502121,"price":32281.5,"qty":0.0,"timestamp":1626994940994}
1626994940.972825: {"feed":"book","product_id":"FI_XBTUSD_210924","side":"sell","seq":13502122,"price":32281.5,"qty":20967.0,"timestamp":1626994940994}
1626994941.064165: {"feed":"book","product_id":"PI_ETHUSD","side":"sell","seq":26662430,"price":2007.4,"qty":0.0,"timestamp":1626994941086}
1626994941.0642922: {"feed":"book","product_id":"PI_ETHUSD","side":"sell","seq":26662431,"price":2007.7,"qty":26916.0,"timestamp":1626994941086}
1626994941.115938: {"feed":"book","product_id":"FI_XBTUSD_210924","side":"buy","seq":13502123,"price":32182.0,"qty":6639.0,"timestamp":1626994941137}
1626994941.1785998: {"feed":"book","product_id":"FI_XBTUSD_210924","side":"sell","seq":13502124,"price":32246.0,"qty":0.0,"timestamp":1626994941198}
1626994941.178731: {"feed":"book","product_id":"FI_XBTUSD_210924","side":"sell","seq":13502125,"price":32256.5,"qty":16971.0,"timestamp":1626994941198}
1626994941.178796: {"feed":"book","product_id":"FI_XBTUSD_210924","side":"buy","seq":13502126,"price":32188.5,"qty":0.0,"timestamp":1626994941198}
1626994941.1788318: {"feed":"book","product_id":"FI_XBTUSD_210924","side":"buy","seq":13502127,"price":32192.5,"qty":18902.0,"timestamp":1626994941198}
1626994941.1788611: {"feed":"book","product_id":"FI_XBTUSD_210730","side":"buy","seq":5160163,"price":32178.5,"qty":0.0,"timestamp":1626994941200}
1626994941.178891: {"feed":"book","product_id":"FI_XBTUSD_210730","side":"buy","seq":5160164,"price":32179.5,"qty":1200.0,"timestamp":1626994941200}
1626994941.1789172: {"feed":"book","product_id":"FI_XBTUSD_210924","side":"buy","seq":13502128,"price":32175.0,"qty":1900.0,"timestamp":1626994941198}
1626994941.1789398: {"feed":"book","product_id":"FI_XBTUSD_210924","side":"buy","seq":13502129,"price":32175.0,"qty":22811.0,"timestamp":1626994941198}
1626994941.179254: {"feed":"book","product_id":"FI_XBTUSD_210924","side":"sell","seq":13502130,"price":32281.5,"qty":0.0,"timestamp":1626994941198}
1626994941.179301: {"feed":"book","product_id":"FI_XBTUSD_210924","side":"sell","seq":13502131,"price":32281.5,"qty":20968.0,"timestamp":1626994941198}
1626994941.1797981: {"feed":"book","product_id":"FI_XBTUSD_210924","side":"sell","seq":13502132,"price":32291.0,"qty":0.0,"timestamp":1626994941202}
1626994941.1798642: {"feed":"book","product_id":"FI_XBTUSD_210924","side":"sell","seq":13502133,"price":32289.5,"qty":20000.0,"timestamp":1626994941202}
1626994941.1914392: {"feed":"book","product_id":"FI_XBTUSD_210730","side":"buy","seq":5160165,"price":32179.0,"qty":0.0,"timestamp":1626994941213}
1626994941.19156: {"feed":"book","product_id":"FI_XBTUSD_210730","side":"buy","seq":5160166,"price":32180.0,"qty":50.0,"timestamp":1626994941213}
1626994941.204687: {"feed":"book","product_id":"FI_XBTUSD_210730","side":"sell","seq":5160167,"price":32215.0,"qty":30000.0,"timestamp":1626994941226}
1626994941.2047942: {"feed":"book","product_id":"FI_XBTUSD_210730","side":"sell","seq":5160168,"price":32214.0,"qty":103.0,"timestamp":1626994941226}
1626994941.2089128: {"feed":"book","product_id":"FI_XBTUSD_210924","side":"sell","seq":13502134,"price":32238.0,"qty":0.0,"timestamp":1626994941231}
1626994941.209037: {"feed":"book","product_id":"FI_XBTUSD_210924","side":"sell","seq":13502135,"price":32237.0,"qty":103.0,"timestamp":1626994941231}
1626994941.278263: {"feed":"book","product_id":"PI_XRPUSD","side":"buy","seq":3456227,"price":0.5849,"qty":125000.0,"timestamp":1626994941301}
1626994941.2887309: {"feed":"book","product_id":"FI_XBTUSD_210730","side":"buy","seq":5160169,"price":32179.5,"qty":0.0,"timestamp":1626994941309}
1626994941.288865: {"feed":"book","product_id":"FI_XBTUSD_210730","side":"buy","seq":5160170,"price":32180.5,"qty":1200.0,"timestamp":1626994941309}
1626994941.298912: {"feed":"book","product_id":"PI_ETHUSD","side":"sell","seq":26662432,"price":2013.35,"qty":0.0,"timestamp":1626994941320}
1626994941.299041: {"feed":"book","product_id":"PI_ETHUSD","side":"sell","seq":26662433,"price":2013.25,"qty":48479.0,"timestamp":1626994941320}
1626994941.29911: {"feed":"book","product_id":"PI_ETHUSD","side":"sell","seq":26662434,"price":2006.45,"qty":0.0,"timestamp":1626994941320}
1626994941.299188: {"feed":"book","product_id":"PI_ETHUSD","side":"sell","seq":26662435,"price":2006.45,"qty":10339.0,"timestamp":1626994941320}
1626994941.29922: {"feed":"book","product_id":"PI_ETHUSD","side":"buy","seq":26662436,"price":2001.3,"qty":0.0,"timestamp":1626994941320}
1626994941.299252: {"feed":"book","product_id":"PI_ETHUSD","side":"buy","seq":26662437,"price":2001.3,"qty":16762.0,"timestamp":1626994941320}
1626994941.2992792: {"feed":"book","product_id":"PI_ETHUSD","side":"buy","seq":26662438,"price":2001.85,"qty":5005.0,"timestamp":1626994941320}
1626994941.2993028: {"feed":"book","product_id":"PI_ETHUSD","side":"buy","seq":26662439,"price":2001.85,"qty":18339.0,"timestamp":1626994941320}
1626994941.2993238: {"feed":"book","product_id":"PI_ETHUSD","side":"buy","seq":26662440,"price":2000.55,"qty":0.0,"timestamp":1626994941320}
1626994941.29935: {"feed":"book","product_id":"PI_ETHUSD","side":"buy","seq":26662441,"price":2000.55,"qty":22849.0,"timestamp":1626994941320}
1626994941.300985: {"feed":"book","product_id":"PI_ETHUSD","side":"sell","seq":26662442,"price":2008.45,"qty":0.0,"timestamp":1626994941320}
1626994941.301074: {"feed":"book","product_id":"PI_ETHUSD","side":"sell","seq":26662443,"price":2008.45,"qty":23848.0,"timestamp":1626994941320}
1626994941.301117: {"feed":"book","product_id":"PI_ETHUSD","side":"buy","seq":26662444,"price":1996.5,"qty":0.0,"timestamp":1626994941320}
1626994941.301152: {"feed":"book","product_id":"PI_ETHUSD","side":"buy","seq":26662445,"price":1996.5,"qty":45155.0,"timestamp":1626994941320}
1626994941.301182: {"feed":"book","product_id":"PI_ETHUSD","side":"buy","seq":26662446,"price":1985.1,"qty":0.0,"timestamp":1626994941320}
1626994941.301209: {"feed":"book","product_id":"PI_ETHUSD","side":"buy","seq":26662447,"price":1985.1,"qty":66946.0,"timestamp":1626994941320}
1626994941.301235: {"feed":"book","product_id":"FI_XBTUSD_210730","side":"buy","seq":5160171,"price":32180.0,"qty":0.0,"timestamp":1626994941323}
1626994941.301265: {"feed":"book","product_id":"FI_XBTUSD_210730","side":"buy","seq":5160172,"price":32181.0,"qty":50.0,"timestamp":1626994941323}
1626994941.3012888: {"feed":"book","product_id":"PI_ETHUSD","side":"sell","seq":26662448,"price":2021.45,"qty":0.0,"timestamp":1626994941320}
1626994941.3013172: {"feed":"book","product_id":"PI_ETHUSD","side":"sell","seq":26662449,"price":2021.45,"qty":67944.0,"timestamp":1626994941320}
1626994941.305503: {"feed":"book","product_id":"FI_XBTUSD_210924","side":"buy","seq":13502136,"price":32182.0,"qty":3639.0,"timestamp":1626994941328}
1626994941.3112772: {"feed":"book","product_id":"FI_XBTUSD_210924","side":"sell","seq":13502137,"price":32302.0,"qty":0.0,"timestamp":1626994941334}
1626994941.311404: {"feed":"book","product_id":"FI_XBTUSD_210924","side":"sell","seq":13502138,"price":32290.0,"qty":250001.0,"timestamp":1626994941334}
1626994941.311469: {"feed":"book","product_id":"PI_ETHUSD","side":"sell","seq":26662450,"price":2013.3,"qty":0.0,"timestamp":1626994941334}
1626994941.3115258: {"feed":"book","product_id":"PI_ETHUSD","side":"sell","seq":26662451,"price":2013.2,"qty":500002.0,"timestamp":1626994941334}
1626994941.3435059: {"feed":"book","product_id":"PI_ETHUSD","side":"buy","seq":26662452,"price":2003.75,"qty":0.0,"timestamp":1626994941365}
1626994941.3436291: {"feed":"book","product_id":"PI_ETHUSD","side":"buy","seq":26662453,"price":2003.85,"qty":19988.0,"timestamp":1626994941365}
1626994941.343683: {"feed":"book","product_id":"PI_ETHUSD","side":"buy","seq":26662454,"price":2003.7,"qty":4146.0,"timestamp":1626994941366}
1626994941.343724: {"feed":"book","product_id":"PI_ETHUSD","side":"buy","seq":26662455,"price":2003.8,"qty":20000.0,"timestamp":1626994941366}
1626994941.3808692: {"feed":"book","product_id":"FI_XBTUSD_210924","side":"sell","seq":13502139,"price":32256.5,"qty":0.0,"timestamp":1626994941402}
1626994941.3809972: {"feed":"book","product_id":"FI_XBTUSD_210924","side":"sell","seq":13502140,"price":32246.0,"qty":14362.0,"timestamp":1626994941402}
1626994941.3850849: {"feed":"book","product_id":"FI_XBTUSD_210924","side":"sell","seq":13502141,"price":32289.5,"qty":0.0,"timestamp":1626994941407}
1626994941.385209: {"feed":"book","product_id":"FI_XBTUSD_210924","side":"sell","seq":13502142,"price":32290.5,"qty":74000.0,"timestamp":1626994941407}
1626994941.3959382: {"feed":"book","product_id":"PI_ETHUSD","side":"sell","seq":26662456,"price":2005.5,"qty":11320.0,"timestamp":1626994941417}
1626994941.4188921: {"feed":"book","product_id":"FI_XBTUSD_210924","side":"buy","seq":13502143,"price":32184.5,"qty":1053.0,"timestamp":1626994941441}
1626994941.4776058: {"feed":"book","product_id":"PI_ETHUSD","side":"buy","seq":26662457,"price":2003.0,"qty":5000.0,"timestamp":1626994941500}
1626994941.504298: {"feed":"book","product_id":"PI_ETHUSD","side":"buy","seq":26662458,"price":2003.3,"qty":4287.0,"timestamp":1626994941516}
1626994941.504431: {"feed":"book","product_id":"PI_ETHUSD","side":"sell","seq":26662459,"price":2006.45,"qty":0.0,"timestamp":1626994941525}
1626994941.5045052: {"feed":"book","product_id":"PI_ETHUSD","side":"sell","seq":26662460,"price":2006.45,"qty":10164.0,"timestamp":1626994941525}
1626994941.504559: {"feed":"book","product_id":"PI_ETHUSD","side":"buy","seq":26662461,"price":2001.3,"qty":0.0,"timestamp":1626994941525}
1626994941.5046122: {"feed":"book","product_id":"PI_ETHUSD","side":"buy","seq":26662462,"price":2001.3,"qty":17023.0,"timestamp":1626994941525}
1626994941.5071812: {"feed":"book","product_id":"PI_ETHUSD","side":"sell","seq":26662463,"price":2007.7,"qty":8742.0,"timestamp":1626994941525}
1626994941.507306: {"feed":"book","product_id":"PI_ETHUSD","side":"sell","seq":26662464,"price":2007.7,"qty":26653.0,"timestamp":1626994941525}
1626994941.507339: {"feed":"book","product_id":"PI_ETHUSD","side":"buy","seq":26662465,"price":2001.85,"qty":5005.0,"timestamp":1626994941525}
1626994941.507366: {"feed":"book","product_id":"PI_ETHUSD","side":"buy","seq":26662466,"price":2001.85,"qty":18514.0,"timestamp":1626994941525}
1626994941.5073879: {"feed":"book","product_id":"PI_ETHUSD","side":"buy","seq":26662467,"price":2000.55,"qty":0.0,"timestamp":1626994941525}
1626994941.507426: {"feed":"book","product_id":"PI_ETHUSD","side":"buy","seq":26662468,"price":2000.55,"qty":23022.0,"timestamp":1626994941525}
1626994941.507466: {"feed":"book","product_id":"PI_ETHUSD","side":"sell","seq":26662469,"price":2008.45,"qty":0.0,"timestamp":1626994941525}
1626994941.507498: {"feed":"book","product_id":"PI_ETHUSD","side":"sell","seq":26662470,"price":2008.45,"qty":23672.0,"timestamp":1626994941525}
1626994941.507526: {"feed":"book","product_id":"PI_ETHUSD","side":"buy","seq":26662471,"price":1996.5,"qty":0.0,"timestamp":1626994941525}
1626994941.507554: {"feed":"book","product_id":"PI_ETHUSD","side":"buy","seq":26662472,"price":1996.5,"qty":45254.0,"timestamp":1626994941525}
1626994941.5075798: {"feed":"book","product_id":"PI_ETHUSD","side":"sell","seq":26662473,"price":2013.25,"qty":0.0,"timestamp":1626994941525}
1626994941.5076082: {"feed":"book","product_id":"PI_ETHUSD","side":"sell","seq":26662474,"price":2013.25,"qty":48378.0,"timestamp":1626994941525}
1626994941.507633: {"feed":"book","product_id":"PI_ETHUSD","side":"buy","seq":26662475,"price":1985.1,"qty":0.0,"timestamp":1626994941525}
1626994941.507659: {"feed":"book","product_id":"PI_ETHUSD","side":"buy","seq":26662476,"price":1985.1,"qty":66948.0,"timestamp":1626994941525}
1626994941.507684: {"feed":"book","product_id":"PI_ETHUSD","side":"sell","seq":26662477,"price":2021.45,"qty":0.0,"timestamp":1626994941525}
1626994941.507711: {"feed":"book","product_id":"PI_ETHUSD","side":"sell","seq":26662478,"price":2021.45,"qty":67945.0,"timestamp":1626994941525}
1626994941.58231: {"feed":"book","product_id":"PI_ETHUSD","side":"sell","seq":26662479,"price":2006.7,"qty":0.0,"timestamp":1626994941604}
1626994941.5824351: {"feed":"book","product_id":"PI_ETHUSD","side":"sell","seq":26662480,"price":2006.5,"qty":49345.0,"timestamp":1626994941605}
1626994941.582897: {"feed":"book","product_id":"FI_XBTUSD_210924","side":"sell","seq":13502144,"price":32246.0,"qty":0.0,"timestamp":1626994941605}
1626994941.5829508: {"feed":"book","product_id":"FI_XBTUSD_210924","side":"sell","seq":13502145,"price":32256.5,"qty":16924.0,"timestamp":1626994941605}
1626994941.586947: {"feed":"book","product_id":"FI_XBTUSD_210924","side":"sell","seq":13502146,"price":32290.5,"qty":54000.0,"timestamp":1626994941609}
1626994941.587053: {"feed":"book","product_id":"FI_XBTUSD_210924","side":"sell","seq":13502147,"price":32289.5,"qty":20000.0,"timestamp":1626994941609}
1626994941.636401: {"feed":"book","product_id":"FI_BCHUSD_210730","side":"sell","seq":91204,"price":439.9,"qty":0.0,"timestamp":1626994941658}
1626994941.6365252: {"feed":"book","product_id":"FI_BCHUSD_210730","side":"sell","seq":91205,"price":440.1,"qty":50.0,"timestamp":1626994941658}
1626994941.636954: {"feed":"book","product_id":"FI_XRPUSD_210924","side":"sell","seq":602291,"price":0.5876,"qty":0.0,"timestamp":1626994941660}
1626994941.638294: {"feed":"book","product_id":"FI_XRPUSD_210924","side":"buy","seq":602292,"price":0.5839,"qty":49.0,"timestamp":1626994941660}
1626994941.708672: {"feed":"book","product_id":"PI_ETHUSD","side":"sell","seq":26662481,"price":2006.45,"qty":0.0,"timestamp":1626994941729}
1626994941.708797: {"feed":"book","product_id":"PI_ETHUSD","side":"sell","seq":26662482,"price":2007.1,"qty":13623.0,"timestamp":1626994941729}
1626994941.708863: {"feed":"book","product_id":"PI_ETHUSD","side":"sell","seq":26662483,"price":2013.25,"qty":0.0,"timestamp":1626994941729}
1626994941.708916: {"feed":"book","product_id":"PI_ETHUSD","side":"sell","seq":26662484,"price":2013.15,"qty":47939.0,"timestamp":1626994941729}
1626994941.708961: {"feed":"book","product_id":"PI_ETHUSD","side":"buy","seq":26662485,"price":2001.3,"qty":0.0,"timestamp":1626994941729}
1626994941.709017: {"feed":"book","product_id":"PI_ETHUSD","side":"buy","seq":26662486,"price":2001.3,"qty":17316.0,"timestamp":1626994941729}
1626994941.711621: {"feed":"book","product_id":"PI_ETHUSD","side":"sell","seq":26662487,"price":2007.7,"qty":8742.0,"timestamp":1626994941729}
1626994941.711696: {"feed":"book","product_id":"PI_ETHUSD","side":"sell","seq":26662488,"price":2007.7,"qty":26358.0,"timestamp":1626994941729}
1626994941.7117271: {"feed":"book","product_id":"PI_ETHUSD","side":"buy","seq":26662489,"price":2001.85,"qty":5005.0,"timestamp":1626994941730}
1626994941.711754: {"feed":"book","product_id":"PI_ETHUSD","side":"buy","seq":26662490,"price":2001.85,"qty":18709.0,"timestamp":1626994941730}
1626994941.711777: {"feed":"book","product_id":"PI_ETHUSD","side":"buy","seq":26662491,"price":2000.55,"qty":0.0,"timestamp":1626994941730}
1626994941.7118132: {"feed":"book","product_id":"PI_ETHUSD","side":"buy","seq":26662492,"price":2000.55,"qty":23217.0,"timestamp":1626994941730}
1626994941.7118442: {"feed":"book","product_id":"PI_ETHUSD","side":"sell","seq":26662493,"price":2008.45,"qty":0.0,"timestamp":1626994941730}
1626994941.711874: {"feed":"book","product_id":"PI_ETHUSD","side":"sell","seq":26662494,"price":2008.45,"qty":23475.0,"timestamp":1626994941730}
1626994941.711901: {"feed":"book","product_id":"PI_ETHUSD","side":"buy","seq":26662495,"price":1996.5,"qty":0.0,"timestamp":1626994941730}
1626994941.7119281: {"feed":"book","product_id":"PI_ETHUSD","side":"buy","seq":26662496,"price":1996.5,"qty":45365.0,"timestamp":1626994941730}
1626994941.71196: {"feed":"book","product_id":"PI_ETHUSD","side":"buy","seq":26662497,"price":1985.1,"qty":0.0,"timestamp":1626994941730}
1626994941.711988: {"feed":"book","product_id":"PI_ETHUSD","side":"buy","seq":26662498,"price":1985.1,"qty":66949.0,"timestamp":1626994941730}
1626994941.712012: {"feed":"book","product_id":"PI_ETHUSD","side":"sell","seq":26662499,"price":2021.45,"qty":0.0,"timestamp":1626994941730}
1626994941.7120378: {"feed":"book","product_id":"PI_ETHUSD","side":"sell","seq":26662500,"price":2021.45,"qty":67946.0,"timestamp":1626994941730}
1626994941.718631: {"feed":"book","product_id":"FI_XBTUSD_210730","side":"buy","seq":5160173,"price":32180.5,"qty":0.0,"timestamp":1626994941740}
1626994941.7187562: {"feed":"book","product_id":"FI_XBTUSD_210730","side":"buy","seq":5160174,"price":32181.5,"qty":1200.0,"timestamp":1626994941740}
1626994941.737421: {"feed":"book","product_id":"FI_XBTUSD_210730","side":"buy","seq":5160175,"price":32181.0,"qty":0.0,"timestamp":1626994941760}
1626994941.7375438: {"feed":"book","product_id":"FI_XBTUSD_210730","side":"buy","seq":5160176,"price":32182.0,"qty":50.0,"timestamp":1626994941760}
1626994941.749578: {"feed":"book","product_id":"PI_LTCUSD","side":"buy","seq":3423293,"price":119.23,"qty":0.0,"timestamp":1626994941772}
1626994941.749703: {"feed":"book","product_id":"PI_LTCUSD","side":"buy","seq":3423294,"price":119.16,"qty":1062.0,"timestamp":1626994941772}
1626994941.8044622: {"feed":"book","product_id":"PI_ETHUSD","side":"buy","seq":26662501,"price":2004.65,"qty":1930.0,"timestamp":1626994941827}
1626994941.804818: {"feed":"book","product_id":"PI_ETHUSD","side":"sell","seq":26662502,"price":2005.15,"qty":1911.0,"timestamp":1626994941827}
1626994941.8097038: {"feed":"book","product_id":"PI_LTCUSD","side":"buy","seq":3423295,"price":119.37,"qty":0.0,"timestamp":1626994941832}
1626994941.809828: {"feed":"book","product_id":"PI_ETHUSD","side":"buy","seq":26662503,"price":2003.5,"qty":0.0,"timestamp":1626994941832}
1626994941.814985: {"feed":"book","product_id":"PI_ETHUSD","side":"buy","seq":26662504,"price":2003.45,"qty":29466.0,"timestamp":1626994941836}
1626994941.8280199: {"feed":"book","product_id":"FI_XBTUSD_210924","side":"buy","seq":13502148,"price":32192.5,"qty":0.0,"timestamp":1626994941850}
1626994941.8281448: {"feed":"book","product_id":"FI_XBTUSD_210924","side":"buy","seq":13502149,"price":32192.5,"qty":18935.0,"timestamp":1626994941850}
1626994941.8282099: {"feed":"book","product_id":"FI_XBTUSD_210924","side":"sell","seq":13502150,"price":32256.5,"qty":0.0,"timestamp":1626994941850}
1626994941.8282619: {"feed":"book","product_id":"FI_XBTUSD_210924","side":"sell","seq":13502151,"price":32256.5,"qty":16938.0,"timestamp":1626994941850}
1626994941.846093: {"feed":"book","product_id":"PI_ETHUSD","side":"buy","seq":26662505,"price":2003.8,"qty":0.0,"timestamp":1626994941857}
1626994941.846217: {"feed":"book","product_id":"PI_ETHUSD","side":"buy","seq":26662506,"price":2003.55,"qty":20000.0,"timestamp":1626994941857}
1626994941.865341: {"feed":"book","product_id":"PI_ETHUSD","side":"buy","seq":26662507,"price":2003.85,"qty":4162.0,"timestamp":1626994941887}
1626994941.86545: {"feed":"book","product_id":"PI_ETHUSD","side":"buy","seq":26662508,"price":2003.6,"qty":15826.0,"timestamp":1626994941887}
1626994941.8682618: {"feed":"book","product_id":"PI_LTCUSD","side":"sell","seq":3423296,"price":119.64,"qty":29709.0,"timestamp":1626994941888}
1626994941.8683689: {"feed":"book","product_id":"PI_LTCUSD","side":"buy","seq":3423297,"price":119.33,"qty":11869.0,"timestamp":1626994941888}
1626994941.8684192: {"feed":"book","product_id":"PI_LTCUSD","side":"sell","seq":3423298,"price":119.6,"qty":4150.0,"timestamp":1626994941888}
1626994941.868472: {"feed":"book","product_id":"PI_LTCUSD","side":"buy","seq":3423299,"price":119.36,"qty":0.0,"timestamp":1626994941888}
1626994941.8713129: {"feed":"book","product_id":"PI_LTCUSD","side":"buy","seq":3423300,"price":119.26,"qty":8979.0,"timestamp":1626994941892}
1626994941.871426: {"feed":"book","product_id":"PI_LTCUSD","side":"buy","seq":3423301,"price":119.25,"qty":1830.0,"timestamp":1626994941892}
1626994941.8870342: {"feed":"book","product_id":"PI_LTCUSD","side":"sell","seq":3423302,"price":119.61,"qty":4235.0,"timestamp":1626994941907}
1626994941.911066: {"feed":"book","product_id":"PI_ETHUSD","side":"sell","seq":26662509,"price":2006.5,"qty":45376.0,"timestamp":1626994941932}
1626994941.932684: {"feed":"book","product_id":"PI_ETHUSD","side":"buy","seq":26662510,"price":2001.3,"qty":0.0,"timestamp":1626994941954}
1626994941.9328089: {"feed":"book","product_id":"PI_ETHUSD","side":"buy","seq":26662511,"price":2001.5,"qty":15735.0,"timestamp":1626994941954}
1626994941.9695091: {"feed":"book","product_id":"PI_LTCUSD","side":"buy","seq":3423303,"price":119.32,"qty":13782.0,"timestamp":1626994941983}
1626994941.9700391: {"feed":"book","product_id":"PI_LTCUSD","side":"buy","seq":3423304,"price":118.75,"qty":19199.0,"timestamp":1626994941983}
1626994941.9701319: {"feed":"book","product_id":"PI_LTCUSD","side":"buy","seq":3423305,"price":118.36,"qty":29999.0,"timestamp":1626994941983}
1626994941.987013: {"feed":"book","product_id":"PI_ETHUSD","side":"buy","seq":26662512,"price":2003.6,"qty":0.0,"timestamp":1626994942007}
1626994941.987136: {"feed":"book","product_id":"PI_ETHUSD","side":"buy","seq":26662513,"price":2003.4,"qty":30826.0,"timestamp":1626994942007}
1626994941.987189: {"feed":"book","product_id":"PI_ETHUSD","side":"buy","seq":26662514,"price":2003.55,"qty":0.0,"timestamp":1626994942008}
1626994941.9872398: {"feed":"book","product_id":"PI_ETHUSD","side":"buy","seq":26662515,"price":2003.35,"qty":23959.0,"timestamp":1626994942008}
1626994942.031828: {"feed":"book","product_id":"FI_XBTUSD_210924","side":"sell","seq":13502152,"price":32256.5,"qty":0.0,"timestamp":1626994942053}
1626994942.0319538: {"feed":"book","product_id":"FI_XBTUSD_210924","side":"sell","seq":13502153,"price":32246.0,"qty":14357.0,"timestamp":1626994942053}
1626994942.036745: {"feed":"book","product_id":"FI_XBTUSD_210924","side":"sell","seq":13502154,"price":32289.5,"qty":0.0,"timestamp":1626994942057}
1626994942.036875: {"feed":"book","product_id":"FI_XBTUSD_210924","side":"sell","seq":13502155,"price":32290.5,"qty":74000.0,"timestamp":1626994942057}
1626994942.143625: {"feed":"book","product_id":"FI_ETHUSD_211231","side":"buy","seq":2199122,"price":2026.45,"qty":5000.0,"timestamp":1626994942165}
1626994942.143738: {"feed":"book","product_id":"FI_ETHUSD_211231","side":"buy","seq":2199123,"price":2027.0,"qty":2757.0,"timestamp":1626994942165}
1626994942.1479628: {"feed":"book","product_id":"PI_ETHUSD","side":"sell","seq":26662516,"price":2007.7,"qty":8742.0,"timestamp":1626994942169}
1626994942.148073: {"feed":"book","product_id":"PI_ETHUSD","side":"sell","seq":26662517,"price":2007.7,"qty":26260.0,"timestamp":1626994942169}
1626994942.148121: {"feed":"book","product_id":"PI_ETHUSD","side":"sell","seq":26662518,"price":2007.1,"qty":0.0,"timestamp":1626994942169}
1626994942.14818: {"feed":"book","product_id":"PI_ETHUSD","side":"sell","seq":26662519,"price":2007.1,"qty":13558.0,"timestamp":1626994942169}
1626994942.150336: {"feed":"book","product_id":"PI_ETHUSD","side":"buy","seq":26662520,"price":2001.85,"qty":5005.0,"timestamp":1626994942169}
1626994942.1504462: {"feed":"book","product_id":"PI_ETHUSD","side":"buy","seq":26662521,"price":2001.85,"qty":18774.0,"timestamp":1626994942169}
1626994942.150496: {"feed":"book","product_id":"PI_ETHUSD","side":"sell","seq":26662522,"price":2008.45,"qty":0.0,"timestamp":1626994942169}
1626994942.150558: {"feed":"book","product_id":"PI_ETHUSD","side":"sell","seq":26662523,"price":2008.45,"qty":23409.0,"timestamp":1626994942169}
1626994942.1506078: {"feed":"book","product_id":"PI_ETHUSD","side":"buy","seq":26662524,"price":2000.55,"qty":0.0,"timestamp":1626994942169}
1626994942.150656: {"feed":"book","product_id":"PI_ETHUSD","side":"buy","seq":26662525,"price":2000.55,"qty":23282.0,"timestamp":1626994942169}
1626994942.1507258: {"feed":"book","product_id":"PI_ETHUSD","side":"buy","seq":26662526,"price":1996.5,"qty":0.0,"timestamp":1626994942169}
1626994942.150753: {"feed":"book","product_id":"PI_ETHUSD","side":"buy","seq":26662527,"price":1996.5,"qty":45402.0,"timestamp":1626994942169}
1626994942.150778: {"feed":"book","product_id":"PI_ETHUSD","side":"sell","seq":26662528,"price":2013.15,"qty":0.0,"timestamp":1626994942169}
1626994942.150806: {"feed":"book","product_id":"PI_ETHUSD","side":"sell","seq":26662529,"price":2013.15,"qty":47902.0,"timestamp":1626994942169}
1626994942.1508312: {"feed":"book","product_id":"PI_ETHUSD","side":"buy","seq":26662530,"price":2001.5,"qty":0.0,"timestamp":1626994942169}
1626994942.150857: {"feed":"book","product_id":"PI_ETHUSD","side":"buy","seq":26662531,"price":2001.5,"qty":15736.0,"timestamp":1626994942169}
1626994942.180983: {"feed":"book","product_id":"FI_XBTUSD_210730","side":"buy","seq":5160177,"price":32181.5,"qty":0.0,"timestamp":1626994942200}
1626994942.181105: {"feed":"book","product_id":"FI_XBTUSD_210730","side":"buy","seq":5160178,"price":32182.5,"qty":1200.0,"timestamp":1626994942200}
1626994942.191453: {"feed":"book","product_id":"FI_XBTUSD_210730","side":"buy","seq":5160179,"price":32182.0,"qty":0.0,"timestamp":1626994942213}
1626994942.191555: {"feed":"book","product_id":"FI_XBTUSD_210730","side":"buy","seq":5160180,"price":32183.0,"qty":50.0,"timestamp":1626994942213}
1626994942.195505: {"feed":"book","product_id":"PI_ETHUSD","side":"buy","seq":26662532,"price":2003.35,"qty":3959.0,"timestamp":1626994942216}
1626994942.195589: {"feed":"book","product_id":"PI_ETHUSD","side":"buy","seq":26662533,"price":2003.45,"qty":49466.0,"timestamp":1626994942216}
1626994942.195638: {"feed":"book","product_id":"PI_ETHUSD","side":"buy","seq":26662534,"price":2003.4,"qty":15000.0,"timestamp":1626994942217}
1626994942.195677: {"feed":"book","product_id":"PI_ETHUSD","side":"buy","seq":26662535,"price":2003.5,"qty":15826.0,"timestamp":1626994942217}
1626994942.23662: {"feed":"book","product_id":"FI_XBTUSD_210924","side":"sell","seq":13502156,"price":32246.0,"qty":0.0,"timestamp":1626994942257}
1626994942.236746: {"feed":"book","product_id":"FI_XBTUSD_210924","side":"sell","seq":13502157,"price":32256.5,"qty":16869.0,"timestamp":1626994942257}
1626994942.2387352: {"feed":"book","product_id":"FI_XBTUSD_210924","side":"sell","seq":13502158,"price":32290.5,"qty":54000.0,"timestamp":1626994942260}
1626994942.238844: {"feed":"book","product_id":"FI_XBTUSD_210924","side":"sell","seq":13502159,"price":32289.5,"qty":20000.0,"timestamp":1626994942260}
1626994942.2799191: {"feed":"book","product_id":"FI_ETHUSD_210730","side":"buy","seq":2138805,"price":1999.8,"qty":0.0,"timestamp":1626994942301}
1626994942.28004: {"feed":"book","product_id":"FI_ETHUSD_211231","side":"sell","seq":2199124,"price":2048.9,"qty":44305.0,"timestamp":1626994942301}
1626994942.2800949: {"feed":"book","product_id":"FI_ETHUSD_211231","side":"sell","seq":2199125,"price":2048.8,"qty":45099.0,"timestamp":1626994942301}
1626994942.280146: {"feed":"book","product_id":"FI_ETHUSD_211231","side":"sell","seq":2199126,"price":2048.9,"qty":0.0,"timestamp":1626994942301}
1626994942.280192: {"feed":"book","product_id":"FI_ETHUSD_211231","side":"sell","seq":2199127,"price":2048.8,"qty":89404.0,"timestamp":1626994942301}
1626994942.29331: {"feed":"book","product_id":"FI_XBTUSD_210924","side":"sell","seq":13502160,"price":32266.5,"qty":5000.0,"timestamp":1626994942315}
1626994942.298957: {"feed":"book","product_id":"FI_XBTUSD_210924","side":"sell","seq":13502161,"price":32289.5,"qty":0.0,"timestamp":1626994942321}
1626994942.299045: {"feed":"book","product_id":"FI_XBTUSD_210924","side":"sell","seq":13502162,"price":32285.0,"qty":20000.0,"timestamp":1626994942321}
1626994942.326088: {"feed":"book","product_id":"PI_ETHUSD","side":"buy","seq":26662536,"price":2003.3,"qty":0.0,"timestamp":1626994942347}
1626994942.3398788: {"feed":"book","product_id":"PI_ETHUSD","side":"buy","seq":26662537,"price":2003.0,"qty":9419.0,"timestamp":1626994942362}
1626994942.3726459: {"feed":"book","product_id":"PI_ETHUSD","side":"buy","seq":26662538,"price":2001.5,"qty":0.0,"timestamp":1626994942392}
1626994942.37277: {"feed":"book","product_id":"PI_ETHUSD","side":"buy","seq":26662539,"price":2001.3,"qty":17251.0,"timestamp":1626994942392}
1626994942.440618: {"feed":"book","product_id":"FI_XBTUSD_210924","side":"sell","seq":13502163,"price":32256.5,"qty":0.0,"timestamp":1626994942461}
1626994942.44074: {"feed":"book","product_id":"FI_XBTUSD_210924","side":"sell","seq":13502164,"price":32246.0,"qty":14366.0,"timestamp":1626994942461}
1626994942.4431648: {"feed":"book","product_id":"FI_XBTUSD_210924","side":"sell","seq":13502165,"price":32285.0,"qty":0.0,"timestamp":1626994942465}
1626994942.443288: {"feed":"book","product_id":"FI_XBTUSD_210924","side":"sell","seq":13502166,"price":32289.5,"qty":20000.0,"timestamp":1626994942465}
1626994942.509831: {"feed":"book","product_id":"FI_ETHUSD_210730","side":"sell","seq":2138806,"price":2013.95,"qty":0.0,"timestamp":1626994942530}
1626994942.5099552: {"feed":"book","product_id":"FI_ETHUSD_210730","side":"sell","seq":2138807,"price":2013.85,"qty":45421.0,"timestamp":1626994942530}
1626994942.52854: {"feed":"book","product_id":"PI_ETHUSD","side":"buy","seq":26662540,"price":2003.45,"qty":29466.0,"timestamp":1626994942549}
1626994942.528648: {"feed":"book","product_id":"PI_ETHUSD","side":"buy","seq":26662541,"price":2003.6,"qty":20000.0,"timestamp":1626994942549}
1626994942.5323951: {"feed":"book","product_id":"PI_ETHUSD","side":"buy","seq":26662542,"price":2003.5,"qty":0.0,"timestamp":1626994942555}
1626994942.532518: {"feed":"book","product_id":"PI_ETHUSD","side":"buy","seq":26662543,"price":2003.65,"qty":22192.0,"timestamp":1626994942555}
1626994942.574678: {"feed":"book","product_id":"PI_ETHUSD","side":"sell","seq":26662544,"price":2007.1,"qty":0.0,"timestamp":1626994942596}
1626994942.5748029: {"feed":"book","product_id":"PI_ETHUSD","side":"sell","seq":26662545,"price":2006.45,"qty":10345.0,"timestamp":1626994942596}
1626994942.5814002: {"feed":"book","product_id":"PI_ETHUSD","side":"sell","seq":26662546,"price":2006.2,"qty":4064.0,"timestamp":1626994942602}
1626994942.585214: {"feed":"book","product_id":"PI_ETHUSD","side":"buy","seq":26662547,"price":2003.7,"qty":0.0,"timestamp":1626994942606}
1626994942.585338: {"feed":"book","product_id":"PI_ETHUSD","side":"buy","seq":26662548,"price":2003.9,"qty":5359.0,"timestamp":1626994942607}
1626994942.685121: {"feed":"book","product_id":"FI_XBTUSD_210924","side":"buy","seq":13502167,"price":32192.5,"qty":0.0,"timestamp":1626994942705}
1626994942.685209: {"feed":"book","product_id":"FI_XBTUSD_210924","side":"buy","seq":13502168,"price":32192.5,"qty":18531.0,"timestamp":1626994942705}
1626994942.6852531: {"feed":"book","product_id":"FI_XBTUSD_210924","side":"sell","seq":13502169,"price":32246.0,"qty":0.0,"timestamp":1626994942705}
1626994942.685291: {"feed":"book","product_id":"FI_XBTUSD_210924","side":"sell","seq":13502170,"price":32246.0,"qty":14630.0,"timestamp":1626994942705}
1626994942.6853209: {"feed":"book","product_id":"FI_XBTUSD_210924","side":"buy","seq":13502171,"price":32175.0,"qty":1900.0,"timestamp":1626994942705}
1626994942.685345: {"feed":"book","product_id":"FI_XBTUSD_210924","side":"buy","seq":13502172,"price":32175.0,"qty":22810.0,"timestamp":1626994942705}
1626994942.685367: {"feed":"book","product_id":"FI_XBTUSD_210924","side":"sell","seq":13502173,"price":32281.5,"qty":0.0,"timestamp":1626994942705}
1626994942.6853938: {"feed":"book","product_id":"FI_XBTUSD_210924","side":"sell","seq":13502174,"price":32281.5,"qty":20967.0,"timestamp":1626994942705}
1626994942.690777: {"feed":"book","product_id":"FI_XBTUSD_210730","side":"buy","seq":5160181,"price":32182.5,"qty":0.0,"timestamp":1626994942711}
1626994942.690869: {"feed":"book","product_id":"FI_XBTUSD_210730","side":"buy","seq":5160182,"price":32183.0,"qty":1250.0,"timestamp":1626994942711}
1626994942.778823: {"feed":"book","product_id":"PI_ETHUSD","side":"sell","seq":26662549,"price":2006.45,"qty":0.0,"timestamp":1626994942800}
1626994942.778949: {"feed":"book","product_id":"PI_ETHUSD","side":"sell","seq":26662550,"price":2007.1,"qty":13634.0,"timestamp":1626994942800}
1626994942.8126578: {"feed":"book","product_id":"PI_ETHUSD","side":"buy","seq":26662551,"price":2003.45,"qty":12020.0,"timestamp":1626994942834}
1626994942.816177: {"feed":"book","product_id":"PI_ETHUSD","side":"buy","seq":26662552,"price":2003.65,"qty":6366.0,"timestamp":1626994942838}
1626994942.816284: {"feed":"book","product_id":"PI_ETHUSD","side":"buy","seq":26662553,"price":2003.55,"qty":15826.0,"timestamp":1626994942838}
1626994942.816349: {"feed":"book","product_id":"PI_ETHUSD","side":"buy","seq":26662554,"price":2003.6,"qty":0.0,"timestamp":1626994942838}
1626994942.816405: {"feed":"book","product_id":"PI_ETHUSD","side":"buy","seq":26662555,"price":2003.5,"qty":20000.0,"timestamp":1626994942838}
1626994942.834576: {"feed":"book","product_id":"PI_ETHUSD","side":"buy","seq":26662556,"price":2003.45,"qty":29466.0,"timestamp":1626994942857}
1626994942.852528: {"feed":"book","product_id":"PI_ETHUSD","side":"buy","seq":26662557,"price":2003.5,"qty":0.0,"timestamp":1626994942873}
1626994942.852654: {"feed":"book","product_id":"PI_ETHUSD","side":"buy","seq":26662558,"price":2003.65,"qty":26366.0,"timestamp":1626994942873}
1626994942.8527098: {"feed":"book","product_id":"PI_ETHUSD","side":"buy","seq":26662559,"price":2003.55,"qty":0.0,"timestamp":1626994942873}
1626994942.8527622: {"feed":"book","product_id":"PI_ETHUSD","side":"buy","seq":26662560,"price":2003.7,"qty":15826.0,"timestamp":1626994942873}
1626994942.925792: {"feed":"book","product_id":"FI_XBTUSD_210924","side":"sell","seq":13502175,"price":32246.0,"qty":0.0,"timestamp":1626994942939}
1626994942.925854: {"feed":"book","product_id":"FI_XBTUSD_210924","side":"sell","seq":13502176,"price":32246.0,"qty":14629.0,"timestamp":1626994942939}
1626994942.9258811: {"feed":"book","product_id":"FI_XBTUSD_210924","side":"buy","seq":13502177,"price":32192.5,"qty":0.0,"timestamp":1626994942939}
1626994942.925903: {"feed":"book","product_id":"FI_XBTUSD_210924","side":"buy","seq":13502178,"price":32192.5,"qty":18532.0,"timestamp":1626994942939}
1626994942.9871721: {"feed":"book","product_id":"PI_ETHUSD","side":"buy","seq":26662561,"price":2003.7,"qty":0.0,"timestamp":1626994943009}
1626994942.987228: {"feed":"book","product_id":"PI_ETHUSD","side":"buy","seq":26662562,"price":2003.6,"qty":15826.0,"timestamp":1626994943009}
1626994942.98822: {"feed":"book","product_id":"PI_ETHUSD","side":"buy","seq":26662563,"price":2003.65,"qty":6366.0,"timestamp":1626994943010}
1626994942.988251: {"feed":"book","product_id":"PI_ETHUSD","side":"buy","seq":26662564,"price":2003.55,"qty":20000.0,"timestamp":1626994943010}
1626994942.992328: {"feed":"book","product_id":"PI_ETHUSD","side":"buy","seq":26662565,"price":2003.45,"qty":12020.0,"timestamp":1626994943013}
1626994942.992357: {"feed":"book","product_id":"PI_ETHUSD","side":"buy","seq":26662566,"price":2001.3,"qty":0.0,"timestamp":1626994943013}
1626994942.9923809: {"feed":"book","product_id":"PI_ETHUSD","side":"buy","seq":26662567,"price":2001.3,"qty":17373.0,"timestamp":1626994943013}
1626994942.994596: {"feed":"book","product_id":"PI_ETHUSD","side":"sell","seq":26662568,"price":2007.1,"qty":0.0,"timestamp":1626994943013}
1626994942.994632: {"feed":"book","product_id":"PI_ETHUSD","side":"sell","seq":26662569,"price":2007.1,"qty":13585.0,"timestamp":1626994943013}
1626994942.994654: {"feed":"book","product_id":"PI_ETHUSD","side":"sell","seq":26662570,"price":2007.7,"qty":8742.0,"timestamp":1626994943013}
1626994942.994668: {"feed":"book","product_id":"PI_ETHUSD","side":"sell","seq":26662571,"price":2007.7,"qty":26301.0,"timestamp":1626994943013}
1626994942.9946811: {"feed":"book","product_id":"PI_ETHUSD","side":"buy","seq":26662572,"price":2001.85,"qty":5005.0,"timestamp":1626994943013}
1626994942.994694: {"feed":"book","product_id":"PI_ETHUSD","side":"buy","seq":26662573,"price":2001.85,"qty":18747.0,"timestamp":1626994943013}
1626994942.994705: {"feed":"book","product_id":"PI_ETHUSD","side":"sell","seq":26662574,"price":2008.45,"qty":0.0,"timestamp":1626994943013}
1626994942.994721: {"feed":"book","product_id":"PI_ETHUSD","side":"sell","seq":26662575,"price":2008.45,"qty":23437.0,"timestamp":1626994943013}
1626994942.9947362: {"feed":"book","product_id":"PI_ETHUSD","side":"buy","seq":26662576,"price":2000.55,"qty":0.0,"timestamp":1626994943013}
1626994942.994751: {"feed":"book","product_id":"PI_ETHUSD","side":"buy","seq":26662577,"price":2000.55,"qty":23255.0,"timestamp":1626994943013}
1626994942.994765: {"feed":"book","product_id":"PI_ETHUSD","side":"buy","seq":26662578,"price":1996.5,"qty":0.0,"timestamp":1626994943013}
1626994942.9947798: {"feed":"book","product_id":"PI_ETHUSD","side":"buy","seq":26662579,"price":1996.5,"qty":45386.0,"timestamp":1626994943013}
1626994942.994793: {"feed":"book","product_id":"PI_ETHUSD","side":"sell","seq":26662580,"price":2013.15,"qty":0.0,"timestamp":1626994943013}
1626994942.994816: {"feed":"book","product_id":"PI_ETHUSD","side":"sell","seq":26662581,"price":2013.15,"qty":47917.0,"timestamp":1626994943013}
1626994943.0350668: {"feed":"book","product_id":"PI_ETHUSD","side":"buy","seq":26662582,"price":2003.45,"qty":29466.0,"timestamp":1626994943057}
1626994943.0599759: {"feed":"book","product_id":"PI_LTCUSD","side":"sell","seq":3423306,"price":119.7,"qty":16668.0,"timestamp":1626994943082}
1626994943.09863: {"feed":"book","product_id":"FI_ETHUSD_211231","side":"buy","seq":2199128,"price":2028.55,"qty":0.0,"timestamp":1626994943118}
1626994943.106532: {"feed":"book","product_id":"PI_ETHUSD","side":"buy","seq":26662583,"price":2003.55,"qty":0.0,"timestamp":1626994943127}
1626994943.10657: {"feed":"book","product_id":"PI_ETHUSD","side":"buy","seq":26662584,"price":2003.65,"qty":26366.0,"timestamp":1626994943127}
1626994943.126765: {"feed":"book","product_id":"PI_ETHUSD","side":"buy","seq":26662585,"price":2003.6,"qty":0.0,"timestamp":1626994943149}
1626994943.126799: {"feed":"book","product_id":"PI_ETHUSD","side":"buy","seq":26662586,"price":2003.7,"qty":15826.0,"timestamp":1626994943149}
1626994943.153993: {"feed":"book","product_id":"FI_XBTUSD_210924","side":"buy","seq":13502179,"price":32184.5,"qty":0.0,"timestamp":1626994943176}
1626994943.154046: {"feed":"book","product_id":"PI_LTCUSD","side":"buy","seq":3423307,"price":119.25,"qty":1000.0,"timestamp":1626994943177}
1626994943.160801: {"feed":"book","product_id":"FI_XBTUSD_210924","side":"buy","seq":13502180,"price":32192.5,"qty":0.0,"timestamp":1626994943183}
1626994943.160842: {"feed":"book","product_id":"FI_XBTUSD_210924","side":"buy","seq":13502181,"price":32193.0,"qty":18402.0,"timestamp":1626994943183}
1626994943.160865: {"feed":"book","product_id":"FI_XBTUSD_210924","side":"sell","seq":13502182,"price":32246.0,"qty":0.0,"timestamp":1626994943183}
1626994943.160884: {"feed":"book","product_id":"FI_XBTUSD_210924","side":"sell","seq":13502183,"price":32246.0,"qty":14630.0,"timestamp":1626994943183}
1626994943.1747289: {"feed":"book","product_id":"PI_ETHUSD","side":"buy","seq":26662587,"price":2003.65,"qty":6366.0,"timestamp":1626994943195}
1626994943.1747682: {"feed":"book","product_id":"PI_ETHUSD","side":"buy","seq":26662588,"price":2003.45,"qty":49466.0,"timestamp":1626994943195}
1626994943.1747851: {"feed":"book","product_id":"PI_ETHUSD","side":"buy","seq":26662589,"price":2003.7,"qty":0.0,"timestamp":1626994943195}
1626994943.174806: {"feed":"book","product_id":"PI_ETHUSD","side":"buy","seq":26662590,"price":2003.5,"qty":15826.0,"timestamp":1626994943195}
1626994943.220703: {"feed":"book","product_id":"PI_ETHUSD","side":"buy","seq":26662591,"price":2001.3,"qty":0.0,"timestamp":1626994943243}
1626994943.2207549: {"feed":"book","product_id":"PI_ETHUSD","side":"buy","seq":26662592,"price":2001.3,"qty":17243.0,"timestamp":1626994943243}
1626994943.220778: {"feed":"book","product_id":"PI_ETHUSD","side":"sell","seq":26662593,"price":2007.7,"qty":8742.0,"timestamp":1626994943243}
1626994943.220793: {"feed":"book","product_id":"PI_ETHUSD","side":"sell","seq":26662594,"price":2007.7,"qty":26433.0,"timestamp":1626994943243}
1626994943.22289: {"feed":"book","product_id":"PI_ETHUSD","side":"sell","seq":26662595,"price":2007.1,"qty":0.0,"timestamp":1626994943243}
1626994943.2229261: {"feed":"book","product_id":"PI_ETHUSD","side":"sell","seq":26662596,"price":2007.1,"qty":13673.0,"timestamp":1626994943243}
1626994943.222949: {"feed":"book","product_id":"PI_ETHUSD","side":"buy","seq":26662597,"price":2001.85,"qty":5005.0,"timestamp":1626994943243}
1626994943.2229629: {"feed":"book","product_id":"PI_ETHUSD","side":"buy","seq":26662598,"price":2001.85,"qty":18660.0,"timestamp":1626994943243}
1626994943.222976: {"feed":"book","product_id":"PI_ETHUSD","side":"buy","seq":26662599,"price":2000.55,"qty":0.0,"timestamp":1626994943243}
1626994943.222992: {"feed":"book","product_id":"PI_ETHUSD","side":"buy","seq":26662600,"price":2000.55,"qty":23169.0,"timestamp":1626994943243}
1626994943.223007: {"feed":"book","product_id":"PI_ETHUSD","side":"sell","seq":26662601,"price":2008.45,"qty":0.0,"timestamp":1626994943243}
1626994943.223021: {"feed":"book","product_id":"PI_ETHUSD","side":"sell","seq":26662602,"price":2008.45,"qty":23524.0,"timestamp":1626994943243}
1626994943.2230349: {"feed":"book","product_id":"PI_ETHUSD","side":"buy","seq":26662603,"price":1996.5,"qty":0.0,"timestamp":1626994943243}
1626994943.2230499: {"feed":"book","product_id":"PI_ETHUSD","side":"buy","seq":26662604,"price":1996.5,"qty":45337.0,"timestamp":1626994943243}
1626994943.223064: {"feed":"book","product_id":"PI_ETHUSD","side":"sell","seq":26662605,"price":2013.15,"qty":0.0,"timestamp":1626994943243}
1626994943.223086: {"feed":"book","product_id":"PI_ETHUSD","side":"sell","seq":26662606,"price":2013.15,"qty":47968.0,"timestamp":1626994943243}
1626994943.223489: {"feed":"book","product_id":"PI_ETHUSD","side":"buy","seq":26662607,"price":1985.1,"qty":0.0,"timestamp":1626994943243}
1626994943.223522: {"feed":"book","product_id":"PI_ETHUSD","side":"buy","seq":26662608,"price":1985.1,"qty":66948.0,"timestamp":1626994943243}
1626994943.3162339: {"feed":"book","product_id":"PI_ETHUSD","side":"buy","seq":26662609,"price":2003.5,"qty":0.0,"timestamp":1626994943338}
1626994943.316285: {"feed":"book","product_id":"PI_ETHUSD","side":"buy","seq":26662610,"price":2003.6,"qty":15826.0,"timestamp":1626994943338}
1626994943.316309: {"feed":"book","product_id":"PI_ETHUSD","side":"buy","seq":26662611,"price":2003.45,"qty":29466.0,"timestamp":1626994943338}
1626994943.316324: {"feed":"book","product_id":"PI_ETHUSD","side":"buy","seq":26662612,"price":2003.55,"qty":20000.0,"timestamp":1626994943338}
1626994943.364922: {"feed":"book","product_id":"FI_XBTUSD_210924","side":"buy","seq":13502184,"price":32193.0,"qty":0.0,"timestamp":1626994943387}
1626994943.364958: {"feed":"book","product_id":"FI_XBTUSD_210924","side":"buy","seq":13502185,"price":32192.5,"qty":18542.0,"timestamp":1626994943387}
1626994943.456377: {"feed":"book","product_id":"PI_ETHUSD","side":"sell","seq":26662613,"price":2007.1,"qty":0.0,"timestamp":1626994943478}
1626994943.456414: {"feed":"book","product_id":"PI_ETHUSD","side":"sell","seq":26662614,"price":2007.05,"qty":13391.0,"timestamp":1626994943478}
1626994943.456437: {"feed":"book","product_id":"PI_ETHUSD","side":"sell","seq":26662615,"price":2008.45,"qty":0.0,"timestamp":1626994943478}
1626994943.456456: {"feed":"book","product_id":"PI_ETHUSD","side":"sell","seq":26662616,"price":2008.4,"qty":23242.0,"timestamp":1626994943478}
1626994943.556781: {"feed":"book","product_id":"PI_ETHUSD","side":"sell","seq":26662617,"price":2013.2,"qty":0.0,"timestamp":1626994943578}
1626994943.5568168: {"feed":"book","product_id":"PI_ETHUSD","side":"sell","seq":26662618,"price":2013.1,"qty":500002.0,"timestamp":1626994943578}
1626994943.556839: {"feed":"book","product_id":"FI_ETHUSD_210730","side":"sell","seq":2138808,"price":2013.9,"qty":0.0,"timestamp":1626994943578}
1626994943.5568588: {"feed":"book","product_id":"FI_ETHUSD_210730","side":"sell","seq":2138809,"price":2013.8,"qty":250002.0,"timestamp":1626994943578}
1626994943.556875: {"feed":"book","product_id":"FI_ETHUSD_211231","side":"sell","seq":2199129,"price":2048.85,"qty":0.0,"timestamp":1626994943578}
1626994943.556892: {"feed":"book","product_id":"FI_ETHUSD_211231","side":"sell","seq":2199130,"price":2048.75,"qty":250002.0,"timestamp":1626994943578}
1626994943.5999308: {"feed":"book","product_id":"FI_XBTUSD_210924","side":"sell","seq":13502186,"price":32246.0,"qty":0.0,"timestamp":1626994943620}
1626994943.599966: {"feed":"book","product_id":"FI_XBTUSD_210924","side":"sell","seq":13502187,"price":32246.0,"qty":14619.0,"timestamp":1626994943620}
1626994943.618498: {"feed":"book","product_id":"PI_LTCUSD","side":"buy","seq":3423308,"price":119.32,"qty":4183.0,"timestamp":1626994943639}
1626994943.660341: {"feed":"book","product_id":"PI_ETHUSD","side":"sell","seq":26662619,"price":2007.05,"qty":0.0,"timestamp":1626994943681}
1626994943.660384: {"feed":"book","product_id":"PI_ETHUSD","side":"sell","seq":26662620,"price":2007.1,"qty":13673.0,"timestamp":1626994943681}
1626994943.660407: {"feed":"book","product_id":"PI_ETHUSD","side":"sell","seq":26662621,"price":2008.4,"qty":0.0,"timestamp":1626994943681}
1626994943.660425: {"feed":"book","product_id":"PI_ETHUSD","side":"sell","seq":26662622,"price":2008.45,"qty":23524.0,"timestamp":1626994943681}
1626994943.799051: {"feed":"book","product_id":"FI_XBTUSD_210730","side":"buy","seq":5160183,"price":32152.5,"qty":0.0,"timestamp":1626994943821}
1626994943.8106859: {"feed":"book","product_id":"PI_ETHUSD","side":"buy","seq":26662623,"price":2003.0,"qty":5000.0,"timestamp":1626994943833}
1626994943.8266308: {"feed":"book","product_id":"PI_ETHUSD","side":"buy","seq":26662624,"price":2003.3,"qty":5012.0,"timestamp":1626994943849}
1626994943.848086: {"feed":"book","product_id":"PI_XRPUSD","side":"buy","seq":3456228,"price":0.5881,"qty":15337.0,"timestamp":1626994943870}
1626994943.851171: {"feed":"book","product_id":"PI_XRPUSD","side":"buy","seq":3456229,"price":0.5881,"qty":5387.0,"timestamp":1626994943873}
1626994943.851201: {"feed":"book","product_id":"PI_XRPUSD","side":"buy","seq":3456230,"price":0.588,"qty":18872.0,"timestamp":1626994943873}
1626994943.864208: {"feed":"book","product_id":"PI_ETHUSD","side":"sell","seq":26662625,"price":2013.15,"qty":0.0,"timestamp":1626994943885}
1626994943.864247: {"feed":"book","product_id":"PI_ETHUSD","side":"sell","seq":26662626,"price":2013.05,"qty":47643.0,"timestamp":1626994943885}
1626994943.864268: {"feed":"book","product_id":"PI_ETHUSD","side":"buy","seq":26662627,"price":2001.85,"qty":5005.0,"timestamp":1626994943885}
1626994943.864288: {"feed":"book","product_id":"PI_ETHUSD","side":"buy","seq":26662628,"price":2001.85,"qty":18661.0,"timestamp":1626994943885}
1626994943.882277: {"feed":"book","product_id":"FI_XBTUSD_210924","side":"sell","seq":13502188,"price":32246.0,"qty":0.0,"timestamp":1626994943904}
1626994943.882314: {"feed":"book","product_id":"FI_XBTUSD_210924","side":"sell","seq":13502189,"price":32246.0,"qty":14639.0,"timestamp":1626994943904}
1626994943.882337: {"feed":"book","product_id":"FI_XBTUSD_210924","side":"buy","seq":13502190,"price":32192.5,"qty":0.0,"timestamp":1626994943904}
1626994943.882356: {"feed":"book","product_id":"FI_XBTUSD_210924","side":"buy","seq":13502191,"price":32192.5,"qty":18522.0,"timestamp":1626994943904}
1626994944.062138: {"feed":"book","product_id":"FI_XBTUSD_210924","side":"buy","seq":13502192,"price":32194.0,"qty":0.0,"timestamp":1626994944083}
1626994944.0691168: {"feed":"book","product_id":"PI_ETHUSD","side":"buy","seq":26662629,"price":2001.3,"qty":0.0,"timestamp":1626994944089}
1626994944.069154: {"feed":"book","product_id":"PI_ETHUSD","side":"buy","seq":26662630,"price":2001.5,"qty":15923.0,"timestamp":1626994944089}
1626994944.069178: {"feed":"book","product_id":"PI_ETHUSD","side":"sell","seq":26662631,"price":2007.7,"qty":8742.0,"timestamp":1626994944089}
1626994944.069193: {"feed":"book","product_id":"PI_ETHUSD","side":"sell","seq":26662632,"price":2007.7,"qty":26072.0,"timestamp":1626994944089}
1626994944.069206: {"feed":"book","product_id":"PI_ETHUSD","side":"sell","seq":26662633,"price":2007.1,"qty":0.0,"timestamp":1626994944089}
1626994944.069223: {"feed":"book","product_id":"PI_ETHUSD","side":"sell","seq":26662634,"price":2007.1,"qty":13432.0,"timestamp":1626994944089}
1626994944.069238: {"feed":"book","product_id":"PI_ETHUSD","side":"buy","seq":26662635,"price":2001.85,"qty":5005.0,"timestamp":1626994944089}
1626994944.06925: {"feed":"book","product_id":"PI_ETHUSD","side":"buy","seq":26662636,"price":2001.85,"qty":18900.0,"timestamp":1626994944089}
1626994944.069262: {"feed":"book","product_id":"PI_ETHUSD","side":"sell","seq":26662637,"price":2008.45,"qty":0.0,"timestamp":1626994944089}
1626994944.0692759: {"feed":"book","product_id":"PI_ETHUSD","side":"sell","seq":26662638,"price":2008.45,"qty":23283.0,"timestamp":1626994944089}
1626994944.06929: {"feed":"book","product_id":"PI_ETHUSD","side":"buy","seq":26662639,"price":2000.55,"qty":0.0,"timestamp":1626994944089}
1626994944.0693052: {"feed":"book","product_id":"PI_ETHUSD","side":"buy","seq":26662640,"price":2000.55,"qty":23407.0,"timestamp":1626994944089}
1626994944.069319: {"feed":"book","product_id":"PI_ETHUSD","side":"buy","seq":26662641,"price":1996.5,"qty":0.0,"timestamp":1626994944089}
1626994944.069334: {"feed":"book","product_id":"PI_ETHUSD","side":"buy","seq":26662642,"price":1996.5,"qty":45473.0,"timestamp":1626994944089}
1626994944.0693471: {"feed":"book","product_id":"PI_ETHUSD","side":"sell","seq":26662643,"price":2013.05,"qty":0.0,"timestamp":1626994944089}
1626994944.069362: {"feed":"book","product_id":"PI_ETHUSD","side":"sell","seq":26662644,"price":2013.05,"qty":47504.0,"timestamp":1626994944089}
1626994944.069376: {"feed":"book","product_id":"PI_ETHUSD","side":"buy","seq":26662645,"price":1985.1,"qty":0.0,"timestamp":1626994944089}
1626994944.06939: {"feed":"book","product_id":"PI_ETHUSD","side":"buy","seq":26662646,"price":1985.1,"qty":66950.0,"timestamp":1626994944089}
1626994944.069403: {"feed":"book","product_id":"PI_ETHUSD","side":"sell","seq":26662647,"price":2021.45,"qty":0.0,"timestamp":1626994944089}
1626994944.069417: {"feed":"book","product_id":"PI_ETHUSD","side":"sell","seq":26662648,"price":2021.45,"qty":67947.0,"timestamp":1626994944089}
1626994944.085699: {"feed":"book","product_id":"FI_XBTUSD_210924","side":"buy","seq":13502193,"price":32192.5,"qty":0.0,"timestamp":1626994944107}
1626994944.0857332: {"feed":"book","product_id":"FI_XBTUSD_210924","side":"buy","seq":13502194,"price":32192.5,"qty":18524.0,"timestamp":1626994944107}
1626994944.0857558: {"feed":"book","product_id":"FI_XBTUSD_210924","side":"sell","seq":13502195,"price":32246.0,"qty":0.0,"timestamp":1626994944107}
1626994944.0857751: {"feed":"book","product_id":"FI_XBTUSD_210924","side":"sell","seq":13502196,"price":32246.0,"qty":14638.0,"timestamp":1626994944107}
1626994944.1016161: {"feed":"book","product_id":"PI_ETHUSD","side":"buy","seq":26662649,"price":2003.6,"qty":0.0,"timestamp":1626994944123}
1626994944.10165: {"feed":"book","product_id":"PI_ETHUSD","side":"buy","seq":26662650,"price":2003.7,"qty":15826.0,"timestamp":1626994944123}
1626994944.105949: {"feed":"book","product_id":"PI_ETHUSD","side":"buy","seq":26662651,"price":2003.55,"qty":0.0,"timestamp":1626994944127}
1626994944.105983: {"feed":"book","product_id":"PI_ETHUSD","side":"buy","seq":26662652,"price":2003.65,"qty":26366.0,"timestamp":1626994944127}
1626994944.111168: {"feed":"book","product_id":"FI_XRPUSD_210924","side":"buy","seq":602293,"price":0.5839,"qty":0.0,"timestamp":1626994944132}
1626994944.111203: {"feed":"book","product_id":"FI_XRPUSD_210924","side":"sell","seq":602294,"price":0.5876,"qty":49.0,"timestamp":1626994944132}
1626994944.1154299: {"feed":"book","product_id":"FI_BCHUSD_210924","side":"buy","seq":402245,"price":440.4,"qty":0.0,"timestamp":1626994944138}
1626994944.115464: {"feed":"book","product_id":"FI_BCHUSD_210924","side":"sell","seq":402246,"price":442.8,"qty":66.0,"timestamp":1626994944138}
1626994944.2087932: {"feed":"book","product_id":"PI_ETHUSD","side":"sell","seq":26662653,"price":2013.1,"qty":0.0,"timestamp":1626994944229}
1626994944.208918: {"feed":"book","product_id":"PI_ETHUSD","side":"sell","seq":26662654,"price":2013.0,"qty":500002.0,"timestamp":1626994944229}
1626994944.23976: {"feed":"book","product_id":"PI_ETHUSD","side":"buy","seq":26662655,"price":2003.3,"qty":0.0,"timestamp":1626994944261}
1626994944.24986: {"feed":"book","product_id":"FI_XBTUSD_210924","side":"buy","seq":13502197,"price":32189.5,"qty":1900.0,"timestamp":1626994944271}
1626994944.272746: {"feed":"book","product_id":"PI_ETHUSD","side":"buy","seq":26662656,"price":2001.5,"qty":0.0,"timestamp":1626994944293}
1626994944.2728372: {"feed":"book","product_id":"PI_ETHUSD","side":"buy","seq":26662657,"price":2001.5,"qty":15956.0,"timestamp":1626994944293}
1626994944.2728782: {"feed":"book","product_id":"PI_ETHUSD","side":"sell","seq":26662658,"price":2007.7,"qty":8742.0,"timestamp":1626994944293}
1626994944.2729049: {"feed":"book","product_id":"PI_ETHUSD","side":"sell","seq":26662659,"price":2007.7,"qty":26039.0,"timestamp":1626994944293}
1626994944.272927: {"feed":"book","product_id":"PI_ETHUSD","side":"sell","seq":26662660,"price":2007.1,"qty":0.0,"timestamp":1626994944294}
1626994944.2729568: {"feed":"book","product_id":"PI_ETHUSD","side":"sell","seq":26662661,"price":2007.1,"qty":13410.0,"timestamp":1626994944294}
1626994944.27331: {"feed":"book","product_id":"PI_ETHUSD","side":"buy","seq":26662662,"price":2001.85,"qty":5005.0,"timestamp":1626994944294}
1626994944.273352: {"feed":"book","product_id":"PI_ETHUSD","side":"buy","seq":26662663,"price":2001.85,"qty":18922.0,"timestamp":1626994944294}
1626994944.2733781: {"feed":"book","product_id":"PI_ETHUSD","side":"sell","seq":26662664,"price":2008.45,"qty":0.0,"timestamp":1626994944294}
1626994944.273411: {"feed":"book","product_id":"PI_ETHUSD","side":"sell","seq":26662665,"price":2008.45,"qty":23261.0,"timestamp":1626994944294}
1626994944.273439: {"feed":"book","product_id":"PI_ETHUSD","side":"buy","seq":26662666,"price":2000.55,"qty":0.0,"timestamp":1626994944294}
1626994944.273468: {"feed":"book","product_id":"PI_ETHUSD","side":"buy","seq":26662667,"price":2000.55,"qty":23429.0,"timestamp":1626994944294}
1626994944.275115: {"feed":"book","product_id":"PI_ETHUSD","side":"sell","seq":26662668,"price":2013.05,"qty":0.0,"timestamp":1626994944294}
1626994944.275177: {"feed":"book","product_id":"PI_ETHUSD","side":"sell","seq":26662669,"price":2013.05,"qty":47491.0,"timestamp":1626994944294}
1626994944.275218: {"feed":"book","product_id":"PI_ETHUSD","side":"buy","seq":26662670,"price":1996.5,"qty":0.0,"timestamp":1626994944294}
1626994944.2752519: {"feed":"book","product_id":"PI_ETHUSD","side":"buy","seq":26662671,"price":1996.5,"qty":45485.0,"timestamp":1626994944294}
1626994944.310615: {"feed":"book","product_id":"FI_XBTUSD_210924","side":"sell","seq":13502198,"price":32246.0,"qty":0.0,"timestamp":1626994944332}
1626994944.3107479: {"feed":"book","product_id":"FI_XBTUSD_210924","side":"sell","seq":13502199,"price":32246.0,"qty":14653.0,"timestamp":1626994944332}
1626994944.311201: {"feed":"book","product_id":"FI_XBTUSD_210924","side":"buy","seq":13502200,"price":32192.5,"qty":0.0,"timestamp":1626994944332}
1626994944.3112588: {"feed":"book","product_id":"FI_XBTUSD_210924","side":"buy","seq":13502201,"price":32192.5,"qty":18508.0,"timestamp":1626994944332}
1626994944.314773: {"feed":"book","product_id":"PI_ETHUSD","side":"sell","seq":26662672,"price":2005.15,"qty":0.0,"timestamp":1626994944336}
1626994944.3152761: {"feed":"book","product_id":"FI_XBTUSD_210924","side":"sell","seq":13502202,"price":32289.5,"qty":0.0,"timestamp":1626994944336}
1626994944.315369: {"feed":"book","product_id":"FI_XBTUSD_210924","side":"sell","seq":13502203,"price":32289.0,"qty":23000.0,"timestamp":1626994944336}
1626994944.318887: {"feed":"book","product_id":"PI_ETHUSD","side":"buy","seq":26662673,"price":2003.45,"qty":12020.0,"timestamp":1626994944340}
1626994944.32964: {"feed":"book","product_id":"PI_ETHUSD","side":"buy","seq":26662674,"price":2003.3,"qty":4285.0,"timestamp":1626994944351}
1626994944.508898: {"feed":"book","product_id":"PI_ETHUSD","side":"buy","seq":26662675,"price":2001.5,"qty":0.0,"timestamp":1626994944529}
1626994944.508985: {"feed":"book","product_id":"PI_ETHUSD","side":"buy","seq":26662676,"price":2001.5,"qty":16054.0,"timestamp":1626994944529}
1626994944.509042: {"feed":"book","product_id":"PI_ETHUSD","side":"sell","seq":26662677,"price":2007.7,"qty":8742.0,"timestamp":1626994944529}
1626994944.509079: {"feed":"book","product_id":"PI_ETHUSD","side":"sell","seq":26662678,"price":2007.7,"qty":25940.0,"timestamp":1626994944529}
1626994944.509102: {"feed":"book","product_id":"PI_ETHUSD","side":"sell","seq":26662679,"price":2007.1,"qty":0.0,"timestamp":1626994944529}
1626994944.509134: {"feed":"book","product_id":"PI_ETHUSD","side":"sell","seq":26662680,"price":2007.1,"qty":13345.0,"timestamp":1626994944529}
1626994944.509162: {"feed":"book","product_id":"PI_ETHUSD","side":"buy","seq":26662681,"price":2001.85,"qty":5005.0,"timestamp":1626994944529}
1626994944.509185: {"feed":"book","product_id":"PI_ETHUSD","side":"buy","seq":26662682,"price":2001.85,"qty":18987.0,"timestamp":1626994944529}
1626994944.509503: {"feed":"book","product_id":"PI_ETHUSD","side":"sell","seq":26662683,"price":2008.45,"qty":0.0,"timestamp":1626994944529}
1626994944.509561: {"feed":"book","product_id":"PI_ETHUSD","side":"sell","seq":26662684,"price":2008.45,"qty":23196.0,"timestamp":1626994944529}
1626994944.513254: {"feed":"book","product_id":"PI_ETHUSD","side":"buy","seq":26662685,"price":2000.55,"qty":0.0,"timestamp":1626994944529}
1626994944.5133471: {"feed":"book","product_id":"PI_ETHUSD","side":"buy","seq":26662686,"price":2000.55,"qty":23494.0,"timestamp":1626994944529}
1626994944.513389: {"feed":"book","product_id":"PI_ETHUSD","side":"buy","seq":26662687,"price":1996.5,"qty":0.0,"timestamp":1626994944529}
1626994944.513422: {"feed":"book","product_id":"PI_ETHUSD","side":"buy","seq":26662688,"price":1996.5,"qty":45522.0,"timestamp":1626994944529}
1626994944.513451: {"feed":"book","product_id":"PI_ETHUSD","side":"sell","seq":26662689,"price":2013.05,"qty":0.0,"timestamp":1626994944530}
1626994944.513482: {"feed":"book","product_id":"PI_ETHUSD","side":"sell","seq":26662690,"price":2013.05,"qty":47454.0,"timestamp":1626994944530}
1626994944.5137868: {"feed":"book","product_id":"FI_ETHUSD_210730","side":"buy","seq":2138810,"price":1999.75,"qty":346.0,"timestamp":1626994944535}
1626994944.515614: {"feed":"book","product_id":"FI_ETHUSD_211231","side":"buy","seq":2199131,"price":2028.55,"qty":114.0,"timestamp":1626994944537}
1626994944.5156631: {"feed":"book","product_id":"PI_LTCUSD","side":"buy","seq":3423309,"price":119.25,"qty":1747.0,"timestamp":1626994944537}
1626994944.528979: {"feed":"book","product_id":"PI_ETHUSD","side":"sell","seq":26662691,"price":2007.75,"qty":325154.0,"timestamp":1626994944550}
1626994944.548649: {"feed":"book","product_id":"FI_XBTUSD_210924","side":"sell","seq":13502204,"price":32246.0,"qty":0.0,"timestamp":1626994944566}
1626994944.548778: {"feed":"book","product_id":"FI_XBTUSD_210924","side":"sell","seq":13502205,"price":32246.0,"qty":14624.0,"timestamp":1626994944566}
1626994944.548842: {"feed":"book","product_id":"FI_XBTUSD_210924","side":"buy","seq":13502206,"price":32192.5,"qty":0.0,"timestamp":1626994944566}
1626994944.548917: {"feed":"book","product_id":"FI_XBTUSD_210924","side":"buy","seq":13502207,"price":32192.5,"qty":18538.0,"timestamp":1626994944566}
1626994944.548985: {"feed":"book","product_id":"FI_XBTUSD_210924","side":"sell","seq":13502208,"price":32289.0,"qty":3000.0,"timestamp":1626994944570}
1626994944.5490088: {"feed":"book","product_id":"FI_XBTUSD_210924","side":"sell","seq":13502209,"price":32289.5,"qty":20000.0,"timestamp":1626994944570}
1626994944.790585: {"feed":"book","product_id":"PI_ETHUSD","side":"buy","seq":26662692,"price":2000.55,"qty":0.0,"timestamp":1626994944780}
1626994944.790723: {"feed":"book","product_id":"PI_ETHUSD","side":"buy","seq":26662693,"price":2000.6,"qty":23215.0,"timestamp":1626994944780}
1626994944.790793: {"feed":"book","product_id":"PI_ETHUSD","side":"sell","seq":26662694,"price":2013.05,"qty":0.0,"timestamp":1626994944780}
1626994944.790848: {"feed":"book","product_id":"PI_ETHUSD","side":"sell","seq":26662695,"price":2012.95,"qty":47128.0,"timestamp":1626994944780}
1626994944.790893: {"feed":"book","product_id":"PI_ETHUSD","side":"buy","seq":26662696,"price":1996.5,"qty":0.0,"timestamp":1626994944780}
1626994944.7909381: {"feed":"book","product_id":"PI_ETHUSD","side":"buy","seq":26662697,"price":1996.55,"qty":45364.0,"timestamp":1626994944780}
1626994944.7909791: {"feed":"book","product_id":"FI_XBTUSD_210924","side":"buy","seq":13502210,"price":32174.5,"qty":0.0,"timestamp":1626994944781}
1626994944.7910242: {"feed":"book","product_id":"FI_XBTUSD_210924","side":"buy","seq":13502211,"price":32195.0,"qty":10198.0,"timestamp":1626994944781}
1626994944.803775: {"feed":"book","product_id":"FI_XBTUSD_210924","side":"buy","seq":13502212,"price":32192.5,"qty":0.0,"timestamp":1626994944823}
1626994944.803911: {"feed":"book","product_id":"FI_XBTUSD_210924","side":"buy","seq":13502213,"price":32193.0,"qty":18409.0,"timestamp":1626994944823}
1626994944.8278358: {"feed":"book","product_id":"FI_ETHUSD_210730","side":"sell","seq":2138811,"price":2013.85,"qty":0.0,"timestamp":1626994944849}
1626994944.827958: {"feed":"book","product_id":"FI_ETHUSD_210730","side":"sell","seq":2138812,"price":2013.75,"qty":45421.0,"timestamp":1626994944849}
1626994944.8301702: {"feed":"book","product_id":"FI_ETHUSD_211231","side":"sell","seq":2199132,"price":2048.8,"qty":44305.0,"timestamp":1626994944849}
1626994944.8302798: {"feed":"book","product_id":"FI_ETHUSD_211231","side":"sell","seq":2199133,"price":2048.7,"qty":45099.0,"timestamp":1626994944849}
1626994944.830343: {"feed":"book","product_id":"FI_ETHUSD_211231","side":"sell","seq":2199134,"price":2048.8,"qty":0.0,"timestamp":1626994944849}
1626994944.830397: {"feed":"book","product_id":"FI_ETHUSD_211231","side":"sell","seq":2199135,"price":2048.7,"qty":89404.0,"timestamp":1626994944849}
1626994944.8613849: {"feed":"book","product_id":"PI_ETHUSD","side":"sell","seq":26662698,"price":2013.0,"qty":0.0,"timestamp":1626994944883}
1626994944.86147: {"feed":"book","product_id":"PI_ETHUSD","side":"sell","seq":26662699,"price":2012.9,"qty":500002.0,"timestamp":1626994944883}
1626994944.862159: {"feed":"book","product_id":"FI_ETHUSD_210730","side":"sell","seq":2138813,"price":2013.8,"qty":0.0,"timestamp":1626994944883}
1626994944.8622222: {"feed":"book","product_id":"FI_ETHUSD_211231","side":"sell","seq":2199136,"price":2048.75,"qty":0.0,"timestamp":1626994944883}
1626994944.862261: {"feed":"book","product_id":"FI_ETHUSD_211231","side":"sell","seq":2199137,"price":2048.65,"qty":250002.0,"timestamp":1626994944883}
1626994944.862294: {"feed":"book","product_id":"FI_ETHUSD_210730","side":"sell","seq":2138814,"price":2013.7,"qty":250002.0,"timestamp":1626994944883}
1626994944.888212: {"feed":"book","product_id":"FI_XRPUSD_210924","side":"buy","seq":602295,"price":0.5838,"qty":64.0,"timestamp":1626994944909}
1626994944.947312: {"feed":"book","product_id":"FI_XBTUSD_210924","side":"buy","seq":13502214,"price":32189.5,"qty":0.0,"timestamp":1626994944968}
1626994944.982213: {"feed":"book","product_id":"PI_ETHUSD","side":"buy","seq":26662700,"price":2000.6,"qty":0.0,"timestamp":1626994944998}
1626994944.982338: {"feed":"book","product_id":"PI_ETHUSD","side":"buy","seq":26662701,"price":2000.55,"qty":23429.0,"timestamp":1626994944998}
1626994944.9824052: {"feed":"book","product_id":"PI_ETHUSD","side":"buy","seq":26662702,"price":1996.55,"qty":0.0,"timestamp":1626994944998}
1626994944.982487: {"feed":"book","product_id":"PI_ETHUSD","side":"buy","seq":26662703,"price":1996.5,"qty":45485.0,"timestamp":1626994944998}
1626994944.982516: {"feed":"book","product_id":"PI_ETHUSD","side":"buy","seq":26662704,"price":2001.5,"qty":0.0,"timestamp":1626994944998}
1626994944.982545: {"feed":"book","product_id":"PI_ETHUSD","side":"buy","seq":26662705,"price":2001.5,"qty":15956.0,"timestamp":1626994944998}
1626994944.9825711: {"feed":"book","product_id":"PI_ETHUSD","side":"sell","seq":26662706,"price":2007.7,"qty":8742.0,"timestamp":1626994944998}
1626994944.982593: {"feed":"book","product_id":"PI_ETHUSD","side":"sell","seq":26662707,"price":2007.7,"qty":26039.0,"timestamp":1626994944998}
1626994944.982613: {"feed":"book","product_id":"PI_ETHUSD","side":"sell","seq":26662708,"price":2007.1,"qty":0.0,"timestamp":1626994944998}
1626994944.982641: {"feed":"book","product_id":"PI_ETHUSD","side":"sell","seq":26662709,"price":2007.1,"qty":13410.0,"timestamp":1626994944998}
1626994944.982666: {"feed":"book","product_id":"PI_ETHUSD","side":"buy","seq":26662710,"price":2001.85,"qty":5005.0,"timestamp":1626994944998}
1626994944.982688: {"feed":"book","product_id":"PI_ETHUSD","side":"buy","seq":26662711,"price":2001.85,"qty":18922.0,"timestamp":1626994944998}
1626994944.9832199: {"feed":"book","product_id":"PI_ETHUSD","side":"sell","seq":26662712,"price":2008.45,"qty":0.0,"timestamp":1626994944998}
1626994944.983281: {"feed":"book","product_id":"PI_ETHUSD","side":"sell","seq":26662713,"price":2008.45,"qty":23261.0,"timestamp":1626994944998}
1626994944.9833212: {"feed":"book","product_id":"PI_ETHUSD","side":"sell","seq":26662714,"price":2012.95,"qty":0.0,"timestamp":1626994944998}
1626994944.983354: {"feed":"book","product_id":"PI_ETHUSD","side":"sell","seq":26662715,"price":2012.95,"qty":47166.0,"timestamp":1626994944998}
1626994945.006559: {"feed":"book","product_id":"FI_XBTUSD_210924","side":"buy","seq":13502215,"price":32193.0,"qty":0.0,"timestamp":1626994945026}
1626994945.00669: {"feed":"book","product_id":"FI_XBTUSD_210924","side":"buy","seq":13502216,"price":32192.5,"qty":18545.0,"timestamp":1626994945026}
1626994945.006758: {"feed":"book","product_id":"FI_XBTUSD_210924","side":"sell","seq":13502217,"price":32246.0,"qty":0.0,"timestamp":1626994945026}
1626994945.006793: {"feed":"book","product_id":"FI_XBTUSD_210924","side":"sell","seq":13502218,"price":32246.0,"qty":14616.0,"timestamp":1626994945026}
1626994945.201937: {"feed":"book","product_id":"PI_ETHUSD","side":"sell","seq":26662716,"price":2012.95,"qty":0.0,"timestamp":1626994945222}
1626994945.202059: {"feed":"book","product_id":"PI_ETHUSD","side":"sell","seq":26662717,"price":2012.85,"qty":46841.0,"timestamp":1626994945222}
1626994945.202124: {"feed":"book","product_id":"PI_ETHUSD","side":"buy","seq":26662718,"price":2001.5,"qty":0.0,"timestamp":1626994945222}
1626994945.202176: {"feed":"book","product_id":"PI_ETHUSD","side":"buy","seq":26662719,"price":2001.5,"qty":15957.0,"timestamp":1626994945222}
1626994945.210057: {"feed":"book","product_id":"FI_XBTUSD_210924","side":"buy","seq":13502219,"price":32192.5,"qty":0.0,"timestamp":1626994945230}
1626994945.2101812: {"feed":"book","product_id":"FI_XBTUSD_210924","side":"buy","seq":13502220,"price":32195.5,"qty":17790.0,"timestamp":1626994945230}
1626994945.2102442: {"feed":"book","product_id":"FI_XBTUSD_210924","side":"buy","seq":13502221,"price":32175.0,"qty":1900.0,"timestamp":1626994945231}
1626994945.210285: {"feed":"book","product_id":"FI_XBTUSD_210924","side":"buy","seq":13502222,"price":32174.0,"qty":23910.0,"timestamp":1626994945231}
1626994945.210319: {"feed":"book","product_id":"FI_XBTUSD_210924","side":"sell","seq":13502223,"price":32246.0,"qty":0.0,"timestamp":1626994945231}
1626994945.2103639: {"feed":"book","product_id":"FI_XBTUSD_210924","side":"sell","seq":13502224,"price":32246.0,"qty":14601.0,"timestamp":1626994945231}
1626994945.312941: {"feed":"book","product_id":"PI_ETHUSD","side":"buy","seq":26662720,"price":1955.05,"qty":0.0,"timestamp":1626994945335}
1626994945.3353732: {"feed":"book","product_id":"FI_XBTUSD_210924","side":"buy","seq":13502225,"price":32194.0,"qty":1900.0,"timestamp":1626994945356}
1626994945.3639019: {"feed":"book","product_id":"PI_ETHUSD","side":"sell","seq":26662721,"price":2005.15,"qty":2092.0,"timestamp":1626994945384}
1626994945.3674922: {"feed":"book","product_id":"PI_ETHUSD","side":"buy","seq":26662722,"price":2003.45,"qty":29466.0,"timestamp":1626994945388}
1626994945.444513: {"feed":"book","product_id":"FI_XBTUSD_210924","side":"sell","seq":13502226,"price":32246.0,"qty":0.0,"timestamp":1626994945465}
1626994945.4446678: {"feed":"book","product_id":"FI_XBTUSD_210924","side":"sell","seq":13502227,"price":32246.0,"qty":14477.0,"timestamp":1626994945465}
1626994945.444731: {"feed":"book","product_id":"FI_XBTUSD_210924","side":"buy","seq":13502228,"price":32195.5,"qty":0.0,"timestamp":1626994945465}
1626994945.4447832: {"feed":"book","product_id":"FI_XBTUSD_210924","side":"buy","seq":13502229,"price":32195.5,"qty":17914.0,"timestamp":1626994945465}
1626994945.460673: {"feed":"book","product_id":"PI_XRPUSD","side":"buy","seq":3456231,"price":0.5688,"qty":0.0,"timestamp":1626994945482}
1626994945.557971: {"feed":"book","product_id":"PI_ETHUSD","side":"buy","seq":26662723,"price":2001.5,"qty":0.0,"timestamp":1626994945578}
1626994945.558093: {"feed":"book","product_id":"PI_ETHUSD","side":"buy","seq":26662724,"price":2001.5,"qty":16054.0,"timestamp":1626994945578}
1626994945.5581582: {"feed":"book","product_id":"PI_ETHUSD","side":"sell","seq":26662725,"price":2007.7,"qty":8742.0,"timestamp":1626994945578}
1626994945.558201: {"feed":"book","product_id":"PI_ETHUSD","side":"sell","seq":26662726,"price":2007.7,"qty":25940.0,"timestamp":1626994945578}
1626994945.558236: {"feed":"book","product_id":"PI_ETHUSD","side":"sell","seq":26662727,"price":2007.1,"qty":0.0,"timestamp":1626994945578}
1626994945.558306: {"feed":"book","product_id":"PI_ETHUSD","side":"sell","seq":26662728,"price":2007.1,"qty":13345.0,"timestamp":1626994945578}
1626994945.560791: {"feed":"book","product_id":"PI_ETHUSD","side":"buy","seq":26662729,"price":2001.85,"qty":5005.0,"timestamp":1626994945578}
1626994945.560866: {"feed":"book","product_id":"PI_ETHUSD","side":"buy","seq":26662730,"price":2001.85,"qty":18987.0,"timestamp":1626994945578}
1626994945.560898: {"feed":"book","product_id":"PI_ETHUSD","side":"sell","seq":26662731,"price":2008.45,"qty":0.0,"timestamp":1626994945578}
1626994945.560939: {"feed":"book","product_id":"PI_ETHUSD","side":"sell","seq":26662732,"price":2008.45,"qty":23196.0,"timestamp":1626994945578}
1626994945.560972: {"feed":"book","product_id":"PI_ETHUSD","side":"buy","seq":26662733,"price":2000.55,"qty":0.0,"timestamp":1626994945578}
1626994945.561004: {"feed":"book","product_id":"PI_ETHUSD","side":"buy","seq":26662734,"price":2000.55,"qty":23494.0,"timestamp":1626994945578}
1626994945.56103: {"feed":"book","product_id":"PI_ETHUSD","side":"buy","seq":26662735,"price":1996.5,"qty":0.0,"timestamp":1626994945578}
1626994945.561058: {"feed":"book","product_id":"PI_ETHUSD","side":"buy","seq":26662736,"price":1996.5,"qty":45522.0,"timestamp":1626994945578}
1626994945.5610838: {"feed":"book","product_id":"PI_ETHUSD","side":"sell","seq":26662737,"price":2012.85,"qty":0.0,"timestamp":1626994945578}
1626994945.561111: {"feed":"book","product_id":"PI_ETHUSD","side":"sell","seq":26662738,"price":2012.85,"qty":46803.0,"timestamp":1626994945578}
1626994945.590154: {"feed":"book","product_id":"PI_ETHUSD","side":"buy","seq":26662739,"price":2003.65,"qty":6366.0,"timestamp":1626994945610}
1626994945.590262: {"feed":"book","product_id":"PI_ETHUSD","side":"buy","seq":26662740,"price":2003.55,"qty":20000.0,"timestamp":1626994945610}
1626994945.590327: {"feed":"book","product_id":"PI_ETHUSD","side":"buy","seq":26662741,"price":2003.7,"qty":0.0,"timestamp":1626994945611}
1626994945.5903842: {"feed":"book","product_id":"PI_ETHUSD","side":"buy","seq":26662742,"price":2003.6,"qty":15826.0,"timestamp":1626994945611}
1626994945.679429: {"feed":"book","product_id":"FI_XBTUSD_210924","side":"sell","seq":13502230,"price":32246.0,"qty":0.0,"timestamp":1626994945700}
1626994945.679552: {"feed":"book","product_id":"FI_XBTUSD_210924","side":"sell","seq":13502231,"price":32246.0,"qty":14415.0,"timestamp":1626994945700}
1626994945.679615: {"feed":"book","product_id":"FI_XBTUSD_210924","side":"buy","seq":13502232,"price":32195.5,"qty":0.0,"timestamp":1626994945700}
1626994945.6796658: {"feed":"book","product_id":"FI_XBTUSD_210924","side":"buy","seq":13502233,"price":32195.5,"qty":17975.0,"timestamp":1626994945700}
1626994945.702844: {"feed":"book","product_id":"PI_ETHUSD","side":"buy","seq":26662743,"price":1999.75,"qty":0.0,"timestamp":1626994945724}
1626994945.7058501: {"feed":"book","product_id":"PI_ETHUSD","side":"buy","seq":26662744,"price":1996.2,"qty":13603.0,"timestamp":1626994945727}
1626994945.761246: {"feed":"book","product_id":"PI_ETHUSD","side":"buy","seq":26662745,"price":2001.5,"qty":0.0,"timestamp":1626994945783}
1626994945.7613351: {"feed":"book","product_id":"PI_ETHUSD","side":"buy","seq":26662746,"price":2001.5,"qty":15981.0,"timestamp":1626994945783}
1626994945.761376: {"feed":"book","product_id":"PI_ETHUSD","side":"sell","seq":26662747,"price":2007.7,"qty":8742.0,"timestamp":1626994945783}
1626994945.7614028: {"feed":"book","product_id":"PI_ETHUSD","side":"sell","seq":26662748,"price":2007.7,"qty":26014.0,"timestamp":1626994945783}
1626994945.7631512: {"feed":"book","product_id":"PI_ETHUSD","side":"sell","seq":26662749,"price":2007.1,"qty":0.0,"timestamp":1626994945783}
1626994945.763238: {"feed":"book","product_id":"PI_ETHUSD","side":"sell","seq":26662750,"price":2007.1,"qty":13394.0,"timestamp":1626994945783}
1626994945.76328: {"feed":"book","product_id":"PI_ETHUSD","side":"buy","seq":26662751,"price":2001.85,"qty":5005.0,"timestamp":1626994945783}
1626994945.763324: {"feed":"book","product_id":"PI_ETHUSD","side":"buy","seq":26662752,"price":2001.85,"qty":18938.0,"timestamp":1626994945783}
1626994945.7633479: {"feed":"book","product_id":"PI_ETHUSD","side":"sell","seq":26662753,"price":2008.45,"qty":0.0,"timestamp":1626994945783}
1626994945.763377: {"feed":"book","product_id":"PI_ETHUSD","side":"sell","seq":26662754,"price":2008.45,"qty":23245.0,"timestamp":1626994945783}
1626994945.7634041: {"feed":"book","product_id":"PI_ETHUSD","side":"buy","seq":26662755,"price":2000.55,"qty":0.0,"timestamp":1626994945783}
1626994945.763434: {"feed":"book","product_id":"PI_ETHUSD","side":"buy","seq":26662756,"price":2000.55,"qty":23446.0,"timestamp":1626994945783}
1626994945.763459: {"feed":"book","product_id":"PI_ETHUSD","side":"sell","seq":26662757,"price":2012.85,"qty":0.0,"timestamp":1626994945783}
1626994945.7635021: {"feed":"book","product_id":"PI_ETHUSD","side":"sell","seq":26662758,"price":2012.85,"qty":46832.0,"timestamp":1626994945783}
1626994945.764268: {"feed":"book","product_id":"PI_ETHUSD","side":"buy","seq":26662759,"price":1996.5,"qty":0.0,"timestamp":1626994945783}
1626994945.764354: {"feed":"book","product_id":"PI_ETHUSD","side":"buy","seq":26662760,"price":1996.5,"qty":45494.0,"timestamp":1626994945783}
1626994945.859134: {"feed":"book","product_id":"PI_LTCUSD","side":"sell","seq":3423310,"price":119.6,"qty":0.0,"timestamp":1626994945877}
1626994945.8592598: {"feed":"book","product_id":"PI_LTCUSD","side":"buy","seq":3423311,"price":119.36,"qty":4021.0,"timestamp":1626994945877}
1626994945.859326: {"feed":"book","product_id":"PI_LTCUSD","side":"sell","seq":3423312,"price":119.63,"qty":9022.0,"timestamp":1626994945878}
1626994945.859369: {"feed":"book","product_id":"PI_LTCUSD","side":"buy","seq":3423313,"price":119.33,"qty":8000.0,"timestamp":1626994945879}
1626994945.859405: {"feed":"book","product_id":"PI_LTCUSD","side":"buy","seq":3423314,"price":119.25,"qty":747.0,"timestamp":1626994945880}
1626994945.859447: {"feed":"book","product_id":"PI_LTCUSD","side":"buy","seq":3423315,"price":119.26,"qty":9979.0,"timestamp":1626994945880}
1626994945.9252841: {"feed":"book","product_id":"PI_ETHUSD","side":"buy","seq":26662761,"price":2003.6,"qty":0.0,"timestamp":1626994945946}
1626994945.925409: {"feed":"book","product_id":"PI_ETHUSD","side":"buy","seq":26662762,"price":2003.7,"qty":15826.0,"timestamp":1626994945946}
1626994945.9254742: {"feed":"book","product_id":"PI_ETHUSD","side":"buy","seq":26662763,"price":2003.55,"qty":0.0,"timestamp":1626994945946}
1626994945.925528: {"feed":"book","product_id":"PI_ETHUSD","side":"buy","seq":26662764,"price":2003.65,"qty":26366.0,"timestamp":1626994945946}
1626994945.9324002: {"feed":"book","product_id":"PI_ETHUSD","side":"buy","seq":26662765,"price":2003.65,"qty":23866.0,"timestamp":1626994945953}
1626994945.932511: {"feed":"book","product_id":"PI_ETHUSD","side":"sell","seq":26662766,"price":2007.5,"qty":0.0,"timestamp":1626994945953}
1626994945.948291: {"feed":"book","product_id":"PI_ETHUSD","side":"sell","seq":26662767,"price":2007.1,"qty":18394.0,"timestamp":1626994945970}
1626994945.9483972: {"feed":"book","product_id":"PI_ETHUSD","side":"buy","seq":26662768,"price":2003.9,"qty":7859.0,"timestamp":1626994945970}
1626994945.966089: {"feed":"book","product_id":"PI_ETHUSD","side":"buy","seq":26662769,"price":2001.5,"qty":0.0,"timestamp":1626994945987}
1626994945.9662132: {"feed":"book","product_id":"PI_ETHUSD","side":"buy","seq":26662770,"price":2001.5,"qty":15956.0,"timestamp":1626994945987}
1626994945.9662778: {"feed":"book","product_id":"PI_ETHUSD","side":"sell","seq":26662771,"price":2007.7,"qty":8742.0,"timestamp":1626994945987}
1626994945.966319: {"feed":"book","product_id":"PI_ETHUSD","side":"sell","seq":26662772,"price":2007.7,"qty":26039.0,"timestamp":1626994945987}
1626994945.966712: {"feed":"book","product_id":"PI_ETHUSD","side":"sell","seq":26662773,"price":2007.1,"qty":5000.0,"timestamp":1626994945987}
1626994945.966754: {"feed":"book","product_id":"PI_ETHUSD","side":"sell","seq":26662774,"price":2007.1,"qty":18411.0,"timestamp":1626994945987}
1626994945.969422: {"feed":"book","product_id":"PI_ETHUSD","side":"buy","seq":26662775,"price":2001.85,"qty":5005.0,"timestamp":1626994945987}
1626994945.9695292: {"feed":"book","product_id":"PI_ETHUSD","side":"buy","seq":26662776,"price":2001.85,"qty":18922.0,"timestamp":1626994945987}
1626994945.96958: {"feed":"book","product_id":"PI_ETHUSD","side":"sell","seq":26662777,"price":2008.45,"qty":0.0,"timestamp":1626994945987}
1626994945.969641: {"feed":"book","product_id":"PI_ETHUSD","side":"sell","seq":26662778,"price":2008.45,"qty":23262.0,"timestamp":1626994945987}
1626994945.969719: {"feed":"book","product_id":"PI_ETHUSD","side":"buy","seq":26662779,"price":2000.55,"qty":0.0,"timestamp":1626994945987}
1626994945.969752: {"feed":"book","product_id":"PI_ETHUSD","side":"buy","seq":26662780,"price":2000.55,"qty":23429.0,"timestamp":1626994945987}
1626994945.969779: {"feed":"book","product_id":"PI_ETHUSD","side":"buy","seq":26662781,"price":1996.5,"qty":0.0,"timestamp":1626994945987}
1626994945.9698071: {"feed":"book","product_id":"PI_ETHUSD","side":"buy","seq":26662782,"price":1996.5,"qty":45485.0,"timestamp":1626994945987}
1626994945.969833: {"feed":"book","product_id":"PI_ETHUSD","side":"sell","seq":26662783,"price":2012.85,"qty":0.0,"timestamp":1626994945987}
1626994945.96986: {"feed":"book","product_id":"PI_ETHUSD","side":"sell","seq":26662784,"price":2012.85,"qty":46841.0,"timestamp":1626994945987}
1626994946.0139909: {"feed":"book","product_id":"PI_ETHUSD","side":"buy","seq":26662785,"price":1953.65,"qty":0.0,"timestamp":1626994946035}
1626994946.121954: {"feed":"book","product_id":"FI_XBTUSD_210924","side":"sell","seq":13502234,"price":32246.0,"qty":0.0,"timestamp":1626994946143}
1626994946.122026: {"feed":"book","product_id":"FI_XBTUSD_210924","side":"sell","seq":13502235,"price":32246.0,"qty":14409.0,"timestamp":1626994946143}
1626994946.122059: {"feed":"book","product_id":"FI_XBTUSD_210924","side":"buy","seq":13502236,"price":32195.5,"qty":0.0,"timestamp":1626994946143}
1626994946.1220858: {"feed":"book","product_id":"FI_XBTUSD_210924","side":"buy","seq":13502237,"price":32195.5,"qty":17981.0,"timestamp":1626994946143}
1626994946.153909: {"feed":"book","product_id":"FI_XBTUSD_210924","side":"buy","seq":13502238,"price":32184.0,"qty":1097.0,"timestamp":1626994946173}
1626994946.153952: {"feed":"book","product_id":"PI_LTCUSD","side":"sell","seq":3423316,"price":119.7,"qty":16000.0,"timestamp":1626994946174}
1626994946.153971: {"feed":"book","product_id":"FI_XBTUSD_210730","side":"buy","seq":5160184,"price":32152.0,"qty":599.0,"timestamp":1626994946174}
1626994946.153989: {"feed":"book","product_id":"FI_XBTUSD_210924","side":"sell","seq":13502239,"price":32282.0,"qty":147656.0,"timestamp":1626994946174}
1626994946.154002: {"feed":"book","product_id":"PI_ETHUSD","side":"sell","seq":26662786,"price":2008.05,"qty":9049.0,"timestamp":1626994946175}
1626994946.154019: {"feed":"book","product_id":"PI_LTCUSD","side":"sell","seq":3423317,"price":119.74,"qty":588.0,"timestamp":1626994946175}
1626994946.155954: {"feed":"book","product_id":"FI_XBTUSD_210924","side":"sell","seq":13502240,"price":32289.5,"qty":0.0,"timestamp":1626994946177}
1626994946.155989: {"feed":"book","product_id":"FI_XBTUSD_210924","side":"sell","seq":13502241,"price":32289.0,"qty":23000.0,"timestamp":1626994946177}
1626994946.192364: {"feed":"book","product_id":"FI_ETHUSD_210730","side":"sell","seq":2138815,"price":2007.4,"qty":2057.0,"timestamp":1626994946213}
1626994946.192412: {"feed":"book","product_id":"PI_ETHUSD","side":"sell","seq":26662787,"price":2008.5,"qty":157311.0,"timestamp":1626994946213}
1626994946.192427: {"feed":"book","product_id":"FI_ETHUSD_211231","side":"sell","seq":2199138,"price":2035.0,"qty":757.0,"timestamp":1626994946213}
1626994946.199903: {"feed":"book","product_id":"PI_ETHUSD","side":"sell","seq":26662788,"price":2008.45,"qty":0.0,"timestamp":1626994946221}
1626994946.1999328: {"feed":"book","product_id":"PI_ETHUSD","side":"sell","seq":26662789,"price":2008.4,"qty":22904.0,"timestamp":1626994946221}
1626994946.19995: {"feed":"book","product_id":"PI_ETHUSD","side":"sell","seq":26662790,"price":2012.85,"qty":0.0,"timestamp":1626994946221}
1626994946.199965: {"feed":"book","product_id":"PI_ETHUSD","side":"sell","seq":26662791,"price":2012.8,"qty":46636.0,"timestamp":1626994946221}
1626994946.1999779: {"feed":"book","product_id":"PI_ETHUSD","side":"buy","seq":26662792,"price":2001.5,"qty":0.0,"timestamp":1626994946221}
1626994946.199997: {"feed":"book","product_id":"PI_ETHUSD","side":"buy","seq":26662793,"price":2001.5,"qty":16068.0,"timestamp":1626994946221}
1626994946.2006269: {"feed":"book","product_id":"PI_ETHUSD","side":"sell","seq":26662794,"price":2007.7,"qty":8742.0,"timestamp":1626994946221}
1626994946.200649: {"feed":"book","product_id":"PI_ETHUSD","side":"sell","seq":26662795,"price":2007.7,"qty":25927.0,"timestamp":1626994946221}
1626994946.20095: {"feed":"book","product_id":"PI_ETHUSD","side":"sell","seq":26662796,"price":2007.1,"qty":5000.0,"timestamp":1626994946221}
1626994946.200972: {"feed":"book","product_id":"PI_ETHUSD","side":"sell","seq":26662797,"price":2007.1,"qty":18336.0,"timestamp":1626994946221}
1626994946.2020109: {"feed":"book","product_id":"PI_ETHUSD","side":"buy","seq":26662798,"price":2001.85,"qty":5005.0,"timestamp":1626994946221}
1626994946.2020328: {"feed":"book","product_id":"PI_ETHUSD","side":"buy","seq":26662799,"price":2001.85,"qty":18996.0,"timestamp":1626994946221}
1626994946.202046: {"feed":"book","product_id":"PI_ETHUSD","side":"buy","seq":26662800,"price":2000.55,"qty":0.0,"timestamp":1626994946221}
1626994946.2020621: {"feed":"book","product_id":"PI_ETHUSD","side":"buy","seq":26662801,"price":2000.55,"qty":23503.0,"timestamp":1626994946221}
1626994946.2027671: {"feed":"book","product_id":"PI_ETHUSD","side":"buy","seq":26662802,"price":1996.5,"qty":0.0,"timestamp":1626994946221}
1626994946.202793: {"feed":"book","product_id":"PI_ETHUSD","side":"buy","seq":26662803,"price":1996.5,"qty":45527.0,"timestamp":1626994946221}
1626994946.202809: {"feed":"book","product_id":"PI_ETHUSD","side":"sell","seq":26662804,"price":2021.45,"qty":0.0,"timestamp":1626994946221}
1626994946.2028239: {"feed":"book","product_id":"PI_ETHUSD","side":"sell","seq":26662805,"price":2021.45,"qty":67948.0,"timestamp":1626994946221}
1626994946.282027: {"feed":"book","product_id":"PI_XRPUSD","side":"buy","seq":3456232,"price":0.5853,"qty":33599.0,"timestamp":1626994946303}
1626994946.349544: {"feed":"book","product_id":"PI_LTCUSD","side":"sell","seq":3423318,"price":119.65,"qty":4105.0,"timestamp":1626994946370}
1626994946.3566232: {"feed":"book","product_id":"FI_XBTUSD_210924","side":"sell","seq":13502242,"price":32246.0,"qty":0.0,"timestamp":1626994946377}
1626994946.356677: {"feed":"book","product_id":"FI_XBTUSD_210924","side":"sell","seq":13502243,"price":32246.0,"qty":14471.0,"timestamp":1626994946377}
1626994946.356697: {"feed":"book","product_id":"FI_XBTUSD_210924","side":"buy","seq":13502244,"price":32195.5,"qty":0.0,"timestamp":1626994946377}
1626994946.356714: {"feed":"book","product_id":"FI_XBTUSD_210924","side":"buy","seq":13502245,"price":32195.5,"qty":17919.0,"timestamp":1626994946377}
1626994946.3775811: {"feed":"book","product_id":"FI_ETHUSD_210730","side":"sell","seq":2138816,"price":2013.75,"qty":0.0,"timestamp":1626994946397}
1626994946.377717: {"feed":"book","product_id":"FI_ETHUSD_210730","side":"sell","seq":2138817,"price":2013.65,"qty":45421.0,"timestamp":1626994946397}
1626994946.3777611: {"feed":"book","product_id":"FI_ETHUSD_211231","side":"sell","seq":2199139,"price":2048.7,"qty":44305.0,"timestamp":1626994946397}
1626994946.377801: {"feed":"book","product_id":"FI_ETHUSD_211231","side":"sell","seq":2199140,"price":2048.6,"qty":45099.0,"timestamp":1626994946397}
1626994946.3778298: {"feed":"book","product_id":"FI_ETHUSD_211231","side":"sell","seq":2199141,"price":2048.7,"qty":0.0,"timestamp":1626994946397}
1626994946.377859: {"feed":"book","product_id":"FI_ETHUSD_211231","side":"sell","seq":2199142,"price":2048.6,"qty":89404.0,"timestamp":1626994946397}
1626994946.377881: {"feed":"book","product_id":"FI_BCHUSD_210730","side":"sell","seq":91206,"price":440.7,"qty":0.0,"timestamp":1626994946399}
1626994946.391559: {"feed":"book","product_id":"FI_XBTUSD_210924","side":"sell","seq":13502246,"price":32290.0,"qty":0.0,"timestamp":1626994946409}
1626994946.391687: {"feed":"book","product_id":"FI_XBTUSD_210924","side":"sell","seq":13502247,"price":32288.5,"qty":251089.0,"timestamp":1626994946409}
1626994946.391741: {"feed":"book","product_id":"PI_ETHUSD","side":"sell","seq":26662806,"price":2012.9,"qty":0.0,"timestamp":1626994946409}
1626994946.391795: {"feed":"book","product_id":"PI_ETHUSD","side":"sell","seq":26662807,"price":2012.75,"qty":500002.0,"timestamp":1626994946409}
1626994946.3918452: {"feed":"book","product_id":"FI_ETHUSD_211231","side":"sell","seq":2199143,"price":2048.65,"qty":0.0,"timestamp":1626994946409}
1626994946.391928: {"feed":"book","product_id":"FI_ETHUSD_211231","side":"sell","seq":2199144,"price":2048.55,"qty":250002.0,"timestamp":1626994946409}
1626994946.3919559: {"feed":"book","product_id":"FI_ETHUSD_210730","side":"sell","seq":2138818,"price":2013.7,"qty":0.0,"timestamp":1626994946409}
1626994946.391985: {"feed":"book","product_id":"FI_ETHUSD_210730","side":"sell","seq":2138819,"price":2014.9,"qty":250002.0,"timestamp":1626994946409}
1626994946.404469: {"feed":"book","product_id":"PI_ETHUSD","side":"sell","seq":26662808,"price":2008.4,"qty":0.0,"timestamp":1626994946425}
1626994946.4046001: {"feed":"book","product_id":"PI_ETHUSD","side":"sell","seq":26662809,"price":2008.45,"qty":23240.0,"timestamp":1626994946425}
1626994946.404665: {"feed":"book","product_id":"PI_ETHUSD","side":"sell","seq":26662810,"price":2012.8,"qty":0.0,"timestamp":1626994946425}
1626994946.404713: {"feed":"book","product_id":"PI_ETHUSD","side":"sell","seq":26662811,"price":2012.85,"qty":46829.0,"timestamp":1626994946425}
1626994946.404758: {"feed":"book","product_id":"PI_ETHUSD","side":"buy","seq":26662812,"price":2001.5,"qty":0.0,"timestamp":1626994946425}
1626994946.404804: {"feed":"book","product_id":"PI_ETHUSD","side":"buy","seq":26662813,"price":2001.5,"qty":15989.0,"timestamp":1626994946425}
1626994946.404845: {"feed":"book","product_id":"PI_ETHUSD","side":"sell","seq":26662814,"price":2007.7,"qty":8742.0,"timestamp":1626994946425}
1626994946.4048781: {"feed":"book","product_id":"PI_ETHUSD","side":"sell","seq":26662815,"price":2007.7,"qty":26006.0,"timestamp":1626994946425}
1626994946.405388: {"feed":"book","product_id":"PI_ETHUSD","side":"sell","seq":26662816,"price":2007.1,"qty":5000.0,"timestamp":1626994946425}
1626994946.40543: {"feed":"book","product_id":"PI_ETHUSD","side":"sell","seq":26662817,"price":2007.1,"qty":18389.0,"timestamp":1626994946425}
1626994946.405471: {"feed":"book","product_id":"PI_ETHUSD","side":"buy","seq":26662818,"price":2001.85,"qty":5005.0,"timestamp":1626994946425}
1626994946.405494: {"feed":"book","product_id":"PI_ETHUSD","side":"buy","seq":26662819,"price":2001.85,"qty":18944.0,"timestamp":1626994946425}
1626994946.405514: {"feed":"book","product_id":"PI_ETHUSD","side":"buy","seq":26662820,"price":2000.55,"qty":0.0,"timestamp":1626994946425}
1626994946.405544: {"feed":"book","product_id":"PI_ETHUSD","side":"buy","seq":26662821,"price":2000.55,"qty":23451.0,"timestamp":1626994946425}
1626994946.40557: {"feed":"book","product_id":"PI_ETHUSD","side":"buy","seq":26662822,"price":1996.5,"qty":0.0,"timestamp":1626994946425}
1626994946.405597: {"feed":"book","product_id":"PI_ETHUSD","side":"buy","seq":26662823,"price":1996.5,"qty":45497.0,"timestamp":1626994946425}
1626994946.405621: {"feed":"book","product_id":"PI_ETHUSD","side":"sell","seq":26662824,"price":2021.45,"qty":0.0,"timestamp":1626994946425}
1626994946.4056478: {"feed":"book","product_id":"PI_ETHUSD","side":"sell","seq":26662825,"price":2021.45,"qty":67947.0,"timestamp":1626994946425}
1626994946.414704: {"feed":"book","product_id":"PI_ETHUSD","side":"sell","seq":26662826,"price":2012.75,"qty":0.0,"timestamp":1626994946435}
1626994946.414798: {"feed":"book","product_id":"PI_ETHUSD","side":"sell","seq":26662827,"price":2012.8,"qty":500002.0,"timestamp":1626994946435}
1626994946.470399: {"feed":"book","product_id":"PI_ETHUSD","side":"buy","seq":26662828,"price":2003.7,"qty":0.0,"timestamp":1626994946491}
1626994946.470521: {"feed":"book","product_id":"PI_ETHUSD","side":"buy","seq":26662829,"price":2003.6,"qty":15826.0,"timestamp":1626994946491}
1626994946.4705842: {"feed":"book","product_id":"PI_ETHUSD","side":"buy","seq":26662830,"price":2003.65,"qty":3866.0,"timestamp":1626994946491}
1626994946.470627: {"feed":"book","product_id":"PI_ETHUSD","side":"buy","seq":26662831,"price":2003.55,"qty":20000.0,"timestamp":1626994946491}
1626994946.590137: {"feed":"book","product_id":"FI_XBTUSD_210924","side":"sell","seq":13502248,"price":32246.0,"qty":0.0,"timestamp":1626994946611}
1626994946.590223: {"feed":"book","product_id":"FI_XBTUSD_210924","side":"sell","seq":13502249,"price":32246.0,"qty":14968.0,"timestamp":1626994946611}
1626994946.590264: {"feed":"book","product_id":"FI_XBTUSD_210924","side":"buy","seq":13502250,"price":32195.5,"qty":0.0,"timestamp":1626994946611}
1626994946.5902982: {"feed":"book","product_id":"FI_XBTUSD_210924","side":"buy","seq":13502251,"price":32195.5,"qty":17424.0,"timestamp":1626994946611}
1626994946.590341: {"feed":"book","product_id":"FI_XBTUSD_210924","side":"buy","seq":13502252,"price":32174.0,"qty":3000.0,"timestamp":1626994946611}
1626994946.590364: {"feed":"book","product_id":"FI_XBTUSD_210924","side":"buy","seq":13502253,"price":32174.0,"qty":23909.0,"timestamp":1626994946611}
1626994946.59156: {"feed":"book","product_id":"FI_XBTUSD_210924","side":"sell","seq":13502254,"price":32281.5,"qty":0.0,"timestamp":1626994946611}
1626994946.591646: {"feed":"book","product_id":"FI_XBTUSD_210924","side":"sell","seq":13502255,"price":32281.5,"qty":20966.0,"timestamp":1626994946611}
1626994946.593191: {"feed":"book","product_id":"FI_XBTUSD_210924","side":"sell","seq":13502256,"price":32289.0,"qty":3000.0,"timestamp":1626994946615}
1626994946.593243: {"feed":"book","product_id":"FI_XBTUSD_210924","side":"sell","seq":13502257,"price":32285.0,"qty":20000.0,"timestamp":1626994946615}
1626994946.59918: {"feed":"book","product_id":"FI_XBTUSD_210924","side":"sell","seq":13502258,"price":32288.5,"qty":1088.0,"timestamp":1626994946619}
1626994946.599263: {"feed":"book","product_id":"FI_XBTUSD_210924","side":"sell","seq":13502259,"price":32290.0,"qty":250001.0,"timestamp":1626994946619}
1626994946.610068: {"feed":"book","product_id":"PI_ETHUSD","side":"buy","seq":26662832,"price":2001.5,"qty":0.0,"timestamp":1626994946629}
1626994946.6101918: {"feed":"book","product_id":"PI_ETHUSD","side":"buy","seq":26662833,"price":2001.5,"qty":16120.0,"timestamp":1626994946629}
1626994946.6102688: {"feed":"book","product_id":"PI_ETHUSD","side":"sell","seq":26662834,"price":2007.7,"qty":8742.0,"timestamp":1626994946629}
1626994946.610296: {"feed":"book","product_id":"PI_ETHUSD","side":"sell","seq":26662835,"price":2007.7,"qty":25875.0,"timestamp":1626994946629}
1626994946.6103182: {"feed":"book","product_id":"PI_ETHUSD","side":"sell","seq":26662836,"price":2007.1,"qty":5000.0,"timestamp":1626994946629}
1626994946.6103392: {"feed":"book","product_id":"PI_ETHUSD","side":"sell","seq":26662837,"price":2007.1,"qty":18301.0,"timestamp":1626994946629}
1626994946.610359: {"feed":"book","product_id":"PI_ETHUSD","side":"buy","seq":26662838,"price":2001.85,"qty":5005.0,"timestamp":1626994946629}
1626994946.61038: {"feed":"book","product_id":"PI_ETHUSD","side":"buy","seq":26662839,"price":2001.85,"qty":19031.0,"timestamp":1626994946629}
1626994946.6104: {"feed":"book","product_id":"PI_ETHUSD","side":"sell","seq":26662840,"price":2008.45,"qty":0.0,"timestamp":1626994946629}
1626994946.61043: {"feed":"book","product_id":"PI_ETHUSD","side":"sell","seq":26662841,"price":2008.45,"qty":23152.0,"timestamp":1626994946629}
1626994946.610471: {"feed":"book","product_id":"PI_ETHUSD","side":"buy","seq":26662842,"price":2000.55,"qty":0.0,"timestamp":1626994946629}
1626994946.6105: {"feed":"book","product_id":"PI_ETHUSD","side":"buy","seq":26662843,"price":2000.55,"qty":23538.0,"timestamp":1626994946629}
1626994946.611219: {"feed":"book","product_id":"PI_ETHUSD","side":"buy","seq":26662844,"price":1996.5,"qty":0.0,"timestamp":1626994946629}
1626994946.611281: {"feed":"book","product_id":"PI_ETHUSD","side":"buy","seq":26662845,"price":1996.5,"qty":45547.0,"timestamp":1626994946629}
1626994946.611321: {"feed":"book","product_id":"PI_ETHUSD","side":"sell","seq":26662846,"price":2012.85,"qty":0.0,"timestamp":1626994946630}
1626994946.6113548: {"feed":"book","product_id":"PI_ETHUSD","side":"sell","seq":26662847,"price":2012.85,"qty":46778.0,"timestamp":1626994946630}
1626994946.611386: {"feed":"book","product_id":"PI_ETHUSD","side":"buy","seq":26662848,"price":1985.1,"qty":0.0,"timestamp":1626994946630}
1626994946.611416: {"feed":"book","product_id":"PI_ETHUSD","side":"buy","seq":26662849,"price":1985.1,"qty":66951.0,"timestamp":1626994946630}
1626994946.611441: {"feed":"book","product_id":"PI_ETHUSD","side":"sell","seq":26662850,"price":2021.45,"qty":0.0,"timestamp":1626994946630}
1626994946.611468: {"feed":"book","product_id":"PI_ETHUSD","side":"sell","seq":26662851,"price":2021.45,"qty":67948.0,"timestamp":1626994946630}
1626994946.6439419: {"feed":"book","product_id":"PI_XRPUSD","side":"buy","seq":3456233,"price":0.5682,"qty":2.0,"timestamp":1626994946665}
1626994946.6461818: {"feed":"book","product_id":"PI_ETHUSD","side":"buy","seq":26662852,"price":2004.65,"qty":0.0,"timestamp":1626994946667}
1626994946.65942: {"feed":"book","product_id":"PI_ETHUSD","side":"buy","seq":26662853,"price":2003.55,"qty":0.0,"timestamp":1626994946680}
1626994946.659549: {"feed":"book","product_id":"PI_ETHUSD","side":"buy","seq":26662854,"price":2003.8,"qty":20000.0,"timestamp":1626994946680}
1626994946.659615: {"feed":"book","product_id":"PI_ETHUSD","side":"buy","seq":26662855,"price":2003.6,"qty":0.0,"timestamp":1626994946680}
1626994946.6596649: {"feed":"book","product_id":"PI_ETHUSD","side":"buy","seq":26662856,"price":2003.85,"qty":19988.0,"timestamp":1626994946680}
1626994946.825023: {"feed":"book","product_id":"FI_XBTUSD_210924","side":"sell","seq":13502260,"price":32246.0,"qty":0.0,"timestamp":1626994946846}
1626994946.8251579: {"feed":"book","product_id":"FI_XBTUSD_210924","side":"sell","seq":13502261,"price":32246.0,"qty":14638.0,"timestamp":1626994946846}
1626994946.825224: {"feed":"book","product_id":"FI_XBTUSD_210924","side":"buy","seq":13502262,"price":32195.5,"qty":0.0,"timestamp":1626994946846}
1626994946.825278: {"feed":"book","product_id":"FI_XBTUSD_210924","side":"buy","seq":13502263,"price":32195.5,"qty":17753.0,"timestamp":1626994946846}
1626994946.8253288: {"feed":"book","product_id":"FI_XBTUSD_210924","side":"buy","seq":13502264,"price":32174.0,"qty":3000.0,"timestamp":1626994946846}
1626994946.82538: {"feed":"book","product_id":"FI_XBTUSD_210924","side":"buy","seq":13502265,"price":32174.0,"qty":23910.0,"timestamp":1626994946846}
1626994946.8257082: {"feed":"book","product_id":"FI_XBTUSD_210924","side":"sell","seq":13502266,"price":32281.5,"qty":0.0,"timestamp":1626994946846}
1626994946.825784: {"feed":"book","product_id":"FI_XBTUSD_210924","side":"sell","seq":13502267,"price":32281.5,"qty":20967.0,"timestamp":1626994946846}
1626994946.840755: {"feed":"book","product_id":"PI_ETHUSD","side":"sell","seq":26662857,"price":2012.85,"qty":0.0,"timestamp":1626994946860}
1626994946.8408802: {"feed":"book","product_id":"PI_ETHUSD","side":"sell","seq":26662858,"price":2012.75,"qty":46428.0,"timestamp":1626994946860}
1626994946.840946: {"feed":"book","product_id":"PI_ETHUSD","side":"buy","seq":26662859,"price":2001.5,"qty":0.0,"timestamp":1626994946860}
1626994946.841002: {"feed":"book","product_id":"PI_ETHUSD","side":"buy","seq":26662860,"price":2001.5,"qty":16185.0,"timestamp":1626994946860}
1626994946.8410492: {"feed":"book","product_id":"PI_ETHUSD","side":"sell","seq":26662861,"price":2007.7,"qty":8742.0,"timestamp":1626994946860}
1626994946.8411: {"feed":"book","product_id":"PI_ETHUSD","side":"sell","seq":26662862,"price":2007.7,"qty":25809.0,"timestamp":1626994946860}
1626994946.842696: {"feed":"book","product_id":"PI_ETHUSD","side":"sell","seq":26662863,"price":2007.1,"qty":5000.0,"timestamp":1626994946860}
1626994946.842772: {"feed":"book","product_id":"PI_ETHUSD","side":"sell","seq":26662864,"price":2007.1,"qty":18257.0,"timestamp":1626994946860}
1626994946.842803: {"feed":"book","product_id":"PI_ETHUSD","side":"buy","seq":26662865,"price":2001.85,"qty":5005.0,"timestamp":1626994946860}
1626994946.842845: {"feed":"book","product_id":"PI_ETHUSD","side":"buy","seq":26662866,"price":2001.85,"qty":19075.0,"timestamp":1626994946860}
1626994946.8428679: {"feed":"book","product_id":"PI_ETHUSD","side":"sell","seq":26662867,"price":2008.45,"qty":0.0,"timestamp":1626994946860}
1626994946.842906: {"feed":"book","product_id":"PI_ETHUSD","side":"sell","seq":26662868,"price":2008.45,"qty":23108.0,"timestamp":1626994946860}
1626994946.842936: {"feed":"book","product_id":"PI_ETHUSD","side":"buy","seq":26662869,"price":2000.55,"qty":0.0,"timestamp":1626994946860}
1626994946.842966: {"feed":"book","product_id":"PI_ETHUSD","side":"buy","seq":26662870,"price":2000.55,"qty":23581.0,"timestamp":1626994946860}
1626994946.842992: {"feed":"book","product_id":"PI_ETHUSD","side":"buy","seq":26662871,"price":1996.5,"qty":0.0,"timestamp":1626994946860}
1626994946.843019: {"feed":"book","product_id":"PI_ETHUSD","side":"buy","seq":26662872,"price":1996.5,"qty":45571.0,"timestamp":1626994946860}
1626994946.8523688: {"feed":"book","product_id":"PI_ETHUSD","side":"sell","seq":26662873,"price":2012.8,"qty":0.0,"timestamp":1626994946871}
1626994946.852493: {"feed":"book","product_id":"PI_ETHUSD","side":"sell","seq":26662874,"price":2013.7,"qty":500002.0,"timestamp":1626994946871}
1626994946.877055: {"feed":"book","product_id":"PI_LTCUSD","side":"sell","seq":3423319,"price":119.61,"qty":8269.0,"timestamp":1626994946897}
1626994946.877163: {"feed":"book","product_id":"PI_LTCUSD","side":"sell","seq":3423320,"price":119.59,"qty":0.0,"timestamp":1626994946898}
1626994946.896231: {"feed":"book","product_id":"PI_LTCUSD","side":"sell","seq":3423321,"price":119.61,"qty":8209.0,"timestamp":1626994946914}
1626994947.013577: {"feed":"book","product_id":"PI_ETHUSD","side":"sell","seq":26662875,"price":2007.45,"qty":0.0,"timestamp":1626994947033}
1626994947.013702: {"feed":"book","product_id":"PI_ETHUSD","side":"sell","seq":26662876,"price":2007.9,"qty":42541.0,"timestamp":1626994947033}
1626994947.05568: {"feed":"book","product_id":"PI_ETHUSD","side":"sell","seq":26662877,"price":2013.7,"qty":0.0,"timestamp":1626994947076}
1626994947.055808: {"feed":"book","product_id":"PI_ETHUSD","side":"sell","seq":26662878,"price":2012.7,"qty":500002.0,"timestamp":1626994947076}
1626994947.057971: {"feed":"book","product_id":"FI_XBTUSD_210924","side":"sell","seq":13502268,"price":32246.0,"qty":0.0,"timestamp":1626994947076}
1626994947.058101: {"feed":"book","product_id":"FI_XBTUSD_210924","side":"sell","seq":13502269,"price":32246.0,"qty":14649.0,"timestamp":1626994947076}
1626994947.0581682: {"feed":"book","product_id":"FI_XBTUSD_210924","side":"buy","seq":13502270,"price":32195.5,"qty":0.0,"timestamp":1626994947076}
1626994947.058222: {"feed":"book","product_id":"FI_XBTUSD_210924","side":"buy","seq":13502271,"price":32195.5,"qty":17742.0,"timestamp":1626994947076}
1626994947.058275: {"feed":"book","product_id":"PI_ETHUSD","side":"buy","seq":26662879,"price":2003.8,"qty":0.0,"timestamp":1626994947076}
1626994947.058332: {"feed":"book","product_id":"PI_ETHUSD","side":"buy","seq":26662880,"price":2003.9,"qty":27859.0,"timestamp":1626994947076}
1626994947.0583549: {"feed":"book","product_id":"PI_ETHUSD","side":"buy","seq":26662881,"price":2003.85,"qty":4162.0,"timestamp":1626994947076}
1626994947.058378: {"feed":"book","product_id":"PI_ETHUSD","side":"buy","seq":26662882,"price":2003.95,"qty":15826.0,"timestamp":1626994947076}
1626994947.092712: {"feed":"book","product_id":"FI_BCHUSD_210730","side":"sell","seq":91207,"price":440.9,"qty":34509.0,"timestamp":1626994947113}
1626994947.097215: {"feed":"book","product_id":"PI_LTCUSD","side":"buy","seq":3423322,"price":119.37,"qty":61.0,"timestamp":1626994947117}
1626994947.102984: {"feed":"book","product_id":"PI_ETHUSD","side":"sell","seq":26662883,"price":2012.75,"qty":0.0,"timestamp":1626994947123}
1626994947.1031082: {"feed":"book","product_id":"PI_ETHUSD","side":"sell","seq":26662884,"price":2013.65,"qty":49354.0,"timestamp":1626994947123}
1626994947.103174: {"feed":"book","product_id":"PI_ETHUSD","side":"buy","seq":26662885,"price":1996.5,"qty":0.0,"timestamp":1626994947123}
1626994947.1032279: {"feed":"book","product_id":"PI_ETHUSD","side":"buy","seq":26662886,"price":1996.5,"qty":45572.0,"timestamp":1626994947123}
1626994947.10818: {"feed":"book","product_id":"PI_ETHUSD","side":"sell","seq":26662887,"price":2012.7,"qty":0.0,"timestamp":1626994947129}
1626994947.1083038: {"feed":"book","product_id":"PI_ETHUSD","side":"sell","seq":26662888,"price":2013.6,"qty":500002.0,"timestamp":1626994947129}
1626994947.1540558: {"feed":"book","product_id":"FI_BCHUSD_210924","side":"sell","seq":402247,"price":442.8,"qty":0.0,"timestamp":1626994947175}
1626994947.260733: {"feed":"book","product_id":"FI_XBTUSD_210924","side":"sell","seq":13502272,"price":32246.0,"qty":0.0,"timestamp":1626994947280}
1626994947.2608562: {"feed":"book","product_id":"FI_XBTUSD_210924","side":"sell","seq":13502273,"price":32246.0,"qty":14629.0,"timestamp":1626994947280}
1626994947.260921: {"feed":"book","product_id":"FI_XBTUSD_210924","side":"buy","seq":13502274,"price":32195.5,"qty":0.0,"timestamp":1626994947280}
1626994947.260989: {"feed":"book","product_id":"FI_XBTUSD_210924","side":"buy","seq":13502275,"price":32195.5,"qty":17762.0,"timestamp":1626994947280}
1626994947.262771: {"feed":"book","product_id":"FI_XBTUSD_210924","side":"sell","seq":13502276,"price":32285.0,"qty":0.0,"timestamp":1626994947283}
1626994947.262837: {"feed":"book","product_id":"FI_XBTUSD_210924","side":"sell","seq":13502277,"price":32289.0,"qty":23000.0,"timestamp":1626994947283}
1626994947.288086: {"feed":"book","product_id":"PI_LTCUSD","side":"buy","seq":3423323,"price":119.35,"qty":0.0,"timestamp":1626994947306}
1626994947.288213: {"feed":"book","product_id":"PI_LTCUSD","side":"buy","seq":3423324,"price":119.38,"qty":4235.0,"timestamp":1626994947306}
1626994947.307012: {"feed":"book","product_id":"PI_ETHUSD","side":"sell","seq":26662889,"price":2013.65,"qty":0.0,"timestamp":1626994947327}
1626994947.30714: {"feed":"book","product_id":"PI_ETHUSD","side":"sell","seq":26662890,"price":2012.65,"qty":46103.0,"timestamp":1626994947327}
1626994947.328966: {"feed":"book","product_id":"FI_ETHUSD_211231","side":"buy","seq":2199145,"price":2028.55,"qty":0.0,"timestamp":1626994947350}
1626994947.331182: {"feed":"book","product_id":"PI_ETHUSD","side":"buy","seq":26662891,"price":2003.9,"qty":7859.0,"timestamp":1626994947352}
1626994947.331222: {"feed":"book","product_id":"PI_ETHUSD","side":"buy","seq":26662892,"price":2003.75,"qty":20000.0,"timestamp":1626994947352}
1626994947.331251: {"feed":"book","product_id":"PI_ETHUSD","side":"buy","seq":26662893,"price":2003.95,"qty":0.0,"timestamp":1626994947352}
1626994947.331276: {"feed":"book","product_id":"PI_ETHUSD","side":"buy","seq":26662894,"price":2003.8,"qty":15826.0,"timestamp":1626994947352}
1626994947.464422: {"feed":"book","product_id":"PI_ETHUSD","side":"buy","seq":26662895,"price":2003.75,"qty":0.0,"timestamp":1626994947484}
1626994947.464548: {"feed":"book","product_id":"PI_ETHUSD","side":"buy","seq":26662896,"price":2003.85,"qty":24162.0,"timestamp":1626994947484}
1626994947.464604: {"feed":"book","product_id":"PI_ETHUSD","side":"buy","seq":26662897,"price":2003.8,"qty":0.0,"timestamp":1626994947484}
1626994947.4646559: {"feed":"book","product_id":"PI_ETHUSD","side":"buy","seq":26662898,"price":2003.9,"qty":23685.0,"timestamp":1626994947484}
1626994947.4835432: {"feed":"book","product_id":"PI_ETHUSD","side":"buy","seq":26662899,"price":2003.45,"qty":12020.0,"timestamp":1626994947504}
1626994947.485659: {"feed":"book","product_id":"PI_ETHUSD","side":"buy","seq":26662900,"price":2003.85,"qty":4162.0,"timestamp":1626994947507}
1626994947.4857678: {"feed":"book","product_id":"PI_ETHUSD","side":"buy","seq":26662901,"price":2003.7,"qty":20000.0,"timestamp":1626994947507}
1626994947.4863: {"feed":"book","product_id":"PI_ETHUSD","side":"buy","seq":26662902,"price":2003.9,"qty":7859.0,"timestamp":1626994947507}
1626994947.4863842: {"feed":"book","product_id":"PI_ETHUSD","side":"buy","seq":26662903,"price":2003.75,"qty":15826.0,"timestamp":1626994947507}
1626994947.4933078: {"feed":"book","product_id":"FI_XBTUSD_210924","side":"sell","seq":13502278,"price":32246.0,"qty":0.0,"timestamp":1626994947514}
1626994947.493432: {"feed":"book","product_id":"FI_XBTUSD_210924","side":"sell","seq":13502279,"price":32246.0,"qty":14627.0,"timestamp":1626994947514}
1626994947.493495: {"feed":"book","product_id":"FI_XBTUSD_210924","side":"buy","seq":13502280,"price":32195.5,"qty":0.0,"timestamp":1626994947514}
1626994947.493547: {"feed":"book","product_id":"FI_XBTUSD_210924","side":"buy","seq":13502281,"price":32195.5,"qty":17764.0,"timestamp":1626994947514}
1626994947.51139: {"feed":"book","product_id":"PI_ETHUSD","side":"sell","seq":26662904,"price":2012.65,"qty":0.0,"timestamp":1626994947531}
1626994947.511513: {"feed":"book","product_id":"PI_ETHUSD","side":"sell","seq":26662905,"price":2013.55,"qty":49042.0,"timestamp":1626994947531}
1626994947.526388: {"feed":"book","product_id":"FI_ETHUSD_211231","side":"sell","seq":2199146,"price":2048.6,"qty":44305.0,"timestamp":1626994947547}
1626994947.526465: {"feed":"book","product_id":"FI_ETHUSD_211231","side":"sell","seq":2199147,"price":2048.5,"qty":45099.0,"timestamp":1626994947547}
1626994947.526509: {"feed":"book","product_id":"FI_ETHUSD_211231","side":"sell","seq":2199148,"price":2048.6,"qty":0.0,"timestamp":1626994947547}
1626994947.5265448: {"feed":"book","product_id":"FI_ETHUSD_211231","side":"sell","seq":2199149,"price":2048.5,"qty":89404.0,"timestamp":1626994947547}
1626994947.53162: {"feed":"book","product_id":"PI_ETHUSD","side":"buy","seq":26662906,"price":2003.45,"qty":29466.0,"timestamp":1626994947553}
1626994947.53809: {"feed":"book","product_id":"PI_ETHUSD","side":"buy","seq":26662907,"price":2003.75,"qty":0.0,"timestamp":1626994947559}
1626994947.538222: {"feed":"book","product_id":"PI_ETHUSD","side":"buy","seq":26662908,"price":2003.85,"qty":19988.0,"timestamp":1626994947559}
1626994947.5382771: {"feed":"book","product_id":"PI_ETHUSD","side":"buy","seq":26662909,"price":2003.7,"qty":0.0,"timestamp":1626994947559}
1626994947.538351: {"feed":"book","product_id":"PI_ETHUSD","side":"buy","seq":26662910,"price":2003.8,"qty":20000.0,"timestamp":1626994947559}
1626994947.546557: {"feed":"book","product_id":"PI_ETHUSD","side":"buy","seq":26662911,"price":2003.45,"qty":12020.0,"timestamp":1626994947568}
1626994947.5572522: {"feed":"book","product_id":"PI_ETHUSD","side":"buy","seq":26662912,"price":2003.45,"qty":29466.0,"timestamp":1626994947579}
1626994947.586278: {"feed":"book","product_id":"PI_LTCUSD","side":"buy","seq":3423325,"price":119.32,"qty":0.0,"timestamp":1626994947606}
1626994947.586402: {"feed":"book","product_id":"PI_LTCUSD","side":"buy","seq":3423326,"price":119.36,"qty":7832.0,"timestamp":1626994947607}
1626994947.6624188: {"feed":"book","product_id":"PI_ETHUSD","side":"buy","seq":26662913,"price":2004.45,"qty":2039.0,"timestamp":1626994947682}
1626994947.695043: {"feed":"book","product_id":"PI_ETHUSD","side":"buy","seq":26662914,"price":2003.8,"qty":0.0,"timestamp":1626994947714}
1626994947.6951659: {"feed":"book","product_id":"PI_ETHUSD","side":"buy","seq":26662915,"price":2003.65,"qty":23866.0,"timestamp":1626994947714}
1626994947.695221: {"feed":"book","product_id":"PI_ETHUSD","side":"buy","seq":26662916,"price":2003.85,"qty":4162.0,"timestamp":1626994947715}
1626994947.695261: {"feed":"book","product_id":"PI_ETHUSD","side":"buy","seq":26662917,"price":2003.7,"qty":15826.0,"timestamp":1626994947715}
1626994947.705627: {"feed":"book","product_id":"PI_ETHUSD","side":"buy","seq":26662918,"price":2003.3,"qty":0.0,"timestamp":1626994947726}
1626994947.728299: {"feed":"book","product_id":"FI_XBTUSD_210924","side":"sell","seq":13502282,"price":32246.0,"qty":0.0,"timestamp":1626994947748}
1626994947.7284238: {"feed":"book","product_id":"FI_XBTUSD_210924","side":"sell","seq":13502283,"price":32246.0,"qty":14658.0,"timestamp":1626994947748}
1626994947.7287529: {"feed":"book","product_id":"FI_XBTUSD_210924","side":"buy","seq":13502284,"price":32195.5,"qty":0.0,"timestamp":1626994947748}
1626994947.728829: {"feed":"book","product_id":"FI_XBTUSD_210924","side":"buy","seq":13502285,"price":32195.5,"qty":17733.0,"timestamp":1626994947748}
1626994947.735691: {"feed":"book","product_id":"FI_XBTUSD_210924","side":"sell","seq":13502286,"price":32289.0,"qty":3000.0,"timestamp":1626994947756}
1626994947.735799: {"feed":"book","product_id":"FI_XBTUSD_210924","side":"sell","seq":13502287,"price":32285.0,"qty":20000.0,"timestamp":1626994947756}
1626994947.74433: {"feed":"book","product_id":"PI_ETHUSD","side":"buy","seq":26662919,"price":2001.5,"qty":0.0,"timestamp":1626994947765}
1626994947.7444649: {"feed":"book","product_id":"PI_ETHUSD","side":"buy","seq":26662920,"price":2001.5,"qty":15950.0,"timestamp":1626994947765}
1626994947.744533: {"feed":"book","product_id":"PI_ETHUSD","side":"sell","seq":26662921,"price":2007.7,"qty":8742.0,"timestamp":1626994947765}
1626994947.744575: {"feed":"book","product_id":"PI_ETHUSD","side":"sell","seq":26662922,"price":2007.7,"qty":26047.0,"timestamp":1626994947765}
1626994947.744611: {"feed":"book","product_id":"PI_ETHUSD","side":"sell","seq":26662923,"price":2007.1,"qty":5000.0,"timestamp":1626994947765}
1626994947.7446442: {"feed":"book","product_id":"PI_ETHUSD","side":"sell","seq":26662924,"price":2007.1,"qty":18416.0,"timestamp":1626994947765}
1626994947.745016: {"feed":"book","product_id":"PI_ETHUSD","side":"buy","seq":26662925,"price":2001.85,"qty":5005.0,"timestamp":1626994947765}
1626994947.745058: {"feed":"book","product_id":"PI_ETHUSD","side":"buy","seq":26662926,"price":2001.85,"qty":18917.0,"timestamp":1626994947765}
1626994947.7450838: {"feed":"book","product_id":"PI_ETHUSD","side":"sell","seq":26662927,"price":2008.45,"qty":0.0,"timestamp":1626994947765}
1626994947.745119: {"feed":"book","product_id":"PI_ETHUSD","side":"sell","seq":26662928,"price":2008.45,"qty":23267.0,"timestamp":1626994947765}
1626994947.745148: {"feed":"book","product_id":"PI_ETHUSD","side":"buy","seq":26662929,"price":2000.55,"qty":0.0,"timestamp":1626994947765}
1626994947.745177: {"feed":"book","product_id":"PI_ETHUSD","side":"buy","seq":26662930,"price":2000.55,"qty":23425.0,"timestamp":1626994947765}
1626994947.747207: {"feed":"book","product_id":"PI_ETHUSD","side":"buy","seq":26662931,"price":1996.5,"qty":0.0,"timestamp":1626994947765}
1626994947.747294: {"feed":"book","product_id":"PI_ETHUSD","side":"buy","seq":26662932,"price":1996.5,"qty":45482.0,"timestamp":1626994947765}
1626994947.747353: {"feed":"book","product_id":"PI_ETHUSD","side":"sell","seq":26662933,"price":2013.55,"qty":0.0,"timestamp":1626994947765}
1626994947.74739: {"feed":"book","product_id":"PI_ETHUSD","side":"sell","seq":26662934,"price":2013.55,"qty":49120.0,"timestamp":1626994947765}
