1618678110.814831: {"feed":"book","product_id":"FI_XRPUSD_210625","side":"buy","seq":3631543,"price":1.6925,"qty":68.0,"timestamp":1618678110789}
1618678110.814892: {"feed":"book","product_id":"FI_XRPUSD_210625","side":"sell","seq":3631544,"price":1.6972,"qty":0.0,"timestamp":1618678110789}
1618678110.814929: {"feed":"book","product_id":"FI_XRPUSD_210625","side":"sell","seq":3631545,"price":1.697,"qty":768.0,"timestamp":1618678110789}
1618678110.818092: {"feed":"book","product_id":"FI_XRPUSD_210625","side":"sell","seq":3631546,"price":1.6983,"qty":288.0,"timestamp":1618678110794}
1618678110.840283: {"feed":"book","product_id":"FI_XBTUSD_210924","side":"buy","seq":13850852,"price":52552.5,"qty":58611.0,"timestamp":1618678110803}
1618678110.872014: {"feed":"book","product_id":"FI_XBTUSD_210924","side":"buy","seq":13850853,"price":52552.5,"qty":58794.0,"timestamp":1618678110845}
1618678110.872128: {"feed":"book","product_id":"FI_XBTUSD_210430","side":"buy","seq":12237555,"price":60664.5,"qty":500.0,"timestamp":1618678110846}
1618678110.8721962: {"feed":"book","product_id":"FI_XBTUSD_210430","side":"sell","seq":12237556,"price":61941.5,"qty":500.0,"timestamp":1618678110846}
1618678110.881593: {"feed":"book","product_id":"FI_XRPUSD_210625","side":"buy","seq":3631547,"price":1.6909,"qty":0.0,"timestamp":1618678110857}
1618678110.881726: {"feed":"book","product_id":"FI_XRPUSD_210625","side":"buy","seq":3631548,"price":1.6917,"qty":19200.0,"timestamp":1618678110857}
1618678110.8879192: {"feed":"book","product_id":"FI_XRPUSD_210625","side":"buy","seq":3631549,"price":1.691,"qty":0.0,"timestamp":1618678110861}
1618678110.932936: {"feed":"book","product_id":"FI_ETHUSD_210625","side":"sell","seq":12455501,"price":2507.85,"qty":0.0,"timestamp":1618678110907}
1618678110.9330711: {"feed":"book","product_id":"FI_ETHUSD_210625","side":"sell","seq":12455502,"price":2507.95,"qty":18809.0,"timestamp":1618678110907}
1618678110.936019: {"feed":"book","product_id":"PI_BCHUSD","side":"buy","seq":16258672,"price":1059.0,"qty":3563.0,"timestamp":1618678110908}
1618678110.965211: {"feed":"book","product_id":"FI_XBTUSD_210625","side":"sell","seq":21455007,"price":64052.5,"qty":0.0,"timestamp":1618678110941}
1618678110.9653382: {"feed":"book","product_id":"FI_XBTUSD_210625","side":"sell","seq":21455008,"price":64053.0,"qty":13736.0,"timestamp":1618678110941}
1618678110.9654: {"feed":"book","product_id":"FI_XBTUSD_210625","side":"sell","seq":21455009,"price":64094.5,"qty":0.0,"timestamp":1618678110941}
1618678110.9654489: {"feed":"book","product_id":"FI_XBTUSD_210625","side":"sell","seq":21455010,"price":64093.5,"qty":22336.0,"timestamp":1618678110941}
1618678110.9888508: {"feed":"book","product_id":"FI_XBTUSD_210625","side":"sell","seq":21455011,"price":64042.0,"qty":5848.0,"timestamp":1618678110965}
1618678111.0147781: {"feed":"book","product_id":"FI_ETHUSD_210924","side":"sell","seq":3859151,"price":2661.55,"qty":0.0,"timestamp":1618678110985}
1618678111.014859: {"feed":"book","product_id":"FI_BCHUSD_210430","side":"buy","seq":1411874,"price":1074.9,"qty":50.0,"timestamp":1618678110986}
1618678111.0149472: {"feed":"book","product_id":"FI_BCHUSD_210625","side":"buy","seq":2240214,"price":1128.5,"qty":50.0,"timestamp":1618678110986}
1618678111.014998: {"feed":"book","product_id":"FI_BCHUSD_210430","side":"sell","seq":1411875,"price":1079.6,"qty":0.0,"timestamp":1618678110986}
1618678111.015049: {"feed":"book","product_id":"FI_BCHUSD_210430","side":"sell","seq":1411876,"price":1078.9,"qty":50.0,"timestamp":1618678110986}
1618678111.015091: {"feed":"book","product_id":"FI_BCHUSD_210625","side":"sell","seq":2240215,"price":1135.9,"qty":77.0,"timestamp":1618678110986}
1618678111.0151129: {"feed":"book","product_id":"FI_BCHUSD_210625","side":"sell","seq":2240216,"price":1134.6,"qty":50.0,"timestamp":1618678110986}
1618678111.015136: {"feed":"book","product_id":"FI_XBTUSD_210625","side":"sell","seq":21455012,"price":63972.0,"qty":5695.0,"timestamp":1618678110991}
1618678111.019009: {"feed":"book","product_id":"FI_XBTUSD_210430","side":"sell","seq":12237557,"price":61235.5,"qty":1904.0,"timestamp":1618678110993}
1618678111.030209: {"feed":"book","product_id":"PI_BCHUSD","side":"sell","seq":16258673,"price":1062.0,"qty":2750.0,"timestamp":1618678111005}
1618678111.030333: {"feed":"book","product_id":"PI_BCHUSD","side":"sell","seq":16258674,"price":1062.0,"qty":5266.0,"timestamp":1618678111005}
1618678111.0957508: {"feed":"book","product_id":"FI_XBTUSD_210430","side":"buy","seq":12237558,"price":59445.5,"qty":48172.0,"timestamp":1618678111072}
1618678111.103383: {"feed":"book","product_id":"FI_XRPUSD_210625","side":"buy","seq":3631550,"price":1.6924,"qty":0.0,"timestamp":1618678111079}
1618678111.103473: {"feed":"book","product_id":"FI_XRPUSD_210625","side":"buy","seq":3631551,"price":1.6926,"qty":50.0,"timestamp":1618678111079}
1618678111.113651: {"feed":"book","product_id":"FI_ETHUSD_210924","side":"sell","seq":3859152,"price":2671.05,"qty":0.0,"timestamp":1618678111089}
1618678111.11374: {"feed":"book","product_id":"FI_ETHUSD_210924","side":"sell","seq":3859153,"price":2670.55,"qty":219.0,"timestamp":1618678111089}
1618678111.113798: {"feed":"book","product_id":"FI_ETHUSD_210625","side":"sell","seq":12455503,"price":2507.5,"qty":0.0,"timestamp":1618678111089}
1618678111.113875: {"feed":"book","product_id":"FI_ETHUSD_210625","side":"sell","seq":12455504,"price":2507.0,"qty":441.0,"timestamp":1618678111089}
1618678111.1139042: {"feed":"book","product_id":"FI_ETHUSD_210430","side":"sell","seq":4780838,"price":2395.0,"qty":0.0,"timestamp":1618678111089}
1618678111.1139321: {"feed":"book","product_id":"FI_ETHUSD_210430","side":"sell","seq":4780839,"price":2394.6,"qty":578.0,"timestamp":1618678111089}
1618678111.1139572: {"feed":"book","product_id":"FI_XRPUSD_210625","side":"buy","seq":3631552,"price":1.6925,"qty":0.0,"timestamp":1618678111089}
1618678111.113985: {"feed":"book","product_id":"FI_XRPUSD_210625","side":"buy","seq":3631553,"price":1.6927,"qty":68.0,"timestamp":1618678111089}
1618678111.1334631: {"feed":"book","product_id":"FI_XRPUSD_210625","side":"buy","seq":3631554,"price":1.6926,"qty":0.0,"timestamp":1618678111106}
1618678111.1335528: {"feed":"book","product_id":"FI_XRPUSD_210625","side":"buy","seq":3631555,"price":1.6928,"qty":50.0,"timestamp":1618678111106}
1618678111.142281: {"feed":"book","product_id":"FI_XRPUSD_210625","side":"buy","seq":3631556,"price":1.6927,"qty":0.0,"timestamp":1618678111113}
1618678111.14237: {"feed":"book","product_id":"FI_XRPUSD_210625","side":"buy","seq":3631557,"price":1.6929,"qty":68.0,"timestamp":1618678111113}
1618678111.142426: {"feed":"book","product_id":"FI_ETHUSD_210625","side":"sell","seq":12455505,"price":2513.8,"qty":0.0,"timestamp":1618678111114}
1618678111.142475: {"feed":"book","product_id":"FI_ETHUSD_210625","side":"sell","seq":12455506,"price":2512.1,"qty":31878.0,"timestamp":1618678111114}
1618678111.142519: {"feed":"book","product_id":"FI_XBTUSD_210430","side":"buy","seq":12237559,"price":59445.5,"qty":52610.0,"timestamp":1618678111117}
1618678111.1646159: {"feed":"book","product_id":"FI_BCHUSD_210625","side":"buy","seq":2240217,"price":1108.1,"qty":13310.0,"timestamp":1618678111139}
1618678111.164727: {"feed":"book","product_id":"FI_BCHUSD_210625","side":"buy","seq":2240218,"price":1120.8,"qty":15022.0,"timestamp":1618678111139}
1618678111.16479: {"feed":"book","product_id":"FI_BCHUSD_210625","side":"buy","seq":2240219,"price":1108.3,"qty":0.0,"timestamp":1618678111139}
1618678111.164843: {"feed":"book","product_id":"FI_BCHUSD_210625","side":"buy","seq":2240220,"price":1120.8,"qty":19535.0,"timestamp":1618678111139}
1618678111.186476: {"feed":"book","product_id":"PI_BCHUSD","side":"sell","seq":16258675,"price":1062.0,"qty":2750.0,"timestamp":1618678111163}
1618678111.186582: {"feed":"book","product_id":"PI_BCHUSD","side":"sell","seq":16258676,"price":1062.8,"qty":27971.0,"timestamp":1618678111163}
1618678111.1884239: {"feed":"book","product_id":"PI_BCHUSD","side":"sell","seq":16258677,"price":1062.9,"qty":0.0,"timestamp":1618678111164}
1618678111.188549: {"feed":"book","product_id":"PI_BCHUSD","side":"buy","seq":16258678,"price":1059.3,"qty":5010.0,"timestamp":1618678111165}
1618678111.189281: {"feed":"book","product_id":"PI_BCHUSD","side":"buy","seq":16258679,"price":1058.7,"qty":7378.0,"timestamp":1618678111167}
1618678111.1947598: {"feed":"book","product_id":"FI_ETHUSD_210430","side":"buy","seq":4780840,"price":2387.6,"qty":0.0,"timestamp":1618678111169}
1618678111.1948118: {"feed":"book","product_id":"FI_ETHUSD_210430","side":"buy","seq":4780841,"price":2387.15,"qty":1020.0,"timestamp":1618678111169}
1618678111.1980789: {"feed":"book","product_id":"FI_ETHUSD_210625","side":"buy","seq":12455507,"price":2501.25,"qty":0.0,"timestamp":1618678111170}
1618678111.198142: {"feed":"book","product_id":"FI_ETHUSD_210625","side":"buy","seq":12455508,"price":2500.75,"qty":860.0,"timestamp":1618678111170}
1618678111.198179: {"feed":"book","product_id":"FI_ETHUSD_210625","side":"buy","seq":12455509,"price":2495.3,"qty":0.0,"timestamp":1618678111171}
1618678111.198211: {"feed":"book","product_id":"FI_ETHUSD_210625","side":"buy","seq":12455510,"price":2491.9,"qty":0.0,"timestamp":1618678111171}
1618678111.198238: {"feed":"book","product_id":"FI_ETHUSD_210430","side":"buy","seq":4780842,"price":2383.35,"qty":0.0,"timestamp":1618678111173}
1618678111.198263: {"feed":"book","product_id":"FI_ETHUSD_210430","side":"buy","seq":4780843,"price":2382.35,"qty":51000.0,"timestamp":1618678111173}
1618678111.202655: {"feed":"book","product_id":"FI_ETHUSD_210625","side":"sell","seq":12455511,"price":2510.05,"qty":0.0,"timestamp":1618678111175}
1618678111.2027981: {"feed":"book","product_id":"FI_ETHUSD_210625","side":"sell","seq":12455512,"price":2508.75,"qty":48000.0,"timestamp":1618678111175}
1618678111.2028632: {"feed":"book","product_id":"FI_ETHUSD_210625","side":"buy","seq":12455513,"price":2491.55,"qty":0.0,"timestamp":1618678111175}
1618678111.202915: {"feed":"book","product_id":"FI_ETHUSD_210625","side":"buy","seq":12455514,"price":2490.05,"qty":96000.0,"timestamp":1618678111175}
1618678111.2029681: {"feed":"book","product_id":"FI_ETHUSD_210625","side":"buy","seq":12455515,"price":2499.8,"qty":0.0,"timestamp":1618678111175}
1618678111.203014: {"feed":"book","product_id":"FI_ETHUSD_210625","side":"buy","seq":12455516,"price":2499.3,"qty":24000.0,"timestamp":1618678111175}
1618678111.2030442: {"feed":"book","product_id":"FI_ETHUSD_210430","side":"buy","seq":4780844,"price":2386.45,"qty":0.0,"timestamp":1618678111173}
1618678111.203072: {"feed":"book","product_id":"FI_ETHUSD_210430","side":"buy","seq":4780845,"price":2386.05,"qty":25500.0,"timestamp":1618678111173}
1618678111.203498: {"feed":"book","product_id":"FI_ETHUSD_210625","side":"sell","seq":12455517,"price":2504.65,"qty":0.0,"timestamp":1618678111175}
1618678111.203539: {"feed":"book","product_id":"FI_ETHUSD_210625","side":"sell","seq":12455518,"price":2504.1,"qty":24000.0,"timestamp":1618678111175}
1618678111.2035918: {"feed":"book","product_id":"FI_ETHUSD_210430","side":"sell","seq":4780846,"price":2390.4,"qty":0.0,"timestamp":1618678111173}
1618678111.2036219: {"feed":"book","product_id":"FI_ETHUSD_210430","side":"sell","seq":4780847,"price":2389.95,"qty":25500.0,"timestamp":1618678111173}
1618678111.203648: {"feed":"book","product_id":"FI_ETHUSD_210430","side":"sell","seq":4780848,"price":2398.6,"qty":0.0,"timestamp":1618678111173}
1618678111.2036722: {"feed":"book","product_id":"FI_ETHUSD_210430","side":"sell","seq":4780849,"price":2397.3,"qty":102000.0,"timestamp":1618678111173}
1618678111.203696: {"feed":"book","product_id":"FI_ETHUSD_210924","side":"sell","seq":3859154,"price":2659.8,"qty":0.0,"timestamp":1618678111174}
1618678111.203722: {"feed":"book","product_id":"FI_ETHUSD_210924","side":"sell","seq":3859155,"price":2659.35,"qty":21000.0,"timestamp":1618678111174}
1618678111.212754: {"feed":"book","product_id":"FI_XBTUSD_210924","side":"buy","seq":13850854,"price":52552.5,"qty":59063.0,"timestamp":1618678111179}
1618678111.212918: {"feed":"book","product_id":"FI_ETHUSD_210924","side":"sell","seq":3859156,"price":2659.7,"qty":359.0,"timestamp":1618678111183}
1618678111.2129622: {"feed":"book","product_id":"FI_ETHUSD_210924","side":"sell","seq":3859157,"price":2659.3,"qty":840.0,"timestamp":1618678111183}
1618678111.219033: {"feed":"book","product_id":"FI_ETHUSD_210924","side":"sell","seq":3859158,"price":2659.75,"qty":0.0,"timestamp":1618678111187}
1618678111.219214: {"feed":"book","product_id":"FI_ETHUSD_210430","side":"sell","seq":4780850,"price":2390.35,"qty":1614.0,"timestamp":1618678111189}
1618678111.219262: {"feed":"book","product_id":"FI_ETHUSD_210430","side":"sell","seq":4780851,"price":2389.9,"qty":1020.0,"timestamp":1618678111189}
1618678111.224093: {"feed":"book","product_id":"FI_ETHUSD_210625","side":"sell","seq":12455519,"price":2509.15,"qty":0.0,"timestamp":1618678111196}
1618678111.247284: {"feed":"book","product_id":"FI_XBTUSD_210625","side":"sell","seq":21455013,"price":64053.5,"qty":29466.0,"timestamp":1618678111205}
1618678111.256741: {"feed":"book","product_id":"FI_ETHUSD_210625","side":"buy","seq":12455520,"price":2494.15,"qty":2000.0,"timestamp":1618678111230}
1618678111.2989: {"feed":"book","product_id":"FI_XRPUSD_210625","side":"buy","seq":3631558,"price":1.6928,"qty":0.0,"timestamp":1618678111273}
1618678111.298986: {"feed":"book","product_id":"FI_XRPUSD_210625","side":"buy","seq":3631559,"price":1.693,"qty":50.0,"timestamp":1618678111273}
1618678111.3119192: {"feed":"book","product_id":"FI_XBTUSD_210625","side":"sell","seq":21455014,"price":64252.0,"qty":0.0,"timestamp":1618678111281}
1618678111.312047: {"feed":"book","product_id":"FI_XBTUSD_210625","side":"sell","seq":21455015,"price":64251.0,"qty":56913.0,"timestamp":1618678111281}
1618678111.312153: {"feed":"book","product_id":"FI_XBTUSD_210625","side":"sell","seq":21455016,"price":64118.5,"qty":0.0,"timestamp":1618678111281}
1618678111.312219: {"feed":"book","product_id":"FI_XBTUSD_210625","side":"sell","seq":21455017,"price":64118.5,"qty":28423.0,"timestamp":1618678111281}
1618678111.312246: {"feed":"book","product_id":"FI_XRPUSD_210625","side":"buy","seq":3631560,"price":1.6929,"qty":0.0,"timestamp":1618678111281}
1618678111.312276: {"feed":"book","product_id":"FI_XRPUSD_210625","side":"buy","seq":3631561,"price":1.6931,"qty":68.0,"timestamp":1618678111281}
1618678111.3123012: {"feed":"book","product_id":"FI_XBTUSD_210625","side":"buy","seq":21455018,"price":63896.0,"qty":1261.0,"timestamp":1618678111281}
1618678111.3123221: {"feed":"book","product_id":"FI_XBTUSD_210625","side":"buy","seq":21455019,"price":63896.0,"qty":2551.0,"timestamp":1618678111281}
1618678111.312342: {"feed":"book","product_id":"FI_XBTUSD_210625","side":"buy","seq":21455020,"price":63896.0,"qty":1290.0,"timestamp":1618678111281}
1618678111.312362: {"feed":"book","product_id":"FI_XBTUSD_210625","side":"buy","seq":21455021,"price":63896.0,"qty":2580.0,"timestamp":1618678111281}
1618678111.314201: {"feed":"book","product_id":"FI_XBTUSD_210625","side":"buy","seq":21455022,"price":63879.0,"qty":0.0,"timestamp":1618678111281}
1618678111.3142898: {"feed":"book","product_id":"FI_XBTUSD_210625","side":"buy","seq":21455023,"price":63879.0,"qty":1531.0,"timestamp":1618678111281}
1618678111.314332: {"feed":"book","product_id":"FI_XBTUSD_210625","side":"buy","seq":21455024,"price":63489.0,"qty":0.0,"timestamp":1618678111281}
1618678111.314364: {"feed":"book","product_id":"FI_XBTUSD_210625","side":"buy","seq":21455025,"price":63489.0,"qty":4315.0,"timestamp":1618678111281}
1618678111.3143911: {"feed":"book","product_id":"FI_XBTUSD_210625","side":"buy","seq":21455026,"price":63728.0,"qty":0.0,"timestamp":1618678111281}
1618678111.3144178: {"feed":"book","product_id":"FI_XBTUSD_210625","side":"buy","seq":21455027,"price":63728.0,"qty":3291.0,"timestamp":1618678111281}
1618678111.314442: {"feed":"book","product_id":"FI_XBTUSD_210625","side":"sell","seq":21455028,"price":64516.5,"qty":0.0,"timestamp":1618678111281}
1618678111.314469: {"feed":"book","product_id":"FI_XBTUSD_210625","side":"sell","seq":21455029,"price":64516.5,"qty":76454.0,"timestamp":1618678111281}
1618678111.314493: {"feed":"book","product_id":"FI_XRPUSD_210625","side":"buy","seq":3631562,"price":1.6905,"qty":248.0,"timestamp":1618678111285}
1618678111.3199549: {"feed":"book","product_id":"FI_XBTUSD_210625","side":"buy","seq":21455030,"price":62989.0,"qty":0.0,"timestamp":1618678111296}
1618678111.320082: {"feed":"book","product_id":"FI_XBTUSD_210625","side":"buy","seq":21455031,"price":62982.0,"qty":10000.0,"timestamp":1618678111296}
1618678111.32219: {"feed":"book","product_id":"FI_XBTUSD_210430","side":"sell","seq":12237560,"price":61235.5,"qty":5402.0,"timestamp":1618678111298}
1618678111.3222988: {"feed":"book","product_id":"PI_BCHUSD","side":"sell","seq":16258680,"price":1063.2,"qty":7839.0,"timestamp":1618678111298}
1618678111.322349: {"feed":"book","product_id":"PI_BCHUSD","side":"sell","seq":16258681,"price":1063.1,"qty":37834.0,"timestamp":1618678111298}
1618678111.3351722: {"feed":"book","product_id":"FI_XBTUSD_210924","side":"buy","seq":13850855,"price":68172.5,"qty":2687.0,"timestamp":1618678111303}
1618678111.335297: {"feed":"book","product_id":"FI_XBTUSD_210924","side":"buy","seq":13850856,"price":68191.0,"qty":0.0,"timestamp":1618678111304}
1618678111.3353589: {"feed":"book","product_id":"PI_BCHUSD","side":"sell","seq":16258682,"price":1062.7,"qty":3368.0,"timestamp":1618678111304}
1618678111.335403: {"feed":"book","product_id":"PI_BCHUSD","side":"buy","seq":16258683,"price":1058.6,"qty":20383.0,"timestamp":1618678111304}
1618678111.33544: {"feed":"book","product_id":"PI_BCHUSD","side":"buy","seq":16258684,"price":1059.0,"qty":0.0,"timestamp":1618678111305}
1618678111.3354828: {"feed":"book","product_id":"PI_BCHUSD","side":"sell","seq":16258685,"price":1062.2,"qty":24517.0,"timestamp":1618678111305}
1618678111.356441: {"feed":"book","product_id":"PI_BCHUSD","side":"buy","seq":16258686,"price":1058.6,"qty":21664.0,"timestamp":1618678111331}
1618678111.362154: {"feed":"book","product_id":"FI_XBTUSD_210625","side":"sell","seq":21455032,"price":64907.0,"qty":0.0,"timestamp":1618678111337}
1618678111.36228: {"feed":"book","product_id":"FI_XBTUSD_210625","side":"sell","seq":21455033,"price":64901.0,"qty":10000.0,"timestamp":1618678111337}
1618678111.3911738: {"feed":"book","product_id":"PI_BCHUSD","side":"sell","seq":16258687,"price":1063.1,"qty":27202.0,"timestamp":1618678111367}
1618678111.391283: {"feed":"book","product_id":"PI_BCHUSD","side":"sell","seq":16258688,"price":1062.9,"qty":10632.0,"timestamp":1618678111367}
1618678111.399791: {"feed":"book","product_id":"FI_XBTUSD_210430","side":"buy","seq":12237561,"price":59445.5,"qty":48172.0,"timestamp":1618678111376}
1618678111.448309: {"feed":"book","product_id":"FI_XBTUSD_210430","side":"buy","seq":12237562,"price":59445.5,"qty":48511.0,"timestamp":1618678111423}
1618678111.4483871: {"feed":"book","product_id":"FI_XBTUSD_210924","side":"sell","seq":13850857,"price":68291.0,"qty":23999.0,"timestamp":1618678111423}
1618678111.4540899: {"feed":"book","product_id":"FI_XBTUSD_210924","side":"sell","seq":13850858,"price":68291.5,"qty":0.0,"timestamp":1618678111428}
1618678111.454227: {"feed":"book","product_id":"FI_XBTUSD_210924","side":"sell","seq":13850859,"price":68290.5,"qty":10000.0,"timestamp":1618678111428}
1618678111.483437: {"feed":"book","product_id":"PI_BCHUSD","side":"sell","seq":16258689,"price":1062.9,"qty":0.0,"timestamp":1618678111459}
1618678111.4835682: {"feed":"book","product_id":"PI_BCHUSD","side":"sell","seq":16258690,"price":1062.7,"qty":14000.0,"timestamp":1618678111459}
1618678111.488935: {"feed":"book","product_id":"PI_BCHUSD","side":"sell","seq":16258691,"price":1061.9,"qty":136.0,"timestamp":1618678111465}
1618678111.495439: {"feed":"book","product_id":"PI_BCHUSD","side":"sell","seq":16258692,"price":1061.9,"qty":50.0,"timestamp":1618678111471}
1618678111.499702: {"feed":"book","product_id":"FI_ETHUSD_210625","side":"buy","seq":12455521,"price":2499.85,"qty":230.0,"timestamp":1618678111473}
1618678111.499815: {"feed":"book","product_id":"FI_ETHUSD_210625","side":"buy","seq":12455522,"price":2499.35,"qty":250.0,"timestamp":1618678111473}
1618678111.4998841: {"feed":"book","product_id":"FI_ETHUSD_210625","side":"buy","seq":12455523,"price":2499.85,"qty":0.0,"timestamp":1618678111473}
1618678111.499939: {"feed":"book","product_id":"FI_ETHUSD_210625","side":"buy","seq":12455524,"price":2499.35,"qty":500.0,"timestamp":1618678111473}
1618678111.4999769: {"feed":"book","product_id":"FI_ETHUSD_210625","side":"sell","seq":12455525,"price":2504.6,"qty":0.0,"timestamp":1618678111473}
1618678111.500048: {"feed":"book","product_id":"FI_ETHUSD_210625","side":"sell","seq":12455526,"price":2504.05,"qty":7267.0,"timestamp":1618678111473}
1618678111.511832: {"feed":"book","product_id":"PI_BCHUSD","side":"sell","seq":16258693,"price":1061.9,"qty":136.0,"timestamp":1618678111486}
1618678111.512418: {"feed":"book","product_id":"FI_XBTUSD_210924","side":"sell","seq":13850860,"price":68276.5,"qty":0.0,"timestamp":1618678111487}
1618678111.512513: {"feed":"book","product_id":"FI_XBTUSD_210924","side":"sell","seq":13850861,"price":68291.0,"qty":24049.0,"timestamp":1618678111487}
1618678111.530838: {"feed":"book","product_id":"PI_BCHUSD","side":"sell","seq":16258694,"price":1061.9,"qty":50.0,"timestamp":1618678111502}
1618678111.530946: {"feed":"book","product_id":"PI_BCHUSD","side":"sell","seq":16258695,"price":1061.9,"qty":136.0,"timestamp":1618678111506}
1618678111.542536: {"feed":"book","product_id":"PI_BCHUSD","side":"sell","seq":16258696,"price":1061.9,"qty":50.0,"timestamp":1618678111512}
1618678111.5426161: {"feed":"book","product_id":"PI_BCHUSD","side":"sell","seq":16258697,"price":1062.4,"qty":14702.0,"timestamp":1618678111518}
1618678111.542659: {"feed":"book","product_id":"PI_BCHUSD","side":"sell","seq":16258698,"price":1062.5,"qty":10284.0,"timestamp":1618678111518}
1618678111.5509279: {"feed":"book","product_id":"FI_XBTUSD_210924","side":"sell","seq":13850862,"price":68291.0,"qty":50.0,"timestamp":1618678111528}
1618678111.555488: {"feed":"book","product_id":"FI_XBTUSD_210924","side":"sell","seq":13850863,"price":68290.5,"qty":0.0,"timestamp":1618678111532}
1618678111.555546: {"feed":"book","product_id":"FI_XBTUSD_210924","side":"sell","seq":13850864,"price":68291.5,"qty":10000.0,"timestamp":1618678111532}
1618678111.565263: {"feed":"book","product_id":"FI_XBTUSD_210924","side":"sell","seq":13850865,"price":68292.0,"qty":0.0,"timestamp":1618678111539}
1618678111.565396: {"feed":"book","product_id":"FI_XBTUSD_210924","side":"sell","seq":13850866,"price":68291.0,"qty":1730.0,"timestamp":1618678111539}
1618678111.568934: {"feed":"book","product_id":"FI_XBTUSD_210924","side":"sell","seq":13850867,"price":68291.5,"qty":0.0,"timestamp":1618678111543}
1618678111.569026: {"feed":"book","product_id":"FI_XBTUSD_210924","side":"sell","seq":13850868,"price":68290.5,"qty":10000.0,"timestamp":1618678111543}
1618678111.592757: {"feed":"book","product_id":"FI_ETHUSD_210625","side":"buy","seq":12455527,"price":2488.25,"qty":0.0,"timestamp":1618678111569}
1618678111.60791: {"feed":"book","product_id":"FI_BCHUSD_210625","side":"buy","seq":2240221,"price":1120.8,"qty":4513.0,"timestamp":1618678111583}
1618678111.608022: {"feed":"book","product_id":"FI_BCHUSD_210625","side":"buy","seq":2240222,"price":1108.5,"qty":15022.0,"timestamp":1618678111583}
1618678111.6338649: {"feed":"book","product_id":"FI_XBTUSD_210625","side":"sell","seq":21455034,"price":64046.5,"qty":3000.0,"timestamp":1618678111605}
1618678111.6364229: {"feed":"book","product_id":"PI_BCHUSD","side":"buy","seq":16258699,"price":1058.6,"qty":1281.0,"timestamp":1618678111611}
1618678111.6365309: {"feed":"book","product_id":"PI_BCHUSD","side":"buy","seq":16258700,"price":1058.1,"qty":27065.0,"timestamp":1618678111611}
1618678111.647653: {"feed":"book","product_id":"FI_XBTUSD_210625","side":"sell","seq":21455035,"price":64053.0,"qty":0.0,"timestamp":1618678111621}
1618678111.6477802: {"feed":"book","product_id":"FI_XBTUSD_210625","side":"sell","seq":21455036,"price":64053.0,"qty":13737.0,"timestamp":1618678111621}
1618678111.65184: {"feed":"book","product_id":"PI_BCHUSD","side":"sell","seq":16258701,"price":1061.9,"qty":136.0,"timestamp":1618678111628}
1618678111.654188: {"feed":"book","product_id":"FI_XBTUSD_210430","side":"buy","seq":12237563,"price":59445.5,"qty":48172.0,"timestamp":1618678111629}
1618678111.7001112: {"feed":"book","product_id":"PI_BCHUSD","side":"sell","seq":16258702,"price":1061.5,"qty":2789.0,"timestamp":1618678111674}
1618678111.700199: {"feed":"book","product_id":"FI_XBTUSD_210430","side":"buy","seq":12237564,"price":59445.5,"qty":52610.0,"timestamp":1618678111676}
1618678111.7054741: {"feed":"book","product_id":"PI_BCHUSD","side":"buy","seq":16258703,"price":1058.6,"qty":0.0,"timestamp":1618678111678}
1618678111.705599: {"feed":"book","product_id":"FI_ETHUSD_210625","side":"buy","seq":12455528,"price":2493.4,"qty":0.0,"timestamp":1618678111679}
1618678111.7056582: {"feed":"book","product_id":"FI_ETHUSD_210625","side":"buy","seq":12455529,"price":2492.15,"qty":624.0,"timestamp":1618678111679}
1618678111.705715: {"feed":"book","product_id":"PI_BCHUSD","side":"buy","seq":16258704,"price":1059.5,"qty":29690.0,"timestamp":1618678111678}
1618678111.705751: {"feed":"book","product_id":"PI_BCHUSD","side":"sell","seq":16258705,"price":1061.5,"qty":3972.0,"timestamp":1618678111679}
1618678111.705785: {"feed":"book","product_id":"PI_BCHUSD","side":"buy","seq":16258706,"price":1057.5,"qty":0.0,"timestamp":1618678111679}
1618678111.705825: {"feed":"book","product_id":"FI_ETHUSD_210430","side":"buy","seq":4780852,"price":2350.7,"qty":0.0,"timestamp":1618678111681}
1618678111.7926059: {"feed":"book","product_id":"PI_BCHUSD","side":"buy","seq":16258707,"price":1057.1,"qty":6032.0,"timestamp":1618678111765}
1618678111.792734: {"feed":"book","product_id":"PI_BCHUSD","side":"buy","seq":16258708,"price":1058.7,"qty":3454.0,"timestamp":1618678111765}
1618678111.794711: {"feed":"book","product_id":"PI_BCHUSD","side":"sell","seq":16258709,"price":1062.6,"qty":4990.0,"timestamp":1618678111765}
1618678111.7947898: {"feed":"book","product_id":"PI_BCHUSD","side":"sell","seq":16258710,"price":1062.3,"qty":4853.0,"timestamp":1618678111765}
1618678111.794821: {"feed":"book","product_id":"PI_BCHUSD","side":"buy","seq":16258711,"price":1058.1,"qty":30825.0,"timestamp":1618678111765}
1618678111.794849: {"feed":"book","product_id":"PI_BCHUSD","side":"sell","seq":16258712,"price":1068.9,"qty":0.0,"timestamp":1618678111770}
1618678111.7948868: {"feed":"book","product_id":"PI_BCHUSD","side":"sell","seq":16258713,"price":1080.3,"qty":97867.0,"timestamp":1618678111770}
1618678111.794909: {"feed":"book","product_id":"PI_BCHUSD","side":"sell","seq":16258714,"price":1083.6,"qty":75347.0,"timestamp":1618678111770}
1618678111.7949288: {"feed":"book","product_id":"PI_BCHUSD","side":"sell","seq":16258715,"price":1098.7,"qty":0.0,"timestamp":1618678111770}
1618678111.794954: {"feed":"book","product_id":"PI_BCHUSD","side":"buy","seq":16258716,"price":1055.1,"qty":0.0,"timestamp":1618678111770}
1618678111.794979: {"feed":"book","product_id":"PI_BCHUSD","side":"buy","seq":16258717,"price":1048.1,"qty":253242.0,"timestamp":1618678111770}
1618678111.795: {"feed":"book","product_id":"PI_BCHUSD","side":"buy","seq":16258718,"price":1034.0,"qty":100.0,"timestamp":1618678111770}
1618678111.795018: {"feed":"book","product_id":"PI_BCHUSD","side":"buy","seq":16258719,"price":1021.1,"qty":25415.0,"timestamp":1618678111770}
1618678111.8030772: {"feed":"book","product_id":"PI_BCHUSD","side":"buy","seq":16258720,"price":1058.1,"qty":45155.0,"timestamp":1618678111770}
1618678111.851808: {"feed":"book","product_id":"FI_BCHUSD_210625","side":"buy","seq":2240223,"price":1128.5,"qty":14449.0,"timestamp":1618678111824}
1618678111.85192: {"feed":"book","product_id":"FI_ETHUSD_210625","side":"buy","seq":12455530,"price":2494.6,"qty":3000.0,"timestamp":1618678111824}
1618678111.851987: {"feed":"book","product_id":"FI_ETHUSD_210625","side":"buy","seq":12455531,"price":2490.95,"qty":8853.0,"timestamp":1618678111824}
1618678111.852032: {"feed":"book","product_id":"FI_ETHUSD_210625","side":"buy","seq":12455532,"price":2487.3,"qty":8853.0,"timestamp":1618678111824}
1618678111.868577: {"feed":"book","product_id":"FI_ETHUSD_210625","side":"sell","seq":12455533,"price":2508.7,"qty":4550.0,"timestamp":1618678111844}
1618678111.905955: {"feed":"book","product_id":"PI_BCHUSD","side":"sell","seq":16258721,"price":1062.7,"qty":3368.0,"timestamp":1618678111882}
1618678111.9060638: {"feed":"book","product_id":"PI_BCHUSD","side":"sell","seq":16258722,"price":1062.6,"qty":15622.0,"timestamp":1618678111882}
1618678111.909039: {"feed":"book","product_id":"FI_XRPUSD_210625","side":"buy","seq":3631563,"price":1.693,"qty":0.0,"timestamp":1618678111884}
1618678111.909128: {"feed":"book","product_id":"FI_XRPUSD_210625","side":"buy","seq":3631564,"price":1.6932,"qty":50.0,"timestamp":1618678111884}
1618678111.9091861: {"feed":"book","product_id":"FI_XBTUSD_210430","side":"buy","seq":12237565,"price":61102.0,"qty":23999.0,"timestamp":1618678111885}
1618678111.9192371: {"feed":"book","product_id":"PI_BCHUSD","side":"buy","seq":16258723,"price":1059.1,"qty":0.0,"timestamp":1618678111895}
1618678111.9193642: {"feed":"book","product_id":"PI_BCHUSD","side":"sell","seq":16258724,"price":1062.3,"qty":8508.0,"timestamp":1618678111895}
1618678111.9194171: {"feed":"book","product_id":"PI_BCHUSD","side":"buy","seq":16258725,"price":1058.7,"qty":6947.0,"timestamp":1618678111895}
1618678111.919455: {"feed":"book","product_id":"PI_BCHUSD","side":"sell","seq":16258726,"price":1062.7,"qty":0.0,"timestamp":1618678111896}
1618678111.931316: {"feed":"book","product_id":"PI_BCHUSD","side":"buy","seq":16258727,"price":1058.6,"qty":3470.0,"timestamp":1618678111908}
1618678111.9389682: {"feed":"book","product_id":"PI_BCHUSD","side":"sell","seq":16258728,"price":1061.5,"qty":1183.0,"timestamp":1618678111912}
1618678111.9443278: {"feed":"book","product_id":"FI_XBTUSD_210430","side":"buy","seq":12237566,"price":59445.5,"qty":48172.0,"timestamp":1618678111916}
1618678111.983868: {"feed":"book","product_id":"FI_XBTUSD_210430","side":"buy","seq":12237567,"price":59445.5,"qty":48491.0,"timestamp":1618678111959}
1618678112.0028548: {"feed":"book","product_id":"FI_XBTUSD_210625","side":"sell","seq":21455037,"price":64053.0,"qty":0.0,"timestamp":1618678111976}
1618678112.002987: {"feed":"book","product_id":"FI_XBTUSD_210625","side":"sell","seq":21455038,"price":64053.0,"qty":13498.0,"timestamp":1618678111976}
1618678112.00305: {"feed":"book","product_id":"FI_XBTUSD_210625","side":"sell","seq":21455039,"price":64093.5,"qty":0.0,"timestamp":1618678111976}
1618678112.003098: {"feed":"book","product_id":"FI_XBTUSD_210625","side":"sell","seq":21455040,"price":64093.5,"qty":21995.0,"timestamp":1618678111976}
1618678112.0031402: {"feed":"book","product_id":"FI_XBTUSD_210625","side":"sell","seq":21455041,"price":64118.5,"qty":0.0,"timestamp":1618678111976}
1618678112.00318: {"feed":"book","product_id":"FI_XBTUSD_210625","side":"sell","seq":21455042,"price":64118.5,"qty":28130.0,"timestamp":1618678111976}
1618678112.0036721: {"feed":"book","product_id":"FI_XBTUSD_210625","side":"buy","seq":21455043,"price":63896.0,"qty":1290.0,"timestamp":1618678111976}
1618678112.003714: {"feed":"book","product_id":"FI_XBTUSD_210625","side":"buy","seq":21455044,"price":63896.0,"qty":2593.0,"timestamp":1618678111976}
1618678112.0037389: {"feed":"book","product_id":"FI_XBTUSD_210625","side":"buy","seq":21455045,"price":63896.0,"qty":1303.0,"timestamp":1618678111976}
1618678112.00376: {"feed":"book","product_id":"FI_XBTUSD_210625","side":"buy","seq":21455046,"price":63896.0,"qty":2606.0,"timestamp":1618678111976}
1618678112.0037801: {"feed":"book","product_id":"FI_XBTUSD_210625","side":"buy","seq":21455047,"price":63879.0,"qty":0.0,"timestamp":1618678111976}
1618678112.0038111: {"feed":"book","product_id":"FI_XBTUSD_210625","side":"buy","seq":21455048,"price":63879.0,"qty":1540.0,"timestamp":1618678111976}
1618678112.0038369: {"feed":"book","product_id":"FI_XBTUSD_210625","side":"buy","seq":21455049,"price":63489.0,"qty":0.0,"timestamp":1618678111976}
1618678112.003862: {"feed":"book","product_id":"FI_XBTUSD_210625","side":"buy","seq":21455050,"price":63489.0,"qty":4292.0,"timestamp":1618678111976}
1618678112.003886: {"feed":"book","product_id":"FI_XBTUSD_210625","side":"buy","seq":21455051,"price":63728.0,"qty":0.0,"timestamp":1618678111976}
1618678112.003911: {"feed":"book","product_id":"FI_XBTUSD_210625","side":"buy","seq":21455052,"price":63728.0,"qty":3281.0,"timestamp":1618678111976}
1618678112.003933: {"feed":"book","product_id":"FI_XBTUSD_210625","side":"sell","seq":21455053,"price":64251.0,"qty":0.0,"timestamp":1618678111976}
1618678112.003958: {"feed":"book","product_id":"FI_XBTUSD_210625","side":"sell","seq":21455054,"price":64251.0,"qty":56795.0,"timestamp":1618678111976}
1618678112.00595: {"feed":"book","product_id":"FI_XBTUSD_210625","side":"sell","seq":21455055,"price":64516.5,"qty":0.0,"timestamp":1618678111976}
1618678112.006038: {"feed":"book","product_id":"FI_XBTUSD_210625","side":"sell","seq":21455056,"price":64516.5,"qty":76456.0,"timestamp":1618678111976}
1618678112.0320692: {"feed":"book","product_id":"FI_ETHUSD_210625","side":"sell","seq":12455534,"price":2506.45,"qty":3000.0,"timestamp":1618678112002}
1618678112.032253: {"feed":"book","product_id":"PI_BCHUSD","side":"sell","seq":16258729,"price":1061.4,"qty":2542.0,"timestamp":1618678112005}
1618678112.0371242: {"feed":"book","product_id":"PI_BCHUSD","side":"sell","seq":16258730,"price":1061.4,"qty":0.0,"timestamp":1618678112011}
1618678112.042065: {"feed":"book","product_id":"FI_XBTUSD_210924","side":"buy","seq":13850869,"price":52552.5,"qty":58880.0,"timestamp":1618678112014}
1618678112.055278: {"feed":"book","product_id":"FI_ETHUSD_210625","side":"sell","seq":12455535,"price":2504.05,"qty":0.0,"timestamp":1618678112030}
1618678112.0554051: {"feed":"book","product_id":"FI_ETHUSD_210625","side":"sell","seq":12455536,"price":2503.9,"qty":9916.0,"timestamp":1618678112030}
1618678112.05708: {"feed":"book","product_id":"PI_BCHUSD","side":"sell","seq":16258731,"price":1062.6,"qty":4990.0,"timestamp":1618678112033}
1618678112.061513: {"feed":"book","product_id":"PI_BCHUSD","side":"sell","seq":16258732,"price":1061.9,"qty":50.0,"timestamp":1618678112035}
1618678112.0663722: {"feed":"book","product_id":"FI_XBTUSD_210924","side":"sell","seq":13850870,"price":68291.0,"qty":1680.0,"timestamp":1618678112037}
1618678112.066444: {"feed":"book","product_id":"FI_XBTUSD_210924","side":"sell","seq":13850871,"price":68289.5,"qty":50.0,"timestamp":1618678112037}
1618678112.069769: {"feed":"book","product_id":"PI_BCHUSD","side":"sell","seq":16258733,"price":1063.2,"qty":18471.0,"timestamp":1618678112045}
1618678112.0698822: {"feed":"book","product_id":"PI_BCHUSD","side":"buy","seq":16258734,"price":1058.1,"qty":30825.0,"timestamp":1618678112045}
1618678112.070282: {"feed":"book","product_id":"PI_BCHUSD","side":"sell","seq":16258735,"price":1062.3,"qty":4863.0,"timestamp":1618678112047}
1618678112.070328: {"feed":"book","product_id":"PI_BCHUSD","side":"buy","seq":16258736,"price":1058.6,"qty":0.0,"timestamp":1618678112048}
1618678112.1388228: {"feed":"book","product_id":"PI_BCHUSD","side":"sell","seq":16258737,"price":1063.2,"qty":7839.0,"timestamp":1618678112112}
1618678112.138934: {"feed":"book","product_id":"PI_BCHUSD","side":"sell","seq":16258738,"price":1063.1,"qty":37834.0,"timestamp":1618678112112}
1618678112.144303: {"feed":"book","product_id":"FI_ETHUSD_210924","side":"sell","seq":3859159,"price":2670.55,"qty":0.0,"timestamp":1618678112118}
1618678112.144431: {"feed":"book","product_id":"FI_ETHUSD_210924","side":"sell","seq":3859160,"price":2670.25,"qty":219.0,"timestamp":1618678112118}
1618678112.144494: {"feed":"book","product_id":"FI_ETHUSD_210430","side":"sell","seq":4780853,"price":2394.6,"qty":0.0,"timestamp":1618678112119}
1618678112.144545: {"feed":"book","product_id":"FI_ETHUSD_210625","side":"sell","seq":12455537,"price":2507.0,"qty":0.0,"timestamp":1618678112118}
1618678112.1445901: {"feed":"book","product_id":"FI_ETHUSD_210430","side":"sell","seq":4780854,"price":2394.3,"qty":578.0,"timestamp":1618678112119}
1618678112.144632: {"feed":"book","product_id":"FI_ETHUSD_210625","side":"sell","seq":12455538,"price":2506.75,"qty":441.0,"timestamp":1618678112118}
1618678112.189981: {"feed":"book","product_id":"FI_BCHUSD_210625","side":"buy","seq":2240224,"price":1108.5,"qty":0.0,"timestamp":1618678112165}
1618678112.1901069: {"feed":"book","product_id":"FI_BCHUSD_210625","side":"buy","seq":2240225,"price":1120.8,"qty":19535.0,"timestamp":1618678112165}
1618678112.194292: {"feed":"book","product_id":"PI_BCHUSD","side":"sell","seq":16258739,"price":1061.9,"qty":0.0,"timestamp":1618678112169}
1618678112.19438: {"feed":"book","product_id":"PI_BCHUSD","side":"sell","seq":16258740,"price":1061.4,"qty":50.0,"timestamp":1618678112169}
1618678112.2136068: {"feed":"book","product_id":"FI_ETHUSD_210924","side":"sell","seq":3859161,"price":2659.3,"qty":20039.0,"timestamp":1618678112190}
1618678112.2306519: {"feed":"book","product_id":"FI_XRPUSD_210625","side":"buy","seq":3631565,"price":1.6825,"qty":0.0,"timestamp":1618678112203}
1618678112.23078: {"feed":"book","product_id":"FI_XRPUSD_210625","side":"buy","seq":3631566,"price":1.6866,"qty":2955.0,"timestamp":1618678112203}
1618678112.259729: {"feed":"book","product_id":"FI_XRPUSD_210625","side":"buy","seq":3631567,"price":1.6866,"qty":36554.0,"timestamp":1618678112234}
1618678112.259841: {"feed":"book","product_id":"FI_ETHUSD_210625","side":"sell","seq":12455539,"price":2503.9,"qty":2420.0,"timestamp":1618678112234}
1618678112.2598898: {"feed":"book","product_id":"FI_ETHUSD_210625","side":"sell","seq":12455540,"price":2504.05,"qty":7262.0,"timestamp":1618678112234}
1618678112.259947: {"feed":"book","product_id":"FI_ETHUSD_210625","side":"buy","seq":12455541,"price":2492.15,"qty":0.0,"timestamp":1618678112234}
1618678112.260001: {"feed":"book","product_id":"FI_ETHUSD_210625","side":"buy","seq":12455542,"price":2493.4,"qty":590.0,"timestamp":1618678112234}
1618678112.2777889: {"feed":"book","product_id":"FI_XRPUSD_210625","side":"buy","seq":3631568,"price":1.6931,"qty":0.0,"timestamp":1618678112254}
1618678112.2778811: {"feed":"book","product_id":"FI_XRPUSD_210625","side":"buy","seq":3631569,"price":1.6933,"qty":68.0,"timestamp":1618678112254}
1618678112.280982: {"feed":"book","product_id":"FI_XRPUSD_210625","side":"sell","seq":3631570,"price":1.6983,"qty":0.0,"timestamp":1618678112256}
1618678112.294127: {"feed":"book","product_id":"FI_ETHUSD_210625","side":"sell","seq":12455543,"price":2506.45,"qty":0.0,"timestamp":1618678112268}
1618678112.294687: {"feed":"book","product_id":"FI_XRPUSD_210625","side":"buy","seq":3631571,"price":1.6932,"qty":0.0,"timestamp":1618678112271}
1618678112.2947352: {"feed":"book","product_id":"FI_XRPUSD_210625","side":"buy","seq":3631572,"price":1.6934,"qty":50.0,"timestamp":1618678112271}
1618678112.2985659: {"feed":"book","product_id":"FI_XBTUSD_210430","side":"buy","seq":12237568,"price":59445.5,"qty":48172.0,"timestamp":1618678112274}
1618678112.305022: {"feed":"book","product_id":"FI_XRPUSD_210625","side":"buy","seq":3631573,"price":1.6933,"qty":0.0,"timestamp":1618678112280}
1618678112.3051488: {"feed":"book","product_id":"FI_XRPUSD_210625","side":"buy","seq":3631574,"price":1.6934,"qty":118.0,"timestamp":1618678112280}
1618678112.307522: {"feed":"book","product_id":"FI_XRPUSD_210625","side":"sell","seq":3631575,"price":1.6987,"qty":0.0,"timestamp":1618678112283}
1618678112.343029: {"feed":"book","product_id":"FI_XBTUSD_210430","side":"buy","seq":12237569,"price":59445.5,"qty":52610.0,"timestamp":1618678112319}
1618678112.3824499: {"feed":"book","product_id":"PI_BCHUSD","side":"sell","seq":16258741,"price":1063.1,"qty":27202.0,"timestamp":1618678112357}
1618678112.382563: {"feed":"book","product_id":"PI_BCHUSD","side":"sell","seq":16258742,"price":1063.0,"qty":15620.0,"timestamp":1618678112357}
1618678112.4095821: {"feed":"book","product_id":"FI_XBTUSD_210924","side":"buy","seq":13850872,"price":52552.5,"qty":58638.0,"timestamp":1618678112384}
1618678112.451148: {"feed":"book","product_id":"FI_XBTUSD_210924","side":"buy","seq":13850873,"price":52552.5,"qty":58799.0,"timestamp":1618678112427}
1618678112.539915: {"feed":"book","product_id":"PI_BCHUSD","side":"sell","seq":16258743,"price":1063.0,"qty":4988.0,"timestamp":1618678112514}
1618678112.540024: {"feed":"book","product_id":"PI_BCHUSD","side":"sell","seq":16258744,"price":1062.8,"qty":38603.0,"timestamp":1618678112514}
1618678112.554251: {"feed":"book","product_id":"FI_ETHUSD_210625","side":"sell","seq":12455544,"price":2514.7,"qty":38399.0,"timestamp":1618678112529}
1618678112.5543811: {"feed":"book","product_id":"FI_XBTUSD_210924","side":"sell","seq":13850874,"price":68292.5,"qty":23999.0,"timestamp":1618678112531}
1618678112.566078: {"feed":"book","product_id":"FI_ETHUSD_210625","side":"sell","seq":12455545,"price":2506.15,"qty":5000.0,"timestamp":1618678112541}
1618678112.5895839: {"feed":"book","product_id":"FI_XBTUSD_210625","side":"sell","seq":21455057,"price":64053.0,"qty":0.0,"timestamp":1618678112563}
1618678112.589718: {"feed":"book","product_id":"FI_XBTUSD_210625","side":"sell","seq":21455058,"price":64053.0,"qty":12736.0,"timestamp":1618678112563}
1618678112.5897799: {"feed":"book","product_id":"FI_XBTUSD_210625","side":"sell","seq":21455059,"price":64093.5,"qty":0.0,"timestamp":1618678112563}
1618678112.58983: {"feed":"book","product_id":"FI_XBTUSD_210625","side":"sell","seq":21455060,"price":64093.5,"qty":20905.0,"timestamp":1618678112563}
1618678112.5898712: {"feed":"book","product_id":"FI_XBTUSD_210625","side":"sell","seq":21455061,"price":64118.5,"qty":0.0,"timestamp":1618678112563}
1618678112.589935: {"feed":"book","product_id":"FI_XBTUSD_210625","side":"sell","seq":21455062,"price":64118.5,"qty":27194.0,"timestamp":1618678112563}
1618678112.591529: {"feed":"book","product_id":"FI_XBTUSD_210625","side":"buy","seq":21455063,"price":63896.0,"qty":1303.0,"timestamp":1618678112563}
1618678112.591608: {"feed":"book","product_id":"FI_XBTUSD_210625","side":"buy","seq":21455064,"price":63896.0,"qty":2645.0,"timestamp":1618678112563}
1618678112.591638: {"feed":"book","product_id":"FI_XBTUSD_210625","side":"buy","seq":21455065,"price":63896.0,"qty":1342.0,"timestamp":1618678112563}
1618678112.5916631: {"feed":"book","product_id":"FI_XBTUSD_210625","side":"buy","seq":21455066,"price":63896.0,"qty":2684.0,"timestamp":1618678112563}
1618678112.591684: {"feed":"book","product_id":"FI_XBTUSD_210625","side":"buy","seq":21455067,"price":63489.0,"qty":0.0,"timestamp":1618678112563}
1618678112.591722: {"feed":"book","product_id":"FI_XBTUSD_210625","side":"buy","seq":21455068,"price":63489.0,"qty":4221.0,"timestamp":1618678112563}
1618678112.5917509: {"feed":"book","product_id":"FI_XBTUSD_210625","side":"buy","seq":21455069,"price":63879.0,"qty":0.0,"timestamp":1618678112563}
1618678112.591778: {"feed":"book","product_id":"FI_XBTUSD_210625","side":"buy","seq":21455070,"price":63879.0,"qty":1566.0,"timestamp":1618678112563}
1618678112.5924969: {"feed":"book","product_id":"FI_XBTUSD_210625","side":"buy","seq":21455071,"price":63728.0,"qty":0.0,"timestamp":1618678112563}
1618678112.592559: {"feed":"book","product_id":"FI_XBTUSD_210625","side":"buy","seq":21455072,"price":63728.0,"qty":3247.0,"timestamp":1618678112563}
1618678112.592597: {"feed":"book","product_id":"FI_XBTUSD_210625","side":"sell","seq":21455073,"price":64251.0,"qty":0.0,"timestamp":1618678112563}
1618678112.592631: {"feed":"book","product_id":"FI_XBTUSD_210625","side":"sell","seq":21455074,"price":64251.0,"qty":56418.0,"timestamp":1618678112563}
1618678112.5945542: {"feed":"book","product_id":"FI_XBTUSD_210625","side":"sell","seq":21455075,"price":64516.5,"qty":0.0,"timestamp":1618678112563}
1618678112.594645: {"feed":"book","product_id":"FI_XBTUSD_210625","side":"sell","seq":21455076,"price":64516.5,"qty":76461.0,"timestamp":1618678112563}
1618678112.6076028: {"feed":"book","product_id":"FI_XBTUSD_210430","side":"buy","seq":12237570,"price":59445.5,"qty":48172.0,"timestamp":1618678112584}
1618678112.652097: {"feed":"book","product_id":"FI_XBTUSD_210430","side":"buy","seq":12237571,"price":59445.5,"qty":48491.0,"timestamp":1618678112627}
1618678112.6977978: {"feed":"book","product_id":"PI_BCHUSD","side":"sell","seq":16258745,"price":1061.5,"qty":4000.0,"timestamp":1618678112674}
1618678112.709606: {"feed":"book","product_id":"FI_XBTUSD_210924","side":"buy","seq":13850875,"price":52552.5,"qty":58638.0,"timestamp":1618678112686}
1618678112.732063: {"feed":"book","product_id":"FI_ETHUSD_210924","side":"buy","seq":3859162,"price":2655.45,"qty":0.0,"timestamp":1618678112706}
1618678112.732151: {"feed":"book","product_id":"FI_ETHUSD_210924","side":"buy","seq":3859163,"price":2654.95,"qty":840.0,"timestamp":1618678112706}
1618678112.741222: {"feed":"book","product_id":"FI_XBTUSD_210625","side":"sell","seq":21455077,"price":64094.0,"qty":0.0,"timestamp":1618678112709}
1618678112.7412832: {"feed":"book","product_id":"FI_XBTUSD_210625","side":"sell","seq":21455078,"price":64093.0,"qty":250001.0,"timestamp":1618678112709}
1618678112.7413208: {"feed":"book","product_id":"FI_ETHUSD_210924","side":"sell","seq":3859164,"price":2659.35,"qty":0.0,"timestamp":1618678112709}
1618678112.741353: {"feed":"book","product_id":"FI_ETHUSD_210924","side":"sell","seq":3859165,"price":2659.25,"qty":21000.0,"timestamp":1618678112709}
1618678112.7413802: {"feed":"book","product_id":"FI_ETHUSD_210430","side":"sell","seq":4780855,"price":2395.05,"qty":0.0,"timestamp":1618678112709}
1618678112.741409: {"feed":"book","product_id":"FI_ETHUSD_210430","side":"sell","seq":4780856,"price":2396.4,"qty":225001.0,"timestamp":1618678112709}
1618678112.7414331: {"feed":"book","product_id":"FI_ETHUSD_210625","side":"sell","seq":12455546,"price":2514.65,"qty":0.0,"timestamp":1618678112709}
1618678112.74146: {"feed":"book","product_id":"FI_ETHUSD_210625","side":"sell","seq":12455547,"price":2513.25,"qty":96000.0,"timestamp":1618678112709}
1618678112.741484: {"feed":"book","product_id":"FI_XBTUSD_210625","side":"sell","seq":21455079,"price":64251.5,"qty":0.0,"timestamp":1618678112709}
1618678112.741508: {"feed":"book","product_id":"FI_XBTUSD_210625","side":"sell","seq":21455080,"price":64250.5,"qty":125003.0,"timestamp":1618678112709}
1618678112.741531: {"feed":"book","product_id":"FI_ETHUSD_210625","side":"sell","seq":12455548,"price":2508.0,"qty":0.0,"timestamp":1618678112709}
1618678112.741555: {"feed":"book","product_id":"FI_ETHUSD_210625","side":"sell","seq":12455549,"price":2508.5,"qty":225001.0,"timestamp":1618678112709}
1618678112.741578: {"feed":"book","product_id":"FI_ETHUSD_210625","side":"sell","seq":12455550,"price":2512.15,"qty":0.0,"timestamp":1618678112709}
1618678112.741602: {"feed":"book","product_id":"FI_ETHUSD_210625","side":"sell","seq":12455551,"price":2512.05,"qty":303574.0,"timestamp":1618678112709}
1618678112.741625: {"feed":"book","product_id":"PI_BCHUSD","side":"sell","seq":16258746,"price":1062.4,"qty":18152.0,"timestamp":1618678112714}
1618678112.741647: {"feed":"book","product_id":"FI_ETHUSD_210430","side":"sell","seq":4780857,"price":2399.6,"qty":0.0,"timestamp":1618678112709}
1618678112.741672: {"feed":"book","product_id":"FI_ETHUSD_210430","side":"sell","seq":4780858,"price":2402.2,"qty":584747.0,"timestamp":1618678112709}
1618678112.749595: {"feed":"book","product_id":"FI_ETHUSD_210924","side":"sell","seq":3859166,"price":2659.3,"qty":19199.0,"timestamp":1618678112717}
1618678112.749665: {"feed":"book","product_id":"FI_ETHUSD_210924","side":"sell","seq":3859167,"price":2659.2,"qty":840.0,"timestamp":1618678112717}
1618678112.749726: {"feed":"book","product_id":"FI_ETHUSD_210924","side":"sell","seq":3859168,"price":2659.95,"qty":0.0,"timestamp":1618678112724}
1618678112.749778: {"feed":"book","product_id":"FI_ETHUSD_210924","side":"sell","seq":3859169,"price":2659.2,"qty":890.0,"timestamp":1618678112724}
1618678112.7573602: {"feed":"book","product_id":"FI_XBTUSD_210924","side":"buy","seq":13850876,"price":52552.5,"qty":58880.0,"timestamp":1618678112732}
1618678112.764967: {"feed":"book","product_id":"FI_ETHUSD_210430","side":"sell","seq":4780859,"price":2400.85,"qty":38399.0,"timestamp":1618678112741}
1618678112.769242: {"feed":"book","product_id":"PI_BCHUSD","side":"buy","seq":16258747,"price":1058.2,"qty":21801.0,"timestamp":1618678112743}
1618678112.808442: {"feed":"book","product_id":"FI_ETHUSD_210625","side":"sell","seq":12455552,"price":2506.15,"qty":2000.0,"timestamp":1618678112781}
1618678112.876158: {"feed":"book","product_id":"FI_XRPUSD_210625","side":"sell","seq":3631576,"price":1.6981,"qty":0.0,"timestamp":1618678112847}
1618678112.876247: {"feed":"book","product_id":"FI_XRPUSD_210625","side":"sell","seq":3631577,"price":1.6991,"qty":18968.0,"timestamp":1618678112847}
1618678112.876729: {"feed":"book","product_id":"PI_BCHUSD","side":"buy","seq":16258748,"price":1058.1,"qty":45224.0,"timestamp":1618678112847}
1618678112.883479: {"feed":"book","product_id":"PI_BCHUSD","side":"sell","seq":16258749,"price":1061.5,"qty":1183.0,"timestamp":1618678112855}
1618678112.883589: {"feed":"book","product_id":"FI_ETHUSD_210625","side":"buy","seq":12455553,"price":2477.25,"qty":0.0,"timestamp":1618678112855}
1618678112.883662: {"feed":"book","product_id":"FI_ETHUSD_210625","side":"buy","seq":12455554,"price":2477.25,"qty":878.0,"timestamp":1618678112855}
1618678112.886922: {"feed":"book","product_id":"FI_ETHUSD_210625","side":"buy","seq":12455555,"price":2496.2,"qty":0.0,"timestamp":1618678112855}
1618678112.887069: {"feed":"book","product_id":"FI_ETHUSD_210625","side":"buy","seq":12455556,"price":2496.2,"qty":428.0,"timestamp":1618678112855}
1618678112.88713: {"feed":"book","product_id":"FI_BCHUSD_210430","side":"buy","seq":1411877,"price":1073.2,"qty":0.0,"timestamp":1618678112855}
1618678112.8871639: {"feed":"book","product_id":"FI_BCHUSD_210430","side":"sell","seq":1411878,"price":1079.9,"qty":0.0,"timestamp":1618678112857}
1618678112.8871932: {"feed":"book","product_id":"FI_ETHUSD_210625","side":"buy","seq":12455557,"price":2499.35,"qty":250.0,"timestamp":1618678112855}
1618678112.8872168: {"feed":"book","product_id":"FI_ETHUSD_210625","side":"buy","seq":12455558,"price":2499.35,"qty":501.0,"timestamp":1618678112855}
1618678112.887239: {"feed":"book","product_id":"FI_ETHUSD_210625","side":"buy","seq":12455559,"price":2499.35,"qty":251.0,"timestamp":1618678112855}
1618678112.8872588: {"feed":"book","product_id":"FI_ETHUSD_210625","side":"buy","seq":12455560,"price":2499.35,"qty":502.0,"timestamp":1618678112855}
1618678112.887278: {"feed":"book","product_id":"FI_ETHUSD_210625","side":"sell","seq":12455561,"price":2504.05,"qty":0.0,"timestamp":1618678112855}
1618678112.8873038: {"feed":"book","product_id":"FI_ETHUSD_210625","side":"sell","seq":12455562,"price":2504.05,"qty":7267.0,"timestamp":1618678112855}
1618678112.887328: {"feed":"book","product_id":"FI_ETHUSD_210625","side":"sell","seq":12455563,"price":2528.95,"qty":0.0,"timestamp":1618678112855}
1618678112.8873532: {"feed":"book","product_id":"FI_ETHUSD_210625","side":"sell","seq":12455564,"price":2528.95,"qty":47829.0,"timestamp":1618678112855}
1618678112.8873758: {"feed":"book","product_id":"FI_ETHUSD_210625","side":"sell","seq":12455565,"price":2512.1,"qty":0.0,"timestamp":1618678112855}
1618678112.8874: {"feed":"book","product_id":"FI_ETHUSD_210625","side":"sell","seq":12455566,"price":2512.1,"qty":31888.0,"timestamp":1618678112855}
1618678112.887423: {"feed":"book","product_id":"FI_ETHUSD_210625","side":"sell","seq":12455567,"price":2506.35,"qty":0.0,"timestamp":1618678112855}
1618678112.887446: {"feed":"book","product_id":"FI_ETHUSD_210625","side":"sell","seq":12455568,"price":2506.35,"qty":14045.0,"timestamp":1618678112855}
1618678112.8880289: {"feed":"book","product_id":"FI_ETHUSD_210625","side":"sell","seq":12455569,"price":2507.95,"qty":0.0,"timestamp":1618678112855}
1618678112.888096: {"feed":"book","product_id":"FI_ETHUSD_210625","side":"sell","seq":12455570,"price":2507.95,"qty":18812.0,"timestamp":1618678112855}
1618678112.888135: {"feed":"book","product_id":"FI_ETHUSD_210625","side":"buy","seq":12455571,"price":2494.6,"qty":0.0,"timestamp":1618678112855}
1618678112.947288: {"feed":"book","product_id":"FI_XBTUSD_210430","side":"buy","seq":12237572,"price":59445.5,"qty":52929.0,"timestamp":1618678112919}
1618678112.947395: {"feed":"book","product_id":"PI_BCHUSD","side":"buy","seq":16258750,"price":1058.7,"qty":10537.0,"timestamp":1618678112919}
1618678112.9625978: {"feed":"book","product_id":"PI_BCHUSD","side":"buy","seq":16258751,"price":1058.2,"qty":7549.0,"timestamp":1618678112939}
1618678112.9646568: {"feed":"book","product_id":"PI_BCHUSD","side":"buy","seq":16258752,"price":1058.1,"qty":25710.0,"timestamp":1618678112941}
1618678112.964705: {"feed":"book","product_id":"PI_BCHUSD","side":"buy","seq":16258753,"price":1058.6,"qty":20113.0,"timestamp":1618678112941}
1618678112.964742: {"feed":"book","product_id":"PI_BCHUSD","side":"sell","seq":16258754,"price":1062.4,"qty":14702.0,"timestamp":1618678112941}
1618678112.979706: {"feed":"book","product_id":"PI_BCHUSD","side":"sell","seq":16258755,"price":1062.8,"qty":27971.0,"timestamp":1618678112953}
1618678113.0014248: {"feed":"book","product_id":"PI_BCHUSD","side":"buy","seq":16258756,"price":1058.7,"qty":6947.0,"timestamp":1618678112975}
1618678113.001547: {"feed":"book","product_id":"PI_BCHUSD","side":"sell","seq":16258757,"price":1062.2,"qty":4992.0,"timestamp":1618678112975}
1618678113.001597: {"feed":"book","product_id":"PI_BCHUSD","side":"sell","seq":16258758,"price":1062.7,"qty":19871.0,"timestamp":1618678112975}
1618678113.001972: {"feed":"book","product_id":"FI_XRPUSD_210625","side":"sell","seq":3631578,"price":1.719,"qty":33599.0,"timestamp":1618678112975}
1618678113.011766: {"feed":"book","product_id":"FI_XBTUSD_210924","side":"buy","seq":13850877,"price":52552.5,"qty":58638.0,"timestamp":1618678112988}
1618678113.0173628: {"feed":"book","product_id":"FI_XRPUSD_210625","side":"sell","seq":3631579,"price":1.697,"qty":0.0,"timestamp":1618678112989}
1618678113.017455: {"feed":"book","product_id":"FI_XRPUSD_210625","side":"sell","seq":3631580,"price":1.6979,"qty":768.0,"timestamp":1618678112989}
1618678113.042582: {"feed":"book","product_id":"FI_XRPUSD_210625","side":"buy","seq":3631581,"price":1.6917,"qty":0.0,"timestamp":1618678112995}
1618678113.042712: {"feed":"book","product_id":"FI_XRPUSD_210625","side":"buy","seq":3631582,"price":1.6926,"qty":19200.0,"timestamp":1618678112995}
1618678113.042774: {"feed":"book","product_id":"FI_XRPUSD_210625","side":"buy","seq":3631583,"price":1.68,"qty":0.0,"timestamp":1618678112995}
1618678113.0428228: {"feed":"book","product_id":"FI_XRPUSD_210625","side":"buy","seq":3631584,"price":1.6822,"qty":172800.0,"timestamp":1618678112995}
1618678113.0428748: {"feed":"book","product_id":"PI_BCHUSD","side":"sell","seq":16258759,"price":1061.6,"qty":2636.0,"timestamp":1618678113005}
1618678113.057154: {"feed":"book","product_id":"FI_XBTUSD_210924","side":"buy","seq":13850878,"price":52552.5,"qty":58823.0,"timestamp":1618678113031}
1618678113.071854: {"feed":"book","product_id":"FI_BCHUSD_210625","side":"buy","seq":2240226,"price":1121.7,"qty":44999.0,"timestamp":1618678113047}
1618678113.0832698: {"feed":"book","product_id":"FI_ETHUSD_210625","side":"buy","seq":12455572,"price":2493.4,"qty":0.0,"timestamp":1618678113058}
1618678113.0834: {"feed":"book","product_id":"FI_ETHUSD_210625","side":"buy","seq":12455573,"price":2492.15,"qty":624.0,"timestamp":1618678113058}
1618678113.083462: {"feed":"book","product_id":"FI_ETHUSD_210625","side":"sell","seq":12455574,"price":2504.05,"qty":0.0,"timestamp":1618678113058}
1618678113.083509: {"feed":"book","product_id":"FI_ETHUSD_210625","side":"sell","seq":12455575,"price":2503.9,"qty":9936.0,"timestamp":1618678113058}
1618678113.083827: {"feed":"book","product_id":"PI_BCHUSD","side":"sell","seq":16258760,"price":1068.9,"qty":14641.0,"timestamp":1618678113060}
1618678113.083903: {"feed":"book","product_id":"PI_BCHUSD","side":"sell","seq":16258761,"price":1076.0,"qty":14641.0,"timestamp":1618678113060}
1618678113.083947: {"feed":"book","product_id":"PI_BCHUSD","side":"sell","seq":16258762,"price":1083.8,"qty":14641.0,"timestamp":1618678113060}
1618678113.0874062: {"feed":"book","product_id":"PI_BCHUSD","side":"sell","seq":16258763,"price":1099.5,"qty":14641.0,"timestamp":1618678113060}
1618678113.087529: {"feed":"book","product_id":"PI_BCHUSD","side":"buy","seq":16258764,"price":1055.8,"qty":14641.0,"timestamp":1618678113060}
1618678113.087587: {"feed":"book","product_id":"PI_BCHUSD","side":"buy","seq":16258765,"price":1048.1,"qty":267883.0,"timestamp":1618678113060}
1618678113.087629: {"feed":"book","product_id":"PI_BCHUSD","side":"buy","seq":16258766,"price":1034.0,"qty":14741.0,"timestamp":1618678113060}
1618678113.0876632: {"feed":"book","product_id":"PI_BCHUSD","side":"buy","seq":16258767,"price":1021.1,"qty":40056.0,"timestamp":1618678113060}
1618678113.0876951: {"feed":"book","product_id":"PI_BCHUSD","side":"sell","seq":16258768,"price":1063.2,"qty":18471.0,"timestamp":1618678113064}
1618678113.105349: {"feed":"book","product_id":"FI_BCHUSD_210430","side":"sell","seq":1411879,"price":1078.6,"qty":7470.0,"timestamp":1618678113075}
1618678113.11639: {"feed":"book","product_id":"FI_ETHUSD_210430","side":"buy","seq":4780860,"price":2350.4,"qty":99600.0,"timestamp":1618678113091}
1618678113.131504: {"feed":"book","product_id":"PI_BCHUSD","side":"sell","seq":16258769,"price":1063.2,"qty":7839.0,"timestamp":1618678113104}
1618678113.131614: {"feed":"book","product_id":"PI_BCHUSD","side":"sell","seq":16258770,"price":1063.1,"qty":37834.0,"timestamp":1618678113104}
1618678113.1316621: {"feed":"book","product_id":"PI_BCHUSD","side":"sell","seq":16258771,"price":1061.6,"qty":0.0,"timestamp":1618678113106}
1618678113.157383: {"feed":"book","product_id":"FI_XBTUSD_210625","side":"sell","seq":21455081,"price":64093.5,"qty":0.0,"timestamp":1618678113131}
1618678113.157511: {"feed":"book","product_id":"FI_XBTUSD_210625","side":"sell","seq":21455082,"price":64092.5,"qty":20982.0,"timestamp":1618678113131}
1618678113.160376: {"feed":"book","product_id":"FI_BCHUSD_210430","side":"buy","seq":1411880,"price":1072.9,"qty":6670.0,"timestamp":1618678113135}
1618678113.163597: {"feed":"book","product_id":"PI_BCHUSD","side":"buy","seq":16258772,"price":1058.6,"qty":25259.0,"timestamp":1618678113139}
1618678113.1840608: {"feed":"book","product_id":"FI_XBTUSD_210430","side":"sell","seq":12237573,"price":61235.5,"qty":1904.0,"timestamp":1618678113160}
1618678113.196963: {"feed":"book","product_id":"FI_ETHUSD_210625","side":"sell","seq":12455576,"price":2503.85,"qty":19199.0,"timestamp":1618678113172}
1618678113.2044642: {"feed":"book","product_id":"FI_ETHUSD_210625","side":"sell","seq":12455577,"price":2503.9,"qty":9101.0,"timestamp":1618678113179}
1618678113.204534: {"feed":"book","product_id":"FI_ETHUSD_210625","side":"sell","seq":12455578,"price":2503.8,"qty":835.0,"timestamp":1618678113179}
1618678113.2157462: {"feed":"book","product_id":"FI_ETHUSD_210924","side":"sell","seq":3859170,"price":2659.3,"qty":0.0,"timestamp":1618678113190}
1618678113.230262: {"feed":"book","product_id":"PI_BCHUSD","side":"sell","seq":16258773,"price":1062.4,"qty":0.0,"timestamp":1618678113203}
1618678113.230387: {"feed":"book","product_id":"PI_BCHUSD","side":"buy","seq":16258774,"price":1058.1,"qty":21950.0,"timestamp":1618678113203}
1618678113.2304409: {"feed":"book","product_id":"PI_BCHUSD","side":"sell","seq":16258775,"price":1062.8,"qty":42027.0,"timestamp":1618678113203}
1618678113.230481: {"feed":"book","product_id":"PI_BCHUSD","side":"buy","seq":16258776,"price":1058.8,"qty":3790.0,"timestamp":1618678113204}
1618678113.230526: {"feed":"book","product_id":"PI_BCHUSD","side":"sell","seq":16258777,"price":1062.1,"qty":5218.0,"timestamp":1618678113204}
1618678113.2305589: {"feed":"book","product_id":"PI_BCHUSD","side":"sell","seq":16258778,"price":1062.0,"qty":0.0,"timestamp":1618678113205}
1618678113.235683: {"feed":"book","product_id":"PI_BCHUSD","side":"sell","seq":16258779,"price":1062.5,"qty":6616.0,"timestamp":1618678113206}
1618678113.235792: {"feed":"book","product_id":"PI_BCHUSD","side":"sell","seq":16258780,"price":1063.0,"qty":8637.0,"timestamp":1618678113209}
1618678113.235839: {"feed":"book","product_id":"PI_BCHUSD","side":"buy","seq":16258781,"price":1058.7,"qty":3493.0,"timestamp":1618678113209}
1618678113.235877: {"feed":"book","product_id":"PI_BCHUSD","side":"buy","seq":16258782,"price":1059.2,"qty":3518.0,"timestamp":1618678113210}
1618678113.239984: {"feed":"book","product_id":"PI_BCHUSD","side":"sell","seq":16258783,"price":1068.9,"qty":0.0,"timestamp":1618678113214}
1618678113.240109: {"feed":"book","product_id":"PI_BCHUSD","side":"sell","seq":16258784,"price":1076.0,"qty":0.0,"timestamp":1618678113214}
1618678113.240166: {"feed":"book","product_id":"PI_BCHUSD","side":"sell","seq":16258785,"price":1083.8,"qty":0.0,"timestamp":1618678113214}
1618678113.2402089: {"feed":"book","product_id":"PI_BCHUSD","side":"sell","seq":16258786,"price":1099.5,"qty":0.0,"timestamp":1618678113214}
1618678113.243047: {"feed":"book","product_id":"FI_BCHUSD_210625","side":"sell","seq":2240227,"price":1143.4,"qty":0.0,"timestamp":1618678113215}
1618678113.243171: {"feed":"book","product_id":"FI_BCHUSD_210625","side":"sell","seq":2240228,"price":1157.7,"qty":73158.0,"timestamp":1618678113215}
1618678113.2432241: {"feed":"book","product_id":"PI_BCHUSD","side":"buy","seq":16258787,"price":1055.8,"qty":0.0,"timestamp":1618678113214}
1618678113.2432761: {"feed":"book","product_id":"FI_BCHUSD_210625","side":"sell","seq":2240229,"price":1189.5,"qty":44836.0,"timestamp":1618678113215}
1618678113.2433128: {"feed":"book","product_id":"PI_BCHUSD","side":"buy","seq":16258788,"price":1048.1,"qty":253242.0,"timestamp":1618678113214}
1618678113.2433448: {"feed":"book","product_id":"PI_BCHUSD","side":"buy","seq":16258789,"price":1034.0,"qty":100.0,"timestamp":1618678113214}
1618678113.243377: {"feed":"book","product_id":"PI_BCHUSD","side":"buy","seq":16258790,"price":1021.1,"qty":25415.0,"timestamp":1618678113214}
1618678113.243407: {"feed":"book","product_id":"FI_BCHUSD_210625","side":"sell","seq":2240230,"price":1204.8,"qty":44211.0,"timestamp":1618678113215}
1618678113.243438: {"feed":"book","product_id":"FI_BCHUSD_210625","side":"buy","seq":2240231,"price":1108.4,"qty":0.0,"timestamp":1618678113215}
1618678113.24542: {"feed":"book","product_id":"FI_BCHUSD_210625","side":"buy","seq":2240232,"price":1108.1,"qty":0.0,"timestamp":1618678113215}
1618678113.245545: {"feed":"book","product_id":"FI_BCHUSD_210625","side":"buy","seq":2240233,"price":1085.9,"qty":44910.0,"timestamp":1618678113215}
1618678113.245599: {"feed":"book","product_id":"FI_BCHUSD_210625","side":"buy","seq":2240234,"price":1059.6,"qty":46182.0,"timestamp":1618678113215}
1618678113.249748: {"feed":"book","product_id":"FI_XRPUSD_210625","side":"sell","seq":3631585,"price":1.6979,"qty":0.0,"timestamp":1618678113225}
1618678113.249876: {"feed":"book","product_id":"FI_XRPUSD_210625","side":"sell","seq":3631586,"price":1.6983,"qty":768.0,"timestamp":1618678113225}
1618678113.260426: {"feed":"book","product_id":"FI_BCHUSD_210625","side":"sell","seq":2240235,"price":1138.8,"qty":14399.0,"timestamp":1618678113226}
1618678113.260549: {"feed":"book","product_id":"FI_BCHUSD_210430","side":"buy","seq":1411881,"price":1072.1,"qty":14399.0,"timestamp":1618678113226}
1618678113.260606: {"feed":"book","product_id":"FI_BCHUSD_210430","side":"sell","seq":1411882,"price":1084.7,"qty":44999.0,"timestamp":1618678113227}
1618678113.260651: {"feed":"book","product_id":"FI_BCHUSD_210430","side":"buy","seq":1411883,"price":1065.6,"qty":44999.0,"timestamp":1618678113227}
1618678113.264676: {"feed":"book","product_id":"FI_BCHUSD_210625","side":"sell","seq":2240236,"price":1146.0,"qty":44999.0,"timestamp":1618678113229}
1618678113.2648: {"feed":"book","product_id":"FI_XRPUSD_210625","side":"sell","seq":3631587,"price":1.6991,"qty":0.0,"timestamp":1618678113228}
1618678113.264867: {"feed":"book","product_id":"FI_XRPUSD_210625","side":"sell","seq":3631588,"price":1.7,"qty":18968.0,"timestamp":1618678113228}
1618678113.264915: {"feed":"book","product_id":"FI_XRPUSD_210625","side":"sell","seq":3631589,"price":1.7038,"qty":0.0,"timestamp":1618678113228}
1618678113.264958: {"feed":"book","product_id":"FI_XRPUSD_210625","side":"sell","seq":3631590,"price":1.7052,"qty":57600.0,"timestamp":1618678113228}
1618678113.2650099: {"feed":"book","product_id":"PI_BCHUSD","side":"sell","seq":16258791,"price":1061.7,"qty":5726.0,"timestamp":1618678113234}
1618678113.283543: {"feed":"book","product_id":"PI_BCHUSD","side":"sell","seq":16258792,"price":1069.3,"qty":44999.0,"timestamp":1618678113257}
1618678113.283638: {"feed":"book","product_id":"PI_BCHUSD","side":"sell","seq":16258793,"price":1068.9,"qty":14641.0,"timestamp":1618678113258}
1618678113.283674: {"feed":"book","product_id":"PI_BCHUSD","side":"sell","seq":16258794,"price":1080.3,"qty":112508.0,"timestamp":1618678113258}
1618678113.283699: {"feed":"book","product_id":"PI_BCHUSD","side":"sell","seq":16258795,"price":1083.8,"qty":14641.0,"timestamp":1618678113258}
1618678113.283725: {"feed":"book","product_id":"FI_BCHUSD_210625","side":"sell","seq":2240237,"price":1143.5,"qty":22606.0,"timestamp":1618678113259}
1618678113.283747: {"feed":"book","product_id":"PI_BCHUSD","side":"sell","seq":16258796,"price":1099.3,"qty":14641.0,"timestamp":1618678113259}
1618678113.28377: {"feed":"book","product_id":"PI_BCHUSD","side":"buy","seq":16258797,"price":1055.8,"qty":14641.0,"timestamp":1618678113259}
1618678113.2837949: {"feed":"book","product_id":"FI_BCHUSD_210625","side":"sell","seq":2240238,"price":1162.1,"qty":90045.0,"timestamp":1618678113259}
1618678113.2838159: {"feed":"book","product_id":"FI_BCHUSD_210625","side":"sell","seq":2240239,"price":1189.5,"qty":58146.0,"timestamp":1618678113259}
1618678113.283836: {"feed":"book","product_id":"PI_BCHUSD","side":"buy","seq":16258798,"price":1048.1,"qty":267883.0,"timestamp":1618678113259}
1618678113.2841191: {"feed":"book","product_id":"PI_BCHUSD","side":"buy","seq":16258799,"price":1034.0,"qty":14741.0,"timestamp":1618678113259}
1618678113.284172: {"feed":"book","product_id":"FI_BCHUSD_210625","side":"sell","seq":2240240,"price":1204.8,"qty":57521.0,"timestamp":1618678113259}
1618678113.284833: {"feed":"book","product_id":"PI_BCHUSD","side":"buy","seq":16258800,"price":1021.1,"qty":40056.0,"timestamp":1618678113259}
1618678113.2848861: {"feed":"book","product_id":"FI_BCHUSD_210625","side":"buy","seq":2240241,"price":1107.9,"qty":13310.0,"timestamp":1618678113259}
1618678113.287717: {"feed":"book","product_id":"FI_BCHUSD_210625","side":"buy","seq":2240242,"price":1107.8,"qty":87105.0,"timestamp":1618678113259}
1618678113.2877738: {"feed":"book","product_id":"FI_BCHUSD_210625","side":"buy","seq":2240243,"price":1085.9,"qty":58220.0,"timestamp":1618678113259}
1618678113.2878048: {"feed":"book","product_id":"FI_BCHUSD_210625","side":"buy","seq":2240244,"price":1059.6,"qty":59492.0,"timestamp":1618678113259}
1618678113.287829: {"feed":"book","product_id":"PI_BCHUSD","side":"sell","seq":16258801,"price":1068.9,"qty":0.0,"timestamp":1618678113266}
1618678113.2887611: {"feed":"book","product_id":"PI_BCHUSD","side":"sell","seq":16258802,"price":1080.3,"qty":97867.0,"timestamp":1618678113266}
1618678113.288813: {"feed":"book","product_id":"PI_BCHUSD","side":"sell","seq":16258803,"price":1083.8,"qty":0.0,"timestamp":1618678113266}
1618678113.289054: {"feed":"book","product_id":"PI_BCHUSD","side":"sell","seq":16258804,"price":1099.3,"qty":0.0,"timestamp":1618678113267}
1618678113.29132: {"feed":"book","product_id":"PI_BCHUSD","side":"buy","seq":16258805,"price":1055.8,"qty":0.0,"timestamp":1618678113267}
1618678113.291368: {"feed":"book","product_id":"PI_BCHUSD","side":"buy","seq":16258806,"price":1048.1,"qty":253242.0,"timestamp":1618678113267}
1618678113.291394: {"feed":"book","product_id":"PI_BCHUSD","side":"buy","seq":16258807,"price":1034.0,"qty":100.0,"timestamp":1618678113267}
1618678113.291413: {"feed":"book","product_id":"PI_BCHUSD","side":"buy","seq":16258808,"price":1021.1,"qty":25415.0,"timestamp":1618678113267}
1618678113.310056: {"feed":"book","product_id":"FI_XBTUSD_210924","side":"buy","seq":13850879,"price":52552.5,"qty":58638.0,"timestamp":1618678113284}
1618678113.3229299: {"feed":"book","product_id":"PI_BCHUSD","side":"sell","seq":16258809,"price":1063.1,"qty":27202.0,"timestamp":1618678113298}
1618678113.323043: {"feed":"book","product_id":"PI_BCHUSD","side":"buy","seq":16258810,"price":1058.7,"qty":0.0,"timestamp":1618678113298}
1618678113.323114: {"feed":"book","product_id":"PI_BCHUSD","side":"sell","seq":16258811,"price":1062.5,"qty":3007.0,"timestamp":1618678113298}
1618678113.340498: {"feed":"book","product_id":"FI_ETHUSD_210625","side":"sell","seq":12455579,"price":2506.1,"qty":3000.0,"timestamp":1618678113307}
1618678113.340631: {"feed":"book","product_id":"PI_BCHUSD","side":"sell","seq":16258812,"price":1062.1,"qty":2698.0,"timestamp":1618678113307}
1618678113.340683: {"feed":"book","product_id":"PI_BCHUSD","side":"sell","seq":16258813,"price":1062.3,"qty":7438.0,"timestamp":1618678113307}
1618678113.3407192: {"feed":"book","product_id":"PI_BCHUSD","side":"sell","seq":16258814,"price":1062.1,"qty":0.0,"timestamp":1618678113307}
1618678113.340769: {"feed":"book","product_id":"PI_BCHUSD","side":"sell","seq":16258815,"price":1063.0,"qty":12075.0,"timestamp":1618678113307}
1618678113.340802: {"feed":"book","product_id":"PI_BCHUSD","side":"buy","seq":16258816,"price":1059.3,"qty":8520.0,"timestamp":1618678113307}
1618678113.3408341: {"feed":"book","product_id":"PI_BCHUSD","side":"buy","seq":16258817,"price":1058.9,"qty":5013.0,"timestamp":1618678113307}
1618678113.3408651: {"feed":"book","product_id":"PI_BCHUSD","side":"buy","seq":16258818,"price":1059.3,"qty":12030.0,"timestamp":1618678113307}
1618678113.340894: {"feed":"book","product_id":"PI_BCHUSD","side":"sell","seq":16258819,"price":1063.0,"qty":15535.0,"timestamp":1618678113307}
1618678113.3409228: {"feed":"book","product_id":"PI_BCHUSD","side":"sell","seq":16258820,"price":1062.3,"qty":3783.0,"timestamp":1618678113307}
1618678113.349921: {"feed":"book","product_id":"FI_XBTUSD_210924","side":"buy","seq":13850880,"price":52552.5,"qty":58880.0,"timestamp":1618678113327}
1618678113.357267: {"feed":"book","product_id":"PI_BCHUSD","side":"sell","seq":16258821,"price":1062.2,"qty":0.0,"timestamp":1618678113331}
1618678113.357396: {"feed":"book","product_id":"PI_BCHUSD","side":"sell","seq":16258822,"price":1063.4,"qty":4986.0,"timestamp":1618678113331}
1618678113.368553: {"feed":"book","product_id":"PI_BCHUSD","side":"sell","seq":16258823,"price":1062.3,"qty":1208.0,"timestamp":1618678113339}
1618678113.368665: {"feed":"book","product_id":"PI_BCHUSD","side":"sell","seq":16258824,"price":1062.7,"qty":0.0,"timestamp":1618678113339}
1618678113.368737: {"feed":"book","product_id":"PI_BCHUSD","side":"sell","seq":16258825,"price":1064.9,"qty":28772.0,"timestamp":1618678113339}
1618678113.368788: {"feed":"book","product_id":"PI_BCHUSD","side":"sell","seq":16258826,"price":1062.8,"qty":27971.0,"timestamp":1618678113339}
1618678113.368823: {"feed":"book","product_id":"PI_BCHUSD","side":"sell","seq":16258827,"price":1063.3,"qty":3910.0,"timestamp":1618678113340}
1618678113.368856: {"feed":"book","product_id":"PI_BCHUSD","side":"buy","seq":16258828,"price":1058.6,"qty":5146.0,"timestamp":1618678113340}
1618678113.37419: {"feed":"book","product_id":"PI_BCHUSD","side":"sell","seq":16258829,"price":1063.8,"qty":0.0,"timestamp":1618678113345}
1618678113.374319: {"feed":"book","product_id":"PI_BCHUSD","side":"sell","seq":16258830,"price":1063.4,"qty":11056.0,"timestamp":1618678113345}
1618678113.3856661: {"feed":"book","product_id":"FI_XBTUSD_210625","side":"sell","seq":21455083,"price":64251.0,"qty":0.0,"timestamp":1618678113352}
1618678113.385792: {"feed":"book","product_id":"FI_XBTUSD_210625","side":"sell","seq":21455084,"price":64250.0,"qty":56350.0,"timestamp":1618678113352}
1618678113.385854: {"feed":"book","product_id":"FI_XBTUSD_210625","side":"sell","seq":21455085,"price":64092.5,"qty":0.0,"timestamp":1618678113352}
1618678113.3859122: {"feed":"book","product_id":"FI_XBTUSD_210625","side":"sell","seq":21455086,"price":64092.5,"qty":20710.0,"timestamp":1618678113352}
1618678113.385959: {"feed":"book","product_id":"FI_XBTUSD_210625","side":"sell","seq":21455087,"price":64053.0,"qty":0.0,"timestamp":1618678113352}
1618678113.385986: {"feed":"book","product_id":"FI_XBTUSD_210625","side":"sell","seq":21455088,"price":64053.0,"qty":12784.0,"timestamp":1618678113352}
1618678113.386011: {"feed":"book","product_id":"FI_XBTUSD_210625","side":"sell","seq":21455089,"price":64118.5,"qty":0.0,"timestamp":1618678113352}
1618678113.386034: {"feed":"book","product_id":"FI_XBTUSD_210625","side":"sell","seq":21455090,"price":64118.5,"qty":27252.0,"timestamp":1618678113352}
1618678113.386058: {"feed":"book","product_id":"FI_XBTUSD_210625","side":"buy","seq":21455091,"price":63896.0,"qty":1342.0,"timestamp":1618678113352}
1618678113.38608: {"feed":"book","product_id":"FI_XBTUSD_210625","side":"buy","seq":21455092,"price":63896.0,"qty":2682.0,"timestamp":1618678113352}
1618678113.3861: {"feed":"book","product_id":"FI_XBTUSD_210625","side":"buy","seq":21455093,"price":63896.0,"qty":1340.0,"timestamp":1618678113352}
1618678113.386118: {"feed":"book","product_id":"FI_XBTUSD_210625","side":"buy","seq":21455094,"price":63896.0,"qty":2680.0,"timestamp":1618678113352}
1618678113.386137: {"feed":"book","product_id":"FI_XBTUSD_210625","side":"buy","seq":21455095,"price":63489.0,"qty":0.0,"timestamp":1618678113352}
1618678113.386163: {"feed":"book","product_id":"FI_XBTUSD_210625","side":"buy","seq":21455096,"price":63489.0,"qty":4226.0,"timestamp":1618678113352}
1618678113.386186: {"feed":"book","product_id":"FI_XBTUSD_210625","side":"buy","seq":21455097,"price":63879.0,"qty":0.0,"timestamp":1618678113352}
1618678113.38621: {"feed":"book","product_id":"FI_XBTUSD_210625","side":"buy","seq":21455098,"price":63879.0,"qty":1565.0,"timestamp":1618678113352}
1618678113.3862321: {"feed":"book","product_id":"FI_XBTUSD_210625","side":"buy","seq":21455099,"price":63728.0,"qty":0.0,"timestamp":1618678113352}
1618678113.386256: {"feed":"book","product_id":"FI_XBTUSD_210625","side":"buy","seq":21455100,"price":63728.0,"qty":3249.0,"timestamp":1618678113352}
1618678113.401866: {"feed":"book","product_id":"FI_ETHUSD_210625","side":"buy","seq":12455580,"price":2494.85,"qty":3000.0,"timestamp":1618678113376}
1618678113.4116979: {"feed":"book","product_id":"PI_BCHUSD","side":"sell","seq":16258831,"price":1062.6,"qty":0.0,"timestamp":1618678113387}
1618678113.438397: {"feed":"book","product_id":"PI_BCHUSD","side":"buy","seq":16258832,"price":1051.2,"qty":44999.0,"timestamp":1618678113413}
1618678113.446997: {"feed":"book","product_id":"FI_BCHUSD_210625","side":"buy","seq":2240245,"price":1121.7,"qty":0.0,"timestamp":1618678113421}
1618678113.447123: {"feed":"book","product_id":"FI_BCHUSD_210625","side":"sell","seq":2240246,"price":1138.8,"qty":0.0,"timestamp":1618678113421}
1618678113.460125: {"feed":"book","product_id":"PI_BCHUSD","side":"buy","seq":16258833,"price":1059.4,"qty":86.0,"timestamp":1618678113436}
1618678113.472009: {"feed":"book","product_id":"FI_ETHUSD_210625","side":"sell","seq":12455581,"price":2503.9,"qty":1585.0,"timestamp":1618678113448}
1618678113.472119: {"feed":"book","product_id":"FI_ETHUSD_210625","side":"sell","seq":12455582,"price":2504.05,"qty":7280.0,"timestamp":1618678113448}
1618678113.472647: {"feed":"book","product_id":"FI_ETHUSD_210625","side":"sell","seq":12455583,"price":2512.1,"qty":0.0,"timestamp":1618678113448}
1618678113.472736: {"feed":"book","product_id":"FI_ETHUSD_210625","side":"sell","seq":12455584,"price":2513.2,"qty":33905.0,"timestamp":1618678113448}
1618678113.4727879: {"feed":"book","product_id":"FI_ETHUSD_210625","side":"buy","seq":12455585,"price":2492.15,"qty":0.0,"timestamp":1618678113448}
1618678113.472836: {"feed":"book","product_id":"FI_ETHUSD_210625","side":"buy","seq":12455586,"price":2493.4,"qty":590.0,"timestamp":1618678113448}
1618678113.479481: {"feed":"book","product_id":"PI_BCHUSD","side":"buy","seq":16258834,"price":1059.5,"qty":29776.0,"timestamp":1618678113455}
1618678113.4827: {"feed":"book","product_id":"PI_BCHUSD","side":"sell","seq":16258835,"price":1061.5,"qty":0.0,"timestamp":1618678113459}
1618678113.5075898: {"feed":"book","product_id":"PI_BCHUSD","side":"sell","seq":16258836,"price":1061.7,"qty":0.0,"timestamp":1618678113484}
1618678113.528776: {"feed":"book","product_id":"FI_XBTUSD_210924","side":"buy","seq":13850881,"price":52552.5,"qty":58638.0,"timestamp":1618678113503}
1618678113.536075: {"feed":"book","product_id":"FI_ETHUSD_210924","side":"sell","seq":3859171,"price":2659.7,"qty":2359.0,"timestamp":1618678113510}
1618678113.538573: {"feed":"book","product_id":"FI_ETHUSD_210924","side":"sell","seq":3859172,"price":2672.85,"qty":5000.0,"timestamp":1618678113510}
1618678113.57027: {"feed":"book","product_id":"FI_XBTUSD_210924","side":"buy","seq":13850882,"price":52552.5,"qty":58823.0,"timestamp":1618678113546}
1618678113.59295: {"feed":"book","product_id":"PI_BCHUSD","side":"sell","seq":16258837,"price":1063.3,"qty":0.0,"timestamp":1618678113569}
1618678113.59308: {"feed":"book","product_id":"PI_BCHUSD","side":"buy","seq":16258838,"price":1059.2,"qty":0.0,"timestamp":1618678113569}
1618678113.593139: {"feed":"book","product_id":"PI_BCHUSD","side":"sell","seq":16258839,"price":1063.8,"qty":27281.0,"timestamp":1618678113570}
1618678113.593214: {"feed":"book","product_id":"PI_BCHUSD","side":"sell","seq":16258840,"price":1063.1,"qty":0.0,"timestamp":1618678113571}
1618678113.596664: {"feed":"book","product_id":"PI_BCHUSD","side":"sell","seq":16258841,"price":1064.0,"qty":30573.0,"timestamp":1618678113571}
1618678113.596776: {"feed":"book","product_id":"PI_BCHUSD","side":"buy","seq":16258842,"price":1051.2,"qty":0.0,"timestamp":1618678113572}
1618678113.596847: {"feed":"book","product_id":"PI_BCHUSD","side":"sell","seq":16258843,"price":1068.9,"qty":14641.0,"timestamp":1618678113573}
1618678113.596898: {"feed":"book","product_id":"PI_BCHUSD","side":"sell","seq":16258844,"price":1080.3,"qty":112508.0,"timestamp":1618678113573}
1618678113.5969331: {"feed":"book","product_id":"PI_BCHUSD","side":"sell","seq":16258845,"price":1094.0,"qty":39081.0,"timestamp":1618678113573}
1618678113.596965: {"feed":"book","product_id":"PI_BCHUSD","side":"sell","seq":16258846,"price":1098.7,"qty":14641.0,"timestamp":1618678113573}
1618678113.597: {"feed":"book","product_id":"PI_BCHUSD","side":"buy","seq":16258847,"price":1056.3,"qty":18585.0,"timestamp":1618678113573}
1618678113.597323: {"feed":"book","product_id":"PI_BCHUSD","side":"buy","seq":16258848,"price":1048.1,"qty":267883.0,"timestamp":1618678113573}
1618678113.597387: {"feed":"book","product_id":"PI_BCHUSD","side":"buy","seq":16258849,"price":1034.0,"qty":14741.0,"timestamp":1618678113573}
1618678113.597433: {"feed":"book","product_id":"PI_BCHUSD","side":"buy","seq":16258850,"price":1030.8,"qty":88206.0,"timestamp":1618678113573}
1618678113.6133928: {"feed":"book","product_id":"PI_BCHUSD","side":"buy","seq":16258851,"price":1058.2,"qty":3675.0,"timestamp":1618678113590}
1618678113.630614: {"feed":"book","product_id":"PI_BCHUSD","side":"buy","seq":16258852,"price":1058.9,"qty":8774.0,"timestamp":1618678113605}
1618678113.6835232: {"feed":"book","product_id":"FI_BCHUSD_210430","side":"buy","seq":1411884,"price":1065.6,"qty":0.0,"timestamp":1618678113659}
1618678113.6990762: {"feed":"book","product_id":"PI_BCHUSD","side":"sell","seq":16258853,"price":1062.5,"qty":5867.0,"timestamp":1618678113674}
1618678113.704677: {"feed":"book","product_id":"FI_BCHUSD_210430","side":"sell","seq":1411885,"price":1080.8,"qty":14399.0,"timestamp":1618678113681}
1618678113.7101078: {"feed":"book","product_id":"FI_ETHUSD_210625","side":"sell","seq":12455587,"price":2506.1,"qty":0.0,"timestamp":1618678113687}
1618678113.7231019: {"feed":"book","product_id":"FI_XBTUSD_210924","side":"buy","seq":13850883,"price":52552.5,"qty":58638.0,"timestamp":1618678113697}
1618678113.740659: {"feed":"book","product_id":"PI_BCHUSD","side":"sell","seq":16258854,"price":1063.3,"qty":3566.0,"timestamp":1618678113713}
1618678113.762882: {"feed":"book","product_id":"PI_BCHUSD","side":"sell","seq":16258855,"price":1063.8,"qty":32265.0,"timestamp":1618678113739}
1618678113.7629912: {"feed":"book","product_id":"FI_XBTUSD_210924","side":"buy","seq":13850884,"price":52552.5,"qty":58880.0,"timestamp":1618678113739}
1618678113.7681699: {"feed":"book","product_id":"PI_BCHUSD","side":"buy","seq":16258856,"price":1059.1,"qty":14277.0,"timestamp":1618678113744}
1618678113.8083231: {"feed":"book","product_id":"FI_XRPUSD_210625","side":"sell","seq":3631591,"price":1.6971,"qty":0.0,"timestamp":1618678113784}
1618678113.9775941: {"feed":"book","product_id":"PI_BCHUSD","side":"buy","seq":16258857,"price":1059.6,"qty":3621.0,"timestamp":1618678113942}
1618678113.97768: {"feed":"book","product_id":"PI_BCHUSD","side":"buy","seq":16258858,"price":1059.1,"qty":34776.0,"timestamp":1618678113942}
1618678113.977723: {"feed":"book","product_id":"PI_BCHUSD","side":"buy","seq":16258859,"price":1059.5,"qty":29690.0,"timestamp":1618678113954}
1618678114.0117812: {"feed":"book","product_id":"FI_ETHUSD_210625","side":"sell","seq":12455588,"price":2507.95,"qty":0.0,"timestamp":1618678113985}
1618678114.0118568: {"feed":"book","product_id":"FI_ETHUSD_210625","side":"sell","seq":12455589,"price":2508.0,"qty":18969.0,"timestamp":1618678113985}
1618678114.015615: {"feed":"book","product_id":"FI_ETHUSD_210625","side":"sell","seq":12455590,"price":2528.95,"qty":0.0,"timestamp":1618678113985}
1618678114.015705: {"feed":"book","product_id":"FI_ETHUSD_210625","side":"sell","seq":12455591,"price":2528.85,"qty":47829.0,"timestamp":1618678113985}
1618678114.015747: {"feed":"book","product_id":"PI_BCHUSD","side":"sell","seq":16258860,"price":1063.1,"qty":20146.0,"timestamp":1618678113985}
1618678114.015779: {"feed":"book","product_id":"FI_ETHUSD_210625","side":"sell","seq":12455592,"price":2504.05,"qty":0.0,"timestamp":1618678113985}
1618678114.01581: {"feed":"book","product_id":"FI_ETHUSD_210625","side":"sell","seq":12455593,"price":2504.05,"qty":7265.0,"timestamp":1618678113985}
1618678114.015836: {"feed":"book","product_id":"FI_ETHUSD_210625","side":"sell","seq":12455594,"price":2513.2,"qty":0.0,"timestamp":1618678113985}
1618678114.015863: {"feed":"book","product_id":"FI_ETHUSD_210625","side":"sell","seq":12455595,"price":2513.2,"qty":33897.0,"timestamp":1618678113985}
1618678114.015887: {"feed":"book","product_id":"FI_ETHUSD_210625","side":"sell","seq":12455596,"price":2506.35,"qty":0.0,"timestamp":1618678113985}
1618678114.0159109: {"feed":"book","product_id":"FI_ETHUSD_210625","side":"sell","seq":12455597,"price":2506.35,"qty":14044.0,"timestamp":1618678113985}
1618678114.0306492: {"feed":"book","product_id":"PI_BCHUSD","side":"sell","seq":16258861,"price":1062.4,"qty":2675.0,"timestamp":1618678114007}
1618678114.04344: {"feed":"book","product_id":"FI_XBTUSD_210924","side":"buy","seq":13850885,"price":52552.5,"qty":58638.0,"timestamp":1618678114015}
1618678114.0954292: {"feed":"book","product_id":"FI_XBTUSD_210924","side":"buy","seq":13850886,"price":52552.5,"qty":58823.0,"timestamp":1618678114069}
1618678114.10931: {"feed":"book","product_id":"FI_XBTUSD_210625","side":"sell","seq":21455101,"price":64025.5,"qty":0.0,"timestamp":1618678114085}
1618678114.154502: {"feed":"book","product_id":"PI_BCHUSD","side":"sell","seq":16258862,"price":1068.9,"qty":0.0,"timestamp":1618678114122}
1618678114.1546292: {"feed":"book","product_id":"PI_BCHUSD","side":"sell","seq":16258863,"price":1080.3,"qty":97867.0,"timestamp":1618678114122}
1618678114.1546838: {"feed":"book","product_id":"PI_BCHUSD","side":"sell","seq":16258864,"price":1094.0,"qty":24440.0,"timestamp":1618678114122}
1618678114.154721: {"feed":"book","product_id":"PI_BCHUSD","side":"sell","seq":16258865,"price":1098.7,"qty":0.0,"timestamp":1618678114122}
1618678114.154773: {"feed":"book","product_id":"PI_BCHUSD","side":"buy","seq":16258866,"price":1056.3,"qty":3944.0,"timestamp":1618678114122}
1618678114.154818: {"feed":"book","product_id":"PI_BCHUSD","side":"buy","seq":16258867,"price":1048.1,"qty":253242.0,"timestamp":1618678114122}
1618678114.154839: {"feed":"book","product_id":"PI_BCHUSD","side":"buy","seq":16258868,"price":1034.0,"qty":100.0,"timestamp":1618678114122}
1618678114.1548579: {"feed":"book","product_id":"PI_BCHUSD","side":"buy","seq":16258869,"price":1030.8,"qty":73565.0,"timestamp":1618678114122}
1618678114.154878: {"feed":"book","product_id":"PI_BCHUSD","side":"sell","seq":16258870,"price":1063.5,"qty":10635.0,"timestamp":1618678114125}
1618678114.154905: {"feed":"book","product_id":"PI_BCHUSD","side":"buy","seq":16258871,"price":1059.4,"qty":0.0,"timestamp":1618678114127}
1618678114.155951: {"feed":"book","product_id":"PI_BCHUSD","side":"sell","seq":16258872,"price":1062.4,"qty":0.0,"timestamp":1618678114131}
1618678114.159561: {"feed":"book","product_id":"PI_BCHUSD","side":"sell","seq":16258873,"price":1062.5,"qty":3007.0,"timestamp":1618678114131}
1618678114.159636: {"feed":"book","product_id":"PI_BCHUSD","side":"buy","seq":16258874,"price":1059.1,"qty":20499.0,"timestamp":1618678114131}
1618678114.159668: {"feed":"book","product_id":"PI_BCHUSD","side":"sell","seq":16258875,"price":1063.3,"qty":0.0,"timestamp":1618678114131}
1618678114.1608078: {"feed":"book","product_id":"PI_BCHUSD","side":"buy","seq":16258876,"price":1059.6,"qty":0.0,"timestamp":1618678114133}
1618678114.160867: {"feed":"book","product_id":"PI_BCHUSD","side":"sell","seq":16258877,"price":1061.7,"qty":1151.0,"timestamp":1618678114136}
1618678114.167039: {"feed":"book","product_id":"FI_BCHUSD_210430","side":"buy","seq":1411886,"price":950.1,"qty":14770.0,"timestamp":1618678114141}
1618678114.167148: {"feed":"book","product_id":"FI_BCHUSD_210430","side":"buy","seq":1411887,"price":1069.4,"qty":4590.0,"timestamp":1618678114141}
1618678114.188489: {"feed":"book","product_id":"PI_BCHUSD","side":"sell","seq":16258878,"price":1064.0,"qty":26953.0,"timestamp":1618678114166}
1618678114.19573: {"feed":"book","product_id":"PI_BCHUSD","side":"sell","seq":16258879,"price":1063.1,"qty":0.0,"timestamp":1618678114167}
1618678114.19586: {"feed":"book","product_id":"PI_BCHUSD","side":"buy","seq":16258880,"price":1059.1,"qty":0.0,"timestamp":1618678114168}
1618678114.2148411: {"feed":"book","product_id":"FI_XBTUSD_210430","side":"sell","seq":12237574,"price":61235.5,"qty":5113.0,"timestamp":1618678114188}
1618678114.214962: {"feed":"book","product_id":"FI_XBTUSD_210430","side":"buy","seq":12237575,"price":61146.5,"qty":3209.0,"timestamp":1618678114188}
1618678114.215032: {"feed":"book","product_id":"FI_XBTUSD_210625","side":"buy","seq":21455102,"price":63863.5,"qty":4955.0,"timestamp":1618678114188}
1618678114.215426: {"feed":"book","product_id":"FI_ETHUSD_210924","side":"sell","seq":3859173,"price":2659.2,"qty":20089.0,"timestamp":1618678114192}
1618678114.220351: {"feed":"book","product_id":"FI_BCHUSD_210430","side":"buy","seq":1411888,"price":1069.4,"qty":0.0,"timestamp":1618678114196}
1618678114.220476: {"feed":"book","product_id":"FI_BCHUSD_210430","side":"buy","seq":1411889,"price":950.1,"qty":19360.0,"timestamp":1618678114196}
1618678114.225995: {"feed":"book","product_id":"PI_BCHUSD","side":"sell","seq":16258881,"price":1063.8,"qty":4984.0,"timestamp":1618678114200}
1618678114.231454: {"feed":"book","product_id":"PI_BCHUSD","side":"sell","seq":16258882,"price":1061.8,"qty":2785.0,"timestamp":1618678114202}
1618678114.231582: {"feed":"book","product_id":"PI_BCHUSD","side":"sell","seq":16258883,"price":1062.6,"qty":14675.0,"timestamp":1618678114204}
1618678114.231637: {"feed":"book","product_id":"PI_BCHUSD","side":"buy","seq":16258884,"price":1058.9,"qty":12409.0,"timestamp":1618678114205}
1618678114.2518709: {"feed":"book","product_id":"FI_XBTUSD_210430","side":"buy","seq":12237576,"price":59445.5,"qty":52610.0,"timestamp":1618678114227}
1618678114.261259: {"feed":"book","product_id":"FI_ETHUSD_210924","side":"buy","seq":3859174,"price":2636.65,"qty":0.0,"timestamp":1618678114234}
1618678114.2667031: {"feed":"book","product_id":"PI_BCHUSD","side":"sell","seq":16258885,"price":1063.5,"qty":0.0,"timestamp":1618678114243}
1618678114.266829: {"feed":"book","product_id":"PI_BCHUSD","side":"sell","seq":16258886,"price":1063.4,"qty":21691.0,"timestamp":1618678114243}
1618678114.266881: {"feed":"book","product_id":"PI_BCHUSD","side":"sell","seq":16258887,"price":1061.4,"qty":1391.0,"timestamp":1618678114244}
1618678114.289831: {"feed":"book","product_id":"PI_BCHUSD","side":"sell","seq":16258888,"price":1062.6,"qty":29074.0,"timestamp":1618678114259}
1618678114.289943: {"feed":"book","product_id":"FI_BCHUSD_210430","side":"buy","seq":1411890,"price":1069.4,"qty":28799.0,"timestamp":1618678114259}
1618678114.290009: {"feed":"book","product_id":"PI_BCHUSD","side":"sell","seq":16258889,"price":1061.8,"qty":0.0,"timestamp":1618678114263}
1618678114.3043141: {"feed":"book","product_id":"FI_XBTUSD_210924","side":"buy","seq":13850887,"price":52552.5,"qty":58638.0,"timestamp":1618678114281}
1618678114.31465: {"feed":"book","product_id":"FI_XBTUSD_210625","side":"sell","seq":21455103,"price":64053.0,"qty":0.0,"timestamp":1618678114284}
1618678114.314806: {"feed":"book","product_id":"FI_XBTUSD_210625","side":"sell","seq":21455104,"price":64053.0,"qty":12927.0,"timestamp":1618678114284}
1618678114.314848: {"feed":"book","product_id":"FI_XBTUSD_210625","side":"sell","seq":21455105,"price":64092.5,"qty":0.0,"timestamp":1618678114284}
1618678114.31488: {"feed":"book","product_id":"FI_XBTUSD_210625","side":"sell","seq":21455106,"price":64092.5,"qty":20915.0,"timestamp":1618678114284}
1618678114.3149078: {"feed":"book","product_id":"FI_XBTUSD_210625","side":"sell","seq":21455107,"price":64118.5,"qty":0.0,"timestamp":1618678114284}
1618678114.314934: {"feed":"book","product_id":"FI_XBTUSD_210625","side":"sell","seq":21455108,"price":64118.5,"qty":27428.0,"timestamp":1618678114284}
1618678114.314958: {"feed":"book","product_id":"FI_XBTUSD_210625","side":"buy","seq":21455109,"price":63896.0,"qty":1340.0,"timestamp":1618678114284}
1618678114.3149812: {"feed":"book","product_id":"FI_XBTUSD_210625","side":"buy","seq":21455110,"price":63896.0,"qty":2672.0,"timestamp":1618678114284}
1618678114.315001: {"feed":"book","product_id":"FI_XBTUSD_210625","side":"buy","seq":21455111,"price":63896.0,"qty":1332.0,"timestamp":1618678114284}
1618678114.315021: {"feed":"book","product_id":"FI_XBTUSD_210625","side":"buy","seq":21455112,"price":63896.0,"qty":2664.0,"timestamp":1618678114284}
1618678114.315039: {"feed":"book","product_id":"FI_XBTUSD_210625","side":"buy","seq":21455113,"price":63879.0,"qty":0.0,"timestamp":1618678114284}
1618678114.3150651: {"feed":"book","product_id":"FI_XBTUSD_210625","side":"buy","seq":21455114,"price":63879.0,"qty":1560.0,"timestamp":1618678114284}
1618678114.31509: {"feed":"book","product_id":"FI_XBTUSD_210625","side":"buy","seq":21455115,"price":63489.0,"qty":0.0,"timestamp":1618678114284}
1618678114.315114: {"feed":"book","product_id":"FI_XBTUSD_210625","side":"buy","seq":21455116,"price":63489.0,"qty":4239.0,"timestamp":1618678114284}
1618678114.315137: {"feed":"book","product_id":"FI_XBTUSD_210625","side":"buy","seq":21455117,"price":63728.0,"qty":0.0,"timestamp":1618678114284}
1618678114.315161: {"feed":"book","product_id":"FI_XBTUSD_210625","side":"buy","seq":21455118,"price":63728.0,"qty":3255.0,"timestamp":1618678114284}
1618678114.315184: {"feed":"book","product_id":"FI_XBTUSD_210625","side":"sell","seq":21455119,"price":64250.0,"qty":0.0,"timestamp":1618678114284}
1618678114.315208: {"feed":"book","product_id":"FI_XBTUSD_210625","side":"sell","seq":21455120,"price":64250.0,"qty":56421.0,"timestamp":1618678114284}
1618678114.316776: {"feed":"book","product_id":"FI_XBTUSD_210625","side":"sell","seq":21455121,"price":64516.5,"qty":0.0,"timestamp":1618678114284}
1618678114.3168662: {"feed":"book","product_id":"FI_XBTUSD_210625","side":"sell","seq":21455122,"price":64516.5,"qty":76460.0,"timestamp":1618678114284}
1618678114.32001: {"feed":"book","product_id":"PI_BCHUSD","side":"sell","seq":16258890,"price":1063.0,"qty":12097.0,"timestamp":1618678114292}
1618678114.320086: {"feed":"book","product_id":"PI_BCHUSD","side":"sell","seq":16258891,"price":1062.7,"qty":3523.0,"timestamp":1618678114292}
1618678114.3344152: {"feed":"book","product_id":"PI_BCHUSD","side":"sell","seq":16258892,"price":1061.7,"qty":3785.0,"timestamp":1618678114301}
1618678114.348713: {"feed":"book","product_id":"FI_XRPUSD_210625","side":"buy","seq":3631592,"price":1.6919,"qty":359.0,"timestamp":1618678114322}
1618678114.348802: {"feed":"book","product_id":"PI_BCHUSD","side":"buy","seq":16258893,"price":1059.6,"qty":50.0,"timestamp":1618678114320}
1618678114.348855: {"feed":"book","product_id":"PI_BCHUSD","side":"sell","seq":16258894,"price":1061.4,"qty":1341.0,"timestamp":1618678114320}
1618678114.348938: {"feed":"book","product_id":"FI_BCHUSD_210430","side":"sell","seq":1411891,"price":1078.9,"qty":0.0,"timestamp":1618678114320}
1618678114.348992: {"feed":"book","product_id":"FI_BCHUSD_210430","side":"sell","seq":1411892,"price":1078.5,"qty":50.0,"timestamp":1618678114320}
1618678114.349018: {"feed":"book","product_id":"FI_XBTUSD_210924","side":"buy","seq":13850888,"price":52552.5,"qty":58854.0,"timestamp":1618678114323}
1618678114.355138: {"feed":"book","product_id":"PI_BCHUSD","side":"buy","seq":16258895,"price":1058.2,"qty":4597.0,"timestamp":1618678114323}
1618678114.357294: {"feed":"book","product_id":"PI_BCHUSD","side":"sell","seq":16258896,"price":1063.4,"qty":11056.0,"timestamp":1618678114332}
1618678114.3573709: {"feed":"book","product_id":"PI_BCHUSD","side":"sell","seq":16258897,"price":1063.2,"qty":18474.0,"timestamp":1618678114332}
1618678114.366621: {"feed":"book","product_id":"PI_BCHUSD","side":"sell","seq":16258898,"price":1068.9,"qty":14641.0,"timestamp":1618678114337}
1618678114.366745: {"feed":"book","product_id":"PI_BCHUSD","side":"sell","seq":16258899,"price":1080.3,"qty":112508.0,"timestamp":1618678114337}
1618678114.3667939: {"feed":"book","product_id":"PI_BCHUSD","side":"sell","seq":16258900,"price":1094.0,"qty":39081.0,"timestamp":1618678114337}
1618678114.366833: {"feed":"book","product_id":"PI_BCHUSD","side":"sell","seq":16258901,"price":1099.3,"qty":14641.0,"timestamp":1618678114337}
1618678114.366873: {"feed":"book","product_id":"PI_BCHUSD","side":"buy","seq":16258902,"price":1055.8,"qty":14641.0,"timestamp":1618678114337}
1618678114.366922: {"feed":"book","product_id":"PI_BCHUSD","side":"buy","seq":16258903,"price":1048.1,"qty":267883.0,"timestamp":1618678114337}
1618678114.366976: {"feed":"book","product_id":"PI_BCHUSD","side":"buy","seq":16258904,"price":1034.0,"qty":14741.0,"timestamp":1618678114337}
1618678114.366997: {"feed":"book","product_id":"PI_BCHUSD","side":"buy","seq":16258905,"price":1021.1,"qty":40056.0,"timestamp":1618678114337}
1618678114.3670158: {"feed":"book","product_id":"PI_BCHUSD","side":"sell","seq":16258906,"price":1063.0,"qty":8448.0,"timestamp":1618678114338}
1618678114.370608: {"feed":"book","product_id":"PI_BCHUSD","side":"sell","seq":16258907,"price":1062.5,"qty":6712.0,"timestamp":1618678114344}
1618678114.414495: {"feed":"book","product_id":"PI_BCHUSD","side":"sell","seq":16258908,"price":1063.0,"qty":3460.0,"timestamp":1618678114383}
1618678114.414606: {"feed":"book","product_id":"PI_BCHUSD","side":"sell","seq":16258909,"price":1063.2,"qty":23461.0,"timestamp":1618678114383}
1618678114.414655: {"feed":"book","product_id":"PI_BCHUSD","side":"sell","seq":16258910,"price":1062.4,"qty":4991.0,"timestamp":1618678114383}
1618678114.414711: {"feed":"book","product_id":"PI_BCHUSD","side":"sell","seq":16258911,"price":1062.8,"qty":32960.0,"timestamp":1618678114383}
1618678114.414755: {"feed":"book","product_id":"PI_BCHUSD","side":"sell","seq":16258912,"price":1063.4,"qty":6070.0,"timestamp":1618678114383}
1618678114.414796: {"feed":"book","product_id":"PI_BCHUSD","side":"sell","seq":16258913,"price":1063.8,"qty":0.0,"timestamp":1618678114383}
1618678114.414827: {"feed":"book","product_id":"FI_ETHUSD_210625","side":"buy","seq":12455598,"price":2493.4,"qty":0.0,"timestamp":1618678114387}
1618678114.414857: {"feed":"book","product_id":"FI_ETHUSD_210625","side":"buy","seq":12455599,"price":2492.15,"qty":624.0,"timestamp":1618678114387}
1618678114.414884: {"feed":"book","product_id":"FI_ETHUSD_210625","side":"sell","seq":12455600,"price":2504.05,"qty":0.0,"timestamp":1618678114387}
1618678114.414911: {"feed":"book","product_id":"FI_ETHUSD_210625","side":"sell","seq":12455601,"price":2503.8,"qty":7979.0,"timestamp":1618678114387}
1618678114.414932: {"feed":"book","product_id":"FI_ETHUSD_210625","side":"sell","seq":12455602,"price":2513.2,"qty":0.0,"timestamp":1618678114387}
1618678114.414957: {"feed":"book","product_id":"FI_ETHUSD_210625","side":"sell","seq":12455603,"price":2512.0,"qty":32090.0,"timestamp":1618678114387}
1618678114.479279: {"feed":"book","product_id":"FI_XBTUSD_210430","side":"buy","seq":12237577,"price":61131.0,"qty":3358.0,"timestamp":1618678114455}
1618678114.479411: {"feed":"book","product_id":"FI_XBTUSD_210430","side":"buy","seq":12237578,"price":61146.5,"qty":0.0,"timestamp":1618678114456}
1618678114.479858: {"feed":"book","product_id":"FI_XBTUSD_210625","side":"buy","seq":21455123,"price":63863.5,"qty":0.0,"timestamp":1618678114456}
1618678114.482541: {"feed":"book","product_id":"FI_XBTUSD_210625","side":"buy","seq":21455124,"price":63849.5,"qty":6944.0,"timestamp":1618678114456}
1618678114.4977238: {"feed":"book","product_id":"FI_XBTUSD_210924","side":"buy","seq":13850889,"price":68172.5,"qty":0.0,"timestamp":1618678114465}
1618678114.497854: {"feed":"book","product_id":"FI_ETHUSD_210924","side":"buy","seq":3859175,"price":2653.75,"qty":0.0,"timestamp":1618678114468}
1618678114.497918: {"feed":"book","product_id":"FI_ETHUSD_210924","side":"sell","seq":3859176,"price":2660.45,"qty":0.0,"timestamp":1618678114468}
1618678114.497967: {"feed":"book","product_id":"FI_ETHUSD_210924","side":"buy","seq":3859177,"price":2650.4,"qty":0.0,"timestamp":1618678114468}
1618678114.498018: {"feed":"book","product_id":"FI_ETHUSD_210924","side":"sell","seq":3859178,"price":2664.05,"qty":0.0,"timestamp":1618678114468}
1618678114.498066: {"feed":"book","product_id":"FI_ETHUSD_210924","side":"buy","seq":3859179,"price":2647.05,"qty":0.0,"timestamp":1618678114468}
1618678114.498098: {"feed":"book","product_id":"FI_ETHUSD_210924","side":"sell","seq":3859180,"price":2667.65,"qty":0.0,"timestamp":1618678114468}
1618678114.498122: {"feed":"book","product_id":"FI_ETHUSD_210924","side":"buy","seq":3859181,"price":2643.75,"qty":0.0,"timestamp":1618678114468}
1618678114.504195: {"feed":"book","product_id":"FI_ETHUSD_210924","side":"sell","seq":3859182,"price":2671.25,"qty":0.0,"timestamp":1618678114468}
1618678114.5043242: {"feed":"book","product_id":"FI_ETHUSD_210924","side":"buy","seq":3859183,"price":2640.45,"qty":0.0,"timestamp":1618678114468}
1618678114.504384: {"feed":"book","product_id":"FI_ETHUSD_210924","side":"sell","seq":3859184,"price":2674.85,"qty":0.0,"timestamp":1618678114468}
1618678114.5133371: {"feed":"book","product_id":"PI_BCHUSD","side":"buy","seq":16258914,"price":1057.9,"qty":4940.0,"timestamp":1618678114488}
1618678114.5134468: {"feed":"book","product_id":"PI_BCHUSD","side":"buy","seq":16258915,"price":1058.2,"qty":3675.0,"timestamp":1618678114488}
1618678114.519726: {"feed":"book","product_id":"PI_BCHUSD","side":"buy","seq":16258916,"price":1058.9,"qty":8648.0,"timestamp":1618678114493}
1618678114.531028: {"feed":"book","product_id":"PI_BCHUSD","side":"buy","seq":16258917,"price":1058.8,"qty":7417.0,"timestamp":1618678114494}
1618678114.531103: {"feed":"book","product_id":"PI_BCHUSD","side":"buy","seq":16258918,"price":1059.3,"qty":8520.0,"timestamp":1618678114494}
1618678114.531133: {"feed":"book","product_id":"FI_XBTUSD_210625","side":"sell","seq":21455125,"price":64093.0,"qty":0.0,"timestamp":1618678114497}
1618678114.531174: {"feed":"book","product_id":"FI_XBTUSD_210625","side":"sell","seq":21455126,"price":64092.0,"qty":250001.0,"timestamp":1618678114497}
1618678114.5312052: {"feed":"book","product_id":"FI_ETHUSD_210924","side":"sell","seq":3859185,"price":2664.0,"qty":0.0,"timestamp":1618678114497}
1618678114.531233: {"feed":"book","product_id":"FI_ETHUSD_210924","side":"sell","seq":3859186,"price":2666.45,"qty":225001.0,"timestamp":1618678114497}
1618678114.5312572: {"feed":"book","product_id":"PI_BCHUSD","side":"buy","seq":16258919,"price":1059.3,"qty":5010.0,"timestamp":1618678114495}
1618678114.5312781: {"feed":"book","product_id":"FI_ETHUSD_210625","side":"sell","seq":12455604,"price":2508.5,"qty":0.0,"timestamp":1618678114497}
1618678114.531306: {"feed":"book","product_id":"FI_ETHUSD_210625","side":"sell","seq":12455605,"price":2508.0,"qty":243970.0,"timestamp":1618678114497}
1618678114.531326: {"feed":"book","product_id":"FI_ETHUSD_210430","side":"sell","seq":4780861,"price":2396.4,"qty":0.0,"timestamp":1618678114497}
1618678114.531351: {"feed":"book","product_id":"FI_ETHUSD_210430","side":"sell","seq":4780862,"price":2395.05,"qty":225001.0,"timestamp":1618678114497}
1618678114.5313752: {"feed":"book","product_id":"PI_BCHUSD","side":"buy","seq":16258920,"price":1058.8,"qty":11060.0,"timestamp":1618678114496}
1618678114.531395: {"feed":"book","product_id":"FI_XBTUSD_210625","side":"sell","seq":21455127,"price":64250.5,"qty":0.0,"timestamp":1618678114497}
1618678114.5314188: {"feed":"book","product_id":"FI_XBTUSD_210625","side":"sell","seq":21455128,"price":64249.5,"qty":125003.0,"timestamp":1618678114497}
1618678114.531441: {"feed":"book","product_id":"PI_BCHUSD","side":"sell","seq":16258921,"price":1062.5,"qty":10326.0,"timestamp":1618678114498}
1618678114.5314612: {"feed":"book","product_id":"FI_ETHUSD_210625","side":"sell","seq":12455606,"price":2512.05,"qty":0.0,"timestamp":1618678114497}
1618678114.531484: {"feed":"book","product_id":"FI_ETHUSD_210625","side":"sell","seq":12455607,"price":2511.65,"qty":303574.0,"timestamp":1618678114497}
1618678114.531507: {"feed":"book","product_id":"PI_BCHUSD","side":"sell","seq":16258922,"price":1063.0,"qty":0.0,"timestamp":1618678114499}
1618678114.531532: {"feed":"book","product_id":"FI_ETHUSD_210430","side":"sell","seq":4780863,"price":2402.2,"qty":0.0,"timestamp":1618678114497}
1618678114.5315552: {"feed":"book","product_id":"FI_ETHUSD_210430","side":"sell","seq":4780864,"price":2399.5,"qty":584747.0,"timestamp":1618678114497}
1618678114.531577: {"feed":"book","product_id":"FI_ETHUSD_210625","side":"sell","seq":12455608,"price":2515.3,"qty":0.0,"timestamp":1618678114497}
1618678114.5315998: {"feed":"book","product_id":"FI_ETHUSD_210625","side":"sell","seq":12455609,"price":2514.65,"qty":25003.0,"timestamp":1618678114497}
1618678114.531623: {"feed":"book","product_id":"FI_ETHUSD_210430","side":"sell","seq":4780865,"price":2405.2,"qty":0.0,"timestamp":1618678114497}
1618678114.5316448: {"feed":"book","product_id":"FI_ETHUSD_210430","side":"sell","seq":4780866,"price":2402.15,"qty":25003.0,"timestamp":1618678114497}
1618678114.531667: {"feed":"book","product_id":"FI_XBTUSD_210430","side":"buy","seq":12237579,"price":59445.5,"qty":48172.0,"timestamp":1618678114506}
1618678114.552707: {"feed":"book","product_id":"FI_XBTUSD_210625","side":"sell","seq":21455129,"price":64053.0,"qty":0.0,"timestamp":1618678114519}
1618678114.552798: {"feed":"book","product_id":"FI_XBTUSD_210625","side":"sell","seq":21455130,"price":64053.0,"qty":13165.0,"timestamp":1618678114519}
1618678114.5528388: {"feed":"book","product_id":"FI_XBTUSD_210625","side":"sell","seq":21455131,"price":64092.5,"qty":0.0,"timestamp":1618678114519}
1618678114.552869: {"feed":"book","product_id":"FI_XBTUSD_210625","side":"sell","seq":21455132,"price":64092.5,"qty":21255.0,"timestamp":1618678114519}
1618678114.552895: {"feed":"book","product_id":"FI_XBTUSD_210625","side":"sell","seq":21455133,"price":64118.5,"qty":0.0,"timestamp":1618678114519}
1618678114.552921: {"feed":"book","product_id":"FI_XBTUSD_210625","side":"sell","seq":21455134,"price":64118.5,"qty":27721.0,"timestamp":1618678114519}
1618678114.557066: {"feed":"book","product_id":"FI_XBTUSD_210625","side":"buy","seq":21455135,"price":63896.0,"qty":1332.0,"timestamp":1618678114520}
1618678114.557142: {"feed":"book","product_id":"FI_XBTUSD_210625","side":"buy","seq":21455136,"price":63896.0,"qty":2652.0,"timestamp":1618678114520}
1618678114.557173: {"feed":"book","product_id":"FI_XBTUSD_210625","side":"buy","seq":21455137,"price":63896.0,"qty":1320.0,"timestamp":1618678114520}
1618678114.5571961: {"feed":"book","product_id":"FI_XBTUSD_210625","side":"buy","seq":21455138,"price":63896.0,"qty":2640.0,"timestamp":1618678114520}
1618678114.5572171: {"feed":"book","product_id":"FI_XBTUSD_210625","side":"buy","seq":21455139,"price":63879.0,"qty":0.0,"timestamp":1618678114520}
1618678114.5572538: {"feed":"book","product_id":"FI_XBTUSD_210625","side":"buy","seq":21455140,"price":63879.0,"qty":1551.0,"timestamp":1618678114520}
1618678114.5572832: {"feed":"book","product_id":"FI_XBTUSD_210625","side":"buy","seq":21455141,"price":63489.0,"qty":0.0,"timestamp":1618678114520}
1618678114.557309: {"feed":"book","product_id":"FI_XBTUSD_210625","side":"buy","seq":21455142,"price":63489.0,"qty":4261.0,"timestamp":1618678114520}
1618678114.557332: {"feed":"book","product_id":"FI_XBTUSD_210625","side":"buy","seq":21455143,"price":63728.0,"qty":0.0,"timestamp":1618678114520}
1618678114.557357: {"feed":"book","product_id":"FI_XBTUSD_210625","side":"buy","seq":21455144,"price":63728.0,"qty":3266.0,"timestamp":1618678114520}
1618678114.5573802: {"feed":"book","product_id":"FI_XBTUSD_210625","side":"sell","seq":21455145,"price":64250.0,"qty":0.0,"timestamp":1618678114520}
1618678114.557407: {"feed":"book","product_id":"FI_XBTUSD_210625","side":"sell","seq":21455146,"price":64250.0,"qty":56539.0,"timestamp":1618678114520}
1618678114.55743: {"feed":"book","product_id":"FI_XBTUSD_210625","side":"sell","seq":21455147,"price":64516.5,"qty":0.0,"timestamp":1618678114520}
1618678114.557454: {"feed":"book","product_id":"FI_XBTUSD_210625","side":"sell","seq":21455148,"price":64516.5,"qty":76458.0,"timestamp":1618678114520}
1618678114.557476: {"feed":"book","product_id":"FI_ETHUSD_210430","side":"sell","seq":4780867,"price":2402.15,"qty":0.0,"timestamp":1618678114527}
1618678114.5575008: {"feed":"book","product_id":"FI_ETHUSD_210430","side":"sell","seq":4780868,"price":2402.2,"qty":25003.0,"timestamp":1618678114527}
1618678114.5677629: {"feed":"book","product_id":"FI_XRPUSD_210625","side":"buy","seq":3631593,"price":1.6919,"qty":0.0,"timestamp":1618678114539}
1618678114.5678568: {"feed":"book","product_id":"FI_XRPUSD_210625","side":"buy","seq":3631594,"price":1.6905,"qty":0.0,"timestamp":1618678114540}
1618678114.567893: {"feed":"book","product_id":"FI_XRPUSD_210625","side":"buy","seq":3631595,"price":1.6895,"qty":242.0,"timestamp":1618678114540}
1618678114.58549: {"feed":"book","product_id":"FI_XBTUSD_210430","side":"buy","seq":12237580,"price":59445.5,"qty":48489.0,"timestamp":1618678114562}
1618678114.5895958: {"feed":"book","product_id":"FI_XRPUSD_210625","side":"sell","seq":3631596,"price":1.7,"qty":0.0,"timestamp":1618678114567}
1618678114.589661: {"feed":"book","product_id":"FI_XRPUSD_210625","side":"sell","seq":3631597,"price":1.6991,"qty":18968.0,"timestamp":1618678114567}
1618678114.592803: {"feed":"book","product_id":"PI_BCHUSD","side":"sell","seq":16258923,"price":1062.8,"qty":61398.0,"timestamp":1618678114569}
1618678114.592862: {"feed":"book","product_id":"PI_BCHUSD","side":"sell","seq":16258924,"price":1063.0,"qty":3822.0,"timestamp":1618678114569}
1618678114.597163: {"feed":"book","product_id":"PI_BCHUSD","side":"sell","seq":16258925,"price":1063.2,"qty":12826.0,"timestamp":1618678114573}
1618678114.597235: {"feed":"book","product_id":"PI_BCHUSD","side":"sell","seq":16258926,"price":1063.0,"qty":14457.0,"timestamp":1618678114573}
1618678114.613885: {"feed":"book","product_id":"FI_XBTUSD_210625","side":"sell","seq":21455149,"price":63937.0,"qty":3000.0,"timestamp":1618678114585}
1618678114.6142359: {"feed":"book","product_id":"FI_XBTUSD_210625","side":"sell","seq":21455150,"price":64055.0,"qty":322753.0,"timestamp":1618678114590}
1618678114.614304: {"feed":"book","product_id":"FI_XBTUSD_210625","side":"sell","seq":21455151,"price":63937.0,"qty":9608.0,"timestamp":1618678114591}
1618678114.619037: {"feed":"book","product_id":"FI_XBTUSD_210625","side":"buy","seq":21455152,"price":63849.5,"qty":0.0,"timestamp":1618678114591}
1618678114.619216: {"feed":"book","product_id":"FI_XBTUSD_210625","side":"sell","seq":21455153,"price":63936.5,"qty":2000.0,"timestamp":1618678114591}
1618678114.619277: {"feed":"book","product_id":"FI_XBTUSD_210625","side":"buy","seq":21455154,"price":63788.5,"qty":0.0,"timestamp":1618678114592}
1618678114.619322: {"feed":"book","product_id":"FI_XBTUSD_210625","side":"buy","seq":21455155,"price":63783.0,"qty":6000.0,"timestamp":1618678114592}
1618678114.622255: {"feed":"book","product_id":"FI_XBTUSD_210625","side":"sell","seq":21455156,"price":63936.5,"qty":3900.0,"timestamp":1618678114595}
1618678114.6359491: {"feed":"book","product_id":"PI_BCHUSD","side":"buy","seq":16258927,"price":1058.2,"qty":7282.0,"timestamp":1618678114611}
1618678114.6497998: {"feed":"book","product_id":"PI_BCHUSD","side":"sell","seq":16258928,"price":1063.0,"qty":3822.0,"timestamp":1618678114621}
1618678114.649909: {"feed":"book","product_id":"PI_BCHUSD","side":"sell","seq":16258929,"price":1062.8,"qty":72033.0,"timestamp":1618678114621}
1618678114.659488: {"feed":"book","product_id":"FI_XBTUSD_210924","side":"buy","seq":13850890,"price":52552.5,"qty":58638.0,"timestamp":1618678114634}
1618678114.6595972: {"feed":"book","product_id":"PI_BCHUSD","side":"buy","seq":16258930,"price":1058.2,"qty":11103.0,"timestamp":1618678114634}
1618678114.6596491: {"feed":"book","product_id":"PI_BCHUSD","side":"buy","seq":16258931,"price":1058.8,"qty":7270.0,"timestamp":1618678114634}
1618678114.6596868: {"feed":"book","product_id":"PI_BCHUSD","side":"sell","seq":16258932,"price":1062.6,"qty":14399.0,"timestamp":1618678114636}
1618678114.666134: {"feed":"book","product_id":"FI_ETHUSD_210625","side":"buy","seq":12455610,"price":2499.35,"qty":251.0,"timestamp":1618678114639}
1618678114.6662452: {"feed":"book","product_id":"FI_ETHUSD_210625","side":"buy","seq":12455611,"price":2499.35,"qty":490.0,"timestamp":1618678114639}
1618678114.666294: {"feed":"book","product_id":"FI_ETHUSD_210625","side":"buy","seq":12455612,"price":2499.35,"qty":239.0,"timestamp":1618678114639}
1618678114.666332: {"feed":"book","product_id":"FI_ETHUSD_210625","side":"buy","seq":12455613,"price":2499.35,"qty":478.0,"timestamp":1618678114639}
1618678114.666365: {"feed":"book","product_id":"FI_ETHUSD_210625","side":"sell","seq":12455614,"price":2506.35,"qty":0.0,"timestamp":1618678114639}
1618678114.666421: {"feed":"book","product_id":"FI_ETHUSD_210625","side":"sell","seq":12455615,"price":2506.35,"qty":14674.0,"timestamp":1618678114639}
1618678114.6668549: {"feed":"book","product_id":"FI_ETHUSD_210625","side":"sell","seq":12455616,"price":2508.0,"qty":225001.0,"timestamp":1618678114639}
1618678114.6668968: {"feed":"book","product_id":"FI_ETHUSD_210625","side":"sell","seq":12455617,"price":2508.0,"qty":244707.0,"timestamp":1618678114639}
1618678114.666923: {"feed":"book","product_id":"FI_ETHUSD_210625","side":"buy","seq":12455618,"price":2496.2,"qty":0.0,"timestamp":1618678114639}
1618678114.6669571: {"feed":"book","product_id":"FI_ETHUSD_210625","side":"buy","seq":12455619,"price":2496.2,"qty":414.0,"timestamp":1618678114639}
1618678114.666985: {"feed":"book","product_id":"FI_ETHUSD_210625","side":"sell","seq":12455620,"price":2503.8,"qty":835.0,"timestamp":1618678114639}
1618678114.667007: {"feed":"book","product_id":"FI_ETHUSD_210625","side":"sell","seq":12455621,"price":2503.8,"qty":8045.0,"timestamp":1618678114639}
1618678114.669247: {"feed":"book","product_id":"FI_ETHUSD_210625","side":"sell","seq":12455622,"price":2512.0,"qty":0.0,"timestamp":1618678114639}
1618678114.669337: {"feed":"book","product_id":"FI_ETHUSD_210625","side":"sell","seq":12455623,"price":2512.0,"qty":32128.0,"timestamp":1618678114639}
1618678114.669377: {"feed":"book","product_id":"FI_ETHUSD_210625","side":"buy","seq":12455624,"price":2477.25,"qty":0.0,"timestamp":1618678114639}
1618678114.66941: {"feed":"book","product_id":"FI_ETHUSD_210625","side":"buy","seq":12455625,"price":2477.25,"qty":879.0,"timestamp":1618678114639}
1618678114.671402: {"feed":"book","product_id":"FI_ETHUSD_210625","side":"sell","seq":12455626,"price":2528.85,"qty":0.0,"timestamp":1618678114639}
1618678114.671496: {"feed":"book","product_id":"FI_ETHUSD_210625","side":"sell","seq":12455627,"price":2528.85,"qty":47825.0,"timestamp":1618678114639}
1618678114.6715362: {"feed":"book","product_id":"FI_ETHUSD_210625","side":"sell","seq":12455628,"price":2506.1,"qty":3000.0,"timestamp":1618678114643}
1618678114.682194: {"feed":"book","product_id":"FI_XBTUSD_210625","side":"sell","seq":21455157,"price":64249.5,"qty":0.0,"timestamp":1618678114649}
1618678114.6823208: {"feed":"book","product_id":"FI_XBTUSD_210625","side":"sell","seq":21455158,"price":64255.5,"qty":125003.0,"timestamp":1618678114649}
1618678114.682385: {"feed":"book","product_id":"FI_XRPUSD_210625","side":"buy","seq":3631598,"price":1.6926,"qty":0.0,"timestamp":1618678114656}
1618678114.682438: {"feed":"book","product_id":"FI_XRPUSD_210625","side":"buy","seq":3631599,"price":1.6917,"qty":19200.0,"timestamp":1618678114656}
1618678114.708409: {"feed":"book","product_id":"PI_BCHUSD","side":"sell","seq":16258933,"price":1061.6,"qty":2951.0,"timestamp":1618678114674}
1618678114.712515: {"feed":"book","product_id":"FI_XBTUSD_210924","side":"buy","seq":13850891,"price":52552.5,"qty":58823.0,"timestamp":1618678114686}
1618678114.7167192: {"feed":"book","product_id":"FI_XBTUSD_210625","side":"sell","seq":21455159,"price":64255.5,"qty":0.0,"timestamp":1618678114691}
1618678114.7168472: {"feed":"book","product_id":"FI_XBTUSD_210625","side":"sell","seq":21455160,"price":64249.5,"qty":125003.0,"timestamp":1618678114691}
1618678114.7468832: {"feed":"book","product_id":"PI_BCHUSD","side":"sell","seq":16258934,"price":1062.3,"qty":4778.0,"timestamp":1618678114715}
1618678114.74699: {"feed":"book","product_id":"FI_XBTUSD_210924","side":"sell","seq":13850892,"price":68469.5,"qty":0.0,"timestamp":1618678114718}
1618678114.747065: {"feed":"book","product_id":"FI_ETHUSD_210430","side":"sell","seq":4780869,"price":2394.1,"qty":51000.0,"timestamp":1618678114718}
1618678114.747108: {"feed":"book","product_id":"FI_XBTUSD_210924","side":"buy","seq":13850893,"price":67999.0,"qty":0.0,"timestamp":1618678114718}
1618678114.747175: {"feed":"book","product_id":"FI_XBTUSD_210924","side":"sell","seq":13850894,"price":68305.5,"qty":0.0,"timestamp":1618678114718}
1618678114.757641: {"feed":"book","product_id":"FI_XBTUSD_210924","side":"buy","seq":13850895,"price":68163.0,"qty":0.0,"timestamp":1618678114718}
1618678114.757768: {"feed":"book","product_id":"FI_XBTUSD_210430","side":"sell","seq":12237581,"price":61941.5,"qty":0.0,"timestamp":1618678114725}
1618678114.7578292: {"feed":"book","product_id":"FI_XBTUSD_210430","side":"buy","seq":12237582,"price":60664.5,"qty":0.0,"timestamp":1618678114725}
1618678114.757878: {"feed":"book","product_id":"FI_ETHUSD_210625","side":"buy","seq":12455629,"price":2494.85,"qty":0.0,"timestamp":1618678114725}
1618678114.7579432: {"feed":"book","product_id":"FI_XBTUSD_210430","side":"buy","seq":12237583,"price":61102.0,"qty":0.0,"timestamp":1618678114725}
1618678114.757995: {"feed":"book","product_id":"FI_XBTUSD_210924","side":"buy","seq":13850896,"price":68051.0,"qty":0.0,"timestamp":1618678114725}
1618678114.7580202: {"feed":"book","product_id":"FI_ETHUSD_210625","side":"buy","seq":12455630,"price":2484.65,"qty":0.0,"timestamp":1618678114726}
1618678114.758044: {"feed":"book","product_id":"FI_XBTUSD_210924","side":"sell","seq":13850897,"price":68292.5,"qty":0.0,"timestamp":1618678114726}
1618678114.75807: {"feed":"book","product_id":"PI_BCHUSD","side":"buy","seq":16258935,"price":1058.1,"qty":7551.0,"timestamp":1618678114726}
1618678114.761376: {"feed":"book","product_id":"FI_XBTUSD_210625","side":"buy","seq":21455161,"price":63785.0,"qty":0.0,"timestamp":1618678114735}
1618678114.761466: {"feed":"book","product_id":"FI_XBTUSD_210625","side":"buy","seq":21455162,"price":63773.5,"qty":250001.0,"timestamp":1618678114735}
1618678114.769245: {"feed":"book","product_id":"FI_XRPUSD_210625","side":"buy","seq":3631600,"price":1.689,"qty":361.0,"timestamp":1618678114741}
1618678114.76937: {"feed":"book","product_id":"FI_XRPUSD_210625","side":"buy","seq":3631601,"price":1.6895,"qty":0.0,"timestamp":1618678114741}
1618678114.775659: {"feed":"book","product_id":"PI_BCHUSD","side":"buy","seq":16258936,"price":1058.2,"qty":25456.0,"timestamp":1618678114749}
1618678114.7975948: {"feed":"book","product_id":"PI_BCHUSD","side":"sell","seq":16258937,"price":1061.6,"qty":0.0,"timestamp":1618678114765}
1618678114.797728: {"feed":"book","product_id":"PI_BCHUSD","side":"sell","seq":16258938,"price":1068.9,"qty":0.0,"timestamp":1618678114770}
1618678114.797786: {"feed":"book","product_id":"PI_BCHUSD","side":"sell","seq":16258939,"price":1080.3,"qty":97867.0,"timestamp":1618678114770}
1618678114.7978292: {"feed":"book","product_id":"PI_BCHUSD","side":"sell","seq":16258940,"price":1094.0,"qty":24440.0,"timestamp":1618678114770}
1618678114.797863: {"feed":"book","product_id":"PI_BCHUSD","side":"sell","seq":16258941,"price":1099.3,"qty":0.0,"timestamp":1618678114770}
1618678114.797903: {"feed":"book","product_id":"PI_BCHUSD","side":"buy","seq":16258942,"price":1055.8,"qty":0.0,"timestamp":1618678114770}
1618678114.797944: {"feed":"book","product_id":"PI_BCHUSD","side":"buy","seq":16258943,"price":1048.1,"qty":253242.0,"timestamp":1618678114770}
1618678114.7979782: {"feed":"book","product_id":"PI_BCHUSD","side":"buy","seq":16258944,"price":1034.0,"qty":100.0,"timestamp":1618678114770}
1618678114.7980092: {"feed":"book","product_id":"PI_BCHUSD","side":"buy","seq":16258945,"price":1021.1,"qty":25415.0,"timestamp":1618678114770}
1618678114.8095338: {"feed":"book","product_id":"FI_XBTUSD_210924","side":"buy","seq":13850898,"price":68163.0,"qty":7500.0,"timestamp":1618678114782}
1618678114.809669: {"feed":"book","product_id":"FI_XBTUSD_210924","side":"sell","seq":13850899,"price":68304.0,"qty":7500.0,"timestamp":1618678114782}
1618678114.809731: {"feed":"book","product_id":"FI_XBTUSD_210924","side":"buy","seq":13850900,"price":67999.0,"qty":10000.0,"timestamp":1618678114785}
1618678114.809778: {"feed":"book","product_id":"FI_XBTUSD_210924","side":"sell","seq":13850901,"price":68468.0,"qty":10000.0,"timestamp":1618678114785}
1618678114.812742: {"feed":"book","product_id":"FI_XBTUSD_210625","side":"sell","seq":21455163,"price":64042.5,"qty":0.0,"timestamp":1618678114787}
1618678114.81281: {"feed":"book","product_id":"FI_XBTUSD_210625","side":"sell","seq":21455164,"price":63999.5,"qty":8784.0,"timestamp":1618678114787}
1618678114.812862: {"feed":"book","product_id":"FI_XBTUSD_210625","side":"buy","seq":21455165,"price":62940.0,"qty":0.0,"timestamp":1618678114787}
1618678114.8128881: {"feed":"book","product_id":"FI_XBTUSD_210625","side":"buy","seq":21455166,"price":63208.5,"qty":149442.0,"timestamp":1618678114787}
1618678114.818628: {"feed":"book","product_id":"FI_XBTUSD_210924","side":"buy","seq":13850902,"price":67699.5,"qty":0.0,"timestamp":1618678114791}
1618678114.818722: {"feed":"book","product_id":"FI_XBTUSD_210924","side":"sell","seq":13850903,"price":68539.0,"qty":0.0,"timestamp":1618678114791}
1618678114.8385332: {"feed":"book","product_id":"PI_BCHUSD","side":"buy","seq":16258946,"price":1058.9,"qty":5013.0,"timestamp":1618678114801}
1618678114.849: {"feed":"book","product_id":"FI_ETHUSD_210430","side":"buy","seq":4780870,"price":2383.05,"qty":0.0,"timestamp":1618678114820}
1618678114.852758: {"feed":"book","product_id":"FI_ETHUSD_210430","side":"buy","seq":4780871,"price":2386.5,"qty":0.0,"timestamp":1618678114823}
1618678114.8618119: {"feed":"book","product_id":"FI_ETHUSD_210924","side":"buy","seq":3859187,"price":2652.0,"qty":105139.0,"timestamp":1618678114823}
1618678114.8619351: {"feed":"book","product_id":"FI_ETHUSD_210430","side":"sell","seq":4780872,"price":2390.55,"qty":0.0,"timestamp":1618678114823}
1618678114.861975: {"feed":"book","product_id":"PI_BCHUSD","side":"buy","seq":16258947,"price":1059.5,"qty":0.0,"timestamp":1618678114823}
1618678114.862008: {"feed":"book","product_id":"FI_ETHUSD_210430","side":"buy","seq":4780873,"price":2384.1,"qty":0.0,"timestamp":1618678114823}
1618678114.862037: {"feed":"book","product_id":"FI_ETHUSD_210924","side":"sell","seq":3859188,"price":2658.65,"qty":126968.0,"timestamp":1618678114823}
1618678114.862066: {"feed":"book","product_id":"PI_BCHUSD","side":"sell","seq":16258948,"price":1062.8,"qty":44062.0,"timestamp":1618678114823}
1618678114.862088: {"feed":"book","product_id":"FI_ETHUSD_210430","side":"sell","seq":4780874,"price":2392.85,"qty":0.0,"timestamp":1618678114823}
1618678114.862114: {"feed":"book","product_id":"FI_ETHUSD_210430","side":"buy","seq":4780875,"price":2381.65,"qty":0.0,"timestamp":1618678114823}
1618678114.862139: {"feed":"book","product_id":"PI_BCHUSD","side":"buy","seq":16258949,"price":1057.6,"qty":31077.0,"timestamp":1618678114823}
1618678114.862161: {"feed":"book","product_id":"FI_ETHUSD_210924","side":"buy","seq":3859189,"price":2648.4,"qty":137490.0,"timestamp":1618678114823}
1618678114.862185: {"feed":"book","product_id":"FI_ETHUSD_210430","side":"sell","seq":4780876,"price":2395.1,"qty":0.0,"timestamp":1618678114823}
1618678114.862208: {"feed":"book","product_id":"PI_BCHUSD","side":"sell","seq":16258950,"price":1064.8,"qty":0.0,"timestamp":1618678114823}
1618678114.8622332: {"feed":"book","product_id":"FI_ETHUSD_210430","side":"buy","seq":4780877,"price":2379.25,"qty":0.0,"timestamp":1618678114823}
1618678114.862257: {"feed":"book","product_id":"FI_ETHUSD_210924","side":"sell","seq":3859190,"price":2662.15,"qty":166035.0,"timestamp":1618678114823}
1618678114.8622808: {"feed":"book","product_id":"FI_ETHUSD_210430","side":"sell","seq":4780878,"price":2397.4,"qty":0.0,"timestamp":1618678114823}
1618678114.862304: {"feed":"book","product_id":"FI_ETHUSD_210430","side":"buy","seq":4780879,"price":2376.8,"qty":0.0,"timestamp":1618678114823}
1618678114.862327: {"feed":"book","product_id":"FI_ETHUSD_210924","side":"buy","seq":3859191,"price":2644.8,"qty":161753.0,"timestamp":1618678114823}
1618678114.86235: {"feed":"book","product_id":"FI_ETHUSD_210430","side":"sell","seq":4780880,"price":2399.65,"qty":0.0,"timestamp":1618678114823}
1618678114.8623738: {"feed":"book","product_id":"FI_ETHUSD_210924","side":"sell","seq":3859192,"price":2665.65,"qty":195335.0,"timestamp":1618678114823}
1618678114.862397: {"feed":"book","product_id":"FI_ETHUSD_210924","side":"buy","seq":3859193,"price":2641.25,"qty":202191.0,"timestamp":1618678114823}
1618678114.86242: {"feed":"book","product_id":"FI_ETHUSD_210924","side":"sell","seq":3859194,"price":2669.15,"qty":244169.0,"timestamp":1618678114823}
1618678114.862443: {"feed":"book","product_id":"FI_ETHUSD_210924","side":"buy","seq":3859195,"price":2637.65,"qty":242629.0,"timestamp":1618678114823}
1618678114.8624651: {"feed":"book","product_id":"FI_ETHUSD_210924","side":"sell","seq":3859196,"price":2672.7,"qty":293002.0,"timestamp":1618678114823}
1618678114.862487: {"feed":"book","product_id":"PI_BCHUSD","side":"buy","seq":16258951,"price":1055.7,"qty":0.0,"timestamp":1618678114823}
1618678114.8625112: {"feed":"book","product_id":"PI_BCHUSD","side":"sell","seq":16258952,"price":1066.8,"qty":0.0,"timestamp":1618678114823}
1618678114.862535: {"feed":"book","product_id":"FI_XBTUSD_210625","side":"sell","seq":21455167,"price":63960.0,"qty":0.0,"timestamp":1618678114829}
1618678114.863969: {"feed":"book","product_id":"FI_ETHUSD_210924","side":"sell","seq":3859197,"price":2663.5,"qty":0.0,"timestamp":1618678114830}
1618678114.864056: {"feed":"book","product_id":"FI_XBTUSD_210924","side":"buy","seq":13850904,"price":68071.5,"qty":0.0,"timestamp":1618678114835}
1618678114.864097: {"feed":"book","product_id":"FI_XBTUSD_210924","side":"buy","seq":13850905,"price":68051.0,"qty":250001.0,"timestamp":1618678114835}
1618678114.8641322: {"feed":"book","product_id":"FI_XBTUSD_210625","side":"buy","seq":21455168,"price":63761.0,"qty":0.0,"timestamp":1618678114835}
1618678114.870785: {"feed":"book","product_id":"FI_ETHUSD_210924","side":"sell","seq":3859198,"price":2659.2,"qty":19249.0,"timestamp":1618678114840}
1618678114.8708549: {"feed":"book","product_id":"FI_ETHUSD_210924","side":"sell","seq":3859199,"price":2658.6,"qty":840.0,"timestamp":1618678114840}
1618678114.8709161: {"feed":"book","product_id":"FI_XBTUSD_210625","side":"sell","seq":21455169,"price":63956.0,"qty":11005.0,"timestamp":1618678114840}
1618678114.8844302: {"feed":"book","product_id":"FI_ETHUSD_210625","side":"sell","seq":12455631,"price":2503.8,"qty":835.0,"timestamp":1618678114846}
1618678114.8845398: {"feed":"book","product_id":"FI_ETHUSD_210625","side":"sell","seq":12455632,"price":2504.05,"qty":7284.0,"timestamp":1618678114846}
1618678114.884606: {"feed":"book","product_id":"FI_XBTUSD_210625","side":"buy","seq":21455170,"price":63773.5,"qty":0.0,"timestamp":1618678114844}
1618678114.884663: {"feed":"book","product_id":"FI_XBTUSD_210625","side":"buy","seq":21455171,"price":63728.0,"qty":253267.0,"timestamp":1618678114844}
1618678114.8846998: {"feed":"book","product_id":"FI_ETHUSD_210924","side":"sell","seq":3859200,"price":2666.45,"qty":0.0,"timestamp":1618678114844}
1618678114.884744: {"feed":"book","product_id":"FI_ETHUSD_210924","side":"sell","seq":3859201,"price":2662.1,"qty":225001.0,"timestamp":1618678114844}
1618678114.884783: {"feed":"book","product_id":"FI_ETHUSD_210625","side":"sell","seq":12455633,"price":2512.0,"qty":0.0,"timestamp":1618678114846}
1618678114.884829: {"feed":"book","product_id":"FI_ETHUSD_210625","side":"sell","seq":12455634,"price":2513.2,"qty":33908.0,"timestamp":1618678114846}
1618678114.8848782: {"feed":"book","product_id":"FI_XBTUSD_210924","side":"buy","seq":13850906,"price":67988.0,"qty":0.0,"timestamp":1618678114844}
1618678114.884904: {"feed":"book","product_id":"FI_XBTUSD_210924","side":"buy","seq":13850907,"price":67964.0,"qty":250002.0,"timestamp":1618678114844}
1618678114.888633: {"feed":"book","product_id":"FI_ETHUSD_210430","side":"sell","seq":4780881,"price":2395.05,"qty":0.0,"timestamp":1618678114853}
1618678114.88876: {"feed":"book","product_id":"FI_ETHUSD_210430","side":"sell","seq":4780882,"price":2396.4,"qty":225001.0,"timestamp":1618678114853}
1618678114.888824: {"feed":"book","product_id":"FI_BCHUSD_210625","side":"buy","seq":2240247,"price":1120.8,"qty":4513.0,"timestamp":1618678114859}
1618678114.888866: {"feed":"book","product_id":"FI_BCHUSD_210625","side":"buy","seq":2240248,"price":1108.5,"qty":15022.0,"timestamp":1618678114859}
1618678114.888907: {"feed":"book","product_id":"PI_BCHUSD","side":"sell","seq":16258953,"price":1062.7,"qty":0.0,"timestamp":1618678114862}
1618678114.898205: {"feed":"book","product_id":"PI_BCHUSD","side":"sell","seq":16258954,"price":1068.9,"qty":14641.0,"timestamp":1618678114865}
1618678114.898329: {"feed":"book","product_id":"PI_BCHUSD","side":"sell","seq":16258955,"price":1080.3,"qty":112508.0,"timestamp":1618678114865}
1618678114.898379: {"feed":"book","product_id":"FI_XBTUSD_210430","side":"buy","seq":12237584,"price":61131.0,"qty":0.0,"timestamp":1618678114866}
1618678114.898435: {"feed":"book","product_id":"PI_BCHUSD","side":"sell","seq":16258956,"price":1083.6,"qty":89988.0,"timestamp":1618678114865}
1618678114.898473: {"feed":"book","product_id":"PI_BCHUSD","side":"sell","seq":16258957,"price":1098.7,"qty":14641.0,"timestamp":1618678114865}
1618678114.898537: {"feed":"book","product_id":"PI_BCHUSD","side":"buy","seq":16258958,"price":1055.1,"qty":14641.0,"timestamp":1618678114865}
1618678114.8985631: {"feed":"book","product_id":"PI_BCHUSD","side":"buy","seq":16258959,"price":1048.1,"qty":267883.0,"timestamp":1618678114865}
1618678114.8985841: {"feed":"book","product_id":"PI_BCHUSD","side":"buy","seq":16258960,"price":1034.0,"qty":14741.0,"timestamp":1618678114865}
1618678114.898605: {"feed":"book","product_id":"PI_BCHUSD","side":"buy","seq":16258961,"price":1021.1,"qty":40056.0,"timestamp":1618678114865}
1618678114.90548: {"feed":"book","product_id":"PI_BCHUSD","side":"sell","seq":16258962,"price":1083.6,"qty":75347.0,"timestamp":1618678114871}
1618678114.905589: {"feed":"book","product_id":"PI_BCHUSD","side":"buy","seq":16258963,"price":1034.0,"qty":100.0,"timestamp":1618678114872}
1618678114.905638: {"feed":"book","product_id":"PI_BCHUSD","side":"sell","seq":16258964,"price":1068.9,"qty":0.0,"timestamp":1618678114872}
1618678114.905699: {"feed":"book","product_id":"PI_BCHUSD","side":"buy","seq":16258965,"price":1048.1,"qty":253242.0,"timestamp":1618678114872}
1618678114.905735: {"feed":"book","product_id":"PI_BCHUSD","side":"sell","seq":16258966,"price":1080.3,"qty":97867.0,"timestamp":1618678114872}
1618678114.9057658: {"feed":"book","product_id":"PI_BCHUSD","side":"buy","seq":16258967,"price":1055.1,"qty":0.0,"timestamp":1618678114872}
1618678114.9058309: {"feed":"book","product_id":"PI_BCHUSD","side":"buy","seq":16258968,"price":1021.1,"qty":25415.0,"timestamp":1618678114877}
1618678114.9058518: {"feed":"book","product_id":"PI_BCHUSD","side":"sell","seq":16258969,"price":1098.7,"qty":0.0,"timestamp":1618678114877}
1618678114.90956: {"feed":"book","product_id":"FI_ETHUSD_210430","side":"sell","seq":4780883,"price":2402.2,"qty":0.0,"timestamp":1618678114879}
1618678114.909703: {"feed":"book","product_id":"FI_ETHUSD_210430","side":"sell","seq":4780884,"price":2405.2,"qty":25003.0,"timestamp":1618678114879}
1618678114.909765: {"feed":"book","product_id":"FI_XBTUSD_210625","side":"buy","seq":21455172,"price":63728.0,"qty":3266.0,"timestamp":1618678114879}
1618678114.909806: {"feed":"book","product_id":"FI_XBTUSD_210625","side":"buy","seq":21455173,"price":63773.5,"qty":250001.0,"timestamp":1618678114879}
1618678114.9258099: {"feed":"book","product_id":"PI_BCHUSD","side":"sell","seq":16258970,"price":1062.5,"qty":6712.0,"timestamp":1618678114889}
1618678114.925917: {"feed":"book","product_id":"PI_BCHUSD","side":"sell","seq":16258971,"price":1063.2,"qty":9021.0,"timestamp":1618678114890}
1618678114.925972: {"feed":"book","product_id":"FI_XBTUSD_210625","side":"sell","seq":21455174,"price":64193.0,"qty":0.0,"timestamp":1618678114892}
1618678114.926045: {"feed":"book","product_id":"FI_XBTUSD_210625","side":"sell","seq":21455175,"price":64517.0,"qty":0.0,"timestamp":1618678114892}
1618678114.926074: {"feed":"book","product_id":"FI_BCHUSD_210625","side":"sell","seq":2240249,"price":1139.7,"qty":0.0,"timestamp":1618678114889}
1618678114.926103: {"feed":"book","product_id":"FI_BCHUSD_210625","side":"sell","seq":2240250,"price":1142.9,"qty":4513.0,"timestamp":1618678114889}
1618678114.9261298: {"feed":"book","product_id":"FI_XBTUSD_210625","side":"sell","seq":21455176,"price":64841.0,"qty":0.0,"timestamp":1618678114892}
1618678114.926156: {"feed":"book","product_id":"FI_XBTUSD_210625","side":"sell","seq":21455177,"price":65489.0,"qty":0.0,"timestamp":1618678114892}
1618678114.9261792: {"feed":"book","product_id":"FI_XBTUSD_210625","side":"buy","seq":21455178,"price":63646.0,"qty":0.0,"timestamp":1618678114892}
1618678114.926205: {"feed":"book","product_id":"FI_XBTUSD_210430","side":"buy","seq":12237585,"price":59445.5,"qty":52927.0,"timestamp":1618678114890}
1618678114.926226: {"feed":"book","product_id":"FI_XBTUSD_210625","side":"buy","seq":21455179,"price":63428.0,"qty":0.0,"timestamp":1618678114892}
1618678114.926251: {"feed":"book","product_id":"FI_XBTUSD_210625","side":"buy","seq":21455180,"price":63210.5,"qty":0.0,"timestamp":1618678114892}
1618678114.926274: {"feed":"book","product_id":"FI_XBTUSD_210625","side":"buy","seq":21455181,"price":62775.0,"qty":0.0,"timestamp":1618678114892}
1618678114.9262981: {"feed":"book","product_id":"FI_XBTUSD_210625","side":"buy","seq":21455182,"price":62121.5,"qty":0.0,"timestamp":1618678114892}
1618678114.9263208: {"feed":"book","product_id":"PI_BCHUSD","side":"buy","seq":16258972,"price":1057.9,"qty":3746.0,"timestamp":1618678114896}
1618678114.931377: {"feed":"book","product_id":"PI_BCHUSD","side":"buy","seq":16258973,"price":1058.8,"qty":3643.0,"timestamp":1618678114902}
1618678114.954149: {"feed":"book","product_id":"PI_BCHUSD","side":"buy","seq":16258974,"price":1058.6,"qty":8598.0,"timestamp":1618678114918}
1618678114.954216: {"feed":"book","product_id":"FI_XRPUSD_210625","side":"sell","seq":3631602,"price":1.6991,"qty":0.0,"timestamp":1618678114918}
1618678114.954282: {"feed":"book","product_id":"FI_XRPUSD_210625","side":"sell","seq":3631603,"price":1.6982,"qty":18968.0,"timestamp":1618678114918}
1618678114.9543302: {"feed":"book","product_id":"FI_XRPUSD_210625","side":"sell","seq":3631604,"price":1.7052,"qty":0.0,"timestamp":1618678114918}
1618678114.9543722: {"feed":"book","product_id":"FI_XRPUSD_210625","side":"sell","seq":3631605,"price":1.7034,"qty":57600.0,"timestamp":1618678114918}
1618678114.95441: {"feed":"book","product_id":"FI_XRPUSD_210625","side":"buy","seq":3631606,"price":1.689,"qty":0.0,"timestamp":1618678114922}
1618678114.964569: {"feed":"book","product_id":"FI_XRPUSD_210625","side":"sell","seq":3631607,"price":1.6983,"qty":0.0,"timestamp":1618678114930}
1618678114.964658: {"feed":"book","product_id":"FI_XRPUSD_210625","side":"sell","seq":3631608,"price":1.6981,"qty":768.0,"timestamp":1618678114930}
1618678114.964714: {"feed":"book","product_id":"FI_XBTUSD_210625","side":"sell","seq":21455183,"price":64427.5,"qty":0.0,"timestamp":1618678114930}
1618678114.973481: {"feed":"book","product_id":"PI_BCHUSD","side":"buy","seq":16258975,"price":1058.0,"qty":48486.0,"timestamp":1618678114945}
1618678114.980437: {"feed":"book","product_id":"FI_ETHUSD_210625","side":"sell","seq":12455635,"price":2511.65,"qty":0.0,"timestamp":1618678114953}
1618678114.980565: {"feed":"book","product_id":"FI_ETHUSD_210625","side":"sell","seq":12455636,"price":2511.3,"qty":303574.0,"timestamp":1618678114953}
1618678114.980628: {"feed":"book","product_id":"FI_XBTUSD_210625","side":"buy","seq":21455184,"price":63773.5,"qty":0.0,"timestamp":1618678114953}
1618678114.980683: {"feed":"book","product_id":"FI_XBTUSD_210625","side":"buy","seq":21455185,"price":63728.0,"qty":253267.0,"timestamp":1618678114953}
1618678114.980721: {"feed":"book","product_id":"FI_ETHUSD_210430","side":"sell","seq":4780885,"price":2405.2,"qty":0.0,"timestamp":1618678114953}
1618678114.980766: {"feed":"book","product_id":"FI_ETHUSD_210430","side":"sell","seq":4780886,"price":2402.2,"qty":25003.0,"timestamp":1618678114953}
1618678114.9981189: {"feed":"book","product_id":"FI_XBTUSD_210924","side":"buy","seq":13850908,"price":52552.5,"qty":58638.0,"timestamp":1618678114965}
1618678115.083211: {"feed":"book","product_id":"PI_BCHUSD","side":"sell","seq":16258976,"price":1062.8,"qty":33427.0,"timestamp":1618678115038}
1618678115.0832808: {"feed":"book","product_id":"PI_BCHUSD","side":"sell","seq":16258977,"price":1062.6,"qty":25034.0,"timestamp":1618678115038}
1618678115.083322: {"feed":"book","product_id":"PI_BCHUSD","side":"sell","seq":16258978,"price":1062.0,"qty":19791.0,"timestamp":1618678115038}
1618678115.083423: {"feed":"book","product_id":"FI_XBTUSD_210625","side":"buy","seq":21455186,"price":63927.0,"qty":89.0,"timestamp":1618678114957}
1618678115.087404: {"feed":"book","product_id":"FI_ETHUSD_210430","side":"buy","seq":4780887,"price":2387.15,"qty":0.0,"timestamp":1618678115038}
1618678115.087498: {"feed":"book","product_id":"FI_ETHUSD_210430","side":"buy","seq":4780888,"price":2386.8,"qty":1020.0,"timestamp":1618678115038}
1618678115.08754: {"feed":"book","product_id":"FI_ETHUSD_210430","side":"sell","seq":4780889,"price":2402.25,"qty":0.0,"timestamp":1618678115038}
1618678115.087574: {"feed":"book","product_id":"FI_ETHUSD_210430","side":"sell","seq":4780890,"price":2400.55,"qty":204000.0,"timestamp":1618678115038}
1618678115.0876029: {"feed":"book","product_id":"FI_ETHUSD_210430","side":"sell","seq":4780891,"price":2394.1,"qty":0.0,"timestamp":1618678115038}
1618678115.087631: {"feed":"book","product_id":"FI_ETHUSD_210430","side":"sell","seq":4780892,"price":2393.2,"qty":52274.0,"timestamp":1618678115038}
1618678115.0876532: {"feed":"book","product_id":"FI_ETHUSD_210430","side":"buy","seq":4780893,"price":2386.05,"qty":0.0,"timestamp":1618678115038}
1618678115.087701: {"feed":"book","product_id":"FI_ETHUSD_210430","side":"buy","seq":4780894,"price":2385.65,"qty":25500.0,"timestamp":1618678115038}
1618678115.087753: {"feed":"book","product_id":"FI_ETHUSD_210430","side":"sell","seq":4780895,"price":2389.95,"qty":0.0,"timestamp":1618678115038}
1618678115.08778: {"feed":"book","product_id":"FI_ETHUSD_210430","side":"sell","seq":4780896,"price":2389.55,"qty":25500.0,"timestamp":1618678115038}
1618678115.087855: {"feed":"book","product_id":"FI_XBTUSD_210625","side":"buy","seq":21455187,"price":63927.0,"qty":0.0,"timestamp":1618678114987}
1618678115.087884: {"feed":"book","product_id":"FI_XBTUSD_210625","side":"sell","seq":21455188,"price":63976.5,"qty":0.0,"timestamp":1618678115038}
1618678115.087911: {"feed":"book","product_id":"FI_XBTUSD_210625","side":"sell","seq":21455189,"price":63964.0,"qty":1920.0,"timestamp":1618678115038}
1618678115.087956: {"feed":"book","product_id":"FI_XBTUSD_210924","side":"buy","seq":13850909,"price":68120.0,"qty":3000.0,"timestamp":1618678115038}
1618678115.0880132: {"feed":"book","product_id":"FI_XBTUSD_210924","side":"sell","seq":13850910,"price":68291.0,"qty":0.0,"timestamp":1618678115038}
1618678115.088039: {"feed":"book","product_id":"FI_XBTUSD_210924","side":"sell","seq":13850911,"price":68289.0,"qty":1680.0,"timestamp":1618678115038}
1618678115.0880818: {"feed":"book","product_id":"FI_XBTUSD_210430","side":"buy","seq":12237586,"price":61176.5,"qty":0.0,"timestamp":1618678115038}
1618678115.088108: {"feed":"book","product_id":"FI_XBTUSD_210430","side":"buy","seq":12237587,"price":61165.5,"qty":658.0,"timestamp":1618678115038}
1618678115.0881312: {"feed":"book","product_id":"FI_ETHUSD_210625","side":"buy","seq":12455637,"price":2500.75,"qty":0.0,"timestamp":1618678115038}
1618678115.088157: {"feed":"book","product_id":"FI_ETHUSD_210625","side":"buy","seq":12455638,"price":2500.25,"qty":860.0,"timestamp":1618678115038}
1618678115.08818: {"feed":"book","product_id":"FI_XBTUSD_210924","side":"buy","seq":13850912,"price":68237.5,"qty":0.0,"timestamp":1618678115038}
1618678115.088205: {"feed":"book","product_id":"FI_XBTUSD_210924","side":"buy","seq":13850913,"price":68219.5,"qty":1680.0,"timestamp":1618678115038}
1618678115.088228: {"feed":"book","product_id":"FI_XBTUSD_210430","side":"buy","seq":12237588,"price":61078.5,"qty":0.0,"timestamp":1618678115038}
1618678115.0882509: {"feed":"book","product_id":"FI_XBTUSD_210430","side":"buy","seq":12237589,"price":61054.5,"qty":102000.0,"timestamp":1618678115038}
1618678115.0882921: {"feed":"book","product_id":"FI_XBTUSD_210430","side":"sell","seq":12237590,"price":61243.5,"qty":0.0,"timestamp":1618678115038}
1618678115.0883179: {"feed":"book","product_id":"FI_XBTUSD_210430","side":"sell","seq":12237591,"price":61233.0,"qty":51000.0,"timestamp":1618678115038}
1618678115.098088: {"feed":"book","product_id":"FI_ETHUSD_210924","side":"sell","seq":3859202,"price":2666.5,"qty":0.0,"timestamp":1618678115038}
1618678115.098221: {"feed":"book","product_id":"FI_ETHUSD_210924","side":"sell","seq":3859203,"price":2664.95,"qty":42000.0,"timestamp":1618678115038}
1618678115.098285: {"feed":"book","product_id":"FI_ETHUSD_210924","side":"buy","seq":3859204,"price":2653.65,"qty":0.0,"timestamp":1618678115038}
1618678115.098337: {"feed":"book","product_id":"FI_ETHUSD_210924","side":"buy","seq":3859205,"price":2652.65,"qty":21000.0,"timestamp":1618678115038}
1618678115.098381: {"feed":"book","product_id":"FI_XBTUSD_210430","side":"buy","seq":12237592,"price":61150.0,"qty":0.0,"timestamp":1618678115038}
1618678115.098473: {"feed":"book","product_id":"FI_XBTUSD_210430","side":"buy","seq":12237593,"price":61139.0,"qty":51000.0,"timestamp":1618678115038}
1618678115.114181: {"feed":"book","product_id":"FI_ETHUSD_210430","side":"buy","seq":4780897,"price":2385.7,"qty":146480.0,"timestamp":1618678115061}
1618678115.114302: {"feed":"book","product_id":"FI_XBTUSD_210924","side":"sell","seq":13850914,"price":68511.5,"qty":0.0,"timestamp":1618678115039}
1618678115.114343: {"feed":"book","product_id":"FI_XBTUSD_210924","side":"sell","seq":13850915,"price":68474.5,"qty":84000.0,"timestamp":1618678115039}
1618678115.114372: {"feed":"book","product_id":"FI_ETHUSD_210430","side":"sell","seq":4780898,"price":2389.45,"qty":107988.0,"timestamp":1618678115061}
1618678115.114399: {"feed":"book","product_id":"PI_BCHUSD","side":"buy","seq":16258979,"price":1057.0,"qty":11021.0,"timestamp":1618678115039}
1618678115.114422: {"feed":"book","product_id":"FI_ETHUSD_210430","side":"buy","seq":4780899,"price":2383.6,"qty":191551.0,"timestamp":1618678115061}
1618678115.1144462: {"feed":"book","product_id":"FI_XBTUSD_210924","side":"sell","seq":13850916,"price":68349.5,"qty":0.0,"timestamp":1618678115039}
1618678115.114472: {"feed":"book","product_id":"FI_XBTUSD_210924","side":"sell","seq":13850917,"price":68327.0,"qty":42000.0,"timestamp":1618678115039}
1618678115.114496: {"feed":"book","product_id":"FI_ETHUSD_210430","side":"sell","seq":4780900,"price":2391.55,"qty":141265.0,"timestamp":1618678115061}
1618678115.114517: {"feed":"book","product_id":"PI_BCHUSD","side":"buy","seq":16258980,"price":1058.4,"qty":0.0,"timestamp":1618678115039}
1618678115.114542: {"feed":"book","product_id":"FI_ETHUSD_210430","side":"buy","seq":4780901,"price":2381.45,"qty":225354.0,"timestamp":1618678115061}
1618678115.1145658: {"feed":"book","product_id":"FI_XBTUSD_210924","side":"buy","seq":13850918,"price":68197.5,"qty":0.0,"timestamp":1618678115039}
1618678115.114592: {"feed":"book","product_id":"FI_XBTUSD_210924","side":"buy","seq":13850919,"price":68174.0,"qty":42000.0,"timestamp":1618678115039}
1618678115.114615: {"feed":"book","product_id":"PI_BCHUSD","side":"buy","seq":16258981,"price":1057.7,"qty":0.0,"timestamp":1618678115039}
1618678115.114639: {"feed":"book","product_id":"FI_XBTUSD_210924","side":"buy","seq":13850920,"price":52552.5,"qty":58854.0,"timestamp":1618678115039}
1618678115.114659: {"feed":"book","product_id":"PI_BCHUSD","side":"sell","seq":16258982,"price":1062.5,"qty":3705.0,"timestamp":1618678115039}
1618678115.114679: {"feed":"book","product_id":"FI_ETHUSD_210430","side":"sell","seq":4780902,"price":2393.7,"qty":166136.0,"timestamp":1618678115061}
1618678115.114702: {"feed":"book","product_id":"FI_XBTUSD_210924","side":"sell","seq":13850921,"price":68325.5,"qty":0.0,"timestamp":1618678115039}
1618678115.114746: {"feed":"book","product_id":"PI_BCHUSD","side":"sell","seq":16258983,"price":1062.9,"qty":25695.0,"timestamp":1618678115039}
1618678115.114772: {"feed":"book","product_id":"PI_BCHUSD","side":"buy","seq":16258984,"price":1058.2,"qty":11103.0,"timestamp":1618678115039}
1618678115.1147919: {"feed":"book","product_id":"PI_BCHUSD","side":"buy","seq":16258985,"price":1058.6,"qty":5146.0,"timestamp":1618678115039}
1618678115.1148312: {"feed":"book","product_id":"FI_ETHUSD_210625","side":"sell","seq":12455639,"price":2504.1,"qty":0.0,"timestamp":1618678115038}
1618678115.114858: {"feed":"book","product_id":"FI_ETHUSD_210625","side":"sell","seq":12455640,"price":2503.6,"qty":24000.0,"timestamp":1618678115038}
1618678115.114881: {"feed":"book","product_id":"FI_XBTUSD_210430","side":"sell","seq":12237594,"price":61429.0,"qty":0.0,"timestamp":1618678115038}
1618678115.1149068: {"feed":"book","product_id":"FI_XBTUSD_210430","side":"sell","seq":12237595,"price":61402.5,"qty":204000.0,"timestamp":1618678115038}
1618678115.11493: {"feed":"book","product_id":"PI_BCHUSD","side":"sell","seq":16258986,"price":1061.1,"qty":2644.0,"timestamp":1618678115039}
1618678115.1149518: {"feed":"book","product_id":"PI_BCHUSD","side":"buy","seq":16258987,"price":1058.0,"qty":20795.0,"timestamp":1618678115039}
1618678115.114971: {"feed":"book","product_id":"PI_BCHUSD","side":"sell","seq":16258988,"price":1062.5,"qty":0.0,"timestamp":1618678115039}
1618678115.114995: {"feed":"book","product_id":"PI_BCHUSD","side":"sell","seq":16258989,"price":1061.6,"qty":4995.0,"timestamp":1618678115039}
1618678115.115017: {"feed":"book","product_id":"PI_BCHUSD","side":"sell","seq":16258990,"price":1062.0,"qty":24784.0,"timestamp":1618678115039}
1618678115.115036: {"feed":"book","product_id":"PI_BCHUSD","side":"sell","seq":16258991,"price":1064.0,"qty":0.0,"timestamp":1618678115039}
1618678115.115059: {"feed":"book","product_id":"PI_BCHUSD","side":"buy","seq":16258992,"price":1057.2,"qty":26948.0,"timestamp":1618678115039}
1618678115.115081: {"feed":"book","product_id":"PI_BCHUSD","side":"sell","seq":16258993,"price":1062.8,"qty":28438.0,"timestamp":1618678115039}
1618678115.1151: {"feed":"book","product_id":"PI_BCHUSD","side":"sell","seq":16258994,"price":1063.2,"qty":4034.0,"timestamp":1618678115039}
1618678115.1151192: {"feed":"book","product_id":"PI_BCHUSD","side":"buy","seq":16258995,"price":1056.1,"qty":29423.0,"timestamp":1618678115039}
1618678115.1151402: {"feed":"book","product_id":"PI_BCHUSD","side":"sell","seq":16258996,"price":1062.3,"qty":1208.0,"timestamp":1618678115039}
1618678115.115158: {"feed":"book","product_id":"FI_ETHUSD_210430","side":"buy","seq":4780903,"price":2379.35,"qty":281692.0,"timestamp":1618678115061}
1618678115.115181: {"feed":"book","product_id":"FI_ETHUSD_210430","side":"sell","seq":4780904,"price":2395.85,"qty":207669.0,"timestamp":1618678115061}
1618678115.115202: {"feed":"book","product_id":"FI_ETHUSD_210430","side":"buy","seq":4780905,"price":2377.25,"qty":338031.0,"timestamp":1618678115061}
1618678115.1152241: {"feed":"book","product_id":"FI_ETHUSD_210430","side":"sell","seq":4780906,"price":2397.95,"qty":249203.0,"timestamp":1618678115061}
1618678115.115246: {"feed":"book","product_id":"PI_BCHUSD","side":"sell","seq":16258997,"price":1061.1,"qty":5086.0,"timestamp":1618678115039}
1618678115.115264: {"feed":"book","product_id":"PI_BCHUSD","side":"buy","seq":16258998,"price":1058.8,"qty":0.0,"timestamp":1618678115039}
1618678115.115287: {"feed":"book","product_id":"FI_ETHUSD_210430","side":"sell","seq":4780907,"price":2402.2,"qty":0.0,"timestamp":1618678115069}
1618678115.115312: {"feed":"book","product_id":"FI_ETHUSD_210430","side":"sell","seq":4780908,"price":2405.2,"qty":25003.0,"timestamp":1618678115069}
1618678115.1153338: {"feed":"book","product_id":"PI_BCHUSD","side":"sell","seq":16258999,"price":1062.7,"qty":3657.0,"timestamp":1618678115039}
1618678115.1153548: {"feed":"book","product_id":"FI_ETHUSD_210430","side":"sell","seq":4780909,"price":2389.55,"qty":0.0,"timestamp":1618678115074}
1618678115.115378: {"feed":"book","product_id":"FI_ETHUSD_210430","side":"sell","seq":4780910,"price":2389.45,"qty":133488.0,"timestamp":1618678115074}
1618678115.115417: {"feed":"book","product_id":"FI_XBTUSD_210430","side":"sell","seq":12237596,"price":61235.5,"qty":3209.0,"timestamp":1618678115078}
1618678115.115437: {"feed":"book","product_id":"FI_XBTUSD_210430","side":"sell","seq":12237597,"price":61232.5,"qty":1904.0,"timestamp":1618678115078}
1618678115.115459: {"feed":"book","product_id":"FI_ETHUSD_210924","side":"sell","seq":3859206,"price":2669.85,"qty":0.0,"timestamp":1618678115074}
1618678115.1366642: {"feed":"book","product_id":"PI_BCHUSD","side":"buy","seq":16259000,"price":1058.2,"qty":7428.0,"timestamp":1618678115039}
1618678115.136777: {"feed":"book","product_id":"PI_BCHUSD","side":"sell","seq":16259001,"price":1063.6,"qty":0.0,"timestamp":1618678115039}
1618678115.136846: {"feed":"book","product_id":"PI_BCHUSD","side":"buy","seq":16259002,"price":1056.8,"qty":33551.0,"timestamp":1618678115039}
1618678115.1368861: {"feed":"book","product_id":"PI_BCHUSD","side":"buy","seq":16259003,"price":1058.6,"qty":33167.0,"timestamp":1618678115039}
1618678115.1369212: {"feed":"book","product_id":"PI_BCHUSD","side":"sell","seq":16259004,"price":1062.0,"qty":55425.0,"timestamp":1618678115039}
1618678115.1369548: {"feed":"book","product_id":"PI_BCHUSD","side":"buy","seq":16259005,"price":1056.3,"qty":36635.0,"timestamp":1618678115039}
1618678115.141917: {"feed":"book","product_id":"PI_BCHUSD","side":"sell","seq":16259006,"price":1064.0,"qty":35748.0,"timestamp":1618678115039}
1618678115.141976: {"feed":"book","product_id":"FI_ETHUSD_210430","side":"sell","seq":4780911,"price":2389.9,"qty":0.0,"timestamp":1618678115078}
1618678115.142015: {"feed":"book","product_id":"FI_ETHUSD_210430","side":"sell","seq":4780912,"price":2389.4,"qty":1020.0,"timestamp":1618678115078}
1618678115.1420429: {"feed":"book","product_id":"PI_BCHUSD","side":"buy","seq":16259007,"price":1054.0,"qty":37361.0,"timestamp":1618678115039}
1618678115.14207: {"feed":"book","product_id":"PI_BCHUSD","side":"sell","seq":16259008,"price":1066.1,"qty":40855.0,"timestamp":1618678115039}
1618678115.1420941: {"feed":"book","product_id":"PI_BCHUSD","side":"sell","seq":16259009,"price":1062.6,"qty":14399.0,"timestamp":1618678115044}
1618678115.1421142: {"feed":"book","product_id":"PI_BCHUSD","side":"sell","seq":16259010,"price":1062.4,"qty":15626.0,"timestamp":1618678115044}
1618678115.142133: {"feed":"book","product_id":"PI_BCHUSD","side":"sell","seq":16259011,"price":1061.5,"qty":86.0,"timestamp":1618678115044}
1618678115.142154: {"feed":"book","product_id":"PI_BCHUSD","side":"sell","seq":16259012,"price":1062.4,"qty":4991.0,"timestamp":1618678115074}
1618678115.1421719: {"feed":"book","product_id":"PI_BCHUSD","side":"sell","seq":16259013,"price":1062.3,"qty":11843.0,"timestamp":1618678115074}
1618678115.14219: {"feed":"book","product_id":"FI_XBTUSD_210924","side":"sell","seq":13850922,"price":68335.0,"qty":0.0,"timestamp":1618678115087}
1618678115.1422179: {"feed":"book","product_id":"PI_BCHUSD","side":"buy","seq":16259014,"price":1057.6,"qty":4164.0,"timestamp":1618678115074}
1618678115.142239: {"feed":"book","product_id":"FI_XBTUSD_210924","side":"buy","seq":13850923,"price":67963.5,"qty":0.0,"timestamp":1618678115087}
1618678115.142265: {"feed":"book","product_id":"PI_BCHUSD","side":"buy","seq":16259015,"price":1056.6,"qty":25614.0,"timestamp":1618678115075}
1618678115.142288: {"feed":"book","product_id":"FI_XBTUSD_210924","side":"buy","seq":13850924,"price":67802.0,"qty":0.0,"timestamp":1618678115087}
1618678115.142312: {"feed":"book","product_id":"PI_BCHUSD","side":"sell","seq":16259016,"price":1062.4,"qty":0.0,"timestamp":1618678115075}
1618678115.142335: {"feed":"book","product_id":"FI_XBTUSD_210625","side":"sell","seq":21455190,"price":64010.0,"qty":0.0,"timestamp":1618678115039}
1618678115.142359: {"feed":"book","product_id":"FI_XBTUSD_210625","side":"sell","seq":21455191,"price":63997.5,"qty":48000.0,"timestamp":1618678115039}
1618678115.1423821: {"feed":"book","product_id":"FI_XBTUSD_210625","side":"buy","seq":21455192,"price":63891.5,"qty":0.0,"timestamp":1618678115039}
1618678115.142407: {"feed":"book","product_id":"FI_XBTUSD_210625","side":"buy","seq":21455193,"price":63880.5,"qty":48000.0,"timestamp":1618678115039}
1618678115.14243: {"feed":"book","product_id":"FI_XBTUSD_210430","side":"sell","seq":12237598,"price":61248.0,"qty":0.0,"timestamp":1618678115090}
1618678115.142455: {"feed":"book","product_id":"FI_XBTUSD_210430","side":"sell","seq":12237599,"price":61247.0,"qty":10000.0,"timestamp":1618678115090}
1618678115.142498: {"feed":"book","product_id":"FI_XBTUSD_210625","side":"buy","seq":21455194,"price":63879.0,"qty":0.0,"timestamp":1618678115061}
1618678115.1425228: {"feed":"book","product_id":"FI_XBTUSD_210625","side":"buy","seq":21455195,"price":63826.5,"qty":2056.0,"timestamp":1618678115061}
1618678115.142546: {"feed":"book","product_id":"FI_XBTUSD_210924","side":"sell","seq":13850925,"price":68265.0,"qty":3000.0,"timestamp":1618678115090}
1618678115.1425679: {"feed":"book","product_id":"FI_XBTUSD_210625","side":"sell","seq":21455196,"price":64053.0,"qty":0.0,"timestamp":1618678115061}
1618678115.142591: {"feed":"book","product_id":"FI_XBTUSD_210625","side":"sell","seq":21455197,"price":64041.5,"qty":12916.0,"timestamp":1618678115061}
1618678115.142613: {"feed":"book","product_id":"FI_XBTUSD_210625","side":"sell","seq":21455198,"price":64118.5,"qty":0.0,"timestamp":1618678115061}
1618678115.142636: {"feed":"book","product_id":"FI_XBTUSD_210625","side":"sell","seq":21455199,"price":64098.0,"qty":25376.0,"timestamp":1618678115061}
1618678115.142657: {"feed":"book","product_id":"FI_XBTUSD_210625","side":"sell","seq":21455200,"price":64098.5,"qty":0.0,"timestamp":1618678115069}
1618678115.1426802: {"feed":"book","product_id":"FI_XBTUSD_210625","side":"buy","seq":21455201,"price":63727.0,"qty":0.0,"timestamp":1618678115069}
1618678115.142721: {"feed":"book","product_id":"FI_XBTUSD_210625","side":"buy","seq":21455202,"price":63896.5,"qty":1920.0,"timestamp":1618678115074}
1618678115.142744: {"feed":"book","product_id":"FI_XBTUSD_210625","side":"sell","seq":21455203,"price":63936.5,"qty":2000.0,"timestamp":1618678115075}
1618678115.142763: {"feed":"book","product_id":"FI_XBTUSD_210625","side":"buy","seq":21455204,"price":63753.0,"qty":3000.0,"timestamp":1618678115082}
1618678115.142784: {"feed":"book","product_id":"FI_XBTUSD_210625","side":"buy","seq":21455205,"price":63799.5,"qty":10000.0,"timestamp":1618678115088}
1618678115.1428201: {"feed":"book","product_id":"FI_XBTUSD_210625","side":"sell","seq":21455206,"price":63936.5,"qty":0.0,"timestamp":1618678115090}
1618678115.142844: {"feed":"book","product_id":"FI_XBTUSD_210625","side":"buy","seq":21455207,"price":63783.0,"qty":0.0,"timestamp":1618678115097}
1618678115.142866: {"feed":"book","product_id":"FI_XBTUSD_210625","side":"buy","seq":21455208,"price":63775.0,"qty":6000.0,"timestamp":1618678115097}
1618678115.14643: {"feed":"book","product_id":"FI_ETHUSD_210625","side":"buy","seq":12455641,"price":2471.65,"qty":0.0,"timestamp":1618678115061}
1618678115.146519: {"feed":"book","product_id":"FI_ETHUSD_210625","side":"buy","seq":12455642,"price":2483.05,"qty":0.0,"timestamp":1618678115061}
1618678115.146556: {"feed":"book","product_id":"FI_ETHUSD_210625","side":"sell","seq":12455643,"price":2504.05,"qty":0.0,"timestamp":1618678115061}
1618678115.1465878: {"feed":"book","product_id":"FI_ETHUSD_210625","side":"sell","seq":12455644,"price":2503.8,"qty":8031.0,"timestamp":1618678115061}
1618678115.1466398: {"feed":"book","product_id":"FI_ETHUSD_210625","side":"sell","seq":12455645,"price":2503.8,"qty":7196.0,"timestamp":1618678115075}
1618678115.1489038: {"feed":"book","product_id":"FI_ETHUSD_210625","side":"sell","seq":12455646,"price":2503.55,"qty":835.0,"timestamp":1618678115075}
1618678115.149: {"feed":"book","product_id":"FI_ETHUSD_210625","side":"sell","seq":12455647,"price":2506.1,"qty":0.0,"timestamp":1618678115080}
1618678115.149041: {"feed":"book","product_id":"FI_ETHUSD_210625","side":"buy","seq":12455648,"price":2494.5,"qty":3000.0,"timestamp":1618678115087}
1618678115.1490712: {"feed":"book","product_id":"FI_ETHUSD_210625","side":"buy","seq":12455649,"price":2483.6,"qty":8866.0,"timestamp":1618678115087}
1618678115.149097: {"feed":"book","product_id":"FI_ETHUSD_210625","side":"buy","seq":12455650,"price":2498.95,"qty":0.0,"timestamp":1618678115095}
1618678115.149125: {"feed":"book","product_id":"FI_ETHUSD_210625","side":"sell","seq":12455651,"price":2503.95,"qty":0.0,"timestamp":1618678115095}
1618678115.14915: {"feed":"book","product_id":"FI_ETHUSD_210625","side":"buy","seq":12455652,"price":2496.15,"qty":0.0,"timestamp":1618678115095}
1618678115.149174: {"feed":"book","product_id":"FI_ETHUSD_210625","side":"sell","seq":12455653,"price":2506.4,"qty":0.0,"timestamp":1618678115095}
1618678115.149198: {"feed":"book","product_id":"FI_BCHUSD_210625","side":"sell","seq":2240251,"price":1142.9,"qty":0.0,"timestamp":1618678115113}
1618678115.149224: {"feed":"book","product_id":"FI_BCHUSD_210625","side":"sell","seq":2240252,"price":1138.8,"qty":4513.0,"timestamp":1618678115113}
1618678115.149247: {"feed":"book","product_id":"FI_ETHUSD_210625","side":"buy","seq":12455654,"price":2493.35,"qty":0.0,"timestamp":1618678115095}
1618678115.149271: {"feed":"book","product_id":"FI_ETHUSD_210625","side":"sell","seq":12455655,"price":2508.9,"qty":0.0,"timestamp":1618678115095}
1618678115.1492941: {"feed":"book","product_id":"FI_ETHUSD_210625","side":"buy","seq":12455656,"price":2490.6,"qty":0.0,"timestamp":1618678115095}
1618678115.149317: {"feed":"book","product_id":"FI_ETHUSD_210625","side":"sell","seq":12455657,"price":2511.35,"qty":0.0,"timestamp":1618678115095}
1618678115.149339: {"feed":"book","product_id":"FI_ETHUSD_210625","side":"buy","seq":12455658,"price":2487.8,"qty":0.0,"timestamp":1618678115095}
1618678115.149361: {"feed":"book","product_id":"FI_ETHUSD_210924","side":"buy","seq":3859207,"price":2617.35,"qty":0.0,"timestamp":1618678115095}
1618678115.149385: {"feed":"book","product_id":"FI_ETHUSD_210924","side":"buy","seq":3859208,"price":2641.4,"qty":0.0,"timestamp":1618678115095}
1618678115.149408: {"feed":"book","product_id":"PI_BCHUSD","side":"sell","seq":16259017,"price":1063.0,"qty":0.0,"timestamp":1618678115102}
1618678115.1494348: {"feed":"book","product_id":"PI_BCHUSD","side":"buy","seq":16259018,"price":1058.0,"qty":0.0,"timestamp":1618678115102}
1618678115.14946: {"feed":"book","product_id":"PI_BCHUSD","side":"sell","seq":16259019,"price":1064.5,"qty":3618.0,"timestamp":1618678115102}
1618678115.1495192: {"feed":"book","product_id":"PI_BCHUSD","side":"sell","seq":16259020,"price":1063.9,"qty":31083.0,"timestamp":1618678115102}
1618678115.149548: {"feed":"book","product_id":"PI_BCHUSD","side":"buy","seq":16259021,"price":1058.2,"qty":3607.0,"timestamp":1618678115103}
1618678115.152276: {"feed":"book","product_id":"PI_BCHUSD","side":"sell","seq":16259022,"price":1063.3,"qty":27345.0,"timestamp":1618678115103}
1618678115.152402: {"feed":"book","product_id":"PI_BCHUSD","side":"sell","seq":16259023,"price":1064.9,"qty":0.0,"timestamp":1618678115104}
1618678115.1524649: {"feed":"book","product_id":"PI_BCHUSD","side":"sell","seq":16259024,"price":1062.9,"qty":29363.0,"timestamp":1618678115104}
1618678115.161381: {"feed":"book","product_id":"PI_BCHUSD","side":"buy","seq":16259025,"price":1057.0,"qty":14829.0,"timestamp":1618678115104}
1618678115.161491: {"feed":"book","product_id":"PI_BCHUSD","side":"sell","seq":16259026,"price":1063.1,"qty":3701.0,"timestamp":1618678115104}
1618678115.161556: {"feed":"book","product_id":"FI_XBTUSD_210924","side":"buy","seq":13850926,"price":67893.5,"qty":0.0,"timestamp":1618678115102}
1618678115.1616158: {"feed":"book","product_id":"PI_BCHUSD","side":"buy","seq":16259027,"price":1058.1,"qty":3748.0,"timestamp":1618678115107}
1618678115.161655: {"feed":"book","product_id":"FI_ETHUSD_210625","side":"sell","seq":12455659,"price":2513.85,"qty":0.0,"timestamp":1618678115095}
1618678115.16171: {"feed":"book","product_id":"FI_XBTUSD_210924","side":"sell","seq":13850927,"price":68290.5,"qty":0.0,"timestamp":1618678115107}
1618678115.161768: {"feed":"book","product_id":"FI_XBTUSD_210924","side":"sell","seq":13850928,"price":68292.5,"qty":10000.0,"timestamp":1618678115107}
1618678115.196617: {"feed":"book","product_id":"FI_BCHUSD_210430","side":"buy","seq":1411893,"price":1074.8,"qty":0.0,"timestamp":1618678115159}
1618678115.1967518: {"feed":"book","product_id":"FI_BCHUSD_210430","side":"sell","seq":1411894,"price":1079.0,"qty":0.0,"timestamp":1618678115159}
1618678115.196809: {"feed":"book","product_id":"FI_XBTUSD_210430","side":"buy","seq":12237600,"price":61101.5,"qty":0.0,"timestamp":1618678115159}
1618678115.196842: {"feed":"book","product_id":"FI_BCHUSD_210430","side":"buy","seq":1411895,"price":1072.0,"qty":0.0,"timestamp":1618678115159}
1618678115.1968682: {"feed":"book","product_id":"FI_BCHUSD_210430","side":"sell","seq":1411896,"price":1081.9,"qty":0.0,"timestamp":1618678115159}
1618678115.196892: {"feed":"book","product_id":"FI_XBTUSD_210430","side":"sell","seq":12237601,"price":61355.0,"qty":0.0,"timestamp":1618678115159}
1618678115.196919: {"feed":"book","product_id":"FI_XBTUSD_210430","side":"sell","seq":12237602,"price":61324.5,"qty":250001.0,"timestamp":1618678115159}
1618678115.196953: {"feed":"book","product_id":"FI_BCHUSD_210430","side":"buy","seq":1411897,"price":1069.3,"qty":0.0,"timestamp":1618678115159}
1618678115.196977: {"feed":"book","product_id":"FI_BCHUSD_210430","side":"sell","seq":1411898,"price":1084.8,"qty":0.0,"timestamp":1618678115159}
1618678115.197: {"feed":"book","product_id":"FI_XBTUSD_210924","side":"sell","seq":13850929,"price":68422.5,"qty":0.0,"timestamp":1618678115159}
1618678115.197025: {"feed":"book","product_id":"FI_XBTUSD_210924","side":"sell","seq":13850930,"price":68374.0,"qty":250001.0,"timestamp":1618678115159}
1618678115.19705: {"feed":"book","product_id":"FI_ETHUSD_210625","side":"sell","seq":12455660,"price":2511.3,"qty":0.0,"timestamp":1618678115159}
1618678115.197076: {"feed":"book","product_id":"FI_ETHUSD_210625","side":"sell","seq":12455661,"price":2511.65,"qty":303574.0,"timestamp":1618678115159}
1618678115.1971: {"feed":"book","product_id":"FI_ETHUSD_210430","side":"sell","seq":4780913,"price":2396.4,"qty":0.0,"timestamp":1618678115159}
1618678115.1971252: {"feed":"book","product_id":"FI_ETHUSD_210430","side":"sell","seq":4780914,"price":2395.8,"qty":225001.0,"timestamp":1618678115159}
1618678115.2043781: {"feed":"book","product_id":"FI_XBTUSD_210924","side":"buy","seq":13850931,"price":67964.0,"qty":0.0,"timestamp":1618678115159}
1618678115.2045062: {"feed":"book","product_id":"FI_XBTUSD_210924","side":"buy","seq":13850932,"price":67934.5,"qty":250002.0,"timestamp":1618678115159}
1618678115.214226: {"feed":"book","product_id":"FI_XBTUSD_210924","side":"sell","seq":13850933,"price":68507.5,"qty":0.0,"timestamp":1618678115159}
1618678115.214356: {"feed":"book","product_id":"FI_XBTUSD_210924","side":"sell","seq":13850934,"price":68474.0,"qty":355466.0,"timestamp":1618678115159}
1618678115.214418: {"feed":"book","product_id":"PI_BCHUSD","side":"buy","seq":16259028,"price":1057.1,"qty":0.0,"timestamp":1618678115158}
1618678115.2144692: {"feed":"book","product_id":"PI_BCHUSD","side":"buy","seq":16259029,"price":1057.2,"qty":32980.0,"timestamp":1618678115158}
1618678115.214506: {"feed":"book","product_id":"PI_BCHUSD","side":"sell","seq":16259030,"price":1062.3,"qty":15642.0,"timestamp":1618678115159}
1618678115.2145789: {"feed":"book","product_id":"FI_XBTUSD_210625","side":"sell","seq":21455209,"price":63936.5,"qty":1900.0,"timestamp":1618678115159}
1618678115.214624: {"feed":"book","product_id":"FI_XBTUSD_210924","side":"sell","seq":13850935,"price":68289.0,"qty":0.0,"timestamp":1618678115169}
1618678115.214666: {"feed":"book","product_id":"FI_XBTUSD_210924","side":"sell","seq":13850936,"price":68281.5,"qty":1680.0,"timestamp":1618678115169}
1618678115.224847: {"feed":"book","product_id":"PI_BCHUSD","side":"sell","seq":16259031,"price":1061.7,"qty":1151.0,"timestamp":1618678115167}
1618678115.224962: {"feed":"book","product_id":"PI_BCHUSD","side":"sell","seq":16259032,"price":1062.8,"qty":0.0,"timestamp":1618678115167}
1618678115.2250292: {"feed":"book","product_id":"PI_BCHUSD","side":"sell","seq":16259033,"price":1063.8,"qty":29313.0,"timestamp":1618678115167}
1618678115.2250628: {"feed":"book","product_id":"PI_BCHUSD","side":"buy","seq":16259034,"price":1058.1,"qty":0.0,"timestamp":1618678115167}
1618678115.2250938: {"feed":"book","product_id":"PI_BCHUSD","side":"buy","seq":16259035,"price":1056.7,"qty":3821.0,"timestamp":1618678115167}
1618678115.225121: {"feed":"book","product_id":"PI_BCHUSD","side":"sell","seq":16259036,"price":1065.6,"qty":0.0,"timestamp":1618678115169}
1618678115.225146: {"feed":"book","product_id":"PI_BCHUSD","side":"sell","seq":16259037,"price":1061.1,"qty":2644.0,"timestamp":1618678115171}
1618678115.225167: {"feed":"book","product_id":"PI_BCHUSD","side":"sell","seq":16259038,"price":1062.0,"qty":35634.0,"timestamp":1618678115172}
1618678115.225188: {"feed":"book","product_id":"FI_ETHUSD_210924","side":"buy","seq":3859209,"price":2641.85,"qty":0.0,"timestamp":1618678115167}
1618678115.225216: {"feed":"book","product_id":"FI_ETHUSD_210625","side":"sell","seq":12455662,"price":2506.15,"qty":0.0,"timestamp":1618678115167}
1618678115.2252421: {"feed":"book","product_id":"FI_ETHUSD_210625","side":"buy","seq":12455663,"price":2496.35,"qty":0.0,"timestamp":1618678115176}
1618678115.225268: {"feed":"book","product_id":"FI_XBTUSD_210625","side":"buy","seq":21455210,"price":63221.5,"qty":0.0,"timestamp":1618678115169}
1618678115.225319: {"feed":"book","product_id":"FI_XBTUSD_210924","side":"sell","seq":13850937,"price":68292.5,"qty":0.0,"timestamp":1618678115189}
1618678115.2253451: {"feed":"book","product_id":"FI_XBTUSD_210924","side":"sell","seq":13850938,"price":68264.5,"qty":10000.0,"timestamp":1618678115189}
1618678115.2253702: {"feed":"book","product_id":"PI_BCHUSD","side":"buy","seq":16259039,"price":1057.9,"qty":0.0,"timestamp":1618678115193}
1618678115.225395: {"feed":"book","product_id":"PI_BCHUSD","side":"buy","seq":16259040,"price":1058.2,"qty":0.0,"timestamp":1618678115194}
1618678115.225419: {"feed":"book","product_id":"FI_ETHUSD_210924","side":"sell","seq":3859210,"price":2659.2,"qty":50.0,"timestamp":1618678115193}
1618678115.225439: {"feed":"book","product_id":"PI_BCHUSD","side":"buy","seq":16259041,"price":1056.9,"qty":34773.0,"timestamp":1618678115195}
1618678115.232568: {"feed":"book","product_id":"PI_BCHUSD","side":"sell","seq":16259042,"price":1061.5,"qty":14118.0,"timestamp":1618678115202}
1618678115.240451: {"feed":"book","product_id":"PI_BCHUSD","side":"buy","seq":16259043,"price":1057.9,"qty":3639.0,"timestamp":1618678115205}
1618678115.265035: {"feed":"book","product_id":"FI_ETHUSD_210625","side":"sell","seq":12455664,"price":2504.4,"qty":0.0,"timestamp":1618678115237}
1618678115.265162: {"feed":"book","product_id":"FI_ETHUSD_210924","side":"buy","seq":3859211,"price":2635.95,"qty":19199.0,"timestamp":1618678115237}
1618678115.288747: {"feed":"book","product_id":"FI_ETHUSD_210625","side":"buy","seq":12455665,"price":2493.3,"qty":3000.0,"timestamp":1618678115256}
1618678115.306497: {"feed":"book","product_id":"PI_BCHUSD","side":"buy","seq":16259044,"price":1058.9,"qty":0.0,"timestamp":1618678115267}
1618678115.306624: {"feed":"book","product_id":"FI_ETHUSD_210625","side":"sell","seq":12455666,"price":2504.9,"qty":0.0,"timestamp":1618678115267}
1618678115.306685: {"feed":"book","product_id":"PI_BCHUSD","side":"buy","seq":16259045,"price":1059.3,"qty":0.0,"timestamp":1618678115267}
1618678115.306732: {"feed":"book","product_id":"FI_ETHUSD_210430","side":"buy","seq":4780915,"price":2350.4,"qty":0.0,"timestamp":1618678115270}
1618678115.316753: {"feed":"book","product_id":"FI_XBTUSD_210430","side":"buy","seq":12237603,"price":59445.5,"qty":52610.0,"timestamp":1618678115283}
1618678115.324533: {"feed":"book","product_id":"PI_BCHUSD","side":"buy","seq":16259046,"price":1055.9,"qty":3928.0,"timestamp":1618678115293}
1618678115.324657: {"feed":"book","product_id":"PI_BCHUSD","side":"buy","seq":16259047,"price":1057.6,"qty":0.0,"timestamp":1618678115293}
1618678115.3247192: {"feed":"book","product_id":"PI_BCHUSD","side":"sell","seq":16259048,"price":1061.4,"qty":4775.0,"timestamp":1618678115293}
1618678115.332445: {"feed":"book","product_id":"FI_XBTUSD_210924","side":"sell","seq":13850939,"price":68322.0,"qty":3000.0,"timestamp":1618678115299}
1618678115.332572: {"feed":"book","product_id":"FI_XBTUSD_210924","side":"buy","seq":13850940,"price":68038.0,"qty":3000.0,"timestamp":1618678115299}
1618678115.33263: {"feed":"book","product_id":"FI_XBTUSD_210924","side":"buy","seq":13850941,"price":67950.5,"qty":22293.0,"timestamp":1618678115299}
1618678115.337538: {"feed":"book","product_id":"FI_XBTUSD_210924","side":"buy","seq":13850942,"price":67775.0,"qty":22293.0,"timestamp":1618678115299}
1618678115.337713: {"feed":"book","product_id":"PI_BCHUSD","side":"buy","seq":16259049,"price":1059.6,"qty":0.0,"timestamp":1618678115299}
1618678115.3378098: {"feed":"book","product_id":"PI_BCHUSD","side":"sell","seq":16259050,"price":1060.8,"qty":2685.0,"timestamp":1618678115301}
1618678115.337881: {"feed":"book","product_id":"PI_BCHUSD","side":"sell","seq":16259051,"price":1063.4,"qty":0.0,"timestamp":1618678115306}
1618678115.33791: {"feed":"book","product_id":"PI_BCHUSD","side":"sell","seq":16259052,"price":1062.8,"qty":6070.0,"timestamp":1618678115306}
1618678115.337939: {"feed":"book","product_id":"FI_BCHUSD_210430","side":"buy","seq":1411899,"price":1073.6,"qty":26979.0,"timestamp":1618678115309}
1618678115.3416162: {"feed":"book","product_id":"FI_BCHUSD_210430","side":"sell","seq":1411900,"price":1077.9,"qty":31496.0,"timestamp":1618678115309}
1618678115.341674: {"feed":"book","product_id":"FI_BCHUSD_210430","side":"buy","seq":1411901,"price":1070.8,"qty":31476.0,"timestamp":1618678115309}
1618678115.341706: {"feed":"book","product_id":"FI_BCHUSD_210430","side":"sell","seq":1411902,"price":1080.8,"qty":51145.0,"timestamp":1618678115309}
1618678115.341731: {"feed":"book","product_id":"FI_BCHUSD_210430","side":"buy","seq":1411903,"price":1068.0,"qty":35972.0,"timestamp":1618678115309}
1618678115.341755: {"feed":"book","product_id":"FI_BCHUSD_210430","side":"sell","seq":1411904,"price":1083.7,"qty":41995.0,"timestamp":1618678115309}
1618678115.341779: {"feed":"book","product_id":"PI_BCHUSD","side":"buy","seq":16259053,"price":1057.2,"qty":26948.0,"timestamp":1618678115312}
1618678115.341802: {"feed":"book","product_id":"FI_XBTUSD_210625","side":"sell","seq":21455211,"price":64516.5,"qty":0.0,"timestamp":1618678115314}
1618678115.341834: {"feed":"book","product_id":"FI_XBTUSD_210625","side":"sell","seq":21455212,"price":64529.5,"qty":76444.0,"timestamp":1618678115314}
1618678115.343877: {"feed":"book","product_id":"PI_BCHUSD","side":"buy","seq":16259054,"price":1058.7,"qty":50.0,"timestamp":1618678115317}
1618678115.343934: {"feed":"book","product_id":"PI_BCHUSD","side":"sell","seq":16259055,"price":1061.1,"qty":2694.0,"timestamp":1618678115317}
1618678115.354951: {"feed":"book","product_id":"FI_ETHUSD_210625","side":"sell","seq":12455667,"price":2513.2,"qty":0.0,"timestamp":1618678115323}
1618678115.3550851: {"feed":"book","product_id":"FI_ETHUSD_210625","side":"sell","seq":12455668,"price":2511.65,"qty":335430.0,"timestamp":1618678115323}
1618678115.355139: {"feed":"book","product_id":"PI_BCHUSD","side":"sell","seq":16259056,"price":1062.8,"qty":0.0,"timestamp":1618678115324}
1618678115.35519: {"feed":"book","product_id":"PI_BCHUSD","side":"sell","seq":16259057,"price":1062.6,"qty":20469.0,"timestamp":1618678115324}
1618678115.355226: {"feed":"book","product_id":"PI_BCHUSD","side":"buy","seq":16259058,"price":1056.4,"qty":6028.0,"timestamp":1618678115326}
1618678115.3552709: {"feed":"book","product_id":"FI_ETHUSD_210625","side":"sell","seq":12455669,"price":2514.7,"qty":0.0,"timestamp":1618678115327}
1618678115.3553338: {"feed":"book","product_id":"FI_XBTUSD_210625","side":"buy","seq":21455213,"price":57321.5,"qty":0.0,"timestamp":1618678115329}
1618678115.371192: {"feed":"book","product_id":"FI_BCHUSD_210430","side":"sell","seq":1411905,"price":1078.5,"qty":0.0,"timestamp":1618678115334}
1618678115.3713: {"feed":"book","product_id":"FI_BCHUSD_210430","side":"sell","seq":1411906,"price":1077.8,"qty":50.0,"timestamp":1618678115334}
1618678115.371362: {"feed":"book","product_id":"FI_XRPUSD_210625","side":"sell","seq":3631609,"price":1.698,"qty":50.0,"timestamp":1618678115334}
1618678115.371414: {"feed":"book","product_id":"FI_XBTUSD_210924","side":"sell","seq":13850943,"price":68289.5,"qty":0.0,"timestamp":1618678115334}
1618678115.371445: {"feed":"book","product_id":"FI_XBTUSD_210924","side":"sell","seq":13850944,"price":68264.0,"qty":50.0,"timestamp":1618678115334}
1618678115.379811: {"feed":"book","product_id":"PI_BCHUSD","side":"sell","seq":16259059,"price":1062.6,"qty":14399.0,"timestamp":1618678115346}
1618678115.379852: {"feed":"book","product_id":"PI_BCHUSD","side":"sell","seq":16259060,"price":1061.6,"qty":8554.0,"timestamp":1618678115346}
1618678115.3798761: {"feed":"book","product_id":"FI_XBTUSD_210625","side":"sell","seq":21455214,"price":64082.0,"qty":34040.0,"timestamp":1618678115346}
1618678115.379904: {"feed":"book","product_id":"FI_XBTUSD_210430","side":"buy","seq":12237604,"price":61097.0,"qty":21604.0,"timestamp":1618678115346}
1618678115.379926: {"feed":"book","product_id":"FI_XBTUSD_210625","side":"buy","seq":21455215,"price":63710.5,"qty":129067.0,"timestamp":1618678115346}
1618678115.388951: {"feed":"book","product_id":"FI_XRPUSD_210625","side":"sell","seq":3631610,"price":1.6981,"qty":0.0,"timestamp":1618678115351}
1618678115.38899: {"feed":"book","product_id":"FI_XRPUSD_210625","side":"sell","seq":3631611,"price":1.6979,"qty":768.0,"timestamp":1618678115351}
1618678115.389018: {"feed":"book","product_id":"FI_XBTUSD_210924","side":"buy","seq":13850945,"price":67934.5,"qty":0.0,"timestamp":1618678115357}
1618678115.3890429: {"feed":"book","product_id":"FI_XBTUSD_210924","side":"buy","seq":13850946,"price":67951.0,"qty":250002.0,"timestamp":1618678115357}
1618678115.389065: {"feed":"book","product_id":"FI_ETHUSD_210625","side":"sell","seq":12455670,"price":2514.65,"qty":0.0,"timestamp":1618678115357}
1618678115.389088: {"feed":"book","product_id":"FI_ETHUSD_210625","side":"sell","seq":12455671,"price":2515.3,"qty":25003.0,"timestamp":1618678115357}
1618678115.395224: {"feed":"book","product_id":"PI_BCHUSD","side":"sell","seq":16259061,"price":1060.8,"qty":0.0,"timestamp":1618678115365}
1618678115.395314: {"feed":"book","product_id":"PI_BCHUSD","side":"sell","seq":16259062,"price":1063.0,"qty":6065.0,"timestamp":1618678115370}
1618678115.398099: {"feed":"book","product_id":"FI_ETHUSD_210625","side":"buy","seq":12455672,"price":2497.45,"qty":152788.0,"timestamp":1618678115371}
1618678115.4081862: {"feed":"book","product_id":"FI_XBTUSD_210625","side":"buy","seq":21455216,"price":57200.5,"qty":47889.0,"timestamp":1618678115372}
1618678115.408257: {"feed":"book","product_id":"FI_ETHUSD_210625","side":"sell","seq":12455673,"price":2502.45,"qty":133012.0,"timestamp":1618678115371}
1618678115.4083378: {"feed":"book","product_id":"FI_ETHUSD_210625","side":"buy","seq":12455674,"price":2494.9,"qty":199800.0,"timestamp":1618678115371}
1618678115.408368: {"feed":"book","product_id":"FI_ETHUSD_210625","side":"sell","seq":12455675,"price":2505.5,"qty":173938.0,"timestamp":1618678115371}
1618678115.408393: {"feed":"book","product_id":"FI_ETHUSD_210625","side":"buy","seq":12455676,"price":2492.4,"qty":235059.0,"timestamp":1618678115371}
1618678115.408417: {"feed":"book","product_id":"FI_ETHUSD_210625","side":"sell","seq":12455677,"price":2508.5,"qty":204633.0,"timestamp":1618678115371}
1618678115.408439: {"feed":"book","product_id":"FI_ETHUSD_210625","side":"buy","seq":12455678,"price":2489.85,"qty":293823.0,"timestamp":1618678115371}
1618678115.408462: {"feed":"book","product_id":"FI_ETHUSD_210625","side":"sell","seq":12455679,"price":2511.5,"qty":255791.0,"timestamp":1618678115371}
1618678115.4084852: {"feed":"book","product_id":"FI_ETHUSD_210625","side":"buy","seq":12455680,"price":2487.3,"qty":361441.0,"timestamp":1618678115371}
1618678115.4085052: {"feed":"book","product_id":"FI_ETHUSD_210625","side":"sell","seq":12455681,"price":2514.55,"qty":306950.0,"timestamp":1618678115371}
1618678115.4085279: {"feed":"book","product_id":"FI_ETHUSD_210625","side":"sell","seq":12455682,"price":2505.85,"qty":3000.0,"timestamp":1618678115371}
1618678115.4085498: {"feed":"book","product_id":"FI_ETHUSD_210625","side":"sell","seq":12455683,"price":2512.55,"qty":0.0,"timestamp":1618678115378}
1618678115.408579: {"feed":"book","product_id":"FI_ETHUSD_210625","side":"sell","seq":12455684,"price":2508.8,"qty":24940.0,"timestamp":1618678115378}
1618678115.408601: {"feed":"book","product_id":"FI_BCHUSD_210625","side":"sell","seq":2240253,"price":1138.8,"qty":0.0,"timestamp":1618678115381}
1618678115.408629: {"feed":"book","product_id":"FI_BCHUSD_210625","side":"sell","seq":2240254,"price":1142.9,"qty":4513.0,"timestamp":1618678115381}
1618678115.4227982: {"feed":"book","product_id":"FI_ETHUSD_210625","side":"sell","seq":12455685,"price":2503.55,"qty":0.0,"timestamp":1618678115381}
1618678115.422932: {"feed":"book","product_id":"FI_ETHUSD_210625","side":"sell","seq":12455686,"price":2502.4,"qty":835.0,"timestamp":1618678115381}
1618678115.422997: {"feed":"book","product_id":"FI_XRPUSD_210625","side":"buy","seq":3631612,"price":1.6934,"qty":50.0,"timestamp":1618678115383}
1618678115.423049: {"feed":"book","product_id":"FI_XRPUSD_210625","side":"buy","seq":3631613,"price":1.6926,"qty":68.0,"timestamp":1618678115383}
1618678115.4230971: {"feed":"book","product_id":"FI_BCHUSD_210625","side":"sell","seq":2240255,"price":1146.0,"qty":0.0,"timestamp":1618678115385}
1618678115.4231548: {"feed":"book","product_id":"FI_XRPUSD_210625","side":"sell","seq":3631614,"price":1.6982,"qty":0.0,"timestamp":1618678115386}
1618678115.4231849: {"feed":"book","product_id":"FI_XRPUSD_210625","side":"sell","seq":3631615,"price":1.6978,"qty":18968.0,"timestamp":1618678115386}
1618678115.423212: {"feed":"book","product_id":"FI_XRPUSD_210625","side":"buy","seq":3631616,"price":1.6917,"qty":0.0,"timestamp":1618678115386}
1618678115.423237: {"feed":"book","product_id":"FI_XRPUSD_210625","side":"buy","seq":3631617,"price":1.6909,"qty":19200.0,"timestamp":1618678115386}
1618678115.423261: {"feed":"book","product_id":"FI_ETHUSD_210625","side":"sell","seq":12455687,"price":2508.7,"qty":0.0,"timestamp":1618678115390}
1618678115.423286: {"feed":"book","product_id":"FI_XRPUSD_210625","side":"sell","seq":3631618,"price":1.698,"qty":0.0,"timestamp":1618678115391}
1618678115.423309: {"feed":"book","product_id":"FI_XRPUSD_210625","side":"sell","seq":3631619,"price":1.6978,"qty":19018.0,"timestamp":1618678115391}
1618678115.42333: {"feed":"book","product_id":"FI_XBTUSD_210430","side":"buy","seq":12237605,"price":60659.5,"qty":500.0,"timestamp":1618678115392}
1618678115.4233558: {"feed":"book","product_id":"FI_XBTUSD_210430","side":"sell","seq":12237606,"price":61941.0,"qty":500.0,"timestamp":1618678115392}
1618678115.44132: {"feed":"book","product_id":"FI_XRPUSD_210625","side":"sell","seq":3631620,"price":1.6979,"qty":0.0,"timestamp":1618678115395}
1618678115.4414122: {"feed":"book","product_id":"FI_XRPUSD_210625","side":"sell","seq":3631621,"price":1.6977,"qty":768.0,"timestamp":1618678115395}
1618678115.4414878: {"feed":"book","product_id":"PI_BCHUSD","side":"sell","seq":16259063,"price":1064.5,"qty":0.0,"timestamp":1618678115400}
1618678115.441521: {"feed":"book","product_id":"PI_BCHUSD","side":"sell","seq":16259064,"price":1062.3,"qty":5007.0,"timestamp":1618678115400}
1618678115.4415438: {"feed":"book","product_id":"PI_BCHUSD","side":"sell","seq":16259065,"price":1062.0,"qty":46269.0,"timestamp":1618678115400}
1618678115.4415638: {"feed":"book","product_id":"PI_BCHUSD","side":"sell","seq":16259066,"price":1063.1,"qty":7610.0,"timestamp":1618678115400}
1618678115.441584: {"feed":"book","product_id":"FI_ETHUSD_210430","side":"sell","seq":4780916,"price":2391.4,"qty":0.0,"timestamp":1618678115405}
1618678115.441611: {"feed":"book","product_id":"FI_ETHUSD_210625","side":"sell","seq":12455688,"price":2516.3,"qty":0.0,"timestamp":1618678115411}
1618678115.441637: {"feed":"book","product_id":"FI_ETHUSD_210625","side":"sell","seq":12455689,"price":2530.45,"qty":0.0,"timestamp":1618678115411}
1618678115.441661: {"feed":"book","product_id":"FI_ETHUSD_210625","side":"sell","seq":12455690,"price":2544.95,"qty":0.0,"timestamp":1618678115411}
1618678115.441684: {"feed":"book","product_id":"FI_ETHUSD_210625","side":"sell","seq":12455691,"price":2574.05,"qty":0.0,"timestamp":1618678115411}
1618678115.4480379: {"feed":"book","product_id":"FI_ETHUSD_210625","side":"buy","seq":12455692,"price":2490.2,"qty":0.0,"timestamp":1618678115411}
1618678115.4481852: {"feed":"book","product_id":"FI_ETHUSD_210625","side":"buy","seq":12455693,"price":2479.2,"qty":500.0,"timestamp":1618678115411}
1618678115.44822: {"feed":"book","product_id":"FI_ETHUSD_210625","side":"buy","seq":12455694,"price":2468.25,"qty":0.0,"timestamp":1618678115411}
1618678115.4482791: {"feed":"book","product_id":"FI_XRPUSD_210625","side":"sell","seq":3631622,"price":1.6978,"qty":18968.0,"timestamp":1618678115413}
1618678115.448305: {"feed":"book","product_id":"FI_XRPUSD_210625","side":"sell","seq":3631623,"price":1.6976,"qty":50.0,"timestamp":1618678115413}
1618678115.450839: {"feed":"book","product_id":"FI_ETHUSD_210625","side":"buy","seq":12455695,"price":2446.35,"qty":0.0,"timestamp":1618678115411}
1618678115.4509299: {"feed":"book","product_id":"FI_ETHUSD_210625","side":"buy","seq":12455696,"price":2413.45,"qty":0.0,"timestamp":1618678115411}
1618678115.454398: {"feed":"book","product_id":"FI_XRPUSD_210625","side":"sell","seq":3631624,"price":1.6977,"qty":0.0,"timestamp":1618678115425}
1618678115.4544609: {"feed":"book","product_id":"FI_XRPUSD_210625","side":"sell","seq":3631625,"price":1.6975,"qty":768.0,"timestamp":1618678115425}
1618678115.4594: {"feed":"book","product_id":"PI_BCHUSD","side":"buy","seq":16259067,"price":1057.7,"qty":5015.0,"timestamp":1618678115429}
1618678115.459523: {"feed":"book","product_id":"PI_BCHUSD","side":"buy","seq":16259068,"price":1058.1,"qty":5013.0,"timestamp":1618678115429}
1618678115.459578: {"feed":"book","product_id":"PI_BCHUSD","side":"sell","seq":16259069,"price":1062.4,"qty":4993.0,"timestamp":1618678115429}
1618678115.4596229: {"feed":"book","product_id":"PI_BCHUSD","side":"sell","seq":16259070,"price":1063.0,"qty":0.0,"timestamp":1618678115431}
1618678115.4596732: {"feed":"book","product_id":"PI_BCHUSD","side":"sell","seq":16259071,"price":1062.8,"qty":6065.0,"timestamp":1618678115431}
1618678115.464538: {"feed":"book","product_id":"FI_XBTUSD_210924","side":"buy","seq":13850947,"price":67881.5,"qty":3000.0,"timestamp":1618678115438}
1618678115.4802592: {"feed":"book","product_id":"FI_XRPUSD_210625","side":"sell","seq":3631626,"price":1.6976,"qty":0.0,"timestamp":1618678115444}
1618678115.4803488: {"feed":"book","product_id":"FI_XRPUSD_210625","side":"sell","seq":3631627,"price":1.6974,"qty":50.0,"timestamp":1618678115444}
1618678115.492702: {"feed":"book","product_id":"FI_XRPUSD_210625","side":"sell","seq":3631628,"price":1.6975,"qty":0.0,"timestamp":1618678115456}
1618678115.492791: {"feed":"book","product_id":"FI_XRPUSD_210625","side":"sell","seq":3631629,"price":1.6973,"qty":768.0,"timestamp":1618678115456}
1618678115.5110662: {"feed":"book","product_id":"FI_XBTUSD_210625","side":"buy","seq":21455217,"price":63753.0,"qty":0.0,"timestamp":1618678115478}
1618678115.511195: {"feed":"book","product_id":"PI_BCHUSD","side":"sell","seq":16259072,"price":1061.2,"qty":86.0,"timestamp":1618678115478}
1618678115.511262: {"feed":"book","product_id":"FI_ETHUSD_210625","side":"buy","seq":12455697,"price":2494.5,"qty":0.0,"timestamp":1618678115480}
1618678115.511317: {"feed":"book","product_id":"FI_ETHUSD_210625","side":"buy","seq":12455698,"price":2490.95,"qty":0.0,"timestamp":1618678115480}
1618678115.5113611: {"feed":"book","product_id":"FI_XBTUSD_210625","side":"sell","seq":21455218,"price":64395.0,"qty":20000.0,"timestamp":1618678115486}
1618678115.519768: {"feed":"book","product_id":"PI_BCHUSD","side":"buy","seq":16259073,"price":1057.9,"qty":7051.0,"timestamp":1618678115493}
1618678115.5198772: {"feed":"book","product_id":"PI_BCHUSD","side":"sell","seq":16259074,"price":1069.3,"qty":0.0,"timestamp":1618678115493}
1618678115.519946: {"feed":"book","product_id":"PI_BCHUSD","side":"buy","seq":16259075,"price":1057.9,"qty":10606.0,"timestamp":1618678115494}
1618678115.519986: {"feed":"book","product_id":"PI_BCHUSD","side":"sell","seq":16259076,"price":1061.6,"qty":12304.0,"timestamp":1618678115495}
1618678115.539368: {"feed":"book","product_id":"FI_ETHUSD_210625","side":"buy","seq":12455699,"price":2496.1,"qty":0.0,"timestamp":1618678115506}
1618678115.539496: {"feed":"book","product_id":"FI_ETHUSD_210625","side":"sell","seq":12455700,"price":2508.05,"qty":0.0,"timestamp":1618678115506}
1618678115.5395572: {"feed":"book","product_id":"FI_ETHUSD_210625","side":"sell","seq":12455701,"price":2511.7,"qty":0.0,"timestamp":1618678115506}
1618678115.539603: {"feed":"book","product_id":"FI_ETHUSD_210625","side":"sell","seq":12455702,"price":2515.35,"qty":0.0,"timestamp":1618678115506}
1618678115.558623: {"feed":"book","product_id":"FI_ETHUSD_210625","side":"sell","seq":12455703,"price":2506.35,"qty":0.0,"timestamp":1618678115528}
1618678115.55875: {"feed":"book","product_id":"FI_ETHUSD_210625","side":"sell","seq":12455704,"price":2507.95,"qty":19531.0,"timestamp":1618678115528}
1618678115.558827: {"feed":"book","product_id":"FI_ETHUSD_210625","side":"sell","seq":12455705,"price":2511.65,"qty":303574.0,"timestamp":1618678115528}
1618678115.558872: {"feed":"book","product_id":"FI_ETHUSD_210625","side":"sell","seq":12455706,"price":2513.2,"qty":34311.0,"timestamp":1618678115528}
1618678115.5589151: {"feed":"book","product_id":"FI_ETHUSD_210625","side":"buy","seq":12455707,"price":2496.2,"qty":0.0,"timestamp":1618678115528}
1618678115.558979: {"feed":"book","product_id":"FI_ETHUSD_210625","side":"buy","seq":12455708,"price":2495.15,"qty":464.0,"timestamp":1618678115528}
1618678115.55904: {"feed":"book","product_id":"FI_XBTUSD_210430","side":"buy","seq":12237607,"price":59445.5,"qty":52854.0,"timestamp":1618678115530}
1618678115.566529: {"feed":"book","product_id":"FI_XBTUSD_210924","side":"sell","seq":13850948,"price":68265.0,"qty":0.0,"timestamp":1618678115533}
1618678115.56659: {"feed":"book","product_id":"FI_XBTUSD_210625","side":"sell","seq":21455219,"price":64142.5,"qty":39930.0,"timestamp":1618678115533}
1618678115.5666292: {"feed":"book","product_id":"FI_XBTUSD_210625","side":"sell","seq":21455220,"price":64380.5,"qty":39930.0,"timestamp":1618678115533}
1618678115.566656: {"feed":"book","product_id":"FI_XBTUSD_210625","side":"sell","seq":21455221,"price":64641.5,"qty":39930.0,"timestamp":1618678115533}
1618678115.56668: {"feed":"book","product_id":"FI_XBTUSD_210625","side":"sell","seq":21455222,"price":65164.0,"qty":39930.0,"timestamp":1618678115534}
1618678115.566703: {"feed":"book","product_id":"FI_XBTUSD_210625","side":"buy","seq":21455223,"price":63629.0,"qty":39930.0,"timestamp":1618678115534}
1618678115.566727: {"feed":"book","product_id":"FI_XBTUSD_210625","side":"buy","seq":21455224,"price":63419.0,"qty":39930.0,"timestamp":1618678115534}
1618678115.566751: {"feed":"book","product_id":"FI_XBTUSD_210625","side":"buy","seq":21455225,"price":63202.5,"qty":39930.0,"timestamp":1618678115534}
1618678115.566773: {"feed":"book","product_id":"FI_XBTUSD_210625","side":"buy","seq":21455226,"price":62769.5,"qty":39930.0,"timestamp":1618678115534}
1618678115.566795: {"feed":"book","product_id":"FI_XBTUSD_210625","side":"buy","seq":21455227,"price":62119.5,"qty":39930.0,"timestamp":1618678115534}
1618678115.575888: {"feed":"book","product_id":"FI_XBTUSD_210625","side":"sell","seq":21455228,"price":64092.0,"qty":0.0,"timestamp":1618678115541}
1618678115.576021: {"feed":"book","product_id":"FI_XBTUSD_210625","side":"sell","seq":21455229,"price":64081.5,"qty":250001.0,"timestamp":1618678115541}
1618678115.576084: {"feed":"book","product_id":"FI_ETHUSD_210625","side":"sell","seq":12455709,"price":2508.0,"qty":19706.0,"timestamp":1618678115541}
1618678115.576127: {"feed":"book","product_id":"FI_ETHUSD_210625","side":"sell","seq":12455710,"price":2508.5,"qty":429634.0,"timestamp":1618678115541}
1618678115.57617: {"feed":"book","product_id":"FI_ETHUSD_210625","side":"sell","seq":12455711,"price":2511.65,"qty":0.0,"timestamp":1618678115541}
1618678115.576225: {"feed":"book","product_id":"FI_ETHUSD_210625","side":"sell","seq":12455712,"price":2511.45,"qty":303574.0,"timestamp":1618678115541}
1618678115.5762508: {"feed":"book","product_id":"FI_ETHUSD_210625","side":"sell","seq":12455713,"price":2515.3,"qty":0.0,"timestamp":1618678115541}
1618678115.576277: {"feed":"book","product_id":"FI_ETHUSD_210625","side":"sell","seq":12455714,"price":2514.5,"qty":25003.0,"timestamp":1618678115541}
1618678115.5859892: {"feed":"book","product_id":"FI_XBTUSD_210924","side":"sell","seq":13850949,"price":68264.5,"qty":0.0,"timestamp":1618678115545}
1618678115.5861208: {"feed":"book","product_id":"FI_XBTUSD_210924","side":"sell","seq":13850950,"price":68281.0,"qty":10000.0,"timestamp":1618678115545}
1618678115.586186: {"feed":"book","product_id":"PI_BCHUSD","side":"sell","seq":16259077,"price":1061.2,"qty":0.0,"timestamp":1618678115545}
1618678115.586238: {"feed":"book","product_id":"FI_BCHUSD_210625","side":"sell","seq":2240256,"price":1142.9,"qty":0.0,"timestamp":1618678115552}
1618678115.586281: {"feed":"book","product_id":"FI_BCHUSD_210625","side":"sell","seq":2240257,"price":1138.8,"qty":4513.0,"timestamp":1618678115552}
1618678115.59107: {"feed":"book","product_id":"PI_BCHUSD","side":"sell","seq":16259078,"price":1061.2,"qty":86.0,"timestamp":1618678115559}
1618678115.5912: {"feed":"book","product_id":"PI_BCHUSD","side":"sell","seq":16259079,"price":1061.2,"qty":0.0,"timestamp":1618678115562}
1618678115.593875: {"feed":"book","product_id":"PI_BCHUSD","side":"sell","seq":16259080,"price":1061.2,"qty":86.0,"timestamp":1618678115566}
1618678115.602377: {"feed":"book","product_id":"PI_BCHUSD","side":"sell","seq":16259081,"price":1062.1,"qty":26464.0,"timestamp":1618678115569}
1618678115.602505: {"feed":"book","product_id":"PI_BCHUSD","side":"sell","seq":16259082,"price":1062.3,"qty":8814.0,"timestamp":1618678115570}
1618678115.602554: {"feed":"book","product_id":"PI_BCHUSD","side":"sell","seq":16259083,"price":1061.1,"qty":2780.0,"timestamp":1618678115570}
1618678115.6194088: {"feed":"book","product_id":"PI_BCHUSD","side":"sell","seq":16259084,"price":1061.4,"qty":1341.0,"timestamp":1618678115589}
1618678115.619488: {"feed":"book","product_id":"FI_XBTUSD_210924","side":"buy","seq":13850951,"price":68095.5,"qty":5000.0,"timestamp":1618678115589}
1618678115.619536: {"feed":"book","product_id":"FI_XBTUSD_210924","side":"sell","seq":13850952,"price":68287.5,"qty":5000.0,"timestamp":1618678115589}
1618678115.6244612: {"feed":"book","product_id":"FI_XBTUSD_210924","side":"sell","seq":13850953,"price":68322.0,"qty":0.0,"timestamp":1618678115591}
1618678115.624612: {"feed":"book","product_id":"PI_BCHUSD","side":"sell","seq":16259085,"price":1061.1,"qty":136.0,"timestamp":1618678115594}
1618678115.624647: {"feed":"book","product_id":"PI_BCHUSD","side":"sell","seq":16259086,"price":1061.5,"qty":86.0,"timestamp":1618678115594}
1618678115.624672: {"feed":"book","product_id":"PI_BCHUSD","side":"sell","seq":16259087,"price":1061.6,"qty":8745.0,"timestamp":1618678115594}
1618678115.634421: {"feed":"book","product_id":"PI_BCHUSD","side":"sell","seq":16259088,"price":1062.0,"qty":35634.0,"timestamp":1618678115600}
1618678115.6344981: {"feed":"book","product_id":"FI_ETHUSD_210430","side":"sell","seq":4780917,"price":2389.55,"qty":24066.0,"timestamp":1618678115600}
1618678115.6345441: {"feed":"book","product_id":"PI_BCHUSD","side":"buy","seq":16259089,"price":1057.5,"qty":3836.0,"timestamp":1618678115605}
1618678115.6374662: {"feed":"book","product_id":"FI_XBTUSD_210625","side":"buy","seq":21455230,"price":57321.5,"qty":2497.0,"timestamp":1618678115606}
1618678115.637546: {"feed":"book","product_id":"PI_BCHUSD","side":"sell","seq":16259090,"price":1061.1,"qty":50.0,"timestamp":1618678115607}
1618678115.63759: {"feed":"book","product_id":"PI_BCHUSD","side":"sell","seq":16259091,"price":1061.2,"qty":0.0,"timestamp":1618678115607}
1618678115.63764: {"feed":"book","product_id":"PI_BCHUSD","side":"sell","seq":16259092,"price":1061.5,"qty":0.0,"timestamp":1618678115607}
1618678115.653148: {"feed":"book","product_id":"FI_ETHUSD_210924","side":"sell","seq":3859212,"price":2660.8,"qty":0.0,"timestamp":1618678115609}
1618678115.65328: {"feed":"book","product_id":"FI_XBTUSD_210924","side":"sell","seq":13850954,"price":68374.0,"qty":0.0,"timestamp":1618678115611}
1618678115.6533408: {"feed":"book","product_id":"FI_XBTUSD_210924","side":"sell","seq":13850955,"price":68422.5,"qty":250001.0,"timestamp":1618678115611}
1618678115.6534169: {"feed":"book","product_id":"FI_ETHUSD_210625","side":"sell","seq":12455715,"price":2508.5,"qty":204633.0,"timestamp":1618678115611}
1618678115.653443: {"feed":"book","product_id":"FI_ETHUSD_210625","side":"sell","seq":12455716,"price":2507.9,"qty":225001.0,"timestamp":1618678115611}
1618678115.6534688: {"feed":"book","product_id":"FI_XBTUSD_210430","side":"sell","seq":12237608,"price":61324.5,"qty":0.0,"timestamp":1618678115611}
1618678115.6534982: {"feed":"book","product_id":"FI_XBTUSD_210430","side":"sell","seq":12237609,"price":61355.0,"qty":250001.0,"timestamp":1618678115611}
1618678115.653522: {"feed":"book","product_id":"FI_XBTUSD_210924","side":"sell","seq":13850956,"price":68474.0,"qty":0.0,"timestamp":1618678115611}
1618678115.653547: {"feed":"book","product_id":"FI_XBTUSD_210924","side":"sell","seq":13850957,"price":68507.5,"qty":355466.0,"timestamp":1618678115611}
1618678115.653569: {"feed":"book","product_id":"PI_BCHUSD","side":"sell","seq":16259093,"price":1062.5,"qty":10625.0,"timestamp":1618678115616}
1618678115.653595: {"feed":"book","product_id":"FI_ETHUSD_210625","side":"sell","seq":12455717,"price":2505.85,"qty":0.0,"timestamp":1618678115616}
1618678115.67184: {"feed":"book","product_id":"PI_BCHUSD","side":"buy","seq":16259094,"price":1057.8,"qty":3788.0,"timestamp":1618678115632}
1618678115.6719701: {"feed":"book","product_id":"FI_XBTUSD_210430","side":"sell","seq":12237610,"price":61941.0,"qty":0.0,"timestamp":1618678115637}
1618678115.6720362: {"feed":"book","product_id":"FI_XBTUSD_210430","side":"buy","seq":12237611,"price":60659.5,"qty":0.0,"timestamp":1618678115637}
1618678115.6840909: {"feed":"book","product_id":"FI_ETHUSD_210924","side":"sell","seq":3859213,"price":2670.25,"qty":0.0,"timestamp":1618678115643}
1618678115.684224: {"feed":"book","product_id":"FI_ETHUSD_210924","side":"sell","seq":3859214,"price":2670.0,"qty":219.0,"timestamp":1618678115643}
1618678115.684287: {"feed":"book","product_id":"FI_ETHUSD_210625","side":"sell","seq":12455718,"price":2506.75,"qty":0.0,"timestamp":1618678115643}
1618678115.684339: {"feed":"book","product_id":"FI_ETHUSD_210625","side":"sell","seq":12455719,"price":2506.5,"qty":441.0,"timestamp":1618678115643}
1618678115.684382: {"feed":"book","product_id":"FI_XBTUSD_210625","side":"sell","seq":21455231,"price":64170.0,"qty":0.0,"timestamp":1618678115645}
1618678115.684439: {"feed":"book","product_id":"FI_XBTUSD_210625","side":"sell","seq":21455232,"price":64187.0,"qty":504470.0,"timestamp":1618678115645}
1618678115.7056792: {"feed":"book","product_id":"FI_XBTUSD_210625","side":"buy","seq":21455233,"price":63789.0,"qty":4500.0,"timestamp":1618678115664}
1618678115.705765: {"feed":"book","product_id":"FI_XBTUSD_210625","side":"buy","seq":21455234,"price":63154.5,"qty":15000.0,"timestamp":1618678115664}
1618678115.705816: {"feed":"book","product_id":"PI_BCHUSD","side":"sell","seq":16259095,"price":1061.6,"qty":3750.0,"timestamp":1618678115669}
1618678115.705856: {"feed":"book","product_id":"FI_XBTUSD_210924","side":"sell","seq":13850958,"price":68287.5,"qty":0.0,"timestamp":1618678115671}
1618678115.70593: {"feed":"book","product_id":"FI_XBTUSD_210625","side":"sell","seq":21455235,"price":64092.5,"qty":0.0,"timestamp":1618678115672}
1618678115.705958: {"feed":"book","product_id":"FI_XBTUSD_210625","side":"sell","seq":21455236,"price":64081.5,"qty":271037.0,"timestamp":1618678115672}
1618678115.7059798: {"feed":"book","product_id":"PI_BCHUSD","side":"sell","seq":16259096,"price":1061.1,"qty":2757.0,"timestamp":1618678115675}
1618678115.711597: {"feed":"book","product_id":"FI_XRPUSD_210625","side":"buy","seq":3631630,"price":1.6926,"qty":0.0,"timestamp":1618678115682}
1618678115.711688: {"feed":"book","product_id":"FI_XRPUSD_210625","side":"buy","seq":3631631,"price":1.693,"qty":68.0,"timestamp":1618678115682}
1618678115.7258382: {"feed":"book","product_id":"FI_ETHUSD_210625","side":"sell","seq":12455720,"price":2502.9,"qty":3000.0,"timestamp":1618678115693}
1618678115.725964: {"feed":"book","product_id":"FI_ETHUSD_210625","side":"sell","seq":12455721,"price":2506.55,"qty":61987.0,"timestamp":1618678115693}
1618678115.726021: {"feed":"book","product_id":"FI_ETHUSD_210625","side":"buy","seq":12455722,"price":2495.8,"qty":3000.0,"timestamp":1618678115693}
1618678115.726068: {"feed":"book","product_id":"FI_ETHUSD_210625","side":"sell","seq":12455723,"price":2510.2,"qty":61987.0,"timestamp":1618678115693}
1618678115.7261078: {"feed":"book","product_id":"FI_ETHUSD_210625","side":"sell","seq":12455724,"price":2513.85,"qty":61986.0,"timestamp":1618678115694}
1618678115.7458339: {"feed":"book","product_id":"PI_BCHUSD","side":"sell","seq":16259097,"price":1061.8,"qty":3560.0,"timestamp":1618678115713}
1618678115.765501: {"feed":"book","product_id":"FI_XBTUSD_210924","side":"sell","seq":13850959,"price":68281.0,"qty":33999.0,"timestamp":1618678115733}
1618678115.765611: {"feed":"book","product_id":"PI_BCHUSD","side":"sell","seq":16259098,"price":1062.3,"qty":5015.0,"timestamp":1618678115735}
1618678115.773246: {"feed":"book","product_id":"PI_BCHUSD","side":"sell","seq":16259099,"price":1061.0,"qty":2630.0,"timestamp":1618678115735}
1618678115.7733319: {"feed":"book","product_id":"FI_XBTUSD_210625","side":"buy","seq":21455237,"price":63762.5,"qty":3000.0,"timestamp":1618678115735}
1618678115.773389: {"feed":"book","product_id":"FI_ETHUSD_210625","side":"sell","seq":12455725,"price":2508.55,"qty":0.0,"timestamp":1618678115736}
1618678115.7734442: {"feed":"book","product_id":"FI_ETHUSD_210625","side":"sell","seq":12455726,"price":2512.2,"qty":0.0,"timestamp":1618678115736}
