1618678106.919737: {"feed":"book","product_id":"FI_XRPUSD_210625","side":"buy","seq":3631468,"price":1.6932,"qty":0.0,"timestamp":1618678106890}
1618678106.91981: {"feed":"book","product_id":"FI_XRPUSD_210625","side":"buy","seq":3631469,"price":1.6925,"qty":19200.0,"timestamp":1618678106890}
1618678106.926047: {"feed":"book","product_id":"FI_XBTUSD_210924","side":"sell","seq":13850732,"price":68312.0,"qty":0.0,"timestamp":1618678106896}
1618678106.9261389: {"feed":"book","product_id":"FI_XBTUSD_210924","side":"sell","seq":13850733,"price":68294.0,"qty":10000.0,"timestamp":1618678106896}
1618678106.931487: {"feed":"book","product_id":"PI_BCHUSD","side":"sell","seq":16258250,"price":1063.6,"qty":3013.0,"timestamp":1618678106898}
1618678106.9315991: {"feed":"book","product_id":"PI_BCHUSD","side":"sell","seq":16258251,"price":1063.7,"qty":27384.0,"timestamp":1618678106899}
1618678106.931649: {"feed":"book","product_id":"PI_BCHUSD","side":"sell","seq":16258252,"price":1064.1,"qty":10643.0,"timestamp":1618678106900}
1618678106.9316869: {"feed":"book","product_id":"PI_BCHUSD","side":"sell","seq":16258253,"price":1064.2,"qty":7800.0,"timestamp":1618678106900}
1618678106.931721: {"feed":"book","product_id":"PI_BCHUSD","side":"sell","seq":16258254,"price":1064.7,"qty":29188.0,"timestamp":1618678106902}
1618678106.9317539: {"feed":"book","product_id":"PI_BCHUSD","side":"buy","seq":16258255,"price":1060.7,"qty":3926.0,"timestamp":1618678106902}
1618678106.9390569: {"feed":"book","product_id":"PI_BCHUSD","side":"buy","seq":16258256,"price":1060.4,"qty":50.0,"timestamp":1618678106902}
1618678106.939171: {"feed":"book","product_id":"PI_BCHUSD","side":"sell","seq":16258257,"price":1063.5,"qty":3888.0,"timestamp":1618678106902}
1618678106.93922: {"feed":"book","product_id":"PI_BCHUSD","side":"sell","seq":16258258,"price":1062.8,"qty":3053.0,"timestamp":1618678106908}
1618678106.939258: {"feed":"book","product_id":"PI_BCHUSD","side":"buy","seq":16258259,"price":1060.4,"qty":3820.0,"timestamp":1618678106909}
1618678106.952825: {"feed":"book","product_id":"PI_BCHUSD","side":"buy","seq":16258260,"price":1060.4,"qty":7500.0,"timestamp":1618678106921}
1618678106.952937: {"feed":"book","product_id":"FI_XBTUSD_210625","side":"buy","seq":21454769,"price":57200.5,"qty":33155.0,"timestamp":1618678106923}
1618678106.955925: {"feed":"book","product_id":"FI_XBTUSD_210625","side":"buy","seq":21454770,"price":63800.0,"qty":0.0,"timestamp":1618678106925}
1618678106.956055: {"feed":"book","product_id":"FI_XBTUSD_210625","side":"buy","seq":21454771,"price":63775.0,"qty":250001.0,"timestamp":1618678106925}
1618678106.956119: {"feed":"book","product_id":"PI_BCHUSD","side":"sell","seq":16258261,"price":1064.3,"qty":3908.0,"timestamp":1618678106925}
1618678106.9561632: {"feed":"book","product_id":"PI_BCHUSD","side":"sell","seq":16258262,"price":1064.2,"qty":13873.0,"timestamp":1618678106925}
1618678106.965628: {"feed":"book","product_id":"FI_XRPUSD_210625","side":"buy","seq":3631470,"price":1.6825,"qty":0.0,"timestamp":1618678106939}
1618678106.965705: {"feed":"book","product_id":"FI_XRPUSD_210625","side":"buy","seq":3631471,"price":1.6884,"qty":2955.0,"timestamp":1618678106939}
1618678106.982881: {"feed":"book","product_id":"FI_ETHUSD_210625","side":"buy","seq":12455297,"price":2484.85,"qty":0.0,"timestamp":1618678106941}
1618678106.9830122: {"feed":"book","product_id":"FI_ETHUSD_210625","side":"buy","seq":12455298,"price":2497.15,"qty":0.0,"timestamp":1618678106941}
1618678106.999711: {"feed":"book","product_id":"FI_XBTUSD_210625","side":"buy","seq":21454772,"price":63871.0,"qty":0.0,"timestamp":1618678106961}
1618678106.9998431: {"feed":"book","product_id":"FI_ETHUSD_210430","side":"buy","seq":4780765,"price":2388.05,"qty":0.0,"timestamp":1618678106960}
1618678106.999904: {"feed":"book","product_id":"FI_ETHUSD_210430","side":"sell","seq":4780766,"price":2391.8,"qty":0.0,"timestamp":1618678106960}
1618678106.9999518: {"feed":"book","product_id":"FI_ETHUSD_210430","side":"buy","seq":4780767,"price":2386.05,"qty":0.0,"timestamp":1618678106960}
1618678106.999993: {"feed":"book","product_id":"FI_ETHUSD_210430","side":"sell","seq":4780768,"price":2393.85,"qty":0.0,"timestamp":1618678106960}
1618678107.000031: {"feed":"book","product_id":"FI_ETHUSD_210430","side":"buy","seq":4780769,"price":2384.05,"qty":0.0,"timestamp":1618678106960}
1618678107.000076: {"feed":"book","product_id":"FI_ETHUSD_210430","side":"sell","seq":4780770,"price":2395.85,"qty":0.0,"timestamp":1618678106960}
1618678107.000125: {"feed":"book","product_id":"FI_ETHUSD_210430","side":"buy","seq":4780771,"price":2382.1,"qty":0.0,"timestamp":1618678106960}
1618678107.0001512: {"feed":"book","product_id":"FI_ETHUSD_210430","side":"sell","seq":4780772,"price":2397.9,"qty":0.0,"timestamp":1618678106960}
1618678107.000174: {"feed":"book","product_id":"FI_ETHUSD_210430","side":"buy","seq":4780773,"price":2380.1,"qty":0.0,"timestamp":1618678106960}
1618678107.000196: {"feed":"book","product_id":"FI_ETHUSD_210430","side":"sell","seq":4780774,"price":2399.9,"qty":0.0,"timestamp":1618678106960}
1618678107.00614: {"feed":"book","product_id":"FI_XBTUSD_210430","side":"buy","seq":12237441,"price":61168.5,"qty":0.0,"timestamp":1618678106961}
1618678107.006271: {"feed":"book","product_id":"FI_XBTUSD_210430","side":"buy","seq":12237442,"price":61156.0,"qty":0.0,"timestamp":1618678106961}
1618678107.01136: {"feed":"book","product_id":"PI_BCHUSD","side":"sell","seq":16258263,"price":1063.0,"qty":5638.0,"timestamp":1618678106969}
1618678107.025772: {"feed":"book","product_id":"FI_XBTUSD_210625","side":"buy","seq":21454773,"price":63906.0,"qty":0.0,"timestamp":1618678106975}
1618678107.025865: {"feed":"book","product_id":"FI_XBTUSD_210625","side":"sell","seq":21454774,"price":63995.5,"qty":0.0,"timestamp":1618678106975}
1618678107.025902: {"feed":"book","product_id":"FI_XBTUSD_210625","side":"buy","seq":21454775,"price":63852.5,"qty":0.0,"timestamp":1618678106975}
1618678107.025933: {"feed":"book","product_id":"FI_XBTUSD_210625","side":"sell","seq":21454776,"price":64047.0,"qty":0.0,"timestamp":1618678106975}
1618678107.025959: {"feed":"book","product_id":"FI_XBTUSD_210625","side":"buy","seq":21454777,"price":63799.5,"qty":0.0,"timestamp":1618678106975}
1618678107.025984: {"feed":"book","product_id":"FI_XBTUSD_210625","side":"sell","seq":21454778,"price":64099.0,"qty":0.0,"timestamp":1618678106975}
1618678107.026007: {"feed":"book","product_id":"FI_XBTUSD_210625","side":"buy","seq":21454779,"price":63746.0,"qty":0.0,"timestamp":1618678106975}
1618678107.02603: {"feed":"book","product_id":"FI_XBTUSD_210625","side":"sell","seq":21454780,"price":64150.5,"qty":0.0,"timestamp":1618678106975}
1618678107.026054: {"feed":"book","product_id":"FI_XBTUSD_210625","side":"buy","seq":21454781,"price":63692.5,"qty":0.0,"timestamp":1618678106975}
1618678107.026077: {"feed":"book","product_id":"FI_XBTUSD_210625","side":"sell","seq":21454782,"price":64202.5,"qty":0.0,"timestamp":1618678106975}
1618678107.0261: {"feed":"book","product_id":"FI_XBTUSD_210625","side":"buy","seq":21454783,"price":63639.5,"qty":0.0,"timestamp":1618678106975}
1618678107.026124: {"feed":"book","product_id":"FI_XBTUSD_210625","side":"sell","seq":21454784,"price":64254.5,"qty":0.0,"timestamp":1618678106975}
1618678107.026146: {"feed":"book","product_id":"FI_XBTUSD_210924","side":"buy","seq":13850734,"price":68191.0,"qty":0.0,"timestamp":1618678106975}
1618678107.02617: {"feed":"book","product_id":"FI_XBTUSD_210924","side":"sell","seq":13850735,"price":68331.5,"qty":0.0,"timestamp":1618678106975}
1618678107.026195: {"feed":"book","product_id":"FI_XBTUSD_210924","side":"buy","seq":13850736,"price":68106.5,"qty":0.0,"timestamp":1618678106975}
1618678107.026217: {"feed":"book","product_id":"FI_XBTUSD_210924","side":"sell","seq":13850737,"price":68411.0,"qty":0.0,"timestamp":1618678106975}
1618678107.026239: {"feed":"book","product_id":"FI_XBTUSD_210924","side":"buy","seq":13850738,"price":68022.0,"qty":0.0,"timestamp":1618678106975}
1618678107.026261: {"feed":"book","product_id":"FI_XBTUSD_210924","side":"sell","seq":13850739,"price":68490.5,"qty":0.0,"timestamp":1618678106975}
1618678107.026284: {"feed":"book","product_id":"FI_XBTUSD_210924","side":"buy","seq":13850740,"price":67938.0,"qty":0.0,"timestamp":1618678106975}
1618678107.0263062: {"feed":"book","product_id":"FI_XBTUSD_210924","side":"sell","seq":13850741,"price":68570.0,"qty":0.0,"timestamp":1618678106975}
1618678107.026329: {"feed":"book","product_id":"FI_XBTUSD_210924","side":"buy","seq":13850742,"price":67853.5,"qty":0.0,"timestamp":1618678106975}
1618678107.02635: {"feed":"book","product_id":"FI_XBTUSD_210924","side":"sell","seq":13850743,"price":68649.5,"qty":0.0,"timestamp":1618678106975}
1618678107.0263722: {"feed":"book","product_id":"FI_XBTUSD_210924","side":"buy","seq":13850744,"price":67769.5,"qty":0.0,"timestamp":1618678106975}
1618678107.0263941: {"feed":"book","product_id":"FI_XBTUSD_210924","side":"sell","seq":13850745,"price":68729.5,"qty":0.0,"timestamp":1618678106975}
1618678107.026416: {"feed":"book","product_id":"FI_XBTUSD_210924","side":"sell","seq":13850746,"price":68507.5,"qty":0.0,"timestamp":1618678106984}
1618678107.026438: {"feed":"book","product_id":"FI_XBTUSD_210924","side":"sell","seq":13850747,"price":68490.0,"qty":355466.0,"timestamp":1618678106984}
1618678107.026467: {"feed":"book","product_id":"FI_XBTUSD_210924","side":"sell","seq":13850748,"price":68612.5,"qty":0.0,"timestamp":1618678106984}
1618678107.0264902: {"feed":"book","product_id":"FI_XBTUSD_210924","side":"sell","seq":13850749,"price":68569.5,"qty":125003.0,"timestamp":1618678106984}
1618678107.0265129: {"feed":"book","product_id":"FI_XBTUSD_210924","side":"sell","seq":13850750,"price":68316.0,"qty":0.0,"timestamp":1618678106991}
1618678107.026537: {"feed":"book","product_id":"FI_XBTUSD_210924","side":"sell","seq":13850751,"price":68307.0,"qty":1680.0,"timestamp":1618678106991}
1618678107.02656: {"feed":"book","product_id":"FI_XBTUSD_210625","side":"sell","seq":21454785,"price":64202.0,"qty":0.0,"timestamp":1618678106984}
1618678107.026583: {"feed":"book","product_id":"FI_XBTUSD_210625","side":"sell","seq":21454786,"price":64192.5,"qty":504470.0,"timestamp":1618678106984}
1618678107.039756: {"feed":"book","product_id":"FI_XBTUSD_210430","side":"sell","seq":12237443,"price":61393.0,"qty":0.0,"timestamp":1618678106984}
1618678107.039844: {"feed":"book","product_id":"FI_XBTUSD_210430","side":"sell","seq":12237444,"price":61346.5,"qty":250001.0,"timestamp":1618678106984}
1618678107.039884: {"feed":"book","product_id":"FI_XBTUSD_210625","side":"sell","seq":21454787,"price":64313.5,"qty":0.0,"timestamp":1618678106984}
1618678107.0399182: {"feed":"book","product_id":"FI_XBTUSD_210625","side":"sell","seq":21454788,"price":64260.0,"qty":125003.0,"timestamp":1618678106984}
1618678107.039945: {"feed":"book","product_id":"FI_XBTUSD_210625","side":"buy","seq":21454789,"price":63852.0,"qty":0.0,"timestamp":1618678106986}
1618678107.039974: {"feed":"book","product_id":"FI_XBTUSD_210625","side":"buy","seq":21454790,"price":63799.0,"qty":10000.0,"timestamp":1618678106986}
1618678107.039999: {"feed":"book","product_id":"PI_BCHUSD","side":"buy","seq":16258264,"price":1059.3,"qty":68292.0,"timestamp":1618678106988}
1618678107.040023: {"feed":"book","product_id":"FI_XBTUSD_210625","side":"sell","seq":21454791,"price":64000.5,"qty":0.0,"timestamp":1618678106989}
1618678107.0400488: {"feed":"book","product_id":"FI_XBTUSD_210625","side":"sell","seq":21454792,"price":63988.0,"qty":1920.0,"timestamp":1618678106989}
1618678107.040072: {"feed":"book","product_id":"PI_BCHUSD","side":"sell","seq":16258265,"price":1062.8,"qty":3003.0,"timestamp":1618678106988}
1618678107.040094: {"feed":"book","product_id":"FI_XBTUSD_210625","side":"sell","seq":21454793,"price":64036.0,"qty":0.0,"timestamp":1618678106992}
1618678107.040117: {"feed":"book","product_id":"FI_XBTUSD_210625","side":"sell","seq":21454794,"price":64022.0,"qty":48000.0,"timestamp":1618678106992}
1618678107.04014: {"feed":"book","product_id":"FI_XBTUSD_210625","side":"buy","seq":21454795,"price":63917.0,"qty":0.0,"timestamp":1618678106992}
1618678107.040164: {"feed":"book","product_id":"FI_XBTUSD_210625","side":"buy","seq":21454796,"price":63904.0,"qty":48000.0,"timestamp":1618678106992}
1618678107.040187: {"feed":"book","product_id":"FI_XBTUSD_210430","side":"buy","seq":12237445,"price":61172.0,"qty":0.0,"timestamp":1618678106997}
1618678107.040211: {"feed":"book","product_id":"FI_XBTUSD_210430","side":"buy","seq":12237446,"price":61161.0,"qty":51000.0,"timestamp":1618678106997}
1618678107.040233: {"feed":"book","product_id":"PI_BCHUSD","side":"buy","seq":16258266,"price":1060.2,"qty":7552.0,"timestamp":1618678106993}
1618678107.040253: {"feed":"book","product_id":"PI_BCHUSD","side":"buy","seq":16258267,"price":1060.1,"qty":8821.0,"timestamp":1618678106994}
1618678107.0402718: {"feed":"book","product_id":"PI_BCHUSD","side":"sell","seq":16258268,"price":1064.6,"qty":0.0,"timestamp":1618678106994}
1618678107.0402958: {"feed":"book","product_id":"PI_BCHUSD","side":"buy","seq":16258269,"price":1060.3,"qty":28806.0,"timestamp":1618678106994}
1618678107.0403159: {"feed":"book","product_id":"FI_ETHUSD_210625","side":"sell","seq":12455299,"price":2513.4,"qty":0.0,"timestamp":1618678106984}
1618678107.040341: {"feed":"book","product_id":"FI_ETHUSD_210625","side":"sell","seq":12455300,"price":2512.5,"qty":303574.0,"timestamp":1618678106984}
1618678107.040364: {"feed":"book","product_id":"FI_ETHUSD_210625","side":"sell","seq":12455301,"price":2516.25,"qty":0.0,"timestamp":1618678106984}
1618678107.040388: {"feed":"book","product_id":"FI_ETHUSD_210625","side":"sell","seq":12455302,"price":2515.9,"qty":25003.0,"timestamp":1618678106984}
1618678107.04041: {"feed":"book","product_id":"FI_XBTUSD_210625","side":"buy","seq":21454797,"price":63799.0,"qty":0.0,"timestamp":1618678106999}
1618678107.040433: {"feed":"book","product_id":"FI_XBTUSD_210625","side":"buy","seq":21454798,"price":63774.5,"qty":35068.0,"timestamp":1618678106999}
1618678107.040454: {"feed":"book","product_id":"FI_XBTUSD_210924","side":"sell","seq":13850752,"price":68410.5,"qty":0.0,"timestamp":1618678106999}
1618678107.040478: {"feed":"book","product_id":"FI_XBTUSD_210924","side":"sell","seq":13850753,"price":68436.5,"qty":250001.0,"timestamp":1618678106999}
1618678107.0405009: {"feed":"book","product_id":"FI_XBTUSD_210924","side":"sell","seq":13850754,"price":68490.0,"qty":0.0,"timestamp":1618678106999}
1618678107.040523: {"feed":"book","product_id":"FI_XBTUSD_210924","side":"sell","seq":13850755,"price":68507.5,"qty":355466.0,"timestamp":1618678106999}
1618678107.040545: {"feed":"book","product_id":"FI_XBTUSD_210924","side":"sell","seq":13850756,"price":68569.5,"qty":0.0,"timestamp":1618678106999}
1618678107.040568: {"feed":"book","product_id":"FI_XBTUSD_210924","side":"sell","seq":13850757,"price":68580.0,"qty":125003.0,"timestamp":1618678106999}
1618678107.04059: {"feed":"book","product_id":"FI_XBTUSD_210924","side":"sell","seq":13850758,"price":68365.5,"qty":0.0,"timestamp":1618678106999}
1618678107.040612: {"feed":"book","product_id":"FI_XBTUSD_210924","side":"sell","seq":13850759,"price":68349.5,"qty":42000.0,"timestamp":1618678106999}
1618678107.04066: {"feed":"book","product_id":"PI_BCHUSD","side":"buy","seq":16258270,"price":1060.7,"qty":0.0,"timestamp":1618678106999}
1618678107.0447218: {"feed":"book","product_id":"FI_XBTUSD_210625","side":"buy","seq":21454799,"price":57200.5,"qty":30165.0,"timestamp":1618678107007}
1618678107.044832: {"feed":"book","product_id":"FI_XRPUSD_210625","side":"buy","seq":3631472,"price":1.692,"qty":0.0,"timestamp":1618678107002}
1618678107.044982: {"feed":"book","product_id":"FI_XBTUSD_210924","side":"sell","seq":13850760,"price":68296.0,"qty":0.0,"timestamp":1618678107004}
1618678107.045033: {"feed":"book","product_id":"FI_XBTUSD_210924","side":"sell","seq":13850761,"price":68293.5,"qty":50.0,"timestamp":1618678107004}
1618678107.0532658: {"feed":"book","product_id":"PI_BCHUSD","side":"sell","seq":16258271,"price":1062.7,"qty":2821.0,"timestamp":1618678107007}
1618678107.0533912: {"feed":"book","product_id":"FI_ETHUSD_210924","side":"buy","seq":3859104,"price":2643.5,"qty":0.0,"timestamp":1618678107019}
1618678107.053459: {"feed":"book","product_id":"FI_BCHUSD_210430","side":"sell","seq":1411846,"price":1079.9,"qty":8106.0,"timestamp":1618678107019}
1618678107.053507: {"feed":"book","product_id":"FI_XBTUSD_210625","side":"buy","seq":21454800,"price":63785.0,"qty":0.0,"timestamp":1618678107021}
1618678107.0535538: {"feed":"book","product_id":"FI_XBTUSD_210625","side":"buy","seq":21454801,"price":63596.0,"qty":0.0,"timestamp":1618678107021}
1618678107.059053: {"feed":"book","product_id":"PI_BCHUSD","side":"sell","seq":16258272,"price":1064.0,"qty":0.0,"timestamp":1618678107024}
1618678107.0591412: {"feed":"book","product_id":"PI_BCHUSD","side":"sell","seq":16258273,"price":1064.4,"qty":19411.0,"timestamp":1618678107025}
1618678107.0591738: {"feed":"book","product_id":"PI_BCHUSD","side":"sell","seq":16258274,"price":1064.8,"qty":0.0,"timestamp":1618678107025}
1618678107.059231: {"feed":"book","product_id":"PI_BCHUSD","side":"sell","seq":16258275,"price":1062.7,"qty":0.0,"timestamp":1618678107026}
1618678107.0830002: {"feed":"book","product_id":"FI_ETHUSD_210625","side":"buy","seq":12455303,"price":2500.85,"qty":227.0,"timestamp":1618678107049}
1618678107.083112: {"feed":"book","product_id":"FI_ETHUSD_210625","side":"buy","seq":12455304,"price":2497.65,"qty":757.0,"timestamp":1618678107049}
1618678107.0886772: {"feed":"book","product_id":"FI_ETHUSD_210625","side":"buy","seq":12455305,"price":2485.5,"qty":0.0,"timestamp":1618678107049}
1618678107.0888052: {"feed":"book","product_id":"FI_ETHUSD_210625","side":"buy","seq":12455306,"price":2477.25,"qty":909.0,"timestamp":1618678107049}
1618678107.0888672: {"feed":"book","product_id":"FI_ETHUSD_210625","side":"sell","seq":12455307,"price":2508.05,"qty":16352.0,"timestamp":1618678107049}
1618678107.088908: {"feed":"book","product_id":"FI_ETHUSD_210625","side":"sell","seq":12455308,"price":2505.35,"qty":11563.0,"timestamp":1618678107049}
1618678107.08895: {"feed":"book","product_id":"FI_ETHUSD_210625","side":"sell","seq":12455309,"price":2530.2,"qty":0.0,"timestamp":1618678107049}
1618678107.088992: {"feed":"book","product_id":"FI_ETHUSD_210625","side":"sell","seq":12455310,"price":2521.05,"qty":47785.0,"timestamp":1618678107049}
1618678107.089055: {"feed":"book","product_id":"FI_XBTUSD_210625","side":"buy","seq":21454802,"price":57200.5,"qty":33185.0,"timestamp":1618678107053}
1618678107.108038: {"feed":"book","product_id":"FI_ETHUSD_210625","side":"buy","seq":12455311,"price":2489.1,"qty":0.0,"timestamp":1618678107063}
1618678107.108166: {"feed":"book","product_id":"PI_BCHUSD","side":"sell","seq":16258276,"price":1064.2,"qty":7800.0,"timestamp":1618678107071}
1618678107.108222: {"feed":"book","product_id":"PI_BCHUSD","side":"sell","seq":16258277,"price":1064.1,"qty":16716.0,"timestamp":1618678107071}
1618678107.124177: {"feed":"book","product_id":"FI_XBTUSD_210625","side":"buy","seq":21454803,"price":63858.0,"qty":0.0,"timestamp":1618678107091}
1618678107.124306: {"feed":"book","product_id":"FI_XBTUSD_210430","side":"buy","seq":12237447,"price":61140.0,"qty":0.0,"timestamp":1618678107096}
1618678107.1243641: {"feed":"book","product_id":"PI_BCHUSD","side":"sell","seq":16258278,"price":1063.1,"qty":3827.0,"timestamp":1618678107096}
1618678107.124418: {"feed":"book","product_id":"PI_BCHUSD","side":"buy","seq":16258279,"price":1060.1,"qty":5007.0,"timestamp":1618678107096}
1618678107.132551: {"feed":"book","product_id":"PI_BCHUSD","side":"sell","seq":16258280,"price":1063.5,"qty":0.0,"timestamp":1618678107102}
1618678107.1506188: {"feed":"book","product_id":"FI_ETHUSD_210430","side":"buy","seq":4780775,"price":2388.6,"qty":0.0,"timestamp":1618678107102}
1618678107.15068: {"feed":"book","product_id":"FI_ETHUSD_210430","side":"buy","seq":4780776,"price":2388.15,"qty":1020.0,"timestamp":1618678107102}
1618678107.150717: {"feed":"book","product_id":"PI_BCHUSD","side":"buy","seq":16258281,"price":1059.3,"qty":72150.0,"timestamp":1618678107102}
1618678107.150743: {"feed":"book","product_id":"FI_ETHUSD_210625","side":"buy","seq":12455312,"price":2502.2,"qty":0.0,"timestamp":1618678107102}
1618678107.150773: {"feed":"book","product_id":"FI_ETHUSD_210625","side":"buy","seq":12455313,"price":2501.75,"qty":860.0,"timestamp":1618678107102}
1618678107.150798: {"feed":"book","product_id":"FI_ETHUSD_210625","side":"buy","seq":12455314,"price":2500.8,"qty":0.0,"timestamp":1618678107106}
1618678107.150822: {"feed":"book","product_id":"FI_ETHUSD_210625","side":"buy","seq":12455315,"price":2500.3,"qty":164056.0,"timestamp":1618678107106}
1618678107.150843: {"feed":"book","product_id":"FI_ETHUSD_210625","side":"buy","seq":12455316,"price":2488.55,"qty":0.0,"timestamp":1618678107106}
1618678107.150867: {"feed":"book","product_id":"FI_ETHUSD_210625","side":"buy","seq":12455317,"price":2486.45,"qty":192000.0,"timestamp":1618678107106}
1618678107.150891: {"feed":"book","product_id":"FI_ETHUSD_210625","side":"sell","seq":12455318,"price":2521.1,"qty":0.0,"timestamp":1618678107106}
1618678107.150916: {"feed":"book","product_id":"FI_ETHUSD_210625","side":"sell","seq":12455319,"price":2518.95,"qty":192000.0,"timestamp":1618678107106}
1618678107.15094: {"feed":"book","product_id":"FI_ETHUSD_210430","side":"buy","seq":4780777,"price":2377.75,"qty":0.0,"timestamp":1618678107103}
1618678107.150964: {"feed":"book","product_id":"FI_ETHUSD_210430","side":"buy","seq":4780778,"price":2375.95,"qty":204000.0,"timestamp":1618678107103}
1618678107.150987: {"feed":"book","product_id":"FI_ETHUSD_210430","side":"buy","seq":4780779,"price":2384.2,"qty":0.0,"timestamp":1618678107103}
1618678107.151009: {"feed":"book","product_id":"FI_ETHUSD_210430","side":"buy","seq":4780780,"price":2383.35,"qty":51000.0,"timestamp":1618678107103}
1618678107.151058: {"feed":"book","product_id":"FI_ETHUSD_210430","side":"sell","seq":4780781,"price":2391.25,"qty":0.0,"timestamp":1618678107103}
1618678107.151084: {"feed":"book","product_id":"FI_ETHUSD_210430","side":"sell","seq":4780782,"price":2390.9,"qty":25500.0,"timestamp":1618678107103}
1618678107.151107: {"feed":"book","product_id":"PI_BCHUSD","side":"buy","seq":16258282,"price":1060.2,"qty":3769.0,"timestamp":1618678107103}
1618678107.151128: {"feed":"book","product_id":"PI_BCHUSD","side":"sell","seq":16258283,"price":1063.6,"qty":6655.0,"timestamp":1618678107103}
1618678107.151148: {"feed":"book","product_id":"PI_BCHUSD","side":"sell","seq":16258284,"price":1063.8,"qty":0.0,"timestamp":1618678107104}
1618678107.151173: {"feed":"book","product_id":"PI_BCHUSD","side":"sell","seq":16258285,"price":1064.4,"qty":15594.0,"timestamp":1618678107106}
1618678107.1511931: {"feed":"book","product_id":"FI_ETHUSD_210924","side":"sell","seq":3859105,"price":2667.85,"qty":0.0,"timestamp":1618678107104}
1618678107.151218: {"feed":"book","product_id":"FI_ETHUSD_210924","side":"sell","seq":3859106,"price":2666.5,"qty":42000.0,"timestamp":1618678107104}
1618678107.151242: {"feed":"book","product_id":"FI_XBTUSD_210430","side":"sell","seq":12237448,"price":61346.5,"qty":0.0,"timestamp":1618678107105}
1618678107.151268: {"feed":"book","product_id":"FI_XBTUSD_210430","side":"sell","seq":12237449,"price":61355.0,"qty":250001.0,"timestamp":1618678107105}
1618678107.151291: {"feed":"book","product_id":"FI_XRPUSD_210625","side":"buy","seq":3631473,"price":1.6884,"qty":0.0,"timestamp":1618678107104}
1618678107.151318: {"feed":"book","product_id":"FI_XRPUSD_210625","side":"buy","seq":3631474,"price":1.6825,"qty":2955.0,"timestamp":1618678107104}
1618678107.1513422: {"feed":"book","product_id":"FI_ETHUSD_210924","side":"buy","seq":3859107,"price":2643.8,"qty":0.0,"timestamp":1618678107104}
1618678107.151367: {"feed":"book","product_id":"FI_ETHUSD_210924","side":"buy","seq":3859108,"price":2641.95,"qty":84000.0,"timestamp":1618678107104}
1618678107.151391: {"feed":"book","product_id":"FI_ETHUSD_210924","side":"sell","seq":3859109,"price":2674.45,"qty":0.0,"timestamp":1618678107104}
1618678107.151414: {"feed":"book","product_id":"FI_ETHUSD_210924","side":"sell","seq":3859110,"price":2672.6,"qty":84000.0,"timestamp":1618678107104}
1618678107.151437: {"feed":"book","product_id":"FI_ETHUSD_210924","side":"sell","seq":3859111,"price":2661.1,"qty":0.0,"timestamp":1618678107104}
1618678107.1514602: {"feed":"book","product_id":"FI_ETHUSD_210924","side":"sell","seq":3859112,"price":2660.4,"qty":40199.0,"timestamp":1618678107104}
1618678107.151501: {"feed":"book","product_id":"FI_ETHUSD_210625","side":"buy","seq":12455320,"price":2498.5,"qty":0.0,"timestamp":1618678107120}
1618678107.159703: {"feed":"book","product_id":"FI_XRPUSD_210625","side":"buy","seq":3631475,"price":1.6946,"qty":0.0,"timestamp":1618678107120}
1618678107.159831: {"feed":"book","product_id":"FI_XRPUSD_210625","side":"buy","seq":3631476,"price":1.6938,"qty":68.0,"timestamp":1618678107120}
1618678107.1598961: {"feed":"book","product_id":"FI_XRPUSD_210625","side":"sell","seq":3631477,"price":1.6998,"qty":0.0,"timestamp":1618678107121}
1618678107.159948: {"feed":"book","product_id":"FI_XRPUSD_210625","side":"sell","seq":3631478,"price":1.699,"qty":18968.0,"timestamp":1618678107121}
1618678107.16004: {"feed":"book","product_id":"FI_ETHUSD_210430","side":"sell","seq":4780783,"price":2391.2,"qty":0.0,"timestamp":1618678107121}
1618678107.160096: {"feed":"book","product_id":"FI_ETHUSD_210430","side":"sell","seq":4780784,"price":2390.85,"qty":1020.0,"timestamp":1618678107121}
1618678107.16491: {"feed":"book","product_id":"FI_XBTUSD_210625","side":"sell","seq":21454804,"price":63988.0,"qty":0.0,"timestamp":1618678107126}
1618678107.165039: {"feed":"book","product_id":"FI_XBTUSD_210625","side":"sell","seq":21454805,"price":63976.5,"qty":1920.0,"timestamp":1618678107126}
1618678107.165148: {"feed":"book","product_id":"FI_XBTUSD_210625","side":"buy","seq":21454806,"price":63940.5,"qty":0.0,"timestamp":1618678107126}
1618678107.1651971: {"feed":"book","product_id":"FI_XBTUSD_210625","side":"buy","seq":21454807,"price":63927.0,"qty":1920.0,"timestamp":1618678107126}
1618678107.16526: {"feed":"book","product_id":"FI_XBTUSD_210625","side":"buy","seq":21454808,"price":57200.5,"qty":30165.0,"timestamp":1618678107131}
1618678107.1658628: {"feed":"book","product_id":"FI_XBTUSD_210430","side":"buy","seq":12237450,"price":61189.5,"qty":0.0,"timestamp":1618678107126}
1618678107.165927: {"feed":"book","product_id":"FI_XBTUSD_210430","side":"buy","seq":12237451,"price":61176.5,"qty":658.0,"timestamp":1618678107126}
1618678107.165992: {"feed":"book","product_id":"FI_XBTUSD_210924","side":"sell","seq":13850762,"price":68307.0,"qty":0.0,"timestamp":1618678107129}
1618678107.1660259: {"feed":"book","product_id":"FI_XBTUSD_210924","side":"sell","seq":13850763,"price":68293.0,"qty":1680.0,"timestamp":1618678107129}
1618678107.174817: {"feed":"book","product_id":"FI_ETHUSD_210625","side":"sell","seq":12455321,"price":2505.4,"qty":0.0,"timestamp":1618678107141}
1618678107.1749032: {"feed":"book","product_id":"FI_ETHUSD_210625","side":"sell","seq":12455322,"price":2505.0,"qty":24000.0,"timestamp":1618678107141}
1618678107.1749609: {"feed":"book","product_id":"FI_XRPUSD_210625","side":"buy","seq":3631479,"price":1.6901,"qty":0.0,"timestamp":1618678107141}
1618678107.17501: {"feed":"book","product_id":"FI_XRPUSD_210625","side":"buy","seq":3631480,"price":1.6908,"qty":0.0,"timestamp":1618678107141}
1618678107.1750882: {"feed":"book","product_id":"FI_ETHUSD_210924","side":"buy","seq":3859113,"price":2656.4,"qty":0.0,"timestamp":1618678107141}
1618678107.175147: {"feed":"book","product_id":"FI_ETHUSD_210924","side":"buy","seq":3859114,"price":2655.95,"qty":840.0,"timestamp":1618678107141}
1618678107.183475: {"feed":"book","product_id":"FI_XBTUSD_210625","side":"buy","seq":21454809,"price":63917.5,"qty":0.0,"timestamp":1618678107148}
1618678107.183604: {"feed":"book","product_id":"FI_XBTUSD_210625","side":"buy","seq":21454810,"price":63878.0,"qty":1463.0,"timestamp":1618678107148}
1618678107.183667: {"feed":"book","product_id":"FI_XBTUSD_210625","side":"sell","seq":21454811,"price":64069.0,"qty":0.0,"timestamp":1618678107148}
1618678107.183721: {"feed":"book","product_id":"FI_XBTUSD_210625","side":"sell","seq":21454812,"price":64042.0,"qty":13016.0,"timestamp":1618678107148}
1618678107.183773: {"feed":"book","product_id":"FI_XBTUSD_210625","side":"sell","seq":21454813,"price":64143.5,"qty":0.0,"timestamp":1618678107148}
1618678107.183819: {"feed":"book","product_id":"FI_XBTUSD_210625","side":"sell","seq":21454814,"price":64098.0,"qty":25380.0,"timestamp":1618678107148}
1618678107.1838431: {"feed":"book","product_id":"FI_XBTUSD_210625","side":"buy","seq":21454815,"price":63746.5,"qty":0.0,"timestamp":1618678107148}
1618678107.183869: {"feed":"book","product_id":"FI_XBTUSD_210625","side":"buy","seq":21454816,"price":63727.5,"qty":3281.0,"timestamp":1618678107148}
1618678107.202369: {"feed":"book","product_id":"FI_XBTUSD_210924","side":"sell","seq":13850764,"price":68349.0,"qty":0.0,"timestamp":1618678107153}
1618678107.202507: {"feed":"book","product_id":"FI_XBTUSD_210924","side":"buy","seq":13850765,"price":68065.0,"qty":0.0,"timestamp":1618678107153}
1618678107.202546: {"feed":"book","product_id":"FI_XBTUSD_210924","side":"sell","seq":13850766,"price":68542.0,"qty":0.0,"timestamp":1618678107153}
1618678107.202576: {"feed":"book","product_id":"FI_XBTUSD_210924","side":"buy","seq":13850767,"price":67905.5,"qty":0.0,"timestamp":1618678107153}
1618678107.202603: {"feed":"book","product_id":"FI_ETHUSD_210430","side":"buy","seq":4780785,"price":2387.35,"qty":0.0,"timestamp":1618678107155}
1618678107.202632: {"feed":"book","product_id":"FI_ETHUSD_210430","side":"buy","seq":4780786,"price":2386.85,"qty":33000.0,"timestamp":1618678107155}
1618678107.202681: {"feed":"book","product_id":"FI_ETHUSD_210430","side":"sell","seq":4780787,"price":2390.9,"qty":0.0,"timestamp":1618678107155}
1618678107.20271: {"feed":"book","product_id":"FI_ETHUSD_210430","side":"sell","seq":4780788,"price":2390.75,"qty":25500.0,"timestamp":1618678107155}
1618678107.2027369: {"feed":"book","product_id":"FI_ETHUSD_210924","side":"buy","seq":3859115,"price":2641.4,"qty":2000.0,"timestamp":1618678107156}
1618678107.202765: {"feed":"book","product_id":"FI_ETHUSD_210924","side":"buy","seq":3859116,"price":2628.25,"qty":5000.0,"timestamp":1618678107156}
1618678107.202788: {"feed":"book","product_id":"PI_BCHUSD","side":"sell","seq":16258286,"price":1064.2,"qty":12787.0,"timestamp":1618678107168}
1618678107.202809: {"feed":"book","product_id":"PI_BCHUSD","side":"sell","seq":16258287,"price":1063.4,"qty":4990.0,"timestamp":1618678107168}
1618678107.202833: {"feed":"book","product_id":"PI_BCHUSD","side":"sell","seq":16258288,"price":1063.8,"qty":4988.0,"timestamp":1618678107168}
1618678107.2028549: {"feed":"book","product_id":"FI_ETHUSD_210625","side":"sell","seq":12455323,"price":2510.25,"qty":0.0,"timestamp":1618678107166}
1618678107.202881: {"feed":"book","product_id":"FI_ETHUSD_210625","side":"buy","seq":12455324,"price":2496.5,"qty":0.0,"timestamp":1618678107171}
1618678107.2056441: {"feed":"book","product_id":"FI_XBTUSD_210625","side":"buy","seq":21454817,"price":57200.5,"qty":33155.0,"timestamp":1618678107175}
1618678107.218176: {"feed":"book","product_id":"PI_BCHUSD","side":"sell","seq":16258289,"price":1063.8,"qty":36550.0,"timestamp":1618678107181}
1618678107.218283: {"feed":"book","product_id":"FI_ETHUSD_210430","side":"buy","seq":4780789,"price":2386.5,"qty":130883.0,"timestamp":1618678107186}
1618678107.218352: {"feed":"book","product_id":"FI_XBTUSD_210625","side":"buy","seq":21454818,"price":63798.0,"qty":0.0,"timestamp":1618678107186}
1618678107.218411: {"feed":"book","product_id":"FI_XBTUSD_210625","side":"buy","seq":21454819,"price":63788.5,"qty":6000.0,"timestamp":1618678107186}
1618678107.2312682: {"feed":"book","product_id":"FI_ETHUSD_210625","side":"buy","seq":12455325,"price":2500.3,"qty":24000.0,"timestamp":1618678107185}
1618678107.231447: {"feed":"book","product_id":"FI_ETHUSD_210625","side":"sell","seq":12455326,"price":2505.2,"qty":0.0,"timestamp":1618678107185}
1618678107.231491: {"feed":"book","product_id":"FI_ETHUSD_210430","side":"sell","seq":4780790,"price":2390.55,"qty":118674.0,"timestamp":1618678107186}
1618678107.2315269: {"feed":"book","product_id":"FI_ETHUSD_210430","side":"buy","seq":4780791,"price":2384.1,"qty":171155.0,"timestamp":1618678107186}
1618678107.231555: {"feed":"book","product_id":"FI_ETHUSD_210625","side":"buy","seq":12455327,"price":2497.6,"qty":0.0,"timestamp":1618678107185}
1618678107.2315829: {"feed":"book","product_id":"FI_ETHUSD_210430","side":"sell","seq":4780792,"price":2392.85,"qty":155189.0,"timestamp":1618678107186}
1618678107.2316082: {"feed":"book","product_id":"FI_ETHUSD_210430","side":"buy","seq":4780793,"price":2381.65,"qty":201358.0,"timestamp":1618678107186}
1618678107.231631: {"feed":"book","product_id":"FI_ETHUSD_210625","side":"sell","seq":12455328,"price":2508.1,"qty":0.0,"timestamp":1618678107185}
1618678107.2316558: {"feed":"book","product_id":"FI_ETHUSD_210430","side":"sell","seq":4780794,"price":2395.1,"qty":182576.0,"timestamp":1618678107186}
1618678107.23168: {"feed":"book","product_id":"PI_BCHUSD","side":"sell","seq":16258290,"price":1065.2,"qty":31724.0,"timestamp":1618678107197}
1618678107.231702: {"feed":"book","product_id":"FI_ETHUSD_210625","side":"buy","seq":12455329,"price":2494.85,"qty":0.0,"timestamp":1618678107186}
1618678107.2317271: {"feed":"book","product_id":"PI_BCHUSD","side":"sell","seq":16258291,"price":1066.0,"qty":3944.0,"timestamp":1618678107197}
1618678107.231748: {"feed":"book","product_id":"FI_ETHUSD_210430","side":"buy","seq":4780795,"price":2379.25,"qty":251698.0,"timestamp":1618678107186}
1618678107.231771: {"feed":"book","product_id":"FI_ETHUSD_210625","side":"sell","seq":12455330,"price":2511.0,"qty":0.0,"timestamp":1618678107186}
1618678107.231796: {"feed":"book","product_id":"PI_BCHUSD","side":"buy","seq":16258292,"price":1060.4,"qty":3730.0,"timestamp":1618678107197}
1618678107.231817: {"feed":"book","product_id":"FI_ETHUSD_210430","side":"sell","seq":4780796,"price":2397.4,"qty":228220.0,"timestamp":1618678107186}
1618678107.243328: {"feed":"book","product_id":"FI_ETHUSD_210625","side":"buy","seq":12455331,"price":2492.1,"qty":0.0,"timestamp":1618678107186}
1618678107.243416: {"feed":"book","product_id":"PI_BCHUSD","side":"buy","seq":16258293,"price":1060.4,"qty":50.0,"timestamp":1618678107197}
1618678107.2434518: {"feed":"book","product_id":"FI_ETHUSD_210430","side":"buy","seq":4780797,"price":2376.8,"qty":302037.0,"timestamp":1618678107186}
1618678107.243487: {"feed":"book","product_id":"FI_ETHUSD_210625","side":"sell","seq":12455332,"price":2513.9,"qty":0.0,"timestamp":1618678107186}
1618678107.243517: {"feed":"book","product_id":"PI_BCHUSD","side":"buy","seq":16258294,"price":1059.2,"qty":7761.0,"timestamp":1618678107197}
1618678107.24354: {"feed":"book","product_id":"FI_ETHUSD_210430","side":"sell","seq":4780798,"price":2399.65,"qty":273864.0,"timestamp":1618678107186}
1618678107.243565: {"feed":"book","product_id":"PI_BCHUSD","side":"sell","seq":16258295,"price":1064.7,"qty":33137.0,"timestamp":1618678107197}
1618678107.243586: {"feed":"book","product_id":"FI_ETHUSD_210625","side":"buy","seq":12455333,"price":2489.4,"qty":0.0,"timestamp":1618678107186}
1618678107.2436101: {"feed":"book","product_id":"PI_BCHUSD","side":"buy","seq":16258296,"price":1060.2,"qty":0.0,"timestamp":1618678107197}
1618678107.243636: {"feed":"book","product_id":"FI_ETHUSD_210625","side":"sell","seq":12455334,"price":2516.8,"qty":0.0,"timestamp":1618678107186}
1618678107.243702: {"feed":"book","product_id":"FI_ETHUSD_210625","side":"sell","seq":12455335,"price":2505.05,"qty":0.0,"timestamp":1618678107191}
1618678107.2437289: {"feed":"book","product_id":"FI_ETHUSD_210625","side":"sell","seq":12455336,"price":2504.95,"qty":835.0,"timestamp":1618678107191}
1618678107.243754: {"feed":"book","product_id":"FI_BCHUSD_210430","side":"buy","seq":1411847,"price":1070.4,"qty":0.0,"timestamp":1618678107197}
1618678107.2437792: {"feed":"book","product_id":"FI_BCHUSD_210430","side":"buy","seq":1411848,"price":1068.2,"qty":19360.0,"timestamp":1618678107197}
1618678107.243799: {"feed":"book","product_id":"FI_XBTUSD_210625","side":"sell","seq":21454820,"price":64365.5,"qty":0.0,"timestamp":1618678107197}
1618678107.2438242: {"feed":"book","product_id":"FI_XBTUSD_210625","side":"sell","seq":21454821,"price":64363.0,"qty":0.0,"timestamp":1618678107198}
1618678107.243846: {"feed":"book","product_id":"FI_XBTUSD_210625","side":"sell","seq":21454822,"price":64313.5,"qty":24858.0,"timestamp":1618678107199}
1618678107.2438688: {"feed":"book","product_id":"FI_XBTUSD_210625","side":"sell","seq":21454823,"price":64316.0,"qty":24857.0,"timestamp":1618678107200}
1618678107.243891: {"feed":"book","product_id":"FI_XBTUSD_210430","side":"buy","seq":12237452,"price":60937.5,"qty":0.0,"timestamp":1618678107203}
1618678107.243917: {"feed":"book","product_id":"FI_XBTUSD_210430","side":"buy","seq":12237453,"price":60896.0,"qty":408000.0,"timestamp":1618678107203}
1618678107.243959: {"feed":"book","product_id":"FI_XBTUSD_210430","side":"sell","seq":12237454,"price":61259.5,"qty":0.0,"timestamp":1618678107203}
1618678107.243984: {"feed":"book","product_id":"FI_XBTUSD_210430","side":"sell","seq":12237455,"price":61243.5,"qty":51000.0,"timestamp":1618678107203}
1618678107.244006: {"feed":"book","product_id":"FI_XBTUSD_210430","side":"buy","seq":12237456,"price":61161.0,"qty":0.0,"timestamp":1618678107203}
1618678107.2440279: {"feed":"book","product_id":"FI_XBTUSD_210430","side":"buy","seq":12237457,"price":61150.0,"qty":51000.0,"timestamp":1618678107203}
1618678107.24405: {"feed":"book","product_id":"FI_XBTUSD_210625","side":"sell","seq":21454824,"price":64144.0,"qty":0.0,"timestamp":1618678107206}
1618678107.244073: {"feed":"book","product_id":"FI_XBTUSD_210625","side":"sell","seq":21454825,"price":64119.0,"qty":96000.0,"timestamp":1618678107206}
1618678107.244095: {"feed":"book","product_id":"FI_XBTUSD_210625","side":"buy","seq":21454826,"price":63808.0,"qty":0.0,"timestamp":1618678107206}
1618678107.244119: {"feed":"book","product_id":"FI_XBTUSD_210625","side":"buy","seq":21454827,"price":63784.5,"qty":96000.0,"timestamp":1618678107206}
1618678107.244142: {"feed":"book","product_id":"FI_XBTUSD_210625","side":"sell","seq":21454828,"price":64261.5,"qty":0.0,"timestamp":1618678107206}
1618678107.244164: {"feed":"book","product_id":"FI_XBTUSD_210625","side":"sell","seq":21454829,"price":64228.0,"qty":192000.0,"timestamp":1618678107206}
1618678107.244192: {"feed":"book","product_id":"FI_XBTUSD_210625","side":"sell","seq":21454830,"price":64022.0,"qty":0.0,"timestamp":1618678107206}
1618678107.244215: {"feed":"book","product_id":"FI_XBTUSD_210625","side":"sell","seq":21454831,"price":64010.0,"qty":48000.0,"timestamp":1618678107206}
1618678107.2442582: {"feed":"book","product_id":"PI_BCHUSD","side":"buy","seq":16258297,"price":1059.8,"qty":0.0,"timestamp":1618678107207}
1618678107.244283: {"feed":"book","product_id":"FI_ETHUSD_210430","side":"sell","seq":4780799,"price":2390.85,"qty":0.0,"timestamp":1618678107204}
1618678107.244307: {"feed":"book","product_id":"FI_ETHUSD_210430","side":"sell","seq":4780800,"price":2390.5,"qty":1020.0,"timestamp":1618678107204}
1618678107.244329: {"feed":"book","product_id":"PI_BCHUSD","side":"sell","seq":16258298,"price":1065.2,"qty":0.0,"timestamp":1618678107210}
1618678107.244354: {"feed":"book","product_id":"PI_BCHUSD","side":"sell","seq":16258299,"price":1063.9,"qty":31083.0,"timestamp":1618678107210}
1618678107.245476: {"feed":"book","product_id":"FI_XBTUSD_210924","side":"sell","seq":13850768,"price":68679.0,"qty":0.0,"timestamp":1618678107205}
1618678107.245565: {"feed":"book","product_id":"FI_XBTUSD_210924","side":"sell","seq":13850769,"price":68632.0,"qty":168000.0,"timestamp":1618678107205}
1618678107.245606: {"feed":"book","product_id":"FI_XBTUSD_210625","side":"buy","seq":21454832,"price":63814.0,"qty":0.0,"timestamp":1618678107217}
1618678107.252005: {"feed":"book","product_id":"FI_XBTUSD_210430","side":"sell","seq":12237458,"price":61355.0,"qty":0.0,"timestamp":1618678107214}
1618678107.252131: {"feed":"book","product_id":"FI_XBTUSD_210430","side":"sell","seq":12237459,"price":61344.0,"qty":250001.0,"timestamp":1618678107214}
1618678107.2521942: {"feed":"book","product_id":"FI_XBTUSD_210430","side":"sell","seq":12237460,"price":61264.5,"qty":0.0,"timestamp":1618678107214}
1618678107.252243: {"feed":"book","product_id":"FI_XBTUSD_210430","side":"sell","seq":12237461,"price":61261.0,"qty":10000.0,"timestamp":1618678107214}
1618678107.2522838: {"feed":"book","product_id":"FI_XBTUSD_210625","side":"buy","seq":21454833,"price":63774.5,"qty":25068.0,"timestamp":1618678107219}
1618678107.25234: {"feed":"book","product_id":"FI_XBTUSD_210625","side":"buy","seq":21454834,"price":63774.0,"qty":18784.0,"timestamp":1618678107219}
1618678107.252361: {"feed":"book","product_id":"FI_ETHUSD_210625","side":"buy","seq":12455337,"price":2496.75,"qty":2000.0,"timestamp":1618678107222}
1618678107.252388: {"feed":"book","product_id":"FI_ETHUSD_210625","side":"sell","seq":12455338,"price":2505.0,"qty":26000.0,"timestamp":1618678107222}
1618678107.26686: {"feed":"book","product_id":"FI_XBTUSD_210430","side":"buy","seq":12237462,"price":61174.5,"qty":0.0,"timestamp":1618678107226}
1618678107.266966: {"feed":"book","product_id":"FI_XBTUSD_210430","side":"sell","seq":12237463,"price":61254.0,"qty":0.0,"timestamp":1618678107226}
1618678107.267005: {"feed":"book","product_id":"FI_XBTUSD_210430","side":"buy","seq":12237464,"price":61128.0,"qty":0.0,"timestamp":1618678107226}
1618678107.2670348: {"feed":"book","product_id":"FI_XBTUSD_210430","side":"sell","seq":12237465,"price":61300.5,"qty":0.0,"timestamp":1618678107226}
1618678107.267061: {"feed":"book","product_id":"FI_XBTUSD_210430","side":"buy","seq":12237466,"price":61081.5,"qty":0.0,"timestamp":1618678107226}
1618678107.267086: {"feed":"book","product_id":"FI_XBTUSD_210430","side":"sell","seq":12237467,"price":61347.0,"qty":0.0,"timestamp":1618678107226}
1618678107.2671099: {"feed":"book","product_id":"FI_XBTUSD_210430","side":"buy","seq":12237468,"price":61035.5,"qty":0.0,"timestamp":1618678107226}
1618678107.267133: {"feed":"book","product_id":"FI_XBTUSD_210430","side":"sell","seq":12237469,"price":61393.5,"qty":0.0,"timestamp":1618678107226}
1618678107.267155: {"feed":"book","product_id":"FI_XBTUSD_210430","side":"buy","seq":12237470,"price":60989.0,"qty":0.0,"timestamp":1618678107226}
1618678107.267178: {"feed":"book","product_id":"FI_XBTUSD_210430","side":"sell","seq":12237471,"price":61440.0,"qty":0.0,"timestamp":1618678107226}
1618678107.2672: {"feed":"book","product_id":"FI_XBTUSD_210625","side":"buy","seq":21454835,"price":57200.5,"qty":30165.0,"timestamp":1618678107231}
1618678107.267224: {"feed":"book","product_id":"FI_XRPUSD_210625","side":"buy","seq":3631481,"price":1.6883,"qty":0.0,"timestamp":1618678107233}
1618678107.267251: {"feed":"book","product_id":"FI_XBTUSD_210625","side":"buy","seq":21454836,"price":63878.5,"qty":138199.0,"timestamp":1618678107234}
1618678107.2672808: {"feed":"book","product_id":"FI_XBTUSD_210625","side":"sell","seq":21454837,"price":63967.0,"qty":171462.0,"timestamp":1618678107234}
1618678107.267307: {"feed":"book","product_id":"FI_XBTUSD_210625","side":"buy","seq":21454838,"price":63826.0,"qty":219493.0,"timestamp":1618678107234}
1618678107.26733: {"feed":"book","product_id":"FI_XBTUSD_210625","side":"sell","seq":21454839,"price":64011.0,"qty":272323.0,"timestamp":1618678107234}
1618678107.267354: {"feed":"book","product_id":"FI_XBTUSD_210625","side":"buy","seq":21454840,"price":63773.0,"qty":260140.0,"timestamp":1618678107234}
1618678107.2673762: {"feed":"book","product_id":"FI_XBTUSD_210625","side":"sell","seq":21454841,"price":64055.0,"qty":328416.0,"timestamp":1618678107234}
1618678107.2673962: {"feed":"book","product_id":"FI_XBTUSD_210625","side":"buy","seq":21454842,"price":63720.5,"qty":284528.0,"timestamp":1618678107234}
1618678107.2674181: {"feed":"book","product_id":"FI_XBTUSD_210625","side":"sell","seq":21454843,"price":64099.0,"qty":353011.0,"timestamp":1618678107235}
1618678107.2674408: {"feed":"book","product_id":"FI_XBTUSD_210625","side":"buy","seq":21454844,"price":63668.0,"qty":365822.0,"timestamp":1618678107235}
1618678107.267463: {"feed":"book","product_id":"FI_XBTUSD_210625","side":"sell","seq":21454845,"price":64143.0,"qty":453871.0,"timestamp":1618678107235}
1618678107.267485: {"feed":"book","product_id":"FI_XBTUSD_210625","side":"buy","seq":21454846,"price":63615.5,"qty":487763.0,"timestamp":1618678107235}
1618678107.269002: {"feed":"book","product_id":"FI_XBTUSD_210625","side":"sell","seq":21454847,"price":64187.5,"qty":605162.0,"timestamp":1618678107235}
1618678107.26909: {"feed":"book","product_id":"FI_ETHUSD_210924","side":"buy","seq":3859117,"price":2653.25,"qty":0.0,"timestamp":1618678107238}
1618678107.2740211: {"feed":"book","product_id":"FI_XBTUSD_210625","side":"buy","seq":21454848,"price":63495.5,"qty":0.0,"timestamp":1618678107242}
1618678107.274082: {"feed":"book","product_id":"FI_XBTUSD_210430","side":"sell","seq":12237472,"price":61253.5,"qty":0.0,"timestamp":1618678107240}
1618678107.274118: {"feed":"book","product_id":"FI_XBTUSD_210625","side":"buy","seq":21454849,"price":63774.0,"qty":8784.0,"timestamp":1618678107242}
1618678107.2741451: {"feed":"book","product_id":"FI_XBTUSD_210625","side":"buy","seq":21454850,"price":63774.5,"qty":35068.0,"timestamp":1618678107242}
1618678107.274167: {"feed":"book","product_id":"FI_XBTUSD_210430","side":"sell","seq":12237473,"price":61243.0,"qty":1904.0,"timestamp":1618678107240}
1618678107.274196: {"feed":"book","product_id":"PI_BCHUSD","side":"sell","seq":16258300,"price":1064.1,"qty":6073.0,"timestamp":1618678107241}
1618678107.274218: {"feed":"book","product_id":"PI_BCHUSD","side":"sell","seq":16258301,"price":1063.8,"qty":47193.0,"timestamp":1618678107241}
1618678107.2742379: {"feed":"book","product_id":"PI_BCHUSD","side":"buy","seq":16258302,"price":1058.9,"qty":20441.0,"timestamp":1618678107241}
1618678107.276031: {"feed":"book","product_id":"PI_BCHUSD","side":"sell","seq":16258303,"price":1063.8,"qty":36550.0,"timestamp":1618678107245}
1618678107.2761412: {"feed":"book","product_id":"PI_BCHUSD","side":"sell","seq":16258304,"price":1063.5,"qty":10643.0,"timestamp":1618678107245}
1618678107.301693: {"feed":"book","product_id":"FI_XBTUSD_210625","side":"buy","seq":21454851,"price":63774.5,"qty":25068.0,"timestamp":1618678107263}
1618678107.301804: {"feed":"book","product_id":"FI_XBTUSD_210625","side":"buy","seq":21454852,"price":63825.5,"qty":10000.0,"timestamp":1618678107263}
1618678107.3018692: {"feed":"book","product_id":"FI_XBTUSD_210430","side":"sell","seq":12237474,"price":61261.0,"qty":0.0,"timestamp":1618678107263}
1618678107.3019252: {"feed":"book","product_id":"FI_XBTUSD_210430","side":"sell","seq":12237475,"price":61247.0,"qty":10000.0,"timestamp":1618678107263}
1618678107.3019662: {"feed":"book","product_id":"FI_XBTUSD_210625","side":"buy","seq":21454853,"price":63925.5,"qty":0.0,"timestamp":1618678107263}
1618678107.302047: {"feed":"book","product_id":"FI_XBTUSD_210924","side":"sell","seq":13850770,"price":68294.0,"qty":0.0,"timestamp":1618678107267}
1618678107.30211: {"feed":"book","product_id":"FI_XBTUSD_210924","side":"sell","seq":13850771,"price":68292.5,"qty":10000.0,"timestamp":1618678107267}
1618678107.3021362: {"feed":"book","product_id":"FI_XBTUSD_210430","side":"sell","seq":12237476,"price":61247.0,"qty":0.0,"timestamp":1618678107268}
1618678107.3021598: {"feed":"book","product_id":"FI_XBTUSD_210430","side":"sell","seq":12237477,"price":61246.5,"qty":10000.0,"timestamp":1618678107268}
1618678107.312963: {"feed":"book","product_id":"FI_XBTUSD_210625","side":"sell","seq":21454854,"price":63967.5,"qty":0.0,"timestamp":1618678107276}
1618678107.3130949: {"feed":"book","product_id":"FI_XBTUSD_210430","side":"buy","seq":12237478,"price":61036.0,"qty":0.0,"timestamp":1618678107276}
1618678107.3131552: {"feed":"book","product_id":"FI_XBTUSD_210430","side":"buy","seq":12237479,"price":60994.0,"qty":250001.0,"timestamp":1618678107276}
1618678107.313218: {"feed":"book","product_id":"FI_XBTUSD_210625","side":"buy","seq":21454855,"price":63775.0,"qty":0.0,"timestamp":1618678107276}
1618678107.313271: {"feed":"book","product_id":"FI_XBTUSD_210625","side":"buy","seq":21454856,"price":63785.0,"qty":250001.0,"timestamp":1618678107276}
1618678107.313299: {"feed":"book","product_id":"FI_XBTUSD_210430","side":"buy","seq":12237480,"price":60938.0,"qty":0.0,"timestamp":1618678107276}
1618678107.313324: {"feed":"book","product_id":"FI_XBTUSD_210430","side":"buy","seq":12237481,"price":60930.0,"qty":493105.0,"timestamp":1618678107276}
1618678107.313347: {"feed":"book","product_id":"FI_XBTUSD_210430","side":"buy","seq":12237482,"price":61127.0,"qty":0.0,"timestamp":1618678107279}
1618678107.313371: {"feed":"book","product_id":"FI_XBTUSD_210625","side":"buy","seq":21454857,"price":57200.5,"qty":33185.0,"timestamp":1618678107279}
1618678107.3156722: {"feed":"book","product_id":"FI_XBTUSD_210924","side":"buy","seq":13850772,"price":68154.5,"qty":155643.0,"timestamp":1618678107281}
1618678107.315763: {"feed":"book","product_id":"FI_XBTUSD_210924","side":"sell","seq":13850773,"price":68293.0,"qty":141623.0,"timestamp":1618678107281}
1618678107.315798: {"feed":"book","product_id":"FI_XBTUSD_210924","side":"buy","seq":13850774,"price":68071.0,"qty":247198.0,"timestamp":1618678107281}
1618678107.315828: {"feed":"book","product_id":"FI_XBTUSD_210924","side":"sell","seq":13850775,"price":68374.5,"qty":222263.0,"timestamp":1618678107281}
1618678107.315855: {"feed":"book","product_id":"FI_XBTUSD_210924","side":"buy","seq":13850776,"price":67987.5,"qty":292976.0,"timestamp":1618678107282}
1618678107.315881: {"feed":"book","product_id":"FI_XBTUSD_210924","side":"sell","seq":13850777,"price":68456.5,"qty":263423.0,"timestamp":1618678107282}
1618678107.315905: {"feed":"book","product_id":"FI_XBTUSD_210924","side":"buy","seq":13850778,"price":67904.0,"qty":320442.0,"timestamp":1618678107282}
1618678107.315928: {"feed":"book","product_id":"FI_XBTUSD_210924","side":"sell","seq":13850779,"price":68538.5,"qty":288119.0,"timestamp":1618678107282}
1618678107.315951: {"feed":"book","product_id":"FI_XBTUSD_210924","side":"buy","seq":13850780,"price":67821.0,"qty":411997.0,"timestamp":1618678107282}
1618678107.315973: {"feed":"book","product_id":"FI_XBTUSD_210924","side":"sell","seq":13850781,"price":68620.5,"qty":370438.0,"timestamp":1618678107282}
1618678107.315995: {"feed":"book","product_id":"FI_XBTUSD_210924","side":"buy","seq":13850782,"price":67738.0,"qty":549329.0,"timestamp":1618678107282}
1618678107.3160179: {"feed":"book","product_id":"FI_XBTUSD_210924","side":"sell","seq":13850783,"price":68702.5,"qty":493918.0,"timestamp":1618678107282}
1618678107.3210292: {"feed":"book","product_id":"FI_XBTUSD_210924","side":"buy","seq":13850784,"price":68163.0,"qty":7500.0,"timestamp":1618678107290}
1618678107.321121: {"feed":"book","product_id":"FI_XBTUSD_210924","side":"sell","seq":13850785,"price":68305.5,"qty":7500.0,"timestamp":1618678107290}
1618678107.321156: {"feed":"book","product_id":"PI_BCHUSD","side":"sell","seq":16258305,"price":1066.0,"qty":0.0,"timestamp":1618678107290}
1618678107.321193: {"feed":"book","product_id":"FI_XBTUSD_210924","side":"buy","seq":13850786,"price":67999.0,"qty":10000.0,"timestamp":1618678107290}
1618678107.3212218: {"feed":"book","product_id":"PI_BCHUSD","side":"sell","seq":16258306,"price":1063.1,"qty":0.0,"timestamp":1618678107290}
1618678107.321248: {"feed":"book","product_id":"FI_XBTUSD_210924","side":"sell","seq":13850787,"price":68469.5,"qty":10000.0,"timestamp":1618678107290}
1618678107.3212721: {"feed":"book","product_id":"PI_BCHUSD","side":"sell","seq":16258307,"price":1064.1,"qty":10153.0,"timestamp":1618678107290}
1618678107.321292: {"feed":"book","product_id":"PI_BCHUSD","side":"sell","seq":16258308,"price":1064.7,"qty":37300.0,"timestamp":1618678107292}
1618678107.321903: {"feed":"book","product_id":"FI_XBTUSD_210430","side":"sell","seq":12237483,"price":61246.5,"qty":0.0,"timestamp":1618678107293}
1618678107.327373: {"feed":"book","product_id":"FI_XBTUSD_210430","side":"sell","seq":12237484,"price":61242.5,"qty":10000.0,"timestamp":1618678107293}
1618678107.338181: {"feed":"book","product_id":"FI_XBTUSD_210924","side":"sell","seq":13850788,"price":68293.0,"qty":139943.0,"timestamp":1618678107290}
1618678107.338252: {"feed":"book","product_id":"FI_XBTUSD_210924","side":"sell","seq":13850789,"price":68292.0,"qty":1680.0,"timestamp":1618678107290}
1618678107.338314: {"feed":"book","product_id":"FI_ETHUSD_210625","side":"buy","seq":12455339,"price":2496.55,"qty":0.0,"timestamp":1618678107303}
1618678107.350388: {"feed":"book","product_id":"FI_XBTUSD_210430","side":"sell","seq":12237485,"price":61243.0,"qty":0.0,"timestamp":1618678107313}
1618678107.350477: {"feed":"book","product_id":"FI_XBTUSD_210430","side":"sell","seq":12237486,"price":61242.0,"qty":1904.0,"timestamp":1618678107313}
1618678107.350534: {"feed":"book","product_id":"FI_XBTUSD_210625","side":"sell","seq":21454858,"price":63960.5,"qty":1000.0,"timestamp":1618678107316}
1618678107.3506172: {"feed":"book","product_id":"FI_XBTUSD_210430","side":"sell","seq":12237487,"price":61242.5,"qty":0.0,"timestamp":1618678107318}
1618678107.350671: {"feed":"book","product_id":"FI_XBTUSD_210430","side":"sell","seq":12237488,"price":61241.5,"qty":10000.0,"timestamp":1618678107318}
1618678107.356282: {"feed":"book","product_id":"PI_BCHUSD","side":"sell","seq":16258309,"price":1063.5,"qty":0.0,"timestamp":1618678107324}
1618678107.356411: {"feed":"book","product_id":"FI_XBTUSD_210430","side":"buy","seq":12237489,"price":60666.0,"qty":500.0,"timestamp":1618678107328}
1618678107.356478: {"feed":"book","product_id":"FI_XBTUSD_210430","side":"sell","seq":12237490,"price":61960.0,"qty":500.0,"timestamp":1618678107328}
1618678107.363591: {"feed":"book","product_id":"FI_XBTUSD_210430","side":"sell","seq":12237491,"price":61242.0,"qty":0.0,"timestamp":1618678107330}
1618678107.3637161: {"feed":"book","product_id":"FI_XBTUSD_210430","side":"sell","seq":12237492,"price":61241.0,"qty":1904.0,"timestamp":1618678107330}
1618678107.3637938: {"feed":"book","product_id":"FI_XBTUSD_210924","side":"buy","seq":13850790,"price":68051.0,"qty":0.0,"timestamp":1618678107331}
1618678107.363851: {"feed":"book","product_id":"FI_XBTUSD_210924","side":"buy","seq":13850791,"price":68071.5,"qty":250001.0,"timestamp":1618678107331}
1618678107.363879: {"feed":"book","product_id":"FI_ETHUSD_210430","side":"sell","seq":4780801,"price":2401.95,"qty":0.0,"timestamp":1618678107332}
1618678107.363911: {"feed":"book","product_id":"FI_ETHUSD_210430","side":"sell","seq":4780802,"price":2399.6,"qty":584747.0,"timestamp":1618678107332}
1618678107.363936: {"feed":"book","product_id":"FI_XBTUSD_210625","side":"sell","seq":21454859,"price":64192.5,"qty":0.0,"timestamp":1618678107332}
1618678107.363963: {"feed":"book","product_id":"FI_XBTUSD_210625","side":"sell","seq":21454860,"price":64187.0,"qty":504470.0,"timestamp":1618678107332}
1618678107.363987: {"feed":"book","product_id":"FI_XBTUSD_210924","side":"buy","seq":13850792,"price":67978.0,"qty":0.0,"timestamp":1618678107332}
1618678107.364012: {"feed":"book","product_id":"FI_XBTUSD_210924","side":"buy","seq":13850793,"price":67988.0,"qty":250002.0,"timestamp":1618678107332}
1618678107.364062: {"feed":"book","product_id":"FI_XBTUSD_210430","side":"sell","seq":12237493,"price":61241.5,"qty":0.0,"timestamp":1618678107335}
1618678107.364089: {"feed":"book","product_id":"FI_XBTUSD_210430","side":"sell","seq":12237494,"price":61240.5,"qty":10000.0,"timestamp":1618678107335}
1618678107.375797: {"feed":"book","product_id":"FI_XBTUSD_210625","side":"buy","seq":21454861,"price":63747.5,"qty":0.0,"timestamp":1618678107344}
1618678107.375923: {"feed":"book","product_id":"FI_XBTUSD_210924","side":"sell","seq":13850794,"price":68394.0,"qty":23999.0,"timestamp":1618678107345}
1618678107.379528: {"feed":"book","product_id":"FI_XBTUSD_210625","side":"buy","seq":21454862,"price":63807.0,"qty":0.0,"timestamp":1618678107346}
1618678107.379657: {"feed":"book","product_id":"FI_ETHUSD_210430","side":"sell","seq":4780803,"price":2399.6,"qty":0.0,"timestamp":1618678107349}
1618678107.3797178: {"feed":"book","product_id":"FI_ETHUSD_210430","side":"sell","seq":4780804,"price":2401.95,"qty":584747.0,"timestamp":1618678107349}
1618678107.389066: {"feed":"book","product_id":"FI_XBTUSD_210430","side":"sell","seq":12237495,"price":61960.0,"qty":0.0,"timestamp":1618678107351}
1618678107.3891919: {"feed":"book","product_id":"FI_XBTUSD_210430","side":"buy","seq":12237496,"price":60666.0,"qty":0.0,"timestamp":1618678107351}
1618678107.389314: {"feed":"book","product_id":"FI_ETHUSD_210625","side":"buy","seq":12455340,"price":2501.75,"qty":0.0,"timestamp":1618678107353}
1618678107.3893461: {"feed":"book","product_id":"FI_ETHUSD_210625","side":"buy","seq":12455341,"price":2501.25,"qty":860.0,"timestamp":1618678107353}
1618678107.389377: {"feed":"book","product_id":"FI_ETHUSD_210430","side":"buy","seq":4780805,"price":2388.15,"qty":0.0,"timestamp":1618678107354}
1618678107.389405: {"feed":"book","product_id":"FI_ETHUSD_210430","side":"buy","seq":4780806,"price":2387.6,"qty":1020.0,"timestamp":1618678107354}
1618678107.38943: {"feed":"book","product_id":"FI_XBTUSD_210625","side":"buy","seq":21454863,"price":63853.0,"qty":0.0,"timestamp":1618678107355}
1618678107.389457: {"feed":"book","product_id":"FI_XBTUSD_210625","side":"buy","seq":21454864,"price":63808.5,"qty":2250.0,"timestamp":1618678107355}
1618678107.389481: {"feed":"book","product_id":"FI_ETHUSD_210430","side":"sell","seq":4780807,"price":2394.9,"qty":0.0,"timestamp":1618678107358}
1618678107.389506: {"feed":"book","product_id":"FI_ETHUSD_210430","side":"sell","seq":4780808,"price":2394.1,"qty":70199.0,"timestamp":1618678107358}
1618678107.389527: {"feed":"book","product_id":"FI_ETHUSD_210430","side":"buy","seq":4780809,"price":2386.85,"qty":7500.0,"timestamp":1618678107358}
1618678107.389548: {"feed":"book","product_id":"FI_ETHUSD_210430","side":"buy","seq":4780810,"price":2386.45,"qty":25500.0,"timestamp":1618678107358}
1618678107.393806: {"feed":"book","product_id":"FI_ETHUSD_210430","side":"sell","seq":4780811,"price":2390.75,"qty":0.0,"timestamp":1618678107358}
1618678107.393895: {"feed":"book","product_id":"FI_ETHUSD_210430","side":"sell","seq":4780812,"price":2390.4,"qty":25500.0,"timestamp":1618678107358}
1618678107.401334: {"feed":"book","product_id":"FI_ETHUSD_210625","side":"buy","seq":12455342,"price":2500.3,"qty":0.0,"timestamp":1618678107361}
1618678107.4014761: {"feed":"book","product_id":"FI_ETHUSD_210625","side":"buy","seq":12455343,"price":2499.8,"qty":24000.0,"timestamp":1618678107361}
1618678107.401547: {"feed":"book","product_id":"FI_ETHUSD_210924","side":"buy","seq":3859118,"price":2648.9,"qty":0.0,"timestamp":1618678107361}
1618678107.401581: {"feed":"book","product_id":"FI_ETHUSD_210924","side":"buy","seq":3859119,"price":2647.55,"qty":42000.0,"timestamp":1618678107361}
1618678107.401609: {"feed":"book","product_id":"FI_ETHUSD_210625","side":"sell","seq":12455344,"price":2505.0,"qty":2000.0,"timestamp":1618678107361}
1618678107.401633: {"feed":"book","product_id":"FI_ETHUSD_210625","side":"sell","seq":12455345,"price":2504.65,"qty":24000.0,"timestamp":1618678107361}
1618678107.401658: {"feed":"book","product_id":"FI_ETHUSD_210924","side":"buy","seq":3859120,"price":2637.95,"qty":0.0,"timestamp":1618678107361}
1618678107.401684: {"feed":"book","product_id":"FI_ETHUSD_210924","side":"buy","seq":3859121,"price":2635.3,"qty":168000.0,"timestamp":1618678107361}
1618678107.4017081: {"feed":"book","product_id":"FI_ETHUSD_210430","side":"buy","seq":4780813,"price":2380.5,"qty":0.0,"timestamp":1618678107358}
1618678107.4017348: {"feed":"book","product_id":"FI_ETHUSD_210430","side":"buy","seq":4780814,"price":2379.1,"qty":102000.0,"timestamp":1618678107358}
1618678107.401759: {"feed":"book","product_id":"FI_ETHUSD_210924","side":"sell","seq":3859122,"price":2680.85,"qty":0.0,"timestamp":1618678107361}
1618678107.4017842: {"feed":"book","product_id":"FI_ETHUSD_210924","side":"sell","seq":3859123,"price":2678.25,"qty":168000.0,"timestamp":1618678107361}
1618678107.401815: {"feed":"book","product_id":"FI_ETHUSD_210924","side":"buy","seq":3859124,"price":2654.65,"qty":0.0,"timestamp":1618678107361}
1618678107.401841: {"feed":"book","product_id":"FI_ETHUSD_210924","side":"buy","seq":3859125,"price":2653.65,"qty":21000.0,"timestamp":1618678107361}
1618678107.401885: {"feed":"book","product_id":"FI_ETHUSD_210924","side":"sell","seq":3859126,"price":2660.4,"qty":19199.0,"timestamp":1618678107361}
1618678107.401906: {"feed":"book","product_id":"FI_ETHUSD_210924","side":"sell","seq":3859127,"price":2659.9,"qty":21000.0,"timestamp":1618678107361}
1618678107.451618: {"feed":"book","product_id":"FI_XBTUSD_210430","side":"sell","seq":12237497,"price":61241.0,"qty":0.0,"timestamp":1618678107420}
1618678107.451704: {"feed":"book","product_id":"FI_XBTUSD_210430","side":"sell","seq":12237498,"price":61240.0,"qty":1904.0,"timestamp":1618678107420}
1618678107.495359: {"feed":"book","product_id":"FI_XBTUSD_210625","side":"buy","seq":21454865,"price":63774.5,"qty":0.0,"timestamp":1618678107425}
1618678107.4954472: {"feed":"book","product_id":"FI_XBTUSD_210625","side":"buy","seq":21454866,"price":63772.0,"qty":0.0,"timestamp":1618678107425}
1618678107.495512: {"feed":"book","product_id":"FI_ETHUSD_210430","side":"sell","seq":4780815,"price":2390.5,"qty":0.0,"timestamp":1618678107425}
1618678107.495543: {"feed":"book","product_id":"FI_ETHUSD_210430","side":"sell","seq":4780816,"price":2390.35,"qty":1020.0,"timestamp":1618678107425}
1618678107.495575: {"feed":"book","product_id":"FI_ETHUSD_210430","side":"buy","seq":4780817,"price":2351.6,"qty":0.0,"timestamp":1618678107425}
1618678107.4956238: {"feed":"book","product_id":"FI_ETHUSD_210625","side":"sell","seq":12455346,"price":2504.95,"qty":0.0,"timestamp":1618678107425}
1618678107.495651: {"feed":"book","product_id":"FI_ETHUSD_210625","side":"sell","seq":12455347,"price":2504.6,"qty":835.0,"timestamp":1618678107425}
1618678107.4956758: {"feed":"book","product_id":"FI_ETHUSD_210625","side":"buy","seq":12455348,"price":2495.55,"qty":0.0,"timestamp":1618678107425}
1618678107.495701: {"feed":"book","product_id":"FI_ETHUSD_210625","side":"sell","seq":12455349,"price":2518.0,"qty":0.0,"timestamp":1618678107425}
1618678107.495744: {"feed":"book","product_id":"FI_ETHUSD_210924","side":"sell","seq":3859128,"price":2659.95,"qty":50.0,"timestamp":1618678107425}
1618678107.495767: {"feed":"book","product_id":"FI_ETHUSD_210924","side":"sell","seq":3859129,"price":2659.85,"qty":840.0,"timestamp":1618678107425}
1618678107.4957922: {"feed":"book","product_id":"FI_XBTUSD_210924","side":"buy","seq":13850795,"price":67862.5,"qty":0.0,"timestamp":1618678107425}
1618678107.495818: {"feed":"book","product_id":"FI_ETHUSD_210924","side":"sell","seq":3859130,"price":2660.4,"qty":0.0,"timestamp":1618678107425}
1618678107.4958599: {"feed":"book","product_id":"FI_ETHUSD_210625","side":"buy","seq":12455350,"price":2493.15,"qty":5106.0,"timestamp":1618678107425}
1618678107.4958808: {"feed":"book","product_id":"FI_XBTUSD_210924","side":"sell","seq":13850796,"price":68292.5,"qty":0.0,"timestamp":1618678107425}
1618678107.495906: {"feed":"book","product_id":"FI_XBTUSD_210924","side":"sell","seq":13850797,"price":68291.5,"qty":10000.0,"timestamp":1618678107425}
1618678107.495948: {"feed":"book","product_id":"FI_ETHUSD_210625","side":"buy","seq":12455351,"price":2496.3,"qty":3000.0,"timestamp":1618678107425}
1618678107.4959722: {"feed":"book","product_id":"FI_XBTUSD_210430","side":"sell","seq":12237499,"price":61240.5,"qty":0.0,"timestamp":1618678107425}
1618678107.4959989: {"feed":"book","product_id":"FI_XBTUSD_210430","side":"sell","seq":12237500,"price":61239.5,"qty":10000.0,"timestamp":1618678107425}
1618678107.496022: {"feed":"book","product_id":"FI_ETHUSD_210625","side":"buy","seq":12455352,"price":2489.0,"qty":105667.0,"timestamp":1618678107425}
1618678107.496045: {"feed":"book","product_id":"FI_XBTUSD_210430","side":"buy","seq":12237501,"price":61159.5,"qty":186229.0,"timestamp":1618678107431}
1618678107.496087: {"feed":"book","product_id":"FI_XBTUSD_210430","side":"sell","seq":12237502,"price":61236.0,"qty":176479.0,"timestamp":1618678107431}
1618678107.496109: {"feed":"book","product_id":"FI_ETHUSD_210625","side":"sell","seq":12455353,"price":2509.25,"qty":229564.0,"timestamp":1618678107425}
1618678107.496129: {"feed":"book","product_id":"FI_XBTUSD_210430","side":"buy","seq":12237503,"price":61118.0,"qty":295776.0,"timestamp":1618678107431}
1618678107.496151: {"feed":"book","product_id":"FI_ETHUSD_210625","side":"buy","seq":12455354,"price":2498.95,"qty":139403.0,"timestamp":1618678107439}
1618678107.496192: {"feed":"book","product_id":"FI_XBTUSD_210430","side":"sell","seq":12237504,"price":61280.5,"qty":280290.0,"timestamp":1618678107431}
1618678107.496213: {"feed":"book","product_id":"FI_ETHUSD_210625","side":"sell","seq":12455355,"price":2503.95,"qty":135854.0,"timestamp":1618678107439}
1618678107.496236: {"feed":"book","product_id":"FI_XBTUSD_210430","side":"buy","seq":12237505,"price":61077.0,"qty":350549.0,"timestamp":1618678107431}
1618678107.496257: {"feed":"book","product_id":"FI_XBTUSD_210430","side":"sell","seq":12237506,"price":61325.0,"qty":332196.0,"timestamp":1618678107431}
1618678107.496278: {"feed":"book","product_id":"FI_ETHUSD_210625","side":"buy","seq":12455356,"price":2496.15,"qty":182296.0,"timestamp":1618678107439}
1618678107.4963: {"feed":"book","product_id":"FI_XBTUSD_210430","side":"buy","seq":12237507,"price":61035.5,"qty":383413.0,"timestamp":1618678107431}
1618678107.496321: {"feed":"book","product_id":"FI_ETHUSD_210625","side":"sell","seq":12455357,"price":2506.4,"qty":177655.0,"timestamp":1618678107439}
1618678107.4963431: {"feed":"book","product_id":"FI_XBTUSD_210430","side":"sell","seq":12237508,"price":61369.5,"qty":363339.0,"timestamp":1618678107431}
1618678107.496364: {"feed":"book","product_id":"FI_ETHUSD_210625","side":"buy","seq":12455358,"price":2493.35,"qty":214466.0,"timestamp":1618678107439}
1618678107.496386: {"feed":"book","product_id":"FI_XBTUSD_210430","side":"buy","seq":12237509,"price":60994.0,"qty":742961.0,"timestamp":1618678107431}
1618678107.496405: {"feed":"book","product_id":"FI_XBTUSD_210430","side":"sell","seq":12237510,"price":61414.0,"qty":467150.0,"timestamp":1618678107431}
1618678107.4964259: {"feed":"book","product_id":"FI_ETHUSD_210625","side":"sell","seq":12455359,"price":2508.9,"qty":209006.0,"timestamp":1618678107439}
1618678107.496448: {"feed":"book","product_id":"FI_ETHUSD_210625","side":"buy","seq":12455360,"price":2490.6,"qty":268082.0,"timestamp":1618678107439}
1618678107.496469: {"feed":"book","product_id":"FI_ETHUSD_210625","side":"sell","seq":12455361,"price":2511.35,"qty":261257.0,"timestamp":1618678107439}
1618678107.496491: {"feed":"book","product_id":"FI_ETHUSD_210625","side":"buy","seq":12455362,"price":2487.8,"qty":321699.0,"timestamp":1618678107439}
1618678107.496512: {"feed":"book","product_id":"FI_ETHUSD_210625","side":"sell","seq":12455363,"price":2513.85,"qty":346920.0,"timestamp":1618678107439}
1618678107.496532: {"feed":"book","product_id":"FI_XBTUSD_210924","side":"sell","seq":13850798,"price":68437.0,"qty":0.0,"timestamp":1618678107441}
1618678107.496555: {"feed":"book","product_id":"FI_XBTUSD_210924","side":"buy","seq":13850799,"price":67977.5,"qty":0.0,"timestamp":1618678107441}
1618678107.4965792: {"feed":"book","product_id":"FI_XBTUSD_210625","side":"buy","seq":21454867,"price":63895.5,"qty":20518.0,"timestamp":1618678107449}
1618678107.496602: {"feed":"book","product_id":"FI_ETHUSD_210625","side":"sell","seq":12455364,"price":2520.05,"qty":0.0,"timestamp":1618678107444}
1618678107.519949: {"feed":"book","product_id":"PI_BCHUSD","side":"sell","seq":16258310,"price":1062.5,"qty":2805.0,"timestamp":1618678107489}
1618678107.535201: {"feed":"book","product_id":"FI_XBTUSD_210430","side":"sell","seq":12237511,"price":61240.0,"qty":0.0,"timestamp":1618678107489}
1618678107.5352561: {"feed":"book","product_id":"FI_XBTUSD_210430","side":"sell","seq":12237512,"price":61235.5,"qty":1904.0,"timestamp":1618678107489}
1618678107.5352929: {"feed":"book","product_id":"FI_XBTUSD_210430","side":"sell","seq":12237513,"price":61239.5,"qty":0.0,"timestamp":1618678107489}
1618678107.535321: {"feed":"book","product_id":"FI_XBTUSD_210430","side":"sell","seq":12237514,"price":61255.5,"qty":10000.0,"timestamp":1618678107489}
1618678107.535346: {"feed":"book","product_id":"PI_BCHUSD","side":"buy","seq":16258311,"price":1059.9,"qty":3662.0,"timestamp":1618678107494}
1618678107.535372: {"feed":"book","product_id":"FI_ETHUSD_210625","side":"sell","seq":12455365,"price":2504.6,"qty":0.0,"timestamp":1618678107489}
1618678107.5354: {"feed":"book","product_id":"FI_ETHUSD_210625","side":"sell","seq":12455366,"price":2503.9,"qty":835.0,"timestamp":1618678107489}
1618678107.535424: {"feed":"book","product_id":"PI_BCHUSD","side":"sell","seq":16258312,"price":1064.1,"qty":4080.0,"timestamp":1618678107499}
1618678107.535445: {"feed":"book","product_id":"PI_BCHUSD","side":"sell","seq":16258313,"price":1063.9,"qty":37156.0,"timestamp":1618678107499}
1618678107.535465: {"feed":"book","product_id":"PI_BCHUSD","side":"buy","seq":16258314,"price":1058.9,"qty":14399.0,"timestamp":1618678107499}
1618678107.535485: {"feed":"book","product_id":"FI_XBTUSD_210625","side":"buy","seq":21454868,"price":63677.0,"qty":0.0,"timestamp":1618678107503}
1618678107.541107: {"feed":"book","product_id":"FI_XBTUSD_210430","side":"sell","seq":12237515,"price":61255.5,"qty":0.0,"timestamp":1618678107512}
1618678107.541167: {"feed":"book","product_id":"FI_XBTUSD_210430","side":"sell","seq":12237516,"price":61248.0,"qty":10000.0,"timestamp":1618678107512}
1618678107.5559502: {"feed":"book","product_id":"PI_BCHUSD","side":"sell","seq":16258315,"price":1062.7,"qty":16129.0,"timestamp":1618678107518}
1618678107.556041: {"feed":"book","product_id":"PI_BCHUSD","side":"buy","seq":16258316,"price":1059.0,"qty":34845.0,"timestamp":1618678107518}
1618678107.556073: {"feed":"book","product_id":"PI_BCHUSD","side":"buy","seq":16258317,"price":1059.4,"qty":3771.0,"timestamp":1618678107519}
1618678107.556104: {"feed":"book","product_id":"PI_BCHUSD","side":"sell","seq":16258318,"price":1062.9,"qty":20847.0,"timestamp":1618678107519}
1618678107.556129: {"feed":"book","product_id":"FI_ETHUSD_210625","side":"sell","seq":12455367,"price":2505.35,"qty":0.0,"timestamp":1618678107521}
1618678107.556164: {"feed":"book","product_id":"FI_ETHUSD_210625","side":"sell","seq":12455368,"price":2508.05,"qty":35586.0,"timestamp":1618678107521}
1618678107.563767: {"feed":"book","product_id":"FI_ETHUSD_210625","side":"sell","seq":12455369,"price":2521.05,"qty":0.0,"timestamp":1618678107521}
1618678107.563898: {"feed":"book","product_id":"FI_ETHUSD_210625","side":"sell","seq":12455370,"price":2530.05,"qty":47809.0,"timestamp":1618678107521}
1618678107.563963: {"feed":"book","product_id":"FI_ETHUSD_210625","side":"buy","seq":12455371,"price":2500.85,"qty":0.0,"timestamp":1618678107521}
1618678107.5640142: {"feed":"book","product_id":"FI_ETHUSD_210625","side":"buy","seq":12455372,"price":2500.35,"qty":201.0,"timestamp":1618678107521}
1618678107.5640588: {"feed":"book","product_id":"PI_BCHUSD","side":"sell","seq":16258319,"price":1063.7,"qty":31057.0,"timestamp":1618678107521}
1618678107.5641222: {"feed":"book","product_id":"PI_BCHUSD","side":"buy","seq":16258320,"price":1059.3,"qty":102413.0,"timestamp":1618678107521}
1618678107.564152: {"feed":"book","product_id":"PI_BCHUSD","side":"sell","seq":16258321,"price":1063.6,"qty":3642.0,"timestamp":1618678107521}
1618678107.5641742: {"feed":"book","product_id":"PI_BCHUSD","side":"sell","seq":16258322,"price":1062.8,"qty":3053.0,"timestamp":1618678107521}
1618678107.564194: {"feed":"book","product_id":"PI_BCHUSD","side":"sell","seq":16258323,"price":1062.9,"qty":24736.0,"timestamp":1618678107521}
1618678107.571583: {"feed":"book","product_id":"FI_XBTUSD_210430","side":"buy","seq":12237517,"price":61104.0,"qty":19764.0,"timestamp":1618678107527}
1618678107.571708: {"feed":"book","product_id":"PI_BCHUSD","side":"sell","seq":16258324,"price":1062.5,"qty":5812.0,"timestamp":1618678107522}
1618678107.571757: {"feed":"book","product_id":"PI_BCHUSD","side":"buy","seq":16258325,"price":1059.7,"qty":8945.0,"timestamp":1618678107524}
1618678107.571795: {"feed":"book","product_id":"PI_BCHUSD","side":"sell","seq":16258326,"price":1063.2,"qty":3885.0,"timestamp":1618678107524}
1618678107.571836: {"feed":"book","product_id":"FI_ETHUSD_210625","side":"sell","seq":12455373,"price":2513.85,"qty":313508.0,"timestamp":1618678107522}
1618678107.5718699: {"feed":"book","product_id":"FI_ETHUSD_210625","side":"sell","seq":12455374,"price":2512.45,"qty":32579.0,"timestamp":1618678107522}
1618678107.5719092: {"feed":"book","product_id":"FI_ETHUSD_210924","side":"sell","seq":3859131,"price":2675.55,"qty":0.0,"timestamp":1618678107524}
1618678107.57198: {"feed":"book","product_id":"FI_ETHUSD_210625","side":"sell","seq":12455375,"price":2505.15,"qty":1894.0,"timestamp":1618678107522}
1618678107.572001: {"feed":"book","product_id":"FI_ETHUSD_210625","side":"sell","seq":12455376,"price":2504.95,"qty":10219.0,"timestamp":1618678107522}
1618678107.572024: {"feed":"book","product_id":"FI_ETHUSD_210625","side":"sell","seq":12455377,"price":2515.95,"qty":0.0,"timestamp":1618678107527}
1618678107.572048: {"feed":"book","product_id":"FI_ETHUSD_210924","side":"buy","seq":3859132,"price":2637.45,"qty":0.0,"timestamp":1618678107524}
1618678107.572074: {"feed":"book","product_id":"FI_XBTUSD_210924","side":"sell","seq":13850800,"price":68327.0,"qty":0.0,"timestamp":1618678107524}
1618678107.581459: {"feed":"book","product_id":"FI_ETHUSD_210625","side":"sell","seq":12455378,"price":2507.55,"qty":0.0,"timestamp":1618678107538}
1618678107.585757: {"feed":"book","product_id":"FI_XBTUSD_210430","side":"buy","seq":12237518,"price":59445.5,"qty":52932.0,"timestamp":1618678107545}
1618678107.5858712: {"feed":"book","product_id":"FI_ETHUSD_210625","side":"buy","seq":12455379,"price":2496.75,"qty":0.0,"timestamp":1618678107552}
1618678107.5923798: {"feed":"book","product_id":"FI_XBTUSD_210625","side":"sell","seq":21454869,"price":64013.0,"qty":0.0,"timestamp":1618678107554}
1618678107.5959492: {"feed":"book","product_id":"FI_ETHUSD_210430","side":"sell","seq":4780818,"price":2401.95,"qty":0.0,"timestamp":1618678107559}
1618678107.596082: {"feed":"book","product_id":"FI_ETHUSD_210430","side":"sell","seq":4780819,"price":2399.6,"qty":584747.0,"timestamp":1618678107559}
1618678107.596163: {"feed":"book","product_id":"FI_ETHUSD_210625","side":"sell","seq":12455380,"price":2509.25,"qty":4563.0,"timestamp":1618678107559}
1618678107.596212: {"feed":"book","product_id":"FI_ETHUSD_210625","side":"sell","seq":12455381,"price":2508.85,"qty":225001.0,"timestamp":1618678107559}
1618678107.5962398: {"feed":"book","product_id":"FI_XBTUSD_210924","side":"sell","seq":13850801,"price":68436.5,"qty":0.0,"timestamp":1618678107559}
1618678107.596271: {"feed":"book","product_id":"FI_XBTUSD_210924","side":"sell","seq":13850802,"price":68393.5,"qty":250001.0,"timestamp":1618678107559}
1618678107.5962949: {"feed":"book","product_id":"FI_ETHUSD_210625","side":"sell","seq":12455382,"price":2512.5,"qty":0.0,"timestamp":1618678107559}
1618678107.596321: {"feed":"book","product_id":"FI_ETHUSD_210625","side":"sell","seq":12455383,"price":2512.4,"qty":303574.0,"timestamp":1618678107559}
1618678107.5963461: {"feed":"book","product_id":"FI_XBTUSD_210430","side":"buy","seq":12237519,"price":60994.0,"qty":492960.0,"timestamp":1618678107559}
1618678107.5963678: {"feed":"book","product_id":"FI_XBTUSD_210430","side":"buy","seq":12237520,"price":61036.0,"qty":250001.0,"timestamp":1618678107559}
1618678107.596392: {"feed":"book","product_id":"FI_ETHUSD_210625","side":"sell","seq":12455384,"price":2515.9,"qty":0.0,"timestamp":1618678107559}
1618678107.596417: {"feed":"book","product_id":"FI_ETHUSD_210625","side":"sell","seq":12455385,"price":2516.25,"qty":25003.0,"timestamp":1618678107559}
1618678107.609976: {"feed":"book","product_id":"FI_XBTUSD_210625","side":"sell","seq":21454870,"price":64181.0,"qty":0.0,"timestamp":1618678107578}
1618678107.614965: {"feed":"book","product_id":"PI_BCHUSD","side":"sell","seq":16258327,"price":1062.8,"qty":50.0,"timestamp":1618678107588}
1618678107.615078: {"feed":"book","product_id":"PI_BCHUSD","side":"sell","seq":16258328,"price":1062.7,"qty":0.0,"timestamp":1618678107591}
1618678107.618637: {"feed":"book","product_id":"PI_BCHUSD","side":"buy","seq":16258329,"price":1057.7,"qty":32101.0,"timestamp":1618678107591}
1618678107.618769: {"feed":"book","product_id":"PI_BCHUSD","side":"buy","seq":16258330,"price":1059.3,"qty":72684.0,"timestamp":1618678107592}
1618678107.618818: {"feed":"book","product_id":"FI_XBTUSD_210924","side":"sell","seq":13850803,"price":68335.0,"qty":3000.0,"timestamp":1618678107592}
1618678107.618865: {"feed":"book","product_id":"FI_XBTUSD_210924","side":"sell","seq":13850804,"price":68423.0,"qty":24960.0,"timestamp":1618678107592}
1618678107.618905: {"feed":"book","product_id":"FI_XBTUSD_210924","side":"buy","seq":13850805,"price":68051.0,"qty":3000.0,"timestamp":1618678107592}
1618678107.618944: {"feed":"book","product_id":"FI_XBTUSD_210924","side":"sell","seq":13850806,"price":68511.0,"qty":24960.0,"timestamp":1618678107592}
1618678107.618978: {"feed":"book","product_id":"PI_BCHUSD","side":"buy","seq":16258331,"price":1059.6,"qty":0.0,"timestamp":1618678107594}
1618678107.621484: {"feed":"book","product_id":"PI_BCHUSD","side":"buy","seq":16258332,"price":1059.2,"qty":3693.0,"timestamp":1618678107594}
1618678107.6215968: {"feed":"book","product_id":"FI_XBTUSD_210924","side":"buy","seq":13850807,"price":67963.5,"qty":22293.0,"timestamp":1618678107592}
1618678107.6216671: {"feed":"book","product_id":"FI_XBTUSD_210924","side":"buy","seq":13850808,"price":67875.5,"qty":22293.0,"timestamp":1618678107592}
1618678107.621713: {"feed":"book","product_id":"PI_BCHUSD","side":"sell","seq":16258333,"price":1062.9,"qty":20847.0,"timestamp":1618678107595}
1618678107.6217542: {"feed":"book","product_id":"PI_BCHUSD","side":"buy","seq":16258334,"price":1058.6,"qty":8997.0,"timestamp":1618678107596}
1618678107.622049: {"feed":"book","product_id":"FI_XBTUSD_210625","side":"buy","seq":21454871,"price":57200.5,"qty":30165.0,"timestamp":1618678107598}
1618678107.643499: {"feed":"book","product_id":"FI_XBTUSD_210625","side":"buy","seq":21454872,"price":63725.0,"qty":25088.0,"timestamp":1618678107600}
1618678107.643625: {"feed":"book","product_id":"FI_XBTUSD_210625","side":"buy","seq":21454873,"price":63727.5,"qty":28368.0,"timestamp":1618678107600}
1618678107.6436732: {"feed":"book","product_id":"PI_BCHUSD","side":"buy","seq":16258335,"price":1057.9,"qty":4018.0,"timestamp":1618678107602}
1618678107.64372: {"feed":"book","product_id":"FI_XBTUSD_210924","side":"buy","seq":13850809,"price":67723.5,"qty":0.0,"timestamp":1618678107602}
1618678107.643771: {"feed":"book","product_id":"FI_XBTUSD_210625","side":"sell","seq":21454874,"price":63960.5,"qty":0.0,"timestamp":1618678107606}
1618678107.6438222: {"feed":"book","product_id":"FI_ETHUSD_210625","side":"sell","seq":12455386,"price":2505.65,"qty":0.0,"timestamp":1618678107610}
1618678107.643869: {"feed":"book","product_id":"FI_ETHUSD_210625","side":"buy","seq":12455387,"price":2496.3,"qty":0.0,"timestamp":1618678107610}
1618678107.643894: {"feed":"book","product_id":"FI_ETHUSD_210625","side":"sell","seq":12455388,"price":2509.3,"qty":0.0,"timestamp":1618678107610}
1618678107.643918: {"feed":"book","product_id":"FI_XBTUSD_210625","side":"sell","seq":21454875,"price":63960.0,"qty":1000.0,"timestamp":1618678107612}
1618678107.6439419: {"feed":"book","product_id":"FI_ETHUSD_210625","side":"buy","seq":12455389,"price":2493.1,"qty":0.0,"timestamp":1618678107610}
1618678107.643967: {"feed":"book","product_id":"FI_ETHUSD_210625","side":"sell","seq":12455390,"price":2512.95,"qty":0.0,"timestamp":1618678107610}
1618678107.643991: {"feed":"book","product_id":"FI_ETHUSD_210625","side":"sell","seq":12455391,"price":2516.6,"qty":0.0,"timestamp":1618678107610}
1618678107.6506371: {"feed":"book","product_id":"FI_XBTUSD_210625","side":"buy","seq":21454876,"price":63926.0,"qty":0.0,"timestamp":1618678107626}
1618678107.650765: {"feed":"book","product_id":"FI_XBTUSD_210625","side":"buy","seq":21454877,"price":63904.5,"qty":1018.0,"timestamp":1618678107626}
1618678107.6636522: {"feed":"book","product_id":"PI_BCHUSD","side":"sell","seq":16258336,"price":1062.7,"qty":4995.0,"timestamp":1618678107635}
1618678107.663779: {"feed":"book","product_id":"PI_BCHUSD","side":"sell","seq":16258337,"price":1063.1,"qty":4993.0,"timestamp":1618678107635}
1618678107.663831: {"feed":"book","product_id":"FI_BCHUSD_210625","side":"buy","seq":2240176,"price":1123.9,"qty":0.0,"timestamp":1618678107635}
1618678107.663886: {"feed":"book","product_id":"FI_BCHUSD_210625","side":"buy","seq":2240177,"price":1108.3,"qty":4513.0,"timestamp":1618678107635}
1618678107.6639261: {"feed":"book","product_id":"PI_BCHUSD","side":"sell","seq":16258338,"price":1063.5,"qty":4992.0,"timestamp":1618678107635}
1618678107.6652281: {"feed":"book","product_id":"PI_BCHUSD","side":"sell","seq":16258339,"price":1063.4,"qty":0.0,"timestamp":1618678107635}
1618678107.665355: {"feed":"book","product_id":"PI_BCHUSD","side":"buy","seq":16258340,"price":1058.6,"qty":4060.0,"timestamp":1618678107635}
1618678107.66541: {"feed":"book","product_id":"PI_BCHUSD","side":"buy","seq":16258341,"price":1057.0,"qty":4937.0,"timestamp":1618678107635}
1618678107.665461: {"feed":"book","product_id":"PI_BCHUSD","side":"sell","seq":16258342,"price":1063.8,"qty":31562.0,"timestamp":1618678107636}
1618678107.665498: {"feed":"book","product_id":"PI_BCHUSD","side":"sell","seq":16258343,"price":1064.2,"qty":7800.0,"timestamp":1618678107637}
1618678107.67798: {"feed":"book","product_id":"FI_ETHUSD_210924","side":"sell","seq":3859133,"price":2671.2,"qty":0.0,"timestamp":1618678107642}
1618678107.678106: {"feed":"book","product_id":"FI_XBTUSD_210625","side":"buy","seq":21454878,"price":63761.0,"qty":3000.0,"timestamp":1618678107643}
1618678107.678174: {"feed":"book","product_id":"FI_XBTUSD_210625","side":"buy","seq":21454879,"price":63660.5,"qty":29467.0,"timestamp":1618678107643}
1618678107.678216: {"feed":"book","product_id":"FI_XBTUSD_210625","side":"buy","seq":21454880,"price":63560.5,"qty":19467.0,"timestamp":1618678107643}
1618678107.678256: {"feed":"book","product_id":"FI_XBTUSD_210625","side":"buy","seq":21454881,"price":63460.0,"qty":19466.0,"timestamp":1618678107643}
1618678107.684054: {"feed":"book","product_id":"PI_BCHUSD","side":"sell","seq":16258344,"price":1063.0,"qty":36919.0,"timestamp":1618678107647}
1618678107.684163: {"feed":"book","product_id":"PI_BCHUSD","side":"buy","seq":16258345,"price":1059.3,"qty":42803.0,"timestamp":1618678107652}
1618678107.6842098: {"feed":"book","product_id":"PI_BCHUSD","side":"buy","seq":16258346,"price":1058.2,"qty":31454.0,"timestamp":1618678107652}
1618678107.684306: {"feed":"book","product_id":"FI_XBTUSD_210625","side":"buy","seq":21454882,"price":57200.5,"qty":33061.0,"timestamp":1618678107653}
1618678107.6887: {"feed":"book","product_id":"PI_BCHUSD","side":"buy","seq":16258347,"price":1060.1,"qty":0.0,"timestamp":1618678107659}
1618678107.688828: {"feed":"book","product_id":"FI_ETHUSD_210430","side":"sell","seq":4780820,"price":2399.6,"qty":0.0,"timestamp":1618678107659}
1618678107.688891: {"feed":"book","product_id":"FI_ETHUSD_210430","side":"sell","seq":4780821,"price":2401.95,"qty":584747.0,"timestamp":1618678107659}
1618678107.688944: {"feed":"book","product_id":"FI_XBTUSD_210625","side":"sell","seq":21454883,"price":64260.0,"qty":0.0,"timestamp":1618678107659}
1618678107.688992: {"feed":"book","product_id":"FI_XBTUSD_210625","side":"sell","seq":21454884,"price":64255.5,"qty":125003.0,"timestamp":1618678107659}
1618678107.705526: {"feed":"book","product_id":"PI_BCHUSD","side":"sell","seq":16258348,"price":1062.2,"qty":2929.0,"timestamp":1618678107675}
1618678107.710954: {"feed":"book","product_id":"PI_BCHUSD","side":"sell","seq":16258349,"price":1062.8,"qty":0.0,"timestamp":1618678107676}
1618678107.7110422: {"feed":"book","product_id":"PI_BCHUSD","side":"sell","seq":16258350,"price":1062.4,"qty":50.0,"timestamp":1618678107676}
1618678107.7110982: {"feed":"book","product_id":"PI_BCHUSD","side":"sell","seq":16258351,"price":1062.6,"qty":3847.0,"timestamp":1618678107677}
1618678107.7111418: {"feed":"book","product_id":"FI_XBTUSD_210924","side":"sell","seq":13850810,"price":68277.0,"qty":3000.0,"timestamp":1618678107677}
1618678107.711186: {"feed":"book","product_id":"FI_BCHUSD_210430","side":"sell","seq":1411849,"price":1079.8,"qty":14399.0,"timestamp":1618678107677}
1618678107.713119: {"feed":"book","product_id":"PI_BCHUSD","side":"sell","seq":16258352,"price":1062.9,"qty":0.0,"timestamp":1618678107685}
1618678107.721378: {"feed":"book","product_id":"PI_BCHUSD","side":"sell","seq":16258353,"price":1063.3,"qty":10633.0,"timestamp":1618678107687}
1618678107.721503: {"feed":"book","product_id":"PI_BCHUSD","side":"sell","seq":16258354,"price":1062.7,"qty":8943.0,"timestamp":1618678107689}
1618678107.721552: {"feed":"book","product_id":"PI_BCHUSD","side":"buy","seq":16258355,"price":1059.4,"qty":7606.0,"timestamp":1618678107689}
1618678107.721591: {"feed":"book","product_id":"PI_BCHUSD","side":"buy","seq":16258356,"price":1059.9,"qty":7469.0,"timestamp":1618678107689}
1618678107.721625: {"feed":"book","product_id":"PI_BCHUSD","side":"sell","seq":16258357,"price":1063.1,"qty":9028.0,"timestamp":1618678107689}
1618678107.721656: {"feed":"book","product_id":"FI_ETHUSD_210625","side":"sell","seq":12455392,"price":2506.15,"qty":0.0,"timestamp":1618678107690}
1618678107.721706: {"feed":"book","product_id":"FI_ETHUSD_210625","side":"sell","seq":12455393,"price":2509.8,"qty":0.0,"timestamp":1618678107690}
1618678107.721747: {"feed":"book","product_id":"FI_ETHUSD_210625","side":"sell","seq":12455394,"price":2513.45,"qty":0.0,"timestamp":1618678107690}
1618678107.7217941: {"feed":"book","product_id":"PI_BCHUSD","side":"sell","seq":16258358,"price":1063.3,"qty":0.0,"timestamp":1618678107692}
1618678107.721837: {"feed":"book","product_id":"PI_BCHUSD","side":"sell","seq":16258359,"price":1063.2,"qty":14518.0,"timestamp":1618678107692}
1618678107.730643: {"feed":"book","product_id":"FI_XBTUSD_210924","side":"sell","seq":13850811,"price":68293.5,"qty":0.0,"timestamp":1618678107702}
1618678107.7307332: {"feed":"book","product_id":"FI_XBTUSD_210924","side":"sell","seq":13850812,"price":68276.5,"qty":50.0,"timestamp":1618678107702}
1618678107.747038: {"feed":"book","product_id":"FI_XBTUSD_210924","side":"buy","seq":13850813,"price":52552.5,"qty":59077.0,"timestamp":1618678107713}
1618678107.747147: {"feed":"book","product_id":"PI_BCHUSD","side":"buy","seq":16258360,"price":1059.3,"qty":12540.0,"timestamp":1618678107722}
1618678107.759536: {"feed":"book","product_id":"PI_BCHUSD","side":"sell","seq":16258361,"price":1068.9,"qty":0.0,"timestamp":1618678107726}
1618678107.759665: {"feed":"book","product_id":"FI_ETHUSD_210625","side":"buy","seq":12455395,"price":2497.65,"qty":408.0,"timestamp":1618678107726}
1618678107.759721: {"feed":"book","product_id":"FI_ETHUSD_210625","side":"buy","seq":12455396,"price":2496.1,"qty":408.0,"timestamp":1618678107726}
1618678107.7597811: {"feed":"book","product_id":"PI_BCHUSD","side":"sell","seq":16258362,"price":1080.3,"qty":97867.0,"timestamp":1618678107726}
1618678107.759826: {"feed":"book","product_id":"PI_BCHUSD","side":"sell","seq":16258363,"price":1083.6,"qty":75347.0,"timestamp":1618678107726}
1618678107.759847: {"feed":"book","product_id":"PI_BCHUSD","side":"sell","seq":16258364,"price":1150.0,"qty":300.0,"timestamp":1618678107726}
1618678107.759865: {"feed":"book","product_id":"PI_BCHUSD","side":"buy","seq":16258365,"price":1056.0,"qty":0.0,"timestamp":1618678107726}
1618678107.759893: {"feed":"book","product_id":"FI_ETHUSD_210625","side":"buy","seq":12455397,"price":2497.65,"qty":0.0,"timestamp":1618678107726}
1618678107.7599192: {"feed":"book","product_id":"FI_ETHUSD_210625","side":"buy","seq":12455398,"price":2496.1,"qty":816.0,"timestamp":1618678107726}
1618678107.759939: {"feed":"book","product_id":"PI_BCHUSD","side":"buy","seq":16258366,"price":1048.1,"qty":253242.0,"timestamp":1618678107726}
1618678107.759959: {"feed":"book","product_id":"PI_BCHUSD","side":"buy","seq":16258367,"price":1034.0,"qty":100.0,"timestamp":1618678107726}
1618678107.759979: {"feed":"book","product_id":"PI_BCHUSD","side":"buy","seq":16258368,"price":1030.8,"qty":73565.0,"timestamp":1618678107726}
1618678107.759997: {"feed":"book","product_id":"FI_ETHUSD_210625","side":"sell","seq":12455399,"price":2508.05,"qty":16352.0,"timestamp":1618678107726}
1618678107.760017: {"feed":"book","product_id":"FI_ETHUSD_210625","side":"sell","seq":12455400,"price":2509.2,"qty":22786.0,"timestamp":1618678107726}
1618678107.760041: {"feed":"book","product_id":"FI_XBTUSD_210924","side":"sell","seq":13850814,"price":68291.5,"qty":0.0,"timestamp":1618678107728}
1618678107.760067: {"feed":"book","product_id":"FI_XBTUSD_210924","side":"sell","seq":13850815,"price":68276.5,"qty":10050.0,"timestamp":1618678107728}
1618678107.760087: {"feed":"book","product_id":"FI_ETHUSD_210625","side":"sell","seq":12455401,"price":2508.05,"qty":0.0,"timestamp":1618678107726}
1618678107.7601101: {"feed":"book","product_id":"FI_ETHUSD_210625","side":"sell","seq":12455402,"price":2509.2,"qty":45572.0,"timestamp":1618678107726}
1618678107.767833: {"feed":"book","product_id":"FI_XRPUSD_210625","side":"buy","seq":3631482,"price":1.6938,"qty":0.0,"timestamp":1618678107734}
1618678107.76796: {"feed":"book","product_id":"FI_XRPUSD_210625","side":"buy","seq":3631483,"price":1.6933,"qty":68.0,"timestamp":1618678107734}
1618678107.768023: {"feed":"book","product_id":"FI_ETHUSD_210924","side":"buy","seq":3859134,"price":2630.35,"qty":0.0,"timestamp":1618678107736}
1618678107.774168: {"feed":"book","product_id":"FI_ETHUSD_210430","side":"sell","seq":4780822,"price":2402.0,"qty":0.0,"timestamp":1618678107738}
1618678107.774254: {"feed":"book","product_id":"FI_XRPUSD_210625","side":"sell","seq":3631484,"price":1.699,"qty":0.0,"timestamp":1618678107738}
1618678107.7743082: {"feed":"book","product_id":"FI_XRPUSD_210625","side":"sell","seq":3631485,"price":1.6986,"qty":18968.0,"timestamp":1618678107738}
1618678107.774358: {"feed":"book","product_id":"FI_XRPUSD_210625","side":"buy","seq":3631486,"price":1.6925,"qty":0.0,"timestamp":1618678107738}
1618678107.774424: {"feed":"book","product_id":"FI_XRPUSD_210625","side":"buy","seq":3631487,"price":1.6917,"qty":19200.0,"timestamp":1618678107738}
1618678107.7744498: {"feed":"book","product_id":"FI_XRPUSD_210625","side":"sell","seq":3631488,"price":1.7055,"qty":0.0,"timestamp":1618678107738}
1618678107.774475: {"feed":"book","product_id":"FI_XRPUSD_210625","side":"sell","seq":3631489,"price":1.7038,"qty":57600.0,"timestamp":1618678107738}
1618678107.7745001: {"feed":"book","product_id":"FI_XRPUSD_210625","side":"buy","seq":3631490,"price":1.6882,"qty":0.0,"timestamp":1618678107738}
1618678107.774524: {"feed":"book","product_id":"FI_XRPUSD_210625","side":"buy","seq":3631491,"price":1.6865,"qty":57600.0,"timestamp":1618678107738}
1618678107.7745469: {"feed":"book","product_id":"PI_BCHUSD","side":"buy","seq":16258369,"price":1059.2,"qty":26324.0,"timestamp":1618678107742}
1618678107.77457: {"feed":"book","product_id":"PI_BCHUSD","side":"buy","seq":16258370,"price":1059.2,"qty":43659.0,"timestamp":1618678107744}
1618678107.77459: {"feed":"book","product_id":"PI_BCHUSD","side":"buy","seq":16258371,"price":1058.7,"qty":0.0,"timestamp":1618678107744}
1618678107.774614: {"feed":"book","product_id":"PI_BCHUSD","side":"buy","seq":16258372,"price":1057.0,"qty":7404.0,"timestamp":1618678107744}
1618678107.776382: {"feed":"book","product_id":"FI_XRPUSD_210625","side":"sell","seq":3631492,"price":1.6987,"qty":50.0,"timestamp":1618678107749}
1618678107.776451: {"feed":"book","product_id":"FI_XRPUSD_210625","side":"sell","seq":3631493,"price":1.6985,"qty":768.0,"timestamp":1618678107749}
1618678107.788209: {"feed":"book","product_id":"FI_XBTUSD_210625","side":"sell","seq":21454885,"price":64255.5,"qty":0.0,"timestamp":1618678107754}
1618678107.7883399: {"feed":"book","product_id":"FI_XBTUSD_210625","side":"sell","seq":21454886,"price":64253.5,"qty":125003.0,"timestamp":1618678107754}
1618678107.788403: {"feed":"book","product_id":"FI_ETHUSD_210430","side":"sell","seq":4780823,"price":2401.95,"qty":0.0,"timestamp":1618678107754}
1618678107.788456: {"feed":"book","product_id":"FI_ETHUSD_210430","side":"sell","seq":4780824,"price":2402.2,"qty":584747.0,"timestamp":1618678107754}
1618678107.802811: {"feed":"book","product_id":"FI_XBTUSD_210625","side":"sell","seq":21454887,"price":64001.0,"qty":10000.0,"timestamp":1618678107771}
1618678107.802987: {"feed":"book","product_id":"FI_XBTUSD_210625","side":"buy","seq":21454888,"price":63799.5,"qty":10000.0,"timestamp":1618678107771}
1618678107.803041: {"feed":"book","product_id":"FI_XRPUSD_210625","side":"sell","seq":3631494,"price":1.6987,"qty":0.0,"timestamp":1618678107769}
1618678107.803096: {"feed":"book","product_id":"FI_XRPUSD_210625","side":"sell","seq":3631495,"price":1.6984,"qty":50.0,"timestamp":1618678107769}
1618678107.808966: {"feed":"book","product_id":"FI_XRPUSD_210625","side":"sell","seq":3631496,"price":1.6985,"qty":0.0,"timestamp":1618678107784}
1618678107.809027: {"feed":"book","product_id":"FI_XRPUSD_210625","side":"sell","seq":3631497,"price":1.6983,"qty":768.0,"timestamp":1618678107784}
1618678107.821526: {"feed":"book","product_id":"PI_BCHUSD","side":"buy","seq":16258373,"price":1058.9,"qty":0.0,"timestamp":1618678107793}
1618678107.834681: {"feed":"book","product_id":"PI_BCHUSD","side":"sell","seq":16258374,"price":1062.4,"qty":0.0,"timestamp":1618678107800}
1618678107.8348072: {"feed":"book","product_id":"PI_BCHUSD","side":"sell","seq":16258375,"price":1062.1,"qty":50.0,"timestamp":1618678107800}
1618678107.8441348: {"feed":"book","product_id":"PI_BCHUSD","side":"sell","seq":16258376,"price":1063.9,"qty":31083.0,"timestamp":1618678107810}
1618678107.844213: {"feed":"book","product_id":"PI_BCHUSD","side":"sell","seq":16258377,"price":1063.7,"qty":37130.0,"timestamp":1618678107810}
1618678107.844243: {"feed":"book","product_id":"FI_ETHUSD_210924","side":"buy","seq":3859135,"price":2641.85,"qty":2000.0,"timestamp":1618678107809}
1618678107.84431: {"feed":"book","product_id":"FI_XRPUSD_210625","side":"sell","seq":3631498,"price":1.6984,"qty":0.0,"timestamp":1618678107814}
1618678107.844346: {"feed":"book","product_id":"FI_XRPUSD_210625","side":"sell","seq":3631499,"price":1.6982,"qty":50.0,"timestamp":1618678107814}
1618678107.84847: {"feed":"book","product_id":"FI_XRPUSD_210625","side":"sell","seq":3631500,"price":1.6983,"qty":0.0,"timestamp":1618678107820}
1618678107.848521: {"feed":"book","product_id":"FI_XRPUSD_210625","side":"sell","seq":3631501,"price":1.6981,"qty":768.0,"timestamp":1618678107820}
1618678107.868347: {"feed":"book","product_id":"FI_XBTUSD_210625","side":"buy","seq":21454889,"price":63878.0,"qty":0.0,"timestamp":1618678107831}
1618678107.868478: {"feed":"book","product_id":"FI_XBTUSD_210625","side":"buy","seq":21454890,"price":63896.0,"qty":1162.0,"timestamp":1618678107831}
1618678107.8685398: {"feed":"book","product_id":"FI_ETHUSD_210625","side":"sell","seq":12455403,"price":2504.4,"qty":3000.0,"timestamp":1618678107834}
1618678107.8685892: {"feed":"book","product_id":"FI_ETHUSD_210625","side":"sell","seq":12455404,"price":2508.05,"qty":62000.0,"timestamp":1618678107834}
1618678107.868629: {"feed":"book","product_id":"FI_ETHUSD_210625","side":"buy","seq":12455405,"price":2495.75,"qty":3000.0,"timestamp":1618678107834}
1618678107.86867: {"feed":"book","product_id":"FI_ETHUSD_210625","side":"sell","seq":12455406,"price":2511.7,"qty":62000.0,"timestamp":1618678107834}
1618678107.868706: {"feed":"book","product_id":"FI_ETHUSD_210625","side":"buy","seq":12455407,"price":2492.1,"qty":105653.0,"timestamp":1618678107834}
1618678107.868742: {"feed":"book","product_id":"FI_ETHUSD_210625","side":"sell","seq":12455408,"price":2515.35,"qty":62000.0,"timestamp":1618678107835}
1618678107.8741171: {"feed":"book","product_id":"FI_BCHUSD_210625","side":"buy","seq":2240178,"price":1129.5,"qty":0.0,"timestamp":1618678107844}
1618678107.897404: {"feed":"book","product_id":"FI_XBTUSD_210924","side":"sell","seq":13850816,"price":68313.5,"qty":3000.0,"timestamp":1618678107866}
1618678107.911927: {"feed":"book","product_id":"FI_XBTUSD_210625","side":"buy","seq":21454891,"price":63669.0,"qty":6013.0,"timestamp":1618678107877}
1618678107.926914: {"feed":"book","product_id":"FI_XBTUSD_210924","side":"sell","seq":13850817,"price":68277.0,"qty":0.0,"timestamp":1618678107900}
1618678107.9334831: {"feed":"book","product_id":"FI_XBTUSD_210430","side":"buy","seq":12237521,"price":60661.5,"qty":500.0,"timestamp":1618678107901}
1618678107.933612: {"feed":"book","product_id":"FI_XBTUSD_210430","side":"sell","seq":12237522,"price":61948.0,"qty":500.0,"timestamp":1618678107901}
1618678107.9512901: {"feed":"book","product_id":"PI_BCHUSD","side":"buy","seq":16258378,"price":1059.6,"qty":3646.0,"timestamp":1618678107908}
1618678107.951484: {"feed":"book","product_id":"FI_ETHUSD_210924","side":"sell","seq":3859136,"price":2659.9,"qty":0.0,"timestamp":1618678107910}
1618678107.951526: {"feed":"book","product_id":"FI_ETHUSD_210924","side":"sell","seq":3859137,"price":2659.8,"qty":21000.0,"timestamp":1618678107910}
1618678107.9515562: {"feed":"book","product_id":"FI_XBTUSD_210430","side":"sell","seq":12237523,"price":61344.5,"qty":0.0,"timestamp":1618678107910}
1618678107.951585: {"feed":"book","product_id":"FI_XBTUSD_210430","side":"sell","seq":12237524,"price":61327.0,"qty":102000.0,"timestamp":1618678107910}
1618678107.9516091: {"feed":"book","product_id":"FI_ETHUSD_210625","side":"buy","seq":12455409,"price":2496.05,"qty":0.0,"timestamp":1618678107909}
1618678107.951637: {"feed":"book","product_id":"FI_ETHUSD_210625","side":"buy","seq":12455410,"price":2495.1,"qty":48000.0,"timestamp":1618678107909}
1618678107.951662: {"feed":"book","product_id":"FI_XBTUSD_210625","side":"buy","seq":21454892,"price":63904.0,"qty":0.0,"timestamp":1618678107913}
1618678107.951688: {"feed":"book","product_id":"FI_XBTUSD_210625","side":"buy","seq":21454893,"price":63891.5,"qty":48000.0,"timestamp":1618678107913}
1618678107.951712: {"feed":"book","product_id":"FI_XBTUSD_210625","side":"buy","seq":21454894,"price":63707.5,"qty":0.0,"timestamp":1618678107913}
1618678107.951736: {"feed":"book","product_id":"FI_XBTUSD_210625","side":"buy","seq":21454895,"price":63673.5,"qty":192000.0,"timestamp":1618678107913}
1618678107.951759: {"feed":"book","product_id":"FI_XBTUSD_210924","side":"sell","seq":13850818,"price":68276.5,"qty":50.0,"timestamp":1618678107913}
1618678107.95178: {"feed":"book","product_id":"FI_XBTUSD_210924","side":"sell","seq":13850819,"price":68291.5,"qty":10000.0,"timestamp":1618678107913}
1618678107.961146: {"feed":"book","product_id":"FI_XBTUSD_210924","side":"buy","seq":13850820,"price":67933.5,"qty":0.0,"timestamp":1618678107913}
1618678107.9612749: {"feed":"book","product_id":"FI_XBTUSD_210924","side":"buy","seq":13850821,"price":67889.0,"qty":168000.0,"timestamp":1618678107913}
1618678107.9695208: {"feed":"book","product_id":"FI_ETHUSD_210625","side":"buy","seq":12455411,"price":2496.1,"qty":408.0,"timestamp":1618678107932}
1618678107.9696379: {"feed":"book","product_id":"FI_ETHUSD_210625","side":"buy","seq":12455412,"price":2499.85,"qty":225.0,"timestamp":1618678107932}
1618678107.969706: {"feed":"book","product_id":"FI_ETHUSD_210625","side":"sell","seq":12455413,"price":2504.95,"qty":0.0,"timestamp":1618678107932}
1618678107.969744: {"feed":"book","product_id":"FI_ETHUSD_210625","side":"sell","seq":12455414,"price":2503.9,"qty":8069.0,"timestamp":1618678107932}
1618678107.969769: {"feed":"book","product_id":"FI_ETHUSD_210625","side":"sell","seq":12455415,"price":2509.2,"qty":22786.0,"timestamp":1618678107932}
1618678107.96979: {"feed":"book","product_id":"FI_ETHUSD_210625","side":"sell","seq":12455416,"price":2506.35,"qty":14420.0,"timestamp":1618678107932}
1618678107.969815: {"feed":"book","product_id":"PI_BCHUSD","side":"buy","seq":16258379,"price":1059.6,"qty":7544.0,"timestamp":1618678107923}
1618678107.9698381: {"feed":"book","product_id":"FI_ETHUSD_210625","side":"buy","seq":12455417,"price":2500.35,"qty":0.0,"timestamp":1618678107933}
1618678107.969864: {"feed":"book","product_id":"FI_ETHUSD_210625","side":"buy","seq":12455418,"price":2499.85,"qty":450.0,"timestamp":1618678107933}
1618678107.9698849: {"feed":"book","product_id":"FI_ETHUSD_210430","side":"buy","seq":4780825,"price":2351.1,"qty":99599.0,"timestamp":1618678107931}
1618678107.9699352: {"feed":"book","product_id":"FI_ETHUSD_210625","side":"sell","seq":12455419,"price":2504.9,"qty":3000.0,"timestamp":1618678107935}
1618678107.96996: {"feed":"book","product_id":"FI_XBTUSD_210625","side":"buy","seq":21454896,"price":57200.5,"qty":30165.0,"timestamp":1618678107935}
1618678107.969982: {"feed":"book","product_id":"FI_ETHUSD_210625","side":"sell","seq":12455420,"price":2508.55,"qty":36827.0,"timestamp":1618678107935}
1618678107.970005: {"feed":"book","product_id":"FI_ETHUSD_210625","side":"buy","seq":12455421,"price":2495.3,"qty":3000.0,"timestamp":1618678107935}
1618678107.970028: {"feed":"book","product_id":"FI_ETHUSD_210625","side":"sell","seq":12455422,"price":2512.2,"qty":36827.0,"timestamp":1618678107935}
1618678107.970051: {"feed":"book","product_id":"FI_ETHUSD_210625","side":"sell","seq":12455423,"price":2515.85,"qty":36826.0,"timestamp":1618678107935}
1618678107.972609: {"feed":"book","product_id":"FI_XBTUSD_210430","side":"sell","seq":12237525,"price":61344.0,"qty":0.0,"timestamp":1618678107941}
1618678107.9726982: {"feed":"book","product_id":"FI_XBTUSD_210430","side":"sell","seq":12237526,"price":61355.0,"qty":250001.0,"timestamp":1618678107941}
1618678107.972739: {"feed":"book","product_id":"FI_ETHUSD_210625","side":"sell","seq":12455424,"price":2516.25,"qty":0.0,"timestamp":1618678107941}
1618678107.9727738: {"feed":"book","product_id":"FI_ETHUSD_210625","side":"sell","seq":12455425,"price":2515.3,"qty":25003.0,"timestamp":1618678107941}
1618678107.992637: {"feed":"book","product_id":"FI_XBTUSD_210625","side":"sell","seq":21454897,"price":64062.5,"qty":0.0,"timestamp":1618678107951}
1618678108.002363: {"feed":"book","product_id":"FI_XRPUSD_210625","side":"sell","seq":3631502,"price":1.7201,"qty":0.0,"timestamp":1618678107969}
1618678108.005655: {"feed":"book","product_id":"FI_XBTUSD_210625","side":"buy","seq":21454898,"price":57200.5,"qty":33185.0,"timestamp":1618678107978}
1618678108.021415: {"feed":"book","product_id":"FI_ETHUSD_210430","side":"sell","seq":4780826,"price":2396.4,"qty":0.0,"timestamp":1618678107995}
1618678108.021541: {"feed":"book","product_id":"FI_ETHUSD_210430","side":"sell","seq":4780827,"price":2395.05,"qty":225001.0,"timestamp":1618678107995}
1618678108.026019: {"feed":"book","product_id":"FI_ETHUSD_210430","side":"sell","seq":4780828,"price":2402.2,"qty":0.0,"timestamp":1618678107996}
1618678108.0261471: {"feed":"book","product_id":"FI_ETHUSD_210430","side":"sell","seq":4780829,"price":2399.6,"qty":584747.0,"timestamp":1618678107996}
1618678108.026211: {"feed":"book","product_id":"FI_XBTUSD_210625","side":"sell","seq":21454899,"price":64187.0,"qty":0.0,"timestamp":1618678107996}
1618678108.026264: {"feed":"book","product_id":"FI_XBTUSD_210625","side":"sell","seq":21454900,"price":64170.0,"qty":504470.0,"timestamp":1618678107996}
1618678108.026308: {"feed":"book","product_id":"FI_ETHUSD_210625","side":"sell","seq":12455426,"price":2508.85,"qty":0.0,"timestamp":1618678107996}
1618678108.0263622: {"feed":"book","product_id":"FI_ETHUSD_210625","side":"sell","seq":12455427,"price":2507.9,"qty":225001.0,"timestamp":1618678107996}
1618678108.0285969: {"feed":"book","product_id":"FI_ETHUSD_210625","side":"sell","seq":12455428,"price":2512.4,"qty":0.0,"timestamp":1618678107996}
1618678108.028686: {"feed":"book","product_id":"FI_ETHUSD_210625","side":"sell","seq":12455429,"price":2512.15,"qty":303574.0,"timestamp":1618678107996}
1618678108.028728: {"feed":"book","product_id":"FI_XBTUSD_210625","side":"sell","seq":21454901,"price":64253.5,"qty":0.0,"timestamp":1618678107996}
1618678108.028762: {"feed":"book","product_id":"FI_XBTUSD_210625","side":"sell","seq":21454902,"price":64260.0,"qty":125003.0,"timestamp":1618678107996}
1618678108.02879: {"feed":"book","product_id":"FI_XBTUSD_210430","side":"sell","seq":12237527,"price":61948.0,"qty":0.0,"timestamp":1618678107996}
1618678108.028835: {"feed":"book","product_id":"FI_XBTUSD_210430","side":"buy","seq":12237528,"price":60661.5,"qty":0.0,"timestamp":1618678107996}
1618678108.035785: {"feed":"book","product_id":"PI_BCHUSD","side":"sell","seq":16258380,"price":1062.1,"qty":2927.0,"timestamp":1618678108005}
1618678108.038599: {"feed":"book","product_id":"PI_BCHUSD","side":"sell","seq":16258381,"price":1062.1,"qty":5913.0,"timestamp":1618678108008}
1618678108.045978: {"feed":"book","product_id":"PI_BCHUSD","side":"sell","seq":16258382,"price":1063.2,"qty":3885.0,"timestamp":1618678108017}
1618678108.0460532: {"feed":"book","product_id":"PI_BCHUSD","side":"sell","seq":16258383,"price":1063.1,"qty":19661.0,"timestamp":1618678108017}
1618678108.0460851: {"feed":"book","product_id":"PI_BCHUSD","side":"buy","seq":16258384,"price":1059.4,"qty":3835.0,"timestamp":1618678108017}
1618678108.04611: {"feed":"book","product_id":"PI_BCHUSD","side":"buy","seq":16258385,"price":1059.0,"qty":4053.0,"timestamp":1618678108017}
1618678108.05076: {"feed":"book","product_id":"FI_ETHUSD_210625","side":"sell","seq":12455430,"price":2509.25,"qty":0.0,"timestamp":1618678108024}
1618678108.0617778: {"feed":"book","product_id":"PI_BCHUSD","side":"buy","seq":16258386,"price":1059.7,"qty":5009.0,"timestamp":1618678108033}
1618678108.061856: {"feed":"book","product_id":"FI_ETHUSD_210625","side":"buy","seq":12455431,"price":2495.35,"qty":2000.0,"timestamp":1618678108033}
1618678108.061905: {"feed":"book","product_id":"FI_ETHUSD_210625","side":"sell","seq":12455432,"price":2506.15,"qty":2000.0,"timestamp":1618678108034}
1618678108.0619369: {"feed":"book","product_id":"PI_BCHUSD","side":"buy","seq":16258387,"price":1058.9,"qty":5013.0,"timestamp":1618678108034}
1618678108.061965: {"feed":"book","product_id":"FI_ETHUSD_210625","side":"buy","seq":12455433,"price":2483.05,"qty":5000.0,"timestamp":1618678108034}
1618678108.0722291: {"feed":"book","product_id":"FI_ETHUSD_210625","side":"sell","seq":12455434,"price":2518.45,"qty":5000.0,"timestamp":1618678108034}
1618678108.078224: {"feed":"book","product_id":"FI_BCHUSD_210625","side":"buy","seq":2240179,"price":1124.8,"qty":0.0,"timestamp":1618678108045}
1618678108.116605: {"feed":"book","product_id":"PI_BCHUSD","side":"sell","seq":16258388,"price":1064.2,"qty":3947.0,"timestamp":1618678108092}
1618678108.117373: {"feed":"book","product_id":"PI_BCHUSD","side":"sell","seq":16258389,"price":1062.8,"qty":3815.0,"timestamp":1618678108095}
1618678108.117491: {"feed":"book","product_id":"PI_BCHUSD","side":"sell","seq":16258390,"price":1063.2,"qty":7919.0,"timestamp":1618678108095}
1618678108.1252449: {"feed":"book","product_id":"FI_ETHUSD_210625","side":"buy","seq":12455435,"price":2495.35,"qty":0.0,"timestamp":1618678108098}
1618678108.1253471: {"feed":"book","product_id":"FI_XBTUSD_210625","side":"buy","seq":21454903,"price":63799.5,"qty":14500.0,"timestamp":1618678108098}
1618678108.125398: {"feed":"book","product_id":"FI_XBTUSD_210625","side":"sell","seq":21454904,"price":64145.5,"qty":10000.0,"timestamp":1618678108098}
1618678108.125449: {"feed":"book","product_id":"PI_BCHUSD","side":"buy","seq":16258391,"price":1059.9,"qty":3807.0,"timestamp":1618678108099}
1618678108.139959: {"feed":"book","product_id":"FI_XBTUSD_210625","side":"buy","seq":21454905,"price":63808.5,"qty":0.0,"timestamp":1618678108098}
1618678108.140084: {"feed":"book","product_id":"FI_XBTUSD_210625","side":"buy","seq":21454906,"price":63826.5,"qty":2077.0,"timestamp":1618678108098}
1618678108.140146: {"feed":"book","product_id":"PI_BCHUSD","side":"sell","seq":16258392,"price":1062.8,"qty":0.0,"timestamp":1618678108101}
1618678108.143949: {"feed":"book","product_id":"PI_BCHUSD","side":"buy","seq":16258393,"price":1059.2,"qty":26324.0,"timestamp":1618678108115}
1618678108.144067: {"feed":"book","product_id":"PI_BCHUSD","side":"sell","seq":16258394,"price":1063.1,"qty":9028.0,"timestamp":1618678108119}
1618678108.1441169: {"feed":"book","product_id":"PI_BCHUSD","side":"sell","seq":16258395,"price":1063.0,"qty":47552.0,"timestamp":1618678108119}
1618678108.144156: {"feed":"book","product_id":"FI_BCHUSD_210625","side":"buy","seq":2240180,"price":1129.1,"qty":0.0,"timestamp":1618678108120}
1618678108.1445131: {"feed":"book","product_id":"PI_BCHUSD","side":"buy","seq":16258396,"price":1059.6,"qty":3898.0,"timestamp":1618678108121}
1618678108.147177: {"feed":"book","product_id":"PI_BCHUSD","side":"sell","seq":16258397,"price":1062.6,"qty":0.0,"timestamp":1618678108121}
1618678108.160214: {"feed":"book","product_id":"FI_ETHUSD_210924","side":"sell","seq":3859138,"price":2661.65,"qty":0.0,"timestamp":1618678108136}
1618678108.1696799: {"feed":"book","product_id":"FI_ETHUSD_210625","side":"sell","seq":12455436,"price":2503.9,"qty":835.0,"timestamp":1618678108139}
1618678108.1697888: {"feed":"book","product_id":"FI_ETHUSD_210625","side":"sell","seq":12455437,"price":2504.6,"qty":9032.0,"timestamp":1618678108139}
1618678108.176252: {"feed":"book","product_id":"FI_XBTUSD_210430","side":"buy","seq":12237529,"price":60285.0,"qty":0.0,"timestamp":1618678108150}
1618678108.1916769: {"feed":"book","product_id":"FI_XRPUSD_210625","side":"buy","seq":3631503,"price":1.6933,"qty":0.0,"timestamp":1618678108160}
1618678108.191808: {"feed":"book","product_id":"FI_XRPUSD_210625","side":"buy","seq":3631504,"price":1.6929,"qty":68.0,"timestamp":1618678108160}
1618678108.191873: {"feed":"book","product_id":"FI_ETHUSD_210625","side":"buy","seq":12455438,"price":2495.75,"qty":0.0,"timestamp":1618678108165}
1618678108.1947122: {"feed":"book","product_id":"FI_ETHUSD_210625","side":"sell","seq":12455439,"price":2507.95,"qty":441.0,"timestamp":1618678108170}
1618678108.201328: {"feed":"book","product_id":"FI_ETHUSD_210625","side":"sell","seq":12455440,"price":2507.9,"qty":0.0,"timestamp":1618678108177}
1618678108.2014568: {"feed":"book","product_id":"FI_ETHUSD_210625","side":"sell","seq":12455441,"price":2508.0,"qty":225001.0,"timestamp":1618678108177}
1618678108.2020512: {"feed":"book","product_id":"FI_XBTUSD_210625","side":"sell","seq":21454907,"price":64260.0,"qty":0.0,"timestamp":1618678108177}
1618678108.202144: {"feed":"book","product_id":"FI_XBTUSD_210625","side":"sell","seq":21454908,"price":64255.5,"qty":125003.0,"timestamp":1618678108177}
1618678108.202199: {"feed":"book","product_id":"FI_XRPUSD_210625","side":"buy","seq":3631505,"price":1.6924,"qty":0.0,"timestamp":1618678108178}
1618678108.2123468: {"feed":"book","product_id":"PI_BCHUSD","side":"buy","seq":16258398,"price":1059.9,"qty":0.0,"timestamp":1618678108185}
1618678108.212478: {"feed":"book","product_id":"PI_BCHUSD","side":"buy","seq":16258399,"price":1059.5,"qty":0.0,"timestamp":1618678108185}
1618678108.212537: {"feed":"book","product_id":"PI_BCHUSD","side":"buy","seq":16258400,"price":1058.4,"qty":3731.0,"timestamp":1618678108186}
1618678108.2125912: {"feed":"book","product_id":"PI_BCHUSD","side":"buy","seq":16258401,"price":1059.3,"qty":8682.0,"timestamp":1618678108187}
1618678108.212628: {"feed":"book","product_id":"PI_BCHUSD","side":"buy","seq":16258402,"price":1058.6,"qty":7855.0,"timestamp":1618678108187}
1618678108.2126698: {"feed":"book","product_id":"PI_BCHUSD","side":"sell","seq":16258403,"price":1062.7,"qty":4995.0,"timestamp":1618678108188}
1618678108.2127202: {"feed":"book","product_id":"PI_BCHUSD","side":"buy","seq":16258404,"price":1058.2,"qty":35129.0,"timestamp":1618678108188}
1618678108.2151349: {"feed":"book","product_id":"PI_BCHUSD","side":"buy","seq":16258405,"price":1059.4,"qty":0.0,"timestamp":1618678108191}
1618678108.21566: {"feed":"book","product_id":"PI_BCHUSD","side":"buy","seq":16258406,"price":1059.3,"qty":5010.0,"timestamp":1618678108191}
1618678108.2157261: {"feed":"book","product_id":"PI_BCHUSD","side":"buy","seq":16258407,"price":1059.0,"qty":0.0,"timestamp":1618678108192}
1618678108.21577: {"feed":"book","product_id":"PI_BCHUSD","side":"buy","seq":16258408,"price":1057.6,"qty":4164.0,"timestamp":1618678108192}
1618678108.232885: {"feed":"book","product_id":"FI_XBTUSD_210625","side":"buy","seq":21454909,"price":57200.5,"qty":30165.0,"timestamp":1618678108209}
1618678108.247217: {"feed":"book","product_id":"FI_BCHUSD_210625","side":"sell","seq":2240181,"price":1141.0,"qty":0.0,"timestamp":1618678108223}
1618678108.247346: {"feed":"book","product_id":"FI_BCHUSD_210430","side":"buy","seq":1411850,"price":1073.3,"qty":0.0,"timestamp":1618678108223}
1618678108.247875: {"feed":"book","product_id":"FI_BCHUSD_210430","side":"buy","seq":1411851,"price":1068.1,"qty":0.0,"timestamp":1618678108223}
1618678108.2479281: {"feed":"book","product_id":"FI_BCHUSD_210430","side":"sell","seq":1411852,"price":1086.6,"qty":0.0,"timestamp":1618678108223}
1618678108.2559261: {"feed":"book","product_id":"FI_BCHUSD_210625","side":"sell","seq":2240182,"price":1147.0,"qty":0.0,"timestamp":1618678108227}
1618678108.274143: {"feed":"book","product_id":"PI_BCHUSD","side":"buy","seq":16258409,"price":1060.3,"qty":0.0,"timestamp":1618678108249}
1618678108.274272: {"feed":"book","product_id":"PI_BCHUSD","side":"sell","seq":16258410,"price":1063.7,"qty":9746.0,"timestamp":1618678108249}
1618678108.274324: {"feed":"book","product_id":"PI_BCHUSD","side":"buy","seq":16258411,"price":1058.1,"qty":0.0,"timestamp":1618678108249}
1618678108.278681: {"feed":"book","product_id":"PI_BCHUSD","side":"sell","seq":16258412,"price":1065.7,"qty":0.0,"timestamp":1618678108249}
1618678108.278806: {"feed":"book","product_id":"FI_BCHUSD_210430","side":"buy","seq":1411853,"price":1075.7,"qty":0.0,"timestamp":1618678108250}
1618678108.2788658: {"feed":"book","product_id":"PI_BCHUSD","side":"buy","seq":16258413,"price":1055.9,"qty":0.0,"timestamp":1618678108249}
1618678108.2789152: {"feed":"book","product_id":"FI_BCHUSD_210430","side":"sell","seq":1411854,"price":1080.2,"qty":0.0,"timestamp":1618678108250}
1618678108.278959: {"feed":"book","product_id":"PI_BCHUSD","side":"sell","seq":16258414,"price":1067.8,"qty":0.0,"timestamp":1618678108249}
1618678108.278997: {"feed":"book","product_id":"FI_BCHUSD_210430","side":"buy","seq":1411855,"price":1073.0,"qty":0.0,"timestamp":1618678108250}
1618678108.2790341: {"feed":"book","product_id":"FI_BCHUSD_210430","side":"sell","seq":1411856,"price":1083.1,"qty":0.0,"timestamp":1618678108250}
1618678108.279078: {"feed":"book","product_id":"FI_BCHUSD_210430","side":"buy","seq":1411857,"price":1070.3,"qty":0.0,"timestamp":1618678108252}
1618678108.27912: {"feed":"book","product_id":"FI_BCHUSD_210430","side":"sell","seq":1411858,"price":1086.1,"qty":0.0,"timestamp":1618678108252}
1618678108.279142: {"feed":"book","product_id":"FI_ETHUSD_210625","side":"sell","seq":12455442,"price":2506.6,"qty":3000.0,"timestamp":1618678108252}
1618678108.2791722: {"feed":"book","product_id":"PI_BCHUSD","side":"buy","seq":16258415,"price":1058.5,"qty":6040.0,"timestamp":1618678108253}
1618678108.279197: {"feed":"book","product_id":"PI_BCHUSD","side":"sell","seq":16258416,"price":1070.4,"qty":0.0,"timestamp":1618678108254}
1618678108.284735: {"feed":"book","product_id":"FI_XBTUSD_210625","side":"buy","seq":21454910,"price":57200.5,"qty":33061.0,"timestamp":1618678108259}
1618678108.341314: {"feed":"book","product_id":"FI_XBTUSD_210625","side":"buy","seq":21454911,"price":63904.5,"qty":0.0,"timestamp":1618678108303}
1618678108.34144: {"feed":"book","product_id":"FI_XBTUSD_210625","side":"buy","seq":21454912,"price":63896.0,"qty":2313.0,"timestamp":1618678108303}
1618678108.351715: {"feed":"book","product_id":"FI_ETHUSD_210625","side":"buy","seq":12455443,"price":2496.35,"qty":2000.0,"timestamp":1618678108326}
1618678108.37903: {"feed":"book","product_id":"FI_XBTUSD_210924","side":"sell","seq":13850822,"price":68394.0,"qty":0.0,"timestamp":1618678108350}
1618678108.384495: {"feed":"book","product_id":"FI_XBTUSD_210924","side":"sell","seq":13850823,"price":68393.5,"qty":0.0,"timestamp":1618678108359}
1618678108.3846242: {"feed":"book","product_id":"FI_XBTUSD_210924","side":"sell","seq":13850824,"price":68422.5,"qty":250001.0,"timestamp":1618678108359}
1618678108.3980742: {"feed":"book","product_id":"FI_BCHUSD_210625","side":"sell","seq":2240183,"price":1147.9,"qty":0.0,"timestamp":1618678108370}
1618678108.3981981: {"feed":"book","product_id":"FI_BCHUSD_210625","side":"sell","seq":2240184,"price":1165.1,"qty":45993.0,"timestamp":1618678108370}
1618678108.398252: {"feed":"book","product_id":"FI_BCHUSD_210625","side":"sell","seq":2240185,"price":1189.5,"qty":44836.0,"timestamp":1618678108370}
1618678108.3983119: {"feed":"book","product_id":"FI_BCHUSD_210625","side":"sell","seq":2240186,"price":1209.9,"qty":0.0,"timestamp":1618678108370}
1618678108.3983412: {"feed":"book","product_id":"FI_BCHUSD_210625","side":"buy","seq":2240187,"price":1108.2,"qty":0.0,"timestamp":1618678108370}
1618678108.398368: {"feed":"book","product_id":"FI_BCHUSD_210625","side":"buy","seq":2240188,"price":1108.1,"qty":15022.0,"timestamp":1618678108371}
1618678108.398389: {"feed":"book","product_id":"FI_BCHUSD_210625","side":"buy","seq":2240189,"price":1085.9,"qty":44910.0,"timestamp":1618678108371}
1618678108.398409: {"feed":"book","product_id":"FI_BCHUSD_210625","side":"buy","seq":2240190,"price":1059.6,"qty":46182.0,"timestamp":1618678108371}
1618678108.398428: {"feed":"book","product_id":"PI_BCHUSD","side":"sell","seq":16258417,"price":1068.9,"qty":14641.0,"timestamp":1618678108371}
1618678108.398456: {"feed":"book","product_id":"PI_BCHUSD","side":"sell","seq":16258418,"price":1080.3,"qty":112508.0,"timestamp":1618678108371}
1618678108.398477: {"feed":"book","product_id":"PI_BCHUSD","side":"sell","seq":16258419,"price":1083.6,"qty":89988.0,"timestamp":1618678108372}
1618678108.398497: {"feed":"book","product_id":"PI_BCHUSD","side":"sell","seq":16258420,"price":1150.0,"qty":14941.0,"timestamp":1618678108372}
1618678108.398516: {"feed":"book","product_id":"PI_BCHUSD","side":"buy","seq":16258421,"price":1054.9,"qty":14641.0,"timestamp":1618678108372}
1618678108.398547: {"feed":"book","product_id":"PI_BCHUSD","side":"buy","seq":16258422,"price":1048.1,"qty":267883.0,"timestamp":1618678108372}
1618678108.398567: {"feed":"book","product_id":"PI_BCHUSD","side":"buy","seq":16258423,"price":1034.0,"qty":14741.0,"timestamp":1618678108372}
1618678108.407428: {"feed":"book","product_id":"PI_BCHUSD","side":"buy","seq":16258424,"price":1021.1,"qty":40056.0,"timestamp":1618678108372}
1618678108.4096158: {"feed":"book","product_id":"PI_BCHUSD","side":"sell","seq":16258425,"price":1068.9,"qty":0.0,"timestamp":1618678108385}
1618678108.411813: {"feed":"book","product_id":"PI_BCHUSD","side":"sell","seq":16258426,"price":1080.3,"qty":97867.0,"timestamp":1618678108385}
1618678108.411925: {"feed":"book","product_id":"PI_BCHUSD","side":"sell","seq":16258427,"price":1083.6,"qty":75347.0,"timestamp":1618678108385}
1618678108.4152598: {"feed":"book","product_id":"PI_BCHUSD","side":"sell","seq":16258428,"price":1150.0,"qty":300.0,"timestamp":1618678108385}
1618678108.415369: {"feed":"book","product_id":"PI_BCHUSD","side":"buy","seq":16258429,"price":1054.9,"qty":0.0,"timestamp":1618678108385}
1618678108.4154398: {"feed":"book","product_id":"PI_BCHUSD","side":"buy","seq":16258430,"price":1048.1,"qty":253242.0,"timestamp":1618678108385}
1618678108.415482: {"feed":"book","product_id":"PI_BCHUSD","side":"buy","seq":16258431,"price":1034.0,"qty":100.0,"timestamp":1618678108385}
1618678108.415516: {"feed":"book","product_id":"PI_BCHUSD","side":"buy","seq":16258432,"price":1021.1,"qty":25415.0,"timestamp":1618678108385}
1618678108.415547: {"feed":"book","product_id":"PI_BCHUSD","side":"buy","seq":16258433,"price":1058.6,"qty":4060.0,"timestamp":1618678108388}
1618678108.4155781: {"feed":"book","product_id":"PI_BCHUSD","side":"sell","seq":16258434,"price":1063.1,"qty":4993.0,"timestamp":1618678108388}
1618678108.422703: {"feed":"book","product_id":"FI_XBTUSD_210924","side":"sell","seq":13850825,"price":68278.5,"qty":3000.0,"timestamp":1618678108399}
1618678108.432603: {"feed":"book","product_id":"FI_XBTUSD_210924","side":"sell","seq":13850826,"price":68291.5,"qty":0.0,"timestamp":1618678108406}
1618678108.432731: {"feed":"book","product_id":"FI_XBTUSD_210924","side":"sell","seq":13850827,"price":68278.0,"qty":10000.0,"timestamp":1618678108406}
1618678108.437114: {"feed":"book","product_id":"PI_BCHUSD","side":"buy","seq":16258435,"price":1053.5,"qty":0.0,"timestamp":1618678108410}
1618678108.443392: {"feed":"book","product_id":"FI_XRPUSD_210625","side":"buy","seq":3631506,"price":1.6916,"qty":1788.0,"timestamp":1618678108414}
1618678108.44883: {"feed":"book","product_id":"FI_XBTUSD_210924","side":"buy","seq":13850828,"price":67828.5,"qty":23999.0,"timestamp":1618678108425}
1618678108.4511108: {"feed":"book","product_id":"FI_XBTUSD_210625","side":"buy","seq":21454913,"price":57200.5,"qty":30165.0,"timestamp":1618678108427}
1618678108.4532092: {"feed":"book","product_id":"FI_ETHUSD_210924","side":"sell","seq":3859139,"price":2659.75,"qty":19199.0,"timestamp":1618678108428}
1618678108.460256: {"feed":"book","product_id":"FI_ETHUSD_210924","side":"sell","seq":3859140,"price":2659.85,"qty":0.0,"timestamp":1618678108436}
1618678108.460345: {"feed":"book","product_id":"FI_ETHUSD_210924","side":"sell","seq":3859141,"price":2659.7,"qty":840.0,"timestamp":1618678108436}
1618678108.4625611: {"feed":"book","product_id":"FI_ETHUSD_210924","side":"buy","seq":3859142,"price":2655.95,"qty":0.0,"timestamp":1618678108436}
1618678108.462694: {"feed":"book","product_id":"FI_ETHUSD_210924","side":"buy","seq":3859143,"price":2655.45,"qty":840.0,"timestamp":1618678108436}
1618678108.47409: {"feed":"book","product_id":"PI_BCHUSD","side":"buy","seq":16258436,"price":1059.7,"qty":0.0,"timestamp":1618678108450}
1618678108.474219: {"feed":"book","product_id":"PI_BCHUSD","side":"buy","seq":16258437,"price":1058.5,"qty":11055.0,"timestamp":1618678108450}
1618678108.551184: {"feed":"book","product_id":"PI_BCHUSD","side":"buy","seq":16258438,"price":1059.2,"qty":3693.0,"timestamp":1618678108509}
1618678108.5512588: {"feed":"book","product_id":"FI_BCHUSD_210625","side":"sell","seq":2240191,"price":1143.4,"qty":13310.0,"timestamp":1618678108510}
1618678108.551306: {"feed":"book","product_id":"PI_BCHUSD","side":"sell","seq":16258439,"price":1068.9,"qty":14641.0,"timestamp":1618678108510}
1618678108.551339: {"feed":"book","product_id":"FI_BCHUSD_210625","side":"sell","seq":2240192,"price":1157.7,"qty":86468.0,"timestamp":1618678108510}
1618678108.551361: {"feed":"book","product_id":"PI_BCHUSD","side":"sell","seq":16258440,"price":1080.3,"qty":112508.0,"timestamp":1618678108510}
1618678108.551383: {"feed":"book","product_id":"PI_BCHUSD","side":"sell","seq":16258441,"price":1083.6,"qty":89988.0,"timestamp":1618678108510}
1618678108.551403: {"feed":"book","product_id":"FI_BCHUSD_210625","side":"sell","seq":2240193,"price":1189.5,"qty":58146.0,"timestamp":1618678108510}
1618678108.551423: {"feed":"book","product_id":"PI_BCHUSD","side":"sell","seq":16258442,"price":1150.0,"qty":14941.0,"timestamp":1618678108510}
1618678108.551442: {"feed":"book","product_id":"PI_BCHUSD","side":"buy","seq":16258443,"price":1054.9,"qty":14641.0,"timestamp":1618678108510}
1618678108.551467: {"feed":"book","product_id":"PI_BCHUSD","side":"buy","seq":16258444,"price":1048.1,"qty":267883.0,"timestamp":1618678108510}
1618678108.551488: {"feed":"book","product_id":"PI_BCHUSD","side":"buy","seq":16258445,"price":1034.0,"qty":14741.0,"timestamp":1618678108510}
1618678108.551507: {"feed":"book","product_id":"FI_XBTUSD_210625","side":"buy","seq":21454914,"price":57200.5,"qty":33185.0,"timestamp":1618678108513}
1618678108.551527: {"feed":"book","product_id":"PI_BCHUSD","side":"buy","seq":16258446,"price":1021.1,"qty":40056.0,"timestamp":1618678108510}
1618678108.551546: {"feed":"book","product_id":"FI_BCHUSD_210625","side":"sell","seq":2240194,"price":1204.8,"qty":57521.0,"timestamp":1618678108510}
1618678108.5515652: {"feed":"book","product_id":"FI_BCHUSD_210625","side":"buy","seq":2240195,"price":1108.4,"qty":13310.0,"timestamp":1618678108510}
1618678108.551588: {"feed":"book","product_id":"FI_BCHUSD_210625","side":"buy","seq":2240196,"price":1108.1,"qty":28332.0,"timestamp":1618678108510}
1618678108.551608: {"feed":"book","product_id":"FI_BCHUSD_210625","side":"buy","seq":2240197,"price":1085.9,"qty":58220.0,"timestamp":1618678108510}
1618678108.551626: {"feed":"book","product_id":"FI_BCHUSD_210625","side":"buy","seq":2240198,"price":1059.6,"qty":59492.0,"timestamp":1618678108510}
1618678108.556111: {"feed":"book","product_id":"FI_ETHUSD_210625","side":"buy","seq":12455444,"price":2496.1,"qty":3408.0,"timestamp":1618678108515}
1618678108.568789: {"feed":"book","product_id":"FI_XBTUSD_210625","side":"sell","seq":21454915,"price":64160.0,"qty":0.0,"timestamp":1618678108515}
1618678108.568922: {"feed":"book","product_id":"FI_XBTUSD_210625","side":"sell","seq":21454916,"price":64042.0,"qty":0.0,"timestamp":1618678108519}
1618678108.5689821: {"feed":"book","product_id":"FI_XBTUSD_210625","side":"sell","seq":21454917,"price":64053.0,"qty":13947.0,"timestamp":1618678108519}
1618678108.569035: {"feed":"book","product_id":"FI_XBTUSD_210625","side":"sell","seq":21454918,"price":64098.0,"qty":0.0,"timestamp":1618678108519}
1618678108.569079: {"feed":"book","product_id":"FI_XBTUSD_210625","side":"sell","seq":21454919,"price":64118.5,"qty":28681.0,"timestamp":1618678108519}
1618678108.569119: {"feed":"book","product_id":"PI_BCHUSD","side":"sell","seq":16258447,"price":1062.1,"qty":3036.0,"timestamp":1618678108516}
1618678108.569154: {"feed":"book","product_id":"FI_XBTUSD_210625","side":"buy","seq":21454920,"price":63826.5,"qty":0.0,"timestamp":1618678108519}
1618678108.569207: {"feed":"book","product_id":"FI_XBTUSD_210625","side":"buy","seq":21454921,"price":63879.0,"qty":1524.0,"timestamp":1618678108519}
1618678108.570643: {"feed":"book","product_id":"PI_BCHUSD","side":"sell","seq":16258448,"price":1062.2,"qty":0.0,"timestamp":1618678108516}
1618678108.570734: {"feed":"book","product_id":"PI_BCHUSD","side":"sell","seq":16258449,"price":1062.5,"qty":3007.0,"timestamp":1618678108516}
1618678108.5707982: {"feed":"book","product_id":"PI_BCHUSD","side":"sell","seq":16258450,"price":1061.7,"qty":2851.0,"timestamp":1618678108519}
1618678108.57083: {"feed":"book","product_id":"PI_BCHUSD","side":"buy","seq":16258451,"price":1058.8,"qty":8511.0,"timestamp":1618678108519}
1618678108.570863: {"feed":"book","product_id":"PI_BCHUSD","side":"buy","seq":16258452,"price":1059.6,"qty":0.0,"timestamp":1618678108519}
1618678108.570893: {"feed":"book","product_id":"PI_BCHUSD","side":"sell","seq":16258453,"price":1063.2,"qty":4034.0,"timestamp":1618678108519}
1618678108.570914: {"feed":"book","product_id":"PI_BCHUSD","side":"buy","seq":16258454,"price":1058.1,"qty":29219.0,"timestamp":1618678108519}
1618678108.5709388: {"feed":"book","product_id":"FI_BCHUSD_210430","side":"buy","seq":1411859,"price":1074.8,"qty":24428.0,"timestamp":1618678108524}
1618678108.570967: {"feed":"book","product_id":"FI_ETHUSD_210924","side":"buy","seq":3859144,"price":2636.65,"qty":19199.0,"timestamp":1618678108534}
1618678108.571015: {"feed":"book","product_id":"PI_BCHUSD","side":"buy","seq":16258455,"price":1057.6,"qty":31077.0,"timestamp":1618678108519}
1618678108.5710368: {"feed":"book","product_id":"FI_BCHUSD_210430","side":"sell","seq":1411860,"price":1079.0,"qty":26895.0,"timestamp":1618678108524}
1618678108.571061: {"feed":"book","product_id":"PI_BCHUSD","side":"sell","seq":16258456,"price":1062.2,"qty":15612.0,"timestamp":1618678108519}
1618678108.571084: {"feed":"book","product_id":"PI_BCHUSD","side":"sell","seq":16258457,"price":1062.1,"qty":6730.0,"timestamp":1618678108519}
1618678108.571104: {"feed":"book","product_id":"FI_BCHUSD_210430","side":"buy","seq":1411861,"price":1072.0,"qty":28500.0,"timestamp":1618678108524}
1618678108.571126: {"feed":"book","product_id":"PI_BCHUSD","side":"buy","seq":16258458,"price":1058.4,"qty":7594.0,"timestamp":1618678108519}
1618678108.571146: {"feed":"book","product_id":"PI_BCHUSD","side":"buy","seq":16258459,"price":1059.5,"qty":29690.0,"timestamp":1618678108524}
1618678108.571168: {"feed":"book","product_id":"FI_BCHUSD_210430","side":"sell","seq":1411862,"price":1081.9,"qty":31377.0,"timestamp":1618678108524}
1618678108.571192: {"feed":"book","product_id":"PI_BCHUSD","side":"sell","seq":16258460,"price":1062.8,"qty":27971.0,"timestamp":1618678108524}
1618678108.5712152: {"feed":"book","product_id":"FI_BCHUSD_210430","side":"buy","seq":1411863,"price":1069.3,"qty":32571.0,"timestamp":1618678108524}
1618678108.571237: {"feed":"book","product_id":"FI_BCHUSD_210430","side":"sell","seq":1411864,"price":1084.8,"qty":35859.0,"timestamp":1618678108524}
1618678108.5712588: {"feed":"book","product_id":"PI_BCHUSD","side":"buy","seq":16258461,"price":1057.6,"qty":65715.0,"timestamp":1618678108524}
1618678108.571279: {"feed":"book","product_id":"PI_BCHUSD","side":"sell","seq":16258462,"price":1064.8,"qty":32633.0,"timestamp":1618678108524}
1618678108.5713012: {"feed":"book","product_id":"PI_BCHUSD","side":"buy","seq":16258463,"price":1055.7,"qty":39586.0,"timestamp":1618678108524}
1618678108.571323: {"feed":"book","product_id":"PI_BCHUSD","side":"sell","seq":16258464,"price":1066.8,"qty":37295.0,"timestamp":1618678108524}
1618678108.5713458: {"feed":"book","product_id":"PI_BCHUSD","side":"buy","seq":16258465,"price":1058.7,"qty":4013.0,"timestamp":1618678108524}
1618678108.571368: {"feed":"book","product_id":"PI_BCHUSD","side":"sell","seq":16258466,"price":1062.6,"qty":3656.0,"timestamp":1618678108524}
1618678108.573214: {"feed":"book","product_id":"PI_BCHUSD","side":"sell","seq":16258467,"price":1062.2,"qty":37673.0,"timestamp":1618678108526}
1618678108.605359: {"feed":"book","product_id":"FI_ETHUSD_210625","side":"sell","seq":12455445,"price":2509.2,"qty":0.0,"timestamp":1618678108574}
1618678108.605491: {"feed":"book","product_id":"FI_ETHUSD_210625","side":"sell","seq":12455446,"price":2507.95,"qty":19315.0,"timestamp":1618678108574}
1618678108.605546: {"feed":"book","product_id":"FI_ETHUSD_210625","side":"sell","seq":12455447,"price":2509.15,"qty":4507.0,"timestamp":1618678108574}
1618678108.6055958: {"feed":"book","product_id":"PI_BCHUSD","side":"sell","seq":16258468,"price":1063.7,"qty":3673.0,"timestamp":1618678108574}
1618678108.605634: {"feed":"book","product_id":"PI_BCHUSD","side":"sell","seq":16258469,"price":1063.5,"qty":11065.0,"timestamp":1618678108574}
1618678108.605667: {"feed":"book","product_id":"PI_BCHUSD","side":"buy","seq":16258470,"price":1058.5,"qty":5015.0,"timestamp":1618678108574}
1618678108.6321769: {"feed":"book","product_id":"FI_ETHUSD_210625","side":"sell","seq":12455448,"price":2508.0,"qty":0.0,"timestamp":1618678108596}
1618678108.6323042: {"feed":"book","product_id":"FI_ETHUSD_210625","side":"sell","seq":12455449,"price":2507.9,"qty":225001.0,"timestamp":1618678108596}
1618678108.632368: {"feed":"book","product_id":"FI_XBTUSD_210625","side":"sell","seq":21454922,"price":64255.5,"qty":0.0,"timestamp":1618678108596}
1618678108.63242: {"feed":"book","product_id":"FI_XBTUSD_210625","side":"sell","seq":21454923,"price":64260.0,"qty":125003.0,"timestamp":1618678108596}
1618678108.6324632: {"feed":"book","product_id":"FI_XBTUSD_210924","side":"buy","seq":13850829,"price":67699.5,"qty":47999.0,"timestamp":1618678108605}
1618678108.6798568: {"feed":"book","product_id":"FI_ETHUSD_210924","side":"sell","seq":3859145,"price":2669.85,"qty":38399.0,"timestamp":1618678108647}
1618678108.690735: {"feed":"book","product_id":"FI_XBTUSD_210625","side":"buy","seq":21454924,"price":57200.5,"qty":30165.0,"timestamp":1618678108659}
1618678108.7005508: {"feed":"book","product_id":"PI_BCHUSD","side":"sell","seq":16258471,"price":1061.7,"qty":5764.0,"timestamp":1618678108675}
1618678108.70066: {"feed":"book","product_id":"FI_BCHUSD_210430","side":"sell","seq":1411865,"price":1079.8,"qty":0.0,"timestamp":1618678108676}
1618678108.7020218: {"feed":"book","product_id":"PI_BCHUSD","side":"sell","seq":16258472,"price":1062.1,"qty":10531.0,"timestamp":1618678108679}
1618678108.707184: {"feed":"book","product_id":"FI_XBTUSD_210625","side":"sell","seq":21454925,"price":64260.0,"qty":0.0,"timestamp":1618678108683}
1618678108.707273: {"feed":"book","product_id":"FI_XBTUSD_210625","side":"sell","seq":21454926,"price":64253.5,"qty":125003.0,"timestamp":1618678108683}
1618678108.71549: {"feed":"book","product_id":"PI_BCHUSD","side":"buy","seq":16258473,"price":1058.2,"qty":39003.0,"timestamp":1618678108687}
1618678108.715598: {"feed":"book","product_id":"PI_BCHUSD","side":"buy","seq":16258474,"price":1058.7,"qty":7759.0,"timestamp":1618678108687}
1618678108.715646: {"feed":"book","product_id":"PI_BCHUSD","side":"sell","seq":16258475,"price":1062.6,"qty":7563.0,"timestamp":1618678108689}
1618678108.7156842: {"feed":"book","product_id":"PI_BCHUSD","side":"sell","seq":16258476,"price":1062.2,"qty":41455.0,"timestamp":1618678108689}
1618678108.7234712: {"feed":"book","product_id":"PI_BCHUSD","side":"sell","seq":16258477,"price":1061.7,"qty":2851.0,"timestamp":1618678108695}
1618678108.723627: {"feed":"book","product_id":"PI_BCHUSD","side":"sell","seq":16258478,"price":1061.7,"qty":0.0,"timestamp":1618678108695}
1618678108.727133: {"feed":"book","product_id":"FI_XBTUSD_210625","side":"buy","seq":21454927,"price":57200.5,"qty":33027.0,"timestamp":1618678108701}
1618678108.738484: {"feed":"book","product_id":"PI_BCHUSD","side":"sell","seq":16258479,"price":1063.5,"qty":4992.0,"timestamp":1618678108705}
1618678108.738591: {"feed":"book","product_id":"FI_XBTUSD_210430","side":"buy","seq":12237530,"price":60663.0,"qty":500.0,"timestamp":1618678108710}
1618678108.738657: {"feed":"book","product_id":"FI_XBTUSD_210430","side":"sell","seq":12237531,"price":61941.5,"qty":500.0,"timestamp":1618678108710}
1618678108.7512882: {"feed":"book","product_id":"PI_BCHUSD","side":"sell","seq":16258480,"price":1068.9,"qty":0.0,"timestamp":1618678108725}
1618678108.751416: {"feed":"book","product_id":"PI_BCHUSD","side":"sell","seq":16258481,"price":1080.3,"qty":97867.0,"timestamp":1618678108725}
1618678108.751468: {"feed":"book","product_id":"PI_BCHUSD","side":"sell","seq":16258482,"price":1083.6,"qty":75347.0,"timestamp":1618678108725}
1618678108.751507: {"feed":"book","product_id":"PI_BCHUSD","side":"sell","seq":16258483,"price":1150.0,"qty":300.0,"timestamp":1618678108725}
1618678108.75154: {"feed":"book","product_id":"PI_BCHUSD","side":"buy","seq":16258484,"price":1054.9,"qty":0.0,"timestamp":1618678108725}
1618678108.751602: {"feed":"book","product_id":"PI_BCHUSD","side":"buy","seq":16258485,"price":1048.1,"qty":253242.0,"timestamp":1618678108725}
1618678108.7516532: {"feed":"book","product_id":"PI_BCHUSD","side":"buy","seq":16258486,"price":1034.0,"qty":100.0,"timestamp":1618678108725}
1618678108.751673: {"feed":"book","product_id":"PI_BCHUSD","side":"buy","seq":16258487,"price":1021.1,"qty":25415.0,"timestamp":1618678108725}
1618678108.751692: {"feed":"book","product_id":"FI_XRPUSD_210625","side":"sell","seq":3631507,"price":1.7095,"qty":16799.0,"timestamp":1618678108726}
1618678108.762186: {"feed":"book","product_id":"PI_BCHUSD","side":"sell","seq":16258488,"price":1063.8,"qty":37632.0,"timestamp":1618678108733}
1618678108.762263: {"feed":"book","product_id":"FI_XBTUSD_210625","side":"buy","seq":21454928,"price":63879.0,"qty":0.0,"timestamp":1618678108732}
1618678108.7623098: {"feed":"book","product_id":"FI_XBTUSD_210625","side":"buy","seq":21454929,"price":63826.5,"qty":2055.0,"timestamp":1618678108732}
1618678108.762343: {"feed":"book","product_id":"FI_XBTUSD_210625","side":"sell","seq":21454930,"price":64053.0,"qty":0.0,"timestamp":1618678108732}
1618678108.7623732: {"feed":"book","product_id":"FI_XBTUSD_210625","side":"sell","seq":21454931,"price":64042.0,"qty":13014.0,"timestamp":1618678108732}
1618678108.762398: {"feed":"book","product_id":"FI_XBTUSD_210625","side":"sell","seq":21454932,"price":64118.5,"qty":0.0,"timestamp":1618678108732}
1618678108.762423: {"feed":"book","product_id":"FI_XBTUSD_210625","side":"sell","seq":21454933,"price":64098.0,"qty":25383.0,"timestamp":1618678108732}
1618678108.767699: {"feed":"book","product_id":"FI_ETHUSD_210924","side":"buy","seq":3859146,"price":2629.0,"qty":38399.0,"timestamp":1618678108738}
1618678108.767822: {"feed":"book","product_id":"PI_BCHUSD","side":"sell","seq":16258489,"price":1068.9,"qty":14641.0,"timestamp":1618678108742}
1618678108.7678888: {"feed":"book","product_id":"PI_BCHUSD","side":"sell","seq":16258490,"price":1080.3,"qty":112508.0,"timestamp":1618678108742}
1618678108.77011: {"feed":"book","product_id":"PI_BCHUSD","side":"sell","seq":16258491,"price":1094.0,"qty":39081.0,"timestamp":1618678108742}
1618678108.770186: {"feed":"book","product_id":"PI_BCHUSD","side":"sell","seq":16258492,"price":1099.3,"qty":14641.0,"timestamp":1618678108742}
1618678108.770229: {"feed":"book","product_id":"PI_BCHUSD","side":"buy","seq":16258493,"price":1054.9,"qty":14641.0,"timestamp":1618678108742}
1618678108.770259: {"feed":"book","product_id":"PI_BCHUSD","side":"buy","seq":16258494,"price":1048.1,"qty":267883.0,"timestamp":1618678108742}
1618678108.770281: {"feed":"book","product_id":"PI_BCHUSD","side":"buy","seq":16258495,"price":1034.0,"qty":14741.0,"timestamp":1618678108742}
1618678108.770302: {"feed":"book","product_id":"PI_BCHUSD","side":"buy","seq":16258496,"price":1021.1,"qty":40056.0,"timestamp":1618678108742}
1618678108.7703218: {"feed":"book","product_id":"PI_BCHUSD","side":"buy","seq":16258497,"price":1058.7,"qty":24003.0,"timestamp":1618678108742}
1618678108.7703412: {"feed":"book","product_id":"PI_BCHUSD","side":"buy","seq":16258498,"price":1058.7,"qty":45363.0,"timestamp":1618678108744}
1618678108.785973: {"feed":"book","product_id":"PI_BCHUSD","side":"sell","seq":16258499,"price":1063.7,"qty":0.0,"timestamp":1618678108761}
1618678108.7861052: {"feed":"book","product_id":"FI_XBTUSD_210924","side":"buy","seq":13850830,"price":52552.5,"qty":58843.0,"timestamp":1618678108761}
1618678108.7884958: {"feed":"book","product_id":"PI_BCHUSD","side":"buy","seq":16258500,"price":1059.2,"qty":0.0,"timestamp":1618678108763}
1618678108.788627: {"feed":"book","product_id":"PI_BCHUSD","side":"sell","seq":16258501,"price":1062.9,"qty":3929.0,"timestamp":1618678108764}
1618678108.7886899: {"feed":"book","product_id":"PI_BCHUSD","side":"sell","seq":16258502,"price":1064.3,"qty":0.0,"timestamp":1618678108764}
1618678108.790762: {"feed":"book","product_id":"PI_BCHUSD","side":"sell","seq":16258503,"price":1063.2,"qty":7961.0,"timestamp":1618678108767}
1618678108.790874: {"feed":"book","product_id":"PI_BCHUSD","side":"buy","seq":16258504,"price":1058.1,"qty":32967.0,"timestamp":1618678108767}
1618678108.793802: {"feed":"book","product_id":"PI_BCHUSD","side":"sell","seq":16258505,"price":1063.0,"qty":36919.0,"timestamp":1618678108769}
1618678108.7939122: {"feed":"book","product_id":"PI_BCHUSD","side":"sell","seq":16258506,"price":1062.9,"qty":14562.0,"timestamp":1618678108769}
1618678108.803583: {"feed":"book","product_id":"FI_ETHUSD_210625","side":"sell","seq":12455450,"price":2504.6,"qty":0.0,"timestamp":1618678108778}
1618678108.803715: {"feed":"book","product_id":"FI_ETHUSD_210625","side":"sell","seq":12455451,"price":2503.9,"qty":8355.0,"timestamp":1618678108778}
1618678108.8037682: {"feed":"book","product_id":"FI_ETHUSD_210625","side":"buy","seq":12455452,"price":2493.15,"qty":4462.0,"timestamp":1618678108778}
1618678108.8038101: {"feed":"book","product_id":"FI_ETHUSD_210625","side":"buy","seq":12455453,"price":2492.15,"qty":637.0,"timestamp":1618678108778}
1618678108.807827: {"feed":"book","product_id":"FI_XRPUSD_210625","side":"buy","seq":3631508,"price":1.6945,"qty":0.0,"timestamp":1618678108783}
1618678108.81774: {"feed":"book","product_id":"PI_BCHUSD","side":"sell","seq":16258507,"price":1062.9,"qty":3929.0,"timestamp":1618678108794}
1618678108.81785: {"feed":"book","product_id":"PI_BCHUSD","side":"sell","seq":16258508,"price":1062.8,"qty":38604.0,"timestamp":1618678108794}
1618678108.85361: {"feed":"book","product_id":"PI_BCHUSD","side":"buy","seq":16258509,"price":1060.4,"qty":0.0,"timestamp":1618678108815}
1618678108.8536909: {"feed":"book","product_id":"FI_BCHUSD_210430","side":"buy","seq":1411866,"price":1075.8,"qty":0.0,"timestamp":1618678108815}
1618678108.8537521: {"feed":"book","product_id":"FI_BCHUSD_210625","side":"buy","seq":2240199,"price":1130.8,"qty":0.0,"timestamp":1618678108815}
1618678108.8537972: {"feed":"book","product_id":"PI_BCHUSD","side":"buy","seq":16258510,"price":1058.7,"qty":41617.0,"timestamp":1618678108818}
1618678108.853823: {"feed":"book","product_id":"PI_BCHUSD","side":"buy","seq":16258511,"price":1058.8,"qty":5082.0,"timestamp":1618678108818}
1618678108.853845: {"feed":"book","product_id":"PI_BCHUSD","side":"buy","seq":16258512,"price":1059.1,"qty":0.0,"timestamp":1618678108820}
1618678108.8538702: {"feed":"book","product_id":"PI_BCHUSD","side":"sell","seq":16258513,"price":1062.2,"qty":37673.0,"timestamp":1618678108820}
1618678108.856224: {"feed":"book","product_id":"PI_BCHUSD","side":"sell","seq":16258514,"price":1062.1,"qty":7545.0,"timestamp":1618678108829}
1618678108.8563: {"feed":"book","product_id":"PI_BCHUSD","side":"sell","seq":16258515,"price":1063.8,"qty":6070.0,"timestamp":1618678108829}
1618678108.8586109: {"feed":"book","product_id":"PI_BCHUSD","side":"sell","seq":16258516,"price":1062.9,"qty":32589.0,"timestamp":1618678108830}
1618678108.869195: {"feed":"book","product_id":"FI_ETHUSD_210924","side":"sell","seq":3859147,"price":2660.8,"qty":2000.0,"timestamp":1618678108840}
1618678108.8755891: {"feed":"book","product_id":"FI_XBTUSD_210625","side":"sell","seq":21454934,"price":64042.5,"qty":11784.0,"timestamp":1618678108851}
1618678108.875697: {"feed":"book","product_id":"FI_XBTUSD_210625","side":"sell","seq":21454935,"price":64143.5,"qty":96427.0,"timestamp":1618678108851}
1618678108.9291022: {"feed":"book","product_id":"FI_XBTUSD_210430","side":"buy","seq":12237532,"price":59445.5,"qty":52569.0,"timestamp":1618678108894}
1618678108.9292102: {"feed":"book","product_id":"PI_BCHUSD","side":"sell","seq":16258517,"price":1062.8,"qty":27971.0,"timestamp":1618678108894}
1618678108.929261: {"feed":"book","product_id":"PI_BCHUSD","side":"sell","seq":16258518,"price":1062.6,"qty":18196.0,"timestamp":1618678108894}
1618678108.929302: {"feed":"book","product_id":"PI_BCHUSD","side":"sell","seq":16258519,"price":1064.7,"qty":8112.0,"timestamp":1618678108894}
1618678108.932699: {"feed":"book","product_id":"FI_XRPUSD_210625","side":"sell","seq":3631509,"price":1.6986,"qty":0.0,"timestamp":1618678108897}
1618678108.932802: {"feed":"book","product_id":"FI_XRPUSD_210625","side":"sell","seq":3631510,"price":1.6977,"qty":18968.0,"timestamp":1618678108897}
1618678108.932863: {"feed":"book","product_id":"FI_XRPUSD_210625","side":"buy","seq":3631511,"price":1.6917,"qty":0.0,"timestamp":1618678108897}
1618678108.932896: {"feed":"book","product_id":"FI_XRPUSD_210625","side":"buy","seq":3631512,"price":1.6909,"qty":19200.0,"timestamp":1618678108897}
1618678108.9329228: {"feed":"book","product_id":"PI_BCHUSD","side":"sell","seq":16258520,"price":1062.1,"qty":7631.0,"timestamp":1618678108894}
1618678108.932947: {"feed":"book","product_id":"PI_BCHUSD","side":"sell","seq":16258521,"price":1063.3,"qty":30841.0,"timestamp":1618678108894}
1618678108.932972: {"feed":"book","product_id":"PI_BCHUSD","side":"sell","seq":16258522,"price":1062.2,"qty":22061.0,"timestamp":1618678108894}
1618678108.932993: {"feed":"book","product_id":"PI_BCHUSD","side":"sell","seq":16258523,"price":1062.3,"qty":28581.0,"timestamp":1618678108894}
1618678108.933015: {"feed":"book","product_id":"PI_BCHUSD","side":"sell","seq":16258524,"price":1062.1,"qty":3830.0,"timestamp":1618678108895}
1618678108.933034: {"feed":"book","product_id":"PI_BCHUSD","side":"buy","seq":16258525,"price":1058.7,"qty":25373.0,"timestamp":1618678108896}
1618678108.933056: {"feed":"book","product_id":"PI_BCHUSD","side":"sell","seq":16258526,"price":1063.0,"qty":5638.0,"timestamp":1618678108896}
1618678108.933075: {"feed":"book","product_id":"PI_BCHUSD","side":"sell","seq":16258527,"price":1063.0,"qty":9386.0,"timestamp":1618678108898}
1618678108.933095: {"feed":"book","product_id":"PI_BCHUSD","side":"sell","seq":16258528,"price":1064.2,"qty":0.0,"timestamp":1618678108898}
1618678108.939126: {"feed":"book","product_id":"PI_BCHUSD","side":"buy","seq":16258529,"price":1058.8,"qty":8662.0,"timestamp":1618678108912}
1618678108.9391959: {"feed":"book","product_id":"FI_XRPUSD_210625","side":"sell","seq":3631513,"price":1.6981,"qty":0.0,"timestamp":1618678108912}
1618678108.9392629: {"feed":"book","product_id":"FI_XRPUSD_210625","side":"sell","seq":3631514,"price":1.6976,"qty":768.0,"timestamp":1618678108912}
1618678108.948863: {"feed":"book","product_id":"PI_BCHUSD","side":"sell","seq":16258530,"price":1062.4,"qty":4996.0,"timestamp":1618678108916}
1618678108.9489942: {"feed":"book","product_id":"PI_BCHUSD","side":"sell","seq":16258531,"price":1062.8,"qty":32965.0,"timestamp":1618678108916}
1618678108.949086: {"feed":"book","product_id":"PI_BCHUSD","side":"sell","seq":16258532,"price":1062.0,"qty":4998.0,"timestamp":1618678108916}
1618678108.9491289: {"feed":"book","product_id":"PI_BCHUSD","side":"sell","seq":16258533,"price":1062.7,"qty":0.0,"timestamp":1618678108916}
1618678108.949176: {"feed":"book","product_id":"PI_BCHUSD","side":"sell","seq":16258534,"price":1063.5,"qty":0.0,"timestamp":1618678108916}
1618678108.949215: {"feed":"book","product_id":"PI_BCHUSD","side":"sell","seq":16258535,"price":1063.1,"qty":0.0,"timestamp":1618678108916}
1618678108.9492521: {"feed":"book","product_id":"PI_BCHUSD","side":"buy","seq":16258536,"price":1058.8,"qty":12340.0,"timestamp":1618678108921}
1618678108.967016: {"feed":"book","product_id":"FI_XBTUSD_210625","side":"sell","seq":21454936,"price":64042.0,"qty":0.0,"timestamp":1618678108938}
1618678108.967144: {"feed":"book","product_id":"FI_XBTUSD_210625","side":"sell","seq":21454937,"price":64053.0,"qty":14571.0,"timestamp":1618678108938}
1618678108.967207: {"feed":"book","product_id":"FI_XBTUSD_210625","side":"sell","seq":21454938,"price":64098.0,"qty":0.0,"timestamp":1618678108938}
1618678108.967256: {"feed":"book","product_id":"FI_XBTUSD_210625","side":"sell","seq":21454939,"price":64118.5,"qty":29448.0,"timestamp":1618678108938}
1618678108.967297: {"feed":"book","product_id":"FI_XBTUSD_210625","side":"buy","seq":21454940,"price":63826.5,"qty":0.0,"timestamp":1618678108938}
1618678108.967341: {"feed":"book","product_id":"FI_XBTUSD_210625","side":"buy","seq":21454941,"price":63879.0,"qty":1501.0,"timestamp":1618678108938}
1618678108.9747908: {"feed":"book","product_id":"FI_XBTUSD_210625","side":"buy","seq":21454942,"price":57200.5,"qty":30165.0,"timestamp":1618678108949}
1618678108.983875: {"feed":"book","product_id":"FI_XRPUSD_210625","side":"sell","seq":3631515,"price":1.6982,"qty":0.0,"timestamp":1618678108954}
1618678108.983962: {"feed":"book","product_id":"FI_XRPUSD_210625","side":"sell","seq":3631516,"price":1.6975,"qty":50.0,"timestamp":1618678108954}
1618678108.9865239: {"feed":"book","product_id":"FI_XBTUSD_210625","side":"sell","seq":21454943,"price":64069.5,"qty":0.0,"timestamp":1618678108962}
1618678108.990576: {"feed":"book","product_id":"FI_XRPUSD_210625","side":"sell","seq":3631517,"price":1.6976,"qty":0.0,"timestamp":1618678108964}
1618678108.990665: {"feed":"book","product_id":"FI_XRPUSD_210625","side":"sell","seq":3631518,"price":1.6974,"qty":768.0,"timestamp":1618678108964}
1618678109.022757: {"feed":"book","product_id":"FI_XBTUSD_210625","side":"buy","seq":21454944,"price":57200.5,"qty":33119.0,"timestamp":1618678108997}
1618678109.0360131: {"feed":"book","product_id":"FI_BCHUSD_210430","side":"buy","seq":1411867,"price":1068.2,"qty":4590.0,"timestamp":1618678109003}
1618678109.0361211: {"feed":"book","product_id":"FI_BCHUSD_210430","side":"buy","seq":1411868,"price":1014.9,"qty":14770.0,"timestamp":1618678109003}
1618678109.0362298: {"feed":"book","product_id":"PI_BCHUSD","side":"sell","seq":16258537,"price":1061.5,"qty":2834.0,"timestamp":1618678109006}
1618678109.041505: {"feed":"book","product_id":"PI_BCHUSD","side":"sell","seq":16258538,"price":1061.5,"qty":5625.0,"timestamp":1618678109010}
1618678109.041614: {"feed":"book","product_id":"FI_XBTUSD_210430","side":"sell","seq":12237533,"price":61941.5,"qty":0.0,"timestamp":1618678109010}
1618678109.0416892: {"feed":"book","product_id":"FI_XBTUSD_210430","side":"buy","seq":12237534,"price":60663.0,"qty":0.0,"timestamp":1618678109010}
1618678109.04179: {"feed":"book","product_id":"FI_ETHUSD_210430","side":"buy","seq":4780830,"price":2351.1,"qty":0.0,"timestamp":1618678109013}
1618678109.053828: {"feed":"book","product_id":"FI_ETHUSD_210625","side":"sell","seq":12455454,"price":2506.6,"qty":0.0,"timestamp":1618678109027}
1618678109.0636768: {"feed":"book","product_id":"FI_XBTUSD_210625","side":"sell","seq":21454945,"price":64002.0,"qty":0.0,"timestamp":1618678109040}
1618678109.075218: {"feed":"book","product_id":"FI_XRPUSD_210625","side":"buy","seq":3631519,"price":1.6929,"qty":0.0,"timestamp":1618678109046}
1618678109.0753632: {"feed":"book","product_id":"FI_XRPUSD_210625","side":"buy","seq":3631520,"price":1.6921,"qty":68.0,"timestamp":1618678109046}
1618678109.086186: {"feed":"book","product_id":"FI_XRPUSD_210625","side":"sell","seq":3631521,"price":1.6977,"qty":0.0,"timestamp":1618678109046}
1618678109.086318: {"feed":"book","product_id":"FI_XRPUSD_210625","side":"sell","seq":3631522,"price":1.6973,"qty":18968.0,"timestamp":1618678109046}
1618678109.086379: {"feed":"book","product_id":"FI_XRPUSD_210625","side":"buy","seq":3631523,"price":1.6824,"qty":0.0,"timestamp":1618678109046}
1618678109.0864289: {"feed":"book","product_id":"FI_XRPUSD_210625","side":"buy","seq":3631524,"price":1.68,"qty":172800.0,"timestamp":1618678109046}
1618678109.0864708: {"feed":"book","product_id":"FI_XRPUSD_210625","side":"sell","seq":3631525,"price":1.6975,"qty":0.0,"timestamp":1618678109046}
1618678109.0865111: {"feed":"book","product_id":"FI_XRPUSD_210625","side":"sell","seq":3631526,"price":1.6973,"qty":19018.0,"timestamp":1618678109046}
1618678109.0895: {"feed":"book","product_id":"FI_XRPUSD_210625","side":"sell","seq":3631527,"price":1.6974,"qty":0.0,"timestamp":1618678109063}
1618678109.08959: {"feed":"book","product_id":"FI_XRPUSD_210625","side":"sell","seq":3631528,"price":1.6972,"qty":768.0,"timestamp":1618678109063}
1618678109.089646: {"feed":"book","product_id":"FI_XBTUSD_210430","side":"buy","seq":12237535,"price":60271.5,"qty":298740.0,"timestamp":1618678109066}
1618678109.09391: {"feed":"book","product_id":"FI_XBTUSD_210430","side":"buy","seq":12237536,"price":61104.0,"qty":0.0,"timestamp":1618678109070}
1618678109.09853: {"feed":"book","product_id":"FI_XBTUSD_210924","side":"buy","seq":13850831,"price":52552.5,"qty":58608.0,"timestamp":1618678109075}
1618678109.113247: {"feed":"book","product_id":"FI_XBTUSD_210924","side":"sell","seq":13850832,"price":68278.5,"qty":0.0,"timestamp":1618678109090}
1618678109.118717: {"feed":"book","product_id":"PI_BCHUSD","side":"sell","seq":16258539,"price":1062.6,"qty":21800.0,"timestamp":1618678109095}
1618678109.11883: {"feed":"book","product_id":"FI_XBTUSD_210924","side":"sell","seq":13850833,"price":68278.0,"qty":0.0,"timestamp":1618678109095}
1618678109.118903: {"feed":"book","product_id":"FI_XBTUSD_210924","side":"sell","seq":13850834,"price":68291.5,"qty":10000.0,"timestamp":1618678109095}
1618678109.143136: {"feed":"book","product_id":"FI_XBTUSD_210924","side":"buy","seq":13850835,"price":52552.5,"qty":58766.0,"timestamp":1618678109117}
1618678109.146283: {"feed":"book","product_id":"PI_BCHUSD","side":"buy","seq":16258540,"price":1058.8,"qty":7258.0,"timestamp":1618678109123}
1618678109.164428: {"feed":"book","product_id":"FI_ETHUSD_210430","side":"buy","seq":4780831,"price":2382.2,"qty":0.0,"timestamp":1618678109138}
1618678109.1645539: {"feed":"book","product_id":"FI_ETHUSD_210430","side":"buy","seq":4780832,"price":2379.6,"qty":6118.0,"timestamp":1618678109138}
1618678109.17332: {"feed":"book","product_id":"FI_BCHUSD_210430","side":"buy","seq":1411869,"price":1068.2,"qty":0.0,"timestamp":1618678109146}
1618678109.173453: {"feed":"book","product_id":"FI_BCHUSD_210430","side":"buy","seq":1411870,"price":950.1,"qty":4590.0,"timestamp":1618678109146}
1618678109.173493: {"feed":"book","product_id":"PI_BCHUSD","side":"buy","seq":16258541,"price":1057.1,"qty":0.0,"timestamp":1618678109146}
1618678109.173527: {"feed":"book","product_id":"PI_BCHUSD","side":"buy","seq":16258542,"price":1055.0,"qty":10217.0,"timestamp":1618678109146}
1618678109.173554: {"feed":"book","product_id":"FI_BCHUSD_210430","side":"buy","seq":1411871,"price":1014.9,"qty":0.0,"timestamp":1618678109146}
1618678109.17358: {"feed":"book","product_id":"FI_BCHUSD_210430","side":"buy","seq":1411872,"price":950.1,"qty":19360.0,"timestamp":1618678109146}
1618678109.1875699: {"feed":"book","product_id":"PI_BCHUSD","side":"sell","seq":16258543,"price":1061.5,"qty":2834.0,"timestamp":1618678109161}
1618678109.188234: {"feed":"book","product_id":"PI_BCHUSD","side":"sell","seq":16258544,"price":1061.5,"qty":0.0,"timestamp":1618678109161}
1618678109.1883352: {"feed":"book","product_id":"PI_BCHUSD","side":"buy","seq":16258545,"price":1058.8,"qty":3678.0,"timestamp":1618678109163}
1618678109.192118: {"feed":"book","product_id":"PI_BCHUSD","side":"sell","seq":16258546,"price":1062.0,"qty":5084.0,"timestamp":1618678109167}
1618678109.2033112: {"feed":"book","product_id":"FI_ETHUSD_210625","side":"sell","seq":12455455,"price":2503.9,"qty":835.0,"timestamp":1618678109178}
1618678109.203422: {"feed":"book","product_id":"FI_ETHUSD_210625","side":"sell","seq":12455456,"price":2504.6,"qty":9210.0,"timestamp":1618678109178}
1618678109.208371: {"feed":"book","product_id":"PI_BCHUSD","side":"buy","seq":16258547,"price":1057.9,"qty":7764.0,"timestamp":1618678109185}
1618678109.213054: {"feed":"book","product_id":"PI_BCHUSD","side":"sell","seq":16258548,"price":1062.6,"qty":18196.0,"timestamp":1618678109188}
1618678109.2217019: {"feed":"book","product_id":"PI_BCHUSD","side":"sell","seq":16258549,"price":1068.9,"qty":0.0,"timestamp":1618678109195}
1618678109.22183: {"feed":"book","product_id":"PI_BCHUSD","side":"sell","seq":16258550,"price":1080.3,"qty":97867.0,"timestamp":1618678109195}
1618678109.2218828: {"feed":"book","product_id":"PI_BCHUSD","side":"sell","seq":16258551,"price":1094.0,"qty":24440.0,"timestamp":1618678109195}
1618678109.221947: {"feed":"book","product_id":"PI_BCHUSD","side":"sell","seq":16258552,"price":1099.3,"qty":0.0,"timestamp":1618678109195}
1618678109.221975: {"feed":"book","product_id":"PI_BCHUSD","side":"buy","seq":16258553,"price":1054.9,"qty":0.0,"timestamp":1618678109195}
1618678109.222003: {"feed":"book","product_id":"PI_BCHUSD","side":"buy","seq":16258554,"price":1048.1,"qty":253242.0,"timestamp":1618678109195}
1618678109.222025: {"feed":"book","product_id":"PI_BCHUSD","side":"buy","seq":16258555,"price":1034.0,"qty":100.0,"timestamp":1618678109195}
1618678109.222044: {"feed":"book","product_id":"PI_BCHUSD","side":"buy","seq":16258556,"price":1021.1,"qty":25415.0,"timestamp":1618678109195}
1618678109.252188: {"feed":"book","product_id":"FI_XBTUSD_210430","side":"buy","seq":12237537,"price":59445.5,"qty":48172.0,"timestamp":1618678109227}
1618678109.282803: {"feed":"book","product_id":"FI_BCHUSD_210430","side":"buy","seq":1411873,"price":1070.7,"qty":0.0,"timestamp":1618678109256}
1618678109.2829282: {"feed":"book","product_id":"PI_BCHUSD","side":"sell","seq":16258557,"price":1064.4,"qty":1195.0,"timestamp":1618678109256}
1618678109.2912881: {"feed":"book","product_id":"PI_BCHUSD","side":"buy","seq":16258558,"price":1058.0,"qty":6037.0,"timestamp":1618678109259}
1618678109.291413: {"feed":"book","product_id":"FI_XBTUSD_210625","side":"buy","seq":21454946,"price":63879.0,"qty":0.0,"timestamp":1618678109265}
1618678109.29148: {"feed":"book","product_id":"FI_XBTUSD_210625","side":"buy","seq":21454947,"price":63826.5,"qty":2055.0,"timestamp":1618678109265}
1618678109.291528: {"feed":"book","product_id":"FI_XBTUSD_210625","side":"sell","seq":21454948,"price":64053.0,"qty":0.0,"timestamp":1618678109265}
1618678109.291575: {"feed":"book","product_id":"FI_XBTUSD_210625","side":"sell","seq":21454949,"price":64042.0,"qty":13018.0,"timestamp":1618678109265}
1618678109.291614: {"feed":"book","product_id":"FI_XBTUSD_210625","side":"sell","seq":21454950,"price":64118.5,"qty":0.0,"timestamp":1618678109265}
1618678109.2916899: {"feed":"book","product_id":"FI_XBTUSD_210625","side":"sell","seq":21454951,"price":64098.0,"qty":25389.0,"timestamp":1618678109265}
1618678109.296902: {"feed":"book","product_id":"FI_XBTUSD_210430","side":"buy","seq":12237538,"price":59445.5,"qty":48501.0,"timestamp":1618678109269}
1618678109.343471: {"feed":"book","product_id":"FI_XBTUSD_210625","side":"buy","seq":21454952,"price":57200.5,"qty":35980.0,"timestamp":1618678109317}
1618678109.348: {"feed":"book","product_id":"PI_BCHUSD","side":"buy","seq":16258559,"price":1059.5,"qty":36986.0,"timestamp":1618678109323}
1618678109.378144: {"feed":"book","product_id":"PI_BCHUSD","side":"buy","seq":16258560,"price":1058.7,"qty":4013.0,"timestamp":1618678109348}
1618678109.3782558: {"feed":"book","product_id":"PI_BCHUSD","side":"buy","seq":16258561,"price":1058.2,"qty":7549.0,"timestamp":1618678109350}
1618678109.378303: {"feed":"book","product_id":"PI_BCHUSD","side":"buy","seq":16258562,"price":1056.8,"qty":29958.0,"timestamp":1618678109350}
1618678109.3783581: {"feed":"book","product_id":"FI_XBTUSD_210924","side":"sell","seq":13850836,"price":68292.5,"qty":23999.0,"timestamp":1618678109353}
1618678109.410013: {"feed":"book","product_id":"FI_ETHUSD_210625","side":"buy","seq":12455457,"price":2492.15,"qty":0.0,"timestamp":1618678109385}
1618678109.410144: {"feed":"book","product_id":"FI_ETHUSD_210625","side":"buy","seq":12455458,"price":2493.4,"qty":602.0,"timestamp":1618678109385}
1618678109.417887: {"feed":"book","product_id":"FI_XBTUSD_210924","side":"buy","seq":13850837,"price":52552.5,"qty":58608.0,"timestamp":1618678109392}
1618678109.460532: {"feed":"book","product_id":"FI_ETHUSD_210430","side":"buy","seq":4780833,"price":2350.7,"qty":99600.0,"timestamp":1618678109434}
1618678109.464619: {"feed":"book","product_id":"FI_ETHUSD_210625","side":"buy","seq":12455459,"price":2496.1,"qty":408.0,"timestamp":1618678109435}
1618678109.464688: {"feed":"book","product_id":"FI_XBTUSD_210924","side":"buy","seq":13850838,"price":52552.5,"qty":58843.0,"timestamp":1618678109436}
1618678109.464733: {"feed":"book","product_id":"FI_ETHUSD_210625","side":"buy","seq":12455460,"price":2489.0,"qty":0.0,"timestamp":1618678109435}
1618678109.4648168: {"feed":"book","product_id":"FI_BCHUSD_210625","side":"buy","seq":2240200,"price":1130.7,"qty":0.0,"timestamp":1618678109435}
1618678109.464847: {"feed":"book","product_id":"FI_BCHUSD_210625","side":"sell","seq":2240201,"price":1136.0,"qty":0.0,"timestamp":1618678109435}
1618678109.464897: {"feed":"book","product_id":"FI_BCHUSD_210625","side":"buy","seq":2240202,"price":1127.3,"qty":0.0,"timestamp":1618678109435}
1618678109.4649222: {"feed":"book","product_id":"FI_BCHUSD_210625","side":"sell","seq":2240203,"price":1139.5,"qty":0.0,"timestamp":1618678109435}
1618678109.464946: {"feed":"book","product_id":"FI_BCHUSD_210625","side":"buy","seq":2240204,"price":1123.8,"qty":0.0,"timestamp":1618678109435}
1618678109.464969: {"feed":"book","product_id":"FI_BCHUSD_210625","side":"sell","seq":2240205,"price":1143.1,"qty":0.0,"timestamp":1618678109435}
1618678109.5037289: {"feed":"book","product_id":"PI_BCHUSD","side":"sell","seq":16258563,"price":1062.1,"qty":136.0,"timestamp":1618678109478}
1618678109.50384: {"feed":"book","product_id":"PI_BCHUSD","side":"buy","seq":16258564,"price":1058.6,"qty":0.0,"timestamp":1618678109479}
1618678109.5039098: {"feed":"book","product_id":"PI_BCHUSD","side":"buy","seq":16258565,"price":1057.4,"qty":4061.0,"timestamp":1618678109481}
1618678109.517199: {"feed":"book","product_id":"PI_BCHUSD","side":"sell","seq":16258566,"price":1061.3,"qty":2617.0,"timestamp":1618678109490}
1618678109.517285: {"feed":"book","product_id":"PI_BCHUSD","side":"buy","seq":16258567,"price":1058.6,"qty":3518.0,"timestamp":1618678109492}
1618678109.517337: {"feed":"book","product_id":"PI_BCHUSD","side":"sell","seq":16258568,"price":1062.6,"qty":7563.0,"timestamp":1618678109493}
1618678109.517374: {"feed":"book","product_id":"PI_BCHUSD","side":"sell","seq":16258569,"price":1062.4,"qty":15629.0,"timestamp":1618678109493}
1618678109.5195: {"feed":"book","product_id":"PI_BCHUSD","side":"buy","seq":16258570,"price":1058.0,"qty":0.0,"timestamp":1618678109495}
1618678109.54564: {"feed":"book","product_id":"PI_BCHUSD","side":"sell","seq":16258571,"price":1061.8,"qty":3757.0,"timestamp":1618678109517}
1618678109.5457659: {"feed":"book","product_id":"PI_BCHUSD","side":"sell","seq":16258572,"price":1062.0,"qty":20092.0,"timestamp":1618678109522}
1618678109.636161: {"feed":"book","product_id":"FI_XBTUSD_210430","side":"buy","seq":12237539,"price":59445.5,"qty":48172.0,"timestamp":1618678109598}
1618678109.6362739: {"feed":"book","product_id":"PI_BCHUSD","side":"buy","seq":16258573,"price":1057.9,"qty":3746.0,"timestamp":1618678109598}
1618678109.6363258: {"feed":"book","product_id":"PI_BCHUSD","side":"buy","seq":16258574,"price":1056.3,"qty":3944.0,"timestamp":1618678109598}
1618678109.636384: {"feed":"book","product_id":"PI_BCHUSD","side":"buy","seq":16258575,"price":1058.7,"qty":0.0,"timestamp":1618678109598}
1618678109.636435: {"feed":"book","product_id":"PI_BCHUSD","side":"buy","seq":16258576,"price":1058.0,"qty":3669.0,"timestamp":1618678109598}
1618678109.6364748: {"feed":"book","product_id":"PI_BCHUSD","side":"buy","seq":16258577,"price":1058.4,"qty":3731.0,"timestamp":1618678109598}
1618678109.636533: {"feed":"book","product_id":"PI_BCHUSD","side":"buy","seq":16258578,"price":1057.5,"qty":3757.0,"timestamp":1618678109599}
1618678109.6424608: {"feed":"book","product_id":"PI_BCHUSD","side":"buy","seq":16258579,"price":1058.1,"qty":3748.0,"timestamp":1618678109607}
1618678109.642549: {"feed":"book","product_id":"PI_BCHUSD","side":"buy","seq":16258580,"price":1057.4,"qty":30303.0,"timestamp":1618678109607}
1618678109.642584: {"feed":"book","product_id":"PI_BCHUSD","side":"buy","seq":16258581,"price":1059.5,"qty":29690.0,"timestamp":1618678109610}
1618678109.6477041: {"feed":"book","product_id":"PI_BCHUSD","side":"sell","seq":16258582,"price":1061.3,"qty":0.0,"timestamp":1618678109620}
1618678109.647774: {"feed":"book","product_id":"PI_BCHUSD","side":"sell","seq":16258583,"price":1061.8,"qty":0.0,"timestamp":1618678109620}
1618678109.690777: {"feed":"book","product_id":"FI_XBTUSD_210430","side":"buy","seq":12237540,"price":59445.5,"qty":52569.0,"timestamp":1618678109662}
1618678109.694081: {"feed":"book","product_id":"PI_BCHUSD","side":"sell","seq":16258584,"price":1068.9,"qty":14641.0,"timestamp":1618678109662}
1618678109.69421: {"feed":"book","product_id":"PI_BCHUSD","side":"sell","seq":16258585,"price":1080.3,"qty":112508.0,"timestamp":1618678109662}
1618678109.69426: {"feed":"book","product_id":"PI_BCHUSD","side":"sell","seq":16258586,"price":1083.6,"qty":89988.0,"timestamp":1618678109662}
1618678109.694298: {"feed":"book","product_id":"PI_BCHUSD","side":"sell","seq":16258587,"price":1098.7,"qty":14641.0,"timestamp":1618678109662}
1618678109.697067: {"feed":"book","product_id":"PI_BCHUSD","side":"buy","seq":16258588,"price":1055.1,"qty":14641.0,"timestamp":1618678109662}
1618678109.697199: {"feed":"book","product_id":"PI_BCHUSD","side":"buy","seq":16258589,"price":1048.1,"qty":267883.0,"timestamp":1618678109662}
1618678109.697251: {"feed":"book","product_id":"PI_BCHUSD","side":"buy","seq":16258590,"price":1034.0,"qty":14741.0,"timestamp":1618678109662}
1618678109.69729: {"feed":"book","product_id":"PI_BCHUSD","side":"buy","seq":16258591,"price":1021.1,"qty":40056.0,"timestamp":1618678109662}
1618678109.697325: {"feed":"book","product_id":"PI_BCHUSD","side":"sell","seq":16258592,"price":1062.0,"qty":5084.0,"timestamp":1618678109670}
1618678109.697359: {"feed":"book","product_id":"PI_BCHUSD","side":"sell","seq":16258593,"price":1062.4,"qty":4996.0,"timestamp":1618678109670}
1618678109.697421: {"feed":"book","product_id":"PI_BCHUSD","side":"sell","seq":16258594,"price":1062.0,"qty":4998.0,"timestamp":1618678109670}
1618678109.697441: {"feed":"book","product_id":"PI_BCHUSD","side":"sell","seq":16258595,"price":1062.1,"qty":50.0,"timestamp":1618678109670}
1618678109.7013068: {"feed":"book","product_id":"PI_BCHUSD","side":"sell","seq":16258596,"price":1061.6,"qty":2860.0,"timestamp":1618678109675}
1618678109.701895: {"feed":"book","product_id":"PI_BCHUSD","side":"sell","seq":16258597,"price":1062.7,"qty":10627.0,"timestamp":1618678109678}
1618678109.701997: {"feed":"book","product_id":"PI_BCHUSD","side":"sell","seq":16258598,"price":1062.3,"qty":0.0,"timestamp":1618678109678}
1618678109.70677: {"feed":"book","product_id":"PI_BCHUSD","side":"sell","seq":16258599,"price":1062.5,"qty":6477.0,"timestamp":1618678109681}
1618678109.70693: {"feed":"book","product_id":"PI_BCHUSD","side":"sell","seq":16258600,"price":1061.6,"qty":0.0,"timestamp":1618678109681}
1618678109.706997: {"feed":"book","product_id":"FI_XBTUSD_210625","side":"buy","seq":21454953,"price":63496.0,"qty":0.0,"timestamp":1618678109681}
1618678109.707049: {"feed":"book","product_id":"FI_XBTUSD_210625","side":"buy","seq":21454954,"price":63489.0,"qty":4195.0,"timestamp":1618678109681}
1618678109.707423: {"feed":"book","product_id":"PI_BCHUSD","side":"sell","seq":16258601,"price":1062.9,"qty":28660.0,"timestamp":1618678109681}
1618678109.707466: {"feed":"book","product_id":"FI_XBTUSD_210625","side":"sell","seq":21454955,"price":64096.5,"qty":0.0,"timestamp":1618678109681}
1618678109.707503: {"feed":"book","product_id":"FI_XBTUSD_210625","side":"sell","seq":21454956,"price":64095.5,"qty":24737.0,"timestamp":1618678109681}
1618678109.707532: {"feed":"book","product_id":"PI_BCHUSD","side":"sell","seq":16258602,"price":1062.6,"qty":3907.0,"timestamp":1618678109683}
1618678109.707555: {"feed":"book","product_id":"PI_BCHUSD","side":"sell","seq":16258603,"price":1063.3,"qty":34751.0,"timestamp":1618678109683}
1618678109.7119172: {"feed":"book","product_id":"PI_BCHUSD","side":"buy","seq":16258604,"price":1058.6,"qty":7137.0,"timestamp":1618678109687}
1618678109.714144: {"feed":"book","product_id":"PI_BCHUSD","side":"sell","seq":16258605,"price":1062.2,"qty":25571.0,"timestamp":1618678109691}
1618678109.718661: {"feed":"book","product_id":"FI_ETHUSD_210625","side":"buy","seq":12455461,"price":2496.1,"qty":3408.0,"timestamp":1618678109695}
1618678109.718771: {"feed":"book","product_id":"FI_ETHUSD_210625","side":"buy","seq":12455462,"price":2488.8,"qty":105653.0,"timestamp":1618678109695}
1618678109.7313821: {"feed":"book","product_id":"FI_XBTUSD_210430","side":"buy","seq":12237541,"price":61101.5,"qty":26740.0,"timestamp":1618678109707}
1618678109.743221: {"feed":"book","product_id":"FI_XBTUSD_210625","side":"sell","seq":21454957,"price":64053.0,"qty":5573.0,"timestamp":1618678109710}
1618678109.743307: {"feed":"book","product_id":"FI_XBTUSD_210625","side":"sell","seq":21454958,"price":63956.0,"qty":10005.0,"timestamp":1618678109713}
1618678109.743387: {"feed":"book","product_id":"PI_BCHUSD","side":"sell","seq":16258606,"price":1062.1,"qty":0.0,"timestamp":1618678109717}
1618678109.7434409: {"feed":"book","product_id":"PI_BCHUSD","side":"sell","seq":16258607,"price":1061.9,"qty":50.0,"timestamp":1618678109717}
1618678109.748775: {"feed":"book","product_id":"PI_BCHUSD","side":"sell","seq":16258608,"price":1061.9,"qty":1105.0,"timestamp":1618678109722}
1618678109.748883: {"feed":"book","product_id":"FI_XBTUSD_210924","side":"buy","seq":13850839,"price":52552.5,"qty":58608.0,"timestamp":1618678109724}
1618678109.750765: {"feed":"book","product_id":"FI_XBTUSD_210625","side":"sell","seq":21454959,"price":63980.5,"qty":4500.0,"timestamp":1618678109726}
1618678109.7625191: {"feed":"book","product_id":"PI_BCHUSD","side":"sell","seq":16258609,"price":1062.2,"qty":3510.0,"timestamp":1618678109739}
1618678109.7630231: {"feed":"book","product_id":"PI_BCHUSD","side":"sell","seq":16258610,"price":1062.7,"qty":31843.0,"timestamp":1618678109739}
1618678109.7639492: {"feed":"book","product_id":"PI_BCHUSD","side":"buy","seq":16258611,"price":1058.6,"qty":27520.0,"timestamp":1618678109742}
1618678109.772608: {"feed":"book","product_id":"PI_BCHUSD","side":"buy","seq":16258612,"price":1058.6,"qty":42848.0,"timestamp":1618678109745}
1618678109.7726772: {"feed":"book","product_id":"FI_BCHUSD_210625","side":"buy","seq":2240206,"price":1128.4,"qty":31962.0,"timestamp":1618678109745}
1618678109.772737: {"feed":"book","product_id":"FI_XBTUSD_210625","side":"sell","seq":21454960,"price":64096.0,"qty":0.0,"timestamp":1618678109745}
1618678109.7728589: {"feed":"book","product_id":"FI_XBTUSD_210625","side":"sell","seq":21454961,"price":64095.0,"qty":250001.0,"timestamp":1618678109745}
1618678109.7728891: {"feed":"book","product_id":"FI_BCHUSD_210625","side":"sell","seq":2240207,"price":1134.8,"qty":29971.0,"timestamp":1618678109745}
1618678109.772916: {"feed":"book","product_id":"FI_BCHUSD_210625","side":"buy","seq":2240208,"price":1124.5,"qty":37289.0,"timestamp":1618678109745}
1618678109.776431: {"feed":"book","product_id":"FI_BCHUSD_210625","side":"sell","seq":2240209,"price":1138.9,"qty":34967.0,"timestamp":1618678109745}
1618678109.7765179: {"feed":"book","product_id":"FI_BCHUSD_210625","side":"buy","seq":2240210,"price":1120.7,"qty":42616.0,"timestamp":1618678109745}
1618678109.7765539: {"feed":"book","product_id":"FI_BCHUSD_210625","side":"sell","seq":2240211,"price":1143.0,"qty":39962.0,"timestamp":1618678109745}
1618678109.778742: {"feed":"book","product_id":"FI_BCHUSD_210625","side":"sell","seq":2240212,"price":1138.1,"qty":0.0,"timestamp":1618678109750}
1618678109.778829: {"feed":"book","product_id":"FI_BCHUSD_210625","side":"sell","seq":2240213,"price":1134.8,"qty":30044.0,"timestamp":1618678109751}
1618678109.786931: {"feed":"book","product_id":"PI_BCHUSD","side":"sell","seq":16258613,"price":1063.9,"qty":34695.0,"timestamp":1618678109764}
1618678109.791318: {"feed":"book","product_id":"FI_XBTUSD_210924","side":"buy","seq":13850840,"price":52552.5,"qty":58776.0,"timestamp":1618678109767}
1618678109.791426: {"feed":"book","product_id":"FI_XBTUSD_210430","side":"sell","seq":12237542,"price":61235.5,"qty":4872.0,"timestamp":1618678109766}
1618678109.800081: {"feed":"book","product_id":"FI_ETHUSD_210625","side":"sell","seq":12455463,"price":2530.05,"qty":0.0,"timestamp":1618678109774}
1618678109.8002088: {"feed":"book","product_id":"FI_ETHUSD_210625","side":"sell","seq":12455464,"price":2528.95,"qty":47810.0,"timestamp":1618678109774}
1618678109.800272: {"feed":"book","product_id":"FI_ETHUSD_210625","side":"sell","seq":12455465,"price":2512.45,"qty":0.0,"timestamp":1618678109774}
1618678109.800323: {"feed":"book","product_id":"FI_ETHUSD_210625","side":"sell","seq":12455466,"price":2512.1,"qty":31876.0,"timestamp":1618678109774}
1618678109.8003662: {"feed":"book","product_id":"FI_ETHUSD_210625","side":"sell","seq":12455467,"price":2507.95,"qty":441.0,"timestamp":1618678109774}
1618678109.800441: {"feed":"book","product_id":"FI_ETHUSD_210625","side":"sell","seq":12455468,"price":2507.85,"qty":18489.0,"timestamp":1618678109774}
1618678109.8004658: {"feed":"book","product_id":"FI_ETHUSD_210625","side":"buy","seq":12455469,"price":2496.1,"qty":3000.0,"timestamp":1618678109774}
1618678109.8004868: {"feed":"book","product_id":"FI_ETHUSD_210625","side":"buy","seq":12455470,"price":2496.2,"qty":436.0,"timestamp":1618678109774}
1618678109.802159: {"feed":"book","product_id":"FI_XBTUSD_210924","side":"sell","seq":13850841,"price":68276.5,"qty":3642.0,"timestamp":1618678109774}
1618678109.8022342: {"feed":"book","product_id":"FI_ETHUSD_210625","side":"sell","seq":12455471,"price":2506.35,"qty":0.0,"timestamp":1618678109774}
1618678109.802283: {"feed":"book","product_id":"FI_ETHUSD_210625","side":"sell","seq":12455472,"price":2506.35,"qty":14041.0,"timestamp":1618678109774}
1618678109.802316: {"feed":"book","product_id":"FI_ETHUSD_210625","side":"sell","seq":12455473,"price":2504.6,"qty":0.0,"timestamp":1618678109774}
1618678109.802346: {"feed":"book","product_id":"FI_ETHUSD_210625","side":"sell","seq":12455474,"price":2504.6,"qty":9002.0,"timestamp":1618678109774}
1618678109.802371: {"feed":"book","product_id":"FI_ETHUSD_210625","side":"buy","seq":12455475,"price":2499.85,"qty":225.0,"timestamp":1618678109774}
1618678109.8023942: {"feed":"book","product_id":"FI_ETHUSD_210625","side":"buy","seq":12455476,"price":2499.85,"qty":455.0,"timestamp":1618678109774}
1618678109.80243: {"feed":"book","product_id":"FI_ETHUSD_210625","side":"buy","seq":12455477,"price":2499.85,"qty":230.0,"timestamp":1618678109774}
1618678109.80245: {"feed":"book","product_id":"FI_ETHUSD_210625","side":"buy","seq":12455478,"price":2499.85,"qty":460.0,"timestamp":1618678109774}
1618678109.802469: {"feed":"book","product_id":"FI_ETHUSD_210625","side":"buy","seq":12455479,"price":2477.25,"qty":0.0,"timestamp":1618678109774}
1618678109.802496: {"feed":"book","product_id":"FI_ETHUSD_210625","side":"buy","seq":12455480,"price":2477.25,"qty":897.0,"timestamp":1618678109774}
1618678109.806293: {"feed":"book","product_id":"FI_XBTUSD_210924","side":"sell","seq":13850842,"price":68291.5,"qty":0.0,"timestamp":1618678109782}
1618678109.8063538: {"feed":"book","product_id":"FI_XBTUSD_210924","side":"sell","seq":13850843,"price":68276.0,"qty":10000.0,"timestamp":1618678109782}
1618678109.8085718: {"feed":"book","product_id":"FI_ETHUSD_210625","side":"sell","seq":12455481,"price":2507.9,"qty":0.0,"timestamp":1618678109785}
1618678109.808672: {"feed":"book","product_id":"FI_ETHUSD_210625","side":"sell","seq":12455482,"price":2508.0,"qty":225001.0,"timestamp":1618678109785}
1618678109.808715: {"feed":"book","product_id":"FI_ETHUSD_210625","side":"sell","seq":12455483,"price":2512.15,"qty":0.0,"timestamp":1618678109785}
1618678109.808749: {"feed":"book","product_id":"FI_ETHUSD_210625","side":"sell","seq":12455484,"price":2512.05,"qty":303574.0,"timestamp":1618678109785}
1618678109.821049: {"feed":"book","product_id":"FI_XRPUSD_210625","side":"buy","seq":3631529,"price":1.691,"qty":16799.0,"timestamp":1618678109793}
1618678109.821187: {"feed":"book","product_id":"PI_BCHUSD","side":"sell","seq":16258614,"price":1063.2,"qty":12953.0,"timestamp":1618678109795}
1618678109.8212411: {"feed":"book","product_id":"PI_BCHUSD","side":"sell","seq":16258615,"price":1062.0,"qty":0.0,"timestamp":1618678109796}
1618678109.821611: {"feed":"book","product_id":"FI_ETHUSD_210430","side":"sell","seq":4780834,"price":2390.35,"qty":2634.0,"timestamp":1618678109799}
1618678109.8243918: {"feed":"book","product_id":"FI_XBTUSD_210430","side":"buy","seq":12237543,"price":60664.5,"qty":500.0,"timestamp":1618678109800}
1618678109.824481: {"feed":"book","product_id":"FI_XBTUSD_210430","side":"sell","seq":12237544,"price":61941.5,"qty":500.0,"timestamp":1618678109800}
1618678109.835196: {"feed":"book","product_id":"PI_BCHUSD","side":"sell","seq":16258616,"price":1062.7,"qty":21216.0,"timestamp":1618678109808}
1618678109.837781: {"feed":"book","product_id":"PI_BCHUSD","side":"sell","seq":16258617,"price":1062.5,"qty":3007.0,"timestamp":1618678109813}
1618678109.8410308: {"feed":"book","product_id":"FI_ETHUSD_210625","side":"sell","seq":12455485,"price":2503.9,"qty":2420.0,"timestamp":1618678109817}
1618678109.841144: {"feed":"book","product_id":"FI_ETHUSD_210625","side":"sell","seq":12455486,"price":2507.5,"qty":0.0,"timestamp":1618678109817}
1618678109.870244: {"feed":"book","product_id":"FI_XRPUSD_210625","side":"sell","seq":3631530,"price":1.6973,"qty":50.0,"timestamp":1618678109846}
1618678109.8703601: {"feed":"book","product_id":"FI_XRPUSD_210625","side":"sell","seq":3631531,"price":1.6981,"qty":18968.0,"timestamp":1618678109846}
1618678109.885335: {"feed":"book","product_id":"FI_ETHUSD_210924","side":"sell","seq":3859148,"price":2659.7,"qty":1199.0,"timestamp":1618678109862}
1618678109.9180212: {"feed":"book","product_id":"FI_XBTUSD_210625","side":"sell","seq":21454962,"price":64042.5,"qty":8784.0,"timestamp":1618678109890}
1618678109.918092: {"feed":"book","product_id":"FI_XRPUSD_210625","side":"sell","seq":3631532,"price":1.6972,"qty":1136.0,"timestamp":1618678109889}
1618678109.9185019: {"feed":"book","product_id":"PI_BCHUSD","side":"sell","seq":16258618,"price":1063.1,"qty":27202.0,"timestamp":1618678109893}
1618678109.925173: {"feed":"book","product_id":"PI_BCHUSD","side":"buy","seq":16258619,"price":1058.6,"qty":39229.0,"timestamp":1618678109899}
1618678109.925281: {"feed":"book","product_id":"PI_BCHUSD","side":"buy","seq":16258620,"price":1058.6,"qty":35711.0,"timestamp":1618678109899}
1618678109.933148: {"feed":"book","product_id":"PI_BCHUSD","side":"sell","seq":16258621,"price":1062.2,"qty":0.0,"timestamp":1618678109901}
1618678109.93329: {"feed":"book","product_id":"PI_BCHUSD","side":"buy","seq":16258622,"price":1057.4,"qty":4061.0,"timestamp":1618678109902}
1618678109.933344: {"feed":"book","product_id":"FI_XBTUSD_210625","side":"sell","seq":21454963,"price":64254.0,"qty":0.0,"timestamp":1618678109901}
1618678109.9333801: {"feed":"book","product_id":"FI_XBTUSD_210625","side":"sell","seq":21454964,"price":64253.0,"qty":57744.0,"timestamp":1618678109901}
1618678109.9334111: {"feed":"book","product_id":"PI_BCHUSD","side":"sell","seq":16258623,"price":1062.9,"qty":0.0,"timestamp":1618678109902}
1618678109.933439: {"feed":"book","product_id":"FI_XBTUSD_210625","side":"buy","seq":21454965,"price":63727.5,"qty":25087.0,"timestamp":1618678109901}
1618678109.933462: {"feed":"book","product_id":"FI_XBTUSD_210625","side":"buy","seq":21454966,"price":63728.0,"qty":3165.0,"timestamp":1618678109901}
1618678109.9334881: {"feed":"book","product_id":"PI_BCHUSD","side":"buy","seq":16258624,"price":1058.0,"qty":0.0,"timestamp":1618678109903}
1618678109.933515: {"feed":"book","product_id":"FI_XBTUSD_210625","side":"buy","seq":21454967,"price":63896.0,"qty":1151.0,"timestamp":1618678109901}
1618678109.933536: {"feed":"book","product_id":"FI_XBTUSD_210625","side":"buy","seq":21454968,"price":63896.0,"qty":2302.0,"timestamp":1618678109901}
1618678109.933555: {"feed":"book","product_id":"PI_BCHUSD","side":"buy","seq":16258625,"price":1058.8,"qty":0.0,"timestamp":1618678109903}
1618678109.933579: {"feed":"book","product_id":"PI_BCHUSD","side":"sell","seq":16258626,"price":1063.0,"qty":5638.0,"timestamp":1618678109904}
1618678109.933599: {"feed":"book","product_id":"PI_BCHUSD","side":"sell","seq":16258627,"price":1064.0,"qty":26953.0,"timestamp":1618678109904}
1618678109.9336221: {"feed":"book","product_id":"FI_XBTUSD_210625","side":"sell","seq":21454969,"price":64516.5,"qty":0.0,"timestamp":1618678109901}
1618678109.933646: {"feed":"book","product_id":"FI_XBTUSD_210625","side":"sell","seq":21454970,"price":64516.5,"qty":76446.0,"timestamp":1618678109901}
1618678109.933669: {"feed":"book","product_id":"PI_BCHUSD","side":"sell","seq":16258628,"price":1064.5,"qty":3618.0,"timestamp":1618678109904}
1618678109.933692: {"feed":"book","product_id":"FI_XBTUSD_210625","side":"sell","seq":21454971,"price":64095.5,"qty":0.0,"timestamp":1618678109901}
1618678109.933716: {"feed":"book","product_id":"FI_XBTUSD_210625","side":"sell","seq":21454972,"price":64095.5,"qty":24738.0,"timestamp":1618678109901}
1618678109.94491: {"feed":"book","product_id":"PI_BCHUSD","side":"buy","seq":16258629,"price":1059.3,"qty":8505.0,"timestamp":1618678109908}
1618678109.94885: {"feed":"book","product_id":"PI_BCHUSD","side":"buy","seq":16258630,"price":1059.3,"qty":12002.0,"timestamp":1618678109923}
1618678109.9541981: {"feed":"book","product_id":"FI_XBTUSD_210625","side":"sell","seq":21454973,"price":64253.5,"qty":0.0,"timestamp":1618678109929}
1618678109.9543302: {"feed":"book","product_id":"FI_XBTUSD_210625","side":"sell","seq":21454974,"price":64252.5,"qty":125003.0,"timestamp":1618678109929}
1618678110.0172439: {"feed":"book","product_id":"FI_ETHUSD_210924","side":"sell","seq":3859149,"price":2671.5,"qty":0.0,"timestamp":1618678109987}
1618678110.017378: {"feed":"book","product_id":"FI_ETHUSD_210430","side":"sell","seq":4780835,"price":2395.45,"qty":0.0,"timestamp":1618678109987}
1618678110.017442: {"feed":"book","product_id":"FI_ETHUSD_210430","side":"sell","seq":4780836,"price":2395.0,"qty":578.0,"timestamp":1618678109987}
1618678110.0174952: {"feed":"book","product_id":"FI_ETHUSD_210924","side":"sell","seq":3859150,"price":2671.05,"qty":219.0,"timestamp":1618678109987}
1618678110.017537: {"feed":"book","product_id":"FI_ETHUSD_210625","side":"sell","seq":12455487,"price":2507.95,"qty":0.0,"timestamp":1618678109988}
1618678110.01759: {"feed":"book","product_id":"FI_ETHUSD_210625","side":"sell","seq":12455488,"price":2507.5,"qty":441.0,"timestamp":1618678109988}
1618678110.02897: {"feed":"book","product_id":"FI_XBTUSD_210430","side":"buy","seq":12237545,"price":59445.5,"qty":48172.0,"timestamp":1618678110006}
1618678110.0294132: {"feed":"book","product_id":"PI_BCHUSD","side":"sell","seq":16258631,"price":1061.9,"qty":3623.0,"timestamp":1618678110007}
1618678110.036327: {"feed":"book","product_id":"PI_BCHUSD","side":"sell","seq":16258632,"price":1061.9,"qty":1105.0,"timestamp":1618678110012}
1618678110.064252: {"feed":"book","product_id":"PI_BCHUSD","side":"buy","seq":16258633,"price":1059.3,"qty":8507.0,"timestamp":1618678110041}
1618678110.074242: {"feed":"book","product_id":"PI_BCHUSD","side":"sell","seq":16258634,"price":1063.0,"qty":0.0,"timestamp":1618678110050}
1618678110.093737: {"feed":"book","product_id":"FI_XBTUSD_210430","side":"buy","seq":12237546,"price":59445.5,"qty":48511.0,"timestamp":1618678110068}
1618678110.0938509: {"feed":"book","product_id":"FI_ETHUSD_210625","side":"sell","seq":12455489,"price":2512.1,"qty":0.0,"timestamp":1618678110070}
1618678110.0939252: {"feed":"book","product_id":"FI_ETHUSD_210625","side":"sell","seq":12455490,"price":2513.8,"qty":34990.0,"timestamp":1618678110070}
1618678110.104482: {"feed":"book","product_id":"FI_ETHUSD_210625","side":"sell","seq":12455491,"price":2512.05,"qty":0.0,"timestamp":1618678110080}
1618678110.1046112: {"feed":"book","product_id":"FI_ETHUSD_210625","side":"sell","seq":12455492,"price":2512.15,"qty":303574.0,"timestamp":1618678110080}
1618678110.1218739: {"feed":"book","product_id":"PI_BCHUSD","side":"sell","seq":16258635,"price":1062.7,"qty":24584.0,"timestamp":1618678110097}
1618678110.1699898: {"feed":"book","product_id":"FI_XBTUSD_210924","side":"buy","seq":13850844,"price":52552.5,"qty":59018.0,"timestamp":1618678110142}
1618678110.1737442: {"feed":"book","product_id":"PI_BCHUSD","side":"sell","seq":16258636,"price":1063.2,"qty":9026.0,"timestamp":1618678110149}
1618678110.1738539: {"feed":"book","product_id":"PI_BCHUSD","side":"sell","seq":16258637,"price":1064.5,"qty":7343.0,"timestamp":1618678110150}
1618678110.178557: {"feed":"book","product_id":"PI_BCHUSD","side":"sell","seq":16258638,"price":1062.3,"qty":1208.0,"timestamp":1618678110155}
1618678110.198237: {"feed":"book","product_id":"PI_BCHUSD","side":"buy","seq":16258639,"price":1058.6,"qty":20383.0,"timestamp":1618678110174}
1618678110.203787: {"feed":"book","product_id":"PI_BCHUSD","side":"buy","seq":16258640,"price":1057.5,"qty":0.0,"timestamp":1618678110179}
1618678110.2103732: {"feed":"book","product_id":"PI_BCHUSD","side":"sell","seq":16258641,"price":1063.2,"qty":12831.0,"timestamp":1618678110187}
1618678110.212629: {"feed":"book","product_id":"PI_BCHUSD","side":"sell","seq":16258642,"price":1062.6,"qty":0.0,"timestamp":1618678110189}
1618678110.24944: {"feed":"book","product_id":"PI_BCHUSD","side":"sell","seq":16258643,"price":1062.4,"qty":10884.0,"timestamp":1618678110225}
1618678110.301023: {"feed":"book","product_id":"FI_XBTUSD_210625","side":"sell","seq":21454975,"price":64042.0,"qty":0.0,"timestamp":1618678110275}
1618678110.301156: {"feed":"book","product_id":"FI_XBTUSD_210625","side":"sell","seq":21454976,"price":64052.5,"qty":14431.0,"timestamp":1618678110275}
1618678110.30236: {"feed":"book","product_id":"FI_XBTUSD_210625","side":"sell","seq":21454977,"price":64098.0,"qty":0.0,"timestamp":1618678110275}
1618678110.30246: {"feed":"book","product_id":"FI_XBTUSD_210625","side":"sell","seq":21454978,"price":64118.5,"qty":29390.0,"timestamp":1618678110275}
1618678110.302517: {"feed":"book","product_id":"FI_XBTUSD_210625","side":"buy","seq":21454979,"price":63826.5,"qty":0.0,"timestamp":1618678110275}
1618678110.302568: {"feed":"book","product_id":"FI_XBTUSD_210625","side":"buy","seq":21454980,"price":63879.0,"qty":1503.0,"timestamp":1618678110275}
1618678110.302612: {"feed":"book","product_id":"PI_BCHUSD","side":"sell","seq":16258644,"price":1062.4,"qty":4996.0,"timestamp":1618678110278}
1618678110.3115919: {"feed":"book","product_id":"PI_BCHUSD","side":"buy","seq":16258645,"price":1057.5,"qty":6034.0,"timestamp":1618678110285}
1618678110.3346078: {"feed":"book","product_id":"FI_XBTUSD_210625","side":"sell","seq":21454981,"price":64053.0,"qty":0.0,"timestamp":1618678110308}
1618678110.335233: {"feed":"book","product_id":"FI_XBTUSD_210430","side":"sell","seq":12237547,"price":61941.5,"qty":0.0,"timestamp":1618678110311}
1618678110.33661: {"feed":"book","product_id":"FI_XBTUSD_210430","side":"buy","seq":12237548,"price":60664.5,"qty":0.0,"timestamp":1618678110311}
1618678110.346059: {"feed":"book","product_id":"PI_BCHUSD","side":"sell","seq":16258646,"price":1062.4,"qty":0.0,"timestamp":1618678110317}
1618678110.3461828: {"feed":"book","product_id":"PI_BCHUSD","side":"sell","seq":16258647,"price":1063.6,"qty":8627.0,"timestamp":1618678110317}
1618678110.4007602: {"feed":"book","product_id":"FI_XBTUSD_210430","side":"buy","seq":12237549,"price":59445.5,"qty":48172.0,"timestamp":1618678110377}
1618678110.409751: {"feed":"book","product_id":"FI_ETHUSD_210625","side":"sell","seq":12455493,"price":2513.8,"qty":0.0,"timestamp":1618678110385}
1618678110.409878: {"feed":"book","product_id":"FI_ETHUSD_210625","side":"sell","seq":12455494,"price":2512.1,"qty":31850.0,"timestamp":1618678110385}
1618678110.416794: {"feed":"book","product_id":"FI_XBTUSD_210430","side":"sell","seq":12237550,"price":61251.5,"qty":2700.0,"timestamp":1618678110392}
1618678110.416926: {"feed":"book","product_id":"FI_XBTUSD_210430","side":"sell","seq":12237551,"price":61308.5,"qty":0.0,"timestamp":1618678110393}
1618678110.433758: {"feed":"book","product_id":"FI_XBTUSD_210924","side":"sell","seq":13850845,"price":68276.5,"qty":50.0,"timestamp":1618678110403}
1618678110.433868: {"feed":"book","product_id":"FI_XBTUSD_210924","side":"sell","seq":13850846,"price":68296.5,"qty":2443.0,"timestamp":1618678110403}
1618678110.433981: {"feed":"book","product_id":"FI_XBTUSD_210924","side":"sell","seq":13850847,"price":68276.0,"qty":0.0,"timestamp":1618678110408}
1618678110.434037: {"feed":"book","product_id":"FI_XBTUSD_210924","side":"sell","seq":13850848,"price":68291.5,"qty":10000.0,"timestamp":1618678110408}
1618678110.441001: {"feed":"book","product_id":"FI_XBTUSD_210924","side":"buy","seq":13850849,"price":68191.0,"qty":2821.0,"timestamp":1618678110414}
1618678110.4411259: {"feed":"book","product_id":"FI_XBTUSD_210924","side":"sell","seq":13850850,"price":68292.5,"qty":0.0,"timestamp":1618678110417}
1618678110.445628: {"feed":"book","product_id":"FI_XBTUSD_210430","side":"buy","seq":12237552,"price":59445.5,"qty":52569.0,"timestamp":1618678110419}
1618678110.459331: {"feed":"book","product_id":"FI_ETHUSD_210625","side":"sell","seq":12455495,"price":2512.15,"qty":0.0,"timestamp":1618678110434}
1618678110.459458: {"feed":"book","product_id":"FI_ETHUSD_210625","side":"sell","seq":12455496,"price":2512.05,"qty":303574.0,"timestamp":1618678110434}
1618678110.482996: {"feed":"book","product_id":"FI_XRPUSD_210625","side":"buy","seq":3631533,"price":1.6922,"qty":50.0,"timestamp":1618678110458}
1618678110.483594: {"feed":"book","product_id":"PI_BCHUSD","side":"buy","seq":16258648,"price":1059.4,"qty":86.0,"timestamp":1618678110460}
1618678110.488299: {"feed":"book","product_id":"PI_BCHUSD","side":"buy","seq":16258649,"price":1059.4,"qty":0.0,"timestamp":1618678110464}
1618678110.49709: {"feed":"book","product_id":"FI_XRPUSD_210625","side":"buy","seq":3631534,"price":1.6921,"qty":0.0,"timestamp":1618678110470}
1618678110.4971771: {"feed":"book","product_id":"FI_XRPUSD_210625","side":"buy","seq":3631535,"price":1.6923,"qty":68.0,"timestamp":1618678110470}
1618678110.507942: {"feed":"book","product_id":"FI_XBTUSD_210625","side":"sell","seq":21454982,"price":64095.5,"qty":0.0,"timestamp":1618678110481}
1618678110.508071: {"feed":"book","product_id":"FI_XBTUSD_210625","side":"sell","seq":21454983,"price":64094.5,"qty":23384.0,"timestamp":1618678110481}
1618678110.508134: {"feed":"book","product_id":"FI_XBTUSD_210625","side":"buy","seq":21454984,"price":63896.0,"qty":1151.0,"timestamp":1618678110481}
1618678110.508184: {"feed":"book","product_id":"FI_XBTUSD_210625","side":"buy","seq":21454985,"price":63896.0,"qty":2412.0,"timestamp":1618678110481}
1618678110.508229: {"feed":"book","product_id":"FI_XBTUSD_210625","side":"buy","seq":21454986,"price":63896.0,"qty":1261.0,"timestamp":1618678110481}
1618678110.508249: {"feed":"book","product_id":"FI_XBTUSD_210625","side":"buy","seq":21454987,"price":63896.0,"qty":2522.0,"timestamp":1618678110481}
1618678110.508269: {"feed":"book","product_id":"FI_XBTUSD_210625","side":"sell","seq":21454988,"price":64253.0,"qty":0.0,"timestamp":1618678110482}
1618678110.508296: {"feed":"book","product_id":"FI_XBTUSD_210625","side":"sell","seq":21454989,"price":64252.0,"qty":57275.0,"timestamp":1618678110482}
1618678110.50832: {"feed":"book","product_id":"FI_XBTUSD_210625","side":"buy","seq":21454990,"price":63728.0,"qty":0.0,"timestamp":1618678110482}
1618678110.5083468: {"feed":"book","product_id":"FI_XBTUSD_210625","side":"buy","seq":21454991,"price":63728.0,"qty":3317.0,"timestamp":1618678110482}
1618678110.5121238: {"feed":"book","product_id":"FI_XBTUSD_210625","side":"buy","seq":21454992,"price":63489.0,"qty":0.0,"timestamp":1618678110482}
1618678110.5122151: {"feed":"book","product_id":"FI_XBTUSD_210625","side":"buy","seq":21454993,"price":63489.0,"qty":4368.0,"timestamp":1618678110482}
1618678110.512257: {"feed":"book","product_id":"FI_XBTUSD_210924","side":"buy","seq":13850851,"price":52552.5,"qty":58850.0,"timestamp":1618678110484}
1618678110.5122838: {"feed":"book","product_id":"FI_XBTUSD_210625","side":"sell","seq":21454994,"price":64052.5,"qty":0.0,"timestamp":1618678110482}
1618678110.512314: {"feed":"book","product_id":"FI_XBTUSD_210625","side":"sell","seq":21454995,"price":64052.5,"qty":14193.0,"timestamp":1618678110482}
1618678110.5123389: {"feed":"book","product_id":"FI_XBTUSD_210625","side":"sell","seq":21454996,"price":64118.5,"qty":0.0,"timestamp":1618678110482}
1618678110.5123641: {"feed":"book","product_id":"FI_XBTUSD_210625","side":"sell","seq":21454997,"price":64118.5,"qty":29097.0,"timestamp":1618678110482}
1618678110.512388: {"feed":"book","product_id":"FI_XBTUSD_210625","side":"buy","seq":21454998,"price":63879.0,"qty":0.0,"timestamp":1618678110482}
1618678110.5124118: {"feed":"book","product_id":"FI_XBTUSD_210625","side":"buy","seq":21454999,"price":63879.0,"qty":1511.0,"timestamp":1618678110482}
1618678110.512436: {"feed":"book","product_id":"FI_XBTUSD_210625","side":"sell","seq":21455000,"price":64516.5,"qty":0.0,"timestamp":1618678110482}
1618678110.512461: {"feed":"book","product_id":"FI_XBTUSD_210625","side":"sell","seq":21455001,"price":64516.5,"qty":76451.0,"timestamp":1618678110482}
1618678110.517536: {"feed":"book","product_id":"PI_BCHUSD","side":"sell","seq":16258650,"price":1062.1,"qty":2520.0,"timestamp":1618678110492}
1618678110.51766: {"feed":"book","product_id":"PI_BCHUSD","side":"buy","seq":16258651,"price":1059.1,"qty":3423.0,"timestamp":1618678110492}
1618678110.5441558: {"feed":"book","product_id":"PI_BCHUSD","side":"sell","seq":16258652,"price":1062.8,"qty":46950.0,"timestamp":1618678110517}
1618678110.544263: {"feed":"book","product_id":"PI_BCHUSD","side":"sell","seq":16258653,"price":1062.9,"qty":3748.0,"timestamp":1618678110518}
1618678110.625481: {"feed":"book","product_id":"FI_ETHUSD_210625","side":"sell","seq":12455497,"price":2512.1,"qty":0.0,"timestamp":1618678110592}
1618678110.6256158: {"feed":"book","product_id":"FI_ETHUSD_210625","side":"sell","seq":12455498,"price":2513.8,"qty":34716.0,"timestamp":1618678110592}
1618678110.626102: {"feed":"book","product_id":"PI_BCHUSD","side":"buy","seq":16258654,"price":1058.1,"qty":7551.0,"timestamp":1618678110598}
1618678110.626178: {"feed":"book","product_id":"PI_BCHUSD","side":"buy","seq":16258655,"price":1058.7,"qty":3924.0,"timestamp":1618678110598}
1618678110.633039: {"feed":"book","product_id":"FI_ETHUSD_210625","side":"sell","seq":12455499,"price":2512.05,"qty":0.0,"timestamp":1618678110603}
1618678110.633172: {"feed":"book","product_id":"FI_ETHUSD_210625","side":"sell","seq":12455500,"price":2512.15,"qty":303574.0,"timestamp":1618678110603}
1618678110.633235: {"feed":"book","product_id":"FI_XBTUSD_210625","side":"sell","seq":21455002,"price":64095.0,"qty":0.0,"timestamp":1618678110603}
1618678110.633288: {"feed":"book","product_id":"FI_XBTUSD_210625","side":"sell","seq":21455003,"price":64094.0,"qty":250001.0,"timestamp":1618678110603}
1618678110.6333299: {"feed":"book","product_id":"FI_XBTUSD_210625","side":"sell","seq":21455004,"price":64252.5,"qty":0.0,"timestamp":1618678110603}
1618678110.633395: {"feed":"book","product_id":"FI_XBTUSD_210625","side":"sell","seq":21455005,"price":64251.5,"qty":125003.0,"timestamp":1618678110603}
1618678110.639442: {"feed":"book","product_id":"PI_BCHUSD","side":"buy","seq":16258656,"price":1058.0,"qty":27691.0,"timestamp":1618678110606}
1618678110.716655: {"feed":"book","product_id":"PI_BCHUSD","side":"sell","seq":16258657,"price":1063.6,"qty":3642.0,"timestamp":1618678110690}
1618678110.716761: {"feed":"book","product_id":"PI_BCHUSD","side":"sell","seq":16258658,"price":1062.8,"qty":41956.0,"timestamp":1618678110690}
1618678110.7168078: {"feed":"book","product_id":"PI_BCHUSD","side":"sell","seq":16258659,"price":1063.2,"qty":7839.0,"timestamp":1618678110690}
1618678110.73182: {"feed":"book","product_id":"FI_XBTUSD_210430","side":"buy","seq":12237553,"price":59445.5,"qty":48172.0,"timestamp":1618678110692}
1618678110.731888: {"feed":"book","product_id":"PI_BCHUSD","side":"sell","seq":16258660,"price":1061.8,"qty":2880.0,"timestamp":1618678110692}
1618678110.7319732: {"feed":"book","product_id":"PI_BCHUSD","side":"sell","seq":16258661,"price":1062.6,"qty":3445.0,"timestamp":1618678110692}
1618678110.732002: {"feed":"book","product_id":"PI_BCHUSD","side":"sell","seq":16258662,"price":1062.5,"qty":6616.0,"timestamp":1618678110692}
1618678110.732024: {"feed":"book","product_id":"PI_BCHUSD","side":"buy","seq":16258663,"price":1058.9,"qty":8545.0,"timestamp":1618678110694}
1618678110.7320452: {"feed":"book","product_id":"PI_BCHUSD","side":"sell","seq":16258664,"price":1063.2,"qty":18471.0,"timestamp":1618678110696}
1618678110.7320662: {"feed":"book","product_id":"FI_ETHUSD_210430","side":"sell","seq":4780837,"price":2399.55,"qty":13049.0,"timestamp":1618678110697}
1618678110.769946: {"feed":"book","product_id":"FI_XBTUSD_210430","side":"buy","seq":12237554,"price":59445.5,"qty":48511.0,"timestamp":1618678110739}
1618678110.7701042: {"feed":"book","product_id":"PI_BCHUSD","side":"sell","seq":16258665,"price":1061.8,"qty":0.0,"timestamp":1618678110739}
1618678110.770171: {"feed":"book","product_id":"PI_BCHUSD","side":"sell","seq":16258666,"price":1062.6,"qty":8435.0,"timestamp":1618678110739}
1618678110.770211: {"feed":"book","product_id":"PI_BCHUSD","side":"sell","seq":16258667,"price":1063.0,"qty":4988.0,"timestamp":1618678110739}
1618678110.7702541: {"feed":"book","product_id":"PI_BCHUSD","side":"sell","seq":16258668,"price":1062.2,"qty":4992.0,"timestamp":1618678110739}
1618678110.777643: {"feed":"book","product_id":"PI_BCHUSD","side":"sell","seq":16258669,"price":1061.9,"qty":50.0,"timestamp":1618678110750}
1618678110.777753: {"feed":"book","product_id":"PI_BCHUSD","side":"buy","seq":16258670,"price":1058.6,"qty":34532.0,"timestamp":1618678110750}
1618678110.781054: {"feed":"book","product_id":"PI_BCHUSD","side":"buy","seq":16258671,"price":1059.5,"qty":30647.0,"timestamp":1618678110757}
1618678110.804131: {"feed":"book","product_id":"FI_XRPUSD_210625","side":"buy","seq":3631536,"price":1.6922,"qty":0.0,"timestamp":1618678110778}
1618678110.804218: {"feed":"book","product_id":"FI_XRPUSD_210625","side":"buy","seq":3631537,"price":1.6924,"qty":50.0,"timestamp":1618678110778}
1618678110.811311: {"feed":"book","product_id":"FI_XRPUSD_210625","side":"sell","seq":3631538,"price":1.6973,"qty":0.0,"timestamp":1618678110778}
1618678110.811401: {"feed":"book","product_id":"FI_XRPUSD_210625","side":"sell","seq":3631539,"price":1.6971,"qty":50.0,"timestamp":1618678110778}
1618678110.811442: {"feed":"book","product_id":"FI_XRPUSD_210625","side":"sell","seq":3631540,"price":1.6972,"qty":768.0,"timestamp":1618678110783}
1618678110.811467: {"feed":"book","product_id":"FI_XRPUSD_210625","side":"sell","seq":3631541,"price":1.6987,"qty":324.0,"timestamp":1618678110783}
1618678110.8114922: {"feed":"book","product_id":"FI_XBTUSD_210625","side":"sell","seq":21455006,"price":64053.5,"qty":32466.0,"timestamp":1618678110786}
1618678110.814772: {"feed":"book","product_id":"FI_XRPUSD_210625","side":"buy","seq":3631542,"price":1.6923,"qty":0.0,"timestamp":1618678110789}
