wss://futures.kraken.com/ws/v1 <- 1618678101.4930098: {"event":"subscribe","feed":"book","product_ids":["pi_bchusd","fi_bchusd_210625","fi_xbtusd_210430","fi_xrpusd_210625","fi_ethusd_210924","fi_xbtusd_210924","fi_ethusd_210430","fi_xbtusd_210625","fi_bchusd_210430","fi_ethusd_210625"]}
1618678101.6031911: {"event":"subscribed","feed":"book","product_ids":["PI_BCHUSD"]}
1618678101.603198: {"event":"subscribed","feed":"book","product_ids":["FI_BCHUSD_210625"]}
1618678101.603204: {"event":"subscribed","feed":"book","product_ids":["FI_XBTUSD_210430"]}
1618678101.603211: {"event":"subscribed","feed":"book","product_ids":["FI_XRPUSD_210625"]}
1618678101.603217: {"event":"subscribed","feed":"book","product_ids":["FI_ETHUSD_210924"]}
1618678101.603223: {"event":"subscribed","feed":"book","product_ids":["FI_XBTUSD_210924"]}
1618678101.60323: {"event":"subscribed","feed":"book","product_ids":["FI_ETHUSD_210430"]}
1618678101.6032362: {"event":"subscribed","feed":"book","product_ids":["FI_XBTUSD_210625"]}
1618678101.603243: {"event":"subscribed","feed":"book","product_ids":["FI_BCHUSD_210430"]}
1618678101.6032488: {"event":"subscribed","feed":"book","product_ids":["FI_ETHUSD_210625"]}
1618678101.8693051: {"feed":"book_snapshot","product_id":"FI_BCHUSD_210625","timestamp":1618678100126,"seq":2240145,"tickSize":null,"bids":[{"price":1130.8,"qty":50.0},{"price":1130.7,"qty":30900.0},{"price":1130.6,"qty":14399.0},{"price":1130.0,"qty":85.0},{"price":1127.3,"qty":36050.0},{"price":1126.9,"qty":10562.0},{"price":1124.8,"qty":44999.0},{"price":1123.8,"qty":41200.0},{"price":1108.3,"qty":4513.0},{"price":1108.2,"qty":13310.0},{"price":1108.1,"qty":28332.0},{"price":1107.8,"qty":73795.0},{"price":1101.7,"qty":77130.0},{"price":1100.7,"qty":76026.0},{"price":1085.9,"qty":58220.0},{"price":1085.0,"qty":45162.0},{"price":1059.6,"qty":59492.0},{"price":1057.2,"qty":45216.0},{"price":1000.0,"qty":100.0},{"price":960.0,"qty":50.0},{"price":437.1,"qty":5000.0}],"asks":[{"price":1135.9,"qty":50.0},{"price":1136.0,"qty":31026.0},{"price":1137.5,"qty":76.0},{"price":1137.8,"qty":83.0},{"price":1138.1,"qty":68.0},{"price":1139.5,"qty":36197.0},{"price":1139.7,"qty":4513.0},{"price":1141.0,"qty":14399.0},{"price":1141.8,"qty":15022.0},{"price":1143.1,"qty":41367.0},{"price":1143.5,"qty":9296.0},{"price":1147.9,"qty":13310.0},{"price":1156.4,"qty":73680.0},{"price":1157.7,"qty":73158.0},{"price":1162.1,"qty":76735.0},{"price":1165.1,"qty":59303.0},{"price":1189.5,"qty":58146.0},{"price":1204.8,"qty":44211.0},{"price":1209.4,"qty":46204.0},{"price":1209.9,"qty":13310.0}]}
1618678101.8708951: {"feed":"book_snapshot","product_id":"FI_ETHUSD_210430","timestamp":1618678101536,"seq":4780731,"tickSize":null,"bids":[{"price":2388.6,"qty":1020.0},{"price":2388.1,"qty":1271.0},{"price":2388.05,"qty":126842.0},{"price":2387.85,"qty":25500.0},{"price":2387.6,"qty":1641.0},{"price":2387.1,"qty":1489.0},{"price":2386.85,"qty":7500.0},{"price":2386.05,"qty":165870.0},{"price":2384.2,"qty":51000.0},{"price":2384.05,"qty":195141.0},{"price":2383.05,"qty":19199.0},{"price":2382.2,"qty":6118.0},{"price":2382.1,"qty":243926.0},{"price":2380.5,"qty":102000.0},{"price":2380.1,"qty":292712.0},{"price":2379.55,"qty":23146.0},{"price":2379.2,"qty":578.0},{"price":2378.35,"qty":20352.0},{"price":2377.75,"qty":204000.0},{"price":2375.75,"qty":38399.0},{"price":2371.55,"qty":201926.0},{"price":2370.2,"qty":59999.0},{"price":2360.8,"qty":95999.0},{"price":2360.6,"qty":10000.0},{"price":2353.2,"qty":97530.0},{"price":2350.8,"qty":78424.0},{"price":2337.2,"qty":39630.0},{"price":2316.15,"qty":39674.0},{"price":2296.95,"qty":39016.0},{"price":2251.0,"qty":100000.0},{"price":2249.65,"qty":39926.0},{"price":2228.1,"qty":100000.0},{"price":2227.45,"qty":5900.0},{"price":2000.0,"qty":660.0},{"price":1610.0,"qty":2500.0}],"asks":[{"price":2391.55,"qty":2559.0},{"price":2391.6,"qty":25500.0},{"price":2391.8,"qty":121999.0},{"price":2392.45,"qty":1283.0},{"price":2393.2,"qty":1274.0},{"price":2393.3,"qty":19928.0},{"price":2393.85,"qty":159537.0},{"price":2393.9,"qty":1351.0},{"price":2394.1,"qty":19199.0},{"price":2394.5,"qty":6118.0},{"price":2395.45,"qty":578.0},{"price":2395.85,"qty":187691.0},{"price":2395.95,"qty":51000.0},{"price":2396.4,"qty":225001.0},{"price":2396.45,"qty":20352.0},{"price":2397.9,"qty":234614.0},{"price":2399.85,"qty":102000.0},{"price":2399.9,"qty":281537.0},{"price":2401.95,"qty":584747.0},{"price":2402.0,"qty":38399.0},{"price":2403.8,"qty":25003.0},{"price":2403.85,"qty":204000.0},{"price":2405.25,"qty":59999.0},{"price":2408.35,"qty":199302.0},{"price":2414.65,"qty":95999.0},{"price":2419.3,"qty":102696.0},{"price":2424.1,"qty":77604.0},{"price":2432.7,"qty":40938.0},{"price":2436.25,"qty":40330.0},{"price":2471.5,"qty":39252.0},{"price":2487.85,"qty":39238.0},{"price":2491.95,"qty":75000.0},{"price":2511.85,"qty":50000.0}]}
1618678101.871256: {"feed":"book_snapshot","product_id":"PI_BCHUSD","timestamp":1618678101097,"seq":16257856,"tickSize":null,"bids":[{"price":1060.4,"qty":50.0},{"price":1060.3,"qty":28806.0},{"price":1060.1,"qty":3541.0},{"price":1059.9,"qty":7476.0},{"price":1059.8,"qty":12289.0},{"price":1059.6,"qty":25335.0},{"price":1059.5,"qty":14870.0},{"price":1059.4,"qty":12294.0},{"price":1059.3,"qty":6972.0},{"price":1059.0,"qty":41451.0},{"price":1058.9,"qty":14399.0},{"price":1058.8,"qty":6042.0},{"price":1058.7,"qty":32122.0},{"price":1058.5,"qty":3768.0},{"price":1058.3,"qty":7744.0},{"price":1058.2,"qty":30505.0},{"price":1058.1,"qty":33608.0},{"price":1057.9,"qty":28962.0},{"price":1057.8,"qty":4107.0},{"price":1057.0,"qty":4937.0},{"price":1056.9,"qty":30993.0},{"price":1056.0,"qty":14641.0},{"price":1055.9,"qty":38409.0},{"price":1055.0,"qty":10217.0},{"price":1054.8,"qty":5161.0},{"price":1054.6,"qty":24787.0},{"price":1053.5,"qty":44999.0},{"price":1048.1,"qty":267883.0},{"price":1045.4,"qty":76035.0},{"price":1044.9,"qty":102647.0},{"price":1034.0,"qty":14741.0},{"price":1030.8,"qty":73565.0},{"price":1021.1,"qty":40056.0},{"price":1017.1,"qty":24880.0},{"price":993.0,"qty":50.0},{"price":963.0,"qty":40.0},{"price":959.0,"qty":100.0},{"price":936.8,"qty":1000.0},{"price":912.0,"qty":100.0},{"price":901.0,"qty":40.0},{"price":873.4,"qty":1000.0},{"price":848.0,"qty":40.0},{"price":810.0,"qty":810.0},{"price":740.0,"qty":2960.0},{"price":707.0,"qty":500.0},{"price":688.0,"qty":120.0},{"price":685.0,"qty":4.0},{"price":680.4,"qty":500.0},{"price":666.0,"qty":80.0},{"price":600.0,"qty":1200.0},{"price":500.0,"qty":250.0},{"price":400.0,"qty":300.0},{"price":373.0,"qty":1000.0},{"price":355.0,"qty":45.0},{"price":350.0,"qty":80.0},{"price":342.7,"qty":360.0},{"price":335.0,"qty":20.0},{"price":325.0,"qty":50.0},{"price":285.0,"qty":100.0},{"price":280.0,"qty":90001.0},{"price":275.0,"qty":100.0},{"price":250.8,"qty":50.0},{"price":230.0,"qty":100.0},{"price":220.0,"qty":100.0},{"price":210.6,"qty":427.0},{"price":210.0,"qty":100.0},{"price":160.0,"qty":177.0},{"price":2.5,"qty":200.0},{"price":1.0,"qty":200.0},{"price":0.5,"qty":200.0},{"price":0.2,"qty":200.0},{"price":0.1,"qty":200.0}],"asks":[{"price":1062.6,"qty":2638.0},{"price":1062.8,"qty":12193.0},{"price":1063.0,"qty":21915.0},{"price":1063.1,"qty":18717.0},{"price":1063.2,"qty":1302.0},{"price":1063.3,"qty":3458.0},{"price":1063.4,"qty":18126.0},{"price":1063.7,"qty":45789.0},{"price":1063.8,"qty":32938.0},{"price":1064.0,"qty":27078.0},{"price":1064.1,"qty":3700.0},{"price":1064.2,"qty":12790.0},{"price":1064.3,"qty":9893.0},{"price":1064.4,"qty":19263.0},{"price":1064.6,"qty":4184.0},{"price":1064.7,"qty":29188.0},{"price":1064.9,"qty":1079.0},{"price":1065.2,"qty":3778.0},{"price":1065.4,"qty":30553.0},{"price":1065.6,"qty":30230.0},{"price":1065.7,"qty":31948.0},{"price":1065.8,"qty":3846.0},{"price":1067.3,"qty":2467.0},{"price":1067.6,"qty":4937.0},{"price":1067.8,"qty":36512.0},{"price":1068.9,"qty":14641.0},{"price":1069.0,"qty":10217.0},{"price":1070.7,"qty":24787.0},{"price":1075.1,"qty":243485.0},{"price":1080.3,"qty":112508.0},{"price":1081.9,"qty":73242.0},{"price":1083.6,"qty":75347.0},{"price":1085.0,"qty":14641.0},{"price":1094.0,"qty":24440.0},{"price":1094.3,"qty":25317.0},{"price":1096.0,"qty":1.0},{"price":1101.0,"qty":14641.0},{"price":1150.0,"qty":300.0},{"price":1200.0,"qty":20.0},{"price":1300.0,"qty":1300.0},{"price":1580.0,"qty":4080.0},{"price":1944.4,"qty":11157.0},{"price":9999999.9,"qty":2000000.0}]}
1618678101.871667: {"feed":"book_snapshot","product_id":"FI_XBTUSD_210430","timestamp":1618678101277,"seq":12237398,"tickSize":null,"bids":[{"price":61189.5,"qty":658.0},{"price":61174.5,"qty":203100.0},{"price":61171.5,"qty":2581.0},{"price":61163.0,"qty":51000.0},{"price":61130.5,"qty":23999.0},{"price":61128.0,"qty":322571.0},{"price":61127.0,"qty":23480.0},{"price":61081.5,"qty":382307.0},{"price":61078.5,"qty":102000.0},{"price":61075.0,"qty":8934.0},{"price":61054.0,"qty":1383.0},{"price":61036.0,"qty":250001.0},{"price":61035.5,"qty":418148.0},{"price":60993.5,"qty":204000.0},{"price":60989.0,"qty":537619.0},{"price":60988.0,"qty":30465.0},{"price":60938.0,"qty":493105.0},{"price":60937.5,"qty":408000.0},{"price":60929.5,"qty":47999.0},{"price":60859.0,"qty":125003.0},{"price":60858.5,"qty":152826.0},{"price":60800.0,"qty":250.0},{"price":60764.0,"qty":74999.0},{"price":60581.5,"qty":119999.0},{"price":60417.0,"qty":145653.0},{"price":60400.0,"qty":150717.0},{"price":60285.0,"qty":298739.0},{"price":60000.0,"qty":20000.0},{"price":59959.0,"qty":88767.0},{"price":59445.5,"qty":52722.0},{"price":59445.0,"qty":300000.0},{"price":59296.0,"qty":91953.0},{"price":58790.0,"qty":87768.0},{"price":57874.5,"qty":89160.0},{"price":55555.0,"qty":2000.0},{"price":55000.0,"qty":11000.0}],"asks":[{"price":61253.5,"qty":1904.0},{"price":61254.0,"qty":143900.0},{"price":61259.5,"qty":51000.0},{"price":61262.5,"qty":23400.0},{"price":61264.5,"qty":10000.0},{"price":61276.5,"qty":2794.0},{"price":61294.0,"qty":2747.0},{"price":61300.5,"qty":228548.0},{"price":61301.0,"qty":1383.0},{"price":61308.5,"qty":2815.0},{"price":61319.0,"qty":8934.0},{"price":61344.5,"qty":102000.0},{"price":61347.0,"qty":270871.0},{"price":61355.5,"qty":23999.0},{"price":61393.0,"qty":250001.0},{"price":61393.5,"qty":296265.0},{"price":61402.0,"qty":30465.0},{"price":61429.0,"qty":204000.0},{"price":61440.0,"qty":380913.0},{"price":61474.5,"qty":47999.0},{"price":61514.0,"qty":408000.0},{"price":61537.0,"qty":148344.0},{"price":61654.0,"qty":74999.0},{"price":61803.5,"qty":151413.0},{"price":61844.5,"qty":119999.0},{"price":62119.5,"qty":150495.0},{"price":62320.0,"qty":88182.0},{"price":62615.5,"qty":90021.0},{"price":63410.0,"qty":91581.0},{"price":63830.0,"qty":5600.0},{"price":63940.0,"qty":91803.0},{"price":63965.5,"qty":1.0},{"price":66330.0,"qty":300.0},{"price":66500.0,"qty":46000.0},{"price":67000.0,"qty":167943.0},{"price":68380.5,"qty":20000.0},{"price":69200.0,"qty":100000.0},{"price":69256.0,"qty":20000.0},{"price":70193.5,"qty":20000.0},{"price":71100.0,"qty":20000.0},{"price":72006.5,"qty":20000.0},{"price":72711.5,"qty":20000.0},{"price":73517.0,"qty":20000.0}]}
1618678101.871953: {"feed":"book_snapshot","product_id":"FI_ETHUSD_210924","timestamp":1618678100841,"seq":3859071,"tickSize":null,"bids":[{"price":2656.9,"qty":840.0},{"price":2654.65,"qty":21000.0},{"price":2653.75,"qty":107300.0},{"price":2653.25,"qty":26400.0},{"price":2650.4,"qty":140316.0},{"price":2648.9,"qty":42000.0},{"price":2647.05,"qty":165077.0},{"price":2643.85,"qty":13310.0},{"price":2643.8,"qty":84000.0},{"price":2643.75,"qty":208347.0},{"price":2643.05,"qty":2000.0},{"price":2640.45,"qty":247616.0},{"price":2638.15,"qty":19199.0},{"price":2637.95,"qty":168000.0},{"price":2630.75,"qty":18310.0},{"price":2630.35,"qty":38399.0},{"price":2617.4,"qty":13867.0},{"price":2617.35,"qty":15000.0},{"price":2615.9,"qty":219.0},{"price":2613.05,"qty":95999.0},{"price":2603.15,"qty":39628.0},{"price":2600.8,"qty":54230.0},{"price":2585.3,"qty":40228.0},{"price":2583.6,"qty":24080.0},{"price":2550.0,"qty":14310.0},{"price":2549.1,"qty":23491.0},{"price":2534.9,"qty":23764.0},{"price":2512.0,"qty":75000.0},{"price":2482.0,"qty":50.0},{"price":2455.55,"qty":24581.0},{"price":2256.0,"qty":10000.0},{"price":2194.0,"qty":100.0},{"price":2180.0,"qty":500.0},{"price":2130.0,"qty":1000.0},{"price":2100.0,"qty":100.0},{"price":2050.0,"qty":20000.0},{"price":2005.0,"qty":100.0},{"price":1950.0,"qty":10.0},{"price":1945.0,"qty":10.0},{"price":1940.0,"qty":10.0},{"price":1935.0,"qty":10.0},{"price":1930.0,"qty":10.0},{"price":1925.0,"qty":10.0},{"price":1920.0,"qty":32309.0},{"price":1915.0,"qty":10.0},{"price":1910.0,"qty":10.0},{"price":1905.0,"qty":10.0},{"price":1900.0,"qty":10.0},{"price":1895.0,"qty":10.0},{"price":1890.0,"qty":10.0},{"price":1885.8,"qty":4000.0},{"price":1885.0,"qty":10.0},{"price":1880.0,"qty":10.0},{"price":1875.0,"qty":10.0},{"price":1870.0,"qty":10.0},{"price":1865.0,"qty":10.0},{"price":1860.0,"qty":10.0},{"price":1855.0,"qty":10.0},{"price":1850.0,"qty":10.0},{"price":1845.0,"qty":10.0},{"price":1840.0,"qty":10.0},{"price":1835.0,"qty":10.0},{"price":1833.5,"qty":5000.0},{"price":1830.0,"qty":10.0},{"price":1736.0,"qty":200.0},{"price":1600.0,"qty":800.0},{"price":1590.0,"qty":500.0},{"price":1450.0,"qty":1000.0},{"price":1206.7,"qty":1000.0}],"asks":[{"price":2660.15,"qty":840.0},{"price":2660.2,"qty":50.0},{"price":2660.4,"qty":19199.0},{"price":2660.45,"qty":134311.0},{"price":2661.1,"qty":21000.0},{"price":2661.5,"qty":315.0},{"price":2662.2,"qty":477.0},{"price":2662.25,"qty":2000.0},{"price":2662.4,"qty":2000.0},{"price":2663.5,"qty":429.0},{"price":2664.0,"qty":225001.0},{"price":2664.05,"qty":175638.0},{"price":2667.65,"qty":206633.0},{"price":2667.85,"qty":42000.0},{"price":2670.1,"qty":13310.0},{"price":2670.15,"qty":12570.0},{"price":2670.6,"qty":557.0},{"price":2671.2,"qty":38399.0},{"price":2671.25,"qty":258291.0},{"price":2671.5,"qty":219.0},{"price":2674.45,"qty":84000.0},{"price":2674.85,"qty":309949.0},{"price":2675.55,"qty":5000.0},{"price":2680.85,"qty":168000.0},{"price":2682.5,"qty":95999.0},{"price":2690.55,"qty":28310.0},{"price":2692.45,"qty":38950.0},{"price":2695.15,"qty":39969.0},{"price":2699.1,"qty":54220.0},{"price":2714.55,"qty":23748.0},{"price":2724.75,"qty":23898.0},{"price":2773.3,"qty":37934.0},{"price":2795.25,"qty":24295.0},{"price":2859.75,"qty":504.0},{"price":2899.75,"qty":502.0},{"price":2995.0,"qty":27522.0},{"price":3170.0,"qty":100000.0},{"price":3448.75,"qty":200.0},{"price":3944.05,"qty":200.0},{"price":19305.0,"qty":10.0}]}
1618678101.873215: {"feed":"book_snapshot","product_id":"FI_ETHUSD_210625","timestamp":1618678101464,"seq":12455147,"tickSize":null,"bids":[{"price":2502.2,"qty":860.0},{"price":2500.85,"qty":227.0},{"price":2500.8,"qty":24000.0},{"price":2500.35,"qty":239.0},{"price":2500.3,"qty":141837.0},{"price":2499.75,"qty":1655.0},{"price":2497.75,"qty":2000.0},{"price":2497.65,"qty":408.0},{"price":2497.6,"qty":183150.0},{"price":2497.15,"qty":2000.0},{"price":2497.0,"qty":48000.0},{"price":2496.55,"qty":4759.0},{"price":2496.5,"qty":3000.0},{"price":2496.25,"qty":3000.0},{"price":2495.4,"qty":21334.0},{"price":2494.85,"qty":215471.0},{"price":2493.9,"qty":623.0},{"price":2493.85,"qty":105707.0},{"price":2492.95,"qty":8787.0},{"price":2492.1,"qty":269338.0},{"price":2491.55,"qty":96000.0},{"price":2491.3,"qty":19199.0},{"price":2490.2,"qty":26620.0},{"price":2490.15,"qty":105680.0},{"price":2489.75,"qty":7610.0},{"price":2489.4,"qty":323206.0},{"price":2489.3,"qty":8787.0},{"price":2488.55,"qty":192000.0},{"price":2487.25,"qty":24940.0},{"price":2486.5,"qty":105680.0},{"price":2485.65,"qty":8786.0},{"price":2484.85,"qty":5000.0},{"price":2484.55,"qty":38399.0},{"price":2479.75,"qty":441.0},{"price":2479.2,"qty":27120.0},{"price":2477.2,"qty":910.0},{"price":2471.65,"qty":15000.0},{"price":2468.6,"qty":128567.0},{"price":2468.25,"qty":26620.0},{"price":2466.25,"qty":128250.0},{"price":2447.65,"qty":121562.0},{"price":2446.35,"qty":26620.0},{"price":2440.0,"qty":1000.0},{"price":2433.4,"qty":73637.0},{"price":2428.0,"qty":300000.0},{"price":2425.0,"qty":5000.0},{"price":2418.0,"qty":150000.0},{"price":2416.85,"qty":76717.0},{"price":2413.45,"qty":26620.0},{"price":2402.0,"qty":100000.0},{"price":2396.75,"qty":74527.0},{"price":2378.0,"qty":441.0},{"price":2330.15,"qty":76267.0},{"price":2303.0,"qty":40000.0},{"price":2261.0,"qty":1000.0},{"price":2143.0,"qty":300.0},{"price":2100.0,"qty":100.0},{"price":2070.0,"qty":50000.0},{"price":1993.0,"qty":2000.0},{"price":1955.0,"qty":40000.0},{"price":1910.0,"qty":50000.0},{"price":1865.0,"qty":10.0},{"price":1860.0,"qty":10.0},{"price":1855.0,"qty":10.0},{"price":1850.0,"qty":1610.0},{"price":1849.0,"qty":2500.0},{"price":1845.0,"qty":10.0},{"price":1840.0,"qty":10.0},{"price":1835.0,"qty":10.0},{"price":1830.0,"qty":10.0},{"price":1825.0,"qty":10.0},{"price":1820.0,"qty":10.0},{"price":1815.0,"qty":10.0},{"price":1810.0,"qty":10.0},{"price":1805.0,"qty":10.0},{"price":1800.0,"qty":10.0},{"price":1795.0,"qty":10.0},{"price":1790.0,"qty":10.0},{"price":1785.0,"qty":10.0},{"price":1780.0,"qty":10.0},{"price":1775.0,"qty":10.0},{"price":1770.0,"qty":10.0},{"price":1765.0,"qty":10.0},{"price":1760.0,"qty":100010.0},{"price":1755.0,"qty":2010.0},{"price":1750.0,"qty":10.0},{"price":1705.0,"qty":2000.0},{"price":1663.7,"qty":8852.0},{"price":1655.0,"qty":2000.0},{"price":1650.0,"qty":75000.0},{"price":1605.0,"qty":2000.0},{"price":1600.0,"qty":22554.0},{"price":1555.0,"qty":2000.0},{"price":1505.0,"qty":2000.0},{"price":1455.0,"qty":2000.0},{"price":1417.0,"qty":2000.0},{"price":1405.0,"qty":2000.0},{"price":1355.0,"qty":2000.0},{"price":1258.0,"qty":2000.0},{"price":1175.05,"qty":50.0},{"price":1111.0,"qty":1000.0},{"price":1075.65,"qty":50.0}],"asks":[{"price":2505.15,"qty":10713.0},{"price":2505.2,"qty":127492.0},{"price":2505.65,"qty":3000.0},{"price":2506.05,"qty":27574.0},{"price":2506.15,"qty":3000.0},{"price":2506.95,"qty":1295.0},{"price":2507.35,"qty":7610.0},{"price":2507.5,"qty":1438.0},{"price":2507.9,"qty":2000.0},{"price":2507.95,"qty":19640.0},{"price":2508.05,"qty":32417.0},{"price":2508.1,"qty":166721.0},{"price":2509.25,"qty":225001.0},{"price":2509.3,"qty":62013.0},{"price":2509.8,"qty":36760.0},{"price":2510.25,"qty":4594.0},{"price":2511.0,"qty":196142.0},{"price":2511.1,"qty":48000.0},{"price":2512.55,"qty":24940.0},{"price":2512.95,"qty":62013.0},{"price":2513.35,"qty":32556.0},{"price":2513.4,"qty":303574.0},{"price":2513.45,"qty":36760.0},{"price":2513.9,"qty":245178.0},{"price":2515.95,"qty":38399.0},{"price":2516.3,"qty":51623.0},{"price":2516.35,"qty":96000.0},{"price":2516.6,"qty":62013.0},{"price":2516.8,"qty":294213.0},{"price":2518.0,"qty":36693.0},{"price":2519.0,"qty":59999.0},{"price":2520.05,"qty":5000.0},{"price":2520.4,"qty":21044.0},{"price":2521.1,"qty":192000.0},{"price":2530.2,"qty":47804.0},{"price":2530.45,"qty":26620.0},{"price":2530.8,"qty":122325.0},{"price":2532.4,"qty":123710.0},{"price":2532.6,"qty":15000.0},{"price":2543.35,"qty":124325.0},{"price":2544.95,"qty":26620.0},{"price":2550.1,"qty":76752.0},{"price":2570.85,"qty":73795.0},{"price":2574.05,"qty":26620.0},{"price":2580.25,"qty":75290.0},{"price":2634.05,"qty":72975.0},{"price":2650.0,"qty":1000.0},{"price":2725.0,"qty":500.0},{"price":2750.0,"qty":1500.0},{"price":2800.0,"qty":1000.0},{"price":2850.0,"qty":1000.0},{"price":2896.0,"qty":502.0},{"price":2899.75,"qty":502.0},{"price":2900.0,"qty":1000.0},{"price":2950.0,"qty":1000.0},{"price":2995.65,"qty":7000.0},{"price":3000.0,"qty":4000.0},{"price":3050.0,"qty":1000.0},{"price":3100.0,"qty":1000.0},{"price":3150.0,"qty":1000.0},{"price":3200.0,"qty":1000.0},{"price":3250.0,"qty":1000.0},{"price":3300.0,"qty":1000.0},{"price":4000.0,"qty":3000.0}]}
1618678101.873674: {"feed":"book_snapshot","product_id":"FI_XRPUSD_210625","timestamp":1618678101461,"seq":3631408,"tickSize":null,"bids":[{"price":1.6954,"qty":50.0},{"price":1.6948,"qty":68.0},{"price":1.6932,"qty":19200.0},{"price":1.6924,"qty":2104.0},{"price":1.6883,"qty":33599.0},{"price":1.6882,"qty":57600.0},{"price":1.6825,"qty":2955.0},{"price":1.6824,"qty":172800.0},{"price":1.6802,"qty":9912.0},{"price":1.67,"qty":48640.0},{"price":1.6638,"qty":48708.0},{"price":1.6629,"qty":51225.0},{"price":1.6456,"qty":30056.0},{"price":1.6293,"qty":30881.0},{"price":1.6161,"qty":30772.0},{"price":1.5739,"qty":30747.0},{"price":1.571,"qty":500.0},{"price":1.513,"qty":10.0},{"price":1.442,"qty":170.0},{"price":1.4378,"qty":20.0},{"price":1.35,"qty":50.0},{"price":1.3424,"qty":5.0},{"price":1.28,"qty":100.0},{"price":1.25,"qty":45.0},{"price":1.1382,"qty":25.0},{"price":1.0428,"qty":25.0},{"price":0.9373,"qty":25.0},{"price":0.7925,"qty":6000.0},{"price":0.7674,"qty":6000.0},{"price":0.75,"qty":5000.0},{"price":0.7465,"qty":6000.0},{"price":0.7228,"qty":6000.0},{"price":0.71,"qty":50.0},{"price":0.62,"qty":50.0},{"price":0.5367,"qty":25.0},{"price":0.4928,"qty":400.0},{"price":0.456,"qty":25.0},{"price":0.4045,"qty":25.0},{"price":0.3523,"qty":25.0}],"asks":[{"price":1.6987,"qty":768.0},{"price":1.6988,"qty":50.0},{"price":1.6995,"qty":18968.0},{"price":1.7055,"qty":57600.0},{"price":1.7096,"qty":172800.0},{"price":1.7108,"qty":2955.0},{"price":1.7122,"qty":9912.0},{"price":1.7135,"qty":1524.0},{"price":1.7201,"qty":33599.0},{"price":1.7322,"qty":49521.0},{"price":1.7335,"qty":50113.0},{"price":1.7336,"qty":50663.0},{"price":1.7389,"qty":30713.0},{"price":1.7603,"qty":29866.0},{"price":1.761,"qty":30338.0},{"price":1.7732,"qty":30838.0},{"price":1.7792,"qty":170.0},{"price":1.8,"qty":50.0},{"price":1.8897,"qty":170.0},{"price":1.9188,"qty":1000.0},{"price":1.9998,"qty":180.0},{"price":2.07,"qty":10000.0},{"price":2.1108,"qty":510.0},{"price":2.222,"qty":2.0},{"price":2.23,"qty":10000.0},{"price":3.333,"qty":2.0}]}
1618678101.951793: {"feed":"book_snapshot","product_id":"FI_BCHUSD_210430","timestamp":1618678099909,"seq":1411829,"tickSize":null,"bids":[{"price":1075.8,"qty":50.0},{"price":1075.7,"qty":24162.0},{"price":1073.6,"qty":5378.0},{"price":1073.0,"qty":28189.0},{"price":1070.7,"qty":28799.0},{"price":1070.3,"qty":32216.0},{"price":1068.2,"qty":19360.0},{"price":1068.1,"qty":44999.0},{"price":1061.1,"qty":146242.0},{"price":1052.5,"qty":74463.0},{"price":1051.6,"qty":74781.0},{"price":1038.7,"qty":45009.0},{"price":1034.5,"qty":44685.0},{"price":1014.8,"qty":44593.0},{"price":1004.0,"qty":45642.0},{"price":950.0,"qty":3493.0},{"price":493.0,"qty":2979.0}],"asks":[{"price":1080.1,"qty":14449.0},{"price":1080.2,"qty":28568.0},{"price":1081.3,"qty":4590.0},{"price":1081.4,"qty":6822.0},{"price":1083.1,"qty":33330.0},{"price":1083.4,"qty":14770.0},{"price":1086.1,"qty":38091.0},{"price":1086.6,"qty":44999.0},{"price":1094.5,"qty":146754.0},{"price":1096.8,"qty":72945.0},{"price":1101.8,"qty":44142.0},{"price":1102.6,"qty":75474.0},{"price":1120.2,"qty":44256.0},{"price":1130.2,"qty":45363.0},{"price":1143.8,"qty":45519.0}]}
1618678101.951987: {"feed":"book_snapshot","product_id":"FI_XBTUSD_210625","timestamp":1618678101572,"seq":21454484,"tickSize":null,"bids":[{"price":63940.5,"qty":1920.0},{"price":63926.0,"qty":2135.0},{"price":63925.5,"qty":21250.0},{"price":63917.0,"qty":48000.0},{"price":63906.0,"qty":200436.0},{"price":63877.5,"qty":5000.0},{"price":63864.5,"qty":3000.0},{"price":63854.0,"qty":3000.0},{"price":63853.0,"qty":2049.0},{"price":63852.5,"qty":318340.0},{"price":63852.0,"qty":10000.0},{"price":63844.0,"qty":3000.0},{"price":63814.0,"qty":4500.0},{"price":63812.0,"qty":10000.0},{"price":63808.0,"qty":96000.0},{"price":63800.0,"qty":250001.0},{"price":63799.5,"qty":377291.0},{"price":63798.5,"qty":23999.0},{"price":63798.0,"qty":6000.0},{"price":63777.5,"qty":3000.0},{"price":63748.5,"qty":3248.0},{"price":63748.0,"qty":25090.0},{"price":63747.5,"qty":5825.0},{"price":63746.0,"qty":412663.0},{"price":63745.5,"qty":25091.0},{"price":63732.0,"qty":8784.0},{"price":63727.0,"qty":129000.0},{"price":63723.5,"qty":1056.0},{"price":63719.5,"qty":48.0},{"price":63707.5,"qty":192000.0},{"price":63692.5,"qty":530566.0},{"price":63677.0,"qty":19440.0},{"price":63668.5,"qty":29466.0},{"price":63666.0,"qty":47999.0},{"price":63660.5,"qty":10000.0},{"price":63646.0,"qty":39930.0},{"price":63639.5,"qty":707421.0},{"price":63628.5,"qty":129053.0},{"price":63596.5,"qty":384000.0},{"price":63596.0,"qty":19333.0},{"price":63544.0,"qty":4221.0},{"price":63543.5,"qty":129053.0},{"price":63495.5,"qty":19333.0},{"price":63488.5,"qty":74999.0},{"price":63428.0,"qty":39930.0},{"price":63268.0,"qty":151167.0},{"price":63250.0,"qty":1500.0},{"price":63221.5,"qty":15000.0},{"price":63210.5,"qty":39930.0},{"price":63121.0,"qty":20000.0},{"price":63000.0,"qty":6000.0},{"price":62998.0,"qty":20000.0},{"price":62989.0,"qty":10000.0},{"price":62940.0,"qty":149442.0},{"price":62907.0,"qty":150468.0},{"price":62869.0,"qty":1000.0},{"price":62834.0,"qty":20000.0},{"price":62775.0,"qty":39930.0},{"price":62760.0,"qty":250000.0},{"price":62630.0,"qty":1000.0},{"price":62396.0,"qty":87540.0},{"price":62234.0,"qty":2500.0},{"price":62200.0,"qty":1100.0},{"price":62121.5,"qty":39930.0},{"price":62074.5,"qty":91602.0},{"price":62051.0,"qty":80000.0},{"price":62000.0,"qty":1000.0},{"price":61698.0,"qty":80000.0},{"price":61415.0,"qty":90624.0},{"price":61350.0,"qty":80000.0},{"price":61316.0,"qty":50.0},{"price":61234.0,"qty":2500.0},{"price":61200.0,"qty":1100.0},{"price":61120.0,"qty":1000.0},{"price":61000.0,"qty":1000.0},{"price":60816.0,"qty":10000.0},{"price":60446.0,"qty":6000.0},{"price":60437.0,"qty":37.0},{"price":60215.0,"qty":385.0},{"price":60205.0,"qty":44.0},{"price":60200.0,"qty":1100.0},{"price":60177.5,"qty":88206.0},{"price":60000.0,"qty":137700.0},{"price":59974.0,"qty":53.0},{"price":59742.0,"qty":64.0},{"price":59510.0,"qty":77.0},{"price":59484.0,"qty":80000.0},{"price":59200.0,"qty":1100.0},{"price":59140.0,"qty":200.0},{"price":58975.5,"qty":6000.0},{"price":58750.0,"qty":5920.0},{"price":58470.0,"qty":80000.0},{"price":58369.0,"qty":1000.0},{"price":58324.0,"qty":2000.0},{"price":58200.0,"qty":3280.0},{"price":58000.0,"qty":3280.0},{"price":57800.0,"qty":3280.0},{"price":57769.0,"qty":1000.0},{"price":57601.0,"qty":80000.0},{"price":57600.0,"qty":3280.0},{"price":57500.0,"qty":11500.0},{"price":57400.5,"qty":4129.0},{"price":57400.0,"qty":3280.0},{"price":57321.5,"qty":15161.0},{"price":57321.0,"qty":2000.0},{"price":57200.5,"qty":33155.0},{"price":57200.0,"qty":3280.0},{"price":57000.0,"qty":3280.0},{"price":56800.0,"qty":3280.0},{"price":56600.0,"qty":3280.0},{"price":56400.0,"qty":3280.0},{"price":56234.0,"qty":2000.0},{"price":56200.0,"qty":3280.0},{"price":56190.5,"qty":54.0},{"price":56000.0,"qty":3280.0},{"price":55889.0,"qty":65.0},{"price":55800.0,"qty":3280.0},{"price":55600.0,"qty":3280.0},{"price":55580.5,"qty":77.0},{"price":55400.0,"qty":3280.0},{"price":55241.5,"qty":93.0},{"price":55234.0,"qty":2000.0},{"price":55200.0,"qty":3280.0},{"price":55000.0,"qty":3280.0},{"price":54857.5,"qty":111.0},{"price":54407.0,"qty":100.0},{"price":54234.0,"qty":2000.0},{"price":54155.0,"qty":200000.0},{"price":53234.0,"qty":2000.0},{"price":53000.0,"qty":500.0},{"price":52900.0,"qty":19000.0},{"price":52845.0,"qty":3000.0},{"price":52750.0,"qty":5000.0},{"price":51389.0,"qty":241.0},{"price":51245.0,"qty":1500.0},{"price":51200.0,"qty":300000.0},{"price":50000.5,"qty":5000.0},{"price":49845.0,"qty":3000.0},{"price":49503.0,"qty":100.0},{"price":48562.5,"qty":500.0},{"price":48345.0,"qty":2000.0},{"price":48000.0,"qty":150000.0},{"price":47500.0,"qty":60000.0},{"price":47025.0,"qty":12219.0},{"price":46845.0,"qty":5000.0},{"price":46500.0,"qty":300000.0},{"price":44065.5,"qty":120.0},{"price":44000.0,"qty":50.0},{"price":43635.0,"qty":1000.0},{"price":43200.0,"qty":4000.0},{"price":42911.0,"qty":1000.0},{"price":42366.5,"qty":1000.0},{"price":42134.0,"qty":1000.0},{"price":42070.0,"qty":21000.0},{"price":41864.0,"qty":1000.0},{"price":41460.0,"qty":500000.0},{"price":41436.0,"qty":200.0},{"price":41323.5,"qty":1000.0},{"price":41050.0,"qty":20500.0},{"price":40000.0,"qty":2000.0},{"price":37500.0,"qty":5000.0},{"price":36500.0,"qty":1000.0},{"price":36000.0,"qty":2000.0},{"price":35220.0,"qty":1000.0},{"price":35000.0,"qty":5000.0},{"price":34225.0,"qty":5000.0},{"price":34000.0,"qty":5000.0},{"price":32503.0,"qty":300.0},{"price":29555.0,"qty":200.0},{"price":29111.0,"qty":500.0},{"price":28900.0,"qty":1000.0},{"price":28700.0,"qty":1000.0},{"price":28555.0,"qty":200.0},{"price":28500.0,"qty":1000.0},{"price":28300.0,"qty":1000.0},{"price":28111.0,"qty":500.0},{"price":28001.0,"qty":4000.0},{"price":27111.0,"qty":500.0},{"price":26111.0,"qty":500.0},{"price":26001.0,"qty":6000.0},{"price":25333.0,"qty":500.0},{"price":25111.0,"qty":500.0},{"price":24111.0,"qty":500.0},{"price":23333.0,"qty":500.0},{"price":22515.5,"qty":500.0},{"price":21555.0,"qty":500.0},{"price":20955.0,"qty":500.0},{"price":17800.0,"qty":800.0}],"asks":[{"price":63956.0,"qty":3000.0},{"price":63966.0,"qty":3000.0},{"price":63973.0,"qty":1000.0},{"price":63991.5,"qty":2775.0},{"price":63992.5,"qty":1920.0},{"price":63995.5,"qty":196296.0},{"price":64000.0,"qty":5000.0},{"price":64002.0,"qty":4500.0},{"price":64003.0,"qty":6913.0},{"price":64003.5,"qty":5000.0},{"price":64005.5,"qty":3000.0},{"price":64013.0,"qty":10000.0},{"price":64015.5,"qty":3000.0},{"price":64025.5,"qty":3000.0},{"price":64036.0,"qty":48000.0},{"price":64042.5,"qty":8784.0},{"price":64047.0,"qty":311764.0},{"price":64053.5,"qty":29466.0},{"price":64055.0,"qty":5663.0},{"price":64069.5,"qty":5489.0},{"price":64089.0,"qty":1056.0},{"price":64098.0,"qty":268642.0},{"price":64098.5,"qty":33973.0},{"price":64099.0,"qty":369498.0},{"price":64143.5,"qty":59148.0},{"price":64144.0,"qty":96000.0},{"price":64150.5,"qty":404138.0},{"price":64160.0,"qty":96173.0},{"price":64170.5,"qty":34027.0},{"price":64181.0,"qty":10000.0},{"price":64192.5,"qty":504470.0},{"price":64193.0,"qty":39930.0},{"price":64202.5,"qty":519606.0},{"price":64223.0,"qty":23999.0},{"price":64254.5,"qty":692808.0},{"price":64256.0,"qty":34026.0},{"price":64260.0,"qty":125003.0},{"price":64260.5,"qty":96173.0},{"price":64261.5,"qty":192000.0},{"price":64313.5,"qty":60601.0},{"price":64314.0,"qty":27378.0},{"price":64349.5,"qty":47999.0},{"price":64361.5,"qty":96173.0},{"price":64363.0,"qty":24825.0},{"price":64363.5,"qty":384000.0},{"price":64365.5,"qty":24824.0},{"price":64389.0,"qty":154137.0},{"price":64427.5,"qty":20000.0},{"price":64516.5,"qty":76430.0},{"price":64517.0,"qty":39930.0},{"price":64530.0,"qty":74999.0},{"price":64556.0,"qty":151689.0},{"price":64592.5,"qty":152397.0},{"price":64662.0,"qty":15000.0},{"price":64841.0,"qty":39930.0},{"price":64907.0,"qty":10000.0},{"price":65187.0,"qty":89226.0},{"price":65200.0,"qty":6000.0},{"price":65226.0,"qty":88227.0},{"price":65489.0,"qty":39930.0},{"price":66086.5,"qty":88131.0},{"price":66241.0,"qty":120.0},{"price":67000.0,"qty":1000.0},{"price":67634.0,"qty":7500.0},{"price":67663.0,"qty":91305.0},{"price":67700.0,"qty":1000.0},{"price":67855.0,"qty":120.0},{"price":68000.0,"qty":200.0},{"price":68400.0,"qty":1000.0},{"price":69000.0,"qty":500.0},{"price":69100.0,"qty":1000.0},{"price":69200.0,"qty":1000.0},{"price":69427.5,"qty":500.0},{"price":69700.0,"qty":1000.0},{"price":70000.0,"qty":500.0},{"price":70200.0,"qty":1000.0},{"price":70293.0,"qty":2.0},{"price":70500.0,"qty":100000.0},{"price":70700.0,"qty":1000.0},{"price":71200.0,"qty":1000.0},{"price":71700.0,"qty":1000.0},{"price":72000.0,"qty":500.0},{"price":72200.0,"qty":1000.0},{"price":72500.0,"qty":1500.0},{"price":72700.0,"qty":1000.0},{"price":73200.0,"qty":1000.0},{"price":73427.5,"qty":500.0},{"price":73900.0,"qty":88.0},{"price":74000.0,"qty":500.0},{"price":74478.0,"qty":300200.0},{"price":75900.0,"qty":1000000.0},{"price":76000.0,"qty":500.0},{"price":77000.0,"qty":25000.0},{"price":78000.0,"qty":3500.0},{"price":78738.0,"qty":1500.0},{"price":79118.5,"qty":12000.0},{"price":80000.0,"qty":500.0},{"price":82000.0,"qty":500.0},{"price":84000.0,"qty":500.0},{"price":84100.0,"qty":8000.0},{"price":85000.0,"qty":2000.0},{"price":86000.0,"qty":500.0},{"price":88000.0,"qty":500.0},{"price":90000.0,"qty":2000.0},{"price":93000.0,"qty":6800.0},{"price":94000.0,"qty":1500.0},{"price":98450.0,"qty":6000.0},{"price":100000.0,"qty":2000.0},{"price":260000.0,"qty":2000.0}]}
1618678101.953341: {"feed":"book_snapshot","product_id":"FI_XBTUSD_210924","timestamp":1618678101454,"seq":13850684,"tickSize":null,"bids":[{"price":68237.5,"qty":1680.0},{"price":68208.0,"qty":3235.0},{"price":68197.5,"qty":42000.0},{"price":68193.5,"qty":2384.0},{"price":68191.0,"qty":172190.0},{"price":68186.5,"qty":3000.0},{"price":68169.0,"qty":3000.0},{"price":68162.5,"qty":7500.0},{"price":68154.0,"qty":23100.0},{"price":68153.0,"qty":23100.0},{"price":68140.0,"qty":3000.0},{"price":68137.0,"qty":23100.0},{"price":68120.0,"qty":8000.0},{"price":68106.5,"qty":273478.0},{"price":68105.0,"qty":3000.0},{"price":68065.0,"qty":3000.0},{"price":68051.0,"qty":250001.0},{"price":68050.5,"qty":84000.0},{"price":68022.0,"qty":324122.0},{"price":67998.5,"qty":10000.0},{"price":67978.0,"qty":250002.0},{"price":67977.5,"qty":22293.0},{"price":67938.0,"qty":354508.0},{"price":67934.0,"qty":19965.0},{"price":67933.5,"qty":168000.0},{"price":67905.5,"qty":22280.0},{"price":67899.0,"qty":3000.0},{"price":67862.5,"qty":23999.0},{"price":67853.5,"qty":455796.0},{"price":67809.5,"qty":526.0},{"price":67802.0,"qty":22293.0},{"price":67769.5,"qty":607728.0},{"price":67756.5,"qty":336000.0},{"price":67754.5,"qty":63180.0},{"price":67735.5,"qty":19965.0},{"price":67723.5,"qty":47999.0},{"price":67623.0,"qty":63180.0},{"price":67519.0,"qty":19965.0},{"price":67515.5,"qty":560.0},{"price":67327.0,"qty":119999.0},{"price":67260.0,"qty":40161.0},{"price":67150.0,"qty":2000.0},{"price":67087.0,"qty":19965.0},{"price":67000.0,"qty":5100.0},{"price":66913.0,"qty":41147.0},{"price":66897.5,"qty":40659.0},{"price":66707.0,"qty":50000.0},{"price":66569.0,"qty":1000.0},{"price":66456.5,"qty":10000.0},{"price":66438.5,"qty":19965.0},{"price":66296.0,"qty":24580.0},{"price":66121.0,"qty":7000.0},{"price":66068.5,"qty":1000.0},{"price":66039.5,"qty":162.0},{"price":66023.5,"qty":23931.0},{"price":66000.0,"qty":1500.0},{"price":65402.5,"qty":1000.0},{"price":65003.0,"qty":200.0},{"price":65000.0,"qty":7000.0},{"price":64668.0,"qty":10000.0},{"price":64658.0,"qty":100000.0},{"price":64560.0,"qty":23494.0},{"price":64326.5,"qty":24196.0},{"price":64258.0,"qty":100000.0},{"price":64058.0,"qty":100000.0},{"price":64041.0,"qty":1000.0},{"price":64000.0,"qty":3500.0},{"price":63930.0,"qty":100.0},{"price":63700.5,"qty":241.0},{"price":63690.0,"qty":10000.0},{"price":63500.0,"qty":4000.0},{"price":63000.0,"qty":1502500.0},{"price":62751.0,"qty":10000.0},{"price":62715.0,"qty":100.0},{"price":62555.0,"qty":50000.0},{"price":62000.0,"qty":4000.0},{"price":61912.0,"qty":500.0},{"price":61800.0,"qty":61800.0},{"price":61769.0,"qty":1000.0},{"price":61500.0,"qty":135601.0},{"price":61200.0,"qty":1500.0},{"price":61000.0,"qty":3000.0},{"price":60764.0,"qty":10000.0},{"price":60669.0,"qty":1000.0},{"price":60563.5,"qty":500.0},{"price":60498.5,"qty":100.0},{"price":60200.0,"qty":225968.0},{"price":60000.0,"qty":1500.0},{"price":59526.0,"qty":1000.0},{"price":59429.5,"qty":100.0},{"price":59327.5,"qty":500.0},{"price":59100.0,"qty":5000.0},{"price":59000.0,"qty":1000.0},{"price":58800.0,"qty":750000.0},{"price":58250.0,"qty":2000.0},{"price":58173.5,"qty":2500.0},{"price":57000.0,"qty":1.0},{"price":56500.0,"qty":2500.0},{"price":56326.0,"qty":1000.0},{"price":55250.0,"qty":5000.0},{"price":55000.0,"qty":1600.0},{"price":54906.5,"qty":2500.0},{"price":54500.0,"qty":3500.0},{"price":54279.5,"qty":321.0},{"price":52552.5,"qty":59069.0},{"price":52552.0,"qty":1000.0},{"price":52263.5,"qty":500.0},{"price":51300.0,"qty":2000.0},{"price":50500.0,"qty":20000.0},{"price":50430.0,"qty":1000.0},{"price":50015.0,"qty":20000.0},{"price":49522.0,"qty":1000.0},{"price":46123.0,"qty":300.0},{"price":45585.0,"qty":500.0},{"price":45000.0,"qty":10500.0},{"price":44501.0,"qty":5000.0},{"price":44430.0,"qty":6000.0},{"price":42633.5,"qty":1000.0},{"price":42527.5,"qty":8.0},{"price":41074.5,"qty":500.0},{"price":40123.0,"qty":560.0},{"price":37686.5,"qty":1000.0},{"price":34270.5,"qty":500.0},{"price":32000.0,"qty":500.0},{"price":28113.5,"qty":32.0},{"price":20125.0,"qty":64.0}],"asks":[{"price":68307.0,"qty":50.0},{"price":68307.5,"qty":10000.0},{"price":68308.0,"qty":1680.0},{"price":68312.5,"qty":3000.0},{"price":68321.5,"qty":7500.0},{"price":68322.5,"qty":3759.0},{"price":68325.5,"qty":5000.0},{"price":68327.0,"qty":3000.0},{"price":68331.5,"qty":184702.0},{"price":68336.5,"qty":3000.0},{"price":68338.5,"qty":2366.0},{"price":68340.0,"qty":526.0},{"price":68349.0,"qty":3000.0},{"price":68353.0,"qty":3000.0},{"price":68356.0,"qty":3000.0},{"price":68360.0,"qty":2780.0},{"price":68365.5,"qty":42000.0},{"price":68405.5,"qty":250001.0},{"price":68406.0,"qty":23999.0},{"price":68411.0,"qty":293350.0},{"price":68437.0,"qty":24973.0},{"price":68445.0,"qty":560.0},{"price":68448.5,"qty":133275.0},{"price":68485.5,"qty":10000.0},{"price":68490.0,"qty":355466.0},{"price":68490.5,"qty":347674.0},{"price":68508.0,"qty":19965.0},{"price":68511.5,"qty":84000.0},{"price":68539.0,"qty":47999.0},{"price":68542.0,"qty":24960.0},{"price":68569.5,"qty":125003.0},{"price":68570.0,"qty":380268.0},{"price":68580.5,"qty":133275.0},{"price":68613.0,"qty":24973.0},{"price":68649.5,"qty":488916.0},{"price":68679.0,"qty":168000.0},{"price":68729.5,"qty":651888.0},{"price":68798.5,"qty":355965.0},{"price":68917.0,"qty":119999.0},{"price":69068.5,"qty":38811.0},{"price":69093.5,"qty":19965.0},{"price":69198.5,"qty":39915.0},{"price":69285.0,"qty":2000.0},{"price":69369.0,"qty":39172.0},{"price":69655.5,"qty":24713.0},{"price":69706.5,"qty":19965.0},{"price":69751.0,"qty":24608.0},{"price":70000.0,"qty":5000.0},{"price":70285.0,"qty":2000.0},{"price":70331.5,"qty":23768.0},{"price":71264.5,"qty":100000.0},{"price":71282.0,"qty":46172.0},{"price":71285.0,"qty":2000.0},{"price":71353.0,"qty":100000.0},{"price":71486.0,"qty":100000.0},{"price":71500.0,"qty":35000.0},{"price":71600.0,"qty":1500.0},{"price":71980.0,"qty":6000.0},{"price":72285.0,"qty":2000.0},{"price":72300.0,"qty":1500.0},{"price":72324.5,"qty":24392.0},{"price":72351.0,"qty":90.0},{"price":72900.0,"qty":5.0},{"price":73000.0,"qty":200.0},{"price":73285.0,"qty":2000.0},{"price":73600.0,"qty":5.0},{"price":74012.0,"qty":100000.0},{"price":74072.5,"qty":500.0},{"price":74112.0,"qty":100000.0},{"price":74212.0,"qty":100000.0},{"price":74245.0,"qty":1.0},{"price":74285.0,"qty":2000.0},{"price":74523.0,"qty":90.0},{"price":74672.0,"qty":1000.0},{"price":74914.5,"qty":50000.0},{"price":75000.0,"qty":37500.0},{"price":75285.0,"qty":2000.0},{"price":75352.0,"qty":100000.0},{"price":75412.0,"qty":100000.0},{"price":75512.0,"qty":50000.0},{"price":75521.0,"qty":1500.0},{"price":75704.5,"qty":256.0},{"price":75900.0,"qty":10000.0},{"price":75914.5,"qty":50000.0},{"price":76285.0,"qty":2000.0},{"price":76914.5,"qty":50000.0},{"price":77000.0,"qty":38501.0},{"price":77285.0,"qty":2000.0},{"price":77500.0,"qty":20.0},{"price":77586.0,"qty":231.0},{"price":77914.0,"qty":50000.0},{"price":78000.0,"qty":39000.0},{"price":78285.0,"qty":2000.0},{"price":79000.0,"qty":39500.0},{"price":79285.0,"qty":2000.0},{"price":79350.0,"qty":495000.0},{"price":79583.0,"qty":321.0},{"price":79609.0,"qty":2500.0},{"price":79945.0,"qty":50.0},{"price":80000.0,"qty":40000.0},{"price":80285.0,"qty":2000.0},{"price":81000.0,"qty":40500.0},{"price":81285.0,"qty":2000.0},{"price":82000.0,"qty":41000.0},{"price":82285.0,"qty":2000.0},{"price":83000.0,"qty":41500.0},{"price":83285.0,"qty":2000.0},{"price":84000.0,"qty":462000.0},{"price":84285.0,"qty":2000.0},{"price":85000.0,"qty":824500.0},{"price":85285.0,"qty":4000.0},{"price":86000.0,"qty":86000.0},{"price":86285.0,"qty":4000.0},{"price":87285.0,"qty":4000.0},{"price":88285.0,"qty":4000.0},{"price":89285.0,"qty":4000.0},{"price":90285.0,"qty":4000.0},{"price":91285.0,"qty":4000.0},{"price":92285.0,"qty":4000.0},{"price":93285.0,"qty":4000.0},{"price":94285.0,"qty":4000.0},{"price":99780.0,"qty":199560.0},{"price":99840.0,"qty":199680.0},{"price":99879.0,"qty":99879.0},{"price":99880.0,"qty":199760.0},{"price":99899.0,"qty":99899.0},{"price":99909.0,"qty":99909.0},{"price":99920.0,"qty":199840.0},{"price":99949.0,"qty":199898.0},{"price":99990.0,"qty":199980.0},{"price":99999.0,"qty":99999.0},{"price":100000.0,"qty":2000.0}]}
1618678101.953973: {"feed":"book","product_id":"FI_XBTUSD_210430","side":"buy","seq":12237399,"price":59445.5,"qty":52569.0,"timestamp":1618678101591}
1618678101.954004: {"feed":"book","product_id":"FI_ETHUSD_210430","side":"buy","seq":4780732,"price":2388.1,"qty":0.0,"timestamp":1618678101593}
1618678101.954033: {"feed":"book","product_id":"FI_XBTUSD_210625","side":"sell","seq":21454485,"price":64098.0,"qty":250001.0,"timestamp":1618678101618}
1618678101.9540532: {"feed":"book","product_id":"FI_XBTUSD_210625","side":"sell","seq":21454486,"price":64069.0,"qty":12695.0,"timestamp":1618678101618}
1618678101.954078: {"feed":"book","product_id":"FI_XBTUSD_210430","side":"buy","seq":12237400,"price":59445.5,"qty":52925.0,"timestamp":1618678101635}
1618678101.954096: {"feed":"book","product_id":"FI_XBTUSD_210430","side":"buy","seq":12237401,"price":60680.0,"qty":500.0,"timestamp":1618678101644}
1618678101.954133: {"feed":"book","product_id":"FI_XBTUSD_210430","side":"sell","seq":12237402,"price":61960.5,"qty":500.0,"timestamp":1618678101644}
1618678101.954153: {"feed":"book","product_id":"FI_XBTUSD_210924","side":"sell","seq":13850685,"price":68297.5,"qty":3000.0,"timestamp":1618678101644}
1618678101.954189: {"feed":"book","product_id":"FI_XBTUSD_210924","side":"sell","seq":13850686,"price":68307.5,"qty":0.0,"timestamp":1618678101655}
1618678101.954211: {"feed":"book","product_id":"FI_XBTUSD_210924","side":"sell","seq":13850687,"price":68297.0,"qty":10000.0,"timestamp":1618678101655}
1618678101.954231: {"feed":"book","product_id":"FI_ETHUSD_210625","side":"buy","seq":12455148,"price":2497.25,"qty":3000.0,"timestamp":1618678101658}
1618678101.954251: {"feed":"book","product_id":"FI_BCHUSD_210625","side":"buy","seq":2240146,"price":1130.6,"qty":0.0,"timestamp":1618678101670}
1618678101.954287: {"feed":"book","product_id":"PI_BCHUSD","side":"sell","seq":16257857,"price":1062.4,"qty":3050.0,"timestamp":1618678101675}
1618678101.9543061: {"feed":"book","product_id":"FI_ETHUSD_210625","side":"buy","seq":12455149,"price":2497.75,"qty":0.0,"timestamp":1618678101675}
1618678101.954327: {"feed":"book","product_id":"PI_BCHUSD","side":"sell","seq":16257858,"price":1063.3,"qty":0.0,"timestamp":1618678101675}
1618678101.954347: {"feed":"book","product_id":"PI_BCHUSD","side":"sell","seq":16257859,"price":1062.8,"qty":9337.0,"timestamp":1618678101677}
1618678101.9543629: {"feed":"book","product_id":"FI_ETHUSD_210430","side":"sell","seq":4780733,"price":2396.4,"qty":0.0,"timestamp":1618678101677}
1618678101.9543831: {"feed":"book","product_id":"FI_ETHUSD_210430","side":"sell","seq":4780734,"price":2397.85,"qty":225001.0,"timestamp":1618678101677}
1618678101.954402: {"feed":"book","product_id":"PI_BCHUSD","side":"sell","seq":16257860,"price":1063.0,"qty":25367.0,"timestamp":1618678101677}
1618678101.954418: {"feed":"book","product_id":"FI_ETHUSD_210924","side":"sell","seq":3859072,"price":2664.0,"qty":0.0,"timestamp":1618678101678}
1618678101.954436: {"feed":"book","product_id":"FI_ETHUSD_210924","side":"sell","seq":3859073,"price":2667.6,"qty":225001.0,"timestamp":1618678101678}
1618678101.9544551: {"feed":"book","product_id":"FI_ETHUSD_210625","side":"sell","seq":12455150,"price":2509.25,"qty":0.0,"timestamp":1618678101677}
1618678101.954474: {"feed":"book","product_id":"FI_ETHUSD_210625","side":"sell","seq":12455151,"price":2509.75,"qty":225001.0,"timestamp":1618678101677}
1618678101.954499: {"feed":"book","product_id":"FI_ETHUSD_210430","side":"sell","seq":4780735,"price":2403.8,"qty":0.0,"timestamp":1618678101678}
1618678101.95452: {"feed":"book","product_id":"FI_ETHUSD_210430","side":"sell","seq":4780736,"price":2405.2,"qty":25003.0,"timestamp":1618678101678}
1618678101.954539: {"feed":"book","product_id":"FI_XRPUSD_210625","side":"sell","seq":3631409,"price":1.6995,"qty":0.0,"timestamp":1618678101677}
1618678101.954558: {"feed":"book","product_id":"FI_XRPUSD_210625","side":"sell","seq":3631410,"price":1.7005,"qty":18968.0,"timestamp":1618678101677}
1618678101.954577: {"feed":"book","product_id":"FI_ETHUSD_210625","side":"sell","seq":12455152,"price":2513.4,"qty":0.0,"timestamp":1618678101678}
1618678101.954595: {"feed":"book","product_id":"FI_ETHUSD_210625","side":"sell","seq":12455153,"price":2513.3,"qty":303574.0,"timestamp":1618678101678}
1618678101.954613: {"feed":"book","product_id":"PI_BCHUSD","side":"buy","seq":16257861,"price":1058.8,"qty":0.0,"timestamp":1618678101684}
1618678101.954632: {"feed":"book","product_id":"FI_XBTUSD_210625","side":"buy","seq":21454487,"price":57200.5,"qty":30165.0,"timestamp":1618678101686}
1618678101.954649: {"feed":"book","product_id":"FI_ETHUSD_210625","side":"sell","seq":12455154,"price":2506.05,"qty":25574.0,"timestamp":1618678101691}
1618678101.954665: {"feed":"book","product_id":"PI_BCHUSD","side":"buy","seq":16257862,"price":1058.8,"qty":6042.0,"timestamp":1618678101698}
1618678101.9546828: {"feed":"book","product_id":"FI_ETHUSD_210924","side":"buy","seq":3859074,"price":2643.75,"qty":206347.0,"timestamp":1618678101716}
1618678101.954698: {"feed":"book","product_id":"FI_XBTUSD_210625","side":"buy","seq":21454488,"price":57200.5,"qty":33170.0,"timestamp":1618678101734}
1618678101.954714: {"feed":"book","product_id":"PI_BCHUSD","side":"sell","seq":16257863,"price":1062.6,"qty":0.0,"timestamp":1618678101741}
1618678101.954732: {"feed":"book","product_id":"PI_BCHUSD","side":"buy","seq":16257864,"price":1059.8,"qty":8488.0,"timestamp":1618678101741}
1618678101.954748: {"feed":"book","product_id":"PI_BCHUSD","side":"buy","seq":16257865,"price":1059.5,"qty":0.0,"timestamp":1618678101742}
1618678101.954767: {"feed":"book","product_id":"PI_BCHUSD","side":"buy","seq":16257866,"price":1059.6,"qty":3957.0,"timestamp":1618678101742}
1618678101.954782: {"feed":"book","product_id":"PI_BCHUSD","side":"buy","seq":16257867,"price":1059.2,"qty":3980.0,"timestamp":1618678101742}
1618678101.9548001: {"feed":"book","product_id":"PI_BCHUSD","side":"buy","seq":16257868,"price":1059.1,"qty":21389.0,"timestamp":1618678101744}
1618678101.954821: {"feed":"book","product_id":"PI_BCHUSD","side":"buy","seq":16257869,"price":1059.1,"qty":36354.0,"timestamp":1618678101760}
1618678101.954837: {"feed":"book","product_id":"PI_BCHUSD","side":"sell","seq":16257870,"price":1063.7,"qty":35150.0,"timestamp":1618678101771}
1618678101.954852: {"feed":"book","product_id":"PI_BCHUSD","side":"sell","seq":16257871,"price":1063.4,"qty":28765.0,"timestamp":1618678101771}
1618678101.954867: {"feed":"book","product_id":"FI_ETHUSD_210430","side":"sell","seq":4780737,"price":2393.3,"qty":0.0,"timestamp":1618678101776}
1618678101.954885: {"feed":"book","product_id":"FI_XBTUSD_210924","side":"buy","seq":13850688,"price":52552.5,"qty":58843.0,"timestamp":1618678101780}
1618678101.954901: {"feed":"book","product_id":"FI_XBTUSD_210625","side":"sell","seq":21454489,"price":64062.5,"qty":3000.0,"timestamp":1618678101786}
1618678101.9549189: {"feed":"book","product_id":"FI_XBTUSD_210924","side":"buy","seq":13850689,"price":68208.0,"qty":0.0,"timestamp":1618678101806}
1618678101.9549382: {"feed":"book","product_id":"FI_ETHUSD_210625","side":"buy","seq":12455155,"price":2496.25,"qty":0.0,"timestamp":1618678101811}
1618678101.954957: {"feed":"book","product_id":"FI_ETHUSD_210625","side":"buy","seq":12455156,"price":2492.95,"qty":0.0,"timestamp":1618678101811}
1618678101.954975: {"feed":"book","product_id":"FI_XBTUSD_210625","side":"buy","seq":21454490,"price":63864.5,"qty":0.0,"timestamp":1618678101812}
1618678101.954994: {"feed":"book","product_id":"FI_ETHUSD_210430","side":"buy","seq":4780738,"price":2387.6,"qty":0.0,"timestamp":1618678101816}
1618678101.955012: {"feed":"book","product_id":"PI_BCHUSD","side":"buy","seq":16257872,"price":1060.1,"qty":0.0,"timestamp":1618678101821}
1618678101.9550312: {"feed":"book","product_id":"PI_BCHUSD","side":"sell","seq":16257873,"price":1063.4,"qty":25323.0,"timestamp":1618678101821}
1618678101.955047: {"feed":"book","product_id":"PI_BCHUSD","side":"sell","seq":16257874,"price":1063.0,"qty":29181.0,"timestamp":1618678101821}
1618678101.955062: {"feed":"book","product_id":"FI_ETHUSD_210625","side":"buy","seq":12455157,"price":2500.3,"qty":140056.0,"timestamp":1618678101824}
1618678101.955078: {"feed":"book","product_id":"PI_BCHUSD","side":"sell","seq":16257875,"price":1063.0,"qty":32622.0,"timestamp":1618678101821}
1618678101.955093: {"feed":"book","product_id":"PI_BCHUSD","side":"sell","seq":16257876,"price":1063.4,"qty":21579.0,"timestamp":1618678101822}
1618678101.9551082: {"feed":"book","product_id":"PI_BCHUSD","side":"buy","seq":16257877,"price":1059.7,"qty":3737.0,"timestamp":1618678101824}
1618678101.955126: {"feed":"book","product_id":"FI_XBTUSD_210924","side":"buy","seq":13850690,"price":52552.5,"qty":58968.0,"timestamp":1618678101825}
1618678101.955159: {"feed":"book","product_id":"PI_BCHUSD","side":"sell","seq":16257878,"price":1062.4,"qty":0.0,"timestamp":1618678101840}
1618678101.955178: {"feed":"book","product_id":"FI_XBTUSD_210430","side":"sell","seq":12237403,"price":61960.5,"qty":0.0,"timestamp":1618678101844}
1618678101.9551969: {"feed":"book","product_id":"FI_XBTUSD_210430","side":"buy","seq":12237404,"price":60680.0,"qty":0.0,"timestamp":1618678101844}
1618678101.955216: {"feed":"book","product_id":"PI_BCHUSD","side":"sell","seq":16257879,"price":1062.9,"qty":86.0,"timestamp":1618678101846}
1618678101.955234: {"feed":"book","product_id":"PI_BCHUSD","side":"sell","seq":16257880,"price":1062.9,"qty":0.0,"timestamp":1618678101851}
1618678101.955253: {"feed":"book","product_id":"PI_BCHUSD","side":"sell","seq":16257881,"price":1063.4,"qty":10940.0,"timestamp":1618678101854}
1618678101.955283: {"feed":"book","product_id":"FI_ETHUSD_210924","side":"buy","seq":3859075,"price":2656.9,"qty":0.0,"timestamp":1618678101859}
1618678101.955303: {"feed":"book","product_id":"FI_ETHUSD_210924","side":"buy","seq":3859076,"price":2656.4,"qty":840.0,"timestamp":1618678101859}
1618678101.955321: {"feed":"book","product_id":"FI_ETHUSD_210430","side":"sell","seq":4780739,"price":2403.85,"qty":0.0,"timestamp":1618678101926}
1618678101.9553401: {"feed":"book","product_id":"FI_ETHUSD_210430","side":"sell","seq":4780740,"price":2402.25,"qty":204000.0,"timestamp":1618678101926}
1618678101.955359: {"feed":"book","product_id":"FI_ETHUSD_210430","side":"sell","seq":4780741,"price":2395.95,"qty":0.0,"timestamp":1618678101926}
1618678101.9553769: {"feed":"book","product_id":"FI_ETHUSD_210430","side":"sell","seq":4780742,"price":2394.9,"qty":51000.0,"timestamp":1618678101926}
1618678101.9573991: {"feed":"book","product_id":"FI_ETHUSD_210430","side":"buy","seq":4780743,"price":2387.85,"qty":0.0,"timestamp":1618678101926}
1618678101.957488: {"feed":"book","product_id":"FI_ETHUSD_210430","side":"buy","seq":4780744,"price":2387.35,"qty":25500.0,"timestamp":1618678101926}
1618678101.957558: {"feed":"book","product_id":"FI_ETHUSD_210430","side":"sell","seq":4780745,"price":2391.6,"qty":0.0,"timestamp":1618678101926}
1618678101.957592: {"feed":"book","product_id":"FI_ETHUSD_210430","side":"sell","seq":4780746,"price":2391.25,"qty":25500.0,"timestamp":1618678101926}
1618678101.95762: {"feed":"book","product_id":"FI_ETHUSD_210430","side":"sell","seq":4780747,"price":2399.85,"qty":0.0,"timestamp":1618678101926}
1618678101.957647: {"feed":"book","product_id":"FI_ETHUSD_210430","side":"sell","seq":4780748,"price":2398.6,"qty":102000.0,"timestamp":1618678101926}
1618678101.968508: {"feed":"book","product_id":"FI_ETHUSD_210625","side":"buy","seq":12455158,"price":2497.0,"qty":0.0,"timestamp":1618678101928}
1618678101.9685671: {"feed":"book","product_id":"FI_ETHUSD_210625","side":"buy","seq":12455159,"price":2496.05,"qty":48000.0,"timestamp":1618678101928}
1618678101.9686038: {"feed":"book","product_id":"FI_XBTUSD_210625","side":"buy","seq":21454491,"price":63926.0,"qty":1073.0,"timestamp":1618678101928}
1618678101.968628: {"feed":"book","product_id":"FI_ETHUSD_210924","side":"sell","seq":3859077,"price":2660.2,"qty":0.0,"timestamp":1618678101928}
1618678101.9686568: {"feed":"book","product_id":"FI_XBTUSD_210625","side":"buy","seq":21454492,"price":63926.0,"qty":2174.0,"timestamp":1618678101928}
1618678101.968677: {"feed":"book","product_id":"FI_ETHUSD_210924","side":"sell","seq":3859078,"price":2660.1,"qty":50.0,"timestamp":1618678101928}
1618678101.9687: {"feed":"book","product_id":"FI_ETHUSD_210625","side":"sell","seq":12455160,"price":2511.1,"qty":0.0,"timestamp":1618678101928}
1618678101.968725: {"feed":"book","product_id":"FI_ETHUSD_210625","side":"sell","seq":12455161,"price":2510.05,"qty":48000.0,"timestamp":1618678101928}
1618678101.968749: {"feed":"book","product_id":"PI_BCHUSD","side":"sell","seq":16257882,"price":1063.7,"qty":45787.0,"timestamp":1618678101928}
1618678101.968771: {"feed":"book","product_id":"FI_ETHUSD_210625","side":"sell","seq":12455162,"price":2516.35,"qty":0.0,"timestamp":1618678101928}
1618678101.968794: {"feed":"book","product_id":"FI_ETHUSD_210625","side":"sell","seq":12455163,"price":2514.65,"qty":96000.0,"timestamp":1618678101928}
1618678101.968816: {"feed":"book","product_id":"FI_ETHUSD_210625","side":"sell","seq":12455164,"price":2506.05,"qty":1574.0,"timestamp":1618678101928}
1618678101.968835: {"feed":"book","product_id":"FI_ETHUSD_210625","side":"sell","seq":12455165,"price":2505.4,"qty":24000.0,"timestamp":1618678101928}
1618678101.968857: {"feed":"book","product_id":"FI_XBTUSD_210625","side":"sell","seq":21454493,"price":64143.5,"qty":29087.0,"timestamp":1618678101928}
1618678101.968877: {"feed":"book","product_id":"FI_XBTUSD_210625","side":"sell","seq":21454494,"price":64143.5,"qty":58299.0,"timestamp":1618678101928}
1618678101.968895: {"feed":"book","product_id":"FI_XBTUSD_210430","side":"buy","seq":12237405,"price":59445.5,"qty":52569.0,"timestamp":1618678101928}
1618678101.968915: {"feed":"book","product_id":"FI_XBTUSD_210625","side":"buy","seq":21454495,"price":63926.0,"qty":1101.0,"timestamp":1618678101928}
1618678101.968933: {"feed":"book","product_id":"FI_XBTUSD_210625","side":"buy","seq":21454496,"price":63926.0,"qty":2202.0,"timestamp":1618678101928}
1618678101.968951: {"feed":"book","product_id":"FI_XBTUSD_210625","side":"buy","seq":21454497,"price":63748.5,"qty":0.0,"timestamp":1618678101928}
1618678101.9689758: {"feed":"book","product_id":"FI_XBTUSD_210625","side":"buy","seq":21454498,"price":63748.5,"qty":3219.0,"timestamp":1618678101928}
1618678101.968998: {"feed":"book","product_id":"FI_XBTUSD_210625","side":"buy","seq":21454499,"price":63853.0,"qty":0.0,"timestamp":1618678101928}
1618678101.96902: {"feed":"book","product_id":"FI_XBTUSD_210625","side":"buy","seq":21454500,"price":63853.0,"qty":2065.0,"timestamp":1618678101928}
1618678101.9690418: {"feed":"book","product_id":"FI_XBTUSD_210625","side":"sell","seq":21454501,"price":64143.5,"qty":29212.0,"timestamp":1618678101928}
1618678101.9690628: {"feed":"book","product_id":"FI_XBTUSD_210625","side":"sell","seq":21454502,"price":64143.5,"qty":58424.0,"timestamp":1618678101928}
1618678101.9690812: {"feed":"book","product_id":"FI_BCHUSD_210625","side":"buy","seq":2240147,"price":1130.0,"qty":0.0,"timestamp":1618678101928}
1618678101.9691038: {"feed":"book","product_id":"FI_XBTUSD_210625","side":"sell","seq":21454503,"price":64069.0,"qty":0.0,"timestamp":1618678101928}
1618678101.9691288: {"feed":"book","product_id":"FI_XBTUSD_210625","side":"sell","seq":21454504,"price":64069.0,"qty":12726.0,"timestamp":1618678101928}
1618678101.969151: {"feed":"book","product_id":"FI_XBTUSD_210625","side":"buy","seq":21454505,"price":63544.0,"qty":0.0,"timestamp":1618678101928}
1618678101.969174: {"feed":"book","product_id":"FI_XBTUSD_210625","side":"buy","seq":21454506,"price":63544.0,"qty":4230.0,"timestamp":1618678101928}
1618678101.969196: {"feed":"book","product_id":"FI_XBTUSD_210625","side":"sell","seq":21454507,"price":64313.5,"qty":0.0,"timestamp":1618678101928}
1618678101.969217: {"feed":"book","product_id":"FI_XBTUSD_210625","side":"sell","seq":21454508,"price":64313.5,"qty":60652.0,"timestamp":1618678101928}
1618678101.969239: {"feed":"book","product_id":"FI_XBTUSD_210625","side":"sell","seq":21454509,"price":64516.5,"qty":0.0,"timestamp":1618678101928}
1618678101.9692621: {"feed":"book","product_id":"FI_XBTUSD_210625","side":"sell","seq":21454510,"price":64516.5,"qty":76434.0,"timestamp":1618678101928}
1618678101.9744298: {"feed":"book","product_id":"FI_XBTUSD_210430","side":"buy","seq":12237406,"price":61171.5,"qty":0.0,"timestamp":1618678101930}
1618678101.974561: {"feed":"book","product_id":"FI_ETHUSD_210625","side":"sell","seq":12455166,"price":2508.05,"qty":16352.0,"timestamp":1618678101941}
1618678101.974614: {"feed":"book","product_id":"FI_ETHUSD_210625","side":"sell","seq":12455167,"price":2506.0,"qty":11585.0,"timestamp":1618678101941}
1618678101.974665: {"feed":"book","product_id":"FI_BCHUSD_210625","side":"buy","seq":2240148,"price":1108.3,"qty":0.0,"timestamp":1618678101930}
1618678101.97471: {"feed":"book","product_id":"FI_BCHUSD_210625","side":"buy","seq":2240149,"price":1123.9,"qty":4513.0,"timestamp":1618678101930}
1618678101.974755: {"feed":"book","product_id":"FI_XBTUSD_210430","side":"buy","seq":12237407,"price":59445.5,"qty":52722.0,"timestamp":1618678101941}
1618678101.9747882: {"feed":"book","product_id":"PI_BCHUSD","side":"buy","seq":16257883,"price":1055.0,"qty":0.0,"timestamp":1618678101930}
1618678101.974833: {"feed":"book","product_id":"PI_BCHUSD","side":"buy","seq":16257884,"price":1057.1,"qty":10217.0,"timestamp":1618678101930}
1618678101.9748712: {"feed":"book","product_id":"FI_ETHUSD_210430","side":"buy","seq":4780749,"price":2387.1,"qty":0.0,"timestamp":1618678101941}
1618678101.974952: {"feed":"book","product_id":"PI_BCHUSD","side":"sell","seq":16257885,"price":1062.8,"qty":6470.0,"timestamp":1618678101930}
1618678101.974987: {"feed":"book","product_id":"PI_BCHUSD","side":"buy","seq":16257886,"price":1059.9,"qty":3580.0,"timestamp":1618678101930}
1618678101.97505: {"feed":"book","product_id":"PI_BCHUSD","side":"sell","seq":16257887,"price":1062.2,"qty":2870.0,"timestamp":1618678101930}
1618678101.97509: {"feed":"book","product_id":"PI_BCHUSD","side":"sell","seq":16257888,"price":1065.4,"qty":0.0,"timestamp":1618678101930}
1618678101.9751282: {"feed":"book","product_id":"FI_ETHUSD_210430","side":"sell","seq":4780750,"price":2391.55,"qty":1539.0,"timestamp":1618678101941}
1618678101.975177: {"feed":"book","product_id":"FI_ETHUSD_210430","side":"sell","seq":4780751,"price":2391.2,"qty":1020.0,"timestamp":1618678101941}
1618678101.9752162: {"feed":"book","product_id":"FI_ETHUSD_210430","side":"buy","seq":4780752,"price":2351.85,"qty":99600.0,"timestamp":1618678101943}
1618678101.975255: {"feed":"book","product_id":"PI_BCHUSD","side":"sell","seq":16257889,"price":1064.1,"qty":31059.0,"timestamp":1618678101941}
1618678101.975287: {"feed":"book","product_id":"PI_BCHUSD","side":"buy","seq":16257890,"price":1059.5,"qty":3556.0,"timestamp":1618678101941}
1618678101.975322: {"feed":"book","product_id":"PI_BCHUSD","side":"buy","seq":16257891,"price":1059.5,"qty":7364.0,"timestamp":1618678101941}
1618678101.979112: {"feed":"book","product_id":"PI_BCHUSD","side":"buy","seq":16257892,"price":1059.8,"qty":5011.0,"timestamp":1618678101941}
1618678101.979221: {"feed":"book","product_id":"FI_ETHUSD_210430","side":"sell","seq":4780753,"price":2397.85,"qty":0.0,"timestamp":1618678101946}
1618678101.9792929: {"feed":"book","product_id":"FI_ETHUSD_210430","side":"sell","seq":4780754,"price":2395.8,"qty":225001.0,"timestamp":1618678101946}
1618678101.979344: {"feed":"book","product_id":"FI_ETHUSD_210430","side":"sell","seq":4780755,"price":2391.4,"qty":28922.0,"timestamp":1618678101946}
1618678101.979406: {"feed":"book","product_id":"FI_ETHUSD_210625","side":"sell","seq":12455168,"price":2509.75,"qty":0.0,"timestamp":1618678101946}
1618678101.979435: {"feed":"book","product_id":"FI_ETHUSD_210625","side":"sell","seq":12455169,"price":2509.25,"qty":225001.0,"timestamp":1618678101946}
1618678101.97946: {"feed":"book","product_id":"FI_ETHUSD_210625","side":"sell","seq":12455170,"price":2513.3,"qty":0.0,"timestamp":1618678101946}
1618678101.979485: {"feed":"book","product_id":"FI_ETHUSD_210625","side":"sell","seq":12455171,"price":2512.9,"qty":303574.0,"timestamp":1618678101946}
1618678101.9795089: {"feed":"book","product_id":"FI_ETHUSD_210625","side":"sell","seq":12455172,"price":2516.3,"qty":26620.0,"timestamp":1618678101946}
1618678101.979529: {"feed":"book","product_id":"FI_ETHUSD_210625","side":"sell","seq":12455173,"price":2515.9,"qty":25003.0,"timestamp":1618678101946}
1618678101.994998: {"feed":"book","product_id":"FI_ETHUSD_210924","side":"sell","seq":3859079,"price":2667.6,"qty":0.0,"timestamp":1618678101946}
1618678101.995123: {"feed":"book","product_id":"FI_ETHUSD_210924","side":"sell","seq":3859080,"price":2664.0,"qty":225001.0,"timestamp":1618678101946}
1618678101.995235: {"feed":"book","product_id":"FI_ETHUSD_210924","side":"sell","seq":3859081,"price":2660.15,"qty":0.0,"timestamp":1618678101954}
1618678101.995285: {"feed":"book","product_id":"FI_ETHUSD_210924","side":"sell","seq":3859082,"price":2660.05,"qty":840.0,"timestamp":1618678101954}
1618678102.0375822: {"feed":"book","product_id":"FI_XBTUSD_210625","side":"buy","seq":21454511,"price":57200.5,"qty":30165.0,"timestamp":1618678102002}
1618678102.0501068: {"feed":"book","product_id":"FI_ETHUSD_210625","side":"buy","seq":12455174,"price":2497.25,"qty":0.0,"timestamp":1618678102002}
1618678102.050158: {"feed":"book","product_id":"FI_ETHUSD_210924","side":"sell","seq":3859083,"price":2660.1,"qty":0.0,"timestamp":1618678102002}
1618678102.050186: {"feed":"book","product_id":"FI_ETHUSD_210924","side":"sell","seq":3859084,"price":2660.0,"qty":50.0,"timestamp":1618678102002}
1618678102.0502121: {"feed":"book","product_id":"PI_BCHUSD","side":"sell","seq":16257893,"price":1062.2,"qty":0.0,"timestamp":1618678102002}
1618678102.050236: {"feed":"book","product_id":"PI_BCHUSD","side":"sell","seq":16257894,"price":1063.7,"qty":35150.0,"timestamp":1618678102002}
1618678102.050255: {"feed":"book","product_id":"PI_BCHUSD","side":"sell","seq":16257895,"price":1063.4,"qty":21577.0,"timestamp":1618678102002}
1618678102.050271: {"feed":"book","product_id":"PI_BCHUSD","side":"buy","seq":16257896,"price":1058.8,"qty":0.0,"timestamp":1618678102002}
1618678102.050293: {"feed":"book","product_id":"PI_BCHUSD","side":"sell","seq":16257897,"price":1064.3,"qty":3820.0,"timestamp":1618678102002}
1618678102.0503092: {"feed":"book","product_id":"PI_BCHUSD","side":"sell","seq":16257898,"price":1063.7,"qty":41223.0,"timestamp":1618678102002}
1618678102.050325: {"feed":"book","product_id":"FI_ETHUSD_210625","side":"buy","seq":12455175,"price":2493.85,"qty":0.0,"timestamp":1618678102002}
1618678102.0504751: {"feed":"book","product_id":"PI_BCHUSD","side":"sell","seq":16257899,"price":1062.6,"qty":2840.0,"timestamp":1618678102011}
1618678102.050498: {"feed":"book","product_id":"PI_BCHUSD","side":"buy","seq":16257900,"price":1059.1,"qty":21389.0,"timestamp":1618678102011}
1618678102.050515: {"feed":"book","product_id":"FI_XRPUSD_210625","side":"sell","seq":3631411,"price":1.7121,"qty":16799.0,"timestamp":1618678102011}
1618678102.0505369: {"feed":"book","product_id":"FI_ETHUSD_210625","side":"sell","seq":12455176,"price":2507.9,"qty":5000.0,"timestamp":1618678102014}
1618678102.050553: {"feed":"book","product_id":"FI_ETHUSD_210625","side":"buy","seq":12455177,"price":2499.75,"qty":0.0,"timestamp":1618678102016}
1618678102.050574: {"feed":"book","product_id":"PI_BCHUSD","side":"buy","seq":16257901,"price":1059.5,"qty":3808.0,"timestamp":1618678102016}
1618678102.05059: {"feed":"book","product_id":"PI_BCHUSD","side":"buy","seq":16257902,"price":1059.5,"qty":0.0,"timestamp":1618678102016}
1618678102.050626: {"feed":"book","product_id":"FI_ETHUSD_210924","side":"sell","seq":3859085,"price":2660.05,"qty":0.0,"timestamp":1618678102023}
1618678102.050647: {"feed":"book","product_id":"FI_ETHUSD_210924","side":"sell","seq":3859086,"price":2659.95,"qty":840.0,"timestamp":1618678102023}
1618678102.069252: {"feed":"book","product_id":"FI_ETHUSD_210924","side":"sell","seq":3859087,"price":2660.0,"qty":0.0,"timestamp":1618678102041}
1618678102.069386: {"feed":"book","product_id":"FI_ETHUSD_210924","side":"sell","seq":3859088,"price":2659.95,"qty":890.0,"timestamp":1618678102041}
1618678102.072022: {"feed":"book","product_id":"PI_BCHUSD","side":"sell","seq":16257903,"price":1063.7,"qty":35150.0,"timestamp":1618678102048}
1618678102.077732: {"feed":"book","product_id":"FI_XBTUSD_210625","side":"buy","seq":21454512,"price":57200.5,"qty":33155.0,"timestamp":1618678102054}
1618678102.093396: {"feed":"book","product_id":"PI_BCHUSD","side":"sell","seq":16257904,"price":1064.1,"qty":37131.0,"timestamp":1618678102070}
1618678102.0935092: {"feed":"book","product_id":"PI_BCHUSD","side":"buy","seq":16257905,"price":1059.1,"qty":0.0,"timestamp":1618678102071}
1618678102.111108: {"feed":"book","product_id":"FI_ETHUSD_210625","side":"buy","seq":12455178,"price":2495.9,"qty":3000.0,"timestamp":1618678102086}
1618678102.111242: {"feed":"book","product_id":"FI_ETHUSD_210625","side":"buy","seq":12455179,"price":2492.25,"qty":8800.0,"timestamp":1618678102086}
1618678102.132959: {"feed":"book","product_id":"FI_XBTUSD_210924","side":"buy","seq":13850691,"price":52552.5,"qty":58843.0,"timestamp":1618678102102}
1618678102.145847: {"feed":"book","product_id":"FI_ETHUSD_210625","side":"buy","seq":12455180,"price":2499.2,"qty":1585.0,"timestamp":1618678102120}
1618678102.1572878: {"feed":"book","product_id":"FI_XBTUSD_210625","side":"buy","seq":21454513,"price":63544.0,"qty":0.0,"timestamp":1618678102132}
1618678102.157417: {"feed":"book","product_id":"FI_XBTUSD_210625","side":"buy","seq":21454514,"price":63496.0,"qty":4260.0,"timestamp":1618678102132}
1618678102.15749: {"feed":"book","product_id":"FI_XBTUSD_210625","side":"sell","seq":21454515,"price":64313.5,"qty":0.0,"timestamp":1618678102132}
1618678102.157543: {"feed":"book","product_id":"FI_XBTUSD_210625","side":"sell","seq":21454516,"price":64259.5,"qty":55868.0,"timestamp":1618678102132}
1618678102.157884: {"feed":"book","product_id":"PI_BCHUSD","side":"sell","seq":16257906,"price":1063.4,"qty":10940.0,"timestamp":1618678102135}
1618678102.167893: {"feed":"book","product_id":"FI_XBTUSD_210924","side":"buy","seq":13850692,"price":52552.5,"qty":59077.0,"timestamp":1618678102143}
1618678102.171146: {"feed":"book","product_id":"PI_BCHUSD","side":"sell","seq":16257907,"price":1062.6,"qty":0.0,"timestamp":1618678102146}
1618678102.171233: {"feed":"book","product_id":"PI_BCHUSD","side":"sell","seq":16257908,"price":1063.0,"qty":29170.0,"timestamp":1618678102147}
1618678102.1733818: {"feed":"book","product_id":"FI_ETHUSD_210625","side":"sell","seq":12455181,"price":2506.0,"qty":0.0,"timestamp":1618678102150}
1618678102.173512: {"feed":"book","product_id":"FI_ETHUSD_210625","side":"sell","seq":12455182,"price":2508.05,"qty":32411.0,"timestamp":1618678102150}
1618678102.1735659: {"feed":"book","product_id":"PI_BCHUSD","side":"buy","seq":16257909,"price":1059.7,"qty":4706.0,"timestamp":1618678102150}
1618678102.184327: {"feed":"book","product_id":"FI_ETHUSD_210924","side":"sell","seq":3859089,"price":2659.95,"qty":1334.0,"timestamp":1618678102160}
1618678102.213268: {"feed":"book","product_id":"FI_XRPUSD_210625","side":"sell","seq":3631412,"price":1.6999,"qty":360.0,"timestamp":1618678102189}
1618678102.2172859: {"feed":"book","product_id":"FI_BCHUSD_210625","side":"sell","seq":2240150,"price":1135.9,"qty":127.0,"timestamp":1618678102193}
1618678102.217397: {"feed":"book","product_id":"FI_BCHUSD_210625","side":"buy","seq":2240151,"price":1129.7,"qty":77.0,"timestamp":1618678102193}
1618678102.224612: {"feed":"book","product_id":"FI_XBTUSD_210430","side":"buy","seq":12237408,"price":59445.5,"qty":53085.0,"timestamp":1618678102201}
1618678102.257518: {"feed":"book","product_id":"FI_ETHUSD_210625","side":"buy","seq":12455183,"price":2497.4,"qty":2000.0,"timestamp":1618678102233}
1618678102.257644: {"feed":"book","product_id":"FI_ETHUSD_210625","side":"sell","seq":12455184,"price":2505.2,"qty":129492.0,"timestamp":1618678102233}
1618678102.281492: {"feed":"book","product_id":"FI_XBTUSD_210625","side":"buy","seq":21454517,"price":57200.5,"qty":30165.0,"timestamp":1618678102258}
1618678102.311583: {"feed":"book","product_id":"FI_XRPUSD_210625","side":"sell","seq":3631413,"price":1.6988,"qty":0.0,"timestamp":1618678102288}
1618678102.325579: {"feed":"book","product_id":"FI_XBTUSD_210625","side":"buy","seq":21454518,"price":57200.5,"qty":33177.0,"timestamp":1618678102301}
1618678102.331756: {"feed":"book","product_id":"PI_BCHUSD","side":"sell","seq":16257910,"price":1062.7,"qty":50.0,"timestamp":1618678102306}
1618678102.339322: {"feed":"book","product_id":"FI_XBTUSD_210625","side":"buy","seq":21454519,"price":63834.0,"qty":3000.0,"timestamp":1618678102316}
1618678102.377056: {"feed":"book","product_id":"FI_XBTUSD_210430","side":"buy","seq":12237409,"price":61158.0,"qty":2884.0,"timestamp":1618678102354}
1618678102.37852: {"feed":"book","product_id":"FI_XBTUSD_210430","side":"sell","seq":12237410,"price":61253.5,"qty":4788.0,"timestamp":1618678102355}
1618678102.378603: {"feed":"book","product_id":"FI_XBTUSD_210924","side":"buy","seq":13850693,"price":52552.5,"qty":58843.0,"timestamp":1618678102356}
1618678102.3786519: {"feed":"book","product_id":"FI_XBTUSD_210625","side":"buy","seq":21454520,"price":63874.0,"qty":5120.0,"timestamp":1618678102356}
1618678102.378714: {"feed":"book","product_id":"FI_XBTUSD_210625","side":"sell","seq":21454521,"price":63960.0,"qty":5120.0,"timestamp":1618678102356}
1618678102.381459: {"feed":"book","product_id":"FI_ETHUSD_210625","side":"sell","seq":12455185,"price":2508.05,"qty":16352.0,"timestamp":1618678102358}
1618678102.381553: {"feed":"book","product_id":"FI_ETHUSD_210625","side":"sell","seq":12455186,"price":2509.2,"qty":19401.0,"timestamp":1618678102358}
1618678102.3816168: {"feed":"book","product_id":"FI_ETHUSD_210625","side":"buy","seq":12455187,"price":2493.9,"qty":0.0,"timestamp":1618678102358}
1618678102.381674: {"feed":"book","product_id":"FI_ETHUSD_210625","side":"buy","seq":12455188,"price":2492.15,"qty":663.0,"timestamp":1618678102358}
1618678102.3888798: {"feed":"book","product_id":"FI_XBTUSD_210924","side":"sell","seq":13850694,"price":68297.0,"qty":12739.0,"timestamp":1618678102366}
1618678102.3889651: {"feed":"book","product_id":"FI_ETHUSD_210430","side":"buy","seq":4780756,"price":2351.85,"qty":0.0,"timestamp":1618678102366}
1618678102.396467: {"feed":"book","product_id":"FI_XBTUSD_210924","side":"sell","seq":13850695,"price":68297.0,"qty":2739.0,"timestamp":1618678102370}
1618678102.3965282: {"feed":"book","product_id":"FI_XBTUSD_210924","side":"sell","seq":13850696,"price":68296.5,"qty":10000.0,"timestamp":1618678102370}
1618678102.417231: {"feed":"book","product_id":"FI_ETHUSD_210924","side":"sell","seq":3859090,"price":2662.4,"qty":0.0,"timestamp":1618678102393}
1618678102.4195242: {"feed":"book","product_id":"FI_ETHUSD_210625","side":"buy","seq":12455189,"price":2496.9,"qty":3000.0,"timestamp":1618678102396}
1618678102.4196212: {"feed":"book","product_id":"FI_ETHUSD_210625","side":"buy","seq":12455190,"price":2493.25,"qty":105693.0,"timestamp":1618678102396}
1618678102.4231098: {"feed":"book","product_id":"FI_XBTUSD_210924","side":"buy","seq":13850697,"price":52552.5,"qty":58968.0,"timestamp":1618678102400}
1618678102.423195: {"feed":"book","product_id":"FI_BCHUSD_210430","side":"buy","seq":1411830,"price":1073.6,"qty":0.0,"timestamp":1618678102401}
1618678102.42326: {"feed":"book","product_id":"FI_BCHUSD_210625","side":"buy","seq":2240152,"price":1126.9,"qty":0.0,"timestamp":1618678102401}
1618678102.4263349: {"feed":"book","product_id":"PI_BCHUSD","side":"sell","seq":16257911,"price":1063.4,"qty":4994.0,"timestamp":1618678102402}
1618678102.4328: {"feed":"book","product_id":"PI_BCHUSD","side":"buy","seq":16257912,"price":1059.3,"qty":0.0,"timestamp":1618678102407}
1618678102.4392262: {"feed":"book","product_id":"FI_BCHUSD_210430","side":"sell","seq":1411831,"price":1081.4,"qty":0.0,"timestamp":1618678102414}
1618678102.492021: {"feed":"book","product_id":"FI_XBTUSD_210625","side":"buy","seq":21454522,"price":57200.5,"qty":30165.0,"timestamp":1618678102467}
1618678102.521725: {"feed":"book","product_id":"FI_BCHUSD_210430","side":"buy","seq":1411832,"price":1068.2,"qty":14770.0,"timestamp":1618678102496}
1618678102.521813: {"feed":"book","product_id":"FI_BCHUSD_210430","side":"buy","seq":1411833,"price":1070.4,"qty":4590.0,"timestamp":1618678102496}
1618678102.537934: {"feed":"book","product_id":"FI_XBTUSD_210625","side":"buy","seq":21454523,"price":57200.5,"qty":33155.0,"timestamp":1618678102515}
1618678102.551657: {"feed":"book","product_id":"FI_XBTUSD_210430","side":"buy","seq":12237411,"price":60679.5,"qty":500.0,"timestamp":1618678102526}
1618678102.551784: {"feed":"book","product_id":"FI_XBTUSD_210430","side":"sell","seq":12237412,"price":61960.5,"qty":500.0,"timestamp":1618678102526}
1618678102.588777: {"feed":"book","product_id":"FI_XBTUSD_210430","side":"sell","seq":12237413,"price":61960.5,"qty":0.0,"timestamp":1618678102564}
1618678102.588906: {"feed":"book","product_id":"FI_XBTUSD_210430","side":"buy","seq":12237414,"price":60679.5,"qty":0.0,"timestamp":1618678102564}
1618678102.5926578: {"feed":"book","product_id":"FI_XBTUSD_210924","side":"buy","seq":13850698,"price":52552.5,"qty":58843.0,"timestamp":1618678102570}
1618678102.632481: {"feed":"book","product_id":"FI_XBTUSD_210625","side":"sell","seq":21454524,"price":63992.5,"qty":0.0,"timestamp":1618678102607}
1618678102.632607: {"feed":"book","product_id":"FI_XBTUSD_210625","side":"sell","seq":21454525,"price":64000.5,"qty":1920.0,"timestamp":1618678102607}
1618678102.634804: {"feed":"book","product_id":"FI_BCHUSD_210430","side":"buy","seq":1411834,"price":1073.2,"qty":6582.0,"timestamp":1618678102609}
1618678102.63494: {"feed":"book","product_id":"FI_XBTUSD_210430","side":"buy","seq":12237415,"price":61163.0,"qty":0.0,"timestamp":1618678102609}
1618678102.635007: {"feed":"book","product_id":"FI_XBTUSD_210430","side":"buy","seq":12237416,"price":61172.0,"qty":51000.0,"timestamp":1618678102609}
1618678102.635056: {"feed":"book","product_id":"FI_XBTUSD_210924","side":"sell","seq":13850699,"price":68308.0,"qty":0.0,"timestamp":1618678102609}
1618678102.635104: {"feed":"book","product_id":"FI_XBTUSD_210924","side":"sell","seq":13850700,"price":68316.0,"qty":1680.0,"timestamp":1618678102609}
1618678102.6354141: {"feed":"book","product_id":"FI_XBTUSD_210924","side":"buy","seq":13850701,"price":52552.5,"qty":59077.0,"timestamp":1618678102612}
1618678102.658356: {"feed":"book","product_id":"FI_ETHUSD_210625","side":"sell","seq":12455191,"price":2507.9,"qty":2000.0,"timestamp":1618678102632}
1618678102.674558: {"feed":"book","product_id":"FI_XBTUSD_210924","side":"sell","seq":13850702,"price":68297.5,"qty":0.0,"timestamp":1618678102650}
1618678102.678609: {"feed":"book","product_id":"FI_XBTUSD_210625","side":"sell","seq":21454526,"price":64143.5,"qty":29212.0,"timestamp":1618678102654}
1618678102.678721: {"feed":"book","product_id":"FI_XBTUSD_210625","side":"sell","seq":21454527,"price":64097.5,"qty":18800.0,"timestamp":1618678102654}
1618678102.690401: {"feed":"book","product_id":"FI_ETHUSD_210625","side":"buy","seq":12455192,"price":2496.9,"qty":0.0,"timestamp":1618678102667}
1618678102.697002: {"feed":"book","product_id":"FI_BCHUSD_210430","side":"sell","seq":1411835,"price":1079.7,"qty":6972.0,"timestamp":1618678102670}
1618678102.697089: {"feed":"book","product_id":"FI_BCHUSD_210430","side":"sell","seq":1411836,"price":1080.1,"qty":50.0,"timestamp":1618678102674}
1618678102.697463: {"feed":"book","product_id":"PI_BCHUSD","side":"sell","seq":16257913,"price":1063.1,"qty":22464.0,"timestamp":1618678102675}
1618678102.69854: {"feed":"book","product_id":"PI_BCHUSD","side":"sell","seq":16257914,"price":1062.5,"qty":3014.0,"timestamp":1618678102675}
1618678102.703263: {"feed":"book","product_id":"PI_BCHUSD","side":"sell","seq":16257915,"price":1062.5,"qty":3927.0,"timestamp":1618678102680}
1618678102.703372: {"feed":"book","product_id":"PI_BCHUSD","side":"sell","seq":16257916,"price":1064.9,"qty":0.0,"timestamp":1618678102680}
1618678102.711089: {"feed":"book","product_id":"FI_ETHUSD_210625","side":"buy","seq":12455193,"price":2499.85,"qty":1611.0,"timestamp":1618678102687}
1618678102.714229: {"feed":"book","product_id":"FI_XBTUSD_210625","side":"buy","seq":21454528,"price":57200.5,"qty":30165.0,"timestamp":1618678102690}
1618678102.716661: {"feed":"book","product_id":"FI_XBTUSD_210625","side":"buy","seq":21454529,"price":63777.5,"qty":0.0,"timestamp":1618678102690}
1618678102.716789: {"feed":"book","product_id":"FI_ETHUSD_210625","side":"sell","seq":12455194,"price":2509.2,"qty":0.0,"timestamp":1618678102690}
1618678102.716851: {"feed":"book","product_id":"FI_ETHUSD_210625","side":"sell","seq":12455195,"price":2508.05,"qty":32412.0,"timestamp":1618678102690}
1618678102.723467: {"feed":"book","product_id":"FI_BCHUSD_210430","side":"sell","seq":1411837,"price":1080.1,"qty":0.0,"timestamp":1618678102693}
1618678102.723553: {"feed":"book","product_id":"FI_BCHUSD_210430","side":"sell","seq":1411838,"price":1079.6,"qty":50.0,"timestamp":1618678102693}
1618678102.723609: {"feed":"book","product_id":"PI_BCHUSD","side":"sell","seq":16257917,"price":1062.5,"qty":913.0,"timestamp":1618678102695}
1618678102.733935: {"feed":"book","product_id":"FI_ETHUSD_210625","side":"sell","seq":12455196,"price":2505.2,"qty":127492.0,"timestamp":1618678102711}
1618678102.74964: {"feed":"book","product_id":"PI_BCHUSD","side":"buy","seq":16257918,"price":1058.8,"qty":6042.0,"timestamp":1618678102726}
1618678102.7531688: {"feed":"book","product_id":"FI_ETHUSD_210924","side":"buy","seq":3859091,"price":2643.45,"qty":2000.0,"timestamp":1618678102730}
1618678102.755119: {"feed":"book","product_id":"FI_XBTUSD_210625","side":"buy","seq":21454530,"price":57200.5,"qty":33177.0,"timestamp":1618678102732}
1618678102.760427: {"feed":"book","product_id":"PI_BCHUSD","side":"sell","seq":16257919,"price":1063.1,"qty":18717.0,"timestamp":1618678102736}
1618678102.762617: {"feed":"book","product_id":"PI_BCHUSD","side":"sell","seq":16257920,"price":1064.1,"qty":31059.0,"timestamp":1618678102739}
1618678102.762727: {"feed":"book","product_id":"PI_BCHUSD","side":"sell","seq":16257921,"price":1063.8,"qty":39010.0,"timestamp":1618678102739}
1618678102.7662258: {"feed":"book","product_id":"PI_BCHUSD","side":"buy","seq":16257922,"price":1059.8,"qty":20678.0,"timestamp":1618678102742}
1618678102.766335: {"feed":"book","product_id":"PI_BCHUSD","side":"buy","seq":16257923,"price":1059.8,"qty":41795.0,"timestamp":1618678102742}
1618678102.778972: {"feed":"book","product_id":"FI_XRPUSD_210625","side":"sell","seq":3631414,"price":1.6999,"qty":0.0,"timestamp":1618678102755}
1618678102.7791018: {"feed":"book","product_id":"FI_XRPUSD_210625","side":"sell","seq":3631415,"price":1.7005,"qty":19193.0,"timestamp":1618678102756}
1618678102.7797918: {"feed":"book","product_id":"FI_BCHUSD_210625","side":"buy","seq":2240153,"price":1130.2,"qty":62.0,"timestamp":1618678102757}
1618678102.80658: {"feed":"book","product_id":"FI_XBTUSD_210924","side":"buy","seq":13850703,"price":52552.5,"qty":58843.0,"timestamp":1618678102783}
1618678102.836852: {"feed":"book","product_id":"FI_XBTUSD_210430","side":"sell","seq":12237417,"price":61262.5,"qty":0.0,"timestamp":1618678102812}
1618678102.849688: {"feed":"book","product_id":"FI_XBTUSD_210924","side":"buy","seq":13850704,"price":52552.5,"qty":58968.0,"timestamp":1618678102826}
1618678102.922967: {"feed":"book","product_id":"FI_XBTUSD_210625","side":"buy","seq":21454531,"price":57200.5,"qty":30165.0,"timestamp":1618678102897}
1618678102.93152: {"feed":"book","product_id":"PI_BCHUSD","side":"sell","seq":16257924,"price":1062.6,"qty":2876.0,"timestamp":1618678102906}
1618678102.931644: {"feed":"book","product_id":"PI_BCHUSD","side":"buy","seq":16257925,"price":1059.9,"qty":7088.0,"timestamp":1618678102907}
1618678102.931694: {"feed":"book","product_id":"PI_BCHUSD","side":"buy","seq":16257926,"price":1059.9,"qty":10894.0,"timestamp":1618678102907}
1618678102.931732: {"feed":"book","product_id":"FI_XBTUSD_210625","side":"buy","seq":21454532,"price":63785.0,"qty":3000.0,"timestamp":1618678102908}
1618678102.931778: {"feed":"book","product_id":"FI_ETHUSD_210625","side":"buy","seq":12455197,"price":2497.15,"qty":5000.0,"timestamp":1618678102909}
1618678102.9645472: {"feed":"book","product_id":"FI_XBTUSD_210625","side":"buy","seq":21454533,"price":57200.5,"qty":33155.0,"timestamp":1618678102940}
1618678102.9777238: {"feed":"book","product_id":"FI_ETHUSD_210924","side":"sell","seq":3859092,"price":2661.55,"qty":2000.0,"timestamp":1618678102954}
1618678103.0532842: {"feed":"book","product_id":"FI_XBTUSD_210924","side":"buy","seq":13850705,"price":52552.5,"qty":58843.0,"timestamp":1618678103025}
1618678103.053364: {"feed":"book","product_id":"FI_XBTUSD_210625","side":"sell","seq":21454534,"price":64097.5,"qty":0.0,"timestamp":1618678103025}
1618678103.053416: {"feed":"book","product_id":"FI_XBTUSD_210625","side":"sell","seq":21454535,"price":64098.0,"qty":268643.0,"timestamp":1618678103025}
1618678103.053443: {"feed":"book","product_id":"FI_XBTUSD_210625","side":"sell","seq":21454536,"price":64069.0,"qty":0.0,"timestamp":1618678103025}
1618678103.053472: {"feed":"book","product_id":"FI_XBTUSD_210625","side":"sell","seq":21454537,"price":64069.0,"qty":13274.0,"timestamp":1618678103025}
1618678103.0535018: {"feed":"book","product_id":"FI_XBTUSD_210625","side":"buy","seq":21454538,"price":63926.0,"qty":1101.0,"timestamp":1618678103025}
1618678103.053532: {"feed":"book","product_id":"FI_XBTUSD_210625","side":"buy","seq":21454539,"price":63926.0,"qty":2171.0,"timestamp":1618678103025}
1618678103.0535529: {"feed":"book","product_id":"FI_XBTUSD_210625","side":"buy","seq":21454540,"price":63926.0,"qty":1070.0,"timestamp":1618678103025}
1618678103.0535731: {"feed":"book","product_id":"FI_XBTUSD_210625","side":"buy","seq":21454541,"price":63926.0,"qty":2140.0,"timestamp":1618678103025}
1618678103.0535932: {"feed":"book","product_id":"FI_XBTUSD_210625","side":"sell","seq":21454542,"price":64143.5,"qty":0.0,"timestamp":1618678103025}
1618678103.053995: {"feed":"book","product_id":"FI_XBTUSD_210625","side":"sell","seq":21454543,"price":64143.5,"qty":29886.0,"timestamp":1618678103025}
1618678103.054053: {"feed":"book","product_id":"FI_XBTUSD_210625","side":"buy","seq":21454544,"price":63748.5,"qty":0.0,"timestamp":1618678103025}
1618678103.054086: {"feed":"book","product_id":"FI_XBTUSD_210625","side":"buy","seq":21454545,"price":63748.5,"qty":3241.0,"timestamp":1618678103025}
1618678103.0541599: {"feed":"book","product_id":"FI_XBTUSD_210625","side":"buy","seq":21454546,"price":63853.0,"qty":0.0,"timestamp":1618678103025}
1618678103.054191: {"feed":"book","product_id":"FI_XBTUSD_210625","side":"buy","seq":21454547,"price":63853.0,"qty":2052.0,"timestamp":1618678103025}
1618678103.054214: {"feed":"book","product_id":"FI_XBTUSD_210625","side":"buy","seq":21454548,"price":63496.0,"qty":0.0,"timestamp":1618678103025}
1618678103.054236: {"feed":"book","product_id":"FI_XBTUSD_210625","side":"buy","seq":21454549,"price":63496.0,"qty":4280.0,"timestamp":1618678103025}
1618678103.056648: {"feed":"book","product_id":"FI_XBTUSD_210625","side":"sell","seq":21454550,"price":64259.5,"qty":0.0,"timestamp":1618678103025}
1618678103.056712: {"feed":"book","product_id":"FI_XBTUSD_210625","side":"sell","seq":21454551,"price":64259.5,"qty":55976.0,"timestamp":1618678103025}
1618678103.0567522: {"feed":"book","product_id":"FI_XBTUSD_210625","side":"sell","seq":21454552,"price":64516.5,"qty":0.0,"timestamp":1618678103025}
1618678103.056784: {"feed":"book","product_id":"FI_XBTUSD_210625","side":"sell","seq":21454553,"price":64516.5,"qty":76430.0,"timestamp":1618678103025}
1618678103.060318: {"feed":"book","product_id":"FI_XBTUSD_210430","side":"sell","seq":12237418,"price":61267.5,"qty":30542.0,"timestamp":1618678103033}
1618678103.060408: {"feed":"book","product_id":"PI_BCHUSD","side":"sell","seq":16257927,"price":1062.6,"qty":5601.0,"timestamp":1618678103033}
1618678103.0604422: {"feed":"book","product_id":"FI_XRPUSD_210625","side":"sell","seq":3631416,"price":1.6996,"qty":354.0,"timestamp":1618678103033}
1618678103.0604758: {"feed":"book","product_id":"PI_BCHUSD","side":"sell","seq":16257928,"price":1063.5,"qty":10635.0,"timestamp":1618678103033}
1618678103.114423: {"feed":"book","product_id":"FI_ETHUSD_210625","side":"buy","seq":12455198,"price":2477.2,"qty":60909.0,"timestamp":1618678103088}
1618678103.114534: {"feed":"book","product_id":"FI_BCHUSD_210430","side":"buy","seq":1411839,"price":1070.4,"qty":0.0,"timestamp":1618678103088}
1618678103.1146061: {"feed":"book","product_id":"FI_BCHUSD_210430","side":"buy","seq":1411840,"price":1068.2,"qty":19360.0,"timestamp":1618678103088}
1618678103.120644: {"feed":"book","product_id":"FI_XBTUSD_210924","side":"buy","seq":13850706,"price":52552.5,"qty":59077.0,"timestamp":1618678103088}
1618678103.120755: {"feed":"book","product_id":"FI_BCHUSD_210625","side":"buy","seq":2240154,"price":1123.9,"qty":0.0,"timestamp":1618678103088}
1618678103.120825: {"feed":"book","product_id":"FI_BCHUSD_210625","side":"buy","seq":2240155,"price":1108.3,"qty":4513.0,"timestamp":1618678103088}
1618678103.120876: {"feed":"book","product_id":"FI_XRPUSD_210625","side":"sell","seq":3631417,"price":1.6992,"qty":248.0,"timestamp":1618678103094}
1618678103.132206: {"feed":"book","product_id":"FI_ETHUSD_210625","side":"sell","seq":12455199,"price":2508.05,"qty":16352.0,"timestamp":1618678103106}
1618678103.132323: {"feed":"book","product_id":"FI_ETHUSD_210625","side":"sell","seq":12455200,"price":2509.2,"qty":19470.0,"timestamp":1618678103106}
1618678103.132392: {"feed":"book","product_id":"FI_BCHUSD_210625","side":"buy","seq":2240156,"price":1108.3,"qty":0.0,"timestamp":1618678103107}
1618678103.13245: {"feed":"book","product_id":"FI_BCHUSD_210625","side":"buy","seq":2240157,"price":1123.9,"qty":4513.0,"timestamp":1618678103107}
1618678103.138648: {"feed":"book","product_id":"FI_XBTUSD_210625","side":"buy","seq":21454554,"price":57200.5,"qty":30165.0,"timestamp":1618678103112}
1618678103.1875682: {"feed":"book","product_id":"FI_XBTUSD_210625","side":"buy","seq":21454555,"price":57200.5,"qty":33200.0,"timestamp":1618678103163}
1618678103.1908102: {"feed":"book","product_id":"FI_ETHUSD_210625","side":"buy","seq":12455201,"price":2497.15,"qty":2000.0,"timestamp":1618678103167}
1618678103.190919: {"feed":"book","product_id":"FI_ETHUSD_210625","side":"buy","seq":12455202,"price":2493.25,"qty":0.0,"timestamp":1618678103168}
1618678103.216405: {"feed":"book","product_id":"PI_BCHUSD","side":"buy","seq":16257929,"price":1059.8,"qty":20678.0,"timestamp":1618678103193}
1618678103.216516: {"feed":"book","product_id":"PI_BCHUSD","side":"buy","seq":16257930,"price":1059.8,"qty":5011.0,"timestamp":1618678103193}
1618678103.234637: {"feed":"book","product_id":"FI_XBTUSD_210924","side":"buy","seq":13850707,"price":52552.5,"qty":59225.0,"timestamp":1618678103210}
1618678103.247447: {"feed":"book","product_id":"FI_XRPUSD_210625","side":"buy","seq":3631418,"price":1.6933,"qty":16799.0,"timestamp":1618678103223}
1618678103.249873: {"feed":"book","product_id":"PI_BCHUSD","side":"sell","seq":16257931,"price":1063.5,"qty":0.0,"timestamp":1618678103226}
1618678103.249999: {"feed":"book","product_id":"PI_BCHUSD","side":"sell","seq":16257932,"price":1063.4,"qty":15629.0,"timestamp":1618678103226}
1618678103.256005: {"feed":"book","product_id":"FI_XBTUSD_210625","side":"sell","seq":21454556,"price":64098.0,"qty":250001.0,"timestamp":1618678103231}
1618678103.256115: {"feed":"book","product_id":"FI_XBTUSD_210625","side":"sell","seq":21454557,"price":64098.5,"qty":52663.0,"timestamp":1618678103231}
1618678103.260457: {"feed":"book","product_id":"FI_XBTUSD_210625","side":"sell","seq":21454558,"price":64069.0,"qty":0.0,"timestamp":1618678103231}
1618678103.260587: {"feed":"book","product_id":"FI_XBTUSD_210625","side":"sell","seq":21454559,"price":64069.0,"qty":13216.0,"timestamp":1618678103231}
1618678103.2606661: {"feed":"book","product_id":"FI_XBTUSD_210625","side":"buy","seq":21454560,"price":63926.0,"qty":1070.0,"timestamp":1618678103231}
1618678103.260694: {"feed":"book","product_id":"FI_XBTUSD_210625","side":"buy","seq":21454561,"price":63926.0,"qty":2143.0,"timestamp":1618678103231}
1618678103.2607172: {"feed":"book","product_id":"FI_XBTUSD_210625","side":"buy","seq":21454562,"price":63926.0,"qty":1073.0,"timestamp":1618678103232}
1618678103.2607381: {"feed":"book","product_id":"FI_XBTUSD_210625","side":"buy","seq":21454563,"price":63926.0,"qty":2146.0,"timestamp":1618678103232}
1618678103.260758: {"feed":"book","product_id":"FI_XBTUSD_210625","side":"sell","seq":21454564,"price":64143.5,"qty":0.0,"timestamp":1618678103232}
1618678103.2607849: {"feed":"book","product_id":"FI_XBTUSD_210625","side":"sell","seq":21454565,"price":64143.5,"qty":29814.0,"timestamp":1618678103232}
1618678103.26081: {"feed":"book","product_id":"PI_BCHUSD","side":"sell","seq":16257933,"price":1062.9,"qty":6966.0,"timestamp":1618678103234}
1618678103.2608361: {"feed":"book","product_id":"FI_XBTUSD_210625","side":"buy","seq":21454566,"price":63496.0,"qty":0.0,"timestamp":1618678103232}
1618678103.260863: {"feed":"book","product_id":"FI_XBTUSD_210625","side":"buy","seq":21454567,"price":63496.0,"qty":4275.0,"timestamp":1618678103232}
1618678103.260886: {"feed":"book","product_id":"FI_XBTUSD_210625","side":"buy","seq":21454568,"price":63748.5,"qty":0.0,"timestamp":1618678103232}
1618678103.260911: {"feed":"book","product_id":"FI_XBTUSD_210625","side":"buy","seq":21454569,"price":63748.5,"qty":3239.0,"timestamp":1618678103232}
1618678103.263448: {"feed":"book","product_id":"FI_XBTUSD_210625","side":"sell","seq":21454570,"price":64259.5,"qty":0.0,"timestamp":1618678103232}
1618678103.263537: {"feed":"book","product_id":"FI_XBTUSD_210625","side":"sell","seq":21454571,"price":64259.5,"qty":55947.0,"timestamp":1618678103232}
1618678103.263579: {"feed":"book","product_id":"FI_XBTUSD_210625","side":"buy","seq":21454572,"price":63853.0,"qty":0.0,"timestamp":1618678103232}
1618678103.263621: {"feed":"book","product_id":"FI_XBTUSD_210625","side":"buy","seq":21454573,"price":63853.0,"qty":2053.0,"timestamp":1618678103232}
1618678103.26365: {"feed":"book","product_id":"FI_XBTUSD_210625","side":"sell","seq":21454574,"price":64516.5,"qty":0.0,"timestamp":1618678103232}
1618678103.2636778: {"feed":"book","product_id":"FI_XBTUSD_210625","side":"sell","seq":21454575,"price":64516.5,"qty":76431.0,"timestamp":1618678103232}
1618678103.263933: {"feed":"book","product_id":"FI_ETHUSD_210625","side":"sell","seq":12455203,"price":2505.65,"qty":5000.0,"timestamp":1618678103242}
1618678103.301013: {"feed":"book","product_id":"FI_XBTUSD_210625","side":"buy","seq":21454576,"price":57200.5,"qty":30165.0,"timestamp":1618678103274}
1618678103.335161: {"feed":"book","product_id":"FI_ETHUSD_210625","side":"sell","seq":12455204,"price":2509.2,"qty":0.0,"timestamp":1618678103311}
1618678103.335287: {"feed":"book","product_id":"FI_ETHUSD_210625","side":"sell","seq":12455205,"price":2508.05,"qty":32206.0,"timestamp":1618678103311}
1618678103.3425112: {"feed":"book","product_id":"FI_XBTUSD_210625","side":"buy","seq":21454577,"price":57200.5,"qty":33155.0,"timestamp":1618678103318}
1618678103.378911: {"feed":"book","product_id":"FI_XBTUSD_210625","side":"sell","seq":21454578,"price":64260.0,"qty":0.0,"timestamp":1618678103354}
1618678103.3790379: {"feed":"book","product_id":"FI_XBTUSD_210625","side":"sell","seq":21454579,"price":64313.5,"qty":125003.0,"timestamp":1618678103354}
1618678103.3947031: {"feed":"book","product_id":"PI_BCHUSD","side":"sell","seq":16257934,"price":1062.6,"qty":2725.0,"timestamp":1618678103370}
1618678103.3947918: {"feed":"book","product_id":"PI_BCHUSD","side":"sell","seq":16257935,"price":1062.6,"qty":0.0,"timestamp":1618678103370}
1618678103.428158: {"feed":"book","product_id":"FI_XBTUSD_210625","side":"buy","seq":21454580,"price":57200.5,"qty":30165.0,"timestamp":1618678103401}
1618678103.452215: {"feed":"book","product_id":"PI_BCHUSD","side":"sell","seq":16257936,"price":1063.4,"qty":4994.0,"timestamp":1618678103428}
1618678103.467629: {"feed":"book","product_id":"FI_XBTUSD_210625","side":"buy","seq":21454581,"price":57200.5,"qty":33200.0,"timestamp":1618678103443}
1618678103.4729412: {"feed":"book","product_id":"FI_XBTUSD_210625","side":"sell","seq":21454582,"price":64098.5,"qty":33973.0,"timestamp":1618678103449}
1618678103.4730508: {"feed":"book","product_id":"FI_XBTUSD_210625","side":"sell","seq":21454583,"price":64143.5,"qty":59430.0,"timestamp":1618678103449}
1618678103.4731: {"feed":"book","product_id":"FI_ETHUSD_210625","side":"buy","seq":12455206,"price":2497.4,"qty":0.0,"timestamp":1618678103449}
1618678103.490043: {"feed":"book","product_id":"PI_BCHUSD","side":"buy","seq":16257937,"price":1059.2,"qty":0.0,"timestamp":1618678103466}
1618678103.490171: {"feed":"book","product_id":"PI_BCHUSD","side":"sell","seq":16257938,"price":1062.9,"qty":9857.0,"timestamp":1618678103467}
1618678103.4902241: {"feed":"book","product_id":"PI_BCHUSD","side":"sell","seq":16257939,"price":1062.8,"qty":3738.0,"timestamp":1618678103467}
1618678103.490262: {"feed":"book","product_id":"PI_BCHUSD","side":"sell","seq":16257940,"price":1062.8,"qty":981.0,"timestamp":1618678103467}
1618678103.4902961: {"feed":"book","product_id":"PI_BCHUSD","side":"sell","seq":16257941,"price":1062.9,"qty":12870.0,"timestamp":1618678103467}
1618678103.490328: {"feed":"book","product_id":"PI_BCHUSD","side":"sell","seq":16257942,"price":1063.5,"qty":3859.0,"timestamp":1618678103468}
1618678103.490672: {"feed":"book","product_id":"PI_BCHUSD","side":"buy","seq":16257943,"price":1059.8,"qty":8642.0,"timestamp":1618678103468}
1618678103.493425: {"feed":"book","product_id":"PI_BCHUSD","side":"sell","seq":16257944,"price":1063.1,"qty":15080.0,"timestamp":1618678103470}
1618678103.514555: {"feed":"book","product_id":"FI_BCHUSD_210625","side":"buy","seq":2240158,"price":1123.9,"qty":0.0,"timestamp":1618678103491}
1618678103.514681: {"feed":"book","product_id":"FI_BCHUSD_210625","side":"buy","seq":2240159,"price":1108.3,"qty":4513.0,"timestamp":1618678103491}
1618678103.5225432: {"feed":"book","product_id":"FI_ETHUSD_210430","side":"buy","seq":4780757,"price":2351.6,"qty":99600.0,"timestamp":1618678103492}
1618678103.522669: {"feed":"book","product_id":"FI_BCHUSD_210625","side":"buy","seq":2240160,"price":1108.3,"qty":0.0,"timestamp":1618678103499}
1618678103.522733: {"feed":"book","product_id":"FI_BCHUSD_210625","side":"buy","seq":2240161,"price":1123.9,"qty":4513.0,"timestamp":1618678103499}
1618678103.524056: {"feed":"book","product_id":"PI_BCHUSD","side":"sell","seq":16257945,"price":1062.9,"qty":9857.0,"timestamp":1618678103501}
1618678103.5326421: {"feed":"book","product_id":"PI_BCHUSD","side":"sell","seq":16257946,"price":1062.9,"qty":6966.0,"timestamp":1618678103503}
1618678103.532751: {"feed":"book","product_id":"PI_BCHUSD","side":"sell","seq":16257947,"price":1063.0,"qty":7255.0,"timestamp":1618678103503}
1618678103.532799: {"feed":"book","product_id":"PI_BCHUSD","side":"buy","seq":16257948,"price":1059.9,"qty":7088.0,"timestamp":1618678103503}
1618678103.5328379: {"feed":"book","product_id":"PI_BCHUSD","side":"sell","seq":16257949,"price":1063.1,"qty":0.0,"timestamp":1618678103503}
1618678103.540205: {"feed":"book","product_id":"FI_XBTUSD_210625","side":"buy","seq":21454584,"price":57200.5,"qty":30165.0,"timestamp":1618678103505}
1618678103.540319: {"feed":"book","product_id":"PI_BCHUSD","side":"sell","seq":16257950,"price":1063.5,"qty":24970.0,"timestamp":1618678103503}
1618678103.540371: {"feed":"book","product_id":"PI_BCHUSD","side":"sell","seq":16257951,"price":1063.5,"qty":40186.0,"timestamp":1618678103503}
1618678103.54041: {"feed":"book","product_id":"PI_BCHUSD","side":"buy","seq":16257952,"price":1059.9,"qty":3580.0,"timestamp":1618678103505}
1618678103.540444: {"feed":"book","product_id":"PI_BCHUSD","side":"sell","seq":16257953,"price":1063.2,"qty":1216.0,"timestamp":1618678103507}
1618678103.543384: {"feed":"book","product_id":"FI_ETHUSD_210625","side":"sell","seq":12455207,"price":2507.65,"qty":3000.0,"timestamp":1618678103519}
1618678103.575734: {"feed":"book","product_id":"FI_XBTUSD_210625","side":"buy","seq":21454585,"price":57200.5,"qty":33155.0,"timestamp":1618678103552}
1618678103.600824: {"feed":"book","product_id":"FI_BCHUSD_210625","side":"buy","seq":2240162,"price":1126.1,"qty":12742.0,"timestamp":1618678103576}
1618678103.6042051: {"feed":"book","product_id":"FI_ETHUSD_210625","side":"sell","seq":12455208,"price":2508.05,"qty":16352.0,"timestamp":1618678103578}
1618678103.604321: {"feed":"book","product_id":"FI_ETHUSD_210625","side":"sell","seq":12455209,"price":2509.2,"qty":19424.0,"timestamp":1618678103578}
1618678103.606934: {"feed":"book","product_id":"FI_ETHUSD_210625","side":"buy","seq":12455210,"price":2500.35,"qty":0.0,"timestamp":1618678103578}
1618678103.6070678: {"feed":"book","product_id":"FI_ETHUSD_210625","side":"buy","seq":12455211,"price":2500.85,"qty":454.0,"timestamp":1618678103578}
1618678103.607121: {"feed":"book","product_id":"FI_ETHUSD_210625","side":"sell","seq":12455212,"price":2513.35,"qty":0.0,"timestamp":1618678103578}
1618678103.607171: {"feed":"book","product_id":"FI_ETHUSD_210625","side":"sell","seq":12455213,"price":2513.85,"qty":33140.0,"timestamp":1618678103578}
1618678103.654357: {"feed":"book","product_id":"FI_XBTUSD_210625","side":"buy","seq":21454586,"price":57200.5,"qty":30165.0,"timestamp":1618678103630}
1618678103.695477: {"feed":"book","product_id":"FI_XBTUSD_210625","side":"buy","seq":21454587,"price":57200.5,"qty":33200.0,"timestamp":1618678103672}
1618678103.711699: {"feed":"book","product_id":"FI_ETHUSD_210924","side":"sell","seq":3859093,"price":2662.25,"qty":0.0,"timestamp":1618678103684}
1618678103.711753: {"feed":"book","product_id":"PI_BCHUSD","side":"sell","seq":16257954,"price":1062.9,"qty":10072.0,"timestamp":1618678103682}
1618678103.711777: {"feed":"book","product_id":"PI_BCHUSD","side":"sell","seq":16257955,"price":1063.5,"qty":43934.0,"timestamp":1618678103682}
1618678103.7472498: {"feed":"book","product_id":"FI_XRPUSD_210625","side":"sell","seq":3631419,"price":1.7121,"qty":0.0,"timestamp":1618678103724}
1618678103.763017: {"feed":"book","product_id":"FI_XBTUSD_210625","side":"buy","seq":21454588,"price":57200.5,"qty":30165.0,"timestamp":1618678103738}
1618678103.764555: {"feed":"book","product_id":"PI_BCHUSD","side":"buy","seq":16257956,"price":1059.7,"qty":20682.0,"timestamp":1618678103742}
1618678103.766637: {"feed":"book","product_id":"PI_BCHUSD","side":"buy","seq":16257957,"price":1059.7,"qty":41854.0,"timestamp":1618678103743}
1618678103.801347: {"feed":"book","product_id":"FI_XRPUSD_210625","side":"buy","seq":3631420,"price":1.6954,"qty":0.0,"timestamp":1618678103777}
1618678103.801435: {"feed":"book","product_id":"FI_XRPUSD_210625","side":"buy","seq":3631421,"price":1.6949,"qty":50.0,"timestamp":1618678103777}
1618678103.803434: {"feed":"book","product_id":"FI_XRPUSD_210625","side":"sell","seq":3631422,"price":1.6987,"qty":1137.0,"timestamp":1618678103780}
1618678103.80404: {"feed":"book","product_id":"FI_XBTUSD_210625","side":"buy","seq":21454589,"price":57200.5,"qty":33155.0,"timestamp":1618678103781}
1618678103.807335: {"feed":"book","product_id":"FI_XRPUSD_210625","side":"buy","seq":3631423,"price":1.6948,"qty":0.0,"timestamp":1618678103783}
1618678103.807467: {"feed":"book","product_id":"FI_XRPUSD_210625","side":"buy","seq":3631424,"price":1.6949,"qty":118.0,"timestamp":1618678103783}
1618678103.80752: {"feed":"book","product_id":"FI_ETHUSD_210625","side":"buy","seq":12455214,"price":2500.85,"qty":227.0,"timestamp":1618678103783}
1618678103.807561: {"feed":"book","product_id":"FI_ETHUSD_210625","side":"buy","seq":12455215,"price":2500.35,"qty":233.0,"timestamp":1618678103783}
1618678103.808962: {"feed":"book","product_id":"FI_ETHUSD_210625","side":"sell","seq":12455216,"price":2509.2,"qty":0.0,"timestamp":1618678103783}
1618678103.809057: {"feed":"book","product_id":"FI_ETHUSD_210625","side":"sell","seq":12455217,"price":2508.05,"qty":33836.0,"timestamp":1618678103783}
1618678103.809092: {"feed":"book","product_id":"PI_BCHUSD","side":"sell","seq":16257958,"price":1063.5,"qty":28718.0,"timestamp":1618678103784}
1618678103.8185432: {"feed":"book","product_id":"FI_XRPUSD_210625","side":"buy","seq":3631425,"price":1.6949,"qty":68.0,"timestamp":1618678103793}
1618678103.8186162: {"feed":"book","product_id":"FI_XRPUSD_210625","side":"buy","seq":3631426,"price":1.6955,"qty":50.0,"timestamp":1618678103793}
1618678103.821564: {"feed":"book","product_id":"FI_XRPUSD_210625","side":"buy","seq":3631427,"price":1.6917,"qty":271.0,"timestamp":1618678103798}
1618678103.824824: {"feed":"book","product_id":"FI_XRPUSD_210625","side":"buy","seq":3631428,"price":1.6949,"qty":0.0,"timestamp":1618678103801}
1618678103.824955: {"feed":"book","product_id":"FI_XRPUSD_210625","side":"buy","seq":3631429,"price":1.6945,"qty":68.0,"timestamp":1618678103801}
1618678103.828189: {"feed":"book","product_id":"FI_XRPUSD_210625","side":"sell","seq":3631430,"price":1.7005,"qty":225.0,"timestamp":1618678103803}
1618678103.828326: {"feed":"book","product_id":"FI_XRPUSD_210625","side":"sell","seq":3631431,"price":1.6996,"qty":19322.0,"timestamp":1618678103803}
1618678103.8728588: {"feed":"book","product_id":"FI_XBTUSD_210625","side":"buy","seq":21454590,"price":57200.5,"qty":30165.0,"timestamp":1618678103849}
1618678103.87616: {"feed":"book","product_id":"FI_XBTUSD_210625","side":"buy","seq":21454591,"price":63496.0,"qty":0.0,"timestamp":1618678103852}
1618678103.876287: {"feed":"book","product_id":"FI_XBTUSD_210625","side":"buy","seq":21454592,"price":63544.0,"qty":4246.0,"timestamp":1618678103852}
1618678103.917676: {"feed":"book","product_id":"FI_XBTUSD_210625","side":"buy","seq":21454593,"price":57200.5,"qty":33200.0,"timestamp":1618678103892}
1618678103.9348302: {"feed":"book","product_id":"PI_BCHUSD","side":"sell","seq":16257959,"price":1062.8,"qty":4060.0,"timestamp":1618678103906}
1618678103.9349399: {"feed":"book","product_id":"PI_BCHUSD","side":"buy","seq":16257960,"price":1060.1,"qty":3536.0,"timestamp":1618678103907}
1618678103.935005: {"feed":"book","product_id":"PI_BCHUSD","side":"buy","seq":16257961,"price":1060.1,"qty":7237.0,"timestamp":1618678103909}
1618678103.9950469: {"feed":"book","product_id":"FI_XRPUSD_210625","side":"buy","seq":3631432,"price":1.6945,"qty":0.0,"timestamp":1618678103970}
1618678103.995137: {"feed":"book","product_id":"FI_XRPUSD_210625","side":"buy","seq":3631433,"price":1.694,"qty":68.0,"timestamp":1618678103970}
1618678103.9986172: {"feed":"book","product_id":"FI_XRPUSD_210625","side":"buy","seq":3631434,"price":1.6932,"qty":0.0,"timestamp":1618678103974}
1618678103.998688: {"feed":"book","product_id":"FI_XRPUSD_210625","side":"buy","seq":3631435,"price":1.6924,"qty":21304.0,"timestamp":1618678103974}
1618678103.99872: {"feed":"book","product_id":"FI_XBTUSD_210625","side":"buy","seq":21454594,"price":57200.5,"qty":30165.0,"timestamp":1618678103974}
1618678104.018995: {"feed":"book","product_id":"FI_ETHUSD_210625","side":"buy","seq":12455218,"price":2496.75,"qty":3000.0,"timestamp":1618678103992}
1618678104.0191271: {"feed":"book","product_id":"FI_ETHUSD_210625","side":"buy","seq":12455219,"price":2493.1,"qty":105693.0,"timestamp":1618678103992}
1618678104.031272: {"feed":"book","product_id":"PI_BCHUSD","side":"sell","seq":16257962,"price":1062.8,"qty":6905.0,"timestamp":1618678104005}
1618678104.040941: {"feed":"book","product_id":"FI_XBTUSD_210625","side":"buy","seq":21454595,"price":57200.5,"qty":33155.0,"timestamp":1618678104017}
1618678104.0612621: {"feed":"book","product_id":"FI_ETHUSD_210625","side":"buy","seq":12455220,"price":2500.35,"qty":0.0,"timestamp":1618678104033}
1618678104.0613918: {"feed":"book","product_id":"FI_ETHUSD_210625","side":"buy","seq":12455221,"price":2500.85,"qty":453.0,"timestamp":1618678104033}
1618678104.070247: {"feed":"book","product_id":"FI_ETHUSD_210625","side":"buy","seq":12455222,"price":2499.85,"qty":0.0,"timestamp":1618678104046}
1618678104.1411: {"feed":"book","product_id":"PI_BCHUSD","side":"sell","seq":16257963,"price":1063.5,"qty":7607.0,"timestamp":1618678104113}
1618678104.14121: {"feed":"book","product_id":"PI_BCHUSD","side":"sell","seq":16257964,"price":1063.7,"qty":45787.0,"timestamp":1618678104113}
1618678104.1488671: {"feed":"book","product_id":"FI_XBTUSD_210625","side":"buy","seq":21454596,"price":57200.5,"qty":30165.0,"timestamp":1618678104118}
1618678104.148978: {"feed":"book","product_id":"PI_BCHUSD","side":"sell","seq":16257965,"price":1063.5,"qty":3859.0,"timestamp":1618678104118}
1618678104.14903: {"feed":"book","product_id":"FI_XRPUSD_210625","side":"buy","seq":3631436,"price":1.6917,"qty":0.0,"timestamp":1618678104118}
1618678104.1490932: {"feed":"book","product_id":"FI_XBTUSD_210625","side":"sell","seq":21454597,"price":64069.0,"qty":0.0,"timestamp":1618678104118}
1618678104.149141: {"feed":"book","product_id":"FI_XBTUSD_210625","side":"sell","seq":21454598,"price":64097.5,"qty":17837.0,"timestamp":1618678104118}
1618678104.149209: {"feed":"book","product_id":"FI_XRPUSD_210625","side":"buy","seq":3631437,"price":1.6905,"qty":356.0,"timestamp":1618678104118}
1618678104.149235: {"feed":"book","product_id":"FI_XBTUSD_210625","side":"sell","seq":21454599,"price":64259.5,"qty":0.0,"timestamp":1618678104118}
1618678104.149261: {"feed":"book","product_id":"FI_XBTUSD_210625","side":"sell","seq":21454600,"price":64313.0,"qty":60535.0,"timestamp":1618678104118}
1618678104.2103941: {"feed":"book","product_id":"FI_XBTUSD_210625","side":"buy","seq":21454601,"price":57200.5,"qty":33200.0,"timestamp":1618678104175}
1618678104.2132769: {"feed":"book","product_id":"FI_XBTUSD_210430","side":"buy","seq":12237419,"price":60683.5,"qty":500.0,"timestamp":1618678104189}
1618678104.213404: {"feed":"book","product_id":"FI_XBTUSD_210430","side":"sell","seq":12237420,"price":61960.5,"qty":500.0,"timestamp":1618678104189}
1618678104.230973: {"feed":"book","product_id":"PI_BCHUSD","side":"sell","seq":16257966,"price":1063.7,"qty":35150.0,"timestamp":1618678104203}
1618678104.2310798: {"feed":"book","product_id":"PI_BCHUSD","side":"sell","seq":16257967,"price":1063.5,"qty":14496.0,"timestamp":1618678104203}
1618678104.24607: {"feed":"book","product_id":"FI_ETHUSD_210625","side":"buy","seq":12455223,"price":2497.45,"qty":2000.0,"timestamp":1618678104222}
1618678104.261893: {"feed":"book","product_id":"FI_XBTUSD_210625","side":"buy","seq":21454602,"price":57200.5,"qty":30165.0,"timestamp":1618678104237}
1618678104.303734: {"feed":"book","product_id":"FI_XBTUSD_210625","side":"buy","seq":21454603,"price":57200.5,"qty":33155.0,"timestamp":1618678104280}
1618678104.3065028: {"feed":"book","product_id":"FI_XBTUSD_210430","side":"sell","seq":12237421,"price":61960.5,"qty":0.0,"timestamp":1618678104282}
1618678104.306635: {"feed":"book","product_id":"FI_XBTUSD_210430","side":"buy","seq":12237422,"price":60683.5,"qty":0.0,"timestamp":1618678104282}
1618678104.3483899: {"feed":"book","product_id":"PI_BCHUSD","side":"sell","seq":16257968,"price":1062.9,"qty":6966.0,"timestamp":1618678104321}
1618678104.3485062: {"feed":"book","product_id":"PI_BCHUSD","side":"buy","seq":16257969,"price":1059.7,"qty":25878.0,"timestamp":1618678104322}
1618678104.348556: {"feed":"book","product_id":"PI_BCHUSD","side":"sell","seq":16257970,"price":1062.8,"qty":4060.0,"timestamp":1618678104322}
1618678104.348594: {"feed":"book","product_id":"PI_BCHUSD","side":"buy","seq":16257971,"price":1060.1,"qty":3701.0,"timestamp":1618678104322}
1618678104.348628: {"feed":"book","product_id":"PI_BCHUSD","side":"sell","seq":16257972,"price":1063.2,"qty":31856.0,"timestamp":1618678104322}
1618678104.348662: {"feed":"book","product_id":"PI_BCHUSD","side":"sell","seq":16257973,"price":1063.8,"qty":11064.0,"timestamp":1618678104323}
1618678104.3511329: {"feed":"book","product_id":"PI_BCHUSD","side":"sell","seq":16257974,"price":1063.5,"qty":10637.0,"timestamp":1618678104323}
1618678104.351211: {"feed":"book","product_id":"PI_BCHUSD","side":"buy","seq":16257975,"price":1060.1,"qty":0.0,"timestamp":1618678104324}
1618678104.351257: {"feed":"book","product_id":"FI_XBTUSD_210625","side":"sell","seq":21454604,"price":64097.5,"qty":0.0,"timestamp":1618678104324}
1618678104.351292: {"feed":"book","product_id":"FI_XBTUSD_210625","side":"sell","seq":21454605,"price":64069.0,"qty":12821.0,"timestamp":1618678104324}
1618678104.351323: {"feed":"book","product_id":"PI_BCHUSD","side":"buy","seq":16257976,"price":1059.8,"qty":5011.0,"timestamp":1618678104324}
1618678104.351346: {"feed":"book","product_id":"FI_XBTUSD_210625","side":"sell","seq":21454606,"price":64313.0,"qty":0.0,"timestamp":1618678104324}
1618678104.351372: {"feed":"book","product_id":"FI_XBTUSD_210625","side":"sell","seq":21454607,"price":64261.0,"qty":55889.0,"timestamp":1618678104324}
1618678104.353215: {"feed":"book","product_id":"FI_XBTUSD_210430","side":"buy","seq":12237423,"price":61158.0,"qty":0.0,"timestamp":1618678104328}
1618678104.353303: {"feed":"book","product_id":"FI_XBTUSD_210430","side":"buy","seq":12237424,"price":61140.0,"qty":2702.0,"timestamp":1618678104329}
1618678104.353344: {"feed":"book","product_id":"FI_XBTUSD_210625","side":"buy","seq":21454608,"price":63858.0,"qty":4419.0,"timestamp":1618678104329}
1618678104.353375: {"feed":"book","product_id":"FI_XBTUSD_210625","side":"buy","seq":21454609,"price":63874.0,"qty":0.0,"timestamp":1618678104329}
1618678104.35954: {"feed":"book","product_id":"FI_XBTUSD_210625","side":"sell","seq":21454610,"price":64098.0,"qty":0.0,"timestamp":1618678104334}
1618678104.359668: {"feed":"book","product_id":"FI_XBTUSD_210625","side":"sell","seq":21454611,"price":64097.0,"qty":250001.0,"timestamp":1618678104334}
1618678104.359731: {"feed":"book","product_id":"FI_XBTUSD_210625","side":"sell","seq":21454612,"price":64313.5,"qty":0.0,"timestamp":1618678104334}
1618678104.35978: {"feed":"book","product_id":"FI_XBTUSD_210625","side":"sell","seq":21454613,"price":64312.5,"qty":125003.0,"timestamp":1618678104334}
1618678104.3633542: {"feed":"book","product_id":"FI_XBTUSD_210625","side":"sell","seq":21454614,"price":64097.0,"qty":0.0,"timestamp":1618678104335}
1618678104.363483: {"feed":"book","product_id":"FI_XBTUSD_210625","side":"sell","seq":21454615,"price":64098.0,"qty":250001.0,"timestamp":1618678104335}
1618678104.3635478: {"feed":"book","product_id":"FI_XBTUSD_210625","side":"sell","seq":21454616,"price":64312.5,"qty":0.0,"timestamp":1618678104335}
1618678104.363599: {"feed":"book","product_id":"FI_XBTUSD_210625","side":"sell","seq":21454617,"price":64313.5,"qty":125003.0,"timestamp":1618678104335}
1618678104.3636448: {"feed":"book","product_id":"FI_XBTUSD_210625","side":"buy","seq":21454618,"price":57200.5,"qty":30165.0,"timestamp":1618678104335}
1618678104.363682: {"feed":"book","product_id":"FI_XBTUSD_210924","side":"buy","seq":13850708,"price":68193.5,"qty":0.0,"timestamp":1618678104336}
1618678104.367276: {"feed":"book","product_id":"PI_BCHUSD","side":"sell","seq":16257977,"price":1063.5,"qty":0.0,"timestamp":1618678104343}
1618678104.367403: {"feed":"book","product_id":"PI_BCHUSD","side":"sell","seq":16257978,"price":1063.4,"qty":15631.0,"timestamp":1618678104343}
1618678104.38045: {"feed":"book","product_id":"PI_BCHUSD","side":"sell","seq":16257979,"price":1063.3,"qty":3810.0,"timestamp":1618678104358}
1618678104.380576: {"feed":"book","product_id":"PI_BCHUSD","side":"sell","seq":16257980,"price":1064.1,"qty":27359.0,"timestamp":1618678104358}
1618678104.386035: {"feed":"book","product_id":"PI_BCHUSD","side":"sell","seq":16257981,"price":1062.9,"qty":10646.0,"timestamp":1618678104361}
1618678104.386144: {"feed":"book","product_id":"PI_BCHUSD","side":"sell","seq":16257982,"price":1063.7,"qty":31134.0,"timestamp":1618678104361}
1618678104.3861918: {"feed":"book","product_id":"FI_ETHUSD_210625","side":"buy","seq":12455224,"price":2498.5,"qty":1713.0,"timestamp":1618678104361}
1618678104.386254: {"feed":"book","product_id":"FI_ETHUSD_210625","side":"buy","seq":12455225,"price":2499.2,"qty":0.0,"timestamp":1618678104362}
1618678104.388353: {"feed":"book","product_id":"PI_BCHUSD","side":"buy","seq":16257983,"price":1059.7,"qty":24909.0,"timestamp":1618678104365}
1618678104.3982651: {"feed":"book","product_id":"PI_BCHUSD","side":"sell","seq":16257984,"price":1063.8,"qty":6072.0,"timestamp":1618678104375}
1618678104.4015229: {"feed":"book","product_id":"PI_BCHUSD","side":"sell","seq":16257985,"price":1063.2,"qty":36848.0,"timestamp":1618678104375}
1618678104.401632: {"feed":"book","product_id":"PI_BCHUSD","side":"sell","seq":16257986,"price":1063.6,"qty":4990.0,"timestamp":1618678104375}
1618678104.401697: {"feed":"book","product_id":"PI_BCHUSD","side":"sell","seq":16257987,"price":1062.8,"qty":9054.0,"timestamp":1618678104375}
1618678104.401738: {"feed":"book","product_id":"PI_BCHUSD","side":"sell","seq":16257988,"price":1063.4,"qty":10637.0,"timestamp":1618678104375}
1618678104.4017699: {"feed":"book","product_id":"PI_BCHUSD","side":"sell","seq":16257989,"price":1064.2,"qty":7800.0,"timestamp":1618678104375}
1618678104.4072661: {"feed":"book","product_id":"FI_XBTUSD_210625","side":"buy","seq":21454619,"price":57200.5,"qty":33200.0,"timestamp":1618678104384}
1618678104.445817: {"feed":"book","product_id":"PI_BCHUSD","side":"sell","seq":16257990,"price":1064.3,"qty":0.0,"timestamp":1618678104422}
1618678104.445944: {"feed":"book","product_id":"PI_BCHUSD","side":"sell","seq":16257991,"price":1063.4,"qty":14435.0,"timestamp":1618678104423}
1618678104.464277: {"feed":"book","product_id":"FI_BCHUSD_210625","side":"buy","seq":2240163,"price":1130.2,"qty":0.0,"timestamp":1618678104437}
1618678104.464405: {"feed":"book","product_id":"FI_BCHUSD_210625","side":"buy","seq":2240164,"price":1129.4,"qty":81.0,"timestamp":1618678104438}
1618678104.468081: {"feed":"book","product_id":"FI_XBTUSD_210625","side":"buy","seq":21454620,"price":57200.5,"qty":30165.0,"timestamp":1618678104444}
1618678104.470345: {"feed":"book","product_id":"FI_ETHUSD_210625","side":"sell","seq":12455226,"price":2507.65,"qty":0.0,"timestamp":1618678104445}
1618678104.4751139: {"feed":"book","product_id":"FI_ETHUSD_210625","side":"buy","seq":12455227,"price":2500.85,"qty":227.0,"timestamp":1618678104451}
1618678104.475235: {"feed":"book","product_id":"FI_ETHUSD_210625","side":"buy","seq":12455228,"price":2497.65,"qty":763.0,"timestamp":1618678104451}
1618678104.475287: {"feed":"book","product_id":"FI_ETHUSD_210625","side":"sell","seq":12455229,"price":2530.2,"qty":0.0,"timestamp":1618678104451}
1618678104.47535: {"feed":"book","product_id":"FI_ETHUSD_210625","side":"sell","seq":12455230,"price":2521.05,"qty":47789.0,"timestamp":1618678104451}
1618678104.47919: {"feed":"book","product_id":"FI_XRPUSD_210625","side":"buy","seq":3631438,"price":1.6933,"qty":0.0,"timestamp":1618678104455}
1618678104.490368: {"feed":"book","product_id":"PI_BCHUSD","side":"sell","seq":16257992,"price":1062.4,"qty":2890.0,"timestamp":1618678104465}
1618678104.490456: {"feed":"book","product_id":"PI_BCHUSD","side":"sell","seq":16257993,"price":1062.4,"qty":5735.0,"timestamp":1618678104466}
1618678104.490499: {"feed":"book","product_id":"PI_BCHUSD","side":"buy","seq":16257994,"price":1059.8,"qty":8711.0,"timestamp":1618678104466}
1618678104.492515: {"feed":"book","product_id":"PI_BCHUSD","side":"sell","seq":16257995,"price":1062.6,"qty":3610.0,"timestamp":1618678104468}
1618678104.497082: {"feed":"book","product_id":"FI_ETHUSD_210924","side":"buy","seq":3859094,"price":2643.45,"qty":0.0,"timestamp":1618678104474}
1618678104.51091: {"feed":"book","product_id":"FI_XBTUSD_210625","side":"buy","seq":21454621,"price":57200.5,"qty":33155.0,"timestamp":1618678104486}
1618678104.514406: {"feed":"book","product_id":"FI_ETHUSD_210625","side":"buy","seq":12455231,"price":2496.75,"qty":0.0,"timestamp":1618678104490}
1618678104.514534: {"feed":"book","product_id":"PI_BCHUSD","side":"sell","seq":16257996,"price":1064.4,"qty":15594.0,"timestamp":1618678104492}
1618678104.514591: {"feed":"book","product_id":"PI_BCHUSD","side":"buy","seq":16257997,"price":1059.9,"qty":0.0,"timestamp":1618678104492}
1618678104.514643: {"feed":"book","product_id":"PI_BCHUSD","side":"buy","seq":16257998,"price":1059.6,"qty":0.0,"timestamp":1618678104492}
1618678104.515913: {"feed":"book","product_id":"PI_BCHUSD","side":"buy","seq":16257999,"price":1059.5,"qty":3480.0,"timestamp":1618678104493}
1618678104.51823: {"feed":"book","product_id":"PI_BCHUSD","side":"buy","seq":16258000,"price":1059.0,"qty":45167.0,"timestamp":1618678104494}
1618678104.51834: {"feed":"book","product_id":"PI_BCHUSD","side":"sell","seq":16258001,"price":1063.6,"qty":8855.0,"timestamp":1618678104494}
1618678104.527662: {"feed":"book","product_id":"PI_BCHUSD","side":"sell","seq":16258002,"price":1062.8,"qty":25846.0,"timestamp":1618678104502}
1618678104.527771: {"feed":"book","product_id":"PI_BCHUSD","side":"sell","seq":16258003,"price":1062.8,"qty":48154.0,"timestamp":1618678104504}
1618678104.544863: {"feed":"book","product_id":"PI_BCHUSD","side":"sell","seq":16258004,"price":1062.8,"qty":45075.0,"timestamp":1618678104519}
1618678104.544938: {"feed":"book","product_id":"PI_BCHUSD","side":"buy","seq":16258005,"price":1059.7,"qty":3737.0,"timestamp":1618678104519}
1618678104.554889: {"feed":"book","product_id":"FI_XBTUSD_210625","side":"sell","seq":21454622,"price":64143.5,"qty":29814.0,"timestamp":1618678104529}
1618678104.555: {"feed":"book","product_id":"FI_XBTUSD_210625","side":"sell","seq":21454623,"price":64098.0,"qty":268654.0,"timestamp":1618678104529}
1618678104.555048: {"feed":"book","product_id":"FI_XBTUSD_210625","side":"buy","seq":21454624,"price":63544.0,"qty":0.0,"timestamp":1618678104529}
1618678104.555112: {"feed":"book","product_id":"FI_XBTUSD_210625","side":"buy","seq":21454625,"price":63496.0,"qty":4281.0,"timestamp":1618678104529}
1618678104.573344: {"feed":"book","product_id":"FI_XRPUSD_210625","side":"sell","seq":3631439,"price":1.6987,"qty":1187.0,"timestamp":1618678104549}
1618678104.5756521: {"feed":"book","product_id":"FI_BCHUSD_210625","side":"buy","seq":2240165,"price":1123.9,"qty":0.0,"timestamp":1618678104550}
1618678104.575727: {"feed":"book","product_id":"FI_BCHUSD_210625","side":"buy","seq":2240166,"price":1108.3,"qty":4513.0,"timestamp":1618678104550}
1618678104.590247: {"feed":"book","product_id":"FI_XBTUSD_210625","side":"buy","seq":21454626,"price":57200.5,"qty":30165.0,"timestamp":1618678104566}
1618678104.5903249: {"feed":"book","product_id":"FI_ETHUSD_210430","side":"buy","seq":4780758,"price":2351.6,"qty":0.0,"timestamp":1618678104567}
1618678104.611928: {"feed":"book","product_id":"PI_BCHUSD","side":"sell","seq":16258006,"price":1063.7,"qty":27384.0,"timestamp":1618678104587}
1618678104.6124249: {"feed":"book","product_id":"PI_BCHUSD","side":"buy","seq":16258007,"price":1059.8,"qty":3700.0,"timestamp":1618678104589}
1618678104.6304152: {"feed":"book","product_id":"PI_BCHUSD","side":"sell","seq":16258008,"price":1063.1,"qty":3931.0,"timestamp":1618678104607}
1618678104.6324742: {"feed":"book","product_id":"FI_XBTUSD_210625","side":"buy","seq":21454627,"price":57200.5,"qty":33200.0,"timestamp":1618678104608}
1618678104.649684: {"feed":"book","product_id":"PI_BCHUSD","side":"sell","seq":16258009,"price":1063.4,"qty":3798.0,"timestamp":1618678104620}
1618678104.649798: {"feed":"book","product_id":"PI_BCHUSD","side":"sell","seq":16258010,"price":1063.2,"qty":47485.0,"timestamp":1618678104620}
1618678104.690002: {"feed":"book","product_id":"FI_ETHUSD_210625","side":"sell","seq":12455232,"price":2521.05,"qty":0.0,"timestamp":1618678104666}
1618678104.6900742: {"feed":"book","product_id":"FI_ETHUSD_210625","side":"sell","seq":12455233,"price":2530.2,"qty":47799.0,"timestamp":1618678104666}
1618678104.6904871: {"feed":"book","product_id":"FI_ETHUSD_210625","side":"buy","seq":12455234,"price":2497.65,"qty":408.0,"timestamp":1618678104666}
1618678104.6905339: {"feed":"book","product_id":"FI_ETHUSD_210625","side":"buy","seq":12455235,"price":2500.85,"qty":443.0,"timestamp":1618678104666}
1618678104.700783: {"feed":"book","product_id":"PI_BCHUSD","side":"sell","seq":16258011,"price":1062.3,"qty":2952.0,"timestamp":1618678104676}
1618678104.700823: {"feed":"book","product_id":"PI_BCHUSD","side":"sell","seq":16258012,"price":1062.5,"qty":4812.0,"timestamp":1618678104676}
1618678104.70468: {"feed":"book","product_id":"PI_BCHUSD","side":"buy","seq":16258013,"price":1058.8,"qty":0.0,"timestamp":1618678104680}
1618678104.709984: {"feed":"book","product_id":"FI_ETHUSD_210625","side":"buy","seq":12455236,"price":2497.45,"qty":0.0,"timestamp":1618678104686}
1618678104.717589: {"feed":"book","product_id":"FI_XBTUSD_210625","side":"buy","seq":21454628,"price":57200.5,"qty":30165.0,"timestamp":1618678104693}
1618678104.73002: {"feed":"book","product_id":"FI_ETHUSD_210625","side":"sell","seq":12455237,"price":2507.9,"qty":0.0,"timestamp":1618678104706}
1618678104.7332218: {"feed":"book","product_id":"PI_BCHUSD","side":"buy","seq":16258014,"price":1058.7,"qty":38163.0,"timestamp":1618678104710}
1618678104.738687: {"feed":"book","product_id":"FI_XBTUSD_210924","side":"buy","seq":13850709,"price":67998.5,"qty":0.0,"timestamp":1618678104715}
1618678104.738815: {"feed":"book","product_id":"FI_XBTUSD_210924","side":"buy","seq":13850710,"price":68162.5,"qty":0.0,"timestamp":1618678104715}
1618678104.738872: {"feed":"book","product_id":"FI_XBTUSD_210924","side":"sell","seq":13850711,"price":68321.5,"qty":0.0,"timestamp":1618678104715}
1618678104.738921: {"feed":"book","product_id":"FI_XBTUSD_210924","side":"sell","seq":13850712,"price":68485.5,"qty":0.0,"timestamp":1618678104715}
1618678104.742152: {"feed":"book","product_id":"FI_XBTUSD_210625","side":"sell","seq":21454629,"price":63973.0,"qty":0.0,"timestamp":1618678104718}
1618678104.746561: {"feed":"book","product_id":"FI_XBTUSD_210625","side":"sell","seq":21454630,"price":63971.5,"qty":1000.0,"timestamp":1618678104723}
1618678104.757014: {"feed":"book","product_id":"FI_XBTUSD_210625","side":"buy","seq":21454631,"price":63926.0,"qty":1073.0,"timestamp":1618678104733}
1618678104.757123: {"feed":"book","product_id":"FI_XBTUSD_210625","side":"buy","seq":21454632,"price":63917.5,"qty":1162.0,"timestamp":1618678104733}
1618678104.757521: {"feed":"book","product_id":"FI_XBTUSD_210625","side":"buy","seq":21454633,"price":57200.5,"qty":33155.0,"timestamp":1618678104736}
1618678104.764586: {"feed":"book","product_id":"PI_BCHUSD","side":"buy","seq":16258015,"price":1059.3,"qty":16741.0,"timestamp":1618678104741}
1618678104.765098: {"feed":"book","product_id":"PI_BCHUSD","side":"buy","seq":16258016,"price":1059.3,"qty":39120.0,"timestamp":1618678104742}
1618678104.782069: {"feed":"book","product_id":"FI_XBTUSD_210625","side":"sell","seq":21454634,"price":63971.5,"qty":0.0,"timestamp":1618678104757}
1618678104.785957: {"feed":"book","product_id":"FI_XRPUSD_210625","side":"buy","seq":3631440,"price":1.6901,"qty":286.0,"timestamp":1618678104761}
1618678104.788448: {"feed":"book","product_id":"FI_XBTUSD_210625","side":"sell","seq":21454635,"price":63967.5,"qty":1000.0,"timestamp":1618678104764}
1618678104.789315: {"feed":"book","product_id":"FI_BCHUSD_210625","side":"buy","seq":2240167,"price":1129.4,"qty":0.0,"timestamp":1618678104766}
1618678104.789425: {"feed":"book","product_id":"FI_BCHUSD_210625","side":"buy","seq":2240168,"price":1129.1,"qty":84.0,"timestamp":1618678104766}
1618678104.789485: {"feed":"book","product_id":"FI_BCHUSD_210625","side":"buy","seq":2240169,"price":1129.7,"qty":0.0,"timestamp":1618678104766}
1618678104.818308: {"feed":"book","product_id":"PI_BCHUSD","side":"buy","seq":16258017,"price":1058.6,"qty":5013.0,"timestamp":1618678104795}
1618678104.818395: {"feed":"book","product_id":"FI_XBTUSD_210625","side":"buy","seq":21454636,"price":63732.0,"qty":0.0,"timestamp":1618678104795}
1618678104.818439: {"feed":"book","product_id":"FI_XBTUSD_210625","side":"buy","seq":21454637,"price":63774.0,"qty":8784.0,"timestamp":1618678104795}
1618678104.827629: {"feed":"book","product_id":"FI_ETHUSD_210625","side":"buy","seq":12455238,"price":2497.2,"qty":3000.0,"timestamp":1618678104802}
1618678104.832766: {"feed":"book","product_id":"FI_BCHUSD_210430","side":"sell","seq":1411841,"price":1083.0,"qty":28799.0,"timestamp":1618678104807}
1618678104.8429592: {"feed":"book","product_id":"FI_XBTUSD_210625","side":"buy","seq":21454638,"price":57200.5,"qty":30165.0,"timestamp":1618678104811}
1618678104.843057: {"feed":"book","product_id":"FI_ETHUSD_210625","side":"sell","seq":12455239,"price":2505.65,"qty":3000.0,"timestamp":1618678104813}
1618678104.8504808: {"feed":"book","product_id":"FI_XBTUSD_210924","side":"sell","seq":13850713,"price":68297.5,"qty":3000.0,"timestamp":1618678104826}
1618678104.8694882: {"feed":"book","product_id":"FI_XBTUSD_210625","side":"buy","seq":21454639,"price":63772.0,"qty":25069.0,"timestamp":1618678104844}
1618678104.869622: {"feed":"book","product_id":"FI_XBTUSD_210625","side":"buy","seq":21454640,"price":63774.5,"qty":25068.0,"timestamp":1618678104844}
1618678104.869678: {"feed":"book","product_id":"FI_XBTUSD_210625","side":"buy","seq":21454641,"price":63748.0,"qty":0.0,"timestamp":1618678104844}
1618678104.8711512: {"feed":"book","product_id":"PI_BCHUSD","side":"sell","seq":16258018,"price":1063.2,"qty":36848.0,"timestamp":1618678104846}
1618678104.87126: {"feed":"book","product_id":"PI_BCHUSD","side":"sell","seq":16258019,"price":1063.1,"qty":14568.0,"timestamp":1618678104846}
1618678104.87131: {"feed":"book","product_id":"FI_XBTUSD_210625","side":"buy","seq":21454642,"price":63745.5,"qty":0.0,"timestamp":1618678104848}
1618678104.882381: {"feed":"book","product_id":"FI_XBTUSD_210625","side":"buy","seq":21454643,"price":57200.5,"qty":33200.0,"timestamp":1618678104859}
1618678104.891882: {"feed":"book","product_id":"FI_XBTUSD_210430","side":"buy","seq":12237425,"price":60679.5,"qty":500.0,"timestamp":1618678104869}
1618678104.89248: {"feed":"book","product_id":"FI_XBTUSD_210430","side":"sell","seq":12237426,"price":61960.5,"qty":500.0,"timestamp":1618678104869}
1618678104.892551: {"feed":"book","product_id":"FI_ETHUSD_210625","side":"buy","seq":12455240,"price":2495.9,"qty":0.0,"timestamp":1618678104869}
1618678104.892596: {"feed":"book","product_id":"FI_ETHUSD_210625","side":"buy","seq":12455241,"price":2489.3,"qty":0.0,"timestamp":1618678104869}
1618678104.893076: {"feed":"book","product_id":"FI_ETHUSD_210625","side":"buy","seq":12455242,"price":2485.65,"qty":0.0,"timestamp":1618678104869}
1618678104.895073: {"feed":"book","product_id":"FI_ETHUSD_210625","side":"buy","seq":12455243,"price":2500.85,"qty":227.0,"timestamp":1618678104871}
1618678104.8951528: {"feed":"book","product_id":"FI_ETHUSD_210625","side":"buy","seq":12455244,"price":2500.35,"qty":232.0,"timestamp":1618678104871}
1618678104.9111419: {"feed":"book","product_id":"PI_BCHUSD","side":"buy","seq":16258020,"price":1059.5,"qty":0.0,"timestamp":1618678104887}
1618678104.913555: {"feed":"book","product_id":"PI_BCHUSD","side":"sell","seq":16258021,"price":1062.3,"qty":0.0,"timestamp":1618678104889}
1618678104.916401: {"feed":"book","product_id":"PI_BCHUSD","side":"buy","seq":16258022,"price":1059.1,"qty":893.0,"timestamp":1618678104892}
1618678104.9357271: {"feed":"book","product_id":"PI_BCHUSD","side":"sell","seq":16258023,"price":1062.4,"qty":8768.0,"timestamp":1618678104907}
1618678104.935837: {"feed":"book","product_id":"PI_BCHUSD","side":"buy","seq":16258024,"price":1060.0,"qty":3893.0,"timestamp":1618678104910}
1618678104.935904: {"feed":"book","product_id":"PI_BCHUSD","side":"buy","seq":16258025,"price":1060.0,"qty":7611.0,"timestamp":1618678104910}
1618678104.935945: {"feed":"book","product_id":"FI_ETHUSD_210625","side":"sell","seq":12455245,"price":2507.55,"qty":3000.0,"timestamp":1618678104911}
1618678104.9421859: {"feed":"book","product_id":"PI_BCHUSD","side":"sell","seq":16258026,"price":1063.1,"qty":3931.0,"timestamp":1618678104913}
1618678104.942297: {"feed":"book","product_id":"FI_BCHUSD_210430","side":"buy","seq":1411842,"price":1073.3,"qty":14399.0,"timestamp":1618678104913}
1618678104.9512792: {"feed":"book","product_id":"PI_BCHUSD","side":"sell","seq":16258027,"price":1062.4,"qty":5878.0,"timestamp":1618678104922}
1618678104.9513888: {"feed":"book","product_id":"PI_BCHUSD","side":"sell","seq":16258028,"price":1062.4,"qty":3033.0,"timestamp":1618678104922}
1618678104.951479: {"feed":"book","product_id":"PI_BCHUSD","side":"sell","seq":16258029,"price":1062.4,"qty":0.0,"timestamp":1618678104925}
1618678104.96188: {"feed":"book","product_id":"FI_XBTUSD_210625","side":"buy","seq":21454644,"price":63917.5,"qty":0.0,"timestamp":1618678104938}
1618678104.9620101: {"feed":"book","product_id":"FI_XBTUSD_210625","side":"buy","seq":21454645,"price":63926.0,"qty":2138.0,"timestamp":1618678104938}
1618678104.9788458: {"feed":"book","product_id":"FI_XBTUSD_210625","side":"buy","seq":21454646,"price":57200.5,"qty":30165.0,"timestamp":1618678104956}
1618678104.986893: {"feed":"book","product_id":"FI_XBTUSD_210924","side":"buy","seq":13850714,"price":67899.0,"qty":0.0,"timestamp":1618678104962}
1618678105.015232: {"feed":"book","product_id":"FI_XBTUSD_210625","side":"buy","seq":21454647,"price":63812.0,"qty":0.0,"timestamp":1618678104991}
1618678105.0153222: {"feed":"book","product_id":"FI_XBTUSD_210430","side":"sell","seq":12237427,"price":61960.5,"qty":0.0,"timestamp":1618678104992}
1618678105.015362: {"feed":"book","product_id":"FI_XBTUSD_210430","side":"buy","seq":12237428,"price":60679.5,"qty":0.0,"timestamp":1618678104992}
1618678105.022086: {"feed":"book","product_id":"FI_XBTUSD_210625","side":"buy","seq":21454648,"price":57200.5,"qty":33155.0,"timestamp":1618678104997}
1618678105.034194: {"feed":"book","product_id":"PI_BCHUSD","side":"sell","seq":16258030,"price":1062.4,"qty":2793.0,"timestamp":1618678105005}
1618678105.0425448: {"feed":"book","product_id":"FI_ETHUSD_210924","side":"buy","seq":3859095,"price":2638.15,"qty":0.0,"timestamp":1618678105012}
1618678105.042634: {"feed":"book","product_id":"FI_ETHUSD_210625","side":"buy","seq":12455246,"price":2497.2,"qty":0.0,"timestamp":1618678105017}
1618678105.0426729: {"feed":"book","product_id":"FI_ETHUSD_210625","side":"buy","seq":12455247,"price":2490.15,"qty":0.0,"timestamp":1618678105017}
1618678105.050762: {"feed":"book","product_id":"PI_BCHUSD","side":"sell","seq":16258031,"price":1070.4,"qty":44999.0,"timestamp":1618678105028}
1618678105.119735: {"feed":"book","product_id":"FI_XBTUSD_210625","side":"buy","seq":21454649,"price":57200.5,"qty":30165.0,"timestamp":1618678105089}
1618678105.1198459: {"feed":"book","product_id":"PI_BCHUSD","side":"sell","seq":16258032,"price":1065.8,"qty":0.0,"timestamp":1618678105091}
1618678105.119919: {"feed":"book","product_id":"PI_BCHUSD","side":"sell","seq":16258033,"price":1065.2,"qty":0.0,"timestamp":1618678105091}
1618678105.119967: {"feed":"book","product_id":"PI_BCHUSD","side":"sell","seq":16258034,"price":1064.0,"qty":30809.0,"timestamp":1618678105093}
1618678105.1200042: {"feed":"book","product_id":"PI_BCHUSD","side":"sell","seq":16258035,"price":1062.7,"qty":3564.0,"timestamp":1618678105094}
1618678105.1200378: {"feed":"book","product_id":"PI_BCHUSD","side":"sell","seq":16258036,"price":1064.5,"qty":4050.0,"timestamp":1618678105094}
1618678105.1228101: {"feed":"book","product_id":"PI_BCHUSD","side":"sell","seq":16258037,"price":1063.0,"qty":3814.0,"timestamp":1618678105097}
1618678105.146372: {"feed":"book","product_id":"FI_BCHUSD_210625","side":"buy","seq":2240170,"price":1129.5,"qty":97.0,"timestamp":1618678105120}
1618678105.156661: {"feed":"book","product_id":"FI_BCHUSD_210625","side":"sell","seq":2240171,"price":1147.0,"qty":44999.0,"timestamp":1618678105128}
1618678105.15679: {"feed":"book","product_id":"PI_BCHUSD","side":"sell","seq":16258038,"price":1063.4,"qty":14432.0,"timestamp":1618678105129}
1618678105.156842: {"feed":"book","product_id":"PI_BCHUSD","side":"buy","seq":16258039,"price":1058.8,"qty":5082.0,"timestamp":1618678105130}
1618678105.159452: {"feed":"book","product_id":"FI_XBTUSD_210625","side":"buy","seq":21454650,"price":57200.5,"qty":33200.0,"timestamp":1618678105132}
1618678105.2416708: {"feed":"book","product_id":"FI_XBTUSD_210430","side":"buy","seq":12237429,"price":61156.0,"qty":3003.0,"timestamp":1618678105216}
1618678105.2417989: {"feed":"book","product_id":"FI_XBTUSD_210625","side":"buy","seq":21454651,"price":63871.0,"qty":5903.0,"timestamp":1618678105216}
1618678105.253555: {"feed":"book","product_id":"FI_XBTUSD_210625","side":"buy","seq":21454652,"price":57200.5,"qty":30165.0,"timestamp":1618678105224}
1618678105.253667: {"feed":"book","product_id":"FI_ETHUSD_210924","side":"buy","seq":3859096,"price":2630.75,"qty":13310.0,"timestamp":1618678105224}
1618678105.253716: {"feed":"book","product_id":"FI_ETHUSD_210924","side":"buy","seq":3859097,"price":2643.05,"qty":0.0,"timestamp":1618678105224}
1618678105.3056881: {"feed":"book","product_id":"FI_XBTUSD_210625","side":"buy","seq":21454653,"price":57200.5,"qty":33155.0,"timestamp":1618678105272}
1618678105.3143198: {"feed":"book","product_id":"FI_ETHUSD_210625","side":"buy","seq":12455248,"price":2495.55,"qty":3000.0,"timestamp":1618678105278}
1618678105.3144479: {"feed":"book","product_id":"FI_ETHUSD_210625","side":"buy","seq":12455249,"price":2488.25,"qty":8827.0,"timestamp":1618678105278}
1618678105.3145049: {"feed":"book","product_id":"FI_ETHUSD_210625","side":"buy","seq":12455250,"price":2484.65,"qty":8826.0,"timestamp":1618678105278}
1618678105.316695: {"feed":"book","product_id":"FI_ETHUSD_210625","side":"sell","seq":12455251,"price":2513.65,"qty":11333.0,"timestamp":1618678105292}
1618678105.335449: {"feed":"book","product_id":"FI_XBTUSD_210924","side":"sell","seq":13850715,"price":68307.0,"qty":0.0,"timestamp":1618678105299}
1618678105.335537: {"feed":"book","product_id":"FI_XBTUSD_210924","side":"sell","seq":13850716,"price":68296.0,"qty":50.0,"timestamp":1618678105299}
1618678105.335595: {"feed":"book","product_id":"PI_BCHUSD","side":"sell","seq":16258040,"price":1062.7,"qty":3514.0,"timestamp":1618678105299}
1618678105.335635: {"feed":"book","product_id":"PI_BCHUSD","side":"sell","seq":16258041,"price":1062.4,"qty":2843.0,"timestamp":1618678105299}
1618678105.346252: {"feed":"book","product_id":"FI_ETHUSD_210625","side":"buy","seq":12455252,"price":2486.5,"qty":0.0,"timestamp":1618678105314}
1618678105.3562508: {"feed":"book","product_id":"FI_XBTUSD_210625","side":"buy","seq":21454654,"price":63807.0,"qty":10000.0,"timestamp":1618678105315}
1618678105.356338: {"feed":"book","product_id":"FI_XRPUSD_210625","side":"buy","seq":3631441,"price":1.6955,"qty":0.0,"timestamp":1618678105315}
1618678105.3564: {"feed":"book","product_id":"FI_ETHUSD_210625","side":"buy","seq":12455253,"price":2500.35,"qty":0.0,"timestamp":1618678105322}
1618678105.356451: {"feed":"book","product_id":"FI_ETHUSD_210625","side":"buy","seq":12455254,"price":2500.85,"qty":449.0,"timestamp":1618678105322}
1618678105.356488: {"feed":"book","product_id":"FI_XBTUSD_210924","side":"buy","seq":13850717,"price":52552.5,"qty":59077.0,"timestamp":1618678105323}
1618678105.3565261: {"feed":"book","product_id":"FI_XBTUSD_210924","side":"buy","seq":13850718,"price":67893.5,"qty":3000.0,"timestamp":1618678105324}
1618678105.356566: {"feed":"book","product_id":"FI_XBTUSD_210924","side":"sell","seq":13850719,"price":68297.5,"qty":0.0,"timestamp":1618678105324}
1618678105.37594: {"feed":"book","product_id":"FI_XRPUSD_210625","side":"buy","seq":3631442,"price":1.6941,"qty":50.0,"timestamp":1618678105348}
1618678105.3760269: {"feed":"book","product_id":"FI_XRPUSD_210625","side":"buy","seq":3631443,"price":1.6905,"qty":0.0,"timestamp":1618678105352}
1618678105.4120588: {"feed":"book","product_id":"FI_XBTUSD_210625","side":"buy","seq":21454655,"price":63748.5,"qty":0.0,"timestamp":1618678105387}
1618678105.412191: {"feed":"book","product_id":"FI_XBTUSD_210625","side":"buy","seq":21454656,"price":63746.5,"qty":3251.0,"timestamp":1618678105387}
1618678105.421653: {"feed":"book","product_id":"FI_XBTUSD_210625","side":"buy","seq":21454657,"price":57200.5,"qty":30165.0,"timestamp":1618678105394}
1618678105.4353228: {"feed":"book","product_id":"FI_XRPUSD_210625","side":"buy","seq":3631444,"price":1.6908,"qty":325.0,"timestamp":1618678105411}
1618678105.4691682: {"feed":"book","product_id":"FI_XBTUSD_210625","side":"buy","seq":21454658,"price":57200.5,"qty":33177.0,"timestamp":1618678105444}
1618678105.46928: {"feed":"book","product_id":"PI_BCHUSD","side":"sell","seq":16258042,"price":1062.4,"qty":50.0,"timestamp":1618678105444}
1618678105.469332: {"feed":"book","product_id":"PI_BCHUSD","side":"buy","seq":16258043,"price":1059.3,"qty":22379.0,"timestamp":1618678105444}
1618678105.474002: {"feed":"book","product_id":"FI_ETHUSD_210625","side":"buy","seq":12455255,"price":2496.65,"qty":2000.0,"timestamp":1618678105449}
1618678105.474607: {"feed":"book","product_id":"FI_ETHUSD_210625","side":"sell","seq":12455256,"price":2505.1,"qty":2000.0,"timestamp":1618678105449}
1618678105.4858408: {"feed":"book","product_id":"FI_ETHUSD_210625","side":"sell","seq":12455257,"price":2505.15,"qty":9878.0,"timestamp":1618678105460}
1618678105.4859111: {"feed":"book","product_id":"FI_ETHUSD_210625","side":"sell","seq":12455258,"price":2505.05,"qty":835.0,"timestamp":1618678105460}
1618678105.491083: {"feed":"book","product_id":"PI_BCHUSD","side":"sell","seq":16258044,"price":1062.5,"qty":7953.0,"timestamp":1618678105466}
1618678105.491194: {"feed":"book","product_id":"PI_BCHUSD","side":"sell","seq":16258045,"price":1062.5,"qty":10942.0,"timestamp":1618678105466}
1618678105.496404: {"feed":"book","product_id":"PI_BCHUSD","side":"sell","seq":16258046,"price":1063.4,"qty":3798.0,"timestamp":1618678105473}
1618678105.505027: {"feed":"book","product_id":"PI_BCHUSD","side":"sell","seq":16258047,"price":1062.5,"qty":7953.0,"timestamp":1618678105480}
1618678105.50514: {"feed":"book","product_id":"PI_BCHUSD","side":"sell","seq":16258048,"price":1062.5,"qty":4812.0,"timestamp":1618678105480}
1618678105.5051892: {"feed":"book","product_id":"PI_BCHUSD","side":"buy","seq":16258049,"price":1060.0,"qty":3718.0,"timestamp":1618678105480}
1618678105.505229: {"feed":"book","product_id":"PI_BCHUSD","side":"buy","seq":16258050,"price":1059.3,"qty":0.0,"timestamp":1618678105480}
1618678105.505289: {"feed":"book","product_id":"PI_BCHUSD","side":"sell","seq":16258051,"price":1062.5,"qty":913.0,"timestamp":1618678105480}
1618678105.5053241: {"feed":"book","product_id":"PI_BCHUSD","side":"buy","seq":16258052,"price":1060.0,"qty":0.0,"timestamp":1618678105482}
1618678105.513856: {"feed":"book","product_id":"PI_BCHUSD","side":"sell","seq":16258053,"price":1062.8,"qty":40081.0,"timestamp":1618678105489}
1618678105.5139682: {"feed":"book","product_id":"PI_BCHUSD","side":"sell","seq":16258054,"price":1064.0,"qty":35797.0,"timestamp":1618678105489}
1618678105.5167658: {"feed":"book","product_id":"PI_BCHUSD","side":"buy","seq":16258055,"price":1059.9,"qty":3456.0,"timestamp":1618678105492}
1618678105.516895: {"feed":"book","product_id":"FI_ETHUSD_210625","side":"buy","seq":12455259,"price":2495.55,"qty":0.0,"timestamp":1618678105493}
1618678105.516962: {"feed":"book","product_id":"FI_ETHUSD_210625","side":"buy","seq":12455260,"price":2492.25,"qty":0.0,"timestamp":1618678105493}
1618678105.5434098: {"feed":"book","product_id":"PI_BCHUSD","side":"sell","seq":16258056,"price":1062.8,"qty":23289.0,"timestamp":1618678105516}
1618678105.54352: {"feed":"book","product_id":"PI_BCHUSD","side":"buy","seq":16258057,"price":1058.7,"qty":8508.0,"timestamp":1618678105516}
1618678105.543568: {"feed":"book","product_id":"PI_BCHUSD","side":"sell","seq":16258058,"price":1062.9,"qty":6966.0,"timestamp":1618678105517}
1618678105.543606: {"feed":"book","product_id":"FI_XBTUSD_210924","side":"buy","seq":13850720,"price":52552.5,"qty":59201.0,"timestamp":1618678105517}
1618678105.543642: {"feed":"book","product_id":"PI_BCHUSD","side":"sell","seq":16258059,"price":1062.6,"qty":0.0,"timestamp":1618678105517}
1618678105.5436969: {"feed":"book","product_id":"PI_BCHUSD","side":"buy","seq":16258060,"price":1059.0,"qty":16388.0,"timestamp":1618678105520}
1618678105.54776: {"feed":"book","product_id":"PI_BCHUSD","side":"buy","seq":16258061,"price":1059.8,"qty":0.0,"timestamp":1618678105520}
1618678105.547889: {"feed":"book","product_id":"PI_BCHUSD","side":"buy","seq":16258062,"price":1059.6,"qty":28145.0,"timestamp":1618678105520}
1618678105.547953: {"feed":"book","product_id":"PI_BCHUSD","side":"sell","seq":16258063,"price":1062.8,"qty":981.0,"timestamp":1618678105520}
1618678105.5479941: {"feed":"book","product_id":"PI_BCHUSD","side":"buy","seq":16258064,"price":1059.8,"qty":30788.0,"timestamp":1618678105520}
1618678105.5480452: {"feed":"book","product_id":"PI_BCHUSD","side":"buy","seq":16258065,"price":1058.5,"qty":0.0,"timestamp":1618678105520}
1618678105.5481: {"feed":"book","product_id":"PI_BCHUSD","side":"sell","seq":16258066,"price":1063.4,"qty":26373.0,"timestamp":1618678105522}
1618678105.548123: {"feed":"book","product_id":"PI_BCHUSD","side":"sell","seq":16258067,"price":1064.0,"qty":39723.0,"timestamp":1618678105522}
1618678105.54815: {"feed":"book","product_id":"PI_BCHUSD","side":"buy","seq":16258068,"price":1059.4,"qty":8646.0,"timestamp":1618678105522}
1618678105.548171: {"feed":"book","product_id":"PI_BCHUSD","side":"buy","seq":16258069,"price":1059.6,"qty":32130.0,"timestamp":1618678105522}
1618678105.548191: {"feed":"book","product_id":"PI_BCHUSD","side":"sell","seq":16258070,"price":1063.3,"qty":0.0,"timestamp":1618678105522}
1618678105.548218: {"feed":"book","product_id":"PI_BCHUSD","side":"buy","seq":16258071,"price":1060.1,"qty":3849.0,"timestamp":1618678105522}
1618678105.551906: {"feed":"book","product_id":"PI_BCHUSD","side":"sell","seq":16258072,"price":1063.2,"qty":40555.0,"timestamp":1618678105522}
1618678105.552017: {"feed":"book","product_id":"PI_BCHUSD","side":"sell","seq":16258073,"price":1063.1,"qty":20222.0,"timestamp":1618678105522}
1618678105.552074: {"feed":"book","product_id":"PI_BCHUSD","side":"sell","seq":16258074,"price":1063.6,"qty":12849.0,"timestamp":1618678105522}
1618678105.5521228: {"feed":"book","product_id":"PI_BCHUSD","side":"buy","seq":16258075,"price":1060.4,"qty":4071.0,"timestamp":1618678105523}
1618678105.5554519: {"feed":"book","product_id":"PI_BCHUSD","side":"buy","seq":16258076,"price":1058.7,"qty":2467.0,"timestamp":1618678105529}
1618678105.555561: {"feed":"book","product_id":"PI_BCHUSD","side":"buy","seq":16258077,"price":1058.8,"qty":11123.0,"timestamp":1618678105529}
1618678105.575531: {"feed":"book","product_id":"FI_XRPUSD_210625","side":"buy","seq":3631445,"price":1.694,"qty":0.0,"timestamp":1618678105550}
1618678105.575617: {"feed":"book","product_id":"FI_XRPUSD_210625","side":"buy","seq":3631446,"price":1.6942,"qty":68.0,"timestamp":1618678105550}
1618678105.577964: {"feed":"book","product_id":"FI_XRPUSD_210625","side":"buy","seq":3631447,"price":1.692,"qty":340.0,"timestamp":1618678105554}
1618678105.593707: {"feed":"book","product_id":"FI_XBTUSD_210430","side":"buy","seq":12237430,"price":61168.5,"qty":2985.0,"timestamp":1618678105569}
1618678105.595882: {"feed":"book","product_id":"FI_ETHUSD_210625","side":"buy","seq":12455261,"price":2496.4,"qty":3000.0,"timestamp":1618678105571}
1618678105.5960078: {"feed":"book","product_id":"FI_ETHUSD_210625","side":"buy","seq":12455262,"price":2489.1,"qty":105667.0,"timestamp":1618678105571}
1618678105.596066: {"feed":"book","product_id":"FI_ETHUSD_210625","side":"buy","seq":12455263,"price":2485.45,"qty":105666.0,"timestamp":1618678105571}
1618678105.596579: {"feed":"book","product_id":"PI_BCHUSD","side":"buy","seq":16258078,"price":1059.0,"qty":11373.0,"timestamp":1618678105574}
1618678105.5993679: {"feed":"book","product_id":"PI_BCHUSD","side":"buy","seq":16258079,"price":1058.6,"qty":0.0,"timestamp":1618678105576}
1618678105.599505: {"feed":"book","product_id":"PI_BCHUSD","side":"buy","seq":16258080,"price":1059.4,"qty":3633.0,"timestamp":1618678105576}
1618678105.610118: {"feed":"book","product_id":"PI_BCHUSD","side":"sell","seq":16258081,"price":1062.7,"qty":0.0,"timestamp":1618678105585}
1618678105.615696: {"feed":"book","product_id":"FI_XBTUSD_210625","side":"buy","seq":21454659,"price":63926.0,"qty":1073.0,"timestamp":1618678105591}
1618678105.6158059: {"feed":"book","product_id":"FI_XBTUSD_210625","side":"buy","seq":21454660,"price":63917.5,"qty":1167.0,"timestamp":1618678105591}
1618678105.634048: {"feed":"book","product_id":"FI_ETHUSD_210625","side":"sell","seq":12455264,"price":2513.85,"qty":0.0,"timestamp":1618678105601}
1618678105.634177: {"feed":"book","product_id":"FI_ETHUSD_210625","side":"sell","seq":12455265,"price":2512.85,"qty":31778.0,"timestamp":1618678105601}
1618678105.634239: {"feed":"book","product_id":"FI_ETHUSD_210625","side":"buy","seq":12455266,"price":2492.15,"qty":0.0,"timestamp":1618678105601}
1618678105.634293: {"feed":"book","product_id":"FI_ETHUSD_210625","side":"buy","seq":12455267,"price":2493.15,"qty":644.0,"timestamp":1618678105601}
1618678105.634336: {"feed":"book","product_id":"FI_XRPUSD_210625","side":"buy","seq":3631448,"price":1.6924,"qty":2104.0,"timestamp":1618678105609}
1618678105.6343732: {"feed":"book","product_id":"FI_XRPUSD_210625","side":"buy","seq":3631449,"price":1.6932,"qty":19200.0,"timestamp":1618678105609}
1618678105.643289: {"feed":"book","product_id":"PI_BCHUSD","side":"sell","seq":16258082,"price":1062.5,"qty":0.0,"timestamp":1618678105617}
1618678105.6488059: {"feed":"book","product_id":"PI_BCHUSD","side":"buy","seq":16258083,"price":1060.3,"qty":28892.0,"timestamp":1618678105621}
1618678105.649973: {"feed":"book","product_id":"FI_XBTUSD_210625","side":"buy","seq":21454661,"price":57200.5,"qty":30165.0,"timestamp":1618678105623}
1618678105.667238: {"feed":"book","product_id":"PI_BCHUSD","side":"sell","seq":16258084,"price":1063.2,"qty":35563.0,"timestamp":1618678105643}
1618678105.670388: {"feed":"book","product_id":"PI_BCHUSD","side":"sell","seq":16258085,"price":1063.2,"qty":4923.0,"timestamp":1618678105646}
1618678105.6718872: {"feed":"book","product_id":"PI_BCHUSD","side":"sell","seq":16258086,"price":1063.8,"qty":35630.0,"timestamp":1618678105648}
1618678105.690146: {"feed":"book","product_id":"FI_XRPUSD_210625","side":"sell","seq":3631450,"price":1.6996,"qty":354.0,"timestamp":1618678105665}
1618678105.690258: {"feed":"book","product_id":"FI_XRPUSD_210625","side":"sell","seq":3631451,"price":1.7006,"qty":18968.0,"timestamp":1618678105665}
1618678105.696565: {"feed":"book","product_id":"FI_XBTUSD_210625","side":"buy","seq":21454662,"price":57200.5,"qty":33155.0,"timestamp":1618678105672}
1618678105.698721: {"feed":"book","product_id":"PI_BCHUSD","side":"sell","seq":16258087,"price":1063.1,"qty":23141.0,"timestamp":1618678105675}
1618678105.698833: {"feed":"book","product_id":"PI_BCHUSD","side":"sell","seq":16258088,"price":1063.2,"qty":8478.0,"timestamp":1618678105676}
1618678105.703941: {"feed":"book","product_id":"PI_BCHUSD","side":"sell","seq":16258089,"price":1063.1,"qty":20222.0,"timestamp":1618678105679}
1618678105.706172: {"feed":"book","product_id":"PI_BCHUSD","side":"buy","seq":16258090,"price":1060.2,"qty":3769.0,"timestamp":1618678105681}
1618678105.706296: {"feed":"book","product_id":"PI_BCHUSD","side":"buy","seq":16258091,"price":1059.4,"qty":0.0,"timestamp":1618678105681}
1618678105.711352: {"feed":"book","product_id":"PI_BCHUSD","side":"buy","seq":16258092,"price":1059.9,"qty":0.0,"timestamp":1618678105687}
1618678105.711479: {"feed":"book","product_id":"FI_XRPUSD_210625","side":"sell","seq":3631452,"price":1.6992,"qty":0.0,"timestamp":1618678105687}
1618678105.7115421: {"feed":"book","product_id":"PI_BCHUSD","side":"buy","seq":16258093,"price":1059.7,"qty":0.0,"timestamp":1618678105687}
1618678105.711592: {"feed":"book","product_id":"FI_XRPUSD_210625","side":"sell","seq":3631453,"price":1.6987,"qty":818.0,"timestamp":1618678105687}
1618678105.711634: {"feed":"book","product_id":"FI_XRPUSD_210625","side":"buy","seq":3631454,"price":1.6936,"qty":317.0,"timestamp":1618678105687}
1618678105.713774: {"feed":"book","product_id":"PI_BCHUSD","side":"buy","seq":16258094,"price":1059.9,"qty":3734.0,"timestamp":1618678105690}
1618678105.717671: {"feed":"book","product_id":"PI_BCHUSD","side":"sell","seq":16258095,"price":1063.1,"qty":16291.0,"timestamp":1618678105690}
1618678105.717779: {"feed":"book","product_id":"PI_BCHUSD","side":"sell","seq":16258096,"price":1063.0,"qty":0.0,"timestamp":1618678105690}
1618678105.717865: {"feed":"book","product_id":"PI_BCHUSD","side":"sell","seq":16258097,"price":1063.8,"qty":39283.0,"timestamp":1618678105690}
1618678105.7178922: {"feed":"book","product_id":"PI_BCHUSD","side":"buy","seq":16258098,"price":1060.4,"qty":7648.0,"timestamp":1618678105692}
1618678105.717917: {"feed":"book","product_id":"PI_BCHUSD","side":"sell","seq":16258099,"price":1063.4,"qty":30172.0,"timestamp":1618678105692}
1618678105.72098: {"feed":"book","product_id":"PI_BCHUSD","side":"buy","seq":16258100,"price":1059.0,"qty":7657.0,"timestamp":1618678105692}
1618678105.72109: {"feed":"book","product_id":"FI_XRPUSD_210625","side":"sell","seq":3631455,"price":1.6996,"qty":0.0,"timestamp":1618678105692}
1618678105.732938: {"feed":"book","product_id":"FI_BCHUSD_210625","side":"buy","seq":2240172,"price":1108.3,"qty":0.0,"timestamp":1618678105708}
1618678105.733064: {"feed":"book","product_id":"FI_BCHUSD_210625","side":"buy","seq":2240173,"price":1123.9,"qty":4513.0,"timestamp":1618678105708}
1618678105.766443: {"feed":"book","product_id":"PI_BCHUSD","side":"buy","seq":16258101,"price":1060.3,"qty":51738.0,"timestamp":1618678105742}
1618678105.766606: {"feed":"book","product_id":"PI_BCHUSD","side":"buy","seq":16258102,"price":1060.6,"qty":17486.0,"timestamp":1618678105742}
1618678105.767049: {"feed":"book","product_id":"PI_BCHUSD","side":"sell","seq":16258103,"price":1063.8,"qty":33211.0,"timestamp":1618678105745}
1618678105.772657: {"feed":"book","product_id":"PI_BCHUSD","side":"sell","seq":16258104,"price":1062.8,"qty":0.0,"timestamp":1618678105747}
1618678105.772786: {"feed":"book","product_id":"PI_BCHUSD","side":"sell","seq":16258105,"price":1063.1,"qty":0.0,"timestamp":1618678105747}
1618678105.772844: {"feed":"book","product_id":"PI_BCHUSD","side":"sell","seq":16258106,"price":1064.3,"qty":3908.0,"timestamp":1618678105748}
1618678105.772897: {"feed":"book","product_id":"PI_BCHUSD","side":"sell","seq":16258107,"price":1063.4,"qty":26374.0,"timestamp":1618678105748}
1618678105.772934: {"feed":"book","product_id":"PI_BCHUSD","side":"sell","seq":16258108,"price":1064.1,"qty":33431.0,"timestamp":1618678105749}
1618678105.778789: {"feed":"book","product_id":"FI_ETHUSD_210625","side":"buy","seq":12455268,"price":2495.55,"qty":3000.0,"timestamp":1618678105754}
1618678105.7788758: {"feed":"book","product_id":"FI_ETHUSD_210625","side":"buy","seq":12455269,"price":2491.9,"qty":8827.0,"timestamp":1618678105754}
1618678105.786148: {"feed":"book","product_id":"FI_XRPUSD_210625","side":"buy","seq":3631456,"price":1.6941,"qty":0.0,"timestamp":1618678105758}
1618678105.786209: {"feed":"book","product_id":"FI_XRPUSD_210625","side":"buy","seq":3631457,"price":1.6943,"qty":50.0,"timestamp":1618678105758}
1618678105.791966: {"feed":"book","product_id":"FI_XRPUSD_210625","side":"buy","seq":3631458,"price":1.6942,"qty":0.0,"timestamp":1618678105766}
1618678105.792017: {"feed":"book","product_id":"FI_XRPUSD_210625","side":"buy","seq":3631459,"price":1.6944,"qty":68.0,"timestamp":1618678105766}
1618678105.8098419: {"feed":"book","product_id":"FI_XRPUSD_210625","side":"buy","seq":3631460,"price":1.6943,"qty":0.0,"timestamp":1618678105784}
1618678105.8098938: {"feed":"book","product_id":"FI_XRPUSD_210625","side":"buy","seq":3631461,"price":1.6945,"qty":50.0,"timestamp":1618678105784}
1618678105.816493: {"feed":"book","product_id":"FI_XRPUSD_210625","side":"buy","seq":3631462,"price":1.6944,"qty":0.0,"timestamp":1618678105790}
1618678105.816542: {"feed":"book","product_id":"FI_XRPUSD_210625","side":"buy","seq":3631463,"price":1.6946,"qty":68.0,"timestamp":1618678105790}
1618678105.816577: {"feed":"book","product_id":"FI_XBTUSD_210625","side":"buy","seq":21454663,"price":57200.5,"qty":30165.0,"timestamp":1618678105791}
1618678105.855989: {"feed":"book","product_id":"PI_BCHUSD","side":"sell","seq":16258109,"price":1063.6,"qty":7859.0,"timestamp":1618678105827}
1618678105.8584168: {"feed":"book","product_id":"FI_XBTUSD_210625","side":"buy","seq":21454664,"price":57200.5,"qty":33177.0,"timestamp":1618678105833}
1618678105.863859: {"feed":"book","product_id":"FI_XBTUSD_210430","side":"buy","seq":12237431,"price":60682.5,"qty":500.0,"timestamp":1618678105840}
1618678105.8639228: {"feed":"book","product_id":"FI_XBTUSD_210430","side":"sell","seq":12237432,"price":61960.5,"qty":500.0,"timestamp":1618678105840}
1618678105.9057379: {"feed":"book","product_id":"PI_BCHUSD","side":"sell","seq":16258110,"price":1063.2,"qty":4923.0,"timestamp":1618678105882}
1618678105.909854: {"feed":"book","product_id":"PI_BCHUSD","side":"buy","seq":16258111,"price":1059.3,"qty":29881.0,"timestamp":1618678105883}
1618678105.914241: {"feed":"book","product_id":"PI_BCHUSD","side":"buy","seq":16258112,"price":1058.2,"qty":0.0,"timestamp":1618678105883}
1618678105.9280891: {"feed":"book","product_id":"PI_BCHUSD","side":"buy","seq":16258113,"price":1060.1,"qty":8856.0,"timestamp":1618678105901}
1618678105.9282: {"feed":"book","product_id":"PI_BCHUSD","side":"buy","seq":16258114,"price":1060.5,"qty":5005.0,"timestamp":1618678105901}
1618678105.928267: {"feed":"book","product_id":"PI_BCHUSD","side":"buy","seq":16258115,"price":1059.7,"qty":5009.0,"timestamp":1618678105901}
1618678105.9283142: {"feed":"book","product_id":"PI_BCHUSD","side":"sell","seq":16258116,"price":1064.4,"qty":20581.0,"timestamp":1618678105901}
1618678105.928352: {"feed":"book","product_id":"PI_BCHUSD","side":"sell","seq":16258117,"price":1064.8,"qty":4985.0,"timestamp":1618678105901}
1618678105.934556: {"feed":"book","product_id":"PI_BCHUSD","side":"sell","seq":16258118,"price":1063.3,"qty":2906.0,"timestamp":1618678105906}
1618678105.934675: {"feed":"book","product_id":"PI_BCHUSD","side":"buy","seq":16258119,"price":1061.0,"qty":3712.0,"timestamp":1618678105907}
1618678105.9391282: {"feed":"book","product_id":"PI_BCHUSD","side":"buy","seq":16258120,"price":1061.0,"qty":7490.0,"timestamp":1618678105909}
1618678105.9392362: {"feed":"book","product_id":"FI_XBTUSD_210625","side":"buy","seq":21454665,"price":57200.5,"qty":30165.0,"timestamp":1618678105913}
1618678105.939286: {"feed":"book","product_id":"FI_ETHUSD_210625","side":"buy","seq":12455270,"price":2477.2,"qty":59999.0,"timestamp":1618678105914}
1618678105.9393249: {"feed":"book","product_id":"FI_ETHUSD_210625","side":"buy","seq":12455271,"price":2485.5,"qty":899.0,"timestamp":1618678105914}
1618678105.939379: {"feed":"book","product_id":"FI_ETHUSD_210625","side":"sell","seq":12455272,"price":2512.85,"qty":0.0,"timestamp":1618678105914}
1618678105.939431: {"feed":"book","product_id":"FI_ETHUSD_210625","side":"sell","seq":12455273,"price":2513.85,"qty":33412.0,"timestamp":1618678105914}
1618678105.9724438: {"feed":"book","product_id":"FI_XBTUSD_210625","side":"sell","seq":21454666,"price":64098.0,"qty":250001.0,"timestamp":1618678105947}
1618678105.972556: {"feed":"book","product_id":"FI_XBTUSD_210625","side":"sell","seq":21454667,"price":64097.5,"qty":18827.0,"timestamp":1618678105947}
1618678105.9726222: {"feed":"book","product_id":"FI_XBTUSD_210625","side":"sell","seq":21454668,"price":64261.0,"qty":0.0,"timestamp":1618678105947}
1618678105.972678: {"feed":"book","product_id":"FI_XBTUSD_210625","side":"sell","seq":21454669,"price":64260.0,"qty":56131.0,"timestamp":1618678105947}
1618678105.975052: {"feed":"book","product_id":"FI_XBTUSD_210625","side":"sell","seq":21454670,"price":64069.0,"qty":0.0,"timestamp":1618678105947}
1618678105.975179: {"feed":"book","product_id":"FI_XBTUSD_210625","side":"sell","seq":21454671,"price":64069.0,"qty":13496.0,"timestamp":1618678105947}
1618678105.975256: {"feed":"book","product_id":"FI_XBTUSD_210625","side":"buy","seq":21454672,"price":63926.0,"qty":0.0,"timestamp":1618678105947}
1618678105.975323: {"feed":"book","product_id":"FI_XBTUSD_210625","side":"buy","seq":21454673,"price":63926.0,"qty":1045.0,"timestamp":1618678105947}
1618678105.975391: {"feed":"book","product_id":"FI_XBTUSD_210625","side":"buy","seq":21454674,"price":63853.0,"qty":0.0,"timestamp":1618678105947}
1618678105.975418: {"feed":"book","product_id":"FI_XBTUSD_210625","side":"buy","seq":21454675,"price":63853.0,"qty":2023.0,"timestamp":1618678105947}
1618678105.975444: {"feed":"book","product_id":"FI_XBTUSD_210625","side":"sell","seq":21454676,"price":64143.5,"qty":0.0,"timestamp":1618678105947}
1618678105.975469: {"feed":"book","product_id":"FI_XBTUSD_210625","side":"sell","seq":21454677,"price":64143.5,"qty":30158.0,"timestamp":1618678105947}
1618678105.9754932: {"feed":"book","product_id":"FI_XBTUSD_210625","side":"buy","seq":21454678,"price":63746.5,"qty":0.0,"timestamp":1618678105947}
1618678105.975518: {"feed":"book","product_id":"FI_XBTUSD_210625","side":"buy","seq":21454679,"price":63746.5,"qty":3224.0,"timestamp":1618678105947}
1618678105.9779031: {"feed":"book","product_id":"FI_XBTUSD_210625","side":"buy","seq":21454680,"price":63496.0,"qty":0.0,"timestamp":1618678105947}
1618678105.9779909: {"feed":"book","product_id":"FI_XBTUSD_210625","side":"buy","seq":21454681,"price":63496.0,"qty":4251.0,"timestamp":1618678105947}
1618678105.978032: {"feed":"book","product_id":"FI_XBTUSD_210625","side":"buy","seq":21454682,"price":63917.5,"qty":0.0,"timestamp":1618678105947}
1618678105.978065: {"feed":"book","product_id":"FI_XBTUSD_210625","side":"buy","seq":21454683,"price":63917.5,"qty":1171.0,"timestamp":1618678105947}
1618678105.978092: {"feed":"book","product_id":"FI_XBTUSD_210625","side":"sell","seq":21454684,"price":64516.5,"qty":0.0,"timestamp":1618678105947}
1618678105.9781199: {"feed":"book","product_id":"FI_XBTUSD_210625","side":"sell","seq":21454685,"price":64516.5,"qty":76429.0,"timestamp":1618678105947}
1618678105.984203: {"feed":"book","product_id":"FI_XBTUSD_210625","side":"buy","seq":21454686,"price":57200.5,"qty":33155.0,"timestamp":1618678105961}
1618678106.0024278: {"feed":"book","product_id":"PI_BCHUSD","side":"sell","seq":16258121,"price":1063.2,"qty":3707.0,"timestamp":1618678105977}
1618678106.008961: {"feed":"book","product_id":"PI_BCHUSD","side":"sell","seq":16258122,"price":1063.6,"qty":3994.0,"timestamp":1618678105985}
1618678106.0090702: {"feed":"book","product_id":"PI_BCHUSD","side":"buy","seq":16258123,"price":1058.3,"qty":3923.0,"timestamp":1618678105985}
1618678106.009619: {"feed":"book","product_id":"FI_XBTUSD_210430","side":"sell","seq":12237433,"price":61960.5,"qty":0.0,"timestamp":1618678105986}
1618678106.009681: {"feed":"book","product_id":"FI_XBTUSD_210430","side":"buy","seq":12237434,"price":60682.5,"qty":0.0,"timestamp":1618678105986}
1618678106.01312: {"feed":"book","product_id":"PI_BCHUSD","side":"buy","seq":16258124,"price":1059.5,"qty":4035.0,"timestamp":1618678105988}
1618678106.013213: {"feed":"book","product_id":"PI_BCHUSD","side":"sell","seq":16258125,"price":1064.4,"qty":24398.0,"timestamp":1618678105989}
1618678106.0132449: {"feed":"book","product_id":"PI_BCHUSD","side":"buy","seq":16258126,"price":1058.3,"qty":0.0,"timestamp":1618678105989}
1618678106.01328: {"feed":"book","product_id":"PI_BCHUSD","side":"buy","seq":16258127,"price":1059.4,"qty":3782.0,"timestamp":1618678105990}
1618678106.033441: {"feed":"book","product_id":"PI_BCHUSD","side":"sell","seq":16258128,"price":1063.3,"qty":5896.0,"timestamp":1618678106005}
1618678106.041905: {"feed":"book","product_id":"FI_ETHUSD_210924","side":"buy","seq":3859098,"price":2637.45,"qty":19199.0,"timestamp":1618678106017}
1618678106.04688: {"feed":"book","product_id":"FI_XBTUSD_210625","side":"buy","seq":21454687,"price":57200.5,"qty":30165.0,"timestamp":1618678106020}
1618678106.0500522: {"feed":"book","product_id":"FI_ETHUSD_210430","side":"buy","seq":4780759,"price":2351.85,"qty":99600.0,"timestamp":1618678106025}
1618678106.054385: {"feed":"book","product_id":"PI_BCHUSD","side":"buy","seq":16258129,"price":1059.0,"qty":4053.0,"timestamp":1618678106030}
1618678106.0544279: {"feed":"book","product_id":"PI_BCHUSD","side":"buy","seq":16258130,"price":1060.4,"qty":4071.0,"timestamp":1618678106030}
1618678106.0578408: {"feed":"book","product_id":"PI_BCHUSD","side":"buy","seq":16258131,"price":1059.9,"qty":0.0,"timestamp":1618678106032}
1618678106.0579: {"feed":"book","product_id":"PI_BCHUSD","side":"buy","seq":16258132,"price":1060.1,"qty":12670.0,"timestamp":1618678106032}
1618678106.072293: {"feed":"book","product_id":"PI_BCHUSD","side":"sell","seq":16258133,"price":1068.9,"qty":0.0,"timestamp":1618678106046}
1618678106.072423: {"feed":"book","product_id":"PI_BCHUSD","side":"sell","seq":16258134,"price":1080.3,"qty":97867.0,"timestamp":1618678106046}
1618678106.0724769: {"feed":"book","product_id":"PI_BCHUSD","side":"sell","seq":16258135,"price":1085.0,"qty":0.0,"timestamp":1618678106046}
1618678106.072522: {"feed":"book","product_id":"PI_BCHUSD","side":"sell","seq":16258136,"price":1101.0,"qty":0.0,"timestamp":1618678106046}
1618678106.072564: {"feed":"book","product_id":"PI_BCHUSD","side":"buy","seq":16258137,"price":1056.0,"qty":0.0,"timestamp":1618678106046}
1618678106.0726058: {"feed":"book","product_id":"PI_BCHUSD","side":"buy","seq":16258138,"price":1048.1,"qty":253242.0,"timestamp":1618678106046}
1618678106.072642: {"feed":"book","product_id":"PI_BCHUSD","side":"buy","seq":16258139,"price":1034.0,"qty":100.0,"timestamp":1618678106046}
1618678106.072674: {"feed":"book","product_id":"PI_BCHUSD","side":"buy","seq":16258140,"price":1021.1,"qty":25415.0,"timestamp":1618678106046}
1618678106.072705: {"feed":"book","product_id":"FI_XRPUSD_210625","side":"sell","seq":3631464,"price":1.7005,"qty":0.0,"timestamp":1618678106048}
1618678106.0794182: {"feed":"book","product_id":"PI_BCHUSD","side":"sell","seq":16258141,"price":1068.9,"qty":14641.0,"timestamp":1618678106056}
1618678106.086435: {"feed":"book","product_id":"PI_BCHUSD","side":"sell","seq":16258142,"price":1080.3,"qty":112508.0,"timestamp":1618678106056}
1618678106.0865479: {"feed":"book","product_id":"PI_BCHUSD","side":"sell","seq":16258143,"price":1094.0,"qty":39081.0,"timestamp":1618678106056}
1618678106.086596: {"feed":"book","product_id":"PI_BCHUSD","side":"sell","seq":16258144,"price":1100.5,"qty":14641.0,"timestamp":1618678106056}
1618678106.086674: {"feed":"book","product_id":"PI_BCHUSD","side":"buy","seq":16258145,"price":1056.0,"qty":14641.0,"timestamp":1618678106057}
1618678106.086719: {"feed":"book","product_id":"PI_BCHUSD","side":"buy","seq":16258146,"price":1048.1,"qty":267883.0,"timestamp":1618678106057}
1618678106.086754: {"feed":"book","product_id":"PI_BCHUSD","side":"buy","seq":16258147,"price":1034.0,"qty":14741.0,"timestamp":1618678106057}
1618678106.0868108: {"feed":"book","product_id":"PI_BCHUSD","side":"buy","seq":16258148,"price":1029.8,"qty":14641.0,"timestamp":1618678106057}
1618678106.092048: {"feed":"book","product_id":"FI_XBTUSD_210625","side":"buy","seq":21454688,"price":57200.5,"qty":33177.0,"timestamp":1618678106065}
1618678106.0997171: {"feed":"book","product_id":"FI_ETHUSD_210924","side":"buy","seq":3859099,"price":2643.5,"qty":2000.0,"timestamp":1618678106071}
1618678106.0998468: {"feed":"book","product_id":"FI_ETHUSD_210924","side":"sell","seq":3859100,"price":2661.25,"qty":2000.0,"timestamp":1618678106072}
1618678106.1036859: {"feed":"book","product_id":"FI_ETHUSD_210625","side":"sell","seq":12455274,"price":2505.1,"qty":0.0,"timestamp":1618678106080}
1618678106.106633: {"feed":"book","product_id":"PI_BCHUSD","side":"sell","seq":16258149,"price":1063.3,"qty":2990.0,"timestamp":1618678106083}
1618678106.106745: {"feed":"book","product_id":"PI_BCHUSD","side":"sell","seq":16258150,"price":1063.3,"qty":0.0,"timestamp":1618678106083}
1618678106.113316: {"feed":"book","product_id":"FI_XBTUSD_210625","side":"sell","seq":21454689,"price":64098.0,"qty":0.0,"timestamp":1618678106084}
1618678106.113448: {"feed":"book","product_id":"FI_XBTUSD_210625","side":"sell","seq":21454690,"price":64097.0,"qty":250001.0,"timestamp":1618678106084}
1618678106.113514: {"feed":"book","product_id":"PI_BCHUSD","side":"sell","seq":16258151,"price":1063.2,"qty":0.0,"timestamp":1618678106085}
1618678106.113568: {"feed":"book","product_id":"FI_ETHUSD_210625","side":"sell","seq":12455275,"price":2512.9,"qty":0.0,"timestamp":1618678106085}
1618678106.1136131: {"feed":"book","product_id":"FI_ETHUSD_210625","side":"sell","seq":12455276,"price":2513.4,"qty":303574.0,"timestamp":1618678106085}
1618678106.113693: {"feed":"book","product_id":"FI_ETHUSD_210430","side":"sell","seq":4780760,"price":2395.8,"qty":0.0,"timestamp":1618678106085}
1618678106.113722: {"feed":"book","product_id":"FI_ETHUSD_210430","side":"sell","seq":4780761,"price":2396.4,"qty":225001.0,"timestamp":1618678106085}
1618678106.116659: {"feed":"book","product_id":"PI_BCHUSD","side":"sell","seq":16258152,"price":1063.5,"qty":3572.0,"timestamp":1618678106093}
1618678106.140279: {"feed":"book","product_id":"PI_BCHUSD","side":"buy","seq":16258153,"price":1057.0,"qty":0.0,"timestamp":1618678106113}
1618678106.140409: {"feed":"book","product_id":"PI_BCHUSD","side":"buy","seq":16258154,"price":1058.6,"qty":4937.0,"timestamp":1618678106113}
1618678106.1404722: {"feed":"book","product_id":"FI_BCHUSD_210430","side":"buy","seq":1411843,"price":1068.2,"qty":14770.0,"timestamp":1618678106113}
1618678106.140515: {"feed":"book","product_id":"FI_BCHUSD_210430","side":"buy","seq":1411844,"price":1070.4,"qty":4590.0,"timestamp":1618678106113}
1618678106.1484952: {"feed":"book","product_id":"PI_BCHUSD","side":"sell","seq":16258155,"price":1063.4,"qty":3799.0,"timestamp":1618678106118}
1618678106.148611: {"feed":"book","product_id":"PI_BCHUSD","side":"buy","seq":16258156,"price":1060.6,"qty":0.0,"timestamp":1618678106118}
1618678106.1486819: {"feed":"book","product_id":"PI_BCHUSD","side":"buy","seq":16258157,"price":1060.4,"qty":50.0,"timestamp":1618678106122}
1618678106.149454: {"feed":"book","product_id":"FI_XBTUSD_210625","side":"buy","seq":21454691,"price":57200.5,"qty":30165.0,"timestamp":1618678106127}
1618678106.154442: {"feed":"book","product_id":"PI_BCHUSD","side":"sell","seq":16258158,"price":1062.4,"qty":0.0,"timestamp":1618678106127}
1618678106.154531: {"feed":"book","product_id":"FI_ETHUSD_210924","side":"sell","seq":3859101,"price":2661.25,"qty":0.0,"timestamp":1618678106128}
1618678106.162464: {"feed":"book","product_id":"PI_BCHUSD","side":"sell","seq":16258159,"price":1064.1,"qty":27359.0,"timestamp":1618678106139}
1618678106.1677482: {"feed":"book","product_id":"FI_ETHUSD_210625","side":"sell","seq":12455277,"price":2515.9,"qty":0.0,"timestamp":1618678106143}
1618678106.167878: {"feed":"book","product_id":"FI_ETHUSD_210625","side":"sell","seq":12455278,"price":2516.55,"qty":25003.0,"timestamp":1618678106143}
1618678106.175831: {"feed":"book","product_id":"PI_BCHUSD","side":"sell","seq":16258160,"price":1063.6,"qty":0.0,"timestamp":1618678106152}
1618678106.175958: {"feed":"book","product_id":"PI_BCHUSD","side":"buy","seq":16258161,"price":1057.8,"qty":0.0,"timestamp":1618678106152}
1618678106.176019: {"feed":"book","product_id":"PI_BCHUSD","side":"buy","seq":16258162,"price":1059.2,"qty":4068.0,"timestamp":1618678106154}
1618678106.182272: {"feed":"book","product_id":"FI_ETHUSD_210430","side":"buy","seq":4780762,"price":2351.85,"qty":0.0,"timestamp":1618678106158}
1618678106.201503: {"feed":"book","product_id":"FI_XBTUSD_210625","side":"buy","seq":21454692,"price":57200.5,"qty":33155.0,"timestamp":1618678106174}
1618678106.207375: {"feed":"book","product_id":"PI_BCHUSD","side":"buy","seq":16258163,"price":1057.9,"qty":0.0,"timestamp":1618678106181}
1618678106.207508: {"feed":"book","product_id":"PI_BCHUSD","side":"buy","seq":16258164,"price":1059.8,"qty":0.0,"timestamp":1618678106181}
1618678106.207566: {"feed":"book","product_id":"PI_BCHUSD","side":"sell","seq":16258165,"price":1064.1,"qty":0.0,"timestamp":1618678106182}
1618678106.207615: {"feed":"book","product_id":"PI_BCHUSD","side":"sell","seq":16258166,"price":1063.8,"qty":3653.0,"timestamp":1618678106182}
1618678106.207655: {"feed":"book","product_id":"PI_BCHUSD","side":"sell","seq":16258167,"price":1065.2,"qty":31724.0,"timestamp":1618678106183}
1618678106.208139: {"feed":"book","product_id":"PI_BCHUSD","side":"buy","seq":16258168,"price":1060.3,"qty":28892.0,"timestamp":1618678106184}
1618678106.208204: {"feed":"book","product_id":"PI_BCHUSD","side":"sell","seq":16258169,"price":1064.7,"qty":59383.0,"timestamp":1618678106184}
1618678106.208244: {"feed":"book","product_id":"PI_BCHUSD","side":"buy","seq":16258170,"price":1059.3,"qty":59610.0,"timestamp":1618678106184}
1618678106.2082791: {"feed":"book","product_id":"PI_BCHUSD","side":"buy","seq":16258171,"price":1061.0,"qty":3712.0,"timestamp":1618678106185}
1618678106.216624: {"feed":"book","product_id":"PI_BCHUSD","side":"buy","seq":16258172,"price":1060.1,"qty":8821.0,"timestamp":1618678106187}
1618678106.2167811: {"feed":"book","product_id":"PI_BCHUSD","side":"buy","seq":16258173,"price":1061.0,"qty":0.0,"timestamp":1618678106187}
1618678106.2168472: {"feed":"book","product_id":"PI_BCHUSD","side":"sell","seq":16258174,"price":1064.6,"qty":0.0,"timestamp":1618678106187}
1618678106.222122: {"feed":"book","product_id":"PI_BCHUSD","side":"sell","seq":16258175,"price":1066.0,"qty":3808.0,"timestamp":1618678106187}
1618678106.222247: {"feed":"book","product_id":"PI_BCHUSD","side":"sell","seq":16258176,"price":1064.0,"qty":35797.0,"timestamp":1618678106187}
1618678106.2222981: {"feed":"book","product_id":"PI_BCHUSD","side":"buy","seq":16258177,"price":1058.8,"qty":5082.0,"timestamp":1618678106190}
1618678106.22234: {"feed":"book","product_id":"PI_BCHUSD","side":"buy","seq":16258178,"price":1059.3,"qty":65651.0,"timestamp":1618678106190}
1618678106.222375: {"feed":"book","product_id":"PI_BCHUSD","side":"sell","seq":16258179,"price":1064.0,"qty":8719.0,"timestamp":1618678106190}
1618678106.2350552: {"feed":"book","product_id":"PI_BCHUSD","side":"buy","seq":16258180,"price":1059.3,"qty":59610.0,"timestamp":1618678106201}
1618678106.2351649: {"feed":"book","product_id":"PI_BCHUSD","side":"buy","seq":16258181,"price":1060.4,"qty":136.0,"timestamp":1618678106204}
1618678106.2425091: {"feed":"book","product_id":"PI_BCHUSD","side":"buy","seq":16258182,"price":1059.6,"qty":3985.0,"timestamp":1618678106204}
1618678106.243103: {"feed":"book","product_id":"FI_XBTUSD_210625","side":"sell","seq":21454693,"price":63960.0,"qty":0.0,"timestamp":1618678106217}
1618678106.26546: {"feed":"book","product_id":"FI_ETHUSD_210625","side":"buy","seq":12455279,"price":2485.5,"qty":0.0,"timestamp":1618678106225}
1618678106.265549: {"feed":"book","product_id":"FI_ETHUSD_210625","side":"buy","seq":12455280,"price":2477.25,"qty":915.0,"timestamp":1618678106225}
1618678106.2655911: {"feed":"book","product_id":"FI_ETHUSD_210625","side":"buy","seq":12455281,"price":2500.85,"qty":227.0,"timestamp":1618678106225}
1618678106.2656178: {"feed":"book","product_id":"FI_ETHUSD_210625","side":"buy","seq":12455282,"price":2500.35,"qty":237.0,"timestamp":1618678106225}
1618678106.265644: {"feed":"book","product_id":"PI_BCHUSD","side":"buy","seq":16258183,"price":1059.1,"qty":6936.0,"timestamp":1618678106232}
1618678106.265667: {"feed":"book","product_id":"FI_ETHUSD_210625","side":"buy","seq":12455283,"price":2496.65,"qty":0.0,"timestamp":1618678106226}
1618678106.265695: {"feed":"book","product_id":"FI_XBTUSD_210924","side":"sell","seq":13850721,"price":68297.0,"qty":0.0,"timestamp":1618678106225}
1618678106.270444: {"feed":"book","product_id":"FI_XBTUSD_210625","side":"buy","seq":21454694,"price":57200.5,"qty":30165.0,"timestamp":1618678106242}
1618678106.3403242: {"feed":"book","product_id":"PI_BCHUSD","side":"sell","seq":16258184,"price":1068.9,"qty":0.0,"timestamp":1618678106313}
1618678106.340451: {"feed":"book","product_id":"PI_BCHUSD","side":"sell","seq":16258185,"price":1080.3,"qty":97867.0,"timestamp":1618678106313}
1618678106.3405042: {"feed":"book","product_id":"PI_BCHUSD","side":"sell","seq":16258186,"price":1094.0,"qty":24440.0,"timestamp":1618678106313}
1618678106.340543: {"feed":"book","product_id":"PI_BCHUSD","side":"sell","seq":16258187,"price":1100.5,"qty":0.0,"timestamp":1618678106313}
1618678106.340588: {"feed":"book","product_id":"PI_BCHUSD","side":"buy","seq":16258188,"price":1056.0,"qty":0.0,"timestamp":1618678106313}
1618678106.346955: {"feed":"book","product_id":"PI_BCHUSD","side":"buy","seq":16258189,"price":1048.1,"qty":253242.0,"timestamp":1618678106313}
1618678106.347064: {"feed":"book","product_id":"PI_BCHUSD","side":"buy","seq":16258190,"price":1034.0,"qty":100.0,"timestamp":1618678106313}
1618678106.3657138: {"feed":"book","product_id":"PI_BCHUSD","side":"buy","seq":16258191,"price":1029.8,"qty":0.0,"timestamp":1618678106326}
1618678106.3658361: {"feed":"book","product_id":"PI_BCHUSD","side":"sell","seq":16258192,"price":1062.8,"qty":50.0,"timestamp":1618678106326}
1618678106.365876: {"feed":"book","product_id":"PI_BCHUSD","side":"sell","seq":16258193,"price":1064.5,"qty":0.0,"timestamp":1618678106326}
1618678106.365907: {"feed":"book","product_id":"FI_ETHUSD_210924","side":"sell","seq":3859102,"price":2659.95,"qty":890.0,"timestamp":1618678106327}
1618678106.365932: {"feed":"book","product_id":"FI_XBTUSD_210924","side":"sell","seq":13850722,"price":68296.5,"qty":0.0,"timestamp":1618678106326}
1618678106.365962: {"feed":"book","product_id":"FI_XBTUSD_210924","side":"sell","seq":13850723,"price":68312.0,"qty":10000.0,"timestamp":1618678106326}
1618678106.3659892: {"feed":"book","product_id":"PI_BCHUSD","side":"sell","seq":16258194,"price":1063.4,"qty":0.0,"timestamp":1618678106326}
1618678106.366014: {"feed":"book","product_id":"PI_BCHUSD","side":"buy","seq":16258195,"price":1059.4,"qty":0.0,"timestamp":1618678106326}
1618678106.366039: {"feed":"book","product_id":"FI_XBTUSD_210430","side":"sell","seq":12237435,"price":61253.5,"qty":1904.0,"timestamp":1618678106326}
1618678106.366061: {"feed":"book","product_id":"PI_BCHUSD","side":"sell","seq":16258196,"price":1063.5,"qty":0.0,"timestamp":1618678106326}
1618678106.366085: {"feed":"book","product_id":"PI_BCHUSD","side":"sell","seq":16258197,"price":1063.8,"qty":0.0,"timestamp":1618678106326}
1618678106.366107: {"feed":"book","product_id":"PI_BCHUSD","side":"sell","seq":16258198,"price":1066.0,"qty":7752.0,"timestamp":1618678106326}
1618678106.3661282: {"feed":"book","product_id":"PI_BCHUSD","side":"sell","seq":16258199,"price":1065.2,"qty":35626.0,"timestamp":1618678106326}
1618678106.366148: {"feed":"book","product_id":"PI_BCHUSD","side":"sell","seq":16258200,"price":1064.0,"qty":4988.0,"timestamp":1618678106327}
1618678106.366167: {"feed":"book","product_id":"FI_XBTUSD_210625","side":"buy","seq":21454695,"price":57200.5,"qty":33177.0,"timestamp":1618678106326}
1618678106.366187: {"feed":"book","product_id":"FI_XBTUSD_210625","side":"sell","seq":21454696,"price":64260.0,"qty":0.0,"timestamp":1618678106327}
1618678106.366213: {"feed":"book","product_id":"FI_XBTUSD_210625","side":"sell","seq":21454697,"price":64255.5,"qty":55929.0,"timestamp":1618678106327}
1618678106.366237: {"feed":"book","product_id":"FI_XBTUSD_210625","side":"sell","seq":21454698,"price":64069.0,"qty":0.0,"timestamp":1618678106327}
1618678106.366261: {"feed":"book","product_id":"FI_XBTUSD_210625","side":"sell","seq":21454699,"price":64068.5,"qty":13829.0,"timestamp":1618678106327}
1618678106.366283: {"feed":"book","product_id":"FI_XBTUSD_210625","side":"sell","seq":21454700,"price":64143.5,"qty":0.0,"timestamp":1618678106327}
1618678106.366307: {"feed":"book","product_id":"FI_XBTUSD_210625","side":"sell","seq":21454701,"price":64143.0,"qty":30568.0,"timestamp":1618678106327}
1618678106.3663301: {"feed":"book","product_id":"FI_XBTUSD_210625","side":"sell","seq":21454702,"price":64097.5,"qty":0.0,"timestamp":1618678106327}
1618678106.366354: {"feed":"book","product_id":"FI_XBTUSD_210625","side":"sell","seq":21454703,"price":64097.5,"qty":19436.0,"timestamp":1618678106327}
1618678106.366376: {"feed":"book","product_id":"FI_XBTUSD_210625","side":"buy","seq":21454704,"price":63917.5,"qty":0.0,"timestamp":1618678106327}
1618678106.3664021: {"feed":"book","product_id":"FI_XBTUSD_210625","side":"buy","seq":21454705,"price":63917.5,"qty":1146.0,"timestamp":1618678106327}
1618678106.366425: {"feed":"book","product_id":"FI_XBTUSD_210625","side":"buy","seq":21454706,"price":63926.0,"qty":0.0,"timestamp":1618678106327}
1618678106.3664489: {"feed":"book","product_id":"FI_XBTUSD_210625","side":"buy","seq":21454707,"price":63926.0,"qty":1030.0,"timestamp":1618678106327}
1618678106.366472: {"feed":"book","product_id":"FI_XBTUSD_210625","side":"buy","seq":21454708,"price":63496.0,"qty":0.0,"timestamp":1618678106327}
1618678106.366496: {"feed":"book","product_id":"FI_XBTUSD_210625","side":"buy","seq":21454709,"price":63496.0,"qty":4287.0,"timestamp":1618678106327}
1618678106.366519: {"feed":"book","product_id":"FI_XBTUSD_210625","side":"buy","seq":21454710,"price":63853.0,"qty":0.0,"timestamp":1618678106327}
1618678106.366542: {"feed":"book","product_id":"FI_XBTUSD_210625","side":"buy","seq":21454711,"price":63853.0,"qty":2011.0,"timestamp":1618678106327}
1618678106.3665652: {"feed":"book","product_id":"FI_XBTUSD_210625","side":"buy","seq":21454712,"price":63746.5,"qty":0.0,"timestamp":1618678106327}
1618678106.3665888: {"feed":"book","product_id":"FI_XBTUSD_210625","side":"buy","seq":21454713,"price":63746.5,"qty":3239.0,"timestamp":1618678106327}
1618678106.368157: {"feed":"book","product_id":"FI_XBTUSD_210625","side":"sell","seq":21454714,"price":64516.5,"qty":0.0,"timestamp":1618678106327}
1618678106.368247: {"feed":"book","product_id":"FI_XBTUSD_210625","side":"sell","seq":21454715,"price":64516.5,"qty":76426.0,"timestamp":1618678106327}
1618678106.368288: {"feed":"book","product_id":"FI_ETHUSD_210625","side":"buy","seq":12455284,"price":2496.4,"qty":0.0,"timestamp":1618678106334}
1618678106.372892: {"feed":"book","product_id":"PI_BCHUSD","side":"buy","seq":16258201,"price":1059.1,"qty":893.0,"timestamp":1618678106342}
1618678106.373003: {"feed":"book","product_id":"FI_XBTUSD_210924","side":"sell","seq":13850724,"price":68406.0,"qty":0.0,"timestamp":1618678106342}
1618678106.380055: {"feed":"book","product_id":"FI_ETHUSD_210625","side":"sell","seq":12455285,"price":2516.55,"qty":0.0,"timestamp":1618678106354}
1618678106.380188: {"feed":"book","product_id":"FI_ETHUSD_210625","side":"sell","seq":12455286,"price":2515.9,"qty":25003.0,"timestamp":1618678106354}
1618678106.433048: {"feed":"book","product_id":"FI_XBTUSD_210924","side":"sell","seq":13850725,"price":68405.5,"qty":0.0,"timestamp":1618678106393}
1618678106.4331799: {"feed":"book","product_id":"FI_XBTUSD_210924","side":"sell","seq":13850726,"price":68410.5,"qty":250001.0,"timestamp":1618678106393}
1618678106.433245: {"feed":"book","product_id":"FI_XBTUSD_210625","side":"buy","seq":21454716,"price":57200.5,"qty":30165.0,"timestamp":1618678106397}
1618678106.4332879: {"feed":"book","product_id":"PI_BCHUSD","side":"buy","seq":16258202,"price":1060.5,"qty":5091.0,"timestamp":1618678106401}
1618678106.4427211: {"feed":"book","product_id":"FI_ETHUSD_210625","side":"sell","seq":12455287,"price":2515.9,"qty":0.0,"timestamp":1618678106409}
1618678106.4428532: {"feed":"book","product_id":"FI_ETHUSD_210625","side":"sell","seq":12455288,"price":2516.25,"qty":25003.0,"timestamp":1618678106409}
1618678106.4546208: {"feed":"book","product_id":"FI_ETHUSD_210625","side":"buy","seq":12455289,"price":2500.35,"qty":0.0,"timestamp":1618678106429}
1618678106.454751: {"feed":"book","product_id":"FI_ETHUSD_210625","side":"buy","seq":12455290,"price":2500.85,"qty":443.0,"timestamp":1618678106429}
1618678106.471979: {"feed":"book","product_id":"FI_XBTUSD_210625","side":"buy","seq":21454717,"price":57200.5,"qty":33155.0,"timestamp":1618678106447}
1618678106.490098: {"feed":"book","product_id":"PI_BCHUSD","side":"sell","seq":16258203,"price":1063.6,"qty":2810.0,"timestamp":1618678106466}
1618678106.4902248: {"feed":"book","product_id":"PI_BCHUSD","side":"sell","seq":16258204,"price":1063.6,"qty":5823.0,"timestamp":1618678106466}
1618678106.51432: {"feed":"book","product_id":"FI_ETHUSD_210430","side":"sell","seq":4780763,"price":2391.55,"qty":50.0,"timestamp":1618678106485}
1618678106.517386: {"feed":"book","product_id":"PI_BCHUSD","side":"buy","seq":16258205,"price":1061.2,"qty":3798.0,"timestamp":1618678106492}
1618678106.54708: {"feed":"book","product_id":"PI_BCHUSD","side":"sell","seq":16258206,"price":1063.5,"qty":17188.0,"timestamp":1618678106517}
1618678106.547214: {"feed":"book","product_id":"PI_BCHUSD","side":"buy","seq":16258207,"price":1059.8,"qty":29135.0,"timestamp":1618678106517}
1618678106.547252: {"feed":"book","product_id":"PI_BCHUSD","side":"buy","seq":16258208,"price":1060.1,"qty":40913.0,"timestamp":1618678106518}
1618678106.5472782: {"feed":"book","product_id":"PI_BCHUSD","side":"sell","seq":16258209,"price":1063.7,"qty":50097.0,"timestamp":1618678106518}
1618678106.547301: {"feed":"book","product_id":"PI_BCHUSD","side":"sell","seq":16258210,"price":1063.8,"qty":3745.0,"timestamp":1618678106518}
1618678106.5473258: {"feed":"book","product_id":"PI_BCHUSD","side":"sell","seq":16258211,"price":1064.6,"qty":3672.0,"timestamp":1618678106519}
1618678106.54735: {"feed":"book","product_id":"PI_BCHUSD","side":"buy","seq":16258212,"price":1060.3,"qty":32743.0,"timestamp":1618678106520}
1618678106.547371: {"feed":"book","product_id":"PI_BCHUSD","side":"sell","seq":16258213,"price":1064.2,"qty":11549.0,"timestamp":1618678106522}
1618678106.54739: {"feed":"book","product_id":"FI_XBTUSD_210625","side":"buy","seq":21454718,"price":57200.5,"qty":30165.0,"timestamp":1618678106522}
1618678106.549929: {"feed":"book","product_id":"PI_BCHUSD","side":"buy","seq":16258214,"price":1060.7,"qty":3957.0,"timestamp":1618678106524}
1618678106.5651278: {"feed":"book","product_id":"FI_ETHUSD_210430","side":"buy","seq":4780764,"price":2351.6,"qty":99600.0,"timestamp":1618678106541}
1618678106.594334: {"feed":"book","product_id":"FI_XBTUSD_210625","side":"buy","seq":21454719,"price":57200.5,"qty":33185.0,"timestamp":1618678106570}
1618678106.6138911: {"feed":"book","product_id":"PI_BCHUSD","side":"buy","seq":16258215,"price":1061.2,"qty":0.0,"timestamp":1618678106589}
1618678106.622091: {"feed":"book","product_id":"PI_BCHUSD","side":"buy","seq":16258216,"price":1060.6,"qty":86.0,"timestamp":1618678106598}
1618678106.622216: {"feed":"book","product_id":"PI_BCHUSD","side":"buy","seq":16258217,"price":1060.3,"qty":32657.0,"timestamp":1618678106598}
1618678106.6588302: {"feed":"book","product_id":"FI_ETHUSD_210625","side":"buy","seq":12455291,"price":2500.85,"qty":227.0,"timestamp":1618678106634}
1618678106.658946: {"feed":"book","product_id":"FI_ETHUSD_210625","side":"buy","seq":12455292,"price":2500.35,"qty":237.0,"timestamp":1618678106634}
1618678106.661798: {"feed":"book","product_id":"FI_XBTUSD_210430","side":"buy","seq":12237436,"price":60682.5,"qty":500.0,"timestamp":1618678106638}
1618678106.6862001: {"feed":"book","product_id":"FI_XBTUSD_210430","side":"sell","seq":12237437,"price":61960.5,"qty":500.0,"timestamp":1618678106639}
1618678106.686294: {"feed":"book","product_id":"FI_XBTUSD_210625","side":"sell","seq":21454720,"price":64068.5,"qty":0.0,"timestamp":1618678106640}
1618678106.6863391: {"feed":"book","product_id":"FI_XBTUSD_210625","side":"sell","seq":21454721,"price":64069.0,"qty":14581.0,"timestamp":1618678106640}
1618678106.686369: {"feed":"book","product_id":"FI_XBTUSD_210625","side":"sell","seq":21454722,"price":64097.5,"qty":0.0,"timestamp":1618678106640}
1618678106.686396: {"feed":"book","product_id":"FI_XBTUSD_210625","side":"sell","seq":21454723,"price":64096.5,"qty":20115.0,"timestamp":1618678106640}
1618678106.686429: {"feed":"book","product_id":"FI_XBTUSD_210625","side":"sell","seq":21454724,"price":64143.0,"qty":0.0,"timestamp":1618678106641}
1618678106.686454: {"feed":"book","product_id":"FI_XBTUSD_210625","side":"sell","seq":21454725,"price":64143.5,"qty":31491.0,"timestamp":1618678106641}
1618678106.686477: {"feed":"book","product_id":"FI_XBTUSD_210625","side":"sell","seq":21454726,"price":64255.5,"qty":0.0,"timestamp":1618678106641}
1618678106.686501: {"feed":"book","product_id":"FI_XBTUSD_210625","side":"sell","seq":21454727,"price":64254.0,"qty":56118.0,"timestamp":1618678106641}
1618678106.686524: {"feed":"book","product_id":"FI_XBTUSD_210625","side":"buy","seq":21454728,"price":63917.5,"qty":0.0,"timestamp":1618678106641}
1618678106.68655: {"feed":"book","product_id":"FI_XBTUSD_210625","side":"buy","seq":21454729,"price":63917.5,"qty":1107.0,"timestamp":1618678106641}
1618678106.686574: {"feed":"book","product_id":"FI_XBTUSD_210625","side":"buy","seq":21454730,"price":63926.0,"qty":0.0,"timestamp":1618678106641}
1618678106.686597: {"feed":"book","product_id":"FI_XBTUSD_210625","side":"buy","seq":21454731,"price":63926.0,"qty":1006.0,"timestamp":1618678106641}
1618678106.6866188: {"feed":"book","product_id":"FI_XBTUSD_210625","side":"buy","seq":21454732,"price":63496.0,"qty":0.0,"timestamp":1618678106641}
1618678106.686643: {"feed":"book","product_id":"FI_XBTUSD_210625","side":"buy","seq":21454733,"price":63496.0,"qty":4344.0,"timestamp":1618678106641}
1618678106.686665: {"feed":"book","product_id":"FI_XBTUSD_210625","side":"buy","seq":21454734,"price":63853.0,"qty":0.0,"timestamp":1618678106641}
1618678106.686688: {"feed":"book","product_id":"FI_XBTUSD_210625","side":"buy","seq":21454735,"price":63853.0,"qty":1991.0,"timestamp":1618678106641}
1618678106.686711: {"feed":"book","product_id":"FI_XBTUSD_210625","side":"buy","seq":21454736,"price":63746.5,"qty":0.0,"timestamp":1618678106641}
1618678106.686733: {"feed":"book","product_id":"FI_XBTUSD_210625","side":"buy","seq":21454737,"price":63746.5,"qty":3264.0,"timestamp":1618678106641}
1618678106.6867561: {"feed":"book","product_id":"FI_XBTUSD_210625","side":"sell","seq":21454738,"price":64516.5,"qty":0.0,"timestamp":1618678106641}
1618678106.68678: {"feed":"book","product_id":"FI_XBTUSD_210625","side":"sell","seq":21454739,"price":64516.5,"qty":76422.0,"timestamp":1618678106641}
1618678106.686802: {"feed":"book","product_id":"FI_XBTUSD_210625","side":"buy","seq":21454740,"price":57200.5,"qty":30165.0,"timestamp":1618678106644}
1618678106.686822: {"feed":"book","product_id":"PI_BCHUSD","side":"sell","seq":16258218,"price":1064.1,"qty":31166.0,"timestamp":1618678106646}
1618678106.686848: {"feed":"book","product_id":"PI_BCHUSD","side":"buy","seq":16258219,"price":1060.6,"qty":0.0,"timestamp":1618678106651}
1618678106.693685: {"feed":"book","product_id":"FI_BCHUSD_210430","side":"sell","seq":1411845,"price":1079.7,"qty":0.0,"timestamp":1618678106670}
1618678106.697325: {"feed":"book","product_id":"FI_BCHUSD_210625","side":"buy","seq":2240174,"price":1130.8,"qty":14449.0,"timestamp":1618678106673}
1618678106.7012532: {"feed":"book","product_id":"PI_BCHUSD","side":"sell","seq":16258220,"price":1063.4,"qty":2943.0,"timestamp":1618678106674}
1618678106.7013812: {"feed":"book","product_id":"PI_BCHUSD","side":"sell","seq":16258221,"price":1063.7,"qty":53614.0,"timestamp":1618678106675}
1618678106.701432: {"feed":"book","product_id":"PI_BCHUSD","side":"sell","seq":16258222,"price":1062.9,"qty":0.0,"timestamp":1618678106678}
1618678106.711645: {"feed":"book","product_id":"PI_BCHUSD","side":"sell","seq":16258223,"price":1063.4,"qty":0.0,"timestamp":1618678106682}
1618678106.711733: {"feed":"book","product_id":"PI_BCHUSD","side":"sell","seq":16258224,"price":1064.3,"qty":14551.0,"timestamp":1618678106683}
1618678106.7224598: {"feed":"book","product_id":"FI_XBTUSD_210625","side":"buy","seq":21454741,"price":57200.5,"qty":33155.0,"timestamp":1618678106687}
1618678106.72257: {"feed":"book","product_id":"PI_BCHUSD","side":"sell","seq":16258225,"price":1063.5,"qty":21076.0,"timestamp":1618678106687}
1618678106.722622: {"feed":"book","product_id":"PI_BCHUSD","side":"buy","seq":16258226,"price":1060.7,"qty":7883.0,"timestamp":1618678106689}
1618678106.722661: {"feed":"book","product_id":"PI_BCHUSD","side":"sell","seq":16258227,"price":1063.8,"qty":7620.0,"timestamp":1618678106689}
1618678106.7226949: {"feed":"book","product_id":"PI_BCHUSD","side":"buy","seq":16258228,"price":1060.2,"qty":7552.0,"timestamp":1618678106689}
1618678106.722729: {"feed":"book","product_id":"PI_BCHUSD","side":"buy","seq":16258229,"price":1060.5,"qty":5005.0,"timestamp":1618678106692}
1618678106.740502: {"feed":"book","product_id":"PI_BCHUSD","side":"sell","seq":16258230,"price":1063.8,"qty":3875.0,"timestamp":1618678106714}
1618678106.740612: {"feed":"book","product_id":"FI_ETHUSD_210924","side":"sell","seq":3859103,"price":2661.65,"qty":2000.0,"timestamp":1618678106714}
1618678106.76542: {"feed":"book","product_id":"PI_BCHUSD","side":"buy","seq":16258231,"price":1060.2,"qty":29789.0,"timestamp":1618678106742}
1618678106.765534: {"feed":"book","product_id":"PI_BCHUSD","side":"buy","seq":16258232,"price":1060.4,"qty":16361.0,"timestamp":1618678106742}
1618678106.777204: {"feed":"book","product_id":"FI_XRPUSD_210625","side":"sell","seq":3631465,"price":1.7006,"qty":0.0,"timestamp":1618678106750}
1618678106.777329: {"feed":"book","product_id":"FI_XRPUSD_210625","side":"sell","seq":3631466,"price":1.6998,"qty":18968.0,"timestamp":1618678106750}
1618678106.781366: {"feed":"book","product_id":"FI_XBTUSD_210625","side":"buy","seq":21454742,"price":57200.5,"qty":30165.0,"timestamp":1618678106754}
1618678106.781831: {"feed":"book","product_id":"PI_BCHUSD","side":"buy","seq":16258233,"price":1059.3,"qty":64620.0,"timestamp":1618678106758}
1618678106.7819269: {"feed":"book","product_id":"PI_BCHUSD","side":"buy","seq":16258234,"price":1060.5,"qty":0.0,"timestamp":1618678106758}
1618678106.791083: {"feed":"book","product_id":"PI_BCHUSD","side":"sell","seq":16258235,"price":1064.3,"qty":20624.0,"timestamp":1618678106762}
1618678106.799734: {"feed":"book","product_id":"PI_BCHUSD","side":"buy","seq":16258236,"price":1060.6,"qty":86.0,"timestamp":1618678106776}
1618678106.8111: {"feed":"book","product_id":"PI_BCHUSD","side":"buy","seq":16258237,"price":1060.6,"qty":0.0,"timestamp":1618678106782}
1618678106.811188: {"feed":"book","product_id":"FI_XBTUSD_210430","side":"sell","seq":12237438,"price":61960.5,"qty":0.0,"timestamp":1618678106786}
1618678106.8112268: {"feed":"book","product_id":"FI_XBTUSD_210430","side":"buy","seq":12237439,"price":60682.5,"qty":0.0,"timestamp":1618678106786}
1618678106.8181472: {"feed":"book","product_id":"PI_BCHUSD","side":"sell","seq":16258238,"price":1063.7,"qty":50097.0,"timestamp":1618678106790}
1618678106.821781: {"feed":"book","product_id":"FI_XBTUSD_210625","side":"buy","seq":21454743,"price":57200.5,"qty":33185.0,"timestamp":1618678106796}
1618678106.823818: {"feed":"book","product_id":"FI_XBTUSD_210924","side":"sell","seq":13850727,"price":68490.0,"qty":0.0,"timestamp":1618678106797}
1618678106.8239439: {"feed":"book","product_id":"FI_XBTUSD_210924","side":"sell","seq":13850728,"price":68507.5,"qty":355466.0,"timestamp":1618678106797}
1618678106.8240068: {"feed":"book","product_id":"FI_XBTUSD_210625","side":"sell","seq":21454744,"price":64097.0,"qty":0.0,"timestamp":1618678106797}
1618678106.824058: {"feed":"book","product_id":"FI_XBTUSD_210625","side":"sell","seq":21454745,"price":64096.0,"qty":250001.0,"timestamp":1618678106797}
1618678106.8241: {"feed":"book","product_id":"FI_XBTUSD_210924","side":"sell","seq":13850729,"price":68569.5,"qty":0.0,"timestamp":1618678106797}
1618678106.82414: {"feed":"book","product_id":"FI_XBTUSD_210924","side":"sell","seq":13850730,"price":68612.5,"qty":125003.0,"timestamp":1618678106797}
1618678106.824178: {"feed":"book","product_id":"FI_XBTUSD_210625","side":"sell","seq":21454746,"price":64192.5,"qty":0.0,"timestamp":1618678106797}
1618678106.824217: {"feed":"book","product_id":"FI_XBTUSD_210625","side":"sell","seq":21454747,"price":64202.0,"qty":504470.0,"timestamp":1618678106797}
1618678106.836997: {"feed":"book","product_id":"FI_BCHUSD_210625","side":"buy","seq":2240175,"price":1130.8,"qty":50.0,"timestamp":1618678106805}
1618678106.8552132: {"feed":"book","product_id":"PI_BCHUSD","side":"sell","seq":16258239,"price":1068.9,"qty":14641.0,"timestamp":1618678106821}
1618678106.85534: {"feed":"book","product_id":"PI_BCHUSD","side":"sell","seq":16258240,"price":1080.3,"qty":112508.0,"timestamp":1618678106821}
1618678106.8553889: {"feed":"book","product_id":"PI_BCHUSD","side":"sell","seq":16258241,"price":1083.6,"qty":89988.0,"timestamp":1618678106821}
1618678106.855426: {"feed":"book","product_id":"PI_BCHUSD","side":"sell","seq":16258242,"price":1150.0,"qty":14941.0,"timestamp":1618678106821}
1618678106.855458: {"feed":"book","product_id":"PI_BCHUSD","side":"buy","seq":16258243,"price":1056.0,"qty":14641.0,"timestamp":1618678106821}
1618678106.855499: {"feed":"book","product_id":"PI_BCHUSD","side":"buy","seq":16258244,"price":1048.1,"qty":267883.0,"timestamp":1618678106821}
1618678106.85553: {"feed":"book","product_id":"PI_BCHUSD","side":"buy","seq":16258245,"price":1034.0,"qty":14741.0,"timestamp":1618678106822}
1618678106.8555672: {"feed":"book","product_id":"PI_BCHUSD","side":"buy","seq":16258246,"price":1030.8,"qty":88206.0,"timestamp":1618678106822}
1618678106.866348: {"feed":"book","product_id":"FI_ETHUSD_210625","side":"buy","seq":12455293,"price":2477.25,"qty":0.0,"timestamp":1618678106840}
1618678106.866478: {"feed":"book","product_id":"FI_ETHUSD_210625","side":"buy","seq":12455294,"price":2485.5,"qty":902.0,"timestamp":1618678106840}
1618678106.86654: {"feed":"book","product_id":"FI_ETHUSD_210625","side":"buy","seq":12455295,"price":2500.35,"qty":0.0,"timestamp":1618678106840}
1618678106.8665879: {"feed":"book","product_id":"FI_ETHUSD_210625","side":"buy","seq":12455296,"price":2500.85,"qty":451.0,"timestamp":1618678106840}
1618678106.885359: {"feed":"book","product_id":"FI_XRPUSD_210625","side":"buy","seq":3631467,"price":1.6936,"qty":0.0,"timestamp":1618678106861}
1618678106.888675: {"feed":"book","product_id":"FI_XBTUSD_210625","side":"sell","seq":21454748,"price":64096.5,"qty":0.0,"timestamp":1618678106864}
1618678106.8888042: {"feed":"book","product_id":"FI_XBTUSD_210625","side":"sell","seq":21454749,"price":64096.5,"qty":19847.0,"timestamp":1618678106864}
1618678106.888869: {"feed":"book","product_id":"FI_XBTUSD_210625","side":"sell","seq":21454750,"price":64069.0,"qty":0.0,"timestamp":1618678106864}
1618678106.888918: {"feed":"book","product_id":"FI_XBTUSD_210625","side":"sell","seq":21454751,"price":64069.0,"qty":14393.0,"timestamp":1618678106864}
1618678106.8909: {"feed":"book","product_id":"FI_XBTUSD_210625","side":"buy","seq":21454752,"price":63917.5,"qty":0.0,"timestamp":1618678106864}
1618678106.891032: {"feed":"book","product_id":"FI_XBTUSD_210625","side":"buy","seq":21454753,"price":63917.5,"qty":1119.0,"timestamp":1618678106864}
1618678106.891096: {"feed":"book","product_id":"FI_XBTUSD_210625","side":"sell","seq":21454754,"price":64143.5,"qty":0.0,"timestamp":1618678106864}
1618678106.891149: {"feed":"book","product_id":"FI_XBTUSD_210625","side":"sell","seq":21454755,"price":64143.5,"qty":31261.0,"timestamp":1618678106864}
1618678106.891191: {"feed":"book","product_id":"PI_BCHUSD","side":"sell","seq":16258247,"price":1064.3,"qty":9981.0,"timestamp":1618678106866}
1618678106.891264: {"feed":"book","product_id":"PI_BCHUSD","side":"sell","seq":16258248,"price":1064.1,"qty":41809.0,"timestamp":1618678106866}
1618678106.893743: {"feed":"book","product_id":"FI_XBTUSD_210625","side":"buy","seq":21454756,"price":63926.0,"qty":0.0,"timestamp":1618678106864}
1618678106.89381: {"feed":"book","product_id":"FI_XBTUSD_210625","side":"buy","seq":21454757,"price":63926.0,"qty":1013.0,"timestamp":1618678106864}
1618678106.893847: {"feed":"book","product_id":"FI_XBTUSD_210625","side":"buy","seq":21454758,"price":63496.0,"qty":0.0,"timestamp":1618678106864}
1618678106.893879: {"feed":"book","product_id":"FI_XBTUSD_210625","side":"buy","seq":21454759,"price":63496.0,"qty":4328.0,"timestamp":1618678106864}
1618678106.893905: {"feed":"book","product_id":"FI_XBTUSD_210625","side":"buy","seq":21454760,"price":63853.0,"qty":0.0,"timestamp":1618678106864}
1618678106.893931: {"feed":"book","product_id":"FI_XBTUSD_210625","side":"buy","seq":21454761,"price":63853.0,"qty":1997.0,"timestamp":1618678106864}
1618678106.893955: {"feed":"book","product_id":"FI_XBTUSD_210625","side":"buy","seq":21454762,"price":63746.5,"qty":0.0,"timestamp":1618678106864}
1618678106.8939788: {"feed":"book","product_id":"FI_XBTUSD_210625","side":"buy","seq":21454763,"price":63746.5,"qty":3257.0,"timestamp":1618678106864}
1618678106.894002: {"feed":"book","product_id":"FI_XBTUSD_210625","side":"sell","seq":21454764,"price":64254.0,"qty":0.0,"timestamp":1618678106864}
1618678106.894026: {"feed":"book","product_id":"FI_XBTUSD_210625","side":"sell","seq":21454765,"price":64254.0,"qty":56025.0,"timestamp":1618678106864}
1618678106.894072: {"feed":"book","product_id":"FI_XBTUSD_210625","side":"sell","seq":21454766,"price":64516.5,"qty":0.0,"timestamp":1618678106864}
1618678106.894091: {"feed":"book","product_id":"FI_XBTUSD_210625","side":"sell","seq":21454767,"price":64516.5,"qty":76423.0,"timestamp":1618678106864}
1618678106.907457: {"feed":"book","product_id":"FI_XBTUSD_210625","side":"buy","seq":21454768,"price":57200.5,"qty":30165.0,"timestamp":1618678106878}
1618678106.9081469: {"feed":"book","product_id":"FI_XBTUSD_210430","side":"buy","seq":12237440,"price":61130.5,"qty":0.0,"timestamp":1618678106881}
1618678106.9115672: {"feed":"book","product_id":"FI_XBTUSD_210924","side":"sell","seq":13850731,"price":68294.5,"qty":3000.0,"timestamp":1618678106884}
1618678106.919625: {"feed":"book","product_id":"PI_BCHUSD","side":"buy","seq":16258249,"price":1060.4,"qty":16275.0,"timestamp":1618678106891}
