1618678134.420416: [1840,{"a":[["9.614752","64.30000000","1618678134.393238"]],"c":"2204770057"},"book-1000","OMG/USD"]
1618678134.432192: [3648,{"b":[["0.00755800","1.97569103","1618678134.404446"]],"c":"4070548093"},"book-1000","KSM/XBT"]
1618678134.43372: [3648,{"a":[["0.00760500","0.00000000","1618678134.404600"]],"c":"3149354142"},"book-1000","KSM/XBT"]
1618678134.438655: [1840,{"a":[["9.614752","0.00000000","1618678134.411713"]],"c":"2204770057"},"book-1000","OMG/USD"]
1618678134.4458618: [1840,{"b":[["9.584186","189.17698969","1618678134.416489"]],"c":"2116800642"},"book-1000","OMG/USD"]
1618678134.447624: [3648,{"a":[["0.00757900","1.34617811","1618678134.420605"]],"c":"3231813603"},"book-1000","KSM/XBT"]
1618678134.472411: [3648,{"a":[["0.00758100","0.54700000","1618678134.445750"]],"c":"1245956387"},"book-1000","KSM/XBT"]
1618678134.477684: [1664,{"a":[["13.312800","1396.00000000","1618678134.449549"]],"c":"1159473869"},"book-1000","WAVES/EUR"]
1618678134.496075: [3648,{"a":[["0.00758600","9.00000000","1618678134.467685"]],"c":"2624369021"},"book-1000","KSM/XBT"]
1618678134.504544: [1920,{"a":[["0.044530","1353.55891767","1618678134.476502"]],"c":"1436403959"},"book-1000","SC/EUR"]
1618678134.508312: [1920,{"b":[["0.042920","30810.00000000","1618678134.477896"]],"c":"1791401266"},"book-1000","SC/EUR"]
1618678134.51777: [1664,{"a":[["13.268500","0.00000000","1618678134.489803"]],"c":"202049188"},"book-1000","WAVES/EUR"]
1618678134.519691: [1360,{"b":[["0.000022860","31571.61559016","1618678134.490367"]],"c":"993647625"},"book-1000","ADA/XBT"]
1618678134.5231519: [1664,{"a":[["13.274800","856.49000000","1618678134.491833"]],"c":"202049188"},"book-1000","WAVES/EUR"]
1618678134.524458: [1360,{"b":[["0.000022820","0.00000000","1618678134.492395"]],"c":"1301617853"},"book-1000","ADA/XBT"]
1618678134.5270212: [992,{"b":[["354.14000000","7.57500000","1618678134.498280"]],"c":"182613861"},"book-1000","XMR/USD"]
1618678134.528809: [992,{"b":[["354.19000000","7.57500000","1618678134.498537"]],"c":"1108155683"},"book-1000","XMR/USD"]
1618678134.530508: [992,{"b":[["354.19000000","0.00000000","1618678134.499405"]],"c":"2702260239"},"book-1000","XMR/USD"]
1618678134.5321841: [992,{"b":[["354.14000000","0.00000000","1618678134.499456"]],"c":"578385793"},"book-1000","XMR/USD"]
1618678134.5340428: [3648,{"b":[["0.00755800","0.88690103","1618678134.502373"]],"c":"2466532719"},"book-1000","KSM/XBT"]
1618678134.535635: [992,{"b":[["354.18000000","0.00000000","1618678134.505889"]],"c":"3274991004"},"book-1000","XMR/USD"]
1618678134.543823: [1920,{"a":[["0.044370","328550.03223264","1618678134.514677"]],"c":"1791401266"},"book-1000","SC/EUR"]
1618678134.557042: [1360,{"a":[["0.000022910","9283.79025460","1618678134.528824"]],"c":"2357531405"},"book-1000","ADA/XBT"]
1618678134.568764: [1664,{"a":[["13.260600","0.00000000","1618678134.540765"]],"c":"294280918"},"book-1000","WAVES/EUR"]
1618678134.5706758: [1360,{"b":[["0.000022880","3599.78110000","1618678134.541453"]],"c":"410132673"},"book-1000","ADA/XBT"]
1618678134.574071: [1360,{"b":[["0.000022840","29027.46641260","1618678134.545345"]],"c":"1486119701"},"book-1000","ADA/XBT"]
1618678134.602825: [1360,{"a":[["0.000022900","11167.18484526","1618678134.574574"]],"c":"2378939080"},"book-1000","ADA/XBT"]
1618678134.6432798: [1920,{"b":[["0.041820","50000.00000000","1618678134.616174"]],"c":"1791401266"},"book-1000","SC/EUR"]
1618678134.647295: [1360,{"a":[["0.000022910","11471.91427162","1618678134.618974"]],"c":"812311733"},"book-1000","ADA/XBT"]
1618678134.65033: [1664,{"a":[["13.448600","0.00000000","1618678134.620745"]],"c":"294280918"},"book-1000","WAVES/EUR"]
1618678134.691488: [1664,{"a":[["13.451200","1602.38415685","1618678134.664320"]],"c":"294280918"},"book-1000","WAVES/EUR"]
1618678134.703451: [3648,{"a":[["0.00761700","0.00000000","1618678134.675888"]],"c":"2466532719"},"book-1000","KSM/XBT"]
1618678134.704865: [1360,{"b":[["0.000022870","18888.28357373","1618678134.675971"]],"c":"255503223"},"book-1000","ADA/XBT"]
1618678134.709182: [1664,{"a":[["13.260700","0.00000000","1618678134.682725"]],"c":"2624717314"},"book-1000","WAVES/EUR"]
1618678134.727136: [1840,{"a":[["9.596675","200.00000000","1618678134.699201"]],"c":"993262207"},"book-1000","OMG/USD"]
1618678134.7431092: [3648,{"a":[["0.00762000","18.35748535","1618678134.716192"]],"c":"2466532719"},"book-1000","KSM/XBT"]
1618678134.758137: [1360,{"b":[["0.000022850","8831.31172198","1618678134.728777"]],"c":"2595803042"},"book-1000","ADA/XBT"]
1618678134.776347: [1360,{"a":[["0.000022910","10408.11587162","1618678134.732511"]],"c":"846206247"},"book-1000","ADA/XBT"]
1618678134.7835772: [1840,{"a":[["9.597862","0.00000000","1618678134.755308"]],"c":"1627725133"},"book-1000","OMG/USD"]
1618678134.8029819: [3648,{"a":[["0.00756900","2.17919581","1618678134.768299"]],"c":"1439338703"},"book-1000","KSM/XBT"]
1618678134.80434: [1840,{"a":[["9.667953","0.00000000","1618678134.774932"]],"c":"1627725133"},"book-1000","OMG/USD"]
1618678134.825299: [496,{"a":[["2205.10000","0.00000000","1618678134.798422"]],"c":"1041248763"},"book-1000","ETH/CHF"]
1618678134.84862: [1920,{"a":[["0.043170","20000.00000000","1618678134.822755"]],"c":"2354028742"},"book-1000","SC/EUR"]
1618678134.851638: [1360,{"b":[["0.000022880","9281.30195100","1618678134.824653"]],"c":"530538157"},"book-1000","ADA/XBT"]
1618678134.865916: [496,{"a":[["2207.46000","1.19133444","1618678134.837829"]],"c":"1041248763"},"book-1000","ETH/CHF"]
1618678134.868952: [1840,{"a":[["9.639637","360.00000000","1618678134.841989"]],"c":"1627725133"},"book-1000","OMG/USD"]
1618678134.8804421: [1360,{"b":[["0.000022870","20113.78357373","1618678134.849132"]],"c":"3461675675"},"book-1000","ADA/XBT"]
1618678134.8860312: [496,{"b":[["2185.10000","0.82991777","1618678134.858335"]],"c":"98529415"},"book-1000","ETH/CHF"]
1618678134.889295: [1360,{"a":[["0.000022900","10175.08484526","1618678134.862144"]],"c":"2344873105"},"book-1000","ADA/XBT"]
1618678134.923709: [496,{"b":[["2185.09000","3.00000000","1618678134.894273"]],"c":"3431620434"},"book-1000","ETH/CHF"]
1618678134.925087: [496,{"b":[["2185.11000","1.51157348","1618678134.896328"]],"c":"767785727"},"book-1000","ETH/CHF"]
1618678134.93419: [496,{"b":[["2185.11000","4.51157348","1618678134.905475"]],"c":"2267903667"},"book-1000","ETH/CHF"]
1618678134.9533598: [992,{"b":[["354.17000000","0.00000000","1618678134.926618"]],"c":"4139043520"},"book-1000","XMR/USD"]
1618678134.9971359: [1920,{"b":[["0.040910","23245.00232450","1618678134.968906"]],"c":"2354028742"},"book-1000","SC/EUR"]
1618678135.000632: [992,{"b":[["354.22000000","6.88199219","1618678134.969629"]],"c":"3975035620"},"book-1000","XMR/USD"]
1618678135.0030248: [992,{"b":[["354.21000000","0.00000000","1618678134.970311"]],"c":"3062537872"},"book-1000","XMR/USD"]
1618678135.004906: [992,{"b":[["354.12000000","1.40000000","1618678134.970442"]],"c":"1258405299"},"book-1000","XMR/USD"]
1618678135.006639: [1360,{"b":[["0.000022850","9583.16915400","1618678134.973522"]],"c":"971820690"},"book-1000","ADA/XBT"]
1618678135.020629: [1840,{"a":[["9.639637","0.00000000","1618678134.990933"]],"c":"1627725133"},"book-1000","OMG/USD"]
1618678135.027915: [1920,{"a":[["0.043170","0.00000000","1618678135.000922"]],"c":"1791401266"},"book-1000","SC/EUR"]
1618678135.031064: [1920,{"a":[["0.043130","56862.77325050","1618678135.001447"]],"c":"2912531199"},"book-1000","SC/EUR"]
1618678135.038392: [992,{"b":[["354.12000000","0.00000000","1618678135.009137"]],"c":"3062537872"},"book-1000","XMR/USD"]
1618678135.041225: [992,{"a":[["356.63000000","0.00000000","1618678135.010081"]],"c":"3062537872"},"book-1000","XMR/USD"]
1618678135.043512: [992,{"b":[["353.86000000","7.00000000","1618678135.012999"]],"c":"1139871795"},"book-1000","XMR/USD"]
1618678135.0455968: [1920,{"b":[["0.042930","139288.00000000","1618678135.017953"]],"c":"788143605"},"book-1000","SC/EUR"]
1618678135.0492642: [1920,{"b":[["0.042960","175181.61219739","1618678135.021980"]],"c":"3036784201"},"book-1000","SC/EUR"]
1618678135.053476: [992,{"b":[["352.55000000","11.52000000","1618678135.026625"]],"c":"1139871795"},"book-1000","XMR/USD"]
1618678135.059241: [1360,{"a":[["0.000022900","7175.08484526","1618678135.031003"]],"c":"892151220"},"book-1000","ADA/XBT"]
1618678135.0632021: [496,{"b":[["2181.04000","0.00000000","1618678135.036259"]],"c":"1046332261"},"book-1000","ETH/CHF"]
1618678135.068331: [992,{"b":[["354.26000000","1.40000000","1618678135.036506"]],"c":"2244003102"},"book-1000","XMR/USD"]
1618678135.071438: [1920,{"a":[["0.043230","52785.98896926","1618678135.043564"]],"c":"3255208054"},"book-1000","SC/EUR"]
1618678135.074354: [1920,{"a":[["0.043280","0.00000000","1618678135.046801"]],"c":"2096812439"},"book-1000","SC/EUR"]
1618678135.079732: [1840,{"a":[["9.667952","360.00000000","1618678135.050802"]],"c":"1627725133"},"book-1000","OMG/USD"]
1618678135.099434: [992,{"a":[["355.91000000","15.27000000","1618678135.070730"]],"c":"2244003102"},"book-1000","XMR/USD"]
1618678135.105684: [1920,{"a":[["0.043130","45060.00000000","1618678135.078658"]],"c":"987951004"},"book-1000","SC/EUR"]
1618678135.112352: [1920,{"a":[["0.043200","0.00000000","1618678135.086199"]],"c":"2357102551"},"book-1000","SC/EUR"]
1618678135.11528: [1920,{"a":[["0.043260","0.00000000","1618678135.087104"]],"c":"1677305947"},"book-1000","SC/EUR"]
1618678135.144046: [1920,{"a":[["0.043310","183452.67067430","1618678135.115334"]],"c":"2510247086"},"book-1000","SC/EUR"]
1618678135.1478431: [1920,{"a":[["0.043230","10324.15010000","1618678135.117354"]],"c":"1240553397"},"book-1000","SC/EUR"]
1618678135.159242: [992,{"a":[["354.79000000","0.00000000","1618678135.131122"]],"c":"3880319150"},"book-1000","XMR/USD"]
1618678135.1624289: [992,{"a":[["354.85000000","0.00000000","1618678135.134567"]],"c":"652164670"},"book-1000","XMR/USD"]
1618678135.164479: [1920,{"a":[["0.043250","0.00000000","1618678135.135904"]],"c":"631542256"},"book-1000","SC/EUR"]
1618678135.189949: [1920,{"a":[["0.043270","1087408.83886926","1618678135.160641"]],"c":"2340065263"},"book-1000","SC/EUR"]
1618678135.197692: [992,{"a":[["354.74000000","6.88198785","1618678135.170961"]],"c":"1343443298"},"book-1000","XMR/USD"]
1618678135.199853: [992,{"a":[["354.75000000","0.00000000","1618678135.171423"]],"c":"2790364006"},"book-1000","XMR/USD"]
1618678135.201813: [992,{"a":[["354.81000000","1.40000000","1618678135.171570"]],"c":"1264259399"},"book-1000","XMR/USD"]
1618678135.206053: [992,{"a":[["354.81000000","0.00000000","1618678135.176218"]],"c":"2790364006"},"book-1000","XMR/USD"]
1618678135.207773: [992,{"a":[["354.98000000","1.40000000","1618678135.176561"]],"c":"3423178889"},"book-1000","XMR/USD"]
1618678135.215976: [1920,{"b":[["0.040950","0.00000000","1618678135.188328"]],"c":"2340065263"},"book-1000","SC/EUR"]
1618678135.222642: [1920,{"a":[["0.043240","906825.33415860","1618678135.195364"]],"c":"458972281"},"book-1000","SC/EUR"]
1618678135.2257621: [1360,{"b":[["0.000022880","3599.78110000","1618678135.197324"]],"c":"415395390"},"book-1000","ADA/XBT"]
1618678135.2302132: [1920,{"b":[["0.042800","0.00000000","1618678135.202629"]],"c":"458972281"},"book-1000","SC/EUR"]
1618678135.232811: [1920,{"b":[["0.042940","54180.00000000","1618678135.203864"]],"c":"2753186071"},"book-1000","SC/EUR"]
1618678135.240819: [992,{"a":[["354.98000000","0.00000000","1618678135.210819"]],"c":"2790364006"},"book-1000","XMR/USD"]
1618678135.2451441: [3648,{"a":[["0.00758600","0.00000000","1618678135.217274"]],"c":"1101714992"},"book-1000","KSM/XBT"]
1618678135.246582: [992,{"a":[["354.70000000","1.40000000","1618678135.219579"]],"c":"2508407348"},"book-1000","XMR/USD"]
1618678135.24872: [496,{"b":[["2185.08000","0.00000000","1618678135.220469"]],"c":"3456380388"},"book-1000","ETH/CHF"]
1618678135.2497768: [496,{"b":[["2185.25000","0.79191000","1618678135.220918"]],"c":"2998964548"},"book-1000","ETH/CHF"]
1618678135.2506251: [496,{"b":[["2185.10000","0.94881777","1618678135.223212"]],"c":"144045627"},"book-1000","ETH/CHF"]
1618678135.251325: [1920,{"a":[["0.044370","0.00000000","1618678135.223844"]],"c":"2753186071"},"book-1000","SC/EUR"]
1618678135.253741: [1920,{"b":[["0.041450","0.00000000","1618678135.224221"]],"c":"2753186071"},"book-1000","SC/EUR"]
1618678135.255788: [1360,{"a":[["0.000022920","14002.32710046","1618678135.225053"]],"c":"212861996"},"book-1000","ADA/XBT"]
1618678135.264543: [1920,{"a":[["0.043240","1500.00000000","1618678135.236822"]],"c":"876321409"},"book-1000","SC/EUR"]
1618678135.2760608: [1920,{"b":[["0.042810","0.00000000","1618678135.247005"]],"c":"876321409"},"book-1000","SC/EUR"]
1618678135.279855: [1840,{"b":[["9.577933","0.00000000","1618678135.250721"]],"c":"96222701"},"book-1000","OMG/USD"]
1618678135.285717: [496,{"b":[["2185.11000","3.00000000","1618678135.257200"]],"c":"3964558884"},"book-1000","ETH/CHF"]
1618678135.287084: [496,{"b":[["2185.26000","1.51146973","1618678135.259334"]],"c":"1334367119"},"book-1000","ETH/CHF"]
1618678135.290016: [1664,{"a":[["13.276200","503.28288506","1618678135.262803"]],"c":"3581044058"},"book-1000","WAVES/EUR"]
1618678135.291636: [1920,{"b":[["0.041650","328335.14073488","1618678135.263673"]],"c":"876321409"},"book-1000","SC/EUR"]
1618678135.2952168: [1920,{"b":[["0.042830","0.00000000","1618678135.267819"]],"c":"3449867781"},"book-1000","SC/EUR"]
1618678135.298013: [1920,{"a":[["0.044400","329836.64073488","1618678135.268228"]],"c":"3449867781"},"book-1000","SC/EUR"]
1618678135.300309: {"event":"heartbeat"}
1618678135.3004951: [1920,{"a":[["0.043130","0.00000000","1618678135.270810"]],"c":"1823900617"},"book-1000","SC/EUR"]
1618678135.302716: [3648,{"a":[["0.00758200","0.00000000","1618678135.272517"]],"c":"290656080"},"book-1000","KSM/XBT"]
1618678135.3035798: [3648,{"a":[["0.00760500","9.00000000","1618678135.277162"]],"c":"4038621439"},"book-1000","KSM/XBT"]
1618678135.306844: [1920,{"a":[["0.043230","915649.48425860","1618678135.278919"]],"c":"3078674236"},"book-1000","SC/EUR"]
1618678135.310752: [1920,{"b":[["0.042960","219931.61219739","1618678135.283664"]],"c":"3621093864"},"book-1000","SC/EUR"]
1618678135.313463: [1920,{"b":[["0.042820","597471.35093778","1618678135.286852"]],"c":"1246614818"},"book-1000","SC/EUR"]
1618678135.323213: [3648,{"b":[["0.00754400","0.00000000","1618678135.294434"]],"c":"3098302100"},"book-1000","KSM/XBT"]
1618678135.333853: [3648,{"b":[["0.00754900","4.95000000","1618678135.305620"]],"c":"201494983"},"book-1000","KSM/XBT"]
1618678135.34673: [3648,{"a":[["0.00758400","4.90000000","1618678135.319983"]],"c":"2119306303"},"book-1000","KSM/XBT"]
1618678135.348087: [1920,{"a":[["0.043230","10324.15010000","1618678135.321061"]],"c":"2269242853"},"book-1000","SC/EUR"]
1618678135.357991: [1920,{"b":[["0.042820","20182.89187450","1618678135.328023"]],"c":"216257821"},"book-1000","SC/EUR"]
1618678135.370361: [1664,{"a":[["13.312800","0.00000000","1618678135.342134"]],"c":"3581044058"},"book-1000","WAVES/EUR"]
1618678135.376657: [3648,{"b":[["0.00756100","1.08840000","1618678135.346893"]],"c":"4008408561"},"book-1000","KSM/XBT"]
1618678135.3778439: [3648,{"b":[["0.00755300","3.26480000","1618678135.346997"]],"c":"3895084504"},"book-1000","KSM/XBT"]
1618678135.387978: [1840,{"a":[["9.596676","0.00000000","1618678135.360053"]],"c":"4035832190"},"book-1000","OMG/USD"]
1618678135.3917198: [1920,{"a":[["0.043220","905325.33415860","1618678135.363078"]],"c":"176140472"},"book-1000","SC/EUR"]
1618678135.40594: [1920,{"b":[["0.042830","577288.45906328","1618678135.377318"]],"c":"1111359494"},"book-1000","SC/EUR"]
1618678135.4097128: [3648,{"b":[["0.00754100","0.63900000","1618678135.378631"]],"c":"3895084504"},"book-1000","KSM/XBT"]
1618678135.4106188: [1360,{"b":[["0.000022830","23587.82089865","1618678135.381606"]],"c":"2889284064"},"book-1000","ADA/XBT"]
1618678135.413625: [3648,{"b":[["0.00755900","0.00000000","1618678135.385861"]],"c":"1104874561"},"book-1000","KSM/XBT"]
1618678135.414387: [3648,{"b":[["0.00756200","0.21000000","1618678135.385992"]],"c":"3556464450"},"book-1000","KSM/XBT"]
1618678135.428939: [1840,{"a":[["9.596674","136.94102295","1618678135.401839"]],"c":"683231689"},"book-1000","OMG/USD"]
1618678135.430343: [1664,{"a":[["13.284300","1396.00000000","1618678135.402316"]],"c":"3581044058"},"book-1000","WAVES/EUR"]
1618678135.431905: [1920,{"a":[["0.043220","0.00000000","1618678135.404594"]],"c":"1151493539"},"book-1000","SC/EUR"]
1618678135.436288: [3648,{"a":[["0.00758400","0.00000000","1618678135.410434"]],"c":"2712390330"},"book-1000","KSM/XBT"]
1618678135.445407: [1920,{"a":[["0.043490","23180.34306907","1618678135.418372"]],"c":"3425286897"},"book-1000","SC/EUR"]
1618678135.4485781: [1920,{"a":[["0.043230","31155.77117818","1618678135.418510"]],"c":"707058233"},"book-1000","SC/EUR"]
1618678135.451133: [1920,{"b":[["0.042830","0.00000000","1618678135.418978"]],"c":"1650813575"},"book-1000","SC/EUR"]
1618678135.4668941: [1664,{"a":[["13.284400","0.00000000","1618678135.439169"]],"c":"3581044058"},"book-1000","WAVES/EUR"]
1618678135.468787: [1664,{"a":[["13.284200","119.15886375","1618678135.440190"]],"c":"3581044058"},"book-1000","WAVES/EUR"]
1618678135.471149: [1360,{"b":[["0.000022880","9599.78110000","1618678135.443822"]],"c":"3913845120"},"book-1000","ADA/XBT"]
1618678135.4754581: [496,{"b":[["2154.95000","0.00000000","1618678135.448868"]],"c":"1334367119"},"book-1000","ETH/CHF"]
1618678135.481357: [1920,{"a":[["0.043210","909832.28951414","1618678135.452544"]],"c":"3559069096"},"book-1000","SC/EUR"]
1618678135.484865: [1840,{"a":[["9.596673","200.00000000","1618678135.454627"]],"c":"2757037205"},"book-1000","OMG/USD"]
1618678135.486128: [496,{"b":[["2185.09000","0.00000000","1618678135.456853"]],"c":"1487862158"},"book-1000","ETH/CHF"]
1618678135.487201: [1920,{"b":[["0.042840","577288.45906328","1618678135.459812"]],"c":"1676481172"},"book-1000","SC/EUR"]
1618678135.508599: [3648,{"b":[["0.00753800","0.00000000","1618678135.480692"]],"c":"2712390330"},"book-1000","KSM/XBT"]
1618678135.5146282: [496,{"b":[["2185.26000","4.51146973","1618678135.486503"]],"c":"661527097"},"book-1000","ETH/CHF"]
1618678135.5159879: [496,{"b":[["2185.11000","0.00000000","1618678135.486636"]],"c":"1503064620"},"book-1000","ETH/CHF"]
1618678135.5174358: [496,{"b":[["2155.23000","14.28451380","1618678135.490584"]],"c":"1503064620"},"book-1000","ETH/CHF"]
1618678135.518535: [3648,{"a":[["0.00758300","0.00000000","1618678135.490634"]],"c":"443567349"},"book-1000","KSM/XBT"]
1618678135.51986: [3648,{"b":[["0.00755200","2.27388316","1618678135.491582"]],"c":"861824159"},"book-1000","KSM/XBT"]
1618678135.520731: [992,{"a":[["361.05000000","0.00000000","1618678135.491722"]],"c":"2508407348"},"book-1000","XMR/USD"]
1618678135.522811: [1920,{"a":[["0.043210","4506.95535554","1618678135.492651"]],"c":"3584781755"},"book-1000","SC/EUR"]
1618678135.525352: [992,{"a":[["710.46000000","0.05000000","1618678135.493899"]],"c":"2508407348"},"book-1000","XMR/USD"]
1618678135.527061: [3648,{"b":[["0.00755900","39.59000000","1618678135.496396"]],"c":"3273372324"},"book-1000","KSM/XBT"]
1618678135.527779: [3648,{"a":[["0.00758700","6.81728193","1618678135.497453"]],"c":"3203937956"},"book-1000","KSM/XBT"]
1618678135.5284889: [1840,{"b":[["9.577263","0.00000000","1618678135.497580"]],"c":"3296310853"},"book-1000","OMG/USD"]
1618678135.5293639: [1360,{"b":[["0.000022810","13561.18760000","1618678135.498145"]],"c":"1616835333"},"book-1000","ADA/XBT"]
1618678135.5324411: [3648,{"a":[["0.00759000","38.75000000","1618678135.503477"]],"c":"2535565706"},"book-1000","KSM/XBT"]
1618678135.533806: [1840,{"a":[["9.596675","0.00000000","1618678135.503595"]],"c":"3041819944"},"book-1000","OMG/USD"]
1618678135.540542: [3648,{"a":[["0.00757900","0.00000000","1618678135.513017"]],"c":"292258819"},"book-1000","KSM/XBT"]
1618678135.5689118: [992,{"a":[["359.70000000","23.77433370","1618678135.533032"]],"c":"2508407348"},"book-1000","XMR/USD"]
1618678135.5717728: [1360,{"b":[["0.000022850","8080.60184548","1618678135.537896"]],"c":"3772832070"},"book-1000","ADA/XBT"]
1618678135.5750442: [1840,{"a":[["9.667952","0.00000000","1618678135.545861"]],"c":"3041819944"},"book-1000","OMG/USD"]
1618678135.591418: [3648,{"b":[["0.00754100","0.00000000","1618678135.563780"]],"c":"292258819"},"book-1000","KSM/XBT"]
1618678135.614321: [1920,{"a":[["0.043230","10324.15010000","1618678135.586085"]],"c":"866520435"},"book-1000","SC/EUR"]
1618678135.632501: [1840,{"a":[["9.639017","360.00000000","1618678135.604768"]],"c":"3041819944"},"book-1000","OMG/USD"]
1618678135.6601868: [1920,{"a":[["0.043320","0.00000000","1618678135.632559"]],"c":"583359832"},"book-1000","SC/EUR"]
1618678135.663717: [1360,{"a":[["0.000023120","0.00000000","1618678135.632699"]],"c":"3772832070"},"book-1000","ADA/XBT"]
1618678135.676327: [3648,{"b":[["0.00754100","0.11671392","1618678135.648185"]],"c":"292258819"},"book-1000","KSM/XBT"]
1618678135.6808681: [5104,{"b":[["0.000027700","44.30000000","1618678135.654383"]],"c":"2276810932"},"book-1000","OCEAN/XBT"]
1618678135.6992671: [1360,{"b":[["0.000022870","21111.78357373","1618678135.671924"]],"c":"3828685568"},"book-1000","ADA/XBT"]
1618678135.724322: [1360,{"b":[["0.000022880","15281.00717282","1618678135.695516"]],"c":"2800645602"},"book-1000","ADA/XBT"]
1618678135.731871: [3648,{"b":[["0.00756100","0.00000000","1618678135.703749"]],"c":"1748825530"},"book-1000","KSM/XBT"]
1618678135.735133: [1840,{"b":[["9.578487","108.92165180","1618678135.706843"]],"c":"903993129"},"book-1000","OMG/USD"]
1618678135.741529: [992,{"b":[["354.23000000","5.00000000","1618678135.714849"]],"c":"1814239865"},"book-1000","XMR/USD"]
1618678135.7583601: [1920,{"a":[["0.043230","31167.75507326","1618678135.730838"]],"c":"2740223845"},"book-1000","SC/EUR"]
1618678135.761902: [992,{"a":[["355.22000000","0.00000000","1618678135.731626"]],"c":"1418869040"},"book-1000","XMR/USD"]
1618678135.764215: [3648,{"a":[["0.00756900","0.00000000","1618678135.732445"]],"c":"1466474428"},"book-1000","KSM/XBT"]
1618678135.789525: [3648,{"a":[["0.00758700","4.54525656","1618678135.763001"]],"c":"3824492000"},"book-1000","KSM/XBT"]
1618678135.790495: [3648,{"a":[["0.00758700","0.00000000","1618678135.763162"]],"c":"62049611"},"book-1000","KSM/XBT"]
1618678135.791403: [1360,{"b":[["0.000022850","9584.20308692","1618678135.763359"]],"c":"2452076220"},"book-1000","ADA/XBT"]
1618678135.7943628: [1360,{"a":[["0.000022950","7340.22471303","1618678135.766751"]],"c":"490857047"},"book-1000","ADA/XBT"]
1618678135.7971299: [1360,{"a":[["0.000022960","36576.53000000","1618678135.766850"]],"c":"2726456122"},"book-1000","ADA/XBT"]
1618678135.799619: [1360,{"b":[["0.000022880","20281.00717282","1618678135.767041"]],"c":"1617593055"},"book-1000","ADA/XBT"]
1618678135.8020859: [992,{"a":[["355.23000000","0.00000000","1618678135.767188"]],"c":"1594891052"},"book-1000","XMR/USD"]
1618678135.804065: [3648,{"a":[["0.00758000","0.21000000","1618678135.773407"]],"c":"1398779621"},"book-1000","KSM/XBT"]
1618678135.8048482: [3648,{"a":[["0.00758000","2.38833659","1618678135.773704"]],"c":"4261645778"},"book-1000","KSM/XBT"]
1618678135.8117938: [992,{"b":[["354.08000000","0.00000000","1618678135.784516"]],"c":"3750842271"},"book-1000","XMR/USD"]
1618678135.813815: [1840,{"a":[["9.639017","0.00000000","1618678135.785316"]],"c":"903993129"},"book-1000","OMG/USD"]
1618678135.819131: [1920,{"b":[["0.042940","34180.00000000","1618678135.791089"]],"c":"351626226"},"book-1000","SC/EUR"]
1618678135.826668: [3648,{"a":[["0.00760500","0.00000000","1618678135.799026"]],"c":"3969377091"},"book-1000","KSM/XBT"]
1618678135.8298619: [3648,{"b":[["0.00750600","5.68093333","1618678135.801143"]],"c":"3969377091"},"book-1000","KSM/XBT"]
1618678135.832034: [992,{"b":[["354.23000000","12.57500000","1618678135.805937"]],"c":"1745423940"},"book-1000","XMR/USD"]
1618678135.855772: [1360,{"a":[["0.000022930","1275.14896627","1618678135.829012"]],"c":"1827557461"},"book-1000","ADA/XBT"]
1618678135.877318: [1840,{"a":[["9.639236","360.00000000","1618678135.849996"]],"c":"903993129"},"book-1000","OMG/USD"]
1618678135.8797388: [992,{"a":[["355.02000000","0.00000000","1618678135.852238"]],"c":"3754446193"},"book-1000","XMR/USD"]
1618678135.8891032: [3648,{"a":[["0.00758900","9.00000000","1618678135.860170"]],"c":"230179812"},"book-1000","KSM/XBT"]
1618678135.901769: [5104,{"b":[["0.000027700","662.94300214","1618678135.875091"]],"c":"1991242673"},"book-1000","OCEAN/XBT"]
1618678135.914315: [1360,{"a":[["0.000022920","13969.81403419","1618678135.887776"]],"c":"3638464022"},"book-1000","ADA/XBT"]
1618678135.933652: [1360,{"a":[["0.000023150","153896.72130500","1618678135.905828"]],"c":"3638464022"},"book-1000","ADA/XBT"]
1618678135.9446: [3648,{"a":[["0.00758500","1.34617811","1618678135.917590"]],"c":"2535423732"},"book-1000","KSM/XBT"]
1618678135.959598: [1664,{"a":[["13.259800","29.17000000","1618678135.931371"]],"c":"2721723272"},"book-1000","WAVES/EUR"]
1618678135.975391: [1360,{"b":[["0.000022870","15111.78357373","1618678135.948050"]],"c":"798704289"},"book-1000","ADA/XBT"]
1618678135.979168: [1360,{"a":[["0.000022920","19969.81403419","1618678135.948133"]],"c":"3502226088"},"book-1000","ADA/XBT"]
1618678135.986012: [3648,{"a":[["0.00758100","0.00000000","1618678135.956487"]],"c":"2974406154"},"book-1000","KSM/XBT"]
1618678135.988511: [1920,{"b":[["0.042950","0.00000000","1618678135.960438"]],"c":"3706107638"},"book-1000","SC/EUR"]
1618678136.008106: [3648,{"a":[["0.00759200","4.54268069","1618678135.977862"]],"c":"3766034794"},"book-1000","KSM/XBT"]
1618678136.009515: [3648,{"a":[["0.00758900","11.27134035","1618678135.980723"]],"c":"2509663591"},"book-1000","KSM/XBT"]
1618678136.020014: [1920,{"b":[["0.042970","20000.00000000","1618678135.990954"]],"c":"699026911"},"book-1000","SC/EUR"]
1618678136.023527: [992,{"b":[["353.30000000","4.34939513","1618678135.992802"]],"c":"3754446193"},"book-1000","XMR/USD"]
1618678136.026369: [1920,{"a":[["0.043270","1044947.00000000","1618678135.996625"]],"c":"2483421535"},"book-1000","SC/EUR"]
1618678136.038771: [1920,{"b":[["0.042970","25799.76157391","1618678136.010881"]],"c":"660343639"},"book-1000","SC/EUR"]
1618678136.042558: [3648,{"b":[["0.00749700","0.00000000","1618678136.011473"]],"c":"2509663591"},"book-1000","KSM/XBT"]
1618678136.043484: [1664,{"a":[["13.276100","119.15886375","1618678136.014130"]],"c":"2721723272"},"book-1000","WAVES/EUR"]
1618678136.045001: [1664,{"a":[["13.284200","0.00000000","1618678136.015984"]],"c":"2721723272"},"book-1000","WAVES/EUR"]
1618678136.0524428: [992,{"b":[["354.22000000","0.00000000","1618678136.021958"]],"c":"739014304"},"book-1000","XMR/USD"]
1618678136.064544: [1920,{"a":[["0.043330","135920.00000000","1618678136.037718"]],"c":"3966361932"},"book-1000","SC/EUR"]
1618678136.0688581: [1920,{"a":[["0.043200","42461.83886926","1618678136.041473"]],"c":"2243774338"},"book-1000","SC/EUR"]
1618678136.07961: [1920,{"b":[["0.042930","0.00000000","1618678136.051188"]],"c":"854041476"},"book-1000","SC/EUR"]
1618678136.0826812: [1920,{"a":[["0.043360","145838.00000000","1618678136.051297"]],"c":"4063594447"},"book-1000","SC/EUR"]
1618678136.088657: [1920,{"a":[["0.043140","0.00000000","1618678136.061004"]],"c":"1340011155"},"book-1000","SC/EUR"]
1618678136.094054: [992,{"b":[["354.27000000","6.88180184","1618678136.063584"]],"c":"2368705194"},"book-1000","XMR/USD"]
1618678136.110781: [992,{"b":[["353.75000000","52.00000000","1618678136.082148"]],"c":"2414625782"},"book-1000","XMR/USD"]
1618678136.129806: [992,{"b":[["354.26000000","0.00000000","1618678136.103593"]],"c":"571395617"},"book-1000","XMR/USD"]
1618678136.1391842: [1920,{"b":[["0.042790","0.00000000","1618678136.111396"]],"c":"138067910"},"book-1000","SC/EUR"]
1618678136.147464: [1920,{"b":[["0.042980","30581.37592640","1618678136.119252"]],"c":"123196566"},"book-1000","SC/EUR"]
1618678136.150957: [1920,{"a":[["0.043310","0.00000000","1618678136.120996"]],"c":"1004335584"},"book-1000","SC/EUR"]
1618678136.1538408: [1920,{"b":[["0.042960","189336.00000000","1618678136.121477"]],"c":"1268528833"},"book-1000","SC/EUR"]
1618678136.156079: [1360,{"a":[["0.000022900","8259.85314526","1618678136.121729"]],"c":"394927907"},"book-1000","ADA/XBT"]
1618678136.158814: [1920,{"a":[["0.043320","183452.67067430","1618678136.124989"]],"c":"71568795"},"book-1000","SC/EUR"]
1618678136.161029: [992,{"a":[["354.90000000","12.24000000","1618678136.125794"]],"c":"1085616095"},"book-1000","XMR/USD"]
1618678136.162764: [1920,{"a":[["0.043200","45810.52742514","1618678136.128374"]],"c":"3913005513"},"book-1000","SC/EUR"]
1618678136.164955: [1920,{"b":[["0.042870","778843.23400000","1618678136.130812"]],"c":"4235158638"},"book-1000","SC/EUR"]
1618678136.167042: [1920,{"b":[["0.042840","0.00000000","1618678136.131975"]],"c":"205860359"},"book-1000","SC/EUR"]
1618678136.169064: [1920,{"a":[["0.043260","905325.33415860","1618678136.132536"]],"c":"2125364101"},"book-1000","SC/EUR"]
1618678136.171032: [992,{"b":[["354.31000000","1.40000000","1618678136.132607"]],"c":"3369808613"},"book-1000","XMR/USD"]
1618678136.1726348: [1840,{"a":[["9.596672","157.02318400","1618678136.134381"]],"c":"2537577311"},"book-1000","OMG/USD"]
1618678136.173414: [1360,{"b":[["0.000022810","12468.00000000","1618678136.137536"]],"c":"1327900702"},"book-1000","ADA/XBT"]
1618678136.1987011: [1920,{"b":[["0.042690","577288.45906328","1618678136.170182"]],"c":"1712507518"},"book-1000","SC/EUR"]
1618678136.213683: [1840,{"a":[["9.596671","200.00000000","1618678136.187111"]],"c":"4171136858"},"book-1000","OMG/USD"]
1618678136.228598: [1360,{"b":[["0.000022810","8000.00000000","1618678136.201624"]],"c":"813048501"},"book-1000","ADA/XBT"]
1618678136.238504: [992,{"b":[["354.28000000","5.00000000","1618678136.211657"]],"c":"2255220413"},"book-1000","XMR/USD"]
1618678136.241708: [992,{"a":[["355.75000000","5.00000000","1618678136.211899"]],"c":"2255220413"},"book-1000","XMR/USD"]
1618678136.245769: [1920,{"a":[["0.043190","11802.77325050","1618678136.218181"]],"c":"4001897144"},"book-1000","SC/EUR"]
1618678136.248802: [1360,{"a":[["0.000022900","7175.08484526","1618678136.219661"]],"c":"3531283918"},"book-1000","ADA/XBT"]
1618678136.254533: [992,{"a":[["354.74000000","0.00000000","1618678136.226511"]],"c":"3142995436"},"book-1000","XMR/USD"]
1618678136.2566988: [464,{"b":[["56111.80000","0.00000000","1618678136.228155"]],"c":"1740639334"},"book-1000","XBT/CHF"]
1618678136.268626: [3648,{"b":[["0.00756200","0.80300000","1618678136.240957"]],"c":"1158403980"},"book-1000","KSM/XBT"]
1618678136.276312: [1920,{"a":[["0.043210","22763.32081137","1618678136.249200"]],"c":"2314852773"},"book-1000","SC/EUR"]
1618678136.283818: [1840,{"b":[["9.584186","136.97698969","1618678136.256395"]],"c":"98545873"},"book-1000","OMG/USD"]
1618678136.291179: [1360,{"b":[["0.000022870","10111.78357373","1618678136.263280"]],"c":"1074604146"},"book-1000","ADA/XBT"]
1618678136.2949681: [992,{"b":[["354.29000000","22.72500000","1618678136.263374"]],"c":"3886517539"},"book-1000","XMR/USD"]
1618678136.297056: [992,{"a":[["356.13000000","22.72500000","1618678136.263477"]],"c":"3886517539"},"book-1000","XMR/USD"]
1618678136.299124: [992,{"b":[["354.23000000","7.57500000","1618678136.264867"]],"c":"4100875503"},"book-1000","XMR/USD"]
1618678136.300844: [1840,{"a":[["9.596673","0.00000000","1618678136.266116"]],"c":"3339704177"},"book-1000","OMG/USD"]
1618678136.301733: [992,{"a":[["354.70000000","0.00000000","1618678136.268208"]],"c":"2278711110"},"book-1000","XMR/USD"]
1618678136.303426: {"event":"heartbeat"}
1618678136.303584: [992,{"a":[["354.89000000","6.88152980","1618678136.272285"]],"c":"2408685490"},"book-1000","XMR/USD"]
1618678136.319082: [992,{"b":[["352.94000000","7.51443554","1618678136.291125"]],"c":"2408685490"},"book-1000","XMR/USD"]
1618678136.321953: [992,{"b":[["354.29000000","30.30000000","1618678136.292140"]],"c":"109715702"},"book-1000","XMR/USD"]
1618678136.327498: [1360,{"b":[["0.000022840","33495.46641260","1618678136.296396"]],"c":"3433734290"},"book-1000","ADA/XBT"]
1618678136.331041: [1360,{"b":[["0.000022870","8886.28357373","1618678136.299380"]],"c":"3570501355"},"book-1000","ADA/XBT"]
1618678136.3340192: [1360,{"b":[["0.000022880","14599.78110000","1618678136.302527"]],"c":"145681118"},"book-1000","ADA/XBT"]
1618678136.3558981: [992,{"b":[["354.30000000","5.00000000","1618678136.328689"]],"c":"2283744044"},"book-1000","XMR/USD"]
1618678136.35823: [1360,{"a":[["0.000023010","0.00000000","1618678136.330126"]],"c":"145681118"},"book-1000","ADA/XBT"]
1618678136.394764: [1360,{"a":[["0.000022910","10440.62893789","1618678136.366473"]],"c":"648351987"},"book-1000","ADA/XBT"]
1618678136.399998: [1360,{"a":[["0.000023020","17720.85077651","1618678136.372894"]],"c":"648351987"},"book-1000","ADA/XBT"]
1618678136.411523: [992,{"b":[["354.28000000","0.00000000","1618678136.383632"]],"c":"1811686220"},"book-1000","XMR/USD"]
1618678136.414492: [992,{"b":[["354.23000000","0.00000000","1618678136.384298"]],"c":"345623956"},"book-1000","XMR/USD"]
1618678136.416834: [992,{"b":[["354.31000000","24.12500000","1618678136.387830"]],"c":"2343836429"},"book-1000","XMR/USD"]
1618678136.437469: [1920,{"a":[["0.043230","10324.15010000","1618678136.409650"]],"c":"3890546758"},"book-1000","SC/EUR"]
1618678136.443159: [1920,{"a":[["0.043360","0.00000000","1618678136.415410"]],"c":"215755875"},"book-1000","SC/EUR"]
1618678136.4464939: [3648,{"a":[["0.00758700","4.95000000","1618678136.417048"]],"c":"4153897974"},"book-1000","KSM/XBT"]
1618678136.447401: [3648,{"b":[["0.00755200","7.22388316","1618678136.418120"]],"c":"4252710319"},"book-1000","KSM/XBT"]
1618678136.45342: [1360,{"a":[["0.000022930","1242.63590000","1618678136.425615"]],"c":"930822367"},"book-1000","ADA/XBT"]
1618678136.464582: [1840,{"b":[["9.573902","0.00000000","1618678136.436617"]],"c":"3314797579"},"book-1000","OMG/USD"]
1618678136.466159: [992,{"b":[["354.29000000","7.57500000","1618678136.437783"]],"c":"3852427761"},"book-1000","XMR/USD"]
1618678136.489909: [1840,{"a":[["9.596674","0.00000000","1618678136.461180"]],"c":"2637557441"},"book-1000","OMG/USD"]
1618678136.527325: [1664,{"a":[["13.273700","0.00000000","1618678136.499902"]],"c":"134693342"},"book-1000","WAVES/EUR"]
1618678136.5315259: [1920,{"b":[["0.042960","144586.00000000","1618678136.503795"]],"c":"2180830825"},"book-1000","SC/EUR"]
1618678136.534595: [1840,{"a":[["9.596670","136.95095027","1618678136.504179"]],"c":"1544965260"},"book-1000","OMG/USD"]
1618678136.57518: [1920,{"a":[["0.043210","4506.95535554","1618678136.547036"]],"c":"762644466"},"book-1000","SC/EUR"]
1618678136.5790348: [1840,{"a":[["9.596671","256.80000000","1618678136.549601"]],"c":"670700500"},"book-1000","OMG/USD"]
1618678136.580286: [1840,{"a":[["9.596669","200.00000000","1618678136.554054"]],"c":"1059605314"},"book-1000","OMG/USD"]
1618678136.58702: [1664,{"b":[["13.227900","97.00000000","1618678136.559957"]],"c":"2248817921"},"book-1000","WAVES/EUR"]
1618678136.591058: [1664,{"b":[["13.221300","0.00000000","1618678136.563890"]],"c":"770326746"},"book-1000","WAVES/EUR"]
1618678137.2529888: [1664,{"b":[["13.224400","500.00000000","1618678137.224863"]],"c":"3270516535"},"book-1000","WAVES/EUR"]
1618678137.2977338: {"event":"heartbeat"}
1618678137.6788359: [1920,{"a":[["0.043200","3348.68855588","1618678137.639392"]],"c":"362943069"},"book-1000","SC/EUR"]
1618678137.682344: [1840,{"a":[["9.600564","62.80000000","1618678137.639705"]],"c":"4229201717"},"book-1000","OMG/USD"]
1618678137.683406: [1920,{"a":[["0.043210","0.00000000","1618678137.640504"]],"c":"2745838"},"book-1000","SC/EUR"]
1618678137.686201: [992,{"b":[["352.94000000","0.17106559","1618678137.642600"]],"c":"3852427761"},"book-1000","XMR/USD"]
1618678137.688024: [1360,{"b":[["0.000022860","30527.61559016","1618678137.649899"]],"c":"3539035846"},"book-1000","ADA/XBT"]
1618678137.698485: [5104,{"a":[["0.000027810","1289.83757069","1618678137.661972"]],"c":"3528270516"},"book-1000","OCEAN/XBT"]
1618678137.699763: [3648,{"b":[["0.00755200","2.27388316","1618678137.662600"]],"c":"4153897974"},"book-1000","KSM/XBT"]
1618678137.700864: [992,{"a":[["710.46000000","0.00000000","1618678137.663292"]],"c":"3852427761"},"book-1000","XMR/USD"]
1618678137.7067251: [1920,{"a":[["0.043190","32444.00422022","1618678137.677037"]],"c":"1449970928"},"book-1000","SC/EUR"]
1618678137.710142: [1920,{"a":[["0.043270","1186028.00000000","1618678137.677106"]],"c":"1300018376"},"book-1000","SC/EUR"]
1618678137.728698: [1840,{"a":[["9.596671","56.80000000","1618678137.698273"]],"c":"2627866242"},"book-1000","OMG/USD"]
1618678137.730609: [1920,{"b":[["0.042790","743308.10000000","1618678137.703135"]],"c":"1630931101"},"book-1000","SC/EUR"]
1618678137.7337751: [1664,{"a":[["13.253800","103.00000000","1618678137.705377"]],"c":"2008685017"},"book-1000","WAVES/EUR"]
1618678137.735156: [1360,{"a":[["0.000022900","8433.38484526","1618678137.705875"]],"c":"4018646994"},"book-1000","ADA/XBT"]
1618678137.739511: [1920,{"b":[["0.042940","0.00000000","1618678137.713107"]],"c":"1522141084"},"book-1000","SC/EUR"]
1618678137.7496629: [1920,{"a":[["0.043330","0.00000000","1618678137.722728"]],"c":"4018629705"},"book-1000","SC/EUR"]
1618678137.753403: [496,{"b":[["2185.10000","0.82991777","1618678137.725612"]],"c":"2576796646"},"book-1000","ETH/CHF"]
1618678137.7543108: [1664,{"b":[["13.231000","0.00000000","1618678137.726043"]],"c":"2903647310"},"book-1000","WAVES/EUR"]
1618678137.756015: [1920,{"b":[["0.040960","23245.00232450","1618678137.727135"]],"c":"4018629705"},"book-1000","SC/EUR"]
1618678137.758349: [1920,{"b":[["0.042870","2332.63400000","1618678137.727571"]],"c":"4231325044"},"book-1000","SC/EUR"]
1618678137.760649: [1664,{"b":[["13.231200","0.00000000","1618678137.730086"]],"c":"3684572526"},"book-1000","WAVES/EUR"]
1618678137.761694: [1920,{"b":[["0.042960","0.00000000","1618678137.732026"]],"c":"3476127259"},"book-1000","SC/EUR"]
1618678137.777927: [1664,{"a":[["13.276400","66.18383578","1618678137.749865"]],"c":"3684572526"},"book-1000","WAVES/EUR"]
1618678137.793849: [992,{"a":[["364.87000000","0.00000000","1618678137.765832"]],"c":"3852427761"},"book-1000","XMR/USD"]
1618678137.796951: [3648,{"b":[["0.00756400","1.08792000","1618678137.768688"]],"c":"1809113763"},"book-1000","KSM/XBT"]
1618678137.798033: [3648,{"a":[["0.00758500","0.00000000","1618678137.771847"]],"c":"1985264245"},"book-1000","KSM/XBT"]
1618678137.800247: [992,{"a":[["364.64000000","47.54512948","1618678137.773433"]],"c":"3852427761"},"book-1000","XMR/USD"]
1618678137.807212: [1920,{"a":[["0.043200","23348.68855588","1618678137.780219"]],"c":"1134451842"},"book-1000","SC/EUR"]
1618678137.8119318: [1360,{"b":[["0.000022870","14886.28357373","1618678137.785312"]],"c":"1532779169"},"book-1000","ADA/XBT"]
1618678137.81625: [1920,{"a":[["0.043180","18491.03212250","1618678137.789299"]],"c":"225138431"},"book-1000","SC/EUR"]
1618678137.824362: [1920,{"b":[["0.043080","14392.33712585","1618678137.796398"]],"c":"3805878799"},"book-1000","SC/EUR"]
1618678137.8287182: [1360,{"a":[["0.000022900","10621.80509022","1618678137.799259"]],"c":"1453649009"},"book-1000","ADA/XBT"]
1618678137.831789: [1360,{"b":[["0.000022750","0.00000000","1618678137.799589"]],"c":"1453649009"},"book-1000","ADA/XBT"]
1618678137.834222: [1360,{"b":[["0.000022880","8599.78110000","1618678137.800090"]],"c":"3995076854"},"book-1000","ADA/XBT"]
1618678137.836598: [1360,{"a":[["0.000022910","16440.62893789","1618678137.800300"]],"c":"906656720"},"book-1000","ADA/XBT"]
1618678137.838978: [1360,{"b":[["0.000022760","21540.55602706","1618678137.801596"]],"c":"906656720"},"book-1000","ADA/XBT"]
1618678137.841551: [992,{"b":[["354.32000000","5.00000000","1618678137.807766"]],"c":"443202390"},"book-1000","XMR/USD"]
1618678137.843245: [1360,{"a":[["0.000022910","14252.50492087","1618678137.813103"]],"c":"2724536378"},"book-1000","ADA/XBT"]
1618678137.845506: [992,{"a":[["354.85000000","1.40000000","1618678137.813368"]],"c":"144580628"},"book-1000","XMR/USD"]
1618678137.848392: [1360,{"b":[["0.000022870","19886.28357373","1618678137.819612"]],"c":"4238487986"},"book-1000","ADA/XBT"]
1618678137.85243: [992,{"b":[["354.27000000","0.00000000","1618678137.822962"]],"c":"1877810326"},"book-1000","XMR/USD"]
1618678137.85743: [1664,{"b":[["13.222300","0.00000000","1618678137.826174"]],"c":"3066352259"},"book-1000","WAVES/EUR"]
1618678137.859057: [1360,{"a":[["0.000022910","15315.97812087","1618678137.826930"]],"c":"401317413"},"book-1000","ADA/XBT"]
1618678137.8620532: [1920,{"a":[["0.043270","1190534.95535554","1618678137.830623"]],"c":"247432338"},"book-1000","SC/EUR"]
1618678137.8644202: [1664,{"a":[["13.276200","276.39468506","1618678137.833052"]],"c":"3066352259"},"book-1000","WAVES/EUR"]
1618678137.8668742: [1360,{"b":[["0.000022880","9670.70100000","1618678137.838870"]],"c":"139760136"},"book-1000","ADA/XBT"]
1618678137.869389: [1360,{"b":[["0.000022880","4670.70100000","1618678137.839839"]],"c":"3439957895"},"book-1000","ADA/XBT"]
1618678137.8716521: [1360,{"a":[["0.000022950","12340.22471303","1618678137.840223"]],"c":"103262274"},"book-1000","ADA/XBT"]
1618678137.8739982: [992,{"b":[["349.99000000","23.77188847","1618678137.843408"]],"c":"1877810326"},"book-1000","XMR/USD"]
1618678137.875527: [1920,{"b":[["0.042680","0.00000000","1618678137.843488"]],"c":"247432338"},"book-1000","SC/EUR"]
1618678137.8774772: [464,{"b":[["55575.10000","0.00000000","1618678137.846170"]],"c":"1740639334"},"book-1000","XBT/CHF"]
1618678137.878745: [464,{"a":[["56914.70000","0.55644760","1618678137.851058"]],"c":"1740639334"},"book-1000","XBT/CHF"]
1618678137.8808022: [3648,{"a":[["0.00758900","16.42134035","1618678137.852717"]],"c":"2578326323"},"book-1000","KSM/XBT"]
1618678137.88383: [1360,{"b":[["0.000022880","3599.78110000","1618678137.856220"]],"c":"625833039"},"book-1000","ADA/XBT"]
1618678137.888051: [1920,{"a":[["0.043270","1049453.95535554","1618678137.861133"]],"c":"2817955726"},"book-1000","SC/EUR"]
1618678137.89234: [1920,{"a":[["0.043180","60952.87099176","1618678137.864859"]],"c":"366939073"},"book-1000","SC/EUR"]
1618678137.89479: [992,{"b":[["349.03000000","0.00000000","1618678137.868421"]],"c":"1877810326"},"book-1000","XMR/USD"]
1618678137.900189: [1664,{"b":[["13.224400","0.00000000","1618678137.872434"]],"c":"4236310759"},"book-1000","WAVES/EUR"]
1618678137.902304: [1840,{"b":[["8.941611","0.00000000","1618678137.874779"]],"c":"2627866242"},"book-1000","OMG/USD"]
1618678137.903751: [464,{"a":[["56916.30000","0.00000000","1618678137.877143"]],"c":"1740639334"},"book-1000","XBT/CHF"]
1618678137.907728: [1840,{"a":[["9.596670","0.00000000","1618678137.880121"]],"c":"2454506227"},"book-1000","OMG/USD"]
1618678137.909156: [464,{"b":[["55573.50000","0.55644760","1618678137.881015"]],"c":"1740639334"},"book-1000","XBT/CHF"]
1618678137.911835: [1840,{"a":[["9.596668","136.94652919","1618678137.883242"]],"c":"3749209819"},"book-1000","OMG/USD"]
1618678137.912986: [1920,{"b":[["0.042690","0.00000000","1618678137.884210"]],"c":"3736834903"},"book-1000","SC/EUR"]
1618678137.915573: [1920,{"a":[["0.043480","183452.67067430","1618678137.884804"]],"c":"1135966818"},"book-1000","SC/EUR"]
1618678137.917875: [1920,{"a":[["0.043320","0.00000000","1618678137.885804"]],"c":"1223729539"},"book-1000","SC/EUR"]
1618678137.923352: [992,{"a":[["364.64000000","0.00000000","1618678137.896504"]],"c":"1877810326"},"book-1000","XMR/USD"]
1618678137.934456: [3648,{"b":[["0.00756400","0.00000000","1618678137.907305"]],"c":"99463782"},"book-1000","KSM/XBT"]
1618678137.943156: [992,{"b":[["354.36000000","1.40000000","1618678137.914929"]],"c":"2991088450"},"book-1000","XMR/USD"]
1618678137.946327: [1664,{"a":[["13.253700","500.00000000","1618678137.918272"]],"c":"1309063064"},"book-1000","WAVES/EUR"]
1618678137.9478688: [1920,{"b":[["0.042980","0.00000000","1618678137.919453"]],"c":"308948742"},"book-1000","SC/EUR"]
1618678137.9504719: [1920,{"b":[["0.042880","72672.69356343","1618678137.919808"]],"c":"1993379351"},"book-1000","SC/EUR"]
1618678137.952678: [1664,{"b":[["13.231400","158.57068022","1618678137.920565"]],"c":"3603926956"},"book-1000","WAVES/EUR"]
1618678137.95373: [1664,{"a":[["13.345200","0.00000000","1618678137.921526"]],"c":"3603926956"},"book-1000","WAVES/EUR"]
1618678137.9549692: [1664,{"b":[["13.220400","500.00000000","1618678137.924289"]],"c":"883515651"},"book-1000","WAVES/EUR"]
1618678137.956042: [992,{"b":[["354.32000000","12.57500000","1618678137.925130"]],"c":"1083052652"},"book-1000","XMR/USD"]
1618678137.9577448: [992,{"a":[["355.08000000","7.57500000","1618678137.925388"]],"c":"2225019123"},"book-1000","XMR/USD"]
1618678137.959407: [1920,{"b":[["0.042680","448012.92057160","1618678137.927729"]],"c":"1382722729"},"book-1000","SC/EUR"]
1618678137.961659: [992,{"a":[["354.89000000","0.00000000","1618678137.932452"]],"c":"1948885565"},"book-1000","XMR/USD"]
1618678137.9710069: [3648,{"b":[["0.00754600","0.00000000","1618678137.944120"]],"c":"3555945218"},"book-1000","KSM/XBT"]
1618678137.978552: [1920,{"b":[["0.040910","0.00000000","1618678137.951384"]],"c":"1382722729"},"book-1000","SC/EUR"]
1618678137.982304: [1840,{"b":[["8.889953","26.06661589","1618678137.955903"]],"c":"3749209819"},"book-1000","OMG/USD"]
1618678137.985539: [1920,{"b":[["0.042890","577288.45906328","1618678137.958566"]],"c":"3973183178"},"book-1000","SC/EUR"]
1618678137.9886332: [3648,{"b":[["0.00749800","5.54913333","1618678137.959891"]],"c":"3555945218"},"book-1000","KSM/XBT"]
1618678137.98972: [992,{"b":[["354.31000000","22.72500000","1618678137.960224"]],"c":"2093865556"},"book-1000","XMR/USD"]
1618678137.991605: [3648,{"b":[["0.00756200","0.21000000","1618678137.961575"]],"c":"57594345"},"book-1000","KSM/XBT"]
1618678137.993522: [992,{"a":[["354.84000000","6.85270489","1618678137.964732"]],"c":"973061391"},"book-1000","XMR/USD"]
1618678137.995479: [1840,{"a":[["9.596670","200.00000000","1618678137.967728"]],"c":"2583772518"},"book-1000","OMG/USD"]
1618678138.000056: [992,{"b":[["354.30000000","0.00000000","1618678137.969679"]],"c":"2018055253"},"book-1000","XMR/USD"]
1618678138.007761: [1920,{"b":[["0.042920","0.00000000","1618678137.977334"]],"c":"1580024130"},"book-1000","SC/EUR"]
1618678138.011282: [1920,{"b":[["0.042680","0.00000000","1618678137.977581"]],"c":"1424033734"},"book-1000","SC/EUR"]
1618678138.01391: [992,{"b":[["354.33000000","22.72500000","1618678137.978213"]],"c":"1258917496"},"book-1000","XMR/USD"]
1618678138.015848: [1664,{"a":[["13.257600","0.00000000","1618678137.980329"]],"c":"91783855"},"book-1000","WAVES/EUR"]
1618678138.016931: [1664,{"b":[["13.231300","0.00000000","1618678137.981332"]],"c":"3907910113"},"book-1000","WAVES/EUR"]
1618678138.017954: [1920,{"a":[["0.043180","42461.83886926","1618678137.983536"]],"c":"660477090"},"book-1000","SC/EUR"]
1618678138.0199091: [1920,{"a":[["0.043260","0.00000000","1618678137.985185"]],"c":"426486571"},"book-1000","SC/EUR"]
1618678138.02197: [1840,{"b":[["9.578702","0.00000000","1618678137.992872"]],"c":"1908679596"},"book-1000","OMG/USD"]
1618678138.022729: [1840,{"b":[["9.580728","0.00000000","1618678137.994277"]],"c":"186230863"},"book-1000","OMG/USD"]
1618678138.023436: [1360,{"a":[["0.000022920","13969.81403419","1618678137.994860"]],"c":"249499030"},"book-1000","ADA/XBT"]
1618678138.025698: [1840,{"a":[["9.596669","0.00000000","1618678137.996420"]],"c":"3369703106"},"book-1000","OMG/USD"]
1618678138.027602: [3648,{"a":[["0.00758300","1.34617811","1618678137.998945"]],"c":"3931816336"},"book-1000","KSM/XBT"]
1618678138.03153: [992,{"a":[["354.85000000","4.88500000","1618678138.002764"]],"c":"1568893742"},"book-1000","XMR/USD"]
1618678138.0332868: [992,{"b":[["351.22000000","0.00000000","1618678138.003225"]],"c":"1568893742"},"book-1000","XMR/USD"]
1618678138.03473: [4528,{"a":[["0.000836100","1035.63462897","1618678138.004670"]],"c":"2922705373"},"book-1000","GRT/ETH"]
1618678138.036155: [1920,{"b":[["0.043080","0.00000000","1618678138.008550"]],"c":"4046060437"},"book-1000","SC/EUR"]
1618678138.038304: [4528,{"a":[["0.000844100","0.00000000","1618678138.009760"]],"c":"1417935183"},"book-1000","GRT/ETH"]
1618678138.038552: [3648,{"a":[["0.00758600","1.00000000","1618678138.010648"]],"c":"3130785202"},"book-1000","KSM/XBT"]
1618678138.0391731: [1840,{"b":[["9.582901","0.00000000","1618678138.012425"]],"c":"4226338022"},"book-1000","OMG/USD"]
1618678138.046916: [992,{"b":[["354.29000000","0.00000000","1618678138.013842"]],"c":"2439545633"},"book-1000","XMR/USD"]
1618678138.0488472: [1920,{"b":[["0.042860","58832.89187450","1618678138.020403"]],"c":"3677381831"},"book-1000","SC/EUR"]
1618678138.051119: [992,{"a":[["354.85000000","3.48500000","1618678138.023131"]],"c":"2545635775"},"book-1000","XMR/USD"]
1618678138.054464: [1920,{"a":[["0.043250","905325.33415860","1618678138.026439"]],"c":"4088080396"},"book-1000","SC/EUR"]
1618678138.056509: [992,{"a":[["354.80000000","1.40000000","1618678138.026509"]],"c":"2298116829"},"book-1000","XMR/USD"]
1618678138.057963: [1664,{"b":[["13.231500","151.15444204","1618678138.027425"]],"c":"3530683240"},"book-1000","WAVES/EUR"]
1618678138.059075: [3648,{"a":[["0.00758500","5.00000000","1618678138.031372"]],"c":"3148979139"},"book-1000","KSM/XBT"]
1618678138.073674: [1840,{"a":[["9.596667","200.00000000","1618678138.043519"]],"c":"179211269"},"book-1000","OMG/USD"]
1618678138.075263: [1840,{"a":[["9.596670","0.00000000","1618678138.043711"]],"c":"1339545528"},"book-1000","OMG/USD"]
1618678138.081656: [3648,{"b":[["0.00755200","0.00000000","1618678138.053320"]],"c":"1749221389"},"book-1000","KSM/XBT"]
1618678138.082943: [992,{"a":[["364.64000000","47.54548892","1618678138.054205"]],"c":"2298116829"},"book-1000","XMR/USD"]
1618678138.090136: [992,{"b":[["354.31000000","0.00000000","1618678138.062887"]],"c":"2510040278"},"book-1000","XMR/USD"]
1618678138.093303: [1920,{"b":[["0.042890","0.00000000","1618678138.064288"]],"c":"1499525027"},"book-1000","SC/EUR"]
1618678138.104458: [1664,{"a":[["13.270600","625.57300000","1618678138.077331"]],"c":"735208927"},"book-1000","WAVES/EUR"]
1618678138.107253: [1920,{"b":[["0.042870","0.00000000","1618678138.079159"]],"c":"869122114"},"book-1000","SC/EUR"]
1618678138.112837: [1664,{"b":[["13.199000","0.00000000","1618678138.085162"]],"c":"735208927"},"book-1000","WAVES/EUR"]
1618678138.114723: [464,{"b":[["55820.20000","0.00000000","1618678138.085531"]],"c":"1740639334"},"book-1000","XBT/CHF"]
1618678138.1201138: [1920,{"b":[["0.042880","42020.00000000","1618678138.093369"]],"c":"1229475276"},"book-1000","SC/EUR"]
1618678138.125001: [1920,{"b":[["0.042980","30581.37588632","1618678138.096725"]],"c":"2872227715"},"book-1000","SC/EUR"]
1618678138.1332211: [1664,{"b":[["13.215800","23.70000000","1618678138.105228"]],"c":"2445904472"},"book-1000","WAVES/EUR"]
1618678138.13535: [1664,{"a":[["13.253700","530.67000000","1618678138.106504"]],"c":"2365904035"},"book-1000","WAVES/EUR"]
1618678138.154965: [992,{"a":[["356.69000000","0.00000000","1618678138.127144"]],"c":"2510040278"},"book-1000","XMR/USD"]
1618678138.1689851: [1840,{"b":[["9.578487","0.00000000","1618678138.141291"]],"c":"3326518519"},"book-1000","OMG/USD"]
1618678138.181634: [992,{"a":[["359.40000000","0.00000000","1618678138.153806"]],"c":"2510040278"},"book-1000","XMR/USD"]
1618678138.188629: [1920,{"a":[["0.043320","23180.34306907","1618678138.161787"]],"c":"1738569582"},"book-1000","SC/EUR"]
1618678138.1913862: [3648,{"b":[["0.00755000","5.18381459","1618678138.163498"]],"c":"2017976488"},"book-1000","KSM/XBT"]
1618678138.200354: [3648,{"b":[["0.00750600","0.00000000","1618678138.172902"]],"c":"2017976488"},"book-1000","KSM/XBT"]
1618678138.203789: [464,{"b":[["55803.30000","0.84510000","1618678138.176019"]],"c":"1740639334"},"book-1000","XBT/CHF"]
1618678138.2051551: [1920,{"b":[["0.042900","41420.00000000","1618678138.178582"]],"c":"29400815"},"book-1000","SC/EUR"]
1618678138.215956: [4528,{"a":[["0.000836100","0.00000000","1618678138.188487"]],"c":"1919083466"},"book-1000","GRT/ETH"]
1618678138.222563: [3648,{"b":[["0.00755200","40.67000000","1618678138.195587"]],"c":"200215087"},"book-1000","KSM/XBT"]
1618678138.223927: [992,{"a":[["356.26000000","52.00000000","1618678138.196126"]],"c":"2510040278"},"book-1000","XMR/USD"]
1618678138.226547: [4528,{"a":[["0.000836100","531.16835699","1618678138.198334"]],"c":"1211935673"},"book-1000","GRT/ETH"]
1618678138.2353559: [1920,{"b":[["0.042950","2332.63400000","1618678138.206699"]],"c":"1941425568"},"book-1000","SC/EUR"]
1618678138.239128: [1920,{"a":[["0.043180","72461.83886926","1618678138.208679"]],"c":"1235754187"},"book-1000","SC/EUR"]
1618678138.24179: [464,{"b":[["56081.90000","0.00000000","1618678138.210410"]],"c":"844692234"},"book-1000","XBT/CHF"]
1618678138.243147: [992,{"b":[["354.34000000","5.00000000","1618678138.210607"]],"c":"1468273720"},"book-1000","XMR/USD"]
1618678138.247838: [464,{"b":[["55526.70000","0.81830725","1618678138.219427"]],"c":"844692234"},"book-1000","XBT/CHF"]
1618678138.249161: [3648,{"b":[["0.00755900","0.00000000","1618678138.221276"]],"c":"1907086452"},"book-1000","KSM/XBT"]
1618678138.2499871: [1664,{"b":[["13.206100","4.18349878","1618678138.222358"]],"c":"3703901859"},"book-1000","WAVES/EUR"]
1618678138.251255: [992,{"b":[["353.92000000","0.00000000","1618678138.223356"]],"c":"1524532611"},"book-1000","XMR/USD"]
1618678138.2529469: [1664,{"a":[["13.284300","0.00000000","1618678138.223654"]],"c":"3703901859"},"book-1000","WAVES/EUR"]
1618678138.266123: [3648,{"b":[["0.00755800","0.71800000","1618678138.238959"]],"c":"26500112"},"book-1000","KSM/XBT"]
1618678138.287068: [1920,{"a":[["0.043190","11802.77325050","1618678138.258454"]],"c":"4157082014"},"book-1000","SC/EUR"]
1618678138.290596: [992,{"b":[["354.32000000","7.57500000","1618678138.259245"]],"c":"2434957674"},"book-1000","XMR/USD"]
1618678138.292928: [3648,{"b":[["0.00756200","0.00000000","1618678138.262098"]],"c":"1146757860"},"book-1000","KSM/XBT"]
1618678138.293809: [1360,{"a":[["0.000022960","31576.53000000","1618678138.264059"]],"c":"2319214734"},"book-1000","ADA/XBT"]
1618678138.296566: [992,{"b":[["354.35000000","22.72500000","1618678138.267396"]],"c":"4133899152"},"book-1000","XMR/USD"]
1618678138.298333: [3648,{"b":[["0.00755900","0.21000000","1618678138.268714"]],"c":"3812746618"},"book-1000","KSM/XBT"]
1618678138.3025658: {"event":"heartbeat"}
1618678138.303262: [1664,{"b":[["13.188000","0.00000000","1618678138.276136"]],"c":"3703901859"},"book-1000","WAVES/EUR"]
1618678138.306994: [1920,{"a":[["0.043290","144645.00000000","1618678138.279399"]],"c":"3200504438"},"book-1000","SC/EUR"]
1618678138.3101041: [992,{"b":[["351.09000000","169.87848200","1618678138.279849"]],"c":"4133899152"},"book-1000","XMR/USD"]
1618678138.312333: [1664,{"b":[["13.216500","415.00000000","1618678138.281707"]],"c":"48987351"},"book-1000","WAVES/EUR"]
1618678138.313447: [1664,{"a":[["13.312800","1396.00000000","1618678138.282409"]],"c":"48987351"},"book-1000","WAVES/EUR"]
1618678138.314686: [3648,{"b":[["0.00755600","4.44960054","1618678138.286450"]],"c":"3978526074"},"book-1000","KSM/XBT"]
1618678138.336598: [992,{"b":[["354.35000000","30.30000000","1618678138.309032"]],"c":"1758270878"},"book-1000","XMR/USD"]
1618678138.354032: [1664,{"b":[["13.199300","143.35200000","1618678138.326682"]],"c":"48987351"},"book-1000","WAVES/EUR"]
1618678138.356265: [1920,{"a":[["0.043170","20000.00000000","1618678138.328360"]],"c":"2585072955"},"book-1000","SC/EUR"]
1618678138.384546: [1920,{"b":[["0.042990","14392.33712585","1618678138.356525"]],"c":"1247188125"},"book-1000","SC/EUR"]
1618678138.388085: [992,{"b":[["354.32000000","0.00000000","1618678138.357869"]],"c":"140056391"},"book-1000","XMR/USD"]
1618678138.390151: [992,{"b":[["354.33000000","0.00000000","1618678138.358150"]],"c":"1948143941"},"book-1000","XMR/USD"]
1618678138.405586: [1920,{"a":[["0.043490","0.00000000","1618678138.378153"]],"c":"1247188125"},"book-1000","SC/EUR"]
1618678138.411075: [992,{"b":[["354.37000000","6.85462332","1618678138.384046"]],"c":"3542823357"},"book-1000","XMR/USD"]
1618678138.416644: [5104,{"b":[["0.000027610","31.87756907","1618678138.387689"]],"c":"1788748117"},"book-1000","OCEAN/XBT"]
1618678138.417762: [3648,{"a":[["0.00758300","41.06617811","1618678138.389080"]],"c":"3740364755"},"book-1000","KSM/XBT"]
1618678138.421616: [1920,{"b":[["0.042980","0.00000000","1618678138.393791"]],"c":"830051930"},"book-1000","SC/EUR"]
1618678138.424913: [3648,{"a":[["0.00759000","0.00000000","1618678138.394062"]],"c":"106774427"},"book-1000","KSM/XBT"]
1618678138.4257972: [1920,{"b":[["0.043000","30567.15179291","1618678138.394590"]],"c":"2186117551"},"book-1000","SC/EUR"]
1618678138.4284642: [1920,{"b":[["0.043060","14392.33712585","1618678138.395365"]],"c":"3386596289"},"book-1000","SC/EUR"]
1618678138.4338439: [1840,{"b":[["9.577324","108.93857148","1618678138.401036"]],"c":"4201843145"},"book-1000","OMG/USD"]
1618678138.437553: [1920,{"a":[["0.043180","93045.65195118","1618678138.408973"]],"c":"1660982038"},"book-1000","SC/EUR"]
1618678138.465162: [992,{"a":[["358.65000000","170.68848700","1618678138.433683"]],"c":"3542823357"},"book-1000","XMR/USD"]
1618678138.47242: [1920,{"a":[["0.043250","0.00000000","1618678138.439996"]],"c":"332203345"},"book-1000","SC/EUR"]
1618678138.475977: [1920,{"b":[["0.042800","577288.45906328","1618678138.443208"]],"c":"2748862284"},"book-1000","SC/EUR"]
1618678138.484205: [992,{"b":[["354.38000000","1.40000000","1618678138.455530"]],"c":"1758082483"},"book-1000","XMR/USD"]
1618678138.487039: [992,{"b":[["354.36000000","0.00000000","1618678138.455772"]],"c":"730758662"},"book-1000","XMR/USD"]
1618678138.507284: [1920,{"a":[["0.043240","906825.33415860","1618678138.479848"]],"c":"2331027495"},"book-1000","SC/EUR"]
1618678138.517914: [1664,{"b":[["13.231400","0.00000000","1618678138.490746"]],"c":"129788360"},"book-1000","WAVES/EUR"]
1618678138.5198138: [1920,{"a":[["0.043200","3348.68855588","1618678138.491171"]],"c":"96916654"},"book-1000","SC/EUR"]
1618678138.522974: [5104,{"a":[["0.000027810","671.30348000","1618678138.494114"]],"c":"2401296084"},"book-1000","OCEAN/XBT"]
1618678138.541642: [1664,{"b":[["13.195000","65.99256858","1618678138.515230"]],"c":"129788360"},"book-1000","WAVES/EUR"]
1618678138.547286: [1920,{"a":[["0.043240","1500.00000000","1618678138.518493"]],"c":"4064125886"},"book-1000","SC/EUR"]
1618678138.563073: [496,{"b":[["2183.82000","0.00000000","1618678138.535376"]],"c":"98610295"},"book-1000","ETH/CHF"]
1618678138.570038: [464,{"b":[["55817.50000","0.42096216","1618678138.543586"]],"c":"844692234"},"book-1000","XBT/CHF"]
1618678138.572313: [1920,{"b":[["0.042990","0.00000000","1618678138.543646"]],"c":"3359552260"},"book-1000","SC/EUR"]
1618678138.582168: [1664,{"a":[["13.345200","4.17098583","1618678138.553617"]],"c":"129788360"},"book-1000","WAVES/EUR"]
1618678138.58408: [1360,{"a":[["0.000023540","14596.00000000","1618678138.556424"]],"c":"2319214734"},"book-1000","ADA/XBT"]
1618678138.592941: [992,{"a":[["354.82000000","11.52000000","1618678138.564149"]],"c":"354127087"},"book-1000","XMR/USD"]
1618678138.610152: [1920,{"b":[["0.043060","0.00000000","1618678138.582834"]],"c":"1147003880"},"book-1000","SC/EUR"]
1618678138.625588: [1360,{"a":[["0.000023510","34411.37285835","1618678138.597612"]],"c":"2319214734"},"book-1000","ADA/XBT"]
1618678138.639759: [496,{"a":[["2192.55000","0.79681000","1618678138.610937"]],"c":"4059931370"},"book-1000","ETH/CHF"]
1618678138.64131: [496,{"a":[["2192.69000","0.00000000","1618678138.610995"]],"c":"1110590562"},"book-1000","ETH/CHF"]
1618678138.682763: [1360,{"b":[["0.000022880","0.00000000","1618678138.655784"]],"c":"1737108315"},"book-1000","ADA/XBT"]
1618678138.686518: [5104,{"b":[["0.000027630","14063.56025489","1618678138.656709"]],"c":"3554164820"},"book-1000","OCEAN/XBT"]
1618678138.687354: [1664,{"a":[["13.274700","119.15886375","1618678138.656798"]],"c":"3040275493"},"book-1000","WAVES/EUR"]
1618678138.6889422: [1664,{"a":[["13.276100","0.00000000","1618678138.660054"]],"c":"3040275493"},"book-1000","WAVES/EUR"]
1618678138.690374: [496,{"a":[["2192.54000","3.00000000","1618678138.662199"]],"c":"134271837"},"book-1000","ETH/CHF"]
1618678138.739297: [496,{"a":[["2192.68000","0.00000000","1618678138.709551"]],"c":"878952311"},"book-1000","ETH/CHF"]
1618678138.747726: [5104,{"a":[["0.000027820","2449.57413284","1618678138.714415"]],"c":"2182617718"},"book-1000","OCEAN/XBT"]
1618678138.7490208: [1360,{"b":[["0.000022860","34129.36099016","1618678138.715439"]],"c":"3460834160"},"book-1000","ADA/XBT"]
1618678138.7619042: [992,{"b":[["354.35000000","7.57500000","1618678138.733848"]],"c":"3849392348"},"book-1000","XMR/USD"]
1618678138.772761: [464,{"b":[["56043.60000","0.00000000","1618678138.744302"]],"c":"710745069"},"book-1000","XBT/CHF"]
1618678138.774922: [464,{"b":[["55973.20000","0.15000000","1618678138.744372"]],"c":"1442785087"},"book-1000","XBT/CHF"]
1618678138.7950542: [992,{"a":[["355.27000000","59.76157570","1618678138.765743"]],"c":"4228563709"},"book-1000","XMR/USD"]
1618678138.804491: [1664,{"b":[["13.195000","0.00000000","1618678138.775831"]],"c":"3040275493"},"book-1000","WAVES/EUR"]
1618678138.807779: [992,{"b":[["354.35000000","0.00000000","1618678138.779554"]],"c":"3849938065"},"book-1000","XMR/USD"]
1618678138.8293278: [496,{"b":[["2182.94000","0.00000000","1618678138.801181"]],"c":"21597381"},"book-1000","ETH/CHF"]
1618678138.834413: [1664,{"b":[["13.195900","0.00000000","1618678138.806818"]],"c":"3040275493"},"book-1000","WAVES/EUR"]
1618678138.8363478: [992,{"b":[["353.95000000","7.00000000","1618678138.807465"]],"c":"2045568421"},"book-1000","XMR/USD"]
1618678138.839947: [1920,{"b":[["0.041000","1487059.00000000","1618678138.812365"]],"c":"1147003880"},"book-1000","SC/EUR"]
1618678138.845068: [3648,{"b":[["0.00755800","1.80677000","1618678138.817884"]],"c":"591385509"},"book-1000","KSM/XBT"]
1618678138.867137: [992,{"b":[["352.55000000","0.00000000","1618678138.838113"]],"c":"2045568421"},"book-1000","XMR/USD"]
1618678138.904306: [5104,{"a":[["0.000028290","0.00000000","1618678138.876304"]],"c":"2182617718"},"book-1000","OCEAN/XBT"]
1618678138.919521: [3648,{"b":[["0.00756000","0.16890103","1618678138.885173"]],"c":"2979102685"},"book-1000","KSM/XBT"]
1618678138.926216: [992,{"b":[["353.86000000","0.00000000","1618678138.891107"]],"c":"4124050734"},"book-1000","XMR/USD"]
1618678138.934415: [992,{"b":[["352.88000000","7.34714826","1618678138.894251"]],"c":"4124050734"},"book-1000","XMR/USD"]
1618678138.937271: [464,{"b":[["55817.50000","0.00000000","1618678138.897452"]],"c":"1442785087"},"book-1000","XBT/CHF"]
1618678138.95056: [1920,{"b":[["0.042970","163780.76157391","1618678138.919124"]],"c":"215796988"},"book-1000","SC/EUR"]
1618678138.956877: [3648,{"b":[["0.00755900","0.00000000","1618678138.924250"]],"c":"89686932"},"book-1000","KSM/XBT"]
1618678138.9580622: [3648,{"b":[["0.00756100","0.21000000","1618678138.924657"]],"c":"1810087630"},"book-1000","KSM/XBT"]
1618678138.959145: [1360,{"b":[["0.000022870","19854.52647546","1618678138.929937"]],"c":"162919370"},"book-1000","ADA/XBT"]
1618678138.984481: [1920,{"a":[["0.044250","0.00000000","1618678138.953403"]],"c":"215796988"},"book-1000","SC/EUR"]
1618678138.991115: [1840,{"a":[["9.596668","0.00000000","1618678138.958313"]],"c":"1039294962"},"book-1000","OMG/USD"]
1618678139.022979: [1840,{"a":[["9.596666","136.96072585","1618678138.985465"]],"c":"1059398334"},"book-1000","OMG/USD"]
1618678139.026487: [1360,{"b":[["0.000022880","31.75709827","1618678138.990191"]],"c":"786018244"},"book-1000","ADA/XBT"]
1618678139.02986: [1920,{"a":[["0.043270","1044947.00000000","1618678138.992751"]],"c":"3370953389"},"book-1000","SC/EUR"]
1618678139.032653: [1840,{"a":[["9.611450","194.10704088","1618678138.998503"]],"c":"1059398334"},"book-1000","OMG/USD"]
1618678139.033588: [1840,{"a":[["9.618100","0.00000000","1618678138.998843"]],"c":"1059398334"},"book-1000","OMG/USD"]
1618678139.039808: [1664,{"b":[["13.196900","66.00134438","1618678139.010505"]],"c":"3040275493"},"book-1000","WAVES/EUR"]
1618678139.0644732: [1840,{"b":[["9.578951","150.00000000","1618678139.033099"]],"c":"3952065603"},"book-1000","OMG/USD"]
1618678139.0660648: [992,{"a":[["354.84000000","0.00000000","1618678139.033632"]],"c":"587230520"},"book-1000","XMR/USD"]
1618678139.079294: [1840,{"a":[["9.601969","143.00000000","1618678139.048312"]],"c":"2464032886"},"book-1000","OMG/USD"]
1618678139.084673: [1360,{"b":[["0.000022890","0.00000000","1618678139.053884"]],"c":"3630878957"},"book-1000","ADA/XBT"]
1618678139.104843: [992,{"a":[["354.79000000","6.85284537","1618678139.074079"]],"c":"2653183611"},"book-1000","XMR/USD"]
1618678139.114666: [4528,{"a":[["0.000836100","0.00000000","1618678139.084573"]],"c":"1919083466"},"book-1000","GRT/ETH"]
1618678139.11852: [4528,{"a":[["0.000836100","1095.84475706","1618678139.087011"]],"c":"406839985"},"book-1000","GRT/ETH"]
1618678139.129825: [1664,{"b":[["13.035100","0.00000000","1618678139.100569"]],"c":"3040275493"},"book-1000","WAVES/EUR"]
1618678139.138344: [1840,{"a":[["9.618091","0.00000000","1618678139.106562"]],"c":"2464032886"},"book-1000","OMG/USD"]
1618678139.145358: [1920,{"b":[["0.043000","0.00000000","1618678139.115431"]],"c":"1075871266"},"book-1000","SC/EUR"]
1618678139.148876: [992,{"a":[["354.80000000","0.00000000","1618678139.115530"]],"c":"4165055083"},"book-1000","XMR/USD"]
1618678139.1551008: [1920,{"b":[["0.042980","30581.37588632","1618678139.125395"]],"c":"559860164"},"book-1000","SC/EUR"]
1618678139.158614: [1360,{"b":[["0.000022870","17666.76413900","1618678139.125810"]],"c":"2612149604"},"book-1000","ADA/XBT"]
1618678139.170439: [1664,{"b":[["13.032100","1602.64257119","1618678139.140396"]],"c":"3040275493"},"book-1000","WAVES/EUR"]
1618678139.1750212: [992,{"a":[["354.75000000","1.40000000","1618678139.144856"]],"c":"1538832783"},"book-1000","XMR/USD"]
1618678139.1871092: [5104,{"b":[["0.000027690","1541.02630356","1618678139.155760"]],"c":"2725196040"},"book-1000","OCEAN/XBT"]
1618678139.1884181: [1920,{"a":[["0.043260","905325.33415860","1618678139.155844"]],"c":"2426519903"},"book-1000","SC/EUR"]
1618678139.20225: [1360,{"b":[["0.000022880","2220.43441812","1618678139.167782"]],"c":"417843023"},"book-1000","ADA/XBT"]
1618678139.2381032: [5104,{"b":[["0.000027700","1256.83759214","1618678139.204151"]],"c":"422088163"},"book-1000","OCEAN/XBT"]
1618678139.272959: [496,{"b":[["2185.26000","1.51146973","1618678139.237862"]],"c":"1335224649"},"book-1000","ETH/CHF"]
1618678139.2745001: [496,{"b":[["2182.55000","3.00000000","1618678139.237936"]],"c":"2466575727"},"book-1000","ETH/CHF"]
1618678139.275553: [1664,{"a":[["13.312800","0.00000000","1618678139.238251"]],"c":"3040275493"},"book-1000","WAVES/EUR"]
1618678139.277146: [1360,{"b":[["0.000022850","8723.80308692","1618678139.239301"]],"c":"2952646524"},"book-1000","ADA/XBT"]
1618678139.280138: [1664,{"b":[["13.216500","0.00000000","1618678139.239566"]],"c":"2559161870"},"book-1000","WAVES/EUR"]
1618678139.3034508: [1920,{"b":[["0.042990","5801.62352520","1618678139.265019"]],"c":"3802783030"},"book-1000","SC/EUR"]
1618678139.3069649: [1920,{"b":[["0.043000","14392.33712585","1618678139.265265"]],"c":"769394338"},"book-1000","SC/EUR"]
1618678139.3099: [992,{"b":[["340.15000000","66.00000000","1618678139.270170"]],"c":"1538832783"},"book-1000","XMR/USD"]
1618678139.3117561: [992,{"b":[["354.34000000","0.00000000","1618678139.271038"]],"c":"3613390895"},"book-1000","XMR/USD"]
1618678139.313493: [992,{"b":[["353.76000000","5.00000000","1618678139.271527"]],"c":"3094223534"},"book-1000","XMR/USD"]
1618678139.315229: {"event":"heartbeat"}
1618678139.315239: [992,{"a":[["355.75000000","0.00000000","1618678139.276231"]],"c":"3094223534"},"book-1000","XMR/USD"]
1618678139.328591: [1664,{"a":[["13.284500","1396.00000000","1618678139.299760"]],"c":"2559161870"},"book-1000","WAVES/EUR"]
1618678139.3330612: [3648,{"a":[["0.00758300","46.01617811","1618678139.301691"]],"c":"1006611780"},"book-1000","KSM/XBT"]
1618678139.344794: [992,{"b":[["347.73000000","86.10198419","1618678139.314300"]],"c":"3094223534"},"book-1000","XMR/USD"]
1618678139.347093: [496,{"b":[["2182.55000","0.00000000","1618678139.314790"]],"c":"1335224649"},"book-1000","ETH/CHF"]
1618678139.3493938: [1920,{"a":[["0.043200","0.00000000","1618678139.315684"]],"c":"616599864"},"book-1000","SC/EUR"]
1618678139.35289: [1664,{"b":[["13.206300","415.00000000","1618678139.319580"]],"c":"1293764021"},"book-1000","WAVES/EUR"]
1618678139.35442: [992,{"b":[["354.38000000","8.97500000","1618678139.320639"]],"c":"1463310792"},"book-1000","XMR/USD"]
1618678139.356408: [992,{"b":[["354.38000000","31.70000000","1618678139.321516"]],"c":"98052810"},"book-1000","XMR/USD"]
1618678139.358117: [464,{"b":[["56056.70000","0.00000000","1618678139.323959"]],"c":"2053556357"},"book-1000","XBT/CHF"]
1618678139.3595939: [1920,{"b":[["0.042940","142039.00000000","1618678139.328561"]],"c":"2795971901"},"book-1000","SC/EUR"]
1618678139.406708: [496,{"b":[["2181.93000","0.00000000","1618678139.375725"]],"c":"2828562945"},"book-1000","ETH/CHF"]
1618678139.4082592: [1920,{"a":[["0.043160","3348.65131686","1618678139.376321"]],"c":"1545495049"},"book-1000","SC/EUR"]
1618678139.4114199: [1920,{"a":[["0.043250","4506.95535554","1618678139.378853"]],"c":"4053031605"},"book-1000","SC/EUR"]
1618678139.41423: [992,{"a":[["354.82000000","0.00000000","1618678139.383254"]],"c":"3238830901"},"book-1000","XMR/USD"]
1618678139.418551: [1840,{"b":[["9.580201","200.00000000","1618678139.388997"]],"c":"896697417"},"book-1000","OMG/USD"]
1618678139.4340422: [1360,{"b":[["0.000022870","11666.76413900","1618678139.404268"]],"c":"1162574773"},"book-1000","ADA/XBT"]
1618678139.459091: [464,{"b":[["55820.30000","0.00000000","1618678139.422662"]],"c":"1471888001"},"book-1000","XBT/CHF"]
1618678139.461335: [464,{"b":[["55807.30000","0.43970731","1618678139.428755"]],"c":"2900654955"},"book-1000","XBT/CHF"]
1618678139.471309: [992,{"b":[["354.37000000","0.00000000","1618678139.441069"]],"c":"1770565690"},"book-1000","XMR/USD"]
1618678139.4771688: [1360,{"b":[["0.000022880","7263.43645571","1618678139.446560"]],"c":"3508938254"},"book-1000","ADA/XBT"]
1618678139.4841201: [1920,{"b":[["0.042920","38460.00000000","1618678139.451002"]],"c":"2376853645"},"book-1000","SC/EUR"]
1618678139.487649: [1840,{"a":[["9.596667","0.00000000","1618678139.457021"]],"c":"2440164620"},"book-1000","OMG/USD"]
1618678139.4887402: [1840,{"a":[["9.596670","200.00000000","1618678139.457551"]],"c":"3865613020"},"book-1000","OMG/USD"]
1618678139.500373: [1920,{"b":[["0.043000","0.00000000","1618678139.469772"]],"c":"2522731124"},"book-1000","SC/EUR"]
1618678139.512664: [992,{"b":[["354.39000000","6.85349010","1618678139.481567"]],"c":"28591943"},"book-1000","XMR/USD"]
1618678139.54905: [992,{"b":[["354.38000000","30.30000000","1618678139.522183"]],"c":"2812480267"},"book-1000","XMR/USD"]
1618678139.557955: [992,{"b":[["354.40000000","7.57500000","1618678139.529648"]],"c":"3883281828"},"book-1000","XMR/USD"]
1618678139.561991: [992,{"b":[["354.40000000","30.30000000","1618678139.534908"]],"c":"3077927357"},"book-1000","XMR/USD"]
1618678139.584408: [992,{"b":[["354.43000000","1.40000000","1618678139.556937"]],"c":"2999983116"},"book-1000","XMR/USD"]
1618678139.5872939: [1840,{"a":[["9.596665","200.00000000","1618678139.558475"]],"c":"1589565311"},"book-1000","OMG/USD"]
1618678139.598599: [1920,{"a":[["0.043160","37268.65131686","1618678139.570669"]],"c":"3543535036"},"book-1000","SC/EUR"]
1618678139.609674: [1664,{"b":[["13.215800","0.00000000","1618678139.582691"]],"c":"3549911618"},"book-1000","WAVES/EUR"]
1618678139.611586: [1840,{"a":[["9.615304","440.22330000","1618678139.582794"]],"c":"1589565311"},"book-1000","OMG/USD"]
1618678139.612888: [1920,{"b":[["0.042970","143780.76157391","1618678139.583492"]],"c":"3640027542"},"book-1000","SC/EUR"]
1618678139.61967: [1664,{"b":[["13.208600","25.62000000","1618678139.591434"]],"c":"1891133987"},"book-1000","WAVES/EUR"]
1618678139.63613: [1840,{"a":[["9.596670","0.00000000","1618678139.607001"]],"c":"3743809226"},"book-1000","OMG/USD"]
1618678139.6375701: [1360,{"b":[["0.000022880","2220.43441812","1618678139.610058"]],"c":"1162574773"},"book-1000","ADA/XBT"]
1618678139.6488671: [992,{"b":[["354.38000000","22.72500000","1618678139.619810"]],"c":"1194769685"},"book-1000","XMR/USD"]
1618678139.6874099: [3648,{"a":[["0.00758600","0.00000000","1618678139.659139"]],"c":"4020853566"},"book-1000","KSM/XBT"]
1618678139.705417: [992,{"b":[["354.38000000","0.00000000","1618678139.676338"]],"c":"441653230"},"book-1000","XMR/USD"]
1618678139.78594: [1664,{"b":[["13.193800","132.36946140","1618678139.758168"]],"c":"1891133987"},"book-1000","WAVES/EUR"]
1618678139.798239: [496,{"a":[["2214.19000","0.00000000","1618678139.769372"]],"c":"2828562945"},"book-1000","ETH/CHF"]
1618678139.799627: [496,{"b":[["2118.27000","0.00000000","1618678139.769443"]],"c":"2828562945"},"book-1000","ETH/CHF"]
1618678139.802351: [1920,{"b":[["0.042920","0.00000000","1618678139.773315"]],"c":"2409061027"},"book-1000","SC/EUR"]
1618678139.805901: [1920,{"b":[["0.042810","20000.00000000","1618678139.778800"]],"c":"1618083170"},"book-1000","SC/EUR"]
1618678139.8157172: [1920,{"a":[["0.043180","50583.81308192","1618678139.788030"]],"c":"2561254892"},"book-1000","SC/EUR"]
1618678139.8201568: [1920,{"b":[["0.042970","5799.76157391","1618678139.794406"]],"c":"4121169997"},"book-1000","SC/EUR"]
1618678139.822674: [496,{"a":[["2213.40000","14.28774479","1618678139.794992"]],"c":"2828562945"},"book-1000","ETH/CHF"]
1618678139.868105: [496,{"b":[["2116.28000","28.57504000","1618678139.806365"]],"c":"2828562945"},"book-1000","ETH/CHF"]
1618678139.8694751: [1920,{"a":[["0.043160","57268.65131686","1618678139.822820"]],"c":"926552634"},"book-1000","SC/EUR"]
1618678139.87253: [1920,{"a":[["0.043180","30000.00000000","1618678139.824371"]],"c":"161261191"},"book-1000","SC/EUR"]
1618678139.875116: [1920,{"b":[["0.042980","0.00000000","1618678139.826028"]],"c":"1478226848"},"book-1000","SC/EUR"]
1618678139.87737: [1920,{"b":[["0.043000","20000.00000000","1618678139.826368"]],"c":"2833194997"},"book-1000","SC/EUR"]
1618678139.8796391: [1920,{"a":[["0.043150","42461.83886926","1618678139.830260"]],"c":"1249398909"},"book-1000","SC/EUR"]
1618678139.882074: [1360,{"b":[["0.000022870","18338.29117813","1618678139.845997"]],"c":"3911399208"},"book-1000","ADA/XBT"]
1618678139.892416: [1920,{"b":[["0.042680","447934.82474220","1618678139.864070"]],"c":"1249398909"},"book-1000","SC/EUR"]
1618678139.896211: [464,{"b":[["55807.30000","0.00000000","1618678139.864909"]],"c":"1471888001"},"book-1000","XBT/CHF"]
1618678139.90488: [1920,{"a":[["0.043150","62461.83886926","1618678139.875359"]],"c":"1926438889"},"book-1000","SC/EUR"]
1618678139.90841: [1920,{"a":[["0.043170","0.00000000","1618678139.875585"]],"c":"3235237435"},"book-1000","SC/EUR"]
1618678139.974376: [992,{"b":[["352.88000000","0.00000000","1618678139.945465"]],"c":"441653230"},"book-1000","XMR/USD"]
1618678140.0581398: [992,{"b":[["354.40000000","34.30000000","1618678140.028479"]],"c":"2079345639"},"book-1000","XMR/USD"]
1618678140.060997: [1920,{"a":[["0.043130","8500.00000000","1618678140.029748"]],"c":"2363323372"},"book-1000","SC/EUR"]
1618678140.070923: [464,{"a":[["56734.80000","0.00000000","1618678140.043458"]],"c":"1471888001"},"book-1000","XBT/CHF"]
1618678140.075958: [1840,{"a":[["9.596666","0.00000000","1618678140.046656"]],"c":"2369823974"},"book-1000","OMG/USD"]
1618678140.082473: [1920,{"b":[["0.042950","10832.63400000","1618678140.054679"]],"c":"34965158"},"book-1000","SC/EUR"]
1618678140.100249: [1920,{"b":[["0.042950","2332.63400000","1618678140.073427"]],"c":"2363323372"},"book-1000","SC/EUR"]
1618678140.104044: [1920,{"b":[["0.042960","8500.00000000","1618678140.076423"]],"c":"2350953256"},"book-1000","SC/EUR"]
1618678140.112299: [1840,{"a":[["9.596664","136.96453430","1618678140.084984"]],"c":"2572281358"},"book-1000","OMG/USD"]
1618678140.124114: [992,{"b":[["354.39000000","0.00000000","1618678140.096597"]],"c":"2228347788"},"book-1000","XMR/USD"]
1618678140.145198: [464,{"b":[["55803.40000","0.43677128","1618678140.117793"]],"c":"1041001890"},"book-1000","XBT/CHF"]
1618678140.147437: [1920,{"b":[["0.043000","0.00000000","1618678140.118172"]],"c":"3875433850"},"book-1000","SC/EUR"]
1618678140.1505358: [1920,{"b":[["0.043000","30567.15249907","1618678140.120723"]],"c":"3757561309"},"book-1000","SC/EUR"]
1618678140.158419: [992,{"b":[["354.40000000","30.30000000","1618678140.131770"]],"c":"3849502597"},"book-1000","XMR/USD"]
1618678140.16127: [992,{"a":[["354.79000000","0.00000000","1618678140.132197"]],"c":"1353241131"},"book-1000","XMR/USD"]
1618678140.163558: [1920,{"b":[["0.042970","14299.76157391","1618678140.134226"]],"c":"338034770"},"book-1000","SC/EUR"]
1618678140.166094: [1840,{"a":[["9.596663","200.00000000","1618678140.134539"]],"c":"3676322186"},"book-1000","OMG/USD"]
1618678140.166985: [1920,{"b":[["0.042960","0.00000000","1618678140.135139"]],"c":"1016458621"},"book-1000","SC/EUR"]
1618678140.190358: [992,{"b":[["354.40000000","7.57500000","1618678140.161125"]],"c":"2278969718"},"book-1000","XMR/USD"]
1618678140.200813: [992,{"a":[["354.74000000","6.85516463","1618678140.173726"]],"c":"3167389958"},"book-1000","XMR/USD"]
1618678140.203903: [992,{"a":[["354.75000000","0.00000000","1618678140.177594"]],"c":"1858178536"},"book-1000","XMR/USD"]
1618678140.206157: [992,{"a":[["354.81000000","1.40000000","1618678140.178043"]],"c":"171084721"},"book-1000","XMR/USD"]
1618678140.208106: [5104,{"a":[["0.000027840","636.76396000","1618678140.179013"]],"c":"2518526544"},"book-1000","OCEAN/XBT"]
1618678140.208961: [992,{"a":[["355.43000000","4.57411888","1618678140.180741"]],"c":"350497065"},"book-1000","XMR/USD"]
1618678140.211811: [992,{"a":[["355.58000000","0.00000000","1618678140.183379"]],"c":"350497065"},"book-1000","XMR/USD"]
1618678140.217474: [1840,{"a":[["9.596665","0.00000000","1618678140.190311"]],"c":"3178334799"},"book-1000","OMG/USD"]
1618678140.240622: [992,{"b":[["354.05000000","6.85509621","1618678140.212893"]],"c":"2344989357"},"book-1000","XMR/USD"]
1618678140.243474: [1920,{"a":[["0.043250","0.00000000","1618678140.213595"]],"c":"2073781469"},"book-1000","SC/EUR"]
1618678140.2465138: [992,{"b":[["354.43000000","0.00000000","1618678140.214725"]],"c":"2623755213"},"book-1000","XMR/USD"]
1618678140.252115: [464,{"b":[["56097.70000","0.00000000","1618678140.224429"]],"c":"1310535574"},"book-1000","XBT/CHF"]
1618678140.2645319: [992,{"b":[["352.55000000","11.88000000","1618678140.232643"]],"c":"2623755213"},"book-1000","XMR/USD"]
1618678140.2684858: [992,{"b":[["352.76000000","7.34766767","1618678140.239467"]],"c":"2623755213"},"book-1000","XMR/USD"]
1618678140.270707: [1360,{"b":[["0.000022880","7263.89480176","1618678140.240649"]],"c":"1052404673"},"book-1000","ADA/XBT"]
1618678140.2736452: [992,{"a":[["354.81000000","0.00000000","1618678140.246984"]],"c":"3426370636"},"book-1000","XMR/USD"]
1618678140.2803571: [992,{"b":[["353.49000000","22.72500000","1618678140.252177"]],"c":"3426370636"},"book-1000","XMR/USD"]
1618678140.283496: [464,{"b":[["55803.40000","0.86921023","1618678140.256226"]],"c":"628884948"},"book-1000","XBT/CHF"]
1618678140.304076: {"event":"heartbeat"}
1618678140.308915: [464,{"b":[["56097.80000","0.00000000","1618678140.280471"]],"c":"4112472538"},"book-1000","XBT/CHF"]
1618678140.311457: [464,{"b":[["56060.00000","0.05891820","1618678140.281768"]],"c":"1690466270"},"book-1000","XBT/CHF"]
1618678140.313141: [464,{"b":[["56071.30000","0.01700000","1618678140.282527"]],"c":"3919680303"},"book-1000","XBT/CHF"]
1618678140.3266518: [1360,{"a":[["0.000022920","14002.32710046","1618678140.300310"]],"c":"98180925"},"book-1000","ADA/XBT"]
1618678140.330646: [1920,{"b":[["0.042900","0.00000000","1618678140.302486"]],"c":"3464950710"},"book-1000","SC/EUR"]
1618678140.3335092: [5104,{"a":[["0.000027820","1212.45426368","1618678140.305660"]],"c":"584175131"},"book-1000","OCEAN/XBT"]
1618678140.342773: [992,{"b":[["352.55000000","0.00000000","1618678140.315192"]],"c":"3426370636"},"book-1000","XMR/USD"]
1618678140.35458: [1920,{"a":[["0.043160","37268.65131686","1618678140.326172"]],"c":"475225144"},"book-1000","SC/EUR"]
1618678140.3581471: [1360,{"b":[["0.000022880","2220.43441812","1618678140.327308"]],"c":"3527623636"},"book-1000","ADA/XBT"]
1618678140.3613498: [1920,{"a":[["0.043250","140799.00000000","1618678140.329248"]],"c":"604555952"},"book-1000","SC/EUR"]
1618678140.38164: [1920,{"a":[["0.043210","4506.95535554","1618678140.352298"]],"c":"3773853807"},"book-1000","SC/EUR"]
1618678140.388185: [1360,{"b":[["0.000022850","9270.55196993","1618678140.360864"]],"c":"3799914352"},"book-1000","ADA/XBT"]
1618678140.392004: [1360,{"a":[["0.000022910","15283.46505460","1618678140.362260"]],"c":"3550383544"},"book-1000","ADA/XBT"]
1618678140.398823: [1360,{"b":[["0.000022870","11666.76413900","1618678140.370490"]],"c":"2146877733"},"book-1000","ADA/XBT"]
1618678140.4041421: [1920,{"a":[["0.043260","0.00000000","1618678140.375707"]],"c":"1493106339"},"book-1000","SC/EUR"]
1618678140.4118242: [4528,{"a":[["0.000836100","0.00000000","1618678140.384094"]],"c":"1919083466"},"book-1000","GRT/ETH"]
1618678140.425607: [4528,{"a":[["0.000836100","152.04077657","1618678140.397165"]],"c":"1964292359"},"book-1000","GRT/ETH"]
1618678140.4449291: [1920,{"a":[["0.043240","906825.33415860","1618678140.417277"]],"c":"1118212344"},"book-1000","SC/EUR"]
1618678140.47156: [1360,{"b":[["0.000022880","31.75709827","1618678140.443264"]],"c":"3545731247"},"book-1000","ADA/XBT"]
1618678140.48723: [5104,{"a":[["0.000027860","16415.25602280","1618678140.459349"]],"c":"3889525881"},"book-1000","OCEAN/XBT"]
1618678140.514575: [1360,{"b":[["0.000022870","13856.07296368","1618678140.486606"]],"c":"3110647220"},"book-1000","ADA/XBT"]
1618678140.527264: [5104,{"a":[["0.000027850","732.36854110","1618678140.498324"]],"c":"4165847456"},"book-1000","OCEAN/XBT"]
1618678140.528586: [5104,{"a":[["0.000027870","0.00000000","1618678140.500228"]],"c":"2913370639"},"book-1000","OCEAN/XBT"]
1618678140.558483: [992,{"b":[["354.40000000","0.00000000","1618678140.531382"]],"c":"3219584339"},"book-1000","XMR/USD"]
1618678140.5607738: [992,{"b":[["354.33000000","7.57500000","1618678140.531723"]],"c":"2366543217"},"book-1000","XMR/USD"]
1618678140.5684538: [5104,{"a":[["0.000027830","1625.68606312","1618678140.540631"]],"c":"2234720765"},"book-1000","OCEAN/XBT"]
1618678140.573557: [1840,{"b":[["9.439504","0.00000000","1618678140.545956"]],"c":"3178334799"},"book-1000","OMG/USD"]
1618678140.593607: [1920,{"b":[["0.040920","23277.46741154","1618678140.564340"]],"c":"1118212344"},"book-1000","SC/EUR"]
1618678140.600679: [1920,{"b":[["0.043000","0.00000000","1618678140.572839"]],"c":"3824306052"},"book-1000","SC/EUR"]
1618678140.6094139: [992,{"b":[["354.06000000","22.72500000","1618678140.580938"]],"c":"3488437506"},"book-1000","XMR/USD"]
1618678140.612253: [992,{"a":[["355.75000000","5.00000000","1618678140.582149"]],"c":"3488437506"},"book-1000","XMR/USD"]
1618678140.614316: [992,{"b":[["354.06000000","27.72500000","1618678140.582587"]],"c":"3237650329"},"book-1000","XMR/USD"]
1618678140.633023: [3648,{"b":[["0.00755800","0.71800000","1618678140.605824"]],"c":"4062303207"},"book-1000","KSM/XBT"]
1618678140.644418: [1920,{"a":[["0.043250","0.00000000","1618678140.616664"]],"c":"3076296349"},"book-1000","SC/EUR"]
1618678140.654271: [1920,{"a":[["0.043130","46450.00000000","1618678140.625498"]],"c":"1930895592"},"book-1000","SC/EUR"]
1618678140.6579998: [1920,{"b":[["0.042860","38650.00000000","1618678140.630578"]],"c":"3621808590"},"book-1000","SC/EUR"]
1618678140.663091: [992,{"b":[["354.06000000","5.00000000","1618678140.632956"]],"c":"1751493900"},"book-1000","XMR/USD"]
1618678140.665706: [992,{"b":[["354.06000000","0.00000000","1618678140.636450"]],"c":"2366543217"},"book-1000","XMR/USD"]
1618678140.684306: [3648,{"b":[["0.00756100","1.29874000","1618678140.656061"]],"c":"1452100140"},"book-1000","KSM/XBT"]
1618678140.688778: [1920,{"a":[["0.043240","1500.00000000","1618678140.660421"]],"c":"1693350482"},"book-1000","SC/EUR"]
1618678140.698229: [1920,{"a":[["0.043130","37950.00000000","1618678140.668192"]],"c":"3500589938"},"book-1000","SC/EUR"]
1618678140.70175: [1920,{"a":[["0.043110","8500.00000000","1618678140.668316"]],"c":"3289816137"},"book-1000","SC/EUR"]
1618678140.715706: [992,{"b":[["354.33000000","0.00000000","1618678140.686444"]],"c":"3219584339"},"book-1000","XMR/USD"]
1618678140.722563: [464,{"a":[["56734.20000","0.04055036","1618678140.694104"]],"c":"3919680303"},"book-1000","XBT/CHF"]
1618678140.7265222: [1920,{"a":[["0.043230","915649.48425860","1618678140.699352"]],"c":"328435401"},"book-1000","SC/EUR"]
1618678140.736383: [992,{"b":[["353.74000000","2.94083399","1618678140.709330"]],"c":"4128132777"},"book-1000","XMR/USD"]
1618678140.765132: [1920,{"a":[["0.043230","10324.15010000","1618678140.738077"]],"c":"3289816137"},"book-1000","SC/EUR"]
1618678140.801425: [1920,{"b":[["0.040960","0.00000000","1618678140.769980"]],"c":"3289816137"},"book-1000","SC/EUR"]
1618678140.825247: [464,{"b":[["55803.40000","0.43677128","1618678140.793199"]],"c":"4157403140"},"book-1000","XBT/CHF"]
1618678140.834464: [1840,{"b":[["9.486855","3095.89963300","1618678140.807635"]],"c":"3178334799"},"book-1000","OMG/USD"]
1618678140.886801: [1920,{"a":[["0.043110","56520.00000000","1618678140.857862"]],"c":"3028958904"},"book-1000","SC/EUR"]
1618678140.904042: [992,{"a":[["354.77000000","11.52000000","1618678140.876688"]],"c":"391362545"},"book-1000","XMR/USD"]
1618678140.9230149: [1360,{"b":[["0.000022880","5075.74835402","1618678140.895294"]],"c":"1339077928"},"book-1000","ADA/XBT"]
1618678140.927029: [1920,{"a":[["0.043110","48020.00000000","1618678140.896074"]],"c":"154791229"},"book-1000","SC/EUR"]
1618678140.9297578: [1920,{"a":[["0.043090","8500.00000000","1618678140.896532"]],"c":"2320402416"},"book-1000","SC/EUR"]
1618678140.9321978: [992,{"b":[["354.06000000","7.00000000","1618678140.900135"]],"c":"1795451908"},"book-1000","XMR/USD"]
1618678140.93419: [464,{"a":[["56734.40000","0.00000000","1618678140.905982"]],"c":"4157403140"},"book-1000","XBT/CHF"]
1618678140.966431: [5104,{"b":[["0.000027720","666.72387000","1618678140.938465"]],"c":"3965971408"},"book-1000","OCEAN/XBT"]
1618678140.967755: [5104,{"b":[["0.000027700","638.19459000","1618678140.939212"]],"c":"2268538666"},"book-1000","OCEAN/XBT"]
1618678140.979771: [1920,{"a":[["0.043840","0.00000000","1618678140.951703"]],"c":"2320402416"},"book-1000","SC/EUR"]
1618678140.998733: [992,{"b":[["353.95000000","0.00000000","1618678140.970070"]],"c":"286028779"},"book-1000","XMR/USD"]
1618678141.001942: [464,{"b":[["56033.80000","0.00000000","1618678140.975374"]],"c":"784647962"},"book-1000","XBT/CHF"]
1618678141.012309: [464,{"b":[["56011.00000","0.01136000","1618678140.984411"]],"c":"842635203"},"book-1000","XBT/CHF"]
1618678141.014857: [1920,{"a":[["0.043480","206633.01374337","1618678140.987319"]],"c":"2320402416"},"book-1000","SC/EUR"]
1618678141.048126: [1920,{"a":[["0.043580","45615.00000000","1618678141.018379"]],"c":"2320402416"},"book-1000","SC/EUR"]
1618678141.056628: [464,{"a":[["56218.40000","0.01270000","1618678141.029442"]],"c":"2528438211"},"book-1000","XBT/CHF"]
1618678141.059078: [3648,{"a":[["0.00758900","14.15000000","1618678141.032057"]],"c":"2715005813"},"book-1000","KSM/XBT"]
1618678141.087889: [992,{"b":[["269.01000000","0.00000000","1618678141.060240"]],"c":"286028779"},"book-1000","XMR/USD"]
1618678141.10406: [1920,{"a":[["0.043180","0.00000000","1618678141.073645"]],"c":"2805835702"},"book-1000","SC/EUR"]
1618678141.1076539: [1920,{"b":[["0.042880","0.00000000","1618678141.074841"]],"c":"3152315603"},"book-1000","SC/EUR"]
1618678141.1102889: [464,{"a":[["56218.30000","0.00000000","1618678141.078000"]],"c":"2334370585"},"book-1000","XBT/CHF"]
1618678141.111934: [464,{"a":[["56250.50000","0.15000000","1618678141.078110"]],"c":"1751619447"},"book-1000","XBT/CHF"]
1618678141.1145952: [1920,{"b":[["0.042680","0.00000000","1618678141.086486"]],"c":"4202578250"},"book-1000","SC/EUR"]
1618678141.1210299: [1920,{"a":[["0.043090","46440.00000000","1618678141.092837"]],"c":"625151956"},"book-1000","SC/EUR"]
1618678141.1238039: [5104,{"a":[["0.000027830","1237.29899486","1618678141.095112"]],"c":"2813010607"},"book-1000","OCEAN/XBT"]
1618678141.124704: [1920,{"b":[["0.042940","0.00000000","1618678141.095871"]],"c":"2256732811"},"book-1000","SC/EUR"]
1618678141.127216: [464,{"a":[["56192.90000","0.01700000","1618678141.100576"]],"c":"3961058593"},"book-1000","XBT/CHF"]
1618678141.131066: [1920,{"b":[["0.042980","30581.37632089","1618678141.104112"]],"c":"284192720"},"book-1000","SC/EUR"]
1618678141.135434: [1920,{"a":[["0.043290","0.00000000","1618678141.108747"]],"c":"284192720"},"book-1000","SC/EUR"]
1618678141.1432729: [1920,{"b":[["0.042970","5799.76157391","1618678141.115364"]],"c":"3620952264"},"book-1000","SC/EUR"]
1618678141.1507242: [1920,{"a":[["0.043480","23180.34306907","1618678141.122559"]],"c":"3620952264"},"book-1000","SC/EUR"]
1618678141.154502: [1920,{"a":[["0.043110","68020.00000000","1618678141.126212"]],"c":"199825931"},"book-1000","SC/EUR"]
1618678141.158529: [1920,{"b":[["0.042940","8500.00000000","1618678141.131909"]],"c":"3325008542"},"book-1000","SC/EUR"]
1618678141.162118: [1920,{"a":[["0.043180","17941.90365910","1618678141.132058"]],"c":"199559812"},"book-1000","SC/EUR"]
1618678141.1650162: [464,{"a":[["56734.10000","3.56787561","1618678141.135012"]],"c":"3961058593"},"book-1000","XBT/CHF"]
1618678141.166383: [1920,{"a":[["0.043080","8500.00000000","1618678141.135978"]],"c":"2107266605"},"book-1000","SC/EUR"]
1618678141.168514: [1920,{"a":[["0.043090","37940.00000000","1618678141.136304"]],"c":"3270043451"},"book-1000","SC/EUR"]
1618678141.172481: [5104,{"a":[["0.000027780","456.53817937","1618678141.143585"]],"c":"2340129151"},"book-1000","OCEAN/XBT"]
1618678141.173224: [1840,{"a":[["9.596664","0.00000000","1618678141.144174"]],"c":"4266878452"},"book-1000","OMG/USD"]
1618678141.175919: [1920,{"a":[["0.043080","0.00000000","1618678141.146702"]],"c":"1759930858"},"book-1000","SC/EUR"]
1618678141.1787121: [1920,{"a":[["0.043070","8500.00000000","1618678141.146959"]],"c":"2063465029"},"book-1000","SC/EUR"]
1618678141.184512: [1920,{"b":[["0.042800","0.00000000","1618678141.154415"]],"c":"1604853178"},"book-1000","SC/EUR"]
1618678141.1877198: [1920,{"a":[["0.043150","20000.00000000","1618678141.159077"]],"c":"2657977870"},"book-1000","SC/EUR"]
1618678141.193899: [1664,{"b":[["13.199300","0.00000000","1618678141.166631"]],"c":"1891133987"},"book-1000","WAVES/EUR"]
1618678141.203996: [5104,{"b":[["0.000027690","3024.39771009","1618678141.176091"]],"c":"2265727489"},"book-1000","OCEAN/XBT"]
1618678141.208501: [5104,{"b":[["0.000027690","1483.37140653","1618678141.182503"]],"c":"957827914"},"book-1000","OCEAN/XBT"]
1618678141.2096431: [5104,{"b":[["0.000027700","1257.08193317","1618678141.182721"]],"c":"3879967410"},"book-1000","OCEAN/XBT"]
1618678141.215178: [1840,{"a":[["9.596662","136.98895110","1618678141.187662"]],"c":"3729193702"},"book-1000","OMG/USD"]
1618678141.2218509: [1920,{"a":[["0.043320","0.00000000","1618678141.194001"]],"c":"2657977870"},"book-1000","SC/EUR"]
1618678141.228336: [1840,{"a":[["9.596663","0.00000000","1618678141.200481"]],"c":"2300749056"},"book-1000","OMG/USD"]
1618678141.2297769: [1840,{"a":[["9.596670","200.00000000","1618678141.200677"]],"c":"4265329360"},"book-1000","OMG/USD"]
1618678141.231023: [1664,{"b":[["13.206300","0.00000000","1618678141.201510"]],"c":"2771163544"},"book-1000","WAVES/EUR"]
1618678141.23233: [1664,{"a":[["13.284500","0.00000000","1618678141.202021"]],"c":"2771163544"},"book-1000","WAVES/EUR"]
1618678141.233838: [1920,{"a":[["0.043100","42461.83886926","1618678141.204313"]],"c":"3254966735"},"book-1000","SC/EUR"]
1618678141.236314: [1920,{"b":[["0.042980","0.00000000","1618678141.206892"]],"c":"1786097441"},"book-1000","SC/EUR"]
1618678141.239291: [5104,{"b":[["0.000027690","0.00000000","1618678141.210218"]],"c":"3020296193"},"book-1000","OCEAN/XBT"]
1618678141.240206: [992,{"b":[["354.07000000","5.00000000","1618678141.212186"]],"c":"1031880592"},"book-1000","XMR/USD"]
1618678141.245955: [1664,{"b":[["13.217200","500.00000000","1618678141.218537"]],"c":"1885113888"},"book-1000","WAVES/EUR"]
1618678141.2471209: [1664,{"b":[["13.220400","0.00000000","1618678141.218596"]],"c":"3795538885"},"book-1000","WAVES/EUR"]
1618678141.248364: [1920,{"a":[["0.043150","0.00000000","1618678141.220216"]],"c":"4025338101"},"book-1000","SC/EUR"]
1618678141.259052: [1664,{"b":[["13.189000","143.35200000","1618678141.229575"]],"c":"3795538885"},"book-1000","WAVES/EUR"]
1618678141.262198: [5104,{"b":[["0.000027660","1542.69769749","1618678141.234741"]],"c":"84318699"},"book-1000","OCEAN/XBT"]
1618678141.267446: [464,{"a":[["56218.30000","0.15000000","1618678141.239923"]],"c":"3839292795"},"book-1000","XBT/CHF"]
1618678141.288175: [1840,{"b":[["9.578951","0.00000000","1618678141.251813"]],"c":"1112086467"},"book-1000","OMG/USD"]
1618678141.289758: [1840,{"a":[["9.599964","142.00000000","1618678141.255059"]],"c":"1512594012"},"book-1000","OMG/USD"]
1618678141.29106: [464,{"a":[["56218.40000","0.00000000","1618678141.255904"]],"c":"3071824072"},"book-1000","XBT/CHF"]
1618678141.2926872: [1840,{"a":[["9.596661","200.00000000","1618678141.256866"]],"c":"2676445264"},"book-1000","OMG/USD"]
1618678141.294271: [992,{"b":[["354.08000000","22.72500000","1618678141.265986"]],"c":"2423150637"},"book-1000","XMR/USD"]
1618678141.29772: [1360,{"a":[["0.000022920","12979.32710046","1618678141.270753"]],"c":"2481436465"},"book-1000","ADA/XBT"]
1618678141.300662: [1664,{"b":[["13.216500","415.00000000","1618678141.270991"]],"c":"2447878472"},"book-1000","WAVES/EUR"]
1618678141.3052459: {"event":"heartbeat"}
1618678141.30967: [992,{"b":[["354.05000000","0.00000000","1618678141.274545"]],"c":"2048706989"},"book-1000","XMR/USD"]
1618678141.312122: [1920,{"b":[["0.042860","0.00000000","1618678141.278133"]],"c":"380468071"},"book-1000","SC/EUR"]
1618678141.3148: [1664,{"a":[["13.312800","1396.00000000","1618678141.279541"]],"c":"2447878472"},"book-1000","WAVES/EUR"]
1618678141.316066: [464,{"a":[["56192.90000","0.02907000","1618678141.282882"]],"c":"2072536286"},"book-1000","XBT/CHF"]
1618678141.3182342: [464,{"b":[["55795.90000","0.42161047","1618678141.289610"]],"c":"2072536286"},"book-1000","XBT/CHF"]
1618678141.322997: [464,{"a":[["56250.50000","0.00000000","1618678141.293291"]],"c":"3599675199"},"book-1000","XBT/CHF"]
1618678141.3246841: [3648,{"b":[["0.00755900","40.81000000","1618678141.293444"]],"c":"1013773235"},"book-1000","KSM/XBT"]
1618678141.325737: [1920,{"a":[["0.043190","0.00000000","1618678141.298077"]],"c":"1837838868"},"book-1000","SC/EUR"]
1618678141.330038: [3648,{"b":[["0.00755200","0.00000000","1618678141.299976"]],"c":"1204292367"},"book-1000","KSM/XBT"]
1618678141.3311172: [3648,{"a":[["0.00759000","39.43000000","1618678141.300656"]],"c":"2485368418"},"book-1000","KSM/XBT"]
1618678141.3320792: [3648,{"a":[["0.00758300","6.29617811","1618678141.302107"]],"c":"1556587871"},"book-1000","KSM/XBT"]
1618678141.340771: [992,{"b":[["280.01000000","0.00000000","1618678141.313768"]],"c":"2048706989"},"book-1000","XMR/USD"]
1618678141.343894: [992,{"b":[["354.08000000","29.57961960","1618678141.315006"]],"c":"619268388"},"book-1000","XMR/USD"]
1618678141.345948: [1664,{"b":[["13.227900","0.00000000","1618678141.316092"]],"c":"869103986"},"book-1000","WAVES/EUR"]
1618678141.347449: [992,{"b":[["353.49000000","0.00000000","1618678141.319388"]],"c":"619268388"},"book-1000","XMR/USD"]
1618678141.349088: [1920,{"b":[["0.042800","577288.45906328","1618678141.319640"]],"c":"2453645815"},"book-1000","SC/EUR"]
1618678141.35127: [1920,{"a":[["0.043090","57940.00000000","1618678141.320952"]],"c":"4115895077"},"book-1000","SC/EUR"]
1618678141.3531961: [992,{"b":[["354.09000000","7.57500000","1618678141.321428"]],"c":"1779162003"},"book-1000","XMR/USD"]
1618678141.3548312: [1664,{"a":[["13.267600","0.00000000","1618678141.321986"]],"c":"3733922214"},"book-1000","WAVES/EUR"]
1618678141.355734: [1664,{"a":[["13.250400","98.00000000","1618678141.322746"]],"c":"2412162590"},"book-1000","WAVES/EUR"]
1618678141.356617: [992,{"b":[["354.07000000","0.00000000","1618678141.323661"]],"c":"35220182"},"book-1000","XMR/USD"]
1618678141.35801: [1664,{"b":[["13.217200","0.00000000","1618678141.325774"]],"c":"3263248485"},"book-1000","WAVES/EUR"]
1618678141.358895: [1664,{"b":[["13.214700","500.00000000","1618678141.326051"]],"c":"2612398117"},"book-1000","WAVES/EUR"]
1618678141.359773: [1920,{"a":[["0.043070","50970.00000000","1618678141.327694"]],"c":"1643508778"},"book-1000","SC/EUR"]
1618678141.361613: [1920,{"a":[["0.043260","905325.33415860","1618678141.327783"]],"c":"1643508778"},"book-1000","SC/EUR"]
1618678141.363574: [1920,{"a":[["0.043160","3348.65131686","1618678141.332343"]],"c":"400566323"},"book-1000","SC/EUR"]
1618678141.365591: [3648,{"a":[["0.00758500","7.27297039","1618678141.335128"]],"c":"395359442"},"book-1000","KSM/XBT"]
1618678141.3662221: [5104,{"a":[["0.000027830","0.00000000","1618678141.335250"]],"c":"966562828"},"book-1000","OCEAN/XBT"]
1618678141.366802: [5104,{"b":[["0.000027650","0.00000000","1618678141.336744"]],"c":"3030986219"},"book-1000","OCEAN/XBT"]
1618678141.3673532: [5104,{"a":[["0.000027820","593.84154000","1618678141.336794"]],"c":"607613109"},"book-1000","OCEAN/XBT"]
1618678141.380991: [1360,{"a":[["0.000022930","2223.63590000","1618678141.351464"]],"c":"388015903"},"book-1000","ADA/XBT"]
1618678141.383165: [1664,{"a":[["13.312800","0.00000000","1618678141.354988"]],"c":"2612398117"},"book-1000","WAVES/EUR"]
1618678141.384237: [1664,{"a":[["13.274700","0.00000000","1618678141.356252"]],"c":"1170152549"},"book-1000","WAVES/EUR"]
1618678141.385143: [1664,{"a":[["13.270500","119.15886375","1618678141.356433"]],"c":"3615514732"},"book-1000","WAVES/EUR"]
1618678141.398369: [992,{"a":[["355.03000000","22.67100000","1618678141.370951"]],"c":"4101483033"},"book-1000","XMR/USD"]
1618678141.403541: [5104,{"a":[["0.000027830","732.36854110","1618678141.374570"]],"c":"689098642"},"book-1000","OCEAN/XBT"]
1618678141.412102: [5104,{"a":[["0.000027850","0.00000000","1618678141.383897"]],"c":"3174590875"},"book-1000","OCEAN/XBT"]
1618678141.418638: [1920,{"a":[["0.043090","37940.00000000","1618678141.388970"]],"c":"2794469032"},"book-1000","SC/EUR"]
1618678141.440116: [1664,{"b":[["13.203300","24.79000000","1618678141.412986"]],"c":"3615514732"},"book-1000","WAVES/EUR"]
1618678141.440959: [1664,{"a":[["13.284500","1396.00000000","1618678141.414164"]],"c":"3615514732"},"book-1000","WAVES/EUR"]
1618678141.454388: [992,{"a":[["355.08000000","0.00000000","1618678141.425922"]],"c":"1145730809"},"book-1000","XMR/USD"]
1618678141.456806: [464,{"b":[["55803.40000","0.00000000","1618678141.427944"]],"c":"2786306867"},"book-1000","XBT/CHF"]
1618678141.484067: [992,{"b":[["353.49000000","2.86900000","1618678141.454967"]],"c":"1145730809"},"book-1000","XMR/USD"]
1618678141.498891: [5104,{"b":[["0.000027650","1543.25563600","1618678141.471890"]],"c":"2441851855"},"book-1000","OCEAN/XBT"]
1618678141.4993742: [5104,{"b":[["0.000027660","0.00000000","1618678141.472577"]],"c":"1415947491"},"book-1000","OCEAN/XBT"]
1618678141.5032902: [3648,{"b":[["0.00749600","0.00000000","1618678141.473290"]],"c":"395359442"},"book-1000","KSM/XBT"]
1618678141.516321: [464,{"a":[["56192.80000","0.15000000","1618678141.489107"]],"c":"189248507"},"book-1000","XBT/CHF"]
1618678141.5193532: [5104,{"b":[["0.000027700","638.19459000","1618678141.492518"]],"c":"2999058389"},"book-1000","OCEAN/XBT"]
1618678141.539948: [1664,{"b":[["13.208600","0.00000000","1618678141.513041"]],"c":"2252320669"},"book-1000","WAVES/EUR"]
1618678141.541048: [3648,{"b":[["0.00750200","18.35282317","1618678141.514136"]],"c":"395359442"},"book-1000","KSM/XBT"]
1618678141.5716321: [464,{"a":[["56218.30000","0.00000000","1618678141.542373"]],"c":"391144265"},"book-1000","XBT/CHF"]
1618678141.572824: [1664,{"b":[["13.203800","0.00000000","1618678141.542797"]],"c":"3169599503"},"book-1000","WAVES/EUR"]
1618678141.611352: [992,{"b":[["295.01000000","0.00000000","1618678141.583492"]],"c":"1145730809"},"book-1000","XMR/USD"]
1618678141.616941: [1360,{"b":[["0.000022870","11666.76413900","1618678141.589478"]],"c":"2099216900"},"book-1000","ADA/XBT"]
1618678141.652307: [1664,{"b":[["13.216500","0.00000000","1618678141.624036"]],"c":"3931272336"},"book-1000","WAVES/EUR"]
1618678141.6579998: [1360,{"b":[["0.000022880","7265.36106386","1618678141.630941"]],"c":"598279551"},"book-1000","ADA/XBT"]
1618678141.666789: [464,{"a":[["56734.30000","0.00000000","1618678141.638305"]],"c":"391144265"},"book-1000","XBT/CHF"]
1618678141.674309: [464,{"b":[["55796.00000","0.43682921","1618678141.645351"]],"c":"1253793733"},"book-1000","XBT/CHF"]
1618678141.69196: [992,{"b":[["354.06000000","0.00000000","1618678141.664262"]],"c":"603132548"},"book-1000","XMR/USD"]
1618678141.717821: [1664,{"b":[["13.206300","415.00000000","1618678141.689770"]],"c":"3206239167"},"book-1000","WAVES/EUR"]
1618678141.7300842: [1920,{"b":[["0.041650","0.00000000","1618678141.699105"]],"c":"2794469032"},"book-1000","SC/EUR"]
1618678141.733593: [1840,{"a":[["9.596670","0.00000000","1618678141.700223"]],"c":"1976406209"},"book-1000","OMG/USD"]
1618678141.7406971: [464,{"a":[["56734.00000","0.51880000","1618678141.712540"]],"c":"1253793733"},"book-1000","XBT/CHF"]
1618678141.756256: [464,{"b":[["55795.90000","0.00000000","1618678141.726146"]],"c":"1253793733"},"book-1000","XBT/CHF"]
1618678141.7671528: [1920,{"a":[["0.043100","0.00000000","1618678141.736392"]],"c":"3580301801"},"book-1000","SC/EUR"]
1618678141.7705421: [1920,{"a":[["0.043210","0.00000000","1618678141.737060"]],"c":"1795261195"},"book-1000","SC/EUR"]
1618678141.7767198: [1360,{"b":[["0.000022850","8723.80308692","1618678141.744655"]],"c":"328487387"},"book-1000","ADA/XBT"]
1618678141.783374: [992,{"b":[["345.38000000","0.00000000","1618678141.754795"]],"c":"603132548"},"book-1000","XMR/USD"]
1618678141.786258: [992,{"b":[["305.00000000","10.53442850","1618678141.755069"]],"c":"603132548"},"book-1000","XMR/USD"]
1618678141.7884061: [992,{"a":[["359.70000000","0.00000000","1618678141.755119"]],"c":"603132548"},"book-1000","XMR/USD"]
1618678141.804798: [496,{"b":[["2155.23000","0.00000000","1618678141.771725"]],"c":"2828562945"},"book-1000","ETH/CHF"]
1618678141.8061938: [1920,{"b":[["0.042410","27992.12566058","1618678141.773126"]],"c":"1795261195"},"book-1000","SC/EUR"]
1618678141.809442: [1920,{"a":[["0.043160","45810.49018612","1618678141.778729"]],"c":"1593174570"},"book-1000","SC/EUR"]
1618678141.814792: [1920,{"a":[["0.043110","48020.00000000","1618678141.787938"]],"c":"3729659450"},"book-1000","SC/EUR"]
1618678141.818217: [1920,{"a":[["0.043120","20000.00000000","1618678141.788492"]],"c":"185319"},"book-1000","SC/EUR"]
1618678141.823046: [992,{"b":[["345.01000000","47.55841259","1618678141.795982"]],"c":"603132548"},"book-1000","XMR/USD"]
1618678141.8273542: [1920,{"b":[["0.041830","328525.58535105","1618678141.799698"]],"c":"185319"},"book-1000","SC/EUR"]
1618678141.830693: [992,{"b":[["325.00000000","81.41463802","1618678141.802916"]],"c":"603132548"},"book-1000","XMR/USD"]
1618678141.832744: [992,{"a":[["359.64000000","23.77836452","1618678141.803701"]],"c":"603132548"},"book-1000","XMR/USD"]
1618678141.8405151: [496,{"b":[["2153.79000","14.29261343","1618678141.813148"]],"c":"2828562945"},"book-1000","ETH/CHF"]
1618678141.898997: [5104,{"a":[["0.000028120","85.15925233","1618678141.870886"]],"c":"2999058389"},"book-1000","OCEAN/XBT"]
1618678141.9491358: [464,{"b":[["56071.30000","0.00000000","1618678141.922487"]],"c":"3485286240"},"book-1000","XBT/CHF"]
1618678141.979075: [1360,{"b":[["0.000022870","17666.76413900","1618678141.948897"]],"c":"4179813650"},"book-1000","ADA/XBT"]
1618678141.998913: [1664,{"b":[["13.193800","0.00000000","1618678141.970359"]],"c":"3206239167"},"book-1000","WAVES/EUR"]
1618678142.0188851: [464,{"b":[["56048.60000","0.01700000","1618678141.988581"]],"c":"2249646592"},"book-1000","XBT/CHF"]
1618678142.065436: [3648,{"a":[["0.00758300","1.34617811","1618678142.037850"]],"c":"2104498332"},"book-1000","KSM/XBT"]
1618678142.142405: [1920,{"b":[["0.042940","150557.00000000","1618678142.109406"]],"c":"1892329490"},"book-1000","SC/EUR"]
1618678142.151995: [3648,{"a":[["0.00762000","0.00000000","1618678142.124565"]],"c":"2104498332"},"book-1000","KSM/XBT"]
1618678142.172298: [1920,{"a":[["0.043250","145085.00000000","1618678142.144329"]],"c":"91972135"},"book-1000","SC/EUR"]
1618678142.192538: [3648,{"a":[["0.00762300","18.35281858","1618678142.163579"]],"c":"2104498332"},"book-1000","KSM/XBT"]
1618678142.208885: [1920,{"b":[["0.042800","0.00000000","1618678142.180387"]],"c":"1987819358"},"book-1000","SC/EUR"]
1618678142.2126179: [464,{"b":[["55793.70000","0.41454149","1618678142.184217"]],"c":"2249646592"},"book-1000","XBT/CHF"]
1618678142.215178: [1920,{"a":[["0.043260","0.00000000","1618678142.186930"]],"c":"1987819358"},"book-1000","SC/EUR"]
1618678142.240514: [992,{"b":[["354.10000000","5.00000000","1618678142.212817"]],"c":"2739306478"},"book-1000","XMR/USD"]
1618678142.2436538: [1664,{"b":[["13.200400","15.02753265","1618678142.214893"]],"c":"3206239167"},"book-1000","WAVES/EUR"]
1618678142.246706: [1664,{"b":[["13.216300","500.00000000","1618678142.218850"]],"c":"543982307"},"book-1000","WAVES/EUR"]
1618678142.254273: [1920,{"b":[["0.042810","597288.45906328","1618678142.225397"]],"c":"3236992730"},"book-1000","SC/EUR"]
1618678142.3029408: {"event":"heartbeat"}
1618678142.4750478: [1840,{"a":[["9.596662","0.00000000","1618678142.447954"]],"c":"1392469131"},"book-1000","OMG/USD"]
1618678142.478833: [1920,{"b":[["0.042420","448131.46416780","1618678142.450202"]],"c":"3236992730"},"book-1000","SC/EUR"]
1618678142.482551: [1920,{"a":[["0.043240","906825.33415860","1618678142.451661"]],"c":"2354466214"},"book-1000","SC/EUR"]
1618678142.489992: [992,{"a":[["355.20000000","142.88110000","1618678142.461908"]],"c":"1228966231"},"book-1000","XMR/USD"]
1618678142.493118: [992,{"a":[["355.44000000","0.00000000","1618678142.462870"]],"c":"2757804459"},"book-1000","XMR/USD"]
1618678142.495251: [1840,{"b":[["9.572568","148.00000000","1618678142.463196"]],"c":"1813170584"},"book-1000","OMG/USD"]
1618678142.496297: [1920,{"a":[["0.043150","4506.95535554","1618678142.463642"]],"c":"1977670043"},"book-1000","SC/EUR"]
1618678142.4989388: [992,{"b":[["351.28000000","5.64477435","1618678142.467436"]],"c":"2757804459"},"book-1000","XMR/USD"]
1618678142.5008378: [1920,{"b":[["0.043000","30567.15200692","1618678142.472473"]],"c":"1552916022"},"book-1000","SC/EUR"]
1618678142.5031948: [1920,{"b":[["0.042810","20000.00000000","1618678142.475912"]],"c":"368028834"},"book-1000","SC/EUR"]
1618678142.511286: [1840,{"a":[["9.596660","136.98409006","1618678142.483879"]],"c":"32718046"},"book-1000","OMG/USD"]
1618678142.5158532: [1920,{"a":[["0.043180","0.00000000","1618678142.486017"]],"c":"215910430"},"book-1000","SC/EUR"]
1618678142.5192618: [1920,{"a":[["0.043220","152999.38223042","1618678142.486292"]],"c":"3138088069"},"book-1000","SC/EUR"]
1618678142.5259688: [992,{"b":[["354.11000000","22.72500000","1618678142.487614"]],"c":"398049598"},"book-1000","XMR/USD"]
1618678142.528734: [992,{"b":[["352.76000000","0.00000000","1618678142.492942"]],"c":"398049598"},"book-1000","XMR/USD"]
1618678142.5307589: [1664,{"b":[["13.214700","0.00000000","1618678142.495877"]],"c":"2454542455"},"book-1000","WAVES/EUR"]
1618678142.532256: [992,{"b":[["354.08000000","22.72500000","1618678142.500180"]],"c":"3697761079"},"book-1000","XMR/USD"]
1618678142.5351071: [992,{"b":[["354.11000000","29.58009620","1618678142.506692"]],"c":"1921784995"},"book-1000","XMR/USD"]
1618678142.536911: [1360,{"a":[["0.000022900","8433.38484526","1618678142.507818"]],"c":"4107948994"},"book-1000","ADA/XBT"]
1618678142.5393898: [1920,{"a":[["0.044400","1501.50000000","1618678142.507937"]],"c":"3138088069"},"book-1000","SC/EUR"]
1618678142.542633: [1920,{"b":[["0.043050","14188.10379252","1618678142.514071"]],"c":"78074471"},"book-1000","SC/EUR"]
1618678142.547938: [1920,{"b":[["0.042970","0.00000000","1618678142.518868"]],"c":"1271733903"},"book-1000","SC/EUR"]
1618678142.5504892: [1920,{"b":[["0.042990","0.00000000","1618678142.519055"]],"c":"3017243777"},"book-1000","SC/EUR"]
1618678142.552612: [1920,{"a":[["0.044160","328530.93258368","1618678142.519234"]],"c":"3017243777"},"book-1000","SC/EUR"]
1618678142.5548: [1840,{"a":[["9.596661","0.00000000","1618678142.524114"]],"c":"3772159761"},"book-1000","OMG/USD"]
1618678142.555566: [1840,{"a":[["9.596670","200.00000000","1618678142.524186"]],"c":"3045396633"},"book-1000","OMG/USD"]
1618678142.556283: [992,{"a":[["355.43000000","0.00000000","1618678142.525138"]],"c":"985265258"},"book-1000","XMR/USD"]
1618678142.557939: [1664,{"b":[["13.226300","0.00000000","1618678142.528948"]],"c":"1936493862"},"book-1000","WAVES/EUR"]
1618678142.559009: [1664,{"b":[["13.217500","99.00000000","1618678142.531518"]],"c":"1032071202"},"book-1000","WAVES/EUR"]
1618678142.5598972: [1360,{"a":[["0.000022910","17472.81671931","1618678142.531858"]],"c":"3551513914"},"book-1000","ADA/XBT"]
1618678142.562173: [992,{"b":[["353.76000000","0.00000000","1618678142.533833"]],"c":"1244122054"},"book-1000","XMR/USD"]
1618678142.5635798: [992,{"a":[["355.50000000","4.57411888","1618678142.536508"]],"c":"2294143969"},"book-1000","XMR/USD"]
1618678142.565948: [992,{"a":[["354.99000000","7.57500000","1618678142.538219"]],"c":"3502108371"},"book-1000","XMR/USD"]
1618678142.567474: [1664,{"b":[["13.191000","132.35425316","1618678142.538358"]],"c":"1032071202"},"book-1000","WAVES/EUR"]
1618678142.568387: [1840,{"a":[["9.599964","0.00000000","1618678142.538922"]],"c":"1670379598"},"book-1000","OMG/USD"]
1618678142.5712729: [1840,{"a":[["9.596659","200.00000000","1618678142.544404"]],"c":"773609820"},"book-1000","OMG/USD"]
1618678142.572098: [464,{"b":[["56060.00000","0.00000000","1618678142.545246"]],"c":"2459222930"},"book-1000","XBT/CHF"]
1618678142.574479: [464,{"b":[["56060.00000","0.05120914","1618678142.547210"]],"c":"842407706"},"book-1000","XBT/CHF"]
1618678142.575828: [5104,{"a":[["0.000027850","732.36854110","1618678142.549048"]],"c":"4233917020"},"book-1000","OCEAN/XBT"]
1618678142.576425: [1360,{"a":[["0.000022950","11593.16491659","1618678142.549805"]],"c":"1181533681"},"book-1000","ADA/XBT"]
1618678142.582561: [5104,{"a":[["0.000027830","0.00000000","1618678142.555595"]],"c":"3028904918"},"book-1000","OCEAN/XBT"]
1618678142.583311: [992,{"b":[["354.08000000","0.00000000","1618678142.556157"]],"c":"2497996836"},"book-1000","XMR/USD"]
1618678142.5899: [992,{"b":[["354.11000000","28.68415596","1618678142.557535"]],"c":"2800565890"},"book-1000","XMR/USD"]
1618678142.593135: [992,{"b":[["354.10000000","0.00000000","1618678142.563316"]],"c":"3100047286"},"book-1000","XMR/USD"]
1618678142.598169: [1360,{"a":[["0.000022960","32323.58979644","1618678142.570890"]],"c":"4098320629"},"book-1000","ADA/XBT"]
1618678142.602046: [1920,{"b":[["0.042830","5056.35803336","1618678142.571639"]],"c":"129699807"},"book-1000","SC/EUR"]
1618678142.604856: [464,{"a":[["56872.70000","0.00000000","1618678142.576788"]],"c":"842407706"},"book-1000","XBT/CHF"]
1618678142.620695: [464,{"b":[["55793.70000","0.00000000","1618678142.593563"]],"c":"842407706"},"book-1000","XBT/CHF"]
1618678142.6294138: [992,{"b":[["353.30000000","0.00000000","1618678142.601547"]],"c":"3100047286"},"book-1000","XMR/USD"]
1618678142.63255: [992,{"b":[["353.76000000","4.34373954","1618678142.604034"]],"c":"1429566498"},"book-1000","XMR/USD"]
1618678142.647008: [1920,{"a":[["0.043250","0.00000000","1618678142.619584"]],"c":"129699807"},"book-1000","SC/EUR"]
1618678142.6505432: [1920,{"a":[["0.043160","42461.83886926","1618678142.619640"]],"c":"2738308845"},"book-1000","SC/EUR"]
1618678142.653449: [1664,{"b":[["13.200500","99.57103949","1618678142.620696"]],"c":"1032071202"},"book-1000","WAVES/EUR"]
1618678142.6545842: [1664,{"b":[["13.206200","0.00000000","1618678142.620748"]],"c":"1091102609"},"book-1000","WAVES/EUR"]
1618678142.6640792: [992,{"a":[["355.19000000","59.76095892","1618678142.636564"]],"c":"175793202"},"book-1000","XMR/USD"]
1618678142.6667688: [992,{"a":[["357.61000000","146.31720310","1618678142.636660"]],"c":"175793202"},"book-1000","XMR/USD"]
1618678142.6968992: [1920,{"a":[["0.043060","3348.56315360","1618678142.670049"]],"c":"1036153534"},"book-1000","SC/EUR"]
1618678142.700449: [992,{"a":[["355.03000000","15.09600000","1618678142.670127"]],"c":"883863998"},"book-1000","XMR/USD"]
1618678142.7061079: [992,{"b":[["353.76000000","0.00000000","1618678142.675485"]],"c":"3646763562"},"book-1000","XMR/USD"]
1618678142.708556: [992,{"b":[["353.76000000","0.82000000","1618678142.677547"]],"c":"3746886845"},"book-1000","XMR/USD"]
1618678142.7207198: [992,{"b":[["352.68000000","7.34776656","1618678142.691968"]],"c":"3746886845"},"book-1000","XMR/USD"]
1618678142.7281961: [1920,{"b":[["0.043050","0.00000000","1618678142.700541"]],"c":"1862544613"},"book-1000","SC/EUR"]
1618678142.731689: [1840,{"a":[["9.596670","0.00000000","1618678142.701552"]],"c":"2944889065"},"book-1000","OMG/USD"]
1618678142.738228: [1920,{"a":[["0.043060","38348.56315360","1618678142.710703"]],"c":"2662567060"},"book-1000","SC/EUR"]
1618678142.745567: [992,{"b":[["353.50000000","4.34693450","1618678142.718350"]],"c":"3746886845"},"book-1000","XMR/USD"]
1618678142.747914: [992,{"b":[["353.76000000","0.00000000","1618678142.720133"]],"c":"2934087825"},"book-1000","XMR/USD"]
1618678142.777869: [992,{"a":[["355.27000000","0.00000000","1618678142.750739"]],"c":"207021088"},"book-1000","XMR/USD"]
1618678142.7810502: [992,{"a":[["357.29000000","0.00000000","1618678142.751682"]],"c":"207021088"},"book-1000","XMR/USD"]
1618678142.7894511: [1360,{"a":[["0.000022920","8697.96187490","1618678142.756311"]],"c":"833593079"},"book-1000","ADA/XBT"]
1618678142.7964668: [992,{"a":[["355.50000000","0.00000000","1618678142.764176"]],"c":"2542056259"},"book-1000","XMR/USD"]
1618678142.7988732: [992,{"a":[["355.27000000","4.57411888","1618678142.764886"]],"c":"546145405"},"book-1000","XMR/USD"]
1618678142.850625: [1920,{"a":[["0.043120","0.00000000","1618678142.822899"]],"c":"185749181"},"book-1000","SC/EUR"]
1618678142.8541708: [1920,{"a":[["0.043130","57950.00000000","1618678142.823044"]],"c":"4269750627"},"book-1000","SC/EUR"]
1618678142.869877: [1360,{"a":[["0.000022910","18295.96527541","1618678142.836091"]],"c":"2958968269"},"book-1000","ADA/XBT"]
1618678142.915948: [1920,{"b":[["0.042980","16069.83712585","1618678142.888448"]],"c":"2278683528"},"book-1000","SC/EUR"]
1618678143.096763: [464,{"b":[["55791.60000","0.41200493","1618678143.068369"]],"c":"842407706"},"book-1000","XBT/CHF"]
1618678143.1011221: [1920,{"b":[["0.042980","0.00000000","1618678143.075027"]],"c":"4269750627"},"book-1000","SC/EUR"]
1618678143.1073852: [1920,{"b":[["0.042940","142057.00000000","1618678143.079451"]],"c":"1727070819"},"book-1000","SC/EUR"]
1618678143.120142: [1920,{"a":[["0.043070","42470.00000000","1618678143.092074"]],"c":"416815562"},"book-1000","SC/EUR"]
1618678143.123692: [1920,{"a":[["0.043050","8500.00000000","1618678143.092163"]],"c":"4247250929"},"book-1000","SC/EUR"]
1618678143.12664: [1920,{"b":[["0.043000","0.00000000","1618678143.092852"]],"c":"2146973676"},"book-1000","SC/EUR"]
1618678143.1290398: [1920,{"b":[["0.042990","30574.26259403","1618678143.098720"]],"c":"1854526696"},"book-1000","SC/EUR"]
1618678143.1391401: [1920,{"a":[["0.043050","0.00000000","1618678143.108986"]],"c":"2339777235"},"book-1000","SC/EUR"]
1618678143.14315: [1920,{"a":[["0.043160","0.00000000","1618678143.115174"]],"c":"4187764728"},"book-1000","SC/EUR"]
1618678143.1539898: [1920,{"a":[["0.043250","143737.00000000","1618678143.125012"]],"c":"1442007454"},"book-1000","SC/EUR"]
1618678143.1665: [1920,{"b":[["0.042940","0.00000000","1618678143.137986"]],"c":"3462917763"},"book-1000","SC/EUR"]
1618678143.178355: [1920,{"a":[["0.043120","20000.00000000","1618678143.151047"]],"c":"3773671200"},"book-1000","SC/EUR"]
1618678143.182077: [1920,{"b":[["0.042990","0.00000000","1618678143.153719"]],"c":"1814261148"},"book-1000","SC/EUR"]
1618678143.1863449: [1920,{"a":[["0.043100","42461.83886926","1618678143.158797"]],"c":"3282637236"},"book-1000","SC/EUR"]
1618678143.189343: [1920,{"b":[["0.042960","20000.00000000","1618678143.158969"]],"c":"1963829582"},"book-1000","SC/EUR"]
1618678143.204195: [1920,{"b":[["0.042810","0.00000000","1618678143.176784"]],"c":"674025943"},"book-1000","SC/EUR"]
1618678143.2381701: [992,{"b":[["354.12000000","5.00000000","1618678143.210042"]],"c":"2347045490"},"book-1000","XMR/USD"]
1618678143.2437289: [1920,{"a":[["0.043250","0.00000000","1618678143.215053"]],"c":"674025943"},"book-1000","SC/EUR"]
1618678143.3048372: {"event":"heartbeat"}
1618678143.3189068: [1920,{"a":[["0.043130","20000.00000000","1618678143.290574"]],"c":"97072454"},"book-1000","SC/EUR"]
1618678143.344654: [464,{"b":[["56060.00000","0.08614558","1618678143.316732"]],"c":"814813640"},"book-1000","XBT/CHF"]
1618678143.3468878: [464,{"b":[["56060.00000","0.03493644","1618678143.316779"]],"c":"265813984"},"book-1000","XBT/CHF"]
1618678143.3555882: [1920,{"a":[["0.043130","0.00000000","1618678143.325787"]],"c":"2383560112"},"book-1000","SC/EUR"]
1618678143.359346: [1920,{"a":[["0.043270","0.00000000","1618678143.330115"]],"c":"2383560112"},"book-1000","SC/EUR"]
1618678143.362033: [1920,{"a":[["0.043200","1101836.90000000","1618678143.330346"]],"c":"2502031157"},"book-1000","SC/EUR"]
1618678143.364525: [1920,{"b":[["0.042670","10527.10700630","1618678143.337065"]],"c":"3646910719"},"book-1000","SC/EUR"]
1618678143.403178: [1920,{"b":[["0.042840","20000.00000000","1618678143.376604"]],"c":"1455146883"},"book-1000","SC/EUR"]
1618678143.406942: [1920,{"a":[["0.043100","62461.83886926","1618678143.378168"]],"c":"4221315770"},"book-1000","SC/EUR"]
1618678143.417105: [1664,{"a":[["13.270600","415.00000000","1618678143.389708"]],"c":"2167926243"},"book-1000","WAVES/EUR"]
1618678143.425944: [3648,{"b":[["0.00755600","2.17710000","1618678143.399147"]],"c":"2550558733"},"book-1000","KSM/XBT"]
1618678143.453377: [3648,{"b":[["0.00750700","5.48989578","1618678143.425414"]],"c":"2550558733"},"book-1000","KSM/XBT"]
1618678143.4760928: [1664,{"b":[["13.206100","0.00000000","1618678143.448896"]],"c":"1093468353"},"book-1000","WAVES/EUR"]
1618678143.4841878: [992,{"a":[["355.59000000","0.00000000","1618678143.456374"]],"c":"2347045490"},"book-1000","XMR/USD"]
1618678143.488634: [464,{"b":[["55791.60000","0.00000000","1618678143.460206"]],"c":"265813984"},"book-1000","XBT/CHF"]
1618678143.4905002: [1664,{"a":[["13.267400","233.07570000","1618678143.462061"]],"c":"4038169085"},"book-1000","WAVES/EUR"]
1618678143.49182: [992,{"a":[["355.33000000","277.80000000","1618678143.462501"]],"c":"2347045490"},"book-1000","XMR/USD"]
1618678143.504599: [1360,{"b":[["0.000022850","7971.94565490","1618678143.476518"]],"c":"596604706"},"book-1000","ADA/XBT"]
1618678143.5085819: [992,{"b":[["352.45000000","0.00000000","1618678143.477156"]],"c":"2347045490"},"book-1000","XMR/USD"]
1618678143.523575: [1360,{"b":[["0.000022850","9388.57750630","1618678143.494091"]],"c":"92447097"},"book-1000","ADA/XBT"]
1618678143.527355: [1360,{"b":[["0.000022840","31627.20816800","1618678143.494441"]],"c":"1944332284"},"book-1000","ADA/XBT"]
1618678143.530381: [1360,{"b":[["0.000022860","27578.69371878","1618678143.499157"]],"c":"3249193392"},"book-1000","ADA/XBT"]
1618678143.5329962: [1360,{"b":[["0.000022870","11666.76413900","1618678143.504359"]],"c":"723285369"},"book-1000","ADA/XBT"]
1618678143.543683: [992,{"a":[["354.69000000","12.12000000","1618678143.515301"]],"c":"771230245"},"book-1000","XMR/USD"]
1618678143.550067: [1360,{"b":[["0.000022880","2221.36980811","1618678143.522055"]],"c":"2987062486"},"book-1000","ADA/XBT"]
1618678143.563048: [1920,{"b":[["0.042960","0.00000000","1618678143.534025"]],"c":"194799951"},"book-1000","SC/EUR"]
1618678143.573142: [1664,{"b":[["13.222500","97.00000000","1618678143.544890"]],"c":"1591628246"},"book-1000","WAVES/EUR"]
1618678143.577612: [1920,{"a":[["0.043240","1500.00000000","1618678143.549264"]],"c":"194799951"},"book-1000","SC/EUR"]
1618678143.581075: [1360,{"a":[["0.000022920","9138.81304741","1618678143.552296"]],"c":"999193145"},"book-1000","ADA/XBT"]
1618678143.584102: [1840,{"a":[["9.596660","0.00000000","1618678143.555668"]],"c":"18517364"},"book-1000","OMG/USD"]
1618678143.585473: [1920,{"b":[["0.042530","850000.00000000","1618678143.558519"]],"c":"3829941267"},"book-1000","SC/EUR"]
1618678143.602419: [992,{"b":[["354.13000000","7.57500000","1618678143.569965"]],"c":"1178297080"},"book-1000","XMR/USD"]
1618678143.605265: [1360,{"b":[["0.000022850","7971.94565490","1618678143.570906"]],"c":"495168610"},"book-1000","ADA/XBT"]
1618678143.608302: [1360,{"b":[["0.000022850","14227.05241748","1618678143.571344"]],"c":"826425835"},"book-1000","ADA/XBT"]
1618678143.6109362: [1360,{"b":[["0.000022840","31974.84471529","1618678143.579308"]],"c":"1352655768"},"book-1000","ADA/XBT"]
1618678143.615554: [1360,{"b":[["0.000022250","1303.37080000","1618678143.588427"]],"c":"1352655768"},"book-1000","ADA/XBT"]
1618678143.618125: [1360,{"b":[["0.000021810","333.79871325","1618678143.588536"]],"c":"1352655768"},"book-1000","ADA/XBT"]
1618678143.620729: [1840,{"a":[["9.596658","136.98583731","1618678143.590142"]],"c":"2818376214"},"book-1000","OMG/USD"]
1618678143.621639: [992,{"a":[["354.74000000","0.00000000","1618678143.592858"]],"c":"1666851926"},"book-1000","XMR/USD"]
1618678143.6368918: [1920,{"b":[["0.042540","577288.45906328","1618678143.604669"]],"c":"1762447429"},"book-1000","SC/EUR"]
1618678143.642751: [1920,{"a":[["0.043120","0.00000000","1618678143.615442"]],"c":"2144237178"},"book-1000","SC/EUR"]
1618678143.646086: [992,{"b":[["349.99000000","0.00000000","1618678143.618249"]],"c":"1666851926"},"book-1000","XMR/USD"]
1618678143.6493802: [992,{"b":[["354.09000000","0.00000000","1618678143.622798"]],"c":"4257292263"},"book-1000","XMR/USD"]
1618678143.651385: [992,{"b":[["354.14000000","5.00000000","1618678143.623444"]],"c":"3779077776"},"book-1000","XMR/USD"]
1618678143.6629372: [1840,{"b":[["9.576671","0.00000000","1618678143.634402"]],"c":"921866148"},"book-1000","OMG/USD"]
1618678143.6645172: [1840,{"a":[["9.598793","148.00000000","1618678143.635144"]],"c":"1169585912"},"book-1000","OMG/USD"]
1618678143.665814: [992,{"b":[["354.14000000","27.72500000","1618678143.635341"]],"c":"2898543165"},"book-1000","XMR/USD"]
1618678143.667904: [1360,{"a":[["0.000022910","16106.61361070","1618678143.635398"]],"c":"1278371266"},"book-1000","ADA/XBT"]
1618678143.670951: [1840,{"b":[["9.580201","0.00000000","1618678143.636159"]],"c":"2896736029"},"book-1000","OMG/USD"]
1618678143.671846: [1840,{"a":[["9.596659","0.00000000","1618678143.636367"]],"c":"3215532733"},"book-1000","OMG/USD"]
1618678143.6727: [1360,{"b":[["0.000022130","51.15181495","1618678143.641090"]],"c":"1278371266"},"book-1000","ADA/XBT"]
1618678143.675067: [1360,{"b":[["0.000021680","109.03440335","1618678143.641267"]],"c":"1278371266"},"book-1000","ADA/XBT"]
1618678143.677404: [1360,{"b":[["0.000022840","31627.20816800","1618678143.643552"]],"c":"770688945"},"book-1000","ADA/XBT"]
1618678143.67965: [1360,{"b":[["0.000022820","1869.89563275","1618678143.644370"]],"c":"4069795467"},"book-1000","ADA/XBT"]
1618678143.681825: [992,{"a":[["354.68000000","6.85530928","1618678143.644448"]],"c":"2110336123"},"book-1000","XMR/USD"]
1618678143.683583: [1920,{"a":[["0.043150","0.00000000","1618678143.647455"]],"c":"2204252397"},"book-1000","SC/EUR"]
1618678143.6855419: [3648,{"b":[["0.00749800","0.00000000","1618678143.649684"]],"c":"2550558733"},"book-1000","KSM/XBT"]
1618678143.6861582: [3648,{"b":[["0.00755800","2.99068160","1618678143.652989"]],"c":"4242521408"},"book-1000","KSM/XBT"]
1618678143.686871: [992,{"b":[["348.89000000","23.77915229","1618678143.658040"]],"c":"2110336123"},"book-1000","XMR/USD"]
1618678143.695938: [1360,{"a":[["0.000022920","10136.81304741","1618678143.668357"]],"c":"2534589335"},"book-1000","ADA/XBT"]
1618678143.700008: [1360,{"a":[["0.000022900","10623.59975312","1618678143.670807"]],"c":"1290031603"},"book-1000","ADA/XBT"]
1618678143.7067788: [992,{"b":[["354.12000000","0.00000000","1618678143.679928"]],"c":"3235728020"},"book-1000","XMR/USD"]
1618678143.711179: [992,{"b":[["354.11000000","21.82905976","1618678143.682062"]],"c":"277400278"},"book-1000","XMR/USD"]
1618678143.7215: [1920,{"a":[["0.043060","50151.33640410","1618678143.694135"]],"c":"1877683199"},"book-1000","SC/EUR"]
1618678143.731894: [992,{"a":[["354.69000000","14.49700000","1618678143.705149"]],"c":"1339475525"},"book-1000","XMR/USD"]
1618678143.736161: [992,{"a":[["355.69000000","0.00000000","1618678143.708990"]],"c":"1339475525"},"book-1000","XMR/USD"]
1618678143.743534: [992,{"b":[["354.15000000","6.85653970","1618678143.716975"]],"c":"623078429"},"book-1000","XMR/USD"]
1618678143.755467: [1920,{"a":[["0.043050","44120.00000000","1618678143.728439"]],"c":"510663532"},"book-1000","SC/EUR"]
1618678143.759367: [1360,{"b":[["0.000022880","31.75709827","1618678143.730007"]],"c":"2714856107"},"book-1000","ADA/XBT"]
1618678143.762382: [1360,{"a":[["0.000023020","550.86315380","1618678143.731311"]],"c":"2714856107"},"book-1000","ADA/XBT"]
1618678143.764868: [992,{"b":[["354.11000000","0.00000000","1618678143.732718"]],"c":"1211932654"},"book-1000","XMR/USD"]
1618678143.772523: [1360,{"b":[["0.000022130","0.00000000","1618678143.744670"]],"c":"2714856107"},"book-1000","ADA/XBT"]
1618678143.7766762: [1360,{"a":[["0.000022920","9695.96187490","1618678143.746773"]],"c":"2274163473"},"book-1000","ADA/XBT"]
1618678143.779656: [464,{"b":[["55573.50000","0.00000000","1618678143.750888"]],"c":"265813984"},"book-1000","XBT/CHF"]
1618678143.780988: [464,{"a":[["56914.70000","0.00000000","1618678143.751307"]],"c":"265813984"},"book-1000","XBT/CHF"]
1618678143.782759: [1360,{"b":[["0.000022870","13857.13890729","1618678143.756229"]],"c":"3276710513"},"book-1000","ADA/XBT"]
1618678143.794624: [992,{"a":[["355.03000000","3.09600000","1618678143.764720"]],"c":"2417789229"},"book-1000","XMR/USD"]
1618678143.800292: [992,{"a":[["355.27000000","0.00000000","1618678143.770451"]],"c":"3396608584"},"book-1000","XMR/USD"]
1618678143.8046458: [992,{"a":[["355.27000000","2.41698820","1618678143.774978"]],"c":"2393481456"},"book-1000","XMR/USD"]
1618678143.807557: [1920,{"a":[["0.043100","20000.00000000","1618678143.778348"]],"c":"667436189"},"book-1000","SC/EUR"]
1618678143.810337: [464,{"a":[["56734.50000","0.00000000","1618678143.778398"]],"c":"265813984"},"book-1000","XBT/CHF"]
1618678143.811957: [992,{"b":[["354.16000000","22.72500000","1618678143.783053"]],"c":"1357569110"},"book-1000","XMR/USD"]
1618678143.813733: [1360,{"a":[["0.000023010","17182.44192203","1618678143.787649"]],"c":"3276710513"},"book-1000","ADA/XBT"]
1618678143.817471: [1840,{"b":[["9.577324","0.00000000","1618678143.790424"]],"c":"3845988582"},"book-1000","OMG/USD"]
1618678143.8182871: [464,{"a":[["56886.20000","0.55664319","1618678143.790992"]],"c":"265813984"},"book-1000","XBT/CHF"]
1618678143.822571: [1360,{"b":[["0.000022130","51.15181495","1618678143.795556"]],"c":"3276710513"},"book-1000","ADA/XBT"]
1618678143.8248162: [464,{"b":[["55544.70000","0.55664319","1618678143.796564"]],"c":"265813984"},"book-1000","XBT/CHF"]
1618678143.8310559: [1920,{"b":[["0.040940","23261.22354035","1618678143.804054"]],"c":"667436189"},"book-1000","SC/EUR"]
1618678143.833179: [1920,{"a":[["0.044480","0.00000000","1618678143.806324"]],"c":"667436189"},"book-1000","SC/EUR"]
1618678143.835047: [1920,{"b":[["0.042670","0.00000000","1618678143.806655"]],"c":"2617007340"},"book-1000","SC/EUR"]
1618678143.847552: [1920,{"a":[["0.043120","42461.83886926","1618678143.821647"]],"c":"2538877459"},"book-1000","SC/EUR"]
1618678143.8502889: [1920,{"a":[["0.043040","20000.00000000","1618678143.821940"]],"c":"1546559771"},"book-1000","SC/EUR"]
1618678143.861564: [464,{"b":[["56011.00000","0.00000000","1618678143.832574"]],"c":"3586288986"},"book-1000","XBT/CHF"]
1618678143.89594: [1664,{"a":[["13.250300","158.60138248","1618678143.868220"]],"c":"1920955188"},"book-1000","WAVES/EUR"]
1618678143.904534: [1360,{"b":[["0.000022870","19542.16512806","1618678143.876978"]],"c":"2998521788"},"book-1000","ADA/XBT"]
1618678143.908559: [1360,{"b":[["0.000022870","18544.16512806","1618678143.878734"]],"c":"3841580730"},"book-1000","ADA/XBT"]
1618678143.9115489: [1920,{"b":[["0.042920","13496.52839030","1618678143.882200"]],"c":"1318442757"},"book-1000","SC/EUR"]
1618678143.916003: [1920,{"a":[["0.044150","901080.00000000","1618678143.887601"]],"c":"1318442757"},"book-1000","SC/EUR"]
1618678143.930366: [992,{"b":[["354.16000000","0.00000000","1618678143.900771"]],"c":"2393481456"},"book-1000","XMR/USD"]
1618678143.933218: [992,{"b":[["354.13000000","0.00000000","1618678143.901569"]],"c":"806652566"},"book-1000","XMR/USD"]
1618678143.9355001: [3648,{"b":[["0.00753900","0.00000000","1618678143.907515"]],"c":"4242521408"},"book-1000","KSM/XBT"]
1618678143.938565: [1664,{"b":[["13.231500","0.00000000","1618678143.911536"]],"c":"4052245779"},"book-1000","WAVES/EUR"]
1618678143.94028: [3648,{"b":[["0.00755000","10.83560510","1618678143.911930"]],"c":"3692848034"},"book-1000","KSM/XBT"]
1618678143.941359: [464,{"b":[["55782.60000","0.41099902","1618678143.912995"]],"c":"2224286539"},"book-1000","XBT/CHF"]
1618678143.9504168: [992,{"a":[["354.73000000","7.05367849","1618678143.922665"]],"c":"4289945907"},"book-1000","XMR/USD"]
1618678143.953578: [3648,{"a":[["0.00758300","6.14617811","1618678143.925269"]],"c":"1139032918"},"book-1000","KSM/XBT"]
1618678143.975978: [1360,{"a":[["0.000022900","16623.59975312","1618678143.947348"]],"c":"2272771563"},"book-1000","ADA/XBT"]
1618678143.9855978: [1664,{"b":[["13.220900","151.27567718","1618678143.955985"]],"c":"2171456456"},"book-1000","WAVES/EUR"]
1618678143.993037: [992,{"b":[["352.27000000","0.00000000","1618678143.965307"]],"c":"4289945907"},"book-1000","XMR/USD"]
1618678144.002652: [1920,{"a":[["0.043080","20581.80752472","1618678143.975510"]],"c":"2477353699"},"book-1000","SC/EUR"]
1618678144.015288: [1664,{"a":[["13.345200","0.00000000","1618678143.986890"]],"c":"2171456456"},"book-1000","WAVES/EUR"]
1618678144.039992: [1920,{"b":[["0.040920","0.00000000","1618678144.011247"]],"c":"2477353699"},"book-1000","SC/EUR"]
1618678144.049418: [992,{"b":[["354.17000000","1.40000000","1618678144.020608"]],"c":"4134684469"},"book-1000","XMR/USD"]
1618678144.051597: [992,{"a":[["354.64000000","1.40000000","1618678144.020678"]],"c":"1570947440"},"book-1000","XMR/USD"]
1618678144.053542: [992,{"a":[["355.27000000","0.00000000","1618678144.021192"]],"c":"1570947440"},"book-1000","XMR/USD"]
1618678144.055295: [992,{"a":[["355.27000000","4.57411888","1618678144.023633"]],"c":"1570947440"},"book-1000","XMR/USD"]
1618678144.06047: [1360,{"a":[["0.000022950","10584.16491659","1618678144.033688"]],"c":"3062023427"},"book-1000","ADA/XBT"]
1618678144.0788531: [1840,{"b":[["9.540000","0.00000000","1618678144.050949"]],"c":"3845988582"},"book-1000","OMG/USD"]
1618678144.094062: [1840,{"b":[["9.574823","108.54482117","1618678144.066823"]],"c":"4157482"},"book-1000","OMG/USD"]
1618678144.0956202: [1664,{"b":[["13.196900","0.00000000","1618678144.067012"]],"c":"2171456456"},"book-1000","WAVES/EUR"]
1618678144.100671: [1920,{"b":[["0.042920","0.00000000","1618678144.067918"]],"c":"362470123"},"book-1000","SC/EUR"]
1618678144.1076522: [496,{"b":[["2185.25000","0.00000000","1618678144.078861"]],"c":"3429558787"},"book-1000","ETH/CHF"]
1618678144.119647: [1664,{"b":[["13.199300","4.18349878","1618678144.090935"]],"c":"2171456456"},"book-1000","WAVES/EUR"]
1618678144.124334: [1920,{"b":[["0.042850","30674.15402567","1618678144.095397"]],"c":"1941526815"},"book-1000","SC/EUR"]
1618678144.135775: [1360,{"b":[["0.000022850","12723.45117604","1618678144.108283"]],"c":"3427199988"},"book-1000","ADA/XBT"]
1618678144.1474948: [496,{"a":[["2192.55000","0.00000000","1618678144.119427"]],"c":"520438071"},"book-1000","ETH/CHF"]
1618678144.149125: [496,{"a":[["2192.11000","0.79681000","1618678144.119773"]],"c":"647414942"},"book-1000","ETH/CHF"]
1618678144.150205: [1664,{"a":[["13.247100","101.00000000","1618678144.121367"]],"c":"3002699960"},"book-1000","WAVES/EUR"]
1618678144.152946: [1920,{"a":[["0.043100","0.00000000","1618678144.125007"]],"c":"967591687"},"book-1000","SC/EUR"]
1618678144.170636: [3648,{"a":[["0.00758900","5.15000000","1618678144.143436"]],"c":"617491614"},"book-1000","KSM/XBT"]
1618678144.1760771: [1664,{"b":[["13.220900","186.75397845","1618678144.148423"]],"c":"930702764"},"book-1000","WAVES/EUR"]
1618678144.187569: [1664,{"b":[["13.216300","0.00000000","1618678144.160488"]],"c":"213506083"},"book-1000","WAVES/EUR"]
1618678144.189308: [1664,{"b":[["13.213000","500.00000000","1618678144.160600"]],"c":"3767165038"},"book-1000","WAVES/EUR"]
1618678144.190685: [1920,{"a":[["0.043190","905325.33415860","1618678144.160827"]],"c":"1078653349"},"book-1000","SC/EUR"]
1618678144.193392: [1664,{"a":[["13.250200","500.00000000","1618678144.160888"]],"c":"442933496"},"book-1000","WAVES/EUR"]
1618678144.197193: [496,{"a":[["2192.54000","0.00000000","1618678144.168766"]],"c":"2942328468"},"book-1000","ETH/CHF"]
1618678144.198165: [496,{"a":[["2192.90000","3.00000000","1618678144.169176"]],"c":"2125447736"},"book-1000","ETH/CHF"]
1618678144.208576: [1840,{"b":[["9.180000","125.00000000","1618678144.181393"]],"c":"4157482"},"book-1000","OMG/USD"]
1618678144.2111502: [1920,{"a":[["0.043080","0.00000000","1618678144.183609"]],"c":"115210565"},"book-1000","SC/EUR"]
1618678144.229405: [1920,{"a":[["0.043040","0.00000000","1618678144.202157"]],"c":"3798888369"},"book-1000","SC/EUR"]
1618678144.23323: [1920,{"a":[["0.043060","70151.33640410","1618678144.202252"]],"c":"1975825217"},"book-1000","SC/EUR"]
1618678144.241098: [992,{"b":[["354.14000000","22.72500000","1618678144.213676"]],"c":"2069450468"},"book-1000","XMR/USD"]
1618678144.2441652: [496,{"a":[["2192.10000","3.00000000","1618678144.216323"]],"c":"4058716303"},"book-1000","ETH/CHF"]
1618678144.249163: [3648,{"a":[["0.00760500","9.00000000","1618678144.221269"]],"c":"1051345366"},"book-1000","KSM/XBT"]
1618678144.255931: [1920,{"a":[["0.043490","23218.01718133","1618678144.227191"]],"c":"1975825217"},"book-1000","SC/EUR"]
1618678144.259708: [1664,{"a":[["13.253700","30.67000000","1618678144.229758"]],"c":"2510208380"},"book-1000","WAVES/EUR"]
1618678144.2610471: [1664,{"a":[["13.247000","500.00000000","1618678144.229850"]],"c":"1364138794"},"book-1000","WAVES/EUR"]
1618678144.266151: [1840,{"a":[["9.596657","200.00000000","1618678144.238162"]],"c":"186011169"},"book-1000","OMG/USD"]
1618678144.2676659: [1840,{"b":[["9.578551","200.00000000","1618678144.238726"]],"c":"3693679083"},"book-1000","OMG/USD"]
1618678144.279325: [1840,{"b":[["9.573281","0.00000000","1618678144.251599"]],"c":"880472081"},"book-1000","OMG/USD"]
1618678144.280915: [1920,{"a":[["0.043120","0.00000000","1618678144.252975"]],"c":"2111608607"},"book-1000","SC/EUR"]
1618678144.291614: [992,{"b":[["354.14000000","0.00000000","1618678144.263584"]],"c":"3777076754"},"book-1000","XMR/USD"]
1618678144.297514: [496,{"a":[["2192.90000","0.00000000","1618678144.265038"]],"c":"630145102"},"book-1000","ETH/CHF"]
1618678144.299031: [1920,{"a":[["0.043130","136132.00000000","1618678144.269413"]],"c":"1683912612"},"book-1000","SC/EUR"]
1618678144.30229: [1920,{"b":[["0.042830","142552.35803336","1618678144.272820"]],"c":"1651467927"},"book-1000","SC/EUR"]
1618678144.304971: {"event":"heartbeat"}
1618678144.3126311: [1920,{"b":[["0.042920","13496.52839030","1618678144.278057"]],"c":"3000089443"},"book-1000","SC/EUR"]
1618678144.316638: [1664,{"b":[["13.198000","66.17466139","1618678144.290800"]],"c":"1364138794"},"book-1000","WAVES/EUR"]
1618678144.320238: [1840,{"b":[["9.567763","114.96940407","1618678144.291758"]],"c":"535718224"},"book-1000","OMG/USD"]
1618678144.323505: [1664,{"a":[["13.260900","0.00000000","1618678144.295709"]],"c":"2717043423"},"book-1000","WAVES/EUR"]
1618678144.325089: [1920,{"a":[["0.043050","86581.83886926","1618678144.296680"]],"c":"2968514147"},"book-1000","SC/EUR"]
1618678144.32781: [1664,{"a":[["13.250200","0.00000000","1618678144.297767"]],"c":"1241945711"},"book-1000","WAVES/EUR"]
1618678144.333183: [1664,{"a":[["13.247100","134.66000000","1618678144.305833"]],"c":"3377333578"},"book-1000","WAVES/EUR"]
1618678144.343601: [992,{"a":[["354.77000000","19.09500000","1618678144.316230"]],"c":"3127367053"},"book-1000","XMR/USD"]
1618678144.3704598: [1920,{"b":[["0.042660","10527.10700630","1618678144.342169"]],"c":"4277636832"},"book-1000","SC/EUR"]
1618678144.373992: [1840,{"a":[["9.603190","0.00000000","1618678144.343438"]],"c":"535718224"},"book-1000","OMG/USD"]
1618678144.3831732: [1360,{"b":[["0.000022830","24580.22089865","1618678144.355243"]],"c":"1793626676"},"book-1000","ADA/XBT"]
1618678144.388709: [992,{"b":[["352.68000000","0.00000000","1618678144.359392"]],"c":"3127367053"},"book-1000","XMR/USD"]
1618678144.39124: [992,{"a":[["354.99000000","0.00000000","1618678144.365004"]],"c":"3925122468"},"book-1000","XMR/USD"]
1618678144.439052: [1840,{"a":[["9.598692","521.40849900","1618678144.410002"]],"c":"125526047"},"book-1000","OMG/USD"]
1618678144.457025: [992,{"a":[["354.90000000","0.00000000","1618678144.430788"]],"c":"1586428884"},"book-1000","XMR/USD"]
1618678144.468181: [464,{"b":[["55796.00000","0.00000000","1618678144.441085"]],"c":"3745937594"},"book-1000","XBT/CHF"]
1618678144.4706979: [1920,{"a":[["0.043480","0.00000000","1618678144.442196"]],"c":"4277636832"},"book-1000","SC/EUR"]
1618678144.473747: [1360,{"a":[["0.000022900","10623.59975312","1618678144.444634"]],"c":"157741413"},"book-1000","ADA/XBT"]
1618678144.4923341: [1920,{"b":[["0.042920","0.00000000","1618678144.464137"]],"c":"3980481899"},"book-1000","SC/EUR"]
1618678144.496161: [1664,{"b":[["13.200400","0.00000000","1618678144.467140"]],"c":"3377333578"},"book-1000","WAVES/EUR"]
1618678144.513876: [1920,{"a":[["0.043600","9714.50918637","1618678144.486123"]],"c":"3980481899"},"book-1000","SC/EUR"]
1618678144.531183: [1664,{"b":[["13.200500","0.00000000","1618678144.503512"]],"c":"1822955479"},"book-1000","WAVES/EUR"]
1618678144.5365: [1664,{"b":[["13.199400","99.57933693","1618678144.508461"]],"c":"283158721"},"book-1000","WAVES/EUR"]
1618678144.564912: [1664,{"a":[["13.270600","419.17098583","1618678144.536670"]],"c":"283158721"},"book-1000","WAVES/EUR"]
1618678144.586077: [992,{"b":[["352.68000000","7.34929042","1618678144.558313"]],"c":"1586428884"},"book-1000","XMR/USD"]
1618678144.589175: [1664,{"a":[["13.266400","119.15886375","1618678144.559919"]],"c":"816554311"},"book-1000","WAVES/EUR"]
1618678144.590517: [1664,{"b":[["13.222500","255.65590156","1618678144.560239"]],"c":"2211781522"},"book-1000","WAVES/EUR"]
1618678144.5929558: [1664,{"a":[["13.270500","0.00000000","1618678144.565840"]],"c":"2211781522"},"book-1000","WAVES/EUR"]
1618678144.599754: [1920,{"a":[["0.043050","44120.00000000","1618678144.571218"]],"c":"4018077803"},"book-1000","SC/EUR"]
1618678144.615818: [496,{"b":[["2185.26000","0.00000000","1618678144.588121"]],"c":"3408584358"},"book-1000","ETH/CHF"]
1618678144.6231732: [1920,{"a":[["0.043130","0.00000000","1618678144.592170"]],"c":"3017140367"},"book-1000","SC/EUR"]
1618678144.627187: [496,{"b":[["2185.11000","1.00430919","1618678144.598099"]],"c":"884067686"},"book-1000","ETH/CHF"]
1618678144.638693: [1920,{"b":[["0.041830","0.00000000","1618678144.612170"]],"c":"3017140367"},"book-1000","SC/EUR"]
1618678144.648847: [1920,{"a":[["0.043090","80401.83886926","1618678144.614330"]],"c":"4154845496"},"book-1000","SC/EUR"]
1618678144.6594381: [496,{"b":[["2183.21000","1.51288895","1618678144.632423"]],"c":"2235389619"},"book-1000","ETH/CHF"]
1618678144.663724: [496,{"b":[["2185.10000","0.00000000","1618678144.636687"]],"c":"4200741730"},"book-1000","ETH/CHF"]
1618678144.6734369: [4528,{"a":[["0.000836100","0.00000000","1618678144.646630"]],"c":"1919083466"},"book-1000","GRT/ETH"]
1618678144.6754088: [1920,{"b":[["0.042420","0.00000000","1618678144.648102"]],"c":"4154845496"},"book-1000","SC/EUR"]
1618678144.6785889: [1840,{"a":[["9.596658","0.00000000","1618678144.648197"]],"c":"3715572500"},"book-1000","OMG/USD"]
1618678144.679853: [1920,{"b":[["0.041800","931624.18546070","1618678144.650117"]],"c":"4154845496"},"book-1000","SC/EUR"]
1618678144.683925: [496,{"b":[["2185.11000","0.00000000","1618678144.653666"]],"c":"3701576392"},"book-1000","ETH/CHF"]
1618678144.68496: [4528,{"a":[["0.000844100","1095.84475706","1618678144.654828"]],"c":"1534345702"},"book-1000","GRT/ETH"]
1618678144.689284: [1920,{"b":[["0.042920","13496.52839030","1618678144.659813"]],"c":"3231686900"},"book-1000","SC/EUR"]
1618678144.716327: [992,{"b":[["352.28000000","5.64286318","1618678144.689063"]],"c":"1586428884"},"book-1000","XMR/USD"]
1618678144.7194922: [1840,{"a":[["9.596656","137.00275062","1618678144.691033"]],"c":"2600713200"},"book-1000","OMG/USD"]
1618678144.72059: [992,{"a":[["354.68000000","0.00000000","1618678144.691843"]],"c":"1436041462"},"book-1000","XMR/USD"]
1618678144.722612: [1920,{"b":[["0.042550","448605.93019970","1618678144.693545"]],"c":"3231686900"},"book-1000","SC/EUR"]
1618678144.7253919: [1664,{"b":[["13.191400","15.03778538","1618678144.698417"]],"c":"2211781522"},"book-1000","WAVES/EUR"]
1618678144.730641: [496,{"b":[["2171.28000","0.82383504","1618678144.700159"]],"c":"1990180648"},"book-1000","ETH/CHF"]
1618678144.731776: [496,{"b":[["2183.23000","0.79264000","1618678144.703592"]],"c":"3131072008"},"book-1000","ETH/CHF"]
1618678144.7328289: [1840,{"a":[["9.596657","0.00000000","1618678144.704019"]],"c":"528586472"},"book-1000","OMG/USD"]
1618678144.761417: [464,{"b":[["55782.60000","0.00000000","1618678144.733840"]],"c":"3122030272"},"book-1000","XBT/CHF"]
1618678144.7636669: [992,{"a":[["354.63000000","6.85662081","1618678144.733995"]],"c":"1411143291"},"book-1000","XMR/USD"]
1618678144.7712178: [1840,{"a":[["9.615304","0.00000000","1618678144.742362"]],"c":"528586472"},"book-1000","OMG/USD"]
1618678144.7827342: [1840,{"b":[["9.575133","144.00000000","1618678144.755690"]],"c":"1361435997"},"book-1000","OMG/USD"]
1618678144.787219: [496,{"b":[["2171.28000","0.00000000","1618678144.759430"]],"c":"834383927"},"book-1000","ETH/CHF"]
1618678144.792469: [1360,{"b":[["0.000022880","5031.75709827","1618678144.764943"]],"c":"4065420040"},"book-1000","ADA/XBT"]
1618678144.7987041: [1920,{"a":[["0.043090","37940.00000000","1618678144.772321"]],"c":"3031655576"},"book-1000","SC/EUR"]
1618678144.801835: [992,{"b":[["354.15000000","0.00000000","1618678144.772910"]],"c":"2999576874"},"book-1000","XMR/USD"]
1618678144.8065228: [992,{"a":[["354.64000000","0.00000000","1618678144.779034"]],"c":"4253438936"},"book-1000","XMR/USD"]
1618678144.808705: [992,{"b":[["354.17000000","0.00000000","1618678144.779626"]],"c":"1205584536"},"book-1000","XMR/USD"]
1618678144.820155: [1920,{"b":[["0.042830","5056.35803336","1618678144.791789"]],"c":"2780149395"},"book-1000","SC/EUR"]
1618678144.843565: [1920,{"a":[["0.043040","42461.83886926","1618678144.814797"]],"c":"444742486"},"book-1000","SC/EUR"]
1618678144.854699: [1920,{"a":[["0.043040","62461.83886926","1618678144.825041"]],"c":"3922464994"},"book-1000","SC/EUR"]
1618678144.86113: [1920,{"b":[["0.042540","0.00000000","1618678144.833913"]],"c":"3922464994"},"book-1000","SC/EUR"]
1618678144.871613: [1920,{"b":[["0.042920","0.00000000","1618678144.845562"]],"c":"3420010665"},"book-1000","SC/EUR"]
1618678144.879112: [1920,{"b":[["0.042790","0.00000000","1618678144.851021"]],"c":"2232460712"},"book-1000","SC/EUR"]
1618678144.885597: [1840,{"a":[["9.684055","0.00000000","1618678144.858861"]],"c":"1361435997"},"book-1000","OMG/USD"]
1618678144.8973: [1920,{"b":[["0.042710","747446.80000000","1618678144.869620"]],"c":"303328111"},"book-1000","SC/EUR"]
1618678144.903706: [1920,{"b":[["0.042560","577288.45906328","1618678144.875522"]],"c":"4281247761"},"book-1000","SC/EUR"]
1618678144.926604: [496,{"b":[["2183.21000","0.00000000","1618678144.893527"]],"c":"851071562"},"book-1000","ETH/CHF"]
1618678144.928074: [496,{"b":[["2183.24000","1.51286819","1618678144.894510"]],"c":"2550555837"},"book-1000","ETH/CHF"]
1618678144.929114: [1920,{"a":[["0.043060","50151.33640410","1618678144.896573"]],"c":"31950028"},"book-1000","SC/EUR"]
1618678144.932249: [1840,{"a":[["9.677625","880.11246340","1618678144.899617"]],"c":"1361435997"},"book-1000","OMG/USD"]
1618678144.933336: [1360,{"a":[["0.000022910","15283.46505460","1618678144.905327"]],"c":"4236681332"},"book-1000","ADA/XBT"]
1618678144.9369621: [992,{"b":[["351.28000000","0.00000000","1618678144.909314"]],"c":"1205584536"},"book-1000","XMR/USD"]
1618678144.941168: [1360,{"b":[["0.000022870","12859.13890729","1618678144.913343"]],"c":"810121956"},"book-1000","ADA/XBT"]
1618678144.9591198: [992,{"b":[["352.68000000","0.00000000","1618678144.931488"]],"c":"1205584536"},"book-1000","XMR/USD"]
1618678144.982833: [464,{"b":[["55680.10000","0.43773848","1618678144.954093"]],"c":"1187543965"},"book-1000","XBT/CHF"]
1618678144.985087: [496,{"b":[["2183.24000","4.51286819","1618678144.956921"]],"c":"3447489137"},"book-1000","ETH/CHF"]
1618678145.00382: [464,{"a":[["56734.20000","0.04455036","1618678144.975425"]],"c":"1187543965"},"book-1000","XBT/CHF"]
1618678145.008783: [1360,{"a":[["0.000022920","10519.11043100","1618678144.979666"]],"c":"1884429932"},"book-1000","ADA/XBT"]
1618678145.012688: [1360,{"b":[["0.000022870","18859.13890729","1618678144.981175"]],"c":"892104204"},"book-1000","ADA/XBT"]
1618678145.051032: [3648,{"a":[["0.00758700","0.00000000","1618678145.024182"]],"c":"1465996640"},"book-1000","KSM/XBT"]
1618678145.052911: [992,{"a":[["354.59000000","1.40000000","1618678145.025344"]],"c":"3009716983"},"book-1000","XMR/USD"]
1618678145.0753238: [992,{"b":[["354.08000000","1.40000000","1618678145.049022"]],"c":"3106219607"},"book-1000","XMR/USD"]
1618678145.10496: [496,{"b":[["2179.42000","0.13690000","1618678145.076930"]],"c":"1335068317"},"book-1000","ETH/CHF"]
1618678145.117815: [992,{"b":[["352.22000000","11.52000000","1618678145.089926"]],"c":"3106219607"},"book-1000","XMR/USD"]
1618678145.1209412: [1920,{"a":[["0.043180","183452.67067430","1618678145.093335"]],"c":"2179098779"},"book-1000","SC/EUR"]
1618678145.1238809: [1920,{"a":[["0.043220","0.00000000","1618678145.095264"]],"c":"1786562727"},"book-1000","SC/EUR"]
1618678145.166904: [1664,{"b":[["13.199400","0.00000000","1618678145.137423"]],"c":"1357175130"},"book-1000","WAVES/EUR"]
1618678145.168797: [1664,{"b":[["13.198100","99.58914540","1618678145.137521"]],"c":"1357175130"},"book-1000","WAVES/EUR"]
1618678145.170295: [992,{"b":[["352.64000000","7.34985490","1618678145.140081"]],"c":"3106219607"},"book-1000","XMR/USD"]
1618678145.172523: [1920,{"a":[["0.043190","0.00000000","1618678145.140979"]],"c":"3259055795"},"book-1000","SC/EUR"]
1618678145.210442: [1920,{"a":[["0.043170","905325.33415860","1618678145.182900"]],"c":"1220834924"},"book-1000","SC/EUR"]
1618678145.215723: [1664,{"b":[["13.215000","500.00000000","1618678145.188027"]],"c":"1511996209"},"book-1000","WAVES/EUR"]
1618678145.226018: [464,{"b":[["55680.10000","0.86780018","1618678145.198202"]],"c":"1745562813"},"book-1000","XBT/CHF"]
1618678145.233187: [1840,{"a":[["9.596655","200.00000000","1618678145.205510"]],"c":"2507693897"},"book-1000","OMG/USD"]
1618678145.2352052: [1360,{"b":[["0.000022760","4368.71996505","1618678145.209296"]],"c":"892104204"},"book-1000","ADA/XBT"]
1618678145.256932: [992,{"b":[["353.95000000","7.00000000","1618678145.229543"]],"c":"3782717071"},"book-1000","XMR/USD"]
1618678145.260038: [1664,{"b":[["13.032100","0.00000000","1618678145.230221"]],"c":"1511996209"},"book-1000","WAVES/EUR"]
1618678145.273026: [1360,{"b":[["0.000022870","16668.76413900","1618678145.245724"]],"c":"138778412"},"book-1000","ADA/XBT"]
1618678145.2770612: [1360,{"b":[["0.000022750","17182.28621515","1618678145.248181"]],"c":"138778412"},"book-1000","ADA/XBT"]
1618678145.283519: [1664,{"b":[["13.213000","0.00000000","1618678145.255815"]],"c":"2064281421"},"book-1000","WAVES/EUR"]
1618678145.285101: [1840,{"a":[["9.612171","650.63790000","1618678145.256120"]],"c":"2507693897"},"book-1000","OMG/USD"]
1618678145.2864: [1840,{"b":[["9.578551","0.00000000","1618678145.258444"]],"c":"746525094"},"book-1000","OMG/USD"]
1618678145.2899358: [1360,{"b":[["0.000022870","11668.76413900","1618678145.264013"]],"c":"2288444099"},"book-1000","ADA/XBT"]
1618678145.305042: {"event":"heartbeat"}
1618678145.3114429: [1664,{"b":[["13.025500","1603.47147897","1618678145.273784"]],"c":"2064281421"},"book-1000","WAVES/EUR"]
1618678145.315676: [1360,{"b":[["0.000022880","7222.02965879","1618678145.286512"]],"c":"4281348087"},"book-1000","ADA/XBT"]
1618678145.33409: [992,{"b":[["353.95000000","0.00000000","1618678145.307570"]],"c":"3106219607"},"book-1000","XMR/USD"]
1618678145.348917: [464,{"b":[["56060.00000","0.00000000","1618678145.318599"]],"c":"3918220800"},"book-1000","XBT/CHF"]
1618678145.351191: [464,{"b":[["56060.00000","0.02412728","1618678145.319635"]],"c":"1223799946"},"book-1000","XBT/CHF"]
1618678145.410021: [992,{"b":[["354.09000000","6.85664701","1618678145.383616"]],"c":"1546947729"},"book-1000","XMR/USD"]
1618678145.4229279: [1920,{"a":[["0.043160","183452.67067430","1618678145.395146"]],"c":"3169131653"},"book-1000","SC/EUR"]
1618678145.4265091: [1920,{"a":[["0.043180","0.00000000","1618678145.395914"]],"c":"3159971103"},"book-1000","SC/EUR"]
1618678145.443656: [1360,{"b":[["0.000021680","56.82085792","1618678145.417397"]],"c":"4281348087"},"book-1000","ADA/XBT"]
1618678145.454893: [992,{"b":[["354.08000000","0.00000000","1618678145.423260"]],"c":"4219138460"},"book-1000","XMR/USD"]
1618678145.45776: [992,{"b":[["354.10000000","1.40000000","1618678145.424130"]],"c":"634916498"},"book-1000","XMR/USD"]
1618678145.467896: [1920,{"a":[["0.043170","0.00000000","1618678145.440983"]],"c":"4128413858"},"book-1000","SC/EUR"]
1618678145.474356: [992,{"a":[["354.55000000","11.64000000","1618678145.447478"]],"c":"1162547065"},"book-1000","XMR/USD"]
1618678145.492874: [1360,{"b":[["0.000021810","385.70103626","1618678145.466387"]],"c":"4281348087"},"book-1000","ADA/XBT"]
1618678145.5247848: [1920,{"a":[["0.043150","905325.33415860","1618678145.480727"]],"c":"1824073038"},"book-1000","SC/EUR"]
1618678145.5282829: [992,{"a":[["354.59000000","0.00000000","1618678145.488558"]],"c":"1245149453"},"book-1000","XMR/USD"]
1618678145.531432: [992,{"a":[["375.07000000","0.00000000","1618678145.504374"]],"c":"1245149453"},"book-1000","XMR/USD"]
1618678145.548535: [1920,{"a":[["0.043150","0.00000000","1618678145.520539"]],"c":"4128413858"},"book-1000","SC/EUR"]
1618678145.570518: [992,{"a":[["377.52000000","36.81096201","1618678145.542418"]],"c":"1245149453"},"book-1000","XMR/USD"]
1618678145.620043: [992,{"b":[["353.74000000","0.00000000","1618678145.589338"]],"c":"3269588856"},"book-1000","XMR/USD"]
1618678145.622907: [992,{"b":[["353.61000000","0.00000000","1618678145.590042"]],"c":"1228923142"},"book-1000","XMR/USD"]
1618678145.629035: [1920,{"b":[["0.042810","145938.00000000","1618678145.600843"]],"c":"2039491262"},"book-1000","SC/EUR"]
1618678145.65326: [496,{"a":[["2238.03000","0.00000000","1618678145.624195"]],"c":"1335068317"},"book-1000","ETH/CHF"]
1618678145.67561: [496,{"a":[["2234.62000","28.59385610","1618678145.646688"]],"c":"1335068317"},"book-1000","ETH/CHF"]
1618678145.688416: [1920,{"b":[["0.042410","0.00000000","1618678145.660898"]],"c":"2039491262"},"book-1000","SC/EUR"]
1618678145.720334: [992,{"a":[["355.92000000","0.00000000","1618678145.692155"]],"c":"1228923142"},"book-1000","XMR/USD"]
1618678145.750272: [1360,{"b":[["0.000022850","13594.25117604","1618678145.713456"]],"c":"1085439734"},"book-1000","ADA/XBT"]
1618678145.754326: [992,{"a":[["354.55000000","10.38309685","1618678145.715785"]],"c":"3781770474"},"book-1000","XMR/USD"]
1618678145.861326: [1920,{"b":[["0.042990","15979.71727919","1618678145.719628"]],"c":"973739027"},"book-1000","SC/EUR"]
1618678145.8647208: [1840,{"a":[["9.596656","0.00000000","1618678145.744252"]],"c":"2073167817"},"book-1000","OMG/USD"]
1618678145.865824: [1920,{"b":[["0.042830","0.00000000","1618678145.762964"]],"c":"1737000212"},"book-1000","SC/EUR"]
1618678145.868364: [1360,{"b":[["0.000022870","16668.76413900","1618678145.764646"]],"c":"3230731033"},"book-1000","ADA/XBT"]
1618678145.8708842: [1360,{"b":[["0.000022880","2222.02965879","1618678145.764762"]],"c":"1876577034"},"book-1000","ADA/XBT"]
1618678145.8732631: [1360,{"b":[["0.000022880","31.75709827","1618678145.767312"]],"c":"4056781190"},"book-1000","ADA/XBT"]
1618678145.875637: [1840,{"a":[["9.596654","136.99621155","1618678145.785322"]],"c":"356327884"},"book-1000","OMG/USD"]
1618678145.876483: [992,{"a":[["354.63000000","0.00000000","1618678145.791627"]],"c":"3070797363"},"book-1000","XMR/USD"]
1618678145.878208: [1360,{"b":[["0.000022870","18859.48103087","1618678145.799664"]],"c":"3570395937"},"book-1000","ADA/XBT"]
1618678145.880578: [992,{"b":[["353.61000000","5.88076601","1618678145.811127"]],"c":"2800346266"},"book-1000","XMR/USD"]
1618678145.882244: [1920,{"b":[["0.042860","5816.67507435","1618678145.812925"]],"c":"3885304146"},"book-1000","SC/EUR"]
1618678145.884396: [1360,{"b":[["0.000022700","4497.40348166","1618678145.826359"]],"c":"3570395937"},"book-1000","ADA/XBT"]
1618678145.886871: [992,{"a":[["355.68000000","0.00000000","1618678145.834474"]],"c":"2800346266"},"book-1000","XMR/USD"]
1618678145.8884249: [992,{"a":[["354.54000000","6.85744624","1618678145.835677"]],"c":"2021146519"},"book-1000","XMR/USD"]
1618678145.889895: [1920,{"a":[["0.043150","144391.00000000","1618678145.836054"]],"c":"3352269211"},"book-1000","SC/EUR"]
1618678145.8917499: [1664,{"b":[["13.220900","151.27567718","1618678145.838807"]],"c":"2664407839"},"book-1000","WAVES/EUR"]
1618678145.8926651: [1920,{"a":[["0.043040","20000.00000000","1618678145.854055"]],"c":"1548674574"},"book-1000","SC/EUR"]
1618678145.8989062: [1920,{"b":[["0.042810","0.00000000","1618678145.858026"]],"c":"2431609168"},"book-1000","SC/EUR"]
1618678145.901182: [1920,{"a":[["0.043060","46802.77325050","1618678145.863013"]],"c":"706073903"},"book-1000","SC/EUR"]
1618678145.913144: [992,{"b":[["354.10000000","6.40000000","1618678145.885986"]],"c":"3664583924"},"book-1000","XMR/USD"]
1618678145.925587: [992,{"b":[["353.21000000","22.72500000","1618678145.887450"]],"c":"3664583924"},"book-1000","XMR/USD"]
1618678145.9284532: [992,{"b":[["354.10000000","13.97500000","1618678145.888189"]],"c":"2310236557"},"book-1000","XMR/USD"]
1618678145.93055: [1920,{"a":[["0.043040","0.00000000","1618678145.892580"]],"c":"2723810438"},"book-1000","SC/EUR"]
1618678145.933389: [1920,{"a":[["0.043120","42461.83886926","1618678145.897990"]],"c":"1798119773"},"book-1000","SC/EUR"]
1618678145.939589: [1920,{"b":[["0.042750","46870.00000000","1618678145.903423"]],"c":"1373678096"},"book-1000","SC/EUR"]
1618678145.9426749: [1920,{"a":[["0.043150","0.00000000","1618678145.912492"]],"c":"3259317136"},"book-1000","SC/EUR"]
1618678145.945385: [1920,{"a":[["0.043030","3348.35028587","1618678145.913537"]],"c":"2363368045"},"book-1000","SC/EUR"]
1618678145.9513211: [1920,{"a":[["0.042990","364630.28272081","1618678145.920470"]]},{"b":[["0.042990","0.00000000","1618678145.920708"]],"c":"4105471083"},"book-1000","SC/EUR"]
1618678145.975349: [1360,{"b":[["0.000022850","12723.45117604","1618678145.943239"]],"c":"1800256032"},"book-1000","ADA/XBT"]
1618678145.979372: [1360,{"a":[["0.000022900","16623.59975312","1618678145.948402"]],"c":"2000835873"},"book-1000","ADA/XBT"]
1618678145.982222: [1360,{"b":[["0.000022870","12859.48103087","1618678145.948445"]],"c":"842802497"},"book-1000","ADA/XBT"]
1618678145.9846241: [1360,{"b":[["0.000022860","33578.69371878","1618678145.948748"]],"c":"1797627681"},"book-1000","ADA/XBT"]
1618678145.995171: [1920,{"a":[["0.043020","35000.00000000","1618678145.966245"]],"c":"2788010390"},"book-1000","SC/EUR"]
1618678145.998147: [1920,{"a":[["0.043060","11802.77325050","1618678145.966690"]],"c":"1906873386"},"book-1000","SC/EUR"]
1618678146.0035882: [992,{"a":[["355.20000000","148.76238639","1618678145.975612"]],"c":"1737548749"},"book-1000","XMR/USD"]
1618678146.03543: [1920,{"a":[["0.043020","0.00000000","1618678146.005717"]],"c":"775689199"},"book-1000","SC/EUR"]
1618678146.038947: [1920,{"b":[["0.042770","42500.00000000","1618678146.007777"]],"c":"2029395640"},"book-1000","SC/EUR"]
1618678146.0479228: [992,{"a":[["355.51000000","0.00000000","1618678146.019376"]],"c":"1737548749"},"book-1000","XMR/USD"]
1618678146.0581388: [992,{"a":[["354.54000000","9.61644624","1618678146.030199"]],"c":"3171397757"},"book-1000","XMR/USD"]
1618678146.071143: [1360,{"b":[["0.000022760","0.00000000","1618678146.042412"]],"c":"1797627681"},"book-1000","ADA/XBT"]
1618678146.083612: [3648,{"a":[["0.00758400","0.56900000","1618678146.056967"]],"c":"1039581854"},"book-1000","KSM/XBT"]
1618678146.0869381: [464,{"b":[["56060.00000","0.00000000","1618678146.058270"]],"c":"3918220800"},"book-1000","XBT/CHF"]
1618678146.088948: [464,{"b":[["56060.00000","0.04279520","1618678146.058478"]],"c":"4091770657"},"book-1000","XBT/CHF"]
1618678146.0957649: [992,{"b":[["353.76000000","2.94035828","1618678146.068988"]],"c":"1238298564"},"book-1000","XMR/USD"]
1618678146.12028: [1920,{"a":[["0.043110","0.00000000","1618678146.092035"]],"c":"3826385497"},"book-1000","SC/EUR"]
1618678146.1238022: [1920,{"b":[["0.042850","0.00000000","1618678146.092181"]],"c":"759270046"},"book-1000","SC/EUR"]
1618678146.126455: [1920,{"b":[["0.042870","30659.84371355","1618678146.093279"]],"c":"418416401"},"book-1000","SC/EUR"]
1618678146.128757: [1920,{"a":[["0.043190","183452.67067430","1618678146.093572"]],"c":"2237187033"},"book-1000","SC/EUR"]
1618678146.131285: [1920,{"a":[["0.042990","0.00000000","1618678146.094975"]],"c":"22697085"},"book-1000","SC/EUR"]
1618678146.1335838: [1664,{"b":[["13.213900","35.47830127","1618678146.095807"]],"c":"1284147427"},"book-1000","WAVES/EUR"]
1618678146.134719: [1920,{"a":[["0.043030","50318.35028587","1618678146.096225"]],"c":"3430713057"},"book-1000","SC/EUR"]
1618678146.159155: [1920,{"a":[["0.043160","0.00000000","1618678146.131202"]],"c":"1638909019"},"book-1000","SC/EUR"]
1618678146.231586: [1840,{"b":[["9.578201","200.00000000","1618678146.204251"]],"c":"3874047650"},"book-1000","OMG/USD"]
1618678146.23439: [1840,{"a":[["9.596653","200.00000000","1618678146.204631"]],"c":"2392621320"},"book-1000","OMG/USD"]
1618678146.2443142: [992,{"a":[["355.17000000","2.94038244","1618678146.217065"]],"c":"396620784"},"book-1000","XMR/USD"]
1618678146.251667: [464,{"a":[["56914.60000","0.01000000","1618678146.225061"]],"c":"4091770657"},"book-1000","XBT/CHF"]
1618678146.2628: [1920,{"a":[["0.043120","0.00000000","1618678146.235333"]],"c":"2467247682"},"book-1000","SC/EUR"]
1618678146.2824252: [496,{"a":[["2213.40000","0.00000000","1618678146.255083"]],"c":"1335068317"},"book-1000","ETH/CHF"]
1618678146.283793: [1840,{"a":[["9.596655","0.00000000","1618678146.255649"]],"c":"2744473274"},"book-1000","OMG/USD"]
1618678146.305751: {"event":"heartbeat"}
1618678146.30964: [1920,{"a":[["0.043030","92780.18915513","1618678146.279227"]],"c":"865748759"},"book-1000","SC/EUR"]
1618678146.3131928: [1920,{"a":[["0.043180","905325.33415860","1618678146.279553"]],"c":"3274434273"},"book-1000","SC/EUR"]
1618678146.3244412: [496,{"a":[["2212.37000","14.29738242","1618678146.295803"]],"c":"1335068317"},"book-1000","ETH/CHF"]
1618678146.3495932: [1840,{"b":[["9.577431","144.00000000","1618678146.321491"]],"c":"3962455436"},"book-1000","OMG/USD"]
1618678146.4617448: [992,{"b":[["353.50000000","0.00000000","1618678146.433442"]],"c":"1612472651"},"book-1000","XMR/USD"]
1618678146.464564: [992,{"b":[["353.30000000","4.34939532","1618678146.434813"]],"c":"1612472651"},"book-1000","XMR/USD"]
1618678146.468838: [1360,{"a":[["0.000022910","9283.46505460","1618678146.440697"]],"c":"110422523"},"book-1000","ADA/XBT"]
1618678146.472128: [992,{"b":[["354.09000000","0.00000000","1618678146.441479"]],"c":"3197443880"},"book-1000","XMR/USD"]
1618678146.5083678: [992,{"b":[["354.11000000","6.85764790","1618678146.481412"]],"c":"3789108064"},"book-1000","XMR/USD"]
1618678146.521195: [1360,{"b":[["0.000022440","1950.00000000","1618678146.493340"]],"c":"110422523"},"book-1000","ADA/XBT"]
1618678146.528916: [992,{"b":[["352.94000000","0.00000000","1618678146.499380"]],"c":"3789108064"},"book-1000","XMR/USD"]
1618678146.55953: [992,{"b":[["354.12000000","7.57500000","1618678146.531162"]],"c":"3219473893"},"book-1000","XMR/USD"]
1618678146.570455: [992,{"b":[["352.11000000","12.36000000","1618678146.542780"]],"c":"3219473893"},"book-1000","XMR/USD"]
1618678146.5916858: [1920,{"a":[["0.043030","50318.35028587","1618678146.558544"]],"c":"3632977643"},"book-1000","SC/EUR"]
1618678146.6011121: [992,{"b":[["354.10000000","12.57500000","1618678146.570337"]],"c":"3442068513"},"book-1000","XMR/USD"]
1618678146.6069: [992,{"b":[["354.10000000","5.00000000","1618678146.579397"]],"c":"3723117484"},"book-1000","XMR/USD"]
1618678146.625935: [1920,{"b":[["0.042870","0.00000000","1618678146.595797"]],"c":"3984383457"},"book-1000","SC/EUR"]
1618678146.6294599: [1920,{"a":[["0.043060","0.00000000","1618678146.598232"]],"c":"3845164040"},"book-1000","SC/EUR"]
1618678146.648454: [1920,{"a":[["0.043140","42461.83886926","1618678146.621738"]],"c":"2714836651"},"book-1000","SC/EUR"]
1618678146.661004: [464,{"b":[["56060.00000","0.07879040","1618678146.633722"]],"c":"2664200582"},"book-1000","XBT/CHF"]
1618678146.663297: [464,{"b":[["56060.00000","0.03599520","1618678146.634393"]],"c":"671933195"},"book-1000","XBT/CHF"]
1618678146.7294688: [1920,{"b":[["0.042760","27992.12566058","1618678146.701021"]],"c":"3802523110"},"book-1000","SC/EUR"]
1618678146.733459: [1360,{"b":[["0.000022420","17506.74692668","1618678146.706494"]],"c":"110422523"},"book-1000","ADA/XBT"]
1618678146.751771: [1840,{"a":[["9.604281","0.00000000","1618678146.723563"]],"c":"3962455436"},"book-1000","OMG/USD"]
1618678146.764141: [1840,{"a":[["9.589667","61.76939651","1618678146.736512"]],"c":"2102389695"},"book-1000","OMG/USD"]
1618678146.771498: [1664,{"a":[["13.247100","101.00000000","1618678146.742547"]],"c":"118297655"},"book-1000","WAVES/EUR"]
1618678146.8275788: [1840,{"a":[["9.605866","0.00000000","1618678146.796030"]],"c":"2102389695"},"book-1000","OMG/USD"]
1618678146.8325608: [1840,{"b":[["9.579768","0.00000000","1618678146.798904"]],"c":"770766105"},"book-1000","OMG/USD"]
1618678146.838089: [1840,{"a":[["9.603089","0.00000000","1618678146.807251"]],"c":"770766105"},"book-1000","OMG/USD"]
1618678146.866196: [1840,{"b":[["9.577431","0.00000000","1618678146.834111"]],"c":"2164408055"},"book-1000","OMG/USD"]
1618678146.875077: [1840,{"a":[["9.596654","0.00000000","1618678146.843196"]],"c":"1335893093"},"book-1000","OMG/USD"]
1618678146.885215: [1840,{"b":[["9.564553","521.45839000","1618678146.852971"]],"c":"1335893093"},"book-1000","OMG/USD"]
1618678146.899968: [992,{"b":[["295.01000000","0.05084573","1618678146.864484"]],"c":"3723117484"},"book-1000","XMR/USD"]
1618678146.9120011: [1840,{"b":[["9.584186","0.00000000","1618678146.884248"]],"c":"1116285438"},"book-1000","OMG/USD"]
1618678146.917655: [992,{"a":[["354.54000000","2.75900000","1618678146.887217"]],"c":"685511367"},"book-1000","XMR/USD"]
1618678146.9547882: [1840,{"a":[["9.589667","0.00000000","1618678146.922990"]],"c":"1762682969"},"book-1000","OMG/USD"]
1618678146.95886: [1840,{"b":[["9.584187","136.99833999","1618678146.927120"]],"c":"44660434"},"book-1000","OMG/USD"]
1618678146.960277: [992,{"a":[["354.53000000","6.85810676","1618678146.927351"]],"c":"3008844997"},"book-1000","XMR/USD"]
1618678146.962707: [1664,{"b":[["13.198000","0.00000000","1618678146.931134"]],"c":"118297655"},"book-1000","WAVES/EUR"]
1618678146.964354: [464,{"b":[["56060.00000","0.00000000","1618678146.937226"]],"c":"3918220800"},"book-1000","XBT/CHF"]
1618678146.965985: [464,{"b":[["56060.00000","0.02029520","1618678146.937381"]],"c":"714207813"},"book-1000","XBT/CHF"]
1618678146.988842: [5104,{"a":[["0.000027850","1461.10142437","1618678146.957140"]],"c":"3680896437"},"book-1000","OCEAN/XBT"]
1618678146.990127: [1920,{"b":[["0.042910","141914.00000000","1618678146.957310"]],"c":"1669955880"},"book-1000","SC/EUR"]
1618678146.993227: [5104,{"a":[["0.000027850","728.73288327","1618678146.959870"]],"c":"2684493286"},"book-1000","OCEAN/XBT"]
1618678146.996196: [1920,{"a":[["0.043220","137040.00000000","1618678146.963757"]],"c":"1204094776"},"book-1000","SC/EUR"]
1618678146.999166: [1664,{"b":[["13.191500","99.63897206","1618678146.966170"]],"c":"118297655"},"book-1000","WAVES/EUR"]
1618678147.000483: [1840,{"a":[["9.596652","136.99915864","1618678146.966532"]],"c":"709274011"},"book-1000","OMG/USD"]
1618678147.00151: [1664,{"b":[["13.198100","0.00000000","1618678146.966799"]],"c":"118297655"},"book-1000","WAVES/EUR"]
1618678147.0118139: [992,{"b":[["353.75000000","0.00000000","1618678146.978471"]],"c":"2361721796"},"book-1000","XMR/USD"]
1618678147.0247161: [992,{"b":[["353.64000000","2.25700000","1618678146.993344"]],"c":"2483654945"},"book-1000","XMR/USD"]
1618678147.0275671: [1920,{"b":[["0.040910","23282.88707799","1618678146.994764"]],"c":"1204094776"},"book-1000","SC/EUR"]
1618678147.032528: [1920,{"b":[["0.042560","0.00000000","1618678147.000007"]],"c":"1204094776"},"book-1000","SC/EUR"]
1618678147.0356328: [3648,{"a":[["0.00758300","1.34617811","1618678147.004629"]],"c":"2140060894"},"book-1000","KSM/XBT"]
1618678147.049524: [3648,{"b":[["0.00723100","0.00000000","1618678147.013597"]],"c":"2140060894"},"book-1000","KSM/XBT"]
1618678147.058822: [1840,{"a":[["9.596696","0.00000000","1618678147.026880"]],"c":"3057272731"},"book-1000","OMG/USD"]
1618678147.072011: [992,{"b":[["353.31000000","52.00000000","1618678147.039729"]],"c":"2483654945"},"book-1000","XMR/USD"]
1618678147.074848: [1920,{"b":[["0.042720","577288.45906328","1618678147.039918"]],"c":"966814825"},"book-1000","SC/EUR"]
1618678147.080967: [1920,{"b":[["0.042550","0.00000000","1618678147.048607"]],"c":"966814825"},"book-1000","SC/EUR"]
1618678147.0958002: [3648,{"b":[["0.00727000","0.95246087","1618678147.063128"]],"c":"2140060894"},"book-1000","KSM/XBT"]
1618678147.124706: [1840,{"b":[["9.570932","0.00000000","1618678147.089723"]],"c":"2772948675"},"book-1000","OMG/USD"]
1618678147.126139: [992,{"b":[["353.76000000","0.00000000","1618678147.091520"]],"c":"1311303139"},"book-1000","XMR/USD"]
1618678147.1286452: [1920,{"b":[["0.042920","30624.12791721","1618678147.099504"]],"c":"410194666"},"book-1000","SC/EUR"]
1618678147.1356192: [1840,{"b":[["9.563248","73.10000000","1618678147.105964"]],"c":"2772948675"},"book-1000","OMG/USD"]
1618678147.149923: [1840,{"a":[["9.604047","61.76939651","1618678147.111820"]],"c":"2772948675"},"book-1000","OMG/USD"]
1618678147.151507: [1920,{"a":[["0.043190","0.00000000","1618678147.116217"]],"c":"2931723506"},"book-1000","SC/EUR"]
1618678147.15627: [1920,{"b":[["0.042540","448347.93441460","1618678147.123492"]],"c":"2931723506"},"book-1000","SC/EUR"]
1618678147.159358: [5104,{"a":[["0.000027780","0.00000000","1618678147.124165"]],"c":"1957005805"},"book-1000","OCEAN/XBT"]
1618678147.160185: [1920,{"a":[["0.043170","183452.67067430","1618678147.124370"]],"c":"4128956976"},"book-1000","SC/EUR"]
1618678147.162782: [496,{"a":[["2192.09000","1.15978265","1618678147.126213"]],"c":"4224469337"},"book-1000","ETH/CHF"]
1618678147.163535: [496,{"a":[["2198.69000","0.00000000","1618678147.127532"]],"c":"1728319805"},"book-1000","ETH/CHF"]
1618678147.164238: [992,{"b":[["280.01000000","0.08035427","1618678147.130688"]],"c":"1311303139"},"book-1000","XMR/USD"]
1618678147.175468: [5104,{"b":[["0.000027700","896.83343711","1618678147.143218"]],"c":"1281114852"},"book-1000","OCEAN/XBT"]
1618678147.182486: [1840,{"a":[["9.596651","200.00000000","1618678147.145195"]],"c":"323351232"},"book-1000","OMG/USD"]
1618678147.1840708: [1840,{"b":[["9.563248","0.00000000","1618678147.150018"]],"c":"323351232"},"book-1000","OMG/USD"]
1618678147.186295: [992,{"b":[["353.32000000","0.17106559","1618678147.157589"]],"c":"1311303139"},"book-1000","XMR/USD"]
1618678147.192496: [1920,{"a":[["0.043180","0.00000000","1618678147.161719"]],"c":"1568967563"},"book-1000","SC/EUR"]
1618678147.213956: [1664,{"b":[["13.196400","66.16741292","1618678147.180785"]],"c":"118297655"},"book-1000","WAVES/EUR"]
1618678147.226721: [992,{"b":[["351.28000000","5.64844103","1618678147.189749"]],"c":"1311303139"},"book-1000","XMR/USD"]
1618678147.229606: [1840,{"a":[["9.596653","0.00000000","1618678147.194959"]],"c":"3025927765"},"book-1000","OMG/USD"]
1618678147.230724: [5104,{"a":[["0.000027850","0.00000000","1618678147.196027"]],"c":"2127200917"},"book-1000","OCEAN/XBT"]
1618678147.231862: [496,{"a":[["2192.08000","3.00000000","1618678147.196254"]],"c":"614938188"},"book-1000","ETH/CHF"]
1618678147.232776: [992,{"b":[["353.85000000","0.00000000","1618678147.197501"]],"c":"1169654210"},"book-1000","XMR/USD"]
1618678147.2366989: [3648,{"b":[["0.00755600","0.00000000","1618678147.200493"]],"c":"4266565371"},"book-1000","KSM/XBT"]
1618678147.23782: [992,{"a":[["355.28000000","0.00000000","1618678147.200931"]],"c":"1169654210"},"book-1000","XMR/USD"]
1618678147.2399209: [992,{"b":[["353.56000000","151.25790000","1618678147.202503"]],"c":"237043965"},"book-1000","XMR/USD"]
1618678147.241822: [992,{"a":[["354.99000000","171.91560000","1618678147.202759"]],"c":"865785791"},"book-1000","XMR/USD"]
1618678147.243511: [1920,{"b":[["0.040940","0.00000000","1618678147.202916"]],"c":"1568967563"},"book-1000","SC/EUR"]
1618678147.2457652: [1920,{"a":[["0.043160","905325.33415860","1618678147.203684"]],"c":"3260010877"},"book-1000","SC/EUR"]
1618678147.251971: [5104,{"a":[["0.000027850","670.30272889","1618678147.220822"]],"c":"2911965877"},"book-1000","OCEAN/XBT"]
1618678147.270675: [992,{"b":[["353.30000000","0.00000000","1618678147.236722"]],"c":"865785791"},"book-1000","XMR/USD"]
1618678147.2734709: [992,{"a":[["355.32000000","4.57411888","1618678147.239559"]],"c":"865785791"},"book-1000","XMR/USD"]
1618678147.274983: [992,{"a":[["355.27000000","0.00000000","1618678147.240118"]],"c":"865785791"},"book-1000","XMR/USD"]
1618678147.276416: [3648,{"a":[["0.00758300","0.00000000","1618678147.241884"]],"c":"1088780056"},"book-1000","KSM/XBT"]
1618678147.27703: [3648,{"b":[["0.00755800","4.21124030","1618678147.242805"]],"c":"370006842"},"book-1000","KSM/XBT"]
1618678147.2776132: [992,{"b":[["353.50000000","4.34693437","1618678147.242914"]],"c":"2350610209"},"book-1000","XMR/USD"]
1618678147.310755: {"event":"heartbeat"}
1618678147.589267: [3648,{"b":[["0.00756000","2.34667103","1618678147.558248"]],"c":"2061146528"},"book-1000","KSM/XBT"]
1618678147.590653: [5104,{"a":[["0.000027850","0.00000000","1618678147.559278"]],"c":"2127200917"},"book-1000","OCEAN/XBT"]
1618678147.591682: [496,{"a":[["2192.10000","0.00000000","1618678147.560409"]],"c":"3901530158"},"book-1000","ETH/CHF"]
1618678147.592949: [5104,{"a":[["0.000027870","728.20994257","1618678147.565501"]],"c":"2708378618"},"book-1000","OCEAN/XBT"]
1618678147.5975392: [3648,{"b":[["0.00755200","5.00000000","1618678147.569998"]],"c":"1252666508"},"book-1000","KSM/XBT"]
1618678147.605369: [992,{"b":[["269.01000000","0.09758001","1618678147.574831"]],"c":"2350610209"},"book-1000","XMR/USD"]
1618678147.608194: [992,{"b":[["352.28000000","0.00000000","1618678147.575668"]],"c":"2350610209"},"book-1000","XMR/USD"]
1618678147.61025: [464,{"b":[["55559.10000","0.00000000","1618678147.576221"]],"c":"714207813"},"book-1000","XBT/CHF"]
1618678147.6118531: [1840,{"b":[["9.577380","146.00000000","1618678147.576447"]],"c":"3142973725"},"book-1000","OMG/USD"]
1618678147.612758: [1920,{"a":[["0.043570","23239.60027887","1618678147.576757"]],"c":"3260010877"},"book-1000","SC/EUR"]
1618678147.615378: [992,{"b":[["353.64000000","0.00000000","1618678147.583932"]],"c":"1476999535"},"book-1000","XMR/USD"]
1618678147.6170812: [3648,{"b":[["0.00750300","5.86086666","1618678147.584036"]],"c":"1252666508"},"book-1000","KSM/XBT"]
1618678147.6178088: [1664,{"b":[["13.220900","0.00000000","1618678147.584779"]],"c":"3187915462"},"book-1000","WAVES/EUR"]
1618678147.6188989: [992,{"b":[["352.22000000","0.00000000","1618678147.585319"]],"c":"1476999535"},"book-1000","XMR/USD"]
1618678147.620578: [1664,{"b":[["13.222500","158.65590156","1618678147.586539"]],"c":"1322225444"},"book-1000","WAVES/EUR"]
1618678147.621634: [1360,{"b":[["0.000022870","18544.31284950","1618678147.586806"]],"c":"4129720198"},"book-1000","ADA/XBT"]
1618678147.6242769: [1664,{"a":[["13.284600","0.00000000","1618678147.590739"]],"c":"1322225444"},"book-1000","WAVES/EUR"]
1618678147.625366: [992,{"b":[["353.69000000","2.94054827","1618678147.593859"]],"c":"2445454981"},"book-1000","XMR/USD"]
1618678147.6270452: [5104,{"a":[["0.000027810","1127.84165937","1618678147.595392"]],"c":"2208646636"},"book-1000","OCEAN/XBT"]
1618678147.628323: [992,{"b":[["354.12000000","0.00000000","1618678147.600079"]],"c":"1873247932"},"book-1000","XMR/USD"]
1618678147.630326: [1664,{"a":[["13.270700","0.00000000","1618678147.602340"]],"c":"1322225444"},"book-1000","WAVES/EUR"]
1618678147.631412: [1664,{"a":[["13.257700","0.00000000","1618678147.603308"]],"c":"4048306443"},"book-1000","WAVES/EUR"]
1618678147.632611: [1664,{"a":[["13.241400","101.00000000","1618678147.604608"]],"c":"3694498896"},"book-1000","WAVES/EUR"]
1618678147.633666: [992,{"b":[["354.10000000","0.00000000","1618678147.605836"]],"c":"2413585987"},"book-1000","XMR/USD"]
1618678147.635433: [1664,{"b":[["13.217700","0.00000000","1618678147.606065"]],"c":"1752005316"},"book-1000","WAVES/EUR"]
1618678147.639269: [1664,{"b":[["13.216400","0.00000000","1618678147.608512"]],"c":"3401700630"},"book-1000","WAVES/EUR"]
1618678147.640536: [1664,{"a":[["13.259100","2018.51000000","1618678147.608819"]],"c":"1203082378"},"book-1000","WAVES/EUR"]
1618678147.641576: [992,{"b":[["354.13000000","6.85909358","1618678147.610307"]],"c":"1257857235"},"book-1000","XMR/USD"]
1618678147.6432588: [1664,{"b":[["13.215000","0.00000000","1618678147.610508"]],"c":"27910720"},"book-1000","WAVES/EUR"]
1618678147.671933: [992,{"b":[["353.21000000","0.00000000","1618678147.610569"]],"c":"1257857235"},"book-1000","XMR/USD"]
1618678147.674649: [496,{"a":[["2207.46000","0.00000000","1618678147.610622"]],"c":"3901530158"},"book-1000","ETH/CHF"]
1618678147.675526: [1664,{"b":[["13.144200","0.00000000","1618678147.611104"]],"c":"27910720"},"book-1000","WAVES/EUR"]
1618678147.676834: [992,{"b":[["353.50000000","0.00000000","1618678147.611402"]],"c":"3042782231"},"book-1000","XMR/USD"]
1618678147.6787431: [992,{"b":[["353.57000000","4.34607376","1618678147.611796"]],"c":"1379457367"},"book-1000","XMR/USD"]
1618678147.680476: [1664,{"a":[["13.274800","29.06000000","1618678147.613916"]],"c":"27910720"},"book-1000","WAVES/EUR"]
1618678147.6815622: [3648,{"b":[["0.00755800","2.99068160","1618678147.614710"]],"c":"474120366"},"book-1000","KSM/XBT"]
1618678147.682315: [496,{"a":[["2192.07000","1.15978265","1618678147.615493"]],"c":"1862317369"},"book-1000","ETH/CHF"]
1618678147.683038: [1664,{"b":[["13.204000","1066.71000000","1618678147.616487"]],"c":"2547773239"},"book-1000","WAVES/EUR"]
1618678147.684108: [1664,{"b":[["13.217500","0.00000000","1618678147.617951"]],"c":"4112048266"},"book-1000","WAVES/EUR"]
1618678147.6851509: [496,{"a":[["2192.09000","0.00000000","1618678147.618428"]],"c":"61514730"},"book-1000","ETH/CHF"]
1618678147.685847: [992,{"b":[["352.64000000","0.00000000","1618678147.619370"]],"c":"1379457367"},"book-1000","XMR/USD"]
1618678147.6897001: [992,{"b":[["354.11000000","0.00000000","1618678147.619783"]],"c":"2962446679"},"book-1000","XMR/USD"]
1618678147.691394: [496,{"b":[["2183.24000","1.51286819","1618678147.620417"]],"c":"2839850918"},"book-1000","ETH/CHF"]
1618678147.69209: [496,{"a":[["2205.10000","1.19254939","1618678147.621102"]],"c":"3961114383"},"book-1000","ETH/CHF"]
1618678147.692783: [496,{"b":[["2180.62000","3.00000000","1618678147.621409"]],"c":"3779527317"},"book-1000","ETH/CHF"]
1618678147.6934688: [1664,{"a":[["13.262300","789.46000000","1618678147.622456"]],"c":"1867999726"},"book-1000","WAVES/EUR"]
1618678147.69452: [1664,{"a":[["13.253800","0.00000000","1618678147.623292"]],"c":"2295703382"},"book-1000","WAVES/EUR"]
1618678147.695584: [992,{"b":[["353.79000000","0.00000000","1618678147.629888"]],"c":"760861215"},"book-1000","XMR/USD"]
1618678147.697251: [992,{"b":[["353.54000000","113.95250000","1618678147.630216"]],"c":"966410274"},"book-1000","XMR/USD"]
1618678147.698879: [1664,{"b":[["13.206300","566.44311759","1618678147.635732"]],"c":"3030283302"},"book-1000","WAVES/EUR"]
1618678147.699896: [992,{"a":[["354.69000000","22.07200000","1618678147.638076"]],"c":"3347035399"},"book-1000","XMR/USD"]
1618678147.7014961: [3648,{"a":[["0.00758200","1.34617811","1618678147.643870"]],"c":"3633293251"},"book-1000","KSM/XBT"]
1618678147.7024262: [1664,{"b":[["13.205900","0.00000000","1618678147.656585"]],"c":"3345409453"},"book-1000","WAVES/EUR"]
1618678147.703413: [1664,{"a":[["13.266400","0.00000000","1618678147.660303"]],"c":"3524397532"},"book-1000","WAVES/EUR"]
1618678147.7043571: [1664,{"a":[["13.262200","119.15886375","1618678147.661514"]],"c":"153471083"},"book-1000","WAVES/EUR"]
1618678147.705261: [1664,{"b":[["13.222500","0.00000000","1618678147.661879"]],"c":"2881855374"},"book-1000","WAVES/EUR"]
1618678147.7061398: [496,{"a":[["2192.06000","3.00000000","1618678147.662649"]],"c":"4651392"},"book-1000","ETH/CHF"]
1618678147.706722: [1664,{"a":[["13.241300","500.00000000","1618678147.673501"]],"c":"3753157220"},"book-1000","WAVES/EUR"]
1618678147.707593: [1664,{"b":[["13.213900","0.00000000","1618678147.674722"]],"c":"2138098606"},"book-1000","WAVES/EUR"]
1618678147.708631: [1920,{"b":[["0.042840","0.00000000","1618678147.677727"]],"c":"2402642127"},"book-1000","SC/EUR"]
1618678147.720551: [992,{"a":[["354.46000000","12.24000000","1618678147.691186"]],"c":"415863870"},"book-1000","XMR/USD"]
1618678147.729247: [992,{"b":[["353.80000000","7.00000000","1618678147.702128"]],"c":"1455389712"},"book-1000","XMR/USD"]
1618678147.736727: [1664,{"b":[["13.143900","8754.33005427","1618678147.708813"]],"c":"2138098606"},"book-1000","WAVES/EUR"]
1618678147.738626: [496,{"b":[["2183.25000","3.00000000","1618678147.709935"]],"c":"2997197892"},"book-1000","ETH/CHF"]
1618678147.739952: [1664,{"b":[["13.191600","347.44736537","1618678147.712260"]],"c":"648363281"},"book-1000","WAVES/EUR"]
1618678147.741274: [1664,{"b":[["12.710000","0.00000000","1618678147.712378"]],"c":"648363281"},"book-1000","WAVES/EUR"]
1618678147.742784: [1840,{"a":[["9.596651","250.00000000","1618678147.714476"]],"c":"4056930438"},"book-1000","OMG/USD"]
1618678147.743773: [1840,{"b":[["9.486856","208.67708535","1618678147.714570"]],"c":"4056930438"},"book-1000","OMG/USD"]
1618678147.752064: [1920,{"a":[["0.043170","0.00000000","1618678147.724767"]],"c":"3120468506"},"book-1000","SC/EUR"]
1618678147.765194: [1664,{"a":[["13.250400","0.00000000","1618678147.734035"]],"c":"2644617912"},"book-1000","WAVES/EUR"]
1618678147.7683148: [1360,{"b":[["0.000022870","12859.48103087","1618678147.739696"]],"c":"110422523"},"book-1000","ADA/XBT"]
1618678147.7718568: [992,{"a":[["354.77000000","11.52000000","1618678147.742900"]],"c":"2198076373"},"book-1000","XMR/USD"]
1618678147.773781: [1664,{"a":[["13.266500","0.00000000","1618678147.744066"]],"c":"2644617912"},"book-1000","WAVES/EUR"]
1618678147.774982: [496,{"b":[["2183.26000","1.51285434","1618678147.748195"]],"c":"3770961676"},"book-1000","ETH/CHF"]
1618678147.775926: [496,{"b":[["2183.24000","0.00000000","1618678147.748717"]],"c":"1949668509"},"book-1000","ETH/CHF"]
1618678147.776793: [496,{"a":[["2192.08000","0.00000000","1618678147.750760"]],"c":"2258262497"},"book-1000","ETH/CHF"]
1618678147.788519: [496,{"b":[["2180.62000","0.00000000","1618678147.761031"]],"c":"3053313163"},"book-1000","ETH/CHF"]
1618678147.7898839: [1664,{"b":[["12.647800","9.19001100","1618678147.761442"]],"c":"2644617912"},"book-1000","WAVES/EUR"]
1618678147.791734: [1664,{"a":[["13.247000","0.00000000","1618678147.764338"]],"c":"2929960383"},"book-1000","WAVES/EUR"]
1618678147.798361: [1664,{"b":[["13.203300","0.00000000","1618678147.768049"]],"c":"2584657210"},"book-1000","WAVES/EUR"]
1618678147.8001301: [1664,{"a":[["13.284500","0.00000000","1618678147.768382"]],"c":"2584657210"},"book-1000","WAVES/EUR"]
1618678147.801663: [1920,{"a":[["0.043160","0.00000000","1618678147.769567"]],"c":"4012898560"},"book-1000","SC/EUR"]
1618678147.809005: [5104,{"a":[["0.000027810","671.30348000","1618678147.781596"]],"c":"2708378618"},"book-1000","OCEAN/XBT"]
1618678147.815097: [1664,{"a":[["13.241400","123.63000000","1618678147.787222"]],"c":"3552513004"},"book-1000","WAVES/EUR"]
1618678147.8206139: [1920,{"a":[["0.043490","0.00000000","1618678147.793920"]],"c":"1372126794"},"book-1000","SC/EUR"]
1618678147.8244429: [1664,{"a":[["13.264200","132.36296561","1618678147.795322"]],"c":"1898248316"},"book-1000","WAVES/EUR"]
1618678147.8257332: [496,{"b":[["2183.25000","0.00000000","1618678147.796751"]],"c":"421731843"},"book-1000","ETH/CHF"]
1618678147.826613: [496,{"b":[["2183.27000","3.00000000","1618678147.797163"]],"c":"807734585"},"book-1000","ETH/CHF"]
1618678147.82759: [1664,{"b":[["13.090200","1000.00000000","1618678147.799376"]],"c":"1898248316"},"book-1000","WAVES/EUR"]
1618678147.828762: [3648,{"b":[["0.00755200","0.00000000","1618678147.801507"]],"c":"3909030639"},"book-1000","KSM/XBT"]
1618678147.847245: [1920,{"a":[["0.043150","905325.33415860","1618678147.808638"]],"c":"3400371254"},"book-1000","SC/EUR"]
1618678147.85273: [3648,{"b":[["0.00750700","0.13542912","1618678147.825043"]],"c":"3909030639"},"book-1000","KSM/XBT"]
1618678147.854084: [1360,{"a":[["0.000022940","21918.88348010","1618678147.826761"]],"c":"2441238493"},"book-1000","ADA/XBT"]
1618678147.85814: [1664,{"a":[["13.312800","1396.00000000","1618678147.830033"]],"c":"1898248316"},"book-1000","WAVES/EUR"]
1618678147.8593202: [992,{"a":[["354.96000000","143.42900000","1618678147.830262"]],"c":"3970281688"},"book-1000","XMR/USD"]
1618678147.861488: [1360,{"a":[["0.000022960","31576.53000000","1618678147.834706"]],"c":"2522724457"},"book-1000","ADA/XBT"]
1618678147.86478: [992,{"a":[["355.20000000","5.88128639","1618678147.836880"]],"c":"3970281688"},"book-1000","XMR/USD"]
1618678147.866559: [992,{"b":[["352.38000000","7.34910898","1618678147.836977"]],"c":"3970281688"},"book-1000","XMR/USD"]
1618678147.87808: [1920,{"a":[["0.043150","0.00000000","1618678147.849316"]],"c":"1372126794"},"book-1000","SC/EUR"]
1618678147.881623: [496,{"a":[["2192.07000","0.00000000","1618678147.850624"]],"c":"2400497056"},"book-1000","ETH/CHF"]
1618678147.882508: [496,{"a":[["2192.05000","1.15978265","1618678147.850872"]],"c":"4061447290"},"book-1000","ETH/CHF"]
1618678147.898528: [1920,{"b":[["0.042930","20000.00000000","1618678147.870663"]],"c":"1576019159"},"book-1000","SC/EUR"]
1618678147.902059: [1920,{"a":[["0.043140","0.00000000","1618678147.871190"]],"c":"47571518"},"book-1000","SC/EUR"]
1618678147.909772: [992,{"a":[["354.69000000","14.49700000","1618678147.879986"]],"c":"522605765"},"book-1000","XMR/USD"]
1618678147.9218402: [1664,{"a":[["13.259100","0.00000000","1618678147.894074"]],"c":"1212886756"},"book-1000","WAVES/EUR"]
1618678147.924024: [1664,{"b":[["13.189000","0.00000000","1618678147.896240"]],"c":"1986342538"},"book-1000","WAVES/EUR"]
1618678147.925662: [1920,{"a":[["0.043220","0.00000000","1618678147.899027"]],"c":"3647866167"},"book-1000","SC/EUR"]
1618678147.9285812: [1664,{"b":[["13.204000","0.00000000","1618678147.900642"]],"c":"1125707504"},"book-1000","WAVES/EUR"]
1618678147.929651: [1664,{"a":[["13.262300","0.00000000","1618678147.900784"]],"c":"1992855495"},"book-1000","WAVES/EUR"]
1618678147.934518: [1920,{"b":[["0.042910","0.00000000","1618678147.906797"]],"c":"648143329"},"book-1000","SC/EUR"]
1618678147.944451: [1920,{"a":[["0.043030","92780.18915513","1618678147.917376"]],"c":"2251591860"},"book-1000","SC/EUR"]
1618678147.9481971: [992,{"a":[["354.46000000","0.00000000","1618678147.918123"]],"c":"3513453501"},"book-1000","XMR/USD"]
1618678147.959868: [1920,{"b":[["0.042920","0.00000000","1618678147.930485"]],"c":"13743373"},"book-1000","SC/EUR"]
1618678147.9651399: [1664,{"b":[["13.206400","158.77566559","1618678147.936644"]],"c":"1305666162"},"book-1000","WAVES/EUR"]
1618678147.966689: [1664,{"b":[["13.196500","4.00000000","1618678147.937319"]],"c":"1072805691"},"book-1000","WAVES/EUR"]
1618678147.967942: [1664,{"b":[["13.191500","0.00000000","1618678147.937369"]],"c":"3686860827"},"book-1000","WAVES/EUR"]
1618678147.969198: [1664,{"a":[["13.264100","119.15886375","1618678147.937621"]],"c":"329169521"},"book-1000","WAVES/EUR"]
1618678147.9704762: [1664,{"a":[["13.262200","0.00000000","1618678147.939307"]],"c":"2079681969"},"book-1000","WAVES/EUR"]
1618678147.982378: [1664,{"b":[["13.191600","0.00000000","1618678147.952752"]],"c":"1585991633"},"book-1000","WAVES/EUR"]
1618678147.984254: [1664,{"a":[["13.245400","47.97246193","1618678147.954783"]],"c":"3263915645"},"book-1000","WAVES/EUR"]
1618678147.997524: [1664,{"b":[["13.196500","0.00000000","1618678147.969663"]],"c":"4244324215"},"book-1000","WAVES/EUR"]
1618678148.000501: [1664,{"b":[["13.196500","2.00000000","1618678147.972959"]],"c":"1389513341"},"book-1000","WAVES/EUR"]
1618678148.002086: [5104,{"a":[["0.000027810","1127.84165937","1618678147.974060"]],"c":"2208646636"},"book-1000","OCEAN/XBT"]
1618678148.0158532: [1664,{"b":[["12.582700","0.00000000","1618678147.988429"]],"c":"1389513341"},"book-1000","WAVES/EUR"]
1618678148.027612: [1664,{"b":[["13.199200","0.00000000","1618678148.000226"]],"c":"4275130818"},"book-1000","WAVES/EUR"]
1618678148.0361578: [496,{"b":[["2183.28000","1.51284047","1618678148.007954"]],"c":"1324276833"},"book-1000","ETH/CHF"]
1618678148.037497: [496,{"b":[["2183.26000","0.00000000","1618678148.008718"]],"c":"54206356"},"book-1000","ETH/CHF"]
1618678148.051641: [1840,{"a":[["9.596652","0.00000000","1618678148.023475"]],"c":"2799649701"},"book-1000","OMG/USD"]
1618678148.058014: [1664,{"b":[["13.172700","0.00000000","1618678148.031053"]],"c":"102894339"},"book-1000","WAVES/EUR"]
1618678148.06017: [1664,{"b":[["13.191000","0.00000000","1618678148.031849"]],"c":"2515084626"},"book-1000","WAVES/EUR"]
1618678148.062965: [1664,{"b":[["12.504300","9.29547605","1618678148.036553"]],"c":"2515084626"},"book-1000","WAVES/EUR"]
1618678148.0823848: [1920,{"a":[["0.043030","104582.96240563","1618678148.055378"]],"c":"3445410494"},"book-1000","SC/EUR"]
1618678148.085651: [496,{"b":[["2183.29000","3.00000000","1618678148.055880"]],"c":"1374810890"},"book-1000","ETH/CHF"]
1618678148.086724: [496,{"a":[["2192.04000","3.00000000","1618678148.056063"]],"c":"3234343482"},"book-1000","ETH/CHF"]
1618678148.089879: [1664,{"b":[["13.172800","1396.00000000","1618678148.062651"]],"c":"1183007765"},"book-1000","WAVES/EUR"]
1618678148.095177: [1840,{"a":[["9.596650","136.99188890","1618678148.067172"]],"c":"102428260"},"book-1000","OMG/USD"]
1618678148.11936: [1840,{"b":[["9.577380","0.00000000","1618678148.091651"]],"c":"152365356"},"book-1000","OMG/USD"]
1618678148.12127: [1920,{"b":[["0.042830","30688.47948986","1618678148.093937"]],"c":"1813151690"},"book-1000","SC/EUR"]
1618678148.124228: [1920,{"a":[["0.043190","183452.67067430","1618678148.094893"]],"c":"40728739"},"book-1000","SC/EUR"]
1618678148.142503: [496,{"b":[["2183.27000","0.00000000","1618678148.114961"]],"c":"252491038"},"book-1000","ETH/CHF"]
1618678148.143871: [496,{"a":[["2192.06000","0.00000000","1618678148.115009"]],"c":"1890981662"},"book-1000","ETH/CHF"]
1618678148.145453: [1840,{"a":[["9.596649","200.00000000","1618678148.118384"]],"c":"357648984"},"book-1000","OMG/USD"]
1618678148.147933: [1664,{"b":[["13.204600","32.74785683","1618678148.120910"]],"c":"1826655411"},"book-1000","WAVES/EUR"]
1618678148.149312: [992,{"a":[["359.64000000","0.00000000","1618678148.121730"]],"c":"3513453501"},"book-1000","XMR/USD"]
1618678148.155272: [496,{"a":[["2192.03000","1.15978265","1618678148.127524"]],"c":"3914768219"},"book-1000","ETH/CHF"]
1618678148.16496: [496,{"a":[["2192.05000","0.00000000","1618678148.136556"]],"c":"3950759903"},"book-1000","ETH/CHF"]
1618678148.1701381: [1664,{"a":[["13.245400","0.00000000","1618678148.141892"]],"c":"4041450783"},"book-1000","WAVES/EUR"]
1618678148.18846: [992,{"a":[["360.96000000","23.78423708","1618678148.160295"]],"c":"3513453501"},"book-1000","XMR/USD"]
1618678148.193279: [496,{"b":[["2153.79000","0.00000000","1618678148.166508"]],"c":"3950759903"},"book-1000","ETH/CHF"]
1618678148.202476: [1840,{"a":[["9.596651","50.00000000","1618678148.173580"]],"c":"2032407243"},"book-1000","OMG/USD"]
1618678148.235411: [496,{"b":[["2153.41000","14.29823432","1618678148.207428"]],"c":"3950759903"},"book-1000","ETH/CHF"]
1618678148.2554722: [1664,{"b":[["13.196500","0.00000000","1618678148.226562"]],"c":"1975177245"},"book-1000","WAVES/EUR"]
1618678148.2575119: [1664,{"b":[["13.172900","99.77966450","1618678148.228378"]],"c":"997882275"},"book-1000","WAVES/EUR"]
1618678148.266297: [496,{"a":[["2192.02000","3.00000000","1618678148.239656"]],"c":"2696237440"},"book-1000","ETH/CHF"]
1618678148.268688: [1360,{"b":[["0.000022870","18544.27415312","1618678148.241748"]],"c":"3897180081"},"book-1000","ADA/XBT"]
1618678148.286751: [1664,{"b":[["13.178200","132.49256062","1618678148.256802"]],"c":"4287492973"},"book-1000","WAVES/EUR"]
1618678148.3064058: {"event":"heartbeat"}
1618678148.309727: [496,{"b":[["2183.28000","0.00000000","1618678148.280194"]],"c":"2132452728"},"book-1000","ETH/CHF"]
1618678148.3112488: [496,{"b":[["2183.30000","1.51282660","1618678148.280327"]],"c":"2626837189"},"book-1000","ETH/CHF"]
1618678148.3125792: [1664,{"a":[["13.276800","0.00000000","1618678148.281276"]],"c":"4287492973"},"book-1000","WAVES/EUR"]
1618678148.3140311: [1664,{"b":[["13.172900","471.99857419","1618678148.281836"]],"c":"3635937751"},"book-1000","WAVES/EUR"]
1618678148.315286: [992,{"b":[["351.09000000","0.00000000","1618678148.283042"]],"c":"3513453501"},"book-1000","XMR/USD"]
1618678148.317395: [496,{"a":[["2192.04000","0.00000000","1618678148.288896"]],"c":"1499264047"},"book-1000","ETH/CHF"]
1618678148.334827: [1664,{"b":[["13.177500","132.41016540","1618678148.306608"]],"c":"4119247583"},"book-1000","WAVES/EUR"]
1618678148.338017: [496,{"a":[["2192.03000","1.27268265","1618678148.310895"]],"c":"2074535350"},"book-1000","ETH/CHF"]
1618678148.3422022: [3648,{"a":[["0.00760500","0.00000000","1618678148.315206"]],"c":"4154457534"},"book-1000","KSM/XBT"]
1618678148.345289: [1664,{"b":[["13.025500","0.00000000","1618678148.318805"]],"c":"4119247583"},"book-1000","WAVES/EUR"]
1618678148.384219: [1664,{"a":[["13.345200","168.20908288","1618678148.357362"]],"c":"4119247583"},"book-1000","WAVES/EUR"]
1618678148.3888: [1664,{"b":[["13.013300","1604.88287017","1618678148.359841"]],"c":"4119247583"},"book-1000","WAVES/EUR"]
1618678148.4016771: [496,{"a":[["2192.03000","0.11290000","1618678148.374180"]],"c":"3901934030"},"book-1000","ETH/CHF"]
1618678148.403043: [496,{"a":[["2192.01000","1.15978265","1618678148.375476"]],"c":"374733981"},"book-1000","ETH/CHF"]
1618678148.40659: [3648,{"a":[["0.00758900","14.15000000","1618678148.376594"]],"c":"1972854354"},"book-1000","KSM/XBT"]
1618678148.41386: [1664,{"b":[["13.172800","0.00000000","1618678148.386807"]],"c":"1930350876"},"book-1000","WAVES/EUR"]
1618678148.419286: [1920,{"b":[["0.042920","11958.39627840","1618678148.391742"]],"c":"13659467"},"book-1000","SC/EUR"]
1618678148.4250371: [1664,{"b":[["13.206300","151.44311759","1618678148.393541"]],"c":"2963476030"},"book-1000","WAVES/EUR"]
1618678148.4446762: [992,{"a":[["358.65000000","0.00000000","1618678148.416618"]],"c":"3513453501"},"book-1000","XMR/USD"]
1618678148.473482: [1664,{"a":[["13.267300","371.76203802","1618678148.446131"]],"c":"3331875290"},"book-1000","WAVES/EUR"]
1618678148.478865: [1664,{"b":[["13.144400","1396.00000000","1618678148.450778"]],"c":"3870906249"},"book-1000","WAVES/EUR"]
1618678148.48629: [1920,{"b":[["0.031000","187534.83870966","1618678148.459053"]],"c":"13659467"},"book-1000","SC/EUR"]
1618678148.49006: [1664,{"b":[["13.178200","0.00000000","1618678148.461165"]],"c":"208030312"},"book-1000","WAVES/EUR"]
1618678148.491615: [1664,{"b":[["13.196400","0.00000000","1618678148.461695"]],"c":"510995794"},"book-1000","WAVES/EUR"]
1618678148.501246: [1920,{"a":[["0.043180","905325.33415860","1618678148.473878"]],"c":"887401722"},"book-1000","SC/EUR"]
1618678148.511474: [1664,{"b":[["13.191400","0.00000000","1618678148.477251"]],"c":"1218200488"},"book-1000","WAVES/EUR"]
1618678148.518431: [1664,{"b":[["13.178300","415.00000000","1618678148.489158"]],"c":"760102537"},"book-1000","WAVES/EUR"]
1618678148.5203352: [1664,{"b":[["13.172900","372.21890969","1618678148.491254"]],"c":"3596196205"},"book-1000","WAVES/EUR"]
1618678148.524918: [1664,{"b":[["13.178300","514.73877905","1618678148.494311"]],"c":"18121804"},"book-1000","WAVES/EUR"]
1618678148.571967: [992,{"b":[["350.90000000","170.56989700","1618678148.544446"]],"c":"3513453501"},"book-1000","XMR/USD"]
1618678148.575083: [1840,{"b":[["9.575720","521.40092900","1618678148.547753"]],"c":"1594808401"},"book-1000","OMG/USD"]
1618678148.611681: [1664,{"b":[["13.204600","0.00000000","1618678148.584307"]],"c":"3091429039"},"book-1000","WAVES/EUR"]
1618678148.625639: [1664,{"a":[["13.242900","2037.38000000","1618678148.598025"]],"c":"870226637"},"book-1000","WAVES/EUR"]
1618678148.628855: [1840,{"a":[["9.598793","0.00000000","1618678148.599286"]],"c":"2164731348"},"book-1000","OMG/USD"]
1618678148.632791: [1664,{"a":[["13.241700","47.97246193","1618678148.603713"]],"c":"2430843133"},"book-1000","WAVES/EUR"]
1618678148.637293: [1664,{"b":[["13.187800","1099.30000000","1618678148.607964"]],"c":"1512303478"},"book-1000","WAVES/EUR"]
1618678148.64241: [1664,{"b":[["13.177600","99.74407618","1618678148.613627"]],"c":"808225100"},"book-1000","WAVES/EUR"]
1618678148.644184: [1664,{"b":[["13.178300","415.00000000","1618678148.613678"]],"c":"552079014"},"book-1000","WAVES/EUR"]
1618678148.648363: [1664,{"a":[["13.246000","801.89000000","1618678148.621270"]],"c":"3598894352"},"book-1000","WAVES/EUR"]
1618678148.65748: [1920,{"b":[["0.042920","0.00000000","1618678148.629532"]],"c":"3191852920"},"book-1000","SC/EUR"]
1618678148.707188: [992,{"a":[["358.34000000","170.31638400","1618678148.676420"]],"c":"3513453501"},"book-1000","XMR/USD"]
1618678148.719925: [1664,{"b":[["13.153000","132.56362888","1618678148.688810"]],"c":"4146362136"},"book-1000","WAVES/EUR"]
1618678148.745976: [1664,{"b":[["13.177500","0.00000000","1618678148.711106"]],"c":"2065646650"},"book-1000","WAVES/EUR"]
1618678148.761416: [1664,{"b":[["13.191400","15.03778383","1618678148.732013"]],"c":"4261023135"},"book-1000","WAVES/EUR"]
1618678148.7632918: [3648,{"b":[["0.00755800","0.71800000","1618678148.734735"]],"c":"477294175"},"book-1000","KSM/XBT"]
1618678148.764608: [1664,{"a":[["13.345400","0.00000000","1618678148.736738"]],"c":"4261023135"},"book-1000","WAVES/EUR"]
1618678148.7744582: [496,{"b":[["2180.63000","3.00000000","1618678148.746593"]],"c":"2787594085"},"book-1000","ETH/CHF"]
1618678148.775817: [496,{"b":[["2183.29000","0.00000000","1618678148.746637"]],"c":"858127558"},"book-1000","ETH/CHF"]
1618678148.776887: [496,{"a":[["2192.00000","3.00000000","1618678148.746767"]],"c":"3783318265"},"book-1000","ETH/CHF"]
1618678148.784996: [1360,{"b":[["0.000022850","14228.66696383","1618678148.757827"]],"c":"186855959"},"book-1000","ADA/XBT"]
1618678148.800999: [1664,{"b":[["13.202100","32.74785683","1618678148.771895"]],"c":"3314824630"},"book-1000","WAVES/EUR"]
1618678148.8090801: [496,{"a":[["2191.99000","1.15978265","1618678148.781885"]],"c":"3894988234"},"book-1000","ETH/CHF"]
1618678148.810703: [464,{"b":[["55573.60000","0.01200000","1618678148.783612"]],"c":"714207813"},"book-1000","XBT/CHF"]
1618678148.812779: [496,{"a":[["2192.01000","0.00000000","1618678148.784159"]],"c":"1618742781"},"book-1000","ETH/CHF"]
1618678148.817546: [1664,{"a":[["13.241700","0.00000000","1618678148.789435"]],"c":"3700625993"},"book-1000","WAVES/EUR"]
1618678148.8217201: [496,{"a":[["2192.02000","0.00000000","1618678148.794109"]],"c":"1442752054"},"book-1000","ETH/CHF"]
1618678148.826287: [992,{"a":[["354.75000000","7.57500000","1618678148.798978"]],"c":"2086532520"},"book-1000","XMR/USD"]
1618678148.828948: [1360,{"b":[["0.000022850","14981.27485772","1618678148.799559"]],"c":"356134121"},"book-1000","ADA/XBT"]
1618678148.832208: [1664,{"b":[["13.187900","66.28496321","1618678148.806043"]],"c":"2374795227"},"book-1000","WAVES/EUR"]
1618678148.84867: [1920,{"a":[["0.043050","64120.00000000","1618678148.819998"]],"c":"697635720"},"book-1000","SC/EUR"]
1618678148.85248: [1664,{"b":[["13.198300","500.00000000","1618678148.822808"]],"c":"859294903"},"book-1000","WAVES/EUR"]
1618678148.853805: [1664,{"a":[["13.234700","102.00000000","1618678148.823812"]],"c":"3532044780"},"book-1000","WAVES/EUR"]
1618678148.8550808: [1664,{"b":[["13.203700","101.00000000","1618678148.824401"]],"c":"3049255133"},"book-1000","WAVES/EUR"]
1618678148.856171: [992,{"b":[["352.25000000","12.36000000","1618678148.824728"]],"c":"2086532520"},"book-1000","XMR/USD"]
1618678148.858036: [496,{"a":[["2191.98000","3.00000000","1618678148.829279"]],"c":"1369554520"},"book-1000","ETH/CHF"]
1618678148.862869: [1664,{"a":[["13.250300","0.00000000","1618678148.835700"]],"c":"681661877"},"book-1000","WAVES/EUR"]
1618678148.900844: [1664,{"b":[["13.173000","99.77890644","1618678148.873708"]],"c":"681661877"},"book-1000","WAVES/EUR"]
1618678148.90231: [1664,{"b":[["13.177600","0.00000000","1618678148.873832"]],"c":"681661877"},"book-1000","WAVES/EUR"]
1618678148.9070961: [496,{"b":[["2183.31000","3.00000000","1618678148.880159"]],"c":"595202386"},"book-1000","ETH/CHF"]
1618678148.9458728: [1664,{"a":[["13.312700","1000.00000000","1618678148.915959"]],"c":"681661877"},"book-1000","WAVES/EUR"]
1618678148.947809: [496,{"b":[["2183.30000","0.00000000","1618678148.916055"]],"c":"2618030304"},"book-1000","ETH/CHF"]
1618678148.950785: [1920,{"a":[["0.043110","138894.00000000","1618678148.919666"]],"c":"2588569763"},"book-1000","SC/EUR"]
1618678148.953793: [1920,{"b":[["0.042800","139258.00000000","1618678148.920142"]],"c":"3852153590"},"book-1000","SC/EUR"]
1618678148.9565299: [496,{"b":[["2183.32000","1.51281277","1618678148.927349"]],"c":"2947949902"},"book-1000","ETH/CHF"]
1618678148.957333: [496,{"a":[["2192.00000","0.00000000","1618678148.927509"]],"c":"147474880"},"book-1000","ETH/CHF"]
