1618678159.440655: [992,{"b":[["353.43000000","7.57500000","1618678159.413063"]],"c":"2626187815"},"book-1000","XMR/USD"]
1618678159.450897: [992,{"b":[["352.65000000","0.00000000","1618678159.423160"]],"c":"2626187815"},"book-1000","XMR/USD"]
1618678159.45405: [1920,{"b":[["0.042930","0.00000000","1618678159.424638"]],"c":"629591921"},"book-1000","SC/EUR"]
1618678159.456783: [1920,{"a":[["0.043140","0.00000000","1618678159.425259"]],"c":"2716090870"},"book-1000","SC/EUR"]
1618678159.459121: [992,{"b":[["352.99000000","117.11050000","1618678159.425463"]],"c":"2626187815"},"book-1000","XMR/USD"]
1618678159.460983: [1664,{"a":[["13.451200","0.00000000","1618678159.430037"]],"c":"2303789431"},"book-1000","WAVES/EUR"]
1618678159.466409: [1840,{"b":[["9.575471","0.00000000","1618678159.438957"]],"c":"3853859975"},"book-1000","OMG/USD"]
1618678159.46986: [1360,{"b":[["0.000022870","12230.58214387","1618678159.442405"]],"c":"2173784157"},"book-1000","ADA/XBT"]
1618678159.473237: [4528,{"a":[["0.000837200","0.00000000","1618678159.443188"]],"c":"364527037"},"book-1000","GRT/ETH"]
1618678159.473773: [992,{"a":[["354.53000000","6.86553892","1618678159.445111"]],"c":"3738160750"},"book-1000","XMR/USD"]
1618678159.4808471: [3648,{"b":[["0.00754600","8.12106000","1618678159.451055"]],"c":"2328735147"},"book-1000","KSM/XBT"]
1618678159.48629: [992,{"b":[["347.73000000","81.63469879","1618678159.458246"]],"c":"3738160750"},"book-1000","XMR/USD"]
1618678159.489135: [992,{"b":[["353.40000000","0.00000000","1618678159.458529"]],"c":"2753395047"},"book-1000","XMR/USD"]
1618678159.4928908: [3648,{"a":[["0.00757900","0.00000000","1618678159.461895"]],"c":"3072265169"},"book-1000","KSM/XBT"]
1618678159.494066: [992,{"b":[["353.43000000","12.57500000","1618678159.465473"]],"c":"3382790638"},"book-1000","XMR/USD"]
1618678159.4963489: [1920,{"a":[["0.043190","947787.17302786","1618678159.467666"]],"c":"2922954005"},"book-1000","SC/EUR"]
1618678159.498954: [1664,{"a":[["13.447800","1603.57015781","1618678159.469971"]],"c":"2303789431"},"book-1000","WAVES/EUR"]
1618678159.515819: [5104,{"a":[["0.000027820","593.84154000","1618678159.486040"]],"c":"1163499891"},"book-1000","OCEAN/XBT"]
1618678159.5170891: [5104,{"b":[["0.000027720","917.26111711","1618678159.486742"]],"c":"3391957516"},"book-1000","OCEAN/XBT"]
1618678159.518085: [3648,{"b":[["0.00755800","0.49100000","1618678159.488207"]],"c":"2507499653"},"book-1000","KSM/XBT"]
1618678159.519399: [3648,{"b":[["0.00755900","0.37890103","1618678159.488798"]],"c":"3308811743"},"book-1000","KSM/XBT"]
1618678159.5202801: [4528,{"a":[["0.000836300","304.01009322","1618678159.491172"]],"c":"1557984463"},"book-1000","GRT/ETH"]
1618678159.52061: [992,{"a":[["354.77000000","7.20002872","1618678159.491645"]],"c":"1499337680"},"book-1000","XMR/USD"]
1618678159.522602: [992,{"a":[["354.77000000","3.50255347","1618678159.492081"]],"c":"1132133928"},"book-1000","XMR/USD"]
1618678159.52428: [992,{"b":[["353.39000000","0.00000000","1618678159.493024"]],"c":"2002169678"},"book-1000","XMR/USD"]
1618678159.525939: [1920,{"b":[["0.042970","20514.81078729","1618678159.493729"]],"c":"3910534587"},"book-1000","SC/EUR"]
1618678159.528342: [992,{"b":[["347.98000000","23.80463099","1618678159.499310"]],"c":"2002169678"},"book-1000","XMR/USD"]
1618678159.531086: [992,{"b":[["353.42000000","6.86558781","1618678159.503296"]],"c":"2615697493"},"book-1000","XMR/USD"]
1618678159.532882: [992,{"b":[["353.44000000","22.72500000","1618678159.503693"]],"c":"4100121424"},"book-1000","XMR/USD"]
1618678159.5449338: [1840,{"b":[["9.519365","0.00000000","1618678159.516577"]],"c":"3853859975"},"book-1000","OMG/USD"]
1618678159.5462568: [1920,{"a":[["0.043190","905325.33415860","1618678159.517365"]],"c":"3872061784"},"book-1000","SC/EUR"]
1618678159.5642948: [496,{"b":[["2183.42000","0.00000000","1618678159.536120"]],"c":"2206946723"},"book-1000","ETH/CHF"]
1618678159.5701199: [1360,{"b":[["0.000022880","19680.95789894","1618678159.539823"]],"c":"215065282"},"book-1000","ADA/XBT"]
1618678159.5738618: [496,{"b":[["2183.44000","1.51272961","1618678159.540440"]],"c":"1290816007"},"book-1000","ETH/CHF"]
1618678159.5747478: [1664,{"b":[["13.182700","15.04770478","1618678159.541042"]],"c":"2303789431"},"book-1000","WAVES/EUR"]
1618678159.576052: [992,{"b":[["353.41000000","0.00000000","1618678159.542890"]],"c":"3946222016"},"book-1000","XMR/USD"]
1618678159.57807: [1920,{"b":[["0.043030","0.00000000","1618678159.549366"]],"c":"1971861976"},"book-1000","SC/EUR"]
1618678159.581057: [5104,{"b":[["0.000027630","17567.16094171","1618678159.550126"]],"c":"1592787385"},"book-1000","OCEAN/XBT"]
1618678159.5839622: [1920,{"b":[["0.043020","31100.00000000","1618678159.553276"]],"c":"1073199099"},"book-1000","SC/EUR"]
1618678159.5877252: [992,{"a":[["354.54000000","0.00000000","1618678159.559568"]],"c":"2713061218"},"book-1000","XMR/USD"]
1618678159.5902562: [1920,{"a":[["0.043120","42461.83886926","1618678159.563317"]],"c":"2527521806"},"book-1000","SC/EUR"]
1618678159.5973408: [1840,{"a":[["9.594245","155.92159500","1618678159.568928"]],"c":"2017004183"},"book-1000","OMG/USD"]
1618678159.607349: [1360,{"b":[["0.000022890","2188.50442708","1618678159.579357"]],"c":"2637837948"},"book-1000","ADA/XBT"]
1618678159.611189: [1840,{"b":[["9.555933","360.00000000","1618678159.579541"]],"c":"2017004183"},"book-1000","OMG/USD"]
1618678159.614893: [992,{"b":[["352.67000000","0.00000000","1618678159.585288"]],"c":"2713061218"},"book-1000","XMR/USD"]
1618678159.617655: [992,{"b":[["353.17000000","4.35099612","1618678159.585751"]],"c":"2683047705"},"book-1000","XMR/USD"]
1618678159.6198761: [1840,{"b":[["9.576517","494.94581039","1618678159.589538"]],"c":"1430487819"},"book-1000","OMG/USD"]
1618678159.620943: [992,{"b":[["353.04000000","76.26474337","1618678159.592473"]],"c":"3355646739"},"book-1000","XMR/USD"]
1618678159.625258: [992,{"b":[["353.45000000","5.00000000","1618678159.595145"]],"c":"1144006844"},"book-1000","XMR/USD"]
1618678159.627407: [1360,{"a":[["0.000022920","7061.85356623","1618678159.595821"]],"c":"2572608397"},"book-1000","ADA/XBT"]
1618678159.629947: [992,{"a":[["354.69000000","2.37700000","1618678159.596416"]],"c":"2838820419"},"book-1000","XMR/USD"]
1618678159.631635: [992,{"b":[["352.93000000","0.00000000","1618678159.597671"]],"c":"2838820419"},"book-1000","XMR/USD"]
1618678159.633512: [992,{"b":[["353.43000000","165.05770000","1618678159.605199"]],"c":"1651477521"},"book-1000","XMR/USD"]
1618678159.636061: [992,{"a":[["354.77000000","0.00000000","1618678159.609954"]],"c":"952343788"},"book-1000","XMR/USD"]
1618678159.638165: [1920,{"b":[["0.042920","0.00000000","1618678159.611356"]],"c":"2193025152"},"book-1000","SC/EUR"]
1618678159.6402571: [992,{"a":[["355.12000000","161.41570000","1618678159.612134"]],"c":"1714410219"},"book-1000","XMR/USD"]
1618678159.6419: [3648,{"b":[["0.00755400","3.95974098","1618678159.612906"]],"c":"3026327173"},"book-1000","KSM/XBT"]
1618678159.644075: [1920,{"a":[["0.043270","139844.00000000","1618678159.614737"]],"c":"37928463"},"book-1000","SC/EUR"]
1618678159.652108: [992,{"a":[["354.78000000","0.00000000","1618678159.623792"]],"c":"1806786759"},"book-1000","XMR/USD"]
1618678159.665477: [1840,{"a":[["9.594245","0.00000000","1618678159.637748"]],"c":"3369055515"},"book-1000","OMG/USD"]
1618678159.6736372: [992,{"a":[["355.03000000","4.57411888","1618678159.643531"]],"c":"2672261255"},"book-1000","XMR/USD"]
1618678159.676973: [992,{"b":[["353.43000000","160.05770000","1618678159.648908"]],"c":"3444404289"},"book-1000","XMR/USD"]
1618678159.6807098: [1360,{"a":[["0.000022960","35923.76059644","1618678159.652726"]],"c":"2838247741"},"book-1000","ADA/XBT"]
1618678159.683944: [1920,{"b":[["0.042960","173624.00000000","1618678159.653958"]],"c":"2404168640"},"book-1000","SC/EUR"]
1618678159.686591: [992,{"b":[["351.69000000","0.00000000","1618678159.655774"]],"c":"3444404289"},"book-1000","XMR/USD"]
1618678159.688315: [496,{"a":[["2192.02000","0.00000000","1618678159.656324"]],"c":"1429847242"},"book-1000","ETH/CHF"]
1618678159.689031: [496,{"a":[["2192.02000","0.13552252","1618678159.657423"]],"c":"1418869461"},"book-1000","ETH/CHF"]
1618678159.700979: [992,{"b":[["353.46000000","22.72500000","1618678159.672935"]],"c":"12415260"},"book-1000","XMR/USD"]
1618678159.7259352: [992,{"a":[["355.03000000","0.00000000","1618678159.698088"]],"c":"4098582876"},"book-1000","XMR/USD"]
1618678159.731324: [496,{"b":[["2183.45000","3.00000000","1618678159.703867"]],"c":"3278062010"},"book-1000","ETH/CHF"]
1618678159.73337: [496,{"a":[["2192.02000","0.00000000","1618678159.705355"]],"c":"3012843771"},"book-1000","ETH/CHF"]
1618678159.734338: [992,{"b":[["352.94000000","0.00000000","1618678159.706082"]],"c":"4098582876"},"book-1000","XMR/USD"]
1618678159.7412071: [1360,{"a":[["0.000022960","32323.58979644","1618678159.712526"]],"c":"2572608397"},"book-1000","ADA/XBT"]
1618678159.7452958: [496,{"a":[["2192.90000","1.15978265","1618678159.715339"]],"c":"1687171381"},"book-1000","ETH/CHF"]
1618678159.7463958: [992,{"a":[["354.94000000","7.00000000","1618678159.719849"]],"c":"1975761899"},"book-1000","XMR/USD"]
1618678159.760122: [464,{"b":[["55789.00000","0.00000000","1618678159.732928"]],"c":"2203918057"},"book-1000","XBT/CHF"]
1618678159.762516: [992,{"b":[["353.44000000","0.00000000","1618678159.733274"]],"c":"1751509939"},"book-1000","XMR/USD"]
1618678159.772471: [3648,{"a":[["0.00758900","0.00000000","1618678159.745056"]],"c":"1130611847"},"book-1000","KSM/XBT"]
1618678159.773663: [992,{"a":[["355.11000000","4.57411888","1618678159.745829"]],"c":"193912070"},"book-1000","XMR/USD"]
1618678159.7765539: [1920,{"b":[["0.042970","0.00000000","1618678159.749817"]],"c":"2815253184"},"book-1000","SC/EUR"]
1618678159.7812831: [1840,{"a":[["9.609936","108.07278812","1618678159.754060"]],"c":"523949281"},"book-1000","OMG/USD"]
1618678159.78287: [496,{"b":[["2183.43000","0.00000000","1618678159.754838"]],"c":"1195394123"},"book-1000","ETH/CHF"]
1618678159.793406: [1664,{"b":[["13.063300","75.64182084","1618678159.766253"]],"c":"2303789431"},"book-1000","WAVES/EUR"]
1618678159.7951481: [1360,{"a":[["0.000022950","5584.16491659","1618678159.766318"]],"c":"4799487"},"book-1000","ADA/XBT"]
1618678159.7981608: [1360,{"a":[["0.000022960","37323.58979644","1618678159.766802"]],"c":"4227601274"},"book-1000","ADA/XBT"]
1618678159.800826: [1840,{"a":[["9.629433","0.00000000","1618678159.770313"]],"c":"523949281"},"book-1000","OMG/USD"]
1618678159.8079832: [1920,{"a":[["0.044330","0.00000000","1618678159.778710"]],"c":"2815253184"},"book-1000","SC/EUR"]
1618678159.811446: [992,{"a":[["355.11000000","0.00000000","1618678159.779789"]],"c":"1751509939"},"book-1000","XMR/USD"]
1618678159.813527: [992,{"a":[["355.16000000","4.57411888","1618678159.781178"]],"c":"2222739791"},"book-1000","XMR/USD"]
1618678159.833824: [1360,{"b":[["0.000022890","7229.85920805","1618678159.806023"]],"c":"23813426"},"book-1000","ADA/XBT"]
1618678159.8499: [496,{"b":[["2183.46000","1.51271577","1618678159.819286"]],"c":"2237764114"},"book-1000","ETH/CHF"]
1618678159.851242: [992,{"a":[["354.94000000","0.00000000","1618678159.820430"]],"c":"2406243258"},"book-1000","XMR/USD"]
1618678159.8536441: [1920,{"a":[["0.044360","328457.42064738","1618678159.820516"]],"c":"2815253184"},"book-1000","SC/EUR"]
1618678159.856367: [496,{"b":[["2183.44000","0.00000000","1618678159.820919"]],"c":"3073325680"},"book-1000","ETH/CHF"]
1618678159.857237: [3648,{"b":[["0.00755500","1.09005000","1618678159.826459"]],"c":"2212370065"},"book-1000","KSM/XBT"]
1618678159.863193: [1360,{"b":[["0.000022760","0.00000000","1618678159.835163"]],"c":"23813426"},"book-1000","ADA/XBT"]
1618678159.867237: [1840,{"a":[["9.596672","0.00000000","1618678159.838669"]],"c":"3930763760"},"book-1000","OMG/USD"]
1618678159.872473: [5104,{"a":[["0.000028160","0.00000000","1618678159.844257"]],"c":"1592787385"},"book-1000","OCEAN/XBT"]
1618678159.895267: [496,{"b":[["2183.47000","3.00000000","1618678159.867336"]],"c":"2979033828"},"book-1000","ETH/CHF"]
1618678159.904238: [1360,{"b":[["0.000022770","17244.99428831","1618678159.876800"]],"c":"23813426"},"book-1000","ADA/XBT"]
1618678159.920976: [992,{"b":[["351.77000000","0.00000000","1618678159.892910"]],"c":"2406243258"},"book-1000","XMR/USD"]
1618678159.929656: [1840,{"b":[["9.562320","0.00000000","1618678159.902081"]],"c":"3930763760"},"book-1000","OMG/USD"]
1618678159.9326541: [1664,{"b":[["13.153000","0.00000000","1618678159.905376"]],"c":"2303789431"},"book-1000","WAVES/EUR"]
1618678159.934317: [1664,{"b":[["13.173200","0.00000000","1618678159.905680"]],"c":"2303789431"},"book-1000","WAVES/EUR"]
1618678159.935786: [5104,{"a":[["0.000027910","41.04853696","1618678159.908063"]],"c":"89071109"},"book-1000","OCEAN/XBT"]
1618678159.9412632: [1360,{"b":[["0.000022870","7943.16413900","1618678159.912995"]],"c":"3750469890"},"book-1000","ADA/XBT"]
1618678159.94981: [992,{"a":[["355.06000000","131.27150000","1618678159.921861"]],"c":"2843312954"},"book-1000","XMR/USD"]
1618678159.958102: [1360,{"a":[["0.000022920","6071.85356623","1618678159.930131"]],"c":"1472510455"},"book-1000","ADA/XBT"]
1618678159.9656: [992,{"b":[["351.88000000","0.00000000","1618678159.937510"]],"c":"2843312954"},"book-1000","XMR/USD"]
1618678159.968562: [5104,{"a":[["0.000027830","1071.47757171","1618678159.937651"]],"c":"4038762950"},"book-1000","OCEAN/XBT"]
1618678159.969666: [1840,{"b":[["9.561621","160.70929543","1618678159.938877"]],"c":"3930763760"},"book-1000","OMG/USD"]
1618678159.9707189: [1840,{"b":[["9.562321","0.00000000","1618678159.940197"]],"c":"3930763760"},"book-1000","OMG/USD"]
1618678159.971926: [1840,{"a":[["9.604803","0.00000000","1618678159.943951"]],"c":"2543995697"},"book-1000","OMG/USD"]
1618678159.978185: [1840,{"a":[["9.630460","194.10704088","1618678159.950413"]],"c":"3758512467"},"book-1000","OMG/USD"]
1618678159.9795861: [1840,{"b":[["9.574672","521.33082500","1618678159.951089"]],"c":"1579865825"},"book-1000","OMG/USD"]
1618678159.987294: [496,{"a":[["2205.10000","0.00000000","1618678159.958601"]],"c":"2979033828"},"book-1000","ETH/CHF"]
1618678160.003127: [1664,{"b":[["13.090300","0.00000000","1618678159.974653"]],"c":"2303789431"},"book-1000","WAVES/EUR"]
1618678160.007797: [1360,{"b":[["0.000022860","29338.26632365","1618678159.980835"]],"c":"1716241239"},"book-1000","ADA/XBT"]
1618678160.011441: [1920,{"a":[["0.043120","0.00000000","1618678159.982300"]],"c":"325072618"},"book-1000","SC/EUR"]
1618678160.021169: [496,{"a":[["2207.46000","1.19097621","1618678159.993085"]],"c":"2979033828"},"book-1000","ETH/CHF"]
1618678160.0275462: [1840,{"b":[["9.576517","544.94581039","1618678159.995285"]],"c":"1838898375"},"book-1000","OMG/USD"]
1618678160.031897: [1360,{"b":[["0.000022850","33671.64696383","1618678160.001709"]],"c":"243266287"},"book-1000","ADA/XBT"]
1618678160.035552: [992,{"b":[["353.03000000","0.00000000","1618678160.002286"]],"c":"2843312954"},"book-1000","XMR/USD"]
1618678160.0376031: [1360,{"b":[["0.000022830","5049.70089865","1618678160.004487"]],"c":"584489560"},"book-1000","ADA/XBT"]
1618678160.044663: [992,{"a":[["354.41000000","3.01559666","1618678160.017513"]],"c":"1998025136"},"book-1000","XMR/USD"]
1618678160.049192: [1920,{"a":[["0.043140","8500.00000000","1618678160.021988"]],"c":"218013993"},"book-1000","SC/EUR"]
1618678160.05251: [1920,{"a":[["0.043170","42461.83886926","1618678160.024488"]],"c":"2643676793"},"book-1000","SC/EUR"]
1618678160.061137: [992,{"a":[["354.49000000","1.40000000","1618678160.032011"]],"c":"1999427646"},"book-1000","XMR/USD"]
1618678160.071297: [1664,{"b":[["13.186200","0.00000000","1618678160.044024"]],"c":"2303789431"},"book-1000","WAVES/EUR"]
1618678160.07265: [1920,{"b":[["0.043000","47280.00000000","1618678160.044585"]],"c":"951341657"},"book-1000","SC/EUR"]
1618678160.0804539: [992,{"b":[["353.50000000","1.40000000","1618678160.052891"]],"c":"3613229839"},"book-1000","XMR/USD"]
1618678160.0864341: [496,{"b":[["2183.48000","1.51270191","1618678160.057884"]],"c":"1648181178"},"book-1000","ETH/CHF"]
1618678160.0877829: [496,{"b":[["2183.46000","0.00000000","1618678160.059596"]],"c":"1641601483"},"book-1000","ETH/CHF"]
1618678160.0917919: [992,{"b":[["353.33000000","15.27000000","1618678160.061344"]],"c":"4133480531"},"book-1000","XMR/USD"]
1618678160.0947719: [1840,{"a":[["9.701959","0.00000000","1618678160.067545"]],"c":"1838898375"},"book-1000","OMG/USD"]
1618678160.1037178: [992,{"b":[["353.49000000","7.00000000","1618678160.076707"]],"c":"1426864704"},"book-1000","XMR/USD"]
1618678160.10779: [992,{"a":[["354.37000000","1.40000000","1618678160.081057"]],"c":"745852842"},"book-1000","XMR/USD"]
1618678160.109959: [992,{"a":[["354.49000000","0.00000000","1618678160.081104"]],"c":"3510882978"},"book-1000","XMR/USD"]
1618678160.1169631: [992,{"a":[["354.41000000","0.00000000","1618678160.088561"]],"c":"2312582980"},"book-1000","XMR/USD"]
1618678160.121266: [5104,{"b":[["0.000027720","654.72387000","1618678160.092588"]],"c":"2144211641"},"book-1000","OCEAN/XBT"]
1618678160.129573: [1664,{"b":[["13.201300","415.00000000","1618678160.101635"]],"c":"2634454858"},"book-1000","WAVES/EUR"]
1618678160.134306: [992,{"a":[["355.11000000","4.57411888","1618678160.105438"]],"c":"2127264814"},"book-1000","XMR/USD"]
1618678160.1420312: [992,{"a":[["355.16000000","0.00000000","1618678160.108178"]],"c":"3866291804"},"book-1000","XMR/USD"]
1618678160.144902: [5104,{"a":[["0.000028130","35212.88207833","1618678160.110399"]],"c":"2144211641"},"book-1000","OCEAN/XBT"]
1618678160.146091: [1840,{"b":[["9.556775","0.00000000","1618678160.112265"]],"c":"1838898375"},"book-1000","OMG/USD"]
1618678160.14716: [1840,{"a":[["9.608471","0.00000000","1618678160.118019"]],"c":"618088826"},"book-1000","OMG/USD"]
1618678160.14816: [1920,{"b":[["0.043030","14156.72843942","1618678160.118747"]],"c":"2587674491"},"book-1000","SC/EUR"]
1618678160.153402: [992,{"b":[["352.67000000","75.00000000","1618678160.126286"]],"c":"3866291804"},"book-1000","XMR/USD"]
1618678160.156673: [992,{"a":[["354.37000000","0.00000000","1618678160.129236"]],"c":"78376205"},"book-1000","XMR/USD"]
1618678160.1590028: [992,{"b":[["353.50000000","24.12500000","1618678160.130920"]],"c":"3040279633"},"book-1000","XMR/USD"]
1618678160.164038: [5104,{"a":[["0.000027810","606.16153000","1618678160.136927"]],"c":"1489576729"},"book-1000","OCEAN/XBT"]
1618678160.1724339: [464,{"b":[["55800.20000","0.41109236","1618678160.145858"]],"c":"2203918057"},"book-1000","XBT/CHF"]
1618678160.174902: [1840,{"b":[["9.569838","73.00000000","1618678160.146273"]],"c":"1597373997"},"book-1000","OMG/USD"]
1618678160.176275: [1664,{"b":[["13.223000","96.00000000","1618678160.147861"]],"c":"1061467626"},"book-1000","WAVES/EUR"]
1618678160.1775901: [992,{"a":[["354.49000000","1.40000000","1618678160.149789"]],"c":"2020182262"},"book-1000","XMR/USD"]
1618678160.1838138: [1840,{"a":[["9.672524","1857.00000000","1618678160.153068"]],"c":"1597373997"},"book-1000","OMG/USD"]
1618678160.1882958: [1360,{"a":[["0.000022920","5053.55356623","1618678160.159457"]],"c":"1069467985"},"book-1000","ADA/XBT"]
1618678160.193702: [1360,{"b":[["0.000022840","30669.50816800","1618678160.164284"]],"c":"1852936339"},"book-1000","ADA/XBT"]
1618678160.197353: [1840,{"a":[["9.596671","0.00000000","1618678160.164665"]],"c":"1698879842"},"book-1000","OMG/USD"]
1618678160.198405: [1360,{"b":[["0.000022880","20681.55789894","1618678160.165446"]],"c":"2597060985"},"book-1000","ADA/XBT"]
1618678160.201196: [992,{"a":[["354.76000000","3.01559666","1618678160.171042"]],"c":"848409763"},"book-1000","XMR/USD"]
1618678160.202881: [992,{"b":[["353.44000000","4.34767230","1618678160.172467"]],"c":"3618880002"},"book-1000","XMR/USD"]
1618678160.2045372: [1840,{"b":[["9.568474","105.00000000","1618678160.172592"]],"c":"3827751925"},"book-1000","OMG/USD"]
1618678160.205714: [1664,{"b":[["13.201300","0.00000000","1618678160.178772"]],"c":"3002100404"},"book-1000","WAVES/EUR"]
1618678160.206743: [992,{"b":[["353.50000000","29.12500000","1618678160.179704"]],"c":"2532008205"},"book-1000","XMR/USD"]
1618678160.20841: [992,{"b":[["353.46000000","0.00000000","1618678160.180235"]],"c":"2213339572"},"book-1000","XMR/USD"]
1618678160.212409: [992,{"b":[["353.17000000","0.00000000","1618678160.185770"]],"c":"1262380416"},"book-1000","XMR/USD"]
1618678160.2181199: [992,{"a":[["354.69000000","0.00000000","1618678160.190487"]],"c":"4291316892"},"book-1000","XMR/USD"]
1618678160.227038: [1840,{"a":[["9.596670","136.94728603","1618678160.200714"]],"c":"3943361354"},"book-1000","OMG/USD"]
1618678160.228875: [1920,{"b":[["0.043000","38780.00000000","1618678160.200807"]],"c":"206836914"},"book-1000","SC/EUR"]
1618678160.231859: [1920,{"b":[["0.043010","14302.95592353","1618678160.200912"]],"c":"937126812"},"book-1000","SC/EUR"]
1618678160.234328: [992,{"a":[["354.90000000","3.10000000","1618678160.201691"]],"c":"2986147275"},"book-1000","XMR/USD"]
1618678160.2425458: [496,{"a":[["2192.03000","0.00000000","1618678160.214435"]],"c":"1967003488"},"book-1000","ETH/CHF"]
1618678160.254566: [992,{"b":[["353.45000000","0.00000000","1618678160.227250"]],"c":"3847064542"},"book-1000","XMR/USD"]
1618678160.2719228: [496,{"b":[["2183.45000","0.00000000","1618678160.239470"]],"c":"153392129"},"book-1000","ETH/CHF"]
1618678160.276835: [1360,{"b":[["0.000022450","785.21959910","1618678160.247864"]],"c":"2597060985"},"book-1000","ADA/XBT"]
1618678160.281007: [1664,{"b":[["13.186200","415.00000000","1618678160.251774"]],"c":"3002100404"},"book-1000","WAVES/EUR"]
1618678160.282339: [992,{"b":[["353.50000000","32.24000000","1618678160.252221"]],"c":"3565535896"},"book-1000","XMR/USD"]
1618678160.2842839: [3648,{"a":[["0.00758800","0.00000000","1618678160.253099"]],"c":"66680426"},"book-1000","KSM/XBT"]
1618678160.285177: [496,{"b":[["2183.47000","0.00000000","1618678160.255121"]],"c":"282925973"},"book-1000","ETH/CHF"]
1618678160.285921: [496,{"b":[["2183.49000","3.00000000","1618678160.255214"]],"c":"381520519"},"book-1000","ETH/CHF"]
1618678160.2876759: [1920,{"b":[["0.043030","0.00000000","1618678160.260249"]],"c":"3885463520"},"book-1000","SC/EUR"]
1618678160.2908878: [1920,{"b":[["0.042890","30645.54721753","1618678160.262169"]],"c":"1923626211"},"book-1000","SC/EUR"]
1618678160.296302: [1360,{"a":[["0.000022900","0.00000000","1618678160.268896"]],"c":"494399451"},"book-1000","ADA/XBT"]
1618678160.3000581: [1840,{"b":[["9.561620","0.00000000","1618678160.271273"]],"c":"3943361354"},"book-1000","OMG/USD"]
1618678160.309215: [1920,{"b":[["0.043120","20520.06634284","1618678160.282129"]],"c":"800789278"},"book-1000","SC/EUR"]
1618678160.318557: [1840,{"a":[["9.588515","0.00000000","1618678160.291191"]],"c":"452002248"},"book-1000","OMG/USD"]
1618678160.325015: [1664,{"a":[["13.264900","0.00000000","1618678160.296992"]],"c":"464389021"},"book-1000","WAVES/EUR"]
1618678160.329186: [1664,{"a":[["13.275700","2065.21000000","1618678160.300958"]],"c":"464389021"},"book-1000","WAVES/EUR"]
1618678160.331064: [1664,{"b":[["13.209200","0.00000000","1618678160.302984"]],"c":"1412471728"},"book-1000","WAVES/EUR"]
1618678160.332567: [3648,{"b":[["0.00753700","0.00000000","1618678160.304121"]],"c":"66680426"},"book-1000","KSM/XBT"]
1618678160.3334699: [1664,{"a":[["13.265100","0.00000000","1618678160.304577"]],"c":"1948175199"},"book-1000","WAVES/EUR"]
1618678160.3346581: [1664,{"a":[["13.267500","0.00000000","1618678160.305722"]],"c":"585570434"},"book-1000","WAVES/EUR"]
1618678160.335907: {"event":"heartbeat"}
1618678160.3359191: [1664,{"b":[["13.218600","1052.75000000","1618678160.307959"]],"c":"3697643977"},"book-1000","WAVES/EUR"]
1618678160.337196: [1664,{"a":[["13.276900","840.81000000","1618678160.311526"]],"c":"3697643977"},"book-1000","WAVES/EUR"]
1618678160.339226: [1360,{"a":[["0.000022910","11028.14468856","1618678160.312166"]],"c":"4287785323"},"book-1000","ADA/XBT"]
1618678160.342247: [1840,{"b":[["9.561621","0.00000000","1618678160.314186"]],"c":"452002248"},"book-1000","OMG/USD"]
1618678160.346567: [1360,{"a":[["0.000022940","18151.97612581","1618678160.319105"]],"c":"2407559149"},"book-1000","ADA/XBT"]
1618678160.349617: [496,{"b":[["2183.48000","0.00000000","1618678160.319922"]],"c":"1469214498"},"book-1000","ETH/CHF"]
1618678160.350451: [1360,{"a":[["0.000022960","50600.49979644","1618678160.320279"]],"c":"1176272071"},"book-1000","ADA/XBT"]
1618678160.353461: [1920,{"b":[["0.043010","5802.95592353","1618678160.325336"]],"c":"1395643524"},"book-1000","SC/EUR"]
1618678160.355699: [1840,{"b":[["9.555934","160.80493105","1618678160.327204"]],"c":"452002248"},"book-1000","OMG/USD"]
1618678160.3587651: [1920,{"a":[["0.043270","0.00000000","1618678160.331269"]],"c":"2678896645"},"book-1000","SC/EUR"]
1618678160.361242: [496,{"b":[["2183.50000","1.51268802","1618678160.332368"]],"c":"3527343782"},"book-1000","ETH/CHF"]
1618678160.362083: [1920,{"b":[["0.043020","39600.00000000","1618678160.334006"]],"c":"1152811466"},"book-1000","SC/EUR"]
1618678160.3645701: [1664,{"b":[["13.186200","0.00000000","1618678160.335052"]],"c":"3697643977"},"book-1000","WAVES/EUR"]
1618678160.3686788: [3648,{"a":[["0.00760500","9.00000000","1618678160.339569"]],"c":"828343052"},"book-1000","KSM/XBT"]
1618678160.3748438: [1664,{"b":[["13.220500","500.00000000","1618678160.347564"]],"c":"923651353"},"book-1000","WAVES/EUR"]
1618678160.3866189: [1840,{"a":[["9.609936","0.00000000","1618678160.359373"]],"c":"342270803"},"book-1000","OMG/USD"]
1618678160.38976: [1664,{"b":[["13.186300","99.67826605","1618678160.361268"]],"c":"923651353"},"book-1000","WAVES/EUR"]
1618678160.3918211: [1920,{"a":[["0.043190","0.00000000","1618678160.364245"]],"c":"1245550616"},"book-1000","SC/EUR"]
1618678160.401093: [1840,{"a":[["9.614212","674.13567699","1618678160.371687"]],"c":"3949842671"},"book-1000","OMG/USD"]
1618678160.402852: [1840,{"b":[["9.581280","151.00000000","1618678160.371793"]],"c":"3062095268"},"book-1000","OMG/USD"]
1618678160.404371: [5104,{"a":[["0.000028130","38134.99513403","1618678160.374715"]],"c":"1489576729"},"book-1000","OCEAN/XBT"]
1618678160.40528: [1664,{"b":[["13.186100","0.00000000","1618678160.374843"]],"c":"923651353"},"book-1000","WAVES/EUR"]
1618678160.4065988: [1664,{"a":[["13.266800","0.00000000","1618678160.374920"]],"c":"1528682479"},"book-1000","WAVES/EUR"]
1618678160.4080799: [1360,{"a":[["0.000022930","4014.28189599","1618678160.380084"]],"c":"2719179944"},"book-1000","ADA/XBT"]
1618678160.414808: [1360,{"a":[["0.000022940","17049.67484215","1618678160.386916"]],"c":"2959371605"},"book-1000","ADA/XBT"]
1618678160.424163: [1664,{"b":[["13.217200","0.00000000","1618678160.395977"]],"c":"3544642371"},"book-1000","WAVES/EUR"]
1618678160.4330912: [464,{"a":[["56733.90000","0.00400000","1618678160.404882"]],"c":"2203918057"},"book-1000","XBT/CHF"]
1618678160.4353468: [1920,{"a":[["0.043450","905325.33415860","1618678160.404989"]],"c":"65426068"},"book-1000","SC/EUR"]
1618678160.438213: [1664,{"b":[["13.201300","415.00000000","1618678160.406181"]],"c":"1592929309"},"book-1000","WAVES/EUR"]
1618678160.4397151: [1664,{"a":[["13.275600","119.15886375","1618678160.409833"]],"c":"3744198020"},"book-1000","WAVES/EUR"]
1618678160.447521: [992,{"b":[["353.42000000","0.00000000","1618678160.419712"]],"c":"2263438136"},"book-1000","XMR/USD"]
1618678160.452319: [1840,{"b":[["9.565188","0.00000000","1618678160.425674"]],"c":"3062095268"},"book-1000","OMG/USD"]
1618678160.45759: [1840,{"b":[["9.569839","0.00000000","1618678160.430161"]],"c":"371674616"},"book-1000","OMG/USD"]
1618678160.459223: [3648,{"b":[["0.00753900","4.81674488","1618678160.431798"]],"c":"1679333544"},"book-1000","KSM/XBT"]
1618678160.460487: [1840,{"a":[["9.619274","107.96787546","1618678160.433850"]],"c":"3781890199"},"book-1000","OMG/USD"]
1618678160.4652212: [1360,{"a":[["0.000022920","5021.04049996","1618678160.436094"]],"c":"2857666961"},"book-1000","ADA/XBT"]
1618678160.47337: [1840,{"b":[["9.576517","407.93320200","1618678160.445784"]],"c":"1553343850"},"book-1000","OMG/USD"]
1618678160.476631: [1840,{"a":[["9.603089","157.04951900","1618678160.448723"]],"c":"3708179332"},"book-1000","OMG/USD"]
1618678160.486165: [992,{"b":[["353.51000000","6.86027965","1618678160.459913"]],"c":"2635808703"},"book-1000","XMR/USD"]
1618678160.489279: [1920,{"a":[["0.043170","0.00000000","1618678160.462415"]],"c":"3617334547"},"book-1000","SC/EUR"]
1618678160.492247: [1360,{"a":[["0.000022960","51719.72884128","1618678160.465769"]],"c":"1281830728"},"book-1000","ADA/XBT"]
1618678160.497955: [1920,{"b":[["0.043120","0.00000000","1618678160.470053"]],"c":"4123125286"},"book-1000","SC/EUR"]
1618678160.5043468: [1920,{"b":[["0.043060","35200.00000000","1618678160.476680"]],"c":"3831144188"},"book-1000","SC/EUR"]
1618678160.515532: [1360,{"b":[["0.000022880","21759.64649894","1618678160.488354"]],"c":"992274818"},"book-1000","ADA/XBT"]
1618678160.529114: [496,{"a":[["2198.69000","1.15978265","1618678160.501661"]],"c":"352485834"},"book-1000","ETH/CHF"]
1618678160.530754: [496,{"a":[["2192.90000","0.00000000","1618678160.503746"]],"c":"3281979017"},"book-1000","ETH/CHF"]
1618678160.532081: [1920,{"a":[["0.043270","42461.83886926","1618678160.504515"]],"c":"1114498458"},"book-1000","SC/EUR"]
1618678160.534857: [464,{"b":[["56023.80000","0.00000000","1618678160.504630"]],"c":"2906521608"},"book-1000","XBT/CHF"]
1618678160.542888: [992,{"a":[["354.53000000","0.00000000","1618678160.515361"]],"c":"650199172"},"book-1000","XMR/USD"]
1618678160.5456908: [1840,{"b":[["9.567579","108.54501182","1618678160.517863"]],"c":"3708179332"},"book-1000","OMG/USD"]
1618678160.548088: [992,{"b":[["353.52000000","22.72500000","1618678160.521503"]],"c":"3774583572"},"book-1000","XMR/USD"]
1618678160.552355: [1920,{"a":[["0.043130","0.00000000","1618678160.525675"]],"c":"4242152934"},"book-1000","SC/EUR"]
1618678160.5591922: [1920,{"b":[["0.042960","140284.00000000","1618678160.530769"]],"c":"3280780901"},"book-1000","SC/EUR"]
1618678160.562517: [1664,{"b":[["13.226200","102.00000000","1618678160.534603"]],"c":"2022114122"},"book-1000","WAVES/EUR"]
1618678160.565112: [992,{"b":[["353.55000000","1.40000000","1618678160.537690"]],"c":"3570250422"},"book-1000","XMR/USD"]
1618678160.567262: [992,{"b":[["353.50000000","30.84000000","1618678160.539197"]],"c":"1961874865"},"book-1000","XMR/USD"]
1618678160.569741: [992,{"a":[["354.48000000","6.86050247","1618678160.543535"]],"c":"4085341517"},"book-1000","XMR/USD"]
1618678160.579702: [1920,{"a":[["0.044360","0.00000000","1618678160.551675"]],"c":"3280780901"},"book-1000","SC/EUR"]
1618678160.582774: [1920,{"b":[["0.043020","31100.00000000","1618678160.554535"]],"c":"412518314"},"book-1000","SC/EUR"]
1618678160.585508: [1920,{"a":[["0.043200","0.00000000","1618678160.555183"]],"c":"3316308789"},"book-1000","SC/EUR"]
1618678160.587657: [1840,{"a":[["9.603089","0.00000000","1618678160.555235"]],"c":"1553343850"},"book-1000","OMG/USD"]
1618678160.5885062: [1840,{"a":[["9.611835","154.59965100","1618678160.556944"]],"c":"954875387"},"book-1000","OMG/USD"]
1618678160.5893881: [1920,{"b":[["0.042780","0.00000000","1618678160.557126"]],"c":"3316308789"},"book-1000","SC/EUR"]
1618678160.591254: [1840,{"b":[["9.581280","200.80000000","1618678160.557243"]],"c":"3775913423"},"book-1000","OMG/USD"]
1618678160.591943: [1920,{"b":[["0.043030","8500.00000000","1618678160.558192"]],"c":"676944007"},"book-1000","SC/EUR"]
1618678160.5939279: [1920,{"b":[["0.042860","756115.40000000","1618678160.559140"]],"c":"676944007"},"book-1000","SC/EUR"]
1618678160.595762: [992,{"a":[["354.49000000","0.00000000","1618678160.560281"]],"c":"3481662407"},"book-1000","XMR/USD"]
1618678160.597207: [1920,{"a":[["0.043270","1095000.93886926","1618678160.561996"]],"c":"2091269414"},"book-1000","SC/EUR"]
1618678160.599036: [1920,{"a":[["0.043140","0.00000000","1618678160.566284"]],"c":"1753680367"},"book-1000","SC/EUR"]
1618678160.601074: [1920,{"a":[["0.043180","8500.00000000","1618678160.572038"]],"c":"982634077"},"book-1000","SC/EUR"]
1618678160.603051: [1664,{"b":[["13.220400","0.00000000","1618678160.575739"]],"c":"1352200067"},"book-1000","WAVES/EUR"]
1618678160.609843: [1360,{"a":[["0.000022930","3511.64896627","1618678160.582634"]],"c":"3030942961"},"book-1000","ADA/XBT"]
1618678160.613028: [1664,{"b":[["13.209600","0.00000000","1618678160.585825"]],"c":"2575182339"},"book-1000","WAVES/EUR"]
1618678160.614113: [1920,{"a":[["0.043120","114893.60898433","1618678160.587724"]],"c":"3675410237"},"book-1000","SC/EUR"]
1618678160.616461: [1664,{"a":[["13.266000","66.13872119","1618678160.588340"]],"c":"1565761432"},"book-1000","WAVES/EUR"]
1618678160.618586: [1920,{"a":[["0.043270","1052539.10000000","1618678160.592125"]],"c":"271963280"},"book-1000","SC/EUR"]
1618678160.620777: [5104,{"b":[["0.000027370","0.00000000","1618678160.593844"]],"c":"1489576729"},"book-1000","OCEAN/XBT"]
1618678160.621494: [1920,{"a":[["0.044380","328342.60591655","1618678160.594403"]],"c":"271963280"},"book-1000","SC/EUR"]
1618678160.625055: [1920,{"a":[["0.043450","0.00000000","1618678160.598075"]],"c":"545042140"},"book-1000","SC/EUR"]
1618678160.6273122: [1920,{"b":[["0.042790","0.00000000","1618678160.600341"]],"c":"545042140"},"book-1000","SC/EUR"]
1618678160.631435: [464,{"b":[["56046.60000","0.01700000","1618678160.603283"]],"c":"2642791186"},"book-1000","XBT/CHF"]
1618678160.6329129: [1920,{"a":[["0.043180","0.00000000","1618678160.603398"]],"c":"4011626022"},"book-1000","SC/EUR"]
1618678160.6351218: [1920,{"a":[["0.043210","8500.00000000","1618678160.603568"]],"c":"1715173119"},"book-1000","SC/EUR"]
1618678160.6372511: [1664,{"b":[["13.201400","99.56425743","1618678160.604585"]],"c":"2380149556"},"book-1000","WAVES/EUR"]
1618678160.638358: [1664,{"b":[["13.186300","0.00000000","1618678160.606593"]],"c":"2380149556"},"book-1000","WAVES/EUR"]
1618678160.639252: [992,{"a":[["354.95000000","0.00000000","1618678160.607174"]],"c":"2527137113"},"book-1000","XMR/USD"]
1618678160.640693: [992,{"b":[["353.50000000","8.11500000","1618678160.609200"]],"c":"479737346"},"book-1000","XMR/USD"]
1618678160.642076: [496,{"b":[["2152.67000","0.00000000","1618678160.610943"]],"c":"3281979017"},"book-1000","ETH/CHF"]
1618678160.6433432: [464,{"a":[["56734.10000","0.00000000","1618678160.617534"]],"c":"2642791186"},"book-1000","XBT/CHF"]
1618678160.649945: [496,{"b":[["2183.51000","3.00000000","1618678160.622852"]],"c":"3450425341"},"book-1000","ETH/CHF"]
1618678160.653196: [1920,{"a":[["0.043210","0.00000000","1618678160.625839"]],"c":"4011626022"},"book-1000","SC/EUR"]
1618678160.65646: [1664,{"b":[["13.224900","151.23039824","1618678160.626677"]],"c":"3979092701"},"book-1000","WAVES/EUR"]
1618678160.657825: [1920,{"a":[["0.043160","8500.00000000","1618678160.627502"]],"c":"1497917526"},"book-1000","SC/EUR"]
1618678160.660135: [1920,{"a":[["0.043260","145099.00000000","1618678160.631291"]],"c":"3072980515"},"book-1000","SC/EUR"]
1618678160.662267: [1664,{"a":[["13.250100","0.00000000","1618678160.631842"]],"c":"3828296822"},"book-1000","WAVES/EUR"]
1618678160.663369: [1920,{"a":[["0.043110","42461.83886926","1618678160.633428"]],"c":"827033493"},"book-1000","SC/EUR"]
1618678160.665218: [3648,{"a":[["0.00758200","5.15000000","1618678160.634878"]],"c":"1176579345"},"book-1000","KSM/XBT"]
1618678160.667136: [992,{"a":[["354.90000000","0.00000000","1618678160.640474"]],"c":"1250005636"},"book-1000","XMR/USD"]
1618678160.673341: [496,{"b":[["2153.99000","14.29367954","1618678160.645209"]],"c":"3450425341"},"book-1000","ETH/CHF"]
1618678160.677021: [1840,{"b":[["9.565565","0.00000000","1618678160.649604"]],"c":"3775913423"},"book-1000","OMG/USD"]
1618678160.6832: [464,{"a":[["56250.60000","0.00000000","1618678160.655088"]],"c":"2448296518"},"book-1000","XBT/CHF"]
1618678160.6857028: [496,{"b":[["2183.50000","0.00000000","1618678160.657713"]],"c":"722504762"},"book-1000","ETH/CHF"]
1618678160.686729: [496,{"b":[["2183.52000","1.51267417","1618678160.657810"]],"c":"3585847921"},"book-1000","ETH/CHF"]
1618678160.6877382: [1920,{"a":[["0.043260","1050424.33415860","1618678160.657875"]],"c":"1879854599"},"book-1000","SC/EUR"]
1618678160.693824: [1920,{"b":[["0.042870","577288.45906328","1618678160.666518"]],"c":"1879854599"},"book-1000","SC/EUR"]
1618678160.699626: [1840,{"a":[["9.614212","0.00000000","1618678160.670634"]],"c":"606310514"},"book-1000","OMG/USD"]
1618678160.70104: [992,{"b":[["353.53000000","7.57500000","1618678160.671270"]],"c":"2471097432"},"book-1000","XMR/USD"]
1618678160.703321: [1920,{"a":[["0.043160","0.00000000","1618678160.672264"]],"c":"1306286133"},"book-1000","SC/EUR"]
1618678160.7059588: [1920,{"a":[["0.043150","8500.00000000","1618678160.672722"]],"c":"426154432"},"book-1000","SC/EUR"]
1618678160.708315: [1840,{"a":[["9.596670","0.00000000","1618678160.673300"]],"c":"163950425"},"book-1000","OMG/USD"]
1618678160.709147: [1840,{"b":[["9.575011","0.00000000","1618678160.676097"]],"c":"3039679143"},"book-1000","OMG/USD"]
1618678160.709959: [1840,{"b":[["9.572438","0.00000000","1618678160.676885"]],"c":"3320974870"},"book-1000","OMG/USD"]
1618678160.71804: [1840,{"b":[["9.581281","114.80719540","1618678160.690038"]],"c":"3549565768"},"book-1000","OMG/USD"]
1618678160.719604: [1840,{"a":[["9.604803","136.90975447","1618678160.690270"]],"c":"1107491385"},"book-1000","OMG/USD"]
1618678160.728105: [1840,{"b":[["9.581281","314.80719540","1618678160.699670"]],"c":"642979670"},"book-1000","OMG/USD"]
1618678160.729681: [1920,{"a":[["0.043260","145099.00000000","1618678160.699713"]],"c":"1566490118"},"book-1000","SC/EUR"]
1618678160.740355: [496,{"b":[["2183.51000","0.00000000","1618678160.711680"]],"c":"626561859"},"book-1000","ETH/CHF"]
1618678160.741725: [992,{"a":[["355.11000000","0.00000000","1618678160.712603"]],"c":"3817395668"},"book-1000","XMR/USD"]
1618678160.744132: [1840,{"b":[["9.555934","0.00000000","1618678160.712888"]],"c":"642979670"},"book-1000","OMG/USD"]
1618678160.74543: [1840,{"b":[["9.569839","88.29805530","1618678160.713807"]],"c":"1480832220"},"book-1000","OMG/USD"]
1618678160.7464588: [992,{"a":[["355.11000000","1.57938328","1618678160.714660"]],"c":"3194586338"},"book-1000","XMR/USD"]
1618678160.748217: [1664,{"b":[["13.201000","0.00000000","1618678160.714866"]],"c":"3828296822"},"book-1000","WAVES/EUR"]
1618678160.74931: [1664,{"a":[["13.250000","0.00000000","1618678160.715358"]],"c":"3399166919"},"book-1000","WAVES/EUR"]
1618678160.750368: [1664,{"a":[["13.256700","600.00000000","1618678160.715433"]],"c":"2497443556"},"book-1000","WAVES/EUR"]
1618678160.751571: [992,{"a":[["360.84000000","0.00000000","1618678160.718444"]],"c":"3194586338"},"book-1000","XMR/USD"]
1618678160.758785: [992,{"b":[["353.16000000","0.00000000","1618678160.723600"]],"c":"3194586338"},"book-1000","XMR/USD"]
1618678160.7611089: [1920,{"a":[["0.043220","10721.04662049","1618678160.723912"]],"c":"1461658585"},"book-1000","SC/EUR"]
1618678160.763714: [1664,{"b":[["13.226200","134.79000000","1618678160.728210"]],"c":"4041905325"},"book-1000","WAVES/EUR"]
1618678160.764766: [992,{"a":[["355.63000000","22.72500000","1618678160.730364"]],"c":"3449218581"},"book-1000","XMR/USD"]
1618678160.766589: [992,{"b":[["353.54000000","22.72500000","1618678160.733756"]],"c":"333482290"},"book-1000","XMR/USD"]
1618678160.771335: [1920,{"a":[["0.043250","905325.33415860","1618678160.742464"]],"c":"2690987213"},"book-1000","SC/EUR"]
1618678160.783117: [496,{"b":[["2183.53000","3.00000000","1618678160.753848"]],"c":"2075786867"},"book-1000","ETH/CHF"]
1618678160.7938309: [992,{"a":[["360.82000000","23.79633523","1618678160.761073"]],"c":"333482290"},"book-1000","XMR/USD"]
1618678160.7966871: [1840,{"b":[["9.576517","207.93320200","1618678160.761261"]],"c":"3687138752"},"book-1000","OMG/USD"]
1618678160.801205: [1664,{"b":[["13.182100","0.00000000","1618678160.772580"]],"c":"4041905325"},"book-1000","WAVES/EUR"]
1618678160.802912: [1840,{"a":[["9.624951","674.13567699","1618678160.772815"]],"c":"2088959495"},"book-1000","OMG/USD"]
1618678160.8055239: [1664,{"a":[["13.256700","100.00000000","1618678160.775223"]],"c":"2930395534"},"book-1000","WAVES/EUR"]
1618678160.809769: [1840,{"a":[["9.604804","0.00000000","1618678160.782645"]],"c":"3745817776"},"book-1000","OMG/USD"]
1618678160.813: [1664,{"a":[["13.266800","500.00000000","1618678160.783530"]],"c":"4146102148"},"book-1000","WAVES/EUR"]
1618678160.8146188: [992,{"b":[["353.43000000","152.48270000","1618678160.783600"]],"c":"711427333"},"book-1000","XMR/USD"]
1618678160.823125: [5104,{"b":[["0.000027720","917.26111711","1618678160.794856"]],"c":"3619524710"},"book-1000","OCEAN/XBT"]
1618678160.834832: [1664,{"b":[["13.173300","0.00000000","1618678160.807384"]],"c":"4146102148"},"book-1000","WAVES/EUR"]
1618678160.841376: [3648,{"a":[["0.00758200","0.00000000","1618678160.813505"]],"c":"1679333544"},"book-1000","KSM/XBT"]
1618678160.84394: [3648,{"b":[["0.00753900","0.11674488","1618678160.816063"]],"c":"1061661274"},"book-1000","KSM/XBT"]
1618678160.848088: [1840,{"b":[["9.519364","0.00000000","1618678160.820695"]],"c":"3745817776"},"book-1000","OMG/USD"]
1618678160.851327: [464,{"a":[["56733.80000","3.56787561","1618678160.824305"]],"c":"2448296518"},"book-1000","XBT/CHF"]
1618678160.8547032: [1664,{"a":[["13.266000","0.00000000","1618678160.826086"]],"c":"3851837632"},"book-1000","WAVES/EUR"]
1618678160.856101: [1664,{"a":[["13.256700","600.00000000","1618678160.827938"]],"c":"1202671983"},"book-1000","WAVES/EUR"]
1618678160.858185: [1840,{"a":[["9.624856","521.11453000","1618678160.832006"]],"c":"3524892579"},"book-1000","OMG/USD"]
1618678160.861377: [496,{"b":[["2183.49000","0.00000000","1618678160.833841"]],"c":"662561816"},"book-1000","ETH/CHF"]
1618678160.866818: [1840,{"a":[["9.630461","0.00000000","1618678160.839762"]],"c":"1486782907"},"book-1000","OMG/USD"]
1618678160.875369: [464,{"b":[["56060.20000","0.03938000","1618678160.848405"]],"c":"3983854921"},"book-1000","XBT/CHF"]
1618678160.877246: [992,{"b":[["353.52000000","0.00000000","1618678160.849036"]],"c":"544472747"},"book-1000","XMR/USD"]
1618678160.882369: [5104,{"b":[["0.000027340","81264.71334805","1618678160.853808"]],"c":"3619524710"},"book-1000","OCEAN/XBT"]
1618678160.898449: [1840,{"a":[["9.630460","0.00000000","1618678160.868835"]],"c":"1106602702"},"book-1000","OMG/USD"]
1618678160.9000251: [1840,{"a":[["9.619273","194.10704088","1618678160.869088"]],"c":"3602706106"},"book-1000","OMG/USD"]
1618678160.925514: [3648,{"a":[["0.00758000","0.00000000","1618678160.898957"]],"c":"885267631"},"book-1000","KSM/XBT"]
1618678160.9299352: [1840,{"a":[["9.667953","465.00000000","1618678160.901726"]],"c":"3602706106"},"book-1000","OMG/USD"]
1618678160.931322: [1840,{"b":[["9.555932","0.00000000","1618678160.902352"]],"c":"3602706106"},"book-1000","OMG/USD"]
1618678160.932361: [1840,{"b":[["9.572440","280.00000000","1618678160.902519"]],"c":"672084329"},"book-1000","OMG/USD"]
1618678160.933345: [3648,{"b":[["0.00756000","0.21000000","1618678160.904338"]],"c":"3704792618"},"book-1000","KSM/XBT"]
1618678160.934484: [3648,{"b":[["0.00755900","0.16890103","1618678160.904388"]],"c":"1204132385"},"book-1000","KSM/XBT"]
1618678160.935318: [1840,{"b":[["9.578337","4235.21000000","1618678160.905789"]],"c":"704989925"},"book-1000","OMG/USD"]
1618678160.936172: [1840,{"a":[["9.607676","0.00000000","1618678160.906277"]],"c":"2979746828"},"book-1000","OMG/USD"]
1618678160.942134: [1840,{"b":[["9.569323","0.00000000","1618678160.908127"]],"c":"2979746828"},"book-1000","OMG/USD"]
1618678160.9435189: [1840,{"a":[["9.616726","3890.37000000","1618678160.909982"]],"c":"3610121133"},"book-1000","OMG/USD"]
1618678160.946581: [496,{"b":[["2183.54000","1.51266034","1618678160.916894"]],"c":"3371421115"},"book-1000","ETH/CHF"]
1618678160.947711: [496,{"b":[["2183.52000","0.00000000","1618678160.917820"]],"c":"3841718543"},"book-1000","ETH/CHF"]
1618678160.953374: [1920,{"a":[["0.043260","0.00000000","1618678160.924384"]],"c":"4110703499"},"book-1000","SC/EUR"]
1618678160.9706721: [1360,{"a":[["0.000022910","8839.14875728","1618678160.942956"]],"c":"1271974095"},"book-1000","ADA/XBT"]
1618678160.99157: [1840,{"a":[["9.610357","55.40652505","1618678160.962292"]],"c":"1913958632"},"book-1000","OMG/USD"]
1618678160.995301: [1920,{"a":[["0.043250","0.00000000","1618678160.968540"]],"c":"728670103"},"book-1000","SC/EUR"]
1618678161.00043: [1840,{"b":[["9.569839","248.86934138","1618678160.969310"]],"c":"3223203137"},"book-1000","OMG/USD"]
1618678161.001836: [992,{"a":[["355.11000000","6.15350216","1618678160.970238"]],"c":"1120603555"},"book-1000","XMR/USD"]
1618678161.003922: [992,{"a":[["355.11000000","4.57411888","1618678160.970356"]],"c":"4243315838"},"book-1000","XMR/USD"]
1618678161.0058749: [1840,{"b":[["9.569839","160.57128608","1618678160.970647"]],"c":"3680573228"},"book-1000","OMG/USD"]
1618678161.006898: [1840,{"b":[["9.576517","157.93320200","1618678160.978642"]],"c":"4126860096"},"book-1000","OMG/USD"]
1618678161.007978: [992,{"b":[["353.44000000","0.00000000","1618678160.980927"]],"c":"2341280811"},"book-1000","XMR/USD"]
1618678161.0099359: [992,{"b":[["353.44000000","2.47700000","1618678160.982390"]],"c":"1994469296"},"book-1000","XMR/USD"]
1618678161.0116138: [1840,{"b":[["9.555933","0.00000000","1618678160.982593"]],"c":"4126860096"},"book-1000","OMG/USD"]
1618678161.0124469: [1664,{"b":[["13.182700","0.00000000","1618678160.982962"]],"c":"1202671983"},"book-1000","WAVES/EUR"]
1618678161.0137112: [1360,{"a":[["0.000022920","7208.65298952","1618678160.986421"]],"c":"534628181"},"book-1000","ADA/XBT"]
1618678161.024043: [1920,{"a":[["0.043200","142145.90114770","1618678160.995484"]],"c":"3104626497"},"book-1000","SC/EUR"]
1618678161.036176: [1664,{"b":[["13.224900","0.00000000","1618678161.005432"]],"c":"660422790"},"book-1000","WAVES/EUR"]
1618678161.03805: [1920,{"a":[["0.043240","906825.33415860","1618678161.006942"]],"c":"4010425318"},"book-1000","SC/EUR"]
1618678161.048299: [1664,{"a":[["13.256700","100.00000000","1618678161.021212"]],"c":"2237952297"},"book-1000","WAVES/EUR"]
1618678161.050185: [1664,{"a":[["13.266800","0.00000000","1618678161.021263"]],"c":"887676838"},"book-1000","WAVES/EUR"]
1618678161.054975: [1664,{"a":[["13.266900","0.00000000","1618678161.027388"]],"c":"549226554"},"book-1000","WAVES/EUR"]
1618678161.056731: [1664,{"b":[["13.205300","122.81940000","1618678161.027667"]],"c":"3338698600"},"book-1000","WAVES/EUR"]
1618678161.0751302: [1360,{"a":[["0.000022930","7111.81976627","1618678161.046720"]],"c":"3903234536"},"book-1000","ADA/XBT"]
1618678161.078933: [1840,{"b":[["9.519367","360.00000000","1618678161.046869"]],"c":"4126860096"},"book-1000","OMG/USD"]
1618678161.079983: [1920,{"a":[["0.043240","1500.00000000","1618678161.046913"]],"c":"3104626497"},"book-1000","SC/EUR"]
1618678161.082806: [1664,{"b":[["13.226300","151.21386933","1618678161.048783"]],"c":"143946820"},"book-1000","WAVES/EUR"]
1618678161.0839438: [992,{"b":[["352.99000000","0.00000000","1618678161.052228"]],"c":"1994469296"},"book-1000","XMR/USD"]
1618678161.085679: [992,{"b":[["353.31000000","114.21380000","1618678161.054696"]],"c":"1994469296"},"book-1000","XMR/USD"]
1618678161.087487: [1664,{"b":[["13.226300","651.21386933","1618678161.056380"]],"c":"525815691"},"book-1000","WAVES/EUR"]
1618678161.0885508: [1840,{"b":[["9.572440","0.00000000","1618678161.056570"]],"c":"1250299043"},"book-1000","OMG/USD"]
1618678161.1086888: [1664,{"b":[["13.185900","136.46134028","1618678161.081123"]],"c":"525815691"},"book-1000","WAVES/EUR"]
1618678161.11059: [1664,{"a":[["13.266700","66.13892075","1618678161.081393"]],"c":"561046155"},"book-1000","WAVES/EUR"]
1618678161.117818: [1920,{"a":[["0.043230","915649.48425860","1618678161.088865"]],"c":"3674287565"},"book-1000","SC/EUR"]
1618678161.1221719: [992,{"a":[["355.04000000","0.00000000","1618678161.095376"]],"c":"750743484"},"book-1000","XMR/USD"]
1618678161.127559: [496,{"a":[["2192.91000","0.00000000","1618678161.100231"]],"c":"1375369956"},"book-1000","ETH/CHF"]
1618678161.131048: [992,{"a":[["355.33000000","293.02850000","1618678161.102896"]],"c":"83467932"},"book-1000","XMR/USD"]
1618678161.137509: [1664,{"a":[["13.256700","0.00000000","1618678161.109969"]],"c":"1603272627"},"book-1000","WAVES/EUR"]
1618678161.143408: [1920,{"b":[["0.042890","0.00000000","1618678161.115538"]],"c":"197386163"},"book-1000","SC/EUR"]
1618678161.147033: [992,{"a":[["354.51000000","11.52000000","1618678161.117754"]],"c":"3863919629"},"book-1000","XMR/USD"]
1618678161.149122: [1920,{"b":[["0.043070","30517.47204063","1618678161.118072"]],"c":"1180730874"},"book-1000","SC/EUR"]
1618678161.151585: [5104,{"b":[["0.000027340","89766.57217672","1618678161.120820"]],"c":"3619524710"},"book-1000","OCEAN/XBT"]
1618678161.1543329: [1664,{"a":[["13.256800","0.00000000","1618678161.125146"]],"c":"2894137337"},"book-1000","WAVES/EUR"]
1618678161.155754: [992,{"b":[["352.18000000","12.24000000","1618678161.125470"]],"c":"3863919629"},"book-1000","XMR/USD"]
1618678161.1575968: [1840,{"b":[["9.486857","0.00000000","1618678161.126461"]],"c":"1250299043"},"book-1000","OMG/USD"]
1618678161.158453: [1920,{"a":[["0.043230","10324.15010000","1618678161.129328"]],"c":"611155830"},"book-1000","SC/EUR"]
1618678161.160661: [1920,{"a":[["0.043200","0.00000000","1618678161.130290"]],"c":"3054450592"},"book-1000","SC/EUR"]
1618678161.162848: [1840,{"a":[["9.616725","194.10704088","1618678161.132480"]],"c":"700482261"},"book-1000","OMG/USD"]
1618678161.163615: [1664,{"b":[["13.220500","0.00000000","1618678161.132616"]],"c":"4294667949"},"book-1000","WAVES/EUR"]
1618678161.164513: [464,{"a":[["56192.70000","0.00000000","1618678161.134477"]],"c":"1237702324"},"book-1000","XBT/CHF"]
1618678161.1656399: [496,{"a":[["2189.99000","0.00000000","1618678161.134799"]],"c":"2916194234"},"book-1000","ETH/CHF"]
1618678161.166253: [1664,{"a":[["13.263400","0.00000000","1618678161.134923"]],"c":"3781071396"},"book-1000","WAVES/EUR"]
1618678161.167305: [1840,{"a":[["9.619273","0.00000000","1618678161.137261"]],"c":"772786804"},"book-1000","OMG/USD"]
1618678161.168019: [1920,{"b":[["0.042880","0.00000000","1618678161.137324"]],"c":"3668537694"},"book-1000","SC/EUR"]
1618678161.169842: [1664,{"a":[["13.264500","0.00000000","1618678161.139290"]],"c":"599063134"},"book-1000","WAVES/EUR"]
1618678161.171896: [1664,{"b":[["13.213200","30.72000000","1618678161.144213"]],"c":"297779528"},"book-1000","WAVES/EUR"]
1618678161.175317: [3648,{"a":[["0.00760500","0.00000000","1618678161.147073"]],"c":"1783046716"},"book-1000","KSM/XBT"]
1618678161.185367: [1920,{"b":[["0.043030","0.00000000","1618678161.157815"]],"c":"2608004819"},"book-1000","SC/EUR"]
1618678161.194991: [1920,{"b":[["0.041190","0.00000000","1618678161.166651"]],"c":"2608004819"},"book-1000","SC/EUR"]
1618678161.198496: [1920,{"a":[["0.043220","916046.38077909","1618678161.168518"]],"c":"610230546"},"book-1000","SC/EUR"]
1618678161.201389: [1360,{"b":[["0.000022860","30090.07358269","1618678161.173189"]],"c":"3084342777"},"book-1000","ADA/XBT"]
1618678161.2039292: [5104,{"a":[["0.000027830","2308.64275989","1618678161.173259"]],"c":"3391220374"},"book-1000","OCEAN/XBT"]
1618678161.210305: [1920,{"b":[["0.042660","10527.10700630","1618678161.180506"]],"c":"610230546"},"book-1000","SC/EUR"]
1618678161.214665: [1920,{"b":[["0.043040","8500.00000000","1618678161.187036"]],"c":"2633900042"},"book-1000","SC/EUR"]
1618678161.217644: [992,{"b":[["353.29000000","0.00000000","1618678161.189900"]],"c":"3863919629"},"book-1000","XMR/USD"]
1618678161.2195442: [464,{"a":[["56192.60000","0.00000000","1618678161.192506"]],"c":"1548012702"},"book-1000","XBT/CHF"]
1618678161.220891: [464,{"a":[["56277.50000","0.15000000","1618678161.192665"]],"c":"1409209246"},"book-1000","XBT/CHF"]
1618678161.228692: [1840,{"b":[["9.528693","271.72073905","1618678161.199781"]],"c":"772786804"},"book-1000","OMG/USD"]
1618678161.2334652: [1664,{"b":[["13.185900","132.27784150","1618678161.205978"]],"c":"297779528"},"book-1000","WAVES/EUR"]
1618678161.2355049: [1920,{"a":[["0.043220","10721.04662049","1618678161.207801"]],"c":"13658384"},"book-1000","SC/EUR"]
1618678161.23861: [992,{"b":[["353.55000000","6.40000000","1618678161.211664"]],"c":"2484907310"},"book-1000","XMR/USD"]
1618678161.2405481: [992,{"a":[["355.26000000","5.00000000","1618678161.211736"]],"c":"2892376198"},"book-1000","XMR/USD"]
1618678161.242176: [496,{"a":[["2198.70000","0.00000000","1618678161.211800"]],"c":"4147377491"},"book-1000","ETH/CHF"]
1618678161.245445: [3648,{"a":[["0.00758500","14.00000000","1618678161.217167"]],"c":"2168419558"},"book-1000","KSM/XBT"]
1618678161.254561: [1920,{"b":[["0.041350","65293.98451871","1618678161.222328"]],"c":"13658384"},"book-1000","SC/EUR"]
1618678161.258304: [464,{"a":[["56277.40000","0.04267101","1618678161.229372"]],"c":"309889825"},"book-1000","XBT/CHF"]
1618678161.259933: [464,{"a":[["56277.60000","0.00000000","1618678161.230854"]],"c":"3728822065"},"book-1000","XBT/CHF"]
1618678161.264579: [992,{"a":[["355.11000000","0.00000000","1618678161.232698"]],"c":"422531403"},"book-1000","XMR/USD"]
1618678161.266464: [496,{"b":[["2183.55000","3.00000000","1618678161.232853"]],"c":"3745719598"},"book-1000","ETH/CHF"]
1618678161.267183: [992,{"a":[["355.05000000","4.31695195","1618678161.234207"]],"c":"185684251"},"book-1000","XMR/USD"]
1618678161.275491: [1920,{"a":[["0.043210","905325.33415860","1618678161.246122"]],"c":"2880928587"},"book-1000","SC/EUR"]
1618678161.279042: [464,{"a":[["56734.00000","0.00000000","1618678161.246183"]],"c":"3728822065"},"book-1000","XBT/CHF"]
1618678161.280874: [496,{"a":[["2199.36000","1.15978265","1618678161.250877"]],"c":"1169555691"},"book-1000","ETH/CHF"]
1618678161.281773: [5104,{"a":[["0.000027830","1856.00298052","1618678161.251637"]],"c":"2157296071"},"book-1000","OCEAN/XBT"]
1618678161.28619: [496,{"a":[["2198.69000","0.00000000","1618678161.258599"]],"c":"1626050629"},"book-1000","ETH/CHF"]
1618678161.291563: [992,{"b":[["353.50000000","3.11500000","1618678161.263862"]],"c":"229213923"},"book-1000","XMR/USD"]
1618678161.293259: [992,{"b":[["353.56000000","22.72500000","1618678161.263991"]],"c":"3262441415"},"book-1000","XMR/USD"]
1618678161.295074: [1920,{"b":[["0.042770","447090.43348140","1618678161.266225"]],"c":"2880928587"},"book-1000","SC/EUR"]
1618678161.305598: [496,{"b":[["2183.54000","0.00000000","1618678161.278869"]],"c":"2526175588"},"book-1000","ETH/CHF"]
1618678161.3094242: [464,{"a":[["56277.30000","0.15000000","1618678161.280637"]],"c":"2215349019"},"book-1000","XBT/CHF"]
1618678161.311679: [1360,{"b":[["0.000022850","32743.84696383","1618678161.283861"]],"c":"3625595345"},"book-1000","ADA/XBT"]
1618678161.314924: [1920,{"a":[["0.043210","0.00000000","1618678161.284328"]],"c":"13658384"},"book-1000","SC/EUR"]
1618678161.317164: [496,{"a":[["2198.68000","3.20000000","1618678161.284609"]],"c":"2038286068"},"book-1000","ETH/CHF"]
1618678161.3179278: [1840,{"a":[["9.604803","186.90975447","1618678161.284965"]],"c":"3704141853"},"book-1000","OMG/USD"]
1618678161.318909: [1360,{"b":[["0.000022890","8320.45920805","1618678161.289308"]],"c":"1406624393"},"book-1000","ADA/XBT"]
1618678161.323426: [496,{"b":[["2183.56000","1.51264650","1618678161.295055"]],"c":"2320781103"},"book-1000","ETH/CHF"]
1618678161.3243918: [1664,{"a":[["13.447800","0.00000000","1618678161.296355"]],"c":"297779528"},"book-1000","WAVES/EUR"]
1618678161.3255491: [1664,{"a":[["13.278800","753.50880000","1618678161.296782"]],"c":"3948177162"},"book-1000","WAVES/EUR"]
1618678161.327561: [496,{"b":[["2183.53000","0.00000000","1618678161.299208"]],"c":"2240631093"},"book-1000","ETH/CHF"]
1618678161.331101: [992,{"a":[["354.59000000","7.57500000","1618678161.302812"]],"c":"1579554068"},"book-1000","XMR/USD"]
1618678161.3332741: [992,{"b":[["353.55000000","5.00000000","1618678161.303872"]],"c":"2439828446"},"book-1000","XMR/USD"]
1618678161.335103: {"event":"heartbeat"}
1618678161.343041: [992,{"b":[["353.54000000","0.00000000","1618678161.314508"]],"c":"3206147840"},"book-1000","XMR/USD"]
1618678161.3461618: [992,{"a":[["357.30000000","0.00000000","1618678161.316715"]],"c":"3206147840"},"book-1000","XMR/USD"]
1618678161.348588: [464,{"a":[["56733.70000","0.51880000","1618678161.319417"]],"c":"2215349019"},"book-1000","XBT/CHF"]
1618678161.3501341: [464,{"a":[["56474.40000","0.00000000","1618678161.319564"]],"c":"2363102476"},"book-1000","XBT/CHF"]
1618678161.352332: [1664,{"a":[["13.276100","4.17098583","1618678161.324723"]],"c":"3957542103"},"book-1000","WAVES/EUR"]
1618678161.353458: [1664,{"a":[["13.275600","0.00000000","1618678161.325754"]],"c":"1640955438"},"book-1000","WAVES/EUR"]
1618678161.357719: [1664,{"a":[["13.275600","56.59742685","1618678161.330094"]],"c":"3865896659"},"book-1000","WAVES/EUR"]
1618678161.359295: [464,{"a":[["56277.50000","0.00000000","1618678161.332613"]],"c":"2481028356"},"book-1000","XBT/CHF"]
1618678161.364251: [496,{"b":[["2183.55000","0.00000000","1618678161.335124"]],"c":"2609194938"},"book-1000","ETH/CHF"]
1618678161.3652081: [1664,{"a":[["13.455100","1602.63117900","1618678161.336485"]],"c":"3865896659"},"book-1000","WAVES/EUR"]
1618678161.366688: [1664,{"a":[["13.258100","29.25957971","1618678161.339624"]],"c":"1511123709"},"book-1000","WAVES/EUR"]
1618678161.3678641: [1920,{"b":[["0.042970","20000.00000000","1618678161.340789"]],"c":"873888922"},"book-1000","SC/EUR"]
1618678161.383408: [1664,{"a":[["13.266700","0.00000000","1618678161.354643"]],"c":"1249744112"},"book-1000","WAVES/EUR"]
1618678161.385303: [992,{"a":[["355.17000000","0.00000000","1618678161.355166"]],"c":"1296805467"},"book-1000","XMR/USD"]
1618678161.387786: [992,{"b":[["353.57000000","7.57500000","1618678161.358066"]],"c":"2677333703"},"book-1000","XMR/USD"]
1618678161.3906171: [464,{"a":[["56277.20000","0.59541531","1618678161.361250"]],"c":"1255482201"},"book-1000","XBT/CHF"]
1618678161.392256: [1840,{"b":[["9.518970","0.00000000","1618678161.361987"]],"c":"3704141853"},"book-1000","OMG/USD"]
1618678161.3931258: [1664,{"a":[["13.275600","0.00000000","1618678161.363853"]],"c":"3271925294"},"book-1000","WAVES/EUR"]
1618678161.394382: [1840,{"b":[["9.576516","71.30000000","1618678161.367170"]],"c":"3640128788"},"book-1000","OMG/USD"]
1618678161.395412: [1664,{"a":[["13.283900","119.15886375","1618678161.368350"]],"c":"1472704443"},"book-1000","WAVES/EUR"]
1618678161.411828: [496,{"b":[["2183.57000","3.00000000","1618678161.384602"]],"c":"108007800"},"book-1000","ETH/CHF"]
1618678161.413687: [992,{"a":[["356.89000000","25.99000000","1618678161.385657"]],"c":"2677333703"},"book-1000","XMR/USD"]
1618678161.4160798: [1840,{"b":[["9.486859","3095.74181500","1618678161.386430"]],"c":"3640128788"},"book-1000","OMG/USD"]
1618678161.422296: [5104,{"b":[["0.000027730","594.11897000","1618678161.394686"]],"c":"2447247826"},"book-1000","OCEAN/XBT"]
1618678161.435335: [464,{"a":[["56277.10000","0.15000000","1618678161.408205"]],"c":"2500293634"},"book-1000","XBT/CHF"]
1618678161.445013: [992,{"b":[["352.04000000","0.83692448","1618678161.417811"]],"c":"2677333703"},"book-1000","XMR/USD"]
1618678161.448064: [5104,{"b":[["0.000027740","658.61897000","1618678161.418526"]],"c":"3154667600"},"book-1000","OCEAN/XBT"]
1618678161.462788: [1920,{"a":[["0.043110","0.00000000","1618678161.432333"]],"c":"3616740606"},"book-1000","SC/EUR"]
1618678161.476547: [464,{"a":[["56277.20000","0.00000000","1618678161.448925"]],"c":"3502008841"},"book-1000","XBT/CHF"]
1618678161.491627: [1920,{"a":[["0.043120","0.00000000","1618678161.461644"]],"c":"697935228"},"book-1000","SC/EUR"]
1618678161.503752: [1920,{"b":[["0.043040","0.00000000","1618678161.473617"]],"c":"3718934937"},"book-1000","SC/EUR"]
1618678161.507209: [1840,{"b":[["9.576850","155.88207800","1618678161.477032"]],"c":"2452795695"},"book-1000","OMG/USD"]
1618678161.508468: [1920,{"a":[["0.043180","42461.83886926","1618678161.477837"]],"c":"1805208923"},"book-1000","SC/EUR"]
1618678161.521875: [1840,{"a":[["9.605515","156.20713700","1618678161.484631"]],"c":"2601952850"},"book-1000","OMG/USD"]
1618678161.523432: [992,{"b":[["353.49000000","0.00000000","1618678161.486222"]],"c":"3477802244"},"book-1000","XMR/USD"]
1618678161.5257988: [1840,{"b":[["9.581281","473.58554540","1618678161.487324"]],"c":"3187974751"},"book-1000","OMG/USD"]
1618678161.526795: [464,{"a":[["56277.00000","0.04267101","1618678161.488162"]],"c":"187547296"},"book-1000","XBT/CHF"]
1618678161.528383: [464,{"a":[["56277.40000","0.00000000","1618678161.489239"]],"c":"1018270464"},"book-1000","XBT/CHF"]
1618678161.5296519: [1920,{"b":[["0.043050","8500.00000000","1618678161.489818"]],"c":"950044638"},"book-1000","SC/EUR"]
1618678161.531905: [1920,{"a":[["0.043190","8500.00000000","1618678161.489903"]],"c":"1658978312"},"book-1000","SC/EUR"]
1618678161.5340722: [1920,{"a":[["0.043150","0.00000000","1618678161.490066"]],"c":"3872040804"},"book-1000","SC/EUR"]
1618678161.536366: [464,{"a":[["56277.00000","0.63808632","1618678161.497345"]],"c":"2410459038"},"book-1000","XBT/CHF"]
1618678161.5375931: [3648,{"b":[["0.00754900","0.00000000","1618678161.497890"]],"c":"1912326625"},"book-1000","KSM/XBT"]
1618678161.565096: [1920,{"b":[["0.043050","0.00000000","1618678161.501324"]],"c":"1323169227"},"book-1000","SC/EUR"]
1618678161.568577: [3648,{"b":[["0.00755600","40.67000000","1618678161.501834"]],"c":"2590708793"},"book-1000","KSM/XBT"]
1618678161.569466: [1920,{"b":[["0.043060","43700.00000000","1618678161.503411"]],"c":"2036527893"},"book-1000","SC/EUR"]
1618678161.571989: [1840,{"a":[["9.605515","0.00000000","1618678161.514109"]],"c":"3072374050"},"book-1000","OMG/USD"]
1618678161.5728588: [496,{"a":[["2198.67000","1.15978265","1618678161.515642"]],"c":"2985705832"},"book-1000","ETH/CHF"]
1618678161.573591: [992,{"b":[["353.51000000","0.00000000","1618678161.516155"]],"c":"184577570"},"book-1000","XMR/USD"]
1618678161.575306: [496,{"a":[["2199.36000","0.00000000","1618678161.519726"]],"c":"527830816"},"book-1000","ETH/CHF"]
1618678161.576006: [1840,{"b":[["9.572587","280.00000000","1618678161.523376"]],"c":"4268567183"},"book-1000","OMG/USD"]
1618678161.5768478: [496,{"b":[["2183.56000","0.00000000","1618678161.529216"]],"c":"4109305982"},"book-1000","ETH/CHF"]
1618678161.577539: [496,{"b":[["2183.58000","1.51263263","1618678161.534447"]],"c":"693060727"},"book-1000","ETH/CHF"]
1618678161.578221: [992,{"b":[["353.53000000","0.00000000","1618678161.535005"]],"c":"4281578943"},"book-1000","XMR/USD"]
1618678161.57988: [3648,{"b":[["0.00754000","0.00000000","1618678161.535941"]],"c":"4269192714"},"book-1000","KSM/XBT"]
1618678161.580582: [464,{"a":[["56277.00000","0.04267101","1618678161.536601"]],"c":"1018270464"},"book-1000","XBT/CHF"]
1618678161.5821471: [3648,{"b":[["0.00754700","5.65403715","1618678161.536989"]],"c":"3831198153"},"book-1000","KSM/XBT"]
1618678161.5828469: [1360,{"b":[["0.000022850","31508.80538147","1618678161.537564"]],"c":"3209788844"},"book-1000","ADA/XBT"]
1618678161.585414: [992,{"b":[["353.58000000","6.86112401","1618678161.558144"]],"c":"426880512"},"book-1000","XMR/USD"]
1618678161.5881531: [1840,{"b":[["9.528694","1000.00000000","1618678161.560334"]],"c":"4268567183"},"book-1000","OMG/USD"]
1618678161.60716: [464,{"a":[["56276.90000","0.59541531","1618678161.577511"]],"c":"2665672761"},"book-1000","XBT/CHF"]
1618678161.6194: [992,{"a":[["355.13000000","2.94286788","1618678161.590605"]],"c":"305290817"},"book-1000","XMR/USD"]
1618678161.622259: [1664,{"a":[["13.277600","66.11376960","1618678161.592055"]],"c":"3388721921"},"book-1000","WAVES/EUR"]
1618678161.623782: [464,{"a":[["56277.30000","0.00000000","1618678161.593912"]],"c":"3416626460"},"book-1000","XBT/CHF"]
1618678161.6255958: [1920,{"a":[["0.043220","31572.89466873","1618678161.598015"]],"c":"3029360789"},"book-1000","SC/EUR"]
1618678161.628433: [992,{"a":[["354.51000000","0.00000000","1618678161.601467"]],"c":"3003335559"},"book-1000","XMR/USD"]
1618678161.636703: [496,{"a":[["2198.68000","0.00000000","1618678161.608139"]],"c":"2201998274"},"book-1000","ETH/CHF"]
1618678161.638059: [1840,{"a":[["9.607590","157.45363700","1618678161.608746"]],"c":"2708354163"},"book-1000","OMG/USD"]
1618678161.643902: [1664,{"a":[["13.312700","0.00000000","1618678161.615948"]],"c":"3388721921"},"book-1000","WAVES/EUR"]
1618678161.648551: [992,{"a":[["355.91000000","0.00000000","1618678161.621020"]],"c":"3003335559"},"book-1000","XMR/USD"]
1618678161.6512809: [1840,{"a":[["9.619274","0.00000000","1618678161.624240"]],"c":"143312817"},"book-1000","OMG/USD"]
1618678161.6538408: [1840,{"b":[["9.581282","136.81729527","1618678161.626913"]],"c":"2530456221"},"book-1000","OMG/USD"]
1618678161.656339: [464,{"a":[["56276.90000","0.74541531","1618678161.629191"]],"c":"1845913122"},"book-1000","XBT/CHF"]
1618678161.678089: [1840,{"b":[["9.558770","108.65127806","1618678161.643486"]],"c":"2530456221"},"book-1000","OMG/USD"]
1618678161.679641: [464,{"a":[["56959.70000","0.01000000","1618678161.651495"]],"c":"1845913122"},"book-1000","XBT/CHF"]
1618678161.684567: [496,{"b":[["2183.59000","3.00000000","1618678161.655594"]],"c":"3858110841"},"book-1000","ETH/CHF"]
1618678161.693171: [1840,{"b":[["9.581281","523.58554540","1618678161.665355"]],"c":"1526078745"},"book-1000","OMG/USD"]
1618678161.695054: [496,{"a":[["2198.66000","3.20000000","1618678161.667759"]],"c":"388072268"},"book-1000","ETH/CHF"]
1618678161.699245: [464,{"a":[["56276.90000","0.15000000","1618678161.671165"]],"c":"1530613354"},"book-1000","XBT/CHF"]
1618678161.7015622: [1920,{"b":[["0.042990","136406.00000000","1618678161.672587"]],"c":"793693851"},"book-1000","SC/EUR"]
1618678161.70433: [1840,{"b":[["9.581281","408.77835000","1618678161.672779"]],"c":"1963410311"},"book-1000","OMG/USD"]
1618678161.708101: [464,{"a":[["56277.10000","0.00000000","1618678161.679681"]],"c":"1478756679"},"book-1000","XBT/CHF"]
1618678161.711533: [992,{"a":[["355.62000000","15.27000000","1618678161.682929"]],"c":"3003335559"},"book-1000","XMR/USD"]
1618678161.714578: [1664,{"b":[["13.210200","66.11290519","1618678161.686461"]],"c":"1343392232"},"book-1000","WAVES/EUR"]
1618678161.720543: [1840,{"a":[["9.677625","0.00000000","1618678161.691947"]],"c":"1963410311"},"book-1000","OMG/USD"]
1618678161.7220411: [1840,{"b":[["9.586072","152.00000000","1618678161.693102"]],"c":"3587594621"},"book-1000","OMG/USD"]
1618678161.723553: [1840,{"a":[["9.609797","149.00000000","1618678161.695983"]],"c":"3372309674"},"book-1000","OMG/USD"]
1618678161.7302349: [496,{"b":[["2183.57000","0.00000000","1618678161.703228"]],"c":"938706433"},"book-1000","ETH/CHF"]
1618678161.739978: [464,{"a":[["56276.80000","0.59541531","1618678161.711887"]],"c":"1728226112"},"book-1000","XBT/CHF"]
1618678161.7446148: [1840,{"b":[["9.581283","114.80717144","1618678161.716354"]],"c":"2093869826"},"book-1000","OMG/USD"]
1618678161.7591932: [992,{"a":[["356.73000000","146.31652791","1618678161.728711"]],"c":"3003335559"},"book-1000","XMR/USD"]
1618678161.762294: [992,{"a":[["355.05000000","64.07894322","1618678161.728779"]],"c":"2644317234"},"book-1000","XMR/USD"]
1618678161.764748: [1840,{"a":[["9.687598","879.43329708","1618678161.732238"]],"c":"2093869826"},"book-1000","OMG/USD"]
1618678161.765841: [1664,{"a":[["13.312800","381.85533482","1618678161.732984"]],"c":"1343392232"},"book-1000","WAVES/EUR"]
1618678161.767061: [1920,{"b":[["0.042770","1236483.73348140","1618678161.733344"]],"c":"793693851"},"book-1000","SC/EUR"]
1618678161.769463: [1920,{"b":[["0.042860","0.00000000","1618678161.736629"]],"c":"793693851"},"book-1000","SC/EUR"]
1618678161.771849: [1840,{"b":[["9.576517","0.00000000","1618678161.740723"]],"c":"976120476"},"book-1000","OMG/USD"]
1618678161.772705: [1840,{"b":[["9.519367","0.00000000","1618678161.741341"]],"c":"976120476"},"book-1000","OMG/USD"]
1618678161.773537: [1840,{"b":[["9.572439","0.00000000","1618678161.742368"]],"c":"976120476"},"book-1000","OMG/USD"]
1618678161.774592: [1360,{"b":[["0.000022890","14000.27829781","1618678161.745032"]],"c":"40284314"},"book-1000","ADA/XBT"]
1618678161.77726: [1840,{"a":[["9.604803","50.00000000","1618678161.749264"]],"c":"343290355"},"book-1000","OMG/USD"]
1618678161.778123: [464,{"a":[["56276.70000","0.04267101","1618678161.750419"]],"c":"655393402"},"book-1000","XBT/CHF"]
1618678161.7801301: [464,{"a":[["56277.00000","0.00000000","1618678161.752865"]],"c":"1040582202"},"book-1000","XBT/CHF"]
1618678161.7844899: [1920,{"a":[["0.043220","10721.04662049","1618678161.756262"]],"c":"3803995419"},"book-1000","SC/EUR"]
1618678161.787255: [1360,{"a":[["0.000022930","7614.45269599","1618678161.758298"]],"c":"3683177953"},"book-1000","ADA/XBT"]
1618678161.789727: [1664,{"b":[["13.201300","419.18349878","1618678161.760269"]],"c":"1343392232"},"book-1000","WAVES/EUR"]
1618678161.794024: [464,{"a":[["56276.70000","0.19267101","1618678161.766526"]],"c":"1496395345"},"book-1000","XBT/CHF"]
1618678161.798075: [496,{"a":[["2198.65000","1.15978265","1618678161.769190"]],"c":"438595819"},"book-1000","ETH/CHF"]
1618678161.7990432: [496,{"a":[["2198.67000","0.00000000","1618678161.769241"]],"c":"1784122513"},"book-1000","ETH/CHF"]
1618678161.816458: [496,{"b":[["2183.58000","0.00000000","1618678161.788713"]],"c":"3860255620"},"book-1000","ETH/CHF"]
1618678161.817628: [1840,{"a":[["9.604802","136.83055203","1618678161.788985"]],"c":"1250268187"},"book-1000","OMG/USD"]
1618678161.820713: [496,{"b":[["2183.60000","1.51261875","1618678161.790873"]],"c":"637511542"},"book-1000","ETH/CHF"]
1618678161.821585: [5104,{"a":[["0.000027860","65.10000000","1618678161.791711"]],"c":"3194720649"},"book-1000","OCEAN/XBT"]
1618678161.822455: [1664,{"b":[["13.188600","15.04097310","1618678161.793686"]],"c":"1343392232"},"book-1000","WAVES/EUR"]
1618678161.826509: [464,{"a":[["56276.80000","0.00000000","1618678161.796771"]],"c":"1187946521"},"book-1000","XBT/CHF"]
1618678161.828178: [3648,{"a":[["0.00758500","5.00000000","1618678161.799725"]],"c":"253962003"},"book-1000","KSM/XBT"]
1618678161.8291998: [1840,{"a":[["9.624855","194.10704088","1618678161.800577"]],"c":"1250268187"},"book-1000","OMG/USD"]
1618678161.835476: [1840,{"a":[["9.616725","0.00000000","1618678161.801579"]],"c":"3497437548"},"book-1000","OMG/USD"]
1618678161.836898: [1840,{"b":[["9.558771","360.00000000","1618678161.805400"]],"c":"3497437548"},"book-1000","OMG/USD"]
1618678161.846476: [496,{"a":[["2198.64000","3.00000000","1618678161.817205"]],"c":"1098530611"},"book-1000","ETH/CHF"]
1618678161.8519151: [1920,{"a":[["0.043200","20000.00000000","1618678161.824554"]],"c":"2666599770"},"book-1000","SC/EUR"]
1618678161.85572: [992,{"a":[["355.05000000","59.76199127","1618678161.826143"]],"c":"3580834318"},"book-1000","XMR/USD"]
1618678161.857867: [1664,{"a":[["13.339900","1000.00000000","1618678161.827045"]],"c":"1343392232"},"book-1000","WAVES/EUR"]
1618678161.859096: [992,{"a":[["355.04000000","0.81952230","1618678161.828145"]],"c":"4236477016"},"book-1000","XMR/USD"]
1618678161.86096: [1664,{"a":[["13.277600","0.00000000","1618678161.832815"]],"c":"3459181906"},"book-1000","WAVES/EUR"]
1618678161.863981: [464,{"a":[["56276.60000","0.59541531","1618678161.836977"]],"c":"2099093779"},"book-1000","XBT/CHF"]
1618678161.869617: [992,{"a":[["356.81000000","0.00000000","1618678161.842366"]],"c":"4236477016"},"book-1000","XMR/USD"]
1618678161.873909: [464,{"a":[["56276.70000","0.04267101","1618678161.847123"]],"c":"25639760"},"book-1000","XBT/CHF"]
1618678161.901838: [496,{"b":[["2183.61000","3.00000000","1618678161.869878"]],"c":"1101491543"},"book-1000","ETH/CHF"]
1618678161.9106948: [1840,{"b":[["9.586072","213.20000000","1618678161.883230"]],"c":"2076156582"},"book-1000","OMG/USD"]
1618678161.918319: [496,{"a":[["2198.66000","0.00000000","1618678161.889426"]],"c":"3857191345"},"book-1000","ETH/CHF"]
1618678161.919681: [464,{"a":[["56276.50000","0.15000000","1618678161.889624"]],"c":"410201540"},"book-1000","XBT/CHF"]
1618678161.921602: [464,{"a":[["56276.90000","0.00000000","1618678161.889787"]],"c":"1772829164"},"book-1000","XBT/CHF"]
1618678161.92333: [1920,{"b":[["0.042990","0.00000000","1618678161.895708"]],"c":"87014228"},"book-1000","SC/EUR"]
1618678161.926054: [3648,{"a":[["0.00760500","9.00000000","1618678161.898324"]],"c":"581017358"},"book-1000","KSM/XBT"]
1618678161.958923: [1920,{"a":[["0.043200","0.00000000","1618678161.931332"]],"c":"2036527893"},"book-1000","SC/EUR"]
1618678161.962461: [464,{"a":[["56276.60000","0.00000000","1618678161.931495"]],"c":"2994689917"},"book-1000","XBT/CHF"]
1618678161.964353: [1920,{"b":[["0.042770","789393.30000000","1618678161.932089"]],"c":"2036527893"},"book-1000","SC/EUR"]
1618678161.975156: [1360,{"a":[["0.000022930","7111.81976627","1618678161.947402"]],"c":"40284314"},"book-1000","ADA/XBT"]
1618678161.9832351: [496,{"a":[["2198.63000","3.20000000","1618678161.953826"]],"c":"1897848109"},"book-1000","ETH/CHF"]
1618678161.984881: [992,{"b":[["352.66000000","0.17106559","1618678161.955905"]],"c":"4236477016"},"book-1000","XMR/USD"]
1618678161.9988532: [464,{"a":[["56276.40000","0.59541531","1618678161.970115"]],"c":"3481127819"},"book-1000","XBT/CHF"]
1618678162.0318809: [496,{"a":[["2198.62000","3.00000000","1618678162.003773"]],"c":"3537045562"},"book-1000","ETH/CHF"]
1618678162.033258: [496,{"b":[["2183.59000","0.00000000","1618678162.003949"]],"c":"395665312"},"book-1000","ETH/CHF"]
1618678162.034566: [5104,{"b":[["0.000027640","0.00000000","1618678162.006992"]],"c":"1864233115"},"book-1000","OCEAN/XBT"]
1618678162.0361989: [5104,{"b":[["0.000027150","0.00000000","1618678162.007440"]],"c":"1864233115"},"book-1000","OCEAN/XBT"]
1618678162.040384: [464,{"a":[["56276.30000","0.04267101","1618678162.009731"]],"c":"2306579700"},"book-1000","XBT/CHF"]
1618678162.042665: [464,{"a":[["56276.70000","0.00000000","1618678162.012375"]],"c":"3683442264"},"book-1000","XBT/CHF"]
1618678162.0472262: [992,{"b":[["353.14000000","52.00000000","1618678162.018691"]],"c":"4236477016"},"book-1000","XMR/USD"]
1618678162.049566: [464,{"a":[["56276.30000","0.19267101","1618678162.019499"]],"c":"1183551342"},"book-1000","XBT/CHF"]
1618678162.056889: [496,{"a":[["2198.62000","4.15978265","1618678162.028354"]],"c":"3215625488"},"book-1000","ETH/CHF"]
1618678162.058101: [496,{"a":[["2198.65000","0.00000000","1618678162.028678"]],"c":"2647050331"},"book-1000","ETH/CHF"]
1618678162.063432: [1840,{"a":[["9.612701","0.00000000","1618678162.035996"]],"c":"2135742885"},"book-1000","OMG/USD"]
1618678162.081093: [496,{"a":[["2198.64000","0.00000000","1618678162.053697"]],"c":"1767433069"},"book-1000","ETH/CHF"]
1618678162.0822248: [5104,{"a":[["0.000027840","15480.20354048","1618678162.054934"]],"c":"1771415995"},"book-1000","OCEAN/XBT"]
1618678162.085835: [496,{"b":[["2183.60000","0.00000000","1618678162.056168"]],"c":"263267417"},"book-1000","ETH/CHF"]
1618678162.086928: [496,{"b":[["2183.62000","1.51260493","1618678162.056302"]],"c":"3815016983"},"book-1000","ETH/CHF"]
1618678162.088723: [464,{"a":[["56276.40000","0.00000000","1618678162.060350"]],"c":"2098753609"},"book-1000","XBT/CHF"]
1618678162.090838: [1840,{"b":[["9.581281","358.77835000","1618678162.060983"]],"c":"1243492443"},"book-1000","OMG/USD"]
1618678162.106497: [5104,{"b":[["0.000027690","626.00000000","1618678162.076810"]],"c":"2712673574"},"book-1000","OCEAN/XBT"]
1618678162.1077929: [5104,{"b":[["0.000027350","1269.00000000","1618678162.076928"]],"c":"2712673574"},"book-1000","OCEAN/XBT"]
1618678162.1141179: [1840,{"a":[["9.633621","520.70660800","1618678162.085713"]],"c":"1243492443"},"book-1000","OMG/USD"]
1618678162.115485: [1840,{"a":[["9.604801","200.00000000","1618678162.086462"]],"c":"2242781457"},"book-1000","OMG/USD"]
1618678162.116503: [992,{"a":[["355.04000000","0.00000000","1618678162.086622"]],"c":"3580834318"},"book-1000","XMR/USD"]
1618678162.1187892: [1840,{"b":[["9.586073","200.00000000","1618678162.086933"]],"c":"699130297"},"book-1000","OMG/USD"]
1618678162.120436: [992,{"a":[["355.04000000","4.31705243","1618678162.091987"]],"c":"1121628122"},"book-1000","XMR/USD"]
1618678162.1248388: [1920,{"a":[["0.043460","0.00000000","1618678162.094455"]],"c":"1151128697"},"book-1000","SC/EUR"]
1618678162.127446: [1664,{"b":[["13.210200","0.00000000","1618678162.098069"]],"c":"1472704443"},"book-1000","WAVES/EUR"]
1618678162.128714: [1664,{"a":[["13.282900","66.12546900","1618678162.098435"]],"c":"3158770930"},"book-1000","WAVES/EUR"]
1618678162.129793: [1664,{"b":[["13.185900","0.00000000","1618678162.098487"]],"c":"3158770930"},"book-1000","WAVES/EUR"]
1618678162.130987: [464,{"a":[["56276.20000","0.59541531","1618678162.102408"]],"c":"2682238271"},"book-1000","XBT/CHF"]
1618678162.135019: [5104,{"b":[["0.000027740","606.11897000","1618678162.106227"]],"c":"3408984150"},"book-1000","OCEAN/XBT"]
1618678162.141699: [3648,{"a":[["0.00758300","0.00000000","1618678162.111550"]],"c":"1072687819"},"book-1000","KSM/XBT"]
1618678162.1433222: [464,{"b":[["56060.30000","0.05804973","1618678162.114364"]],"c":"586808624"},"book-1000","XBT/CHF"]
1618678162.145219: [464,{"b":[["56023.90000","0.00000000","1618678162.116225"]],"c":"3097853742"},"book-1000","XBT/CHF"]
1618678162.149943: [3648,{"a":[["0.00758100","44.71000000","1618678162.120312"]],"c":"867853571"},"book-1000","KSM/XBT"]
1618678162.151135: [1920,{"a":[["0.043260","34591.64355062","1618678162.121768"]],"c":"149656219"},"book-1000","SC/EUR"]
1618678162.153902: [3648,{"b":[["0.00754300","5.10000000","1618678162.123011"]],"c":"867853571"},"book-1000","KSM/XBT"]
1618678162.154748: [464,{"a":[["56276.30000","0.04267101","1618678162.124114"]],"c":"2687332628"},"book-1000","XBT/CHF"]
1618678162.165478: [1840,{"b":[["9.581281","158.77835000","1618678162.138092"]],"c":"4014737286"},"book-1000","OMG/USD"]
1618678162.178129: [464,{"a":[["56733.80000","0.00000000","1618678162.151066"]],"c":"2687332628"},"book-1000","XBT/CHF"]
1618678162.184683: [464,{"a":[["56276.50000","0.00000000","1618678162.155179"]],"c":"2916099334"},"book-1000","XBT/CHF"]
1618678162.187096: [464,{"a":[["56276.10000","0.15000000","1618678162.155295"]],"c":"2753774998"},"book-1000","XBT/CHF"]
1618678162.2193081: [1360,{"a":[["0.000022940","17552.30777187","1618678162.190200"]],"c":"1435716389"},"book-1000","ADA/XBT"]
1618678162.223103: [1920,{"b":[["0.043060","35200.00000000","1618678162.190257"]],"c":"1062507589"},"book-1000","SC/EUR"]
1618678162.226032: [464,{"a":[["56276.20000","0.00000000","1618678162.195699"]],"c":"934898774"},"book-1000","XBT/CHF"]
1618678162.337166: {"event":"heartbeat"}
1618678162.5257: [496,{"a":[["2198.63000","0.00000000","1618678162.497112"]],"c":"2656401918"},"book-1000","ETH/CHF"]
1618678162.527435: [464,{"b":[["56060.30000","0.00000000","1618678162.498119"]],"c":"4123864748"},"book-1000","XBT/CHF"]
1618678162.529369: [464,{"b":[["56046.70000","0.05893218","1618678162.498908"]],"c":"430531833"},"book-1000","XBT/CHF"]
1618678162.531119: [992,{"b":[["353.59000000","5.00000000","1618678162.500427"]],"c":"525273186"},"book-1000","XMR/USD"]
1618678162.533203: [1920,{"a":[["0.043500","918972.56718037","1618678162.502513"]],"c":"926707201"},"book-1000","SC/EUR"]
1618678162.535916: [1360,{"a":[["0.000022920","5021.04049996","1618678162.505298"]],"c":"1159543920"},"book-1000","ADA/XBT"]
1618678162.53872: [464,{"a":[["56276.00000","0.59541531","1618678162.510670"]],"c":"753254238"},"book-1000","XBT/CHF"]
1618678162.5400581: [1360,{"b":[["0.000022890","8320.45920805","1618678162.511095"]],"c":"1980950594"},"book-1000","ADA/XBT"]
1618678162.559272: [464,{"a":[["56951.50000","3.56787561","1618678162.529837"]],"c":"753254238"},"book-1000","XBT/CHF"]
1618678162.5618382: [992,{"b":[["351.76000000","5.66091140","1618678162.530034"]],"c":"525273186"},"book-1000","XMR/USD"]
1618678162.564103: [1664,{"b":[["13.090400","75.64182084","1618678162.530440"]],"c":"3158770930"},"book-1000","WAVES/EUR"]
1618678162.565399: [1360,{"a":[["0.000022920","4050.46490863","1618678162.531164"]],"c":"987015646"},"book-1000","ADA/XBT"]
1618678162.568037: [1664,{"b":[["13.232900","102.00000000","1618678162.531610"]],"c":"4039456719"},"book-1000","WAVES/EUR"]
1618678162.569365: [992,{"a":[["357.11000000","0.14249480","1618678162.531816"]],"c":"525273186"},"book-1000","XMR/USD"]
1618678162.571074: [992,{"a":[["356.70000000","0.00000000","1618678162.534343"]],"c":"525273186"},"book-1000","XMR/USD"]
1618678162.572748: [1360,{"a":[["0.000022910","11026.78958050","1618678162.538618"]],"c":"3182460892"},"book-1000","ADA/XBT"]
1618678162.5751019: [464,{"a":[["56951.60000","0.00000000","1618678162.539185"]],"c":"753254238"},"book-1000","XBT/CHF"]
1618678162.5763369: [464,{"b":[["55594.40000","0.00000000","1618678162.539292"]],"c":"753254238"},"book-1000","XBT/CHF"]
1618678162.577537: [496,{"b":[["2183.63000","3.00000000","1618678162.539386"]],"c":"2646911370"},"book-1000","ETH/CHF"]
1618678162.578212: [464,{"a":[["56980.60000","0.55666559","1618678162.541769"]],"c":"753254238"},"book-1000","XBT/CHF"]
1618678162.579654: [1920,{"b":[["0.042820","0.00000000","1618678162.543120"]],"c":"926707201"},"book-1000","SC/EUR"]
1618678162.58179: [464,{"a":[["57415.90000","0.04049010","1618678162.543457"]],"c":"753254238"},"book-1000","XBT/CHF"]
1618678162.582952: [1360,{"b":[["0.000022880","20759.04649894","1618678162.544595"]],"c":"3624597360"},"book-1000","ADA/XBT"]
1618678162.585016: [1664,{"a":[["13.264600","103.00000000","1618678162.544851"]],"c":"570720772"},"book-1000","WAVES/EUR"]
1618678162.585883: [3648,{"a":[["0.00758000","2.27368185","1618678162.546621"]],"c":"2562985320"},"book-1000","KSM/XBT"]
1618678162.5864892: [464,{"b":[["55623.00000","0.55666559","1618678162.546992"]],"c":"753254238"},"book-1000","XBT/CHF"]
1618678162.5875351: [1664,{"b":[["13.199700","132.24753551","1618678162.548848"]],"c":"570720772"},"book-1000","WAVES/EUR"]
1618678162.5885582: [1920,{"b":[["0.042850","0.00000000","1618678162.550491"]],"c":"926707201"},"book-1000","SC/EUR"]
1618678162.590382: [1920,{"b":[["0.043010","0.00000000","1618678162.550688"]],"c":"1683606899"},"book-1000","SC/EUR"]
1618678162.592196: [5104,{"b":[["0.000027700","44.30000000","1618678162.554760"]],"c":"3403825845"},"book-1000","OCEAN/XBT"]
1618678162.592764: [1920,{"b":[["0.042870","0.00000000","1618678162.557124"]],"c":"11316373"},"book-1000","SC/EUR"]
1618678162.594561: [496,{"a":[["2212.77000","0.00000000","1618678162.559113"]],"c":"2646911370"},"book-1000","ETH/CHF"]
1618678162.595361: [1840,{"b":[["9.565023","0.00000000","1618678162.561287"]],"c":"4014737286"},"book-1000","OMG/USD"]
1618678162.596101: [464,{"b":[["56046.70000","0.00000000","1618678162.564600"]],"c":"3175765052"},"book-1000","XBT/CHF"]
1618678162.597148: [464,{"a":[["56276.30000","0.00000000","1618678162.565023"]],"c":"3902712690"},"book-1000","XBT/CHF"]
1618678162.598198: [464,{"b":[["56060.30000","0.05805128","1618678162.565368"]],"c":"708271037"},"book-1000","XBT/CHF"]
1618678162.599242: [496,{"a":[["2198.61000","3.20000000","1618678162.565920"]],"c":"3354839577"},"book-1000","ETH/CHF"]
1618678162.5999942: [3648,{"b":[["0.00755800","0.00000000","1618678162.567938"]],"c":"3394953656"},"book-1000","KSM/XBT"]
1618678162.600595: [5104,{"a":[["0.000027820","1046.48131937","1618678162.568671"]],"c":"2820889515"},"book-1000","OCEAN/XBT"]
1618678162.6011431: [992,{"b":[["353.60000000","22.72500000","1618678162.571339"]],"c":"2963887609"},"book-1000","XMR/USD"]
1618678162.602527: [1360,{"a":[["0.000022940","17049.67484215","1618678162.572274"]],"c":"1162112260"},"book-1000","ADA/XBT"]
1618678162.604647: [496,{"a":[["2213.47000","14.29214021","1618678162.572439"]],"c":"3354839577"},"book-1000","ETH/CHF"]
1618678162.605242: [464,{"a":[["56276.00000","0.63808632","1618678162.575699"]],"c":"299374280"},"book-1000","XBT/CHF"]
1618678162.606411: [1840,{"a":[["9.605014","157.29284600","1618678162.577027"]],"c":"2969878773"},"book-1000","OMG/USD"]
1618678162.60901: [1664,{"b":[["13.226300","500.00000000","1618678162.580722"]],"c":"3933234136"},"book-1000","WAVES/EUR"]
1618678162.610153: [5104,{"a":[["0.000027880","0.00000000","1618678162.581612"]],"c":"1780063574"},"book-1000","OCEAN/XBT"]
1618678162.612333: [992,{"a":[["354.57000000","11.64000000","1618678162.582702"]],"c":"1224464950"},"book-1000","XMR/USD"]
1618678162.61402: [992,{"b":[["353.55000000","0.00000000","1618678162.583241"]],"c":"3860608006"},"book-1000","XMR/USD"]
1618678162.615437: [496,{"b":[["2183.64000","1.51259107","1618678162.583343"]],"c":"2751639450"},"book-1000","ETH/CHF"]
1618678162.61626: [992,{"a":[["354.59000000","0.00000000","1618678162.583990"]],"c":"2614999543"},"book-1000","XMR/USD"]
1618678162.617693: [464,{"a":[["56276.00000","0.04267101","1618678162.585571"]],"c":"2811047194"},"book-1000","XBT/CHF"]
1618678162.618935: [496,{"b":[["2183.62000","0.00000000","1618678162.587805"]],"c":"130487233"},"book-1000","ETH/CHF"]
1618678162.622729: [1664,{"b":[["13.233000","500.00000000","1618678162.593921"]],"c":"1713727628"},"book-1000","WAVES/EUR"]
1618678162.623907: [1664,{"a":[["13.264900","500.00000000","1618678162.593995"]],"c":"2908028870"},"book-1000","WAVES/EUR"]
1618678162.62518: [992,{"b":[["352.06000000","12.00000000","1618678162.596100"]],"c":"2614999543"},"book-1000","XMR/USD"]
1618678162.6274931: [992,{"b":[["353.48000000","288.61890000","1618678162.596167"]],"c":"1014478094"},"book-1000","XMR/USD"]
1618678162.629718: [464,{"b":[["56060.30000","0.00000000","1618678162.599747"]],"c":"2694915919"},"book-1000","XBT/CHF"]
1618678162.640995: [1360,{"a":[["0.000022920","8331.78644075","1618678162.600758"]],"c":"957718949"},"book-1000","ADA/XBT"]
1618678162.6447308: [464,{"b":[["56060.30000","0.05804987","1618678162.602062"]],"c":"2882776482"},"book-1000","XBT/CHF"]
1618678162.6463182: [1920,{"b":[["0.043070","36311.57644124","1618678162.607293"]],"c":"244993810"},"book-1000","SC/EUR"]
1618678162.648715: [5104,{"a":[["0.000027900","732.36854110","1618678162.607388"]],"c":"807246611"},"book-1000","OCEAN/XBT"]
1618678162.649378: [496,{"a":[["2198.62000","3.00000000","1618678162.610925"]],"c":"2271189183"},"book-1000","ETH/CHF"]
1618678162.650082: [496,{"a":[["2198.60000","1.15978265","1618678162.612328"]],"c":"1763269684"},"book-1000","ETH/CHF"]
1618678162.6510222: [992,{"b":[["353.58000000","0.00000000","1618678162.614817"]],"c":"1528498727"},"book-1000","XMR/USD"]
1618678162.65275: [1920,{"b":[["0.042880","27992.12566058","1618678162.621657"]],"c":"2029736018"},"book-1000","SC/EUR"]
1618678162.6548722: [464,{"a":[["56275.90000","0.15000000","1618678162.622430"]],"c":"467185847"},"book-1000","XBT/CHF"]
1618678162.6562681: [992,{"b":[["353.56000000","0.00000000","1618678162.625551"]],"c":"4090009958"},"book-1000","XMR/USD"]
1618678162.6576908: [1664,{"b":[["13.233000","651.13730823","1618678162.625911"]],"c":"1931918718"},"book-1000","WAVES/EUR"]
1618678162.658624: [496,{"b":[["2183.61000","0.00000000","1618678162.625997"]],"c":"2112152649"},"book-1000","ETH/CHF"]
1618678162.659203: [464,{"a":[["56275.90000","0.74541531","1618678162.626352"]],"c":"786798847"},"book-1000","XBT/CHF"]
1618678162.660269: [496,{"a":[["2198.60000","4.15978265","1618678162.626530"]],"c":"1225811637"},"book-1000","ETH/CHF"]
1618678162.661073: [1664,{"b":[["13.188600","0.00000000","1618678162.633693"]],"c":"1931918718"},"book-1000","WAVES/EUR"]
1618678162.665039: [5104,{"a":[["0.000028600","0.00000000","1618678162.637066"]],"c":"807246611"},"book-1000","OCEAN/XBT"]
1618678162.6659992: [464,{"a":[["57214.30000","0.00000000","1618678162.638497"]],"c":"786798847"},"book-1000","XBT/CHF"]
1618678162.667283: [1840,{"b":[["9.558771","0.00000000","1618678162.639365"]],"c":"2969878773"},"book-1000","OMG/USD"]
1618678162.668015: [992,{"b":[["353.61000000","5.00000000","1618678162.640192"]],"c":"843374499"},"book-1000","XMR/USD"]
1618678162.672962: [464,{"b":[["56060.30000","0.00000000","1618678162.645532"]],"c":"3053337651"},"book-1000","XBT/CHF"]
1618678162.676849: [464,{"b":[["56060.30000","0.05804973","1618678162.648388"]],"c":"3684734396"},"book-1000","XBT/CHF"]
1618678162.682611: [1664,{"a":[["13.264500","500.00000000","1618678162.654180"]],"c":"3933768391"},"book-1000","WAVES/EUR"]
1618678162.685535: [496,{"b":[["2183.65000","3.00000000","1618678162.658722"]],"c":"391534135"},"book-1000","ETH/CHF"]
1618678162.6866791: [496,{"b":[["2183.63000","0.00000000","1618678162.658919"]],"c":"3619664884"},"book-1000","ETH/CHF"]
1618678162.687712: [1664,{"b":[["13.226300","0.00000000","1618678162.659988"]],"c":"3296022022"},"book-1000","WAVES/EUR"]
1618678162.691086: [992,{"b":[["353.61000000","11.86028723","1618678162.663537"]],"c":"1821439118"},"book-1000","XMR/USD"]
1618678162.698078: [464,{"a":[["56275.90000","0.15000000","1618678162.669102"]],"c":"4003315188"},"book-1000","XBT/CHF"]
1618678162.7004852: [1664,{"b":[["13.220100","33.99000000","1618678162.673307"]],"c":"1870825513"},"book-1000","WAVES/EUR"]
1618678162.71296: [1840,{"b":[["9.581282","0.00000000","1618678162.684410"]],"c":"305169621"},"book-1000","OMG/USD"]
1618678162.7268312: [464,{"a":[["56276.10000","0.00000000","1618678162.699177"]],"c":"4282697411"},"book-1000","XBT/CHF"]
1618678162.729388: [1920,{"a":[["0.043260","127535.21497918","1618678162.701117"]],"c":"3829386297"},"book-1000","SC/EUR"]
1618678162.732488: [1920,{"a":[["0.043260","92943.57142856","1618678162.701494"]],"c":"885534926"},"book-1000","SC/EUR"]
1618678162.735865: [1664,{"a":[["13.265000","0.00000000","1618678162.702741"]],"c":"2848044916"},"book-1000","WAVES/EUR"]
1618678162.73724: [992,{"b":[["353.59000000","0.00000000","1618678162.703990"]],"c":"3499481417"},"book-1000","XMR/USD"]
1618678162.739329: [3648,{"b":[["0.00754700","46.87403715","1618678162.704380"]],"c":"4188698556"},"book-1000","KSM/XBT"]
1618678162.7402802: [496,{"a":[["2198.62000","0.00000000","1618678162.706586"]],"c":"3402140756"},"book-1000","ETH/CHF"]
1618678162.741034: [464,{"a":[["56275.80000","0.59541531","1618678162.711370"]],"c":"361613673"},"book-1000","XBT/CHF"]
1618678162.742448: [992,{"b":[["353.62000000","22.72500000","1618678162.714763"]],"c":"1832254700"},"book-1000","XMR/USD"]
1618678162.746939: [1840,{"b":[["9.528695","360.00000000","1618678162.718383"]],"c":"305169621"},"book-1000","OMG/USD"]
1618678162.748281: [464,{"b":[["55789.10000","0.00000000","1618678162.718973"]],"c":"361613673"},"book-1000","XBT/CHF"]
1618678162.750079: [464,{"a":[["56951.40000","0.17560000","1618678162.720033"]],"c":"361613673"},"book-1000","XBT/CHF"]
1618678162.751629: [464,{"a":[["56169.90000","0.00000000","1618678162.721143"]],"c":"1495614256"},"book-1000","XBT/CHF"]
1618678162.7620769: [5104,{"a":[["0.000028650","62.64268195","1618678162.726358"]],"c":"807246611"},"book-1000","OCEAN/XBT"]
1618678162.763349: [1840,{"b":[["9.586074","136.84482827","1618678162.729564"]],"c":"830458275"},"book-1000","OMG/USD"]
1618678162.7646642: [3648,{"b":[["0.00755600","0.00000000","1618678162.732241"]],"c":"1206466393"},"book-1000","KSM/XBT"]
1618678162.765955: [1664,{"b":[["13.063300","0.00000000","1618678162.736506"]],"c":"2848044916"},"book-1000","WAVES/EUR"]
1618678162.770781: [992,{"b":[["351.46000000","0.00000000","1618678162.742685"]],"c":"1832254700"},"book-1000","XMR/USD"]
1618678162.781337: [464,{"a":[["56275.80000","0.00000000","1618678162.751323"]],"c":"1566479948"},"book-1000","XBT/CHF"]
1618678162.794223: [496,{"a":[["2198.61000","0.00000000","1618678162.765289"]],"c":"3207757324"},"book-1000","ETH/CHF"]
1618678162.795313: [1840,{"a":[["9.612272","147.00000000","1618678162.766298"]],"c":"3642564280"},"book-1000","OMG/USD"]
1618678162.796374: [1664,{"a":[["13.264900","0.00000000","1618678162.766350"]],"c":"738935470"},"book-1000","WAVES/EUR"]
1618678162.8148339: [1664,{"b":[["13.206500","0.00000000","1618678162.786516"]],"c":"525355955"},"book-1000","WAVES/EUR"]
1618678162.817916: [1664,{"b":[["13.231900","25.92000000","1618678162.790368"]],"c":"3527800623"},"book-1000","WAVES/EUR"]
1618678162.819476: [464,{"a":[["56275.70000","0.59541531","1618678162.791591"]],"c":"2756389885"},"book-1000","XBT/CHF"]
1618678162.821267: [1840,{"b":[["9.586073","357.32198000","1618678162.793929"]],"c":"1645055617"},"book-1000","OMG/USD"]
1618678162.833893: [1840,{"b":[["9.582680","155.56943800","1618678162.797884"]],"c":"2062085057"},"book-1000","OMG/USD"]
1618678162.835504: [5104,{"b":[["0.000027710","618.49333546","1618678162.798105"]],"c":"206995175"},"book-1000","OCEAN/XBT"]
1618678162.836534: [464,{"a":[["56275.80000","0.04267101","1618678162.801827"]],"c":"3503105212"},"book-1000","XBT/CHF"]
1618678162.844099: [464,{"a":[["56194.20000","0.01700000","1618678162.808237"]],"c":"2098128383"},"book-1000","XBT/CHF"]
1618678162.846508: [464,{"a":[["56276.00000","0.00000000","1618678162.812842"]],"c":"1380111424"},"book-1000","XBT/CHF"]
1618678162.848484: [1840,{"b":[["9.586075","200.00000000","1618678162.817453"]],"c":"2779601803"},"book-1000","OMG/USD"]
1618678162.865361: [1920,{"b":[["0.043070","5794.10440061","1618678162.833570"]],"c":"4293886477"},"book-1000","SC/EUR"]
1618678162.873963: [496,{"b":[["2183.64000","0.00000000","1618678162.836517"]],"c":"132847040"},"book-1000","ETH/CHF"]
1618678162.875208: [992,{"b":[["353.44000000","3.29700000","1618678162.837604"]],"c":"3636346219"},"book-1000","XMR/USD"]
1618678162.885847: [496,{"a":[["2198.59000","3.20000000","1618678162.844922"]],"c":"393228626"},"book-1000","ETH/CHF"]
1618678162.8872042: [464,{"a":[["56275.60000","0.15000000","1618678162.845063"]],"c":"3499115759"},"book-1000","XBT/CHF"]
1618678162.889153: [464,{"b":[["55573.60000","0.00000000","1618678162.846670"]],"c":"3499115759"},"book-1000","XBT/CHF"]
1618678162.8906722: [1840,{"a":[["9.604802","0.00000000","1618678162.847320"]],"c":"1052996954"},"book-1000","OMG/USD"]
1618678162.8917298: [496,{"b":[["2183.66000","1.51257720","1618678162.849591"]],"c":"1896658102"},"book-1000","ETH/CHF"]
1618678162.892542: [1840,{"a":[["9.607309","144.00000000","1618678162.851012"]],"c":"2683358237"},"book-1000","OMG/USD"]
1618678162.89358: [5104,{"a":[["0.000027820","593.84154000","1618678162.853226"]],"c":"273858491"},"book-1000","OCEAN/XBT"]
1618678162.9045382: [1840,{"b":[["9.586073","157.32198000","1618678162.865849"]],"c":"2219558866"},"book-1000","OMG/USD"]
1618678162.906106: [1360,{"b":[["0.000022890","3279.10442708","1618678162.869515"]],"c":"3876739429"},"book-1000","ADA/XBT"]
1618678162.9102988: [992,{"b":[["353.44000000","2.47700000","1618678162.880124"]],"c":"1832254700"},"book-1000","XMR/USD"]
1618678162.914273: [5104,{"a":[["0.000028120","0.00000000","1618678162.885187"]],"c":"273858491"},"book-1000","OCEAN/XBT"]
1618678162.915734: [992,{"b":[["353.60000000","0.00000000","1618678162.886204"]],"c":"1969214698"},"book-1000","XMR/USD"]
1618678162.91831: [464,{"a":[["56275.70000","0.00000000","1618678162.887106"]],"c":"1918794987"},"book-1000","XBT/CHF"]
1618678162.919936: [1840,{"a":[["9.604800","136.84969211","1618678162.889016"]],"c":"2411199731"},"book-1000","OMG/USD"]
1618678162.924994: [464,{"a":[["56275.90000","0.00000000","1618678162.894792"]],"c":"1820663224"},"book-1000","XBT/CHF"]
1618678162.92685: [992,{"b":[["353.44000000","0.00000000","1618678162.896326"]],"c":"3684176056"},"book-1000","XMR/USD"]
1618678162.932162: [992,{"b":[["353.15000000","4.35124257","1618678162.898165"]],"c":"3579516621"},"book-1000","XMR/USD"]
1618678162.9391701: [496,{"a":[["2198.58000","1.15978265","1618678162.902896"]],"c":"3239048053"},"book-1000","ETH/CHF"]
1618678162.9403572: [1920,{"a":[["0.043280","141668.00000000","1618678162.902976"]],"c":"790059368"},"book-1000","SC/EUR"]
1618678162.9432719: [1664,{"b":[["13.199700","0.00000000","1618678162.906128"]],"c":"3527800623"},"book-1000","WAVES/EUR"]
1618678162.9448352: [1664,{"a":[["13.284100","0.00000000","1618678162.906358"]],"c":"3527800623"},"book-1000","WAVES/EUR"]
1618678162.945934: [496,{"a":[["2198.60000","3.00000000","1618678162.907395"]],"c":"1615295876"},"book-1000","ETH/CHF"]
1618678162.948374: [1360,{"a":[["0.000022900","160.00000000","1618678162.914838"]],"c":"1542372404"},"book-1000","ADA/XBT"]
1618678162.957385: [464,{"a":[["56275.50000","0.59541531","1618678162.925198"]],"c":"1533369078"},"book-1000","XBT/CHF"]
1618678162.973894: [1920,{"b":[["0.042980","191741.00000000","1618678162.945178"]],"c":"1859691981"},"book-1000","SC/EUR"]
1618678162.979121: [1360,{"b":[["0.000022880","14759.04649894","1618678162.947717"]],"c":"1754007587"},"book-1000","ADA/XBT"]
1618678162.982578: [1360,{"b":[["0.000022870","13943.16413900","1618678162.948164"]],"c":"2694598003"},"book-1000","ADA/XBT"]
1618678162.9853: [464,{"b":[["55827.60000","0.43658195","1618678162.948318"]],"c":"1533369078"},"book-1000","XBT/CHF"]
1618678162.9867961: [496,{"a":[["2198.57000","3.00000000","1618678162.950732"]],"c":"651602985"},"book-1000","ETH/CHF"]
1618678162.987552: [496,{"b":[["2183.67000","3.00000000","1618678162.950796"]],"c":"1547970672"},"book-1000","ETH/CHF"]
1618678162.999989: [1360,{"a":[["0.000022900","5200.50427342","1618678162.963831"]],"c":"2641488046"},"book-1000","ADA/XBT"]
1618678163.004579: [464,{"a":[["56275.40000","0.15000000","1618678162.972981"]],"c":"1715393062"},"book-1000","XBT/CHF"]
1618678163.0122292: [1920,{"a":[["0.043260","0.00000000","1618678162.981794"]],"c":"1840259898"},"book-1000","SC/EUR"]
1618678163.030059: [3648,{"b":[["0.00755500","0.00000000","1618678162.998503"]],"c":"1991028018"},"book-1000","KSM/XBT"]
1618678163.031422: [496,{"a":[["2198.60000","0.00000000","1618678162.999752"]],"c":"4153639662"},"book-1000","ETH/CHF"]
1618678163.0369952: [496,{"b":[["2183.65000","0.00000000","1618678163.000148"]],"c":"2099562311"},"book-1000","ETH/CHF"]
1618678163.04413: [1360,{"b":[["0.000022870","12681.76413900","1618678163.010770"]],"c":"2843306710"},"book-1000","ADA/XBT"]
1618678163.0475562: [464,{"a":[["56275.50000","0.00000000","1618678163.012222"]],"c":"2071589469"},"book-1000","XBT/CHF"]
1618678163.051106: [1920,{"a":[["0.043190","0.00000000","1618678163.012955"]],"c":"1790635534"},"book-1000","SC/EUR"]
1618678163.054108: [1920,{"b":[["0.043060","0.00000000","1618678163.013075"]],"c":"1949678036"},"book-1000","SC/EUR"]
1618678163.061003: [464,{"a":[["56275.60000","0.00000000","1618678163.024180"]],"c":"3606117443"},"book-1000","XBT/CHF"]
1618678163.062886: [1920,{"a":[["0.043500","13647.23302177","1618678163.024488"]],"c":"3601688372"},"book-1000","SC/EUR"]
1618678163.065603: [1920,{"b":[["0.042980","45500.00000000","1618678163.025095"]],"c":"1686171178"},"book-1000","SC/EUR"]
1618678163.082329: [496,{"a":[["2198.59000","0.00000000","1618678163.042623"]],"c":"2848196290"},"book-1000","ETH/CHF"]
1618678163.0835211: [1920,{"a":[["0.043180","50961.83886926","1618678163.043473"]],"c":"1708327248"},"book-1000","SC/EUR"]
1618678163.0864341: [1840,{"b":[["9.586072","61.20000000","1618678163.043847"]],"c":"2247297944"},"book-1000","OMG/USD"]
1618678163.0874932: [1360,{"b":[["0.000022890","2188.50442708","1618678163.045850"]],"c":"3482030101"},"book-1000","ADA/XBT"]
1618678163.090091: [3648,{"b":[["0.00749600","8.84000000","1618678163.046012"]],"c":"1991028018"},"book-1000","KSM/XBT"]
1618678163.0908191: [5104,{"a":[["0.000027820","1046.48131937","1618678163.046231"]],"c":"206995175"},"book-1000","OCEAN/XBT"]
1618678163.0914948: [3648,{"b":[["0.00755100","1.08991000","1618678163.046301"]],"c":"3969072930"},"book-1000","KSM/XBT"]
1618678163.092192: [464,{"a":[["56275.30000","0.59541531","1618678163.051120"]],"c":"2778851292"},"book-1000","XBT/CHF"]
1618678163.093716: [464,{"a":[["56275.30000","0.63808632","1618678163.054193"]],"c":"617372412"},"book-1000","XBT/CHF"]
1618678163.09501: [464,{"a":[["56275.80000","0.00000000","1618678163.059722"]],"c":"818304921"},"book-1000","XBT/CHF"]
1618678163.0962958: [464,{"a":[["56275.40000","0.00000000","1618678163.059844"]],"c":"3496818108"},"book-1000","XBT/CHF"]
1618678163.130409: [1360,{"a":[["0.000022900","7200.50427342","1618678163.094045"]],"c":"1923205333"},"book-1000","ADA/XBT"]
1618678163.134212: [1360,{"a":[["0.000022920","9273.88644075","1618678163.096054"]],"c":"2059108456"},"book-1000","ADA/XBT"]
1618678163.1370509: [464,{"a":[["56275.30000","0.04267101","1618678163.096840"]],"c":"2918386657"},"book-1000","XBT/CHF"]
1618678163.1384268: [1920,{"a":[["0.043260","88248.92048080","1618678163.097397"]],"c":"1103621587"},"book-1000","SC/EUR"]
1618678163.142273: [464,{"a":[["56275.20000","0.15000000","1618678163.100343"]],"c":"1206772928"},"book-1000","XBT/CHF"]
1618678163.1439722: [496,{"b":[["2183.68000","1.51256335","1618678163.101530"]],"c":"2071650297"},"book-1000","ETH/CHF"]
1618678163.144814: [496,{"a":[["2198.56000","3.20000000","1618678163.102733"]],"c":"2549341068"},"book-1000","ETH/CHF"]
1618678163.145514: [1920,{"b":[["0.043030","30545.84157000","1618678163.110786"]],"c":"3284559302"},"book-1000","SC/EUR"]
1618678163.153538: [496,{"b":[["2183.66000","0.00000000","1618678163.112178"]],"c":"3518579410"},"book-1000","ETH/CHF"]
1618678163.15485: [1920,{"a":[["0.043180","42461.83886926","1618678163.112655"]],"c":"1930931723"},"book-1000","SC/EUR"]
1618678163.1647518: [1664,{"b":[["13.208000","132.22934680","1618678163.135755"]],"c":"3973476462"},"book-1000","WAVES/EUR"]
1618678163.1671958: [464,{"a":[["56275.20000","0.74541531","1618678163.137048"]],"c":"1926286472"},"book-1000","XBT/CHF"]
1618678163.173841: [1664,{"a":[["13.286200","132.22934680","1618678163.138673"]],"c":"3973476462"},"book-1000","WAVES/EUR"]
1618678163.175732: [992,{"b":[["353.15000000","0.00000000","1618678163.142435"]],"c":"3684176056"},"book-1000","XMR/USD"]
1618678163.1780128: [992,{"b":[["353.49000000","4.34705734","1618678163.142611"]],"c":"3176814161"},"book-1000","XMR/USD"]
1618678163.1800058: [496,{"a":[["2198.58000","0.00000000","1618678163.142743"]],"c":"1021802268"},"book-1000","ETH/CHF"]
1618678163.181003: [1360,{"a":[["0.000022910","11866.08958050","1618678163.145735"]],"c":"304853628"},"book-1000","ADA/XBT"]
1618678163.183768: [496,{"b":[["2183.69000","3.00000000","1618678163.150247"]],"c":"2883270313"},"book-1000","ETH/CHF"]
1618678163.189203: [1360,{"b":[["0.000022890","0.00000000","1618678163.156821"]],"c":"1223294805"},"book-1000","ADA/XBT"]
1618678163.1980019: [496,{"a":[["2198.55000","1.15978265","1618678163.158559"]],"c":"2792733308"},"book-1000","ETH/CHF"]
1618678163.199361: [1664,{"a":[["13.589900","0.00000000","1618678163.163577"]],"c":"3973476462"},"book-1000","WAVES/EUR"]
1618678163.2095392: [464,{"a":[["56275.20000","0.15000000","1618678163.177267"]],"c":"1206772928"},"book-1000","XBT/CHF"]
1618678163.215791: [1664,{"b":[["13.201200","0.00000000","1618678163.182559"]],"c":"3973476462"},"book-1000","WAVES/EUR"]
1618678163.2222779: [496,{"a":[["2198.55000","4.15978265","1618678163.188246"]],"c":"1009695253"},"book-1000","ETH/CHF"]
1618678163.229166: [992,{"b":[["353.63000000","5.00000000","1618678163.191796"]],"c":"3179059140"},"book-1000","XMR/USD"]
1618678163.233166: [1360,{"b":[["0.000022880","16947.13445094","1618678163.198509"]],"c":"1270046910"},"book-1000","ADA/XBT"]
1618678163.236285: [1840,{"a":[["9.604799","200.00000000","1618678163.201857"]],"c":"2961595054"},"book-1000","OMG/USD"]
1618678163.2438521: [1920,{"a":[["0.043450","23196.47413593","1618678163.207285"]],"c":"3487941598"},"book-1000","SC/EUR"]
1618678163.2546308: [464,{"a":[["56275.10000","0.59541531","1618678163.218192"]],"c":"3289732514"},"book-1000","XBT/CHF"]
1618678163.2634828: [1360,{"a":[["0.000022910","12932.15588050","1618678163.225919"]],"c":"4272797800"},"book-1000","ADA/XBT"]
1618678163.267349: [5104,{"a":[["0.000027820","593.84154000","1618678163.230920"]],"c":"273858491"},"book-1000","OCEAN/XBT"]
1618678163.2735639: [496,{"b":[["2183.67000","0.00000000","1618678163.238191"]],"c":"1689000166"},"book-1000","ETH/CHF"]
1618678163.27493: [496,{"a":[["2198.57000","0.00000000","1618678163.238943"]],"c":"96261385"},"book-1000","ETH/CHF"]
1618678163.277907: [992,{"b":[["353.61000000","6.86028723","1618678163.243386"]],"c":"3328580917"},"book-1000","XMR/USD"]
1618678163.28043: [992,{"b":[["353.64000000","22.72500000","1618678163.245037"]],"c":"2185554411"},"book-1000","XMR/USD"]
1618678163.2919722: [1840,{"a":[["9.604801","0.00000000","1618678163.261322"]],"c":"540460483"},"book-1000","OMG/USD"]
1618678163.296364: [464,{"a":[["56275.00000","0.15000000","1618678163.266047"]],"c":"458917492"},"book-1000","XBT/CHF"]
1618678163.306824: [1920,{"b":[["0.042960","0.00000000","1618678163.277469"]],"c":"618143068"},"book-1000","SC/EUR"]
1618678163.310326: [496,{"a":[["2198.56000","0.00000000","1618678163.278140"]],"c":"694360366"},"book-1000","ETH/CHF"]
1618678163.3114219: [1360,{"b":[["0.000022880","11947.13445094","1618678163.279973"]],"c":"1320338001"},"book-1000","ADA/XBT"]
1618678163.314261: [1360,{"b":[["0.000022870","17681.76413900","1618678163.280593"]],"c":"4087106535"},"book-1000","ADA/XBT"]
1618678163.316869: [1360,{"a":[["0.000022950","10584.16491659","1618678163.281750"]],"c":"2361326681"},"book-1000","ADA/XBT"]
1618678163.3192298: [3648,{"b":[["0.00750400","0.00000000","1618678163.285133"]],"c":"3969072930"},"book-1000","KSM/XBT"]
1618678163.324853: [992,{"b":[["353.62000000","0.00000000","1618678163.295480"]],"c":"1691467551"},"book-1000","XMR/USD"]
1618678163.3269901: [1920,{"b":[["0.043040","30600.00000000","1618678163.295831"]],"c":"3526311853"},"book-1000","SC/EUR"]
1618678163.339707: [992,{"b":[["353.64000000","30.30000000","1618678163.305296"]],"c":"1428009488"},"book-1000","XMR/USD"]
1618678163.3424482: [992,{"a":[["354.67000000","7.57500000","1618678163.305503"]],"c":"2695395383"},"book-1000","XMR/USD"]
1618678163.344555: [464,{"a":[["56275.10000","0.00000000","1618678163.305641"]],"c":"3825859849"},"book-1000","XBT/CHF"]
1618678163.34614: {"event":"heartbeat"}
1618678163.348514: [1664,{"b":[["13.186000","0.00000000","1618678163.308099"]],"c":"3973476462"},"book-1000","WAVES/EUR"]
1618678163.3498602: [1360,{"a":[["0.000022940","13446.18034215","1618678163.309296"]],"c":"659619456"},"book-1000","ADA/XBT"]
1618678163.3526368: [5104,{"b":[["0.000027700","1584.76997750","1618678163.316125"]],"c":"2196805940"},"book-1000","OCEAN/XBT"]
1618678163.353302: [464,{"a":[["56274.90000","0.04267101","1618678163.317024"]],"c":"778192996"},"book-1000","XBT/CHF"]
1618678163.354541: [5104,{"b":[["0.000027660","0.00000000","1618678163.317180"]],"c":"2815827483"},"book-1000","OCEAN/XBT"]
1618678163.361881: [1920,{"b":[["0.042950","0.00000000","1618678163.318329"]],"c":"4058690033"},"book-1000","SC/EUR"]
1618678163.365427: [1840,{"b":[["9.586072","0.00000000","1618678163.323225"]],"c":"1921670645"},"book-1000","OMG/USD"]
1618678163.366488: [464,{"a":[["56275.30000","0.00000000","1618678163.327300"]],"c":"532245536"},"book-1000","XBT/CHF"]
1618678163.368086: [1920,{"a":[["0.043170","20000.00000000","1618678163.327760"]],"c":"2651642486"},"book-1000","SC/EUR"]
1618678163.3728619: [1664,{"a":[["13.264500","0.00000000","1618678163.334706"]],"c":"560301834"},"book-1000","WAVES/EUR"]


