1626994933.22703: {"feed":"book","product_id":"FI_XBTUSD_210924","side":"sell","seq":13501671,"price":32226.0,"qty":0.0,"timestamp":1626994933252}
1626994933.227089: {"feed":"book","product_id":"FI_XBTUSD_210924","side":"sell","seq":13501672,"price":32227.0,"qty":103.0,"timestamp":1626994933252}
1626994933.2332869: {"feed":"book","product_id":"PI_ETHUSD","side":"sell","seq":26661460,"price":2004.7,"qty":0.0,"timestamp":1626994933258}
1626994933.237376: {"feed":"book","product_id":"FI_XBTUSD_210924","side":"sell","seq":13501673,"price":32227.0,"qty":0.0,"timestamp":1626994933262}
1626994933.237463: {"feed":"book","product_id":"FI_XBTUSD_210924","side":"sell","seq":13501674,"price":32230.0,"qty":103.0,"timestamp":1626994933262}
1626994933.239567: {"feed":"book","product_id":"FI_XBTUSD_210730","side":"sell","seq":5160003,"price":32204.0,"qty":0.0,"timestamp":1626994933262}
1626994933.239655: {"feed":"book","product_id":"FI_XBTUSD_210730","side":"sell","seq":5160004,"price":32207.0,"qty":103.0,"timestamp":1626994933262}
1626994933.243689: {"feed":"book","product_id":"PI_ETHUSD","side":"buy","seq":26661461,"price":1995.6,"qty":38399.0,"timestamp":1626994933265}
1626994933.243762: {"feed":"book","product_id":"PI_ETHUSD","side":"sell","seq":26661462,"price":2005.45,"qty":4986.0,"timestamp":1626994933265}
1626994933.243789: {"feed":"book","product_id":"FI_ETHUSD_210730","side":"sell","seq":2138701,"price":2003.15,"qty":0.0,"timestamp":1626994933265}
1626994933.2438211: {"feed":"book","product_id":"PI_XRPUSD","side":"buy","seq":3456209,"price":0.5682,"qty":2.0,"timestamp":1626994933264}
1626994933.24508: {"feed":"book","product_id":"FI_XBTUSD_210730","side":"sell","seq":5160005,"price":32207.0,"qty":0.0,"timestamp":1626994933269}
1626994933.2451289: {"feed":"book","product_id":"FI_XBTUSD_210730","side":"sell","seq":5160006,"price":32208.0,"qty":103.0,"timestamp":1626994933269}
1626994933.245161: {"feed":"book","product_id":"FI_XBTUSD_210924","side":"sell","seq":13501675,"price":32230.0,"qty":0.0,"timestamp":1626994933269}
1626994933.245198: {"feed":"book","product_id":"FI_XBTUSD_210924","side":"sell","seq":13501676,"price":32231.0,"qty":103.0,"timestamp":1626994933269}
1626994933.250697: {"feed":"book","product_id":"PI_ETHUSD","side":"buy","seq":26661463,"price":1999.7,"qty":0.0,"timestamp":1626994933274}
1626994933.2507882: {"feed":"book","product_id":"PI_ETHUSD","side":"buy","seq":26661464,"price":1999.8,"qty":500001.0,"timestamp":1626994933274}
1626994933.250848: {"feed":"book","product_id":"FI_XBTUSD_210924","side":"buy","seq":13501677,"price":32128.0,"qty":0.0,"timestamp":1626994933274}
1626994933.250901: {"feed":"book","product_id":"FI_XBTUSD_210924","side":"buy","seq":13501678,"price":32130.0,"qty":250001.0,"timestamp":1626994933274}
1626994933.250946: {"feed":"book","product_id":"PI_ETHUSD","side":"sell","seq":26661465,"price":2007.7,"qty":8564.0,"timestamp":1626994933274}
1626994933.2509818: {"feed":"book","product_id":"PI_ETHUSD","side":"sell","seq":26661466,"price":2009.05,"qty":500001.0,"timestamp":1626994933274}
1626994933.251025: {"feed":"book","product_id":"FI_ETHUSD_211231","side":"sell","seq":2199007,"price":2038.25,"qty":8748.0,"timestamp":1626994933274}
1626994933.25108: {"feed":"book","product_id":"FI_ETHUSD_211231","side":"sell","seq":2199008,"price":2038.7,"qty":250001.0,"timestamp":1626994933274}
1626994933.251106: {"feed":"book","product_id":"PI_ETHUSD","side":"buy","seq":26661467,"price":1995.25,"qty":0.0,"timestamp":1626994933274}
1626994933.251134: {"feed":"book","product_id":"PI_ETHUSD","side":"buy","seq":26661468,"price":1995.35,"qty":500002.0,"timestamp":1626994933274}
1626994933.2511601: {"feed":"book","product_id":"FI_ETHUSD_211231","side":"sell","seq":2199009,"price":2049.85,"qty":0.0,"timestamp":1626994933274}
1626994933.251186: {"feed":"book","product_id":"FI_ETHUSD_211231","side":"sell","seq":2199010,"price":2049.75,"qty":250002.0,"timestamp":1626994933274}
1626994933.251214: {"feed":"book","product_id":"PI_ETHUSD","side":"sell","seq":26661469,"price":2012.9,"qty":0.0,"timestamp":1626994933274}
1626994933.251241: {"feed":"book","product_id":"PI_ETHUSD","side":"sell","seq":26661470,"price":2012.8,"qty":500002.0,"timestamp":1626994933274}
1626994933.251266: {"feed":"book","product_id":"FI_ETHUSD_210730","side":"sell","seq":2138702,"price":2008.35,"qty":3200.0,"timestamp":1626994933274}
1626994933.251287: {"feed":"book","product_id":"FI_ETHUSD_210730","side":"sell","seq":2138703,"price":2011.3,"qty":250001.0,"timestamp":1626994933274}
1626994933.2538261: {"feed":"book","product_id":"PI_ETHUSD","side":"sell","seq":26661471,"price":2005.9,"qty":0.0,"timestamp":1626994933278}
1626994933.2539551: {"feed":"book","product_id":"PI_ETHUSD","side":"sell","seq":26661472,"price":2005.9,"qty":11003.0,"timestamp":1626994933278}
1626994933.254434: {"feed":"book","product_id":"PI_ETHUSD","side":"buy","seq":26661473,"price":2000.55,"qty":0.0,"timestamp":1626994933278}
1626994933.254493: {"feed":"book","product_id":"PI_ETHUSD","side":"buy","seq":26661474,"price":2000.55,"qty":17450.0,"timestamp":1626994933278}
1626994933.2545311: {"feed":"book","product_id":"PI_ETHUSD","side":"sell","seq":26661475,"price":2007.0,"qty":5000.0,"timestamp":1626994933278}
1626994933.2545578: {"feed":"book","product_id":"PI_ETHUSD","side":"sell","seq":26661476,"price":2007.0,"qty":22907.0,"timestamp":1626994933278}
1626994933.25458: {"feed":"book","product_id":"PI_ETHUSD","side":"buy","seq":26661477,"price":2000.85,"qty":0.0,"timestamp":1626994933278}
1626994933.2546098: {"feed":"book","product_id":"PI_ETHUSD","side":"buy","seq":26661478,"price":2000.85,"qty":15191.0,"timestamp":1626994933278}
1626994933.2571251: {"feed":"book","product_id":"PI_ETHUSD","side":"sell","seq":26661479,"price":2007.65,"qty":0.0,"timestamp":1626994933278}
1626994933.257257: {"feed":"book","product_id":"PI_ETHUSD","side":"sell","seq":26661480,"price":2007.65,"qty":23102.0,"timestamp":1626994933278}
1626994933.257321: {"feed":"book","product_id":"PI_ETHUSD","side":"buy","seq":26661481,"price":1999.75,"qty":0.0,"timestamp":1626994933278}
1626994933.257375: {"feed":"book","product_id":"PI_ETHUSD","side":"buy","seq":26661482,"price":1999.75,"qty":23583.0,"timestamp":1626994933278}
1626994933.25742: {"feed":"book","product_id":"PI_ETHUSD","side":"buy","seq":26661483,"price":1995.3,"qty":0.0,"timestamp":1626994933278}
1626994933.2574642: {"feed":"book","product_id":"PI_ETHUSD","side":"buy","seq":26661484,"price":1995.3,"qty":46828.0,"timestamp":1626994933278}
1626994933.257518: {"feed":"book","product_id":"PI_ETHUSD","side":"sell","seq":26661485,"price":2012.85,"qty":0.0,"timestamp":1626994933278}
1626994933.257545: {"feed":"book","product_id":"PI_ETHUSD","side":"sell","seq":26661486,"price":2012.85,"qty":49343.0,"timestamp":1626994933278}
1626994933.257571: {"feed":"book","product_id":"PI_ETHUSD","side":"buy","seq":26661487,"price":1988.9,"qty":0.0,"timestamp":1626994933278}
1626994933.257597: {"feed":"book","product_id":"PI_ETHUSD","side":"buy","seq":26661488,"price":1988.9,"qty":66924.0,"timestamp":1626994933278}
1626994933.257621: {"feed":"book","product_id":"PI_ETHUSD","side":"sell","seq":26661489,"price":2021.45,"qty":0.0,"timestamp":1626994933278}
1626994933.257647: {"feed":"book","product_id":"PI_ETHUSD","side":"sell","seq":26661490,"price":2021.45,"qty":67921.0,"timestamp":1626994933278}
1626994933.2576709: {"feed":"book","product_id":"PI_ETHUSD","side":"buy","seq":26661491,"price":1999.4,"qty":0.0,"timestamp":1626994933282}
1626994933.258969: {"feed":"book","product_id":"PI_ETHUSD","side":"buy","seq":26661492,"price":2001.85,"qty":13718.0,"timestamp":1626994933284}
1626994933.264825: {"feed":"book","product_id":"FI_XBTUSD_210730","side":"buy","seq":5160007,"price":32159.0,"qty":0.0,"timestamp":1626994933289}
1626994933.264951: {"feed":"book","product_id":"FI_XBTUSD_210730","side":"buy","seq":5160008,"price":32171.0,"qty":50.0,"timestamp":1626994933289}
1626994933.277828: {"feed":"book","product_id":"FI_XBTUSD_210924","side":"sell","seq":13501679,"price":32221.0,"qty":0.0,"timestamp":1626994933301}
1626994933.2779799: {"feed":"book","product_id":"FI_XBTUSD_210924","side":"sell","seq":13501680,"price":32225.0,"qty":1009.0,"timestamp":1626994933301}
1626994933.278046: {"feed":"book","product_id":"FI_XBTUSD_210730","side":"sell","seq":5160009,"price":32192.5,"qty":0.0,"timestamp":1626994933302}
1626994933.278095: {"feed":"book","product_id":"FI_XBTUSD_210730","side":"sell","seq":5160010,"price":32197.0,"qty":1200.0,"timestamp":1626994933302}
1626994933.278419: {"feed":"book","product_id":"FI_XBTUSD_210730","side":"sell","seq":5160011,"price":32235.5,"qty":0.0,"timestamp":1626994933303}
1626994933.278492: {"feed":"book","product_id":"FI_XBTUSD_210730","side":"sell","seq":5160012,"price":32255.0,"qty":60000.0,"timestamp":1626994933303}
1626994933.282114: {"feed":"book","product_id":"FI_XBTUSD_210730","side":"buy","seq":5160013,"price":32097.5,"qty":0.0,"timestamp":1626994933303}
1626994933.282263: {"feed":"book","product_id":"FI_XBTUSD_210730","side":"buy","seq":5160014,"price":32117.5,"qty":60000.0,"timestamp":1626994933303}
1626994933.2823281: {"feed":"book","product_id":"FI_XBTUSD_210924","side":"buy","seq":13501681,"price":32143.0,"qty":0.0,"timestamp":1626994933304}
1626994933.282408: {"feed":"book","product_id":"FI_XBTUSD_210924","side":"buy","seq":13501682,"price":32144.5,"qty":1500.0,"timestamp":1626994933304}
1626994933.2824378: {"feed":"book","product_id":"FI_XBTUSD_210730","side":"buy","seq":5160015,"price":32157.0,"qty":0.0,"timestamp":1626994933303}
1626994933.282466: {"feed":"book","product_id":"FI_XBTUSD_210730","side":"buy","seq":5160016,"price":32162.0,"qty":30000.0,"timestamp":1626994933303}
1626994933.282492: {"feed":"book","product_id":"FI_XBTUSD_210730","side":"buy","seq":5160017,"price":32122.0,"qty":0.0,"timestamp":1626994933304}
1626994933.282518: {"feed":"book","product_id":"FI_XBTUSD_210730","side":"buy","seq":5160018,"price":32124.0,"qty":1500.0,"timestamp":1626994933304}
1626994933.282542: {"feed":"book","product_id":"PI_LTCUSD","side":"sell","seq":3423173,"price":119.54,"qty":1062.0,"timestamp":1626994933305}
1626994933.2884989: {"feed":"book","product_id":"FI_XBTUSD_210730","side":"buy","seq":5160019,"price":32098.0,"qty":0.0,"timestamp":1626994933311}
1626994933.288629: {"feed":"book","product_id":"FI_XBTUSD_210730","side":"buy","seq":5160020,"price":32091.5,"qty":250001.0,"timestamp":1626994933311}
1626994933.288694: {"feed":"book","product_id":"FI_XBTUSD_210730","side":"sell","seq":5160021,"price":32259.0,"qty":0.0,"timestamp":1626994933311}
1626994933.2887459: {"feed":"book","product_id":"FI_XBTUSD_210730","side":"sell","seq":5160022,"price":32254.5,"qty":250001.0,"timestamp":1626994933311}
1626994933.300722: {"feed":"book","product_id":"FI_XBTUSD_210924","side":"sell","seq":13501683,"price":32237.5,"qty":0.0,"timestamp":1626994933325}
1626994933.304758: {"feed":"book","product_id":"FI_XBTUSD_210924","side":"sell","seq":13501684,"price":32271.5,"qty":1075.0,"timestamp":1626994933330}
1626994933.305274: {"feed":"book","product_id":"FI_XBTUSD_210730","side":"sell","seq":5160023,"price":32201.0,"qty":0.0,"timestamp":1626994933330}
1626994933.309803: {"feed":"book","product_id":"FI_XBTUSD_210924","side":"sell","seq":13501685,"price":32236.0,"qty":0.0,"timestamp":1626994933334}
1626994933.313685: {"feed":"book","product_id":"FI_XBTUSD_210924","side":"sell","seq":13501686,"price":32270.0,"qty":0.0,"timestamp":1626994933338}
1626994933.3138099: {"feed":"book","product_id":"FI_XBTUSD_210924","side":"sell","seq":13501687,"price":32281.0,"qty":43267.0,"timestamp":1626994933338}
1626994933.32043: {"feed":"book","product_id":"FI_XBTUSD_210730","side":"sell","seq":5160024,"price":32208.0,"qty":0.0,"timestamp":1626994933341}
1626994933.320554: {"feed":"book","product_id":"FI_XBTUSD_210730","side":"sell","seq":5160025,"price":32209.0,"qty":103.0,"timestamp":1626994933341}
1626994933.3206248: {"feed":"book","product_id":"FI_ETHUSD_211231","side":"sell","seq":2199011,"price":2036.25,"qty":154.0,"timestamp":1626994933341}
1626994933.320679: {"feed":"book","product_id":"FI_ETHUSD_211231","side":"sell","seq":2199012,"price":2035.65,"qty":0.0,"timestamp":1626994933342}
1626994933.320756: {"feed":"book","product_id":"PI_ETHUSD","side":"buy","seq":26661493,"price":2003.8,"qty":0.0,"timestamp":1626994933342}
1626994933.320789: {"feed":"book","product_id":"PI_ETHUSD","side":"buy","seq":26661494,"price":2003.7,"qty":20000.0,"timestamp":1626994933342}
1626994933.320817: {"feed":"book","product_id":"PI_LTCUSD","side":"sell","seq":3423174,"price":119.59,"qty":4988.0,"timestamp":1626994933343}
1626994933.320841: {"feed":"book","product_id":"PI_ETHUSD","side":"buy","seq":26661495,"price":2003.85,"qty":0.0,"timestamp":1626994933344}
1626994933.320868: {"feed":"book","product_id":"PI_ETHUSD","side":"buy","seq":26661496,"price":2003.75,"qty":15826.0,"timestamp":1626994933344}
1626994933.326078: {"feed":"book","product_id":"PI_LTCUSD","side":"buy","seq":3423175,"price":119.27,"qty":0.0,"timestamp":1626994933351}
1626994933.3262012: {"feed":"book","product_id":"PI_LTCUSD","side":"buy","seq":3423176,"price":119.3,"qty":16934.0,"timestamp":1626994933351}
1626994933.326256: {"feed":"book","product_id":"PI_LTCUSD","side":"sell","seq":3423177,"price":119.5,"qty":0.0,"timestamp":1626994933351}
1626994933.326307: {"feed":"book","product_id":"PI_LTCUSD","side":"sell","seq":3423178,"price":119.53,"qty":8000.0,"timestamp":1626994933351}
1626994933.326355: {"feed":"book","product_id":"PI_LTCUSD","side":"sell","seq":3423179,"price":119.63,"qty":12633.0,"timestamp":1626994933351}
1626994933.326391: {"feed":"book","product_id":"PI_LTCUSD","side":"sell","seq":3423180,"price":119.7,"qty":16000.0,"timestamp":1626994933351}
1626994933.332466: {"feed":"book","product_id":"FI_ETHUSD_210730","side":"buy","seq":2138704,"price":1999.35,"qty":317.0,"timestamp":1626994933357}
1626994933.3329868: {"feed":"book","product_id":"FI_XBTUSD_210924","side":"sell","seq":13501688,"price":32252.5,"qty":0.0,"timestamp":1626994933358}
1626994933.348105: {"feed":"book","product_id":"PI_LTCUSD","side":"buy","seq":3423181,"price":119.3,"qty":12886.0,"timestamp":1626994933372}
1626994933.348215: {"feed":"book","product_id":"FI_XBTUSD_210924","side":"sell","seq":13501689,"price":32231.0,"qty":0.0,"timestamp":1626994933373}
1626994933.348286: {"feed":"book","product_id":"FI_XBTUSD_210924","side":"sell","seq":13501690,"price":32232.0,"qty":103.0,"timestamp":1626994933373}
1626994933.362092: {"feed":"book","product_id":"PI_LTCUSD","side":"sell","seq":3423182,"price":119.57,"qty":5275.0,"timestamp":1626994933386}
1626994933.3647292: {"feed":"book","product_id":"FI_XBTUSD_210730","side":"sell","seq":5160026,"price":32209.0,"qty":0.0,"timestamp":1626994933388}
1626994933.364853: {"feed":"book","product_id":"FI_XBTUSD_210730","side":"sell","seq":5160027,"price":32211.0,"qty":103.0,"timestamp":1626994933388}
1626994933.364917: {"feed":"book","product_id":"FI_XBTUSD_210924","side":"sell","seq":13501691,"price":32232.0,"qty":0.0,"timestamp":1626994933388}
1626994933.364971: {"feed":"book","product_id":"FI_XBTUSD_210924","side":"sell","seq":13501692,"price":32234.0,"qty":103.0,"timestamp":1626994933388}
1626994933.36907: {"feed":"book","product_id":"FI_XBTUSD_210730","side":"sell","seq":5160028,"price":32211.0,"qty":0.0,"timestamp":1626994933391}
1626994933.369192: {"feed":"book","product_id":"FI_XBTUSD_210730","side":"sell","seq":5160029,"price":32212.0,"qty":103.0,"timestamp":1626994933391}
1626994933.3720782: {"feed":"book","product_id":"PI_ETHUSD","side":"buy","seq":26661497,"price":2003.75,"qty":19704.0,"timestamp":1626994933396}
1626994933.376556: {"feed":"book","product_id":"PI_ETHUSD","side":"sell","seq":26661498,"price":2005.85,"qty":0.0,"timestamp":1626994933399}
1626994933.378727: {"feed":"book","product_id":"PI_ETHUSD","side":"sell","seq":26661499,"price":2006.05,"qty":4035.0,"timestamp":1626994933401}
1626994933.381056: {"feed":"book","product_id":"PI_LTCUSD","side":"sell","seq":3423183,"price":119.6,"qty":63.0,"timestamp":1626994933405}
1626994933.381165: {"feed":"book","product_id":"PI_LTCUSD","side":"sell","seq":3423184,"price":119.65,"qty":4105.0,"timestamp":1626994933406}
1626994933.393207: {"feed":"book","product_id":"FI_XBTUSD_210924","side":"sell","seq":13501693,"price":32258.5,"qty":0.0,"timestamp":1626994933417}
1626994933.393332: {"feed":"book","product_id":"FI_XBTUSD_210924","side":"sell","seq":13501694,"price":32269.0,"qty":20962.0,"timestamp":1626994933417}
1626994933.393399: {"feed":"book","product_id":"FI_XBTUSD_210924","side":"buy","seq":13501695,"price":32166.0,"qty":0.0,"timestamp":1626994933417}
1626994933.393461: {"feed":"book","product_id":"FI_XBTUSD_210924","side":"buy","seq":13501696,"price":32172.0,"qty":20906.0,"timestamp":1626994933417}
1626994933.393512: {"feed":"book","product_id":"FI_XBTUSD_210924","side":"sell","seq":13501697,"price":32235.5,"qty":940.0,"timestamp":1626994933417}
1626994933.393536: {"feed":"book","product_id":"FI_XBTUSD_210924","side":"sell","seq":13501698,"price":32235.5,"qty":15697.0,"timestamp":1626994933417}
1626994933.393557: {"feed":"book","product_id":"FI_XBTUSD_210924","side":"buy","seq":13501699,"price":32188.5,"qty":881.0,"timestamp":1626994933417}
1626994933.3935769: {"feed":"book","product_id":"FI_XBTUSD_210924","side":"buy","seq":13501700,"price":32188.5,"qty":17615.0,"timestamp":1626994933417}
1626994933.406647: {"feed":"book","product_id":"FI_XBTUSD_210924","side":"buy","seq":13501701,"price":32171.5,"qty":3000.0,"timestamp":1626994933429}
1626994933.406764: {"feed":"book","product_id":"PI_ETHUSD","side":"buy","seq":26661500,"price":2003.75,"qty":3878.0,"timestamp":1626994933429}
1626994933.406819: {"feed":"book","product_id":"PI_ETHUSD","side":"buy","seq":26661501,"price":2003.9,"qty":15826.0,"timestamp":1626994933429}
1626994933.406857: {"feed":"book","product_id":"PI_ETHUSD","side":"buy","seq":26661502,"price":2003.7,"qty":0.0,"timestamp":1626994933431}
1626994933.406893: {"feed":"book","product_id":"PI_ETHUSD","side":"buy","seq":26661503,"price":2003.85,"qty":20000.0,"timestamp":1626994933431}
1626994933.4209201: {"feed":"book","product_id":"FI_XBTUSD_210924","side":"sell","seq":13501702,"price":32234.0,"qty":0.0,"timestamp":1626994933446}
1626994933.421045: {"feed":"book","product_id":"FI_XBTUSD_210924","side":"sell","seq":13501703,"price":32235.0,"qty":103.0,"timestamp":1626994933446}
1626994933.423462: {"feed":"book","product_id":"FI_BCHUSD_210924","side":"sell","seq":402232,"price":442.7,"qty":0.0,"timestamp":1626994933448}
1626994933.431137: {"feed":"book","product_id":"PI_LTCUSD","side":"buy","seq":3423185,"price":119.34,"qty":28616.0,"timestamp":1626994933455}
1626994933.439562: {"feed":"book","product_id":"PI_ETHUSD","side":"buy","seq":26661504,"price":2003.1,"qty":3862.0,"timestamp":1626994933464}
1626994933.445086: {"feed":"book","product_id":"PI_ETHUSD","side":"buy","seq":26661505,"price":2003.35,"qty":3909.0,"timestamp":1626994933469}
1626994933.445209: {"feed":"book","product_id":"PI_ETHUSD","side":"sell","seq":26661506,"price":2005.8,"qty":3800.0,"timestamp":1626994933470}
1626994933.4456031: {"feed":"book","product_id":"PI_ETHUSD","side":"sell","seq":26661507,"price":2005.55,"qty":15000.0,"timestamp":1626994933471}
1626994933.452142: {"feed":"book","product_id":"PI_ETHUSD","side":"buy","seq":26661508,"price":2003.9,"qty":0.0,"timestamp":1626994933478}
1626994933.452228: {"feed":"book","product_id":"PI_ETHUSD","side":"buy","seq":26661509,"price":2003.8,"qty":15826.0,"timestamp":1626994933478}
1626994933.4522712: {"feed":"book","product_id":"PI_ETHUSD","side":"buy","seq":26661510,"price":2003.85,"qty":0.0,"timestamp":1626994933478}
1626994933.452306: {"feed":"book","product_id":"PI_ETHUSD","side":"buy","seq":26661511,"price":2003.75,"qty":23878.0,"timestamp":1626994933478}
1626994933.460612: {"feed":"book","product_id":"PI_ETHUSD","side":"sell","seq":26661512,"price":2005.9,"qty":0.0,"timestamp":1626994933482}
1626994933.4606998: {"feed":"book","product_id":"PI_ETHUSD","side":"sell","seq":26661513,"price":2006.25,"qty":11484.0,"timestamp":1626994933482}
1626994933.460744: {"feed":"book","product_id":"PI_ETHUSD","side":"sell","seq":26661514,"price":2007.65,"qty":0.0,"timestamp":1626994933482}
1626994933.460778: {"feed":"book","product_id":"PI_ETHUSD","side":"sell","seq":26661515,"price":2008.35,"qty":25560.0,"timestamp":1626994933482}
1626994933.4608068: {"feed":"book","product_id":"PI_ETHUSD","side":"buy","seq":26661516,"price":2000.85,"qty":0.0,"timestamp":1626994933482}
1626994933.4608371: {"feed":"book","product_id":"PI_ETHUSD","side":"buy","seq":26661517,"price":2001.85,"qty":24792.0,"timestamp":1626994933482}
1626994933.46086: {"feed":"book","product_id":"PI_ETHUSD","side":"sell","seq":26661518,"price":2007.0,"qty":5000.0,"timestamp":1626994933483}
1626994933.4608798: {"feed":"book","product_id":"PI_ETHUSD","side":"sell","seq":26661519,"price":2007.35,"qty":22792.0,"timestamp":1626994933483}
1626994933.4609: {"feed":"book","product_id":"PI_ETHUSD","side":"buy","seq":26661520,"price":2000.55,"qty":0.0,"timestamp":1626994933483}
1626994933.460927: {"feed":"book","product_id":"PI_ETHUSD","side":"buy","seq":26661521,"price":2000.85,"qty":17150.0,"timestamp":1626994933483}
1626994933.460952: {"feed":"book","product_id":"PI_ETHUSD","side":"buy","seq":26661522,"price":1999.75,"qty":0.0,"timestamp":1626994933483}
1626994933.4609768: {"feed":"book","product_id":"PI_ETHUSD","side":"buy","seq":26661523,"price":2000.05,"qty":23384.0,"timestamp":1626994933483}
1626994933.461001: {"feed":"book","product_id":"PI_ETHUSD","side":"sell","seq":26661524,"price":2012.85,"qty":0.0,"timestamp":1626994933483}
1626994933.461026: {"feed":"book","product_id":"PI_ETHUSD","side":"sell","seq":26661525,"price":2012.85,"qty":48486.0,"timestamp":1626994933483}
1626994933.461051: {"feed":"book","product_id":"PI_ETHUSD","side":"buy","seq":26661526,"price":1995.3,"qty":0.0,"timestamp":1626994933483}
1626994933.461076: {"feed":"book","product_id":"PI_ETHUSD","side":"buy","seq":26661527,"price":1995.3,"qty":47666.0,"timestamp":1626994933483}
1626994933.4611: {"feed":"book","product_id":"FI_XBTUSD_210924","side":"sell","seq":13501704,"price":32240.5,"qty":0.0,"timestamp":1626994933485}
1626994933.46114: {"feed":"book","product_id":"PI_ETHUSD","side":"buy","seq":26661528,"price":1988.9,"qty":0.0,"timestamp":1626994933483}
1626994933.461167: {"feed":"book","product_id":"PI_ETHUSD","side":"buy","seq":26661529,"price":1988.9,"qty":66933.0,"timestamp":1626994933483}
1626994933.461191: {"feed":"book","product_id":"FI_XBTUSD_210924","side":"buy","seq":13501705,"price":32155.5,"qty":0.0,"timestamp":1626994933485}
1626994933.4614348: {"feed":"book","product_id":"FI_XBTUSD_210924","side":"sell","seq":13501706,"price":32269.5,"qty":0.0,"timestamp":1626994933485}
1626994933.461478: {"feed":"book","product_id":"PI_ETHUSD","side":"sell","seq":26661530,"price":2021.45,"qty":0.0,"timestamp":1626994933483}
1626994933.46151: {"feed":"book","product_id":"PI_ETHUSD","side":"sell","seq":26661531,"price":2021.45,"qty":67930.0,"timestamp":1626994933483}
1626994933.461539: {"feed":"book","product_id":"FI_XBTUSD_210924","side":"buy","seq":13501707,"price":32127.5,"qty":0.0,"timestamp":1626994933485}
1626994933.4615738: {"feed":"book","product_id":"PI_ETHUSD","side":"sell","seq":26661532,"price":2004.8,"qty":0.0,"timestamp":1626994933483}
1626994933.463176: {"feed":"book","product_id":"PI_ETHUSD","side":"sell","seq":26661533,"price":2005.95,"qty":52078.0,"timestamp":1626994933487}
1626994933.468765: {"feed":"book","product_id":"PI_ETHUSD","side":"sell","seq":26661534,"price":2008.15,"qty":4990.0,"timestamp":1626994933494}
1626994933.472179: {"feed":"book","product_id":"FI_XBTUSD_210924","side":"sell","seq":13501708,"price":32280.5,"qty":0.0,"timestamp":1626994933494}
1626994933.472285: {"feed":"book","product_id":"FI_XBTUSD_210924","side":"sell","seq":13501709,"price":32268.5,"qty":250001.0,"timestamp":1626994933494}
1626994933.472321: {"feed":"book","product_id":"PI_ETHUSD","side":"buy","seq":26661535,"price":1999.8,"qty":0.0,"timestamp":1626994933494}
1626994933.472352: {"feed":"book","product_id":"PI_ETHUSD","side":"buy","seq":26661536,"price":1999.6,"qty":503886.0,"timestamp":1626994933494}
1626994933.472373: {"feed":"book","product_id":"PI_ETHUSD","side":"sell","seq":26661537,"price":2006.35,"qty":0.0,"timestamp":1626994933494}
1626994933.472399: {"feed":"book","product_id":"FI_XBTUSD_210924","side":"buy","seq":13501710,"price":32180.0,"qty":0.0,"timestamp":1626994933494}
1626994933.472422: {"feed":"book","product_id":"FI_XBTUSD_210924","side":"buy","seq":13501711,"price":32175.5,"qty":3639.0,"timestamp":1626994933494}
1626994933.4724438: {"feed":"book","product_id":"FI_ETHUSD_211231","side":"sell","seq":2199013,"price":2038.7,"qty":0.0,"timestamp":1626994933494}
1626994933.472467: {"feed":"book","product_id":"FI_ETHUSD_211231","side":"sell","seq":2199014,"price":2041.65,"qty":250001.0,"timestamp":1626994933494}
1626994933.47607: {"feed":"book","product_id":"FI_XBTUSD_210924","side":"sell","seq":13501712,"price":32281.0,"qty":23267.0,"timestamp":1626994933498}
1626994933.4761448: {"feed":"book","product_id":"FI_XBTUSD_210924","side":"sell","seq":13501713,"price":32269.0,"qty":40962.0,"timestamp":1626994933498}
1626994933.478807: {"feed":"book","product_id":"PI_ETHUSD","side":"sell","seq":26661538,"price":2005.45,"qty":1.0,"timestamp":1626994933502}
1626994933.4789178: {"feed":"book","product_id":"PI_ETHUSD","side":"sell","seq":26661539,"price":2005.5,"qty":6263.0,"timestamp":1626994933503}
1626994933.4803069: {"feed":"book","product_id":"PI_ETHUSD","side":"sell","seq":26661540,"price":2005.9,"qty":6379.0,"timestamp":1626994933505}
1626994933.491106: {"feed":"book","product_id":"PI_ETHUSD","side":"buy","seq":26661541,"price":2000.5,"qty":98057.0,"timestamp":1626994933514}
1626994933.491213: {"feed":"book","product_id":"PI_ETHUSD","side":"buy","seq":26661542,"price":2001.0,"qty":125638.0,"timestamp":1626994933514}
1626994933.4912798: {"feed":"book","product_id":"PI_LTCUSD","side":"sell","seq":3423186,"price":119.58,"qty":31917.0,"timestamp":1626994933516}
1626994933.493868: {"feed":"book","product_id":"PI_LTCUSD","side":"sell","seq":3423187,"price":119.61,"qty":3869.0,"timestamp":1626994933517}
1626994933.493993: {"feed":"book","product_id":"PI_LTCUSD","side":"buy","seq":3423188,"price":119.32,"qty":7994.0,"timestamp":1626994933518}
1626994933.4940429: {"feed":"book","product_id":"PI_LTCUSD","side":"buy","seq":3423189,"price":119.28,"qty":33194.0,"timestamp":1626994933519}
1626994933.494793: {"feed":"book","product_id":"FI_BCHUSD_210730","side":"sell","seq":91197,"price":439.5,"qty":0.0,"timestamp":1626994933519}
1626994933.502501: {"feed":"book","product_id":"PI_ETHUSD","side":"buy","seq":26661543,"price":2000.75,"qty":0.0,"timestamp":1626994933524}
1626994933.5026371: {"feed":"book","product_id":"PI_ETHUSD","side":"buy","seq":26661544,"price":2001.3,"qty":150000.0,"timestamp":1626994933524}
1626994933.5027049: {"feed":"book","product_id":"FI_BCHUSD_210730","side":"sell","seq":91198,"price":439.9,"qty":0.0,"timestamp":1626994933525}
1626994933.5027578: {"feed":"book","product_id":"FI_XBTUSD_210730","side":"buy","seq":5160030,"price":32152.0,"qty":0.0,"timestamp":1626994933525}
1626994933.502806: {"feed":"book","product_id":"FI_XBTUSD_210730","side":"buy","seq":5160031,"price":32147.5,"qty":4688.0,"timestamp":1626994933525}
1626994933.50318: {"feed":"book","product_id":"PI_ETHUSD","side":"buy","seq":26661545,"price":2003.5,"qty":18046.0,"timestamp":1626994933527}
1626994933.505826: {"feed":"book","product_id":"FI_XBTUSD_210924","side":"buy","seq":13501714,"price":32176.5,"qty":0.0,"timestamp":1626994933530}
1626994933.508766: {"feed":"book","product_id":"FI_XBTUSD_210924","side":"sell","seq":13501715,"price":32240.0,"qty":0.0,"timestamp":1626994933530}
1626994933.508856: {"feed":"book","product_id":"PI_ETHUSD","side":"sell","seq":26661546,"price":2006.5,"qty":0.0,"timestamp":1626994933532}
1626994933.508899: {"feed":"book","product_id":"PI_ETHUSD","side":"sell","seq":26661547,"price":2006.3,"qty":19199.0,"timestamp":1626994933532}
1626994933.508929: {"feed":"book","product_id":"PI_ETHUSD","side":"sell","seq":26661548,"price":2007.25,"qty":3830.0,"timestamp":1626994933533}
1626994933.508961: {"feed":"book","product_id":"PI_ETHUSD","side":"sell","seq":26661549,"price":2006.85,"qty":8005.0,"timestamp":1626994933534}
1626994933.509364: {"feed":"book","product_id":"PI_ETHUSD","side":"sell","seq":26661550,"price":2005.8,"qty":8258.0,"timestamp":1626994933535}
1626994933.5094268: {"feed":"book","product_id":"FI_XBTUSD_210924","side":"sell","seq":13501716,"price":32245.0,"qty":0.0,"timestamp":1626994933536}
1626994933.510985: {"feed":"book","product_id":"FI_XBTUSD_210924","side":"buy","seq":13501717,"price":32152.5,"qty":0.0,"timestamp":1626994933536}
1626994933.511074: {"feed":"book","product_id":"FI_XBTUSD_210924","side":"sell","seq":13501718,"price":32281.0,"qty":2400.0,"timestamp":1626994933536}
1626994933.513002: {"feed":"book","product_id":"FI_XBTUSD_210924","side":"buy","seq":13501719,"price":32115.0,"qty":0.0,"timestamp":1626994933536}
1626994933.513091: {"feed":"book","product_id":"PI_ETHUSD","side":"buy","seq":26661551,"price":1988.85,"qty":0.0,"timestamp":1626994933536}
1626994933.5147479: {"feed":"book","product_id":"PI_ETHUSD","side":"sell","seq":26661552,"price":2006.0,"qty":0.0,"timestamp":1626994933538}
1626994933.514838: {"feed":"book","product_id":"PI_ETHUSD","side":"buy","seq":26661553,"price":2003.5,"qty":600.0,"timestamp":1626994933539}
1626994933.5148742: {"feed":"book","product_id":"PI_ETHUSD","side":"buy","seq":26661554,"price":2003.45,"qty":56762.0,"timestamp":1626994933539}
1626994933.514901: {"feed":"book","product_id":"PI_ETHUSD","side":"sell","seq":26661555,"price":2005.65,"qty":0.0,"timestamp":1626994933540}
1626994933.5193431: {"feed":"book","product_id":"PI_ETHUSD","side":"sell","seq":26661556,"price":2004.85,"qty":0.0,"timestamp":1626994933542}
1626994933.519467: {"feed":"book","product_id":"PI_ETHUSD","side":"sell","seq":26661557,"price":2005.15,"qty":600.0,"timestamp":1626994933542}
1626994933.519532: {"feed":"book","product_id":"PI_ETHUSD","side":"buy","seq":26661558,"price":2003.5,"qty":0.0,"timestamp":1626994933542}
1626994933.519586: {"feed":"book","product_id":"PI_ETHUSD","side":"buy","seq":26661559,"price":2003.85,"qty":600.0,"timestamp":1626994933542}
1626994933.5196319: {"feed":"book","product_id":"FI_ETHUSD_211231","side":"sell","seq":2199015,"price":2031.9,"qty":0.0,"timestamp":1626994933543}
1626994933.5196779: {"feed":"book","product_id":"FI_ETHUSD_211231","side":"sell","seq":2199016,"price":2032.5,"qty":420.0,"timestamp":1626994933543}
1626994933.521822: {"feed":"book","product_id":"FI_ETHUSD_210730","side":"sell","seq":2138705,"price":2003.0,"qty":0.0,"timestamp":1626994933544}
1626994933.5219479: {"feed":"book","product_id":"FI_ETHUSD_210730","side":"sell","seq":2138706,"price":2003.35,"qty":600.0,"timestamp":1626994933544}
1626994933.522013: {"feed":"book","product_id":"FI_ETHUSD_211231","side":"sell","seq":2199017,"price":2033.5,"qty":0.0,"timestamp":1626994933545}
1626994933.5220659: {"feed":"book","product_id":"FI_ETHUSD_211231","side":"sell","seq":2199018,"price":2034.1,"qty":10500.0,"timestamp":1626994933545}
1626994933.522112: {"feed":"book","product_id":"FI_ETHUSD_210730","side":"sell","seq":2138707,"price":2003.95,"qty":0.0,"timestamp":1626994933545}
1626994933.522157: {"feed":"book","product_id":"FI_ETHUSD_210730","side":"sell","seq":2138708,"price":2004.3,"qty":15000.0,"timestamp":1626994933545}
1626994933.526304: {"feed":"book","product_id":"FI_ETHUSD_210730","side":"buy","seq":2138709,"price":2000.25,"qty":0.0,"timestamp":1626994933546}
1626994933.526428: {"feed":"book","product_id":"FI_ETHUSD_210730","side":"buy","seq":2138710,"price":2000.85,"qty":117934.0,"timestamp":1626994933546}
1626994933.526483: {"feed":"book","product_id":"FI_ETHUSD_210730","side":"buy","seq":2138711,"price":1992.35,"qty":0.0,"timestamp":1626994933546}
1626994933.5265632: {"feed":"book","product_id":"FI_ETHUSD_210730","side":"buy","seq":2138712,"price":1994.7,"qty":60000.0,"timestamp":1626994933546}
1626994933.526597: {"feed":"book","product_id":"PI_ETHUSD","side":"buy","seq":26661560,"price":2003.45,"qty":39316.0,"timestamp":1626994933546}
1626994933.526622: {"feed":"book","product_id":"PI_ETHUSD","side":"sell","seq":26661561,"price":2007.05,"qty":0.0,"timestamp":1626994933547}
1626994933.5266528: {"feed":"book","product_id":"PI_ETHUSD","side":"sell","seq":26661562,"price":2008.2,"qty":30000.0,"timestamp":1626994933547}
1626994933.5266812: {"feed":"book","product_id":"PI_ETHUSD","side":"sell","seq":26661563,"price":2005.55,"qty":0.0,"timestamp":1626994933547}
1626994933.526709: {"feed":"book","product_id":"PI_ETHUSD","side":"sell","seq":26661564,"price":2005.9,"qty":21379.0,"timestamp":1626994933547}
1626994933.526731: {"feed":"book","product_id":"PI_ETHUSD","side":"buy","seq":26661565,"price":2002.8,"qty":95775.0,"timestamp":1626994933547}
1626994933.526753: {"feed":"book","product_id":"PI_ETHUSD","side":"buy","seq":26661566,"price":2003.15,"qty":15000.0,"timestamp":1626994933547}
1626994933.534143: {"feed":"book","product_id":"PI_ETHUSD","side":"buy","seq":26661567,"price":2002.5,"qty":0.0,"timestamp":1626994933558}
1626994933.534266: {"feed":"book","product_id":"PI_ETHUSD","side":"sell","seq":26661568,"price":2006.3,"qty":21699.0,"timestamp":1626994933558}
1626994933.5343192: {"feed":"book","product_id":"PI_ETHUSD","side":"sell","seq":26661569,"price":2005.8,"qty":3800.0,"timestamp":1626994933558}
1626994933.5713081: {"feed":"book","product_id":"FI_ETHUSD_210730","side":"sell","seq":2138713,"price":2014.65,"qty":0.0,"timestamp":1626994933594}
1626994933.571433: {"feed":"book","product_id":"FI_ETHUSD_210730","side":"sell","seq":2138714,"price":2014.55,"qty":45421.0,"timestamp":1626994933594}
1626994933.571498: {"feed":"book","product_id":"FI_ETHUSD_211231","side":"sell","seq":2199019,"price":2049.8,"qty":44305.0,"timestamp":1626994933594}
1626994933.571541: {"feed":"book","product_id":"FI_ETHUSD_211231","side":"sell","seq":2199020,"price":2049.7,"qty":45099.0,"timestamp":1626994933594}
1626994933.571584: {"feed":"book","product_id":"FI_ETHUSD_211231","side":"sell","seq":2199021,"price":2049.8,"qty":0.0,"timestamp":1626994933594}
1626994933.571628: {"feed":"book","product_id":"FI_ETHUSD_211231","side":"sell","seq":2199022,"price":2049.7,"qty":89404.0,"timestamp":1626994933594}
1626994933.5739179: {"feed":"book","product_id":"PI_LTCUSD","side":"sell","seq":3423190,"price":119.48,"qty":0.0,"timestamp":1626994933595}
1626994933.580248: {"feed":"book","product_id":"PI_ETHUSD","side":"buy","seq":26661570,"price":2002.75,"qty":5100.0,"timestamp":1626994933595}
1626994933.580381: {"feed":"book","product_id":"PI_ETHUSD","side":"sell","seq":26661571,"price":2005.8,"qty":8974.0,"timestamp":1626994933595}
1626994933.580435: {"feed":"book","product_id":"PI_ETHUSD","side":"buy","seq":26661572,"price":2000.35,"qty":0.0,"timestamp":1626994933597}
1626994933.580493: {"feed":"book","product_id":"PI_ETHUSD","side":"buy","seq":26661573,"price":2000.8,"qty":162519.0,"timestamp":1626994933597}
1626994933.58054: {"feed":"book","product_id":"PI_ETHUSD","side":"sell","seq":26661574,"price":2007.4,"qty":42541.0,"timestamp":1626994933598}
1626994933.5805728: {"feed":"book","product_id":"PI_ETHUSD","side":"sell","seq":26661575,"price":2008.7,"qty":13111.0,"timestamp":1626994933599}
1626994933.580605: {"feed":"book","product_id":"PI_LTCUSD","side":"buy","seq":3423191,"price":119.35,"qty":3929.0,"timestamp":1626994933599}
1626994933.580648: {"feed":"book","product_id":"PI_LTCUSD","side":"buy","seq":3423192,"price":119.33,"qty":0.0,"timestamp":1626994933600}
1626994933.580692: {"feed":"book","product_id":"PI_LTCUSD","side":"buy","seq":3423193,"price":119.23,"qty":1062.0,"timestamp":1626994933600}
1626994933.580725: {"feed":"book","product_id":"PI_LTCUSD","side":"buy","seq":3423194,"price":119.27,"qty":1000.0,"timestamp":1626994933600}
1626994933.5996659: {"feed":"book","product_id":"FI_BCHUSD_210730","side":"sell","seq":91199,"price":439.8,"qty":50.0,"timestamp":1626994933623}
1626994933.599786: {"feed":"book","product_id":"FI_ETHUSD_211231","side":"buy","seq":2199023,"price":2028.3,"qty":0.0,"timestamp":1626994933623}
1626994933.5998552: {"feed":"book","product_id":"FI_ETHUSD_211231","side":"buy","seq":2199024,"price":2028.95,"qty":50.0,"timestamp":1626994933623}
1626994933.6088479: {"feed":"book","product_id":"FI_XBTUSD_210924","side":"sell","seq":13501720,"price":32235.5,"qty":940.0,"timestamp":1626994933623}
1626994933.608962: {"feed":"book","product_id":"FI_XBTUSD_210924","side":"sell","seq":13501721,"price":32244.5,"qty":15316.0,"timestamp":1626994933623}
1626994933.609026: {"feed":"book","product_id":"PI_ETHUSD","side":"buy","seq":26661576,"price":2002.85,"qty":4077.0,"timestamp":1626994933624}
1626994933.609069: {"feed":"book","product_id":"FI_XBTUSD_210924","side":"buy","seq":13501722,"price":32172.0,"qty":0.0,"timestamp":1626994933623}
1626994933.6091242: {"feed":"book","product_id":"FI_XBTUSD_210924","side":"buy","seq":13501723,"price":32178.0,"qty":20910.0,"timestamp":1626994933623}
1626994933.609167: {"feed":"book","product_id":"FI_XBTUSD_210924","side":"buy","seq":13501724,"price":32188.5,"qty":881.0,"timestamp":1626994933623}
1626994933.609201: {"feed":"book","product_id":"FI_XBTUSD_210924","side":"buy","seq":13501725,"price":32188.5,"qty":19375.0,"timestamp":1626994933623}
1626994933.609232: {"feed":"book","product_id":"FI_XBTUSD_210924","side":"sell","seq":13501726,"price":32269.0,"qty":20000.0,"timestamp":1626994933623}
1626994933.6092632: {"feed":"book","product_id":"FI_XBTUSD_210924","side":"sell","seq":13501727,"price":32269.0,"qty":40967.0,"timestamp":1626994933623}
1626994933.6092942: {"feed":"book","product_id":"PI_ETHUSD","side":"buy","seq":26661577,"price":2003.55,"qty":17446.0,"timestamp":1626994933626}
1626994933.613143: {"feed":"book","product_id":"FI_ETHUSD_210730","side":"buy","seq":2138715,"price":2000.0,"qty":0.0,"timestamp":1626994933636}
1626994933.6132648: {"feed":"book","product_id":"FI_ETHUSD_210730","side":"buy","seq":2138716,"price":2000.95,"qty":50.0,"timestamp":1626994933636}
1626994933.613328: {"feed":"book","product_id":"PI_ETHUSD","side":"sell","seq":26661578,"price":2005.8,"qty":3800.0,"timestamp":1626994933637}
1626994933.617316: {"feed":"book","product_id":"PI_ETHUSD","side":"buy","seq":26661579,"price":2003.55,"qty":0.0,"timestamp":1626994933641}
1626994933.625473: {"feed":"book","product_id":"PI_ETHUSD","side":"buy","seq":26661580,"price":2003.55,"qty":17446.0,"timestamp":1626994933649}
1626994933.630789: {"feed":"book","product_id":"PI_XRPUSD","side":"buy","seq":3456210,"price":0.5875,"qty":2296.0,"timestamp":1626994933655}
1626994933.6389189: {"feed":"book","product_id":"FI_XBTUSD_210730","side":"buy","seq":5160032,"price":32112.5,"qty":2400.0,"timestamp":1626994933662}
1626994933.639028: {"feed":"book","product_id":"FI_XBTUSD_210730","side":"sell","seq":5160033,"price":32253.5,"qty":451.0,"timestamp":1626994933662}
1626994933.639092: {"feed":"book","product_id":"FI_XBTUSD_210730","side":"buy","seq":5160034,"price":32145.0,"qty":451.0,"timestamp":1626994933662}
1626994933.639148: {"feed":"book","product_id":"FI_XBTUSD_210730","side":"sell","seq":5160035,"price":32243.0,"qty":0.0,"timestamp":1626994933663}
1626994933.6420522: {"feed":"book","product_id":"PI_ETHUSD","side":"sell","seq":26661581,"price":2005.9,"qty":26451.0,"timestamp":1626994933665}
1626994933.645151: {"feed":"book","product_id":"PI_LTCUSD","side":"buy","seq":3423195,"price":119.12,"qty":5275.0,"timestamp":1626994933669}
1626994933.6452632: {"feed":"book","product_id":"PI_LTCUSD","side":"buy","seq":3423196,"price":119.24,"qty":5805.0,"timestamp":1626994933669}
1626994933.6476889: {"feed":"book","product_id":"FI_XBTUSD_210924","side":"sell","seq":13501728,"price":32265.0,"qty":0.0,"timestamp":1626994933672}
1626994933.6542022: {"feed":"book","product_id":"FI_XBTUSD_210924","side":"buy","seq":13501729,"price":32165.5,"qty":214781.0,"timestamp":1626994933677}
1626994933.654312: {"feed":"book","product_id":"FI_XBTUSD_210924","side":"sell","seq":13501730,"price":32251.5,"qty":3000.0,"timestamp":1626994933677}
1626994933.654377: {"feed":"book","product_id":"FI_XBTUSD_210924","side":"buy","seq":13501731,"price":32137.5,"qty":20865.0,"timestamp":1626994933677}
1626994933.654426: {"feed":"book","product_id":"FI_XBTUSD_210924","side":"sell","seq":13501732,"price":32279.5,"qty":16095.0,"timestamp":1626994933677}
1626994933.65611: {"feed":"book","product_id":"PI_ETHUSD","side":"sell","seq":26661582,"price":2006.3,"qty":19199.0,"timestamp":1626994933680}
1626994933.658807: {"feed":"book","product_id":"PI_ETHUSD","side":"sell","seq":26661583,"price":2005.95,"qty":0.0,"timestamp":1626994933683}
1626994933.6636438: {"feed":"book","product_id":"PI_ETHUSD","side":"buy","seq":26661584,"price":1995.3,"qty":0.0,"timestamp":1626994933687}
1626994933.663778: {"feed":"book","product_id":"PI_ETHUSD","side":"buy","seq":26661585,"price":1995.65,"qty":46674.0,"timestamp":1626994933687}
1626994933.663821: {"feed":"book","product_id":"PI_ETHUSD","side":"buy","seq":26661586,"price":2001.85,"qty":13718.0,"timestamp":1626994933687}
1626994933.663848: {"feed":"book","product_id":"PI_ETHUSD","side":"buy","seq":26661587,"price":2001.9,"qty":10994.0,"timestamp":1626994933687}
1626994933.663877: {"feed":"book","product_id":"PI_ETHUSD","side":"sell","seq":26661588,"price":2012.85,"qty":0.0,"timestamp":1626994933687}
1626994933.663908: {"feed":"book","product_id":"PI_ETHUSD","side":"sell","seq":26661589,"price":2012.75,"qty":48045.0,"timestamp":1626994933687}
1626994933.663935: {"feed":"book","product_id":"PI_ETHUSD","side":"sell","seq":26661590,"price":2006.25,"qty":0.0,"timestamp":1626994933687}
1626994933.6639621: {"feed":"book","product_id":"PI_ETHUSD","side":"sell","seq":26661591,"price":2006.25,"qty":11284.0,"timestamp":1626994933687}
1626994933.6639879: {"feed":"book","product_id":"PI_ETHUSD","side":"buy","seq":26661592,"price":2000.85,"qty":0.0,"timestamp":1626994933687}
1626994933.6640158: {"feed":"book","product_id":"PI_ETHUSD","side":"buy","seq":26661593,"price":2000.85,"qty":17449.0,"timestamp":1626994933687}
1626994933.664041: {"feed":"book","product_id":"PI_ETHUSD","side":"sell","seq":26661594,"price":2007.35,"qty":4164.0,"timestamp":1626994933687}
1626994933.664063: {"feed":"book","product_id":"PI_ETHUSD","side":"sell","seq":26661595,"price":2007.35,"qty":22491.0,"timestamp":1626994933687}
1626994933.664083: {"feed":"book","product_id":"PI_ETHUSD","side":"buy","seq":26661596,"price":2000.05,"qty":0.0,"timestamp":1626994933687}
1626994933.664109: {"feed":"book","product_id":"PI_ETHUSD","side":"buy","seq":26661597,"price":2000.05,"qty":23583.0,"timestamp":1626994933687}
1626994933.664133: {"feed":"book","product_id":"PI_ETHUSD","side":"sell","seq":26661598,"price":2008.35,"qty":0.0,"timestamp":1626994933687}
1626994933.66416: {"feed":"book","product_id":"PI_ETHUSD","side":"sell","seq":26661599,"price":2008.35,"qty":25359.0,"timestamp":1626994933687}
1626994933.664185: {"feed":"book","product_id":"PI_ETHUSD","side":"buy","seq":26661600,"price":1988.9,"qty":0.0,"timestamp":1626994933687}
1626994933.6642098: {"feed":"book","product_id":"PI_ETHUSD","side":"buy","seq":26661601,"price":1988.9,"qty":66934.0,"timestamp":1626994933687}
1626994933.664234: {"feed":"book","product_id":"PI_ETHUSD","side":"sell","seq":26661602,"price":2021.45,"qty":0.0,"timestamp":1626994933687}
1626994933.6642601: {"feed":"book","product_id":"PI_ETHUSD","side":"sell","seq":26661603,"price":2021.45,"qty":67931.0,"timestamp":1626994933687}
1626994933.672117: {"feed":"book","product_id":"FI_XBTUSD_210730","side":"buy","seq":5160036,"price":32091.5,"qty":0.0,"timestamp":1626994933693}
1626994933.6722088: {"feed":"book","product_id":"FI_XBTUSD_210730","side":"buy","seq":5160037,"price":32111.5,"qty":250001.0,"timestamp":1626994933693}
1626994933.67226: {"feed":"book","product_id":"FI_ETHUSD_211231","side":"sell","seq":2199025,"price":2049.75,"qty":0.0,"timestamp":1626994933693}
1626994933.672297: {"feed":"book","product_id":"FI_ETHUSD_211231","side":"sell","seq":2199026,"price":2049.65,"qty":250002.0,"timestamp":1626994933693}
1626994933.6723258: {"feed":"book","product_id":"FI_ETHUSD_210730","side":"buy","seq":2138717,"price":1989.75,"qty":0.0,"timestamp":1626994933693}
1626994933.6723561: {"feed":"book","product_id":"FI_ETHUSD_210730","side":"buy","seq":2138718,"price":1991.55,"qty":250002.0,"timestamp":1626994933693}
1626994933.6723819: {"feed":"book","product_id":"FI_ETHUSD_210730","side":"sell","seq":2138719,"price":2014.6,"qty":0.0,"timestamp":1626994933693}
1626994933.672409: {"feed":"book","product_id":"FI_ETHUSD_210730","side":"sell","seq":2138720,"price":2014.5,"qty":250002.0,"timestamp":1626994933693}
1626994933.672435: {"feed":"book","product_id":"FI_ETHUSD_211231","side":"sell","seq":2199027,"price":2036.25,"qty":0.0,"timestamp":1626994933695}
1626994933.67247: {"feed":"book","product_id":"FI_ETHUSD_211231","side":"sell","seq":2199028,"price":2036.85,"qty":167.0,"timestamp":1626994933695}
1626994933.6724968: {"feed":"book","product_id":"FI_ETHUSD_211231","side":"buy","seq":2199029,"price":2025.45,"qty":0.0,"timestamp":1626994933695}
1626994933.6725252: {"feed":"book","product_id":"FI_ETHUSD_211231","side":"buy","seq":2199030,"price":2028.0,"qty":167.0,"timestamp":1626994933695}
1626994933.67255: {"feed":"book","product_id":"PI_ETHUSD","side":"buy","seq":26661604,"price":2003.15,"qty":17500.0,"timestamp":1626994933696}
1626994933.672574: {"feed":"book","product_id":"PI_ETHUSD","side":"sell","seq":26661605,"price":2006.65,"qty":6692.0,"timestamp":1626994933696}
1626994933.682403: {"feed":"book","product_id":"FI_ETHUSD_211231","side":"buy","seq":2199031,"price":2026.2,"qty":0.0,"timestamp":1626994933707}
1626994933.689099: {"feed":"book","product_id":"PI_ETHUSD","side":"buy","seq":26661606,"price":1995.35,"qty":0.0,"timestamp":1626994933714}
1626994933.689227: {"feed":"book","product_id":"PI_ETHUSD","side":"buy","seq":26661607,"price":1995.7,"qty":500002.0,"timestamp":1626994933714}
1626994933.6892931: {"feed":"book","product_id":"FI_XBTUSD_210730","side":"buy","seq":5160038,"price":32111.5,"qty":0.0,"timestamp":1626994933714}
1626994933.68935: {"feed":"book","product_id":"FI_XBTUSD_210730","side":"buy","seq":5160039,"price":32091.5,"qty":250001.0,"timestamp":1626994933714}
1626994933.690335: {"feed":"book","product_id":"PI_ETHUSD","side":"sell","seq":26661608,"price":2012.8,"qty":0.0,"timestamp":1626994933714}
1626994933.6904588: {"feed":"book","product_id":"PI_ETHUSD","side":"sell","seq":26661609,"price":2012.7,"qty":500002.0,"timestamp":1626994933714}
1626994933.701463: {"feed":"book","product_id":"FI_ETHUSD_210730","side":"buy","seq":2138721,"price":1997.75,"qty":0.0,"timestamp":1626994933725}
1626994933.7015512: {"feed":"book","product_id":"FI_ETHUSD_210730","side":"buy","seq":2138722,"price":1999.9,"qty":325.0,"timestamp":1626994933726}
1626994933.7080262: {"feed":"book","product_id":"FI_XBTUSD_210730","side":"buy","seq":5160040,"price":32091.5,"qty":0.0,"timestamp":1626994933732}
1626994933.708149: {"feed":"book","product_id":"FI_XBTUSD_210730","side":"buy","seq":5160041,"price":32111.5,"qty":250001.0,"timestamp":1626994933732}
1626994933.718855: {"feed":"book","product_id":"FI_XBTUSD_210924","side":"buy","seq":13501733,"price":32182.5,"qty":3000.0,"timestamp":1626994933744}
1626994933.7193222: {"feed":"book","product_id":"PI_LTCUSD","side":"buy","seq":3423197,"price":119.22,"qty":32114.0,"timestamp":1626994933745}
1626994933.727077: {"feed":"book","product_id":"PI_LTCUSD","side":"sell","seq":3423198,"price":119.57,"qty":9432.0,"timestamp":1626994933750}
1626994933.734506: {"feed":"book","product_id":"PI_LTCUSD","side":"buy","seq":3423199,"price":119.34,"qty":28296.0,"timestamp":1626994933759}
1626994933.7346182: {"feed":"book","product_id":"PI_LTCUSD","side":"buy","seq":3423200,"price":119.35,"qty":4249.0,"timestamp":1626994933759}
1626994933.7385752: {"feed":"book","product_id":"FI_XBTUSD_210730","side":"buy","seq":5160042,"price":32124.0,"qty":0.0,"timestamp":1626994933763}
1626994933.738703: {"feed":"book","product_id":"FI_XBTUSD_210730","side":"buy","seq":5160043,"price":32123.5,"qty":1500.0,"timestamp":1626994933763}
1626994933.752768: {"feed":"book","product_id":"FI_XBTUSD_210730","side":"buy","seq":5160044,"price":32123.5,"qty":0.0,"timestamp":1626994933765}
1626994933.7528992: {"feed":"book","product_id":"FI_XBTUSD_210730","side":"buy","seq":5160045,"price":32126.0,"qty":1500.0,"timestamp":1626994933765}
1626994933.753272: {"feed":"book","product_id":"PI_LTCUSD","side":"sell","seq":3423201,"price":119.5,"qty":22310.0,"timestamp":1626994933774}
1626994933.753355: {"feed":"book","product_id":"FI_XBTUSD_210924","side":"buy","seq":13501734,"price":32144.5,"qty":0.0,"timestamp":1626994933771}
1626994933.7534149: {"feed":"book","product_id":"FI_XBTUSD_210924","side":"buy","seq":13501735,"price":32146.5,"qty":1500.0,"timestamp":1626994933771}
1626994933.75585: {"feed":"book","product_id":"PI_LTCUSD","side":"buy","seq":3423202,"price":119.27,"qty":0.0,"timestamp":1626994933780}
1626994933.755979: {"feed":"book","product_id":"PI_LTCUSD","side":"buy","seq":3423203,"price":119.24,"qty":6805.0,"timestamp":1626994933780}
1626994933.769482: {"feed":"book","product_id":"FI_XBTUSD_210730","side":"sell","seq":5160046,"price":32212.0,"qty":0.0,"timestamp":1626994933792}
1626994933.76961: {"feed":"book","product_id":"FI_XBTUSD_210730","side":"sell","seq":5160047,"price":32210.5,"qty":103.0,"timestamp":1626994933792}
1626994933.770129: {"feed":"book","product_id":"PI_ETHUSD","side":"buy","seq":26661610,"price":1996.45,"qty":0.0,"timestamp":1626994933795}
1626994933.7701912: {"feed":"book","product_id":"PI_ETHUSD","side":"buy","seq":26661611,"price":1999.15,"qty":0.0,"timestamp":1626994933795}
1626994933.770228: {"feed":"book","product_id":"PI_ETHUSD","side":"buy","seq":26661612,"price":2000.8,"qty":158400.0,"timestamp":1626994933796}
1626994933.770695: {"feed":"book","product_id":"PI_ETHUSD","side":"buy","seq":26661613,"price":2002.95,"qty":9414.0,"timestamp":1626994933796}
1626994933.773459: {"feed":"book","product_id":"PI_ETHUSD","side":"buy","seq":26661614,"price":2000.9,"qty":3996.0,"timestamp":1626994933797}
1626994933.773549: {"feed":"book","product_id":"PI_ETHUSD","side":"sell","seq":26661615,"price":2011.05,"qty":3840.0,"timestamp":1626994933797}
1626994933.7769752: {"feed":"book","product_id":"PI_ETHUSD","side":"sell","seq":26661616,"price":2006.6,"qty":3821.0,"timestamp":1626994933798}
1626994933.7771132: {"feed":"book","product_id":"PI_ETHUSD","side":"sell","seq":26661617,"price":2005.8,"qty":0.0,"timestamp":1626994933799}
1626994933.777157: {"feed":"book","product_id":"PI_ETHUSD","side":"sell","seq":26661618,"price":2008.1,"qty":4039.0,"timestamp":1626994933799}
1626994933.77719: {"feed":"book","product_id":"PI_ETHUSD","side":"sell","seq":26661619,"price":2009.0,"qty":3972.0,"timestamp":1626994933799}
1626994933.777217: {"feed":"book","product_id":"PI_ETHUSD","side":"buy","seq":26661620,"price":2003.35,"qty":0.0,"timestamp":1626994933801}
1626994933.77725: {"feed":"book","product_id":"PI_ETHUSD","side":"sell","seq":26661621,"price":2006.85,"qty":3822.0,"timestamp":1626994933801}
1626994933.7781172: {"feed":"book","product_id":"FI_ETHUSD_211231","side":"buy","seq":2199032,"price":2026.45,"qty":5000.0,"timestamp":1626994933802}
1626994933.7782028: {"feed":"book","product_id":"PI_ETHUSD","side":"sell","seq":26661622,"price":2007.2,"qty":0.0,"timestamp":1626994933802}
1626994933.779917: {"feed":"book","product_id":"PI_ETHUSD","side":"buy","seq":26661623,"price":1998.95,"qty":3890.0,"timestamp":1626994933805}
1626994933.780452: {"feed":"book","product_id":"PI_ETHUSD","side":"buy","seq":26661624,"price":2002.85,"qty":0.0,"timestamp":1626994933806}
1626994933.786191: {"feed":"book","product_id":"PI_ETHUSD","side":"buy","seq":26661625,"price":2002.4,"qty":0.0,"timestamp":1626994933808}
1626994933.786316: {"feed":"book","product_id":"PI_ETHUSD","side":"buy","seq":26661626,"price":2002.05,"qty":3883.0,"timestamp":1626994933810}
1626994933.795275: {"feed":"book","product_id":"PI_ETHUSD","side":"sell","seq":26661627,"price":2008.45,"qty":0.0,"timestamp":1626994933811}
1626994933.7954009: {"feed":"book","product_id":"PI_ETHUSD","side":"sell","seq":26661628,"price":2006.1,"qty":0.0,"timestamp":1626994933813}
1626994933.795462: {"feed":"book","product_id":"FI_XBTUSD_210924","side":"buy","seq":13501736,"price":32183.5,"qty":1900.0,"timestamp":1626994933811}
1626994933.7955232: {"feed":"book","product_id":"PI_ETHUSD","side":"buy","seq":26661629,"price":2003.35,"qty":3959.0,"timestamp":1626994933814}
1626994933.7955709: {"feed":"book","product_id":"FI_XBTUSD_210924","side":"sell","seq":13501737,"price":32245.5,"qty":2430.0,"timestamp":1626994933811}
1626994933.795639: {"feed":"book","product_id":"FI_XBTUSD_210924","side":"sell","seq":13501738,"price":32320.0,"qty":800.0,"timestamp":1626994933814}
1626994933.798286: {"feed":"book","product_id":"PI_ETHUSD","side":"sell","seq":26661630,"price":2009.1,"qty":0.0,"timestamp":1626994933822}
1626994933.798374: {"feed":"book","product_id":"PI_ETHUSD","side":"buy","seq":26661631,"price":2003.8,"qty":0.0,"timestamp":1626994933823}
1626994933.7984152: {"feed":"book","product_id":"PI_ETHUSD","side":"buy","seq":26661632,"price":2004.05,"qty":15826.0,"timestamp":1626994933823}
1626994933.79846: {"feed":"book","product_id":"PI_ETHUSD","side":"buy","seq":26661633,"price":2003.75,"qty":3878.0,"timestamp":1626994933824}
1626994933.798486: {"feed":"book","product_id":"PI_ETHUSD","side":"buy","seq":26661634,"price":2004.05,"qty":35826.0,"timestamp":1626994933824}
1626994933.7987452: {"feed":"book","product_id":"FI_ETHUSD_210730","side":"sell","seq":2138723,"price":2014.15,"qty":0.0,"timestamp":1626994933824}
1626994933.7995389: {"feed":"book","product_id":"PI_ETHUSD","side":"sell","seq":26661635,"price":2006.25,"qty":11346.0,"timestamp":1626994933825}
1626994933.799616: {"feed":"book","product_id":"PI_ETHUSD","side":"buy","seq":26661636,"price":1995.6,"qty":0.0,"timestamp":1626994933825}
1626994933.80269: {"feed":"book","product_id":"PI_ETHUSD","side":"buy","seq":26661637,"price":2002.35,"qty":62.0,"timestamp":1626994933826}
1626994933.802776: {"feed":"book","product_id":"FI_XBTUSD_210924","side":"sell","seq":13501739,"price":32269.0,"qty":20000.0,"timestamp":1626994933828}
1626994933.8028119: {"feed":"book","product_id":"FI_XBTUSD_210924","side":"sell","seq":13501740,"price":32268.0,"qty":20967.0,"timestamp":1626994933828}
1626994933.8028429: {"feed":"book","product_id":"FI_XBTUSD_210924","side":"sell","seq":13501741,"price":32244.5,"qty":0.0,"timestamp":1626994933828}
1626994933.802878: {"feed":"book","product_id":"FI_XBTUSD_210924","side":"sell","seq":13501742,"price":32244.5,"qty":15445.0,"timestamp":1626994933828}
1626994933.803784: {"feed":"book","product_id":"FI_XBTUSD_210924","side":"buy","seq":13501743,"price":32188.5,"qty":881.0,"timestamp":1626994933828}
1626994933.803859: {"feed":"book","product_id":"FI_XBTUSD_210924","side":"buy","seq":13501744,"price":32188.5,"qty":19246.0,"timestamp":1626994933828}
1626994933.805789: {"feed":"book","product_id":"PI_ETHUSD","side":"buy","seq":26661638,"price":2003.55,"qty":0.0,"timestamp":1626994933830}
1626994933.805876: {"feed":"book","product_id":"PI_ETHUSD","side":"buy","seq":26661639,"price":2003.6,"qty":17446.0,"timestamp":1626994933830}
1626994933.809039: {"feed":"book","product_id":"FI_BCHUSD_210924","side":"buy","seq":402233,"price":440.3,"qty":56.0,"timestamp":1626994933833}
1626994933.809124: {"feed":"book","product_id":"FI_XRPUSD_210924","side":"sell","seq":602282,"price":0.5876,"qty":0.0,"timestamp":1626994933832}
1626994933.8104792: {"feed":"book","product_id":"PI_ETHUSD","side":"sell","seq":26661640,"price":2009.05,"qty":0.0,"timestamp":1626994933834}
1626994933.810566: {"feed":"book","product_id":"PI_ETHUSD","side":"sell","seq":26661641,"price":2009.1,"qty":500001.0,"timestamp":1626994933834}
1626994933.812695: {"feed":"book","product_id":"PI_XRPUSD","side":"buy","seq":3456211,"price":0.588,"qty":8922.0,"timestamp":1626994933837}
1626994933.817312: {"feed":"book","product_id":"PI_ETHUSD","side":"sell","seq":26661642,"price":2005.15,"qty":0.0,"timestamp":1626994933839}
1626994933.817439: {"feed":"book","product_id":"PI_ETHUSD","side":"sell","seq":26661643,"price":2005.4,"qty":600.0,"timestamp":1626994933839}
1626994933.8175051: {"feed":"book","product_id":"PI_ETHUSD","side":"buy","seq":26661644,"price":2003.85,"qty":0.0,"timestamp":1626994933839}
1626994933.817585: {"feed":"book","product_id":"PI_ETHUSD","side":"buy","seq":26661645,"price":2004.05,"qty":36426.0,"timestamp":1626994933839}
1626994933.817611: {"feed":"book","product_id":"FI_ETHUSD_211231","side":"sell","seq":2199033,"price":2032.5,"qty":0.0,"timestamp":1626994933840}
1626994933.817641: {"feed":"book","product_id":"FI_ETHUSD_211231","side":"sell","seq":2199034,"price":2032.7,"qty":420.0,"timestamp":1626994933840}
1626994933.8176682: {"feed":"book","product_id":"FI_ETHUSD_210730","side":"sell","seq":2138724,"price":2003.35,"qty":0.0,"timestamp":1626994933840}
1626994933.817696: {"feed":"book","product_id":"FI_ETHUSD_210730","side":"sell","seq":2138725,"price":2003.55,"qty":600.0,"timestamp":1626994933840}
1626994933.8177228: {"feed":"book","product_id":"FI_ETHUSD_211231","side":"buy","seq":2199035,"price":2028.25,"qty":0.0,"timestamp":1626994933841}
1626994933.81775: {"feed":"book","product_id":"FI_ETHUSD_211231","side":"buy","seq":2199036,"price":2028.85,"qty":106840.0,"timestamp":1626994933841}
1626994933.821586: {"feed":"book","product_id":"FI_ETHUSD_210730","side":"buy","seq":2138726,"price":1996.9,"qty":0.0,"timestamp":1626994933842}
1626994933.8216891: {"feed":"book","product_id":"FI_ETHUSD_210730","side":"buy","seq":2138727,"price":1998.0,"qty":30000.0,"timestamp":1626994933842}
1626994933.8217332: {"feed":"book","product_id":"FI_ETHUSD_210730","side":"buy","seq":2138728,"price":2000.85,"qty":102934.0,"timestamp":1626994933842}
1626994933.8217611: {"feed":"book","product_id":"FI_ETHUSD_210730","side":"buy","seq":2138729,"price":2001.1,"qty":15000.0,"timestamp":1626994933842}
1626994933.8217878: {"feed":"book","product_id":"PI_ETHUSD","side":"buy","seq":26661646,"price":2000.25,"qty":62.0,"timestamp":1626994933843}
1626994933.821812: {"feed":"book","product_id":"PI_ETHUSD","side":"buy","seq":26661647,"price":2001.1,"qty":30000.0,"timestamp":1626994933843}
1626994933.821841: {"feed":"book","product_id":"FI_ETHUSD_210730","side":"sell","seq":2138730,"price":2008.4,"qty":0.0,"timestamp":1626994933842}
1626994933.821871: {"feed":"book","product_id":"FI_ETHUSD_210730","side":"sell","seq":2138731,"price":2010.65,"qty":60000.0,"timestamp":1626994933842}
1626994933.8219001: {"feed":"book","product_id":"PI_ETHUSD","side":"buy","seq":26661648,"price":2003.15,"qty":2500.0,"timestamp":1626994933843}
1626994933.821923: {"feed":"book","product_id":"PI_ETHUSD","side":"buy","seq":26661649,"price":2003.4,"qty":18844.0,"timestamp":1626994933843}
1626994933.821944: {"feed":"book","product_id":"PI_ETHUSD","side":"buy","seq":26661650,"price":1993.95,"qty":0.0,"timestamp":1626994933843}
1626994933.821971: {"feed":"book","product_id":"PI_ETHUSD","side":"buy","seq":26661651,"price":1996.45,"qty":120000.0,"timestamp":1626994933843}
1626994933.8219972: {"feed":"book","product_id":"FI_ETHUSD_210730","side":"sell","seq":2138732,"price":2009.15,"qty":233563.0,"timestamp":1626994933845}
1626994933.822022: {"feed":"book","product_id":"PI_ETHUSD","side":"buy","seq":26661652,"price":2002.1,"qty":0.0,"timestamp":1626994933845}
1626994933.823175: {"feed":"book","product_id":"PI_ETHUSD","side":"buy","seq":26661653,"price":2003.6,"qty":0.0,"timestamp":1626994933847}
1626994933.8232992: {"feed":"book","product_id":"FI_XBTUSD_210924","side":"sell","seq":13501745,"price":32235.0,"qty":0.0,"timestamp":1626994933847}
1626994933.823384: {"feed":"book","product_id":"FI_XBTUSD_210924","side":"sell","seq":13501746,"price":32233.0,"qty":103.0,"timestamp":1626994933847}
1626994933.8252249: {"feed":"book","product_id":"PI_ETHUSD","side":"sell","seq":26661654,"price":2006.95,"qty":100.0,"timestamp":1626994933850}
1626994933.829609: {"feed":"book","product_id":"PI_ETHUSD","side":"buy","seq":26661655,"price":2002.75,"qty":0.0,"timestamp":1626994933853}
1626994933.8297338: {"feed":"book","product_id":"FI_XBTUSD_210730","side":"buy","seq":5160048,"price":32126.0,"qty":0.0,"timestamp":1626994933853}
1626994933.829797: {"feed":"book","product_id":"FI_XBTUSD_210730","side":"buy","seq":5160049,"price":32128.5,"qty":2047.0,"timestamp":1626994933853}
1626994933.829841: {"feed":"book","product_id":"PI_ETHUSD","side":"sell","seq":26661656,"price":2005.9,"qty":21379.0,"timestamp":1626994933855}
1626994933.833788: {"feed":"book","product_id":"FI_XBTUSD_210924","side":"buy","seq":13501747,"price":32146.5,"qty":0.0,"timestamp":1626994933858}
1626994933.833914: {"feed":"book","product_id":"FI_XBTUSD_210924","side":"buy","seq":13501748,"price":32149.0,"qty":1500.0,"timestamp":1626994933858}
1626994933.8339798: {"feed":"book","product_id":"PI_ETHUSD","side":"buy","seq":26661657,"price":2002.6,"qty":0.0,"timestamp":1626994933858}
1626994933.8379478: {"feed":"book","product_id":"PI_ETHUSD","side":"buy","seq":26661658,"price":2001.0,"qty":0.0,"timestamp":1626994933861}
1626994933.8380742: {"feed":"book","product_id":"PI_ETHUSD","side":"buy","seq":26661659,"price":2001.45,"qty":125638.0,"timestamp":1626994933861}
1626994933.838636: {"feed":"book","product_id":"FI_ETHUSD_210730","side":"buy","seq":2138733,"price":1996.95,"qty":0.0,"timestamp":1626994933864}
1626994933.838696: {"feed":"book","product_id":"FI_ETHUSD_210730","side":"buy","seq":2138734,"price":1996.65,"qty":250001.0,"timestamp":1626994933864}
1626994933.8387341: {"feed":"book","product_id":"FI_XBTUSD_210924","side":"buy","seq":13501749,"price":32130.0,"qty":0.0,"timestamp":1626994933864}
1626994933.838767: {"feed":"book","product_id":"FI_XBTUSD_210924","side":"buy","seq":13501750,"price":32138.0,"qty":250001.0,"timestamp":1626994933864}
1626994933.838795: {"feed":"book","product_id":"FI_XBTUSD_210924","side":"sell","seq":13501751,"price":32268.5,"qty":0.0,"timestamp":1626994933864}
1626994933.838824: {"feed":"book","product_id":"FI_XBTUSD_210924","side":"sell","seq":13501752,"price":32267.5,"qty":250001.0,"timestamp":1626994933864}
1626994933.83885: {"feed":"book","product_id":"FI_ETHUSD_210730","side":"sell","seq":2138735,"price":2011.3,"qty":0.0,"timestamp":1626994933864}
1626994933.838878: {"feed":"book","product_id":"FI_ETHUSD_210730","side":"sell","seq":2138736,"price":2010.6,"qty":250001.0,"timestamp":1626994933864}
1626994933.842278: {"feed":"book","product_id":"PI_ETHUSD","side":"buy","seq":26661660,"price":2002.6,"qty":5000.0,"timestamp":1626994933866}
1626994933.845932: {"feed":"book","product_id":"PI_ETHUSD","side":"buy","seq":26661661,"price":1999.85,"qty":0.0,"timestamp":1626994933869}
1626994933.846055: {"feed":"book","product_id":"FI_ETHUSD_210730","side":"buy","seq":2138737,"price":2000.95,"qty":0.0,"timestamp":1626994933869}
1626994933.846117: {"feed":"book","product_id":"FI_ETHUSD_210730","side":"buy","seq":2138738,"price":2001.15,"qty":50.0,"timestamp":1626994933869}
1626994933.847906: {"feed":"book","product_id":"PI_ETHUSD","side":"buy","seq":26661662,"price":2003.6,"qty":17446.0,"timestamp":1626994933871}
1626994933.85119: {"feed":"book","product_id":"FI_XBTUSD_210924","side":"sell","seq":13501753,"price":32269.0,"qty":0.0,"timestamp":1626994933876}
1626994933.8513138: {"feed":"book","product_id":"FI_XBTUSD_210924","side":"sell","seq":13501754,"price":32268.0,"qty":40967.0,"timestamp":1626994933876}
1626994933.861879: {"feed":"book","product_id":"PI_ETHUSD","side":"sell","seq":26661663,"price":2007.0,"qty":0.0,"timestamp":1626994933885}
1626994933.8651571: {"feed":"book","product_id":"FI_XBTUSD_210730","side":"buy","seq":5160050,"price":32128.5,"qty":547.0,"timestamp":1626994933887}
1626994933.8652868: {"feed":"book","product_id":"FI_XBTUSD_210730","side":"buy","seq":5160051,"price":32130.5,"qty":1500.0,"timestamp":1626994933887}
1626994933.8676102: {"feed":"book","product_id":"PI_ETHUSD","side":"sell","seq":26661664,"price":2007.75,"qty":175154.0,"timestamp":1626994933891}
1626994933.86772: {"feed":"book","product_id":"PI_ETHUSD","side":"sell","seq":26661665,"price":2008.2,"qty":180000.0,"timestamp":1626994933891}
1626994933.8677702: {"feed":"book","product_id":"FI_XBTUSD_210924","side":"buy","seq":13501755,"price":32149.0,"qty":0.0,"timestamp":1626994933890}
1626994933.8678641: {"feed":"book","product_id":"FI_XBTUSD_210924","side":"buy","seq":13501756,"price":32151.0,"qty":1500.0,"timestamp":1626994933890}
1626994933.867899: {"feed":"book","product_id":"PI_ETHUSD","side":"buy","seq":26661666,"price":1988.9,"qty":0.0,"timestamp":1626994933891}
1626994933.8679318: {"feed":"book","product_id":"PI_ETHUSD","side":"buy","seq":26661667,"price":1985.1,"qty":66941.0,"timestamp":1626994933891}
1626994933.86796: {"feed":"book","product_id":"FI_XBTUSD_210924","side":"sell","seq":13501757,"price":32260.0,"qty":5000.0,"timestamp":1626994933891}
1626994933.867987: {"feed":"book","product_id":"PI_ETHUSD","side":"sell","seq":26661668,"price":2006.25,"qty":62.0,"timestamp":1626994933891}
1626994933.86801: {"feed":"book","product_id":"PI_ETHUSD","side":"sell","seq":26661669,"price":2006.35,"qty":10663.0,"timestamp":1626994933891}
1626994933.868036: {"feed":"book","product_id":"PI_ETHUSD","side":"buy","seq":26661670,"price":2000.85,"qty":0.0,"timestamp":1626994933891}
1626994933.868066: {"feed":"book","product_id":"PI_ETHUSD","side":"buy","seq":26661671,"price":2001.05,"qty":17536.0,"timestamp":1626994933891}
1626994933.869568: {"feed":"book","product_id":"PI_ETHUSD","side":"buy","seq":26661672,"price":2000.05,"qty":0.0,"timestamp":1626994933891}
1626994933.8696551: {"feed":"book","product_id":"PI_ETHUSD","side":"buy","seq":26661673,"price":2000.3,"qty":23362.0,"timestamp":1626994933891}
1626994933.869698: {"feed":"book","product_id":"PI_ETHUSD","side":"sell","seq":26661674,"price":2008.35,"qty":0.0,"timestamp":1626994933891}
1626994933.8697338: {"feed":"book","product_id":"PI_ETHUSD","side":"sell","seq":26661675,"price":2008.15,"qty":28033.0,"timestamp":1626994933891}
1626994933.86976: {"feed":"book","product_id":"PI_ETHUSD","side":"sell","seq":26661676,"price":2007.35,"qty":4164.0,"timestamp":1626994933891}
1626994933.869783: {"feed":"book","product_id":"PI_ETHUSD","side":"sell","seq":26661677,"price":2007.35,"qty":20715.0,"timestamp":1626994933891}
1626994933.8698041: {"feed":"book","product_id":"PI_ETHUSD","side":"buy","seq":26661678,"price":2001.9,"qty":0.0,"timestamp":1626994933891}
1626994933.8698308: {"feed":"book","product_id":"PI_ETHUSD","side":"buy","seq":26661679,"price":2001.9,"qty":12171.0,"timestamp":1626994933891}
1626994933.869857: {"feed":"book","product_id":"PI_ETHUSD","side":"sell","seq":26661680,"price":2012.75,"qty":0.0,"timestamp":1626994933891}
1626994933.8698938: {"feed":"book","product_id":"PI_ETHUSD","side":"sell","seq":26661681,"price":2012.75,"qty":47363.0,"timestamp":1626994933891}
1626994933.869921: {"feed":"book","product_id":"FI_XBTUSD_210924","side":"sell","seq":13501758,"price":32267.5,"qty":0.0,"timestamp":1626994933893}
1626994933.869963: {"feed":"book","product_id":"FI_XBTUSD_210924","side":"sell","seq":13501759,"price":32281.5,"qty":250001.0,"timestamp":1626994933893}
1626994933.869992: {"feed":"book","product_id":"PI_ETHUSD","side":"buy","seq":26661682,"price":1995.65,"qty":0.0,"timestamp":1626994933891}
1626994933.8700202: {"feed":"book","product_id":"PI_ETHUSD","side":"buy","seq":26661683,"price":1995.65,"qty":47340.0,"timestamp":1626994933891}
1626994933.870045: {"feed":"book","product_id":"PI_ETHUSD","side":"sell","seq":26661684,"price":2021.45,"qty":0.0,"timestamp":1626994933891}
1626994933.870071: {"feed":"book","product_id":"PI_ETHUSD","side":"sell","seq":26661685,"price":2021.45,"qty":67938.0,"timestamp":1626994933891}
1626994933.872577: {"feed":"book","product_id":"PI_ETHUSD","side":"buy","seq":26661686,"price":2003.75,"qty":0.0,"timestamp":1626994933896}
1626994933.872663: {"feed":"book","product_id":"PI_ETHUSD","side":"sell","seq":26661687,"price":2007.35,"qty":16551.0,"timestamp":1626994933897}
1626994933.873672: {"feed":"book","product_id":"PI_ETHUSD","side":"sell","seq":26661688,"price":2007.7,"qty":4594.0,"timestamp":1626994933898}
1626994933.873746: {"feed":"book","product_id":"PI_ETHUSD","side":"sell","seq":26661689,"price":2006.65,"qty":2500.0,"timestamp":1626994933898}
1626994933.873779: {"feed":"book","product_id":"FI_XBTUSD_210730","side":"buy","seq":5160052,"price":32130.5,"qty":0.0,"timestamp":1626994933898}
1626994933.8738198: {"feed":"book","product_id":"FI_XBTUSD_210730","side":"buy","seq":5160053,"price":32129.0,"qty":1500.0,"timestamp":1626994933898}
1626994933.873852: {"feed":"book","product_id":"PI_ETHUSD","side":"sell","seq":26661690,"price":2008.2,"qty":183894.0,"timestamp":1626994933898}
1626994933.8744361: {"feed":"book","product_id":"FI_XBTUSD_210924","side":"sell","seq":13501760,"price":32268.0,"qty":20967.0,"timestamp":1626994933898}
1626994933.8744938: {"feed":"book","product_id":"FI_XBTUSD_210924","side":"sell","seq":13501761,"price":32282.0,"qty":166559.0,"timestamp":1626994933898}
1626994933.874527: {"feed":"book","product_id":"FI_XBTUSD_210924","side":"buy","seq":13501762,"price":32151.0,"qty":0.0,"timestamp":1626994933899}
1626994933.874579: {"feed":"book","product_id":"FI_XBTUSD_210924","side":"buy","seq":13501763,"price":32150.0,"qty":1500.0,"timestamp":1626994933899}
1626994933.874613: {"feed":"book","product_id":"PI_ETHUSD","side":"sell","seq":26661691,"price":2009.45,"qty":4092.0,"timestamp":1626994933900}
1626994933.874651: {"feed":"book","product_id":"PI_ETHUSD","side":"buy","seq":26661692,"price":2003.85,"qty":4162.0,"timestamp":1626994933900}
1626994933.874681: {"feed":"book","product_id":"PI_ETHUSD","side":"sell","seq":26661693,"price":2008.75,"qty":4989.0,"timestamp":1626994933900}
1626994933.876151: {"feed":"book","product_id":"PI_ETHUSD","side":"sell","seq":26661694,"price":2007.15,"qty":8306.0,"timestamp":1626994933901}
1626994933.8762329: {"feed":"book","product_id":"PI_ETHUSD","side":"buy","seq":26661695,"price":1999.6,"qty":500001.0,"timestamp":1626994933901}
1626994933.876266: {"feed":"book","product_id":"PI_ETHUSD","side":"sell","seq":26661696,"price":2006.3,"qty":0.0,"timestamp":1626994933901}
1626994933.876555: {"feed":"book","product_id":"PI_ETHUSD","side":"buy","seq":26661697,"price":1999.25,"qty":8775.0,"timestamp":1626994933902}
1626994933.8766: {"feed":"book","product_id":"PI_ETHUSD","side":"buy","seq":26661698,"price":2003.4,"qty":15000.0,"timestamp":1626994933902}
1626994933.879067: {"feed":"book","product_id":"PI_ETHUSD","side":"buy","seq":26661699,"price":2001.35,"qty":4054.0,"timestamp":1626994933903}
1626994933.8791308: {"feed":"book","product_id":"PI_ETHUSD","side":"sell","seq":26661700,"price":2006.05,"qty":0.0,"timestamp":1626994933905}
1626994933.8814669: {"feed":"book","product_id":"PI_ETHUSD","side":"sell","seq":26661701,"price":2008.4,"qty":0.0,"timestamp":1626994933906}
1626994933.881554: {"feed":"book","product_id":"PI_ETHUSD","side":"sell","seq":26661702,"price":2008.95,"qty":150000.0,"timestamp":1626994933906}
1626994933.884964: {"feed":"book","product_id":"PI_ETHUSD","side":"buy","seq":26661703,"price":2003.6,"qty":0.0,"timestamp":1626994933909}
1626994933.885089: {"feed":"book","product_id":"PI_ETHUSD","side":"buy","seq":26661704,"price":2003.65,"qty":17446.0,"timestamp":1626994933909}
1626994933.890871: {"feed":"book","product_id":"FI_XBTUSD_210924","side":"buy","seq":13501764,"price":32112.5,"qty":0.0,"timestamp":1626994933915}
1626994933.911362: {"feed":"book","product_id":"PI_ETHUSD","side":"sell","seq":26661705,"price":2006.25,"qty":4699.0,"timestamp":1626994933935}
1626994933.911472: {"feed":"book","product_id":"PI_ETHUSD","side":"buy","seq":26661706,"price":2003.05,"qty":6201.0,"timestamp":1626994933936}
1626994933.911523: {"feed":"book","product_id":"PI_ETHUSD","side":"buy","seq":26661707,"price":2003.15,"qty":0.0,"timestamp":1626994933936}
1626994933.9218838: {"feed":"book","product_id":"PI_ETHUSD","side":"sell","seq":26661708,"price":2010.3,"qty":234767.0,"timestamp":1626994933946}
1626994933.927691: {"feed":"book","product_id":"PI_ETHUSD","side":"sell","seq":26661709,"price":2009.1,"qty":0.0,"timestamp":1626994933951}
1626994933.927816: {"feed":"book","product_id":"PI_ETHUSD","side":"sell","seq":26661710,"price":2008.9,"qty":500001.0,"timestamp":1626994933951}
1626994933.933154: {"feed":"book","product_id":"PI_ETHUSD","side":"buy","seq":26661711,"price":2003.05,"qty":1312.0,"timestamp":1626994933957}
1626994933.9694989: {"feed":"book","product_id":"PI_ETHUSD","side":"sell","seq":26661712,"price":2006.65,"qty":0.0,"timestamp":1626994933990}
1626994933.973566: {"feed":"book","product_id":"PI_ETHUSD","side":"buy","seq":26661713,"price":2000.8,"qty":8400.0,"timestamp":1626994933994}
1626994933.973674: {"feed":"book","product_id":"PI_ETHUSD","side":"buy","seq":26661714,"price":2001.25,"qty":155068.0,"timestamp":1626994933994}
1626994933.97514: {"feed":"book","product_id":"PI_LTCUSD","side":"sell","seq":3423204,"price":119.58,"qty":27737.0,"timestamp":1626994933998}
1626994933.9752471: {"feed":"book","product_id":"PI_LTCUSD","side":"sell","seq":3423205,"price":119.61,"qty":8044.0,"timestamp":1626994934000}
1626994933.9752982: {"feed":"book","product_id":"PI_ETHUSD","side":"buy","seq":26661715,"price":2003.1,"qty":0.0,"timestamp":1626994934000}
1626994933.981001: {"feed":"book","product_id":"PI_ETHUSD","side":"buy","seq":26661716,"price":2003.65,"qty":21312.0,"timestamp":1626994934004}
1626994933.9811141: {"feed":"book","product_id":"PI_ETHUSD","side":"sell","seq":26661717,"price":2007.7,"qty":8742.0,"timestamp":1626994934006}
1626994933.981556: {"feed":"book","product_id":"PI_ETHUSD","side":"sell","seq":26661718,"price":2007.15,"qty":4174.0,"timestamp":1626994934006}
1626994933.984309: {"feed":"book","product_id":"FI_ETHUSD_210730","side":"buy","seq":2138739,"price":1991.5,"qty":0.0,"timestamp":1626994934008}
1626994933.984434: {"feed":"book","product_id":"FI_ETHUSD_210730","side":"buy","seq":2138740,"price":1991.6,"qty":44704.0,"timestamp":1626994934008}
1626994933.984499: {"feed":"book","product_id":"FI_ETHUSD_211231","side":"sell","seq":2199037,"price":2049.7,"qty":44305.0,"timestamp":1626994934008}
1626994933.984572: {"feed":"book","product_id":"FI_ETHUSD_211231","side":"sell","seq":2199038,"price":2049.6,"qty":45099.0,"timestamp":1626994934008}
1626994933.984603: {"feed":"book","product_id":"FI_ETHUSD_210730","side":"sell","seq":2138741,"price":2014.55,"qty":0.0,"timestamp":1626994934008}
1626994933.9846349: {"feed":"book","product_id":"FI_ETHUSD_210730","side":"sell","seq":2138742,"price":2014.45,"qty":45421.0,"timestamp":1626994934008}
1626994933.984663: {"feed":"book","product_id":"FI_ETHUSD_211231","side":"sell","seq":2199039,"price":2049.7,"qty":0.0,"timestamp":1626994934008}
1626994933.98469: {"feed":"book","product_id":"FI_ETHUSD_211231","side":"sell","seq":2199040,"price":2049.6,"qty":89404.0,"timestamp":1626994934008}
1626994933.9850209: {"feed":"book","product_id":"PI_ETHUSD","side":"buy","seq":26661719,"price":2003.4,"qty":17500.0,"timestamp":1626994934009}
1626994933.9850628: {"feed":"book","product_id":"PI_ETHUSD","side":"sell","seq":26661720,"price":2007.05,"qty":2500.0,"timestamp":1626994934009}
1626994933.985098: {"feed":"book","product_id":"PI_ETHUSD","side":"buy","seq":26661721,"price":2002.9,"qty":0.0,"timestamp":1626994934010}
1626994933.98704: {"feed":"book","product_id":"PI_ETHUSD","side":"sell","seq":26661722,"price":2007.5,"qty":5000.0,"timestamp":1626994934012}
1626994933.987582: {"feed":"book","product_id":"PI_ETHUSD","side":"buy","seq":26661723,"price":2001.05,"qty":25036.0,"timestamp":1626994934013}
1626994933.9904141: {"feed":"book","product_id":"PI_ETHUSD","side":"buy","seq":26661724,"price":2003.45,"qty":0.0,"timestamp":1626994934015}
1626994934.007723: {"feed":"book","product_id":"FI_XBTUSD_210924","side":"sell","seq":13501765,"price":32244.5,"qty":0.0,"timestamp":1626994934031}
1626994934.0078459: {"feed":"book","product_id":"FI_XBTUSD_210924","side":"sell","seq":13501766,"price":32258.5,"qty":18939.0,"timestamp":1626994934031}
1626994934.0120351: {"feed":"book","product_id":"FI_XBTUSD_210924","side":"sell","seq":13501767,"price":32225.0,"qty":0.0,"timestamp":1626994934035}
1626994934.012168: {"feed":"book","product_id":"FI_XBTUSD_210924","side":"sell","seq":13501768,"price":32229.0,"qty":1009.0,"timestamp":1626994934035}
1626994934.012234: {"feed":"book","product_id":"FI_XBTUSD_210730","side":"sell","seq":5160054,"price":32197.0,"qty":0.0,"timestamp":1626994934036}
1626994934.0122838: {"feed":"book","product_id":"FI_XBTUSD_210730","side":"sell","seq":5160055,"price":32201.0,"qty":1200.0,"timestamp":1626994934036}
1626994934.012335: {"feed":"book","product_id":"FI_ETHUSD_210730","side":"sell","seq":2138743,"price":2015.3,"qty":29546.0,"timestamp":1626994934036}
1626994934.015007: {"feed":"book","product_id":"FI_XBTUSD_210924","side":"sell","seq":13501769,"price":32238.0,"qty":0.0,"timestamp":1626994934037}
1626994934.015056: {"feed":"book","product_id":"FI_XBTUSD_210924","side":"sell","seq":13501770,"price":32246.5,"qty":27000.0,"timestamp":1626994934037}
1626994934.015088: {"feed":"book","product_id":"FI_XBTUSD_210730","side":"sell","seq":5160056,"price":32206.5,"qty":0.0,"timestamp":1626994934038}
1626994934.015114: {"feed":"book","product_id":"FI_XBTUSD_210730","side":"sell","seq":5160057,"price":32215.0,"qty":30000.0,"timestamp":1626994934038}
1626994934.015137: {"feed":"book","product_id":"FI_XBTUSD_210924","side":"buy","seq":13501771,"price":32177.5,"qty":0.0,"timestamp":1626994934037}
1626994934.015161: {"feed":"book","product_id":"FI_XBTUSD_210924","side":"buy","seq":13501772,"price":32185.5,"qty":27000.0,"timestamp":1626994934037}
1626994934.015182: {"feed":"book","product_id":"FI_XBTUSD_210924","side":"sell","seq":13501773,"price":32321.5,"qty":0.0,"timestamp":1626994934037}
1626994934.015203: {"feed":"book","product_id":"FI_XBTUSD_210924","side":"sell","seq":13501774,"price":32359.5,"qty":108000.0,"timestamp":1626994934037}
1626994934.015223: {"feed":"book","product_id":"FI_XBTUSD_210924","side":"buy","seq":13501775,"price":32150.0,"qty":0.0,"timestamp":1626994934040}
1626994934.015244: {"feed":"book","product_id":"FI_XBTUSD_210924","side":"buy","seq":13501776,"price":32149.5,"qty":1500.0,"timestamp":1626994934040}
1626994934.023472: {"feed":"book","product_id":"PI_ETHUSD","side":"sell","seq":26661725,"price":2007.4,"qty":0.0,"timestamp":1626994934048}
1626994934.0235982: {"feed":"book","product_id":"PI_ETHUSD","side":"sell","seq":26661726,"price":2008.0,"qty":42541.0,"timestamp":1626994934048}
1626994934.033422: {"feed":"book","product_id":"FI_XBTUSD_210924","side":"sell","seq":13501777,"price":32281.0,"qty":0.0,"timestamp":1626994934057}
1626994934.0335512: {"feed":"book","product_id":"FI_XBTUSD_210924","side":"sell","seq":13501778,"price":32300.0,"qty":5400.0,"timestamp":1626994934057}
1626994934.0336058: {"feed":"book","product_id":"FI_XBTUSD_210924","side":"sell","seq":13501779,"price":32320.0,"qty":0.0,"timestamp":1626994934057}
1626994934.0336561: {"feed":"book","product_id":"FI_XBTUSD_210924","side":"sell","seq":13501780,"price":32338.0,"qty":3800.0,"timestamp":1626994934057}
1626994934.0337229: {"feed":"book","product_id":"FI_XBTUSD_210924","side":"sell","seq":13501781,"price":32298.0,"qty":16095.0,"timestamp":1626994934057}
1626994934.0337632: {"feed":"book","product_id":"FI_XBTUSD_210924","side":"sell","seq":13501782,"price":32316.0,"qty":9400.0,"timestamp":1626994934057}
1626994934.0406349: {"feed":"book","product_id":"PI_ETHUSD","side":"buy","seq":26661727,"price":2003.3,"qty":4963.0,"timestamp":1626994934065}
1626994934.040726: {"feed":"book","product_id":"FI_XBTUSD_210924","side":"sell","seq":13501783,"price":32311.5,"qty":0.0,"timestamp":1626994934065}
1626994934.0407722: {"feed":"book","product_id":"FI_XBTUSD_210924","side":"sell","seq":13501784,"price":32309.0,"qty":0.0,"timestamp":1626994934065}
1626994934.0439: {"feed":"book","product_id":"FI_XBTUSD_210924","side":"sell","seq":13501785,"price":32329.5,"qty":24904.0,"timestamp":1626994934068}
1626994934.043987: {"feed":"book","product_id":"FI_XBTUSD_210924","side":"sell","seq":13501786,"price":32327.0,"qty":24906.0,"timestamp":1626994934068}
1626994934.056415: {"feed":"book","product_id":"PI_LTCUSD","side":"buy","seq":3423206,"price":119.33,"qty":4060.0,"timestamp":1626994934081}
1626994934.074645: {"feed":"book","product_id":"PI_ETHUSD","side":"sell","seq":26661728,"price":2006.35,"qty":0.0,"timestamp":1626994934096}
1626994934.0747352: {"feed":"book","product_id":"PI_ETHUSD","side":"sell","seq":26661729,"price":2007.35,"qty":32160.0,"timestamp":1626994934096}
1626994934.074772: {"feed":"book","product_id":"PI_ETHUSD","side":"sell","seq":26661730,"price":2007.35,"qty":15609.0,"timestamp":1626994934096}
1626994934.0747972: {"feed":"book","product_id":"PI_ETHUSD","side":"sell","seq":26661731,"price":2007.7,"qty":27229.0,"timestamp":1626994934096}
1626994934.074819: {"feed":"book","product_id":"PI_ETHUSD","side":"sell","seq":26661732,"price":2008.15,"qty":4990.0,"timestamp":1626994934096}
1626994934.074841: {"feed":"book","product_id":"PI_ETHUSD","side":"sell","seq":26661733,"price":2008.35,"qty":23492.0,"timestamp":1626994934096}
1626994934.07487: {"feed":"book","product_id":"PI_ETHUSD","side":"buy","seq":26661734,"price":2001.05,"qty":7500.0,"timestamp":1626994934096}
1626994934.074893: {"feed":"book","product_id":"PI_ETHUSD","side":"buy","seq":26661735,"price":2001.35,"qty":20083.0,"timestamp":1626994934096}
1626994934.074913: {"feed":"book","product_id":"PI_ETHUSD","side":"buy","seq":26661736,"price":2000.3,"qty":0.0,"timestamp":1626994934096}
1626994934.0749419: {"feed":"book","product_id":"PI_ETHUSD","side":"buy","seq":26661737,"price":2000.55,"qty":22640.0,"timestamp":1626994934096}
1626994934.074969: {"feed":"book","product_id":"PI_ETHUSD","side":"sell","seq":26661738,"price":2012.75,"qty":0.0,"timestamp":1626994934096}
1626994934.074996: {"feed":"book","product_id":"PI_ETHUSD","side":"sell","seq":26661739,"price":2012.65,"qty":46648.0,"timestamp":1626994934096}
1626994934.075022: {"feed":"book","product_id":"PI_ETHUSD","side":"buy","seq":26661740,"price":1995.65,"qty":0.0,"timestamp":1626994934096}
1626994934.075048: {"feed":"book","product_id":"PI_ETHUSD","side":"buy","seq":26661741,"price":1995.75,"qty":47406.0,"timestamp":1626994934096}
1626994934.075073: {"feed":"book","product_id":"PI_ETHUSD","side":"buy","seq":26661742,"price":2001.9,"qty":0.0,"timestamp":1626994934096}
1626994934.075099: {"feed":"book","product_id":"PI_ETHUSD","side":"buy","seq":26661743,"price":2001.9,"qty":12845.0,"timestamp":1626994934096}
1626994934.075124: {"feed":"book","product_id":"PI_ETHUSD","side":"buy","seq":26661744,"price":1985.1,"qty":0.0,"timestamp":1626994934096}
1626994934.07515: {"feed":"book","product_id":"PI_ETHUSD","side":"buy","seq":26661745,"price":1985.1,"qty":66945.0,"timestamp":1626994934096}
1626994934.0751748: {"feed":"book","product_id":"PI_ETHUSD","side":"sell","seq":26661746,"price":2021.45,"qty":0.0,"timestamp":1626994934096}
1626994934.075201: {"feed":"book","product_id":"PI_ETHUSD","side":"sell","seq":26661747,"price":2021.45,"qty":67942.0,"timestamp":1626994934096}
1626994934.092164: {"feed":"book","product_id":"FI_XBTUSD_210730","side":"sell","seq":5160058,"price":32210.5,"qty":0.0,"timestamp":1626994934116}
1626994934.092291: {"feed":"book","product_id":"FI_XBTUSD_210730","side":"sell","seq":5160059,"price":32209.5,"qty":103.0,"timestamp":1626994934116}
1626994934.095362: {"feed":"book","product_id":"PI_ETHUSD","side":"sell","seq":26661748,"price":2005.2,"qty":1839.0,"timestamp":1626994934120}
1626994934.0954828: {"feed":"book","product_id":"PI_ETHUSD","side":"buy","seq":26661749,"price":2004.7,"qty":1915.0,"timestamp":1626994934120}
1626994934.098669: {"feed":"book","product_id":"PI_ETHUSD","side":"sell","seq":26661750,"price":2005.35,"qty":1203.0,"timestamp":1626994934123}
1626994934.0988019: {"feed":"book","product_id":"PI_ETHUSD","side":"buy","seq":26661751,"price":2004.1,"qty":1478.0,"timestamp":1626994934123}
1626994934.0988748: {"feed":"book","product_id":"PI_ETHUSD","side":"buy","seq":26661752,"price":2003.95,"qty":0.0,"timestamp":1626994934124}
1626994934.0991948: {"feed":"book","product_id":"PI_ETHUSD","side":"buy","seq":26661753,"price":2003.65,"qty":3866.0,"timestamp":1626994934124}
1626994934.103026: {"feed":"book","product_id":"PI_ETHUSD","side":"buy","seq":26661754,"price":2003.05,"qty":0.0,"timestamp":1626994934126}
1626994934.111261: {"feed":"book","product_id":"FI_XBTUSD_210924","side":"sell","seq":13501787,"price":32418.0,"qty":0.0,"timestamp":1626994934134}
1626994934.111398: {"feed":"book","product_id":"FI_XBTUSD_210924","side":"sell","seq":13501788,"price":32359.0,"qty":250002.0,"timestamp":1626994934134}
1626994934.1114671: {"feed":"book","product_id":"PI_ETHUSD","side":"buy","seq":26661755,"price":1995.7,"qty":0.0,"timestamp":1626994934134}
1626994934.1115038: {"feed":"book","product_id":"PI_ETHUSD","side":"buy","seq":26661756,"price":1995.8,"qty":500002.0,"timestamp":1626994934134}
1626994934.1115332: {"feed":"book","product_id":"FI_ETHUSD_210730","side":"buy","seq":2138744,"price":1991.55,"qty":0.0,"timestamp":1626994934134}
1626994934.11158: {"feed":"book","product_id":"FI_ETHUSD_210730","side":"buy","seq":2138745,"price":1991.65,"qty":250002.0,"timestamp":1626994934134}
1626994934.111608: {"feed":"book","product_id":"PI_ETHUSD","side":"sell","seq":26661757,"price":2012.7,"qty":0.0,"timestamp":1626994934134}
1626994934.111638: {"feed":"book","product_id":"PI_ETHUSD","side":"sell","seq":26661758,"price":2012.6,"qty":500002.0,"timestamp":1626994934134}
1626994934.111664: {"feed":"book","product_id":"FI_ETHUSD_210730","side":"sell","seq":2138746,"price":2014.5,"qty":0.0,"timestamp":1626994934134}
1626994934.111692: {"feed":"book","product_id":"FI_ETHUSD_210730","side":"sell","seq":2138747,"price":2014.4,"qty":250002.0,"timestamp":1626994934134}
1626994934.111716: {"feed":"book","product_id":"FI_ETHUSD_211231","side":"sell","seq":2199041,"price":2049.65,"qty":0.0,"timestamp":1626994934134}
1626994934.111745: {"feed":"book","product_id":"FI_ETHUSD_211231","side":"sell","seq":2199042,"price":2049.55,"qty":250002.0,"timestamp":1626994934134}
1626994934.1117692: {"feed":"book","product_id":"PI_ETHUSD","side":"buy","seq":26661759,"price":2004.05,"qty":16426.0,"timestamp":1626994934136}
1626994934.111792: {"feed":"book","product_id":"PI_ETHUSD","side":"buy","seq":26661760,"price":2003.95,"qty":20000.0,"timestamp":1626994934136}
1626994934.12009: {"feed":"book","product_id":"FI_XBTUSD_210730","side":"sell","seq":5160060,"price":32209.5,"qty":0.0,"timestamp":1626994934145}
1626994934.120161: {"feed":"book","product_id":"FI_XBTUSD_210730","side":"sell","seq":5160061,"price":32210.5,"qty":103.0,"timestamp":1626994934145}
1626994934.125089: {"feed":"book","product_id":"PI_ETHUSD","side":"buy","seq":26661761,"price":2003.95,"qty":0.0,"timestamp":1626994934149}
1626994934.1251872: {"feed":"book","product_id":"PI_ETHUSD","side":"buy","seq":26661762,"price":2004.05,"qty":36426.0,"timestamp":1626994934149}
1626994934.131189: {"feed":"book","product_id":"PI_ETHUSD","side":"buy","seq":26661763,"price":2004.05,"qty":20600.0,"timestamp":1626994934155}
1626994934.131268: {"feed":"book","product_id":"PI_ETHUSD","side":"buy","seq":26661764,"price":2004.15,"qty":15826.0,"timestamp":1626994934155}
1626994934.134526: {"feed":"book","product_id":"PI_ETHUSD","side":"buy","seq":26661765,"price":2003.6,"qty":17446.0,"timestamp":1626994934159}
1626994934.147651: {"feed":"book","product_id":"PI_ETHUSD","side":"buy","seq":26661766,"price":2003.6,"qty":0.0,"timestamp":1626994934171}
1626994934.147773: {"feed":"book","product_id":"PI_ETHUSD","side":"buy","seq":26661767,"price":2003.65,"qty":21312.0,"timestamp":1626994934171}
1626994934.150594: {"feed":"book","product_id":"PI_ETHUSD","side":"buy","seq":26661768,"price":2003.65,"qty":3866.0,"timestamp":1626994934174}
1626994934.150702: {"feed":"book","product_id":"FI_XBTUSD_210924","side":"buy","seq":13501789,"price":32139.5,"qty":3000.0,"timestamp":1626994934174}
1626994934.150753: {"feed":"book","product_id":"FI_XBTUSD_210924","side":"buy","seq":13501790,"price":32176.0,"qty":1103.0,"timestamp":1626994934175}
1626994934.150808: {"feed":"book","product_id":"FI_XBTUSD_210924","side":"buy","seq":13501791,"price":32181.0,"qty":5000.0,"timestamp":1626994934175}
1626994934.150851: {"feed":"book","product_id":"FI_XBTUSD_210924","side":"sell","seq":13501792,"price":32246.0,"qty":5000.0,"timestamp":1626994934175}
1626994934.152719: {"feed":"book","product_id":"PI_ETHUSD","side":"buy","seq":26661769,"price":2004.05,"qty":600.0,"timestamp":1626994934177}
1626994934.1527932: {"feed":"book","product_id":"PI_ETHUSD","side":"buy","seq":26661770,"price":2004.15,"qty":35826.0,"timestamp":1626994934177}
1626994934.15871: {"feed":"book","product_id":"PI_ETHUSD","side":"buy","seq":26661771,"price":2004.15,"qty":20000.0,"timestamp":1626994934182}
1626994934.158824: {"feed":"book","product_id":"PI_ETHUSD","side":"buy","seq":26661772,"price":2004.05,"qty":16426.0,"timestamp":1626994934182}
1626994934.158871: {"feed":"book","product_id":"PI_ETHUSD","side":"buy","seq":26661773,"price":2004.15,"qty":0.0,"timestamp":1626994934183}
1626994934.158932: {"feed":"book","product_id":"PI_ETHUSD","side":"buy","seq":26661774,"price":2004.0,"qty":114218.0,"timestamp":1626994934183}
1626994934.1748219: {"feed":"book","product_id":"PI_LTCUSD","side":"buy","seq":3423207,"price":119.32,"qty":3912.0,"timestamp":1626994934198}
1626994934.178316: {"feed":"book","product_id":"PI_ETHUSD","side":"buy","seq":26661775,"price":2004.05,"qty":66132.0,"timestamp":1626994934201}
1626994934.178423: {"feed":"book","product_id":"FI_XBTUSD_210730","side":"buy","seq":5160062,"price":32170.5,"qty":0.0,"timestamp":1626994934202}
1626994934.1784902: {"feed":"book","product_id":"FI_XBTUSD_210730","side":"buy","seq":5160063,"price":32171.5,"qty":1200.0,"timestamp":1626994934202}
1626994934.178541: {"feed":"book","product_id":"FI_ETHUSD_211231","side":"buy","seq":2199043,"price":2028.9,"qty":0.0,"timestamp":1626994934203}
1626994934.1785889: {"feed":"book","product_id":"FI_ETHUSD_211231","side":"buy","seq":2199044,"price":2029.0,"qty":420.0,"timestamp":1626994934203}
1626994934.1786509: {"feed":"book","product_id":"FI_ETHUSD_210730","side":"buy","seq":2138748,"price":2000.9,"qty":0.0,"timestamp":1626994934203}
1626994934.178696: {"feed":"book","product_id":"FI_ETHUSD_210730","side":"buy","seq":2138749,"price":2001.2,"qty":600.0,"timestamp":1626994934203}
1626994934.1824708: {"feed":"book","product_id":"FI_XBTUSD_210730","side":"buy","seq":5160064,"price":32129.0,"qty":0.0,"timestamp":1626994934206}
1626994934.182593: {"feed":"book","product_id":"FI_XBTUSD_210730","side":"buy","seq":5160065,"price":32129.5,"qty":1500.0,"timestamp":1626994934206}
1626994934.191531: {"feed":"book","product_id":"FI_ETHUSD_211231","side":"buy","seq":2199045,"price":2027.0,"qty":2000.0,"timestamp":1626994934215}
1626994934.1965911: {"feed":"book","product_id":"FI_XBTUSD_210730","side":"buy","seq":5160066,"price":32171.0,"qty":0.0,"timestamp":1626994934219}
1626994934.196714: {"feed":"book","product_id":"FI_XBTUSD_210730","side":"buy","seq":5160067,"price":32172.0,"qty":50.0,"timestamp":1626994934219}
1626994934.2076921: {"feed":"book","product_id":"FI_ETHUSD_210730","side":"buy","seq":2138750,"price":2001.15,"qty":0.0,"timestamp":1626994934232}
1626994934.207819: {"feed":"book","product_id":"FI_ETHUSD_210730","side":"buy","seq":2138751,"price":2001.2,"qty":650.0,"timestamp":1626994934232}
1626994934.207874: {"feed":"book","product_id":"FI_ETHUSD_211231","side":"buy","seq":2199046,"price":2028.95,"qty":0.0,"timestamp":1626994934232}
1626994934.2079291: {"feed":"book","product_id":"FI_ETHUSD_211231","side":"buy","seq":2199047,"price":2029.05,"qty":50.0,"timestamp":1626994934232}
1626994934.210882: {"feed":"book","product_id":"FI_XBTUSD_210924","side":"sell","seq":13501793,"price":32268.0,"qty":0.0,"timestamp":1626994934235}
1626994934.211005: {"feed":"book","product_id":"FI_XBTUSD_210924","side":"sell","seq":13501794,"price":32279.0,"qty":20967.0,"timestamp":1626994934235}
1626994934.223583: {"feed":"book","product_id":"FI_XBTUSD_210924","side":"buy","seq":13501795,"price":32201.5,"qty":3000.0,"timestamp":1626994934247}
1626994934.226816: {"feed":"book","product_id":"FI_ETHUSD_210730","side":"buy","seq":2138752,"price":1991.6,"qty":0.0,"timestamp":1626994934250}
1626994934.226939: {"feed":"book","product_id":"FI_ETHUSD_210730","side":"buy","seq":2138753,"price":1991.7,"qty":44704.0,"timestamp":1626994934250}
1626994934.2270021: {"feed":"book","product_id":"FI_ETHUSD_210730","side":"sell","seq":2138754,"price":2014.45,"qty":0.0,"timestamp":1626994934250}
1626994934.227057: {"feed":"book","product_id":"FI_ETHUSD_210730","side":"sell","seq":2138755,"price":2014.35,"qty":45421.0,"timestamp":1626994934250}
1626994934.235863: {"feed":"book","product_id":"FI_XBTUSD_210924","side":"buy","seq":13501796,"price":32149.5,"qty":0.0,"timestamp":1626994934254}
1626994934.236004: {"feed":"book","product_id":"FI_XBTUSD_210924","side":"buy","seq":13501797,"price":32150.0,"qty":1500.0,"timestamp":1626994934254}
1626994934.240366: {"feed":"book","product_id":"FI_XBTUSD_210924","side":"buy","seq":13501798,"price":32189.5,"qty":1080.0,"timestamp":1626994934263}
1626994934.240473: {"feed":"book","product_id":"FI_XBTUSD_210924","side":"buy","seq":13501799,"price":32202.0,"qty":50.0,"timestamp":1626994934263}
1626994934.244569: {"feed":"book","product_id":"PI_ETHUSD","side":"buy","seq":26661776,"price":2000.25,"qty":0.0,"timestamp":1626994934265}
1626994934.265013: {"feed":"book","product_id":"PI_ETHUSD","side":"buy","seq":26661777,"price":2004.7,"qty":0.0,"timestamp":1626994934290}
1626994934.269207: {"feed":"book","product_id":"PI_ETHUSD","side":"buy","seq":26661778,"price":2003.6,"qty":17446.0,"timestamp":1626994934293}
1626994934.273639: {"feed":"book","product_id":"FI_XRPUSD_210924","side":"buy","seq":602283,"price":0.584,"qty":57.0,"timestamp":1626994934298}
1626994934.275986: {"feed":"book","product_id":"PI_ETHUSD","side":"sell","seq":26661779,"price":2008.35,"qty":0.0,"timestamp":1626994934300}
1626994934.276115: {"feed":"book","product_id":"PI_ETHUSD","side":"sell","seq":26661780,"price":2008.85,"qty":26148.0,"timestamp":1626994934300}
1626994934.27618: {"feed":"book","product_id":"PI_ETHUSD","side":"sell","seq":26661781,"price":2007.35,"qty":0.0,"timestamp":1626994934300}
1626994934.2762299: {"feed":"book","product_id":"PI_ETHUSD","side":"sell","seq":26661782,"price":2007.65,"qty":17817.0,"timestamp":1626994934300}
1626994934.276544: {"feed":"book","product_id":"PI_ETHUSD","side":"buy","seq":26661783,"price":1995.75,"qty":0.0,"timestamp":1626994934300}
1626994934.2766259: {"feed":"book","product_id":"PI_ETHUSD","side":"buy","seq":26661784,"price":1996.5,"qty":45130.0,"timestamp":1626994934300}
1626994934.2781792: {"feed":"book","product_id":"PI_ETHUSD","side":"buy","seq":26661785,"price":2001.35,"qty":4054.0,"timestamp":1626994934300}
1626994934.2782888: {"feed":"book","product_id":"PI_ETHUSD","side":"buy","seq":26661786,"price":2001.35,"qty":20329.0,"timestamp":1626994934300}
1626994934.278337: {"feed":"book","product_id":"PI_ETHUSD","side":"sell","seq":26661787,"price":2007.7,"qty":8742.0,"timestamp":1626994934300}
1626994934.278388: {"feed":"book","product_id":"PI_ETHUSD","side":"sell","seq":26661788,"price":2007.7,"qty":26981.0,"timestamp":1626994934300}
1626994934.2787259: {"feed":"book","product_id":"PI_ETHUSD","side":"buy","seq":26661789,"price":2001.9,"qty":0.0,"timestamp":1626994934300}
1626994934.278809: {"feed":"book","product_id":"PI_ETHUSD","side":"buy","seq":26661790,"price":2001.9,"qty":13010.0,"timestamp":1626994934300}
1626994934.278888: {"feed":"book","product_id":"PI_ETHUSD","side":"buy","seq":26661791,"price":2000.55,"qty":0.0,"timestamp":1626994934300}
1626994934.278966: {"feed":"book","product_id":"PI_ETHUSD","side":"buy","seq":26661792,"price":2000.55,"qty":22804.0,"timestamp":1626994934300}
1626994934.2798479: {"feed":"book","product_id":"PI_ETHUSD","side":"sell","seq":26661793,"price":2012.65,"qty":0.0,"timestamp":1626994934300}
1626994934.279917: {"feed":"book","product_id":"PI_ETHUSD","side":"sell","seq":26661794,"price":2012.65,"qty":46553.0,"timestamp":1626994934300}
1626994934.279958: {"feed":"book","product_id":"PI_ETHUSD","side":"buy","seq":26661795,"price":1985.1,"qty":0.0,"timestamp":1626994934300}
1626994934.279992: {"feed":"book","product_id":"PI_ETHUSD","side":"buy","seq":26661796,"price":1985.1,"qty":66946.0,"timestamp":1626994934300}
1626994934.280362: {"feed":"book","product_id":"PI_ETHUSD","side":"sell","seq":26661797,"price":2021.45,"qty":0.0,"timestamp":1626994934300}
1626994934.280423: {"feed":"book","product_id":"PI_ETHUSD","side":"sell","seq":26661798,"price":2021.45,"qty":67943.0,"timestamp":1626994934300}
1626994934.2819378: {"feed":"book","product_id":"PI_ETHUSD","side":"buy","seq":26661799,"price":2004.05,"qty":50306.0,"timestamp":1626994934301}
1626994934.282006: {"feed":"book","product_id":"PI_ETHUSD","side":"buy","seq":26661800,"price":2004.15,"qty":15826.0,"timestamp":1626994934301}
1626994934.282037: {"feed":"book","product_id":"PI_ETHUSD","side":"buy","seq":26661801,"price":2004.1,"qty":0.0,"timestamp":1626994934306}
1626994934.286022: {"feed":"book","product_id":"PI_ETHUSD","side":"buy","seq":26661802,"price":2004.0,"qty":94218.0,"timestamp":1626994934308}
1626994934.2860851: {"feed":"book","product_id":"PI_ETHUSD","side":"buy","seq":26661803,"price":2004.15,"qty":35826.0,"timestamp":1626994934308}
1626994934.286117: {"feed":"book","product_id":"FI_XBTUSD_210924","side":"sell","seq":13501800,"price":32281.5,"qty":0.0,"timestamp":1626994934309}
1626994934.286155: {"feed":"book","product_id":"FI_XBTUSD_210924","side":"sell","seq":13501801,"price":32278.5,"qty":250001.0,"timestamp":1626994934309}
1626994934.286185: {"feed":"book","product_id":"FI_ETHUSD_210730","side":"buy","seq":2138756,"price":1991.65,"qty":0.0,"timestamp":1626994934309}
1626994934.286217: {"feed":"book","product_id":"FI_ETHUSD_210730","side":"buy","seq":2138757,"price":1991.75,"qty":250002.0,"timestamp":1626994934309}
1626994934.2862442: {"feed":"book","product_id":"PI_ETHUSD","side":"sell","seq":26661804,"price":2008.9,"qty":0.0,"timestamp":1626994934309}
1626994934.286273: {"feed":"book","product_id":"PI_ETHUSD","side":"sell","seq":26661805,"price":2008.8,"qty":500001.0,"timestamp":1626994934309}
1626994934.2863061: {"feed":"book","product_id":"FI_ETHUSD_210730","side":"sell","seq":2138758,"price":2014.4,"qty":0.0,"timestamp":1626994934309}
1626994934.286335: {"feed":"book","product_id":"FI_ETHUSD_210730","side":"sell","seq":2138759,"price":2014.3,"qty":250002.0,"timestamp":1626994934309}
1626994934.28636: {"feed":"book","product_id":"PI_ETHUSD","side":"buy","seq":26661806,"price":1995.8,"qty":0.0,"timestamp":1626994934309}
1626994934.2863889: {"feed":"book","product_id":"PI_ETHUSD","side":"buy","seq":26661807,"price":1993.15,"qty":500002.0,"timestamp":1626994934309}
1626994934.2920802: {"feed":"book","product_id":"FI_XBTUSD_210924","side":"sell","seq":13501802,"price":32282.0,"qty":146559.0,"timestamp":1626994934315}
1626994934.292207: {"feed":"book","product_id":"FI_XBTUSD_210924","side":"sell","seq":13501803,"price":32279.0,"qty":40967.0,"timestamp":1626994934315}
1626994934.292257: {"feed":"book","product_id":"PI_ETHUSD","side":"buy","seq":26661808,"price":2003.6,"qty":0.0,"timestamp":1626994934316}
1626994934.292317: {"feed":"book","product_id":"PI_ETHUSD","side":"buy","seq":26661809,"price":2003.65,"qty":21312.0,"timestamp":1626994934316}
1626994934.296674: {"feed":"book","product_id":"FI_XBTUSD_210924","side":"buy","seq":13501804,"price":32201.5,"qty":0.0,"timestamp":1626994934321}
1626994934.338596: {"feed":"book","product_id":"PI_ETHUSD","side":"sell","seq":26661810,"price":2008.0,"qty":0.0,"timestamp":1626994934363}
1626994934.338696: {"feed":"book","product_id":"PI_ETHUSD","side":"sell","seq":26661811,"price":2007.5,"qty":47541.0,"timestamp":1626994934363}
1626994934.3727438: {"feed":"book","product_id":"PI_ETHUSD","side":"buy","seq":26661812,"price":2004.15,"qty":39835.0,"timestamp":1626994934396}
1626994934.3749409: {"feed":"book","product_id":"PI_ETHUSD","side":"sell","seq":26661813,"price":2006.7,"qty":4083.0,"timestamp":1626994934399}
1626994934.3779478: {"feed":"book","product_id":"PI_ETHUSD","side":"buy","seq":26661814,"price":2004.15,"qty":35826.0,"timestamp":1626994934402}
1626994934.37839: {"feed":"book","product_id":"PI_LTCUSD","side":"sell","seq":3423208,"price":119.57,"qty":5275.0,"timestamp":1626994934404}
1626994934.4033148: {"feed":"book","product_id":"FI_ETHUSD_211231","side":"sell","seq":2199048,"price":2049.6,"qty":44305.0,"timestamp":1626994934427}
1626994934.4034271: {"feed":"book","product_id":"FI_ETHUSD_211231","side":"sell","seq":2199049,"price":2049.5,"qty":45099.0,"timestamp":1626994934427}
1626994934.4034932: {"feed":"book","product_id":"FI_ETHUSD_211231","side":"sell","seq":2199050,"price":2049.6,"qty":0.0,"timestamp":1626994934427}
1626994934.403549: {"feed":"book","product_id":"FI_ETHUSD_211231","side":"sell","seq":2199051,"price":2049.5,"qty":89404.0,"timestamp":1626994934427}
1626994934.407176: {"feed":"book","product_id":"PI_ETHUSD","side":"buy","seq":26661815,"price":2003.1,"qty":10000.0,"timestamp":1626994934430}
1626994934.407296: {"feed":"book","product_id":"PI_ETHUSD","side":"sell","seq":26661816,"price":2005.35,"qty":11203.0,"timestamp":1626994934430}
1626994934.4113998: {"feed":"book","product_id":"PI_ETHUSD","side":"buy","seq":26661817,"price":2003.65,"qty":3866.0,"timestamp":1626994934434}
1626994934.411507: {"feed":"book","product_id":"PI_ETHUSD","side":"buy","seq":26661818,"price":2003.55,"qty":17446.0,"timestamp":1626994934434}
1626994934.4169312: {"feed":"book","product_id":"FI_XBTUSD_210924","side":"sell","seq":13501805,"price":32258.5,"qty":0.0,"timestamp":1626994934438}
1626994934.417056: {"feed":"book","product_id":"FI_XBTUSD_210924","side":"sell","seq":13501806,"price":32246.0,"qty":21219.0,"timestamp":1626994934438}
1626994934.41711: {"feed":"book","product_id":"FI_XBTUSD_210924","side":"buy","seq":13501807,"price":32178.0,"qty":0.0,"timestamp":1626994934438}
1626994934.417162: {"feed":"book","product_id":"FI_XBTUSD_210924","side":"buy","seq":13501808,"price":32175.0,"qty":20909.0,"timestamp":1626994934438}
1626994934.4238029: {"feed":"book","product_id":"PI_LTCUSD","side":"sell","seq":3423209,"price":119.63,"qty":8829.0,"timestamp":1626994934448}
1626994934.4244711: {"feed":"book","product_id":"PI_LTCUSD","side":"sell","seq":3423210,"price":119.73,"qty":14649.0,"timestamp":1626994934449}
1626994934.4321642: {"feed":"book","product_id":"PI_ETHUSD","side":"buy","seq":26661819,"price":2003.4,"qty":15000.0,"timestamp":1626994934457}
1626994934.441217: {"feed":"book","product_id":"PI_ETHUSD","side":"sell","seq":26661820,"price":2006.15,"qty":3970.0,"timestamp":1626994934465}
1626994934.4413419: {"feed":"book","product_id":"PI_ETHUSD","side":"buy","seq":26661821,"price":2003.7,"qty":4140.0,"timestamp":1626994934466}
1626994934.448591: {"feed":"book","product_id":"PI_ETHUSD","side":"buy","seq":26661822,"price":2003.05,"qty":2500.0,"timestamp":1626994934472}
1626994934.459327: {"feed":"book","product_id":"PI_ETHUSD","side":"buy","seq":26661823,"price":2004.05,"qty":600.0,"timestamp":1626994934483}
1626994934.4755478: {"feed":"book","product_id":"FI_XBTUSD_210924","side":"sell","seq":13501809,"price":32257.5,"qty":10000.0,"timestamp":1626994934500}
1626994934.475652: {"feed":"book","product_id":"FI_XBTUSD_210924","side":"buy","seq":13501810,"price":32162.0,"qty":10000.0,"timestamp":1626994934500}
1626994934.475691: {"feed":"book","product_id":"FI_XBTUSD_210924","side":"sell","seq":13501811,"price":32295.0,"qty":20880.0,"timestamp":1626994934500}
1626994934.475721: {"feed":"book","product_id":"FI_XBTUSD_210924","side":"buy","seq":13501812,"price":32124.5,"qty":26107.0,"timestamp":1626994934500}
1626994934.47575: {"feed":"book","product_id":"FI_XBTUSD_210924","side":"sell","seq":13501813,"price":32333.0,"qty":20880.0,"timestamp":1626994934500}
1626994934.481031: {"feed":"book","product_id":"PI_ETHUSD","side":"sell","seq":26661824,"price":2007.65,"qty":0.0,"timestamp":1626994934504}
1626994934.481185: {"feed":"book","product_id":"PI_ETHUSD","side":"sell","seq":26661825,"price":2006.35,"qty":10535.0,"timestamp":1626994934504}
1626994934.481246: {"feed":"book","product_id":"PI_ETHUSD","side":"buy","seq":26661826,"price":2000.55,"qty":0.0,"timestamp":1626994934504}
1626994934.481282: {"feed":"book","product_id":"PI_ETHUSD","side":"buy","seq":26661827,"price":2000.05,"qty":24883.0,"timestamp":1626994934504}
1626994934.481317: {"feed":"book","product_id":"PI_ETHUSD","side":"buy","seq":26661828,"price":2001.35,"qty":4054.0,"timestamp":1626994934505}
1626994934.481341: {"feed":"book","product_id":"PI_ETHUSD","side":"buy","seq":26661829,"price":2001.15,"qty":16887.0,"timestamp":1626994934505}
1626994934.481367: {"feed":"book","product_id":"PI_ETHUSD","side":"buy","seq":26661830,"price":1996.5,"qty":0.0,"timestamp":1626994934505}
1626994934.481395: {"feed":"book","product_id":"PI_ETHUSD","side":"buy","seq":26661831,"price":1995.85,"qty":46780.0,"timestamp":1626994934505}
1626994934.481427: {"feed":"book","product_id":"PI_ETHUSD","side":"sell","seq":26661832,"price":2008.85,"qty":0.0,"timestamp":1626994934505}
1626994934.4814541: {"feed":"book","product_id":"PI_ETHUSD","side":"sell","seq":26661833,"price":2008.15,"qty":27906.0,"timestamp":1626994934505}
1626994934.481866: {"feed":"book","product_id":"PI_ETHUSD","side":"sell","seq":26661834,"price":2012.65,"qty":0.0,"timestamp":1626994934505}
1626994934.481914: {"feed":"book","product_id":"PI_ETHUSD","side":"sell","seq":26661835,"price":2012.55,"qty":46640.0,"timestamp":1626994934505}
1626994934.481953: {"feed":"book","product_id":"PI_ETHUSD","side":"buy","seq":26661836,"price":2001.9,"qty":0.0,"timestamp":1626994934505}
1626994934.481984: {"feed":"book","product_id":"PI_ETHUSD","side":"buy","seq":26661837,"price":2001.9,"qty":12298.0,"timestamp":1626994934505}
1626994934.4820118: {"feed":"book","product_id":"PI_ETHUSD","side":"sell","seq":26661838,"price":2007.7,"qty":8742.0,"timestamp":1626994934505}
1626994934.482034: {"feed":"book","product_id":"PI_ETHUSD","side":"sell","seq":26661839,"price":2007.7,"qty":28055.0,"timestamp":1626994934505}
1626994934.482054: {"feed":"book","product_id":"PI_ETHUSD","side":"buy","seq":26661840,"price":1985.1,"qty":0.0,"timestamp":1626994934505}
1626994934.48208: {"feed":"book","product_id":"PI_ETHUSD","side":"buy","seq":26661841,"price":1985.1,"qty":66942.0,"timestamp":1626994934505}
1626994934.4824162: {"feed":"book","product_id":"PI_ETHUSD","side":"sell","seq":26661842,"price":2021.45,"qty":0.0,"timestamp":1626994934505}
1626994934.482466: {"feed":"book","product_id":"PI_ETHUSD","side":"sell","seq":26661843,"price":2021.45,"qty":67939.0,"timestamp":1626994934505}
1626994934.493342: {"feed":"book","product_id":"PI_ETHUSD","side":"sell","seq":26661844,"price":2008.8,"qty":0.0,"timestamp":1626994934517}
1626994934.493469: {"feed":"book","product_id":"PI_ETHUSD","side":"sell","seq":26661845,"price":2008.9,"qty":500001.0,"timestamp":1626994934517}
1626994934.493536: {"feed":"book","product_id":"FI_ETHUSD_211231","side":"sell","seq":2199052,"price":2049.55,"qty":0.0,"timestamp":1626994934517}
1626994934.493591: {"feed":"book","product_id":"FI_ETHUSD_211231","side":"sell","seq":2199053,"price":2049.45,"qty":250002.0,"timestamp":1626994934517}
1626994934.493658: {"feed":"book","product_id":"PI_ETHUSD","side":"buy","seq":26661846,"price":1993.15,"qty":0.0,"timestamp":1626994934517}
1626994934.493691: {"feed":"book","product_id":"PI_ETHUSD","side":"buy","seq":26661847,"price":1995.9,"qty":500002.0,"timestamp":1626994934517}
1626994934.493718: {"feed":"book","product_id":"PI_ETHUSD","side":"sell","seq":26661848,"price":2012.6,"qty":0.0,"timestamp":1626994934517}
1626994934.4937458: {"feed":"book","product_id":"PI_ETHUSD","side":"sell","seq":26661849,"price":2012.5,"qty":500002.0,"timestamp":1626994934517}
1626994934.496147: {"feed":"book","product_id":"PI_ETHUSD","side":"sell","seq":26661850,"price":2008.95,"qty":0.0,"timestamp":1626994934520}
1626994934.496235: {"feed":"book","product_id":"PI_ETHUSD","side":"sell","seq":26661851,"price":2008.5,"qty":150000.0,"timestamp":1626994934520}
1626994934.496279: {"feed":"book","product_id":"PI_ETHUSD","side":"buy","seq":26661852,"price":2003.1,"qty":15813.0,"timestamp":1626994934521}
1626994934.501639: {"feed":"book","product_id":"PI_ETHUSD","side":"sell","seq":26661853,"price":2007.75,"qty":181961.0,"timestamp":1626994934526}
1626994934.511279: {"feed":"book","product_id":"FI_XBTUSD_210924","side":"buy","seq":13501814,"price":32159.5,"qty":0.0,"timestamp":1626994934535}
1626994934.511402: {"feed":"book","product_id":"FI_XBTUSD_210924","side":"buy","seq":13501815,"price":32068.5,"qty":0.0,"timestamp":1626994934535}
1626994934.5244591: {"feed":"book","product_id":"FI_XBTUSD_210730","side":"sell","seq":5160068,"price":32210.5,"qty":0.0,"timestamp":1626994934548}
1626994934.5245812: {"feed":"book","product_id":"FI_XBTUSD_210730","side":"sell","seq":5160069,"price":32209.5,"qty":103.0,"timestamp":1626994934548}
1626994934.5731468: {"feed":"book","product_id":"PI_LTCUSD","side":"buy","seq":3423211,"price":119.34,"qty":32135.0,"timestamp":1626994934593}
1626994934.6122482: {"feed":"book","product_id":"FI_XBTUSD_210924","side":"buy","seq":13501816,"price":32142.5,"qty":0.0,"timestamp":1626994934632}
1626994934.650399: {"feed":"book","product_id":"FI_XBTUSD_210924","side":"sell","seq":13501817,"price":32246.0,"qty":5000.0,"timestamp":1626994934674}
1626994934.6504629: {"feed":"book","product_id":"FI_XBTUSD_210924","side":"sell","seq":13501818,"price":32245.5,"qty":18529.0,"timestamp":1626994934674}
1626994934.6504881: {"feed":"book","product_id":"FI_XBTUSD_210924","side":"sell","seq":13501819,"price":32279.0,"qty":20000.0,"timestamp":1626994934674}
1626994934.650508: {"feed":"book","product_id":"FI_XBTUSD_210924","side":"sell","seq":13501820,"price":32278.0,"qty":20966.0,"timestamp":1626994934674}
1626994934.6505349: {"feed":"book","product_id":"FI_XBTUSD_210924","side":"buy","seq":13501821,"price":32188.5,"qty":881.0,"timestamp":1626994934674}
1626994934.650559: {"feed":"book","product_id":"FI_XBTUSD_210924","side":"buy","seq":13501822,"price":32188.5,"qty":18852.0,"timestamp":1626994934674}
1626994934.6526809: {"feed":"book","product_id":"PI_XRPUSD","side":"sell","seq":3456212,"price":0.5893,"qty":22531.0,"timestamp":1626994934677}
1626994934.655961: {"feed":"book","product_id":"PI_XRPUSD","side":"buy","seq":3456213,"price":0.5883,"qty":200.0,"timestamp":1626994934680}
1626994934.656041: {"feed":"book","product_id":"PI_XRPUSD","side":"buy","seq":3456214,"price":0.588,"qty":18872.0,"timestamp":1626994934680}
1626994934.6862621: {"feed":"book","product_id":"PI_ETHUSD","side":"buy","seq":26661854,"price":1995.85,"qty":0.0,"timestamp":1626994934709}
1626994934.68639: {"feed":"book","product_id":"PI_ETHUSD","side":"buy","seq":26661855,"price":1993.2,"qty":55154.0,"timestamp":1626994934709}
1626994934.6864572: {"feed":"book","product_id":"PI_ETHUSD","side":"sell","seq":26661856,"price":2007.7,"qty":8742.0,"timestamp":1626994934709}
1626994934.686502: {"feed":"book","product_id":"PI_ETHUSD","side":"sell","seq":26661857,"price":2007.45,"qty":17203.0,"timestamp":1626994934709}
1626994934.695681: {"feed":"book","product_id":"FI_XBTUSD_210924","side":"sell","seq":13501823,"price":32278.5,"qty":0.0,"timestamp":1626994934716}
1626994934.695808: {"feed":"book","product_id":"FI_XBTUSD_210924","side":"sell","seq":13501824,"price":32277.5,"qty":252431.0,"timestamp":1626994934716}
1626994934.695861: {"feed":"book","product_id":"PI_ETHUSD","side":"sell","seq":26661858,"price":2008.9,"qty":0.0,"timestamp":1626994934716}
1626994934.6959171: {"feed":"book","product_id":"PI_ETHUSD","side":"sell","seq":26661859,"price":2008.45,"qty":500001.0,"timestamp":1626994934716}
1626994934.695968: {"feed":"book","product_id":"PI_ETHUSD","side":"buy","seq":26661860,"price":1995.9,"qty":0.0,"timestamp":1626994934716}
1626994934.696044: {"feed":"book","product_id":"PI_ETHUSD","side":"buy","seq":26661861,"price":1993.25,"qty":500002.0,"timestamp":1626994934716}
1626994934.69905: {"feed":"book","product_id":"FI_XBTUSD_210924","side":"sell","seq":13501825,"price":32279.0,"qty":0.0,"timestamp":1626994934722}
1626994934.699177: {"feed":"book","product_id":"FI_XBTUSD_210924","side":"sell","seq":13501826,"price":32278.0,"qty":40966.0,"timestamp":1626994934722}
1626994934.726764: {"feed":"book","product_id":"PI_LTCUSD","side":"sell","seq":3423212,"price":119.58,"qty":31925.0,"timestamp":1626994934751}
1626994934.797098: {"feed":"book","product_id":"FI_XBTUSD_210924","side":"buy","seq":13501827,"price":32203.5,"qty":3000.0,"timestamp":1626994934821}
1626994934.811024: {"feed":"book","product_id":"FI_XBTUSD_210924","side":"buy","seq":13501828,"price":32202.0,"qty":0.0,"timestamp":1626994934834}
1626994934.811147: {"feed":"book","product_id":"FI_XBTUSD_210924","side":"buy","seq":13501829,"price":32204.0,"qty":50.0,"timestamp":1626994934834}
1626994934.870672: {"feed":"book","product_id":"FI_XBTUSD_210924","side":"buy","seq":13501830,"price":32167.0,"qty":3000.0,"timestamp":1626994934894}
1626994934.8707929: {"feed":"book","product_id":"FI_XBTUSD_210924","side":"buy","seq":13501831,"price":32124.5,"qty":45080.0,"timestamp":1626994934894}
1626994934.870844: {"feed":"book","product_id":"FI_XBTUSD_210924","side":"buy","seq":13501832,"price":32082.0,"qty":18973.0,"timestamp":1626994934894}
1626994934.884068: {"feed":"book","product_id":"FI_XBTUSD_210924","side":"sell","seq":13501833,"price":32245.5,"qty":2430.0,"timestamp":1626994934907}
1626994934.8841732: {"feed":"book","product_id":"FI_XBTUSD_210924","side":"sell","seq":13501834,"price":32245.5,"qty":18405.0,"timestamp":1626994934907}
1626994934.884222: {"feed":"book","product_id":"FI_XBTUSD_210924","side":"buy","seq":13501835,"price":32188.5,"qty":881.0,"timestamp":1626994934907}
1626994934.8842618: {"feed":"book","product_id":"FI_XBTUSD_210924","side":"buy","seq":13501836,"price":32188.5,"qty":18976.0,"timestamp":1626994934907}
1626994934.889173: {"feed":"book","product_id":"PI_ETHUSD","side":"buy","seq":26661862,"price":1993.2,"qty":0.0,"timestamp":1626994934913}
1626994934.889299: {"feed":"book","product_id":"PI_ETHUSD","side":"buy","seq":26661863,"price":1995.95,"qty":46472.0,"timestamp":1626994934913}
1626994934.898985: {"feed":"book","product_id":"PI_ETHUSD","side":"buy","seq":26661864,"price":1993.25,"qty":0.0,"timestamp":1626994934922}
1626994934.8991108: {"feed":"book","product_id":"PI_ETHUSD","side":"buy","seq":26661865,"price":1993.15,"qty":500002.0,"timestamp":1626994934922}
1626994934.937108: {"feed":"book","product_id":"PI_ETHUSD","side":"buy","seq":26661866,"price":1987.0,"qty":0.0,"timestamp":1626994934960}
1626994934.937234: {"feed":"book","product_id":"PI_ETHUSD","side":"buy","seq":26661867,"price":1989.45,"qty":2500.0,"timestamp":1626994934960}
1626994934.961953: {"feed":"book","product_id":"FI_XBTUSD_210730","side":"sell","seq":5160070,"price":32209.5,"qty":0.0,"timestamp":1626994934985}
1626994934.962076: {"feed":"book","product_id":"FI_XBTUSD_210730","side":"sell","seq":5160071,"price":32210.5,"qty":103.0,"timestamp":1626994934985}
1626994935.0531042: {"feed":"book","product_id":"PI_LTCUSD","side":"sell","seq":3423213,"price":119.58,"qty":27737.0,"timestamp":1626994935075}
1626994935.053211: {"feed":"book","product_id":"PI_LTCUSD","side":"buy","seq":3423214,"price":119.33,"qty":0.0,"timestamp":1626994935077}
1626994935.058611: {"feed":"book","product_id":"PI_LTCUSD","side":"buy","seq":3423215,"price":119.36,"qty":3959.0,"timestamp":1626994935081}
1626994935.092941: {"feed":"book","product_id":"PI_ETHUSD","side":"buy","seq":26661868,"price":1995.95,"qty":0.0,"timestamp":1626994935116}
1626994935.0930681: {"feed":"book","product_id":"PI_ETHUSD","side":"buy","seq":26661869,"price":1993.3,"qty":54845.0,"timestamp":1626994935116}
1626994935.096174: {"feed":"book","product_id":"PI_LTCUSD","side":"sell","seq":3423216,"price":119.6,"qty":0.0,"timestamp":1626994935120}
1626994935.1140192: {"feed":"book","product_id":"PI_ETHUSD","side":"buy","seq":26661870,"price":2004.05,"qty":5025.0,"timestamp":1626994935137}
1626994935.114126: {"feed":"book","product_id":"PI_ETHUSD","side":"sell","seq":26661871,"price":2005.45,"qty":4931.0,"timestamp":1626994935138}
1626994935.116222: {"feed":"book","product_id":"PI_ETHUSD","side":"buy","seq":26661872,"price":2002.95,"qty":3921.0,"timestamp":1626994935140}
1626994935.117571: {"feed":"book","product_id":"FI_XBTUSD_210924","side":"sell","seq":13501837,"price":32278.0,"qty":20000.0,"timestamp":1626994935141}
1626994935.117679: {"feed":"book","product_id":"FI_XBTUSD_210924","side":"sell","seq":13501838,"price":32277.0,"qty":20966.0,"timestamp":1626994935141}
1626994935.1177442: {"feed":"book","product_id":"FI_XBTUSD_210924","side":"sell","seq":13501839,"price":32245.5,"qty":2430.0,"timestamp":1626994935141}
1626994935.117785: {"feed":"book","product_id":"FI_XBTUSD_210924","side":"sell","seq":13501840,"price":32245.5,"qty":18306.0,"timestamp":1626994935141}
1626994935.1178272: {"feed":"book","product_id":"FI_XBTUSD_210924","side":"buy","seq":13501841,"price":32188.5,"qty":881.0,"timestamp":1626994935141}
1626994935.117874: {"feed":"book","product_id":"FI_XBTUSD_210924","side":"buy","seq":13501842,"price":32188.5,"qty":19074.0,"timestamp":1626994935141}
1626994935.1192582: {"feed":"book","product_id":"PI_ETHUSD","side":"buy","seq":26661873,"price":2003.55,"qty":0.0,"timestamp":1626994935144}
1626994935.1193442: {"feed":"book","product_id":"PI_ETHUSD","side":"buy","seq":26661874,"price":2003.5,"qty":17446.0,"timestamp":1626994935144}
1626994935.149419: {"feed":"book","product_id":"FI_ETHUSD_210730","side":"buy","seq":2138760,"price":1999.9,"qty":0.0,"timestamp":1626994935173}
1626994935.150028: {"feed":"book","product_id":"PI_XRPUSD","side":"buy","seq":3456215,"price":0.5875,"qty":1385.0,"timestamp":1626994935174}
1626994935.150115: {"feed":"book","product_id":"PI_ETHUSD","side":"sell","seq":26661875,"price":2007.3,"qty":7767.0,"timestamp":1626994935175}
1626994935.1508732: {"feed":"book","product_id":"PI_LTCUSD","side":"buy","seq":3423217,"price":119.24,"qty":6006.0,"timestamp":1626994935175}
1626994935.1773498: {"feed":"book","product_id":"FI_ETHUSD_211231","side":"buy","seq":2199054,"price":2029.0,"qty":0.0,"timestamp":1626994935201}
1626994935.1774762: {"feed":"book","product_id":"FI_ETHUSD_211231","side":"buy","seq":2199055,"price":2029.1,"qty":420.0,"timestamp":1626994935201}
1626994935.17754: {"feed":"book","product_id":"FI_XBTUSD_210924","side":"buy","seq":13501843,"price":32189.5,"qty":0.0,"timestamp":1626994935201}
1626994935.177593: {"feed":"book","product_id":"FI_XBTUSD_210924","side":"buy","seq":13501844,"price":32203.0,"qty":1080.0,"timestamp":1626994935201}
1626994935.179202: {"feed":"book","product_id":"FI_XBTUSD_210730","side":"buy","seq":5160072,"price":32171.5,"qty":0.0,"timestamp":1626994935202}
1626994935.1792881: {"feed":"book","product_id":"FI_XBTUSD_210730","side":"buy","seq":5160073,"price":32172.5,"qty":1200.0,"timestamp":1626994935202}
1626994935.189507: {"feed":"book","product_id":"PI_ETHUSD","side":"sell","seq":26661876,"price":2007.05,"qty":0.0,"timestamp":1626994935212}
1626994935.189641: {"feed":"book","product_id":"PI_LTCUSD","side":"sell","seq":3423218,"price":119.46,"qty":0.0,"timestamp":1626994935213}
1626994935.1896892: {"feed":"book","product_id":"PI_LTCUSD","side":"sell","seq":3423219,"price":119.49,"qty":320.0,"timestamp":1626994935213}
1626994935.189962: {"feed":"book","product_id":"PI_LTCUSD","side":"buy","seq":3423220,"price":119.35,"qty":3929.0,"timestamp":1626994935213}
1626994935.1900039: {"feed":"book","product_id":"PI_LTCUSD","side":"buy","seq":3423221,"price":119.37,"qty":320.0,"timestamp":1626994935213}
1626994935.190036: {"feed":"book","product_id":"FI_ETHUSD_211231","side":"buy","seq":2199056,"price":2029.05,"qty":0.0,"timestamp":1626994935214}
1626994935.190071: {"feed":"book","product_id":"FI_ETHUSD_211231","side":"buy","seq":2199057,"price":2029.15,"qty":50.0,"timestamp":1626994935214}
1626994935.192415: {"feed":"book","product_id":"PI_LTCUSD","side":"sell","seq":3423222,"price":119.53,"qty":0.0,"timestamp":1626994935216}
1626994935.1924639: {"feed":"book","product_id":"PI_LTCUSD","side":"sell","seq":3423223,"price":119.55,"qty":8000.0,"timestamp":1626994935216}
1626994935.203254: {"feed":"book","product_id":"FI_XBTUSD_210730","side":"buy","seq":5160074,"price":32172.0,"qty":0.0,"timestamp":1626994935227}
1626994935.2033029: {"feed":"book","product_id":"FI_XBTUSD_210730","side":"buy","seq":5160075,"price":32173.0,"qty":50.0,"timestamp":1626994935227}
1626994935.2033432: {"feed":"book","product_id":"PI_ETHUSD","side":"sell","seq":26661877,"price":2006.75,"qty":2500.0,"timestamp":1626994935227}
1626994935.241757: {"feed":"book","product_id":"FI_XBTUSD_210924","side":"sell","seq":13501845,"price":32277.5,"qty":2430.0,"timestamp":1626994935265}
1626994935.241868: {"feed":"book","product_id":"FI_XBTUSD_210924","side":"sell","seq":13501846,"price":32276.5,"qty":250001.0,"timestamp":1626994935265}
1626994935.241933: {"feed":"book","product_id":"PI_ETHUSD","side":"buy","seq":26661878,"price":1993.15,"qty":0.0,"timestamp":1626994935265}
1626994935.241995: {"feed":"book","product_id":"PI_ETHUSD","side":"buy","seq":26661879,"price":1993.35,"qty":500002.0,"timestamp":1626994935265}
1626994935.24342: {"feed":"book","product_id":"FI_XBTUSD_210924","side":"sell","seq":13501847,"price":32278.0,"qty":0.0,"timestamp":1626994935268}
1626994935.243546: {"feed":"book","product_id":"FI_XBTUSD_210924","side":"sell","seq":13501848,"price":32277.0,"qty":40966.0,"timestamp":1626994935268}
1626994935.2591581: {"feed":"book","product_id":"FI_ETHUSD_211231","side":"sell","seq":2199058,"price":2049.5,"qty":44305.0,"timestamp":1626994935281}
1626994935.2592692: {"feed":"book","product_id":"FI_ETHUSD_211231","side":"sell","seq":2199059,"price":2049.4,"qty":45099.0,"timestamp":1626994935281}
1626994935.2593331: {"feed":"book","product_id":"FI_ETHUSD_211231","side":"sell","seq":2199060,"price":2049.5,"qty":0.0,"timestamp":1626994935281}
1626994935.259391: {"feed":"book","product_id":"FI_ETHUSD_211231","side":"sell","seq":2199061,"price":2049.4,"qty":89404.0,"timestamp":1626994935281}
1626994935.2817001: {"feed":"book","product_id":"PI_LTCUSD","side":"sell","seq":3423224,"price":119.69,"qty":64.0,"timestamp":1626994935305}
1626994935.296768: {"feed":"book","product_id":"PI_ETHUSD","side":"buy","seq":26661880,"price":1993.3,"qty":0.0,"timestamp":1626994935320}
1626994935.296895: {"feed":"book","product_id":"PI_ETHUSD","side":"buy","seq":26661881,"price":1996.5,"qty":44848.0,"timestamp":1626994935320}
1626994935.296958: {"feed":"book","product_id":"PI_ETHUSD","side":"buy","seq":26661882,"price":2001.15,"qty":0.0,"timestamp":1626994935320}
1626994935.29701: {"feed":"book","product_id":"PI_ETHUSD","side":"buy","seq":26661883,"price":2001.3,"qty":165949.0,"timestamp":1626994935320}
1626994935.297049: {"feed":"book","product_id":"FI_XBTUSD_210924","side":"sell","seq":13501849,"price":32289.0,"qty":3000.0,"timestamp":1626994935321}
1626994935.303099: {"feed":"book","product_id":"PI_ETHUSD","side":"buy","seq":26661884,"price":1993.35,"qty":0.0,"timestamp":1626994935326}
1626994935.303227: {"feed":"book","product_id":"PI_ETHUSD","side":"buy","seq":26661885,"price":1993.15,"qty":500002.0,"timestamp":1626994935326}
1626994935.303295: {"feed":"book","product_id":"FI_ETHUSD_211231","side":"sell","seq":2199062,"price":2049.45,"qty":0.0,"timestamp":1626994935326}
1626994935.303351: {"feed":"book","product_id":"FI_ETHUSD_211231","side":"sell","seq":2199063,"price":2049.35,"qty":250002.0,"timestamp":1626994935326}
1626994935.3212469: {"feed":"book","product_id":"PI_ETHUSD","side":"buy","seq":26661886,"price":2004.5,"qty":2009.0,"timestamp":1626994935344}
1626994935.325519: {"feed":"book","product_id":"PI_ETHUSD","side":"buy","seq":26661887,"price":2003.95,"qty":1512.0,"timestamp":1626994935348}
1626994935.331578: {"feed":"book","product_id":"PI_ETHUSD","side":"buy","seq":26661888,"price":2003.5,"qty":0.0,"timestamp":1626994935354}
1626994935.3330371: {"feed":"book","product_id":"PI_ETHUSD","side":"buy","seq":26661889,"price":2004.15,"qty":20000.0,"timestamp":1626994935356}
1626994935.3331451: {"feed":"book","product_id":"PI_ETHUSD","side":"buy","seq":26661890,"price":2004.05,"qty":20851.0,"timestamp":1626994935356}
1626994935.333196: {"feed":"book","product_id":"PI_ETHUSD","side":"buy","seq":26661891,"price":2004.15,"qty":0.0,"timestamp":1626994935357}
1626994935.333257: {"feed":"book","product_id":"PI_ETHUSD","side":"buy","seq":26661892,"price":2004.0,"qty":114218.0,"timestamp":1626994935357}
1626994935.352643: {"feed":"book","product_id":"FI_XBTUSD_210924","side":"sell","seq":13501850,"price":32245.5,"qty":2430.0,"timestamp":1626994935375}
1626994935.352751: {"feed":"book","product_id":"FI_XBTUSD_210924","side":"sell","seq":13501851,"price":32245.5,"qty":18521.0,"timestamp":1626994935375}
1626994935.352798: {"feed":"book","product_id":"FI_XBTUSD_210924","side":"buy","seq":13501852,"price":32188.5,"qty":881.0,"timestamp":1626994935375}
1626994935.352858: {"feed":"book","product_id":"FI_XBTUSD_210924","side":"buy","seq":13501853,"price":32188.5,"qty":18861.0,"timestamp":1626994935375}
1626994935.372267: {"feed":"book","product_id":"PI_ETHUSD","side":"buy","seq":26661893,"price":2003.85,"qty":8207.0,"timestamp":1626994935396}
1626994935.404864: {"feed":"book","product_id":"PI_ETHUSD","side":"sell","seq":26661894,"price":2006.4,"qty":131908.0,"timestamp":1626994935429}
1626994935.408012: {"feed":"book","product_id":"FI_XBTUSD_210924","side":"buy","seq":13501854,"price":32203.5,"qty":0.0,"timestamp":1626994935431}
1626994935.4181619: {"feed":"book","product_id":"PI_ETHUSD","side":"buy","seq":26661895,"price":2003.7,"qty":0.0,"timestamp":1626994935442}
1626994935.440964: {"feed":"book","product_id":"PI_ETHUSD","side":"buy","seq":26661896,"price":2003.4,"qty":18774.0,"timestamp":1626994935464}
1626994935.4572449: {"feed":"book","product_id":"PI_ETHUSD","side":"buy","seq":26661897,"price":2004.0,"qty":94218.0,"timestamp":1626994935481}
1626994935.457354: {"feed":"book","product_id":"PI_ETHUSD","side":"buy","seq":26661898,"price":2003.9,"qty":20000.0,"timestamp":1626994935481}
1626994935.45742: {"feed":"book","product_id":"PI_ETHUSD","side":"buy","seq":26661899,"price":2004.05,"qty":5025.0,"timestamp":1626994935482}
1626994935.457462: {"feed":"book","product_id":"PI_ETHUSD","side":"buy","seq":26661900,"price":2003.95,"qty":17338.0,"timestamp":1626994935482}
1626994935.465398: {"feed":"book","product_id":"PI_ETHUSD","side":"buy","seq":26661901,"price":2003.95,"qty":1512.0,"timestamp":1626994935488}
1626994935.4655051: {"feed":"book","product_id":"PI_ETHUSD","side":"buy","seq":26661902,"price":2003.85,"qty":24033.0,"timestamp":1626994935488}
1626994935.465555: {"feed":"book","product_id":"PI_ETHUSD","side":"buy","seq":26661903,"price":2003.9,"qty":0.0,"timestamp":1626994935488}
1626994935.465616: {"feed":"book","product_id":"PI_ETHUSD","side":"buy","seq":26661904,"price":2003.8,"qty":20000.0,"timestamp":1626994935488}
1626994935.468718: {"feed":"book","product_id":"PI_ETHUSD","side":"buy","seq":26661905,"price":2004.5,"qty":0.0,"timestamp":1626994935492}
1626994935.468842: {"feed":"book","product_id":"PI_ETHUSD","side":"buy","seq":26661906,"price":2003.8,"qty":0.0,"timestamp":1626994935492}
1626994935.4689019: {"feed":"book","product_id":"PI_ETHUSD","side":"buy","seq":26661907,"price":2003.75,"qty":20000.0,"timestamp":1626994935492}
1626994935.469364: {"feed":"book","product_id":"PI_ETHUSD","side":"buy","seq":26661908,"price":2003.85,"qty":8207.0,"timestamp":1626994935493}
1626994935.469434: {"feed":"book","product_id":"PI_ETHUSD","side":"buy","seq":26661909,"price":2003.8,"qty":15826.0,"timestamp":1626994935493}
1626994935.4698062: {"feed":"book","product_id":"PI_ETHUSD","side":"buy","seq":26661910,"price":2003.45,"qty":17446.0,"timestamp":1626994935495}
1626994935.480562: {"feed":"book","product_id":"PI_ETHUSD","side":"buy","seq":26661911,"price":2003.8,"qty":0.0,"timestamp":1626994935504}
1626994935.4806888: {"feed":"book","product_id":"PI_ETHUSD","side":"buy","seq":26661912,"price":2004.0,"qty":110044.0,"timestamp":1626994935504}
1626994935.480745: {"feed":"book","product_id":"PI_ETHUSD","side":"buy","seq":26661913,"price":2003.75,"qty":0.0,"timestamp":1626994935504}
1626994935.4807968: {"feed":"book","product_id":"PI_ETHUSD","side":"buy","seq":26661914,"price":2004.0,"qty":130044.0,"timestamp":1626994935504}
1626994935.500362: {"feed":"book","product_id":"PI_ETHUSD","side":"buy","seq":26661915,"price":1996.5,"qty":0.0,"timestamp":1626994935523}
1626994935.5004869: {"feed":"book","product_id":"PI_ETHUSD","side":"buy","seq":26661916,"price":1993.4,"qty":54565.0,"timestamp":1626994935523}
1626994935.502487: {"feed":"book","product_id":"PI_XRPUSD","side":"sell","seq":3456216,"price":0.5897,"qty":4849.0,"timestamp":1626994935526}
1626994935.516259: {"feed":"book","product_id":"FI_XBTUSD_210924","side":"sell","seq":13501855,"price":32271.5,"qty":0.0,"timestamp":1626994935540}
1626994935.539482: {"feed":"book","product_id":"FI_XBTUSD_210924","side":"buy","seq":13501856,"price":32153.5,"qty":5000.0,"timestamp":1626994935563}
1626994935.578736: {"feed":"book","product_id":"FI_ETHUSD_210730","side":"buy","seq":2138761,"price":1991.7,"qty":0.0,"timestamp":1626994935602}
1626994935.578864: {"feed":"book","product_id":"FI_ETHUSD_210730","side":"buy","seq":2138762,"price":1991.8,"qty":44704.0,"timestamp":1626994935602}
1626994935.578926: {"feed":"book","product_id":"FI_ETHUSD_210730","side":"sell","seq":2138763,"price":2014.35,"qty":0.0,"timestamp":1626994935602}
1626994935.578979: {"feed":"book","product_id":"FI_ETHUSD_210730","side":"sell","seq":2138764,"price":2014.25,"qty":45421.0,"timestamp":1626994935602}
1626994935.586978: {"feed":"book","product_id":"FI_XBTUSD_210924","side":"sell","seq":13501857,"price":32277.0,"qty":20000.0,"timestamp":1626994935610}
1626994935.5870879: {"feed":"book","product_id":"FI_XBTUSD_210924","side":"sell","seq":13501858,"price":32276.0,"qty":20966.0,"timestamp":1626994935610}
1626994935.647027: {"feed":"book","product_id":"PI_ETHUSD","side":"buy","seq":26661917,"price":2004.0,"qty":114218.0,"timestamp":1626994935669}
1626994935.647131: {"feed":"book","product_id":"PI_ETHUSD","side":"buy","seq":26661918,"price":2004.1,"qty":15826.0,"timestamp":1626994935669}
1626994935.704082: {"feed":"book","product_id":"PI_ETHUSD","side":"buy","seq":26661919,"price":1993.4,"qty":0.0,"timestamp":1626994935727}
1626994935.7042089: {"feed":"book","product_id":"PI_ETHUSD","side":"buy","seq":26661920,"price":1996.5,"qty":44795.0,"timestamp":1626994935727}
1626994935.728624: {"feed":"book","product_id":"FI_BCHUSD_210730","side":"sell","seq":91200,"price":440.0,"qty":26342.0,"timestamp":1626994935745}
1626994935.728745: {"feed":"book","product_id":"PI_LTCUSD","side":"sell","seq":3423225,"price":119.6,"qty":3967.0,"timestamp":1626994935750}
1626994935.768221: {"feed":"book","product_id":"PI_ETHUSD","side":"buy","seq":26661921,"price":2004.0,"qty":94218.0,"timestamp":1626994935790}
1626994935.76833: {"feed":"book","product_id":"PI_ETHUSD","side":"buy","seq":26661922,"price":2004.1,"qty":35826.0,"timestamp":1626994935790}
1626994935.778692: {"feed":"book","product_id":"PI_ETHUSD","side":"buy","seq":26661923,"price":2003.45,"qty":0.0,"timestamp":1626994935795}
1626994935.778816: {"feed":"book","product_id":"PI_ETHUSD","side":"buy","seq":26661924,"price":2003.5,"qty":17446.0,"timestamp":1626994935795}
1626994935.778881: {"feed":"book","product_id":"PI_ETHUSD","side":"buy","seq":26661925,"price":2003.95,"qty":0.0,"timestamp":1626994935802}
1626994935.787541: {"feed":"book","product_id":"PI_ETHUSD","side":"buy","seq":26661926,"price":2004.1,"qty":15826.0,"timestamp":1626994935810}
1626994935.787646: {"feed":"book","product_id":"PI_ETHUSD","side":"buy","seq":26661927,"price":2003.95,"qty":20000.0,"timestamp":1626994935810}
1626994935.787712: {"feed":"book","product_id":"PI_ETHUSD","side":"buy","seq":26661928,"price":2004.1,"qty":0.0,"timestamp":1626994935810}
1626994935.7877681: {"feed":"book","product_id":"PI_ETHUSD","side":"buy","seq":26661929,"price":2003.95,"qty":35826.0,"timestamp":1626994935810}
1626994935.787808: {"feed":"book","product_id":"PI_ETHUSD","side":"buy","seq":26661930,"price":2003.5,"qty":0.0,"timestamp":1626994935812}
1626994935.7923489: {"feed":"book","product_id":"PI_ETHUSD","side":"buy","seq":26661931,"price":2003.45,"qty":17446.0,"timestamp":1626994935816}
1626994935.795834: {"feed":"book","product_id":"PI_ETHUSD","side":"buy","seq":26661932,"price":2003.95,"qty":15826.0,"timestamp":1626994935819}
1626994935.795943: {"feed":"book","product_id":"PI_ETHUSD","side":"buy","seq":26661933,"price":2004.1,"qty":20000.0,"timestamp":1626994935819}
1626994935.7984278: {"feed":"book","product_id":"PI_ETHUSD","side":"buy","seq":26661934,"price":2003.95,"qty":0.0,"timestamp":1626994935822}
1626994935.798557: {"feed":"book","product_id":"PI_ETHUSD","side":"buy","seq":26661935,"price":2004.15,"qty":15826.0,"timestamp":1626994935822}
1626994935.79862: {"feed":"book","product_id":"PI_ETHUSD","side":"buy","seq":26661936,"price":2004.15,"qty":0.0,"timestamp":1626994935822}
1626994935.798672: {"feed":"book","product_id":"PI_ETHUSD","side":"buy","seq":26661937,"price":2004.1,"qty":35826.0,"timestamp":1626994935822}
1626994935.802201: {"feed":"book","product_id":"PI_ETHUSD","side":"buy","seq":26661938,"price":2003.45,"qty":0.0,"timestamp":1626994935826}
1626994935.8041: {"feed":"book","product_id":"FI_XRPUSD_210924","side":"buy","seq":602284,"price":0.584,"qty":0.0,"timestamp":1626994935828}
1626994935.8063412: {"feed":"book","product_id":"PI_ETHUSD","side":"buy","seq":26661939,"price":2003.5,"qty":17446.0,"timestamp":1626994935830}
1626994935.8083572: {"feed":"book","product_id":"FI_XBTUSD_210924","side":"sell","seq":13501859,"price":32237.5,"qty":169570.0,"timestamp":1626994935832}
1626994935.808418: {"feed":"book","product_id":"FI_XBTUSD_210730","side":"sell","seq":5160076,"price":32202.0,"qty":177217.0,"timestamp":1626994935832}
1626994935.817065: {"feed":"book","product_id":"FI_XBTUSD_210924","side":"sell","seq":13501860,"price":32277.0,"qty":0.0,"timestamp":1626994935840}
1626994935.817191: {"feed":"book","product_id":"FI_XBTUSD_210924","side":"sell","seq":13501861,"price":32276.5,"qty":270001.0,"timestamp":1626994935840}
1626994935.8221571: {"feed":"book","product_id":"FI_XBTUSD_210924","side":"buy","seq":13501862,"price":32138.0,"qty":0.0,"timestamp":1626994935844}
1626994935.8222861: {"feed":"book","product_id":"FI_XBTUSD_210924","side":"buy","seq":13501863,"price":32130.0,"qty":250001.0,"timestamp":1626994935844}
1626994935.8223538: {"feed":"book","product_id":"FI_XBTUSD_210924","side":"sell","seq":13501864,"price":32276.5,"qty":20000.0,"timestamp":1626994935844}
1626994935.822407: {"feed":"book","product_id":"FI_XBTUSD_210924","side":"sell","seq":13501865,"price":32275.5,"qty":250001.0,"timestamp":1626994935844}
1626994935.82246: {"feed":"book","product_id":"FI_ETHUSD_210730","side":"buy","seq":2138765,"price":1991.75,"qty":0.0,"timestamp":1626994935844}
1626994935.822494: {"feed":"book","product_id":"FI_ETHUSD_210730","side":"buy","seq":2138766,"price":1991.85,"qty":250002.0,"timestamp":1626994935844}
1626994935.822521: {"feed":"book","product_id":"FI_ETHUSD_210730","side":"sell","seq":2138767,"price":2014.3,"qty":0.0,"timestamp":1626994935844}
1626994935.82255: {"feed":"book","product_id":"FI_ETHUSD_210730","side":"sell","seq":2138768,"price":2014.2,"qty":250002.0,"timestamp":1626994935844}
1626994935.8294048: {"feed":"book","product_id":"FI_XBTUSD_210924","side":"sell","seq":13501866,"price":32276.5,"qty":0.0,"timestamp":1626994935853}
1626994935.829531: {"feed":"book","product_id":"FI_XBTUSD_210924","side":"sell","seq":13501867,"price":32276.0,"qty":40966.0,"timestamp":1626994935853}
1626994935.881021: {"feed":"book","product_id":"FI_XBTUSD_210924","side":"sell","seq":13501868,"price":32245.5,"qty":2430.0,"timestamp":1626994935904}
1626994935.8810759: {"feed":"book","product_id":"FI_XBTUSD_210924","side":"sell","seq":13501869,"price":32245.5,"qty":18552.0,"timestamp":1626994935904}
1626994935.881097: {"feed":"book","product_id":"FI_XBTUSD_210924","side":"buy","seq":13501870,"price":32188.5,"qty":881.0,"timestamp":1626994935904}
1626994935.881114: {"feed":"book","product_id":"FI_XBTUSD_210924","side":"buy","seq":13501871,"price":32188.5,"qty":18830.0,"timestamp":1626994935904}
1626994935.8811278: {"feed":"book","product_id":"FI_XBTUSD_210924","side":"sell","seq":13501872,"price":32276.0,"qty":20000.0,"timestamp":1626994935904}
1626994935.881151: {"feed":"book","product_id":"FI_XBTUSD_210924","side":"sell","seq":13501873,"price":32276.0,"qty":40965.0,"timestamp":1626994935904}
1626994935.90033: {"feed":"book","product_id":"FI_XBTUSD_210730","side":"sell","seq":5160077,"price":32210.5,"qty":0.0,"timestamp":1626994935923}
1626994935.900368: {"feed":"book","product_id":"FI_XBTUSD_210730","side":"sell","seq":5160078,"price":32209.5,"qty":103.0,"timestamp":1626994935923}
1626994935.973242: {"feed":"book","product_id":"PI_ETHUSD","side":"sell","seq":26661940,"price":2012.55,"qty":0.0,"timestamp":1626994935992}
1626994935.973314: {"feed":"book","product_id":"PI_ETHUSD","side":"sell","seq":26661941,"price":2012.45,"qty":46192.0,"timestamp":1626994935992}
1626994935.9733372: {"feed":"book","product_id":"PI_ETHUSD","side":"sell","seq":26661942,"price":2006.35,"qty":0.0,"timestamp":1626994935992}
1626994935.973355: {"feed":"book","product_id":"PI_ETHUSD","side":"sell","seq":26661943,"price":2006.35,"qty":10323.0,"timestamp":1626994935992}
1626994935.97337: {"feed":"book","product_id":"PI_ETHUSD","side":"sell","seq":26661944,"price":2007.45,"qty":0.0,"timestamp":1626994935992}
1626994935.973401: {"feed":"book","product_id":"PI_ETHUSD","side":"sell","seq":26661945,"price":2007.45,"qty":16884.0,"timestamp":1626994935992}
1626994935.973415: {"feed":"book","product_id":"PI_ETHUSD","side":"buy","seq":26661946,"price":2001.9,"qty":0.0,"timestamp":1626994935992}
1626994935.973431: {"feed":"book","product_id":"PI_ETHUSD","side":"buy","seq":26661947,"price":2001.9,"qty":12510.0,"timestamp":1626994935992}
1626994935.973444: {"feed":"book","product_id":"PI_ETHUSD","side":"sell","seq":26661948,"price":2008.15,"qty":4990.0,"timestamp":1626994935992}
1626994935.973456: {"feed":"book","product_id":"PI_ETHUSD","side":"sell","seq":26661949,"price":2008.15,"qty":27693.0,"timestamp":1626994935992}
1626994935.9734662: {"feed":"book","product_id":"PI_ETHUSD","side":"buy","seq":26661950,"price":2000.05,"qty":0.0,"timestamp":1626994935992}
1626994935.97348: {"feed":"book","product_id":"PI_ETHUSD","side":"buy","seq":26661951,"price":2000.05,"qty":25094.0,"timestamp":1626994935992}
1626994935.973493: {"feed":"book","product_id":"PI_ETHUSD","side":"buy","seq":26661952,"price":1996.5,"qty":0.0,"timestamp":1626994935992}
1626994935.973506: {"feed":"book","product_id":"PI_ETHUSD","side":"buy","seq":26661953,"price":1996.5,"qty":44847.0,"timestamp":1626994935992}
1626994935.973519: {"feed":"book","product_id":"PI_ETHUSD","side":"buy","seq":26661954,"price":2001.3,"qty":150000.0,"timestamp":1626994935992}
1626994935.97353: {"feed":"book","product_id":"PI_ETHUSD","side":"buy","seq":26661955,"price":2001.3,"qty":165945.0,"timestamp":1626994935992}
1626994935.97354: {"feed":"book","product_id":"PI_ETHUSD","side":"buy","seq":26661956,"price":1985.1,"qty":0.0,"timestamp":1626994935992}
1626994935.973553: {"feed":"book","product_id":"PI_ETHUSD","side":"buy","seq":26661957,"price":1985.1,"qty":66943.0,"timestamp":1626994935992}
1626994935.9735832: {"feed":"book","product_id":"PI_ETHUSD","side":"sell","seq":26661958,"price":2021.45,"qty":0.0,"timestamp":1626994935992}
1626994935.9735959: {"feed":"book","product_id":"PI_ETHUSD","side":"sell","seq":26661959,"price":2021.45,"qty":67940.0,"timestamp":1626994935992}
1626994935.976444: {"feed":"book","product_id":"FI_XBTUSD_210730","side":"sell","seq":5160079,"price":32209.5,"qty":0.0,"timestamp":1626994936000}
1626994935.976474: {"feed":"book","product_id":"FI_XBTUSD_210730","side":"sell","seq":5160080,"price":32208.5,"qty":103.0,"timestamp":1626994936000}
1626994935.977058: {"feed":"book","product_id":"PI_ETHUSD","side":"sell","seq":26661960,"price":2012.5,"qty":0.0,"timestamp":1626994936002}
1626994935.9770849: {"feed":"book","product_id":"PI_ETHUSD","side":"sell","seq":26661961,"price":2013.7,"qty":500002.0,"timestamp":1626994936002}
1626994935.9911082: {"feed":"book","product_id":"PI_ETHUSD","side":"buy","seq":26661962,"price":2003.4,"qty":15000.0,"timestamp":1626994936015}
1626994935.996852: {"feed":"book","product_id":"FI_XBTUSD_210924","side":"sell","seq":13501874,"price":32233.0,"qty":0.0,"timestamp":1626994936021}
1626994935.996879: {"feed":"book","product_id":"FI_XBTUSD_210924","side":"sell","seq":13501875,"price":32231.5,"qty":103.0,"timestamp":1626994936021}
1626994936.0195048: {"feed":"book","product_id":"PI_ETHUSD","side":"buy","seq":26661963,"price":2001.3,"qty":15945.0,"timestamp":1626994936043}
1626994936.0195572: {"feed":"book","product_id":"PI_ETHUSD","side":"buy","seq":26661964,"price":2001.8,"qty":236012.0,"timestamp":1626994936043}
1626994936.065312: {"feed":"book","product_id":"PI_LTCUSD","side":"sell","seq":3423226,"price":119.61,"qty":4175.0,"timestamp":1626994936089}
1626994936.065357: {"feed":"book","product_id":"PI_LTCUSD","side":"sell","seq":3423227,"price":119.64,"qty":4059.0,"timestamp":1626994936090}
1626994936.069001: {"feed":"book","product_id":"FI_XBTUSD_210924","side":"buy","seq":13501876,"price":32206.0,"qty":3000.0,"timestamp":1626994936093}
1626994936.083474: {"feed":"book","product_id":"FI_XBTUSD_210924","side":"sell","seq":13501877,"price":32245.5,"qty":2430.0,"timestamp":1626994936108}
1626994936.083501: {"feed":"book","product_id":"FI_XBTUSD_210924","side":"sell","seq":13501878,"price":32245.5,"qty":18527.0,"timestamp":1626994936108}
1626994936.085748: {"feed":"book","product_id":"FI_XBTUSD_210924","side":"buy","seq":13501879,"price":32188.5,"qty":881.0,"timestamp":1626994936108}
1626994936.0857742: {"feed":"book","product_id":"FI_XBTUSD_210924","side":"buy","seq":13501880,"price":32188.5,"qty":18854.0,"timestamp":1626994936108}
1626994936.08579: {"feed":"book","product_id":"FI_XBTUSD_210924","side":"sell","seq":13501881,"price":32276.0,"qty":20000.0,"timestamp":1626994936108}
1626994936.085801: {"feed":"book","product_id":"FI_XBTUSD_210924","side":"sell","seq":13501882,"price":32276.0,"qty":40966.0,"timestamp":1626994936108}
1626994936.1180449: {"feed":"book","product_id":"PI_ETHUSD","side":"buy","seq":26661965,"price":2004.1,"qty":15826.0,"timestamp":1626994936141}
1626994936.118158: {"feed":"book","product_id":"PI_ETHUSD","side":"buy","seq":26661966,"price":2004.0,"qty":114218.0,"timestamp":1626994936141}
1626994936.120939: {"feed":"book","product_id":"PI_ETHUSD","side":"buy","seq":26661967,"price":2003.5,"qty":0.0,"timestamp":1626994936144}
1626994936.121027: {"feed":"book","product_id":"PI_ETHUSD","side":"buy","seq":26661968,"price":2003.45,"qty":17446.0,"timestamp":1626994936144}
1626994936.146848: {"feed":"book","product_id":"PI_ETHUSD","side":"buy","seq":26661969,"price":2004.05,"qty":4425.0,"timestamp":1626994936170}
1626994936.146958: {"feed":"book","product_id":"PI_ETHUSD","side":"buy","seq":26661970,"price":2004.1,"qty":16426.0,"timestamp":1626994936170}
1626994936.15112: {"feed":"book","product_id":"PI_LTCUSD","side":"buy","seq":3423228,"price":119.26,"qty":4517.0,"timestamp":1626994936174}
1626994936.160279: {"feed":"book","product_id":"PI_ETHUSD","side":"buy","seq":26661971,"price":2004.0,"qty":94218.0,"timestamp":1626994936182}
1626994936.160388: {"feed":"book","product_id":"PI_ETHUSD","side":"buy","seq":26661972,"price":2004.1,"qty":36426.0,"timestamp":1626994936182}
1626994936.162984: {"feed":"book","product_id":"PI_ETHUSD","side":"buy","seq":26661973,"price":2003.45,"qty":0.0,"timestamp":1626994936186}
1626994936.1631129: {"feed":"book","product_id":"PI_ETHUSD","side":"buy","seq":26661974,"price":2003.5,"qty":17446.0,"timestamp":1626994936186}
1626994936.172867: {"feed":"book","product_id":"PI_ETHUSD","side":"sell","seq":26661975,"price":2006.35,"qty":0.0,"timestamp":1626994936196}
1626994936.1729999: {"feed":"book","product_id":"PI_ETHUSD","side":"sell","seq":26661976,"price":2007.25,"qty":18843.0,"timestamp":1626994936196}
1626994936.173054: {"feed":"book","product_id":"PI_ETHUSD","side":"sell","seq":26661977,"price":2008.15,"qty":4990.0,"timestamp":1626994936196}
1626994936.173093: {"feed":"book","product_id":"PI_ETHUSD","side":"sell","seq":26661978,"price":2008.4,"qty":23741.0,"timestamp":1626994936196}
1626994936.1734989: {"feed":"book","product_id":"PI_ETHUSD","side":"buy","seq":26661979,"price":2000.05,"qty":0.0,"timestamp":1626994936196}
1626994936.173612: {"feed":"book","product_id":"PI_ETHUSD","side":"buy","seq":26661980,"price":2000.55,"qty":22674.0,"timestamp":1626994936196}
1626994936.176474: {"feed":"book","product_id":"FI_ETHUSD_211231","side":"buy","seq":2199064,"price":2029.1,"qty":0.0,"timestamp":1626994936201}
1626994936.176525: {"feed":"book","product_id":"FI_ETHUSD_211231","side":"buy","seq":2199065,"price":2029.2,"qty":420.0,"timestamp":1626994936201}
1626994936.180195: {"feed":"book","product_id":"FI_XBTUSD_210730","side":"buy","seq":5160081,"price":32172.5,"qty":0.0,"timestamp":1626994936202}
1626994936.18032: {"feed":"book","product_id":"FI_XBTUSD_210730","side":"buy","seq":5160082,"price":32173.5,"qty":1200.0,"timestamp":1626994936202}
1626994936.182404: {"feed":"book","product_id":"PI_ETHUSD","side":"sell","seq":26661981,"price":2007.5,"qty":5000.0,"timestamp":1626994936205}
1626994936.182515: {"feed":"book","product_id":"PI_ETHUSD","side":"sell","seq":26661982,"price":2008.0,"qty":42541.0,"timestamp":1626994936205}
1626994936.187528: {"feed":"book","product_id":"PI_LTCUSD","side":"sell","seq":3423229,"price":119.5,"qty":0.0,"timestamp":1626994936211}
1626994936.190746: {"feed":"book","product_id":"FI_ETHUSD_211231","side":"buy","seq":2199066,"price":2029.15,"qty":0.0,"timestamp":1626994936214}
1626994936.190809: {"feed":"book","product_id":"FI_ETHUSD_211231","side":"buy","seq":2199067,"price":2029.25,"qty":50.0,"timestamp":1626994936214}
1626994936.19085: {"feed":"book","product_id":"PI_LTCUSD","side":"buy","seq":3423230,"price":119.24,"qty":5006.0,"timestamp":1626994936214}
1626994936.190878: {"feed":"book","product_id":"PI_LTCUSD","side":"buy","seq":3423231,"price":119.27,"qty":1000.0,"timestamp":1626994936214}
1626994936.1946409: {"feed":"book","product_id":"PI_ETHUSD","side":"sell","seq":26661983,"price":2006.4,"qty":86728.0,"timestamp":1626994936218}
1626994936.2065809: {"feed":"book","product_id":"FI_XBTUSD_210730","side":"buy","seq":5160083,"price":32173.0,"qty":0.0,"timestamp":1626994936227}
1626994936.206709: {"feed":"book","product_id":"FI_XBTUSD_210730","side":"buy","seq":5160084,"price":32174.0,"qty":50.0,"timestamp":1626994936227}
1626994936.221662: {"feed":"book","product_id":"FI_XBTUSD_210924","side":"buy","seq":13501883,"price":32206.0,"qty":0.0,"timestamp":1626994936244}
1626994936.280598: {"feed":"book","product_id":"FI_ETHUSD_211231","side":"sell","seq":2199068,"price":2049.4,"qty":44305.0,"timestamp":1626994936303}
1626994936.280709: {"feed":"book","product_id":"FI_ETHUSD_211231","side":"sell","seq":2199069,"price":2049.3,"qty":45099.0,"timestamp":1626994936303}
1626994936.281048: {"feed":"book","product_id":"FI_ETHUSD_211231","side":"sell","seq":2199070,"price":2049.4,"qty":0.0,"timestamp":1626994936303}
1626994936.281129: {"feed":"book","product_id":"FI_ETHUSD_211231","side":"sell","seq":2199071,"price":2049.3,"qty":89404.0,"timestamp":1626994936303}
1626994936.2896771: {"feed":"book","product_id":"FI_XBTUSD_210924","side":"sell","seq":13501884,"price":32276.0,"qty":20000.0,"timestamp":1626994936312}
1626994936.2897851: {"feed":"book","product_id":"FI_XBTUSD_210924","side":"sell","seq":13501885,"price":32275.0,"qty":20966.0,"timestamp":1626994936312}
1626994936.289851: {"feed":"book","product_id":"FI_XBTUSD_210924","side":"sell","seq":13501886,"price":32245.5,"qty":2430.0,"timestamp":1626994936312}
1626994936.2898939: {"feed":"book","product_id":"FI_XBTUSD_210924","side":"sell","seq":13501887,"price":32245.5,"qty":18523.0,"timestamp":1626994936312}
1626994936.289929: {"feed":"book","product_id":"FI_XBTUSD_210924","side":"buy","seq":13501888,"price":32188.5,"qty":881.0,"timestamp":1626994936312}
1626994936.289964: {"feed":"book","product_id":"FI_XBTUSD_210924","side":"buy","seq":13501889,"price":32188.5,"qty":18858.0,"timestamp":1626994936312}
1626994936.292715: {"feed":"book","product_id":"FI_XBTUSD_210924","side":"sell","seq":13501890,"price":32276.0,"qty":0.0,"timestamp":1626994936316}
1626994936.2928379: {"feed":"book","product_id":"FI_XBTUSD_210924","side":"sell","seq":13501891,"price":32275.5,"qty":270001.0,"timestamp":1626994936316}
1626994936.297355: {"feed":"book","product_id":"FI_ETHUSD_211231","side":"sell","seq":2199072,"price":2049.35,"qty":0.0,"timestamp":1626994936319}
1626994936.297477: {"feed":"book","product_id":"FI_ETHUSD_211231","side":"sell","seq":2199073,"price":2049.25,"qty":250002.0,"timestamp":1626994936319}
1626994936.2975402: {"feed":"book","product_id":"FI_XBTUSD_210924","side":"sell","seq":13501892,"price":32275.5,"qty":20000.0,"timestamp":1626994936319}
1626994936.297584: {"feed":"book","product_id":"FI_XBTUSD_210924","side":"sell","seq":13501893,"price":32274.5,"qty":250001.0,"timestamp":1626994936319}
1626994936.3018281: {"feed":"book","product_id":"FI_XBTUSD_210924","side":"sell","seq":13501894,"price":32275.5,"qty":0.0,"timestamp":1626994936323}
1626994936.301952: {"feed":"book","product_id":"FI_XBTUSD_210924","side":"sell","seq":13501895,"price":32275.0,"qty":40966.0,"timestamp":1626994936323}
1626994936.3712242: {"feed":"book","product_id":"PI_LTCUSD","side":"sell","seq":3423232,"price":119.51,"qty":26822.0,"timestamp":1626994936395}
1626994936.3745332: {"feed":"book","product_id":"PI_LTCUSD","side":"buy","seq":3423233,"price":119.27,"qty":0.0,"timestamp":1626994936398}
1626994936.3746629: {"feed":"book","product_id":"PI_LTCUSD","side":"buy","seq":3423234,"price":119.25,"qty":1063.0,"timestamp":1626994936398}
1626994936.3761668: {"feed":"book","product_id":"PI_ETHUSD","side":"sell","seq":26661984,"price":2012.45,"qty":0.0,"timestamp":1626994936400}
1626994936.376235: {"feed":"book","product_id":"PI_ETHUSD","side":"sell","seq":26661985,"price":2013.65,"qty":49691.0,"timestamp":1626994936400}
1626994936.4304519: {"feed":"book","product_id":"PI_ETHUSD","side":"buy","seq":26661986,"price":2004.05,"qty":48019.0,"timestamp":1626994936454}
1626994936.4421551: {"feed":"book","product_id":"PI_ETHUSD","side":"buy","seq":26661987,"price":2003.75,"qty":3877.0,"timestamp":1626994936464}
1626994936.467627: {"feed":"book","product_id":"PI_ETHUSD","side":"sell","seq":26661988,"price":2005.2,"qty":1799.0,"timestamp":1626994936490}
1626994936.470051: {"feed":"book","product_id":"PI_ETHUSD","side":"buy","seq":26661989,"price":2004.65,"qty":2421.0,"timestamp":1626994936494}
1626994936.470175: {"feed":"book","product_id":"PI_ETHUSD","side":"buy","seq":26661990,"price":2002.65,"qty":11528.0,"timestamp":1626994936494}
1626994936.4702349: {"feed":"book","product_id":"PI_ETHUSD","side":"sell","seq":26661991,"price":2007.15,"qty":14141.0,"timestamp":1626994936494}
1626994936.4734359: {"feed":"book","product_id":"PI_ETHUSD","side":"buy","seq":26661992,"price":1999.25,"qty":0.0,"timestamp":1626994936497}
1626994936.481565: {"feed":"book","product_id":"PI_ETHUSD","side":"buy","seq":26661993,"price":2004.1,"qty":20600.0,"timestamp":1626994936504}
1626994936.481672: {"feed":"book","product_id":"PI_ETHUSD","side":"buy","seq":26661994,"price":2004.25,"qty":15826.0,"timestamp":1626994936504}
1626994936.481738: {"feed":"book","product_id":"PI_ETHUSD","side":"buy","seq":26661995,"price":2004.25,"qty":0.0,"timestamp":1626994936505}
1626994936.481794: {"feed":"book","product_id":"PI_ETHUSD","side":"buy","seq":26661996,"price":2004.0,"qty":110044.0,"timestamp":1626994936505}
1626994936.481833: {"feed":"book","product_id":"PI_ETHUSD","side":"buy","seq":26661997,"price":2004.1,"qty":600.0,"timestamp":1626994936505}
1626994936.481867: {"feed":"book","product_id":"PI_ETHUSD","side":"buy","seq":26661998,"price":2003.95,"qty":20000.0,"timestamp":1626994936505}
1626994936.484129: {"feed":"book","product_id":"PI_ETHUSD","side":"buy","seq":26661999,"price":2003.5,"qty":0.0,"timestamp":1626994936507}
1626994936.484254: {"feed":"book","product_id":"PI_ETHUSD","side":"buy","seq":26662000,"price":2003.55,"qty":17446.0,"timestamp":1626994936507}
1626994936.485759: {"feed":"book","product_id":"PI_ETHUSD","side":"buy","seq":26662001,"price":2003.1,"qty":10000.0,"timestamp":1626994936509}
1626994936.486889: {"feed":"book","product_id":"PI_ETHUSD","side":"buy","seq":26662002,"price":2003.0,"qty":0.0,"timestamp":1626994936510}
1626994936.4870121: {"feed":"book","product_id":"PI_ETHUSD","side":"buy","seq":26662003,"price":2003.55,"qty":0.0,"timestamp":1626994936510}
1626994936.487073: {"feed":"book","product_id":"PI_ETHUSD","side":"buy","seq":26662004,"price":2003.45,"qty":17446.0,"timestamp":1626994936510}
1626994936.4981859: {"feed":"book","product_id":"FI_ETHUSD_211231","side":"buy","seq":2199074,"price":2025.85,"qty":0.0,"timestamp":1626994936521}
1626994936.4983108: {"feed":"book","product_id":"FI_ETHUSD_211231","side":"buy","seq":2199075,"price":2026.45,"qty":5757.0,"timestamp":1626994936521}
1626994936.4983659: {"feed":"book","product_id":"FI_ETHUSD_210730","side":"buy","seq":2138769,"price":1997.05,"qty":0.0,"timestamp":1626994936521}
1626994936.4984179: {"feed":"book","product_id":"FI_ETHUSD_210730","side":"buy","seq":2138770,"price":1997.7,"qty":2057.0,"timestamp":1626994936521}
1626994936.498466: {"feed":"book","product_id":"PI_ETHUSD","side":"buy","seq":26662005,"price":2000.6,"qty":0.0,"timestamp":1626994936522}
1626994936.498514: {"feed":"book","product_id":"PI_ETHUSD","side":"buy","seq":26662006,"price":2001.2,"qty":4306.0,"timestamp":1626994936522}
1626994936.517972: {"feed":"book","product_id":"PI_ETHUSD","side":"sell","seq":26662007,"price":2013.7,"qty":0.0,"timestamp":1626994936542}
1626994936.518097: {"feed":"book","product_id":"PI_ETHUSD","side":"sell","seq":26662008,"price":2013.6,"qty":500002.0,"timestamp":1626994936542}
1626994936.522484: {"feed":"book","product_id":"FI_XBTUSD_210924","side":"sell","seq":13501896,"price":32245.5,"qty":2430.0,"timestamp":1626994936547}
1626994936.522605: {"feed":"book","product_id":"FI_XBTUSD_210924","side":"sell","seq":13501897,"price":32245.5,"qty":18529.0,"timestamp":1626994936547}
1626994936.523094: {"feed":"book","product_id":"FI_XBTUSD_210924","side":"buy","seq":13501898,"price":32188.5,"qty":881.0,"timestamp":1626994936547}
1626994936.523156: {"feed":"book","product_id":"FI_XBTUSD_210924","side":"buy","seq":13501899,"price":32188.5,"qty":18852.0,"timestamp":1626994936547}
1626994936.541858: {"feed":"book","product_id":"PI_LTCUSD","side":"sell","seq":3423235,"price":119.71,"qty":8950.0,"timestamp":1626994936565}
1626994936.541963: {"feed":"book","product_id":"PI_LTCUSD","side":"sell","seq":3423236,"price":119.59,"qty":0.0,"timestamp":1626994936565}
1626994936.5608718: {"feed":"book","product_id":"PI_ETHUSD","side":"buy","seq":26662009,"price":2003.95,"qty":0.0,"timestamp":1626994936584}
1626994936.560998: {"feed":"book","product_id":"PI_ETHUSD","side":"buy","seq":26662010,"price":2003.85,"qty":28207.0,"timestamp":1626994936584}
1626994936.5619378: {"feed":"book","product_id":"PI_ETHUSD","side":"buy","seq":26662011,"price":2004.0,"qty":94218.0,"timestamp":1626994936585}
1626994936.562046: {"feed":"book","product_id":"PI_ETHUSD","side":"buy","seq":26662012,"price":2003.9,"qty":15826.0,"timestamp":1626994936585}
1626994936.582017: {"feed":"book","product_id":"PI_ETHUSD","side":"sell","seq":26662013,"price":2007.45,"qty":0.0,"timestamp":1626994936604}
1626994936.582106: {"feed":"book","product_id":"PI_ETHUSD","side":"sell","seq":26662014,"price":2007.7,"qty":26653.0,"timestamp":1626994936604}
1626994936.582141: {"feed":"book","product_id":"PI_ETHUSD","side":"buy","seq":26662015,"price":2001.3,"qty":0.0,"timestamp":1626994936604}
1626994936.582177: {"feed":"book","product_id":"PI_ETHUSD","side":"buy","seq":26662016,"price":2001.3,"qty":17021.0,"timestamp":1626994936604}
1626994936.582209: {"feed":"book","product_id":"PI_ETHUSD","side":"buy","seq":26662017,"price":2001.9,"qty":0.0,"timestamp":1626994936604}
1626994936.582237: {"feed":"book","product_id":"PI_ETHUSD","side":"buy","seq":26662018,"price":2001.9,"qty":13228.0,"timestamp":1626994936604}
1626994936.582263: {"feed":"book","product_id":"PI_ETHUSD","side":"sell","seq":26662019,"price":2007.25,"qty":3830.0,"timestamp":1626994936604}
1626994936.5822852: {"feed":"book","product_id":"PI_ETHUSD","side":"sell","seq":26662020,"price":2007.25,"qty":18493.0,"timestamp":1626994936604}
1626994936.582307: {"feed":"book","product_id":"PI_ETHUSD","side":"buy","seq":26662021,"price":2000.55,"qty":0.0,"timestamp":1626994936604}
1626994936.582332: {"feed":"book","product_id":"PI_ETHUSD","side":"buy","seq":26662022,"price":2000.55,"qty":23021.0,"timestamp":1626994936604}
1626994936.582357: {"feed":"book","product_id":"PI_ETHUSD","side":"sell","seq":26662023,"price":2008.4,"qty":0.0,"timestamp":1626994936604}
1626994936.582384: {"feed":"book","product_id":"PI_ETHUSD","side":"sell","seq":26662024,"price":2008.4,"qty":23390.0,"timestamp":1626994936604}
1626994936.582409: {"feed":"book","product_id":"PI_ETHUSD","side":"buy","seq":26662025,"price":1996.5,"qty":0.0,"timestamp":1626994936604}
1626994936.5824351: {"feed":"book","product_id":"PI_ETHUSD","side":"buy","seq":26662026,"price":1996.5,"qty":45253.0,"timestamp":1626994936604}
1626994936.582459: {"feed":"book","product_id":"PI_ETHUSD","side":"sell","seq":26662027,"price":2013.65,"qty":0.0,"timestamp":1626994936604}
1626994936.582491: {"feed":"book","product_id":"PI_ETHUSD","side":"sell","seq":26662028,"price":2013.65,"qty":49678.0,"timestamp":1626994936604}
1626994936.582517: {"feed":"book","product_id":"PI_ETHUSD","side":"buy","seq":26662029,"price":1985.1,"qty":0.0,"timestamp":1626994936604}
1626994936.5825431: {"feed":"book","product_id":"PI_ETHUSD","side":"buy","seq":26662030,"price":1985.1,"qty":66948.0,"timestamp":1626994936604}
1626994936.583812: {"feed":"book","product_id":"PI_ETHUSD","side":"sell","seq":26662031,"price":2021.45,"qty":0.0,"timestamp":1626994936604}
1626994936.5839: {"feed":"book","product_id":"PI_ETHUSD","side":"sell","seq":26662032,"price":2021.45,"qty":67945.0,"timestamp":1626994936604}
1626994936.595642: {"feed":"book","product_id":"PI_ETHUSD","side":"buy","seq":26662033,"price":2003.9,"qty":0.0,"timestamp":1626994936618}
1626994936.595768: {"feed":"book","product_id":"PI_ETHUSD","side":"buy","seq":26662034,"price":2004.0,"qty":110044.0,"timestamp":1626994936618}
1626994936.595823: {"feed":"book","product_id":"PI_ETHUSD","side":"buy","seq":26662035,"price":2003.85,"qty":8207.0,"timestamp":1626994936619}
1626994936.595864: {"feed":"book","product_id":"PI_ETHUSD","side":"buy","seq":26662036,"price":2003.95,"qty":20000.0,"timestamp":1626994936619}
1626994936.598485: {"feed":"book","product_id":"PI_ETHUSD","side":"buy","seq":26662037,"price":2003.45,"qty":0.0,"timestamp":1626994936623}
1626994936.684536: {"feed":"book","product_id":"PI_LTCUSD","side":"buy","seq":3423237,"price":119.35,"qty":0.0,"timestamp":1626994936706}
1626994936.68466: {"feed":"book","product_id":"PI_LTCUSD","side":"buy","seq":3423238,"price":119.38,"qty":4024.0,"timestamp":1626994936706}
1626994936.685248: {"feed":"book","product_id":"PI_ETHUSD","side":"sell","seq":26662038,"price":2005.2,"qty":0.0,"timestamp":1626994936706}
1626994936.703402: {"feed":"book","product_id":"PI_ETHUSD","side":"buy","seq":26662039,"price":2004.0,"qty":94218.0,"timestamp":1626994936723}
1626994936.703509: {"feed":"book","product_id":"PI_ETHUSD","side":"buy","seq":26662040,"price":2003.85,"qty":24033.0,"timestamp":1626994936723}
1626994936.703559: {"feed":"book","product_id":"PI_ETHUSD","side":"buy","seq":26662041,"price":2003.95,"qty":0.0,"timestamp":1626994936723}
1626994936.703619: {"feed":"book","product_id":"PI_ETHUSD","side":"buy","seq":26662042,"price":2003.8,"qty":20000.0,"timestamp":1626994936723}
1626994936.712: {"feed":"book","product_id":"PI_ETHUSD","side":"buy","seq":26662043,"price":2003.85,"qty":8207.0,"timestamp":1626994936735}
1626994936.712106: {"feed":"book","product_id":"PI_ETHUSD","side":"buy","seq":26662044,"price":2003.65,"qty":19692.0,"timestamp":1626994936735}
1626994936.714216: {"feed":"book","product_id":"PI_ETHUSD","side":"buy","seq":26662045,"price":2003.65,"qty":3866.0,"timestamp":1626994936736}
1626994936.714324: {"feed":"book","product_id":"PI_ETHUSD","side":"buy","seq":26662046,"price":2003.95,"qty":15826.0,"timestamp":1626994936736}
1626994936.717461: {"feed":"book","product_id":"FI_XBTUSD_210924","side":"buy","seq":13501900,"price":32201.5,"qty":3000.0,"timestamp":1626994936739}
1626994936.71758: {"feed":"book","product_id":"PI_ETHUSD","side":"buy","seq":26662047,"price":2003.05,"qty":0.0,"timestamp":1626994936741}
1626994936.719666: {"feed":"book","product_id":"PI_ETHUSD","side":"buy","seq":26662048,"price":2003.8,"qty":0.0,"timestamp":1626994936742}
1626994936.7197912: {"feed":"book","product_id":"PI_ETHUSD","side":"buy","seq":26662049,"price":2003.6,"qty":20000.0,"timestamp":1626994936742}
1626994936.719857: {"feed":"book","product_id":"PI_ETHUSD","side":"buy","seq":26662050,"price":2003.95,"qty":0.0,"timestamp":1626994936742}
1626994936.7199109: {"feed":"book","product_id":"PI_ETHUSD","side":"buy","seq":26662051,"price":2003.6,"qty":35826.0,"timestamp":1626994936742}
1626994936.729644: {"feed":"book","product_id":"PI_LTCUSD","side":"sell","seq":3423239,"price":119.49,"qty":0.0,"timestamp":1626994936746}
1626994936.7297769: {"feed":"book","product_id":"PI_LTCUSD","side":"sell","seq":3423240,"price":119.51,"qty":27142.0,"timestamp":1626994936746}
1626994936.7298439: {"feed":"book","product_id":"PI_ETHUSD","side":"buy","seq":26662052,"price":2003.6,"qty":20000.0,"timestamp":1626994936747}
1626994936.729872: {"feed":"book","product_id":"PI_ETHUSD","side":"buy","seq":26662053,"price":2003.65,"qty":19692.0,"timestamp":1626994936747}
1626994936.7298958: {"feed":"book","product_id":"PI_LTCUSD","side":"buy","seq":3423241,"price":119.3,"qty":4886.0,"timestamp":1626994936747}
1626994936.729918: {"feed":"book","product_id":"PI_LTCUSD","side":"buy","seq":3423242,"price":119.33,"qty":8000.0,"timestamp":1626994936747}
1626994936.729949: {"feed":"book","product_id":"PI_LTCUSD","side":"sell","seq":3423243,"price":119.9,"qty":0.0,"timestamp":1626994936747}
1626994936.729978: {"feed":"book","product_id":"PI_LTCUSD","side":"sell","seq":3423244,"price":120.09,"qty":64000.0,"timestamp":1626994936747}
1626994936.730005: {"feed":"book","product_id":"PI_LTCUSD","side":"buy","seq":3423245,"price":119.08,"qty":0.0,"timestamp":1626994936747}
1626994936.7300322: {"feed":"book","product_id":"PI_LTCUSD","side":"buy","seq":3423246,"price":119.15,"qty":16708.0,"timestamp":1626994936747}
1626994936.730054: {"feed":"book","product_id":"FI_XBTUSD_210924","side":"sell","seq":13501901,"price":32275.0,"qty":20000.0,"timestamp":1626994936750}
1626994936.730075: {"feed":"book","product_id":"FI_XBTUSD_210924","side":"sell","seq":13501902,"price":32274.0,"qty":20966.0,"timestamp":1626994936750}
1626994936.730101: {"feed":"book","product_id":"FI_XBTUSD_210924","side":"sell","seq":13501903,"price":32245.5,"qty":2430.0,"timestamp":1626994936750}
1626994936.730122: {"feed":"book","product_id":"FI_XBTUSD_210924","side":"sell","seq":13501904,"price":32245.5,"qty":18536.0,"timestamp":1626994936750}
1626994936.730141: {"feed":"book","product_id":"FI_XBTUSD_210924","side":"buy","seq":13501905,"price":32188.5,"qty":881.0,"timestamp":1626994936750}
1626994936.730162: {"feed":"book","product_id":"FI_XBTUSD_210924","side":"buy","seq":13501906,"price":32188.5,"qty":18845.0,"timestamp":1626994936750}
1626994936.731172: {"feed":"book","product_id":"PI_ETHUSD","side":"buy","seq":26662054,"price":2003.35,"qty":6459.0,"timestamp":1626994936755}
1626994936.742806: {"feed":"book","product_id":"FI_XBTUSD_210924","side":"sell","seq":13501907,"price":32275.0,"qty":0.0,"timestamp":1626994936764}
1626994936.742892: {"feed":"book","product_id":"FI_XBTUSD_210924","side":"sell","seq":13501908,"price":32274.5,"qty":270001.0,"timestamp":1626994936764}
1626994936.74503: {"feed":"book","product_id":"FI_XBTUSD_210924","side":"buy","seq":13501909,"price":32201.5,"qty":0.0,"timestamp":1626994936768}
1626994936.774529: {"feed":"book","product_id":"PI_ETHUSD","side":"buy","seq":26662055,"price":2003.6,"qty":0.0,"timestamp":1626994936797}
1626994936.774661: {"feed":"book","product_id":"PI_ETHUSD","side":"buy","seq":26662056,"price":2003.7,"qty":20000.0,"timestamp":1626994936797}
1626994936.789269: {"feed":"book","product_id":"PI_ETHUSD","side":"buy","seq":26662057,"price":2001.3,"qty":0.0,"timestamp":1626994936810}
1626994936.789402: {"feed":"book","product_id":"PI_ETHUSD","side":"buy","seq":26662058,"price":2001.5,"qty":15801.0,"timestamp":1626994936810}
1626994936.7894669: {"feed":"book","product_id":"PI_ETHUSD","side":"sell","seq":26662059,"price":2007.25,"qty":3830.0,"timestamp":1626994936810}
1626994936.789512: {"feed":"book","product_id":"PI_ETHUSD","side":"sell","seq":26662060,"price":2007.1,"qty":13512.0,"timestamp":1626994936810}
1626994936.797299: {"feed":"book","product_id":"PI_ETHUSD","side":"buy","seq":26662061,"price":2004.1,"qty":2099.0,"timestamp":1626994936820}
1626994936.805711: {"feed":"book","product_id":"PI_ETHUSD","side":"buy","seq":26662062,"price":2003.65,"qty":3866.0,"timestamp":1626994936827}
1626994936.805821: {"feed":"book","product_id":"PI_ETHUSD","side":"buy","seq":26662063,"price":2003.75,"qty":19703.0,"timestamp":1626994936827}
1626994936.828654: {"feed":"book","product_id":"PI_LTCUSD","side":"buy","seq":3423247,"price":119.37,"qty":381.0,"timestamp":1626994936851}
1626994936.9158468: {"feed":"book","product_id":"FI_ETHUSD_211231","side":"sell","seq":2199076,"price":2049.3,"qty":44305.0,"timestamp":1626994936937}
1626994936.91596: {"feed":"book","product_id":"FI_ETHUSD_211231","side":"sell","seq":2199077,"price":2049.2,"qty":45099.0,"timestamp":1626994936937}
1626994936.916023: {"feed":"book","product_id":"FI_ETHUSD_210730","side":"buy","seq":2138771,"price":1991.8,"qty":0.0,"timestamp":1626994936937}
1626994936.916081: {"feed":"book","product_id":"FI_ETHUSD_210730","side":"buy","seq":2138772,"price":1991.9,"qty":44704.0,"timestamp":1626994936937}
1626994936.9161248: {"feed":"book","product_id":"FI_ETHUSD_211231","side":"sell","seq":2199078,"price":2049.3,"qty":0.0,"timestamp":1626994936937}
1626994936.916169: {"feed":"book","product_id":"FI_ETHUSD_211231","side":"sell","seq":2199079,"price":2049.2,"qty":89404.0,"timestamp":1626994936937}
1626994936.916204: {"feed":"book","product_id":"PI_LTCUSD","side":"sell","seq":3423248,"price":119.54,"qty":0.0,"timestamp":1626994936938}
1626994936.916248: {"feed":"book","product_id":"PI_LTCUSD","side":"sell","seq":3423249,"price":119.66,"qty":1062.0,"timestamp":1626994936938}
1626994936.916288: {"feed":"book","product_id":"FI_ETHUSD_210730","side":"sell","seq":2138773,"price":2014.25,"qty":0.0,"timestamp":1626994936937}
1626994936.9163442: {"feed":"book","product_id":"FI_ETHUSD_210730","side":"sell","seq":2138774,"price":2014.15,"qty":45421.0,"timestamp":1626994936937}
1626994936.916385: {"feed":"book","product_id":"PI_LTCUSD","side":"sell","seq":3423250,"price":119.56,"qty":0.0,"timestamp":1626994936938}
1626994936.916425: {"feed":"book","product_id":"PI_LTCUSD","side":"sell","seq":3423251,"price":119.72,"qty":2096.0,"timestamp":1626994936938}
1626994936.916464: {"feed":"book","product_id":"PI_LTCUSD","side":"sell","seq":3423252,"price":119.57,"qty":0.0,"timestamp":1626994936938}
1626994936.916502: {"feed":"book","product_id":"PI_LTCUSD","side":"sell","seq":3423253,"price":119.76,"qty":5275.0,"timestamp":1626994936938}
1626994936.9185731: {"feed":"book","product_id":"PI_LTCUSD","side":"sell","seq":3423254,"price":119.51,"qty":320.0,"timestamp":1626994936941}
1626994936.9212859: {"feed":"book","product_id":"PI_LTCUSD","side":"buy","seq":3423255,"price":119.25,"qty":63.0,"timestamp":1626994936944}
1626994936.921396: {"feed":"book","product_id":"PI_LTCUSD","side":"buy","seq":3423256,"price":119.28,"qty":34194.0,"timestamp":1626994936944}
1626994936.924279: {"feed":"book","product_id":"FI_XBTUSD_210924","side":"sell","seq":13501910,"price":32274.5,"qty":20000.0,"timestamp":1626994936947}
1626994936.924386: {"feed":"book","product_id":"FI_XBTUSD_210924","side":"sell","seq":13501911,"price":32273.5,"qty":250001.0,"timestamp":1626994936947}
1626994936.924449: {"feed":"book","product_id":"FI_ETHUSD_211231","side":"sell","seq":2199080,"price":2049.25,"qty":0.0,"timestamp":1626994936947}
1626994936.9245088: {"feed":"book","product_id":"FI_ETHUSD_211231","side":"sell","seq":2199081,"price":2049.15,"qty":250002.0,"timestamp":1626994936947}
1626994936.924578: {"feed":"book","product_id":"FI_ETHUSD_210730","side":"buy","seq":2138775,"price":1991.85,"qty":0.0,"timestamp":1626994936947}
1626994936.924609: {"feed":"book","product_id":"FI_ETHUSD_210730","side":"buy","seq":2138776,"price":1991.95,"qty":250002.0,"timestamp":1626994936947}
1626994936.924635: {"feed":"book","product_id":"FI_ETHUSD_210730","side":"sell","seq":2138777,"price":2014.2,"qty":0.0,"timestamp":1626994936947}
1626994936.924662: {"feed":"book","product_id":"FI_ETHUSD_210730","side":"sell","seq":2138778,"price":2014.9,"qty":250002.0,"timestamp":1626994936947}
1626994936.9246862: {"feed":"book","product_id":"PI_ETHUSD","side":"buy","seq":26662064,"price":2003.7,"qty":0.0,"timestamp":1626994936949}
1626994936.924715: {"feed":"book","product_id":"PI_ETHUSD","side":"buy","seq":26662065,"price":2003.8,"qty":20000.0,"timestamp":1626994936949}
1626994936.9261088: {"feed":"book","product_id":"PI_ETHUSD","side":"buy","seq":26662066,"price":2003.75,"qty":3877.0,"timestamp":1626994936949}
1626994936.926215: {"feed":"book","product_id":"PI_ETHUSD","side":"buy","seq":26662067,"price":2003.85,"qty":24033.0,"timestamp":1626994936949}
1626994936.934784: {"feed":"book","product_id":"FI_XBTUSD_210924","side":"sell","seq":13501912,"price":32274.5,"qty":0.0,"timestamp":1626994936958}
1626994936.934907: {"feed":"book","product_id":"FI_XBTUSD_210924","side":"sell","seq":13501913,"price":32274.0,"qty":40966.0,"timestamp":1626994936958}
1626994936.957592: {"feed":"book","product_id":"PI_LTCUSD","side":"buy","seq":3423257,"price":118.69,"qty":0.0,"timestamp":1626994936980}
1626994936.957715: {"feed":"book","product_id":"PI_LTCUSD","side":"buy","seq":3423258,"price":119.11,"qty":52179.0,"timestamp":1626994936980}
1626994936.957768: {"feed":"book","product_id":"PI_LTCUSD","side":"buy","seq":3423259,"price":118.3,"qty":0.0,"timestamp":1626994936981}
1626994936.961663: {"feed":"book","product_id":"FI_XBTUSD_210924","side":"sell","seq":13501914,"price":32245.5,"qty":2430.0,"timestamp":1626994936985}
1626994936.9617689: {"feed":"book","product_id":"FI_XBTUSD_210924","side":"sell","seq":13501915,"price":32245.5,"qty":18529.0,"timestamp":1626994936985}
1626994936.961817: {"feed":"book","product_id":"FI_XBTUSD_210924","side":"buy","seq":13501916,"price":32188.5,"qty":881.0,"timestamp":1626994936985}
1626994936.961854: {"feed":"book","product_id":"FI_XBTUSD_210924","side":"buy","seq":13501917,"price":32188.5,"qty":18852.0,"timestamp":1626994936985}
1626994937.0286899: {"feed":"book","product_id":"PI_ETHUSD","side":"buy","seq":26662068,"price":2003.8,"qty":0.0,"timestamp":1626994937050}
1626994937.028821: {"feed":"book","product_id":"PI_ETHUSD","side":"buy","seq":26662069,"price":2003.9,"qty":20000.0,"timestamp":1626994937050}
1626994937.0331662: {"feed":"book","product_id":"PI_ETHUSD","side":"sell","seq":26662070,"price":2013.65,"qty":0.0,"timestamp":1626994937056}
1626994937.033298: {"feed":"book","product_id":"PI_ETHUSD","side":"sell","seq":26662071,"price":2013.55,"qty":49033.0,"timestamp":1626994937056}
1626994937.0333629: {"feed":"book","product_id":"PI_ETHUSD","side":"sell","seq":26662072,"price":2007.7,"qty":8742.0,"timestamp":1626994937056}
1626994937.0334039: {"feed":"book","product_id":"PI_ETHUSD","side":"sell","seq":26662073,"price":2007.7,"qty":25818.0,"timestamp":1626994937056}
1626994937.033439: {"feed":"book","product_id":"PI_ETHUSD","side":"buy","seq":26662074,"price":2001.9,"qty":0.0,"timestamp":1626994937056}
1626994937.0334861: {"feed":"book","product_id":"PI_ETHUSD","side":"buy","seq":26662075,"price":2001.9,"qty":13781.0,"timestamp":1626994937056}
1626994937.035188: {"feed":"book","product_id":"PI_ETHUSD","side":"sell","seq":26662076,"price":2008.4,"qty":0.0,"timestamp":1626994937056}
1626994937.035315: {"feed":"book","product_id":"PI_ETHUSD","side":"sell","seq":26662077,"price":2008.4,"qty":22832.0,"timestamp":1626994937056}
1626994937.035381: {"feed":"book","product_id":"PI_ETHUSD","side":"buy","seq":26662078,"price":2000.55,"qty":0.0,"timestamp":1626994937056}
1626994937.035434: {"feed":"book","product_id":"PI_ETHUSD","side":"buy","seq":26662079,"price":2000.55,"qty":23573.0,"timestamp":1626994937056}
1626994937.0376372: {"feed":"book","product_id":"PI_ETHUSD","side":"buy","seq":26662080,"price":2001.5,"qty":0.0,"timestamp":1626994937056}
1626994937.037766: {"feed":"book","product_id":"PI_ETHUSD","side":"buy","seq":26662081,"price":2001.5,"qty":16173.0,"timestamp":1626994937056}
1626994937.03784: {"feed":"book","product_id":"PI_ETHUSD","side":"sell","seq":26662082,"price":2007.1,"qty":0.0,"timestamp":1626994937056}
1626994937.037893: {"feed":"book","product_id":"PI_ETHUSD","side":"sell","seq":26662083,"price":2007.1,"qty":13263.0,"timestamp":1626994937056}
1626994937.0379221: {"feed":"book","product_id":"PI_ETHUSD","side":"buy","seq":26662084,"price":1996.5,"qty":0.0,"timestamp":1626994937056}
1626994937.037951: {"feed":"book","product_id":"PI_ETHUSD","side":"buy","seq":26662085,"price":1996.5,"qty":45567.0,"timestamp":1626994937056}
1626994937.037977: {"feed":"book","product_id":"PI_ETHUSD","side":"buy","seq":26662086,"price":1985.1,"qty":0.0,"timestamp":1626994937056}
1626994937.038004: {"feed":"book","product_id":"PI_ETHUSD","side":"buy","seq":26662087,"price":1985.1,"qty":66951.0,"timestamp":1626994937056}
1626994937.038029: {"feed":"book","product_id":"PI_ETHUSD","side":"sell","seq":26662088,"price":2021.45,"qty":0.0,"timestamp":1626994937056}
1626994937.0380569: {"feed":"book","product_id":"PI_ETHUSD","side":"sell","seq":26662089,"price":2021.45,"qty":67948.0,"timestamp":1626994937056}
1626994937.051475: {"feed":"book","product_id":"PI_ETHUSD","side":"buy","seq":26662090,"price":2003.45,"qty":6057.0,"timestamp":1626994937075}
1626994937.054055: {"feed":"book","product_id":"PI_ETHUSD","side":"buy","seq":26662091,"price":2003.45,"qty":12020.0,"timestamp":1626994937077}
1626994937.071008: {"feed":"book","product_id":"PI_LTCUSD","side":"buy","seq":3423260,"price":119.32,"qty":0.0,"timestamp":1626994937094}
1626994937.072861: {"feed":"book","product_id":"PI_LTCUSD","side":"sell","seq":3423261,"price":119.6,"qty":0.0,"timestamp":1626994937095}
1626994937.0729852: {"feed":"book","product_id":"PI_LTCUSD","side":"sell","seq":3423262,"price":119.62,"qty":3802.0,"timestamp":1626994937095}
1626994937.074902: {"feed":"book","product_id":"PI_LTCUSD","side":"buy","seq":3423263,"price":119.36,"qty":8082.0,"timestamp":1626994937096}
1626994937.1504571: {"feed":"book","product_id":"PI_LTCUSD","side":"buy","seq":3423264,"price":119.25,"qty":0.0,"timestamp":1626994937173}
1626994937.15253: {"feed":"book","product_id":"FI_XBTUSD_210924","side":"sell","seq":13501918,"price":32277.0,"qty":1045.0,"timestamp":1626994937176}
1626994937.156982: {"feed":"book","product_id":"PI_ETHUSD","side":"buy","seq":26662092,"price":2003.35,"qty":3959.0,"timestamp":1626994937180}
1626994937.164953: {"feed":"book","product_id":"FI_XBTUSD_210924","side":"sell","seq":13501919,"price":32245.5,"qty":2430.0,"timestamp":1626994937188}
1626994937.16507: {"feed":"book","product_id":"FI_XBTUSD_210924","side":"sell","seq":13501920,"price":32245.5,"qty":18531.0,"timestamp":1626994937188}
1626994937.165565: {"feed":"book","product_id":"FI_XBTUSD_210924","side":"buy","seq":13501921,"price":32188.5,"qty":881.0,"timestamp":1626994937188}
1626994937.165623: {"feed":"book","product_id":"FI_XBTUSD_210924","side":"buy","seq":13501922,"price":32188.5,"qty":18850.0,"timestamp":1626994937188}
1626994937.178113: {"feed":"book","product_id":"PI_LTCUSD","side":"buy","seq":3423265,"price":119.37,"qty":61.0,"timestamp":1626994937199}
1626994937.1782222: {"feed":"book","product_id":"PI_LTCUSD","side":"buy","seq":3423266,"price":119.38,"qty":4344.0,"timestamp":1626994937199}
1626994937.178271: {"feed":"book","product_id":"FI_ETHUSD_211231","side":"buy","seq":2199082,"price":2029.2,"qty":0.0,"timestamp":1626994937200}
1626994937.1783319: {"feed":"book","product_id":"FI_ETHUSD_211231","side":"buy","seq":2199083,"price":2029.3,"qty":420.0,"timestamp":1626994937200}
1626994937.186993: {"feed":"book","product_id":"PI_LTCUSD","side":"sell","seq":3423267,"price":119.66,"qty":5107.0,"timestamp":1626994937201}
1626994937.187101: {"feed":"book","product_id":"PI_ETHUSD","side":"buy","seq":26662093,"price":2003.65,"qty":6366.0,"timestamp":1626994937201}
1626994937.1871529: {"feed":"book","product_id":"PI_LTCUSD","side":"sell","seq":3423268,"price":119.63,"qty":4989.0,"timestamp":1626994937201}
1626994937.1871932: {"feed":"book","product_id":"FI_XBTUSD_210730","side":"buy","seq":5160085,"price":32173.5,"qty":0.0,"timestamp":1626994937202}
1626994937.1872509: {"feed":"book","product_id":"FI_XBTUSD_210730","side":"buy","seq":5160086,"price":32174.5,"qty":1200.0,"timestamp":1626994937202}
1626994937.190003: {"feed":"book","product_id":"FI_ETHUSD_211231","side":"buy","seq":2199084,"price":2029.25,"qty":0.0,"timestamp":1626994937213}
1626994937.190089: {"feed":"book","product_id":"FI_ETHUSD_211231","side":"buy","seq":2199085,"price":2029.35,"qty":50.0,"timestamp":1626994937213}
1626994937.1972742: {"feed":"book","product_id":"FI_ETHUSD_211231","side":"sell","seq":2199086,"price":2049.2,"qty":44305.0,"timestamp":1626994937219}
1626994937.197382: {"feed":"book","product_id":"FI_ETHUSD_211231","side":"sell","seq":2199087,"price":2049.1,"qty":45099.0,"timestamp":1626994937219}
1626994937.1974468: {"feed":"book","product_id":"FI_ETHUSD_211231","side":"sell","seq":2199088,"price":2049.2,"qty":0.0,"timestamp":1626994937219}
1626994937.197503: {"feed":"book","product_id":"FI_ETHUSD_211231","side":"sell","seq":2199089,"price":2049.1,"qty":89404.0,"timestamp":1626994937219}
1626994937.202676: {"feed":"book","product_id":"FI_XBTUSD_210730","side":"buy","seq":5160087,"price":32174.0,"qty":0.0,"timestamp":1626994937225}
1626994937.2027981: {"feed":"book","product_id":"FI_XBTUSD_210730","side":"buy","seq":5160088,"price":32175.0,"qty":50.0,"timestamp":1626994937225}
1626994937.228759: {"feed":"book","product_id":"PI_ETHUSD","side":"buy","seq":26662094,"price":2002.6,"qty":0.0,"timestamp":1626994937251}
1626994937.2429771: {"feed":"book","product_id":"FI_XBTUSD_210924","side":"buy","seq":13501923,"price":32205.5,"qty":3000.0,"timestamp":1626994937265}
1626994937.266322: {"feed":"book","product_id":"PI_ETHUSD","side":"buy","seq":26662095,"price":2001.5,"qty":0.0,"timestamp":1626994937287}
1626994937.2664142: {"feed":"book","product_id":"PI_ETHUSD","side":"buy","seq":26662096,"price":2001.5,"qty":16140.0,"timestamp":1626994937287}
1626994937.2664561: {"feed":"book","product_id":"PI_ETHUSD","side":"sell","seq":26662097,"price":2007.7,"qty":8742.0,"timestamp":1626994937287}
1626994937.266484: {"feed":"book","product_id":"PI_ETHUSD","side":"sell","seq":26662098,"price":2007.7,"qty":25851.0,"timestamp":1626994937287}
1626994937.266507: {"feed":"book","product_id":"PI_ETHUSD","side":"sell","seq":26662099,"price":2007.1,"qty":0.0,"timestamp":1626994937287}
1626994937.266538: {"feed":"book","product_id":"PI_ETHUSD","side":"sell","seq":26662100,"price":2007.1,"qty":13285.0,"timestamp":1626994937287}
1626994937.266565: {"feed":"book","product_id":"PI_ETHUSD","side":"buy","seq":26662101,"price":2001.9,"qty":0.0,"timestamp":1626994937287}
1626994937.266592: {"feed":"book","product_id":"PI_ETHUSD","side":"buy","seq":26662102,"price":2001.9,"qty":13759.0,"timestamp":1626994937287}
1626994937.266618: {"feed":"book","product_id":"PI_ETHUSD","side":"sell","seq":26662103,"price":2008.4,"qty":0.0,"timestamp":1626994937288}
1626994937.266645: {"feed":"book","product_id":"PI_ETHUSD","side":"sell","seq":26662104,"price":2008.4,"qty":22854.0,"timestamp":1626994937288}
1626994937.26667: {"feed":"book","product_id":"PI_ETHUSD","side":"buy","seq":26662105,"price":2000.55,"qty":0.0,"timestamp":1626994937288}
1626994937.266696: {"feed":"book","product_id":"PI_ETHUSD","side":"buy","seq":26662106,"price":2000.55,"qty":23551.0,"timestamp":1626994937288}
1626994937.266721: {"feed":"book","product_id":"PI_ETHUSD","side":"buy","seq":26662107,"price":1996.5,"qty":0.0,"timestamp":1626994937288}
1626994937.266748: {"feed":"book","product_id":"PI_ETHUSD","side":"buy","seq":26662108,"price":1996.5,"qty":45554.0,"timestamp":1626994937288}
1626994937.266772: {"feed":"book","product_id":"PI_ETHUSD","side":"sell","seq":26662109,"price":2013.55,"qty":0.0,"timestamp":1626994937288}
1626994937.266798: {"feed":"book","product_id":"PI_ETHUSD","side":"sell","seq":26662110,"price":2013.55,"qty":49045.0,"timestamp":1626994937288}
1626994937.28587: {"feed":"book","product_id":"PI_ETHUSD","side":"buy","seq":26662111,"price":2004.65,"qty":0.0,"timestamp":1626994937308}
1626994937.287961: {"feed":"book","product_id":"PI_ETHUSD","side":"buy","seq":26662112,"price":2003.45,"qty":29466.0,"timestamp":1626994937311}
1626994937.291248: {"feed":"book","product_id":"PI_ETHUSD","side":"buy","seq":26662113,"price":2004.1,"qty":600.0,"timestamp":1626994937314}
1626994937.295989: {"feed":"book","product_id":"PI_ETHUSD","side":"buy","seq":26662114,"price":2003.9,"qty":0.0,"timestamp":1626994937319}
1626994937.296118: {"feed":"book","product_id":"PI_ETHUSD","side":"buy","seq":26662115,"price":2004.15,"qty":20000.0,"timestamp":1626994937319}
1626994937.301226: {"feed":"book","product_id":"PI_ETHUSD","side":"buy","seq":26662116,"price":2003.45,"qty":12020.0,"timestamp":1626994937324}
1626994937.301306: {"feed":"book","product_id":"PI_ETHUSD","side":"buy","seq":26662117,"price":2003.5,"qty":17446.0,"timestamp":1626994937324}
1626994937.3440871: {"feed":"book","product_id":"FI_XRPUSD_210924","side":"sell","seq":602285,"price":0.5876,"qty":56.0,"timestamp":1626994937367}
1626994937.35165: {"feed":"book","product_id":"PI_ETHUSD","side":"sell","seq":26662118,"price":2008.0,"qty":0.0,"timestamp":1626994937375}
1626994937.3517811: {"feed":"book","product_id":"PI_ETHUSD","side":"sell","seq":26662119,"price":2007.45,"qty":42541.0,"timestamp":1626994937375}
1626994937.4025059: {"feed":"book","product_id":"FI_XBTUSD_210924","side":"sell","seq":13501924,"price":32274.0,"qty":20000.0,"timestamp":1626994937423}
1626994937.402616: {"feed":"book","product_id":"FI_XBTUSD_210924","side":"sell","seq":13501925,"price":32273.0,"qty":20966.0,"timestamp":1626994937423}
1626994937.402677: {"feed":"book","product_id":"FI_XBTUSD_210924","side":"sell","seq":13501926,"price":32245.5,"qty":2430.0,"timestamp":1626994937423}
1626994937.402714: {"feed":"book","product_id":"FI_XBTUSD_210924","side":"sell","seq":13501927,"price":32245.5,"qty":18530.0,"timestamp":1626994937423}
1626994937.402747: {"feed":"book","product_id":"FI_XBTUSD_210924","side":"buy","seq":13501928,"price":32188.5,"qty":881.0,"timestamp":1626994937423}
1626994937.4027798: {"feed":"book","product_id":"FI_XBTUSD_210924","side":"buy","seq":13501929,"price":32188.5,"qty":18851.0,"timestamp":1626994937423}
1626994937.410524: {"feed":"book","product_id":"FI_XBTUSD_210924","side":"sell","seq":13501930,"price":32274.0,"qty":0.0,"timestamp":1626994937433}
1626994937.410648: {"feed":"book","product_id":"FI_XBTUSD_210924","side":"sell","seq":13501931,"price":32273.5,"qty":270001.0,"timestamp":1626994937433}
1626994937.477817: {"feed":"book","product_id":"PI_ETHUSD","side":"buy","seq":26662120,"price":2001.5,"qty":0.0,"timestamp":1626994937499}
1626994937.477943: {"feed":"book","product_id":"PI_ETHUSD","side":"buy","seq":26662121,"price":2001.3,"qty":16971.0,"timestamp":1626994937499}
1626994937.483426: {"feed":"book","product_id":"PI_ETHUSD","side":"buy","seq":26662122,"price":2003.85,"qty":8207.0,"timestamp":1626994937505}
1626994937.483534: {"feed":"book","product_id":"PI_ETHUSD","side":"buy","seq":26662123,"price":2004.2,"qty":15826.0,"timestamp":1626994937505}
1626994937.486641: {"feed":"book","product_id":"PI_ETHUSD","side":"buy","seq":26662124,"price":2003.5,"qty":0.0,"timestamp":1626994937510}
1626994937.486766: {"feed":"book","product_id":"PI_ETHUSD","side":"buy","seq":26662125,"price":2003.55,"qty":17446.0,"timestamp":1626994937510}
1626994937.506788: {"feed":"book","product_id":"PI_ETHUSD","side":"sell","seq":26662126,"price":2006.75,"qty":0.0,"timestamp":1626994937530}
1626994937.5237498: {"feed":"book","product_id":"PI_ETHUSD","side":"sell","seq":26662127,"price":2006.5,"qty":2500.0,"timestamp":1626994937546}
1626994937.523875: {"feed":"book","product_id":"PI_ETHUSD","side":"buy","seq":26662128,"price":2003.0,"qty":5000.0,"timestamp":1626994937546}
1626994937.538805: {"feed":"book","product_id":"FI_XBTUSD_210924","side":"buy","seq":13501932,"price":32205.5,"qty":0.0,"timestamp":1626994937561}
1626994937.680861: {"feed":"book","product_id":"PI_ETHUSD","side":"sell","seq":26662129,"price":2007.7,"qty":8742.0,"timestamp":1626994937703}
1626994937.6809669: {"feed":"book","product_id":"PI_ETHUSD","side":"sell","seq":26662130,"price":2007.4,"qty":15857.0,"timestamp":1626994937703}
1626994937.808279: {"feed":"book","product_id":"PI_ETHUSD","side":"buy","seq":26662131,"price":2001.85,"qty":5005.0,"timestamp":1626994937830}
1626994937.883599: {"feed":"book","product_id":"FI_XBTUSD_210730","side":"buy","seq":5160089,"price":32145.0,"qty":0.0,"timestamp":1626994937906}
1626994937.88638: {"feed":"book","product_id":"PI_LTCUSD","side":"buy","seq":3423269,"price":119.26,"qty":3970.0,"timestamp":1626994937910}
1626994937.891367: {"feed":"book","product_id":"FI_XBTUSD_210924","side":"buy","seq":13501933,"price":32176.0,"qty":0.0,"timestamp":1626994937913}
1626994937.89149: {"feed":"book","product_id":"FI_XBTUSD_210924","side":"sell","seq":13501934,"price":32268.5,"qty":825.0,"timestamp":1626994937914}
1626994937.8943648: {"feed":"book","product_id":"FI_XBTUSD_210924","side":"sell","seq":13501935,"price":32273.5,"qty":250001.0,"timestamp":1626994937917}
1626994937.894472: {"feed":"book","product_id":"FI_XBTUSD_210924","side":"sell","seq":13501936,"price":32269.0,"qty":20000.0,"timestamp":1626994937917}
1626994937.9105: {"feed":"book","product_id":"FI_ETHUSD_211231","side":"buy","seq":2199090,"price":2028.0,"qty":0.0,"timestamp":1626994937933}
1626994937.916372: {"feed":"book","product_id":"PI_ETHUSD","side":"buy","seq":26662132,"price":2001.9,"qty":0.0,"timestamp":1626994937937}
1626994937.916499: {"feed":"book","product_id":"PI_ETHUSD","side":"buy","seq":26662133,"price":2001.9,"qty":12929.0,"timestamp":1626994937937}
1626994937.916542: {"feed":"book","product_id":"PI_ETHUSD","side":"sell","seq":26662134,"price":2007.1,"qty":0.0,"timestamp":1626994937937}
1626994937.916578: {"feed":"book","product_id":"PI_ETHUSD","side":"sell","seq":26662135,"price":2007.1,"qty":14120.0,"timestamp":1626994937937}
1626994937.916606: {"feed":"book","product_id":"PI_ETHUSD","side":"buy","seq":26662136,"price":2000.55,"qty":0.0,"timestamp":1626994937937}
1626994937.9166348: {"feed":"book","product_id":"PI_ETHUSD","side":"buy","seq":26662137,"price":2000.55,"qty":22723.0,"timestamp":1626994937937}
1626994937.916662: {"feed":"book","product_id":"PI_ETHUSD","side":"sell","seq":26662138,"price":2008.4,"qty":0.0,"timestamp":1626994937937}
1626994937.916689: {"feed":"book","product_id":"PI_ETHUSD","side":"sell","seq":26662139,"price":2008.4,"qty":23692.0,"timestamp":1626994937937}
1626994937.916714: {"feed":"book","product_id":"PI_ETHUSD","side":"buy","seq":26662140,"price":2001.3,"qty":0.0,"timestamp":1626994937937}
1626994937.9167402: {"feed":"book","product_id":"PI_ETHUSD","side":"buy","seq":26662141,"price":2001.3,"qty":16573.0,"timestamp":1626994937937}
1626994937.916765: {"feed":"book","product_id":"PI_ETHUSD","side":"buy","seq":26662142,"price":1996.5,"qty":0.0,"timestamp":1626994937937}
1626994937.91679: {"feed":"book","product_id":"PI_ETHUSD","side":"buy","seq":26662143,"price":1996.5,"qty":45084.0,"timestamp":1626994937937}
1626994937.916815: {"feed":"book","product_id":"PI_ETHUSD","side":"sell","seq":26662144,"price":2013.55,"qty":0.0,"timestamp":1626994937937}
1626994937.916841: {"feed":"book","product_id":"PI_ETHUSD","side":"sell","seq":26662145,"price":2013.55,"qty":49527.0,"timestamp":1626994937937}
1626994937.916866: {"feed":"book","product_id":"PI_ETHUSD","side":"sell","seq":26662146,"price":2007.4,"qty":0.0,"timestamp":1626994937937}
1626994937.9168909: {"feed":"book","product_id":"PI_ETHUSD","side":"sell","seq":26662147,"price":2007.4,"qty":15831.0,"timestamp":1626994937937}
1626994937.916915: {"feed":"book","product_id":"PI_ETHUSD","side":"buy","seq":26662148,"price":1985.1,"qty":0.0,"timestamp":1626994937937}
1626994937.9169412: {"feed":"book","product_id":"PI_ETHUSD","side":"buy","seq":26662149,"price":1985.1,"qty":66946.0,"timestamp":1626994937937}
1626994937.916965: {"feed":"book","product_id":"PI_ETHUSD","side":"sell","seq":26662150,"price":2021.45,"qty":0.0,"timestamp":1626994937937}
1626994937.916991: {"feed":"book","product_id":"PI_ETHUSD","side":"sell","seq":26662151,"price":2021.45,"qty":67943.0,"timestamp":1626994937937}
1626994937.9501219: {"feed":"book","product_id":"FI_ETHUSD_210730","side":"buy","seq":2138779,"price":1999.35,"qty":0.0,"timestamp":1626994937973}
1626994938.034396: {"feed":"book","product_id":"FI_XBTUSD_210924","side":"buy","seq":13501937,"price":32207.0,"qty":3000.0,"timestamp":1626994938058}
1626994938.100557: {"feed":"book","product_id":"PI_ETHUSD","side":"buy","seq":26662152,"price":2004.15,"qty":0.0,"timestamp":1626994938123}
1626994938.100683: {"feed":"book","product_id":"PI_ETHUSD","side":"buy","seq":26662153,"price":2004.25,"qty":20000.0,"timestamp":1626994938123}
1626994938.104077: {"feed":"book","product_id":"FI_XRPUSD_210924","side":"buy","seq":602286,"price":0.5838,"qty":0.0,"timestamp":1626994938126}
1626994938.111816: {"feed":"book","product_id":"PI_ETHUSD","side":"buy","seq":26662154,"price":2004.25,"qty":0.0,"timestamp":1626994938130}
1626994938.1119418: {"feed":"book","product_id":"PI_ETHUSD","side":"buy","seq":26662155,"price":2004.1,"qty":20600.0,"timestamp":1626994938130}
1626994938.1119978: {"feed":"book","product_id":"PI_ETHUSD","side":"buy","seq":26662156,"price":2003.75,"qty":0.0,"timestamp":1626994938133}
1626994938.112051: {"feed":"book","product_id":"PI_ETHUSD","side":"buy","seq":26662157,"price":2003.4,"qty":18966.0,"timestamp":1626994938133}
1626994938.11209: {"feed":"book","product_id":"PI_ETHUSD","side":"buy","seq":26662158,"price":2003.55,"qty":0.0,"timestamp":1626994938134}
1626994938.112134: {"feed":"book","product_id":"PI_ETHUSD","side":"buy","seq":26662159,"price":2003.5,"qty":17446.0,"timestamp":1626994938134}
1626994938.118099: {"feed":"book","product_id":"PI_ETHUSD","side":"buy","seq":26662160,"price":2001.9,"qty":0.0,"timestamp":1626994938141}
1626994938.118222: {"feed":"book","product_id":"PI_ETHUSD","side":"buy","seq":26662161,"price":2001.85,"qty":18023.0,"timestamp":1626994938141}
1626994938.118604: {"feed":"book","product_id":"PI_ETHUSD","side":"buy","seq":26662162,"price":2004.2,"qty":0.0,"timestamp":1626994938142}
1626994938.1186602: {"feed":"book","product_id":"PI_ETHUSD","side":"buy","seq":26662163,"price":2004.1,"qty":36426.0,"timestamp":1626994938142}
1626994938.154339: {"feed":"book","product_id":"PI_ETHUSD","side":"sell","seq":26662164,"price":2006.65,"qty":6513.0,"timestamp":1626994938175}
1626994938.160671: {"feed":"book","product_id":"PI_ETHUSD","side":"buy","seq":26662165,"price":2001.8,"qty":86012.0,"timestamp":1626994938183}
1626994938.160779: {"feed":"book","product_id":"PI_ETHUSD","side":"buy","seq":26662166,"price":2001.2,"qty":154306.0,"timestamp":1626994938183}
1626994938.1885052: {"feed":"book","product_id":"FI_ETHUSD_211231","side":"buy","seq":2199091,"price":2029.3,"qty":0.0,"timestamp":1626994938200}
1626994938.18863: {"feed":"book","product_id":"FI_ETHUSD_211231","side":"buy","seq":2199092,"price":2029.4,"qty":420.0,"timestamp":1626994938200}
1626994938.1886919: {"feed":"book","product_id":"FI_XBTUSD_210730","side":"buy","seq":5160090,"price":32174.5,"qty":0.0,"timestamp":1626994938202}
1626994938.188745: {"feed":"book","product_id":"FI_XBTUSD_210730","side":"buy","seq":5160091,"price":32175.5,"qty":1200.0,"timestamp":1626994938202}
1626994938.18879: {"feed":"book","product_id":"FI_XBTUSD_210924","side":"buy","seq":13501938,"price":32188.5,"qty":881.0,"timestamp":1626994938204}
1626994938.188826: {"feed":"book","product_id":"FI_XBTUSD_210924","side":"buy","seq":13501939,"price":32188.5,"qty":18852.0,"timestamp":1626994938204}
1626994938.204653: {"feed":"book","product_id":"FI_XBTUSD_210730","side":"buy","seq":5160092,"price":32175.0,"qty":0.0,"timestamp":1626994938227}
1626994938.2047749: {"feed":"book","product_id":"FI_XBTUSD_210730","side":"buy","seq":5160093,"price":32176.0,"qty":50.0,"timestamp":1626994938227}
1626994938.292566: {"feed":"book","product_id":"PI_ETHUSD","side":"buy","seq":26662167,"price":2003.9,"qty":1308.0,"timestamp":1626994938315}
1626994938.298579: {"feed":"book","product_id":"PI_ETHUSD","side":"buy","seq":26662168,"price":2004.6,"qty":2220.0,"timestamp":1626994938320}
1626994938.3000672: {"feed":"book","product_id":"PI_ETHUSD","side":"sell","seq":26662169,"price":2005.1,"qty":2186.0,"timestamp":1626994938320}
1626994938.309115: {"feed":"book","product_id":"PI_ETHUSD","side":"buy","seq":26662170,"price":2004.1,"qty":20600.0,"timestamp":1626994938331}
1626994938.309221: {"feed":"book","product_id":"PI_ETHUSD","side":"buy","seq":26662171,"price":2003.85,"qty":24033.0,"timestamp":1626994938331}
1626994938.309271: {"feed":"book","product_id":"PI_ETHUSD","side":"buy","seq":26662172,"price":2004.1,"qty":600.0,"timestamp":1626994938332}
1626994938.309309: {"feed":"book","product_id":"PI_ETHUSD","side":"buy","seq":26662173,"price":2003.8,"qty":20000.0,"timestamp":1626994938332}
1626994938.312054: {"feed":"book","product_id":"PI_ETHUSD","side":"sell","seq":26662174,"price":2005.1,"qty":0.0,"timestamp":1626994938333}
1626994938.3206809: {"feed":"book","product_id":"PI_ETHUSD","side":"buy","seq":26662175,"price":2003.5,"qty":0.0,"timestamp":1626994938342}
1626994938.320809: {"feed":"book","product_id":"PI_ETHUSD","side":"buy","seq":26662176,"price":2003.45,"qty":29466.0,"timestamp":1626994938342}
1626994938.323931: {"feed":"book","product_id":"PI_LTCUSD","side":"sell","seq":3423270,"price":119.65,"qty":13704.0,"timestamp":1626994938346}
1626994938.324037: {"feed":"book","product_id":"PI_ETHUSD","side":"buy","seq":26662177,"price":2003.45,"qty":12020.0,"timestamp":1626994938347}
1626994938.332581: {"feed":"book","product_id":"FI_ETHUSD_211231","side":"buy","seq":2199093,"price":2029.35,"qty":0.0,"timestamp":1626994938353}
1626994938.3327072: {"feed":"book","product_id":"FI_ETHUSD_211231","side":"buy","seq":2199094,"price":2029.45,"qty":50.0,"timestamp":1626994938353}
1626994938.335676: {"feed":"book","product_id":"PI_ETHUSD","side":"buy","seq":26662178,"price":2003.3,"qty":0.0,"timestamp":1626994938358}
1626994938.3448288: {"feed":"book","product_id":"PI_ETHUSD","side":"sell","seq":26662179,"price":2007.4,"qty":0.0,"timestamp":1626994938364}
1626994938.344953: {"feed":"book","product_id":"PI_ETHUSD","side":"sell","seq":26662180,"price":2007.4,"qty":16119.0,"timestamp":1626994938364}
1626994938.3450198: {"feed":"book","product_id":"PI_ETHUSD","side":"buy","seq":26662181,"price":2001.3,"qty":0.0,"timestamp":1626994938364}
1626994938.345076: {"feed":"book","product_id":"PI_ETHUSD","side":"buy","seq":26662182,"price":2001.3,"qty":16287.0,"timestamp":1626994938364}
1626994938.3451478: {"feed":"book","product_id":"PI_ETHUSD","side":"sell","seq":26662183,"price":2007.1,"qty":0.0,"timestamp":1626994938364}
1626994938.3451772: {"feed":"book","product_id":"PI_ETHUSD","side":"sell","seq":26662184,"price":2007.1,"qty":14312.0,"timestamp":1626994938364}
1626994938.3452039: {"feed":"book","product_id":"PI_ETHUSD","side":"buy","seq":26662185,"price":2000.55,"qty":0.0,"timestamp":1626994938364}
1626994938.345231: {"feed":"book","product_id":"PI_ETHUSD","side":"buy","seq":26662186,"price":2000.55,"qty":22533.0,"timestamp":1626994938364}
1626994938.3452559: {"feed":"book","product_id":"PI_ETHUSD","side":"sell","seq":26662187,"price":2008.4,"qty":0.0,"timestamp":1626994938365}
1626994938.345282: {"feed":"book","product_id":"PI_ETHUSD","side":"sell","seq":26662188,"price":2008.4,"qty":23884.0,"timestamp":1626994938365}
1626994938.3453062: {"feed":"book","product_id":"PI_ETHUSD","side":"buy","seq":26662189,"price":1996.5,"qty":0.0,"timestamp":1626994938365}
1626994938.345332: {"feed":"book","product_id":"PI_ETHUSD","side":"buy","seq":26662190,"price":1996.5,"qty":44976.0,"timestamp":1626994938365}
1626994938.345356: {"feed":"book","product_id":"PI_ETHUSD","side":"sell","seq":26662191,"price":2013.55,"qty":0.0,"timestamp":1626994938365}
1626994938.345382: {"feed":"book","product_id":"PI_ETHUSD","side":"sell","seq":26662192,"price":2013.55,"qty":49637.0,"timestamp":1626994938365}
1626994938.346477: {"feed":"book","product_id":"PI_ETHUSD","side":"buy","seq":26662193,"price":1985.1,"qty":0.0,"timestamp":1626994938365}
1626994938.346564: {"feed":"book","product_id":"PI_ETHUSD","side":"buy","seq":26662194,"price":1985.1,"qty":66945.0,"timestamp":1626994938365}
