1618678148.958046: [496,{"b":[["2180.63000","0.00000000","1618678148.927967"]],"c":"2904242507"},"book-1000","ETH/CHF"]
1618678148.967299: [1664,{"a":[["13.267400","0.00000000","1618678148.936067"]],"c":"681661877"},"book-1000","WAVES/EUR"]
1618678148.969235: [1664,{"b":[["13.176500","143.35200000","1618678148.936329"]],"c":"681661877"},"book-1000","WAVES/EUR"]
1618678148.977: [1664,{"b":[["13.173300","132.43865450","1618678148.950704"]],"c":"681661877"},"book-1000","WAVES/EUR"]
1618678148.983148: [3648,{"b":[["0.00755900","43.08291753","1618678148.956379"]],"c":"1111895733"},"book-1000","KSM/XBT"]
1618678148.998868: [496,{"b":[["2183.31000","0.00000000","1618678148.965103"]],"c":"2182540856"},"book-1000","ETH/CHF"]
1618678149.000265: [1664,{"b":[["13.143900","8368.00000000","1618678148.967752"]],"c":"681661877"},"book-1000","WAVES/EUR"]
1618678149.001924: [992,{"a":[["354.73000000","0.00000000","1618678148.970999"]],"c":"1114644424"},"book-1000","XMR/USD"]
1618678149.0129201: [1920,{"b":[["0.042910","15940.15183395","1618678148.983985"]],"c":"3354760019"},"book-1000","SC/EUR"]
1618678149.036681: [1664,{"a":[["13.234700","135.51000000","1618678149.009329"]],"c":"3149257780"},"book-1000","WAVES/EUR"]
1618678149.0397089: [1664,{"a":[["13.274800","0.00000000","1618678149.012418"]],"c":"3149257780"},"book-1000","WAVES/EUR"]
1618678149.0432398: [496,{"b":[["2180.67000","3.00000000","1618678149.014754"]],"c":"460419750"},"book-1000","ETH/CHF"]
1618678149.044388: [3648,{"b":[["0.00756000","2.17777000","1618678149.016286"]],"c":"1945158869"},"book-1000","KSM/XBT"]
1618678149.0704582: [496,{"a":[["2191.97000","1.15978265","1618678149.042855"]],"c":"1848683692"},"book-1000","ETH/CHF"]
1618678149.072155: [496,{"a":[["2191.99000","0.00000000","1618678149.045463"]],"c":"741484958"},"book-1000","ETH/CHF"]
1618678149.087539: [1920,{"b":[["0.042940","5814.98681653","1618678149.056425"]],"c":"1494072052"},"book-1000","SC/EUR"]
1618678149.1188009: [1920,{"a":[["0.043190","0.00000000","1618678149.092122"]],"c":"4228712795"},"book-1000","SC/EUR"]
1618678149.122277: [1920,{"a":[["0.043170","183452.67067430","1618678149.092258"]],"c":"3884548054"},"book-1000","SC/EUR"]
1618678149.145706: [1920,{"a":[["0.043030","101234.61211976","1618678149.116577"]],"c":"2553435078"},"book-1000","SC/EUR"]
1618678149.151318: [1840,{"a":[["9.596650","0.00000000","1618678149.123351"]],"c":"1533700967"},"book-1000","OMG/USD"]
1618678149.160214: [1664,{"b":[["13.173000","0.00000000","1618678149.132439"]],"c":"3149257780"},"book-1000","WAVES/EUR"]
1618678149.162546: [1664,{"b":[["13.178400","99.73802090","1618678149.133945"]],"c":"1727104028"},"book-1000","WAVES/EUR"]
1618678149.166309: [1664,{"b":[["13.191400","0.00000000","1618678149.137806"]],"c":"550747432"},"book-1000","WAVES/EUR"]
1618678149.1729422: [5104,{"a":[["0.000027810","671.30348000","1618678149.144171"]],"c":"2708378618"},"book-1000","OCEAN/XBT"]
1618678149.1822872: [1360,{"a":[["0.000022920","9695.96187490","1618678149.152560"]],"c":"1698477455"},"book-1000","ADA/XBT"]
1618678149.1876411: [1840,{"a":[["9.598886","148.00000000","1618678149.160157"]],"c":"4045700677"},"book-1000","OMG/USD"]
1618678149.188979: [1920,{"a":[["0.043180","0.00000000","1618678149.160739"]],"c":"2471288368"},"book-1000","SC/EUR"]
1618678149.191948: [1664,{"a":[["13.234600","500.00000000","1618678149.162776"]],"c":"849114780"},"book-1000","WAVES/EUR"]
1618678149.1933088: [1840,{"a":[["9.596648","136.99635811","1618678149.165167"]],"c":"3295123804"},"book-1000","OMG/USD"]
1618678149.194208: [1920,{"a":[["0.043040","3348.38405103","1618678149.166996"]],"c":"614214718"},"book-1000","SC/EUR"]
1618678149.200638: [1664,{"b":[["13.187900","0.00000000","1618678149.169828"]],"c":"1180190646"},"book-1000","WAVES/EUR"]
1618678149.20254: [1920,{"b":[["0.042910","0.00000000","1618678149.170756"]],"c":"1424333461"},"book-1000","SC/EUR"]
1618678149.234368: [1920,{"a":[["0.043160","905325.33415860","1618678149.206404"]],"c":"1108953480"},"book-1000","SC/EUR"]
1618678149.250368: [1360,{"a":[["0.000022910","13566.65806089","1618678149.221932"]],"c":"746207762"},"book-1000","ADA/XBT"]
1618678149.254195: [464,{"b":[["56060.00000","0.00000000","1618678149.222278"]],"c":"3918220800"},"book-1000","XBT/CHF"]
1618678149.255775: [1664,{"a":[["13.252500","148.42080000","1618678149.222355"]],"c":"2325636608"},"book-1000","WAVES/EUR"]
1618678149.257084: [464,{"b":[["56060.00000","0.00162728","1618678149.222666"]],"c":"3435913667"},"book-1000","XBT/CHF"]
1618678149.2583418: [1664,{"a":[["13.241300","0.00000000","1618678149.222800"]],"c":"1954900828"},"book-1000","WAVES/EUR"]
1618678149.259506: [1664,{"b":[["13.168800","15.06359134","1618678149.227574"]],"c":"1954900828"},"book-1000","WAVES/EUR"]
1618678149.265654: [496,{"a":[["2191.96000","3.00000000","1618678149.237949"]],"c":"526183599"},"book-1000","ETH/CHF"]
1618678149.275123: [1920,{"a":[["0.043160","0.00000000","1618678149.246894"]],"c":"1424333461"},"book-1000","SC/EUR"]
1618678149.28703: [1920,{"a":[["0.043040","23348.38405103","1618678149.258579"]],"c":"1801407346"},"book-1000","SC/EUR"]
1618678149.307698: {"event":"heartbeat"}
1618678149.315398: [1920,{"a":[["0.043150","905325.33415860","1618678149.285857"]],"c":"1943814621"},"book-1000","SC/EUR"]
1618678149.328734: [1840,{"a":[["9.596649","0.00000000","1618678149.301680"]],"c":"144546025"},"book-1000","OMG/USD"]
1618678149.330682: [1840,{"a":[["9.596650","200.00000000","1618678149.302106"]],"c":"2989625787"},"book-1000","OMG/USD"]
1618678149.346486: [496,{"a":[["2191.97000","0.00000000","1618678149.313107"]],"c":"3330928048"},"book-1000","ETH/CHF"]
1618678149.348372: [496,{"a":[["2191.95000","1.15978265","1618678149.320684"]],"c":"649087052"},"book-1000","ETH/CHF"]
1618678149.3495018: [1920,{"a":[["0.043050","44120.00000000","1618678149.322369"]],"c":"2336237208"},"book-1000","SC/EUR"]
1618678149.352712: [992,{"b":[["354.13000000","0.00000000","1618678149.324755"]],"c":"1421611479"},"book-1000","XMR/USD"]
1618678149.3628302: [1920,{"a":[["0.045370","0.00000000","1618678149.334697"]],"c":"2336237208"},"book-1000","SC/EUR"]
1618678149.366642: [1664,{"b":[["13.144400","0.00000000","1618678149.337438"]],"c":"1954900828"},"book-1000","WAVES/EUR"]
1618678149.367978: [1920,{"a":[["0.043150","0.00000000","1618678149.338058"]],"c":"1986584810"},"book-1000","SC/EUR"]
1618678149.372305: [5104,{"a":[["0.000027790","456.53817937","1618678149.344876"]],"c":"3518257989"},"book-1000","OCEAN/XBT"]
1618678149.380424: [1840,{"a":[["9.596647","200.00000000","1618678149.352439"]],"c":"3402436774"},"book-1000","OMG/USD"]
1618678149.392464: [992,{"b":[["354.05000000","6.85954924","1618678149.364518"]],"c":"531996807"},"book-1000","XMR/USD"]
1618678149.425764: [1664,{"b":[["13.199300","0.00000000","1618678149.398742"]],"c":"258513151"},"book-1000","WAVES/EUR"]
1618678149.429237: [1920,{"a":[["0.044790","152505.00000000","1618678149.401051"]],"c":"1986584810"},"book-1000","SC/EUR"]
1618678149.4323351: [1664,{"b":[["13.168900","1396.00000000","1618678149.401415"]],"c":"258513151"},"book-1000","WAVES/EUR"]
1618678149.433868: [1840,{"a":[["9.596650","0.00000000","1618678149.404996"]],"c":"4219638721"},"book-1000","OMG/USD"]
1618678149.450289: [1664,{"b":[["13.178700","66.28244053","1618678149.422846"]],"c":"4132377039"},"book-1000","WAVES/EUR"]
1618678149.468822: [1664,{"b":[["13.206300","0.00000000","1618678149.440051"]],"c":"4012046242"},"book-1000","WAVES/EUR"]
1618678149.471117: [5104,{"a":[["0.000027850","628.44452421","1618678149.443093"]],"c":"2483251139"},"book-1000","OCEAN/XBT"]
1618678149.4768682: [5104,{"a":[["0.000027870","0.00000000","1618678149.448246"]],"c":"886669179"},"book-1000","OCEAN/XBT"]
1618678149.497476: [992,{"b":[["353.94000000","0.00000000","1618678149.470448"]],"c":"1416056807"},"book-1000","XMR/USD"]
1618678149.507806: [1664,{"b":[["13.206500","151.44057849","1618678149.481937"]],"c":"579633111"},"book-1000","WAVES/EUR"]
1618678149.518613: [496,{"a":[["2191.96000","0.00000000","1618678149.491315"]],"c":"195322656"},"book-1000","ETH/CHF"]
1618678149.564895: [992,{"b":[["353.62000000","15.27000000","1618678149.537972"]],"c":"3048302467"},"book-1000","XMR/USD"]
1618678149.576051: [496,{"a":[["2191.94000","3.00000000","1618678149.546353"]],"c":"1138578044"},"book-1000","ETH/CHF"]
1618678149.585912: [1664,{"b":[["13.202100","0.00000000","1618678149.558087"]],"c":"4165172291"},"book-1000","WAVES/EUR"]
1618678149.613025: [496,{"a":[["2191.93000","1.15978265","1618678149.584094"]],"c":"1724513265"},"book-1000","ETH/CHF"]
1618678149.6141498: [496,{"a":[["2191.95000","0.00000000","1618678149.585031"]],"c":"422868312"},"book-1000","ETH/CHF"]
1618678149.650347: [1920,{"a":[["0.044160","0.00000000","1618678149.622383"]],"c":"1986584810"},"book-1000","SC/EUR"]
1618678149.655306: [496,{"a":[["2191.55000","0.79681000","1618678149.625499"]],"c":"2705046444"},"book-1000","ETH/CHF"]
1618678149.666411: [464,{"b":[["56119.00000","0.09837187","1618678149.640054"]],"c":"1506159216"},"book-1000","XBT/CHF"]
1618678149.682419: [496,{"a":[["2192.11000","0.00000000","1618678149.654910"]],"c":"3347371942"},"book-1000","ETH/CHF"]
1618678149.687753: [1920,{"a":[["0.044250","328840.38297917","1618678149.658142"]],"c":"1986584810"},"book-1000","SC/EUR"]
1618678149.69152: [1920,{"b":[["0.042940","21121.66087270","1618678149.662170"]],"c":"4112957207"},"book-1000","SC/EUR"]
1618678149.695486: [496,{"b":[["2180.67000","0.00000000","1618678149.666890"]],"c":"1591954232"},"book-1000","ETH/CHF"]
1618678149.719637: [1664,{"b":[["13.144500","75.72086261","1618678149.690553"]],"c":"4165172291"},"book-1000","WAVES/EUR"]
1618678149.7374861: [992,{"b":[["354.06000000","5.00000000","1618678149.707666"]],"c":"2981121245"},"book-1000","XMR/USD"]
1618678149.749239: [1360,{"b":[["0.000022870","12859.48103087","1618678149.719292"]],"c":"1382923722"},"book-1000","ADA/XBT"]
1618678149.7532291: [5104,{"a":[["0.000027790","0.00000000","1618678149.725580"]],"c":"3449492293"},"book-1000","OCEAN/XBT"]
1618678149.755643: [1920,{"a":[["0.043110","0.00000000","1618678149.728210"]],"c":"1646711847"},"book-1000","SC/EUR"]
1618678149.774102: [992,{"b":[["353.17000000","22.72500000","1618678149.745147"]],"c":"2981121245"},"book-1000","XMR/USD"]
1618678149.787094: [1920,{"a":[["0.043820","0.00000000","1618678149.758640"]],"c":"1646711847"},"book-1000","SC/EUR"]
1618678149.79014: [496,{"a":[["2191.98000","0.00000000","1618678149.759423"]],"c":"3870589661"},"book-1000","ETH/CHF"]
1618678149.791029: [1664,{"a":[["13.241600","47.58135082","1618678149.760212"]],"c":"1915821329"},"book-1000","WAVES/EUR"]
1618678149.792454: [992,{"b":[["354.07000000","7.57500000","1618678149.762406"]],"c":"4068297219"},"book-1000","XMR/USD"]
1618678149.798008: [5104,{"a":[["0.000027850","0.00000000","1618678149.771361"]],"c":"2127200917"},"book-1000","OCEAN/XBT"]
1618678149.8075361: [5104,{"a":[["0.000027810","605.90348000","1618678149.780201"]],"c":"3796947629"},"book-1000","OCEAN/XBT"]
1618678149.828793: [1360,{"b":[["0.000022880","5031.75709827","1618678149.801933"]],"c":"2076761869"},"book-1000","ADA/XBT"]
1618678149.835576: [496,{"a":[["2191.54000","3.00000000","1618678149.807672"]],"c":"544337099"},"book-1000","ETH/CHF"]
1618678149.836967: [5104,{"a":[["0.000027870","732.36854110","1618678149.808458"]],"c":"246827782"},"book-1000","OCEAN/XBT"]
1618678149.8379982: [1360,{"a":[["0.000022940","21989.81983580","1618678149.808904"]],"c":"1318003710"},"book-1000","ADA/XBT"]
1618678149.841165: [1360,{"a":[["0.000022940","21242.76003936","1618678149.812312"]],"c":"196032490"},"book-1000","ADA/XBT"]
1618678149.8469: [1920,{"a":[["0.043590","147120.00000000","1618678149.820898"]],"c":"1646711847"},"book-1000","SC/EUR"]
1618678149.8784509: [1920,{"b":[["0.042940","5814.98681653","1618678149.850691"]],"c":"2765773025"},"book-1000","SC/EUR"]
1618678149.8822038: [496,{"a":[["2191.94000","0.00000000","1618678149.855176"]],"c":"2143055782"},"book-1000","ETH/CHF"]
1618678149.883295: [1360,{"b":[["0.000022870","18544.79692254","1618678149.856672"]],"c":"311932793"},"book-1000","ADA/XBT"]
1618678149.889931: [1920,{"b":[["0.040940","23282.88707799","1618678149.862555"]],"c":"2765773025"},"book-1000","SC/EUR"]
1618678149.892761: [1840,{"b":[["9.575133","0.00000000","1618678149.863955"]],"c":"4053655716"},"book-1000","OMG/USD"]
1618678149.916039: [464,{"b":[["56119.00000","0.00000000","1618678149.886070"]],"c":"731437724"},"book-1000","XBT/CHF"]
1618678149.918262: [464,{"a":[["56886.20000","0.00000000","1618678149.886142"]],"c":"731437724"},"book-1000","XBT/CHF"]
1618678149.91996: [464,{"b":[["55544.70000","0.00000000","1618678149.886380"]],"c":"731437724"},"book-1000","XBT/CHF"]
1618678149.921469: [496,{"b":[["2183.33000","0.83827527","1618678149.887029"]],"c":"1291874287"},"book-1000","ETH/CHF"]
1618678149.9289222: [3648,{"a":[["0.00839500","0.00000000","1618678149.900980"]],"c":"1945158869"},"book-1000","KSM/XBT"]
1618678149.950311: [496,{"a":[["2191.93000","0.00000000","1618678149.923150"]],"c":"2765448188"},"book-1000","ETH/CHF"]
1618678149.951675: [496,{"a":[["2192.02000","1.15978265","1618678149.923923"]],"c":"2788419540"},"book-1000","ETH/CHF"]
1618678149.969634: [464,{"b":[["56060.00000","0.10006519","1618678149.939110"]],"c":"2079998735"},"book-1000","XBT/CHF"]
1618678149.971864: [464,{"b":[["55610.80000","0.55684752","1618678149.939419"]],"c":"2079998735"},"book-1000","XBT/CHF"]
1618678149.97354: [1664,{"b":[["13.206700","98.00000000","1618678149.939987"]],"c":"4277407687"},"book-1000","WAVES/EUR"]
1618678149.9748669: [1840,{"a":[["9.606402","0.00000000","1618678149.942780"]],"c":"4053655716"},"book-1000","OMG/USD"]
1618678149.9762151: [496,{"b":[["2183.34000","1.51279891","1618678149.943783"]],"c":"2687937261"},"book-1000","ETH/CHF"]
1618678149.977001: [496,{"b":[["2183.32000","0.00000000","1618678149.943830"]],"c":"3842264730"},"book-1000","ETH/CHF"]
1618678149.9777348: [464,{"a":[["56959.80000","0.55684752","1618678149.945749"]],"c":"2079998735"},"book-1000","XBT/CHF"]
1618678149.979064: [464,{"b":[["55973.30000","0.04245474","1618678149.948371"]],"c":"3424443305"},"book-1000","XBT/CHF"]
1618678149.980494: [1840,{"b":[["9.584187","0.00000000","1618678149.951650"]],"c":"1899898726"},"book-1000","OMG/USD"]
1618678149.98416: [1360,{"a":[["0.000022910","9283.46505460","1618678149.957152"]],"c":"2877265113"},"book-1000","ADA/XBT"]
1618678149.986977: [5104,{"a":[["0.000027810","1062.44165937","1618678149.957388"]],"c":"3518695041"},"book-1000","OCEAN/XBT"]
1618678149.9876711: [1920,{"a":[["0.044000","1818.18181000","1618678149.957651"]],"c":"2765773025"},"book-1000","SC/EUR"]
1618678149.9931881: [496,{"b":[["2183.20000","0.00000000","1618678149.966799"]],"c":"788036933"},"book-1000","ETH/CHF"]
1618678149.994148: [496,{"a":[["2192.91000","0.14790000","1618678149.966891"]],"c":"1852591537"},"book-1000","ETH/CHF"]
1618678149.998865: [1664,{"b":[["13.202800","33.13896794","1618678149.971730"]],"c":"874161956"},"book-1000","WAVES/EUR"]
1618678150.000799: [1664,{"a":[["13.241600","0.00000000","1618678149.971935"]],"c":"723189690"},"book-1000","WAVES/EUR"]
1618678150.0073159: [1840,{"b":[["9.583710","137.02172242","1618678149.980908"]],"c":"510576313"},"book-1000","OMG/USD"]
1618678150.014781: [496,{"b":[["2179.42000","0.00000000","1618678149.985216"]],"c":"432298670"},"book-1000","ETH/CHF"]
1618678150.016595: [1360,{"b":[["0.000022870","12859.48103087","1618678149.989539"]],"c":"2991002698"},"book-1000","ADA/XBT"]
1618678150.020083: [1664,{"b":[["13.178700","0.00000000","1618678149.990959"]],"c":"193197959"},"book-1000","WAVES/EUR"]
1618678150.027662: [1840,{"b":[["9.574823","0.00000000","1618678150.000117"]],"c":"166902142"},"book-1000","OMG/USD"]
1618678150.032058: [1664,{"a":[["13.270600","415.00000000","1618678150.004200"]],"c":"193197959"},"book-1000","WAVES/EUR"]
1618678150.034157: [992,{"b":[["352.25000000","0.00000000","1618678150.006075"]],"c":"4068297219"},"book-1000","XMR/USD"]
1618678150.042735: [992,{"b":[["354.07000000","0.00000000","1618678150.012565"]],"c":"2981121245"},"book-1000","XMR/USD"]
1618678150.045582: [5104,{"a":[["0.000027810","468.53817937","1618678150.015979"]],"c":"1956493818"},"book-1000","OCEAN/XBT"]
1618678150.046636: [992,{"b":[["354.06000000","0.00000000","1618678150.018254"]],"c":"3048302467"},"book-1000","XMR/USD"]
1618678150.048925: [3648,{"b":[["0.00750800","5.86086666","1618678150.019794"]],"c":"1945158869"},"book-1000","KSM/XBT"]
1618678150.04974: [992,{"a":[["354.49000000","1.40000000","1618678150.021368"]],"c":"2022094717"},"book-1000","XMR/USD"]
1618678150.051438: [992,{"b":[["354.07000000","1.40000000","1618678150.021952"]],"c":"4163483300"},"book-1000","XMR/USD"]
1618678150.0541859: [496,{"a":[["2190.17000","0.31000000","1618678150.024806"]],"c":"596495583"},"book-1000","ETH/CHF"]
1618678150.054995: [992,{"a":[["354.47000000","12.24000000","1618678150.026173"]],"c":"57852165"},"book-1000","XMR/USD"]
1618678150.0567439: [1840,{"b":[["9.572568","0.00000000","1618678150.027338"]],"c":"1121339737"},"book-1000","OMG/USD"]
1618678150.069487: [496,{"b":[["2180.41000","0.31000000","1618678150.041749"]],"c":"693687854"},"book-1000","ETH/CHF"]
1618678150.0834088: [992,{"b":[["354.07000000","0.00000000","1618678150.055654"]],"c":"2212348124"},"book-1000","XMR/USD"]
1618678150.0862541: [1920,{"a":[["0.043010","8500.00000000","1618678150.057347"]],"c":"2887409406"},"book-1000","SC/EUR"]
1618678150.0916438: [5104,{"a":[["0.000027860","17009.29750280","1618678150.064648"]],"c":"2138949054"},"book-1000","OCEAN/XBT"]
1618678150.095943: [992,{"a":[["354.43000000","1.40000000","1618678150.067905"]],"c":"2532178194"},"book-1000","XMR/USD"]
1618678150.098295: [992,{"a":[["354.49000000","0.00000000","1618678150.067965"]],"c":"532243184"},"book-1000","XMR/USD"]
1618678150.100558: [1360,{"a":[["0.000022920","10694.79418834","1618678150.071901"]],"c":"1039372151"},"book-1000","ADA/XBT"]
1618678150.1062222: [1920,{"b":[["0.040910","0.00000000","1618678150.076968"]],"c":"2887409406"},"book-1000","SC/EUR"]
1618678150.109764: [1920,{"b":[["0.042860","14316.67507435","1618678150.078532"]],"c":"730171430"},"book-1000","SC/EUR"]
1618678150.118795: [1920,{"b":[["0.042860","5816.67507435","1618678150.090544"]],"c":"2887409406"},"book-1000","SC/EUR"]
1618678150.12236: [1920,{"b":[["0.042870","8500.00000000","1618678150.090766"]],"c":"1708133506"},"book-1000","SC/EUR"]
1618678150.125272: [3648,{"b":[["0.00756200","0.16890103","1618678150.092075"]],"c":"2171477125"},"book-1000","KSM/XBT"]
1618678150.126045: [992,{"a":[["354.53000000","0.00000000","1618678150.093273"]],"c":"2001164777"},"book-1000","XMR/USD"]
1618678150.1277719: [1920,{"a":[["0.043190","183452.67067430","1618678150.094286"]],"c":"2100086355"},"book-1000","SC/EUR"]
1618678150.130075: [1840,{"b":[["9.575720","0.00000000","1618678150.098426"]],"c":"4217015346"},"book-1000","OMG/USD"]
1618678150.131972: [1920,{"b":[["0.042770","0.00000000","1618678150.104170"]],"c":"2741385609"},"book-1000","SC/EUR"]
1618678150.135102: [1840,{"a":[["9.598692","0.00000000","1618678150.107362"]],"c":"2276429990"},"book-1000","OMG/USD"]
1618678150.138416: [992,{"b":[["352.11000000","0.00000000","1618678150.110730"]],"c":"2001164777"},"book-1000","XMR/USD"]
1618678150.141877: [1920,{"a":[["0.043170","0.00000000","1618678150.113986"]],"c":"2263162417"},"book-1000","SC/EUR"]
1618678150.144675: [1920,{"a":[["0.043150","136355.00000000","1618678150.114617"]],"c":"3791808254"},"book-1000","SC/EUR"]
1618678150.1469939: [992,{"b":[["353.49000000","0.00000000","1618678150.118653"]],"c":"601335177"},"book-1000","XMR/USD"]
1618678150.148683: [992,{"b":[["353.57000000","5.16607376","1618678150.119557"]],"c":"1343372634"},"book-1000","XMR/USD"]
1618678150.1527271: [992,{"b":[["353.25000000","3.63200000","1618678150.124390"]],"c":"1343372634"},"book-1000","XMR/USD"]
1618678150.159404: [992,{"a":[["354.77000000","0.00000000","1618678150.130698"]],"c":"4071087336"},"book-1000","XMR/USD"]
1618678150.1621928: [496,{"b":[["2178.51000","0.13720000","1618678150.134799"]],"c":"1330787562"},"book-1000","ETH/CHF"]
1618678150.163091: [3648,{"b":[["0.00756100","1.08874000","1618678150.135759"]],"c":"444145806"},"book-1000","KSM/XBT"]
1618678150.163979: [3648,{"b":[["0.00756300","0.21000000","1618678150.135878"]],"c":"1159811507"},"book-1000","KSM/XBT"]
1618678150.1649249: [992,{"a":[["354.42000000","6.86044565","1618678150.136596"]],"c":"3464522487"},"book-1000","XMR/USD"]
1618678150.166584: [1840,{"b":[["9.549530","0.00000000","1618678150.136971"]],"c":"2276429990"},"book-1000","OMG/USD"]
1618678150.174457: [992,{"b":[["353.57000000","0.82000000","1618678150.145594"]],"c":"1651375334"},"book-1000","XMR/USD"]
1618678150.1773078: [3648,{"b":[["0.00732800","0.00000000","1618678150.146535"]],"c":"1159811507"},"book-1000","KSM/XBT"]
1618678150.17824: [992,{"b":[["344.29000000","0.00000000","1618678150.146601"]],"c":"1651375334"},"book-1000","XMR/USD"]
1618678150.180475: [992,{"a":[["354.62000000","7.57500000","1618678150.148556"]],"c":"4079513490"},"book-1000","XMR/USD"]
1618678150.182654: [1840,{"b":[["9.578201","0.00000000","1618678150.154850"]],"c":"914345545"},"book-1000","OMG/USD"]
1618678150.187871: [1360,{"a":[["0.000022920","11197.42711806","1618678150.156352"]],"c":"4000090284"},"book-1000","ADA/XBT"]
1618678150.191089: [992,{"b":[["353.32000000","4.52021464","1618678150.156560"]],"c":"682024703"},"book-1000","XMR/USD"]
1618678150.1929758: [992,{"b":[["348.89000000","0.00000000","1618678150.156631"]],"c":"682024703"},"book-1000","XMR/USD"]
1618678150.194599: [992,{"b":[["347.73000000","81.63469879","1618678150.160280"]],"c":"682024703"},"book-1000","XMR/USD"]
1618678150.19745: [1840,{"b":[["9.542545","70.60000000","1618678150.168837"]],"c":"914345545"},"book-1000","OMG/USD"]
1618678150.200027: [1920,{"a":[["0.043030","58772.77325050","1618678150.171460"]],"c":"2618893925"},"book-1000","SC/EUR"]
1618678150.202993: [992,{"b":[["353.57000000","0.00000000","1618678150.171613"]],"c":"1635886006"},"book-1000","XMR/USD"]
1618678150.2060642: [1840,{"a":[["9.593971","521.69176500","1618678150.178556"]],"c":"27250332"},"book-1000","OMG/USD"]
1618678150.207005: [1840,{"b":[["9.570750","521.69176500","1618678150.178667"]],"c":"623811203"},"book-1000","OMG/USD"]
1618678150.2172532: [1920,{"a":[["0.043040","3348.38405103","1618678150.189777"]],"c":"3007382058"},"book-1000","SC/EUR"]
1618678150.2210839: [1920,{"b":[["0.042800","0.00000000","1618678150.191484"]],"c":"2868653252"},"book-1000","SC/EUR"]
1618678150.2238011: [1920,{"a":[["0.043150","0.00000000","1618678150.191548"]],"c":"700558938"},"book-1000","SC/EUR"]
1618678150.225965: [3648,{"a":[["0.00840300","12.00000000","1618678150.193562"]],"c":"1159811507"},"book-1000","KSM/XBT"]
1618678150.226923: [992,{"b":[["340.87000000","87.71109640","1618678150.194132"]],"c":"1635886006"},"book-1000","XMR/USD"]
1618678150.228597: [992,{"b":[["348.32000000","23.79012278","1618678150.194618"]],"c":"1635886006"},"book-1000","XMR/USD"]
1618678150.229992: [992,{"b":[["344.29000000","0.18367206","1618678150.198400"]],"c":"1635886006"},"book-1000","XMR/USD"]
1618678150.231387: [3648,{"b":[["0.00736500","0.94017523","1618678150.198803"]],"c":"1159811507"},"book-1000","KSM/XBT"]
1618678150.232167: [496,{"b":[["2178.51000","0.00000000","1618678150.200479"]],"c":"693687854"},"book-1000","ETH/CHF"]
1618678150.2328131: [992,{"a":[["354.43000000","0.00000000","1618678150.203207"]],"c":"3071844059"},"book-1000","XMR/USD"]
1618678150.234682: [1920,{"a":[["0.043030","46970.00000000","1618678150.206125"]],"c":"1163401609"},"book-1000","SC/EUR"]
1618678150.236894: [496,{"a":[["2190.17000","0.46210000","1618678150.206925"]],"c":"2356576981"},"book-1000","ETH/CHF"]
1618678150.237581: [1840,{"b":[["9.583709","0.00000000","1618678150.206978"]],"c":"554454957"},"book-1000","OMG/USD"]
1618678150.2402759: [1920,{"a":[["0.043150","42461.83886926","1618678150.213354"]],"c":"2306642636"},"book-1000","SC/EUR"]
1618678150.243063: [992,{"a":[["354.38000000","1.40000000","1618678150.215332"]],"c":"4224380344"},"book-1000","XMR/USD"]
1618678150.250844: [1920,{"b":[["0.021500","532579.43241859","1618678150.223785"]],"c":"2306642636"},"book-1000","SC/EUR"]
1618678150.2575529: [1840,{"a":[["9.611451","0.00000000","1618678150.225320"]],"c":"554454957"},"book-1000","OMG/USD"]
1618678150.258965: [992,{"a":[["354.75000000","0.00000000","1618678150.228413"]],"c":"3026260173"},"book-1000","XMR/USD"]
1618678150.261285: [3648,{"b":[["0.00750300","0.00000000","1618678150.231409"]],"c":"1159811507"},"book-1000","KSM/XBT"]
1618678150.2674172: [1920,{"b":[["0.042720","0.00000000","1618678150.240093"]],"c":"4278394647"},"book-1000","SC/EUR"]
1618678150.270525: [1920,{"a":[["0.043090","0.00000000","1618678150.240712"]],"c":"1137011947"},"book-1000","SC/EUR"]
1618678150.274053: [1840,{"a":[["9.596648","0.00000000","1618678150.245469"]],"c":"1359281050"},"book-1000","OMG/USD"]
1618678150.27498: [3648,{"b":[["0.00756100","0.00000000","1618678150.246289"]],"c":"647603111"},"book-1000","KSM/XBT"]
1618678150.28221: [1840,{"a":[["9.593970","157.48954700","1618678150.252167"]],"c":"692747360"},"book-1000","OMG/USD"]
1618678150.287192: [1840,{"b":[["9.583710","0.00000000","1618678150.257943"]],"c":"1315770544"},"book-1000","OMG/USD"]
1618678150.288683: [1920,{"a":[["0.043010","44240.00000000","1618678150.259113"]],"c":"3110960256"},"book-1000","SC/EUR"]
1618678150.292567: [1840,{"b":[["9.573323","108.57917745","1618678150.264326"]],"c":"1808787076"},"book-1000","OMG/USD"]
1618678150.29406: [1840,{"a":[["9.611450","0.00000000","1618678150.264382"]],"c":"1808787076"},"book-1000","OMG/USD"]
1618678150.3008919: [1840,{"a":[["9.593970","294.54669061","1618678150.272781"]],"c":"3391955364"},"book-1000","OMG/USD"]
1618678150.3027542: [1840,{"a":[["9.593970","494.54669061","1618678150.275018"]],"c":"100315171"},"book-1000","OMG/USD"]
1618678150.304043: [992,{"b":[["353.17000000","0.00000000","1618678150.276365"]],"c":"3026260173"},"book-1000","XMR/USD"]
1618678150.306106: [1840,{"a":[["9.612170","194.10704088","1618678150.276569"]],"c":"100315171"},"book-1000","OMG/USD"]
1618678150.3073971: [992,{"b":[["353.69000000","0.00000000","1618678150.277664"]],"c":"2954527484"},"book-1000","XMR/USD"]
1618678150.309736: [3648,{"a":[["0.00758900","5.15000000","1618678150.278277"]],"c":"1668974291"},"book-1000","KSM/XBT"]
1618678150.310821: [1360,{"b":[["0.000022880","31.75709827","1618678150.281348"]],"c":"1324027551"},"book-1000","ADA/XBT"]
1618678150.313808: {"event":"heartbeat"}
1618678150.313983: [1664,{"b":[["13.178300","419.18349878","1618678150.285060"]],"c":"2969578226"},"book-1000","WAVES/EUR"]
1618678150.318466: [1920,{"a":[["0.043480","23239.60027887","1618678150.290459"]],"c":"3110960256"},"book-1000","SC/EUR"]
1618678150.323251: [3648,{"b":[["0.00756400","1.08903000","1618678150.294288"]],"c":"254090332"},"book-1000","KSM/XBT"]
1618678150.334625: [992,{"b":[["344.29000000","0.00000000","1618678150.305754"]],"c":"2954527484"},"book-1000","XMR/USD"]
1618678150.358729: [992,{"a":[["354.52000000","7.05616709","1618678150.328205"]],"c":"20200834"},"book-1000","XMR/USD"]
1618678150.3616629: [1920,{"a":[["0.043010","35740.00000000","1618678150.330026"]],"c":"2612893519"},"book-1000","SC/EUR"]
1618678150.3646479: [3648,{"b":[["0.00756500","0.21000000","1618678150.334541"]],"c":"1614964115"},"book-1000","KSM/XBT"]
1618678150.3655272: [3648,{"b":[["0.00756300","0.00000000","1618678150.334750"]],"c":"3997005152"},"book-1000","KSM/XBT"]
1618678150.366265: [1664,{"b":[["13.200300","500.00000000","1618678150.336650"]],"c":"2043513395"},"book-1000","WAVES/EUR"]
1618678150.369929: [3648,{"a":[["0.00760500","9.00000000","1618678150.343149"]],"c":"2171116497"},"book-1000","KSM/XBT"]
1618678150.3709052: [3648,{"b":[["0.00756200","0.73490103","1618678150.344034"]],"c":"769278259"},"book-1000","KSM/XBT"]
1618678150.37203: [1360,{"a":[["0.000022920","10694.79418834","1618678150.344825"]],"c":"3565954169"},"book-1000","ADA/XBT"]
1618678150.38113: [1664,{"a":[["13.244500","43.03468415","1618678150.350447"]],"c":"449487646"},"book-1000","WAVES/EUR"]
1618678150.383036: [1840,{"b":[["9.579765","0.00000000","1618678150.352805"]],"c":"941520957"},"book-1000","OMG/USD"]
1618678150.3842938: [992,{"b":[["344.29000000","0.18367206","1618678150.354349"]],"c":"20200834"},"book-1000","XMR/USD"]
1618678150.386545: [1840,{"b":[["9.571019","158.70997000","1618678150.355628"]],"c":"3119461902"},"book-1000","OMG/USD"]
1618678150.387763: [1840,{"b":[["9.542545","0.00000000","1618678150.359863"]],"c":"3119461902"},"book-1000","OMG/USD"]
1618678150.3886259: [1920,{"a":[["0.043000","8500.00000000","1618678150.360046"]],"c":"2456068032"},"book-1000","SC/EUR"]
1618678150.390913: [1840,{"b":[["9.562689","0.00000000","1618678150.360991"]],"c":"4161918666"},"book-1000","OMG/USD"]
1618678150.391896: [1840,{"b":[["9.545951","160.97309893","1618678150.362122"]],"c":"854948114"},"book-1000","OMG/USD"]
1618678150.392915: [3648,{"b":[["0.00661800","0.00000000","1618678150.364342"]],"c":"769278259"},"book-1000","KSM/XBT"]
1618678150.393667: [1664,{"b":[["13.171900","66.26938736","1618678150.365183"]],"c":"449487646"},"book-1000","WAVES/EUR"]
1618678150.397782: [1840,{"b":[["9.562690","0.00000000","1618678150.370767"]],"c":"2927425074"},"book-1000","OMG/USD"]
1618678150.408704: [1920,{"b":[["0.041800","602870.57416267","1618678150.380427"]],"c":"2456068032"},"book-1000","SC/EUR"]
1618678150.412251: [1920,{"a":[["0.043180","905325.33415860","1618678150.380593"]],"c":"1703999446"},"book-1000","SC/EUR"]
1618678150.4151402: [1920,{"b":[["0.042770","577288.45906328","1618678150.382588"]],"c":"2967313023"},"book-1000","SC/EUR"]
1618678150.417393: [1920,{"a":[["0.043140","65420.54242002","1618678150.383056"]],"c":"165381562"},"book-1000","SC/EUR"]
1618678150.4195788: [1920,{"a":[["0.043190","0.00000000","1618678150.383346"]],"c":"828584728"},"book-1000","SC/EUR"]
1618678150.421699: [1664,{"b":[["13.198300","0.00000000","1618678150.386521"]],"c":"81810648"},"book-1000","WAVES/EUR"]
1618678150.422934: [1840,{"b":[["9.579766","137.06272135","1618678150.394100"]],"c":"2121854164"},"book-1000","OMG/USD"]
1618678150.425859: [992,{"a":[["355.03000000","0.00000000","1618678150.398453"]],"c":"20200834"},"book-1000","XMR/USD"]
1618678150.428853: [3648,{"b":[["0.00755100","5.05000000","1618678150.400591"]],"c":"3389416044"},"book-1000","KSM/XBT"]
1618678150.430639: [1840,{"a":[["9.596647","0.00000000","1618678150.403009"]],"c":"3010489656"},"book-1000","OMG/USD"]
1618678150.44609: [992,{"a":[["354.38000000","4.95600000","1618678150.410034"]],"c":"2008212945"},"book-1000","XMR/USD"]
1618678150.454905: [1920,{"b":[["0.041660","328955.93199375","1618678150.423781"]],"c":"828584728"},"book-1000","SC/EUR"]
1618678150.458426: [3648,{"b":[["0.00754100","0.00000000","1618678150.424137"]],"c":"3389416044"},"book-1000","KSM/XBT"]
1618678150.4593349: [992,{"b":[["354.05000000","0.00000000","1618678150.424487"]],"c":"3755855282"},"book-1000","XMR/USD"]
1618678150.4676979: [1920,{"a":[["0.043180","0.00000000","1618678150.438934"]],"c":"4018813397"},"book-1000","SC/EUR"]
1618678150.472327: [1840,{"b":[["9.545951","265.97309893","1618678150.444314"]],"c":"1610960502"},"book-1000","OMG/USD"]
1618678150.477941: [1664,{"b":[["13.200300","0.00000000","1618678150.450724"]],"c":"4031372742"},"book-1000","WAVES/EUR"]
1618678150.479858: [1664,{"b":[["13.198400","500.00000000","1618678150.450843"]],"c":"377589089"},"book-1000","WAVES/EUR"]
1618678150.495074: [992,{"b":[["353.81000000","6.86167316","1618678150.466631"]],"c":"2716081395"},"book-1000","XMR/USD"]
1618678150.513105: [992,{"a":[["354.69000000","2.37700000","1618678150.486559"]],"c":"2807788557"},"book-1000","XMR/USD"]
1618678150.5290282: [1840,{"b":[["9.573323","0.00000000","1618678150.501532"]],"c":"962275304"},"book-1000","OMG/USD"]
1618678150.532031: [992,{"b":[["353.62000000","18.21040624","1618678150.502389"]],"c":"2354551979"},"book-1000","XMR/USD"]
1618678150.534432: [1840,{"a":[["9.596651","0.00000000","1618678150.504786"]],"c":"189112843"},"book-1000","OMG/USD"]
1618678150.5357492: [1920,{"a":[["0.043150","0.00000000","1618678150.507261"]],"c":"2567483110"},"book-1000","SC/EUR"]
1618678150.5433211: [1920,{"a":[["0.043570","0.00000000","1618678150.515687"]],"c":"2567483110"},"book-1000","SC/EUR"]
1618678150.545741: [1920,{"b":[["0.021500","531079.43241859","1618678150.516458"]],"c":"2567483110"},"book-1000","SC/EUR"]
1618678150.555677: [1664,{"a":[["13.312600","4.17098583","1618678150.527979"]],"c":"377589089"},"book-1000","WAVES/EUR"]
1618678150.564163: [1664,{"a":[["13.244500","0.00000000","1618678150.536337"]],"c":"1971758156"},"book-1000","WAVES/EUR"]
1618678150.566137: [1840,{"b":[["9.568854","68.89691853","1618678150.538592"]],"c":"1486490431"},"book-1000","OMG/USD"]
1618678150.57586: [992,{"b":[["353.82000000","7.00000000","1618678150.546736"]],"c":"719081025"},"book-1000","XMR/USD"]
1618678150.578401: [1920,{"a":[["0.043010","78201.83886926","1618678150.548468"]],"c":"1203096696"},"book-1000","SC/EUR"]
1618678150.6030421: [1664,{"a":[["13.267300","0.00000000","1618678150.574726"]],"c":"1971758156"},"book-1000","WAVES/EUR"]
1618678150.606674: [1840,{"b":[["9.538110","64.10000000","1618678150.577792"]],"c":"1486490431"},"book-1000","OMG/USD"]
1618678150.6152802: [1664,{"b":[["13.200200","500.00000000","1618678150.586114"]],"c":"4059344663"},"book-1000","WAVES/EUR"]
1618678150.623343: [3648,{"b":[["0.00662500","4.83014300","1618678150.593403"]],"c":"3389416044"},"book-1000","KSM/XBT"]
1618678150.66671: [992,{"b":[["353.80000000","0.00000000","1618678150.635975"]],"c":"1600461403"},"book-1000","XMR/USD"]
1618678150.6695611: [1664,{"b":[["13.198400","0.00000000","1618678150.637463"]],"c":"2229291658"},"book-1000","WAVES/EUR"]
1618678150.681721: [1840,{"a":[["9.618101","0.00000000","1618678150.651881"]],"c":"1486490431"},"book-1000","OMG/USD"]
1618678150.706124: [1920,{"b":[["0.042950","0.00000000","1618678150.678882"]],"c":"3262905666"},"book-1000","SC/EUR"]
1618678150.7099142: [1920,{"a":[["0.043010","35740.00000000","1618678150.683223"]],"c":"2382726175"},"book-1000","SC/EUR"]
1618678150.716598: [1840,{"a":[["9.639236","0.00000000","1618678150.687065"]],"c":"1486490431"},"book-1000","OMG/USD"]
1618678150.720758: [1664,{"b":[["13.197900","500.00000000","1618678150.691571"]],"c":"510449617"},"book-1000","WAVES/EUR"]
1618678150.722504: [1664,{"b":[["13.200200","0.00000000","1618678150.691843"]],"c":"1105312545"},"book-1000","WAVES/EUR"]
1618678150.731937: [992,{"b":[["353.82000000","0.00000000","1618678150.704020"]],"c":"150156951"},"book-1000","XMR/USD"]
1618678150.752424: [1840,{"b":[["9.568854","0.00000000","1618678150.724903"]],"c":"189112843"},"book-1000","OMG/USD"]
1618678150.759394: [1920,{"a":[["0.043080","42461.83886926","1618678150.728648"]],"c":"1513048104"},"book-1000","SC/EUR"]
1618678150.77807: [496,{"a":[["2190.16000","3.00000000","1618678150.750706"]],"c":"821710531"},"book-1000","ETH/CHF"]
1618678150.784496: [1840,{"b":[["9.545947","0.00000000","1618678150.756300"]],"c":"189112843"},"book-1000","OMG/USD"]
1618678150.790766: [3648,{"b":[["0.00754400","0.11666751","1618678150.762780"]],"c":"3389416044"},"book-1000","KSM/XBT"]
1618678150.799742: [1840,{"a":[["9.667953","360.00000000","1618678150.773163"]],"c":"189112843"},"book-1000","OMG/USD"]
1618678150.826304: [496,{"a":[["2191.54000","0.00000000","1618678150.798741"]],"c":"237694703"},"book-1000","ETH/CHF"]
1618678150.839817: [1920,{"b":[["0.042950","2332.63400000","1618678150.811634"]],"c":"28400296"},"book-1000","SC/EUR"]
1618678150.8435671: [1840,{"b":[["9.486855","0.00000000","1618678150.814417"]],"c":"189112843"},"book-1000","OMG/USD"]
1618678150.860694: [992,{"b":[["354.04000000","0.00000000","1618678150.826417"],["353.81000000","5.14412712","1618678150.827816"]],"c":"3050606190"},"book-1000","XMR/USD"]
1618678150.871559: [1840,{"b":[["9.570422","108.59675675","1618678150.843652"]],"c":"2345354988"},"book-1000","OMG/USD"]
1618678150.874395: [1920,{"a":[["0.043140","0.00000000","1618678150.845776"]],"c":"4066921800"},"book-1000","SC/EUR"]
1618678150.9017642: [992,{"b":[["353.85000000","1.40000000","1618678150.874098"]],"c":"111866136"},"book-1000","XMR/USD"]
1618678150.958358: [3648,{"b":[["0.00707800","0.00000000","1618678150.930400"]],"c":"3389416044"},"book-1000","KSM/XBT"]
1618678150.96619: [1840,{"a":[["9.596825","145.00000000","1618678150.938481"]],"c":"2676170850"},"book-1000","OMG/USD"]
1618678150.9866838: [1840,{"b":[["9.526091","1000.00000000","1618678150.959191"]],"c":"2676170850"},"book-1000","OMG/USD"]
1618678151.006469: [1360,{"a":[["0.000023010","0.00000000","1618678150.979451"]],"c":"3565954169"},"book-1000","ADA/XBT"]
1618678151.017678: [992,{"a":[["355.33000000","0.00000000","1618678150.990573"]],"c":"111866136"},"book-1000","XMR/USD"]
1618678151.0253062: [992,{"a":[["355.07000000","285.51450000","1618678150.996802"]],"c":"111866136"},"book-1000","XMR/USD"]
1618678151.028418: [1840,{"b":[["9.545950","0.00000000","1618678150.998834"]],"c":"2676170850"},"book-1000","OMG/USD"]
1618678151.041096: [3648,{"a":[["0.00759200","0.00000000","1618678151.013171"]],"c":"1852210332"},"book-1000","KSM/XBT"]
1618678151.044541: [1360,{"a":[["0.000023000","17415.33591581","1618678151.016200"]],"c":"3565954169"},"book-1000","ADA/XBT"]
1618678151.047916: [992,{"b":[["353.25000000","0.00000000","1618678151.018855"]],"c":"274495561"},"book-1000","XMR/USD"]
1618678151.049782: [992,{"b":[["352.90000000","0.00000000","1618678151.019692"]],"c":"823268533"},"book-1000","XMR/USD"]
1618678151.054881: [1920,{"b":[["0.042930","0.00000000","1618678151.025733"]],"c":"3491515070"},"book-1000","SC/EUR"]
1618678151.07757: [1664,{"a":[["13.244800","43.03468415","1618678151.049569"]],"c":"1911348625"},"book-1000","WAVES/EUR"]
1618678151.081816: [992,{"b":[["353.31000000","0.00000000","1618678151.053917"]],"c":"848925506"},"book-1000","XMR/USD"]
1618678151.103529: [1840,{"b":[["9.486857","3106.26396400","1618678151.077155"]],"c":"2676170850"},"book-1000","OMG/USD"]
1618678151.125885: [1664,{"a":[["13.259700","371.45710637","1618678151.097999"]],"c":"3789160914"},"book-1000","WAVES/EUR"]
1618678151.127809: [1920,{"a":[["0.043190","183452.67067430","1618678151.098328"]],"c":"747204653"},"book-1000","SC/EUR"]
1618678151.141304: [992,{"b":[["352.91000000","52.00000000","1618678151.113825"]],"c":"4288477719"},"book-1000","XMR/USD"]
1618678151.152533: [1360,{"a":[["0.000022940","21171.82368366","1618678151.123542"]],"c":"848863701"},"book-1000","ADA/XBT"]
1618678151.156524: [1360,{"a":[["0.000022940","21918.88348010","1618678151.127370"]],"c":"2777554931"},"book-1000","ADA/XBT"]
1618678151.218644: [992,{"a":[["354.42000000","0.00000000","1618678151.191621"]],"c":"4026440345"},"book-1000","XMR/USD"]
1618678151.238333: [1920,{"b":[["0.042840","20000.00000000","1618678151.212718"]],"c":"4075335489"},"book-1000","SC/EUR"]
1618678151.2506392: [1920,{"b":[["0.042860","150104.67507435","1618678151.222221"]],"c":"226643799"},"book-1000","SC/EUR"]
1618678151.2544699: [992,{"b":[["352.43000000","75.00000000","1618678151.223146"]],"c":"2188078155"},"book-1000","XMR/USD"]
1618678151.256588: [1920,{"a":[["0.043160","137519.00000000","1618678151.223790"]],"c":"1867942321"},"book-1000","SC/EUR"]
1618678151.260192: [992,{"a":[["354.37000000","6.86096865","1618678151.232046"]],"c":"2998129581"},"book-1000","XMR/USD"]
1618678151.2663229: [1840,{"a":[["9.593970","544.54669061","1618678151.237749"]],"c":"54238772"},"book-1000","OMG/USD"]
1618678151.26763: [1664,{"a":[["13.244800","0.00000000","1618678151.238521"]],"c":"926853820"},"book-1000","WAVES/EUR"]
1618678151.271038: [496,{"b":[["2180.30000","3.00000000","1618678151.242508"]],"c":"833320941"},"book-1000","ETH/CHF"]
1618678151.2849479: [1360,{"a":[["0.000022940","26918.88348010","1618678151.257040"]],"c":"437658561"},"book-1000","ADA/XBT"]
1618678151.2887301: [1920,{"a":[["0.043180","905325.33415860","1618678151.257241"]],"c":"2345541612"},"book-1000","SC/EUR"]
1618678151.291682: [1840,{"b":[["9.579404","157.05569900","1618678151.260251"]],"c":"2418038976"},"book-1000","OMG/USD"]
1618678151.294771: [1920,{"b":[["0.042770","0.00000000","1618678151.265307"]],"c":"1585672773"},"book-1000","SC/EUR"]
1618678151.297386: [3648,{"a":[["0.00758600","4.54601508","1618678151.267926"]],"c":"3492657613"},"book-1000","KSM/XBT"]
1618678151.300077: [992,{"a":[["354.38000000","3.55600000","1618678151.271984"]],"c":"4230630747"},"book-1000","XMR/USD"]
1618678151.313986: {"event":"heartbeat"}
1618678151.320744: [992,{"b":[["354.05000000","2.54000000","1618678151.293239"]],"c":"1074061059"},"book-1000","XMR/USD"]
1618678151.3235881: [992,{"a":[["354.34000000","11.52000000","1618678151.293660"]],"c":"1480665535"},"book-1000","XMR/USD"]
1618678151.329157: [992,{"a":[["354.33000000","1.40000000","1618678151.301362"]],"c":"3065982057"},"book-1000","XMR/USD"]
1618678151.334802: [1920,{"b":[["0.042780","577288.45906328","1618678151.307386"]],"c":"3042705764"},"book-1000","SC/EUR"]
1618678151.353915: [1840,{"a":[["9.593970","407.48954700","1618678151.323469"]],"c":"1264197236"},"book-1000","OMG/USD"]
1618678151.3770082: [1840,{"b":[["9.579404","0.00000000","1618678151.349225"]],"c":"3628193920"},"book-1000","OMG/USD"]
1618678151.378582: [1920,{"b":[["0.042780","0.00000000","1618678151.350133"]],"c":"1585672773"},"book-1000","SC/EUR"]
1618678151.381852: [1920,{"a":[["0.043190","0.00000000","1618678151.352642"]],"c":"2607642049"},"book-1000","SC/EUR"]
1618678151.384398: [992,{"b":[["353.82000000","5.00000000","1618678151.352765"]],"c":"4150430178"},"book-1000","XMR/USD"]
1618678151.3863199: [1920,{"a":[["0.043150","119557.37659325","1618678151.353147"]],"c":"3824741642"},"book-1000","SC/EUR"]
1618678151.388939: [992,{"b":[["353.86000000","7.57500000","1618678151.361427"]],"c":"927021804"},"book-1000","XMR/USD"]
1618678151.390719: [1920,{"b":[["0.042860","5816.67507435","1618678151.361489"]],"c":"2074408340"},"book-1000","SC/EUR"]
1618678151.3929589: [1664,{"b":[["13.144300","0.00000000","1618678151.362289"]],"c":"926853820"},"book-1000","WAVES/EUR"]
1618678151.3967419: [1840,{"a":[["9.593969","137.04079906","1618678151.370132"]],"c":"3536803050"},"book-1000","OMG/USD"]
1618678151.4238021: [3648,{"b":[["0.00756400","0.00000000","1618678151.396097"]],"c":"358197212"},"book-1000","KSM/XBT"]
1618678151.42516: [3648,{"b":[["0.00756000","0.00000000","1618678151.396230"]],"c":"37361739"},"book-1000","KSM/XBT"]
1618678151.426232: [3648,{"b":[["0.00755200","37.97000000","1618678151.397460"]],"c":"934189477"},"book-1000","KSM/XBT"]
1618678151.427208: [3648,{"b":[["0.00755900","2.27291753","1618678151.397591"]],"c":"1877694882"},"book-1000","KSM/XBT"]
1618678151.436724: [3648,{"b":[["0.00755100","0.00000000","1618678151.409744"]],"c":"245510005"},"book-1000","KSM/XBT"]
1618678151.439403: [3648,{"b":[["0.00754900","0.00000000","1618678151.410366"]],"c":"2423331131"},"book-1000","KSM/XBT"]
1618678151.446749: [1840,{"a":[["9.593968","200.00000000","1618678151.419664"]],"c":"3482699827"},"book-1000","OMG/USD"]
1618678151.465429: [1840,{"b":[["9.573934","157.37821500","1618678151.437885"]],"c":"3328943838"},"book-1000","OMG/USD"]
1618678151.4760299: [1840,{"b":[["9.579766","0.00000000","1618678151.447606"]],"c":"4054733897"},"book-1000","OMG/USD"]
1618678151.482751: [3648,{"b":[["0.00755600","2.17917000","1618678151.454612"]],"c":"911500298"},"book-1000","KSM/XBT"]
1618678151.4841118: [3648,{"b":[["0.00755900","3.36250753","1618678151.454847"]],"c":"23413074"},"book-1000","KSM/XBT"]
1618678151.4879029: [1840,{"b":[["9.574142","146.00000000","1618678151.459386"]],"c":"1673538121"},"book-1000","OMG/USD"]
1618678151.495425: [1840,{"a":[["9.593970","207.48954700","1618678151.467833"]],"c":"1982795269"},"book-1000","OMG/USD"]
1618678151.500758: [3648,{"a":[["0.00758900","0.00000000","1618678151.473055"]],"c":"1396030501"},"book-1000","KSM/XBT"]
1618678151.51167: [1840,{"a":[["9.667953","0.00000000","1618678151.483773"]],"c":"1982795269"},"book-1000","OMG/USD"]
1618678151.51354: [3648,{"b":[["0.00754600","5.65478642","1618678151.485530"]],"c":"2283406921"},"book-1000","KSM/XBT"]
1618678151.514981: [1840,{"b":[["9.579767","137.04434994","1618678151.487454"]],"c":"2925581589"},"book-1000","OMG/USD"]
1618678151.516018: [3648,{"a":[["0.00758200","0.00000000","1618678151.487677"]],"c":"2900568994"},"book-1000","KSM/XBT"]
1618678151.516875: [3648,{"b":[["0.00756900","1.22055870","1618678151.488179"]],"c":"606683944"},"book-1000","KSM/XBT"]
1618678151.517717: [3648,{"b":[["0.00755000","5.18381459","1618678151.488298"]],"c":"1868133265"},"book-1000","KSM/XBT"]
1618678151.5330272: [464,{"b":[["56060.10000","0.00081364","1618678151.506076"]],"c":"4264455516"},"book-1000","XBT/CHF"]
1618678151.544799: [992,{"b":[["353.81000000","0.00000000","1618678151.517481"]],"c":"3477052564"},"book-1000","XMR/USD"]
1618678151.5478778: [1840,{"b":[["9.545952","6.78128277","1618678151.520079"]],"c":"2925581589"},"book-1000","OMG/USD"]
1618678151.558523: [464,{"b":[["56060.00000","0.09843791","1618678151.529460"]],"c":"2932595273"},"book-1000","XBT/CHF"]
1618678151.566908: [3648,{"b":[["0.00736500","0.00000000","1618678151.539345"]],"c":"1868133265"},"book-1000","KSM/XBT"]
1618678151.571434: [992,{"b":[["352.02000000","12.36000000","1618678151.543388"]],"c":"3477052564"},"book-1000","XMR/USD"]
1618678151.5742002: [1840,{"a":[["9.602664","521.77461100","1618678151.544955"]],"c":"2925581589"},"book-1000","OMG/USD"]
1618678151.5760489: [3648,{"b":[["0.00754500","0.00000000","1618678151.549191"]],"c":"1868133265"},"book-1000","KSM/XBT"]
1618678151.586998: [464,{"b":[["56048.60000","0.00000000","1618678151.559707"]],"c":"2977635175"},"book-1000","XBT/CHF"]
1618678151.589602: [3648,{"b":[["0.00749500","0.00000000","1618678151.561545"]],"c":"1868133265"},"book-1000","KSM/XBT"]
1618678151.59073: [992,{"b":[["353.87000000","6.86168321","1618678151.562282"]],"c":"3959439029"},"book-1000","XMR/USD"]
1618678151.594211: [992,{"b":[["353.87000000","29.58668321","1618678151.566394"]],"c":"996044847"},"book-1000","XMR/USD"]
1618678151.5965729: [992,{"b":[["353.87000000","34.58668321","1618678151.568592"]],"c":"3915400280"},"book-1000","XMR/USD"]
1618678151.601779: [3648,{"b":[["0.00756500","0.00000000","1618678151.575217"]],"c":"1601511172"},"book-1000","KSM/XBT"]
1618678151.607768: [464,{"a":[["56192.70000","0.03955000","1618678151.581379"]],"c":"942509700"},"book-1000","XBT/CHF"]
1618678151.615417: [3648,{"b":[["0.00732800","0.94492229","1618678151.587805"]],"c":"1601511172"},"book-1000","KSM/XBT"]
1618678151.627411: [1840,{"a":[["9.637421","360.00000000","1618678151.599587"]],"c":"2925581589"},"book-1000","OMG/USD"]
1618678151.6395159: [992,{"b":[["353.88000000","7.57500000","1618678151.612547"]],"c":"2593635548"},"book-1000","XMR/USD"]
1618678151.6600661: [3648,{"a":[["0.00758500","5.00000000","1618678151.630977"]],"c":"337776265"},"book-1000","KSM/XBT"]
1618678151.6614242: [3648,{"b":[["0.00755900","2.27291753","1618678151.632014"]],"c":"4248610402"},"book-1000","KSM/XBT"]
1618678151.662485: [3648,{"b":[["0.00755300","0.00000000","1618678151.632077"]],"c":"2181016008"},"book-1000","KSM/XBT"]
1618678151.663451: [3648,{"b":[["0.00755600","0.00000000","1618678151.632283"]],"c":"4225535949"},"book-1000","KSM/XBT"]
1618678151.66429: [464,{"b":[["56023.80000","0.01700000","1618678151.632455"]],"c":"1832142042"},"book-1000","XBT/CHF"]
1618678151.6734982: [3648,{"b":[["0.00751200","57.00000000","1618678151.645704"]],"c":"4225535949"},"book-1000","KSM/XBT"]
1618678151.6875362: [5104,{"b":[["0.000027630","58.10945196","1618678151.659124"]],"c":"1504500835"},"book-1000","OCEAN/XBT"]
1618678151.688828: [5104,{"b":[["0.000027340","15.33848456","1618678151.659215"]],"c":"1504500835"},"book-1000","OCEAN/XBT"]
1618678151.6898282: [3648,{"a":[["0.00758900","0.43982210","1618678151.659536"]],"c":"1126131702"},"book-1000","KSM/XBT"]
1618678151.691139: [992,{"b":[["353.89000000","5.00000000","1618678151.661309"]],"c":"1042859741"},"book-1000","XMR/USD"]
1618678151.6932511: [992,{"b":[["353.87000000","29.58668321","1618678151.661444"]],"c":"766180304"},"book-1000","XMR/USD"]
1618678151.6950889: [992,{"b":[["353.86000000","0.00000000","1618678151.662076"]],"c":"2590753907"},"book-1000","XMR/USD"]
1618678151.696774: [992,{"b":[["353.89000000","27.72500000","1618678151.662631"]],"c":"2383056164"},"book-1000","XMR/USD"]
1618678151.6986182: [3648,{"b":[["0.00756200","0.16890103","1618678151.668289"]],"c":"2412961124"},"book-1000","KSM/XBT"]
1618678151.703312: [3648,{"b":[["0.00756900","0.00000000","1618678151.672894"]],"c":"1357613935"},"book-1000","KSM/XBT"]
1618678151.706641: [3648,{"a":[["0.00758300","1.45490700","1618678151.676260"]],"c":"1149998289"},"book-1000","KSM/XBT"]
1618678151.7275012: [464,{"b":[["55986.20000","0.00974000","1618678151.700299"]],"c":"3899911477"},"book-1000","XBT/CHF"]
1618678151.730019: [464,{"a":[["56192.60000","0.15000000","1618678151.701826"]],"c":"147542223"},"book-1000","XBT/CHF"]
1618678151.7365172: [992,{"b":[["353.90000000","7.57500000","1618678151.709734"]],"c":"315003122"},"book-1000","XMR/USD"]
1618678151.739833: [992,{"b":[["353.87000000","6.86168321","1618678151.711017"]],"c":"2895123438"},"book-1000","XMR/USD"]
1618678151.74211: [3648,{"b":[["0.00754600","0.00000000","1618678151.712812"]],"c":"1263719633"},"book-1000","KSM/XBT"]
1618678151.7430248: [3648,{"b":[["0.00754500","5.65553590","1618678151.713270"]],"c":"413463334"},"book-1000","KSM/XBT"]
1618678151.743778: [992,{"b":[["353.82000000","0.00000000","1618678151.714020"]],"c":"256948224"},"book-1000","XMR/USD"]
1618678151.745755: [1840,{"a":[["9.615360","106.36114280","1618678151.718606"]],"c":"2925581589"},"book-1000","OMG/USD"]
1618678151.746675: [992,{"b":[["353.32000000","0.17106559","1618678151.719782"]],"c":"256948224"},"book-1000","XMR/USD"]
1618678151.749536: [992,{"b":[["353.33000000","3.76058445","1618678151.722530"]],"c":"256948224"},"book-1000","XMR/USD"]
1618678151.75512: [1920,{"a":[["0.043080","0.00000000","1618678151.727357"]],"c":"694177913"},"book-1000","SC/EUR"]
1618678151.7695942: [1360,{"b":[["0.000022870","19532.56060141","1618678151.741551"]],"c":"54156543"},"book-1000","ADA/XBT"]
1618678151.773386: [464,{"a":[["56474.60000","0.00000000","1618678151.742384"]],"c":"3336978148"},"book-1000","XBT/CHF"]
1618678151.775213: [1840,{"b":[["9.526090","0.00000000","1618678151.743586"]],"c":"2925581589"},"book-1000","OMG/USD"]
1618678151.780653: [1360,{"a":[["0.000022940","26171.82368366","1618678151.752218"]],"c":"2485969625"},"book-1000","ADA/XBT"]
1618678151.783604: [464,{"b":[["56060.00000","0.00000000","1618678151.752868"]],"c":"2543661637"},"book-1000","XBT/CHF"]
1618678151.7849321: [1360,{"a":[["0.000022950","11331.22471303","1618678151.753007"]],"c":"3210309302"},"book-1000","ADA/XBT"]
1618678151.787304: [464,{"b":[["56023.90000","0.05895616","1618678151.753261"]],"c":"1901925371"},"book-1000","XBT/CHF"]
1618678151.78876: [464,{"b":[["56060.10000","0.00000000","1618678151.753675"]],"c":"2959605834"},"book-1000","XBT/CHF"]
1618678151.790058: [1360,{"b":[["0.000022870","17341.84370954","1618678151.753772"]],"c":"4138646238"},"book-1000","ADA/XBT"]
1618678151.7926168: [992,{"b":[["353.91000000","22.72500000","1618678151.761394"]],"c":"2168337420"},"book-1000","XMR/USD"]
1618678151.794305: [992,{"b":[["353.89000000","22.72500000","1618678151.763227"]],"c":"3535773725"},"book-1000","XMR/USD"]
1618678151.7959108: [992,{"b":[["353.91000000","27.72500000","1618678151.763666"]],"c":"3314290516"},"book-1000","XMR/USD"]
1618678151.797617: [1360,{"a":[["0.000022940","21171.82368366","1618678151.766939"]],"c":"1228310252"},"book-1000","ADA/XBT"]
1618678151.7997582: [992,{"b":[["353.88000000","0.00000000","1618678151.770481"]],"c":"3982152179"},"book-1000","XMR/USD"]
1618678151.801316: [1920,{"a":[["0.043020","42461.83886926","1618678151.773631"]],"c":"4100743313"},"book-1000","SC/EUR"]
1618678151.812426: [1920,{"a":[["0.043070","62470.00000000","1618678151.781617"]],"c":"2332223645"},"book-1000","SC/EUR"]
1618678151.815992: [992,{"b":[["353.33000000","0.00000000","1618678151.781984"]],"c":"3982152179"},"book-1000","XMR/USD"]
1618678151.818073: [464,{"a":[["56192.50000","0.59541531","1618678151.783585"]],"c":"2981627784"},"book-1000","XBT/CHF"]
1618678151.819726: [1840,{"b":[["9.518969","880.57916638","1618678151.784521"]],"c":"2925581589"},"book-1000","OMG/USD"]
1618678151.820586: [992,{"b":[["352.92000000","4.35407844","1618678151.785403"]],"c":"3982152179"},"book-1000","XMR/USD"]
1618678151.8222: [464,{"a":[["56192.80000","0.00000000","1618678151.791889"]],"c":"1277118740"},"book-1000","XBT/CHF"]
1618678151.823657: [464,{"b":[["56060.10000","0.09844256","1618678151.793783"]],"c":"1986715257"},"book-1000","XBT/CHF"]
1618678151.825752: [1360,{"b":[["0.000022880","2222.51031534","1618678151.795369"]],"c":"1973640962"},"book-1000","ADA/XBT"]
1618678151.83852: [992,{"b":[["353.89000000","0.00000000","1618678151.810173"]],"c":"3052126546"},"book-1000","XMR/USD"]
1618678151.844845: [992,{"b":[["353.92000000","7.57500000","1618678151.815948"]],"c":"2900577227"},"book-1000","XMR/USD"]
1618678151.860158: [464,{"a":[["56192.40000","0.15000000","1618678151.831919"]],"c":"3200395417"},"book-1000","XBT/CHF"]
1618678151.870616: [464,{"b":[["55973.30000","0.00000000","1618678151.842831"]],"c":"3617195707"},"book-1000","XBT/CHF"]
1618678151.926903: [1360,{"b":[["0.000022880","7269.17481601","1618678151.899032"]],"c":"2987985638"},"book-1000","ADA/XBT"]
1618678151.93072: [464,{"a":[["56192.50000","0.00000000","1618678151.899079"]],"c":"2620487156"},"book-1000","XBT/CHF"]
1618678151.986901: [496,{"a":[["2191.54000","1.15978265","1618678151.957862"]],"c":"1383015221"},"book-1000","ETH/CHF"]
1618678151.987872: [496,{"a":[["2192.02000","0.00000000","1618678151.957925"]],"c":"1942160021"},"book-1000","ETH/CHF"]
1618678151.988738: [464,{"a":[["56192.60000","0.00000000","1618678151.958925"]],"c":"3019003173"},"book-1000","XBT/CHF"]
1618678151.994547: [3648,{"a":[["0.00758000","4.66247519","1618678151.961546"]],"c":"3897797554"},"book-1000","KSM/XBT"]
1618678151.995521: [1664,{"a":[["13.276400","0.00000000","1618678151.963330"]],"c":"926853820"},"book-1000","WAVES/EUR"]
1618678152.002429: [5104,{"b":[["0.000027700","1515.67838664","1618678151.968428"]],"c":"1929034142"},"book-1000","OCEAN/XBT"]
1618678152.003535: [5104,{"b":[["0.000027650","2780.94553505","1618678151.968527"]],"c":"1280675286"},"book-1000","OCEAN/XBT"]
1618678152.00453: [1840,{"b":[["9.545951","160.97309893","1618678151.970015"]],"c":"2925581589"},"book-1000","OMG/USD"]
1618678152.00562: [5104,{"b":[["0.000027650","16855.56719581","1618678151.970611"]],"c":"2179565640"},"book-1000","OCEAN/XBT"]
1618678152.006401: [5104,{"b":[["0.000027370","86555.53271619","1618678151.971201"]],"c":"2179565640"},"book-1000","OCEAN/XBT"]
1618678152.0071769: [464,{"a":[["56192.30000","0.59541531","1618678151.972934"]],"c":"27191541"},"book-1000","XBT/CHF"]
1618678152.008678: [464,{"a":[["56192.40000","0.00000000","1618678151.974541"]],"c":"3732512186"},"book-1000","XBT/CHF"]
1618678152.0101209: [1360,{"a":[["0.000022900","10623.59975312","1618678151.977774"]],"c":"3305256351"},"book-1000","ADA/XBT"]
1618678152.012807: [1360,{"b":[["0.000022850","16259.47485772","1618678151.982294"]],"c":"3915761503"},"book-1000","ADA/XBT"]
1618678152.020711: [1360,{"a":[["0.000022910","15283.46505460","1618678151.992880"]],"c":"1969340076"},"book-1000","ADA/XBT"]
1618678152.024725: [1360,{"b":[["0.000022870","23341.84370954","1618678151.993433"]],"c":"4135672287"},"book-1000","ADA/XBT"]
1618678152.047195: [464,{"b":[["55680.10000","0.43773848","1618678152.019278"]],"c":"946813584"},"book-1000","XBT/CHF"]
1618678152.0491588: [464,{"a":[["56192.30000","0.00000000","1618678152.021066"]],"c":"3036361067"},"book-1000","XBT/CHF"]
1618678152.057908: [5104,{"b":[["0.000027650","15312.31155981","1618678152.031329"]],"c":"683425591"},"book-1000","OCEAN/XBT"]
1618678152.059038: [5104,{"b":[["0.000027690","1541.02630262","1618678152.032020"]],"c":"1388414649"},"book-1000","OCEAN/XBT"]
1618678152.061394: [1840,{"b":[["9.570115","149.00000000","1618678152.034554"]],"c":"998706433"},"book-1000","OMG/USD"]
1618678152.062824: [992,{"b":[["354.05000000","0.00000000","1618678152.035321"]],"c":"2240739079"},"book-1000","XMR/USD"]
1618678152.065021: [1840,{"b":[["9.563816","105.00000000","1618678152.037117"]],"c":"998706433"},"book-1000","OMG/USD"]
1618678152.0960488: [1920,{"a":[["0.043020","0.00000000","1618678152.066608"]],"c":"892768056"},"book-1000","SC/EUR"]
1618678152.099822: [464,{"a":[["56474.60000","0.59541531","1618678152.071377"]],"c":"3369401815"},"book-1000","XBT/CHF"]
1618678152.1151638: [3648,{"a":[["0.00758300","0.00000000","1618678152.087433"]],"c":"4216736925"},"book-1000","KSM/XBT"]
1618678152.116437: [3648,{"a":[["0.00757100","1.59099411","1618678152.087699"]],"c":"3842327467"},"book-1000","KSM/XBT"]
1618678152.117731: [992,{"b":[["353.90000000","0.00000000","1618678152.088070"]],"c":"3760403391"},"book-1000","XMR/USD"]
1618678152.121258: [3648,{"a":[["0.00759000","0.00000000","1618678152.093545"]],"c":"614260713"},"book-1000","KSM/XBT"]
1618678152.125189: [3648,{"a":[["0.00758300","39.81000000","1618678152.096689"]],"c":"1085562967"},"book-1000","KSM/XBT"]
1618678152.132749: [464,{"a":[["56192.20000","0.15000000","1618678152.103712"]],"c":"4231154997"},"book-1000","XBT/CHF"]
1618678152.156665: [3648,{"a":[["0.00757000","1.30823483","1618678152.128999"]],"c":"2318274361"},"book-1000","KSM/XBT"]
1618678152.158196: [3648,{"a":[["0.00758000","2.48413860","1618678152.129064"]],"c":"2839601701"},"book-1000","KSM/XBT"]
1618678152.1661901: [992,{"b":[["353.91000000","5.00000000","1618678152.138766"]],"c":"1128439287"},"book-1000","XMR/USD"]
1618678152.169056: [3648,{"b":[["0.00755800","0.00000000","1618678152.139162"]],"c":"77677157"},"book-1000","KSM/XBT"]
1618678152.171226: [992,{"b":[["353.02000000","22.72500000","1618678152.141988"]],"c":"1128439287"},"book-1000","XMR/USD"]
1618678152.173375: [3648,{"a":[["0.00758000","3.08113860","1618678152.144486"]],"c":"1820437694"},"book-1000","KSM/XBT"]
1618678152.219062: [3648,{"b":[["0.00754300","0.00000000","1618678152.189825"]],"c":"259653425"},"book-1000","KSM/XBT"]
1618678152.229722: [1840,{"b":[["9.575095","200.00000000","1618678152.201953"]],"c":"3869739259"},"book-1000","OMG/USD"]
1618678152.231532: [5104,{"b":[["0.000027350","0.00000000","1618678152.204603"]],"c":"1388414649"},"book-1000","OCEAN/XBT"]
1618678152.2534668: [5104,{"a":[["0.000027860","659.14148000","1618678152.222888"]],"c":"2684478185"},"book-1000","OCEAN/XBT"]
1618678152.254758: [5104,{"a":[["0.000028130","35014.42580225","1618678152.223553"]],"c":"2684478185"},"book-1000","OCEAN/XBT"]
1618678152.255747: [5104,{"a":[["0.000028130","0.00000000","1618678152.223611"]],"c":"2684478185"},"book-1000","OCEAN/XBT"]
1618678152.256917: [1920,{"a":[["0.043080","42461.83886926","1618678152.229721"]],"c":"1893100277"},"book-1000","SC/EUR"]
1618678152.259944: [3648,{"a":[["0.00760500","0.00000000","1618678152.232170"]],"c":"2133037863"},"book-1000","KSM/XBT"]
1618678152.260749: [464,{"b":[["56024.00000","0.04616665","1618678152.232241"]],"c":"3879950723"},"book-1000","XBT/CHF"]
1618678152.2643971: [3648,{"a":[["0.00758000","2.87113860","1618678152.237120"]],"c":"1440764094"},"book-1000","KSM/XBT"]
1618678152.2678778: [1664,{"a":[["13.249300","66.20314997","1618678152.241384"]],"c":"6215171"},"book-1000","WAVES/EUR"]
1618678152.2707798: [992,{"a":[["355.32000000","0.00000000","1618678152.243142"]],"c":"1128439287"},"book-1000","XMR/USD"]
1618678152.27289: [992,{"a":[["355.06000000","4.57411888","1618678152.243675"]],"c":"1128439287"},"book-1000","XMR/USD"]
1618678152.282033: [992,{"b":[["353.32000000","0.00000000","1618678152.254055"]],"c":"2430350541"},"book-1000","XMR/USD"]
1618678152.2851431: [992,{"b":[["353.02000000","0.00000000","1618678152.254200"]],"c":"619999849"},"book-1000","XMR/USD"]
1618678152.3163362: {"event":"heartbeat"}
1618678152.696169: [992,{"b":[["353.91000000","0.00000000","1618678152.577072"]],"c":"2765122604"},"book-1000","XMR/USD"]
1618678152.6987572: [1920,{"b":[["0.042860","0.00000000","1618678152.577209"]],"c":"2409465368"},"book-1000","SC/EUR"]
1618678152.701463: [1920,{"b":[["0.042940","0.00000000","1618678152.577291"]],"c":"4128097316"},"book-1000","SC/EUR"]
1618678152.703883: [3648,{"a":[["0.00757000","1.51823483","1618678152.581145"]],"c":"907146902"},"book-1000","KSM/XBT"]
1618678152.70466: [3648,{"a":[["0.00757000","1.30823483","1618678152.581471"]],"c":"1440764094"},"book-1000","KSM/XBT"]
1618678152.7054179: [3648,{"a":[["0.00756900","0.21000000","1618678152.581590"]],"c":"2749699582"},"book-1000","KSM/XBT"]
1618678152.7061381: [464,{"b":[["56023.90000","0.00000000","1618678152.583520"]],"c":"1599054528"},"book-1000","XBT/CHF"]
1618678152.707505: [1920,{"b":[["0.042770","577288.45906328","1618678152.584088"]],"c":"3971960872"},"book-1000","SC/EUR"]
1618678152.709769: [496,{"b":[["2183.34000","0.00000000","1618678152.584342"]],"c":"3702527187"},"book-1000","ETH/CHF"]
1618678152.710517: [464,{"b":[["56024.10000","0.05895595","1618678152.584475"]],"c":"1228868631"},"book-1000","XBT/CHF"]
1618678152.711838: [496,{"b":[["2183.34000","0.92254684","1618678152.585133"]],"c":"1681811161"},"book-1000","ETH/CHF"]
1618678152.71255: [1920,{"a":[["0.043180","0.00000000","1618678152.585715"]],"c":"2133491791"},"book-1000","SC/EUR"]
1618678152.714818: [5104,{"b":[["0.000027380","1286.09242508","1618678152.588580"]],"c":"2684478185"},"book-1000","OCEAN/XBT"]
1618678152.715523: [3648,{"a":[["0.00757100","0.00000000","1618678152.589688"]],"c":"3601929685"},"book-1000","KSM/XBT"]
1618678152.716224: [3648,{"a":[["0.00758800","9.00000000","1618678152.591988"]],"c":"931319514"},"book-1000","KSM/XBT"]
1618678152.716915: [992,{"b":[["351.83000000","11.16000000","1618678152.593854"]],"c":"2765122604"},"book-1000","XMR/USD"]
1618678152.7185879: [992,{"b":[["352.02000000","0.00000000","1618678152.596956"]],"c":"2765122604"},"book-1000","XMR/USD"]
1618678152.720263: [3648,{"a":[["0.00757500","0.62900000","1618678152.599563"]],"c":"1402690020"},"book-1000","KSM/XBT"]
1618678152.7209642: [1360,{"b":[["0.000022870","16668.76413900","1618678152.602327"]],"c":"1170612029"},"book-1000","ADA/XBT"]
1618678152.72343: [992,{"a":[["354.55000000","0.00000000","1618678152.611243"]],"c":"2827907783"},"book-1000","XMR/USD"]
1618678152.725101: [1920,{"b":[["0.042850","146165.00000000","1618678152.614217"]],"c":"2980572704"},"book-1000","SC/EUR"]
1618678152.7273018: [992,{"b":[["353.56000000","0.00000000","1618678152.615216"]],"c":"2959108134"},"book-1000","XMR/USD"]
1618678152.728974: [992,{"a":[["354.99000000","0.00000000","1618678152.615294"]],"c":"2959108134"},"book-1000","XMR/USD"]
1618678152.730616: [992,{"b":[["353.26000000","153.46750000","1618678152.615396"]],"c":"3225190976"},"book-1000","XMR/USD"]
1618678152.732203: [1664,{"b":[["13.185800","28.15000000","1618678152.615745"]],"c":"848374780"},"book-1000","WAVES/EUR"]
1618678152.733206: [992,{"a":[["354.69000000","170.61230000","1618678152.615835"]],"c":"880416442"},"book-1000","XMR/USD"]
1618678152.73475: [992,{"b":[["353.26000000","263.21720000","1618678152.616656"]],"c":"2318904349"},"book-1000","XMR/USD"]
1618678152.7362618: [992,{"b":[["353.54000000","0.00000000","1618678152.616724"]],"c":"3566401002"},"book-1000","XMR/USD"]
1618678152.737709: [992,{"a":[["354.96000000","0.00000000","1618678152.616874"]],"c":"3566401002"},"book-1000","XMR/USD"]
1618678152.7390988: [992,{"a":[["354.69000000","311.52770000","1618678152.617307"]],"c":"3402598662"},"book-1000","XMR/USD"]
1618678152.740494: [3648,{"b":[["0.00750300","6.10460000","1618678152.617588"]],"c":"1402690020"},"book-1000","KSM/XBT"]
1618678152.741075: [3648,{"b":[["0.00754400","5.26666751","1618678152.621685"]],"c":"1142322588"},"book-1000","KSM/XBT"]
1618678152.741657: [1920,{"a":[["0.043060","20000.00000000","1618678152.623884"]],"c":"60902967"},"book-1000","SC/EUR"]
1618678152.7435021: [992,{"a":[["354.37000000","0.00000000","1618678152.624455"]],"c":"2255029685"},"book-1000","XMR/USD"]
1618678152.744908: [1920,{"b":[["0.042820","151695.89187450","1618678152.637815"]],"c":"2561762342"},"book-1000","SC/EUR"]
1618678152.746738: [1664,{"b":[["13.199700","500.00000000","1618678152.639478"]],"c":"2381838544"},"book-1000","WAVES/EUR"]
1618678152.7476108: [992,{"a":[["354.95000000","59.76192421","1618678152.641729"]],"c":"965345853"},"book-1000","XMR/USD"]
1618678152.748994: [992,{"a":[["354.32000000","6.86262774","1618678152.642469"]],"c":"4291651432"},"book-1000","XMR/USD"]
1618678152.7503932: [1840,{"a":[["9.593969","0.00000000","1618678152.645913"]],"c":"756783561"},"book-1000","OMG/USD"]
1618678152.7511292: [992,{"b":[["353.63000000","7.00000000","1618678152.647058"]],"c":"2908006100"},"book-1000","XMR/USD"]
1618678152.752512: [992,{"b":[["353.92000000","0.00000000","1618678152.647344"]],"c":"3102155931"},"book-1000","XMR/USD"]
1618678152.753889: [464,{"b":[["55680.20000","0.41663742","1618678152.648345"]],"c":"1228868631"},"book-1000","XBT/CHF"]
1618678152.754944: [1360,{"b":[["0.000022860","27578.69371878","1618678152.648626"]],"c":"484418909"},"book-1000","ADA/XBT"]
1618678152.7569652: [1920,{"a":[["0.043070","42470.00000000","1618678152.649165"]],"c":"109427490"},"book-1000","SC/EUR"]
1618678152.758816: [992,{"a":[["356.81000000","146.31735377","1618678152.652983"]],"c":"3102155931"},"book-1000","XMR/USD"]
1618678152.760181: [496,{"a":[["2212.37000","0.00000000","1618678152.653110"]],"c":"1681811161"},"book-1000","ETH/CHF"]
1618678152.7607412: [1840,{"a":[["9.593967","137.04028667","1618678152.657219"]],"c":"3109234744"},"book-1000","OMG/USD"]
1618678152.7614038: [1840,{"b":[["9.577260","157.57638300","1618678152.658253"]],"c":"1427318268"},"book-1000","OMG/USD"]
1618678152.7620292: [5104,{"a":[["0.000027880","16664.28029076","1618678152.658693"]],"c":"2271204893"},"book-1000","OCEAN/XBT"]
1618678152.762524: [992,{"b":[["353.87000000","0.00000000","1618678152.660012"]],"c":"1971591765"},"book-1000","XMR/USD"]
1618678152.764139: [992,{"b":[["353.63000000","13.86595931","1618678152.665401"]],"c":"622602611"},"book-1000","XMR/USD"]
1618678152.765347: [1360,{"a":[["0.000022950","6331.22471303","1618678152.666065"]],"c":"2908045482"},"book-1000","ADA/XBT"]
1618678152.766974: [1360,{"b":[["0.000022750","0.00000000","1618678152.674599"]],"c":"2908045482"},"book-1000","ADA/XBT"]
1618678152.768542: [5104,{"a":[["0.000028160","30849.84225106","1618678152.674688"]],"c":"2271204893"},"book-1000","OCEAN/XBT"]
1618678152.768961: [992,{"b":[["352.38000000","0.00000000","1618678152.676024"]],"c":"2186899154"},"book-1000","XMR/USD"]
1618678152.770022: [3648,{"b":[["0.00750200","0.00000000","1618678152.680241"]],"c":"1142322588"},"book-1000","KSM/XBT"]
1618678152.7704692: [496,{"a":[["2212.19000","14.30168378","1618678152.681965"]],"c":"1681811161"},"book-1000","ETH/CHF"]
1618678152.770915: [3648,{"a":[["0.00757000","0.00000000","1618678152.685250"]],"c":"2541687908"},"book-1000","KSM/XBT"]
1618678152.77136: [1920,{"b":[["0.042880","5058.29725588","1618678152.687080"]],"c":"3751220974"},"book-1000","SC/EUR"]
1618678152.772863: [1840,{"b":[["9.526091","0.00000000","1618678152.691606"]],"c":"1427318268"},"book-1000","OMG/USD"]
1618678152.7734022: [1360,{"a":[["0.000022970","15036.00000000","1618678152.693351"]],"c":"2166783766"},"book-1000","ADA/XBT"]
1618678152.7749052: [1920,{"b":[["0.042770","0.00000000","1618678152.694007"]],"c":"182090567"},"book-1000","SC/EUR"]
1618678152.776635: [1664,{"a":[["13.245200","43.03468415","1618678152.694568"]],"c":"1517307166"},"book-1000","WAVES/EUR"]
1618678152.777803: [3648,{"a":[["0.00756800","2.18103188","1618678152.696519"]],"c":"110916632"},"book-1000","KSM/XBT"]
1618678152.778362: [992,{"a":[["354.33000000","8.97500000","1618678152.696728"]],"c":"1887454112"},"book-1000","XMR/USD"]
1618678152.779778: [1360,{"b":[["0.000022760","17185.95201960","1618678152.697111"]],"c":"2166783766"},"book-1000","ADA/XBT"]
1618678152.781277: [992,{"a":[["354.95000000","64.76192421","1618678152.700132"]],"c":"1887454112"},"book-1000","XMR/USD"]
1618678152.78241: [3648,{"b":[["0.00749500","18.37400705","1618678152.701040"]],"c":"110916632"},"book-1000","KSM/XBT"]
1618678152.783137: [992,{"b":[["353.85000000","0.00000000","1618678152.703103"]],"c":"3202950154"},"book-1000","XMR/USD"]
1618678152.7848608: [992,{"b":[["353.62000000","15.27000000","1618678152.708305"]],"c":"1303158109"},"book-1000","XMR/USD"]
1618678152.786155: [992,{"b":[["353.61000000","0.00000000","1618678152.708730"]],"c":"467614083"},"book-1000","XMR/USD"]
1618678152.787213: [1840,{"a":[["9.593968","0.00000000","1618678152.710331"]],"c":"2760637670"},"book-1000","OMG/USD"]
1618678152.787762: [992,{"a":[["354.33000000","7.57500000","1618678152.714803"]],"c":"2977387354"},"book-1000","XMR/USD"]
1618678152.7888262: [3648,{"b":[["0.00754500","0.00000000","1618678152.716250"]],"c":"3715663905"},"book-1000","KSM/XBT"]
1618678152.78939: [3648,{"b":[["0.00753300","5.66454511","1618678152.717056"]],"c":"4253927463"},"book-1000","KSM/XBT"]
1618678152.789834: [1664,{"b":[["13.197900","0.00000000","1618678152.721714"]],"c":"2744354492"},"book-1000","WAVES/EUR"]
1618678152.7905111: [992,{"b":[["351.83000000","0.00000000","1618678152.724925"]],"c":"1783528560"},"book-1000","XMR/USD"]
1618678152.791563: [3648,{"a":[["0.00756900","0.00000000","1618678152.732546"]],"c":"3325606772"},"book-1000","KSM/XBT"]
1618678152.7920482: [3648,{"b":[["0.00755900","0.00000000","1618678152.732661"]],"c":"3344908287"},"book-1000","KSM/XBT"]
1618678152.7925482: [3648,{"a":[["0.00757400","0.21000000","1618678152.732744"]],"c":"710145847"},"book-1000","KSM/XBT"]
1618678152.79299: [1920,{"a":[["0.043040","0.00000000","1618678152.732905"]],"c":"2087978677"},"book-1000","SC/EUR"]
1618678152.7949061: [992,{"b":[["353.63000000","6.86595931","1618678152.743158"]],"c":"3572547051"},"book-1000","XMR/USD"]
1618678152.7960162: [992,{"a":[["354.62000000","0.00000000","1618678152.758040"]],"c":"2483386259"},"book-1000","XMR/USD"]
1618678152.797131: [992,{"a":[["355.75000000","0.00000000","1618678152.761239"]],"c":"2483386259"},"book-1000","XMR/USD"]
1618678152.798187: [3648,{"a":[["0.00756700","0.21000000","1618678152.765280"]],"c":"3245080489"},"book-1000","KSM/XBT"]
1618678152.798635: [3648,{"a":[["0.00757400","0.00000000","1618678152.765515"]],"c":"94991919"},"book-1000","KSM/XBT"]
1618678152.799079: [992,{"a":[["355.19000000","0.00000000","1618678152.766297"]],"c":"2483386259"},"book-1000","XMR/USD"]
1618678152.8003478: [496,{"b":[["2177.69000","0.13550000","1618678152.769544"]],"c":"2651261865"},"book-1000","ETH/CHF"]
1618678152.811336: [1920,{"a":[["0.043000","11848.32050552","1618678152.783528"]],"c":"2407303230"},"book-1000","SC/EUR"]
1618678152.815101: [1840,{"b":[["9.543652","69.10000000","1618678152.786192"]],"c":"2760637670"},"book-1000","OMG/USD"]
1618678152.8188748: [4528,{"b":[["0.000806900","0.00000000","1618678152.791101"]],"c":"1534345702"},"book-1000","GRT/ETH"]
1618678152.825137: [992,{"a":[["357.61000000","0.00000000","1618678152.797867"]],"c":"2483386259"},"book-1000","XMR/USD"]
1618678152.846488: [3648,{"a":[["0.00756800","0.00000000","1618678152.818816"]],"c":"1364361013"},"book-1000","KSM/XBT"]
1618678152.847689: [3648,{"b":[["0.00755700","1.08998000","1618678152.819031"]],"c":"1495577442"},"book-1000","KSM/XBT"]
1618678152.84869: [3648,{"b":[["0.00755000","7.36452459","1618678152.819102"]],"c":"1999088766"},"book-1000","KSM/XBT"]
1618678152.849534: [3648,{"a":[["0.00756600","2.18142427","1618678152.819224"]],"c":"2219942443"},"book-1000","KSM/XBT"]
1618678152.8503711: [3648,{"b":[["0.00754600","3.27106000","1618678152.819358"]],"c":"313766145"},"book-1000","KSM/XBT"]
1618678152.85157: [1920,{"a":[["0.043000","3348.32050552","1618678152.822027"]],"c":"729329700"},"book-1000","SC/EUR"]
1618678152.875943: [3648,{"b":[["0.00750800","0.00000000","1618678152.847738"]],"c":"313766145"},"book-1000","KSM/XBT"]
1618678152.884804: [1920,{"a":[["0.042990","8500.00000000","1618678152.855632"]],"c":"2822159547"},"book-1000","SC/EUR"]
1618678152.8883278: [992,{"b":[["352.92000000","4.52514403","1618678152.857247"]],"c":"4010806555"},"book-1000","XMR/USD"]
1618678152.8906: [3648,{"a":[["0.00757400","0.21000000","1618678152.860635"]],"c":"2976944120"},"book-1000","KSM/XBT"]
1618678152.891487: [3648,{"a":[["0.00756700","0.00000000","1618678152.860914"]],"c":"2524622835"},"book-1000","KSM/XBT"]
1618678152.9310799: [1840,{"b":[["9.538493","1000.00000000","1618678152.903317"]],"c":"2760637670"},"book-1000","OMG/USD"]
1618678152.9331741: [1920,{"b":[["0.040910","23282.88707799","1618678152.905712"]],"c":"2822159547"},"book-1000","SC/EUR"]
1618678152.9389281: [1920,{"a":[["0.043150","0.00000000","1618678152.909243"]],"c":"567960220"},"book-1000","SC/EUR"]
1618678152.942013: [1920,{"a":[["0.043150","99564.28736962","1618678152.909329"]],"c":"3757872313"},"book-1000","SC/EUR"]
1618678152.944567: [992,{"b":[["352.07000000","7.36479104","1618678152.909928"]],"c":"1403874139"},"book-1000","XMR/USD"]
1618678152.946317: [1360,{"b":[["0.000022880","5078.42159894","1618678152.910688"]],"c":"1854468486"},"book-1000","ADA/XBT"]
1618678152.948896: [992,{"b":[["350.54000000","0.00000000","1618678152.911454"]],"c":"1403874139"},"book-1000","XMR/USD"]
1618678152.957147: [992,{"b":[["353.08000000","5.88514672","1618678152.929634"]],"c":"3880969550"},"book-1000","XMR/USD"]
1618678152.9615638: [992,{"b":[["353.30000000","2.94257336","1618678152.934217"]],"c":"826465955"},"book-1000","XMR/USD"]
1618678152.964989: [1920,{"a":[["0.043080","0.00000000","1618678152.937152"]],"c":"3374540698"},"book-1000","SC/EUR"]
1618678152.975926: [1360,{"b":[["0.000022870","18859.86101271","1618678152.944594"]],"c":"2561831622"},"book-1000","ADA/XBT"]
1618678152.979724: [992,{"b":[["353.63000000","0.00000000","1618678152.948232"]],"c":"2803663028"},"book-1000","XMR/USD"]
1618678152.98415: [1920,{"b":[["0.042850","0.00000000","1618678152.957916"]],"c":"362820263"},"book-1000","SC/EUR"]
1618678152.992018: [1840,{"b":[["9.577260","0.00000000","1618678152.963120"]],"c":"1221325090"},"book-1000","OMG/USD"]
1618678153.003846: [464,{"a":[["56192.90000","0.01207000","1618678152.974833"]],"c":"1005234390"},"book-1000","XBT/CHF"]
1618678153.011002: [992,{"b":[["353.30000000","9.81243515","1618678152.982288"]],"c":"3438612261"},"book-1000","XMR/USD"]
1618678153.013817: [1920,{"a":[["0.043030","89431.83886926","1618678152.982918"]],"c":"124867739"},"book-1000","SC/EUR"]
1618678153.016586: [1840,{"a":[["9.612170","0.00000000","1618678152.983211"]],"c":"1221325090"},"book-1000","OMG/USD"]
1618678153.017632: [1840,{"a":[["9.608695","194.10704088","1618678152.983695"]],"c":"1221325090"},"book-1000","OMG/USD"]
1618678153.018664: [3648,{"b":[["0.00755700","3.36484858","1618678152.990235"]],"c":"1969372364"},"book-1000","KSM/XBT"]
1618678153.019402: [992,{"a":[["354.31000000","2.38346000","1618678152.992260"]],"c":"1303854481"},"book-1000","XMR/USD"]
1618678153.029539: [4528,{"b":[["0.000807000","61.91831785","1618678153.001832"]],"c":"1534345702"},"book-1000","GRT/ETH"]
1618678153.043169: [1840,{"b":[["9.575095","0.00000000","1618678153.013844"]],"c":"2515236056"},"book-1000","OMG/USD"]
1618678153.048343: [1840,{"b":[["9.574142","0.00000000","1618678153.021275"]],"c":"4090150033"},"book-1000","OMG/USD"]
1618678153.0496798: [1840,{"a":[["9.603909","0.00000000","1618678153.022267"]],"c":"4090150033"},"book-1000","OMG/USD"]
1618678153.055509: [1920,{"b":[["0.042830","0.00000000","1618678153.026815"]],"c":"2696630132"},"book-1000","SC/EUR"]
1618678153.059077: [1920,{"b":[["0.042850","30674.15619954","1618678153.026961"]],"c":"564561198"},"book-1000","SC/EUR"]
1618678153.0620558: [1664,{"b":[["13.206400","0.00000000","1618678153.029416"]],"c":"3429016523"},"book-1000","WAVES/EUR"]
1618678153.0632: [1840,{"b":[["9.567763","0.00000000","1618678153.032262"]],"c":"2316521878"},"book-1000","OMG/USD"]
1618678153.06673: [1920,{"a":[["0.043070","0.00000000","1618678153.039706"]],"c":"517772851"},"book-1000","SC/EUR"]
1618678153.069332: [1840,{"b":[["9.570115","0.00000000","1618678153.039793"]],"c":"937086255"},"book-1000","OMG/USD"]
1618678153.0723882: [1920,{"a":[["0.042990","48920.00000000","1618678153.043530"]],"c":"1503146163"},"book-1000","SC/EUR"]
1618678153.0884302: [1840,{"a":[["9.601969","0.00000000","1618678153.061292"]],"c":"746037877"},"book-1000","OMG/USD"]
1618678153.103359: [1840,{"b":[["9.563816","0.00000000","1618678153.075910"]],"c":"249237780"},"book-1000","OMG/USD"]
1618678153.1049442: [1840,{"b":[["9.579767","0.00000000","1618678153.076583"]],"c":"2041802756"},"book-1000","OMG/USD"]
1618678153.11232: [1840,{"b":[["9.561769","114.97598188","1618678153.083874"]],"c":"673807051"},"book-1000","OMG/USD"]
1618678153.118881: [1840,{"a":[["9.604047","0.00000000","1618678153.090439"]],"c":"673807051"},"book-1000","OMG/USD"]
1618678153.120481: [1840,{"a":[["9.588518","61.76939651","1618678153.090849"]],"c":"1924602150"},"book-1000","OMG/USD"]
1618678153.12174: [1840,{"b":[["9.562688","0.00000000","1618678153.091726"]],"c":"3689090513"},"book-1000","OMG/USD"]
1618678153.122991: [1360,{"b":[["0.000022850","14981.27485772","1618678153.093065"]],"c":"3033890822"},"book-1000","ADA/XBT"]
1618678153.126077: [992,{"a":[["355.07000000","0.00000000","1618678153.098529"]],"c":"1303854481"},"book-1000","XMR/USD"]
1618678153.1458502: [1840,{"b":[["9.573935","137.08800372","1618678153.116908"]],"c":"4001495790"},"book-1000","OMG/USD"]
1618678153.14742: [1920,{"b":[["0.040940","0.00000000","1618678153.118499"]],"c":"1503146163"},"book-1000","SC/EUR"]
1618678153.1598341: [464,{"a":[["56169.90000","0.01700000","1618678153.131090"]],"c":"566356366"},"book-1000","XBT/CHF"]
1618678153.1871061: [1840,{"a":[["9.588517","200.00000000","1618678153.157644"]],"c":"2563512965"},"book-1000","OMG/USD"]
1618678153.203246: [1840,{"a":[["9.588517","356.03038400","1618678153.171631"]],"c":"3774466615"},"book-1000","OMG/USD"]
1618678153.204834: [496,{"b":[["2183.34000","0.00000000","1618678153.173598"]],"c":"4065608220"},"book-1000","ETH/CHF"]
1618678153.2062411: [496,{"b":[["2183.34000","0.90282284","1618678153.176525"]],"c":"79021108"},"book-1000","ETH/CHF"]
1618678153.207123: [1840,{"b":[["9.545953","105.00000000","1618678153.178253"]],"c":"2814588039"},"book-1000","OMG/USD"]
1618678153.2098649: [992,{"b":[["353.62000000","0.00000000","1618678153.179561"]],"c":"417435379"},"book-1000","XMR/USD"]
1618678153.212515: [1920,{"a":[["0.043150","0.00000000","1618678153.182364"]],"c":"625679064"},"book-1000","SC/EUR"]
1618678153.2152262: [1840,{"b":[["9.543652","0.00000000","1618678153.183035"]],"c":"2814588039"},"book-1000","OMG/USD"]
1618678153.216228: [1840,{"b":[["9.563815","0.00000000","1618678153.183168"]],"c":"4129154223"},"book-1000","OMG/USD"]
1618678153.217301: [1840,{"b":[["9.538110","0.00000000","1618678153.183424"]],"c":"4129154223"},"book-1000","OMG/USD"]
1618678153.2181811: [464,{"a":[["56192.60000","0.15000000","1618678153.184117"]],"c":"402493951"},"book-1000","XBT/CHF"]
1618678153.21956: [464,{"a":[["56192.20000","0.00000000","1618678153.184176"]],"c":"464436926"},"book-1000","XBT/CHF"]
1618678153.220852: [1664,{"b":[["13.178300","4.18349878","1618678153.184226"]],"c":"501850717"},"book-1000","WAVES/EUR"]
1618678153.223867: [1920,{"a":[["0.043150","119545.68482037","1618678153.195098"]],"c":"3807081696"},"book-1000","SC/EUR"]
1618678153.238539: [992,{"a":[["354.31000000","7.38346000","1618678153.210020"]],"c":"2841098102"},"book-1000","XMR/USD"]
1618678153.241756: [496,{"b":[["2183.34000","1.80564267","1618678153.212675"]],"c":"49784475"},"book-1000","ETH/CHF"]
1618678153.242677: [496,{"b":[["2183.34000","0.90281983","1618678153.214460"]],"c":"1319634008"},"book-1000","ETH/CHF"]
1618678153.243702: [1840,{"b":[["9.573934","0.00000000","1618678153.215723"]],"c":"1263236284"},"book-1000","OMG/USD"]
1618678153.247915: [3648,{"b":[["0.00755000","2.81971000","1618678153.220658"]],"c":"313836234"},"book-1000","KSM/XBT"]
1618678153.254108: [496,{"b":[["2180.30000","0.00000000","1618678153.225518"]],"c":"3663780591"},"book-1000","ETH/CHF"]
1618678153.2609348: [1664,{"b":[["13.206800","158.81102117","1618678153.233433"]],"c":"1421137523"},"book-1000","WAVES/EUR"]
1618678153.263104: [992,{"a":[["355.22000000","22.72500000","1618678153.235585"]],"c":"2841098102"},"book-1000","XMR/USD"]
1618678153.267215: [992,{"b":[["353.30000000","25.08243515","1618678153.238568"]],"c":"3146833418"},"book-1000","XMR/USD"]
1618678153.270433: [1840,{"a":[["9.608695","0.00000000","1618678153.242402"]],"c":"1263236284"},"book-1000","OMG/USD"]
1618678153.2715561: [992,{"a":[["357.56000000","0.00000000","1618678153.243125"]],"c":"3146833418"},"book-1000","XMR/USD"]
1618678153.2735329: [1840,{"a":[["9.602663","194.10704088","1618678153.243306"]],"c":"1263236284"},"book-1000","OMG/USD"]
1618678153.2743711: [992,{"b":[["340.87000000","83.27759500","1618678153.243467"]],"c":"3146833418"},"book-1000","XMR/USD"]
1618678153.2762592: [992,{"b":[["348.32000000","0.00000000","1618678153.243609"]],"c":"3146833418"},"book-1000","XMR/USD"]
1618678153.27795: [1840,{"b":[["9.538493","0.00000000","1618678153.246107"]],"c":"1263236284"},"book-1000","OMG/USD"]
1618678153.278782: [1664,{"b":[["13.187900","415.00000000","1618678153.247144"]],"c":"4188277223"},"book-1000","WAVES/EUR"]
1618678153.281135: [992,{"a":[["357.12000000","0.14235281","1618678153.253868"]],"c":"3146833418"},"book-1000","XMR/USD"]
1618678153.3014998: [1840,{"a":[["9.588518","125.86939651","1618678153.274472"]],"c":"3313779280"},"book-1000","OMG/USD"]
1618678153.305572: [1664,{"b":[["13.206500","0.00000000","1618678153.277713"]],"c":"1518574664"},"book-1000","WAVES/EUR"]
1618678153.307494: [1664,{"b":[["13.202800","0.00000000","1618678153.278810"]],"c":"2707128011"},"book-1000","WAVES/EUR"]
1618678153.3138938: [992,{"b":[["340.15000000","70.43758680","1618678153.285012"]],"c":"3146833418"},"book-1000","XMR/USD"]
1618678153.316534: [992,{"b":[["347.73000000","105.44279096","1618678153.285403"]],"c":"3146833418"},"book-1000","XMR/USD"]
1618678153.318848: {"event":"heartbeat"}
1618678153.3188632: [992,{"a":[["356.13000000","0.00000000","1618678153.289839"]],"c":"3146833418"},"book-1000","XMR/USD"]
1618678153.3209531: [992,{"a":[["354.95000000","59.76192421","1618678153.292005"]],"c":"3146833418"},"book-1000","XMR/USD"]
1618678153.326922: [1840,{"a":[["9.608696","0.00000000","1618678153.298698"]],"c":"3313779280"},"book-1000","OMG/USD"]
1618678153.3284822: [1840,{"a":[["9.599774","3929.07000000","1618678153.299438"]],"c":"3313779280"},"book-1000","OMG/USD"]
1618678153.3300018: [992,{"b":[["353.30000000","22.13986179","1618678153.301296"]],"c":"894624169"},"book-1000","XMR/USD"]
1618678153.3320808: [1840,{"b":[["9.561453","4182.43000000","1618678153.301400"]],"c":"4011399543"},"book-1000","OMG/USD"]
1618678153.333326: [464,{"b":[["55680.20000","0.00000000","1618678153.304508"]],"c":"464436926"},"book-1000","XBT/CHF"]
1618678153.3347158: [1664,{"b":[["13.090300","75.72086261","1618678153.305620"]],"c":"2707128011"},"book-1000","WAVES/EUR"]
1618678153.335806: [992,{"b":[["350.09000000","0.05000000","1618678153.306164"]],"c":"894624169"},"book-1000","XMR/USD"]
1618678153.3375769: [1840,{"b":[["9.570338","0.00000000","1618678153.308136"]],"c":"762437399"},"book-1000","OMG/USD"]
1618678153.340681: [464,{"a":[["56316.50000","0.00000000","1618678153.311949"]],"c":"2732125247"},"book-1000","XBT/CHF"]
1618678153.3460212: [1360,{"b":[["0.000022750","4370.62937062","1618678153.314701"]],"c":"3033890822"},"book-1000","ADA/XBT"]
1618678153.34924: [464,{"a":[["56169.90000","0.02972000","1618678153.316271"]],"c":"1315620798"},"book-1000","XBT/CHF"]
1618678153.3509388: [1664,{"b":[["13.206900","151.43599178","1618678153.322225"]],"c":"238860168"},"book-1000","WAVES/EUR"]
1618678153.363123: [1840,{"b":[["9.570750","0.00000000","1618678153.329819"]],"c":"2522923205"},"book-1000","OMG/USD"]
1618678153.366425: [1920,{"a":[["0.043490","23255.81395348","1618678153.335134"]],"c":"3807081696"},"book-1000","SC/EUR"]
1618678153.3795142: [1840,{"a":[["9.598886","0.00000000","1618678153.349087"]],"c":"1893941235"},"book-1000","OMG/USD"]
1618678153.381074: [992,{"a":[["354.30000000","7.57500000","1618678153.352296"]],"c":"2553067503"},"book-1000","XMR/USD"]
1618678153.407539: [5104,{"b":[["0.000027380","17.09242508","1618678153.377312"]],"c":"2271204893"},"book-1000","OCEAN/XBT"]
1618678153.40882: [1360,{"a":[["0.000022940","27368.62162581","1618678153.377453"]],"c":"3273794283"},"book-1000","ADA/XBT"]
1618678153.412139: [1920,{"a":[["0.043190","905325.33415860","1618678153.377693"]],"c":"3290807000"},"book-1000","SC/EUR"]
1618678153.414989: [1920,{"b":[["0.042720","577288.45906328","1618678153.379743"]],"c":"2569629356"},"book-1000","SC/EUR"]
1618678153.417204: [1840,{"b":[["9.555242","521.94389600","1618678153.386345"]],"c":"2142031534"},"book-1000","OMG/USD"]
1618678153.41807: [992,{"a":[["354.72000000","273.47460000","1618678153.387698"]],"c":"2553067503"},"book-1000","XMR/USD"]
1618678153.4316008: [992,{"a":[["354.29000000","5.00000000","1618678153.403284"]],"c":"342552862"},"book-1000","XMR/USD"]
1618678153.438848: [992,{"a":[["354.33000000","0.00000000","1618678153.408578"]],"c":"1224026332"},"book-1000","XMR/USD"]
1618678153.444175: [992,{"b":[["352.07000000","0.00000000","1618678153.416859"]],"c":"1946618085"},"book-1000","XMR/USD"]
1618678153.474282: [1840,{"a":[["9.615360","0.00000000","1618678153.444769"]],"c":"2142031534"},"book-1000","OMG/USD"]
1618678153.475838: [5104,{"b":[["0.000027150","1269.00000000","1618678153.444946"]],"c":"2271204893"},"book-1000","OCEAN/XBT"]
1618678153.476876: [3648,{"a":[["0.00757800","4.90000000","1618678153.445253"]],"c":"141022761"},"book-1000","KSM/XBT"]
1618678153.481771: [992,{"a":[["354.31000000","2.38346000","1618678153.452909"]],"c":"975666008"},"book-1000","XMR/USD"]
1618678153.484531: [496,{"b":[["2183.34000","0.00000000","1618678153.453749"]],"c":"1146436572"},"book-1000","ETH/CHF"]
1618678153.486708: [464,{"a":[["56313.20000","0.00000000","1618678153.458928"]],"c":"2056078431"},"book-1000","XBT/CHF"]
1618678153.4886029: [1840,{"b":[["9.518970","1000.00000000","1618678153.461152"]],"c":"2142031534"},"book-1000","OMG/USD"]
1618678153.4907851: [3648,{"b":[["0.00755200","42.51996775","1618678153.462317"]],"c":"2800590572"},"book-1000","KSM/XBT"]
1618678153.4916081: [496,{"b":[["2183.34000","0.85650754","1618678153.464215"]],"c":"2162643394"},"book-1000","ETH/CHF"]
1618678153.492348: [1840,{"a":[["9.612171","0.00000000","1618678153.464534"]],"c":"2142031534"},"book-1000","OMG/USD"]
1618678153.4965491: [992,{"b":[["351.45000000","12.36000000","1618678153.469441"]],"c":"3495776493"},"book-1000","XMR/USD"]
1618678153.499495: [1840,{"a":[["9.596825","0.00000000","1618678153.471294"]],"c":"796876868"},"book-1000","OMG/USD"]
1618678153.515351: [1840,{"a":[["9.602663","324.81692833","1618678153.488436"]],"c":"796876868"},"book-1000","OMG/USD"]
1618678153.5169358: [1840,{"a":[["9.602663","130.70988745","1618678153.488498"]],"c":"796876868"},"book-1000","OMG/USD"]
1618678153.528197: [1920,{"a":[["0.042990","40420.00000000","1618678153.500896"]],"c":"2291330044"},"book-1000","SC/EUR"]
1618678153.5381372: [1840,{"a":[["9.593970","157.48954700","1618678153.509180"]],"c":"99658201"},"book-1000","OMG/USD"]
1618678153.5441668: [1840,{"a":[["9.608231","674.13567699","1618678153.516086"]],"c":"99658201"},"book-1000","OMG/USD"]
1618678153.547518: [1664,{"b":[["13.144500","0.00000000","1618678153.519503"]],"c":"238860168"},"book-1000","WAVES/EUR"]
1618678153.550566: [464,{"a":[["56474.50000","0.17090000","1618678153.523050"]],"c":"3583487547"},"book-1000","XBT/CHF"]
1618678153.557636: [1920,{"a":[["0.042980","8500.00000000","1618678153.530312"]],"c":"4271949488"},"book-1000","SC/EUR"]
1618678153.5615108: [1840,{"b":[["9.561769","0.00000000","1618678153.532907"]],"c":"2790502396"},"book-1000","OMG/USD"]
1618678153.562607: [464,{"a":[["56169.80000","0.15000000","1618678153.534116"]],"c":"3034221387"},"book-1000","XBT/CHF"]
1618678153.568344: [1920,{"a":[["0.043480","0.00000000","1618678153.540331"]],"c":"4271949488"},"book-1000","SC/EUR"]
1618678153.5766022: [1360,{"a":[["0.000022920","9695.96187490","1618678153.547978"]],"c":"1927924777"},"book-1000","ADA/XBT"]
1618678153.58444: [1840,{"b":[["9.570422","0.00000000","1618678153.556894"]],"c":"3669205763"},"book-1000","OMG/USD"]
1618678153.593853: [464,{"a":[["56474.60000","0.00000000","1618678153.566274"]],"c":"1755378768"},"book-1000","XBT/CHF"]
1618678153.610236: [1840,{"b":[["9.556774","114.97598188","1618678153.582161"]],"c":"2293152664"},"book-1000","OMG/USD"]
1618678153.620524: [1840,{"b":[["9.571019","0.00000000","1618678153.592541"]],"c":"3181292382"},"book-1000","OMG/USD"]
1618678153.623602: [992,{"b":[["351.75000000","7.36835797","1618678153.595051"]],"c":"2527844232"},"book-1000","XMR/USD"]
1618678153.62603: [1920,{"a":[["0.043130","143275.00000000","1618678153.595386"]],"c":"340610481"},"book-1000","SC/EUR"]
1618678153.6289191: [1840,{"b":[["9.562273","157.08110900","1618678153.597216"]],"c":"876052848"},"book-1000","OMG/USD"]
1618678153.629985: [1840,{"a":[["9.602664","0.00000000","1618678153.599951"]],"c":"876052848"},"book-1000","OMG/USD"]
1618678153.637377: [3648,{"b":[["0.00753900","4.70000000","1618678153.608080"]],"c":"2390679728"},"book-1000","KSM/XBT"]
1618678153.6390588: [464,{"a":[["56169.70000","0.59541531","1618678153.609108"]],"c":"2054796259"},"book-1000","XBT/CHF"]
1618678153.643656: [1360,{"a":[["0.000022910","19566.65806089","1618678153.613942"]],"c":"2396626717"},"book-1000","ADA/XBT"]
1618678153.647433: [464,{"a":[["56192.60000","0.00000000","1618678153.614501"]],"c":"1459693002"},"book-1000","XBT/CHF"]
1618678153.64924: [1840,{"a":[["9.637421","0.00000000","1618678153.616754"]],"c":"876052848"},"book-1000","OMG/USD"]
1618678153.661243: [1360,{"b":[["0.000022700","126.77411104","1618678153.633923"]],"c":"2396626717"},"book-1000","ADA/XBT"]
1618678153.690851: [464,{"a":[["56169.60000","0.15000000","1618678153.661318"]],"c":"525604260"},"book-1000","XBT/CHF"]
1618678153.693363: [464,{"a":[["56169.70000","0.00000000","1618678153.665706"]],"c":"806279951"},"book-1000","XBT/CHF"]
1618678153.7018812: [1840,{"a":[["9.667953","360.00000000","1618678153.675161"]],"c":"876052848"},"book-1000","OMG/USD"]
1618678153.733114: [464,{"a":[["56169.50000","0.59541531","1618678153.705504"]],"c":"1970971634"},"book-1000","XBT/CHF"]
1618678153.736404: [464,{"a":[["56169.80000","0.00000000","1618678153.709350"]],"c":"104259146"},"book-1000","XBT/CHF"]
1618678153.739837: [992,{"a":[["354.32000000","0.00000000","1618678153.712173"]],"c":"1960269232"},"book-1000","XMR/USD"]
1618678153.75168: [1840,{"a":[["9.593967","0.00000000","1618678153.724261"]],"c":"74817589"},"book-1000","OMG/USD"]
1618678153.774143: [464,{"a":[["56169.60000","0.00000000","1618678153.746296"]],"c":"3817739135"},"book-1000","XBT/CHF"]
1618678153.7769768: [464,{"b":[["55766.10000","0.40003900","1618678153.747886"]],"c":"3817739135"},"book-1000","XBT/CHF"]
1618678153.778702: [464,{"a":[["56169.50000","0.00000000","1618678153.750367"]],"c":"402996292"},"book-1000","XBT/CHF"]
1618678153.780249: [1840,{"a":[["9.605795","194.10704088","1618678153.750589"]],"c":"74817589"},"book-1000","OMG/USD"]
1618678153.781291: [1840,{"a":[["9.602663","0.00000000","1618678153.750782"]],"c":"868192415"},"book-1000","OMG/USD"]
1618678153.7823129: [992,{"a":[["354.28000000","6.87078474","1618678153.754070"]],"c":"82176411"},"book-1000","XMR/USD"]
1618678153.784276: [464,{"a":[["56169.40000","0.15000000","1618678153.754601"]],"c":"1510110553"},"book-1000","XBT/CHF"]
1618678153.7931972: [1360,{"a":[["0.000022950","11331.22471303","1618678153.765586"]],"c":"2399182850"},"book-1000","ADA/XBT"]
1618678153.795766: [1840,{"a":[["9.588516","137.16417853","1618678153.766316"]],"c":"2659185290"},"book-1000","OMG/USD"]
1618678153.8011289: [1840,{"b":[["9.565021","108.64728371","1618678153.772524"]],"c":"1801682865"},"book-1000","OMG/USD"]
1618678153.8205209: [464,{"a":[["56474.40000","0.59541531","1618678153.791164"]],"c":"696979112"},"book-1000","XBT/CHF"]
1618678153.82689: [992,{"b":[["353.26000000","109.74970000","1618678153.796810"]],"c":"4083343190"},"book-1000","XMR/USD"]
1618678153.83367: [496,{"b":[["2183.34000","0.00000000","1618678153.807485"]],"c":"1146436572"},"book-1000","ETH/CHF"]
1618678153.836583: [992,{"b":[["352.93000000","154.13810000","1618678153.809487"]],"c":"3197655323"},"book-1000","XMR/USD"]
1618678153.841835: [992,{"a":[["354.27000000","5.00000000","1618678153.814086"]],"c":"3402224006"},"book-1000","XMR/USD"]
1618678153.844585: [1840,{"a":[["9.588515","200.00000000","1618678153.815906"]],"c":"741064742"},"book-1000","OMG/USD"]
1618678153.8482392: [1920,{"a":[["0.043040","20000.00000000","1618678153.820115"]],"c":"355313690"},"book-1000","SC/EUR"]
1618678153.8526762: [992,{"b":[["351.28000000","17.28844103","1618678153.824925"]],"c":"3402224006"},"book-1000","XMR/USD"]
1618678153.862644: [496,{"b":[["2180.42000","1.51482481","1618678153.834980"]],"c":"763851226"},"book-1000","ETH/CHF"]
1618678153.863551: [1920,{"a":[["0.043200","0.00000000","1618678153.836558"]],"c":"355313690"},"book-1000","SC/EUR"]
1618678153.8657448: [992,{"a":[["354.69000000","170.61230000","1618678153.838101"]],"c":"3402224006"},"book-1000","XMR/USD"]
1618678153.868913: [1920,{"a":[["0.043130","1185940.60000000","1618678153.841887"]],"c":"274177858"},"book-1000","SC/EUR"]
1618678153.871016: [992,{"a":[["354.44000000","132.09920000","1618678153.842524"]],"c":"2730959102"},"book-1000","XMR/USD"]
1618678153.872687: [992,{"b":[["353.26000000","0.00000000","1618678153.843466"]],"c":"1581844005"},"book-1000","XMR/USD"]
1618678153.87428: [992,{"b":[["352.92000000","0.17106559","1618678153.845772"]],"c":"1889069432"},"book-1000","XMR/USD"]
1618678153.8756852: [992,{"b":[["353.01000000","111.91220000","1618678153.846096"]],"c":"3019940470"},"book-1000","XMR/USD"]
1618678153.894062: [992,{"b":[["353.09000000","4.35198211","1618678153.866723"]],"c":"3301853875"},"book-1000","XMR/USD"]
1618678153.896884: [1840,{"a":[["9.588517","156.03038400","1618678153.866907"]],"c":"117349971"},"book-1000","OMG/USD"]
1618678153.900316: [992,{"a":[["354.47000000","0.00000000","1618678153.872159"]],"c":"2081265659"},"book-1000","XMR/USD"]
1618678153.90697: [1920,{"b":[["0.042970","17126.31850062","1618678153.880246"]],"c":"103323056"},"book-1000","SC/EUR"]
1618678153.910723: [1920,{"a":[["0.043190","0.00000000","1618678153.883247"]],"c":"103323056"},"book-1000","SC/EUR"]
1618678153.917734: [1920,{"b":[["0.042870","0.00000000","1618678153.889663"]],"c":"3325526345"},"book-1000","SC/EUR"]
1618678153.9212859: [1920,{"b":[["0.042830","8500.00000000","1618678153.890400"]],"c":"2840459768"},"book-1000","SC/EUR"]
1618678153.9336162: [3648,{"b":[["0.00754400","5.15000000","1618678153.904892"]],"c":"987613055"},"book-1000","KSM/XBT"]
1618678153.947776: [1920,{"b":[["0.042830","0.00000000","1618678153.919235"]],"c":"3325526345"},"book-1000","SC/EUR"]
1618678153.964006: [3648,{"b":[["0.00705900","4.44795438","1618678153.933883"]],"c":"987613055"},"book-1000","KSM/XBT"]
1618678153.979838: [992,{"b":[["352.43000000","0.00000000","1618678153.951655"]],"c":"2720533591"},"book-1000","XMR/USD"]
1618678154.013039: [1664,{"b":[["13.196800","37.68563461","1618678153.985305"]],"c":"4068822152"},"book-1000","WAVES/EUR"]
1618678154.020247: [992,{"b":[["353.02000000","76.26339867","1618678153.990476"]],"c":"2878644893"},"book-1000","XMR/USD"]
1618678154.023068: [992,{"b":[["351.29000000","186.71611774","1618678153.990840"]],"c":"2878644893"},"book-1000","XMR/USD"]
1618678154.035501: [3648,{"b":[["0.00754200","0.11669845","1618678154.008528"]],"c":"3017375142"},"book-1000","KSM/XBT"]
1618678154.048115: [992,{"b":[["353.13000000","2.94348437","1618678154.018935"]],"c":"2117068767"},"book-1000","XMR/USD"]
1618678154.05497: [1920,{"b":[["0.042790","149682.00000000","1618678154.027770"]],"c":"1139066836"},"book-1000","SC/EUR"]
1618678154.0778182: [1360,{"b":[["0.000022870","16668.76413900","1618678154.049724"]],"c":"2033853250"},"book-1000","ADA/XBT"]
1618678154.0874088: [1840,{"b":[["9.518969","0.00000000","1618678154.059959"]],"c":"117349971"},"book-1000","OMG/USD"]
1618678154.09157: [1920,{"b":[["0.042780","45440.00000000","1618678154.062840"]],"c":"3962471596"},"book-1000","SC/EUR"]
1618678154.127933: [1360,{"b":[["0.000022880","7269.18401823","1618678154.100503"]],"c":"2843304165"},"book-1000","ADA/XBT"]
1618678154.1319182: [1840,{"b":[["9.513012","881.02937341","1618678154.102695"]],"c":"117349971"},"book-1000","OMG/USD"]
1618678154.133504: [992,{"b":[["351.27000000","0.00000000","1618678154.104465"]],"c":"2117068767"},"book-1000","XMR/USD"]
1618678154.135458: [1840,{"b":[["9.564553","0.00000000","1618678154.106452"]],"c":"3351012183"},"book-1000","OMG/USD"]
1618678154.1375282: [1920,{"b":[["0.040000","1660638.62443533","1618678154.107682"]],"c":"3962471596"},"book-1000","SC/EUR"]
1618678154.142266: [1920,{"a":[["0.043150","0.00000000","1618678154.115639"]],"c":"1307597711"},"book-1000","SC/EUR"]
1618678154.1585689: [1920,{"a":[["0.043120","128623.62244897","1618678154.131443"]],"c":"3673784884"},"book-1000","SC/EUR"]
1618678154.175561: [1840,{"b":[["9.538492","0.00000000","1618678154.149099"]],"c":"3351012183"},"book-1000","OMG/USD"]
1618678154.1831481: [992,{"b":[["351.88000000","75.00000000","1618678154.154274"]],"c":"2117068767"},"book-1000","XMR/USD"]
1618678154.185972: [1840,{"b":[["9.547726","522.18995500","1618678154.156725"]],"c":"2450568324"},"book-1000","OMG/USD"]
1618678154.1870568: [1840,{"a":[["9.588231","522.14566300","1618678154.156858"]],"c":"3058251783"},"book-1000","OMG/USD"]
1618678154.188242: [1920,{"a":[["0.043120","1033948.95660757","1618678154.158605"]],"c":"4094608930"},"book-1000","SC/EUR"]
1618678154.190988: [1920,{"b":[["0.042890","14267.62936447","1618678154.161134"]],"c":"2317058177"},"book-1000","SC/EUR"]
1618678154.193184: [992,{"b":[["352.91000000","0.00000000","1618678154.161509"]],"c":"856288958"},"book-1000","XMR/USD"]
1618678154.194805: [1920,{"b":[["0.042850","0.00000000","1618678154.164247"]],"c":"2495860286"},"book-1000","SC/EUR"]
1618678154.203016: [1840,{"b":[["9.573935","0.00000000","1618678154.175520"]],"c":"3352363357"},"book-1000","OMG/USD"]
1618678154.235623: [1840,{"a":[["9.599733","0.00000000","1618678154.206610"]],"c":"842982875"},"book-1000","OMG/USD"]
1618678154.2422872: [1840,{"b":[["9.565022","137.16614525","1618678154.215513"]],"c":"3597908026"},"book-1000","OMG/USD"]
1618678154.248029: [992,{"b":[["351.79000000","52.00000000","1618678154.220571"]],"c":"856288958"},"book-1000","XMR/USD"]
1618678154.261031: [992,{"a":[["354.26000000","22.72500000","1618678154.233446"]],"c":"172822640"},"book-1000","XMR/USD"]
1618678154.267244: [1664,{"b":[["13.193200","32.57000000","1618678154.239045"]],"c":"2604747964"},"book-1000","WAVES/EUR"]
1618678154.283543: [992,{"b":[["353.08000000","0.00000000","1618678154.255366"]],"c":"3044776933"},"book-1000","XMR/USD"]
1618678154.296179: [992,{"a":[["354.29000000","0.00000000","1618678154.267381"]],"c":"249419348"},"book-1000","XMR/USD"]
1618678154.300054: [992,{"b":[["353.01000000","0.00000000","1618678154.272082"]],"c":"3959564249"},"book-1000","XMR/USD"]
1618678154.310729: [992,{"a":[["355.22000000","0.00000000","1618678154.282686"]],"c":"3959564249"},"book-1000","XMR/USD"]
1618678154.313587: [496,{"b":[["2180.42000","0.00000000","1618678154.285134"]],"c":"1146436572"},"book-1000","ETH/CHF"]
1618678154.3147361: [496,{"b":[["2183.24000","1.51286820","1618678154.286102"]],"c":"3551888891"},"book-1000","ETH/CHF"]
1618678154.3182569: {"event":"heartbeat"}
1618678154.318675: [992,{"a":[["354.25000000","7.57500000","1618678154.289381"]],"c":"1549680787"},"book-1000","XMR/USD"]
1618678154.354929: [1664,{"a":[["13.252500","0.00000000","1618678154.327135"]],"c":"875715360"},"book-1000","WAVES/EUR"]
1618678154.3673542: [1920,{"a":[["0.043060","0.00000000","1618678154.339019"]],"c":"1424384375"},"book-1000","SC/EUR"]
1618678154.370955: [496,{"b":[["2153.41000","0.00000000","1618678154.340013"]],"c":"3551888891"},"book-1000","ETH/CHF"]
1618678154.410004: [496,{"b":[["2152.67000","14.30306748","1618678154.382189"]],"c":"3551888891"},"book-1000","ETH/CHF"]
1618678154.4193401: [1840,{"b":[["9.486854","0.00000000","1618678154.390648"]],"c":"3597908026"},"book-1000","OMG/USD"]
1618678154.450687: [1840,{"b":[["9.565021","0.00000000","1618678154.421442"]],"c":"3049434791"},"book-1000","OMG/USD"]
1618678154.45872: [1920,{"a":[["0.043030","109431.83886926","1618678154.429728"]],"c":"2781175364"},"book-1000","SC/EUR"]
1618678154.462513: [3648,{"a":[["0.00757800","0.00000000","1618678154.433681"]],"c":"2836031813"},"book-1000","KSM/XBT"]
1618678154.463424: [1840,{"b":[["9.563370","148.00000000","1618678154.435340"]],"c":"1341614957"},"book-1000","OMG/USD"]
1618678154.4814248: [992,{"a":[["354.81000000","5.00000000","1618678154.453800"]],"c":"1549680787"},"book-1000","XMR/USD"]
1618678154.4844558: [992,{"a":[["354.27000000","0.00000000","1618678154.453849"]],"c":"1736765136"},"book-1000","XMR/USD"]
1618678154.4867818: [1920,{"a":[["0.042990","0.00000000","1618678154.456141"]],"c":"1410524589"},"book-1000","SC/EUR"]
1618678154.489493: [1920,{"b":[["0.042820","183985.89187450","1618678154.459312"]],"c":"921409297"},"book-1000","SC/EUR"]
1618678154.531852: [992,{"a":[["354.30000000","0.00000000","1618678154.502538"]],"c":"826982359"},"book-1000","XMR/USD"]
1618678154.534684: [992,{"a":[["360.96000000","0.00000000","1618678154.503274"]],"c":"826982359"},"book-1000","XMR/USD"]
1618678154.536733: [992,{"a":[["354.26000000","0.00000000","1618678154.503398"]],"c":"448843616"},"book-1000","XMR/USD"]
1618678154.538687: [992,{"a":[["355.18000000","22.72500000","1618678154.503466"]],"c":"448843616"},"book-1000","XMR/USD"]
1618678154.54916: [1840,{"a":[["9.588230","200.00000000","1618678154.517928"]],"c":"4182070992"},"book-1000","OMG/USD"]
1618678154.550464: [1664,{"b":[["13.201000","32.86000000","1618678154.519499"]],"c":"2153599639"},"book-1000","WAVES/EUR"]
1618678154.551782: [992,{"b":[["353.00000000","5.88844731","1618678154.519781"]],"c":"3724687117"},"book-1000","XMR/USD"]
1618678154.570575: [992,{"a":[["360.84000000","23.81136851","1618678154.543391"]],"c":"3724687117"},"book-1000","XMR/USD"]
1618678154.592957: [1664,{"b":[["13.172900","0.00000000","1618678154.566034"]],"c":"2153599639"},"book-1000","WAVES/EUR"]
1618678154.600348: [1840,{"a":[["9.588515","0.00000000","1618678154.572040"]],"c":"2423205449"},"book-1000","OMG/USD"]
1618678154.609526: [1840,{"a":[["9.586367","143.00000000","1618678154.582070"]],"c":"1351327697"},"book-1000","OMG/USD"]
1618678154.6377091: [1360,{"a":[["0.000022910","18503.18486089","1618678154.608944"]],"c":"4202503914"},"book-1000","ADA/XBT"]
1618678154.64173: [1840,{"b":[["9.563821","108.65495306","1618678154.612976"]],"c":"154151474"},"book-1000","OMG/USD"]
1618678154.6577852: [3648,{"b":[["0.00754200","0.00000000","1618678154.630972"]],"c":"537842588"},"book-1000","KSM/XBT"]
1618678154.702328: [1840,{"a":[["9.588515","50.00000000","1618678154.675399"]],"c":"3312864907"},"book-1000","OMG/USD"]
1618678154.7069252: [1920,{"a":[["0.043120","905325.33415860","1618678154.680000"]],"c":"4053816275"},"book-1000","SC/EUR"]
1618678154.7437031: [496,{"b":[["2183.34000","1.51279890","1618678154.716275"]],"c":"2255081407"},"book-1000","ETH/CHF"]
1618678154.7453911: [496,{"b":[["2183.24000","0.00000000","1618678154.717701"]],"c":"3030498967"},"book-1000","ETH/CHF"]
1618678154.755533: [1920,{"a":[["0.043030","89431.83886926","1618678154.727485"]],"c":"3365932044"},"book-1000","SC/EUR"]
1618678154.761774: [992,{"b":[["353.14000000","7.00000000","1618678154.732985"]],"c":"2116004314"},"book-1000","XMR/USD"]
1618678154.76494: [1360,{"b":[["0.000022860","28652.59371878","1618678154.737043"]],"c":"2037021083"},"book-1000","ADA/XBT"]
1618678154.782515: [1840,{"a":[["9.605795","0.00000000","1618678154.751604"]],"c":"3312864907"},"book-1000","OMG/USD"]
1618678154.784055: [1920,{"a":[["0.043010","0.00000000","1618678154.752238"]],"c":"2802629312"},"book-1000","SC/EUR"]
1618678154.7870631: [496,{"b":[["2180.15000","3.00000000","1618678154.752587"]],"c":"1204706764"},"book-1000","ETH/CHF"]
1618678154.787945: [1840,{"a":[["9.596670","194.10704088","1618678154.752749"]],"c":"1184179531"},"book-1000","OMG/USD"]
1618678154.7889578: [1920,{"b":[["0.042840","0.00000000","1618678154.753753"]],"c":"1764309359"},"book-1000","SC/EUR"]
1618678154.7912378: [1840,{"b":[["9.517776","272.22078717","1618678154.753858"]],"c":"1184179531"},"book-1000","OMG/USD"]
1618678154.793439: [1360,{"b":[["0.000022880","12269.18401823","1618678154.765271"]],"c":"2420057479"},"book-1000","ADA/XBT"]
1618678154.7993321: [992,{"b":[["353.09000000","0.00000000","1618678154.771521"]],"c":"2971531407"},"book-1000","XMR/USD"]
1618678154.802166: [992,{"b":[["353.15000000","4.35124281","1618678154.771605"]],"c":"1044620313"},"book-1000","XMR/USD"]
1618678154.808081: [1840,{"b":[["9.563370","0.00000000","1618678154.779636"]],"c":"1868108745"},"book-1000","OMG/USD"]
1618678154.8095691: [1840,{"b":[["9.469371","2.00000000","1618678154.780995"]],"c":"1868108745"},"book-1000","OMG/USD"]
1618678154.839843: [992,{"a":[["354.28000000","0.00000000","1618678154.812190"]],"c":"2109435283"},"book-1000","XMR/USD"]
1618678154.854717: [1840,{"a":[["9.588516","0.00000000","1618678154.826840"]],"c":"1893742906"},"book-1000","OMG/USD"]
1618678154.864059: [992,{"a":[["354.24000000","5.00000000","1618678154.837311"]],"c":"3008439890"},"book-1000","XMR/USD"]
1618678154.867048: [992,{"b":[["351.56000000","12.00000000","1618678154.839158"]],"c":"3008439890"},"book-1000","XMR/USD"]
1618678154.869109: [992,{"b":[["352.65000000","114.57860000","1618678154.839310"]],"c":"3952367226"},"book-1000","XMR/USD"]
1618678154.884654: [3648,{"b":[["0.00754200","0.11669845","1618678154.858267"]],"c":"2836031813"},"book-1000","KSM/XBT"]
1618678154.8912299: [1840,{"b":[["9.565023","2.00000000","1618678154.860339"]],"c":"3412165037"},"book-1000","OMG/USD"]
1618678154.900106: [1840,{"a":[["9.586366","137.17228350","1618678154.866088"]],"c":"1344434604"},"book-1000","OMG/USD"]
1618678154.901969: [992,{"a":[["354.24000000","11.87103237","1618678154.870191"]],"c":"3743128222"},"book-1000","XMR/USD"]
1618678154.9218612: [992,{"a":[["354.81000000","0.00000000","1618678154.890689"]],"c":"3743128222"},"book-1000","XMR/USD"]
1618678154.9305: [1920,{"b":[["0.042970","0.00000000","1618678154.897835"]],"c":"505756997"},"book-1000","SC/EUR"]
1618678154.934062: [496,{"b":[["2179.27000","0.10200000","1618678154.898009"]],"c":"4208380029"},"book-1000","ETH/CHF"]
1618678154.937195: [992,{"a":[["354.07000000","12.12000000","1618678154.900979"]],"c":"3054652875"},"book-1000","XMR/USD"]
1618678154.9395578: [992,{"b":[["353.30000000","6.86986179","1618678154.902875"]],"c":"545090822"},"book-1000","XMR/USD"]
1618678154.941602: [992,{"b":[["351.79000000","0.00000000","1618678154.903300"]],"c":"545090822"},"book-1000","XMR/USD"]
1618678154.943501: [1360,{"a":[["0.000022910","14219.99185460","1618678154.909252"]],"c":"525249648"},"book-1000","ADA/XBT"]
1618678154.955721: [1920,{"b":[["0.042890","0.00000000","1618678154.924381"]],"c":"1016630133"},"book-1000","SC/EUR"]
1618678154.973523: [1840,{"b":[["9.563821","0.00000000","1618678154.938107"]],"c":"2094052423"},"book-1000","OMG/USD"]
1618678154.975274: [3648,{"a":[["0.00757900","4.90000000","1618678154.939982"]],"c":"1984212229"},"book-1000","KSM/XBT"]
1618678154.979136: [1920,{"b":[["0.042830","20000.00000000","1618678154.949010"]],"c":"1235630696"},"book-1000","SC/EUR"]
1618678154.982551: [1920,{"a":[["0.043030","109431.83886926","1618678154.950562"]],"c":"849586100"},"book-1000","SC/EUR"]
1618678154.987494: [992,{"a":[["354.81000000","5.00000000","1618678154.952209"]],"c":"545090822"},"book-1000","XMR/USD"]
1618678154.9899032: [992,{"a":[["354.24000000","6.87103237","1618678154.952261"]],"c":"348201245"},"book-1000","XMR/USD"]
1618678154.996383: [992,{"b":[["353.03000000","15.27000000","1618678154.963128"]],"c":"2055153576"},"book-1000","XMR/USD"]
1618678155.005337: [992,{"b":[["352.66000000","52.00000000","1618678154.973611"]],"c":"2055153576"},"book-1000","XMR/USD"]
1618678155.008192: [1360,{"a":[["0.000022920","10666.53746623","1618678154.975004"]],"c":"3309337813"},"book-1000","ADA/XBT"]
1618678155.1162171: [992,{"a":[["354.85000000","0.00000000","1618678155.081479"]],"c":"2055153576"},"book-1000","XMR/USD"]
1618678155.119095: [1920,{"b":[["0.042940","16448.72189840","1618678155.086487"]],"c":"3486806786"},"book-1000","SC/EUR"]
1618678155.1220648: [992,{"a":[["354.07000000","15.65300000","1618678155.090063"]],"c":"1266894314"},"book-1000","XMR/USD"]
1618678155.147886: [1920,{"b":[["0.042840","30681.31485711","1618678155.119216"]],"c":"2492597098"},"book-1000","SC/EUR"]
1618678155.1516101: [1920,{"a":[["0.043150","19981.39745075","1618678155.119670"]],"c":"2365057023"},"book-1000","SC/EUR"]
1618678155.1542652: [1664,{"a":[["13.234700","102.00000000","1618678155.121266"]],"c":"3037894056"},"book-1000","WAVES/EUR"]
1618678155.166059: [1664,{"b":[["13.206500","35.14000000","1618678155.130488"]],"c":"2640104603"},"book-1000","WAVES/EUR"]
1618678155.1768792: [992,{"a":[["354.52000000","0.00000000","1618678155.140985"]],"c":"3745025018"},"book-1000","XMR/USD"]
1618678155.1799161: [3648,{"b":[["0.00719900","0.00000000","1618678155.141623"]],"c":"1984212229"},"book-1000","KSM/XBT"]
1618678155.184962: [1664,{"a":[["13.252500","64.28070000","1618678155.147298"]],"c":"1802709720"},"book-1000","WAVES/EUR"]
1618678155.190856: [992,{"b":[["325.00000000","70.47693000","1618678155.154460"]],"c":"3745025018"},"book-1000","XMR/USD"]
1618678155.200992: [1664,{"b":[["13.185900","350.84408229","1618678155.168108"]],"c":"1802709720"},"book-1000","WAVES/EUR"]
1618678155.207723: [1664,{"b":[["13.201900","500.00000000","1618678155.170903"]],"c":"4199056436"},"book-1000","WAVES/EUR"]
1618678155.213983: [3648,{"b":[["0.00720600","36.74619625","1618678155.179810"]],"c":"1984212229"},"book-1000","KSM/XBT"]
1618678155.215353: [1664,{"b":[["13.178300","0.00000000","1618678155.181546"]],"c":"4199056436"},"book-1000","WAVES/EUR"]
1618678155.2377: [992,{"b":[["300.00000000","122.05162362","1618678155.194620"]],"c":"3745025018"},"book-1000","XMR/USD"]
1618678155.240003: [1840,{"b":[["9.561620","108.66107309","1618678155.197527"]],"c":"1890881360"},"book-1000","OMG/USD"]
1618678155.241054: [1840,{"a":[["9.586365","200.00000000","1618678155.203710"]],"c":"2038409240"},"book-1000","OMG/USD"]
1618678155.25404: [1664,{"b":[["13.176600","99.75164649","1618678155.221072"]],"c":"4199056436"},"book-1000","WAVES/EUR"]
1618678155.258421: [1664,{"b":[["13.201900","0.00000000","1618678155.222375"]],"c":"1802709720"},"book-1000","WAVES/EUR"]
1618678155.260183: [992,{"a":[["357.12000000","0.00000000","1618678155.228254"]],"c":"3745025018"},"book-1000","XMR/USD"]
1618678155.262317: [1664,{"b":[["13.178400","0.00000000","1618678155.229272"]],"c":"1802709720"},"book-1000","WAVES/EUR"]
1618678155.277222: [1664,{"b":[["13.176500","0.00000000","1618678155.232283"]],"c":"1802709720"},"book-1000","WAVES/EUR"]
1618678155.27914: [496,{"a":[["2191.55000","0.00000000","1618678155.233194"]],"c":"2622601729"},"book-1000","ETH/CHF"]
1618678155.280243: [496,{"a":[["2190.02000","0.79681000","1618678155.233281"]],"c":"875179542"},"book-1000","ETH/CHF"]
1618678155.281086: [464,{"a":[["56169.40000","0.00000000","1618678155.243518"]],"c":"393802153"},"book-1000","XBT/CHF"]
1618678155.284084: [464,{"a":[["56169.80000","0.15000000","1618678155.243758"]],"c":"640612632"},"book-1000","XBT/CHF"]
1618678155.2863429: [5104,{"a":[["0.000027820","1212.68560477","1618678155.250616"]],"c":"2576202275"},"book-1000","OCEAN/XBT"]
1618678155.2897122: [1360,{"b":[["0.000022870","11668.76413900","1618678155.262163"]],"c":"1164118330"},"book-1000","ADA/XBT"]
1618678155.294612: [992,{"a":[["356.70000000","1.85882822","1618678155.264241"]],"c":"3745025018"},"book-1000","XMR/USD"]
1618678155.302111: [992,{"b":[["351.78000000","0.00000000","1618678155.267777"]],"c":"3745025018"},"book-1000","XMR/USD"]
1618678155.3049119: [496,{"a":[["2192.02000","1.15978265","1618678155.269438"]],"c":"944033862"},"book-1000","ETH/CHF"]
1618678155.305851: [496,{"a":[["2191.54000","0.00000000","1618678155.269572"]],"c":"1004274035"},"book-1000","ETH/CHF"]
1618678155.306707: [1840,{"a":[["9.588230","0.00000000","1618678155.270834"]],"c":"1502967005"},"book-1000","OMG/USD"]
1618678155.307986: [1840,{"b":[["9.565022","0.00000000","1618678155.274772"]],"c":"1860797214"},"book-1000","OMG/USD"]
1618678155.3098161: [1840,{"a":[["9.588230","155.48750800","1618678155.279046"]],"c":"4167445726"},"book-1000","OMG/USD"]
1618678155.322243: {"event":"heartbeat"}
1618678155.3500931: [1840,{"b":[["9.565023","139.14994563","1618678155.316156"]],"c":"3943812637"},"book-1000","OMG/USD"]
1618678155.351676: [1840,{"a":[["9.667953","0.00000000","1618678155.318348"]],"c":"3943812637"},"book-1000","OMG/USD"]
1618678155.3529532: [1840,{"a":[["9.586367","0.00000000","1618678155.318992"]],"c":"4162703615"},"book-1000","OMG/USD"]
1618678155.35401: [1920,{"a":[["0.043040","0.00000000","1618678155.320871"]],"c":"3398118564"},"book-1000","SC/EUR"]
1618678155.368591: [1920,{"a":[["0.043030","66970.00000000","1618678155.334579"]],"c":"2782492782"},"book-1000","SC/EUR"]
1618678155.372127: [496,{"a":[["2223.29000","0.00000000","1618678155.337844"]],"c":"1004274035"},"book-1000","ETH/CHF"]
1618678155.376192: [1360,{"a":[["0.000022900","9365.29975312","1618678155.340379"]],"c":"2538738420"},"book-1000","ADA/XBT"]
1618678155.4013388: [1920,{"a":[["0.043160","0.00000000","1618678155.359809"]],"c":"3496680426"},"book-1000","SC/EUR"]
1618678155.404875: [992,{"a":[["354.07000000","22.72143660","1618678155.360134"]],"c":"2948374419"},"book-1000","XMR/USD"]
1618678155.406958: [1920,{"b":[["0.042790","0.00000000","1618678155.360725"]],"c":"4192026477"},"book-1000","SC/EUR"]
1618678155.4093702: [496,{"a":[["2190.01000","3.00000000","1618678155.363142"]],"c":"1888752808"},"book-1000","ETH/CHF"]
1618678155.410377: [1920,{"a":[["0.043090","137235.00000000","1618678155.369130"]],"c":"3781084236"},"book-1000","SC/EUR"]
1618678155.41264: [1920,{"b":[["0.042820","52472.89187450","1618678155.371860"]],"c":"1103632056"},"book-1000","SC/EUR"]
1618678155.414845: [4528,{"a":[["0.000835600","0.00000000","1618678155.371982"]],"c":"3433916767"},"book-1000","GRT/ETH"]
1618678155.415273: [1920,{"a":[["0.043040","42461.83886926","1618678155.381692"]],"c":"4204072771"},"book-1000","SC/EUR"]
1618678155.429528: [1840,{"a":[["9.636818","360.00000000","1618678155.398371"]],"c":"4162703615"},"book-1000","OMG/USD"]
1618678155.4389088: [496,{"a":[["2213.75000","9.39000000","1618678155.403972"]],"c":"1888752808"},"book-1000","ETH/CHF"]
1618678155.44052: [3648,{"a":[["0.00757500","0.00000000","1618678155.409423"]],"c":"3793130634"},"book-1000","KSM/XBT"]
1618678155.4477398: [1920,{"a":[["0.043010","20000.00000000","1618678155.417098"]],"c":"2903187569"},"book-1000","SC/EUR"]
1618678155.451276: [4528,{"a":[["0.000837000","304.17989619","1618678155.420629"]],"c":"2678851092"},"book-1000","GRT/ETH"]
1618678155.46602: [464,{"b":[["56021.40000","0.00882000","1618678155.433236"]],"c":"2771932968"},"book-1000","XBT/CHF"]
1618678155.468433: [1664,{"a":[["13.241400","101.00000000","1618678155.436194"]],"c":"4081540204"},"book-1000","WAVES/EUR"]
1618678155.4699771: [1664,{"b":[["13.171900","0.00000000","1618678155.436296"]],"c":"4081540204"},"book-1000","WAVES/EUR"]
1618678155.509655: [1664,{"b":[["13.173400","99.77587711","1618678155.477873"]],"c":"4081540204"},"book-1000","WAVES/EUR"]
1618678155.511551: [992,{"a":[["354.34000000","0.00000000","1618678155.478205"]],"c":"4177678494"},"book-1000","XMR/USD"]
1618678155.513848: [1664,{"b":[["13.176600","0.00000000","1618678155.480563"]],"c":"4081540204"},"book-1000","WAVES/EUR"]
1618678155.539876: [464,{"b":[["56024.10000","0.00000000","1618678155.512458"]],"c":"3124439906"},"book-1000","XBT/CHF"]
1618678155.542607: [1360,{"a":[["0.000022950","10584.16491659","1618678155.515522"]],"c":"1669385270"},"book-1000","ADA/XBT"]
1618678155.545728: [464,{"b":[["56024.10000","0.03425949","1618678155.516133"]],"c":"1504214707"},"book-1000","XBT/CHF"]
1618678155.5530229: [992,{"a":[["354.12000000","7.57500000","1618678155.525394"]],"c":"3460049610"},"book-1000","XMR/USD"]
1618678155.5561202: [1840,{"b":[["9.517776","0.00000000","1618678155.526896"]],"c":"4162703615"},"book-1000","OMG/USD"]
1618678155.5716171: [1360,{"a":[["0.000022960","32323.58979644","1618678155.543418"]],"c":"1851636379"},"book-1000","ADA/XBT"]
1618678155.5923069: [1920,{"b":[["0.042940","0.00000000","1618678155.563009"]],"c":"1106395663"},"book-1000","SC/EUR"]
1618678155.608135: [1840,{"a":[["9.636818","0.00000000","1618678155.579264"]],"c":"4162703615"},"book-1000","OMG/USD"]
1618678155.6279309: [496,{"b":[["2095.79000","0.00000000","1618678155.600523"]],"c":"1888752808"},"book-1000","ETH/CHF"]
1618678155.63996: [1920,{"a":[["0.043030","46970.00000000","1618678155.610924"]],"c":"524934119"},"book-1000","SC/EUR"]
1618678155.6437418: [1664,{"a":[["13.245200","0.00000000","1618678155.614237"]],"c":"1032416748"},"book-1000","WAVES/EUR"]
1618678155.649483: [992,{"a":[["354.25000000","0.00000000","1618678155.622014"]],"c":"644557685"},"book-1000","XMR/USD"]
1618678155.6525598: [1664,{"a":[["13.252500","0.00000000","1618678155.622484"]],"c":"4140461728"},"book-1000","WAVES/EUR"]
1618678155.654221: [1664,{"b":[["13.182100","143.35200000","1618678155.622804"]],"c":"4140461728"},"book-1000","WAVES/EUR"]
1618678155.655523: [1840,{"b":[["9.511510","0.00000000","1618678155.626397"]],"c":"4162703615"},"book-1000","OMG/USD"]
1618678155.656706: [1360,{"b":[["0.000022880","13355.96971823","1618678155.628343"]],"c":"971082857"},"book-1000","ADA/XBT"]
1618678155.660449: [1840,{"a":[["9.588518","64.10000000","1618678155.630366"]],"c":"886337924"},"book-1000","OMG/USD"]
1618678155.667277: [1840,{"a":[["9.667953","360.00000000","1618678155.639928"]],"c":"886337924"},"book-1000","OMG/USD"]
1618678155.668993: [496,{"b":[["2092.81000","72.33863871","1618678155.640962"]],"c":"1888752808"},"book-1000","ETH/CHF"]
1618678155.677121: [1664,{"b":[["13.173200","66.25659655","1618678155.649676"]],"c":"4140461728"},"book-1000","WAVES/EUR"]
1618678155.6822321: [1840,{"b":[["9.562040","48.63979000","1618678155.654362"]],"c":"3794738224"},"book-1000","OMG/USD"]
1618678155.683797: [1664,{"a":[["13.234600","0.00000000","1618678155.655002"]],"c":"1155501165"},"book-1000","WAVES/EUR"]
1618678155.688676: [1840,{"b":[["9.545953","0.00000000","1618678155.661900"]],"c":"2278140127"},"book-1000","OMG/USD"]
1618678155.690306: [1840,{"a":[["9.588518","0.00000000","1618678155.662805"]],"c":"715240077"},"book-1000","OMG/USD"]
1618678155.69757: [1664,{"a":[["13.234700","0.00000000","1618678155.670332"]],"c":"3068646525"},"book-1000","WAVES/EUR"]
1618678155.699748: [1360,{"b":[["0.000022880","12269.18401823","1618678155.672241"]],"c":"1851636379"},"book-1000","ADA/XBT"]
1618678155.702946: [1664,{"b":[["13.213200","101.00000000","1618678155.672641"]],"c":"715030582"},"book-1000","WAVES/EUR"]
1618678155.704361: [1664,{"b":[["13.203700","601.00000000","1618678155.675070"]],"c":"2011554842"},"book-1000","WAVES/EUR"]
1618678155.728082: [4528,{"b":[["0.000832500","0.00000000","1618678155.700786"]],"c":"2009970608"},"book-1000","GRT/ETH"]
1618678155.729174: [1360,{"a":[["0.000022910","15289.79525460","1618678155.701812"]],"c":"412398087"},"book-1000","ADA/XBT"]
1618678155.7330089: [1664,{"b":[["13.187800","0.00000000","1618678155.705595"]],"c":"2011554842"},"book-1000","WAVES/EUR"]
1618678155.7365482: [1664,{"a":[["13.254900","816.98000000","1618678155.707153"]],"c":"4141573199"},"book-1000","WAVES/EUR"]
1618678155.73827: [1360,{"a":[["0.000022900","7175.08484526","1618678155.707442"]],"c":"605042312"},"book-1000","ADA/XBT"]
1618678155.741241: [1664,{"a":[["13.246000","0.00000000","1618678155.709467"]],"c":"2145042040"},"book-1000","WAVES/EUR"]
1618678155.7425458: [1664,{"b":[["13.196600","1085.13000000","1618678155.711526"]],"c":"289480721"},"book-1000","WAVES/EUR"]
1618678155.7437508: [1664,{"b":[["13.206900","0.00000000","1618678155.715321"]],"c":"2778194291"},"book-1000","WAVES/EUR"]
1618678155.7450519: [1664,{"b":[["13.207000","500.00000000","1618678155.716207"]],"c":"4275433085"},"book-1000","WAVES/EUR"]
1618678155.756497: [1920,{"a":[["0.042980","0.00000000","1618678155.718950"],["0.043000","965.15385023","1618678155.720582"]],"c":"1009224149"},"book-1000","SC/EUR"]
1618678155.76004: [4528,{"a":[["0.000835800","0.00000000","1618678155.724856"]],"c":"2301591422"},"book-1000","GRT/ETH"]
1618678155.7603788: [1840,{"b":[["9.556775","105.00000000","1618678155.726051"]],"c":"2177153889"},"book-1000","OMG/USD"]
1618678155.7616692: [1664,{"b":[["13.196800","0.00000000","1618678155.726814"]],"c":"2623481587"},"book-1000","WAVES/EUR"]
1618678155.763016: [1664,{"a":[["13.260400","335.25360000","1618678155.729394"]],"c":"2719175186"},"book-1000","WAVES/EUR"]
1618678155.766266: [1840,{"b":[["9.519364","272.15673653","1618678155.738625"]],"c":"2177153889"},"book-1000","OMG/USD"]
1618678155.767594: [992,{"b":[["351.09000000","0.14241363","1618678155.740469"]],"c":"644557685"},"book-1000","XMR/USD"]
1618678155.770675: [1664,{"b":[["13.193300","35.11315059","1618678155.741267"]],"c":"1962883667"},"book-1000","WAVES/EUR"]
1618678155.771997: [1664,{"b":[["13.173400","0.00000000","1618678155.742237"]],"c":"1962883667"},"book-1000","WAVES/EUR"]
1618678155.7731571: [1664,{"b":[["13.185900","355.02758107","1618678155.743911"]],"c":"1962883667"},"book-1000","WAVES/EUR"]
1618678155.780062: [496,{"a":[["2190.16000","0.00000000","1618678155.751252"]],"c":"3987014154"},"book-1000","ETH/CHF"]
1618678155.783078: [1360,{"a":[["0.000022910","17480.06695063","1618678155.753908"]],"c":"924487362"},"book-1000","ADA/XBT"]
1618678155.786721: [1664,{"b":[["13.199700","0.00000000","1618678155.756732"]],"c":"1748770365"},"book-1000","WAVES/EUR"]
1618678155.788086: [1664,{"b":[["13.213300","151.36264218","1618678155.757810"]],"c":"1288408145"},"book-1000","WAVES/EUR"]
1618678155.817211: [1840,{"b":[["9.565055","143.00000000","1618678155.789107"]],"c":"4137625574"},"book-1000","OMG/USD"]
1618678155.82371: [1664,{"a":[["13.242900","0.00000000","1618678155.795249"]],"c":"1379303403"},"book-1000","WAVES/EUR"]
1618678155.8295429: [1664,{"a":[["13.241300","539.67771095","1618678155.801374"]],"c":"302466598"},"book-1000","WAVES/EUR"]
1618678155.831451: [1664,{"a":[["13.312500","1321.27991302","1618678155.801583"]],"c":"302466598"},"book-1000","WAVES/EUR"]
1618678155.832952: [1664,{"b":[["13.203700","101.00000000","1618678155.801786"]],"c":"102823724"},"book-1000","WAVES/EUR"]
1618678155.834234: [1664,{"a":[["13.253700","2047.10000000","1618678155.802330"]],"c":"2966971396"},"book-1000","WAVES/EUR"]
1618678155.835744: [1664,{"b":[["13.213600","45.06851683","1618678155.804046"]],"c":"2589270072"},"book-1000","WAVES/EUR"]
1618678155.837049: [1360,{"a":[["0.000022910","13877.81025063","1618678155.807999"]],"c":"2215459347"},"book-1000","ADA/XBT"]
1618678155.8395789: [5104,{"b":[["0.000027690","0.00000000","1618678155.808157"]],"c":"2772763336"},"book-1000","OCEAN/XBT"]
1618678155.8402681: [5104,{"b":[["0.000027660","1542.69769975","1618678155.809719"]],"c":"1768309762"},"book-1000","OCEAN/XBT"]
1618678155.8484328: [1360,{"b":[["0.000022870","12691.16413900","1618678155.818007"]],"c":"3944798600"},"book-1000","ADA/XBT"]
1618678155.854683: [1664,{"a":[["13.241400","0.00000000","1618678155.827631"]],"c":"2483085583"},"book-1000","WAVES/EUR"]
1618678155.8564548: [1920,{"a":[["0.043010","0.00000000","1618678155.828021"]],"c":"2950479373"},"book-1000","SC/EUR"]
1618678155.859384: [1920,{"a":[["0.043020","20000.00000000","1618678155.828090"]],"c":"3309855654"},"book-1000","SC/EUR"]
1618678155.861952: [1360,{"b":[["0.000022850","14228.66696383","1618678155.832938"]],"c":"4114204534"},"book-1000","ADA/XBT"]
1618678155.865505: [1360,{"b":[["0.000022870","13704.16413900","1618678155.839131"]],"c":"655617908"},"book-1000","ADA/XBT"]
1618678155.87517: [1664,{"a":[["13.259700","0.00000000","1618678155.848087"]],"c":"2331607057"},"book-1000","WAVES/EUR"]
1618678155.8797572: [1664,{"b":[["13.168800","0.00000000","1618678155.850320"]],"c":"2331607057"},"book-1000","WAVES/EUR"]
1618678155.881469: [1664,{"a":[["13.253700","2016.43000000","1618678155.851365"]],"c":"2848491476"},"book-1000","WAVES/EUR"]
1618678155.882755: [1664,{"b":[["13.210800","500.00000000","1618678155.852334"]],"c":"854695979"},"book-1000","WAVES/EUR"]
1618678155.88591: [1664,{"b":[["13.185800","0.00000000","1618678155.859404"]],"c":"854695979"},"book-1000","WAVES/EUR"]
1618678155.8877409: [1360,{"a":[["0.000022940","30972.11612581","1618678155.861539"]],"c":"4283355077"},"book-1000","ADA/XBT"]
1618678155.8909702: [1360,{"a":[["0.000022900","7015.08484526","1618678155.864024"]],"c":"3748702573"},"book-1000","ADA/XBT"]
1618678155.898858: [1664,{"b":[["13.213200","131.72000000","1618678155.872217"]],"c":"4070507395"},"book-1000","WAVES/EUR"]
1618678155.900983: [1664,{"b":[["13.090200","0.00000000","1618678155.873560"]],"c":"4070507395"},"book-1000","WAVES/EUR"]
1618678155.905074: [1920,{"b":[["0.042880","0.00000000","1618678155.877461"]],"c":"2833270494"},"book-1000","SC/EUR"]
1618678155.915384: [1360,{"a":[["0.000022910","13059.01025063","1618678155.886747"]],"c":"1041492999"},"book-1000","ADA/XBT"]
1618678155.918823: [1840,{"b":[["9.547726","0.00000000","1618678155.888679"]],"c":"3819898535"},"book-1000","OMG/USD"]
1618678155.921746: [1360,{"a":[["0.000022930","3479.13590000","1618678155.893026"]],"c":"2932835339"},"book-1000","ADA/XBT"]
1618678155.925738: [464,{"b":[["56024.10000","0.00000000","1618678155.895130"]],"c":"3124439906"},"book-1000","XBT/CHF"]
1618678155.92735: [464,{"b":[["56024.10000","0.05895595","1618678155.896765"]],"c":"2771932968"},"book-1000","XBT/CHF"]
1618678155.928768: [1664,{"b":[["13.185900","4.18349878","1618678155.898841"]],"c":"4070507395"},"book-1000","WAVES/EUR"]
1618678155.929993: [1664,{"a":[["13.276100","348.16526710","1618678155.899559"]],"c":"4070507395"},"book-1000","WAVES/EUR"]
1618678155.94121: [1664,{"a":[["13.260400","0.00000000","1618678155.912144"]],"c":"1776906795"},"book-1000","WAVES/EUR"]
1618678155.943398: [1664,{"a":[["13.345300","0.00000000","1618678155.915538"]],"c":"1776906795"},"book-1000","WAVES/EUR"]
1618678155.944892: [1840,{"a":[["9.588230","0.00000000","1618678155.916434"]],"c":"1385779364"},"book-1000","OMG/USD"]
1618678155.947343: [1840,{"a":[["9.588517","0.00000000","1618678155.919856"]],"c":"4007641527"},"book-1000","OMG/USD"]
1618678155.948668: [1920,{"a":[["0.043090","0.00000000","1618678155.921499"]],"c":"3720805224"},"book-1000","SC/EUR"]
1618678155.9573262: [1360,{"a":[["0.000022920","9668.53746623","1618678155.929668"]],"c":"1590912033"},"book-1000","ADA/XBT"]
1618678155.9613812: [1664,{"b":[["13.203700","0.00000000","1618678155.931520"]],"c":"692111720"},"book-1000","WAVES/EUR"]
1618678155.962712: [1840,{"a":[["9.586366","0.00000000","1618678155.932927"]],"c":"102071376"},"book-1000","OMG/USD"]
1618678155.966221: [1840,{"b":[["9.562320","521.98294000","1618678155.939181"]],"c":"3155728571"},"book-1000","OMG/USD"]
1618678155.9736881: [992,{"a":[["354.24000000","0.00000000","1618678155.945376"]],"c":"1902625988"},"book-1000","XMR/USD"]
1618678155.976529: [1664,{"a":[["13.249300","0.00000000","1618678155.945469"]],"c":"2727708988"},"book-1000","WAVES/EUR"]
1618678155.9779031: [1664,{"b":[["13.175700","15.05570266","1618678155.945671"]],"c":"2727708988"},"book-1000","WAVES/EUR"]
1618678155.979433: [1360,{"a":[["0.000022910","7059.01025063","1618678155.949562"]],"c":"406427794"},"book-1000","ADA/XBT"]
1618678155.9820218: [1360,{"b":[["0.000022880","18269.18401823","1618678155.949721"]],"c":"2648579829"},"book-1000","ADA/XBT"]
1618678155.984322: [1360,{"a":[["0.000022920","15668.53746623","1618678155.949792"]],"c":"1284381557"},"book-1000","ADA/XBT"]
1618678155.986667: [1920,{"b":[["0.042850","5816.46917318","1618678155.955609"]],"c":"2300064054"},"book-1000","SC/EUR"]
1618678155.990349: [1664,{"b":[["13.213400","500.00000000","1618678155.963334"]],"c":"2533523088"},"book-1000","WAVES/EUR"]
1618678155.991596: [1664,{"b":[["13.207000","0.00000000","1618678155.963461"]],"c":"1721692626"},"book-1000","WAVES/EUR"]
1618678155.9926348: [1840,{"a":[["9.586364","137.14459004","1618678155.963964"]],"c":"2804887926"},"book-1000","OMG/USD"]
1618678156.0058181: [1664,{"a":[["13.251100","29.89513527","1618678155.977158"]],"c":"968724656"},"book-1000","WAVES/EUR"]
1618678156.009964: [1664,{"a":[["13.264100","217.03789812","1618678155.980990"]],"c":"3992465668"},"book-1000","WAVES/EUR"]
1618678156.011658: [1664,{"a":[["13.264100","97.87903437","1618678155.982588"]],"c":"200575809"},"book-1000","WAVES/EUR"]
1618678156.01315: [992,{"a":[["354.06000000","6.86977239","1618678155.984292"]],"c":"2105418125"},"book-1000","XMR/USD"]
1618678156.015198: [992,{"a":[["353.98000000","12.36000000","1618678155.986359"]],"c":"362160"},"book-1000","XMR/USD"]
1618678156.01936: [1664,{"b":[["13.213600","0.00000000","1618678155.990228"]],"c":"929933356"},"book-1000","WAVES/EUR"]
1618678156.02404: [992,{"a":[["354.12000000","0.00000000","1618678155.993783"]],"c":"361169073"},"book-1000","XMR/USD"]
1618678156.0267541: [1664,{"a":[["13.253700","0.00000000","1618678155.995294"]],"c":"4009296350"},"book-1000","WAVES/EUR"]
1618678156.0283442: [1664,{"b":[["13.193300","0.00000000","1618678155.998978"]],"c":"940927391"},"book-1000","WAVES/EUR"]
1618678156.029658: [1664,{"b":[["13.193300","99.62538014","1618678155.999188"]],"c":"1626120350"},"book-1000","WAVES/EUR"]
1618678156.031262: [1664,{"b":[["13.196600","0.00000000","1618678156.004701"]],"c":"3023300744"},"book-1000","WAVES/EUR"]
1618678156.038578: [1664,{"a":[["13.254900","0.00000000","1618678156.007051"]],"c":"2619125749"},"book-1000","WAVES/EUR"]
1618678156.0404391: [1920,{"a":[["0.043000","0.00000000","1618678156.008179"]],"c":"2308103967"},"book-1000","SC/EUR"]
1618678156.043406: [1840,{"a":[["9.596670","0.00000000","1618678156.010354"]],"c":"2494550057"},"book-1000","OMG/USD"]
1618678156.04448: [1664,{"a":[["13.266900","318.78000000","1618678156.011796"]],"c":"391594304"},"book-1000","WAVES/EUR"]
1618678156.053168: [1664,{"a":[["13.247100","0.00000000","1618678156.026213"]],"c":"3815868838"},"book-1000","WAVES/EUR"]
1618678156.054762: [1664,{"b":[["13.206700","0.00000000","1618678156.027622"]],"c":"3796934833"},"book-1000","WAVES/EUR"]
1618678156.0563111: [1664,{"b":[["13.210800","0.00000000","1618678156.029503"]],"c":"1975605389"},"book-1000","WAVES/EUR"]
1618678156.074497: [1840,{"a":[["9.605795","194.10704088","1618678156.047375"]],"c":"2494550057"},"book-1000","OMG/USD"]
1618678156.077461: [1920,{"a":[["0.043020","0.00000000","1618678156.049898"]],"c":"2927101937"},"book-1000","SC/EUR"]
1618678156.095055: [464,{"b":[["55610.80000","0.00000000","1618678156.067130"]],"c":"2771932968"},"book-1000","XBT/CHF"]
1618678156.0972002: [464,{"a":[["56959.80000","0.00000000","1618678156.067440"]],"c":"2771932968"},"book-1000","XBT/CHF"]
1618678156.0988648: [464,{"a":[["56734.20000","0.00400000","1618678156.067508"]],"c":"2771932968"},"book-1000","XBT/CHF"]
1618678156.107166: [1664,{"a":[["13.264200","0.00000000","1618678156.080671"]],"c":"4126026236"},"book-1000","WAVES/EUR"]
1618678156.124363: [1840,{"a":[["9.593971","0.00000000","1618678156.096220"]],"c":"1010288120"},"book-1000","OMG/USD"]
1618678156.1310909: [1664,{"b":[["13.144000","1000.00000000","1618678156.103635"]],"c":"4126026236"},"book-1000","WAVES/EUR"]
1618678156.1355991: [464,{"b":[["55594.40000","0.55691176","1618678156.107688"]],"c":"2771932968"},"book-1000","XBT/CHF"]
1618678156.137662: [464,{"a":[["56951.60000","0.55691176","1618678156.108540"]],"c":"2771932968"},"book-1000","XBT/CHF"]
1618678156.144384: [1920,{"b":[["0.042840","0.00000000","1618678156.114638"]],"c":"2010414928"},"book-1000","SC/EUR"]
1618678156.1477382: [1840,{"a":[["9.588231","0.00000000","1618678156.116003"]],"c":"3077101751"},"book-1000","OMG/USD"]
1618678156.1494389: [1920,{"b":[["0.042860","30666.99755718","1618678156.122414"]],"c":"1263241164"},"book-1000","SC/EUR"]
1618678156.1521769: [1920,{"a":[["0.043150","0.00000000","1618678156.122740"]],"c":"176745657"},"book-1000","SC/EUR"]
1618678156.15462: [1920,{"a":[["0.043030","0.00000000","1618678156.125408"]],"c":"29681787"},"book-1000","SC/EUR"]
1618678156.156854: [1920,{"a":[["0.043050","0.00000000","1618678156.125869"]],"c":"2612493704"},"book-1000","SC/EUR"]
1618678156.159047: [1920,{"a":[["0.043110","78613.31941544","1618678156.126878"]],"c":"3932384142"},"book-1000","SC/EUR"]
1618678156.1612532: [1920,{"b":[["0.042870","31680.00000000","1618678156.127487"]],"c":"1438470398"},"book-1000","SC/EUR"]
1618678156.16343: [1840,{"b":[["9.556774","0.00000000","1618678156.127984"]],"c":"3997209400"},"book-1000","OMG/USD"]
1618678156.164287: [1664,{"a":[["13.266800","74.57826302","1618678156.128188"]],"c":"121800383"},"book-1000","WAVES/EUR"]
1618678156.1656032: [1664,{"a":[["13.264100","0.00000000","1618678156.128617"]],"c":"4017443313"},"book-1000","WAVES/EUR"]
1618678156.1666439: [496,{"a":[["2190.02000","0.00000000","1618678156.131157"]],"c":"1774683169"},"book-1000","ETH/CHF"]
1618678156.1673632: [1840,{"a":[["9.703429","0.00000000","1618678156.133400"]],"c":"3997209400"},"book-1000","OMG/USD"]
1618678156.171934: [1840,{"b":[["9.483833","4603.00000000","1618678156.144343"]],"c":"3997209400"},"book-1000","OMG/USD"]
1618678156.175075: [992,{"a":[["353.98000000","0.00000000","1618678156.147572"]],"c":"371765868"},"book-1000","XMR/USD"]
1618678156.177483: [1840,{"a":[["9.586363","200.00000000","1618678156.149616"]],"c":"1166280550"},"book-1000","OMG/USD"]
1618678156.17835: [1840,{"a":[["9.586365","0.00000000","1618678156.150961"]],"c":"2847886743"},"book-1000","OMG/USD"]
1618678156.1984031: [1664,{"a":[["13.259800","0.00000000","1618678156.168754"]],"c":"1000208521"},"book-1000","WAVES/EUR"]
1618678156.200298: [1920,{"a":[["0.043110","0.00000000","1618678156.169260"]],"c":"808378298"},"book-1000","SC/EUR"]
1618678156.203563: [1840,{"b":[["9.565056","114.97598188","1618678156.171879"]],"c":"2819682118"},"book-1000","OMG/USD"]
1618678156.2046452: [992,{"b":[["351.28000000","5.64844103","1618678156.172447"]],"c":"371765868"},"book-1000","XMR/USD"]
1618678156.206484: [1664,{"a":[["13.251100","0.00000000","1618678156.173512"]],"c":"3943440523"},"book-1000","WAVES/EUR"]
1618678156.207542: [992,{"a":[["354.07000000","15.65300000","1618678156.173666"]],"c":"2359096279"},"book-1000","XMR/USD"]
1618678156.209218: [1664,{"a":[["13.267900","30.26000000","1618678156.175311"]],"c":"1990354905"},"book-1000","WAVES/EUR"]
1618678156.233357: [496,{"a":[["2189.99000","0.79681000","1618678156.204905"]],"c":"3223862298"},"book-1000","ETH/CHF"]
1618678156.240771: [1840,{"b":[["9.565056","0.00000000","1618678156.212020"]],"c":"2847886743"},"book-1000","OMG/USD"]
1618678156.249312: [1664,{"a":[["13.265100","66.10505062","1618678156.222394"]],"c":"2156569489"},"book-1000","WAVES/EUR"]
1618678156.2694862: [1920,{"a":[["0.043470","23255.81395348","1618678156.242126"]],"c":"765765452"},"book-1000","SC/EUR"]
1618678156.2806022: [1840,{"b":[["9.565057","200.00000000","1618678156.251196"]],"c":"2034282901"},"book-1000","OMG/USD"]
1618678156.284846: [1840,{"b":[["9.556474","114.97598188","1618678156.253819"]],"c":"1917941584"},"book-1000","OMG/USD"]
1618678156.302965: [496,{"a":[["2189.98000","3.00000000","1618678156.272981"]],"c":"541633124"},"book-1000","ETH/CHF"]
1618678156.307969: [1664,{"a":[["13.345600","0.00000000","1618678156.275712"]],"c":"2156569489"},"book-1000","WAVES/EUR"]
1618678156.309696: [1664,{"b":[["13.168900","0.00000000","1618678156.276632"]],"c":"2156569489"},"book-1000","WAVES/EUR"]
1618678156.317939: {"event":"heartbeat"}
1618678156.328106: [1664,{"b":[["13.187900","0.00000000","1618678156.298856"]],"c":"1896361781"},"book-1000","WAVES/EUR"]
1618678156.3388932: [1840,{"b":[["9.565057","0.00000000","1618678156.303003"]],"c":"914606082"},"book-1000","OMG/USD"]
1618678156.34197: [464,{"b":[["56024.10000","0.00000000","1618678156.313737"]],"c":"3124439906"},"book-1000","XBT/CHF"]
1618678156.344214: [464,{"b":[["56024.10000","0.03425948","1618678156.314218"]],"c":"1809760930"},"book-1000","XBT/CHF"]
1618678156.346106: [1664,{"a":[["13.284100","132.20585322","1618678156.317750"]],"c":"3836426627"},"book-1000","WAVES/EUR"]
1618678156.3492858: [496,{"a":[["2190.01000","0.00000000","1618678156.320034"]],"c":"1565628313"},"book-1000","ETH/CHF"]
1618678156.356075: [1840,{"a":[["9.596671","0.00000000","1618678156.328649"]],"c":"3503693957"},"book-1000","OMG/USD"]
1618678156.362431: [1664,{"b":[["13.186000","1396.00000000","1618678156.334874"]],"c":"632344080"},"book-1000","WAVES/EUR"]
1618678156.375214: [1664,{"a":[["13.589900","350.29073962","1618678156.348436"]],"c":"632344080"},"book-1000","WAVES/EUR"]
1618678156.3807218: [1840,{"a":[["9.600564","0.00000000","1618678156.353037"]],"c":"3224944072"},"book-1000","OMG/USD"]
1618678156.382197: [1664,{"a":[["13.315400","8338.00000000","1618678156.353404"]],"c":"632344080"},"book-1000","WAVES/EUR"]
1618678156.391268: [1664,{"b":[["13.201100","415.00000000","1618678156.362623"]],"c":"1511510484"},"book-1000","WAVES/EUR"]
1618678156.3931599: [1920,{"a":[["0.043000","11802.77325050","1618678156.362696"]],"c":"4271151170"},"book-1000","SC/EUR"]
1618678156.3974478: [1840,{"b":[["9.565023","2.00000000","1618678156.370651"]],"c":"1200668863"},"book-1000","OMG/USD"]
1618678156.399659: [1840,{"a":[["9.595323","148.00000000","1618678156.372036"]],"c":"2583008988"},"book-1000","OMG/USD"]
1618678156.401275: [1840,{"b":[["9.555932","280.00000000","1618678156.373205"]],"c":"2797408015"},"book-1000","OMG/USD"]
1618678156.428288: [1664,{"b":[["13.193400","357.53883443","1618678156.401440"]],"c":"3238400729"},"book-1000","WAVES/EUR"]
1618678156.4411469: [1840,{"b":[["9.565056","137.08346917","1618678156.412526"]],"c":"1282568178"},"book-1000","OMG/USD"]
1618678156.453865: [1920,{"b":[["0.042820","194013.89187450","1618678156.426962"]],"c":"476263434"},"book-1000","SC/EUR"]
1618678156.4636679: [1664,{"b":[["13.193500","99.62387505","1618678156.437442"]],"c":"3362335063"},"book-1000","WAVES/EUR"]
1618678156.465535: [1664,{"b":[["13.193300","0.00000000","1618678156.437892"]],"c":"2425413718"},"book-1000","WAVES/EUR"]
1618678156.469151: [1360,{"b":[["0.000022870","7704.16413900","1618678156.441508"]],"c":"2109187664"},"book-1000","ADA/XBT"]
1618678156.4836748: [1920,{"a":[["0.043490","0.00000000","1618678156.455748"]],"c":"1893350738"},"book-1000","SC/EUR"]
1618678156.541037: [1664,{"a":[["13.312800","0.00000000","1618678156.513533"]],"c":"2425413718"},"book-1000","WAVES/EUR"]
1618678156.5604239: [1840,{"a":[["9.693688","2.00000000","1618678156.533987"]],"c":"1282568178"},"book-1000","OMG/USD"]
1618678156.567807: [1920,{"a":[["0.043000","0.00000000","1618678156.538379"]],"c":"4201375908"},"book-1000","SC/EUR"]
1618678156.599713: [1664,{"a":[["13.284000","1396.00000000","1618678156.571987"]],"c":"3240097100"},"book-1000","WAVES/EUR"]
1618678156.653406: [5104,{"b":[["0.000027700","1257.03953953","1618678156.623505"]],"c":"1707408278"},"book-1000","OCEAN/XBT"]
1618678156.6812: [1360,{"b":[["0.000022880","23952.72504855","1618678156.651842"]],"c":"2880113771"},"book-1000","ADA/XBT"]
1618678156.7167501: [1920,{"a":[["0.043090","44640.00000000","1618678156.687928"]],"c":"593413948"},"book-1000","SC/EUR"]
1618678156.7204978: [1360,{"b":[["0.000022880","21761.96262926","1618678156.688256"]],"c":"415549216"},"book-1000","ADA/XBT"]
1618678156.7285519: [1920,{"a":[["0.043030","11802.77325050","1618678156.700969"]],"c":"3022247493"},"book-1000","SC/EUR"]
1618678156.7397919: [1664,{"a":[["13.267500","800.53000000","1618678156.709385"]],"c":"3997973919"},"book-1000","WAVES/EUR"]
1618678156.741728: [1664,{"b":[["13.209200","1037.55000000","1618678156.709475"]],"c":"2359022011"},"book-1000","WAVES/EUR"]
1618678156.755831: [1920,{"b":[["0.042750","0.00000000","1618678156.720486"]],"c":"2453874839"},"book-1000","SC/EUR"]
1618678156.759369: [1920,{"b":[["0.042890","29780.00000000","1618678156.720821"]],"c":"33622049"},"book-1000","SC/EUR"]
1618678156.7678962: [1840,{"a":[["9.586364","0.00000000","1618678156.725102"]],"c":"776319728"},"book-1000","OMG/USD"]
1618678156.769453: [1360,{"b":[["0.000022880","23951.83077641","1618678156.731330"]],"c":"545303065"},"book-1000","ADA/XBT"]
1618678156.7727108: [1840,{"a":[["9.588514","137.05507040","1618678156.738654"]],"c":"4202994765"},"book-1000","OMG/USD"]
1618678156.789873: [3648,{"a":[["0.00758000","0.59700000","1618678156.761535"]],"c":"2997746796"},"book-1000","KSM/XBT"]
1618678156.794971: [1664,{"a":[["13.312600","0.00000000","1618678156.766963"]],"c":"2359022011"},"book-1000","WAVES/EUR"]
1618678156.811938: [496,{"b":[["2100.96000","0.00000000","1618678156.783258"]],"c":"1565628313"},"book-1000","ETH/CHF"]
1618678156.813586: [992,{"a":[["354.12000000","7.57500000","1618678156.784831"]],"c":"1988897804"},"book-1000","XMR/USD"]
1618678156.822619: [1840,{"a":[["9.701958","0.00000000","1618678156.794101"]],"c":"4202994765"},"book-1000","OMG/USD"]
1618678156.826863: [5104,{"a":[["0.000027820","593.84154000","1618678156.798916"]],"c":"2065078184"},"book-1000","OCEAN/XBT"]
1618678156.8336031: [1840,{"b":[["9.569838","146.00000000","1618678156.806160"]],"c":"2272105486"},"book-1000","OMG/USD"]
1618678156.835145: [1664,{"a":[["13.241300","0.00000000","1618678156.806773"]],"c":"561635335"},"book-1000","WAVES/EUR"]
1618678156.844385: [3648,{"b":[["0.00756200","0.00000000","1618678156.817293"]],"c":"2712421532"},"book-1000","KSM/XBT"]
1618678156.84756: [1920,{"a":[["0.044250","0.00000000","1618678156.818085"]],"c":"33622049"},"book-1000","SC/EUR"]
1618678156.8509161: [1664,{"a":[["13.264900","2072.62000000","1618678156.820682"]],"c":"2281121631"},"book-1000","WAVES/EUR"]
1618678156.870595: [1664,{"a":[["13.266800","0.00000000","1618678156.841369"]],"c":"1730118799"},"book-1000","WAVES/EUR"]
1618678156.872504: [496,{"a":[["2258.69000","0.00000000","1618678156.841811"]],"c":"1565628313"},"book-1000","ETH/CHF"]
1618678156.8738759: [1664,{"a":[["13.265000","74.58838295","1618678156.843878"]],"c":"3676764692"},"book-1000","WAVES/EUR"]
1618678156.8751712: [1360,{"a":[["0.000022920","16658.53746623","1618678156.843998"]],"c":"2886760133"},"book-1000","ADA/XBT"]
1618678156.8800142: [1664,{"a":[["13.387300","1321.27991302","1618678156.848860"]],"c":"3676764692"},"book-1000","WAVES/EUR"]
1618678156.881414: [1664,{"a":[["13.265000","614.26609390","1618678156.849101"]],"c":"2820833896"},"book-1000","WAVES/EUR"]
1618678156.882658: [1840,{"b":[["9.569839","156.44463700","1618678156.853941"]],"c":"4279957644"},"book-1000","OMG/USD"]
1618678156.884823: [3648,{"b":[["0.00755800","0.21000000","1618678156.855896"]],"c":"3827199099"},"book-1000","KSM/XBT"]
1618678156.888214: [1840,{"b":[["9.565188","154.76749300","1618678156.858603"]],"c":"406328748"},"book-1000","OMG/USD"]
1618678156.889388: [1920,{"a":[["0.044220","328876.47802590","1618678156.860443"]],"c":"33622049"},"book-1000","SC/EUR"]
1618678156.909635: [1664,{"a":[["13.263400","34.33444000","1618678156.882337"]],"c":"1328577517"},"book-1000","WAVES/EUR"]
1618678156.9127328: [3648,{"b":[["0.00749600","9.09746666","1618678156.885303"]],"c":"3827199099"},"book-1000","KSM/XBT"]
1618678156.9510431: [1664,{"b":[["13.213300","0.00000000","1618678156.923705"]],"c":"359403276"},"book-1000","WAVES/EUR"]
1618678156.953266: [1840,{"a":[["9.605795","0.00000000","1618678156.925212"]],"c":"2941825280"},"book-1000","OMG/USD"]
1618678156.954526: [1840,{"a":[["9.605795","154.15215501","1618678156.925445"]],"c":"3516081713"},"book-1000","OMG/USD"]
1618678156.9638898: [1664,{"a":[["13.265000","772.86069708","1618678156.935893"]],"c":"3209613390"},"book-1000","WAVES/EUR"]
1618678156.980994: [1664,{"a":[["13.345200","0.00000000","1618678156.953701"]],"c":"3209613390"},"book-1000","WAVES/EUR"]
1618678156.9863732: [1664,{"b":[["13.205600","50.82518350","1618678156.958885"]],"c":"2102559721"},"book-1000","WAVES/EUR"]
1618678156.990595: [1664,{"a":[["13.312500","0.00000000","1618678156.963162"]],"c":"2102559721"},"book-1000","WAVES/EUR"]
1618678156.995899: [1664,{"b":[["13.213500","151.36035115","1618678156.967932"]],"c":"3573420070"},"book-1000","WAVES/EUR"]
1618678157.0013518: [1664,{"a":[["13.264800","500.00000000","1618678156.974659"]],"c":"1717771755"},"book-1000","WAVES/EUR"]
1618678157.0055602: [1840,{"a":[["9.591245","158.25369800","1618678156.975764"]],"c":"3164374883"},"book-1000","OMG/USD"]
1618678157.016882: [3648,{"a":[["0.00758300","42.08487212","1618678156.989573"]],"c":"1318515866"},"book-1000","KSM/XBT"]
1618678157.0182452: [1840,{"b":[["9.569838","219.00000000","1618678156.989667"]],"c":"3523404694"},"book-1000","OMG/USD"]
1618678157.028907: [1664,{"a":[["13.264500","29.89513527","1618678157.002124"]],"c":"624483761"},"book-1000","WAVES/EUR"]
1618678157.033376: [496,{"b":[["2096.01000","16.67110500","1618678157.005501"]],"c":"1565628313"},"book-1000","ETH/CHF"]
1618678157.034657: [5104,{"a":[["0.000027830","618.83779234","1618678157.005658"]],"c":"4121358666"},"book-1000","OCEAN/XBT"]
1618678157.0371299: [5104,{"b":[["0.000027700","638.19459000","1618678157.007415"]],"c":"1305830309"},"book-1000","OCEAN/XBT"]
1618678157.047016: [1360,{"b":[["0.000022390","122.30731049","1618678157.020408"]],"c":"2886760133"},"book-1000","ADA/XBT"]
1618678157.062282: [1664,{"a":[["13.265000","698.27231413","1618678157.032034"]],"c":"3040198624"},"book-1000","WAVES/EUR"]
1618678157.0641742: [1664,{"a":[["13.256800","99.00000000","1618678157.034216"]],"c":"4195425653"},"book-1000","WAVES/EUR"]
1618678157.065668: [1664,{"a":[["13.266800","91.36678776","1618678157.035155"]],"c":"2776260855"},"book-1000","WAVES/EUR"]
1618678157.068595: [1664,{"b":[["13.220100","103.00000000","1618678157.041488"]],"c":"3275391062"},"book-1000","WAVES/EUR"]
1618678157.082336: [992,{"b":[["353.02000000","0.00000000","1618678157.052204"]],"c":"501798709"},"book-1000","XMR/USD"]
1618678157.0851588: [1664,{"b":[["13.213600","500.00000000","1618678157.052475"]],"c":"3854452133"},"book-1000","WAVES/EUR"]
1618678157.08671: [1840,{"a":[["9.605795","0.00000000","1618678157.056861"]],"c":"2301904090"},"book-1000","OMG/USD"]
1618678157.089409: [1840,{"a":[["9.618614","194.10704088","1618678157.061446"]],"c":"2301904090"},"book-1000","OMG/USD"]
1618678157.091941: [496,{"a":[["2255.68000","28.63031442","1618678157.063366"]],"c":"1565628313"},"book-1000","ETH/CHF"]
1618678157.098829: [1664,{"a":[["13.266800","0.00000000","1618678157.067917"]],"c":"3267358086"},"book-1000","WAVES/EUR"]
1618678157.100786: [1664,{"a":[["13.266800","37.30072812","1618678157.068069"]],"c":"2125847319"},"book-1000","WAVES/EUR"]
1618678157.108108: [1664,{"b":[["13.213500","0.00000000","1618678157.080533"]],"c":"3871912346"},"book-1000","WAVES/EUR"]
1618678157.112062: [1840,{"a":[["9.693687","3107.23011200","1618678157.084766"]],"c":"2301904090"},"book-1000","OMG/USD"]
1618678157.12079: [1920,{"a":[["0.043110","19988.23474831","1618678157.092975"]],"c":"2013725662"},"book-1000","SC/EUR"]
1618678157.1243021: [3648,{"b":[["0.00750300","0.00000000","1618678157.093032"]],"c":"1318515866"},"book-1000","KSM/XBT"]
1618678157.14117: [992,{"a":[["354.12000000","0.00000000","1618678157.113691"]],"c":"3891792110"},"book-1000","XMR/USD"]
1618678157.150655: [1664,{"a":[["13.266800","0.00000000","1618678157.122922"]],"c":"2323462699"},"book-1000","WAVES/EUR"]
1618678157.152568: [1664,{"b":[["13.220200","151.28364169","1618678157.123097"]],"c":"4143773393"},"book-1000","WAVES/EUR"]
1618678157.1542568: [1664,{"a":[["13.276000","119.15886375","1618678157.125322"]],"c":"4143773393"},"book-1000","WAVES/EUR"]
1618678157.1579142: [1664,{"b":[["13.213400","0.00000000","1618678157.127509"]],"c":"3859566840"},"book-1000","WAVES/EUR"]
1618678157.176311: [1664,{"b":[["13.205600","0.00000000","1618678157.148850"]],"c":"918984905"},"book-1000","WAVES/EUR"]
1618678157.183489: [1920,{"a":[["0.043130","1042665.60000000","1618678157.154523"]],"c":"3787689710"},"book-1000","SC/EUR"]
1618678157.18702: [992,{"a":[["356.70000000","0.14260046","1618678157.155314"]],"c":"3891792110"},"book-1000","XMR/USD"]
1618678157.2112231: [992,{"a":[["354.18000000","12.00000000","1618678157.178372"]],"c":"2210647882"},"book-1000","XMR/USD"]
1618678157.2140758: [3648,{"b":[["0.00754200","0.00000000","1618678157.179260"]],"c":"3348254275"},"book-1000","KSM/XBT"]
1618678157.221738: [992,{"b":[["351.69000000","12.36000000","1618678157.193962"]],"c":"2210647882"},"book-1000","XMR/USD"]
1618678157.230589: [1840,{"a":[["9.586363","0.00000000","1618678157.201908"]],"c":"450991540"},"book-1000","OMG/USD"]
1618678157.236816: [1360,{"a":[["0.000023820","161.67322565","1618678157.208769"]],"c":"2886760133"},"book-1000","ADA/XBT"]
1618678157.245047: [1664,{"b":[["13.217200","500.00000000","1618678157.218118"]],"c":"3641823715"},"book-1000","WAVES/EUR"]
1618678157.252722: [1664,{"b":[["13.193200","0.00000000","1618678157.221797"]],"c":"3641823715"},"book-1000","WAVES/EUR"]
1618678157.254346: [1664,{"b":[["13.220100","136.99000000","1618678157.224726"]],"c":"2906395579"},"book-1000","WAVES/EUR"]
1618678157.257882: [1360,{"b":[["0.000022870","6681.76413900","1618678157.225379"]],"c":"2214694476"},"book-1000","ADA/XBT"]
1618678157.271434: [5104,{"b":[["0.000027700","1257.01737043","1618678157.242899"]],"c":"2146275938"},"book-1000","OCEAN/XBT"]
1618678157.272565: [1840,{"b":[["9.556474","0.00000000","1618678157.244230"]],"c":"450991540"},"book-1000","OMG/USD"]
1618678157.286384: [1360,{"a":[["0.000022950","5584.16491659","1618678157.259190"]],"c":"2982158178"},"book-1000","ADA/XBT"]
1618678157.2894568: [1360,{"a":[["0.000022960","37323.58979644","1618678157.259439"]],"c":"3500474173"},"book-1000","ADA/XBT"]
1618678157.317491: {"event":"heartbeat"}
1618678157.708139: [1664,{"b":[["13.213600","0.00000000","1618678157.636406"]],"c":"1184186038"},"book-1000","WAVES/EUR"]
1618678158.0213811: [1920,{"a":[["0.043030","10721.04662050","1618678157.908269"]],"c":"722269960"},"book-1000","SC/EUR"]
1618678158.024534: [1664,{"a":[["13.276100","352.33625293","1618678157.913981"]],"c":"1184186038"},"book-1000","WAVES/EUR"]
1618678158.025859: [1840,{"b":[["9.565565","114.97598188","1618678157.915676"]],"c":"3771464264"},"book-1000","OMG/USD"]
1618678158.026901: [1920,{"b":[["0.042960","20188.72189840","1618678157.926550"]],"c":"194143715"},"book-1000","SC/EUR"]
1618678158.0291688: [992,{"a":[["356.70000000","0.00000000","1618678157.930594"]],"c":"2210647882"},"book-1000","XMR/USD"]
1618678158.030954: [992,{"a":[["355.85000000","82.14357013","1618678157.932043"]],"c":"2210647882"},"book-1000","XMR/USD"]
1618678158.032695: [1920,{"a":[["0.043170","144704.00000000","1618678157.935050"]],"c":"725867206"},"book-1000","SC/EUR"]
1618678158.034961: [1920,{"a":[["0.043040","0.00000000","1618678157.936031"]],"c":"3969489798"},"book-1000","SC/EUR"]
1618678158.037196: [1920,{"b":[["0.042820","52472.89187450","1618678157.936389"]],"c":"343630678"},"book-1000","SC/EUR"]
1618678158.039392: [1920,{"a":[["0.043030","0.00000000","1618678157.937566"]],"c":"614485556"},"book-1000","SC/EUR"]
1618678158.041654: [1360,{"b":[["0.000022850","15156.46696383","1618678157.938199"]],"c":"1085025543"},"book-1000","ADA/XBT"]
1618678158.044161: [464,{"a":[["56914.60000","0.00000000","1618678157.944931"]],"c":"1809760930"},"book-1000","XBT/CHF"]
1618678158.045491: [1920,{"b":[["0.042960","15188.72189840","1618678157.946108"]],"c":"460381266"},"book-1000","SC/EUR"]
1618678158.047692: [1920,{"a":[["0.043040","20000.00000000","1618678157.958294"]],"c":"2116642403"},"book-1000","SC/EUR"]
1618678158.049854: [1840,{"b":[["9.572438","146.00000000","1618678157.958950"]],"c":"3579496022"},"book-1000","OMG/USD"]
1618678158.050666: [992,{"b":[["351.46000000","5.66091140","1618678157.967591"]],"c":"2210647882"},"book-1000","XMR/USD"]
1618678158.052227: [1920,{"b":[["0.042830","0.00000000","1618678157.968443"]],"c":"3660851022"},"book-1000","SC/EUR"]
1618678158.054239: [1840,{"b":[["9.545945","0.00000000","1618678157.969174"]],"c":"3579496022"},"book-1000","OMG/USD"]
1618678158.054996: [1360,{"b":[["0.000022880","18268.28974609","1618678157.969429"]],"c":"3196578982"},"book-1000","ADA/XBT"]
1618678158.057045: [992,{"b":[["353.16000000","7.00000000","1618678157.970486"]],"c":"66564514"},"book-1000","XMR/USD"]
1618678158.0584252: [3648,{"b":[["0.00753700","0.11677586","1618678157.972341"]],"c":"3957512461"},"book-1000","KSM/XBT"]
1618678158.059029: [3648,{"a":[["0.00757700","4.85000000","1618678157.972740"]],"c":"55654154"},"book-1000","KSM/XBT"]
1618678158.059616: [3648,{"b":[["0.00754400","0.00000000","1618678157.973007"]],"c":"1887478656"},"book-1000","KSM/XBT"]
1618678158.060199: [1840,{"a":[["9.593356","144.00000000","1618678157.973564"]],"c":"1186673199"},"book-1000","OMG/USD"]
1618678158.060888: [4528,{"b":[["0.000833400","506.86531733","1618678157.979957"]],"c":"364527037"},"book-1000","GRT/ETH"]
1618678158.061107: [4528,{"a":[["0.000837200","304.10395344","1618678157.980528"]],"c":"3437052571"},"book-1000","GRT/ETH"]
1618678158.061321: [1840,{"b":[["9.486858","209.09518033","1618678157.981779"]],"c":"1186673199"},"book-1000","OMG/USD"]
1618678158.0620081: [1360,{"a":[["0.000023820","4964.98145729","1618678157.994325"]],"c":"3196578982"},"book-1000","ADA/XBT"]
1618678158.0642939: [1840,{"b":[["9.565056","0.00000000","1618678157.996680"]],"c":"43351684"},"book-1000","OMG/USD"]
1618678158.0650082: [5104,{"a":[["0.000027810","12.00000000","1618678158.008457"]],"c":"2496390250"},"book-1000","OCEAN/XBT"]
1618678158.065579: [5104,{"b":[["0.000027720","929.26111711","1618678158.009676"]],"c":"1722741493"},"book-1000","OCEAN/XBT"]
1618678158.066122: [1840,{"a":[["9.604804","521.91266800","1618678158.012117"]],"c":"971744107"},"book-1000","OMG/USD"]
1618678158.0668192: [992,{"a":[["354.72000000","0.00000000","1618678158.015629"]],"c":"259865838"},"book-1000","XMR/USD"]
1618678158.0682151: [1920,{"b":[["0.041660","0.00000000","1618678158.015829"]],"c":"3660851022"},"book-1000","SC/EUR"]
1618678158.0700212: [1920,{"b":[["0.041700","328874.91030292","1618678158.016748"]],"c":"3660851022"},"book-1000","SC/EUR"]
1618678158.0718348: [1360,{"b":[["0.000022870","10969.18214387","1618678158.018380"]],"c":"1759567877"},"book-1000","ADA/XBT"]
1618678158.073792: [1840,{"a":[["9.594823","521.86431300","1618678158.020664"]],"c":"2622120164"},"book-1000","OMG/USD"]
1618678158.074527: [992,{"a":[["355.04000000","275.75810000","1618678158.026904"]],"c":"259865838"},"book-1000","XMR/USD"]
1618678158.075947: [992,{"b":[["353.31000000","5.00000000","1618678158.034610"]],"c":"823692294"},"book-1000","XMR/USD"]
1618678158.0775669: [1360,{"a":[["0.000022950","10584.16491659","1618678158.034694"]],"c":"3020106843"},"book-1000","ADA/XBT"]
1618678158.079572: [992,{"b":[["353.31000000","12.57500000","1618678158.036243"]],"c":"2916894123"},"book-1000","XMR/USD"]
1618678158.08094: [992,{"a":[["354.12000000","7.57500000","1618678158.036495"]],"c":"1081439865"},"book-1000","XMR/USD"]
1618678158.082252: [992,{"b":[["353.31000000","35.30000000","1618678158.043336"]],"c":"667764240"},"book-1000","XMR/USD"]
1618678158.0835378: [1360,{"b":[["0.000022890","1067.53620000","1618678158.044361"]],"c":"932572912"},"book-1000","ADA/XBT"]
1618678158.0852532: [1360,{"b":[["0.000022890","0.00000000","1618678158.047954"]],"c":"3020106843"},"book-1000","ADA/XBT"]
1618678158.087441: [1664,{"b":[["13.209600","50.82518350","1618678158.049958"]],"c":"59644368"},"book-1000","WAVES/EUR"]
1618678158.088178: [3648,{"a":[["0.00756600","2.39142427","1618678158.053179"]],"c":"2722045260"},"book-1000","KSM/XBT"]
1618678158.088663: [1664,{"a":[["13.265000","158.59460318","1618678158.053235"]],"c":"1460644290"},"book-1000","WAVES/EUR"]
1618678158.089351: [1840,{"a":[["9.591245","0.00000000","1618678158.053942"]],"c":"4117130471"},"book-1000","OMG/USD"]
1618678158.089907: [1920,{"b":[["0.043020","19451.47745395","1618678158.057189"]],"c":"1371356022"},"book-1000","SC/EUR"]
1618678158.091561: [1360,{"b":[["0.000022870","16969.18214387","1618678158.058945"]],"c":"2295790715"},"book-1000","ADA/XBT"]
1618678158.093099: [1360,{"a":[["0.000022900","7175.08484526","1618678158.064291"]],"c":"3644188430"},"book-1000","ADA/XBT"]
1618678158.10211: [464,{"b":[["56060.10000","0.00000000","1618678158.071390"]],"c":"1332619605"},"book-1000","XBT/CHF"]
1618678158.1044621: [496,{"b":[["2183.23000","0.00000000","1618678158.072590"]],"c":"641075988"},"book-1000","ETH/CHF"]
1618678158.105543: [992,{"b":[["353.17000000","4.35099614","1618678158.072984"]],"c":"2881644023"},"book-1000","XMR/USD"]
1618678158.1076381: [496,{"b":[["2183.35000","0.79260000","1618678158.073886"]],"c":"906918400"},"book-1000","ETH/CHF"]
1618678158.108741: [3648,{"a":[["0.00757400","0.00000000","1618678158.076005"]],"c":"3072150464"},"book-1000","KSM/XBT"]
1618678158.109531: [1360,{"a":[["0.000022910","5989.20685063","1618678158.077029"]],"c":"2167685841"},"book-1000","ADA/XBT"]
1618678158.1119292: [1920,{"a":[["0.043220","183452.67067430","1618678158.079086"]],"c":"2470036304"},"book-1000","SC/EUR"]
1618678158.114028: [1360,{"b":[["0.000022880","12268.28974609","1618678158.079223"]],"c":"80987318"},"book-1000","ADA/XBT"]
1618678158.116002: [1360,{"a":[["0.000022910","11989.20685063","1618678158.079292"]],"c":"656454049"},"book-1000","ADA/XBT"]
1618678158.118199: [1360,{"a":[["0.000022910","9798.93515460","1618678158.083095"]],"c":"3088285728"},"book-1000","ADA/XBT"]
1618678158.1201742: [464,{"a":[["56169.90000","0.01700000","1618678158.083832"]],"c":"1217310692"},"book-1000","XBT/CHF"]
1618678158.1212091: [1920,{"a":[["0.043110","58168.23474831","1618678158.084010"]],"c":"2691546060"},"book-1000","SC/EUR"]
1618678158.1229959: [992,{"b":[["353.14000000","0.00000000","1618678158.086791"]],"c":"1622814177"},"book-1000","XMR/USD"]
1618678158.124344: [496,{"a":[["2189.98000","0.00000000","1618678158.088819"]],"c":"285020320"},"book-1000","ETH/CHF"]
1618678158.124915: [1360,{"a":[["0.000022900","9365.08987894","1618678158.090091"]],"c":"3527594737"},"book-1000","ADA/XBT"]
1618678158.126847: [992,{"a":[["354.07000000","12.12000000","1618678158.091435"]],"c":"233681968"},"book-1000","XMR/USD"]
1618678158.128313: [1840,{"b":[["9.572439","156.15142500","1618678158.094351"]],"c":"2943940055"},"book-1000","OMG/USD"]
1618678158.129003: [464,{"b":[["56059.90000","0.12518839","1618678158.097759"]],"c":"2826501610"},"book-1000","XBT/CHF"]
1618678158.129961: [1920,{"a":[["0.043080","42461.83886926","1618678158.098295"]],"c":"1932806790"},"book-1000","SC/EUR"]
1618678158.131571: [1664,{"a":[["13.267900","0.00000000","1618678158.099582"]],"c":"2429124399"},"book-1000","WAVES/EUR"]
1618678158.1324952: [3648,{"b":[["0.00755900","0.16890103","1618678158.101678"]],"c":"463184309"},"book-1000","KSM/XBT"]
1618678158.133002: [5104,{"b":[["0.000027630","16.93777050","1618678158.104898"]],"c":"2234668827"},"book-1000","OCEAN/XBT"]
1618678158.1382568: [5104,{"a":[["0.000027880","41.04853696","1618678158.111791"]],"c":"307222504"},"book-1000","OCEAN/XBT"]
1618678158.150563: [1920,{"a":[["0.043090","0.00000000","1618678158.121762"]],"c":"4190367019"},"book-1000","SC/EUR"]
1618678158.154355: [1920,{"a":[["0.043110","38180.00000000","1618678158.126240"]],"c":"1695093875"},"book-1000","SC/EUR"]
1618678158.161071: [3648,{"a":[["0.00757700","0.00000000","1618678158.133860"]],"c":"2897144442"},"book-1000","KSM/XBT"]
1618678158.162428: [1360,{"a":[["0.000022930","3511.64896627","1618678158.134452"]],"c":"3922476322"},"book-1000","ADA/XBT"]
1618678158.167906: [1920,{"a":[["0.043040","0.00000000","1618678158.135041"]],"c":"1242909698"},"book-1000","SC/EUR"]
1618678158.1709042: [992,{"a":[["355.06000000","0.00000000","1618678158.142247"]],"c":"233681968"},"book-1000","XMR/USD"]
1618678158.172781: [1920,{"b":[["0.042920","41650.00000000","1618678158.144476"]],"c":"2635428842"},"book-1000","SC/EUR"]
1618678158.174943: [1920,{"b":[["0.042780","0.00000000","1618678158.146233"]],"c":"4267414243"},"book-1000","SC/EUR"]
1618678158.176975: [464,{"b":[["55766.10000","0.00000000","1618678158.147147"]],"c":"2826501610"},"book-1000","XBT/CHF"]
1618678158.1782348: [1920,{"a":[["0.043110","0.00000000","1618678158.149458"]],"c":"3548702027"},"book-1000","SC/EUR"]
1618678158.180091: [1920,{"a":[["0.043580","0.00000000","1618678158.150550"]],"c":"3548702027"},"book-1000","SC/EUR"]
1618678158.1820512: [992,{"a":[["354.80000000","4.57411888","1618678158.151196"]],"c":"801516631"},"book-1000","XMR/USD"]
1618678158.185189: [992,{"b":[["351.22000000","186.71631741","1618678158.156292"]],"c":"801516631"},"book-1000","XMR/USD"]
1618678158.186742: [992,{"b":[["352.94000000","76.26368505","1618678158.158654"]],"c":"90857573"},"book-1000","XMR/USD"]
1618678158.1882932: [992,{"b":[["353.15000000","0.00000000","1618678158.159541"]],"c":"3089354055"},"book-1000","XMR/USD"]
1618678158.195167: [992,{"b":[["353.30000000","0.00000000","1618678158.168590"]],"c":"3981131240"},"book-1000","XMR/USD"]
1618678158.1975691: [992,{"b":[["352.66000000","0.00000000","1618678158.168702"]],"c":"3981131240"},"book-1000","XMR/USD"]
1618678158.204896: [1920,{"b":[["0.042880","20000.00000000","1618678158.177340"]],"c":"4117658648"},"book-1000","SC/EUR"]
1618678158.208695: [1920,{"b":[["0.042960","0.00000000","1618678158.177754"]],"c":"2645197893"},"book-1000","SC/EUR"]
1618678158.211363: [496,{"b":[["2183.36000","1.51278503","1618678158.179942"]],"c":"944032370"},"book-1000","ETH/CHF"]
1618678158.2121038: [992,{"b":[["353.31000000","12.57500000","1618678158.180222"]],"c":"2331184513"},"book-1000","XMR/USD"]
1618678158.2139132: [1664,{"a":[["13.266800","119.15886375","1618678158.186272"]],"c":"2285262876"},"book-1000","WAVES/EUR"]
1618678158.219141: [1664,{"a":[["13.276000","0.00000000","1618678158.189392"]],"c":"2285262876"},"book-1000","WAVES/EUR"]
1618678158.222369: [1920,{"a":[["0.043130","1081735.60000000","1618678158.193889"]],"c":"4236600138"},"book-1000","SC/EUR"]
1618678158.2255402: [1360,{"b":[["0.000022860","25050.84831878","1618678158.194004"]],"c":"1304674767"},"book-1000","ADA/XBT"]
1618678158.233247: [1840,{"b":[["9.486856","0.00000000","1618678158.203793"]],"c":"2943940055"},"book-1000","OMG/USD"]
1618678158.2348218: [992,{"b":[["351.28000000","0.00000000","1618678158.203926"]],"c":"2331184513"},"book-1000","XMR/USD"]
1618678158.2385569: [1920,{"b":[["0.042900","30638.40359093","1618678158.211311"]],"c":"2611557580"},"book-1000","SC/EUR"]
1618678158.246003: [3648,{"b":[["0.00755700","2.27486858","1618678158.218374"]],"c":"3931855063"},"book-1000","KSM/XBT"]
1618678158.252955: [1920,{"a":[["0.043120","0.00000000","1618678158.224038"]],"c":"562795626"},"book-1000","SC/EUR"]
1618678158.2649758: [1920,{"b":[["0.043030","75000.00000000","1618678158.226704"]],"c":"3440144734"},"book-1000","SC/EUR"]
1618678158.2687402: [496,{"b":[["2183.34000","0.00000000","1618678158.230567"]],"c":"927710383"},"book-1000","ETH/CHF"]
1618678158.269632: [464,{"a":[["56192.60000","0.15000000","1618678158.232265"]],"c":"1851433655"},"book-1000","XBT/CHF"]
1618678158.27121: [464,{"a":[["56169.80000","0.00000000","1618678158.232434"]],"c":"3992104080"},"book-1000","XBT/CHF"]
1618678158.272626: [992,{"b":[["353.17000000","27.07599614","1618678158.234424"]],"c":"3100902210"},"book-1000","XMR/USD"]
1618678158.2743301: [1920,{"b":[["0.042860","0.00000000","1618678158.234608"]],"c":"260296488"},"book-1000","SC/EUR"]
1618678158.276694: [3648,{"b":[["0.00755200","37.97000000","1618678158.238934"]],"c":"463344129"},"book-1000","KSM/XBT"]
1618678158.277453: [1920,{"a":[["0.043490","45615.00000000","1618678158.239099"]],"c":"3347432015"},"book-1000","SC/EUR"]
1618678158.2795892: [1360,{"a":[["0.000022930","3479.13590000","1618678158.239533"]],"c":"1984769564"},"book-1000","ADA/XBT"]
1618678158.281929: [992,{"b":[["351.89000000","52.00000000","1618678158.243919"]],"c":"3100902210"},"book-1000","XMR/USD"]
1618678158.283427: [5104,{"b":[["0.000027650","1237.68989905","1618678158.247349"]],"c":"2929070315"},"book-1000","OCEAN/XBT"]
1618678158.284223: [992,{"b":[["353.32000000","6.86967377","1618678158.248761"]],"c":"3776870094"},"book-1000","XMR/USD"]
1618678158.285652: [496,{"b":[["2183.35000","3.79260000","1618678158.251092"]],"c":"1665791427"},"book-1000","ETH/CHF"]
1618678158.2911968: [496,{"b":[["2183.37000","3.00000000","1618678158.261306"]],"c":"1624657868"},"book-1000","ETH/CHF"]
1618678158.292165: [1360,{"b":[["0.000022880","15870.82604609","1618678158.263270"]],"c":"663722253"},"book-1000","ADA/XBT"]
1618678158.29493: [1920,{"b":[["0.043020","0.00000000","1618678158.263620"]],"c":"3625901431"},"book-1000","SC/EUR"]
1618678158.298364: [1920,{"b":[["0.042820","20182.89187450","1618678158.270907"]],"c":"3047629086"},"book-1000","SC/EUR"]
1618678158.3005161: [1920,{"a":[["0.043130","1042665.60000000","1618678158.271986"]],"c":"3358844823"},"book-1000","SC/EUR"]
1618678158.302665: [1664,{"b":[["13.206800","0.00000000","1618678158.274585"]],"c":"2747482174"},"book-1000","WAVES/EUR"]
1618678158.303602: [1920,{"b":[["0.042960","33340.00000000","1618678158.275910"]],"c":"903631476"},"book-1000","SC/EUR"]
1618678158.306924: [464,{"a":[["56221.10000","0.00842000","1618678158.279898"]],"c":"2829934258"},"book-1000","XBT/CHF"]
1618678158.309827: [992,{"a":[["354.31000000","0.00000000","1618678158.282121"]],"c":"1026058489"},"book-1000","XMR/USD"]
1618678158.312347: [496,{"a":[["2190.17000","0.31000000","1618678158.284033"]],"c":"1692165279"},"book-1000","ETH/CHF"]
1618678158.312961: [5104,{"b":[["0.000027720","666.72387000","1618678158.284116"]],"c":"2843787704"},"book-1000","OCEAN/XBT"]
1618678158.313549: [1920,{"a":[["0.043110","905325.33415860","1618678158.284779"]],"c":"2850494089"},"book-1000","SC/EUR"]
1618678158.315556: [1840,{"a":[["9.618615","0.00000000","1618678158.287988"]],"c":"2943940055"},"book-1000","OMG/USD"]
1618678158.3163111: [5104,{"a":[["0.000027820","1046.48131937","1618678158.288134"]],"c":"625895892"},"book-1000","OCEAN/XBT"]
1618678158.316861: [496,{"b":[["2183.35000","3.92900000","1618678158.288476"]],"c":"1958154092"},"book-1000","ETH/CHF"]
1618678158.321079: [3648,{"b":[["0.00755200","39.06058000","1618678158.290415"]],"c":"1540062422"},"book-1000","KSM/XBT"]
1618678158.321782: [464,{"a":[["56169.70000","0.15000000","1618678158.292434"]],"c":"2469206244"},"book-1000","XBT/CHF"]
1618678158.326831: [1664,{"a":[["13.263300","500.00000000","1618678158.295301"]],"c":"2140522718"},"book-1000","WAVES/EUR"]
1618678158.327981: [496,{"a":[["2192.02000","2.04483249","1618678158.296116"]],"c":"2308725537"},"book-1000","ETH/CHF"]
1618678158.328703: [496,{"a":[["2192.02000","0.88504984","1618678158.296831"]],"c":"2090505325"},"book-1000","ETH/CHF"]
1618678158.329382: [1840,{"b":[["9.572438","196.00000000","1618678158.298169"]],"c":"1212597359"},"book-1000","OMG/USD"]
1618678158.3303502: {"event":"heartbeat"}
1618678158.3335419: [3648,{"b":[["0.00755200","1.09058000","1618678158.306861"]],"c":"1040682006"},"book-1000","KSM/XBT"]
1618678158.334343: [992,{"a":[["354.12000000","0.00000000","1618678158.307429"]],"c":"68488644"},"book-1000","XMR/USD"]
1618678158.338015: [992,{"a":[["354.28000000","7.57500000","1618678158.309407"]],"c":"3867322490"},"book-1000","XMR/USD"]
1618678158.339777: [3648,{"b":[["0.00755800","0.70100000","1618678158.309794"]],"c":"88556996"},"book-1000","KSM/XBT"]
1618678158.341562: [1920,{"b":[["0.042870","0.00000000","1618678158.312727"]],"c":"2581920588"},"book-1000","SC/EUR"]
1618678158.3437529: [3648,{"b":[["0.00754500","37.83000000","1618678158.316459"]],"c":"318287828"},"book-1000","KSM/XBT"]
1618678158.3445399: [3648,{"a":[["0.00757600","37.52000000","1618678158.317218"]],"c":"506160607"},"book-1000","KSM/XBT"]
1618678158.34515: [1920,{"b":[["0.042980","45500.00000000","1618678158.318133"]],"c":"137628387"},"book-1000","SC/EUR"]
1618678158.346976: [992,{"b":[["353.32000000","29.59467377","1618678158.318242"]],"c":"1716148646"},"book-1000","XMR/USD"]
1618678158.348556: [3648,{"a":[["0.00758300","2.27487212","1618678158.319402"]],"c":"3957481336"},"book-1000","KSM/XBT"]
1618678158.3492868: [1840,{"a":[["9.593356","0.00000000","1618678158.322771"]],"c":"3246470021"},"book-1000","OMG/USD"]
1618678158.359244: [1920,{"a":[["0.044220","0.00000000","1618678158.331687"]],"c":"137628387"},"book-1000","SC/EUR"]
1618678158.363039: [992,{"b":[["351.29000000","0.00000000","1618678158.334942"]],"c":"1716148646"},"book-1000","XMR/USD"]
1618678158.3651252: [992,{"b":[["351.77000000","12.36000000","1618678158.335738"]],"c":"1716148646"},"book-1000","XMR/USD"]
1618678158.366914: [1360,{"a":[["0.000022960","32323.58979644","1618678158.336394"]],"c":"3694834056"},"book-1000","ADA/XBT"]
1618678158.369395: [992,{"b":[["353.33000000","5.00000000","1618678158.336563"]],"c":"1593917629"},"book-1000","XMR/USD"]
1618678158.371218: [496,{"a":[["2192.02000","1.54742612","1618678158.343148"]],"c":"1425456843"},"book-1000","ETH/CHF"]
1618678158.371957: [496,{"a":[["2192.02000","0.66237628","1618678158.343200"]],"c":"3636171642"},"book-1000","ETH/CHF"]
1618678158.4017081: [1920,{"b":[["0.043030","0.00000000","1618678158.368670"]],"c":"2926629338"},"book-1000","SC/EUR"]
1618678158.4051929: [1840,{"b":[["9.555242","0.00000000","1618678158.368823"]],"c":"3246470021"},"book-1000","OMG/USD"]
1618678158.406232: [3648,{"b":[["0.00753300","0.00000000","1618678158.370728"]],"c":"3957481336"},"book-1000","KSM/XBT"]
1618678158.407115: [3648,{"b":[["0.00754000","5.65928624","1618678158.371558"]],"c":"3802874807"},"book-1000","KSM/XBT"]
1618678158.408234: [496,{"b":[["2183.35000","0.92900000","1618678158.372262"]],"c":"930459950"},"book-1000","ETH/CHF"]
1618678158.409013: [1920,{"a":[["0.044330","328633.84261483","1618678158.373814"]],"c":"2926629338"},"book-1000","SC/EUR"]
1618678158.411413: [1664,{"a":[["13.264800","0.00000000","1618678158.381786"]],"c":"4083814685"},"book-1000","WAVES/EUR"]
1618678158.412682: [496,{"b":[["2183.36000","0.00000000","1618678158.384611"]],"c":"2344559727"},"book-1000","ETH/CHF"]
1618678158.413409: [1920,{"a":[["0.043110","0.00000000","1618678158.385054"]],"c":"843814183"},"book-1000","SC/EUR"]
1618678158.415807: [1360,{"a":[["0.000023000","227.37491877","1618678158.385754"]],"c":"3694834056"},"book-1000","ADA/XBT"]
1618678158.4229069: [496,{"b":[["2183.38000","1.51277116","1618678158.394944"]],"c":"4073583489"},"book-1000","ETH/CHF"]
1618678158.429846: [1360,{"a":[["0.000023010","17183.11058402","1618678158.403550"]],"c":"3694834056"},"book-1000","ADA/XBT"]
1618678158.433554: [992,{"b":[["353.31000000","7.57500000","1618678158.405672"]],"c":"986219049"},"book-1000","XMR/USD"]
1618678158.435789: [1920,{"b":[["0.042530","0.00000000","1618678158.407849"]],"c":"843814183"},"book-1000","SC/EUR"]
1618678158.443487: [464,{"a":[["56221.10000","0.00000000","1618678158.411365"]],"c":"1645619435"},"book-1000","XBT/CHF"]
1618678158.445594: [464,{"b":[["56059.90000","0.13343839","1618678158.413670"]],"c":"3949223212"},"book-1000","XBT/CHF"]
1618678158.447412: [1664,{"b":[["13.220300","158.50594760","1618678158.418352"]],"c":"879662201"},"book-1000","WAVES/EUR"]
1618678158.454547: [1920,{"a":[["0.043100","905325.33415860","1618678158.427740"]],"c":"4041604538"},"book-1000","SC/EUR"]
1618678158.465198: [1920,{"a":[["0.043170","0.00000000","1618678158.438556"]],"c":"3044678541"},"book-1000","SC/EUR"]
1618678158.468849: [1360,{"a":[["0.000022920","10658.53746623","1618678158.440931"]],"c":"813227963"},"book-1000","ADA/XBT"]
1618678158.471785: [992,{"a":[["354.38000000","0.00000000","1618678158.441627"]],"c":"2066506457"},"book-1000","XMR/USD"]
1618678158.485722: [992,{"b":[["353.34000000","22.72500000","1618678158.457081"]],"c":"3520868338"},"book-1000","XMR/USD"]
1618678158.488541: [992,{"b":[["353.32000000","6.86967377","1618678158.457488"]],"c":"2588092478"},"book-1000","XMR/USD"]
1618678158.490598: [1920,{"b":[["0.043000","18840.36634284","1618678158.457571"]],"c":"4036634643"},"book-1000","SC/EUR"]
1618678158.49333: [464,{"a":[["56169.70000","0.00000000","1618678158.459543"]],"c":"1686165847"},"book-1000","XBT/CHF"]
1618678158.4946759: [3648,{"b":[["0.00755300","4.55039188","1618678158.461167"]],"c":"877125732"},"book-1000","KSM/XBT"]
1618678158.495407: [992,{"a":[["354.07000000","0.00000000","1618678158.462157"]],"c":"202057841"},"book-1000","XMR/USD"]
1618678158.497101: [1664,{"b":[["13.193400","0.00000000","1618678158.464566"]],"c":"879662201"},"book-1000","WAVES/EUR"]
1618678158.499289: [1920,{"a":[["0.043100","0.00000000","1618678158.469940"]],"c":"1378310059"},"book-1000","SC/EUR"]
1618678158.5105422: [1840,{"b":[["9.562040","0.00000000","1618678158.481324"]],"c":"3246470021"},"book-1000","OMG/USD"]
1618678158.5185978: [1664,{"a":[["13.256700","100.00000000","1618678158.487194"]],"c":"44438294"},"book-1000","WAVES/EUR"]
1618678158.5205262: [1360,{"a":[["0.000022900","9205.08987894","1618678158.487869"]],"c":"1637598414"},"book-1000","ADA/XBT"]
1618678158.523751: [1840,{"b":[["9.576516","68.34201222","1618678158.488113"]],"c":"225001761"},"book-1000","OMG/USD"]
1618678158.528533: [1664,{"b":[["13.186100","99.67978312","1618678158.499155"]],"c":"44438294"},"book-1000","WAVES/EUR"]
1618678158.530085: [1664,{"b":[["13.193500","0.00000000","1618678158.499205"]],"c":"44438294"},"book-1000","WAVES/EUR"]
1618678158.531546: [1840,{"a":[["9.593970","0.00000000","1618678158.503701"]],"c":"2563114033"},"book-1000","OMG/USD"]
1618678158.534858: [464,{"b":[["56024.00000","0.00000000","1618678158.506382"]],"c":"2872746898"},"book-1000","XBT/CHF"]
1618678158.537884: [1920,{"a":[["0.043210","905325.33415860","1618678158.512096"]],"c":"3298192934"},"book-1000","SC/EUR"]
1618678158.542666: [3648,{"b":[["0.00755200","0.00000000","1618678158.515468"]],"c":"2326616327"},"book-1000","KSM/XBT"]
1618678158.543412: [1920,{"b":[["0.042890","0.00000000","1618678158.515663"]],"c":"2103847349"},"book-1000","SC/EUR"]
1618678158.5457761: [1920,{"b":[["0.043000","57620.36634284","1618678158.518902"]],"c":"2505157789"},"book-1000","SC/EUR"]
1618678158.5480692: [1920,{"a":[["0.043190","138318.00000000","1618678158.520494"]],"c":"2415031863"},"book-1000","SC/EUR"]
1618678158.552203: [992,{"a":[["356.26000000","0.00000000","1618678158.523922"]],"c":"202057841"},"book-1000","XMR/USD"]
1618678158.553966: [5104,{"b":[["0.000027630","17535.30644725","1618678158.524829"]],"c":"3923766425"},"book-1000","OCEAN/XBT"]
1618678158.554612: [5104,{"a":[["0.000027860","17273.75095573","1618678158.525794"]],"c":"2296213364"},"book-1000","OCEAN/XBT"]
1618678158.555326: [464,{"b":[["55789.00000","0.42365238","1618678158.527521"]],"c":"296302617"},"book-1000","XBT/CHF"]
1618678158.562259: [1664,{"b":[["13.201200","348.19874091","1618678158.533486"]],"c":"2785479563"},"book-1000","WAVES/EUR"]
1618678158.5639732: [992,{"b":[["351.45000000","0.00000000","1618678158.534759"]],"c":"202057841"},"book-1000","XMR/USD"]
1618678158.566263: [1840,{"b":[["9.562273","0.00000000","1618678158.537718"]],"c":"2563114033"},"book-1000","OMG/USD"]
1618678158.567348: [1664,{"a":[["13.256700","600.00000000","1618678158.538057"]],"c":"71186980"},"book-1000","WAVES/EUR"]
1618678158.568552: [1840,{"b":[["9.574170","200.00000000","1618678158.541321"]],"c":"3666594522"},"book-1000","OMG/USD"]
1618678158.5693781: [464,{"b":[["56023.90000","0.05895616","1618678158.541544"]],"c":"3927707753"},"book-1000","XBT/CHF"]
1618678158.570653: [1840,{"a":[["9.588513","200.00000000","1618678158.541701"]],"c":"2596858771"},"book-1000","OMG/USD"]
1618678158.571767: [464,{"b":[["56024.10000","0.00000000","1618678158.543170"]],"c":"2539946684"},"book-1000","XBT/CHF"]
1618678158.574369: [5104,{"a":[["0.000027870","0.00000000","1618678158.545122"]],"c":"604328981"},"book-1000","OCEAN/XBT"]
1618678158.575299: [5104,{"a":[["0.000027880","773.41707806","1618678158.546364"]],"c":"1377837311"},"book-1000","OCEAN/XBT"]
1618678158.576056: [992,{"b":[["350.90000000","0.00000000","1618678158.547795"]],"c":"202057841"},"book-1000","XMR/USD"]
1618678158.5784361: [1840,{"b":[["9.545952","0.00000000","1618678158.550558"]],"c":"2596858771"},"book-1000","OMG/USD"]
1618678158.615034: [1920,{"a":[["0.043190","0.00000000","1618678158.586142"]],"c":"2505157789"},"book-1000","SC/EUR"]
1618678158.61883: [992,{"a":[["355.18000000","0.00000000","1618678158.589640"]],"c":"202057841"},"book-1000","XMR/USD"]
1618678158.620932: [992,{"a":[["354.81000000","0.00000000","1618678158.589759"]],"c":"723123934"},"book-1000","XMR/USD"]
1618678158.6265311: [992,{"a":[["356.74000000","52.00000000","1618678158.599913"]],"c":"723123934"},"book-1000","XMR/USD"]
1618678158.629154: [992,{"b":[["352.92000000","0.00000000","1618678158.601644"]],"c":"723123934"},"book-1000","XMR/USD"]
1618678158.635406: [992,{"a":[["354.28000000","0.00000000","1618678158.607746"]],"c":"1631257093"},"book-1000","XMR/USD"]
1618678158.638527: [1360,{"a":[["0.000022910","3798.93515460","1618678158.609751"]],"c":"3167432407"},"book-1000","ADA/XBT"]
1618678158.6416872: [1840,{"a":[["9.588514","0.00000000","1618678158.611660"]],"c":"3457255545"},"book-1000","OMG/USD"]
1618678158.643724: [5104,{"b":[["0.000027650","1278.86158051","1618678158.616339"]],"c":"84795708"},"book-1000","OCEAN/XBT"]
1618678158.652422: [992,{"a":[["354.80000000","0.00000000","1618678158.624643"]],"c":"952057521"},"book-1000","XMR/USD"]
1618678158.655256: [1840,{"b":[["9.545951","0.00000000","1618678158.624690"]],"c":"3457255545"},"book-1000","OMG/USD"]
1618678158.656533: [1840,{"b":[["9.562321","81.38027753","1618678158.625491"]],"c":"3457255545"},"book-1000","OMG/USD"]
1618678158.6575592: [992,{"a":[["354.94000000","4.57411888","1618678158.627833"]],"c":"577309412"},"book-1000","XMR/USD"]
1618678158.659629: [1920,{"b":[["0.042650","853333.00000000","1618678158.631784"]],"c":"2505157789"},"book-1000","SC/EUR"]
1618678158.6681468: [992,{"b":[["353.17000000","4.35099614","1618678158.639955"]],"c":"387109784"},"book-1000","XMR/USD"]
1618678158.670987: [992,{"b":[["353.35000000","5.00000000","1618678158.640986"]],"c":"1987656170"},"book-1000","XMR/USD"]
1618678158.673215: [992,{"b":[["351.75000000","0.00000000","1618678158.644748"]],"c":"1987656170"},"book-1000","XMR/USD"]
1618678158.681856: [1920,{"b":[["0.043000","38780.00000000","1618678158.653961"]],"c":"898657156"},"book-1000","SC/EUR"]
1618678158.685663: [1840,{"a":[["9.588512","137.04871748","1618678158.654975"]],"c":"2898609488"},"book-1000","OMG/USD"]
1618678158.6869388: [1840,{"b":[["9.506564","312.27089521","1618678158.655296"]],"c":"2898609488"},"book-1000","OMG/USD"]
1618678158.687961: [464,{"a":[["56192.90000","0.00000000","1618678158.657335"]],"c":"789017897"},"book-1000","XBT/CHF"]
1618678158.692725: [1840,{"a":[["9.588513","0.00000000","1618678158.664427"]],"c":"1175544685"},"book-1000","OMG/USD"]
1618678158.694775: [1920,{"b":[["0.042780","765148.70000000","1618678158.666792"]],"c":"4096482421"},"book-1000","SC/EUR"]
1618678158.697959: [1840,{"a":[["9.608231","0.00000000","1618678158.670565"]],"c":"3837901832"},"book-1000","OMG/USD"]
1618678158.707638: [992,{"a":[["358.34000000","0.00000000","1618678158.680922"]],"c":"1987656170"},"book-1000","XMR/USD"]
1618678158.712873: [1920,{"b":[["0.042710","0.00000000","1618678158.684886"]],"c":"4096482421"},"book-1000","SC/EUR"]
1618678158.7170408: [1840,{"b":[["9.469371","0.00000000","1618678158.689116"]],"c":"3837901832"},"book-1000","OMG/USD"]
1618678158.718362: [496,{"a":[["2212.19000","0.00000000","1618678158.691003"]],"c":"4073583489"},"book-1000","ETH/CHF"]
1618678158.7205918: [3648,{"b":[["0.00754500","0.00000000","1618678158.693148"]],"c":"383986682"},"book-1000","KSM/XBT"]
1618678158.721555: [3648,{"a":[["0.00756600","2.18142427","1618678158.693514"]],"c":"2765626076"},"book-1000","KSM/XBT"]
1618678158.727026: [3648,{"a":[["0.00757600","0.00000000","1618678158.699487"]],"c":"3758598482"},"book-1000","KSM/XBT"]
1618678158.738115: [1920,{"b":[["0.042720","0.00000000","1618678158.710897"]],"c":"4096482421"},"book-1000","SC/EUR"]
1618678158.7416341: [992,{"b":[["353.33000000","0.00000000","1618678158.711777"]],"c":"2779568448"},"book-1000","XMR/USD"]
1618678158.743912: [1840,{"b":[["9.545949","0.00000000","1618678158.716446"]],"c":"3837901832"},"book-1000","OMG/USD"]
1618678158.745111: [1664,{"a":[["13.263300","0.00000000","1618678158.717718"]],"c":"398651019"},"book-1000","WAVES/EUR"]
1618678158.74669: [5104,{"a":[["0.000027820","593.84154000","1618678158.718618"]],"c":"3709281943"},"book-1000","OCEAN/XBT"]
1618678158.74756: [5104,{"b":[["0.000027730","262.53724711","1618678158.719019"]],"c":"3572981208"},"book-1000","OCEAN/XBT"]
1618678158.7554328: [1840,{"a":[["9.595323","0.00000000","1618678158.728123"]],"c":"764319998"},"book-1000","OMG/USD"]
1618678158.758498: [496,{"a":[["2212.77000","14.29866649","1618678158.730492"]],"c":"4073583489"},"book-1000","ETH/CHF"]
1618678158.759701: [992,{"b":[["353.36000000","22.72500000","1618678158.732236"]],"c":"3972139939"},"book-1000","XMR/USD"]
1618678158.7636821: [1360,{"a":[["0.000022900","7015.08484526","1618678158.735511"]],"c":"3600448518"},"book-1000","ADA/XBT"]
1618678158.7669408: [1840,{"b":[["9.576516","139.64201222","1618678158.737481"]],"c":"3758359869"},"book-1000","OMG/USD"]
1618678158.773584: [464,{"b":[["55680.10000","0.00000000","1618678158.745876"]],"c":"789017897"},"book-1000","XBT/CHF"]
1618678158.7787142: [496,{"b":[["2183.39000","3.00000000","1618678158.751065"]],"c":"53654242"},"book-1000","ETH/CHF"]
1618678158.779903: [496,{"b":[["2183.37000","0.00000000","1618678158.751248"]],"c":"1834714481"},"book-1000","ETH/CHF"]
1618678158.781009: [1840,{"a":[["9.623280","67.20000000","1618678158.754186"]],"c":"4185461359"},"book-1000","OMG/USD"]
1618678158.790323: [1920,{"b":[["0.042790","577288.45906328","1618678158.760041"]],"c":"3911629413"},"book-1000","SC/EUR"]
1618678158.7938151: [992,{"b":[["353.32000000","9.36567377","1618678158.760744"]],"c":"4079306989"},"book-1000","XMR/USD"]
1618678158.795873: [496,{"b":[["2180.15000","0.00000000","1618678158.761413"]],"c":"1451527340"},"book-1000","ETH/CHF"]
1618678158.796771: [5104,{"b":[["0.000027720","654.72387000","1618678158.762627"]],"c":"3583083703"},"book-1000","OCEAN/XBT"]
1618678158.802691: [1664,{"b":[["13.175700","0.00000000","1618678158.772497"]],"c":"398651019"},"book-1000","WAVES/EUR"]
1618678158.8046038: [1360,{"a":[["0.000022910","5987.93108588","1618678158.773360"]],"c":"2080641885"},"book-1000","ADA/XBT"]
1618678158.808034: [1840,{"b":[["9.519365","360.00000000","1618678158.776231"]],"c":"4185461359"},"book-1000","OMG/USD"]
1618678158.809098: [1920,{"a":[["0.043080","0.00000000","1618678158.778423"]],"c":"433261529"},"book-1000","SC/EUR"]
1618678158.815091: [1920,{"b":[["0.042540","0.00000000","1618678158.787707"]],"c":"433261529"},"book-1000","SC/EUR"]
1618678158.8200462: [496,{"b":[["2183.38000","0.00000000","1618678158.791657"]],"c":"619885739"},"book-1000","ETH/CHF"]
1618678158.8211992: [496,{"b":[["2183.40000","1.51275731","1618678158.791993"]],"c":"312086928"},"book-1000","ETH/CHF"]
1618678158.8291562: [5104,{"b":[["0.000027730","274.53724711","1618678158.797384"]],"c":"3958503784"},"book-1000","OCEAN/XBT"]
1618678158.830268: [1360,{"a":[["0.000022930","3981.76882972","1618678158.798187"]],"c":"2858900325"},"book-1000","ADA/XBT"]
1618678158.83362: [5104,{"b":[["0.000027710","0.00000000","1618678158.804816"]],"c":"1637128738"},"book-1000","OCEAN/XBT"]
1618678158.834435: [5104,{"b":[["0.000027700","663.12278043","1618678158.804887"]],"c":"128509993"},"book-1000","OCEAN/XBT"]
1618678158.8369: [992,{"b":[["350.10000000","170.01692100","1618678158.809240"]],"c":"4079306989"},"book-1000","XMR/USD"]
1618678158.839148: [992,{"b":[["353.34000000","0.00000000","1618678158.812880"]],"c":"38419073"},"book-1000","XMR/USD"]
1618678158.8410408: [992,{"b":[["353.37000000","5.00000000","1618678158.814371"]],"c":"2753688501"},"book-1000","XMR/USD"]
1618678158.8483698: [1920,{"a":[["0.043210","0.00000000","1618678158.820536"]],"c":"671752930"},"book-1000","SC/EUR"]
1618678158.853309: [1920,{"a":[["0.043140","42461.83886926","1618678158.824692"]],"c":"1853343658"},"book-1000","SC/EUR"]
1618678158.861102: [3648,{"b":[["0.00755700","0.00000000","1618678158.829014"]],"c":"1847735606"},"book-1000","KSM/XBT"]
1618678158.862306: [992,{"a":[["354.18000000","0.00000000","1618678158.829712"]],"c":"3821949760"},"book-1000","XMR/USD"]
1618678158.8646579: [1920,{"a":[["0.043130","0.00000000","1618678158.833323"]],"c":"2685354472"},"book-1000","SC/EUR"]
1618678158.867198: [1920,{"a":[["0.043200","1028655.80000000","1618678158.836795"]],"c":"2036475322"},"book-1000","SC/EUR"]
1618678158.86939: [1920,{"b":[["0.042660","458679.35642020","1618678158.838630"]],"c":"2036475322"},"book-1000","SC/EUR"]
1618678158.8732202: [5104,{"b":[["0.000027610","0.00000000","1618678158.845656"]],"c":"2572730124"},"book-1000","OCEAN/XBT"]
1618678158.884811: [5104,{"b":[["0.000027740","594.11897000","1618678158.856058"]],"c":"294834640"},"book-1000","OCEAN/XBT"]
1618678158.886102: [5104,{"b":[["0.000027730","868.65621711","1618678158.856270"]],"c":"147570835"},"book-1000","OCEAN/XBT"]
1618678158.888005: [1920,{"a":[["0.043200","1933981.13415860","1618678158.861431"]],"c":"3804353075"},"book-1000","SC/EUR"]
1618678158.89616: [992,{"b":[["353.35000000","0.00000000","1618678158.867557"]],"c":"3677575889"},"book-1000","XMR/USD"]
1618678158.9071229: [1664,{"b":[["13.201100","0.00000000","1618678158.877650"]],"c":"2217240154"},"book-1000","WAVES/EUR"]
1618678158.912502: [1840,{"b":[["9.562321","0.00000000","1618678158.884562"]],"c":"4185461359"},"book-1000","OMG/USD"]
1618678158.91424: [1840,{"b":[["9.562321","155.58027753","1618678158.887464"]],"c":"4185461359"},"book-1000","OMG/USD"]
1618678158.915489: [5104,{"a":[["0.000027860","16679.70947573","1618678158.887614"]],"c":"3927307566"},"book-1000","OCEAN/XBT"]
1618678158.9164858: [1840,{"a":[["9.608471","602.46450000","1618678158.888760"]],"c":"1891476621"},"book-1000","OMG/USD"]
1618678158.926788: [1840,{"b":[["9.561453","0.00000000","1618678158.898713"]],"c":"1891476621"},"book-1000","OMG/USD"]
1618678158.928501: [1920,{"a":[["0.043200","1028655.80000000","1618678158.900088"]],"c":"2036475322"},"book-1000","SC/EUR"]
1618678158.931799: [1840,{"a":[["9.599774","0.00000000","1618678158.902310"]],"c":"3289395139"},"book-1000","OMG/USD"]
1618678158.932987: [1840,{"a":[["9.607676","3925.38000000","1618678158.905150"]],"c":"3799100802"},"book-1000","OMG/USD"]
1618678158.940053: [1840,{"b":[["9.569323","4309.14000000","1618678158.912105"]],"c":"602013122"},"book-1000","OMG/USD"]
1618678158.9501529: [992,{"b":[["353.38000000","22.72500000","1618678158.922635"]],"c":"3473372586"},"book-1000","XMR/USD"]
1618678158.952991: [992,{"a":[["354.44000000","0.00000000","1618678158.922688"]],"c":"910033422"},"book-1000","XMR/USD"]
1618678158.955334: [1664,{"a":[["13.250100","101.00000000","1618678158.927318"]],"c":"1646774059"},"book-1000","WAVES/EUR"]
1618678158.9649851: [992,{"a":[["354.78000000","141.00460000","1618678158.937875"]],"c":"118505710"},"book-1000","XMR/USD"]
1618678158.967799: [1920,{"a":[["0.043190","905325.33415860","1618678158.938058"]],"c":"3372020759"},"book-1000","SC/EUR"]
1618678158.97072: [1840,{"a":[["9.618614","0.00000000","1618678158.940290"]],"c":"315800400"},"book-1000","OMG/USD"]
1618678158.97172: [1840,{"a":[["9.605795","88.92264512","1618678158.941707"]],"c":"3153754171"},"book-1000","OMG/USD"]
1618678158.978119: [1360,{"b":[["0.000022880","21870.82604609","1618678158.948927"]],"c":"1513359443"},"book-1000","ADA/XBT"]
1618678158.981915: [1664,{"b":[["13.186200","415.00000000","1618678158.949159"]],"c":"1646774059"},"book-1000","WAVES/EUR"]
1618678158.999579: [464,{"b":[["55789.10000","0.43688323","1618678158.970353"]],"c":"3329938153"},"book-1000","XBT/CHF"]
1618678159.00179: [1664,{"b":[["13.220200","0.00000000","1618678158.971738"]],"c":"4083892500"},"book-1000","WAVES/EUR"]
1618678159.003252: [992,{"a":[["354.77000000","4.57411888","1618678158.973112"]],"c":"3002990787"},"book-1000","XMR/USD"]
1618678159.0053031: [992,{"a":[["354.94000000","0.00000000","1618678158.973309"]],"c":"2062408634"},"book-1000","XMR/USD"]
1618678159.007314: [1840,{"a":[["9.588511","156.35900000","1618678158.977604"]],"c":"1705601586"},"book-1000","OMG/USD"]
1618678159.00899: [992,{"a":[["357.61000000","169.98549000","1618678158.981670"]],"c":"2062408634"},"book-1000","XMR/USD"]
1618678159.0366359: [1840,{"a":[["9.594823","0.00000000","1618678159.008939"]],"c":"2373178164"},"book-1000","OMG/USD"]
1618678159.044031: [464,{"b":[["56060.00000","0.04629160","1618678159.016752"]],"c":"2203918057"},"book-1000","XBT/CHF"]
1618678159.046377: [1664,{"b":[["13.220400","151.28135305","1618678159.018079"]],"c":"3782730710"},"book-1000","WAVES/EUR"]
1618678159.0482628: [992,{"b":[["353.39000000","7.57500000","1618678159.021422"]],"c":"332652288"},"book-1000","XMR/USD"]
1618678159.0538208: [1840,{"a":[["9.623280","0.00000000","1618678159.026429"]],"c":"4167202835"},"book-1000","OMG/USD"]
1618678159.066005: [5104,{"b":[["0.000027740","646.61897000","1618678159.038472"]],"c":"3557650557"},"book-1000","OCEAN/XBT"]
1618678159.067223: [3648,{"b":[["0.00750400","9.09746666","1618678159.038553"]],"c":"1847735606"},"book-1000","KSM/XBT"]
1618678159.0686269: [992,{"b":[["353.36000000","0.00000000","1618678159.040964"]],"c":"3594718171"},"book-1000","XMR/USD"]
1618678159.070745: [1840,{"a":[["9.629433","55.70000000","1618678159.042588"]],"c":"1780462719"},"book-1000","OMG/USD"]
1618678159.086251: [992,{"b":[["351.93000000","7.36249625","1618678159.057454"]],"c":"3594718171"},"book-1000","XMR/USD"]
1618678159.0893838: [3648,{"b":[["0.00755400","2.84385730","1618678159.062109"]],"c":"3645069691"},"book-1000","KSM/XBT"]
1618678159.094655: [1840,{"a":[["9.612701","521.48635000","1618678159.064484"]],"c":"9838403"},"book-1000","OMG/USD"]
1618678159.0960908: [1840,{"b":[["9.568473","521.65004400","1618678159.064630"]],"c":"2998415204"},"book-1000","OMG/USD"]
1618678159.097336: [992,{"a":[["354.77000000","8.27159864","1618678159.066726"]],"c":"745917963"},"book-1000","XMR/USD"]
1618678159.099635: [992,{"a":[["354.77000000","3.69747976","1618678159.069033"]],"c":"1387388041"},"book-1000","XMR/USD"]
1618678159.101557: [992,{"b":[["353.31000000","0.00000000","1618678159.070341"]],"c":"588051022"},"book-1000","XMR/USD"]
1618678159.103214: [1920,{"a":[["0.043220","0.00000000","1618678159.071398"]],"c":"3461851270"},"book-1000","SC/EUR"]
1618678159.105484: [1840,{"a":[["9.588512","0.00000000","1618678159.071948"]],"c":"1043014639"},"book-1000","OMG/USD"]
1618678159.106525: [1840,{"b":[["9.519366","6.78128277","1618678159.074727"]],"c":"1043014639"},"book-1000","OMG/USD"]
1618678159.107373: [992,{"b":[["353.38000000","0.00000000","1618678159.077222"]],"c":"2728687914"},"book-1000","XMR/USD"]
1618678159.1090329: [992,{"b":[["353.40000000","22.72500000","1618678159.077602"]],"c":"2116254651"},"book-1000","XMR/USD"]
1618678159.110846: [1360,{"b":[["0.000022880","27553.74710584","1618678159.081749"]],"c":"320155147"},"book-1000","ADA/XBT"]
1618678159.117321: [1840,{"b":[["9.480750","2.00000000","1618678159.089470"]],"c":"1043014639"},"book-1000","OMG/USD"]
1618678159.11829: [992,{"b":[["351.89000000","0.00000000","1618678159.089899"]],"c":"2116254651"},"book-1000","XMR/USD"]
1618678159.1201868: [1920,{"a":[["0.043130","10721.04662049","1618678159.091415"]],"c":"728471291"},"book-1000","SC/EUR"]
1618678159.122616: [1920,{"b":[["0.042930","30616.99432341","1618678159.094569"]],"c":"520815794"},"book-1000","SC/EUR"]
1618678159.129117: [1840,{"a":[["9.596671","137.01786152","1618678159.102276"]],"c":"837311986"},"book-1000","OMG/USD"]
1618678159.148603: [1920,{"a":[["0.043460","183452.67067430","1618678159.121302"]],"c":"2539482300"},"book-1000","SC/EUR"]
1618678159.1524029: [992,{"b":[["352.66000000","0.17106559","1618678159.123511"]],"c":"2116254651"},"book-1000","XMR/USD"]
1618678159.154486: [1920,{"b":[["0.042900","0.00000000","1618678159.123885"]],"c":"2622505646"},"book-1000","SC/EUR"]
1618678159.168352: [1840,{"b":[["9.576517","137.01260839","1618678159.142136"]],"c":"2438842990"},"book-1000","OMG/USD"]
1618678159.174863: [464,{"a":[["56734.20000","0.00000000","1618678159.147318"]],"c":"2203918057"},"book-1000","XBT/CHF"]
1618678159.179002: [992,{"a":[["354.77000000","0.00000000","1618678159.152488"]],"c":"2300972252"},"book-1000","XMR/USD"]
1618678159.181534: [1840,{"a":[["9.604803","88.93165221","1618678159.154096"]],"c":"2721360731"},"book-1000","OMG/USD"]
1618678159.1837912: [1840,{"a":[["9.605795","0.00000000","1618678159.155840"]],"c":"3783143056"},"book-1000","OMG/USD"]
1618678159.1859388: [992,{"a":[["354.77000000","3.69747525","1618678159.158398"]],"c":"1307146601"},"book-1000","XMR/USD"]
1618678159.192787: [1360,{"b":[["0.000022890","1086.69770000","1618678159.165705"]],"c":"3776298907"},"book-1000","ADA/XBT"]
1618678159.207555: [992,{"b":[["353.39000000","12.57500000","1618678159.179450"]],"c":"4060306649"},"book-1000","XMR/USD"]
1618678159.2130811: [1664,{"b":[["12.504300","0.00000000","1618678159.185291"]],"c":"3782730710"},"book-1000","WAVES/EUR"]
1618678159.218522: [1664,{"a":[["13.250000","500.00000000","1618678159.190939"]],"c":"3014750538"},"book-1000","WAVES/EUR"]
1618678159.231472: [1920,{"b":[["0.043010","5802.95592353","1618678159.203387"]],"c":"4213292058"},"book-1000","SC/EUR"]
1618678159.234993: [992,{"b":[["352.66000000","52.17106559","1618678159.203575"]],"c":"4060306649"},"book-1000","XMR/USD"]
1618678159.246349: [496,{"a":[["2192.02000","0.88222048","1618678159.218862"]],"c":"2922037448"},"book-1000","ETH/CHF"]
1618678159.248024: [496,{"a":[["2192.02000","0.21984420","1618678159.218997"]],"c":"1233545306"},"book-1000","ETH/CHF"]
1618678159.2491221: [1840,{"a":[["9.591427","157.68871600","1618678159.220592"]],"c":"568276283"},"book-1000","OMG/USD"]
1618678159.255348: [1840,{"b":[["9.572438","146.00000000","1618678159.228285"]],"c":"1423383365"},"book-1000","OMG/USD"]
1618678159.266916: [496,{"b":[["2183.41000","3.00000000","1618678159.239284"]],"c":"2937587676"},"book-1000","ETH/CHF"]
1618678159.2714071: [1664,{"b":[["12.596800","9.22721811","1618678159.244918"]],"c":"3014750538"},"book-1000","WAVES/EUR"]
1618678159.2801092: [5104,{"b":[["0.000027730","606.11897000","1618678159.252051"]],"c":"3108574696"},"book-1000","OCEAN/XBT"]
1618678159.2813702: [992,{"b":[["353.37000000","0.00000000","1618678159.252682"]],"c":"2066923881"},"book-1000","XMR/USD"]
1618678159.2837539: [5104,{"a":[["0.000027820","1046.48131937","1618678159.253519"]],"c":"1632883267"},"book-1000","OCEAN/XBT"]
1618678159.29652: [3648,{"b":[["0.00749600","0.00000000","1618678159.268090"]],"c":"3645069691"},"book-1000","KSM/XBT"]
1618678159.307275: [496,{"b":[["2183.42000","1.51274346","1618678159.276570"]],"c":"2970835028"},"book-1000","ETH/CHF"]
1618678159.308649: [496,{"b":[["2183.40000","0.00000000","1618678159.276734"]],"c":"2285512591"},"book-1000","ETH/CHF"]
1618678159.309712: [1840,{"b":[["9.575471","200.00000000","1618678159.277772"]],"c":"908459926"},"book-1000","OMG/USD"]
1618678159.310883: [992,{"b":[["351.56000000","0.00000000","1618678159.279022"]],"c":"2066923881"},"book-1000","XMR/USD"]
1618678159.322064: [992,{"b":[["353.39000000","7.57500000","1618678159.291885"]],"c":"2968295616"},"book-1000","XMR/USD"]
1618678159.324897: [992,{"b":[["353.41000000","5.00000000","1618678159.291980"]],"c":"3238597384"},"book-1000","XMR/USD"]
1618678159.327138: [3648,{"a":[["0.00758100","39.91000000","1618678159.297256"]],"c":"1820293037"},"book-1000","KSM/XBT"]
1618678159.328317: [3648,{"b":[["0.00754900","37.43000000","1618678159.299088"]],"c":"2817640104"},"book-1000","KSM/XBT"]
1618678159.330794: {"event":"heartbeat"}
1618678159.341166: [1664,{"a":[["13.256700","100.00000000","1618678159.304118"]],"c":"2303789431"},"book-1000","WAVES/EUR"]
1618678159.3430998: [1360,{"a":[["0.000022910","7078.64828588","1618678159.306152"]],"c":"4066803913"},"book-1000","ADA/XBT"]
1618678159.346331: [5104,{"a":[["0.000027880","732.36854110","1618678159.311343"]],"c":"2638438104"},"book-1000","OCEAN/XBT"]
1618678159.350719: [992,{"b":[["353.32000000","2.49600000","1618678159.323404"]],"c":"3363524450"},"book-1000","XMR/USD"]
1618678159.353853: [496,{"b":[["2183.43000","3.00000000","1618678159.324804"]],"c":"155189524"},"book-1000","ETH/CHF"]
1618678159.3547661: [496,{"b":[["2183.41000","0.00000000","1618678159.324860"]],"c":"95767427"},"book-1000","ETH/CHF"]
1618678159.355618: [992,{"b":[["353.17000000","0.00000000","1618678159.325214"]],"c":"180067619"},"book-1000","XMR/USD"]
1618678159.357561: [1840,{"b":[["9.575011","150.00000000","1618678159.326220"]],"c":"228450271"},"book-1000","OMG/USD"]
1618678159.358433: [992,{"b":[["352.67000000","4.35716477","1618678159.326775"]],"c":"180067619"},"book-1000","XMR/USD"]
1618678159.360225: [1840,{"b":[["9.565055","0.00000000","1618678159.330866"]],"c":"228450271"},"book-1000","OMG/USD"]
1618678159.36956: [1840,{"b":[["9.574170","0.00000000","1618678159.341864"]],"c":"2741655547"},"book-1000","OMG/USD"]
1618678159.3741949: [1360,{"b":[["0.000022830","23587.82089865","1618678159.345914"]],"c":"3991132478"},"book-1000","ADA/XBT"]
1618678159.377855: [1360,{"b":[["0.000022870","18230.58214387","1618678159.347679"]],"c":"1030271759"},"book-1000","ADA/XBT"]
1618678159.380846: [1360,{"b":[["0.000022880","21870.82604609","1618678159.353173"]],"c":"2164590416"},"book-1000","ADA/XBT"]
1618678159.3893461: [1840,{"b":[["9.576517","337.01260839","1618678159.362244"]],"c":"2114157279"},"book-1000","OMG/USD"]
1618678159.391215: [1920,{"b":[["0.043030","20514.81078729","1618678159.363082"]],"c":"1499241780"},"book-1000","SC/EUR"]
1618678159.394175: [992,{"b":[["353.42000000","6.86558781","1618678159.364176"]],"c":"210295960"},"book-1000","XMR/USD"]
1618678159.400266: [1840,{"a":[["9.588511","0.00000000","1618678159.373046"]],"c":"4257174243"},"book-1000","OMG/USD"]
1618678159.407209: [1360,{"a":[["0.000022900","2000.00000000","1618678159.378953"]],"c":"4275925931"},"book-1000","ADA/XBT"]
1618678159.4110022: [992,{"b":[["353.42000000","29.59058781","1618678159.379626"]],"c":"453598291"},"book-1000","XMR/USD"]
1618678159.413075: [496,{"b":[["2183.39000","0.00000000","1618678159.380046"]],"c":"645514199"},"book-1000","ETH/CHF"]
1618678159.41415: [992,{"a":[["356.70000000","0.14259640","1618678159.381794"]],"c":"453598291"},"book-1000","XMR/USD"]
1618678159.417875: [1840,{"a":[["9.604803","0.00000000","1618678159.390559"]],"c":"1086644696"},"book-1000","OMG/USD"]
1618678159.419211: [1840,{"a":[["9.604803","194.10704088","1618678159.391991"]],"c":"1601982899"},"book-1000","OMG/USD"]
1618678159.426722: [1360,{"b":[["0.000022890","0.00000000","1618678159.397485"]],"c":"3617333103"},"book-1000","ADA/XBT"]
1618678159.430717: [1840,{"a":[["9.591427","0.00000000","1618678159.400085"]],"c":"3986784689"},"book-1000","OMG/USD"]
1618678159.431998: [1360,{"a":[["0.000022910","5987.93108588","1618678159.400910"]],"c":"3304005693"},"book-1000","ADA/XBT"]
1618678159.434773: [992,{"a":[["354.06000000","0.00000000","1618678159.406495"]],"c":"452665561"},"book-1000","XMR/USD"]
