1619378338.806206: {"data":{"sequenceStart":1613277184889,"symbol":"BCHSV-USDT","changes":{"asks":[["243.262","0","1613277184889"]],"bids":[]},"sequenceEnd":1613277184889},"subject":"trade.l2update","topic":"/market/level2:BCHSV-USDT","type":"message"}
1619378338.8258119: {"data":{"sequenceStart":1613277184890,"symbol":"BCHSV-USDT","changes":{"asks":[["0","0","1613277184890"]],"bids":[]},"sequenceEnd":1613277184890},"subject":"trade.l2update","topic":"/market/level2:BCHSV-USDT","type":"message"}
1619378338.82589: {"data":{"sequenceStart":1613277184891,"symbol":"BCHSV-USDT","changes":{"asks":[["243.26","0.6","1613277184891"]],"bids":[]},"sequenceEnd":1613277184891},"subject":"trade.l2update","topic":"/market/level2:BCHSV-USDT","type":"message"}
1619378338.836568: {"data":{"sequenceStart":1612712745691,"symbol":"FET-BTC","changes":{"asks":[["0.00000785","147.7272","1612712745691"]],"bids":[]},"sequenceEnd":1612712745691},"subject":"trade.l2update","topic":"/market/level2:FET-BTC","type":"message"}
1619378338.8390348: {"data":{"sequenceStart":1612702190345,"symbol":"NRG-BTC","changes":{"asks":[["0","0","1612702190345"]],"bids":[]},"sequenceEnd":1612702190345},"subject":"trade.l2update","topic":"/market/level2:NRG-BTC","type":"message"}
1619378338.839144: {"data":{"sequenceStart":1612702190346,"symbol":"NRG-BTC","changes":{"asks":[["0.00006229","13.679","1612702190346"]],"bids":[]},"sequenceEnd":1612702190346},"subject":"trade.l2update","topic":"/market/level2:NRG-BTC","type":"message"}
1619378338.843694: {"data":{"sequenceStart":1612712745692,"symbol":"FET-BTC","changes":{"asks":[["0","0","1612712745692"]],"bids":[]},"sequenceEnd":1612712745692},"subject":"trade.l2update","topic":"/market/level2:FET-BTC","type":"message"}
1619378338.8438022: {"data":{"sequenceStart":1612712745693,"symbol":"FET-BTC","changes":{"asks":[["0.00000781","159.36","1612712745693"]],"bids":[]},"sequenceEnd":1612712745693},"subject":"trade.l2update","topic":"/market/level2:FET-BTC","type":"message"}
1619378338.847486: {"data":{"sequenceStart":1612694580177,"symbol":"CAPP-BTC","changes":{"asks":[["0","0","1612694580177"]],"bids":[]},"sequenceEnd":1612694580177},"subject":"trade.l2update","topic":"/market/level2:CAPP-BTC","type":"message"}
1619378338.847567: {"data":{"sequenceStart":1612694580178,"symbol":"CAPP-BTC","changes":{"asks":[["0.0000002196","330.25","1612694580178"]],"bids":[]},"sequenceEnd":1612694580178},"subject":"trade.l2update","topic":"/market/level2:CAPP-BTC","type":"message"}
1619378338.857439: {"data":{"sequenceStart":1612702190347,"symbol":"NRG-BTC","changes":{"asks":[["0.00006229","0","1612702190347"]],"bids":[]},"sequenceEnd":1612702190347},"subject":"trade.l2update","topic":"/market/level2:NRG-BTC","type":"message"}
1619378338.8575811: {"data":{"sequenceStart":1613277184892,"symbol":"BCHSV-USDT","changes":{"asks":[["243.879","0","1613277184892"]],"bids":[]},"sequenceEnd":1613277184892},"subject":"trade.l2update","topic":"/market/level2:BCHSV-USDT","type":"message"}
1619378338.857656: {"data":{"sequenceStart":1613277184893,"symbol":"BCHSV-USDT","changes":{"asks":[["244.517","0","1613277184893"]],"bids":[]},"sequenceEnd":1613277184893},"subject":"trade.l2update","topic":"/market/level2:BCHSV-USDT","type":"message"}
1619378338.857714: {"data":{"sequenceStart":1613277184894,"symbol":"BCHSV-USDT","changes":{"asks":[],"bids":[["241.717","0","1613277184894"]]},"sequenceEnd":1613277184894},"subject":"trade.l2update","topic":"/market/level2:BCHSV-USDT","type":"message"}
1619378338.871516: {"data":{"sequenceStart":1612712745694,"symbol":"FET-BTC","changes":{"asks":[["0.00000792","114.2511","1612712745694"]],"bids":[]},"sequenceEnd":1612712745694},"subject":"trade.l2update","topic":"/market/level2:FET-BTC","type":"message"}
1619378338.876657: {"data":{"sequence":"1613277184894","bestAsk":"243","size":"0.14324938","bestBidSize":"0.45082023","price":"242.781","time":1619378338833,"bestAskSize":"4.51280965","bestBid":"242.635"},"subject":"trade.ticker","topic":"/market/ticker:BCHSV-USDT","type":"message"}
1619378338.881377: {"data":{"sequenceStart":1612699351274,"symbol":"COV-BTC","changes":{"asks":[["0","0","1612699351274"]],"bids":[]},"sequenceEnd":1612699351274},"subject":"trade.l2update","topic":"/market/level2:COV-BTC","type":"message"}
1619378338.8814971: {"data":{"sequenceStart":1612699351275,"symbol":"COV-BTC","changes":{"asks":[["0.00001126","137.9035","1612699351275"]],"bids":[]},"sequenceEnd":1612699351275},"subject":"trade.l2update","topic":"/market/level2:COV-BTC","type":"message"}
1619378338.8918579: {"data":{"sequenceStart":1613277184895,"symbol":"BCHSV-USDT","changes":{"asks":[],"bids":[["241.603","0","1613277184895"]]},"sequenceEnd":1613277184895},"subject":"trade.l2update","topic":"/market/level2:BCHSV-USDT","type":"message"}
1619378338.903311: {"data":{"sequenceStart":1613277184896,"symbol":"BCHSV-USDT","changes":{"asks":[["0","0","1613277184896"]],"bids":[]},"sequenceEnd":1613277184896},"subject":"trade.l2update","topic":"/market/level2:BCHSV-USDT","type":"message"}
1619378338.9033952: {"data":{"sequenceStart":1613277184897,"symbol":"BCHSV-USDT","changes":{"asks":[["242.999","10.12458721","1613277184897"]],"bids":[]},"sequenceEnd":1613277184897},"subject":"trade.l2update","topic":"/market/level2:BCHSV-USDT","type":"message"}
1619378338.9034739: {"data":{"sequenceStart":1613277184898,"symbol":"BCHSV-USDT","changes":{"asks":[["243.26","0","1613277184898"]],"bids":[]},"sequenceEnd":1613277184898},"subject":"trade.l2update","topic":"/market/level2:BCHSV-USDT","type":"message"}
1619378338.908291: {"data":{"sequenceStart":1612699351276,"symbol":"COV-BTC","changes":{"asks":[["0.00001126","0","1612699351276"]],"bids":[]},"sequenceEnd":1612699351276},"subject":"trade.l2update","topic":"/market/level2:COV-BTC","type":"message"}
1619378338.908406: {"data":{"sequence":"1612712745694","bestAsk":"0.00000776","size":"401.2004","bestBidSize":"357.285","price":"0.00000772","time":1619378338868,"bestAskSize":"1154.0416","bestBid":"0.00000771"},"subject":"trade.ticker","topic":"/market/ticker:FET-BTC","type":"message"}
1619378338.9270852: {"data":{"sequence":"1612694580178","bestAsk":"0.0000002196","size":"1000.02","bestBidSize":"83.07","price":"0.0000002182","time":1619378338882,"bestAskSize":"330.25","bestBid":"0.0000002181"},"subject":"trade.ticker","topic":"/market/ticker:CAPP-BTC","type":"message"}
1619378338.9324448: {"data":{"sequence":"1612699351276","bestAsk":"0.00001127","size":"96.1525","bestBidSize":"49.6422","price":"0.00001126","time":1619378338888,"bestAskSize":"4331.68226035","bestBid":"0.00001121"},"subject":"trade.ticker","topic":"/market/ticker:COV-BTC","type":"message"}
1619378338.967434: {"data":{"sequence":"1612702190347","bestAsk":"0.00006218","size":"0.0431","bestBidSize":"19.5017","price":"0.00006141","time":1619378338891,"bestAskSize":"43.3399","bestBid":"0.00006141"},"subject":"trade.ticker","topic":"/market/ticker:NRG-BTC","type":"message"}
1619378338.976671: {"data":{"sequenceStart":1613277184899,"symbol":"BCHSV-USDT","changes":{"asks":[["0","0","1613277184899"]],"bids":[]},"sequenceEnd":1613277184899},"subject":"trade.l2update","topic":"/market/level2:BCHSV-USDT","type":"message"}
1619378338.976778: {"data":{"sequenceStart":1613277184900,"symbol":"BCHSV-USDT","changes":{"asks":[["243.057","2.99000033","1613277184900"]],"bids":[]},"sequenceEnd":1613277184900},"subject":"trade.l2update","topic":"/market/level2:BCHSV-USDT","type":"message"}
1619378338.9768589: {"data":{"sequenceStart":1613277184901,"symbol":"BCHSV-USDT","changes":{"asks":[["0","0","1613277184901"]],"bids":[]},"sequenceEnd":1613277184901},"subject":"trade.l2update","topic":"/market/level2:BCHSV-USDT","type":"message"}
1619378338.976903: {"data":{"sequenceStart":1613277184902,"symbol":"BCHSV-USDT","changes":{"asks":[["242.928","0.6","1613277184902"]],"bids":[]},"sequenceEnd":1613277184902},"subject":"trade.l2update","topic":"/market/level2:BCHSV-USDT","type":"message"}
1619378338.997387: {"data":{"sequenceStart":1613277184903,"symbol":"BCHSV-USDT","changes":{"asks":[],"bids":[["0","0","1613277184903"]]},"sequenceEnd":1613277184903},"subject":"trade.l2update","topic":"/market/level2:BCHSV-USDT","type":"message"}
1619378338.997498: {"data":{"sequenceStart":1613277184904,"symbol":"BCHSV-USDT","changes":{"asks":[],"bids":[["242.109","10.04358514","1613277184904"]]},"sequenceEnd":1613277184904},"subject":"trade.l2update","topic":"/market/level2:BCHSV-USDT","type":"message"}
1619378338.9975932: {"data":{"sequenceStart":1613277184905,"symbol":"BCHSV-USDT","changes":{"asks":[],"bids":[["0","0","1613277184905"]]},"sequenceEnd":1613277184905},"subject":"trade.l2update","topic":"/market/level2:BCHSV-USDT","type":"message"}
1619378338.997621: {"data":{"sequenceStart":1613277184906,"symbol":"BCHSV-USDT","changes":{"asks":[],"bids":[["239.54","25","1613277184906"]]},"sequenceEnd":1613277184906},"subject":"trade.l2update","topic":"/market/level2:BCHSV-USDT","type":"message"}
1619378338.997653: {"data":{"sequence":"1613277184903","bestAsk":"242.928","size":"0.14324938","bestBidSize":"0.45082023","price":"242.781","time":1619378338933,"bestAskSize":"0.6","bestBid":"242.635"},"subject":"trade.ticker","topic":"/market/ticker:BCHSV-USDT","type":"message"}
1619378338.997696: {"data":{"sequenceStart":1613277184907,"symbol":"BCHSV-USDT","changes":{"asks":[["243.057","0","1613277184907"]],"bids":[]},"sequenceEnd":1613277184907},"subject":"trade.l2update","topic":"/market/level2:BCHSV-USDT","type":"message"}
1619378338.9977422: {"data":{"sequenceStart":1613277184908,"symbol":"BCHSV-USDT","changes":{"asks":[],"bids":[["0","0","1613277184908"]]},"sequenceEnd":1613277184908},"subject":"trade.l2update","topic":"/market/level2:BCHSV-USDT","type":"message"}
1619378338.997765: {"data":{"sequenceStart":1613277184909,"symbol":"BCHSV-USDT","changes":{"asks":[],"bids":[["233.837","125","1613277184909"]]},"sequenceEnd":1613277184909},"subject":"trade.l2update","topic":"/market/level2:BCHSV-USDT","type":"message"}
1619378338.997796: {"data":{"sequenceStart":1613277184910,"symbol":"BCHSV-USDT","changes":{"asks":[],"bids":[["0","0","1613277184910"]]},"sequenceEnd":1613277184910},"subject":"trade.l2update","topic":"/market/level2:BCHSV-USDT","type":"message"}
1619378338.997817: {"data":{"sequenceStart":1613277184911,"symbol":"BCHSV-USDT","changes":{"asks":[],"bids":[["236.679","70","1613277184911"]]},"sequenceEnd":1613277184911},"subject":"trade.l2update","topic":"/market/level2:BCHSV-USDT","type":"message"}
1619378339.023811: {"data":{"sequenceStart":1613277184912,"symbol":"BCHSV-USDT","changes":{"asks":[["242.928","0","1613277184912"]],"bids":[]},"sequenceEnd":1613277184912},"subject":"trade.l2update","topic":"/market/level2:BCHSV-USDT","type":"message"}
1619378339.0238972: {"data":{"sequenceStart":1612694580179,"symbol":"CAPP-BTC","changes":{"asks":[["0","0","1612694580179"]],"bids":[]},"sequenceEnd":1612694580179},"subject":"trade.l2update","topic":"/market/level2:CAPP-BTC","type":"message"}
1619378339.0239239: {"data":{"sequenceStart":1612694580180,"symbol":"CAPP-BTC","changes":{"asks":[["0.0000002197","4895.9","1612694580180"]],"bids":[]},"sequenceEnd":1612694580180},"subject":"trade.l2update","topic":"/market/level2:CAPP-BTC","type":"message"}
1619378339.045656: {"data":{"sequence":"1612694580180","bestAsk":"0.0000002196","size":"1000.02","bestBidSize":"83.07","price":"0.0000002182","time":1619378338981,"bestAskSize":"330.25","bestBid":"0.0000002181"},"subject":"trade.ticker","topic":"/market/ticker:CAPP-BTC","type":"message"}
1619378339.045758: {"data":{"sequenceStart":1613277184913,"symbol":"BCHSV-USDT","changes":{"asks":[["0","0","1613277184913"]],"bids":[]},"sequenceEnd":1613277184913},"subject":"trade.l2update","topic":"/market/level2:BCHSV-USDT","type":"message"}
1619378339.045821: {"data":{"sequenceStart":1613277184914,"symbol":"BCHSV-USDT","changes":{"asks":[["243.264","0.6","1613277184914"]],"bids":[]},"sequenceEnd":1613277184914},"subject":"trade.l2update","topic":"/market/level2:BCHSV-USDT","type":"message"}
1619378339.04587: {"data":{"sequenceStart":1613277184915,"symbol":"BCHSV-USDT","changes":{"asks":[],"bids":[["0","0","1613277184915"]]},"sequenceEnd":1613277184915},"subject":"trade.l2update","topic":"/market/level2:BCHSV-USDT","type":"message"}
1619378339.045897: {"data":{"sequenceStart":1613277184916,"symbol":"BCHSV-USDT","changes":{"asks":[],"bids":[["242.646","0.68148185","1613277184916"]]},"sequenceEnd":1613277184916},"subject":"trade.l2update","topic":"/market/level2:BCHSV-USDT","type":"message"}
1619378339.045929: {"data":{"sequenceStart":1612701563993,"symbol":"DAPPT-BTC","changes":{"asks":[],"bids":[["0","0","1612701563993"]]},"sequenceEnd":1612701563993},"subject":"trade.l2update","topic":"/market/level2:DAPPT-BTC","type":"message"}
1619378339.045952: {"data":{"sequenceStart":1612701563994,"symbol":"DAPPT-BTC","changes":{"asks":[],"bids":[["0.0000001102","70929.196","1612701563994"]]},"sequenceEnd":1612701563994},"subject":"trade.l2update","topic":"/market/level2:DAPPT-BTC","type":"message"}
1619378339.09087: {"data":{"sequence":"1612701563994","bestAsk":"0.000000113","size":"145.4959","bestBidSize":"5148.7686","price":"0.0000001126","time":1619378339030,"bestAskSize":"1208.0878","bestBid":"0.000000112"},"subject":"trade.ticker","topic":"/market/ticker:DAPPT-BTC","type":"message"}
1619378339.0936131: {"data":{"sequence":"1613277184916","bestAsk":"242.999","size":"0.14324938","bestBidSize":"0.68148185","price":"242.781","time":1619378339032,"bestAskSize":"10.12458721","bestBid":"242.646"},"subject":"trade.ticker","topic":"/market/ticker:BCHSV-USDT","type":"message"}
1619378339.116713: {"data":{"sequenceStart":1612702190348,"symbol":"NRG-BTC","changes":{"asks":[["0","0","1612702190348"]],"bids":[]},"sequenceEnd":1612702190348},"subject":"trade.l2update","topic":"/market/level2:NRG-BTC","type":"message"}
1619378339.116823: {"data":{"sequenceStart":1612702190349,"symbol":"NRG-BTC","changes":{"asks":[["0.0000623","13.679","1612702190349"]],"bids":[]},"sequenceEnd":1612702190349},"subject":"trade.l2update","topic":"/market/level2:NRG-BTC","type":"message"}
1619378339.116906: {"data":{"sequenceStart":1612712745695,"symbol":"FET-BTC","changes":{"asks":[],"bids":[["0.00000769","20","1612712745695"]]},"sequenceEnd":1612712745695},"subject":"trade.l2update","topic":"/market/level2:FET-BTC","type":"message"}
1619378339.116957: {"data":{"sequenceStart":1612701563995,"symbol":"DAPPT-BTC","changes":{"asks":[],"bids":[["0","0","1612701563995"]]},"sequenceEnd":1612701563995},"subject":"trade.l2update","topic":"/market/level2:DAPPT-BTC","type":"message"}
1619378339.117006: {"data":{"sequenceStart":1612701563996,"symbol":"DAPPT-BTC","changes":{"asks":[],"bids":[["0.0000001115","3091.7","1612701563996"]]},"sequenceEnd":1612701563996},"subject":"trade.l2update","topic":"/market/level2:DAPPT-BTC","type":"message"}
1619378339.127882: {"data":{"sequenceStart":1612699351277,"symbol":"COV-BTC","changes":{"asks":[["0","0","1612699351277"]],"bids":[]},"sequenceEnd":1612699351277},"subject":"trade.l2update","topic":"/market/level2:COV-BTC","type":"message"}
1619378339.12799: {"data":{"sequenceStart":1612699351278,"symbol":"COV-BTC","changes":{"asks":[["0.00001127","4469.58576035","1612699351278"]],"bids":[]},"sequenceEnd":1612699351278},"subject":"trade.l2update","topic":"/market/level2:COV-BTC","type":"message"}
1619378339.135607: {"data":{"sequence":"1612712745695","bestAsk":"0.00000776","size":"401.2004","bestBidSize":"357.285","price":"0.00000772","time":1619378339068,"bestAskSize":"1154.0416","bestBid":"0.00000771"},"subject":"trade.ticker","topic":"/market/ticker:FET-BTC","type":"message"}
1619378339.135669: {"data":{"sequenceStart":1613277184917,"symbol":"BCHSV-USDT","changes":{"asks":[],"bids":[["242.089","0","1613277184917"]]},"sequenceEnd":1613277184917},"subject":"trade.l2update","topic":"/market/level2:BCHSV-USDT","type":"message"}
1619378339.135734: {"data":{"sequenceStart":1613277184918,"symbol":"BCHSV-USDT","changes":{"asks":[],"bids":[["242.108","2.99","1613277184918"]]},"sequenceEnd":1613277184918},"subject":"trade.l2update","topic":"/market/level2:BCHSV-USDT","type":"message"}
1619378339.138744: {"data":{"sequenceStart":1613277184919,"symbol":"BCHSV-USDT","changes":{"asks":[],"bids":[["242.108","0","1613277184919"]]},"sequenceEnd":1613277184919},"subject":"trade.l2update","topic":"/market/level2:BCHSV-USDT","type":"message"}
1619378339.1388412: {"data":{"sequence":"1612699351278","bestAsk":"0.00001127","size":"96.1525","bestBidSize":"49.6422","price":"0.00001126","time":1619378339089,"bestAskSize":"4469.58576035","bestBid":"0.00001121"},"subject":"trade.ticker","topic":"/market/ticker:COV-BTC","type":"message"}
1619378339.144515: {"data":{"sequenceStart":1612712745696,"symbol":"FET-BTC","changes":{"asks":[["0.00000791","24.0985","1612712745696"]],"bids":[]},"sequenceEnd":1612712745696},"subject":"trade.l2update","topic":"/market/level2:FET-BTC","type":"message"}
1619378339.144634: {"data":{"sequence":"1612702190349","bestAsk":"0.00006218","size":"0.0431","bestBidSize":"19.5017","price":"0.00006141","time":1619378339091,"bestAskSize":"43.3399","bestBid":"0.00006141"},"subject":"trade.ticker","topic":"/market/ticker:NRG-BTC","type":"message"}
1619378339.1806989: {"data":{"sequence":"1612701563996","bestAsk":"0.000000113","size":"145.4959","bestBidSize":"5148.7686","price":"0.0000001126","time":1619378339130,"bestAskSize":"1208.0878","bestBid":"0.000000112"},"subject":"trade.ticker","topic":"/market/ticker:DAPPT-BTC","type":"message"}
1619378339.191437: {"data":{"sequence":"1613277184919","bestAsk":"242.999","size":"0.14324938","bestBidSize":"0.68148185","price":"242.781","time":1619378339132,"bestAskSize":"10.12458721","bestBid":"242.646"},"subject":"trade.ticker","topic":"/market/ticker:BCHSV-USDT","type":"message"}
1619378339.1915278: {"data":{"sequenceStart":1613277184920,"symbol":"BCHSV-USDT","changes":{"asks":[],"bids":[["0","0","1613277184920"]]},"sequenceEnd":1613277184920},"subject":"trade.l2update","topic":"/market/level2:BCHSV-USDT","type":"message"}
1619378339.191596: {"data":{"sequenceStart":1613277184921,"symbol":"BCHSV-USDT","changes":{"asks":[],"bids":[["242.288","5.52","1613277184921"]]},"sequenceEnd":1613277184921},"subject":"trade.l2update","topic":"/market/level2:BCHSV-USDT","type":"message"}
1619378339.1916769: {"data":{"sequenceStart":1613277184922,"symbol":"BCHSV-USDT","changes":{"asks":[],"bids":[["0","0","1613277184922"]]},"sequenceEnd":1613277184922},"subject":"trade.l2update","topic":"/market/level2:BCHSV-USDT","type":"message"}
1619378339.1917179: {"data":{"sequenceStart":1613277184923,"symbol":"BCHSV-USDT","changes":{"asks":[],"bids":[["242.11","2.99","1613277184923"]]},"sequenceEnd":1613277184923},"subject":"trade.l2update","topic":"/market/level2:BCHSV-USDT","type":"message"}
1619378339.191749: {"data":{"sequenceStart":1612712745697,"symbol":"FET-BTC","changes":{"asks":[],"bids":[["0","0","1612712745697"]]},"sequenceEnd":1612712745697},"subject":"trade.l2update","topic":"/market/level2:FET-BTC","type":"message"}
1619378339.191773: {"data":{"sequenceStart":1612712745698,"symbol":"FET-BTC","changes":{"asks":[],"bids":[["0.00000769","88.5593","1612712745698"]]},"sequenceEnd":1612712745698},"subject":"trade.l2update","topic":"/market/level2:FET-BTC","type":"message"}
1619378339.2155662: {"data":{"sequenceStart":1613277184924,"symbol":"BCHSV-USDT","changes":{"asks":[],"bids":[["242.288","0","1613277184924"]]},"sequenceEnd":1613277184924},"subject":"trade.l2update","topic":"/market/level2:BCHSV-USDT","type":"message"}
1619378339.2157152: {"data":{"sequenceStart":1613277184925,"symbol":"BCHSV-USDT","changes":{"asks":[],"bids":[["0","0","1613277184925"]]},"sequenceEnd":1613277184925},"subject":"trade.l2update","topic":"/market/level2:BCHSV-USDT","type":"message"}
1619378339.215768: {"data":{"sequenceStart":1613277184926,"symbol":"BCHSV-USDT","changes":{"asks":[],"bids":[["242.11","5.98","1613277184926"]]},"sequenceEnd":1613277184926},"subject":"trade.l2update","topic":"/market/level2:BCHSV-USDT","type":"message"}
1619378339.218863: {"data":{"sequenceStart":1613277184927,"symbol":"BCHSV-USDT","changes":{"asks":[["243.264","0","1613277184927"]],"bids":[]},"sequenceEnd":1613277184927},"subject":"trade.l2update","topic":"/market/level2:BCHSV-USDT","type":"message"}
1619378339.218987: {"data":{"sequenceStart":1613277184928,"symbol":"BCHSV-USDT","changes":{"asks":[],"bids":[["242.646","0","1613277184928"]]},"sequenceEnd":1613277184928},"subject":"trade.l2update","topic":"/market/level2:BCHSV-USDT","type":"message"}
1619378339.2190561: {"data":{"sequenceStart":1612712745699,"symbol":"FET-BTC","changes":{"asks":[],"bids":[["0","0","1612712745699"]]},"sequenceEnd":1612712745699},"subject":"trade.l2update","topic":"/market/level2:FET-BTC","type":"message"}
1619378339.2191029: {"data":{"sequenceStart":1612712745700,"symbol":"FET-BTC","changes":{"asks":[],"bids":[["0.00000771","1250.285","1612712745700"]]},"sequenceEnd":1612712745700},"subject":"trade.l2update","topic":"/market/level2:FET-BTC","type":"message"}
1619378339.219148: {"data":{"sequence":"1612712745700","bestAsk":"0.00000776","size":"401.2004","bestBidSize":"1250.285","price":"0.00000772","time":1619378339167,"bestAskSize":"1154.0416","bestBid":"0.00000771"},"subject":"trade.ticker","topic":"/market/ticker:FET-BTC","type":"message"}
1619378339.24854: {"data":{"sequenceStart":1613277184929,"symbol":"BCHSV-USDT","changes":{"asks":[["0","0","1613277184929"]],"bids":[]},"sequenceEnd":1613277184929},"subject":"trade.l2update","topic":"/market/level2:BCHSV-USDT","type":"message"}
1619378339.248648: {"data":{"sequenceStart":1613277184930,"symbol":"BCHSV-USDT","changes":{"asks":[["243.286","0.6","1613277184930"]],"bids":[]},"sequenceEnd":1613277184930},"subject":"trade.l2update","topic":"/market/level2:BCHSV-USDT","type":"message"}
1619378339.2487261: {"data":{"sequenceStart":1612712745701,"symbol":"FET-BTC","changes":{"asks":[],"bids":[["0.00000769","20","1612712745701"]]},"sequenceEnd":1612712745701},"subject":"trade.l2update","topic":"/market/level2:FET-BTC","type":"message"}
1619378339.250027: {"data":{"sequenceStart":1613277184931,"symbol":"BCHSV-USDT","changes":{"asks":[],"bids":[["0","0","1613277184931"]]},"sequenceEnd":1613277184931},"subject":"trade.l2update","topic":"/market/level2:BCHSV-USDT","type":"message"}
1619378339.2501361: {"data":{"sequenceStart":1613277184932,"symbol":"BCHSV-USDT","changes":{"asks":[],"bids":[["242.139","5.52","1613277184932"]]},"sequenceEnd":1613277184932},"subject":"trade.l2update","topic":"/market/level2:BCHSV-USDT","type":"message"}
1619378339.256819: {"data":{"sequenceStart":1613277184933,"symbol":"BCHSV-USDT","changes":{"asks":[["242.999","0","1613277184933"]],"bids":[]},"sequenceEnd":1613277184933},"subject":"trade.l2update","topic":"/market/level2:BCHSV-USDT","type":"message"}
1619378339.2966158: {"data":{"sequence":"1613277184933","bestAsk":"243","size":"0.14324938","bestBidSize":"0.45082023","price":"242.781","time":1619378339232,"bestAskSize":"4.51280965","bestBid":"242.635"},"subject":"trade.ticker","topic":"/market/ticker:BCHSV-USDT","type":"message"}
1619378339.303641: {"data":{"sequenceStart":1612734157872,"symbol":"ANKR-BTC","changes":{"asks":[],"bids":[["0.0000025561","67","1612734157872"]]},"sequenceEnd":1612734157872},"subject":"trade.l2update","topic":"/market/level2:ANKR-BTC","type":"message"}
1619378339.318772: {"data":{"sequenceStart":1613277184934,"symbol":"BCHSV-USDT","changes":{"asks":[["243.286","0","1613277184934"]],"bids":[]},"sequenceEnd":1613277184934},"subject":"trade.l2update","topic":"/market/level2:BCHSV-USDT","type":"message"}
1619378339.3188312: {"data":{"sequenceStart":1613277184935,"symbol":"BCHSV-USDT","changes":{"asks":[["243","0","1613277184935"]],"bids":[]},"sequenceEnd":1613277184935},"subject":"trade.l2update","topic":"/market/level2:BCHSV-USDT","type":"message"}
1619378339.3188648: {"data":{"sequenceStart":1612712745702,"symbol":"FET-BTC","changes":{"asks":[],"bids":[["0","0","1612712745702"]]},"sequenceEnd":1612712745702},"subject":"trade.l2update","topic":"/market/level2:FET-BTC","type":"message"}
1619378339.318889: {"data":{"sequenceStart":1612712745703,"symbol":"FET-BTC","changes":{"asks":[],"bids":[["0.00000769","88.5593","1612712745703"]]},"sequenceEnd":1612712745703},"subject":"trade.l2update","topic":"/market/level2:FET-BTC","type":"message"}
1619378339.318913: {"data":{"sequence":"1612712745701","bestAsk":"0.00000776","size":"401.2004","bestBidSize":"1250.285","price":"0.00000772","time":1619378339267,"bestAskSize":"1154.0416","bestBid":"0.00000771"},"subject":"trade.ticker","topic":"/market/ticker:FET-BTC","type":"message"}
1619378339.333044: {"data":{"sequenceStart":1613277184936,"symbol":"BCHSV-USDT","changes":{"asks":[["0","0","1613277184936"]],"bids":[]},"sequenceEnd":1613277184936},"subject":"trade.l2update","topic":"/market/level2:BCHSV-USDT","type":"message"}
1619378339.333156: {"data":{"sequenceStart":1613277184937,"symbol":"BCHSV-USDT","changes":{"asks":[["243.847","9.64164628","1613277184937"]],"bids":[]},"sequenceEnd":1613277184937},"subject":"trade.l2update","topic":"/market/level2:BCHSV-USDT","type":"message"}
1619378339.333237: {"data":{"sequenceStart":1613277184938,"symbol":"BCHSV-USDT","changes":{"asks":[],"bids":[["242.11","2.99","1613277184938"]]},"sequenceEnd":1613277184938},"subject":"trade.l2update","topic":"/market/level2:BCHSV-USDT","type":"message"}
1619378339.335389: {"data":{"sequence":"1612734157872","bestAsk":"0.0000026208","size":"46","bestBidSize":"5034.7285","price":"0.0000026071","time":1619378339288,"bestAskSize":"10987.6265","bestBid":"0.0000026001"},"subject":"trade.ticker","topic":"/market/ticker:ANKR-BTC","type":"message"}
1619378339.335497: {"data":{"sequenceStart":1613277184939,"symbol":"BCHSV-USDT","changes":{"asks":[],"bids":[["242.11","0","1613277184939"]]},"sequenceEnd":1613277184939},"subject":"trade.l2update","topic":"/market/level2:BCHSV-USDT","type":"message"}
1619378339.335593: {"data":{"sequenceStart":1613277184940,"symbol":"BCHSV-USDT","changes":{"asks":[["0","0","1613277184940"]],"bids":[]},"sequenceEnd":1613277184940},"subject":"trade.l2update","topic":"/market/level2:BCHSV-USDT","type":"message"}
1619378339.335639: {"data":{"sequenceStart":1613277184941,"symbol":"BCHSV-USDT","changes":{"asks":[["243.057","3.73920503","1613277184941"]],"bids":[]},"sequenceEnd":1613277184941},"subject":"trade.l2update","topic":"/market/level2:BCHSV-USDT","type":"message"}
1619378339.37747: {"data":{"sequenceStart":1612712745704,"symbol":"FET-BTC","changes":{"asks":[],"bids":[["0.00000769","20","1612712745704"]]},"sequenceEnd":1612712745704},"subject":"trade.l2update","topic":"/market/level2:FET-BTC","type":"message"}
1619378339.3775911: {"data":{"sequenceStart":1613277184942,"symbol":"BCHSV-USDT","changes":{"asks":[["246.421","0","1613277184942"]],"bids":[]},"sequenceEnd":1613277184942},"subject":"trade.l2update","topic":"/market/level2:BCHSV-USDT","type":"message"}
1619378339.38126: {"data":{"sequence":"1613277184944","bestAsk":"243.05","size":"0.14324938","bestBidSize":"0.45082023","price":"242.781","time":1619378339332,"bestAskSize":"5.98","bestBid":"242.635"},"subject":"trade.ticker","topic":"/market/ticker:BCHSV-USDT","type":"message"}
1619378339.381354: {"data":{"sequenceStart":1613277184943,"symbol":"BCHSV-USDT","changes":{"asks":[],"bids":[["0","0","1613277184943"]]},"sequenceEnd":1613277184943},"subject":"trade.l2update","topic":"/market/level2:BCHSV-USDT","type":"message"}
1619378339.3814201: {"data":{"sequenceStart":1613277184944,"symbol":"BCHSV-USDT","changes":{"asks":[],"bids":[["242.14","2.99","1613277184944"]]},"sequenceEnd":1613277184944},"subject":"trade.l2update","topic":"/market/level2:BCHSV-USDT","type":"message"}
1619378339.398408: {"data":{"sequenceStart":1613277184945,"symbol":"BCHSV-USDT","changes":{"asks":[],"bids":[["0","0","1613277184945"]]},"sequenceEnd":1613277184945},"subject":"trade.l2update","topic":"/market/level2:BCHSV-USDT","type":"message"}
1619378339.39852: {"data":{"sequenceStart":1613277184946,"symbol":"BCHSV-USDT","changes":{"asks":[],"bids":[["242.14","5.98","1613277184946"]]},"sequenceEnd":1613277184946},"subject":"trade.l2update","topic":"/market/level2:BCHSV-USDT","type":"message"}
1619378339.4159849: {"data":{"sequence":"1612712745704","bestAsk":"0.00000776","size":"401.2004","bestBidSize":"1250.285","price":"0.00000772","time":1619378339367,"bestAskSize":"1154.0416","bestBid":"0.00000771"},"subject":"trade.ticker","topic":"/market/ticker:FET-BTC","type":"message"}
1619378339.4285362: {"data":{"sequenceStart":1613277184947,"symbol":"BCHSV-USDT","changes":{"asks":[["0","0","1613277184947"]],"bids":[]},"sequenceEnd":1613277184947},"subject":"trade.l2update","topic":"/market/level2:BCHSV-USDT","type":"message"}
1619378339.4286451: {"data":{"sequenceStart":1613277184948,"symbol":"BCHSV-USDT","changes":{"asks":[["243.042","1","1613277184948"]],"bids":[]},"sequenceEnd":1613277184948},"subject":"trade.l2update","topic":"/market/level2:BCHSV-USDT","type":"message"}
1619378339.432411: {"data":{"sequenceStart":1612712745705,"symbol":"FET-BTC","changes":{"asks":[["0","0","1612712745705"]],"bids":[]},"sequenceEnd":1612712745705},"subject":"trade.l2update","topic":"/market/level2:FET-BTC","type":"message"}
1619378339.432519: {"data":{"sequenceStart":1612712745706,"symbol":"FET-BTC","changes":{"asks":[["0.00000794","1528.8753","1612712745706"]],"bids":[]},"sequenceEnd":1612712745706},"subject":"trade.l2update","topic":"/market/level2:FET-BTC","type":"message"}
1619378339.4326022: {"data":{"sequenceStart":1613277184949,"symbol":"BCHSV-USDT","changes":{"asks":[["0","0","1613277184949"]],"bids":[]},"sequenceEnd":1613277184949},"subject":"trade.l2update","topic":"/market/level2:BCHSV-USDT","type":"message"}
1619378339.432647: {"data":{"sequenceStart":1613277184950,"symbol":"BCHSV-USDT","changes":{"asks":[["247.395","37.111","1613277184950"]],"bids":[]},"sequenceEnd":1613277184950},"subject":"trade.l2update","topic":"/market/level2:BCHSV-USDT","type":"message"}
1619378339.4778361: {"data":{"sequenceStart":1613277184951,"symbol":"BCHSV-USDT","changes":{"asks":[],"bids":[["0","0","1613277184951"]]},"sequenceEnd":1613277184951},"subject":"trade.l2update","topic":"/market/level2:BCHSV-USDT","type":"message"}
1619378339.477943: {"data":{"sequenceStart":1613277184952,"symbol":"BCHSV-USDT","changes":{"asks":[],"bids":[["241.592","5","1613277184952"]]},"sequenceEnd":1613277184952},"subject":"trade.l2update","topic":"/market/level2:BCHSV-USDT","type":"message"}
1619378339.478019: {"data":{"sequenceStart":1613277184953,"symbol":"BCHSV-USDT","changes":{"asks":[["0","0","1613277184953"]],"bids":[]},"sequenceEnd":1613277184953},"subject":"trade.l2update","topic":"/market/level2:BCHSV-USDT","type":"message"}
1619378339.4780679: {"data":{"sequenceStart":1613277184954,"symbol":"BCHSV-USDT","changes":{"asks":[["243.754","5","1613277184954"]],"bids":[]},"sequenceEnd":1613277184954},"subject":"trade.l2update","topic":"/market/level2:BCHSV-USDT","type":"message"}
1619378339.478129: {"data":{"sequenceStart":1613277184955,"symbol":"BCHSV-USDT","changes":{"asks":[["0","0","1613277184955"]],"bids":[]},"sequenceEnd":1613277184955},"subject":"trade.l2update","topic":"/market/level2:BCHSV-USDT","type":"message"}
1619378339.4781508: {"data":{"sequenceStart":1613277184956,"symbol":"BCHSV-USDT","changes":{"asks":[["244.391","150","1613277184956"]],"bids":[]},"sequenceEnd":1613277184956},"subject":"trade.l2update","topic":"/market/level2:BCHSV-USDT","type":"message"}
1619378339.4781802: {"data":{"sequence":"1613277184956","bestAsk":"243.042","size":"0.14324938","bestBidSize":"0.45082023","price":"242.781","time":1619378339432,"bestAskSize":"1","bestBid":"242.635"},"subject":"trade.ticker","topic":"/market/ticker:BCHSV-USDT","type":"message"}
1619378339.5023072: {"data":{"sequenceStart":1613277184957,"symbol":"BCHSV-USDT","changes":{"asks":[],"bids":[["0","0","1613277184957"]]},"sequenceEnd":1613277184957},"subject":"trade.l2update","topic":"/market/level2:BCHSV-USDT","type":"message"}
1619378339.5024178: {"data":{"sequenceStart":1613277184958,"symbol":"BCHSV-USDT","changes":{"asks":[],"bids":[["240.959","150","1613277184958"]]},"sequenceEnd":1613277184958},"subject":"trade.l2update","topic":"/market/level2:BCHSV-USDT","type":"message"}
1619378339.506382: {"data":{"sequenceStart":1613277184959,"symbol":"BCHSV-USDT","changes":{"asks":[["243.042","0","1613277184959"]],"bids":[]},"sequenceEnd":1613277184959},"subject":"trade.l2update","topic":"/market/level2:BCHSV-USDT","type":"message"}
1619378339.5176709: {"data":{"sequence":"1612712745706","bestAsk":"0.00000776","size":"401.2004","bestBidSize":"1250.285","price":"0.00000772","time":1619378339467,"bestAskSize":"1154.0416","bestBid":"0.00000771"},"subject":"trade.ticker","topic":"/market/ticker:FET-BTC","type":"message"}
1619378339.5177758: {"data":{"sequenceStart":1613277184960,"symbol":"BCHSV-USDT","changes":{"asks":[],"bids":[["0","0","1613277184960"]]},"sequenceEnd":1613277184960},"subject":"trade.l2update","topic":"/market/level2:BCHSV-USDT","type":"message"}
1619378339.5178418: {"data":{"sequenceStart":1613277184961,"symbol":"BCHSV-USDT","changes":{"asks":[],"bids":[["240.265","2.0810355","1613277184961"]]},"sequenceEnd":1613277184961},"subject":"trade.l2update","topic":"/market/level2:BCHSV-USDT","type":"message"}
1619378339.541214: {"data":{"sequenceStart":1613277184962,"symbol":"BCHSV-USDT","changes":{"asks":[["0","0","1613277184962"]],"bids":[]},"sequenceEnd":1613277184962},"subject":"trade.l2update","topic":"/market/level2:BCHSV-USDT","type":"message"}
1619378339.541323: {"data":{"sequenceStart":1613277184963,"symbol":"BCHSV-USDT","changes":{"asks":[["243.039","1","1613277184963"]],"bids":[]},"sequenceEnd":1613277184963},"subject":"trade.l2update","topic":"/market/level2:BCHSV-USDT","type":"message"}
1619378339.552926: {"data":{"sequenceStart":1619079123953,"symbol":"EQZ-BTC","changes":{"asks":[],"bids":[["0.0000237","226.7699","1619079123953"]]},"sequenceEnd":1619079123953},"subject":"trade.l2update","topic":"/market/level2:EQZ-BTC","type":"message"}
1619378339.5641658: {"data":{"sequenceStart":1612694580181,"symbol":"CAPP-BTC","changes":{"asks":[["0.0000002515","0","1612694580181"]],"bids":[]},"sequenceEnd":1612694580181},"subject":"trade.l2update","topic":"/market/level2:CAPP-BTC","type":"message"}
1619378339.571567: {"data":{"sequence":"1613277184963","bestAsk":"243.039","size":"0.14324938","bestBidSize":"0.45082023","price":"242.781","time":1619378339530,"bestAskSize":"1","bestBid":"242.635"},"subject":"trade.ticker","topic":"/market/ticker:BCHSV-USDT","type":"message"}
1619378339.578646: {"data":{"sequence":"1619079123953","bestAsk":"0.00002395","size":"0.375","bestBidSize":"20.5373","price":"0.00002383","time":1619378339538,"bestAskSize":"72.1515","bestBid":"0.00002383"},"subject":"trade.ticker","topic":"/market/ticker:EQZ-BTC","type":"message"}
1619378339.5958872: {"data":{"sequenceStart":1613277184964,"symbol":"BCHSV-USDT","changes":{"asks":[["243.039","0","1613277184964"]],"bids":[]},"sequenceEnd":1613277184964},"subject":"trade.l2update","topic":"/market/level2:BCHSV-USDT","type":"message"}
1619378339.6088572: {"data":{"sequenceStart":1612734157873,"symbol":"ANKR-BTC","changes":{"asks":[],"bids":[["0","0","1612734157873"]]},"sequenceEnd":1612734157873},"subject":"trade.l2update","topic":"/market/level2:ANKR-BTC","type":"message"}
1619378339.6089349: {"data":{"sequenceStart":1612734157874,"symbol":"ANKR-BTC","changes":{"asks":[],"bids":[["0.0000025511","291.9522","1612734157874"]]},"sequenceEnd":1612734157874},"subject":"trade.l2update","topic":"/market/level2:ANKR-BTC","type":"message"}
1619378339.6148741: {"data":{"sequenceStart":1613277184965,"symbol":"BCHSV-USDT","changes":{"asks":[["0","0","1613277184965"]],"bids":[]},"sequenceEnd":1613277184965},"subject":"trade.l2update","topic":"/market/level2:BCHSV-USDT","type":"message"}
1619378339.614989: {"data":{"sequenceStart":1613277184966,"symbol":"BCHSV-USDT","changes":{"asks":[["243.037","1","1613277184966"]],"bids":[]},"sequenceEnd":1613277184966},"subject":"trade.l2update","topic":"/market/level2:BCHSV-USDT","type":"message"}
1619378339.623223: {"data":{"sequence":"1612694580181","bestAsk":"0.0000002196","size":"1000.02","bestBidSize":"83.07","price":"0.0000002182","time":1619378339582,"bestAskSize":"330.25","bestBid":"0.0000002181"},"subject":"trade.ticker","topic":"/market/ticker:CAPP-BTC","type":"message"}
1619378339.623286: {"data":{"sequence":"1612734157874","bestAsk":"0.0000026208","size":"46","bestBidSize":"5034.7285","price":"0.0000026071","time":1619378339588,"bestAskSize":"10987.6265","bestBid":"0.0000026001"},"subject":"trade.ticker","topic":"/market/ticker:ANKR-BTC","type":"message"}
1619378339.672823: {"data":{"sequence":"1613277184966","bestAsk":"243.037","size":"0.14324938","bestBidSize":"0.45082023","price":"242.781","time":1619378339633,"bestAskSize":"1","bestBid":"242.635"},"subject":"trade.ticker","topic":"/market/ticker:BCHSV-USDT","type":"message"}
1619378339.6808598: {"data":{"sequenceStart":1612694580182,"symbol":"CAPP-BTC","changes":{"asks":[["0.0000002197","735.9","1612694580182"]],"bids":[]},"sequenceEnd":1612694580182},"subject":"trade.l2update","topic":"/market/level2:CAPP-BTC","type":"message"}
1619378339.701944: {"data":{"sequenceStart":1613277184967,"symbol":"BCHSV-USDT","changes":{"asks":[["243.094","0","1613277184967"]],"bids":[]},"sequenceEnd":1613277184967},"subject":"trade.l2update","topic":"/market/level2:BCHSV-USDT","type":"message"}
1619378339.710711: {"data":{"sequenceStart":1613277184968,"symbol":"BCHSV-USDT","changes":{"asks":[],"bids":[["242.397","0","1613277184968"]]},"sequenceEnd":1613277184968},"subject":"trade.l2update","topic":"/market/level2:BCHSV-USDT","type":"message"}
1619378339.722371: {"data":{"sequence":"1612694580182","bestAsk":"0.0000002196","size":"1000.02","bestBidSize":"83.07","price":"0.0000002182","time":1619378339681,"bestAskSize":"330.25","bestBid":"0.0000002181"},"subject":"trade.ticker","topic":"/market/ticker:CAPP-BTC","type":"message"}
1619378339.762157: {"data":{"sequenceStart":1613277184969,"symbol":"BCHSV-USDT","changes":{"asks":[["243.847","0","1613277184969"]],"bids":[]},"sequenceEnd":1613277184969},"subject":"trade.l2update","topic":"/market/level2:BCHSV-USDT","type":"message"}
1619378339.762296: {"data":{"sequenceStart":1613277184970,"symbol":"BCHSV-USDT","changes":{"asks":[["243.057","0","1613277184970"]],"bids":[]},"sequenceEnd":1613277184970},"subject":"trade.l2update","topic":"/market/level2:BCHSV-USDT","type":"message"}
1619378339.767049: {"data":{"sequence":"1613277184970","bestAsk":"243.037","size":"0.14324938","bestBidSize":"0.45082023","price":"242.781","time":1619378339730,"bestAskSize":"1","bestBid":"242.635"},"subject":"trade.ticker","topic":"/market/ticker:BCHSV-USDT","type":"message"}
1619378339.798301: {"data":{"sequenceStart":1613277184971,"symbol":"BCHSV-USDT","changes":{"asks":[["243.037","0","1613277184971"]],"bids":[]},"sequenceEnd":1613277184971},"subject":"trade.l2update","topic":"/market/level2:BCHSV-USDT","type":"message"}
1619378339.815261: {"data":{"sequenceStart":1612712745707,"symbol":"FET-BTC","changes":{"asks":[],"bids":[["0","0","1612712745707"]]},"sequenceEnd":1612712745707},"subject":"trade.l2update","topic":"/market/level2:FET-BTC","type":"message"}
1619378339.8153448: {"data":{"sequenceStart":1612712745708,"symbol":"FET-BTC","changes":{"asks":[],"bids":[["0.00000769","88.5593","1612712745708"]]},"sequenceEnd":1612712745708},"subject":"trade.l2update","topic":"/market/level2:FET-BTC","type":"message"}
1619378339.824515: {"data":{"sequenceStart":1613277184972,"symbol":"BCHSV-USDT","changes":{"asks":[["0","0","1613277184972"]],"bids":[]},"sequenceEnd":1613277184972},"subject":"trade.l2update","topic":"/market/level2:BCHSV-USDT","type":"message"}
1619378339.8245912: {"data":{"sequenceStart":1613277184973,"symbol":"BCHSV-USDT","changes":{"asks":[["243.037","1","1613277184973"]],"bids":[]},"sequenceEnd":1613277184973},"subject":"trade.l2update","topic":"/market/level2:BCHSV-USDT","type":"message"}
1619378339.843046: {"data":{"sequenceStart":1613277184974,"symbol":"BCHSV-USDT","changes":{"asks":[["0","0","1613277184974"]],"bids":[]},"sequenceEnd":1613277184974},"subject":"trade.l2update","topic":"/market/level2:BCHSV-USDT","type":"message"}
1619378339.843157: {"data":{"sequenceStart":1613277184975,"symbol":"BCHSV-USDT","changes":{"asks":[["243.036","9.62448872","1613277184975"]],"bids":[]},"sequenceEnd":1613277184975},"subject":"trade.l2update","topic":"/market/level2:BCHSV-USDT","type":"message"}
1619378339.847785: {"data":{"sequenceStart":1613277184976,"symbol":"BCHSV-USDT","changes":{"asks":[["244.391","0","1613277184976"]],"bids":[]},"sequenceEnd":1613277184976},"subject":"trade.l2update","topic":"/market/level2:BCHSV-USDT","type":"message"}
1619378339.847929: {"data":{"sequenceStart":1613277184977,"symbol":"BCHSV-USDT","changes":{"asks":[["243.754","0","1613277184977"]],"bids":[]},"sequenceEnd":1613277184977},"subject":"trade.l2update","topic":"/market/level2:BCHSV-USDT","type":"message"}
1619378339.862147: {"data":{"sequenceStart":1613277184978,"symbol":"BCHSV-USDT","changes":{"asks":[],"bids":[["241.592","0","1613277184978"]]},"sequenceEnd":1613277184978},"subject":"trade.l2update","topic":"/market/level2:BCHSV-USDT","type":"message"}
1619378339.862293: {"data":{"sequenceStart":1613277184979,"symbol":"BCHSV-USDT","changes":{"asks":[],"bids":[["240.959","0","1613277184979"]]},"sequenceEnd":1613277184979},"subject":"trade.l2update","topic":"/market/level2:BCHSV-USDT","type":"message"}
1619378339.871422: {"data":{"sequence":"1613277184979","bestAsk":"243.036","size":"0.14324938","bestBidSize":"0.45082023","price":"242.781","time":1619378339830,"bestAskSize":"9.62448872","bestBid":"242.635"},"subject":"trade.ticker","topic":"/market/ticker:BCHSV-USDT","type":"message"}
1619378339.877352: {"data":{"sequenceStart":1613277184980,"symbol":"BCHSV-USDT","changes":{"asks":[],"bids":[["240.265","0","1613277184980"]]},"sequenceEnd":1613277184980},"subject":"trade.l2update","topic":"/market/level2:BCHSV-USDT","type":"message"}
1619378339.905036: {"data":{"sequence":"1612712745708","bestAsk":"0.00000776","size":"401.2004","bestBidSize":"1250.285","price":"0.00000772","time":1619378339867,"bestAskSize":"1154.0416","bestBid":"0.00000771"},"subject":"trade.ticker","topic":"/market/ticker:FET-BTC","type":"message"}
1619378339.962414: {"data":{"sequenceStart":1612712745709,"symbol":"FET-BTC","changes":{"asks":[],"bids":[["0","0","1612712745709"]]},"sequenceEnd":1612712745709},"subject":"trade.l2update","topic":"/market/level2:FET-BTC","type":"message"}
1619378339.962521: {"data":{"sequenceStart":1612712745710,"symbol":"FET-BTC","changes":{"asks":[["0.00000776","1141.8325","1612712745710"]],"bids":[]},"sequenceEnd":1612712745710},"subject":"trade.l2update","topic":"/market/level2:FET-BTC","type":"message"}
1619378339.9625862: {"data":{"sequenceStart":1612712745711,"symbol":"FET-BTC","changes":{"asks":[],"bids":[["0","0","1612712745711"]]},"sequenceEnd":1612712745711},"subject":"trade.l2update","topic":"/market/level2:FET-BTC","type":"message"}
1619378339.9626281: {"data":{"symbol":"FET-BTC","sequence":"1612712745710","side":"buy","size":"12.2091","price":"0.00000776","takerOrderId":"6085c0a36ac0850006c4b00b","time":"1619378339919173052","type":"match","makerOrderId":"6085c0a082ed340006c05dd9","tradeId":"6085c0a378577837f306b46e"},"subject":"trade.l3match","topic":"/market/match:FET-BTC","type":"message"}
1619378339.9675488: {"data":{"sequenceStart":1613277184981,"symbol":"BCHSV-USDT","changes":{"asks":[],"bids":[["0","0","1613277184981"]]},"sequenceEnd":1613277184981},"subject":"trade.l2update","topic":"/market/level2:BCHSV-USDT","type":"message"}
1619378339.967624: {"data":{"sequenceStart":1613277184982,"symbol":"BCHSV-USDT","changes":{"asks":[],"bids":[["242.45","6.17546537","1613277184982"]]},"sequenceEnd":1613277184982},"subject":"trade.l2update","topic":"/market/level2:BCHSV-USDT","type":"message"}
1619378339.976293: {"data":{"sequence":"1613277184982","bestAsk":"243.036","size":"0.14324938","bestBidSize":"0.45082023","price":"242.781","time":1619378339932,"bestAskSize":"9.62448872","bestBid":"242.635"},"subject":"trade.ticker","topic":"/market/ticker:BCHSV-USDT","type":"message"}
1619378339.976387: {"data":{"sequenceStart":1613277184983,"symbol":"BCHSV-USDT","changes":{"asks":[["0","0","1613277184983"]],"bids":[]},"sequenceEnd":1613277184983},"subject":"trade.l2update","topic":"/market/level2:BCHSV-USDT","type":"message"}
1619378339.976452: {"data":{"sequenceStart":1613277184984,"symbol":"BCHSV-USDT","changes":{"asks":[["243.155","6.17546537","1613277184984"]],"bids":[]},"sequenceEnd":1613277184984},"subject":"trade.l2update","topic":"/market/level2:BCHSV-USDT","type":"message"}
1619378340.0091462: {"data":{"sequence":"1612712745711","bestAsk":"0.00000776","size":"12.2091","bestBidSize":"1250.285","price":"0.00000776","time":1619378339967,"bestAskSize":"1141.8325","bestBid":"0.00000771"},"subject":"trade.ticker","topic":"/market/ticker:FET-BTC","type":"message"}
1619378340.009237: {"data":{"sequenceStart":1613277184985,"symbol":"BCHSV-USDT","changes":{"asks":[["243.037","0","1613277184985"]],"bids":[]},"sequenceEnd":1613277184985},"subject":"trade.l2update","topic":"/market/level2:BCHSV-USDT","type":"message"}
1619378340.0235431: {"data":{"sequenceStart":1613277184986,"symbol":"BCHSV-USDT","changes":{"asks":[["0","0","1613277184986"]],"bids":[]},"sequenceEnd":1613277184986},"subject":"trade.l2update","topic":"/market/level2:BCHSV-USDT","type":"message"}
1619378340.0236201: {"data":{"sequenceStart":1613277184987,"symbol":"BCHSV-USDT","changes":{"asks":[["243.035","1","1613277184987"]],"bids":[]},"sequenceEnd":1613277184987},"subject":"trade.l2update","topic":"/market/level2:BCHSV-USDT","type":"message"}
1619378340.068815: {"data":{"sequence":"1613277184987","bestAsk":"243.035","size":"0.14324938","bestBidSize":"0.45082023","price":"242.781","time":1619378340032,"bestAskSize":"1","bestBid":"242.635"},"subject":"trade.ticker","topic":"/market/ticker:BCHSV-USDT","type":"message"}
1619378340.073493: {"data":{"sequenceStart":1613277184988,"symbol":"BCHSV-USDT","changes":{"asks":[],"bids":[["0","0","1613277184988"]]},"sequenceEnd":1613277184988},"subject":"trade.l2update","topic":"/market/level2:BCHSV-USDT","type":"message"}
1619378340.073605: {"data":{"sequenceStart":1613277184989,"symbol":"BCHSV-USDT","changes":{"asks":[],"bids":[["242.635","20.17782023","1613277184989"]]},"sequenceEnd":1613277184989},"subject":"trade.l2update","topic":"/market/level2:BCHSV-USDT","type":"message"}
1619378340.166357: {"data":{"sequence":"1613277184989","bestAsk":"243.035","size":"0.14324938","bestBidSize":"20.17782023","price":"242.781","time":1619378340132,"bestAskSize":"1","bestBid":"242.635"},"subject":"trade.ticker","topic":"/market/ticker:BCHSV-USDT","type":"message"}
1619378340.224252: {"data":{"sequenceStart":1613277184990,"symbol":"BCHSV-USDT","changes":{"asks":[],"bids":[["242.579","0","1613277184990"]]},"sequenceEnd":1613277184990},"subject":"trade.l2update","topic":"/market/level2:BCHSV-USDT","type":"message"}
1619378340.24875: {"data":{"sequenceStart":1613277184991,"symbol":"BCHSV-USDT","changes":{"asks":[["0","0","1613277184991"]],"bids":[]},"sequenceEnd":1613277184991},"subject":"trade.l2update","topic":"/market/level2:BCHSV-USDT","type":"message"}
1619378340.248862: {"data":{"sequenceStart":1613277184992,"symbol":"BCHSV-USDT","changes":{"asks":[["243.04","4.51280965","1613277184992"]],"bids":[]},"sequenceEnd":1613277184992},"subject":"trade.l2update","topic":"/market/level2:BCHSV-USDT","type":"message"}
1619378340.2576299: {"data":{"sequenceStart":1613277184993,"symbol":"BCHSV-USDT","changes":{"asks":[],"bids":[["0","0","1613277184993"]]},"sequenceEnd":1613277184993},"subject":"trade.l2update","topic":"/market/level2:BCHSV-USDT","type":"message"}
1619378340.2577422: {"data":{"sequenceStart":1613277184994,"symbol":"BCHSV-USDT","changes":{"asks":[],"bids":[["242.719","4.51280965","1613277184994"]]},"sequenceEnd":1613277184994},"subject":"trade.l2update","topic":"/market/level2:BCHSV-USDT","type":"message"}
1619378340.2734668: {"data":{"sequence":"1613277184994","bestAsk":"243.035","size":"0.14324938","bestBidSize":"4.51280965","price":"242.781","time":1619378340233,"bestAskSize":"1","bestBid":"242.719"},"subject":"trade.ticker","topic":"/market/ticker:BCHSV-USDT","type":"message"}
1619378340.302495: {"data":{"sequenceStart":1613277184995,"symbol":"BCHSV-USDT","changes":{"asks":[],"bids":[["0","0","1613277184995"]]},"sequenceEnd":1613277184995},"subject":"trade.l2update","topic":"/market/level2:BCHSV-USDT","type":"message"}
1619378340.302606: {"data":{"sequenceStart":1613277184996,"symbol":"BCHSV-USDT","changes":{"asks":[],"bids":[["242.637","5","1613277184996"]]},"sequenceEnd":1613277184996},"subject":"trade.l2update","topic":"/market/level2:BCHSV-USDT","type":"message"}
1619378340.3026829: {"data":{"sequenceStart":1613277184997,"symbol":"BCHSV-USDT","changes":{"asks":[["243.035","0","1613277184997"]],"bids":[]},"sequenceEnd":1613277184997},"subject":"trade.l2update","topic":"/market/level2:BCHSV-USDT","type":"message"}
1619378340.329937: {"data":{"sequenceStart":1613277184998,"symbol":"BCHSV-USDT","changes":{"asks":[["0","0","1613277184998"]],"bids":[]},"sequenceEnd":1613277184998},"subject":"trade.l2update","topic":"/market/level2:BCHSV-USDT","type":"message"}
1619378340.330046: {"data":{"sequenceStart":1613277184999,"symbol":"BCHSV-USDT","changes":{"asks":[["242.96","0.6","1613277184999"]],"bids":[]},"sequenceEnd":1613277184999},"subject":"trade.l2update","topic":"/market/level2:BCHSV-USDT","type":"message"}
1619378340.355802: {"data":{"sequenceStart":1613277185000,"symbol":"BCHSV-USDT","changes":{"asks":[["0","0","1613277185000"]],"bids":[]},"sequenceEnd":1613277185000},"subject":"trade.l2update","topic":"/market/level2:BCHSV-USDT","type":"message"}
1619378340.355912: {"data":{"sequenceStart":1613277185001,"symbol":"BCHSV-USDT","changes":{"asks":[["242.958","0.6","1613277185001"]],"bids":[]},"sequenceEnd":1613277185001},"subject":"trade.l2update","topic":"/market/level2:BCHSV-USDT","type":"message"}
1619378340.367569: {"data":{"sequence":"1613277185001","bestAsk":"242.958","size":"0.14324938","bestBidSize":"4.51280965","price":"242.781","time":1619378340332,"bestAskSize":"0.6","bestBid":"242.719"},"subject":"trade.ticker","topic":"/market/ticker:BCHSV-USDT","type":"message"}
1619378340.443158: {"data":{"sequenceStart":1613277185002,"symbol":"BCHSV-USDT","changes":{"asks":[["242.958","0","1613277185002"]],"bids":[]},"sequenceEnd":1613277185002},"subject":"trade.l2update","topic":"/market/level2:BCHSV-USDT","type":"message"}
1619378340.443296: {"data":{"sequenceStart":1613277185003,"symbol":"BCHSV-USDT","changes":{"asks":[["242.96","0","1613277185003"]],"bids":[]},"sequenceEnd":1613277185003},"subject":"trade.l2update","topic":"/market/level2:BCHSV-USDT","type":"message"}
1619378340.448498: {"data":{"sequenceStart":1612712745712,"symbol":"FET-BTC","changes":{"asks":[["0","0","1612712745712"]],"bids":[]},"sequenceEnd":1612712745712},"subject":"trade.l2update","topic":"/market/level2:FET-BTC","type":"message"}
1619378340.448596: {"data":{"sequenceStart":1612712745713,"symbol":"FET-BTC","changes":{"asks":[["0.00000793","3343.2272","1612712745713"]],"bids":[]},"sequenceEnd":1612712745713},"subject":"trade.l2update","topic":"/market/level2:FET-BTC","type":"message"}
1619378340.4532712: {"data":{"sequenceStart":1613277185004,"symbol":"BCHSV-USDT","changes":{"asks":[],"bids":[["0","0","1613277185004"]]},"sequenceEnd":1613277185004},"subject":"trade.l2update","topic":"/market/level2:BCHSV-USDT","type":"message"}
1619378340.453326: {"data":{"sequenceStart":1613277185005,"symbol":"BCHSV-USDT","changes":{"asks":[],"bids":[["242.716","0.68148185","1613277185005"]]},"sequenceEnd":1613277185005},"subject":"trade.l2update","topic":"/market/level2:BCHSV-USDT","type":"message"}
1619378340.453373: {"data":{"sequenceStart":1613277185006,"symbol":"BCHSV-USDT","changes":{"asks":[["0","0","1613277185006"]],"bids":[]},"sequenceEnd":1613277185006},"subject":"trade.l2update","topic":"/market/level2:BCHSV-USDT","type":"message"}
1619378340.4534001: {"data":{"sequenceStart":1613277185007,"symbol":"BCHSV-USDT","changes":{"asks":[["243.289","0.6","1613277185007"]],"bids":[]},"sequenceEnd":1613277185007},"subject":"trade.l2update","topic":"/market/level2:BCHSV-USDT","type":"message"}
1619378340.472757: {"data":{"sequenceStart":1613277185008,"symbol":"BCHSV-USDT","changes":{"asks":[["0","0","1613277185008"]],"bids":[]},"sequenceEnd":1613277185008},"subject":"trade.l2update","topic":"/market/level2:BCHSV-USDT","type":"message"}
1619378340.4728441: {"data":{"sequenceStart":1613277185009,"symbol":"BCHSV-USDT","changes":{"asks":[["244.367","150","1613277185009"]],"bids":[]},"sequenceEnd":1613277185009},"subject":"trade.l2update","topic":"/market/level2:BCHSV-USDT","type":"message"}
1619378340.4729202: {"data":{"sequenceStart":1613277185010,"symbol":"BCHSV-USDT","changes":{"asks":[],"bids":[["0","0","1613277185010"]]},"sequenceEnd":1613277185010},"subject":"trade.l2update","topic":"/market/level2:BCHSV-USDT","type":"message"}
1619378340.472963: {"data":{"sequenceStart":1613277185011,"symbol":"BCHSV-USDT","changes":{"asks":[],"bids":[["241.569","5","1613277185011"]]},"sequenceEnd":1613277185011},"subject":"trade.l2update","topic":"/market/level2:BCHSV-USDT","type":"message"}
1619378340.473032: {"data":{"sequenceStart":1613277185012,"symbol":"BCHSV-USDT","changes":{"asks":[["0","0","1613277185012"]],"bids":[]},"sequenceEnd":1613277185012},"subject":"trade.l2update","topic":"/market/level2:BCHSV-USDT","type":"message"}
1619378340.473055: {"data":{"sequenceStart":1613277185013,"symbol":"BCHSV-USDT","changes":{"asks":[["243.73","5","1613277185013"]],"bids":[]},"sequenceEnd":1613277185013},"subject":"trade.l2update","topic":"/market/level2:BCHSV-USDT","type":"message"}
1619378340.4730828: {"data":{"sequenceStart":1613277185014,"symbol":"BCHSV-USDT","changes":{"asks":[],"bids":[["242.637","0","1613277185014"]]},"sequenceEnd":1613277185014},"subject":"trade.l2update","topic":"/market/level2:BCHSV-USDT","type":"message"}
1619378340.473118: {"data":{"sequence":"1613277185008","bestAsk":"243.036","size":"0.14324938","bestBidSize":"4.51280965","price":"242.781","time":1619378340432,"bestAskSize":"9.62448872","bestBid":"242.719"},"subject":"trade.ticker","topic":"/market/ticker:BCHSV-USDT","type":"message"}
1619378340.48749: {"data":{"sequenceStart":1613277185015,"symbol":"BCHSV-USDT","changes":{"asks":[],"bids":[["241.77","0","1613277185015"]]},"sequenceEnd":1613277185015},"subject":"trade.l2update","topic":"/market/level2:BCHSV-USDT","type":"message"}
1619378340.4876318: {"data":{"sequenceStart":1613277185016,"symbol":"BCHSV-USDT","changes":{"asks":[],"bids":[["0","0","1613277185016"]]},"sequenceEnd":1613277185016},"subject":"trade.l2update","topic":"/market/level2:BCHSV-USDT","type":"message"}
1619378340.487686: {"data":{"sequenceStart":1613277185017,"symbol":"BCHSV-USDT","changes":{"asks":[],"bids":[["240.935","150","1613277185017"]]},"sequenceEnd":1613277185017},"subject":"trade.l2update","topic":"/market/level2:BCHSV-USDT","type":"message"}
1619378340.506776: {"data":{"sequence":"1612712745713","bestAsk":"0.00000776","size":"12.2091","bestBidSize":"1250.285","price":"0.00000776","time":1619378340467,"bestAskSize":"1141.8325","bestBid":"0.00000771"},"subject":"trade.ticker","topic":"/market/ticker:FET-BTC","type":"message"}
1619378340.512255: {"data":{"sequenceStart":1613277185018,"symbol":"BCHSV-USDT","changes":{"asks":[],"bids":[["0","0","1613277185018"]]},"sequenceEnd":1613277185018},"subject":"trade.l2update","topic":"/market/level2:BCHSV-USDT","type":"message"}
1619378340.5123682: {"data":{"sequenceStart":1613277185019,"symbol":"BCHSV-USDT","changes":{"asks":[],"bids":[["241.162","4.12141694","1613277185019"]]},"sequenceEnd":1613277185019},"subject":"trade.l2update","topic":"/market/level2:BCHSV-USDT","type":"message"}
1619378340.5421581: {"data":{"sequenceStart":1612694580183,"symbol":"CAPP-BTC","changes":{"asks":[["0","0","1612694580183"]],"bids":[]},"sequenceEnd":1612694580183},"subject":"trade.l2update","topic":"/market/level2:CAPP-BTC","type":"message"}
1619378340.5422652: {"data":{"sequenceStart":1612694580184,"symbol":"CAPP-BTC","changes":{"asks":[["0.0000002196","4490.25","1612694580184"]],"bids":[]},"sequenceEnd":1612694580184},"subject":"trade.l2update","topic":"/market/level2:CAPP-BTC","type":"message"}
1619378340.557066: {"data":{"sequenceStart":1612712745714,"symbol":"FET-BTC","changes":{"asks":[],"bids":[["0","0","1612712745714"]]},"sequenceEnd":1612712745714},"subject":"trade.l2update","topic":"/market/level2:FET-BTC","type":"message"}
1619378340.557175: {"data":{"sequenceStart":1612712745715,"symbol":"FET-BTC","changes":{"asks":[],"bids":[["0.00000764","278.7348","1612712745715"]]},"sequenceEnd":1612712745715},"subject":"trade.l2update","topic":"/market/level2:FET-BTC","type":"message"}
1619378340.5635798: {"data":{"sequence":"1613277185019","bestAsk":"243.036","size":"0.14324938","bestBidSize":"4.51280965","price":"242.781","time":1619378340530,"bestAskSize":"9.62448872","bestBid":"242.719"},"subject":"trade.ticker","topic":"/market/ticker:BCHSV-USDT","type":"message"}
1619378340.608824: {"data":{"sequence":"1612712745715","bestAsk":"0.00000776","size":"12.2091","bestBidSize":"1250.285","price":"0.00000776","time":1619378340567,"bestAskSize":"1141.8325","bestBid":"0.00000771"},"subject":"trade.ticker","topic":"/market/ticker:FET-BTC","type":"message"}
1619378340.625699: {"data":{"sequence":"1612694580184","bestAsk":"0.0000002196","size":"1000.02","bestBidSize":"83.07","price":"0.0000002182","time":1619378340581,"bestAskSize":"4490.25","bestBid":"0.0000002181"},"subject":"trade.ticker","topic":"/market/ticker:CAPP-BTC","type":"message"}
1619378340.625788: {"data":{"sequenceStart":1613277185020,"symbol":"BCHSV-USDT","changes":{"asks":[["243.289","0","1613277185020"]],"bids":[]},"sequenceEnd":1613277185020},"subject":"trade.l2update","topic":"/market/level2:BCHSV-USDT","type":"message"}
1619378340.634832: {"data":{"sequenceStart":1613277185021,"symbol":"BCHSV-USDT","changes":{"asks":[],"bids":[["242.716","0","1613277185021"]]},"sequenceEnd":1613277185021},"subject":"trade.l2update","topic":"/market/level2:BCHSV-USDT","type":"message"}
1619378340.669259: {"data":{"sequenceStart":1613277185022,"symbol":"BCHSV-USDT","changes":{"asks":[["0","0","1613277185022"]],"bids":[]},"sequenceEnd":1613277185022},"subject":"trade.l2update","topic":"/market/level2:BCHSV-USDT","type":"message"}
1619378340.6693702: {"data":{"sequenceStart":1613277185023,"symbol":"BCHSV-USDT","changes":{"asks":[["242.957","0.6","1613277185023"]],"bids":[]},"sequenceEnd":1613277185023},"subject":"trade.l2update","topic":"/market/level2:BCHSV-USDT","type":"message"}
1619378340.6694531: {"data":{"sequenceStart":1613277185024,"symbol":"BCHSV-USDT","changes":{"asks":[["0","0","1613277185024"]],"bids":[]},"sequenceEnd":1613277185024},"subject":"trade.l2update","topic":"/market/level2:BCHSV-USDT","type":"message"}
1619378340.669496: {"data":{"sequenceStart":1613277185025,"symbol":"BCHSV-USDT","changes":{"asks":[["245.648","17.79999999","1613277185025"]],"bids":[]},"sequenceEnd":1613277185025},"subject":"trade.l2update","topic":"/market/level2:BCHSV-USDT","type":"message"}
1619378340.669548: {"data":{"sequence":"1613277185025","bestAsk":"242.957","size":"0.14324938","bestBidSize":"4.51280965","price":"242.781","time":1619378340633,"bestAskSize":"0.6","bestBid":"242.719"},"subject":"trade.ticker","topic":"/market/ticker:BCHSV-USDT","type":"message"}
1619378340.678124: {"data":{"sequenceStart":1613277185026,"symbol":"BCHSV-USDT","changes":{"asks":[],"bids":[["242.109","0","1613277185026"]]},"sequenceEnd":1613277185026},"subject":"trade.l2update","topic":"/market/level2:BCHSV-USDT","type":"message"}
1619378340.771405: {"data":{"sequence":"1613277185026","bestAsk":"242.957","size":"0.14324938","bestBidSize":"4.51280965","price":"242.781","time":1619378340732,"bestAskSize":"0.6","bestBid":"242.719"},"subject":"trade.ticker","topic":"/market/ticker:BCHSV-USDT","type":"message"}
1619378340.794667: {"data":{"sequenceStart":1613277185027,"symbol":"BCHSV-USDT","changes":{"asks":[],"bids":[["0","0","1613277185027"]]},"sequenceEnd":1613277185027},"subject":"trade.l2update","topic":"/market/level2:BCHSV-USDT","type":"message"}
1619378340.794775: {"data":{"sequenceStart":1613277185028,"symbol":"BCHSV-USDT","changes":{"asks":[],"bids":[["242.715","5","1613277185028"]]},"sequenceEnd":1613277185028},"subject":"trade.l2update","topic":"/market/level2:BCHSV-USDT","type":"message"}
1619378340.803212: {"data":{"sequenceStart":1613277185029,"symbol":"BCHSV-USDT","changes":{"asks":[],"bids":[["240.772","0","1613277185029"]]},"sequenceEnd":1613277185029},"subject":"trade.l2update","topic":"/market/level2:BCHSV-USDT","type":"message"}
1619378340.822659: {"data":{"sequenceStart":1613277185030,"symbol":"BCHSV-USDT","changes":{"asks":[["242.957","0","1613277185030"]],"bids":[]},"sequenceEnd":1613277185030},"subject":"trade.l2update","topic":"/market/level2:BCHSV-USDT","type":"message"}
1619378340.85076: {"data":{"sequenceStart":1613277185031,"symbol":"BCHSV-USDT","changes":{"asks":[],"bids":[["0","0","1613277185031"]]},"sequenceEnd":1613277185031},"subject":"trade.l2update","topic":"/market/level2:BCHSV-USDT","type":"message"}
1619378340.8508868: {"data":{"sequenceStart":1613277185032,"symbol":"BCHSV-USDT","changes":{"asks":[],"bids":[["241.654","7.20964831","1613277185032"]]},"sequenceEnd":1613277185032},"subject":"trade.l2update","topic":"/market/level2:BCHSV-USDT","type":"message"}
1619378340.850943: {"data":{"sequenceStart":1613277185033,"symbol":"BCHSV-USDT","changes":{"asks":[],"bids":[["0","0","1613277185033"]]},"sequenceEnd":1613277185033},"subject":"trade.l2update","topic":"/market/level2:BCHSV-USDT","type":"message"}
1619378340.85097: {"data":{"sequenceStart":1613277185034,"symbol":"BCHSV-USDT","changes":{"asks":[],"bids":[["242.715","5.68148185","1613277185034"]]},"sequenceEnd":1613277185034},"subject":"trade.l2update","topic":"/market/level2:BCHSV-USDT","type":"message"}
1619378340.851001: {"data":{"sequenceStart":1613277185035,"symbol":"BCHSV-USDT","changes":{"asks":[["0","0","1613277185035"]],"bids":[]},"sequenceEnd":1613277185035},"subject":"trade.l2update","topic":"/market/level2:BCHSV-USDT","type":"message"}
1619378340.851024: {"data":{"sequenceStart":1613277185036,"symbol":"BCHSV-USDT","changes":{"asks":[["243.289","0.6","1613277185036"]],"bids":[]},"sequenceEnd":1613277185036},"subject":"trade.l2update","topic":"/market/level2:BCHSV-USDT","type":"message"}
1619378340.858697: {"data":{"sequenceStart":1613277185037,"symbol":"BCHSV-USDT","changes":{"asks":[["243.73","0","1613277185037"]],"bids":[]},"sequenceEnd":1613277185037},"subject":"trade.l2update","topic":"/market/level2:BCHSV-USDT","type":"message"}
1619378340.858839: {"data":{"sequenceStart":1613277185038,"symbol":"BCHSV-USDT","changes":{"asks":[],"bids":[["241.569","0","1613277185038"]]},"sequenceEnd":1613277185038},"subject":"trade.l2update","topic":"/market/level2:BCHSV-USDT","type":"message"}
1619378340.868646: {"data":{"sequenceStart":1612694580185,"symbol":"CAPP-BTC","changes":{"asks":[["0","0","1612694580185"]],"bids":[]},"sequenceEnd":1612694580185},"subject":"trade.l2update","topic":"/market/level2:CAPP-BTC","type":"message"}
1619378340.8687592: {"data":{"sequenceStart":1612694580186,"symbol":"CAPP-BTC","changes":{"asks":[["0.0000002497","22424.96","1612694580186"]],"bids":[]},"sequenceEnd":1612694580186},"subject":"trade.l2update","topic":"/market/level2:CAPP-BTC","type":"message"}
1619378340.868845: {"data":{"sequence":"1613277185041","bestAsk":"243.036","size":"0.14324938","bestBidSize":"4.51280965","price":"242.781","time":1619378340832,"bestAskSize":"9.62448872","bestBid":"242.719"},"subject":"trade.ticker","topic":"/market/ticker:BCHSV-USDT","type":"message"}
1619378340.8689349: {"data":{"sequenceStart":1613277185039,"symbol":"BCHSV-USDT","changes":{"asks":[],"bids":[["242.715","0.68148185","1613277185039"]]},"sequenceEnd":1613277185039},"subject":"trade.l2update","topic":"/market/level2:BCHSV-USDT","type":"message"}
1619378340.868971: {"data":{"sequenceStart":1613277185040,"symbol":"BCHSV-USDT","changes":{"asks":[],"bids":[["240.935","0","1613277185040"]]},"sequenceEnd":1613277185040},"subject":"trade.l2update","topic":"/market/level2:BCHSV-USDT","type":"message"}
1619378340.8690119: {"data":{"sequenceStart":1613277185041,"symbol":"BCHSV-USDT","changes":{"asks":[["244.367","0","1613277185041"]],"bids":[]},"sequenceEnd":1613277185041},"subject":"trade.l2update","topic":"/market/level2:BCHSV-USDT","type":"message"}
1619378340.883212: {"data":{"sequenceStart":1612694580187,"symbol":"CAPP-BTC","changes":{"asks":[["0","0","1612694580187"]],"bids":[]},"sequenceEnd":1612694580187},"subject":"trade.l2update","topic":"/market/level2:CAPP-BTC","type":"message"}
1619378340.883322: {"data":{"sequenceStart":1612694580188,"symbol":"CAPP-BTC","changes":{"asks":[["0.0000002195","270.17","1612694580188"]],"bids":[]},"sequenceEnd":1612694580188},"subject":"trade.l2update","topic":"/market/level2:CAPP-BTC","type":"message"}
1619378340.9222772: {"data":{"sequence":"1612694580188","bestAsk":"0.0000002195","size":"1000.02","bestBidSize":"83.07","price":"0.0000002182","time":1619378340881,"bestAskSize":"270.17","bestBid":"0.0000002181"},"subject":"trade.ticker","topic":"/market/ticker:CAPP-BTC","type":"message"}
1619378341.0167801: {"data":{"symbol":"FET-BTC","candles":["1619378280","0.00000776","0.00000776","0.00000776","0.00000776","12.2091","0.000094742616"],"time":1619378340978811189},"subject":"trade.candles.add","topic":"/market/candles:FET-BTC_1min","type":"message"}
1619378341.0287318: {"data":{"sequenceStart":1613277185042,"symbol":"BCHSV-USDT","changes":{"asks":[["243.289","0","1613277185042"]],"bids":[]},"sequenceEnd":1613277185042},"subject":"trade.l2update","topic":"/market/level2:BCHSV-USDT","type":"message"}
1619378341.0372689: {"data":{"sequenceStart":1613277185043,"symbol":"BCHSV-USDT","changes":{"asks":[],"bids":[["242.715","0","1613277185043"]]},"sequenceEnd":1613277185043},"subject":"trade.l2update","topic":"/market/level2:BCHSV-USDT","type":"message"}
1619378341.0547352: {"data":{"sequenceStart":1613277185044,"symbol":"BCHSV-USDT","changes":{"asks":[["0","0","1613277185044"]],"bids":[]},"sequenceEnd":1613277185044},"subject":"trade.l2update","topic":"/market/level2:BCHSV-USDT","type":"message"}
1619378341.054847: {"data":{"sequenceStart":1613277185045,"symbol":"BCHSV-USDT","changes":{"asks":[["243.3","0.6","1613277185045"]],"bids":[]},"sequenceEnd":1613277185045},"subject":"trade.l2update","topic":"/market/level2:BCHSV-USDT","type":"message"}
1619378341.068844: {"data":{"sequence":"1613277185045","bestAsk":"243.036","size":"0.14324938","bestBidSize":"4.51280965","price":"242.781","time":1619378341033,"bestAskSize":"9.62448872","bestBid":"242.719"},"subject":"trade.ticker","topic":"/market/ticker:BCHSV-USDT","type":"message"}
1619378341.083905: {"data":{"sequenceStart":1613277185046,"symbol":"BCHSV-USDT","changes":{"asks":[],"bids":[["241.602","0","1613277185046"]]},"sequenceEnd":1613277185046},"subject":"trade.l2update","topic":"/market/level2:BCHSV-USDT","type":"message"}
1619378341.117075: {"data":{"sequenceStart":1612844051988,"symbol":"SNX-BTC","changes":{"asks":[["0","0","1612844051988"]],"bids":[]},"sequenceEnd":1612844051988},"subject":"trade.l2update","topic":"/market/level2:SNX-BTC","type":"message"}
1619378341.117187: {"data":{"sequenceStart":1612844051989,"symbol":"SNX-BTC","changes":{"asks":[["0.000291","100.19091256","1612844051989"]],"bids":[]},"sequenceEnd":1612844051989},"subject":"trade.l2update","topic":"/market/level2:SNX-BTC","type":"message"}
1619378341.158601: {"data":{"sequence":"1612844051989","bestAsk":"0.00028711","size":"0.01745248","bestBidSize":"0.19100065","price":"0.00028676","time":1619378341123,"bestAskSize":"29.24570683","bestBid":"0.00028678"},"subject":"trade.ticker","topic":"/market/ticker:SNX-BTC","type":"message"}
1619378341.166965: {"data":{"sequence":"1613277185047","bestAsk":"243.036","size":"0.14324938","bestBidSize":"4.51280965","price":"242.781","time":1619378341132,"bestAskSize":"9.62448872","bestBid":"242.719"},"subject":"trade.ticker","topic":"/market/ticker:BCHSV-USDT","type":"message"}
1619378341.17457: {"data":{"sequenceStart":1613277185047,"symbol":"BCHSV-USDT","changes":{"asks":[["245.648","0","1613277185047"]],"bids":[]},"sequenceEnd":1613277185047},"subject":"trade.l2update","topic":"/market/level2:BCHSV-USDT","type":"message"}
1619378341.2042072: {"data":{"sequenceStart":1612712745716,"symbol":"FET-BTC","changes":{"asks":[["0.00000781","0","1612712745716"]],"bids":[]},"sequenceEnd":1612712745716},"subject":"trade.l2update","topic":"/market/level2:FET-BTC","type":"message"}
1619378341.20912: {"data":{"sequence":"1612712745716","bestAsk":"0.00000776","size":"12.2091","bestBidSize":"1250.285","price":"0.00000776","time":1619378341167,"bestAskSize":"1141.8325","bestBid":"0.00000771"},"subject":"trade.ticker","topic":"/market/ticker:FET-BTC","type":"message"}
1619378341.240722: {"data":{"sequenceStart":1613277185048,"symbol":"BCHSV-USDT","changes":{"asks":[["243.3","0","1613277185048"]],"bids":[]},"sequenceEnd":1613277185048},"subject":"trade.l2update","topic":"/market/level2:BCHSV-USDT","type":"message"}
1619378341.2656069: {"data":{"sequenceStart":1613277185049,"symbol":"BCHSV-USDT","changes":{"asks":[["0","0","1613277185049"]],"bids":[]},"sequenceEnd":1613277185049},"subject":"trade.l2update","topic":"/market/level2:BCHSV-USDT","type":"message"}
1619378341.265715: {"data":{"sequenceStart":1613277185050,"symbol":"BCHSV-USDT","changes":{"asks":[["243.298","0.6","1613277185050"]],"bids":[]},"sequenceEnd":1613277185050},"subject":"trade.l2update","topic":"/market/level2:BCHSV-USDT","type":"message"}
1619378341.270977: {"data":{"sequence":"1613277185050","bestAsk":"243.036","size":"0.14324938","bestBidSize":"4.51280965","price":"242.781","time":1619378341232,"bestAskSize":"9.62448872","bestBid":"242.719"},"subject":"trade.ticker","topic":"/market/ticker:BCHSV-USDT","type":"message"}
1619378341.280784: {"data":{"sequenceStart":1612694580189,"symbol":"CAPP-BTC","changes":{"asks":[["0.0000002196","330.25","1612694580189"]],"bids":[]},"sequenceEnd":1612694580189},"subject":"trade.l2update","topic":"/market/level2:CAPP-BTC","type":"message"}
1619378341.291389: {"data":{"sequenceStart":1612712745717,"symbol":"FET-BTC","changes":{"asks":[],"bids":[["0","0","1612712745717"]]},"sequenceEnd":1612712745717},"subject":"trade.l2update","topic":"/market/level2:FET-BTC","type":"message"}
1619378341.291497: {"data":{"sequenceStart":1612712745718,"symbol":"FET-BTC","changes":{"asks":[],"bids":[["0.00000761","1274.9105","1612712745718"]]},"sequenceEnd":1612712745718},"subject":"trade.l2update","topic":"/market/level2:FET-BTC","type":"message"}
1619378341.29618: {"data":{"sequenceStart":1612712745719,"symbol":"FET-BTC","changes":{"asks":[],"bids":[["0.00000771","1099.8694","1612712745719"]]},"sequenceEnd":1612712745719},"subject":"trade.l2update","topic":"/market/level2:FET-BTC","type":"message"}
1619378341.300597: {"data":{"sequenceStart":1612844051990,"symbol":"SNX-BTC","changes":{"asks":[["0.00029399","0","1612844051990"]],"bids":[]},"sequenceEnd":1612844051990},"subject":"trade.l2update","topic":"/market/level2:SNX-BTC","type":"message"}
1619378341.305027: {"data":{"sequence":"1612712745719","bestAsk":"0.00000776","size":"12.2091","bestBidSize":"1099.8694","price":"0.00000776","time":1619378341267,"bestAskSize":"1141.8325","bestBid":"0.00000771"},"subject":"trade.ticker","topic":"/market/ticker:FET-BTC","type":"message"}
1619378341.319072: {"data":{"sequence":"1612694580189","bestAsk":"0.0000002195","size":"1000.02","bestBidSize":"83.07","price":"0.0000002182","time":1619378341281,"bestAskSize":"270.17","bestBid":"0.0000002181"},"subject":"trade.ticker","topic":"/market/ticker:CAPP-BTC","type":"message"}
1619378341.338839: {"data":{"sequenceStart":1612712745720,"symbol":"FET-BTC","changes":{"asks":[],"bids":[["0.00000764","208.7648","1612712745720"]]},"sequenceEnd":1612712745720},"subject":"trade.l2update","topic":"/market/level2:FET-BTC","type":"message"}
1619378341.360214: {"data":{"sequence":"1612844051990","bestAsk":"0.00028711","size":"0.01745248","bestBidSize":"0.19100065","price":"0.00028676","time":1619378341323,"bestAskSize":"29.24570683","bestBid":"0.00028678"},"subject":"trade.ticker","topic":"/market/ticker:SNX-BTC","type":"message"}
1619378341.3937001: {"data":{"sequenceStart":1612734157875,"symbol":"ANKR-BTC","changes":{"asks":[],"bids":[["0.0000025365","21922.0053","1612734157875"]]},"sequenceEnd":1612734157875},"subject":"trade.l2update","topic":"/market/level2:ANKR-BTC","type":"message"}
1619378341.403997: {"data":{"sequence":"1612712745720","bestAsk":"0.00000776","size":"12.2091","bestBidSize":"1099.8694","price":"0.00000776","time":1619378341367,"bestAskSize":"1141.8325","bestBid":"0.00000771"},"subject":"trade.ticker","topic":"/market/ticker:FET-BTC","type":"message"}
1619378341.412832: {"data":{"sequenceStart":1613277185051,"symbol":"BCHSV-USDT","changes":{"asks":[["244.792","0","1613277185051"]],"bids":[]},"sequenceEnd":1613277185051},"subject":"trade.l2update","topic":"/market/level2:BCHSV-USDT","type":"message"}
1619378341.41293: {"data":{"sequenceStart":1613277185052,"symbol":"BCHSV-USDT","changes":{"asks":[["243.04","0","1613277185052"]],"bids":[]},"sequenceEnd":1613277185052},"subject":"trade.l2update","topic":"/market/level2:BCHSV-USDT","type":"message"}
1619378341.422661: {"data":{"sequence":"1612734157875","bestAsk":"0.0000026208","size":"46","bestBidSize":"5034.7285","price":"0.0000026071","time":1619378341388,"bestAskSize":"10987.6265","bestBid":"0.0000026001"},"subject":"trade.ticker","topic":"/market/ticker:ANKR-BTC","type":"message"}
1619378341.4337559: {"data":{"sequenceStart":1613277185053,"symbol":"BCHSV-USDT","changes":{"asks":[["243.298","0","1613277185053"]],"bids":[]},"sequenceEnd":1613277185053},"subject":"trade.l2update","topic":"/market/level2:BCHSV-USDT","type":"message"}
1619378341.441355: {"data":{"sequenceStart":1613277185054,"symbol":"BCHSV-USDT","changes":{"asks":[],"bids":[["0","0","1613277185054"]]},"sequenceEnd":1613277185054},"subject":"trade.l2update","topic":"/market/level2:BCHSV-USDT","type":"message"}
1619378341.441466: {"data":{"sequenceStart":1613277185055,"symbol":"BCHSV-USDT","changes":{"asks":[],"bids":[["241.713","8.5825042","1613277185055"]]},"sequenceEnd":1613277185055},"subject":"trade.l2update","topic":"/market/level2:BCHSV-USDT","type":"message"}
1619378341.441547: {"data":{"sequenceStart":1613277185056,"symbol":"BCHSV-USDT","changes":{"asks":[["0","0","1613277185056"]],"bids":[]},"sequenceEnd":1613277185056},"subject":"trade.l2update","topic":"/market/level2:BCHSV-USDT","type":"message"}
1619378341.441591: {"data":{"sequenceStart":1613277185057,"symbol":"BCHSV-USDT","changes":{"asks":[["243.306","0.6","1613277185057"]],"bids":[]},"sequenceEnd":1613277185057},"subject":"trade.l2update","topic":"/market/level2:BCHSV-USDT","type":"message"}
1619378341.4648361: {"data":{"sequence":"1613277185065","bestAsk":"243.036","size":"0.14324938","bestBidSize":"4.51280965","price":"242.781","time":1619378341430,"bestAskSize":"9.62448872","bestBid":"242.719"},"subject":"trade.ticker","topic":"/market/ticker:BCHSV-USDT","type":"message"}
1619378341.486784: {"data":{"sequenceStart":1613277185058,"symbol":"BCHSV-USDT","changes":{"asks":[["0","0","1613277185058"]],"bids":[]},"sequenceEnd":1613277185058},"subject":"trade.l2update","topic":"/market/level2:BCHSV-USDT","type":"message"}
1619378341.4868941: {"data":{"sequenceStart":1613277185059,"symbol":"BCHSV-USDT","changes":{"asks":[["243.76","5","1613277185059"]],"bids":[]},"sequenceEnd":1613277185059},"subject":"trade.l2update","topic":"/market/level2:BCHSV-USDT","type":"message"}
1619378341.486978: {"data":{"sequenceStart":1613277185060,"symbol":"BCHSV-USDT","changes":{"asks":[],"bids":[["0","0","1613277185060"]]},"sequenceEnd":1613277185060},"subject":"trade.l2update","topic":"/market/level2:BCHSV-USDT","type":"message"}
1619378341.487023: {"data":{"sequenceStart":1613277185061,"symbol":"BCHSV-USDT","changes":{"asks":[],"bids":[["241.598","5","1613277185061"]]},"sequenceEnd":1613277185061},"subject":"trade.l2update","topic":"/market/level2:BCHSV-USDT","type":"message"}
1619378341.487076: {"data":{"sequenceStart":1613277185062,"symbol":"BCHSV-USDT","changes":{"asks":[["0","0","1613277185062"]],"bids":[]},"sequenceEnd":1613277185062},"subject":"trade.l2update","topic":"/market/level2:BCHSV-USDT","type":"message"}
1619378341.4871192: {"data":{"sequenceStart":1613277185063,"symbol":"BCHSV-USDT","changes":{"asks":[["244.397","150","1613277185063"]],"bids":[]},"sequenceEnd":1613277185063},"subject":"trade.l2update","topic":"/market/level2:BCHSV-USDT","type":"message"}
1619378341.48718: {"data":{"sequenceStart":1613277185064,"symbol":"BCHSV-USDT","changes":{"asks":[],"bids":[["0","0","1613277185064"]]},"sequenceEnd":1613277185064},"subject":"trade.l2update","topic":"/market/level2:BCHSV-USDT","type":"message"}
1619378341.487202: {"data":{"sequenceStart":1613277185065,"symbol":"BCHSV-USDT","changes":{"asks":[],"bids":[["242.716","52.488","1613277185065"]]},"sequenceEnd":1613277185065},"subject":"trade.l2update","topic":"/market/level2:BCHSV-USDT","type":"message"}
1619378341.496632: {"data":{"sequenceStart":1613277185066,"symbol":"BCHSV-USDT","changes":{"asks":[],"bids":[["0","0","1613277185066"]]},"sequenceEnd":1613277185066},"subject":"trade.l2update","topic":"/market/level2:BCHSV-USDT","type":"message"}
1619378341.4967449: {"data":{"sequenceStart":1613277185067,"symbol":"BCHSV-USDT","changes":{"asks":[],"bids":[["240.965","150","1613277185067"]]},"sequenceEnd":1613277185067},"subject":"trade.l2update","topic":"/market/level2:BCHSV-USDT","type":"message"}
1619378341.514956: {"data":{"sequenceStart":1613277185068,"symbol":"BCHSV-USDT","changes":{"asks":[["0","0","1613277185068"]],"bids":[]},"sequenceEnd":1613277185068},"subject":"trade.l2update","topic":"/market/level2:BCHSV-USDT","type":"message"}
1619378341.515063: {"data":{"sequenceStart":1613277185069,"symbol":"BCHSV-USDT","changes":{"asks":[["245.074","25","1613277185069"]],"bids":[]},"sequenceEnd":1613277185069},"subject":"trade.l2update","topic":"/market/level2:BCHSV-USDT","type":"message"}
1619378341.526745: {"data":{"sequenceStart":1612734157876,"symbol":"ANKR-BTC","changes":{"asks":[],"bids":[["0","0","1612734157876"]]},"sequenceEnd":1612734157876},"subject":"trade.l2update","topic":"/market/level2:ANKR-BTC","type":"message"}
1619378341.526853: {"data":{"sequenceStart":1613277185070,"symbol":"BCHSV-USDT","changes":{"asks":[["243.306","0","1613277185070"]],"bids":[]},"sequenceEnd":1613277185070},"subject":"trade.l2update","topic":"/market/level2:BCHSV-USDT","type":"message"}
1619378341.531355: {"data":{"sequenceStart":1612734157877,"symbol":"ANKR-BTC","changes":{"asks":[],"bids":[["0.0000026002","3496.1094","1612734157877"]]},"sequenceEnd":1612734157877},"subject":"trade.l2update","topic":"/market/level2:ANKR-BTC","type":"message"}
1619378341.53149: {"data":{"sequenceStart":1612694580190,"symbol":"CAPP-BTC","changes":{"asks":[],"bids":[["0.0000001872","0","1612694580190"]]},"sequenceEnd":1612694580190},"subject":"trade.l2update","topic":"/market/level2:CAPP-BTC","type":"message"}
1619378341.537774: {"data":{"sequenceStart":1613277185071,"symbol":"BCHSV-USDT","changes":{"asks":[["0","0","1613277185071"]],"bids":[]},"sequenceEnd":1613277185071},"subject":"trade.l2update","topic":"/market/level2:BCHSV-USDT","type":"message"}
1619378341.5378802: {"data":{"sequenceStart":1613277185072,"symbol":"BCHSV-USDT","changes":{"asks":[["243.305","0.6","1613277185072"]],"bids":[]},"sequenceEnd":1613277185072},"subject":"trade.l2update","topic":"/market/level2:BCHSV-USDT","type":"message"}
1619378341.552073: {"data":{"sequenceStart":1613277185073,"symbol":"BCHSV-USDT","changes":{"asks":[],"bids":[["0","0","1613277185073"]]},"sequenceEnd":1613277185073},"subject":"trade.l2update","topic":"/market/level2:BCHSV-USDT","type":"message"}
1619378341.552178: {"data":{"sequenceStart":1613277185074,"symbol":"BCHSV-USDT","changes":{"asks":[],"bids":[["241.77","9.9995565","1613277185074"]]},"sequenceEnd":1613277185074},"subject":"trade.l2update","topic":"/market/level2:BCHSV-USDT","type":"message"}
1619378341.563894: {"data":{"sequenceStart":1612734157878,"symbol":"ANKR-BTC","changes":{"asks":[],"bids":[["0.0000026001","0","1612734157878"]]},"sequenceEnd":1612734157878},"subject":"trade.l2update","topic":"/market/level2:ANKR-BTC","type":"message"}
1619378341.564033: {"data":{"sequence":"1613277185074","bestAsk":"243.036","size":"0.14324938","bestBidSize":"4.51280965","price":"242.781","time":1619378341530,"bestAskSize":"9.62448872","bestBid":"242.719"},"subject":"trade.ticker","topic":"/market/ticker:BCHSV-USDT","type":"message"}
1619378341.591639: {"data":{"sequenceStart":1612734157879,"symbol":"ANKR-BTC","changes":{"asks":[],"bids":[["0","0","1612734157879"]]},"sequenceEnd":1612734157879},"subject":"trade.l2update","topic":"/market/level2:ANKR-BTC","type":"message"}
1619378341.591748: {"data":{"sequenceStart":1612734157880,"symbol":"ANKR-BTC","changes":{"asks":[],"bids":[["0.0000026003","5032.6841","1612734157880"]]},"sequenceEnd":1612734157880},"subject":"trade.l2update","topic":"/market/level2:ANKR-BTC","type":"message"}
1619378341.624487: {"data":{"sequence":"1612694580190","bestAsk":"0.0000002195","size":"1000.02","bestBidSize":"83.07","price":"0.0000002182","time":1619378341581,"bestAskSize":"270.17","bestBid":"0.0000002181"},"subject":"trade.ticker","topic":"/market/ticker:CAPP-BTC","type":"message"}
1619378341.624578: {"data":{"sequence":"1612734157880","bestAsk":"0.0000026208","size":"46","bestBidSize":"5032.6841","price":"0.0000026071","time":1619378341588,"bestAskSize":"10987.6265","bestBid":"0.0000026003"},"subject":"trade.ticker","topic":"/market/ticker:ANKR-BTC","type":"message"}
1619378341.7268639: {"data":{"sequenceStart":1613277185075,"symbol":"BCHSV-USDT","changes":{"asks":[["243.305","0","1613277185075"]],"bids":[]},"sequenceEnd":1613277185075},"subject":"trade.l2update","topic":"/market/level2:BCHSV-USDT","type":"message"}
1619378341.747363: {"data":{"sequenceStart":1613277185076,"symbol":"BCHSV-USDT","changes":{"asks":[["0","0","1613277185076"]],"bids":[]},"sequenceEnd":1613277185076},"subject":"trade.l2update","topic":"/market/level2:BCHSV-USDT","type":"message"}
1619378341.747492: {"data":{"sequenceStart":1613277185077,"symbol":"BCHSV-USDT","changes":{"asks":[["243.303","0.6","1613277185077"]],"bids":[]},"sequenceEnd":1613277185077},"subject":"trade.l2update","topic":"/market/level2:BCHSV-USDT","type":"message"}
1619378341.747576: {"data":{"sequenceStart":1613277185078,"symbol":"BCHSV-USDT","changes":{"asks":[],"bids":[["242.719","0","1613277185078"]]},"sequenceEnd":1613277185078},"subject":"trade.l2update","topic":"/market/level2:BCHSV-USDT","type":"message"}
1619378341.7696698: {"data":{"sequence":"1613277185078","bestAsk":"243.036","size":"0.14324938","bestBidSize":"52.488","price":"242.781","time":1619378341730,"bestAskSize":"9.62448872","bestBid":"242.716"},"subject":"trade.ticker","topic":"/market/ticker:BCHSV-USDT","type":"message"}
1619378341.7964082: {"data":{"sequenceStart":1612712745721,"symbol":"FET-BTC","changes":{"asks":[["0","0","1612712745721"]],"bids":[]},"sequenceEnd":1612712745721},"subject":"trade.l2update","topic":"/market/level2:FET-BTC","type":"message"}
1619378341.7965162: {"data":{"sequenceStart":1612712745722,"symbol":"FET-BTC","changes":{"asks":[["0.0000078","1514.0642","1612712745722"]],"bids":[]},"sequenceEnd":1612712745722},"subject":"trade.l2update","topic":"/market/level2:FET-BTC","type":"message"}
1619378341.806047: {"data":{"sequence":"1612712745722","bestAsk":"0.00000776","size":"12.2091","bestBidSize":"1099.8694","price":"0.00000776","time":1619378341768,"bestAskSize":"1141.8325","bestBid":"0.00000771"},"subject":"trade.ticker","topic":"/market/ticker:FET-BTC","type":"message"}
1619378341.8427489: {"data":{"sequenceStart":1613277185079,"symbol":"BCHSV-USDT","changes":{"asks":[],"bids":[["0","0","1613277185079"]]},"sequenceEnd":1613277185079},"subject":"trade.l2update","topic":"/market/level2:BCHSV-USDT","type":"message"}
1619378341.842859: {"data":{"sequenceStart":1613277185080,"symbol":"BCHSV-USDT","changes":{"asks":[],"bids":[["242.716","72.215","1613277185080"]]},"sequenceEnd":1613277185080},"subject":"trade.l2update","topic":"/market/level2:BCHSV-USDT","type":"message"}
1619378341.863297: {"data":{"sequenceStart":1613277185081,"symbol":"BCHSV-USDT","changes":{"asks":[["243.76","0","1613277185081"]],"bids":[]},"sequenceEnd":1613277185081},"subject":"trade.l2update","topic":"/market/level2:BCHSV-USDT","type":"message"}
1619378341.8634381: {"data":{"sequenceStart":1613277185082,"symbol":"BCHSV-USDT","changes":{"asks":[],"bids":[["241.598","0","1613277185082"]]},"sequenceEnd":1613277185082},"subject":"trade.l2update","topic":"/market/level2:BCHSV-USDT","type":"message"}
1619378341.863511: {"data":{"sequenceStart":1613277185083,"symbol":"BCHSV-USDT","changes":{"asks":[["244.397","0","1613277185083"]],"bids":[]},"sequenceEnd":1613277185083},"subject":"trade.l2update","topic":"/market/level2:BCHSV-USDT","type":"message"}
1619378341.8635688: {"data":{"sequenceStart":1613277185084,"symbol":"BCHSV-USDT","changes":{"asks":[],"bids":[["240.965","0","1613277185084"]]},"sequenceEnd":1613277185084},"subject":"trade.l2update","topic":"/market/level2:BCHSV-USDT","type":"message"}
1619378341.867659: {"data":{"sequenceStart":1612702190350,"symbol":"NRG-BTC","changes":{"asks":[],"bids":[["0.00006141","0","1612702190350"]]},"sequenceEnd":1612702190350},"subject":"trade.l2update","topic":"/market/level2:NRG-BTC","type":"message"}
1619378341.873305: {"data":{"sequence":"1613277185084","bestAsk":"243.036","size":"0.14324938","bestBidSize":"72.215","price":"242.781","time":1619378341832,"bestAskSize":"9.62448872","bestBid":"242.716"},"subject":"trade.ticker","topic":"/market/ticker:BCHSV-USDT","type":"message"}
1619378341.906361: {"data":{"sequenceStart":1612702190351,"symbol":"NRG-BTC","changes":{"asks":[],"bids":[["0.00006073","0","1612702190351"]]},"sequenceEnd":1612702190351},"subject":"trade.l2update","topic":"/market/level2:NRG-BTC","type":"message"}
1619378341.906444: {"data":{"sequenceStart":1613277185085,"symbol":"BCHSV-USDT","changes":{"asks":[],"bids":[["242.716","52.488","1613277185085"]]},"sequenceEnd":1613277185085},"subject":"trade.l2update","topic":"/market/level2:BCHSV-USDT","type":"message"}
1619378341.929059: {"data":{"sequenceStart":1613277185086,"symbol":"BCHSV-USDT","changes":{"asks":[["243.303","0","1613277185086"]],"bids":[]},"sequenceEnd":1613277185086},"subject":"trade.l2update","topic":"/market/level2:BCHSV-USDT","type":"message"}
1619378341.9326599: {"data":{"sequence":"1612702190351","bestAsk":"0.00006218","size":"0.0431","bestBidSize":"18.897","price":"0.00006141","time":1619378341891,"bestAskSize":"43.3399","bestBid":"0.0000614"},"subject":"trade.ticker","topic":"/market/ticker:NRG-BTC","type":"message"}
1619378341.9366121: {"data":{"sequenceStart":1612699351279,"symbol":"COV-BTC","changes":{"asks":[],"bids":[["0","0","1612699351279"]]},"sequenceEnd":1612699351279},"subject":"trade.l2update","topic":"/market/level2:COV-BTC","type":"message"}
1619378341.936718: {"data":{"sequenceStart":1612699351280,"symbol":"COV-BTC","changes":{"asks":[],"bids":[["0.00001093","188.4121","1612699351280"]]},"sequenceEnd":1612699351280},"subject":"trade.l2update","topic":"/market/level2:COV-BTC","type":"message"}
1619378341.941361: {"data":{"sequenceStart":1613277185087,"symbol":"BCHSV-USDT","changes":{"asks":[["0","0","1613277185087"]],"bids":[]},"sequenceEnd":1613277185087},"subject":"trade.l2update","topic":"/market/level2:BCHSV-USDT","type":"message"}
1619378341.9414752: {"data":{"sequenceStart":1613277185088,"symbol":"BCHSV-USDT","changes":{"asks":[["243.3","0.6","1613277185088"]],"bids":[]},"sequenceEnd":1613277185088},"subject":"trade.l2update","topic":"/market/level2:BCHSV-USDT","type":"message"}
1619378341.967969: {"data":{"sequenceStart":1612734157881,"symbol":"ANKR-BTC","changes":{"asks":[],"bids":[["0","0","1612734157881"]]},"sequenceEnd":1612734157881},"subject":"trade.l2update","topic":"/market/level2:ANKR-BTC","type":"message"}
1619378341.968032: {"data":{"sequenceStart":1612734157882,"symbol":"ANKR-BTC","changes":{"asks":[],"bids":[["0.000002535","97.4321","1612734157882"]]},"sequenceEnd":1612734157882},"subject":"trade.l2update","topic":"/market/level2:ANKR-BTC","type":"message"}
1619378341.968075: {"data":{"sequence":"1613277185088","bestAsk":"243.036","size":"0.14324938","bestBidSize":"52.488","price":"242.781","time":1619378341932,"bestAskSize":"9.62448872","bestBid":"242.716"},"subject":"trade.ticker","topic":"/market/ticker:BCHSV-USDT","type":"message"}
1619378342.020981: {"data":{"sequence":"1612734157882","bestAsk":"0.0000026208","size":"46","bestBidSize":"5032.6841","price":"0.0000026071","time":1619378341988,"bestAskSize":"10987.6265","bestBid":"0.0000026003"},"subject":"trade.ticker","topic":"/market/ticker:ANKR-BTC","type":"message"}
1619378342.027742: {"data":{"sequence":"1612699351280","bestAsk":"0.00001127","size":"96.1525","bestBidSize":"49.6422","price":"0.00001126","time":1619378341988,"bestAskSize":"4469.58576035","bestBid":"0.00001121"},"subject":"trade.ticker","topic":"/market/ticker:COV-BTC","type":"message"}
1619378342.027854: {"data":{"sequenceStart":1613277185089,"symbol":"BCHSV-USDT","changes":{"asks":[["243.3","0","1613277185089"]],"bids":[]},"sequenceEnd":1613277185089},"subject":"trade.l2update","topic":"/market/level2:BCHSV-USDT","type":"message"}
1619378342.053201: {"data":{"sequenceStart":1613277185090,"symbol":"BCHSV-USDT","changes":{"asks":[["0","0","1613277185090"]],"bids":[]},"sequenceEnd":1613277185090},"subject":"trade.l2update","topic":"/market/level2:BCHSV-USDT","type":"message"}
1619378342.053316: {"data":{"sequenceStart":1613277185091,"symbol":"BCHSV-USDT","changes":{"asks":[["243.299","0.6","1613277185091"]],"bids":[]},"sequenceEnd":1613277185091},"subject":"trade.l2update","topic":"/market/level2:BCHSV-USDT","type":"message"}
1619378342.0665832: {"data":{"sequence":"1613277185091","bestAsk":"243.036","size":"0.14324938","bestBidSize":"52.488","price":"242.781","time":1619378342030,"bestAskSize":"9.62448872","bestBid":"242.716"},"subject":"trade.ticker","topic":"/market/ticker:BCHSV-USDT","type":"message"}
1619378342.2023969: {"data":{"sequenceStart":1613277185092,"symbol":"BCHSV-USDT","changes":{"asks":[],"bids":[["242.716","0","1613277185092"]]},"sequenceEnd":1613277185092},"subject":"trade.l2update","topic":"/market/level2:BCHSV-USDT","type":"message"}
1619378342.23261: {"data":{"sequenceStart":1613277185093,"symbol":"BCHSV-USDT","changes":{"asks":[["243.299","0","1613277185093"]],"bids":[]},"sequenceEnd":1613277185093},"subject":"trade.l2update","topic":"/market/level2:BCHSV-USDT","type":"message"}
1619378342.232752: {"data":{"sequenceStart":1612844051991,"symbol":"SNX-BTC","changes":{"asks":[],"bids":[["0.0002866","0","1612844051991"]]},"sequenceEnd":1612844051991},"subject":"trade.l2update","topic":"/market/level2:SNX-BTC","type":"message"}
1619378342.242631: {"data":{"sequenceStart":1613277185094,"symbol":"BCHSV-USDT","changes":{"asks":[],"bids":[["0","0","1613277185094"]]},"sequenceEnd":1613277185094},"subject":"trade.l2update","topic":"/market/level2:BCHSV-USDT","type":"message"}
1619378342.24274: {"data":{"sequenceStart":1613277185095,"symbol":"BCHSV-USDT","changes":{"asks":[],"bids":[["242.636","3.91470595","1613277185095"]]},"sequenceEnd":1613277185095},"subject":"trade.l2update","topic":"/market/level2:BCHSV-USDT","type":"message"}
1619378342.248076: {"data":{"sequenceStart":1613277185096,"symbol":"BCHSV-USDT","changes":{"asks":[["0","0","1613277185096"]],"bids":[]},"sequenceEnd":1613277185096},"subject":"trade.l2update","topic":"/market/level2:BCHSV-USDT","type":"message"}
1619378342.248189: {"data":{"sequenceStart":1613277185097,"symbol":"BCHSV-USDT","changes":{"asks":[["242.99","4.51280965","1613277185097"]],"bids":[]},"sequenceEnd":1613277185097},"subject":"trade.l2update","topic":"/market/level2:BCHSV-USDT","type":"message"}
1619378342.2482681: {"data":{"sequenceStart":1613277185098,"symbol":"BCHSV-USDT","changes":{"asks":[],"bids":[["0","0","1613277185098"]]},"sequenceEnd":1613277185098},"subject":"trade.l2update","topic":"/market/level2:BCHSV-USDT","type":"message"}
1619378342.253824: {"data":{"sequenceStart":1619079123954,"symbol":"EQZ-BTC","changes":{"asks":[],"bids":[["0.00002332","0","1619079123954"]]},"sequenceEnd":1619079123954},"subject":"trade.l2update","topic":"/market/level2:EQZ-BTC","type":"message"}
1619378342.253962: {"data":{"sequenceStart":1613277185099,"symbol":"BCHSV-USDT","changes":{"asks":[],"bids":[["242.729","4.51280965","1613277185099"]]},"sequenceEnd":1613277185099},"subject":"trade.l2update","topic":"/market/level2:BCHSV-USDT","type":"message"}
1619378342.2603: {"data":{"sequenceStart":1613277185100,"symbol":"BCHSV-USDT","changes":{"asks":[],"bids":[["241.77","0","1613277185100"]]},"sequenceEnd":1613277185100},"subject":"trade.l2update","topic":"/market/level2:BCHSV-USDT","type":"message"}
1619378342.27157: {"data":{"sequenceStart":1612844051992,"symbol":"SNX-BTC","changes":{"asks":[["0","0","1612844051992"]],"bids":[]},"sequenceEnd":1612844051992},"subject":"trade.l2update","topic":"/market/level2:SNX-BTC","type":"message"}
1619378342.271679: {"data":{"sequenceStart":1612844051993,"symbol":"SNX-BTC","changes":{"asks":[["0.0002871","14.04126604","1612844051993"]],"bids":[]},"sequenceEnd":1612844051993},"subject":"trade.l2update","topic":"/market/level2:SNX-BTC","type":"message"}
1619378342.271761: {"data":{"sequence":"1613277185100","bestAsk":"242.99","size":"0.14324938","bestBidSize":"4.51280965","price":"242.781","time":1619378342232,"bestAskSize":"4.51280965","bestBid":"242.729"},"subject":"trade.ticker","topic":"/market/ticker:BCHSV-USDT","type":"message"}
1619378342.2838132: {"data":{"sequence":"1619079123954","bestAsk":"0.00002395","size":"0.375","bestBidSize":"20.5373","price":"0.00002383","time":1619378342238,"bestAskSize":"72.1515","bestBid":"0.00002383"},"subject":"trade.ticker","topic":"/market/ticker:EQZ-BTC","type":"message"}
1619378342.283902: {"data":{"sequence":"1612844051993","bestAsk":"0.0002871","size":"0.01745248","bestBidSize":"0.19100065","price":"0.00028676","time":1619378342248,"bestAskSize":"14.04126604","bestBid":"0.00028678"},"subject":"trade.ticker","topic":"/market/ticker:SNX-BTC","type":"message"}
1619378342.295846: {"data":{"sequenceStart":1612844051994,"symbol":"SNX-BTC","changes":{"asks":[],"bids":[["0","0","1612844051994"]]},"sequenceEnd":1612844051994},"subject":"trade.l2update","topic":"/market/level2:SNX-BTC","type":"message"}
1619378342.295954: {"data":{"sequenceStart":1612844051995,"symbol":"SNX-BTC","changes":{"asks":[],"bids":[["0.00028659","14.06802286","1612844051995"]]},"sequenceEnd":1612844051995},"subject":"trade.l2update","topic":"/market/level2:SNX-BTC","type":"message"}
1619378342.296034: {"data":{"sequenceStart":1613277185101,"symbol":"BCHSV-USDT","changes":{"asks":[],"bids":[["242.636","0","1613277185101"]]},"sequenceEnd":1613277185101},"subject":"trade.l2update","topic":"/market/level2:BCHSV-USDT","type":"message"}
1619378342.296103: {"data":{"sequenceStart":1613277185102,"symbol":"BCHSV-USDT","changes":{"asks":[],"bids":[["0","0","1613277185102"]]},"sequenceEnd":1613277185102},"subject":"trade.l2update","topic":"/market/level2:BCHSV-USDT","type":"message"}
1619378342.296151: {"data":{"sequenceStart":1613277185103,"symbol":"BCHSV-USDT","changes":{"asks":[],"bids":[["240.337","2.08041207","1613277185103"]]},"sequenceEnd":1613277185103},"subject":"trade.l2update","topic":"/market/level2:BCHSV-USDT","type":"message"}
1619378342.305233: {"data":{"sequenceStart":1612844051996,"symbol":"SNX-BTC","changes":{"asks":[],"bids":[["0","0","1612844051996"]]},"sequenceEnd":1612844051996},"subject":"trade.l2update","topic":"/market/level2:SNX-BTC","type":"message"}
1619378342.3053389: {"data":{"sequenceStart":1612844051997,"symbol":"SNX-BTC","changes":{"asks":[],"bids":[["0.00028616","14.12188243","1612844051997"]]},"sequenceEnd":1612844051997},"subject":"trade.l2update","topic":"/market/level2:SNX-BTC","type":"message"}
1619378342.314019: {"data":{"sequenceStart":1612699351281,"symbol":"COV-BTC","changes":{"asks":[],"bids":[["0.00001095","10","1612699351281"]]},"sequenceEnd":1612699351281},"subject":"trade.l2update","topic":"/market/level2:COV-BTC","type":"message"}
1619378342.318826: {"data":{"sequenceStart":1612712745723,"symbol":"FET-BTC","changes":{"asks":[],"bids":[["0.00000771","206.8694","1612712745723"]]},"sequenceEnd":1612712745723},"subject":"trade.l2update","topic":"/market/level2:FET-BTC","type":"message"}
1619378342.3235352: {"data":{"sequence":"1612699351281","bestAsk":"0.00001127","size":"96.1525","bestBidSize":"49.6422","price":"0.00001126","time":1619378342288,"bestAskSize":"4469.58576035","bestBid":"0.00001121"},"subject":"trade.ticker","topic":"/market/ticker:COV-BTC","type":"message"}
1619378342.3382242: {"data":{"sequenceStart":1612844051998,"symbol":"SNX-BTC","changes":{"asks":[],"bids":[["0","0","1612844051998"]]},"sequenceEnd":1612844051998},"subject":"trade.l2update","topic":"/market/level2:SNX-BTC","type":"message"}
1619378342.3383071: {"data":{"sequenceStart":1612844051999,"symbol":"SNX-BTC","changes":{"asks":[],"bids":[["0.00028611","35.16341646","1612844051999"]]},"sequenceEnd":1612844051999},"subject":"trade.l2update","topic":"/market/level2:SNX-BTC","type":"message"}
1619378342.344139: {"data":{"sequenceStart":1613277185104,"symbol":"BCHSV-USDT","changes":{"asks":[],"bids":[["242.635","19.727","1613277185104"]]},"sequenceEnd":1613277185104},"subject":"trade.l2update","topic":"/market/level2:BCHSV-USDT","type":"message"}
1619378342.344225: {"data":{"sequenceStart":1613277185105,"symbol":"BCHSV-USDT","changes":{"asks":[],"bids":[["0","0","1613277185105"]]},"sequenceEnd":1613277185105},"subject":"trade.l2update","topic":"/market/level2:BCHSV-USDT","type":"message"}
1619378342.344258: {"data":{"sequenceStart":1613277185106,"symbol":"BCHSV-USDT","changes":{"asks":[],"bids":[["242.695","0.68148185","1613277185106"]]},"sequenceEnd":1613277185106},"subject":"trade.l2update","topic":"/market/level2:BCHSV-USDT","type":"message"}
1619378342.3443: {"data":{"sequenceStart":1613277185107,"symbol":"BCHSV-USDT","changes":{"asks":[["0","0","1613277185107"]],"bids":[]},"sequenceEnd":1613277185107},"subject":"trade.l2update","topic":"/market/level2:BCHSV-USDT","type":"message"}
1619378342.349691: {"data":{"sequenceStart":1613277185108,"symbol":"BCHSV-USDT","changes":{"asks":[["243.296","0.6","1613277185108"]],"bids":[]},"sequenceEnd":1613277185108},"subject":"trade.l2update","topic":"/market/level2:BCHSV-USDT","type":"message"}
1619378342.3588321: {"data":{"sequence":"1612844051999","bestAsk":"0.0002871","size":"0.01745248","bestBidSize":"0.19100065","price":"0.00028676","time":1619378342323,"bestAskSize":"14.04126604","bestBid":"0.00028678"},"subject":"trade.ticker","topic":"/market/ticker:SNX-BTC","type":"message"}
1619378342.369204: {"data":{"sequenceStart":1612844052000,"symbol":"SNX-BTC","changes":{"asks":[["0.0002871","0","1612844052000"]],"bids":[]},"sequenceEnd":1612844052000},"subject":"trade.l2update","topic":"/market/level2:SNX-BTC","type":"message"}
1619378342.3693461: {"data":{"sequence":"1613277185108","bestAsk":"242.99","size":"0.14324938","bestBidSize":"4.51280965","price":"242.781","time":1619378342333,"bestAskSize":"4.51280965","bestBid":"242.729"},"subject":"trade.ticker","topic":"/market/ticker:BCHSV-USDT","type":"message"}
1619378342.377655: {"data":{"sequenceStart":1612844052001,"symbol":"SNX-BTC","changes":{"asks":[],"bids":[["0.0002861","0","1612844052001"]]},"sequenceEnd":1612844052001},"subject":"trade.l2update","topic":"/market/level2:SNX-BTC","type":"message"}
1619378342.382741: {"data":{"sequenceStart":1613277185109,"symbol":"BCHSV-USDT","changes":{"asks":[],"bids":[["242.729","0","1613277185109"]]},"sequenceEnd":1613277185109},"subject":"trade.l2update","topic":"/market/level2:BCHSV-USDT","type":"message"}
1619378342.3828852: {"data":{"sequenceStart":1613277185110,"symbol":"BCHSV-USDT","changes":{"asks":[],"bids":[["0","0","1613277185110"]]},"sequenceEnd":1613277185110},"subject":"trade.l2update","topic":"/market/level2:BCHSV-USDT","type":"message"}
1619378342.3829389: {"data":{"sequenceStart":1613277185111,"symbol":"BCHSV-USDT","changes":{"asks":[],"bids":[["242.697","5","1613277185111"]]},"sequenceEnd":1613277185111},"subject":"trade.l2update","topic":"/market/level2:BCHSV-USDT","type":"message"}
1619378342.400683: {"data":{"sequenceStart":1612844052002,"symbol":"SNX-BTC","changes":{"asks":[],"bids":[["0.00028616","0","1612844052002"]]},"sequenceEnd":1612844052002},"subject":"trade.l2update","topic":"/market/level2:SNX-BTC","type":"message"}
1619378342.4114811: {"data":{"sequence":"1612712745723","bestAsk":"0.00000776","size":"12.2091","bestBidSize":"206.8694","price":"0.00000776","time":1619378342369,"bestAskSize":"1141.8325","bestBid":"0.00000771"},"subject":"trade.ticker","topic":"/market/ticker:FET-BTC","type":"message"}
1619378342.416415: {"data":{"sequenceStart":1612844052003,"symbol":"SNX-BTC","changes":{"asks":[["0","0","1612844052003"]],"bids":[]},"sequenceEnd":1612844052003},"subject":"trade.l2update","topic":"/market/level2:SNX-BTC","type":"message"}
1619378342.416523: {"data":{"sequenceStart":1612844052004,"symbol":"SNX-BTC","changes":{"asks":[["0.0002871","14.04127562","1612844052004"]],"bids":[]},"sequenceEnd":1612844052004},"subject":"trade.l2update","topic":"/market/level2:SNX-BTC","type":"message"}
1619378342.44274: {"data":{"sequenceStart":1613277185112,"symbol":"BCHSV-USDT","changes":{"asks":[],"bids":[["0","0","1613277185112"]]},"sequenceEnd":1613277185112},"subject":"trade.l2update","topic":"/market/level2:BCHSV-USDT","type":"message"}
1619378342.442849: {"data":{"sequenceStart":1613277185113,"symbol":"BCHSV-USDT","changes":{"asks":[],"bids":[["242.639","0.45082023","1613277185113"]]},"sequenceEnd":1613277185113},"subject":"trade.l2update","topic":"/market/level2:BCHSV-USDT","type":"message"}
1619378342.4516978: {"data":{"sequenceStart":1612844052005,"symbol":"SNX-BTC","changes":{"asks":[["0.0002871","0","1612844052005"]],"bids":[]},"sequenceEnd":1612844052005},"subject":"trade.l2update","topic":"/market/level2:SNX-BTC","type":"message"}
1619378342.4578428: {"data":{"sequenceStart":1613277185114,"symbol":"BCHSV-USDT","changes":{"asks":[],"bids":[["242.639","0","1613277185114"]]},"sequenceEnd":1613277185114},"subject":"trade.l2update","topic":"/market/level2:BCHSV-USDT","type":"message"}
1619378342.46348: {"data":{"sequence":"1612844052005","bestAsk":"0.00028711","size":"0.01745248","bestBidSize":"0.19100065","price":"0.00028676","time":1619378342423,"bestAskSize":"29.24570683","bestBid":"0.00028678"},"subject":"trade.ticker","topic":"/market/ticker:SNX-BTC","type":"message"}
1619378342.473878: {"data":{"sequence":"1613277185120","bestAsk":"242.99","size":"0.14324938","bestBidSize":"5","price":"242.781","time":1619378342433,"bestAskSize":"4.51280965","bestBid":"242.697"},"subject":"trade.ticker","topic":"/market/ticker:BCHSV-USDT","type":"message"}
1619378342.473967: {"data":{"sequenceStart":1612712745724,"symbol":"FET-BTC","changes":{"asks":[],"bids":[["0","0","1612712745724"]]},"sequenceEnd":1612712745724},"subject":"trade.l2update","topic":"/market/level2:FET-BTC","type":"message"}
1619378342.4740329: {"data":{"sequenceStart":1613277185115,"symbol":"BCHSV-USDT","changes":{"asks":[["0","0","1613277185115"]],"bids":[]},"sequenceEnd":1613277185115},"subject":"trade.l2update","topic":"/market/level2:BCHSV-USDT","type":"message"}
1619378342.474101: {"data":{"sequenceStart":1613277185116,"symbol":"BCHSV-USDT","changes":{"asks":[["243.775","5","1613277185116"]],"bids":[]},"sequenceEnd":1613277185116},"subject":"trade.l2update","topic":"/market/level2:BCHSV-USDT","type":"message"}
1619378342.474145: {"data":{"sequenceStart":1613277185117,"symbol":"BCHSV-USDT","changes":{"asks":[],"bids":[["0","0","1613277185117"]]},"sequenceEnd":1613277185117},"subject":"trade.l2update","topic":"/market/level2:BCHSV-USDT","type":"message"}
1619378342.474168: {"data":{"sequenceStart":1613277185118,"symbol":"BCHSV-USDT","changes":{"asks":[],"bids":[["241.614","5","1613277185118"]]},"sequenceEnd":1613277185118},"subject":"trade.l2update","topic":"/market/level2:BCHSV-USDT","type":"message"}
1619378342.474199: {"data":{"sequenceStart":1613277185119,"symbol":"BCHSV-USDT","changes":{"asks":[["0","0","1613277185119"]],"bids":[]},"sequenceEnd":1613277185119},"subject":"trade.l2update","topic":"/market/level2:BCHSV-USDT","type":"message"}
1619378342.474221: {"data":{"sequenceStart":1613277185120,"symbol":"BCHSV-USDT","changes":{"asks":[["244.413","150","1613277185120"]],"bids":[]},"sequenceEnd":1613277185120},"subject":"trade.l2update","topic":"/market/level2:BCHSV-USDT","type":"message"}
1619378342.474249: {"data":{"sequenceStart":1612712745725,"symbol":"FET-BTC","changes":{"asks":[],"bids":[["0.00000771","357.2953","1612712745725"]]},"sequenceEnd":1612712745725},"subject":"trade.l2update","topic":"/market/level2:FET-BTC","type":"message"}
1619378342.503683: {"data":{"sequenceStart":1613277185121,"symbol":"BCHSV-USDT","changes":{"asks":[],"bids":[["0","0","1613277185121"]]},"sequenceEnd":1613277185121},"subject":"trade.l2update","topic":"/market/level2:BCHSV-USDT","type":"message"}
1619378342.50381: {"data":{"sequenceStart":1613277185122,"symbol":"BCHSV-USDT","changes":{"asks":[],"bids":[["240.98","150","1613277185122"]]},"sequenceEnd":1613277185122},"subject":"trade.l2update","topic":"/market/level2:BCHSV-USDT","type":"message"}
1619378342.503891: {"data":{"sequenceStart":1613277185123,"symbol":"BCHSV-USDT","changes":{"asks":[["242.99","0","1613277185123"]],"bids":[]},"sequenceEnd":1613277185123},"subject":"trade.l2update","topic":"/market/level2:BCHSV-USDT","type":"message"}
1619378342.503959: {"data":{"sequenceStart":1612701563997,"symbol":"DAPPT-BTC","changes":{"asks":[],"bids":[["0.000000112","0","1612701563997"]]},"sequenceEnd":1612701563997},"subject":"trade.l2update","topic":"/market/level2:DAPPT-BTC","type":"message"}
1619378342.50945: {"data":{"sequenceStart":1612734157883,"symbol":"ANKR-BTC","changes":{"asks":[],"bids":[["0.0000026002","0","1612734157883"]]},"sequenceEnd":1612734157883},"subject":"trade.l2update","topic":"/market/level2:ANKR-BTC","type":"message"}
1619378342.50959: {"data":{"sequence":"1612712745725","bestAsk":"0.00000776","size":"12.2091","bestBidSize":"357.2953","price":"0.00000776","time":1619378342469,"bestAskSize":"1141.8325","bestBid":"0.00000771"},"subject":"trade.ticker","topic":"/market/ticker:FET-BTC","type":"message"}
1619378342.5231528: {"data":{"sequenceStart":1612844052006,"symbol":"SNX-BTC","changes":{"asks":[],"bids":[["0.00028659","0","1612844052006"]]},"sequenceEnd":1612844052006},"subject":"trade.l2update","topic":"/market/level2:SNX-BTC","type":"message"}
1619378342.528918: {"data":{"sequence":"1612734157883","bestAsk":"0.0000026208","size":"46","bestBidSize":"5032.6841","price":"0.0000026071","time":1619378342488,"bestAskSize":"10987.6265","bestBid":"0.0000026003"},"subject":"trade.ticker","topic":"/market/ticker:ANKR-BTC","type":"message"}
1619378342.5362718: {"data":{"sequenceStart":1612844052007,"symbol":"SNX-BTC","changes":{"asks":[["0","0","1612844052007"]],"bids":[]},"sequenceEnd":1612844052007},"subject":"trade.l2update","topic":"/market/level2:SNX-BTC","type":"message"}
1619378342.536381: {"data":{"sequenceStart":1612844052008,"symbol":"SNX-BTC","changes":{"asks":[["0.00028711","43.28403854","1612844052008"]],"bids":[]},"sequenceEnd":1612844052008},"subject":"trade.l2update","topic":"/market/level2:SNX-BTC","type":"message"}
1619378342.536447: {"data":{"sequenceStart":1613277185124,"symbol":"BCHSV-USDT","changes":{"asks":[["243.296","0","1613277185124"]],"bids":[]},"sequenceEnd":1613277185124},"subject":"trade.l2update","topic":"/market/level2:BCHSV-USDT","type":"message"}
1619378342.55455: {"data":{"sequenceStart":1613277185125,"symbol":"BCHSV-USDT","changes":{"asks":[],"bids":[["242.695","0","1613277185125"]]},"sequenceEnd":1613277185125},"subject":"trade.l2update","topic":"/market/level2:BCHSV-USDT","type":"message"}
1619378342.554688: {"data":{"sequenceStart":1613277185126,"symbol":"BCHSV-USDT","changes":{"asks":[["0","0","1613277185126"]],"bids":[]},"sequenceEnd":1613277185126},"subject":"trade.l2update","topic":"/market/level2:BCHSV-USDT","type":"message"}
1619378342.554741: {"data":{"sequenceStart":1613277185127,"symbol":"BCHSV-USDT","changes":{"asks":[["243.301","0.6","1613277185127"]],"bids":[]},"sequenceEnd":1613277185127},"subject":"trade.l2update","topic":"/market/level2:BCHSV-USDT","type":"message"}
1619378342.568438: {"data":{"sequence":"1612701563997","bestAsk":"0.000000113","size":"145.4959","bestBidSize":"361.2609","price":"0.0000001126","time":1619378342530,"bestAskSize":"1208.0878","bestBid":"0.0000001119"},"subject":"trade.ticker","topic":"/market/ticker:DAPPT-BTC","type":"message"}
1619378342.573798: {"data":{"sequence":"1613277185127","bestAsk":"243.036","size":"0.14324938","bestBidSize":"5","price":"242.781","time":1619378342533,"bestAskSize":"9.62448872","bestBid":"242.697"},"subject":"trade.ticker","topic":"/market/ticker:BCHSV-USDT","type":"message"}
1619378342.577735: {"data":{"sequenceStart":1613277185128,"symbol":"BCHSV-USDT","changes":{"asks":[],"bids":[["242.697","0","1613277185128"]]},"sequenceEnd":1613277185128},"subject":"trade.l2update","topic":"/market/level2:BCHSV-USDT","type":"message"}
1619378342.577874: {"data":{"sequenceStart":1612844052009,"symbol":"SNX-BTC","changes":{"asks":[],"bids":[["0","0","1612844052009"]]},"sequenceEnd":1612844052009},"subject":"trade.l2update","topic":"/market/level2:SNX-BTC","type":"message"}
1619378342.577929: {"data":{"sequenceStart":1612844052010,"symbol":"SNX-BTC","changes":{"asks":[],"bids":[["0.00028663","14.06606922","1612844052010"]]},"sequenceEnd":1612844052010},"subject":"trade.l2update","topic":"/market/level2:SNX-BTC","type":"message"}
1619378342.583387: {"data":{"sequenceStart":1612701563998,"symbol":"DAPPT-BTC","changes":{"asks":[],"bids":[["0","0","1612701563998"]]},"sequenceEnd":1612701563998},"subject":"trade.l2update","topic":"/market/level2:DAPPT-BTC","type":"message"}
1619378342.583495: {"data":{"sequenceStart":1612701563999,"symbol":"DAPPT-BTC","changes":{"asks":[],"bids":[["0.000000112","5148.7686","1612701563999"]]},"sequenceEnd":1612701563999},"subject":"trade.l2update","topic":"/market/level2:DAPPT-BTC","type":"message"}
1619378342.5898502: {"data":{"sequence":"1612844052010","bestAsk":"0.00028711","size":"0.01745248","bestBidSize":"0.19100065","price":"0.00028676","time":1619378342550,"bestAskSize":"43.28403854","bestBid":"0.00028678"},"subject":"trade.ticker","topic":"/market/ticker:SNX-BTC","type":"message"}
1619378342.594644: {"data":{"sequenceStart":1612734157884,"symbol":"ANKR-BTC","changes":{"asks":[],"bids":[["0","0","1612734157884"]]},"sequenceEnd":1612734157884},"subject":"trade.l2update","topic":"/market/level2:ANKR-BTC","type":"message"}
1619378342.59475: {"data":{"sequenceStart":1612734157885,"symbol":"ANKR-BTC","changes":{"asks":[],"bids":[["0.0000026004","3495.5714","1612734157885"]]},"sequenceEnd":1612734157885},"subject":"trade.l2update","topic":"/market/level2:ANKR-BTC","type":"message"}
1619378342.610527: {"data":{"sequenceStart":1612844052011,"symbol":"SNX-BTC","changes":{"asks":[],"bids":[["0.00028663","0","1612844052011"]]},"sequenceEnd":1612844052011},"subject":"trade.l2update","topic":"/market/level2:SNX-BTC","type":"message"}
1619378342.610635: {"data":{"sequenceStart":1612734157886,"symbol":"ANKR-BTC","changes":{"asks":[],"bids":[["0.0000026003","0","1612734157886"]]},"sequenceEnd":1612734157886},"subject":"trade.l2update","topic":"/market/level2:ANKR-BTC","type":"message"}
1619378342.6123679: {"data":{"sequenceStart":1612701564000,"symbol":"DAPPT-BTC","changes":{"asks":[],"bids":[["0.000000112","0","1612701564000"]]},"sequenceEnd":1612701564000},"subject":"trade.l2update","topic":"/market/level2:DAPPT-BTC","type":"message"}
1619378342.612465: {"data":{"sequenceStart":1612844052012,"symbol":"SNX-BTC","changes":{"asks":[["0","0","1612844052012"]],"bids":[]},"sequenceEnd":1612844052012},"subject":"trade.l2update","topic":"/market/level2:SNX-BTC","type":"message"}
1619378342.612501: {"data":{"sequenceStart":1612844052013,"symbol":"SNX-BTC","changes":{"asks":[["0.00029397","164.52403098","1612844052013"]],"bids":[]},"sequenceEnd":1612844052013},"subject":"trade.l2update","topic":"/market/level2:SNX-BTC","type":"message"}
1619378342.618075: {"data":{"sequenceStart":1612734157887,"symbol":"ANKR-BTC","changes":{"asks":[],"bids":[["0.0000026004","0","1612734157887"]]},"sequenceEnd":1612734157887},"subject":"trade.l2update","topic":"/market/level2:ANKR-BTC","type":"message"}
1619378342.623383: {"data":{"sequence":"1612734157887","bestAsk":"0.0000026208","size":"46","bestBidSize":"3668","price":"0.0000026071","time":1619378342588,"bestAskSize":"10987.6265","bestBid":"0.0000025998"},"subject":"trade.ticker","topic":"/market/ticker:ANKR-BTC","type":"message"}
1619378342.64139: {"data":{"sequenceStart":1613277185129,"symbol":"BCHSV-USDT","changes":{"asks":[],"bids":[["0","0","1613277185129"]]},"sequenceEnd":1613277185129},"subject":"trade.l2update","topic":"/market/level2:BCHSV-USDT","type":"message"}
1619378342.6414962: {"data":{"sequenceStart":1613277185130,"symbol":"BCHSV-USDT","changes":{"asks":[],"bids":[["242.583","0.50082074","1613277185130"]]},"sequenceEnd":1613277185130},"subject":"trade.l2update","topic":"/market/level2:BCHSV-USDT","type":"message"}
1619378342.65017: {"data":{"sequenceStart":1612844052014,"symbol":"SNX-BTC","changes":{"asks":[],"bids":[["0","0","1612844052014"]]},"sequenceEnd":1612844052014},"subject":"trade.l2update","topic":"/market/level2:SNX-BTC","type":"message"}
1619378342.6502788: {"data":{"sequenceStart":1612844052015,"symbol":"SNX-BTC","changes":{"asks":[],"bids":[["0.00028615","14.1211949","1612844052015"]]},"sequenceEnd":1612844052015},"subject":"trade.l2update","topic":"/market/level2:SNX-BTC","type":"message"}
1619378342.671068: {"data":{"sequence":"1612701564000","bestAsk":"0.000000113","size":"145.4959","bestBidSize":"361.2609","price":"0.0000001126","time":1619378342630,"bestAskSize":"1208.0878","bestBid":"0.0000001119"},"subject":"trade.ticker","topic":"/market/ticker:DAPPT-BTC","type":"message"}
1619378342.6711612: {"data":{"sequenceStart":1612734157888,"symbol":"ANKR-BTC","changes":{"asks":[],"bids":[["0","0","1612734157888"]]},"sequenceEnd":1612734157888},"subject":"trade.l2update","topic":"/market/level2:ANKR-BTC","type":"message"}
1619378342.6712298: {"data":{"sequenceStart":1612734157889,"symbol":"ANKR-BTC","changes":{"asks":[],"bids":[["0.0000026005","5032.6841","1612734157889"]]},"sequenceEnd":1612734157889},"subject":"trade.l2update","topic":"/market/level2:ANKR-BTC","type":"message"}
1619378342.675362: {"data":{"sequence":"1613277185130","bestAsk":"243.036","size":"0.14324938","bestBidSize":"19.727","price":"242.781","time":1619378342634,"bestAskSize":"9.62448872","bestBid":"242.635"},"subject":"trade.ticker","topic":"/market/ticker:BCHSV-USDT","type":"message"}
1619378342.686073: {"data":{"sequenceStart":1612844052016,"symbol":"SNX-BTC","changes":{"asks":[],"bids":[["0.00028615","0","1612844052016"]]},"sequenceEnd":1612844052016},"subject":"trade.l2update","topic":"/market/level2:SNX-BTC","type":"message"}
1619378342.691885: {"data":{"sequence":"1612844052016","bestAsk":"0.00028711","size":"0.01745248","bestBidSize":"0.19100065","price":"0.00028676","time":1619378342651,"bestAskSize":"43.28403854","bestBid":"0.00028678"},"subject":"trade.ticker","topic":"/market/ticker:SNX-BTC","type":"message"}
1619378342.715009: {"data":{"sequenceStart":1612734157890,"symbol":"ANKR-BTC","changes":{"asks":[],"bids":[["0","0","1612734157890"]]},"sequenceEnd":1612734157890},"subject":"trade.l2update","topic":"/market/level2:ANKR-BTC","type":"message"}
1619378342.715116: {"data":{"sequenceStart":1612734157891,"symbol":"ANKR-BTC","changes":{"asks":[],"bids":[["0.0000026006","3495.4378","1612734157891"]]},"sequenceEnd":1612734157891},"subject":"trade.l2update","topic":"/market/level2:ANKR-BTC","type":"message"}
1619378342.727125: {"data":{"sequence":"1612734157891","bestAsk":"0.0000026208","size":"46","bestBidSize":"3495.4378","price":"0.0000026071","time":1619378342688,"bestAskSize":"10987.6265","bestBid":"0.0000026006"},"subject":"trade.ticker","topic":"/market/ticker:ANKR-BTC","type":"message"}
1619378342.727233: {"data":{"sequenceStart":1613277185131,"symbol":"BCHSV-USDT","changes":{"asks":[],"bids":[["240.337","0","1613277185131"]]},"sequenceEnd":1613277185131},"subject":"trade.l2update","topic":"/market/level2:BCHSV-USDT","type":"message"}
1619378342.734619: {"data":{"sequenceStart":1613277185132,"symbol":"BCHSV-USDT","changes":{"asks":[["243.301","0","1613277185132"]],"bids":[]},"sequenceEnd":1613277185132},"subject":"trade.l2update","topic":"/market/level2:BCHSV-USDT","type":"message"}
1619378342.738174: {"data":{"sequenceStart":1612844052017,"symbol":"SNX-BTC","changes":{"asks":[],"bids":[["0","0","1612844052017"]]},"sequenceEnd":1612844052017},"subject":"trade.l2update","topic":"/market/level2:SNX-BTC","type":"message"}
1619378342.738281: {"data":{"sequenceStart":1612844052018,"symbol":"SNX-BTC","changes":{"asks":[],"bids":[["0.00028666","14.06459716","1612844052018"]]},"sequenceEnd":1612844052018},"subject":"trade.l2update","topic":"/market/level2:SNX-BTC","type":"message"}
1619378342.7502139: {"data":{"sequenceStart":1613277185133,"symbol":"BCHSV-USDT","changes":{"asks":[],"bids":[["0","0","1613277185133"]]},"sequenceEnd":1613277185133},"subject":"trade.l2update","topic":"/market/level2:BCHSV-USDT","type":"message"}
1619378342.750323: {"data":{"sequenceStart":1613277185134,"symbol":"BCHSV-USDT","changes":{"asks":[],"bids":[["242.635","45.893","1613277185134"]]},"sequenceEnd":1613277185134},"subject":"trade.l2update","topic":"/market/level2:BCHSV-USDT","type":"message"}
1619378342.750387: {"data":{"sequenceStart":1612734157892,"symbol":"ANKR-BTC","changes":{"asks":[],"bids":[["0.0000026005","0","1612734157892"]]},"sequenceEnd":1612734157892},"subject":"trade.l2update","topic":"/market/level2:ANKR-BTC","type":"message"}
1619378342.756736: {"data":{"sequenceStart":1619079123955,"symbol":"EQZ-BTC","changes":{"asks":[],"bids":[["0","0","1619079123955"]]},"sequenceEnd":1619079123955},"subject":"trade.l2update","topic":"/market/level2:EQZ-BTC","type":"message"}
1619378342.756841: {"data":{"sequenceStart":1619079123956,"symbol":"EQZ-BTC","changes":{"asks":[],"bids":[["0.00002328","231.701","1619079123956"]]},"sequenceEnd":1619079123956},"subject":"trade.l2update","topic":"/market/level2:EQZ-BTC","type":"message"}
1619378342.756918: {"data":{"sequenceStart":1612844052019,"symbol":"SNX-BTC","changes":{"asks":[],"bids":[["0","0","1612844052019"]]},"sequenceEnd":1612844052019},"subject":"trade.l2update","topic":"/market/level2:SNX-BTC","type":"message"}
1619378342.756961: {"data":{"sequenceStart":1612844052020,"symbol":"SNX-BTC","changes":{"asks":[],"bids":[["0.00028614","1.62116778","1612844052020"]]},"sequenceEnd":1612844052020},"subject":"trade.l2update","topic":"/market/level2:SNX-BTC","type":"message"}
1619378342.765468: {"data":{"sequenceStart":1612712745726,"symbol":"FET-BTC","changes":{"asks":[["0.00000785","0","1612712745726"]],"bids":[]},"sequenceEnd":1612712745726},"subject":"trade.l2update","topic":"/market/level2:FET-BTC","type":"message"}
1619378342.7707798: {"data":{"sequence":"1613277185134","bestAsk":"243.036","size":"0.14324938","bestBidSize":"45.893","price":"242.781","time":1619378342732,"bestAskSize":"9.62448872","bestBid":"242.635"},"subject":"trade.ticker","topic":"/market/ticker:BCHSV-USDT","type":"message"}
1619378342.773283: {"data":{"sequenceStart":1612734157893,"symbol":"ANKR-BTC","changes":{"asks":[],"bids":[["0","0","1612734157893"]]},"sequenceEnd":1612734157893},"subject":"trade.l2update","topic":"/market/level2:ANKR-BTC","type":"message"}
1619378342.773393: {"data":{"sequenceStart":1612734157894,"symbol":"ANKR-BTC","changes":{"asks":[],"bids":[["0.0000026007","5032.6841","1612734157894"]]},"sequenceEnd":1612734157894},"subject":"trade.l2update","topic":"/market/level2:ANKR-BTC","type":"message"}
1619378342.784707: {"data":{"sequence":"1619079123956","bestAsk":"0.00002395","size":"0.375","bestBidSize":"20.5373","price":"0.00002383","time":1619378342738,"bestAskSize":"72.1515","bestBid":"0.00002383"},"subject":"trade.ticker","topic":"/market/ticker:EQZ-BTC","type":"message"}
1619378342.784797: {"data":{"sequenceStart":1612844052021,"symbol":"SNX-BTC","changes":{"asks":[],"bids":[["0.00028614","0","1612844052021"]]},"sequenceEnd":1612844052021},"subject":"trade.l2update","topic":"/market/level2:SNX-BTC","type":"message"}
1619378342.78787: {"data":{"sequence":"1612844052021","bestAsk":"0.00028711","size":"0.01745248","bestBidSize":"0.19100065","price":"0.00028676","time":1619378342749,"bestAskSize":"43.28403854","bestBid":"0.00028678"},"subject":"trade.ticker","topic":"/market/ticker:SNX-BTC","type":"message"}
1619378342.803262: {"data":{"sequenceStart":1613277185135,"symbol":"BCHSV-USDT","changes":{"asks":[],"bids":[["0","0","1613277185135"]]},"sequenceEnd":1613277185135},"subject":"trade.l2update","topic":"/market/level2:BCHSV-USDT","type":"message"}
1619378342.8033779: {"data":{"sequenceStart":1613277185136,"symbol":"BCHSV-USDT","changes":{"asks":[],"bids":[["242.141","9.61311182","1613277185136"]]},"sequenceEnd":1613277185136},"subject":"trade.l2update","topic":"/market/level2:BCHSV-USDT","type":"message"}
1619378342.804302: {"data":{"sequence":"1612712745726","bestAsk":"0.00000776","size":"12.2091","bestBidSize":"357.2953","price":"0.00000776","time":1619378342769,"bestAskSize":"1141.8325","bestBid":"0.00000771"},"subject":"trade.ticker","topic":"/market/ticker:FET-BTC","type":"message"}
1619378342.828274: {"data":{"sequence":"1612734157894","bestAsk":"0.0000026208","size":"46","bestBidSize":"5032.6841","price":"0.0000026071","time":1619378342791,"bestAskSize":"10987.6265","bestBid":"0.0000026007"},"subject":"trade.ticker","topic":"/market/ticker:ANKR-BTC","type":"message"}
1619378342.864743: {"data":{"sequenceStart":1612694580191,"symbol":"CAPP-BTC","changes":{"asks":[],"bids":[["0","0","1612694580191"]]},"sequenceEnd":1612694580191},"subject":"trade.l2update","topic":"/market/level2:CAPP-BTC","type":"message"}
1619378342.864853: {"data":{"sequenceStart":1612694580192,"symbol":"CAPP-BTC","changes":{"asks":[],"bids":[["0.0000001817","137627.7","1612694580192"]]},"sequenceEnd":1612694580192},"subject":"trade.l2update","topic":"/market/level2:CAPP-BTC","type":"message"}
1619378342.871315: {"data":{"sequence":"1613277185136","bestAsk":"243.036","size":"0.14324938","bestBidSize":"45.893","price":"242.781","time":1619378342832,"bestAskSize":"9.62448872","bestBid":"242.635"},"subject":"trade.ticker","topic":"/market/ticker:BCHSV-USDT","type":"message"}
1619378342.875917: {"data":{"sequenceStart":1613277185137,"symbol":"BCHSV-USDT","changes":{"asks":[["243.775","0","1613277185137"]],"bids":[]},"sequenceEnd":1613277185137},"subject":"trade.l2update","topic":"/market/level2:BCHSV-USDT","type":"message"}
1619378342.8759968: {"data":{"sequenceStart":1613277185138,"symbol":"BCHSV-USDT","changes":{"asks":[],"bids":[["241.614","0","1613277185138"]]},"sequenceEnd":1613277185138},"subject":"trade.l2update","topic":"/market/level2:BCHSV-USDT","type":"message"}
1619378342.876034: {"data":{"sequenceStart":1613277185139,"symbol":"BCHSV-USDT","changes":{"asks":[["244.413","0","1613277185139"]],"bids":[]},"sequenceEnd":1613277185139},"subject":"trade.l2update","topic":"/market/level2:BCHSV-USDT","type":"message"}
1619378342.8760629: {"data":{"sequenceStart":1613277185140,"symbol":"BCHSV-USDT","changes":{"asks":[],"bids":[["240.98","0","1613277185140"]]},"sequenceEnd":1613277185140},"subject":"trade.l2update","topic":"/market/level2:BCHSV-USDT","type":"message"}
1619378342.900117: {"data":{"sequenceStart":1612694580193,"symbol":"CAPP-BTC","changes":{"asks":[],"bids":[["0.0000002147","0","1612694580193"]]},"sequenceEnd":1612694580193},"subject":"trade.l2update","topic":"/market/level2:CAPP-BTC","type":"message"}
1619378342.900259: {"data":{"sequenceStart":1612712745727,"symbol":"FET-BTC","changes":{"asks":[["0.0000078","0","1612712745727"]],"bids":[]},"sequenceEnd":1612712745727},"subject":"trade.l2update","topic":"/market/level2:FET-BTC","type":"message"}
1619378342.90497: {"data":{"sequenceStart":1613277185141,"symbol":"BCHSV-USDT","changes":{"asks":[["0","0","1613277185141"]],"bids":[]},"sequenceEnd":1613277185141},"subject":"trade.l2update","topic":"/market/level2:BCHSV-USDT","type":"message"}
1619378342.9050891: {"data":{"sequenceStart":1613277185142,"symbol":"BCHSV-USDT","changes":{"asks":[["243.109","8.58072736","1613277185142"]],"bids":[]},"sequenceEnd":1613277185142},"subject":"trade.l2update","topic":"/market/level2:BCHSV-USDT","type":"message"}
1619378342.9086359: {"data":{"sequence":"1612712745727","bestAsk":"0.00000776","size":"12.2091","bestBidSize":"357.2953","price":"0.00000776","time":1619378342867,"bestAskSize":"1141.8325","bestBid":"0.00000771"},"subject":"trade.ticker","topic":"/market/ticker:FET-BTC","type":"message"}
1619378342.916953: {"data":{"sequenceStart":1613277185143,"symbol":"BCHSV-USDT","changes":{"asks":[],"bids":[["242.14","2.99","1613277185143"]]},"sequenceEnd":1613277185143},"subject":"trade.l2update","topic":"/market/level2:BCHSV-USDT","type":"message"}
1619378342.9233851: {"data":{"sequence":"1612694580193","bestAsk":"0.0000002195","size":"1000.02","bestBidSize":"83.07","price":"0.0000002182","time":1619378342882,"bestAskSize":"270.17","bestBid":"0.0000002181"},"subject":"trade.ticker","topic":"/market/ticker:CAPP-BTC","type":"message"}
1619378342.928899: {"data":{"sequenceStart":1613277185144,"symbol":"BCHSV-USDT","changes":{"asks":[],"bids":[["242.14","0","1613277185144"]]},"sequenceEnd":1613277185144},"subject":"trade.l2update","topic":"/market/level2:BCHSV-USDT","type":"message"}
1619378342.9663491: {"data":{"sequence":"1613277185144","bestAsk":"243.036","size":"0.14324938","bestBidSize":"45.893","price":"242.781","time":1619378342930,"bestAskSize":"9.62448872","bestBid":"242.635"},"subject":"trade.ticker","topic":"/market/ticker:BCHSV-USDT","type":"message"}
1619378342.971551: {"data":{"sequenceStart":1613277185145,"symbol":"BCHSV-USDT","changes":{"asks":[],"bids":[["0","0","1613277185145"]]},"sequenceEnd":1613277185145},"subject":"trade.l2update","topic":"/market/level2:BCHSV-USDT","type":"message"}
1619378342.971663: {"data":{"sequenceStart":1613277185146,"symbol":"BCHSV-USDT","changes":{"asks":[],"bids":[["242.142","2.99","1613277185146"]]},"sequenceEnd":1613277185146},"subject":"trade.l2update","topic":"/market/level2:BCHSV-USDT","type":"message"}
1619378342.98074: {"data":{"sequenceStart":1613277185147,"symbol":"BCHSV-USDT","changes":{"asks":[],"bids":[["0","0","1613277185147"]]},"sequenceEnd":1613277185147},"subject":"trade.l2update","topic":"/market/level2:BCHSV-USDT","type":"message"}
1619378342.980852: {"data":{"sequenceStart":1613277185148,"symbol":"BCHSV-USDT","changes":{"asks":[],"bids":[["242.142","5.98","1613277185148"]]},"sequenceEnd":1613277185148},"subject":"trade.l2update","topic":"/market/level2:BCHSV-USDT","type":"message"}
1619378342.980916: {"data":{"sequenceStart":1612844052022,"symbol":"SNX-BTC","changes":{"asks":[],"bids":[["0.00028666","0","1612844052022"]]},"sequenceEnd":1612844052022},"subject":"trade.l2update","topic":"/market/level2:SNX-BTC","type":"message"}
1619378342.9987998: {"data":{"sequenceStart":1612702190352,"symbol":"NRG-BTC","changes":{"asks":[],"bids":[["0","0","1612702190352"]]},"sequenceEnd":1612702190352},"subject":"trade.l2update","topic":"/market/level2:NRG-BTC","type":"message"}
1619378342.99891: {"data":{"sequenceStart":1612702190353,"symbol":"NRG-BTC","changes":{"asks":[],"bids":[["0.0000612","19.5687","1612702190353"]]},"sequenceEnd":1612702190353},"subject":"trade.l2update","topic":"/market/level2:NRG-BTC","type":"message"}
1619378343.014271: {"data":{"sequenceStart":1612844052023,"symbol":"SNX-BTC","changes":{"asks":[],"bids":[["0","0","1612844052023"]]},"sequenceEnd":1612844052023},"subject":"trade.l2update","topic":"/market/level2:SNX-BTC","type":"message"}
1619378343.01438: {"data":{"sequenceStart":1612844052024,"symbol":"SNX-BTC","changes":{"asks":[],"bids":[["0.00028281","106.47592516","1612844052024"]]},"sequenceEnd":1612844052024},"subject":"trade.l2update","topic":"/market/level2:SNX-BTC","type":"message"}
1619378343.0300329: {"data":{"sequence":"1612702190353","bestAsk":"0.00006218","size":"0.0431","bestBidSize":"18.897","price":"0.00006141","time":1619378342991,"bestAskSize":"43.3399","bestBid":"0.0000614"},"subject":"trade.ticker","topic":"/market/ticker:NRG-BTC","type":"message"}
1619378343.058228: {"data":{"sequence":"1612844052024","bestAsk":"0.00028711","size":"0.01745248","bestBidSize":"0.19100065","price":"0.00028676","time":1619378343023,"bestAskSize":"43.28403854","bestBid":"0.00028678"},"subject":"trade.ticker","topic":"/market/ticker:SNX-BTC","type":"message"}
1619378343.068161: {"data":{"sequence":"1613277185148","bestAsk":"243.036","size":"0.14324938","bestBidSize":"45.893","price":"242.781","time":1619378343030,"bestAskSize":"9.62448872","bestBid":"242.635"},"subject":"trade.ticker","topic":"/market/ticker:BCHSV-USDT","type":"message"}
1619378343.0682619: {"data":{"sequenceStart":1612712745728,"symbol":"FET-BTC","changes":{"asks":[],"bids":[["0","0","1612712745728"]]},"sequenceEnd":1612712745728},"subject":"trade.l2update","topic":"/market/level2:FET-BTC","type":"message"}
1619378343.068331: {"data":{"sequenceStart":1612712745729,"symbol":"FET-BTC","changes":{"asks":[],"bids":[["0.00000764","278.7348","1612712745729"]]},"sequenceEnd":1612712745729},"subject":"trade.l2update","topic":"/market/level2:FET-BTC","type":"message"}
1619378343.0683908: {"data":{"sequenceStart":1612702190354,"symbol":"NRG-BTC","changes":{"asks":[],"bids":[["0","0","1612702190354"]]},"sequenceEnd":1612702190354},"subject":"trade.l2update","topic":"/market/level2:NRG-BTC","type":"message"}
1619378343.068446: {"data":{"sequenceStart":1612702190355,"symbol":"NRG-BTC","changes":{"asks":[],"bids":[["0.00006124","11.182","1612702190355"]]},"sequenceEnd":1612702190355},"subject":"trade.l2update","topic":"/market/level2:NRG-BTC","type":"message"}
1619378343.101953: {"data":{"sequenceStart":1613277185149,"symbol":"BCHSV-USDT","changes":{"asks":[["0","0","1613277185149"]],"bids":[]},"sequenceEnd":1613277185149},"subject":"trade.l2update","topic":"/market/level2:BCHSV-USDT","type":"message"}
1619378343.102062: {"data":{"sequenceStart":1613277185150,"symbol":"BCHSV-USDT","changes":{"asks":[["245.677","17.79999999","1613277185150"]],"bids":[]},"sequenceEnd":1613277185150},"subject":"trade.l2update","topic":"/market/level2:BCHSV-USDT","type":"message"}
1619378343.10819: {"data":{"sequence":"1612712745729","bestAsk":"0.00000776","size":"12.2091","bestBidSize":"357.2953","price":"0.00000776","time":1619378343069,"bestAskSize":"1141.8325","bestBid":"0.00000771"},"subject":"trade.ticker","topic":"/market/ticker:FET-BTC","type":"message"}
1619378343.130389: {"data":{"sequence":"1612702190355","bestAsk":"0.00006218","size":"0.0431","bestBidSize":"18.897","price":"0.00006141","time":1619378343091,"bestAskSize":"43.3399","bestBid":"0.0000614"},"subject":"trade.ticker","topic":"/market/ticker:NRG-BTC","type":"message"}
1619378343.159811: {"data":{"sequenceStart":1613277185151,"symbol":"BCHSV-USDT","changes":{"asks":[],"bids":[["242.005","0","1613277185151"]]},"sequenceEnd":1613277185151},"subject":"trade.l2update","topic":"/market/level2:BCHSV-USDT","type":"message"}
1619378343.168105: {"data":{"sequence":"1613277185151","bestAsk":"243.036","size":"0.14324938","bestBidSize":"45.893","price":"242.781","time":1619378343130,"bestAskSize":"9.62448872","bestBid":"242.635"},"subject":"trade.ticker","topic":"/market/ticker:BCHSV-USDT","type":"message"}
1619378343.179042: {"data":{"sequenceStart":1612844052025,"symbol":"SNX-BTC","changes":{"asks":[["0.00029097","0","1612844052025"]],"bids":[]},"sequenceEnd":1612844052025},"subject":"trade.l2update","topic":"/market/level2:SNX-BTC","type":"message"}
1619378343.26354: {"data":{"sequence":"1612844052025","bestAsk":"0.00028711","size":"0.01745248","bestBidSize":"0.19100065","price":"0.00028676","time":1619378343223,"bestAskSize":"43.28403854","bestBid":"0.00028678"},"subject":"trade.ticker","topic":"/market/ticker:SNX-BTC","type":"message"}
1619378343.306009: {"data":{"sequenceStart":1613277185152,"symbol":"BCHSV-USDT","changes":{"asks":[["248.676","0","1613277185152"]],"bids":[]},"sequenceEnd":1613277185152},"subject":"trade.l2update","topic":"/market/level2:BCHSV-USDT","type":"message"}
1619378343.306149: {"data":{"sequenceStart":1613277185153,"symbol":"BCHSV-USDT","changes":{"asks":[["251.609","0","1613277185153"]],"bids":[]},"sequenceEnd":1613277185153},"subject":"trade.l2update","topic":"/market/level2:BCHSV-USDT","type":"message"}
1619378343.310157: {"data":{"sequenceStart":1612844052026,"symbol":"SNX-BTC","changes":{"asks":[],"bids":[["0.0002825","0","1612844052026"]]},"sequenceEnd":1612844052026},"subject":"trade.l2update","topic":"/market/level2:SNX-BTC","type":"message"}
1619378343.35823: {"data":{"sequenceStart":1613277185154,"symbol":"BCHSV-USDT","changes":{"asks":[],"bids":[["242.141","0","1613277185154"]]},"sequenceEnd":1613277185154},"subject":"trade.l2update","topic":"/market/level2:BCHSV-USDT","type":"message"}
1619378343.3670259: {"data":{"sequence":"1613277185154","bestAsk":"243.036","size":"0.14324938","bestBidSize":"45.893","price":"242.781","time":1619378343330,"bestAskSize":"9.62448872","bestBid":"242.635"},"subject":"trade.ticker","topic":"/market/ticker:BCHSV-USDT","type":"message"}
1619378343.381116: {"data":{"sequence":"1612844052026","bestAsk":"0.00028711","size":"0.01745248","bestBidSize":"0.19100065","price":"0.00028676","time":1619378343349,"bestAskSize":"43.28403854","bestBid":"0.00028678"},"subject":"trade.ticker","topic":"/market/ticker:SNX-BTC","type":"message"}
1619378343.472518: {"data":{"sequenceStart":1613277185155,"symbol":"BCHSV-USDT","changes":{"asks":[["245.905","0","1613277185155"]],"bids":[]},"sequenceEnd":1613277185155},"subject":"trade.l2update","topic":"/market/level2:BCHSV-USDT","type":"message"}
1619378343.4726589: {"data":{"sequenceStart":1613277185156,"symbol":"BCHSV-USDT","changes":{"asks":[["244.133","0","1613277185156"]],"bids":[]},"sequenceEnd":1613277185156},"subject":"trade.l2update","topic":"/market/level2:BCHSV-USDT","type":"message"}
1619378343.4727502: {"data":{"sequenceStart":1613277185157,"symbol":"BCHSV-USDT","changes":{"asks":[],"bids":[["241.161","0","1613277185157"]]},"sequenceEnd":1613277185157},"subject":"trade.l2update","topic":"/market/level2:BCHSV-USDT","type":"message"}
1619378343.47279: {"data":{"sequenceStart":1613277185158,"symbol":"BCHSV-USDT","changes":{"asks":[],"bids":[["0","0","1613277185158"]]},"sequenceEnd":1613277185158},"subject":"trade.l2update","topic":"/market/level2:BCHSV-USDT","type":"message"}
1619378343.472815: {"data":{"sequenceStart":1613277185159,"symbol":"BCHSV-USDT","changes":{"asks":[],"bids":[["241.609","5","1613277185159"]]},"sequenceEnd":1613277185159},"subject":"trade.l2update","topic":"/market/level2:BCHSV-USDT","type":"message"}
1619378343.472849: {"data":{"sequenceStart":1613277185160,"symbol":"BCHSV-USDT","changes":{"asks":[["0","0","1613277185160"]],"bids":[]},"sequenceEnd":1613277185160},"subject":"trade.l2update","topic":"/market/level2:BCHSV-USDT","type":"message"}
1619378343.472872: {"data":{"sequenceStart":1613277185161,"symbol":"BCHSV-USDT","changes":{"asks":[["243.771","5","1613277185161"]],"bids":[]},"sequenceEnd":1613277185161},"subject":"trade.l2update","topic":"/market/level2:BCHSV-USDT","type":"message"}
1619378343.472901: {"data":{"sequenceStart":1613277185162,"symbol":"BCHSV-USDT","changes":{"asks":[["0","0","1613277185162"]],"bids":[]},"sequenceEnd":1613277185162},"subject":"trade.l2update","topic":"/market/level2:BCHSV-USDT","type":"message"}
1619378343.4729228: {"data":{"sequenceStart":1613277185163,"symbol":"BCHSV-USDT","changes":{"asks":[["244.408","150","1613277185163"]],"bids":[]},"sequenceEnd":1613277185163},"subject":"trade.l2update","topic":"/market/level2:BCHSV-USDT","type":"message"}
1619378343.4851022: {"data":{"sequenceStart":1613277185164,"symbol":"BCHSV-USDT","changes":{"asks":[],"bids":[["0","0","1613277185164"]]},"sequenceEnd":1613277185164},"subject":"trade.l2update","topic":"/market/level2:BCHSV-USDT","type":"message"}
1619378343.485211: {"data":{"sequenceStart":1613277185165,"symbol":"BCHSV-USDT","changes":{"asks":[],"bids":[["241.706","0.68448822","1613277185165"]]},"sequenceEnd":1613277185165},"subject":"trade.l2update","topic":"/market/level2:BCHSV-USDT","type":"message"}
1619378343.4959612: {"data":{"sequenceStart":1613277185166,"symbol":"BCHSV-USDT","changes":{"asks":[],"bids":[["0","0","1613277185166"]]},"sequenceEnd":1613277185166},"subject":"trade.l2update","topic":"/market/level2:BCHSV-USDT","type":"message"}
1619378343.49607: {"data":{"sequenceStart":1613277185167,"symbol":"BCHSV-USDT","changes":{"asks":[],"bids":[["240.975","150","1613277185167"]]},"sequenceEnd":1613277185167},"subject":"trade.l2update","topic":"/market/level2:BCHSV-USDT","type":"message"}
1619378343.511016: {"data":{"sequenceStart":1612712745730,"symbol":"FET-BTC","changes":{"asks":[["0","0","1612712745730"]],"bids":[]},"sequenceEnd":1612712745730},"subject":"trade.l2update","topic":"/market/level2:FET-BTC","type":"message"}
1619378343.511128: {"data":{"sequenceStart":1612712745731,"symbol":"FET-BTC","changes":{"asks":[["0.00000781","159.36","1612712745731"]],"bids":[]},"sequenceEnd":1612712745731},"subject":"trade.l2update","topic":"/market/level2:FET-BTC","type":"message"}
1619378343.548586: {"data":{"sequenceStart":1613277185168,"symbol":"BCHSV-USDT","changes":{"asks":[["0","0","1613277185168"]],"bids":[]},"sequenceEnd":1613277185168},"subject":"trade.l2update","topic":"/market/level2:BCHSV-USDT","type":"message"}
1619378343.548715: {"data":{"sequenceStart":1613277185169,"symbol":"BCHSV-USDT","changes":{"asks":[["245.946","25","1613277185169"]],"bids":[]},"sequenceEnd":1613277185169},"subject":"trade.l2update","topic":"/market/level2:BCHSV-USDT","type":"message"}
1619378343.554092: {"data":{"sequenceStart":1613277185170,"symbol":"BCHSV-USDT","changes":{"asks":[["0","0","1613277185170"]],"bids":[]},"sequenceEnd":1613277185170},"subject":"trade.l2update","topic":"/market/level2:BCHSV-USDT","type":"message"}
1619378343.554205: {"data":{"sequenceStart":1613277185171,"symbol":"BCHSV-USDT","changes":{"asks":[["251.568","125","1613277185171"]],"bids":[]},"sequenceEnd":1613277185171},"subject":"trade.l2update","topic":"/market/level2:BCHSV-USDT","type":"message"}
1619378343.554286: {"data":{"sequenceStart":1613277185172,"symbol":"BCHSV-USDT","changes":{"asks":[["0","0","1613277185172"]],"bids":[]},"sequenceEnd":1613277185172},"subject":"trade.l2update","topic":"/market/level2:BCHSV-USDT","type":"message"}
1619378343.5543292: {"data":{"sequenceStart":1613277185173,"symbol":"BCHSV-USDT","changes":{"asks":[["244.183","5","1613277185173"]],"bids":[]},"sequenceEnd":1613277185173},"subject":"trade.l2update","topic":"/market/level2:BCHSV-USDT","type":"message"}
1619378343.554379: {"data":{"sequenceStart":1613277185174,"symbol":"BCHSV-USDT","changes":{"asks":[],"bids":[["0","0","1613277185174"]]},"sequenceEnd":1613277185174},"subject":"trade.l2update","topic":"/market/level2:BCHSV-USDT","type":"message"}
1619378343.554423: {"data":{"sequenceStart":1613277185175,"symbol":"BCHSV-USDT","changes":{"asks":[],"bids":[["241.271","5","1613277185175"]]},"sequenceEnd":1613277185175},"subject":"trade.l2update","topic":"/market/level2:BCHSV-USDT","type":"message"}
1619378343.5544739: {"data":{"sequenceStart":1613277185176,"symbol":"BCHSV-USDT","changes":{"asks":[["0","0","1613277185176"]],"bids":[]},"sequenceEnd":1613277185176},"subject":"trade.l2update","topic":"/market/level2:BCHSV-USDT","type":"message"}
1619378343.554496: {"data":{"sequenceStart":1613277185177,"symbol":"BCHSV-USDT","changes":{"asks":[["248.748","70","1613277185177"]],"bids":[]},"sequenceEnd":1613277185177},"subject":"trade.l2update","topic":"/market/level2:BCHSV-USDT","type":"message"}
1619378343.569841: {"data":{"sequence":"1613277185177","bestAsk":"243.036","size":"0.14324938","bestBidSize":"45.893","price":"242.781","time":1619378343532,"bestAskSize":"9.62448872","bestBid":"242.635"},"subject":"trade.ticker","topic":"/market/ticker:BCHSV-USDT","type":"message"}
1619378343.590209: {"data":{"sequenceStart":1612844052027,"symbol":"SNX-BTC","changes":{"asks":[],"bids":[["0","0","1612844052027"]]},"sequenceEnd":1612844052027},"subject":"trade.l2update","topic":"/market/level2:SNX-BTC","type":"message"}
1619378343.590316: {"data":{"sequenceStart":1612844052028,"symbol":"SNX-BTC","changes":{"asks":[],"bids":[["0.00028614","3.24192977","1612844052028"]]},"sequenceEnd":1612844052028},"subject":"trade.l2update","topic":"/market/level2:SNX-BTC","type":"message"}
1619378343.6039941: {"data":{"sequence":"1612712745731","bestAsk":"0.00000776","size":"12.2091","bestBidSize":"357.2953","price":"0.00000776","time":1619378343568,"bestAskSize":"1141.8325","bestBid":"0.00000771"},"subject":"trade.ticker","topic":"/market/ticker:FET-BTC","type":"message"}
1619378343.6568902: {"data":{"sequenceStart":1613277185178,"symbol":"BCHSV-USDT","changes":{"asks":[["245.677","0","1613277185178"]],"bids":[]},"sequenceEnd":1613277185178},"subject":"trade.l2update","topic":"/market/level2:BCHSV-USDT","type":"message"}
1619378343.6570299: {"data":{"sequence":"1612844052028","bestAsk":"0.00028711","size":"0.01745248","bestBidSize":"0.19100065","price":"0.00028676","time":1619378343623,"bestAskSize":"43.28403854","bestBid":"0.00028678"},"subject":"trade.ticker","topic":"/market/ticker:SNX-BTC","type":"message"}
1619378343.668948: {"data":{"sequence":"1613277185178","bestAsk":"243.036","size":"0.14324938","bestBidSize":"45.893","price":"242.781","time":1619378343632,"bestAskSize":"9.62448872","bestBid":"242.635"},"subject":"trade.ticker","topic":"/market/ticker:BCHSV-USDT","type":"message"}
1619378343.719397: {"data":{"sequenceStart":1612844052029,"symbol":"SNX-BTC","changes":{"asks":[],"bids":[["0.00028608","0","1612844052029"]]},"sequenceEnd":1612844052029},"subject":"trade.l2update","topic":"/market/level2:SNX-BTC","type":"message"}
1619378343.738755: {"data":{"sequenceStart":1613277185179,"symbol":"BCHSV-USDT","changes":{"asks":[["243.05","2.99","1613277185179"]],"bids":[]},"sequenceEnd":1613277185179},"subject":"trade.l2update","topic":"/market/level2:BCHSV-USDT","type":"message"}
1619378343.7388759: {"data":{"sequenceStart":1613277185180,"symbol":"BCHSV-USDT","changes":{"asks":[["243.05","0","1613277185180"]],"bids":[]},"sequenceEnd":1613277185180},"subject":"trade.l2update","topic":"/market/level2:BCHSV-USDT","type":"message"}
1619378343.738954: {"data":{"sequenceStart":1613277185181,"symbol":"BCHSV-USDT","changes":{"asks":[],"bids":[["242.142","2.99","1613277185181"]]},"sequenceEnd":1613277185181},"subject":"trade.l2update","topic":"/market/level2:BCHSV-USDT","type":"message"}
1619378343.739004: {"data":{"sequenceStart":1613277185182,"symbol":"BCHSV-USDT","changes":{"asks":[],"bids":[["242.142","0","1613277185182"]]},"sequenceEnd":1613277185182},"subject":"trade.l2update","topic":"/market/level2:BCHSV-USDT","type":"message"}
1619378343.748254: {"data":{"sequenceStart":1613277185183,"symbol":"BCHSV-USDT","changes":{"asks":[],"bids":[["0","0","1613277185183"]]},"sequenceEnd":1613277185183},"subject":"trade.l2update","topic":"/market/level2:BCHSV-USDT","type":"message"}
1619378343.748363: {"data":{"sequenceStart":1613277185184,"symbol":"BCHSV-USDT","changes":{"asks":[],"bids":[["242.702","0.68148185","1613277185184"]]},"sequenceEnd":1613277185184},"subject":"trade.l2update","topic":"/market/level2:BCHSV-USDT","type":"message"}
1619378343.7574441: {"data":{"sequence":"1612844052029","bestAsk":"0.00028711","size":"0.01745248","bestBidSize":"0.19100065","price":"0.00028676","time":1619378343723,"bestAskSize":"43.28403854","bestBid":"0.00028678"},"subject":"trade.ticker","topic":"/market/ticker:SNX-BTC","type":"message"}
1619378343.7669609: {"data":{"sequence":"1613277185184","bestAsk":"243.036","size":"0.14324938","bestBidSize":"0.68148185","price":"242.781","time":1619378343733,"bestAskSize":"9.62448872","bestBid":"242.702"},"subject":"trade.ticker","topic":"/market/ticker:BCHSV-USDT","type":"message"}
1619378343.79992: {"data":{"sequenceStart":1613277185185,"symbol":"BCHSV-USDT","changes":{"asks":[],"bids":[["0","0","1613277185185"]]},"sequenceEnd":1613277185185},"subject":"trade.l2update","topic":"/market/level2:BCHSV-USDT","type":"message"}
1619378343.800031: {"data":{"sequenceStart":1613277185186,"symbol":"BCHSV-USDT","changes":{"asks":[],"bids":[["242.706","5","1613277185186"]]},"sequenceEnd":1613277185186},"subject":"trade.l2update","topic":"/market/level2:BCHSV-USDT","type":"message"}
1619378343.8001049: {"data":{"sequenceStart":1613277185187,"symbol":"BCHSV-USDT","changes":{"asks":[],"bids":[["0","0","1613277185187"]]},"sequenceEnd":1613277185187},"subject":"trade.l2update","topic":"/market/level2:BCHSV-USDT","type":"message"}
1619378343.800194: {"data":{"sequenceStart":1613277185188,"symbol":"BCHSV-USDT","changes":{"asks":[],"bids":[["242.474","2.99","1613277185188"]]},"sequenceEnd":1613277185188},"subject":"trade.l2update","topic":"/market/level2:BCHSV-USDT","type":"message"}
1619378343.8052878: {"data":{"sequenceStart":1613277185189,"symbol":"BCHSV-USDT","changes":{"asks":[],"bids":[["0","0","1613277185189"]]},"sequenceEnd":1613277185189},"subject":"trade.l2update","topic":"/market/level2:BCHSV-USDT","type":"message"}
1619378343.805368: {"data":{"sequenceStart":1613277185190,"symbol":"BCHSV-USDT","changes":{"asks":[],"bids":[["242.474","5.98","1613277185190"]]},"sequenceEnd":1613277185190},"subject":"trade.l2update","topic":"/market/level2:BCHSV-USDT","type":"message"}
1619378343.80976: {"data":{"sequenceStart":1613277185191,"symbol":"BCHSV-USDT","changes":{"asks":[],"bids":[["242.583","0.05000051","1613277185191"]]},"sequenceEnd":1613277185191},"subject":"trade.l2update","topic":"/market/level2:BCHSV-USDT","type":"message"}
1619378343.834742: {"data":{"sequenceStart":1612844052030,"symbol":"SNX-BTC","changes":{"asks":[],"bids":[["0","0","1612844052030"]]},"sequenceEnd":1612844052030},"subject":"trade.l2update","topic":"/market/level2:SNX-BTC","type":"message"}
1619378343.8348749: {"data":{"sequenceStart":1612844052031,"symbol":"SNX-BTC","changes":{"asks":[],"bids":[["0.00028621","73.36088277","1612844052031"]]},"sequenceEnd":1612844052031},"subject":"trade.l2update","topic":"/market/level2:SNX-BTC","type":"message"}
1619378343.852173: {"data":{"sequenceStart":1612844052032,"symbol":"SNX-BTC","changes":{"asks":[["0.000291","0","1612844052032"]],"bids":[]},"sequenceEnd":1612844052032},"subject":"trade.l2update","topic":"/market/level2:SNX-BTC","type":"message"}
1619378343.858037: {"data":{"sequence":"1612844052032","bestAsk":"0.00028711","size":"0.01745248","bestBidSize":"0.19100065","price":"0.00028676","time":1619378343823,"bestAskSize":"43.28403854","bestBid":"0.00028678"},"subject":"trade.ticker","topic":"/market/ticker:SNX-BTC","type":"message"}
1619378343.86916: {"data":{"sequenceStart":1613277185192,"symbol":"BCHSV-USDT","changes":{"asks":[["243.771","0","1613277185192"]],"bids":[]},"sequenceEnd":1613277185192},"subject":"trade.l2update","topic":"/market/level2:BCHSV-USDT","type":"message"}
1619378343.869301: {"data":{"sequenceStart":1613277185193,"symbol":"BCHSV-USDT","changes":{"asks":[["244.408","0","1613277185193"]],"bids":[]},"sequenceEnd":1613277185193},"subject":"trade.l2update","topic":"/market/level2:BCHSV-USDT","type":"message"}
1619378343.874974: {"data":{"sequence":"1613277185193","bestAsk":"243.036","size":"0.14324938","bestBidSize":"5","price":"242.781","time":1619378343835,"bestAskSize":"9.62448872","bestBid":"242.706"},"subject":"trade.ticker","topic":"/market/ticker:BCHSV-USDT","type":"message"}
1619378343.875067: {"data":{"sequenceStart":1613277185194,"symbol":"BCHSV-USDT","changes":{"asks":[],"bids":[["241.609","0","1613277185194"]]},"sequenceEnd":1613277185194},"subject":"trade.l2update","topic":"/market/level2:BCHSV-USDT","type":"message"}
1619378343.875166: {"data":{"sequenceStart":1613277185195,"symbol":"BCHSV-USDT","changes":{"asks":[],"bids":[["0","0","1613277185195"]]},"sequenceEnd":1613277185195},"subject":"trade.l2update","topic":"/market/level2:BCHSV-USDT","type":"message"}
1619378343.875212: {"data":{"sequenceStart":1613277185196,"symbol":"BCHSV-USDT","changes":{"asks":[],"bids":[["241.707","9.86116934","1613277185196"]]},"sequenceEnd":1613277185196},"subject":"trade.l2update","topic":"/market/level2:BCHSV-USDT","type":"message"}
1619378343.875268: {"data":{"sequenceStart":1613277185197,"symbol":"BCHSV-USDT","changes":{"asks":[],"bids":[["240.975","0","1613277185197"]]},"sequenceEnd":1613277185197},"subject":"trade.l2update","topic":"/market/level2:BCHSV-USDT","type":"message"}
1619378343.8880482: {"data":{"sequenceStart":1613277185198,"symbol":"BCHSV-USDT","changes":{"asks":[],"bids":[["242.706","0","1613277185198"]]},"sequenceEnd":1613277185198},"subject":"trade.l2update","topic":"/market/level2:BCHSV-USDT","type":"message"}
1619378343.888187: {"data":{"sequenceStart":1613277185199,"symbol":"BCHSV-USDT","changes":{"asks":[["0","0","1613277185199"]],"bids":[]},"sequenceEnd":1613277185199},"subject":"trade.l2update","topic":"/market/level2:BCHSV-USDT","type":"message"}
1619378343.888242: {"data":{"sequenceStart":1613277185200,"symbol":"BCHSV-USDT","changes":{"asks":[["243.154","2.99","1613277185200"]],"bids":[]},"sequenceEnd":1613277185200},"subject":"trade.l2update","topic":"/market/level2:BCHSV-USDT","type":"message"}
1619378343.888305: {"data":{"sequenceStart":1612844052033,"symbol":"SNX-BTC","changes":{"asks":[],"bids":[["0.00028614","0","1612844052033"]]},"sequenceEnd":1612844052033},"subject":"trade.l2update","topic":"/market/level2:SNX-BTC","type":"message"}
1619378343.895522: {"data":{"sequenceStart":1613277185201,"symbol":"BCHSV-USDT","changes":{"asks":[["0","0","1613277185201"]],"bids":[]},"sequenceEnd":1613277185201},"subject":"trade.l2update","topic":"/market/level2:BCHSV-USDT","type":"message"}
1619378343.895633: {"data":{"sequenceStart":1613277185202,"symbol":"BCHSV-USDT","changes":{"asks":[["243.154","5.98","1613277185202"]],"bids":[]},"sequenceEnd":1613277185202},"subject":"trade.l2update","topic":"/market/level2:BCHSV-USDT","type":"message"}
1619378343.895699: {"data":{"sequenceStart":1613277185203,"symbol":"BCHSV-USDT","changes":{"asks":[],"bids":[["0","0","1613277185203"]]},"sequenceEnd":1613277185203},"subject":"trade.l2update","topic":"/market/level2:BCHSV-USDT","type":"message"}
1619378343.895742: {"data":{"sequenceStart":1613277185204,"symbol":"BCHSV-USDT","changes":{"asks":[],"bids":[["242.71","5","1613277185204"]]},"sequenceEnd":1613277185204},"subject":"trade.l2update","topic":"/market/level2:BCHSV-USDT","type":"message"}
1619378343.895799: {"data":{"sequenceStart":1612702190356,"symbol":"NRG-BTC","changes":{"asks":[],"bids":[["0.00006074","0","1612702190356"]]},"sequenceEnd":1612702190356},"subject":"trade.l2update","topic":"/market/level2:NRG-BTC","type":"message"}
1619378343.919283: {"data":{"sequenceStart":1612702190357,"symbol":"NRG-BTC","changes":{"asks":[],"bids":[["0","0","1612702190357"]]},"sequenceEnd":1612702190357},"subject":"trade.l2update","topic":"/market/level2:NRG-BTC","type":"message"}
1619378343.919392: {"data":{"sequenceStart":1612702190358,"symbol":"NRG-BTC","changes":{"asks":[],"bids":[["0.00006082","31.5567","1612702190358"]]},"sequenceEnd":1612702190358},"subject":"trade.l2update","topic":"/market/level2:NRG-BTC","type":"message"}
1619378343.927401: {"data":{"sequenceStart":1613277185205,"symbol":"BCHSV-USDT","changes":{"asks":[],"bids":[["242.702","0","1613277185205"]]},"sequenceEnd":1613277185205},"subject":"trade.l2update","topic":"/market/level2:BCHSV-USDT","type":"message"}
1619378343.932158: {"data":{"sequence":"1612702190358","bestAsk":"0.00006218","size":"0.0431","bestBidSize":"18.897","price":"0.00006141","time":1619378343891,"bestAskSize":"43.3399","bestBid":"0.0000614"},"subject":"trade.ticker","topic":"/market/ticker:NRG-BTC","type":"message"}
1619378343.93225: {"data":{"sequenceStart":1613277185206,"symbol":"BCHSV-USDT","changes":{"asks":[["243.848","0","1613277185206"]],"bids":[]},"sequenceEnd":1613277185206},"subject":"trade.l2update","topic":"/market/level2:BCHSV-USDT","type":"message"}
1619378343.932348: {"data":{"sequenceStart":1613277185207,"symbol":"BCHSV-USDT","changes":{"asks":[["243.655","0","1613277185207"]],"bids":[]},"sequenceEnd":1613277185207},"subject":"trade.l2update","topic":"/market/level2:BCHSV-USDT","type":"message"}
1619378343.932412: {"data":{"sequenceStart":1613277185208,"symbol":"BCHSV-USDT","changes":{"asks":[],"bids":[["0","0","1613277185208"]]},"sequenceEnd":1613277185208},"subject":"trade.l2update","topic":"/market/level2:BCHSV-USDT","type":"message"}
1619378343.93247: {"data":{"sequenceStart":1613277185209,"symbol":"BCHSV-USDT","changes":{"asks":[],"bids":[["242.583","0.50082074","1613277185209"]]},"sequenceEnd":1613277185209},"subject":"trade.l2update","topic":"/market/level2:BCHSV-USDT","type":"message"}
1619378343.947402: {"data":{"sequenceStart":1612712745732,"symbol":"FET-BTC","changes":{"asks":[["0.00000781","0","1612712745732"]],"bids":[]},"sequenceEnd":1612712745732},"subject":"trade.l2update","topic":"/market/level2:FET-BTC","type":"message"}
1619378343.947546: {"data":{"sequenceStart":1613277185210,"symbol":"BCHSV-USDT","changes":{"asks":[],"bids":[["0","0","1613277185210"]]},"sequenceEnd":1613277185210},"subject":"trade.l2update","topic":"/market/level2:BCHSV-USDT","type":"message"}
1619378343.947603: {"data":{"sequenceStart":1613277185211,"symbol":"BCHSV-USDT","changes":{"asks":[],"bids":[["242.719","0.68148185","1613277185211"]]},"sequenceEnd":1613277185211},"subject":"trade.l2update","topic":"/market/level2:BCHSV-USDT","type":"message"}
1619378343.947665: {"data":{"sequenceStart":1613277185212,"symbol":"BCHSV-USDT","changes":{"asks":[["0","0","1613277185212"]],"bids":[]},"sequenceEnd":1613277185212},"subject":"trade.l2update","topic":"/market/level2:BCHSV-USDT","type":"message"}
1619378343.947735: {"data":{"sequenceStart":1613277185213,"symbol":"BCHSV-USDT","changes":{"asks":[["243.434","0.6","1613277185213"]],"bids":[]},"sequenceEnd":1613277185213},"subject":"trade.l2update","topic":"/market/level2:BCHSV-USDT","type":"message"}
1619378343.957259: {"data":{"sequenceStart":1612712745733,"symbol":"FET-BTC","changes":{"asks":[["0","0","1612712745733"]],"bids":[]},"sequenceEnd":1612712745733},"subject":"trade.l2update","topic":"/market/level2:FET-BTC","type":"message"}
1619378343.9573681: {"data":{"sequenceStart":1612712745734,"symbol":"FET-BTC","changes":{"asks":[["0.00000781","148.4999","1612712745734"]],"bids":[]},"sequenceEnd":1612712745734},"subject":"trade.l2update","topic":"/market/level2:FET-BTC","type":"message"}
1619378343.957452: {"data":{"sequenceStart":1613277185214,"symbol":"BCHSV-USDT","changes":{"asks":[],"bids":[["242.583","0.05000051","1613277185214"]]},"sequenceEnd":1613277185214},"subject":"trade.l2update","topic":"/market/level2:BCHSV-USDT","type":"message"}
1619378343.96269: {"data":{"sequence":"1612844052033","bestAsk":"0.00028711","size":"0.01745248","bestBidSize":"0.19100065","price":"0.00028676","time":1619378343923,"bestAskSize":"43.28403854","bestBid":"0.00028678"},"subject":"trade.ticker","topic":"/market/ticker:SNX-BTC","type":"message"}
1619378343.967627: {"data":{"sequenceStart":1613277185215,"symbol":"BCHSV-USDT","changes":{"asks":[],"bids":[["242.71","0","1613277185215"]]},"sequenceEnd":1613277185215},"subject":"trade.l2update","topic":"/market/level2:BCHSV-USDT","type":"message"}
1619378343.967765: {"data":{"sequence":"1613277185215","bestAsk":"243.036","size":"0.14324938","bestBidSize":"0.68148185","price":"242.781","time":1619378343932,"bestAskSize":"9.62448872","bestBid":"242.719"},"subject":"trade.ticker","topic":"/market/ticker:BCHSV-USDT","type":"message"}
1619378343.990617: {"data":{"sequenceStart":1613277185216,"symbol":"BCHSV-USDT","changes":{"asks":[["243.14","0","1613277185216"]],"bids":[]},"sequenceEnd":1613277185216},"subject":"trade.l2update","topic":"/market/level2:BCHSV-USDT","type":"message"}
1619378343.990755: {"data":{"sequenceStart":1613277185217,"symbol":"BCHSV-USDT","changes":{"asks":[],"bids":[["241.769","0","1613277185217"]]},"sequenceEnd":1613277185217},"subject":"trade.l2update","topic":"/market/level2:BCHSV-USDT","type":"message"}
1619378343.990828: {"data":{"sequenceStart":1613277185218,"symbol":"BCHSV-USDT","changes":{"asks":[["0","0","1613277185218"]],"bids":[]},"sequenceEnd":1613277185218},"subject":"trade.l2update","topic":"/market/level2:BCHSV-USDT","type":"message"}
1619378343.990881: {"data":{"sequenceStart":1613277185219,"symbol":"BCHSV-USDT","changes":{"asks":[["243.655","5.52","1613277185219"]],"bids":[]},"sequenceEnd":1613277185219},"subject":"trade.l2update","topic":"/market/level2:BCHSV-USDT","type":"message"}
1619378343.9909341: {"data":{"sequenceStart":1613277185220,"symbol":"BCHSV-USDT","changes":{"asks":[["243.109","0","1613277185220"]],"bids":[]},"sequenceEnd":1613277185220},"subject":"trade.l2update","topic":"/market/level2:BCHSV-USDT","type":"message"}
1619378343.990966: {"data":{"sequenceStart":1613277185221,"symbol":"BCHSV-USDT","changes":{"asks":[["0","0","1613277185221"]],"bids":[]},"sequenceEnd":1613277185221},"subject":"trade.l2update","topic":"/market/level2:BCHSV-USDT","type":"message"}
1619378343.990988: {"data":{"sequenceStart":1613277185222,"symbol":"BCHSV-USDT","changes":{"asks":[["243.898","20.43","1613277185222"]],"bids":[]},"sequenceEnd":1613277185222},"subject":"trade.l2update","topic":"/market/level2:BCHSV-USDT","type":"message"}
1619378344.005973: {"data":{"sequence":"1612712745734","bestAsk":"0.00000776","size":"12.2091","bestBidSize":"357.2953","price":"0.00000776","time":1619378343969,"bestAskSize":"1141.8325","bestBid":"0.00000771"},"subject":"trade.ticker","topic":"/market/ticker:FET-BTC","type":"message"}
1619378344.06608: {"data":{"sequence":"1613277185222","bestAsk":"243.036","size":"0.14324938","bestBidSize":"0.68148185","price":"242.781","time":1619378344030,"bestAskSize":"9.62448872","bestBid":"242.719"},"subject":"trade.ticker","topic":"/market/ticker:BCHSV-USDT","type":"message"}
1619378344.085921: {"data":{"sequenceStart":1613277185223,"symbol":"BCHSV-USDT","changes":{"asks":[],"bids":[["0","0","1613277185223"]]},"sequenceEnd":1613277185223},"subject":"trade.l2update","topic":"/market/level2:BCHSV-USDT","type":"message"}
1619378344.086008: {"data":{"sequenceStart":1613277185224,"symbol":"BCHSV-USDT","changes":{"asks":[],"bids":[["242.725","5","1613277185224"]]},"sequenceEnd":1613277185224},"subject":"trade.l2update","topic":"/market/level2:BCHSV-USDT","type":"message"}
1619378344.116516: {"data":{"sequenceStart":1612844052034,"symbol":"SNX-BTC","changes":{"asks":[["0.00028711","14.03833171","1612844052034"]],"bids":[]},"sequenceEnd":1612844052034},"subject":"trade.l2update","topic":"/market/level2:SNX-BTC","type":"message"}
1619378344.1166432: {"data":{"sequenceStart":1613277185225,"symbol":"BCHSV-USDT","changes":{"asks":[],"bids":[["0","0","1613277185225"]]},"sequenceEnd":1613277185225},"subject":"trade.l2update","topic":"/market/level2:BCHSV-USDT","type":"message"}
1619378344.1166961: {"data":{"sequenceStart":1613277185226,"symbol":"BCHSV-USDT","changes":{"asks":[],"bids":[["242.583","0.50082074","1613277185226"]]},"sequenceEnd":1613277185226},"subject":"trade.l2update","topic":"/market/level2:BCHSV-USDT","type":"message"}
1619378344.1258712: {"data":{"sequenceStart":1613277185227,"symbol":"BCHSV-USDT","changes":{"asks":[["243.434","0","1613277185227"]],"bids":[]},"sequenceEnd":1613277185227},"subject":"trade.l2update","topic":"/market/level2:BCHSV-USDT","type":"message"}
1619378344.1389802: {"data":{"sequenceStart":1613277185228,"symbol":"BCHSV-USDT","changes":{"asks":[],"bids":[["242.719","0","1613277185228"]]},"sequenceEnd":1613277185228},"subject":"trade.l2update","topic":"/market/level2:BCHSV-USDT","type":"message"}
1619378344.154277: {"data":{"sequenceStart":1612844052035,"symbol":"SNX-BTC","changes":{"asks":[],"bids":[["0","0","1612844052035"]]},"sequenceEnd":1612844052035},"subject":"trade.l2update","topic":"/market/level2:SNX-BTC","type":"message"}
1619378344.1544042: {"data":{"sequenceStart":1612844052036,"symbol":"SNX-BTC","changes":{"asks":[],"bids":[["0.0002866","14.067532","1612844052036"]]},"sequenceEnd":1612844052036},"subject":"trade.l2update","topic":"/market/level2:SNX-BTC","type":"message"}
1619378344.154486: {"data":{"sequenceStart":1613277185229,"symbol":"BCHSV-USDT","changes":{"asks":[],"bids":[["242.583","0.05000051","1613277185229"]]},"sequenceEnd":1613277185229},"subject":"trade.l2update","topic":"/market/level2:BCHSV-USDT","type":"message"}
1619378344.154539: {"data":{"sequenceStart":1613277185230,"symbol":"BCHSV-USDT","changes":{"asks":[],"bids":[["0","0","1613277185230"]]},"sequenceEnd":1613277185230},"subject":"trade.l2update","topic":"/market/level2:BCHSV-USDT","type":"message"}
1619378344.1545951: {"data":{"sequenceStart":1613277185231,"symbol":"BCHSV-USDT","changes":{"asks":[],"bids":[["242.765","0.68148185","1613277185231"]]},"sequenceEnd":1613277185231},"subject":"trade.l2update","topic":"/market/level2:BCHSV-USDT","type":"message"}
1619378344.1602292: {"data":{"sequenceStart":1613277185232,"symbol":"BCHSV-USDT","changes":{"asks":[],"bids":[["0","0","1613277185232"]]},"sequenceEnd":1613277185232},"subject":"trade.l2update","topic":"/market/level2:BCHSV-USDT","type":"message"}
1619378344.160337: {"data":{"sequenceStart":1613277185233,"symbol":"BCHSV-USDT","changes":{"asks":[],"bids":[["242.719","19.727","1613277185233"]]},"sequenceEnd":1613277185233},"subject":"trade.l2update","topic":"/market/level2:BCHSV-USDT","type":"message"}
1619378344.160436: {"data":{"sequence":"1612844052036","bestAsk":"0.00028711","size":"0.01745248","bestBidSize":"0.19100065","price":"0.00028676","time":1619378344123,"bestAskSize":"14.03833171","bestBid":"0.00028678"},"subject":"trade.ticker","topic":"/market/ticker:SNX-BTC","type":"message"}
1619378344.1705: {"data":{"sequence":"1613277185233","bestAsk":"243.036","size":"0.14324938","bestBidSize":"0.68148185","price":"242.781","time":1619378344130,"bestAskSize":"9.62448872","bestBid":"242.765"},"subject":"trade.ticker","topic":"/market/ticker:BCHSV-USDT","type":"message"}
1619378344.170607: {"data":{"sequenceStart":1613277185234,"symbol":"BCHSV-USDT","changes":{"asks":[],"bids":[["242.725","0","1613277185234"]]},"sequenceEnd":1613277185234},"subject":"trade.l2update","topic":"/market/level2:BCHSV-USDT","type":"message"}
1619378344.1773021: {"data":{"sequenceStart":1613277185235,"symbol":"BCHSV-USDT","changes":{"asks":[],"bids":[["0","0","1613277185235"]]},"sequenceEnd":1613277185235},"subject":"trade.l2update","topic":"/market/level2:BCHSV-USDT","type":"message"}
1619378344.1774132: {"data":{"sequenceStart":1613277185236,"symbol":"BCHSV-USDT","changes":{"asks":[],"bids":[["242.768","5","1613277185236"]]},"sequenceEnd":1613277185236},"subject":"trade.l2update","topic":"/market/level2:BCHSV-USDT","type":"message"}
1619378344.1905751: {"data":{"sequenceStart":1613277185237,"symbol":"BCHSV-USDT","changes":{"asks":[],"bids":[["0","0","1613277185237"]]},"sequenceEnd":1613277185237},"subject":"trade.l2update","topic":"/market/level2:BCHSV-USDT","type":"message"}
1619378344.1906838: {"data":{"sequenceStart":1613277185238,"symbol":"BCHSV-USDT","changes":{"asks":[],"bids":[["242.719","41.139","1613277185238"]]},"sequenceEnd":1613277185238},"subject":"trade.l2update","topic":"/market/level2:BCHSV-USDT","type":"message"}
1619378344.225108: {"data":{"sequenceStart":1613277185239,"symbol":"BCHSV-USDT","changes":{"asks":[["243.036","0","1613277185239"]],"bids":[]},"sequenceEnd":1613277185239},"subject":"trade.l2update","topic":"/market/level2:BCHSV-USDT","type":"message"}
1619378344.225248: {"data":{"sequenceStart":1613277185240,"symbol":"BCHSV-USDT","changes":{"asks":[],"bids":[["241.707","0","1613277185240"]]},"sequenceEnd":1613277185240},"subject":"trade.l2update","topic":"/market/level2:BCHSV-USDT","type":"message"}
1619378344.239653: {"data":{"sequenceStart":1613277185241,"symbol":"BCHSV-USDT","changes":{"asks":[],"bids":[["242.765","0","1613277185241"]]},"sequenceEnd":1613277185241},"subject":"trade.l2update","topic":"/market/level2:BCHSV-USDT","type":"message"}
1619378344.255454: {"data":{"sequenceStart":1613277185242,"symbol":"BCHSV-USDT","changes":{"asks":[],"bids":[["0","0","1613277185242"]]},"sequenceEnd":1613277185242},"subject":"trade.l2update","topic":"/market/level2:BCHSV-USDT","type":"message"}
1619378344.255489: {"data":{"sequenceStart":1613277185243,"symbol":"BCHSV-USDT","changes":{"asks":[],"bids":[["242.782","0.68148185","1613277185243"]]},"sequenceEnd":1613277185243},"subject":"trade.l2update","topic":"/market/level2:BCHSV-USDT","type":"message"}
1619378344.268712: {"data":{"sequenceStart":1613277185244,"symbol":"BCHSV-USDT","changes":{"asks":[],"bids":[["0","0","1613277185244"]]},"sequenceEnd":1613277185244},"subject":"trade.l2update","topic":"/market/level2:BCHSV-USDT","type":"message"}
1619378344.268778: {"data":{"sequenceStart":1613277185245,"symbol":"BCHSV-USDT","changes":{"asks":[],"bids":[["242.809","4.51280965","1613277185245"]]},"sequenceEnd":1613277185245},"subject":"trade.l2update","topic":"/market/level2:BCHSV-USDT","type":"message"}
1619378344.268811: {"data":{"sequence":"1613277185245","bestAsk":"243.073","size":"0.14324938","bestBidSize":"4.51280965","price":"242.781","time":1619378344230,"bestAskSize":"0.96","bestBid":"242.809"},"subject":"trade.ticker","topic":"/market/ticker:BCHSV-USDT","type":"message"}
1619378344.281446: {"data":{"sequenceStart":1613277185246,"symbol":"BCHSV-USDT","changes":{"asks":[["0","0","1613277185246"]],"bids":[]},"sequenceEnd":1613277185246},"subject":"trade.l2update","topic":"/market/level2:BCHSV-USDT","type":"message"}
1619378344.281555: {"data":{"sequenceStart":1613277185247,"symbol":"BCHSV-USDT","changes":{"asks":[["243.438","0.6","1613277185247"]],"bids":[]},"sequenceEnd":1613277185247},"subject":"trade.l2update","topic":"/market/level2:BCHSV-USDT","type":"message"}
1619378344.281632: {"data":{"sequenceStart":1613277185248,"symbol":"BCHSV-USDT","changes":{"asks":[["0","0","1613277185248"]],"bids":[]},"sequenceEnd":1613277185248},"subject":"trade.l2update","topic":"/market/level2:BCHSV-USDT","type":"message"}
1619378344.281673: {"data":{"sequenceStart":1613277185249,"symbol":"BCHSV-USDT","changes":{"asks":[["243.08","4.51280965","1613277185249"]],"bids":[]},"sequenceEnd":1613277185249},"subject":"trade.l2update","topic":"/market/level2:BCHSV-USDT","type":"message"}
1619378344.296798: {"data":{"sequenceStart":1612844052037,"symbol":"SNX-BTC","changes":{"asks":[["0.00029398","0","1612844052037"]],"bids":[]},"sequenceEnd":1612844052037},"subject":"trade.l2update","topic":"/market/level2:SNX-BTC","type":"message"}
1619378344.358243: {"data":{"sequence":"1612844052037","bestAsk":"0.00028711","size":"0.01745248","bestBidSize":"0.19100065","price":"0.00028676","time":1619378344323,"bestAskSize":"14.03833171","bestBid":"0.00028678"},"subject":"trade.ticker","topic":"/market/ticker:SNX-BTC","type":"message"}
1619378344.358334: {"data":{"sequenceStart":1613277185250,"symbol":"BCHSV-USDT","changes":{"asks":[],"bids":[["0","0","1613277185250"]]},"sequenceEnd":1613277185250},"subject":"trade.l2update","topic":"/market/level2:BCHSV-USDT","type":"message"}
1619378344.358402: {"data":{"sequenceStart":1613277185251,"symbol":"BCHSV-USDT","changes":{"asks":[],"bids":[["241.714","9.25190589","1613277185251"]]},"sequenceEnd":1613277185251},"subject":"trade.l2update","topic":"/market/level2:BCHSV-USDT","type":"message"}
1619378344.3692968: {"data":{"sequence":"1613277185254","bestAsk":"243.073","size":"0.14324938","bestBidSize":"4.51280965","price":"242.781","time":1619378344332,"bestAskSize":"0.96","bestBid":"242.809"},"subject":"trade.ticker","topic":"/market/ticker:BCHSV-USDT","type":"message"}
1619378344.369387: {"data":{"sequenceStart":1613277185252,"symbol":"BCHSV-USDT","changes":{"asks":[],"bids":[["242.768","0","1613277185252"]]},"sequenceEnd":1613277185252},"subject":"trade.l2update","topic":"/market/level2:BCHSV-USDT","type":"message"}
1619378344.369484: {"data":{"sequenceStart":1613277185253,"symbol":"BCHSV-USDT","changes":{"asks":[["0","0","1613277185253"]],"bids":[]},"sequenceEnd":1613277185253},"subject":"trade.l2update","topic":"/market/level2:BCHSV-USDT","type":"message"}
1619378344.369534: {"data":{"sequenceStart":1613277185254,"symbol":"BCHSV-USDT","changes":{"asks":[["243.897","9.57806988","1613277185254"]],"bids":[]},"sequenceEnd":1613277185254},"subject":"trade.l2update","topic":"/market/level2:BCHSV-USDT","type":"message"}
1619378344.3808892: {"data":{"sequenceStart":1613277185255,"symbol":"BCHSV-USDT","changes":{"asks":[],"bids":[["0","0","1613277185255"]]},"sequenceEnd":1613277185255},"subject":"trade.l2update","topic":"/market/level2:BCHSV-USDT","type":"message"}
1619378344.381004: {"data":{"sequenceStart":1613277185256,"symbol":"BCHSV-USDT","changes":{"asks":[],"bids":[["241.844","4.28933964","1613277185256"]]},"sequenceEnd":1613277185256},"subject":"trade.l2update","topic":"/market/level2:BCHSV-USDT","type":"message"}
1619378344.3810828: {"data":{"sequenceStart":1613277185257,"symbol":"BCHSV-USDT","changes":{"asks":[],"bids":[["0","0","1613277185257"]]},"sequenceEnd":1613277185257},"subject":"trade.l2update","topic":"/market/level2:BCHSV-USDT","type":"message"}
1619378344.381124: {"data":{"sequenceStart":1613277185258,"symbol":"BCHSV-USDT","changes":{"asks":[],"bids":[["242.786","5","1613277185258"]]},"sequenceEnd":1613277185258},"subject":"trade.l2update","topic":"/market/level2:BCHSV-USDT","type":"message"}
1619378344.381172: {"data":{"sequenceStart":1613277185259,"symbol":"BCHSV-USDT","changes":{"asks":[["0","0","1613277185259"]],"bids":[]},"sequenceEnd":1613277185259},"subject":"trade.l2update","topic":"/market/level2:BCHSV-USDT","type":"message"}
1619378344.381207: {"data":{"sequenceStart":1613277185260,"symbol":"BCHSV-USDT","changes":{"asks":[["243.149","4.28933964","1613277185260"]],"bids":[]},"sequenceEnd":1613277185260},"subject":"trade.l2update","topic":"/market/level2:BCHSV-USDT","type":"message"}
1619378344.381254: {"data":{"sequenceStart":1613277185261,"symbol":"BCHSV-USDT","changes":{"asks":[["0","0","1613277185261"]],"bids":[]},"sequenceEnd":1613277185261},"subject":"trade.l2update","topic":"/market/level2:BCHSV-USDT","type":"message"}
1619378344.381286: {"data":{"sequenceStart":1613277185262,"symbol":"BCHSV-USDT","changes":{"asks":[["243.198","8.57867928","1613277185262"]],"bids":[]},"sequenceEnd":1613277185262},"subject":"trade.l2update","topic":"/market/level2:BCHSV-USDT","type":"message"}
1619378344.408407: {"data":{"sequenceStart":1613277185263,"symbol":"BCHSV-USDT","changes":{"asks":[],"bids":[["242.45","0","1613277185263"]]},"sequenceEnd":1613277185263},"subject":"trade.l2update","topic":"/market/level2:BCHSV-USDT","type":"message"}
1619378344.421985: {"data":{"sequenceStart":1613277185264,"symbol":"BCHSV-USDT","changes":{"asks":[["243.155","0","1613277185264"]],"bids":[]},"sequenceEnd":1613277185264},"subject":"trade.l2update","topic":"/market/level2:BCHSV-USDT","type":"message"}
1619378344.441943: {"data":{"sequenceStart":1613277185265,"symbol":"BCHSV-USDT","changes":{"asks":[["243.438","0","1613277185265"]],"bids":[]},"sequenceEnd":1613277185265},"subject":"trade.l2update","topic":"/market/level2:BCHSV-USDT","type":"message"}
1619378344.442061: {"data":{"sequenceStart":1613277185266,"symbol":"BCHSV-USDT","changes":{"asks":[],"bids":[["242.782","0","1613277185266"]]},"sequenceEnd":1613277185266},"subject":"trade.l2update","topic":"/market/level2:BCHSV-USDT","type":"message"}
1619378344.454242: {"data":{"sequenceStart":1613277185267,"symbol":"BCHSV-USDT","changes":{"asks":[["0","0","1613277185267"]],"bids":[]},"sequenceEnd":1613277185267},"subject":"trade.l2update","topic":"/market/level2:BCHSV-USDT","type":"message"}
1619378344.4542878: {"data":{"sequenceStart":1613277185268,"symbol":"BCHSV-USDT","changes":{"asks":[["243.437","0.6","1613277185268"]],"bids":[]},"sequenceEnd":1613277185268},"subject":"trade.l2update","topic":"/market/level2:BCHSV-USDT","type":"message"}
1619378344.454328: {"data":{"sequenceStart":1613277185269,"symbol":"BCHSV-USDT","changes":{"asks":[],"bids":[["0","0","1613277185269"]]},"sequenceEnd":1613277185269},"subject":"trade.l2update","topic":"/market/level2:BCHSV-USDT","type":"message"}
1619378344.45435: {"data":{"sequenceStart":1613277185270,"symbol":"BCHSV-USDT","changes":{"asks":[],"bids":[["242.784","0.68148185","1613277185270"]]},"sequenceEnd":1613277185270},"subject":"trade.l2update","topic":"/market/level2:BCHSV-USDT","type":"message"}
1619378344.461932: {"data":{"sequenceStart":1613277185271,"symbol":"BCHSV-USDT","changes":{"asks":[],"bids":[["242.786","0","1613277185271"]]},"sequenceEnd":1613277185271},"subject":"trade.l2update","topic":"/market/level2:BCHSV-USDT","type":"message"}
1619378344.4719381: {"data":{"sequence":"1613277185271","bestAsk":"243.073","size":"0.14324938","bestBidSize":"4.51280965","price":"242.781","time":1619378344432,"bestAskSize":"0.96","bestBid":"242.809"},"subject":"trade.ticker","topic":"/market/ticker:BCHSV-USDT","type":"message"}
1619378344.478534: {"data":{"sequenceStart":1612712745735,"symbol":"FET-BTC","changes":{"asks":[["0","0","1612712745735"]],"bids":[]},"sequenceEnd":1612712745735},"subject":"trade.l2update","topic":"/market/level2:FET-BTC","type":"message"}
1619378344.478646: {"data":{"sequenceStart":1612712745736,"symbol":"FET-BTC","changes":{"asks":[["0.0000078","1514.0642","1612712745736"]],"bids":[]},"sequenceEnd":1612712745736},"subject":"trade.l2update","topic":"/market/level2:FET-BTC","type":"message"}
1619378344.496133: {"data":{"sequenceStart":1612712745737,"symbol":"FET-BTC","changes":{"asks":[["0.0000078","0","1612712745737"]],"bids":[]},"sequenceEnd":1612712745737},"subject":"trade.l2update","topic":"/market/level2:FET-BTC","type":"message"}
1619378344.506162: {"data":{"sequenceStart":1613277185272,"symbol":"BCHSV-USDT","changes":{"asks":[["0","0","1613277185272"]],"bids":[]},"sequenceEnd":1613277185272},"subject":"trade.l2update","topic":"/market/level2:BCHSV-USDT","type":"message"}
1619378344.506273: {"data":{"sequenceStart":1613277185273,"symbol":"BCHSV-USDT","changes":{"asks":[["244.395","150","1613277185273"]],"bids":[]},"sequenceEnd":1613277185273},"subject":"trade.l2update","topic":"/market/level2:BCHSV-USDT","type":"message"}
1619378344.506353: {"data":{"sequenceStart":1613277185274,"symbol":"BCHSV-USDT","changes":{"asks":[["0","0","1613277185274"]],"bids":[]},"sequenceEnd":1613277185274},"subject":"trade.l2update","topic":"/market/level2:BCHSV-USDT","type":"message"}
1619378344.506397: {"data":{"sequenceStart":1613277185275,"symbol":"BCHSV-USDT","changes":{"asks":[["243.758","5","1613277185275"]],"bids":[]},"sequenceEnd":1613277185275},"subject":"trade.l2update","topic":"/market/level2:BCHSV-USDT","type":"message"}
1619378344.506447: {"data":{"sequenceStart":1613277185276,"symbol":"BCHSV-USDT","changes":{"asks":[],"bids":[["0","0","1613277185276"]]},"sequenceEnd":1613277185276},"subject":"trade.l2update","topic":"/market/level2:BCHSV-USDT","type":"message"}
1619378344.506484: {"data":{"sequenceStart":1613277185277,"symbol":"BCHSV-USDT","changes":{"asks":[],"bids":[["241.596","5","1613277185277"]]},"sequenceEnd":1613277185277},"subject":"trade.l2update","topic":"/market/level2:BCHSV-USDT","type":"message"}
1619378344.5065532: {"data":{"sequenceStart":1613277185278,"symbol":"BCHSV-USDT","changes":{"asks":[],"bids":[["242.809","0","1613277185278"]]},"sequenceEnd":1613277185278},"subject":"trade.l2update","topic":"/market/level2:BCHSV-USDT","type":"message"}
1619378344.511625: {"data":{"sequence":"1612712745737","bestAsk":"0.00000776","size":"12.2091","bestBidSize":"357.2953","price":"0.00000776","time":1619378344468,"bestAskSize":"1141.8325","bestBid":"0.00000771"},"subject":"trade.ticker","topic":"/market/ticker:FET-BTC","type":"message"}
1619378344.51173: {"data":{"sequenceStart":1612712745738,"symbol":"FET-BTC","changes":{"asks":[["0.00000794","0","1612712745738"]],"bids":[]},"sequenceEnd":1612712745738},"subject":"trade.l2update","topic":"/market/level2:FET-BTC","type":"message"}
1619378344.550884: {"data":{"sequenceStart":1613277185279,"symbol":"BCHSV-USDT","changes":{"asks":[["243.897","0","1613277185279"]],"bids":[]},"sequenceEnd":1613277185279},"subject":"trade.l2update","topic":"/market/level2:BCHSV-USDT","type":"message"}
1619378344.569066: {"data":{"sequence":"1613277185279","bestAsk":"243.073","size":"0.14324938","bestBidSize":"0.68148185","price":"242.781","time":1619378344533,"bestAskSize":"0.96","bestBid":"242.784"},"subject":"trade.ticker","topic":"/market/ticker:BCHSV-USDT","type":"message"}
1619378344.577735: {"data":{"sequenceStart":1613277185280,"symbol":"BCHSV-USDT","changes":{"asks":[],"bids":[["241.714","0","1613277185280"]]},"sequenceEnd":1613277185280},"subject":"trade.l2update","topic":"/market/level2:BCHSV-USDT","type":"message"}
1619378344.577873: {"data":{"sequenceStart":1613277185281,"symbol":"BCHSV-USDT","changes":{"asks":[],"bids":[["0","0","1613277185281"]]},"sequenceEnd":1613277185281},"subject":"trade.l2update","topic":"/market/level2:BCHSV-USDT","type":"message"}
1619378344.5779269: {"data":{"sequenceStart":1613277185282,"symbol":"BCHSV-USDT","changes":{"asks":[],"bids":[["242.762","52.488","1613277185282"]]},"sequenceEnd":1613277185282},"subject":"trade.l2update","topic":"/market/level2:BCHSV-USDT","type":"message"}
1619378344.5779881: {"data":{"sequenceStart":1613277185283,"symbol":"BCHSV-USDT","changes":{"asks":[],"bids":[["0","0","1613277185283"]]},"sequenceEnd":1613277185283},"subject":"trade.l2update","topic":"/market/level2:BCHSV-USDT","type":"message"}
1619378344.578027: {"data":{"sequenceStart":1613277185284,"symbol":"BCHSV-USDT","changes":{"asks":[],"bids":[["242.782","5","1613277185284"]]},"sequenceEnd":1613277185284},"subject":"trade.l2update","topic":"/market/level2:BCHSV-USDT","type":"message"}
1619378344.608094: {"data":{"sequence":"1612712745738","bestAsk":"0.00000776","size":"12.2091","bestBidSize":"357.2953","price":"0.00000776","time":1619378344567,"bestAskSize":"1141.8325","bestBid":"0.00000771"},"subject":"trade.ticker","topic":"/market/ticker:FET-BTC","type":"message"}
1619378344.6352599: {"data":{"sequenceStart":1613277185285,"symbol":"BCHSV-USDT","changes":{"asks":[],"bids":[["242.784","0","1613277185285"]]},"sequenceEnd":1613277185285},"subject":"trade.l2update","topic":"/market/level2:BCHSV-USDT","type":"message"}
1619378344.6405382: {"data":{"sequenceStart":1613277185286,"symbol":"BCHSV-USDT","changes":{"asks":[["0","0","1613277185286"]],"bids":[]},"sequenceEnd":1613277185286},"subject":"trade.l2update","topic":"/market/level2:BCHSV-USDT","type":"message"}
1619378344.640648: {"data":{"sequenceStart":1613277185287,"symbol":"BCHSV-USDT","changes":{"asks":[["243.757","9.94353055","1613277185287"]],"bids":[]},"sequenceEnd":1613277185287},"subject":"trade.l2update","topic":"/market/level2:BCHSV-USDT","type":"message"}
1619378344.6407301: {"data":{"sequenceStart":1613277185288,"symbol":"BCHSV-USDT","changes":{"asks":[],"bids":[["0","0","1613277185288"]]},"sequenceEnd":1613277185288},"subject":"trade.l2update","topic":"/market/level2:BCHSV-USDT","type":"message"}
1619378344.640791: {"data":{"sequenceStart":1613277185289,"symbol":"BCHSV-USDT","changes":{"asks":[],"bids":[["242.14","10.13372879","1613277185289"]]},"sequenceEnd":1613277185289},"subject":"trade.l2update","topic":"/market/level2:BCHSV-USDT","type":"message"}
1619378344.640864: {"data":{"sequenceStart":1613277185290,"symbol":"BCHSV-USDT","changes":{"asks":[],"bids":[["0","0","1613277185290"]]},"sequenceEnd":1613277185290},"subject":"trade.l2update","topic":"/market/level2:BCHSV-USDT","type":"message"}
1619378344.640888: {"data":{"sequenceStart":1613277185291,"symbol":"BCHSV-USDT","changes":{"asks":[],"bids":[["242.78","0.68148185","1613277185291"]]},"sequenceEnd":1613277185291},"subject":"trade.l2update","topic":"/market/level2:BCHSV-USDT","type":"message"}
1619378344.6708748: {"data":{"sequence":"1613277185291","bestAsk":"243.073","size":"0.14324938","bestBidSize":"5","price":"242.781","time":1619378344632,"bestAskSize":"0.96","bestBid":"242.782"},"subject":"trade.ticker","topic":"/market/ticker:BCHSV-USDT","type":"message"}
1619378344.670963: {"data":{"sequenceStart":1613277185292,"symbol":"BCHSV-USDT","changes":{"asks":[],"bids":[["0","0","1613277185292"]]},"sequenceEnd":1613277185292},"subject":"trade.l2update","topic":"/market/level2:BCHSV-USDT","type":"message"}
1619378344.671028: {"data":{"sequenceStart":1613277185293,"symbol":"BCHSV-USDT","changes":{"asks":[],"bids":[["242.551","6.17411836","1613277185293"]]},"sequenceEnd":1613277185293},"subject":"trade.l2update","topic":"/market/level2:BCHSV-USDT","type":"message"}
1619378344.671099: {"data":{"sequenceStart":1613277185294,"symbol":"BCHSV-USDT","changes":{"asks":[["0","0","1613277185294"]],"bids":[]},"sequenceEnd":1613277185294},"subject":"trade.l2update","topic":"/market/level2:BCHSV-USDT","type":"message"}
1619378344.671139: {"data":{"sequenceStart":1613277185295,"symbol":"BCHSV-USDT","changes":{"asks":[["243.24","6.17411836","1613277185295"]],"bids":[]},"sequenceEnd":1613277185295},"subject":"trade.l2update","topic":"/market/level2:BCHSV-USDT","type":"message"}
1619378344.682784: {"data":{"sequenceStart":1612844052038,"symbol":"SNX-BTC","changes":{"asks":[["0","0","1612844052038"]],"bids":[]},"sequenceEnd":1612844052038},"subject":"trade.l2update","topic":"/market/level2:SNX-BTC","type":"message"}
1619378344.682892: {"data":{"sequenceStart":1612844052039,"symbol":"SNX-BTC","changes":{"asks":[["0.00028712","29.24570683","1612844052039"]],"bids":[]},"sequenceEnd":1612844052039},"subject":"trade.l2update","topic":"/market/level2:SNX-BTC","type":"message"}
1619378344.6829739: {"data":{"sequenceStart":1612844052040,"symbol":"SNX-BTC","changes":{"asks":[["0.00028712","0","1612844052040"]],"bids":[]},"sequenceEnd":1612844052040},"subject":"trade.l2update","topic":"/market/level2:SNX-BTC","type":"message"}
1619378344.683064: {"data":{"sequenceStart":1612844052041,"symbol":"SNX-BTC","changes":{"asks":[["0","0","1612844052041"]],"bids":[]},"sequenceEnd":1612844052041},"subject":"trade.l2update","topic":"/market/level2:SNX-BTC","type":"message"}
1619378344.68309: {"data":{"sequenceStart":1612844052042,"symbol":"SNX-BTC","changes":{"asks":[["0.00028711","43.28403854","1612844052042"]],"bids":[]},"sequenceEnd":1612844052042},"subject":"trade.l2update","topic":"/market/level2:SNX-BTC","type":"message"}
1619378344.6945522: {"data":{"sequenceStart":1612844052043,"symbol":"SNX-BTC","changes":{"asks":[["0","0","1612844052043"]],"bids":[]},"sequenceEnd":1612844052043},"subject":"trade.l2update","topic":"/market/level2:SNX-BTC","type":"message"}
1619378344.6946602: {"data":{"sequenceStart":1612844052044,"symbol":"SNX-BTC","changes":{"asks":[["0.00029396","765.40500797","1612844052044"]],"bids":[]},"sequenceEnd":1612844052044},"subject":"trade.l2update","topic":"/market/level2:SNX-BTC","type":"message"}
1619378344.7662039: {"data":{"sequence":"1613277185295","bestAsk":"243.073","size":"0.14324938","bestBidSize":"5","price":"242.781","time":1619378344730,"bestAskSize":"0.96","bestBid":"242.782"},"subject":"trade.ticker","topic":"/market/ticker:BCHSV-USDT","type":"message"}
1619378344.771024: {"data":{"sequenceStart":1613277185296,"symbol":"BCHSV-USDT","changes":{"asks":[],"bids":[["242.782","0","1613277185296"]]},"sequenceEnd":1613277185296},"subject":"trade.l2update","topic":"/market/level2:BCHSV-USDT","type":"message"}
1619378344.781024: {"data":{"sequence":"1612844052044","bestAsk":"0.00028711","size":"0.01745248","bestBidSize":"0.19100065","price":"0.00028676","time":1619378344746,"bestAskSize":"43.28403854","bestBid":"0.00028678"},"subject":"trade.ticker","topic":"/market/ticker:SNX-BTC","type":"message"}
1619378344.786613: {"data":{"sequenceStart":1613277185297,"symbol":"BCHSV-USDT","changes":{"asks":[],"bids":[["0","0","1613277185297"]]},"sequenceEnd":1613277185297},"subject":"trade.l2update","topic":"/market/level2:BCHSV-USDT","type":"message"}
1619378344.786724: {"data":{"sequenceStart":1613277185298,"symbol":"BCHSV-USDT","changes":{"asks":[],"bids":[["242.785","5","1613277185298"]]},"sequenceEnd":1613277185298},"subject":"trade.l2update","topic":"/market/level2:BCHSV-USDT","type":"message"}
1619378344.8316648: {"data":{"sequenceStart":1613277185299,"symbol":"BCHSV-USDT","changes":{"asks":[],"bids":[["242.78","0","1613277185299"]]},"sequenceEnd":1613277185299},"subject":"trade.l2update","topic":"/market/level2:BCHSV-USDT","type":"message"}
1619378344.8567832: {"data":{"sequenceStart":1613277185300,"symbol":"BCHSV-USDT","changes":{"asks":[],"bids":[["0","0","1613277185300"]]},"sequenceEnd":1613277185300},"subject":"trade.l2update","topic":"/market/level2:BCHSV-USDT","type":"message"}
1619378344.856894: {"data":{"sequenceStart":1613277185301,"symbol":"BCHSV-USDT","changes":{"asks":[],"bids":[["242.783","0.68148185","1613277185301"]]},"sequenceEnd":1613277185301},"subject":"trade.l2update","topic":"/market/level2:BCHSV-USDT","type":"message"}
1619378344.869233: {"data":{"sequence":"1613277185301","bestAsk":"243.073","size":"0.14324938","bestBidSize":"5","price":"242.781","time":1619378344832,"bestAskSize":"0.96","bestBid":"242.785"},"subject":"trade.ticker","topic":"/market/ticker:BCHSV-USDT","type":"message"}
1619378344.876414: {"data":{"sequenceStart":1613277185302,"symbol":"BCHSV-USDT","changes":{"asks":[],"bids":[["242.785","0","1613277185302"]]},"sequenceEnd":1613277185302},"subject":"trade.l2update","topic":"/market/level2:BCHSV-USDT","type":"message"}
1619378344.876514: {"data":{"sequenceStart":1613277185303,"symbol":"BCHSV-USDT","changes":{"asks":[],"bids":[["241.596","0","1613277185303"]]},"sequenceEnd":1613277185303},"subject":"trade.l2update","topic":"/market/level2:BCHSV-USDT","type":"message"}
1619378344.876557: {"data":{"sequenceStart":1613277185304,"symbol":"BCHSV-USDT","changes":{"asks":[["244.395","0","1613277185304"]],"bids":[]},"sequenceEnd":1613277185304},"subject":"trade.l2update","topic":"/market/level2:BCHSV-USDT","type":"message"}
1619378344.8765929: {"data":{"sequenceStart":1613277185305,"symbol":"BCHSV-USDT","changes":{"asks":[["243.758","0","1613277185305"]],"bids":[]},"sequenceEnd":1613277185305},"subject":"trade.l2update","topic":"/market/level2:BCHSV-USDT","type":"message"}
1619378344.968661: {"data":{"sequence":"1613277185305","bestAsk":"243.073","size":"0.14324938","bestBidSize":"0.68148185","price":"242.781","time":1619378344931,"bestAskSize":"0.96","bestBid":"242.783"},"subject":"trade.ticker","topic":"/market/ticker:BCHSV-USDT","type":"message"}
1619378344.989125: {"data":{"sequenceStart":1613277185306,"symbol":"BCHSV-USDT","changes":{"asks":[],"bids":[["240.315","0","1613277185306"]]},"sequenceEnd":1613277185306},"subject":"trade.l2update","topic":"/market/level2:BCHSV-USDT","type":"message"}
1619378344.98925: {"data":{"sequenceStart":1613277185307,"symbol":"BCHSV-USDT","changes":{"asks":[],"bids":[["0","0","1613277185307"]]},"sequenceEnd":1613277185307},"subject":"trade.l2update","topic":"/market/level2:BCHSV-USDT","type":"message"}
1619378344.989302: {"data":{"sequenceStart":1613277185308,"symbol":"BCHSV-USDT","changes":{"asks":[],"bids":[["242.786","5","1613277185308"]]},"sequenceEnd":1613277185308},"subject":"trade.l2update","topic":"/market/level2:BCHSV-USDT","type":"message"}
1619378344.9893591: {"data":{"sequenceStart":1613277185309,"symbol":"BCHSV-USDT","changes":{"asks":[],"bids":[["0","0","1613277185309"]]},"sequenceEnd":1613277185309},"subject":"trade.l2update","topic":"/market/level2:BCHSV-USDT","type":"message"}
1619378344.989395: {"data":{"sequenceStart":1613277185310,"symbol":"BCHSV-USDT","changes":{"asks":[],"bids":[["240.399","2.07987552","1613277185310"]]},"sequenceEnd":1613277185310},"subject":"trade.l2update","topic":"/market/level2:BCHSV-USDT","type":"message"}
1619378345.044172: {"data":{"sequenceStart":1613277185311,"symbol":"BCHSV-USDT","changes":{"asks":[],"bids":[["241.654","0","1613277185311"]]},"sequenceEnd":1613277185311},"subject":"trade.l2update","topic":"/market/level2:BCHSV-USDT","type":"message"}
1619378345.070507: {"data":{"sequence":"1613277185311","bestAsk":"243.073","size":"0.14324938","bestBidSize":"5","price":"242.781","time":1619378345032,"bestAskSize":"0.96","bestBid":"242.786"},"subject":"trade.ticker","topic":"/market/ticker:BCHSV-USDT","type":"message"}
1619378345.090525: {"data":{"sequenceStart":1613277185312,"symbol":"BCHSV-USDT","changes":{"asks":[],"bids":[["0","0","1613277185312"]]},"sequenceEnd":1613277185312},"subject":"trade.l2update","topic":"/market/level2:BCHSV-USDT","type":"message"}
1619378345.090633: {"data":{"sequenceStart":1613277185313,"symbol":"BCHSV-USDT","changes":{"asks":[],"bids":[["240.445","25","1613277185313"]]},"sequenceEnd":1613277185313},"subject":"trade.l2update","topic":"/market/level2:BCHSV-USDT","type":"message"}
1619378345.131534: {"data":{"sequenceStart":1613277185314,"symbol":"BCHSV-USDT","changes":{"asks":[],"bids":[["242.783","0","1613277185314"]]},"sequenceEnd":1613277185314},"subject":"trade.l2update","topic":"/market/level2:BCHSV-USDT","type":"message"}
1619378345.1316822: {"data":{"sequenceStart":1613277185315,"symbol":"BCHSV-USDT","changes":{"asks":[],"bids":[["242.14","0","1613277185315"]]},"sequenceEnd":1613277185315},"subject":"trade.l2update","topic":"/market/level2:BCHSV-USDT","type":"message"}
1619378345.141275: {"data":{"sequenceStart":1613277185316,"symbol":"BCHSV-USDT","changes":{"asks":[["243.757","0","1613277185316"]],"bids":[]},"sequenceEnd":1613277185316},"subject":"trade.l2update","topic":"/market/level2:BCHSV-USDT","type":"message"}
1619378345.141418: {"data":{"sequenceStart":1613277185317,"symbol":"BCHSV-USDT","changes":{"asks":[],"bids":[["0","0","1613277185317"]]},"sequenceEnd":1613277185317},"subject":"trade.l2update","topic":"/market/level2:BCHSV-USDT","type":"message"}
1619378345.14147: {"data":{"sequenceStart":1613277185318,"symbol":"BCHSV-USDT","changes":{"asks":[],"bids":[["242.785","0.68148185","1613277185318"]]},"sequenceEnd":1613277185318},"subject":"trade.l2update","topic":"/market/level2:BCHSV-USDT","type":"message"}
1619378345.1676118: {"data":{"sequenceStart":1613277185319,"symbol":"BCHSV-USDT","changes":{"asks":[],"bids":[["242.786","0","1613277185319"]]},"sequenceEnd":1613277185319},"subject":"trade.l2update","topic":"/market/level2:BCHSV-USDT","type":"message"}
1619378345.167757: {"data":{"sequence":"1613277185319","bestAsk":"243.073","size":"0.14324938","bestBidSize":"0.68148185","price":"242.781","time":1619378345131,"bestAskSize":"0.96","bestBid":"242.785"},"subject":"trade.ticker","topic":"/market/ticker:BCHSV-USDT","type":"message"}
1619378345.182444: {"data":{"sequenceStart":1613277185320,"symbol":"BCHSV-USDT","changes":{"asks":[],"bids":[["0","0","1613277185320"]]},"sequenceEnd":1613277185320},"subject":"trade.l2update","topic":"/market/level2:BCHSV-USDT","type":"message"}
1619378345.1825569: {"data":{"sequenceStart":1613277185321,"symbol":"BCHSV-USDT","changes":{"asks":[],"bids":[["242.787","5","1613277185321"]]},"sequenceEnd":1613277185321},"subject":"trade.l2update","topic":"/market/level2:BCHSV-USDT","type":"message"}
1619378345.23498: {"data":{"sequenceStart":1612712745739,"symbol":"FET-BTC","changes":{"asks":[["0","0","1612712745739"]],"bids":[]},"sequenceEnd":1612712745739},"subject":"trade.l2update","topic":"/market/level2:FET-BTC","type":"message"}
1619378345.240005: {"data":{"sequenceStart":1612712745740,"symbol":"FET-BTC","changes":{"asks":[["0.0000078","595.8284","1612712745740"]],"bids":[]},"sequenceEnd":1612712745740},"subject":"trade.l2update","topic":"/market/level2:FET-BTC","type":"message"}
1619378345.280904: {"data":{"sequence":"1613277185321","bestAsk":"243.073","size":"0.14324938","bestBidSize":"5","price":"242.781","time":1619378345230,"bestAskSize":"0.96","bestBid":"242.787"},"subject":"trade.ticker","topic":"/market/ticker:BCHSV-USDT","type":"message"}
1619378345.30069: {"data":{"sequenceStart":1612712745741,"symbol":"FET-BTC","changes":{"asks":[["0","0","1612712745741"]],"bids":[]},"sequenceEnd":1612712745741},"subject":"trade.l2update","topic":"/market/level2:FET-BTC","type":"message"}
1619378345.300766: {"data":{"sequenceStart":1612712745742,"symbol":"FET-BTC","changes":{"asks":[["0.00000792","1643.1264","1612712745742"]],"bids":[]},"sequenceEnd":1612712745742},"subject":"trade.l2update","topic":"/market/level2:FET-BTC","type":"message"}
1619378345.305324: {"data":{"sequence":"1612712745742","bestAsk":"0.00000776","size":"12.2091","bestBidSize":"357.2953","price":"0.00000776","time":1619378345267,"bestAskSize":"1141.8325","bestBid":"0.00000771"},"subject":"trade.ticker","topic":"/market/ticker:FET-BTC","type":"message"}
1619378345.376121: {"data":{"sequenceStart":1613277185322,"symbol":"BCHSV-USDT","changes":{"asks":[],"bids":[["242.787","0","1613277185322"]]},"sequenceEnd":1613277185322},"subject":"trade.l2update","topic":"/market/level2:BCHSV-USDT","type":"message"}
1619378345.388072: {"data":{"sequenceStart":1613277185323,"symbol":"BCHSV-USDT","changes":{"asks":[],"bids":[["0","0","1613277185323"]]},"sequenceEnd":1613277185323},"subject":"trade.l2update","topic":"/market/level2:BCHSV-USDT","type":"message"}
1619378345.388191: {"data":{"sequenceStart":1613277185324,"symbol":"BCHSV-USDT","changes":{"asks":[],"bids":[["242.786","5","1613277185324"]]},"sequenceEnd":1613277185324},"subject":"trade.l2update","topic":"/market/level2:BCHSV-USDT","type":"message"}
1619378345.391625: {"data":{"sequenceStart":1612712745743,"symbol":"FET-BTC","changes":{"asks":[["0.0000078","0","1612712745743"]],"bids":[]},"sequenceEnd":1612712745743},"subject":"trade.l2update","topic":"/market/level2:FET-BTC","type":"message"}
1619378345.40718: {"data":{"sequence":"1612712745743","bestAsk":"0.00000776","size":"12.2091","bestBidSize":"357.2953","price":"0.00000776","time":1619378345367,"bestAskSize":"1141.8325","bestBid":"0.00000771"},"subject":"trade.ticker","topic":"/market/ticker:FET-BTC","type":"message"}
1619378345.429653: {"data":{"sequenceStart":1613277185325,"symbol":"BCHSV-USDT","changes":{"asks":[],"bids":[["242.785","0","1613277185325"]]},"sequenceEnd":1613277185325},"subject":"trade.l2update","topic":"/market/level2:BCHSV-USDT","type":"message"}
1619378345.429791: {"data":{"sequenceStart":1613277185326,"symbol":"BCHSV-USDT","changes":{"asks":[],"bids":[["0","0","1613277185326"]]},"sequenceEnd":1613277185326},"subject":"trade.l2update","topic":"/market/level2:BCHSV-USDT","type":"message"}
1619378345.429845: {"data":{"sequenceStart":1613277185327,"symbol":"BCHSV-USDT","changes":{"asks":[],"bids":[["241.715","7.20782886","1613277185327"]]},"sequenceEnd":1613277185327},"subject":"trade.l2update","topic":"/market/level2:BCHSV-USDT","type":"message"}
1619378345.455073: {"data":{"sequenceStart":1613277185328,"symbol":"BCHSV-USDT","changes":{"asks":[],"bids":[["0","0","1613277185328"]]},"sequenceEnd":1613277185328},"subject":"trade.l2update","topic":"/market/level2:BCHSV-USDT","type":"message"}
1619378345.45518: {"data":{"sequenceStart":1613277185329,"symbol":"BCHSV-USDT","changes":{"asks":[],"bids":[["242.783","0.68148185","1613277185329"]]},"sequenceEnd":1613277185329},"subject":"trade.l2update","topic":"/market/level2:BCHSV-USDT","type":"message"}
1619378345.465358: {"data":{"sequenceStart":1612712745744,"symbol":"FET-BTC","changes":{"asks":[["0","0","1612712745744"]],"bids":[]},"sequenceEnd":1612712745744},"subject":"trade.l2update","topic":"/market/level2:FET-BTC","type":"message"}
1619378345.465466: {"data":{"sequenceStart":1612712745745,"symbol":"FET-BTC","changes":{"asks":[["0.00000785","159.4","1612712745745"]],"bids":[]},"sequenceEnd":1612712745745},"subject":"trade.l2update","topic":"/market/level2:FET-BTC","type":"message"}
1619378345.4709601: {"data":{"sequence":"1613277185329","bestAsk":"243.073","size":"0.14324938","bestBidSize":"5","price":"242.781","time":1619378345432,"bestAskSize":"0.96","bestBid":"242.786"},"subject":"trade.ticker","topic":"/market/ticker:BCHSV-USDT","type":"message"}
1619378345.4802198: {"data":{"sequenceStart":1613277185330,"symbol":"BCHSV-USDT","changes":{"asks":[["0","0","1613277185330"]],"bids":[]},"sequenceEnd":1613277185330},"subject":"trade.l2update","topic":"/market/level2:BCHSV-USDT","type":"message"}
1619378345.48033: {"data":{"sequenceStart":1613277185331,"symbol":"BCHSV-USDT","changes":{"asks":[["244.476","150","1613277185331"]],"bids":[]},"sequenceEnd":1613277185331},"subject":"trade.l2update","topic":"/market/level2:BCHSV-USDT","type":"message"}
1619378345.480412: {"data":{"sequenceStart":1613277185332,"symbol":"BCHSV-USDT","changes":{"asks":[],"bids":[["0","0","1613277185332"]]},"sequenceEnd":1613277185332},"subject":"trade.l2update","topic":"/market/level2:BCHSV-USDT","type":"message"}
1619378345.4804559: {"data":{"sequenceStart":1613277185333,"symbol":"BCHSV-USDT","changes":{"asks":[],"bids":[["241.676","5","1613277185333"]]},"sequenceEnd":1613277185333},"subject":"trade.l2update","topic":"/market/level2:BCHSV-USDT","type":"message"}
1619378345.480546: {"data":{"sequenceStart":1613277185334,"symbol":"BCHSV-USDT","changes":{"asks":[["0","0","1613277185334"]],"bids":[]},"sequenceEnd":1613277185334},"subject":"trade.l2update","topic":"/market/level2:BCHSV-USDT","type":"message"}
1619378345.48057: {"data":{"sequenceStart":1613277185335,"symbol":"BCHSV-USDT","changes":{"asks":[["243.838","5","1613277185335"]],"bids":[]},"sequenceEnd":1613277185335},"subject":"trade.l2update","topic":"/market/level2:BCHSV-USDT","type":"message"}
