1619378330.992312: {"data":{"sequenceStart":1613277184190,"symbol":"BCHSV-USDT","changes":{"asks":[],"bids":[["241.946","0","1613277184190"]]},"sequenceEnd":1613277184190},"subject":"trade.l2update","topic":"/market/level2:BCHSV-USDT","type":"message"}
1619378330.9923992: {"data":{"sequenceStart":1613277184191,"symbol":"BCHSV-USDT","changes":{"asks":[],"bids":[["242.139","0","1613277184191"]]},"sequenceEnd":1613277184191},"subject":"trade.l2update","topic":"/market/level2:BCHSV-USDT","type":"message"}
1619378331.020999: {"data":{"sequenceStart":1613277184192,"symbol":"BCHSV-USDT","changes":{"asks":[["243.074","0","1613277184192"]],"bids":[]},"sequenceEnd":1613277184192},"subject":"trade.l2update","topic":"/market/level2:BCHSV-USDT","type":"message"}
1619378331.0211399: {"data":{"sequenceStart":1613277184193,"symbol":"BCHSV-USDT","changes":{"asks":[],"bids":[["242.522","0.10226994","1613277184193"]]},"sequenceEnd":1613277184193},"subject":"trade.l2update","topic":"/market/level2:BCHSV-USDT","type":"message"}
1619378331.0212018: {"data":{"sequenceStart":1613277184194,"symbol":"BCHSV-USDT","changes":{"asks":[["243.143","0","1613277184194"]],"bids":[]},"sequenceEnd":1613277184194},"subject":"trade.l2update","topic":"/market/level2:BCHSV-USDT","type":"message"}
1619378331.0212631: {"data":{"sequenceStart":1613277184195,"symbol":"BCHSV-USDT","changes":{"asks":[["0","0","1613277184195"]],"bids":[]},"sequenceEnd":1613277184195},"subject":"trade.l2update","topic":"/market/level2:BCHSV-USDT","type":"message"}
1619378331.021325: {"data":{"sequenceStart":1613277184196,"symbol":"BCHSV-USDT","changes":{"asks":[["243.002","3.73844146","1613277184196"]],"bids":[]},"sequenceEnd":1613277184196},"subject":"trade.l2update","topic":"/market/level2:BCHSV-USDT","type":"message"}
1619378331.027932: {"data":{"sequenceStart":1613277184197,"symbol":"BCHSV-USDT","changes":{"asks":[["0","0","1613277184197"]],"bids":[]},"sequenceEnd":1613277184197},"subject":"trade.l2update","topic":"/market/level2:BCHSV-USDT","type":"message"}
1619378331.028042: {"data":{"sequenceStart":1613277184198,"symbol":"BCHSV-USDT","changes":{"asks":[["243.096","0.6","1613277184198"]],"bids":[]},"sequenceEnd":1613277184198},"subject":"trade.l2update","topic":"/market/level2:BCHSV-USDT","type":"message"}
1619378331.0281222: {"data":{"sequenceStart":1613277184199,"symbol":"BCHSV-USDT","changes":{"asks":[],"bids":[["0","0","1613277184199"]]},"sequenceEnd":1613277184199},"subject":"trade.l2update","topic":"/market/level2:BCHSV-USDT","type":"message"}
1619378331.028167: {"data":{"sequenceStart":1613277184200,"symbol":"BCHSV-USDT","changes":{"asks":[],"bids":[["242.14","2.99","1613277184200"]]},"sequenceEnd":1613277184200},"subject":"trade.l2update","topic":"/market/level2:BCHSV-USDT","type":"message"}
1619378331.039517: {"data":{"sequenceStart":1613277184201,"symbol":"BCHSV-USDT","changes":{"asks":[["242.987","2.99","1613277184201"]],"bids":[]},"sequenceEnd":1613277184201},"subject":"trade.l2update","topic":"/market/level2:BCHSV-USDT","type":"message"}
1619378331.039646: {"data":{"sequenceStart":1613277184202,"symbol":"BCHSV-USDT","changes":{"asks":[],"bids":[["0","0","1613277184202"]]},"sequenceEnd":1613277184202},"subject":"trade.l2update","topic":"/market/level2:BCHSV-USDT","type":"message"}
1619378331.0397: {"data":{"sequenceStart":1613277184203,"symbol":"BCHSV-USDT","changes":{"asks":[],"bids":[["242.14","5.98","1613277184203"]]},"sequenceEnd":1613277184203},"subject":"trade.l2update","topic":"/market/level2:BCHSV-USDT","type":"message"}
1619378331.0397482: {"data":{"sequenceStart":1613277184204,"symbol":"BCHSV-USDT","changes":{"asks":[],"bids":[["0","0","1613277184204"]]},"sequenceEnd":1613277184204},"subject":"trade.l2update","topic":"/market/level2:BCHSV-USDT","type":"message"}
1619378331.039785: {"data":{"sequenceStart":1613277184205,"symbol":"BCHSV-USDT","changes":{"asks":[],"bids":[["241.989","5.52","1613277184205"]]},"sequenceEnd":1613277184205},"subject":"trade.l2update","topic":"/market/level2:BCHSV-USDT","type":"message"}
1619378331.046846: {"data":{"sequenceStart":1613277184206,"symbol":"BCHSV-USDT","changes":{"asks":[],"bids":[["0","0","1613277184206"]]},"sequenceEnd":1613277184206},"subject":"trade.l2update","topic":"/market/level2:BCHSV-USDT","type":"message"}
1619378331.046956: {"data":{"sequenceStart":1613277184207,"symbol":"BCHSV-USDT","changes":{"asks":[],"bids":[["241.746","20.43","1613277184207"]]},"sequenceEnd":1613277184207},"subject":"trade.l2update","topic":"/market/level2:BCHSV-USDT","type":"message"}
1619378331.0470679: {"data":{"sequenceStart":1613277184208,"symbol":"BCHSV-USDT","changes":{"asks":[["243.002","0","1613277184208"]],"bids":[]},"sequenceEnd":1613277184208},"subject":"trade.l2update","topic":"/market/level2:BCHSV-USDT","type":"message"}
1619378331.0471208: {"data":{"sequenceStart":1613277184209,"symbol":"BCHSV-USDT","changes":{"asks":[],"bids":[["0","0","1613277184209"]]},"sequenceEnd":1613277184209},"subject":"trade.l2update","topic":"/market/level2:BCHSV-USDT","type":"message"}
1619378331.047148: {"data":{"sequenceStart":1613277184210,"symbol":"BCHSV-USDT","changes":{"asks":[],"bids":[["241.602","8.58110427","1613277184210"]]},"sequenceEnd":1613277184210},"subject":"trade.l2update","topic":"/market/level2:BCHSV-USDT","type":"message"}
1619378331.047178: {"data":{"sequenceStart":1612844051759,"symbol":"SNX-BTC","changes":{"asks":[["0.00028733","0","1612844051759"]],"bids":[]},"sequenceEnd":1612844051759},"subject":"trade.l2update","topic":"/market/level2:SNX-BTC","type":"message"}
1619378331.047217: {"data":{"sequenceStart":1613277184211,"symbol":"BCHSV-USDT","changes":{"asks":[["242.987","0","1613277184211"]],"bids":[]},"sequenceEnd":1613277184211},"subject":"trade.l2update","topic":"/market/level2:BCHSV-USDT","type":"message"}
1619378331.0472472: {"data":{"sequenceStart":1612712745608,"symbol":"FET-BTC","changes":{"asks":[["0.0000078","0","1612712745608"]],"bids":[]},"sequenceEnd":1612712745608},"subject":"trade.l2update","topic":"/market/level2:FET-BTC","type":"message"}
1619378331.047282: {"data":{"sequenceStart":1612702190320,"symbol":"NRG-BTC","changes":{"asks":[["0.00006229","0","1612702190320"]],"bids":[]},"sequenceEnd":1612702190320},"subject":"trade.l2update","topic":"/market/level2:NRG-BTC","type":"message"}
1619378331.05806: {"data":{"sequenceStart":1613277184212,"symbol":"BCHSV-USDT","changes":{"asks":[["243.021","0","1613277184212"]],"bids":[]},"sequenceEnd":1613277184212},"subject":"trade.l2update","topic":"/market/level2:BCHSV-USDT","type":"message"}
1619378331.058199: {"data":{"sequenceStart":1613277184213,"symbol":"BCHSV-USDT","changes":{"asks":[],"bids":[["242.14","2.99","1613277184213"]]},"sequenceEnd":1613277184213},"subject":"trade.l2update","topic":"/market/level2:BCHSV-USDT","type":"message"}
1619378331.058282: {"data":{"sequenceStart":1612699351252,"symbol":"COV-BTC","changes":{"asks":[["0.00001126","0","1612699351252"]],"bids":[]},"sequenceEnd":1612699351252},"subject":"trade.l2update","topic":"/market/level2:COV-BTC","type":"message"}
1619378331.0739431: {"data":{"sequence":"1612844051759","bestAsk":"0.00028715","size":"0.01745248","bestBidSize":"0.19100065","price":"0.00028676","time":1619378331023,"bestAskSize":"29.24570683","bestBid":"0.00028678"},"subject":"trade.ticker","topic":"/market/ticker:SNX-BTC","type":"message"}
1619378331.079672: {"data":{"sequenceStart":1613277184214,"symbol":"BCHSV-USDT","changes":{"asks":[],"bids":[["242.14","0","1613277184214"]]},"sequenceEnd":1613277184214},"subject":"trade.l2update","topic":"/market/level2:BCHSV-USDT","type":"message"}
1619378331.079813: {"data":{"sequenceStart":1613277184215,"symbol":"BCHSV-USDT","changes":{"asks":[["0","0","1613277184215"]],"bids":[]},"sequenceEnd":1613277184215},"subject":"trade.l2update","topic":"/market/level2:BCHSV-USDT","type":"message"}
1619378331.0798678: {"data":{"sequenceStart":1613277184216,"symbol":"BCHSV-USDT","changes":{"asks":[["245.609","17.79999999","1613277184216"]],"bids":[]},"sequenceEnd":1613277184216},"subject":"trade.l2update","topic":"/market/level2:BCHSV-USDT","type":"message"}
1619378331.0799308: {"data":{"sequence":"1613277184216","bestAsk":"242.811","size":"0.08000012","bestBidSize":"0.10226994","price":"243.65","time":1619378331031,"bestAskSize":"4.51280965","bestBid":"242.522"},"subject":"trade.ticker","topic":"/market/ticker:BCHSV-USDT","type":"message"}
1619378331.099911: {"data":{"sequenceStart":1613277184217,"symbol":"BCHSV-USDT","changes":{"asks":[["0","0","1613277184217"]],"bids":[]},"sequenceEnd":1613277184217},"subject":"trade.l2update","topic":"/market/level2:BCHSV-USDT","type":"message"}
1619378331.10002: {"data":{"sequenceStart":1613277184218,"symbol":"BCHSV-USDT","changes":{"asks":[["242.933","2.99","1613277184218"]],"bids":[]},"sequenceEnd":1613277184218},"subject":"trade.l2update","topic":"/market/level2:BCHSV-USDT","type":"message"}
1619378331.100102: {"data":{"sequenceStart":1612734157754,"symbol":"ANKR-BTC","changes":{"asks":[],"bids":[["0.0000026016","0","1612734157754"]]},"sequenceEnd":1612734157754},"subject":"trade.l2update","topic":"/market/level2:ANKR-BTC","type":"message"}
1619378331.100173: {"data":{"sequenceStart":1613277184219,"symbol":"BCHSV-USDT","changes":{"asks":[],"bids":[["241.704","0","1613277184219"]]},"sequenceEnd":1613277184219},"subject":"trade.l2update","topic":"/market/level2:BCHSV-USDT","type":"message"}
1619378331.100239: {"data":{"sequenceStart":1612702190321,"symbol":"NRG-BTC","changes":{"asks":[["0","0","1612702190321"]],"bids":[]},"sequenceEnd":1612702190321},"subject":"trade.l2update","topic":"/market/level2:NRG-BTC","type":"message"}
1619378331.1002848: {"data":{"sequenceStart":1612702190322,"symbol":"NRG-BTC","changes":{"asks":[["0.00006227","8.0295","1612702190322"]],"bids":[]},"sequenceEnd":1612702190322},"subject":"trade.l2update","topic":"/market/level2:NRG-BTC","type":"message"}
1619378331.10032: {"data":{"sequenceStart":1613277184220,"symbol":"BCHSV-USDT","changes":{"asks":[["0","0","1613277184220"]],"bids":[]},"sequenceEnd":1613277184220},"subject":"trade.l2update","topic":"/market/level2:BCHSV-USDT","type":"message"}
1619378331.100343: {"data":{"sequenceStart":1613277184221,"symbol":"BCHSV-USDT","changes":{"asks":[["242.933","5.98","1613277184221"]],"bids":[]},"sequenceEnd":1613277184221},"subject":"trade.l2update","topic":"/market/level2:BCHSV-USDT","type":"message"}
1619378331.113421: {"data":{"sequenceStart":1612712745609,"symbol":"FET-BTC","changes":{"asks":[["0","0","1612712745609"]],"bids":[]},"sequenceEnd":1612712745609},"subject":"trade.l2update","topic":"/market/level2:FET-BTC","type":"message"}
1619378331.113546: {"data":{"sequenceStart":1612712745610,"symbol":"FET-BTC","changes":{"asks":[["0.00000779","64.2216","1612712745610"]],"bids":[]},"sequenceEnd":1612712745610},"subject":"trade.l2update","topic":"/market/level2:FET-BTC","type":"message"}
1619378331.113628: {"data":{"sequenceStart":1613277184222,"symbol":"BCHSV-USDT","changes":{"asks":[["243.096","0","1613277184222"]],"bids":[]},"sequenceEnd":1613277184222},"subject":"trade.l2update","topic":"/market/level2:BCHSV-USDT","type":"message"}
1619378331.113696: {"data":{"sequenceStart":1612734157755,"symbol":"ANKR-BTC","changes":{"asks":[["0","0","1612734157755"]],"bids":[]},"sequenceEnd":1612734157755},"subject":"trade.l2update","topic":"/market/level2:ANKR-BTC","type":"message"}
1619378331.113738: {"data":{"sequenceStart":1612734157756,"symbol":"ANKR-BTC","changes":{"asks":[["0.0000026186","191.1686","1612734157756"]],"bids":[]},"sequenceEnd":1612734157756},"subject":"trade.l2update","topic":"/market/level2:ANKR-BTC","type":"message"}
1619378331.113792: {"data":{"sequence":"1612712745610","bestAsk":"0.00000775","size":"401.2004","bestBidSize":"357.285","price":"0.00000772","time":1619378331068,"bestAskSize":"1154.0416","bestBid":"0.00000771"},"subject":"trade.ticker","topic":"/market/ticker:FET-BTC","type":"message"}
1619378331.136965: {"data":{"sequenceStart":1613277184223,"symbol":"BCHSV-USDT","changes":{"asks":[["0","0","1613277184223"]],"bids":[]},"sequenceEnd":1613277184223},"subject":"trade.l2update","topic":"/market/level2:BCHSV-USDT","type":"message"}
1619378331.137078: {"data":{"sequenceStart":1613277184224,"symbol":"BCHSV-USDT","changes":{"asks":[["243.108","0.6","1613277184224"]],"bids":[]},"sequenceEnd":1613277184224},"subject":"trade.l2update","topic":"/market/level2:BCHSV-USDT","type":"message"}
1619378331.1371598: {"data":{"sequenceStart":1613277184225,"symbol":"BCHSV-USDT","changes":{"asks":[],"bids":[["0","0","1613277184225"]]},"sequenceEnd":1613277184225},"subject":"trade.l2update","topic":"/market/level2:BCHSV-USDT","type":"message"}
1619378331.137204: {"data":{"sequenceStart":1613277184226,"symbol":"BCHSV-USDT","changes":{"asks":[],"bids":[["242.22","2.99","1613277184226"]]},"sequenceEnd":1613277184226},"subject":"trade.l2update","topic":"/market/level2:BCHSV-USDT","type":"message"}
1619378331.144008: {"data":{"sequence":"1612699351252","bestAsk":"0.00001127","size":"96.1525","bestBidSize":"49.6422","price":"0.00001126","time":1619378331088,"bestAskSize":"4331.68226035","bestBid":"0.00001121"},"subject":"trade.ticker","topic":"/market/ticker:COV-BTC","type":"message"}
1619378331.1441019: {"data":{"sequence":"1612734157756","bestAsk":"0.0000026186","size":"46","bestBidSize":"4051.2663","price":"0.0000026071","time":1619378331088,"bestAskSize":"191.1686","bestBid":"0.0000026033"},"subject":"trade.ticker","topic":"/market/ticker:ANKR-BTC","type":"message"}
1619378331.156339: {"data":{"sequenceStart":1613277184227,"symbol":"BCHSV-USDT","changes":{"asks":[],"bids":[["0","0","1613277184227"]]},"sequenceEnd":1613277184227},"subject":"trade.l2update","topic":"/market/level2:BCHSV-USDT","type":"message"}
1619378331.156451: {"data":{"sequenceStart":1613277184228,"symbol":"BCHSV-USDT","changes":{"asks":[],"bids":[["242.22","5.98","1613277184228"]]},"sequenceEnd":1613277184228},"subject":"trade.l2update","topic":"/market/level2:BCHSV-USDT","type":"message"}
1619378331.1620321: {"data":{"sequenceStart":1612699351253,"symbol":"COV-BTC","changes":{"asks":[["0","0","1612699351253"]],"bids":[]},"sequenceEnd":1612699351253},"subject":"trade.l2update","topic":"/market/level2:COV-BTC","type":"message"}
1619378331.162147: {"data":{"sequenceStart":1612699351254,"symbol":"COV-BTC","changes":{"asks":[["0.00001126","44.4224","1612699351254"]],"bids":[]},"sequenceEnd":1612699351254},"subject":"trade.l2update","topic":"/market/level2:COV-BTC","type":"message"}
1619378331.166263: {"data":{"sequenceStart":1612701563941,"symbol":"DAPPT-BTC","changes":{"asks":[],"bids":[["0.0000001098","1569.3487","1612701563941"]]},"sequenceEnd":1612701563941},"subject":"trade.l2update","topic":"/market/level2:DAPPT-BTC","type":"message"}
1619378331.166354: {"data":{"sequence":"1612702190322","bestAsk":"0.00006218","size":"0.0431","bestBidSize":"19.5017","price":"0.00006141","time":1619378331091,"bestAskSize":"43.3399","bestBid":"0.00006141"},"subject":"trade.ticker","topic":"/market/ticker:NRG-BTC","type":"message"}
1619378331.182375: {"data":{"sequenceStart":1613277184229,"symbol":"BCHSV-USDT","changes":{"asks":[["0","0","1613277184229"]],"bids":[]},"sequenceEnd":1613277184229},"subject":"trade.l2update","topic":"/market/level2:BCHSV-USDT","type":"message"}
1619378331.182493: {"data":{"sequenceStart":1613277184230,"symbol":"BCHSV-USDT","changes":{"asks":[["242.81","9.21961606","1613277184230"]],"bids":[]},"sequenceEnd":1613277184230},"subject":"trade.l2update","topic":"/market/level2:BCHSV-USDT","type":"message"}
1619378331.1825762: {"data":{"sequence":"1612701563941","bestAsk":"0.0000001126","size":"310.5072","bestBidSize":"6450","price":"0.0000001123","time":1619378331130,"bestAskSize":"361.2609","bestBid":"0.0000001115"},"subject":"trade.ticker","topic":"/market/ticker:DAPPT-BTC","type":"message"}
1619378331.182621: {"data":{"sequence":"1613277184230","bestAsk":"242.81","size":"0.08000012","bestBidSize":"0.10226994","price":"243.65","time":1619378331130,"bestAskSize":"9.21961606","bestBid":"242.522"},"subject":"trade.ticker","topic":"/market/ticker:BCHSV-USDT","type":"message"}
1619378331.1904058: {"data":{"sequenceStart":1612712745611,"symbol":"FET-BTC","changes":{"asks":[["0.00000779","0","1612712745611"]],"bids":[]},"sequenceEnd":1612712745611},"subject":"trade.l2update","topic":"/market/level2:FET-BTC","type":"message"}
1619378331.212845: {"data":{"sequenceStart":1613277184231,"symbol":"BCHSV-USDT","changes":{"asks":[["243.108","0","1613277184231"]],"bids":[]},"sequenceEnd":1613277184231},"subject":"trade.l2update","topic":"/market/level2:BCHSV-USDT","type":"message"}
1619378331.227267: {"data":{"sequence":"1612712745611","bestAsk":"0.00000775","size":"401.2004","bestBidSize":"357.285","price":"0.00000772","time":1619378331167,"bestAskSize":"1154.0416","bestBid":"0.00000771"},"subject":"trade.ticker","topic":"/market/ticker:FET-BTC","type":"message"}
1619378331.2273211: {"data":{"sequenceStart":1613277184232,"symbol":"BCHSV-USDT","changes":{"asks":[["245.135","0","1613277184232"]],"bids":[]},"sequenceEnd":1613277184232},"subject":"trade.l2update","topic":"/market/level2:BCHSV-USDT","type":"message"}
1619378331.2273762: {"data":{"sequenceStart":1613277184233,"symbol":"BCHSV-USDT","changes":{"asks":[["0","0","1613277184233"]],"bids":[]},"sequenceEnd":1613277184233},"subject":"trade.l2update","topic":"/market/level2:BCHSV-USDT","type":"message"}
1619378331.227402: {"data":{"sequenceStart":1613277184234,"symbol":"BCHSV-USDT","changes":{"asks":[["243.107","0.6","1613277184234"]],"bids":[]},"sequenceEnd":1613277184234},"subject":"trade.l2update","topic":"/market/level2:BCHSV-USDT","type":"message"}
1619378331.241537: {"data":{"sequenceStart":1612702190323,"symbol":"NRG-BTC","changes":{"asks":[],"bids":[["0.00006072","0","1612702190323"]]},"sequenceEnd":1612702190323},"subject":"trade.l2update","topic":"/market/level2:NRG-BTC","type":"message"}
1619378331.244842: {"data":{"sequenceStart":1612694580157,"symbol":"CAPP-BTC","changes":{"asks":[],"bids":[["0.0000001501","0","1612694580157"]]},"sequenceEnd":1612694580157},"subject":"trade.l2update","topic":"/market/level2:CAPP-BTC","type":"message"}
1619378331.244988: {"data":{"sequence":"1612699351254","bestAsk":"0.00001126","size":"96.1525","bestBidSize":"49.6422","price":"0.00001126","time":1619378331188,"bestAskSize":"44.4224","bestBid":"0.00001121"},"subject":"trade.ticker","topic":"/market/ticker:COV-BTC","type":"message"}
1619378331.245038: {"data":{"sequence":"1612702190323","bestAsk":"0.00006218","size":"0.0431","bestBidSize":"19.5017","price":"0.00006141","time":1619378331191,"bestAskSize":"43.3399","bestBid":"0.00006141"},"subject":"trade.ticker","topic":"/market/ticker:NRG-BTC","type":"message"}
1619378331.267167: {"data":{"sequenceStart":1612702190324,"symbol":"NRG-BTC","changes":{"asks":[],"bids":[["0","0","1612702190324"]]},"sequenceEnd":1612702190324},"subject":"trade.l2update","topic":"/market/level2:NRG-BTC","type":"message"}
1619378331.2672808: {"data":{"sequenceStart":1612702190325,"symbol":"NRG-BTC","changes":{"asks":[],"bids":[["0.00006074","31.2591","1612702190325"]]},"sequenceEnd":1612702190325},"subject":"trade.l2update","topic":"/market/level2:NRG-BTC","type":"message"}
1619378331.284905: {"data":{"sequence":"1613277184234","bestAsk":"242.81","size":"0.08000012","bestBidSize":"0.10226994","price":"243.65","time":1619378331230,"bestAskSize":"9.21961606","bestBid":"242.522"},"subject":"trade.ticker","topic":"/market/ticker:BCHSV-USDT","type":"message"}
1619378331.307859: {"data":{"sequenceStart":1612702190326,"symbol":"NRG-BTC","changes":{"asks":[["0.00006227","0","1612702190326"]],"bids":[]},"sequenceEnd":1612702190326},"subject":"trade.l2update","topic":"/market/level2:NRG-BTC","type":"message"}
1619378331.3231301: {"data":{"sequenceStart":1612699351255,"symbol":"COV-BTC","changes":{"asks":[["0.00001126","0","1612699351255"]],"bids":[]},"sequenceEnd":1612699351255},"subject":"trade.l2update","topic":"/market/level2:COV-BTC","type":"message"}
1619378331.336595: {"data":{"sequence":"1612694580157","bestAsk":"0.0000002196","size":"1000.02","bestBidSize":"83.07","price":"0.0000002182","time":1619378331282,"bestAskSize":"4490.25","bestBid":"0.0000002181"},"subject":"trade.ticker","topic":"/market/ticker:CAPP-BTC","type":"message"}
1619378331.3366861: {"data":{"sequenceStart":1612712745612,"symbol":"FET-BTC","changes":{"asks":[["0","0","1612712745612"]],"bids":[]},"sequenceEnd":1612712745612},"subject":"trade.l2update","topic":"/market/level2:FET-BTC","type":"message"}
1619378331.3367522: {"data":{"sequenceStart":1612712745613,"symbol":"FET-BTC","changes":{"asks":[["0.0000078","2696.2591","1612712745613"]],"bids":[]},"sequenceEnd":1612712745613},"subject":"trade.l2update","topic":"/market/level2:FET-BTC","type":"message"}
1619378331.347431: {"data":{"sequence":"1612699351255","bestAsk":"0.00001127","size":"96.1525","bestBidSize":"49.6422","price":"0.00001126","time":1619378331288,"bestAskSize":"4331.68226035","bestBid":"0.00001121"},"subject":"trade.ticker","topic":"/market/ticker:COV-BTC","type":"message"}
1619378331.347508: {"data":{"sequence":"1612702190326","bestAsk":"0.00006218","size":"0.0431","bestBidSize":"19.5017","price":"0.00006141","time":1619378331292,"bestAskSize":"43.3399","bestBid":"0.00006141"},"subject":"trade.ticker","topic":"/market/ticker:NRG-BTC","type":"message"}
1619378331.3475358: {"data":{"sequenceStart":1612734157757,"symbol":"ANKR-BTC","changes":{"asks":[["0.0000026186","0","1612734157757"]],"bids":[]},"sequenceEnd":1612734157757},"subject":"trade.l2update","topic":"/market/level2:ANKR-BTC","type":"message"}
1619378331.3602052: {"data":{"sequenceStart":1613277184235,"symbol":"BCHSV-USDT","changes":{"asks":[["0","0","1613277184235"]],"bids":[]},"sequenceEnd":1613277184235},"subject":"trade.l2update","topic":"/market/level2:BCHSV-USDT","type":"message"}
1619378331.3603141: {"data":{"sequenceStart":1613277184236,"symbol":"BCHSV-USDT","changes":{"asks":[["244.792","25","1613277184236"]],"bids":[]},"sequenceEnd":1613277184236},"subject":"trade.l2update","topic":"/market/level2:BCHSV-USDT","type":"message"}
1619378331.36847: {"data":{"sequenceStart":1612712745614,"symbol":"FET-BTC","changes":{"asks":[["0.0000078","0","1612712745614"]],"bids":[]},"sequenceEnd":1612712745614},"subject":"trade.l2update","topic":"/market/level2:FET-BTC","type":"message"}
1619378331.390924: {"data":{"sequenceStart":1612734157758,"symbol":"ANKR-BTC","changes":{"asks":[],"bids":[["0","0","1612734157758"]]},"sequenceEnd":1612734157758},"subject":"trade.l2update","topic":"/market/level2:ANKR-BTC","type":"message"}
1619378331.3910348: {"data":{"sequenceStart":1612734157759,"symbol":"ANKR-BTC","changes":{"asks":[],"bids":[["0.0000025996","3500.0095","1612734157759"]]},"sequenceEnd":1612734157759},"subject":"trade.l2update","topic":"/market/level2:ANKR-BTC","type":"message"}
1619378331.4003909: {"data":{"sequence":"1613277184237","bestAsk":"242.81","size":"0.08000012","bestBidSize":"0.18247733","price":"243.65","time":1619378331331,"bestAskSize":"9.21961606","bestBid":"242.473"},"subject":"trade.ticker","topic":"/market/ticker:BCHSV-USDT","type":"message"}
1619378331.400482: {"data":{"sequenceStart":1613277184237,"symbol":"BCHSV-USDT","changes":{"asks":[],"bids":[["242.522","0","1613277184237"]]},"sequenceEnd":1613277184237},"subject":"trade.l2update","topic":"/market/level2:BCHSV-USDT","type":"message"}
1619378331.400599: {"data":{"sequenceStart":1612844051760,"symbol":"SNX-BTC","changes":{"asks":[],"bids":[["0.00028655","0","1612844051760"]]},"sequenceEnd":1612844051760},"subject":"trade.l2update","topic":"/market/level2:SNX-BTC","type":"message"}
1619378331.400644: {"data":{"sequenceStart":1612701563942,"symbol":"DAPPT-BTC","changes":{"asks":[["0.0000001133","4948.0983","1612701563942"]],"bids":[]},"sequenceEnd":1612701563942},"subject":"trade.l2update","topic":"/market/level2:DAPPT-BTC","type":"message"}
1619378331.400678: {"data":{"sequenceStart":1612702190327,"symbol":"NRG-BTC","changes":{"asks":[["0","0","1612702190327"]],"bids":[]},"sequenceEnd":1612702190327},"subject":"trade.l2update","topic":"/market/level2:NRG-BTC","type":"message"}
1619378331.400702: {"data":{"sequenceStart":1612702190328,"symbol":"NRG-BTC","changes":{"asks":[["0.00006228","13.679","1612702190328"]],"bids":[]},"sequenceEnd":1612702190328},"subject":"trade.l2update","topic":"/market/level2:NRG-BTC","type":"message"}
1619378331.400738: {"data":{"sequenceStart":1612734157760,"symbol":"ANKR-BTC","changes":{"asks":[],"bids":[["0.0000025745","0","1612734157760"]]},"sequenceEnd":1612734157760},"subject":"trade.l2update","topic":"/market/level2:ANKR-BTC","type":"message"}
1619378331.400773: {"data":{"sequenceStart":1612734157761,"symbol":"ANKR-BTC","changes":{"asks":[],"bids":[["0.0000025996","0","1612734157761"]]},"sequenceEnd":1612734157761},"subject":"trade.l2update","topic":"/market/level2:ANKR-BTC","type":"message"}
1619378331.4185941: {"data":{"sequenceStart":1612844051761,"symbol":"SNX-BTC","changes":{"asks":[["0","0","1612844051761"]],"bids":[]},"sequenceEnd":1612844051761},"subject":"trade.l2update","topic":"/market/level2:SNX-BTC","type":"message"}
1619378331.4186711: {"data":{"sequenceStart":1612844051762,"symbol":"SNX-BTC","changes":{"asks":[["0.00028714","14.05008598","1612844051762"]],"bids":[]},"sequenceEnd":1612844051762},"subject":"trade.l2update","topic":"/market/level2:SNX-BTC","type":"message"}
1619378331.418726: {"data":{"sequenceStart":1612699351256,"symbol":"COV-BTC","changes":{"asks":[["0","0","1612699351256"]],"bids":[]},"sequenceEnd":1612699351256},"subject":"trade.l2update","topic":"/market/level2:COV-BTC","type":"message"}
1619378331.418756: {"data":{"sequenceStart":1612699351257,"symbol":"COV-BTC","changes":{"asks":[["0.00001126","137.9035","1612699351257"]],"bids":[]},"sequenceEnd":1612699351257},"subject":"trade.l2update","topic":"/market/level2:COV-BTC","type":"message"}
1619378331.418802: {"data":{"sequenceStart":1613277184238,"symbol":"BCHSV-USDT","changes":{"asks":[["243.107","0","1613277184238"]],"bids":[]},"sequenceEnd":1613277184238},"subject":"trade.l2update","topic":"/market/level2:BCHSV-USDT","type":"message"}
1619378331.4188428: {"data":{"sequenceStart":1613277184239,"symbol":"BCHSV-USDT","changes":{"asks":[],"bids":[["0","0","1613277184239"]]},"sequenceEnd":1613277184239},"subject":"trade.l2update","topic":"/market/level2:BCHSV-USDT","type":"message"}
1619378331.418868: {"data":{"sequenceStart":1613277184240,"symbol":"BCHSV-USDT","changes":{"asks":[],"bids":[["241.544","5","1613277184240"]]},"sequenceEnd":1613277184240},"subject":"trade.l2update","topic":"/market/level2:BCHSV-USDT","type":"message"}
1619378331.418899: {"data":{"sequenceStart":1613277184241,"symbol":"BCHSV-USDT","changes":{"asks":[["0","0","1613277184241"]],"bids":[]},"sequenceEnd":1613277184241},"subject":"trade.l2update","topic":"/market/level2:BCHSV-USDT","type":"message"}
1619378331.41892: {"data":{"sequenceStart":1613277184242,"symbol":"BCHSV-USDT","changes":{"asks":[["244.342","150","1613277184242"]],"bids":[]},"sequenceEnd":1613277184242},"subject":"trade.l2update","topic":"/market/level2:BCHSV-USDT","type":"message"}
1619378331.4189491: {"data":{"sequence":"1612712745614","bestAsk":"0.00000775","size":"401.2004","bestBidSize":"357.285","price":"0.00000772","time":1619378331368,"bestAskSize":"1154.0416","bestBid":"0.00000771"},"subject":"trade.ticker","topic":"/market/ticker:FET-BTC","type":"message"}
1619378331.418973: {"data":{"sequenceStart":1612701563943,"symbol":"DAPPT-BTC","changes":{"asks":[],"bids":[["0","0","1612701563943"]]},"sequenceEnd":1612701563943},"subject":"trade.l2update","topic":"/market/level2:DAPPT-BTC","type":"message"}
1619378331.4189959: {"data":{"sequenceStart":1612701563944,"symbol":"DAPPT-BTC","changes":{"asks":[["0.0000001126","145.4959","1612701563944"]],"bids":[]},"sequenceEnd":1612701563944},"subject":"trade.l2update","topic":"/market/level2:DAPPT-BTC","type":"message"}
1619378331.4190211: {"data":{"sequenceStart":1612701563945,"symbol":"DAPPT-BTC","changes":{"asks":[],"bids":[["0","0","1612701563945"]]},"sequenceEnd":1612701563945},"subject":"trade.l2update","topic":"/market/level2:DAPPT-BTC","type":"message"}
1619378331.419042: {"data":{"symbol":"DAPPT-BTC","sequence":"1612701563944","side":"buy","size":"215.765","price":"0.0000001126","takerOrderId":"6085c09b9bb39f00068345e6","time":"1619378331368668357","type":"match","makerOrderId":"6085bf316ac0850006bdb24f","tradeId":"6085c09b69bc506996295e53"},"subject":"trade.l3match","topic":"/market/match:DAPPT-BTC","type":"message"}
1619378331.426255: {"data":{"sequenceStart":1613277184243,"symbol":"BCHSV-USDT","changes":{"asks":[["0","0","1613277184243"]],"bids":[]},"sequenceEnd":1613277184243},"subject":"trade.l2update","topic":"/market/level2:BCHSV-USDT","type":"message"}
1619378331.426364: {"data":{"sequenceStart":1613277184244,"symbol":"BCHSV-USDT","changes":{"asks":[["243.705","5","1613277184244"]],"bids":[]},"sequenceEnd":1613277184244},"subject":"trade.l2update","topic":"/market/level2:BCHSV-USDT","type":"message"}
1619378331.433868: {"data":{"sequence":"1612734157761","bestAsk":"0.0000026187","size":"46","bestBidSize":"4051.2663","price":"0.0000026071","time":1619378331388,"bestAskSize":"4664.7644","bestBid":"0.0000026033"},"subject":"trade.ticker","topic":"/market/ticker:ANKR-BTC","type":"message"}
1619378331.4377909: {"data":{"sequence":"1612699351257","bestAsk":"0.00001126","size":"96.1525","bestBidSize":"49.6422","price":"0.00001126","time":1619378331388,"bestAskSize":"137.9035","bestBid":"0.00001121"},"subject":"trade.ticker","topic":"/market/ticker:COV-BTC","type":"message"}
1619378331.4378822: {"data":{"sequence":"1612702190328","bestAsk":"0.00006218","size":"0.0431","bestBidSize":"19.5017","price":"0.00006141","time":1619378331391,"bestAskSize":"43.3399","bestBid":"0.00006141"},"subject":"trade.ticker","topic":"/market/ticker:NRG-BTC","type":"message"}
1619378331.441907: {"data":{"sequenceStart":1612844051763,"symbol":"SNX-BTC","changes":{"asks":[],"bids":[["0","0","1612844051763"]]},"sequenceEnd":1612844051763},"subject":"trade.l2update","topic":"/market/level2:SNX-BTC","type":"message"}
1619378331.442015: {"data":{"sequenceStart":1612844051764,"symbol":"SNX-BTC","changes":{"asks":[],"bids":[["0.00028612","2.10974473","1612844051764"]]},"sequenceEnd":1612844051764},"subject":"trade.l2update","topic":"/market/level2:SNX-BTC","type":"message"}
1619378331.467489: {"data":{"sequenceStart":1613277184245,"symbol":"BCHSV-USDT","changes":{"asks":[["245.609","0","1613277184245"]],"bids":[]},"sequenceEnd":1613277184245},"subject":"trade.l2update","topic":"/market/level2:BCHSV-USDT","type":"message"}
1619378331.4734058: {"data":{"sequenceStart":1612734157762,"symbol":"ANKR-BTC","changes":{"asks":[],"bids":[["0","0","1612734157762"]]},"sequenceEnd":1612734157762},"subject":"trade.l2update","topic":"/market/level2:ANKR-BTC","type":"message"}
1619378331.473523: {"data":{"sequenceStart":1612734157763,"symbol":"ANKR-BTC","changes":{"asks":[],"bids":[["0.0000025953","8127.767","1612734157763"]]},"sequenceEnd":1612734157763},"subject":"trade.l2update","topic":"/market/level2:ANKR-BTC","type":"message"}
1619378331.473578: {"data":{"symbol":"DAPPT-BTC","sequence":"1612701563947","side":"buy","size":"145.4959","price":"0.0000001126","takerOrderId":"6085c09b9bb39f000683465c","time":"1619378331420904551","type":"match","makerOrderId":"6085bf316ac0850006bdb24f","tradeId":"6085c09b69bc506996295e54"},"subject":"trade.l3match","topic":"/market/match:DAPPT-BTC","type":"message"}
1619378331.473623: {"data":{"sequenceStart":1612734157764,"symbol":"ANKR-BTC","changes":{"asks":[],"bids":[["0","0","1612734157764"]]},"sequenceEnd":1612734157764},"subject":"trade.l2update","topic":"/market/level2:ANKR-BTC","type":"message"}
1619378331.473651: {"data":{"sequenceStart":1612734157765,"symbol":"ANKR-BTC","changes":{"asks":[],"bids":[["0.0000025996","2116.0275","1612734157765"]]},"sequenceEnd":1612734157765},"subject":"trade.l2update","topic":"/market/level2:ANKR-BTC","type":"message"}
1619378331.473685: {"data":{"sequenceStart":1612701563946,"symbol":"DAPPT-BTC","changes":{"asks":[],"bids":[["0","0","1612701563946"]]},"sequenceEnd":1612701563946},"subject":"trade.l2update","topic":"/market/level2:DAPPT-BTC","type":"message"}
1619378331.473709: {"data":{"sequenceStart":1612701563947,"symbol":"DAPPT-BTC","changes":{"asks":[["0.0000001126","0","1612701563947"]],"bids":[]},"sequenceEnd":1612701563947},"subject":"trade.l2update","topic":"/market/level2:DAPPT-BTC","type":"message"}
1619378331.47375: {"data":{"sequenceStart":1612701563948,"symbol":"DAPPT-BTC","changes":{"asks":[],"bids":[["0","0","1612701563948"]]},"sequenceEnd":1612701563948},"subject":"trade.l2update","topic":"/market/level2:DAPPT-BTC","type":"message"}
1619378331.473773: {"data":{"sequenceStart":1612701563949,"symbol":"DAPPT-BTC","changes":{"asks":[["0","0","1612701563949"]],"bids":[]},"sequenceEnd":1612701563949},"subject":"trade.l2update","topic":"/market/level2:DAPPT-BTC","type":"message"}
1619378331.473794: {"data":{"sequenceStart":1612844051765,"symbol":"SNX-BTC","changes":{"asks":[],"bids":[["0","0","1612844051765"]]},"sequenceEnd":1612844051765},"subject":"trade.l2update","topic":"/market/level2:SNX-BTC","type":"message"}
1619378331.473815: {"data":{"sequenceStart":1612844051766,"symbol":"SNX-BTC","changes":{"asks":[],"bids":[["0.00028655","2.1097563","1612844051766"]]},"sequenceEnd":1612844051766},"subject":"trade.l2update","topic":"/market/level2:SNX-BTC","type":"message"}
1619378331.473846: {"data":{"sequenceStart":1612844051767,"symbol":"SNX-BTC","changes":{"asks":[["0.00028715","0","1612844051767"]],"bids":[]},"sequenceEnd":1612844051767},"subject":"trade.l2update","topic":"/market/level2:SNX-BTC","type":"message"}
1619378331.480205: {"data":{"sequence":"1612701563949","bestAsk":"0.000000113","size":"145.4959","bestBidSize":"6450","price":"0.0000001126","time":1619378331430,"bestAskSize":"1208.0878","bestBid":"0.0000001115"},"subject":"trade.ticker","topic":"/market/ticker:DAPPT-BTC","type":"message"}
1619378331.480298: {"data":{"sequence":"1613277184245","bestAsk":"242.81","size":"0.08000012","bestBidSize":"0.18247733","price":"243.65","time":1619378331433,"bestAskSize":"9.21961606","bestBid":"242.473"},"subject":"trade.ticker","topic":"/market/ticker:BCHSV-USDT","type":"message"}
1619378331.480339: {"data":{"sequenceStart":1612712745615,"symbol":"FET-BTC","changes":{"asks":[["0","0","1612712745615"]],"bids":[]},"sequenceEnd":1612712745615},"subject":"trade.l2update","topic":"/market/level2:FET-BTC","type":"message"}
1619378331.4803991: {"data":{"sequenceStart":1612712745616,"symbol":"FET-BTC","changes":{"asks":[["0.0000078","2182.1789","1612712745616"]],"bids":[]},"sequenceEnd":1612712745616},"subject":"trade.l2update","topic":"/market/level2:FET-BTC","type":"message"}
1619378331.487524: {"data":{"sequence":"1612844051767","bestAsk":"0.00028714","size":"0.01745248","bestBidSize":"0.19100065","price":"0.00028676","time":1619378331447,"bestAskSize":"14.05008598","bestBid":"0.00028678"},"subject":"trade.ticker","topic":"/market/ticker:SNX-BTC","type":"message"}
1619378331.487627: {"data":{"sequenceStart":1613277184246,"symbol":"BCHSV-USDT","changes":{"asks":[],"bids":[["0","0","1613277184246"]]},"sequenceEnd":1613277184246},"subject":"trade.l2update","topic":"/market/level2:BCHSV-USDT","type":"message"}
1619378331.4876952: {"data":{"sequenceStart":1613277184247,"symbol":"BCHSV-USDT","changes":{"asks":[],"bids":[["241.642","7.21000634","1613277184247"]]},"sequenceEnd":1613277184247},"subject":"trade.l2update","topic":"/market/level2:BCHSV-USDT","type":"message"}
1619378331.487787: {"data":{"sequenceStart":1613277184248,"symbol":"BCHSV-USDT","changes":{"asks":[["243.505","0","1613277184248"]],"bids":[]},"sequenceEnd":1613277184248},"subject":"trade.l2update","topic":"/market/level2:BCHSV-USDT","type":"message"}
1619378331.487832: {"data":{"sequenceStart":1613277184249,"symbol":"BCHSV-USDT","changes":{"asks":[["243.798","0","1613277184249"]],"bids":[]},"sequenceEnd":1613277184249},"subject":"trade.l2update","topic":"/market/level2:BCHSV-USDT","type":"message"}
1619378331.4878669: {"data":{"sequenceStart":1612844051768,"symbol":"SNX-BTC","changes":{"asks":[["0","0","1612844051768"]],"bids":[]},"sequenceEnd":1612844051768},"subject":"trade.l2update","topic":"/market/level2:SNX-BTC","type":"message"}
1619378331.487892: {"data":{"sequenceStart":1612844051769,"symbol":"SNX-BTC","changes":{"asks":[["0.00028713","29.24570683","1612844051769"]],"bids":[]},"sequenceEnd":1612844051769},"subject":"trade.l2update","topic":"/market/level2:SNX-BTC","type":"message"}
1619378331.5023282: {"data":{"sequenceStart":1613277184250,"symbol":"BCHSV-USDT","changes":{"asks":[],"bids":[["0","0","1613277184250"]]},"sequenceEnd":1613277184250},"subject":"trade.l2update","topic":"/market/level2:BCHSV-USDT","type":"message"}
1619378331.5024378: {"data":{"sequenceStart":1613277184251,"symbol":"BCHSV-USDT","changes":{"asks":[],"bids":[["242.474","0.4008184","1613277184251"]]},"sequenceEnd":1613277184251},"subject":"trade.l2update","topic":"/market/level2:BCHSV-USDT","type":"message"}
1619378331.51037: {"data":{"sequenceStart":1612844051770,"symbol":"SNX-BTC","changes":{"asks":[],"bids":[["0.00028612","0","1612844051770"]]},"sequenceEnd":1612844051770},"subject":"trade.l2update","topic":"/market/level2:SNX-BTC","type":"message"}
1619378331.51051: {"data":{"sequence":"1612712745616","bestAsk":"0.00000775","size":"401.2004","bestBidSize":"357.285","price":"0.00000772","time":1619378331467,"bestAskSize":"1154.0416","bestBid":"0.00000771"},"subject":"trade.ticker","topic":"/market/ticker:FET-BTC","type":"message"}
1619378331.5105789: {"data":{"sequenceStart":1612712745617,"symbol":"FET-BTC","changes":{"asks":[["0.0000078","0","1612712745617"]],"bids":[]},"sequenceEnd":1612712745617},"subject":"trade.l2update","topic":"/market/level2:FET-BTC","type":"message"}
1619378331.526853: {"data":{"sequence":"1612734157765","bestAsk":"0.0000026187","size":"46","bestBidSize":"4051.2663","price":"0.0000026071","time":1619378331488,"bestAskSize":"4664.7644","bestBid":"0.0000026033"},"subject":"trade.ticker","topic":"/market/ticker:ANKR-BTC","type":"message"}
1619378331.531092: {"data":{"sequenceStart":1612712745618,"symbol":"FET-BTC","changes":{"asks":[["0.00000781","0","1612712745618"]],"bids":[]},"sequenceEnd":1612712745618},"subject":"trade.l2update","topic":"/market/level2:FET-BTC","type":"message"}
1619378331.531235: {"data":{"sequenceStart":1612701563950,"symbol":"DAPPT-BTC","changes":{"asks":[["0","0","1612701563950"]],"bids":[]},"sequenceEnd":1612701563950},"subject":"trade.l2update","topic":"/market/level2:DAPPT-BTC","type":"message"}
1619378331.5312908: {"data":{"sequenceStart":1612701563951,"symbol":"DAPPT-BTC","changes":{"asks":[["0.0000001133","6377.0102","1612701563951"]],"bids":[]},"sequenceEnd":1612701563951},"subject":"trade.l2update","topic":"/market/level2:DAPPT-BTC","type":"message"}
1619378331.531341: {"data":{"sequenceStart":1612701563952,"symbol":"DAPPT-BTC","changes":{"asks":[],"bids":[["0","0","1612701563952"]]},"sequenceEnd":1612701563952},"subject":"trade.l2update","topic":"/market/level2:DAPPT-BTC","type":"message"}
1619378331.53141: {"data":{"sequenceStart":1612701563953,"symbol":"DAPPT-BTC","changes":{"asks":[],"bids":[["0.0000001116","3774.8315","1612701563953"]]},"sequenceEnd":1612701563953},"subject":"trade.l2update","topic":"/market/level2:DAPPT-BTC","type":"message"}
1619378331.536431: {"data":{"sequenceStart":1613277184252,"symbol":"BCHSV-USDT","changes":{"asks":[["0","0","1613277184252"]],"bids":[]},"sequenceEnd":1613277184252},"subject":"trade.l2update","topic":"/market/level2:BCHSV-USDT","type":"message"}
1619378331.5365388: {"data":{"sequenceStart":1613277184253,"symbol":"BCHSV-USDT","changes":{"asks":[["243.547","20.43","1613277184253"]],"bids":[]},"sequenceEnd":1613277184253},"subject":"trade.l2update","topic":"/market/level2:BCHSV-USDT","type":"message"}
1619378331.536633: {"data":{"sequenceStart":1613277184254,"symbol":"BCHSV-USDT","changes":{"asks":[["0","0","1613277184254"]],"bids":[]},"sequenceEnd":1613277184254},"subject":"trade.l2update","topic":"/market/level2:BCHSV-USDT","type":"message"}
1619378331.536661: {"data":{"sequenceStart":1613277184255,"symbol":"BCHSV-USDT","changes":{"asks":[["243.304","5.52","1613277184255"]],"bids":[]},"sequenceEnd":1613277184255},"subject":"trade.l2update","topic":"/market/level2:BCHSV-USDT","type":"message"}
1619378331.565859: {"data":{"sequenceStart":1612701563954,"symbol":"DAPPT-BTC","changes":{"asks":[["0.0000001133","4948.0983","1612701563954"]],"bids":[]},"sequenceEnd":1612701563954},"subject":"trade.l2update","topic":"/market/level2:DAPPT-BTC","type":"message"}
1619378331.565998: {"data":{"sequence":"1612701563954","bestAsk":"0.000000113","size":"145.4959","bestBidSize":"3774.8315","price":"0.0000001126","time":1619378331530,"bestAskSize":"1208.0878","bestBid":"0.0000001116"},"subject":"trade.ticker","topic":"/market/ticker:DAPPT-BTC","type":"message"}
1619378331.575436: {"data":{"sequence":"1613277184255","bestAsk":"242.81","size":"0.08000012","bestBidSize":"0.4008184","price":"243.65","time":1619378331530,"bestAskSize":"9.21961606","bestBid":"242.474"},"subject":"trade.ticker","topic":"/market/ticker:BCHSV-USDT","type":"message"}
1619378331.584564: {"data":{"sequence":"1612844051770","bestAsk":"0.00028713","size":"0.01745248","bestBidSize":"0.19100065","price":"0.00028676","time":1619378331546,"bestAskSize":"29.24570683","bestBid":"0.00028678"},"subject":"trade.ticker","topic":"/market/ticker:SNX-BTC","type":"message"}
1619378331.598357: {"data":{"sequenceStart":1612712745619,"symbol":"FET-BTC","changes":{"asks":[["0","0","1612712745619"]],"bids":[]},"sequenceEnd":1612712745619},"subject":"trade.l2update","topic":"/market/level2:FET-BTC","type":"message"}
1619378331.598465: {"data":{"sequenceStart":1612712745620,"symbol":"FET-BTC","changes":{"asks":[["0.0000078","3869.4013","1612712745620"]],"bids":[]},"sequenceEnd":1612712745620},"subject":"trade.l2update","topic":"/market/level2:FET-BTC","type":"message"}
1619378331.607052: {"data":{"sequence":"1612712745620","bestAsk":"0.00000775","size":"401.2004","bestBidSize":"357.285","price":"0.00000772","time":1619378331567,"bestAskSize":"1154.0416","bestBid":"0.00000771"},"subject":"trade.ticker","topic":"/market/ticker:FET-BTC","type":"message"}
1619378331.6342: {"data":{"sequenceStart":1612712745621,"symbol":"FET-BTC","changes":{"asks":[["0.0000078","0","1612712745621"]],"bids":[]},"sequenceEnd":1612712745621},"subject":"trade.l2update","topic":"/market/level2:FET-BTC","type":"message"}
1619378331.650228: {"data":{"sequenceStart":1612701563955,"symbol":"DAPPT-BTC","changes":{"asks":[],"bids":[["0","0","1612701563955"]]},"sequenceEnd":1612701563955},"subject":"trade.l2update","topic":"/market/level2:DAPPT-BTC","type":"message"}
1619378331.6503391: {"data":{"sequenceStart":1613277184256,"symbol":"BCHSV-USDT","changes":{"asks":[],"bids":[["0","0","1613277184256"]]},"sequenceEnd":1613277184256},"subject":"trade.l2update","topic":"/market/level2:BCHSV-USDT","type":"message"}
1619378331.650391: {"data":{"sequenceStart":1613277184257,"symbol":"BCHSV-USDT","changes":{"asks":[],"bids":[["240.138","2.08213609","1613277184257"]]},"sequenceEnd":1613277184257},"subject":"trade.l2update","topic":"/market/level2:BCHSV-USDT","type":"message"}
1619378331.668329: {"data":{"sequence":"1613277184257","bestAsk":"242.81","size":"0.08000012","bestBidSize":"0.4008184","price":"243.65","time":1619378331632,"bestAskSize":"9.21961606","bestBid":"242.474"},"subject":"trade.ticker","topic":"/market/ticker:BCHSV-USDT","type":"message"}
1619378331.6684191: {"data":{"sequence":"1612701563955","bestAsk":"0.000000113","size":"145.4959","bestBidSize":"3774.8315","price":"0.0000001126","time":1619378331630,"bestAskSize":"1208.0878","bestBid":"0.0000001116"},"subject":"trade.ticker","topic":"/market/ticker:DAPPT-BTC","type":"message"}
1619378331.70887: {"data":{"sequence":"1612712745621","bestAsk":"0.00000775","size":"401.2004","bestBidSize":"357.285","price":"0.00000772","time":1619378331667,"bestAskSize":"1154.0416","bestBid":"0.00000771"},"subject":"trade.ticker","topic":"/market/ticker:FET-BTC","type":"message"}
1619378331.75549: {"data":{"sequenceStart":1612701563956,"symbol":"DAPPT-BTC","changes":{"asks":[],"bids":[["0","0","1612701563956"]]},"sequenceEnd":1612701563956},"subject":"trade.l2update","topic":"/market/level2:DAPPT-BTC","type":"message"}
1619378331.755599: {"data":{"sequenceStart":1612701563957,"symbol":"DAPPT-BTC","changes":{"asks":[],"bids":[["0","0","1612701563957"]]},"sequenceEnd":1612701563957},"subject":"trade.l2update","topic":"/market/level2:DAPPT-BTC","type":"message"}
1619378331.768267: {"data":{"sequence":"1612701563957","bestAsk":"0.000000113","size":"145.4959","bestBidSize":"3774.8315","price":"0.0000001126","time":1619378331730,"bestAskSize":"1208.0878","bestBid":"0.0000001116"},"subject":"trade.ticker","topic":"/market/ticker:DAPPT-BTC","type":"message"}
1619378331.774196: {"data":{"sequenceStart":1612701563958,"symbol":"DAPPT-BTC","changes":{"asks":[],"bids":[["0.0000001115","0","1612701563958"]]},"sequenceEnd":1612701563958},"subject":"trade.l2update","topic":"/market/level2:DAPPT-BTC","type":"message"}
1619378331.826293: {"data":{"sequenceStart":1613277184258,"symbol":"BCHSV-USDT","changes":{"asks":[["243.705","0","1613277184258"]],"bids":[]},"sequenceEnd":1613277184258},"subject":"trade.l2update","topic":"/market/level2:BCHSV-USDT","type":"message"}
1619378331.826376: {"data":{"sequenceStart":1613277184259,"symbol":"BCHSV-USDT","changes":{"asks":[["244.342","0","1613277184259"]],"bids":[]},"sequenceEnd":1613277184259},"subject":"trade.l2update","topic":"/market/level2:BCHSV-USDT","type":"message"}
1619378331.826412: {"data":{"sequenceStart":1613277184260,"symbol":"BCHSV-USDT","changes":{"asks":[],"bids":[["0","0","1613277184260"]]},"sequenceEnd":1613277184260},"subject":"trade.l2update","topic":"/market/level2:BCHSV-USDT","type":"message"}
1619378331.826435: {"data":{"sequenceStart":1613277184261,"symbol":"BCHSV-USDT","changes":{"asks":[],"bids":[["242.528","0.68148185","1613277184261"]]},"sequenceEnd":1613277184261},"subject":"trade.l2update","topic":"/market/level2:BCHSV-USDT","type":"message"}
1619378331.826463: {"data":{"sequenceStart":1613277184262,"symbol":"BCHSV-USDT","changes":{"asks":[],"bids":[["241.544","0","1613277184262"]]},"sequenceEnd":1613277184262},"subject":"trade.l2update","topic":"/market/level2:BCHSV-USDT","type":"message"}
1619378331.845857: {"data":{"sequenceStart":1612701563959,"symbol":"DAPPT-BTC","changes":{"asks":[["0","0","1612701563959"]],"bids":[]},"sequenceEnd":1612701563959},"subject":"trade.l2update","topic":"/market/level2:DAPPT-BTC","type":"message"}
1619378331.84597: {"data":{"sequenceStart":1612701563960,"symbol":"DAPPT-BTC","changes":{"asks":[["0.0000001133","7402.3639","1612701563960"]],"bids":[]},"sequenceEnd":1612701563960},"subject":"trade.l2update","topic":"/market/level2:DAPPT-BTC","type":"message"}
1619378331.865994: {"data":{"sequenceStart":1613277184263,"symbol":"BCHSV-USDT","changes":{"asks":[],"bids":[["0","0","1613277184263"]]},"sequenceEnd":1613277184263},"subject":"trade.l2update","topic":"/market/level2:BCHSV-USDT","type":"message"}
1619378331.866103: {"data":{"sequenceStart":1613277184264,"symbol":"BCHSV-USDT","changes":{"asks":[],"bids":[["242.53","5","1613277184264"]]},"sequenceEnd":1613277184264},"subject":"trade.l2update","topic":"/market/level2:BCHSV-USDT","type":"message"}
1619378331.870402: {"data":{"sequence":"1613277184264","bestAsk":"242.81","size":"0.08000012","bestBidSize":"5","price":"243.65","time":1619378331830,"bestAskSize":"9.21961606","bestBid":"242.53"},"subject":"trade.ticker","topic":"/market/ticker:BCHSV-USDT","type":"message"}
1619378331.870495: {"data":{"sequence":"1612701563960","bestAsk":"0.000000113","size":"145.4959","bestBidSize":"3774.8315","price":"0.0000001126","time":1619378331830,"bestAskSize":"1208.0878","bestBid":"0.0000001116"},"subject":"trade.ticker","topic":"/market/ticker:DAPPT-BTC","type":"message"}
1619378331.915581: {"data":{"sequenceStart":1613277184265,"symbol":"BCHSV-USDT","changes":{"asks":[["242.81","0","1613277184265"]],"bids":[]},"sequenceEnd":1613277184265},"subject":"trade.l2update","topic":"/market/level2:BCHSV-USDT","type":"message"}
1619378331.920372: {"data":{"sequenceStart":1613277184266,"symbol":"BCHSV-USDT","changes":{"asks":[["0","0","1613277184266"]],"bids":[]},"sequenceEnd":1613277184266},"subject":"trade.l2update","topic":"/market/level2:BCHSV-USDT","type":"message"}
1619378331.9204822: {"data":{"sequenceStart":1613277184267,"symbol":"BCHSV-USDT","changes":{"asks":[["243.136","0.6","1613277184267"]],"bids":[]},"sequenceEnd":1613277184267},"subject":"trade.l2update","topic":"/market/level2:BCHSV-USDT","type":"message"}
1619378331.942875: {"data":{"sequenceStart":1613277184268,"symbol":"BCHSV-USDT","changes":{"asks":[],"bids":[["242.53","0","1613277184268"]]},"sequenceEnd":1613277184268},"subject":"trade.l2update","topic":"/market/level2:BCHSV-USDT","type":"message"}
1619378331.950392: {"data":{"sequenceStart":1613277184269,"symbol":"BCHSV-USDT","changes":{"asks":[],"bids":[["0","0","1613277184269"]]},"sequenceEnd":1613277184269},"subject":"trade.l2update","topic":"/market/level2:BCHSV-USDT","type":"message"}
1619378331.950502: {"data":{"sequenceStart":1613277184270,"symbol":"BCHSV-USDT","changes":{"asks":[],"bids":[["242.532","5","1613277184270"]]},"sequenceEnd":1613277184270},"subject":"trade.l2update","topic":"/market/level2:BCHSV-USDT","type":"message"}
1619378331.9691362: {"data":{"sequence":"1613277184270","bestAsk":"242.811","size":"0.08000012","bestBidSize":"5","price":"243.65","time":1619378331932,"bestAskSize":"4.51280965","bestBid":"242.532"},"subject":"trade.ticker","topic":"/market/ticker:BCHSV-USDT","type":"message"}
1619378331.982224: {"data":{"sequenceStart":1613277184271,"symbol":"BCHSV-USDT","changes":{"asks":[["0","0","1613277184271"]],"bids":[]},"sequenceEnd":1613277184271},"subject":"trade.l2update","topic":"/market/level2:BCHSV-USDT","type":"message"}
1619378331.982334: {"data":{"sequenceStart":1613277184272,"symbol":"BCHSV-USDT","changes":{"asks":[["243.546","10.15389078","1613277184272"]],"bids":[]},"sequenceEnd":1613277184272},"subject":"trade.l2update","topic":"/market/level2:BCHSV-USDT","type":"message"}
1619378331.992787: {"data":{"sequenceStart":1613277184273,"symbol":"BCHSV-USDT","changes":{"asks":[["242.811","0","1613277184273"]],"bids":[]},"sequenceEnd":1613277184273},"subject":"trade.l2update","topic":"/market/level2:BCHSV-USDT","type":"message"}
1619378332.012058: {"data":{"sequenceStart":1613277184274,"symbol":"BCHSV-USDT","changes":{"asks":[["243.136","0","1613277184274"]],"bids":[]},"sequenceEnd":1613277184274},"subject":"trade.l2update","topic":"/market/level2:BCHSV-USDT","type":"message"}
1619378332.02968: {"data":{"sequenceStart":1613277184275,"symbol":"BCHSV-USDT","changes":{"asks":[],"bids":[["242.528","0","1613277184275"]]},"sequenceEnd":1613277184275},"subject":"trade.l2update","topic":"/market/level2:BCHSV-USDT","type":"message"}
1619378332.035747: {"data":{"sequenceStart":1613277184276,"symbol":"BCHSV-USDT","changes":{"asks":[],"bids":[["0","0","1613277184276"]]},"sequenceEnd":1613277184276},"subject":"trade.l2update","topic":"/market/level2:BCHSV-USDT","type":"message"}
1619378332.035858: {"data":{"sequenceStart":1613277184277,"symbol":"BCHSV-USDT","changes":{"asks":[],"bids":[["242.532","5.68148185","1613277184277"]]},"sequenceEnd":1613277184277},"subject":"trade.l2update","topic":"/market/level2:BCHSV-USDT","type":"message"}
1619378332.0359209: {"data":{"sequenceStart":1613277184278,"symbol":"BCHSV-USDT","changes":{"asks":[["0","0","1613277184278"]],"bids":[]},"sequenceEnd":1613277184278},"subject":"trade.l2update","topic":"/market/level2:BCHSV-USDT","type":"message"}
1619378332.035964: {"data":{"sequenceStart":1613277184279,"symbol":"BCHSV-USDT","changes":{"asks":[["243.141","0.6","1613277184279"]],"bids":[]},"sequenceEnd":1613277184279},"subject":"trade.l2update","topic":"/market/level2:BCHSV-USDT","type":"message"}
1619378332.063396: {"data":{"sequenceStart":1613277184280,"symbol":"BCHSV-USDT","changes":{"asks":[["0","0","1613277184280"]],"bids":[]},"sequenceEnd":1613277184280},"subject":"trade.l2update","topic":"/market/level2:BCHSV-USDT","type":"message"}
1619378332.063508: {"data":{"sequenceStart":1613277184281,"symbol":"BCHSV-USDT","changes":{"asks":[["243.001","3.73844146","1613277184281"]],"bids":[]},"sequenceEnd":1613277184281},"subject":"trade.l2update","topic":"/market/level2:BCHSV-USDT","type":"message"}
1619378332.070474: {"data":{"sequence":"1613277184281","bestAsk":"242.933","size":"0.08000012","bestBidSize":"5.68148185","price":"243.65","time":1619378332033,"bestAskSize":"5.98","bestBid":"242.532"},"subject":"trade.ticker","topic":"/market/ticker:BCHSV-USDT","type":"message"}
1619378332.135832: {"data":{"sequenceStart":1613277184282,"symbol":"BCHSV-USDT","changes":{"asks":[],"bids":[["242.532","0.68148185","1613277184282"]]},"sequenceEnd":1613277184282},"subject":"trade.l2update","topic":"/market/level2:BCHSV-USDT","type":"message"}
1619378332.1431522: {"data":{"sequenceStart":1613277184283,"symbol":"BCHSV-USDT","changes":{"asks":[["243.032","0","1613277184283"]],"bids":[]},"sequenceEnd":1613277184283},"subject":"trade.l2update","topic":"/market/level2:BCHSV-USDT","type":"message"}
1619378332.174988: {"data":{"sequence":"1613277184283","bestAsk":"242.933","size":"0.08000012","bestBidSize":"0.68148185","price":"243.65","time":1619378332131,"bestAskSize":"5.98","bestBid":"242.532"},"subject":"trade.ticker","topic":"/market/ticker:BCHSV-USDT","type":"message"}
1619378332.180629: {"data":{"sequenceStart":1613277184284,"symbol":"BCHSV-USDT","changes":{"asks":[],"bids":[["0","0","1613277184284"]]},"sequenceEnd":1613277184284},"subject":"trade.l2update","topic":"/market/level2:BCHSV-USDT","type":"message"}
1619378332.180741: {"data":{"sequenceStart":1613277184285,"symbol":"BCHSV-USDT","changes":{"asks":[],"bids":[["242.601","4.51280965","1613277184285"]]},"sequenceEnd":1613277184285},"subject":"trade.l2update","topic":"/market/level2:BCHSV-USDT","type":"message"}
1619378332.180816: {"data":{"sequenceStart":1613277184286,"symbol":"BCHSV-USDT","changes":{"asks":[["0","0","1613277184286"]],"bids":[]},"sequenceEnd":1613277184286},"subject":"trade.l2update","topic":"/market/level2:BCHSV-USDT","type":"message"}
1619378332.1808581: {"data":{"sequenceStart":1613277184287,"symbol":"BCHSV-USDT","changes":{"asks":[["242.901","4.51280965","1613277184287"]],"bids":[]},"sequenceEnd":1613277184287},"subject":"trade.l2update","topic":"/market/level2:BCHSV-USDT","type":"message"}
1619378332.1897779: {"data":{"sequenceStart":1612712745622,"symbol":"FET-BTC","changes":{"asks":[["0","0","1612712745622"]],"bids":[]},"sequenceEnd":1612712745622},"subject":"trade.l2update","topic":"/market/level2:FET-BTC","type":"message"}
1619378332.189889: {"data":{"sequenceStart":1612712745623,"symbol":"FET-BTC","changes":{"asks":[["0.00000779","596.8955","1612712745623"]],"bids":[]},"sequenceEnd":1612712745623},"subject":"trade.l2update","topic":"/market/level2:FET-BTC","type":"message"}
1619378332.189972: {"data":{"sequenceStart":1613277184288,"symbol":"BCHSV-USDT","changes":{"asks":[],"bids":[["240.138","0","1613277184288"]]},"sequenceEnd":1613277184288},"subject":"trade.l2update","topic":"/market/level2:BCHSV-USDT","type":"message"}
1619378332.200536: {"data":{"sequenceStart":1613277184289,"symbol":"BCHSV-USDT","changes":{"asks":[],"bids":[["242.532","0","1613277184289"]]},"sequenceEnd":1613277184289},"subject":"trade.l2update","topic":"/market/level2:BCHSV-USDT","type":"message"}
1619378332.2006762: {"data":{"sequenceStart":1613277184290,"symbol":"BCHSV-USDT","changes":{"asks":[["243.141","0","1613277184290"]],"bids":[]},"sequenceEnd":1613277184290},"subject":"trade.l2update","topic":"/market/level2:BCHSV-USDT","type":"message"}
1619378332.210156: {"data":{"sequence":"1612712745623","bestAsk":"0.00000775","size":"401.2004","bestBidSize":"357.285","price":"0.00000772","time":1619378332167,"bestAskSize":"1154.0416","bestBid":"0.00000771"},"subject":"trade.ticker","topic":"/market/ticker:FET-BTC","type":"message"}
1619378332.210258: {"data":{"sequenceStart":1613277184291,"symbol":"BCHSV-USDT","changes":{"asks":[["243.001","0","1613277184291"]],"bids":[]},"sequenceEnd":1613277184291},"subject":"trade.l2update","topic":"/market/level2:BCHSV-USDT","type":"message"}
1619378332.216937: {"data":{"sequenceStart":1612844051771,"symbol":"SNX-BTC","changes":{"asks":[["0.00028719","0","1612844051771"]],"bids":[]},"sequenceEnd":1612844051771},"subject":"trade.l2update","topic":"/market/level2:SNX-BTC","type":"message"}
1619378332.220204: {"data":{"sequenceStart":1613277184292,"symbol":"BCHSV-USDT","changes":{"asks":[["242.934","0","1613277184292"]],"bids":[]},"sequenceEnd":1613277184292},"subject":"trade.l2update","topic":"/market/level2:BCHSV-USDT","type":"message"}
1619378332.220344: {"data":{"sequenceStart":1613277184293,"symbol":"BCHSV-USDT","changes":{"asks":[],"bids":[["242.219","0","1613277184293"]]},"sequenceEnd":1613277184293},"subject":"trade.l2update","topic":"/market/level2:BCHSV-USDT","type":"message"}
1619378332.240445: {"data":{"sequenceStart":1613277184294,"symbol":"BCHSV-USDT","changes":{"asks":[["0","0","1613277184294"]],"bids":[]},"sequenceEnd":1613277184294},"subject":"trade.l2update","topic":"/market/level2:BCHSV-USDT","type":"message"}
1619378332.240556: {"data":{"sequenceStart":1613277184295,"symbol":"BCHSV-USDT","changes":{"asks":[["242.903","1","1613277184295"]],"bids":[]},"sequenceEnd":1613277184295},"subject":"trade.l2update","topic":"/market/level2:BCHSV-USDT","type":"message"}
1619378332.2526588: {"data":{"sequenceStart":1612712745624,"symbol":"FET-BTC","changes":{"asks":[["0.00000779","0","1612712745624"]],"bids":[]},"sequenceEnd":1612712745624},"subject":"trade.l2update","topic":"/market/level2:FET-BTC","type":"message"}
1619378332.2625742: {"data":{"sequence":"1612844051771","bestAsk":"0.00028713","size":"0.01745248","bestBidSize":"0.19100065","price":"0.00028676","time":1619378332223,"bestAskSize":"29.24570683","bestBid":"0.00028678"},"subject":"trade.ticker","topic":"/market/ticker:SNX-BTC","type":"message"}
1619378332.2682261: {"data":{"sequence":"1613277184295","bestAsk":"242.901","size":"0.08000012","bestBidSize":"4.51280965","price":"243.65","time":1619378332232,"bestAskSize":"4.51280965","bestBid":"242.601"},"subject":"trade.ticker","topic":"/market/ticker:BCHSV-USDT","type":"message"}
1619378332.279156: {"data":{"sequenceStart":1613277184296,"symbol":"BCHSV-USDT","changes":{"asks":[["243.546","0","1613277184296"]],"bids":[]},"sequenceEnd":1613277184296},"subject":"trade.l2update","topic":"/market/level2:BCHSV-USDT","type":"message"}
1619378332.28746: {"data":{"sequenceStart":1612844051772,"symbol":"SNX-BTC","changes":{"asks":[],"bids":[["0.00028655","0","1612844051772"]]},"sequenceEnd":1612844051772},"subject":"trade.l2update","topic":"/market/level2:SNX-BTC","type":"message"}
1619378332.287544: {"data":{"sequenceStart":1612734157766,"symbol":"ANKR-BTC","changes":{"asks":[],"bids":[["0.0000025996","0","1612734157766"]]},"sequenceEnd":1612734157766},"subject":"trade.l2update","topic":"/market/level2:ANKR-BTC","type":"message"}
1619378332.300969: {"data":{"sequenceStart":1613277184297,"symbol":"BCHSV-USDT","changes":{"asks":[["242.903","0","1613277184297"]],"bids":[]},"sequenceEnd":1613277184297},"subject":"trade.l2update","topic":"/market/level2:BCHSV-USDT","type":"message"}
1619378332.307204: {"data":{"sequence":"1612712745624","bestAsk":"0.00000775","size":"401.2004","bestBidSize":"357.285","price":"0.00000772","time":1619378332269,"bestAskSize":"1154.0416","bestBid":"0.00000771"},"subject":"trade.ticker","topic":"/market/ticker:FET-BTC","type":"message"}
1619378332.321759: {"data":{"sequenceStart":1612734157767,"symbol":"ANKR-BTC","changes":{"asks":[],"bids":[["0.0000025952","0","1612734157767"]]},"sequenceEnd":1612734157767},"subject":"trade.l2update","topic":"/market/level2:ANKR-BTC","type":"message"}
1619378332.321903: {"data":{"sequenceStart":1612844051773,"symbol":"SNX-BTC","changes":{"asks":[["0","0","1612844051773"]],"bids":[]},"sequenceEnd":1612844051773},"subject":"trade.l2update","topic":"/market/level2:SNX-BTC","type":"message"}
1619378332.321961: {"data":{"sequenceStart":1612844051774,"symbol":"SNX-BTC","changes":{"asks":[["0.00028712","73.39457178","1612844051774"]],"bids":[]},"sequenceEnd":1612844051774},"subject":"trade.l2update","topic":"/market/level2:SNX-BTC","type":"message"}
1619378332.3274: {"data":{"sequence":"1612734157767","bestAsk":"0.0000026187","size":"46","bestBidSize":"4051.2663","price":"0.0000026071","time":1619378332288,"bestAskSize":"4664.7644","bestBid":"0.0000026033"},"subject":"trade.ticker","topic":"/market/ticker:ANKR-BTC","type":"message"}
1619378332.337159: {"data":{"sequenceStart":1613277184298,"symbol":"BCHSV-USDT","changes":{"asks":[["0","0","1613277184298"]],"bids":[]},"sequenceEnd":1613277184298},"subject":"trade.l2update","topic":"/market/level2:BCHSV-USDT","type":"message"}
1619378332.337276: {"data":{"sequenceStart":1613277184299,"symbol":"BCHSV-USDT","changes":{"asks":[["242.822","0.6","1613277184299"]],"bids":[]},"sequenceEnd":1613277184299},"subject":"trade.l2update","topic":"/market/level2:BCHSV-USDT","type":"message"}
1619378332.3422341: {"data":{"sequenceStart":1612844051775,"symbol":"SNX-BTC","changes":{"asks":[],"bids":[["0","0","1612844051775"]]},"sequenceEnd":1612844051775},"subject":"trade.l2update","topic":"/market/level2:SNX-BTC","type":"message"}
1619378332.342286: {"data":{"sequenceStart":1612844051776,"symbol":"SNX-BTC","changes":{"asks":[],"bids":[["0.00028655","2.1097563","1612844051776"]]},"sequenceEnd":1612844051776},"subject":"trade.l2update","topic":"/market/level2:SNX-BTC","type":"message"}
1619378332.35086: {"data":{"sequenceStart":1612844051777,"symbol":"SNX-BTC","changes":{"asks":[],"bids":[["0","0","1612844051777"]]},"sequenceEnd":1612844051777},"subject":"trade.l2update","topic":"/market/level2:SNX-BTC","type":"message"}
1619378332.350903: {"data":{"sequenceStart":1612844051778,"symbol":"SNX-BTC","changes":{"asks":[],"bids":[["0.00028616","2.10974118","1612844051778"]]},"sequenceEnd":1612844051778},"subject":"trade.l2update","topic":"/market/level2:SNX-BTC","type":"message"}
1619378332.361324: {"data":{"sequenceStart":1612844051779,"symbol":"SNX-BTC","changes":{"asks":[["0","0","1612844051779"]],"bids":[]},"sequenceEnd":1612844051779},"subject":"trade.l2update","topic":"/market/level2:SNX-BTC","type":"message"}
1619378332.361433: {"data":{"sequenceStart":1612844051780,"symbol":"SNX-BTC","changes":{"asks":[["0.00028737","10.01376568","1612844051780"]],"bids":[]},"sequenceEnd":1612844051780},"subject":"trade.l2update","topic":"/market/level2:SNX-BTC","type":"message"}
1619378332.370744: {"data":{"sequence":"1613277184299","bestAsk":"242.822","size":"0.08000012","bestBidSize":"4.51280965","price":"243.65","time":1619378332331,"bestAskSize":"0.6","bestBid":"242.601"},"subject":"trade.ticker","topic":"/market/ticker:BCHSV-USDT","type":"message"}
1619378332.389378: {"data":{"sequence":"1612844051780","bestAsk":"0.00028712","size":"0.01745248","bestBidSize":"0.19100065","price":"0.00028676","time":1619378332348,"bestAskSize":"73.39457178","bestBid":"0.00028678"},"subject":"trade.ticker","topic":"/market/ticker:SNX-BTC","type":"message"}
1619378332.389469: {"data":{"sequenceStart":1612734157768,"symbol":"ANKR-BTC","changes":{"asks":[],"bids":[["0","0","1612734157768"]]},"sequenceEnd":1612734157768},"subject":"trade.l2update","topic":"/market/level2:ANKR-BTC","type":"message"}
1619378332.389535: {"data":{"sequenceStart":1612734157769,"symbol":"ANKR-BTC","changes":{"asks":[],"bids":[["0.0000025995","3500.1441","1612734157769"]]},"sequenceEnd":1612734157769},"subject":"trade.l2update","topic":"/market/level2:ANKR-BTC","type":"message"}
1619378332.40165: {"data":{"sequenceStart":1612844051781,"symbol":"SNX-BTC","changes":{"asks":[["0.00028737","0.01376935","1612844051781"]],"bids":[]},"sequenceEnd":1612844051781},"subject":"trade.l2update","topic":"/market/level2:SNX-BTC","type":"message"}
1619378332.401773: {"data":{"sequenceStart":1613277184300,"symbol":"BCHSV-USDT","changes":{"asks":[["0","0","1613277184300"]],"bids":[]},"sequenceEnd":1613277184300},"subject":"trade.l2update","topic":"/market/level2:BCHSV-USDT","type":"message"}
1619378332.401848: {"data":{"sequenceStart":1613277184301,"symbol":"BCHSV-USDT","changes":{"asks":[["244.22","150","1613277184301"]],"bids":[]},"sequenceEnd":1613277184301},"subject":"trade.l2update","topic":"/market/level2:BCHSV-USDT","type":"message"}
1619378332.4018922: {"data":{"sequenceStart":1613277184302,"symbol":"BCHSV-USDT","changes":{"asks":[["0","0","1613277184302"]],"bids":[]},"sequenceEnd":1613277184302},"subject":"trade.l2update","topic":"/market/level2:BCHSV-USDT","type":"message"}
1619378332.4019158: {"data":{"sequenceStart":1613277184303,"symbol":"BCHSV-USDT","changes":{"asks":[["243.583","5","1613277184303"]],"bids":[]},"sequenceEnd":1613277184303},"subject":"trade.l2update","topic":"/market/level2:BCHSV-USDT","type":"message"}
1619378332.410073: {"data":{"sequenceStart":1613277184304,"symbol":"BCHSV-USDT","changes":{"asks":[],"bids":[["0","0","1613277184304"]]},"sequenceEnd":1613277184304},"subject":"trade.l2update","topic":"/market/level2:BCHSV-USDT","type":"message"}
1619378332.410184: {"data":{"sequenceStart":1613277184305,"symbol":"BCHSV-USDT","changes":{"asks":[],"bids":[["241.423","5","1613277184305"]]},"sequenceEnd":1613277184305},"subject":"trade.l2update","topic":"/market/level2:BCHSV-USDT","type":"message"}
1619378332.410261: {"data":{"sequenceStart":1613277184306,"symbol":"BCHSV-USDT","changes":{"asks":[["0","0","1613277184306"]],"bids":[]},"sequenceEnd":1613277184306},"subject":"trade.l2update","topic":"/market/level2:BCHSV-USDT","type":"message"}
1619378332.4103029: {"data":{"sequenceStart":1613277184307,"symbol":"BCHSV-USDT","changes":{"asks":[["243.004","3.73844146","1613277184307"]],"bids":[]},"sequenceEnd":1613277184307},"subject":"trade.l2update","topic":"/market/level2:BCHSV-USDT","type":"message"}
1619378332.421619: {"data":{"sequenceStart":1612844051782,"symbol":"SNX-BTC","changes":{"asks":[],"bids":[["0.00028616","0","1612844051782"]]},"sequenceEnd":1612844051782},"subject":"trade.l2update","topic":"/market/level2:SNX-BTC","type":"message"}
1619378332.426388: {"data":{"sequence":"1612734157769","bestAsk":"0.0000026187","size":"46","bestBidSize":"4051.2663","price":"0.0000026071","time":1619378332388,"bestAskSize":"4664.7644","bestBid":"0.0000026033"},"subject":"trade.ticker","topic":"/market/ticker:ANKR-BTC","type":"message"}
1619378332.434428: {"data":{"sequenceStart":1612844051783,"symbol":"SNX-BTC","changes":{"asks":[["0.00028713","0","1612844051783"]],"bids":[]},"sequenceEnd":1612844051783},"subject":"trade.l2update","topic":"/market/level2:SNX-BTC","type":"message"}
1619378332.4408278: {"data":{"sequenceStart":1613277184308,"symbol":"BCHSV-USDT","changes":{"asks":[["243.004","0","1613277184308"]],"bids":[]},"sequenceEnd":1613277184308},"subject":"trade.l2update","topic":"/market/level2:BCHSV-USDT","type":"message"}
1619378332.45073: {"data":{"sequenceStart":1612712745625,"symbol":"FET-BTC","changes":{"asks":[["0","0","1612712745625"]],"bids":[]},"sequenceEnd":1612712745625},"subject":"trade.l2update","topic":"/market/level2:FET-BTC","type":"message"}
1619378332.4508421: {"data":{"sequenceStart":1612712745626,"symbol":"FET-BTC","changes":{"asks":[["0.00000779","1630.4488","1612712745626"]],"bids":[]},"sequenceEnd":1612712745626},"subject":"trade.l2update","topic":"/market/level2:FET-BTC","type":"message"}
1619378332.450924: {"data":{"sequenceStart":1613277184309,"symbol":"BCHSV-USDT","changes":{"asks":[],"bids":[["0","0","1613277184309"]]},"sequenceEnd":1613277184309},"subject":"trade.l2update","topic":"/market/level2:BCHSV-USDT","type":"message"}
1619378332.450968: {"data":{"sequenceStart":1613277184310,"symbol":"BCHSV-USDT","changes":{"asks":[],"bids":[["242.565","5","1613277184310"]]},"sequenceEnd":1613277184310},"subject":"trade.l2update","topic":"/market/level2:BCHSV-USDT","type":"message"}
1619378332.493999: {"data":{"sequence":"1613277184310","bestAsk":"242.822","size":"0.08000012","bestBidSize":"4.51280965","price":"243.65","time":1619378332433,"bestAskSize":"0.6","bestBid":"242.601"},"subject":"trade.ticker","topic":"/market/ticker:BCHSV-USDT","type":"message"}
1619378332.501972: {"data":{"sequenceStart":1613277184311,"symbol":"BCHSV-USDT","changes":{"asks":[["0","0","1613277184311"]],"bids":[]},"sequenceEnd":1613277184311},"subject":"trade.l2update","topic":"/market/level2:BCHSV-USDT","type":"message"}
1619378332.502079: {"data":{"sequenceStart":1613277184312,"symbol":"BCHSV-USDT","changes":{"asks":[["243.546","9.21197685","1613277184312"]],"bids":[]},"sequenceEnd":1613277184312},"subject":"trade.l2update","topic":"/market/level2:BCHSV-USDT","type":"message"}
1619378332.5021598: {"data":{"sequenceStart":1613277184313,"symbol":"BCHSV-USDT","changes":{"asks":[["0","0","1613277184313"]],"bids":[]},"sequenceEnd":1613277184313},"subject":"trade.l2update","topic":"/market/level2:BCHSV-USDT","type":"message"}
1619378332.502202: {"data":{"sequenceStart":1613277184314,"symbol":"BCHSV-USDT","changes":{"asks":[["243.011","6.17993851","1613277184314"]],"bids":[]},"sequenceEnd":1613277184314},"subject":"trade.l2update","topic":"/market/level2:BCHSV-USDT","type":"message"}
1619378332.502283: {"data":{"sequenceStart":1613277184315,"symbol":"BCHSV-USDT","changes":{"asks":[],"bids":[["0","0","1613277184315"]]},"sequenceEnd":1613277184315},"subject":"trade.l2update","topic":"/market/level2:BCHSV-USDT","type":"message"}
1619378332.5023081: {"data":{"sequenceStart":1613277184316,"symbol":"BCHSV-USDT","changes":{"asks":[],"bids":[["242.298","6.17993851","1613277184316"]]},"sequenceEnd":1613277184316},"subject":"trade.l2update","topic":"/market/level2:BCHSV-USDT","type":"message"}
1619378332.5054631: {"data":{"sequence":"1612844051783","bestAsk":"0.00028712","size":"0.01745248","bestBidSize":"0.19100065","price":"0.00028676","time":1619378332447,"bestAskSize":"73.39457178","bestBid":"0.00028678"},"subject":"trade.ticker","topic":"/market/ticker:SNX-BTC","type":"message"}
1619378332.505572: {"data":{"sequenceStart":1612712745627,"symbol":"FET-BTC","changes":{"asks":[["0.00000779","0","1612712745627"]],"bids":[]},"sequenceEnd":1612712745627},"subject":"trade.l2update","topic":"/market/level2:FET-BTC","type":"message"}
1619378332.5113091: {"data":{"sequenceStart":1613277184317,"symbol":"BCHSV-USDT","changes":{"asks":[["242.822","0","1613277184317"]],"bids":[]},"sequenceEnd":1613277184317},"subject":"trade.l2update","topic":"/market/level2:BCHSV-USDT","type":"message"}
1619378332.51145: {"data":{"sequence":"1612712745627","bestAsk":"0.00000775","size":"401.2004","bestBidSize":"357.285","price":"0.00000772","time":1619378332467,"bestAskSize":"1154.0416","bestBid":"0.00000771"},"subject":"trade.ticker","topic":"/market/ticker:FET-BTC","type":"message"}
1619378332.511498: {"data":{"sequenceStart":1612844051784,"symbol":"SNX-BTC","changes":{"asks":[["0","0","1612844051784"]],"bids":[]},"sequenceEnd":1612844051784},"subject":"trade.l2update","topic":"/market/level2:SNX-BTC","type":"message"}
1619378332.5115469: {"data":{"sequenceStart":1612844051785,"symbol":"SNX-BTC","changes":{"asks":[["0.00028737","0.07994587","1612844051785"]],"bids":[]},"sequenceEnd":1612844051785},"subject":"trade.l2update","topic":"/market/level2:SNX-BTC","type":"message"}
1619378332.5168772: {"data":{"sequenceStart":1613277184318,"symbol":"BCHSV-USDT","changes":{"asks":[["0","0","1613277184318"]],"bids":[]},"sequenceEnd":1613277184318},"subject":"trade.l2update","topic":"/market/level2:BCHSV-USDT","type":"message"}
1619378332.5169861: {"data":{"sequenceStart":1613277184319,"symbol":"BCHSV-USDT","changes":{"asks":[["243.151","0.6","1613277184319"]],"bids":[]},"sequenceEnd":1613277184319},"subject":"trade.l2update","topic":"/market/level2:BCHSV-USDT","type":"message"}
1619378332.517065: {"data":{"sequenceStart":1613277184320,"symbol":"BCHSV-USDT","changes":{"asks":[],"bids":[["0","0","1613277184320"]]},"sequenceEnd":1613277184320},"subject":"trade.l2update","topic":"/market/level2:BCHSV-USDT","type":"message"}
1619378332.517129: {"data":{"sequenceStart":1613277184321,"symbol":"BCHSV-USDT","changes":{"asks":[],"bids":[["242.562","0.68148185","1613277184321"]]},"sequenceEnd":1613277184321},"subject":"trade.l2update","topic":"/market/level2:BCHSV-USDT","type":"message"}
1619378332.533828: {"data":{"sequenceStart":1612844051786,"symbol":"SNX-BTC","changes":{"asks":[["0.00028737","0.01376935","1612844051786"]],"bids":[]},"sequenceEnd":1612844051786},"subject":"trade.l2update","topic":"/market/level2:SNX-BTC","type":"message"}
1619378332.539639: {"data":{"sequenceStart":1612694580158,"symbol":"CAPP-BTC","changes":{"asks":[],"bids":[["0","0","1612694580158"]]},"sequenceEnd":1612694580158},"subject":"trade.l2update","topic":"/market/level2:CAPP-BTC","type":"message"}
1619378332.539747: {"data":{"sequenceStart":1612694580159,"symbol":"CAPP-BTC","changes":{"asks":[],"bids":[["0.0000001511","5308.9","1612694580159"]]},"sequenceEnd":1612694580159},"subject":"trade.l2update","topic":"/market/level2:CAPP-BTC","type":"message"}
1619378332.559073: {"data":{"sequence":"1612844051786","bestAsk":"0.00028712","size":"0.01745248","bestBidSize":"0.19100065","price":"0.00028676","time":1619378332523,"bestAskSize":"73.39457178","bestBid":"0.00028678"},"subject":"trade.ticker","topic":"/market/ticker:SNX-BTC","type":"message"}
1619378332.5591621: {"data":{"sequenceStart":1613277184322,"symbol":"BCHSV-USDT","changes":{"asks":[],"bids":[["242.601","0","1613277184322"]]},"sequenceEnd":1613277184322},"subject":"trade.l2update","topic":"/market/level2:BCHSV-USDT","type":"message"}
1619378332.5753129: {"data":{"sequenceStart":1613277184323,"symbol":"BCHSV-USDT","changes":{"asks":[["244.105","0","1613277184323"]],"bids":[]},"sequenceEnd":1613277184323},"subject":"trade.l2update","topic":"/market/level2:BCHSV-USDT","type":"message"}
1619378332.5754519: {"data":{"sequence":"1613277184323","bestAsk":"242.901","size":"0.08000012","bestBidSize":"5","price":"243.65","time":1619378332531,"bestAskSize":"4.51280965","bestBid":"242.565"},"subject":"trade.ticker","topic":"/market/ticker:BCHSV-USDT","type":"message"}
1619378332.575501: {"data":{"sequenceStart":1612844051787,"symbol":"SNX-BTC","changes":{"asks":[["0","0","1612844051787"]],"bids":[]},"sequenceEnd":1612844051787},"subject":"trade.l2update","topic":"/market/level2:SNX-BTC","type":"message"}
1619378332.575555: {"data":{"sequenceStart":1612844051788,"symbol":"SNX-BTC","changes":{"asks":[["0.00028711","29.24570683","1612844051788"]],"bids":[]},"sequenceEnd":1612844051788},"subject":"trade.l2update","topic":"/market/level2:SNX-BTC","type":"message"}
1619378332.5756228: {"data":{"sequenceStart":1612844051789,"symbol":"SNX-BTC","changes":{"asks":[["0","0","1612844051789"]],"bids":[]},"sequenceEnd":1612844051789},"subject":"trade.l2update","topic":"/market/level2:SNX-BTC","type":"message"}
1619378332.575646: {"data":{"sequenceStart":1612844051790,"symbol":"SNX-BTC","changes":{"asks":[["0.00028737","4.54501714","1612844051790"]],"bids":[]},"sequenceEnd":1612844051790},"subject":"trade.l2update","topic":"/market/level2:SNX-BTC","type":"message"}
1619378332.5782871: {"data":{"sequenceStart":1613277184324,"symbol":"BCHSV-USDT","changes":{"asks":[["0","0","1613277184324"]],"bids":[]},"sequenceEnd":1613277184324},"subject":"trade.l2update","topic":"/market/level2:BCHSV-USDT","type":"message"}
1619378332.578363: {"data":{"sequenceStart":1613277184325,"symbol":"BCHSV-USDT","changes":{"asks":[["243.004","3.73844146","1613277184325"]],"bids":[]},"sequenceEnd":1613277184325},"subject":"trade.l2update","topic":"/market/level2:BCHSV-USDT","type":"message"}
1619378332.5922759: {"data":{"sequenceStart":1612712745628,"symbol":"FET-BTC","changes":{"asks":[["0","0","1612712745628"]],"bids":[]},"sequenceEnd":1612712745628},"subject":"trade.l2update","topic":"/market/level2:FET-BTC","type":"message"}
1619378332.592385: {"data":{"sequenceStart":1612712745629,"symbol":"FET-BTC","changes":{"asks":[["0.00000779","1630.4488","1612712745629"]],"bids":[]},"sequenceEnd":1612712745629},"subject":"trade.l2update","topic":"/market/level2:FET-BTC","type":"message"}
1619378332.612402: {"data":{"sequenceStart":1612712745630,"symbol":"FET-BTC","changes":{"asks":[["0.00000779","0","1612712745630"]],"bids":[]},"sequenceEnd":1612712745630},"subject":"trade.l2update","topic":"/market/level2:FET-BTC","type":"message"}
1619378332.6269271: {"data":{"sequenceStart":1612844051791,"symbol":"SNX-BTC","changes":{"asks":[["0","0","1612844051791"]],"bids":[]},"sequenceEnd":1612844051791},"subject":"trade.l2update","topic":"/market/level2:SNX-BTC","type":"message"}
1619378332.627038: {"data":{"sequenceStart":1612844051792,"symbol":"SNX-BTC","changes":{"asks":[["0.00028736","4.88060646","1612844051792"]],"bids":[]},"sequenceEnd":1612844051792},"subject":"trade.l2update","topic":"/market/level2:SNX-BTC","type":"message"}
1619378332.627118: {"data":{"sequenceStart":1612844051793,"symbol":"SNX-BTC","changes":{"asks":[["0.00028737","0.01376935","1612844051793"]],"bids":[]},"sequenceEnd":1612844051793},"subject":"trade.l2update","topic":"/market/level2:SNX-BTC","type":"message"}
1619378332.627168: {"data":{"sequence":"1612712745629","bestAsk":"0.00000775","size":"401.2004","bestBidSize":"357.285","price":"0.00000772","time":1619378332567,"bestAskSize":"1154.0416","bestBid":"0.00000771"},"subject":"trade.ticker","topic":"/market/ticker:FET-BTC","type":"message"}
1619378332.6272058: {"data":{"sequenceStart":1612701563961,"symbol":"DAPPT-BTC","changes":{"asks":[["0.0000001133","4948.0983","1612701563961"]],"bids":[]},"sequenceEnd":1612701563961},"subject":"trade.l2update","topic":"/market/level2:DAPPT-BTC","type":"message"}
1619378332.6272588: {"data":{"sequence":"1612694580159","bestAsk":"0.0000002196","size":"1000.02","bestBidSize":"83.07","price":"0.0000002182","time":1619378332581,"bestAskSize":"4490.25","bestBid":"0.0000002181"},"subject":"trade.ticker","topic":"/market/ticker:CAPP-BTC","type":"message"}
1619378332.6273012: {"data":{"sequenceStart":1613277184326,"symbol":"BCHSV-USDT","changes":{"asks":[["243.546","0","1613277184326"]],"bids":[]},"sequenceEnd":1613277184326},"subject":"trade.l2update","topic":"/market/level2:BCHSV-USDT","type":"message"}
1619378332.633624: {"data":{"sequenceStart":1613277184327,"symbol":"BCHSV-USDT","changes":{"asks":[],"bids":[["242.565","0","1613277184327"]]},"sequenceEnd":1613277184327},"subject":"trade.l2update","topic":"/market/level2:BCHSV-USDT","type":"message"}
1619378332.64351: {"data":{"sequenceStart":1613277184328,"symbol":"BCHSV-USDT","changes":{"asks":[["243.004","0","1613277184328"]],"bids":[]},"sequenceEnd":1613277184328},"subject":"trade.l2update","topic":"/market/level2:BCHSV-USDT","type":"message"}
1619378332.6495109: {"data":{"sequenceStart":1612844051794,"symbol":"SNX-BTC","changes":{"asks":[["0.00028736","0","1612844051794"]],"bids":[]},"sequenceEnd":1612844051794},"subject":"trade.l2update","topic":"/market/level2:SNX-BTC","type":"message"}
1619378332.65786: {"data":{"sequenceStart":1612734157770,"symbol":"ANKR-BTC","changes":{"asks":[],"bids":[["0.0000025995","0","1612734157770"]]},"sequenceEnd":1612734157770},"subject":"trade.l2update","topic":"/market/level2:ANKR-BTC","type":"message"}
1619378332.6721568: {"data":{"sequence":"1613277184328","bestAsk":"242.901","size":"0.08000012","bestBidSize":"0.68148185","price":"243.65","time":1619378332633,"bestAskSize":"4.51280965","bestBid":"242.562"},"subject":"trade.ticker","topic":"/market/ticker:BCHSV-USDT","type":"message"}
1619378332.6813178: {"data":{"sequence":"1612844051794","bestAsk":"0.00028711","size":"0.01745248","bestBidSize":"0.19100065","price":"0.00028676","time":1619378332645,"bestAskSize":"29.24570683","bestBid":"0.00028678"},"subject":"trade.ticker","topic":"/market/ticker:SNX-BTC","type":"message"}
1619378332.689976: {"data":{"sequence":"1612701563961","bestAsk":"0.000000113","size":"145.4959","bestBidSize":"3774.8315","price":"0.0000001126","time":1619378332630,"bestAskSize":"1208.0878","bestBid":"0.0000001116"},"subject":"trade.ticker","topic":"/market/ticker:DAPPT-BTC","type":"message"}
1619378332.696671: {"data":{"sequenceStart":1613277184329,"symbol":"BCHSV-USDT","changes":{"asks":[],"bids":[["242.562","0","1613277184329"]]},"sequenceEnd":1613277184329},"subject":"trade.l2update","topic":"/market/level2:BCHSV-USDT","type":"message"}
1619378332.6968079: {"data":{"sequenceStart":1612712745631,"symbol":"FET-BTC","changes":{"asks":[["0","0","1612712745631"]],"bids":[]},"sequenceEnd":1612712745631},"subject":"trade.l2update","topic":"/market/level2:FET-BTC","type":"message"}
1619378332.696866: {"data":{"sequenceStart":1612712745632,"symbol":"FET-BTC","changes":{"asks":[["0.00000785","535.6272","1612712745632"]],"bids":[]},"sequenceEnd":1612712745632},"subject":"trade.l2update","topic":"/market/level2:FET-BTC","type":"message"}
1619378332.696917: {"data":{"sequenceStart":1612734157771,"symbol":"ANKR-BTC","changes":{"asks":[],"bids":[["0","0","1612734157771"]]},"sequenceEnd":1612734157771},"subject":"trade.l2update","topic":"/market/level2:ANKR-BTC","type":"message"}
1619378332.696975: {"data":{"sequenceStart":1612734157772,"symbol":"ANKR-BTC","changes":{"asks":[],"bids":[["0.0000025992","3500.5481","1612734157772"]]},"sequenceEnd":1612734157772},"subject":"trade.l2update","topic":"/market/level2:ANKR-BTC","type":"message"}
1619378332.7025862: {"data":{"sequenceStart":1612701563962,"symbol":"DAPPT-BTC","changes":{"asks":[["0","0","1612701563962"]],"bids":[]},"sequenceEnd":1612701563962},"subject":"trade.l2update","topic":"/market/level2:DAPPT-BTC","type":"message"}
1619378332.702662: {"data":{"sequenceStart":1612701563963,"symbol":"DAPPT-BTC","changes":{"asks":[["0.0000001133","6048.9923","1612701563963"]],"bids":[]},"sequenceEnd":1612701563963},"subject":"trade.l2update","topic":"/market/level2:DAPPT-BTC","type":"message"}
1619378332.70799: {"data":{"sequence":"1612712745632","bestAsk":"0.00000775","size":"401.2004","bestBidSize":"357.285","price":"0.00000772","time":1619378332667,"bestAskSize":"1154.0416","bestBid":"0.00000771"},"subject":"trade.ticker","topic":"/market/ticker:FET-BTC","type":"message"}
1619378332.7080839: {"data":{"sequenceStart":1612844051795,"symbol":"SNX-BTC","changes":{"asks":[],"bids":[["0.00028655","0","1612844051795"]]},"sequenceEnd":1612844051795},"subject":"trade.l2update","topic":"/market/level2:SNX-BTC","type":"message"}
1619378332.7081852: {"data":{"sequenceStart":1612844051796,"symbol":"SNX-BTC","changes":{"asks":[["0.00029096","0","1612844051796"]],"bids":[]},"sequenceEnd":1612844051796},"subject":"trade.l2update","topic":"/market/level2:SNX-BTC","type":"message"}
1619378332.70829: {"data":{"sequenceStart":1613277184330,"symbol":"BCHSV-USDT","changes":{"asks":[["243.151","0","1613277184330"]],"bids":[]},"sequenceEnd":1613277184330},"subject":"trade.l2update","topic":"/market/level2:BCHSV-USDT","type":"message"}
1619378332.70833: {"data":{"sequenceStart":1613277184331,"symbol":"BCHSV-USDT","changes":{"asks":[["0","0","1613277184331"]],"bids":[]},"sequenceEnd":1613277184331},"subject":"trade.l2update","topic":"/market/level2:BCHSV-USDT","type":"message"}
1619378332.708354: {"data":{"sequenceStart":1613277184332,"symbol":"BCHSV-USDT","changes":{"asks":[["242.9","9.88630737","1613277184332"]],"bids":[]},"sequenceEnd":1613277184332},"subject":"trade.l2update","topic":"/market/level2:BCHSV-USDT","type":"message"}
1619378332.717301: {"data":{"sequenceStart":1613277184333,"symbol":"BCHSV-USDT","changes":{"asks":[["0","0","1613277184333"]],"bids":[]},"sequenceEnd":1613277184333},"subject":"trade.l2update","topic":"/market/level2:BCHSV-USDT","type":"message"}
1619378332.717356: {"data":{"sequenceStart":1613277184334,"symbol":"BCHSV-USDT","changes":{"asks":[["242.896","1","1613277184334"]],"bids":[]},"sequenceEnd":1613277184334},"subject":"trade.l2update","topic":"/market/level2:BCHSV-USDT","type":"message"}
1619378332.717404: {"data":{"sequenceStart":1612701563964,"symbol":"DAPPT-BTC","changes":{"asks":[],"bids":[["0","0","1612701563964"]]},"sequenceEnd":1612701563964},"subject":"trade.l2update","topic":"/market/level2:DAPPT-BTC","type":"message"}
1619378332.717433: {"data":{"sequenceStart":1612701563965,"symbol":"DAPPT-BTC","changes":{"asks":[],"bids":[["0.0000001116","10224.8315","1612701563965"]]},"sequenceEnd":1612701563965},"subject":"trade.l2update","topic":"/market/level2:DAPPT-BTC","type":"message"}
1619378332.727106: {"data":{"sequenceStart":1612712745633,"symbol":"FET-BTC","changes":{"asks":[["0.00000794","0","1612712745633"]],"bids":[]},"sequenceEnd":1612712745633},"subject":"trade.l2update","topic":"/market/level2:FET-BTC","type":"message"}
1619378332.733899: {"data":{"sequenceStart":1612734157773,"symbol":"ANKR-BTC","changes":{"asks":[],"bids":[["0.0000025992","0","1612734157773"]]},"sequenceEnd":1612734157773},"subject":"trade.l2update","topic":"/market/level2:ANKR-BTC","type":"message"}
1619378332.738816: {"data":{"sequence":"1612734157772","bestAsk":"0.0000026187","size":"46","bestBidSize":"4051.2663","price":"0.0000026071","time":1619378332688,"bestAskSize":"4664.7644","bestBid":"0.0000026033"},"subject":"trade.ticker","topic":"/market/ticker:ANKR-BTC","type":"message"}
1619378332.7649121: {"data":{"sequenceStart":1612844051797,"symbol":"SNX-BTC","changes":{"asks":[["0.00028714","0","1612844051797"]],"bids":[]},"sequenceEnd":1612844051797},"subject":"trade.l2update","topic":"/market/level2:SNX-BTC","type":"message"}
1619378332.7703779: {"data":{"sequence":"1612701563965","bestAsk":"0.000000113","size":"145.4959","bestBidSize":"10224.8315","price":"0.0000001126","time":1619378332730,"bestAskSize":"1208.0878","bestBid":"0.0000001116"},"subject":"trade.ticker","topic":"/market/ticker:DAPPT-BTC","type":"message"}
1619378332.77047: {"data":{"sequence":"1613277184336","bestAsk":"242.896","size":"0.08000012","bestBidSize":"0.4008184","price":"243.65","time":1619378332731,"bestAskSize":"1","bestBid":"242.474"},"subject":"trade.ticker","topic":"/market/ticker:BCHSV-USDT","type":"message"}
1619378332.7769861: {"data":{"sequenceStart":1613277184335,"symbol":"BCHSV-USDT","changes":{"asks":[["0","0","1613277184335"]],"bids":[]},"sequenceEnd":1613277184335},"subject":"trade.l2update","topic":"/market/level2:BCHSV-USDT","type":"message"}
1619378332.7771: {"data":{"sequenceStart":1613277184336,"symbol":"BCHSV-USDT","changes":{"asks":[["243.007","0.20416582","1613277184336"]],"bids":[]},"sequenceEnd":1613277184336},"subject":"trade.l2update","topic":"/market/level2:BCHSV-USDT","type":"message"}
1619378332.7771819: {"data":{"sequenceStart":1612844051798,"symbol":"SNX-BTC","changes":{"asks":[],"bids":[["0","0","1612844051798"]]},"sequenceEnd":1612844051798},"subject":"trade.l2update","topic":"/market/level2:SNX-BTC","type":"message"}
1619378332.777226: {"data":{"sequenceStart":1612844051799,"symbol":"SNX-BTC","changes":{"asks":[],"bids":[["0.00028653","1.74527973","1612844051799"]]},"sequenceEnd":1612844051799},"subject":"trade.l2update","topic":"/market/level2:SNX-BTC","type":"message"}
1619378332.788954: {"data":{"sequenceStart":1612734157774,"symbol":"ANKR-BTC","changes":{"asks":[],"bids":[["0","0","1612734157774"]]},"sequenceEnd":1612734157774},"subject":"trade.l2update","topic":"/market/level2:ANKR-BTC","type":"message"}
1619378332.789035: {"data":{"sequenceStart":1612734157775,"symbol":"ANKR-BTC","changes":{"asks":[],"bids":[["0.0000025995","961.8677","1612734157775"]]},"sequenceEnd":1612734157775},"subject":"trade.l2update","topic":"/market/level2:ANKR-BTC","type":"message"}
1619378332.789091: {"data":{"sequenceStart":1612734157776,"symbol":"ANKR-BTC","changes":{"asks":[["0.0000026187","0","1612734157776"]],"bids":[]},"sequenceEnd":1612734157776},"subject":"trade.l2update","topic":"/market/level2:ANKR-BTC","type":"message"}
1619378332.7891352: {"data":{"sequence":"1612844051799","bestAsk":"0.00028711","size":"0.01745248","bestBidSize":"0.19100065","price":"0.00028676","time":1619378332747,"bestAskSize":"29.24570683","bestBid":"0.00028678"},"subject":"trade.ticker","topic":"/market/ticker:SNX-BTC","type":"message"}
1619378332.8005838: {"data":{"sequenceStart":1613277184337,"symbol":"BCHSV-USDT","changes":{"asks":[["243.007","0","1613277184337"]],"bids":[]},"sequenceEnd":1613277184337},"subject":"trade.l2update","topic":"/market/level2:BCHSV-USDT","type":"message"}
1619378332.800724: {"data":{"sequenceStart":1612844051800,"symbol":"SNX-BTC","changes":{"asks":[],"bids":[["0.00028576","0","1612844051800"]]},"sequenceEnd":1612844051800},"subject":"trade.l2update","topic":"/market/level2:SNX-BTC","type":"message"}
1619378332.800797: {"data":{"sequenceStart":1613277184338,"symbol":"BCHSV-USDT","changes":{"asks":[["242.896","0","1613277184338"]],"bids":[]},"sequenceEnd":1613277184338},"subject":"trade.l2update","topic":"/market/level2:BCHSV-USDT","type":"message"}
1619378332.80907: {"data":{"sequence":"1612712745633","bestAsk":"0.00000775","size":"401.2004","bestBidSize":"357.285","price":"0.00000772","time":1619378332767,"bestAskSize":"1154.0416","bestBid":"0.00000771"},"subject":"trade.ticker","topic":"/market/ticker:FET-BTC","type":"message"}
1619378332.814564: {"data":{"sequenceStart":1612844051801,"symbol":"SNX-BTC","changes":{"asks":[],"bids":[["0.00028653","0","1612844051801"]]},"sequenceEnd":1612844051801},"subject":"trade.l2update","topic":"/market/level2:SNX-BTC","type":"message"}
1619378332.814705: {"data":{"sequenceStart":1612844051802,"symbol":"SNX-BTC","changes":{"asks":[["0","0","1612844051802"]],"bids":[]},"sequenceEnd":1612844051802},"subject":"trade.l2update","topic":"/market/level2:SNX-BTC","type":"message"}
1619378332.814759: {"data":{"sequenceStart":1612844051803,"symbol":"SNX-BTC","changes":{"asks":[["0.0002871","14.04664884","1612844051803"]],"bids":[]},"sequenceEnd":1612844051803},"subject":"trade.l2update","topic":"/market/level2:SNX-BTC","type":"message"}
1619378332.819971: {"data":{"sequenceStart":1612734157777,"symbol":"ANKR-BTC","changes":{"asks":[],"bids":[["0.0000025995","0","1612734157777"]]},"sequenceEnd":1612734157777},"subject":"trade.l2update","topic":"/market/level2:ANKR-BTC","type":"message"}
1619378332.829854: {"data":{"sequenceStart":1613277184339,"symbol":"BCHSV-USDT","changes":{"asks":[],"bids":[["242.22","2.99","1613277184339"]]},"sequenceEnd":1613277184339},"subject":"trade.l2update","topic":"/market/level2:BCHSV-USDT","type":"message"}
1619378332.829974: {"data":{"sequenceStart":1613277184340,"symbol":"BCHSV-USDT","changes":{"asks":[],"bids":[["242.22","0","1613277184340"]]},"sequenceEnd":1613277184340},"subject":"trade.l2update","topic":"/market/level2:BCHSV-USDT","type":"message"}
1619378332.83538: {"data":{"sequence":"1612734157777","bestAsk":"0.0000026208","size":"46","bestBidSize":"4051.2663","price":"0.0000026071","time":1619378332788,"bestAskSize":"10987.6265","bestBid":"0.0000026033"},"subject":"trade.ticker","topic":"/market/ticker:ANKR-BTC","type":"message"}
1619378332.841245: {"data":{"sequenceStart":1613277184341,"symbol":"BCHSV-USDT","changes":{"asks":[],"bids":[["0","0","1613277184341"]]},"sequenceEnd":1613277184341},"subject":"trade.l2update","topic":"/market/level2:BCHSV-USDT","type":"message"}
1619378332.841355: {"data":{"sequenceStart":1612712745634,"symbol":"FET-BTC","changes":{"asks":[["0","0","1612712745634"]],"bids":[]},"sequenceEnd":1612712745634},"subject":"trade.l2update","topic":"/market/level2:FET-BTC","type":"message"}
1619378332.841407: {"data":{"sequenceStart":1613277184342,"symbol":"BCHSV-USDT","changes":{"asks":[],"bids":[["242.551","0.68148185","1613277184342"]]},"sequenceEnd":1613277184342},"subject":"trade.l2update","topic":"/market/level2:BCHSV-USDT","type":"message"}
1619378332.84149: {"data":{"sequenceStart":1613277184343,"symbol":"BCHSV-USDT","changes":{"asks":[["246.341","0","1613277184343"]],"bids":[]},"sequenceEnd":1613277184343},"subject":"trade.l2update","topic":"/market/level2:BCHSV-USDT","type":"message"}
1619378332.8415308: {"data":{"sequenceStart":1612712745635,"symbol":"FET-BTC","changes":{"asks":[["0.00000779","4011.0848","1612712745635"]],"bids":[]},"sequenceEnd":1612712745635},"subject":"trade.l2update","topic":"/market/level2:FET-BTC","type":"message"}
1619378332.841572: {"data":{"sequenceStart":1613277184344,"symbol":"BCHSV-USDT","changes":{"asks":[],"bids":[["241.423","0","1613277184344"]]},"sequenceEnd":1613277184344},"subject":"trade.l2update","topic":"/market/level2:BCHSV-USDT","type":"message"}
1619378332.841606: {"data":{"sequenceStart":1613277184345,"symbol":"BCHSV-USDT","changes":{"asks":[["244.22","0","1613277184345"]],"bids":[]},"sequenceEnd":1613277184345},"subject":"trade.l2update","topic":"/market/level2:BCHSV-USDT","type":"message"}
1619378332.8416378: {"data":{"sequenceStart":1613277184346,"symbol":"BCHSV-USDT","changes":{"asks":[["243.583","0","1613277184346"]],"bids":[]},"sequenceEnd":1613277184346},"subject":"trade.l2update","topic":"/market/level2:BCHSV-USDT","type":"message"}
1619378332.841669: {"data":{"sequenceStart":1612844051804,"symbol":"SNX-BTC","changes":{"asks":[["0.00028711","0","1612844051804"]],"bids":[]},"sequenceEnd":1612844051804},"subject":"trade.l2update","topic":"/market/level2:SNX-BTC","type":"message"}
1619378332.843682: {"data":{"sequenceStart":1612734157778,"symbol":"ANKR-BTC","changes":{"asks":[["0","0","1612734157778"]],"bids":[]},"sequenceEnd":1612734157778},"subject":"trade.l2update","topic":"/market/level2:ANKR-BTC","type":"message"}
1619378332.843758: {"data":{"sequenceStart":1612734157779,"symbol":"ANKR-BTC","changes":{"asks":[["0.0000026207","4147.8755","1612734157779"]],"bids":[]},"sequenceEnd":1612734157779},"subject":"trade.l2update","topic":"/market/level2:ANKR-BTC","type":"message"}
1619378332.849001: {"data":{"symbol":"DAPPT-BTC","candles":["1619378280","0.0000001117","0.0000001126","0.0000001126","0.0000001117","3799.1984","0.00042624222239"],"time":1619378332805085744},"subject":"trade.candles.update","topic":"/market/candles:DAPPT-BTC_1min","type":"message"}
1619378332.8556402: {"data":{"sequenceStart":1613277184347,"symbol":"BCHSV-USDT","changes":{"asks":[],"bids":[["0","0","1613277184347"]]},"sequenceEnd":1613277184347},"subject":"trade.l2update","topic":"/market/level2:BCHSV-USDT","type":"message"}
1619378332.8557491: {"data":{"sequenceStart":1613277184348,"symbol":"BCHSV-USDT","changes":{"asks":[],"bids":[["242.485","5","1613277184348"]]},"sequenceEnd":1613277184348},"subject":"trade.l2update","topic":"/market/level2:BCHSV-USDT","type":"message"}
1619378332.869535: {"data":{"sequenceStart":1612844051805,"symbol":"SNX-BTC","changes":{"asks":[["0","0","1612844051805"]],"bids":[]},"sequenceEnd":1612844051805},"subject":"trade.l2update","topic":"/market/level2:SNX-BTC","type":"message"}
1619378332.8696089: {"data":{"sequenceStart":1612844051806,"symbol":"SNX-BTC","changes":{"asks":[["0.0002871","43.29235567","1612844051806"]],"bids":[]},"sequenceEnd":1612844051806},"subject":"trade.l2update","topic":"/market/level2:SNX-BTC","type":"message"}
1619378332.877304: {"data":{"sequenceStart":1612734157780,"symbol":"ANKR-BTC","changes":{"asks":[],"bids":[["0","0","1612734157780"]]},"sequenceEnd":1612734157780},"subject":"trade.l2update","topic":"/market/level2:ANKR-BTC","type":"message"}
1619378332.877414: {"data":{"sequenceStart":1612734157781,"symbol":"ANKR-BTC","changes":{"asks":[],"bids":[["0.0000025954","2887.7583","1612734157781"]]},"sequenceEnd":1612734157781},"subject":"trade.l2update","topic":"/market/level2:ANKR-BTC","type":"message"}
1619378332.877493: {"data":{"sequenceStart":1612734157782,"symbol":"ANKR-BTC","changes":{"asks":[],"bids":[["0","0","1612734157782"]]},"sequenceEnd":1612734157782},"subject":"trade.l2update","topic":"/market/level2:ANKR-BTC","type":"message"}
1619378332.877536: {"data":{"sequenceStart":1612734157783,"symbol":"ANKR-BTC","changes":{"asks":[],"bids":[["0.0000025993","192.3883","1612734157783"]]},"sequenceEnd":1612734157783},"subject":"trade.l2update","topic":"/market/level2:ANKR-BTC","type":"message"}
1619378332.88431: {"data":{"sequence":"1613277184348","bestAsk":"242.9","size":"0.08000012","bestBidSize":"0.68148185","price":"243.65","time":1619378332834,"bestAskSize":"9.88630737","bestBid":"242.551"},"subject":"trade.ticker","topic":"/market/ticker:BCHSV-USDT","type":"message"}
1619378332.884373: {"data":{"sequence":"1612844051806","bestAsk":"0.0002871","size":"0.01745248","bestBidSize":"0.19100065","price":"0.00028676","time":1619378332848,"bestAskSize":"43.29235567","bestBid":"0.00028678"},"subject":"trade.ticker","topic":"/market/ticker:SNX-BTC","type":"message"}
1619378332.895052: {"data":{"sequenceStart":1613277184349,"symbol":"BCHSV-USDT","changes":{"asks":[],"bids":[["0","0","1613277184349"]]},"sequenceEnd":1613277184349},"subject":"trade.l2update","topic":"/market/level2:BCHSV-USDT","type":"message"}
1619378332.895149: {"data":{"sequenceStart":1613277184350,"symbol":"BCHSV-USDT","changes":{"asks":[],"bids":[["242.299","2.99","1613277184350"]]},"sequenceEnd":1613277184350},"subject":"trade.l2update","topic":"/market/level2:BCHSV-USDT","type":"message"}
1619378332.901675: {"data":{"sequenceStart":1613277184351,"symbol":"BCHSV-USDT","changes":{"asks":[],"bids":[["0","0","1613277184351"]]},"sequenceEnd":1613277184351},"subject":"trade.l2update","topic":"/market/level2:BCHSV-USDT","type":"message"}
1619378332.901786: {"data":{"sequenceStart":1613277184352,"symbol":"BCHSV-USDT","changes":{"asks":[],"bids":[["242.564","5","1613277184352"]]},"sequenceEnd":1613277184352},"subject":"trade.l2update","topic":"/market/level2:BCHSV-USDT","type":"message"}
1619378332.908103: {"data":{"sequenceStart":1612844051807,"symbol":"SNX-BTC","changes":{"asks":[],"bids":[["0","0","1612844051807"]]},"sequenceEnd":1612844051807},"subject":"trade.l2update","topic":"/market/level2:SNX-BTC","type":"message"}
1619378332.908216: {"data":{"sequenceStart":1612844051808,"symbol":"SNX-BTC","changes":{"asks":[],"bids":[["0.00028655","2.1097563","1612844051808"]]},"sequenceEnd":1612844051808},"subject":"trade.l2update","topic":"/market/level2:SNX-BTC","type":"message"}
1619378332.908295: {"data":{"sequenceStart":1612844051809,"symbol":"SNX-BTC","changes":{"asks":[],"bids":[["0","0","1612844051809"]]},"sequenceEnd":1612844051809},"subject":"trade.l2update","topic":"/market/level2:SNX-BTC","type":"message"}
1619378332.908339: {"data":{"sequenceStart":1612844051810,"symbol":"SNX-BTC","changes":{"asks":[],"bids":[["0.00028608","75.54307296","1612844051810"]]},"sequenceEnd":1612844051810},"subject":"trade.l2update","topic":"/market/level2:SNX-BTC","type":"message"}
1619378332.911714: {"data":{"sequenceStart":1612712745636,"symbol":"FET-BTC","changes":{"asks":[["0.00000779","0","1612712745636"]],"bids":[]},"sequenceEnd":1612712745636},"subject":"trade.l2update","topic":"/market/level2:FET-BTC","type":"message"}
1619378332.918368: {"data":{"sequenceStart":1613277184353,"symbol":"BCHSV-USDT","changes":{"asks":[],"bids":[["0","0","1613277184353"]]},"sequenceEnd":1613277184353},"subject":"trade.l2update","topic":"/market/level2:BCHSV-USDT","type":"message"}
1619378332.918483: {"data":{"sequenceStart":1613277184354,"symbol":"BCHSV-USDT","changes":{"asks":[],"bids":[["238.681","0.78","1613277184354"]]},"sequenceEnd":1613277184354},"subject":"trade.l2update","topic":"/market/level2:BCHSV-USDT","type":"message"}
1619378332.918559: {"data":{"sequenceStart":1613277184355,"symbol":"BCHSV-USDT","changes":{"asks":[],"bids":[["0","0","1613277184355"]]},"sequenceEnd":1613277184355},"subject":"trade.l2update","topic":"/market/level2:BCHSV-USDT","type":"message"}
1619378332.918599: {"data":{"sequenceStart":1613277184356,"symbol":"BCHSV-USDT","changes":{"asks":[],"bids":[["242.299","5.98","1613277184356"]]},"sequenceEnd":1613277184356},"subject":"trade.l2update","topic":"/market/level2:BCHSV-USDT","type":"message"}
1619378332.9186392: {"data":{"sequenceStart":1613277184357,"symbol":"BCHSV-USDT","changes":{"asks":[["0","0","1613277184357"]],"bids":[]},"sequenceEnd":1613277184357},"subject":"trade.l2update","topic":"/market/level2:BCHSV-USDT","type":"message"}
1619378332.9186718: {"data":{"sequenceStart":1613277184358,"symbol":"BCHSV-USDT","changes":{"asks":[["246.421","37.167","1613277184358"]],"bids":[]},"sequenceEnd":1613277184358},"subject":"trade.l2update","topic":"/market/level2:BCHSV-USDT","type":"message"}
1619378332.918719: {"data":{"sequenceStart":1613277184359,"symbol":"BCHSV-USDT","changes":{"asks":[["242.9","0","1613277184359"]],"bids":[]},"sequenceEnd":1613277184359},"subject":"trade.l2update","topic":"/market/level2:BCHSV-USDT","type":"message"}
1619378332.918797: {"data":{"sequenceStart":1612734157784,"symbol":"ANKR-BTC","changes":{"asks":[],"bids":[["0.0000025993","0","1612734157784"]]},"sequenceEnd":1612734157784},"subject":"trade.l2update","topic":"/market/level2:ANKR-BTC","type":"message"}
1619378332.9188511: {"data":{"sequence":"1612712745635","bestAsk":"0.00000775","size":"401.2004","bestBidSize":"357.285","price":"0.00000772","time":1619378332867,"bestAskSize":"1154.0416","bestBid":"0.00000771"},"subject":"trade.ticker","topic":"/market/ticker:FET-BTC","type":"message"}
1619378332.920681: {"data":{"sequenceStart":1612844051811,"symbol":"SNX-BTC","changes":{"asks":[],"bids":[["0","0","1612844051811"]]},"sequenceEnd":1612844051811},"subject":"trade.l2update","topic":"/market/level2:SNX-BTC","type":"message"}
1619378332.9207969: {"data":{"sequenceStart":1612844051812,"symbol":"SNX-BTC","changes":{"asks":[],"bids":[["0.00028578","257.12703361","1612844051812"]]},"sequenceEnd":1612844051812},"subject":"trade.l2update","topic":"/market/level2:SNX-BTC","type":"message"}
1619378332.926413: {"data":{"sequence":"1612734157784","bestAsk":"0.0000026207","size":"46","bestBidSize":"4051.2663","price":"0.0000026071","time":1619378332888,"bestAskSize":"4147.8755","bestBid":"0.0000026033"},"subject":"trade.ticker","topic":"/market/ticker:ANKR-BTC","type":"message"}
1619378332.9372082: {"data":{"sequenceStart":1613277184360,"symbol":"BCHSV-USDT","changes":{"asks":[["243.304","0","1613277184360"]],"bids":[]},"sequenceEnd":1613277184360},"subject":"trade.l2update","topic":"/market/level2:BCHSV-USDT","type":"message"}
1619378332.937351: {"data":{"sequenceStart":1612844051813,"symbol":"SNX-BTC","changes":{"asks":[],"bids":[["0.00028655","0","1612844051813"]]},"sequenceEnd":1612844051813},"subject":"trade.l2update","topic":"/market/level2:SNX-BTC","type":"message"}
1619378332.9374259: {"data":{"sequenceStart":1612844051814,"symbol":"SNX-BTC","changes":{"asks":[],"bids":[["0.00028608","73.43333533","1612844051814"]]},"sequenceEnd":1612844051814},"subject":"trade.l2update","topic":"/market/level2:SNX-BTC","type":"message"}
1619378332.9470232: {"data":{"sequenceStart":1612844051815,"symbol":"SNX-BTC","changes":{"asks":[["0","0","1612844051815"]],"bids":[]},"sequenceEnd":1612844051815},"subject":"trade.l2update","topic":"/market/level2:SNX-BTC","type":"message"}
1619378332.947137: {"data":{"sequenceStart":1612844051816,"symbol":"SNX-BTC","changes":{"asks":[["0.00028737","2.04440048","1612844051816"]],"bids":[]},"sequenceEnd":1612844051816},"subject":"trade.l2update","topic":"/market/level2:SNX-BTC","type":"message"}
1619378332.9472032: {"data":{"sequenceStart":1613277184361,"symbol":"BCHSV-USDT","changes":{"asks":[],"bids":[["0","0","1613277184361"]]},"sequenceEnd":1613277184361},"subject":"trade.l2update","topic":"/market/level2:BCHSV-USDT","type":"message"}
1619378332.947249: {"data":{"sequenceStart":1613277184362,"symbol":"BCHSV-USDT","changes":{"asks":[],"bids":[["238.669","0.51","1613277184362"]]},"sequenceEnd":1613277184362},"subject":"trade.l2update","topic":"/market/level2:BCHSV-USDT","type":"message"}
1619378332.9653602: {"data":{"sequenceStart":1613277184363,"symbol":"BCHSV-USDT","changes":{"asks":[],"bids":[["242.485","0","1613277184363"]]},"sequenceEnd":1613277184363},"subject":"trade.l2update","topic":"/market/level2:BCHSV-USDT","type":"message"}
1619378332.965502: {"data":{"sequenceStart":1613277184364,"symbol":"BCHSV-USDT","changes":{"asks":[],"bids":[["242.564","0","1613277184364"]]},"sequenceEnd":1613277184364},"subject":"trade.l2update","topic":"/market/level2:BCHSV-USDT","type":"message"}
1619378332.981521: {"data":{"sequence":"1613277184364","bestAsk":"242.901","size":"0.08000012","bestBidSize":"0.68148185","price":"243.65","time":1619378332933,"bestAskSize":"4.51280965","bestBid":"242.551"},"subject":"trade.ticker","topic":"/market/ticker:BCHSV-USDT","type":"message"}
1619378332.981632: {"data":{"sequenceStart":1613277184365,"symbol":"BCHSV-USDT","changes":{"asks":[],"bids":[["242.474","0","1613277184365"]]},"sequenceEnd":1613277184365},"subject":"trade.l2update","topic":"/market/level2:BCHSV-USDT","type":"message"}
1619378332.984375: {"data":{"sequenceStart":1612734157785,"symbol":"ANKR-BTC","changes":{"asks":[],"bids":[["0","0","1612734157785"]]},"sequenceEnd":1612734157785},"subject":"trade.l2update","topic":"/market/level2:ANKR-BTC","type":"message"}
1619378332.984482: {"data":{"sequenceStart":1612734157786,"symbol":"ANKR-BTC","changes":{"asks":[],"bids":[["0.0000025988","299.9988","1612734157786"]]},"sequenceEnd":1612734157786},"subject":"trade.l2update","topic":"/market/level2:ANKR-BTC","type":"message"}
1619378332.991442: {"data":{"sequenceStart":1612844051817,"symbol":"SNX-BTC","changes":{"asks":[],"bids":[["0","0","1612844051817"]]},"sequenceEnd":1612844051817},"subject":"trade.l2update","topic":"/market/level2:SNX-BTC","type":"message"}
1619378332.991552: {"data":{"sequenceStart":1612844051818,"symbol":"SNX-BTC","changes":{"asks":[],"bids":[["0.00028608","75.54307296","1612844051818"]]},"sequenceEnd":1612844051818},"subject":"trade.l2update","topic":"/market/level2:SNX-BTC","type":"message"}
1619378332.991617: {"data":{"sequenceStart":1612844051819,"symbol":"SNX-BTC","changes":{"asks":[],"bids":[["0","0","1612844051819"]]},"sequenceEnd":1612844051819},"subject":"trade.l2update","topic":"/market/level2:SNX-BTC","type":"message"}
1619378332.991668: {"data":{"sequenceStart":1619079123935,"symbol":"EQZ-BTC","changes":{"asks":[],"bids":[["0.00002328","0","1619079123935"]]},"sequenceEnd":1619079123935},"subject":"trade.l2update","topic":"/market/level2:EQZ-BTC","type":"message"}
1619378332.99173: {"data":{"sequenceStart":1612844051820,"symbol":"SNX-BTC","changes":{"asks":[],"bids":[["0.00028653","2.10972904","1612844051820"]]},"sequenceEnd":1612844051820},"subject":"trade.l2update","topic":"/market/level2:SNX-BTC","type":"message"}
1619378332.991766: {"data":{"sequence":"1612844051816","bestAsk":"0.0002871","size":"0.01745248","bestBidSize":"0.19100065","price":"0.00028676","time":1619378332950,"bestAskSize":"43.29235567","bestBid":"0.00028678"},"subject":"trade.ticker","topic":"/market/ticker:SNX-BTC","type":"message"}
1619378332.9917922: {"data":{"sequenceStart":1613277184366,"symbol":"BCHSV-USDT","changes":{"asks":[["243.547","0","1613277184366"]],"bids":[]},"sequenceEnd":1613277184366},"subject":"trade.l2update","topic":"/market/level2:BCHSV-USDT","type":"message"}
1619378332.994556: {"data":{"sequenceStart":1613277184367,"symbol":"BCHSV-USDT","changes":{"asks":[["0","0","1613277184367"]],"bids":[]},"sequenceEnd":1613277184367},"subject":"trade.l2update","topic":"/market/level2:BCHSV-USDT","type":"message"}
1619378332.994632: {"data":{"sequenceStart":1613277184368,"symbol":"BCHSV-USDT","changes":{"asks":[["243.404","5.52","1613277184368"]],"bids":[]},"sequenceEnd":1613277184368},"subject":"trade.l2update","topic":"/market/level2:BCHSV-USDT","type":"message"}
1619378333.006409: {"data":{"sequenceStart":1613277184369,"symbol":"BCHSV-USDT","changes":{"asks":[],"bids":[["242.551","0","1613277184369"]]},"sequenceEnd":1613277184369},"subject":"trade.l2update","topic":"/market/level2:BCHSV-USDT","type":"message"}
1619378333.0131671: {"data":{"sequence":"1612712745636","bestAsk":"0.00000775","size":"401.2004","bestBidSize":"357.285","price":"0.00000772","time":1619378332967,"bestAskSize":"1154.0416","bestBid":"0.00000771"},"subject":"trade.ticker","topic":"/market/ticker:FET-BTC","type":"message"}
1619378333.013258: {"data":{"sequenceStart":1612844051821,"symbol":"SNX-BTC","changes":{"asks":[["0.00028737","0.01376935","1612844051821"]],"bids":[]},"sequenceEnd":1612844051821},"subject":"trade.l2update","topic":"/market/level2:SNX-BTC","type":"message"}
1619378333.0235362: {"data":{"sequenceStart":1613277184370,"symbol":"BCHSV-USDT","changes":{"asks":[["0","0","1613277184370"]],"bids":[]},"sequenceEnd":1613277184370},"subject":"trade.l2update","topic":"/market/level2:BCHSV-USDT","type":"message"}
1619378333.0236: {"data":{"sequenceStart":1613277184371,"symbol":"BCHSV-USDT","changes":{"asks":[["243.236","0.6","1613277184371"]],"bids":[]},"sequenceEnd":1613277184371},"subject":"trade.l2update","topic":"/market/level2:BCHSV-USDT","type":"message"}
1619378333.0266721: {"data":{"sequenceStart":1612844051822,"symbol":"SNX-BTC","changes":{"asks":[],"bids":[["0.00028608","73.43333533","1612844051822"]]},"sequenceEnd":1612844051822},"subject":"trade.l2update","topic":"/market/level2:SNX-BTC","type":"message"}
1619378333.0336971: {"data":{"sequence":"1612734157786","bestAsk":"0.0000026207","size":"46","bestBidSize":"4051.2663","price":"0.0000026071","time":1619378332988,"bestAskSize":"4147.8755","bestBid":"0.0000026033"},"subject":"trade.ticker","topic":"/market/ticker:ANKR-BTC","type":"message"}
1619378333.034291: {"data":{"sequenceStart":1612844051823,"symbol":"SNX-BTC","changes":{"asks":[],"bids":[["0.00028653","0","1612844051823"]]},"sequenceEnd":1612844051823},"subject":"trade.l2update","topic":"/market/level2:SNX-BTC","type":"message"}
1619378333.0410628: {"data":{"sequenceStart":1613277184372,"symbol":"BCHSV-USDT","changes":{"asks":[["0","0","1613277184372"]],"bids":[]},"sequenceEnd":1613277184372},"subject":"trade.l2update","topic":"/market/level2:BCHSV-USDT","type":"message"}
1619378333.0411782: {"data":{"sequenceStart":1613277184373,"symbol":"BCHSV-USDT","changes":{"asks":[["243.546","9.95738911","1613277184373"]],"bids":[]},"sequenceEnd":1613277184373},"subject":"trade.l2update","topic":"/market/level2:BCHSV-USDT","type":"message"}
1619378333.051282: {"data":{"sequenceStart":1613277184374,"symbol":"BCHSV-USDT","changes":{"asks":[],"bids":[["0","0","1613277184374"]]},"sequenceEnd":1613277184374},"subject":"trade.l2update","topic":"/market/level2:BCHSV-USDT","type":"message"}
1619378333.051394: {"data":{"sequenceStart":1613277184375,"symbol":"BCHSV-USDT","changes":{"asks":[],"bids":[["242.575","0.68148185","1613277184375"]]},"sequenceEnd":1613277184375},"subject":"trade.l2update","topic":"/market/level2:BCHSV-USDT","type":"message"}
1619378333.0630012: {"data":{"sequenceStart":1612712745637,"symbol":"FET-BTC","changes":{"asks":[["0","0","1612712745637"]],"bids":[]},"sequenceEnd":1612712745637},"subject":"trade.l2update","topic":"/market/level2:FET-BTC","type":"message"}
1619378333.0631151: {"data":{"sequenceStart":1612712745638,"symbol":"FET-BTC","changes":{"asks":[["0.00000779","1630.4488","1612712745638"]],"bids":[]},"sequenceEnd":1612712745638},"subject":"trade.l2update","topic":"/market/level2:FET-BTC","type":"message"}
1619378333.0632021: {"data":{"sequenceStart":1613277184376,"symbol":"BCHSV-USDT","changes":{"asks":[["0","0","1613277184376"]],"bids":[]},"sequenceEnd":1613277184376},"subject":"trade.l2update","topic":"/market/level2:BCHSV-USDT","type":"message"}
1619378333.0632489: {"data":{"sequenceStart":1613277184377,"symbol":"BCHSV-USDT","changes":{"asks":[["243.697","20.43","1613277184377"]],"bids":[]},"sequenceEnd":1613277184377},"subject":"trade.l2update","topic":"/market/level2:BCHSV-USDT","type":"message"}
1619378333.0633512: {"data":{"sequenceStart":1613277184378,"symbol":"BCHSV-USDT","changes":{"asks":[],"bids":[["242.299","2.99","1613277184378"]]},"sequenceEnd":1613277184378},"subject":"trade.l2update","topic":"/market/level2:BCHSV-USDT","type":"message"}
1619378333.0718122: {"data":{"sequence":"1613277184378","bestAsk":"242.901","size":"0.08000012","bestBidSize":"0.68148185","price":"243.65","time":1619378333033,"bestAskSize":"4.51280965","bestBid":"242.575"},"subject":"trade.ticker","topic":"/market/ticker:BCHSV-USDT","type":"message"}
1619378333.075979: {"data":{"sequenceStart":1612844051824,"symbol":"SNX-BTC","changes":{"asks":[["0","0","1612844051824"]],"bids":[]},"sequenceEnd":1612844051824},"subject":"trade.l2update","topic":"/market/level2:SNX-BTC","type":"message"}
1619378333.076056: {"data":{"sequenceStart":1612844051825,"symbol":"SNX-BTC","changes":{"asks":[["0.00028737","10.01376568","1612844051825"]],"bids":[]},"sequenceEnd":1612844051825},"subject":"trade.l2update","topic":"/market/level2:SNX-BTC","type":"message"}
1619378333.076098: {"data":{"sequenceStart":1612844051826,"symbol":"SNX-BTC","changes":{"asks":[["0","0","1612844051826"]],"bids":[]},"sequenceEnd":1612844051826},"subject":"trade.l2update","topic":"/market/level2:SNX-BTC","type":"message"}
1619378333.076124: {"data":{"sequenceStart":1612844051827,"symbol":"SNX-BTC","changes":{"asks":[["0.00029398","765.40500797","1612844051827"]],"bids":[]},"sequenceEnd":1612844051827},"subject":"trade.l2update","topic":"/market/level2:SNX-BTC","type":"message"}
1619378333.0821052: {"data":{"sequence":"1619079123935","bestAsk":"0.00002395","size":"0.375","bestBidSize":"20.5373","price":"0.00002383","time":1619378333038,"bestAskSize":"72.1515","bestBid":"0.00002383"},"subject":"trade.ticker","topic":"/market/ticker:EQZ-BTC","type":"message"}
1619378333.0858681: {"data":{"sequence":"1612844051828","bestAsk":"0.0002871","size":"0.01745248","bestBidSize":"0.19100065","price":"0.00028676","time":1619378333047,"bestAskSize":"43.29235567","bestBid":"0.00028678"},"subject":"trade.ticker","topic":"/market/ticker:SNX-BTC","type":"message"}
1619378333.08596: {"data":{"sequenceStart":1612844051828,"symbol":"SNX-BTC","changes":{"asks":[],"bids":[["0.00028578","0","1612844051828"]]},"sequenceEnd":1612844051828},"subject":"trade.l2update","topic":"/market/level2:SNX-BTC","type":"message"}
1619378333.086076: {"data":{"sequenceStart":1619079123936,"symbol":"EQZ-BTC","changes":{"asks":[],"bids":[["0","0","1619079123936"]]},"sequenceEnd":1619079123936},"subject":"trade.l2update","topic":"/market/level2:EQZ-BTC","type":"message"}
1619378333.0944939: {"data":{"sequenceStart":1612701563966,"symbol":"DAPPT-BTC","changes":{"asks":[],"bids":[["0","0","1612701563966"]]},"sequenceEnd":1612701563966},"subject":"trade.l2update","topic":"/market/level2:DAPPT-BTC","type":"message"}
1619378333.094604: {"data":{"sequenceStart":1613277184379,"symbol":"BCHSV-USDT","changes":{"asks":[],"bids":[["242.299","0","1613277184379"]]},"sequenceEnd":1613277184379},"subject":"trade.l2update","topic":"/market/level2:BCHSV-USDT","type":"message"}
1619378333.102551: {"data":{"sequenceStart":1613277184380,"symbol":"BCHSV-USDT","changes":{"asks":[],"bids":[["0","0","1613277184380"]]},"sequenceEnd":1613277184380},"subject":"trade.l2update","topic":"/market/level2:BCHSV-USDT","type":"message"}
1619378333.1026618: {"data":{"sequenceStart":1613277184381,"symbol":"BCHSV-USDT","changes":{"asks":[],"bids":[["242.499","1.94145932","1613277184381"]]},"sequenceEnd":1613277184381},"subject":"trade.l2update","topic":"/market/level2:BCHSV-USDT","type":"message"}
1619378333.1109362: {"data":{"sequence":"1612712745638","bestAsk":"0.00000775","size":"401.2004","bestBidSize":"357.285","price":"0.00000772","time":1619378333067,"bestAskSize":"1154.0416","bestBid":"0.00000771"},"subject":"trade.ticker","topic":"/market/ticker:FET-BTC","type":"message"}
1619378333.1165051: {"data":{"sequenceStart":1612734157787,"symbol":"ANKR-BTC","changes":{"asks":[],"bids":[["0.0000025988","0","1612734157787"]]},"sequenceEnd":1612734157787},"subject":"trade.l2update","topic":"/market/level2:ANKR-BTC","type":"message"}
1619378333.1264288: {"data":{"sequenceStart":1612701563967,"symbol":"DAPPT-BTC","changes":{"asks":[],"bids":[["0","0","1612701563967"]]},"sequenceEnd":1612701563967},"subject":"trade.l2update","topic":"/market/level2:DAPPT-BTC","type":"message"}
1619378333.126508: {"data":{"sequenceStart":1612701563968,"symbol":"DAPPT-BTC","changes":{"asks":[],"bids":[["0.0000001119","361.2609","1612701563968"]]},"sequenceEnd":1612701563968},"subject":"trade.l2update","topic":"/market/level2:DAPPT-BTC","type":"message"}
1619378333.126558: {"data":{"sequence":"1612734157787","bestAsk":"0.0000026207","size":"46","bestBidSize":"4051.2663","price":"0.0000026071","time":1619378333088,"bestAskSize":"4147.8755","bestBid":"0.0000026033"},"subject":"trade.ticker","topic":"/market/ticker:ANKR-BTC","type":"message"}
1619378333.1520069: {"data":{"sequenceStart":1613277184382,"symbol":"BCHSV-USDT","changes":{"asks":[],"bids":[["0","0","1613277184382"]]},"sequenceEnd":1613277184382},"subject":"trade.l2update","topic":"/market/level2:BCHSV-USDT","type":"message"}
1619378333.15212: {"data":{"sequenceStart":1613277184383,"symbol":"BCHSV-USDT","changes":{"asks":[],"bids":[["242.565","0.10226994","1613277184383"]]},"sequenceEnd":1613277184383},"subject":"trade.l2update","topic":"/market/level2:BCHSV-USDT","type":"message"}
1619378333.1522: {"data":{"sequenceStart":1613277184384,"symbol":"BCHSV-USDT","changes":{"asks":[],"bids":[["0","0","1613277184384"]]},"sequenceEnd":1613277184384},"subject":"trade.l2update","topic":"/market/level2:BCHSV-USDT","type":"message"}
1619378333.152243: {"data":{"sequenceStart":1613277184385,"symbol":"BCHSV-USDT","changes":{"asks":[],"bids":[["242.348","2.99","1613277184385"]]},"sequenceEnd":1613277184385},"subject":"trade.l2update","topic":"/market/level2:BCHSV-USDT","type":"message"}
1619378333.1703758: {"data":{"sequenceStart":1613277184386,"symbol":"BCHSV-USDT","changes":{"asks":[],"bids":[["0","0","1613277184386"]]},"sequenceEnd":1613277184386},"subject":"trade.l2update","topic":"/market/level2:BCHSV-USDT","type":"message"}
1619378333.177356: {"data":{"sequence":"1612701563968","bestAsk":"0.000000113","size":"145.4959","bestBidSize":"361.2609","price":"0.0000001126","time":1619378333130,"bestAskSize":"1208.0878","bestBid":"0.0000001119"},"subject":"trade.ticker","topic":"/market/ticker:DAPPT-BTC","type":"message"}
1619378333.1821399: {"data":{"sequenceStart":1613277184387,"symbol":"BCHSV-USDT","changes":{"asks":[],"bids":[["242.348","5.98","1613277184387"]]},"sequenceEnd":1613277184387},"subject":"trade.l2update","topic":"/market/level2:BCHSV-USDT","type":"message"}
1619378333.182265: {"data":{"sequenceStart":1612844051829,"symbol":"SNX-BTC","changes":{"asks":[],"bids":[["0","0","1612844051829"]]},"sequenceEnd":1612844051829},"subject":"trade.l2update","topic":"/market/level2:SNX-BTC","type":"message"}
1619378333.182316: {"data":{"sequenceStart":1612844051830,"symbol":"SNX-BTC","changes":{"asks":[],"bids":[["0.00028648","2.10974814","1612844051830"]]},"sequenceEnd":1612844051830},"subject":"trade.l2update","topic":"/market/level2:SNX-BTC","type":"message"}
1619378333.19366: {"data":{"sequenceStart":1613277184388,"symbol":"BCHSV-USDT","changes":{"asks":[["243.546","0","1613277184388"]],"bids":[]},"sequenceEnd":1613277184388},"subject":"trade.l2update","topic":"/market/level2:BCHSV-USDT","type":"message"}
1619378333.1938: {"data":{"sequenceStart":1613277184389,"symbol":"BCHSV-USDT","changes":{"asks":[],"bids":[["242.565","0","1613277184389"]]},"sequenceEnd":1613277184389},"subject":"trade.l2update","topic":"/market/level2:BCHSV-USDT","type":"message"}
1619378333.19387: {"data":{"sequenceStart":1619079123937,"symbol":"EQZ-BTC","changes":{"asks":[],"bids":[["0","0","1619079123937"]]},"sequenceEnd":1619079123937},"subject":"trade.l2update","topic":"/market/level2:EQZ-BTC","type":"message"}
1619378333.1939142: {"data":{"sequenceStart":1619079123938,"symbol":"EQZ-BTC","changes":{"asks":[],"bids":[["0","0","1619079123938"]]},"sequenceEnd":1619079123938},"subject":"trade.l2update","topic":"/market/level2:EQZ-BTC","type":"message"}
1619378333.193949: {"data":{"sequence":"1613277184389","bestAsk":"242.901","size":"0.08000012","bestBidSize":"0.68148185","price":"243.65","time":1619378333131,"bestAskSize":"4.51280965","bestBid":"242.575"},"subject":"trade.ticker","topic":"/market/ticker:BCHSV-USDT","type":"message"}
1619378333.193986: {"data":{"sequence":"1619079123936","bestAsk":"0.00002395","size":"0.375","bestBidSize":"20.5373","price":"0.00002383","time":1619378333138,"bestAskSize":"72.1515","bestBid":"0.00002383"},"subject":"trade.ticker","topic":"/market/ticker:EQZ-BTC","type":"message"}
1619378333.1980731: {"data":{"sequence":"1612844051832","bestAsk":"0.0002871","size":"0.01745248","bestBidSize":"0.19100065","price":"0.00028676","time":1619378333155,"bestAskSize":"29.24570683","bestBid":"0.00028678"},"subject":"trade.ticker","topic":"/market/ticker:SNX-BTC","type":"message"}
1619378333.206622: {"data":{"sequenceStart":1612844051831,"symbol":"SNX-BTC","changes":{"asks":[["0.0002871","29.24570683","1612844051831"]],"bids":[]},"sequenceEnd":1612844051831},"subject":"trade.l2update","topic":"/market/level2:SNX-BTC","type":"message"}
1619378333.206753: {"data":{"sequenceStart":1612844051832,"symbol":"SNX-BTC","changes":{"asks":[],"bids":[["0.00028648","0","1612844051832"]]},"sequenceEnd":1612844051832},"subject":"trade.l2update","topic":"/market/level2:SNX-BTC","type":"message"}
1619378333.21282: {"data":{"sequenceStart":1613277184390,"symbol":"BCHSV-USDT","changes":{"asks":[["243.236","0","1613277184390"]],"bids":[]},"sequenceEnd":1613277184390},"subject":"trade.l2update","topic":"/market/level2:BCHSV-USDT","type":"message"}
1619378333.2129579: {"data":{"sequenceStart":1612734157788,"symbol":"ANKR-BTC","changes":{"asks":[],"bids":[["0","0","1612734157788"]]},"sequenceEnd":1612734157788},"subject":"trade.l2update","topic":"/market/level2:ANKR-BTC","type":"message"}
1619378333.213012: {"data":{"sequenceStart":1612734157789,"symbol":"ANKR-BTC","changes":{"asks":[],"bids":[["0.0000025986","299.9988","1612734157789"]]},"sequenceEnd":1612734157789},"subject":"trade.l2update","topic":"/market/level2:ANKR-BTC","type":"message"}
1619378333.2213938: {"data":{"sequenceStart":1613277184391,"symbol":"BCHSV-USDT","changes":{"asks":[],"bids":[["242.575","0","1613277184391"]]},"sequenceEnd":1613277184391},"subject":"trade.l2update","topic":"/market/level2:BCHSV-USDT","type":"message"}
1619378333.2370691: {"data":{"sequence":"1612734157789","bestAsk":"0.0000026207","size":"46","bestBidSize":"4051.2663","price":"0.0000026071","time":1619378333188,"bestAskSize":"4147.8755","bestBid":"0.0000026033"},"subject":"trade.ticker","topic":"/market/ticker:ANKR-BTC","type":"message"}
1619378333.237161: {"data":{"sequenceStart":1613277184392,"symbol":"BCHSV-USDT","changes":{"asks":[["0","0","1613277184392"]],"bids":[]},"sequenceEnd":1613277184392},"subject":"trade.l2update","topic":"/market/level2:BCHSV-USDT","type":"message"}
1619378333.237229: {"data":{"sequenceStart":1613277184393,"symbol":"BCHSV-USDT","changes":{"asks":[["243.267","0.6","1613277184393"]],"bids":[]},"sequenceEnd":1613277184393},"subject":"trade.l2update","topic":"/market/level2:BCHSV-USDT","type":"message"}
1619378333.2373: {"data":{"sequenceStart":1612701563969,"symbol":"DAPPT-BTC","changes":{"asks":[],"bids":[["0","0","1612701563969"]]},"sequenceEnd":1612701563969},"subject":"trade.l2update","topic":"/market/level2:DAPPT-BTC","type":"message"}
1619378333.237341: {"data":{"sequenceStart":1612701563970,"symbol":"DAPPT-BTC","changes":{"asks":[],"bids":[["0","0","1612701563970"]]},"sequenceEnd":1612701563970},"subject":"trade.l2update","topic":"/market/level2:DAPPT-BTC","type":"message"}
1619378333.2373838: {"data":{"sequenceStart":1613277184394,"symbol":"BCHSV-USDT","changes":{"asks":[["0","0","1613277184394"]],"bids":[]},"sequenceEnd":1613277184394},"subject":"trade.l2update","topic":"/market/level2:BCHSV-USDT","type":"message"}
1619378333.237421: {"data":{"sequenceStart":1613277184395,"symbol":"BCHSV-USDT","changes":{"asks":[["243.073","0.96","1613277184395"]],"bids":[]},"sequenceEnd":1613277184395},"subject":"trade.l2update","topic":"/market/level2:BCHSV-USDT","type":"message"}
1619378333.237451: {"data":{"sequenceStart":1613277184396,"symbol":"BCHSV-USDT","changes":{"asks":[],"bids":[["0","0","1613277184396"]]},"sequenceEnd":1613277184396},"subject":"trade.l2update","topic":"/market/level2:BCHSV-USDT","type":"message"}
1619378333.2374709: {"data":{"sequenceStart":1613277184397,"symbol":"BCHSV-USDT","changes":{"asks":[],"bids":[["242.578","0.68148185","1613277184397"]]},"sequenceEnd":1613277184397},"subject":"trade.l2update","topic":"/market/level2:BCHSV-USDT","type":"message"}
1619378333.2496672: {"data":{"sequenceStart":1612844051833,"symbol":"SNX-BTC","changes":{"asks":[["0.00028737","0.01376935","1612844051833"]],"bids":[]},"sequenceEnd":1612844051833},"subject":"trade.l2update","topic":"/market/level2:SNX-BTC","type":"message"}
1619378333.256135: {"data":{"sequenceStart":1612701563971,"symbol":"DAPPT-BTC","changes":{"asks":[],"bids":[["0","0","1612701563971"]]},"sequenceEnd":1612701563971},"subject":"trade.l2update","topic":"/market/level2:DAPPT-BTC","type":"message"}
1619378333.2665431: {"data":{"sequence":"1612701563971","bestAsk":"0.000000113","size":"145.4959","bestBidSize":"361.2609","price":"0.0000001126","time":1619378333230,"bestAskSize":"1208.0878","bestBid":"0.0000001119"},"subject":"trade.ticker","topic":"/market/ticker:DAPPT-BTC","type":"message"}
1619378333.266633: {"data":{"sequenceStart":1613277184398,"symbol":"BCHSV-USDT","changes":{"asks":[["244.063","0","1613277184398"]],"bids":[]},"sequenceEnd":1613277184398},"subject":"trade.l2update","topic":"/market/level2:BCHSV-USDT","type":"message"}
1619378333.270014: {"data":{"sequenceStart":1613277184399,"symbol":"BCHSV-USDT","changes":{"asks":[["245.834","0","1613277184399"]],"bids":[]},"sequenceEnd":1613277184399},"subject":"trade.l2update","topic":"/market/level2:BCHSV-USDT","type":"message"}
1619378333.270171: {"data":{"sequenceStart":1613277184400,"symbol":"BCHSV-USDT","changes":{"asks":[["248.687","0","1613277184400"]],"bids":[]},"sequenceEnd":1613277184400},"subject":"trade.l2update","topic":"/market/level2:BCHSV-USDT","type":"message"}
1619378333.270247: {"data":{"sequenceStart":1613277184401,"symbol":"BCHSV-USDT","changes":{"asks":[],"bids":[["241.231","0","1613277184401"]]},"sequenceEnd":1613277184401},"subject":"trade.l2update","topic":"/market/level2:BCHSV-USDT","type":"message"}
1619378333.27031: {"data":{"sequenceStart":1613277184402,"symbol":"BCHSV-USDT","changes":{"asks":[["251.537","0","1613277184402"]],"bids":[]},"sequenceEnd":1613277184402},"subject":"trade.l2update","topic":"/market/level2:BCHSV-USDT","type":"message"}
1619378333.270365: {"data":{"sequenceStart":1613277184403,"symbol":"BCHSV-USDT","changes":{"asks":[],"bids":[["242.499","0","1613277184403"]]},"sequenceEnd":1613277184403},"subject":"trade.l2update","topic":"/market/level2:BCHSV-USDT","type":"message"}
1619378333.2704132: {"data":{"sequence":"1613277184403","bestAsk":"242.901","size":"0.08000012","bestBidSize":"0.68148185","price":"243.65","time":1619378333233,"bestAskSize":"4.51280965","bestBid":"242.578"},"subject":"trade.ticker","topic":"/market/ticker:BCHSV-USDT","type":"message"}
1619378333.276257: {"data":{"sequence":"1619079123938","bestAsk":"0.00002395","size":"0.375","bestBidSize":"20.5373","price":"0.00002383","time":1619378333238,"bestAskSize":"72.1515","bestBid":"0.00002383"},"subject":"trade.ticker","topic":"/market/ticker:EQZ-BTC","type":"message"}
1619378333.2828841: {"data":{"sequenceStart":1613277184404,"symbol":"BCHSV-USDT","changes":{"asks":[],"bids":[["0","0","1613277184404"]]},"sequenceEnd":1613277184404},"subject":"trade.l2update","topic":"/market/level2:BCHSV-USDT","type":"message"}
1619378333.282996: {"data":{"sequenceStart":1613277184405,"symbol":"BCHSV-USDT","changes":{"asks":[],"bids":[["242.58","5","1613277184405"]]},"sequenceEnd":1613277184405},"subject":"trade.l2update","topic":"/market/level2:BCHSV-USDT","type":"message"}
1619378333.283099: {"data":{"sequenceStart":1612844051834,"symbol":"SNX-BTC","changes":{"asks":[["0","0","1612844051834"]],"bids":[]},"sequenceEnd":1612844051834},"subject":"trade.l2update","topic":"/market/level2:SNX-BTC","type":"message"}
1619378333.2831302: {"data":{"sequenceStart":1612844051835,"symbol":"SNX-BTC","changes":{"asks":[["0.00028709","14.05008598","1612844051835"]],"bids":[]},"sequenceEnd":1612844051835},"subject":"trade.l2update","topic":"/market/level2:SNX-BTC","type":"message"}
1619378333.283168: {"data":{"sequenceStart":1612844051836,"symbol":"SNX-BTC","changes":{"asks":[],"bids":[["0","0","1612844051836"]]},"sequenceEnd":1612844051836},"subject":"trade.l2update","topic":"/market/level2:SNX-BTC","type":"message"}
1619378333.283199: {"data":{"sequenceStart":1612844051837,"symbol":"SNX-BTC","changes":{"asks":[],"bids":[["0.00028647","2.10975196","1612844051837"]]},"sequenceEnd":1612844051837},"subject":"trade.l2update","topic":"/market/level2:SNX-BTC","type":"message"}
1619378333.2832289: {"data":{"sequence":"1612844051837","bestAsk":"0.00028709","size":"0.01745248","bestBidSize":"0.19100065","price":"0.00028676","time":1619378333246,"bestAskSize":"14.05008598","bestBid":"0.00028678"},"subject":"trade.ticker","topic":"/market/ticker:SNX-BTC","type":"message"}
1619378333.284877: {"data":{"sequenceStart":1612734157790,"symbol":"ANKR-BTC","changes":{"asks":[],"bids":[["0.0000026033","0","1612734157790"]]},"sequenceEnd":1612734157790},"subject":"trade.l2update","topic":"/market/level2:ANKR-BTC","type":"message"}
1619378333.292286: {"data":{"sequenceStart":1613277184406,"symbol":"BCHSV-USDT","changes":{"asks":[],"bids":[["241.976","0","1613277184406"]]},"sequenceEnd":1613277184406},"subject":"trade.l2update","topic":"/market/level2:BCHSV-USDT","type":"message"}
1619378333.2977018: {"data":{"sequenceStart":1613277184407,"symbol":"BCHSV-USDT","changes":{"asks":[],"bids":[["242.578","0","1613277184407"]]},"sequenceEnd":1613277184407},"subject":"trade.l2update","topic":"/market/level2:BCHSV-USDT","type":"message"}
1619378333.310554: {"data":{"sequenceStart":1613277184408,"symbol":"BCHSV-USDT","changes":{"asks":[],"bids":[["0","0","1613277184408"]]},"sequenceEnd":1613277184408},"subject":"trade.l2update","topic":"/market/level2:BCHSV-USDT","type":"message"}
1619378333.310663: {"data":{"sequenceStart":1613277184409,"symbol":"BCHSV-USDT","changes":{"asks":[],"bids":[["242.5","0.4008184","1613277184409"]]},"sequenceEnd":1613277184409},"subject":"trade.l2update","topic":"/market/level2:BCHSV-USDT","type":"message"}
1619378333.310742: {"data":{"sequenceStart":1612844051838,"symbol":"SNX-BTC","changes":{"asks":[],"bids":[["0.00028647","0","1612844051838"]]},"sequenceEnd":1612844051838},"subject":"trade.l2update","topic":"/market/level2:SNX-BTC","type":"message"}
1619378333.3222442: {"data":{"sequenceStart":1613277184410,"symbol":"BCHSV-USDT","changes":{"asks":[],"bids":[["0","0","1613277184410"]]},"sequenceEnd":1613277184410},"subject":"trade.l2update","topic":"/market/level2:BCHSV-USDT","type":"message"}
1619378333.3222988: {"data":{"sequenceStart":1613277184411,"symbol":"BCHSV-USDT","changes":{"asks":[],"bids":[["242.579","0.68148185","1613277184411"]]},"sequenceEnd":1613277184411},"subject":"trade.l2update","topic":"/market/level2:BCHSV-USDT","type":"message"}
1619378333.326541: {"data":{"sequenceStart":1612734157791,"symbol":"ANKR-BTC","changes":{"asks":[],"bids":[["0","0","1612734157791"]]},"sequenceEnd":1612734157791},"subject":"trade.l2update","topic":"/market/level2:ANKR-BTC","type":"message"}
1619378333.326585: {"data":{"sequenceStart":1612734157792,"symbol":"ANKR-BTC","changes":{"asks":[],"bids":[["0.0000025987","5436.0663","1612734157792"]]},"sequenceEnd":1612734157792},"subject":"trade.l2update","topic":"/market/level2:ANKR-BTC","type":"message"}
1619378333.333123: {"data":{"sequence":"1612734157792","bestAsk":"0.0000026207","size":"46","bestBidSize":"5436.0663","price":"0.0000026071","time":1619378333288,"bestAskSize":"4147.8755","bestBid":"0.0000025987"},"subject":"trade.ticker","topic":"/market/ticker:ANKR-BTC","type":"message"}
1619378333.3558762: {"data":{"sequenceStart":1612844051839,"symbol":"SNX-BTC","changes":{"asks":[],"bids":[["0","0","1612844051839"]]},"sequenceEnd":1612844051839},"subject":"trade.l2update","topic":"/market/level2:SNX-BTC","type":"message"}
1619378333.355989: {"data":{"sequenceStart":1612844051840,"symbol":"SNX-BTC","changes":{"asks":[],"bids":[["0.00028281","116.74680358","1612844051840"]]},"sequenceEnd":1612844051840},"subject":"trade.l2update","topic":"/market/level2:SNX-BTC","type":"message"}
1619378333.3560681: {"data":{"sequenceStart":1612734157793,"symbol":"ANKR-BTC","changes":{"asks":[],"bids":[["0.0000025986","0","1612734157793"]]},"sequenceEnd":1612734157793},"subject":"trade.l2update","topic":"/market/level2:ANKR-BTC","type":"message"}
1619378333.372715: {"data":{"sequence":"1613277184411","bestAsk":"242.901","size":"0.08000012","bestBidSize":"5","price":"243.65","time":1619378333333,"bestAskSize":"4.51280965","bestBid":"242.58"},"subject":"trade.ticker","topic":"/market/ticker:BCHSV-USDT","type":"message"}
1619378333.379306: {"data":{"sequenceStart":1612844051841,"symbol":"SNX-BTC","changes":{"asks":[["0.0002871","0","1612844051841"]],"bids":[]},"sequenceEnd":1612844051841},"subject":"trade.l2update","topic":"/market/level2:SNX-BTC","type":"message"}
1619378333.383165: {"data":{"sequenceStart":1613277184412,"symbol":"BCHSV-USDT","changes":{"asks":[["0","0","1613277184412"]],"bids":[]},"sequenceEnd":1613277184412},"subject":"trade.l2update","topic":"/market/level2:BCHSV-USDT","type":"message"}
1619378333.383273: {"data":{"sequenceStart":1613277184413,"symbol":"BCHSV-USDT","changes":{"asks":[["245.905","25","1613277184413"]],"bids":[]},"sequenceEnd":1613277184413},"subject":"trade.l2update","topic":"/market/level2:BCHSV-USDT","type":"message"}
1619378333.38337: {"data":{"sequenceStart":1613277184414,"symbol":"BCHSV-USDT","changes":{"asks":[["0","0","1613277184414"]],"bids":[]},"sequenceEnd":1613277184414},"subject":"trade.l2update","topic":"/market/level2:BCHSV-USDT","type":"message"}
1619378333.3834: {"data":{"sequenceStart":1613277184415,"symbol":"BCHSV-USDT","changes":{"asks":[["244.133","5","1613277184415"]],"bids":[]},"sequenceEnd":1613277184415},"subject":"trade.l2update","topic":"/market/level2:BCHSV-USDT","type":"message"}
1619378333.383446: {"data":{"sequenceStart":1613277184416,"symbol":"BCHSV-USDT","changes":{"asks":[["0","0","1613277184416"]],"bids":[]},"sequenceEnd":1613277184416},"subject":"trade.l2update","topic":"/market/level2:BCHSV-USDT","type":"message"}
1619378333.38347: {"data":{"sequenceStart":1613277184417,"symbol":"BCHSV-USDT","changes":{"asks":[["248.676","70","1613277184417"]],"bids":[]},"sequenceEnd":1613277184417},"subject":"trade.l2update","topic":"/market/level2:BCHSV-USDT","type":"message"}
1619378333.383498: {"data":{"sequenceStart":1613277184418,"symbol":"BCHSV-USDT","changes":{"asks":[],"bids":[["0","0","1613277184418"]]},"sequenceEnd":1613277184418},"subject":"trade.l2update","topic":"/market/level2:BCHSV-USDT","type":"message"}
1619378333.38352: {"data":{"sequenceStart":1613277184419,"symbol":"BCHSV-USDT","changes":{"asks":[],"bids":[["241.161","5","1613277184419"]]},"sequenceEnd":1613277184419},"subject":"trade.l2update","topic":"/market/level2:BCHSV-USDT","type":"message"}
1619378333.388045: {"data":{"sequenceStart":1613277184420,"symbol":"BCHSV-USDT","changes":{"asks":[["0","0","1613277184420"]],"bids":[]},"sequenceEnd":1613277184420},"subject":"trade.l2update","topic":"/market/level2:BCHSV-USDT","type":"message"}
1619378333.388155: {"data":{"sequenceStart":1613277184421,"symbol":"BCHSV-USDT","changes":{"asks":[["251.516","125","1613277184421"]],"bids":[]},"sequenceEnd":1613277184421},"subject":"trade.l2update","topic":"/market/level2:BCHSV-USDT","type":"message"}
1619378333.388234: {"data":{"sequenceStart":1612844051842,"symbol":"SNX-BTC","changes":{"asks":[["0.00028709","0","1612844051842"]],"bids":[]},"sequenceEnd":1612844051842},"subject":"trade.l2update","topic":"/market/level2:SNX-BTC","type":"message"}
1619378333.3910341: {"data":{"sequence":"1612844051842","bestAsk":"0.00028712","size":"0.01745248","bestBidSize":"0.19100065","price":"0.00028676","time":1619378333349,"bestAskSize":"73.39457178","bestBid":"0.00028678"},"subject":"trade.ticker","topic":"/market/ticker:SNX-BTC","type":"message"}
1619378333.3954601: {"data":{"sequenceStart":1613277184422,"symbol":"BCHSV-USDT","changes":{"asks":[["243.267","0","1613277184422"]],"bids":[]},"sequenceEnd":1613277184422},"subject":"trade.l2update","topic":"/market/level2:BCHSV-USDT","type":"message"}
1619378333.395604: {"data":{"sequenceStart":1612844051843,"symbol":"SNX-BTC","changes":{"asks":[["0","0","1612844051843"]],"bids":[]},"sequenceEnd":1612844051843},"subject":"trade.l2update","topic":"/market/level2:SNX-BTC","type":"message"}
1619378333.395661: {"data":{"sequenceStart":1612844051844,"symbol":"SNX-BTC","changes":{"asks":[["0.00028708","29.24570683","1612844051844"]],"bids":[]},"sequenceEnd":1612844051844},"subject":"trade.l2update","topic":"/market/level2:SNX-BTC","type":"message"}
1619378333.410614: {"data":{"sequenceStart":1612844051845,"symbol":"SNX-BTC","changes":{"asks":[],"bids":[["0","0","1612844051845"]]},"sequenceEnd":1612844051845},"subject":"trade.l2update","topic":"/market/level2:SNX-BTC","type":"message"}
1619378333.410725: {"data":{"sequenceStart":1612844051846,"symbol":"SNX-BTC","changes":{"asks":[],"bids":[["0.00028645","2.1097596","1612844051846"]]},"sequenceEnd":1612844051846},"subject":"trade.l2update","topic":"/market/level2:SNX-BTC","type":"message"}
1619378333.4108071: {"data":{"sequenceStart":1613277184423,"symbol":"BCHSV-USDT","changes":{"asks":[["0","0","1613277184423"]],"bids":[]},"sequenceEnd":1613277184423},"subject":"trade.l2update","topic":"/market/level2:BCHSV-USDT","type":"message"}
1619378333.4108531: {"data":{"sequenceStart":1613277184424,"symbol":"BCHSV-USDT","changes":{"asks":[["245.571","17.79999999","1613277184424"]],"bids":[]},"sequenceEnd":1613277184424},"subject":"trade.l2update","topic":"/market/level2:BCHSV-USDT","type":"message"}
1619378333.428849: {"data":{"sequence":"1612734157793","bestAsk":"0.0000026207","size":"46","bestBidSize":"5436.0663","price":"0.0000026071","time":1619378333388,"bestAskSize":"4147.8755","bestBid":"0.0000025987"},"subject":"trade.ticker","topic":"/market/ticker:ANKR-BTC","type":"message"}
1619378333.4353678: {"data":{"sequenceStart":1612712745639,"symbol":"FET-BTC","changes":{"asks":[["0.00000779","0","1612712745639"]],"bids":[]},"sequenceEnd":1612712745639},"subject":"trade.l2update","topic":"/market/level2:FET-BTC","type":"message"}
1619378333.453821: {"data":{"sequenceStart":1619079123939,"symbol":"EQZ-BTC","changes":{"asks":[],"bids":[["0","0","1619079123939"]]},"sequenceEnd":1619079123939},"subject":"trade.l2update","topic":"/market/level2:EQZ-BTC","type":"message"}
1619378333.453931: {"data":{"sequenceStart":1619079123940,"symbol":"EQZ-BTC","changes":{"asks":[],"bids":[["0.00002332","231.3036","1619079123940"]]},"sequenceEnd":1619079123940},"subject":"trade.l2update","topic":"/market/level2:EQZ-BTC","type":"message"}
1619378333.458446: {"data":{"sequenceStart":1613277184425,"symbol":"BCHSV-USDT","changes":{"asks":[["0","0","1613277184425"]],"bids":[]},"sequenceEnd":1613277184425},"subject":"trade.l2update","topic":"/market/level2:BCHSV-USDT","type":"message"}
1619378333.4585578: {"data":{"sequenceStart":1613277184426,"symbol":"BCHSV-USDT","changes":{"asks":[["243.266","0.6","1613277184426"]],"bids":[]},"sequenceEnd":1613277184426},"subject":"trade.l2update","topic":"/market/level2:BCHSV-USDT","type":"message"}
1619378333.458636: {"data":{"sequenceStart":1612844051847,"symbol":"SNX-BTC","changes":{"asks":[],"bids":[["0","0","1612844051847"]]},"sequenceEnd":1612844051847},"subject":"trade.l2update","topic":"/market/level2:SNX-BTC","type":"message"}
1619378333.4586802: {"data":{"sequenceStart":1612844051848,"symbol":"SNX-BTC","changes":{"asks":[],"bids":[["0.00028609","35.16587467","1612844051848"]]},"sequenceEnd":1612844051848},"subject":"trade.l2update","topic":"/market/level2:SNX-BTC","type":"message"}
1619378333.458733: {"data":{"sequenceStart":1612844051849,"symbol":"SNX-BTC","changes":{"asks":[["0","0","1612844051849"]],"bids":[]},"sequenceEnd":1612844051849},"subject":"trade.l2update","topic":"/market/level2:SNX-BTC","type":"message"}
1619378333.4587688: {"data":{"sequenceStart":1612844051850,"symbol":"SNX-BTC","changes":{"asks":[["0.00028709","14.05154587","1612844051850"]],"bids":[]},"sequenceEnd":1612844051850},"subject":"trade.l2update","topic":"/market/level2:SNX-BTC","type":"message"}
1619378333.458816: {"data":{"sequenceStart":1612844051851,"symbol":"SNX-BTC","changes":{"asks":[["0","0","1612844051851"]],"bids":[]},"sequenceEnd":1612844051851},"subject":"trade.l2update","topic":"/market/level2:SNX-BTC","type":"message"}
1619378333.458849: {"data":{"sequenceStart":1612844051852,"symbol":"SNX-BTC","changes":{"asks":[["0.00028737","14.03939979","1612844051852"]],"bids":[]},"sequenceEnd":1612844051852},"subject":"trade.l2update","topic":"/market/level2:SNX-BTC","type":"message"}
1619378333.4624279: {"data":{"sequence":"1612844051852","bestAsk":"0.00028708","size":"0.01745248","bestBidSize":"0.19100065","price":"0.00028676","time":1619378333423,"bestAskSize":"29.24570683","bestBid":"0.00028678"},"subject":"trade.ticker","topic":"/market/ticker:SNX-BTC","type":"message"}
1619378333.4669619: {"data":{"sequenceStart":1613277184427,"symbol":"BCHSV-USDT","changes":{"asks":[],"bids":[["242.58","0","1613277184427"]]},"sequenceEnd":1613277184427},"subject":"trade.l2update","topic":"/market/level2:BCHSV-USDT","type":"message"}
1619378333.4738822: {"data":{"sequence":"1613277184427","bestAsk":"242.901","size":"0.08000012","bestBidSize":"0.68148185","price":"243.65","time":1619378333433,"bestAskSize":"4.51280965","bestBid":"242.579"},"subject":"trade.ticker","topic":"/market/ticker:BCHSV-USDT","type":"message"}
1619378333.473972: {"data":{"sequence":"1619079123940","bestAsk":"0.00002395","size":"0.375","bestBidSize":"20.5373","price":"0.00002383","time":1619378333438,"bestAskSize":"72.1515","bestBid":"0.00002383"},"subject":"trade.ticker","topic":"/market/ticker:EQZ-BTC","type":"message"}
1619378333.4829051: {"data":{"sequenceStart":1612712745640,"symbol":"FET-BTC","changes":{"asks":[["0.00000793","122.6882","1612712745640"]],"bids":[]},"sequenceEnd":1612712745640},"subject":"trade.l2update","topic":"/market/level2:FET-BTC","type":"message"}
1619378333.4830341: {"data":{"sequenceStart":1612844051853,"symbol":"SNX-BTC","changes":{"asks":[],"bids":[["0","0","1612844051853"]]},"sequenceEnd":1612844051853},"subject":"trade.l2update","topic":"/market/level2:SNX-BTC","type":"message"}
1619378333.4830852: {"data":{"sequenceStart":1612844051854,"symbol":"SNX-BTC","changes":{"asks":[],"bids":[["0.00028569","257.03341456","1612844051854"]]},"sequenceEnd":1612844051854},"subject":"trade.l2update","topic":"/market/level2:SNX-BTC","type":"message"}
1619378333.496112: {"data":{"sequenceStart":1612694580160,"symbol":"CAPP-BTC","changes":{"asks":[],"bids":[["0","0","1612694580160"]]},"sequenceEnd":1612694580160},"subject":"trade.l2update","topic":"/market/level2:CAPP-BTC","type":"message"}
1619378333.4962199: {"data":{"sequenceStart":1612694580161,"symbol":"CAPP-BTC","changes":{"asks":[],"bids":[["0.0000002078","9271.1","1612694580161"]]},"sequenceEnd":1612694580161},"subject":"trade.l2update","topic":"/market/level2:CAPP-BTC","type":"message"}
1619378333.501672: {"data":{"sequenceStart":1613277184428,"symbol":"BCHSV-USDT","changes":{"asks":[],"bids":[["0","0","1613277184428"]]},"sequenceEnd":1613277184428},"subject":"trade.l2update","topic":"/market/level2:BCHSV-USDT","type":"message"}
1619378333.5017831: {"data":{"sequenceStart":1613277184429,"symbol":"BCHSV-USDT","changes":{"asks":[],"bids":[["242.581","5","1613277184429"]]},"sequenceEnd":1613277184429},"subject":"trade.l2update","topic":"/market/level2:BCHSV-USDT","type":"message"}
1619378333.51284: {"data":{"sequenceStart":1613277184430,"symbol":"BCHSV-USDT","changes":{"asks":[["243.266","0","1613277184430"]],"bids":[]},"sequenceEnd":1613277184430},"subject":"trade.l2update","topic":"/market/level2:BCHSV-USDT","type":"message"}
1619378333.512979: {"data":{"sequenceStart":1613277184431,"symbol":"BCHSV-USDT","changes":{"asks":[],"bids":[["241.642","0","1613277184431"]]},"sequenceEnd":1613277184431},"subject":"trade.l2update","topic":"/market/level2:BCHSV-USDT","type":"message"}
1619378333.5130491: {"data":{"sequenceStart":1612844051855,"symbol":"SNX-BTC","changes":{"asks":[["0.00028737","0.01376935","1612844051855"]],"bids":[]},"sequenceEnd":1612844051855},"subject":"trade.l2update","topic":"/market/level2:SNX-BTC","type":"message"}
1619378333.513102: {"data":{"sequence":"1612712745640","bestAsk":"0.00000775","size":"401.2004","bestBidSize":"357.285","price":"0.00000772","time":1619378333469,"bestAskSize":"1154.0416","bestBid":"0.00000771"},"subject":"trade.ticker","topic":"/market/ticker:FET-BTC","type":"message"}
1619378333.516181: {"data":{"sequenceStart":1612734157794,"symbol":"ANKR-BTC","changes":{"asks":[["0.0000026207","0","1612734157794"]],"bids":[]},"sequenceEnd":1612734157794},"subject":"trade.l2update","topic":"/market/level2:ANKR-BTC","type":"message"}
1619378333.519665: {"data":{"sequence":"1612694580161","bestAsk":"0.0000002196","size":"1000.02","bestBidSize":"83.07","price":"0.0000002182","time":1619378333481,"bestAskSize":"4490.25","bestBid":"0.0000002181"},"subject":"trade.ticker","topic":"/market/ticker:CAPP-BTC","type":"message"}
1619378333.527105: {"data":{"sequenceStart":1613277184432,"symbol":"BCHSV-USDT","changes":{"asks":[["0","0","1613277184432"]],"bids":[]},"sequenceEnd":1613277184432},"subject":"trade.l2update","topic":"/market/level2:BCHSV-USDT","type":"message"}
1619378333.5271811: {"data":{"sequenceStart":1613277184433,"symbol":"BCHSV-USDT","changes":{"asks":[["243.265","0.6","1613277184433"]],"bids":[]},"sequenceEnd":1613277184433},"subject":"trade.l2update","topic":"/market/level2:BCHSV-USDT","type":"message"}
1619378333.530292: {"data":{"sequence":"1612734157794","bestAsk":"0.0000026208","size":"46","bestBidSize":"5436.0663","price":"0.0000026071","time":1619378333488,"bestAskSize":"10987.6265","bestBid":"0.0000025987"},"subject":"trade.ticker","topic":"/market/ticker:ANKR-BTC","type":"message"}
1619378333.530354: {"data":{"sequenceStart":1612844051856,"symbol":"SNX-BTC","changes":{"asks":[["0.00028709","0","1612844051856"]],"bids":[]},"sequenceEnd":1612844051856},"subject":"trade.l2update","topic":"/market/level2:SNX-BTC","type":"message"}
1619378333.5368588: {"data":{"sequenceStart":1612712745641,"symbol":"FET-BTC","changes":{"asks":[["0","0","1612712745641"]],"bids":[]},"sequenceEnd":1612712745641},"subject":"trade.l2update","topic":"/market/level2:FET-BTC","type":"message"}
1619378333.536971: {"data":{"sequenceStart":1612712745642,"symbol":"FET-BTC","changes":{"asks":[["0.0000078","1628.5043","1612712745642"]],"bids":[]},"sequenceEnd":1612712745642},"subject":"trade.l2update","topic":"/market/level2:FET-BTC","type":"message"}
1619378333.544705: {"data":{"sequenceStart":1612734157795,"symbol":"ANKR-BTC","changes":{"asks":[],"bids":[["0","0","1612734157795"]]},"sequenceEnd":1612734157795},"subject":"trade.l2update","topic":"/market/level2:ANKR-BTC","type":"message"}
1619378333.5448132: {"data":{"sequenceStart":1612734157796,"symbol":"ANKR-BTC","changes":{"asks":[],"bids":[["0.0000025986","2501.7221","1612734157796"]]},"sequenceEnd":1612734157796},"subject":"trade.l2update","topic":"/market/level2:ANKR-BTC","type":"message"}
1619378333.562779: {"data":{"sequenceStart":1612712745643,"symbol":"FET-BTC","changes":{"asks":[["0","0","1612712745643"]],"bids":[]},"sequenceEnd":1612712745643},"subject":"trade.l2update","topic":"/market/level2:FET-BTC","type":"message"}
1619378333.562887: {"data":{"sequenceStart":1612712745644,"symbol":"FET-BTC","changes":{"asks":[["0.00000792","1643.1264","1612712745644"]],"bids":[]},"sequenceEnd":1612712745644},"subject":"trade.l2update","topic":"/market/level2:FET-BTC","type":"message"}
1619378333.56295: {"data":{"sequence":"1612844051856","bestAsk":"0.00028708","size":"0.01745248","bestBidSize":"0.19100065","price":"0.00028676","time":1619378333523,"bestAskSize":"29.24570683","bestBid":"0.00028678"},"subject":"trade.ticker","topic":"/market/ticker:SNX-BTC","type":"message"}
1619378333.57637: {"data":{"sequence":"1613277184433","bestAsk":"242.901","size":"0.08000012","bestBidSize":"5","price":"243.65","time":1619378333533,"bestAskSize":"4.51280965","bestBid":"242.581"},"subject":"trade.ticker","topic":"/market/ticker:BCHSV-USDT","type":"message"}
1619378333.5804942: {"data":{"sequenceStart":1612844051857,"symbol":"SNX-BTC","changes":{"asks":[["0","0","1612844051857"]],"bids":[]},"sequenceEnd":1612844051857},"subject":"trade.l2update","topic":"/market/level2:SNX-BTC","type":"message"}
1619378333.580601: {"data":{"sequenceStart":1612844051858,"symbol":"SNX-BTC","changes":{"asks":[["0.00028737","14.03939979","1612844051858"]],"bids":[]},"sequenceEnd":1612844051858},"subject":"trade.l2update","topic":"/market/level2:SNX-BTC","type":"message"}
1619378333.580668: {"data":{"sequenceStart":1613277184434,"symbol":"BCHSV-USDT","changes":{"asks":[["0","0","1613277184434"]],"bids":[]},"sequenceEnd":1613277184434},"subject":"trade.l2update","topic":"/market/level2:BCHSV-USDT","type":"message"}
1619378333.5807118: {"data":{"sequenceStart":1613277184435,"symbol":"BCHSV-USDT","changes":{"asks":[["243.696","9.77617409","1613277184435"]],"bids":[]},"sequenceEnd":1613277184435},"subject":"trade.l2update","topic":"/market/level2:BCHSV-USDT","type":"message"}
1619378333.6100779: {"data":{"sequence":"1612712745644","bestAsk":"0.00000775","size":"401.2004","bestBidSize":"357.285","price":"0.00000772","time":1619378333569,"bestAskSize":"1154.0416","bestBid":"0.00000771"},"subject":"trade.ticker","topic":"/market/ticker:FET-BTC","type":"message"}
1619378333.613847: {"data":{"sequenceStart":1612844051859,"symbol":"SNX-BTC","changes":{"asks":[["0","0","1612844051859"]],"bids":[]},"sequenceEnd":1612844051859},"subject":"trade.l2update","topic":"/market/level2:SNX-BTC","type":"message"}
1619378333.613937: {"data":{"sequenceStart":1612844051860,"symbol":"SNX-BTC","changes":{"asks":[["0.00028711","14.04664884","1612844051860"]],"bids":[]},"sequenceEnd":1612844051860},"subject":"trade.l2update","topic":"/market/level2:SNX-BTC","type":"message"}
1619378333.614031: {"data":{"sequenceStart":1612844051861,"symbol":"SNX-BTC","changes":{"asks":[],"bids":[["0.00028645","0","1612844051861"]]},"sequenceEnd":1612844051861},"subject":"trade.l2update","topic":"/market/level2:SNX-BTC","type":"message"}
1619378333.620547: {"data":{"sequenceStart":1613277184436,"symbol":"BCHSV-USDT","changes":{"asks":[],"bids":[["240.434","0","1613277184436"]]},"sequenceEnd":1613277184436},"subject":"trade.l2update","topic":"/market/level2:BCHSV-USDT","type":"message"}
1619378333.628621: {"data":{"sequence":"1612734157796","bestAsk":"0.0000026208","size":"46","bestBidSize":"5436.0663","price":"0.0000026071","time":1619378333588,"bestAskSize":"10987.6265","bestBid":"0.0000025987"},"subject":"trade.ticker","topic":"/market/ticker:ANKR-BTC","type":"message"}
1619378333.660286: {"data":{"sequence":"1612844051861","bestAsk":"0.00028708","size":"0.01745248","bestBidSize":"0.19100065","price":"0.00028676","time":1619378333623,"bestAskSize":"29.24570683","bestBid":"0.00028678"},"subject":"trade.ticker","topic":"/market/ticker:SNX-BTC","type":"message"}
1619378333.663789: {"data":{"sequenceStart":1613277184437,"symbol":"BCHSV-USDT","changes":{"asks":[],"bids":[["242.581","0","1613277184437"]]},"sequenceEnd":1613277184437},"subject":"trade.l2update","topic":"/market/level2:BCHSV-USDT","type":"message"}
1619378333.675148: {"data":{"sequence":"1613277184439","bestAsk":"242.901","size":"0.08000012","bestBidSize":"0.68148185","price":"243.65","time":1619378333633,"bestAskSize":"4.51280965","bestBid":"242.579"},"subject":"trade.ticker","topic":"/market/ticker:BCHSV-USDT","type":"message"}
1619378333.675217: {"data":{"sequenceStart":1613277184438,"symbol":"BCHSV-USDT","changes":{"asks":[],"bids":[["0","0","1613277184438"]]},"sequenceEnd":1613277184438},"subject":"trade.l2update","topic":"/market/level2:BCHSV-USDT","type":"message"}
1619378333.675277: {"data":{"sequenceStart":1613277184439,"symbol":"BCHSV-USDT","changes":{"asks":[],"bids":[["241.769","4.29281126","1613277184439"]]},"sequenceEnd":1613277184439},"subject":"trade.l2update","topic":"/market/level2:BCHSV-USDT","type":"message"}
1619378333.683611: {"data":{"sequenceStart":1613277184440,"symbol":"BCHSV-USDT","changes":{"asks":[],"bids":[["0","0","1613277184440"]]},"sequenceEnd":1613277184440},"subject":"trade.l2update","topic":"/market/level2:BCHSV-USDT","type":"message"}
1619378333.683726: {"data":{"sequenceStart":1613277184441,"symbol":"BCHSV-USDT","changes":{"asks":[],"bids":[["242.583","5","1613277184441"]]},"sequenceEnd":1613277184441},"subject":"trade.l2update","topic":"/market/level2:BCHSV-USDT","type":"message"}
1619378333.702406: {"data":{"sequenceStart":1612712745645,"symbol":"FET-BTC","changes":{"asks":[["0","0","1612712745645"]],"bids":[]},"sequenceEnd":1612712745645},"subject":"trade.l2update","topic":"/market/level2:FET-BTC","type":"message"}
1619378333.702519: {"data":{"sequenceStart":1612712745646,"symbol":"FET-BTC","changes":{"asks":[["0.00000794","3220.539","1612712745646"]],"bids":[]},"sequenceEnd":1612712745646},"subject":"trade.l2update","topic":"/market/level2:FET-BTC","type":"message"}
1619378333.7025988: {"data":{"sequenceStart":1613277184442,"symbol":"BCHSV-USDT","changes":{"asks":[],"bids":[["242.579","0","1613277184442"]]},"sequenceEnd":1613277184442},"subject":"trade.l2update","topic":"/market/level2:BCHSV-USDT","type":"message"}
1619378333.706558: {"data":{"sequence":"1612712745646","bestAsk":"0.00000775","size":"401.2004","bestBidSize":"357.285","price":"0.00000772","time":1619378333667,"bestAskSize":"1154.0416","bestBid":"0.00000771"},"subject":"trade.ticker","topic":"/market/ticker:FET-BTC","type":"message"}
1619378333.711633: {"data":{"sequenceStart":1612844051862,"symbol":"SNX-BTC","changes":{"asks":[],"bids":[["0.0002825","0","1612844051862"]]},"sequenceEnd":1612844051862},"subject":"trade.l2update","topic":"/market/level2:SNX-BTC","type":"message"}
1619378333.7222521: {"data":{"sequenceStart":1613277184443,"symbol":"BCHSV-USDT","changes":{"asks":[],"bids":[["0","0","1613277184443"]]},"sequenceEnd":1613277184443},"subject":"trade.l2update","topic":"/market/level2:BCHSV-USDT","type":"message"}
1619378333.722361: {"data":{"sequenceStart":1613277184444,"symbol":"BCHSV-USDT","changes":{"asks":[],"bids":[["242.581","0.68148185","1613277184444"]]},"sequenceEnd":1613277184444},"subject":"trade.l2update","topic":"/market/level2:BCHSV-USDT","type":"message"}
1619378333.7416341: {"data":{"sequenceStart":1613277184445,"symbol":"BCHSV-USDT","changes":{"asks":[],"bids":[["0","0","1613277184445"]]},"sequenceEnd":1613277184445},"subject":"trade.l2update","topic":"/market/level2:BCHSV-USDT","type":"message"}
1619378333.741743: {"data":{"sequenceStart":1613277184446,"symbol":"BCHSV-USDT","changes":{"asks":[],"bids":[["239.431","10.23257894","1613277184446"]]},"sequenceEnd":1613277184446},"subject":"trade.l2update","topic":"/market/level2:BCHSV-USDT","type":"message"}
1619378333.746794: {"data":{"sequenceStart":1612712745647,"symbol":"FET-BTC","changes":{"asks":[["0.0000078","0","1612712745647"]],"bids":[]},"sequenceEnd":1612712745647},"subject":"trade.l2update","topic":"/market/level2:FET-BTC","type":"message"}
1619378333.757241: {"data":{"sequence":"1612844051862","bestAsk":"0.00028708","size":"0.01745248","bestBidSize":"0.19100065","price":"0.00028676","time":1619378333723,"bestAskSize":"29.24570683","bestBid":"0.00028678"},"subject":"trade.ticker","topic":"/market/ticker:SNX-BTC","type":"message"}
1619378333.765923: {"data":{"sequenceStart":1613277184447,"symbol":"BCHSV-USDT","changes":{"asks":[],"bids":[["242.583","0","1613277184447"]]},"sequenceEnd":1613277184447},"subject":"trade.l2update","topic":"/market/level2:BCHSV-USDT","type":"message"}
1619378333.774558: {"data":{"sequenceStart":1612701563972,"symbol":"DAPPT-BTC","changes":{"asks":[],"bids":[["0.0000001116","3774.8315","1612701563972"]]},"sequenceEnd":1612701563972},"subject":"trade.l2update","topic":"/market/level2:DAPPT-BTC","type":"message"}
1619378333.7746801: {"data":{"sequence":"1613277184447","bestAsk":"242.901","size":"0.08000012","bestBidSize":"0.68148185","price":"243.65","time":1619378333732,"bestAskSize":"4.51280965","bestBid":"242.581"},"subject":"trade.ticker","topic":"/market/ticker:BCHSV-USDT","type":"message"}
1619378333.784544: {"data":{"sequenceStart":1612844051863,"symbol":"SNX-BTC","changes":{"asks":[],"bids":[["0","0","1612844051863"]]},"sequenceEnd":1612844051863},"subject":"trade.l2update","topic":"/market/level2:SNX-BTC","type":"message"}
1619378333.784651: {"data":{"sequenceStart":1612844051864,"symbol":"SNX-BTC","changes":{"asks":[],"bids":[["0.00028612","14.11890361","1612844051864"]]},"sequenceEnd":1612844051864},"subject":"trade.l2update","topic":"/market/level2:SNX-BTC","type":"message"}
1619378333.788466: {"data":{"sequenceStart":1613277184448,"symbol":"BCHSV-USDT","changes":{"asks":[],"bids":[["0","0","1613277184448"]]},"sequenceEnd":1613277184448},"subject":"trade.l2update","topic":"/market/level2:BCHSV-USDT","type":"message"}
1619378333.788576: {"data":{"sequenceStart":1613277184449,"symbol":"BCHSV-USDT","changes":{"asks":[],"bids":[["242.584","5","1613277184449"]]},"sequenceEnd":1613277184449},"subject":"trade.l2update","topic":"/market/level2:BCHSV-USDT","type":"message"}
1619378333.788652: {"data":{"sequenceStart":1613277184450,"symbol":"BCHSV-USDT","changes":{"asks":[["245.571","0","1613277184450"]],"bids":[]},"sequenceEnd":1613277184450},"subject":"trade.l2update","topic":"/market/level2:BCHSV-USDT","type":"message"}
1619378333.793705: {"data":{"sequenceStart":1613277184451,"symbol":"BCHSV-USDT","changes":{"asks":[["243.265","0","1613277184451"]],"bids":[]},"sequenceEnd":1613277184451},"subject":"trade.l2update","topic":"/market/level2:BCHSV-USDT","type":"message"}
1619378333.819196: {"data":{"sequence":"1612712745647","bestAsk":"0.00000775","size":"401.2004","bestBidSize":"357.285","price":"0.00000772","time":1619378333767,"bestAskSize":"1154.0416","bestBid":"0.00000771"},"subject":"trade.ticker","topic":"/market/ticker:FET-BTC","type":"message"}
1619378333.829974: {"data":{"sequenceStart":1612694580162,"symbol":"CAPP-BTC","changes":{"asks":[],"bids":[["0.0000002104","0","1612694580162"]]},"sequenceEnd":1612694580162},"subject":"trade.l2update","topic":"/market/level2:CAPP-BTC","type":"message"}
1619378333.8301141: {"data":{"sequenceStart":1613277184452,"symbol":"BCHSV-USDT","changes":{"asks":[["0","0","1613277184452"]],"bids":[]},"sequenceEnd":1613277184452},"subject":"trade.l2update","topic":"/market/level2:BCHSV-USDT","type":"message"}
1619378333.830168: {"data":{"sequenceStart":1613277184453,"symbol":"BCHSV-USDT","changes":{"asks":[["243.251","0.6","1613277184453"]],"bids":[]},"sequenceEnd":1613277184453},"subject":"trade.l2update","topic":"/market/level2:BCHSV-USDT","type":"message"}
1619378333.837261: {"data":{"sequenceStart":1612712745648,"symbol":"FET-BTC","changes":{"asks":[["0","0","1612712745648"]],"bids":[]},"sequenceEnd":1612712745648},"subject":"trade.l2update","topic":"/market/level2:FET-BTC","type":"message"}
1619378333.8373692: {"data":{"sequenceStart":1612712745649,"symbol":"FET-BTC","changes":{"asks":[["0.0000078","3869.4013","1612712745649"]],"bids":[]},"sequenceEnd":1612712745649},"subject":"trade.l2update","topic":"/market/level2:FET-BTC","type":"message"}
1619378333.842602: {"data":{"sequenceStart":1612734157797,"symbol":"ANKR-BTC","changes":{"asks":[],"bids":[["0","0","1612734157797"]]},"sequenceEnd":1612734157797},"subject":"trade.l2update","topic":"/market/level2:ANKR-BTC","type":"message"}
1619378333.842709: {"data":{"sequenceStart":1612734157798,"symbol":"ANKR-BTC","changes":{"asks":[],"bids":[["0.0000025818","660","1612734157798"]]},"sequenceEnd":1612734157798},"subject":"trade.l2update","topic":"/market/level2:ANKR-BTC","type":"message"}
1619378333.85649: {"data":{"sequence":"1612844051864","bestAsk":"0.00028708","size":"0.01745248","bestBidSize":"0.19100065","price":"0.00028676","time":1619378333823,"bestAskSize":"29.24570683","bestBid":"0.00028678"},"subject":"trade.ticker","topic":"/market/ticker:SNX-BTC","type":"message"}
1619378333.8704572: {"data":{"sequence":"1613277184455","bestAsk":"242.901","size":"0.08000012","bestBidSize":"5","price":"243.65","time":1619378333832,"bestAskSize":"4.51280965","bestBid":"242.584"},"subject":"trade.ticker","topic":"/market/ticker:BCHSV-USDT","type":"message"}
1619378333.870507: {"data":{"sequenceStart":1613277184454,"symbol":"BCHSV-USDT","changes":{"asks":[],"bids":[["0","0","1613277184454"]]},"sequenceEnd":1613277184454},"subject":"trade.l2update","topic":"/market/level2:BCHSV-USDT","type":"message"}
1619378333.870552: {"data":{"sequenceStart":1613277184455,"symbol":"BCHSV-USDT","changes":{"asks":[],"bids":[["241.704","7.20815689","1613277184455"]]},"sequenceEnd":1613277184455},"subject":"trade.l2update","topic":"/market/level2:BCHSV-USDT","type":"message"}
1619378333.870601: {"data":{"sequence":"1612701563972","bestAsk":"0.000000113","size":"145.4959","bestBidSize":"361.2609","price":"0.0000001126","time":1619378333830,"bestAskSize":"1208.0878","bestBid":"0.0000001119"},"subject":"trade.ticker","topic":"/market/ticker:DAPPT-BTC","type":"message"}
1619378333.9162922: {"data":{"sequenceStart":1612734157799,"symbol":"ANKR-BTC","changes":{"asks":[],"bids":[["0.0000025986","0","1612734157799"]]},"sequenceEnd":1612734157799},"subject":"trade.l2update","topic":"/market/level2:ANKR-BTC","type":"message"}
1619378333.920942: {"data":{"sequence":"1612712745649","bestAsk":"0.00000775","size":"401.2004","bestBidSize":"357.285","price":"0.00000772","time":1619378333868,"bestAskSize":"1154.0416","bestBid":"0.00000771"},"subject":"trade.ticker","topic":"/market/ticker:FET-BTC","type":"message"}
1619378333.921057: {"data":{"sequence":"1612694580162","bestAsk":"0.0000002196","size":"1000.02","bestBidSize":"83.07","price":"0.0000002182","time":1619378333882,"bestAskSize":"4490.25","bestBid":"0.0000002181"},"subject":"trade.ticker","topic":"/market/ticker:CAPP-BTC","type":"message"}
1619378333.931154: {"data":{"sequence":"1612734157799","bestAsk":"0.0000026208","size":"46","bestBidSize":"5436.0663","price":"0.0000026071","time":1619378333888,"bestAskSize":"10987.6265","bestBid":"0.0000025987"},"subject":"trade.ticker","topic":"/market/ticker:ANKR-BTC","type":"message"}
1619378333.976427: {"data":{"sequenceStart":1612694580163,"symbol":"CAPP-BTC","changes":{"asks":[],"bids":[["0.0000002167","5526.55","1612694580163"]]},"sequenceEnd":1612694580163},"subject":"trade.l2update","topic":"/market/level2:CAPP-BTC","type":"message"}
1619378333.9993632: {"data":{"sequenceStart":1613277184456,"symbol":"BCHSV-USDT","changes":{"asks":[],"bids":[["242.581","0","1613277184456"]]},"sequenceEnd":1613277184456},"subject":"trade.l2update","topic":"/market/level2:BCHSV-USDT","type":"message"}
1619378334.006034: {"data":{"sequenceStart":1613277184457,"symbol":"BCHSV-USDT","changes":{"asks":[["243.251","0","1613277184457"]],"bids":[]},"sequenceEnd":1613277184457},"subject":"trade.l2update","topic":"/market/level2:BCHSV-USDT","type":"message"}
1619378334.009644: {"data":{"sequenceStart":1613277184458,"symbol":"BCHSV-USDT","changes":{"asks":[["0","0","1613277184458"]],"bids":[]},"sequenceEnd":1613277184458},"subject":"trade.l2update","topic":"/market/level2:BCHSV-USDT","type":"message"}
1619378334.0097558: {"data":{"sequenceStart":1613277184459,"symbol":"BCHSV-USDT","changes":{"asks":[["243.252","0.6","1613277184459"]],"bids":[]},"sequenceEnd":1613277184459},"subject":"trade.l2update","topic":"/market/level2:BCHSV-USDT","type":"message"}
1619378334.029108: {"data":{"sequence":"1612694580163","bestAsk":"0.0000002196","size":"1000.02","bestBidSize":"83.07","price":"0.0000002182","time":1619378333982,"bestAskSize":"4490.25","bestBid":"0.0000002181"},"subject":"trade.ticker","topic":"/market/ticker:CAPP-BTC","type":"message"}
1619378334.0291991: {"data":{"sequenceStart":1612844051865,"symbol":"SNX-BTC","changes":{"asks":[],"bids":[["0","0","1612844051865"]]},"sequenceEnd":1612844051865},"subject":"trade.l2update","topic":"/market/level2:SNX-BTC","type":"message"}
1619378334.029245: {"data":{"sequenceStart":1612844051866,"symbol":"SNX-BTC","changes":{"asks":[],"bids":[["0.00028646","14.07441675","1612844051866"]]},"sequenceEnd":1612844051866},"subject":"trade.l2update","topic":"/market/level2:SNX-BTC","type":"message"}
1619378334.029293: {"data":{"sequenceStart":1612844051867,"symbol":"SNX-BTC","changes":{"asks":[["0.00028737","0.01376935","1612844051867"]],"bids":[]},"sequenceEnd":1612844051867},"subject":"trade.l2update","topic":"/market/level2:SNX-BTC","type":"message"}
1619378334.029324: {"data":{"sequenceStart":1612734157800,"symbol":"ANKR-BTC","changes":{"asks":[],"bids":[["0","0","1612734157800"]]},"sequenceEnd":1612734157800},"subject":"trade.l2update","topic":"/market/level2:ANKR-BTC","type":"message"}
1619378334.0293481: {"data":{"sequenceStart":1612734157801,"symbol":"ANKR-BTC","changes":{"asks":[],"bids":[["0.0000025988","3498.6629","1612734157801"]]},"sequenceEnd":1612734157801},"subject":"trade.l2update","topic":"/market/level2:ANKR-BTC","type":"message"}
1619378334.02938: {"data":{"sequenceStart":1613277184460,"symbol":"BCHSV-USDT","changes":{"asks":[],"bids":[["0","0","1613277184460"]]},"sequenceEnd":1613277184460},"subject":"trade.l2update","topic":"/market/level2:BCHSV-USDT","type":"message"}
1619378334.029403: {"data":{"sequenceStart":1613277184461,"symbol":"BCHSV-USDT","changes":{"asks":[],"bids":[["242.582","0.68148185","1613277184461"]]},"sequenceEnd":1613277184461},"subject":"trade.l2update","topic":"/market/level2:BCHSV-USDT","type":"message"}
1619378334.029432: {"data":{"sequence":"1612734157801","bestAsk":"0.0000026208","size":"46","bestBidSize":"3498.6629","price":"0.0000026071","time":1619378333988,"bestAskSize":"10987.6265","bestBid":"0.0000025988"},"subject":"trade.ticker","topic":"/market/ticker:ANKR-BTC","type":"message"}
1619378334.048202: {"data":{"sequenceStart":1612734157802,"symbol":"ANKR-BTC","changes":{"asks":[],"bids":[["0.0000025987","0","1612734157802"]]},"sequenceEnd":1612734157802},"subject":"trade.l2update","topic":"/market/level2:ANKR-BTC","type":"message"}
1619378334.078135: {"data":{"sequenceStart":1612844051868,"symbol":"SNX-BTC","changes":{"asks":[],"bids":[["0.00028646","0","1612844051868"]]},"sequenceEnd":1612844051868},"subject":"trade.l2update","topic":"/market/level2:SNX-BTC","type":"message"}
1619378334.081735: {"data":{"sequenceStart":1613277184462,"symbol":"BCHSV-USDT","changes":{"asks":[],"bids":[["242.584","0","1613277184462"]]},"sequenceEnd":1613277184462},"subject":"trade.l2update","topic":"/market/level2:BCHSV-USDT","type":"message"}
1619378334.081872: {"data":{"sequence":"1613277184461","bestAsk":"242.901","size":"0.08000012","bestBidSize":"5","price":"243.65","time":1619378334030,"bestAskSize":"4.51280965","bestBid":"242.584"},"subject":"trade.ticker","topic":"/market/ticker:BCHSV-USDT","type":"message"}
1619378334.081922: {"data":{"sequence":"1612844051868","bestAsk":"0.00028708","size":"0.01745248","bestBidSize":"0.19100065","price":"0.00028676","time":1619378334048,"bestAskSize":"29.24570683","bestBid":"0.00028678"},"subject":"trade.ticker","topic":"/market/ticker:SNX-BTC","type":"message"}
1619378334.0876002: {"data":{"sequenceStart":1612734157803,"symbol":"ANKR-BTC","changes":{"asks":[],"bids":[["0","0","1612734157803"]]},"sequenceEnd":1612734157803},"subject":"trade.l2update","topic":"/market/level2:ANKR-BTC","type":"message"}
1619378334.08771: {"data":{"sequenceStart":1612734157804,"symbol":"ANKR-BTC","changes":{"asks":[],"bids":[["0.0000025989","5127.1098","1612734157804"]]},"sequenceEnd":1612734157804},"subject":"trade.l2update","topic":"/market/level2:ANKR-BTC","type":"message"}
1619378334.1309671: {"data":{"sequenceStart":1613277184463,"symbol":"BCHSV-USDT","changes":{"asks":[],"bids":[["242.582","0","1613277184463"]]},"sequenceEnd":1613277184463},"subject":"trade.l2update","topic":"/market/level2:BCHSV-USDT","type":"message"}
1619378334.1311061: {"data":{"sequenceStart":1613277184464,"symbol":"BCHSV-USDT","changes":{"asks":[["243.252","0","1613277184464"]],"bids":[]},"sequenceEnd":1613277184464},"subject":"trade.l2update","topic":"/market/level2:BCHSV-USDT","type":"message"}
1619378334.131181: {"data":{"sequenceStart":1612844051869,"symbol":"SNX-BTC","changes":{"asks":[],"bids":[["0.00028612","0","1612844051869"]]},"sequenceEnd":1612844051869},"subject":"trade.l2update","topic":"/market/level2:SNX-BTC","type":"message"}
1619378334.137312: {"data":{"sequence":"1612734157804","bestAsk":"0.0000026208","size":"46","bestBidSize":"5127.1098","price":"0.0000026071","time":1619378334088,"bestAskSize":"10987.6265","bestBid":"0.0000025989"},"subject":"trade.ticker","topic":"/market/ticker:ANKR-BTC","type":"message"}
1619378334.142307: {"data":{"sequenceStart":1613277184465,"symbol":"BCHSV-USDT","changes":{"asks":[],"bids":[["0","0","1613277184465"]]},"sequenceEnd":1613277184465},"subject":"trade.l2update","topic":"/market/level2:BCHSV-USDT","type":"message"}
1619378334.142417: {"data":{"sequenceStart":1613277184466,"symbol":"BCHSV-USDT","changes":{"asks":[],"bids":[["242.579","5","1613277184466"]]},"sequenceEnd":1613277184466},"subject":"trade.l2update","topic":"/market/level2:BCHSV-USDT","type":"message"}
1619378334.142493: {"data":{"sequenceStart":1613277184467,"symbol":"BCHSV-USDT","changes":{"asks":[["0","0","1613277184467"]],"bids":[]},"sequenceEnd":1613277184467},"subject":"trade.l2update","topic":"/market/level2:BCHSV-USDT","type":"message"}
1619378334.142536: {"data":{"sequenceStart":1613277184468,"symbol":"BCHSV-USDT","changes":{"asks":[["243.251","0.6","1613277184468"]],"bids":[]},"sequenceEnd":1613277184468},"subject":"trade.l2update","topic":"/market/level2:BCHSV-USDT","type":"message"}
1619378334.142612: {"data":{"sequenceStart":1613277184469,"symbol":"BCHSV-USDT","changes":{"asks":[],"bids":[["0","0","1613277184469"]]},"sequenceEnd":1613277184469},"subject":"trade.l2update","topic":"/market/level2:BCHSV-USDT","type":"message"}
1619378334.142636: {"data":{"sequenceStart":1613277184470,"symbol":"BCHSV-USDT","changes":{"asks":[],"bids":[["242.568","0.68148185","1613277184470"]]},"sequenceEnd":1613277184470},"subject":"trade.l2update","topic":"/market/level2:BCHSV-USDT","type":"message"}
1619378334.142665: {"data":{"sequenceStart":1612734157805,"symbol":"ANKR-BTC","changes":{"asks":[],"bids":[["0.0000025988","0","1612734157805"]]},"sequenceEnd":1612734157805},"subject":"trade.l2update","topic":"/market/level2:ANKR-BTC","type":"message"}
1619378334.1710432: {"data":{"sequenceStart":1612844051870,"symbol":"SNX-BTC","changes":{"asks":[],"bids":[["0","0","1612844051870"]]},"sequenceEnd":1612844051870},"subject":"trade.l2update","topic":"/market/level2:SNX-BTC","type":"message"}
1619378334.1711528: {"data":{"sequenceStart":1612844051871,"symbol":"SNX-BTC","changes":{"asks":[],"bids":[["0.00028645","14.07490809","1612844051871"]]},"sequenceEnd":1612844051871},"subject":"trade.l2update","topic":"/market/level2:SNX-BTC","type":"message"}
1619378334.171232: {"data":{"sequenceStart":1612844051872,"symbol":"SNX-BTC","changes":{"asks":[],"bids":[["0","0","1612844051872"]]},"sequenceEnd":1612844051872},"subject":"trade.l2update","topic":"/market/level2:SNX-BTC","type":"message"}
1619378334.171276: {"data":{"sequenceStart":1612844051873,"symbol":"SNX-BTC","changes":{"asks":[],"bids":[["0.00028616","8.10796833","1612844051873"]]},"sequenceEnd":1612844051873},"subject":"trade.l2update","topic":"/market/level2:SNX-BTC","type":"message"}
1619378334.171335: {"data":{"sequence":"1613277184470","bestAsk":"242.901","size":"0.08000012","bestBidSize":"5","price":"243.65","time":1619378334131,"bestAskSize":"4.51280965","bestBid":"242.579"},"subject":"trade.ticker","topic":"/market/ticker:BCHSV-USDT","type":"message"}
1619378334.181992: {"data":{"sequence":"1612844051873","bestAsk":"0.00028708","size":"0.01745248","bestBidSize":"0.19100065","price":"0.00028676","time":1619378334145,"bestAskSize":"29.24570683","bestBid":"0.00028678"},"subject":"trade.ticker","topic":"/market/ticker:SNX-BTC","type":"message"}
1619378334.191821: {"data":{"sequenceStart":1612844051874,"symbol":"SNX-BTC","changes":{"asks":[],"bids":[["0.00028645","0","1612844051874"]]},"sequenceEnd":1612844051874},"subject":"trade.l2update","topic":"/market/level2:SNX-BTC","type":"message"}
1619378334.210667: {"data":{"sequenceStart":1619079123941,"symbol":"EQZ-BTC","changes":{"asks":[],"bids":[["0.00002369","0","1619079123941"]]},"sequenceEnd":1619079123941},"subject":"trade.l2update","topic":"/market/level2:EQZ-BTC","type":"message"}
1619378334.227566: {"data":{"sequence":"1612734157805","bestAsk":"0.0000026208","size":"46","bestBidSize":"5127.1098","price":"0.0000026071","time":1619378334188,"bestAskSize":"10987.6265","bestBid":"0.0000025989"},"subject":"trade.ticker","topic":"/market/ticker:ANKR-BTC","type":"message"}
1619378334.232935: {"data":{"sequenceStart":1613277184471,"symbol":"BCHSV-USDT","changes":{"asks":[],"bids":[["240.653","0","1613277184471"]]},"sequenceEnd":1613277184471},"subject":"trade.l2update","topic":"/market/level2:BCHSV-USDT","type":"message"}
1619378334.233077: {"data":{"sequenceStart":1613277184472,"symbol":"BCHSV-USDT","changes":{"asks":[],"bids":[["0","0","1613277184472"]]},"sequenceEnd":1613277184472},"subject":"trade.l2update","topic":"/market/level2:BCHSV-USDT","type":"message"}
1619378334.233129: {"data":{"sequenceStart":1613277184473,"symbol":"BCHSV-USDT","changes":{"asks":[],"bids":[["242.52","4.51280965","1613277184473"]]},"sequenceEnd":1613277184473},"subject":"trade.l2update","topic":"/market/level2:BCHSV-USDT","type":"message"}
1619378334.258143: {"data":{"sequence":"1612844051874","bestAsk":"0.00028708","size":"0.01745248","bestBidSize":"0.19100065","price":"0.00028676","time":1619378334223,"bestAskSize":"29.24570683","bestBid":"0.00028678"},"subject":"trade.ticker","topic":"/market/ticker:SNX-BTC","type":"message"}
1619378334.272059: {"data":{"sequence":"1613277184474","bestAsk":"242.901","size":"0.08000012","bestBidSize":"0.68148185","price":"243.65","time":1619378334233,"bestAskSize":"4.51280965","bestBid":"242.568"},"subject":"trade.ticker","topic":"/market/ticker:BCHSV-USDT","type":"message"}
1619378334.27215: {"data":{"sequenceStart":1613277184474,"symbol":"BCHSV-USDT","changes":{"asks":[],"bids":[["242.579","0","1613277184474"]]},"sequenceEnd":1613277184474},"subject":"trade.l2update","topic":"/market/level2:BCHSV-USDT","type":"message"}
1619378334.295109: {"data":{"sequence":"1619079123941","bestAsk":"0.00002395","size":"0.375","bestBidSize":"20.5373","price":"0.00002383","time":1619378334238,"bestAskSize":"72.1515","bestBid":"0.00002383"},"subject":"trade.ticker","topic":"/market/ticker:EQZ-BTC","type":"message"}
1619378334.3107688: {"data":{"sequenceStart":1613277184475,"symbol":"BCHSV-USDT","changes":{"asks":[],"bids":[["242.568","0","1613277184475"]]},"sequenceEnd":1613277184475},"subject":"trade.l2update","topic":"/market/level2:BCHSV-USDT","type":"message"}
1619378334.310865: {"data":{"sequenceStart":1613277184476,"symbol":"BCHSV-USDT","changes":{"asks":[["243.251","0","1613277184476"]],"bids":[]},"sequenceEnd":1613277184476},"subject":"trade.l2update","topic":"/market/level2:BCHSV-USDT","type":"message"}
1619378334.3109272: {"data":{"sequenceStart":1613277184477,"symbol":"BCHSV-USDT","changes":{"asks":[],"bids":[["0","0","1613277184477"]]},"sequenceEnd":1613277184477},"subject":"trade.l2update","topic":"/market/level2:BCHSV-USDT","type":"message"}
1619378334.310956: {"data":{"sequenceStart":1613277184478,"symbol":"BCHSV-USDT","changes":{"asks":[],"bids":[["242.573","0.68148185","1613277184478"]]},"sequenceEnd":1613277184478},"subject":"trade.l2update","topic":"/market/level2:BCHSV-USDT","type":"message"}
1619378334.31099: {"data":{"sequenceStart":1613277184479,"symbol":"BCHSV-USDT","changes":{"asks":[["0","0","1613277184479"]],"bids":[]},"sequenceEnd":1613277184479},"subject":"trade.l2update","topic":"/market/level2:BCHSV-USDT","type":"message"}
1619378334.3110132: {"data":{"sequenceStart":1613277184480,"symbol":"BCHSV-USDT","changes":{"asks":[["243.249","0.6","1613277184480"]],"bids":[]},"sequenceEnd":1613277184480},"subject":"trade.l2update","topic":"/market/level2:BCHSV-USDT","type":"message"}
1619378334.335087: {"data":{"sequenceStart":1612844051875,"symbol":"SNX-BTC","changes":{"asks":[],"bids":[["0.00028616","0","1612844051875"]]},"sequenceEnd":1612844051875},"subject":"trade.l2update","topic":"/market/level2:SNX-BTC","type":"message"}
1619378334.355655: {"data":{"sequence":"1612844051875","bestAsk":"0.00028708","size":"0.01745248","bestBidSize":"0.19100065","price":"0.00028676","time":1619378334323,"bestAskSize":"29.24570683","bestBid":"0.00028678"},"subject":"trade.ticker","topic":"/market/ticker:SNX-BTC","type":"message"}
1619378334.364981: {"data":{"sequence":"1613277184480","bestAsk":"242.901","size":"0.08000012","bestBidSize":"0.68148185","price":"243.65","time":1619378334330,"bestAskSize":"4.51280965","bestBid":"242.573"},"subject":"trade.ticker","topic":"/market/ticker:BCHSV-USDT","type":"message"}
1619378334.380277: {"data":{"sequenceStart":1613277184481,"symbol":"BCHSV-USDT","changes":{"asks":[],"bids":[["0","0","1613277184481"]]},"sequenceEnd":1613277184481},"subject":"trade.l2update","topic":"/market/level2:BCHSV-USDT","type":"message"}
1619378334.380386: {"data":{"sequenceStart":1613277184482,"symbol":"BCHSV-USDT","changes":{"asks":[],"bids":[["242.577","5","1613277184482"]]},"sequenceEnd":1613277184482},"subject":"trade.l2update","topic":"/market/level2:BCHSV-USDT","type":"message"}
1619378334.380461: {"data":{"sequenceStart":1613277184483,"symbol":"BCHSV-USDT","changes":{"asks":[],"bids":[["0","0","1613277184483"]]},"sequenceEnd":1613277184483},"subject":"trade.l2update","topic":"/market/level2:BCHSV-USDT","type":"message"}
1619378334.380503: {"data":{"sequenceStart":1613277184484,"symbol":"BCHSV-USDT","changes":{"asks":[],"bids":[["239.841","10.63203006","1613277184484"]]},"sequenceEnd":1613277184484},"subject":"trade.l2update","topic":"/market/level2:BCHSV-USDT","type":"message"}
1619378334.4025621: {"data":{"sequenceStart":1613277184485,"symbol":"BCHSV-USDT","changes":{"asks":[],"bids":[["242.573","0","1613277184485"]]},"sequenceEnd":1613277184485},"subject":"trade.l2update","topic":"/market/level2:BCHSV-USDT","type":"message"}
1619378334.410097: {"data":{"sequenceStart":1613277184486,"symbol":"BCHSV-USDT","changes":{"asks":[],"bids":[["0","0","1613277184486"]]},"sequenceEnd":1613277184486},"subject":"trade.l2update","topic":"/market/level2:BCHSV-USDT","type":"message"}
1619378334.410205: {"data":{"sequenceStart":1613277184487,"symbol":"BCHSV-USDT","changes":{"asks":[],"bids":[["242.575","0.68148185","1613277184487"]]},"sequenceEnd":1613277184487},"subject":"trade.l2update","topic":"/market/level2:BCHSV-USDT","type":"message"}
1619378334.444633: {"data":{"sequenceStart":1613277184488,"symbol":"BCHSV-USDT","changes":{"asks":[],"bids":[["0","0","1613277184488"]]},"sequenceEnd":1613277184488},"subject":"trade.l2update","topic":"/market/level2:BCHSV-USDT","type":"message"}
1619378334.44474: {"data":{"sequenceStart":1613277184489,"symbol":"BCHSV-USDT","changes":{"asks":[],"bids":[["241.515","5","1613277184489"]]},"sequenceEnd":1613277184489},"subject":"trade.l2update","topic":"/market/level2:BCHSV-USDT","type":"message"}
1619378334.45421: {"data":{"sequenceStart":1613277184490,"symbol":"BCHSV-USDT","changes":{"asks":[["0","0","1613277184490"]],"bids":[]},"sequenceEnd":1613277184490},"subject":"trade.l2update","topic":"/market/level2:BCHSV-USDT","type":"message"}
1619378334.454319: {"data":{"sequenceStart":1613277184491,"symbol":"BCHSV-USDT","changes":{"asks":[["244.312","150","1613277184491"]],"bids":[]},"sequenceEnd":1613277184491},"subject":"trade.l2update","topic":"/market/level2:BCHSV-USDT","type":"message"}
1619378334.454418: {"data":{"sequenceStart":1613277184492,"symbol":"BCHSV-USDT","changes":{"asks":[["0","0","1613277184492"]],"bids":[]},"sequenceEnd":1613277184492},"subject":"trade.l2update","topic":"/market/level2:BCHSV-USDT","type":"message"}
1619378334.45446: {"data":{"sequenceStart":1613277184493,"symbol":"BCHSV-USDT","changes":{"asks":[["243.675","5","1613277184493"]],"bids":[]},"sequenceEnd":1613277184493},"subject":"trade.l2update","topic":"/market/level2:BCHSV-USDT","type":"message"}
1619378334.454508: {"data":{"sequenceStart":1613277184494,"symbol":"BCHSV-USDT","changes":{"asks":[],"bids":[["0","0","1613277184494"]]},"sequenceEnd":1613277184494},"subject":"trade.l2update","topic":"/market/level2:BCHSV-USDT","type":"message"}
1619378334.454543: {"data":{"sequenceStart":1613277184495,"symbol":"BCHSV-USDT","changes":{"asks":[],"bids":[["240.239","2.08126072","1613277184495"]]},"sequenceEnd":1613277184495},"subject":"trade.l2update","topic":"/market/level2:BCHSV-USDT","type":"message"}
1619378334.468308: {"data":{"sequence":"1613277184495","bestAsk":"242.901","size":"0.08000012","bestBidSize":"5","price":"243.65","time":1619378334433,"bestAskSize":"4.51280965","bestBid":"242.577"},"subject":"trade.ticker","topic":"/market/ticker:BCHSV-USDT","type":"message"}
1619378334.53632: {"data":{"sequenceStart":1612734157806,"symbol":"ANKR-BTC","changes":{"asks":[],"bids":[["0.0000025951","0","1612734157806"]]},"sequenceEnd":1612734157806},"subject":"trade.l2update","topic":"/market/level2:ANKR-BTC","type":"message"}
1619378334.546231: {"data":{"sequenceStart":1612844051876,"symbol":"SNX-BTC","changes":{"asks":[["0.00028749","0","1612844051876"]],"bids":[]},"sequenceEnd":1612844051876},"subject":"trade.l2update","topic":"/market/level2:SNX-BTC","type":"message"}
1619378334.5519638: {"data":{"sequenceStart":1612734157807,"symbol":"ANKR-BTC","changes":{"asks":[],"bids":[["0","0","1612734157807"]]},"sequenceEnd":1612734157807},"subject":"trade.l2update","topic":"/market/level2:ANKR-BTC","type":"message"}
1619378334.5520809: {"data":{"sequenceStart":1612734157808,"symbol":"ANKR-BTC","changes":{"asks":[],"bids":[["0.0000025957","20000","1612734157808"]]},"sequenceEnd":1612734157808},"subject":"trade.l2update","topic":"/market/level2:ANKR-BTC","type":"message"}
1619378334.557077: {"data":{"sequenceStart":1613277184496,"symbol":"BCHSV-USDT","changes":{"asks":[],"bids":[["242.577","0","1613277184496"]]},"sequenceEnd":1613277184496},"subject":"trade.l2update","topic":"/market/level2:BCHSV-USDT","type":"message"}
1619378334.55722: {"data":{"sequence":"1612844051876","bestAsk":"0.00028708","size":"0.01745248","bestBidSize":"0.19100065","price":"0.00028676","time":1619378334523,"bestAskSize":"29.24570683","bestBid":"0.00028678"},"subject":"trade.ticker","topic":"/market/ticker:SNX-BTC","type":"message"}
1619378334.566624: {"data":{"sequence":"1613277184496","bestAsk":"242.901","size":"0.08000012","bestBidSize":"0.68148185","price":"243.65","time":1619378334530,"bestAskSize":"4.51280965","bestBid":"242.575"},"subject":"trade.ticker","topic":"/market/ticker:BCHSV-USDT","type":"message"}
1619378334.581857: {"data":{"sequenceStart":1613277184497,"symbol":"BCHSV-USDT","changes":{"asks":[],"bids":[["0","0","1613277184497"]]},"sequenceEnd":1613277184497},"subject":"trade.l2update","topic":"/market/level2:BCHSV-USDT","type":"message"}
1619378334.5819688: {"data":{"sequenceStart":1613277184498,"symbol":"BCHSV-USDT","changes":{"asks":[],"bids":[["242.579","5","1613277184498"]]},"sequenceEnd":1613277184498},"subject":"trade.l2update","topic":"/market/level2:BCHSV-USDT","type":"message"}
1619378334.592258: {"data":{"sequenceStart":1619079123942,"symbol":"EQZ-BTC","changes":{"asks":[],"bids":[["0","0","1619079123942"]]},"sequenceEnd":1619079123942},"subject":"trade.l2update","topic":"/market/level2:EQZ-BTC","type":"message"}
1619378334.5923688: {"data":{"sequenceStart":1619079123943,"symbol":"EQZ-BTC","changes":{"asks":[],"bids":[["0.0000237","267.7699","1619079123943"]]},"sequenceEnd":1619079123943},"subject":"trade.l2update","topic":"/market/level2:EQZ-BTC","type":"message"}
1619378334.5974898: {"data":{"sequenceStart":1613277184499,"symbol":"BCHSV-USDT","changes":{"asks":[],"bids":[["242.575","0","1613277184499"]]},"sequenceEnd":1613277184499},"subject":"trade.l2update","topic":"/market/level2:BCHSV-USDT","type":"message"}
1619378334.597635: {"data":{"sequenceStart":1613277184500,"symbol":"BCHSV-USDT","changes":{"asks":[["243.249","0","1613277184500"]],"bids":[]},"sequenceEnd":1613277184500},"subject":"trade.l2update","topic":"/market/level2:BCHSV-USDT","type":"message"}
1619378334.6178792: {"data":{"sequenceStart":1613277184501,"symbol":"BCHSV-USDT","changes":{"asks":[],"bids":[["0","0","1613277184501"]]},"sequenceEnd":1613277184501},"subject":"trade.l2update","topic":"/market/level2:BCHSV-USDT","type":"message"}
1619378334.623596: {"data":{"sequenceStart":1613277184502,"symbol":"BCHSV-USDT","changes":{"asks":[],"bids":[["242.578","0.68148185","1613277184502"]]},"sequenceEnd":1613277184502},"subject":"trade.l2update","topic":"/market/level2:BCHSV-USDT","type":"message"}
1619378334.6237319: {"data":{"sequenceStart":1613277184503,"symbol":"BCHSV-USDT","changes":{"asks":[["0","0","1613277184503"]],"bids":[]},"sequenceEnd":1613277184503},"subject":"trade.l2update","topic":"/market/level2:BCHSV-USDT","type":"message"}
1619378334.6237838: {"data":{"sequenceStart":1613277184504,"symbol":"BCHSV-USDT","changes":{"asks":[["243.245","0.6","1613277184504"]],"bids":[]},"sequenceEnd":1613277184504},"subject":"trade.l2update","topic":"/market/level2:BCHSV-USDT","type":"message"}
1619378334.623842: {"data":{"sequence":"1612734157808","bestAsk":"0.0000026208","size":"46","bestBidSize":"5127.1098","price":"0.0000026071","time":1619378334588,"bestAskSize":"10987.6265","bestBid":"0.0000025989"},"subject":"trade.ticker","topic":"/market/ticker:ANKR-BTC","type":"message"}
1619378334.6598458: {"data":{"sequenceStart":1612844051877,"symbol":"SNX-BTC","changes":{"asks":[["0","0","1612844051877"]],"bids":[]},"sequenceEnd":1612844051877},"subject":"trade.l2update","topic":"/market/level2:SNX-BTC","type":"message"}
1619378334.6599538: {"data":{"sequenceStart":1612844051878,"symbol":"SNX-BTC","changes":{"asks":[["0.00028713","256.50243154","1612844051878"]],"bids":[]},"sequenceEnd":1612844051878},"subject":"trade.l2update","topic":"/market/level2:SNX-BTC","type":"message"}
1619378334.669356: {"data":{"sequenceStart":1613277184505,"symbol":"BCHSV-USDT","changes":{"asks":[],"bids":[["242.579","0","1613277184505"]]},"sequenceEnd":1613277184505},"subject":"trade.l2update","topic":"/market/level2:BCHSV-USDT","type":"message"}
1619378334.674011: {"data":{"sequence":"1613277184505","bestAsk":"242.901","size":"0.08000012","bestBidSize":"0.68148185","price":"243.65","time":1619378334633,"bestAskSize":"4.51280965","bestBid":"242.578"},"subject":"trade.ticker","topic":"/market/ticker:BCHSV-USDT","type":"message"}
1619378334.674103: {"data":{"sequenceStart":1613277184506,"symbol":"BCHSV-USDT","changes":{"asks":[],"bids":[["0","0","1613277184506"]]},"sequenceEnd":1613277184506},"subject":"trade.l2update","topic":"/market/level2:BCHSV-USDT","type":"message"}
1619378334.674169: {"data":{"sequenceStart":1613277184507,"symbol":"BCHSV-USDT","changes":{"asks":[],"bids":[["242.58","5","1613277184507"]]},"sequenceEnd":1613277184507},"subject":"trade.l2update","topic":"/market/level2:BCHSV-USDT","type":"message"}
1619378334.678245: {"data":{"sequence":"1619079123943","bestAsk":"0.00002395","size":"0.375","bestBidSize":"20.5373","price":"0.00002383","time":1619378334638,"bestAskSize":"72.1515","bestBid":"0.00002383"},"subject":"trade.ticker","topic":"/market/ticker:EQZ-BTC","type":"message"}
1619378334.749931: {"data":{"sequenceStart":1612712745650,"symbol":"FET-BTC","changes":{"asks":[["0.00000794","0","1612712745650"]],"bids":[]},"sequenceEnd":1612712745650},"subject":"trade.l2update","topic":"/market/level2:FET-BTC","type":"message"}
1619378334.7628102: {"data":{"sequence":"1613277184507","bestAsk":"242.901","size":"0.08000012","bestBidSize":"5","price":"243.65","time":1619378334730,"bestAskSize":"4.51280965","bestBid":"242.58"},"subject":"trade.ticker","topic":"/market/ticker:BCHSV-USDT","type":"message"}
1619378334.808428: {"data":{"sequenceStart":1613277184508,"symbol":"BCHSV-USDT","changes":{"asks":[],"bids":[["242.58","0","1613277184508"]]},"sequenceEnd":1613277184508},"subject":"trade.l2update","topic":"/market/level2:BCHSV-USDT","type":"message"}
1619378334.8141692: {"data":{"sequenceStart":1613277184509,"symbol":"BCHSV-USDT","changes":{"asks":[],"bids":[["0","0","1613277184509"]]},"sequenceEnd":1613277184509},"subject":"trade.l2update","topic":"/market/level2:BCHSV-USDT","type":"message"}
1619378334.814255: {"data":{"sequenceStart":1613277184510,"symbol":"BCHSV-USDT","changes":{"asks":[],"bids":[["242.582","5","1613277184510"]]},"sequenceEnd":1613277184510},"subject":"trade.l2update","topic":"/market/level2:BCHSV-USDT","type":"message"}
1619378334.814307: {"data":{"sequence":"1612844051878","bestAsk":"0.00028708","size":"0.01745248","bestBidSize":"0.19100065","price":"0.00028676","time":1619378334747,"bestAskSize":"29.24570683","bestBid":"0.00028678"},"subject":"trade.ticker","topic":"/market/ticker:SNX-BTC","type":"message"}
1619378334.8216069: {"data":{"sequenceStart":1613277184511,"symbol":"BCHSV-USDT","changes":{"asks":[],"bids":[["240.415","0","1613277184511"]]},"sequenceEnd":1613277184511},"subject":"trade.l2update","topic":"/market/level2:BCHSV-USDT","type":"message"}
1619378334.8217459: {"data":{"sequenceStart":1613277184512,"symbol":"BCHSV-USDT","changes":{"asks":[],"bids":[["242.578","0","1613277184512"]]},"sequenceEnd":1613277184512},"subject":"trade.l2update","topic":"/market/level2:BCHSV-USDT","type":"message"}
1619378334.821816: {"data":{"sequenceStart":1613277184513,"symbol":"BCHSV-USDT","changes":{"asks":[["243.245","0","1613277184513"]],"bids":[]},"sequenceEnd":1613277184513},"subject":"trade.l2update","topic":"/market/level2:BCHSV-USDT","type":"message"}
1619378334.828786: {"data":{"sequenceStart":1613277184514,"symbol":"BCHSV-USDT","changes":{"asks":[["0","0","1613277184514"]],"bids":[]},"sequenceEnd":1613277184514},"subject":"trade.l2update","topic":"/market/level2:BCHSV-USDT","type":"message"}
1619378334.828892: {"data":{"sequenceStart":1613277184515,"symbol":"BCHSV-USDT","changes":{"asks":[["243.248","0.6","1613277184515"]],"bids":[]},"sequenceEnd":1613277184515},"subject":"trade.l2update","topic":"/market/level2:BCHSV-USDT","type":"message"}
1619378334.828941: {"data":{"sequenceStart":1613277184516,"symbol":"BCHSV-USDT","changes":{"asks":[],"bids":[["0","0","1613277184516"]]},"sequenceEnd":1613277184516},"subject":"trade.l2update","topic":"/market/level2:BCHSV-USDT","type":"message"}
1619378334.828969: {"data":{"sequenceStart":1613277184517,"symbol":"BCHSV-USDT","changes":{"asks":[],"bids":[["242.579","0.68148185","1613277184517"]]},"sequenceEnd":1613277184517},"subject":"trade.l2update","topic":"/market/level2:BCHSV-USDT","type":"message"}
1619378334.829003: {"data":{"sequenceStart":1612734157809,"symbol":"ANKR-BTC","changes":{"asks":[],"bids":[["0","0","1612734157809"]]},"sequenceEnd":1612734157809},"subject":"trade.l2update","topic":"/market/level2:ANKR-BTC","type":"message"}
1619378334.8342242: {"data":{"sequenceStart":1612734157810,"symbol":"ANKR-BTC","changes":{"asks":[],"bids":[["0.000002599","3498.7974","1612734157810"]]},"sequenceEnd":1612734157810},"subject":"trade.l2update","topic":"/market/level2:ANKR-BTC","type":"message"}
1619378334.84802: {"data":{"sequence":"1612712745650","bestAsk":"0.00000775","size":"401.2004","bestBidSize":"357.285","price":"0.00000772","time":1619378334767,"bestAskSize":"1154.0416","bestBid":"0.00000771"},"subject":"trade.ticker","topic":"/market/ticker:FET-BTC","type":"message"}
1619378334.848112: {"data":{"sequenceStart":1612844051879,"symbol":"SNX-BTC","changes":{"asks":[],"bids":[["0","0","1612844051879"]]},"sequenceEnd":1612844051879},"subject":"trade.l2update","topic":"/market/level2:SNX-BTC","type":"message"}
1619378334.848182: {"data":{"sequenceStart":1612844051880,"symbol":"SNX-BTC","changes":{"asks":[],"bids":[["0.00028645","14.07490809","1612844051880"]]},"sequenceEnd":1612844051880},"subject":"trade.l2update","topic":"/market/level2:SNX-BTC","type":"message"}
1619378334.848254: {"data":{"sequenceStart":1612844051881,"symbol":"SNX-BTC","changes":{"asks":[],"bids":[["0","0","1612844051881"]]},"sequenceEnd":1612844051881},"subject":"trade.l2update","topic":"/market/level2:SNX-BTC","type":"message"}
1619378334.848309: {"data":{"sequenceStart":1612844051882,"symbol":"SNX-BTC","changes":{"asks":[],"bids":[["0.00028616","14.11707112","1612844051882"]]},"sequenceEnd":1612844051882},"subject":"trade.l2update","topic":"/market/level2:SNX-BTC","type":"message"}
1619378334.84834: {"data":{"sequenceStart":1613277184518,"symbol":"BCHSV-USDT","changes":{"asks":[],"bids":[["241.515","0","1613277184518"]]},"sequenceEnd":1613277184518},"subject":"trade.l2update","topic":"/market/level2:BCHSV-USDT","type":"message"}
1619378334.848379: {"data":{"sequenceStart":1613277184519,"symbol":"BCHSV-USDT","changes":{"asks":[["243.675","0","1613277184519"]],"bids":[]},"sequenceEnd":1613277184519},"subject":"trade.l2update","topic":"/market/level2:BCHSV-USDT","type":"message"}
1619378334.848415: {"data":{"sequenceStart":1613277184520,"symbol":"BCHSV-USDT","changes":{"asks":[["244.312","0","1613277184520"]],"bids":[]},"sequenceEnd":1613277184520},"subject":"trade.l2update","topic":"/market/level2:BCHSV-USDT","type":"message"}
1619378334.8521469: {"data":{"sequenceStart":1612844051883,"symbol":"SNX-BTC","changes":{"asks":[["0.00028708","0","1612844051883"]],"bids":[]},"sequenceEnd":1612844051883},"subject":"trade.l2update","topic":"/market/level2:SNX-BTC","type":"message"}
1619378334.865655: {"data":{"sequenceStart":1612734157811,"symbol":"ANKR-BTC","changes":{"asks":[],"bids":[["0.0000025989","0","1612734157811"]]},"sequenceEnd":1612734157811},"subject":"trade.l2update","topic":"/market/level2:ANKR-BTC","type":"message"}
1619378334.8658: {"data":{"sequenceStart":1612734157812,"symbol":"ANKR-BTC","changes":{"asks":[],"bids":[["0.000002599","0","1612734157812"]]},"sequenceEnd":1612734157812},"subject":"trade.l2update","topic":"/market/level2:ANKR-BTC","type":"message"}
1619378334.880894: {"data":{"sequence":"1613277184520","bestAsk":"242.901","size":"0.08000012","bestBidSize":"5","price":"243.65","time":1619378334830,"bestAskSize":"4.51280965","bestBid":"242.582"},"subject":"trade.ticker","topic":"/market/ticker:BCHSV-USDT","type":"message"}
1619378334.885865: {"data":{"sequence":"1612844051884","bestAsk":"0.00028711","size":"0.01745248","bestBidSize":"0.19100065","price":"0.00028676","time":1619378334849,"bestAskSize":"14.04664884","bestBid":"0.00028678"},"subject":"trade.ticker","topic":"/market/ticker:SNX-BTC","type":"message"}
1619378334.897988: {"data":{"sequenceStart":1613277184521,"symbol":"BCHSV-USDT","changes":{"asks":[["246.421","0","1613277184521"]],"bids":[]},"sequenceEnd":1613277184521},"subject":"trade.l2update","topic":"/market/level2:BCHSV-USDT","type":"message"}
1619378334.9028149: {"data":{"sequenceStart":1612734157813,"symbol":"ANKR-BTC","changes":{"asks":[],"bids":[["0","0","1612734157813"]]},"sequenceEnd":1612734157813},"subject":"trade.l2update","topic":"/market/level2:ANKR-BTC","type":"message"}
1619378334.902866: {"data":{"sequenceStart":1612734157814,"symbol":"ANKR-BTC","changes":{"asks":[],"bids":[["0.0000025991","5034.7285","1612734157814"]]},"sequenceEnd":1612734157814},"subject":"trade.l2update","topic":"/market/level2:ANKR-BTC","type":"message"}
1619378334.905642: {"data":{"sequenceStart":1612844051884,"symbol":"SNX-BTC","changes":{"asks":[],"bids":[["0.00028616","0","1612844051884"]]},"sequenceEnd":1612844051884},"subject":"trade.l2update","topic":"/market/level2:SNX-BTC","type":"message"}
1619378334.905717: {"data":{"sequenceStart":1612844051885,"symbol":"SNX-BTC","changes":{"asks":[["0.00028713","0","1612844051885"]],"bids":[]},"sequenceEnd":1612844051885},"subject":"trade.l2update","topic":"/market/level2:SNX-BTC","type":"message"}
1619378334.905765: {"data":{"sequenceStart":1612844051886,"symbol":"SNX-BTC","changes":{"asks":[],"bids":[["0.00028645","0","1612844051886"]]},"sequenceEnd":1612844051886},"subject":"trade.l2update","topic":"/market/level2:SNX-BTC","type":"message"}
1619378334.913433: {"data":{"sequenceStart":1612844051887,"symbol":"SNX-BTC","changes":{"asks":[["0","0","1612844051887"]],"bids":[]},"sequenceEnd":1612844051887},"subject":"trade.l2update","topic":"/market/level2:SNX-BTC","type":"message"}
1619378334.913541: {"data":{"sequenceStart":1612844051888,"symbol":"SNX-BTC","changes":{"asks":[["0.00028711","43.29235567","1612844051888"]],"bids":[]},"sequenceEnd":1612844051888},"subject":"trade.l2update","topic":"/market/level2:SNX-BTC","type":"message"}
1619378334.9136052: {"data":{"sequenceStart":1612702190329,"symbol":"NRG-BTC","changes":{"asks":[["0.00006228","0","1612702190329"]],"bids":[]},"sequenceEnd":1612702190329},"subject":"trade.l2update","topic":"/market/level2:NRG-BTC","type":"message"}
1619378334.913676: {"data":{"sequenceStart":1613277184522,"symbol":"BCHSV-USDT","changes":{"asks":[["243.248","0","1613277184522"]],"bids":[]},"sequenceEnd":1613277184522},"subject":"trade.l2update","topic":"/market/level2:BCHSV-USDT","type":"message"}
1619378334.917613: {"data":{"sequenceStart":1612699351258,"symbol":"COV-BTC","changes":{"asks":[],"bids":[["0","0","1612699351258"]]},"sequenceEnd":1612699351258},"subject":"trade.l2update","topic":"/market/level2:COV-BTC","type":"message"}
1619378334.917721: {"data":{"sequenceStart":1612699351259,"symbol":"COV-BTC","changes":{"asks":[],"bids":[["0.00001095","188.4121","1612699351259"]]},"sequenceEnd":1612699351259},"subject":"trade.l2update","topic":"/market/level2:COV-BTC","type":"message"}
1619378334.917802: {"data":{"sequenceStart":1613277184523,"symbol":"BCHSV-USDT","changes":{"asks":[],"bids":[["0","0","1613277184523"]]},"sequenceEnd":1613277184523},"subject":"trade.l2update","topic":"/market/level2:BCHSV-USDT","type":"message"}
