1619378334.91783: {"data":{"sequenceStart":1613277184524,"symbol":"BCHSV-USDT","changes":{"asks":[],"bids":[["240.315","25","1613277184524"]]},"sequenceEnd":1613277184524},"subject":"trade.l2update","topic":"/market/level2:BCHSV-USDT","type":"message"}
1619378334.917869: {"data":{"sequenceStart":1612734157815,"symbol":"ANKR-BTC","changes":{"asks":[],"bids":[["0","0","1612734157815"]]},"sequenceEnd":1612734157815},"subject":"trade.l2update","topic":"/market/level2:ANKR-BTC","type":"message"}
1619378334.9178932: {"data":{"sequenceStart":1612734157816,"symbol":"ANKR-BTC","changes":{"asks":[],"bids":[["0.0000025958","3498.7981","1612734157816"]]},"sequenceEnd":1612734157816},"subject":"trade.l2update","topic":"/market/level2:ANKR-BTC","type":"message"}
1619378334.9296021: {"data":{"sequenceStart":1613277184525,"symbol":"BCHSV-USDT","changes":{"asks":[],"bids":[["242.579","0","1613277184525"]]},"sequenceEnd":1613277184525},"subject":"trade.l2update","topic":"/market/level2:BCHSV-USDT","type":"message"}
1619378334.929697: {"data":{"sequenceStart":1613277184526,"symbol":"BCHSV-USDT","changes":{"asks":[],"bids":[["0","0","1613277184526"]]},"sequenceEnd":1613277184526},"subject":"trade.l2update","topic":"/market/level2:BCHSV-USDT","type":"message"}
1619378334.929733: {"data":{"sequenceStart":1613277184527,"symbol":"BCHSV-USDT","changes":{"asks":[],"bids":[["242.583","0.05000051","1613277184527"]]},"sequenceEnd":1613277184527},"subject":"trade.l2update","topic":"/market/level2:BCHSV-USDT","type":"message"}
1619378334.929771: {"data":{"sequence":"1612699351259","bestAsk":"0.00001126","size":"96.1525","bestBidSize":"49.6422","price":"0.00001126","time":1619378334888,"bestAskSize":"137.9035","bestBid":"0.00001121"},"subject":"trade.ticker","topic":"/market/ticker:COV-BTC","type":"message"}
1619378334.9297972: {"data":{"sequence":"1612734157816","bestAsk":"0.0000026208","size":"46","bestBidSize":"5034.7285","price":"0.0000026071","time":1619378334888,"bestAskSize":"10987.6265","bestBid":"0.0000025991"},"subject":"trade.ticker","topic":"/market/ticker:ANKR-BTC","type":"message"}
1619378334.9347389: {"data":{"sequence":"1612702190329","bestAsk":"0.00006218","size":"0.0431","bestBidSize":"19.5017","price":"0.00006141","time":1619378334891,"bestAskSize":"43.3399","bestBid":"0.00006141"},"subject":"trade.ticker","topic":"/market/ticker:NRG-BTC","type":"message"}
1619378334.9348009: {"data":{"sequenceStart":1613277184528,"symbol":"BCHSV-USDT","changes":{"asks":[],"bids":[["0","0","1613277184528"]]},"sequenceEnd":1613277184528},"subject":"trade.l2update","topic":"/market/level2:BCHSV-USDT","type":"message"}
1619378334.934844: {"data":{"sequenceStart":1613277184529,"symbol":"BCHSV-USDT","changes":{"asks":[],"bids":[["242.591","0.68148185","1613277184529"]]},"sequenceEnd":1613277184529},"subject":"trade.l2update","topic":"/market/level2:BCHSV-USDT","type":"message"}
1619378334.93489: {"data":{"sequenceStart":1613277184530,"symbol":"BCHSV-USDT","changes":{"asks":[["0","0","1613277184530"]],"bids":[]},"sequenceEnd":1613277184530},"subject":"trade.l2update","topic":"/market/level2:BCHSV-USDT","type":"message"}
1619378334.9349172: {"data":{"sequenceStart":1613277184531,"symbol":"BCHSV-USDT","changes":{"asks":[["243.247","0.6","1613277184531"]],"bids":[]},"sequenceEnd":1613277184531},"subject":"trade.l2update","topic":"/market/level2:BCHSV-USDT","type":"message"}
1619378334.943518: {"data":{"sequenceStart":1612734157817,"symbol":"ANKR-BTC","changes":{"asks":[],"bids":[["0.0000025958","0","1612734157817"]]},"sequenceEnd":1612734157817},"subject":"trade.l2update","topic":"/market/level2:ANKR-BTC","type":"message"}
1619378334.9843872: {"data":{"sequenceStart":1613277184532,"symbol":"BCHSV-USDT","changes":{"asks":[],"bids":[["242.5","0","1613277184532"]]},"sequenceEnd":1613277184532},"subject":"trade.l2update","topic":"/market/level2:BCHSV-USDT","type":"message"}
1619378334.9902542: {"data":{"sequenceStart":1613277184533,"symbol":"BCHSV-USDT","changes":{"asks":[["0","0","1613277184533"]],"bids":[]},"sequenceEnd":1613277184533},"subject":"trade.l2update","topic":"/market/level2:BCHSV-USDT","type":"message"}
1619378334.990363: {"data":{"sequenceStart":1613277184534,"symbol":"BCHSV-USDT","changes":{"asks":[["247.395","37.271","1613277184534"]],"bids":[]},"sequenceEnd":1613277184534},"subject":"trade.l2update","topic":"/market/level2:BCHSV-USDT","type":"message"}
1619378334.990444: {"data":{"sequenceStart":1613277184535,"symbol":"BCHSV-USDT","changes":{"asks":[],"bids":[["242.582","0","1613277184535"]]},"sequenceEnd":1613277184535},"subject":"trade.l2update","topic":"/market/level2:BCHSV-USDT","type":"message"}
1619378334.9905112: {"data":{"sequence":"1613277184535","bestAsk":"242.901","size":"0.08000012","bestBidSize":"0.68148185","price":"243.65","time":1619378334934,"bestAskSize":"4.51280965","bestBid":"242.591"},"subject":"trade.ticker","topic":"/market/ticker:BCHSV-USDT","type":"message"}
1619378334.990551: {"data":{"sequence":"1612844051888","bestAsk":"0.00028711","size":"0.01745248","bestBidSize":"0.19100065","price":"0.00028676","time":1619378334948,"bestAskSize":"43.29235567","bestBid":"0.00028678"},"subject":"trade.ticker","topic":"/market/ticker:SNX-BTC","type":"message"}
1619378334.997698: {"data":{"sequenceStart":1613277184536,"symbol":"BCHSV-USDT","changes":{"asks":[],"bids":[["0","0","1613277184536"]]},"sequenceEnd":1613277184536},"subject":"trade.l2update","topic":"/market/level2:BCHSV-USDT","type":"message"}
1619378334.997825: {"data":{"sequenceStart":1613277184537,"symbol":"BCHSV-USDT","changes":{"asks":[],"bids":[["242.596","5","1613277184537"]]},"sequenceEnd":1613277184537},"subject":"trade.l2update","topic":"/market/level2:BCHSV-USDT","type":"message"}
1619378334.997906: {"data":{"sequenceStart":1612712745651,"symbol":"FET-BTC","changes":{"asks":[["0","0","1612712745651"]],"bids":[]},"sequenceEnd":1612712745651},"subject":"trade.l2update","topic":"/market/level2:FET-BTC","type":"message"}
1619378334.9979498: {"data":{"sequenceStart":1612712745652,"symbol":"FET-BTC","changes":{"asks":[["0.00000791","3244.6375","1612712745652"]],"bids":[]},"sequenceEnd":1612712745652},"subject":"trade.l2update","topic":"/market/level2:FET-BTC","type":"message"}
1619378335.00593: {"data":{"sequenceStart":1612702190330,"symbol":"NRG-BTC","changes":{"asks":[["0","0","1612702190330"]],"bids":[]},"sequenceEnd":1612702190330},"subject":"trade.l2update","topic":"/market/level2:NRG-BTC","type":"message"}
1619378335.006006: {"data":{"sequenceStart":1612702190331,"symbol":"NRG-BTC","changes":{"asks":[["0.00006229","13.679","1612702190331"]],"bids":[]},"sequenceEnd":1612702190331},"subject":"trade.l2update","topic":"/market/level2:NRG-BTC","type":"message"}
1619378335.006062: {"data":{"sequenceStart":1612699351260,"symbol":"COV-BTC","changes":{"asks":[],"bids":[["0.00001093","10","1612699351260"]]},"sequenceEnd":1612699351260},"subject":"trade.l2update","topic":"/market/level2:COV-BTC","type":"message"}
1619378335.006094: {"data":{"sequenceStart":1612844051889,"symbol":"SNX-BTC","changes":{"asks":[["0.00028711","29.24570683","1612844051889"]],"bids":[]},"sequenceEnd":1612844051889},"subject":"trade.l2update","topic":"/market/level2:SNX-BTC","type":"message"}
1619378335.010206: {"data":{"sequence":"1612712745652","bestAsk":"0.00000775","size":"401.2004","bestBidSize":"357.285","price":"0.00000772","time":1619378334967,"bestAskSize":"1154.0416","bestBid":"0.00000771"},"subject":"trade.ticker","topic":"/market/ticker:FET-BTC","type":"message"}
1619378335.0168269: {"data":{"sequenceStart":1612844051890,"symbol":"SNX-BTC","changes":{"asks":[],"bids":[["0","0","1612844051890"]]},"sequenceEnd":1612844051890},"subject":"trade.l2update","topic":"/market/level2:SNX-BTC","type":"message"}
1619378335.016871: {"data":{"sequenceStart":1612844051891,"symbol":"SNX-BTC","changes":{"asks":[],"bids":[["0.00028644","14.07539946","1612844051891"]]},"sequenceEnd":1612844051891},"subject":"trade.l2update","topic":"/market/level2:SNX-BTC","type":"message"}
1619378335.01691: {"data":{"sequenceStart":1612844051892,"symbol":"SNX-BTC","changes":{"asks":[],"bids":[["0","0","1612844051892"]]},"sequenceEnd":1612844051892},"subject":"trade.l2update","topic":"/market/level2:SNX-BTC","type":"message"}
1619378335.016932: {"data":{"sequenceStart":1612844051893,"symbol":"SNX-BTC","changes":{"asks":[],"bids":[["0.00028616","14.11707112","1612844051893"]]},"sequenceEnd":1612844051893},"subject":"trade.l2update","topic":"/market/level2:SNX-BTC","type":"message"}
1619378335.016958: {"data":{"sequenceStart":1612844051894,"symbol":"SNX-BTC","changes":{"asks":[["0","0","1612844051894"]],"bids":[]},"sequenceEnd":1612844051894},"subject":"trade.l2update","topic":"/market/level2:SNX-BTC","type":"message"}
1619378335.0169768: {"data":{"sequenceStart":1612844051895,"symbol":"SNX-BTC","changes":{"asks":[["0.00028737","14.03939979","1612844051895"]],"bids":[]},"sequenceEnd":1612844051895},"subject":"trade.l2update","topic":"/market/level2:SNX-BTC","type":"message"}
1619378335.032778: {"data":{"sequence":"1612699351260","bestAsk":"0.00001126","size":"96.1525","bestBidSize":"49.6422","price":"0.00001126","time":1619378334988,"bestAskSize":"137.9035","bestBid":"0.00001121"},"subject":"trade.ticker","topic":"/market/ticker:COV-BTC","type":"message"}
1619378335.0328698: {"data":{"sequence":"1612734157817","bestAsk":"0.0000026208","size":"46","bestBidSize":"5034.7285","price":"0.0000026071","time":1619378334988,"bestAskSize":"10987.6265","bestBid":"0.0000025991"},"subject":"trade.ticker","topic":"/market/ticker:ANKR-BTC","type":"message"}
1619378335.0329118: {"data":{"sequenceStart":1613277184538,"symbol":"BCHSV-USDT","changes":{"asks":[],"bids":[["0","0","1613277184538"]]},"sequenceEnd":1613277184538},"subject":"trade.l2update","topic":"/market/level2:BCHSV-USDT","type":"message"}
1619378335.0329769: {"data":{"sequenceStart":1613277184539,"symbol":"BCHSV-USDT","changes":{"asks":[],"bids":[["242.584","0.45082023","1613277184539"]]},"sequenceEnd":1613277184539},"subject":"trade.l2update","topic":"/market/level2:BCHSV-USDT","type":"message"}
1619378335.033092: {"data":{"sequenceStart":1612734157818,"symbol":"ANKR-BTC","changes":{"asks":[],"bids":[["0","0","1612734157818"]]},"sequenceEnd":1612734157818},"subject":"trade.l2update","topic":"/market/level2:ANKR-BTC","type":"message"}
1619378335.033119: {"data":{"sequenceStart":1612734157819,"symbol":"ANKR-BTC","changes":{"asks":[],"bids":[["0.0000025992","3498.932","1612734157819"]]},"sequenceEnd":1612734157819},"subject":"trade.l2update","topic":"/market/level2:ANKR-BTC","type":"message"}
1619378335.037846: {"data":{"sequence":"1612702190331","bestAsk":"0.00006218","size":"0.0431","bestBidSize":"19.5017","price":"0.00006141","time":1619378334991,"bestAskSize":"43.3399","bestBid":"0.00006141"},"subject":"trade.ticker","topic":"/market/ticker:NRG-BTC","type":"message"}
1619378335.047668: {"data":{"sequenceStart":1612734157820,"symbol":"ANKR-BTC","changes":{"asks":[],"bids":[["0.0000025991","0","1612734157820"]]},"sequenceEnd":1612734157820},"subject":"trade.l2update","topic":"/market/level2:ANKR-BTC","type":"message"}
1619378335.0582411: {"data":{"sequenceStart":1612844051896,"symbol":"SNX-BTC","changes":{"asks":[["0","0","1612844051896"]],"bids":[]},"sequenceEnd":1612844051896},"subject":"trade.l2update","topic":"/market/level2:SNX-BTC","type":"message"}
1619378335.0583198: {"data":{"sequenceStart":1612844051897,"symbol":"SNX-BTC","changes":{"asks":[["0.0002871","14.04274325","1612844051897"]],"bids":[]},"sequenceEnd":1612844051897},"subject":"trade.l2update","topic":"/market/level2:SNX-BTC","type":"message"}
1619378335.058375: {"data":{"sequenceStart":1612844051898,"symbol":"SNX-BTC","changes":{"asks":[["0.00028737","0.01376935","1612844051898"]],"bids":[]},"sequenceEnd":1612844051898},"subject":"trade.l2update","topic":"/market/level2:SNX-BTC","type":"message"}
1619378335.0584152: {"data":{"sequenceStart":1612844051899,"symbol":"SNX-BTC","changes":{"asks":[],"bids":[["0.00028616","0","1612844051899"]]},"sequenceEnd":1612844051899},"subject":"trade.l2update","topic":"/market/level2:SNX-BTC","type":"message"}
1619378335.0584562: {"data":{"sequence":"1612844051899","bestAsk":"0.0002871","size":"0.01745248","bestBidSize":"0.19100065","price":"0.00028676","time":1619378335023,"bestAskSize":"14.04274325","bestBid":"0.00028678"},"subject":"trade.ticker","topic":"/market/ticker:SNX-BTC","type":"message"}
1619378335.064523: {"data":{"sequenceStart":1612712745653,"symbol":"FET-BTC","changes":{"asks":[],"bids":[["0","0","1612712745653"]]},"sequenceEnd":1612712745653},"subject":"trade.l2update","topic":"/market/level2:FET-BTC","type":"message"}
1619378335.0646012: {"data":{"sequenceStart":1612712745654,"symbol":"FET-BTC","changes":{"asks":[],"bids":[["0.00000767","351.2908","1612712745654"]]},"sequenceEnd":1612712745654},"subject":"trade.l2update","topic":"/market/level2:FET-BTC","type":"message"}
1619378335.0646431: {"data":{"sequenceStart":1613277184540,"symbol":"BCHSV-USDT","changes":{"asks":[],"bids":[["242.596","0","1613277184540"]]},"sequenceEnd":1613277184540},"subject":"trade.l2update","topic":"/market/level2:BCHSV-USDT","type":"message"}
1619378335.082975: {"data":{"sequence":"1613277184540","bestAsk":"242.901","size":"0.08000012","bestBidSize":"0.68148185","price":"243.65","time":1619378335034,"bestAskSize":"4.51280965","bestBid":"242.591"},"subject":"trade.ticker","topic":"/market/ticker:BCHSV-USDT","type":"message"}
1619378335.083068: {"data":{"sequenceStart":1612734157821,"symbol":"ANKR-BTC","changes":{"asks":[],"bids":[["0.0000025957","0","1612734157821"]]},"sequenceEnd":1612734157821},"subject":"trade.l2update","topic":"/market/level2:ANKR-BTC","type":"message"}
1619378335.0872488: {"data":{"sequenceStart":1613277184541,"symbol":"BCHSV-USDT","changes":{"asks":[],"bids":[["0","0","1613277184541"]]},"sequenceEnd":1613277184541},"subject":"trade.l2update","topic":"/market/level2:BCHSV-USDT","type":"message"}
1619378335.087363: {"data":{"sequenceStart":1613277184542,"symbol":"BCHSV-USDT","changes":{"asks":[],"bids":[["242.607","5","1613277184542"]]},"sequenceEnd":1613277184542},"subject":"trade.l2update","topic":"/market/level2:BCHSV-USDT","type":"message"}
1619378335.0925062: {"data":{"sequenceStart":1612734157822,"symbol":"ANKR-BTC","changes":{"asks":[],"bids":[["0","0","1612734157822"]]},"sequenceEnd":1612734157822},"subject":"trade.l2update","topic":"/market/level2:ANKR-BTC","type":"message"}
1619378335.092619: {"data":{"sequenceStart":1612734157823,"symbol":"ANKR-BTC","changes":{"asks":[],"bids":[["0.0000025993","5034.7285","1612734157823"]]},"sequenceEnd":1612734157823},"subject":"trade.l2update","topic":"/market/level2:ANKR-BTC","type":"message"}
1619378335.103341: {"data":{"sequenceStart":1612734157824,"symbol":"ANKR-BTC","changes":{"asks":[],"bids":[["0.0000025992","0","1612734157824"]]},"sequenceEnd":1612734157824},"subject":"trade.l2update","topic":"/market/level2:ANKR-BTC","type":"message"}
1619378335.110477: {"data":{"sequenceStart":1613277184543,"symbol":"BCHSV-USDT","changes":{"asks":[],"bids":[["242.591","0","1613277184543"]]},"sequenceEnd":1613277184543},"subject":"trade.l2update","topic":"/market/level2:BCHSV-USDT","type":"message"}
1619378335.110621: {"data":{"sequence":"1612712745654","bestAsk":"0.00000775","size":"401.2004","bestBidSize":"357.285","price":"0.00000772","time":1619378335067,"bestAskSize":"1154.0416","bestBid":"0.00000771"},"subject":"trade.ticker","topic":"/market/ticker:FET-BTC","type":"message"}
1619378335.11067: {"data":{"sequenceStart":1612699351261,"symbol":"COV-BTC","changes":{"asks":[["0.00001126","0","1612699351261"]],"bids":[]},"sequenceEnd":1612699351261},"subject":"trade.l2update","topic":"/market/level2:COV-BTC","type":"message"}
1619378335.119515: {"data":{"sequenceStart":1613277184544,"symbol":"BCHSV-USDT","changes":{"asks":[["243.247","0","1613277184544"]],"bids":[]},"sequenceEnd":1613277184544},"subject":"trade.l2update","topic":"/market/level2:BCHSV-USDT","type":"message"}
1619378335.130285: {"data":{"sequence":"1612734157824","bestAsk":"0.0000026208","size":"46","bestBidSize":"5034.7285","price":"0.0000026071","time":1619378335088,"bestAskSize":"10987.6265","bestBid":"0.0000025993"},"subject":"trade.ticker","topic":"/market/ticker:ANKR-BTC","type":"message"}
1619378335.130377: {"data":{"sequenceStart":1613277184545,"symbol":"BCHSV-USDT","changes":{"asks":[],"bids":[["240.239","0","1613277184545"]]},"sequenceEnd":1613277184545},"subject":"trade.l2update","topic":"/market/level2:BCHSV-USDT","type":"message"}
1619378335.130473: {"data":{"sequence":"1612699351261","bestAsk":"0.00001127","size":"96.1525","bestBidSize":"49.6422","price":"0.00001126","time":1619378335089,"bestAskSize":"4331.68226035","bestBid":"0.00001121"},"subject":"trade.ticker","topic":"/market/ticker:COV-BTC","type":"message"}
1619378335.141098: {"data":{"sequenceStart":1612844051900,"symbol":"SNX-BTC","changes":{"asks":[],"bids":[["0.00028644","0","1612844051900"]]},"sequenceEnd":1612844051900},"subject":"trade.l2update","topic":"/market/level2:SNX-BTC","type":"message"}
1619378335.14689: {"data":{"sequenceStart":1612734157825,"symbol":"ANKR-BTC","changes":{"asks":[],"bids":[["0","0","1612734157825"]]},"sequenceEnd":1612734157825},"subject":"trade.l2update","topic":"/market/level2:ANKR-BTC","type":"message"}
1619378335.147: {"data":{"sequenceStart":1612734157826,"symbol":"ANKR-BTC","changes":{"asks":[],"bids":[["0.0000025961","20000","1612734157826"]]},"sequenceEnd":1612734157826},"subject":"trade.l2update","topic":"/market/level2:ANKR-BTC","type":"message"}
1619378335.1470778: {"data":{"sequenceStart":1613277184546,"symbol":"BCHSV-USDT","changes":{"asks":[["0","0","1613277184546"]],"bids":[]},"sequenceEnd":1613277184546},"subject":"trade.l2update","topic":"/market/level2:BCHSV-USDT","type":"message"}
1619378335.147122: {"data":{"sequenceStart":1613277184547,"symbol":"BCHSV-USDT","changes":{"asks":[["243.249","0.6","1613277184547"]],"bids":[]},"sequenceEnd":1613277184547},"subject":"trade.l2update","topic":"/market/level2:BCHSV-USDT","type":"message"}
1619378335.1471732: {"data":{"sequenceStart":1613277184548,"symbol":"BCHSV-USDT","changes":{"asks":[],"bids":[["0","0","1613277184548"]]},"sequenceEnd":1613277184548},"subject":"trade.l2update","topic":"/market/level2:BCHSV-USDT","type":"message"}
1619378335.1472168: {"data":{"sequenceStart":1613277184549,"symbol":"BCHSV-USDT","changes":{"asks":[],"bids":[["242.604","0.68148185","1613277184549"]]},"sequenceEnd":1613277184549},"subject":"trade.l2update","topic":"/market/level2:BCHSV-USDT","type":"message"}
1619378335.159706: {"data":{"sequenceStart":1613277184550,"symbol":"BCHSV-USDT","changes":{"asks":[],"bids":[["242.607","0","1613277184550"]]},"sequenceEnd":1613277184550},"subject":"trade.l2update","topic":"/market/level2:BCHSV-USDT","type":"message"}
1619378335.164997: {"data":{"sequenceStart":1612734157827,"symbol":"ANKR-BTC","changes":{"asks":[],"bids":[["0","0","1612734157827"]]},"sequenceEnd":1612734157827},"subject":"trade.l2update","topic":"/market/level2:ANKR-BTC","type":"message"}
1619378335.165107: {"data":{"sequenceStart":1612734157828,"symbol":"ANKR-BTC","changes":{"asks":[],"bids":[["0.0000025955","3499.0665","1612734157828"]]},"sequenceEnd":1612734157828},"subject":"trade.l2update","topic":"/market/level2:ANKR-BTC","type":"message"}
1619378335.1736588: {"data":{"sequence":"1613277184550","bestAsk":"242.901","size":"0.08000012","bestBidSize":"0.68148185","price":"243.65","time":1619378335134,"bestAskSize":"4.51280965","bestBid":"242.604"},"subject":"trade.ticker","topic":"/market/ticker:BCHSV-USDT","type":"message"}
1619378335.183149: {"data":{"sequence":"1612844051900","bestAsk":"0.0002871","size":"0.01745248","bestBidSize":"0.19100065","price":"0.00028676","time":1619378335149,"bestAskSize":"14.04274325","bestBid":"0.00028678"},"subject":"trade.ticker","topic":"/market/ticker:SNX-BTC","type":"message"}
1619378335.193878: {"data":{"sequenceStart":1613277184551,"symbol":"BCHSV-USDT","changes":{"asks":[["243.404","0","1613277184551"]],"bids":[]},"sequenceEnd":1613277184551},"subject":"trade.l2update","topic":"/market/level2:BCHSV-USDT","type":"message"}
1619378335.1992571: {"data":{"sequenceStart":1613277184552,"symbol":"BCHSV-USDT","changes":{"asks":[],"bids":[["242.604","0","1613277184552"]]},"sequenceEnd":1613277184552},"subject":"trade.l2update","topic":"/market/level2:BCHSV-USDT","type":"message"}
1619378335.203965: {"data":{"sequenceStart":1613277184553,"symbol":"BCHSV-USDT","changes":{"asks":[["243.011","0","1613277184553"]],"bids":[]},"sequenceEnd":1613277184553},"subject":"trade.l2update","topic":"/market/level2:BCHSV-USDT","type":"message"}
1619378335.204103: {"data":{"sequenceStart":1613277184554,"symbol":"BCHSV-USDT","changes":{"asks":[],"bids":[["242.298","0","1613277184554"]]},"sequenceEnd":1613277184554},"subject":"trade.l2update","topic":"/market/level2:BCHSV-USDT","type":"message"}
1619378335.204175: {"data":{"sequenceStart":1612699351262,"symbol":"COV-BTC","changes":{"asks":[],"bids":[["0.00001092","10","1612699351262"]]},"sequenceEnd":1612699351262},"subject":"trade.l2update","topic":"/market/level2:COV-BTC","type":"message"}
1619378335.2042282: {"data":{"sequenceStart":1612844051901,"symbol":"SNX-BTC","changes":{"asks":[],"bids":[["0","0","1612844051901"]]},"sequenceEnd":1612844051901},"subject":"trade.l2update","topic":"/market/level2:SNX-BTC","type":"message"}
1619378335.2042902: {"data":{"sequenceStart":1612844051902,"symbol":"SNX-BTC","changes":{"asks":[],"bids":[["0.00028618","0.97350705","1612844051902"]]},"sequenceEnd":1612844051902},"subject":"trade.l2update","topic":"/market/level2:SNX-BTC","type":"message"}
1619378335.219388: {"data":{"sequenceStart":1613277184555,"symbol":"BCHSV-USDT","changes":{"asks":[],"bids":[["0","0","1613277184555"]]},"sequenceEnd":1613277184555},"subject":"trade.l2update","topic":"/market/level2:BCHSV-USDT","type":"message"}
1619378335.219501: {"data":{"sequenceStart":1613277184556,"symbol":"BCHSV-USDT","changes":{"asks":[],"bids":[["242.623","0.68148185","1613277184556"]]},"sequenceEnd":1613277184556},"subject":"trade.l2update","topic":"/market/level2:BCHSV-USDT","type":"message"}
1619378335.225874: {"data":{"sequenceStart":1612734157829,"symbol":"ANKR-BTC","changes":{"asks":[],"bids":[["0.0000025955","0","1612734157829"]]},"sequenceEnd":1612734157829},"subject":"trade.l2update","topic":"/market/level2:ANKR-BTC","type":"message"}
1619378335.226014: {"data":{"sequence":"1612699351262","bestAsk":"0.00001127","size":"96.1525","bestBidSize":"49.6422","price":"0.00001126","time":1619378335188,"bestAskSize":"4331.68226035","bestBid":"0.00001121"},"subject":"trade.ticker","topic":"/market/ticker:COV-BTC","type":"message"}
1619378335.233324: {"data":{"sequence":"1612734157829","bestAsk":"0.0000026208","size":"46","bestBidSize":"5034.7285","price":"0.0000026071","time":1619378335188,"bestAskSize":"10987.6265","bestBid":"0.0000025993"},"subject":"trade.ticker","topic":"/market/ticker:ANKR-BTC","type":"message"}
1619378335.234978: {"data":{"sequenceStart":1612844051903,"symbol":"SNX-BTC","changes":{"asks":[],"bids":[["0.00028618","0","1612844051903"]]},"sequenceEnd":1612844051903},"subject":"trade.l2update","topic":"/market/level2:SNX-BTC","type":"message"}
1619378335.245874: {"data":{"sequenceStart":1612844051904,"symbol":"SNX-BTC","changes":{"asks":[],"bids":[["0","0","1612844051904"]]},"sequenceEnd":1612844051904},"subject":"trade.l2update","topic":"/market/level2:SNX-BTC","type":"message"}
1619378335.245953: {"data":{"sequenceStart":1612844051905,"symbol":"SNX-BTC","changes":{"asks":[],"bids":[["0.00028644","3.49165619","1612844051905"]]},"sequenceEnd":1612844051905},"subject":"trade.l2update","topic":"/market/level2:SNX-BTC","type":"message"}
1619378335.250391: {"data":{"sequenceStart":1612712745655,"symbol":"FET-BTC","changes":{"asks":[["0.0000078","0","1612712745655"]],"bids":[]},"sequenceEnd":1612712745655},"subject":"trade.l2update","topic":"/market/level2:FET-BTC","type":"message"}
1619378335.2700758: {"data":{"sequenceStart":1613277184557,"symbol":"BCHSV-USDT","changes":{"asks":[],"bids":[["242.347","0","1613277184557"]]},"sequenceEnd":1613277184557},"subject":"trade.l2update","topic":"/market/level2:BCHSV-USDT","type":"message"}
1619378335.270184: {"data":{"sequenceStart":1613277184558,"symbol":"BCHSV-USDT","changes":{"asks":[["0","0","1613277184558"]],"bids":[]},"sequenceEnd":1613277184558},"subject":"trade.l2update","topic":"/market/level2:BCHSV-USDT","type":"message"}
1619378335.270237: {"data":{"sequenceStart":1613277184559,"symbol":"BCHSV-USDT","changes":{"asks":[["243.555","5.52","1613277184559"]],"bids":[]},"sequenceEnd":1613277184559},"subject":"trade.l2update","topic":"/market/level2:BCHSV-USDT","type":"message"}
1619378335.270297: {"data":{"sequence":"1612844051905","bestAsk":"0.0002871","size":"0.01745248","bestBidSize":"0.19100065","price":"0.00028676","time":1619378335223,"bestAskSize":"14.04274325","bestBid":"0.00028678"},"subject":"trade.ticker","topic":"/market/ticker:SNX-BTC","type":"message"}
1619378335.270355: {"data":{"sequence":"1613277184559","bestAsk":"242.901","size":"0.08000012","bestBidSize":"0.68148185","price":"243.65","time":1619378335231,"bestAskSize":"4.51280965","bestBid":"242.623"},"subject":"trade.ticker","topic":"/market/ticker:BCHSV-USDT","type":"message"}
1619378335.276145: {"data":{"sequenceStart":1612844051906,"symbol":"SNX-BTC","changes":{"asks":[["0.00028711","0","1612844051906"]],"bids":[]},"sequenceEnd":1612844051906},"subject":"trade.l2update","topic":"/market/level2:SNX-BTC","type":"message"}
1619378335.291109: {"data":{"sequenceStart":1613277184560,"symbol":"BCHSV-USDT","changes":{"asks":[],"bids":[["0","0","1613277184560"]]},"sequenceEnd":1613277184560},"subject":"trade.l2update","topic":"/market/level2:BCHSV-USDT","type":"message"}
1619378335.291221: {"data":{"sequenceStart":1613277184561,"symbol":"BCHSV-USDT","changes":{"asks":[],"bids":[["242.638","5","1613277184561"]]},"sequenceEnd":1613277184561},"subject":"trade.l2update","topic":"/market/level2:BCHSV-USDT","type":"message"}
1619378335.323922: {"data":{"sequence":"1612712745655","bestAsk":"0.00000775","size":"401.2004","bestBidSize":"357.285","price":"0.00000772","time":1619378335267,"bestAskSize":"1154.0416","bestBid":"0.00000771"},"subject":"trade.ticker","topic":"/market/ticker:FET-BTC","type":"message"}
1619378335.328383: {"data":{"sequenceStart":1613277184562,"symbol":"BCHSV-USDT","changes":{"asks":[["243.696","0","1613277184562"]],"bids":[]},"sequenceEnd":1613277184562},"subject":"trade.l2update","topic":"/market/level2:BCHSV-USDT","type":"message"}
1619378335.334669: {"data":{"sequenceStart":1612712745656,"symbol":"FET-BTC","changes":{"asks":[["0","0","1612712745656"]],"bids":[]},"sequenceEnd":1612712745656},"subject":"trade.l2update","topic":"/market/level2:FET-BTC","type":"message"}
1619378335.334783: {"data":{"sequenceStart":1612712745657,"symbol":"FET-BTC","changes":{"asks":[["0.00000779","4011.0849","1612712745657"]],"bids":[]},"sequenceEnd":1612712745657},"subject":"trade.l2update","topic":"/market/level2:FET-BTC","type":"message"}
1619378335.34846: {"data":{"sequenceStart":1613277184563,"symbol":"BCHSV-USDT","changes":{"asks":[],"bids":[["0","0","1613277184563"]]},"sequenceEnd":1613277184563},"subject":"trade.l2update","topic":"/market/level2:BCHSV-USDT","type":"message"}
1619378335.348568: {"data":{"sequenceStart":1613277184564,"symbol":"BCHSV-USDT","changes":{"asks":[],"bids":[["242.108","9.98367509","1613277184564"]]},"sequenceEnd":1613277184564},"subject":"trade.l2update","topic":"/market/level2:BCHSV-USDT","type":"message"}
1619378335.359232: {"data":{"sequence":"1612844051906","bestAsk":"0.0002871","size":"0.01745248","bestBidSize":"0.19100065","price":"0.00028676","time":1619378335323,"bestAskSize":"14.04274325","bestBid":"0.00028678"},"subject":"trade.ticker","topic":"/market/ticker:SNX-BTC","type":"message"}
1619378335.3593228: {"data":{"sequenceStart":1612699351263,"symbol":"COV-BTC","changes":{"asks":[],"bids":[["0","0","1612699351263"]]},"sequenceEnd":1612699351263},"subject":"trade.l2update","topic":"/market/level2:COV-BTC","type":"message"}
1619378335.35939: {"data":{"sequenceStart":1612699351264,"symbol":"COV-BTC","changes":{"asks":[],"bids":[["0.00001092","32.5988","1612699351264"]]},"sequenceEnd":1612699351264},"subject":"trade.l2update","topic":"/market/level2:COV-BTC","type":"message"}
1619378335.369874: {"data":{"sequence":"1613277184564","bestAsk":"242.901","size":"0.08000012","bestBidSize":"5","price":"243.65","time":1619378335330,"bestAskSize":"4.51280965","bestBid":"242.638"},"subject":"trade.ticker","topic":"/market/ticker:BCHSV-USDT","type":"message"}
1619378335.400231: {"data":{"sequenceStart":1613277184565,"symbol":"BCHSV-USDT","changes":{"asks":[],"bids":[["242.623","0","1613277184565"]]},"sequenceEnd":1613277184565},"subject":"trade.l2update","topic":"/market/level2:BCHSV-USDT","type":"message"}
1619378335.405466: {"data":{"sequence":"1612712745657","bestAsk":"0.00000775","size":"401.2004","bestBidSize":"357.285","price":"0.00000772","time":1619378335367,"bestAskSize":"1154.0416","bestBid":"0.00000771"},"subject":"trade.ticker","topic":"/market/ticker:FET-BTC","type":"message"}
1619378335.409645: {"data":{"sequenceStart":1612712745658,"symbol":"FET-BTC","changes":{"asks":[["0.00000779","0","1612712745658"]],"bids":[]},"sequenceEnd":1612712745658},"subject":"trade.l2update","topic":"/market/level2:FET-BTC","type":"message"}
1619378335.419096: {"data":{"sequenceStart":1613277184566,"symbol":"BCHSV-USDT","changes":{"asks":[["242.933","2.99","1613277184566"]],"bids":[]},"sequenceEnd":1613277184566},"subject":"trade.l2update","topic":"/market/level2:BCHSV-USDT","type":"message"}
1619378335.419168: {"data":{"sequenceStart":1613277184567,"symbol":"BCHSV-USDT","changes":{"asks":[["242.933","0","1613277184567"]],"bids":[]},"sequenceEnd":1613277184567},"subject":"trade.l2update","topic":"/market/level2:BCHSV-USDT","type":"message"}
1619378335.419209: {"data":{"sequenceStart":1613277184568,"symbol":"BCHSV-USDT","changes":{"asks":[],"bids":[["0","0","1613277184568"]]},"sequenceEnd":1613277184568},"subject":"trade.l2update","topic":"/market/level2:BCHSV-USDT","type":"message"}
1619378335.419243: {"data":{"sequenceStart":1613277184569,"symbol":"BCHSV-USDT","changes":{"asks":[],"bids":[["242.662","0.68148185","1613277184569"]]},"sequenceEnd":1613277184569},"subject":"trade.l2update","topic":"/market/level2:BCHSV-USDT","type":"message"}
1619378335.4239318: {"data":{"sequence":"1612699351264","bestAsk":"0.00001127","size":"96.1525","bestBidSize":"49.6422","price":"0.00001126","time":1619378335388,"bestAskSize":"4331.68226035","bestBid":"0.00001121"},"subject":"trade.ticker","topic":"/market/ticker:COV-BTC","type":"message"}
1619378335.456183: {"data":{"sequenceStart":1612844051907,"symbol":"SNX-BTC","changes":{"asks":[["0","0","1612844051907"]],"bids":[]},"sequenceEnd":1612844051907},"subject":"trade.l2update","topic":"/market/level2:SNX-BTC","type":"message"}
1619378335.456296: {"data":{"sequenceStart":1612844051908,"symbol":"SNX-BTC","changes":{"asks":[["0.00028714","29.24570683","1612844051908"]],"bids":[]},"sequenceEnd":1612844051908},"subject":"trade.l2update","topic":"/market/level2:SNX-BTC","type":"message"}
1619378335.4563782: {"data":{"sequenceStart":1613277184570,"symbol":"BCHSV-USDT","changes":{"asks":[["0","0","1613277184570"]],"bids":[]},"sequenceEnd":1613277184570},"subject":"trade.l2update","topic":"/market/level2:BCHSV-USDT","type":"message"}
1619378335.4564312: {"data":{"sequenceStart":1613277184571,"symbol":"BCHSV-USDT","changes":{"asks":[["243.683","5","1613277184571"]],"bids":[]},"sequenceEnd":1613277184571},"subject":"trade.l2update","topic":"/market/level2:BCHSV-USDT","type":"message"}
1619378335.456491: {"data":{"sequenceStart":1613277184572,"symbol":"BCHSV-USDT","changes":{"asks":[],"bids":[["0","0","1613277184572"]]},"sequenceEnd":1613277184572},"subject":"trade.l2update","topic":"/market/level2:BCHSV-USDT","type":"message"}
1619378335.459177: {"data":{"sequenceStart":1613277184573,"symbol":"BCHSV-USDT","changes":{"asks":[],"bids":[["241.522","5","1613277184573"]]},"sequenceEnd":1613277184573},"subject":"trade.l2update","topic":"/market/level2:BCHSV-USDT","type":"message"}
1619378335.459272: {"data":{"sequenceStart":1613277184574,"symbol":"BCHSV-USDT","changes":{"asks":[["0","0","1613277184574"]],"bids":[]},"sequenceEnd":1613277184574},"subject":"trade.l2update","topic":"/market/level2:BCHSV-USDT","type":"message"}
1619378335.459306: {"data":{"sequenceStart":1613277184575,"symbol":"BCHSV-USDT","changes":{"asks":[["244.32","150","1613277184575"]],"bids":[]},"sequenceEnd":1613277184575},"subject":"trade.l2update","topic":"/market/level2:BCHSV-USDT","type":"message"}
1619378335.495175: {"data":{"sequenceStart":1613277184576,"symbol":"BCHSV-USDT","changes":{"asks":[["243.037","0","1613277184576"]],"bids":[]},"sequenceEnd":1613277184576},"subject":"trade.l2update","topic":"/market/level2:BCHSV-USDT","type":"message"}
1619378335.495317: {"data":{"sequence":"1612844051908","bestAsk":"0.0002871","size":"0.01745248","bestBidSize":"0.19100065","price":"0.00028676","time":1619378335423,"bestAskSize":"14.04274325","bestBid":"0.00028678"},"subject":"trade.ticker","topic":"/market/ticker:SNX-BTC","type":"message"}
1619378335.5103822: {"data":{"sequenceStart":1612712745659,"symbol":"FET-BTC","changes":{"asks":[["0.00000775","0","1612712745659"]],"bids":[]},"sequenceEnd":1612712745659},"subject":"trade.l2update","topic":"/market/level2:FET-BTC","type":"message"}
1619378335.5105238: {"data":{"sequence":"1613277184576","bestAsk":"242.901","size":"0.08000012","bestBidSize":"0.68148185","price":"243.65","time":1619378335459,"bestAskSize":"4.51280965","bestBid":"242.662"},"subject":"trade.ticker","topic":"/market/ticker:BCHSV-USDT","type":"message"}
1619378335.510574: {"data":{"sequenceStart":1613277184577,"symbol":"BCHSV-USDT","changes":{"asks":[],"bids":[["242.638","0","1613277184577"]]},"sequenceEnd":1613277184577},"subject":"trade.l2update","topic":"/market/level2:BCHSV-USDT","type":"message"}
1619378335.5106409: {"data":{"sequenceStart":1613277184578,"symbol":"BCHSV-USDT","changes":{"asks":[],"bids":[["0","0","1613277184578"]]},"sequenceEnd":1613277184578},"subject":"trade.l2update","topic":"/market/level2:BCHSV-USDT","type":"message"}
1619378335.5107021: {"data":{"sequenceStart":1613277184579,"symbol":"BCHSV-USDT","changes":{"asks":[],"bids":[["242.687","5","1613277184579"]]},"sequenceEnd":1613277184579},"subject":"trade.l2update","topic":"/market/level2:BCHSV-USDT","type":"message"}
1619378335.514815: {"data":{"sequenceStart":1613277184580,"symbol":"BCHSV-USDT","changes":{"asks":[],"bids":[["242.662","0","1613277184580"]]},"sequenceEnd":1613277184580},"subject":"trade.l2update","topic":"/market/level2:BCHSV-USDT","type":"message"}
1619378335.520556: {"data":{"sequenceStart":1613277184581,"symbol":"BCHSV-USDT","changes":{"asks":[],"bids":[["0","0","1613277184581"]]},"sequenceEnd":1613277184581},"subject":"trade.l2update","topic":"/market/level2:BCHSV-USDT","type":"message"}
1619378335.520664: {"data":{"sequenceStart":1613277184582,"symbol":"BCHSV-USDT","changes":{"asks":[],"bids":[["242.685","0.68148185","1613277184582"]]},"sequenceEnd":1613277184582},"subject":"trade.l2update","topic":"/market/level2:BCHSV-USDT","type":"message"}
1619378335.5207412: {"data":{"sequence":"1612712745659","bestAsk":"0.00000776","size":"401.2004","bestBidSize":"357.285","price":"0.00000772","time":1619378335467,"bestAskSize":"839","bestBid":"0.00000771"},"subject":"trade.ticker","topic":"/market/ticker:FET-BTC","type":"message"}
1619378335.540323: {"data":{"sequenceStart":1612844051909,"symbol":"SNX-BTC","changes":{"asks":[["0","0","1612844051909"]],"bids":[]},"sequenceEnd":1612844051909},"subject":"trade.l2update","topic":"/market/level2:SNX-BTC","type":"message"}
1619378335.54043: {"data":{"sequenceStart":1612844051910,"symbol":"SNX-BTC","changes":{"asks":[["0.00028725","256.43435053","1612844051910"]],"bids":[]},"sequenceEnd":1612844051910},"subject":"trade.l2update","topic":"/market/level2:SNX-BTC","type":"message"}
1619378335.543943: {"data":{"sequenceStart":1613277184583,"symbol":"BCHSV-USDT","changes":{"asks":[],"bids":[["241.989","0","1613277184583"]]},"sequenceEnd":1613277184583},"subject":"trade.l2update","topic":"/market/level2:BCHSV-USDT","type":"message"}
1619378335.544078: {"data":{"sequenceStart":1612712745660,"symbol":"FET-BTC","changes":{"asks":[["0","0","1612712745660"]],"bids":[]},"sequenceEnd":1612712745660},"subject":"trade.l2update","topic":"/market/level2:FET-BTC","type":"message"}
1619378335.544136: {"data":{"sequenceStart":1612712745661,"symbol":"FET-BTC","changes":{"asks":[["0.00000781","387.8867","1612712745661"]],"bids":[]},"sequenceEnd":1612712745661},"subject":"trade.l2update","topic":"/market/level2:FET-BTC","type":"message"}
1619378335.558641: {"data":{"sequence":"1612844051910","bestAsk":"0.0002871","size":"0.01745248","bestBidSize":"0.19100065","price":"0.00028676","time":1619378335523,"bestAskSize":"14.04274325","bestBid":"0.00028678"},"subject":"trade.ticker","topic":"/market/ticker:SNX-BTC","type":"message"}
1619378335.55873: {"data":{"sequenceStart":1613277184584,"symbol":"BCHSV-USDT","changes":{"asks":[["242.901","0","1613277184584"]],"bids":[]},"sequenceEnd":1613277184584},"subject":"trade.l2update","topic":"/market/level2:BCHSV-USDT","type":"message"}
1619378335.569104: {"data":{"sequence":"1613277184587","bestAsk":"243.073","size":"0.08000012","bestBidSize":"0.68148185","price":"243.65","time":1619378335530,"bestAskSize":"0.96","bestBid":"242.685"},"subject":"trade.ticker","topic":"/market/ticker:BCHSV-USDT","type":"message"}
1619378335.57366: {"data":{"sequenceStart":1613277184585,"symbol":"BCHSV-USDT","changes":{"asks":[["0","0","1613277184585"]],"bids":[]},"sequenceEnd":1613277184585},"subject":"trade.l2update","topic":"/market/level2:BCHSV-USDT","type":"message"}
1619378335.573774: {"data":{"sequenceStart":1613277184586,"symbol":"BCHSV-USDT","changes":{"asks":[["243.11","0.20416582","1613277184586"]],"bids":[]},"sequenceEnd":1613277184586},"subject":"trade.l2update","topic":"/market/level2:BCHSV-USDT","type":"message"}
1619378335.5738492: {"data":{"sequenceStart":1613277184587,"symbol":"BCHSV-USDT","changes":{"asks":[],"bids":[["242.687","0","1613277184587"]]},"sequenceEnd":1613277184587},"subject":"trade.l2update","topic":"/market/level2:BCHSV-USDT","type":"message"}
1619378335.578961: {"data":{"sequenceStart":1613277184588,"symbol":"BCHSV-USDT","changes":{"asks":[["0","0","1613277184588"]],"bids":[]},"sequenceEnd":1613277184588},"subject":"trade.l2update","topic":"/market/level2:BCHSV-USDT","type":"message"}
1619378335.579072: {"data":{"sequenceStart":1613277184589,"symbol":"BCHSV-USDT","changes":{"asks":[["243.097","4.29825582","1613277184589"]],"bids":[]},"sequenceEnd":1613277184589},"subject":"trade.l2update","topic":"/market/level2:BCHSV-USDT","type":"message"}
1619378335.599093: {"data":{"sequenceStart":1613277184590,"symbol":"BCHSV-USDT","changes":{"asks":[["0","0","1613277184590"]],"bids":[]},"sequenceEnd":1613277184590},"subject":"trade.l2update","topic":"/market/level2:BCHSV-USDT","type":"message"}
1619378335.59917: {"data":{"sequenceStart":1613277184591,"symbol":"BCHSV-USDT","changes":{"asks":[["243.248","2.99","1613277184591"]],"bids":[]},"sequenceEnd":1613277184591},"subject":"trade.l2update","topic":"/market/level2:BCHSV-USDT","type":"message"}
1619378335.5992231: {"data":{"sequenceStart":1613277184592,"symbol":"BCHSV-USDT","changes":{"asks":[["0","0","1613277184592"]],"bids":[]},"sequenceEnd":1613277184592},"subject":"trade.l2update","topic":"/market/level2:BCHSV-USDT","type":"message"}
1619378335.599248: {"data":{"sequenceStart":1613277184593,"symbol":"BCHSV-USDT","changes":{"asks":[["243.248","5.98","1613277184593"]],"bids":[]},"sequenceEnd":1613277184593},"subject":"trade.l2update","topic":"/market/level2:BCHSV-USDT","type":"message"}
1619378335.599274: {"data":{"sequenceStart":1613277184594,"symbol":"BCHSV-USDT","changes":{"asks":[],"bids":[["0","0","1613277184594"]]},"sequenceEnd":1613277184594},"subject":"trade.l2update","topic":"/market/level2:BCHSV-USDT","type":"message"}
1619378335.599295: {"data":{"sequenceStart":1613277184595,"symbol":"BCHSV-USDT","changes":{"asks":[],"bids":[["242.188","5.52","1613277184595"]]},"sequenceEnd":1613277184595},"subject":"trade.l2update","topic":"/market/level2:BCHSV-USDT","type":"message"}
1619378335.599339: {"data":{"sequenceStart":1612844051911,"symbol":"SNX-BTC","changes":{"asks":[["0.00028725","0","1612844051911"]],"bids":[]},"sequenceEnd":1612844051911},"subject":"trade.l2update","topic":"/market/level2:SNX-BTC","type":"message"}
1619378335.603658: {"data":{"sequence":"1612712745661","bestAsk":"0.00000776","size":"401.2004","bestBidSize":"357.285","price":"0.00000772","time":1619378335567,"bestAskSize":"839","bestBid":"0.00000771"},"subject":"trade.ticker","topic":"/market/ticker:FET-BTC","type":"message"}
1619378335.62131: {"data":{"sequenceStart":1613277184596,"symbol":"BCHSV-USDT","changes":{"asks":[["0","0","1613277184596"]],"bids":[]},"sequenceEnd":1613277184596},"subject":"trade.l2update","topic":"/market/level2:BCHSV-USDT","type":"message"}
1619378335.621386: {"data":{"sequenceStart":1613277184597,"symbol":"BCHSV-USDT","changes":{"asks":[["243.554","9.76192837","1613277184597"]],"bids":[]},"sequenceEnd":1613277184597},"subject":"trade.l2update","topic":"/market/level2:BCHSV-USDT","type":"message"}
1619378335.6332412: {"data":{"sequenceStart":1613277184598,"symbol":"BCHSV-USDT","changes":{"asks":[["0","0","1613277184598"]],"bids":[]},"sequenceEnd":1613277184598},"subject":"trade.l2update","topic":"/market/level2:BCHSV-USDT","type":"message"}
1619378335.6333492: {"data":{"sequenceStart":1613277184599,"symbol":"BCHSV-USDT","changes":{"asks":[["243.261","3.75310107","1613277184599"]],"bids":[]},"sequenceEnd":1613277184599},"subject":"trade.l2update","topic":"/market/level2:BCHSV-USDT","type":"message"}
1619378335.633429: {"data":{"sequenceStart":1613277184600,"symbol":"BCHSV-USDT","changes":{"asks":[],"bids":[["242.108","0","1613277184600"]]},"sequenceEnd":1613277184600},"subject":"trade.l2update","topic":"/market/level2:BCHSV-USDT","type":"message"}
1619378335.633496: {"data":{"sequenceStart":1613277184601,"symbol":"BCHSV-USDT","changes":{"asks":[["243.248","2.99","1613277184601"]],"bids":[]},"sequenceEnd":1613277184601},"subject":"trade.l2update","topic":"/market/level2:BCHSV-USDT","type":"message"}
1619378335.642586: {"data":{"sequenceStart":1613277184602,"symbol":"BCHSV-USDT","changes":{"asks":[["243.248","0","1613277184602"]],"bids":[]},"sequenceEnd":1613277184602},"subject":"trade.l2update","topic":"/market/level2:BCHSV-USDT","type":"message"}
1619378335.6555882: {"data":{"sequenceStart":1613277184603,"symbol":"BCHSV-USDT","changes":{"asks":[["243.261","0","1613277184603"]],"bids":[]},"sequenceEnd":1613277184603},"subject":"trade.l2update","topic":"/market/level2:BCHSV-USDT","type":"message"}
1619378335.663166: {"data":{"sequence":"1612844051911","bestAsk":"0.0002871","size":"0.01745248","bestBidSize":"0.19100065","price":"0.00028676","time":1619378335623,"bestAskSize":"14.04274325","bestBid":"0.00028678"},"subject":"trade.ticker","topic":"/market/ticker:SNX-BTC","type":"message"}
1619378335.672744: {"data":{"sequence":"1613277184603","bestAsk":"243.073","size":"0.08000012","bestBidSize":"0.68148185","price":"243.65","time":1619378335632,"bestAskSize":"0.96","bestBid":"242.685"},"subject":"trade.ticker","topic":"/market/ticker:BCHSV-USDT","type":"message"}
1619378335.6836522: {"data":{"sequenceStart":1613277184604,"symbol":"BCHSV-USDT","changes":{"asks":[["0","0","1613277184604"]],"bids":[]},"sequenceEnd":1613277184604},"subject":"trade.l2update","topic":"/market/level2:BCHSV-USDT","type":"message"}
1619378335.6837618: {"data":{"sequenceStart":1613277184605,"symbol":"BCHSV-USDT","changes":{"asks":[["243.109","2.99","1613277184605"]],"bids":[]},"sequenceEnd":1613277184605},"subject":"trade.l2update","topic":"/market/level2:BCHSV-USDT","type":"message"}
1619378335.688131: {"data":{"sequenceStart":1612701563973,"symbol":"DAPPT-BTC","changes":{"asks":[],"bids":[["0.0000001116","0","1612701563973"]]},"sequenceEnd":1612701563973},"subject":"trade.l2update","topic":"/market/level2:DAPPT-BTC","type":"message"}
1619378335.749367: {"data":{"sequenceStart":1612699351265,"symbol":"COV-BTC","changes":{"asks":[["0","0","1612699351265"]],"bids":[]},"sequenceEnd":1612699351265},"subject":"trade.l2update","topic":"/market/level2:COV-BTC","type":"message"}
1619378335.7494469: {"data":{"sequenceStart":1612699351266,"symbol":"COV-BTC","changes":{"asks":[["0.00001127","4469.58576035","1612699351266"]],"bids":[]},"sequenceEnd":1612699351266},"subject":"trade.l2update","topic":"/market/level2:COV-BTC","type":"message"}
1619378335.749488: {"data":{"sequenceStart":1613277184606,"symbol":"BCHSV-USDT","changes":{"asks":[],"bids":[["242.685","0","1613277184606"]]},"sequenceEnd":1613277184606},"subject":"trade.l2update","topic":"/market/level2:BCHSV-USDT","type":"message"}
1619378335.749536: {"data":{"sequenceStart":1613277184607,"symbol":"BCHSV-USDT","changes":{"asks":[["0","0","1613277184607"]],"bids":[]},"sequenceEnd":1613277184607},"subject":"trade.l2update","topic":"/market/level2:BCHSV-USDT","type":"message"}
1619378335.74956: {"data":{"sequenceStart":1613277184608,"symbol":"BCHSV-USDT","changes":{"asks":[["243.109","5.98","1613277184608"]],"bids":[]},"sequenceEnd":1613277184608},"subject":"trade.l2update","topic":"/market/level2:BCHSV-USDT","type":"message"}
1619378335.7495859: {"data":{"sequenceStart":1613277184609,"symbol":"BCHSV-USDT","changes":{"asks":[["0","0","1613277184609"]],"bids":[]},"sequenceEnd":1613277184609},"subject":"trade.l2update","topic":"/market/level2:BCHSV-USDT","type":"message"}
1619378335.749606: {"data":{"sequenceStart":1613277184610,"symbol":"BCHSV-USDT","changes":{"asks":[["242.996","0.6","1613277184610"]],"bids":[]},"sequenceEnd":1613277184610},"subject":"trade.l2update","topic":"/market/level2:BCHSV-USDT","type":"message"}
1619378335.7496388: {"data":{"sequenceStart":1613277184611,"symbol":"BCHSV-USDT","changes":{"asks":[["0","0","1613277184611"]],"bids":[]},"sequenceEnd":1613277184611},"subject":"trade.l2update","topic":"/market/level2:BCHSV-USDT","type":"message"}
1619378335.74966: {"data":{"sequenceStart":1613277184612,"symbol":"BCHSV-USDT","changes":{"asks":[["245.582","17.79999999","1613277184612"]],"bids":[]},"sequenceEnd":1613277184612},"subject":"trade.l2update","topic":"/market/level2:BCHSV-USDT","type":"message"}
1619378335.749689: {"data":{"sequenceStart":1613277184613,"symbol":"BCHSV-USDT","changes":{"asks":[["243.249","0","1613277184613"]],"bids":[]},"sequenceEnd":1613277184613},"subject":"trade.l2update","topic":"/market/level2:BCHSV-USDT","type":"message"}
1619378335.74972: {"data":{"sequenceStart":1613277184614,"symbol":"BCHSV-USDT","changes":{"asks":[],"bids":[["0","0","1613277184614"]]},"sequenceEnd":1613277184614},"subject":"trade.l2update","topic":"/market/level2:BCHSV-USDT","type":"message"}
1619378335.749742: {"data":{"sequenceStart":1613277184615,"symbol":"BCHSV-USDT","changes":{"asks":[],"bids":[["242.521","9.33489988","1613277184615"]]},"sequenceEnd":1613277184615},"subject":"trade.l2update","topic":"/market/level2:BCHSV-USDT","type":"message"}
1619378335.74977: {"data":{"sequenceStart":1612844051912,"symbol":"SNX-BTC","changes":{"asks":[["0","0","1612844051912"]],"bids":[]},"sequenceEnd":1612844051912},"subject":"trade.l2update","topic":"/market/level2:SNX-BTC","type":"message"}
1619378335.749791: {"data":{"sequenceStart":1612844051913,"symbol":"SNX-BTC","changes":{"asks":[["0.00028732","256.41080259","1612844051913"]],"bids":[]},"sequenceEnd":1612844051913},"subject":"trade.l2update","topic":"/market/level2:SNX-BTC","type":"message"}
1619378335.749832: {"data":{"sequence":"1612699351266","bestAsk":"0.00001127","size":"96.1525","bestBidSize":"49.6422","price":"0.00001126","time":1619378335688,"bestAskSize":"4469.58576035","bestBid":"0.00001121"},"subject":"trade.ticker","topic":"/market/ticker:COV-BTC","type":"message"}
1619378335.7507179: {"data":{"sequenceStart":1613277184616,"symbol":"BCHSV-USDT","changes":{"asks":[["243.11","0","1613277184616"]],"bids":[]},"sequenceEnd":1613277184616},"subject":"trade.l2update","topic":"/market/level2:BCHSV-USDT","type":"message"}
1619378335.7649589: {"data":{"sequence":"1612844051913","bestAsk":"0.0002871","size":"0.01745248","bestBidSize":"0.19100065","price":"0.00028676","time":1619378335723,"bestAskSize":"14.04274325","bestBid":"0.00028678"},"subject":"trade.ticker","topic":"/market/ticker:SNX-BTC","type":"message"}
1619378335.770605: {"data":{"sequence":"1612701563973","bestAsk":"0.000000113","size":"145.4959","bestBidSize":"361.2609","price":"0.0000001126","time":1619378335730,"bestAskSize":"1208.0878","bestBid":"0.0000001119"},"subject":"trade.ticker","topic":"/market/ticker:DAPPT-BTC","type":"message"}
1619378335.777005: {"data":{"sequence":"1613277184616","bestAsk":"242.996","size":"0.08000012","bestBidSize":"0.45082023","price":"243.65","time":1619378335733,"bestAskSize":"0.6","bestBid":"242.584"},"subject":"trade.ticker","topic":"/market/ticker:BCHSV-USDT","type":"message"}
1619378335.786054: {"data":{"sequenceStart":1613277184617,"symbol":"BCHSV-USDT","changes":{"asks":[],"bids":[["0","0","1613277184617"]]},"sequenceEnd":1613277184617},"subject":"trade.l2update","topic":"/market/level2:BCHSV-USDT","type":"message"}
1619378335.786166: {"data":{"sequenceStart":1613277184618,"symbol":"BCHSV-USDT","changes":{"asks":[],"bids":[["242.633","5","1613277184618"]]},"sequenceEnd":1613277184618},"subject":"trade.l2update","topic":"/market/level2:BCHSV-USDT","type":"message"}
1619378335.796515: {"data":{"sequenceStart":1613277184619,"symbol":"BCHSV-USDT","changes":{"asks":[],"bids":[["0","0","1613277184619"]]},"sequenceEnd":1613277184619},"subject":"trade.l2update","topic":"/market/level2:BCHSV-USDT","type":"message"}
1619378335.796625: {"data":{"sequenceStart":1613277184620,"symbol":"BCHSV-USDT","changes":{"asks":[],"bids":[["242.475","6.1778974","1613277184620"]]},"sequenceEnd":1613277184620},"subject":"trade.l2update","topic":"/market/level2:BCHSV-USDT","type":"message"}
1619378335.7967072: {"data":{"sequenceStart":1613277184621,"symbol":"BCHSV-USDT","changes":{"asks":[["0","0","1613277184621"]],"bids":[]},"sequenceEnd":1613277184621},"subject":"trade.l2update","topic":"/market/level2:BCHSV-USDT","type":"message"}
1619378335.796751: {"data":{"sequenceStart":1613277184622,"symbol":"BCHSV-USDT","changes":{"asks":[["243.184","6.1778974","1613277184622"]],"bids":[]},"sequenceEnd":1613277184622},"subject":"trade.l2update","topic":"/market/level2:BCHSV-USDT","type":"message"}
1619378335.8119302: {"data":{"sequenceStart":1612702190332,"symbol":"NRG-BTC","changes":{"asks":[["0.00006229","0","1612702190332"]],"bids":[]},"sequenceEnd":1612702190332},"subject":"trade.l2update","topic":"/market/level2:NRG-BTC","type":"message"}
1619378335.8120692: {"data":{"sequenceStart":1612844051914,"symbol":"SNX-BTC","changes":{"asks":[],"bids":[["0.00028644","0","1612844051914"]]},"sequenceEnd":1612844051914},"subject":"trade.l2update","topic":"/market/level2:SNX-BTC","type":"message"}
1619378335.8365881: {"data":{"sequence":"1612702190332","bestAsk":"0.00006218","size":"0.0431","bestBidSize":"19.5017","price":"0.00006141","time":1619378335792,"bestAskSize":"43.3399","bestBid":"0.00006141"},"subject":"trade.ticker","topic":"/market/ticker:NRG-BTC","type":"message"}
1619378335.841397: {"data":{"sequenceStart":1612734157830,"symbol":"ANKR-BTC","changes":{"asks":[],"bids":[["0","0","1612734157830"]]},"sequenceEnd":1612734157830},"subject":"trade.l2update","topic":"/market/level2:ANKR-BTC","type":"message"}
1619378335.841505: {"data":{"sequenceStart":1612734157831,"symbol":"ANKR-BTC","changes":{"asks":[],"bids":[["0.0000025994","3499.0665","1612734157831"]]},"sequenceEnd":1612734157831},"subject":"trade.l2update","topic":"/market/level2:ANKR-BTC","type":"message"}
1619378335.851375: {"data":{"sequenceStart":1613277184623,"symbol":"BCHSV-USDT","changes":{"asks":[],"bids":[["241.522","0","1613277184623"]]},"sequenceEnd":1613277184623},"subject":"trade.l2update","topic":"/market/level2:BCHSV-USDT","type":"message"}
1619378335.851511: {"data":{"sequenceStart":1613277184624,"symbol":"BCHSV-USDT","changes":{"asks":[["244.32","0","1613277184624"]],"bids":[]},"sequenceEnd":1613277184624},"subject":"trade.l2update","topic":"/market/level2:BCHSV-USDT","type":"message"}
1619378335.851585: {"data":{"sequenceStart":1613277184625,"symbol":"BCHSV-USDT","changes":{"asks":[["243.683","0","1613277184625"]],"bids":[]},"sequenceEnd":1613277184625},"subject":"trade.l2update","topic":"/market/level2:BCHSV-USDT","type":"message"}
1619378335.860307: {"data":{"sequenceStart":1613277184626,"symbol":"BCHSV-USDT","changes":{"asks":[],"bids":[["0","0","1613277184626"]]},"sequenceEnd":1613277184626},"subject":"trade.l2update","topic":"/market/level2:BCHSV-USDT","type":"message"}
1619378335.8604171: {"data":{"sequenceStart":1613277184627,"symbol":"BCHSV-USDT","changes":{"asks":[],"bids":[["242.686","52.488","1613277184627"]]},"sequenceEnd":1613277184627},"subject":"trade.l2update","topic":"/market/level2:BCHSV-USDT","type":"message"}
1619378335.8754282: {"data":{"sequence":"1613277184627","bestAsk":"242.996","size":"0.08000012","bestBidSize":"52.488","price":"243.65","time":1619378335834,"bestAskSize":"0.6","bestBid":"242.686"},"subject":"trade.ticker","topic":"/market/ticker:BCHSV-USDT","type":"message"}
1619378335.875519: {"data":{"sequenceStart":1612734157832,"symbol":"ANKR-BTC","changes":{"asks":[],"bids":[["0.0000025993","0","1612734157832"]]},"sequenceEnd":1612734157832},"subject":"trade.l2update","topic":"/market/level2:ANKR-BTC","type":"message"}
1619378335.883564: {"data":{"sequenceStart":1613277184628,"symbol":"BCHSV-USDT","changes":{"asks":[],"bids":[["0","0","1613277184628"]]},"sequenceEnd":1613277184628},"subject":"trade.l2update","topic":"/market/level2:BCHSV-USDT","type":"message"}
1619378335.8836732: {"data":{"sequenceStart":1613277184629,"symbol":"BCHSV-USDT","changes":{"asks":[],"bids":[["242.668","5","1613277184629"]]},"sequenceEnd":1613277184629},"subject":"trade.l2update","topic":"/market/level2:BCHSV-USDT","type":"message"}
1619378335.8837519: {"data":{"sequenceStart":1613277184630,"symbol":"BCHSV-USDT","changes":{"asks":[],"bids":[["242.633","0","1613277184630"]]},"sequenceEnd":1613277184630},"subject":"trade.l2update","topic":"/market/level2:BCHSV-USDT","type":"message"}
1619378335.883849: {"data":{"sequenceStart":1612701563974,"symbol":"DAPPT-BTC","changes":{"asks":[],"bids":[["0","0","1612701563974"]]},"sequenceEnd":1612701563974},"subject":"trade.l2update","topic":"/market/level2:DAPPT-BTC","type":"message"}
1619378335.883877: {"data":{"sequenceStart":1612701563975,"symbol":"DAPPT-BTC","changes":{"asks":[],"bids":[["0.000000112","5148.7686","1612701563975"]]},"sequenceEnd":1612701563975},"subject":"trade.l2update","topic":"/market/level2:DAPPT-BTC","type":"message"}
1619378335.885589: {"data":{"sequenceStart":1612712745662,"symbol":"FET-BTC","changes":{"asks":[],"bids":[["0.00000768","108.5572","1612712745662"]]},"sequenceEnd":1612712745662},"subject":"trade.l2update","topic":"/market/level2:FET-BTC","type":"message"}
1619378335.8965278: {"data":{"sequenceStart":1612702190333,"symbol":"NRG-BTC","changes":{"asks":[["0","0","1612702190333"]],"bids":[]},"sequenceEnd":1612702190333},"subject":"trade.l2update","topic":"/market/level2:NRG-BTC","type":"message"}
1619378335.896637: {"data":{"sequenceStart":1612702190334,"symbol":"NRG-BTC","changes":{"asks":[["0.00006229","13.679","1612702190334"]],"bids":[]},"sequenceEnd":1612702190334},"subject":"trade.l2update","topic":"/market/level2:NRG-BTC","type":"message"}
1619378335.9013891: {"data":{"sequenceStart":1613277184631,"symbol":"BCHSV-USDT","changes":{"asks":[["242.996","0","1613277184631"]],"bids":[]},"sequenceEnd":1613277184631},"subject":"trade.l2update","topic":"/market/level2:BCHSV-USDT","type":"message"}
1619378335.9055092: {"data":{"sequence":"1612712745662","bestAsk":"0.00000776","size":"401.2004","bestBidSize":"357.285","price":"0.00000772","time":1619378335867,"bestAskSize":"839","bestBid":"0.00000771"},"subject":"trade.ticker","topic":"/market/ticker:FET-BTC","type":"message"}
1619378335.916516: {"data":{"sequenceStart":1612844051915,"symbol":"SNX-BTC","changes":{"asks":[],"bids":[["0","0","1612844051915"]]},"sequenceEnd":1612844051915},"subject":"trade.l2update","topic":"/market/level2:SNX-BTC","type":"message"}
1619378335.916594: {"data":{"sequenceStart":1612844051916,"symbol":"SNX-BTC","changes":{"asks":[],"bids":[["0.00028622","14.11590094","1612844051916"]]},"sequenceEnd":1612844051916},"subject":"trade.l2update","topic":"/market/level2:SNX-BTC","type":"message"}
1619378335.916647: {"data":{"sequenceStart":1612844051917,"symbol":"SNX-BTC","changes":{"asks":[],"bids":[["0","0","1612844051917"]]},"sequenceEnd":1612844051917},"subject":"trade.l2update","topic":"/market/level2:SNX-BTC","type":"message"}
1619378335.916673: {"data":{"sequenceStart":1612844051918,"symbol":"SNX-BTC","changes":{"asks":[],"bids":[["0.00028643","14.07589087","1612844051918"]]},"sequenceEnd":1612844051918},"subject":"trade.l2update","topic":"/market/level2:SNX-BTC","type":"message"}
1619378335.924293: {"data":{"sequenceStart":1613277184632,"symbol":"BCHSV-USDT","changes":{"asks":[],"bids":[["0","0","1613277184632"]]},"sequenceEnd":1613277184632},"subject":"trade.l2update","topic":"/market/level2:BCHSV-USDT","type":"message"}
1619378335.924404: {"data":{"sequence":"1612734157834","bestAsk":"0.0000026208","size":"46","bestBidSize":"5034.7285","price":"0.0000026071","time":1619378335888,"bestAskSize":"10987.6265","bestBid":"0.0000025995"},"subject":"trade.ticker","topic":"/market/ticker:ANKR-BTC","type":"message"}
1619378335.924452: {"data":{"sequenceStart":1613277184633,"symbol":"BCHSV-USDT","changes":{"asks":[],"bids":[["242.744","0.68148185","1613277184633"]]},"sequenceEnd":1613277184633},"subject":"trade.l2update","topic":"/market/level2:BCHSV-USDT","type":"message"}
1619378335.935149: {"data":{"sequence":"1612844051918","bestAsk":"0.0002871","size":"0.01745248","bestBidSize":"0.19100065","price":"0.00028676","time":1619378335885,"bestAskSize":"14.04274325","bestBid":"0.00028678"},"subject":"trade.ticker","topic":"/market/ticker:SNX-BTC","type":"message"}
1619378335.935241: {"data":{"sequenceStart":1612844051919,"symbol":"SNX-BTC","changes":{"asks":[],"bids":[["0.00028622","0","1612844051919"]]},"sequenceEnd":1612844051919},"subject":"trade.l2update","topic":"/market/level2:SNX-BTC","type":"message"}
1619378335.939809: {"data":{"sequenceStart":1612734157833,"symbol":"ANKR-BTC","changes":{"asks":[],"bids":[["0","0","1612734157833"]]},"sequenceEnd":1612734157833},"subject":"trade.l2update","topic":"/market/level2:ANKR-BTC","type":"message"}
1619378335.9399219: {"data":{"sequenceStart":1612734157834,"symbol":"ANKR-BTC","changes":{"asks":[],"bids":[["0.0000025995","5034.7285","1612734157834"]]},"sequenceEnd":1612734157834},"subject":"trade.l2update","topic":"/market/level2:ANKR-BTC","type":"message"}
1619378335.968837: {"data":{"sequence":"1612701563975","bestAsk":"0.000000113","size":"145.4959","bestBidSize":"5148.7686","price":"0.0000001126","time":1619378335930,"bestAskSize":"1208.0878","bestBid":"0.000000112"},"subject":"trade.ticker","topic":"/market/ticker:DAPPT-BTC","type":"message"}
1619378335.973593: {"data":{"sequence":"1612702190334","bestAsk":"0.00006218","size":"0.0431","bestBidSize":"19.5017","price":"0.00006141","time":1619378335891,"bestAskSize":"43.3399","bestBid":"0.00006141"},"subject":"trade.ticker","topic":"/market/ticker:NRG-BTC","type":"message"}
1619378335.973685: {"data":{"sequenceStart":1612844051920,"symbol":"SNX-BTC","changes":{"asks":[["0.00028714","0","1612844051920"]],"bids":[]},"sequenceEnd":1612844051920},"subject":"trade.l2update","topic":"/market/level2:SNX-BTC","type":"message"}
1619378335.973784: {"data":{"sequence":"1613277184635","bestAsk":"243.073","size":"0.08000012","bestBidSize":"0.68148185","price":"243.65","time":1619378335934,"bestAskSize":"0.96","bestBid":"242.744"},"subject":"trade.ticker","topic":"/market/ticker:BCHSV-USDT","type":"message"}
1619378335.9818418: {"data":{"sequenceStart":1613277184634,"symbol":"BCHSV-USDT","changes":{"asks":[],"bids":[["242.668","0","1613277184634"]]},"sequenceEnd":1613277184634},"subject":"trade.l2update","topic":"/market/level2:BCHSV-USDT","type":"message"}
1619378335.981981: {"data":{"sequenceStart":1613277184635,"symbol":"BCHSV-USDT","changes":{"asks":[],"bids":[["242.584","0","1613277184635"]]},"sequenceEnd":1613277184635},"subject":"trade.l2update","topic":"/market/level2:BCHSV-USDT","type":"message"}
1619378335.982049: {"data":{"sequence":"1612844051920","bestAsk":"0.0002871","size":"0.01745248","bestBidSize":"0.19100065","price":"0.00028676","time":1619378335934,"bestAskSize":"14.04274325","bestBid":"0.00028678"},"subject":"trade.ticker","topic":"/market/ticker:SNX-BTC","type":"message"}
1619378335.982094: {"data":{"sequenceStart":1612844051921,"symbol":"SNX-BTC","changes":{"asks":[["0.0002871","0","1612844051921"]],"bids":[]},"sequenceEnd":1612844051921},"subject":"trade.l2update","topic":"/market/level2:SNX-BTC","type":"message"}
1619378335.989262: {"data":{"sequenceStart":1612844051922,"symbol":"SNX-BTC","changes":{"asks":[],"bids":[["0.00028643","0","1612844051922"]]},"sequenceEnd":1612844051922},"subject":"trade.l2update","topic":"/market/level2:SNX-BTC","type":"message"}
1619378335.994658: {"data":{"sequenceStart":1613277184636,"symbol":"BCHSV-USDT","changes":{"asks":[],"bids":[["242.744","0","1613277184636"]]},"sequenceEnd":1613277184636},"subject":"trade.l2update","topic":"/market/level2:BCHSV-USDT","type":"message"}
1619378336.0172238: {"data":{"sequenceStart":1613277184637,"symbol":"BCHSV-USDT","changes":{"asks":[["0","0","1613277184637"]],"bids":[]},"sequenceEnd":1613277184637},"subject":"trade.l2update","topic":"/market/level2:BCHSV-USDT","type":"message"}
1619378336.0173361: {"data":{"sequenceStart":1613277184638,"symbol":"BCHSV-USDT","changes":{"asks":[["242.993","0.6","1613277184638"]],"bids":[]},"sequenceEnd":1613277184638},"subject":"trade.l2update","topic":"/market/level2:BCHSV-USDT","type":"message"}
1619378336.048691: {"data":{"sequenceStart":1619079123944,"symbol":"EQZ-BTC","changes":{"asks":[],"bids":[["0","0","1619079123944"]]},"sequenceEnd":1619079123944},"subject":"trade.l2update","topic":"/market/level2:EQZ-BTC","type":"message"}
1619378336.064229: {"data":{"sequenceStart":1612844051923,"symbol":"SNX-BTC","changes":{"asks":[],"bids":[["0","0","1612844051923"]]},"sequenceEnd":1612844051923},"subject":"trade.l2update","topic":"/market/level2:SNX-BTC","type":"message"}
1619378336.064335: {"data":{"sequenceStart":1612844051924,"symbol":"SNX-BTC","changes":{"asks":[],"bids":[["0.00028643","5.91524668","1612844051924"]]},"sequenceEnd":1612844051924},"subject":"trade.l2update","topic":"/market/level2:SNX-BTC","type":"message"}
1619378336.064416: {"data":{"sequenceStart":1612844051925,"symbol":"SNX-BTC","changes":{"asks":[],"bids":[["0","0","1612844051925"]]},"sequenceEnd":1612844051925},"subject":"trade.l2update","topic":"/market/level2:SNX-BTC","type":"message"}
1619378336.064459: {"data":{"sequenceStart":1612844051926,"symbol":"SNX-BTC","changes":{"asks":[],"bids":[["0.00028622","1.48966343","1612844051926"]]},"sequenceEnd":1612844051926},"subject":"trade.l2update","topic":"/market/level2:SNX-BTC","type":"message"}
1619378336.074104: {"data":{"sequenceStart":1612844051927,"symbol":"SNX-BTC","changes":{"asks":[["0","0","1612844051927"]],"bids":[]},"sequenceEnd":1612844051927},"subject":"trade.l2update","topic":"/market/level2:SNX-BTC","type":"message"}
1619378336.074214: {"data":{"sequenceStart":1612844051928,"symbol":"SNX-BTC","changes":{"asks":[["0.00028711","14.04224443","1612844051928"]],"bids":[]},"sequenceEnd":1612844051928},"subject":"trade.l2update","topic":"/market/level2:SNX-BTC","type":"message"}
1619378336.0742972: {"data":{"sequenceStart":1613277184639,"symbol":"BCHSV-USDT","changes":{"asks":[],"bids":[["0","0","1613277184639"]]},"sequenceEnd":1613277184639},"subject":"trade.l2update","topic":"/market/level2:BCHSV-USDT","type":"message"}
1619378336.0743418: {"data":{"sequenceStart":1613277184640,"symbol":"BCHSV-USDT","changes":{"asks":[],"bids":[["242.648","0.45082023","1613277184640"]]},"sequenceEnd":1613277184640},"subject":"trade.l2update","topic":"/market/level2:BCHSV-USDT","type":"message"}
1619378336.0744152: {"data":{"sequence":"1619079123944","bestAsk":"0.00002395","size":"0.375","bestBidSize":"20.5373","price":"0.00002383","time":1619378336038,"bestAskSize":"72.1515","bestBid":"0.00002383"},"subject":"trade.ticker","topic":"/market/ticker:EQZ-BTC","type":"message"}
1619378336.07444: {"data":{"sequence":"1613277184640","bestAsk":"242.993","size":"0.08000012","bestBidSize":"52.488","price":"243.65","time":1619378336034,"bestAskSize":"0.6","bestBid":"242.686"},"subject":"trade.ticker","topic":"/market/ticker:BCHSV-USDT","type":"message"}
1619378336.078462: {"data":{"sequenceStart":1613277184641,"symbol":"BCHSV-USDT","changes":{"asks":[],"bids":[["0","0","1613277184641"]]},"sequenceEnd":1613277184641},"subject":"trade.l2update","topic":"/market/level2:BCHSV-USDT","type":"message"}
1619378336.07857: {"data":{"sequenceStart":1613277184642,"symbol":"BCHSV-USDT","changes":{"asks":[],"bids":[["242.753","5","1613277184642"]]},"sequenceEnd":1613277184642},"subject":"trade.l2update","topic":"/market/level2:BCHSV-USDT","type":"message"}
1619378336.086414: {"data":{"sequenceStart":1612844051929,"symbol":"SNX-BTC","changes":{"asks":[],"bids":[["0","0","1612844051929"]]},"sequenceEnd":1612844051929},"subject":"trade.l2update","topic":"/market/level2:SNX-BTC","type":"message"}
1619378336.08652: {"data":{"sequenceStart":1612844051930,"symbol":"SNX-BTC","changes":{"asks":[],"bids":[["0.0002861","35.16464552","1612844051930"]]},"sequenceEnd":1612844051930},"subject":"trade.l2update","topic":"/market/level2:SNX-BTC","type":"message"}
1619378336.0865989: {"data":{"sequence":"1612844051930","bestAsk":"0.00028711","size":"0.01745248","bestBidSize":"0.19100065","price":"0.00028676","time":1619378336047,"bestAskSize":"14.04224443","bestBid":"0.00028678"},"subject":"trade.ticker","topic":"/market/ticker:SNX-BTC","type":"message"}
1619378336.0939531: {"data":{"sequenceStart":1612844051931,"symbol":"SNX-BTC","changes":{"asks":[],"bids":[["0.00028622","0","1612844051931"]]},"sequenceEnd":1612844051931},"subject":"trade.l2update","topic":"/market/level2:SNX-BTC","type":"message"}
1619378336.1205702: {"data":{"sequenceStart":1612844051932,"symbol":"SNX-BTC","changes":{"asks":[],"bids":[["0.00028643","0","1612844051932"]]},"sequenceEnd":1612844051932},"subject":"trade.l2update","topic":"/market/level2:SNX-BTC","type":"message"}
1619378336.1207092: {"data":{"sequenceStart":1612844051933,"symbol":"SNX-BTC","changes":{"asks":[],"bids":[["0.00028609","0","1612844051933"]]},"sequenceEnd":1612844051933},"subject":"trade.l2update","topic":"/market/level2:SNX-BTC","type":"message"}
1619378336.123615: {"data":{"sequenceStart":1619079123945,"symbol":"EQZ-BTC","changes":{"asks":[],"bids":[["0","0","1619079123945"]]},"sequenceEnd":1619079123945},"subject":"trade.l2update","topic":"/market/level2:EQZ-BTC","type":"message"}
1619378336.123725: {"data":{"sequenceStart":1619079123946,"symbol":"EQZ-BTC","changes":{"asks":[],"bids":[["0","0","1619079123946"]]},"sequenceEnd":1619079123946},"subject":"trade.l2update","topic":"/market/level2:EQZ-BTC","type":"message"}
1619378336.123772: {"data":{"sequenceStart":1613277184643,"symbol":"BCHSV-USDT","changes":{"asks":[["251.516","0","1613277184643"]],"bids":[]},"sequenceEnd":1613277184643},"subject":"trade.l2update","topic":"/market/level2:BCHSV-USDT","type":"message"}
1619378336.147874: {"data":{"sequenceStart":1613277184644,"symbol":"BCHSV-USDT","changes":{"asks":[],"bids":[["241.746","0","1613277184644"]]},"sequenceEnd":1613277184644},"subject":"trade.l2update","topic":"/market/level2:BCHSV-USDT","type":"message"}
1619378336.160713: {"data":{"sequence":"1612844051933","bestAsk":"0.00028711","size":"0.01745248","bestBidSize":"0.19100065","price":"0.00028676","time":1619378336123,"bestAskSize":"14.04224443","bestBid":"0.00028678"},"subject":"trade.ticker","topic":"/market/ticker:SNX-BTC","type":"message"}
1619378336.168171: {"data":{"sequenceStart":1612712745663,"symbol":"FET-BTC","changes":{"asks":[],"bids":[["0","0","1612712745663"]]},"sequenceEnd":1612712745663},"subject":"trade.l2update","topic":"/market/level2:FET-BTC","type":"message"}
1619378336.168277: {"data":{"sequenceStart":1612712745664,"symbol":"FET-BTC","changes":{"asks":[],"bids":[["0.00000769","88.5593","1612712745664"]]},"sequenceEnd":1612712745664},"subject":"trade.l2update","topic":"/market/level2:FET-BTC","type":"message"}
1619378336.1746418: {"data":{"sequence":"1613277184644","bestAsk":"242.993","size":"0.08000012","bestBidSize":"5","price":"243.65","time":1619378336134,"bestAskSize":"0.6","bestBid":"242.753"},"subject":"trade.ticker","topic":"/market/ticker:BCHSV-USDT","type":"message"}
1619378336.178338: {"data":{"sequence":"1619079123946","bestAsk":"0.00002395","size":"0.375","bestBidSize":"20.5373","price":"0.00002383","time":1619378336138,"bestAskSize":"72.1515","bestBid":"0.00002383"},"subject":"trade.ticker","topic":"/market/ticker:EQZ-BTC","type":"message"}
1619378336.193374: {"data":{"sequenceStart":1612844051934,"symbol":"SNX-BTC","changes":{"asks":[],"bids":[["0","0","1612844051934"]]},"sequenceEnd":1612844051934},"subject":"trade.l2update","topic":"/market/level2:SNX-BTC","type":"message"}
1619378336.193482: {"data":{"sequenceStart":1612844051935,"symbol":"SNX-BTC","changes":{"asks":[],"bids":[["0.00028622","14.10720341","1612844051935"]]},"sequenceEnd":1612844051935},"subject":"trade.l2update","topic":"/market/level2:SNX-BTC","type":"message"}
1619378336.193563: {"data":{"sequenceStart":1613277184645,"symbol":"BCHSV-USDT","changes":{"asks":[],"bids":[["0","0","1613277184645"]]},"sequenceEnd":1613277184645},"subject":"trade.l2update","topic":"/market/level2:BCHSV-USDT","type":"message"}
1619378336.193609: {"data":{"sequenceStart":1613277184646,"symbol":"BCHSV-USDT","changes":{"asks":[],"bids":[["242.095","20.43","1613277184646"]]},"sequenceEnd":1613277184646},"subject":"trade.l2update","topic":"/market/level2:BCHSV-USDT","type":"message"}
1619378336.210484: {"data":{"sequence":"1612712745664","bestAsk":"0.00000776","size":"401.2004","bestBidSize":"357.285","price":"0.00000772","time":1619378336167,"bestAskSize":"839","bestBid":"0.00000771"},"subject":"trade.ticker","topic":"/market/ticker:FET-BTC","type":"message"}
1619378336.210573: {"data":{"sequenceStart":1613277184647,"symbol":"BCHSV-USDT","changes":{"asks":[["242.993","0","1613277184647"]],"bids":[]},"sequenceEnd":1613277184647},"subject":"trade.l2update","topic":"/market/level2:BCHSV-USDT","type":"message"}
1619378336.21067: {"data":{"sequenceStart":1613277184648,"symbol":"BCHSV-USDT","changes":{"asks":[],"bids":[["242.52","0","1613277184648"]]},"sequenceEnd":1613277184648},"subject":"trade.l2update","topic":"/market/level2:BCHSV-USDT","type":"message"}
1619378336.210735: {"data":{"sequenceStart":1613277184649,"symbol":"BCHSV-USDT","changes":{"asks":[["245.582","0","1613277184649"]],"bids":[]},"sequenceEnd":1613277184649},"subject":"trade.l2update","topic":"/market/level2:BCHSV-USDT","type":"message"}
1619378336.214965: {"data":{"sequenceStart":1613277184650,"symbol":"BCHSV-USDT","changes":{"asks":[["0","0","1613277184650"]],"bids":[]},"sequenceEnd":1613277184650},"subject":"trade.l2update","topic":"/market/level2:BCHSV-USDT","type":"message"}
1619378336.215075: {"data":{"sequenceStart":1613277184651,"symbol":"BCHSV-USDT","changes":{"asks":[["243.321","0.6","1613277184651"]],"bids":[]},"sequenceEnd":1613277184651},"subject":"trade.l2update","topic":"/market/level2:BCHSV-USDT","type":"message"}
1619378336.229578: {"data":{"sequenceStart":1613277184652,"symbol":"BCHSV-USDT","changes":{"asks":[],"bids":[["241.703","0","1613277184652"]]},"sequenceEnd":1613277184652},"subject":"trade.l2update","topic":"/market/level2:BCHSV-USDT","type":"message"}
1619378336.2297149: {"data":{"sequenceStart":1613277184653,"symbol":"BCHSV-USDT","changes":{"asks":[["243.697","0","1613277184653"]],"bids":[]},"sequenceEnd":1613277184653},"subject":"trade.l2update","topic":"/market/level2:BCHSV-USDT","type":"message"}
1619378336.229822: {"data":{"sequenceStart":1613277184654,"symbol":"BCHSV-USDT","changes":{"asks":[],"bids":[["0","0","1613277184654"]]},"sequenceEnd":1613277184654},"subject":"trade.l2update","topic":"/market/level2:BCHSV-USDT","type":"message"}
1619378336.229852: {"data":{"sequenceStart":1613277184655,"symbol":"BCHSV-USDT","changes":{"asks":[],"bids":[["242.752","0.68148185","1613277184655"]]},"sequenceEnd":1613277184655},"subject":"trade.l2update","topic":"/market/level2:BCHSV-USDT","type":"message"}
1619378336.229889: {"data":{"sequenceStart":1613277184656,"symbol":"BCHSV-USDT","changes":{"asks":[],"bids":[["0","0","1613277184656"]]},"sequenceEnd":1613277184656},"subject":"trade.l2update","topic":"/market/level2:BCHSV-USDT","type":"message"}
1619378336.229913: {"data":{"sequenceStart":1613277184657,"symbol":"BCHSV-USDT","changes":{"asks":[],"bids":[["242.781","4.51280965","1613277184657"]]},"sequenceEnd":1613277184657},"subject":"trade.l2update","topic":"/market/level2:BCHSV-USDT","type":"message"}
1619378336.229941: {"data":{"sequenceStart":1613277184658,"symbol":"BCHSV-USDT","changes":{"asks":[["0","0","1613277184658"]],"bids":[]},"sequenceEnd":1613277184658},"subject":"trade.l2update","topic":"/market/level2:BCHSV-USDT","type":"message"}
1619378336.2299619: {"data":{"sequenceStart":1613277184659,"symbol":"BCHSV-USDT","changes":{"asks":[["243.021","4.51280965","1613277184659"]],"bids":[]},"sequenceEnd":1613277184659},"subject":"trade.l2update","topic":"/market/level2:BCHSV-USDT","type":"message"}
1619378336.236066: {"data":{"symbol":"BCHSV-USDT","sequence":"1613277184661","side":"sell","size":"0.14324938","price":"242.781","takerOrderId":"6085c0a0b3436b00064d456b","time":"1619378336197407320","type":"match","makerOrderId":"6085c0a0587c2000060d188c","tradeId":"6085c0a069bc50686d66da3c"},"subject":"trade.l3match","topic":"/market/match:BCHSV-USDT","type":"message"}
1619378336.2406678: {"data":{"sequenceStart":1613277184660,"symbol":"BCHSV-USDT","changes":{"asks":[["0","0","1613277184660"]],"bids":[]},"sequenceEnd":1613277184660},"subject":"trade.l2update","topic":"/market/level2:BCHSV-USDT","type":"message"}
1619378336.240778: {"data":{"sequenceStart":1613277184661,"symbol":"BCHSV-USDT","changes":{"asks":[],"bids":[["242.781","4.36956027","1613277184661"]]},"sequenceEnd":1613277184661},"subject":"trade.l2update","topic":"/market/level2:BCHSV-USDT","type":"message"}
1619378336.240844: {"data":{"sequenceStart":1613277184662,"symbol":"BCHSV-USDT","changes":{"asks":[["0","0","1613277184662"]],"bids":[]},"sequenceEnd":1613277184662},"subject":"trade.l2update","topic":"/market/level2:BCHSV-USDT","type":"message"}
1619378336.295703: {"data":{"sequence":"1612844051935","bestAsk":"0.00028711","size":"0.01745248","bestBidSize":"0.19100065","price":"0.00028676","time":1619378336223,"bestAskSize":"14.04224443","bestBid":"0.00028678"},"subject":"trade.ticker","topic":"/market/ticker:SNX-BTC","type":"message"}
1619378336.295795: {"data":{"sequenceStart":1613277184663,"symbol":"BCHSV-USDT","changes":{"asks":[],"bids":[["242.648","0","1613277184663"]]},"sequenceEnd":1613277184663},"subject":"trade.l2update","topic":"/market/level2:BCHSV-USDT","type":"message"}
1619378336.295889: {"data":{"sequenceStart":1613277184664,"symbol":"BCHSV-USDT","changes":{"asks":[],"bids":[["242.753","0","1613277184664"]]},"sequenceEnd":1613277184664},"subject":"trade.l2update","topic":"/market/level2:BCHSV-USDT","type":"message"}
1619378336.2959511: {"data":{"sequence":"1613277184664","bestAsk":"243.021","size":"0.14324938","bestBidSize":"4.36956027","price":"242.781","time":1619378336234,"bestAskSize":"4.51280965","bestBid":"242.781"},"subject":"trade.ticker","topic":"/market/ticker:BCHSV-USDT","type":"message"}
1619378336.296018: {"data":{"sequenceStart":1613277184665,"symbol":"BCHSV-USDT","changes":{"asks":[],"bids":[["0","0","1613277184665"]]},"sequenceEnd":1613277184665},"subject":"trade.l2update","topic":"/market/level2:BCHSV-USDT","type":"message"}
1619378336.296043: {"data":{"sequenceStart":1613277184666,"symbol":"BCHSV-USDT","changes":{"asks":[],"bids":[["242.754","5","1613277184666"]]},"sequenceEnd":1613277184666},"subject":"trade.l2update","topic":"/market/level2:BCHSV-USDT","type":"message"}
1619378336.29954: {"data":{"sequenceStart":1613277184667,"symbol":"BCHSV-USDT","changes":{"asks":[["0","0","1613277184667"]],"bids":[]},"sequenceEnd":1613277184667},"subject":"trade.l2update","topic":"/market/level2:BCHSV-USDT","type":"message"}
1619378336.299615: {"data":{"sequenceStart":1613277184668,"symbol":"BCHSV-USDT","changes":{"asks":[["243.848","20.43","1613277184668"]],"bids":[]},"sequenceEnd":1613277184668},"subject":"trade.l2update","topic":"/market/level2:BCHSV-USDT","type":"message"}
1619378336.37142: {"data":{"sequence":"1613277184668","bestAsk":"243.021","size":"0.14324938","bestBidSize":"4.36956027","price":"242.781","time":1619378336331,"bestAskSize":"4.51280965","bestBid":"242.781"},"subject":"trade.ticker","topic":"/market/ticker:BCHSV-USDT","type":"message"}
1619378336.415824: {"data":{"sequenceStart":1612712745665,"symbol":"FET-BTC","changes":{"asks":[["0.00000781","0","1612712745665"]],"bids":[]},"sequenceEnd":1612712745665},"subject":"trade.l2update","topic":"/market/level2:FET-BTC","type":"message"}
1619378336.4212039: {"data":{"sequenceStart":1613277184669,"symbol":"BCHSV-USDT","changes":{"asks":[["243.321","0","1613277184669"]],"bids":[]},"sequenceEnd":1613277184669},"subject":"trade.l2update","topic":"/market/level2:BCHSV-USDT","type":"message"}
1619378336.468241: {"data":{"sequence":"1613277184680","bestAsk":"243.021","size":"0.14324938","bestBidSize":"4.36956027","price":"242.781","time":1619378336433,"bestAskSize":"4.51280965","bestBid":"242.781"},"subject":"trade.ticker","topic":"/market/ticker:BCHSV-USDT","type":"message"}
1619378336.491859: {"data":{"sequenceStart":1612694580164,"symbol":"CAPP-BTC","changes":{"asks":[],"bids":[["0.0000001511","0","1612694580164"]]},"sequenceEnd":1612694580164},"subject":"trade.l2update","topic":"/market/level2:CAPP-BTC","type":"message"}
1619378336.492: {"data":{"sequenceStart":1613277184670,"symbol":"BCHSV-USDT","changes":{"asks":[],"bids":[["0","0","1613277184670"]]},"sequenceEnd":1613277184670},"subject":"trade.l2update","topic":"/market/level2:BCHSV-USDT","type":"message"}
1619378336.492054: {"data":{"sequenceStart":1613277184671,"symbol":"BCHSV-USDT","changes":{"asks":[],"bids":[["241.753","102.92","1613277184671"]]},"sequenceEnd":1613277184671},"subject":"trade.l2update","topic":"/market/level2:BCHSV-USDT","type":"message"}
1619378336.492117: {"data":{"sequenceStart":1613277184672,"symbol":"BCHSV-USDT","changes":{"asks":[["0","0","1613277184672"]],"bids":[]},"sequenceEnd":1613277184672},"subject":"trade.l2update","topic":"/market/level2:BCHSV-USDT","type":"message"}
1619378336.4921799: {"data":{"sequenceStart":1613277184673,"symbol":"BCHSV-USDT","changes":{"asks":[["251.609","125","1613277184673"]],"bids":[]},"sequenceEnd":1613277184673},"subject":"trade.l2update","topic":"/market/level2:BCHSV-USDT","type":"message"}
1619378336.492214: {"data":{"sequenceStart":1613277184674,"symbol":"BCHSV-USDT","changes":{"asks":[["0","0","1613277184674"]],"bids":[]},"sequenceEnd":1613277184674},"subject":"trade.l2update","topic":"/market/level2:BCHSV-USDT","type":"message"}
1619378336.4922361: {"data":{"sequenceStart":1613277184675,"symbol":"BCHSV-USDT","changes":{"asks":[["243.721","5","1613277184675"]],"bids":[]},"sequenceEnd":1613277184675},"subject":"trade.l2update","topic":"/market/level2:BCHSV-USDT","type":"message"}
1619378336.502333: {"data":{"sequenceStart":1613277184676,"symbol":"BCHSV-USDT","changes":{"asks":[["0","0","1613277184676"]],"bids":[]},"sequenceEnd":1613277184676},"subject":"trade.l2update","topic":"/market/level2:BCHSV-USDT","type":"message"}
1619378336.502448: {"data":{"sequenceStart":1613277184677,"symbol":"BCHSV-USDT","changes":{"asks":[["244.358","150","1613277184677"]],"bids":[]},"sequenceEnd":1613277184677},"subject":"trade.l2update","topic":"/market/level2:BCHSV-USDT","type":"message"}
1619378336.5025222: {"data":{"sequenceStart":1613277184678,"symbol":"BCHSV-USDT","changes":{"asks":[["0","0","1613277184678"]],"bids":[]},"sequenceEnd":1613277184678},"subject":"trade.l2update","topic":"/market/level2:BCHSV-USDT","type":"message"}
1619378336.502551: {"data":{"sequenceStart":1613277184679,"symbol":"BCHSV-USDT","changes":{"asks":[["243.322","0.6","1613277184679"]],"bids":[]},"sequenceEnd":1613277184679},"subject":"trade.l2update","topic":"/market/level2:BCHSV-USDT","type":"message"}
1619378336.502584: {"data":{"sequenceStart":1613277184680,"symbol":"BCHSV-USDT","changes":{"asks":[],"bids":[["242.754","0","1613277184680"]]},"sequenceEnd":1613277184680},"subject":"trade.l2update","topic":"/market/level2:BCHSV-USDT","type":"message"}
1619378336.502621: {"data":{"sequenceStart":1613277184681,"symbol":"BCHSV-USDT","changes":{"asks":[],"bids":[["0","0","1613277184681"]]},"sequenceEnd":1613277184681},"subject":"trade.l2update","topic":"/market/level2:BCHSV-USDT","type":"message"}
1619378336.502645: {"data":{"sequenceStart":1613277184682,"symbol":"BCHSV-USDT","changes":{"asks":[],"bids":[["241.56","5","1613277184682"]]},"sequenceEnd":1613277184682},"subject":"trade.l2update","topic":"/market/level2:BCHSV-USDT","type":"message"}
1619378336.502675: {"data":{"sequenceStart":1613277184683,"symbol":"BCHSV-USDT","changes":{"asks":[],"bids":[["0","0","1613277184683"]]},"sequenceEnd":1613277184683},"subject":"trade.l2update","topic":"/market/level2:BCHSV-USDT","type":"message"}
1619378336.5026948: {"data":{"sequenceStart":1613277184684,"symbol":"BCHSV-USDT","changes":{"asks":[],"bids":[["242.767","5","1613277184684"]]},"sequenceEnd":1613277184684},"subject":"trade.l2update","topic":"/market/level2:BCHSV-USDT","type":"message"}
1619378336.5027368: {"data":{"sequenceStart":1613277184685,"symbol":"BCHSV-USDT","changes":{"asks":[],"bids":[["242.348","2.99","1613277184685"]]},"sequenceEnd":1613277184685},"subject":"trade.l2update","topic":"/market/level2:BCHSV-USDT","type":"message"}
1619378336.502767: {"data":{"sequenceStart":1613277184686,"symbol":"BCHSV-USDT","changes":{"asks":[],"bids":[["242.348","0","1613277184686"]]},"sequenceEnd":1613277184686},"subject":"trade.l2update","topic":"/market/level2:BCHSV-USDT","type":"message"}
1619378336.5080059: {"data":{"sequence":"1612712745665","bestAsk":"0.00000776","size":"401.2004","bestBidSize":"357.285","price":"0.00000772","time":1619378336467,"bestAskSize":"839","bestBid":"0.00000771"},"subject":"trade.ticker","topic":"/market/ticker:FET-BTC","type":"message"}
1619378336.5081139: {"data":{"sequenceStart":1613277184687,"symbol":"BCHSV-USDT","changes":{"asks":[],"bids":[["242.752","0","1613277184687"]]},"sequenceEnd":1613277184687},"subject":"trade.l2update","topic":"/market/level2:BCHSV-USDT","type":"message"}
1619378336.5152152: {"data":{"sequenceStart":1613277184688,"symbol":"BCHSV-USDT","changes":{"asks":[],"bids":[["0","0","1613277184688"]]},"sequenceEnd":1613277184688},"subject":"trade.l2update","topic":"/market/level2:BCHSV-USDT","type":"message"}
1619378336.5153248: {"data":{"sequenceStart":1613277184689,"symbol":"BCHSV-USDT","changes":{"asks":[],"bids":[["242.765","0.68148185","1613277184689"]]},"sequenceEnd":1613277184689},"subject":"trade.l2update","topic":"/market/level2:BCHSV-USDT","type":"message"}
1619378336.5210612: {"data":{"sequenceStart":1612702190335,"symbol":"NRG-BTC","changes":{"asks":[["0.00006229","0","1612702190335"]],"bids":[]},"sequenceEnd":1612702190335},"subject":"trade.l2update","topic":"/market/level2:NRG-BTC","type":"message"}
1619378336.521204: {"data":{"sequenceStart":1612699351267,"symbol":"COV-BTC","changes":{"asks":[["0.00001127","4331.68226035","1612699351267"]],"bids":[]},"sequenceEnd":1612699351267},"subject":"trade.l2update","topic":"/market/level2:COV-BTC","type":"message"}
1619378336.5274339: {"data":{"sequence":"1612699351267","bestAsk":"0.00001127","size":"96.1525","bestBidSize":"49.6422","price":"0.00001126","time":1619378336488,"bestAskSize":"4331.68226035","bestBid":"0.00001121"},"subject":"trade.ticker","topic":"/market/ticker:COV-BTC","type":"message"}
1619378336.533159: {"data":{"sequence":"1612694580164","bestAsk":"0.0000002196","size":"1000.02","bestBidSize":"83.07","price":"0.0000002182","time":1619378336481,"bestAskSize":"4490.25","bestBid":"0.0000002181"},"subject":"trade.ticker","topic":"/market/ticker:CAPP-BTC","type":"message"}
1619378336.533258: {"data":{"sequence":"1612702190335","bestAsk":"0.00006218","size":"0.0431","bestBidSize":"19.5017","price":"0.00006141","time":1619378336491,"bestAskSize":"43.3399","bestBid":"0.00006141"},"subject":"trade.ticker","topic":"/market/ticker:NRG-BTC","type":"message"}
1619378336.533299: {"data":{"sequenceStart":1612694580165,"symbol":"CAPP-BTC","changes":{"asks":[["0.0000002196","4160","1612694580165"]],"bids":[]},"sequenceEnd":1612694580165},"subject":"trade.l2update","topic":"/market/level2:CAPP-BTC","type":"message"}
1619378336.53337: {"data":{"sequenceStart":1612734157835,"symbol":"ANKR-BTC","changes":{"asks":[["0.0000026255","0","1612734157835"]],"bids":[]},"sequenceEnd":1612734157835},"subject":"trade.l2update","topic":"/market/level2:ANKR-BTC","type":"message"}
1619378336.540781: {"data":{"sequenceStart":1613277184690,"symbol":"BCHSV-USDT","changes":{"asks":[["243.021","0","1613277184690"]],"bids":[]},"sequenceEnd":1613277184690},"subject":"trade.l2update","topic":"/market/level2:BCHSV-USDT","type":"message"}
1619378336.54092: {"data":{"sequenceStart":1613277184691,"symbol":"BCHSV-USDT","changes":{"asks":[],"bids":[["0","0","1613277184691"]]},"sequenceEnd":1613277184691},"subject":"trade.l2update","topic":"/market/level2:BCHSV-USDT","type":"message"}
1619378336.540988: {"data":{"sequenceStart":1613277184692,"symbol":"BCHSV-USDT","changes":{"asks":[],"bids":[["242.476","2.99","1613277184692"]]},"sequenceEnd":1613277184692},"subject":"trade.l2update","topic":"/market/level2:BCHSV-USDT","type":"message"}
1619378336.541064: {"data":{"sequenceStart":1612712745666,"symbol":"FET-BTC","changes":{"asks":[["0","0","1612712745666"]],"bids":[]},"sequenceEnd":1612712745666},"subject":"trade.l2update","topic":"/market/level2:FET-BTC","type":"message"}
1619378336.541091: {"data":{"sequenceStart":1612712745667,"symbol":"FET-BTC","changes":{"asks":[["0.0000078","4011.0844","1612712745667"]],"bids":[]},"sequenceEnd":1612712745667},"subject":"trade.l2update","topic":"/market/level2:FET-BTC","type":"message"}
1619378336.541127: {"data":{"sequenceStart":1612712745668,"symbol":"FET-BTC","changes":{"asks":[["0","0","1612712745668"]],"bids":[]},"sequenceEnd":1612712745668},"subject":"trade.l2update","topic":"/market/level2:FET-BTC","type":"message"}
1619378336.541149: {"data":{"sequenceStart":1612712745669,"symbol":"FET-BTC","changes":{"asks":[["0.00000776","1993.0416","1612712745669"]],"bids":[]},"sequenceEnd":1612712745669},"subject":"trade.l2update","topic":"/market/level2:FET-BTC","type":"message"}
1619378336.547088: {"data":{"sequenceStart":1613277184693,"symbol":"BCHSV-USDT","changes":{"asks":[["0","0","1613277184693"]],"bids":[]},"sequenceEnd":1613277184693},"subject":"trade.l2update","topic":"/market/level2:BCHSV-USDT","type":"message"}
1619378336.547198: {"data":{"sequenceStart":1613277184694,"symbol":"BCHSV-USDT","changes":{"asks":[["243.4","0.6","1613277184694"]],"bids":[]},"sequenceEnd":1613277184694},"subject":"trade.l2update","topic":"/market/level2:BCHSV-USDT","type":"message"}
1619378336.547276: {"data":{"sequenceStart":1613277184695,"symbol":"BCHSV-USDT","changes":{"asks":[],"bids":[["0","0","1613277184695"]]},"sequenceEnd":1613277184695},"subject":"trade.l2update","topic":"/market/level2:BCHSV-USDT","type":"message"}
1619378336.547317: {"data":{"sequenceStart":1613277184696,"symbol":"BCHSV-USDT","changes":{"asks":[],"bids":[["242.476","5.98","1613277184696"]]},"sequenceEnd":1613277184696},"subject":"trade.l2update","topic":"/market/level2:BCHSV-USDT","type":"message"}
1619378336.561853: {"data":{"sequenceStart":1612694580166,"symbol":"CAPP-BTC","changes":{"asks":[],"bids":[["0","0","1612694580166"]]},"sequenceEnd":1612694580166},"subject":"trade.l2update","topic":"/market/level2:CAPP-BTC","type":"message"}
1619378336.561959: {"data":{"sequenceStart":1612694580167,"symbol":"CAPP-BTC","changes":{"asks":[],"bids":[["0.0000002147","3048.2","1612694580167"]]},"sequenceEnd":1612694580167},"subject":"trade.l2update","topic":"/market/level2:CAPP-BTC","type":"message"}
1619378336.56654: {"data":{"sequenceStart":1612712745670,"symbol":"FET-BTC","changes":{"asks":[["0.0000078","0","1612712745670"]],"bids":[]},"sequenceEnd":1612712745670},"subject":"trade.l2update","topic":"/market/level2:FET-BTC","type":"message"}
1619378336.573162: {"data":{"sequence":"1613277184696","bestAsk":"243.073","size":"0.14324938","bestBidSize":"4.36956027","price":"242.781","time":1619378336533,"bestAskSize":"0.96","bestBid":"242.781"},"subject":"trade.ticker","topic":"/market/ticker:BCHSV-USDT","type":"message"}
1619378336.5819259: {"data":{"sequenceStart":1612734157836,"symbol":"ANKR-BTC","changes":{"asks":[],"bids":[["0.0000025953","0","1612734157836"]]},"sequenceEnd":1612734157836},"subject":"trade.l2update","topic":"/market/level2:ANKR-BTC","type":"message"}
1619378336.593169: {"data":{"sequenceStart":1612734157837,"symbol":"ANKR-BTC","changes":{"asks":[["0.0000026258","0","1612734157837"]],"bids":[]},"sequenceEnd":1612734157837},"subject":"trade.l2update","topic":"/market/level2:ANKR-BTC","type":"message"}
1619378336.597662: {"data":{"sequenceStart":1613277184697,"symbol":"BCHSV-USDT","changes":{"asks":[["243.322","0","1613277184697"]],"bids":[]},"sequenceEnd":1613277184697},"subject":"trade.l2update","topic":"/market/level2:BCHSV-USDT","type":"message"}
1619378336.597804: {"data":{"sequenceStart":1612734157838,"symbol":"ANKR-BTC","changes":{"asks":[],"bids":[["0.0000025818","0","1612734157838"]]},"sequenceEnd":1612734157838},"subject":"trade.l2update","topic":"/market/level2:ANKR-BTC","type":"message"}
1619378336.603539: {"data":{"sequence":"1612712745670","bestAsk":"0.00000776","size":"401.2004","bestBidSize":"357.285","price":"0.00000772","time":1619378336567,"bestAskSize":"1993.0416","bestBid":"0.00000771"},"subject":"trade.ticker","topic":"/market/ticker:FET-BTC","type":"message"}
1619378336.622046: {"data":{"sequence":"1612694580167","bestAsk":"0.0000002196","size":"1000.02","bestBidSize":"83.07","price":"0.0000002182","time":1619378336582,"bestAskSize":"4160","bestBid":"0.0000002181"},"subject":"trade.ticker","topic":"/market/ticker:CAPP-BTC","type":"message"}
1619378336.627511: {"data":{"sequence":"1612734157838","bestAsk":"0.0000026208","size":"46","bestBidSize":"5034.7285","price":"0.0000026071","time":1619378336588,"bestAskSize":"10987.6265","bestBid":"0.0000025995"},"subject":"trade.ticker","topic":"/market/ticker:ANKR-BTC","type":"message"}
1619378336.667768: {"data":{"sequence":"1613277184697","bestAsk":"243.073","size":"0.14324938","bestBidSize":"4.36956027","price":"242.781","time":1619378336630,"bestAskSize":"0.96","bestBid":"242.781"},"subject":"trade.ticker","topic":"/market/ticker:BCHSV-USDT","type":"message"}
1619378336.6678169: {"data":{"sequenceStart":1613277184698,"symbol":"BCHSV-USDT","changes":{"asks":[["244.162","0","1613277184698"]],"bids":[]},"sequenceEnd":1613277184698},"subject":"trade.l2update","topic":"/market/level2:BCHSV-USDT","type":"message"}
1619378336.667868: {"data":{"sequenceStart":1613277184699,"symbol":"BCHSV-USDT","changes":{"asks":[],"bids":[["242.767","0","1613277184699"]]},"sequenceEnd":1613277184699},"subject":"trade.l2update","topic":"/market/level2:BCHSV-USDT","type":"message"}
1619378336.667899: {"data":{"sequenceStart":1613277184700,"symbol":"BCHSV-USDT","changes":{"asks":[["243.555","0","1613277184700"]],"bids":[]},"sequenceEnd":1613277184700},"subject":"trade.l2update","topic":"/market/level2:BCHSV-USDT","type":"message"}
1619378336.673802: {"data":{"sequenceStart":1612844051936,"symbol":"SNX-BTC","changes":{"asks":[],"bids":[["0","0","1612844051936"]]},"sequenceEnd":1612844051936},"subject":"trade.l2update","topic":"/market/level2:SNX-BTC","type":"message"}
1619378336.673833: {"data":{"sequenceStart":1612844051937,"symbol":"SNX-BTC","changes":{"asks":[],"bids":[["0.00028658","5.23492568","1612844051937"]]},"sequenceEnd":1612844051937},"subject":"trade.l2update","topic":"/market/level2:SNX-BTC","type":"message"}
1619378336.6775649: {"data":{"sequenceStart":1613277184701,"symbol":"BCHSV-USDT","changes":{"asks":[],"bids":[["0","0","1613277184701"]]},"sequenceEnd":1613277184701},"subject":"trade.l2update","topic":"/market/level2:BCHSV-USDT","type":"message"}
1619378336.6776: {"data":{"sequenceStart":1613277184702,"symbol":"BCHSV-USDT","changes":{"asks":[],"bids":[["242.781","9.36956027","1613277184702"]]},"sequenceEnd":1613277184702},"subject":"trade.l2update","topic":"/market/level2:BCHSV-USDT","type":"message"}
1619378336.6993291: {"data":{"sequenceStart":1613277184703,"symbol":"BCHSV-USDT","changes":{"asks":[["243.4","0","1613277184703"]],"bids":[]},"sequenceEnd":1613277184703},"subject":"trade.l2update","topic":"/market/level2:BCHSV-USDT","type":"message"}
1619378336.6993868: {"data":{"sequenceStart":1613277184704,"symbol":"BCHSV-USDT","changes":{"asks":[],"bids":[["242.765","0","1613277184704"]]},"sequenceEnd":1613277184704},"subject":"trade.l2update","topic":"/market/level2:BCHSV-USDT","type":"message"}
1619378336.718775: {"data":{"sequenceStart":1612844051938,"symbol":"SNX-BTC","changes":{"asks":[],"bids":[["0.00028622","0","1612844051938"]]},"sequenceEnd":1612844051938},"subject":"trade.l2update","topic":"/market/level2:SNX-BTC","type":"message"}
1619378336.724402: {"data":{"sequenceStart":1613277184705,"symbol":"BCHSV-USDT","changes":{"asks":[],"bids":[["0","0","1613277184705"]]},"sequenceEnd":1613277184705},"subject":"trade.l2update","topic":"/market/level2:BCHSV-USDT","type":"message"}
1619378336.724438: {"data":{"sequenceStart":1613277184706,"symbol":"BCHSV-USDT","changes":{"asks":[],"bids":[["242.779","0.68148185","1613277184706"]]},"sequenceEnd":1613277184706},"subject":"trade.l2update","topic":"/market/level2:BCHSV-USDT","type":"message"}
1619378336.724468: {"data":{"sequenceStart":1613277184707,"symbol":"BCHSV-USDT","changes":{"asks":[["0","0","1613277184707"]],"bids":[]},"sequenceEnd":1613277184707},"subject":"trade.l2update","topic":"/market/level2:BCHSV-USDT","type":"message"}
1619378336.724483: {"data":{"sequenceStart":1613277184708,"symbol":"BCHSV-USDT","changes":{"asks":[["243.408","0.6","1613277184708"]],"bids":[]},"sequenceEnd":1613277184708},"subject":"trade.l2update","topic":"/market/level2:BCHSV-USDT","type":"message"}
1619378336.7404218: {"data":{"sequenceStart":1613277184709,"symbol":"BCHSV-USDT","changes":{"asks":[["0","0","1613277184709"]],"bids":[]},"sequenceEnd":1613277184709},"subject":"trade.l2update","topic":"/market/level2:BCHSV-USDT","type":"message"}
1619378336.74047: {"data":{"sequenceStart":1613277184710,"symbol":"BCHSV-USDT","changes":{"asks":[["243.655","5.52","1613277184710"]],"bids":[]},"sequenceEnd":1613277184710},"subject":"trade.l2update","topic":"/market/level2:BCHSV-USDT","type":"message"}
1619378336.7405: {"data":{"sequenceStart":1613277184711,"symbol":"BCHSV-USDT","changes":{"asks":[["0","0","1613277184711"]],"bids":[]},"sequenceEnd":1613277184711},"subject":"trade.l2update","topic":"/market/level2:BCHSV-USDT","type":"message"}
1619378336.740515: {"data":{"sequenceStart":1613277184712,"symbol":"BCHSV-USDT","changes":{"asks":[["244.262","102.92","1613277184712"]],"bids":[]},"sequenceEnd":1613277184712},"subject":"trade.l2update","topic":"/market/level2:BCHSV-USDT","type":"message"}
1619378336.751532: {"data":{"sequenceStart":1612734157839,"symbol":"ANKR-BTC","changes":{"asks":[["0","0","1612734157839"]],"bids":[]},"sequenceEnd":1612734157839},"subject":"trade.l2update","topic":"/market/level2:ANKR-BTC","type":"message"}
1619378336.751563: {"data":{"sequenceStart":1612734157840,"symbol":"ANKR-BTC","changes":{"asks":[["0.0000026308","20000","1612734157840"]],"bids":[]},"sequenceEnd":1612734157840},"subject":"trade.l2update","topic":"/market/level2:ANKR-BTC","type":"message"}
1619378336.7615192: {"data":{"sequence":"1612844051938","bestAsk":"0.00028711","size":"0.01745248","bestBidSize":"0.19100065","price":"0.00028676","time":1619378336723,"bestAskSize":"14.04224443","bestBid":"0.00028678"},"subject":"trade.ticker","topic":"/market/ticker:SNX-BTC","type":"message"}
1619378336.7672908: {"data":{"sequence":"1613277184712","bestAsk":"243.073","size":"0.14324938","bestBidSize":"9.36956027","price":"242.781","time":1619378336730,"bestAskSize":"0.96","bestBid":"242.781"},"subject":"trade.ticker","topic":"/market/ticker:BCHSV-USDT","type":"message"}
1619378336.806467: {"data":{"sequenceStart":1612844051939,"symbol":"SNX-BTC","changes":{"asks":[],"bids":[["0.00028658","0","1612844051939"]]},"sequenceEnd":1612844051939},"subject":"trade.l2update","topic":"/market/level2:SNX-BTC","type":"message"}
1619378336.812086: {"data":{"sequenceStart":1612701563976,"symbol":"DAPPT-BTC","changes":{"asks":[],"bids":[["0.000000112","0","1612701563976"]]},"sequenceEnd":1612701563976},"subject":"trade.l2update","topic":"/market/level2:DAPPT-BTC","type":"message"}
1619378336.816714: {"data":{"sequenceStart":1612734157841,"symbol":"ANKR-BTC","changes":{"asks":[],"bids":[["0.0000025994","0","1612734157841"]]},"sequenceEnd":1612734157841},"subject":"trade.l2update","topic":"/market/level2:ANKR-BTC","type":"message"}
1619378336.826987: {"data":{"sequence":"1612734157841","bestAsk":"0.0000026208","size":"46","bestBidSize":"5034.7285","price":"0.0000026071","time":1619378336788,"bestAskSize":"10987.6265","bestBid":"0.0000025995"},"subject":"trade.ticker","topic":"/market/ticker:ANKR-BTC","type":"message"}
1619378336.8551009: {"data":{"sequenceStart":1613277184713,"symbol":"BCHSV-USDT","changes":{"asks":[],"bids":[["242.475","0","1613277184713"]]},"sequenceEnd":1613277184713},"subject":"trade.l2update","topic":"/market/level2:BCHSV-USDT","type":"message"}
1619378336.8551638: {"data":{"sequenceStart":1613277184714,"symbol":"BCHSV-USDT","changes":{"asks":[["243.721","0","1613277184714"]],"bids":[]},"sequenceEnd":1613277184714},"subject":"trade.l2update","topic":"/market/level2:BCHSV-USDT","type":"message"}
1619378336.855192: {"data":{"sequenceStart":1613277184715,"symbol":"BCHSV-USDT","changes":{"asks":[["243.938","0","1613277184715"]],"bids":[]},"sequenceEnd":1613277184715},"subject":"trade.l2update","topic":"/market/level2:BCHSV-USDT","type":"message"}
1619378336.855212: {"data":{"sequenceStart":1613277184716,"symbol":"BCHSV-USDT","changes":{"asks":[["244.358","0","1613277184716"]],"bids":[]},"sequenceEnd":1613277184716},"subject":"trade.l2update","topic":"/market/level2:BCHSV-USDT","type":"message"}
1619378336.855229: {"data":{"sequenceStart":1613277184717,"symbol":"BCHSV-USDT","changes":{"asks":[],"bids":[["241.56","0","1613277184717"]]},"sequenceEnd":1613277184717},"subject":"trade.l2update","topic":"/market/level2:BCHSV-USDT","type":"message"}
1619378336.860044: {"data":{"sequenceStart":1612844051940,"symbol":"SNX-BTC","changes":{"asks":[],"bids":[["0","0","1612844051940"]]},"sequenceEnd":1612844051940},"subject":"trade.l2update","topic":"/market/level2:SNX-BTC","type":"message"}
1619378336.8600771: {"data":{"sequenceStart":1612844051941,"symbol":"SNX-BTC","changes":{"asks":[],"bids":[["0.00028654","1.74521882","1612844051941"]]},"sequenceEnd":1612844051941},"subject":"trade.l2update","topic":"/market/level2:SNX-BTC","type":"message"}
1619378336.860107: {"data":{"sequence":"1612844051941","bestAsk":"0.00028711","size":"0.01745248","bestBidSize":"0.19100065","price":"0.00028676","time":1619378336823,"bestAskSize":"14.04224443","bestBid":"0.00028678"},"subject":"trade.ticker","topic":"/market/ticker:SNX-BTC","type":"message"}
1619378336.874144: {"data":{"sequence":"1612701563976","bestAsk":"0.000000113","size":"145.4959","bestBidSize":"361.2609","price":"0.0000001126","time":1619378336830,"bestAskSize":"1208.0878","bestBid":"0.0000001119"},"subject":"trade.ticker","topic":"/market/ticker:DAPPT-BTC","type":"message"}
1619378336.8741848: {"data":{"sequence":"1613277184717","bestAsk":"243.073","size":"0.14324938","bestBidSize":"9.36956027","price":"242.781","time":1619378336833,"bestAskSize":"0.96","bestBid":"242.781"},"subject":"trade.ticker","topic":"/market/ticker:BCHSV-USDT","type":"message"}
1619378336.880789: {"data":{"sequenceStart":1613277184718,"symbol":"BCHSV-USDT","changes":{"asks":[],"bids":[["242.781","4.36956027","1613277184718"]]},"sequenceEnd":1613277184718},"subject":"trade.l2update","topic":"/market/level2:BCHSV-USDT","type":"message"}
1619378336.89201: {"data":{"sequenceStart":1613277184719,"symbol":"BCHSV-USDT","changes":{"asks":[],"bids":[["0","0","1613277184719"]]},"sequenceEnd":1613277184719},"subject":"trade.l2update","topic":"/market/level2:BCHSV-USDT","type":"message"}
1619378336.892052: {"data":{"sequenceStart":1613277184720,"symbol":"BCHSV-USDT","changes":{"asks":[],"bids":[["242.795","5","1613277184720"]]},"sequenceEnd":1613277184720},"subject":"trade.l2update","topic":"/market/level2:BCHSV-USDT","type":"message"}
1619378336.909971: {"data":{"sequenceStart":1612734157842,"symbol":"ANKR-BTC","changes":{"asks":[],"bids":[["0","0","1612734157842"]]},"sequenceEnd":1612734157842},"subject":"trade.l2update","topic":"/market/level2:ANKR-BTC","type":"message"}
1619378336.910081: {"data":{"sequenceStart":1612734157843,"symbol":"ANKR-BTC","changes":{"asks":[],"bids":[["0.0000025996","3499.2011","1612734157843"]]},"sequenceEnd":1612734157843},"subject":"trade.l2update","topic":"/market/level2:ANKR-BTC","type":"message"}
1619378336.915204: {"data":{"sequenceStart":1613277184721,"symbol":"BCHSV-USDT","changes":{"asks":[["243.408","0","1613277184721"]],"bids":[]},"sequenceEnd":1613277184721},"subject":"trade.l2update","topic":"/market/level2:BCHSV-USDT","type":"message"}
1619378336.915345: {"data":{"sequenceStart":1612844051942,"symbol":"SNX-BTC","changes":{"asks":[],"bids":[["0.00028654","0","1612844051942"]]},"sequenceEnd":1612844051942},"subject":"trade.l2update","topic":"/market/level2:SNX-BTC","type":"message"}
1619378336.927424: {"data":{"sequenceStart":1613277184722,"symbol":"BCHSV-USDT","changes":{"asks":[],"bids":[["242.779","0","1613277184722"]]},"sequenceEnd":1613277184722},"subject":"trade.l2update","topic":"/market/level2:BCHSV-USDT","type":"message"}
1619378336.927567: {"data":{"sequenceStart":1613277184723,"symbol":"BCHSV-USDT","changes":{"asks":[],"bids":[["0","0","1613277184723"]]},"sequenceEnd":1613277184723},"subject":"trade.l2update","topic":"/market/level2:BCHSV-USDT","type":"message"}
1619378336.927637: {"data":{"sequenceStart":1613277184724,"symbol":"BCHSV-USDT","changes":{"asks":[],"bids":[["240.355","2.08025627","1613277184724"]]},"sequenceEnd":1613277184724},"subject":"trade.l2update","topic":"/market/level2:BCHSV-USDT","type":"message"}
1619378336.927697: {"data":{"sequence":"1612734157843","bestAsk":"0.0000026208","size":"46","bestBidSize":"3499.2011","price":"0.0000026071","time":1619378336888,"bestAskSize":"10987.6265","bestBid":"0.0000025996"},"subject":"trade.ticker","topic":"/market/ticker:ANKR-BTC","type":"message"}
1619378336.932269: {"data":{"sequenceStart":1612734157844,"symbol":"ANKR-BTC","changes":{"asks":[],"bids":[["0.0000025995","0","1612734157844"]]},"sequenceEnd":1612734157844},"subject":"trade.l2update","topic":"/market/level2:ANKR-BTC","type":"message"}
1619378336.9324238: {"data":{"sequenceStart":1613277184725,"symbol":"BCHSV-USDT","changes":{"asks":[],"bids":[["0","0","1613277184725"]]},"sequenceEnd":1613277184725},"subject":"trade.l2update","topic":"/market/level2:BCHSV-USDT","type":"message"}
1619378336.932478: {"data":{"sequenceStart":1613277184726,"symbol":"BCHSV-USDT","changes":{"asks":[],"bids":[["242.792","0.68148185","1613277184726"]]},"sequenceEnd":1613277184726},"subject":"trade.l2update","topic":"/market/level2:BCHSV-USDT","type":"message"}
1619378336.932541: {"data":{"sequenceStart":1613277184727,"symbol":"BCHSV-USDT","changes":{"asks":[["0","0","1613277184727"]],"bids":[]},"sequenceEnd":1613277184727},"subject":"trade.l2update","topic":"/market/level2:BCHSV-USDT","type":"message"}
1619378336.932579: {"data":{"sequenceStart":1613277184728,"symbol":"BCHSV-USDT","changes":{"asks":[["243.435","0.6","1613277184728"]],"bids":[]},"sequenceEnd":1613277184728},"subject":"trade.l2update","topic":"/market/level2:BCHSV-USDT","type":"message"}
1619378336.932631: {"data":{"sequenceStart":1612701563977,"symbol":"DAPPT-BTC","changes":{"asks":[],"bids":[["0","0","1612701563977"]]},"sequenceEnd":1612701563977},"subject":"trade.l2update","topic":"/market/level2:DAPPT-BTC","type":"message"}
1619378336.932666: {"data":{"sequenceStart":1612701563978,"symbol":"DAPPT-BTC","changes":{"asks":[],"bids":[["0.000000112","5148.7686","1612701563978"]]},"sequenceEnd":1612701563978},"subject":"trade.l2update","topic":"/market/level2:DAPPT-BTC","type":"message"}
1619378336.939189: {"data":{"sequenceStart":1612734157845,"symbol":"ANKR-BTC","changes":{"asks":[],"bids":[["0.0000025996","0","1612734157845"]]},"sequenceEnd":1612734157845},"subject":"trade.l2update","topic":"/market/level2:ANKR-BTC","type":"message"}
1619378336.956492: {"data":{"sequenceStart":1612844051943,"symbol":"SNX-BTC","changes":{"asks":[["0","0","1612844051943"]],"bids":[]},"sequenceEnd":1612844051943},"subject":"trade.l2update","topic":"/market/level2:SNX-BTC","type":"message"}
1619378336.956542: {"data":{"sequenceStart":1612844051944,"symbol":"SNX-BTC","changes":{"asks":[["0.00028712","102.64027861","1612844051944"]],"bids":[]},"sequenceEnd":1612844051944},"subject":"trade.l2update","topic":"/market/level2:SNX-BTC","type":"message"}
1619378336.9603798: {"data":{"sequenceStart":1612701563979,"symbol":"DAPPT-BTC","changes":{"asks":[],"bids":[["0.000000112","0","1612701563979"]]},"sequenceEnd":1612701563979},"subject":"trade.l2update","topic":"/market/level2:DAPPT-BTC","type":"message"}
1619378336.960432: {"data":{"sequence":"1612844051944","bestAsk":"0.00028711","size":"0.01745248","bestBidSize":"0.19100065","price":"0.00028676","time":1619378336923,"bestAskSize":"14.04224443","bestBid":"0.00028678"},"subject":"trade.ticker","topic":"/market/ticker:SNX-BTC","type":"message"}
1619378336.960454: {"data":{"sequenceStart":1612734157846,"symbol":"ANKR-BTC","changes":{"asks":[],"bids":[["0","0","1612734157846"]]},"sequenceEnd":1612734157846},"subject":"trade.l2update","topic":"/market/level2:ANKR-BTC","type":"message"}
1619378336.960475: {"data":{"sequenceStart":1612734157847,"symbol":"ANKR-BTC","changes":{"asks":[],"bids":[["0.0000025997","5034.7285","1612734157847"]]},"sequenceEnd":1612734157847},"subject":"trade.l2update","topic":"/market/level2:ANKR-BTC","type":"message"}
1619378336.9660878: {"data":{"sequenceStart":1612844051945,"symbol":"SNX-BTC","changes":{"asks":[],"bids":[["0","0","1612844051945"]]},"sequenceEnd":1612844051945},"subject":"trade.l2update","topic":"/market/level2:SNX-BTC","type":"message"}
1619378336.966123: {"data":{"sequenceStart":1612844051946,"symbol":"SNX-BTC","changes":{"asks":[],"bids":[["0.00028656","14.06950524","1612844051946"]]},"sequenceEnd":1612844051946},"subject":"trade.l2update","topic":"/market/level2:SNX-BTC","type":"message"}
1619378336.966154: {"data":{"sequenceStart":1612844051947,"symbol":"SNX-BTC","changes":{"asks":[["0.00028711","0","1612844051947"]],"bids":[]},"sequenceEnd":1612844051947},"subject":"trade.l2update","topic":"/market/level2:SNX-BTC","type":"message"}
1619378336.971942: {"data":{"sequence":"1612701563979","bestAsk":"0.000000113","size":"145.4959","bestBidSize":"361.2609","price":"0.0000001126","time":1619378336930,"bestAskSize":"1208.0878","bestBid":"0.0000001119"},"subject":"trade.ticker","topic":"/market/ticker:DAPPT-BTC","type":"message"}
1619378336.9719748: {"data":{"sequence":"1613277184728","bestAsk":"243.073","size":"0.14324938","bestBidSize":"5","price":"242.781","time":1619378336933,"bestAskSize":"0.96","bestBid":"242.795"},"subject":"trade.ticker","topic":"/market/ticker:BCHSV-USDT","type":"message"}
1619378336.991988: {"data":{"sequenceStart":1612712745671,"symbol":"FET-BTC","changes":{"asks":[],"bids":[["0.00000769","20","1612712745671"]]},"sequenceEnd":1612712745671},"subject":"trade.l2update","topic":"/market/level2:FET-BTC","type":"message"}
1619378336.997269: {"data":{"sequenceStart":1612844051948,"symbol":"SNX-BTC","changes":{"asks":[["0.00028712","73.39457178","1612844051948"]],"bids":[]},"sequenceEnd":1612844051948},"subject":"trade.l2update","topic":"/market/level2:SNX-BTC","type":"message"}
1619378337.0118332: {"data":{"sequenceStart":1612844051949,"symbol":"SNX-BTC","changes":{"asks":[],"bids":[["0","0","1612844051949"]]},"sequenceEnd":1612844051949},"subject":"trade.l2update","topic":"/market/level2:SNX-BTC","type":"message"}
1619378337.011868: {"data":{"sequenceStart":1612844051950,"symbol":"SNX-BTC","changes":{"asks":[],"bids":[["0.0002861","36.78810969","1612844051950"]]},"sequenceEnd":1612844051950},"subject":"trade.l2update","topic":"/market/level2:SNX-BTC","type":"message"}
1619378337.01189: {"data":{"sequenceStart":1612844051951,"symbol":"SNX-BTC","changes":{"asks":[["0","0","1612844051951"]],"bids":[]},"sequenceEnd":1612844051951},"subject":"trade.l2update","topic":"/market/level2:SNX-BTC","type":"message"}
1619378337.011904: {"data":{"sequenceStart":1612844051952,"symbol":"SNX-BTC","changes":{"asks":[["0.00028711","29.24570683","1612844051952"]],"bids":[]},"sequenceEnd":1612844051952},"subject":"trade.l2update","topic":"/market/level2:SNX-BTC","type":"message"}
1619378337.0119328: {"data":{"sequenceStart":1612734157848,"symbol":"ANKR-BTC","changes":{"asks":[],"bids":[["0","0","1612734157848"]]},"sequenceEnd":1612734157848},"subject":"trade.l2update","topic":"/market/level2:ANKR-BTC","type":"message"}
1619378337.011946: {"data":{"sequenceStart":1612734157849,"symbol":"ANKR-BTC","changes":{"asks":[],"bids":[["0.0000025962","2307.9497","1612734157849"]]},"sequenceEnd":1612734157849},"subject":"trade.l2update","topic":"/market/level2:ANKR-BTC","type":"message"}
1619378337.011963: {"data":{"sequenceStart":1612734157850,"symbol":"ANKR-BTC","changes":{"asks":[],"bids":[["0","0","1612734157850"]]},"sequenceEnd":1612734157850},"subject":"trade.l2update","topic":"/market/level2:ANKR-BTC","type":"message"}
1619378337.0119748: {"data":{"sequenceStart":1612734157851,"symbol":"ANKR-BTC","changes":{"asks":[],"bids":[["0.0000025997","13195.4916","1612734157851"]]},"sequenceEnd":1612734157851},"subject":"trade.l2update","topic":"/market/level2:ANKR-BTC","type":"message"}
1619378337.0119889: {"data":{"sequence":"1612712745671","bestAsk":"0.00000776","size":"401.2004","bestBidSize":"357.285","price":"0.00000772","time":1619378336967,"bestAskSize":"1993.0416","bestBid":"0.00000771"},"subject":"trade.ticker","topic":"/market/ticker:FET-BTC","type":"message"}
1619378337.0290089: {"data":{"sequenceStart":1612734157852,"symbol":"ANKR-BTC","changes":{"asks":[],"bids":[["0.0000025962","0","1612734157852"]]},"sequenceEnd":1612734157852},"subject":"trade.l2update","topic":"/market/level2:ANKR-BTC","type":"message"}
1619378337.029105: {"data":{"sequence":"1612734157852","bestAsk":"0.0000026208","size":"46","bestBidSize":"13195.4916","price":"0.0000026071","time":1619378336988,"bestAskSize":"10987.6265","bestBid":"0.0000025997"},"subject":"trade.ticker","topic":"/market/ticker:ANKR-BTC","type":"message"}
1619378337.033468: {"data":{"sequenceStart":1612701563980,"symbol":"DAPPT-BTC","changes":{"asks":[],"bids":[["0","0","1612701563980"]]},"sequenceEnd":1612701563980},"subject":"trade.l2update","topic":"/market/level2:DAPPT-BTC","type":"message"}
1619378337.033493: {"data":{"sequenceStart":1612701563981,"symbol":"DAPPT-BTC","changes":{"asks":[],"bids":[["0.000000112","5148.7223","1612701563981"]]},"sequenceEnd":1612701563981},"subject":"trade.l2update","topic":"/market/level2:DAPPT-BTC","type":"message"}
1619378337.0443342: {"data":{"sequenceStart":1612844051953,"symbol":"SNX-BTC","changes":{"asks":[],"bids":[["0.00028656","0","1612844051953"]]},"sequenceEnd":1612844051953},"subject":"trade.l2update","topic":"/market/level2:SNX-BTC","type":"message"}
1619378337.044372: {"data":{"sequenceStart":1612844051954,"symbol":"SNX-BTC","changes":{"asks":[],"bids":[["0.0002861","35.16464552","1612844051954"]]},"sequenceEnd":1612844051954},"subject":"trade.l2update","topic":"/market/level2:SNX-BTC","type":"message"}
1619378337.044391: {"data":{"sequenceStart":1612844051955,"symbol":"SNX-BTC","changes":{"asks":[["0","0","1612844051955"]],"bids":[]},"sequenceEnd":1612844051955},"subject":"trade.l2update","topic":"/market/level2:SNX-BTC","type":"message"}
1619378337.044404: {"data":{"sequenceStart":1612844051956,"symbol":"SNX-BTC","changes":{"asks":[["0.00028711","43.28893935","1612844051956"]],"bids":[]},"sequenceEnd":1612844051956},"subject":"trade.l2update","topic":"/market/level2:SNX-BTC","type":"message"}
1619378337.060383: {"data":{"sequence":"1612844051956","bestAsk":"0.00028711","size":"0.01745248","bestBidSize":"0.19100065","price":"0.00028676","time":1619378337023,"bestAskSize":"43.28893935","bestBid":"0.00028678"},"subject":"trade.ticker","topic":"/market/ticker:SNX-BTC","type":"message"}
1619378337.069841: {"data":{"sequence":"1612701563981","bestAsk":"0.000000113","size":"145.4959","bestBidSize":"5148.7223","price":"0.0000001126","time":1619378337030,"bestAskSize":"1208.0878","bestBid":"0.000000112"},"subject":"trade.ticker","topic":"/market/ticker:DAPPT-BTC","type":"message"}
1619378337.080538: {"data":{"sequenceStart":1612844051957,"symbol":"SNX-BTC","changes":{"asks":[["0.00028711","29.24570683","1612844051957"]],"bids":[]},"sequenceEnd":1612844051957},"subject":"trade.l2update","topic":"/market/level2:SNX-BTC","type":"message"}
1619378337.085932: {"data":{"sequenceStart":1612844051958,"symbol":"SNX-BTC","changes":{"asks":[],"bids":[["0","0","1612844051958"]]},"sequenceEnd":1612844051958},"subject":"trade.l2update","topic":"/market/level2:SNX-BTC","type":"message"}
1619378337.085959: {"data":{"sequenceStart":1612844051959,"symbol":"SNX-BTC","changes":{"asks":[],"bids":[["0.00028653","14.07096874","1612844051959"]]},"sequenceEnd":1612844051959},"subject":"trade.l2update","topic":"/market/level2:SNX-BTC","type":"message"}
1619378337.102305: {"data":{"sequenceStart":1613277184729,"symbol":"BCHSV-USDT","changes":{"asks":[],"bids":[["242.792","0","1613277184729"]]},"sequenceEnd":1613277184729},"subject":"trade.l2update","topic":"/market/level2:BCHSV-USDT","type":"message"}
1619378337.113684: {"data":{"sequenceStart":1613277184730,"symbol":"BCHSV-USDT","changes":{"asks":[["243.435","0","1613277184730"]],"bids":[]},"sequenceEnd":1613277184730},"subject":"trade.l2update","topic":"/market/level2:BCHSV-USDT","type":"message"}
1619378337.113738: {"data":{"sequenceStart":1613277184731,"symbol":"BCHSV-USDT","changes":{"asks":[["0","0","1613277184731"]],"bids":[]},"sequenceEnd":1613277184731},"subject":"trade.l2update","topic":"/market/level2:BCHSV-USDT","type":"message"}
1619378337.113754: {"data":{"sequenceStart":1613277184732,"symbol":"BCHSV-USDT","changes":{"asks":[["244.155","28.81671351","1613277184732"]],"bids":[]},"sequenceEnd":1613277184732},"subject":"trade.l2update","topic":"/market/level2:BCHSV-USDT","type":"message"}
1619378337.121073: {"data":{"sequenceStart":1612844051960,"symbol":"SNX-BTC","changes":{"asks":[],"bids":[["0","0","1612844051960"]]},"sequenceEnd":1612844051960},"subject":"trade.l2update","topic":"/market/level2:SNX-BTC","type":"message"}
1619378337.121103: {"data":{"sequenceStart":1612844051961,"symbol":"SNX-BTC","changes":{"asks":[],"bids":[["0.0002861","36.78810969","1612844051961"]]},"sequenceEnd":1612844051961},"subject":"trade.l2update","topic":"/market/level2:SNX-BTC","type":"message"}
1619378337.156197: {"data":{"sequenceStart":1613277184733,"symbol":"BCHSV-USDT","changes":{"asks":[],"bids":[["0","0","1613277184733"]]},"sequenceEnd":1613277184733},"subject":"trade.l2update","topic":"/market/level2:BCHSV-USDT","type":"message"}
1619378337.1562471: {"data":{"sequenceStart":1613277184734,"symbol":"BCHSV-USDT","changes":{"asks":[],"bids":[["242.795","5.68148185","1613277184734"]]},"sequenceEnd":1613277184734},"subject":"trade.l2update","topic":"/market/level2:BCHSV-USDT","type":"message"}
1619378337.1562681: {"data":{"sequenceStart":1613277184735,"symbol":"BCHSV-USDT","changes":{"asks":[["0","0","1613277184735"]],"bids":[]},"sequenceEnd":1613277184735},"subject":"trade.l2update","topic":"/market/level2:BCHSV-USDT","type":"message"}
1619378337.156281: {"data":{"sequenceStart":1613277184736,"symbol":"BCHSV-USDT","changes":{"asks":[["243.433","0.6","1613277184736"]],"bids":[]},"sequenceEnd":1613277184736},"subject":"trade.l2update","topic":"/market/level2:BCHSV-USDT","type":"message"}
1619378337.156302: {"data":{"sequenceStart":1613277184737,"symbol":"BCHSV-USDT","changes":{"asks":[],"bids":[["0","0","1613277184737"]]},"sequenceEnd":1613277184737},"subject":"trade.l2update","topic":"/market/level2:BCHSV-USDT","type":"message"}
1619378337.1563132: {"data":{"sequenceStart":1613277184738,"symbol":"BCHSV-USDT","changes":{"asks":[],"bids":[["242.579","6.1735685","1613277184738"]]},"sequenceEnd":1613277184738},"subject":"trade.l2update","topic":"/market/level2:BCHSV-USDT","type":"message"}
1619378337.156328: {"data":{"sequenceStart":1613277184739,"symbol":"BCHSV-USDT","changes":{"asks":[],"bids":[["242.521","0","1613277184739"]]},"sequenceEnd":1613277184739},"subject":"trade.l2update","topic":"/market/level2:BCHSV-USDT","type":"message"}
1619378337.166143: {"data":{"sequence":"1612844051961","bestAsk":"0.00028711","size":"0.01745248","bestBidSize":"0.19100065","price":"0.00028676","time":1619378337123,"bestAskSize":"29.24570683","bestBid":"0.00028678"},"subject":"trade.ticker","topic":"/market/ticker:SNX-BTC","type":"message"}
1619378337.178347: {"data":{"sequence":"1613277184739","bestAsk":"243.073","size":"0.14324938","bestBidSize":"5.68148185","price":"242.781","time":1619378337133,"bestAskSize":"0.96","bestBid":"242.795"},"subject":"trade.ticker","topic":"/market/ticker:BCHSV-USDT","type":"message"}
1619378337.17841: {"data":{"sequenceStart":1613277184740,"symbol":"BCHSV-USDT","changes":{"asks":[],"bids":[["242.795","0.68148185","1613277184740"]]},"sequenceEnd":1613277184740},"subject":"trade.l2update","topic":"/market/level2:BCHSV-USDT","type":"message"}
1619378337.184269: {"data":{"sequenceStart":1613277184741,"symbol":"BCHSV-USDT","changes":{"asks":[],"bids":[["0","0","1613277184741"]]},"sequenceEnd":1613277184741},"subject":"trade.l2update","topic":"/market/level2:BCHSV-USDT","type":"message"}
1619378337.1843321: {"data":{"sequenceStart":1613277184742,"symbol":"BCHSV-USDT","changes":{"asks":[],"bids":[["242.797","5","1613277184742"]]},"sequenceEnd":1613277184742},"subject":"trade.l2update","topic":"/market/level2:BCHSV-USDT","type":"message"}
1619378337.209012: {"data":{"sequenceStart":1619079123947,"symbol":"EQZ-BTC","changes":{"asks":[],"bids":[["0","0","1619079123947"]]},"sequenceEnd":1619079123947},"subject":"trade.l2update","topic":"/market/level2:EQZ-BTC","type":"message"}
1619378337.26445: {"data":{"sequenceStart":1613277184743,"symbol":"BCHSV-USDT","changes":{"asks":[],"bids":[["242.797","0","1613277184743"]]},"sequenceEnd":1613277184743},"subject":"trade.l2update","topic":"/market/level2:BCHSV-USDT","type":"message"}
1619378337.2684002: {"data":{"sequence":"1613277184743","bestAsk":"243.073","size":"0.14324938","bestBidSize":"0.68148185","price":"242.781","time":1619378337230,"bestAskSize":"0.96","bestBid":"242.795"},"subject":"trade.ticker","topic":"/market/ticker:BCHSV-USDT","type":"message"}
1619378337.278731: {"data":{"sequence":"1619079123947","bestAsk":"0.00002395","size":"0.375","bestBidSize":"20.5373","price":"0.00002383","time":1619378337238,"bestAskSize":"72.1515","bestBid":"0.00002383"},"subject":"trade.ticker","topic":"/market/ticker:EQZ-BTC","type":"message"}
1619378337.289521: {"data":{"sequenceStart":1619079123948,"symbol":"EQZ-BTC","changes":{"asks":[],"bids":[["0","0","1619079123948"]]},"sequenceEnd":1619079123948},"subject":"trade.l2update","topic":"/market/level2:EQZ-BTC","type":"message"}
1619378337.28963: {"data":{"sequenceStart":1619079123949,"symbol":"EQZ-BTC","changes":{"asks":[],"bids":[["0","0","1619079123949"]]},"sequenceEnd":1619079123949},"subject":"trade.l2update","topic":"/market/level2:EQZ-BTC","type":"message"}
1619378337.2956421: {"data":{"sequenceStart":1613277184744,"symbol":"BCHSV-USDT","changes":{"asks":[["243.433","0","1613277184744"]],"bids":[]},"sequenceEnd":1613277184744},"subject":"trade.l2update","topic":"/market/level2:BCHSV-USDT","type":"message"}
1619378337.29575: {"data":{"sequenceStart":1613277184745,"symbol":"BCHSV-USDT","changes":{"asks":[],"bids":[["242.795","0","1613277184745"]]},"sequenceEnd":1613277184745},"subject":"trade.l2update","topic":"/market/level2:BCHSV-USDT","type":"message"}
1619378337.320117: {"data":{"sequenceStart":1613277184746,"symbol":"BCHSV-USDT","changes":{"asks":[],"bids":[["0","0","1613277184746"]]},"sequenceEnd":1613277184746},"subject":"trade.l2update","topic":"/market/level2:BCHSV-USDT","type":"message"}
1619378337.32016: {"data":{"sequenceStart":1613277184747,"symbol":"BCHSV-USDT","changes":{"asks":[],"bids":[["242.692","0.45082023","1613277184747"]]},"sequenceEnd":1613277184747},"subject":"trade.l2update","topic":"/market/level2:BCHSV-USDT","type":"message"}
1619378337.320195: {"data":{"sequenceStart":1613277184748,"symbol":"BCHSV-USDT","changes":{"asks":[["0","0","1613277184748"]],"bids":[]},"sequenceEnd":1613277184748},"subject":"trade.l2update","topic":"/market/level2:BCHSV-USDT","type":"message"}
1619378337.320213: {"data":{"sequenceStart":1613277184749,"symbol":"BCHSV-USDT","changes":{"asks":[["243.431","0.6","1613277184749"]],"bids":[]},"sequenceEnd":1613277184749},"subject":"trade.l2update","topic":"/market/level2:BCHSV-USDT","type":"message"}
1619378337.32674: {"data":{"sequenceStart":1612734157853,"symbol":"ANKR-BTC","changes":{"asks":[],"bids":[["0","0","1612734157853"]]},"sequenceEnd":1612734157853},"subject":"trade.l2update","topic":"/market/level2:ANKR-BTC","type":"message"}
1619378337.326794: {"data":{"sequenceStart":1612734157854,"symbol":"ANKR-BTC","changes":{"asks":[],"bids":[["0.0000025998","3668","1612734157854"]]},"sequenceEnd":1612734157854},"subject":"trade.l2update","topic":"/market/level2:ANKR-BTC","type":"message"}
1619378337.331651: {"data":{"sequenceStart":1613277184750,"symbol":"BCHSV-USDT","changes":{"asks":[],"bids":[["0","0","1613277184750"]]},"sequenceEnd":1613277184750},"subject":"trade.l2update","topic":"/market/level2:BCHSV-USDT","type":"message"}
1619378337.331728: {"data":{"sequenceStart":1613277184751,"symbol":"BCHSV-USDT","changes":{"asks":[],"bids":[["242.792","0.68148185","1613277184751"]]},"sequenceEnd":1613277184751},"subject":"trade.l2update","topic":"/market/level2:BCHSV-USDT","type":"message"}
1619378337.334809: {"data":{"sequenceStart":1612702190336,"symbol":"NRG-BTC","changes":{"asks":[["0.00006239","0","1612702190336"]],"bids":[]},"sequenceEnd":1612702190336},"subject":"trade.l2update","topic":"/market/level2:NRG-BTC","type":"message"}
1619378337.34716: {"data":{"sequenceStart":1612712745672,"symbol":"FET-BTC","changes":{"asks":[],"bids":[["0.00000764","208.7648","1612712745672"]]},"sequenceEnd":1612712745672},"subject":"trade.l2update","topic":"/market/level2:FET-BTC","type":"message"}
1619378337.354042: {"data":{"sequenceStart":1612734157855,"symbol":"ANKR-BTC","changes":{"asks":[],"bids":[["0.0000025997","8160.7631","1612734157855"]]},"sequenceEnd":1612734157855},"subject":"trade.l2update","topic":"/market/level2:ANKR-BTC","type":"message"}
1619378337.358485: {"data":{"sequenceStart":1613277184752,"symbol":"BCHSV-USDT","changes":{"asks":[],"bids":[["240.355","0","1613277184752"]]},"sequenceEnd":1613277184752},"subject":"trade.l2update","topic":"/market/level2:BCHSV-USDT","type":"message"}
1619378337.3678951: {"data":{"sequence":"1613277184752","bestAsk":"243.073","size":"0.14324938","bestBidSize":"0.68148185","price":"242.781","time":1619378337330,"bestAskSize":"0.96","bestBid":"242.792"},"subject":"trade.ticker","topic":"/market/ticker:BCHSV-USDT","type":"message"}
1619378337.368002: {"data":{"sequenceStart":1612734157856,"symbol":"ANKR-BTC","changes":{"asks":[],"bids":[["0","0","1612734157856"]]},"sequenceEnd":1612734157856},"subject":"trade.l2update","topic":"/market/level2:ANKR-BTC","type":"message"}
1619378337.3706582: {"data":{"sequenceStart":1612734157857,"symbol":"ANKR-BTC","changes":{"asks":[],"bids":[["0.0000025999","3499.6056","1612734157857"]]},"sequenceEnd":1612734157857},"subject":"trade.l2update","topic":"/market/level2:ANKR-BTC","type":"message"}
1619378337.370791: {"data":{"sequenceStart":1612734157858,"symbol":"ANKR-BTC","changes":{"asks":[["0","0","1612734157858"]],"bids":[]},"sequenceEnd":1612734157858},"subject":"trade.l2update","topic":"/market/level2:ANKR-BTC","type":"message"}
1619378337.3708448: {"data":{"sequenceStart":1612734157859,"symbol":"ANKR-BTC","changes":{"asks":[["0.0000026261","2921.4586","1612734157859"]],"bids":[]},"sequenceEnd":1612734157859},"subject":"trade.l2update","topic":"/market/level2:ANKR-BTC","type":"message"}
1619378337.3798609: {"data":{"sequence":"1619079123949","bestAsk":"0.00002395","size":"0.375","bestBidSize":"20.5373","price":"0.00002383","time":1619378337338,"bestAskSize":"72.1515","bestBid":"0.00002383"},"subject":"trade.ticker","topic":"/market/ticker:EQZ-BTC","type":"message"}
1619378337.379951: {"data":{"sequenceStart":1612734157860,"symbol":"ANKR-BTC","changes":{"asks":[],"bids":[["0","0","1612734157860"]]},"sequenceEnd":1612734157860},"subject":"trade.l2update","topic":"/market/level2:ANKR-BTC","type":"message"}
1619378337.380016: {"data":{"sequenceStart":1612734157861,"symbol":"ANKR-BTC","changes":{"asks":[],"bids":[["0.0000025999","8534.3341","1612734157861"]]},"sequenceEnd":1612734157861},"subject":"trade.l2update","topic":"/market/level2:ANKR-BTC","type":"message"}
1619378337.380074: {"data":{"sequenceStart":1613277184753,"symbol":"BCHSV-USDT","changes":{"asks":[],"bids":[["0","0","1613277184753"]]},"sequenceEnd":1613277184753},"subject":"trade.l2update","topic":"/market/level2:BCHSV-USDT","type":"message"}
1619378337.3801138: {"data":{"sequenceStart":1613277184754,"symbol":"BCHSV-USDT","changes":{"asks":[],"bids":[["242.796","5","1613277184754"]]},"sequenceEnd":1613277184754},"subject":"trade.l2update","topic":"/market/level2:BCHSV-USDT","type":"message"}
1619378337.388708: {"data":{"sequenceStart":1613277184755,"symbol":"BCHSV-USDT","changes":{"asks":[],"bids":[["0","0","1613277184755"]]},"sequenceEnd":1613277184755},"subject":"trade.l2update","topic":"/market/level2:BCHSV-USDT","type":"message"}
1619378337.3888152: {"data":{"sequenceStart":1613277184756,"symbol":"BCHSV-USDT","changes":{"asks":[],"bids":[["242.693","9.34393396","1613277184756"]]},"sequenceEnd":1613277184756},"subject":"trade.l2update","topic":"/market/level2:BCHSV-USDT","type":"message"}
1619378337.40151: {"data":{"sequenceStart":1613277184757,"symbol":"BCHSV-USDT","changes":{"asks":[],"bids":[["242.692","0","1613277184757"]]},"sequenceEnd":1613277184757},"subject":"trade.l2update","topic":"/market/level2:BCHSV-USDT","type":"message"}
1619378337.408142: {"data":{"sequence":"1612712745672","bestAsk":"0.00000776","size":"401.2004","bestBidSize":"357.285","price":"0.00000772","time":1619378337369,"bestAskSize":"1993.0416","bestBid":"0.00000771"},"subject":"trade.ticker","topic":"/market/ticker:FET-BTC","type":"message"}
1619378337.429325: {"data":{"sequence":"1612734157861","bestAsk":"0.0000026208","size":"46","bestBidSize":"8534.3341","price":"0.0000026071","time":1619378337388,"bestAskSize":"10987.6265","bestBid":"0.0000025999"},"subject":"trade.ticker","topic":"/market/ticker:ANKR-BTC","type":"message"}
1619378337.440099: {"data":{"sequence":"1612702190336","bestAsk":"0.00006218","size":"0.0431","bestBidSize":"19.5017","price":"0.00006141","time":1619378337391,"bestAskSize":"43.3399","bestBid":"0.00006141"},"subject":"trade.ticker","topic":"/market/ticker:NRG-BTC","type":"message"}
1619378337.45808: {"data":{"sequenceStart":1613277184758,"symbol":"BCHSV-USDT","changes":{"asks":[["0","0","1613277184758"]],"bids":[]},"sequenceEnd":1613277184758},"subject":"trade.l2update","topic":"/market/level2:BCHSV-USDT","type":"message"}
1619378337.458176: {"data":{"sequenceStart":1613277184759,"symbol":"BCHSV-USDT","changes":{"asks":[["243.808","5","1613277184759"]],"bids":[]},"sequenceEnd":1613277184759},"subject":"trade.l2update","topic":"/market/level2:BCHSV-USDT","type":"message"}
1619378337.458255: {"data":{"sequenceStart":1613277184760,"symbol":"BCHSV-USDT","changes":{"asks":[["0","0","1613277184760"]],"bids":[]},"sequenceEnd":1613277184760},"subject":"trade.l2update","topic":"/market/level2:BCHSV-USDT","type":"message"}
1619378337.458295: {"data":{"sequenceStart":1613277184761,"symbol":"BCHSV-USDT","changes":{"asks":[["244.446","150","1613277184761"]],"bids":[]},"sequenceEnd":1613277184761},"subject":"trade.l2update","topic":"/market/level2:BCHSV-USDT","type":"message"}
1619378337.458345: {"data":{"sequenceStart":1613277184762,"symbol":"BCHSV-USDT","changes":{"asks":[],"bids":[["0","0","1613277184762"]]},"sequenceEnd":1613277184762},"subject":"trade.l2update","topic":"/market/level2:BCHSV-USDT","type":"message"}
1619378337.45838: {"data":{"sequenceStart":1613277184763,"symbol":"BCHSV-USDT","changes":{"asks":[],"bids":[["241.647","5","1613277184763"]]},"sequenceEnd":1613277184763},"subject":"trade.l2update","topic":"/market/level2:BCHSV-USDT","type":"message"}
1619378337.469005: {"data":{"sequence":"1613277184763","bestAsk":"243.073","size":"0.14324938","bestBidSize":"5","price":"242.781","time":1619378337430,"bestAskSize":"0.96","bestBid":"242.796"},"subject":"trade.ticker","topic":"/market/ticker:BCHSV-USDT","type":"message"}
1619378337.494857: {"data":{"sequenceStart":1613277184764,"symbol":"BCHSV-USDT","changes":{"asks":[["243.431","0","1613277184764"]],"bids":[]},"sequenceEnd":1613277184764},"subject":"trade.l2update","topic":"/market/level2:BCHSV-USDT","type":"message"}
1619378337.4949272: {"data":{"sequenceStart":1613277184765,"symbol":"BCHSV-USDT","changes":{"asks":[],"bids":[["242.792","0","1613277184765"]]},"sequenceEnd":1613277184765},"subject":"trade.l2update","topic":"/market/level2:BCHSV-USDT","type":"message"}
1619378337.53533: {"data":{"sequenceStart":1613277184766,"symbol":"BCHSV-USDT","changes":{"asks":[["0","0","1613277184766"]],"bids":[]},"sequenceEnd":1613277184766},"subject":"trade.l2update","topic":"/market/level2:BCHSV-USDT","type":"message"}
1619378337.535396: {"data":{"sequenceStart":1613277184767,"symbol":"BCHSV-USDT","changes":{"asks":[["243.43","0.6","1613277184767"]],"bids":[]},"sequenceEnd":1613277184767},"subject":"trade.l2update","topic":"/market/level2:BCHSV-USDT","type":"message"}
1619378337.535439: {"data":{"sequenceStart":1613277184768,"symbol":"BCHSV-USDT","changes":{"asks":[],"bids":[["0","0","1613277184768"]]},"sequenceEnd":1613277184768},"subject":"trade.l2update","topic":"/market/level2:BCHSV-USDT","type":"message"}
1619378337.5354722: {"data":{"sequenceStart":1613277184769,"symbol":"BCHSV-USDT","changes":{"asks":[],"bids":[["242.794","0.68148185","1613277184769"]]},"sequenceEnd":1613277184769},"subject":"trade.l2update","topic":"/market/level2:BCHSV-USDT","type":"message"}
1619378337.572955: {"data":{"sequence":"1613277184769","bestAsk":"243.073","size":"0.14324938","bestBidSize":"5","price":"242.781","time":1619378337530,"bestAskSize":"0.96","bestBid":"242.796"},"subject":"trade.ticker","topic":"/market/ticker:BCHSV-USDT","type":"message"}
1619378337.644897: {"data":{"sequenceStart":1612702190337,"symbol":"NRG-BTC","changes":{"asks":[["0","0","1612702190337"]],"bids":[]},"sequenceEnd":1612702190337},"subject":"trade.l2update","topic":"/market/level2:NRG-BTC","type":"message"}
1619378337.6449559: {"data":{"sequenceStart":1612702190338,"symbol":"NRG-BTC","changes":{"asks":[["0.00006263","68.532","1612702190338"]],"bids":[]},"sequenceEnd":1612702190338},"subject":"trade.l2update","topic":"/market/level2:NRG-BTC","type":"message"}
1619378337.659163: {"data":{"sequenceStart":1612844051962,"symbol":"SNX-BTC","changes":{"asks":[],"bids":[["0.0002861","35.16464552","1612844051962"]]},"sequenceEnd":1612844051962},"subject":"trade.l2update","topic":"/market/level2:SNX-BTC","type":"message"}
1619378337.675099: {"data":{"sequenceStart":1612712745673,"symbol":"FET-BTC","changes":{"asks":[],"bids":[["0","0","1612712745673"]]},"sequenceEnd":1612712745673},"subject":"trade.l2update","topic":"/market/level2:FET-BTC","type":"message"}
1619378337.6752079: {"data":{"sequenceStart":1612712745674,"symbol":"FET-BTC","changes":{"asks":[],"bids":[["0.00000769","88.5593","1612712745674"]]},"sequenceEnd":1612712745674},"subject":"trade.l2update","topic":"/market/level2:FET-BTC","type":"message"}
1619378337.708797: {"data":{"sequence":"1612712745674","bestAsk":"0.00000776","size":"401.2004","bestBidSize":"357.285","price":"0.00000772","time":1619378337667,"bestAskSize":"1993.0416","bestBid":"0.00000771"},"subject":"trade.ticker","topic":"/market/ticker:FET-BTC","type":"message"}
1619378337.7330308: {"data":{"sequence":"1612702190338","bestAsk":"0.00006218","size":"0.0431","bestBidSize":"19.5017","price":"0.00006141","time":1619378337691,"bestAskSize":"43.3399","bestBid":"0.00006141"},"subject":"trade.ticker","topic":"/market/ticker:NRG-BTC","type":"message"}
1619378337.745585: {"data":{"sequenceStart":1613277184770,"symbol":"BCHSV-USDT","changes":{"asks":[],"bids":[["241.704","0","1613277184770"]]},"sequenceEnd":1613277184770},"subject":"trade.l2update","topic":"/market/level2:BCHSV-USDT","type":"message"}
1619378337.7642949: {"data":{"sequenceStart":1612702190339,"symbol":"NRG-BTC","changes":{"asks":[["0","0","1612702190339"]],"bids":[]},"sequenceEnd":1612702190339},"subject":"trade.l2update","topic":"/market/level2:NRG-BTC","type":"message"}
1619378337.7643788: {"data":{"sequenceStart":1612702190340,"symbol":"NRG-BTC","changes":{"asks":[["0.0000623","13.679","1612702190340"]],"bids":[]},"sequenceEnd":1612702190340},"subject":"trade.l2update","topic":"/market/level2:NRG-BTC","type":"message"}
1619378337.764435: {"data":{"sequence":"1612844051962","bestAsk":"0.00028711","size":"0.01745248","bestBidSize":"0.19100065","price":"0.00028676","time":1619378337723,"bestAskSize":"29.24570683","bestBid":"0.00028678"},"subject":"trade.ticker","topic":"/market/ticker:SNX-BTC","type":"message"}
1619378337.7644632: {"data":{"sequenceStart":1612712745675,"symbol":"FET-BTC","changes":{"asks":[["0","0","1612712745675"]],"bids":[]},"sequenceEnd":1612712745675},"subject":"trade.l2update","topic":"/market/level2:FET-BTC","type":"message"}
1619378337.764489: {"data":{"sequenceStart":1612712745676,"symbol":"FET-BTC","changes":{"asks":[["0.0000078","4011.0844","1612712745676"]],"bids":[]},"sequenceEnd":1612712745676},"subject":"trade.l2update","topic":"/market/level2:FET-BTC","type":"message"}
1619378337.7645252: {"data":{"sequenceStart":1612694580168,"symbol":"CAPP-BTC","changes":{"asks":[],"bids":[["0","0","1612694580168"]]},"sequenceEnd":1612694580168},"subject":"trade.l2update","topic":"/market/level2:CAPP-BTC","type":"message"}
1619378337.764548: {"data":{"sequenceStart":1612694580169,"symbol":"CAPP-BTC","changes":{"asks":[],"bids":[["0.0000001521","5274","1612694580169"]]},"sequenceEnd":1612694580169},"subject":"trade.l2update","topic":"/market/level2:CAPP-BTC","type":"message"}
1619378337.766829: {"data":{"sequenceStart":1613277184771,"symbol":"BCHSV-USDT","changes":{"asks":[],"bids":[["242.796","0","1613277184771"]]},"sequenceEnd":1613277184771},"subject":"trade.l2update","topic":"/market/level2:BCHSV-USDT","type":"message"}
1619378337.766915: {"data":{"sequence":"1613277184771","bestAsk":"243.073","size":"0.14324938","bestBidSize":"0.68148185","price":"242.781","time":1619378337730,"bestAskSize":"0.96","bestBid":"242.794"},"subject":"trade.ticker","topic":"/market/ticker:BCHSV-USDT","type":"message"}
1619378337.777759: {"data":{"sequenceStart":1612699351268,"symbol":"COV-BTC","changes":{"asks":[["0","0","1612699351268"]],"bids":[]},"sequenceEnd":1612699351268},"subject":"trade.l2update","topic":"/market/level2:COV-BTC","type":"message"}
1619378337.777878: {"data":{"sequenceStart":1612699351269,"symbol":"COV-BTC","changes":{"asks":[["0.00001127","4469.58576035","1612699351269"]],"bids":[]},"sequenceEnd":1612699351269},"subject":"trade.l2update","topic":"/market/level2:COV-BTC","type":"message"}
1619378337.777921: {"data":{"sequenceStart":1613277184772,"symbol":"BCHSV-USDT","changes":{"asks":[],"bids":[["0","0","1613277184772"]]},"sequenceEnd":1613277184772},"subject":"trade.l2update","topic":"/market/level2:BCHSV-USDT","type":"message"}
1619378337.77795: {"data":{"sequenceStart":1613277184773,"symbol":"BCHSV-USDT","changes":{"asks":[],"bids":[["242.792","5","1613277184773"]]},"sequenceEnd":1613277184773},"subject":"trade.l2update","topic":"/market/level2:BCHSV-USDT","type":"message"}
1619378337.797239: {"data":{"sequenceStart":1612694580170,"symbol":"CAPP-BTC","changes":{"asks":[["0","0","1612694580170"]],"bids":[]},"sequenceEnd":1612694580170},"subject":"trade.l2update","topic":"/market/level2:CAPP-BTC","type":"message"}
1619378337.79732: {"data":{"sequenceStart":1612694580171,"symbol":"CAPP-BTC","changes":{"asks":[["0.0000002195","330.25","1612694580171"]],"bids":[]},"sequenceEnd":1612694580171},"subject":"trade.l2update","topic":"/market/level2:CAPP-BTC","type":"message"}
1619378337.810784: {"data":{"sequence":"1612712745676","bestAsk":"0.00000776","size":"401.2004","bestBidSize":"357.285","price":"0.00000772","time":1619378337768,"bestAskSize":"1993.0416","bestBid":"0.00000771"},"subject":"trade.ticker","topic":"/market/ticker:FET-BTC","type":"message"}
1619378337.816061: {"data":{"sequenceStart":1613277184774,"symbol":"BCHSV-USDT","changes":{"asks":[],"bids":[["242.794","0","1613277184774"]]},"sequenceEnd":1613277184774},"subject":"trade.l2update","topic":"/market/level2:BCHSV-USDT","type":"message"}
1619378337.8162: {"data":{"sequenceStart":1613277184775,"symbol":"BCHSV-USDT","changes":{"asks":[["243.43","0","1613277184775"]],"bids":[]},"sequenceEnd":1613277184775},"subject":"trade.l2update","topic":"/market/level2:BCHSV-USDT","type":"message"}
1619378337.821695: {"data":{"sequenceStart":1613277184776,"symbol":"BCHSV-USDT","changes":{"asks":[["0","0","1613277184776"]],"bids":[]},"sequenceEnd":1613277184776},"subject":"trade.l2update","topic":"/market/level2:BCHSV-USDT","type":"message"}
1619378337.821766: {"data":{"sequenceStart":1613277184777,"symbol":"BCHSV-USDT","changes":{"asks":[["243.429","0.6","1613277184777"]],"bids":[]},"sequenceEnd":1613277184777},"subject":"trade.l2update","topic":"/market/level2:BCHSV-USDT","type":"message"}
1619378337.821811: {"data":{"sequenceStart":1613277184778,"symbol":"BCHSV-USDT","changes":{"asks":[],"bids":[["0","0","1613277184778"]]},"sequenceEnd":1613277184778},"subject":"trade.l2update","topic":"/market/level2:BCHSV-USDT","type":"message"}
1619378337.821833: {"data":{"sequenceStart":1613277184779,"symbol":"BCHSV-USDT","changes":{"asks":[],"bids":[["242.792","5.68148185","1613277184779"]]},"sequenceEnd":1613277184779},"subject":"trade.l2update","topic":"/market/level2:BCHSV-USDT","type":"message"}
1619378337.821855: {"data":{"sequence":"1612694580171","bestAsk":"0.0000002195","size":"1000.02","bestBidSize":"83.07","price":"0.0000002182","time":1619378337782,"bestAskSize":"330.25","bestBid":"0.0000002181"},"subject":"trade.ticker","topic":"/market/ticker:CAPP-BTC","type":"message"}
1619378337.831615: {"data":{"sequence":"1612699351269","bestAsk":"0.00001127","size":"96.1525","bestBidSize":"49.6422","price":"0.00001126","time":1619378337789,"bestAskSize":"4469.58576035","bestBid":"0.00001121"},"subject":"trade.ticker","topic":"/market/ticker:COV-BTC","type":"message"}
1619378337.8349571: {"data":{"sequence":"1612702190340","bestAsk":"0.00006218","size":"0.0431","bestBidSize":"19.5017","price":"0.00006141","time":1619378337791,"bestAskSize":"43.3399","bestBid":"0.00006141"},"subject":"trade.ticker","topic":"/market/ticker:NRG-BTC","type":"message"}
1619378337.834988: {"data":{"sequenceStart":1612712745677,"symbol":"FET-BTC","changes":{"asks":[["0.0000078","0","1612712745677"]],"bids":[]},"sequenceEnd":1612712745677},"subject":"trade.l2update","topic":"/market/level2:FET-BTC","type":"message"}
1619378337.844405: {"data":{"symbol":"BCHSV-USDT","candles":["1619378280","242.781","242.781","242.781","242.781","0.14324938","34.77822772578"],"time":1619378337806000034},"subject":"trade.candles.add","topic":"/market/candles:BCHSV-USDT_1min","type":"message"}
1619378337.8510542: {"data":{"sequenceStart":1613277184780,"symbol":"BCHSV-USDT","changes":{"asks":[["243.808","0","1613277184780"]],"bids":[]},"sequenceEnd":1613277184780},"subject":"trade.l2update","topic":"/market/level2:BCHSV-USDT","type":"message"}
1619378337.8511958: {"data":{"sequenceStart":1613277184781,"symbol":"BCHSV-USDT","changes":{"asks":[],"bids":[["241.647","0","1613277184781"]]},"sequenceEnd":1613277184781},"subject":"trade.l2update","topic":"/market/level2:BCHSV-USDT","type":"message"}
1619378337.85127: {"data":{"sequenceStart":1613277184782,"symbol":"BCHSV-USDT","changes":{"asks":[["244.446","0","1613277184782"]],"bids":[]},"sequenceEnd":1613277184782},"subject":"trade.l2update","topic":"/market/level2:BCHSV-USDT","type":"message"}
1619378337.859616: {"data":{"sequenceStart":1613277184783,"symbol":"BCHSV-USDT","changes":{"asks":[],"bids":[["242.792","0.68148185","1613277184783"]]},"sequenceEnd":1613277184783},"subject":"trade.l2update","topic":"/market/level2:BCHSV-USDT","type":"message"}
1619378337.86983: {"data":{"sequence":"1613277184783","bestAsk":"243.073","size":"0.14324938","bestBidSize":"0.68148185","price":"242.781","time":1619378337832,"bestAskSize":"0.96","bestBid":"242.792"},"subject":"trade.ticker","topic":"/market/ticker:BCHSV-USDT","type":"message"}
1619378337.8948228: {"data":{"sequenceStart":1613277184784,"symbol":"BCHSV-USDT","changes":{"asks":[["243.429","0","1613277184784"]],"bids":[]},"sequenceEnd":1613277184784},"subject":"trade.l2update","topic":"/market/level2:BCHSV-USDT","type":"message"}
1619378337.907997: {"data":{"sequence":"1612712745677","bestAsk":"0.00000776","size":"401.2004","bestBidSize":"357.285","price":"0.00000772","time":1619378337867,"bestAskSize":"1993.0416","bestBid":"0.00000771"},"subject":"trade.ticker","topic":"/market/ticker:FET-BTC","type":"message"}
1619378337.912412: {"data":{"sequenceStart":1613277184785,"symbol":"BCHSV-USDT","changes":{"asks":[["0","0","1613277184785"]],"bids":[]},"sequenceEnd":1613277184785},"subject":"trade.l2update","topic":"/market/level2:BCHSV-USDT","type":"message"}
1619378337.912477: {"data":{"sequenceStart":1613277184786,"symbol":"BCHSV-USDT","changes":{"asks":[["243.428","0.6","1613277184786"]],"bids":[]},"sequenceEnd":1613277184786},"subject":"trade.l2update","topic":"/market/level2:BCHSV-USDT","type":"message"}
1619378337.973862: {"data":{"sequence":"1613277184786","bestAsk":"243.073","size":"0.14324938","bestBidSize":"0.68148185","price":"242.781","time":1619378337930,"bestAskSize":"0.96","bestBid":"242.792"},"subject":"trade.ticker","topic":"/market/ticker:BCHSV-USDT","type":"message"}
1619378337.982461: {"data":{"sequenceStart":1613277184787,"symbol":"BCHSV-USDT","changes":{"asks":[],"bids":[["0","0","1613277184787"]]},"sequenceEnd":1613277184787},"subject":"trade.l2update","topic":"/market/level2:BCHSV-USDT","type":"message"}
1619378337.982573: {"data":{"sequenceStart":1613277184788,"symbol":"BCHSV-USDT","changes":{"asks":[],"bids":[["242.795","5","1613277184788"]]},"sequenceEnd":1613277184788},"subject":"trade.l2update","topic":"/market/level2:BCHSV-USDT","type":"message"}
1619378337.9826481: {"data":{"sequenceStart":1613277184789,"symbol":"BCHSV-USDT","changes":{"asks":[],"bids":[["242.579","0","1613277184789"]]},"sequenceEnd":1613277184789},"subject":"trade.l2update","topic":"/market/level2:BCHSV-USDT","type":"message"}
1619378337.9827158: {"data":{"sequenceStart":1612712745678,"symbol":"FET-BTC","changes":{"asks":[["0","0","1612712745678"]],"bids":[]},"sequenceEnd":1612712745678},"subject":"trade.l2update","topic":"/market/level2:FET-BTC","type":"message"}
1619378337.982744: {"data":{"sequenceStart":1612712745679,"symbol":"FET-BTC","changes":{"asks":[["0.00000781","159.36","1612712745679"]],"bids":[]},"sequenceEnd":1612712745679},"subject":"trade.l2update","topic":"/market/level2:FET-BTC","type":"message"}
1619378338.01674: {"data":{"sequenceStart":1613277184790,"symbol":"BCHSV-USDT","changes":{"asks":[["243.428","0","1613277184790"]],"bids":[]},"sequenceEnd":1613277184790},"subject":"trade.l2update","topic":"/market/level2:BCHSV-USDT","type":"message"}
1619378338.016882: {"data":{"sequence":"1612712745680","bestAsk":"0.00000776","size":"401.2004","bestBidSize":"357.285","price":"0.00000772","time":1619378337967,"bestAskSize":"1993.0416","bestBid":"0.00000771"},"subject":"trade.ticker","topic":"/market/ticker:FET-BTC","type":"message"}
1619378338.016931: {"data":{"sequenceStart":1612712745680,"symbol":"FET-BTC","changes":{"asks":[],"bids":[["0.00000769","20","1612712745680"]]},"sequenceEnd":1612712745680},"subject":"trade.l2update","topic":"/market/level2:FET-BTC","type":"message"}
1619378338.018705: {"data":{"sequenceStart":1612844051963,"symbol":"SNX-BTC","changes":{"asks":[["0","0","1612844051963"]],"bids":[]},"sequenceEnd":1612844051963},"subject":"trade.l2update","topic":"/market/level2:SNX-BTC","type":"message"}
1619378338.018812: {"data":{"sequenceStart":1612844051964,"symbol":"SNX-BTC","changes":{"asks":[["0.0002871","1.74195969","1612844051964"]],"bids":[]},"sequenceEnd":1612844051964},"subject":"trade.l2update","topic":"/market/level2:SNX-BTC","type":"message"}
1619378338.0244951: {"data":{"sequenceStart":1613277184791,"symbol":"BCHSV-USDT","changes":{"asks":[["0","0","1613277184791"]],"bids":[]},"sequenceEnd":1613277184791},"subject":"trade.l2update","topic":"/market/level2:BCHSV-USDT","type":"message"}
1619378338.0246038: {"data":{"sequenceStart":1613277184792,"symbol":"BCHSV-USDT","changes":{"asks":[["243.392","0.6","1613277184792"]],"bids":[]},"sequenceEnd":1613277184792},"subject":"trade.l2update","topic":"/market/level2:BCHSV-USDT","type":"message"}
1619378338.036254: {"data":{"sequenceStart":1613277184793,"symbol":"BCHSV-USDT","changes":{"asks":[["243.109","2.99","1613277184793"]],"bids":[]},"sequenceEnd":1613277184793},"subject":"trade.l2update","topic":"/market/level2:BCHSV-USDT","type":"message"}
1619378338.045623: {"data":{"sequenceStart":1612701563982,"symbol":"DAPPT-BTC","changes":{"asks":[["0.0000001133","4948.0983","1612701563982"]],"bids":[]},"sequenceEnd":1612701563982},"subject":"trade.l2update","topic":"/market/level2:DAPPT-BTC","type":"message"}
1619378338.051434: {"data":{"sequenceStart":1612734157862,"symbol":"ANKR-BTC","changes":{"asks":[],"bids":[["0.0000025999","5034.7285","1612734157862"]]},"sequenceEnd":1612734157862},"subject":"trade.l2update","topic":"/market/level2:ANKR-BTC","type":"message"}
1619378338.055437: {"data":{"sequenceStart":1612844051965,"symbol":"SNX-BTC","changes":{"asks":[["0.0002871","0","1612844051965"]],"bids":[]},"sequenceEnd":1612844051965},"subject":"trade.l2update","topic":"/market/level2:SNX-BTC","type":"message"}
1619378338.055535: {"data":{"sequenceStart":1613277184794,"symbol":"BCHSV-USDT","changes":{"asks":[],"bids":[["242.693","0","1613277184794"]]},"sequenceEnd":1613277184794},"subject":"trade.l2update","topic":"/market/level2:BCHSV-USDT","type":"message"}
1619378338.055582: {"data":{"sequenceStart":1612702190341,"symbol":"NRG-BTC","changes":{"asks":[["0.0000623","0","1612702190341"]],"bids":[]},"sequenceEnd":1612702190341},"subject":"trade.l2update","topic":"/market/level2:NRG-BTC","type":"message"}
1619378338.066999: {"data":{"sequence":"1612844051965","bestAsk":"0.00028711","size":"0.01745248","bestBidSize":"0.19100065","price":"0.00028676","time":1619378338023,"bestAskSize":"29.24570683","bestBid":"0.00028678"},"subject":"trade.ticker","topic":"/market/ticker:SNX-BTC","type":"message"}
1619378338.067073: {"data":{"sequenceStart":1612699351270,"symbol":"COV-BTC","changes":{"asks":[["0.00001127","4331.68226035","1612699351270"]],"bids":[]},"sequenceEnd":1612699351270},"subject":"trade.l2update","topic":"/market/level2:COV-BTC","type":"message"}
1619378338.067126: {"data":{"sequenceStart":1612694580172,"symbol":"CAPP-BTC","changes":{"asks":[["0.0000002195","0","1612694580172"]],"bids":[]},"sequenceEnd":1612694580172},"subject":"trade.l2update","topic":"/market/level2:CAPP-BTC","type":"message"}
1619378338.067178: {"data":{"sequence":"1612701563982","bestAsk":"0.000000113","size":"145.4959","bestBidSize":"5148.7223","price":"0.0000001126","time":1619378338030,"bestAskSize":"1208.0878","bestBid":"0.000000112"},"subject":"trade.ticker","topic":"/market/ticker:DAPPT-BTC","type":"message"}
1619378338.072216: {"data":{"sequenceStart":1612844051966,"symbol":"SNX-BTC","changes":{"asks":[["0.00028712","0","1612844051966"]],"bids":[]},"sequenceEnd":1612844051966},"subject":"trade.l2update","topic":"/market/level2:SNX-BTC","type":"message"}
1619378338.078018: {"data":{"sequenceStart":1612844051967,"symbol":"SNX-BTC","changes":{"asks":[],"bids":[["0.00028653","0","1612844051967"]]},"sequenceEnd":1612844051967},"subject":"trade.l2update","topic":"/market/level2:SNX-BTC","type":"message"}
1619378338.084574: {"data":{"sequenceStart":1612712745681,"symbol":"FET-BTC","changes":{"asks":[],"bids":[["0","0","1612712745681"]]},"sequenceEnd":1612712745681},"subject":"trade.l2update","topic":"/market/level2:FET-BTC","type":"message"}
1619378338.084652: {"data":{"sequenceStart":1612712745682,"symbol":"FET-BTC","changes":{"asks":[],"bids":[["0.00000769","75.4148","1612712745682"]]},"sequenceEnd":1612712745682},"subject":"trade.l2update","topic":"/market/level2:FET-BTC","type":"message"}
1619378338.084693: {"data":{"sequenceStart":1612694580173,"symbol":"CAPP-BTC","changes":{"asks":[["0.0000002196","0","1612694580173"]],"bids":[]},"sequenceEnd":1612694580173},"subject":"trade.l2update","topic":"/market/level2:CAPP-BTC","type":"message"}
1619378338.092972: {"data":{"sequence":"1613277184794","bestAsk":"243.073","size":"0.14324938","bestBidSize":"5","price":"242.781","time":1619378338033,"bestAskSize":"0.96","bestBid":"242.795"},"subject":"trade.ticker","topic":"/market/ticker:BCHSV-USDT","type":"message"}
1619378338.104161: {"data":{"sequenceStart":1613277184795,"symbol":"BCHSV-USDT","changes":{"asks":[["243.109","0","1613277184795"]],"bids":[]},"sequenceEnd":1613277184795},"subject":"trade.l2update","topic":"/market/level2:BCHSV-USDT","type":"message"}
1619378338.110755: {"data":{"sequence":"1612712745682","bestAsk":"0.00000776","size":"401.2004","bestBidSize":"357.285","price":"0.00000772","time":1619378338069,"bestAskSize":"1993.0416","bestBid":"0.00000771"},"subject":"trade.ticker","topic":"/market/ticker:FET-BTC","type":"message"}
1619378338.126186: {"data":{"sequenceStart":1613277184796,"symbol":"BCHSV-USDT","changes":{"asks":[["0","0","1613277184796"]],"bids":[]},"sequenceEnd":1613277184796},"subject":"trade.l2update","topic":"/market/level2:BCHSV-USDT","type":"message"}
1619378338.12623: {"data":{"sequenceStart":1613277184797,"symbol":"BCHSV-USDT","changes":{"asks":[["243.14","4.29121219","1613277184797"]],"bids":[]},"sequenceEnd":1613277184797},"subject":"trade.l2update","topic":"/market/level2:BCHSV-USDT","type":"message"}
1619378338.126268: {"data":{"sequenceStart":1613277184798,"symbol":"BCHSV-USDT","changes":{"asks":[],"bids":[["242.792","0","1613277184798"]]},"sequenceEnd":1613277184798},"subject":"trade.l2update","topic":"/market/level2:BCHSV-USDT","type":"message"}
1619378338.1262982: {"data":{"sequenceStart":1613277184799,"symbol":"BCHSV-USDT","changes":{"asks":[],"bids":[["242.781","0","1613277184799"]]},"sequenceEnd":1613277184799},"subject":"trade.l2update","topic":"/market/level2:BCHSV-USDT","type":"message"}
1619378338.126322: {"data":{"sequenceStart":1613277184800,"symbol":"BCHSV-USDT","changes":{"asks":[],"bids":[["0","0","1613277184800"]]},"sequenceEnd":1613277184800},"subject":"trade.l2update","topic":"/market/level2:BCHSV-USDT","type":"message"}
1619378338.126338: {"data":{"sequenceStart":1613277184801,"symbol":"BCHSV-USDT","changes":{"asks":[],"bids":[["241.754","10.01559834","1613277184801"]]},"sequenceEnd":1613277184801},"subject":"trade.l2update","topic":"/market/level2:BCHSV-USDT","type":"message"}
1619378338.126358: {"data":{"sequenceStart":1613277184802,"symbol":"BCHSV-USDT","changes":{"asks":[["243.392","0","1613277184802"]],"bids":[]},"sequenceEnd":1613277184802},"subject":"trade.l2update","topic":"/market/level2:BCHSV-USDT","type":"message"}
1619378338.127213: {"data":{"sequenceStart":1612734157863,"symbol":"ANKR-BTC","changes":{"asks":[],"bids":[["0","0","1612734157863"]]},"sequenceEnd":1612734157863},"subject":"trade.l2update","topic":"/market/level2:ANKR-BTC","type":"message"}
1619378338.127249: {"data":{"sequenceStart":1612734157864,"symbol":"ANKR-BTC","changes":{"asks":[],"bids":[["0.0000026","1923.1435","1612734157864"]]},"sequenceEnd":1612734157864},"subject":"trade.l2update","topic":"/market/level2:ANKR-BTC","type":"message"}
1619378338.127279: {"data":{"sequence":"1612694580173","bestAsk":"0.0000002197","size":"1000.02","bestBidSize":"83.07","price":"0.0000002182","time":1619378338082,"bestAskSize":"735.9","bestBid":"0.0000002181"},"subject":"trade.ticker","topic":"/market/ticker:CAPP-BTC","type":"message"}
1619378338.127302: {"data":{"sequenceStart":1612701563983,"symbol":"DAPPT-BTC","changes":{"asks":[["0","0","1612701563983"]],"bids":[]},"sequenceEnd":1612701563983},"subject":"trade.l2update","topic":"/market/level2:DAPPT-BTC","type":"message"}
1619378338.127321: {"data":{"sequenceStart":1612701563984,"symbol":"DAPPT-BTC","changes":{"asks":[["0.0000001133","5580.4836","1612701563984"]],"bids":[]},"sequenceEnd":1612701563984},"subject":"trade.l2update","topic":"/market/level2:DAPPT-BTC","type":"message"}
1619378338.1323469: {"data":{"sequenceStart":1612712745683,"symbol":"FET-BTC","changes":{"asks":[["0.00000781","0","1612712745683"]],"bids":[]},"sequenceEnd":1612712745683},"subject":"trade.l2update","topic":"/market/level2:FET-BTC","type":"message"}
1619378338.132401: {"data":{"sequenceStart":1613277184803,"symbol":"BCHSV-USDT","changes":{"asks":[],"bids":[["0","0","1613277184803"]]},"sequenceEnd":1613277184803},"subject":"trade.l2update","topic":"/market/level2:BCHSV-USDT","type":"message"}
1619378338.1324239: {"data":{"sequenceStart":1613277184804,"symbol":"BCHSV-USDT","changes":{"asks":[],"bids":[["242.773","52.488","1613277184804"]]},"sequenceEnd":1613277184804},"subject":"trade.l2update","topic":"/market/level2:BCHSV-USDT","type":"message"}
1619378338.13245: {"data":{"sequenceStart":1613277184805,"symbol":"BCHSV-USDT","changes":{"asks":[["0","0","1613277184805"]],"bids":[]},"sequenceEnd":1613277184805},"subject":"trade.l2update","topic":"/market/level2:BCHSV-USDT","type":"message"}
1619378338.132467: {"data":{"sequenceStart":1613277184806,"symbol":"BCHSV-USDT","changes":{"asks":[["243.051","1","1613277184806"]],"bids":[]},"sequenceEnd":1613277184806},"subject":"trade.l2update","topic":"/market/level2:BCHSV-USDT","type":"message"}
1619378338.132488: {"data":{"sequence":"1612734157864","bestAsk":"0.0000026208","size":"46","bestBidSize":"1923.1435","price":"0.0000026071","time":1619378338088,"bestAskSize":"10987.6265","bestBid":"0.0000026"},"subject":"trade.ticker","topic":"/market/ticker:ANKR-BTC","type":"message"}
1619378338.132504: {"data":{"sequence":"1612699351270","bestAsk":"0.00001127","size":"96.1525","bestBidSize":"49.6422","price":"0.00001126","time":1619378338089,"bestAskSize":"4331.68226035","bestBid":"0.00001121"},"subject":"trade.ticker","topic":"/market/ticker:COV-BTC","type":"message"}
1619378338.139657: {"data":{"sequence":"1612702190341","bestAsk":"0.00006218","size":"0.0431","bestBidSize":"19.5017","price":"0.00006141","time":1619378338091,"bestAskSize":"43.3399","bestBid":"0.00006141"},"subject":"trade.ticker","topic":"/market/ticker:NRG-BTC","type":"message"}
1619378338.1396859: {"data":{"sequenceStart":1612712745684,"symbol":"FET-BTC","changes":{"asks":[],"bids":[["0.00000769","20","1612712745684"]]},"sequenceEnd":1612712745684},"subject":"trade.l2update","topic":"/market/level2:FET-BTC","type":"message"}
1619378338.139715: {"data":{"sequenceStart":1612701563985,"symbol":"DAPPT-BTC","changes":{"asks":[],"bids":[["0.000000112","0","1612701563985"]]},"sequenceEnd":1612701563985},"subject":"trade.l2update","topic":"/market/level2:DAPPT-BTC","type":"message"}
1619378338.139745: {"data":{"sequenceStart":1613277184807,"symbol":"BCHSV-USDT","changes":{"asks":[],"bids":[["0","0","1613277184807"]]},"sequenceEnd":1613277184807},"subject":"trade.l2update","topic":"/market/level2:BCHSV-USDT","type":"message"}
1619378338.1397629: {"data":{"sequenceStart":1613277184808,"symbol":"BCHSV-USDT","changes":{"asks":[],"bids":[["241.77","7.20618916","1613277184808"]]},"sequenceEnd":1613277184808},"subject":"trade.l2update","topic":"/market/level2:BCHSV-USDT","type":"message"}
1619378338.1397839: {"data":{"sequenceStart":1613277184809,"symbol":"BCHSV-USDT","changes":{"asks":[],"bids":[["242.188","0","1613277184809"]]},"sequenceEnd":1613277184809},"subject":"trade.l2update","topic":"/market/level2:BCHSV-USDT","type":"message"}
1619378338.139804: {"data":{"sequenceStart":1613277184810,"symbol":"BCHSV-USDT","changes":{"asks":[],"bids":[["241.753","0","1613277184810"]]},"sequenceEnd":1613277184810},"subject":"trade.l2update","topic":"/market/level2:BCHSV-USDT","type":"message"}
1619378338.146184: {"data":{"sequenceStart":1613277184811,"symbol":"BCHSV-USDT","changes":{"asks":[["0","0","1613277184811"]],"bids":[]},"sequenceEnd":1613277184811},"subject":"trade.l2update","topic":"/market/level2:BCHSV-USDT","type":"message"}
1619378338.146213: {"data":{"sequenceStart":1613277184812,"symbol":"BCHSV-USDT","changes":{"asks":[["243.096","2.99","1613277184812"]],"bids":[]},"sequenceEnd":1613277184812},"subject":"trade.l2update","topic":"/market/level2:BCHSV-USDT","type":"message"}
1619378338.1520598: {"data":{"sequenceStart":1612844051968,"symbol":"SNX-BTC","changes":{"asks":[["0","0","1612844051968"]],"bids":[]},"sequenceEnd":1612844051968},"subject":"trade.l2update","topic":"/market/level2:SNX-BTC","type":"message"}
1619378338.15209: {"data":{"sequenceStart":1612844051969,"symbol":"SNX-BTC","changes":{"asks":[["0.0002871","0.24960548","1612844051969"]],"bids":[]},"sequenceEnd":1612844051969},"subject":"trade.l2update","topic":"/market/level2:SNX-BTC","type":"message"}
1619378338.158396: {"data":{"sequenceStart":1612734157865,"symbol":"ANKR-BTC","changes":{"asks":[],"bids":[["0.0000025999","0","1612734157865"]]},"sequenceEnd":1612734157865},"subject":"trade.l2update","topic":"/market/level2:ANKR-BTC","type":"message"}
1619378338.158459: {"data":{"sequenceStart":1612734157866,"symbol":"ANKR-BTC","changes":{"asks":[],"bids":[["0.0000026","0","1612734157866"]]},"sequenceEnd":1612734157866},"subject":"trade.l2update","topic":"/market/level2:ANKR-BTC","type":"message"}
1619378338.158484: {"data":{"sequenceStart":1612701563986,"symbol":"DAPPT-BTC","changes":{"asks":[],"bids":[["0.0000001103","0","1612701563986"]]},"sequenceEnd":1612701563986},"subject":"trade.l2update","topic":"/market/level2:DAPPT-BTC","type":"message"}
1619378338.158516: {"data":{"sequenceStart":1613277184813,"symbol":"BCHSV-USDT","changes":{"asks":[],"bids":[["242.095","0","1613277184813"]]},"sequenceEnd":1613277184813},"subject":"trade.l2update","topic":"/market/level2:BCHSV-USDT","type":"message"}
1619378338.158536: {"data":{"sequenceStart":1613277184814,"symbol":"BCHSV-USDT","changes":{"asks":[["0","0","1613277184814"]],"bids":[]},"sequenceEnd":1613277184814},"subject":"trade.l2update","topic":"/market/level2:BCHSV-USDT","type":"message"}
1619378338.158549: {"data":{"sequenceStart":1613277184815,"symbol":"BCHSV-USDT","changes":{"asks":[["245.774","17.79999999","1613277184815"]],"bids":[]},"sequenceEnd":1613277184815},"subject":"trade.l2update","topic":"/market/level2:BCHSV-USDT","type":"message"}
1619378338.163456: {"data":{"sequenceStart":1612844051970,"symbol":"SNX-BTC","changes":{"asks":[["0.00028732","0","1612844051970"]],"bids":[]},"sequenceEnd":1612844051970},"subject":"trade.l2update","topic":"/market/level2:SNX-BTC","type":"message"}
1619378338.163539: {"data":{"sequenceStart":1612701563987,"symbol":"DAPPT-BTC","changes":{"asks":[["0.0000001133","4948.0983","1612701563987"]],"bids":[]},"sequenceEnd":1612701563987},"subject":"trade.l2update","topic":"/market/level2:DAPPT-BTC","type":"message"}
1619378338.187365: {"data":{"sequenceStart":1613277184816,"symbol":"BCHSV-USDT","changes":{"asks":[],"bids":[["242.795","0","1613277184816"]]},"sequenceEnd":1613277184816},"subject":"trade.l2update","topic":"/market/level2:BCHSV-USDT","type":"message"}
1619378338.1874619: {"data":{"sequenceStart":1613277184817,"symbol":"BCHSV-USDT","changes":{"asks":[["243.096","0","1613277184817"]],"bids":[]},"sequenceEnd":1613277184817},"subject":"trade.l2update","topic":"/market/level2:BCHSV-USDT","type":"message"}
1619378338.18751: {"data":{"sequenceStart":1613277184818,"symbol":"BCHSV-USDT","changes":{"asks":[["0","0","1613277184818"]],"bids":[]},"sequenceEnd":1613277184818},"subject":"trade.l2update","topic":"/market/level2:BCHSV-USDT","type":"message"}
1619378338.187537: {"data":{"sequenceStart":1613277184819,"symbol":"BCHSV-USDT","changes":{"asks":[["243.096","2.99","1613277184819"]],"bids":[]},"sequenceEnd":1613277184819},"subject":"trade.l2update","topic":"/market/level2:BCHSV-USDT","type":"message"}
1619378338.187572: {"data":{"sequence":"1612701563987","bestAsk":"0.000000113","size":"145.4959","bestBidSize":"361.2609","price":"0.0000001126","time":1619378338130,"bestAskSize":"1208.0878","bestBid":"0.0000001119"},"subject":"trade.ticker","topic":"/market/ticker:DAPPT-BTC","type":"message"}
1619378338.1876118: {"data":{"sequence":"1613277184815","bestAsk":"243.051","size":"0.14324938","bestBidSize":"5","price":"242.781","time":1619378338133,"bestAskSize":"1","bestBid":"242.795"},"subject":"trade.ticker","topic":"/market/ticker:BCHSV-USDT","type":"message"}
1619378338.189303: {"data":{"sequenceStart":1619079123950,"symbol":"EQZ-BTC","changes":{"asks":[],"bids":[["0","0","1619079123950"]]},"sequenceEnd":1619079123950},"subject":"trade.l2update","topic":"/market/level2:EQZ-BTC","type":"message"}
1619378338.189379: {"data":{"sequenceStart":1612844051971,"symbol":"SNX-BTC","changes":{"asks":[["0","0","1612844051971"]],"bids":[]},"sequenceEnd":1612844051971},"subject":"trade.l2update","topic":"/market/level2:SNX-BTC","type":"message"}
1619378338.189412: {"data":{"sequenceStart":1612844051972,"symbol":"SNX-BTC","changes":{"asks":[["0.00028719","73.34812145","1612844051972"]],"bids":[]},"sequenceEnd":1612844051972},"subject":"trade.l2update","topic":"/market/level2:SNX-BTC","type":"message"}
1619378338.1894588: {"data":{"sequence":"1612844051972","bestAsk":"0.0002871","size":"0.01745248","bestBidSize":"0.19100065","price":"0.00028676","time":1619378338148,"bestAskSize":"0.24960548","bestBid":"0.00028678"},"subject":"trade.ticker","topic":"/market/ticker:SNX-BTC","type":"message"}
1619378338.192675: {"data":{"sequenceStart":1612844051973,"symbol":"SNX-BTC","changes":{"asks":[],"bids":[["0","0","1612844051973"]]},"sequenceEnd":1612844051973},"subject":"trade.l2update","topic":"/market/level2:SNX-BTC","type":"message"}
1619378338.1928031: {"data":{"sequenceStart":1612844051974,"symbol":"SNX-BTC","changes":{"asks":[],"bids":[["0.00028658","14.06852335","1612844051974"]]},"sequenceEnd":1612844051974},"subject":"trade.l2update","topic":"/market/level2:SNX-BTC","type":"message"}
1619378338.1989608: {"data":{"sequenceStart":1613277184820,"symbol":"BCHSV-USDT","changes":{"asks":[],"bids":[["241.754","0","1613277184820"]]},"sequenceEnd":1613277184820},"subject":"trade.l2update","topic":"/market/level2:BCHSV-USDT","type":"message"}
1619378338.199012: {"data":{"sequenceStart":1612702190342,"symbol":"NRG-BTC","changes":{"asks":[["0","0","1612702190342"]],"bids":[]},"sequenceEnd":1612702190342},"subject":"trade.l2update","topic":"/market/level2:NRG-BTC","type":"message"}
1619378338.199035: {"data":{"sequenceStart":1612702190343,"symbol":"NRG-BTC","changes":{"asks":[["0.0000623","13.679","1612702190343"]],"bids":[]},"sequenceEnd":1612702190343},"subject":"trade.l2update","topic":"/market/level2:NRG-BTC","type":"message"}
1619378338.2089741: {"data":{"sequenceStart":1613277184821,"symbol":"BCHSV-USDT","changes":{"asks":[],"bids":[["0","0","1613277184821"]]},"sequenceEnd":1613277184821},"subject":"trade.l2update","topic":"/market/level2:BCHSV-USDT","type":"message"}
1619378338.209038: {"data":{"sequenceStart":1613277184822,"symbol":"BCHSV-USDT","changes":{"asks":[],"bids":[["241.846","20.43","1613277184822"]]},"sequenceEnd":1613277184822},"subject":"trade.l2update","topic":"/market/level2:BCHSV-USDT","type":"message"}
1619378338.2090812: {"data":{"sequenceStart":1613277184823,"symbol":"BCHSV-USDT","changes":{"asks":[],"bids":[["0","0","1613277184823"]]},"sequenceEnd":1613277184823},"subject":"trade.l2update","topic":"/market/level2:BCHSV-USDT","type":"message"}
1619378338.2091038: {"data":{"sequenceStart":1613277184824,"symbol":"BCHSV-USDT","changes":{"asks":[],"bids":[["242.089","5.52","1613277184824"]]},"sequenceEnd":1613277184824},"subject":"trade.l2update","topic":"/market/level2:BCHSV-USDT","type":"message"}
1619378338.20913: {"data":{"sequenceStart":1613277184825,"symbol":"BCHSV-USDT","changes":{"asks":[["0","0","1613277184825"]],"bids":[]},"sequenceEnd":1613277184825},"subject":"trade.l2update","topic":"/market/level2:BCHSV-USDT","type":"message"}
1619378338.209148: {"data":{"sequenceStart":1613277184826,"symbol":"BCHSV-USDT","changes":{"asks":[["0","0","1613277184826"]],"bids":[]},"sequenceEnd":1613277184826},"subject":"trade.l2update","topic":"/market/level2:BCHSV-USDT","type":"message"}
1619378338.2091641: {"data":{"sequenceStart":1613277184827,"symbol":"BCHSV-USDT","changes":{"asks":[["0","0","1613277184827"]],"bids":[]},"sequenceEnd":1613277184827},"subject":"trade.l2update","topic":"/market/level2:BCHSV-USDT","type":"message"}
1619378338.2091799: {"data":{"sequenceStart":1613277184828,"symbol":"BCHSV-USDT","changes":{"asks":[["243.106","0.30624872","1613277184828"]],"bids":[]},"sequenceEnd":1613277184828},"subject":"trade.l2update","topic":"/market/level2:BCHSV-USDT","type":"message"}
1619378338.215886: {"data":{"sequence":"1612712745684","bestAsk":"0.00000776","size":"401.2004","bestBidSize":"357.285","price":"0.00000772","time":1619378338167,"bestAskSize":"1993.0416","bestBid":"0.00000771"},"subject":"trade.ticker","topic":"/market/ticker:FET-BTC","type":"message"}
1619378338.215977: {"data":{"sequenceStart":1612844051975,"symbol":"SNX-BTC","changes":{"asks":[["0.0002871","0","1612844051975"]],"bids":[]},"sequenceEnd":1612844051975},"subject":"trade.l2update","topic":"/market/level2:SNX-BTC","type":"message"}
1619378338.216074: {"data":{"sequenceStart":1612734157867,"symbol":"ANKR-BTC","changes":{"asks":[],"bids":[["0","0","1612734157867"]]},"sequenceEnd":1612734157867},"subject":"trade.l2update","topic":"/market/level2:ANKR-BTC","type":"message"}
1619378338.2161229: {"data":{"sequenceStart":1612734157868,"symbol":"ANKR-BTC","changes":{"asks":[],"bids":[["0.0000026001","5034.7285","1612734157868"]]},"sequenceEnd":1612734157868},"subject":"trade.l2update","topic":"/market/level2:ANKR-BTC","type":"message"}
1619378338.21618: {"data":{"sequenceStart":1613277184829,"symbol":"BCHSV-USDT","changes":{"asks":[["0","0","1613277184829"]],"bids":[]},"sequenceEnd":1613277184829},"subject":"trade.l2update","topic":"/market/level2:BCHSV-USDT","type":"message"}
1619378338.2232761: {"data":{"sequenceStart":1613277184830,"symbol":"BCHSV-USDT","changes":{"asks":[["0","0","1613277184830"]],"bids":[]},"sequenceEnd":1613277184830},"subject":"trade.l2update","topic":"/market/level2:BCHSV-USDT","type":"message"}
1619378338.230305: {"data":{"sequenceStart":1612699351271,"symbol":"COV-BTC","changes":{"asks":[["0","0","1612699351271"]],"bids":[]},"sequenceEnd":1612699351271},"subject":"trade.l2update","topic":"/market/level2:COV-BTC","type":"message"}
1619378338.23038: {"data":{"sequence":"1612734157870","bestAsk":"0.0000026208","size":"46","bestBidSize":"5034.7285","price":"0.0000026071","time":1619378338188,"bestAskSize":"10987.6265","bestBid":"0.0000026001"},"subject":"trade.ticker","topic":"/market/ticker:ANKR-BTC","type":"message"}
1619378338.230418: {"data":{"sequenceStart":1612699351272,"symbol":"COV-BTC","changes":{"asks":[["0.00001127","4469.58576035","1612699351272"]],"bids":[]},"sequenceEnd":1612699351272},"subject":"trade.l2update","topic":"/market/level2:COV-BTC","type":"message"}
1619378338.230459: {"data":{"sequenceStart":1612694580174,"symbol":"CAPP-BTC","changes":{"asks":[["0","0","1612694580174"]],"bids":[]},"sequenceEnd":1612694580174},"subject":"trade.l2update","topic":"/market/level2:CAPP-BTC","type":"message"}
1619378338.230485: {"data":{"sequenceStart":1612694580175,"symbol":"CAPP-BTC","changes":{"asks":[["0.0000002196","330.25","1612694580175"]],"bids":[]},"sequenceEnd":1612694580175},"subject":"trade.l2update","topic":"/market/level2:CAPP-BTC","type":"message"}
1619378338.230526: {"data":{"sequenceStart":1612734157869,"symbol":"ANKR-BTC","changes":{"asks":[],"bids":[["0","0","1612734157869"]]},"sequenceEnd":1612734157869},"subject":"trade.l2update","topic":"/market/level2:ANKR-BTC","type":"message"}
1619378338.23055: {"data":{"sequenceStart":1612734157870,"symbol":"ANKR-BTC","changes":{"asks":[],"bids":[["0.0000026","576.8987","1612734157870"]]},"sequenceEnd":1612734157870},"subject":"trade.l2update","topic":"/market/level2:ANKR-BTC","type":"message"}
1619378338.2399812: {"data":{"sequence":"1612699351272","bestAsk":"0.00001127","size":"96.1525","bestBidSize":"49.6422","price":"0.00001126","time":1619378338189,"bestAskSize":"4469.58576035","bestBid":"0.00001121"},"subject":"trade.ticker","topic":"/market/ticker:COV-BTC","type":"message"}
1619378338.240015: {"data":{"sequence":"1612702190343","bestAsk":"0.00006218","size":"0.0431","bestBidSize":"19.5017","price":"0.00006141","time":1619378338191,"bestAskSize":"43.3399","bestBid":"0.00006141"},"subject":"trade.ticker","topic":"/market/ticker:NRG-BTC","type":"message"}
1619378338.240031: {"data":{"sequenceStart":1612844051976,"symbol":"SNX-BTC","changes":{"asks":[],"bids":[["0","0","1612844051976"]]},"sequenceEnd":1612844051976},"subject":"trade.l2update","topic":"/market/level2:SNX-BTC","type":"message"}
1619378338.240053: {"data":{"sequenceStart":1612844051977,"symbol":"SNX-BTC","changes":{"asks":[],"bids":[["0.0002825","119.52410924","1612844051977"]]},"sequenceEnd":1612844051977},"subject":"trade.l2update","topic":"/market/level2:SNX-BTC","type":"message"}
1619378338.2400799: {"data":{"sequenceStart":1612844051978,"symbol":"SNX-BTC","changes":{"asks":[],"bids":[["0.00028658","0","1612844051978"]]},"sequenceEnd":1612844051978},"subject":"trade.l2update","topic":"/market/level2:SNX-BTC","type":"message"}
1619378338.240107: {"data":{"sequenceStart":1613277184831,"symbol":"BCHSV-USDT","changes":{"asks":[["243.106","0","1613277184831"]],"bids":[]},"sequenceEnd":1613277184831},"subject":"trade.l2update","topic":"/market/level2:BCHSV-USDT","type":"message"}
1619378338.251203: {"data":{"sequenceStart":1613277184832,"symbol":"BCHSV-USDT","changes":{"asks":[],"bids":[["0","0","1613277184832"]]},"sequenceEnd":1613277184832},"subject":"trade.l2update","topic":"/market/level2:BCHSV-USDT","type":"message"}
1619378338.251241: {"data":{"sequenceStart":1613277184833,"symbol":"BCHSV-USDT","changes":{"asks":[],"bids":[["242.579","4.51280965","1613277184833"]]},"sequenceEnd":1613277184833},"subject":"trade.l2update","topic":"/market/level2:BCHSV-USDT","type":"message"}
1619378338.251273: {"data":{"sequenceStart":1613277184834,"symbol":"BCHSV-USDT","changes":{"asks":[["0","0","1613277184834"]],"bids":[]},"sequenceEnd":1613277184834},"subject":"trade.l2update","topic":"/market/level2:BCHSV-USDT","type":"message"}
1619378338.251292: {"data":{"sequenceStart":1613277184835,"symbol":"BCHSV-USDT","changes":{"asks":[["243.072","2.99","1613277184835"]],"bids":[]},"sequenceEnd":1613277184835},"subject":"trade.l2update","topic":"/market/level2:BCHSV-USDT","type":"message"}
1619378338.251314: {"data":{"sequenceStart":1613277184836,"symbol":"BCHSV-USDT","changes":{"asks":[],"bids":[["0","0","1613277184836"]]},"sequenceEnd":1613277184836},"subject":"trade.l2update","topic":"/market/level2:BCHSV-USDT","type":"message"}
1619378338.251328: {"data":{"sequenceStart":1613277184837,"symbol":"BCHSV-USDT","changes":{"asks":[],"bids":[["242.397","6.17566142","1613277184837"]]},"sequenceEnd":1613277184837},"subject":"trade.l2update","topic":"/market/level2:BCHSV-USDT","type":"message"}
1619378338.2513468: {"data":{"sequenceStart":1613277184838,"symbol":"BCHSV-USDT","changes":{"asks":[],"bids":[["0","0","1613277184838"]]},"sequenceEnd":1613277184838},"subject":"trade.l2update","topic":"/market/level2:BCHSV-USDT","type":"message"}
1619378338.2513611: {"data":{"sequenceStart":1613277184839,"symbol":"BCHSV-USDT","changes":{"asks":[],"bids":[["242.623","0.45082023","1613277184839"]]},"sequenceEnd":1613277184839},"subject":"trade.l2update","topic":"/market/level2:BCHSV-USDT","type":"message"}
1619378338.251379: {"data":{"sequenceStart":1613277184840,"symbol":"BCHSV-USDT","changes":{"asks":[],"bids":[["242.773","0","1613277184840"]]},"sequenceEnd":1613277184840},"subject":"trade.l2update","topic":"/market/level2:BCHSV-USDT","type":"message"}
1619378338.251401: {"data":{"sequenceStart":1613277184841,"symbol":"BCHSV-USDT","changes":{"asks":[["243.096","0","1613277184841"]],"bids":[]},"sequenceEnd":1613277184841},"subject":"trade.l2update","topic":"/market/level2:BCHSV-USDT","type":"message"}
1619378338.256808: {"data":{"sequenceStart":1612734157871,"symbol":"ANKR-BTC","changes":{"asks":[],"bids":[["0.0000026","0","1612734157871"]]},"sequenceEnd":1612734157871},"subject":"trade.l2update","topic":"/market/level2:ANKR-BTC","type":"message"}
1619378338.264886: {"data":{"sequenceStart":1613277184842,"symbol":"BCHSV-USDT","changes":{"asks":[["0","0","1613277184842"]],"bids":[]},"sequenceEnd":1613277184842},"subject":"trade.l2update","topic":"/market/level2:BCHSV-USDT","type":"message"}
1619378338.26493: {"data":{"sequenceStart":1613277184843,"symbol":"BCHSV-USDT","changes":{"asks":[["243","4.51280965","1613277184843"]],"bids":[]},"sequenceEnd":1613277184843},"subject":"trade.l2update","topic":"/market/level2:BCHSV-USDT","type":"message"}
1619378338.27055: {"data":{"sequenceStart":1612699351273,"symbol":"COV-BTC","changes":{"asks":[["0.00001127","4331.68226035","1612699351273"]],"bids":[]},"sequenceEnd":1612699351273},"subject":"trade.l2update","topic":"/market/level2:COV-BTC","type":"message"}
1619378338.2706199: {"data":{"sequenceStart":1613277184844,"symbol":"BCHSV-USDT","changes":{"asks":[],"bids":[["242.476","2.99","1613277184844"]]},"sequenceEnd":1613277184844},"subject":"trade.l2update","topic":"/market/level2:BCHSV-USDT","type":"message"}
1619378338.2706518: {"data":{"sequenceStart":1613277184845,"symbol":"BCHSV-USDT","changes":{"asks":[],"bids":[["242.476","0","1613277184845"]]},"sequenceEnd":1613277184845},"subject":"trade.l2update","topic":"/market/level2:BCHSV-USDT","type":"message"}
1619378338.2706869: {"data":{"sequenceStart":1613277184846,"symbol":"BCHSV-USDT","changes":{"asks":[["243.072","0","1613277184846"]],"bids":[]},"sequenceEnd":1613277184846},"subject":"trade.l2update","topic":"/market/level2:BCHSV-USDT","type":"message"}
1619378338.2707179: {"data":{"sequence":"1613277184846","bestAsk":"243","size":"0.14324938","bestBidSize":"52.488","price":"242.781","time":1619378338233,"bestAskSize":"4.51280965","bestBid":"242.686"},"subject":"trade.ticker","topic":"/market/ticker:BCHSV-USDT","type":"message"}
1619378338.27075: {"data":{"sequenceStart":1612712745685,"symbol":"FET-BTC","changes":{"asks":[],"bids":[["0","0","1612712745685"]]},"sequenceEnd":1612712745685},"subject":"trade.l2update","topic":"/market/level2:FET-BTC","type":"message"}
1619378338.270771: {"data":{"sequenceStart":1612712745686,"symbol":"FET-BTC","changes":{"asks":[],"bids":[["0.00000769","88.5593","1612712745686"]]},"sequenceEnd":1612712745686},"subject":"trade.l2update","topic":"/market/level2:FET-BTC","type":"message"}
1619378338.276051: {"data":{"sequenceStart":1612844051979,"symbol":"SNX-BTC","changes":{"asks":[["0","0","1612844051979"]],"bids":[]},"sequenceEnd":1612844051979},"subject":"trade.l2update","topic":"/market/level2:SNX-BTC","type":"message"}
1619378338.276157: {"data":{"sequenceStart":1612844051980,"symbol":"SNX-BTC","changes":{"asks":[["0.00028736","256.72194469","1612844051980"]],"bids":[]},"sequenceEnd":1612844051980},"subject":"trade.l2update","topic":"/market/level2:SNX-BTC","type":"message"}
1619378338.276235: {"data":{"sequence":"1619079123950","bestAsk":"0.00002395","size":"0.375","bestBidSize":"20.5373","price":"0.00002383","time":1619378338238,"bestAskSize":"72.1515","bestBid":"0.00002383"},"subject":"trade.ticker","topic":"/market/ticker:EQZ-BTC","type":"message"}
1619378338.282889: {"data":{"sequenceStart":1613277184847,"symbol":"BCHSV-USDT","changes":{"asks":[],"bids":[["242.623","0","1613277184847"]]},"sequenceEnd":1613277184847},"subject":"trade.l2update","topic":"/market/level2:BCHSV-USDT","type":"message"}
1619378338.28758: {"data":{"sequence":"1612844051980","bestAsk":"0.00028711","size":"0.01745248","bestBidSize":"0.19100065","price":"0.00028676","time":1619378338248,"bestAskSize":"29.24570683","bestBid":"0.00028678"},"subject":"trade.ticker","topic":"/market/ticker:SNX-BTC","type":"message"}
1619378338.29405: {"data":{"sequenceStart":1613277184848,"symbol":"BCHSV-USDT","changes":{"asks":[["0","0","1613277184848"]],"bids":[]},"sequenceEnd":1613277184848},"subject":"trade.l2update","topic":"/market/level2:BCHSV-USDT","type":"message"}
1619378338.2941608: {"data":{"sequenceStart":1613277184849,"symbol":"BCHSV-USDT","changes":{"asks":[["243.072","2.99","1613277184849"]],"bids":[]},"sequenceEnd":1613277184849},"subject":"trade.l2update","topic":"/market/level2:BCHSV-USDT","type":"message"}
1619378338.3016572: {"data":{"sequenceStart":1612712745687,"symbol":"FET-BTC","changes":{"asks":[["0.00000776","1154.0416","1612712745687"]],"bids":[]},"sequenceEnd":1612712745687},"subject":"trade.l2update","topic":"/market/level2:FET-BTC","type":"message"}
1619378338.3017411: {"data":{"sequenceStart":1613277184850,"symbol":"BCHSV-USDT","changes":{"asks":[["243.051","0","1613277184850"]],"bids":[]},"sequenceEnd":1613277184850},"subject":"trade.l2update","topic":"/market/level2:BCHSV-USDT","type":"message"}
1619378338.301794: {"data":{"sequenceStart":1613277184851,"symbol":"BCHSV-USDT","changes":{"asks":[],"bids":[["242.686","0","1613277184851"]]},"sequenceEnd":1613277184851},"subject":"trade.l2update","topic":"/market/level2:BCHSV-USDT","type":"message"}
1619378338.308043: {"data":{"sequenceStart":1612701563988,"symbol":"DAPPT-BTC","changes":{"asks":[["0","0","1612701563988"]],"bids":[]},"sequenceEnd":1612701563988},"subject":"trade.l2update","topic":"/market/level2:DAPPT-BTC","type":"message"}
1619378338.308154: {"data":{"sequenceStart":1612701563989,"symbol":"DAPPT-BTC","changes":{"asks":[["0.0000001133","6048.9923","1612701563989"]],"bids":[]},"sequenceEnd":1612701563989},"subject":"trade.l2update","topic":"/market/level2:DAPPT-BTC","type":"message"}
1619378338.3082209: {"data":{"sequenceStart":1612701563990,"symbol":"DAPPT-BTC","changes":{"asks":[],"bids":[["0","0","1612701563990"]]},"sequenceEnd":1612701563990},"subject":"trade.l2update","topic":"/market/level2:DAPPT-BTC","type":"message"}
1619378338.308265: {"data":{"sequenceStart":1612701563991,"symbol":"DAPPT-BTC","changes":{"asks":[],"bids":[["0.000000112","5148.7686","1612701563991"]]},"sequenceEnd":1612701563991},"subject":"trade.l2update","topic":"/market/level2:DAPPT-BTC","type":"message"}
1619378338.313925: {"data":{"sequence":"1612712745687","bestAsk":"0.00000776","size":"401.2004","bestBidSize":"357.285","price":"0.00000772","time":1619378338268,"bestAskSize":"1154.0416","bestBid":"0.00000771"},"subject":"trade.ticker","topic":"/market/ticker:FET-BTC","type":"message"}
1619378338.314027: {"data":{"sequenceStart":1613277184852,"symbol":"BCHSV-USDT","changes":{"asks":[["0","0","1613277184852"]],"bids":[]},"sequenceEnd":1613277184852},"subject":"trade.l2update","topic":"/market/level2:BCHSV-USDT","type":"message"}
1619378338.314095: {"data":{"sequenceStart":1613277184853,"symbol":"BCHSV-USDT","changes":{"asks":[["243.262","0.6","1613277184853"]],"bids":[]},"sequenceEnd":1613277184853},"subject":"trade.l2update","topic":"/market/level2:BCHSV-USDT","type":"message"}
1619378338.3141701: {"data":{"sequenceStart":1613277184854,"symbol":"BCHSV-USDT","changes":{"asks":[["247.395","0","1613277184854"]],"bids":[]},"sequenceEnd":1613277184854},"subject":"trade.l2update","topic":"/market/level2:BCHSV-USDT","type":"message"}
1619378338.322647: {"data":{"sequenceStart":1619079123951,"symbol":"EQZ-BTC","changes":{"asks":[],"bids":[["0","0","1619079123951"]]},"sequenceEnd":1619079123951},"subject":"trade.l2update","topic":"/market/level2:EQZ-BTC","type":"message"}
1619378338.322756: {"data":{"sequenceStart":1619079123952,"symbol":"EQZ-BTC","changes":{"asks":[],"bids":[["0","0","1619079123952"]]},"sequenceEnd":1619079123952},"subject":"trade.l2update","topic":"/market/level2:EQZ-BTC","type":"message"}
1619378338.322805: {"data":{"sequence":"1612694580175","bestAsk":"0.0000002196","size":"1000.02","bestBidSize":"83.07","price":"0.0000002182","time":1619378338282,"bestAskSize":"330.25","bestBid":"0.0000002181"},"subject":"trade.ticker","topic":"/market/ticker:CAPP-BTC","type":"message"}
1619378338.333195: {"data":{"sequenceStart":1613277184855,"symbol":"BCHSV-USDT","changes":{"asks":[],"bids":[["0","0","1613277184855"]]},"sequenceEnd":1613277184855},"subject":"trade.l2update","topic":"/market/level2:BCHSV-USDT","type":"message"}
1619378338.333329: {"data":{"sequenceStart":1613277184856,"symbol":"BCHSV-USDT","changes":{"asks":[],"bids":[["241.603","9.6068238","1613277184856"]]},"sequenceEnd":1613277184856},"subject":"trade.l2update","topic":"/market/level2:BCHSV-USDT","type":"message"}
1619378338.3333812: {"data":{"sequenceStart":1613277184857,"symbol":"BCHSV-USDT","changes":{"asks":[["243.072","0","1613277184857"]],"bids":[]},"sequenceEnd":1613277184857},"subject":"trade.l2update","topic":"/market/level2:BCHSV-USDT","type":"message"}
1619378338.3334248: {"data":{"sequenceStart":1613277184858,"symbol":"BCHSV-USDT","changes":{"asks":[],"bids":[["0","0","1613277184858"]]},"sequenceEnd":1613277184858},"subject":"trade.l2update","topic":"/market/level2:BCHSV-USDT","type":"message"}
1619378338.333451: {"data":{"sequenceStart":1613277184859,"symbol":"BCHSV-USDT","changes":{"asks":[],"bids":[["242.108","2.99","1613277184859"]]},"sequenceEnd":1613277184859},"subject":"trade.l2update","topic":"/market/level2:BCHSV-USDT","type":"message"}
1619378338.333482: {"data":{"sequence":"1612699351273","bestAsk":"0.00001127","size":"96.1525","bestBidSize":"49.6422","price":"0.00001126","time":1619378338288,"bestAskSize":"4331.68226035","bestBid":"0.00001121"},"subject":"trade.ticker","topic":"/market/ticker:COV-BTC","type":"message"}
1619378338.333507: {"data":{"sequenceStart":1612844051981,"symbol":"SNX-BTC","changes":{"asks":[],"bids":[["0","0","1612844051981"]]},"sequenceEnd":1612844051981},"subject":"trade.l2update","topic":"/market/level2:SNX-BTC","type":"message"}
1619378338.3335302: {"data":{"sequenceStart":1612844051982,"symbol":"SNX-BTC","changes":{"asks":[],"bids":[["0.0002866","5.23456036","1612844051982"]]},"sequenceEnd":1612844051982},"subject":"trade.l2update","topic":"/market/level2:SNX-BTC","type":"message"}
1619378338.33356: {"data":{"sequenceStart":1612844051983,"symbol":"SNX-BTC","changes":{"asks":[["0","0","1612844051983"]],"bids":[]},"sequenceEnd":1612844051983},"subject":"trade.l2update","topic":"/market/level2:SNX-BTC","type":"message"}
1619378338.3335822: {"data":{"sequenceStart":1612844051984,"symbol":"SNX-BTC","changes":{"asks":[["0.0002871","8.70767455","1612844051984"]],"bids":[]},"sequenceEnd":1612844051984},"subject":"trade.l2update","topic":"/market/level2:SNX-BTC","type":"message"}
1619378338.335333: {"data":{"sequenceStart":1612712745688,"symbol":"FET-BTC","changes":{"asks":[["0","0","1612712745688"]],"bids":[]},"sequenceEnd":1612712745688},"subject":"trade.l2update","topic":"/market/level2:FET-BTC","type":"message"}
1619378338.335409: {"data":{"sequenceStart":1612712745689,"symbol":"FET-BTC","changes":{"asks":[["0.00000781","159.36","1612712745689"]],"bids":[]},"sequenceEnd":1612712745689},"subject":"trade.l2update","topic":"/market/level2:FET-BTC","type":"message"}
1619378338.341131: {"data":{"sequenceStart":1612844051985,"symbol":"SNX-BTC","changes":{"asks":[["0.000291","0","1612844051985"]],"bids":[]},"sequenceEnd":1612844051985},"subject":"trade.l2update","topic":"/market/level2:SNX-BTC","type":"message"}
1619378338.345574: {"data":{"sequence":"1612734157871","bestAsk":"0.0000026208","size":"46","bestBidSize":"5034.7285","price":"0.0000026071","time":1619378338288,"bestAskSize":"10987.6265","bestBid":"0.0000026001"},"subject":"trade.ticker","topic":"/market/ticker:ANKR-BTC","type":"message"}
1619378338.3617249: {"data":{"sequenceStart":1613277184860,"symbol":"BCHSV-USDT","changes":{"asks":[["0","0","1613277184860"]],"bids":[]},"sequenceEnd":1613277184860},"subject":"trade.l2update","topic":"/market/level2:BCHSV-USDT","type":"message"}
1619378338.361836: {"data":{"sequenceStart":1613277184861,"symbol":"BCHSV-USDT","changes":{"asks":[["243.05","2.99","1613277184861"]],"bids":[]},"sequenceEnd":1613277184861},"subject":"trade.l2update","topic":"/market/level2:BCHSV-USDT","type":"message"}
1619378338.3619149: {"data":{"sequenceStart":1613277184862,"symbol":"BCHSV-USDT","changes":{"asks":[],"bids":[["0","0","1613277184862"]]},"sequenceEnd":1613277184862},"subject":"trade.l2update","topic":"/market/level2:BCHSV-USDT","type":"message"}
1619378338.361963: {"data":{"sequenceStart":1613277184863,"symbol":"BCHSV-USDT","changes":{"asks":[],"bids":[["242.108","5.98","1613277184863"]]},"sequenceEnd":1613277184863},"subject":"trade.l2update","topic":"/market/level2:BCHSV-USDT","type":"message"}
1619378338.3784058: {"data":{"sequence":"1612701563991","bestAsk":"0.000000113","size":"145.4959","bestBidSize":"5148.7686","price":"0.0000001126","time":1619378338330,"bestAskSize":"1208.0878","bestBid":"0.000000112"},"subject":"trade.ticker","topic":"/market/ticker:DAPPT-BTC","type":"message"}
1619378338.381526: {"data":{"sequence":"1613277184863","bestAsk":"243","size":"0.14324938","bestBidSize":"0.05000051","price":"242.781","time":1619378338333,"bestAskSize":"4.51280965","bestBid":"242.583"},"subject":"trade.ticker","topic":"/market/ticker:BCHSV-USDT","type":"message"}
1619378338.381623: {"data":{"sequence":"1619079123952","bestAsk":"0.00002395","size":"0.375","bestBidSize":"20.5373","price":"0.00002383","time":1619378338338,"bestAskSize":"72.1515","bestBid":"0.00002383"},"subject":"trade.ticker","topic":"/market/ticker:EQZ-BTC","type":"message"}
1619378338.387329: {"data":{"sequenceStart":1613277184864,"symbol":"BCHSV-USDT","changes":{"asks":[["243.554","0","1613277184864"]],"bids":[]},"sequenceEnd":1613277184864},"subject":"trade.l2update","topic":"/market/level2:BCHSV-USDT","type":"message"}
1619378338.387469: {"data":{"sequenceStart":1613277184865,"symbol":"BCHSV-USDT","changes":{"asks":[["0","0","1613277184865"]],"bids":[]},"sequenceEnd":1613277184865},"subject":"trade.l2update","topic":"/market/level2:BCHSV-USDT","type":"message"}
1619378338.3875232: {"data":{"sequenceStart":1613277184866,"symbol":"BCHSV-USDT","changes":{"asks":[["243.05","5.98","1613277184866"]],"bids":[]},"sequenceEnd":1613277184866},"subject":"trade.l2update","topic":"/market/level2:BCHSV-USDT","type":"message"}
1619378338.387573: {"data":{"sequenceStart":1612844051986,"symbol":"SNX-BTC","changes":{"asks":[["0.0002871","0","1612844051986"]],"bids":[]},"sequenceEnd":1612844051986},"subject":"trade.l2update","topic":"/market/level2:SNX-BTC","type":"message"}
1619378338.3876412: {"data":{"sequence":"1612844051986","bestAsk":"0.00028711","size":"0.01745248","bestBidSize":"0.19100065","price":"0.00028676","time":1619378338347,"bestAskSize":"29.24570683","bestBid":"0.00028678"},"subject":"trade.ticker","topic":"/market/ticker:SNX-BTC","type":"message"}
1619378338.3928761: {"data":{"sequenceStart":1613277184867,"symbol":"BCHSV-USDT","changes":{"asks":[["0","0","1613277184867"]],"bids":[]},"sequenceEnd":1613277184867},"subject":"trade.l2update","topic":"/market/level2:BCHSV-USDT","type":"message"}
1619378338.392986: {"data":{"sequenceStart":1613277184868,"symbol":"BCHSV-USDT","changes":{"asks":[["246.421","37.111","1613277184868"]],"bids":[]},"sequenceEnd":1613277184868},"subject":"trade.l2update","topic":"/market/level2:BCHSV-USDT","type":"message"}
1619378338.3968582: {"data":{"sequenceStart":1613277184869,"symbol":"BCHSV-USDT","changes":{"asks":[["243.184","0","1613277184869"]],"bids":[]},"sequenceEnd":1613277184869},"subject":"trade.l2update","topic":"/market/level2:BCHSV-USDT","type":"message"}
1619378338.396966: {"data":{"sequenceStart":1613277184870,"symbol":"BCHSV-USDT","changes":{"asks":[["243.262","0","1613277184870"]],"bids":[]},"sequenceEnd":1613277184870},"subject":"trade.l2update","topic":"/market/level2:BCHSV-USDT","type":"message"}
1619378338.408587: {"data":{"sequence":"1612712745689","bestAsk":"0.00000776","size":"401.2004","bestBidSize":"357.285","price":"0.00000772","time":1619378338367,"bestAskSize":"1154.0416","bestBid":"0.00000771"},"subject":"trade.ticker","topic":"/market/ticker:FET-BTC","type":"message"}
1619378338.413003: {"data":{"sequenceStart":1612701563992,"symbol":"DAPPT-BTC","changes":{"asks":[],"bids":[["0.0000001097","0","1612701563992"]]},"sequenceEnd":1612701563992},"subject":"trade.l2update","topic":"/market/level2:DAPPT-BTC","type":"message"}
1619378338.4187012: {"data":{"sequenceStart":1613277184871,"symbol":"BCHSV-USDT","changes":{"asks":[],"bids":[["0","0","1613277184871"]]},"sequenceEnd":1613277184871},"subject":"trade.l2update","topic":"/market/level2:BCHSV-USDT","type":"message"}
1619378338.4187799: {"data":{"sequenceStart":1613277184872,"symbol":"BCHSV-USDT","changes":{"asks":[],"bids":[["242.635","0.45082023","1613277184872"]]},"sequenceEnd":1613277184872},"subject":"trade.l2update","topic":"/market/level2:BCHSV-USDT","type":"message"}
1619378338.469337: {"data":{"sequence":"1612701563992","bestAsk":"0.000000113","size":"145.4959","bestBidSize":"5148.7686","price":"0.0000001126","time":1619378338430,"bestAskSize":"1208.0878","bestBid":"0.000000112"},"subject":"trade.ticker","topic":"/market/ticker:DAPPT-BTC","type":"message"}
1619378338.4740748: {"data":{"sequenceStart":1613277184873,"symbol":"BCHSV-USDT","changes":{"asks":[["0","0","1613277184873"]],"bids":[]},"sequenceEnd":1613277184873},"subject":"trade.l2update","topic":"/market/level2:BCHSV-USDT","type":"message"}
1619378338.474186: {"data":{"sequenceStart":1613277184874,"symbol":"BCHSV-USDT","changes":{"asks":[["244.517","150","1613277184874"]],"bids":[]},"sequenceEnd":1613277184874},"subject":"trade.l2update","topic":"/market/level2:BCHSV-USDT","type":"message"}
1619378338.4742668: {"data":{"sequenceStart":1613277184875,"symbol":"BCHSV-USDT","changes":{"asks":[["0","0","1613277184875"]],"bids":[]},"sequenceEnd":1613277184875},"subject":"trade.l2update","topic":"/market/level2:BCHSV-USDT","type":"message"}
1619378338.47431: {"data":{"sequenceStart":1613277184876,"symbol":"BCHSV-USDT","changes":{"asks":[["243.879","5","1613277184876"]],"bids":[]},"sequenceEnd":1613277184876},"subject":"trade.l2update","topic":"/market/level2:BCHSV-USDT","type":"message"}
1619378338.47436: {"data":{"sequenceStart":1613277184877,"symbol":"BCHSV-USDT","changes":{"asks":[],"bids":[["0","0","1613277184877"]]},"sequenceEnd":1613277184877},"subject":"trade.l2update","topic":"/market/level2:BCHSV-USDT","type":"message"}
1619378338.474396: {"data":{"sequenceStart":1613277184878,"symbol":"BCHSV-USDT","changes":{"asks":[],"bids":[["241.717","5","1613277184878"]]},"sequenceEnd":1613277184878},"subject":"trade.l2update","topic":"/market/level2:BCHSV-USDT","type":"message"}
1619378338.480124: {"data":{"sequence":"1613277184878","bestAsk":"243","size":"0.14324938","bestBidSize":"0.45082023","price":"242.781","time":1619378338432,"bestAskSize":"4.51280965","bestBid":"242.635"},"subject":"trade.ticker","topic":"/market/ticker:BCHSV-USDT","type":"message"}
1619378338.51436: {"data":{"sequenceStart":1612844051987,"symbol":"SNX-BTC","changes":{"asks":[],"bids":[["0.00028281","0","1612844051987"]]},"sequenceEnd":1612844051987},"subject":"trade.l2update","topic":"/market/level2:SNX-BTC","type":"message"}
1619378338.519624: {"data":{"sequenceStart":1613277184879,"symbol":"BCHSV-USDT","changes":{"asks":[["0","0","1613277184879"]],"bids":[]},"sequenceEnd":1613277184879},"subject":"trade.l2update","topic":"/market/level2:BCHSV-USDT","type":"message"}
1619378338.5263019: {"data":{"sequenceStart":1613277184880,"symbol":"BCHSV-USDT","changes":{"asks":[["243.259","0.6","1613277184880"]],"bids":[]},"sequenceEnd":1613277184880},"subject":"trade.l2update","topic":"/market/level2:BCHSV-USDT","type":"message"}
1619378338.558961: {"data":{"sequence":"1612844051987","bestAsk":"0.00028711","size":"0.01745248","bestBidSize":"0.19100065","price":"0.00028676","time":1619378338523,"bestAskSize":"29.24570683","bestBid":"0.00028678"},"subject":"trade.ticker","topic":"/market/ticker:SNX-BTC","type":"message"}
1619378338.56805: {"data":{"sequence":"1613277184880","bestAsk":"243","size":"0.14324938","bestBidSize":"0.45082023","price":"242.781","time":1619378338530,"bestAskSize":"4.51280965","bestBid":"242.635"},"subject":"trade.ticker","topic":"/market/ticker:BCHSV-USDT","type":"message"}
1619378338.583704: {"data":{"sequenceStart":1613277184881,"symbol":"BCHSV-USDT","changes":{"asks":[],"bids":[["0","0","1613277184881"]]},"sequenceEnd":1613277184881},"subject":"trade.l2update","topic":"/market/level2:BCHSV-USDT","type":"message"}
1619378338.5838132: {"data":{"sequenceStart":1613277184882,"symbol":"BCHSV-USDT","changes":{"asks":[],"bids":[["241.653","102.92","1613277184882"]]},"sequenceEnd":1613277184882},"subject":"trade.l2update","topic":"/market/level2:BCHSV-USDT","type":"message"}
1619378338.616155: {"data":{"sequenceStart":1612702190344,"symbol":"NRG-BTC","changes":{"asks":[["0.0000623","0","1612702190344"]],"bids":[]},"sequenceEnd":1612702190344},"subject":"trade.l2update","topic":"/market/level2:NRG-BTC","type":"message"}
1619378338.6326022: {"data":{"sequenceStart":1612694580176,"symbol":"CAPP-BTC","changes":{"asks":[["0.0000002196","0","1612694580176"]],"bids":[]},"sequenceEnd":1612694580176},"subject":"trade.l2update","topic":"/market/level2:CAPP-BTC","type":"message"}
1619378338.637405: {"data":{"sequence":"1612702190344","bestAsk":"0.00006218","size":"0.0431","bestBidSize":"19.5017","price":"0.00006141","time":1619378338592,"bestAskSize":"43.3399","bestBid":"0.00006141"},"subject":"trade.ticker","topic":"/market/ticker:NRG-BTC","type":"message"}
1619378338.704871: {"data":{"sequenceStart":1612712745690,"symbol":"FET-BTC","changes":{"asks":[["0.00000781","0","1612712745690"]],"bids":[]},"sequenceEnd":1612712745690},"subject":"trade.l2update","topic":"/market/level2:FET-BTC","type":"message"}
1619378338.705009: {"data":{"sequence":"1613277184884","bestAsk":"243","size":"0.14324938","bestBidSize":"0.45082023","price":"242.781","time":1619378338632,"bestAskSize":"4.51280965","bestBid":"242.635"},"subject":"trade.ticker","topic":"/market/ticker:BCHSV-USDT","type":"message"}
1619378338.705058: {"data":{"sequenceStart":1613277184883,"symbol":"BCHSV-USDT","changes":{"asks":[["0","0","1613277184883"]],"bids":[]},"sequenceEnd":1613277184883},"subject":"trade.l2update","topic":"/market/level2:BCHSV-USDT","type":"message"}
1619378338.7051048: {"data":{"sequenceStart":1613277184884,"symbol":"BCHSV-USDT","changes":{"asks":[["243.094","6.17814101","1613277184884"]],"bids":[]},"sequenceEnd":1613277184884},"subject":"trade.l2update","topic":"/market/level2:BCHSV-USDT","type":"message"}
1619378338.705191: {"data":{"sequenceStart":1613277184885,"symbol":"BCHSV-USDT","changes":{"asks":[["245.774","0","1613277184885"]],"bids":[]},"sequenceEnd":1613277184885},"subject":"trade.l2update","topic":"/market/level2:BCHSV-USDT","type":"message"}
1619378338.710868: {"data":{"sequenceStart":1613277184886,"symbol":"BCHSV-USDT","changes":{"asks":[["243.259","0","1613277184886"]],"bids":[]},"sequenceEnd":1613277184886},"subject":"trade.l2update","topic":"/market/level2:BCHSV-USDT","type":"message"}
1619378338.719409: {"data":{"sequence":"1612712745690","bestAsk":"0.00000776","size":"401.2004","bestBidSize":"357.285","price":"0.00000772","time":1619378338667,"bestAskSize":"1154.0416","bestBid":"0.00000771"},"subject":"trade.ticker","topic":"/market/ticker:FET-BTC","type":"message"}
1619378338.7194722: {"data":{"sequenceStart":1613277184887,"symbol":"BCHSV-USDT","changes":{"asks":[["0","0","1613277184887"]],"bids":[]},"sequenceEnd":1613277184887},"subject":"trade.l2update","topic":"/market/level2:BCHSV-USDT","type":"message"}
1619378338.719509: {"data":{"sequenceStart":1613277184888,"symbol":"BCHSV-USDT","changes":{"asks":[["243.262","0.6","1613277184888"]],"bids":[]},"sequenceEnd":1613277184888},"subject":"trade.l2update","topic":"/market/level2:BCHSV-USDT","type":"message"}
1619378338.719549: {"data":{"sequence":"1612694580176","bestAsk":"0.0000002197","size":"1000.02","bestBidSize":"83.07","price":"0.0000002182","time":1619378338681,"bestAskSize":"735.9","bestBid":"0.0000002181"},"subject":"trade.ticker","topic":"/market/ticker:CAPP-BTC","type":"message"}
1619378338.768151: {"data":{"sequence":"1613277184888","bestAsk":"243","size":"0.14324938","bestBidSize":"0.45082023","price":"242.781","time":1619378338732,"bestAskSize":"4.51280965","bestBid":"242.635"},"subject":"trade.ticker","topic":"/market/ticker:BCHSV-USDT","type":"message"}
