wss://push-private.kucoin.com/endpoint?token=2neAiuYvAU61ZDXANAGAsiL4-iAExhsBXZxftpOeh_55i3Ysy2q2LEsEWU64mdzUOPusi34M_wGoSf7iNyEWJ9rmuQLyOxiA9ONrSePS8T67L0Ypy-pc0NiYB9J6i9GjsxUuhPw3BlrzazF6ghq4L403cNj4-QVAMsb1LQk8PR4=.4H2_-HDsATP9Nf4fVAdyYQ== <-> 1619378325.387221
wss://push-private.kucoin.com/endpoint?token=2neAiuYvAU61ZDXANAGAsiL4-iAExhsBXZxftpOeh_55i3Ysy2q2LEsEWU64mdzUOPusi34M_wGoSf7iNyEWJ9rmuQLyOxiA9ONrSePS8T67L0Ypy-pc0NiYB9J6i9GjsxUuhPw3BlrzazF6ghq4L403cNj4-QVAMsb1LQk8PR4=.4H2_-HDsATP9Nf4fVAdyYQ== <- 1619378326.125891: {"id":1,"type":"subscribe","topic":"/market/match:EQZ-BTC,ANKR-BTC,SNX-BTC,FET-BTC,BCHSV-USDT,NRG-BTC,CAPP-BTC,DAPPT-BTC,COV-BTC,LTX-USDT","privateChannel":false,"response":true}
wss://push-private.kucoin.com/endpoint?token=2neAiuYvAU61ZDXANAGAsiL4-iAExhsBXZxftpOeh_55i3Ysy2q2LEsEWU64mdzUOPusi34M_wGoSf7iNyEWJ9rmuQLyOxiA9ONrSePS8T67L0Ypy-pc0NiYB9J6i9GjsxUuhPw3BlrzazF6ghq4L403cNj4-QVAMsb1LQk8PR4=.4H2_-HDsATP9Nf4fVAdyYQ== <- 1619378326.126047: {"id":1,"type":"subscribe","topic":"/market/candles:EQZ-BTC_1min","privateChannel":false,"response":true}
wss://push-private.kucoin.com/endpoint?token=2neAiuYvAU61ZDXANAGAsiL4-iAExhsBXZxftpOeh_55i3Ysy2q2LEsEWU64mdzUOPusi34M_wGoSf7iNyEWJ9rmuQLyOxiA9ONrSePS8T67L0Ypy-pc0NiYB9J6i9GjsxUuhPw3BlrzazF6ghq4L403cNj4-QVAMsb1LQk8PR4=.4H2_-HDsATP9Nf4fVAdyYQ== <- 1619378326.126113: {"id":1,"type":"subscribe","topic":"/market/candles:ANKR-BTC_1min","privateChannel":false,"response":true}
wss://push-private.kucoin.com/endpoint?token=2neAiuYvAU61ZDXANAGAsiL4-iAExhsBXZxftpOeh_55i3Ysy2q2LEsEWU64mdzUOPusi34M_wGoSf7iNyEWJ9rmuQLyOxiA9ONrSePS8T67L0Ypy-pc0NiYB9J6i9GjsxUuhPw3BlrzazF6ghq4L403cNj4-QVAMsb1LQk8PR4=.4H2_-HDsATP9Nf4fVAdyYQ== <- 1619378326.126167: {"id":1,"type":"subscribe","topic":"/market/candles:SNX-BTC_1min","privateChannel":false,"response":true}
wss://push-private.kucoin.com/endpoint?token=2neAiuYvAU61ZDXANAGAsiL4-iAExhsBXZxftpOeh_55i3Ysy2q2LEsEWU64mdzUOPusi34M_wGoSf7iNyEWJ9rmuQLyOxiA9ONrSePS8T67L0Ypy-pc0NiYB9J6i9GjsxUuhPw3BlrzazF6ghq4L403cNj4-QVAMsb1LQk8PR4=.4H2_-HDsATP9Nf4fVAdyYQ== <- 1619378326.1262138: {"id":1,"type":"subscribe","topic":"/market/candles:FET-BTC_1min","privateChannel":false,"response":true}
wss://push-private.kucoin.com/endpoint?token=2neAiuYvAU61ZDXANAGAsiL4-iAExhsBXZxftpOeh_55i3Ysy2q2LEsEWU64mdzUOPusi34M_wGoSf7iNyEWJ9rmuQLyOxiA9ONrSePS8T67L0Ypy-pc0NiYB9J6i9GjsxUuhPw3BlrzazF6ghq4L403cNj4-QVAMsb1LQk8PR4=.4H2_-HDsATP9Nf4fVAdyYQ== <- 1619378326.126258: {"id":1,"type":"subscribe","topic":"/market/candles:BCHSV-USDT_1min","privateChannel":false,"response":true}
wss://push-private.kucoin.com/endpoint?token=2neAiuYvAU61ZDXANAGAsiL4-iAExhsBXZxftpOeh_55i3Ysy2q2LEsEWU64mdzUOPusi34M_wGoSf7iNyEWJ9rmuQLyOxiA9ONrSePS8T67L0Ypy-pc0NiYB9J6i9GjsxUuhPw3BlrzazF6ghq4L403cNj4-QVAMsb1LQk8PR4=.4H2_-HDsATP9Nf4fVAdyYQ== <- 1619378326.1262999: {"id":1,"type":"subscribe","topic":"/market/candles:NRG-BTC_1min","privateChannel":false,"response":true}
wss://push-private.kucoin.com/endpoint?token=2neAiuYvAU61ZDXANAGAsiL4-iAExhsBXZxftpOeh_55i3Ysy2q2LEsEWU64mdzUOPusi34M_wGoSf7iNyEWJ9rmuQLyOxiA9ONrSePS8T67L0Ypy-pc0NiYB9J6i9GjsxUuhPw3BlrzazF6ghq4L403cNj4-QVAMsb1LQk8PR4=.4H2_-HDsATP9Nf4fVAdyYQ== <- 1619378326.1263418: {"id":1,"type":"subscribe","topic":"/market/candles:CAPP-BTC_1min","privateChannel":false,"response":true}
wss://push-private.kucoin.com/endpoint?token=2neAiuYvAU61ZDXANAGAsiL4-iAExhsBXZxftpOeh_55i3Ysy2q2LEsEWU64mdzUOPusi34M_wGoSf7iNyEWJ9rmuQLyOxiA9ONrSePS8T67L0Ypy-pc0NiYB9J6i9GjsxUuhPw3BlrzazF6ghq4L403cNj4-QVAMsb1LQk8PR4=.4H2_-HDsATP9Nf4fVAdyYQ== <- 1619378326.126384: {"id":1,"type":"subscribe","topic":"/market/candles:DAPPT-BTC_1min","privateChannel":false,"response":true}
wss://push-private.kucoin.com/endpoint?token=2neAiuYvAU61ZDXANAGAsiL4-iAExhsBXZxftpOeh_55i3Ysy2q2LEsEWU64mdzUOPusi34M_wGoSf7iNyEWJ9rmuQLyOxiA9ONrSePS8T67L0Ypy-pc0NiYB9J6i9GjsxUuhPw3BlrzazF6ghq4L403cNj4-QVAMsb1LQk8PR4=.4H2_-HDsATP9Nf4fVAdyYQ== <- 1619378326.1264262: {"id":1,"type":"subscribe","topic":"/market/candles:COV-BTC_1min","privateChannel":false,"response":true}
wss://push-private.kucoin.com/endpoint?token=2neAiuYvAU61ZDXANAGAsiL4-iAExhsBXZxftpOeh_55i3Ysy2q2LEsEWU64mdzUOPusi34M_wGoSf7iNyEWJ9rmuQLyOxiA9ONrSePS8T67L0Ypy-pc0NiYB9J6i9GjsxUuhPw3BlrzazF6ghq4L403cNj4-QVAMsb1LQk8PR4=.4H2_-HDsATP9Nf4fVAdyYQ== <- 1619378326.126467: {"id":1,"type":"subscribe","topic":"/market/candles:LTX-USDT_1min","privateChannel":false,"response":true}
wss://push-private.kucoin.com/endpoint?token=2neAiuYvAU61ZDXANAGAsiL4-iAExhsBXZxftpOeh_55i3Ysy2q2LEsEWU64mdzUOPusi34M_wGoSf7iNyEWJ9rmuQLyOxiA9ONrSePS8T67L0Ypy-pc0NiYB9J6i9GjsxUuhPw3BlrzazF6ghq4L403cNj4-QVAMsb1LQk8PR4=.4H2_-HDsATP9Nf4fVAdyYQ== <- 1619378326.126514: {"id":1,"type":"subscribe","topic":"/market/ticker:EQZ-BTC,ANKR-BTC,SNX-BTC,FET-BTC,BCHSV-USDT,NRG-BTC,CAPP-BTC,DAPPT-BTC,COV-BTC,LTX-USDT","privateChannel":false,"response":true}
wss://push-private.kucoin.com/endpoint?token=2neAiuYvAU61ZDXANAGAsiL4-iAExhsBXZxftpOeh_55i3Ysy2q2LEsEWU64mdzUOPusi34M_wGoSf7iNyEWJ9rmuQLyOxiA9ONrSePS8T67L0Ypy-pc0NiYB9J6i9GjsxUuhPw3BlrzazF6ghq4L403cNj4-QVAMsb1LQk8PR4=.4H2_-HDsATP9Nf4fVAdyYQ== <- 1619378326.1265652: {"id":1,"type":"subscribe","topic":"/market/level2:EQZ-BTC,ANKR-BTC,SNX-BTC,FET-BTC,BCHSV-USDT,NRG-BTC,CAPP-BTC,DAPPT-BTC,COV-BTC,LTX-USDT","privateChannel":false,"response":true}
1619378326.134871: {"id":"NSkIrWGB1s","type":"welcome"}
1619378326.32176: {"id":"1","type":"ack"}
1619378326.321804: {"id":"1","type":"ack"}
1619378326.32182: {"id":"1","type":"ack"}
1619378326.326813: {"id":"1","type":"ack"}
1619378326.326855: {"id":"1","type":"ack"}
1619378326.3313339: {"id":"1","type":"ack"}
1619378326.3313549: {"id":"1","type":"ack"}
1619378326.3313642: {"id":"1","type":"ack"}
1619378326.336965: {"id":"1","type":"ack"}
1619378326.337007: {"id":"1","type":"ack"}
1619378326.337023: {"id":"1","type":"ack"}
1619378326.354197: {"id":"1","type":"ack"}
1619378326.364592: {"data":{"sequence":"1612844051653","bestAsk":"0.00028717","size":"0.01745248","bestBidSize":"3.70422021","price":"0.00028676","time":1619378326323,"bestAskSize":"14.04274325","bestBid":"0.00028678"},"subject":"trade.ticker","topic":"/market/ticker:SNX-BTC","type":"message"}
1619378326.364695: {"id":"1","type":"ack"}
1619378326.3684192: {"data":{"sequence":"1613277183873","bestAsk":"242.951","size":"0.08000012","bestBidSize":"0.68148185","price":"243.65","time":1619378326330,"bestAskSize":"4.51280965","bestBid":"242.654"},"subject":"trade.ticker","topic":"/market/ticker:BCHSV-USDT","type":"message"}
1619378326.3942132: {"data":{"sequenceStart":1613277183874,"symbol":"BCHSV-USDT","changes":{"asks":[["0","0","1613277183874"]],"bids":[]},"sequenceEnd":1613277183874},"subject":"trade.l2update","topic":"/market/level2:BCHSV-USDT","type":"message"}
1619378326.664499: {"data":{"sequenceStart":1613277183875,"symbol":"BCHSV-USDT","changes":{"asks":[["244.351","150","1613277183875"]],"bids":[]},"sequenceEnd":1613277183875},"subject":"trade.l2update","topic":"/market/level2:BCHSV-USDT","type":"message"}
1619378326.664525: {"data":{"sequenceStart":1613277183876,"symbol":"BCHSV-USDT","changes":{"asks":[["0","0","1613277183876"]],"bids":[]},"sequenceEnd":1613277183876},"subject":"trade.l2update","topic":"/market/level2:BCHSV-USDT","type":"message"}
1619378326.6645389: {"data":{"sequenceStart":1613277183877,"symbol":"BCHSV-USDT","changes":{"asks":[["243.714","5","1613277183877"]],"bids":[]},"sequenceEnd":1613277183877},"subject":"trade.l2update","topic":"/market/level2:BCHSV-USDT","type":"message"}
1619378326.664549: {"data":{"sequenceStart":1613277183878,"symbol":"BCHSV-USDT","changes":{"asks":[],"bids":[["0","0","1613277183878"]]},"sequenceEnd":1613277183878},"subject":"trade.l2update","topic":"/market/level2:BCHSV-USDT","type":"message"}
1619378326.6645582: {"data":{"sequenceStart":1613277183879,"symbol":"BCHSV-USDT","changes":{"asks":[],"bids":[["241.553","5","1613277183879"]]},"sequenceEnd":1613277183879},"subject":"trade.l2update","topic":"/market/level2:BCHSV-USDT","type":"message"}
1619378326.664567: {"data":{"sequenceStart":1613277183880,"symbol":"BCHSV-USDT","changes":{"asks":[["243.289","0","1613277183880"]],"bids":[]},"sequenceEnd":1613277183880},"subject":"trade.l2update","topic":"/market/level2:BCHSV-USDT","type":"message"}
1619378326.664577: {"data":{"sequenceStart":1613277183881,"symbol":"BCHSV-USDT","changes":{"asks":[],"bids":[["242.654","0","1613277183881"]]},"sequenceEnd":1613277183881},"subject":"trade.l2update","topic":"/market/level2:BCHSV-USDT","type":"message"}
1619378326.6645849: {"data":{"sequenceStart":1613277183882,"symbol":"BCHSV-USDT","changes":{"asks":[],"bids":[["0","0","1613277183882"]]},"sequenceEnd":1613277183882},"subject":"trade.l2update","topic":"/market/level2:BCHSV-USDT","type":"message"}
1619378326.664594: {"data":{"sequenceStart":1613277183883,"symbol":"BCHSV-USDT","changes":{"asks":[],"bids":[["242.545","0.4008184","1613277183883"]]},"sequenceEnd":1613277183883},"subject":"trade.l2update","topic":"/market/level2:BCHSV-USDT","type":"message"}
1619378326.664603: {"data":{"sequenceStart":1613277183884,"symbol":"BCHSV-USDT","changes":{"asks":[["0","0","1613277183884"]],"bids":[]},"sequenceEnd":1613277183884},"subject":"trade.l2update","topic":"/market/level2:BCHSV-USDT","type":"message"}
1619378326.664612: {"data":{"sequenceStart":1613277183885,"symbol":"BCHSV-USDT","changes":{"asks":[["243.287","0.6","1613277183885"]],"bids":[]},"sequenceEnd":1613277183885},"subject":"trade.l2update","topic":"/market/level2:BCHSV-USDT","type":"message"}
1619378326.664621: {"data":{"sequenceStart":1613277183886,"symbol":"BCHSV-USDT","changes":{"asks":[],"bids":[["0","0","1613277183886"]]},"sequenceEnd":1613277183886},"subject":"trade.l2update","topic":"/market/level2:BCHSV-USDT","type":"message"}
1619378326.66463: {"data":{"sequenceStart":1613277183887,"symbol":"BCHSV-USDT","changes":{"asks":[],"bids":[["242.646","0.68148185","1613277183887"]]},"sequenceEnd":1613277183887},"subject":"trade.l2update","topic":"/market/level2:BCHSV-USDT","type":"message"}
1619378326.664639: {"data":{"sequenceStart":1612844051654,"symbol":"SNX-BTC","changes":{"asks":[["0.00028718","0","1612844051654"]],"bids":[]},"sequenceEnd":1612844051654},"subject":"trade.l2update","topic":"/market/level2:SNX-BTC","type":"message"}
1619378326.883311: {"data":{"sequence":"1612734157720","bestAsk":"0.0000026192","size":"46","bestBidSize":"4051.2663","price":"0.0000026071","time":1619378326388,"bestAskSize":"4664.7644","bestBid":"0.0000026033"},"subject":"trade.ticker","topic":"/market/ticker:ANKR-BTC","type":"message"}
1619378326.883338: {"data":{"sequenceStart":1613277183888,"symbol":"BCHSV-USDT","changes":{"asks":[],"bids":[["0","0","1613277183888"]]},"sequenceEnd":1613277183888},"subject":"trade.l2update","topic":"/market/level2:BCHSV-USDT","type":"message"}
1619378326.8833501: {"data":{"sequenceStart":1613277183889,"symbol":"BCHSV-USDT","changes":{"asks":[],"bids":[["242.649","5","1613277183889"]]},"sequenceEnd":1613277183889},"subject":"trade.l2update","topic":"/market/level2:BCHSV-USDT","type":"message"}
1619378326.883358: {"data":{"sequence":"1612844051654","bestAsk":"0.00028717","size":"0.01745248","bestBidSize":"3.70422021","price":"0.00028676","time":1619378326423,"bestAskSize":"14.04274325","bestBid":"0.00028678"},"subject":"trade.ticker","topic":"/market/ticker:SNX-BTC","type":"message"}
1619378326.883369: {"data":{"sequence":"1613277183889","bestAsk":"242.951","size":"0.08000012","bestBidSize":"5","price":"243.65","time":1619378326430,"bestAskSize":"4.51280965","bestBid":"242.649"},"subject":"trade.ticker","topic":"/market/ticker:BCHSV-USDT","type":"message"}
1619378326.883379: {"data":{"sequenceStart":1612844051655,"symbol":"SNX-BTC","changes":{"asks":[["0","0","1612844051655"]],"bids":[]},"sequenceEnd":1612844051655},"subject":"trade.l2update","topic":"/market/level2:SNX-BTC","type":"message"}
1619378326.8833869: {"data":{"sequenceStart":1612844051656,"symbol":"SNX-BTC","changes":{"asks":[["0.00028734","14.05828264","1612844051656"]],"bids":[]},"sequenceEnd":1612844051656},"subject":"trade.l2update","topic":"/market/level2:SNX-BTC","type":"message"}
1619378326.883394: {"data":{"sequenceStart":1612844051657,"symbol":"SNX-BTC","changes":{"asks":[["0.00028734","0","1612844051657"]],"bids":[]},"sequenceEnd":1612844051657},"subject":"trade.l2update","topic":"/market/level2:SNX-BTC","type":"message"}
1619378326.883413: {"data":{"sequenceStart":1613277183890,"symbol":"BCHSV-USDT","changes":{"asks":[["0","0","1613277183890"]],"bids":[]},"sequenceEnd":1613277183890},"subject":"trade.l2update","topic":"/market/level2:BCHSV-USDT","type":"message"}
1619378326.88342: {"data":{"sequenceStart":1613277183891,"symbol":"BCHSV-USDT","changes":{"asks":[["245.635","17.79999999","1613277183891"]],"bids":[]},"sequenceEnd":1613277183891},"subject":"trade.l2update","topic":"/market/level2:BCHSV-USDT","type":"message"}
1619378326.883426: {"data":{"sequenceStart":1613277183892,"symbol":"BCHSV-USDT","changes":{"asks":[],"bids":[["240.256","0","1613277183892"]]},"sequenceEnd":1613277183892},"subject":"trade.l2update","topic":"/market/level2:BCHSV-USDT","type":"message"}
1619378326.88344: {"data":{"sequence":"1613277183892","bestAsk":"242.951","size":"0.08000012","bestBidSize":"5","price":"243.65","time":1619378326533,"bestAskSize":"4.51280965","bestBid":"242.649"},"subject":"trade.ticker","topic":"/market/ticker:BCHSV-USDT","type":"message"}
1619378326.88345: {"data":{"sequence":"1612844051657","bestAsk":"0.00028717","size":"0.01745248","bestBidSize":"3.70422021","price":"0.00028676","time":1619378326545,"bestAskSize":"14.04274325","bestBid":"0.00028678"},"subject":"trade.ticker","topic":"/market/ticker:SNX-BTC","type":"message"}
1619378326.883459: {"data":{"sequenceStart":1613277183893,"symbol":"BCHSV-USDT","changes":{"asks":[["243.287","0","1613277183893"]],"bids":[]},"sequenceEnd":1613277183893},"subject":"trade.l2update","topic":"/market/level2:BCHSV-USDT","type":"message"}
1619378326.8834822: {"data":{"sequenceStart":1613277183894,"symbol":"BCHSV-USDT","changes":{"asks":[],"bids":[["242.646","0","1613277183894"]]},"sequenceEnd":1613277183894},"subject":"trade.l2update","topic":"/market/level2:BCHSV-USDT","type":"message"}
1619378326.883501: {"data":{"sequenceStart":1612694580140,"symbol":"CAPP-BTC","changes":{"asks":[],"bids":[["0.0000002102","245.42","1612694580140"]]},"sequenceEnd":1612694580140},"subject":"trade.l2update","topic":"/market/level2:CAPP-BTC","type":"message"}
1619378327.0942662: {"data":{"sequenceStart":1613277183895,"symbol":"BCHSV-USDT","changes":{"asks":[],"bids":[["0","0","1613277183895"]]},"sequenceEnd":1613277183895},"subject":"trade.l2update","topic":"/market/level2:BCHSV-USDT","type":"message"}
1619378327.094304: {"data":{"sequenceStart":1613277183896,"symbol":"BCHSV-USDT","changes":{"asks":[],"bids":[["242.647","0.68148185","1613277183896"]]},"sequenceEnd":1613277183896},"subject":"trade.l2update","topic":"/market/level2:BCHSV-USDT","type":"message"}
1619378327.094336: {"data":{"sequenceStart":1613277183897,"symbol":"BCHSV-USDT","changes":{"asks":[["0","0","1613277183897"]],"bids":[]},"sequenceEnd":1613277183897},"subject":"trade.l2update","topic":"/market/level2:BCHSV-USDT","type":"message"}
1619378327.0943549: {"data":{"sequenceStart":1613277183898,"symbol":"BCHSV-USDT","changes":{"asks":[["243.285","0.6","1613277183898"]],"bids":[]},"sequenceEnd":1613277183898},"subject":"trade.l2update","topic":"/market/level2:BCHSV-USDT","type":"message"}
1619378327.0943801: {"data":{"sequence":"1612694580140","bestAsk":"0.0000002197","size":"1000.02","bestBidSize":"83.07","price":"0.0000002182","time":1619378326581,"bestAskSize":"735.9","bestBid":"0.0000002181"},"subject":"trade.ticker","topic":"/market/ticker:CAPP-BTC","type":"message"}
1619378327.094399: {"data":{"sequenceStart":1613277183899,"symbol":"BCHSV-USDT","changes":{"asks":[],"bids":[["0","0","1613277183899"]]},"sequenceEnd":1613277183899},"subject":"trade.l2update","topic":"/market/level2:BCHSV-USDT","type":"message"}
1619378327.0944169: {"data":{"sequenceStart":1613277183900,"symbol":"BCHSV-USDT","changes":{"asks":[],"bids":[["242.069","4.29542956","1613277183900"]]},"sequenceEnd":1613277183900},"subject":"trade.l2update","topic":"/market/level2:BCHSV-USDT","type":"message"}
1619378327.094439: {"data":{"sequenceStart":1613277183901,"symbol":"BCHSV-USDT","changes":{"asks":[],"bids":[["0","0","1613277183901"]]},"sequenceEnd":1613277183901},"subject":"trade.l2update","topic":"/market/level2:BCHSV-USDT","type":"message"}
1619378327.094456: {"data":{"sequenceStart":1613277183902,"symbol":"BCHSV-USDT","changes":{"asks":[],"bids":[["241.824","8.59085912","1613277183902"]]},"sequenceEnd":1613277183902},"subject":"trade.l2update","topic":"/market/level2:BCHSV-USDT","type":"message"}
1619378327.094476: {"data":{"sequenceStart":1613277183903,"symbol":"BCHSV-USDT","changes":{"asks":[],"bids":[["242.649","0","1613277183903"]]},"sequenceEnd":1613277183903},"subject":"trade.l2update","topic":"/market/level2:BCHSV-USDT","type":"message"}
1619378327.094502: {"data":{"sequenceStart":1613277183904,"symbol":"BCHSV-USDT","changes":{"asks":[],"bids":[["0","0","1613277183904"]]},"sequenceEnd":1613277183904},"subject":"trade.l2update","topic":"/market/level2:BCHSV-USDT","type":"message"}
1619378327.0945191: {"data":{"sequenceStart":1613277183905,"symbol":"BCHSV-USDT","changes":{"asks":[],"bids":[["242.65","5","1613277183905"]]},"sequenceEnd":1613277183905},"subject":"trade.l2update","topic":"/market/level2:BCHSV-USDT","type":"message"}
1619378327.094539: {"data":{"sequence":"1613277183905","bestAsk":"242.951","size":"0.08000012","bestBidSize":"5","price":"243.65","time":1619378326630,"bestAskSize":"4.51280965","bestBid":"242.65"},"subject":"trade.ticker","topic":"/market/ticker:BCHSV-USDT","type":"message"}
1619378327.094555: {"data":{"sequenceStart":1613277183906,"symbol":"BCHSV-USDT","changes":{"asks":[["247.395","0","1613277183906"]],"bids":[]},"sequenceEnd":1613277183906},"subject":"trade.l2update","topic":"/market/level2:BCHSV-USDT","type":"message"}
1619378327.094579: {"data":{"sequenceStart":1613277183907,"symbol":"BCHSV-USDT","changes":{"asks":[],"bids":[["242.65","0","1613277183907"]]},"sequenceEnd":1613277183907},"subject":"trade.l2update","topic":"/market/level2:BCHSV-USDT","type":"message"}
1619378327.094601: {"data":{"sequenceStart":1613277183908,"symbol":"BCHSV-USDT","changes":{"asks":[["0","0","1613277183908"]],"bids":[]},"sequenceEnd":1613277183908},"subject":"trade.l2update","topic":"/market/level2:BCHSV-USDT","type":"message"}
1619378327.0946188: {"data":{"sequenceStart":1613277183909,"symbol":"BCHSV-USDT","changes":{"asks":[["246.421","37.241","1613277183909"]],"bids":[]},"sequenceEnd":1613277183909},"subject":"trade.l2update","topic":"/market/level2:BCHSV-USDT","type":"message"}
1619378327.094641: {"data":{"sequence":"1613277183909","bestAsk":"242.951","size":"0.08000012","bestBidSize":"0.68148185","price":"243.65","time":1619378326732,"bestAskSize":"4.51280965","bestBid":"242.647"},"subject":"trade.ticker","topic":"/market/ticker:BCHSV-USDT","type":"message"}
1619378327.094656: {"data":{"sequenceStart":1613277183910,"symbol":"BCHSV-USDT","changes":{"asks":[["244.351","0","1613277183910"]],"bids":[]},"sequenceEnd":1613277183910},"subject":"trade.l2update","topic":"/market/level2:BCHSV-USDT","type":"message"}
1619378327.094679: {"data":{"sequenceStart":1613277183911,"symbol":"BCHSV-USDT","changes":{"asks":[["243.714","0","1613277183911"]],"bids":[]},"sequenceEnd":1613277183911},"subject":"trade.l2update","topic":"/market/level2:BCHSV-USDT","type":"message"}
1619378327.094701: {"data":{"sequenceStart":1613277183912,"symbol":"BCHSV-USDT","changes":{"asks":[],"bids":[["241.553","0","1613277183912"]]},"sequenceEnd":1613277183912},"subject":"trade.l2update","topic":"/market/level2:BCHSV-USDT","type":"message"}
1619378327.0947242: {"data":{"sequenceStart":1612734157721,"symbol":"ANKR-BTC","changes":{"asks":[["0","0","1612734157721"]],"bids":[]},"sequenceEnd":1612734157721},"subject":"trade.l2update","topic":"/market/level2:ANKR-BTC","type":"message"}
1619378327.296959: {"data":{"sequenceStart":1612734157722,"symbol":"ANKR-BTC","changes":{"asks":[["0.0000026255","20000","1612734157722"]],"bids":[]},"sequenceEnd":1612734157722},"subject":"trade.l2update","topic":"/market/level2:ANKR-BTC","type":"message"}
1619378327.297001: {"data":{"sequenceStart":1613277183913,"symbol":"BCHSV-USDT","changes":{"asks":[],"bids":[["0","0","1613277183913"]]},"sequenceEnd":1613277183913},"subject":"trade.l2update","topic":"/market/level2:BCHSV-USDT","type":"message"}
1619378327.2970219: {"data":{"sequenceStart":1613277183914,"symbol":"BCHSV-USDT","changes":{"asks":[],"bids":[["242.652","5","1613277183914"]]},"sequenceEnd":1613277183914},"subject":"trade.l2update","topic":"/market/level2:BCHSV-USDT","type":"message"}
1619378327.297046: {"data":{"sequenceStart":1613277183915,"symbol":"BCHSV-USDT","changes":{"asks":[["245.635","0","1613277183915"]],"bids":[]},"sequenceEnd":1613277183915},"subject":"trade.l2update","topic":"/market/level2:BCHSV-USDT","type":"message"}
1619378327.2970738: {"data":{"sequence":"1613277183914","bestAsk":"242.951","size":"0.08000012","bestBidSize":"5","price":"243.65","time":1619378326831,"bestAskSize":"4.51280965","bestBid":"242.652"},"subject":"trade.ticker","topic":"/market/ticker:BCHSV-USDT","type":"message"}
1619378327.297091: {"data":{"sequenceStart":1613277183916,"symbol":"BCHSV-USDT","changes":{"asks":[["243.285","0","1613277183916"]],"bids":[]},"sequenceEnd":1613277183916},"subject":"trade.l2update","topic":"/market/level2:BCHSV-USDT","type":"message"}
1619378327.297112: {"data":{"sequenceStart":1613277183917,"symbol":"BCHSV-USDT","changes":{"asks":[],"bids":[["242.647","0","1613277183917"]]},"sequenceEnd":1613277183917},"subject":"trade.l2update","topic":"/market/level2:BCHSV-USDT","type":"message"}
1619378327.297133: {"data":{"sequenceStart":1613277183918,"symbol":"BCHSV-USDT","changes":{"asks":[],"bids":[["0","0","1613277183918"]]},"sequenceEnd":1613277183918},"subject":"trade.l2update","topic":"/market/level2:BCHSV-USDT","type":"message"}
1619378327.297148: {"data":{"sequenceStart":1613277183919,"symbol":"BCHSV-USDT","changes":{"asks":[],"bids":[["242.649","0.68148185","1613277183919"]]},"sequenceEnd":1613277183919},"subject":"trade.l2update","topic":"/market/level2:BCHSV-USDT","type":"message"}
1619378327.297167: {"data":{"sequenceStart":1613277183920,"symbol":"BCHSV-USDT","changes":{"asks":[["0","0","1613277183920"]],"bids":[]},"sequenceEnd":1613277183920},"subject":"trade.l2update","topic":"/market/level2:BCHSV-USDT","type":"message"}
1619378327.297184: {"data":{"sequenceStart":1613277183921,"symbol":"BCHSV-USDT","changes":{"asks":[["243.284","0.6","1613277183921"]],"bids":[]},"sequenceEnd":1613277183921},"subject":"trade.l2update","topic":"/market/level2:BCHSV-USDT","type":"message"}
1619378327.2972028: {"data":{"sequence":"1612734157722","bestAsk":"0.0000026192","size":"46","bestBidSize":"4051.2663","price":"0.0000026071","time":1619378326888,"bestAskSize":"4664.7644","bestBid":"0.0000026033"},"subject":"trade.ticker","topic":"/market/ticker:ANKR-BTC","type":"message"}
1619378327.29722: {"data":{"sequenceStart":1613277183922,"symbol":"BCHSV-USDT","changes":{"asks":[],"bids":[["242.652","0","1613277183922"]]},"sequenceEnd":1613277183922},"subject":"trade.l2update","topic":"/market/level2:BCHSV-USDT","type":"message"}
1619378327.297247: {"data":{"sequenceStart":1613277183923,"symbol":"BCHSV-USDT","changes":{"asks":[],"bids":[["242.069","0","1613277183923"]]},"sequenceEnd":1613277183923},"subject":"trade.l2update","topic":"/market/level2:BCHSV-USDT","type":"message"}
1619378327.297267: {"data":{"sequenceStart":1613277183924,"symbol":"BCHSV-USDT","changes":{"asks":[],"bids":[["241.824","0","1613277183924"]]},"sequenceEnd":1613277183924},"subject":"trade.l2update","topic":"/market/level2:BCHSV-USDT","type":"message"}
1619378327.2972858: {"data":{"sequenceStart":1612712745581,"symbol":"FET-BTC","changes":{"asks":[["0.00000785","0","1612712745581"]],"bids":[]},"sequenceEnd":1612712745581},"subject":"trade.l2update","topic":"/market/level2:FET-BTC","type":"message"}
1619378327.509471: {"data":{"sequenceStart":1613277183925,"symbol":"BCHSV-USDT","changes":{"asks":[],"bids":[["0","0","1613277183925"]]},"sequenceEnd":1613277183925},"subject":"trade.l2update","topic":"/market/level2:BCHSV-USDT","type":"message"}
1619378327.5095181: {"data":{"sequenceStart":1613277183926,"symbol":"BCHSV-USDT","changes":{"asks":[],"bids":[["242.655","5","1613277183926"]]},"sequenceEnd":1613277183926},"subject":"trade.l2update","topic":"/market/level2:BCHSV-USDT","type":"message"}
1619378327.509553: {"data":{"sequence":"1613277183926","bestAsk":"242.951","size":"0.08000012","bestBidSize":"5","price":"243.65","time":1619378326930,"bestAskSize":"4.51280965","bestBid":"242.655"},"subject":"trade.ticker","topic":"/market/ticker:BCHSV-USDT","type":"message"}
1619378327.509574: {"data":{"sequenceStart":1612712745582,"symbol":"FET-BTC","changes":{"asks":[["0.00000789","0","1612712745582"]],"bids":[]},"sequenceEnd":1612712745582},"subject":"trade.l2update","topic":"/market/level2:FET-BTC","type":"message"}
1619378327.5095959: {"data":{"sequence":"1612712745582","bestAsk":"0.00000775","size":"401.2004","bestBidSize":"357.285","price":"0.00000772","time":1619378326968,"bestAskSize":"8025.7777","bestBid":"0.00000771"},"subject":"trade.ticker","topic":"/market/ticker:FET-BTC","type":"message"}
1619378327.509613: {"data":{"sequenceStart":1613277183927,"symbol":"BCHSV-USDT","changes":{"asks":[],"bids":[["242.655","0","1613277183927"]]},"sequenceEnd":1613277183927},"subject":"trade.l2update","topic":"/market/level2:BCHSV-USDT","type":"message"}
1619378327.509643: {"data":{"sequence":"1613277183927","bestAsk":"242.951","size":"0.08000012","bestBidSize":"0.68148185","price":"243.65","time":1619378327030,"bestAskSize":"4.51280965","bestBid":"242.649"},"subject":"trade.ticker","topic":"/market/ticker:BCHSV-USDT","type":"message"}
1619378327.5096588: {"data":{"sequenceStart":1613277183928,"symbol":"BCHSV-USDT","changes":{"asks":[],"bids":[["242.649","0","1613277183928"]]},"sequenceEnd":1613277183928},"subject":"trade.l2update","topic":"/market/level2:BCHSV-USDT","type":"message"}
1619378327.509683: {"data":{"sequenceStart":1613277183929,"symbol":"BCHSV-USDT","changes":{"asks":[],"bids":[["0","0","1613277183929"]]},"sequenceEnd":1613277183929},"subject":"trade.l2update","topic":"/market/level2:BCHSV-USDT","type":"message"}
1619378327.509702: {"data":{"sequenceStart":1613277183930,"symbol":"BCHSV-USDT","changes":{"asks":[],"bids":[["242.646","0.68148185","1613277183930"]]},"sequenceEnd":1613277183930},"subject":"trade.l2update","topic":"/market/level2:BCHSV-USDT","type":"message"}
1619378327.509726: {"data":{"sequenceStart":1613277183931,"symbol":"BCHSV-USDT","changes":{"asks":[],"bids":[["0","0","1613277183931"]]},"sequenceEnd":1613277183931},"subject":"trade.l2update","topic":"/market/level2:BCHSV-USDT","type":"message"}
1619378327.5097432: {"data":{"sequenceStart":1613277183932,"symbol":"BCHSV-USDT","changes":{"asks":[],"bids":[["242.57","5","1613277183932"]]},"sequenceEnd":1613277183932},"subject":"trade.l2update","topic":"/market/level2:BCHSV-USDT","type":"message"}
1619378327.5097651: {"data":{"sequence":"1613277183932","bestAsk":"242.951","size":"0.08000012","bestBidSize":"0.68148185","price":"243.65","time":1619378327130,"bestAskSize":"4.51280965","bestBid":"242.646"},"subject":"trade.ticker","topic":"/market/ticker:BCHSV-USDT","type":"message"}
1619378327.50978: {"data":{"sequenceStart":1612844051658,"symbol":"SNX-BTC","changes":{"asks":[["0","0","1612844051658"]],"bids":[]},"sequenceEnd":1612844051658},"subject":"trade.l2update","topic":"/market/level2:SNX-BTC","type":"message"}
1619378327.509799: {"data":{"sequenceStart":1612844051659,"symbol":"SNX-BTC","changes":{"asks":[["0.00028717","43.28845008","1612844051659"]],"bids":[]},"sequenceEnd":1612844051659},"subject":"trade.l2update","topic":"/market/level2:SNX-BTC","type":"message"}
1619378327.5098188: {"data":{"sequenceStart":1612844051660,"symbol":"SNX-BTC","changes":{"asks":[],"bids":[["0.00028678","0.19100065","1612844051660"]]},"sequenceEnd":1612844051660},"subject":"trade.l2update","topic":"/market/level2:SNX-BTC","type":"message"}
1619378327.509839: {"data":{"sequenceStart":1613277183933,"symbol":"BCHSV-USDT","changes":{"asks":[],"bids":[["242.545","0","1613277183933"]]},"sequenceEnd":1613277183933},"subject":"trade.l2update","topic":"/market/level2:BCHSV-USDT","type":"message"}
1619378327.509862: {"data":{"sequenceStart":1612844051661,"symbol":"SNX-BTC","changes":{"asks":[["0.00028717","29.24570683","1612844051661"]],"bids":[]},"sequenceEnd":1612844051661},"subject":"trade.l2update","topic":"/market/level2:SNX-BTC","type":"message"}
1619378327.5098822: {"data":{"sequenceStart":1613277183934,"symbol":"BCHSV-USDT","changes":{"asks":[],"bids":[["242.57","0","1613277183934"]]},"sequenceEnd":1613277183934},"subject":"trade.l2update","topic":"/market/level2:BCHSV-USDT","type":"message"}
1619378327.5099049: {"data":{"sequenceStart":1612844051662,"symbol":"SNX-BTC","changes":{"asks":[],"bids":[["0","0","1612844051662"]]},"sequenceEnd":1612844051662},"subject":"trade.l2update","topic":"/market/level2:SNX-BTC","type":"message"}
1619378327.509923: {"data":{"sequenceStart":1612844051663,"symbol":"SNX-BTC","changes":{"asks":[],"bids":[["0.00028653","2.10972904","1612844051663"]]},"sequenceEnd":1612844051663},"subject":"trade.l2update","topic":"/market/level2:SNX-BTC","type":"message"}
1619378327.5099468: {"data":{"sequenceStart":1612734157723,"symbol":"ANKR-BTC","changes":{"asks":[["0.0000026193","0","1612734157723"]],"bids":[]},"sequenceEnd":1612734157723},"subject":"trade.l2update","topic":"/market/level2:ANKR-BTC","type":"message"}
1619378327.509973: {"data":{"sequenceStart":1613277183935,"symbol":"BCHSV-USDT","changes":{"asks":[],"bids":[["0","0","1613277183935"]]},"sequenceEnd":1613277183935},"subject":"trade.l2update","topic":"/market/level2:BCHSV-USDT","type":"message"}
1619378327.509991: {"data":{"sequenceStart":1613277183936,"symbol":"BCHSV-USDT","changes":{"asks":[],"bids":[["242.65","5","1613277183936"]]},"sequenceEnd":1613277183936},"subject":"trade.l2update","topic":"/market/level2:BCHSV-USDT","type":"message"}
1619378327.510012: {"data":{"sequence":"1612844051663","bestAsk":"0.00028717","size":"0.01745248","bestBidSize":"0.19100065","price":"0.00028676","time":1619378327223,"bestAskSize":"29.24570683","bestBid":"0.00028678"},"subject":"trade.ticker","topic":"/market/ticker:SNX-BTC","type":"message"}
1619378327.510027: {"data":{"sequence":"1613277183936","bestAsk":"242.951","size":"0.08000012","bestBidSize":"5","price":"243.65","time":1619378327231,"bestAskSize":"4.51280965","bestBid":"242.65"},"subject":"trade.ticker","topic":"/market/ticker:BCHSV-USDT","type":"message"}
1619378327.510041: {"data":{"sequenceStart":1612844051664,"symbol":"SNX-BTC","changes":{"asks":[],"bids":[["0","0","1612844051664"]]},"sequenceEnd":1612844051664},"subject":"trade.l2update","topic":"/market/level2:SNX-BTC","type":"message"}
1619378327.510058: {"data":{"sequenceStart":1612844051665,"symbol":"SNX-BTC","changes":{"asks":[],"bids":[["0.00028623","35.1714161","1612844051665"]]},"sequenceEnd":1612844051665},"subject":"trade.l2update","topic":"/market/level2:SNX-BTC","type":"message"}
1619378327.51008: {"data":{"sequenceStart":1612701563860,"symbol":"DAPPT-BTC","changes":{"asks":[],"bids":[["0.0000001115","0","1612701563860"]]},"sequenceEnd":1612701563860},"subject":"trade.l2update","topic":"/market/level2:DAPPT-BTC","type":"message"}
1619378327.727243: {"data":{"sequenceStart":1612844051666,"symbol":"SNX-BTC","changes":{"asks":[],"bids":[["0.00028653","0","1612844051666"]]},"sequenceEnd":1612844051666},"subject":"trade.l2update","topic":"/market/level2:SNX-BTC","type":"message"}
1619378327.727307: {"data":{"sequenceStart":1613277183937,"symbol":"BCHSV-USDT","changes":{"asks":[],"bids":[["242.646","0","1613277183937"]]},"sequenceEnd":1613277183937},"subject":"trade.l2update","topic":"/market/level2:BCHSV-USDT","type":"message"}
1619378327.7273421: {"data":{"sequenceStart":1612702190309,"symbol":"NRG-BTC","changes":{"asks":[["0.00006228","0","1612702190309"]],"bids":[]},"sequenceEnd":1612702190309},"subject":"trade.l2update","topic":"/market/level2:NRG-BTC","type":"message"}
1619378327.943608: {"data":{"sequenceStart":1612699351240,"symbol":"COV-BTC","changes":{"asks":[["0.00001126","0","1612699351240"]],"bids":[]},"sequenceEnd":1612699351240},"subject":"trade.l2update","topic":"/market/level2:COV-BTC","type":"message"}
1619378328.155125: {"data":{"sequenceStart":1613277183938,"symbol":"BCHSV-USDT","changes":{"asks":[["243.284","0","1613277183938"]],"bids":[]},"sequenceEnd":1613277183938},"subject":"trade.l2update","topic":"/market/level2:BCHSV-USDT","type":"message"}
1619378328.155184: {"data":{"sequenceStart":1612844051667,"symbol":"SNX-BTC","changes":{"asks":[["0","0","1612844051667"]],"bids":[]},"sequenceEnd":1612844051667},"subject":"trade.l2update","topic":"/market/level2:SNX-BTC","type":"message"}
1619378328.15521: {"data":{"sequenceStart":1612844051668,"symbol":"SNX-BTC","changes":{"asks":[["0.00028716","1.74177762","1612844051668"]],"bids":[]},"sequenceEnd":1612844051668},"subject":"trade.l2update","topic":"/market/level2:SNX-BTC","type":"message"}
1619378328.155244: {"data":{"sequenceStart":1613277183939,"symbol":"BCHSV-USDT","changes":{"asks":[["0","0","1613277183939"]],"bids":[]},"sequenceEnd":1613277183939},"subject":"trade.l2update","topic":"/market/level2:BCHSV-USDT","type":"message"}
1619378328.155263: {"data":{"sequenceStart":1613277183940,"symbol":"BCHSV-USDT","changes":{"asks":[["243.283","0.6","1613277183940"]],"bids":[]},"sequenceEnd":1613277183940},"subject":"trade.l2update","topic":"/market/level2:BCHSV-USDT","type":"message"}
1619378328.155286: {"data":{"sequenceStart":1613277183941,"symbol":"BCHSV-USDT","changes":{"asks":[],"bids":[["0","0","1613277183941"]]},"sequenceEnd":1613277183941},"subject":"trade.l2update","topic":"/market/level2:BCHSV-USDT","type":"message"}
1619378328.155304: {"data":{"sequenceStart":1613277183942,"symbol":"BCHSV-USDT","changes":{"asks":[],"bids":[["242.647","0.68148185","1613277183942"]]},"sequenceEnd":1613277183942},"subject":"trade.l2update","topic":"/market/level2:BCHSV-USDT","type":"message"}
1619378328.155327: {"data":{"sequenceStart":1612734157724,"symbol":"ANKR-BTC","changes":{"asks":[["0","0","1612734157724"]],"bids":[]},"sequenceEnd":1612734157724},"subject":"trade.l2update","topic":"/market/level2:ANKR-BTC","type":"message"}
1619378328.1553438: {"data":{"sequenceStart":1612734157725,"symbol":"ANKR-BTC","changes":{"asks":[["0.0000026191","191.1759","1612734157725"]],"bids":[]},"sequenceEnd":1612734157725},"subject":"trade.l2update","topic":"/market/level2:ANKR-BTC","type":"message"}
1619378328.155369: {"data":{"sequence":"1612734157725","bestAsk":"0.0000026191","size":"46","bestBidSize":"4051.2663","price":"0.0000026071","time":1619378327288,"bestAskSize":"191.1759","bestBid":"0.0000026033"},"subject":"trade.ticker","topic":"/market/ticker:ANKR-BTC","type":"message"}
1619378328.1553879: {"data":{"sequence":"1612699351240","bestAsk":"0.00001127","size":"96.1525","bestBidSize":"49.6422","price":"0.00001126","time":1619378327288,"bestAskSize":"4331.68226035","bestBid":"0.00001121"},"subject":"trade.ticker","topic":"/market/ticker:COV-BTC","type":"message"}
1619378328.155403: {"data":{"sequence":"1612702190309","bestAsk":"0.00006218","size":"0.0431","bestBidSize":"19.5017","price":"0.00006141","time":1619378327292,"bestAskSize":"43.3399","bestBid":"0.00006141"},"subject":"trade.ticker","topic":"/market/ticker:NRG-BTC","type":"message"}
1619378328.1554172: {"data":{"sequenceStart":1612694580141,"symbol":"CAPP-BTC","changes":{"asks":[],"bids":[["0","0","1612694580141"]]},"sequenceEnd":1612694580141},"subject":"trade.l2update","topic":"/market/level2:CAPP-BTC","type":"message"}
1619378328.155434: {"data":{"sequenceStart":1612694580142,"symbol":"CAPP-BTC","changes":{"asks":[],"bids":[["0.0000001501","5344.27","1612694580142"]]},"sequenceEnd":1612694580142},"subject":"trade.l2update","topic":"/market/level2:CAPP-BTC","type":"message"}
1619378328.155458: {"data":{"sequenceStart":1613277183943,"symbol":"BCHSV-USDT","changes":{"asks":[],"bids":[["0","0","1613277183943"]]},"sequenceEnd":1613277183943},"subject":"trade.l2update","topic":"/market/level2:BCHSV-USDT","type":"message"}
1619378328.155475: {"data":{"sequenceStart":1612844051669,"symbol":"SNX-BTC","changes":{"asks":[["0.00028717","0","1612844051669"]],"bids":[]},"sequenceEnd":1612844051669},"subject":"trade.l2update","topic":"/market/level2:SNX-BTC","type":"message"}
1619378328.155499: {"data":{"sequenceStart":1613277183944,"symbol":"BCHSV-USDT","changes":{"asks":[],"bids":[["242.545","0.10226994","1613277183944"]]},"sequenceEnd":1613277183944},"subject":"trade.l2update","topic":"/market/level2:BCHSV-USDT","type":"message"}
1619378328.155522: {"data":{"sequenceStart":1613277183945,"symbol":"BCHSV-USDT","changes":{"asks":[["243.414","0","1613277183945"]],"bids":[]},"sequenceEnd":1613277183945},"subject":"trade.l2update","topic":"/market/level2:BCHSV-USDT","type":"message"}
1619378328.155545: {"data":{"sequenceStart":1612734157726,"symbol":"ANKR-BTC","changes":{"asks":[["0.0000026192","0","1612734157726"]],"bids":[]},"sequenceEnd":1612734157726},"subject":"trade.l2update","topic":"/market/level2:ANKR-BTC","type":"message"}
1619378328.1555688: {"data":{"sequenceStart":1612702190310,"symbol":"NRG-BTC","changes":{"asks":[],"bids":[["0.00006071","0","1612702190310"]]},"sequenceEnd":1612702190310},"subject":"trade.l2update","topic":"/market/level2:NRG-BTC","type":"message"}
1619378328.1555798: {"data":{"sequenceStart":1613277183946,"symbol":"BCHSV-USDT","changes":{"asks":[],"bids":[["240.618","0","1613277183946"]]},"sequenceEnd":1613277183946},"subject":"trade.l2update","topic":"/market/level2:BCHSV-USDT","type":"message"}
1619378328.1556082: {"data":{"sequenceStart":1612734157727,"symbol":"ANKR-BTC","changes":{"asks":[["0.0000026191","0","1612734157727"]],"bids":[]},"sequenceEnd":1612734157727},"subject":"trade.l2update","topic":"/market/level2:ANKR-BTC","type":"message"}
1619378328.155631: {"data":{"sequenceStart":1613277183947,"symbol":"BCHSV-USDT","changes":{"asks":[],"bids":[["0","0","1613277183947"]]},"sequenceEnd":1613277183947},"subject":"trade.l2update","topic":"/market/level2:BCHSV-USDT","type":"message"}
1619378328.155648: {"data":{"sequenceStart":1613277183948,"symbol":"BCHSV-USDT","changes":{"asks":[],"bids":[["241.771","8.59017087","1613277183948"]]},"sequenceEnd":1613277183948},"subject":"trade.l2update","topic":"/market/level2:BCHSV-USDT","type":"message"}
1619378328.155668: {"data":{"sequenceStart":1613277183949,"symbol":"BCHSV-USDT","changes":{"asks":[["0","0","1613277183949"]],"bids":[]},"sequenceEnd":1613277183949},"subject":"trade.l2update","topic":"/market/level2:BCHSV-USDT","type":"message"}
1619378328.155684: {"data":{"sequenceStart":1613277183950,"symbol":"BCHSV-USDT","changes":{"asks":[["243.005","8.59017087","1613277183950"]],"bids":[]},"sequenceEnd":1613277183950},"subject":"trade.l2update","topic":"/market/level2:BCHSV-USDT","type":"message"}
1619378328.155705: {"data":{"sequenceStart":1613277183951,"symbol":"BCHSV-USDT","changes":{"asks":[],"bids":[["0","0","1613277183951"]]},"sequenceEnd":1613277183951},"subject":"trade.l2update","topic":"/market/level2:BCHSV-USDT","type":"message"}
1619378328.15572: {"data":{"sequenceStart":1613277183952,"symbol":"BCHSV-USDT","changes":{"asks":[],"bids":[["241.976","4.29508543","1613277183952"]]},"sequenceEnd":1613277183952},"subject":"trade.l2update","topic":"/market/level2:BCHSV-USDT","type":"message"}
1619378328.155745: {"data":{"sequenceStart":1612844051670,"symbol":"SNX-BTC","changes":{"asks":[["0","0","1612844051670"]],"bids":[]},"sequenceEnd":1612844051670},"subject":"trade.l2update","topic":"/market/level2:SNX-BTC","type":"message"}
1619378328.155761: {"data":{"sequenceStart":1612844051671,"symbol":"SNX-BTC","changes":{"asks":[["0.00028715","29.24570683","1612844051671"]],"bids":[]},"sequenceEnd":1612844051671},"subject":"trade.l2update","topic":"/market/level2:SNX-BTC","type":"message"}
1619378328.155782: {"data":{"sequenceStart":1612844051672,"symbol":"SNX-BTC","changes":{"asks":[["0.00028716","0","1612844051672"]],"bids":[]},"sequenceEnd":1612844051672},"subject":"trade.l2update","topic":"/market/level2:SNX-BTC","type":"message"}
1619378328.1558049: {"data":{"sequenceStart":1612701563861,"symbol":"DAPPT-BTC","changes":{"asks":[],"bids":[["0","0","1612701563861"]]},"sequenceEnd":1612701563861},"subject":"trade.l2update","topic":"/market/level2:DAPPT-BTC","type":"message"}
1619378328.155815: {"data":{"sequenceStart":1612701563862,"symbol":"DAPPT-BTC","changes":{"asks":[],"bids":[["0.0000001103","3091.7","1612701563862"]]},"sequenceEnd":1612701563862},"subject":"trade.l2update","topic":"/market/level2:DAPPT-BTC","type":"message"}
1619378328.155825: {"data":{"sequenceStart":1613277183953,"symbol":"BCHSV-USDT","changes":{"asks":[],"bids":[["242.545","0","1613277183953"]]},"sequenceEnd":1613277183953},"subject":"trade.l2update","topic":"/market/level2:BCHSV-USDT","type":"message"}
1619378328.1558459: {"data":{"sequenceStart":1612734157728,"symbol":"ANKR-BTC","changes":{"asks":[["0","0","1612734157728"]],"bids":[]},"sequenceEnd":1612734157728},"subject":"trade.l2update","topic":"/market/level2:ANKR-BTC","type":"message"}
1619378328.155862: {"data":{"sequenceStart":1612734157729,"symbol":"ANKR-BTC","changes":{"asks":[["0.000002619","4664.7644","1612734157729"]],"bids":[]},"sequenceEnd":1612734157729},"subject":"trade.l2update","topic":"/market/level2:ANKR-BTC","type":"message"}
1619378328.155884: {"data":{"sequence":"1612701563862","bestAsk":"0.0000001117","size":"1427.5512","bestBidSize":"1463.5949","price":"0.0000001116","time":1619378327330,"bestAskSize":"81.8814","bestBid":"0.0000001114"},"subject":"trade.ticker","topic":"/market/ticker:DAPPT-BTC","type":"message"}
1619378328.1559: {"data":{"sequence":"1613277183953","bestAsk":"242.951","size":"0.08000012","bestBidSize":"5","price":"243.65","time":1619378327331,"bestAskSize":"4.51280965","bestBid":"242.65"},"subject":"trade.ticker","topic":"/market/ticker:BCHSV-USDT","type":"message"}
1619378328.155914: {"data":{"sequenceStart":1612844051673,"symbol":"SNX-BTC","changes":{"asks":[],"bids":[["0","0","1612844051673"]]},"sequenceEnd":1612844051673},"subject":"trade.l2update","topic":"/market/level2:SNX-BTC","type":"message"}
1619378328.155931: {"data":{"sequenceStart":1612844051674,"symbol":"SNX-BTC","changes":{"asks":[],"bids":[["0.00028654","2.10972522","1612844051674"]]},"sequenceEnd":1612844051674},"subject":"trade.l2update","topic":"/market/level2:SNX-BTC","type":"message"}
1619378328.155953: {"data":{"sequence":"1612844051674","bestAsk":"0.00028715","size":"0.01745248","bestBidSize":"0.19100065","price":"0.00028676","time":1619378327346,"bestAskSize":"29.24570683","bestBid":"0.00028678"},"subject":"trade.ticker","topic":"/market/ticker:SNX-BTC","type":"message"}
1619378328.155968: {"data":{"sequenceStart":1612734157730,"symbol":"ANKR-BTC","changes":{"asks":[],"bids":[["0.0000026014","0","1612734157730"]]},"sequenceEnd":1612734157730},"subject":"trade.l2update","topic":"/market/level2:ANKR-BTC","type":"message"}
1619378328.155993: {"data":{"sequenceStart":1613277183954,"symbol":"BCHSV-USDT","changes":{"asks":[["0","0","1613277183954"]],"bids":[]},"sequenceEnd":1613277183954},"subject":"trade.l2update","topic":"/market/level2:BCHSV-USDT","type":"message"}
1619378328.156009: {"data":{"sequenceStart":1613277183955,"symbol":"BCHSV-USDT","changes":{"asks":[["244.386","150","1613277183955"]],"bids":[]},"sequenceEnd":1613277183955},"subject":"trade.l2update","topic":"/market/level2:BCHSV-USDT","type":"message"}
1619378328.15603: {"data":{"sequenceStart":1613277183956,"symbol":"BCHSV-USDT","changes":{"asks":[["0","0","1613277183956"]],"bids":[]},"sequenceEnd":1613277183956},"subject":"trade.l2update","topic":"/market/level2:BCHSV-USDT","type":"message"}
1619378328.156045: {"data":{"sequenceStart":1613277183957,"symbol":"BCHSV-USDT","changes":{"asks":[["243.748","5","1613277183957"]],"bids":[]},"sequenceEnd":1613277183957},"subject":"trade.l2update","topic":"/market/level2:BCHSV-USDT","type":"message"}
1619378328.156066: {"data":{"sequenceStart":1613277183958,"symbol":"BCHSV-USDT","changes":{"asks":[],"bids":[["0","0","1613277183958"]]},"sequenceEnd":1613277183958},"subject":"trade.l2update","topic":"/market/level2:BCHSV-USDT","type":"message"}
1619378328.156081: {"data":{"sequenceStart":1613277183959,"symbol":"BCHSV-USDT","changes":{"asks":[],"bids":[["241.587","5","1613277183959"]]},"sequenceEnd":1613277183959},"subject":"trade.l2update","topic":"/market/level2:BCHSV-USDT","type":"message"}
1619378328.1561012: {"data":{"sequenceStart":1612701563863,"symbol":"DAPPT-BTC","changes":{"asks":[],"bids":[["0","0","1612701563863"]]},"sequenceEnd":1612701563863},"subject":"trade.l2update","topic":"/market/level2:DAPPT-BTC","type":"message"}
1619378328.156111: {"data":{"sequenceStart":1612701563864,"symbol":"DAPPT-BTC","changes":{"asks":[],"bids":[["0.0000001115","10812.7228","1612701563864"]]},"sequenceEnd":1612701563864},"subject":"trade.l2update","topic":"/market/level2:DAPPT-BTC","type":"message"}
1619378328.156119: {"data":{"sequenceStart":1612844051675,"symbol":"SNX-BTC","changes":{"asks":[["0","0","1612844051675"]],"bids":[]},"sequenceEnd":1612844051675},"subject":"trade.l2update","topic":"/market/level2:SNX-BTC","type":"message"}
1619378328.156139: {"data":{"sequenceStart":1612844051676,"symbol":"SNX-BTC","changes":{"asks":[["0.00028714","14.04665842","1612844051676"]],"bids":[]},"sequenceEnd":1612844051676},"subject":"trade.l2update","topic":"/market/level2:SNX-BTC","type":"message"}
1619378328.15616: {"data":{"sequence":"1612694580142","bestAsk":"0.0000002197","size":"1000.02","bestBidSize":"83.07","price":"0.0000002182","time":1619378327382,"bestAskSize":"735.9","bestBid":"0.0000002181"},"subject":"trade.ticker","topic":"/market/ticker:CAPP-BTC","type":"message"}
1619378328.1561742: {"data":{"sequence":"1612702190310","bestAsk":"0.00006218","size":"0.0431","bestBidSize":"19.5017","price":"0.00006141","time":1619378327391,"bestAskSize":"43.3399","bestBid":"0.00006141"},"subject":"trade.ticker","topic":"/market/ticker:NRG-BTC","type":"message"}
1619378328.1561868: {"data":{"sequence":"1612734157730","bestAsk":"0.000002619","size":"46","bestBidSize":"4051.2663","price":"0.0000026071","time":1619378327388,"bestAskSize":"4664.7644","bestBid":"0.0000026033"},"subject":"trade.ticker","topic":"/market/ticker:ANKR-BTC","type":"message"}
1619378328.1562: {"data":{"sequenceStart":1612734157731,"symbol":"ANKR-BTC","changes":{"asks":[["0","0","1612734157731"]],"bids":[]},"sequenceEnd":1612734157731},"subject":"trade.l2update","topic":"/market/level2:ANKR-BTC","type":"message"}
1619378328.1562161: {"data":{"sequenceStart":1612734157732,"symbol":"ANKR-BTC","changes":{"asks":[["0.0000026189","191.1686","1612734157732"]],"bids":[]},"sequenceEnd":1612734157732},"subject":"trade.l2update","topic":"/market/level2:ANKR-BTC","type":"message"}
1619378328.1562371: {"data":{"sequenceStart":1612844051677,"symbol":"SNX-BTC","changes":{"asks":[["0.00028715","0","1612844051677"]],"bids":[]},"sequenceEnd":1612844051677},"subject":"trade.l2update","topic":"/market/level2:SNX-BTC","type":"message"}
1619378328.15626: {"data":{"sequenceStart":1613277183960,"symbol":"BCHSV-USDT","changes":{"asks":[],"bids":[["242.65","0","1613277183960"]]},"sequenceEnd":1613277183960},"subject":"trade.l2update","topic":"/market/level2:BCHSV-USDT","type":"message"}
1619378328.1562822: {"data":{"sequenceStart":1612844051678,"symbol":"SNX-BTC","changes":{"asks":[["0.00028714","0","1612844051678"]],"bids":[]},"sequenceEnd":1612844051678},"subject":"trade.l2update","topic":"/market/level2:SNX-BTC","type":"message"}
1619378328.156304: {"data":{"sequenceStart":1613277183961,"symbol":"BCHSV-USDT","changes":{"asks":[],"bids":[["0","0","1613277183961"]]},"sequenceEnd":1613277183961},"subject":"trade.l2update","topic":"/market/level2:BCHSV-USDT","type":"message"}
1619378328.156321: {"data":{"sequenceStart":1613277183962,"symbol":"BCHSV-USDT","changes":{"asks":[],"bids":[["242.651","5","1613277183962"]]},"sequenceEnd":1613277183962},"subject":"trade.l2update","topic":"/market/level2:BCHSV-USDT","type":"message"}
1619378328.156341: {"data":{"sequenceStart":1612734157733,"symbol":"ANKR-BTC","changes":{"asks":[["0.000002619","0","1612734157733"]],"bids":[]},"sequenceEnd":1612734157733},"subject":"trade.l2update","topic":"/market/level2:ANKR-BTC","type":"message"}
1619378328.156364: {"data":{"sequenceStart":1612734157734,"symbol":"ANKR-BTC","changes":{"asks":[],"bids":[["0","0","1612734157734"]]},"sequenceEnd":1612734157734},"subject":"trade.l2update","topic":"/market/level2:ANKR-BTC","type":"message"}
1619378328.15638: {"data":{"sequenceStart":1612734157735,"symbol":"ANKR-BTC","changes":{"asks":[],"bids":[["0.0000026015","118.3841","1612734157735"]]},"sequenceEnd":1612734157735},"subject":"trade.l2update","topic":"/market/level2:ANKR-BTC","type":"message"}
1619378328.1564019: {"data":{"sequenceStart":1612702190311,"symbol":"NRG-BTC","changes":{"asks":[["0","0","1612702190311"]],"bids":[]},"sequenceEnd":1612702190311},"subject":"trade.l2update","topic":"/market/level2:NRG-BTC","type":"message"}
1619378328.156412: {"data":{"sequenceStart":1612702190312,"symbol":"NRG-BTC","changes":{"asks":[["0.00006229","13.679","1612702190312"]],"bids":[]},"sequenceEnd":1612702190312},"subject":"trade.l2update","topic":"/market/level2:NRG-BTC","type":"message"}
1619378328.1564212: {"data":{"sequenceStart":1612699351241,"symbol":"COV-BTC","changes":{"asks":[["0","0","1612699351241"]],"bids":[]},"sequenceEnd":1612699351241},"subject":"trade.l2update","topic":"/market/level2:COV-BTC","type":"message"}
1619378328.15643: {"data":{"sequenceStart":1612699351242,"symbol":"COV-BTC","changes":{"asks":[["0.00001126","137.9035","1612699351242"]],"bids":[]},"sequenceEnd":1612699351242},"subject":"trade.l2update","topic":"/market/level2:COV-BTC","type":"message"}
1619378328.156439: {"data":{"sequence":"1613277183962","bestAsk":"242.951","size":"0.08000012","bestBidSize":"5","price":"243.65","time":1619378327431,"bestAskSize":"4.51280965","bestBid":"242.651"},"subject":"trade.ticker","topic":"/market/ticker:BCHSV-USDT","type":"message"}
1619378328.1564531: {"data":{"sequenceStart":1612844051679,"symbol":"SNX-BTC","changes":{"asks":[["0","0","1612844051679"]],"bids":[]},"sequenceEnd":1612844051679},"subject":"trade.l2update","topic":"/market/level2:SNX-BTC","type":"message"}
1619378328.156469: {"data":{"sequenceStart":1612844051680,"symbol":"SNX-BTC","changes":{"asks":[["0.00028713","29.24570683","1612844051680"]],"bids":[]},"sequenceEnd":1612844051680},"subject":"trade.l2update","topic":"/market/level2:SNX-BTC","type":"message"}
1619378328.15649: {"data":{"sequence":"1612701563864","bestAsk":"0.0000001117","size":"1427.5512","bestBidSize":"10812.7228","price":"0.0000001116","time":1619378327430,"bestAskSize":"81.8814","bestBid":"0.0000001115"},"subject":"trade.ticker","topic":"/market/ticker:DAPPT-BTC","type":"message"}
1619378328.1565042: {"data":{"sequenceStart":1612844051681,"symbol":"SNX-BTC","changes":{"asks":[],"bids":[["0.00028623","0","1612844051681"]]},"sequenceEnd":1612844051681},"subject":"trade.l2update","topic":"/market/level2:SNX-BTC","type":"message"}
1619378328.156526: {"data":{"sequenceStart":1612844051682,"symbol":"SNX-BTC","changes":{"asks":[["0.00028713","0","1612844051682"]],"bids":[]},"sequenceEnd":1612844051682},"subject":"trade.l2update","topic":"/market/level2:SNX-BTC","type":"message"}
1619378328.156548: {"data":{"sequenceStart":1612844051683,"symbol":"SNX-BTC","changes":{"asks":[["0","0","1612844051683"]],"bids":[]},"sequenceEnd":1612844051683},"subject":"trade.l2update","topic":"/market/level2:SNX-BTC","type":"message"}
1619378328.156564: {"data":{"sequenceStart":1612844051684,"symbol":"SNX-BTC","changes":{"asks":[["0.00028748","14.05828264","1612844051684"]],"bids":[]},"sequenceEnd":1612844051684},"subject":"trade.l2update","topic":"/market/level2:SNX-BTC","type":"message"}
1619378328.156585: {"data":{"sequenceStart":1612701563865,"symbol":"DAPPT-BTC","changes":{"asks":[],"bids":[["0","0","1612701563865"]]},"sequenceEnd":1612701563865},"subject":"trade.l2update","topic":"/market/level2:DAPPT-BTC","type":"message"}
1619378328.156596: {"data":{"sequenceStart":1612701563866,"symbol":"DAPPT-BTC","changes":{"asks":[],"bids":[["0","0","1612701563866"]]},"sequenceEnd":1612701563866},"subject":"trade.l2update","topic":"/market/level2:DAPPT-BTC","type":"message"}
1619378328.156605: {"data":{"sequence":"1612844051684","bestAsk":"0.00028719","size":"0.01745248","bestBidSize":"0.19100065","price":"0.00028676","time":1619378327446,"bestAskSize":"73.32024488","bestBid":"0.00028678"},"subject":"trade.ticker","topic":"/market/ticker:SNX-BTC","type":"message"}
1619378328.1566179: {"data":{"sequenceStart":1612734157736,"symbol":"ANKR-BTC","changes":{"asks":[["0","0","1612734157736"]],"bids":[]},"sequenceEnd":1612734157736},"subject":"trade.l2update","topic":"/market/level2:ANKR-BTC","type":"message"}
1619378328.1566331: {"data":{"sequenceStart":1612734157737,"symbol":"ANKR-BTC","changes":{"asks":[["0.0000026189","4855.933","1612734157737"]],"bids":[]},"sequenceEnd":1612734157737},"subject":"trade.l2update","topic":"/market/level2:ANKR-BTC","type":"message"}
1619378328.156651: {"data":{"sequenceStart":1613277183963,"symbol":"BCHSV-USDT","changes":{"asks":[["243.283","0","1613277183963"]],"bids":[]},"sequenceEnd":1613277183963},"subject":"trade.l2update","topic":"/market/level2:BCHSV-USDT","type":"message"}
1619378328.156673: {"data":{"sequenceStart":1613277183964,"symbol":"BCHSV-USDT","changes":{"asks":[],"bids":[["242.647","0","1613277183964"]]},"sequenceEnd":1613277183964},"subject":"trade.l2update","topic":"/market/level2:BCHSV-USDT","type":"message"}
1619378328.156694: {"data":{"sequenceStart":1612699351243,"symbol":"COV-BTC","changes":{"asks":[["0.00001126","0","1612699351243"]],"bids":[]},"sequenceEnd":1612699351243},"subject":"trade.l2update","topic":"/market/level2:COV-BTC","type":"message"}
1619378328.156712: {"data":{"sequenceStart":1612844051685,"symbol":"SNX-BTC","changes":{"asks":[["0.00028748","0","1612844051685"]],"bids":[]},"sequenceEnd":1612844051685},"subject":"trade.l2update","topic":"/market/level2:SNX-BTC","type":"message"}
1619378328.156733: {"data":{"sequenceStart":1613277183965,"symbol":"BCHSV-USDT","changes":{"asks":[["0","0","1613277183965"]],"bids":[]},"sequenceEnd":1613277183965},"subject":"trade.l2update","topic":"/market/level2:BCHSV-USDT","type":"message"}
1619378328.156749: {"data":{"sequenceStart":1613277183966,"symbol":"BCHSV-USDT","changes":{"asks":[["243.282","0.6","1613277183966"]],"bids":[]},"sequenceEnd":1613277183966},"subject":"trade.l2update","topic":"/market/level2:BCHSV-USDT","type":"message"}
1619378328.15677: {"data":{"sequenceStart":1613277183967,"symbol":"BCHSV-USDT","changes":{"asks":[],"bids":[["0","0","1613277183967"]]},"sequenceEnd":1613277183967},"subject":"trade.l2update","topic":"/market/level2:BCHSV-USDT","type":"message"}
1619378328.156786: {"data":{"sequenceStart":1613277183968,"symbol":"BCHSV-USDT","changes":{"asks":[],"bids":[["242.648","0.68148185","1613277183968"]]},"sequenceEnd":1613277183968},"subject":"trade.l2update","topic":"/market/level2:BCHSV-USDT","type":"message"}
1619378328.156806: {"data":{"sequenceStart":1612844051686,"symbol":"SNX-BTC","changes":{"asks":[["0","0","1612844051686"]],"bids":[]},"sequenceEnd":1612844051686},"subject":"trade.l2update","topic":"/market/level2:SNX-BTC","type":"message"}
1619378328.156822: {"data":{"sequenceStart":1612844051687,"symbol":"SNX-BTC","changes":{"asks":[["0.00028712","1.74226323","1612844051687"]],"bids":[]},"sequenceEnd":1612844051687},"subject":"trade.l2update","topic":"/market/level2:SNX-BTC","type":"message"}
1619378328.156842: {"data":{"sequence":"1612734157737","bestAsk":"0.0000026189","size":"46","bestBidSize":"4051.2663","price":"0.0000026071","time":1619378327488,"bestAskSize":"4855.933","bestBid":"0.0000026033"},"subject":"trade.ticker","topic":"/market/ticker:ANKR-BTC","type":"message"}
1619378328.156856: {"data":{"sequence":"1612702190312","bestAsk":"0.00006218","size":"0.0431","bestBidSize":"19.5017","price":"0.00006141","time":1619378327491,"bestAskSize":"43.3399","bestBid":"0.00006141"},"subject":"trade.ticker","topic":"/market/ticker:NRG-BTC","type":"message"}
1619378328.15687: {"data":{"sequenceStart":1613277183969,"symbol":"BCHSV-USDT","changes":{"asks":[],"bids":[["0","0","1613277183969"]]},"sequenceEnd":1613277183969},"subject":"trade.l2update","topic":"/market/level2:BCHSV-USDT","type":"message"}
1619378328.156885: {"data":{"sequenceStart":1613277183970,"symbol":"BCHSV-USDT","changes":{"asks":[],"bids":[["242.538","0.10226994","1613277183970"]]},"sequenceEnd":1613277183970},"subject":"trade.l2update","topic":"/market/level2:BCHSV-USDT","type":"message"}
1619378328.156905: {"data":{"sequenceStart":1612701563867,"symbol":"DAPPT-BTC","changes":{"asks":[],"bids":[["0","0","1612701563867"]]},"sequenceEnd":1612701563867},"subject":"trade.l2update","topic":"/market/level2:DAPPT-BTC","type":"message"}
1619378328.1569211: {"data":{"sequence":"1612699351243","bestAsk":"0.00001127","size":"96.1525","bestBidSize":"49.6422","price":"0.00001126","time":1619378327488,"bestAskSize":"4331.68226035","bestBid":"0.00001121"},"subject":"trade.ticker","topic":"/market/ticker:COV-BTC","type":"message"}
1619378328.156939: {"data":{"sequenceStart":1613277183971,"symbol":"BCHSV-USDT","changes":{"asks":[],"bids":[["242.651","0","1613277183971"]]},"sequenceEnd":1613277183971},"subject":"trade.l2update","topic":"/market/level2:BCHSV-USDT","type":"message"}
1619378328.156961: {"data":{"sequence":"1612844051687","bestAsk":"0.00028712","size":"0.01745248","bestBidSize":"0.19100065","price":"0.00028676","time":1619378327523,"bestAskSize":"1.74226323","bestBid":"0.00028678"},"subject":"trade.ticker","topic":"/market/ticker:SNX-BTC","type":"message"}
1619378328.156978: {"data":{"sequence":"1612701563867","bestAsk":"0.0000001117","size":"1427.5512","bestBidSize":"10812.7228","price":"0.0000001116","time":1619378327530,"bestAskSize":"81.8814","bestBid":"0.0000001115"},"subject":"trade.ticker","topic":"/market/ticker:DAPPT-BTC","type":"message"}
1619378328.156994: {"data":{"sequence":"1613277183971","bestAsk":"242.951","size":"0.08000012","bestBidSize":"0.68148185","price":"243.65","time":1619378327531,"bestAskSize":"4.51280965","bestBid":"242.648"},"subject":"trade.ticker","topic":"/market/ticker:BCHSV-USDT","type":"message"}
1619378328.157006: {"data":{"sequenceStart":1612844051688,"symbol":"SNX-BTC","changes":{"asks":[["0","0","1612844051688"]],"bids":[]},"sequenceEnd":1612844051688},"subject":"trade.l2update","topic":"/market/level2:SNX-BTC","type":"message"}
1619378328.157022: {"data":{"sequenceStart":1612844051689,"symbol":"SNX-BTC","changes":{"asks":[["0.00028734","14.05828264","1612844051689"]],"bids":[]},"sequenceEnd":1612844051689},"subject":"trade.l2update","topic":"/market/level2:SNX-BTC","type":"message"}
1619378328.157044: {"data":{"sequenceStart":1612712745583,"symbol":"FET-BTC","changes":{"asks":[["0.00000781","148.4897","1612712745583"]],"bids":[]},"sequenceEnd":1612712745583},"subject":"trade.l2update","topic":"/market/level2:FET-BTC","type":"message"}
1619378328.157064: {"data":{"sequenceStart":1612702190313,"symbol":"NRG-BTC","changes":{"asks":[],"bids":[["0","0","1612702190313"]]},"sequenceEnd":1612702190313},"subject":"trade.l2update","topic":"/market/level2:NRG-BTC","type":"message"}
1619378328.157074: {"data":{"sequenceStart":1612702190314,"symbol":"NRG-BTC","changes":{"asks":[],"bids":[["0.00006071","59.3742","1612702190314"]]},"sequenceEnd":1612702190314},"subject":"trade.l2update","topic":"/market/level2:NRG-BTC","type":"message"}
1619378328.1570911: {"data":{"sequence":"1612702190314","bestAsk":"0.00006218","size":"0.0431","bestBidSize":"19.5017","price":"0.00006141","time":1619378327591,"bestAskSize":"43.3399","bestBid":"0.00006141"},"subject":"trade.ticker","topic":"/market/ticker:NRG-BTC","type":"message"}
1619378328.157105: {"data":{"sequence":"1612844051689","bestAsk":"0.00028712","size":"0.01745248","bestBidSize":"0.19100065","price":"0.00028676","time":1619378327623,"bestAskSize":"1.74226323","bestBid":"0.00028678"},"subject":"trade.ticker","topic":"/market/ticker:SNX-BTC","type":"message"}
1619378328.1571178: {"data":{"sequenceStart":1612712745584,"symbol":"FET-BTC","changes":{"asks":[["0","0","1612712745584"]],"bids":[]},"sequenceEnd":1612712745584},"subject":"trade.l2update","topic":"/market/level2:FET-BTC","type":"message"}
1619378328.157133: {"data":{"sequenceStart":1612712745585,"symbol":"FET-BTC","changes":{"asks":[["0.00000794","1528.8753","1612712745585"]],"bids":[]},"sequenceEnd":1612712745585},"subject":"trade.l2update","topic":"/market/level2:FET-BTC","type":"message"}
1619378328.15716: {"data":{"sequenceStart":1613277183972,"symbol":"BCHSV-USDT","changes":{"asks":[],"bids":[["242.648","0","1613277183972"]]},"sequenceEnd":1613277183972},"subject":"trade.l2update","topic":"/market/level2:BCHSV-USDT","type":"message"}
1619378328.157182: {"data":{"sequenceStart":1613277183973,"symbol":"BCHSV-USDT","changes":{"asks":[],"bids":[["0","0","1613277183973"]]},"sequenceEnd":1613277183973},"subject":"trade.l2update","topic":"/market/level2:BCHSV-USDT","type":"message"}
1619378328.1571982: {"data":{"sequenceStart":1613277183974,"symbol":"BCHSV-USDT","changes":{"asks":[],"bids":[["242.652","1.93588101","1613277183974"]]},"sequenceEnd":1613277183974},"subject":"trade.l2update","topic":"/market/level2:BCHSV-USDT","type":"message"}
1619378328.1572192: {"data":{"sequenceStart":1613277183975,"symbol":"BCHSV-USDT","changes":{"asks":[],"bids":[["0","0","1613277183975"]]},"sequenceEnd":1613277183975},"subject":"trade.l2update","topic":"/market/level2:BCHSV-USDT","type":"message"}
1619378328.157234: {"data":{"sequenceStart":1613277183976,"symbol":"BCHSV-USDT","changes":{"asks":[],"bids":[["242.649","0.68148185","1613277183976"]]},"sequenceEnd":1613277183976},"subject":"trade.l2update","topic":"/market/level2:BCHSV-USDT","type":"message"}
1619378328.157254: {"data":{"sequence":"1612712745585","bestAsk":"0.00000775","size":"401.2004","bestBidSize":"357.285","price":"0.00000772","time":1619378327669,"bestAskSize":"8025.7777","bestBid":"0.00000771"},"subject":"trade.ticker","topic":"/market/ticker:FET-BTC","type":"message"}
1619378328.157268: {"data":{"sequenceStart":1612844051690,"symbol":"SNX-BTC","changes":{"asks":[["0.00028734","0","1612844051690"]],"bids":[]},"sequenceEnd":1612844051690},"subject":"trade.l2update","topic":"/market/level2:SNX-BTC","type":"message"}
1619378328.157291: {"data":{"sequenceStart":1612844051691,"symbol":"SNX-BTC","changes":{"asks":[["0","0","1612844051691"]],"bids":[]},"sequenceEnd":1612844051691},"subject":"trade.l2update","topic":"/market/level2:SNX-BTC","type":"message"}
1619378328.157307: {"data":{"sequenceStart":1612844051692,"symbol":"SNX-BTC","changes":{"asks":[["0.00028713","29.24570683","1612844051692"]],"bids":[]},"sequenceEnd":1612844051692},"subject":"trade.l2update","topic":"/market/level2:SNX-BTC","type":"message"}
1619378328.157328: {"data":{"sequenceStart":1612844051693,"symbol":"SNX-BTC","changes":{"asks":[["0.00028713","0","1612844051693"]],"bids":[]},"sequenceEnd":1612844051693},"subject":"trade.l2update","topic":"/market/level2:SNX-BTC","type":"message"}
1619378328.1573498: {"data":{"sequenceStart":1613277183977,"symbol":"BCHSV-USDT","changes":{"asks":[],"bids":[["242.652","0","1613277183977"]]},"sequenceEnd":1613277183977},"subject":"trade.l2update","topic":"/market/level2:BCHSV-USDT","type":"message"}
1619378328.1573708: {"data":{"sequenceStart":1612844051694,"symbol":"SNX-BTC","changes":{"asks":[["0","0","1612844051694"]],"bids":[]},"sequenceEnd":1612844051694},"subject":"trade.l2update","topic":"/market/level2:SNX-BTC","type":"message"}
1619378328.157387: {"data":{"sequenceStart":1612844051695,"symbol":"SNX-BTC","changes":{"asks":[["0.00028712","30.98797006","1612844051695"]],"bids":[]},"sequenceEnd":1612844051695},"subject":"trade.l2update","topic":"/market/level2:SNX-BTC","type":"message"}
1619378328.157405: {"data":{"sequenceStart":1613277183978,"symbol":"BCHSV-USDT","changes":{"asks":[],"bids":[["0","0","1613277183978"]]},"sequenceEnd":1613277183978},"subject":"trade.l2update","topic":"/market/level2:BCHSV-USDT","type":"message"}
1619378328.157421: {"data":{"sequenceStart":1613277183979,"symbol":"BCHSV-USDT","changes":{"asks":[],"bids":[["242.648","5","1613277183979"]]},"sequenceEnd":1613277183979},"subject":"trade.l2update","topic":"/market/level2:BCHSV-USDT","type":"message"}
1619378328.157442: {"data":{"sequence":"1613277183979","bestAsk":"242.951","size":"0.08000012","bestBidSize":"0.68148185","price":"243.65","time":1619378327730,"bestAskSize":"4.51280965","bestBid":"242.649"},"subject":"trade.ticker","topic":"/market/ticker:BCHSV-USDT","type":"message"}
1619378328.157456: {"data":{"sequenceStart":1612701563868,"symbol":"DAPPT-BTC","changes":{"asks":[],"bids":[["0","0","1612701563868"]]},"sequenceEnd":1612701563868},"subject":"trade.l2update","topic":"/market/level2:DAPPT-BTC","type":"message"}
1619378328.157472: {"data":{"sequenceStart":1612701563869,"symbol":"DAPPT-BTC","changes":{"asks":[["0.0000001117","0","1612701563869"]],"bids":[]},"sequenceEnd":1612701563869},"subject":"trade.l2update","topic":"/market/level2:DAPPT-BTC","type":"message"}
1619378328.1574972: {"data":{"sequenceStart":1612701563870,"symbol":"DAPPT-BTC","changes":{"asks":[["0","0","1612701563870"]],"bids":[]},"sequenceEnd":1612701563870},"subject":"trade.l2update","topic":"/market/level2:DAPPT-BTC","type":"message"}
1619378328.157512: {"data":{"sequenceStart":1612701563871,"symbol":"DAPPT-BTC","changes":{"asks":[["0.0000001119","0","1612701563871"]],"bids":[]},"sequenceEnd":1612701563871},"subject":"trade.l2update","topic":"/market/level2:DAPPT-BTC","type":"message"}
1619378328.157534: {"data":{"sequenceStart":1612701563872,"symbol":"DAPPT-BTC","changes":{"asks":[["0","0","1612701563872"]],"bids":[]},"sequenceEnd":1612701563872},"subject":"trade.l2update","topic":"/market/level2:DAPPT-BTC","type":"message"}
1619378328.15755: {"data":{"sequenceStart":1612701563873,"symbol":"DAPPT-BTC","changes":{"asks":[["0.000000112","154.2968","1612701563873"]],"bids":[]},"sequenceEnd":1612701563873},"subject":"trade.l2update","topic":"/market/level2:DAPPT-BTC","type":"message"}
1619378328.157568: {"data":{"sequenceStart":1612701563874,"symbol":"DAPPT-BTC","changes":{"asks":[],"bids":[["0","0","1612701563874"]]},"sequenceEnd":1612701563874},"subject":"trade.l2update","topic":"/market/level2:DAPPT-BTC","type":"message"}
1619378328.157583: {"data":{"symbol":"DAPPT-BTC","sequence":"1612701563869","side":"buy","size":"81.8814","price":"0.0000001117","takerOrderId":"6085c097587c2000060cde57","time":"1619378327739050725","type":"match","makerOrderId":"6085c06144b3790006512a4d","tradeId":"6085c09769bc506996295e36"},"subject":"trade.l3match","topic":"/market/match:DAPPT-BTC","type":"message"}
1619378328.157606: {"data":{"symbol":"DAPPT-BTC","sequence":"1612701563871","side":"buy","size":"0.0267","price":"0.0000001119","takerOrderId":"6085c097587c2000060cde57","time":"1619378327739050725","type":"match","makerOrderId":"6085bf2fbcabdc0006cf0f69","tradeId":"6085c09769bc506996295e37"},"subject":"trade.l3match","topic":"/market/match:DAPPT-BTC","type":"message"}
1619378328.157623: {"data":{"symbol":"DAPPT-BTC","sequence":"1612701563873","side":"buy","size":"1355.35","price":"0.000000112","takerOrderId":"6085c097587c2000060cde57","time":"1619378327739050725","type":"match","makerOrderId":"6085bf2c9bb39f00067c6ff5","tradeId":"6085c09769bc506996295e38"},"subject":"trade.l3match","topic":"/market/match:DAPPT-BTC","type":"message"}
1619378328.157639: {"data":{"sequence":"1612844051695","bestAsk":"0.00028712","size":"0.01745248","bestBidSize":"0.19100065","price":"0.00028676","time":1619378327747,"bestAskSize":"30.98797006","bestBid":"0.00028678"},"subject":"trade.ticker","topic":"/market/ticker:SNX-BTC","type":"message"}
1619378328.157656: {"data":{"sequenceStart":1612844051696,"symbol":"SNX-BTC","changes":{"asks":[["0","0","1612844051696"]],"bids":[]},"sequenceEnd":1612844051696},"subject":"trade.l2update","topic":"/market/level2:SNX-BTC","type":"message"}
1619378328.157687: {"data":{"sequenceStart":1612844051697,"symbol":"SNX-BTC","changes":{"asks":[["0.00028734","14.05828264","1612844051697"]],"bids":[]},"sequenceEnd":1612844051697},"subject":"trade.l2update","topic":"/market/level2:SNX-BTC","type":"message"}
1619378328.157706: {"data":{"sequenceStart":1612701563875,"symbol":"DAPPT-BTC","changes":{"asks":[],"bids":[["0.0000001115","0","1612701563875"]]},"sequenceEnd":1612701563875},"subject":"trade.l2update","topic":"/market/level2:DAPPT-BTC","type":"message"}
1619378328.157728: {"data":{"sequenceStart":1612844051698,"symbol":"SNX-BTC","changes":{"asks":[],"bids":[["0.00028593","0","1612844051698"]]},"sequenceEnd":1612844051698},"subject":"trade.l2update","topic":"/market/level2:SNX-BTC","type":"message"}
1619378328.157748: {"data":{"sequenceStart":1613277183980,"symbol":"BCHSV-USDT","changes":{"asks":[],"bids":[["238.762","0","1613277183980"]]},"sequenceEnd":1613277183980},"subject":"trade.l2update","topic":"/market/level2:BCHSV-USDT","type":"message"}
1619378328.1577668: {"data":{"sequenceStart":1613277183981,"symbol":"BCHSV-USDT","changes":{"asks":[],"bids":[["241.587","0","1613277183981"]]},"sequenceEnd":1613277183981},"subject":"trade.l2update","topic":"/market/level2:BCHSV-USDT","type":"message"}
1619378328.1577861: {"data":{"sequenceStart":1613277183982,"symbol":"BCHSV-USDT","changes":{"asks":[["244.386","0","1613277183982"]],"bids":[]},"sequenceEnd":1613277183982},"subject":"trade.l2update","topic":"/market/level2:BCHSV-USDT","type":"message"}
1619378328.157805: {"data":{"sequenceStart":1613277183983,"symbol":"BCHSV-USDT","changes":{"asks":[["243.748","0","1613277183983"]],"bids":[]},"sequenceEnd":1613277183983},"subject":"trade.l2update","topic":"/market/level2:BCHSV-USDT","type":"message"}
1619378328.157824: {"data":{"sequenceStart":1613277183984,"symbol":"BCHSV-USDT","changes":{"asks":[],"bids":[["242.648","0","1613277183984"]]},"sequenceEnd":1613277183984},"subject":"trade.l2update","topic":"/market/level2:BCHSV-USDT","type":"message"}
1619378328.157842: {"data":{"sequenceStart":1613277183985,"symbol":"BCHSV-USDT","changes":{"asks":[],"bids":[["0","0","1613277183985"]]},"sequenceEnd":1613277183985},"subject":"trade.l2update","topic":"/market/level2:BCHSV-USDT","type":"message"}
1619378328.157856: {"data":{"sequenceStart":1613277183986,"symbol":"BCHSV-USDT","changes":{"asks":[],"bids":[["242.65","5","1613277183986"]]},"sequenceEnd":1613277183986},"subject":"trade.l2update","topic":"/market/level2:BCHSV-USDT","type":"message"}
1619378328.1578739: {"data":{"sequenceStart":1612701563876,"symbol":"DAPPT-BTC","changes":{"asks":[],"bids":[["0","0","1612701563876"]]},"sequenceEnd":1612701563876},"subject":"trade.l2update","topic":"/market/level2:DAPPT-BTC","type":"message"}
1619378328.157888: {"data":{"sequenceStart":1612701563877,"symbol":"DAPPT-BTC","changes":{"asks":[["0.000000112","0","1612701563877"]],"bids":[]},"sequenceEnd":1612701563877},"subject":"trade.l2update","topic":"/market/level2:DAPPT-BTC","type":"message"}
1619378328.157908: {"data":{"sequenceStart":1612701563878,"symbol":"DAPPT-BTC","changes":{"asks":[["0","0","1612701563878"]],"bids":[]},"sequenceEnd":1612701563878},"subject":"trade.l2update","topic":"/market/level2:DAPPT-BTC","type":"message"}
1619378328.157922: {"data":{"sequenceStart":1612701563879,"symbol":"DAPPT-BTC","changes":{"asks":[["0.0000001122","138.018","1612701563879"]],"bids":[]},"sequenceEnd":1612701563879},"subject":"trade.l2update","topic":"/market/level2:DAPPT-BTC","type":"message"}
1619378328.157938: {"data":{"sequenceStart":1612701563880,"symbol":"DAPPT-BTC","changes":{"asks":[],"bids":[["0","0","1612701563880"]]},"sequenceEnd":1612701563880},"subject":"trade.l2update","topic":"/market/level2:DAPPT-BTC","type":"message"}
1619378328.157952: {"data":{"sequence":"1612844051698","bestAsk":"0.00028712","size":"0.01745248","bestBidSize":"0.19100065","price":"0.00028676","time":1619378327823,"bestAskSize":"30.98797006","bestBid":"0.00028678"},"subject":"trade.ticker","topic":"/market/ticker:SNX-BTC","type":"message"}
1619378328.157965: {"data":{"symbol":"DAPPT-BTC","sequence":"1612701563877","side":"buy","size":"154.2968","price":"0.000000112","takerOrderId":"6085c09744b3790006523b90","time":"1619378327823308414","type":"match","makerOrderId":"6085bf2c9bb39f00067c6ff5","tradeId":"6085c09769bc506996295e3a"},"subject":"trade.l3match","topic":"/market/match:DAPPT-BTC","type":"message"}
1619378328.157984: {"data":{"symbol":"DAPPT-BTC","sequence":"1612701563879","side":"buy","size":"3.0084","price":"0.0000001122","takerOrderId":"6085c09744b3790006523b90","time":"1619378327823308414","type":"match","makerOrderId":"6085bf2bbcabdc0006ceffd4","tradeId":"6085c09769bc506996295e3b"},"subject":"trade.l3match","topic":"/market/match:DAPPT-BTC","type":"message"}
1619378328.157998: {"data":{"sequence":"1612701563880","bestAsk":"0.0000001122","size":"3.0084","bestBidSize":"1463.5949","price":"0.0000001122","time":1619378327830,"bestAskSize":"138.018","bestBid":"0.0000001114"},"subject":"trade.ticker","topic":"/market/ticker:DAPPT-BTC","type":"message"}
1619378328.15801: {"data":{"sequenceStart":1612701563881,"symbol":"DAPPT-BTC","changes":{"asks":[],"bids":[["0","0","1612701563881"]]},"sequenceEnd":1612701563881},"subject":"trade.l2update","topic":"/market/level2:DAPPT-BTC","type":"message"}
1619378328.1580238: {"data":{"sequenceStart":1612701563882,"symbol":"DAPPT-BTC","changes":{"asks":[["0.0000001122","0","1612701563882"]],"bids":[]},"sequenceEnd":1612701563882},"subject":"trade.l2update","topic":"/market/level2:DAPPT-BTC","type":"message"}
1619378328.1580448: {"data":{"sequenceStart":1612701563883,"symbol":"DAPPT-BTC","changes":{"asks":[["0","0","1612701563883"]],"bids":[]},"sequenceEnd":1612701563883},"subject":"trade.l2update","topic":"/market/level2:DAPPT-BTC","type":"message"}
1619378328.1580591: {"data":{"sequenceStart":1612701563884,"symbol":"DAPPT-BTC","changes":{"asks":[["0.0000001123","1262.421","1612701563884"]],"bids":[]},"sequenceEnd":1612701563884},"subject":"trade.l2update","topic":"/market/level2:DAPPT-BTC","type":"message"}
1619378328.1580749: {"data":{"sequenceStart":1612701563885,"symbol":"DAPPT-BTC","changes":{"asks":[],"bids":[["0","0","1612701563885"]]},"sequenceEnd":1612701563885},"subject":"trade.l2update","topic":"/market/level2:DAPPT-BTC","type":"message"}
1619378328.158089: {"data":{"sequenceStart":1612701563886,"symbol":"DAPPT-BTC","changes":{"asks":[],"bids":[["0","0","1612701563886"]]},"sequenceEnd":1612701563886},"subject":"trade.l2update","topic":"/market/level2:DAPPT-BTC","type":"message"}
1619378328.158102: {"data":{"sequenceStart":1612701563887,"symbol":"DAPPT-BTC","changes":{"asks":[],"bids":[["0.0000001115","578.6264","1612701563887"]]},"sequenceEnd":1612701563887},"subject":"trade.l2update","topic":"/market/level2:DAPPT-BTC","type":"message"}
1619378328.15812: {"data":{"symbol":"DAPPT-BTC","sequence":"1612701563882","side":"buy","size":"138.018","price":"0.0000001122","takerOrderId":"6085c097bcabdc0006d5f52b","time":"1619378327833607760","type":"match","makerOrderId":"6085bf2bbcabdc0006ceffd4","tradeId":"6085c09769bc506996295e3c"},"subject":"trade.l3match","topic":"/market/match:DAPPT-BTC","type":"message"}
1619378328.158135: {"data":{"symbol":"DAPPT-BTC","sequence":"1612701563884","side":"buy","size":"442.9352","price":"0.0000001123","takerOrderId":"6085c097bcabdc0006d5f52b","time":"1619378327833607760","type":"match","makerOrderId":"6085bfdb587c200006095bb1","tradeId":"6085c09769bc506996295e3d"},"subject":"trade.l3match","topic":"/market/match:DAPPT-BTC","type":"message"}
1619378328.158148: {"data":{"sequence":"1613277183986","bestAsk":"242.951","size":"0.08000012","bestBidSize":"5","price":"243.65","time":1619378327830,"bestAskSize":"4.51280965","bestBid":"242.65"},"subject":"trade.ticker","topic":"/market/ticker:BCHSV-USDT","type":"message"}
1619378328.15816: {"data":{"sequenceStart":1612701563888,"symbol":"DAPPT-BTC","changes":{"asks":[],"bids":[["0","0","1612701563888"]]},"sequenceEnd":1612701563888},"subject":"trade.l2update","topic":"/market/level2:DAPPT-BTC","type":"message"}
1619378328.158174: {"data":{"sequenceStart":1612701563889,"symbol":"DAPPT-BTC","changes":{"asks":[],"bids":[["0","0","1612701563889"]]},"sequenceEnd":1612701563889},"subject":"trade.l2update","topic":"/market/level2:DAPPT-BTC","type":"message"}
1619378328.158188: {"data":{"sequenceStart":1613277183987,"symbol":"BCHSV-USDT","changes":{"asks":[],"bids":[["242.649","0","1613277183987"]]},"sequenceEnd":1613277183987},"subject":"trade.l2update","topic":"/market/level2:BCHSV-USDT","type":"message"}
1619378328.158207: {"data":{"sequenceStart":1612701563890,"symbol":"DAPPT-BTC","changes":{"asks":[],"bids":[["0.0000001115","0","1612701563890"]]},"sequenceEnd":1612701563890},"subject":"trade.l2update","topic":"/market/level2:DAPPT-BTC","type":"message"}
1619378328.158226: {"data":{"sequenceStart":1612694580143,"symbol":"CAPP-BTC","changes":{"asks":[],"bids":[["0.000000218","709.46","1612694580143"]]},"sequenceEnd":1612694580143},"subject":"trade.l2update","topic":"/market/level2:CAPP-BTC","type":"message"}
1619378328.1582432: {"data":{"sequenceStart":1613277183988,"symbol":"BCHSV-USDT","changes":{"asks":[["243.282","0","1613277183988"]],"bids":[]},"sequenceEnd":1613277183988},"subject":"trade.l2update","topic":"/market/level2:BCHSV-USDT","type":"message"}
1619378328.158262: {"data":{"sequence":"1612694580143","bestAsk":"0.0000002197","size":"1000.02","bestBidSize":"83.07","price":"0.0000002182","time":1619378327881,"bestAskSize":"735.9","bestBid":"0.0000002181"},"subject":"trade.ticker","topic":"/market/ticker:CAPP-BTC","type":"message"}
1619378328.1582751: {"data":{"sequenceStart":1612701563891,"symbol":"DAPPT-BTC","changes":{"asks":[],"bids":[["0","0","1612701563891"]]},"sequenceEnd":1612701563891},"subject":"trade.l2update","topic":"/market/level2:DAPPT-BTC","type":"message"}
1619378328.158289: {"data":{"sequenceStart":1612701563892,"symbol":"DAPPT-BTC","changes":{"asks":[["0.0000001123","765.2607","1612701563892"]],"bids":[]},"sequenceEnd":1612701563892},"subject":"trade.l2update","topic":"/market/level2:DAPPT-BTC","type":"message"}
1619378328.158307: {"data":{"sequenceStart":1612701563893,"symbol":"DAPPT-BTC","changes":{"asks":[],"bids":[["0","0","1612701563893"]]},"sequenceEnd":1612701563893},"subject":"trade.l2update","topic":"/market/level2:DAPPT-BTC","type":"message"}
1619378328.1583202: {"data":{"sequenceStart":1612701563894,"symbol":"DAPPT-BTC","changes":{"asks":[],"bids":[["0","0","1612701563894"]]},"sequenceEnd":1612701563894},"subject":"trade.l2update","topic":"/market/level2:DAPPT-BTC","type":"message"}
1619378328.158334: {"data":{"sequenceStart":1612701563895,"symbol":"DAPPT-BTC","changes":{"asks":[["0.0000001123","310.5072","1612701563895"]],"bids":[]},"sequenceEnd":1612701563895},"subject":"trade.l2update","topic":"/market/level2:DAPPT-BTC","type":"message"}
1619378328.158349: {"data":{"sequenceStart":1612701563896,"symbol":"DAPPT-BTC","changes":{"asks":[],"bids":[["0","0","1612701563896"]]},"sequenceEnd":1612701563896},"subject":"trade.l2update","topic":"/market/level2:DAPPT-BTC","type":"message"}
1619378328.1583629: {"data":{"sequenceStart":1613277183989,"symbol":"BCHSV-USDT","changes":{"asks":[["0","0","1613277183989"]],"bids":[]},"sequenceEnd":1613277183989},"subject":"trade.l2update","topic":"/market/level2:BCHSV-USDT","type":"message"}
1619378328.158377: {"data":{"sequenceStart":1613277183990,"symbol":"BCHSV-USDT","changes":{"asks":[["243.279","0.6","1613277183990"]],"bids":[]},"sequenceEnd":1613277183990},"subject":"trade.l2update","topic":"/market/level2:BCHSV-USDT","type":"message"}
1619378328.1583948: {"data":{"sequenceStart":1613277183991,"symbol":"BCHSV-USDT","changes":{"asks":[],"bids":[["0","0","1613277183991"]]},"sequenceEnd":1613277183991},"subject":"trade.l2update","topic":"/market/level2:BCHSV-USDT","type":"message"}
1619378328.1584089: {"data":{"sequenceStart":1613277183992,"symbol":"BCHSV-USDT","changes":{"asks":[],"bids":[["242.648","0.68148185","1613277183992"]]},"sequenceEnd":1613277183992},"subject":"trade.l2update","topic":"/market/level2:BCHSV-USDT","type":"message"}
1619378328.1584268: {"data":{"symbol":"DAPPT-BTC","sequence":"1612701563892","side":"buy","size":"497.1603","price":"0.0000001123","takerOrderId":"6085c097b3436b00064d0c49","time":"1619378327876253766","type":"match","makerOrderId":"6085bfdb587c200006095bb1","tradeId":"6085c09769bc506996295e40"},"subject":"trade.l3match","topic":"/market/match:DAPPT-BTC","type":"message"}
1619378328.158442: {"data":{"symbol":"DAPPT-BTC","sequence":"1612701563895","side":"buy","size":"454.7535","price":"0.0000001123","takerOrderId":"6085c0976ac0850006c45ae1","time":"1619378327876496435","type":"match","makerOrderId":"6085bfdb587c200006095bb1","tradeId":"6085c09769bc506996295e41"},"subject":"trade.l3match","topic":"/market/match:DAPPT-BTC","type":"message"}
1619378328.1584551: {"data":{"sequenceStart":1613277183993,"symbol":"BCHSV-USDT","changes":{"asks":[],"bids":[["242.65","0","1613277183993"]]},"sequenceEnd":1613277183993},"subject":"trade.l2update","topic":"/market/level2:BCHSV-USDT","type":"message"}
1619378328.158474: {"data":{"sequenceStart":1612701563897,"symbol":"DAPPT-BTC","changes":{"asks":[],"bids":[["0","0","1612701563897"]]},"sequenceEnd":1612701563897},"subject":"trade.l2update","topic":"/market/level2:DAPPT-BTC","type":"message"}
1619378328.158489: {"data":{"sequenceStart":1612701563898,"symbol":"DAPPT-BTC","changes":{"asks":[["0.0000001123","0","1612701563898"]],"bids":[]},"sequenceEnd":1612701563898},"subject":"trade.l2update","topic":"/market/level2:DAPPT-BTC","type":"message"}
1619378328.158509: {"data":{"sequenceStart":1612701563899,"symbol":"DAPPT-BTC","changes":{"asks":[["0","0","1612701563899"]],"bids":[]},"sequenceEnd":1612701563899},"subject":"trade.l2update","topic":"/market/level2:DAPPT-BTC","type":"message"}
1619378328.1585228: {"data":{"sequenceStart":1612701563900,"symbol":"DAPPT-BTC","changes":{"asks":[],"bids":[["0","0","1612701563900"]]},"sequenceEnd":1612701563900},"subject":"trade.l2update","topic":"/market/level2:DAPPT-BTC","type":"message"}
1619378328.158536: {"data":{"sequenceStart":1613277183994,"symbol":"BCHSV-USDT","changes":{"asks":[],"bids":[["0","0","1613277183994"]]},"sequenceEnd":1613277183994},"subject":"trade.l2update","topic":"/market/level2:BCHSV-USDT","type":"message"}
1619378328.158549: {"data":{"sequenceStart":1613277183995,"symbol":"BCHSV-USDT","changes":{"asks":[],"bids":[["239.883","1.65079888","1613277183995"]]},"sequenceEnd":1613277183995},"subject":"trade.l2update","topic":"/market/level2:BCHSV-USDT","type":"message"}
1619378328.158568: {"data":{"symbol":"DAPPT-BTC","sequence":"1612701563898","side":"buy","size":"310.5072","price":"0.0000001123","takerOrderId":"6085c0979bb39f0006833424","time":"1619378327896516815","type":"match","makerOrderId":"6085bfdb587c200006095bb1","tradeId":"6085c09769bc506996295e42"},"subject":"trade.l3match","topic":"/market/match:DAPPT-BTC","type":"message"}
1619378328.158596: {"data":{"sequenceStart":1612694580144,"symbol":"CAPP-BTC","changes":{"asks":[["0","0","1612694580144"]],"bids":[]},"sequenceEnd":1612694580144},"subject":"trade.l2update","topic":"/market/level2:CAPP-BTC","type":"message"}
1619378328.1586099: {"data":{"sequenceStart":1612694580145,"symbol":"CAPP-BTC","changes":{"asks":[["0.0000002196","330.25","1612694580145"]],"bids":[]},"sequenceEnd":1612694580145},"subject":"trade.l2update","topic":"/market/level2:CAPP-BTC","type":"message"}
1619378328.158632: {"data":{"sequenceStart":1612701563901,"symbol":"DAPPT-BTC","changes":{"asks":[],"bids":[["0","0","1612701563901"]]},"sequenceEnd":1612701563901},"subject":"trade.l2update","topic":"/market/level2:DAPPT-BTC","type":"message"}
1619378328.158646: {"data":{"sequenceStart":1612701563902,"symbol":"DAPPT-BTC","changes":{"asks":[],"bids":[["0","0","1612701563902"]]},"sequenceEnd":1612701563902},"subject":"trade.l2update","topic":"/market/level2:DAPPT-BTC","type":"message"}
1619378328.158659: {"data":{"sequenceStart":1612844051699,"symbol":"SNX-BTC","changes":{"asks":[["0.00028734","0","1612844051699"]],"bids":[]},"sequenceEnd":1612844051699},"subject":"trade.l2update","topic":"/market/level2:SNX-BTC","type":"message"}
1619378328.158678: {"data":{"sequence":"1612844051699","bestAsk":"0.00028712","size":"0.01745248","bestBidSize":"0.19100065","price":"0.00028676","time":1619378327923,"bestAskSize":"30.98797006","bestBid":"0.00028678"},"subject":"trade.ticker","topic":"/market/ticker:SNX-BTC","type":"message"}
1619378328.1586912: {"data":{"sequence":"1613277183995","bestAsk":"242.951","size":"0.08000012","bestBidSize":"0.68148185","price":"243.65","time":1619378327930,"bestAskSize":"4.51280965","bestBid":"242.648"},"subject":"trade.ticker","topic":"/market/ticker:BCHSV-USDT","type":"message"}
1619378328.1587021: {"data":{"sequence":"1612701563902","bestAsk":"0.0000001126","size":"310.5072","bestBidSize":"1463.5949","price":"0.0000001123","time":1619378327930,"bestAskSize":"361.2609","bestBid":"0.0000001114"},"subject":"trade.ticker","topic":"/market/ticker:DAPPT-BTC","type":"message"}
1619378328.158713: {"data":{"sequenceStart":1612701563903,"symbol":"DAPPT-BTC","changes":{"asks":[],"bids":[["0","0","1612701563903"]]},"sequenceEnd":1612701563903},"subject":"trade.l2update","topic":"/market/level2:DAPPT-BTC","type":"message"}
1619378328.158726: {"data":{"sequenceStart":1612701563904,"symbol":"DAPPT-BTC","changes":{"asks":[],"bids":[["0","0","1612701563904"]]},"sequenceEnd":1612701563904},"subject":"trade.l2update","topic":"/market/level2:DAPPT-BTC","type":"message"}
1619378328.1587389: {"data":{"sequenceStart":1612701563905,"symbol":"DAPPT-BTC","changes":{"asks":[],"bids":[["0","0","1612701563905"]]},"sequenceEnd":1612701563905},"subject":"trade.l2update","topic":"/market/level2:DAPPT-BTC","type":"message"}
1619378328.158752: {"data":{"sequenceStart":1612701563906,"symbol":"DAPPT-BTC","changes":{"asks":[],"bids":[["0","0","1612701563906"]]},"sequenceEnd":1612701563906},"subject":"trade.l2update","topic":"/market/level2:DAPPT-BTC","type":"message"}
1619378328.158765: {"data":{"sequenceStart":1612701563907,"symbol":"DAPPT-BTC","changes":{"asks":[],"bids":[["0","0","1612701563907"]]},"sequenceEnd":1612701563907},"subject":"trade.l2update","topic":"/market/level2:DAPPT-BTC","type":"message"}
1619378328.158777: {"data":{"sequenceStart":1612701563908,"symbol":"DAPPT-BTC","changes":{"asks":[],"bids":[["0","0","1612701563908"]]},"sequenceEnd":1612701563908},"subject":"trade.l2update","topic":"/market/level2:DAPPT-BTC","type":"message"}
1619378328.1587899: {"data":{"sequenceStart":1612701563909,"symbol":"DAPPT-BTC","changes":{"asks":[],"bids":[["0","0","1612701563909"]]},"sequenceEnd":1612701563909},"subject":"trade.l2update","topic":"/market/level2:DAPPT-BTC","type":"message"}
1619378328.158803: {"data":{"sequenceStart":1612701563910,"symbol":"DAPPT-BTC","changes":{"asks":[],"bids":[["0","0","1612701563910"]]},"sequenceEnd":1612701563910},"subject":"trade.l2update","topic":"/market/level2:DAPPT-BTC","type":"message"}
1619378328.158815: {"data":{"sequenceStart":1612701563911,"symbol":"DAPPT-BTC","changes":{"asks":[],"bids":[["0","0","1612701563911"]]},"sequenceEnd":1612701563911},"subject":"trade.l2update","topic":"/market/level2:DAPPT-BTC","type":"message"}
1619378328.158828: {"data":{"sequenceStart":1612701563912,"symbol":"DAPPT-BTC","changes":{"asks":[],"bids":[["0.0000001115","137.6876","1612701563912"]]},"sequenceEnd":1612701563912},"subject":"trade.l2update","topic":"/market/level2:DAPPT-BTC","type":"message"}
1619378328.158846: {"data":{"sequenceStart":1612844051700,"symbol":"SNX-BTC","changes":{"asks":[["0.00028712","1.74226323","1612844051700"]],"bids":[]},"sequenceEnd":1612844051700},"subject":"trade.l2update","topic":"/market/level2:SNX-BTC","type":"message"}
1619378328.1588612: {"data":{"sequenceStart":1612701563913,"symbol":"DAPPT-BTC","changes":{"asks":[],"bids":[["0.0000001115","0","1612701563913"]]},"sequenceEnd":1612701563913},"subject":"trade.l2update","topic":"/market/level2:DAPPT-BTC","type":"message"}
1619378328.15888: {"data":{"sequenceStart":1612701563914,"symbol":"DAPPT-BTC","changes":{"asks":[],"bids":[["0","0","1612701563914"]]},"sequenceEnd":1612701563914},"subject":"trade.l2update","topic":"/market/level2:DAPPT-BTC","type":"message"}
1619378328.158894: {"data":{"sequenceStart":1612701563915,"symbol":"DAPPT-BTC","changes":{"asks":[],"bids":[["0","0","1612701563915"]]},"sequenceEnd":1612701563915},"subject":"trade.l2update","topic":"/market/level2:DAPPT-BTC","type":"message"}
1619378328.1589062: {"data":{"sequence":"1612694580145","bestAsk":"0.0000002196","size":"1000.02","bestBidSize":"83.07","price":"0.0000002182","time":1619378327981,"bestAskSize":"330.25","bestBid":"0.0000002181"},"subject":"trade.ticker","topic":"/market/ticker:CAPP-BTC","type":"message"}
1619378328.158918: {"data":{"sequenceStart":1612701563916,"symbol":"DAPPT-BTC","changes":{"asks":[],"bids":[["0","0","1612701563916"]]},"sequenceEnd":1612701563916},"subject":"trade.l2update","topic":"/market/level2:DAPPT-BTC","type":"message"}
1619378328.158931: {"data":{"sequenceStart":1613277183996,"symbol":"BCHSV-USDT","changes":{"asks":[],"bids":[["0","0","1613277183996"]]},"sequenceEnd":1613277183996},"subject":"trade.l2update","topic":"/market/level2:BCHSV-USDT","type":"message"}
1619378328.158944: {"data":{"sequence":"1612844051700","bestAsk":"0.00028712","size":"0.01745248","bestBidSize":"0.19100065","price":"0.00028676","time":1619378328023,"bestAskSize":"1.74226323","bestBid":"0.00028678"},"subject":"trade.ticker","topic":"/market/ticker:SNX-BTC","type":"message"}
1619378328.158957: {"data":{"sequenceStart":1613277183997,"symbol":"BCHSV-USDT","changes":{"asks":[],"bids":[["242.653","5","1613277183997"]]},"sequenceEnd":1613277183997},"subject":"trade.l2update","topic":"/market/level2:BCHSV-USDT","type":"message"}
1619378328.158974: {"data":{"sequence":"1612701563916","bestAsk":"0.0000001126","size":"310.5072","bestBidSize":"1463.5949","price":"0.0000001123","time":1619378328030,"bestAskSize":"361.2609","bestBid":"0.0000001114"},"subject":"trade.ticker","topic":"/market/ticker:DAPPT-BTC","type":"message"}
1619378328.158986: {"data":{"sequence":"1613277183997","bestAsk":"242.951","size":"0.08000012","bestBidSize":"5","price":"243.65","time":1619378328030,"bestAskSize":"4.51280965","bestBid":"242.653"},"subject":"trade.ticker","topic":"/market/ticker:BCHSV-USDT","type":"message"}
1619378328.158997: {"data":{"sequenceStart":1612844051701,"symbol":"SNX-BTC","changes":{"asks":[["0","0","1612844051701"]],"bids":[]},"sequenceEnd":1612844051701},"subject":"trade.l2update","topic":"/market/level2:SNX-BTC","type":"message"}
1619378328.1590111: {"data":{"sequenceStart":1612844051702,"symbol":"SNX-BTC","changes":{"asks":[["0.00028711","29.24570683","1612844051702"]],"bids":[]},"sequenceEnd":1612844051702},"subject":"trade.l2update","topic":"/market/level2:SNX-BTC","type":"message"}
1619378328.159029: {"data":{"sequenceStart":1613277183998,"symbol":"BCHSV-USDT","changes":{"asks":[["243.279","0","1613277183998"]],"bids":[]},"sequenceEnd":1613277183998},"subject":"trade.l2update","topic":"/market/level2:BCHSV-USDT","type":"message"}
1619378328.159049: {"data":{"sequenceStart":1613277183999,"symbol":"BCHSV-USDT","changes":{"asks":[],"bids":[["242.648","0","1613277183999"]]},"sequenceEnd":1613277183999},"subject":"trade.l2update","topic":"/market/level2:BCHSV-USDT","type":"message"}
1619378328.159067: {"data":{"sequenceStart":1613277184000,"symbol":"BCHSV-USDT","changes":{"asks":[["0","0","1613277184000"]],"bids":[]},"sequenceEnd":1613277184000},"subject":"trade.l2update","topic":"/market/level2:BCHSV-USDT","type":"message"}
1619378328.159081: {"data":{"sequenceStart":1613277184001,"symbol":"BCHSV-USDT","changes":{"asks":[["243.277","0.6","1613277184001"]],"bids":[]},"sequenceEnd":1613277184001},"subject":"trade.l2update","topic":"/market/level2:BCHSV-USDT","type":"message"}
1619378328.1590989: {"data":{"sequenceStart":1612701563917,"symbol":"DAPPT-BTC","changes":{"asks":[],"bids":[["0","0","1612701563917"]]},"sequenceEnd":1612701563917},"subject":"trade.l2update","topic":"/market/level2:DAPPT-BTC","type":"message"}
1619378328.159112: {"data":{"sequenceStart":1612701563918,"symbol":"DAPPT-BTC","changes":{"asks":[],"bids":[["0","0","1612701563918"]]},"sequenceEnd":1612701563918},"subject":"trade.l2update","topic":"/market/level2:DAPPT-BTC","type":"message"}
1619378328.159125: {"data":{"sequenceStart":1613277184002,"symbol":"BCHSV-USDT","changes":{"asks":[],"bids":[["0","0","1613277184002"]]},"sequenceEnd":1613277184002},"subject":"trade.l2update","topic":"/market/level2:BCHSV-USDT","type":"message"}
1619378328.159137: {"data":{"sequenceStart":1613277184003,"symbol":"BCHSV-USDT","changes":{"asks":[],"bids":[["242.651","0.68148185","1613277184003"]]},"sequenceEnd":1613277184003},"subject":"trade.l2update","topic":"/market/level2:BCHSV-USDT","type":"message"}
1619378328.159154: {"data":{"sequenceStart":1612712745586,"symbol":"FET-BTC","changes":{"asks":[["0.00000788","205.0081","1612712745586"]],"bids":[]},"sequenceEnd":1612712745586},"subject":"trade.l2update","topic":"/market/level2:FET-BTC","type":"message"}
1619378328.1591702: {"data":{"sequenceStart":1613277184004,"symbol":"BCHSV-USDT","changes":{"asks":[["242.951","0","1613277184004"]],"bids":[]},"sequenceEnd":1613277184004},"subject":"trade.l2update","topic":"/market/level2:BCHSV-USDT","type":"message"}
1619378328.159188: {"data":{"sequenceStart":1613277184005,"symbol":"BCHSV-USDT","changes":{"asks":[],"bids":[["242.653","0","1613277184005"]]},"sequenceEnd":1613277184005},"subject":"trade.l2update","topic":"/market/level2:BCHSV-USDT","type":"message"}
1619378328.159206: {"data":{"sequenceStart":1612701563919,"symbol":"DAPPT-BTC","changes":{"asks":[],"bids":[["0","0","1612701563919"]]},"sequenceEnd":1612701563919},"subject":"trade.l2update","topic":"/market/level2:DAPPT-BTC","type":"message"}
1619378328.15922: {"data":{"sequenceStart":1612701563920,"symbol":"DAPPT-BTC","changes":{"asks":[],"bids":[["0.0000001115","163.8789","1612701563920"]]},"sequenceEnd":1612701563920},"subject":"trade.l2update","topic":"/market/level2:DAPPT-BTC","type":"message"}
1619378328.1592379: {"data":{"sequenceStart":1613277184006,"symbol":"BCHSV-USDT","changes":{"asks":[],"bids":[["0","0","1613277184006"]]},"sequenceEnd":1613277184006},"subject":"trade.l2update","topic":"/market/level2:BCHSV-USDT","type":"message"}
1619378328.1595929: {"data":{"sequenceStart":1613277184007,"symbol":"BCHSV-USDT","changes":{"asks":[],"bids":[["242.654","5","1613277184007"]]},"sequenceEnd":1613277184007},"subject":"trade.l2update","topic":"/market/level2:BCHSV-USDT","type":"message"}
1619378328.15963: {"data":{"sequenceStart":1612844051703,"symbol":"SNX-BTC","changes":{"asks":[],"bids":[["0","0","1612844051703"]]},"sequenceEnd":1612844051703},"subject":"trade.l2update","topic":"/market/level2:SNX-BTC","type":"message"}
1619378328.15965: {"data":{"sequenceStart":1612844051704,"symbol":"SNX-BTC","changes":{"asks":[],"bids":[["0.0002825","118.74289539","1612844051704"]]},"sequenceEnd":1612844051704},"subject":"trade.l2update","topic":"/market/level2:SNX-BTC","type":"message"}
1619378328.159672: {"data":{"sequenceStart":1613277184008,"symbol":"BCHSV-USDT","changes":{"asks":[["0","0","1613277184008"]],"bids":[]},"sequenceEnd":1613277184008},"subject":"trade.l2update","topic":"/market/level2:BCHSV-USDT","type":"message"}
1619378328.1596868: {"data":{"sequenceStart":1613277184009,"symbol":"BCHSV-USDT","changes":{"asks":[["242.851","4.51280965","1613277184009"]],"bids":[]},"sequenceEnd":1613277184009},"subject":"trade.l2update","topic":"/market/level2:BCHSV-USDT","type":"message"}
1619378328.1597068: {"data":{"sequenceStart":1613277184010,"symbol":"BCHSV-USDT","changes":{"asks":[],"bids":[["0","0","1613277184010"]]},"sequenceEnd":1613277184010},"subject":"trade.l2update","topic":"/market/level2:BCHSV-USDT","type":"message"}
1619378328.159722: {"data":{"sequenceStart":1613277184011,"symbol":"BCHSV-USDT","changes":{"asks":[],"bids":[["242.621","4.51280965","1613277184011"]]},"sequenceEnd":1613277184011},"subject":"trade.l2update","topic":"/market/level2:BCHSV-USDT","type":"message"}
1619378328.15974: {"data":{"sequence":"1612844051704","bestAsk":"0.00028711","size":"0.01745248","bestBidSize":"0.19100065","price":"0.00028676","time":1619378328123,"bestAskSize":"29.24570683","bestBid":"0.00028678"},"subject":"trade.ticker","topic":"/market/ticker:SNX-BTC","type":"message"}
1619378328.16582: {"data":{"sequence":"1612701563920","bestAsk":"0.0000001126","size":"310.5072","bestBidSize":"163.8789","price":"0.0000001123","time":1619378328130,"bestAskSize":"361.2609","bestBid":"0.0000001115"},"subject":"trade.ticker","topic":"/market/ticker:DAPPT-BTC","type":"message"}
1619378328.165874: {"data":{"sequence":"1613277184011","bestAsk":"242.851","size":"0.08000012","bestBidSize":"5","price":"243.65","time":1619378328131,"bestAskSize":"4.51280965","bestBid":"242.654"},"subject":"trade.ticker","topic":"/market/ticker:BCHSV-USDT","type":"message"}
1619378328.1724732: {"data":{"sequenceStart":1612844051705,"symbol":"SNX-BTC","changes":{"asks":[["0.00028711","0","1612844051705"]],"bids":[]},"sequenceEnd":1612844051705},"subject":"trade.l2update","topic":"/market/level2:SNX-BTC","type":"message"}
1619378328.177849: {"data":{"sequenceStart":1613277184012,"symbol":"BCHSV-USDT","changes":{"asks":[],"bids":[["242.538","0","1613277184012"]]},"sequenceEnd":1613277184012},"subject":"trade.l2update","topic":"/market/level2:BCHSV-USDT","type":"message"}
1619378328.202212: {"data":{"sequenceStart":1612844051706,"symbol":"SNX-BTC","changes":{"asks":[["0","0","1612844051706"]],"bids":[]},"sequenceEnd":1612844051706},"subject":"trade.l2update","topic":"/market/level2:SNX-BTC","type":"message"}
1619378328.2022889: {"data":{"sequenceStart":1612844051707,"symbol":"SNX-BTC","changes":{"asks":[["0.00028732","0.12637694","1612844051707"]],"bids":[]},"sequenceEnd":1612844051707},"subject":"trade.l2update","topic":"/market/level2:SNX-BTC","type":"message"}
1619378328.202344: {"data":{"sequenceStart":1613277184013,"symbol":"BCHSV-USDT","changes":{"asks":[["246.421","0","1613277184013"]],"bids":[]},"sequenceEnd":1613277184013},"subject":"trade.l2update","topic":"/market/level2:BCHSV-USDT","type":"message"}
1619378328.2069209: {"data":{"sequence":"1612712745586","bestAsk":"0.00000775","size":"401.2004","bestBidSize":"357.285","price":"0.00000772","time":1619378328167,"bestAskSize":"8025.7777","bestBid":"0.00000771"},"subject":"trade.ticker","topic":"/market/ticker:FET-BTC","type":"message"}
1619378328.2310588: {"data":{"sequenceStart":1613277184014,"symbol":"BCHSV-USDT","changes":{"asks":[],"bids":[["238.669","0","1613277184014"]]},"sequenceEnd":1613277184014},"subject":"trade.l2update","topic":"/market/level2:BCHSV-USDT","type":"message"}
1619378328.236726: {"data":{"sequenceStart":1612701563921,"symbol":"DAPPT-BTC","changes":{"asks":[],"bids":[["0","0","1612701563921"]]},"sequenceEnd":1612701563921},"subject":"trade.l2update","topic":"/market/level2:DAPPT-BTC","type":"message"}
1619378328.23684: {"data":{"sequenceStart":1612844051708,"symbol":"SNX-BTC","changes":{"asks":[],"bids":[["0","0","1612844051708"]]},"sequenceEnd":1612844051708},"subject":"trade.l2update","topic":"/market/level2:SNX-BTC","type":"message"}
1619378328.236892: {"data":{"sequenceStart":1612844051709,"symbol":"SNX-BTC","changes":{"asks":[],"bids":[["0.00028586","256.97655","1612844051709"]]},"sequenceEnd":1612844051709},"subject":"trade.l2update","topic":"/market/level2:SNX-BTC","type":"message"}
1619378328.258555: {"data":{"sequenceStart":1613277184015,"symbol":"BCHSV-USDT","changes":{"asks":[["0","0","1613277184015"]],"bids":[]},"sequenceEnd":1613277184015},"subject":"trade.l2update","topic":"/market/level2:BCHSV-USDT","type":"message"}
1619378328.2586722: {"data":{"sequenceStart":1613277184016,"symbol":"BCHSV-USDT","changes":{"asks":[["246.421","37.177","1613277184016"]],"bids":[]},"sequenceEnd":1613277184016},"subject":"trade.l2update","topic":"/market/level2:BCHSV-USDT","type":"message"}
1619378328.264619: {"data":{"sequence":"1612701563921","bestAsk":"0.0000001126","size":"310.5072","bestBidSize":"163.8789","price":"0.0000001123","time":1619378328230,"bestAskSize":"361.2609","bestBid":"0.0000001115"},"subject":"trade.ticker","topic":"/market/ticker:DAPPT-BTC","type":"message"}
1619378328.267788: {"data":{"sequence":"1613277184016","bestAsk":"242.851","size":"0.08000012","bestBidSize":"5","price":"243.65","time":1619378328230,"bestAskSize":"4.51280965","bestBid":"242.654"},"subject":"trade.ticker","topic":"/market/ticker:BCHSV-USDT","type":"message"}
1619378328.284362: {"data":{"sequence":"1612844051709","bestAsk":"0.00028712","size":"0.01745248","bestBidSize":"0.19100065","price":"0.00028676","time":1619378328247,"bestAskSize":"1.74226323","bestBid":"0.00028678"},"subject":"trade.ticker","topic":"/market/ticker:SNX-BTC","type":"message"}
1619378328.307373: {"data":{"sequenceStart":1612701563922,"symbol":"DAPPT-BTC","changes":{"asks":[],"bids":[["0","0","1612701563922"]]},"sequenceEnd":1612701563922},"subject":"trade.l2update","topic":"/market/level2:DAPPT-BTC","type":"message"}
1619378328.307482: {"data":{"sequenceStart":1612701563923,"symbol":"DAPPT-BTC","changes":{"asks":[],"bids":[["0","0","1612701563923"]]},"sequenceEnd":1612701563923},"subject":"trade.l2update","topic":"/market/level2:DAPPT-BTC","type":"message"}
1619378328.35359: {"data":{"sequenceStart":1612712745587,"symbol":"FET-BTC","changes":{"asks":[["0","0","1612712745587"]],"bids":[]},"sequenceEnd":1612712745587},"subject":"trade.l2update","topic":"/market/level2:FET-BTC","type":"message"}
1619378328.353705: {"data":{"sequenceStart":1612712745588,"symbol":"FET-BTC","changes":{"asks":[["0.00000793","3343.2272","1612712745588"]],"bids":[]},"sequenceEnd":1612712745588},"subject":"trade.l2update","topic":"/market/level2:FET-BTC","type":"message"}
1619378328.371722: {"data":{"sequence":"1612701563923","bestAsk":"0.0000001126","size":"310.5072","bestBidSize":"163.8789","price":"0.0000001123","time":1619378328330,"bestAskSize":"361.2609","bestBid":"0.0000001115"},"subject":"trade.ticker","topic":"/market/ticker:DAPPT-BTC","type":"message"}
1619378328.371812: {"data":{"sequenceStart":1612844051710,"symbol":"SNX-BTC","changes":{"asks":[["0.00028712","0","1612844051710"]],"bids":[]},"sequenceEnd":1612844051710},"subject":"trade.l2update","topic":"/market/level2:SNX-BTC","type":"message"}
1619378328.374912: {"data":{"sequenceStart":1612734157738,"symbol":"ANKR-BTC","changes":{"asks":[["0.0000026189","4664.7644","1612734157738"]],"bids":[]},"sequenceEnd":1612734157738},"subject":"trade.l2update","topic":"/market/level2:ANKR-BTC","type":"message"}
1619378328.38675: {"data":{"sequenceStart":1613277184017,"symbol":"BCHSV-USDT","changes":{"asks":[],"bids":[["0","0","1613277184017"]]},"sequenceEnd":1613277184017},"subject":"trade.l2update","topic":"/market/level2:BCHSV-USDT","type":"message"}
1619378328.386858: {"data":{"sequenceStart":1613277184018,"symbol":"BCHSV-USDT","changes":{"asks":[],"bids":[["226.55","0.54","1613277184018"]]},"sequenceEnd":1613277184018},"subject":"trade.l2update","topic":"/market/level2:BCHSV-USDT","type":"message"}
1619378328.3869371: {"data":{"sequenceStart":1612844051711,"symbol":"SNX-BTC","changes":{"asks":[],"bids":[["0.00028654","0","1612844051711"]]},"sequenceEnd":1612844051711},"subject":"trade.l2update","topic":"/market/level2:SNX-BTC","type":"message"}
1619378328.399505: {"data":{"sequenceStart":1613277184019,"symbol":"BCHSV-USDT","changes":{"asks":[["243.277","0","1613277184019"]],"bids":[]},"sequenceEnd":1613277184019},"subject":"trade.l2update","topic":"/market/level2:BCHSV-USDT","type":"message"}
1619378328.399649: {"data":{"sequenceStart":1613277184020,"symbol":"BCHSV-USDT","changes":{"asks":[],"bids":[["0","0","1613277184020"]]},"sequenceEnd":1613277184020},"subject":"trade.l2update","topic":"/market/level2:BCHSV-USDT","type":"message"}
1619378328.399704: {"data":{"sequenceStart":1613277184021,"symbol":"BCHSV-USDT","changes":{"asks":[],"bids":[["241.579","5","1613277184021"]]},"sequenceEnd":1613277184021},"subject":"trade.l2update","topic":"/market/level2:BCHSV-USDT","type":"message"}
1619378328.3997922: {"data":{"sequenceStart":1613277184022,"symbol":"BCHSV-USDT","changes":{"asks":[["0","0","1613277184022"]],"bids":[]},"sequenceEnd":1613277184022},"subject":"trade.l2update","topic":"/market/level2:BCHSV-USDT","type":"message"}
1619378328.399818: {"data":{"sequenceStart":1613277184023,"symbol":"BCHSV-USDT","changes":{"asks":[["243.74","5","1613277184023"]],"bids":[]},"sequenceEnd":1613277184023},"subject":"trade.l2update","topic":"/market/level2:BCHSV-USDT","type":"message"}
1619378328.406404: {"data":{"sequenceStart":1613277184024,"symbol":"BCHSV-USDT","changes":{"asks":[["0","0","1613277184024"]],"bids":[]},"sequenceEnd":1613277184024},"subject":"trade.l2update","topic":"/market/level2:BCHSV-USDT","type":"message"}
1619378328.406513: {"data":{"sequenceStart":1613277184025,"symbol":"BCHSV-USDT","changes":{"asks":[["244.377","150","1613277184025"]],"bids":[]},"sequenceEnd":1613277184025},"subject":"trade.l2update","topic":"/market/level2:BCHSV-USDT","type":"message"}
1619378328.406594: {"data":{"sequenceStart":1613277184026,"symbol":"BCHSV-USDT","changes":{"asks":[["0","0","1613277184026"]],"bids":[]},"sequenceEnd":1613277184026},"subject":"trade.l2update","topic":"/market/level2:BCHSV-USDT","type":"message"}
1619378328.4066381: {"data":{"sequenceStart":1613277184027,"symbol":"BCHSV-USDT","changes":{"asks":[["243.244","0.6","1613277184027"]],"bids":[]},"sequenceEnd":1613277184027},"subject":"trade.l2update","topic":"/market/level2:BCHSV-USDT","type":"message"}
1619378328.409757: {"data":{"sequenceStart":1612694580146,"symbol":"CAPP-BTC","changes":{"asks":[],"bids":[["0.0000002087","0","1612694580146"]]},"sequenceEnd":1612694580146},"subject":"trade.l2update","topic":"/market/level2:CAPP-BTC","type":"message"}
1619378328.4099042: {"data":{"sequence":"1612712745588","bestAsk":"0.00000775","size":"401.2004","bestBidSize":"357.285","price":"0.00000772","time":1619378328368,"bestAskSize":"8025.7777","bestBid":"0.00000771"},"subject":"trade.ticker","topic":"/market/ticker:FET-BTC","type":"message"}
1619378328.419405: {"data":{"sequenceStart":1612844051712,"symbol":"SNX-BTC","changes":{"asks":[["0","0","1612844051712"]],"bids":[]},"sequenceEnd":1612844051712},"subject":"trade.l2update","topic":"/market/level2:SNX-BTC","type":"message"}
1619378328.4194822: {"data":{"sequenceStart":1612844051713,"symbol":"SNX-BTC","changes":{"asks":[["0.00028718","1.74226323","1612844051713"]],"bids":[]},"sequenceEnd":1612844051713},"subject":"trade.l2update","topic":"/market/level2:SNX-BTC","type":"message"}
1619378328.4195359: {"data":{"sequenceStart":1613277184028,"symbol":"BCHSV-USDT","changes":{"asks":[],"bids":[["0","0","1613277184028"]]},"sequenceEnd":1613277184028},"subject":"trade.l2update","topic":"/market/level2:BCHSV-USDT","type":"message"}
1619378328.419565: {"data":{"sequenceStart":1613277184029,"symbol":"BCHSV-USDT","changes":{"asks":[],"bids":[["240.945","150","1613277184029"]]},"sequenceEnd":1613277184029},"subject":"trade.l2update","topic":"/market/level2:BCHSV-USDT","type":"message"}
1619378328.433986: {"data":{"sequence":"1612734157738","bestAsk":"0.0000026189","size":"46","bestBidSize":"4051.2663","price":"0.0000026071","time":1619378328388,"bestAskSize":"4664.7644","bestBid":"0.0000026033"},"subject":"trade.ticker","topic":"/market/ticker:ANKR-BTC","type":"message"}
1619378328.4340758: {"data":{"sequence":"1612694580146","bestAsk":"0.0000002196","size":"1000.02","bestBidSize":"83.07","price":"0.0000002182","time":1619378328382,"bestAskSize":"330.25","bestBid":"0.0000002181"},"subject":"trade.ticker","topic":"/market/ticker:CAPP-BTC","type":"message"}
1619378328.4692018: {"data":{"sequence":"1613277184029","bestAsk":"242.851","size":"0.08000012","bestBidSize":"5","price":"243.65","time":1619378328431,"bestAskSize":"4.51280965","bestBid":"242.654"},"subject":"trade.ticker","topic":"/market/ticker:BCHSV-USDT","type":"message"}
1619378328.469293: {"data":{"sequenceStart":1612734157739,"symbol":"ANKR-BTC","changes":{"asks":[["0","0","1612734157739"]],"bids":[]},"sequenceEnd":1612734157739},"subject":"trade.l2update","topic":"/market/level2:ANKR-BTC","type":"message"}
1619378328.46936: {"data":{"sequenceStart":1612734157740,"symbol":"ANKR-BTC","changes":{"asks":[["0.0000026188","191.1686","1612734157740"]],"bids":[]},"sequenceEnd":1612734157740},"subject":"trade.l2update","topic":"/market/level2:ANKR-BTC","type":"message"}
1619378328.48368: {"data":{"sequence":"1612844051715","bestAsk":"0.00028718","size":"0.01745248","bestBidSize":"0.19100065","price":"0.00028676","time":1619378328446,"bestAskSize":"1.74226323","bestBid":"0.00028678"},"subject":"trade.ticker","topic":"/market/ticker:SNX-BTC","type":"message"}
1619378328.487679: {"data":{"sequenceStart":1612844051714,"symbol":"SNX-BTC","changes":{"asks":[],"bids":[["0","0","1612844051714"]]},"sequenceEnd":1612844051714},"subject":"trade.l2update","topic":"/market/level2:SNX-BTC","type":"message"}
1619378328.4877892: {"data":{"sequenceStart":1612844051715,"symbol":"SNX-BTC","changes":{"asks":[],"bids":[["0.00028655","2.1097563","1612844051715"]]},"sequenceEnd":1612844051715},"subject":"trade.l2update","topic":"/market/level2:SNX-BTC","type":"message"}
1619378328.487869: {"data":{"sequenceStart":1612734157741,"symbol":"ANKR-BTC","changes":{"asks":[["0.0000026189","0","1612734157741"]],"bids":[]},"sequenceEnd":1612734157741},"subject":"trade.l2update","topic":"/market/level2:ANKR-BTC","type":"message"}
1619378328.509553: {"data":{"sequenceStart":1612844051716,"symbol":"SNX-BTC","changes":{"asks":[],"bids":[["0.00028622","0","1612844051716"]]},"sequenceEnd":1612844051716},"subject":"trade.l2update","topic":"/market/level2:SNX-BTC","type":"message"}
1619378328.509692: {"data":{"sequenceStart":1612844051717,"symbol":"SNX-BTC","changes":{"asks":[],"bids":[["0.00028586","0","1612844051717"]]},"sequenceEnd":1612844051717},"subject":"trade.l2update","topic":"/market/level2:SNX-BTC","type":"message"}
1619378328.528411: {"data":{"sequenceStart":1612734157742,"symbol":"ANKR-BTC","changes":{"asks":[["0","0","1612734157742"]],"bids":[]},"sequenceEnd":1612734157742},"subject":"trade.l2update","topic":"/market/level2:ANKR-BTC","type":"message"}
1619378328.528524: {"data":{"sequenceStart":1612734157743,"symbol":"ANKR-BTC","changes":{"asks":[["0.0000026187","4664.7644","1612734157743"]],"bids":[]},"sequenceEnd":1612734157743},"subject":"trade.l2update","topic":"/market/level2:ANKR-BTC","type":"message"}
1619378328.52863: {"data":{"sequence":"1612734157743","bestAsk":"0.0000026187","size":"46","bestBidSize":"4051.2663","price":"0.0000026071","time":1619378328488,"bestAskSize":"4664.7644","bestBid":"0.0000026033"},"subject":"trade.ticker","topic":"/market/ticker:ANKR-BTC","type":"message"}
1619378328.541376: {"data":{"sequenceStart":1612844051718,"symbol":"SNX-BTC","changes":{"asks":[],"bids":[["0.00028281","0","1612844051718"]]},"sequenceEnd":1612844051718},"subject":"trade.l2update","topic":"/market/level2:SNX-BTC","type":"message"}
1619378328.5435252: {"data":{"sequenceStart":1612734157744,"symbol":"ANKR-BTC","changes":{"asks":[["0.0000026188","0","1612734157744"]],"bids":[]},"sequenceEnd":1612734157744},"subject":"trade.l2update","topic":"/market/level2:ANKR-BTC","type":"message"}
1619378328.543672: {"data":{"sequenceStart":1612844051719,"symbol":"SNX-BTC","changes":{"asks":[["0.00028718","0","1612844051719"]],"bids":[]},"sequenceEnd":1612844051719},"subject":"trade.l2update","topic":"/market/level2:SNX-BTC","type":"message"}
1619378328.579442: {"data":{"sequence":"1612844051719","bestAsk":"0.00028719","size":"0.01745248","bestBidSize":"0.19100065","price":"0.00028676","time":1619378328546,"bestAskSize":"73.32024488","bestBid":"0.00028678"},"subject":"trade.ticker","topic":"/market/ticker:SNX-BTC","type":"message"}
1619378328.589699: {"data":{"sequenceStart":1612844051720,"symbol":"SNX-BTC","changes":{"asks":[["0.00029399","164.52403098","1612844051720"]],"bids":[]},"sequenceEnd":1612844051720},"subject":"trade.l2update","topic":"/market/level2:SNX-BTC","type":"message"}
1619378328.595565: {"data":{"sequenceStart":1613277184030,"symbol":"BCHSV-USDT","changes":{"asks":[],"bids":[["242.651","0","1613277184030"]]},"sequenceEnd":1613277184030},"subject":"trade.l2update","topic":"/market/level2:BCHSV-USDT","type":"message"}
1619378328.595671: {"data":{"sequenceStart":1613277184031,"symbol":"BCHSV-USDT","changes":{"asks":[["243.244","0","1613277184031"]],"bids":[]},"sequenceEnd":1613277184031},"subject":"trade.l2update","topic":"/market/level2:BCHSV-USDT","type":"message"}
1619378328.595741: {"data":{"sequenceStart":1613277184032,"symbol":"BCHSV-USDT","changes":{"asks":[["243.063","2.99","1613277184032"]],"bids":[]},"sequenceEnd":1613277184032},"subject":"trade.l2update","topic":"/market/level2:BCHSV-USDT","type":"message"}
1619378328.595791: {"data":{"sequenceStart":1612699351244,"symbol":"COV-BTC","changes":{"asks":[],"bids":[["0.0000111","10","1612699351244"]]},"sequenceEnd":1612699351244},"subject":"trade.l2update","topic":"/market/level2:COV-BTC","type":"message"}
1619378328.6052868: {"data":{"sequenceStart":1612734157745,"symbol":"ANKR-BTC","changes":{"asks":[["0","0","1612734157745"]],"bids":[]},"sequenceEnd":1612734157745},"subject":"trade.l2update","topic":"/market/level2:ANKR-BTC","type":"message"}
1619378328.605398: {"data":{"sequenceStart":1612734157746,"symbol":"ANKR-BTC","changes":{"asks":[["0.0000026186","191.1686","1612734157746"]],"bids":[]},"sequenceEnd":1612734157746},"subject":"trade.l2update","topic":"/market/level2:ANKR-BTC","type":"message"}
1619378328.605482: {"data":{"sequenceStart":1613277184033,"symbol":"BCHSV-USDT","changes":{"asks":[["0","0","1613277184033"]],"bids":[]},"sequenceEnd":1613277184033},"subject":"trade.l2update","topic":"/market/level2:BCHSV-USDT","type":"message"}
1619378328.605527: {"data":{"sequenceStart":1613277184034,"symbol":"BCHSV-USDT","changes":{"asks":[["243.243","0.6","1613277184034"]],"bids":[]},"sequenceEnd":1613277184034},"subject":"trade.l2update","topic":"/market/level2:BCHSV-USDT","type":"message"}
1619378328.60559: {"data":{"sequenceStart":1613277184035,"symbol":"BCHSV-USDT","changes":{"asks":[["243.063","0","1613277184035"]],"bids":[]},"sequenceEnd":1613277184035},"subject":"trade.l2update","topic":"/market/level2:BCHSV-USDT","type":"message"}
1619378328.612536: {"data":{"sequenceStart":1613277184036,"symbol":"BCHSV-USDT","changes":{"asks":[],"bids":[["0","0","1613277184036"]]},"sequenceEnd":1613277184036},"subject":"trade.l2update","topic":"/market/level2:BCHSV-USDT","type":"message"}
1619378328.6126: {"data":{"sequenceStart":1613277184037,"symbol":"BCHSV-USDT","changes":{"asks":[],"bids":[["242.639","0.68148185","1613277184037"]]},"sequenceEnd":1613277184037},"subject":"trade.l2update","topic":"/market/level2:BCHSV-USDT","type":"message"}
1619378328.612643: {"data":{"sequenceStart":1612844051721,"symbol":"SNX-BTC","changes":{"asks":[["0","0","1612844051721"]],"bids":[]},"sequenceEnd":1612844051721},"subject":"trade.l2update","topic":"/market/level2:SNX-BTC","type":"message"}
1619378328.6126661: {"data":{"sequenceStart":1612844051722,"symbol":"SNX-BTC","changes":{"asks":[["0.00028718","1.74226323","1612844051722"]],"bids":[]},"sequenceEnd":1612844051722},"subject":"trade.l2update","topic":"/market/level2:SNX-BTC","type":"message"}
1619378328.628087: {"data":{"sequence":"1612734157746","bestAsk":"0.0000026186","size":"46","bestBidSize":"4051.2663","price":"0.0000026071","time":1619378328588,"bestAskSize":"191.1686","bestBid":"0.0000026033"},"subject":"trade.ticker","topic":"/market/ticker:ANKR-BTC","type":"message"}
1619378328.62818: {"data":{"sequence":"1612699351244","bestAsk":"0.00001127","size":"96.1525","bestBidSize":"49.6422","price":"0.00001126","time":1619378328588,"bestAskSize":"4331.68226035","bestBid":"0.00001121"},"subject":"trade.ticker","topic":"/market/ticker:COV-BTC","type":"message"}
1619378328.637696: {"data":{"sequenceStart":1612734157747,"symbol":"ANKR-BTC","changes":{"asks":[],"bids":[["0.0000026015","0","1612734157747"]]},"sequenceEnd":1612734157747},"subject":"trade.l2update","topic":"/market/level2:ANKR-BTC","type":"message"}
1619378328.643168: {"data":{"sequenceStart":1613277184038,"symbol":"BCHSV-USDT","changes":{"asks":[["0","0","1613277184038"]],"bids":[]},"sequenceEnd":1613277184038},"subject":"trade.l2update","topic":"/market/level2:BCHSV-USDT","type":"message"}
1619378328.643245: {"data":{"sequenceStart":1613277184039,"symbol":"BCHSV-USDT","changes":{"asks":[["243.036","2.99","1613277184039"]],"bids":[]},"sequenceEnd":1613277184039},"subject":"trade.l2update","topic":"/market/level2:BCHSV-USDT","type":"message"}
1619378328.6596322: {"data":{"sequenceStart":1613277184040,"symbol":"BCHSV-USDT","changes":{"asks":[],"bids":[["242.654","0","1613277184040"]]},"sequenceEnd":1613277184040},"subject":"trade.l2update","topic":"/market/level2:BCHSV-USDT","type":"message"}
1619378328.669566: {"data":{"sequenceStart":1612699351245,"symbol":"COV-BTC","changes":{"asks":[],"bids":[["0","0","1612699351245"]]},"sequenceEnd":1612699351245},"subject":"trade.l2update","topic":"/market/level2:COV-BTC","type":"message"}
1619378328.669676: {"data":{"sequenceStart":1612699351246,"symbol":"COV-BTC","changes":{"asks":[],"bids":[["0.00001092","188.4121","1612699351246"]]},"sequenceEnd":1612699351246},"subject":"trade.l2update","topic":"/market/level2:COV-BTC","type":"message"}
1619378328.669742: {"data":{"sequence":"1613277184040","bestAsk":"242.851","size":"0.08000012","bestBidSize":"0.68148185","price":"243.65","time":1619378328631,"bestAskSize":"4.51280965","bestBid":"242.639"},"subject":"trade.ticker","topic":"/market/ticker:BCHSV-USDT","type":"message"}
1619378328.669785: {"data":{"sequenceStart":1612844051723,"symbol":"SNX-BTC","changes":{"asks":[],"bids":[["0","0","1612844051723"]]},"sequenceEnd":1612844051723},"subject":"trade.l2update","topic":"/market/level2:SNX-BTC","type":"message"}
1619378328.669835: {"data":{"sequenceStart":1612844051724,"symbol":"SNX-BTC","changes":{"asks":[],"bids":[["0.00028608","73.43333533","1612844051724"]]},"sequenceEnd":1612844051724},"subject":"trade.l2update","topic":"/market/level2:SNX-BTC","type":"message"}
1619378328.674175: {"data":{"sequenceStart":1613277184041,"symbol":"BCHSV-USDT","changes":{"asks":[],"bids":[["0","0","1613277184041"]]},"sequenceEnd":1613277184041},"subject":"trade.l2update","topic":"/market/level2:BCHSV-USDT","type":"message"}
1619378328.674284: {"data":{"sequenceStart":1613277184042,"symbol":"BCHSV-USDT","changes":{"asks":[],"bids":[["242.642","5","1613277184042"]]},"sequenceEnd":1613277184042},"subject":"trade.l2update","topic":"/market/level2:BCHSV-USDT","type":"message"}
1619378328.679786: {"data":{"sequence":"1612844051724","bestAsk":"0.00028718","size":"0.01745248","bestBidSize":"0.19100065","price":"0.00028676","time":1619378328645,"bestAskSize":"1.74226323","bestBid":"0.00028678"},"subject":"trade.ticker","topic":"/market/ticker:SNX-BTC","type":"message"}
1619378328.6850822: {"data":{"sequenceStart":1613277184043,"symbol":"BCHSV-USDT","changes":{"asks":[],"bids":[["242.639","0","1613277184043"]]},"sequenceEnd":1613277184043},"subject":"trade.l2update","topic":"/market/level2:BCHSV-USDT","type":"message"}
1619378328.6954088: {"data":{"sequenceStart":1613277184044,"symbol":"BCHSV-USDT","changes":{"asks":[],"bids":[["0","0","1613277184044"]]},"sequenceEnd":1613277184044},"subject":"trade.l2update","topic":"/market/level2:BCHSV-USDT","type":"message"}
1619378328.69913: {"data":{"sequenceStart":1613277184045,"symbol":"BCHSV-USDT","changes":{"asks":[],"bids":[["240.294","2.08078435","1613277184045"]]},"sequenceEnd":1613277184045},"subject":"trade.l2update","topic":"/market/level2:BCHSV-USDT","type":"message"}
1619378328.699266: {"data":{"sequenceStart":1613277184046,"symbol":"BCHSV-USDT","changes":{"asks":[["0","0","1613277184046"]],"bids":[]},"sequenceEnd":1613277184046},"subject":"trade.l2update","topic":"/market/level2:BCHSV-USDT","type":"message"}
1619378328.69932: {"data":{"sequenceStart":1613277184047,"symbol":"BCHSV-USDT","changes":{"asks":[["243.036","5.98","1613277184047"]],"bids":[]},"sequenceEnd":1613277184047},"subject":"trade.l2update","topic":"/market/level2:BCHSV-USDT","type":"message"}
1619378328.703538: {"data":{"sequenceStart":1613277184048,"symbol":"BCHSV-USDT","changes":{"asks":[],"bids":[["0","0","1613277184048"]]},"sequenceEnd":1613277184048},"subject":"trade.l2update","topic":"/market/level2:BCHSV-USDT","type":"message"}
1619378328.703649: {"data":{"sequenceStart":1613277184049,"symbol":"BCHSV-USDT","changes":{"asks":[],"bids":[["242.64","0.68148185","1613277184049"]]},"sequenceEnd":1613277184049},"subject":"trade.l2update","topic":"/market/level2:BCHSV-USDT","type":"message"}
1619378328.723016: {"data":{"sequenceStart":1613277184050,"symbol":"BCHSV-USDT","changes":{"asks":[],"bids":[["0","0","1613277184050"]]},"sequenceEnd":1613277184050},"subject":"trade.l2update","topic":"/market/level2:BCHSV-USDT","type":"message"}
1619378328.723125: {"data":{"sequenceStart":1613277184051,"symbol":"BCHSV-USDT","changes":{"asks":[],"bids":[["242.532","0.10226994","1613277184051"]]},"sequenceEnd":1613277184051},"subject":"trade.l2update","topic":"/market/level2:BCHSV-USDT","type":"message"}
1619378328.7272818: {"data":{"sequence":"1612734157747","bestAsk":"0.0000026186","size":"46","bestBidSize":"4051.2663","price":"0.0000026071","time":1619378328688,"bestAskSize":"191.1686","bestBid":"0.0000026033"},"subject":"trade.ticker","topic":"/market/ticker:ANKR-BTC","type":"message"}
1619378328.727372: {"data":{"sequence":"1612699351246","bestAsk":"0.00001127","size":"96.1525","bestBidSize":"49.6422","price":"0.00001126","time":1619378328688,"bestAskSize":"4331.68226035","bestBid":"0.00001121"},"subject":"trade.ticker","topic":"/market/ticker:COV-BTC","type":"message"}
1619378328.74772: {"data":{"sequenceStart":1613277184052,"symbol":"BCHSV-USDT","changes":{"asks":[],"bids":[["242.532","0","1613277184052"]]},"sequenceEnd":1613277184052},"subject":"trade.l2update","topic":"/market/level2:BCHSV-USDT","type":"message"}
1619378328.7704399: {"data":{"sequenceStart":1612701563924,"symbol":"DAPPT-BTC","changes":{"asks":[],"bids":[["0.0000001091","361.2609","1612701563924"]]},"sequenceEnd":1612701563924},"subject":"trade.l2update","topic":"/market/level2:DAPPT-BTC","type":"message"}
1619378328.770517: {"data":{"sequence":"1613277184054","bestAsk":"242.851","size":"0.08000012","bestBidSize":"5","price":"243.65","time":1619378328731,"bestAskSize":"4.51280965","bestBid":"242.642"},"subject":"trade.ticker","topic":"/market/ticker:BCHSV-USDT","type":"message"}
1619378328.770541: {"data":{"sequenceStart":1613277184053,"symbol":"BCHSV-USDT","changes":{"asks":[["0","0","1613277184053"]],"bids":[]},"sequenceEnd":1613277184053},"subject":"trade.l2update","topic":"/market/level2:BCHSV-USDT","type":"message"}
1619378328.770565: {"data":{"sequenceStart":1613277184054,"symbol":"BCHSV-USDT","changes":{"asks":[["245.634","17.79999999","1613277184054"]],"bids":[]},"sequenceEnd":1613277184054},"subject":"trade.l2update","topic":"/market/level2:BCHSV-USDT","type":"message"}
1619378328.770598: {"data":{"sequence":"1612701563924","bestAsk":"0.0000001126","size":"310.5072","bestBidSize":"163.8789","price":"0.0000001123","time":1619378328730,"bestAskSize":"361.2609","bestBid":"0.0000001115"},"subject":"trade.ticker","topic":"/market/ticker:DAPPT-BTC","type":"message"}
1619378328.821346: {"data":{"sequenceStart":1612844051725,"symbol":"SNX-BTC","changes":{"asks":[],"bids":[["0","0","1612844051725"]]},"sequenceEnd":1612844051725},"subject":"trade.l2update","topic":"/market/level2:SNX-BTC","type":"message"}
1619378328.821464: {"data":{"sequenceStart":1612844051726,"symbol":"SNX-BTC","changes":{"asks":[],"bids":[["0.00028583","257.02380209","1612844051726"]]},"sequenceEnd":1612844051726},"subject":"trade.l2update","topic":"/market/level2:SNX-BTC","type":"message"}
1619378328.8215501: {"data":{"sequenceStart":1613277184055,"symbol":"BCHSV-USDT","changes":{"asks":[],"bids":[["241.579","0","1613277184055"]]},"sequenceEnd":1613277184055},"subject":"trade.l2update","topic":"/market/level2:BCHSV-USDT","type":"message"}
1619378328.821594: {"data":{"sequenceStart":1613277184056,"symbol":"BCHSV-USDT","changes":{"asks":[["243.74","0","1613277184056"]],"bids":[]},"sequenceEnd":1613277184056},"subject":"trade.l2update","topic":"/market/level2:BCHSV-USDT","type":"message"}
1619378328.821633: {"data":{"sequenceStart":1613277184057,"symbol":"BCHSV-USDT","changes":{"asks":[["244.377","0","1613277184057"]],"bids":[]},"sequenceEnd":1613277184057},"subject":"trade.l2update","topic":"/market/level2:BCHSV-USDT","type":"message"}
1619378328.821666: {"data":{"sequenceStart":1613277184058,"symbol":"BCHSV-USDT","changes":{"asks":[],"bids":[["240.945","0","1613277184058"]]},"sequenceEnd":1613277184058},"subject":"trade.l2update","topic":"/market/level2:BCHSV-USDT","type":"message"}
1619378328.857688: {"data":{"sequence":"1612844051726","bestAsk":"0.00028718","size":"0.01745248","bestBidSize":"0.19100065","price":"0.00028676","time":1619378328823,"bestAskSize":"1.74226323","bestBid":"0.00028678"},"subject":"trade.ticker","topic":"/market/ticker:SNX-BTC","type":"message"}
1619378328.866884: {"data":{"symbol":"DAPPT-BTC","candles":["1619378220","0.0000001116","0.0000001116","0.0000001116","0.0000001116","0","0"],"time":1619378328806000034},"subject":"trade.candles.add","topic":"/market/candles:DAPPT-BTC_1min","type":"message"}
1619378328.867116: {"data":{"symbol":"DAPPT-BTC","candles":["1619378280","0.0000001117","0.0000001123","0.0000001123","0.0000001117","3437.9375","0.00038556424505"],"time":1619378328806720268},"subject":"trade.candles.add","topic":"/market/candles:DAPPT-BTC_1min","type":"message"}
1619378328.877732: {"data":{"sequence":"1613277184058","bestAsk":"242.851","size":"0.08000012","bestBidSize":"5","price":"243.65","time":1619378328832,"bestAskSize":"4.51280965","bestBid":"242.642"},"subject":"trade.ticker","topic":"/market/ticker:BCHSV-USDT","type":"message"}
1619378328.882905: {"data":{"sequenceStart":1613277184059,"symbol":"BCHSV-USDT","changes":{"asks":[["243.243","0","1613277184059"]],"bids":[]},"sequenceEnd":1613277184059},"subject":"trade.l2update","topic":"/market/level2:BCHSV-USDT","type":"message"}
1619378328.913493: {"data":{"sequenceStart":1613277184060,"symbol":"BCHSV-USDT","changes":{"asks":[["0","0","1613277184060"]],"bids":[]},"sequenceEnd":1613277184060},"subject":"trade.l2update","topic":"/market/level2:BCHSV-USDT","type":"message"}
1619378328.913604: {"data":{"sequenceStart":1613277184061,"symbol":"BCHSV-USDT","changes":{"asks":[["243.241","0.6","1613277184061"]],"bids":[]},"sequenceEnd":1613277184061},"subject":"trade.l2update","topic":"/market/level2:BCHSV-USDT","type":"message"}
1619378328.933863: {"data":{"sequenceStart":1612701563925,"symbol":"DAPPT-BTC","changes":{"asks":[],"bids":[["0","0","1612701563925"]]},"sequenceEnd":1612701563925},"subject":"trade.l2update","topic":"/market/level2:DAPPT-BTC","type":"message"}
1619378328.933973: {"data":{"sequenceStart":1612701563926,"symbol":"DAPPT-BTC","changes":{"asks":[],"bids":[["0.0000001115","6613.8789","1612701563926"]]},"sequenceEnd":1612701563926},"subject":"trade.l2update","topic":"/market/level2:DAPPT-BTC","type":"message"}
1619378328.934038: {"data":{"sequenceStart":1612694580147,"symbol":"CAPP-BTC","changes":{"asks":[],"bids":[["0.0000002103","0","1612694580147"]]},"sequenceEnd":1612694580147},"subject":"trade.l2update","topic":"/market/level2:CAPP-BTC","type":"message"}
1619378328.953022: {"data":{"sequenceStart":1612844051727,"symbol":"SNX-BTC","changes":{"asks":[["0","0","1612844051727"]],"bids":[]},"sequenceEnd":1612844051727},"subject":"trade.l2update","topic":"/market/level2:SNX-BTC","type":"message"}
1619378328.9531362: {"data":{"sequenceStart":1612844051728,"symbol":"SNX-BTC","changes":{"asks":[["0.00029096","765.40500797","1612844051728"]],"bids":[]},"sequenceEnd":1612844051728},"subject":"trade.l2update","topic":"/market/level2:SNX-BTC","type":"message"}
1619378328.9661949: {"data":{"sequenceStart":1612699351247,"symbol":"COV-BTC","changes":{"asks":[],"bids":[["0.00001095","10","1612699351247"]]},"sequenceEnd":1612699351247},"subject":"trade.l2update","topic":"/market/level2:COV-BTC","type":"message"}
1619378328.966314: {"data":{"sequenceStart":1612699351248,"symbol":"COV-BTC","changes":{"asks":[],"bids":[["0","0","1612699351248"]]},"sequenceEnd":1612699351248},"subject":"trade.l2update","topic":"/market/level2:COV-BTC","type":"message"}
1619378328.966367: {"data":{"sequenceStart":1612699351249,"symbol":"COV-BTC","changes":{"asks":[],"bids":[["0.00001109","68.6113","1612699351249"]]},"sequenceEnd":1612699351249},"subject":"trade.l2update","topic":"/market/level2:COV-BTC","type":"message"}
1619378328.9664152: {"data":{"sequence":"1612701563926","bestAsk":"0.0000001126","size":"310.5072","bestBidSize":"6613.8789","price":"0.0000001123","time":1619378328930,"bestAskSize":"361.2609","bestBid":"0.0000001115"},"subject":"trade.ticker","topic":"/market/ticker:DAPPT-BTC","type":"message"}
1619378328.972631: {"data":{"sequenceStart":1612702190315,"symbol":"NRG-BTC","changes":{"asks":[],"bids":[["0","0","1612702190315"]]},"sequenceEnd":1612702190315},"subject":"trade.l2update","topic":"/market/level2:NRG-BTC","type":"message"}
1619378328.9727411: {"data":{"sequenceStart":1612702190316,"symbol":"NRG-BTC","changes":{"asks":[],"bids":[["0.00006005","133.6381","1612702190316"]]},"sequenceEnd":1612702190316},"subject":"trade.l2update","topic":"/market/level2:NRG-BTC","type":"message"}
1619378328.972807: {"data":{"sequence":"1613277184061","bestAsk":"242.851","size":"0.08000012","bestBidSize":"5","price":"243.65","time":1619378328933,"bestAskSize":"4.51280965","bestBid":"242.642"},"subject":"trade.ticker","topic":"/market/ticker:BCHSV-USDT","type":"message"}
1619378328.986696: {"data":{"sequence":"1612844051728","bestAsk":"0.00028718","size":"0.01745248","bestBidSize":"0.19100065","price":"0.00028676","time":1619378328945,"bestAskSize":"1.74226323","bestBid":"0.00028678"},"subject":"trade.ticker","topic":"/market/ticker:SNX-BTC","type":"message"}
1619378328.99197: {"data":{"sequenceStart":1612844051729,"symbol":"SNX-BTC","changes":{"asks":[["0","0","1612844051729"]],"bids":[]},"sequenceEnd":1612844051729},"subject":"trade.l2update","topic":"/market/level2:SNX-BTC","type":"message"}
1619378328.99208: {"data":{"sequenceStart":1612844051730,"symbol":"SNX-BTC","changes":{"asks":[["0.0002872","29.24570683","1612844051730"]],"bids":[]},"sequenceEnd":1612844051730},"subject":"trade.l2update","topic":"/market/level2:SNX-BTC","type":"message"}
1619378329.009579: {"data":{"sequenceStart":1612694580148,"symbol":"CAPP-BTC","changes":{"asks":[["0","0","1612694580148"]],"bids":[]},"sequenceEnd":1612694580148},"subject":"trade.l2update","topic":"/market/level2:CAPP-BTC","type":"message"}
1619378329.009689: {"data":{"sequenceStart":1612694580149,"symbol":"CAPP-BTC","changes":{"asks":[["0.0000002197","4895.9","1612694580149"]],"bids":[]},"sequenceEnd":1612694580149},"subject":"trade.l2update","topic":"/market/level2:CAPP-BTC","type":"message"}
1619378329.022094: {"data":{"sequence":"1612694580149","bestAsk":"0.0000002196","size":"1000.02","bestBidSize":"83.07","price":"0.0000002182","time":1619378328981,"bestAskSize":"330.25","bestBid":"0.0000002181"},"subject":"trade.ticker","topic":"/market/ticker:CAPP-BTC","type":"message"}
1619378329.0273652: {"data":{"sequence":"1612699351249","bestAsk":"0.00001127","size":"96.1525","bestBidSize":"49.6422","price":"0.00001126","time":1619378328988,"bestAskSize":"4331.68226035","bestBid":"0.00001121"},"subject":"trade.ticker","topic":"/market/ticker:COV-BTC","type":"message"}
1619378329.032063: {"data":{"sequence":"1612702190316","bestAsk":"0.00006218","size":"0.0431","bestBidSize":"19.5017","price":"0.00006141","time":1619378328991,"bestAskSize":"43.3399","bestBid":"0.00006141"},"subject":"trade.ticker","topic":"/market/ticker:NRG-BTC","type":"message"}
1619378329.0321531: {"data":{"sequenceStart":1612702190317,"symbol":"NRG-BTC","changes":{"asks":[],"bids":[["0","0","1612702190317"]]},"sequenceEnd":1612702190317},"subject":"trade.l2update","topic":"/market/level2:NRG-BTC","type":"message"}
1619378329.03222: {"data":{"sequenceStart":1612702190318,"symbol":"NRG-BTC","changes":{"asks":[],"bids":[["0.00006073","11.182","1612702190318"]]},"sequenceEnd":1612702190318},"subject":"trade.l2update","topic":"/market/level2:NRG-BTC","type":"message"}
1619378329.0699: {"data":{"sequenceStart":1612701563927,"symbol":"DAPPT-BTC","changes":{"asks":[],"bids":[["0.0000001089","0","1612701563927"]]},"sequenceEnd":1612701563927},"subject":"trade.l2update","topic":"/market/level2:DAPPT-BTC","type":"message"}
1619378329.080192: {"data":{"sequence":"1612844051731","bestAsk":"0.00028718","size":"0.01745248","bestBidSize":"0.19100065","price":"0.00028676","time":1619378329046,"bestAskSize":"1.74226323","bestBid":"0.00028678"},"subject":"trade.ticker","topic":"/market/ticker:SNX-BTC","type":"message"}
1619378329.080248: {"data":{"sequenceStart":1612844051731,"symbol":"SNX-BTC","changes":{"asks":[["0.00028732","0","1612844051731"]],"bids":[]},"sequenceEnd":1612844051731},"subject":"trade.l2update","topic":"/market/level2:SNX-BTC","type":"message"}
1619378329.1095521: {"data":{"sequenceStart":1612844051732,"symbol":"SNX-BTC","changes":{"asks":[["0.0002872","0","1612844051732"]],"bids":[]},"sequenceEnd":1612844051732},"subject":"trade.l2update","topic":"/market/level2:SNX-BTC","type":"message"}
1619378329.1096509: {"data":{"sequenceStart":1612844051733,"symbol":"SNX-BTC","changes":{"asks":[],"bids":[["0.00028583","0","1612844051733"]]},"sequenceEnd":1612844051733},"subject":"trade.l2update","topic":"/market/level2:SNX-BTC","type":"message"}
1619378329.129612: {"data":{"sequenceStart":1612844051734,"symbol":"SNX-BTC","changes":{"asks":[["0","0","1612844051734"]],"bids":[]},"sequenceEnd":1612844051734},"subject":"trade.l2update","topic":"/market/level2:SNX-BTC","type":"message"}
1619378329.1297238: {"data":{"sequenceStart":1612844051735,"symbol":"SNX-BTC","changes":{"asks":[["0.00028717","29.24570683","1612844051735"]],"bids":[]},"sequenceEnd":1612844051735},"subject":"trade.l2update","topic":"/market/level2:SNX-BTC","type":"message"}
1619378329.130871: {"data":{"sequence":"1612702190318","bestAsk":"0.00006218","size":"0.0431","bestBidSize":"19.5017","price":"0.00006141","time":1619378329091,"bestAskSize":"43.3399","bestBid":"0.00006141"},"subject":"trade.ticker","topic":"/market/ticker:NRG-BTC","type":"message"}
1619378329.152391: {"data":{"sequenceStart":1612844051736,"symbol":"SNX-BTC","changes":{"asks":[["0","0","1612844051736"]],"bids":[]},"sequenceEnd":1612844051736},"subject":"trade.l2update","topic":"/market/level2:SNX-BTC","type":"message"}
1619378329.152504: {"data":{"sequenceStart":1612844051737,"symbol":"SNX-BTC","changes":{"asks":[["0.00028734","4.87767305","1612844051737"]],"bids":[]},"sequenceEnd":1612844051737},"subject":"trade.l2update","topic":"/market/level2:SNX-BTC","type":"message"}
1619378329.156984: {"data":{"sequenceStart":1613277184062,"symbol":"BCHSV-USDT","changes":{"asks":[["243.005","0","1613277184062"]],"bids":[]},"sequenceEnd":1613277184062},"subject":"trade.l2update","topic":"/market/level2:BCHSV-USDT","type":"message"}
1619378329.162876: {"data":{"sequenceStart":1612701563928,"symbol":"DAPPT-BTC","changes":{"asks":[],"bids":[["0","0","1612701563928"]]},"sequenceEnd":1612701563928},"subject":"trade.l2update","topic":"/market/level2:DAPPT-BTC","type":"message"}
1619378329.162984: {"data":{"sequenceStart":1612701563929,"symbol":"DAPPT-BTC","changes":{"asks":[],"bids":[["0.0000001092","387646.2426","1612701563929"]]},"sequenceEnd":1612701563929},"subject":"trade.l2update","topic":"/market/level2:DAPPT-BTC","type":"message"}
1619378329.1675048: {"data":{"sequenceStart":1613277184063,"symbol":"BCHSV-USDT","changes":{"asks":[["245.634","0","1613277184063"]],"bids":[]},"sequenceEnd":1613277184063},"subject":"trade.l2update","topic":"/market/level2:BCHSV-USDT","type":"message"}
1619378329.173882: {"data":{"sequence":"1612701563929","bestAsk":"0.0000001126","size":"310.5072","bestBidSize":"6613.8789","price":"0.0000001123","time":1619378329130,"bestAskSize":"361.2609","bestBid":"0.0000001115"},"subject":"trade.ticker","topic":"/market/ticker:DAPPT-BTC","type":"message"}
1619378329.1739762: {"data":{"sequence":"1613277184063","bestAsk":"242.851","size":"0.08000012","bestBidSize":"5","price":"243.65","time":1619378329130,"bestAskSize":"4.51280965","bestBid":"242.642"},"subject":"trade.ticker","topic":"/market/ticker:BCHSV-USDT","type":"message"}
1619378329.174028: {"data":{"sequenceStart":1612844051738,"symbol":"SNX-BTC","changes":{"asks":[["0.00028734","0","1612844051738"]],"bids":[]},"sequenceEnd":1612844051738},"subject":"trade.l2update","topic":"/market/level2:SNX-BTC","type":"message"}
1619378329.178592: {"data":{"sequenceStart":1613277184064,"symbol":"BCHSV-USDT","changes":{"asks":[],"bids":[["240.294","0","1613277184064"]]},"sequenceEnd":1613277184064},"subject":"trade.l2update","topic":"/market/level2:BCHSV-USDT","type":"message"}
1619378329.1871161: {"data":{"sequence":"1612844051738","bestAsk":"0.00028717","size":"0.01745248","bestBidSize":"0.19100065","price":"0.00028676","time":1619378329147,"bestAskSize":"29.24570683","bestBid":"0.00028678"},"subject":"trade.ticker","topic":"/market/ticker:SNX-BTC","type":"message"}
1619378329.187207: {"data":{"sequenceStart":1613277184065,"symbol":"BCHSV-USDT","changes":{"asks":[["243.241","0","1613277184065"]],"bids":[]},"sequenceEnd":1613277184065},"subject":"trade.l2update","topic":"/market/level2:BCHSV-USDT","type":"message"}
1619378329.2025962: {"data":{"sequenceStart":1613277184066,"symbol":"BCHSV-USDT","changes":{"asks":[["0","0","1613277184066"]],"bids":[]},"sequenceEnd":1613277184066},"subject":"trade.l2update","topic":"/market/level2:BCHSV-USDT","type":"message"}
1619378329.202708: {"data":{"sequenceStart":1613277184067,"symbol":"BCHSV-USDT","changes":{"asks":[["243.242","0.6","1613277184067"]],"bids":[]},"sequenceEnd":1613277184067},"subject":"trade.l2update","topic":"/market/level2:BCHSV-USDT","type":"message"}
1619378329.2187672: {"data":{"sequenceStart":1612844051739,"symbol":"SNX-BTC","changes":{"asks":[],"bids":[["0","0","1612844051739"]]},"sequenceEnd":1612844051739},"subject":"trade.l2update","topic":"/market/level2:SNX-BTC","type":"message"}
1619378329.218878: {"data":{"sequenceStart":1612844051740,"symbol":"SNX-BTC","changes":{"asks":[],"bids":[["0.00028576","257.07331975","1612844051740"]]},"sequenceEnd":1612844051740},"subject":"trade.l2update","topic":"/market/level2:SNX-BTC","type":"message"}
1619378329.2508109: {"data":{"sequenceStart":1619079123933,"symbol":"EQZ-BTC","changes":{"asks":[],"bids":[["0","0","1619079123933"]]},"sequenceEnd":1619079123933},"subject":"trade.l2update","topic":"/market/level2:EQZ-BTC","type":"message"}
1619378330.0161269: {"data":{"sequenceStart":1619079123934,"symbol":"EQZ-BTC","changes":{"asks":[],"bids":[["0.00002369","41","1619079123934"]]},"sequenceEnd":1619079123934},"subject":"trade.l2update","topic":"/market/level2:EQZ-BTC","type":"message"}
1619378330.0161788: {"data":{"sequence":"1612844051740","bestAsk":"0.00028717","size":"0.01745248","bestBidSize":"0.19100065","price":"0.00028676","time":1619378329223,"bestAskSize":"29.24570683","bestBid":"0.00028678"},"subject":"trade.ticker","topic":"/market/ticker:SNX-BTC","type":"message"}
1619378330.016204: {"data":{"sequenceStart":1612702190319,"symbol":"NRG-BTC","changes":{"asks":[],"bids":[["0.00005969","2.5129","1612702190319"]]},"sequenceEnd":1612702190319},"subject":"trade.l2update","topic":"/market/level2:NRG-BTC","type":"message"}
1619378330.0162292: {"data":{"sequence":"1613277184067","bestAsk":"242.851","size":"0.08000012","bestBidSize":"5","price":"243.65","time":1619378329231,"bestAskSize":"4.51280965","bestBid":"242.642"},"subject":"trade.ticker","topic":"/market/ticker:BCHSV-USDT","type":"message"}
1619378330.016246: {"data":{"sequence":"1619079123934","bestAsk":"0.00002395","size":"0.375","bestBidSize":"20.5373","price":"0.00002383","time":1619378329238,"bestAskSize":"72.1515","bestBid":"0.00002383"},"subject":"trade.ticker","topic":"/market/ticker:EQZ-BTC","type":"message"}
1619378330.0162601: {"data":{"sequenceStart":1612701563930,"symbol":"DAPPT-BTC","changes":{"asks":[],"bids":[["0","0","1612701563930"]]},"sequenceEnd":1612701563930},"subject":"trade.l2update","topic":"/market/level2:DAPPT-BTC","type":"message"}
1619378330.0162802: {"data":{"sequenceStart":1612701563931,"symbol":"DAPPT-BTC","changes":{"asks":[],"bids":[["0.0000001091","389339.6854","1612701563931"]]},"sequenceEnd":1612701563931},"subject":"trade.l2update","topic":"/market/level2:DAPPT-BTC","type":"message"}
1619378330.0163012: {"data":{"sequenceStart":1612712745589,"symbol":"FET-BTC","changes":{"asks":[],"bids":[["0.00000769","20","1612712745589"]]},"sequenceEnd":1612712745589},"subject":"trade.l2update","topic":"/market/level2:FET-BTC","type":"message"}
1619378330.016321: {"data":{"sequenceStart":1612694580150,"symbol":"CAPP-BTC","changes":{"asks":[],"bids":[["0","0","1612694580150"]]},"sequenceEnd":1612694580150},"subject":"trade.l2update","topic":"/market/level2:CAPP-BTC","type":"message"}
1619378330.0163379: {"data":{"sequenceStart":1612694580151,"symbol":"CAPP-BTC","changes":{"asks":[],"bids":[["0.0000002101","475271.91","1612694580151"]]},"sequenceEnd":1612694580151},"subject":"trade.l2update","topic":"/market/level2:CAPP-BTC","type":"message"}
1619378330.016365: {"data":{"sequence":"1612702190319","bestAsk":"0.00006218","size":"0.0431","bestBidSize":"19.5017","price":"0.00006141","time":1619378329291,"bestAskSize":"43.3399","bestBid":"0.00006141"},"subject":"trade.ticker","topic":"/market/ticker:NRG-BTC","type":"message"}
1619378330.0163798: {"data":{"sequenceStart":1612712745590,"symbol":"FET-BTC","changes":{"asks":[["0","0","1612712745590"]],"bids":[]},"sequenceEnd":1612712745590},"subject":"trade.l2update","topic":"/market/level2:FET-BTC","type":"message"}
1619378330.0163982: {"data":{"sequenceStart":1612712745591,"symbol":"FET-BTC","changes":{"asks":[["0.0000078","1813.0491","1612712745591"]],"bids":[]},"sequenceEnd":1612712745591},"subject":"trade.l2update","topic":"/market/level2:FET-BTC","type":"message"}
1619378330.016424: {"data":{"sequenceStart":1612712745592,"symbol":"FET-BTC","changes":{"asks":[],"bids":[["0.00000764","208.7648","1612712745592"]]},"sequenceEnd":1612712745592},"subject":"trade.l2update","topic":"/market/level2:FET-BTC","type":"message"}
1619378330.016444: {"data":{"sequence":"1612701563931","bestAsk":"0.0000001126","size":"310.5072","bestBidSize":"6613.8789","price":"0.0000001123","time":1619378329330,"bestAskSize":"361.2609","bestBid":"0.0000001115"},"subject":"trade.ticker","topic":"/market/ticker:DAPPT-BTC","type":"message"}
1619378330.016459: {"data":{"sequenceStart":1613277184068,"symbol":"BCHSV-USDT","changes":{"asks":[["243.242","0","1613277184068"]],"bids":[]},"sequenceEnd":1613277184068},"subject":"trade.l2update","topic":"/market/level2:BCHSV-USDT","type":"message"}
1619378330.01649: {"data":{"sequenceStart":1612712745593,"symbol":"FET-BTC","changes":{"asks":[["0.0000078","0","1612712745593"]],"bids":[]},"sequenceEnd":1612712745593},"subject":"trade.l2update","topic":"/market/level2:FET-BTC","type":"message"}
1619378330.0165172: {"data":{"sequence":"1612712745593","bestAsk":"0.00000775","size":"401.2004","bestBidSize":"357.285","price":"0.00000772","time":1619378329367,"bestAskSize":"8025.7777","bestBid":"0.00000771"},"subject":"trade.ticker","topic":"/market/ticker:FET-BTC","type":"message"}
1619378330.016532: {"data":{"sequenceStart":1613277184069,"symbol":"BCHSV-USDT","changes":{"asks":[["0","0","1613277184069"]],"bids":[]},"sequenceEnd":1613277184069},"subject":"trade.l2update","topic":"/market/level2:BCHSV-USDT","type":"message"}
1619378330.016549: {"data":{"sequenceStart":1613277184070,"symbol":"BCHSV-USDT","changes":{"asks":[["243.24","0.6","1613277184070"]],"bids":[]},"sequenceEnd":1613277184070},"subject":"trade.l2update","topic":"/market/level2:BCHSV-USDT","type":"message"}
1619378330.016572: {"data":{"sequenceStart":1613277184071,"symbol":"BCHSV-USDT","changes":{"asks":[],"bids":[["0","0","1613277184071"]]},"sequenceEnd":1613277184071},"subject":"trade.l2update","topic":"/market/level2:BCHSV-USDT","type":"message"}
1619378330.0165892: {"data":{"sequenceStart":1613277184072,"symbol":"BCHSV-USDT","changes":{"asks":[],"bids":[["241.573","5","1613277184072"]]},"sequenceEnd":1613277184072},"subject":"trade.l2update","topic":"/market/level2:BCHSV-USDT","type":"message"}
1619378330.016612: {"data":{"sequenceStart":1613277184073,"symbol":"BCHSV-USDT","changes":{"asks":[["0","0","1613277184073"]],"bids":[]},"sequenceEnd":1613277184073},"subject":"trade.l2update","topic":"/market/level2:BCHSV-USDT","type":"message"}
1619378330.016628: {"data":{"sequenceStart":1613277184074,"symbol":"BCHSV-USDT","changes":{"asks":[["243.734","5","1613277184074"]],"bids":[]},"sequenceEnd":1613277184074},"subject":"trade.l2update","topic":"/market/level2:BCHSV-USDT","type":"message"}
1619378330.01665: {"data":{"sequenceStart":1613277184075,"symbol":"BCHSV-USDT","changes":{"asks":[["0","0","1613277184075"]],"bids":[]},"sequenceEnd":1613277184075},"subject":"trade.l2update","topic":"/market/level2:BCHSV-USDT","type":"message"}
1619378330.01667: {"data":{"sequenceStart":1613277184076,"symbol":"BCHSV-USDT","changes":{"asks":[["244.371","150","1613277184076"]],"bids":[]},"sequenceEnd":1613277184076},"subject":"trade.l2update","topic":"/market/level2:BCHSV-USDT","type":"message"}
1619378330.016692: {"data":{"sequenceStart":1612712745594,"symbol":"FET-BTC","changes":{"asks":[],"bids":[["0","0","1612712745594"]]},"sequenceEnd":1612712745594},"subject":"trade.l2update","topic":"/market/level2:FET-BTC","type":"message"}
1619378330.016709: {"data":{"sequenceStart":1612712745595,"symbol":"FET-BTC","changes":{"asks":[],"bids":[["0.00000768","177.1165","1612712745595"]]},"sequenceEnd":1612712745595},"subject":"trade.l2update","topic":"/market/level2:FET-BTC","type":"message"}
1619378330.016727: {"data":{"sequence":"1612694580151","bestAsk":"0.0000002196","size":"1000.02","bestBidSize":"83.07","price":"0.0000002182","time":1619378329381,"bestAskSize":"330.25","bestBid":"0.0000002181"},"subject":"trade.ticker","topic":"/market/ticker:CAPP-BTC","type":"message"}
1619378330.016743: {"data":{"sequence":"1613277184076","bestAsk":"242.851","size":"0.08000012","bestBidSize":"5","price":"243.65","time":1619378329430,"bestAskSize":"4.51280965","bestBid":"242.642"},"subject":"trade.ticker","topic":"/market/ticker:BCHSV-USDT","type":"message"}
1619378330.016756: {"data":{"sequence":"1612712745595","bestAsk":"0.00000775","size":"401.2004","bestBidSize":"357.285","price":"0.00000772","time":1619378329467,"bestAskSize":"8025.7777","bestBid":"0.00000771"},"subject":"trade.ticker","topic":"/market/ticker:FET-BTC","type":"message"}
1619378330.016769: {"data":{"sequenceStart":1613277184077,"symbol":"BCHSV-USDT","changes":{"asks":[["0","0","1613277184077"]],"bids":[]},"sequenceEnd":1613277184077},"subject":"trade.l2update","topic":"/market/level2:BCHSV-USDT","type":"message"}
1619378330.0167859: {"data":{"sequenceStart":1613277184078,"symbol":"BCHSV-USDT","changes":{"asks":[["243.032","8.59035286","1613277184078"]],"bids":[]},"sequenceEnd":1613277184078},"subject":"trade.l2update","topic":"/market/level2:BCHSV-USDT","type":"message"}
1619378330.016808: {"data":{"sequenceStart":1612694580152,"symbol":"CAPP-BTC","changes":{"asks":[["0.0000002197","735.9","1612694580152"]],"bids":[]},"sequenceEnd":1612694580152},"subject":"trade.l2update","topic":"/market/level2:CAPP-BTC","type":"message"}
1619378330.016829: {"data":{"sequence":"1613277184078","bestAsk":"242.851","size":"0.08000012","bestBidSize":"5","price":"243.65","time":1619378329532,"bestAskSize":"4.51280965","bestBid":"242.642"},"subject":"trade.ticker","topic":"/market/ticker:BCHSV-USDT","type":"message"}
1619378330.016843: {"data":{"sequence":"1612694580152","bestAsk":"0.0000002196","size":"1000.02","bestBidSize":"83.07","price":"0.0000002182","time":1619378329581,"bestAskSize":"330.25","bestBid":"0.0000002181"},"subject":"trade.ticker","topic":"/market/ticker:CAPP-BTC","type":"message"}
1619378330.016856: {"data":{"sequenceStart":1612712745596,"symbol":"FET-BTC","changes":{"asks":[["0","0","1612712745596"]],"bids":[]},"sequenceEnd":1612712745596},"subject":"trade.l2update","topic":"/market/level2:FET-BTC","type":"message"}
1619378330.016872: {"data":{"sequenceStart":1612712745597,"symbol":"FET-BTC","changes":{"asks":[["0.0000078","1814.1302","1612712745597"]],"bids":[]},"sequenceEnd":1612712745597},"subject":"trade.l2update","topic":"/market/level2:FET-BTC","type":"message"}
1619378330.016895: {"data":{"sequenceStart":1613277184079,"symbol":"BCHSV-USDT","changes":{"asks":[["246.421","0","1613277184079"]],"bids":[]},"sequenceEnd":1613277184079},"subject":"trade.l2update","topic":"/market/level2:BCHSV-USDT","type":"message"}
1619378330.0169191: {"data":{"sequenceStart":1613277184080,"symbol":"BCHSV-USDT","changes":{"asks":[["243.24","0","1613277184080"]],"bids":[]},"sequenceEnd":1613277184080},"subject":"trade.l2update","topic":"/market/level2:BCHSV-USDT","type":"message"}
1619378330.0169432: {"data":{"sequenceStart":1613277184081,"symbol":"BCHSV-USDT","changes":{"asks":[["0","0","1613277184081"]],"bids":[]},"sequenceEnd":1613277184081},"subject":"trade.l2update","topic":"/market/level2:BCHSV-USDT","type":"message"}
1619378330.01696: {"data":{"sequenceStart":1613277184082,"symbol":"BCHSV-USDT","changes":{"asks":[["243.241","0.6","1613277184082"]],"bids":[]},"sequenceEnd":1613277184082},"subject":"trade.l2update","topic":"/market/level2:BCHSV-USDT","type":"message"}
1619378330.016982: {"data":{"sequence":"1612712745597","bestAsk":"0.00000775","size":"401.2004","bestBidSize":"357.285","price":"0.00000772","time":1619378329668,"bestAskSize":"8025.7777","bestBid":"0.00000771"},"subject":"trade.ticker","topic":"/market/ticker:FET-BTC","type":"message"}
1619378330.0169961: {"data":{"sequenceStart":1613277184083,"symbol":"BCHSV-USDT","changes":{"asks":[["0","0","1613277184083"]],"bids":[]},"sequenceEnd":1613277184083},"subject":"trade.l2update","topic":"/market/level2:BCHSV-USDT","type":"message"}
1619378330.017012: {"data":{"sequenceStart":1613277184084,"symbol":"BCHSV-USDT","changes":{"asks":[["247.395","37.33","1613277184084"]],"bids":[]},"sequenceEnd":1613277184084},"subject":"trade.l2update","topic":"/market/level2:BCHSV-USDT","type":"message"}
1619378330.017034: {"data":{"sequenceStart":1612712745598,"symbol":"FET-BTC","changes":{"asks":[["0.00000775","1154.0416","1612712745598"]],"bids":[]},"sequenceEnd":1612712745598},"subject":"trade.l2update","topic":"/market/level2:FET-BTC","type":"message"}
1619378330.017053: {"data":{"sequenceStart":1612844051741,"symbol":"SNX-BTC","changes":{"asks":[["0.00028718","0","1612844051741"]],"bids":[]},"sequenceEnd":1612844051741},"subject":"trade.l2update","topic":"/market/level2:SNX-BTC","type":"message"}
1619378330.017079: {"data":{"sequenceStart":1612701563932,"symbol":"DAPPT-BTC","changes":{"asks":[["0.0000001129","0","1612701563932"]],"bids":[]},"sequenceEnd":1612701563932},"subject":"trade.l2update","topic":"/market/level2:DAPPT-BTC","type":"message"}
1619378330.017107: {"data":{"sequence":"1612844051741","bestAsk":"0.00028717","size":"0.01745248","bestBidSize":"0.19100065","price":"0.00028676","time":1619378329723,"bestAskSize":"29.24570683","bestBid":"0.00028678"},"subject":"trade.ticker","topic":"/market/ticker:SNX-BTC","type":"message"}
1619378330.0171258: {"data":{"sequence":"1613277184084","bestAsk":"242.851","size":"0.08000012","bestBidSize":"5","price":"243.65","time":1619378329730,"bestAskSize":"4.51280965","bestBid":"242.642"},"subject":"trade.ticker","topic":"/market/ticker:BCHSV-USDT","type":"message"}
1619378330.01714: {"data":{"sequence":"1612701563932","bestAsk":"0.0000001126","size":"310.5072","bestBidSize":"6613.8789","price":"0.0000001123","time":1619378329730,"bestAskSize":"361.2609","bestBid":"0.0000001115"},"subject":"trade.ticker","topic":"/market/ticker:DAPPT-BTC","type":"message"}
1619378330.0171561: {"data":{"sequenceStart":1613277184085,"symbol":"BCHSV-USDT","changes":{"asks":[],"bids":[["242.64","0","1613277184085"]]},"sequenceEnd":1613277184085},"subject":"trade.l2update","topic":"/market/level2:BCHSV-USDT","type":"message"}
1619378330.0171819: {"data":{"sequenceStart":1613277184086,"symbol":"BCHSV-USDT","changes":{"asks":[],"bids":[["0","0","1613277184086"]]},"sequenceEnd":1613277184086},"subject":"trade.l2update","topic":"/market/level2:BCHSV-USDT","type":"message"}
1619378330.017199: {"data":{"sequenceStart":1613277184087,"symbol":"BCHSV-USDT","changes":{"asks":[],"bids":[["242.639","0.68148185","1613277184087"]]},"sequenceEnd":1613277184087},"subject":"trade.l2update","topic":"/market/level2:BCHSV-USDT","type":"message"}
1619378330.0172212: {"data":{"sequence":"1612712745598","bestAsk":"0.00000775","size":"401.2004","bestBidSize":"357.285","price":"0.00000772","time":1619378329767,"bestAskSize":"1154.0416","bestBid":"0.00000771"},"subject":"trade.ticker","topic":"/market/ticker:FET-BTC","type":"message"}
1619378330.017236: {"data":{"sequenceStart":1613277184088,"symbol":"BCHSV-USDT","changes":{"asks":[["243.734","0","1613277184088"]],"bids":[]},"sequenceEnd":1613277184088},"subject":"trade.l2update","topic":"/market/level2:BCHSV-USDT","type":"message"}
1619378330.017258: {"data":{"sequenceStart":1613277184089,"symbol":"BCHSV-USDT","changes":{"asks":[],"bids":[["241.573","0","1613277184089"]]},"sequenceEnd":1613277184089},"subject":"trade.l2update","topic":"/market/level2:BCHSV-USDT","type":"message"}
1619378330.017281: {"data":{"sequenceStart":1612844051742,"symbol":"SNX-BTC","changes":{"asks":[["0","0","1612844051742"]],"bids":[]},"sequenceEnd":1612844051742},"subject":"trade.l2update","topic":"/market/level2:SNX-BTC","type":"message"}
1619378330.017298: {"data":{"sequenceStart":1612844051743,"symbol":"SNX-BTC","changes":{"asks":[["0.00028733","14.05873709","1612844051743"]],"bids":[]},"sequenceEnd":1612844051743},"subject":"trade.l2update","topic":"/market/level2:SNX-BTC","type":"message"}
1619378330.0173209: {"data":{"sequenceStart":1612712745599,"symbol":"FET-BTC","changes":{"asks":[["0.0000078","0","1612712745599"]],"bids":[]},"sequenceEnd":1612712745599},"subject":"trade.l2update","topic":"/market/level2:FET-BTC","type":"message"}
1619378330.017345: {"data":{"sequenceStart":1613277184090,"symbol":"BCHSV-USDT","changes":{"asks":[["244.371","0","1613277184090"]],"bids":[]},"sequenceEnd":1613277184090},"subject":"trade.l2update","topic":"/market/level2:BCHSV-USDT","type":"message"}
1619378330.017368: {"data":{"sequenceStart":1613277184091,"symbol":"BCHSV-USDT","changes":{"asks":[],"bids":[["242.642","0","1613277184091"]]},"sequenceEnd":1613277184091},"subject":"trade.l2update","topic":"/market/level2:BCHSV-USDT","type":"message"}
1619378330.0173912: {"data":{"sequenceStart":1612712745600,"symbol":"FET-BTC","changes":{"asks":[],"bids":[["0","0","1612712745600"]]},"sequenceEnd":1612712745600},"subject":"trade.l2update","topic":"/market/level2:FET-BTC","type":"message"}
1619378330.017408: {"data":{"sequenceStart":1612712745601,"symbol":"FET-BTC","changes":{"asks":[],"bids":[["0.00000767","116.5908","1612712745601"]]},"sequenceEnd":1612712745601},"subject":"trade.l2update","topic":"/market/level2:FET-BTC","type":"message"}
1619378330.017427: {"data":{"sequenceStart":1612699351250,"symbol":"COV-BTC","changes":{"asks":[["0","0","1612699351250"]],"bids":[]},"sequenceEnd":1612699351250},"subject":"trade.l2update","topic":"/market/level2:COV-BTC","type":"message"}
1619378330.017445: {"data":{"sequenceStart":1612699351251,"symbol":"COV-BTC","changes":{"asks":[["0.00001126","137.9035","1612699351251"]],"bids":[]},"sequenceEnd":1612699351251},"subject":"trade.l2update","topic":"/market/level2:COV-BTC","type":"message"}
1619378330.017471: {"data":{"sequenceStart":1613277184092,"symbol":"BCHSV-USDT","changes":{"asks":[],"bids":[["0","0","1613277184092"]]},"sequenceEnd":1613277184092},"subject":"trade.l2update","topic":"/market/level2:BCHSV-USDT","type":"message"}
1619378330.0174878: {"data":{"sequenceStart":1613277184093,"symbol":"BCHSV-USDT","changes":{"asks":[],"bids":[["242.641","5","1613277184093"]]},"sequenceEnd":1613277184093},"subject":"trade.l2update","topic":"/market/level2:BCHSV-USDT","type":"message"}
1619378330.0175092: {"data":{"sequence":"1613277184093","bestAsk":"242.851","size":"0.08000012","bestBidSize":"5","price":"243.65","time":1619378329831,"bestAskSize":"4.51280965","bestBid":"242.641"},"subject":"trade.ticker","topic":"/market/ticker:BCHSV-USDT","type":"message"}
1619378330.017523: {"data":{"sequence":"1612844051743","bestAsk":"0.00028717","size":"0.01745248","bestBidSize":"0.19100065","price":"0.00028676","time":1619378329846,"bestAskSize":"29.24570683","bestBid":"0.00028678"},"subject":"trade.ticker","topic":"/market/ticker:SNX-BTC","type":"message"}
1619378330.017536: {"data":{"sequenceStart":1613277184094,"symbol":"BCHSV-USDT","changes":{"asks":[],"bids":[["0","0","1613277184094"]]},"sequenceEnd":1613277184094},"subject":"trade.l2update","topic":"/market/level2:BCHSV-USDT","type":"message"}
1619378330.017552: {"data":{"sequenceStart":1613277184095,"symbol":"BCHSV-USDT","changes":{"asks":[],"bids":[["242.532","0.4008184","1613277184095"]]},"sequenceEnd":1613277184095},"subject":"trade.l2update","topic":"/market/level2:BCHSV-USDT","type":"message"}
1619378330.017573: {"data":{"sequence":"1612712745601","bestAsk":"0.00000775","size":"401.2004","bestBidSize":"357.285","price":"0.00000772","time":1619378329867,"bestAskSize":"1154.0416","bestBid":"0.00000771"},"subject":"trade.ticker","topic":"/market/ticker:FET-BTC","type":"message"}
1619378330.017587: {"data":{"sequenceStart":1613277184096,"symbol":"BCHSV-USDT","changes":{"asks":[],"bids":[["242.532","0","1613277184096"]]},"sequenceEnd":1613277184096},"subject":"trade.l2update","topic":"/market/level2:BCHSV-USDT","type":"message"}
1619378330.01761: {"data":{"sequenceStart":1613277184097,"symbol":"BCHSV-USDT","changes":{"asks":[["243.078","0","1613277184097"]],"bids":[]},"sequenceEnd":1613277184097},"subject":"trade.l2update","topic":"/market/level2:BCHSV-USDT","type":"message"}
1619378330.017633: {"data":{"sequence":"1612699351251","bestAsk":"0.00001126","size":"96.1525","bestBidSize":"49.6422","price":"0.00001126","time":1619378329888,"bestAskSize":"137.9035","bestBid":"0.00001121"},"subject":"trade.ticker","topic":"/market/ticker:COV-BTC","type":"message"}
1619378330.0176508: {"data":{"sequenceStart":1612701563933,"symbol":"DAPPT-BTC","changes":{"asks":[],"bids":[["0.0000001115","6450","1612701563933"]]},"sequenceEnd":1612701563933},"subject":"trade.l2update","topic":"/market/level2:DAPPT-BTC","type":"message"}
1619378330.0176718: {"data":{"sequenceStart":1612712745602,"symbol":"FET-BTC","changes":{"asks":[],"bids":[["0","0","1612712745602"]]},"sequenceEnd":1612712745602},"subject":"trade.l2update","topic":"/market/level2:FET-BTC","type":"message"}
1619378330.017688: {"data":{"sequenceStart":1612712745603,"symbol":"FET-BTC","changes":{"asks":[],"bids":[["0.00000764","278.7348","1612712745603"]]},"sequenceEnd":1612712745603},"subject":"trade.l2update","topic":"/market/level2:FET-BTC","type":"message"}
1619378330.017707: {"data":{"sequence":"1613277184097","bestAsk":"242.851","size":"0.08000012","bestBidSize":"5","price":"243.65","time":1619378329930,"bestAskSize":"4.51280965","bestBid":"242.641"},"subject":"trade.ticker","topic":"/market/ticker:BCHSV-USDT","type":"message"}
1619378330.0177212: {"data":{"sequence":"1612701563933","bestAsk":"0.0000001126","size":"310.5072","bestBidSize":"6450","price":"0.0000001123","time":1619378329930,"bestAskSize":"361.2609","bestBid":"0.0000001115"},"subject":"trade.ticker","topic":"/market/ticker:DAPPT-BTC","type":"message"}
1619378330.0177338: {"data":{"sequenceStart":1612701563934,"symbol":"DAPPT-BTC","changes":{"asks":[["0.000000113","1208.0878","1612701563934"]],"bids":[]},"sequenceEnd":1612701563934},"subject":"trade.l2update","topic":"/market/level2:DAPPT-BTC","type":"message"}
1619378330.0177531: {"data":{"sequenceStart":1613277184098,"symbol":"BCHSV-USDT","changes":{"asks":[["243.241","0","1613277184098"]],"bids":[]},"sequenceEnd":1613277184098},"subject":"trade.l2update","topic":"/market/level2:BCHSV-USDT","type":"message"}
1619378330.017776: {"data":{"sequenceStart":1613277184099,"symbol":"BCHSV-USDT","changes":{"asks":[["0","0","1613277184099"]],"bids":[]},"sequenceEnd":1613277184099},"subject":"trade.l2update","topic":"/market/level2:BCHSV-USDT","type":"message"}
1619378330.017792: {"data":{"sequenceStart":1613277184100,"symbol":"BCHSV-USDT","changes":{"asks":[["243.24","0.6","1613277184100"]],"bids":[]},"sequenceEnd":1613277184100},"subject":"trade.l2update","topic":"/market/level2:BCHSV-USDT","type":"message"}
1619378330.017813: {"data":{"sequence":"1612712745603","bestAsk":"0.00000775","size":"401.2004","bestBidSize":"357.285","price":"0.00000772","time":1619378329967,"bestAskSize":"1154.0416","bestBid":"0.00000771"},"subject":"trade.ticker","topic":"/market/ticker:FET-BTC","type":"message"}
1619378330.067651: {"data":{"sequence":"1612701563934","bestAsk":"0.0000001126","size":"310.5072","bestBidSize":"6450","price":"0.0000001123","time":1619378330030,"bestAskSize":"361.2609","bestBid":"0.0000001115"},"subject":"trade.ticker","topic":"/market/ticker:DAPPT-BTC","type":"message"}
1619378330.067744: {"data":{"sequence":"1613277184100","bestAsk":"242.851","size":"0.08000012","bestBidSize":"5","price":"243.65","time":1619378330030,"bestAskSize":"4.51280965","bestBid":"242.641"},"subject":"trade.ticker","topic":"/market/ticker:BCHSV-USDT","type":"message"}
1619378330.101093: {"data":{"sequenceStart":1612712745604,"symbol":"FET-BTC","changes":{"asks":[["0","0","1612712745604"]],"bids":[]},"sequenceEnd":1612712745604},"subject":"trade.l2update","topic":"/market/level2:FET-BTC","type":"message"}
1619378330.101202: {"data":{"sequenceStart":1612712745605,"symbol":"FET-BTC","changes":{"asks":[["0.0000078","1814.1302","1612712745605"]],"bids":[]},"sequenceEnd":1612712745605},"subject":"trade.l2update","topic":"/market/level2:FET-BTC","type":"message"}
1619378330.107477: {"data":{"sequence":"1612712745605","bestAsk":"0.00000775","size":"401.2004","bestBidSize":"357.285","price":"0.00000772","time":1619378330067,"bestAskSize":"1154.0416","bestBid":"0.00000771"},"subject":"trade.ticker","topic":"/market/ticker:FET-BTC","type":"message"}
1619378330.154289: {"data":{"sequenceStart":1613277184101,"symbol":"BCHSV-USDT","changes":{"asks":[["242.851","0","1613277184101"]],"bids":[]},"sequenceEnd":1613277184101},"subject":"trade.l2update","topic":"/market/level2:BCHSV-USDT","type":"message"}
1619378330.154428: {"data":{"sequenceStart":1613277184102,"symbol":"BCHSV-USDT","changes":{"asks":[["0","0","1613277184102"]],"bids":[]},"sequenceEnd":1613277184102},"subject":"trade.l2update","topic":"/market/level2:BCHSV-USDT","type":"message"}
1619378330.154484: {"data":{"sequenceStart":1613277184103,"symbol":"BCHSV-USDT","changes":{"asks":[["242.988","6.18045643","1613277184103"]],"bids":[]},"sequenceEnd":1613277184103},"subject":"trade.l2update","topic":"/market/level2:BCHSV-USDT","type":"message"}
1619378330.170708: {"data":{"sequence":"1613277184103","bestAsk":"242.988","size":"0.08000012","bestBidSize":"5","price":"243.65","time":1619378330133,"bestAskSize":"6.18045643","bestBid":"242.641"},"subject":"trade.ticker","topic":"/market/ticker:BCHSV-USDT","type":"message"}
1619378330.187389: {"data":{"sequenceStart":1613277184104,"symbol":"BCHSV-USDT","changes":{"asks":[["0","0","1613277184104"]],"bids":[]},"sequenceEnd":1613277184104},"subject":"trade.l2update","topic":"/market/level2:BCHSV-USDT","type":"message"}
1619378330.187499: {"data":{"sequenceStart":1613277184105,"symbol":"BCHSV-USDT","changes":{"asks":[["242.811","4.51280965","1613277184105"]],"bids":[]},"sequenceEnd":1613277184105},"subject":"trade.l2update","topic":"/market/level2:BCHSV-USDT","type":"message"}
1619378330.1875799: {"data":{"sequenceStart":1613277184106,"symbol":"BCHSV-USDT","changes":{"asks":[],"bids":[["242.621","0","1613277184106"]]},"sequenceEnd":1613277184106},"subject":"trade.l2update","topic":"/market/level2:BCHSV-USDT","type":"message"}
1619378330.2032058: {"data":{"sequenceStart":1613277184107,"symbol":"BCHSV-USDT","changes":{"asks":[["243.036","2.99","1613277184107"]],"bids":[]},"sequenceEnd":1613277184107},"subject":"trade.l2update","topic":"/market/level2:BCHSV-USDT","type":"message"}
1619378330.203326: {"data":{"sequenceStart":1613277184108,"symbol":"BCHSV-USDT","changes":{"asks":[["243.036","0","1613277184108"]],"bids":[]},"sequenceEnd":1613277184108},"subject":"trade.l2update","topic":"/market/level2:BCHSV-USDT","type":"message"}
1619378330.2363698: {"data":{"sequenceStart":1613277184109,"symbol":"BCHSV-USDT","changes":{"asks":[],"bids":[["242.641","0","1613277184109"]]},"sequenceEnd":1613277184109},"subject":"trade.l2update","topic":"/market/level2:BCHSV-USDT","type":"message"}
1619378330.253488: {"data":{"sequenceStart":1613277184110,"symbol":"BCHSV-USDT","changes":{"asks":[],"bids":[["0","0","1613277184110"]]},"sequenceEnd":1613277184110},"subject":"trade.l2update","topic":"/market/level2:BCHSV-USDT","type":"message"}
1619378330.253603: {"data":{"sequenceStart":1613277184111,"symbol":"BCHSV-USDT","changes":{"asks":[],"bids":[["242.532","0.10226994","1613277184111"]]},"sequenceEnd":1613277184111},"subject":"trade.l2update","topic":"/market/level2:BCHSV-USDT","type":"message"}
1619378330.2536561: {"data":{"sequenceStart":1613277184112,"symbol":"BCHSV-USDT","changes":{"asks":[["0","0","1613277184112"]],"bids":[]},"sequenceEnd":1613277184112},"subject":"trade.l2update","topic":"/market/level2:BCHSV-USDT","type":"message"}
1619378330.253685: {"data":{"sequenceStart":1613277184113,"symbol":"BCHSV-USDT","changes":{"asks":[["243.031","2.99","1613277184113"]],"bids":[]},"sequenceEnd":1613277184113},"subject":"trade.l2update","topic":"/market/level2:BCHSV-USDT","type":"message"}
1619378330.2537248: {"data":{"sequenceStart":1613277184114,"symbol":"BCHSV-USDT","changes":{"asks":[],"bids":[["0","0","1613277184114"]]},"sequenceEnd":1613277184114},"subject":"trade.l2update","topic":"/market/level2:BCHSV-USDT","type":"message"}
1619378330.25375: {"data":{"sequenceStart":1613277184115,"symbol":"BCHSV-USDT","changes":{"asks":[],"bids":[["242.559","5","1613277184115"]]},"sequenceEnd":1613277184115},"subject":"trade.l2update","topic":"/market/level2:BCHSV-USDT","type":"message"}
1619378330.2684858: {"data":{"sequenceStart":1613277184116,"symbol":"BCHSV-USDT","changes":{"asks":[["0","0","1613277184116"]],"bids":[]},"sequenceEnd":1613277184116},"subject":"trade.l2update","topic":"/market/level2:BCHSV-USDT","type":"message"}
1619378330.268564: {"data":{"sequenceStart":1613277184117,"symbol":"BCHSV-USDT","changes":{"asks":[["243.031","5.98","1613277184117"]],"bids":[]},"sequenceEnd":1613277184117},"subject":"trade.l2update","topic":"/market/level2:BCHSV-USDT","type":"message"}
1619378330.268606: {"data":{"sequence":"1613277184117","bestAsk":"242.811","size":"0.08000012","bestBidSize":"0.68148185","price":"243.65","time":1619378330231,"bestAskSize":"4.51280965","bestBid":"242.639"},"subject":"trade.ticker","topic":"/market/ticker:BCHSV-USDT","type":"message"}
1619378330.287651: {"data":{"sequenceStart":1613277184118,"symbol":"BCHSV-USDT","changes":{"asks":[["243.031","2.99","1613277184118"]],"bids":[]},"sequenceEnd":1613277184118},"subject":"trade.l2update","topic":"/market/level2:BCHSV-USDT","type":"message"}
1619378330.30214: {"data":{"sequenceStart":1613277184119,"symbol":"BCHSV-USDT","changes":{"asks":[["243.031","0","1613277184119"]],"bids":[]},"sequenceEnd":1613277184119},"subject":"trade.l2update","topic":"/market/level2:BCHSV-USDT","type":"message"}
1619378330.327446: {"data":{"sequenceStart":1612694580153,"symbol":"CAPP-BTC","changes":{"asks":[],"bids":[["0","0","1612694580153"]]},"sequenceEnd":1612694580153},"subject":"trade.l2update","topic":"/market/level2:CAPP-BTC","type":"message"}
1619378330.327559: {"data":{"sequenceStart":1612694580154,"symbol":"CAPP-BTC","changes":{"asks":[],"bids":[["0.0000002068","84253.05","1612694580154"]]},"sequenceEnd":1612694580154},"subject":"trade.l2update","topic":"/market/level2:CAPP-BTC","type":"message"}
1619378330.3353422: {"data":{"sequenceStart":1613277184120,"symbol":"BCHSV-USDT","changes":{"asks":[["243.24","0","1613277184120"]],"bids":[]},"sequenceEnd":1613277184120},"subject":"trade.l2update","topic":"/market/level2:BCHSV-USDT","type":"message"}
1619378330.335486: {"data":{"sequenceStart":1613277184121,"symbol":"BCHSV-USDT","changes":{"asks":[],"bids":[["242.639","0","1613277184121"]]},"sequenceEnd":1613277184121},"subject":"trade.l2update","topic":"/market/level2:BCHSV-USDT","type":"message"}
1619378330.335586: {"data":{"sequenceStart":1613277184122,"symbol":"BCHSV-USDT","changes":{"asks":[["0","0","1613277184122"]],"bids":[]},"sequenceEnd":1613277184122},"subject":"trade.l2update","topic":"/market/level2:BCHSV-USDT","type":"message"}
1619378330.335616: {"data":{"sequenceStart":1613277184123,"symbol":"BCHSV-USDT","changes":{"asks":[["243.213","0.6","1613277184123"]],"bids":[]},"sequenceEnd":1613277184123},"subject":"trade.l2update","topic":"/market/level2:BCHSV-USDT","type":"message"}
1619378330.335652: {"data":{"sequenceStart":1613277184124,"symbol":"BCHSV-USDT","changes":{"asks":[["0","0","1613277184124"]],"bids":[]},"sequenceEnd":1613277184124},"subject":"trade.l2update","topic":"/market/level2:BCHSV-USDT","type":"message"}
1619378330.335676: {"data":{"sequenceStart":1613277184125,"symbol":"BCHSV-USDT","changes":{"asks":[["242.987","2.99","1613277184125"]],"bids":[]},"sequenceEnd":1613277184125},"subject":"trade.l2update","topic":"/market/level2:BCHSV-USDT","type":"message"}
1619378330.335706: {"data":{"sequenceStart":1613277184126,"symbol":"BCHSV-USDT","changes":{"asks":[],"bids":[["0","0","1613277184126"]]},"sequenceEnd":1613277184126},"subject":"trade.l2update","topic":"/market/level2:BCHSV-USDT","type":"message"}
1619378330.3357282: {"data":{"sequenceStart":1613277184127,"symbol":"BCHSV-USDT","changes":{"asks":[],"bids":[["242.558","0.68148185","1613277184127"]]},"sequenceEnd":1613277184127},"subject":"trade.l2update","topic":"/market/level2:BCHSV-USDT","type":"message"}
1619378330.341333: {"data":{"sequenceStart":1613277184128,"symbol":"BCHSV-USDT","changes":{"asks":[],"bids":[["242.559","0","1613277184128"]]},"sequenceEnd":1613277184128},"subject":"trade.l2update","topic":"/market/level2:BCHSV-USDT","type":"message"}
1619378330.35235: {"data":{"sequenceStart":1613277184129,"symbol":"BCHSV-USDT","changes":{"asks":[],"bids":[["0","0","1613277184129"]]},"sequenceEnd":1613277184129},"subject":"trade.l2update","topic":"/market/level2:BCHSV-USDT","type":"message"}
1619378330.352462: {"data":{"sequenceStart":1613277184130,"symbol":"BCHSV-USDT","changes":{"asks":[],"bids":[["242.561","5","1613277184130"]]},"sequenceEnd":1613277184130},"subject":"trade.l2update","topic":"/market/level2:BCHSV-USDT","type":"message"}
1619378330.352559: {"data":{"sequenceStart":1613277184131,"symbol":"BCHSV-USDT","changes":{"asks":[["0","0","1613277184131"]],"bids":[]},"sequenceEnd":1613277184131},"subject":"trade.l2update","topic":"/market/level2:BCHSV-USDT","type":"message"}
1619378330.352604: {"data":{"sequenceStart":1613277184132,"symbol":"BCHSV-USDT","changes":{"asks":[["242.987","5.98","1613277184132"]],"bids":[]},"sequenceEnd":1613277184132},"subject":"trade.l2update","topic":"/market/level2:BCHSV-USDT","type":"message"}
1619378330.373566: {"data":{"sequence":"1613277184132","bestAsk":"242.811","size":"0.08000012","bestBidSize":"5","price":"243.65","time":1619378330332,"bestAskSize":"4.51280965","bestBid":"242.561"},"subject":"trade.ticker","topic":"/market/ticker:BCHSV-USDT","type":"message"}
1619378330.4057531: {"data":{"sequenceStart":1613277184133,"symbol":"BCHSV-USDT","changes":{"asks":[],"bids":[["242.558","0","1613277184133"]]},"sequenceEnd":1613277184133},"subject":"trade.l2update","topic":"/market/level2:BCHSV-USDT","type":"message"}
1619378330.41891: {"data":{"sequenceStart":1612694580155,"symbol":"CAPP-BTC","changes":{"asks":[["0","0","1612694580155"]],"bids":[]},"sequenceEnd":1612694580155},"subject":"trade.l2update","topic":"/market/level2:CAPP-BTC","type":"message"}
1619378330.419036: {"data":{"sequenceStart":1612694580156,"symbol":"CAPP-BTC","changes":{"asks":[["0.0000002196","4490.25","1612694580156"]],"bids":[]},"sequenceEnd":1612694580156},"subject":"trade.l2update","topic":"/market/level2:CAPP-BTC","type":"message"}
1619378330.4191139: {"data":{"sequenceStart":1613277184134,"symbol":"BCHSV-USDT","changes":{"asks":[],"bids":[["0","0","1613277184134"]]},"sequenceEnd":1613277184134},"subject":"trade.l2update","topic":"/market/level2:BCHSV-USDT","type":"message"}
1619378330.419144: {"data":{"sequenceStart":1613277184135,"symbol":"BCHSV-USDT","changes":{"asks":[],"bids":[["241.559","5","1613277184135"]]},"sequenceEnd":1613277184135},"subject":"trade.l2update","topic":"/market/level2:BCHSV-USDT","type":"message"}
1619378330.419182: {"data":{"sequenceStart":1613277184136,"symbol":"BCHSV-USDT","changes":{"asks":[["0","0","1613277184136"]],"bids":[]},"sequenceEnd":1613277184136},"subject":"trade.l2update","topic":"/market/level2:BCHSV-USDT","type":"message"}
1619378330.419206: {"data":{"sequenceStart":1613277184137,"symbol":"BCHSV-USDT","changes":{"asks":[["243.72","5","1613277184137"]],"bids":[]},"sequenceEnd":1613277184137},"subject":"trade.l2update","topic":"/market/level2:BCHSV-USDT","type":"message"}
1619378330.4192371: {"data":{"sequenceStart":1613277184138,"symbol":"BCHSV-USDT","changes":{"asks":[["0","0","1613277184138"]],"bids":[]},"sequenceEnd":1613277184138},"subject":"trade.l2update","topic":"/market/level2:BCHSV-USDT","type":"message"}
1619378330.4192588: {"data":{"sequenceStart":1613277184139,"symbol":"BCHSV-USDT","changes":{"asks":[["244.357","150","1613277184139"]],"bids":[]},"sequenceEnd":1613277184139},"subject":"trade.l2update","topic":"/market/level2:BCHSV-USDT","type":"message"}
1619378330.4192882: {"data":{"sequenceStart":1613277184140,"symbol":"BCHSV-USDT","changes":{"asks":[],"bids":[["0","0","1613277184140"]]},"sequenceEnd":1613277184140},"subject":"trade.l2update","topic":"/market/level2:BCHSV-USDT","type":"message"}
1619378330.41931: {"data":{"sequenceStart":1613277184141,"symbol":"BCHSV-USDT","changes":{"asks":[],"bids":[["242.538","0.68148185","1613277184141"]]},"sequenceEnd":1613277184141},"subject":"trade.l2update","topic":"/market/level2:BCHSV-USDT","type":"message"}
1619378330.42203: {"data":{"sequence":"1612694580156","bestAsk":"0.0000002196","size":"1000.02","bestBidSize":"83.07","price":"0.0000002182","time":1619378330381,"bestAskSize":"4490.25","bestBid":"0.0000002181"},"subject":"trade.ticker","topic":"/market/ticker:CAPP-BTC","type":"message"}
1619378330.466665: {"data":{"sequence":"1613277184141","bestAsk":"242.811","size":"0.08000012","bestBidSize":"5","price":"243.65","time":1619378330430,"bestAskSize":"4.51280965","bestBid":"242.561"},"subject":"trade.ticker","topic":"/market/ticker:BCHSV-USDT","type":"message"}
1619378330.497026: {"data":{"sequenceStart":1613277184142,"symbol":"BCHSV-USDT","changes":{"asks":[["243.213","0","1613277184142"]],"bids":[]},"sequenceEnd":1613277184142},"subject":"trade.l2update","topic":"/market/level2:BCHSV-USDT","type":"message"}
1619378330.509778: {"data":{"sequenceStart":1613277184143,"symbol":"BCHSV-USDT","changes":{"asks":[["0","0","1613277184143"]],"bids":[]},"sequenceEnd":1613277184143},"subject":"trade.l2update","topic":"/market/level2:BCHSV-USDT","type":"message"}
1619378330.5118709: {"data":{"sequenceStart":1613277184144,"symbol":"BCHSV-USDT","changes":{"asks":[["243.145","0.6","1613277184144"]],"bids":[]},"sequenceEnd":1613277184144},"subject":"trade.l2update","topic":"/market/level2:BCHSV-USDT","type":"message"}
1619378330.5315142: {"data":{"sequenceStart":1613277184145,"symbol":"BCHSV-USDT","changes":{"asks":[],"bids":[["242.561","0","1613277184145"]]},"sequenceEnd":1613277184145},"subject":"trade.l2update","topic":"/market/level2:BCHSV-USDT","type":"message"}
1619378330.5530088: {"data":{"sequenceStart":1613277184146,"symbol":"BCHSV-USDT","changes":{"asks":[],"bids":[["0","0","1613277184146"]]},"sequenceEnd":1613277184146},"subject":"trade.l2update","topic":"/market/level2:BCHSV-USDT","type":"message"}
1619378330.553118: {"data":{"sequenceStart":1613277184147,"symbol":"BCHSV-USDT","changes":{"asks":[],"bids":[["242.54","5","1613277184147"]]},"sequenceEnd":1613277184147},"subject":"trade.l2update","topic":"/market/level2:BCHSV-USDT","type":"message"}
1619378330.568148: {"data":{"sequence":"1613277184147","bestAsk":"242.811","size":"0.08000012","bestBidSize":"5","price":"243.65","time":1619378330530,"bestAskSize":"4.51280965","bestBid":"242.54"},"subject":"trade.ticker","topic":"/market/ticker:BCHSV-USDT","type":"message"}
1619378330.6454332: {"data":{"sequenceStart":1613277184148,"symbol":"BCHSV-USDT","changes":{"asks":[],"bids":[["242.54","0","1613277184148"]]},"sequenceEnd":1613277184148},"subject":"trade.l2update","topic":"/market/level2:BCHSV-USDT","type":"message"}
1619378330.6455739: {"data":{"sequenceStart":1613277184149,"symbol":"BCHSV-USDT","changes":{"asks":[],"bids":[["241.771","0","1613277184149"]]},"sequenceEnd":1613277184149},"subject":"trade.l2update","topic":"/market/level2:BCHSV-USDT","type":"message"}
1619378330.649193: {"data":{"sequenceStart":1613277184150,"symbol":"BCHSV-USDT","changes":{"asks":[],"bids":[["242.532","0","1613277184150"]]},"sequenceEnd":1613277184150},"subject":"trade.l2update","topic":"/market/level2:BCHSV-USDT","type":"message"}
1619378330.649336: {"data":{"sequenceStart":1613277184151,"symbol":"BCHSV-USDT","changes":{"asks":[],"bids":[["0","0","1613277184151"]]},"sequenceEnd":1613277184151},"subject":"trade.l2update","topic":"/market/level2:BCHSV-USDT","type":"message"}
1619378330.6493921: {"data":{"sequenceStart":1613277184152,"symbol":"BCHSV-USDT","changes":{"asks":[],"bids":[["242.521","5","1613277184152"]]},"sequenceEnd":1613277184152},"subject":"trade.l2update","topic":"/market/level2:BCHSV-USDT","type":"message"}
1619378330.649454: {"data":{"sequenceStart":1612734157748,"symbol":"ANKR-BTC","changes":{"asks":[["0.0000026186","0","1612734157748"]],"bids":[]},"sequenceEnd":1612734157748},"subject":"trade.l2update","topic":"/market/level2:ANKR-BTC","type":"message"}
1619378330.659901: {"data":{"sequenceStart":1612734157749,"symbol":"ANKR-BTC","changes":{"asks":[],"bids":[["0","0","1612734157749"]]},"sequenceEnd":1612734157749},"subject":"trade.l2update","topic":"/market/level2:ANKR-BTC","type":"message"}
1619378330.660013: {"data":{"sequenceStart":1612734157750,"symbol":"ANKR-BTC","changes":{"asks":[],"bids":[["0.0000026016","118.3834","1612734157750"]]},"sequenceEnd":1612734157750},"subject":"trade.l2update","topic":"/market/level2:ANKR-BTC","type":"message"}
1619378330.672721: {"data":{"sequence":"1613277184152","bestAsk":"242.811","size":"0.08000012","bestBidSize":"0.68148185","price":"243.65","time":1619378330633,"bestAskSize":"4.51280965","bestBid":"242.538"},"subject":"trade.ticker","topic":"/market/ticker:BCHSV-USDT","type":"message"}
1619378330.683024: {"data":{"sequenceStart":1613277184153,"symbol":"BCHSV-USDT","changes":{"asks":[],"bids":[["242.345","0","1613277184153"]]},"sequenceEnd":1613277184153},"subject":"trade.l2update","topic":"/market/level2:BCHSV-USDT","type":"message"}
1619378330.683163: {"data":{"sequenceStart":1613277184154,"symbol":"BCHSV-USDT","changes":{"asks":[["242.988","0","1613277184154"]],"bids":[]},"sequenceEnd":1613277184154},"subject":"trade.l2update","topic":"/market/level2:BCHSV-USDT","type":"message"}
1619378330.690061: {"data":{"sequenceStart":1612844051744,"symbol":"SNX-BTC","changes":{"asks":[["0","0","1612844051744"]],"bids":[]},"sequenceEnd":1612844051744},"subject":"trade.l2update","topic":"/market/level2:SNX-BTC","type":"message"}
1619378330.6901739: {"data":{"sequenceStart":1612844051745,"symbol":"SNX-BTC","changes":{"asks":[["0.00028716","14.05057577","1612844051745"]],"bids":[]},"sequenceEnd":1612844051745},"subject":"trade.l2update","topic":"/market/level2:SNX-BTC","type":"message"}
1619378330.7002308: {"data":{"sequenceStart":1612734157751,"symbol":"ANKR-BTC","changes":{"asks":[["0","0","1612734157751"]],"bids":[]},"sequenceEnd":1612734157751},"subject":"trade.l2update","topic":"/market/level2:ANKR-BTC","type":"message"}
1619378330.70034: {"data":{"sequenceStart":1612844051746,"symbol":"SNX-BTC","changes":{"asks":[["0.00028733","0","1612844051746"]],"bids":[]},"sequenceEnd":1612844051746},"subject":"trade.l2update","topic":"/market/level2:SNX-BTC","type":"message"}
1619378330.700424: {"data":{"sequenceStart":1613277184155,"symbol":"BCHSV-USDT","changes":{"asks":[["243.145","0","1613277184155"]],"bids":[]},"sequenceEnd":1613277184155},"subject":"trade.l2update","topic":"/market/level2:BCHSV-USDT","type":"message"}
1619378330.705028: {"data":{"sequenceStart":1612734157752,"symbol":"ANKR-BTC","changes":{"asks":[["0.0000026186","1640.0018","1612734157752"]],"bids":[]},"sequenceEnd":1612734157752},"subject":"trade.l2update","topic":"/market/level2:ANKR-BTC","type":"message"}
1619378330.7051651: {"data":{"sequenceStart":1612844051747,"symbol":"SNX-BTC","changes":{"asks":[["0.00028716","0","1612844051747"]],"bids":[]},"sequenceEnd":1612844051747},"subject":"trade.l2update","topic":"/market/level2:SNX-BTC","type":"message"}
1619378330.7052429: {"data":{"sequenceStart":1612844051748,"symbol":"SNX-BTC","changes":{"asks":[["0.00028717","0","1612844051748"]],"bids":[]},"sequenceEnd":1612844051748},"subject":"trade.l2update","topic":"/market/level2:SNX-BTC","type":"message"}
1619378330.710216: {"data":{"sequenceStart":1613277184156,"symbol":"BCHSV-USDT","changes":{"asks":[],"bids":[["242.538","0","1613277184156"]]},"sequenceEnd":1613277184156},"subject":"trade.l2update","topic":"/market/level2:BCHSV-USDT","type":"message"}
1619378330.7103539: {"data":{"sequenceStart":1613277184157,"symbol":"BCHSV-USDT","changes":{"asks":[],"bids":[["0","0","1613277184157"]]},"sequenceEnd":1613277184157},"subject":"trade.l2update","topic":"/market/level2:BCHSV-USDT","type":"message"}
1619378330.710409: {"data":{"sequenceStart":1613277184158,"symbol":"BCHSV-USDT","changes":{"asks":[],"bids":[["242.518","0.4008184","1613277184158"]]},"sequenceEnd":1613277184158},"subject":"trade.l2update","topic":"/market/level2:BCHSV-USDT","type":"message"}
1619378330.719455: {"data":{"sequenceStart":1613277184159,"symbol":"BCHSV-USDT","changes":{"asks":[["0","0","1613277184159"]],"bids":[]},"sequenceEnd":1613277184159},"subject":"trade.l2update","topic":"/market/level2:BCHSV-USDT","type":"message"}
1619378330.7195652: {"data":{"sequenceStart":1613277184160,"symbol":"BCHSV-USDT","changes":{"asks":[["243.143","0.6","1613277184160"]],"bids":[]},"sequenceEnd":1613277184160},"subject":"trade.l2update","topic":"/market/level2:BCHSV-USDT","type":"message"}
1619378330.7313569: {"data":{"sequenceStart":1612844051749,"symbol":"SNX-BTC","changes":{"asks":[["0","0","1612844051749"]],"bids":[]},"sequenceEnd":1612844051749},"subject":"trade.l2update","topic":"/market/level2:SNX-BTC","type":"message"}
1619378330.731468: {"data":{"sequenceStart":1612844051750,"symbol":"SNX-BTC","changes":{"asks":[["0.00028715","29.24570683","1612844051750"]],"bids":[]},"sequenceEnd":1612844051750},"subject":"trade.l2update","topic":"/market/level2:SNX-BTC","type":"message"}
1619378330.731549: {"data":{"sequence":"1612734157752","bestAsk":"0.0000026186","size":"46","bestBidSize":"4051.2663","price":"0.0000026071","time":1619378330688,"bestAskSize":"1640.0018","bestBid":"0.0000026033"},"subject":"trade.ticker","topic":"/market/ticker:ANKR-BTC","type":"message"}
1619378330.74201: {"data":{"sequenceStart":1613277184161,"symbol":"BCHSV-USDT","changes":{"asks":[["247.395","0","1613277184161"]],"bids":[]},"sequenceEnd":1613277184161},"subject":"trade.l2update","topic":"/market/level2:BCHSV-USDT","type":"message"}
1619378330.746809: {"data":{"sequenceStart":1612734157753,"symbol":"ANKR-BTC","changes":{"asks":[["0.0000026186","0","1612734157753"]],"bids":[]},"sequenceEnd":1612734157753},"subject":"trade.l2update","topic":"/market/level2:ANKR-BTC","type":"message"}
1619378330.746956: {"data":{"sequenceStart":1613277184162,"symbol":"BCHSV-USDT","changes":{"asks":[],"bids":[["0","0","1613277184162"]]},"sequenceEnd":1613277184162},"subject":"trade.l2update","topic":"/market/level2:BCHSV-USDT","type":"message"}
1619378330.747015: {"data":{"sequenceStart":1613277184163,"symbol":"BCHSV-USDT","changes":{"asks":[],"bids":[["242.52","0.68148185","1613277184163"]]},"sequenceEnd":1613277184163},"subject":"trade.l2update","topic":"/market/level2:BCHSV-USDT","type":"message"}
1619378330.747096: {"data":{"sequenceStart":1612844051751,"symbol":"SNX-BTC","changes":{"asks":[["0","0","1612844051751"]],"bids":[]},"sequenceEnd":1612844051751},"subject":"trade.l2update","topic":"/market/level2:SNX-BTC","type":"message"}
1619378330.7471411: {"data":{"sequenceStart":1612844051752,"symbol":"SNX-BTC","changes":{"asks":[["0.00028733","14.05896433","1612844051752"]],"bids":[]},"sequenceEnd":1612844051752},"subject":"trade.l2update","topic":"/market/level2:SNX-BTC","type":"message"}
1619378330.762151: {"data":{"sequence":"1612844051756","bestAsk":"0.00028715","size":"0.01745248","bestBidSize":"0.19100065","price":"0.00028676","time":1619378330723,"bestAskSize":"29.24570683","bestBid":"0.00028678"},"subject":"trade.ticker","topic":"/market/ticker:SNX-BTC","type":"message"}
1619378330.7622411: {"data":{"sequenceStart":1612844051753,"symbol":"SNX-BTC","changes":{"asks":[["0","0","1612844051753"]],"bids":[]},"sequenceEnd":1612844051753},"subject":"trade.l2update","topic":"/market/level2:SNX-BTC","type":"message"}
1619378330.762306: {"data":{"sequenceStart":1612844051754,"symbol":"SNX-BTC","changes":{"asks":[["0.0002874","9.99999617","1612844051754"]],"bids":[]},"sequenceEnd":1612844051754},"subject":"trade.l2update","topic":"/market/level2:SNX-BTC","type":"message"}
1619378330.7623801: {"data":{"sequenceStart":1612844051755,"symbol":"SNX-BTC","changes":{"asks":[["0","0","1612844051755"]],"bids":[]},"sequenceEnd":1612844051755},"subject":"trade.l2update","topic":"/market/level2:SNX-BTC","type":"message"}
1619378330.7624278: {"data":{"sequenceStart":1612844051756,"symbol":"SNX-BTC","changes":{"asks":[["0.00028718","10.45649469","1612844051756"]],"bids":[]},"sequenceEnd":1612844051756},"subject":"trade.l2update","topic":"/market/level2:SNX-BTC","type":"message"}
1619378330.7765388: {"data":{"sequence":"1613277184163","bestAsk":"242.811","size":"0.08000012","bestBidSize":"5","price":"243.65","time":1619378330733,"bestAskSize":"4.51280965","bestBid":"242.521"},"subject":"trade.ticker","topic":"/market/ticker:BCHSV-USDT","type":"message"}
1619378330.776629: {"data":{"sequenceStart":1613277184164,"symbol":"BCHSV-USDT","changes":{"asks":[["0","0","1613277184164"]],"bids":[]},"sequenceEnd":1613277184164},"subject":"trade.l2update","topic":"/market/level2:BCHSV-USDT","type":"message"}
1619378330.7766972: {"data":{"sequenceStart":1613277184165,"symbol":"BCHSV-USDT","changes":{"asks":[["243.021","3.75096641","1613277184165"]],"bids":[]},"sequenceEnd":1613277184165},"subject":"trade.l2update","topic":"/market/level2:BCHSV-USDT","type":"message"}
1619378330.78185: {"data":{"sequenceStart":1612844051757,"symbol":"SNX-BTC","changes":{"asks":[["0.00028718","0","1612844051757"]],"bids":[]},"sequenceEnd":1612844051757},"subject":"trade.l2update","topic":"/market/level2:SNX-BTC","type":"message"}
1619378330.786355: {"data":{"sequenceStart":1613277184166,"symbol":"BCHSV-USDT","changes":{"asks":[],"bids":[["242.518","0","1613277184166"]]},"sequenceEnd":1613277184166},"subject":"trade.l2update","topic":"/market/level2:BCHSV-USDT","type":"message"}
1619378330.7904232: {"data":{"sequenceStart":1612844051758,"symbol":"SNX-BTC","changes":{"asks":[["0.0002874","0","1612844051758"]],"bids":[]},"sequenceEnd":1612844051758},"subject":"trade.l2update","topic":"/market/level2:SNX-BTC","type":"message"}
1619378330.795017: {"data":{"sequenceStart":1613277184167,"symbol":"BCHSV-USDT","changes":{"asks":[["0","0","1613277184167"]],"bids":[]},"sequenceEnd":1613277184167},"subject":"trade.l2update","topic":"/market/level2:BCHSV-USDT","type":"message"}
1619378330.7951329: {"data":{"sequenceStart":1613277184168,"symbol":"BCHSV-USDT","changes":{"asks":[["246.341","37.33","1613277184168"]],"bids":[]},"sequenceEnd":1613277184168},"subject":"trade.l2update","topic":"/market/level2:BCHSV-USDT","type":"message"}
1619378330.7952142: {"data":{"sequenceStart":1613277184169,"symbol":"BCHSV-USDT","changes":{"asks":[],"bids":[["242.52","0","1613277184169"]]},"sequenceEnd":1613277184169},"subject":"trade.l2update","topic":"/market/level2:BCHSV-USDT","type":"message"}
1619378330.815726: {"data":{"sequenceStart":1613277184170,"symbol":"BCHSV-USDT","changes":{"asks":[],"bids":[["0","0","1613277184170"]]},"sequenceEnd":1613277184170},"subject":"trade.l2update","topic":"/market/level2:BCHSV-USDT","type":"message"}
1619378330.815836: {"data":{"sequenceStart":1613277184171,"symbol":"BCHSV-USDT","changes":{"asks":[],"bids":[["242.522","0.68148185","1613277184171"]]},"sequenceEnd":1613277184171},"subject":"trade.l2update","topic":"/market/level2:BCHSV-USDT","type":"message"}
1619378330.830816: {"data":{"sequence":"1612734157753","bestAsk":"0.0000026187","size":"46","bestBidSize":"4051.2663","price":"0.0000026071","time":1619378330788,"bestAskSize":"4664.7644","bestBid":"0.0000026033"},"subject":"trade.ticker","topic":"/market/ticker:ANKR-BTC","type":"message"}
1619378330.830922: {"data":{"sequenceStart":1613277184172,"symbol":"BCHSV-USDT","changes":{"asks":[["244.357","0","1613277184172"]],"bids":[]},"sequenceEnd":1613277184172},"subject":"trade.l2update","topic":"/market/level2:BCHSV-USDT","type":"message"}
1619378330.831022: {"data":{"sequenceStart":1613277184173,"symbol":"BCHSV-USDT","changes":{"asks":[],"bids":[["241.559","0","1613277184173"]]},"sequenceEnd":1613277184173},"subject":"trade.l2update","topic":"/market/level2:BCHSV-USDT","type":"message"}
1619378330.8311071: {"data":{"sequenceStart":1613277184174,"symbol":"BCHSV-USDT","changes":{"asks":[["243.72","0","1613277184174"]],"bids":[]},"sequenceEnd":1613277184174},"subject":"trade.l2update","topic":"/market/level2:BCHSV-USDT","type":"message"}
1619378330.8359969: {"data":{"sequenceStart":1613277184175,"symbol":"BCHSV-USDT","changes":{"asks":[],"bids":[["242.521","0","1613277184175"]]},"sequenceEnd":1613277184175},"subject":"trade.l2update","topic":"/market/level2:BCHSV-USDT","type":"message"}
1619378330.86019: {"data":{"sequenceStart":1613277184176,"symbol":"BCHSV-USDT","changes":{"asks":[],"bids":[["0","0","1613277184176"]]},"sequenceEnd":1613277184176},"subject":"trade.l2update","topic":"/market/level2:BCHSV-USDT","type":"message"}
1619378330.860268: {"data":{"sequenceStart":1613277184177,"symbol":"BCHSV-USDT","changes":{"asks":[],"bids":[["242.524","5","1613277184177"]]},"sequenceEnd":1613277184177},"subject":"trade.l2update","topic":"/market/level2:BCHSV-USDT","type":"message"}
1619378330.860318: {"data":{"sequenceStart":1612712745606,"symbol":"FET-BTC","changes":{"asks":[["0","0","1612712745606"]],"bids":[]},"sequenceEnd":1612712745606},"subject":"trade.l2update","topic":"/market/level2:FET-BTC","type":"message"}
1619378330.8603468: {"data":{"sequenceStart":1612712745607,"symbol":"FET-BTC","changes":{"asks":[["0.00000785","387.9","1612712745607"]],"bids":[]},"sequenceEnd":1612712745607},"subject":"trade.l2update","topic":"/market/level2:FET-BTC","type":"message"}
1619378330.860387: {"data":{"sequence":"1612844051758","bestAsk":"0.00028715","size":"0.01745248","bestBidSize":"0.19100065","price":"0.00028676","time":1619378330823,"bestAskSize":"29.24570683","bestBid":"0.00028678"},"subject":"trade.ticker","topic":"/market/ticker:SNX-BTC","type":"message"}
1619378330.866843: {"data":{"sequenceStart":1613277184178,"symbol":"BCHSV-USDT","changes":{"asks":[["0","0","1613277184178"]],"bids":[]},"sequenceEnd":1613277184178},"subject":"trade.l2update","topic":"/market/level2:BCHSV-USDT","type":"message"}
1619378330.8668811: {"data":{"sequenceStart":1613277184179,"symbol":"BCHSV-USDT","changes":{"asks":[["243.002","2.99000021","1613277184179"]],"bids":[]},"sequenceEnd":1613277184179},"subject":"trade.l2update","topic":"/market/level2:BCHSV-USDT","type":"message"}
1619378330.866915: {"data":{"sequenceStart":1613277184180,"symbol":"BCHSV-USDT","changes":{"asks":[],"bids":[["0","0","1613277184180"]]},"sequenceEnd":1613277184180},"subject":"trade.l2update","topic":"/market/level2:BCHSV-USDT","type":"message"}
1619378330.866935: {"data":{"sequenceStart":1613277184181,"symbol":"BCHSV-USDT","changes":{"asks":[],"bids":[["242.522","0.78375179","1613277184181"]]},"sequenceEnd":1613277184181},"subject":"trade.l2update","topic":"/market/level2:BCHSV-USDT","type":"message"}
1619378330.871259: {"data":{"sequence":"1613277184181","bestAsk":"242.811","size":"0.08000012","bestBidSize":"5","price":"243.65","time":1619378330832,"bestAskSize":"4.51280965","bestBid":"242.524"},"subject":"trade.ticker","topic":"/market/ticker:BCHSV-USDT","type":"message"}
1619378330.8712971: {"data":{"sequenceStart":1612701563935,"symbol":"DAPPT-BTC","changes":{"asks":[],"bids":[["0","0","1612701563935"]]},"sequenceEnd":1612701563935},"subject":"trade.l2update","topic":"/market/level2:DAPPT-BTC","type":"message"}
1619378330.8713238: {"data":{"sequenceStart":1612701563936,"symbol":"DAPPT-BTC","changes":{"asks":[],"bids":[["0.00000011","20068.6089","1612701563936"]]},"sequenceEnd":1612701563936},"subject":"trade.l2update","topic":"/market/level2:DAPPT-BTC","type":"message"}
1619378330.92815: {"data":{"sequenceStart":1613277184182,"symbol":"BCHSV-USDT","changes":{"asks":[["243.002","0","1613277184182"]],"bids":[]},"sequenceEnd":1613277184182},"subject":"trade.l2update","topic":"/market/level2:BCHSV-USDT","type":"message"}
1619378330.9440699: {"data":{"sequence":"1612712745607","bestAsk":"0.00000775","size":"401.2004","bestBidSize":"357.285","price":"0.00000772","time":1619378330868,"bestAskSize":"1154.0416","bestBid":"0.00000771"},"subject":"trade.ticker","topic":"/market/ticker:FET-BTC","type":"message"}
1619378330.956063: {"data":{"sequenceStart":1612701563937,"symbol":"DAPPT-BTC","changes":{"asks":[["0","0","1612701563937"]],"bids":[]},"sequenceEnd":1612701563937},"subject":"trade.l2update","topic":"/market/level2:DAPPT-BTC","type":"message"}
1619378330.9561758: {"data":{"sequenceStart":1612701563938,"symbol":"DAPPT-BTC","changes":{"asks":[["0.0000001133","6377.0102","1612701563938"]],"bids":[]},"sequenceEnd":1612701563938},"subject":"trade.l2update","topic":"/market/level2:DAPPT-BTC","type":"message"}
1619378330.981457: {"data":{"sequenceStart":1612701563939,"symbol":"DAPPT-BTC","changes":{"asks":[["0","0","1612701563939"]],"bids":[]},"sequenceEnd":1612701563939},"subject":"trade.l2update","topic":"/market/level2:DAPPT-BTC","type":"message"}
1619378330.981567: {"data":{"sequenceStart":1612701563940,"symbol":"DAPPT-BTC","changes":{"asks":[["0.0000001132","1450.4813","1612701563940"]],"bids":[]},"sequenceEnd":1612701563940},"subject":"trade.l2update","topic":"/market/level2:DAPPT-BTC","type":"message"}
1619378330.9816508: {"data":{"sequenceStart":1613277184183,"symbol":"BCHSV-USDT","changes":{"asks":[],"bids":[["242.524","0","1613277184183"]]},"sequenceEnd":1613277184183},"subject":"trade.l2update","topic":"/market/level2:BCHSV-USDT","type":"message"}
1619378330.98174: {"data":{"sequenceStart":1613277184184,"symbol":"BCHSV-USDT","changes":{"asks":[],"bids":[["0","0","1613277184184"]]},"sequenceEnd":1613277184184},"subject":"trade.l2update","topic":"/market/level2:BCHSV-USDT","type":"message"}
1619378330.981766: {"data":{"sequenceStart":1613277184185,"symbol":"BCHSV-USDT","changes":{"asks":[],"bids":[["242.219","6.18268324","1613277184185"]]},"sequenceEnd":1613277184185},"subject":"trade.l2update","topic":"/market/level2:BCHSV-USDT","type":"message"}
1619378330.9817972: {"data":{"sequenceStart":1613277184186,"symbol":"BCHSV-USDT","changes":{"asks":[["0","0","1613277184186"]],"bids":[]},"sequenceEnd":1613277184186},"subject":"trade.l2update","topic":"/market/level2:BCHSV-USDT","type":"message"}
1619378330.9818199: {"data":{"sequenceStart":1613277184187,"symbol":"BCHSV-USDT","changes":{"asks":[["242.934","6.18268324","1613277184187"]],"bids":[]},"sequenceEnd":1613277184187},"subject":"trade.l2update","topic":"/market/level2:BCHSV-USDT","type":"message"}
1619378330.9818492: {"data":{"sequenceStart":1613277184188,"symbol":"BCHSV-USDT","changes":{"asks":[],"bids":[["242.348","2.99","1613277184188"]]},"sequenceEnd":1613277184188},"subject":"trade.l2update","topic":"/market/level2:BCHSV-USDT","type":"message"}
1619378330.9818728: {"data":{"sequenceStart":1613277184189,"symbol":"BCHSV-USDT","changes":{"asks":[],"bids":[["242.348","0","1613277184189"]]},"sequenceEnd":1613277184189},"subject":"trade.l2update","topic":"/market/level2:BCHSV-USDT","type":"message"}
1619378330.992161: {"data":{"sequence":"1612701563940","bestAsk":"0.0000001126","size":"310.5072","bestBidSize":"6450","price":"0.0000001123","time":1619378330930,"bestAskSize":"361.2609","bestBid":"0.0000001115"},"subject":"trade.ticker","topic":"/market/ticker:DAPPT-BTC","type":"message"}
1619378330.992251: {"data":{"sequence":"1613277184189","bestAsk":"242.811","size":"0.08000012","bestBidSize":"0.78375179","price":"243.65","time":1619378330932,"bestAskSize":"4.51280965","bestBid":"242.522"},"subject":"trade.ticker","topic":"/market/ticker:BCHSV-USDT","type":"message"}
