1626995766.243166: {"arg":{"channel":"books-l2-tbt","instId":"TRX-USDT-210924"},"action":"update","data":[{"asks":[["0.05461","282","0","3"]],"bids":[],"ts":"1626995766197","checksum":962776081}]}
1626995766.254307: {"arg":{"channel":"books-l2-tbt","instId":"TRX-USDT-210924"},"action":"update","data":[{"asks":[["0.05499","382","0","1"]],"bids":[],"ts":"1626995766206","checksum":1919354280}]}
1626995766.254459: {"arg":{"channel":"books-l2-tbt","instId":"AUCTION-USDT"},"action":"update","data":[{"asks":[],"bids":[["14.27","0","0","0"]],"ts":"1626995766208","checksum":1100991073}]}
1626995766.313838: {"arg":{"channel":"books-l2-tbt","instId":"TRX-USDT-210924"},"action":"update","data":[{"asks":[["0.05458","1","0","1"],["0.0546","62","0","2"],["0.05461","144","0","2"],["0.05476","0","0","0"]],"bids":[["0.05445","8","0","1"],["0.05414","0","0","0"]],"ts":"1626995766268","checksum":364269095}]}
1626995766.3757172: {"arg":{"channel":"books-l2-tbt","instId":"TRX-USDT-210924"},"action":"update","data":[{"asks":[["0.05459","248","0","2"],["0.05461","289","0","3"],["0.05477","274","0","1"]],"bids":[["0.05442","240","0","2"],["0.05406","776","0","2"]],"ts":"1626995766329","checksum":2071344255}]}
1626995766.3921752: {"arg":{"channel":"books-l2-tbt","instId":"XMR-USDT-SWAP"},"action":"update","data":[{"asks":[["196.44","636","0","2"],["196.46","7","0","1"]],"bids":[],"ts":"1626995766346","checksum":1364947734}]}
1626995766.4137459: {"arg":{"channel":"books-l2-tbt","instId":"XMR-USDT-SWAP"},"action":"update","data":[{"asks":[],"bids":[["196.01","30","0","2"],["195.99","30","0","2"],["195.97","0","0","0"],["195.95","0","0","0"],["195.89","49","0","2"],["195.85","12","0","1"],["195.56","27","0","1"],["195.52","0","0","0"],["194.97","57","0","3"],["194.93","0","0","0"]],"ts":"1626995766367","checksum":885825856}]}
1626995766.456214: {"arg":{"channel":"books-l2-tbt","instId":"XMR-USDT-SWAP"},"action":"update","data":[{"asks":[],"bids":[["196.17","0","0","0"]],"ts":"1626995766408","checksum":15327289}]}
1626995766.457953: {"arg":{"channel":"books-l2-tbt","instId":"TRX-USDT-210924"},"action":"update","data":[{"asks":[["0.05459","124","0","1"],["0.05461","144","0","2"],["0.05477","0","0","0"]],"bids":[["0.05442","120","0","1"],["0.05406","388","0","1"]],"ts":"1626995766411","checksum":-823934746}]}
1626995766.471679: {"arg":{"channel":"books-l2-tbt","instId":"XMR-USDT-SWAP"},"action":"update","data":[{"asks":[["196.48","45","0","2"]],"bids":[["196.09","235","0","2"]],"ts":"1626995766425","checksum":926168509}]}
1626995766.480224: {"arg":{"channel":"books-l2-tbt","instId":"TRX-USDT-210924"},"action":"update","data":[{"asks":[],"bids":[["0.0545","0","0","0"],["0.05443","28","0","2"]],"ts":"1626995766433","checksum":295068440}]}
1626995766.488759: {"arg":{"channel":"books-l2-tbt","instId":"TRX-USDT-210924"},"action":"update","data":[{"asks":[],"bids":[["0.05444","34","0","2"]],"ts":"1626995766442","checksum":-1407995484}]}
1626995766.494157: {"arg":{"channel":"books-l2-tbt","instId":"XMR-USDT-SWAP"},"action":"update","data":[{"asks":[["196.41","3","0","1"],["196.52","61","0","2"],["196.53","94","0","3"]],"bids":[],"ts":"1626995766448","checksum":-1935889578}]}
1626995766.4983659: {"arg":{"channel":"books-l2-tbt","instId":"TRX-USDT-210924"},"action":"update","data":[{"asks":[],"bids":[["0.05445","28","0","2"],["0.05443","8","0","1"]],"ts":"1626995766452","checksum":1381940919}]}
1626995766.5261598: {"arg":{"channel":"books-l2-tbt","instId":"TRX-USDT-210924"},"action":"update","data":[{"asks":[["0.05459","248","0","2"],["0.0546","199","0","3"],["0.05477","274","0","1"]],"bids":[["0.05443","107","0","2"],["0.05407","491","0","3"]],"ts":"1626995766472","checksum":-325622620}]}
1626995766.526232: {"arg":{"channel":"books-l2-tbt","instId":"AUCTION-USDT"},"action":"update","data":[{"asks":[],"bids":[["14.31","159.011605","0","2"]],"ts":"1626995766475","checksum":-2058340696}]}
1626995766.5351832: {"arg":{"channel":"books-l2-tbt","instId":"XMR-USDT-SWAP"},"action":"update","data":[{"asks":[],"bids":[["196.19","1","0","1"]],"ts":"1626995766488","checksum":-2135911942}]}
1626995766.539038: {"arg":{"channel":"books-l2-tbt","instId":"TRX-USDT-210924"},"action":"update","data":[{"asks":[],"bids":[["0.05436","0","0","0"],["0.05435","1","0","1"]],"ts":"1626995766493","checksum":608431930}]}
1626995766.550773: {"arg":{"channel":"books-l2-tbt","instId":"TRX-USDT-210924"},"action":"update","data":[{"asks":[],"bids":[["0.05425","3","0","1"],["0.05424","1","0","1"]],"ts":"1626995766504","checksum":-2000783790}]}
1626995766.55713: {"arg":{"channel":"books-l2-tbt","instId":"XMR-USDT-SWAP"},"action":"update","data":[{"asks":[["196.48","7","0","1"]],"bids":[["196.13","35","0","1"]],"ts":"1626995766510","checksum":-532304583}]}
1626995766.6015859: {"arg":{"channel":"books-l2-tbt","instId":"XMR-USDT-SWAP"},"action":"update","data":[{"asks":[["196.51","66","0","2"],["196.53","28","0","1"]],"bids":[],"ts":"1626995766550","checksum":-1673403056}]}
1626995766.702896: {"arg":{"channel":"books-l2-tbt","instId":"PAY-BTC"},"action":"update","data":[{"asks":[["0.0000014","2870.065","0","3"]],"bids":[],"ts":"1626995766655","checksum":290683904}]}
1626995766.703029: {"arg":{"channel":"books-l2-tbt","instId":"XMR-USDT-SWAP"},"action":"update","data":[{"asks":[["196.51","34","0","1"]],"bids":[],"ts":"1626995766655","checksum":-2088004047}]}
1626995766.722048: {"arg":{"channel":"books-l2-tbt","instId":"OKT-BTC"},"action":"update","data":[{"asks":[],"bids":[["0.00147","14.19651658","0","2"]],"ts":"1626995766669","checksum":188476749}]}
1626995766.729265: {"arg":{"channel":"books-l2-tbt","instId":"XMR-USDT-SWAP"},"action":"update","data":[{"asks":[["196.5","39","0","2"]],"bids":[],"ts":"1626995766676","checksum":1589656008}]}
1626995766.7528782: {"arg":{"channel":"books-l2-tbt","instId":"TRX-USDT-210924"},"action":"update","data":[{"asks":[],"bids":[["0.0544","7","0","1"],["0.05438","4","0","2"]],"ts":"1626995766706","checksum":1563028058}]}
1626995766.796704: {"arg":{"channel":"books-l2-tbt","instId":"PAY-BTC"},"action":"update","data":[{"asks":[["0.00000139","5342.072","0","4"]],"bids":[],"ts":"1626995766748","checksum":2021975078}]}
1626995766.80295: {"arg":{"channel":"books-l2-tbt","instId":"XMR-USDT-SWAP"},"action":"update","data":[{"asks":[],"bids":[["196.09","49","0","1"]],"ts":"1626995766757","checksum":-1987162387}]}
1626995766.8241768: {"arg":{"channel":"books-l2-tbt","instId":"XMR-USDT-SWAP"},"action":"update","data":[{"asks":[["196.49","34","0","1"],["196.51","0","0","0"]],"bids":[],"ts":"1626995766777","checksum":-236160204}]}
1626995766.8354828: {"arg":{"channel":"books-l2-tbt","instId":"ONT-USDT"},"action":"update","data":[{"asks":[["0.6222","688.334745","0","2"],["0.6223","1045.028438","0","2"]],"bids":[],"ts":"1626995766790","checksum":211353493}]}
1626995766.8529222: {"arg":{"channel":"books-l2-tbt","instId":"TRX-USDT-210924"},"action":"update","data":[{"asks":[],"bids":[["0.0544","16","0","2"],["0.05438","1","0","1"]],"ts":"1626995766803","checksum":-2000783790}]}
1626995766.8572931: {"arg":{"channel":"books-l2-tbt","instId":"ONT-USDT"},"action":"update","data":[{"asks":[],"bids":[["0.6216","4048.374312","0","4"]],"ts":"1626995766810","checksum":69608626}]}
1626995766.883633: {"arg":{"channel":"books-l2-tbt","instId":"XMR-USDT-SWAP"},"action":"update","data":[{"asks":[["196.25","0","0","0"],["196.44","7","0","1"],["196.46","636","0","2"]],"bids":[],"ts":"1626995766838","checksum":981751711}]}
1626995766.8890371: {"arg":{"channel":"books-l2-tbt","instId":"OKT-BTC"},"action":"update","data":[{"asks":[],"bids":[["0.001471","7.02290692","0","2"]],"ts":"1626995766843","checksum":-495621698}]}
1626995766.905709: {"arg":{"channel":"books-l2-tbt","instId":"XMR-USDT-SWAP"},"action":"update","data":[{"asks":[],"bids":[["196.09","235","0","2"]],"ts":"1626995766859","checksum":-2082715086}]}
1626995766.918546: {"arg":{"channel":"books-l2-tbt","instId":"ONT-USDT"},"action":"update","data":[{"asks":[],"bids":[["0.6205","972.683796","0","1"],["0.6203","0","0","0"]],"ts":"1626995766871","checksum":83672496}]}
1626995766.9253912: {"arg":{"channel":"books-l2-tbt","instId":"XMR-USDT-SWAP"},"action":"update","data":[{"asks":[["196.44","608","0","2"],["196.46","40","0","2"],["196.48","39","0","2"],["196.49","0","0","0"],["196.5","7","0","1"]],"bids":[],"ts":"1626995766879","checksum":-253400300}]}
1626995766.928714: {"arg":{"channel":"books-l2-tbt","instId":"ONT-USDT"},"action":"update","data":[{"asks":[["0.6223","99.489438","0","1"]],"bids":[["0.6217","945.539","0","1"],["0.6216","3102.835312","0","3"],["0.6204","710","0","1"]],"ts":"1626995766882","checksum":516630157}]}
1626995766.961271: {"arg":{"channel":"books-l2-tbt","instId":"ONT-USDT"},"action":"update","data":[{"asks":[["0.6224","390","0","1"],["0.6227","0","0","0"],["0.6228","402.871384","0","2"],["0.6235","1223.318397","0","1"]],"bids":[["0.6205","2196.002193","0","2"],["0.6202","0","0","0"],["0.6173","0","0","0"]],"ts":"1626995766915","checksum":1812072921}]}
1626995766.9648588: {"arg":{"channel":"books-l2-tbt","instId":"XMR-USDT-SWAP"},"action":"update","data":[{"asks":[["196.29","0","0","0"]],"bids":[],"ts":"1626995766919","checksum":-234901471}]}
1626995766.993802: {"arg":{"channel":"books-l2-tbt","instId":"ONT-USDT"},"action":"update","data":[{"asks":[["0.6222","85","0","1"]],"bids":[],"ts":"1626995766947","checksum":-2119908362}]}
1626995767.002501: {"arg":{"channel":"books-l2-tbt","instId":"ONT-USDT"},"action":"update","data":[{"asks":[["0.6229","1970","0","1"],["0.6232","1418.334745","0","2"]],"bids":[["0.6201","0","0","0"]],"ts":"1626995766957","checksum":-1119019990}]}
1626995767.017772: {"arg":{"channel":"books-l2-tbt","instId":"ONT-USDT"},"action":"update","data":[{"asks":[],"bids":[["0.6218","51","0","1"],["0.6208","405.5","0","1"],["0.6195","449.868423","0","2"]],"ts":"1626995766968","checksum":-1067404109}]}
1626995767.0367: {"arg":{"channel":"books-l2-tbt","instId":"ONT-USDT"},"action":"update","data":[{"asks":[["0.6225","945.539","0","1"],["1.13","0","0","0"]],"bids":[],"ts":"1626995766990","checksum":1939650305}]}
1626995767.04385: {"arg":{"channel":"books-l2-tbt","instId":"ONT-USDT"},"action":"update","data":[{"asks":[],"bids":[["0.6219","6.866926","0","1"],["0.6187","4217","0","2"]],"ts":"1626995766997","checksum":-698498736}]}
1626995767.043923: {"arg":{"channel":"books-l2-tbt","instId":"TRX-USDT-210924"},"action":"update","data":[{"asks":[["0.05451","0","0","0"],["0.05452","16","0","2"]],"bids":[],"ts":"1626995766997","checksum":-2080159345}]}
1626995767.046816: {"arg":{"channel":"books-l2-tbt","instId":"XMR-USDT-SWAP"},"action":"update","data":[{"asks":[["196.4","5","0","1"]],"bids":[],"ts":"1626995767000","checksum":-737517303}]}
1626995767.0594401: {"arg":{"channel":"books-l2-tbt","instId":"ONT-USDT"},"action":"update","data":[{"asks":[],"bids":[["0.6174","1330.02235","0","2"]],"ts":"1626995767009","checksum":668888859}]}
1626995767.065464: {"arg":{"channel":"books-l2-tbt","instId":"ONT-USDT"},"action":"update","data":[{"asks":[["0.6222","0","0","0"],["1.13","13919.895296","0","1"]],"bids":[],"ts":"1626995767020","checksum":629009473}]}
1626995767.076604: {"arg":{"channel":"books-l2-tbt","instId":"ONT-USDT"},"action":"update","data":[{"asks":[["0.6225","1548.873745","0","2"]],"bids":[],"ts":"1626995767029","checksum":-1739205198}]}
1626995767.086496: {"arg":{"channel":"books-l2-tbt","instId":"ONT-USDT"},"action":"update","data":[{"asks":[],"bids":[["0.6218","996.539","0","2"],["0.6217","0","0","0"]],"ts":"1626995767041","checksum":1443848}]}
1626995767.090013: {"arg":{"channel":"books-l2-tbt","instId":"XMR-USDT-SWAP"},"action":"update","data":[{"asks":[["196.59","0","0","0"]],"bids":[],"ts":"1626995767045","checksum":-839151909}]}
1626995767.112591: {"arg":{"channel":"books-l2-tbt","instId":"XMR-USDT-SWAP"},"action":"update","data":[{"asks":[["196.22","33","0","1"],["196.3","0","0","0"],["196.35","250","0","1"],["196.53","58","0","2"]],"bids":[["196.19","0","0","0"]],"ts":"1626995767065","checksum":1539449325}]}
1626995767.1153831: {"arg":{"channel":"books-l2-tbt","instId":"ONT-USDT"},"action":"update","data":[{"asks":[],"bids":[["0.6219","2786.471768","0","2"],["0.6206","486.341898","0","1"],["0.6205","1223.318397","0","1"],["0.6183","599.667797","0","2"],["0.6162","0","0","0"]],"ts":"1626995767069","checksum":-1249027984}]}
1626995767.1276212: {"arg":{"channel":"books-l2-tbt","instId":"TRX-USDT-210924"},"action":"update","data":[{"asks":[["0.05453","0","0","0"]],"bids":[["0.05442","123","0","2"],["0.0544","7","0","1"]],"ts":"1626995767080","checksum":-1052977410}]}
1626995767.13421: {"arg":{"channel":"books-l2-tbt","instId":"XMR-USDT-SWAP"},"action":"update","data":[{"asks":[["196.45","5","0","1"]],"bids":[],"ts":"1626995767086","checksum":-1411426261}]}
1626995767.138249: {"arg":{"channel":"books-l2-tbt","instId":"TRX-USDT-210924"},"action":"update","data":[{"asks":[["0.05452","24","0","3"]],"bids":[],"ts":"1626995767091","checksum":819341332}]}
1626995767.138861: {"arg":{"channel":"books-l2-tbt","instId":"ONT-USDT"},"action":"update","data":[{"asks":[["0.6232","688.334745","0","1"]],"bids":[["0.6212","0","0","0"]],"ts":"1626995767093","checksum":776056809}]}
1626995767.149066: {"arg":{"channel":"books-l2-tbt","instId":"ONT-USDT"},"action":"update","data":[{"asks":[["0.6223","0","0","0"],["0.6225","1649.413578","0","3"],["0.6253","19.423762","0","1"]],"bids":[["0.6216","3203.375145","0","4"],["0.6195","2949.868423","0","3"]],"ts":"1626995767102","checksum":1500692325}]}
1626995767.1539829: {"arg":{"channel":"books-l2-tbt","instId":"XMR-USDT-SWAP"},"action":"update","data":[{"asks":[["197.1","142","0","1"]],"bids":[["195.87","17","0","1"],["195.86","97","0","2"],["195.79","0","0","0"],["195.78","0","0","0"],["195.48","17","0","1"],["195.4","0","0","0"]],"ts":"1626995767106","checksum":399857764}]}
1626995767.158667: {"arg":{"channel":"books-l2-tbt","instId":"ONT-USDT"},"action":"update","data":[{"asks":[["0.6225","1046.078833","0","2"]],"bids":[],"ts":"1626995767112","checksum":305321791}]}
1626995767.17152: {"arg":{"channel":"books-l2-tbt","instId":"ONT-USDT"},"action":"update","data":[{"asks":[["0.6224","1078.334745","0","3"]],"bids":[],"ts":"1626995767125","checksum":-1070057046}]}
1626995767.1720388: {"arg":{"channel":"books-l2-tbt","instId":"XMR-USDT-SWAP"},"action":"update","data":[{"asks":[["196.44","7","0","1"],["196.46","641","0","3"]],"bids":[],"ts":"1626995767126","checksum":-1780647822}]}
1626995767.20046: {"arg":{"channel":"books-l2-tbt","instId":"ONT-USDT"},"action":"update","data":[{"asks":[["0.6247","6081.056624","0","1"]],"bids":[],"ts":"1626995767153","checksum":81555785}]}
1626995767.207642: {"arg":{"channel":"books-l2-tbt","instId":"TRX-USDT-210924"},"action":"update","data":[{"asks":[["0.05452","16","0","2"]],"bids":[],"ts":"1626995767162","checksum":-1052977410}]}
1626995767.211446: {"arg":{"channel":"books-l2-tbt","instId":"XMR-USDT-SWAP"},"action":"update","data":[{"asks":[["196.46","40","0","2"],["196.49","592","0","1"],["196.55","3","0","1"]],"bids":[],"ts":"1626995767166","checksum":1540192795}]}
1626995767.220674: {"arg":{"channel":"books-l2-tbt","instId":"TRX-USDT-210924"},"action":"update","data":[{"asks":[["0.05453","8","0","1"]],"bids":[],"ts":"1626995767174","checksum":1129730363}]}
1626995767.2338161: {"arg":{"channel":"books-l2-tbt","instId":"XMR-USDT-SWAP"},"action":"update","data":[{"asks":[["196.66","233","0","1"],["196.92","0","0","0"]],"bids":[["196.13","219","0","2"],["195.48","0","0","0"]],"ts":"1626995767187","checksum":-674503011}]}
1626995767.241497: {"arg":{"channel":"books-l2-tbt","instId":"TRX-USDT-210924"},"action":"update","data":[{"asks":[["0.0656","0","0","0"],["0.06593","1619","0","1"]],"bids":[],"ts":"1626995767194","checksum":1129730363}]}
1626995767.252054: {"arg":{"channel":"books-l2-tbt","instId":"ONT-USDT"},"action":"update","data":[{"asks":[["0.6225","945.539","0","1"],["0.6227","101.710964","0","1"],["1.13","0","0","0"]],"bids":[["0.6217","101.710964","0","1"],["0.6216","3102.835312","0","3"]],"ts":"1626995767206","checksum":1845405397}]}
1626995767.2558248: {"arg":{"channel":"books-l2-tbt","instId":"XMR-USDT-SWAP"},"action":"update","data":[{"asks":[["196.22","0","0","0"]],"bids":[["196.14","46","0","1"],["195.87","0","0","0"],["195.72","70","0","1"],["195.66","0","0","0"]],"ts":"1626995767208","checksum":408162709}]}
1626995767.2711492: {"arg":{"channel":"books-l2-tbt","instId":"TRX-USDT-210924"},"action":"update","data":[{"asks":[["0.05472","0","0","0"],["0.05476","81","0","1"]],"bids":[],"ts":"1626995767224","checksum":-1603174341}]}
1626995767.277934: {"arg":{"channel":"books-l2-tbt","instId":"XMR-USDT-SWAP"},"action":"update","data":[{"asks":[["196.32","77","0","2"],["196.35","275","0","2"],["196.52","12","0","1"]],"bids":[],"ts":"1626995767229","checksum":1615093693}]}
1626995767.295197: {"arg":{"channel":"books-l2-tbt","instId":"XMR-USDT-SWAP"},"action":"update","data":[{"asks":[["196.49","0","0","0"],["196.51","592","0","1"]],"bids":[],"ts":"1626995767248","checksum":-290176297}]}
1626995767.3170319: {"arg":{"channel":"books-l2-tbt","instId":"XMR-USDT-SWAP"},"action":"update","data":[{"asks":[["196.5","599","0","2"],["196.51","0","0","0"]],"bids":[],"ts":"1626995767270","checksum":170694263}]}
1626995767.338947: {"arg":{"channel":"books-l2-tbt","instId":"XMR-USDT-SWAP"},"action":"update","data":[{"asks":[["196.53","28","0","1"],["196.56","30","0","1"],["197.01","0","0","0"]],"bids":[],"ts":"1626995767293","checksum":-2091677667}]}
1626995767.364019: {"arg":{"channel":"books-l2-tbt","instId":"XMR-USDT-SWAP"},"action":"update","data":[{"asks":[["196.5","7","0","1"],["196.53","620","0","2"]],"bids":[["196.17","1","0","1"],["196.13","35","0","1"]],"ts":"1626995767314","checksum":-862410888}]}
1626995767.379432: {"arg":{"channel":"books-l2-tbt","instId":"XMR-USDT-SWAP"},"action":"update","data":[{"asks":[["196.35","250","0","1"],["196.53","592","0","1"],["196.57","500","0","1"],["196.6","35","0","2"],["196.64","31","0","2"],["197.42","0","0","0"],["197.53","27","0","1"]],"bids":[["196.04","399","0","7"],["196.02","192","0","2"],["196","50","0","2"],["195.98","6","0","1"],["195.96","98","0","3"],["195.94","6","0","1"],["195.92","6","0","1"],["195.89","27","0","1"],["195.88","70","0","1"],["195.86","103","0","3"],["195.84","0","0","0"],["195.8","6","0","1"],["195.76","0","0","0"],["195.75","12","0","1"],["195.6","76","0","2"],["195.51","0","0","0"],["195.02","6","0","1"],["194.92","0","0","0"]],"ts":"1626995767332","checksum":-291209059}]}
1626995767.3880398: {"arg":{"channel":"books-l2-tbt","instId":"FUN-BTC"},"action":"update","data":[{"asks":[],"bids":[["0.000000407","0","0","0"]],"ts":"1626995767342","checksum":-1828732146}]}
1626995767.388146: {"arg":{"channel":"trades","instId":"TRX-USDT-210924"},"data":[{"instId":"TRX-USDT-210924","tradeId":"1200053","px":"0.05447","sz":"13","side":"sell","ts":"1626995767335"}]}
1626995767.4064798: {"arg":{"channel":"books-l2-tbt","instId":"XMR-USDT-SWAP"},"action":"update","data":[{"asks":[["196.51","592","0","1"],["196.52","0","0","0"],["196.53","0","0","0"],["196.59","12","0","1"],["196.62","0","0","0"],["196.68","12","0","1"],["197.11","0","0","0"],["197.18","37","0","2"]],"bids":[["196.02","6","0","1"],["195.9","12","0","1"],["195.85","0","0","0"],["195.8","18","0","2"],["195.75","0","0","0"],["195.7","12","0","1"],["195.65","0","0","0"],["195.51","12","0","1"],["195.46","70","0","1"],["195.31","12","0","1"],["195.26","70","0","1"]],"ts":"1626995767359","checksum":1672738788}]}
1626995767.406852: {"arg":{"channel":"books-l2-tbt","instId":"ONT-USDT"},"action":"update","data":[{"asks":[],"bids":[["0.6195","2547","0","2"]],"ts":"1626995767360","checksum":-1029491614}]}
1626995767.417244: {"arg":{"channel":"tickers","instId":"TRX-USDT-210924"},"data":[{"instType":"FUTURES","instId":"TRX-USDT-210924","last":"0.05447","lastSz":"13","askPx":"0.05451","askSz":"14","bidPx":"0.05448","bidSz":"2","open24h":"0.05332","high24h":"0.05491","low24h":"0.05244","sodUtc0":"0.05345","sodUtc8":"0.05461","volCcy24h":"62429000","vol24h":"62429","ts":"1626995767360"}]}
1626995767.417364: {"arg":{"channel":"books-l2-tbt","instId":"ONT-USDT"},"action":"update","data":[{"asks":[],"bids":[["0.6205","1626.18682","0","2"]],"ts":"1626995767370","checksum":-1641061549}]}
1626995767.421977: {"arg":{"channel":"books-l2-tbt","instId":"XMR-USDT-SWAP"},"action":"update","data":[{"asks":[["196.5","599","0","2"],["196.51","0","0","0"]],"bids":[],"ts":"1626995767375","checksum":1148392965}]}
1626995767.446364: {"arg":{"channel":"books-l2-tbt","instId":"TRX-USDT-210924"},"action":"update","data":[{"asks":[["0.05452","14","0","1"]],"bids":[],"ts":"1626995767399","checksum":-431436214}]}
1626995767.448677: {"arg":{"channel":"books-l2-tbt","instId":"ONT-USDT"},"action":"update","data":[{"asks":[],"bids":[["0.6219","6.866926","0","1"]],"ts":"1626995767401","checksum":1927114997}]}
1626995767.459064: {"arg":{"channel":"books-l2-tbt","instId":"ONT-USDT"},"action":"update","data":[{"asks":[],"bids":[["0.6216","841","0","2"]],"ts":"1626995767412","checksum":-1048152796}]}
1626995767.46516: {"arg":{"channel":"books-l2-tbt","instId":"BTC-USD-210924-42000-P"},"action":"update","data":[{"asks":[["0.342","301","0","1"],["0.3425","0","0","0"]],"bids":[],"ts":"1626995767418","checksum":426803234}]}
1626995767.467499: {"arg":{"channel":"books-l2-tbt","instId":"TRX-USDT-210924"},"action":"update","data":[{"asks":[["0.05457","0","0","0"]],"bids":[],"ts":"1626995767420","checksum":-148929062}]}
1626995767.475986: {"arg":{"channel":"books-l2-tbt","instId":"ONT-USDT"},"action":"update","data":[{"asks":[["0.6225","1047.249964","0","2"],["0.6227","0","0","0"],["1.13","13919.895296","0","1"]],"bids":[],"ts":"1626995767423","checksum":1429512719}]}
1626995767.4828281: {"arg":{"channel":"books-l2-tbt","instId":"XMR-USDT-SWAP"},"action":"update","data":[{"asks":[["196.46","7","0","1"],["196.49","28","0","1"],["196.53","61","0","2"],["196.54","89","0","3"],["196.59","0","0","0"],["196.6","7","0","1"],["196.63","12","0","1"],["196.64","3","0","1"],["196.68","0","0","0"],["197.13","12","0","1"],["197.18","25","0","1"],["197.42","27","0","1"],["197.53","0","0","0"]],"bids":[["195.97","22","0","1"],["195.96","76","0","2"]],"ts":"1626995767436","checksum":123892045}]}
1626995767.504043: {"arg":{"channel":"books-l2-tbt","instId":"XMR-USDT-SWAP"},"action":"update","data":[{"asks":[["196.31","156","0","1"],["196.49","620","0","2"],["196.5","7","0","1"]],"bids":[["195.86","120","0","4"]],"ts":"1626995767458","checksum":1588840986}]}
1626995767.507366: {"arg":{"channel":"books-l2-tbt","instId":"TRX-USDT-210924"},"action":"update","data":[{"asks":[["0.05458","43","0","2"],["0.0546","157","0","2"],["0.05461","1","0","1"],["0.05462","202","0","2"],["0.05478","420","0","2"],["0.05492","0","0","0"],["0.05499","525","0","2"],["0.055","205","0","1"]],"bids":[["0.05427","0","0","0"],["0.05426","212","0","2"],["0.05419","42","0","1"],["0.05415","0","0","0"]],"ts":"1626995767461","checksum":-1041560671}]}
1626995767.516931: {"arg":{"channel":"books-l2-tbt","instId":"TRX-USDT-210924"},"action":"update","data":[{"asks":[],"bids":[["0.05445","42","0","3"],["0.05444","20","0","1"]],"ts":"1626995767470","checksum":-1576920750}]}
1626995767.5242162: {"arg":{"channel":"books-l2-tbt","instId":"XMR-USDT-SWAP"},"action":"update","data":[{"asks":[["196.56","62","0","2"],["196.62","17","0","1"],["196.95","29","0","2"]],"bids":[["195.8","35","0","3"],["195.73","87","0","2"],["195.67","17","0","1"],["195.47","250","0","2"]],"ts":"1626995767478","checksum":1575930037}]}
1626995767.5263119: {"arg":{"channel":"books-l2-tbt","instId":"TRX-USDT-210924"},"action":"update","data":[{"asks":[["0.05458","42","0","1"],["0.0546","158","0","3"],["0.05461","0","0","0"],["0.05462","203","0","3"],["0.05463","0","0","0"],["0.05465","70","0","2"],["0.05469","28","0","2"],["0.0547","1","0","1"],["0.05474","0","0","0"],["0.05476","82","0","2"]],"bids":[],"ts":"1626995767481","checksum":-2078576190}]}
1626995767.5886562: {"arg":{"channel":"books-l2-tbt","instId":"XMR-USDT-SWAP"},"action":"update","data":[{"asks":[],"bids":[["195.97","0","0","0"]],"ts":"1626995767542","checksum":404526056}]}
1626995767.5917509: {"arg":{"channel":"books-l2-tbt","instId":"BTC-USD-210924-42000-P"},"action":"update","data":[{"asks":[["0.341","305","0","2"],["0.3415","0","0","0"]],"bids":[["0.334","0","0","0"],["0.3335","601","0","2"]],"ts":"1626995767544","checksum":-854162226}]}
1626995767.608999: {"arg":{"channel":"books-l2-tbt","instId":"XMR-USDT-SWAP"},"action":"update","data":[{"asks":[["196.47","595","0","2"],["196.49","61","0","2"],["196.53","28","0","1"]],"bids":[["195.89","49","0","2"]],"ts":"1626995767562","checksum":-631351331}]}
1626995767.609152: {"arg":{"channel":"books-l2-tbt","instId":"TRX-USDT-210924"},"action":"update","data":[{"asks":[["0.05459","252","0","3"]],"bids":[],"ts":"1626995767563","checksum":1217972371}]}
1626995767.620468: {"arg":{"channel":"books-l2-tbt","instId":"TRX-USDT-210924"},"action":"update","data":[{"asks":[["0.0546","21","0","2"],["0.05477","0","0","0"]],"bids":[["0.05443","8","0","1"],["0.05434","5","0","1"],["0.05407","103","0","2"]],"ts":"1626995767573","checksum":125300740}]}
1626995767.651604: {"arg":{"channel":"books-l2-tbt","instId":"TRX-USDT-210924"},"action":"update","data":[{"asks":[],"bids":[["0.05425","0","0","0"],["0.05424","4","0","2"]],"ts":"1626995767603","checksum":1975277005}]}
1626995767.664238: {"arg":{"channel":"books-l2-tbt","instId":"ONT-USDT"},"action":"update","data":[{"asks":[["0.624","0","0","0"],["1.1314","181.020619","0","1"]],"bids":[],"ts":"1626995767618","checksum":-1095850753}]}
1626995767.675065: {"arg":{"channel":"books-l2-tbt","instId":"BTC-USD-210924-42000-P"},"action":"update","data":[{"asks":[["0.3405","5","0","1"],["0.341","300","0","1"]],"bids":[["0.3345","0","0","0"],["0.334","5","0","1"],["0.3335","300","0","1"],["0.333","301","0","1"]],"ts":"1626995767628","checksum":-2036540433}]}
1626995767.675547: {"arg":{"channel":"books-l2-tbt","instId":"FUN-BTC"},"action":"update","data":[{"asks":[],"bids":[["0.000000412","6726.74","0","1"]],"ts":"1626995767630","checksum":-1927206994}]}
1626995767.685225: {"arg":{"channel":"books-l2-tbt","instId":"ONT-USDT"},"action":"update","data":[{"asks":[["0.6243","884.031182","0","1"],["1.1314","0","0","0"]],"bids":[],"ts":"1626995767638","checksum":1591369171}]}
1626995767.691863: {"arg":{"channel":"books-l2-tbt","instId":"TRX-USDT-210924"},"action":"update","data":[{"asks":[["0.0546","158","0","3"],["0.05475","260","0","1"]],"bids":[["0.05445","118","0","4"],["0.05434","199","0","2"],["0.05406","776","0","2"]],"ts":"1626995767644","checksum":855329822}]}
1626995767.694634: {"arg":{"channel":"books-l2-tbt","instId":"ONT-USDT"},"action":"update","data":[{"asks":[],"bids":[["0.6208","891.841898","0","2"],["0.6206","0","0","0"]],"ts":"1626995767647","checksum":1433458717}]}
1626995767.701531: {"arg":{"channel":"books-l2-tbt","instId":"TRX-USDT-210924"},"action":"update","data":[{"asks":[],"bids":[["0.05445","104","0","3"],["0.05444","34","0","2"],["0.05425","3","0","1"],["0.05424","1","0","1"]],"ts":"1626995767655","checksum":296610874}]}
1626995767.7126122: {"arg":{"channel":"books-l2-tbt","instId":"TRX-USDT-210924"},"action":"update","data":[{"asks":[["0.05473","0","0","0"],["0.05496","213","0","1"]],"bids":[],"ts":"1626995767666","checksum":1531753151}]}
1626995767.722219: {"arg":{"channel":"books-l2-tbt","instId":"TRX-USDT-210924"},"action":"update","data":[{"asks":[["0.05589","0","0","0"],["0.0559","3","0","1"]],"bids":[],"ts":"1626995767675","checksum":1531753151}]}
1626995767.734671: {"arg":{"channel":"books-l2-tbt","instId":"XMR-USDT-SWAP"},"action":"update","data":[{"asks":[],"bids":[["194.41","0","0","0"]],"ts":"1626995767686","checksum":-631351331}]}
1626995767.755093: {"arg":{"channel":"trades","instId":"XMR-USDT-SWAP"},"data":[{"instId":"XMR-USDT-SWAP","tradeId":"6845127","px":"196.2","sz":"6","side":"buy","ts":"1626995767704"}]}
1626995767.7634912: {"arg":{"channel":"books-l2-tbt","instId":"TRX-USDT-210924"},"action":"update","data":[{"asks":[["0.0546","21","0","2"]],"bids":[["0.05434","5","0","1"],["0.05406","388","0","1"]],"ts":"1626995767717","checksum":-1163489246}]}
1626995767.7683089: {"arg":{"channel":"books-l2-tbt","instId":"OKT-BTC"},"action":"update","data":[{"asks":[],"bids":[["0.00145","4.57","0","2"]],"ts":"1626995767721","checksum":664612605}]}
1626995767.773819: {"arg":{"channel":"books-l2-tbt","instId":"XMR-USDT-SWAP"},"action":"update","data":[{"asks":[["196.52","36","0","1"]],"bids":[],"ts":"1626995767726","checksum":1989387914}]}
1626995767.821314: {"arg":{"channel":"tickers","instId":"XMR-USDT-SWAP"},"data":[{"instType":"SWAP","instId":"XMR-USDT-SWAP","last":"196.2","lastSz":"6","askPx":"196.22","askSz":"103","bidPx":"196.04","bidSz":"139","open24h":"197.32","high24h":"202.54","low24h":"189.85","sodUtc0":"196.66","sodUtc8":"199.56","volCcy24h":"65228.7","vol24h":"652287","ts":"1626995767755"}]}
1626995767.821425: {"arg":{"channel":"books-l2-tbt","instId":"XMR-USDT-SWAP"},"action":"update","data":[{"asks":[],"bids":[["195.27","19","0","2"]],"ts":"1626995767775","checksum":1989387914}]}
1626995767.824739: {"arg":{"channel":"books-l2-tbt","instId":"TRX-USDT-210924"},"action":"update","data":[{"asks":[["0.05461","137","0","1"]],"bids":[["0.05442","258","0","3"],["0.05416","344","0","1"]],"ts":"1626995767777","checksum":714088525}]}
1626995767.881289: {"arg":{"channel":"books-l2-tbt","instId":"DHT-USDT"},"action":"update","data":[{"asks":[["0.794","40","0","1"]],"bids":[],"ts":"1626995767835","checksum":798497741}]}
1626995767.881433: {"arg":{"channel":"books-l2-tbt","instId":"XMR-USDT-SWAP"},"action":"update","data":[{"asks":[],"bids":[["195.26","80","0","2"]],"ts":"1626995767835","checksum":1989387914}]}
1626995767.893883: {"arg":{"channel":"books-l2-tbt","instId":"TRX-USDT-210924"},"action":"update","data":[{"asks":[["0.05459","128","0","2"],["0.05499","143","0","1"]],"bids":[["0.05445","28","0","2"],["0.05442","123","0","2"],["0.05416","0","0","0"],["0.05406","0","0","0"]],"ts":"1626995767848","checksum":427983719}]}
1626995767.9236832: {"arg":{"channel":"books-l2-tbt","instId":"XMR-USDT-SWAP"},"action":"update","data":[{"asks":[["196.46","599","0","2"],["196.47","3","0","1"]],"bids":[],"ts":"1626995767877","checksum":-798025396}]}
1626995767.947165: {"arg":{"channel":"books-l2-tbt","instId":"XMR-USDT-SWAP"},"action":"update","data":[{"asks":[["197.05","28","0","1"]],"bids":[],"ts":"1626995767900","checksum":-798025396}]}
1626995767.958421: {"arg":{"channel":"books-l2-tbt","instId":"TRX-USDT-210924"},"action":"update","data":[{"asks":[["0.05459","4","0","1"]],"bids":[],"ts":"1626995767910","checksum":1887647509}]}
1626995767.9669518: {"arg":{"channel":"books-l2-tbt","instId":"TRX-USDT-210924"},"action":"update","data":[{"asks":[["0.05457","86","0","1"],["0.05461","282","0","2"]],"bids":[["0.05445","104","0","3"],["0.05442","3","0","1"],["0.05434","199","0","2"],["0.05427","253","0","1"],["0.05406","388","0","1"]],"ts":"1626995767920","checksum":-458499358}]}
1626995768.024195: {"arg":{"channel":"books-l2-tbt","instId":"ONT-USDT"},"action":"update","data":[{"asks":[],"bids":[["0.6197","1970","0","1"],["0.6194","0","0","0"]],"ts":"1626995767977","checksum":-247926697}]}
1626995768.028181: {"arg":{"channel":"books-l2-tbt","instId":"TRX-USDT-210924"},"action":"update","data":[{"asks":[["0.05458","146","0","2"],["0.05461","137","0","1"]],"bids":[["0.05445","28","0","2"],["0.05442","123","0","2"],["0.05406","0","0","0"]],"ts":"1626995767981","checksum":104789003}]}
1626995768.08958: {"arg":{"channel":"books-l2-tbt","instId":"TRX-USDT-210924"},"action":"update","data":[{"asks":[["0.05495","382","0","1"]],"bids":[["0.05445","104","0","3"],["0.05406","388","0","1"]],"ts":"1626995768042","checksum":115383013}]}
1626995768.11049: {"arg":{"channel":"books-l2-tbt","instId":"XMR-USDT-SWAP"},"action":"update","data":[{"asks":[],"bids":[["196.17","0","0","0"]],"ts":"1626995768061","checksum":-1127542303}]}
1626995768.128468: {"arg":{"channel":"books-l2-tbt","instId":"ONT-USDT"},"action":"update","data":[{"asks":[],"bids":[["0.6192","978.813384","0","2"]],"ts":"1626995768082","checksum":1840153461}]}
1626995768.143405: {"arg":{"channel":"books-l2-tbt","instId":"TRX-USDT-210924"},"action":"update","data":[{"asks":[["0.05452","0","0","0"],["0.05453","22","0","2"]],"bids":[],"ts":"1626995768095","checksum":-158893985}]}
1626995768.1486762: {"arg":{"channel":"books-l2-tbt","instId":"ONT-USDT"},"action":"update","data":[{"asks":[["0.6229","12349.409","0","2"]],"bids":[],"ts":"1626995768102","checksum":-1865986898}]}
1626995768.150944: {"arg":{"channel":"books-l2-tbt","instId":"TRX-USDT-210924"},"action":"update","data":[{"asks":[],"bids":[["0.05444","20","0","1"],["0.00055","0","0","0"]],"ts":"1626995768104","checksum":-603272420}]}
1626995768.16011: {"arg":{"channel":"books-l2-tbt","instId":"TRX-USDT-210924"},"action":"update","data":[{"asks":[["0.05458","42","0","1"],["0.05461","0","0","0"],["0.05464","158","0","1"],["0.05548","0","0","0"],["0.05551","188","0","1"],["0.05558","0","0","0"],["0.05561","913","0","1"],["0.05564","0","0","0"],["0.05567","908","0","1"],["0.05569","0","0","0"],["0.05572","915","0","1"],["0.05575","0","0","0"],["0.05578","904","0","1"],["0.0558","140","0","1"],["0.05583","898","0","1"]],"bids":[["0.05445","42","0","3"],["0.05406","0","0","0"]],"ts":"1626995768114","checksum":-790843259}]}
1626995768.194852: {"arg":{"channel":"books-l2-tbt","instId":"XMR-USDT-SWAP"},"action":"update","data":[{"asks":[],"bids":[["196.13","221","0","2"]],"ts":"1626995768148","checksum":1364767194}]}
1626995768.203327: {"arg":{"channel":"books-l2-tbt","instId":"TRX-USDT-210924"},"action":"update","data":[{"asks":[["0.05458","0","0","0"],["0.0546","63","0","3"]],"bids":[["0.05445","28","0","2"]],"ts":"1626995768155","checksum":-853799352}]}
1626995768.214567: {"arg":{"channel":"books-l2-tbt","instId":"TRX-USDT-210924"},"action":"update","data":[{"asks":[["0.05453","8","0","1"],["0.05495","525","0","2"],["0.05499","0","0","0"]],"bids":[["0.05428","42","0","1"],["0.05419","0","0","0"],["0.05406","143","0","1"],["0.05405","271","0","1"]],"ts":"1626995768166","checksum":52599143}]}
1626995768.222189: {"arg":{"channel":"books-l2-tbt","instId":"AUCTION-USDT"},"action":"update","data":[{"asks":[],"bids":[["14.31","8","0","1"]],"ts":"1626995768175","checksum":1100991073}]}
1626995768.222317: {"arg":{"channel":"books-l2-tbt","instId":"TRX-USDT-210924"},"action":"update","data":[{"asks":[],"bids":[["0.05445","37","0","3"]],"ts":"1626995768176","checksum":-576046063}]}
1626995768.232915: {"arg":{"channel":"books-l2-tbt","instId":"TRX-USDT-210924"},"action":"update","data":[{"asks":[["0.05454","181","0","3"],["0.0546","337","0","5"]],"bids":[["0.05446","14","0","1"],["0.05445","113","0","4"],["0.05406","531","0","2"]],"ts":"1626995768186","checksum":-837255050}]}
1626995768.2384572: {"arg":{"channel":"books-l2-tbt","instId":"ONT-USDT"},"action":"update","data":[{"asks":[],"bids":[["0.6193","6105.056622","0","2"]],"ts":"1626995768192","checksum":33274581}]}
1626995768.254338: {"arg":{"channel":"books-l2-tbt","instId":"XMR-USDT-SWAP"},"action":"update","data":[{"asks":[],"bids":[["195.96","98","0","3"],["195.89","27","0","1"]],"ts":"1626995768208","checksum":-861166763}]}
1626995768.2717109: {"arg":{"channel":"books-l2-tbt","instId":"TRX-USDT-210924"},"action":"update","data":[{"asks":[["0.05462","202","0","2"],["0.05463","1","0","1"],["0.0547","0","0","0"],["0.05471","1","0","1"]],"bids":[["0.05442","124","0","3"],["0.05441","150","0","2"],["0.05439","1","0","1"],["0.05438","0","0","0"],["0.05437","8","0","2"],["0.05435","0","0","0"],["0.05431","1","0","1"],["0.0543","0","0","0"],["0.05426","213","0","3"],["0.05424","0","0","0"]],"ts":"1626995768225","checksum":1179610243}]}
1626995768.275542: {"arg":{"channel":"books-l2-tbt","instId":"XMR-USDT-SWAP"},"action":"update","data":[{"asks":[],"bids":[["196.24","1","0","1"],["196.06","3","0","1"],["196.01","27","0","1"],["195.83","3","0","1"],["195.77","0","0","0"]],"ts":"1626995768229","checksum":1912863501}]}
1626995768.293045: {"arg":{"channel":"books-l2-tbt","instId":"TRX-USDT-210924"},"action":"update","data":[{"asks":[["0.05466","192","0","1"]],"bids":[["0.05426","216","0","4"],["0.05425","0","0","0"]],"ts":"1626995768246","checksum":-794839808}]}
1626995768.3219972: {"arg":{"channel":"books-l2-tbt","instId":"TRX-USDT-210924"},"action":"update","data":[{"asks":[["0.05462","59","0","1"],["0.05463","144","0","2"],["0.05478","277","0","1"],["0.05495","668","0","3"]],"bids":[["0.05445","105","0","3"],["0.05444","29","0","2"],["0.05442","121","0","2"],["0.05428","143","0","1"],["0.05427","295","0","2"],["0.05426","73","0","3"],["0.05407","246","0","3"],["0.05406","388","0","1"]],"ts":"1626995768268","checksum":-1159159441}]}
1626995768.3340642: {"arg":{"channel":"books-l2-tbt","instId":"TRX-USDT-210924"},"action":"update","data":[{"asks":[],"bids":[["0.05445","85","0","2"]],"ts":"1626995768287","checksum":-806495233}]}
1626995768.344275: {"arg":{"channel":"books-l2-tbt","instId":"TRX-USDT-210924"},"action":"update","data":[{"asks":[],"bids":[["0.05446","35","0","2"]],"ts":"1626995768298","checksum":-418116433}]}
1626995768.3540092: {"arg":{"channel":"books-l2-tbt","instId":"TRX-USDT-210924"},"action":"update","data":[{"asks":[],"bids":[["0.05447","8","0","1"]],"ts":"1626995768309","checksum":1385700767}]}
1626995768.359164: {"arg":{"channel":"books-l2-tbt","instId":"DHT-USDT"},"action":"update","data":[{"asks":[["0.795","0","0","0"]],"bids":[],"ts":"1626995768313","checksum":-564066120}]}
1626995768.364171: {"arg":{"channel":"books-l2-tbt","instId":"TRX-USDT-210924"},"action":"update","data":[{"asks":[["0.05453","0","0","0"],["0.05454","189","0","4"]],"bids":[],"ts":"1626995768317","checksum":-170298262}]}
1626995768.3794591: {"arg":{"channel":"books-l2-tbt","instId":"XMR-USDT-SWAP"},"action":"update","data":[{"asks":[],"bids":[["195.97","22","0","1"],["195.96","76","0","2"]],"ts":"1626995768333","checksum":1801529532}]}
1626995768.379616: {"arg":{"channel":"books-l2-tbt","instId":"ONT-USDT"},"action":"update","data":[{"asks":[],"bids":[["0.6158","3200","0","1"],["0.6144","0","0","0"]],"ts":"1626995768333","checksum":33274581}]}
1626995768.37971: {"arg":{"channel":"books-l2-tbt","instId":"OKT-BTC"},"action":"update","data":[{"asks":[],"bids":[["0.001471","0.24901841","0","1"]],"ts":"1626995768334","checksum":367267798}]}
1626995768.3912032: {"arg":{"channel":"books-l2-tbt","instId":"ONT-USDT"},"action":"update","data":[{"asks":[],"bids":[["0.6211","10380.269","0","1"]],"ts":"1626995768345","checksum":-1662905081}]}
1626995768.395635: {"arg":{"channel":"books-l2-tbt","instId":"TRX-USDT-210924"},"action":"update","data":[{"asks":[["0.05455","0","0","0"],["0.05457","9","0","1"],["0.0546","63","0","3"],["0.05495","286","0","2"]],"bids":[["0.05445","9","0","1"],["0.05444","20","0","1"],["0.05443","17","0","2"],["0.05406","0","0","0"]],"ts":"1626995768348","checksum":-1596035351}]}
1626995768.418321: {"arg":{"channel":"books-l2-tbt","instId":"TRX-USDT-210924"},"action":"update","data":[{"asks":[["0.0546","43","0","2"],["0.05462","79","0","2"]],"bids":[],"ts":"1626995768370","checksum":236359895}]}
1626995768.418935: {"arg":{"channel":"books-l2-tbt","instId":"PAY-BTC"},"action":"update","data":[{"asks":[],"bids":[["0.00000138","3151.777","0","1"]],"ts":"1626995768373","checksum":383034055}]}
1626995768.422243: {"arg":{"channel":"trades","instId":"PAY-BTC"},"data":[{"instId":"PAY-BTC","tradeId":"6071314","px":"0.00000138","sz":"3151.777","side":"sell","ts":"1626995768372"}]}
1626995768.42864: {"arg":{"channel":"books-l2-tbt","instId":"PAY-BTC"},"action":"update","data":[{"asks":[],"bids":[["0.00000138","0","0","0"]],"ts":"1626995768381","checksum":2021975078}]}
1626995768.458703: {"arg":{"channel":"books-l2-tbt","instId":"TRX-USDT-210924"},"action":"update","data":[{"asks":[],"bids":[["0.05446","103","0","3"],["0.05407","634","0","4"]],"ts":"1626995768412","checksum":-825173436}]}
1626995768.461783: {"arg":{"channel":"books-l2-tbt","instId":"ONT-USDT"},"action":"update","data":[{"asks":[],"bids":[["0.5899","0","0","0"]],"ts":"1626995768415","checksum":-1662905081}]}
1626995768.461847: {"arg":{"channel":"books-l2-tbt","instId":"AUCTION-USDT"},"action":"update","data":[{"asks":[],"bids":[["14.24","151.753938","0","1"]],"ts":"1626995768416","checksum":-901825230}]}
1626995768.465941: {"arg":{"channel":"books-l2-tbt","instId":"TRX-USDT-210924"},"action":"update","data":[{"asks":[["0.05459","252","0","3"],["0.05461","145","0","1"],["0.05494","382","0","1"]],"bids":[],"ts":"1626995768420","checksum":1683426889}]}
1626995768.477442: {"arg":{"channel":"books-l2-tbt","instId":"TRX-USDT-210924"},"action":"update","data":[{"asks":[["0.05454","191","0","5"]],"bids":[["0.05451","2","0","1"]],"ts":"1626995768431","checksum":-703549943}]}
1626995768.495709: {"arg":{"channel":"books-l2-tbt","instId":"TRX-USDT-210924"},"action":"update","data":[{"asks":[["0.0559","0","0","0"],["0.05593","3","0","1"]],"bids":[],"ts":"1626995768450","checksum":-703549943}]}
1626995768.533504: {"arg":{"channel":"books-l2-tbt","instId":"ONT-USDT"},"action":"update","data":[{"asks":[],"bids":[["0.5901","294.595831","0","1"]],"ts":"1626995768486","checksum":-1662905081}]}
1626995768.541332: {"arg":{"channel":"books-l2-tbt","instId":"TRX-USDT-210924"},"action":"update","data":[{"asks":[["0.05459","128","0","2"]],"bids":[["0.05427","42","0","1"],["0.05407","246","0","3"]],"ts":"1626995768492","checksum":-1798023274}]}
1626995768.555841: {"arg":{"channel":"tickers","instId":"PAY-BTC"},"data":[{"instType":"SPOT","instId":"PAY-BTC","last":"0.00000138","lastSz":"3151.777","askPx":"0.00000139","askSz":"4702.072","bidPx":"0.00000136","bidSz":"6884.955","open24h":"0.00000136","high24h":"0.00000144","low24h":"0.00000136","sodUtc0":"0.00000138","sodUtc8":"0.00000138","volCcy24h":"45.109","vol24h":"32757700.19","ts":"1626995768498"}]}
1626995768.5992289: {"arg":{"channel":"books-l2-tbt","instId":"TRX-USDT-210924"},"action":"update","data":[{"asks":[["0.05461","290","0","2"]],"bids":[["0.05446","35","0","2"],["0.05442","240","0","3"],["0.05413","359","0","1"]],"ts":"1626995768553","checksum":75741601}]}
1626995768.602954: {"arg":{"channel":"books-l2-tbt","instId":"DHT-USDT"},"action":"update","data":[{"asks":[["0.797","423.1407","0","1"]],"bids":[],"ts":"1626995768557","checksum":653320199}]}
1626995768.6205812: {"arg":{"channel":"books-l2-tbt","instId":"TRX-USDT-210924"},"action":"update","data":[{"asks":[],"bids":[["0.05445","0","0","0"]],"ts":"1626995768574","checksum":853278362}]}
1626995768.624459: {"arg":{"channel":"books-l2-tbt","instId":"OKT-BTC"},"action":"update","data":[{"asks":[],"bids":[["0.00145","11.4419931","0","3"]],"ts":"1626995768578","checksum":-387370544}]}
1626995768.663905: {"arg":{"channel":"trades","instId":"OKT-BTC"},"data":[{"instId":"OKT-BTC","tradeId":"3406234","px":"0.001473","sz":"0.63289998","side":"buy","ts":"1626995768615"}]}
1626995768.669921: {"arg":{"channel":"books-l2-tbt","instId":"TRX-USDT-210924"},"action":"update","data":[{"asks":[],"bids":[["0.05408","388","0","1"]],"ts":"1626995768624","checksum":-751408287}]}
1626995768.6807098: {"arg":{"channel":"tickers","instId":"OKT-BTC"},"data":[{"instType":"SPOT","instId":"OKT-BTC","last":"0.001473","lastSz":"0.63289998","askPx":"0.001475","askSz":"10.622771","bidPx":"0.001471","bidSz":"2.64188214","open24h":"0.001402","high24h":"0.001489","low24h":"0.001387","sodUtc0":"0.001408","sodUtc8":"0.001437","volCcy24h":"17.1573795","vol24h":"12035.19121555","ts":"1626995768624"}]}
1626995768.702218: {"arg":{"channel":"books-l2-tbt","instId":"TRX-USDT-210924"},"action":"update","data":[{"asks":[["0.05454","177","0","4"]],"bids":[["0.05426","70","0","2"],["0.05425","3","0","1"]],"ts":"1626995768655","checksum":-152336245}]}
1626995768.7138329: {"arg":{"channel":"books-l2-tbt","instId":"TRX-USDT-210924"},"action":"update","data":[{"asks":[["0.05455","14","0","1"]],"bids":[],"ts":"1626995768667","checksum":-217188536}]}
1626995768.7139862: {"arg":{"channel":"books-l2-tbt","instId":"XMR-USDT-SWAP"},"action":"update","data":[{"asks":[],"bids":[["196.13","35","0","1"]],"ts":"1626995768668","checksum":963988615}]}
1626995768.752334: {"arg":{"channel":"books-l2-tbt","instId":"AUCTION-USDT"},"action":"update","data":[{"asks":[],"bids":[["13.78","1.124663","0","1"]],"ts":"1626995768705","checksum":-901825230}]}
1626995768.7864718: {"arg":{"channel":"books-l2-tbt","instId":"TRX-USDT-210924"},"action":"update","data":[{"asks":[],"bids":[["0.05446","55","0","3"],["0.05444","0","0","0"]],"ts":"1626995768739","checksum":318513679}]}
1626995768.806865: {"arg":{"channel":"books-l2-tbt","instId":"TRX-USDT-210924"},"action":"update","data":[{"asks":[],"bids":[["0.05434","5","0","1"],["0.05413","0","0","0"]],"ts":"1626995768759","checksum":32077988}]}
1626995768.8236082: {"arg":{"channel":"books-l2-tbt","instId":"ONT-USDT"},"action":"update","data":[{"asks":[],"bids":[["0.6083","1768.976523","0","1"]],"ts":"1626995768777","checksum":-1662905081}]}
1626995768.865623: {"arg":{"channel":"books-l2-tbt","instId":"TRX-USDT-210924"},"action":"update","data":[{"asks":[],"bids":[["0.05442","392","0","4"],["0.05408","776","0","2"]],"ts":"1626995768819","checksum":2088658378}]}
1626995768.899478: {"arg":{"channel":"books-l2-tbt","instId":"XMR-USDT-SWAP"},"action":"update","data":[{"asks":[],"bids":[["196.24","0","0","0"]],"ts":"1626995768854","checksum":-121795374}]}
1626995768.9202712: {"arg":{"channel":"books-l2-tbt","instId":"XMR-USDT-SWAP"},"action":"update","data":[{"asks":[["196.48","79","0","3"]],"bids":[["196.13","221","0","2"]],"ts":"1626995768874","checksum":-248577021}]}
1626995768.945251: {"arg":{"channel":"books-l2-tbt","instId":"ONT-USDT"},"action":"update","data":[{"asks":[],"bids":[["0.6211","19913.585","0","2"]],"ts":"1626995768899","checksum":805847647}]}
1626995768.959083: {"arg":{"channel":"books-l2-tbt","instId":"TRX-USDT-210924"},"action":"update","data":[{"asks":[["0.05592","3","0","1"],["0.05593","0","0","0"]],"bids":[["0.05426","73","0","3"],["0.05425","0","0","0"]],"ts":"1626995768912","checksum":1801623742}]}
1626995768.9772968: {"arg":{"channel":"books-l2-tbt","instId":"XMR-USDT-SWAP"},"action":"update","data":[{"asks":[],"bids":[["196.27","1","0","1"]],"ts":"1626995768929","checksum":1949409350}]}
1626995768.996623: {"arg":{"channel":"books-l2-tbt","instId":"XMR-USDT-SWAP"},"action":"update","data":[{"asks":[["196.48","39","0","2"],["196.52","0","0","0"]],"bids":[],"ts":"1626995768950","checksum":630254212}]}
1626995769.030315: {"arg":{"channel":"books-l2-tbt","instId":"TRX-USDT-210924"},"action":"update","data":[{"asks":[],"bids":[["0.05446","41","0","2"]],"ts":"1626995768976","checksum":243370224}]}
1626995769.0316212: {"arg":{"channel":"books-l2-tbt","instId":"TRX-USDT-210924"},"action":"update","data":[{"asks":[],"bids":[["0.05447","22","0","2"],["0.05426","70","0","2"],["0.05425","3","0","1"]],"ts":"1626995768985","checksum":-929663751}]}
1626995769.105382: {"arg":{"channel":"books-l2-tbt","instId":"TRX-USDT-210924"},"action":"update","data":[{"asks":[],"bids":[["0.05443","18","0","3"],["0.05442","391","0","3"],["0.0544","8","0","2"],["0.05439","0","0","0"],["0.05432","1","0","1"],["0.05431","0","0","0"]],"ts":"1626995769058","checksum":1432728013}]}
1626995769.121171: {"arg":{"channel":"books-l2-tbt","instId":"AUCTION-USDT"},"action":"update","data":[{"asks":[],"bids":[["14.01","9.636099","0","3"]],"ts":"1626995769073","checksum":-901825230}]}
1626995769.14825: {"arg":{"channel":"books-l2-tbt","instId":"TRX-USDT-210924"},"action":"update","data":[{"asks":[],"bids":[["0.05426","73","0","3"],["0.05425","0","0","0"]],"ts":"1626995769100","checksum":1349480045}]}
1626995769.209056: {"arg":{"channel":"books-l2-tbt","instId":"TRX-USDT-210924"},"action":"update","data":[{"asks":[],"bids":[["0.05447","8","0","1"],["0.05446","55","0","3"]],"ts":"1626995769162","checksum":-284432534}]}
1626995769.2368782: {"arg":{"channel":"books-l2-tbt","instId":"XMR-USDT-SWAP"},"action":"update","data":[{"asks":[["196.37","25","0","1"]],"bids":[],"ts":"1626995769190","checksum":-1723746831}]}
1626995769.2697442: {"arg":{"channel":"books-l2-tbt","instId":"TRX-USDT-210924"},"action":"update","data":[{"asks":[],"bids":[["0.05426","70","0","2"],["0.05425","3","0","1"]],"ts":"1626995769222","checksum":-876723993}]}
1626995769.280766: {"arg":{"channel":"books-l2-tbt","instId":"ONT-USDT"},"action":"update","data":[{"asks":[["0.6224","2023.873745","0","4"],["0.6225","101.710964","0","1"]],"bids":[],"ts":"1626995769235","checksum":-180355146}]}
1626995769.291696: {"arg":{"channel":"books-l2-tbt","instId":"TRX-USDT-210924"},"action":"update","data":[{"asks":[],"bids":[["0.05451","0","0","0"]],"ts":"1626995769245","checksum":-373205207}]}
1626995769.293995: {"arg":{"channel":"trades","instId":"XMR-USDT-SWAP"},"data":[{"instId":"XMR-USDT-SWAP","tradeId":"6845128","px":"196.27","sz":"1","side":"sell","ts":"1626995769245"}]}
1626995769.300164: {"arg":{"channel":"books-l2-tbt","instId":"XMR-USDT-SWAP"},"action":"update","data":[{"asks":[],"bids":[["196.27","0","0","0"]],"ts":"1626995769254","checksum":402588407}]}
1626995769.324029: {"arg":{"channel":"books-l2-tbt","instId":"XMR-USDT-SWAP"},"action":"update","data":[{"asks":[["196.45","47","0","2"]],"bids":[["196.13","0","0","0"]],"ts":"1626995769274","checksum":1095421834}]}
1626995769.3241951: {"arg":{"channel":"books-l2-tbt","instId":"TRX-USDT-210924"},"action":"update","data":[{"asks":[],"bids":[["0.05443","17","0","2"],["0.05441","151","0","3"],["0.0544","7","0","1"],["0.05438","1","0","1"],["0.05437","7","0","1"],["0.05436","1","0","1"],["0.05432","0","0","0"],["0.0543","1","0","1"],["0.05426","69","0","1"],["0.05425","4","0","2"]],"ts":"1626995769275","checksum":122008645}]}
1626995769.3260748: {"arg":{"channel":"tickers","instId":"XMR-USDT-SWAP"},"data":[{"instType":"SWAP","instId":"XMR-USDT-SWAP","last":"196.27","lastSz":"1","askPx":"196.31","askSz":"156","bidPx":"196.17","bidSz":"1","open24h":"197.32","high24h":"202.54","low24h":"189.85","sodUtc0":"196.66","sodUtc8":"199.56","volCcy24h":"65228.8","vol24h":"652288","ts":"1626995769275"}]}
1626995769.334562: {"arg":{"channel":"books-l2-tbt","instId":"ONT-USDT"},"action":"update","data":[{"asks":[],"bids":[["0.6102","567.84018","0","1"]],"ts":"1626995769287","checksum":-180355146}]}
1626995769.338049: {"arg":{"channel":"books-l2-tbt","instId":"BTC-USD-210924-42000-P"},"action":"update","data":[{"asks":[["0.341","0","0","0"],["0.3415","300","0","1"]],"bids":[],"ts":"1626995769291","checksum":-639600716}]}
1626995769.342995: {"arg":{"channel":"books-l2-tbt","instId":"ONT-USDT"},"action":"update","data":[{"asks":[["0.6225","0","0","0"],["1.1314","181.020619","0","1"]],"bids":[],"ts":"1626995769297","checksum":-1607679710}]}
1626995769.353806: {"arg":{"channel":"books-l2-tbt","instId":"ONT-USDT"},"action":"update","data":[{"asks":[["0.6227","103.023816","0","1"],["1.1314","0","0","0"]],"bids":[],"ts":"1626995769308","checksum":1792976256}]}
1626995769.362265: {"arg":{"channel":"books-l2-tbt","instId":"TRX-USDT-210924"},"action":"update","data":[{"asks":[["0.05461","294","0","3"]],"bids":[],"ts":"1626995769315","checksum":1455466367}]}
1626995769.379344: {"arg":{"channel":"books-l2-tbt","instId":"XMR-USDT-SWAP"},"action":"update","data":[{"asks":[],"bids":[["195.97","0","0","0"],["195.9","0","0","0"],["195.89","49","0","2"],["195.86","132","0","5"],["195.8","23","0","2"],["195.76","12","0","1"],["195.51","0","0","0"],["195.47","262","0","3"],["195.31","0","0","0"],["195.27","31","0","3"]],"ts":"1626995769333","checksum":1925270216}]}
1626995769.3831732: {"arg":{"channel":"books-l2-tbt","instId":"ONT-USDT"},"action":"update","data":[{"asks":[],"bids":[["0.6216","51","0","1"]],"ts":"1626995769338","checksum":-1287685437}]}
1626995769.383233: {"arg":{"channel":"books-l2-tbt","instId":"OKT-BTC"},"action":"update","data":[{"asks":[["0.001476","0","0","0"]],"bids":[],"ts":"1626995769338","checksum":558755541}]}
1626995769.4003022: {"arg":{"channel":"books-l2-tbt","instId":"TRX-USDT-210924"},"action":"update","data":[{"asks":[["0.05591","3","0","1"],["0.05592","0","0","0"]],"bids":[],"ts":"1626995769346","checksum":1455466367}]}
1626995769.400407: {"arg":{"channel":"books-l2-tbt","instId":"FUN-BTC"},"action":"update","data":[{"asks":[],"bids":[["0.000000412","0","0","0"]],"ts":"1626995769350","checksum":-1828732146}]}
1626995769.4004412: {"arg":{"channel":"books-l2-tbt","instId":"XMR-USDT-SWAP"},"action":"update","data":[{"asks":[["196.37","63","0","2"]],"bids":[["196.09","186","0","1"],["196.04","353","0","6"],["196","6","0","1"]],"ts":"1626995769353","checksum":1758635850}]}
1626995769.400488: {"arg":{"channel":"books-l2-tbt","instId":"BTC-USD-210924-42000-P"},"action":"update","data":[{"asks":[["0.3405","0","0","0"],["0.341","5","0","1"]],"bids":[],"ts":"1626995769353","checksum":841790327}]}
1626995769.405259: {"arg":{"channel":"books-l2-tbt","instId":"TRX-USDT-210924"},"action":"update","data":[{"asks":[["0.05465","77","0","3"]],"bids":[],"ts":"1626995769357","checksum":1347061763}]}
1626995769.416821: {"arg":{"channel":"books-l2-tbt","instId":"ONT-USDT"},"action":"update","data":[{"asks":[],"bids":[["0.6211","10380.269","0","1"]],"ts":"1626995769371","checksum":534064539}]}
1626995769.422098: {"arg":{"channel":"books-l2-tbt","instId":"BTC-USD-210924-42000-P"},"action":"update","data":[{"asks":[],"bids":[["0.334","305","0","2"],["0.3335","0","0","0"]],"ts":"1626995769375","checksum":-1954981264}]}
1626995769.424636: {"arg":{"channel":"books-l2-tbt","instId":"TRX-USDT-210924"},"action":"update","data":[{"asks":[],"bids":[["0.05442","392","0","4"],["0.05441","150","0","2"],["0.05439","1","0","1"],["0.05438","0","0","0"],["0.05431","1","0","1"],["0.0543","0","0","0"]],"ts":"1626995769378","checksum":239403932}]}
1626995769.4317708: {"arg":{"channel":"books-l2-tbt","instId":"ONT-USDT"},"action":"update","data":[{"asks":[],"bids":[["0.6208","405.5","0","1"],["0.6207","1386.341898","0","2"]],"ts":"1626995769384","checksum":-1148667604}]}
1626995769.4399161: {"arg":{"channel":"books-l2-tbt","instId":"ONT-USDT"},"action":"update","data":[{"asks":[],"bids":[["0.6218","51","0","1"],["0.6217","1047.249964","0","2"]],"ts":"1626995769390","checksum":1504250926}]}
1626995769.440056: {"arg":{"channel":"books-l2-tbt","instId":"OKT-BTC"},"action":"update","data":[{"asks":[["0.001475","11.24535514","0","2"]],"bids":[],"ts":"1626995769390","checksum":1630093641}]}
1626995769.4460459: {"arg":{"channel":"books-l2-tbt","instId":"TRX-USDT-210924"},"action":"update","data":[{"asks":[["0.05455","0","0","0"],["0.05456","22","0","1"]],"bids":[],"ts":"1626995769399","checksum":-1860043353}]}
1626995769.449754: {"arg":{"channel":"books-l2-tbt","instId":"ONT-USDT"},"action":"update","data":[{"asks":[["0.6224","1420.539","0","3"]],"bids":[],"ts":"1626995769401","checksum":-1960834878}]}
1626995769.456674: {"arg":{"channel":"books-l2-tbt","instId":"TRX-USDT-210924"},"action":"update","data":[{"asks":[["0.05454","191","0","5"]],"bids":[],"ts":"1626995769409","checksum":-239960205}]}
1626995769.4591172: {"arg":{"channel":"books-l2-tbt","instId":"OKT-BTC"},"action":"update","data":[{"asks":[["0.001475","10.622771","0","1"]],"bids":[],"ts":"1626995769412","checksum":558755541}]}
1626995769.459208: {"arg":{"channel":"books-l2-tbt","instId":"ONT-USDT"},"action":"update","data":[{"asks":[],"bids":[["0.6217","945.539","0","1"],["0.6212","103.023816","0","1"]],"ts":"1626995769413","checksum":-1872070023}]}
1626995769.4715772: {"arg":{"channel":"books-l2-tbt","instId":"ONT-USDT"},"action":"update","data":[{"asks":[["0.6223","3183.125104","0","1"],["1.13","0","0","0"]],"bids":[],"ts":"1626995769422","checksum":-459615895}]}
1626995769.471753: {"arg":{"channel":"books-l2-tbt","instId":"AUCTION-USDT"},"action":"update","data":[{"asks":[],"bids":[["14.24","0","0","0"]],"ts":"1626995769424","checksum":1100991073}]}
1626995769.484162: {"arg":{"channel":"books-l2-tbt","instId":"TRX-USDT-210924"},"action":"update","data":[{"asks":[],"bids":[["0.05446","34","0","2"],["0.05443","9","0","1"],["0.05425","1","0","1"],["0.05423","3","0","1"]],"ts":"1626995769431","checksum":534671950}]}
1626995769.4842591: {"arg":{"channel":"books-l2-tbt","instId":"FUN-BTC"},"action":"update","data":[{"asks":[],"bids":[["0.000000451","0","0","0"]],"ts":"1626995769435","checksum":1771737504}]}
1626995769.484328: {"arg":{"channel":"books-l2-tbt","instId":"XMR-USDT-SWAP"},"action":"update","data":[{"asks":[["196.47","35","0","2"],["196.49","28","0","1"]],"bids":[["196.09","0","0","0"]],"ts":"1626995769437","checksum":-1012405560}]}
1626995769.489492: {"arg":{"channel":"books-l2-tbt","instId":"OKT-BTC"},"action":"update","data":[{"asks":[["0.001476","0.87832741","0","1"]],"bids":[],"ts":"1626995769443","checksum":-174062401}]}
1626995769.4895518: {"arg":{"channel":"books-l2-tbt","instId":"ONT-USDT"},"action":"update","data":[{"asks":[["0.6223","4128.664104","0","2"],["0.6224","475","0","2"],["0.6227","733.023816","0","2"]],"bids":[["0.6217","0","0","0"],["0.621","0","0","0"]],"ts":"1626995769444","checksum":-1382875966}]}
1626995769.50485: {"arg":{"channel":"books-l2-tbt","instId":"XMR-USDT-SWAP"},"action":"update","data":[{"asks":[["196.31","228","0","3"],["196.37","38","0","1"]],"bids":[["196.06","0","0","0"],["196","9","0","2"],["195.97","98","0","1"],["195.83","0","0","0"],["195.77","3","0","1"],["195.62","0","0","0"]],"ts":"1626995769458","checksum":2085717969}]}
1626995769.5068119: {"arg":{"channel":"books-l2-tbt","instId":"TRX-USDT-210924"},"action":"update","data":[{"asks":[["0.05454","177","0","4"],["0.05455","14","0","1"]],"bids":[],"ts":"1626995769460","checksum":-1928212518}]}
1626995769.514255: {"arg":{"channel":"books-l2-tbt","instId":"ONT-USDT"},"action":"update","data":[{"asks":[],"bids":[["0.6211","0","0","0"]],"ts":"1626995769466","checksum":-375234394}]}
1626995769.5274298: {"arg":{"channel":"books-l2-tbt","instId":"BTC-USD-210924-42000-P"},"action":"update","data":[{"asks":[],"bids":[["0.3345","5","0","1"],["0.334","300","0","1"]],"ts":"1626995769480","checksum":1063707503}]}
1626995769.527585: {"arg":{"channel":"books-l2-tbt","instId":"TRX-USDT-210924"},"action":"update","data":[{"asks":[["0.05455","0","0","0"]],"bids":[],"ts":"1626995769481","checksum":431972716}]}
1626995769.53531: {"arg":{"channel":"books-l2-tbt","instId":"ONT-USDT"},"action":"update","data":[{"asks":[],"bids":[["0.6207","900","0","1"],["0.6206","486.341898","0","1"]],"ts":"1626995769487","checksum":660491696}]}
1626995769.5377228: {"arg":{"channel":"books-l2-tbt","instId":"TRX-USDT-210924"},"action":"update","data":[{"asks":[["0.05454","191","0","5"]],"bids":[],"ts":"1626995769491","checksum":534671950}]}
1626995769.5547688: {"arg":{"channel":"books-l2-tbt","instId":"FUN-BTC"},"action":"update","data":[{"asks":[],"bids":[["0.000000452","131439.69","0","1"]],"ts":"1626995769509","checksum":-1552966004}]}
1626995769.573812: {"arg":{"channel":"books-l2-tbt","instId":"DHT-USDT"},"action":"update","data":[{"asks":[["0.797","0","0","0"]],"bids":[],"ts":"1626995769527","checksum":-564066120}]}
1626995769.5742369: {"arg":{"channel":"books-l2-tbt","instId":"ONT-USDT"},"action":"update","data":[{"asks":[["0.6224","578.023816","0","3"],["0.6227","630","0","1"]],"bids":[["0.6212","0","0","0"],["0.6209","103.023816","0","1"]],"ts":"1626995769529","checksum":1366399128}]}
1626995769.585483: {"arg":{"channel":"books-l2-tbt","instId":"ONT-USDT"},"action":"update","data":[{"asks":[["0.6229","1970","0","1"]],"bids":[],"ts":"1626995769539","checksum":-1377961788}]}
1626995769.587618: {"arg":{"channel":"books-l2-tbt","instId":"TRX-USDT-210924"},"action":"update","data":[{"asks":[["0.0559","3","0","1"],["0.05591","0","0","0"]],"bids":[],"ts":"1626995769541","checksum":534671950}]}
1626995769.596242: {"arg":{"channel":"books-l2-tbt","instId":"ONT-USDT"},"action":"update","data":[{"asks":[["0.6222","351.838861","0","1"],["0.6223","3183.125104","0","1"],["1.1288","0","0","0"]],"bids":[],"ts":"1626995769550","checksum":-228900491}]}
1626995769.606872: {"arg":{"channel":"books-l2-tbt","instId":"XMR-USDT-SWAP"},"action":"update","data":[{"asks":[["196.45","110","0","4"],["196.47","3","0","1"],["196.48","7","0","1"],["197.1","0","0","0"]],"bids":[],"ts":"1626995769561","checksum":94139085}]}
1626995769.629387: {"arg":{"channel":"books-l2-tbt","instId":"XMR-USDT-SWAP"},"action":"update","data":[{"asks":[["196.46","7","0","1"]],"bids":[],"ts":"1626995769582","checksum":-749359657}]}
1626995769.648927: {"arg":{"channel":"books-l2-tbt","instId":"XMR-USDT-SWAP"},"action":"update","data":[{"asks":[["196.46","607","0","2"]],"bids":[],"ts":"1626995769602","checksum":1770989615}]}
1626995769.65969: {"arg":{"channel":"books-l2-tbt","instId":"ONT-USDT"},"action":"update","data":[{"asks":[],"bids":[["0.6206","0","0","0"],["0.6205","2112.528718","0","3"]],"ts":"1626995769613","checksum":-1550439591}]}
1626995769.681014: {"arg":{"channel":"books-l2-tbt","instId":"ONT-USDT"},"action":"update","data":[{"asks":[],"bids":[["0.6216","996.539","0","2"]],"ts":"1626995769633","checksum":2048898420}]}
1626995769.681141: {"arg":{"channel":"books-l2-tbt","instId":"FUN-BTC"},"action":"update","data":[{"asks":[],"bids":[["0.000000403","6876.94","0","1"]],"ts":"1626995769634","checksum":-849563155}]}
1626995769.693669: {"arg":{"channel":"books-l2-tbt","instId":"FUN-BTC"},"action":"update","data":[{"asks":[],"bids":[["0.000000452","0","0","0"]],"ts":"1626995769646","checksum":-1924357789}]}
1626995769.701199: {"arg":{"channel":"books-l2-tbt","instId":"ONT-USDT"},"action":"update","data":[{"asks":[["0.6223","4128.664104","0","2"]],"bids":[],"ts":"1626995769654","checksum":-892497355}]}
1626995769.709871: {"arg":{"channel":"books-l2-tbt","instId":"DHT-USDT"},"action":"update","data":[{"asks":[],"bids":[["0.734","2350","0","1"]],"ts":"1626995769663","checksum":-172509966}]}
1626995769.716202: {"arg":{"channel":"books-l2-tbt","instId":"XMR-USDT-SWAP"},"action":"update","data":[{"asks":[["196.46","658","0","2"]],"bids":[],"ts":"1626995769669","checksum":263946437}]}
1626995769.719876: {"arg":{"channel":"books-l2-tbt","instId":"DHT-USDT"},"action":"update","data":[{"asks":[],"bids":[["0.734","0","0","0"]],"ts":"1626995769673","checksum":-564066120}]}
1626995769.721992: {"arg":{"channel":"books-l2-tbt","instId":"AUCTION-USDT"},"action":"update","data":[{"asks":[["15.01","155.904417","0","3"]],"bids":[["14.28","151.328857","0","1"]],"ts":"1626995769676","checksum":-867438323}]}
1626995769.7291892: {"arg":{"channel":"books-l2-tbt","instId":"XMR-USDT-SWAP"},"action":"update","data":[{"asks":[["197.07","142","0","1"]],"bids":[["194.12","0","0","0"]],"ts":"1626995769683","checksum":263946437}]}
1626995769.772185: {"arg":{"channel":"books-l2-tbt","instId":"XMR-USDT-SWAP"},"action":"update","data":[{"asks":[["196.46","7","0","1"]],"bids":[],"ts":"1626995769725","checksum":-749359657}]}
1626995769.791722: {"arg":{"channel":"books-l2-tbt","instId":"XMR-USDT-SWAP"},"action":"update","data":[{"asks":[["196.46","658","0","2"]],"bids":[["194.19","0","0","0"]],"ts":"1626995769745","checksum":263946437}]}
1626995769.8078022: {"arg":{"channel":"books-l2-tbt","instId":"AUCTION-USDT"},"action":"update","data":[{"asks":[["15.02","15.8","0","3"]],"bids":[],"ts":"1626995769761","checksum":-878475051}]}
1626995769.838261: {"arg":{"channel":"books-l2-tbt","instId":"TRX-USDT-210924"},"action":"update","data":[{"asks":[["0.05459","4","0","1"],["0.05461","4","0","1"],["0.05475","0","0","0"],["0.05494","0","0","0"],["0.0559","0","0","0"],["0.05591","3","0","1"]],"bids":[["0.05442","240","0","3"],["0.05408","388","0","1"]],"ts":"1626995769779","checksum":1524948215}]}
1626995769.83842: {"arg":{"channel":"books-l2-tbt","instId":"XMR-USDT-SWAP"},"action":"update","data":[{"asks":[["196.45","79","0","3"],["196.53","59","0","2"]],"bids":[],"ts":"1626995769786","checksum":1210711481}]}
1626995769.838479: {"arg":{"channel":"books-l2-tbt","instId":"DHT-USDT"},"action":"update","data":[{"asks":[["0.794","463.1407","0","2"]],"bids":[],"ts":"1626995769787","checksum":2058410061}]}
1626995769.838511: {"arg":{"channel":"books-l2-tbt","instId":"TRX-USDT-210924"},"action":"update","data":[{"asks":[],"bids":[["0.05443","10","0","2"],["0.05442","239","0","2"],["0.0544","8","0","2"],["0.05439","0","0","0"],["0.05438","1","0","1"],["0.05436","0","0","0"],["0.05432","1","0","1"],["0.05431","0","0","0"],["0.05427","43","0","2"],["0.05425","0","0","0"]],"ts":"1626995769788","checksum":-1892724253}]}
1626995769.846226: {"arg":{"channel":"books-l2-tbt","instId":"XMR-USDT-SWAP"},"action":"update","data":[{"asks":[["196.31","298","0","4"]],"bids":[["196.14","116","0","2"]],"ts":"1626995769800","checksum":732676882}]}
1626995769.8666549: {"arg":{"channel":"books-l2-tbt","instId":"XMR-USDT-SWAP"},"action":"update","data":[{"asks":[],"bids":[["195.32","4","0","1"]],"ts":"1626995769819","checksum":732676882}]}
1626995769.895484: {"arg":{"channel":"books-l2-tbt","instId":"TRX-USDT-210924"},"action":"update","data":[{"asks":[["0.05459","82","0","2"],["0.05461","107","0","2"],["0.05463","280","0","3"],["0.05477","252","0","1"],["0.05495","668","0","3"]],"bids":[["0.05447","92","0","2"],["0.05429","299","0","2"]],"ts":"1626995769848","checksum":-223809527}]}
1626995769.911444: {"arg":{"channel":"books-l2-tbt","instId":"AUCTION-USDT"},"action":"update","data":[{"asks":[["15.19","10.5","0","2"]],"bids":[],"ts":"1626995769863","checksum":-2111423749}]}
1626995769.927679: {"arg":{"channel":"books-l2-tbt","instId":"XMR-USDT-SWAP"},"action":"update","data":[{"asks":[["196.46","689","0","3"],["196.53","28","0","1"]],"bids":[["195.31","142","0","1"]],"ts":"1626995769881","checksum":-207184005}]}
1626995769.94701: {"arg":{"channel":"books-l2-tbt","instId":"XMR-USDT-SWAP"},"action":"update","data":[{"asks":[],"bids":[["195.26","84","0","3"]],"ts":"1626995769900","checksum":-207184005}]}
1626995769.967287: {"arg":{"channel":"books-l2-tbt","instId":"TRX-USDT-210924"},"action":"update","data":[{"asks":[],"bids":[["0.05447","84","0","1"]],"ts":"1626995769919","checksum":-1772836348}]}
1626995769.975803: {"arg":{"channel":"books-l2-tbt","instId":"TRX-USDT-210924"},"action":"update","data":[{"asks":[["0.05459","4","0","1"]],"bids":[["0.05448","8","0","1"],["0.05442","0","0","0"],["0.05408","0","0","0"]],"ts":"1626995769929","checksum":1732709009}]}
1626995769.998147: {"arg":{"channel":"books-l2-tbt","instId":"ONT-USDT"},"action":"update","data":[{"asks":[["0.6224","493.023816","0","2"]],"bids":[],"ts":"1626995769951","checksum":-980316348}]}
1626995769.998276: {"arg":{"channel":"books-l2-tbt","instId":"TRX-USDT-210924"},"action":"update","data":[{"asks":[],"bids":[["0.05446","20","0","1"]],"ts":"1626995769951","checksum":1457464666}]}
1626995770.00639: {"arg":{"channel":"books-l2-tbt","instId":"TRX-USDT-210924"},"action":"update","data":[{"asks":[],"bids":[["0.05445","14","0","1"]],"ts":"1626995769959","checksum":392601731}]}
1626995770.0179892: {"arg":{"channel":"books-l2-tbt","instId":"ONT-USDT"},"action":"update","data":[{"asks":[["0.6222","436.838861","0","2"],["0.6224","103.023816","0","1"],["0.6228","792.871384","0","3"],["0.6234","0","0","0"],["0.6242","4129","0","1"],["0.6252","0","0","0"],["0.6284","9873","0","1"]],"bids":[],"ts":"1626995769971","checksum":-1362483160}]}
1626995770.036515: {"arg":{"channel":"books-l2-tbt","instId":"TRX-USDT-210924"},"action":"update","data":[{"asks":[],"bids":[["0.05442","304","0","2"]],"ts":"1626995769990","checksum":196701224}]}
1626995770.0370922: {"arg":{"channel":"books-l2-tbt","instId":"ONT-USDT"},"action":"update","data":[{"asks":[["0.623","3320","0","2"]],"bids":[],"ts":"1626995769992","checksum":-1068349733}]}
1626995770.045662: {"arg":{"channel":"books-l2-tbt","instId":"TRX-USDT-210924"},"action":"update","data":[{"asks":[["0.05459","82","0","2"]],"bids":[["0.05408","387","0","1"]],"ts":"1626995769999","checksum":1815101982}]}
1626995770.0679932: {"arg":{"channel":"books-l2-tbt","instId":"TRX-USDT-210924"},"action":"update","data":[{"asks":[["0.05589","3","0","1"],["0.05591","0","0","0"]],"bids":[],"ts":"1626995770021","checksum":1815101982}]}
1626995770.104074: {"arg":{"channel":"books-l2-tbt","instId":"FUN-BTC"},"action":"update","data":[{"asks":[["0.000000453","32.3","0","1"]],"bids":[],"ts":"1626995770058","checksum":263336453}]}
1626995770.1066391: {"arg":{"channel":"trades","instId":"FUN-BTC"},"data":[{"instId":"FUN-BTC","tradeId":"3435658","px":"0.000000453","sz":"32.3","side":"buy","ts":"1626995770057"}]}
1626995770.113725: {"arg":{"channel":"books-l2-tbt","instId":"FUN-BTC"},"action":"update","data":[{"asks":[["0.000000453","0","0","0"]],"bids":[],"ts":"1626995770067","checksum":-1924357789}]}
1626995770.12164: {"arg":{"channel":"tickers","instId":"FUN-BTC"},"data":[{"instType":"SPOT","instId":"FUN-BTC","last":"0.000000453","lastSz":"32.3","askPx":"0.000000454","askSz":"130606.89","bidPx":"0.00000045","bidSz":"21957.39","open24h":"0.000000444","high24h":"0.000000467","low24h":"0.000000443","sodUtc0":"0.000000446","sodUtc8":"0.000000449","volCcy24h":"0.13","vol24h":"302343.5","ts":"1626995770069"}]}
1626995770.1228: {"arg":{"channel":"books-l2-tbt","instId":"ONT-USDT"},"action":"update","data":[{"asks":[["0.6224","0","0","0"],["0.6226","103.023816","0","1"]],"bids":[],"ts":"1626995770077","checksum":-199382277}]}
1626995770.128362: {"arg":{"channel":"books-l2-tbt","instId":"TRX-USDT-210924"},"action":"update","data":[{"asks":[],"bids":[["0.05445","0","0","0"]],"ts":"1626995770082","checksum":-234390161}]}
1626995770.139509: {"arg":{"channel":"books-l2-tbt","instId":"TRX-USDT-210924"},"action":"update","data":[{"asks":[],"bids":[["0.05446","34","0","2"]],"ts":"1626995770092","checksum":-2011425379}]}
1626995770.150497: {"arg":{"channel":"books-l2-tbt","instId":"TRX-USDT-210924"},"action":"update","data":[{"asks":[],"bids":[["0.05447","0","0","0"]],"ts":"1626995770103","checksum":-768183771}]}
1626995770.153644: {"arg":{"channel":"books-l2-tbt","instId":"XMR-USDT-SWAP"},"action":"update","data":[{"asks":[["197.86","526","0","6"]],"bids":[],"ts":"1626995770108","checksum":-207184005}]}
1626995770.168119: {"arg":{"channel":"books-l2-tbt","instId":"TRX-USDT-210924"},"action":"update","data":[{"asks":[["0.05589","0","0","0"],["0.0559","3","0","1"]],"bids":[],"ts":"1626995770122","checksum":-768183771}]}
1626995770.2103019: {"arg":{"channel":"books-l2-tbt","instId":"TRX-USDT-210924"},"action":"update","data":[{"asks":[],"bids":[["0.05442","456","0","3"]],"ts":"1626995770164","checksum":-1476846709}]}
1626995770.282893: {"arg":{"channel":"books-l2-tbt","instId":"TRX-USDT-210924"},"action":"update","data":[{"asks":[["0.05495","286","0","2"],["0.05589","3","0","1"],["0.0559","0","0","0"]],"bids":[["0.05442","304","0","2"]],"ts":"1626995770236","checksum":-1298899789}]}
1626995770.29318: {"arg":{"channel":"books-l2-tbt","instId":"TRX-USDT-210924"},"action":"update","data":[{"asks":[],"bids":[["0.0545","2","0","1"]],"ts":"1626995770246","checksum":-952484677}]}
1626995770.319972: {"arg":{"channel":"books-l2-tbt","instId":"XMR-USDT-SWAP"},"action":"update","data":[{"asks":[["196.46","722","0","3"]],"bids":[],"ts":"1626995770272","checksum":-1476484485}]}
1626995770.3252401: {"arg":{"channel":"books-l2-tbt","instId":"OKT-BTC"},"action":"update","data":[{"asks":[],"bids":[["0.00145","9.3419931","0","2"]],"ts":"1626995770279","checksum":928629891}]}
1626995770.343574: {"arg":{"channel":"books-l2-tbt","instId":"TRX-USDT-210924"},"action":"update","data":[{"asks":[["0.05499","382","0","1"]],"bids":[["0.05448","88","0","2"]],"ts":"1626995770296","checksum":-2113241823}]}
1626995770.3920891: {"arg":{"channel":"books-l2-tbt","instId":"TRX-USDT-210924"},"action":"update","data":[{"asks":[["0.05454","183","0","4"]],"bids":[],"ts":"1626995770345","checksum":-1358093593}]}
1626995770.402394: {"arg":{"channel":"books-l2-tbt","instId":"TRX-USDT-210924"},"action":"update","data":[{"asks":[["0.05455","8","0","1"]],"bids":[],"ts":"1626995770355","checksum":113965487}]}
1626995770.409064: {"arg":{"channel":"books-l2-tbt","instId":"OKT-BTC"},"action":"update","data":[{"asks":[],"bids":[["0.001451","0","0","0"]],"ts":"1626995770361","checksum":858601983}]}
1626995770.411571: {"arg":{"channel":"books-l2-tbt","instId":"TRX-USDT-210924"},"action":"update","data":[{"asks":[],"bids":[["0.05448","8","0","1"],["0.05442","0","0","0"]],"ts":"1626995770366","checksum":1792677101}]}
1626995770.422634: {"arg":{"channel":"books-l2-tbt","instId":"TRX-USDT-210924"},"action":"update","data":[{"asks":[],"bids":[["0.05446","20","0","1"],["0.05445","14","0","1"]],"ts":"1626995770376","checksum":-1010279147}]}
1626995770.437974: {"arg":{"channel":"books-l2-tbt","instId":"ONT-USDT"},"action":"update","data":[{"asks":[],"bids":[["0.6187","4129","0","1"]],"ts":"1626995770391","checksum":1311253921}]}
1626995770.4531121: {"arg":{"channel":"books-l2-tbt","instId":"TRX-USDT-210924"},"action":"update","data":[{"asks":[],"bids":[["0.05423","0","0","0"],["0.05422","3","0","1"]],"ts":"1626995770406","checksum":-1539323549}]}
1626995770.484051: {"arg":{"channel":"books-l2-tbt","instId":"TRX-USDT-210924"},"action":"update","data":[{"asks":[],"bids":[["0.05447","91","0","1"],["0.05442","314","0","2"]],"ts":"1626995770436","checksum":829577950}]}
1626995770.5152729: {"arg":{"channel":"books-l2-tbt","instId":"TRX-USDT-210924"},"action":"update","data":[{"asks":[],"bids":[["0.05446","34","0","2"],["0.05445","0","0","0"]],"ts":"1626995770469","checksum":615909520}]}
1626995770.527472: {"arg":{"channel":"books-l2-tbt","instId":"TRX-USDT-210924"},"action":"update","data":[{"asks":[["0.05589","0","0","0"],["0.0559","3","0","1"]],"bids":[["0.05423","3","0","1"],["0.05422","0","0","0"]],"ts":"1626995770478","checksum":-735290308}]}
1626995770.532632: {"arg":{"channel":"books-l2-tbt","instId":"ONT-USDT"},"action":"update","data":[{"asks":[],"bids":[["0.6189","88","0","1"]],"ts":"1626995770484","checksum":-217675889}]}
1626995770.538941: {"arg":{"channel":"books-l2-tbt","instId":"OKT-BTC"},"action":"update","data":[{"asks":[["0.001476","0","0","0"]],"bids":[["0.001306","5.62","0","3"]],"ts":"1626995770493","checksum":633507940}]}
1626995770.578461: {"arg":{"channel":"books-l2-tbt","instId":"TRX-USDT-210924"},"action":"update","data":[{"asks":[],"bids":[["0.05423","0","0","0"],["0.05422","3","0","1"]],"ts":"1626995770532","checksum":615909520}]}
1626995770.59768: {"arg":{"channel":"books-l2-tbt","instId":"TRX-USDT-210924"},"action":"update","data":[{"asks":[["0.05463","144","0","2"]],"bids":[["0.05447","0","0","0"]],"ts":"1626995770551","checksum":-2017501290}]}
1626995770.654342: {"arg":{"channel":"books-l2-tbt","instId":"FUN-BTC"},"action":"update","data":[{"asks":[],"bids":[["0.000000452","131439.69","0","1"]],"ts":"1626995770608","checksum":-849563155}]}
1626995770.6600032: {"arg":{"channel":"books-l2-tbt","instId":"TRX-USDT-210924"},"action":"update","data":[{"asks":[["0.05464","297","0","2"]],"bids":[["0.05442","472","0","3"]],"ts":"1626995770613","checksum":-195762026}]}
1626995770.692084: {"arg":{"channel":"books-l2-tbt","instId":"TRX-USDT-210924"},"action":"update","data":[{"asks":[["0.05589","3","0","1"],["0.0559","0","0","0"]],"bids":[],"ts":"1626995770645","checksum":-195762026}]}
1626995770.712456: {"arg":{"channel":"books-l2-tbt","instId":"ONT-USDT"},"action":"update","data":[{"asks":[["0.6224","603.334745","0","1"],["1.1285","0","0","0"]],"bids":[],"ts":"1626995770666","checksum":482366851}]}
1626995770.7160819: {"arg":{"channel":"books-l2-tbt","instId":"AUCTION-USDT"},"action":"update","data":[{"asks":[],"bids":[["13.5","9.822222","0","4"]],"ts":"1626995770669","checksum":-2111423749}]}
1626995770.722559: {"arg":{"channel":"books-l2-tbt","instId":"TRX-USDT-210924"},"action":"update","data":[{"asks":[],"bids":[["0.05442","314","0","2"]],"ts":"1626995770676","checksum":-1043481407}]}
1626995770.725997: {"arg":{"channel":"books-l2-tbt","instId":"BTC-USD-210924-42000-P"},"action":"update","data":[{"asks":[],"bids":[],"ts":"1626995770680","checksum":1063707503}]}
1626995770.773955: {"arg":{"channel":"books-l2-tbt","instId":"PAY-BTC"},"action":"update","data":[{"asks":[["0.00000139","4702.072","0","3"]],"bids":[],"ts":"1626995770716","checksum":290683904}]}
1626995770.774088: {"arg":{"channel":"books-l2-tbt","instId":"ONT-USDT"},"action":"update","data":[{"asks":[["0.6224","0","0","0"],["1.1285","10.5","0","1"]],"bids":[],"ts":"1626995770717","checksum":-217675889}]}
1626995770.792209: {"arg":{"channel":"books-l2-tbt","instId":"TRX-USDT-210924"},"action":"update","data":[{"asks":[],"bids":[["0.05448","90","0","2"]],"ts":"1626995770746","checksum":1806376867}]}
1626995770.8746629: {"arg":{"channel":"books-l2-tbt","instId":"TRX-USDT-210924"},"action":"update","data":[{"asks":[["0.05452","2","0","1"],["0.05454","219","0","5"]],"bids":[],"ts":"1626995770828","checksum":1931864250}]}
1626995770.878082: {"arg":{"channel":"books-l2-tbt","instId":"PAY-BTC"},"action":"update","data":[{"asks":[["0.0000014","3510.065","0","4"]],"bids":[],"ts":"1626995770831","checksum":-705740171}]}
1626995770.882327: {"arg":{"channel":"books-l2-tbt","instId":"OKT-BTC"},"action":"update","data":[{"asks":[["0.001476","0.62258414","0","1"]],"bids":[["0.001469","2.95320808","0","2"]],"ts":"1626995770834","checksum":1377422640}]}
1626995770.8853009: {"arg":{"channel":"books-l2-tbt","instId":"TRX-USDT-210924"},"action":"update","data":[{"asks":[["0.05454","217","0","4"]],"bids":[],"ts":"1626995770839","checksum":1935428723}]}
1626995770.897213: {"arg":{"channel":"books-l2-tbt","instId":"BTC-USD-210924-66000-C"},"action":"update","data":[{"asks":[],"bids":[],"ts":"1626995770850","checksum":-90978610}]}
1626995770.9036648: {"arg":{"channel":"books-l2-tbt","instId":"TRX-USDT-210924"},"action":"update","data":[{"asks":[],"bids":[["0.05443","9","0","1"],["0.05441","151","0","3"],["0.0544","7","0","1"],["0.05436","1","0","1"],["0.05432","0","0","0"],["0.0543","1","0","1"],["0.05427","42","0","1"],["0.05425","1","0","1"]],"ts":"1626995770857","checksum":-1276338720}]}
1626995770.9515011: {"arg":{"channel":"books-l2-tbt","instId":"XMR-USDT-SWAP"},"action":"update","data":[{"asks":[["196.46","721","0","3"]],"bids":[],"ts":"1626995770904","checksum":-1789551226}]}
1626995770.964751: {"arg":{"channel":"books-l2-tbt","instId":"TRX-USDT-210924"},"action":"update","data":[{"asks":[],"bids":[["0.0545","0","0","0"]],"ts":"1626995770918","checksum":-2028061729}]}
1626995770.97253: {"arg":{"channel":"books-l2-tbt","instId":"XMR-USDT-SWAP"},"action":"update","data":[{"asks":[["196.4","0","0","0"]],"bids":[],"ts":"1626995770925","checksum":1687956282}]}
1626995770.985683: {"arg":{"channel":"books-l2-tbt","instId":"TRX-USDT-210924"},"action":"update","data":[{"asks":[["0.05462","86","0","3"]],"bids":[],"ts":"1626995770940","checksum":1353488543}]}
1626995771.0043678: {"arg":{"channel":"books-l2-tbt","instId":"OKT-BTC"},"action":"update","data":[{"asks":[["0.001476","0","0","0"]],"bids":[],"ts":"1626995770957","checksum":-1685258764}]}
1626995771.05433: {"arg":{"channel":"books-l2-tbt","instId":"XMR-USDT-SWAP"},"action":"update","data":[{"asks":[["196.45","84","0","4"]],"bids":[],"ts":"1626995771006","checksum":-2112020106}]}
1626995771.054466: {"arg":{"channel":"books-l2-tbt","instId":"BTC-USD-210924-42000-P"},"action":"update","data":[{"asks":[["0.3415","0","0","0"],["0.342","601","0","2"]],"bids":[["0.3345","305","0","2"],["0.334","0","0","0"]],"ts":"1626995771006","checksum":2005526082}]}
1626995771.196259: {"arg":{"channel":"books-l2-tbt","instId":"XMR-USDT-SWAP"},"action":"update","data":[{"asks":[["196.44","690","0","2"],["196.46","38","0","2"]],"bids":[],"ts":"1626995771150","checksum":1520865598}]}
1626995771.2196128: {"arg":{"channel":"books-l2-tbt","instId":"ONT-USDT"},"action":"update","data":[{"asks":[],"bids":[["0.6098","0","0","0"]],"ts":"1626995771174","checksum":-217675889}]}
1626995771.246346: {"arg":{"channel":"books-l2-tbt","instId":"TRX-USDT-210924"},"action":"update","data":[{"asks":[],"bids":[["0.05446","14","0","1"],["0.05444","20","0","1"]],"ts":"1626995771200","checksum":-198235572}]}
1626995771.2592828: {"arg":{"channel":"books-l2-tbt","instId":"XMR-USDT-SWAP"},"action":"update","data":[{"asks":[["196.46","7","0","1"],["196.53","60","0","2"]],"bids":[],"ts":"1626995771209","checksum":-1102342189}]}
1626995771.277977: {"arg":{"channel":"books-l2-tbt","instId":"BTC-USD-210924-42000-P"},"action":"update","data":[{"asks":[["0.341","0","0","0"],["0.3415","5","0","1"],["0.342","300","0","1"],["0.3425","301","0","1"]],"bids":[["0.335","5","0","1"],["0.3345","300","0","1"]],"ts":"1626995771231","checksum":446791778}]}
1626995771.4129338: {"arg":{"channel":"books-l2-tbt","instId":"FUN-BTC"},"action":"update","data":[{"asks":[],"bids":[["0.000000403","0","0","0"]],"ts":"1626995771364","checksum":-1552966004}]}
1626995771.510998: {"arg":{"channel":"books-l2-tbt","instId":"TRX-USDT-210924"},"action":"update","data":[{"asks":[["0.05461","4","0","1"]],"bids":[["0.05448","8","0","1"]],"ts":"1626995771459","checksum":1619697711}]}
1626995771.511137: {"arg":{"channel":"books-l2-tbt","instId":"ONT-USDT"},"action":"update","data":[{"asks":[],"bids":[["0.6103","206.896","0","1"]],"ts":"1626995771462","checksum":-217675889}]}
1626995771.569705: {"arg":{"channel":"books-l2-tbt","instId":"BTC-USD-210924-42000-P"},"action":"update","data":[{"asks":[],"bids":[["0.334","301","0","1"],["0.333","0","0","0"]],"ts":"1626995771522","checksum":-1431042442}]}
1626995771.576482: {"arg":{"channel":"books-l2-tbt","instId":"TRX-USDT-210924"},"action":"update","data":[{"asks":[["0.05464","432","0","3"]],"bids":[["0.05442","476","0","3"]],"ts":"1626995771529","checksum":-2104602319}]}
1626995771.6198962: {"arg":{"channel":"books-l2-tbt","instId":"DHT-USDT"},"action":"update","data":[{"asks":[["0.794","40","0","1"]],"bids":[],"ts":"1626995771573","checksum":-564066120}]}
1626995771.649014: {"arg":{"channel":"books-l2-tbt","instId":"TRX-USDT-210924"},"action":"update","data":[{"asks":[["0.05464","293","0","2"]],"bids":[["0.05442","314","0","2"]],"ts":"1626995771602","checksum":-313688847}]}
1626995771.65805: {"arg":{"channel":"books-l2-tbt","instId":"TRX-USDT-210924"},"action":"update","data":[{"asks":[["0.05459","78","0","1"]],"bids":[],"ts":"1626995771612","checksum":1568243220}]}
1626995771.708759: {"arg":{"channel":"books-l2-tbt","instId":"FUN-BTC"},"action":"update","data":[{"asks":[],"bids":[["0.00000041","6759.53","0","1"]],"ts":"1626995771660","checksum":-198759559}]}
1626995771.708908: {"arg":{"channel":"books-l2-tbt","instId":"TRX-USDT-210924"},"action":"update","data":[{"asks":[["0.05464","428","0","3"]],"bids":[["0.05449","77","0","1"]],"ts":"1626995771663","checksum":635917784}]}
1626995771.714567: {"arg":{"channel":"books-l2-tbt","instId":"ONT-USDT"},"action":"update","data":[{"asks":[],"bids":[["0.6192","884.813384","0","1"]],"ts":"1626995771667","checksum":-975625368}]}
1626995771.760202: {"arg":{"channel":"trades","instId":"XMR-USDT-SWAP"},"data":[{"instId":"XMR-USDT-SWAP","tradeId":"6845129","px":"196.23","sz":"4","side":"buy","ts":"1626995771710"}]}
1626995771.767276: {"arg":{"channel":"books-l2-tbt","instId":"OKT-BTC"},"action":"update","data":[{"asks":[["0.001474","0","0","0"]],"bids":[],"ts":"1626995771721","checksum":1592854100}]}
1626995771.780278: {"arg":{"channel":"books-l2-tbt","instId":"TRX-USDT-210924"},"action":"update","data":[{"asks":[["0.05464","293","0","2"]],"bids":[["0.05449","0","0","0"]],"ts":"1626995771734","checksum":1568243220}]}
1626995771.782701: {"arg":{"channel":"tickers","instId":"XMR-USDT-SWAP"},"data":[{"instType":"SWAP","instId":"XMR-USDT-SWAP","last":"196.23","lastSz":"4","askPx":"196.31","askSz":"156","bidPx":"196.17","bidSz":"1","open24h":"197.32","high24h":"202.54","low24h":"189.85","sodUtc0":"196.66","sodUtc8":"199.56","volCcy24h":"65229.2","vol24h":"652292","ts":"1626995771723"}]}
1626995771.786653: {"arg":{"channel":"books-l2-tbt","instId":"OKT-BTC"},"action":"update","data":[{"asks":[["0.001474","0.34898236","0","1"],["0.001475","0","0","0"],["0.001476","0.87832741","0","1"]],"bids":[],"ts":"1626995771741","checksum":-466162366}]}
1626995771.800797: {"arg":{"channel":"books-l2-tbt","instId":"ONT-USDT"},"action":"update","data":[{"asks":[],"bids":[["0.6193","6199.056622","0","3"]],"ts":"1626995771754","checksum":-1111618233}]}
1626995771.8423738: {"arg":{"channel":"books-l2-tbt","instId":"TRX-USDT-210924"},"action":"update","data":[{"asks":[["0.05464","428","0","3"]],"bids":[["0.05442","476","0","3"]],"ts":"1626995771795","checksum":934956789}]}
1626995771.848213: {"arg":{"channel":"books-l2-tbt","instId":"DHT-USDT"},"action":"update","data":[{"asks":[["0.796","439.1407","0","2"]],"bids":[],"ts":"1626995771801","checksum":-1627187672}]}
1626995771.902861: {"arg":{"channel":"books-l2-tbt","instId":"TRX-USDT-210924"},"action":"update","data":[{"asks":[["0.05464","293","0","2"]],"bids":[],"ts":"1626995771856","checksum":-671232601}]}
1626995771.974777: {"arg":{"channel":"books-l2-tbt","instId":"TRX-USDT-210924"},"action":"update","data":[{"asks":[["0.05462","186","0","4"]],"bids":[],"ts":"1626995771929","checksum":-452417160}]}
1626995772.02299: {"arg":{"channel":"books-l2-tbt","instId":"TRX-USDT-210924"},"action":"update","data":[{"asks":[],"bids":[["0.05449","2","0","1"]],"ts":"1626995771940","checksum":635370191}]}
1626995772.0231261: {"arg":{"channel":"books-l2-tbt","instId":"DHT-USDT"},"action":"update","data":[{"asks":[["0.794","0","0","0"]],"bids":[],"ts":"1626995771943","checksum":715300993}]}
1626995772.027458: {"arg":{"channel":"books-l2-tbt","instId":"XMR-USDT-SWAP"},"action":"update","data":[{"asks":[],"bids":[["196.04","330","0","5"]],"ts":"1626995771978","checksum":-623790367}]}
1626995772.092392: {"arg":{"channel":"books-l2-tbt","instId":"FUN-BTC"},"action":"update","data":[{"asks":[["0.000000454","0","0","0"]],"bids":[],"ts":"1626995772042","checksum":-1239944353}]}
1626995772.146741: {"arg":{"channel":"books-l2-tbt","instId":"XMR-USDT-SWAP"},"action":"update","data":[{"asks":[["196.45","116","0","5"],["196.53","28","0","1"]],"bids":[],"ts":"1626995772099","checksum":-1654615605}]}
1626995772.157433: {"arg":{"channel":"books-l2-tbt","instId":"FUN-BTC"},"action":"update","data":[{"asks":[["0.000000455","120646.08","0","1"]],"bids":[],"ts":"1626995772111","checksum":-48349032}]}
1626995772.189499: {"arg":{"channel":"books-l2-tbt","instId":"AUCTION-USDT"},"action":"update","data":[{"asks":[],"bids":[["14.28","0","0","0"]],"ts":"1626995772144","checksum":1416180795}]}
1626995772.299774: {"arg":{"channel":"books-l2-tbt","instId":"ONT-USDT"},"action":"update","data":[{"asks":[["0.6235","5352.318397","0","2"],["0.6242","0","0","0"],["1.1288","10.09339","0","1"]],"bids":[],"ts":"1626995772252","checksum":-173716910}]}
1626995772.320149: {"arg":{"channel":"books-l2-tbt","instId":"OKT-BTC"},"action":"update","data":[{"asks":[],"bids":[["0.00145","11.8119931","0","3"]],"ts":"1626995772273","checksum":-744155888}]}
1626995772.437849: {"arg":{"channel":"books-l2-tbt","instId":"DHT-USDT"},"action":"update","data":[{"asks":[],"bids":[],"ts":"1626995772391","checksum":715300993}]}
1626995772.4471: {"arg":{"channel":"books-l2-tbt","instId":"AUCTION-USDT"},"action":"update","data":[{"asks":[],"bids":[["14.25","151.647444","0","1"]],"ts":"1626995772399","checksum":-1873054304}]}
1626995772.47456: {"arg":{"channel":"books-l2-tbt","instId":"TRX-USDT-210924"},"action":"update","data":[{"asks":[],"bids":[["0.05446","0","0","0"],["0.05445","14","0","1"]],"ts":"1626995772427","checksum":1745595819}]}
1626995772.4953878: {"arg":{"channel":"books-l2-tbt","instId":"ONT-USDT"},"action":"update","data":[{"asks":[],"bids":[["0.5901","0","0","0"]],"ts":"1626995772449","checksum":-173716910}]}
1626995772.517463: {"arg":{"channel":"books-l2-tbt","instId":"ONT-USDT"},"action":"update","data":[{"asks":[],"bids":[["0.5899","294.695711","0","1"]],"ts":"1626995772471","checksum":-173716910}]}
1626995772.598919: {"arg":{"channel":"books-l2-tbt","instId":"ONT-USDT"},"action":"update","data":[{"asks":[],"bids":[["0.6219","0","0","0"],["0.6216","51","0","1"],["0.6215","945.539","0","1"]],"ts":"1626995772551","checksum":679086318}]}
1626995772.6080582: {"arg":{"channel":"books-l2-tbt","instId":"TRX-USDT-210924"},"action":"update","data":[{"asks":[["0.05453","14","0","1"],["0.05454","203","0","3"]],"bids":[],"ts":"1626995772562","checksum":-667108492}]}
1626995772.619343: {"arg":{"channel":"books-l2-tbt","instId":"ONT-USDT"},"action":"update","data":[{"asks":[["0.6221","945.539","0","1"],["0.6222","351.838861","0","1"],["0.6223","3183.125104","0","1"],["1.1288","0","0","0"]],"bids":[["0.6218","0","0","0"],["0.6215","0","0","0"],["0.6205","1709.660295","0","2"]],"ts":"1626995772573","checksum":101726975}]}
1626995772.630354: {"arg":{"channel":"books-l2-tbt","instId":"OKT-BTC"},"action":"update","data":[{"asks":[["0.001474","0","0","0"]],"bids":[],"ts":"1626995772583","checksum":-716835451}]}
1626995772.639819: {"arg":{"channel":"books-l2-tbt","instId":"ONT-USDT"},"action":"update","data":[{"asks":[["0.6218","85","0","1"],["1.1285","0","0","0"]],"bids":[["0.6216","0","0","0"],["0.6212","51","0","1"],["0.62","1091.868423","0","3"]],"ts":"1626995772593","checksum":-132927316}]}
1626995772.652815: {"arg":{"channel":"books-l2-tbt","instId":"OKT-BTC"},"action":"update","data":[{"asks":[["0.001476","12.41548384","0","2"]],"bids":[],"ts":"1626995772605","checksum":-96412237}]}
1626995772.6529438: {"arg":{"channel":"books-l2-tbt","instId":"ONT-USDT"},"action":"update","data":[{"asks":[],"bids":[["0.6205","10976.968421","0","3"],["0.62","689","0","2"]],"ts":"1626995772605","checksum":-1609519006}]}
1626995772.660434: {"arg":{"channel":"books-l2-tbt","instId":"ONT-USDT"},"action":"update","data":[{"asks":[["0.6218","0","0","0"],["0.622","102.819052","0","1"],["0.6222","0","0","0"],["0.6231","1709.660295","0","2"],["0.6232","0","0","0"],["0.6246","0","0","0"],["0.6247","0","0","0"],["0.6262","812.661146","0","2"],["1.1285","10.5","0","1"],["1.1288","10.09339","0","1"],["1.13","13919.895296","0","1"],["1.1314","181.020619","0","1"]],"bids":[["0.6213","548.849604","0","1"],["0.6198","402.868423","0","1"],["0.6193","118","0","2"]],"ts":"1626995772613","checksum":-2115255798}]}
1626995772.660749: {"arg":{"channel":"books-l2-tbt","instId":"OKT-BTC"},"action":"update","data":[{"asks":[["0.001475","0.4130644","0","1"]],"bids":[],"ts":"1626995772614","checksum":-1141228513}]}
1626995772.669898: {"arg":{"channel":"books-l2-tbt","instId":"OKT-BTC"},"action":"update","data":[{"asks":[["0.001476","0.87832741","0","1"]],"bids":[],"ts":"1626995772624","checksum":-299048902}]}
1626995772.6699898: {"arg":{"channel":"books-l2-tbt","instId":"ONT-USDT"},"action":"update","data":[{"asks":[["0.6226","0","0","0"],["1.1346","10.5","0","1"]],"bids":[],"ts":"1626995772624","checksum":-628413634}]}
1626995772.680744: {"arg":{"channel":"books-l2-tbt","instId":"ONT-USDT"},"action":"update","data":[{"asks":[],"bids":[["0.6214","51","0","1"]],"ts":"1626995772634","checksum":-2106444372}]}
1626995772.692547: {"arg":{"channel":"books-l2-tbt","instId":"ONT-USDT"},"action":"update","data":[{"asks":[["0.622","187.819052","0","2"]],"bids":[],"ts":"1626995772646","checksum":426340765}]}
1626995772.69965: {"arg":{"channel":"books-l2-tbt","instId":"PAY-BTC"},"action":"update","data":[{"asks":[],"bids":[["0.00000136","4282.772","0","2"]],"ts":"1626995772654","checksum":1653678379}]}
1626995772.704986: {"arg":{"channel":"books-l2-tbt","instId":"ONT-USDT"},"action":"update","data":[{"asks":[["0.6226","390","0","1"],["0.6228","402.871384","0","2"],["1.1346","0","0","0"]],"bids":[],"ts":"1626995772656","checksum":-1692778269}]}
1626995772.7229: {"arg":{"channel":"books-l2-tbt","instId":"TRX-USDT-210924"},"action":"update","data":[{"asks":[["0.05588","3","0","1"],["0.05589","0","0","0"]],"bids":[["0.0544","0","0","0"]],"ts":"1626995772675","checksum":617903303}]}
1626995772.7329988: {"arg":{"channel":"books-l2-tbt","instId":"ONT-USDT"},"action":"update","data":[{"asks":[],"bids":[["0.6213","3522.309082","0","2"]],"ts":"1626995772686","checksum":-932795030}]}
1626995772.74384: {"arg":{"channel":"books-l2-tbt","instId":"ONT-USDT"},"action":"update","data":[{"asks":[["0.6223","0","0","0"],["1.1346","10.5","0","1"]],"bids":[],"ts":"1626995772697","checksum":53609371}]}
1626995772.781873: {"arg":{"channel":"books-l2-tbt","instId":"ONT-USDT"},"action":"update","data":[{"asks":[["0.6226","10768.795","0","2"]],"bids":[],"ts":"1626995772734","checksum":1231174935}]}
1626995772.784527: {"arg":{"channel":"books-l2-tbt","instId":"ONT-USDT"},"action":"update","data":[{"asks":[["0.6245","6078.616777","0","1"],["1.1346","0","0","0"]],"bids":[["0.6213","3625.128134","0","3"],["0.6209","0","0","0"],["0.619","6078.616776","0","1"]],"ts":"1626995772736","checksum":326292187}]}
1626995772.804011: {"arg":{"channel":"books-l2-tbt","instId":"ONT-USDT"},"action":"update","data":[{"asks":[],"bids":[["0.6214","996.539","0","2"]],"ts":"1626995772757","checksum":-1290909760}]}
1626995772.835073: {"arg":{"channel":"books-l2-tbt","instId":"DHT-USDT"},"action":"update","data":[{"asks":[["0.796","16","0","1"]],"bids":[],"ts":"1626995772785","checksum":-765422627}]}
1626995772.8351202: {"arg":{"channel":"books-l2-tbt","instId":"ONT-USDT"},"action":"update","data":[{"asks":[["0.6226","390","0","1"]],"bids":[],"ts":"1626995772788","checksum":-1593505625}]}
1626995772.854719: {"arg":{"channel":"books-l2-tbt","instId":"ONT-USDT"},"action":"update","data":[{"asks":[],"bids":[["0.6158","0","0","0"],["0.6144","3200","0","1"]],"ts":"1626995772807","checksum":-1593505625}]}
1626995772.8851242: {"arg":{"channel":"books-l2-tbt","instId":"ONT-USDT"},"action":"update","data":[{"asks":[["0.622","85","0","1"],["0.6225","102.819052","0","1"],["1.1314","0","0","0"]],"bids":[],"ts":"1626995772839","checksum":-320546549}]}
1626995772.897919: {"arg":{"channel":"books-l2-tbt","instId":"XMR-USDT-SWAP"},"action":"update","data":[{"asks":[],"bids":[["195.97","0","0","0"],["195.86","105","0","4"],["195.82","0","0","0"],["195.81","42","0","2"],["195.78","27","0","1"],["195.56","0","0","0"],["195.52","27","0","1"]],"ts":"1626995772851","checksum":-1742764446}]}
1626995772.936446: {"arg":{"channel":"books-l2-tbt","instId":"TRX-USDT-210924"},"action":"update","data":[{"asks":[["0.05588","0","0","0"],["0.05589","3","0","1"]],"bids":[],"ts":"1626995772890","checksum":617903303}]}
1626995773.0010371: {"arg":{"channel":"books-l2-tbt","instId":"ONT-USDT"},"action":"update","data":[{"asks":[["0.6261","82","0","1"],["1.13","0","0","0"]],"bids":[],"ts":"1626995772954","checksum":387755853}]}
1626995773.011122: {"arg":{"channel":"books-l2-tbt","instId":"XMR-USDT-SWAP"},"action":"update","data":[{"asks":[],"bids":[["196.01","0","0","0"],["195.99","3","0","1"],["195.96","103","0","3"],["195.94","33","0","2"],["195.89","22","0","1"],["195.84","27","0","1"],["194.97","30","0","2"],["194.92","27","0","1"]],"ts":"1626995772964","checksum":173935560}]}
1626995773.021981: {"arg":{"channel":"books-l2-tbt","instId":"OKT-BTC"},"action":"update","data":[{"asks":[],"bids":[["0.001469","0.30706","0","1"]],"ts":"1626995772975","checksum":-1975648761}]}
1626995773.032886: {"arg":{"channel":"books-l2-tbt","instId":"XMR-USDT-SWAP"},"action":"update","data":[{"asks":[],"bids":[["195.94","131","0","3"]],"ts":"1626995772985","checksum":-416569538}]}
1626995773.083044: {"arg":{"channel":"books-l2-tbt","instId":"ONT-USDT"},"action":"update","data":[{"asks":[["0.6283","82","0","1"],["1.1288","0","0","0"]],"bids":[],"ts":"1626995773037","checksum":-514410379}]}
1626995773.090881: {"arg":{"channel":"books-l2-tbt","instId":"DHT-USDT"},"action":"update","data":[{"asks":[["0.793","423.1407","0","1"]],"bids":[],"ts":"1626995773044","checksum":-224137376}]}
1626995773.1318662: {"arg":{"channel":"books-l2-tbt","instId":"TRX-USDT-210924"},"action":"update","data":[{"asks":[["0.05588","3","0","1"],["0.05589","0","0","0"]],"bids":[],"ts":"1626995773085","checksum":617903303}]}
1626995773.147918: {"arg":{"channel":"books-l2-tbt","instId":"XMR-USDT-SWAP"},"action":"update","data":[{"asks":[["196.44","723","0","3"],["196.45","84","0","4"],["197.07","0","0","0"]],"bids":[],"ts":"1626995773102","checksum":-2000628242}]}
1626995773.23003: {"arg":{"channel":"books-l2-tbt","instId":"XMR-USDT-SWAP"},"action":"update","data":[{"asks":[],"bids":[["196.04","318","0","3"],["196","3","0","1"],["195.97","12","0","2"],["195.96","97","0","2"],["195.93","6","0","1"],["195.92","0","0","0"],["195.89","28","0","2"],["195.86","93","0","3"],["195.85","6","0","1"],["195.82","12","0","1"],["195.8","17","0","1"],["195.76","0","0","0"],["195.73","93","0","3"],["195.72","82","0","2"],["195.7","0","0","0"],["195.62","12","0","1"],["195.47","250","0","2"],["195.43","12","0","1"],["195.27","19","0","2"],["195.23","12","0","1"]],"ts":"1626995773183","checksum":166591800}]}
1626995773.250516: {"arg":{"channel":"books-l2-tbt","instId":"XMR-USDT-SWAP"},"action":"update","data":[{"asks":[["197.06","142","0","1"]],"bids":[],"ts":"1626995773203","checksum":166591800}]}
1626995773.2751172: {"arg":{"channel":"books-l2-tbt","instId":"TRX-USDT-210924"},"action":"update","data":[{"asks":[["0.05588","0","0","0"],["0.05589","3","0","1"]],"bids":[],"ts":"1626995773228","checksum":617903303}]}
1626995773.3289258: {"arg":{"channel":"books-l2-tbt","instId":"XMR-USDT-SWAP"},"action":"update","data":[{"asks":[["196.36","3","0","1"],["196.41","0","0","0"],["196.42","10","0","2"],["196.47","0","0","0"],["196.5","10","0","2"],["196.55","0","0","0"],["196.99","3","0","1"],["197.04","0","0","0"]],"bids":[],"ts":"1626995773282","checksum":1177918342}]}
1626995773.333816: {"arg":{"channel":"books-l2-tbt","instId":"ONT-USDT"},"action":"update","data":[{"asks":[],"bids":[["0.6214","1316.539","0","3"]],"ts":"1626995773287","checksum":1642067877}]}
1626995773.3517492: {"arg":{"channel":"books-l2-tbt","instId":"XMR-USDT-SWAP"},"action":"update","data":[{"asks":[["196.44","755","0","4"]],"bids":[],"ts":"1626995773304","checksum":-1605707193}]}
1626995773.3734112: {"arg":{"channel":"books-l2-tbt","instId":"XMR-USDT-SWAP"},"action":"update","data":[{"asks":[["196.45","52","0","3"]],"bids":[],"ts":"1626995773324","checksum":605980847}]}
1626995773.384686: {"arg":{"channel":"books-l2-tbt","instId":"ONT-USDT"},"action":"update","data":[{"asks":[],"bids":[["0.6214","2596.539","0","7"]],"ts":"1626995773338","checksum":503095006}]}
1626995773.414623: {"arg":{"channel":"books-l2-tbt","instId":"AUCTION-USDT"},"action":"update","data":[{"asks":[],"bids":[["14.25","0","0","0"]],"ts":"1626995773369","checksum":1416180795}]}
1626995773.424148: {"arg":{"channel":"books-l2-tbt","instId":"OKT-BTC"},"action":"update","data":[{"asks":[],"bids":[],"ts":"1626995773377","checksum":-1975648761}]}
1626995773.427277: {"arg":{"channel":"trades","instId":"PAY-BTC"},"data":[{"instId":"PAY-BTC","tradeId":"6071315","px":"0.00000137","sz":"2586.649","side":"buy","ts":"1626995773376"}]}
1626995773.435621: {"arg":{"channel":"books-l2-tbt","instId":"XMR-USDT-SWAP"},"action":"update","data":[{"asks":[],"bids":[["196.02","0","0","0"],["195.98","0","0","0"],["195.9","6","0","1"],["195.78","33","0","2"],["195.02","0","0","0"],["194.94","6","0","1"]],"ts":"1626995773389","checksum":495836438}]}
1626995773.460573: {"arg":{"channel":"books-l2-tbt","instId":"TRX-USDT-210924"},"action":"update","data":[{"asks":[],"bids":[["0.05445","0","0","0"],["0.05444","34","0","2"]],"ts":"1626995773411","checksum":555182434}]}
1626995773.460732: {"arg":{"channel":"books-l2-tbt","instId":"FUN-BTC"},"action":"update","data":[{"asks":[],"bids":[["0.00000041","0","0","0"]],"ts":"1626995773412","checksum":645519708}]}
1626995773.465871: {"arg":{"channel":"books-l2-tbt","instId":"ONT-USDT"},"action":"update","data":[{"asks":[],"bids":[["0.6208","9933.431","0","2"]],"ts":"1626995773419","checksum":-806991940}]}
1626995773.4881139: {"arg":{"channel":"books-l2-tbt","instId":"TRX-USDT-210924"},"action":"update","data":[{"asks":[],"bids":[["0.05449","0","0","0"]],"ts":"1626995773441","checksum":971842596}]}
1626995773.5095081: {"arg":{"channel":"books-l2-tbt","instId":"TRX-USDT-210924"},"action":"update","data":[{"asks":[["0.05453","0","0","0"]],"bids":[],"ts":"1626995773462","checksum":-1388532625}]}
1626995773.517798: {"arg":{"channel":"books-l2-tbt","instId":"TRX-USDT-210924"},"action":"update","data":[{"asks":[["0.05452","16","0","2"]],"bids":[["0.05443","0","0","0"],["0.05442","479","0","4"]],"ts":"1626995773472","checksum":-1934351386}]}
1626995773.53844: {"arg":{"channel":"books-l2-tbt","instId":"ONT-USDT"},"action":"update","data":[{"asks":[],"bids":[["0.6214","2916.539","0","8"]],"ts":"1626995773491","checksum":1124021786}]}
1626995773.538572: {"arg":{"channel":"books-l2-tbt","instId":"XMR-USDT-SWAP"},"action":"update","data":[{"asks":[["196.31","548","0","5"],["196.35","0","0","0"]],"bids":[],"ts":"1626995773491","checksum":1127207036}]}
1626995773.5386639: {"arg":{"channel":"books-l2-tbt","instId":"OKT-BTC"},"action":"update","data":[{"asks":[["0.001476","0","0","0"]],"bids":[],"ts":"1626995773492","checksum":921147846}]}
1626995773.53901: {"arg":{"channel":"books-l2-tbt","instId":"TRX-USDT-210924"},"action":"update","data":[{"asks":[],"bids":[["0.05448","0","0","0"]],"ts":"1626995773492","checksum":-196599100}]}
1626995773.550545: {"arg":{"channel":"books-l2-tbt","instId":"TRX-USDT-210924"},"action":"update","data":[{"asks":[["0.05459","79","0","2"],["0.0546","42","0","1"],["0.05461","5","0","2"],["0.05463","143","0","1"],["0.05469","29","0","3"],["0.05471","0","0","0"],["0.05475","1","0","1"],["0.05476","81","0","1"]],"bids":[["0.05444","55","0","3"],["0.05436","0","0","0"],["0.05435","1","0","1"],["0.05425","0","0","0"],["0.05424","1","0","1"]],"ts":"1626995773502","checksum":-2031988935}]}
1626995773.552813: {"arg":{"channel":"tickers","instId":"PAY-BTC"},"data":[{"instType":"SPOT","instId":"PAY-BTC","last":"0.00000137","lastSz":"2586.649","askPx":"0.00000139","askSz":"5342.072","bidPx":"0.00000136","bidSz":"6884.955","open24h":"0.00000136","high24h":"0.00000144","low24h":"0.00000136","sodUtc0":"0.00000138","sodUtc8":"0.00000138","volCcy24h":"45.113","vol24h":"32760286.839","ts":"1626995773498"}]}
1626995773.571764: {"arg":{"channel":"books-l2-tbt","instId":"TRX-USDT-210924"},"action":"update","data":[{"asks":[["0.05588","3","0","1"],["0.05589","0","0","0"]],"bids":[],"ts":"1626995773525","checksum":-2031988935}]}
1626995773.578109: {"arg":{"channel":"books-l2-tbt","instId":"XMR-USDT-SWAP"},"action":"update","data":[{"asks":[["196.43","65","0","2"],["196.44","690","0","2"],["197.06","0","0","0"]],"bids":[],"ts":"1626995773531","checksum":814626894}]}
1626995773.582735: {"arg":{"channel":"books-l2-tbt","instId":"TRX-USDT-210924"},"action":"update","data":[{"asks":[],"bids":[["0.05445","8","0","1"]],"ts":"1626995773534","checksum":-1061623402}]}
1626995773.601313: {"arg":{"channel":"books-l2-tbt","instId":"XMR-USDT-SWAP"},"action":"update","data":[{"asks":[["196.43","762","0","3"],["196.44","7","0","1"]],"bids":[],"ts":"1626995773552","checksum":474200535}]}
1626995773.601461: {"arg":{"channel":"books-l2-tbt","instId":"TRX-USDT-210924"},"action":"update","data":[{"asks":[],"bids":[["0.05444","41","0","2"]],"ts":"1626995773556","checksum":793211919}]}
1626995773.609586: {"arg":{"channel":"books-l2-tbt","instId":"OKT-BTC"},"action":"update","data":[{"asks":[["0.001489","11.54107264","0","1"]],"bids":[],"ts":"1626995773563","checksum":-1724916304}]}
1626995773.609687: {"arg":{"channel":"books-l2-tbt","instId":"ONT-USDT"},"action":"update","data":[{"asks":[],"bids":[["0.6201","390","0","1"],["0.6199","0","0","0"]],"ts":"1626995773564","checksum":-581181735}]}
1626995773.6097522: {"arg":{"channel":"books-l2-tbt","instId":"TRX-USDT-210924"},"action":"update","data":[{"asks":[],"bids":[["0.05443","14","0","1"]],"ts":"1626995773564","checksum":-2113843440}]}
1626995773.640543: {"arg":{"channel":"books-l2-tbt","instId":"OKT-BTC"},"action":"update","data":[{"asks":[["0.00149","0","0","0"]],"bids":[],"ts":"1626995773594","checksum":-224621184}]}
1626995773.6522439: {"arg":{"channel":"books-l2-tbt","instId":"OKT-BTC"},"action":"update","data":[{"asks":[["0.001488","1.26604034","0","1"]],"bids":[],"ts":"1626995773605","checksum":-330981321}]}
1626995773.659768: {"arg":{"channel":"books-l2-tbt","instId":"ONT-USDT"},"action":"update","data":[{"asks":[["0.6231","1223.318397","0","1"],["0.6232","486.341898","0","1"],["1.1285","0","0","0"]],"bids":[],"ts":"1626995773613","checksum":1097552946}]}
1626995773.6650748: {"arg":{"channel":"books-l2-tbt","instId":"XMR-USDT-SWAP"},"action":"update","data":[{"asks":[["196.32","263","0","3"]],"bids":[],"ts":"1626995773618","checksum":-2141475231}]}
1626995773.673902: {"arg":{"channel":"books-l2-tbt","instId":"AUCTION-USDT"},"action":"update","data":[{"asks":[],"bids":[["14.29","151.222958","0","1"]],"ts":"1626995773628","checksum":-1774051742}]}
1626995773.684281: {"arg":{"channel":"books-l2-tbt","instId":"XMR-USDT-SWAP"},"action":"update","data":[{"asks":[["197.04","142","0","1"]],"bids":[["195.31","0","0","0"]],"ts":"1626995773638","checksum":-2141475231}]}
1626995773.715393: {"arg":{"channel":"books-l2-tbt","instId":"TRX-USDT-210924"},"action":"update","data":[{"asks":[],"bids":[["0.05442","3","0","1"]],"ts":"1626995773669","checksum":474690702}]}
1626995773.722754: {"arg":{"channel":"books-l2-tbt","instId":"OKT-BTC"},"action":"update","data":[{"asks":[],"bids":[["0.00145","4.94","0","2"]],"ts":"1626995773676","checksum":778974076}]}
1626995773.727482: {"arg":{"channel":"books-l2-tbt","instId":"TRX-USDT-210924"},"action":"update","data":[{"asks":[["0.05588","0","0","0"],["0.05589","3","0","1"]],"bids":[],"ts":"1626995773680","checksum":474690702}]}
1626995773.735702: {"arg":{"channel":"books-l2-tbt","instId":"ONT-USDT"},"action":"update","data":[{"asks":[],"bids":[["0.6214","2596.539","0","7"]],"ts":"1626995773687","checksum":1951483401}]}
1626995773.7358341: {"arg":{"channel":"books-l2-tbt","instId":"TRX-USDT-210924"},"action":"update","data":[{"asks":[],"bids":[["0.05445","17","0","2"]],"ts":"1626995773689","checksum":1961601580}]}
1626995773.741987: {"arg":{"channel":"books-l2-tbt","instId":"FUN-BTC"},"action":"update","data":[{"asks":[],"bids":[["0.000000413","6710.43","0","1"]],"ts":"1626995773696","checksum":1223695811}]}
1626995773.757616: {"arg":{"channel":"books-l2-tbt","instId":"TRX-USDT-210924"},"action":"update","data":[{"asks":[["0.05458","1","0","1"],["0.05459","78","0","1"],["0.05463","144","0","2"],["0.05465","76","0","2"],["0.05474","1","0","1"],["0.05475","0","0","0"]],"bids":[],"ts":"1626995773710","checksum":1741587975}]}
1626995773.785324: {"arg":{"channel":"books-l2-tbt","instId":"ONT-USDT"},"action":"update","data":[{"asks":[],"bids":[["0.6214","2276.539","0","6"]],"ts":"1626995773739","checksum":1141725199}]}
1626995773.7854578: {"arg":{"channel":"books-l2-tbt","instId":"TRX-USDT-210924"},"action":"update","data":[{"asks":[],"bids":[["0.05445","419","0","5"]],"ts":"1626995773739","checksum":1498850155}]}
1626995773.795538: {"arg":{"channel":"books-l2-tbt","instId":"TRX-USDT-210924"},"action":"update","data":[{"asks":[],"bids":[["0.05422","0","0","0"],["0.05421","3","0","1"]],"ts":"1626995773749","checksum":641035462}]}
1626995773.7967858: {"arg":{"channel":"books-l2-tbt","instId":"XMR-USDT-SWAP"},"action":"update","data":[{"asks":[["196.42","75","0","4"],["196.43","697","0","1"]],"bids":[],"ts":"1626995773751","checksum":-1847806368}]}
1626995773.817863: {"arg":{"channel":"books-l2-tbt","instId":"TRX-USDT-210924"},"action":"update","data":[{"asks":[],"bids":[["0.05446","8","0","1"],["0.05445","411","0","4"]],"ts":"1626995773770","checksum":778806333}]}
1626995773.831428: {"arg":{"channel":"books-l2-tbt","instId":"ONT-USDT"},"action":"update","data":[{"asks":[],"bids":[["0.6214","1636.539","0","4"]],"ts":"1626995773784","checksum":1927275999}]}
1626995773.841383: {"arg":{"channel":"books-l2-tbt","instId":"ONT-USDT"},"action":"update","data":[{"asks":[],"bids":[["0.6214","1316.539","0","3"]],"ts":"1626995773793","checksum":307091130}]}
1626995773.857076: {"arg":{"channel":"books-l2-tbt","instId":"TRX-USDT-210924"},"action":"update","data":[{"asks":[["0.05462","86","0","3"]],"bids":[["0.05445","143","0","2"]],"ts":"1626995773809","checksum":788744263}]}
1626995773.907777: {"arg":{"channel":"books-l2-tbt","instId":"ONT-USDT"},"action":"update","data":[{"asks":[],"bids":[["0.6215","320","0","1"]],"ts":"1626995773861","checksum":1784433689}]}
1626995773.9215722: {"arg":{"channel":"books-l2-tbt","instId":"TRX-USDT-210924"},"action":"update","data":[{"asks":[["0.05461","94","0","3"]],"bids":[["0.05442","319","0","3"]],"ts":"1626995773874","checksum":799769806}]}
1626995773.950943: {"arg":{"channel":"books-l2-tbt","instId":"TRX-USDT-210924"},"action":"update","data":[{"asks":[["0.05588","3","0","1"],["0.05589","0","0","0"]],"bids":[],"ts":"1626995773904","checksum":799769806}]}
1626995773.964042: {"arg":{"channel":"books-l2-tbt","instId":"OKT-BTC"},"action":"update","data":[{"asks":[],"bids":[["0.001409","7.07195883","0","1"]],"ts":"1626995773916","checksum":1210553246}]}
1626995773.970606: {"arg":{"channel":"books-l2-tbt","instId":"TRX-USDT-210924"},"action":"update","data":[{"asks":[],"bids":[["0.05444","21","0","1"],["0.05442","339","0","4"]],"ts":"1626995773924","checksum":-397218953}]}
1626995773.975112: {"arg":{"channel":"books-l2-tbt","instId":"ONT-USDT"},"action":"update","data":[{"asks":[],"bids":[["0.6215","640","0","2"],["0.6214","996.539","0","2"]],"ts":"1626995773928","checksum":-1381522734}]}
1626995774.050903: {"arg":{"channel":"books-l2-tbt","instId":"XMR-USDT-SWAP"},"action":"update","data":[{"asks":[["196.43","1357","0","2"]],"bids":[],"ts":"1626995774003","checksum":835630810}]}
1626995774.0584729: {"arg":{"channel":"books-l2-tbt","instId":"OKT-BTC"},"action":"update","data":[{"asks":[["0.001491","0","0","0"]],"bids":[],"ts":"1626995774012","checksum":345514676}]}
1626995774.070217: {"arg":{"channel":"books-l2-tbt","instId":"XMR-USDT-SWAP"},"action":"update","data":[{"asks":[["196.43","659","0","1"]],"bids":[],"ts":"1626995774023","checksum":-1061643191}]}
1626995774.0889359: {"arg":{"channel":"books-l2-tbt","instId":"ONT-USDT"},"action":"update","data":[{"asks":[["0.623","3806.341898","0","3"],["0.6232","0","0","0"],["1.1285","10.5","0","1"]],"bids":[["0.6215","960","0","3"]],"ts":"1626995774043","checksum":-1818752471}]}
1626995774.108874: {"arg":{"channel":"books-l2-tbt","instId":"OKT-BTC"},"action":"update","data":[{"asks":[["0.001476","0.62258414","0","1"]],"bids":[],"ts":"1626995774062","checksum":924847522}]}
1626995774.125153: {"arg":{"channel":"books-l2-tbt","instId":"TRX-USDT-210924"},"action":"update","data":[{"asks":[["0.05464","158","0","1"],["0.05499","0","0","0"]],"bids":[["0.05445","9","0","1"]],"ts":"1626995774077","checksum":715971789}]}
1626995774.131865: {"arg":{"channel":"books-l2-tbt","instId":"ONT-USDT"},"action":"update","data":[{"asks":[["0.622","1030.539","0","2"],["0.6221","0","0","0"],["1.1288","10.09339","0","1"]],"bids":[],"ts":"1626995774084","checksum":-2009900036}]}
1626995774.168353: {"arg":{"channel":"books-l2-tbt","instId":"TRX-USDT-210924"},"action":"update","data":[{"asks":[],"bids":[["0.05421","0","0","0"],["0.0542","7","0","2"],["0.00055","1","0","1"]],"ts":"1626995774119","checksum":-2131082635}]}
1626995774.179698: {"arg":{"channel":"books-l2-tbt","instId":"ONT-USDT"},"action":"update","data":[{"asks":[],"bids":[["0.6215","1600","0","5"]],"ts":"1626995774133","checksum":193248692}]}
1626995774.1861708: {"arg":{"channel":"books-l2-tbt","instId":"TRX-USDT-210924"},"action":"update","data":[{"asks":[["0.05463","277","0","3"],["0.05495","668","0","3"]],"bids":[["0.05442","494","0","5"]],"ts":"1626995774139","checksum":-1997195715}]}
1626995774.193938: {"arg":{"channel":"books-l2-tbt","instId":"XMR-USDT-SWAP"},"action":"update","data":[{"asks":[],"bids":[["195.94","33","0","2"],["195.81","27","0","1"],["195.76","30","0","1"]],"ts":"1626995774147","checksum":-1705896031}]}
1626995774.2235131: {"arg":{"channel":"books-l2-tbt","instId":"ONT-USDT"},"action":"update","data":[{"asks":[],"bids":[["0.6215","1280","0","4"]],"ts":"1626995774177","checksum":337779326}]}
1626995774.248775: {"arg":{"channel":"books-l2-tbt","instId":"TRX-USDT-210924"},"action":"update","data":[{"asks":[],"bids":[["0.05442","339","0","4"]],"ts":"1626995774202","checksum":1453749598}]}
1626995774.263859: {"arg":{"channel":"books-l2-tbt","instId":"TRX-USDT-210924"},"action":"update","data":[{"asks":[],"bids":[["0.05442","181","0","3"],["0.05421","3","0","1"],["0.0542","4","0","1"]],"ts":"1626995774211","checksum":2120397273}]}
1626995774.263915: {"arg":{"channel":"books-l2-tbt","instId":"ONT-USDT"},"action":"update","data":[{"asks":[],"bids":[["0.6216","2545.765255","0","1"],["0.6209","10376.899","0","1"]],"ts":"1626995774216","checksum":559747200}]}
1626995774.277579: {"arg":{"channel":"books-l2-tbt","instId":"ONT-USDT"},"action":"update","data":[{"asks":[["0.622","85","0","1"]],"bids":[["0.6214","51","0","1"]],"ts":"1626995774229","checksum":1372273185}]}
1626995774.2841642: {"arg":{"channel":"books-l2-tbt","instId":"ONT-USDT"},"action":"update","data":[{"asks":[],"bids":[["0.6213","4570.667134","0","4"]],"ts":"1626995774238","checksum":1080260251}]}
1626995774.295177: {"arg":{"channel":"books-l2-tbt","instId":"ONT-USDT"},"action":"update","data":[{"asks":[["0.622","0","0","0"],["1.13","13919.895296","0","1"]],"bids":[["0.6217","51","0","1"],["0.6215","960","0","3"],["0.6212","0","0","0"]],"ts":"1626995774247","checksum":1991233902}]}
1626995774.300849: {"arg":{"channel":"books-l2-tbt","instId":"XMR-USDT-SWAP"},"action":"update","data":[{"asks":[["196.35","7","0","1"],["196.39","7","0","1"],["196.42","68","0","3"],["196.43","666","0","2"],["196.44","35","0","2"],["196.46","0","0","0"],["196.47","7","0","1"],["196.48","35","0","2"],["196.49","0","0","0"],["196.5","3","0","1"],["196.53","0","0","0"],["196.54","82","0","2"],["196.55","17","0","1"],["196.62","0","0","0"],["196.88","17","0","1"],["196.95","12","0","1"],["197.37","27","0","1"],["197.42","0","0","0"]],"bids":[],"ts":"1626995774252","checksum":-1497765641}]}
1626995774.304257: {"arg":{"channel":"books-l2-tbt","instId":"ONT-USDT"},"action":"update","data":[{"asks":[["0.6234","6385.082783","0","1"],["1.13","0","0","0"]],"bids":[],"ts":"1626995774258","checksum":528814813}]}
1626995774.327918: {"arg":{"channel":"books-l2-tbt","instId":"ONT-USDT"},"action":"update","data":[{"asks":[["0.6222","85","0","1"],["0.6224","945.539","0","1"],["0.6226","993.334745","0","2"],["1.1285","0","0","0"],["1.1288","0","0","0"]],"bids":[["0.6217","0","0","0"]],"ts":"1626995774270","checksum":-490377474}]}
1626995774.327996: {"arg":{"channel":"books-l2-tbt","instId":"XMR-USDT-SWAP"},"action":"update","data":[{"asks":[["196.49","12","0","1"],["196.54","70","0","1"],["196.58","3","0","1"],["196.59","12","0","1"],["196.63","0","0","0"],["196.64","0","0","0"],["196.68","12","0","1"],["196.75","0","0","0"],["196.88","29","0","2"],["196.95","0","0","0"],["197.08","12","0","1"],["197.13","0","0","0"]],"bids":[["196.04","132","0","2"]],"ts":"1626995774270","checksum":-266589314}]}
1626995774.328075: {"arg":{"channel":"books-l2-tbt","instId":"TRX-USDT-210924"},"action":"update","data":[{"asks":[],"bids":[["0.05446","222","0","3"]],"ts":"1626995774275","checksum":1708879082}]}
1626995774.328107: {"arg":{"channel":"books-l2-tbt","instId":"ONT-USDT"},"action":"update","data":[{"asks":[],"bids":[["0.6216","2649.505516","0","2"],["0.6213","4467.848082","0","3"]],"ts":"1626995774280","checksum":839816713}]}
1626995774.3371258: {"arg":{"channel":"books-l2-tbt","instId":"ONT-USDT"},"action":"update","data":[{"asks":[["0.6224","1565.539","0","2"]],"bids":[["0.6216","3340.505516","0","5"]],"ts":"1626995774290","checksum":663071505}]}
1626995774.358381: {"arg":{"channel":"books-l2-tbt","instId":"XMR-USDT-SWAP"},"action":"update","data":[{"asks":[["196.31","734","0","6"]],"bids":[],"ts":"1626995774311","checksum":-1433396381}]}
1626995774.36856: {"arg":{"channel":"books-l2-tbt","instId":"ONT-USDT"},"action":"update","data":[{"asks":[],"bids":[["0.6198","0","0","0"]],"ts":"1626995774322","checksum":-104574214}]}
1626995774.3803022: {"arg":{"channel":"books-l2-tbt","instId":"ONT-USDT"},"action":"update","data":[{"asks":[],"bids":[["0.6216","794.740261","0","4"],["0.6208","405.5","0","1"],["0.6201","792.868423","0","2"]],"ts":"1626995774334","checksum":-575562895}]}
1626995774.383224: {"arg":{"channel":"books-l2-tbt","instId":"TRX-USDT-210924"},"action":"update","data":[{"asks":[],"bids":[["0.05446","8","0","1"],["0.05442","23","0","2"]],"ts":"1626995774335","checksum":2034929258}]}
1626995774.390143: {"arg":{"channel":"books-l2-tbt","instId":"ONT-USDT"},"action":"update","data":[{"asks":[["0.6244","0","0","0"],["1.1285","10.5","0","1"]],"bids":[["0.6216","1114.740261","0","5"],["0.6213","548.849604","0","1"]],"ts":"1626995774343","checksum":30473690}]}
1626995774.401063: {"arg":{"channel":"books-l2-tbt","instId":"ONT-USDT"},"action":"update","data":[{"asks":[["0.6224","4290.641786","0","3"]],"bids":[["0.6215","640","0","2"]],"ts":"1626995774354","checksum":1206906306}]}
1626995774.402936: {"arg":{"channel":"books-l2-tbt","instId":"TRX-USDT-210924"},"action":"update","data":[{"asks":[],"bids":[["0.05437","0","0","0"]],"ts":"1626995774356","checksum":1943848476}]}
1626995774.411797: {"arg":{"channel":"books-l2-tbt","instId":"ONT-USDT"},"action":"update","data":[{"asks":[],"bids":[["0.6201","390","0","1"]],"ts":"1626995774365","checksum":219285657}]}
1626995774.421299: {"arg":{"channel":"books-l2-tbt","instId":"ONT-USDT"},"action":"update","data":[{"asks":[["0.6224","3345.102786","0","2"]],"bids":[["0.6198","402.868423","0","1"]],"ts":"1626995774375","checksum":195209342}]}
1626995774.432031: {"arg":{"channel":"books-l2-tbt","instId":"ONT-USDT"},"action":"update","data":[{"asks":[["0.6223","103.740261","0","1"],["0.6225","0","0","0"]],"bids":[["0.6216","1011","0","4"],["0.6214","154.740261","0","2"]],"ts":"1626995774385","checksum":2097208221}]}
1626995774.443769: {"arg":{"channel":"books-l2-tbt","instId":"TRX-USDT-210924"},"action":"update","data":[{"asks":[],"bids":[["0.05442","178","0","3"]],"ts":"1626995774397","checksum":-136723941}]}
1626995774.453248: {"arg":{"channel":"books-l2-tbt","instId":"TRX-USDT-210924"},"action":"update","data":[{"asks":[],"bids":[["0.05442","488","0","5"]],"ts":"1626995774408","checksum":-218154324}]}
1626995774.4625988: {"arg":{"channel":"books-l2-tbt","instId":"XMR-USDT-SWAP"},"action":"update","data":[{"asks":[["196.41","34","0","1"],["196.42","35","0","2"],["196.5","18","0","2"],["196.56","32","0","1"]],"bids":[],"ts":"1626995774413","checksum":1291355745}]}
1626995774.48135: {"arg":{"channel":"books-l2-tbt","instId":"ONT-USDT"},"action":"update","data":[{"asks":[["0.6254","79","0","1"],["1.1285","0","0","0"]],"bids":[],"ts":"1626995774435","checksum":-894491910}]}
1626995774.493098: {"arg":{"channel":"books-l2-tbt","instId":"ONT-USDT"},"action":"update","data":[{"asks":[],"bids":[["0.6217","320","0","1"]],"ts":"1626995774446","checksum":144593417}]}
1626995774.503783: {"arg":{"channel":"books-l2-tbt","instId":"ONT-USDT"},"action":"update","data":[{"asks":[],"bids":[["0.6214","1100.279261","0","3"]],"ts":"1626995774457","checksum":-932391582}]}
1626995774.509423: {"arg":{"channel":"books-l2-tbt","instId":"TRX-USDT-210924"},"action":"update","data":[{"asks":[],"bids":[["0.05447","2","0","1"]],"ts":"1626995774460","checksum":-634497759}]}
1626995774.514836: {"arg":{"channel":"books-l2-tbt","instId":"TRX-USDT-210924"},"action":"update","data":[{"asks":[["0.0545","2","0","1"]],"bids":[],"ts":"1626995774469","checksum":-632520368}]}
1626995774.520184: {"arg":{"channel":"books-l2-tbt","instId":"XMR-USDT-SWAP"},"action":"update","data":[{"asks":[],"bids":[["196.04","70","0","1"],["196","65","0","2"],["195.99","0","0","0"],["195.9","9","0","2"]],"ts":"1626995774474","checksum":1794417340}]}
1626995774.5242: {"arg":{"channel":"books-l2-tbt","instId":"ONT-USDT"},"action":"update","data":[{"asks":[["0.6222","1030.539","0","2"]],"bids":[],"ts":"1626995774478","checksum":545952632}]}
1626995774.524244: {"arg":{"channel":"books-l2-tbt","instId":"OKT-BTC"},"action":"update","data":[{"asks":[["0.001476","0","0","0"]],"bids":[],"ts":"1626995774479","checksum":345514676}]}
1626995774.528197: {"arg":{"channel":"books-l2-tbt","instId":"TRX-USDT-210924"},"action":"update","data":[{"asks":[["0.05452","14","0","1"],["0.05458","8","0","2"]],"bids":[],"ts":"1626995774481","checksum":-6300264}]}
1626995774.534742: {"arg":{"channel":"books-l2-tbt","instId":"ONT-USDT"},"action":"update","data":[{"asks":[],"bids":[["0.6215","0","0","0"]],"ts":"1626995774488","checksum":1504445449}]}
1626995774.541632: {"arg":{"channel":"books-l2-tbt","instId":"XMR-USDT-SWAP"},"action":"update","data":[{"asks":[],"bids":[["195.91","0","0","0"],["195.82","15","0","2"],["195.77","0","0","0"],["195.72","85","0","3"],["195.42","0","0","0"],["195.33","3","0","1"]],"ts":"1626995774492","checksum":552005717}]}
1626995774.563457: {"arg":{"channel":"books-l2-tbt","instId":"AUCTION-USDT"},"action":"update","data":[{"asks":[],"bids":[],"ts":"1626995774516","checksum":-1774051742}]}
1626995774.5638368: {"arg":{"channel":"books-l2-tbt","instId":"OKT-BTC"},"action":"update","data":[{"asks":[["0.001476","0.62258414","0","1"]],"bids":[],"ts":"1626995774518","checksum":924847522}]}
1626995774.579402: {"arg":{"channel":"books-l2-tbt","instId":"TRX-USDT-210924"},"action":"update","data":[{"asks":[["0.05495","286","0","2"]],"bids":[["0.05442","23","0","2"]],"ts":"1626995774533","checksum":-1848980903}]}
1626995774.583052: {"arg":{"channel":"books-l2-tbt","instId":"XMR-USDT-SWAP"},"action":"update","data":[{"asks":[["196.41","66","0","2"],["196.42","3","0","1"],["196.43","637","0","2"]],"bids":[],"ts":"1626995774536","checksum":-1932065706}]}
1626995774.613861: {"arg":{"channel":"books-l2-tbt","instId":"TRX-USDT-210924"},"action":"update","data":[{"asks":[["0.05452","22","0","2"],["0.05455","0","0","0"]],"bids":[],"ts":"1626995774564","checksum":-558707701}]}
1626995774.6167629: {"arg":{"channel":"books-l2-tbt","instId":"ONT-USDT"},"action":"update","data":[{"asks":[["0.6221","2752.353814","0","1"],["1.1269","0","0","0"]],"bids":[],"ts":"1626995774570","checksum":-1933994139}]}
1626995774.632846: {"arg":{"channel":"books-l2-tbt","instId":"TRX-USDT-210924"},"action":"update","data":[{"asks":[["0.0546","0","0","0"],["0.05461","279","0","5"],["0.05463","134","0","2"],["0.05477","395","0","2"],["0.05495","143","0","1"]],"bids":[["0.0543","43","0","2"],["0.05428","0","0","0"],["0.05427","0","0","0"],["0.05413","143","0","1"],["0.05407","103","0","2"],["0.05405","414","0","2"]],"ts":"1626995774586","checksum":-1421933031}]}
1626995774.643233: {"arg":{"channel":"books-l2-tbt","instId":"TRX-USDT-210924"},"action":"update","data":[{"asks":[["0.05499","381","0","1"]],"bids":[["0.05442","497","0","5"]],"ts":"1626995774596","checksum":-1454691355}]}
1626995774.645887: {"arg":{"channel":"books-l2-tbt","instId":"ONT-USDT"},"action":"update","data":[{"asks":[["0.623","1306.341898","0","2"]],"bids":[["0.6217","640","0","2"]],"ts":"1626995774600","checksum":-1073035112}]}
1626995774.6582348: {"arg":{"channel":"books-l2-tbt","instId":"ONT-USDT"},"action":"update","data":[{"asks":[],"bids":[["0.6216","371","0","2"],["0.6207","0","0","0"]],"ts":"1626995774612","checksum":1782602715}]}
1626995774.662053: {"arg":{"channel":"trades","instId":"OKT-BTC"},"data":[{"instId":"OKT-BTC","tradeId":"3406235","px":"0.001472","sz":"0.38686369","side":"sell","ts":"1626995774612"}]}
1626995774.663533: {"arg":{"channel":"books-l2-tbt","instId":"TRX-USDT-210924"},"action":"update","data":[{"asks":[],"bids":[["0.05445","0","0","0"]],"ts":"1626995774616","checksum":-1248573041}]}
1626995774.67456: {"arg":{"channel":"books-l2-tbt","instId":"TRX-USDT-210924"},"action":"update","data":[{"asks":[["0.05456","23","0","2"],["0.05458","7","0","1"],["0.05459","79","0","2"],["0.05461","278","0","4"],["0.05467","1","0","1"],["0.05469","28","0","2"],["0.05473","1","0","1"],["0.05474","0","0","0"]],"bids":[["0.05441","150","0","2"],["0.05439","1","0","1"],["0.05438","0","0","0"],["0.05436","1","0","1"],["0.05435","0","0","0"],["0.05434","6","0","2"],["0.0543","42","0","1"],["0.05428","1","0","1"],["0.05424","0","0","0"],["0.05423","1","0","1"]],"ts":"1626995774627","checksum":-2144021851}]}
1626995774.678216: {"arg":{"channel":"books-l2-tbt","instId":"ONT-USDT"},"action":"update","data":[{"asks":[],"bids":[["0.6209","0","0","0"]],"ts":"1626995774632","checksum":1902958194}]}
1626995774.694052: {"arg":{"channel":"books-l2-tbt","instId":"ONT-USDT"},"action":"update","data":[{"asks":[],"bids":[["0.6216","51","0","1"]],"ts":"1626995774643","checksum":-371377737}]}
1626995774.718158: {"arg":{"channel":"books-l2-tbt","instId":"XMR-USDT-SWAP"},"action":"update","data":[{"asks":[],"bids":[],"ts":"1626995774671","checksum":-1932065706}]}
1626995774.721909: {"arg":{"channel":"books-l2-tbt","instId":"ONT-USDT"},"action":"update","data":[{"asks":[["0.6242","2500","0","1"],["1.1224","0","0","0"]],"bids":[],"ts":"1626995774675","checksum":-92984242}]}
1626995774.745164: {"arg":{"channel":"tickers","instId":"OKT-BTC"},"data":[{"instType":"SPOT","instId":"OKT-BTC","last":"0.001472","lastSz":"0.38686369","askPx":"0.001474","askSz":"0.62267756","bidPx":"0.001471","bidSz":"0.24901841","open24h":"0.001402","high24h":"0.001489","low24h":"0.001387","sodUtc0":"0.001408","sodUtc8":"0.001437","volCcy24h":"17.15794896","vol24h":"12035.57807924","ts":"1626995774693"}]}
1626995774.757194: {"arg":{"channel":"books-l2-tbt","instId":"TRX-USDT-210924"},"action":"update","data":[{"asks":[["0.0546","20","0","1"],["0.05462","66","0","2"]],"bids":[],"ts":"1626995774709","checksum":-2084296745}]}
1626995774.7593: {"arg":{"channel":"books-l2-tbt","instId":"PAY-BTC"},"action":"update","data":[{"asks":[["0.0000014","2870.065","0","3"]],"bids":[],"ts":"1626995774712","checksum":-1506992290}]}
1626995774.765384: {"arg":{"channel":"books-l2-tbt","instId":"TRX-USDT-210924"},"action":"update","data":[{"asks":[["0.05456","1","0","1"]],"bids":[["0.05444","0","0","0"]],"ts":"1626995774719","checksum":-2025272530}]}
1626995774.7720802: {"arg":{"channel":"books-l2-tbt","instId":"DHT-USDT"},"action":"update","data":[{"asks":[["0.793","0","0","0"]],"bids":[],"ts":"1626995774725","checksum":-765422627}]}
1626995774.778346: {"arg":{"channel":"books-l2-tbt","instId":"TRX-USDT-210924"},"action":"update","data":[{"asks":[],"bids":[["0.05434","5","0","1"],["0.05433","334","0","2"],["0.05423","0","0","0"],["0.05422","1","0","1"]],"ts":"1626995774728","checksum":1549145885}]}
1626995774.7837691: {"arg":{"channel":"books-l2-tbt","instId":"ONT-USDT"},"action":"update","data":[{"asks":[],"bids":[["0.6218","320","0","1"]],"ts":"1626995774735","checksum":678158394}]}
1626995774.791706: {"arg":{"channel":"books-l2-tbt","instId":"XMR-USDT-SWAP"},"action":"update","data":[{"asks":[["196.43","593","0","2"]],"bids":[],"ts":"1626995774744","checksum":-1060511826}]}
1626995774.794454: {"arg":{"channel":"books-l2-tbt","instId":"ONT-USDT"},"action":"update","data":[{"asks":[],"bids":[["0.6217","320","0","1"]],"ts":"1626995774747","checksum":1280848100}]}
1626995774.7972548: {"arg":{"channel":"books-l2-tbt","instId":"TRX-USDT-210924"},"action":"update","data":[{"asks":[["0.05459","1","0","1"],["0.05461","189","0","3"],["0.05463","1","0","1"]],"bids":[["0.05429","39","0","1"],["0.05408","0","0","0"]],"ts":"1626995774751","checksum":-873606725}]}
1626995774.810663: {"arg":{"channel":"books-l2-tbt","instId":"XMR-USDT-SWAP"},"action":"update","data":[{"asks":[],"bids":[["195.83","31","0","1"]],"ts":"1626995774764","checksum":-907017916}]}
1626995774.83407: {"arg":{"channel":"books-l2-tbt","instId":"ONT-USDT"},"action":"update","data":[{"asks":[],"bids":[["0.6217","640","0","2"]],"ts":"1626995774788","checksum":678158394}]}
1626995774.844484: {"arg":{"channel":"books-l2-tbt","instId":"PAY-BTC"},"action":"update","data":[{"asks":[["0.00000139","5342.072","0","4"]],"bids":[],"ts":"1626995774797","checksum":-805664904}]}
1626995774.871897: {"arg":{"channel":"books-l2-tbt","instId":"TRX-USDT-210924"},"action":"update","data":[{"asks":[["0.0546","101","0","2"],["0.05461","280","0","4"],["0.05463","132","0","2"]],"bids":[["0.05414","378","0","1"],["0.05406","387","0","1"]],"ts":"1626995774823","checksum":1482796587}]}
1626995774.881165: {"arg":{"channel":"trades","instId":"ONT-USDT"},"data":[{"instId":"ONT-USDT","tradeId":"11366800","px":"0.6219","sz":"129.312412","side":"sell","ts":"1626995774830"}]}
1626995774.8917189: {"arg":{"channel":"books-l2-tbt","instId":"XMR-USDT-SWAP"},"action":"update","data":[{"asks":[["196.43","7","0","1"]],"bids":[],"ts":"1626995774845","checksum":-173253125}]}
1626995774.896924: {"arg":{"channel":"books-l2-tbt","instId":"ONT-USDT"},"action":"update","data":[{"asks":[["0.622","351.838861","0","1"],["1.1196","0","0","0"]],"bids":[["0.6207","590","0","1"]],"ts":"1626995774851","checksum":-383181654}]}
1626995774.908416: {"arg":{"channel":"books-l2-tbt","instId":"ONT-USDT"},"action":"update","data":[{"asks":[],"bids":[["0.6217","320","0","1"]],"ts":"1626995774862","checksum":-1320090957}]}
1626995774.911734: {"arg":{"channel":"books-l2-tbt","instId":"XMR-USDT-SWAP"},"action":"update","data":[{"asks":[["196.43","593","0","2"]],"bids":[],"ts":"1626995774865","checksum":-907017916}]}
1626995774.9420118: {"arg":{"channel":"books-l2-tbt","instId":"TRX-USDT-210924"},"action":"update","data":[{"asks":[["0.05463","1","0","1"]],"bids":[["0.05414","0","0","0"],["0.05406","0","0","0"]],"ts":"1626995774895","checksum":-809772801}]}
1626995774.951585: {"arg":{"channel":"books-l2-tbt","instId":"ONT-USDT"},"action":"update","data":[{"asks":[],"bids":[["0.6215","320","0","1"]],"ts":"1626995774906","checksum":693932975}]}
1626995774.961962: {"arg":{"channel":"books-l2-tbt","instId":"OKT-BTC"},"action":"update","data":[{"asks":[],"bids":[["0.00145","2.47","0","1"]],"ts":"1626995774915","checksum":1887734633}]}
1626995774.9795158: {"arg":{"channel":"tickers","instId":"ONT-USDT"},"data":[{"instType":"SPOT","instId":"ONT-USDT","last":"0.6219","lastSz":"129.312412","askPx":"0.6221","askSz":"2752.353814","bidPx":"0.6217","bidSz":"640","open24h":"0.6075","high24h":"0.6314","low24h":"0.5967","sodUtc0":"0.6131","sodUtc8":"0.6275","volCcy24h":"9394743.796983","vol24h":"15284031.73951","ts":"1626995774923"}]}
1626995775.006193: {"arg":{"channel":"books-l2-tbt","instId":"TRX-USDT-210924"},"action":"update","data":[{"asks":[],"bids":[["0.0543","299","0","2"],["0.05409","387","0","1"]],"ts":"1626995774956","checksum":804154053}]}
1626995775.014372: {"arg":{"channel":"books-l2-tbt","instId":"DHT-USDT"},"action":"update","data":[{"asks":[["0.795","423.1407","0","1"]],"bids":[],"ts":"1626995774967","checksum":148653133}]}
1626995775.014472: {"arg":{"channel":"books-l2-tbt","instId":"TRX-USDT-210924"},"action":"update","data":[{"asks":[["0.05463","132","0","2"]],"bids":[["0.05443","0","0","0"]],"ts":"1626995774967","checksum":-671316167}]}
1626995775.025874: {"arg":{"channel":"books-l2-tbt","instId":"TRX-USDT-210924"},"action":"update","data":[{"asks":[],"bids":[["0.05441","105","0","2"],["0.05438","59","0","1"]],"ts":"1626995774977","checksum":-313972425}]}
1626995775.02603: {"arg":{"channel":"books-l2-tbt","instId":"ONT-USDT"},"action":"update","data":[{"asks":[],"bids":[["0.6218","0","0","0"]],"ts":"1626995774978","checksum":-597060753}]}
1626995775.0662348: {"arg":{"channel":"books-l2-tbt","instId":"TRX-USDT-210924"},"action":"update","data":[{"asks":[["0.05587","3","0","1"],["0.05588","0","0","0"]],"bids":[],"ts":"1626995775019","checksum":-313972425}]}
1626995775.076684: {"arg":{"channel":"books-l2-tbt","instId":"XMR-USDT-SWAP"},"action":"update","data":[{"asks":[["196.41","71","0","3"]],"bids":[],"ts":"1626995775029","checksum":-741198047}]}
1626995775.0768142: {"arg":{"channel":"books-l2-tbt","instId":"TRX-USDT-210924"},"action":"update","data":[{"asks":[],"bids":[["0.0543","42","0","1"],["0.05409","0","0","0"]],"ts":"1626995775030","checksum":221294303}]}
1626995775.087569: {"arg":{"channel":"books-l2-tbt","instId":"ONT-USDT"},"action":"update","data":[{"asks":[],"bids":[["0.6217","0","0","0"],["0.6215","640","0","2"]],"ts":"1626995775041","checksum":-1052340187}]}
1626995775.09896: {"arg":{"channel":"books-l2-tbt","instId":"XMR-USDT-SWAP"},"action":"update","data":[{"asks":[["196.27","250","0","1"],["196.31","484","0","5"]],"bids":[],"ts":"1626995775051","checksum":1106130078}]}
1626995775.106883: {"arg":{"channel":"books-l2-tbt","instId":"ONT-USDT"},"action":"update","data":[{"asks":[["0.6222","945.539","0","1"]],"bids":[],"ts":"1626995775060","checksum":-273241575}]}
1626995775.1191869: {"arg":{"channel":"books-l2-tbt","instId":"XMR-USDT-SWAP"},"action":"update","data":[{"asks":[["196.27","284","0","2"],["196.56","0","0","0"]],"bids":[],"ts":"1626995775072","checksum":2040530855}]}
1626995775.125588: {"arg":{"channel":"books-l2-tbt","instId":"TRX-USDT-210924"},"action":"update","data":[{"asks":[["0.05587","0","0","0"],["0.05588","3","0","1"]],"bids":[],"ts":"1626995775079","checksum":221294303}]}
1626995775.131131: {"arg":{"channel":"books-l2-tbt","instId":"ONT-USDT"},"action":"update","data":[{"asks":[["0.622","436.838861","0","2"]],"bids":[],"ts":"1626995775085","checksum":-768166849}]}
1626995775.1380758: {"arg":{"channel":"books-l2-tbt","instId":"TRX-USDT-210924"},"action":"update","data":[{"asks":[],"bids":[["0.05414","378","0","1"],["0.05406","387","0","1"]],"ts":"1626995775091","checksum":-889802679}]}
1626995775.158967: {"arg":{"channel":"books-l2-tbt","instId":"ONT-USDT"},"action":"update","data":[{"asks":[["0.6228","2.196878","0","1"]],"bids":[],"ts":"1626995775111","checksum":1451444192}]}
1626995775.1590989: {"arg":{"channel":"books-l2-tbt","instId":"XMR-USDT-SWAP"},"action":"update","data":[{"asks":[["196.42","8","0","2"]],"bids":[],"ts":"1626995775111","checksum":-44942488}]}
1626995775.168354: {"arg":{"channel":"books-l2-tbt","instId":"ONT-USDT"},"action":"update","data":[{"asks":[["0.6226","1394.009251","0","3"]],"bids":[],"ts":"1626995775121","checksum":1175630869}]}
1626995775.198116: {"arg":{"channel":"books-l2-tbt","instId":"XMR-USDT-SWAP"},"action":"update","data":[{"asks":[["196.26","171","0","1"]],"bids":[],"ts":"1626995775151","checksum":947948087}]}
1626995775.201917: {"arg":{"channel":"books-l2-tbt","instId":"OKT-BTC"},"action":"update","data":[{"asks":[],"bids":[["0.001409","0","0","0"]],"ts":"1626995775155","checksum":-1354309381}]}
1626995775.213111: {"arg":{"channel":"books-l2-tbt","instId":"ONT-USDT"},"action":"update","data":[{"asks":[["0.6222","1050.700226","0","2"],["0.6223","0","0","0"],["1.1196","19.988","0","1"]],"bids":[],"ts":"1626995775165","checksum":-870901897}]}
1626995775.252469: {"arg":{"channel":"books-l2-tbt","instId":"ONT-USDT"},"action":"update","data":[{"asks":[],"bids":[["0.617","1408.602182","0","1"]],"ts":"1626995775206","checksum":335058979}]}
1626995775.281347: {"arg":{"channel":"books-l2-tbt","instId":"ONT-USDT"},"action":"update","data":[{"asks":[],"bids":[["0.6215","960","0","3"]],"ts":"1626995775235","checksum":1069752057}]}
1626995775.306624: {"arg":{"channel":"books-l2-tbt","instId":"TRX-USDT-210924"},"action":"update","data":[{"asks":[["0.05452","8","0","1"]],"bids":[],"ts":"1626995775256","checksum":-1153884843}]}
1626995775.30672: {"arg":{"channel":"books-l2-tbt","instId":"OKT-BTC"},"action":"update","data":[{"asks":[],"bids":[["0.001459","2.47","0","1"]],"ts":"1626995775258","checksum":-6650883}]}
1626995775.310752: {"arg":{"channel":"books-l2-tbt","instId":"TRX-USDT-210924"},"action":"update","data":[{"asks":[["0.0545","16","0","2"]],"bids":[],"ts":"1626995775265","checksum":1379193509}]}
1626995775.3261461: {"arg":{"channel":"books-l2-tbt","instId":"TRX-USDT-210924"},"action":"update","data":[{"asks":[["0.05558","907","0","1"],["0.05561","0","0","0"]],"bids":[],"ts":"1626995775278","checksum":1379193509}]}
1626995775.333645: {"arg":{"channel":"books-l2-tbt","instId":"TRX-USDT-210924"},"action":"update","data":[{"asks":[["0.05548","197","0","1"],["0.05551","0","0","0"],["0.05564","899","0","1"],["0.05567","0","0","0"],["0.05569","902","0","1"],["0.05572","0","0","0"],["0.05575","905","0","1"],["0.05578","0","0","0"],["0.0558","1040","0","2"],["0.05583","0","0","0"]],"bids":[],"ts":"1626995775286","checksum":1379193509}]}
1626995775.336446: {"arg":{"channel":"books-l2-tbt","instId":"OKT-BTC"},"action":"update","data":[{"asks":[],"bids":[["0.001458","0","0","0"]],"ts":"1626995775289","checksum":625608377}]}
1626995775.353958: {"arg":{"channel":"books-l2-tbt","instId":"OKT-BTC"},"action":"update","data":[{"asks":[],"bids":[["0.00146","1.27980441","0","1"]],"ts":"1626995775307","checksum":1418439334}]}
1626995775.381239: {"arg":{"channel":"books-l2-tbt","instId":"XMR-USDT-SWAP"},"action":"update","data":[{"asks":[["196.54","0","0","0"],["196.56","69","0","1"],["196.66","0","0","0"],["196.84","233","0","1"],["197.27","0","0","0"],["197.29","233","0","1"],["197.87","0","0","0"],["197.89","233","0","1"]],"bids":[["195.62","81","0","2"],["195.6","6","0","1"],["194.86","233","0","1"],["194.84","0","0","0"],["194.22","233","0","1"],["194.2","0","0","0"]],"ts":"1626995775334","checksum":1736016479}]}
1626995775.3857322: {"arg":{"channel":"books-l2-tbt","instId":"ONT-USDT"},"action":"update","data":[{"asks":[],"bids":[["0.6215","640","0","2"]],"ts":"1626995775339","checksum":335058979}]}
1626995775.393234: {"arg":{"channel":"books-l2-tbt","instId":"TRX-USDT-210924"},"action":"update","data":[{"asks":[["0.05458","27","0","2"],["0.0546","81","0","1"],["0.05472","81","0","1"],["0.05476","0","0","0"]],"bids":[],"ts":"1626995775347","checksum":-1645985039}]}
1626995775.43378: {"arg":{"channel":"trades","instId":"PAY-BTC"},"data":[{"instId":"PAY-BTC","tradeId":"6071316","px":"0.00000138","sz":"4015.326","side":"sell","ts":"1626995775384"}]}
1626995775.4412968: {"arg":{"channel":"books-l2-tbt","instId":"OKT-BTC"},"action":"update","data":[{"asks":[],"bids":[["0.001451","6.86725706","0","1"]],"ts":"1626995775394","checksum":-1118725674}]}
1626995775.44665: {"arg":{"channel":"books-l2-tbt","instId":"ONT-USDT"},"action":"update","data":[{"asks":[],"bids":[["0.6216","371","0","2"]],"ts":"1626995775400","checksum":-1256496946}]}
1626995775.4776928: {"arg":{"channel":"books-l2-tbt","instId":"ONT-USDT"},"action":"update","data":[{"asks":[],"bids":[["0.6216","691","0","3"]],"ts":"1626995775431","checksum":1867490067}]}
1626995775.520282: {"arg":{"channel":"books-l2-tbt","instId":"FUN-BTC"},"action":"update","data":[{"asks":[],"bids":[["0.000000413","0","0","0"]],"ts":"1626995775474","checksum":645519708}]}
1626995775.528123: {"arg":{"channel":"tickers","instId":"PAY-BTC"},"data":[{"instType":"SPOT","instId":"PAY-BTC","last":"0.00000138","lastSz":"4015.326","askPx":"0.00000139","askSz":"4702.072","bidPx":"0.00000136","bidSz":"4282.772","open24h":"0.00000136","high24h":"0.00000144","low24h":"0.00000136","sodUtc0":"0.00000138","sodUtc8":"0.00000138","volCcy24h":"45.118","vol24h":"32764302.165","ts":"1626995775468"}]}
1626995775.559695: {"arg":{"channel":"books-l2-tbt","instId":"ONT-USDT"},"action":"update","data":[{"asks":[],"bids":[["0.6215","320","0","1"]],"ts":"1626995775513","checksum":-693100732}]}
1626995775.5695128: {"arg":{"channel":"books-l2-tbt","instId":"ONT-USDT"},"action":"update","data":[{"asks":[],"bids":[["0.6215","0","0","0"]],"ts":"1626995775523","checksum":220721679}]}
1626995775.5905159: {"arg":{"channel":"books-l2-tbt","instId":"ONT-USDT"},"action":"update","data":[{"asks":[],"bids":[["0.6216","1011","0","4"]],"ts":"1626995775544","checksum":1581922440}]}
1626995775.601986: {"arg":{"channel":"books-l2-tbt","instId":"ONT-USDT"},"action":"update","data":[{"asks":[],"bids":[["0.6216","1331","0","5"]],"ts":"1626995775554","checksum":-1716514484}]}
1626995775.633728: {"arg":{"channel":"books-l2-tbt","instId":"OKT-BTC"},"action":"update","data":[{"asks":[["0.001476","0","0","0"]],"bids":[],"ts":"1626995775587","checksum":1789136534}]}
1626995775.650917: {"arg":{"channel":"books-l2-tbt","instId":"XMR-USDT-SWAP"},"action":"update","data":[{"asks":[["196.43","556","0","2"]],"bids":[],"ts":"1626995775604","checksum":1967446870}]}
1626995775.663776: {"arg":{"channel":"books-l2-tbt","instId":"ONT-USDT"},"action":"update","data":[{"asks":[],"bids":[["0.6215","320","0","1"]],"ts":"1626995775617","checksum":-557957393}]}
1626995775.6902988: {"arg":{"channel":"books-l2-tbt","instId":"OKT-BTC"},"action":"update","data":[{"asks":[["0.001477","0.36773856","0","1"]],"bids":[],"ts":"1626995775643","checksum":-111550181}]}
1626995775.700001: {"arg":{"channel":"books-l2-tbt","instId":"ONT-USDT"},"action":"update","data":[{"asks":[],"bids":[["0.6213","0","0","0"]],"ts":"1626995775652","checksum":-28762952}]}
1626995775.730633: {"arg":{"channel":"books-l2-tbt","instId":"ONT-USDT"},"action":"update","data":[{"asks":[],"bids":[["0.6216","1011","0","4"]],"ts":"1626995775683","checksum":-1384562847}]}
1626995775.762181: {"arg":{"channel":"books-l2-tbt","instId":"ONT-USDT"},"action":"update","data":[{"asks":[],"bids":[["0.6216","691","0","3"],["0.6214","996.539","0","2"],["0.6209","105.161226","0","1"]],"ts":"1626995775713","checksum":-96779094}]}
1626995775.769571: {"arg":{"channel":"books-l2-tbt","instId":"ONT-USDT"},"action":"update","data":[{"asks":[],"bids":[["0.6165","0","0","0"]],"ts":"1626995775723","checksum":-96779094}]}
1626995775.793322: {"arg":{"channel":"books-l2-tbt","instId":"FUN-BTC"},"action":"update","data":[{"asks":[],"bids":[["0.000000404","6859.95","0","1"]],"ts":"1626995775746","checksum":595823907}]}
1626995775.8640032: {"arg":{"channel":"books-l2-tbt","instId":"ONT-USDT"},"action":"update","data":[{"asks":[],"bids":[["0.6216","371","0","2"]],"ts":"1626995775816","checksum":-1684853854}]}
1626995775.88673: {"arg":{"channel":"books-l2-tbt","instId":"ONT-USDT"},"action":"update","data":[{"asks":[],"bids":[["0.6216","51","0","1"]],"ts":"1626995775836","checksum":399010031}]}
1626995775.892585: {"arg":{"channel":"books-l2-tbt","instId":"XMR-USDT-SWAP"},"action":"update","data":[{"asks":[],"bids":[["195.27","9","0","1"]],"ts":"1626995775847","checksum":1967446870}]}
1626995775.901171: {"arg":{"channel":"books-l2-tbt","instId":"ONT-USDT"},"action":"update","data":[{"asks":[["0.6221","3697.892814","0","2"],["0.6222","105.161226","0","1"]],"bids":[],"ts":"1626995775855","checksum":2087415057}]}
1626995775.932162: {"arg":{"channel":"books-l2-tbt","instId":"ONT-USDT"},"action":"update","data":[{"asks":[],"bids":[["0.6215","0","0","0"],["0.621","640","0","2"]],"ts":"1626995775886","checksum":-1407204153}]}
1626995775.9438632: {"arg":{"channel":"books-l2-tbt","instId":"ONT-USDT"},"action":"update","data":[{"asks":[],"bids":[["0.621","960","0","3"]],"ts":"1626995775897","checksum":-2020682162}]}
1626995775.953048: {"arg":{"channel":"books-l2-tbt","instId":"ONT-USDT"},"action":"update","data":[{"asks":[],"bids":[["0.6216","0","0","0"]],"ts":"1626995775906","checksum":-812825494}]}
1626995775.962738: {"arg":{"channel":"books-l2-tbt","instId":"DHT-USDT"},"action":"update","data":[{"asks":[["0.795","0","0","0"]],"bids":[],"ts":"1626995775915","checksum":-765422627}]}
1626995775.983705: {"arg":{"channel":"books-l2-tbt","instId":"ONT-USDT"},"action":"update","data":[{"asks":[["0.6221","3803.05404","0","3"],["0.6222","0","0","0"],["0.6245","0","0","0"],["1.1224","10.5","0","1"],["1.1269","240","0","1"]],"bids":[["0.6211","105.161226","0","1"],["0.6209","0","0","0"]],"ts":"1626995775937","checksum":801868580}]}
1626995775.996576: {"arg":{"channel":"books-l2-tbt","instId":"XMR-USDT-SWAP"},"action":"update","data":[{"asks":[["197.86","519","0","5"]],"bids":[],"ts":"1626995775950","checksum":1967446870}]}
1626995776.01358: {"arg":{"channel":"books-l2-tbt","instId":"DHT-USDT"},"action":"update","data":[{"asks":[["0.794","40","0","1"]],"bids":[],"ts":"1626995775966","checksum":-564066120}]}
1626995776.026749: {"arg":{"channel":"books-l2-tbt","instId":"ONT-USDT"},"action":"update","data":[{"asks":[["0.6226","993.334745","0","2"]],"bids":[],"ts":"1626995775980","checksum":-894278643}]}
1626995776.036433: {"arg":{"channel":"books-l2-tbt","instId":"ONT-USDT"},"action":"update","data":[{"asks":[["0.6221","1050.700226","0","2"],["0.6224","1020.674506","0","2"]],"bids":[],"ts":"1626995775990","checksum":-1797941019}]}
1626995776.067505: {"arg":{"channel":"books-l2-tbt","instId":"ONT-USDT"},"action":"update","data":[{"asks":[["0.6222","603.334745","0","1"],["0.6226","390","0","1"],["1.1269","0","0","0"]],"bids":[],"ts":"1626995776020","checksum":-1166775122}]}
1626995776.0968902: {"arg":{"channel":"books-l2-tbt","instId":"ONT-USDT"},"action":"update","data":[{"asks":[["0.6244","6080.078495","0","1"],["1.1224","0","0","0"]],"bids":[],"ts":"1626995776051","checksum":-1876356213}]}
1626995776.104372: {"arg":{"channel":"trades","instId":"FUN-BTC"},"data":[{"instId":"FUN-BTC","tradeId":"3435659","px":"0.000000453","sz":"13.76","side":"buy","ts":"1626995776055"}]}
1626995776.1055748: {"arg":{"channel":"books-l2-tbt","instId":"ONT-USDT"},"action":"update","data":[{"asks":[],"bids":[["0.6211","745.161226","0","3"]],"ts":"1626995776059","checksum":191304329}]}
1626995776.1214778: {"arg":{"channel":"books-l2-tbt","instId":"XMR-USDT-SWAP"},"action":"update","data":[{"asks":[["196.31","298","0","4"],["196.32","77","0","2"],["196.43","553","0","2"]],"bids":[["195.26","94","0","4"]],"ts":"1626995776075","checksum":201185397}]}
1626995776.1428852: {"arg":{"channel":"books-l2-tbt","instId":"XMR-USDT-SWAP"},"action":"update","data":[{"asks":[["196.26","357","0","2"]],"bids":[["195.28","142","0","1"]],"ts":"1626995776096","checksum":430490847}]}
1626995776.149323: {"arg":{"channel":"books-l2-tbt","instId":"AUCTION-USDT"},"action":"update","data":[{"asks":[],"bids":[["14.29","0","0","0"]],"ts":"1626995776102","checksum":1416180795}]}
1626995776.167163: {"arg":{"channel":"books-l2-tbt","instId":"ONT-USDT"},"action":"update","data":[{"asks":[],"bids":[["0.621","640","0","2"]],"ts":"1626995776120","checksum":1770790103}]}
1626995776.177817: {"arg":{"channel":"books-l2-tbt","instId":"ONT-USDT"},"action":"update","data":[{"asks":[],"bids":[["0.621","320","0","1"]],"ts":"1626995776131","checksum":490563209}]}
1626995776.18717: {"arg":{"channel":"books-l2-tbt","instId":"ONT-USDT"},"action":"update","data":[{"asks":[],"bids":[["0.6214","1916.121509","0","3"],["0.621","0","0","0"]],"ts":"1626995776141","checksum":953252420}]}
1626995776.2032309: {"arg":{"channel":"books-l2-tbt","instId":"XMR-USDT-SWAP"},"action":"update","data":[{"asks":[["197.54","7","0","1"]],"bids":[],"ts":"1626995776156","checksum":430490847}]}
1626995776.2071512: {"arg":{"channel":"books-l2-tbt","instId":"ONT-USDT"},"action":"update","data":[{"asks":[],"bids":[["0.6212","105.234414","0","1"],["0.6211","640","0","2"],["0.5899","0","0","0"]],"ts":"1626995776162","checksum":124713354}]}
1626995776.226762: {"arg":{"channel":"books-l2-tbt","instId":"DHT-USDT"},"action":"update","data":[{"asks":[["0.793","423.1407","0","1"]],"bids":[],"ts":"1626995776180","checksum":-1239610714}]}
1626995776.22897: {"arg":{"channel":"books-l2-tbt","instId":"ONT-USDT"},"action":"update","data":[{"asks":[],"bids":[["0.6209","320","0","1"]],"ts":"1626995776182","checksum":-1411670632}]}
1626995776.234702: {"arg":{"channel":"books-l2-tbt","instId":"TRX-USDT-210924"},"action":"update","data":[{"asks":[],"bids":[["0.05422","4","0","2"],["0.05421","0","0","0"]],"ts":"1626995776187","checksum":-898691207}]}
1626995776.2403681: {"arg":{"channel":"tickers","instId":"FUN-BTC"},"data":[{"instType":"SPOT","instId":"FUN-BTC","last":"0.000000453","lastSz":"13.76","askPx":"0.000000454","askSz":"130606.89","bidPx":"0.00000045","bidSz":"21957.39","open24h":"0.000000444","high24h":"0.000000467","low24h":"0.000000443","sodUtc0":"0.000000446","sodUtc8":"0.000000449","volCcy24h":"0.13","vol24h":"302357.26","ts":"1626995776188"}]}
1626995776.2633758: {"arg":{"channel":"books-l2-tbt","instId":"TRX-USDT-210924"},"action":"update","data":[{"asks":[["0.05461","189","0","3"]],"bids":[],"ts":"1626995776216","checksum":-140873960}]}
1626995776.2693: {"arg":{"channel":"books-l2-tbt","instId":"ONT-USDT"},"action":"update","data":[{"asks":[["0.6221","105.161226","0","1"],["0.6222","1548.873745","0","2"]],"bids":[],"ts":"1626995776223","checksum":-2084631049}]}
1626995776.28202: {"arg":{"channel":"books-l2-tbt","instId":"ONT-USDT"},"action":"update","data":[{"asks":[],"bids":[["0.5897","294.795658","0","1"]],"ts":"1626995776236","checksum":-2084631049}]}
1626995776.324584: {"arg":{"channel":"books-l2-tbt","instId":"TRX-USDT-210924"},"action":"update","data":[{"asks":[["0.05464","295","0","2"]],"bids":[],"ts":"1626995776277","checksum":878399965}]}
1626995776.346336: {"arg":{"channel":"books-l2-tbt","instId":"TRX-USDT-210924"},"action":"update","data":[{"asks":[],"bids":[["0.05422","1","0","1"],["0.05421","3","0","1"]],"ts":"1626995776298","checksum":232768763}]}
1626995776.3518069: {"arg":{"channel":"books-l2-tbt","instId":"ONT-USDT"},"action":"update","data":[{"asks":[],"bids":[["0.6211","320","0","1"]],"ts":"1626995776306","checksum":391614910}]}
1626995776.360554: {"arg":{"channel":"books-l2-tbt","instId":"ONT-USDT"},"action":"update","data":[{"asks":[],"bids":[["0.6211","0","0","0"]],"ts":"1626995776315","checksum":-1670136703}]}
1626995776.4029691: {"arg":{"channel":"books-l2-tbt","instId":"ONT-USDT"},"action":"update","data":[{"asks":[],"bids":[["0.6212","425.234414","0","2"]],"ts":"1626995776356","checksum":1705055027}]}
1626995776.405547: {"arg":{"channel":"books-l2-tbt","instId":"AUCTION-USDT"},"action":"update","data":[{"asks":[],"bids":[["14.26","151.541099","0","1"]],"ts":"1626995776359","checksum":-1595672917}]}
1626995776.414413: {"arg":{"channel":"books-l2-tbt","instId":"ONT-USDT"},"action":"update","data":[{"asks":[],"bids":[["0.6212","745.234414","0","3"]],"ts":"1626995776367","checksum":1927713708}]}
1626995776.430903: {"arg":{"channel":"books-l2-tbt","instId":"XMR-USDT-SWAP"},"action":"update","data":[{"asks":[["196.67","233","0","1"],["196.84","0","0","0"],["197.28","233","0","1"],["197.29","0","0","0"],["197.88","233","0","1"],["197.89","0","0","0"]],"bids":[["196","3","0","1"],["195.62","12","0","1"],["195.61","69","0","1"],["194.86","0","0","0"],["194.85","256","0","2"],["194.22","0","0","0"],["194.21","233","0","1"]],"ts":"1626995776383","checksum":-81385477}]}
1626995776.445882: {"arg":{"channel":"books-l2-tbt","instId":"TRX-USDT-210924"},"action":"update","data":[{"asks":[["0.05463","1","0","1"]],"bids":[],"ts":"1626995776399","checksum":433520292}]}
1626995776.451523: {"arg":{"channel":"books-l2-tbt","instId":"XMR-USDT-SWAP"},"action":"update","data":[{"asks":[["196.4","35","0","1"]],"bids":[["195.96","159","0","3"]],"ts":"1626995776405","checksum":-580894024}]}
1626995776.4727669: {"arg":{"channel":"books-l2-tbt","instId":"XMR-USDT-SWAP"},"action":"update","data":[{"asks":[["196.41","37","0","2"]],"bids":[],"ts":"1626995776425","checksum":169278993}]}
1626995776.476128: {"arg":{"channel":"books-l2-tbt","instId":"ONT-USDT"},"action":"update","data":[{"asks":[["0.6261","129","0","2"]],"bids":[],"ts":"1626995776429","checksum":-998775739}]}
1626995776.484753: {"arg":{"channel":"books-l2-tbt","instId":"ONT-USDT"},"action":"update","data":[{"asks":[],"bids":[["0.6213","320","0","1"]],"ts":"1626995776439","checksum":-1341738293}]}
1626995776.494376: {"arg":{"channel":"books-l2-tbt","instId":"XMR-USDT-SWAP"},"action":"update","data":[{"asks":[["196.43","535","0","2"]],"bids":[],"ts":"1626995776445","checksum":-427265667}]}
1626995776.4960902: {"arg":{"channel":"books-l2-tbt","instId":"ONT-USDT"},"action":"update","data":[{"asks":[],"bids":[["0.6213","640","0","2"],["0.6209","0","0","0"]],"ts":"1626995776450","checksum":263126289}]}
1626995776.504284: {"arg":{"channel":"books-l2-tbt","instId":"TRX-USDT-210924"},"action":"update","data":[{"asks":[["0.05464","432","0","3"]],"bids":[],"ts":"1626995776458","checksum":-1522219507}]}
1626995776.52955: {"arg":{"channel":"books-l2-tbt","instId":"ONT-USDT"},"action":"update","data":[{"asks":[],"bids":[["0.6213","960","0","3"]],"ts":"1626995776481","checksum":590074104}]}
1626995776.547127: {"arg":{"channel":"books-l2-tbt","instId":"ONT-USDT"},"action":"update","data":[{"asks":[],"bids":[["0.6213","1280","0","4"]],"ts":"1626995776501","checksum":-187911041}]}
1626995776.561441: {"arg":{"channel":"books-l2-tbt","instId":"FUN-BTC"},"action":"update","data":[{"asks":[],"bids":[],"ts":"1626995776515","checksum":595823907}]}
1626995776.5694919: {"arg":{"channel":"books-l2-tbt","instId":"ONT-USDT"},"action":"update","data":[{"asks":[],"bids":[["0.6215","2682.238788","0","1"]],"ts":"1626995776522","checksum":1131044971}]}
1626995776.590452: {"arg":{"channel":"books-l2-tbt","instId":"ONT-USDT"},"action":"update","data":[{"asks":[["0.6224","620","0","1"]],"bids":[],"ts":"1626995776543","checksum":-661922332}]}
1626995776.598475: {"arg":{"channel":"books-l2-tbt","instId":"ONT-USDT"},"action":"update","data":[{"asks":[["0.6228","402.871384","0","2"]],"bids":[],"ts":"1626995776551","checksum":-1642979937}]}
1626995776.651333: {"arg":{"channel":"books-l2-tbt","instId":"ONT-USDT"},"action":"update","data":[{"asks":[],"bids":[["0.6213","1385.234414","0","5"],["0.6212","640","0","2"]],"ts":"1626995776605","checksum":-287668408}]}
1626995776.6636102: {"arg":{"channel":"books-l2-tbt","instId":"ONT-USDT"},"action":"update","data":[{"asks":[],"bids":[["0.6212","320","0","1"]],"ts":"1626995776615","checksum":929943269}]}
1626995776.671194: {"arg":{"channel":"books-l2-tbt","instId":"ONT-USDT"},"action":"update","data":[{"asks":[],"bids":[["0.6212","0","0","0"]],"ts":"1626995776625","checksum":638966872}]}
1626995776.733173: {"arg":{"channel":"books-l2-tbt","instId":"ONT-USDT"},"action":"update","data":[{"asks":[],"bids":[["0.6215","3002.238788","0","2"]],"ts":"1626995776685","checksum":-213953095}]}
1626995776.753335: {"arg":{"channel":"books-l2-tbt","instId":"ONT-USDT"},"action":"update","data":[{"asks":[],"bids":[["0.6213","745.234414","0","3"]],"ts":"1626995776706","checksum":1644418001}]}
1626995776.764076: {"arg":{"channel":"books-l2-tbt","instId":"XMR-USDT-SWAP"},"action":"update","data":[{"asks":[["196.27","250","0","1"]],"bids":[],"ts":"1626995776718","checksum":-1948096646}]}
1626995776.8050072: {"arg":{"channel":"books-l2-tbt","instId":"ONT-USDT"},"action":"update","data":[{"asks":[],"bids":[["0.6216","320","0","1"],["0.6213","105.234414","0","1"]],"ts":"1626995776757","checksum":-613797699}]}
1626995776.837169: {"arg":{"channel":"books-l2-tbt","instId":"ONT-USDT"},"action":"update","data":[{"asks":[],"bids":[["0.6216","640","0","2"]],"ts":"1626995776789","checksum":-1381588089}]}
1626995776.846878: {"arg":{"channel":"books-l2-tbt","instId":"ONT-USDT"},"action":"update","data":[{"asks":[],"bids":[["0.6216","960","0","3"]],"ts":"1626995776800","checksum":-596968946}]}
1626995776.857053: {"arg":{"channel":"books-l2-tbt","instId":"ONT-USDT"},"action":"update","data":[{"asks":[["0.6224","0","0","0"],["1.1224","10.5","0","1"]],"bids":[],"ts":"1626995776808","checksum":-1569928698}]}
1626995776.8655622: {"arg":{"channel":"books-l2-tbt","instId":"ONT-USDT"},"action":"update","data":[{"asks":[["0.6225","105.234414","0","1"],["1.1224","0","0","0"]],"bids":[["0.6209","105.234414","0","1"]],"ts":"1626995776819","checksum":1743612218}]}
1626995776.875655: {"arg":{"channel":"books-l2-tbt","instId":"ONT-USDT"},"action":"update","data":[{"asks":[["0.6221","0","0","0"],["1.1224","10.5","0","1"]],"bids":[["0.6216","1280","0","4"],["0.6213","0","0","0"]],"ts":"1626995776828","checksum":-52188744}]}
1626995776.8977711: {"arg":{"channel":"books-l2-tbt","instId":"ONT-USDT"},"action":"update","data":[{"asks":[],"bids":[["0.6216","1331","0","5"]],"ts":"1626995776851","checksum":1316709449}]}
1626995776.9202292: {"arg":{"channel":"books-l2-tbt","instId":"ONT-USDT"},"action":"update","data":[{"asks":[],"bids":[["0.6215","320","0","1"]],"ts":"1626995776872","checksum":-1211220658}]}
1626995776.925689: {"arg":{"channel":"books-l2-tbt","instId":"ONT-USDT"},"action":"update","data":[{"asks":[],"bids":[["0.6215","640","0","2"]],"ts":"1626995776879","checksum":-2006640161}]}
1626995776.931594: {"arg":{"channel":"books-l2-tbt","instId":"XMR-USDT-SWAP"},"action":"update","data":[{"asks":[["196.43","530","0","2"]],"bids":[],"ts":"1626995776884","checksum":-360282331}]}
1626995776.9881432: {"arg":{"channel":"books-l2-tbt","instId":"ONT-USDT"},"action":"update","data":[{"asks":[["0.623","820","0","1"],["0.6233","486.341898","0","1"],["1.1224","0","0","0"]],"bids":[],"ts":"1626995776942","checksum":-587398896}]}
1626995776.998108: {"arg":{"channel":"books-l2-tbt","instId":"ONT-USDT"},"action":"update","data":[{"asks":[],"bids":[["0.6215","320","0","1"]],"ts":"1626995776950","checksum":-1025552970}]}
1626995777.002611: {"arg":{"channel":"books-l2-tbt","instId":"PAY-BTC"},"action":"update","data":[{"asks":[],"bids":[],"ts":"1626995776956","checksum":-805664904}]}
1626995777.0391219: {"arg":{"channel":"books-l2-tbt","instId":"ONT-USDT"},"action":"update","data":[{"asks":[],"bids":[["0.6216","1651","0","6"]],"ts":"1626995776992","checksum":-1357227101}]}
1626995777.049938: {"arg":{"channel":"books-l2-tbt","instId":"ONT-USDT"},"action":"update","data":[{"asks":[],"bids":[["0.6216","1331","0","5"]],"ts":"1626995777003","checksum":-1025552970}]}
1626995777.068928: {"arg":{"channel":"books-l2-tbt","instId":"TRX-USDT-210924"},"action":"update","data":[{"asks":[],"bids":[["0.05422","4","0","2"],["0.05421","0","0","0"]],"ts":"1626995777021","checksum":-1733042607}]}
1626995777.069088: {"arg":{"channel":"books-l2-tbt","instId":"XMR-USDT-SWAP"},"action":"update","data":[{"asks":[["196.41","560","0","3"],["196.43","7","0","1"]],"bids":[],"ts":"1626995777022","checksum":-2041549814}]}
1626995777.089479: {"arg":{"channel":"books-l2-tbt","instId":"ONT-USDT"},"action":"update","data":[{"asks":[],"bids":[["0.6216","1011","0","4"]],"ts":"1626995777043","checksum":1353925242}]}
1626995777.1113532: {"arg":{"channel":"books-l2-tbt","instId":"ONT-USDT"},"action":"update","data":[{"asks":[],"bids":[["0.6217","320","0","1"]],"ts":"1626995777064","checksum":1636826112}]}
1626995777.117604: {"arg":{"channel":"books-l2-tbt","instId":"TRX-USDT-210924"},"action":"update","data":[{"asks":[["0.05588","0","0","0"],["0.05589","3","0","1"]],"bids":[],"ts":"1626995777072","checksum":-1733042607}]}
1626995777.1196969: {"arg":{"channel":"books-l2-tbt","instId":"ONT-USDT"},"action":"update","data":[{"asks":[],"bids":[["0.6216","691","0","3"]],"ts":"1626995777074","checksum":1305709555}]}
1626995777.132531: {"arg":{"channel":"books-l2-tbt","instId":"ONT-USDT"},"action":"update","data":[{"asks":[],"bids":[["0.6215","1265.539","0","2"],["0.6214","970.582509","0","2"]],"ts":"1626995777086","checksum":-1652873320}]}
1626995777.141089: {"arg":{"channel":"books-l2-tbt","instId":"ONT-USDT"},"action":"update","data":[{"asks":[],"bids":[["0.6216","371","0","2"]],"ts":"1626995777095","checksum":688271888}]}
1626995777.1924422: {"arg":{"channel":"books-l2-tbt","instId":"ONT-USDT"},"action":"update","data":[{"asks":[],"bids":[["0.6217","640","0","2"],["0.6215","945.539","0","1"]],"ts":"1626995777146","checksum":-261675877}]}
1626995777.202152: {"arg":{"channel":"books-l2-tbt","instId":"DHT-USDT"},"action":"update","data":[{"asks":[["0.793","0","0","0"]],"bids":[],"ts":"1626995777154","checksum":-564066120}]}
1626995777.2021902: {"arg":{"channel":"books-l2-tbt","instId":"ONT-USDT"},"action":"update","data":[{"asks":[],"bids":[["0.6217","960","0","3"],["0.6214","1078.17659","0","3"],["0.6209","0","0","0"]],"ts":"1626995777157","checksum":-831259086}]}
1626995777.274335: {"arg":{"channel":"books-l2-tbt","instId":"ONT-USDT"},"action":"update","data":[{"asks":[],"bids":[["0.6217","1280","0","4"]],"ts":"1626995777227","checksum":1568050055}]}
1626995777.274434: {"arg":{"channel":"books-l2-tbt","instId":"OKT-BTC"},"action":"update","data":[{"asks":[],"bids":[["0.00147","11.55283724","0","1"]],"ts":"1626995777228","checksum":580774899}]}
1626995777.284872: {"arg":{"channel":"books-l2-tbt","instId":"ONT-USDT"},"action":"update","data":[{"asks":[["0.6226","10769.181","0","2"]],"bids":[],"ts":"1626995777238","checksum":-793095269}]}
1626995777.305162: {"arg":{"channel":"books-l2-tbt","instId":"OKT-BTC"},"action":"update","data":[{"asks":[],"bids":[["0.001471","2.89090055","0","2"]],"ts":"1626995777258","checksum":-1810392486}]}
1626995777.323437: {"arg":{"channel":"books-l2-tbt","instId":"OKT-BTC"},"action":"update","data":[{"asks":[["0.001489","0","0","0"]],"bids":[],"ts":"1626995777278","checksum":148626349}]}
1626995777.33746: {"arg":{"channel":"books-l2-tbt","instId":"ONT-USDT"},"action":"update","data":[{"asks":[],"bids":[["0.6216","51","0","1"]],"ts":"1626995777289","checksum":-364685710}]}
1626995777.337492: {"arg":{"channel":"books-l2-tbt","instId":"OKT-BTC"},"action":"update","data":[{"asks":[["0.001488","0","0","0"]],"bids":[],"ts":"1626995777289","checksum":1834090431}]}
1626995777.3581598: {"arg":{"channel":"books-l2-tbt","instId":"OKT-BTC"},"action":"update","data":[{"asks":[["0.001476","11.54107264","0","1"],["0.001492","1.28239582","0","1"]],"bids":[],"ts":"1626995777310","checksum":-1175402729}]}
1626995777.368075: {"arg":{"channel":"books-l2-tbt","instId":"OKT-BTC"},"action":"update","data":[{"asks":[],"bids":[["0.001471","0.24901841","0","1"]],"ts":"1626995777322","checksum":259700414}]}
1626995777.3998: {"arg":{"channel":"books-l2-tbt","instId":"OKT-BTC"},"action":"update","data":[{"asks":[],"bids":[["0.001471","2.89090055","0","2"]],"ts":"1626995777352","checksum":-1175402729}]}
1626995777.409496: {"arg":{"channel":"books-l2-tbt","instId":"ONT-USDT"},"action":"update","data":[{"asks":[],"bids":[["0.6217","1600","0","5"]],"ts":"1626995777362","checksum":1898617374}]}
1626995777.4119759: {"arg":{"channel":"books-l2-tbt","instId":"AUCTION-USDT"},"action":"update","data":[{"asks":[],"bids":[["14.26","0","0","0"]],"ts":"1626995777365","checksum":1416180795}]}
1626995777.440851: {"arg":{"channel":"books-l2-tbt","instId":"ONT-USDT"},"action":"update","data":[{"asks":[],"bids":[["0.6218","320","0","1"],["0.6217","1280","0","4"]],"ts":"1626995777395","checksum":-1970796006}]}
1626995777.446131: {"arg":{"channel":"books-l2-tbt","instId":"TRX-USDT-210924"},"action":"update","data":[{"asks":[["0.05458","20","0","1"]],"bids":[],"ts":"1626995777399","checksum":405635864}]}
1626995777.4494212: {"arg":{"channel":"books-l2-tbt","instId":"DHT-USDT"},"action":"update","data":[{"asks":[["0.795","423.1407","0","1"]],"bids":[],"ts":"1626995777404","checksum":798497741}]}
1626995777.4653819: {"arg":{"channel":"books-l2-tbt","instId":"ONT-USDT"},"action":"update","data":[{"asks":[["0.6222","603.334745","0","1"],["0.6223","945.539","0","1"],["1.1196","0","0","0"]],"bids":[["0.6217","960","0","3"]],"ts":"1626995777415","checksum":1180850442}]}
1626995777.470696: {"arg":{"channel":"books-l2-tbt","instId":"ONT-USDT"},"action":"update","data":[{"asks":[["0.622","351.838861","0","1"]],"bids":[],"ts":"1626995777425","checksum":-781391512}]}
1626995777.4836621: {"arg":{"channel":"books-l2-tbt","instId":"ONT-USDT"},"action":"update","data":[{"asks":[["0.6229","2942.683796","0","2"],["0.6233","0","0","0"],["1.1196","19.988","0","1"]],"bids":[],"ts":"1626995777437","checksum":1101444623}]}
1626995777.502856: {"arg":{"channel":"books-l2-tbt","instId":"ONT-USDT"},"action":"update","data":[{"asks":[],"bids":[["0.6218","640","0","2"]],"ts":"1626995777456","checksum":664278050}]}
1626995777.536163: {"arg":{"channel":"books-l2-tbt","instId":"ONT-USDT"},"action":"update","data":[{"asks":[],"bids":[["0.6218","960","0","3"],["0.6215","1053.133081","0","2"],["0.6214","970.582509","0","2"]],"ts":"1626995777488","checksum":-1702615024}]}
1626995777.536315: {"arg":{"channel":"books-l2-tbt","instId":"FUN-BTC"},"action":"update","data":[{"asks":[],"bids":[["0.000000404","0","0","0"]],"ts":"1626995777489","checksum":645519708}]}
1626995777.5390232: {"arg":{"channel":"books-l2-tbt","instId":"TRX-USDT-210924"},"action":"update","data":[{"asks":[["0.0545","2","0","1"]],"bids":[],"ts":"1626995777492","checksum":-249541400}]}
1626995777.544194: {"arg":{"channel":"books-l2-tbt","instId":"ONT-USDT"},"action":"update","data":[{"asks":[],"bids":[["0.6217","640","0","2"]],"ts":"1626995777498","checksum":-2125468077}]}
1626995777.54639: {"arg":{"channel":"books-l2-tbt","instId":"TRX-USDT-210924"},"action":"update","data":[{"asks":[["0.05452","22","0","2"]],"bids":[],"ts":"1626995777500","checksum":-2131762700}]}
1626995777.577609: {"arg":{"channel":"books-l2-tbt","instId":"ONT-USDT"},"action":"update","data":[{"asks":[["0.6229","1970","0","1"]],"bids":[["0.5897","0","0","0"]],"ts":"1626995777531","checksum":1046264027}]}
1626995777.5882869: {"arg":{"channel":"books-l2-tbt","instId":"ONT-USDT"},"action":"update","data":[{"asks":[["0.6232","486.341898","0","1"],["1.1196","0","0","0"]],"bids":[],"ts":"1626995777542","checksum":-2519758}]}
1626995777.5979588: {"arg":{"channel":"books-l2-tbt","instId":"ONT-USDT"},"action":"update","data":[{"asks":[],"bids":[["0.6218","1280","0","4"]],"ts":"1626995777551","checksum":-1166277207}]}
1626995777.607701: {"arg":{"channel":"books-l2-tbt","instId":"ONT-USDT"},"action":"update","data":[{"asks":[],"bids":[["0.5898","294.745676","0","1"]],"ts":"1626995777561","checksum":-1166277207}]}
1626995777.637467: {"arg":{"channel":"books-l2-tbt","instId":"ONT-USDT"},"action":"update","data":[{"asks":[],"bids":[["0.6217","320","0","1"]],"ts":"1626995777591","checksum":-1537324785}]}
1626995777.657965: {"arg":{"channel":"books-l2-tbt","instId":"ONT-USDT"},"action":"update","data":[{"asks":[],"bids":[["0.6217","0","0","0"]],"ts":"1626995777612","checksum":644247973}]}
1626995777.661449: {"arg":{"channel":"books-l2-tbt","instId":"AUCTION-USDT"},"action":"update","data":[{"asks":[],"bids":[["14.3","358.2294","0","2"]],"ts":"1626995777615","checksum":-540890044}]}
1626995777.689711: {"arg":{"channel":"books-l2-tbt","instId":"ONT-USDT"},"action":"update","data":[{"asks":[],"bids":[["0.6218","1600","0","5"]],"ts":"1626995777643","checksum":-1025682234}]}
1626995777.700413: {"arg":{"channel":"books-l2-tbt","instId":"TRX-USDT-210924"},"action":"update","data":[{"asks":[["0.05588","3","0","1"],["0.05589","0","0","0"]],"bids":[],"ts":"1626995777652","checksum":-2131762700}]}
1626995777.719452: {"arg":{"channel":"books-l2-tbt","instId":"ONT-USDT"},"action":"update","data":[{"asks":[],"bids":[["0.6219","320","0","1"]],"ts":"1626995777673","checksum":-221394127}]}
1626995777.7537768: {"arg":{"channel":"books-l2-tbt","instId":"AUCTION-USDT"},"action":"update","data":[{"asks":[["15.19","1.5","0","1"]],"bids":[],"ts":"1626995777707","checksum":-1603839782}]}
1626995777.76352: {"arg":{"channel":"books-l2-tbt","instId":"ONT-USDT"},"action":"update","data":[{"asks":[],"bids":[["0.6218","1280","0","4"]],"ts":"1626995777717","checksum":928215926}]}
1626995777.7921002: {"arg":{"channel":"books-l2-tbt","instId":"ONT-USDT"},"action":"update","data":[{"asks":[],"bids":[["0.6218","960","0","3"],["0.6198","0","0","0"]],"ts":"1626995777746","checksum":1390959929}]}
1626995777.80268: {"arg":{"channel":"books-l2-tbt","instId":"ONT-USDT"},"action":"update","data":[{"asks":[["0.6229","2942.683796","0","2"],["0.6232","0","0","0"],["1.1196","19.988","0","1"]],"bids":[["0.6201","792.868423","0","2"]],"ts":"1626995777756","checksum":588686249}]}
1626995777.802871: {"arg":{"channel":"books-l2-tbt","instId":"TRX-USDT-210924"},"action":"update","data":[{"asks":[["0.05588","0","0","0"],["0.05589","3","0","1"]],"bids":[],"ts":"1626995777756","checksum":-2131762700}]}
1626995777.815829: {"arg":{"channel":"books-l2-tbt","instId":"ONT-USDT"},"action":"update","data":[{"asks":[],"bids":[["0.6219","640","0","2"]],"ts":"1626995777765","checksum":868485609}]}
1626995777.8261409: {"arg":{"channel":"books-l2-tbt","instId":"FUN-BTC"},"action":"update","data":[{"asks":[],"bids":[["0.000000414","6694.25","0","1"]],"ts":"1626995777778","checksum":-1824091500}]}
1626995777.8312929: {"arg":{"channel":"books-l2-tbt","instId":"ONT-USDT"},"action":"update","data":[{"asks":[],"bids":[["0.621","680","0","1"]],"ts":"1626995777785","checksum":-223579979}]}
1626995777.842867: {"arg":{"channel":"books-l2-tbt","instId":"XMR-USDT-SWAP"},"action":"update","data":[{"asks":[],"bids":[["195.32","0","0","0"]],"ts":"1626995777795","checksum":-2041549814}]}
1626995777.851827: {"arg":{"channel":"books-l2-tbt","instId":"ONT-USDT"},"action":"update","data":[{"asks":[],"bids":[["0.6218","640","0","2"]],"ts":"1626995777806","checksum":953108704}]}
1626995777.8723168: {"arg":{"channel":"books-l2-tbt","instId":"ONT-USDT"},"action":"update","data":[{"asks":[["0.6233","5092.915","0","1"],["1.1196","0","0","0"]],"bids":[],"ts":"1626995777826","checksum":-1586215753}]}
1626995777.8840199: {"arg":{"channel":"books-l2-tbt","instId":"ONT-USDT"},"action":"update","data":[{"asks":[["0.6233","0","0","0"],["1.1196","19.988","0","1"]],"bids":[["0.6208","9935.162","0","2"]],"ts":"1626995777837","checksum":124018632}]}
1626995777.895829: {"arg":{"channel":"books-l2-tbt","instId":"OKT-BTC"},"action":"update","data":[{"asks":[],"bids":[["0.001452","2.27","0","1"]],"ts":"1626995777846","checksum":241701678}]}
1626995777.895972: {"arg":{"channel":"books-l2-tbt","instId":"ONT-USDT"},"action":"update","data":[{"asks":[],"bids":[["0.6218","320","0","1"]],"ts":"1626995777848","checksum":1396522985}]}
1626995777.9035919: {"arg":{"channel":"books-l2-tbt","instId":"ONT-USDT"},"action":"update","data":[{"asks":[],"bids":[["0.6217","320","0","1"]],"ts":"1626995777857","checksum":-1955264239}]}
1626995777.925118: {"arg":{"channel":"books-l2-tbt","instId":"XMR-USDT-SWAP"},"action":"update","data":[{"asks":[],"bids":[["195.26","90","0","3"]],"ts":"1626995777879","checksum":-2041549814}]}
1626995777.9443042: {"arg":{"channel":"books-l2-tbt","instId":"ONT-USDT"},"action":"update","data":[{"asks":[],"bids":[["0.6218","0","0","0"]],"ts":"1626995777898","checksum":2131396698}]}
1626995777.958264: {"arg":{"channel":"books-l2-tbt","instId":"AUCTION-USDT"},"action":"update","data":[{"asks":[["15.01","166.404417","0","4"]],"bids":[],"ts":"1626995777912","checksum":1765487850}]}
1626995777.968349: {"arg":{"channel":"books-l2-tbt","instId":"ONT-USDT"},"action":"update","data":[{"asks":[],"bids":[["0.6219","320","0","1"]],"ts":"1626995777918","checksum":-1838060988}]}
1626995777.976063: {"arg":{"channel":"books-l2-tbt","instId":"OKT-BTC"},"action":"update","data":[{"asks":[],"bids":[["0.00145","4.59","0","2"]],"ts":"1626995777930","checksum":2107253096}]}
1626995777.989486: {"arg":{"channel":"books-l2-tbt","instId":"ONT-USDT"},"action":"update","data":[{"asks":[["0.6227","0","0","0"],["1.1224","10.5","0","1"]],"bids":[],"ts":"1626995777939","checksum":1532737839}]}
1626995778.012324: {"arg":{"channel":"books-l2-tbt","instId":"XMR-USDT-SWAP"},"action":"update","data":[{"asks":[],"bids":[["195.22","0","0","0"]],"ts":"1626995777966","checksum":-2041549814}]}
1626995778.015389: {"arg":{"channel":"books-l2-tbt","instId":"ONT-USDT"},"action":"update","data":[{"asks":[],"bids":[["0.6217","640","0","2"]],"ts":"1626995777969","checksum":251844878}]}
1626995778.0682921: {"arg":{"channel":"books-l2-tbt","instId":"ONT-USDT"},"action":"update","data":[{"asks":[["0.6221","2997.613064","0","1"],["0.6222","1548.873745","0","2"],["0.6223","0","0","0"],["0.6226","390","0","1"]],"bids":[["0.6219","0","0","0"]],"ts":"1626995778021","checksum":-1307662213}]}
1626995778.097501: {"arg":{"channel":"books-l2-tbt","instId":"XMR-USDT-SWAP"},"action":"update","data":[{"asks":[["197.86","516","0","4"]],"bids":[],"ts":"1626995778049","checksum":-2041549814}]}
1626995778.1012108: {"arg":{"channel":"books-l2-tbt","instId":"ONT-USDT"},"action":"update","data":[{"asks":[],"bids":[["0.6201","390","0","1"],["0.6198","402.868423","0","1"]],"ts":"1626995778051","checksum":-1285030772}]}
1626995778.113895: {"arg":{"channel":"trades","instId":"FUN-BTC"},"data":[{"instId":"FUN-BTC","tradeId":"3435660","px":"0.000000454","sz":"16.09","side":"sell","ts":"1626995778060"}]}
1626995778.1226711: {"arg":{"channel":"tickers","instId":"FUN-BTC"},"data":[{"instType":"SPOT","instId":"FUN-BTC","last":"0.000000454","lastSz":"16.09","askPx":"0.000000455","askSz":"120646.08","bidPx":"0.000000452","bidSz":"131439.69","open24h":"0.000000444","high24h":"0.000000467","low24h":"0.000000443","sodUtc0":"0.000000446","sodUtc8":"0.000000449","volCcy24h":"0.13","vol24h":"302373.35","ts":"1626995778070"}]}
1626995778.128268: {"arg":{"channel":"books-l2-tbt","instId":"ONT-USDT"},"action":"update","data":[{"asks":[],"bids":[["0.6218","640","0","2"]],"ts":"1626995778083","checksum":437695727}]}
1626995778.150576: {"arg":{"channel":"books-l2-tbt","instId":"ONT-USDT"},"action":"update","data":[{"asks":[["0.6221","0","0","0"],["0.6222","603.334745","0","1"],["1.1269","240","0","1"]],"bids":[],"ts":"1626995778103","checksum":16622352}]}
1626995778.1582952: {"arg":{"channel":"books-l2-tbt","instId":"XMR-USDT-SWAP"},"action":"update","data":[{"asks":[["197.87","3","0","1"]],"bids":[],"ts":"1626995778111","checksum":-2041549814}]}
1626995778.1618: {"arg":{"channel":"books-l2-tbt","instId":"ONT-USDT"},"action":"update","data":[{"asks":[],"bids":[["0.6217","320","0","1"],["0.6208","405.5","0","1"]],"ts":"1626995778112","checksum":-789658031}]}
1626995778.161938: {"arg":{"channel":"books-l2-tbt","instId":"TRX-USDT-210924"},"action":"update","data":[{"asks":[],"bids":[["0.00055","0","0","0"]],"ts":"1626995778113","checksum":-2131762700}]}
1626995778.2399318: {"arg":{"channel":"books-l2-tbt","instId":"ONT-USDT"},"action":"update","data":[{"asks":[],"bids":[["0.6216","371","0","2"]],"ts":"1626995778194","checksum":298994179}]}
1626995778.249511: {"arg":{"channel":"books-l2-tbt","instId":"ONT-USDT"},"action":"update","data":[{"asks":[],"bids":[["0.6216","691","0","3"]],"ts":"1626995778203","checksum":552750054}]}
1626995778.26127: {"arg":{"channel":"books-l2-tbt","instId":"TRX-USDT-210924"},"action":"update","data":[{"asks":[["0.05588","3","0","1"],["0.05589","0","0","0"]],"bids":[],"ts":"1626995778214","checksum":-2131762700}]}
1626995778.261447: {"arg":{"channel":"books-l2-tbt","instId":"ONT-USDT"},"action":"update","data":[{"asks":[["0.6223","945.539","0","1"],["1.1269","0","0","0"]],"bids":[],"ts":"1626995778215","checksum":1494971016}]}
1626995778.2828538: {"arg":{"channel":"books-l2-tbt","instId":"ONT-USDT"},"action":"update","data":[{"asks":[],"bids":[["0.6217","0","0","0"]],"ts":"1626995778236","checksum":-1458962939}]}
1626995778.3348658: {"arg":{"channel":"books-l2-tbt","instId":"TRX-USDT-210924"},"action":"update","data":[{"asks":[["0.05588","0","0","0"],["0.05589","3","0","1"]],"bids":[],"ts":"1626995778287","checksum":-2131762700}]}
1626995778.350902: {"arg":{"channel":"books-l2-tbt","instId":"ONT-USDT"},"action":"update","data":[{"asks":[["0.6279","0","0","0"],["1.1269","240","0","1"]],"bids":[],"ts":"1626995778305","checksum":-884264334}]}
1626995778.434083: {"arg":{"channel":"books-l2-tbt","instId":"ONT-USDT"},"action":"update","data":[{"asks":[],"bids":[["0.6218","320","0","1"]],"ts":"1626995778387","checksum":-204286552}]}
1626995778.4495978: {"arg":{"channel":"books-l2-tbt","instId":"ONT-USDT"},"action":"update","data":[{"asks":[],"bids":[["0.6218","0","0","0"]],"ts":"1626995778398","checksum":999352993}]}
1626995778.4525492: {"arg":{"channel":"books-l2-tbt","instId":"DHT-USDT"},"action":"update","data":[{"asks":[["0.795","0","0","0"]],"bids":[],"ts":"1626995778406","checksum":-564066120}]}
1626995778.463491: {"arg":{"channel":"books-l2-tbt","instId":"ONT-USDT"},"action":"update","data":[{"asks":[["0.6222","1548.873745","0","2"],["0.6223","0","0","0"],["1.1285","10.5","0","1"]],"bids":[],"ts":"1626995778417","checksum":1139668806}]}
1626995778.463669: {"arg":{"channel":"books-l2-tbt","instId":"TRX-USDT-210924"},"action":"update","data":[{"asks":[["0.05588","3","0","1"],["0.05589","0","0","0"]],"bids":[],"ts":"1626995778417","checksum":-2131762700}]}
1626995778.4944918: {"arg":{"channel":"books-l2-tbt","instId":"ONT-USDT"},"action":"update","data":[{"asks":[],"bids":[["0.6216","1331","0","5"]],"ts":"1626995778448","checksum":-1628835498}]}
1626995778.505158: {"arg":{"channel":"books-l2-tbt","instId":"ONT-USDT"},"action":"update","data":[{"asks":[],"bids":[["0.6216","1011","0","4"]],"ts":"1626995778458","checksum":-977227940}]}
1626995778.50969: {"arg":{"channel":"books-l2-tbt","instId":"XMR-USDT-SWAP"},"action":"update","data":[{"asks":[],"bids":[["195.27","0","0","0"]],"ts":"1626995778463","checksum":-2041549814}]}
1626995778.526815: {"arg":{"channel":"books-l2-tbt","instId":"ONT-USDT"},"action":"update","data":[{"asks":[["0.6244","0","0","0"],["1.1288","10.09339","0","1"]],"bids":[["0.619","0","0","0"]],"ts":"1626995778479","checksum":653397707}]}
1626995778.5522351: {"arg":{"channel":"books-l2-tbt","instId":"XMR-USDT-SWAP"},"action":"update","data":[{"asks":[["197.04","0","0","0"]],"bids":[],"ts":"1626995778504","checksum":-2041549814}]}
1626995778.58246: {"arg":{"channel":"books-l2-tbt","instId":"XMR-USDT-SWAP"},"action":"update","data":[{"asks":[],"bids":[["195.28","0","0","0"]],"ts":"1626995778525","checksum":-2041549814}]}
1626995778.582546: {"arg":{"channel":"books-l2-tbt","instId":"ONT-USDT"},"action":"update","data":[{"asks":[],"bids":[["0.6131","82","0","1"]],"ts":"1626995778529","checksum":653397707}]}
1626995778.59503: {"arg":{"channel":"books-l2-tbt","instId":"XMR-USDT-SWAP"},"action":"update","data":[{"asks":[],"bids":[["195.29","9","0","1"]],"ts":"1626995778545","checksum":-2041549814}]}
1626995778.611991: {"arg":{"channel":"books-l2-tbt","instId":"ONT-USDT"},"action":"update","data":[{"asks":[],"bids":[["0.6216","1331","0","5"]],"ts":"1626995778562","checksum":-1805786777}]}
1626995778.6367161: {"arg":{"channel":"books-l2-tbt","instId":"ONT-USDT"},"action":"update","data":[{"asks":[["0.6246","6080.411023","0","1"],["1.1288","0","0","0"]],"bids":[["0.6191","6080.411021","0","1"]],"ts":"1626995778590","checksum":217924314}]}
1626995778.65752: {"arg":{"channel":"books-l2-tbt","instId":"AUCTION-USDT"},"action":"update","data":[{"asks":[],"bids":[["14.3","207.112192","0","1"]],"ts":"1626995778612","checksum":-1707538221}]}
1626995778.6631749: {"arg":{"channel":"trades","instId":"OKT-BTC"},"data":[{"instId":"OKT-BTC","tradeId":"3406236","px":"0.001473","sz":"0.26274046","side":"buy","ts":"1626995778612"}]}
1626995778.676207: {"arg":{"channel":"books-l2-tbt","instId":"XMR-USDT-SWAP"},"action":"update","data":[{"asks":[["197.03","142","0","1"]],"bids":[["195.28","142","0","1"]],"ts":"1626995778630","checksum":-2041549814}]}
1626995778.683437: {"arg":{"channel":"tickers","instId":"OKT-BTC"},"data":[{"instType":"SPOT","instId":"OKT-BTC","last":"0.001473","lastSz":"0.26274046","askPx":"0.001475","askSz":"0.4130644","bidPx":"0.001471","bidSz":"0.24901841","open24h":"0.001402","high24h":"0.001489","low24h":"0.001387","sodUtc0":"0.001408","sodUtc8":"0.001437","volCcy24h":"17.15833598","vol24h":"12035.8408197","ts":"1626995778626"}]}
1626995778.687294: {"arg":{"channel":"books-l2-tbt","instId":"DHT-USDT"},"action":"update","data":[{"asks":[["0.792","423.1407","0","1"]],"bids":[],"ts":"1626995778640","checksum":821243757}]}
1626995778.6910348: {"arg":{"channel":"books-l2-tbt","instId":"TRX-USDT-210924"},"action":"update","data":[{"asks":[["0.05588","0","0","0"],["0.05589","3","0","1"]],"bids":[],"ts":"1626995778645","checksum":-2131762700}]}
1626995778.706408: {"arg":{"channel":"books-l2-tbt","instId":"PAY-BTC"},"action":"update","data":[{"asks":[["0.0000014","1666.454","0","2"]],"bids":[],"ts":"1626995778648","checksum":-1553003114}]}
1626995778.706542: {"arg":{"channel":"books-l2-tbt","instId":"PAY-BTC"},"action":"update","data":[{"asks":[],"bids":[["0.00000134","2946.063","0","4"]],"ts":"1626995778659","checksum":-401915286}]}
1626995778.718209: {"arg":{"channel":"books-l2-tbt","instId":"XMR-USDT-SWAP"},"action":"update","data":[{"asks":[["196.26","171","0","1"]],"bids":[],"ts":"1626995778671","checksum":-875552317}]}
1626995778.756944: {"arg":{"channel":"trades","instId":"XMR-USDT-SWAP"},"data":[{"instId":"XMR-USDT-SWAP","tradeId":"6845130","px":"196.24","sz":"43","side":"buy","ts":"1626995778708"}]}
1626995778.783884: {"arg":{"channel":"books-l2-tbt","instId":"XMR-USDT-SWAP"},"action":"update","data":[{"asks":[["196.41","37","0","2"],["196.43","506","0","2"]],"bids":[["195.28","0","0","0"]],"ts":"1626995778732","checksum":525916821}]}
1626995778.783926: {"arg":{"channel":"books-l2-tbt","instId":"ONT-USDT"},"action":"update","data":[{"asks":[],"bids":[["0.6216","371","0","2"]],"ts":"1626995778733","checksum":121331465}]}
1626995778.8122299: {"arg":{"channel":"books-l2-tbt","instId":"AUCTION-USDT"},"action":"update","data":[{"asks":[],"bids":[["13.5","8.222222","0","3"]],"ts":"1626995778765","checksum":-1707538221}]}
1626995778.825592: {"arg":{"channel":"books-l2-tbt","instId":"XMR-USDT-SWAP"},"action":"update","data":[{"asks":[["196.26","357","0","2"]],"bids":[],"ts":"1626995778775","checksum":-38985524}]}
1626995778.870672: {"arg":{"channel":"books-l2-tbt","instId":"ONT-USDT"},"action":"update","data":[{"asks":[],"bids":[["0.6198","9935.399423","0","2"]],"ts":"1626995778824","checksum":-449161719}]}
1626995778.879433: {"arg":{"channel":"tickers","instId":"XMR-USDT-SWAP"},"data":[{"instType":"SWAP","instId":"XMR-USDT-SWAP","last":"196.24","lastSz":"43","askPx":"196.26","askSz":"357","bidPx":"196.14","bidSz":"116","open24h":"197.32","high24h":"202.54","low24h":"189.85","sodUtc0":"196.66","sodUtc8":"199.56","volCcy24h":"65233.5","vol24h":"652335","ts":"1626995778824"}]}
1626995778.879545: {"arg":{"channel":"books-l2-tbt","instId":"XMR-USDT-SWAP"},"action":"update","data":[{"asks":[["196.43","512","0","2"]],"bids":[],"ts":"1626995778833","checksum":131858494}]}
1626995778.8937669: {"arg":{"channel":"books-l2-tbt","instId":"AUCTION-USDT"},"action":"update","data":[{"asks":[],"bids":[["14.24","151.753938","0","1"]],"ts":"1626995778847","checksum":-928210981}]}
1626995778.9004428: {"arg":{"channel":"books-l2-tbt","instId":"XMR-USDT-SWAP"},"action":"update","data":[{"asks":[],"bids":[["195.3","142","0","1"]],"ts":"1626995778854","checksum":131858494}]}
1626995778.900552: {"arg":{"channel":"books-l2-tbt","instId":"ONT-USDT"},"action":"update","data":[{"asks":[],"bids":[["0.6216","51","0","1"]],"ts":"1626995778855","checksum":75206885}]}
1626995778.922389: {"arg":{"channel":"books-l2-tbt","instId":"ONT-USDT"},"action":"update","data":[{"asks":[["0.622","436.838861","0","2"]],"bids":[],"ts":"1626995778876","checksum":-263933242}]}
1626995778.9405289: {"arg":{"channel":"books-l2-tbt","instId":"XMR-USDT-SWAP"},"action":"update","data":[{"asks":[["196.43","7","0","1"]],"bids":[],"ts":"1626995778894","checksum":942982005}]}
1626995778.9612658: {"arg":{"channel":"books-l2-tbt","instId":"XMR-USDT-SWAP"},"action":"update","data":[{"asks":[["196.43","512","0","2"]],"bids":[],"ts":"1626995778915","checksum":131858494}]}
1626995778.963341: {"arg":{"channel":"books-l2-tbt","instId":"ONT-USDT"},"action":"update","data":[{"asks":[],"bids":[["0.6211","427.75354","0","2"]],"ts":"1626995778917","checksum":-1459744114}]}
1626995778.974051: {"arg":{"channel":"books-l2-tbt","instId":"ONT-USDT"},"action":"update","data":[{"asks":[["0.6222","1656.627285","0","3"],["0.6225","0","0","0"],["1.1288","10.09339","0","1"]],"bids":[["0.6215","945.539","0","1"]],"ts":"1626995778928","checksum":404823471}]}
1626995779.002999: {"arg":{"channel":"books-l2-tbt","instId":"XMR-USDT-SWAP"},"action":"update","data":[{"asks":[["196.43","7","0","1"]],"bids":[],"ts":"1626995778956","checksum":942982005}]}
1626995779.022379: {"arg":{"channel":"books-l2-tbt","instId":"XMR-USDT-SWAP"},"action":"update","data":[{"asks":[["196.43","512","0","2"]],"bids":[],"ts":"1626995778976","checksum":131858494}]}
1626995779.022468: {"arg":{"channel":"books-l2-tbt","instId":"OKT-BTC"},"action":"update","data":[{"asks":[],"bids":[["0.001471","0.24901841","0","1"]],"ts":"1626995778977","checksum":-888123199}]}
1626995779.057179: {"arg":{"channel":"books-l2-tbt","instId":"OKT-BTC"},"action":"update","data":[{"asks":[],"bids":[["0.001471","2.89090055","0","2"]],"ts":"1626995779010","checksum":2107253096}]}
1626995779.076152: {"arg":{"channel":"books-l2-tbt","instId":"ONT-USDT"},"action":"update","data":[{"asks":[],"bids":[["0.6211","320","0","1"]],"ts":"1626995779030","checksum":872190746}]}
1626995779.10005: {"arg":{"channel":"books-l2-tbt","instId":"ONT-USDT"},"action":"update","data":[{"asks":[],"bids":[["0.6212","107.75354","0","1"]],"ts":"1626995779053","checksum":-1855729682}]}
1626995779.1669571: {"arg":{"channel":"books-l2-tbt","instId":"XMR-USDT-SWAP"},"action":"update","data":[{"asks":[["196.39","12","0","2"]],"bids":[],"ts":"1626995779121","checksum":-849932391}]}
1626995779.207946: {"arg":{"channel":"books-l2-tbt","instId":"XMR-USDT-SWAP"},"action":"update","data":[{"asks":[["196.43","1017","0","3"]],"bids":[],"ts":"1626995779161","checksum":-1627201789}]}
1626995779.223826: {"arg":{"channel":"books-l2-tbt","instId":"TRX-USDT-210924"},"action":"update","data":[{"asks":[["0.05588","3","0","1"],["0.05589","0","0","0"]],"bids":[],"ts":"1626995779177","checksum":-2131762700}]}
1626995779.227637: {"arg":{"channel":"books-l2-tbt","instId":"XMR-USDT-SWAP"},"action":"update","data":[{"asks":[["196.43","512","0","2"]],"bids":[],"ts":"1626995779181","checksum":-849932391}]}
1626995779.272904: {"arg":{"channel":"books-l2-tbt","instId":"ONT-USDT"},"action":"update","data":[{"asks":[],"bids":[["0.6216","0","0","0"]],"ts":"1626995779227","checksum":-1601669132}]}
1626995779.353052: {"arg":{"channel":"books-l2-tbt","instId":"ONT-USDT"},"action":"update","data":[{"asks":[],"bids":[["0.6198","402.868423","0","1"]],"ts":"1626995779307","checksum":-1192677085}]}
1626995779.363602: {"arg":{"channel":"books-l2-tbt","instId":"ONT-USDT"},"action":"update","data":[{"asks":[],"bids":[["0.6216","2691.594812","0","1"]],"ts":"1626995779317","checksum":1429762152}]}
1626995779.36739: {"arg":{"channel":"books-l2-tbt","instId":"TRX-USDT-210924"},"action":"update","data":[{"asks":[],"bids":[["0.05422","1","0","1"],["0.05421","3","0","1"]],"ts":"1626995779321","checksum":-744476984}]}
1626995779.382808: {"arg":{"channel":"books-l2-tbt","instId":"ONT-USDT"},"action":"update","data":[{"asks":[],"bids":[["0.6211","0","0","0"]],"ts":"1626995779337","checksum":-894656581}]}
1626995779.39778: {"arg":{"channel":"books-l2-tbt","instId":"TRX-USDT-210924"},"action":"update","data":[{"asks":[["0.05452","8","0","1"]],"bids":[["0.05447","0","0","0"]],"ts":"1626995779351","checksum":2084874574}]}
1626995779.407315: {"arg":{"channel":"books-l2-tbt","instId":"TRX-USDT-210924"},"action":"update","data":[{"asks":[["0.0545","16","0","2"]],"bids":[],"ts":"1626995779361","checksum":1495208266}]}
1626995779.431995: {"arg":{"channel":"books-l2-tbt","instId":"ONT-USDT"},"action":"update","data":[{"asks":[["0.6222","1548.873745","0","2"],["0.6225","107.690915","0","1"],["1.1288","0","0","0"]],"bids":[["0.6214","1078.273424","0","3"],["0.6212","0","0","0"]],"ts":"1626995779385","checksum":-1099080501}]}
1626995779.451305: {"arg":{"channel":"books-l2-tbt","instId":"XMR-USDT-SWAP"},"action":"update","data":[{"asks":[["196.41","542","0","3"],["196.43","7","0","1"]],"bids":[],"ts":"1626995779405","checksum":804157611}]}
1626995779.470457: {"arg":{"channel":"books-l2-tbt","instId":"TRX-USDT-210924"},"action":"update","data":[{"asks":[["0.05464","158","0","1"],["0.05477","143","0","1"],["0.05499","0","0","0"]],"bids":[],"ts":"1626995779423","checksum":-1195841732}]}
1626995779.5373418: {"arg":{"channel":"books-l2-tbt","instId":"TRX-USDT-210924"},"action":"update","data":[{"asks":[["0.05461","285","0","4"],["0.05463","134","0","2"],["0.05476","242","0","1"]],"bids":[],"ts":"1626995779486","checksum":-1812255509}]}
1626995779.544554: {"arg":{"channel":"books-l2-tbt","instId":"TRX-USDT-210924"},"action":"update","data":[{"asks":[["0.05495","525","0","2"]],"bids":[],"ts":"1626995779496","checksum":-1497368903}]}
1626995779.562044: {"arg":{"channel":"books-l2-tbt","instId":"FUN-BTC"},"action":"update","data":[{"asks":[],"bids":[["0.000000414","0","0","0"]],"ts":"1626995779507","checksum":645519708}]}
1626995779.5621681: {"arg":{"channel":"books-l2-tbt","instId":"ONT-USDT"},"action":"update","data":[{"asks":[],"bids":[["0.6208","10784.195","0","2"]],"ts":"1626995779514","checksum":-153085648}]}
1626995779.635875: {"arg":{"channel":"books-l2-tbt","instId":"TRX-USDT-210924"},"action":"update","data":[{"asks":[["0.05463","1","0","1"]],"bids":[],"ts":"1626995779589","checksum":-459519303}]}
1626995779.646474: {"arg":{"channel":"books-l2-tbt","instId":"TRX-USDT-210924"},"action":"update","data":[{"asks":[["0.05476","0","0","0"],["0.05495","143","0","1"]],"bids":[],"ts":"1626995779600","checksum":656066721}]}
1626995779.6710231: {"arg":{"channel":"books-l2-tbt","instId":"DHT-USDT"},"action":"update","data":[{"asks":[["0.792","0","0","0"]],"bids":[],"ts":"1626995779624","checksum":-564066120}]}
1626995779.684453: {"arg":{"channel":"books-l2-tbt","instId":"OKT-BTC"},"action":"update","data":[{"asks":[["0.001477","0","0","0"]],"bids":[],"ts":"1626995779637","checksum":171466922}]}
1626995779.706909: {"arg":{"channel":"books-l2-tbt","instId":"TRX-USDT-210924"},"action":"update","data":[{"asks":[["0.05463","133","0","2"],["0.05476","241","0","1"],["0.05499","382","0","1"]],"bids":[],"ts":"1626995779660","checksum":374723117}]}
1626995779.718695: {"arg":{"channel":"books-l2-tbt","instId":"XMR-USDT-SWAP"},"action":"update","data":[{"asks":[["196.26","427","0","3"]],"bids":[],"ts":"1626995779672","checksum":-12778881}]}
1626995779.756093: {"arg":{"channel":"books-l2-tbt","instId":"ONT-USDT"},"action":"update","data":[{"asks":[["0.6279","83.730044","0","1"],["1.1285","0","0","0"]],"bids":[["0.6132","343.806974","0","2"]],"ts":"1626995779710","checksum":209968172}]}
1626995779.782787: {"arg":{"channel":"books-l2-tbt","instId":"XMR-USDT-SWAP"},"action":"update","data":[{"asks":[["196.4","67","0","2"],["196.41","510","0","2"]],"bids":[],"ts":"1626995779736","checksum":-110044803}]}
1626995779.802732: {"arg":{"channel":"books-l2-tbt","instId":"PAY-BTC"},"action":"update","data":[{"asks":[["0.0000014","2866.44","0","3"]],"bids":[["0.00000134","4117.948","0","5"]],"ts":"1626995779749","checksum":-73858121}]}
1626995779.8415868: {"arg":{"channel":"books-l2-tbt","instId":"FUN-BTC"},"action":"update","data":[{"asks":[],"bids":[["0.000000405","6843.01","0","1"]],"ts":"1626995779795","checksum":602925849}]}
1626995779.8624551: {"arg":{"channel":"books-l2-tbt","instId":"AUCTION-USDT"},"action":"update","data":[{"asks":[],"bids":[["14.24","0","0","0"]],"ts":"1626995779813","checksum":-1707538221}]}
1626995779.919224: {"arg":{"channel":"books-l2-tbt","instId":"DHT-USDT"},"action":"update","data":[{"asks":[["0.794","463.1407","0","2"]],"bids":[],"ts":"1626995779872","checksum":2058410061}]}
1626995779.9293902: {"arg":{"channel":"books-l2-tbt","instId":"ONT-USDT"},"action":"update","data":[{"asks":[],"bids":[["0.6216","0","0","0"]],"ts":"1626995779883","checksum":-1108563422}]}
1626995779.9411662: {"arg":{"channel":"books-l2-tbt","instId":"ONT-USDT"},"action":"update","data":[{"asks":[],"bids":[["0.6216","51","0","1"],["0.6205","1709.660295","0","2"]],"ts":"1626995779895","checksum":451328989}]}
1626995779.9498382: {"arg":{"channel":"books-l2-tbt","instId":"ONT-USDT"},"action":"update","data":[{"asks":[["0.6234","0","0","0"],["1.1285","10.5","0","1"]],"bids":[],"ts":"1626995779904","checksum":693690036}]}
1626995779.961303: {"arg":{"channel":"books-l2-tbt","instId":"ONT-USDT"},"action":"update","data":[{"asks":[["0.6222","1656.56466","0","3"]],"bids":[["0.6214","970.582509","0","2"],["0.6211","107.690915","0","1"]],"ts":"1626995779915","checksum":-667923519}]}
1626995779.971502: {"arg":{"channel":"books-l2-tbt","instId":"ONT-USDT"},"action":"update","data":[{"asks":[["0.6225","0","0","0"],["1.1288","10.09339","0","1"]],"bids":[],"ts":"1626995779924","checksum":1273487267}]}
1626995780.0114691: {"arg":{"channel":"books-l2-tbt","instId":"XMR-USDT-SWAP"},"action":"update","data":[{"asks":[],"bids":[["195.26","80","0","2"]],"ts":"1626995779965","checksum":-110044803}]}
1626995780.03471: {"arg":{"channel":"books-l2-tbt","instId":"TRX-USDT-210924"},"action":"update","data":[{"asks":[["0.05463","1","0","1"]],"bids":[],"ts":"1626995779988","checksum":1851681337}]}
1626995780.0439382: {"arg":{"channel":"books-l2-tbt","instId":"TRX-USDT-210924"},"action":"update","data":[{"asks":[["0.05476","0","0","0"]],"bids":[],"ts":"1626995779997","checksum":-2144220311}]}
1626995780.0638988: {"arg":{"channel":"books-l2-tbt","instId":"ONT-USDT"},"action":"update","data":[{"asks":[],"bids":[["0.6217","6.871136","0","1"]],"ts":"1626995780017","checksum":-1800343160}]}
1626995780.0824351: {"arg":{"channel":"books-l2-tbt","instId":"DHT-USDT"},"action":"update","data":[{"asks":[["0.794","423.1407","0","1"]],"bids":[],"ts":"1626995780036","checksum":-831419424}]}
1626995780.095194: {"arg":{"channel":"books-l2-tbt","instId":"XMR-USDT-SWAP"},"action":"update","data":[{"asks":[],"bids":[["195.26","70","0","1"]],"ts":"1626995780049","checksum":-110044803}]}
1626995780.105963: {"arg":{"channel":"books-l2-tbt","instId":"TRX-USDT-210924"},"action":"update","data":[{"asks":[["0.05464","297","0","2"],["0.05477","389","0","2"]],"bids":[],"ts":"1626995780059","checksum":-1030490672}]}
1626995780.1061099: {"arg":{"channel":"books-l2-tbt","instId":"AUCTION-USDT"},"action":"update","data":[{"asks":[],"bids":[["14.31","159.011605","0","2"]],"ts":"1626995780060","checksum":-2017225663}]}
1626995780.138303: {"arg":{"channel":"books-l2-tbt","instId":"XMR-USDT-SWAP"},"action":"update","data":[{"asks":[["196.28","3","0","1"],["196.34","10","0","2"],["196.36","0","0","0"],["196.38","7","0","1"],["196.44","28","0","1"],["196.46","7","0","1"],["196.48","28","0","1"],["196.5","15","0","1"],["196.52","3","0","1"],["196.58","0","0","0"],["196.6","0","0","0"],["196.91","3","0","1"],["196.99","0","0","0"],["197.3","6","0","1"],["197.44","0","0","0"]],"bids":[],"ts":"1626995780092","checksum":625834411}]}
1626995780.1842291: {"arg":{"channel":"books-l2-tbt","instId":"ONT-USDT"},"action":"update","data":[{"asks":[["0.6222","1548.873745","0","2"],["0.6225","109.084803","0","1"],["1.1288","0","0","0"]],"bids":[["0.6214","1079.667312","0","3"],["0.6211","0","0","0"]],"ts":"1626995780138","checksum":650264088}]}
1626995780.276598: {"arg":{"channel":"books-l2-tbt","instId":"ONT-USDT"},"action":"update","data":[{"asks":[["0.6222","945.539","0","1"]],"bids":[],"ts":"1626995780230","checksum":1173713922}]}
1626995780.359509: {"arg":{"channel":"books-l2-tbt","instId":"OKT-BTC"},"action":"update","data":[{"asks":[["0.001475","3.05407465","0","2"]],"bids":[],"ts":"1626995780312","checksum":-551100225}]}
1626995780.385407: {"arg":{"channel":"books-l2-tbt","instId":"TRX-USDT-210924"},"action":"update","data":[{"asks":[],"bids":[["0.05442","494","0","4"],["0.05438","68","0","2"]],"ts":"1626995780337","checksum":-590053769}]}
1626995780.4586968: {"arg":{"channel":"books-l2-tbt","instId":"ONT-USDT"},"action":"update","data":[{"asks":[],"bids":[["0.62","642","0","1"]],"ts":"1626995780413","checksum":355589848}]}
1626995780.4896598: {"arg":{"channel":"books-l2-tbt","instId":"TRX-USDT-210924"},"action":"update","data":[{"asks":[],"bids":[["0.05438","59","0","1"],["0.05437","9","0","1"]],"ts":"1626995780443","checksum":-1301741005}]}
1626995780.543102: {"arg":{"channel":"books-l2-tbt","instId":"XMR-USDT-SWAP"},"action":"update","data":[{"asks":[["196.34","3","0","1"],["196.38","0","0","0"],["196.42","15","0","3"],["196.54","7","0","1"],["197.3","0","0","0"],["197.38","6","0","1"]],"bids":[],"ts":"1626995780495","checksum":-1719283129}]}
1626995780.543314: {"arg":{"channel":"books-l2-tbt","instId":"ONT-USDT"},"action":"update","data":[{"asks":[],"bids":[["0.6212","320","0","1"]],"ts":"1626995780497","checksum":507284436}]}
1626995780.553728: {"arg":{"channel":"books-l2-tbt","instId":"ONT-USDT"},"action":"update","data":[{"asks":[],"bids":[["0.6212","640","0","2"],["0.6175","41276.433198","0","3"]],"ts":"1626995780506","checksum":-1509162525}]}
1626995780.5626209: {"arg":{"channel":"books-l2-tbt","instId":"TRX-USDT-210924"},"action":"update","data":[{"asks":[],"bids":[["0.05446","10","0","2"]],"ts":"1626995780513","checksum":1647602788}]}
1626995780.590076: {"arg":{"channel":"books-l2-tbt","instId":"ONT-USDT"},"action":"update","data":[{"asks":[],"bids":[["0.6212","1920","0","6"]],"ts":"1626995780541","checksum":457405123}]}
1626995780.5902138: {"arg":{"channel":"books-l2-tbt","instId":"TRX-USDT-210924"},"action":"update","data":[{"asks":[],"bids":[["0.05442","497","0","5"],["0.05437","0","0","0"]],"ts":"1626995780542","checksum":-1654414783}]}
1626995780.654149: {"arg":{"channel":"books-l2-tbt","instId":"ONT-USDT"},"action":"update","data":[{"asks":[],"bids":[["0.6199","47","0","1"]],"ts":"1626995780605","checksum":1406710721}]}
1626995780.742825: {"arg":{"channel":"books-l2-tbt","instId":"ONT-USDT"},"action":"update","data":[{"asks":[],"bids":[["0.6198","449.868423","0","2"]],"ts":"1626995780696","checksum":-2000613342}]}
1626995780.7528698: {"arg":{"channel":"books-l2-tbt","instId":"DHT-USDT"},"action":"update","data":[{"asks":[],"bids":[["0.734","2350","0","1"]],"ts":"1626995780705","checksum":1325937747}]}
1626995780.763464: {"arg":{"channel":"books-l2-tbt","instId":"DHT-USDT"},"action":"update","data":[{"asks":[],"bids":[["0.734","0","0","0"]],"ts":"1626995780717","checksum":-831419424}]}
1626995780.795251: {"arg":{"channel":"books-l2-tbt","instId":"ONT-USDT"},"action":"update","data":[{"asks":[["0.6228","10780.143384","0","3"]],"bids":[],"ts":"1626995780749","checksum":2144129657}]}
1626995780.866614: {"arg":{"channel":"trades","instId":"ONT-USDT"},"data":[{"instId":"ONT-USDT","tradeId":"11366801","px":"0.6219","sz":"489.355689","side":"buy","ts":"1626995780817"}]}
1626995780.917161: {"arg":{"channel":"books-l2-tbt","instId":"DHT-USDT"},"action":"update","data":[{"asks":[],"bids":[["0.721","0","0","0"]],"ts":"1626995780870","checksum":-292693670}]}
1626995780.9323049: {"arg":{"channel":"books-l2-tbt","instId":"ONT-USDT"},"action":"update","data":[{"asks":[],"bids":[["0.6212","1280","0","4"]],"ts":"1626995780883","checksum":1591057751}]}
1626995780.935275: {"arg":{"channel":"tickers","instId":"ONT-USDT"},"data":[{"instType":"SPOT","instId":"ONT-USDT","last":"0.6219","lastSz":"489.355689","askPx":"0.6221","askSz":"2752.353814","bidPx":"0.6217","bidSz":"640","open24h":"0.6075","high24h":"0.6314","low24h":"0.5967","sodUtc0":"0.6131","sodUtc8":"0.6275","volCcy24h":"9395048.127286","vol24h":"15284521.095199","ts":"1626995780882"}]}
1626995780.938123: {"arg":{"channel":"books-l2-tbt","instId":"ONT-USDT"},"action":"update","data":[{"asks":[],"bids":[["0.6212","960","0","3"]],"ts":"1626995780892","checksum":-414710993}]}
1626995780.948925: {"arg":{"channel":"books-l2-tbt","instId":"ONT-USDT"},"action":"update","data":[{"asks":[],"bids":[["0.6212","320","0","1"]],"ts":"1626995780903","checksum":-1497730675}]}
