wss://ws.okex.com:8443/ws/v5/public <-> 1626995752.315705
wss://ws.okex.com:8443/ws/v5/public <- 1626995753.098816: {"op":"subscribe","args":[{"channel":"books-l2-tbt","instId":"FUN-BTC"},{"channel":"books-l2-tbt","instId":"BTC-USD-210924-66000-C"},{"channel":"books-l2-tbt","instId":"XMR-USDT-SWAP"},{"channel":"books-l2-tbt","instId":"AUCTION-USDT"},{"channel":"books-l2-tbt","instId":"OKT-BTC"},{"channel":"books-l2-tbt","instId":"PAY-BTC"},{"channel":"books-l2-tbt","instId":"BTC-USD-210924-42000-P"},{"channel":"books-l2-tbt","instId":"ONT-USDT"},{"channel":"books-l2-tbt","instId":"DHT-USDT"},{"channel":"books-l2-tbt","instId":"TRX-USDT-210924"},{"channel":"trades","instId":"FUN-BTC"},{"channel":"trades","instId":"BTC-USD-210924-66000-C"},{"channel":"trades","instId":"XMR-USDT-SWAP"},{"channel":"trades","instId":"AUCTION-USDT"},{"channel":"trades","instId":"OKT-BTC"},{"channel":"trades","instId":"PAY-BTC"},{"channel":"trades","instId":"BTC-USD-210924-42000-P"},{"channel":"trades","instId":"ONT-USDT"},{"channel":"trades","instId":"DHT-USDT"},{"channel":"trades","instId":"TRX-USDT-210924"},{"channel":"tickers","instId":"FUN-BTC"},{"channel":"tickers","instId":"BTC-USD-210924-66000-C"},{"channel":"tickers","instId":"XMR-USDT-SWAP"},{"channel":"tickers","instId":"AUCTION-USDT"},{"channel":"tickers","instId":"OKT-BTC"},{"channel":"tickers","instId":"PAY-BTC"},{"channel":"tickers","instId":"BTC-USD-210924-42000-P"},{"channel":"tickers","instId":"ONT-USDT"},{"channel":"tickers","instId":"DHT-USDT"},{"channel":"tickers","instId":"TRX-USDT-210924"}]}
1626995753.337132: {"event":"subscribe","arg":{"channel":"books-l2-tbt","instId":"FUN-BTC"}}
1626995753.337163: {"event":"subscribe","arg":{"channel":"books-l2-tbt","instId":"BTC-USD-210924-66000-C"}}
1626995753.3371751: {"event":"subscribe","arg":{"channel":"books-l2-tbt","instId":"XMR-USDT-SWAP"}}
1626995753.337184: {"event":"subscribe","arg":{"channel":"books-l2-tbt","instId":"AUCTION-USDT"}}
1626995753.3371918: {"event":"subscribe","arg":{"channel":"books-l2-tbt","instId":"OKT-BTC"}}
1626995753.3371992: {"event":"subscribe","arg":{"channel":"books-l2-tbt","instId":"PAY-BTC"}}
1626995753.3372061: {"event":"subscribe","arg":{"channel":"books-l2-tbt","instId":"BTC-USD-210924-42000-P"}}
1626995753.337214: {"event":"subscribe","arg":{"channel":"books-l2-tbt","instId":"ONT-USDT"}}
1626995753.3372211: {"event":"subscribe","arg":{"channel":"books-l2-tbt","instId":"DHT-USDT"}}
1626995753.337228: {"event":"subscribe","arg":{"channel":"books-l2-tbt","instId":"TRX-USDT-210924"}}
1626995753.337235: {"event":"subscribe","arg":{"channel":"trades","instId":"FUN-BTC"}}
1626995753.3372421: {"event":"subscribe","arg":{"channel":"trades","instId":"BTC-USD-210924-66000-C"}}
1626995753.337248: {"event":"subscribe","arg":{"channel":"trades","instId":"XMR-USDT-SWAP"}}
1626995753.337255: {"event":"subscribe","arg":{"channel":"trades","instId":"AUCTION-USDT"}}
1626995753.3372622: {"event":"subscribe","arg":{"channel":"trades","instId":"OKT-BTC"}}
1626995753.337269: {"event":"subscribe","arg":{"channel":"trades","instId":"PAY-BTC"}}
1626995753.337276: {"event":"subscribe","arg":{"channel":"trades","instId":"BTC-USD-210924-42000-P"}}
1626995753.337282: {"event":"subscribe","arg":{"channel":"trades","instId":"ONT-USDT"}}
1626995753.3372889: {"event":"subscribe","arg":{"channel":"trades","instId":"DHT-USDT"}}
1626995753.3372958: {"event":"subscribe","arg":{"channel":"trades","instId":"TRX-USDT-210924"}}
1626995753.337303: {"event":"subscribe","arg":{"channel":"tickers","instId":"FUN-BTC"}}
1626995753.337309: {"event":"subscribe","arg":{"channel":"tickers","instId":"BTC-USD-210924-66000-C"}}
1626995753.337316: {"event":"subscribe","arg":{"channel":"tickers","instId":"XMR-USDT-SWAP"}}
1626995753.3373241: {"event":"subscribe","arg":{"channel":"tickers","instId":"AUCTION-USDT"}}
1626995753.337331: {"event":"subscribe","arg":{"channel":"tickers","instId":"OKT-BTC"}}
1626995753.337337: {"event":"subscribe","arg":{"channel":"tickers","instId":"PAY-BTC"}}
1626995753.337344: {"event":"subscribe","arg":{"channel":"tickers","instId":"BTC-USD-210924-42000-P"}}
1626995753.3373508: {"event":"subscribe","arg":{"channel":"tickers","instId":"ONT-USDT"}}
1626995753.337358: {"event":"subscribe","arg":{"channel":"tickers","instId":"DHT-USDT"}}
1626995753.337364: {"event":"subscribe","arg":{"channel":"tickers","instId":"TRX-USDT-210924"}}
1626995753.3373709: {"arg":{"channel":"trades","instId":"BTC-USD-210924-66000-C"},"data":[{"instId":"BTC-USD-210924-66000-C","tradeId":"206","px":"0.0065","sz":"2","side":"sell","ts":"1626922893155"}]}
1626995753.3374238: {"arg":{"channel":"trades","instId":"FUN-BTC"},"data":[{"instId":"FUN-BTC","tradeId":"3435655","px":"0.000000454","sz":"11.83","side":"sell","ts":"1626995753055"}]}
1626995753.337452: {"arg":{"channel":"trades","instId":"AUCTION-USDT"},"data":[{"instId":"AUCTION-USDT","tradeId":"584231","px":"14.87","sz":"0.556412","side":"buy","ts":"1626995748554"}]}
1626995753.337475: {"arg":{"channel":"trades","instId":"XMR-USDT-SWAP"},"data":[{"instId":"XMR-USDT-SWAP","tradeId":"6845125","px":"196.11","sz":"8","side":"buy","ts":"1626995753200"}]}
1626995753.337496: {"arg":{"channel":"trades","instId":"OKT-BTC"},"data":[{"instId":"OKT-BTC","tradeId":"3406229","px":"0.001473","sz":"0.55833367","side":"sell","ts":"1626995748605"}]}
1626995753.337515: {"arg":{"channel":"trades","instId":"PAY-BTC"},"data":[{"instId":"PAY-BTC","tradeId":"6071311","px":"0.00000138","sz":"2351.35","side":"sell","ts":"1626995751369"}]}
1626995753.337535: {"arg":{"channel":"trades","instId":"ONT-USDT"},"data":[{"instId":"ONT-USDT","tradeId":"11366799","px":"0.6217","sz":"1342.208542","side":"buy","ts":"1626995748814"}]}
1626995753.337554: {"arg":{"channel":"trades","instId":"DHT-USDT"},"data":[{"instId":"DHT-USDT","tradeId":"1135005","px":"0.757","sz":"73.639284","side":"buy","ts":"1626995752886"}]}
1626995753.337573: {"arg":{"channel":"trades","instId":"TRX-USDT-210924"},"data":[{"instId":"TRX-USDT-210924","tradeId":"1200052","px":"0.0545","sz":"4","side":"sell","ts":"1626995752334"}]}
1626995753.3375921: {"arg":{"channel":"tickers","instId":"FUN-BTC"},"data":[{"instType":"SPOT","instId":"FUN-BTC","last":"0.000000454","lastSz":"11.83","askPx":"0.000000455","askSz":"142796.14","bidPx":"0.000000452","bidSz":"141211.03","open24h":"0.000000445","high24h":"0.000000467","low24h":"0.000000443","sodUtc0":"0.000000446","sodUtc8":"0.000000449","volCcy24h":"0.13","vol24h":"302436.11","ts":"1626995753163"}]}
1626995753.337622: {"arg":{"channel":"tickers","instId":"BTC-USD-210924-66000-C"},"data":[{"instType":"OPTION","instId":"BTC-USD-210924-66000-C","last":"0.0065","lastSz":"0","askPx":"0.008","askSz":"300","bidPx":"0.0065","bidSz":"5","open24h":"0.006","high24h":"0.0065","low24h":"0.006","sodUtc0":"0.006","sodUtc8":"0.0065","volCcy24h":"0.2","vol24h":"2","ts":"1626995703355"}]}
1626995753.337646: {"arg":{"channel":"tickers","instId":"XMR-USDT-SWAP"},"data":[{"instType":"SWAP","instId":"XMR-USDT-SWAP","last":"196.11","lastSz":"8","askPx":"196.11","askSz":"116","bidPx":"195.96","bidSz":"342","open24h":"197.31","high24h":"202.54","low24h":"189.85","sodUtc0":"196.66","sodUtc8":"199.56","volCcy24h":"65232.9","vol24h":"652329","ts":"1626995753264"}]}
1626995753.3376682: {"arg":{"channel":"tickers","instId":"AUCTION-USDT"},"data":[{"instType":"SPOT","instId":"AUCTION-USDT","last":"14.87","lastSz":"0.556412","askPx":"14.98","askSz":"2.665343","bidPx":"14.83","bidSz":"2.701428","open24h":"14.88","high24h":"15.43","low24h":"14.22","sodUtc0":"14.94","sodUtc8":"14.86","volCcy24h":"118038.064317","vol24h":"7944.656842","ts":"1626995748670"}]}
1626995753.3376908: {"arg":{"channel":"tickers","instId":"OKT-BTC"},"data":[{"instType":"SPOT","instId":"OKT-BTC","last":"0.001473","lastSz":"0.55833367","askPx":"0.001475","askSz":"10.856012","bidPx":"0.001471","bidSz":"6.77388851","open24h":"0.001402","high24h":"0.001489","low24h":"0.001387","sodUtc0":"0.001408","sodUtc8":"0.001437","volCcy24h":"17.16368064","vol24h":"12039.78807342","ts":"1626995748674"}]}
1626995753.337713: {"arg":{"channel":"tickers","instId":"PAY-BTC"},"data":[{"instType":"SPOT","instId":"PAY-BTC","last":"0.00000138","lastSz":"2351.35","askPx":"0.00000139","askSz":"4702.072","bidPx":"0.00000136","bidSz":"3602.183","open24h":"0.00000137","high24h":"0.00000144","low24h":"0.00000136","sodUtc0":"0.00000138","sodUtc8":"0.00000138","volCcy24h":"45.094","vol24h":"32746823.489","ts":"1626995751435"}]}
1626995753.337734: {"arg":{"channel":"tickers","instId":"BTC-USD-210924-42000-P"},"data":[{"instType":"OPTION","instId":"BTC-USD-210924-42000-P","last":"0.2075","lastSz":"0","askPx":"0.342","askSz":"5","bidPx":"0.3355","bidSz":"5","open24h":"0.2075","high24h":"0.2075","low24h":"0.2075","sodUtc0":"0.2075","sodUtc8":"0.2075","volCcy24h":"0","vol24h":"0","ts":"1626995703570"}]}
1626995753.337755: {"arg":{"channel":"tickers","instId":"ONT-USDT"},"data":[{"instType":"SPOT","instId":"ONT-USDT","last":"0.6217","lastSz":"1342.208542","askPx":"0.6218","askSz":"85","bidPx":"0.6214","bidSz":"57.871136","open24h":"0.608","high24h":"0.6314","low24h":"0.5967","sodUtc0":"0.6131","sodUtc8":"0.6275","volCcy24h":"9400150.288967","vol24h":"15292929.815123","ts":"1626995748886"}]}
1626995753.337777: {"arg":{"channel":"tickers","instId":"DHT-USDT"},"data":[{"instType":"SPOT","instId":"DHT-USDT","last":"0.757","lastSz":"73.639284","askPx":"0.759","askSz":"0.119353","bidPx":"0.751","bidSz":"116.167814","open24h":"0.751","high24h":"0.759","low24h":"0.749","sodUtc0":"0.753","sodUtc8":"0.756","volCcy24h":"108359.3236","vol24h":"143605.687017","ts":"1626995753013"}]}
1626995753.3377979: {"arg":{"channel":"tickers","instId":"TRX-USDT-210924"},"data":[{"instType":"FUTURES","instId":"TRX-USDT-210924","last":"0.0545","lastSz":"4","askPx":"0.05451","askSz":"16","bidPx":"0.05448","bidSz":"2","open24h":"0.05335","high24h":"0.05491","low24h":"0.05244","sodUtc0":"0.05345","sodUtc8":"0.05461","volCcy24h":"62464000","vol24h":"62464","ts":"1626995752469"}]}
1626995753.423179: {"arg":{"channel":"books-l2-tbt","instId":"BTC-USD-210924-42000-P"},"action":"snapshot","data":[{"asks":[["0.3415","5","0","1"],["0.342","300","0","1"],["0.3425","301","0","1"],["0.3445","305","0","1"]],"bids":[["0.335","5","0","1"],["0.3345","300","0","1"],["0.334","301","0","1"],["0.3295","305","0","1"],["0.0005","10","0","1"]],"ts":"1626995750044","checksum":-1431042442}]}
1626995753.424631: {"arg":{"channel":"books-l2-tbt","instId":"DHT-USDT"},"action":"snapshot","data":[{"asks":[["0.759","0.119353","0","1"],["0.772","9.972026","0","1"],["0.773","94.872165","0","2"],["0.779","19","0","1"],["0.78","99.812511","0","2"],["0.781","24.9928","0","2"],["0.79","40","0","1"],["0.796","16","0","1"],["0.798","119","0","2"],["0.8","174.323582","0","2"],["0.811","423.1407","0","1"],["0.812","4.327949","0","1"],["0.818","40","0","1"],["0.82","1.836154","0","1"],["0.849","4.327949","0","1"],["0.85","573.121161","0","2"],["0.867","57.631283","0","1"],["0.899","6.924719","0","1"],["0.9","117.940752","0","1"],["0.921","23.875746","0","1"],["0.949","8.6559","0","1"],["0.95","151.268389","0","2"],["0.955","10.992299","0","1"],["0.979","10.38708","0","1"],["0.98","400","0","1"],["0.992","11.077604","0","1"],["1","76.905311","0","1"],["1.05","1099.615871","0","1"],["1.055","1.988","0","1"],["1.057","1.988","0","1"],["1.06","1.988","0","1"],["1.14","59.412871","0","1"],["1.149","5.716","0","1"],["1.18","171.573206","0","1"],["1.2","152.442806","0","1"],["1.22","174.573205","0","2"],["1.274","11.766784","0","1"],["1.36","47.530296","0","1"],["1.409","3.665445","0","1"],["1.41","45.370488","0","1"],["1.446","49.95","0","1"],["1.45","366.842226","0","1"],["1.46","74.266088","0","1"],["1.5","2572.214542","0","5"],["1.55","499.5","0","1"],["1.579","46.922567","0","1"],["1.59","90.150946","0","2"],["1.6","1.9932","0","1"],["1.642","26.219881","0","2"],["1.65","1.4988","0","1"],["1.7","12.048072","0","2"],["1.706","44.222935","0","1"],["1.71","3098.140401","0","1"],["1.987","6","0","1"],["2","96.052664","0","1"],["2.087","16.623579","0","1"],["2.1","3","0","1"],["2.212","924.075","0","1"],["2.23","2456.370258","0","1"],["2.3","137.783553","0","1"],["2.338","595.832857","0","1"],["2.35","42.456647","0","1"],["2.381","5.698233","0","1"],["2.383","272.7816","0","1"],["2.44","14.445885","0","1"],["2.496","9.992","0","1"],["2.5","3","0","1"],["2.6","49.325199","0","1"],["2.8","34.863345","0","3"],["2.813","20","0","1"],["2.824","19","0","1"],["2.9","74.50696","0","2"],["2.98","22","0","1"],["2.984","36","0","1"],["3","707.802735","0","6"],["3.01","1.158715","0","1"],["3.099","49.95","0","1"],["3.1","4.984","0","1"],["3.14","1","0","1"],["3.15","25.109758","0","1"],["3.2","138.109552","0","2"],["3.298","33","0","1"],["3.3","139.835726","0","1"],["3.35","18.832319","0","1"],["3.38","2.4975","0","1"],["3.4","19.984","0","1"],["3.48","8.991","0","1"],["3.498","1.437054","0","1"],["3.5","17.384096","0","1"],["3.6","5.582564","0","1"],["3.607","1.4","0","1"],["3.65","233.44699","0","2"],["3.7","27.026945","0","2"],["3.718","1.35","0","1"],["3.78","120","0","2"],["3.8","248.811585","0","6"],["3.833","2.618","0","1"],["3.85","286.969407","0","1"],["3.9","30.462496","0","3"],["3.952","2.54","0","1"],["3.97","28.248479","0","1"],["3.98","26.1458","0","1"],["4","266.516534","0","9"],["4.03","6.198437","0","1"],["4.074","2.462","0","1"],["4.09","12.579128","0","1"],["4.18","24.9381","0","1"],["4.2","530.839745","0","3"],["4.201","2.6648","0","1"],["4.3","272.164687","0","2"],["4.33","2.318","0","1"],["4.4","208.4047","0","2"],["4.464","2.248","0","1"],["4.5","503.167353","0","5"],["4.501","1.3324","0","1"],["4.56","8","0","1"],["4.6","508.2417","0","2"],["4.602","1.09","0","1"],["4.64","528.912231","0","1"],["4.65","1159.774063","0","2"],["4.68","10.4715","0","1"],["4.744","2.115","0","1"],["4.79","3.592723","0","1"],["4.8","104.4118","0","4"],["4.88","32.3752","0","2"],["4.891","2.052","0","1"],["4.9","585.4322","0","5"],["4.95","2.2745","0","1"],["4.99","11.9446","0","1"],["5","3083.776219","0","12"],["5.1","3160.56275","0","2"],["5.159","402.122978","0","1"],["5.17","8","0","1"],["5.2","242.7479","0","4"],["5.25","34.972","0","1"],["5.4","14.0675","0","3"],["5.5","3.4965","0","2"],["5.6","14.822893","0","1"],["5.66","10","0","1"],["5.68","11.8938","0","1"],["5.79","149.88","0","1"],["5.8","3132.903051","0","2"],["5.831","31.5548","0","1"],["5.844","30","0","1"],["5.85","41.1313","0","1"],["5.87","8","0","1"],["5.88","34.236957","0","1"],["5.888","1","0","1"],["5.985","1.9883","0","1"],["6","1904.905403","0","9"],["6.198","24.975","0","1"],["6.32","6.125456","0","1"],["6.5","9.992","0","1"],["6.78","49.4","0","1"],["6.8","5","0","1"],["6.87","30","0","1"],["7","14.9796","0","1"],["7.1","219.0803","0","1"],["7.12","5","0","1"],["7.8","2.4725","0","1"],["7.96","40","0","1"],["8.088","5.897178","0","1"],["8.466","2.598582","0","1"],["8.8","141.1397","0","1"],["10.1","1","0","1"],["10.38","20","0","1"],["12.396","12.4875","0","1"],["12.89","49.4","0","1"],["15","6.2685","0","1"],["16","4.6789","0","1"],["17.1","4.083727","0","1"],["20","326.11088","0","1"],["22.89","42.3","0","1"],["24.792","6.24375","0","1"],["25","5","0","1"],["28","206.0802","0","1"],["49.584","3.121875","0","1"],["50","5","0","1"],["90","399.425846","0","1"],["100","4.5408","0","1"],["200","6.7941","0","2"]],"bids":[["0.751","116.167814","0","1"],["0.75","102.246666","0","1"],["0.746","8.03319","0","1"],["0.74","40","0","1"],["0.739","50.81723","0","1"],["0.736","40","0","1"],["0.735","894.347702","0","3"],["0.733","40","0","1"],["0.727","15.130674","0","1"],["0.726","117","0","2"],["0.719","20","0","1"],["0.718","61.977715","0","1"],["0.717","40","0","1"],["0.707","15.558699","0","1"],["0.706","207.963172","0","2"],["0.702","15.669516","0","1"],["0.7","131.883413","0","2"],["0.699","17.142857","0","1"],["0.668","16.467066","0","1"],["0.667","37.481259","0","1"],["0.666","20.430881","0","1"],["0.665","73.68421","0","1"],["0.601","18.302829","0","1"],["0.6","50","0","1"],["0.5","20","0","1"],["0.4","13","0","1"],["0.3","1","0","1"],["0.18","31.4062","0","1"],["0.1","1","0","1"],["0.052","19","0","1"],["0.011","530.4931","0","1"],["0.002","547.712571","0","1"],["0.001","5253.272318","0","3"]],"ts":"1626995753326","checksum":138080785}]}
1626995753.425534: {"arg":{"channel":"books-l2-tbt","instId":"FUN-BTC"},"action":"snapshot","data":[{"asks":[["0.000000455","142796.14","0","1"],["0.000000461","1134312.21","0","1"],["0.000000483","3988.29","0","1"],["0.000000487","579","0","1"],["0.000000489","22579.22","0","2"],["0.00000057","2167","0","2"],["0.000000658","30.04","0","1"],["0.000000659","3096.68","0","1"],["0.000000695","316.56","0","1"],["0.0000007","188.55","0","1"],["0.000000777","16989.8","0","1"],["0.000000797","144.22","0","1"],["0.000000798","162.13","0","1"],["0.000000812","2767.01","0","1"],["0.0000009","146.34","0","1"],["0.00000092","16077.14","0","1"],["0.00000094","76019.42","0","2"],["0.000001","3734.83","0","1"],["0.0000012","1997","0","1"],["0.000001205","298.26","0","1"],["0.00000122","64321.77","0","1"],["0.0000013","2000","0","1"],["0.00000149","250.47","0","1"],["0.000001591","7500","0","1"],["0.00000161","1010","0","1"],["0.000001675","148","0","1"],["0.00000169","4000","0","3"],["0.000001702","24317.49","0","1"],["0.00000179","4000","0","3"],["0.0000018","121.57","0","1"],["0.00000181","138.09","0","1"],["0.00000189","4000","0","3"],["0.00000197","207.14","0","1"],["0.00000199","4000","0","3"],["0.000002","2779.46","0","3"],["0.00000209","4103.58","0","4"],["0.0000021","10681.01","0","1"],["0.00000214","103.57","0","1"],["0.00000219","5000","0","3"],["0.00000221","291.8","0","1"],["0.00000228","1000","0","1"],["0.00000229","4000","0","2"],["0.00000239","4000","0","2"],["0.00000249","3000","0","1"],["0.00000259","3000","0","1"],["0.0000026","499","0","1"],["0.00000269","3000","0","1"],["0.00000279","4030.85","0","1"],["0.000003","15380.34","0","1"],["0.00000333","8675.02","0","1"],["0.00000379","268.11","0","1"],["0.0000039","7101.81","0","1"],["0.00000398","989.49","0","1"],["0.00000399","910.01","0","1"],["0.000004","11535.25","0","1"],["0.00000418","1000","0","1"],["0.00000429","1787.68","0","1"],["0.00000438","1000","0","1"],["0.00000447","122.46","0","1"],["0.00000458","1000","0","1"],["0.00000478","1000","0","1"],["0.0000048","17302.89","0","1"],["0.00000498","1000","0","1"],["0.000005","84125.29","0","3"],["0.00000518","1000","0","1"],["0.0000052","249.5","0","1"],["0.000005322","200","0","1"],["0.00000543","122.46","0","1"],["0.0000055","19970","0","1"],["0.00000569","29.74","0","1"],["0.000006","13063.11","0","1"],["0.0000062","447.38","0","1"],["0.0000063","8034.68","0","1"],["0.0000065","17302.89","0","1"],["0.00000668","0.48","0","1"],["0.00000678","2019.75","0","1"],["0.00000688","4031.6","0","2"],["0.00000698","1999.99","0","1"],["0.00000715","141.19","0","1"],["0.00000716","962.47","0","1"],["0.00000718","1743.36","0","1"],["0.00000719","2999.99","0","1"],["0.00000728","159.23","0","1"],["0.00000729","2999.99","0","1"],["0.00000735","76.7","0","1"],["0.00000739","2999.99","0","1"],["0.00000749","2999.99","0","1"],["0.0000075","1000","0","1"],["0.00000759","2999.99","0","1"],["0.00000769","2999.99","0","1"],["0.00000772","128.43","0","1"],["0.00000773","80.86","0","1"],["0.00000779","2999.99","0","1"],["0.00000789","2999.99","0","1"],["0.00000798","2999.99","0","1"],["0.000008","37000.07","0","1"],["0.00000809","2999.99","0","1"],["0.00000819","2999.99","0","1"],["0.0000082","37.56","0","1"],["0.00000829","2999.99","0","1"],["0.00000839","2999.99","0","1"],["0.00000849","3055.18631369","0","2"],["0.0000085","599.1","0","1"],["0.00000858","76.7","0","1"],["0.00000859","1808.34","0","1"],["0.000008655","200","0","1"],["0.00000893","29.9","0","1"],["0.00000899","2524.20972002","0","1"],["0.000009","249.5","0","1"],["0.00000902","80.86","0","1"],["0.00000926","128.43","0","1"],["0.00000934","40","0","1"],["0.0000098","76.7","0","1"],["0.00001","1009","0","1"],["0.0000103","80.87","0","1"],["0.0000108","128.43","0","1"],["0.00001099","70","0","1"],["0.00001199","1503.501608","0","1"],["0.00001229","1000","0","1"],["0.00001235","10","0","1"],["0.000012355","200","0","1"],["0.00001249","1500","0","1"],["0.00001269","1000","0","1"],["0.000012702","58.37","0","1"],["0.00001298","4999.99999999","0","1"],["0.00001319","1500","0","1"],["0.00001339","1500","0","1"],["0.0000135","20","0","1"],["0.00001359","1500","0","1"],["0.00001379","1500","0","1"],["0.00001399","1500","0","1"],["0.00001424","1100","0","1"],["0.00001429","2000","0","1"],["0.00001469","2000","0","1"],["0.00001498","2000","0","1"],["0.00001539","2500","0","1"],["0.00001569","2500","0","1"],["0.00001598","2500","0","1"],["0.00001632","66.79","0","1"],["0.00001639","2500","0","1"],["0.00001669","2500","0","1"],["0.00001698","2500","0","1"],["0.00001739","2500","0","1"],["0.00001769","3000","0","1"],["0.00001788","1500","0","1"],["0.00001798","3000","0","1"],["0.00001842","140","0","1"],["0.00001858","3000","0","1"],["0.000018655","200","0","1"],["0.00001958","5001.29992829","0","1"],["0.00001988","1500","0","1"],["0.00002188","2000","0","1"],["0.00002388","1500","0","1"],["0.00002449","89.22","0","1"],["0.0000252","2505","0","1"],["0.00002588","1500","0","1"],["0.00002788","1500","0","1"],["0.0000282","1220","0","1"],["0.00002988","1500","0","1"],["0.00003","29.44","0","1"],["0.00003188","1500","0","1"],["0.00003388","1500","0","1"],["0.00003674","80.3","0","1"],["0.00003888","1500","0","1"],["0.00004","5699.05","0","1"],["0.00004288","1500","0","1"],["0.00004788","1500","0","1"],["0.00005","21636.31","0","3"],["0.00005388","1500","0","1"],["0.00005512","72.27","0","1"],["0.00006","472.27","0","1"],["0.00006188","1500","0","1"],["0.00006988","1500","0","1"],["0.00007588","1500","0","1"],["0.0000777","865.12","0","1"],["0.00008","354.2","0","1"],["0.00008269","65.04","0","1"],["0.00008488","1500","0","1"],["0.00008956","100","0","1"],["0.00009388","2000","0","1"],["0.0001","1755.06","0","2"],["0.00010988","2858.27899963","0","1"],["0.00011111","100","0","1"],["0.00012404","58.54","0","1"],["0.0001356","190","0","1"],["0.00018607","52.68","0","1"],["0.0002","4823.86","0","2"],["0.000252","2505","0","1"],["0.00027911","47.42","0","1"],["0.0003","35.26","0","1"],["0.00041867","42.67","0","1"],["0.0005","199.24","0","1"],["0.00062801","38.41","0","1"],["0.0008","298.86","0","1"],["0.0009","525.005","0","2"],["0.001","447.79","0","3"],["0.0015","49","0","1"],["0.00189999","199.8","0","1"],["0.009","20","0","1"],["0.01237","63.58158319","0","1"],["0.05","10","0","1"],["0.09","20","0","1"],["0.1","51.92","0","2"],["0.5","50","0","1"],["0.8","10","0","1"],["0.9","20","0","1"],["1","2","0","1"],["10","0.999","0","1"]],"bids":[["0.000000452","141211.03","0","1"],["0.00000045","21957.39","0","1"],["0.000000446","1098553.58","0","1"],["0.000000402","6894.07","0","1"],["0.0000004","1000","0","1"],["0.00000035","20992.34","0","1"],["0.0000003","1000","0","1"],["0.000000075","3197.51","0","1"],["0.00000006","8888","0","1"],["0.000000011","932307.96","0","1"],["0.00000001","1000","0","1"],["0.000000008","31975.17","0","1"],["0.000000001","144946.13","0","1"]],"ts":"1626995751919","checksum":-1838897127}]}
1626995753.4263492: {"arg":{"channel":"books-l2-tbt","instId":"OKT-BTC"},"action":"snapshot","data":[{"asks":[["0.001475","10.622771","0","1"],["0.001476","0.62258414","0","1"],["0.00149","1.27582324","0","1"],["0.001491","0.4","0","1"],["0.001493","0.30706","0","1"],["0.001506","0.30706","0","1"],["0.001518","0.30706","0","1"],["0.00153","0.30706","0","1"],["0.001542","0.30706","0","1"],["0.00155","0.2","0","1"],["0.001555","0.26905546","0","1"],["0.001556","0.71","0","1"],["0.001557","7.9","0","4"],["0.001558","26.40939969","0","1"],["0.001567","0.30706","0","1"],["0.001578","0.59662349","0","1"],["0.001579","0.30706","0","1"],["0.001585","0.4","0","1"],["0.001591","0.30706","0","1"],["0.001604","0.30706","0","1"],["0.001616","0.30706","0","1"],["0.00162","0.6","0","1"],["0.001628","0.30706","0","1"],["0.00164","0.30706","0","1"],["0.001653","0.30706","0","1"],["0.00166","0.7","0","1"],["0.001665","0.30706","0","1"],["0.001677","0.30706","0","1"],["0.00168","0.06119159","0","1"],["0.001689","0.30706","0","1"],["0.0017","0.31225","0","1"],["0.001702","0.30706","0","1"],["0.001714","1.80706","0","2"],["0.001715","4.50145773","0","1"],["0.00172","0.398","0","1"],["0.001726","0.30706","0","1"],["0.00173","0.4","0","1"],["0.001738","0.30706","0","1"],["0.001749","3","0","2"],["0.00175","272.15353173","0","1"],["0.001751","0.30706","0","1"],["0.001763","0.30706","0","1"],["0.001775","0.30706","0","1"],["0.00178","0.6","0","1"],["0.001787","0.30706","0","1"],["0.001789","2.2","0","1"],["0.00179","314.00051436","0","1"],["0.001799","0.30706","0","1"],["0.00181","0.1","0","1"],["0.001812","0.30706","0","1"],["0.001824","0.30706","0","1"],["0.00183","0.4","0","1"],["0.001836","0.30706","0","1"],["0.001838","45","0","1"],["0.001848","0.30706","0","1"],["0.00185","0.1","0","1"],["0.001861","0.30706","0","1"],["0.001873","0.30706","0","1"],["0.00188","0.9","0","2"],["0.001885","0.30706","0","1"],["0.001897","0.30706","0","1"],["0.00191","0.30706","0","1"],["0.00192","0.1","0","1"],["0.001922","0.30706","0","1"],["0.00193","0.4","0","1"],["0.001934","0.30706","0","1"],["0.001946","0.30706","0","1"],["0.001959","0.30706","0","1"],["0.00196","0.1","0","1"],["0.001971","0.30706","0","1"],["0.001977","0.20459979","0","1"],["0.001983","0.30706","0","1"],["0.001995","0.30706","0","1"],["0.002","1.0968","0","2"],["0.002008","0.30706","0","1"],["0.00202","0.30706","0","1"],["0.002032","0.30706","0","1"],["0.002044","0.30706","0","1"],["0.002045","0.1","0","1"],["0.002057","0.30706","0","1"],["0.002069","164.20645982","0","2"],["0.002081","0.30706","0","1"],["0.002086","0.1","0","1"],["0.002093","0.30706","0","1"],["0.002106","0.30706","0","1"],["0.002118","0.30706","0","1"],["0.002128","0.1","0","1"],["0.00213","0.30706","0","1"],["0.002142","0.30706","0","1"],["0.002155","0.30706","0","1"],["0.002167","0.30706","0","1"],["0.002172","0.1","0","1"],["0.002179","0.30706","0","1"],["0.002188","0.05301611","0","1"],["0.002191","0.30706","0","1"],["0.0022","38","0","1"],["0.002204","0.30706","0","1"],["0.00221","2.50236545","0","1"],["0.002216","0.44706","0","2"],["0.002223","2.18244656","0","1"],["0.002228","0.30706","0","1"],["0.002236","1.48651658","0","1"],["0.00224","0.30706","0","1"],["0.002249","2.37229272","0","1"],["0.002253","0.30706","0","1"],["0.002261","0.1","0","1"],["0.002262","1.88695907","0","1"],["0.002265","0.30706","0","1"],["0.002275","1.96637765","0","1"],["0.002277","0.30706","0","1"],["0.002288","1.64551523","0","1"],["0.002289","0.30706","0","1"],["0.0023","69.30742512","0","2"],["0.002301","1.7028394","0","1"],["0.002302","0.30706","0","1"],["0.002307","0.1","0","1"],["0.002314","1.96949646","0","2"],["0.002326","0.30706","0","1"],["0.002338","0.30706","0","1"],["0.002351","0.30706","0","1"],["0.002354","0.1","0","1"],["0.002363","0.30706","0","1"],["0.002375","0.30706","0","1"],["0.002387","0.30706","0","1"],["0.0024","0.30706","0","1"],["0.002403","0.1","0","1"],["0.002444","0.86751574","0","1"],["0.002451","0.1","0","1"],["0.002501","0.1","0","1"],["0.002552","0.1","0","1"],["0.002604","0.1","0","1"],["0.002672","0.15","0","1"],["0.002712","0.15","0","1"],["0.002767","0.15","0","1"],["0.002799","3.62210093","0","1"],["0.002823","0.15","0","1"],["0.002881","0.15","0","1"],["0.00294","0.1","0","1"],["0.002985","671.74346453","0","1"],["0.003","2666.026","0","3"],["0.00306","0.1","0","1"],["0.0035","100","0","1"],["0.003539","2","0","1"],["0.0038","0.1","0","1"],["0.00385","812.06042875","0","1"],["0.0039","0.1","0","1"],["0.003981","61.22454221","0","1"],["0.003991","0.67809616","0","1"],["0.003995","66.34727908","0","1"],["0.004","318.75752627","0","4"],["0.004021","0.02596255","0","1"],["0.004048","0.60847751","0","1"],["0.0041","0.1","0","1"],["0.004163","0.450706","0","1"],["0.004187","0.450706","0","1"],["0.0042","37.09904","0","3"],["0.004212","0.450706","0","1"],["0.004236","0.450706","0","1"],["0.004261","0.450706","0","1"],["0.004285","0.450706","0","1"],["0.00431","0.450706","0","1"],["0.004334","0.450706","0","1"],["0.00435","2","0","1"],["0.004359","0.450706","0","1"],["0.004383","0.450706","0","1"],["0.0044","0.12953617","0","1"],["0.004408","0.450706","0","1"],["0.00442","39.968","0","1"],["0.004432","0.450706","0","1"],["0.004457","0.450706","0","1"],["0.004481","0.450706","0","1"],["0.004495","1","0","1"],["0.0045","100","0","1"],["0.004506","0.450706","0","1"],["0.00453","0.450706","0","1"],["0.004539","1","0","1"],["0.00455","0.02814647","0","1"],["0.004555","0.450706","0","1"],["0.004579","0.450706","0","1"],["0.004604","0.450706","0","1"],["0.004628","0.450706","0","1"],["0.004653","0.450706","0","1"],["0.004677","0.450706","0","1"],["0.004702","0.450706","0","1"],["0.004726","0.450706","0","1"],["0.004751","0.450706","0","1"],["0.004775","0.450706","0","1"],["0.004795","1","0","1"],["0.0048","10.460806","0","3"],["0.004848","0.680706","0","1"],["0.004897","0.680706","0","1"],["0.004946","0.680706","0","1"],["0.004963","0.38679629","0","1"],["0.004988","120.54639024","0","1"],["0.004995","0.680706","0","1"],["0.005","47.64450681","0","5"],["0.005044","0.680706","0","1"],["0.005093","0.680706","0","1"],["0.0051","130","0","2"],["0.005142","0.680706","0","1"],["0.005191","0.680706","0","1"],["0.0052","3.00000099","0","1"],["0.005233","220","0","1"],["0.00524","0.680706","0","1"],["0.005289","0.680706","0","1"],["0.005298","1","0","1"],["0.0053","80","0","1"],["0.005338","0.680706","0","1"],["0.005379","12.58365335","0","1"],["0.005387","0.680706","0","1"],["0.005395","1","0","1"],["0.0054","228.4","0","3"],["0.005436","0.680706","0","1"],["0.005485","0.680706","0","1"],["0.0055","1","0","1"],["0.005534","0.680706","0","1"],["0.005583","0.680706","0","1"],["0.0056","80","0","1"],["0.005632","0.680706","0","1"],["0.005681","0.680706","0","1"],["0.0057","140","0","1"],["0.00573","0.680706","0","1"],["0.005779","0.680706","0","1"],["0.0058","0.01563415","0","1"],["0.005828","0.680706","0","1"],["0.005877","0.680706","0","1"],["0.0059","158.4","0","2"],["0.005926","0.680706","0","1"],["0.005975","0.680706","0","1"],["0.006","150","0","2"],["0.006024","0.680706","0","1"],["0.006073","0.680706","0","1"],["0.006122","0.680706","0","1"],["0.006171","0.680706","0","1"],["0.0062","80","0","1"],["0.00622","0.680706","0","1"],["0.006269","0.680706","0","1"],["0.006295","477.18084737","0","1"],["0.0063","126.63964798","0","2"],["0.006318","0.680706","0","1"],["0.006367","0.680706","0","1"],["0.0064","78.4","0","1"],["0.006416","0.680706","0","1"],["0.006465","0.680706","0","1"],["0.006479","26.4268789","0","1"],["0.0065","80","0","1"],["0.006514","0.680706","0","1"],["0.006563","0.680706","0","1"],["0.0066","126.45607102","0","1"],["0.006612","0.680706","0","1"],["0.006661","0.680706","0","1"],["0.00671","0.680706","0","1"],["0.006759","0.680706","0","1"],["0.0068","67.66202129","0","1"],["0.006808","0.680706","0","1"],["0.00682","0.2","0","1"],["0.006857","0.680706","0","1"],["0.0069","78.4","0","1"],["0.006906","0.680706","0","1"],["0.006955","0.680706","0","1"],["0.007","0.15179296","0","1"],["0.007004","0.680706","0","1"],["0.007053","0.680706","0","1"],["0.007102","0.680706","0","1"],["0.007151","0.680706","0","1"],["0.007199","0.680706","0","1"],["0.007248","0.680706","0","1"],["0.007297","0.680706","0","1"],["0.007346","0.680706","0","1"],["0.007395","0.680706","0","1"],["0.0074","78.4","0","1"],["0.00744","0.2","0","1"],["0.007444","0.680706","0","1"],["0.007493","0.680706","0","1"],["0.0075","10","0","1"],["0.007542","0.680706","0","1"],["0.007591","0.680706","0","1"],["0.00764","0.680706","0","1"],["0.007689","0.680706","0","1"],["0.007738","0.680706","0","1"],["0.007787","0.680706","0","1"],["0.007836","0.680706","0","1"],["0.007885","0.680706","0","1"],["0.0079","78.11975209","0","1"],["0.007934","0.680706","0","1"],["0.007983","0.680706","0","1"],["0.008","0.01781731","0","1"],["0.008032","0.680706","0","1"],["0.00806","0.2","0","1"],["0.008081","0.680706","0","1"],["0.00813","0.680706","0","1"],["0.008179","0.680706","0","1"],["0.008228","0.680706","0","1"],["0.008277","0.680706","0","1"],["0.008326","0.680706","0","1"],["0.008375","0.680706","0","1"],["0.008424","0.680706","0","1"],["0.008473","0.680706","0","1"],["0.008522","0.680706","0","1"],["0.008571","0.680706","0","1"],["0.00862","0.680706","0","1"],["0.008669","0.680706","0","1"],["0.008718","0.680706","0","1"],["0.008767","0.680706","0","1"],["0.008816","0.680706","0","1"],["0.008865","0.680706","0","1"],["0.008914","0.680706","0","1"],["0.008963","0.680706","0","1"],["0.009","100","0","1"],["0.009012","0.680706","0","1"],["0.009061","0.680706","0","1"],["0.00911","0.680706","0","1"],["0.009159","0.680706","0","1"],["0.009208","0.680706","0","1"],["0.009257","0.680706","0","1"],["0.009306","0.680706","0","1"],["0.009355","0.680706","0","1"],["0.009404","0.680706","0","1"],["0.009453","0.680706","0","1"],["0.009502","0.680706","0","1"],["0.009551","0.680706","0","1"],["0.0096","0.680706","0","1"],["0.01","40.61524029","0","2"],["0.04399","0.01136621","0","1"],["0.069999","4.20251164","0","1"],["0.1","0.07589161","0","1"],["0.2","86.17079819","0","1"],["1","517.98891555","0","2"]],"bids":[["0.001471","2.89090055","0","2"],["0.00147","46.260578","0","7"],["0.001469","0.30706","0","1"],["0.001458","1.25956052","0","1"],["0.001457","0.30706","0","1"],["0.00145","9.3419931","0","2"],["0.001449","17.08040896","0","1"],["0.001445","2.5","0","1"],["0.001444","0.30706","0","1"],["0.001432","0.30706","0","1"],["0.001422","0.8","0","1"],["0.00142","0.30706","0","1"],["0.001414","0.19726082","0","1"],["0.001408","0.30706","0","1"],["0.001399","2.37","0","1"],["0.001395","0.30706","0","1"],["0.001384","2.47","0","1"],["0.001383","0.30706","0","1"],["0.001371","0.30706","0","1"],["0.001359","0.30706","0","1"],["0.00135","0.01005","0","1"],["0.001346","0.30706","0","1"],["0.001334","0.00000494","0","1"],["0.00133","0.01005","0","1"],["0.001322","0.30706","0","1"],["0.001321","5.72","0","3"],["0.00132","50.01005","0","2"],["0.00131","0.31711","0","2"],["0.001308","2.62","0","1"],["0.001306","3","0","2"],["0.001305","20.78988504","0","3"],["0.001304","2300.6134","0","1"],["0.001303","0.11","0","1"],["0.0013","1.01005","0","2"],["0.001297","0.30706","0","1"],["0.00129","0.01005","0","1"],["0.001285","0.30706","0","1"],["0.00128","0.01005","0","1"],["0.001279","0.11","0","1"],["0.001273","0.30706","0","1"],["0.00127","0.01005","0","1"],["0.001261","0.30706","0","1"],["0.00126","50.01005","0","2"],["0.001253","0.11","0","1"],["0.00125","51.61005","0","3"],["0.001248","0.30706","0","1"],["0.001239","50.3783293","0","2"],["0.001236","0.30706","0","1"],["0.00123","0.01005","0","1"],["0.001228","0.11","0","1"],["0.001226","50","0","1"],["0.001224","50.30706","0","2"],["0.001218","150","0","2"],["0.001212","0.30706","0","1"],["0.00121","50.01005","0","2"],["0.001203","0.11","0","1"],["0.0012","0.31711","0","2"],["0.00118","0.01005","0","1"],["0.00115","122.40961917","0","1"],["0.001101","22.74383869","0","1"],["0.00105","35.00271224","0","1"],["0.00102","0.1002","0","1"],["0.001001","1.67168628","0","1"],["0.001","143.84773001","0","5"],["0.00098","0.1005","0","1"],["0.00095","0.1005","0","1"],["0.0009","0.80013333","0","2"],["0.00085","0.1005","0","1"],["0.00083","0.1005","0","1"],["0.0008","0.1005","0","1"],["0.00075","0.1005","0","1"],["0.00074","5.12721848","0","2"],["0.000736","3.17196316","0","1"],["0.000733","0.68212824","0","1"],["0.000732","1.88028892","0","1"],["0.00073","0.1005","0","1"],["0.000728","2.29045259","0","1"],["0.000724","1.35950493","0","1"],["0.00072","1.89178797","0","2"],["0.000716","2.90012083","0","1"],["0.000712","1.25089384","0","1"],["0.000708","1.87767413","0","1"],["0.000512","1000","0","1"],["0.0005","156.94986","0","1"],["0.000105","2.29176579","0","1"],["0.000011","22.91765796","0","1"],["0.000001","1429.17657965","0","2"]],"ts":"1626995753092","checksum":-1995831529}]}
1626995753.557348: {"arg":{"channel":"books-l2-tbt","instId":"ONT-USDT"},"action":"snapshot","data":[{"asks":[["0.6218","85","0","1"],["0.6219","945.539","0","1"],["0.622","688.337776","0","2"],["0.6221","390","0","1"],["0.6224","2372.871384","0","3"],["0.6226","486.341898","0","1"],["0.6227","1223.318397","0","1"],["0.6229","760","0","1"],["0.6231","1223.318397","0","1"],["0.6232","730","0","1"],["0.6234","4129","0","1"],["0.6235","2500","0","1"],["0.6236","41469.813384","0","2"],["0.6243","6082.524409","0","1"],["0.6244","88","0","1"],["0.6246","737.184763","0","1"],["0.6247","19.442644","0","1"],["0.6252","9873","0","1"],["0.6262","94","0","1"],["0.6279","84.995997","0","1"],["0.628","15.714644","0","1"],["0.6282","47","0","1"],["0.6299","115","0","1"],["0.6314","290.063032","0","2"],["0.6325","62.894","0","1"],["0.635","1.09934","0","1"],["0.6359","15.714644","0","1"],["0.6393","240","0","1"],["0.6399","82","0","1"],["0.64","451","0","2"],["0.6425","318.75084","0","1"],["0.644","15.714644","0","1"],["0.645","1.467569","0","1"],["0.646","1.467569","0","1"],["0.6471","240","0","1"],["0.6488","40","0","1"],["0.65","143.347971","0","1"],["0.6522","15.714644","0","1"],["0.6549","7.093992","0","1"],["0.655","240","0","1"],["0.658","3.117219","0","1"],["0.66","2.9982","0","1"],["0.6604","15.714644","0","1"],["0.6629","240","0","1"],["0.6665","129","0","2"],["0.6666","3006.1952","0","1"],["0.667","57.397","0","1"],["0.6687","15.714644","0","1"],["0.67","124.93381","0","2"],["0.6707","240","0","1"],["0.6728","7.093992","0","1"],["0.6729","119514.920019","0","1"],["0.6771","15.714644","0","1"],["0.6786","240","0","1"],["0.68","9","0","1"],["0.6808","74.2717","0","1"],["0.6832","74.0077","0","1"],["0.6856","73.745572","0","1"],["0.6858","15.714644","0","1"],["0.6859","298.606083","0","1"],["0.6865","240","0","1"],["0.6888","40","0","1"],["0.6899","11.350387","0","1"],["0.69","401.272743","0","2"],["0.693","50","0","1"],["0.6943","240","0","1"],["0.6944","15.714644","0","1"],["0.6979","139.969658","0","1"],["0.699","9","0","1"],["0.6999","9","0","1"],["0.7","19","0","2"],["0.701","292.178166","0","2"],["0.7022","240","0","1"],["0.7032","15.714644","0","1"],["0.706","326.105624","0","1"],["0.7061","10.5","0","1"],["0.71","19","0","2"],["0.7101","240","0","1"],["0.7106","14.187984","0","1"],["0.7107","4261.566","0","1"],["0.712","73.649844","0","2"],["0.7122","10.5","0","1"],["0.7164","285.888613","0","1"],["0.7179","240","0","1"],["0.7183","10.5","0","1"],["0.72","1135.924651","0","4"],["0.7211","15.714644","0","1"],["0.7244","10.5","0","1"],["0.7258","240","0","1"],["0.729","20","0","1"],["0.73","9","0","1"],["0.7302","15.714644","0","1"],["0.7304","53.653","0","1"],["0.7306","10.5","0","1"],["0.7337","240","0","1"],["0.736","52","0","1"],["0.7367","10.5","0","1"],["0.7394","15.714644","0","1"],["0.74","9","0","1"],["0.7415","240","0","1"],["0.7428","10.5","0","1"],["0.7431","14.129789","0","1"],["0.7482","273.712774","0","1"],["0.7488","15.714644","0","1"],["0.7489","10.5","0","1"],["0.7494","240","0","1"],["0.7499","17.025581","0","1"],["0.75","7801","0","3"],["0.7551","10.5","0","1"],["0.7573","240","0","1"],["0.7582","15.714644","0","1"],["0.76","879.281487","0","2"],["0.7612","10.5","0","1"],["0.763","53.9364","0","1"],["0.7647","267.820719","0","1"],["0.7651","240","0","1"],["0.7673","10.5","0","1"],["0.7678","44.350747","0","2"],["0.77","188.892","0","2"],["0.773","240","0","1"],["0.7734","10.5","0","1"],["0.7776","15.714644","0","1"],["0.779","1840.278777","0","1"],["0.7795","10.5","0","1"],["0.78","2249.849361","0","4"],["0.7808","240","0","1"],["0.7815","262.055498","0","1"],["0.7857","10.5","0","1"],["0.7873","15.714644","0","1"],["0.7878","48.152","0","1"],["0.7887","240","0","1"],["0.79","22.923098","0","2"],["0.7918","10.5","0","1"],["0.7966","240","0","1"],["0.7974","15.714644","0","1"],["0.7979","10.5","0","1"],["0.7987","256.414381","0","1"],["0.799","9","0","1"],["0.7999","9","0","1"],["0.8","255.320382","0","4"],["0.804","10.5","0","1"],["0.8044","240","0","1"],["0.8074","15.714644","0","1"],["0.81","9","0","1"],["0.8102","10.5","0","1"],["0.8123","240","0","1"],["0.8163","261.394698","0","2"],["0.8176","15.714644","0","1"],["0.82","9","0","1"],["0.8202","240","0","1"],["0.8224","10.5","0","1"],["0.8259","29.904178","0","1"],["0.8279","15.714644","0","1"],["0.828","240","0","1"],["0.8285","10.5","0","1"],["0.83","655.445796","0","2"],["0.8342","245.493833","0","1"],["0.8346","10.5","0","1"],["0.8359","240","0","1"],["0.8385","15.714644","0","1"],["0.84","188","0","2"],["0.8408","10.5","0","1"],["0.8438","240","0","1"],["0.8469","10.5","0","1"],["0.849","15.714644","0","1"],["0.85","288.483036","0","4"],["0.8516","240","0","1"],["0.8527","240.20923","0","1"],["0.853","10.5","0","1"],["0.8591","10.5","0","1"],["0.8595","240","0","1"],["0.8598","15.714644","0","1"],["0.86","11","0","2"],["0.8628","8","0","1"],["0.8653","10.5","0","1"],["0.8674","240","0","1"],["0.87","524.329666","0","4"],["0.8706","15.714644","0","1"],["0.8714","245.538386","0","2"],["0.872","4","0","2"],["0.873","4","0","2"],["0.8738","2","0","1"],["0.8739","21.263645","0","3"],["0.874","4","0","2"],["0.8741","2","0","1"],["0.8742","2","0","1"],["0.8752","240","0","1"],["0.8775","10.5","0","1"],["0.8776","17.190402","0","1"],["0.88","9","0","1"],["0.8816","15.714644","0","1"],["0.8831","240","0","1"],["0.8836","10.5","0","1"],["0.8856","41.952","0","1"],["0.889","125.030333","0","1"],["0.8897","10.5","0","1"],["0.89","9","0","1"],["0.891","240","0","1"],["0.8924","16.903539","0","1"],["0.8928","15.714644","0","1"],["0.8959","10.5","0","1"],["0.8961","16.833314","0","1"],["0.8988","240","0","1"],["0.899","9","0","1"],["0.8999","629.13745","0","2"],["0.9","1721.571714","0","6"],["0.902","10.5","0","1"],["0.904","15.714644","0","1"],["0.9067","240","0","1"],["0.9072","16.626094","0","1"],["0.9081","10.5","0","1"],["0.91","9","0","1"],["0.9101","225.02823","0","1"],["0.9109","16.558151","0","1"],["0.9142","10.5","0","1"],["0.9146","256.49076","0","2"],["0.9155","15.714644","0","1"],["0.9194","99.94","0","1"],["0.92","63.394327","0","2"],["0.9204","10.5","0","1"],["0.922","8.832289","0","1"],["0.9224","240","0","1"],["0.9265","10.5","0","1"],["0.927","15.714644","0","1"],["0.93","5.929702","0","1"],["0.9302","220.184178","0","1"],["0.9303","240","0","1"],["0.9326","10.5","0","1"],["0.9382","240","0","1"],["0.9387","10.5","0","1"],["0.9388","15.714644","0","1"],["0.94","2.964851","0","1"],["0.9448","10.5","0","1"],["0.946","240","0","1"],["0.949","2.964852","0","1"],["0.95","30.469896","0","2"],["0.9507","231.159045","0","2"],["0.951","10.5","0","1"],["0.9539","240","0","1"],["0.9555","727.767316","0","1"],["0.9571","10.5","0","1"],["0.9581","110.832921","0","1"],["0.959","15.722862","0","1"],["0.96","2320.192948","0","2"],["0.9617","240","0","1"],["0.9627","31.376731","0","2"],["0.9632","10.5","0","1"],["0.9664","15.601779","0","1"],["0.9693","10.5","0","1"],["0.9696","240","0","1"],["0.9701","15.541934","0","1"],["0.9716","210.806655","0","1"],["0.972","31.167879","0","1"],["0.9738","15.482545","0","1"],["0.974","31.103215","0","1"],["0.9748","15.714644","0","1"],["0.9755","10.5","0","1"],["0.976","31.038819","0","1"],["0.9775","255.42361","0","2"],["0.978","30.974689","0","1"],["0.98","2290.532259","0","2"],["0.9812","15.365121","0","1"],["0.9816","10.5","0","1"],["0.982","1030.847221","0","2"],["0.9849","15.307075","0","1"],["0.9853","240","0","1"],["0.9872","15.714644","0","1"],["0.9877","10.5","0","1"],["0.9886","15.249465","0","1"],["0.9893","1.01431","0","1"],["0.99","2018.764","0","2"],["0.9903","1.013281","0","1"],["0.9913","1.012255","0","1"],["0.9923","16.203517","0","2"],["0.9932","240","0","1"],["0.9933","1.010208","0","1"],["0.9938","10.5","0","1"],["0.9943","1.009189","0","1"],["0.9953","1.00817","0","1"],["0.9955","1000","0","1"],["0.996","15.135536","0","1"],["0.9963","1.007154","0","1"],["0.9973","1.00614","0","1"],["0.9983","20.843205","0","2"],["0.9993","20.822263","0","2"],["0.9997","30.793852","0","2"],["1","5310.180121","0","11"],["1.0003","20.801362","0","2"],["1.0005","40.093","0","1"],["1.0011","240","0","1"],["1.0013","20.780505","0","2"],["1.0023","19.758588","0","1"],["1.0033","19.738816","0","1"],["1.0034","15.023298","0","1"],["1.0043","19.719083","0","1"],["1.0053","19.69939","0","1"],["1.0061","10.5","0","1"],["1.0063","19.679736","0","1"],["1.0071","14.967801","0","1"],["1.0073","19.66012","0","1"],["1.008","220.207873","0","1"],["1.0083","19.640545","0","1"],["1.0089","240","0","1"],["1.0093","19.621008","0","1"],["1.0103","19.60151","0","1"],["1.0108","14.912712","0","1"],["1.0113","19.58205","0","1"],["1.0122","10.5","0","1"],["1.0123","19.562629","0","1"],["1.0133","19.543247","0","1"],["1.0143","19.523903","0","1"],["1.0145","14.858027","0","1"],["1.0148","201.828515","0","1"],["1.0153","19.504597","0","1"],["1.0163","19.485329","0","1"],["1.0168","240","0","1"],["1.0173","19.4661","0","1"],["1.0182","14.803742","0","1"],["1.0183","29.946908","0","2"],["1.0188","1000","0","1"],["1.0193","19.427755","0","1"],["1.02","6052.113449","0","3"],["1.0203","19.408638","0","1"],["1.021","13.116141","0","1"],["1.0213","19.38956","0","1"],["1.0219","14.749852","0","1"],["1.0223","39.358518","0","2"],["1.0233","19.351515","0","1"],["1.0243","19.332548","0","1"],["1.0244","10.5","0","1"],["1.0247","240","0","1"],["1.0253","19.313619","0","1"],["1.0263","19.294727","0","1"],["1.0273","19.275871","0","1"],["1.0283","19.257052","0","1"],["1.0293","19.238271","0","1"],["1.0303","0.000006","0","1"],["1.0306","10.5","0","1"],["1.0313","19.200817","0","1"],["1.0323","19.182144","0","1"],["1.0325","240","0","1"],["1.0333","19.163508","0","1"],["1.0343","19.144909","0","1"],["1.0353","19.126345","0","1"],["1.0363","19.107817","0","1"],["1.0367","10.5","0","1"],["1.0373","19.089324","0","1"],["1.0383","19.070868","0","1"],["1.0393","19.052447","0","1"],["1.0403","19.034062","0","1"],["1.0404","240","0","1"],["1.0413","19.015713","0","1"],["1.0423","18.997398","0","1"],["1.0428","10.5","0","1"],["1.0433","18.979119","0","1"],["1.0443","18.960876","0","1"],["1.0453","18.942667","0","1"],["1.0456","123.562149","0","1"],["1.0463","18.924493","0","1"],["1.0473","18.906354","0","1"],["1.0483","258.88825","0","2"],["1.0489","10.5","0","1"],["1.0493","18.87018","0","1"],["1.0503","18.852144","0","1"],["1.0513","18.834144","0","1"],["1.0523","18.816178","0","1"],["1.0533","18.798246","0","1"],["1.0551","10.5","0","1"],["1.0561","240","0","1"],["1.0599","193.23275","0","1"],["1.0612","10.5","0","1"],["1.0633","35.296","0","1"],["1.064","240","0","1"],["1.0673","10.5","0","1"],["1.07","380.10826","0","1"],["1.071","19.988","0","1"],["1.0719","240","0","1"],["1.0734","10.5","0","1"],["1.0795","10.5","0","1"],["1.0797","240","0","1"],["1.08","100.4397","0","1"],["1.0832","189.07314","0","1"],["1.0857","10.5","0","1"],["1.0876","240","0","1"],["1.0918","10.5","0","1"],["1.0955","240","0","1"],["1.0979","10.5","0","1"],["1.1","7259.853725","0","4"],["1.1033","240","0","1"],["1.104","10.5","0","1"],["1.107","185.003073","0","1"],["1.1102","10.5","0","1"],["1.1112","240","0","1"],["1.1141","1.494","0","1"],["1.1163","10.5","0","1"],["1.1191","240","0","1"],["1.1196","19.988","0","1"],["1.1224","10.5","0","1"],["1.1269","240","0","1"],["1.1285","10.5","0","1"]],"bids":[["0.6214","57.871136","0","2"],["0.6213","830","0","1"],["0.6212","1025.906209","0","2"],["0.6211","371","0","2"],["0.621","630","0","1"],["0.6207","900","0","1"],["0.6205","9537.626","0","1"],["0.6204","1115.5","0","2"],["0.6203","486.341898","0","1"],["0.6202","1223.318397","0","1"],["0.62","1044.868423","0","2"],["0.6199","390","0","1"],["0.6195","47","0","1"],["0.6194","1970","0","1"],["0.6193","24","0","1"],["0.6192","884.813384","0","1"],["0.619","94","0","1"],["0.6189","6082.857203","0","1"],["0.6188","47","0","1"],["0.6187","6717","0","3"],["0.6185","47","0","1"],["0.6183","47","0","1"],["0.6181","47","0","1"],["0.6176","82","0","1"],["0.6175","41323.433198","0","4"],["0.6174","1165.02235","0","1"],["0.6173","165","0","1"],["0.6171","47","0","1"],["0.6163","82","0","1"],["0.6162","608.986662","0","1"],["0.616","1652.276975","0","2"],["0.6157","240","0","1"],["0.6151","82","0","1"],["0.6149","95","0","1"],["0.6144","3200","0","1"],["0.6143","82","0","1"],["0.6139","64","0","1"],["0.6134","82","0","1"],["0.6132","260.464761","0","1"],["0.6131","167.443291","0","2"],["0.613","19576","0","1"],["0.6124","50","0","1"],["0.6113","15.714644","0","1"],["0.6098","207.065","0","1"],["0.6097","2189.088092","0","1"],["0.6086","328.617767","0","1"],["0.6083","2338.546157","0","2"],["0.6078","240","0","1"],["0.6073","4053","0","1"],["0.607","7965","0","1"],["0.6036","15.714644","0","1"],["0.6001","100399.631531","0","1"],["0.6","415.959333","0","3"],["0.5979","4095.44214","0","2"],["0.5961","15.714644","0","1"],["0.59","60","0","1"],["0.5899","294.695711","0","1"],["0.5886","15.714644","0","1"],["0.5813","15.714644","0","1"],["0.58","1002","0","1"],["0.574","15.714644","0","1"],["0.5701","19.294861","0","1"],["0.57","1706.0396","0","1"],["0.5669","15.714644","0","1"],["0.5598","15.714644","0","1"],["0.5528","15.714644","0","1"],["0.5502","36.350418","0","1"],["0.5501","19.996364","0","1"],["0.55","6773.972162","0","3"],["0.5488","2000","0","1"],["0.5459","15.714644","0","1"],["0.5433","500","0","1"],["0.542","500","0","1"],["0.54","1000","0","1"],["0.5391","15.714644","0","1"],["0.5324","15.714644","0","1"],["0.53","100","0","1"],["0.5282","75.728891","0","1"],["0.5281","20.829388","0","1"],["0.528","1893.939393","0","1"],["0.5257","15.714644","0","1"],["0.5218","530.742985","0","1"],["0.52","489.230949","0","5"],["0.5192","15.714644","0","1"],["0.5188","300","0","1"],["0.515","575.79165","0","1"],["0.514","73.929961","0","1"],["0.5127","15.714644","0","1"],["0.511","19.569471","0","1"],["0.5109","300.6","0","1"],["0.5102","117.600941","0","1"],["0.5101","39.207998","0","1"],["0.51","2609.646765","0","8"],["0.509","491.713507","0","1"],["0.5063","15.714644","0","1"],["0.501","1000","0","1"],["0.5008","200","0","1"],["0.5","14611.778222","0","21"],["0.4999","50","0","1"],["0.4824","100","0","1"],["0.4666","4.767038","0","1"],["0.46","200","0","1"],["0.4536","6.326818","0","1"],["0.453","1021.530022","0","1"],["0.4501","66.651855","0","1"],["0.45","16224.888244","0","10"],["0.44","700.217903","0","3"],["0.4361","96.728836","0","1"],["0.43","421.034","0","1"],["0.42","727.395007","0","1"],["0.4188","500","0","1"],["0.411","600","0","1"],["0.41","65","0","1"],["0.4001","10012.84355","0","1"],["0.4","1803.857068","0","12"],["0.386","401","0","1"],["0.3858","735.859253","0","1"],["0.3855","1","0","1"],["0.38","697.368421","0","2"],["0.3622","1","0","1"],["0.3536","8.116078","0","1"],["0.3535","2015.67099","0","1"],["0.351","1747.376942","0","3"],["0.35","1261.465809","0","7"],["0.34","373.528764","0","2"],["0.3377","1000","0","1"],["0.3188","500","0","1"],["0.3126","10","0","1"],["0.3","13858.335728","0","5"],["0.2999","895.447364","0","1"],["0.283","14.197261","0","1"],["0.28","500","0","1"],["0.2777","601.681121","0","1"],["0.25","1000","0","1"],["0.232","7960","0","1"],["0.23","50","0","1"],["0.2188","500","0","1"],["0.2103","100","0","1"],["0.21","6680.613","0","2"],["0.2077","1526.226506","0","1"],["0.2075","1527.697108","0","1"],["0.2","2352.351696","0","6"],["0.1994","786.830675","0","1"],["0.189","519.501556","0","1"],["0.16","1","0","1"],["0.15","368.351696","0","2"],["0.1128","5004","0","1"],["0.1098","30.593","0","1"],["0.1","2361.582633","0","3"],["0.0589","500","0","1"],["0.0442","113.122","0","1"],["0.0221","226.244","0","1"],["0.0111","450.45","0","1"],["0.011","305.932","0","1"],["0.0055","909.09","0","1"],["0.0012","16666.666666","0","1"],["0.0011","3059.323","0","1"],["0.0003","3000","0","1"],["0.0002","16000","0","4"],["0.0001","61134","0","5"]],"ts":"1626995753368","checksum":216354575}]}
1626995753.559285: {"arg":{"channel":"books-l2-tbt","instId":"AUCTION-USDT"},"action":"snapshot","data":[{"asks":[["14.98","2.665343","0","2"],["15","17.022485","0","4"],["15.01","163.804417","0","4"],["15.02","18.4","0","4"],["15.05","0.1284","0","1"],["15.12","1.268257","0","1"],["15.13","3.562783","0","3"],["15.19","1.5","0","1"],["15.2","4.517549","0","1"],["15.22","0.126947","0","1"],["15.23","2.848458","0","1"],["15.3","1.84252","0","1"],["15.32","3.6","0","1"],["15.33","8","0","1"],["15.4","0.125443","0","1"],["15.43","0.437444","0","1"],["15.5","3","0","1"],["15.53","8","0","1"],["15.54","8.8","0","1"],["15.58","0.124056","0","1"],["15.63","2.957633","0","1"],["15.73","9.51426","0","2"],["15.74","1.019102","0","1"],["15.77","0.122541","0","1"],["15.79","1.836097","0","1"],["15.84","8","0","1"],["15.87","4.672748","0","2"],["15.9","44.52004","0","1"],["15.94","5.33819","0","1"],["15.95","1.93985","0","2"],["16.01","2.419085","0","1"],["16.03","1.809571","0","1"],["16.04","8","0","1"],["16.11","1.800523","0","1"],["16.13","0.11977","0","1"],["16.14","8","0","1"],["16.15","1.303807","0","1"],["16.19","1.791565","0","1"],["16.22","0.69958","0","1"],["16.24","8","0","1"],["16.27","1.782696","0","1"],["16.29","6.111792","0","1"],["16.33","0.118357","0","1"],["16.34","8","0","1"],["16.35","1.773914","0","1"],["16.36","8.8","0","1"],["16.43","6.739543","0","1"],["16.44","8.85369","0","2"],["16.52","1.872515","0","2"],["16.55","8","0","1"],["16.57","8.080703","0","1"],["16.6","1.747021","0","1"],["16.65","8","0","1"],["16.68","1.738586","0","1"],["16.71","7.60981","0","2"],["16.75","8","0","1"],["16.77","1.729194","0","1"],["16.85","9.72093","0","2"],["16.86","5.336227","0","1"],["16.88","8.945059","0","1"],["16.9","0.114313","0","1"],["16.93","1.712745","0","1"],["16.95","8","0","1"],["17.02","1.297335","0","1"],["17.05","8","0","1"],["17.1","1.695607","0","1"],["17.11","0.112958","0","1"],["17.15","8","0","1"],["17.18","8.8","0","1"],["17.19","1.686673","0","1"],["17.26","1.747574","0","1"],["17.28","1.678809","0","1"],["17.3","0.111701","0","1"],["17.36","8","0","1"],["17.37","1.67005","0","1"],["17.45","1.662341","0","1"],["17.46","8","0","1"],["17.51","0.110344","0","1"],["17.54","1.653752","0","1"],["17.56","8","0","1"],["17.63","1.645252","0","1"],["17.66","8","0","1"],["17.72","1.636839","0","1"],["17.73","0.109019","0","1"],["17.76","8","0","1"],["17.81","1.628511","0","1"],["17.86","5.536395","0","1"],["17.88","8.945059","0","1"],["17.89","1.62118","0","1"],["17.94","0.107725","0","1"],["17.97","8","0","1"],["17.98","0.78358","0","1"],["18","40.709671","0","2"],["18.07","9.604923","0","2"],["18.15","0.106462","0","1"],["18.16","1.596916","0","1"],["18.17","8","0","1"],["18.25","1.588989","0","1"],["18.27","8","0","1"],["18.34","1.58114","0","1"],["18.37","8","0","1"],["18.44","1.572509","0","1"],["18.47","8","0","1"],["18.53","1.564822","0","1"],["18.57","8","0","1"],["18.62","1.557209","0","1"],["18.68","12.4973","0","2"],["18.7","5.995159","0","1"],["18.72","1.54967","0","1"],["18.78","8","0","1"],["18.82","1.541379","0","1"],["18.88","8","0","1"],["18.91","1.533992","0","1"],["18.98","8","0","1"],["19","1.526676","0","1"],["19.08","8","0","1"],["19.1","1.518628","0","1"],["19.18","8","0","1"],["19.19","0.126591","0","1"],["19.28","12","0","2"],["19.29","1.503568","0","1"],["19.38","1.496539","0","1"],["19.39","8","0","1"],["19.43","6.24625","0","1"],["19.48","1.488804","0","1"],["19.49","8","0","1"],["19.5","0.608276","0","1"],["19.58","1.48115","0","1"],["19.59","8","0","1"],["19.68","1.473574","0","1"],["19.69","8","0","1"],["19.77","1.466821","0","1"],["19.79","8","0","1"],["19.87","1.45939","0","1"],["19.89","8","0","1"],["19.9","7.578958","0","1"],["19.97","1.452035","0","1"],["20","123.611849","0","8"],["20.07","1.444753","0","1"],["20.18","1.437543","0","1"],["20.28","1.430405","0","1"],["20.38","1.423338","0","1"],["20.4","4.684687","0","1"],["20.48","1.416341","0","1"],["20.57","4","0","1"],["20.59","1.408722","0","1"],["20.69","1.401867","0","1"],["20.79","1.265831","0","1"],["20.89","0.678255","0","1"],["21","1.394516","0","2"],["21.1","1.374445","0","1"],["21.21","1.367269","0","1"],["21.31","1.360811","0","1"],["21.42","1.353777","0","1"],["21.5","23.20045","0","2"],["21.52","2.860862","0","1"],["21.53","1.346815","0","1"],["21.64","1.340548","0","1"],["21.75","0.000007","0","1"],["21.85","4","0","1"],["21.86","1.326963","0","1"],["21.88","5.9964","0","1"],["21.97","1.320273","0","1"],["22.08","1.313651","0","1"],["22.19","1.307095","0","1"],["22.3","1.300603","0","1"],["22.41","0.57307","0","1"],["22.5","2.635137","0","1"],["22.52","1.287812","0","1"],["22.63","1.281511","0","1"],["22.75","1.274706","0","1"],["22.86","1.268532","0","1"],["22.97","1.262417","0","1"],["23.05","0.026039","0","1"],["23.1","1.255814","0","1"],["23.14","4","0","1"],["23.21","1.249821","0","1"],["23.33","1.243348","0","1"],["23.44","1.237473","0","1"],["23.56","1.231127","0","1"],["23.68","1.224845","0","1"],["23.7","1.976352","0","1"],["23.8","1.122041","0","1"],["23.91","1.212984","0","1"],["24.03","1.206886","0","1"],["24.15","1.200849","0","1"],["24.27","1.194872","0","1"],["24.39","1.188954","0","1"],["24.42","4","0","1"],["24.53","1.182609","0","1"],["24.65","1.176812","0","1"],["24.77","1.171072","0","1"],["24.8","1.482264","0","1"],["24.88","15.433441","0","1"],["24.89","1.262971","0","1"],["25","15.009507","0","3"],["25.02","1.262971","0","1"],["25.14","1.262971","0","1"],["25.27","1.262971","0","1"],["25.39","1.262971","0","1"],["25.52","1.262971","0","1"],["25.65","1.262971","0","1"],["25.71","4","0","1"],["25.78","1.262971","0","1"],["26.1","1.111698","0","1"],["26.6","0.848713","0","1"],["26.85","9.939323","0","1"],["26.88","5","0","1"],["27","36.385293","0","3"],["27.4","0.833774","0","1"],["27.9","70.006299","0","1"],["28","20.602559","0","2"],["28.7","0.62533","0","1"],["29","3.510881","0","2"],["29.4","1.011566","0","2"],["29.5","10.750519","0","2"],["29.9","14.647834","0","1"],["30","54.844608","0","4"],["30.06","0.19988","0","1"],["30.61","0.1","0","1"],["31","0.32258","0","2"],["31.22","0.1","0","1"],["31.83","0.1","0","1"],["32","29.490015","0","4"],["32.44","0.1","0","1"],["32.5","0.018465","0","1"],["33","0.30303","0","2"],["33.06","0.1","0","1"],["33.67","0.1","0","1"],["34","0.487758","0","1"],["34.28","0.1","0","1"],["34.89","0.1","0","1"],["35","5.139857","0","2"],["35.28","89.541213","0","1"],["35.51","0.1","0","1"],["35.57","6.407937","0","1"],["36","33.452045","0","1"],["36.12","0.1","0","1"],["36.73","0.1","0","1"],["37","21.815415","0","2"],["37.34","0.1","0","1"],["37.95","0.1","0","1"],["38.57","0.1","0","1"],["39","0.128205","0","1"],["39.18","0.1","0","1"],["39.79","0.1","0","1"],["40.4","0.1","0","1"],["41","0.121951","0","1"],["41.02","0.1","0","1"],["41.63","0.1","0","1"],["41.66","0.2","0","1"],["42.24","0.044151","0","1"],["42.85","0.1","0","1"],["43","0.116279","0","1"],["43.46","0.1","0","1"],["44.08","0.1","0","1"],["44.69","0.1","0","1"],["45","32.685904","0","6"],["45.18","0.292222","0","1"],["45.3","0.1","0","1"],["45.91","0.1","0","1"],["46.53","0.1","0","1"],["47","5.717037","0","3"],["47.14","0.1","0","1"],["47.75","0.1","0","1"],["48","8.075456","0","3"],["48.36","0.1","0","1"],["48.66","0.387805","0","1"],["48.97","0.1","0","1"],["49","0.4243","0","2"],["49.59","0.1","0","1"],["50","37.613662","0","4"],["50.08","2.500382","0","1"],["50.2","0.1","0","1"],["50.81","0.1","0","1"],["51","0.098039","0","1"],["51.42","0.1","0","1"],["52","88.581832","0","2"],["52.04","0.1","0","1"],["52.65","0.1","0","1"],["53","10","0","1"],["53.26","0.1","0","1"],["53.87","0.1","0","1"],["54.48","0.1","0","1"],["55","14.7495","0","4"],["55.1","0.1","0","1"],["55.71","0.1","0","1"],["56","1.036727","0","1"],["56.32","0.1","0","1"],["56.93","0.1","0","1"],["57","3.066872","0","2"],["57.55","0.1","0","1"],["58","3.9976","0","1"],["58.16","0.1","0","1"],["58.68","8.164501","0","1"],["58.77","0.1","0","1"],["59","100.32415","0","4"],["59.38","0.1","0","1"],["60","15.412732","0","6"],["60.2","1.994","0","1"],["60.61","0.1","0","1"],["61","101.0008","0","2"],["61.17","0.79952","0","1"],["61.22","0.1","0","1"],["61.83","0.1","0","1"],["62","3.996944","0","3"],["62.44","0.1","0","1"],["63","5.400676","0","3"],["63.06","0.1","0","1"],["63.67","0.1","0","1"],["64.28","0.1","0","1"],["64.87","20.3208","0","1"],["64.89","0.1","0","1"],["65","8.32629","0","4"],["65.51","0.1","0","1"],["66","9.049383","0","3"],["66.12","0.1","0","1"],["66.73","0.1","0","1"],["67","2.21771","0","1"],["67.34","0.1","0","1"],["67.95","0.1","0","1"],["68.57","0.1","0","1"],["69","2.097035","0","2"],["69.18","0.1","0","1"],["69.79","0.1","0","1"],["69.89","1.9988","0","1"],["70","19.369449","0","4"],["70.4","0.1","0","1"],["71","0.9994","0","1"],["71.02","0.1","0","1"],["71.63","0.1","0","1"],["72","1.6","0","2"],["72.24","0.1","0","1"],["72.85","0.1","0","1"],["73","0.59964","0","1"],["73.4","3.611111","0","1"],["73.46","0.1","0","1"],["74.08","0.1","0","1"],["74.69","0.1","0","1"],["75","16.307046","0","3"],["75.3","0.1","0","1"],["75.91","0.1","0","1"],["76","0.2","0","1"],["76.53","0.1","0","1"],["77","0.407093","0","2"],["77.14","0.1","0","1"],["77.75","0.1","0","1"],["78.36","0.1","0","1"],["78.97","0.1","0","1"],["79.59","0.1","0","1"],["80.2","0.1","0","1"],["80.81","0.1","0","1"],["80.9","0.225852","0","1"],["81.42","0.1","0","1"],["82.04","0.1","0","1"],["82.65","0.1","0","1"],["83.26","0.1","0","1"],["83.87","0.1","0","1"],["84.48","0.1","0","1"],["85.1","0.1","0","1"],["85.49","17","0","1"],["85.71","0.1","0","1"],["86.32","0.1","0","1"],["86.93","0.1","0","1"],["87.55","0.1","0","1"],["88","1.076959","0","1"],["88.16","0.1","0","1"],["88.77","0.1","0","1"],["89.38","0.1","0","1"],["90","16.334318","0","2"],["92","199.88","0","1"],["92.49","39.02","0","1"],["96.5","16.76","0","1"],["99","0.119928","0","1"],["100","142.893164","0","3"],["105.25","33.76","0","1"],["111.55","38.033728","0","1"],["120","8.74475","0","1"],["122.34","0.39976","0","1"],["151.36","0.145348","0","1"],["210","64.961","0","1"],["244.68","0.19988","0","1"],["256","17.061003","0","1"],["260","202.506538","0","1"],["489.36","0.09994","0","1"],["500","0.333556","0","1"]],"bids":[["14.83","2.701428","0","1"],["14.82","8","0","1"],["14.77","17.197659","0","2"],["14.76","4.8573","0","1"],["14.73","0.789014","0","1"],["14.72","5.155523","0","1"],["14.7","1.427327","0","1"],["14.67","0.129975","0","1"],["14.64","1.379219","0","1"],["14.63","10.5","0","1"],["14.62","8","0","1"],["14.55","9","0","1"],["14.54","6.276792","0","1"],["14.52","8","0","1"],["14.5","41.510807","0","2"],["14.42","8","0","1"],["14.41","2.080443","0","1"],["14.36","10.5","0","1"],["14.34","0.132967","0","1"],["14.31","8","0","1"],["14.3","207.112192","0","1"],["14.24","151.753938","0","1"],["14.23","5.478759","0","1"],["14.21","3.385501","0","1"],["14.17","0.000002","0","1"],["14.11","8","0","1"],["14.01","8.136099","0","2"],["14","17.462142","0","3"],["13.91","10.953248","0","3"],["13.9","10.1","0","2"],["13.84","0.13777","0","1"],["13.81","9.3","0","2"],["13.78","2.224663","0","2"],["13.71","8","0","1"],["13.68","0.139382","0","1"],["13.64","3.591387","0","1"],["13.6","8","0","1"],["13.52","0.141031","0","1"],["13.5","8.222222","0","3"],["13.4","9.5","0","2"],["13.37","0.142613","0","1"],["13.3","9.3","0","2"],["13.21","0.144341","0","1"],["13.2","9.3","0","2"],["13.1","9.3","0","2"],["13.09","8.8","0","1"],["13.06","0.145999","0","1"],["13","47.227388","0","3"],["12.91","0.147695","0","1"],["12.76","0.147466","0","1"],["12.61","0.151209","0","1"],["12.5","0.12","0","1"],["12.47","0.152906","0","1"],["12.32","0.154768","0","1"],["12.27","8.8","0","1"],["12.18","0.156547","0","1"],["12.04","0.158367","0","1"],["12","61.565169","0","6"],["11.9","0.16023","0","1"],["11.76","0.162138","0","1"],["11.62","0.164091","0","1"],["11.5","0.173913","0","1"],["11.49","0.165948","0","1"],["11.45","8.8","0","1"],["11.36","0.167847","0","1"],["11.22","0.169941","0","1"],["11.09","0.171933","0","1"],["11","1.363636","0","3"],["10.97","0.173814","0","1"],["10.84","0.175899","0","1"],["10.71","0.178034","0","1"],["10.63","8.8","0","1"],["10.61","87.266736","0","1"],["10.59","0.180051","0","1"],["10.5","0.190476","0","1"],["10.47","0.182115","0","1"],["10.34","0.184404","0","1"],["10.22","0.18657","0","1"],["10.11","0.1886","0","1"],["10","5.4655","0","4"],["9.99","0.190865","0","1"],["9.87","0.193186","0","1"],["9.81","8.8","0","1"],["9.76","0.195363","0","1"],["9.65","0.19759","0","1"],["9.53","0.200078","0","1"],["9.5","0.210526","0","1"],["9.42","0.202414","0","1"],["9.31","0.204806","0","1"],["9.21","0.20703","0","1"],["9.1","0.209532","0","1"],["9","11.0222","0","3"],["8.99","0.212096","0","1"],["8.89","0.214482","0","1"],["8.79","0.216922","0","1"],["8.69","0.219418","0","1"],["8.58","0.222231","0","1"],["8.49","0.224587","0","1"],["8.39","0.227264","0","1"],["8.29","0.230005","0","1"],["8.19","0.232814","0","1"],["8.1","0.2354","0","1"],["8","0.493843","0","2"],["7.91","0.241055","0","1"],["7.82","0.243829","0","1"],["7.73","0.246668","0","1"],["7.64","0.249574","0","1"],["7.55","0.252549","0","1"],["7.46","0.255596","0","1"],["7.38","0.258366","0","1"],["7.29","0.261556","0","1"],["7.21","0.264458","0","1"],["7.12","0.267801","0","1"],["7.04","0.270844","0","1"],["7","1.333","0","2"],["6.96","0.273957","0","1"],["6.88","0.277143","0","1"],["6.8","0.280404","0","1"],["6.72","0.283742","0","1"],["6.64","0.28716","0","1"],["6.57","0.29022","0","1"],["6.49","0.293797","0","1"],["6.41","0.297464","0","1"],["6.34","0.300748","0","1"],["6.27","0.304106","0","1"],["6.19","0.308036","0","1"],["6.12","0.31156","0","1"],["6.05","0.315164","0","1"],["5.98","0.318854","0","1"],["5.91","0.32263","0","1"],["5.84","0.326497","0","1"],["5.78","0.329887","0","1"],["5.71","0.333931","0","1"],["5.64","0.338075","0","1"],["2","2.5125","0","1"],["0.52","1","0","1"],["0.01","1134.307468","0","3"]],"ts":"1626995753044","checksum":-901825230}]}
1626995753.5606132: {"arg":{"channel":"books-l2-tbt","instId":"XMR-USDT-SWAP"},"action":"snapshot","data":[{"asks":[["196.11","103","0","2"],["196.23","5","0","1"],["196.24","44","0","1"],["196.25","3","0","1"],["196.26","250","0","1"],["196.28","3","0","1"],["196.29","5","0","1"],["196.3","7","0","1"],["196.33","244","0","1"],["196.34","10","0","2"],["196.36","507","0","2"],["196.38","7","0","1"],["196.4","709","0","2"],["196.42","103","0","5"],["196.44","30","0","1"],["196.45","82","0","2"],["196.46","93","0","3"],["196.48","7","0","1"],["196.53","17","0","1"],["196.55","248","0","3"],["196.65","12","0","1"],["196.84","12","0","1"],["196.85","26","0","4"],["196.89","2000","0","1"],["196.91","31","0","2"],["196.94","28","0","1"],["197","9","0","1"],["197.04","12","0","1"],["197.12","1475","0","1"],["197.14","29","0","1"],["197.16","233","0","1"],["197.18","25","0","1"],["197.33","6","0","1"],["197.34","56","0","2"],["197.5","9","0","1"],["197.69","3","0","1"],["197.75","10","0","1"],["197.76","233","0","1"],["197.85","11","0","2"],["197.86","500","0","1"],["198.29","4","0","1"],["198.3","502","0","1"],["199.82","5","0","1"],["199.83","514","0","1"],["200.5","30","0","1"],["202.76","509","0","1"],["203","1","0","1"],["203.77","1","0","1"],["203.79","499","0","1"],["205.18","30","0","1"],["205.87","3","0","1"],["206","1","0","1"],["209","83","0","1"],["209.7","502","0","1"],["210","80","0","1"],["212.26","1","0","1"],["215","10","0","1"],["216.16","2","0","1"],["220","155","0","1"],["226.96","1","0","1"],["236","5","0","1"],["237.3","1","0","1"],["238.26","1","0","1"],["238.3","2","0","1"],["250","10","0","1"],["250.21","3","0","1"],["273","10","0","1"],["278.08","9","0","1"],["280","10","0","1"],["285","10","0","1"],["293.82","9","0","1"],["311.34","5","0","1"],["315","30","0","1"],["328","1100","0","1"],["385","10","0","1"],["490","2","0","1"]],"bids":[["195.96","528","0","5"],["195.95","248","0","2"],["195.94","189","0","2"],["195.93","244","0","2"],["195.92","68","0","3"],["195.9","39","0","3"],["195.88","108","0","3"],["195.86","76","0","2"],["195.84","31","0","3"],["195.83","37","0","1"],["195.82","6","0","1"],["195.81","27","0","1"],["195.8","12","0","1"],["195.79","17","0","1"],["195.78","6","0","1"],["195.77","27","0","1"],["195.76","9","0","2"],["195.74","70","0","1"],["195.73","97","0","2"],["195.72","85","0","2"],["195.7","21","0","3"],["195.65","17","0","1"],["195.64","70","0","1"],["195.63","70","0","1"],["195.62","98","0","1"],["195.61","12","0","1"],["195.59","17","0","1"],["195.54","102","0","1"],["195.51","6","0","1"],["195.5","70","0","1"],["195.47","27","0","1"],["195.46","70","0","1"],["195.45","70","0","1"],["195.44","244","0","1"],["195.41","12","0","1"],["195.4","17","0","1"],["195.33","233","0","1"],["195.27","3","0","1"],["195.26","70","0","1"],["195.25","500","0","1"],["195.24","730","0","1"],["195.21","12","0","1"],["195.13","14","0","2"],["195.12","16","0","1"],["195.01","10","0","1"],["194.97","4","0","1"],["194.93","24","0","1"],["194.92","6","0","1"],["194.88","27","0","1"],["194.82","14","0","2"],["194.73","263","0","2"],["194.69","14","0","2"],["194.68","1976","0","1"],["194.64","4","0","1"],["194.6","10","0","1"],["194.59","4","0","1"],["194.56","10","0","1"],["194.5","14","0","3"],["194.44","4","0","1"],["194.43","9","0","1"],["194.41","10","0","1"],["194.4","28","0","1"],["194.39","4","0","1"],["194.38","26","0","1"],["194.24","1519","0","1"],["194.19","4","0","1"],["194.12","4","0","1"],["194.09","233","0","1"],["194","1","0","1"],["193.77","9","0","1"],["193.74","9","0","1"],["193.6","512","0","1"],["193","1","0","1"],["192.83","494","0","1"],["192.81","493","0","1"],["192","1","0","1"],["191.5","1","0","1"],["191","1","0","1"],["190.5","1","0","1"],["190.22","5","0","1"],["190.21","507","0","1"],["190.01","5","0","1"],["190","101","0","2"],["189.5","1","0","1"],["189.24","5","0","1"],["189.23","487","0","1"],["189","1","0","1"],["188.98","3","0","1"],["188.5","1","0","1"],["188.23","1","0","1"],["188","1","0","1"],["187.5","1","0","1"],["187.23","5","0","1"],["187.22","490","0","1"],["187","1","0","1"],["186.5","1","0","1"],["186.27","3","0","1"],["186","1","0","1"],["185.5","1","0","1"],["185","11","0","2"],["184.5","1","0","1"],["184","1","0","1"],["183.5","1","0","1"],["183.07","3","0","1"],["183","11","0","2"],["182.5","1","0","1"],["182","1","0","1"],["181.5","1","0","1"],["181","1","0","1"],["180.5","2","0","2"],["180.01","3","0","1"],["180","29","0","3"],["179.9","1","0","1"],["179.8","1","0","1"],["179.7","1","0","1"],["179.6","1","0","1"],["179.4","1","0","1"],["179.3","1","0","1"],["179.2","1","0","1"],["179.1","1","0","1"],["179","2","0","2"],["178.9","1","0","1"],["178.8","1","0","1"],["178.7","1","0","1"],["178.6","1","0","1"],["178.5","1","0","1"],["178.4","1","0","1"],["178.3","1","0","1"],["178.2","1","0","1"],["178.1","1","0","1"],["178","1","0","1"],["177.9","1","0","1"],["177.8","1","0","1"],["177.7","1","0","1"],["177.6","1","0","1"],["177.5","1","0","1"],["177.4","1","0","1"],["177.3","1","0","1"],["177.2","1","0","1"],["177.17","4","0","1"],["177.14","1","0","1"],["177.1","1","0","1"],["177","1","0","1"],["176.96","1","0","1"],["176.9","1","0","1"],["176.8","1","0","1"],["176.7","1","0","1"],["176.6","1","0","1"],["176.5","1","0","1"],["176.4","1","0","1"],["176.3","1","0","1"],["176.2","1","0","1"],["176.1","1","0","1"],["176","1","0","1"],["175.5","1","0","1"],["175.01","2","0","1"],["175","21","0","2"],["174.5","1","0","1"],["174","1","0","1"],["173.5","1","0","1"],["173","21","0","2"],["172.5","1","0","1"],["172","1","0","1"],["171.5","1","0","1"],["171","1","0","1"],["170.5","1","0","1"],["170","1","0","1"],["169.5","1","0","1"],["169.29","4","0","1"],["169","1","0","1"],["168.5","1","0","1"],["168.12","2","0","1"],["168","1","0","1"],["167.5","1","0","1"],["167","1","0","1"],["166.5","1","0","1"],["166","1","0","1"],["165.5","1","0","1"],["165","1","0","1"],["164.5","1","0","1"],["164","31","0","2"],["163.5","1","0","1"],["163","1","0","1"],["162.5","1","0","1"],["162","1","0","1"],["161.5","1","0","1"],["161.42","4","0","1"],["161","51","0","2"],["160.5","1","0","1"],["160","5","0","2"],["159.72","1","0","1"],["151.74","2","0","1"],["130","1","0","1"],["128","2","0","1"],["120","43","0","1"],["70.7","80","0","1"],["0.02","5000","0","1"],["0.01","2000","0","2"]],"ts":"1626995753297","checksum":-997002951}]}
1626995753.561248: {"arg":{"channel":"books-l2-tbt","instId":"TRX-USDT-210924"},"action":"snapshot","data":[{"asks":[["0.05451","16","0","2"],["0.05453","8","0","1"],["0.05454","167","0","2"],["0.05455","9","0","1"],["0.05457","89","0","2"],["0.05458","43","0","2"],["0.0546","21","0","2"],["0.05461","289","0","2"],["0.05462","59","0","1"],["0.05463","144","0","2"],["0.05464","350","0","2"],["0.05465","76","0","2"],["0.05468","153","0","2"],["0.05469","28","0","2"],["0.05472","81","0","1"],["0.05473","213","0","1"],["0.05474","1","0","1"],["0.05477","267","0","1"],["0.05478","425","0","3"],["0.05493","382","0","1"],["0.05494","143","0","1"],["0.055","205","0","1"],["0.05522","1","0","1"],["0.05526","136","0","1"],["0.05548","187","0","1"],["0.05553","140","0","1"],["0.05558","914","0","1"],["0.05564","908","0","1"],["0.05569","915","0","1"],["0.05575","914","0","1"],["0.05579","1","0","1"],["0.0558","1043","0","2"],["0.05588","3","0","1"],["0.0575","1","0","1"],["0.06024","3","0","1"],["0.06325","2","0","1"],["0.0654","7717","0","1"],["0.0656","1540","0","1"],["0.06626","2","0","1"],["0.06957","2","0","1"],["0.07288","2","0","1"],["0.07652","2","0","1"],["0.08016","1","0","1"],["0.08417","3","0","1"],["0.08817","1","0","1"]],"bids":[["0.05448","2","0","1"],["0.05445","8","0","1"],["0.05444","104","0","2"],["0.05443","39","0","3"],["0.05442","120","0","1"],["0.05441","150","0","2"],["0.0544","17","0","3"],["0.05437","8","0","2"],["0.05434","201","0","3"],["0.05433","333","0","1"],["0.05429","40","0","2"],["0.05427","253","0","1"],["0.05426","111","0","2"],["0.05423","1","0","1"],["0.05422","3","0","1"],["0.0542","4","0","1"],["0.05418","21","0","1"],["0.05414","4","0","1"],["0.05413","143","0","1"],["0.05412","94","0","1"],["0.05407","96","0","1"],["0.05406","388","0","1"],["0.05405","271","0","1"],["0.05396","251","0","2"],["0.05382","355","0","2"],["0.05379","204","0","1"],["0.0535","3","0","1"],["0.05337","137","0","1"],["0.05323","137","0","1"],["0.05296","139","0","1"],["0.0525","5","0","1"],["0.05204","1","0","1"],["0.05","3","0","1"],["0.0493","1","0","1"],["0.04684","2","0","1"],["0.04437","2","0","1"],["0.04216","3","0","1"],["0.03994","2","0","1"],["0.03795","2","0","1"],["0.03595","1","0","1"],["0.03558","24","0","1"],["0.03416","1","0","1"],["0.03236","1","0","1"],["0.03","97","0","1"]],"ts":"1626995752730","checksum":993559197}]}
1626995753.643115: {"arg":{"channel":"books-l2-tbt","instId":"PAY-BTC"},"action":"snapshot","data":[{"asks":[["0.00000139","4702.072","0","3"],["0.0000014","3510.065","0","4"],["0.00000141","8253.238","0","1"],["0.00000142","640","0","1"],["0.00000143","3500","0","2"],["0.00000152","440","0","1"],["0.00000154","940","0","2"],["0.00000155","2269.559","0","2"],["0.00000158","430","0","1"],["0.00000159","967.161","0","1"],["0.0000016","1000","0","1"],["0.00000163","1000","0","1"],["0.0000017","536.183","0","1"],["0.00000171","157.432","0","1"],["0.00000175","384.951","0","2"],["0.0000018","268.092","0","1"],["0.00000192","2455.82","0","1"],["0.00000218","2149.55","0","1"],["0.00000227","46.056","0","1"],["0.00000228","1456.735","0","1"],["0.00000238","950","0","1"],["0.00000275","17.278","0","1"],["0.00000281","2144.811","0","1"],["0.00000301","10.732","0","1"],["0.00000311","17.149","0","1"],["0.00000375","3143.229","0","1"],["0.00000378","99.7","0","1"],["0.00000386","2885.802","0","1"],["0.00000388","100","0","1"],["0.00000397","485.865","0","1"],["0.00000398","100","0","1"],["0.000004","242.903","0","1"],["0.00000408","100","0","1"],["0.00000418","100","0","1"],["0.0000042","1132.998","0","1"],["0.00000429","100","0","1"],["0.00000437","238.824","0","1"],["0.00000447","4196.855","0","1"],["0.00000449","200","0","2"],["0.0000045","1646.17","0","1"],["0.00000465","1431.166","0","1"],["0.00000469","100","0","1"],["0.0000047","20","0","1"],["0.00000473","2708.403","0","1"],["0.0000049","397.109","0","1"],["0.00000499","100","0","1"],["0.000005","1318.61","0","1"],["0.00000529","100","0","1"],["0.00000549","200","0","2"],["0.0000055","1431.167","0","1"],["0.00000569","100","0","1"],["0.00000575","8717.557","0","1"],["0.00000576","9538.168","0","1"],["0.00000599","99.52","0","1"],["0.000006","500","0","1"],["0.00000629","100","0","1"],["0.00000631","1345.755","0","1"],["0.00000649","200","0","2"],["0.00000669","100","0","1"],["0.00000685","20","0","1"],["0.00000699","100","0","1"],["0.00000729","100","0","1"],["0.00000749","6197.599","0","3"],["0.00000769","100","0","1"],["0.00000777","3136.792","0","1"],["0.00000799","100","0","1"],["0.00000829","100","0","1"],["0.00000849","200","0","2"],["0.00000869","100","0","1"],["0.00000873","1500","0","1"],["0.00000899","100","0","1"],["0.00000929","100","0","1"],["0.00000948","740.75","0","1"],["0.00000949","200","0","2"],["0.00000969","100","0","1"],["0.00000999","127.161","0","2"],["0.00001","8914.696","0","2"],["0.00001029","100","0","1"],["0.0000103","5788.186","0","1"],["0.00001049","100","0","1"],["0.00001069","100","0","1"],["0.00001099","100","0","1"],["0.00001129","100","0","1"],["0.00001149","100","0","1"],["0.00001169","100","0","1"],["0.00001173","1275","0","1"],["0.00001199","100","0","1"],["0.00001229","100","0","1"],["0.00001249","100","0","1"],["0.00001269","100","0","1"],["0.00001299","100","0","1"],["0.00001329","100","0","1"],["0.00001349","100","0","1"],["0.00001369","100","0","1"],["0.00001399","100","0","1"],["0.0000141","625.125","0","1"],["0.00001429","100","0","1"],["0.00001449","100","0","1"],["0.00001469","100","0","1"],["0.00001499","100","0","1"],["0.00001509","100","0","1"],["0.00001519","100","0","1"],["0.00001529","100","0","1"],["0.00001539","100","0","1"],["0.00001549","100","0","1"],["0.00001559","100","0","1"],["0.00001569","100","0","1"],["0.00001579","100","0","1"],["0.00001589","100","0","1"],["0.00001599","100","0","1"],["0.00001609","100","0","1"],["0.00001619","100","0","1"],["0.00001629","100","0","1"],["0.00001639","100","0","1"],["0.00001649","100","0","1"],["0.00001659","100","0","1"],["0.00001669","100","0","1"],["0.00001679","100","0","1"],["0.00001689","100","0","1"],["0.00001699","100","0","1"],["0.00001709","100","0","1"],["0.00001719","100","0","1"],["0.00001729","100","0","1"],["0.00001739","100","0","1"],["0.00001749","100","0","1"],["0.00001759","100","0","1"],["0.00001769","100","0","1"],["0.00001779","100","0","1"],["0.00001789","100","0","1"],["0.00001799","100","0","1"],["0.00001809","100","0","1"],["0.00001819","100","0","1"],["0.00001829","100","0","1"],["0.00001839","100","0","1"],["0.00001849","100","0","1"],["0.00001859","100","0","1"],["0.00001869","100","0","1"],["0.00001879","100","0","1"],["0.00001888","20","0","1"],["0.00001889","100","0","1"],["0.0000189","100","0","1"],["0.00001899","100","0","1"],["0.00001909","100","0","1"],["0.00001919","100","0","1"],["0.00001929","100","0","1"],["0.00001939","100","0","1"],["0.00001949","100","0","1"],["0.00001959","100","0","1"],["0.00001969","100","0","1"],["0.00001979","100","0","1"],["0.00001989","100","0","1"],["0.0000199","100","0","1"],["0.00001999","100","0","1"],["0.00002009","100","0","1"],["0.00002019","100","0","1"],["0.00002029","100","0","1"],["0.00002039","100","0","1"],["0.00002049","200","0","2"],["0.00002059","100","0","1"],["0.00002069","100","0","1"],["0.00002079","100","0","1"],["0.00002089","100","0","1"],["0.00002099","100","0","1"],["0.00002109","100","0","1"],["0.00002119","100","0","1"],["0.00002129","100","0","1"],["0.00002139","100","0","1"],["0.00002149","200","0","2"],["0.00002159","100","0","1"],["0.00002169","100","0","1"],["0.00002179","100","0","1"],["0.00002189","100","0","1"],["0.00002199","100","0","1"],["0.00002209","100","0","1"],["0.00002219","100","0","1"],["0.00002229","100","0","1"],["0.00002239","100","0","1"],["0.00002249","200","0","2"],["0.00002259","100","0","1"],["0.00002269","100","0","1"],["0.00002279","100","0","1"],["0.00002289","100","0","1"],["0.00002299","100","0","1"],["0.00002309","100","0","1"],["0.00002319","100","0","1"],["0.00002329","100","0","1"],["0.00002339","100","0","1"],["0.00002349","100","0","1"],["0.00002359","100","0","1"],["0.00002369","100","0","1"],["0.00002379","100","0","1"],["0.00002389","100","0","1"],["0.00002399","200","0","2"],["0.00002409","100","0","1"],["0.00002419","100","0","1"],["0.00002429","100","0","1"],["0.00002439","100","0","1"],["0.00002449","100","0","1"],["0.00002459","100","0","1"],["0.00002469","200","0","1"],["0.00002479","200","0","1"],["0.00002489","200","0","1"],["0.00002499","200","0","1"],["0.00002509","200","0","1"],["0.00002519","200","0","1"],["0.00002529","200","0","1"],["0.00002539","200","0","1"],["0.00002549","200","0","1"],["0.00002559","200","0","1"],["0.0000256","1000","0","1"],["0.00002569","200","0","1"],["0.00002579","200","0","1"],["0.00002589","300","0","1"],["0.00002599","300","0","1"],["0.00002609","300","0","1"],["0.00002619","300","0","1"],["0.00002629","300","0","1"],["0.00002639","300","0","1"],["0.00002649","300","0","1"],["0.00002659","300","0","1"],["0.00002669","300","0","1"],["0.00002679","300","0","1"],["0.00002689","300","0","1"],["0.00002699","300","0","1"],["0.00002709","300","0","1"],["0.00002719","300","0","1"],["0.00002729","300","0","1"],["0.00002739","300","0","1"],["0.00002749","300","0","1"],["0.00002759","300","0","1"],["0.00002769","300","0","1"],["0.00002779","300","0","1"],["0.00002888","30","0","1"],["0.00003","7.492","0","1"],["0.00003888","29.9","0","1"],["0.0000637","20406.448","0","1"],["0.000069","1251.19","0","1"],["0.00007","34.341","0","1"],["0.00008","997.622","0","1"],["0.0000871","35.945","0","1"],["0.0000944","163.019","0","1"],["0.0000949","201.312","0","1"],["0.000095","3.301","0","1"],["0.00009524","264.994","0","1"],["0.0001","3697.78","0","1"],["0.000105","5","0","1"],["0.00011892","109.317","0","1"],["0.0001239","2402.652","0","1"],["0.00013","16.86","0","1"],["0.000132","109.074","0","1"],["0.000149","331.361","0","1"],["0.00015","6.194","0","1"],["0.00017","14.978","0","1"],["0.00017654","498","0","1"],["0.0001916","109.074","0","1"],["0.00019366","1657.615","0","1"],["0.00024","10","0","1"],["0.00029211","0.01","0","1"],["0.000299","431.69565217","0","1"],["0.0003","51.202","0","2"],["0.00031","249.85","0","1"],["0.000318","2181.957","0","1"],["0.0003376","20.78970297","0","1"],["0.0004749","1.788","0","1"],["0.0005058","20.017","0","1"],["0.00058888","376.87503617","0","2"],["0.00059999","1","0","1"],["0.00071236","2.378","0","1"],["0.000731","321.613","0","1"],["0.0009","30581.532","0","3"],["0.00099","0.999","0","1"],["0.001","26369.871","0","1"],["0.0010058","20.401","0","1"],["0.00106855","2.14","0","1"],["0.00119999","100","0","1"],["0.00152","23.532","0","1"],["0.00158","100","0","1"],["0.00160283","1.926","0","1"],["0.00166","30000","0","1"],["0.001743","10","0","1"],["0.00179","30165.057","0","1"],["0.00199999","100","0","1"],["0.002","59.7224249","0","2"],["0.00240425","1.733","0","1"],["0.00299999","100","0","1"],["0.00360638","1.56","0","1"],["0.00477777","100","0","1"],["0.00540958","1.404","0","1"],["0.0059999","1","0","1"],["0.0078","156.13168877","0","1"],["0.00811438","1.264","0","1"],["0.01217158","1.137","0","1"],["0.01825738","1.024","0","1"],["0.059999","1","0","1"],["0.09","1","0","1"],["0.5","1","0","1"],["0.59999","1","0","1"],["5.99999999","1","0","1"],["41.1973773","199.7","0","1"],["59.99999999","1","0","1"],["399.99999999","1.089","0","1"],["1743","10","0","1"],["10000","0.01998","0","1"]],"bids":[["0.00000136","3602.183","0","2"],["0.00000135","5714.675","0","5"],["0.00000134","4137.717","0","5"],["0.00000133","7687.544","0","1"],["0.00000132","7138.815","0","1"],["0.00000128","19335.667","0","1"],["0.00000126","1000","0","1"],["0.00000122","1768.443","0","2"],["0.0000005","10.901","0","1"],["0.00000036","104949.416","0","1"],["0.00000035","682.595","0","1"],["0.0000002","999","0","1"],["0.00000004","6825.951","0","1"],["0.00000001","10000","0","1"]],"ts":"1626995743143","checksum":1143089411}]}
1626995753.6443992: {"arg":{"channel":"books-l2-tbt","instId":"BTC-USD-210924-66000-C"},"action":"snapshot","data":[{"asks":[["0.008","300","0","1"],["0.0085","402","0","1"],["0.009","301","0","1"],["0.0105","305","0","1"],["0.019","13","0","1"],["0.026","6","0","1"],["0.14","6","0","1"],["0.2","2","0","1"]],"bids":[["0.0065","5","0","1"],["0.006","305","0","1"],["0.0055","601","0","2"],["0.001","2","0","1"],["0.0005","10","0","1"]],"ts":"1626995750217","checksum":-90978610}]}
1626995753.6445189: {"arg":{"channel":"books-l2-tbt","instId":"XMR-USDT-SWAP"},"action":"update","data":[{"asks":[["196.4","774","0","4"],["196.42","38","0","3"]],"bids":[],"ts":"1626995753399","checksum":1449106703}]}
1626995753.644568: {"arg":{"channel":"books-l2-tbt","instId":"ONT-USDT"},"action":"update","data":[{"asks":[],"bids":[["0.6211","1011","0","4"],["0.6205","0","0","0"]],"ts":"1626995753401","checksum":1249737969}]}
1626995753.644623: {"arg":{"channel":"books-l2-tbt","instId":"ONT-USDT"},"action":"update","data":[{"asks":[],"bids":[["0.62","642","0","1"]],"ts":"1626995753424","checksum":1367084306}]}
1626995753.644653: {"arg":{"channel":"books-l2-tbt","instId":"ONT-USDT"},"action":"update","data":[{"asks":[],"bids":[["0.6195","449.868423","0","2"]],"ts":"1626995753433","checksum":553966788}]}
1626995753.644682: {"arg":{"channel":"books-l2-tbt","instId":"XMR-USDT-SWAP"},"action":"update","data":[{"asks":[["196.11","33","0","1"]],"bids":[],"ts":"1626995753480","checksum":1718157236}]}
1626995753.6447082: {"arg":{"channel":"books-l2-tbt","instId":"OKT-BTC"},"action":"update","data":[{"asks":[],"bids":[["0.001459","0.4","0","1"]],"ts":"1626995753566","checksum":293844739}]}
1626995753.6447449: {"arg":{"channel":"books-l2-tbt","instId":"OKT-BTC"},"action":"update","data":[{"asks":[],"bids":[["0.001458","0","0","0"]],"ts":"1626995753585","checksum":1019103965}]}
1626995753.644778: {"arg":{"channel":"books-l2-tbt","instId":"ONT-USDT"},"action":"update","data":[{"asks":[],"bids":[["0.6212","1345.906209","0","3"]],"ts":"1626995753586","checksum":-1002306308}]}
1626995753.646569: {"arg":{"channel":"books-l2-tbt","instId":"OKT-BTC"},"action":"update","data":[{"asks":[],"bids":[["0.00146","1.29073976","0","1"]],"ts":"1626995753596","checksum":-1355561027}]}
1626995753.6649501: {"arg":{"channel":"trades","instId":"OKT-BTC"},"data":[{"instId":"OKT-BTC","tradeId":"3406230","px":"0.001474","sz":"0.3497805","side":"buy","ts":"1626995753612"}]}
1626995753.678803: {"arg":{"channel":"books-l2-tbt","instId":"ONT-USDT"},"action":"update","data":[{"asks":[],"bids":[["0.6211","691","0","3"]],"ts":"1626995753628","checksum":-755589615}]}
1626995753.7096388: {"arg":{"channel":"books-l2-tbt","instId":"ONT-USDT"},"action":"update","data":[{"asks":[],"bids":[["0.6214","2523.066909","0","3"]],"ts":"1626995753657","checksum":-723000411}]}
1626995753.729536: {"arg":{"channel":"books-l2-tbt","instId":"ONT-USDT"},"action":"update","data":[{"asks":[["0.6219","0","0","0"],["0.622","1633.876776","0","3"],["1.1288","10.09339","0","1"]],"bids":[],"ts":"1626995753677","checksum":856135951}]}
1626995753.729727: {"arg":{"channel":"books-l2-tbt","instId":"OKT-BTC"},"action":"update","data":[{"asks":[],"bids":[["0.001451","0.83","0","1"]],"ts":"1626995753677","checksum":-359828920}]}
1626995753.730674: {"arg":{"channel":"tickers","instId":"OKT-BTC"},"data":[{"instType":"SPOT","instId":"OKT-BTC","last":"0.001474","lastSz":"0.3497805","askPx":"0.001474","askSz":"0.62267756","bidPx":"0.00147","bidSz":"46.50976581","open24h":"0.001402","high24h":"0.001489","low24h":"0.001387","sodUtc0":"0.001408","sodUtc8":"0.001437","volCcy24h":"17.16419621","vol24h":"12040.13785392","ts":"1626995753662"}]}
1626995753.7491431: {"arg":{"channel":"books-l2-tbt","instId":"ONT-USDT"},"action":"update","data":[{"asks":[],"bids":[["0.6211","371","0","2"]],"ts":"1626995753697","checksum":402177023}]}
1626995753.759939: {"arg":{"channel":"books-l2-tbt","instId":"ONT-USDT"},"action":"update","data":[{"asks":[],"bids":[["0.6211","51","0","1"]],"ts":"1626995753709","checksum":722390113}]}
1626995753.801543: {"arg":{"channel":"books-l2-tbt","instId":"XMR-USDT-SWAP"},"action":"update","data":[{"asks":[["196.36","7","0","1"],["196.38","709","0","2"],["196.4","72","0","3"],["196.44","0","0","0"],["196.5","30","0","1"],["196.57","500","0","1"]],"bids":[],"ts":"1626995753748","checksum":-157958929}]}
1626995753.8041291: {"arg":{"channel":"books-l2-tbt","instId":"ONT-USDT"},"action":"update","data":[{"asks":[],"bids":[["0.6214","2843.066909","0","4"]],"ts":"1626995753754","checksum":-1039682649}]}
1626995753.810797: {"arg":{"channel":"books-l2-tbt","instId":"ONT-USDT"},"action":"update","data":[{"asks":[],"bids":[["0.6214","377.871136","0","3"]],"ts":"1626995753760","checksum":700228918}]}
1626995753.8209789: {"arg":{"channel":"books-l2-tbt","instId":"XMR-USDT-SWAP"},"action":"update","data":[{"asks":[["196.91","3","0","1"],["196.96","28","0","1"]],"bids":[],"ts":"1626995753767","checksum":-157958929}]}
1626995753.862397: {"arg":{"channel":"books-l2-tbt","instId":"OKT-BTC"},"action":"update","data":[{"asks":[],"bids":[["0.00145","2.47","0","1"]],"ts":"1626995753809","checksum":2042997572}]}
1626995753.880445: {"arg":{"channel":"books-l2-tbt","instId":"ONT-USDT"},"action":"update","data":[{"asks":[],"bids":[["0.6214","697.871136","0","4"]],"ts":"1626995753829","checksum":-863053658}]}
1626995753.880577: {"arg":{"channel":"books-l2-tbt","instId":"XMR-USDT-SWAP"},"action":"update","data":[{"asks":[["196.39","33","0","1"],["196.4","39","0","2"]],"bids":[],"ts":"1626995753830","checksum":319004261}]}
1626995753.889997: {"arg":{"channel":"books-l2-tbt","instId":"ONT-USDT"},"action":"update","data":[{"asks":[],"bids":[["0.6214","3440.055198","0","5"]],"ts":"1626995753840","checksum":-739492245}]}
1626995753.920778: {"arg":{"channel":"books-l2-tbt","instId":"XMR-USDT-SWAP"},"action":"update","data":[{"asks":[["196.44","30","0","1"],["196.5","0","0","0"]],"bids":[["195.78","21","0","2"],["195.72","70","0","1"],["194.46","29","0","1"],["194.4","0","0","0"]],"ts":"1626995753870","checksum":-1918248816}]}
1626995753.951566: {"arg":{"channel":"books-l2-tbt","instId":"XMR-USDT-SWAP"},"action":"update","data":[{"asks":[],"bids":[],"ts":"1626995753901","checksum":-1918248816}]}
1626995753.990059: {"arg":{"channel":"books-l2-tbt","instId":"AUCTION-USDT"},"action":"update","data":[{"asks":[],"bids":[],"ts":"1626995753940","checksum":-901825230}]}
1626995754.0314581: {"arg":{"channel":"books-l2-tbt","instId":"ONT-USDT"},"action":"update","data":[{"asks":[],"bids":[["0.6212","1025.906209","0","2"]],"ts":"1626995753980","checksum":1475603723}]}
1626995754.041645: {"arg":{"channel":"books-l2-tbt","instId":"ONT-USDT"},"action":"update","data":[{"asks":[],"bids":[["0.6215","320","0","1"]],"ts":"1626995753992","checksum":1308435329}]}
1626995754.082849: {"arg":{"channel":"books-l2-tbt","instId":"AUCTION-USDT"},"action":"update","data":[{"asks":[],"bids":[["14.24","0","0","0"]],"ts":"1626995754033","checksum":1100991073}]}
1626995754.09141: {"arg":{"channel":"books-l2-tbt","instId":"OKT-BTC"},"action":"update","data":[{"asks":[],"bids":[["0.001471","9.66478906","0","3"]],"ts":"1626995754042","checksum":840286803}]}
1626995754.102014: {"arg":{"channel":"books-l2-tbt","instId":"XMR-USDT-SWAP"},"action":"update","data":[{"asks":[["196.11","0","0","0"]],"bids":[],"ts":"1626995754051","checksum":-35145558}]}
1626995754.1085382: {"arg":{"channel":"books-l2-tbt","instId":"XMR-USDT-SWAP"},"action":"update","data":[{"asks":[],"bids":[["195.78","6","0","1"],["195.73","127","0","3"]],"ts":"1626995754058","checksum":832893522}]}
1626995754.1298401: {"arg":{"channel":"books-l2-tbt","instId":"XMR-USDT-SWAP"},"action":"update","data":[{"asks":[["196.24","230","0","2"],["196.25","28","0","2"]],"bids":[],"ts":"1626995754079","checksum":-752077526}]}
1626995754.143114: {"arg":{"channel":"books-l2-tbt","instId":"ONT-USDT"},"action":"update","data":[{"asks":[],"bids":[["0.6215","640","0","2"]],"ts":"1626995754093","checksum":1407151911}]}
1626995754.149596: {"arg":{"channel":"books-l2-tbt","instId":"XMR-USDT-SWAP"},"action":"update","data":[{"asks":[["196.25","3","0","1"]],"bids":[],"ts":"1626995754099","checksum":594973296}]}
1626995754.156322: {"arg":{"channel":"books-l2-tbt","instId":"TRX-USDT-210924"},"action":"update","data":[{"asks":[],"bids":[["0.00055","1","0","1"]],"ts":"1626995754106","checksum":993559197}]}
1626995754.1617658: {"arg":{"channel":"books-l2-tbt","instId":"ONT-USDT"},"action":"update","data":[{"asks":[],"bids":[["0.6213","0","0","0"]],"ts":"1626995754112","checksum":-565837949}]}
1626995754.1936378: {"arg":{"channel":"books-l2-tbt","instId":"ONT-USDT"},"action":"update","data":[{"asks":[],"bids":[["0.6215","960","0","3"],["0.6214","3120.055198","0","4"]],"ts":"1626995754142","checksum":-1398190772}]}
1626995754.254064: {"arg":{"channel":"books-l2-tbt","instId":"ONT-USDT"},"action":"update","data":[{"asks":[["0.6218","0","0","0"],["1.13","13919.895296","0","1"]],"bids":[],"ts":"1626995754203","checksum":734288571}]}
1626995754.255927: {"arg":{"channel":"books-l2-tbt","instId":"XMR-USDT-SWAP"},"action":"update","data":[{"asks":[["196.38","7","0","1"],["196.4","701","0","3"]],"bids":[],"ts":"1626995754204","checksum":-698296657}]}
1626995754.273893: {"arg":{"channel":"books-l2-tbt","instId":"ONT-USDT"},"action":"update","data":[{"asks":[["0.6218","85","0","1"],["1.13","0","0","0"]],"bids":[],"ts":"1626995754224","checksum":-1398190772}]}
1626995754.2964559: {"arg":{"channel":"books-l2-tbt","instId":"XMR-USDT-SWAP"},"action":"update","data":[{"asks":[["196.24","44","0","1"]],"bids":[],"ts":"1626995754245","checksum":-1276533514}]}
1626995754.2965848: {"arg":{"channel":"books-l2-tbt","instId":"ONT-USDT"},"action":"update","data":[{"asks":[],"bids":[["0.6215","1280","0","4"],["0.6214","2800.055198","0","3"]],"ts":"1626995754247","checksum":-2070037299}]}
1626995754.314347: {"arg":{"channel":"books-l2-tbt","instId":"XMR-USDT-SWAP"},"action":"update","data":[{"asks":[["196.28","28","0","2"]],"bids":[],"ts":"1626995754264","checksum":991326116}]}
1626995754.320218: {"arg":{"channel":"books-l2-tbt","instId":"AUCTION-USDT"},"action":"update","data":[{"asks":[],"bids":[["14.31","159.011605","0","2"]],"ts":"1626995754268","checksum":-2058340696}]}
1626995754.3378549: {"arg":{"channel":"books-l2-tbt","instId":"XMR-USDT-SWAP"},"action":"update","data":[{"asks":[],"bids":[["195.86","98","0","3"],["195.84","9","0","2"]],"ts":"1626995754288","checksum":-1174097731}]}
1626995754.348595: {"arg":{"channel":"books-l2-tbt","instId":"ONT-USDT"},"action":"update","data":[{"asks":[],"bids":[["0.6195","9986.905423","0","3"]],"ts":"1626995754298","checksum":-35795705}]}
1626995754.3581572: {"arg":{"channel":"books-l2-tbt","instId":"ONT-USDT"},"action":"update","data":[{"asks":[],"bids":[["0.6215","1600","0","5"]],"ts":"1626995754308","checksum":-880404564}]}
1626995754.379916: {"arg":{"channel":"books-l2-tbt","instId":"ONT-USDT"},"action":"update","data":[{"asks":[["0.6218","0","0","0"],["1.13","13919.895296","0","1"]],"bids":[],"ts":"1626995754329","checksum":-383534837}]}
1626995754.400268: {"arg":{"channel":"books-l2-tbt","instId":"XMR-USDT-SWAP"},"action":"update","data":[{"asks":[],"bids":[["195.24","757","0","2"],["195.12","0","0","0"],["195.05","22","0","1"],["194.93","0","0","0"],["194.85","23","0","1"],["194.73","233","0","1"]],"ts":"1626995754347","checksum":-1174097731}]}
1626995754.400477: {"arg":{"channel":"books-l2-tbt","instId":"DHT-USDT"},"action":"update","data":[{"asks":[["0.811","0","0","0"]],"bids":[],"ts":"1626995754348","checksum":316614474}]}
1626995754.400553: {"arg":{"channel":"books-l2-tbt","instId":"ONT-USDT"},"action":"update","data":[{"asks":[["0.6219","85","0","1"],["0.6224","1972.196878","0","2"],["1.13","0","0","0"]],"bids":[["0.6195","449.868423","0","2"]],"ts":"1626995754350","checksum":-1762891517}]}
1626995754.409654: {"arg":{"channel":"books-l2-tbt","instId":"ONT-USDT"},"action":"update","data":[{"asks":[["0.6226","887.016404","0","2"]],"bids":[],"ts":"1626995754360","checksum":1879417189}]}
1626995754.431582: {"arg":{"channel":"books-l2-tbt","instId":"ONT-USDT"},"action":"update","data":[{"asks":[["0.622","1548.873745","0","2"],["0.6223","72.693856","0","1"],["0.6243","0","0","0"]],"bids":[["0.6213","72.693856","0","1"],["0.6212","945.539","0","1"],["0.6189","0","0","0"]],"ts":"1626995754381","checksum":-603290208}]}
1626995754.452258: {"arg":{"channel":"books-l2-tbt","instId":"ONT-USDT"},"action":"update","data":[{"asks":[],"bids":[["0.6215","1280","0","4"],["0.6195","47","0","1"]],"ts":"1626995754400","checksum":-436601495}]}
1626995754.460887: {"arg":{"channel":"books-l2-tbt","instId":"ONT-USDT"},"action":"update","data":[{"asks":[],"bids":[["0.6208","9533.507","0","1"],["0.6201","402.868423","0","1"]],"ts":"1626995754410","checksum":-1905135573}]}
1626995754.5430348: {"arg":{"channel":"books-l2-tbt","instId":"ONT-USDT"},"action":"update","data":[{"asks":[["0.6245","6082.690803","0","1"],["1.1288","0","0","0"]],"bids":[["0.6215","960","0","3"],["0.619","6176.690801","0","2"]],"ts":"1626995754493","checksum":-286188137}]}
1626995754.551587: {"arg":{"channel":"books-l2-tbt","instId":"ONT-USDT"},"action":"update","data":[{"asks":[],"bids":[["0.6215","1280","0","4"]],"ts":"1626995754501","checksum":-1512235414}]}
1626995754.643703: {"arg":{"channel":"books-l2-tbt","instId":"ONT-USDT"},"action":"update","data":[{"asks":[],"bids":[["0.6215","960","0","3"]],"ts":"1626995754592","checksum":-286188137}]}
1626995754.672686: {"arg":{"channel":"books-l2-tbt","instId":"DHT-USDT"},"action":"update","data":[{"asks":[],"bids":[["0.735","117.006802","0","2"]],"ts":"1626995754621","checksum":171003263}]}
1626995754.703707: {"arg":{"channel":"books-l2-tbt","instId":"ONT-USDT"},"action":"update","data":[{"asks":[],"bids":[["0.6215","640","0","2"]],"ts":"1626995754653","checksum":-180692012}]}
1626995754.745292: {"arg":{"channel":"books-l2-tbt","instId":"ONT-USDT"},"action":"update","data":[{"asks":[],"bids":[["0.6215","320","0","1"]],"ts":"1626995754694","checksum":-896401595}]}
1626995754.767196: {"arg":{"channel":"books-l2-tbt","instId":"ONT-USDT"},"action":"update","data":[{"asks":[["0.6221","462.693856","0","2"],["0.6223","0","0","0"],["1.1288","10.09339","0","1"]],"bids":[],"ts":"1626995754716","checksum":172570561}]}
1626995754.788803: {"arg":{"channel":"books-l2-tbt","instId":"TRX-USDT-210924"},"action":"update","data":[{"asks":[],"bids":[["0.05443","34","0","2"]],"ts":"1626995754737","checksum":-648087781}]}
1626995754.848395: {"arg":{"channel":"books-l2-tbt","instId":"XMR-USDT-SWAP"},"action":"update","data":[{"asks":[["196.38","619","0","2"]],"bids":[],"ts":"1626995754798","checksum":816637369}]}
1626995754.8585742: {"arg":{"channel":"books-l2-tbt","instId":"ONT-USDT"},"action":"update","data":[{"asks":[],"bids":[["0.6215","640","0","2"]],"ts":"1626995754807","checksum":-882632925}]}
1626995754.869251: {"arg":{"channel":"books-l2-tbt","instId":"XMR-USDT-SWAP"},"action":"update","data":[{"asks":[["196.4","39","0","2"]],"bids":[],"ts":"1626995754818","checksum":1058374658}]}
1626995754.87674: {"arg":{"channel":"books-l2-tbt","instId":"ONT-USDT"},"action":"update","data":[{"asks":[["0.6221","390","0","1"],["0.6223","72.693856","0","1"],["1.1288","0","0","0"]],"bids":[],"ts":"1626995754827","checksum":-180692012}]}
1626995754.905377: {"arg":{"channel":"books-l2-tbt","instId":"DHT-USDT"},"action":"update","data":[{"asks":[["0.796","439.1407","0","2"]],"bids":[],"ts":"1626995754855","checksum":602405310}]}
1626995754.926877: {"arg":{"channel":"books-l2-tbt","instId":"ONT-USDT"},"action":"update","data":[{"asks":[],"bids":[["0.6215","960","0","3"]],"ts":"1626995754877","checksum":-286188137}]}
1626995755.050455: {"arg":{"channel":"books-l2-tbt","instId":"XMR-USDT-SWAP"},"action":"update","data":[{"asks":[["196.22","33","0","1"]],"bids":[],"ts":"1626995755000","checksum":-499522763}]}
1626995755.0621052: {"arg":{"channel":"books-l2-tbt","instId":"ONT-USDT"},"action":"update","data":[{"asks":[],"bids":[["0.6215","640","0","2"]],"ts":"1626995755011","checksum":-180692012}]}
1626995755.0704992: {"arg":{"channel":"books-l2-tbt","instId":"XMR-USDT-SWAP"},"action":"update","data":[{"asks":[["196.42","89","0","4"]],"bids":[],"ts":"1626995755020","checksum":1765887355}]}
1626995755.113408: {"arg":{"channel":"books-l2-tbt","instId":"XMR-USDT-SWAP"},"action":"update","data":[{"asks":[],"bids":[["195.86","76","0","2"],["195.75","22","0","1"]],"ts":"1626995755061","checksum":1124331064}]}
1626995755.14296: {"arg":{"channel":"books-l2-tbt","instId":"ONT-USDT"},"action":"update","data":[{"asks":[],"bids":[["0.6216","320","0","1"]],"ts":"1626995755092","checksum":1991400357}]}
1626995755.1458519: {"arg":{"channel":"books-l2-tbt","instId":"FUN-BTC"},"action":"update","data":[{"asks":[],"bids":[["0.000000402","0","0","0"]],"ts":"1626995755095","checksum":446600849}]}
1626995755.152701: {"arg":{"channel":"books-l2-tbt","instId":"DHT-USDT"},"action":"update","data":[{"asks":[],"bids":[["0.72","793.5355","0","1"]],"ts":"1626995755100","checksum":1586774313}]}
1626995755.152838: {"arg":{"channel":"books-l2-tbt","instId":"ONT-USDT"},"action":"update","data":[{"asks":[],"bids":[["0.6216","640","0","2"]],"ts":"1626995755102","checksum":-242920621}]}
1626995755.1873841: {"arg":{"channel":"books-l2-tbt","instId":"OKT-BTC"},"action":"update","data":[{"asks":[],"bids":[["0.001399","0","0","0"]],"ts":"1626995755134","checksum":-699675021}]}
1626995755.1951191: {"arg":{"channel":"books-l2-tbt","instId":"XMR-USDT-SWAP"},"action":"update","data":[{"asks":[["196.28","3","0","1"]],"bids":[],"ts":"1626995755144","checksum":-924957329}]}
1626995755.2203698: {"arg":{"channel":"books-l2-tbt","instId":"XMR-USDT-SWAP"},"action":"update","data":[{"asks":[],"bids":[["195.83","59","0","2"],["195.75","0","0","0"]],"ts":"1626995755164","checksum":1799242413}]}
1626995755.2495959: {"arg":{"channel":"books-l2-tbt","instId":"ONT-USDT"},"action":"update","data":[{"asks":[],"bids":[["0.6214","57.871136","0","2"]],"ts":"1626995755196","checksum":1323725314}]}
1626995755.293649: {"arg":{"channel":"books-l2-tbt","instId":"AUCTION-USDT"},"action":"update","data":[{"asks":[],"bids":[["14.31","8","0","1"]],"ts":"1626995755242","checksum":1100991073}]}
1626995755.329907: {"arg":{"channel":"books-l2-tbt","instId":"ONT-USDT"},"action":"update","data":[{"asks":[],"bids":[["0.6208","0","0","0"]],"ts":"1626995755280","checksum":738849665}]}
1626995755.354371: {"arg":{"channel":"books-l2-tbt","instId":"ONT-USDT"},"action":"update","data":[{"asks":[],"bids":[["0.6215","320","0","1"]],"ts":"1626995755301","checksum":1891575156}]}
1626995755.4013178: {"arg":{"channel":"books-l2-tbt","instId":"ONT-USDT"},"action":"update","data":[{"asks":[["0.6219","0","0","0"],["1.1288","10.09339","0","1"]],"bids":[],"ts":"1626995755351","checksum":-1663882108}]}
1626995755.423: {"arg":{"channel":"books-l2-tbt","instId":"ONT-USDT"},"action":"update","data":[{"asks":[["0.622","1633.873745","0","3"]],"bids":[],"ts":"1626995755372","checksum":579721105}]}
1626995755.4230652: {"arg":{"channel":"books-l2-tbt","instId":"FUN-BTC"},"action":"update","data":[{"asks":[],"bids":[["0.00000041","6759.56","0","1"]],"ts":"1626995755374","checksum":-1950443083}]}
1626995755.430874: {"arg":{"channel":"books-l2-tbt","instId":"ONT-USDT"},"action":"update","data":[{"asks":[],"bids":[["0.619","6082.690801","0","1"]],"ts":"1626995755381","checksum":-1052637144}]}
1626995755.526443: {"arg":{"channel":"books-l2-tbt","instId":"ONT-USDT"},"action":"update","data":[{"asks":[],"bids":[["0.6191","94","0","1"]],"ts":"1626995755475","checksum":-175916516}]}
1626995755.537729: {"arg":{"channel":"books-l2-tbt","instId":"ONT-USDT"},"action":"update","data":[{"asks":[],"bids":[["0.6215","0","0","0"]],"ts":"1626995755485","checksum":2134267450}]}
1626995755.537771: {"arg":{"channel":"books-l2-tbt","instId":"AUCTION-USDT"},"action":"update","data":[{"asks":[],"bids":[["14.25","151.647444","0","1"]],"ts":"1626995755486","checksum":-915200773}]}
1626995755.6661959: {"arg":{"channel":"trades","instId":"OKT-BTC"},"data":[{"instId":"OKT-BTC","tradeId":"3406231","px":"0.001474","sz":"0.28861356","side":"buy","ts":"1626995755612"}]}
1626995755.690754: {"arg":{"channel":"books-l2-tbt","instId":"OKT-BTC"},"action":"update","data":[{"asks":[],"bids":[["0.001422","0","0","0"]],"ts":"1626995755640","checksum":619090578}]}
1626995755.7606778: {"arg":{"channel":"tickers","instId":"OKT-BTC"},"data":[{"instType":"SPOT","instId":"OKT-BTC","last":"0.001474","lastSz":"0.28861356","askPx":"0.001475","askSz":"10.622771","bidPx":"0.001471","bidSz":"2.89090055","open24h":"0.001402","high24h":"0.001489","low24h":"0.001387","sodUtc0":"0.001408","sodUtc8":"0.001437","volCcy24h":"17.16462163","vol24h":"12040.42646748","ts":"1626995755701"}]}
1626995755.7956421: {"arg":{"channel":"books-l2-tbt","instId":"ONT-USDT"},"action":"update","data":[{"asks":[],"bids":[["0.6208","10381.841","0","1"]],"ts":"1626995755743","checksum":-735958469}]}
1626995755.932402: {"arg":{"channel":"books-l2-tbt","instId":"BTC-USD-210924-42000-P"},"action":"update","data":[{"asks":[["0.3415","305","0","2"],["0.342","0","0","0"]],"bids":[["0.3345","0","0","0"],["0.334","601","0","2"]],"ts":"1626995755882","checksum":-1447581190}]}
1626995755.958039: {"arg":{"channel":"books-l2-tbt","instId":"FUN-BTC"},"action":"update","data":[{"asks":[],"bids":[],"ts":"1626995755908","checksum":-1950443083}]}
1626995755.976109: {"arg":{"channel":"books-l2-tbt","instId":"XMR-USDT-SWAP"},"action":"update","data":[{"asks":[["196.44","0","0","0"],["196.51","30","0","1"]],"bids":[],"ts":"1626995755925","checksum":-1830860769}]}
1626995756.00237: {"arg":{"channel":"books-l2-tbt","instId":"ONT-USDT"},"action":"update","data":[{"asks":[["0.6221","0","0","0"],["0.6224","2362.196878","0","3"],["1.13","13919.895296","0","1"]],"bids":[],"ts":"1626995755953","checksum":895780452}]}
1626995756.0140438: {"arg":{"channel":"books-l2-tbt","instId":"PAY-BTC"},"action":"update","data":[{"asks":[],"bids":[["0.00000135","3053.957","0","4"]],"ts":"1626995755964","checksum":1410305764}]}
1626995756.0341408: {"arg":{"channel":"books-l2-tbt","instId":"BTC-USD-210924-42000-P"},"action":"update","data":[{"asks":[["0.3415","5","0","1"],["0.342","300","0","1"]],"bids":[["0.3345","300","0","1"],["0.334","301","0","1"]],"ts":"1626995755982","checksum":-1431042442}]}
1626995756.0461051: {"arg":{"channel":"books-l2-tbt","instId":"ONT-USDT"},"action":"update","data":[{"asks":[],"bids":[["0.6171","0","0","0"]],"ts":"1626995755997","checksum":895780452}]}
1626995756.054563: {"arg":{"channel":"books-l2-tbt","instId":"BTC-USD-210924-42000-P"},"action":"update","data":[{"asks":[["0.341","5","0","1"],["0.3415","0","0","0"]],"bids":[["0.335","0","0","0"],["0.3345","305","0","2"],["0.334","0","0","0"],["0.3335","301","0","1"]],"ts":"1626995756003","checksum":813493843}]}
1626995756.090017: {"arg":{"channel":"books-l2-tbt","instId":"ONT-USDT"},"action":"update","data":[{"asks":[],"bids":[["0.6212","0","0","0"]],"ts":"1626995756039","checksum":-1635529233}]}
1626995756.098815: {"arg":{"channel":"books-l2-tbt","instId":"ONT-USDT"},"action":"update","data":[{"asks":[],"bids":[["0.6213","1018.232856","0","2"]],"ts":"1626995756048","checksum":-2012321916}]}
1626995756.121068: {"arg":{"channel":"books-l2-tbt","instId":"XMR-USDT-SWAP"},"action":"update","data":[{"asks":[["196.37","15","0","1"],["196.38","491","0","2"],["196.51","0","0","0"]],"bids":[],"ts":"1626995756068","checksum":-1297707186}]}
1626995756.1378171: {"arg":{"channel":"books-l2-tbt","instId":"ONT-USDT"},"action":"update","data":[{"asks":[["0.622","688.334745","0","2"],["0.6221","945.539","0","1"],["1.13","0","0","0"]],"bids":[["0.62","689","0","2"]],"ts":"1626995756087","checksum":-1614210062}]}
1626995756.137872: {"arg":{"channel":"books-l2-tbt","instId":"XMR-USDT-SWAP"},"action":"update","data":[{"asks":[["196.37","499","0","2"],["196.38","7","0","1"]],"bids":[],"ts":"1626995756088","checksum":-292827362}]}
1626995756.1590679: {"arg":{"channel":"books-l2-tbt","instId":"BTC-USD-210924-42000-P"},"action":"update","data":[{"asks":[["0.341","0","0","0"],["0.3415","5","0","1"]],"bids":[["0.335","5","0","1"],["0.3345","300","0","1"]],"ts":"1626995756108","checksum":439282224}]}
1626995756.2208462: {"arg":{"channel":"books-l2-tbt","instId":"XMR-USDT-SWAP"},"action":"update","data":[{"asks":[["196.37","484","0","1"],["196.51","30","0","1"]],"bids":[],"ts":"1626995756169","checksum":-431908581}]}
1626995756.283116: {"arg":{"channel":"books-l2-tbt","instId":"PAY-BTC"},"action":"update","data":[{"asks":[],"bids":[["0.00000136","6884.955","0","3"]],"ts":"1626995756231","checksum":-293096816}]}
1626995756.283155: {"arg":{"channel":"books-l2-tbt","instId":"ONT-USDT"},"action":"update","data":[{"asks":[],"bids":[["0.6205","9536.225","0","1"]],"ts":"1626995756234","checksum":-1475709967}]}
1626995756.283378: {"arg":{"channel":"books-l2-tbt","instId":"XMR-USDT-SWAP"},"action":"update","data":[{"asks":[],"bids":[["194.43","0","0","0"]],"ts":"1626995756234","checksum":-431908581}]}
1626995756.346653: {"arg":{"channel":"books-l2-tbt","instId":"XMR-USDT-SWAP"},"action":"update","data":[{"asks":[],"bids":[["194.48","9","0","1"]],"ts":"1626995756295","checksum":-431908581}]}
1626995756.353024: {"arg":{"channel":"books-l2-tbt","instId":"ONT-USDT"},"action":"update","data":[{"asks":[],"bids":[["0.6205","0","0","0"]],"ts":"1626995756303","checksum":-1614210062}]}
1626995756.3905768: {"arg":{"channel":"books-l2-tbt","instId":"XMR-USDT-SWAP"},"action":"update","data":[{"asks":[["196.94","0","0","0"],["196.96","0","0","0"],["197.04","27","0","2"],["197.14","0","0","0"],["197.24","18","0","1"],["197.34","27","0","1"],["197.44","21","0","1"]],"bids":[],"ts":"1626995756340","checksum":-431908581}]}
1626995756.399668: {"arg":{"channel":"books-l2-tbt","instId":"PAY-BTC"},"action":"update","data":[{"asks":[],"bids":[],"ts":"1626995756349","checksum":-293096816}]}
1626995756.410963: {"arg":{"channel":"books-l2-tbt","instId":"XMR-USDT-SWAP"},"action":"update","data":[{"asks":[["197.01","28","0","1"]],"bids":[],"ts":"1626995756360","checksum":-431908581}]}
1626995756.430869: {"arg":{"channel":"trades","instId":"PAY-BTC"},"data":[{"instId":"PAY-BTC","tradeId":"6071312","px":"0.00000138","sz":"4686.845","side":"sell","ts":"1626995756375"}]}
1626995756.471173: {"arg":{"channel":"books-l2-tbt","instId":"XMR-USDT-SWAP"},"action":"update","data":[{"asks":[],"bids":[["195.9","42","0","4"],["195.84","6","0","1"],["195.82","9","0","2"],["195.76","6","0","1"],["195.33","236","0","2"],["195.27","0","0","0"]],"ts":"1626995756421","checksum":-633003347}]}
1626995756.483466: {"arg":{"channel":"books-l2-tbt","instId":"ONT-USDT"},"action":"update","data":[{"asks":[],"bids":[["0.6216","320","0","1"]],"ts":"1626995756434","checksum":-738962740}]}
1626995756.4947882: {"arg":{"channel":"books-l2-tbt","instId":"ONT-USDT"},"action":"update","data":[{"asks":[],"bids":[["0.6216","0","0","0"]],"ts":"1626995756445","checksum":-1743525688}]}
1626995756.502544: {"arg":{"channel":"tickers","instId":"PAY-BTC"},"data":[{"instType":"SPOT","instId":"PAY-BTC","last":"0.00000138","lastSz":"4686.845","askPx":"0.00000139","askSz":"4702.072","bidPx":"0.00000136","bidSz":"3602.183","open24h":"0.00000137","high24h":"0.00000144","low24h":"0.00000136","sodUtc0":"0.00000138","sodUtc8":"0.00000138","volCcy24h":"45.1","vol24h":"32751510.334","ts":"1626995756449"}]}
1626995756.502613: {"arg":{"channel":"books-l2-tbt","instId":"PAY-BTC"},"action":"update","data":[{"asks":[],"bids":[["0.00000134","3711.654","0","4"]],"ts":"1626995756453","checksum":-581084138}]}
1626995756.507288: {"arg":{"channel":"books-l2-tbt","instId":"AUCTION-USDT"},"action":"update","data":[{"asks":[],"bids":[["14.25","0","0","0"]],"ts":"1626995756457","checksum":1100991073}]}
1626995756.5192409: {"arg":{"channel":"books-l2-tbt","instId":"ONT-USDT"},"action":"update","data":[{"asks":[["0.622","1548.873745","0","2"],["0.6221","0","0","0"],["1.13","13919.895296","0","1"]],"bids":[["0.6201","0","0","0"]],"ts":"1626995756467","checksum":-1384935722}]}
1626995756.5278678: {"arg":{"channel":"books-l2-tbt","instId":"ONT-USDT"},"action":"update","data":[{"asks":[],"bids":[["0.6213","945.539","0","1"],["0.6195","449.868423","0","2"]],"ts":"1626995756478","checksum":-619185324}]}
1626995756.5415099: {"arg":{"channel":"books-l2-tbt","instId":"ONT-USDT"},"action":"update","data":[{"asks":[["0.6219","85","0","1"],["1.13","0","0","0"]],"bids":[["0.6211","128.84406","0","2"]],"ts":"1626995756487","checksum":-559528564}]}
1626995756.574913: {"arg":{"channel":"books-l2-tbt","instId":"XMR-USDT-SWAP"},"action":"update","data":[{"asks":[],"bids":[["195.97","27","0","1"],["195.96","540","0","7"],["195.95","275","0","3"],["195.92","47","0","3"],["195.9","3","0","1"],["195.88","114","0","4"],["195.86","70","0","1"],["195.85","27","0","1"],["195.84","12","0","2"],["195.82","30","0","2"],["195.81","0","0","0"],["195.78","27","0","1"],["195.77","0","0","0"],["195.73","100","0","2"],["195.52","27","0","1"],["195.47","0","0","0"],["194.93","27","0","1"],["194.88","0","0","0"]],"ts":"1626995756524","checksum":2138514383}]}
1626995756.595795: {"arg":{"channel":"books-l2-tbt","instId":"XMR-USDT-SWAP"},"action":"update","data":[{"asks":[],"bids":[["195.98","23","0","1"],["195.97","213","0","2"],["195.96","517","0","6"],["195.94","3","0","1"]],"ts":"1626995756546","checksum":1764957317}]}
1626995756.617078: {"arg":{"channel":"books-l2-tbt","instId":"XMR-USDT-SWAP"},"action":"update","data":[{"asks":[],"bids":[["195.98","209","0","2"],["195.95","89","0","2"]],"ts":"1626995756566","checksum":634130626}]}
1626995756.630953: {"arg":{"channel":"books-l2-tbt","instId":"PAY-BTC"},"action":"update","data":[{"asks":[],"bids":[["0.00000135","3476.864","0","5"]],"ts":"1626995756581","checksum":683115118}]}
1626995756.637571: {"arg":{"channel":"books-l2-tbt","instId":"XMR-USDT-SWAP"},"action":"update","data":[{"asks":[],"bids":[["195.99","23","0","1"],["195.98","186","0","1"]],"ts":"1626995756587","checksum":1285868693}]}
1626995756.659153: {"arg":{"channel":"books-l2-tbt","instId":"XMR-USDT-SWAP"},"action":"update","data":[{"asks":[],"bids":[["195.99","209","0","2"],["195.96","331","0","5"],["195.84","34","0","3"],["195.83","37","0","1"]],"ts":"1626995756609","checksum":-1135787859}]}
1626995756.67965: {"arg":{"channel":"books-l2-tbt","instId":"XMR-USDT-SWAP"},"action":"update","data":[{"asks":[["196.42","38","0","3"]],"bids":[["196","23","0","1"],["195.99","186","0","1"]],"ts":"1626995756630","checksum":-399530597}]}
1626995756.701393: {"arg":{"channel":"books-l2-tbt","instId":"XMR-USDT-SWAP"},"action":"update","data":[{"asks":[],"bids":[["196","253","0","3"],["195.97","27","0","1"],["195.83","0","0","0"]],"ts":"1626995756652","checksum":857726606}]}
1626995756.7153668: {"arg":{"channel":"books-l2-tbt","instId":"ONT-USDT"},"action":"update","data":[{"asks":[],"bids":[["0.6176","0","0","0"]],"ts":"1626995756666","checksum":76072640}]}
1626995756.7215722: {"arg":{"channel":"books-l2-tbt","instId":"XMR-USDT-SWAP"},"action":"update","data":[{"asks":[],"bids":[["196.01","23","0","1"],["196","230","0","2"]],"ts":"1626995756672","checksum":1401815167}]}
1626995756.742118: {"arg":{"channel":"books-l2-tbt","instId":"XMR-USDT-SWAP"},"action":"update","data":[{"asks":[],"bids":[["196.01","209","0","2"],["195.98","0","0","0"]],"ts":"1626995756692","checksum":1472505874}]}
1626995756.7468648: {"arg":{"channel":"books-l2-tbt","instId":"OKT-BTC"},"action":"update","data":[{"asks":[],"bids":[["0.001471","2.89090055","0","2"]],"ts":"1626995756697","checksum":-192123339}]}
1626995756.7469: {"arg":{"channel":"books-l2-tbt","instId":"AUCTION-USDT"},"action":"update","data":[{"asks":[],"bids":[["14.3","358.2294","0","2"]],"ts":"1626995756698","checksum":-716211462}]}
1626995756.762924: {"arg":{"channel":"trades","instId":"XMR-USDT-SWAP"},"data":[{"instId":"XMR-USDT-SWAP","tradeId":"6845126","px":"196.06","sz":"25","side":"buy","ts":"1626995756708"}]}
1626995756.76332: {"arg":{"channel":"books-l2-tbt","instId":"XMR-USDT-SWAP"},"action":"update","data":[{"asks":[],"bids":[["195.84","12","0","2"],["195.75","22","0","1"]],"ts":"1626995756713","checksum":688529288}]}
1626995756.800769: {"arg":{"channel":"books-l2-tbt","instId":"ONT-USDT"},"action":"update","data":[{"asks":[],"bids":[["0.6188","129","0","2"]],"ts":"1626995756748","checksum":1170502178}]}
1626995756.803875: {"arg":{"channel":"books-l2-tbt","instId":"XMR-USDT-SWAP"},"action":"update","data":[{"asks":[],"bids":[["196.02","23","0","1"],["196.01","186","0","1"]],"ts":"1626995756755","checksum":-336366061}]}
1626995756.827845: {"arg":{"channel":"books-l2-tbt","instId":"XMR-USDT-SWAP"},"action":"update","data":[{"asks":[],"bids":[["196.02","209","0","2"],["195.99","0","0","0"]],"ts":"1626995756776","checksum":2074878483}]}
1626995756.8278668: {"arg":{"channel":"books-l2-tbt","instId":"PAY-BTC"},"action":"update","data":[{"asks":[],"bids":[["0.00000135","3053.957","0","4"]],"ts":"1626995756777","checksum":-581084138}]}
1626995756.839502: {"arg":{"channel":"tickers","instId":"XMR-USDT-SWAP"},"data":[{"instType":"SWAP","instId":"XMR-USDT-SWAP","last":"196.06","lastSz":"25","askPx":"196.11","askSz":"116","bidPx":"195.96","bidSz":"342","open24h":"197.31","high24h":"202.54","low24h":"189.85","sodUtc0":"196.66","sodUtc8":"199.56","volCcy24h":"65235.4","vol24h":"652354","ts":"1626995756781"}]}
1626995756.868502: {"arg":{"channel":"books-l2-tbt","instId":"XMR-USDT-SWAP"},"action":"update","data":[{"asks":[],"bids":[["195.86","92","0","2"],["195.75","0","0","0"]],"ts":"1626995756817","checksum":1788093262}]}
1626995756.89049: {"arg":{"channel":"books-l2-tbt","instId":"ONT-USDT"},"action":"update","data":[{"asks":[],"bids":[["0.6209","320","0","1"]],"ts":"1626995756841","checksum":-412098758}]}
1626995756.96084: {"arg":{"channel":"books-l2-tbt","instId":"PAY-BTC"},"action":"update","data":[{"asks":[],"bids":[["0.00000134","4137.717","0","5"]],"ts":"1626995756910","checksum":-293096816}]}
1626995756.9753962: {"arg":{"channel":"books-l2-tbt","instId":"ONT-USDT"},"action":"update","data":[{"asks":[["0.6245","0","0","0"],["1.13","13919.895296","0","1"]],"bids":[],"ts":"1626995756922","checksum":653788330}]}
1626995756.983518: {"arg":{"channel":"books-l2-tbt","instId":"OKT-BTC"},"action":"update","data":[{"asks":[],"bids":[["0.00145","9.3419931","0","2"]],"ts":"1626995756933","checksum":-1503738595}]}
1626995756.99282: {"arg":{"channel":"books-l2-tbt","instId":"XMR-USDT-SWAP"},"action":"update","data":[{"asks":[],"bids":[["195.86","70","0","1"],["195.75","22","0","1"]],"ts":"1626995756939","checksum":2074878483}]}
1626995757.0098: {"arg":{"channel":"books-l2-tbt","instId":"XMR-USDT-SWAP"},"action":"update","data":[{"asks":[["196.45","12","0","1"],["196.54","70","0","1"],["196.55","15","0","2"],["196.83","233","0","1"],["197.16","0","0","0"],["197.26","233","0","1"],["197.76","0","0","0"],["197.87","233","0","1"]],"bids":[["195.6","70","0","1"],["195.5","0","0","0"],["195.47","233","0","1"],["195.33","3","0","1"],["194.83","233","0","1"],["194.73","0","0","0"],["194.19","237","0","2"],["194.09","0","0","0"]],"ts":"1626995756959","checksum":1220819296}]}
1626995757.088911: {"arg":{"channel":"books-l2-tbt","instId":"ONT-USDT"},"action":"update","data":[{"asks":[["0.6244","6170.039962","0","2"]],"bids":[["0.6209","640","0","2"]],"ts":"1626995757034","checksum":1013855403}]}
1626995757.1129658: {"arg":{"channel":"books-l2-tbt","instId":"XMR-USDT-SWAP"},"action":"update","data":[{"asks":[],"bids":[["195.99","62","0","1"],["195.95","27","0","1"]],"ts":"1626995757062","checksum":-1141331487}]}
1626995757.133271: {"arg":{"channel":"books-l2-tbt","instId":"XMR-USDT-SWAP"},"action":"update","data":[{"asks":[["196.42","10","0","2"],["196.49","28","0","1"],["196.53","0","0","0"],["196.66","17","0","1"]],"bids":[],"ts":"1626995757084","checksum":267704502}]}
1626995757.159133: {"arg":{"channel":"books-l2-tbt","instId":"XMR-USDT-SWAP"},"action":"update","data":[{"asks":[["196.3","0","0","0"],["196.34","3","0","1"],["196.37","7","0","1"],["196.38","0","0","0"],["196.4","514","0","3"],["196.41","7","0","1"],["196.42","3","0","1"],["196.45","7","0","1"],["196.46","65","0","2"],["196.49","35","0","2"],["196.52","12","0","1"],["196.53","28","0","1"],["196.55","3","0","1"],["196.62","12","0","1"],["196.65","0","0","0"],["196.71","12","0","1"],["196.84","0","0","0"],["196.85","9","0","3"],["196.91","15","0","2"],["196.92","17","0","1"],["197.04","15","0","1"],["197.11","12","0","1"],["197.34","0","0","0"],["197.42","27","0","1"]],"bids":[],"ts":"1626995757105","checksum":1084945802}]}
1626995757.187916: {"arg":{"channel":"books-l2-tbt","instId":"FUN-BTC"},"action":"update","data":[{"asks":[],"bids":[["0.00000041","0","0","0"]],"ts":"1626995757138","checksum":446600849}]}
1626995757.217359: {"arg":{"channel":"books-l2-tbt","instId":"BTC-USD-210924-42000-P"},"action":"update","data":[{"asks":[],"bids":[["0.3345","0","0","0"],["0.334","300","0","1"]],"ts":"1626995757161","checksum":-1912795264}]}
1626995757.242412: {"arg":{"channel":"books-l2-tbt","instId":"XMR-USDT-SWAP"},"action":"update","data":[{"asks":[["196.4","39","0","2"],["196.43","475","0","1"]],"bids":[["196.03","23","0","1"],["196.02","186","0","1"]],"ts":"1626995757190","checksum":-1075454420}]}
1626995757.258207: {"arg":{"channel":"books-l2-tbt","instId":"XMR-USDT-SWAP"},"action":"update","data":[{"asks":[],"bids":[["196.03","209","0","2"],["196","44","0","1"]],"ts":"1626995757209","checksum":875819087}]}
1626995757.273175: {"arg":{"channel":"books-l2-tbt","instId":"BTC-USD-210924-42000-P"},"action":"update","data":[{"asks":[],"bids":[["0.335","0","0","0"],["0.3345","5","0","1"]],"ts":"1626995757223","checksum":-1924192720}]}
1626995757.282391: {"arg":{"channel":"books-l2-tbt","instId":"XMR-USDT-SWAP"},"action":"update","data":[{"asks":[["196.43","0","0","0"],["196.46","492","0","2"]],"bids":[["196.03","23","0","1"]],"ts":"1626995757232","checksum":-1100849802}]}
1626995757.301198: {"arg":{"channel":"books-l2-tbt","instId":"XMR-USDT-SWAP"},"action":"update","data":[{"asks":[["196.44","475","0","1"],["196.46","17","0","1"]],"bids":[],"ts":"1626995757250","checksum":1985148956}]}
1626995757.32203: {"arg":{"channel":"books-l2-tbt","instId":"XMR-USDT-SWAP"},"action":"update","data":[{"asks":[],"bids":[["195.93","46","0","1"]],"ts":"1626995757269","checksum":1478297853}]}
1626995757.3481338: {"arg":{"channel":"books-l2-tbt","instId":"ONT-USDT"},"action":"update","data":[{"asks":[],"bids":[["0.621","950","0","2"]],"ts":"1626995757289","checksum":-518264992}]}
1626995757.348268: {"arg":{"channel":"books-l2-tbt","instId":"XMR-USDT-SWAP"},"action":"update","data":[{"asks":[],"bids":[["196.03","209","0","2"]],"ts":"1626995757290","checksum":-49074450}]}
1626995757.363111: {"arg":{"channel":"books-l2-tbt","instId":"XMR-USDT-SWAP"},"action":"update","data":[{"asks":[],"bids":[["196.04","23","0","1"],["196.03","186","0","1"]],"ts":"1626995757311","checksum":-1922771188}]}
1626995757.381981: {"arg":{"channel":"books-l2-tbt","instId":"ONT-USDT"},"action":"update","data":[{"asks":[],"bids":[["0.621","1590","0","4"]],"ts":"1626995757329","checksum":-2130410289}]}
1626995757.38363: {"arg":{"channel":"books-l2-tbt","instId":"XMR-USDT-SWAP"},"action":"update","data":[{"asks":[["196.28","0","0","0"],["196.34","0","0","0"],["196.35","3","0","1"],["196.36","0","0","0"],["196.4","32","0","1"],["196.41","10","0","2"],["196.42","0","0","0"],["196.44","482","0","2"],["196.48","14","0","2"],["196.49","38","0","3"],["196.91","12","0","1"],["196.98","3","0","1"]],"bids":[["196.04","255","0","3"],["196.01","3","0","1"],["195.94","0","0","0"],["195.88","82","0","3"],["195.77","3","0","1"],["195.7","18","0","2"]],"ts":"1626995757333","checksum":-1290573462}]}
1626995757.400248: {"arg":{"channel":"books-l2-tbt","instId":"BTC-USD-210924-42000-P"},"action":"update","data":[{"asks":[],"bids":[["0.3345","305","0","2"],["0.334","0","0","0"]],"ts":"1626995757349","checksum":28342894}]}
1626995757.418221: {"arg":{"channel":"books-l2-tbt","instId":"PAY-BTC"},"action":"update","data":[{"asks":[],"bids":[["0.00000134","3711.654","0","4"]],"ts":"1626995757368","checksum":-581084138}]}
1626995757.425685: {"arg":{"channel":"books-l2-tbt","instId":"XMR-USDT-SWAP"},"action":"update","data":[{"asks":[],"bids":[["195.86","92","0","2"],["195.75","0","0","0"]],"ts":"1626995757375","checksum":900708065}]}
1626995757.481416: {"arg":{"channel":"books-l2-tbt","instId":"BTC-USD-210924-42000-P"},"action":"update","data":[{"asks":[],"bids":[["0.335","5","0","1"],["0.3345","300","0","1"]],"ts":"1626995757431","checksum":439282224}]}
1626995757.4860318: {"arg":{"channel":"books-l2-tbt","instId":"XMR-USDT-SWAP"},"action":"update","data":[{"asks":[["196.46","0","0","0"],["196.55","20","0","2"]],"bids":[],"ts":"1626995757435","checksum":404420682}]}
1626995757.491626: {"arg":{"channel":"books-l2-tbt","instId":"ONT-USDT"},"action":"update","data":[{"asks":[],"bids":[["0.6209","320","0","1"]],"ts":"1626995757440","checksum":-830628031}]}
1626995757.5024939: {"arg":{"channel":"books-l2-tbt","instId":"FUN-BTC"},"action":"update","data":[{"asks":[],"bids":[["0.000000417","6646.09","0","1"]],"ts":"1626995757453","checksum":-1713578279}]}
1626995757.579489: {"arg":{"channel":"books-l2-tbt","instId":"PAY-BTC"},"action":"update","data":[{"asks":[],"bids":[["0.00000135","3476.864","0","5"]],"ts":"1626995757529","checksum":683115118}]}
1626995757.593948: {"arg":{"channel":"books-l2-tbt","instId":"ONT-USDT"},"action":"update","data":[{"asks":[],"bids":[["0.6205","9535.328","0","1"]],"ts":"1626995757542","checksum":-1011071922}]}
1626995757.621173: {"arg":{"channel":"books-l2-tbt","instId":"ONT-USDT"},"action":"update","data":[{"asks":[],"bids":[["0.6165","1570.000621","0","1"]],"ts":"1626995757570","checksum":-1011071922}]}
1626995757.6267982: {"arg":{"channel":"books-l2-tbt","instId":"BTC-USD-210924-42000-P"},"action":"update","data":[{"asks":[["0.3415","305","0","2"],["0.342","0","0","0"]],"bids":[["0.3345","0","0","0"],["0.334","300","0","1"]],"ts":"1626995757575","checksum":317222885}]}
1626995757.6408288: {"arg":{"channel":"books-l2-tbt","instId":"ONT-USDT"},"action":"update","data":[{"asks":[],"bids":[["0.6209","0","0","0"]],"ts":"1626995757590","checksum":-903046485}]}
1626995757.650965: {"arg":{"channel":"books-l2-tbt","instId":"OKT-BTC"},"action":"update","data":[{"asks":[],"bids":[["0.001459","0","0","0"]],"ts":"1626995757601","checksum":68239467}]}
1626995757.663918: {"arg":{"channel":"books-l2-tbt","instId":"ONT-USDT"},"action":"update","data":[{"asks":[],"bids":[["0.6205","0","0","0"]],"ts":"1626995757612","checksum":-1672083252}]}
1626995757.667682: {"arg":{"channel":"books-l2-tbt","instId":"XMR-USDT-SWAP"},"action":"update","data":[{"asks":[],"bids":[["195.96","122","0","4"]],"ts":"1626995757618","checksum":-345770533}]}
1626995757.6825778: {"arg":{"channel":"books-l2-tbt","instId":"OKT-BTC"},"action":"update","data":[{"asks":[],"bids":[["0.00146","0","0","0"]],"ts":"1626995757632","checksum":1835166083}]}
1626995757.690719: {"arg":{"channel":"books-l2-tbt","instId":"BTC-USD-210924-42000-P"},"action":"update","data":[{"asks":[["0.341","5","0","1"],["0.3415","300","0","1"]],"bids":[["0.335","0","0","0"],["0.3345","5","0","1"]],"ts":"1626995757637","checksum":20748665}]}
1626995757.690877: {"arg":{"channel":"books-l2-tbt","instId":"OKT-BTC"},"action":"update","data":[{"asks":[],"bids":[["0.001458","1.27917322","0","1"]],"ts":"1626995757641","checksum":937251268}]}
1626995757.708649: {"arg":{"channel":"books-l2-tbt","instId":"BTC-USD-210924-42000-P"},"action":"update","data":[{"asks":[["0.3415","0","0","0"],["0.342","300","0","1"]],"bids":[["0.3345","305","0","2"],["0.334","0","0","0"]],"ts":"1626995757658","checksum":813493843}]}
1626995757.726273: {"arg":{"channel":"books-l2-tbt","instId":"OKT-BTC"},"action":"update","data":[{"asks":[],"bids":[["0.001308","0","0","0"]],"ts":"1626995757673","checksum":937251268}]}
1626995757.726312: {"arg":{"channel":"books-l2-tbt","instId":"AUCTION-USDT"},"action":"update","data":[{"asks":[],"bids":[["14.3","207.112192","0","1"]],"ts":"1626995757674","checksum":1100991073}]}
1626995757.784118: {"arg":{"channel":"books-l2-tbt","instId":"PAY-BTC"},"action":"update","data":[{"asks":[],"bids":[["0.00000135","3053.957","0","4"]],"ts":"1626995757730","checksum":-581084138}]}
1626995757.803939: {"arg":{"channel":"books-l2-tbt","instId":"OKT-BTC"},"action":"update","data":[{"asks":[],"bids":[["0.001451","2.28","0","2"]],"ts":"1626995757754","checksum":1738936482}]}
1626995757.856381: {"arg":{"channel":"books-l2-tbt","instId":"ONT-USDT"},"action":"update","data":[{"asks":[],"bids":[["0.621","1270","0","3"]],"ts":"1626995757806","checksum":397257658}]}
1626995757.8735201: {"arg":{"channel":"books-l2-tbt","instId":"XMR-USDT-SWAP"},"action":"update","data":[{"asks":[["196.4","507","0","2"],["196.44","7","0","1"]],"bids":[["196.04","69","0","2"],["196.03","0","0","0"]],"ts":"1626995757823","checksum":-1326694957}]}
1626995757.89632: {"arg":{"channel":"books-l2-tbt","instId":"BTC-USD-210924-42000-P"},"action":"update","data":[{"asks":[["0.341","0","0","0"],["0.3415","5","0","1"]],"bids":[["0.335","5","0","1"],["0.3345","300","0","1"]],"ts":"1626995757845","checksum":439282224}]}
1626995757.896372: {"arg":{"channel":"books-l2-tbt","instId":"ONT-USDT"},"action":"update","data":[{"asks":[],"bids":[["0.6211","448.84406","0","3"]],"ts":"1626995757846","checksum":-679053813}]}
1626995757.9063349: {"arg":{"channel":"books-l2-tbt","instId":"PAY-BTC"},"action":"update","data":[{"asks":[],"bids":[["0.00000134","4137.717","0","5"]],"ts":"1626995757854","checksum":-293096816}]}
1626995757.906371: {"arg":{"channel":"books-l2-tbt","instId":"OKT-BTC"},"action":"update","data":[{"asks":[],"bids":[["0.00145","11.4419931","0","3"]],"ts":"1626995757855","checksum":663762037}]}
1626995757.9379709: {"arg":{"channel":"books-l2-tbt","instId":"ONT-USDT"},"action":"update","data":[{"asks":[],"bids":[["0.6211","768.84406","0","4"],["0.621","630","0","1"]],"ts":"1626995757887","checksum":1993190717}]}
1626995757.95593: {"arg":{"channel":"books-l2-tbt","instId":"XMR-USDT-SWAP"},"action":"update","data":[{"asks":[],"bids":[["196.04","255","0","3"]],"ts":"1626995757906","checksum":708925821}]}
1626995757.959956: {"arg":{"channel":"books-l2-tbt","instId":"AUCTION-USDT"},"action":"update","data":[{"asks":[],"bids":[["14.25","151.647444","0","1"]],"ts":"1626995757910","checksum":-915200773}]}
1626995757.96819: {"arg":{"channel":"books-l2-tbt","instId":"ONT-USDT"},"action":"update","data":[{"asks":[],"bids":[["0.6212","75.725495","0","1"],["0.6211","691","0","3"]],"ts":"1626995757918","checksum":1717447184}]}
1626995757.977809: {"arg":{"channel":"books-l2-tbt","instId":"XMR-USDT-SWAP"},"action":"update","data":[{"asks":[["196.39","0","0","0"],["196.4","475","0","1"],["196.48","80","0","4"]],"bids":[["195.86","70","0","1"],["195.75","22","0","1"]],"ts":"1626995757927","checksum":1804166153}]}
1626995757.9897401: {"arg":{"channel":"books-l2-tbt","instId":"ONT-USDT"},"action":"update","data":[{"asks":[],"bids":[["0.6211","1011","0","4"]],"ts":"1626995757939","checksum":-884677289}]}
1626995758.061727: {"arg":{"channel":"books-l2-tbt","instId":"XMR-USDT-SWAP"},"action":"update","data":[{"asks":[],"bids":[["193.74","0","0","0"]],"ts":"1626995758011","checksum":1804166153}]}
1626995758.082658: {"arg":{"channel":"books-l2-tbt","instId":"XMR-USDT-SWAP"},"action":"update","data":[{"asks":[["196.47","32","0","1"],["196.48","48","0","3"]],"bids":[],"ts":"1626995758032","checksum":-905383462}]}
1626995758.1115599: {"arg":{"channel":"trades","instId":"FUN-BTC"},"data":[{"instId":"FUN-BTC","tradeId":"3435656","px":"0.000000454","sz":"10.61","side":"buy","ts":"1626995758056"}]}
1626995758.11214: {"arg":{"channel":"books-l2-tbt","instId":"ONT-USDT"},"action":"update","data":[{"asks":[],"bids":[["0.616","82","0","1"]],"ts":"1626995758061","checksum":-884677289}]}
1626995758.1166568: {"arg":{"channel":"books-l2-tbt","instId":"XMR-USDT-SWAP"},"action":"update","data":[{"asks":[["196.47","66","0","2"],["196.48","14","0","2"]],"bids":[],"ts":"1626995758066","checksum":1029284469}]}
1626995758.143048: {"arg":{"channel":"books-l2-tbt","instId":"XMR-USDT-SWAP"},"action":"update","data":[{"asks":[],"bids":[["195.27","9","0","1"]],"ts":"1626995758093","checksum":1029284469}]}
1626995758.152172: {"arg":{"channel":"books-l2-tbt","instId":"PAY-BTC"},"action":"update","data":[{"asks":[],"bids":[["0.00000134","3711.654","0","4"]],"ts":"1626995758102","checksum":-581084138}]}
1626995758.166552: {"arg":{"channel":"books-l2-tbt","instId":"TRX-USDT-210924"},"action":"update","data":[{"asks":[],"bids":[["0.00055","0","0","0"]],"ts":"1626995758116","checksum":-648087781}]}
1626995758.1934102: {"arg":{"channel":"books-l2-tbt","instId":"OKT-BTC"},"action":"update","data":[{"asks":[],"bids":[["0.00145","4.57","0","2"]],"ts":"1626995758143","checksum":-114331616}]}
1626995758.232033: {"arg":{"channel":"tickers","instId":"FUN-BTC"},"data":[{"instType":"SPOT","instId":"FUN-BTC","last":"0.000000454","lastSz":"10.61","askPx":"0.000000455","askSz":"142796.14","bidPx":"0.000000452","bidSz":"141211.03","open24h":"0.000000445","high24h":"0.000000467","low24h":"0.000000443","sodUtc0":"0.000000446","sodUtc8":"0.000000449","volCcy24h":"0.13","vol24h":"302446.72","ts":"1626995758178"}]}
1626995758.233384: {"arg":{"channel":"books-l2-tbt","instId":"OKT-BTC"},"action":"update","data":[{"asks":[],"bids":[["0.00147","6.608654","0","1"]],"ts":"1626995758183","checksum":-1152235077}]}
1626995758.245803: {"arg":{"channel":"books-l2-tbt","instId":"OKT-BTC"},"action":"update","data":[{"asks":[],"bids":[["0.00147","0","0","0"]],"ts":"1626995758194","checksum":-683903549}]}
1626995758.253085: {"arg":{"channel":"books-l2-tbt","instId":"PAY-BTC"},"action":"update","data":[{"asks":[["0.00000171","0","0","0"]],"bids":[],"ts":"1626995758203","checksum":1600511523}]}
1626995758.2634618: {"arg":{"channel":"books-l2-tbt","instId":"PAY-BTC"},"action":"update","data":[{"asks":[],"bids":[["0.00000135","3476.864","0","5"]],"ts":"1626995758213","checksum":21941747}]}
1626995758.345599: {"arg":{"channel":"books-l2-tbt","instId":"ONT-USDT"},"action":"update","data":[{"asks":[],"bids":[["0.6211","691","0","3"]],"ts":"1626995758294","checksum":1717447184}]}
1626995758.352125: {"arg":{"channel":"books-l2-tbt","instId":"DHT-USDT"},"action":"update","data":[{"asks":[["0.796","16","0","1"]],"bids":[],"ts":"1626995758302","checksum":1848307256}]}
1626995758.396218: {"arg":{"channel":"books-l2-tbt","instId":"ONT-USDT"},"action":"update","data":[{"asks":[],"bids":[["0.6211","371","0","2"]],"ts":"1626995758346","checksum":609669203}]}
1626995758.427829: {"arg":{"channel":"books-l2-tbt","instId":"OKT-BTC"},"action":"update","data":[{"asks":[],"bids":[["0.001471","9.66478906","0","3"]],"ts":"1626995758377","checksum":-1621218956}]}
1626995758.4377751: {"arg":{"channel":"books-l2-tbt","instId":"ONT-USDT"},"action":"update","data":[{"asks":[],"bids":[["0.6211","51","0","1"]],"ts":"1626995758387","checksum":-290172132}]}
1626995758.488561: {"arg":{"channel":"books-l2-tbt","instId":"ONT-USDT"},"action":"update","data":[{"asks":[],"bids":[["0.6208","19915.779","0","2"]],"ts":"1626995758438","checksum":1820711699}]}
1626995758.496962: {"arg":{"channel":"books-l2-tbt","instId":"XMR-USDT-SWAP"},"action":"update","data":[{"asks":[],"bids":[["196.04","69","0","2"]],"ts":"1626995758447","checksum":212697598}]}
1626995758.497841: {"arg":{"channel":"books-l2-tbt","instId":"ONT-USDT"},"action":"update","data":[{"asks":[],"bids":[["0.6212","395.725495","0","2"]],"ts":"1626995758449","checksum":-1362930497}]}
1626995758.540373: {"arg":{"channel":"books-l2-tbt","instId":"XMR-USDT-SWAP"},"action":"update","data":[{"asks":[],"bids":[["196.04","255","0","3"]],"ts":"1626995758488","checksum":1029284469}]}
1626995758.540457: {"arg":{"channel":"books-l2-tbt","instId":"ONT-USDT"},"action":"update","data":[{"asks":[],"bids":[["0.6212","715.725495","0","3"]],"ts":"1626995758489","checksum":933238421}]}
1626995758.550663: {"arg":{"channel":"books-l2-tbt","instId":"ONT-USDT"},"action":"update","data":[{"asks":[],"bids":[["0.6214","377.871136","0","3"]],"ts":"1626995758500","checksum":643135109}]}
1626995758.579749: {"arg":{"channel":"books-l2-tbt","instId":"XMR-USDT-SWAP"},"action":"update","data":[{"asks":[["196.28","25","0","1"]],"bids":[],"ts":"1626995758528","checksum":1432770888}]}
1626995758.591634: {"arg":{"channel":"books-l2-tbt","instId":"ONT-USDT"},"action":"update","data":[{"asks":[],"bids":[["0.6214","697.871136","0","4"]],"ts":"1626995758541","checksum":1523385594}]}
1626995758.603772: {"arg":{"channel":"books-l2-tbt","instId":"DHT-USDT"},"action":"update","data":[{"asks":[["0.794","423.1407","0","1"]],"bids":[],"ts":"1626995758549","checksum":-281303646}]}
1626995758.6464052: {"arg":{"channel":"books-l2-tbt","instId":"XMR-USDT-SWAP"},"action":"update","data":[{"asks":[],"bids":[["195.86","92","0","2"]],"ts":"1626995758590","checksum":1761402362}]}
1626995758.6620789: {"arg":{"channel":"books-l2-tbt","instId":"XMR-USDT-SWAP"},"action":"update","data":[{"asks":[],"bids":[["195.75","0","0","0"]],"ts":"1626995758612","checksum":524940307}]}
1626995758.72432: {"arg":{"channel":"books-l2-tbt","instId":"XMR-USDT-SWAP"},"action":"update","data":[{"asks":[["196.23","0","0","0"]],"bids":[],"ts":"1626995758673","checksum":-187260264}]}
1626995758.7545931: {"arg":{"channel":"books-l2-tbt","instId":"ONT-USDT"},"action":"update","data":[{"asks":[],"bids":[["0.6208","10381.841","0","1"]],"ts":"1626995758704","checksum":-654537483}]}
1626995758.763762: {"arg":{"channel":"books-l2-tbt","instId":"PAY-BTC"},"action":"update","data":[{"asks":[],"bids":[["0.00000135","3053.957","0","4"]],"ts":"1626995758712","checksum":1600511523}]}
1626995758.8764749: {"arg":{"channel":"books-l2-tbt","instId":"PAY-BTC"},"action":"update","data":[{"asks":[],"bids":[["0.00000134","4137.717","0","5"]],"ts":"1626995758826","checksum":1535976152}]}
1626995758.878714: {"arg":{"channel":"books-l2-tbt","instId":"ONT-USDT"},"action":"update","data":[{"asks":[],"bids":[["0.6212","395.725495","0","2"]],"ts":"1626995758828","checksum":1100992223}]}
1626995758.887785: {"arg":{"channel":"books-l2-tbt","instId":"ONT-USDT"},"action":"update","data":[{"asks":[],"bids":[["0.6212","75.725495","0","1"]],"ts":"1626995758837","checksum":1581438729}]}
1626995758.949904: {"arg":{"channel":"books-l2-tbt","instId":"ONT-USDT"},"action":"update","data":[{"asks":[["0.6219","0","0","0"],["1.1314","181.020619","0","1"]],"bids":[],"ts":"1626995758900","checksum":-437594417}]}
1626995758.9597518: {"arg":{"channel":"books-l2-tbt","instId":"ONT-USDT"},"action":"update","data":[{"asks":[],"bids":[["0.6213","1019.216549","0","2"],["0.6212","0","0","0"]],"ts":"1626995758910","checksum":-892588324}]}
1626995758.97162: {"arg":{"channel":"books-l2-tbt","instId":"XMR-USDT-SWAP"},"action":"update","data":[{"asks":[["196.26","0","0","0"],["196.66","250","0","2"],["196.83","0","0","0"],["197.26","0","0","0"],["197.27","233","0","1"]],"bids":[["195.99","0","0","0"],["194.84","233","0","1"],["194.83","0","0","0"],["194.2","233","0","1"],["194.19","4","0","1"]],"ts":"1626995758919","checksum":984965261}]}
1626995758.972265: {"arg":{"channel":"books-l2-tbt","instId":"AUCTION-USDT"},"action":"update","data":[{"asks":[],"bids":[["14.25","0","0","0"]],"ts":"1626995758923","checksum":1100991073}]}
1626995758.980947: {"arg":{"channel":"books-l2-tbt","instId":"ONT-USDT"},"action":"update","data":[{"asks":[["0.6219","85","0","1"],["1.1314","0","0","0"]],"bids":[],"ts":"1626995758931","checksum":113481055}]}
1626995758.990866: {"arg":{"channel":"books-l2-tbt","instId":"ONT-USDT"},"action":"update","data":[{"asks":[],"bids":[["0.6214","377.871136","0","3"]],"ts":"1626995758940","checksum":-366001316}]}
1626995759.000083: {"arg":{"channel":"books-l2-tbt","instId":"XMR-USDT-SWAP"},"action":"update","data":[{"asks":[["196.3","250","0","1"]],"bids":[["196.05","62","0","1"]],"ts":"1626995758949","checksum":-1675422907}]}
1626995759.001913: {"arg":{"channel":"books-l2-tbt","instId":"TRX-USDT-210924"},"action":"update","data":[{"asks":[["0.05588","0","0","0"],["0.05589","3","0","1"]],"bids":[],"ts":"1626995758951","checksum":-648087781}]}
1626995759.0112371: {"arg":{"channel":"books-l2-tbt","instId":"XMR-USDT-SWAP"},"action":"update","data":[{"asks":[],"bids":[["196.05","248","0","2"]],"ts":"1626995758960","checksum":-757012350}]}
1626995759.026015: {"arg":{"channel":"books-l2-tbt","instId":"ONT-USDT"},"action":"update","data":[{"asks":[],"bids":[["0.6214","3389.309942","0","4"]],"ts":"1626995758970","checksum":-608742345}]}
1626995759.0752718: {"arg":{"channel":"books-l2-tbt","instId":"XMR-USDT-SWAP"},"action":"update","data":[{"asks":[["196.4","0","0","0"],["196.43","464","0","1"]],"bids":[["196.05","0","0","0"],["196.04","69","0","2"],["196","106","0","2"]],"ts":"1626995759023","checksum":-1438211691}]}
1626995759.080637: {"arg":{"channel":"books-l2-tbt","instId":"ONT-USDT"},"action":"update","data":[{"asks":[],"bids":[["0.6213","945.539","0","1"],["0.6211","124.677549","0","2"]],"ts":"1626995759031","checksum":-2052729285}]}
1626995759.083236: {"arg":{"channel":"books-l2-tbt","instId":"TRX-USDT-210924"},"action":"update","data":[{"asks":[["0.05588","3","0","1"],["0.05589","0","0","0"]],"bids":[],"ts":"1626995759032","checksum":-648087781}]}
1626995759.091681: {"arg":{"channel":"books-l2-tbt","instId":"XMR-USDT-SWAP"},"action":"update","data":[{"asks":[["196.37","0","0","0"],["196.41","3","0","1"],["196.42","7","0","1"],["196.45","0","0","0"],["196.46","75","0","3"],["196.47","34","0","1"],["196.48","7","0","1"],["196.49","31","0","2"],["196.5","7","0","1"],["196.54","77","0","2"],["196.6","7","0","1"],["196.71","0","0","0"],["196.75","12","0","1"],["196.91","0","0","0"],["196.95","12","0","1"],["197.33","0","0","0"],["197.44","27","0","2"]],"bids":[["195.87","22","0","1"],["195.86","70","0","1"]],"ts":"1626995759042","checksum":1333403496}]}
1626995759.1305091: {"arg":{"channel":"books-l2-tbt","instId":"PAY-BTC"},"action":"update","data":[{"asks":[],"bids":[["0.00000134","3711.654","0","4"]],"ts":"1626995759078","checksum":1600511523}]}
1626995759.141376: {"arg":{"channel":"books-l2-tbt","instId":"ONT-USDT"},"action":"update","data":[{"asks":[],"bids":[["0.6215","320","0","1"]],"ts":"1626995759091","checksum":-1421585399}]}
1626995759.159681: {"arg":{"channel":"books-l2-tbt","instId":"XMR-USDT-SWAP"},"action":"update","data":[{"asks":[],"bids":[["196.04","255","0","3"]],"ts":"1626995759110","checksum":237343735}]}
1626995759.184036: {"arg":{"channel":"books-l2-tbt","instId":"ONT-USDT"},"action":"update","data":[{"asks":[],"bids":[["0.6213","1028.341664","0","2"],["0.6211","51","0","1"]],"ts":"1626995759132","checksum":-1208933449}]}
1626995759.201928: {"arg":{"channel":"books-l2-tbt","instId":"XMR-USDT-SWAP"},"action":"update","data":[{"asks":[["196.43","498","0","2"],["196.45","32","0","1"],["196.46","43","0","2"],["196.47","0","0","0"]],"bids":[],"ts":"1626995759151","checksum":-72140328}]}
1626995759.227496: {"arg":{"channel":"books-l2-tbt","instId":"AUCTION-USDT"},"action":"update","data":[{"asks":[],"bids":[["14.3","358.2294","0","2"]],"ts":"1626995759177","checksum":-716211462}]}
1626995759.2435908: {"arg":{"channel":"books-l2-tbt","instId":"PAY-BTC"},"action":"update","data":[{"asks":[],"bids":[["0.00000135","3476.864","0","5"]],"ts":"1626995759193","checksum":21941747}]}
1626995759.243725: {"arg":{"channel":"books-l2-tbt","instId":"ONT-USDT"},"action":"update","data":[{"asks":[],"bids":[["0.6215","960","0","3"]],"ts":"1626995759193","checksum":-1738824476}]}
1626995759.257051: {"arg":{"channel":"books-l2-tbt","instId":"FUN-BTC"},"action":"update","data":[{"asks":[],"bids":[["0.000000417","0","0","0"]],"ts":"1626995759205","checksum":446600849}]}
1626995759.308545: {"arg":{"channel":"books-l2-tbt","instId":"XMR-USDT-SWAP"},"action":"update","data":[{"asks":[["196.43","530","0","3"],["196.45","0","0","0"]],"bids":[],"ts":"1626995759257","checksum":1429268415}]}
1626995759.335472: {"arg":{"channel":"books-l2-tbt","instId":"ONT-USDT"},"action":"update","data":[{"asks":[],"bids":[["0.6215","1280","0","4"]],"ts":"1626995759286","checksum":-1306783328}]}
1626995759.397783: {"arg":{"channel":"books-l2-tbt","instId":"ONT-USDT"},"action":"update","data":[{"asks":[],"bids":[["0.6216","320","0","1"]],"ts":"1626995759336","checksum":1437407190}]}
1626995759.3979142: {"arg":{"channel":"books-l2-tbt","instId":"ONT-USDT"},"action":"update","data":[{"asks":[["0.622","603.334745","0","1"]],"bids":[["0.6214","3069.309942","0","3"]],"ts":"1626995759347","checksum":1531857556}]}
1626995759.407199: {"arg":{"channel":"books-l2-tbt","instId":"ONT-USDT"},"action":"update","data":[{"asks":[["0.6221","945.539","0","1"],["1.13","0","0","0"]],"bids":[],"ts":"1626995759357","checksum":-515728992}]}
1626995759.436105: {"arg":{"channel":"books-l2-tbt","instId":"XMR-USDT-SWAP"},"action":"update","data":[{"asks":[["196.43","66","0","2"],["196.46","614","0","3"]],"bids":[],"ts":"1626995759385","checksum":667077252}]}
1626995759.4545379: {"arg":{"channel":"books-l2-tbt","instId":"XMR-USDT-SWAP"},"action":"update","data":[{"asks":[["196.46","43","0","2"]],"bids":[],"ts":"1626995759404","checksum":819795404}]}
1626995759.4611042: {"arg":{"channel":"books-l2-tbt","instId":"ONT-USDT"},"action":"update","data":[{"asks":[],"bids":[["0.6195","47","0","1"]],"ts":"1626995759408","checksum":-267599024}]}
1626995759.4696052: {"arg":{"channel":"books-l2-tbt","instId":"ONT-USDT"},"action":"update","data":[{"asks":[],"bids":[["0.6201","402.868423","0","1"]],"ts":"1626995759420","checksum":-256476442}]}
1626995759.4753659: {"arg":{"channel":"books-l2-tbt","instId":"XMR-USDT-SWAP"},"action":"update","data":[{"asks":[["196.44","578","0","2"]],"bids":[],"ts":"1626995759425","checksum":-538390659}]}
1626995759.480874: {"arg":{"channel":"books-l2-tbt","instId":"ONT-USDT"},"action":"update","data":[{"asks":[],"bids":[["0.6215","960","0","3"]],"ts":"1626995759431","checksum":-2015600158}]}
1626995759.5022411: {"arg":{"channel":"books-l2-tbt","instId":"ONT-USDT"},"action":"update","data":[{"asks":[],"bids":[["0.6216","640","0","2"]],"ts":"1626995759452","checksum":-35578566}]}
1626995759.545415: {"arg":{"channel":"books-l2-tbt","instId":"FUN-BTC"},"action":"update","data":[{"asks":[],"bids":[["0.000000403","6876.94","0","1"]],"ts":"1626995759495","checksum":-118283910}]}
1626995759.5588071: {"arg":{"channel":"books-l2-tbt","instId":"XMR-USDT-SWAP"},"action":"update","data":[{"asks":[["197.75","0","0","0"]],"bids":[],"ts":"1626995759509","checksum":-538390659}]}
1626995759.581772: {"arg":{"channel":"books-l2-tbt","instId":"DHT-USDT"},"action":"update","data":[{"asks":[["0.794","0","0","0"]],"bids":[],"ts":"1626995759531","checksum":1848307256}]}
1626995759.60274: {"arg":{"channel":"books-l2-tbt","instId":"XMR-USDT-SWAP"},"action":"update","data":[{"asks":[["196.43","637","0","3"],["196.44","7","0","1"]],"bids":[["195.79","32","0","2"],["195.73","70","0","1"]],"ts":"1626995759552","checksum":-1935536242}]}
1626995759.63539: {"arg":{"channel":"books-l2-tbt","instId":"ONT-USDT"},"action":"update","data":[{"asks":[],"bids":[["0.6215","640","0","2"]],"ts":"1626995759585","checksum":-1411092600}]}
1626995759.6464489: {"arg":{"channel":"books-l2-tbt","instId":"XMR-USDT-SWAP"},"action":"update","data":[{"asks":[["197.86","510","0","2"]],"bids":[],"ts":"1626995759593","checksum":-1935536242}]}
1626995759.656159: {"arg":{"channel":"books-l2-tbt","instId":"ONT-USDT"},"action":"update","data":[{"asks":[],"bids":[["0.6191","0","0","0"]],"ts":"1626995759605","checksum":-164006520}]}
1626995759.6867352: {"arg":{"channel":"books-l2-tbt","instId":"XMR-USDT-SWAP"},"action":"update","data":[{"asks":[],"bids":[["196.04","69","0","2"]],"ts":"1626995759635","checksum":-839023855}]}
1626995759.690159: {"arg":{"channel":"books-l2-tbt","instId":"ONT-USDT"},"action":"update","data":[{"asks":[],"bids":[["0.6215","320","0","1"]],"ts":"1626995759636","checksum":-2107748845}]}
1626995759.708322: {"arg":{"channel":"books-l2-tbt","instId":"XMR-USDT-SWAP"},"action":"update","data":[{"asks":[["196.28","0","0","0"]],"bids":[],"ts":"1626995759658","checksum":-1241380384}]}
1626995759.7294312: {"arg":{"channel":"books-l2-tbt","instId":"XMR-USDT-SWAP"},"action":"update","data":[{"asks":[["196.43","1262","0","4"]],"bids":[],"ts":"1626995759678","checksum":970766063}]}
1626995759.748068: {"arg":{"channel":"books-l2-tbt","instId":"XMR-USDT-SWAP"},"action":"update","data":[{"asks":[["196.42","73","0","3"],["196.43","625","0","1"]],"bids":[["196.04","255","0","3"],["195.87","0","0","0"],["195.75","22","0","1"]],"ts":"1626995759697","checksum":-792338805}]}
1626995759.7481449: {"arg":{"channel":"books-l2-tbt","instId":"ONT-USDT"},"action":"update","data":[{"asks":[],"bids":[["0.6192","978.813384","0","2"]],"ts":"1626995759698","checksum":-1380913282}]}
1626995759.791184: {"arg":{"channel":"books-l2-tbt","instId":"ONT-USDT"},"action":"update","data":[{"asks":[],"bids":[["0.6215","0","0","0"]],"ts":"1626995759740","checksum":-1899362117}]}
1626995759.83906: {"arg":{"channel":"books-l2-tbt","instId":"DHT-USDT"},"action":"update","data":[{"asks":[["0.796","439.1407","0","2"]],"bids":[],"ts":"1626995759789","checksum":1586774313}]}
1626995759.875932: {"arg":{"channel":"books-l2-tbt","instId":"ONT-USDT"},"action":"update","data":[{"asks":[],"bids":[["0.6214","57.871136","0","2"]],"ts":"1626995759823","checksum":13788999}]}
1626995759.876065: {"arg":{"channel":"books-l2-tbt","instId":"XMR-USDT-SWAP"},"action":"update","data":[{"asks":[["196.24","0","0","0"],["196.32","44","0","1"]],"bids":[["195.87","22","0","1"],["195.75","0","0","0"]],"ts":"1626995759823","checksum":-1269832798}]}
1626995759.914582: {"arg":{"channel":"books-l2-tbt","instId":"XMR-USDT-SWAP"},"action":"update","data":[{"asks":[["196.22","103","0","2"]],"bids":[["196.04","325","0","4"]],"ts":"1626995759864","checksum":-28087262}]}
1626995759.933256: {"arg":{"channel":"books-l2-tbt","instId":"ONT-USDT"},"action":"update","data":[{"asks":[["0.622","1548.873745","0","2"],["0.6221","0","0","0"],["1.13","13919.895296","0","1"]],"bids":[],"ts":"1626995759883","checksum":1738521305}]}
1626995759.935734: {"arg":{"channel":"books-l2-tbt","instId":"BTC-USD-210924-42000-P"},"action":"update","data":[{"asks":[],"bids":[["0.334","301","0","1"],["0.3335","0","0","0"]],"ts":"1626995759884","checksum":-1431042442}]}
1626995759.9415329: {"arg":{"channel":"books-l2-tbt","instId":"PAY-BTC"},"action":"update","data":[{"asks":[["0.00000171","157.432","0","1"]],"bids":[],"ts":"1626995759890","checksum":683115118}]}
1626995759.943553: {"arg":{"channel":"books-l2-tbt","instId":"ONT-USDT"},"action":"update","data":[{"asks":[["0.6224","392.196878","0","2"],["0.6229","2730","0","2"]],"bids":[["0.6216","1280","0","4"]],"ts":"1626995759893","checksum":-1573835005}]}
1626995759.975884: {"arg":{"channel":"books-l2-tbt","instId":"XMR-USDT-SWAP"},"action":"update","data":[{"asks":[["196.43","0","0","0"]],"bids":[],"ts":"1626995759925","checksum":2125773106}]}
1626995759.9842932: {"arg":{"channel":"books-l2-tbt","instId":"ONT-USDT"},"action":"update","data":[{"asks":[["0.6219","0","0","0"],["1.1314","181.020619","0","1"]],"bids":[["0.6216","960","0","3"]],"ts":"1626995759935","checksum":1174403026}]}
1626995759.993888: {"arg":{"channel":"books-l2-tbt","instId":"XMR-USDT-SWAP"},"action":"update","data":[{"asks":[["196.43","625","0","1"]],"bids":[],"ts":"1626995759944","checksum":-28087262}]}
1626995760.0064378: {"arg":{"channel":"books-l2-tbt","instId":"ONT-USDT"},"action":"update","data":[{"asks":[["0.6219","85","0","1"],["1.1314","0","0","0"]],"bids":[["0.6205","9533.255","0","1"]],"ts":"1626995759954","checksum":-808893342}]}
1626995760.012387: {"arg":{"channel":"books-l2-tbt","instId":"PAY-BTC"},"action":"update","data":[{"asks":[],"bids":[["0.00000135","2476.864","0","4"]],"ts":"1626995759962","checksum":333410955}]}
1626995760.0465522: {"arg":{"channel":"books-l2-tbt","instId":"ONT-USDT"},"action":"update","data":[{"asks":[],"bids":[["0.6216","640","0","2"]],"ts":"1626995759994","checksum":29243261}]}
1626995760.073901: {"arg":{"channel":"books-l2-tbt","instId":"ONT-USDT"},"action":"update","data":[{"asks":[],"bids":[["0.6205","0","0","0"]],"ts":"1626995760023","checksum":-522677058}]}
1626995760.134197: {"arg":{"channel":"books-l2-tbt","instId":"ONT-USDT"},"action":"update","data":[{"asks":[],"bids":[["0.6215","320","0","1"]],"ts":"1626995760084","checksum":-1925404831}]}
1626995760.159803: {"arg":{"channel":"books-l2-tbt","instId":"XMR-USDT-SWAP"},"action":"update","data":[{"asks":[],"bids":[["195.79","17","0","1"],["195.75","15","0","1"]],"ts":"1626995760108","checksum":-276571574}]}
1626995760.176609: {"arg":{"channel":"books-l2-tbt","instId":"ONT-USDT"},"action":"update","data":[{"asks":[],"bids":[["0.6215","640","0","2"]],"ts":"1626995760126","checksum":-359298410}]}
1626995760.239518: {"arg":{"channel":"books-l2-tbt","instId":"XMR-USDT-SWAP"},"action":"update","data":[{"asks":[["196.43","0","0","0"]],"bids":[],"ts":"1626995760171","checksum":1605929971}]}
1626995760.246609: {"arg":{"channel":"books-l2-tbt","instId":"AUCTION-USDT"},"action":"update","data":[{"asks":[],"bids":[["14.3","207.112192","0","1"]],"ts":"1626995760191","checksum":1100991073}]}
1626995760.246743: {"arg":{"channel":"books-l2-tbt","instId":"XMR-USDT-SWAP"},"action":"update","data":[{"asks":[["196.43","625","0","1"]],"bids":[],"ts":"1626995760191","checksum":-276571574}]}
1626995760.2598321: {"arg":{"channel":"books-l2-tbt","instId":"ONT-USDT"},"action":"update","data":[{"asks":[],"bids":[["0.5899","0","0","0"]],"ts":"1626995760209","checksum":-359298410}]}
1626995760.282889: {"arg":{"channel":"books-l2-tbt","instId":"XMR-USDT-SWAP"},"action":"update","data":[{"asks":[],"bids":[["196.04","139","0","3"]],"ts":"1626995760233","checksum":-1756452995}]}
1626995760.303804: {"arg":{"channel":"books-l2-tbt","instId":"XMR-USDT-SWAP"},"action":"update","data":[{"asks":[["196.42","112","0","4"]],"bids":[],"ts":"1626995760254","checksum":1030934789}]}
1626995760.3220632: {"arg":{"channel":"books-l2-tbt","instId":"ONT-USDT"},"action":"update","data":[{"asks":[],"bids":[["0.6216","691","0","3"],["0.6215","3152.928018","0","3"],["0.6211","0","0","0"]],"ts":"1626995760272","checksum":-803283139}]}
1626995760.3385768: {"arg":{"channel":"books-l2-tbt","instId":"ONT-USDT"},"action":"update","data":[{"asks":[["0.622","945.539","0","1"]],"bids":[["0.5898","294.745676","0","1"]],"ts":"1626995760283","checksum":580237287}]}
1626995760.344425: {"arg":{"channel":"books-l2-tbt","instId":"ONT-USDT"},"action":"update","data":[{"asks":[["0.622","603.334745","0","1"],["0.6221","945.539","0","1"],["1.13","0","0","0"]],"bids":[["0.6216","371","0","2"]],"ts":"1626995760294","checksum":-1215445193}]}
1626995760.389302: {"arg":{"channel":"books-l2-tbt","instId":"XMR-USDT-SWAP"},"action":"update","data":[{"asks":[],"bids":[["196.04","325","0","4"]],"ts":"1626995760336","checksum":-2051557001}]}
1626995760.394955: {"arg":{"channel":"books-l2-tbt","instId":"ONT-USDT"},"action":"update","data":[{"asks":[],"bids":[["0.6216","51","0","1"]],"ts":"1626995760345","checksum":-120376452}]}
1626995760.424719: {"arg":{"channel":"books-l2-tbt","instId":"PAY-BTC"},"action":"update","data":[{"asks":[],"bids":[["0.00000135","2053.957","0","3"]],"ts":"1626995760372","checksum":-432689933}]}
1626995760.4255471: {"arg":{"channel":"books-l2-tbt","instId":"ONT-USDT"},"action":"update","data":[{"asks":[],"bids":[["0.6214","51","0","1"]],"ts":"1626995760376","checksum":411298487}]}
1626995760.427061: {"arg":{"channel":"books-l2-tbt","instId":"XMR-USDT-SWAP"},"action":"update","data":[{"asks":[["196.41","628","0","2"],["196.43","0","0","0"]],"bids":[],"ts":"1626995760378","checksum":1477294373}]}
1626995760.447826: {"arg":{"channel":"books-l2-tbt","instId":"ONT-USDT"},"action":"update","data":[{"asks":[],"bids":[["0.6217","6.866926","0","1"]],"ts":"1626995760393","checksum":-1933075252}]}
1626995760.473022: {"arg":{"channel":"books-l2-tbt","instId":"ONT-USDT"},"action":"update","data":[{"asks":[],"bids":[["0.6214","996.539","0","2"],["0.6213","82.802664","0","1"]],"ts":"1626995760416","checksum":852206305}]}
1626995760.478423: {"arg":{"channel":"books-l2-tbt","instId":"ONT-USDT"},"action":"update","data":[{"asks":[["0.622","0","0","0"],["1.13","13919.895296","0","1"]],"bids":[],"ts":"1626995760427","checksum":-1745943833}]}
1626995760.497001: {"arg":{"channel":"books-l2-tbt","instId":"ONT-USDT"},"action":"update","data":[{"asks":[["0.6219","0","0","0"],["1.1314","181.020619","0","1"]],"bids":[],"ts":"1626995760446","checksum":-1768409284}]}
1626995760.497046: {"arg":{"channel":"books-l2-tbt","instId":"AUCTION-USDT"},"action":"update","data":[{"asks":[],"bids":[["14.26","151.541099","0","1"]],"ts":"1626995760447","checksum":-104093712}]}
1626995760.5155241: {"arg":{"channel":"books-l2-tbt","instId":"ONT-USDT"},"action":"update","data":[{"asks":[["0.6221","0","0","0"],["0.6223","676.028601","0","2"],["1.1346","10.5","0","1"]],"bids":[],"ts":"1626995760457","checksum":824323504}]}
1626995760.519277: {"arg":{"channel":"books-l2-tbt","instId":"ONT-USDT"},"action":"update","data":[{"asks":[["0.6221","85","0","1"],["0.6226","486.341898","0","1"],["0.6244","88","0","1"],["1.1346","0","0","0"]],"bids":[["0.6215","3235.38726","0","4"],["0.6213","0","0","0"],["0.619","0","0","0"]],"ts":"1626995760468","checksum":1584382657}]}
1626995760.52652: {"arg":{"channel":"books-l2-tbt","instId":"PAY-BTC"},"action":"update","data":[{"asks":[],"bids":[["0.00000134","4137.717","0","5"]],"ts":"1626995760476","checksum":-705740171}]}
1626995760.527728: {"arg":{"channel":"books-l2-tbt","instId":"ONT-USDT"},"action":"update","data":[{"asks":[["0.6223","72.693856","0","1"],["0.6228","400.674506","0","1"],["1.1314","0","0","0"]],"bids":[["0.6215","722.459242","0","3"]],"ts":"1626995760477","checksum":-1763166280}]}
1626995760.537267: {"arg":{"channel":"books-l2-tbt","instId":"ONT-USDT"},"action":"update","data":[{"asks":[["0.6221","85","0","1"]],"bids":[],"ts":"1626995760487","checksum":-1763166280}]}
1626995760.5480142: {"arg":{"channel":"books-l2-tbt","instId":"ONT-USDT"},"action":"update","data":[{"asks":[["0.6221","1030.539","0","2"]],"bids":[["0.6215","402.459242","0","2"]],"ts":"1626995760497","checksum":-1702168005}]}
1626995760.563603: {"arg":{"channel":"books-l2-tbt","instId":"ONT-USDT"},"action":"update","data":[{"asks":[["0.6223","676.028601","0","2"]],"bids":[["0.6208","0","0","0"]],"ts":"1626995760507","checksum":-1819437174}]}
1626995760.5673358: {"arg":{"channel":"books-l2-tbt","instId":"ONT-USDT"},"action":"update","data":[{"asks":[],"bids":[["0.6201","0","0","0"]],"ts":"1626995760517","checksum":1714057906}]}
1626995760.57811: {"arg":{"channel":"books-l2-tbt","instId":"ONT-USDT"},"action":"update","data":[{"asks":[["0.622","3133.868204","0","1"],["1.13","0","0","0"]],"bids":[["0.6203","889.210321","0","2"]],"ts":"1626995760528","checksum":-434050192}]}
1626995760.5919921: {"arg":{"channel":"books-l2-tbt","instId":"ONT-USDT"},"action":"update","data":[{"asks":[],"bids":[["0.6214","51","0","1"]],"ts":"1626995760540","checksum":-1827775430}]}
1626995760.6023638: {"arg":{"channel":"books-l2-tbt","instId":"ONT-USDT"},"action":"update","data":[{"asks":[["0.6221","945.539","0","1"]],"bids":[],"ts":"1626995760548","checksum":-1871198141}]}
1626995760.6230872: {"arg":{"channel":"books-l2-tbt","instId":"ONT-USDT"},"action":"update","data":[{"asks":[["0.622","3218.868204","0","2"]],"bids":[["0.6191","6082.03996","0","1"]],"ts":"1626995760569","checksum":929549802}]}
1626995760.63041: {"arg":{"channel":"books-l2-tbt","instId":"ONT-USDT"},"action":"update","data":[{"asks":[["0.6222","82.459242","0","1"],["0.6223","603.334745","0","1"],["0.6245","6082.039962","0","1"],["1.1285","0","0","0"],["1.1288","0","0","0"]],"bids":[["0.6215","320","0","1"],["0.6211","82.459242","0","1"]],"ts":"1626995760580","checksum":-535642695}]}
1626995760.637693: {"arg":{"channel":"books-l2-tbt","instId":"ONT-USDT"},"action":"update","data":[{"asks":[],"bids":[["0.6215","0","0","0"]],"ts":"1626995760588","checksum":1078040469}]}
1626995760.6609821: {"arg":{"channel":"books-l2-tbt","instId":"ONT-USDT"},"action":"update","data":[{"asks":[],"bids":[["0.6208","10381.169","0","1"]],"ts":"1626995760608","checksum":-606355978}]}
1626995760.668021: {"arg":{"channel":"trades","instId":"OKT-BTC"},"data":[{"instId":"OKT-BTC","tradeId":"3406232","px":"0.001473","sz":"0.39720557","side":"sell","ts":"1626995760611"}]}
1626995760.668063: {"arg":{"channel":"books-l2-tbt","instId":"DHT-USDT"},"action":"update","data":[{"asks":[],"bids":[["0.734","2350","0","1"]],"ts":"1626995760617","checksum":100183748}]}
1626995760.6810281: {"arg":{"channel":"books-l2-tbt","instId":"ONT-USDT"},"action":"update","data":[{"asks":[],"bids":[["0.6214","996.539","0","2"]],"ts":"1626995760630","checksum":-2119005078}]}
1626995760.690311: {"arg":{"channel":"books-l2-tbt","instId":"DHT-USDT"},"action":"update","data":[{"asks":[],"bids":[["0.734","0","0","0"]],"ts":"1626995760636","checksum":1586774313}]}
1626995760.7017841: {"arg":{"channel":"books-l2-tbt","instId":"ONT-USDT"},"action":"update","data":[{"asks":[],"bids":[["0.6216","371","0","2"]],"ts":"1626995760650","checksum":-1257665393}]}
1626995760.7425568: {"arg":{"channel":"tickers","instId":"OKT-BTC"},"data":[{"instType":"SPOT","instId":"OKT-BTC","last":"0.001473","lastSz":"0.39720557","askPx":"0.001475","askSz":"10.622771","bidPx":"0.001471","bidSz":"9.66478906","open24h":"0.001402","high24h":"0.001489","low24h":"0.001387","sodUtc0":"0.001408","sodUtc8":"0.001437","volCcy24h":"17.15599394","vol24h":"12034.25057896","ts":"1626995760681"}]}
1626995760.821113: {"arg":{"channel":"books-l2-tbt","instId":"DHT-USDT"},"action":"update","data":[{"asks":[["0.796","16","0","1"]],"bids":[],"ts":"1626995760770","checksum":1848307256}]}
1626995760.9144409: {"arg":{"channel":"books-l2-tbt","instId":"ONT-USDT"},"action":"update","data":[{"asks":[["0.6228","0","0","0"],["1.1285","10.5","0","1"]],"bids":[],"ts":"1626995760864","checksum":1345615445}]}
1626995760.923007: {"arg":{"channel":"books-l2-tbt","instId":"XMR-USDT-SWAP"},"action":"update","data":[{"asks":[],"bids":[["196.04","139","0","3"]],"ts":"1626995760871","checksum":-523710121}]}
1626995760.9356108: {"arg":{"channel":"books-l2-tbt","instId":"ONT-USDT"},"action":"update","data":[{"asks":[["0.6226","887.016404","0","2"]],"bids":[],"ts":"1626995760885","checksum":-1913616673}]}
1626995760.962761: {"arg":{"channel":"books-l2-tbt","instId":"XMR-USDT-SWAP"},"action":"update","data":[{"asks":[["196.41","660","0","3"],["196.42","80","0","3"]],"bids":[["195.87","0","0","0"]],"ts":"1626995760912","checksum":-1677986}]}
1626995760.9787362: {"arg":{"channel":"books-l2-tbt","instId":"TRX-USDT-210924"},"action":"update","data":[{"asks":[["0.05588","0","0","0"],["0.05589","3","0","1"]],"bids":[],"ts":"1626995760928","checksum":-648087781}]}
1626995760.981007: {"arg":{"channel":"books-l2-tbt","instId":"XMR-USDT-SWAP"},"action":"update","data":[{"asks":[["196.41","694","0","4"],["196.42","46","0","2"]],"bids":[["196.04","325","0","4"],["195.75","37","0","2"]],"ts":"1626995760931","checksum":-612908738}]}
1626995760.9882612: {"arg":{"channel":"books-l2-tbt","instId":"ONT-USDT"},"action":"update","data":[{"asks":[],"bids":[["0.6212","320","0","1"]],"ts":"1626995760937","checksum":-1084571988}]}
1626995761.054871: {"arg":{"channel":"books-l2-tbt","instId":"DHT-USDT"},"action":"update","data":[{"asks":[["0.793","423.1407","0","1"]],"bids":[],"ts":"1626995761005","checksum":794339516}]}
1626995761.0766861: {"arg":{"channel":"books-l2-tbt","instId":"TRX-USDT-210924"},"action":"update","data":[{"asks":[["0.05588","3","0","1"],["0.05589","0","0","0"]],"bids":[],"ts":"1626995761027","checksum":-648087781}]}
1626995761.0922189: {"arg":{"channel":"books-l2-tbt","instId":"XMR-USDT-SWAP"},"action":"update","data":[{"asks":[],"bids":[["195.86","92","0","2"],["195.75","15","0","1"]],"ts":"1626995761031","checksum":-1471621089}]}
1626995761.0923579: {"arg":{"channel":"books-l2-tbt","instId":"ONT-USDT"},"action":"update","data":[{"asks":[],"bids":[["0.6214","1078.998242","0","3"],["0.6211","0","0","0"]],"ts":"1626995761038","checksum":318787974}]}
1626995761.10052: {"arg":{"channel":"books-l2-tbt","instId":"ONT-USDT"},"action":"update","data":[{"asks":[],"bids":[["0.6216","51","0","1"]],"ts":"1626995761050","checksum":995517589}]}
1626995761.216107: {"arg":{"channel":"books-l2-tbt","instId":"ONT-USDT"},"action":"update","data":[{"asks":[],"bids":[["0.6208","19914.369","0","2"]],"ts":"1626995761161","checksum":879362060}]}
1626995761.2774882: {"arg":{"channel":"books-l2-tbt","instId":"FUN-BTC"},"action":"update","data":[{"asks":[],"bids":[["0.000000403","0","0","0"]],"ts":"1626995761224","checksum":446600849}]}
1626995761.284628: {"arg":{"channel":"books-l2-tbt","instId":"ONT-USDT"},"action":"update","data":[{"asks":[],"bids":[["0.6208","10381.169","0","1"]],"ts":"1626995761234","checksum":995517589}]}
1626995761.29163: {"arg":{"channel":"books-l2-tbt","instId":"ONT-USDT"},"action":"update","data":[{"asks":[],"bids":[["0.6212","640","0","2"]],"ts":"1626995761242","checksum":1138253387}]}
1626995761.335753: {"arg":{"channel":"books-l2-tbt","instId":"ONT-USDT"},"action":"update","data":[{"asks":[],"bids":[["0.6212","1280","0","4"]],"ts":"1626995761286","checksum":-733654156}]}
1626995761.4210272: {"arg":{"channel":"books-l2-tbt","instId":"ONT-USDT"},"action":"update","data":[{"asks":[["0.6225","10380.932","0","1"],["1.1285","0","0","0"]],"bids":[],"ts":"1626995761369","checksum":-1040514386}]}
1626995761.438038: {"arg":{"channel":"books-l2-tbt","instId":"ONT-USDT"},"action":"update","data":[{"asks":[],"bids":[["0.6212","960","0","3"]],"ts":"1626995761388","checksum":673053102}]}
1626995761.449813: {"arg":{"channel":"books-l2-tbt","instId":"XMR-USDT-SWAP"},"action":"update","data":[{"asks":[["196.42","7","0","1"]],"bids":[["195.81","15","0","1"],["195.75","0","0","0"]],"ts":"1626995761399","checksum":-820204361}]}
1626995761.5008378: {"arg":{"channel":"books-l2-tbt","instId":"ONT-USDT"},"action":"update","data":[{"asks":[],"bids":[["0.6211","320","0","1"]],"ts":"1626995761449","checksum":829196621}]}
1626995761.512897: {"arg":{"channel":"books-l2-tbt","instId":"XMR-USDT-SWAP"},"action":"update","data":[{"asks":[],"bids":[["196.04","139","0","3"]],"ts":"1626995761462","checksum":-1052021178}]}
1626995761.55626: {"arg":{"channel":"books-l2-tbt","instId":"XMR-USDT-SWAP"},"action":"update","data":[{"asks":[["196.41","69","0","3"],["196.43","681","0","1"],["197.69","0","0","0"]],"bids":[],"ts":"1626995761504","checksum":-1882927796}]}
1626995761.572469: {"arg":{"channel":"books-l2-tbt","instId":"OKT-BTC"},"action":"update","data":[{"asks":[],"bids":[["0.001471","2.89090055","0","2"]],"ts":"1626995761519","checksum":-683903549}]}
1626995761.572599: {"arg":{"channel":"books-l2-tbt","instId":"FUN-BTC"},"action":"update","data":[{"asks":[],"bids":[["0.000000411","6743.09","0","1"]],"ts":"1626995761522","checksum":508841969}]}
1626995761.6340249: {"arg":{"channel":"books-l2-tbt","instId":"ONT-USDT"},"action":"update","data":[{"asks":[],"bids":[["0.5898","0","0","0"]],"ts":"1626995761584","checksum":829196621}]}
1626995761.636629: {"arg":{"channel":"books-l2-tbt","instId":"XMR-USDT-SWAP"},"action":"update","data":[{"asks":[["197.86","513","0","3"]],"bids":[["196.04","325","0","4"],["195.86","70","0","1"],["195.75","22","0","1"]],"ts":"1626995761587","checksum":2023597565}]}
1626995761.650696: {"arg":{"channel":"books-l2-tbt","instId":"ONT-USDT"},"action":"update","data":[{"asks":[],"bids":[["0.6212","640","0","2"]],"ts":"1626995761601","checksum":-861060669}]}
1626995761.6582808: {"arg":{"channel":"books-l2-tbt","instId":"XMR-USDT-SWAP"},"action":"update","data":[{"asks":[],"bids":[["195.81","0","0","0"],["195.75","37","0","2"]],"ts":"1626995761608","checksum":1304950522}]}
1626995761.673134: {"arg":{"channel":"books-l2-tbt","instId":"ONT-USDT"},"action":"update","data":[{"asks":[],"bids":[["0.5899","294.695711","0","1"]],"ts":"1626995761623","checksum":-861060669}]}
1626995761.6934998: {"arg":{"channel":"books-l2-tbt","instId":"ONT-USDT"},"action":"update","data":[{"asks":[],"bids":[["0.6212","320","0","1"]],"ts":"1626995761643","checksum":1678977503}]}
1626995761.734556: {"arg":{"channel":"books-l2-tbt","instId":"ONT-USDT"},"action":"update","data":[{"asks":[],"bids":[["0.6212","0","0","0"]],"ts":"1626995761684","checksum":525556460}]}
1626995761.738552: {"arg":{"channel":"books-l2-tbt","instId":"XMR-USDT-SWAP"},"action":"update","data":[{"asks":[],"bids":[["195.86","92","0","2"],["195.75","15","0","1"]],"ts":"1626995761688","checksum":-1838754856}]}
1626995761.754129: {"arg":{"channel":"books-l2-tbt","instId":"TRX-USDT-210924"},"action":"update","data":[{"asks":[["0.05588","0","0","0"],["0.05589","3","0","1"]],"bids":[],"ts":"1626995761703","checksum":-648087781}]}
1626995761.760579: {"arg":{"channel":"books-l2-tbt","instId":"XMR-USDT-SWAP"},"action":"update","data":[{"asks":[["203.77","0","0","0"],["203.92","1","0","1"]],"bids":[],"ts":"1626995761710","checksum":-1838754856}]}
1626995761.8069172: {"arg":{"channel":"books-l2-tbt","instId":"OKT-BTC"},"action":"update","data":[{"asks":[],"bids":[["0.001451","1.45","0","1"],["0.00145","11.4419931","0","3"]],"ts":"1626995761755","checksum":-970167483}]}
1626995761.836405: {"arg":{"channel":"books-l2-tbt","instId":"ONT-USDT"},"action":"update","data":[{"asks":[],"bids":[["0.6214","996.539","0","2"],["0.6212","90.463051","0","1"]],"ts":"1626995761786","checksum":-540849954}]}
1626995761.86544: {"arg":{"channel":"books-l2-tbt","instId":"TRX-USDT-210924"},"action":"update","data":[{"asks":[["0.05588","3","0","1"],["0.05589","0","0","0"]],"bids":[],"ts":"1626995761815","checksum":-648087781}]}
1626995761.897967: {"arg":{"channel":"books-l2-tbt","instId":"OKT-BTC"},"action":"update","data":[{"asks":[],"bids":[["0.001445","0","0","0"]],"ts":"1626995761847","checksum":551012187}]}
1626995761.94106: {"arg":{"channel":"books-l2-tbt","instId":"ONT-USDT"},"action":"update","data":[{"asks":[],"bids":[["0.6211","0","0","0"]],"ts":"1626995761889","checksum":-961398723}]}
1626995762.0124412: {"arg":{"channel":"books-l2-tbt","instId":"ONT-USDT"},"action":"update","data":[{"asks":[["0.622","3133.868204","0","1"]],"bids":[],"ts":"1626995761961","checksum":1845337103}]}
1626995762.0326898: {"arg":{"channel":"books-l2-tbt","instId":"ONT-USDT"},"action":"update","data":[{"asks":[["0.622","3218.868204","0","2"]],"bids":[],"ts":"1626995761983","checksum":-961398723}]}
1626995762.042145: {"arg":{"channel":"books-l2-tbt","instId":"DHT-USDT"},"action":"update","data":[{"asks":[["0.793","0","0","0"]],"bids":[],"ts":"1626995761992","checksum":1848307256}]}
1626995762.083609: {"arg":{"channel":"books-l2-tbt","instId":"ONT-USDT"},"action":"update","data":[{"asks":[],"bids":[],"ts":"1626995762032","checksum":-961398723}]}
1626995762.094558: {"arg":{"channel":"books-l2-tbt","instId":"XMR-USDT-SWAP"},"action":"update","data":[{"asks":[],"bids":[["188.37","1","0","1"],["188.23","0","0","0"]],"ts":"1626995762041","checksum":-1838754856}]}
1626995762.10296: {"arg":{"channel":"books-l2-tbt","instId":"OKT-BTC"},"action":"update","data":[{"asks":[],"bids":[["0.001471","2.64188214","0","1"]],"ts":"1626995762052","checksum":124865235}]}
1626995762.1579149: {"arg":{"channel":"books-l2-tbt","instId":"XMR-USDT-SWAP"},"action":"update","data":[{"asks":[],"bids":[["196.04","139","0","3"]],"ts":"1626995762107","checksum":1490175632}]}
1626995762.177661: {"arg":{"channel":"books-l2-tbt","instId":"XMR-USDT-SWAP"},"action":"update","data":[{"asks":[],"bids":[["195.86","70","0","1"],["195.75","37","0","2"]],"ts":"1626995762127","checksum":-2022480974}]}
1626995762.2377212: {"arg":{"channel":"books-l2-tbt","instId":"TRX-USDT-210924"},"action":"update","data":[{"asks":[],"bids":[],"ts":"1626995762174","checksum":-648087781}]}
1626995762.2872682: {"arg":{"channel":"books-l2-tbt","instId":"DHT-USDT"},"action":"update","data":[{"asks":[["0.795","423.1407","0","1"]],"bids":[],"ts":"1626995762235","checksum":-2020901621}]}
1626995762.299274: {"arg":{"channel":"books-l2-tbt","instId":"AUCTION-USDT"},"action":"update","data":[{"asks":[],"bids":[["14.26","0","0","0"]],"ts":"1626995762248","checksum":1100991073}]}
1626995762.3076348: {"arg":{"channel":"books-l2-tbt","instId":"OKT-BTC"},"action":"update","data":[{"asks":[],"bids":[["0.001451","1.70245078","0","2"]],"ts":"1626995762257","checksum":-929030240}]}
1626995762.574025: {"arg":{"channel":"books-l2-tbt","instId":"TRX-USDT-210924"},"action":"update","data":[{"asks":[],"bids":[["0.05443","20","0","1"]],"ts":"1626995762465","checksum":260978794}]}
1626995762.574058: {"arg":{"channel":"books-l2-tbt","instId":"ONT-USDT"},"action":"update","data":[{"asks":[],"bids":[["0.6208","19916.425","0","2"]],"ts":"1626995762474","checksum":-1620613804}]}
1626995762.5740852: {"arg":{"channel":"books-l2-tbt","instId":"TRX-USDT-210924"},"action":"update","data":[{"asks":[],"bids":[["0.05442","134","0","2"]],"ts":"1626995762475","checksum":-488048100}]}
1626995762.5741088: {"arg":{"channel":"books-l2-tbt","instId":"AUCTION-USDT"},"action":"update","data":[{"asks":[],"bids":[["14.31","159.011605","0","2"]],"ts":"1626995762496","checksum":-2058340696}]}
1626995762.613258: {"arg":{"channel":"books-l2-tbt","instId":"TRX-USDT-210924"},"action":"update","data":[{"asks":[["0.05451","14","0","1"]],"bids":[],"ts":"1626995762559","checksum":1349174330}]}
1626995762.6319182: {"arg":{"channel":"books-l2-tbt","instId":"TRX-USDT-210924"},"action":"update","data":[{"asks":[],"bids":[["0.05443","34","0","2"],["0.05442","120","0","1"]],"ts":"1626995762580","checksum":1809631549}]}
1626995762.710387: {"arg":{"channel":"books-l2-tbt","instId":"ONT-USDT"},"action":"update","data":[{"asks":[["0.6225","0","0","0"],["1.1285","10.5","0","1"]],"bids":[],"ts":"1626995762659","checksum":1641017802}]}
1626995762.792877: {"arg":{"channel":"books-l2-tbt","instId":"TRX-USDT-210924"},"action":"update","data":[{"asks":[["0.05588","0","0","0"],["0.05589","3","0","1"]],"bids":[["0.05422","0","0","0"],["0.05421","3","0","1"]],"ts":"1626995762742","checksum":1799674154}]}
1626995762.844893: {"arg":{"channel":"books-l2-tbt","instId":"TRX-USDT-210924"},"action":"update","data":[{"asks":[],"bids":[["0.05444","20","0","1"]],"ts":"1626995762793","checksum":1845861043}]}
1626995762.853751: {"arg":{"channel":"books-l2-tbt","instId":"TRX-USDT-210924"},"action":"update","data":[{"asks":[],"bids":[["0.05422","3","0","1"],["0.05421","0","0","0"]],"ts":"1626995762803","checksum":1855818404}]}
1626995762.871161: {"arg":{"channel":"books-l2-tbt","instId":"ONT-USDT"},"action":"update","data":[{"asks":[["0.6229","1970","0","1"]],"bids":[],"ts":"1626995762821","checksum":-116380896}]}
1626995762.901255: {"arg":{"channel":"books-l2-tbt","instId":"XMR-USDT-SWAP"},"action":"update","data":[{"asks":[["196.5","47","0","2"]],"bids":[],"ts":"1626995762847","checksum":1996503281}]}
1626995762.9054332: {"arg":{"channel":"books-l2-tbt","instId":"TRX-USDT-210924"},"action":"update","data":[{"asks":[],"bids":[["0.05444","104","0","2"]],"ts":"1626995762854","checksum":1809631549}]}
1626995762.92505: {"arg":{"channel":"books-l2-tbt","instId":"ONT-USDT"},"action":"update","data":[{"asks":[["0.6226","11266.400404","0","3"]],"bids":[],"ts":"1626995762875","checksum":-2121686441}]}
1626995762.9783192: {"arg":{"channel":"books-l2-tbt","instId":"TRX-USDT-210924"},"action":"update","data":[{"asks":[],"bids":[["0.05443","42","0","3"]],"ts":"1626995762923","checksum":968901348}]}
1626995763.029449: {"arg":{"channel":"books-l2-tbt","instId":"ONT-USDT"},"action":"update","data":[{"asks":[["0.622","3133.868204","0","1"]],"bids":[],"ts":"1626995762978","checksum":521193848}]}
1626995763.091933: {"arg":{"channel":"books-l2-tbt","instId":"XMR-USDT-SWAP"},"action":"update","data":[{"asks":[],"bids":[["195.81","15","0","1"],["195.75","22","0","1"]],"ts":"1626995763040","checksum":-277496901}]}
1626995763.1038349: {"arg":{"channel":"books-l2-tbt","instId":"TRX-USDT-210924"},"action":"update","data":[{"asks":[],"bids":[["0.05443","28","0","2"]],"ts":"1626995763050","checksum":1315491718}]}
1626995763.119912: {"arg":{"channel":"books-l2-tbt","instId":"TRX-USDT-210924"},"action":"update","data":[{"asks":[],"bids":[["0.05442","134","0","2"]],"ts":"1626995763060","checksum":-1559360016}]}
1626995763.1199841: {"arg":{"channel":"tickers","instId":"ONT-USDT"},"data":[{"instType":"SPOT","instId":"ONT-USDT","last":"0.6217","lastSz":"0","askPx":"0.622","askSz":"3218.868204","bidPx":"0.6217","bidSz":"6.866926","open24h":"0.6075","high24h":"0.6314","low24h":"0.5967","sodUtc0":"0.6131","sodUtc8":"0.6275","volCcy24h":"9394663.377594","vol24h":"15283902.427098","ts":"1626995763055"}]}
1626995763.128383: {"arg":{"channel":"books-l2-tbt","instId":"TRX-USDT-210924"},"action":"update","data":[{"asks":[["0.05589","0","0","0"],["0.0559","3","0","1"]],"bids":[],"ts":"1626995763070","checksum":-1559360016}]}
1626995763.128513: {"arg":{"channel":"tickers","instId":"TRX-USDT-210924"},"data":[{"instType":"FUTURES","instId":"TRX-USDT-210924","last":"0.0545","lastSz":"0","askPx":"0.05451","askSz":"14","bidPx":"0.05448","bidSz":"2","open24h":"0.05332","high24h":"0.05491","low24h":"0.05244","sodUtc0":"0.05345","sodUtc8":"0.05461","volCcy24h":"62416000","vol24h":"62416","ts":"1626995763053"}]}
1626995763.165549: {"arg":{"channel":"tickers","instId":"XMR-USDT-SWAP"},"data":[{"instType":"SWAP","instId":"XMR-USDT-SWAP","last":"196.06","lastSz":"0","askPx":"196.22","askSz":"103","bidPx":"196.04","bidSz":"139","open24h":"197.32","high24h":"202.54","low24h":"189.85","sodUtc0":"196.66","sodUtc8":"199.56","volCcy24h":"65228.1","vol24h":"652281","ts":"1626995763110"}]}
1626995763.182935: {"arg":{"channel":"books-l2-tbt","instId":"TRX-USDT-210924"},"action":"update","data":[{"asks":[],"bids":[["0.05423","4","0","2"],["0.05422","0","0","0"]],"ts":"1626995763130","checksum":-1413357423}]}
1626995763.2200918: {"arg":{"channel":"books-l2-tbt","instId":"ONT-USDT"},"action":"update","data":[{"asks":[["0.622","3218.868204","0","2"]],"bids":[],"ts":"1626995763169","checksum":-2121686441}]}
1626995763.237112: {"arg":{"channel":"books-l2-tbt","instId":"XMR-USDT-SWAP"},"action":"update","data":[{"asks":[],"bids":[["196.04","325","0","4"]],"ts":"1626995763184","checksum":1471206345}]}
1626995763.241083: {"arg":{"channel":"tickers","instId":"BTC-USD-210924-42000-P"},"data":[{"instType":"OPTION","instId":"BTC-USD-210924-42000-P","last":"0.2075","lastSz":"0","askPx":"0.3415","askSz":"5","bidPx":"0.335","bidSz":"5","open24h":"0.2075","high24h":"0.2075","low24h":"0.2075","sodUtc0":"0.2075","sodUtc8":"0.2075","volCcy24h":"0","vol24h":"0","ts":"1626995763169"}]}
1626995763.241143: {"arg":{"channel":"tickers","instId":"PAY-BTC"},"data":[{"instType":"SPOT","instId":"PAY-BTC","last":"0.00000138","lastSz":"0","askPx":"0.00000139","askSz":"4702.072","bidPx":"0.00000136","bidSz":"6884.955","open24h":"0.00000136","high24h":"0.00000144","low24h":"0.00000136","sodUtc0":"0.00000138","sodUtc8":"0.00000138","volCcy24h":"45.1","vol24h":"32751510.334","ts":"1626995763188"}]}
1626995763.256665: {"arg":{"channel":"books-l2-tbt","instId":"XMR-USDT-SWAP"},"action":"update","data":[{"asks":[["196.46","7","0","1"]],"bids":[],"ts":"1626995763204","checksum":-1744885407}]}
1626995763.286073: {"arg":{"channel":"tickers","instId":"FUN-BTC"},"data":[{"instType":"SPOT","instId":"FUN-BTC","last":"0.000000454","lastSz":"0","askPx":"0.000000455","askSz":"142796.14","bidPx":"0.000000452","bidSz":"141211.03","open24h":"0.000000444","high24h":"0.000000467","low24h":"0.000000443","sodUtc0":"0.000000446","sodUtc8":"0.000000449","volCcy24h":"0.13","vol24h":"302296.51","ts":"1626995763228"}]}
1626995763.2947829: {"arg":{"channel":"books-l2-tbt","instId":"XMR-USDT-SWAP"},"action":"update","data":[{"asks":[],"bids":[["195.87","22","0","1"],["195.81","0","0","0"],["195.75","15","0","1"]],"ts":"1626995763244","checksum":1368086384}]}
1626995763.305089: {"arg":{"channel":"books-l2-tbt","instId":"TRX-USDT-210924"},"action":"update","data":[{"asks":[],"bids":[["0.05444","20","0","1"],["0.05442","120","0","1"]],"ts":"1626995763253","checksum":-392670173}]}
1626995763.315648: {"arg":{"channel":"books-l2-tbt","instId":"TRX-USDT-210924"},"action":"update","data":[{"asks":[],"bids":[["0.05443","42","0","3"]],"ts":"1626995763263","checksum":744150323}]}
1626995763.3356202: {"arg":{"channel":"books-l2-tbt","instId":"FUN-BTC"},"action":"update","data":[{"asks":[],"bids":[["0.000000411","0","0","0"]],"ts":"1626995763285","checksum":446600849}]}
1626995763.357355: {"arg":{"channel":"books-l2-tbt","instId":"TRX-USDT-210924"},"action":"update","data":[{"asks":[],"bids":[["0.05442","240","0","2"]],"ts":"1626995763306","checksum":-10831389}]}
1626995763.357483: {"arg":{"channel":"books-l2-tbt","instId":"XMR-USDT-SWAP"},"action":"update","data":[{"asks":[["196.43","0","0","0"],["196.46","809","0","2"]],"bids":[],"ts":"1626995763307","checksum":-1134839513}]}
1626995763.370347: {"arg":{"channel":"books-l2-tbt","instId":"DHT-USDT"},"action":"update","data":[{"asks":[],"bids":[["0.72","0","0","0"]],"ts":"1626995763320","checksum":331813306}]}
1626995763.427958: {"arg":{"channel":"trades","instId":"PAY-BTC"},"data":[{"instId":"PAY-BTC","tradeId":"6071313","px":"0.00000138","sz":"3038.079","side":"sell","ts":"1626995763370"}]}
1626995763.428061: {"arg":{"channel":"books-l2-tbt","instId":"TRX-USDT-210924"},"action":"update","data":[{"asks":[],"bids":[["0.05442","120","0","1"]],"ts":"1626995763376","checksum":744150323}]}
1626995763.481854: {"arg":{"channel":"books-l2-tbt","instId":"TRX-USDT-210924"},"action":"update","data":[{"asks":[],"bids":[["0.05445","84","0","2"]],"ts":"1626995763430","checksum":876851817}]}
1626995763.528045: {"arg":{"channel":"books-l2-tbt","instId":"AUCTION-USDT"},"action":"update","data":[{"asks":[],"bids":[["14.31","8","0","1"]],"ts":"1626995763467","checksum":1100991073}]}
1626995763.556705: {"arg":{"channel":"books-l2-tbt","instId":"TRX-USDT-210924"},"action":"update","data":[{"asks":[],"bids":[["0.05445","8","0","1"],["0.05442","0","0","0"]],"ts":"1626995763501","checksum":-1783399886}]}
1626995763.6196659: {"arg":{"channel":"books-l2-tbt","instId":"TRX-USDT-210924"},"action":"update","data":[{"asks":[],"bids":[["0.05444","104","0","2"],["0.05443","141","0","4"]],"ts":"1626995763563","checksum":1648587038}]}
1626995763.6198049: {"arg":{"channel":"books-l2-tbt","instId":"DHT-USDT"},"action":"update","data":[{"asks":[["0.795","0","0","0"]],"bids":[],"ts":"1626995763563","checksum":171003263}]}
1626995763.634241: {"arg":{"channel":"books-l2-tbt","instId":"TRX-USDT-210924"},"action":"update","data":[{"asks":[["0.05452","2","0","1"]],"bids":[],"ts":"1626995763584","checksum":1122761557}]}
1626995763.639765: {"arg":{"channel":"books-l2-tbt","instId":"FUN-BTC"},"action":"update","data":[{"asks":[],"bids":[["0.000000409","6776.08","0","1"]],"ts":"1626995763588","checksum":1333387825}]}
1626995763.6622: {"arg":{"channel":"books-l2-tbt","instId":"XMR-USDT-SWAP"},"action":"update","data":[{"asks":[["197.85","4","0","1"]],"bids":[],"ts":"1626995763612","checksum":-1134839513}]}
1626995763.676116: {"arg":{"channel":"books-l2-tbt","instId":"TRX-USDT-210924"},"action":"update","data":[{"asks":[],"bids":[["0.05444","20","0","1"]],"ts":"1626995763624","checksum":1159097276}]}
1626995763.735884: {"arg":{"channel":"books-l2-tbt","instId":"TRX-USDT-210924"},"action":"update","data":[{"asks":[],"bids":[["0.05446","68","0","1"]],"ts":"1626995763685","checksum":-699238096}]}
1626995763.761867: {"arg":{"channel":"books-l2-tbt","instId":"AUCTION-USDT"},"action":"update","data":[{"asks":[],"bids":[["14.27","151.434904","0","1"]],"ts":"1626995763711","checksum":410895283}]}
1626995763.765588: {"arg":{"channel":"books-l2-tbt","instId":"XMR-USDT-SWAP"},"action":"update","data":[{"asks":[["197.86","520","0","4"]],"bids":[],"ts":"1626995763715","checksum":-1134839513}]}
1626995763.797631: {"arg":{"channel":"books-l2-tbt","instId":"TRX-USDT-210924"},"action":"update","data":[{"asks":[],"bids":[["0.05446","0","0","0"],["0.05443","42","0","3"]],"ts":"1626995763748","checksum":615478423}]}
1626995763.8057332: {"arg":{"channel":"tickers","instId":"DHT-USDT"},"data":[{"instType":"SPOT","instId":"DHT-USDT","last":"0.757","lastSz":"0","askPx":"0.759","askSz":"0.119353","bidPx":"0.751","bidSz":"116.167814","open24h":"0.749","high24h":"0.759","low24h":"0.749","sodUtc0":"0.753","sodUtc8":"0.756","volCcy24h":"108329.347523","vol24h":"143565.772134","ts":"1626995763745"}]}
1626995763.822975: {"arg":{"channel":"books-l2-tbt","instId":"DHT-USDT"},"action":"update","data":[{"asks":[["0.79","0","0","0"]],"bids":[],"ts":"1626995763770","checksum":-765150260}]}
1626995763.843081: {"arg":{"channel":"tickers","instId":"BTC-USD-210924-66000-C"},"data":[{"instType":"OPTION","instId":"BTC-USD-210924-66000-C","last":"0.0065","lastSz":"0","askPx":"0.008","askSz":"300","bidPx":"0.0065","bidSz":"5","open24h":"0.006","high24h":"0.0065","low24h":"0.006","sodUtc0":"0.006","sodUtc8":"0.0065","volCcy24h":"0.2","vol24h":"2","ts":"1626995763789"}]}
1626995763.860311: {"arg":{"channel":"books-l2-tbt","instId":"DHT-USDT"},"action":"update","data":[{"asks":[["0.81","423.1407","0","1"]],"bids":[],"ts":"1626995763810","checksum":-890966048}]}
1626995763.8605912: {"arg":{"channel":"books-l2-tbt","instId":"TRX-USDT-210924"},"action":"update","data":[{"asks":[],"bids":[["0.05444","104","0","2"],["0.05442","120","0","1"]],"ts":"1626995763810","checksum":-697698098}]}
1626995763.9057012: {"arg":{"channel":"tickers","instId":"AUCTION-USDT"},"data":[{"instType":"SPOT","instId":"AUCTION-USDT","last":"14.87","lastSz":"0","askPx":"14.98","askSz":"2.665343","bidPx":"14.83","bidSz":"2.701428","open24h":"14.94","high24h":"15.43","low24h":"14.22","sodUtc0":"14.94","sodUtc8":"14.86","volCcy24h":"117848.293617","vol24h":"7932.004463","ts":"1626995763849"}]}
1626995763.965324: {"arg":{"channel":"books-l2-tbt","instId":"ONT-USDT"},"action":"update","data":[{"asks":[],"bids":[["0.6208","10381.169","0","1"]],"ts":"1626995763915","checksum":-404104149}]}
1626995764.015947: {"arg":{"channel":"books-l2-tbt","instId":"OKT-BTC"},"action":"update","data":[{"asks":[],"bids":[["0.00145","13.9119931","0","4"]],"ts":"1626995763964","checksum":-1073753761}]}
1626995764.031704: {"arg":{"channel":"tickers","instId":"PAY-BTC"},"data":[{"instType":"SPOT","instId":"PAY-BTC","last":"0.00000138","lastSz":"3038.079","askPx":"0.00000139","askSz":"4702.072","bidPx":"0.00000136","bidSz":"6884.955","open24h":"0.00000136","high24h":"0.00000144","low24h":"0.00000136","sodUtc0":"0.00000138","sodUtc8":"0.00000138","volCcy24h":"45.105","vol24h":"32754548.413","ts":"1626995763977"}]}
1626995764.107347: {"arg":{"channel":"books-l2-tbt","instId":"DHT-USDT"},"action":"update","data":[{"asks":[],"bids":[["0.736","816.2848","0","2"]],"ts":"1626995764057","checksum":321480543}]}
1626995764.1151319: {"arg":{"channel":"trades","instId":"FUN-BTC"},"data":[{"instId":"FUN-BTC","tradeId":"3435657","px":"0.000000454","sz":"14.69","side":"buy","ts":"1626995764061"}]}
1626995764.118409: {"arg":{"channel":"books-l2-tbt","instId":"ONT-USDT"},"action":"update","data":[{"asks":[],"bids":[["0.6205","9538.458","0","1"]],"ts":"1626995764068","checksum":1946151866}]}
1626995764.158108: {"arg":{"channel":"books-l2-tbt","instId":"TRX-USDT-210924"},"action":"update","data":[{"asks":[],"bids":[["0.00055","1","0","1"]],"ts":"1626995764106","checksum":-697698098}]}
1626995764.193596: {"arg":{"channel":"tickers","instId":"FUN-BTC"},"data":[{"instType":"SPOT","instId":"FUN-BTC","last":"0.000000454","lastSz":"14.69","askPx":"0.000000455","askSz":"142796.14","bidPx":"0.000000452","bidSz":"141211.03","open24h":"0.000000444","high24h":"0.000000467","low24h":"0.000000443","sodUtc0":"0.000000446","sodUtc8":"0.000000449","volCcy24h":"0.13","vol24h":"302311.2","ts":"1626995764132"}]}
1626995764.22081: {"arg":{"channel":"books-l2-tbt","instId":"ONT-USDT"},"action":"update","data":[{"asks":[["0.622","3133.868204","0","1"]],"bids":[],"ts":"1626995764171","checksum":-1052178554}]}
1626995764.243454: {"arg":{"channel":"books-l2-tbt","instId":"ONT-USDT"},"action":"update","data":[{"asks":[],"bids":[["0.6205","0","0","0"]],"ts":"1626995764192","checksum":2037430020}]}
1626995764.290657: {"arg":{"channel":"books-l2-tbt","instId":"TRX-USDT-210924"},"action":"update","data":[{"asks":[["0.0546","20","0","1"],["0.05461","290","0","3"],["0.05468","152","0","1"],["0.05469","29","0","3"]],"bids":[],"ts":"1626995764239","checksum":-2110139088}]}
1626995764.352875: {"arg":{"channel":"books-l2-tbt","instId":"TRX-USDT-210924"},"action":"update","data":[{"asks":[["0.05458","1","0","1"],["0.05459","42","0","1"]],"bids":[],"ts":"1626995764301","checksum":-187663211}]}
1626995764.3616571: {"arg":{"channel":"books-l2-tbt","instId":"TRX-USDT-210924"},"action":"update","data":[{"asks":[["0.05461","433","0","4"],["0.05463","1","0","1"],["0.05477","410","0","2"],["0.05478","282","0","2"],["0.05493","525","0","2"],["0.05494","0","0","0"]],"bids":[["0.0543","42","0","1"],["0.05426","69","0","1"]],"ts":"1626995764311","checksum":1510786135}]}
1626995764.5054889: {"arg":{"channel":"books-l2-tbt","instId":"XMR-USDT-SWAP"},"action":"update","data":[{"asks":[["196.5","7","0","1"],["196.55","50","0","3"]],"bids":[],"ts":"1626995764454","checksum":-1304344177}]}
1626995764.520161: {"arg":{"channel":"books-l2-tbt","instId":"ONT-USDT"},"action":"update","data":[{"asks":[["0.622","3218.868204","0","2"]],"bids":[],"ts":"1626995764470","checksum":-404104149}]}
1626995764.536514: {"arg":{"channel":"books-l2-tbt","instId":"TRX-USDT-210924"},"action":"update","data":[{"asks":[["0.05457","4","0","1"],["0.05461","144","0","2"],["0.05477","143","0","1"],["0.05493","143","0","1"]],"bids":[["0.05427","0","0","0"],["0.05406","0","0","0"]],"ts":"1626995764486","checksum":-921481242}]}
1626995764.6009789: {"arg":{"channel":"books-l2-tbt","instId":"TRX-USDT-210924"},"action":"update","data":[{"asks":[["0.05458","105","0","2"],["0.0546","294","0","3"],["0.05476","267","0","1"],["0.05492","382","0","1"]],"bids":[["0.05414","355","0","2"],["0.05406","388","0","1"]],"ts":"1626995764550","checksum":-556350561}]}
1626995764.663899: {"arg":{"channel":"trades","instId":"OKT-BTC"},"data":[{"instId":"OKT-BTC","tradeId":"3406233","px":"0.001473","sz":"0.30773661","side":"buy","ts":"1626995764608"}]}
1626995764.727732: {"arg":{"channel":"books-l2-tbt","instId":"XMR-USDT-SWAP"},"action":"update","data":[{"asks":[],"bids":[["195.81","15","0","1"],["195.75","0","0","0"]],"ts":"1626995764677","checksum":-985398576}]}
1626995764.90697: {"arg":{"channel":"books-l2-tbt","instId":"OKT-BTC"},"action":"update","data":[{"asks":[["0.001474","0.62267756","0","1"]],"bids":[["0.001471","0","0","0"]],"ts":"1626995764856","checksum":-2093392121}]}
1626995764.910343: {"arg":{"channel":"tickers","instId":"OKT-BTC"},"data":[{"instType":"SPOT","instId":"OKT-BTC","last":"0.001473","lastSz":"0.30773661","askPx":"0.001475","askSz":"10.622771","bidPx":"0.001471","bidSz":"9.66478906","open24h":"0.001402","high24h":"0.001489","low24h":"0.001387","sodUtc0":"0.001408","sodUtc8":"0.001437","volCcy24h":"17.15644724","vol24h":"12034.55831557","ts":"1626995764840"}]}
1626995764.93068: {"arg":{"channel":"books-l2-tbt","instId":"OKT-BTC"},"action":"update","data":[{"asks":[],"bids":[["0.001468","2.64614808","0","1"]],"ts":"1626995764879","checksum":346852092}]}
1626995764.9433541: {"arg":{"channel":"books-l2-tbt","instId":"OKT-BTC"},"action":"update","data":[{"asks":[],"bids":[["0.00147","11.64085258","0","2"]],"ts":"1626995764889","checksum":196790164}]}
1626995764.960782: {"arg":{"channel":"books-l2-tbt","instId":"OKT-BTC"},"action":"update","data":[{"asks":[],"bids":[["0.00147","11.55283724","0","1"]],"ts":"1626995764911","checksum":1993037955}]}
1626995764.9733372: {"arg":{"channel":"books-l2-tbt","instId":"XMR-USDT-SWAP"},"action":"update","data":[{"asks":[["196.51","65","0","2"]],"bids":[],"ts":"1626995764923","checksum":777648779}]}
1626995765.011227: {"arg":{"channel":"books-l2-tbt","instId":"OKT-BTC"},"action":"update","data":[{"asks":[],"bids":[["0.001471","2.64188214","0","1"]],"ts":"1626995764961","checksum":-1819250463}]}
1626995765.0317702: {"arg":{"channel":"books-l2-tbt","instId":"OKT-BTC"},"action":"update","data":[{"asks":[],"bids":[["0.001468","0","0","0"]],"ts":"1626995764980","checksum":-1019379699}]}
1626995765.0984662: {"arg":{"channel":"books-l2-tbt","instId":"DHT-USDT"},"action":"update","data":[{"asks":[["0.81","0","0","0"]],"bids":[],"ts":"1626995765048","checksum":27404697}]}
1626995765.117363: {"arg":{"channel":"books-l2-tbt","instId":"XMR-USDT-SWAP"},"action":"update","data":[{"asks":[],"bids":[["196.13","1","0","1"]],"ts":"1626995765066","checksum":-1777673619}]}
1626995765.135963: {"arg":{"channel":"books-l2-tbt","instId":"XMR-USDT-SWAP"},"action":"update","data":[{"asks":[["196.46","649","0","2"]],"bids":[["196.09","49","0","1"],["195.93","0","0","0"],["195.92","12","0","2"]],"ts":"1626995765086","checksum":537585318}]}
1626995765.177665: {"arg":{"channel":"books-l2-tbt","instId":"FUN-BTC"},"action":"update","data":[{"asks":[["0.000000455","0","0","0"]],"bids":[["0.000000452","0","0","0"]],"ts":"1626995765123","checksum":-702974451}]}
1626995765.1806211: {"arg":{"channel":"books-l2-tbt","instId":"XMR-USDT-SWAP"},"action":"update","data":[{"asks":[],"bids":[["195.88","104","0","4"],["195.87","0","0","0"]],"ts":"1626995765129","checksum":1675593016}]}
1626995765.221768: {"arg":{"channel":"books-l2-tbt","instId":"XMR-USDT-SWAP"},"action":"update","data":[{"asks":[["196.24","187","0","1"]],"bids":[],"ts":"1626995765170","checksum":1083974438}]}
1626995765.224869: {"arg":{"channel":"books-l2-tbt","instId":"OKT-BTC"},"action":"update","data":[{"asks":[],"bids":[["0.001471","0","0","0"]],"ts":"1626995765173","checksum":-1277843819}]}
1626995765.2441542: {"arg":{"channel":"books-l2-tbt","instId":"OKT-BTC"},"action":"update","data":[{"asks":[],"bids":[["0.00147","14.19651658","0","2"],["0.001468","2.64614808","0","1"]],"ts":"1626995765194","checksum":-1093772848}]}
1626995765.248821: {"arg":{"channel":"books-l2-tbt","instId":"FUN-BTC"},"action":"update","data":[{"asks":[["0.000000454","130606.89","0","1"]],"bids":[["0.000000451","131439.69","0","1"]],"ts":"1626995765197","checksum":-1944790714}]}
1626995765.261873: {"arg":{"channel":"books-l2-tbt","instId":"BTC-USD-210924-42000-P"},"action":"update","data":[{"asks":[["0.3415","305","0","2"],["0.342","0","0","0"]],"bids":[["0.3345","0","0","0"],["0.334","601","0","2"]],"ts":"1626995765210","checksum":-1447581190}]}
1626995765.3003452: {"arg":{"channel":"books-l2-tbt","instId":"ONT-USDT"},"action":"update","data":[{"asks":[["0.622","3133.868204","0","1"]],"bids":[],"ts":"1626995765247","checksum":2037430020}]}
1626995765.303296: {"arg":{"channel":"books-l2-tbt","instId":"XMR-USDT-SWAP"},"action":"update","data":[{"asks":[],"bids":[["196.13","31","0","2"],["195.96","82","0","3"]],"ts":"1626995765252","checksum":27651502}]}
1626995765.323802: {"arg":{"channel":"books-l2-tbt","instId":"XMR-USDT-SWAP"},"action":"update","data":[{"asks":[["196.51","30","0","1"]],"bids":[],"ts":"1626995765272","checksum":1127723203}]}
1626995765.338666: {"arg":{"channel":"books-l2-tbt","instId":"DHT-USDT"},"action":"update","data":[{"asks":[],"bids":[["0.736","40","0","1"]],"ts":"1626995765287","checksum":-765150260}]}
1626995765.34864: {"arg":{"channel":"books-l2-tbt","instId":"ONT-USDT"},"action":"update","data":[{"asks":[["0.6226","10780.058506","0","2"],["0.6229","2942.683796","0","2"]],"bids":[],"ts":"1626995765299","checksum":1219931965}]}
1626995765.3487182: {"arg":{"channel":"books-l2-tbt","instId":"TRX-USDT-210924"},"action":"update","data":[{"asks":[["0.0559","0","0","0"],["0.05591","3","0","1"]],"bids":[],"ts":"1626995765299","checksum":-556350561}]}
1626995765.362311: {"arg":{"channel":"books-l2-tbt","instId":"TRX-USDT-210924"},"action":"update","data":[{"asks":[],"bids":[["0.05424","3","0","1"],["0.05423","1","0","1"]],"ts":"1626995765309","checksum":943725629}]}
1626995765.362378: {"arg":{"channel":"books-l2-tbt","instId":"XMR-USDT-SWAP"},"action":"update","data":[{"asks":[["196.35","0","0","0"],["196.47","3","0","1"],["196.49","28","0","1"],["196.64","3","0","1"],["196.98","0","0","0"],["197.04","18","0","2"]],"bids":[],"ts":"1626995765312","checksum":859789399}]}
1626995765.3754659: {"arg":{"channel":"books-l2-tbt","instId":"FUN-BTC"},"action":"update","data":[{"asks":[],"bids":[["0.000000409","0","0","0"]],"ts":"1626995765322","checksum":-1828732146}]}
1626995765.393051: {"arg":{"channel":"books-l2-tbt","instId":"ONT-USDT"},"action":"update","data":[{"asks":[["0.6221","0","0","0"],["0.6222","1027.998242","0","2"],["0.6236","40585","0","1"],["1.1288","10.09339","0","1"]],"bids":[],"ts":"1626995765340","checksum":-129079800}]}
1626995765.404145: {"arg":{"channel":"books-l2-tbt","instId":"TRX-USDT-210924"},"action":"update","data":[{"asks":[],"bids":[["0.05425","3","0","1"],["0.05424","0","0","0"]],"ts":"1626995765351","checksum":-2124890246}]}
1626995765.410146: {"arg":{"channel":"books-l2-tbt","instId":"BTC-USD-210924-42000-P"},"action":"update","data":[{"asks":[["0.341","5","0","1"],["0.3415","300","0","1"]],"bids":[["0.335","0","0","0"],["0.3345","5","0","1"],["0.334","300","0","1"],["0.3335","301","0","1"]],"ts":"1626995765355","checksum":20748665}]}
1626995765.418099: {"arg":{"channel":"books-l2-tbt","instId":"ONT-USDT"},"action":"update","data":[{"asks":[["0.624","884.457666","0","1"],["1.1288","0","0","0"]],"bids":[],"ts":"1626995765361","checksum":239772097}]}
1626995765.424431: {"arg":{"channel":"books-l2-tbt","instId":"ONT-USDT"},"action":"update","data":[{"asks":[["0.622","0","0","0"],["1.1288","10.09339","0","1"]],"bids":[],"ts":"1626995765371","checksum":-104952330}]}
1626995765.429974: {"arg":{"channel":"books-l2-tbt","instId":"XMR-USDT-SWAP"},"action":"update","data":[{"asks":[["196.55","20","0","2"]],"bids":[],"ts":"1626995765375","checksum":-1802020902}]}
1626995765.437373: {"arg":{"channel":"books-l2-tbt","instId":"TRX-USDT-210924"},"action":"update","data":[{"asks":[["0.05468","157","0","2"]],"bids":[],"ts":"1626995765383","checksum":-919230507}]}
1626995765.44589: {"arg":{"channel":"books-l2-tbt","instId":"ONT-USDT"},"action":"update","data":[{"asks":[["0.6222","167.459242","0","2"]],"bids":[["0.6217","952.405926","0","2"],["0.6216","841","0","2"],["0.6214","51","0","1"]],"ts":"1626995765391","checksum":1728531836}]}
1626995765.452375: {"arg":{"channel":"books-l2-tbt","instId":"ONT-USDT"},"action":"update","data":[{"asks":[],"bids":[["0.6208","0","0","0"]],"ts":"1626995765402","checksum":50353610}]}
1626995765.463126: {"arg":{"channel":"books-l2-tbt","instId":"ONT-USDT"},"action":"update","data":[{"asks":[["0.6226","10379.384","0","1"],["0.6229","1970","0","1"]],"bids":[],"ts":"1626995765412","checksum":1543618105}]}
