1626995780.9984581: {"arg":{"channel":"books-l2-tbt","instId":"ONT-USDT"},"action":"update","data":[{"asks":[],"bids":[["0.6212","0","0","0"]],"ts":"1626995780952","checksum":906153922}]}
1626995781.008758: {"arg":{"channel":"books-l2-tbt","instId":"OKT-BTC"},"action":"update","data":[{"asks":[],"bids":[["0.001469","1.10732111","0","2"]],"ts":"1626995780963","checksum":-447464062}]}
1626995781.0914922: {"arg":{"channel":"books-l2-tbt","instId":"AUCTION-USDT"},"action":"update","data":[{"asks":[],"bids":[["14.31","8","0","1"]],"ts":"1626995781044","checksum":-1707538221}]}
1626995781.091624: {"arg":{"channel":"books-l2-tbt","instId":"ONT-USDT"},"action":"update","data":[{"asks":[],"bids":[["0.6213","320","0","1"]],"ts":"1626995781045","checksum":-597250537}]}
1626995781.161791: {"arg":{"channel":"books-l2-tbt","instId":"DHT-USDT"},"action":"update","data":[{"asks":[["0.794","0","0","0"]],"bids":[],"ts":"1626995781114","checksum":-765150260}]}
1626995781.2200801: {"arg":{"channel":"books-l2-tbt","instId":"AUCTION-USDT"},"action":"update","data":[{"asks":[],"bids":[["14.01","8.136099","0","2"]],"ts":"1626995781169","checksum":-1707538221}]}
1626995781.2332969: {"arg":{"channel":"books-l2-tbt","instId":"ONT-USDT"},"action":"update","data":[{"asks":[],"bids":[["0.6216","371","0","2"]],"ts":"1626995781188","checksum":-423300975}]}
1626995781.2569568: {"arg":{"channel":"books-l2-tbt","instId":"XMR-USDT-SWAP"},"action":"update","data":[{"asks":[["196.26","241","0","2"]],"bids":[],"ts":"1626995781210","checksum":1699071945}]}
1626995781.2637272: {"arg":{"channel":"books-l2-tbt","instId":"TRX-USDT-210924"},"action":"update","data":[{"asks":[["0.05588","0","0","0"],["0.05589","3","0","1"]],"bids":[["0.05422","4","0","2"],["0.05421","0","0","0"]],"ts":"1626995781217","checksum":-1382761186}]}
1626995781.276247: {"arg":{"channel":"books-l2-tbt","instId":"OKT-BTC"},"action":"update","data":[{"asks":[],"bids":[["0.001469","0.30706","0","1"]],"ts":"1626995781229","checksum":-551100225}]}
1626995781.276381: {"arg":{"channel":"books-l2-tbt","instId":"XMR-USDT-SWAP"},"action":"update","data":[{"asks":[],"bids":[["195.91","33","0","1"]],"ts":"1626995781230","checksum":1027272784}]}
1626995781.3061361: {"arg":{"channel":"books-l2-tbt","instId":"ONT-USDT"},"action":"update","data":[{"asks":[],"bids":[["0.6209","9526.942","0","1"]],"ts":"1626995781259","checksum":2123772878}]}
1626995781.316136: {"arg":{"channel":"books-l2-tbt","instId":"TRX-USDT-210924"},"action":"update","data":[{"asks":[["0.05588","3","0","1"],["0.05589","0","0","0"]],"bids":[],"ts":"1626995781270","checksum":-1382761186}]}
1626995781.321911: {"arg":{"channel":"books-l2-tbt","instId":"XMR-USDT-SWAP"},"action":"update","data":[{"asks":[["196.26","427","0","3"]],"bids":[],"ts":"1626995781274","checksum":-1040521762}]}
1626995781.326298: {"arg":{"channel":"books-l2-tbt","instId":"ONT-USDT"},"action":"update","data":[{"asks":[],"bids":[["0.6208","405.5","0","1"]],"ts":"1626995781279","checksum":-1194445649}]}
1626995781.3371332: {"arg":{"channel":"books-l2-tbt","instId":"AUCTION-USDT"},"action":"update","data":[{"asks":[],"bids":[["14.25","151.647444","0","1"]],"ts":"1626995781291","checksum":-874478062}]}
1626995781.346806: {"arg":{"channel":"books-l2-tbt","instId":"ONT-USDT"},"action":"update","data":[{"asks":[],"bids":[["0.6216","691","0","3"]],"ts":"1626995781300","checksum":156966480}]}
1626995781.4211369: {"arg":{"channel":"trades","instId":"PAY-BTC"},"data":[{"instId":"PAY-BTC","tradeId":"6071317","px":"0.00000137","sz":"4886.217","side":"sell","ts":"1626995781373"}]}
1626995781.424094: {"arg":{"channel":"books-l2-tbt","instId":"XMR-USDT-SWAP"},"action":"update","data":[{"asks":[["197.03","0","0","0"]],"bids":[],"ts":"1626995781377","checksum":-1040521762}]}
1626995781.427051: {"arg":{"channel":"books-l2-tbt","instId":"DHT-USDT"},"action":"update","data":[{"asks":[["0.809","423.1407","0","1"]],"bids":[],"ts":"1626995781381","checksum":224375159}]}
1626995781.436074: {"arg":{"channel":"books-l2-tbt","instId":"ONT-USDT"},"action":"update","data":[{"asks":[],"bids":[["0.6213","0","0","0"]],"ts":"1626995781390","checksum":-18926941}]}
1626995781.503634: {"arg":{"channel":"tickers","instId":"PAY-BTC"},"data":[{"instType":"SPOT","instId":"PAY-BTC","last":"0.00000137","lastSz":"4886.217","askPx":"0.00000139","askSz":"5342.072","bidPx":"0.00000136","bidSz":"4282.772","open24h":"0.00000136","high24h":"0.00000144","low24h":"0.00000136","sodUtc0":"0.00000138","sodUtc8":"0.00000138","volCcy24h":"45.125","vol24h":"32769188.382","ts":"1626995781444"}]}
1626995781.526633: {"arg":{"channel":"books-l2-tbt","instId":"ONT-USDT"},"action":"update","data":[{"asks":[],"bids":[["0.6216","1011","0","4"]],"ts":"1626995781480","checksum":398476765}]}
1626995781.5367308: {"arg":{"channel":"books-l2-tbt","instId":"ONT-USDT"},"action":"update","data":[{"asks":[],"bids":[["0.6216","1331","0","5"]],"ts":"1626995781491","checksum":-112906576}]}
1626995781.545842: {"arg":{"channel":"books-l2-tbt","instId":"ONT-USDT"},"action":"update","data":[{"asks":[],"bids":[["0.6216","1651","0","6"]],"ts":"1626995781500","checksum":297506118}]}
1626995781.54922: {"arg":{"channel":"books-l2-tbt","instId":"XMR-USDT-SWAP"},"action":"update","data":[{"asks":[["197.02","142","0","1"]],"bids":[],"ts":"1626995781502","checksum":-1040521762}]}
1626995781.560086: {"arg":{"channel":"books-l2-tbt","instId":"FUN-BTC"},"action":"update","data":[{"asks":[],"bids":[["0.000000405","0","0","0"]],"ts":"1626995781513","checksum":645519708}]}
1626995781.6315782: {"arg":{"channel":"books-l2-tbt","instId":"ONT-USDT"},"action":"update","data":[{"asks":[],"bids":[["0.6216","1331","0","5"]],"ts":"1626995781585","checksum":-112906576}]}
1626995781.671763: {"arg":{"channel":"books-l2-tbt","instId":"DHT-USDT"},"action":"update","data":[{"asks":[],"bids":[["0.734","778.4","0","1"]],"ts":"1626995781625","checksum":1655920288}]}
1626995781.712755: {"arg":{"channel":"books-l2-tbt","instId":"ONT-USDT"},"action":"update","data":[{"asks":[],"bids":[["0.621","11058.227","0","2"]],"ts":"1626995781667","checksum":-706024325}]}
1626995781.755671: {"arg":{"channel":"books-l2-tbt","instId":"OKT-BTC"},"action":"update","data":[{"asks":[],"bids":[["0.001469","2.95208731","0","2"]],"ts":"1626995781709","checksum":-1739138756}]}
1626995781.835657: {"arg":{"channel":"books-l2-tbt","instId":"ONT-USDT"},"action":"update","data":[{"asks":[],"bids":[["0.6217","326.871136","0","2"],["0.6216","691","0","3"],["0.5898","0","0","0"]],"ts":"1626995781789","checksum":1512535071}]}
1626995781.8465862: {"arg":{"channel":"books-l2-tbt","instId":"FUN-BTC"},"action":"update","data":[{"asks":[],"bids":[["0.000000411","6743.11","0","1"]],"ts":"1626995781800","checksum":732530277}]}
1626995781.84673: {"arg":{"channel":"books-l2-tbt","instId":"ONT-USDT"},"action":"update","data":[{"asks":[],"bids":[["0.6216","371","0","2"]],"ts":"1626995781800","checksum":1506416939}]}
1626995781.85594: {"arg":{"channel":"books-l2-tbt","instId":"ONT-USDT"},"action":"update","data":[{"asks":[],"bids":[["0.5897","294.795658","0","1"]],"ts":"1626995781809","checksum":1506416939}]}
1626995781.8750331: {"arg":{"channel":"books-l2-tbt","instId":"ONT-USDT"},"action":"update","data":[{"asks":[],"bids":[["0.6216","51","0","1"]],"ts":"1626995781829","checksum":1134087048}]}
1626995781.901087: {"arg":{"channel":"books-l2-tbt","instId":"TRX-USDT-210924"},"action":"update","data":[{"asks":[["0.05588","0","0","0"],["0.05589","3","0","1"]],"bids":[],"ts":"1626995781854","checksum":-1382761186}]}
1626995781.940587: {"arg":{"channel":"books-l2-tbt","instId":"ONT-USDT"},"action":"update","data":[{"asks":[],"bids":[["0.6217","646.871136","0","3"]],"ts":"1626995781894","checksum":1958037059}]}
1626995781.983148: {"arg":{"channel":"books-l2-tbt","instId":"TRX-USDT-210924"},"action":"update","data":[{"asks":[["0.05588","3","0","1"],["0.05589","0","0","0"]],"bids":[],"ts":"1626995781935","checksum":-1382761186}]}
1626995782.044661: {"arg":{"channel":"books-l2-tbt","instId":"ONT-USDT"},"action":"update","data":[{"asks":[],"bids":[["0.6218","320","0","1"]],"ts":"1626995781998","checksum":-425921751}]}
1626995782.055292: {"arg":{"channel":"books-l2-tbt","instId":"ONT-USDT"},"action":"update","data":[{"asks":[["0.6222","1548.873745","0","2"]],"bids":[],"ts":"1626995782009","checksum":942049909}]}
1626995782.066423: {"arg":{"channel":"books-l2-tbt","instId":"ONT-USDT"},"action":"update","data":[{"asks":[],"bids":[["0.6215","1053.553072","0","2"],["0.6214","970.582509","0","2"],["0.6191","0","0","0"]],"ts":"1626995782020","checksum":-1013874821}]}
1626995782.09632: {"arg":{"channel":"books-l2-tbt","instId":"ONT-USDT"},"action":"update","data":[{"asks":[],"bids":[["0.6217","966.871136","0","4"]],"ts":"1626995782048","checksum":-425154391}]}
1626995782.102539: {"arg":{"channel":"books-l2-tbt","instId":"ONT-USDT"},"action":"update","data":[{"asks":[],"bids":[["0.6217","1286.871136","0","5"]],"ts":"1626995782057","checksum":-454344593}]}
1626995782.113274: {"arg":{"channel":"books-l2-tbt","instId":"OKT-BTC"},"action":"update","data":[{"asks":[],"bids":[["0.001452","0","0","0"]],"ts":"1626995782067","checksum":775457265}]}
1626995782.1139069: {"arg":{"channel":"books-l2-tbt","instId":"ONT-USDT"},"action":"update","data":[{"asks":[],"bids":[["0.6217","966.871136","0","4"],["0.6198","47","0","1"]],"ts":"1626995782068","checksum":-2119924194}]}
1626995782.126867: {"arg":{"channel":"books-l2-tbt","instId":"ONT-USDT"},"action":"update","data":[{"asks":[],"bids":[["0.6201","792.868423","0","2"]],"ts":"1626995782080","checksum":1787715327}]}
1626995782.1297522: {"arg":{"channel":"books-l2-tbt","instId":"TRX-USDT-210924"},"action":"update","data":[{"asks":[["0.05588","0","0","0"],["0.05589","3","0","1"]],"bids":[],"ts":"1626995782082","checksum":-1382761186}]}
1626995782.17597: {"arg":{"channel":"books-l2-tbt","instId":"ONT-USDT"},"action":"update","data":[{"asks":[],"bids":[["0.6192","6965.224405","0","2"]],"ts":"1626995782129","checksum":-1896693444}]}
1626995782.1953669: {"arg":{"channel":"books-l2-tbt","instId":"ONT-USDT"},"action":"update","data":[{"asks":[],"bids":[["0.6217","646.871136","0","3"]],"ts":"1626995782149","checksum":-1412753682}]}
1626995782.195503: {"arg":{"channel":"books-l2-tbt","instId":"OKT-BTC"},"action":"update","data":[{"asks":[],"bids":[["0.00145","2.47","0","1"]],"ts":"1626995782150","checksum":-298281790}]}
1626995782.208161: {"arg":{"channel":"books-l2-tbt","instId":"TRX-USDT-210924"},"action":"update","data":[{"asks":[["0.05588","3","0","1"],["0.05589","0","0","0"]],"bids":[],"ts":"1626995782162","checksum":-1382761186}]}
1626995782.282358: {"arg":{"channel":"books-l2-tbt","instId":"ONT-USDT"},"action":"update","data":[{"asks":[],"bids":[["0.6216","371","0","2"]],"ts":"1626995782234","checksum":715076155}]}
1626995782.3132632: {"arg":{"channel":"books-l2-tbt","instId":"AUCTION-USDT"},"action":"update","data":[{"asks":[],"bids":[["14.25","0","0","0"]],"ts":"1626995782267","checksum":-1707538221}]}
1626995782.342303: {"arg":{"channel":"books-l2-tbt","instId":"OKT-BTC"},"action":"update","data":[{"asks":[["0.001475","0.4130644","0","1"]],"bids":[],"ts":"1626995782296","checksum":895045796}]}
1626995782.342432: {"arg":{"channel":"books-l2-tbt","instId":"ONT-USDT"},"action":"update","data":[{"asks":[],"bids":[["0.6218","0","0","0"]],"ts":"1626995782297","checksum":-1043854918}]}
1626995782.3613591: {"arg":{"channel":"books-l2-tbt","instId":"ONT-USDT"},"action":"update","data":[{"asks":[["0.6227","740","0","1"],["1.1285","0","0","0"]],"bids":[],"ts":"1626995782316","checksum":-1977844168}]}
1626995782.39439: {"arg":{"channel":"books-l2-tbt","instId":"ONT-USDT"},"action":"update","data":[{"asks":[],"bids":[["0.6217","6.871136","0","1"]],"ts":"1626995782348","checksum":-1511261218}]}
1626995782.4329631: {"arg":{"channel":"books-l2-tbt","instId":"TRX-USDT-210924"},"action":"update","data":[{"asks":[["0.05448","2","0","1"],["0.0545","14","0","1"]],"bids":[],"ts":"1626995782386","checksum":-1624340387}]}
1626995782.433121: {"arg":{"channel":"books-l2-tbt","instId":"OKT-BTC"},"action":"update","data":[{"asks":[["0.001476","14.17873561","0","2"]],"bids":[],"ts":"1626995782387","checksum":1579143159}]}
1626995782.442471: {"arg":{"channel":"books-l2-tbt","instId":"TRX-USDT-210924"},"action":"update","data":[{"asks":[["0.05466","0","0","0"]],"bids":[],"ts":"1626995782396","checksum":-1921144408}]}
1626995782.444957: {"arg":{"channel":"books-l2-tbt","instId":"ONT-USDT"},"action":"update","data":[{"asks":[["0.6228","402.871384","0","2"]],"bids":[],"ts":"1626995782399","checksum":1446127844}]}
1626995782.453748: {"arg":{"channel":"books-l2-tbt","instId":"TRX-USDT-210924"},"action":"update","data":[{"asks":[["0.05462","258","0","3"]],"bids":[],"ts":"1626995782407","checksum":-1445863329}]}
1626995782.4733849: {"arg":{"channel":"books-l2-tbt","instId":"TRX-USDT-210924"},"action":"update","data":[{"asks":[],"bids":[["0.05442","494","0","4"],["0.05438","68","0","2"]],"ts":"1626995782427","checksum":-1180693520}]}
1626995782.50504: {"arg":{"channel":"books-l2-tbt","instId":"ONT-USDT"},"action":"update","data":[{"asks":[["0.6222","945.539","0","1"]],"bids":[["0.6216","691","0","3"]],"ts":"1626995782458","checksum":-448411827}]}
1626995782.535291: {"arg":{"channel":"books-l2-tbt","instId":"ONT-USDT"},"action":"update","data":[{"asks":[],"bids":[["0.6216","1011","0","4"]],"ts":"1626995782489","checksum":-846615250}]}
1626995782.568634: {"arg":{"channel":"books-l2-tbt","instId":"AUCTION-USDT"},"action":"update","data":[{"asks":[],"bids":[["14.3","358.2294","0","2"]],"ts":"1626995782521","checksum":1765487850}]}
1626995782.573982: {"arg":{"channel":"books-l2-tbt","instId":"ONT-USDT"},"action":"update","data":[{"asks":[],"bids":[["0.6216","691","0","3"]],"ts":"1626995782528","checksum":-448411827}]}
1626995782.5786712: {"arg":{"channel":"books-l2-tbt","instId":"TRX-USDT-210924"},"action":"update","data":[{"asks":[],"bids":[["0.05422","1","0","1"],["0.05421","3","0","1"]],"ts":"1626995782531","checksum":-874721299}]}
1626995782.606415: {"arg":{"channel":"trades","instId":"AUCTION-USDT"},"data":[{"instId":"AUCTION-USDT","tradeId":"584232","px":"14.87","sz":"0.668542","side":"buy","ts":"1626995782556"}]}
1626995782.617748: {"arg":{"channel":"books-l2-tbt","instId":"XMR-USDT-SWAP"},"action":"update","data":[{"asks":[],"bids":[["195.29","0","0","0"]],"ts":"1626995782571","checksum":-1040521762}]}
1626995782.635788: {"arg":{"channel":"books-l2-tbt","instId":"DHT-USDT"},"action":"update","data":[{"asks":[["0.809","0","0","0"]],"bids":[],"ts":"1626995782588","checksum":-552937011}]}
1626995782.68085: {"arg":{"channel":"books-l2-tbt","instId":"XMR-USDT-SWAP"},"action":"update","data":[{"asks":[],"bids":[["195.31","9","0","1"]],"ts":"1626995782634","checksum":-1040521762}]}
1626995782.717217: {"arg":{"channel":"tickers","instId":"AUCTION-USDT"},"data":[{"instType":"SPOT","instId":"AUCTION-USDT","last":"14.87","lastSz":"0.668542","askPx":"14.98","askSz":"2.665343","bidPx":"14.83","bidSz":"2.701428","open24h":"14.94","high24h":"15.43","low24h":"14.22","sodUtc0":"14.94","sodUtc8":"14.86","volCcy24h":"117858.234837","vol24h":"7932.673005","ts":"1626995782653"}]}
1626995782.734179: {"arg":{"channel":"books-l2-tbt","instId":"ONT-USDT"},"action":"update","data":[{"asks":[],"bids":[],"ts":"1626995782679","checksum":-448411827}]}
1626995782.734248: {"arg":{"channel":"books-l2-tbt","instId":"TRX-USDT-210924"},"action":"update","data":[{"asks":[],"bids":[],"ts":"1626995782680","checksum":-874721299}]}
1626995782.741559: {"arg":{"channel":"books-l2-tbt","instId":"ONT-USDT"},"action":"update","data":[{"asks":[],"bids":[["0.6216","1331","0","5"]],"ts":"1626995782692","checksum":1729063385}]}
1626995782.7606158: {"arg":{"channel":"books-l2-tbt","instId":"ONT-USDT"},"action":"update","data":[{"asks":[],"bids":[["0.6216","1651","0","6"]],"ts":"1626995782714","checksum":1140138625}]}
1626995782.784775: {"arg":{"channel":"books-l2-tbt","instId":"ONT-USDT"},"action":"update","data":[{"asks":[],"bids":[["0.6216","1331","0","5"]],"ts":"1626995782734","checksum":1729063385}]}
1626995782.811168: {"arg":{"channel":"books-l2-tbt","instId":"ONT-USDT"},"action":"update","data":[{"asks":[],"bids":[["0.6216","1011","0","4"]],"ts":"1626995782764","checksum":-846615250}]}
1626995782.8357859: {"arg":{"channel":"books-l2-tbt","instId":"TRX-USDT-210924"},"action":"update","data":[{"asks":[["0.05448","0","0","0"]],"bids":[],"ts":"1626995782787","checksum":-1395395927}]}
1626995782.8462899: {"arg":{"channel":"books-l2-tbt","instId":"TRX-USDT-210924"},"action":"update","data":[{"asks":[],"bids":[["0.05437","5","0","1"]],"ts":"1626995782799","checksum":-2146029274}]}
1626995782.880826: {"arg":{"channel":"books-l2-tbt","instId":"ONT-USDT"},"action":"update","data":[{"asks":[],"bids":[["0.6217","326.871136","0","2"]],"ts":"1626995782834","checksum":-1247532871}]}
1626995782.902285: {"arg":{"channel":"books-l2-tbt","instId":"DHT-USDT"},"action":"update","data":[{"asks":[],"bids":[["0.734","0","0","0"]],"ts":"1626995782856","checksum":-765150260}]}
1626995782.902843: {"arg":{"channel":"books-l2-tbt","instId":"ONT-USDT"},"action":"update","data":[{"asks":[],"bids":[["0.6217","646.871136","0","3"]],"ts":"1626995782857","checksum":-1188749812}]}
1626995782.912909: {"arg":{"channel":"books-l2-tbt","instId":"ONT-USDT"},"action":"update","data":[{"asks":[["0.6226","10768.802","0","2"]],"bids":[],"ts":"1626995782865","checksum":252521527}]}
1626995782.98526: {"arg":{"channel":"books-l2-tbt","instId":"ONT-USDT"},"action":"update","data":[{"asks":[],"bids":[["0.6217","966.871136","0","4"]],"ts":"1626995782939","checksum":-1048944856}]}
1626995783.037515: {"arg":{"channel":"books-l2-tbt","instId":"ONT-USDT"},"action":"update","data":[{"asks":[],"bids":[["0.6216","691","0","3"]],"ts":"1626995782991","checksum":671927696}]}
1626995783.047413: {"arg":{"channel":"books-l2-tbt","instId":"ONT-USDT"},"action":"update","data":[{"asks":[],"bids":[["0.6216","51","0","1"]],"ts":"1626995783000","checksum":-694151480}]}
1626995783.101609: {"arg":{"channel":"books-l2-tbt","instId":"ONT-USDT"},"action":"update","data":[{"asks":[],"bids":[["0.6217","1606.871136","0","6"]],"ts":"1626995783055","checksum":-181074743}]}
1626995783.121551: {"arg":{"channel":"books-l2-tbt","instId":"ONT-USDT"},"action":"update","data":[{"asks":[],"bids":[["0.6217","1926.871136","0","7"]],"ts":"1626995783075","checksum":242890262}]}
1626995783.1582248: {"arg":{"channel":"books-l2-tbt","instId":"DHT-USDT"},"action":"update","data":[{"asks":[["0.795","423.1407","0","1"]],"bids":[],"ts":"1626995783112","checksum":-746928502}]}
1626995783.1970859: {"arg":{"channel":"books-l2-tbt","instId":"ONT-USDT"},"action":"update","data":[{"asks":[],"bids":[["0.6217","1606.871136","0","6"]],"ts":"1626995783148","checksum":-181074743}]}
1626995783.2089758: {"arg":{"channel":"books-l2-tbt","instId":"ONT-USDT"},"action":"update","data":[{"asks":[],"bids":[["0.6217","1286.871136","0","5"]],"ts":"1626995783159","checksum":-359423229}]}
1626995783.2575722: {"arg":{"channel":"books-l2-tbt","instId":"ONT-USDT"},"action":"update","data":[{"asks":[["0.6226","390","0","1"]],"bids":[["0.6217","966.871136","0","4"]],"ts":"1626995783211","checksum":-1893978316}]}
1626995783.276683: {"arg":{"channel":"books-l2-tbt","instId":"ONT-USDT"},"action":"update","data":[{"asks":[["0.6229","9330.33355","0","3"]],"bids":[["0.6218","640","0","2"]],"ts":"1626995783230","checksum":1953007708}]}
1626995783.309788: {"arg":{"channel":"books-l2-tbt","instId":"ONT-USDT"},"action":"update","data":[{"asks":[],"bids":[["0.6218","960","0","3"]],"ts":"1626995783263","checksum":215066916}]}
1626995783.309877: {"arg":{"channel":"books-l2-tbt","instId":"OKT-BTC"},"action":"update","data":[{"asks":[["0.001476","11.54107264","0","1"]],"bids":[],"ts":"1626995783263","checksum":895045796}]}
1626995783.379423: {"arg":{"channel":"books-l2-tbt","instId":"DHT-USDT"},"action":"update","data":[{"asks":[],"bids":[["0.722","791.3374","0","1"]],"ts":"1626995783333","checksum":-1081941396}]}
