1626995779.473726: {"arg":{"channel":"books-l2-tbt","instId":"TRX-USDT-210924"},"action":"update","data":[{"asks":[["0.05464","158","0","1"],["0.05477","143","0","1"],["0.05499","0","0","0"]],"bids":[],"ts":"1626995779423","checksum":-1195841732}]}
1626995779.5374331: {"arg":{"channel":"books-l2-tbt","instId":"TRX-USDT-210924"},"action":"update","data":[{"asks":[["0.05461","285","0","4"],["0.05463","134","0","2"],["0.05476","242","0","1"]],"bids":[],"ts":"1626995779486","checksum":-1812255509}]}
1626995779.547034: {"arg":{"channel":"books-l2-tbt","instId":"TRX-USDT-210924"},"action":"update","data":[{"asks":[["0.05495","525","0","2"]],"bids":[],"ts":"1626995779496","checksum":-1497368903}]}
1626995779.558075: {"arg":{"channel":"books-l2-tbt","instId":"FUN-BTC"},"action":"update","data":[{"asks":[],"bids":[["0.000000414","0","0","0"]],"ts":"1626995779507","checksum":645519708}]}
1626995779.5650501: {"arg":{"channel":"books-l2-tbt","instId":"ONT-USDT"},"action":"update","data":[{"asks":[],"bids":[["0.6208","10784.195","0","2"]],"ts":"1626995779514","checksum":-153085648}]}
1626995779.6396658: {"arg":{"channel":"books-l2-tbt","instId":"TRX-USDT-210924"},"action":"update","data":[{"asks":[["0.05463","1","0","1"]],"bids":[],"ts":"1626995779589","checksum":-459519303}]}
1626995779.651458: {"arg":{"channel":"books-l2-tbt","instId":"TRX-USDT-210924"},"action":"update","data":[{"asks":[["0.05476","0","0","0"],["0.05495","143","0","1"]],"bids":[],"ts":"1626995779600","checksum":656066721}]}
1626995779.67505: {"arg":{"channel":"books-l2-tbt","instId":"DHT-USDT"},"action":"update","data":[{"asks":[["0.792","0","0","0"]],"bids":[],"ts":"1626995779624","checksum":-564066120}]}
1626995779.687414: {"arg":{"channel":"books-l2-tbt","instId":"OKT-BTC"},"action":"update","data":[{"asks":[["0.001477","0","0","0"]],"bids":[],"ts":"1626995779637","checksum":171466922}]}
1626995779.710633: {"arg":{"channel":"books-l2-tbt","instId":"TRX-USDT-210924"},"action":"update","data":[{"asks":[["0.05463","133","0","2"],["0.05476","241","0","1"],["0.05499","382","0","1"]],"bids":[],"ts":"1626995779660","checksum":374723117}]}
1626995779.7253: {"arg":{"channel":"books-l2-tbt","instId":"XMR-USDT-SWAP"},"action":"update","data":[{"asks":[["196.26","427","0","3"]],"bids":[],"ts":"1626995779672","checksum":-12778881}]}
1626995779.759628: {"arg":{"channel":"books-l2-tbt","instId":"ONT-USDT"},"action":"update","data":[{"asks":[["0.6279","83.730044","0","1"],["1.1285","0","0","0"]],"bids":[["0.6132","343.806974","0","2"]],"ts":"1626995779710","checksum":209968172}]}
1626995779.788159: {"arg":{"channel":"books-l2-tbt","instId":"XMR-USDT-SWAP"},"action":"update","data":[{"asks":[["196.4","67","0","2"],["196.41","510","0","2"]],"bids":[],"ts":"1626995779736","checksum":-110044803}]}
1626995779.800045: {"arg":{"channel":"books-l2-tbt","instId":"PAY-BTC"},"action":"update","data":[{"asks":[["0.0000014","2866.44","0","3"]],"bids":[["0.00000134","4117.948","0","5"]],"ts":"1626995779749","checksum":-73858121}]}
1626995779.845833: {"arg":{"channel":"books-l2-tbt","instId":"FUN-BTC"},"action":"update","data":[{"asks":[],"bids":[["0.000000405","6843.01","0","1"]],"ts":"1626995779795","checksum":602925849}]}
1626995779.8628109: {"arg":{"channel":"books-l2-tbt","instId":"AUCTION-USDT"},"action":"update","data":[{"asks":[],"bids":[["14.24","0","0","0"]],"ts":"1626995779813","checksum":-1707538221}]}
1626995779.925013: {"arg":{"channel":"books-l2-tbt","instId":"DHT-USDT"},"action":"update","data":[{"asks":[["0.794","463.1407","0","2"]],"bids":[],"ts":"1626995779872","checksum":2058410061}]}
1626995779.933202: {"arg":{"channel":"books-l2-tbt","instId":"ONT-USDT"},"action":"update","data":[{"asks":[],"bids":[["0.6216","0","0","0"]],"ts":"1626995779883","checksum":-1108563422}]}
1626995779.944889: {"arg":{"channel":"books-l2-tbt","instId":"ONT-USDT"},"action":"update","data":[{"asks":[],"bids":[["0.6216","51","0","1"],["0.6205","1709.660295","0","2"]],"ts":"1626995779895","checksum":451328989}]}
1626995779.955171: {"arg":{"channel":"books-l2-tbt","instId":"ONT-USDT"},"action":"update","data":[{"asks":[["0.6234","0","0","0"],["1.1285","10.5","0","1"]],"bids":[],"ts":"1626995779904","checksum":693690036}]}
1626995779.9671738: {"arg":{"channel":"books-l2-tbt","instId":"ONT-USDT"},"action":"update","data":[{"asks":[["0.6222","1656.56466","0","3"]],"bids":[["0.6214","970.582509","0","2"],["0.6211","107.690915","0","1"]],"ts":"1626995779915","checksum":-667923519}]}
1626995779.974247: {"arg":{"channel":"books-l2-tbt","instId":"ONT-USDT"},"action":"update","data":[{"asks":[["0.6225","0","0","0"],["1.1288","10.09339","0","1"]],"bids":[],"ts":"1626995779924","checksum":1273487267}]}
1626995780.0175738: {"arg":{"channel":"books-l2-tbt","instId":"XMR-USDT-SWAP"},"action":"update","data":[{"asks":[],"bids":[["195.26","80","0","2"]],"ts":"1626995779965","checksum":-110044803}]}
1626995780.038369: {"arg":{"channel":"books-l2-tbt","instId":"TRX-USDT-210924"},"action":"update","data":[{"asks":[["0.05463","1","0","1"]],"bids":[],"ts":"1626995779988","checksum":1851681337}]}
1626995780.047704: {"arg":{"channel":"books-l2-tbt","instId":"TRX-USDT-210924"},"action":"update","data":[{"asks":[["0.05476","0","0","0"]],"bids":[],"ts":"1626995779997","checksum":-2144220311}]}
1626995780.0677388: {"arg":{"channel":"books-l2-tbt","instId":"ONT-USDT"},"action":"update","data":[{"asks":[],"bids":[["0.6217","6.871136","0","1"]],"ts":"1626995780017","checksum":-1800343160}]}
1626995780.0855439: {"arg":{"channel":"books-l2-tbt","instId":"DHT-USDT"},"action":"update","data":[{"asks":[["0.794","423.1407","0","1"]],"bids":[],"ts":"1626995780036","checksum":-831419424}]}
1626995780.0994701: {"arg":{"channel":"books-l2-tbt","instId":"XMR-USDT-SWAP"},"action":"update","data":[{"asks":[],"bids":[["195.26","70","0","1"]],"ts":"1626995780049","checksum":-110044803}]}
1626995780.1106439: {"arg":{"channel":"books-l2-tbt","instId":"TRX-USDT-210924"},"action":"update","data":[{"asks":[["0.05464","297","0","2"],["0.05477","389","0","2"]],"bids":[],"ts":"1626995780059","checksum":-1030490672}]}
1626995780.1107001: {"arg":{"channel":"books-l2-tbt","instId":"AUCTION-USDT"},"action":"update","data":[{"asks":[],"bids":[["14.31","159.011605","0","2"]],"ts":"1626995780060","checksum":-2017225663}]}
1626995780.143143: {"arg":{"channel":"books-l2-tbt","instId":"XMR-USDT-SWAP"},"action":"update","data":[{"asks":[["196.28","3","0","1"],["196.34","10","0","2"],["196.36","0","0","0"],["196.38","7","0","1"],["196.44","28","0","1"],["196.46","7","0","1"],["196.48","28","0","1"],["196.5","15","0","1"],["196.52","3","0","1"],["196.58","0","0","0"],["196.6","0","0","0"],["196.91","3","0","1"],["196.99","0","0","0"],["197.3","6","0","1"],["197.44","0","0","0"]],"bids":[],"ts":"1626995780092","checksum":625834411}]}
1626995780.189904: {"arg":{"channel":"books-l2-tbt","instId":"ONT-USDT"},"action":"update","data":[{"asks":[["0.6222","1548.873745","0","2"],["0.6225","109.084803","0","1"],["1.1288","0","0","0"]],"bids":[["0.6214","1079.667312","0","3"],["0.6211","0","0","0"]],"ts":"1626995780138","checksum":650264088}]}
1626995780.2803478: {"arg":{"channel":"books-l2-tbt","instId":"ONT-USDT"},"action":"update","data":[{"asks":[["0.6222","945.539","0","1"]],"bids":[],"ts":"1626995780230","checksum":1173713922}]}
1626995780.363691: {"arg":{"channel":"books-l2-tbt","instId":"OKT-BTC"},"action":"update","data":[{"asks":[["0.001475","3.05407465","0","2"]],"bids":[],"ts":"1626995780312","checksum":-551100225}]}
1626995780.387001: {"arg":{"channel":"books-l2-tbt","instId":"TRX-USDT-210924"},"action":"update","data":[{"asks":[],"bids":[["0.05442","494","0","4"],["0.05438","68","0","2"]],"ts":"1626995780337","checksum":-590053769}]}
1626995780.4625258: {"arg":{"channel":"books-l2-tbt","instId":"ONT-USDT"},"action":"update","data":[{"asks":[],"bids":[["0.62","642","0","1"]],"ts":"1626995780413","checksum":355589848}]}
1626995780.4933078: {"arg":{"channel":"books-l2-tbt","instId":"TRX-USDT-210924"},"action":"update","data":[{"asks":[],"bids":[["0.05438","59","0","1"],["0.05437","9","0","1"]],"ts":"1626995780443","checksum":-1301741005}]}
1626995780.546318: {"arg":{"channel":"books-l2-tbt","instId":"XMR-USDT-SWAP"},"action":"update","data":[{"asks":[["196.34","3","0","1"],["196.38","0","0","0"],["196.42","15","0","3"],["196.54","7","0","1"],["197.3","0","0","0"],["197.38","6","0","1"]],"bids":[],"ts":"1626995780495","checksum":-1719283129}]}
1626995780.546388: {"arg":{"channel":"books-l2-tbt","instId":"ONT-USDT"},"action":"update","data":[{"asks":[],"bids":[["0.6212","320","0","1"]],"ts":"1626995780497","checksum":507284436}]}
1626995780.556057: {"arg":{"channel":"books-l2-tbt","instId":"ONT-USDT"},"action":"update","data":[{"asks":[],"bids":[["0.6212","640","0","2"],["0.6175","41276.433198","0","3"]],"ts":"1626995780506","checksum":-1509162525}]}
1626995780.56318: {"arg":{"channel":"books-l2-tbt","instId":"TRX-USDT-210924"},"action":"update","data":[{"asks":[],"bids":[["0.05446","10","0","2"]],"ts":"1626995780513","checksum":1647602788}]}
1626995780.59157: {"arg":{"channel":"books-l2-tbt","instId":"ONT-USDT"},"action":"update","data":[{"asks":[],"bids":[["0.6212","1920","0","6"]],"ts":"1626995780541","checksum":457405123}]}
1626995780.59166: {"arg":{"channel":"books-l2-tbt","instId":"TRX-USDT-210924"},"action":"update","data":[{"asks":[],"bids":[["0.05442","497","0","5"],["0.05437","0","0","0"]],"ts":"1626995780542","checksum":-1654414783}]}
1626995780.6563158: {"arg":{"channel":"books-l2-tbt","instId":"ONT-USDT"},"action":"update","data":[{"asks":[],"bids":[["0.6199","47","0","1"]],"ts":"1626995780605","checksum":1406710721}]}
1626995780.747455: {"arg":{"channel":"books-l2-tbt","instId":"ONT-USDT"},"action":"update","data":[{"asks":[],"bids":[["0.6198","449.868423","0","2"]],"ts":"1626995780696","checksum":-2000613342}]}
1626995780.755402: {"arg":{"channel":"books-l2-tbt","instId":"DHT-USDT"},"action":"update","data":[{"asks":[],"bids":[["0.734","2350","0","1"]],"ts":"1626995780705","checksum":1325937747}]}
1626995780.7672052: {"arg":{"channel":"books-l2-tbt","instId":"DHT-USDT"},"action":"update","data":[{"asks":[],"bids":[["0.734","0","0","0"]],"ts":"1626995780717","checksum":-831419424}]}
1626995780.802212: {"arg":{"channel":"books-l2-tbt","instId":"ONT-USDT"},"action":"update","data":[{"asks":[["0.6228","10780.143384","0","3"]],"bids":[],"ts":"1626995780749","checksum":2144129657}]}
1626995780.8702888: {"arg":{"channel":"trades","instId":"ONT-USDT"},"data":[{"instId":"ONT-USDT","tradeId":"11366801","px":"0.6219","sz":"489.355689","side":"buy","ts":"1626995780817"}]}
1626995780.920452: {"arg":{"channel":"books-l2-tbt","instId":"DHT-USDT"},"action":"update","data":[{"asks":[],"bids":[["0.721","0","0","0"]],"ts":"1626995780870","checksum":-292693670}]}
1626995780.937793: {"arg":{"channel":"books-l2-tbt","instId":"ONT-USDT"},"action":"update","data":[{"asks":[],"bids":[["0.6212","1280","0","4"]],"ts":"1626995780883","checksum":1591057751}]}
1626995780.941893: {"arg":{"channel":"tickers","instId":"ONT-USDT"},"data":[{"instType":"SPOT","instId":"ONT-USDT","last":"0.6219","lastSz":"489.355689","askPx":"0.6221","askSz":"2752.353814","bidPx":"0.6217","bidSz":"640","open24h":"0.6075","high24h":"0.6314","low24h":"0.5967","sodUtc0":"0.6131","sodUtc8":"0.6275","volCcy24h":"9395048.127286","vol24h":"15284521.095199","ts":"1626995780882"}]}
1626995780.9420002: {"arg":{"channel":"books-l2-tbt","instId":"ONT-USDT"},"action":"update","data":[{"asks":[],"bids":[["0.6212","960","0","3"]],"ts":"1626995780892","checksum":-414710993}]}
1626995780.9533298: {"arg":{"channel":"books-l2-tbt","instId":"ONT-USDT"},"action":"update","data":[{"asks":[],"bids":[["0.6212","320","0","1"]],"ts":"1626995780903","checksum":-1497730675}]}
1626995781.002344: {"arg":{"channel":"books-l2-tbt","instId":"ONT-USDT"},"action":"update","data":[{"asks":[],"bids":[["0.6212","0","0","0"]],"ts":"1626995780952","checksum":906153922}]}
1626995781.0128891: {"arg":{"channel":"books-l2-tbt","instId":"OKT-BTC"},"action":"update","data":[{"asks":[],"bids":[["0.001469","1.10732111","0","2"]],"ts":"1626995780963","checksum":-447464062}]}
1626995781.09587: {"arg":{"channel":"books-l2-tbt","instId":"AUCTION-USDT"},"action":"update","data":[{"asks":[],"bids":[["14.31","8","0","1"]],"ts":"1626995781044","checksum":-1707538221}]}
1626995781.095955: {"arg":{"channel":"books-l2-tbt","instId":"ONT-USDT"},"action":"update","data":[{"asks":[],"bids":[["0.6213","320","0","1"]],"ts":"1626995781045","checksum":-597250537}]}
1626995781.1653728: {"arg":{"channel":"books-l2-tbt","instId":"DHT-USDT"},"action":"update","data":[{"asks":[["0.794","0","0","0"]],"bids":[],"ts":"1626995781114","checksum":-765150260}]}
1626995781.219873: {"arg":{"channel":"books-l2-tbt","instId":"AUCTION-USDT"},"action":"update","data":[{"asks":[],"bids":[["14.01","8.136099","0","2"]],"ts":"1626995781169","checksum":-1707538221}]}
1626995781.2368371: {"arg":{"channel":"books-l2-tbt","instId":"ONT-USDT"},"action":"update","data":[{"asks":[],"bids":[["0.6216","371","0","2"]],"ts":"1626995781188","checksum":-423300975}]}
1626995781.261568: {"arg":{"channel":"books-l2-tbt","instId":"XMR-USDT-SWAP"},"action":"update","data":[{"asks":[["196.26","241","0","2"]],"bids":[],"ts":"1626995781210","checksum":1699071945}]}
1626995781.267655: {"arg":{"channel":"books-l2-tbt","instId":"TRX-USDT-210924"},"action":"update","data":[{"asks":[["0.05588","0","0","0"],["0.05589","3","0","1"]],"bids":[["0.05422","4","0","2"],["0.05421","0","0","0"]],"ts":"1626995781217","checksum":-1382761186}]}
1626995781.2822988: {"arg":{"channel":"books-l2-tbt","instId":"OKT-BTC"},"action":"update","data":[{"asks":[],"bids":[["0.001469","0.30706","0","1"]],"ts":"1626995781229","checksum":-551100225}]}
1626995781.2823648: {"arg":{"channel":"books-l2-tbt","instId":"XMR-USDT-SWAP"},"action":"update","data":[{"asks":[],"bids":[["195.91","33","0","1"]],"ts":"1626995781230","checksum":1027272784}]}
1626995781.309951: {"arg":{"channel":"books-l2-tbt","instId":"ONT-USDT"},"action":"update","data":[{"asks":[],"bids":[["0.6209","9526.942","0","1"]],"ts":"1626995781259","checksum":2123772878}]}
1626995781.322119: {"arg":{"channel":"books-l2-tbt","instId":"TRX-USDT-210924"},"action":"update","data":[{"asks":[["0.05588","3","0","1"],["0.05589","0","0","0"]],"bids":[],"ts":"1626995781270","checksum":-1382761186}]}
1626995781.326506: {"arg":{"channel":"books-l2-tbt","instId":"XMR-USDT-SWAP"},"action":"update","data":[{"asks":[["196.26","427","0","3"]],"bids":[],"ts":"1626995781274","checksum":-1040521762}]}
1626995781.329195: {"arg":{"channel":"books-l2-tbt","instId":"ONT-USDT"},"action":"update","data":[{"asks":[],"bids":[["0.6208","405.5","0","1"]],"ts":"1626995781279","checksum":-1194445649}]}
1626995781.341395: {"arg":{"channel":"books-l2-tbt","instId":"AUCTION-USDT"},"action":"update","data":[{"asks":[],"bids":[["14.25","151.647444","0","1"]],"ts":"1626995781291","checksum":-874478062}]}
1626995781.350404: {"arg":{"channel":"books-l2-tbt","instId":"ONT-USDT"},"action":"update","data":[{"asks":[],"bids":[["0.6216","691","0","3"]],"ts":"1626995781300","checksum":156966480}]}
1626995781.426754: {"arg":{"channel":"trades","instId":"PAY-BTC"},"data":[{"instId":"PAY-BTC","tradeId":"6071317","px":"0.00000137","sz":"4886.217","side":"sell","ts":"1626995781373"}]}
1626995781.426826: {"arg":{"channel":"books-l2-tbt","instId":"XMR-USDT-SWAP"},"action":"update","data":[{"asks":[["197.03","0","0","0"]],"bids":[],"ts":"1626995781377","checksum":-1040521762}]}
1626995781.4341388: {"arg":{"channel":"books-l2-tbt","instId":"DHT-USDT"},"action":"update","data":[{"asks":[["0.809","423.1407","0","1"]],"bids":[],"ts":"1626995781381","checksum":224375159}]}
1626995781.440555: {"arg":{"channel":"books-l2-tbt","instId":"ONT-USDT"},"action":"update","data":[{"asks":[],"bids":[["0.6213","0","0","0"]],"ts":"1626995781390","checksum":-18926941}]}
1626995781.503448: {"arg":{"channel":"tickers","instId":"PAY-BTC"},"data":[{"instType":"SPOT","instId":"PAY-BTC","last":"0.00000137","lastSz":"4886.217","askPx":"0.00000139","askSz":"5342.072","bidPx":"0.00000136","bidSz":"4282.772","open24h":"0.00000136","high24h":"0.00000144","low24h":"0.00000136","sodUtc0":"0.00000138","sodUtc8":"0.00000138","volCcy24h":"45.125","vol24h":"32769188.382","ts":"1626995781444"}]}
1626995781.531308: {"arg":{"channel":"books-l2-tbt","instId":"ONT-USDT"},"action":"update","data":[{"asks":[],"bids":[["0.6216","1011","0","4"]],"ts":"1626995781480","checksum":398476765}]}
1626995781.542559: {"arg":{"channel":"books-l2-tbt","instId":"ONT-USDT"},"action":"update","data":[{"asks":[],"bids":[["0.6216","1331","0","5"]],"ts":"1626995781491","checksum":-112906576}]}
1626995781.55136: {"arg":{"channel":"books-l2-tbt","instId":"ONT-USDT"},"action":"update","data":[{"asks":[],"bids":[["0.6216","1651","0","6"]],"ts":"1626995781500","checksum":297506118}]}
1626995781.5557828: {"arg":{"channel":"books-l2-tbt","instId":"XMR-USDT-SWAP"},"action":"update","data":[{"asks":[["197.02","142","0","1"]],"bids":[],"ts":"1626995781502","checksum":-1040521762}]}
1626995781.565205: {"arg":{"channel":"books-l2-tbt","instId":"FUN-BTC"},"action":"update","data":[{"asks":[],"bids":[["0.000000405","0","0","0"]],"ts":"1626995781513","checksum":645519708}]}
1626995781.6359522: {"arg":{"channel":"books-l2-tbt","instId":"ONT-USDT"},"action":"update","data":[{"asks":[],"bids":[["0.6216","1331","0","5"]],"ts":"1626995781585","checksum":-112906576}]}
1626995781.679649: {"arg":{"channel":"books-l2-tbt","instId":"DHT-USDT"},"action":"update","data":[{"asks":[],"bids":[["0.734","778.4","0","1"]],"ts":"1626995781625","checksum":1655920288}]}
1626995781.7160041: {"arg":{"channel":"books-l2-tbt","instId":"ONT-USDT"},"action":"update","data":[{"asks":[],"bids":[["0.621","11058.227","0","2"]],"ts":"1626995781667","checksum":-706024325}]}
1626995781.7601159: {"arg":{"channel":"books-l2-tbt","instId":"OKT-BTC"},"action":"update","data":[{"asks":[],"bids":[["0.001469","2.95208731","0","2"]],"ts":"1626995781709","checksum":-1739138756}]}
1626995781.8388422: {"arg":{"channel":"books-l2-tbt","instId":"ONT-USDT"},"action":"update","data":[{"asks":[],"bids":[["0.6217","326.871136","0","2"],["0.6216","691","0","3"],["0.5898","0","0","0"]],"ts":"1626995781789","checksum":1512535071}]}
1626995781.8528068: {"arg":{"channel":"books-l2-tbt","instId":"FUN-BTC"},"action":"update","data":[{"asks":[],"bids":[["0.000000411","6743.11","0","1"]],"ts":"1626995781800","checksum":732530277}]}
1626995781.852938: {"arg":{"channel":"books-l2-tbt","instId":"ONT-USDT"},"action":"update","data":[{"asks":[],"bids":[["0.6216","371","0","2"]],"ts":"1626995781800","checksum":1506416939}]}
1626995781.8593888: {"arg":{"channel":"books-l2-tbt","instId":"ONT-USDT"},"action":"update","data":[{"asks":[],"bids":[["0.5897","294.795658","0","1"]],"ts":"1626995781809","checksum":1506416939}]}
1626995781.886011: {"arg":{"channel":"books-l2-tbt","instId":"ONT-USDT"},"action":"update","data":[{"asks":[],"bids":[["0.6216","51","0","1"]],"ts":"1626995781829","checksum":1134087048}]}
1626995781.905014: {"arg":{"channel":"books-l2-tbt","instId":"TRX-USDT-210924"},"action":"update","data":[{"asks":[["0.05588","0","0","0"],["0.05589","3","0","1"]],"bids":[],"ts":"1626995781854","checksum":-1382761186}]}
1626995781.945416: {"arg":{"channel":"books-l2-tbt","instId":"ONT-USDT"},"action":"update","data":[{"asks":[],"bids":[["0.6217","646.871136","0","3"]],"ts":"1626995781894","checksum":1958037059}]}
1626995781.989608: {"arg":{"channel":"books-l2-tbt","instId":"TRX-USDT-210924"},"action":"update","data":[{"asks":[["0.05588","3","0","1"],["0.05589","0","0","0"]],"bids":[],"ts":"1626995781935","checksum":-1382761186}]}
1626995782.0482712: {"arg":{"channel":"books-l2-tbt","instId":"ONT-USDT"},"action":"update","data":[{"asks":[],"bids":[["0.6218","320","0","1"]],"ts":"1626995781998","checksum":-425921751}]}
1626995782.066696: {"arg":{"channel":"books-l2-tbt","instId":"ONT-USDT"},"action":"update","data":[{"asks":[["0.6222","1548.873745","0","2"]],"bids":[],"ts":"1626995782009","checksum":942049909}]}
1626995782.0732028: {"arg":{"channel":"books-l2-tbt","instId":"ONT-USDT"},"action":"update","data":[{"asks":[],"bids":[["0.6215","1053.553072","0","2"],["0.6214","970.582509","0","2"],["0.6191","0","0","0"]],"ts":"1626995782020","checksum":-1013874821}]}
1626995782.098527: {"arg":{"channel":"books-l2-tbt","instId":"ONT-USDT"},"action":"update","data":[{"asks":[],"bids":[["0.6217","966.871136","0","4"]],"ts":"1626995782048","checksum":-425154391}]}
1626995782.110097: {"arg":{"channel":"books-l2-tbt","instId":"ONT-USDT"},"action":"update","data":[{"asks":[],"bids":[["0.6217","1286.871136","0","5"]],"ts":"1626995782057","checksum":-454344593}]}
1626995782.116964: {"arg":{"channel":"books-l2-tbt","instId":"OKT-BTC"},"action":"update","data":[{"asks":[],"bids":[["0.001452","0","0","0"]],"ts":"1626995782067","checksum":775457265}]}
1626995782.1183329: {"arg":{"channel":"books-l2-tbt","instId":"ONT-USDT"},"action":"update","data":[{"asks":[],"bids":[["0.6217","966.871136","0","4"],["0.6198","47","0","1"]],"ts":"1626995782068","checksum":-2119924194}]}
1626995782.130091: {"arg":{"channel":"books-l2-tbt","instId":"ONT-USDT"},"action":"update","data":[{"asks":[],"bids":[["0.6201","792.868423","0","2"]],"ts":"1626995782080","checksum":1787715327}]}
1626995782.131649: {"arg":{"channel":"books-l2-tbt","instId":"TRX-USDT-210924"},"action":"update","data":[{"asks":[["0.05588","0","0","0"],["0.05589","3","0","1"]],"bids":[],"ts":"1626995782082","checksum":-1382761186}]}
1626995782.17907: {"arg":{"channel":"books-l2-tbt","instId":"ONT-USDT"},"action":"update","data":[{"asks":[],"bids":[["0.6192","6965.224405","0","2"]],"ts":"1626995782129","checksum":-1896693444}]}
1626995782.200047: {"arg":{"channel":"books-l2-tbt","instId":"ONT-USDT"},"action":"update","data":[{"asks":[],"bids":[["0.6217","646.871136","0","3"]],"ts":"1626995782149","checksum":-1412753682}]}
1626995782.2001832: {"arg":{"channel":"books-l2-tbt","instId":"OKT-BTC"},"action":"update","data":[{"asks":[],"bids":[["0.00145","2.47","0","1"]],"ts":"1626995782150","checksum":-298281790}]}
1626995782.214786: {"arg":{"channel":"books-l2-tbt","instId":"TRX-USDT-210924"},"action":"update","data":[{"asks":[["0.05588","3","0","1"],["0.05589","0","0","0"]],"bids":[],"ts":"1626995782162","checksum":-1382761186}]}
1626995782.284608: {"arg":{"channel":"books-l2-tbt","instId":"ONT-USDT"},"action":"update","data":[{"asks":[],"bids":[["0.6216","371","0","2"]],"ts":"1626995782234","checksum":715076155}]}
1626995782.3173351: {"arg":{"channel":"books-l2-tbt","instId":"AUCTION-USDT"},"action":"update","data":[{"asks":[],"bids":[["14.25","0","0","0"]],"ts":"1626995782267","checksum":-1707538221}]}
1626995782.347937: {"arg":{"channel":"books-l2-tbt","instId":"OKT-BTC"},"action":"update","data":[{"asks":[["0.001475","0.4130644","0","1"]],"bids":[],"ts":"1626995782296","checksum":895045796}]}
1626995782.348035: {"arg":{"channel":"books-l2-tbt","instId":"ONT-USDT"},"action":"update","data":[{"asks":[],"bids":[["0.6218","0","0","0"]],"ts":"1626995782297","checksum":-1043854918}]}
1626995782.365054: {"arg":{"channel":"books-l2-tbt","instId":"ONT-USDT"},"action":"update","data":[{"asks":[["0.6227","740","0","1"],["1.1285","0","0","0"]],"bids":[],"ts":"1626995782316","checksum":-1977844168}]}
1626995782.3990002: {"arg":{"channel":"books-l2-tbt","instId":"ONT-USDT"},"action":"update","data":[{"asks":[],"bids":[["0.6217","6.871136","0","1"]],"ts":"1626995782348","checksum":-1511261218}]}
1626995782.439866: {"arg":{"channel":"books-l2-tbt","instId":"TRX-USDT-210924"},"action":"update","data":[{"asks":[["0.05448","2","0","1"],["0.0545","14","0","1"]],"bids":[],"ts":"1626995782386","checksum":-1624340387}]}
1626995782.440005: {"arg":{"channel":"books-l2-tbt","instId":"OKT-BTC"},"action":"update","data":[{"asks":[["0.001476","14.17873561","0","2"]],"bids":[],"ts":"1626995782387","checksum":1579143159}]}
1626995782.445347: {"arg":{"channel":"books-l2-tbt","instId":"TRX-USDT-210924"},"action":"update","data":[{"asks":[["0.05466","0","0","0"]],"bids":[],"ts":"1626995782396","checksum":-1921144408}]}
1626995782.449882: {"arg":{"channel":"books-l2-tbt","instId":"ONT-USDT"},"action":"update","data":[{"asks":[["0.6228","402.871384","0","2"]],"bids":[],"ts":"1626995782399","checksum":1446127844}]}
1626995782.458014: {"arg":{"channel":"books-l2-tbt","instId":"TRX-USDT-210924"},"action":"update","data":[{"asks":[["0.05462","258","0","3"]],"bids":[],"ts":"1626995782407","checksum":-1445863329}]}
1626995782.4771929: {"arg":{"channel":"books-l2-tbt","instId":"TRX-USDT-210924"},"action":"update","data":[{"asks":[],"bids":[["0.05442","494","0","4"],["0.05438","68","0","2"]],"ts":"1626995782427","checksum":-1180693520}]}
1626995782.509123: {"arg":{"channel":"books-l2-tbt","instId":"ONT-USDT"},"action":"update","data":[{"asks":[["0.6222","945.539","0","1"]],"bids":[["0.6216","691","0","3"]],"ts":"1626995782458","checksum":-448411827}]}
1626995782.541873: {"arg":{"channel":"books-l2-tbt","instId":"ONT-USDT"},"action":"update","data":[{"asks":[],"bids":[["0.6216","1011","0","4"]],"ts":"1626995782489","checksum":-846615250}]}
1626995782.571195: {"arg":{"channel":"books-l2-tbt","instId":"AUCTION-USDT"},"action":"update","data":[{"asks":[],"bids":[["14.3","358.2294","0","2"]],"ts":"1626995782521","checksum":1765487850}]}
1626995782.5803468: {"arg":{"channel":"books-l2-tbt","instId":"ONT-USDT"},"action":"update","data":[{"asks":[],"bids":[["0.6216","691","0","3"]],"ts":"1626995782528","checksum":-448411827}]}
1626995782.5829241: {"arg":{"channel":"books-l2-tbt","instId":"TRX-USDT-210924"},"action":"update","data":[{"asks":[],"bids":[["0.05422","1","0","1"],["0.05421","3","0","1"]],"ts":"1626995782531","checksum":-874721299}]}
1626995782.6130729: {"arg":{"channel":"trades","instId":"AUCTION-USDT"},"data":[{"instId":"AUCTION-USDT","tradeId":"584232","px":"14.87","sz":"0.668542","side":"buy","ts":"1626995782556"}]}
1626995782.62222: {"arg":{"channel":"books-l2-tbt","instId":"XMR-USDT-SWAP"},"action":"update","data":[{"asks":[],"bids":[["195.29","0","0","0"]],"ts":"1626995782571","checksum":-1040521762}]}
1626995782.638788: {"arg":{"channel":"books-l2-tbt","instId":"DHT-USDT"},"action":"update","data":[{"asks":[["0.809","0","0","0"]],"bids":[],"ts":"1626995782588","checksum":-552937011}]}
1626995782.685153: {"arg":{"channel":"books-l2-tbt","instId":"XMR-USDT-SWAP"},"action":"update","data":[{"asks":[],"bids":[["195.31","9","0","1"]],"ts":"1626995782634","checksum":-1040521762}]}
1626995782.717346: {"arg":{"channel":"tickers","instId":"AUCTION-USDT"},"data":[{"instType":"SPOT","instId":"AUCTION-USDT","last":"14.87","lastSz":"0.668542","askPx":"14.98","askSz":"2.665343","bidPx":"14.83","bidSz":"2.701428","open24h":"14.94","high24h":"15.43","low24h":"14.22","sodUtc0":"14.94","sodUtc8":"14.86","volCcy24h":"117858.234837","vol24h":"7932.673005","ts":"1626995782653"}]}
1626995782.728019: {"arg":{"channel":"books-l2-tbt","instId":"ONT-USDT"},"action":"update","data":[{"asks":[],"bids":[],"ts":"1626995782679","checksum":-448411827}]}
1626995782.730037: {"arg":{"channel":"books-l2-tbt","instId":"TRX-USDT-210924"},"action":"update","data":[{"asks":[],"bids":[],"ts":"1626995782680","checksum":-874721299}]}
1626995782.741781: {"arg":{"channel":"books-l2-tbt","instId":"ONT-USDT"},"action":"update","data":[{"asks":[],"bids":[["0.6216","1331","0","5"]],"ts":"1626995782692","checksum":1729063385}]}
1626995782.7641852: {"arg":{"channel":"books-l2-tbt","instId":"ONT-USDT"},"action":"update","data":[{"asks":[],"bids":[["0.6216","1651","0","6"]],"ts":"1626995782714","checksum":1140138625}]}
1626995782.784692: {"arg":{"channel":"books-l2-tbt","instId":"ONT-USDT"},"action":"update","data":[{"asks":[],"bids":[["0.6216","1331","0","5"]],"ts":"1626995782734","checksum":1729063385}]}
1626995782.817614: {"arg":{"channel":"books-l2-tbt","instId":"ONT-USDT"},"action":"update","data":[{"asks":[],"bids":[["0.6216","1011","0","4"]],"ts":"1626995782764","checksum":-846615250}]}
1626995782.837763: {"arg":{"channel":"books-l2-tbt","instId":"TRX-USDT-210924"},"action":"update","data":[{"asks":[["0.05448","0","0","0"]],"bids":[],"ts":"1626995782787","checksum":-1395395927}]}
1626995782.849154: {"arg":{"channel":"books-l2-tbt","instId":"TRX-USDT-210924"},"action":"update","data":[{"asks":[],"bids":[["0.05437","5","0","1"]],"ts":"1626995782799","checksum":-2146029274}]}
1626995782.88558: {"arg":{"channel":"books-l2-tbt","instId":"ONT-USDT"},"action":"update","data":[{"asks":[],"bids":[["0.6217","326.871136","0","2"]],"ts":"1626995782834","checksum":-1247532871}]}
1626995782.906454: {"arg":{"channel":"books-l2-tbt","instId":"DHT-USDT"},"action":"update","data":[{"asks":[],"bids":[["0.734","0","0","0"]],"ts":"1626995782856","checksum":-765150260}]}
1626995782.90707: {"arg":{"channel":"books-l2-tbt","instId":"ONT-USDT"},"action":"update","data":[{"asks":[],"bids":[["0.6217","646.871136","0","3"]],"ts":"1626995782857","checksum":-1188749812}]}
1626995782.9150898: {"arg":{"channel":"books-l2-tbt","instId":"ONT-USDT"},"action":"update","data":[{"asks":[["0.6226","10768.802","0","2"]],"bids":[],"ts":"1626995782865","checksum":252521527}]}
1626995782.990956: {"arg":{"channel":"books-l2-tbt","instId":"ONT-USDT"},"action":"update","data":[{"asks":[],"bids":[["0.6217","966.871136","0","4"]],"ts":"1626995782939","checksum":-1048944856}]}
1626995783.0423381: {"arg":{"channel":"books-l2-tbt","instId":"ONT-USDT"},"action":"update","data":[{"asks":[],"bids":[["0.6216","691","0","3"]],"ts":"1626995782991","checksum":671927696}]}
1626995783.052798: {"arg":{"channel":"books-l2-tbt","instId":"ONT-USDT"},"action":"update","data":[{"asks":[],"bids":[["0.6216","51","0","1"]],"ts":"1626995783000","checksum":-694151480}]}
1626995783.1055129: {"arg":{"channel":"books-l2-tbt","instId":"ONT-USDT"},"action":"update","data":[{"asks":[],"bids":[["0.6217","1606.871136","0","6"]],"ts":"1626995783055","checksum":-181074743}]}
1626995783.12516: {"arg":{"channel":"books-l2-tbt","instId":"ONT-USDT"},"action":"update","data":[{"asks":[],"bids":[["0.6217","1926.871136","0","7"]],"ts":"1626995783075","checksum":242890262}]}
1626995783.163577: {"arg":{"channel":"books-l2-tbt","instId":"DHT-USDT"},"action":"update","data":[{"asks":[["0.795","423.1407","0","1"]],"bids":[],"ts":"1626995783112","checksum":-746928502}]}
1626995783.1974669: {"arg":{"channel":"books-l2-tbt","instId":"ONT-USDT"},"action":"update","data":[{"asks":[],"bids":[["0.6217","1606.871136","0","6"]],"ts":"1626995783148","checksum":-181074743}]}
1626995783.210651: {"arg":{"channel":"books-l2-tbt","instId":"ONT-USDT"},"action":"update","data":[{"asks":[],"bids":[["0.6217","1286.871136","0","5"]],"ts":"1626995783159","checksum":-359423229}]}
1626995783.261278: {"arg":{"channel":"books-l2-tbt","instId":"ONT-USDT"},"action":"update","data":[{"asks":[["0.6226","390","0","1"]],"bids":[["0.6217","966.871136","0","4"]],"ts":"1626995783211","checksum":-1893978316}]}
1626995783.2803352: {"arg":{"channel":"books-l2-tbt","instId":"ONT-USDT"},"action":"update","data":[{"asks":[["0.6229","9330.33355","0","3"]],"bids":[["0.6218","640","0","2"]],"ts":"1626995783230","checksum":1953007708}]}
1626995783.315538: {"arg":{"channel":"books-l2-tbt","instId":"ONT-USDT"},"action":"update","data":[{"asks":[],"bids":[["0.6218","960","0","3"]],"ts":"1626995783263","checksum":215066916}]}
1626995783.315583: {"arg":{"channel":"books-l2-tbt","instId":"OKT-BTC"},"action":"update","data":[{"asks":[["0.001476","11.54107264","0","1"]],"bids":[],"ts":"1626995783263","checksum":895045796}]}
1626995783.384726: {"arg":{"channel":"books-l2-tbt","instId":"DHT-USDT"},"action":"update","data":[{"asks":[],"bids":[["0.722","791.3374","0","1"]],"ts":"1626995783333","checksum":-1081941396}]}
