1626995781.552192: {"arg":{"channel":"books-l2-tbt","instId":"XMR-USDT-SWAP"},"action":"update","data":[{"asks":[["197.02","142","0","1"]],"bids":[],"ts":"1626995781502","checksum":-1040521762}]}
1626995781.563096: {"arg":{"channel":"books-l2-tbt","instId":"FUN-BTC"},"action":"update","data":[{"asks":[],"bids":[["0.000000405","0","0","0"]],"ts":"1626995781513","checksum":645519708}]}
1626995781.635725: {"arg":{"channel":"books-l2-tbt","instId":"ONT-USDT"},"action":"update","data":[{"asks":[],"bids":[["0.6216","1331","0","5"]],"ts":"1626995781585","checksum":-112906576}]}
1626995781.674796: {"arg":{"channel":"books-l2-tbt","instId":"DHT-USDT"},"action":"update","data":[{"asks":[],"bids":[["0.734","778.4","0","1"]],"ts":"1626995781625","checksum":1655920288}]}
1626995781.715859: {"arg":{"channel":"books-l2-tbt","instId":"ONT-USDT"},"action":"update","data":[{"asks":[],"bids":[["0.621","11058.227","0","2"]],"ts":"1626995781667","checksum":-706024325}]}
1626995781.760368: {"arg":{"channel":"books-l2-tbt","instId":"OKT-BTC"},"action":"update","data":[{"asks":[],"bids":[["0.001469","2.95208731","0","2"]],"ts":"1626995781709","checksum":-1739138756}]}
1626995781.838618: {"arg":{"channel":"books-l2-tbt","instId":"ONT-USDT"},"action":"update","data":[{"asks":[],"bids":[["0.6217","326.871136","0","2"],["0.6216","691","0","3"],["0.5898","0","0","0"]],"ts":"1626995781789","checksum":1512535071}]}
1626995781.849611: {"arg":{"channel":"books-l2-tbt","instId":"FUN-BTC"},"action":"update","data":[{"asks":[],"bids":[["0.000000411","6743.11","0","1"]],"ts":"1626995781800","checksum":732530277}]}
1626995781.84974: {"arg":{"channel":"books-l2-tbt","instId":"ONT-USDT"},"action":"update","data":[{"asks":[],"bids":[["0.6216","371","0","2"]],"ts":"1626995781800","checksum":1506416939}]}
1626995781.859614: {"arg":{"channel":"books-l2-tbt","instId":"ONT-USDT"},"action":"update","data":[{"asks":[],"bids":[["0.5897","294.795658","0","1"]],"ts":"1626995781809","checksum":1506416939}]}
1626995781.8781571: {"arg":{"channel":"books-l2-tbt","instId":"ONT-USDT"},"action":"update","data":[{"asks":[],"bids":[["0.6216","51","0","1"]],"ts":"1626995781829","checksum":1134087048}]}
1626995781.904793: {"arg":{"channel":"books-l2-tbt","instId":"TRX-USDT-210924"},"action":"update","data":[{"asks":[["0.05588","0","0","0"],["0.05589","3","0","1"]],"bids":[],"ts":"1626995781854","checksum":-1382761186}]}
1626995781.945206: {"arg":{"channel":"books-l2-tbt","instId":"ONT-USDT"},"action":"update","data":[{"asks":[],"bids":[["0.6217","646.871136","0","3"]],"ts":"1626995781894","checksum":1958037059}]}
1626995781.986631: {"arg":{"channel":"books-l2-tbt","instId":"TRX-USDT-210924"},"action":"update","data":[{"asks":[["0.05588","3","0","1"],["0.05589","0","0","0"]],"bids":[],"ts":"1626995781935","checksum":-1382761186}]}
1626995782.048053: {"arg":{"channel":"books-l2-tbt","instId":"ONT-USDT"},"action":"update","data":[{"asks":[],"bids":[["0.6218","320","0","1"]],"ts":"1626995781998","checksum":-425921751}]}
1626995782.058642: {"arg":{"channel":"books-l2-tbt","instId":"ONT-USDT"},"action":"update","data":[{"asks":[["0.6222","1548.873745","0","2"]],"bids":[],"ts":"1626995782009","checksum":942049909}]}
1626995782.070484: {"arg":{"channel":"books-l2-tbt","instId":"ONT-USDT"},"action":"update","data":[{"asks":[],"bids":[["0.6215","1053.553072","0","2"],["0.6214","970.582509","0","2"],["0.6191","0","0","0"]],"ts":"1626995782020","checksum":-1013874821}]}
1626995782.0983: {"arg":{"channel":"books-l2-tbt","instId":"ONT-USDT"},"action":"update","data":[{"asks":[],"bids":[["0.6217","966.871136","0","4"]],"ts":"1626995782048","checksum":-425154391}]}
1626995782.106007: {"arg":{"channel":"books-l2-tbt","instId":"ONT-USDT"},"action":"update","data":[{"asks":[],"bids":[["0.6217","1286.871136","0","5"]],"ts":"1626995782057","checksum":-454344593}]}
1626995782.116558: {"arg":{"channel":"books-l2-tbt","instId":"OKT-BTC"},"action":"update","data":[{"asks":[],"bids":[["0.001452","0","0","0"]],"ts":"1626995782067","checksum":775457265}]}
1626995782.116652: {"arg":{"channel":"books-l2-tbt","instId":"ONT-USDT"},"action":"update","data":[{"asks":[],"bids":[["0.6217","966.871136","0","4"],["0.6198","47","0","1"]],"ts":"1626995782068","checksum":-2119924194}]}
1626995782.130005: {"arg":{"channel":"books-l2-tbt","instId":"ONT-USDT"},"action":"update","data":[{"asks":[],"bids":[["0.6201","792.868423","0","2"]],"ts":"1626995782080","checksum":1787715327}]}
1626995782.131495: {"arg":{"channel":"books-l2-tbt","instId":"TRX-USDT-210924"},"action":"update","data":[{"asks":[["0.05588","0","0","0"],["0.05589","3","0","1"]],"bids":[],"ts":"1626995782082","checksum":-1382761186}]}
1626995782.1788568: {"arg":{"channel":"books-l2-tbt","instId":"ONT-USDT"},"action":"update","data":[{"asks":[],"bids":[["0.6192","6965.224405","0","2"]],"ts":"1626995782129","checksum":-1896693444}]}
1626995782.200324: {"arg":{"channel":"books-l2-tbt","instId":"ONT-USDT"},"action":"update","data":[{"asks":[],"bids":[["0.6217","646.871136","0","3"]],"ts":"1626995782149","checksum":-1412753682}]}
1626995782.200366: {"arg":{"channel":"books-l2-tbt","instId":"OKT-BTC"},"action":"update","data":[{"asks":[],"bids":[["0.00145","2.47","0","1"]],"ts":"1626995782150","checksum":-298281790}]}
1626995782.2124522: {"arg":{"channel":"books-l2-tbt","instId":"TRX-USDT-210924"},"action":"update","data":[{"asks":[["0.05588","3","0","1"],["0.05589","0","0","0"]],"bids":[],"ts":"1626995782162","checksum":-1382761186}]}
1626995782.2827048: {"arg":{"channel":"books-l2-tbt","instId":"ONT-USDT"},"action":"update","data":[{"asks":[],"bids":[["0.6216","371","0","2"]],"ts":"1626995782234","checksum":715076155}]}
1626995782.316752: {"arg":{"channel":"books-l2-tbt","instId":"AUCTION-USDT"},"action":"update","data":[{"asks":[],"bids":[["14.25","0","0","0"]],"ts":"1626995782267","checksum":-1707538221}]}
1626995782.347661: {"arg":{"channel":"books-l2-tbt","instId":"OKT-BTC"},"action":"update","data":[{"asks":[["0.001475","0.4130644","0","1"]],"bids":[],"ts":"1626995782296","checksum":895045796}]}
1626995782.3477912: {"arg":{"channel":"books-l2-tbt","instId":"ONT-USDT"},"action":"update","data":[{"asks":[],"bids":[["0.6218","0","0","0"]],"ts":"1626995782297","checksum":-1043854918}]}
1626995782.364634: {"arg":{"channel":"books-l2-tbt","instId":"ONT-USDT"},"action":"update","data":[{"asks":[["0.6227","740","0","1"],["1.1285","0","0","0"]],"bids":[],"ts":"1626995782316","checksum":-1977844168}]}
1626995782.3987908: {"arg":{"channel":"books-l2-tbt","instId":"ONT-USDT"},"action":"update","data":[{"asks":[],"bids":[["0.6217","6.871136","0","1"]],"ts":"1626995782348","checksum":-1511261218}]}
1626995782.4360251: {"arg":{"channel":"books-l2-tbt","instId":"TRX-USDT-210924"},"action":"update","data":[{"asks":[["0.05448","2","0","1"],["0.0545","14","0","1"]],"bids":[],"ts":"1626995782386","checksum":-1624340387}]}
1626995782.436165: {"arg":{"channel":"books-l2-tbt","instId":"OKT-BTC"},"action":"update","data":[{"asks":[["0.001476","14.17873561","0","2"]],"bids":[],"ts":"1626995782387","checksum":1579143159}]}
1626995782.44517: {"arg":{"channel":"books-l2-tbt","instId":"TRX-USDT-210924"},"action":"update","data":[{"asks":[["0.05466","0","0","0"]],"bids":[],"ts":"1626995782396","checksum":-1921144408}]}
1626995782.449667: {"arg":{"channel":"books-l2-tbt","instId":"ONT-USDT"},"action":"update","data":[{"asks":[["0.6228","402.871384","0","2"]],"bids":[],"ts":"1626995782399","checksum":1446127844}]}
1626995782.460284: {"arg":{"channel":"books-l2-tbt","instId":"TRX-USDT-210924"},"action":"update","data":[{"asks":[["0.05462","258","0","3"]],"bids":[],"ts":"1626995782407","checksum":-1445863329}]}
1626995782.476974: {"arg":{"channel":"books-l2-tbt","instId":"TRX-USDT-210924"},"action":"update","data":[{"asks":[],"bids":[["0.05442","494","0","4"],["0.05438","68","0","2"]],"ts":"1626995782427","checksum":-1180693520}]}
1626995782.5089018: {"arg":{"channel":"books-l2-tbt","instId":"ONT-USDT"},"action":"update","data":[{"asks":[["0.6222","945.539","0","1"]],"bids":[["0.6216","691","0","3"]],"ts":"1626995782458","checksum":-448411827}]}
1626995782.538517: {"arg":{"channel":"books-l2-tbt","instId":"ONT-USDT"},"action":"update","data":[{"asks":[],"bids":[["0.6216","1011","0","4"]],"ts":"1626995782489","checksum":-846615250}]}
1626995782.570988: {"arg":{"channel":"books-l2-tbt","instId":"AUCTION-USDT"},"action":"update","data":[{"asks":[],"bids":[["14.3","358.2294","0","2"]],"ts":"1626995782521","checksum":1765487850}]}
1626995782.5784588: {"arg":{"channel":"books-l2-tbt","instId":"ONT-USDT"},"action":"update","data":[{"asks":[],"bids":[["0.6216","691","0","3"]],"ts":"1626995782528","checksum":-448411827}]}
1626995782.580492: {"arg":{"channel":"books-l2-tbt","instId":"TRX-USDT-210924"},"action":"update","data":[{"asks":[],"bids":[["0.05422","1","0","1"],["0.05421","3","0","1"]],"ts":"1626995782531","checksum":-874721299}]}
1626995782.609809: {"arg":{"channel":"trades","instId":"AUCTION-USDT"},"data":[{"instId":"AUCTION-USDT","tradeId":"584232","px":"14.87","sz":"0.668542","side":"buy","ts":"1626995782556"}]}
1626995782.622016: {"arg":{"channel":"books-l2-tbt","instId":"XMR-USDT-SWAP"},"action":"update","data":[{"asks":[],"bids":[["195.29","0","0","0"]],"ts":"1626995782571","checksum":-1040521762}]}
1626995782.638581: {"arg":{"channel":"books-l2-tbt","instId":"DHT-USDT"},"action":"update","data":[{"asks":[["0.809","0","0","0"]],"bids":[],"ts":"1626995782588","checksum":-552937011}]}
1626995782.6849432: {"arg":{"channel":"books-l2-tbt","instId":"XMR-USDT-SWAP"},"action":"update","data":[{"asks":[],"bids":[["195.31","9","0","1"]],"ts":"1626995782634","checksum":-1040521762}]}
1626995782.717417: {"arg":{"channel":"tickers","instId":"AUCTION-USDT"},"data":[{"instType":"SPOT","instId":"AUCTION-USDT","last":"14.87","lastSz":"0.668542","askPx":"14.98","askSz":"2.665343","bidPx":"14.83","bidSz":"2.701428","open24h":"14.94","high24h":"15.43","low24h":"14.22","sodUtc0":"14.94","sodUtc8":"14.86","volCcy24h":"117858.234837","vol24h":"7932.673005","ts":"1626995782653"}]}
1626995782.727881: {"arg":{"channel":"books-l2-tbt","instId":"ONT-USDT"},"action":"update","data":[{"asks":[],"bids":[],"ts":"1626995782679","checksum":-448411827}]}
1626995782.728308: {"arg":{"channel":"books-l2-tbt","instId":"TRX-USDT-210924"},"action":"update","data":[{"asks":[],"bids":[],"ts":"1626995782680","checksum":-874721299}]}
1626995782.741864: {"arg":{"channel":"books-l2-tbt","instId":"ONT-USDT"},"action":"update","data":[{"asks":[],"bids":[["0.6216","1331","0","5"]],"ts":"1626995782692","checksum":1729063385}]}
1626995782.7639658: {"arg":{"channel":"books-l2-tbt","instId":"ONT-USDT"},"action":"update","data":[{"asks":[],"bids":[["0.6216","1651","0","6"]],"ts":"1626995782714","checksum":1140138625}]}
1626995782.78447: {"arg":{"channel":"books-l2-tbt","instId":"ONT-USDT"},"action":"update","data":[{"asks":[],"bids":[["0.6216","1331","0","5"]],"ts":"1626995782734","checksum":1729063385}]}
1626995782.8143392: {"arg":{"channel":"books-l2-tbt","instId":"ONT-USDT"},"action":"update","data":[{"asks":[],"bids":[["0.6216","1011","0","4"]],"ts":"1626995782764","checksum":-846615250}]}
1626995782.83691: {"arg":{"channel":"books-l2-tbt","instId":"TRX-USDT-210924"},"action":"update","data":[{"asks":[["0.05448","0","0","0"]],"bids":[],"ts":"1626995782787","checksum":-1395395927}]}
1626995782.848572: {"arg":{"channel":"books-l2-tbt","instId":"TRX-USDT-210924"},"action":"update","data":[{"asks":[],"bids":[["0.05437","5","0","1"]],"ts":"1626995782799","checksum":-2146029274}]}
1626995782.885369: {"arg":{"channel":"books-l2-tbt","instId":"ONT-USDT"},"action":"update","data":[{"asks":[],"bids":[["0.6217","326.871136","0","2"]],"ts":"1626995782834","checksum":-1247532871}]}
1626995782.922057: {"arg":{"channel":"books-l2-tbt","instId":"DHT-USDT"},"action":"update","data":[{"asks":[],"bids":[["0.734","0","0","0"]],"ts":"1626995782856","checksum":-765150260}]}
1626995782.9221811: {"arg":{"channel":"books-l2-tbt","instId":"ONT-USDT"},"action":"update","data":[{"asks":[],"bids":[["0.6217","646.871136","0","3"]],"ts":"1626995782857","checksum":-1188749812}]}
1626995782.92225: {"arg":{"channel":"books-l2-tbt","instId":"ONT-USDT"},"action":"update","data":[{"asks":[["0.6226","10768.802","0","2"]],"bids":[],"ts":"1626995782865","checksum":252521527}]}
1626995782.988993: {"arg":{"channel":"books-l2-tbt","instId":"ONT-USDT"},"action":"update","data":[{"asks":[],"bids":[["0.6217","966.871136","0","4"]],"ts":"1626995782939","checksum":-1048944856}]}
1626995783.042117: {"arg":{"channel":"books-l2-tbt","instId":"ONT-USDT"},"action":"update","data":[{"asks":[],"bids":[["0.6216","691","0","3"]],"ts":"1626995782991","checksum":671927696}]}
1626995783.050543: {"arg":{"channel":"books-l2-tbt","instId":"ONT-USDT"},"action":"update","data":[{"asks":[],"bids":[["0.6216","51","0","1"]],"ts":"1626995783000","checksum":-694151480}]}
1626995783.104352: {"arg":{"channel":"books-l2-tbt","instId":"ONT-USDT"},"action":"update","data":[{"asks":[],"bids":[["0.6217","1606.871136","0","6"]],"ts":"1626995783055","checksum":-181074743}]}
1626995783.124942: {"arg":{"channel":"books-l2-tbt","instId":"ONT-USDT"},"action":"update","data":[{"asks":[],"bids":[["0.6217","1926.871136","0","7"]],"ts":"1626995783075","checksum":242890262}]}
1626995783.161953: {"arg":{"channel":"books-l2-tbt","instId":"DHT-USDT"},"action":"update","data":[{"asks":[["0.795","423.1407","0","1"]],"bids":[],"ts":"1626995783112","checksum":-746928502}]}
1626995783.1973271: {"arg":{"channel":"books-l2-tbt","instId":"ONT-USDT"},"action":"update","data":[{"asks":[],"bids":[["0.6217","1606.871136","0","6"]],"ts":"1626995783148","checksum":-181074743}]}
1626995783.208766: {"arg":{"channel":"books-l2-tbt","instId":"ONT-USDT"},"action":"update","data":[{"asks":[],"bids":[["0.6217","1286.871136","0","5"]],"ts":"1626995783159","checksum":-359423229}]}
1626995783.26106: {"arg":{"channel":"books-l2-tbt","instId":"ONT-USDT"},"action":"update","data":[{"asks":[["0.6226","390","0","1"]],"bids":[["0.6217","966.871136","0","4"]],"ts":"1626995783211","checksum":-1893978316}]}
1626995783.280116: {"arg":{"channel":"books-l2-tbt","instId":"ONT-USDT"},"action":"update","data":[{"asks":[["0.6229","9330.33355","0","3"]],"bids":[["0.6218","640","0","2"]],"ts":"1626995783230","checksum":1953007708}]}
1626995783.3152661: {"arg":{"channel":"books-l2-tbt","instId":"ONT-USDT"},"action":"update","data":[{"asks":[],"bids":[["0.6218","960","0","3"]],"ts":"1626995783263","checksum":215066916}]}
1626995783.315368: {"arg":{"channel":"books-l2-tbt","instId":"OKT-BTC"},"action":"update","data":[{"asks":[["0.001476","11.54107264","0","1"]],"bids":[],"ts":"1626995783263","checksum":895045796}]}
1626995783.3912919: {"arg":{"channel":"books-l2-tbt","instId":"DHT-USDT"},"action":"update","data":[{"asks":[],"bids":[["0.722","791.3374","0","1"]],"ts":"1626995783333","checksum":-1081941396}]}
