1646003669.423176: {"arg":{"channel":"books-l2-tbt","instId":"UNI-USD-SWAP"},"action":"update","data":[{"asks":[["9.649","1230","0","2"],["9.658","61","0","2"]],"bids":[["9.61","21","0","1"],["9.606","80","0","1"],["9.605","56","0","2"],["9.603","1248","0","1"],["9.586","162","0","2"]],"ts":"1646003669409","checksum":1643765071}]}
1646003669.429746: {"arg":{"channel":"books-l2-tbt","instId":"ELON-USDT"},"action":"update","data":[{"asks":[],"bids":[["0.00000069607","392232580","0","1"],["0.00000068215","357069727","0","1"],["0.00000066851","304808572","0","1"],["0.00000065514","258030494","0","1"]],"ts":"1646003669419","checksum":-97942910}]}
1646003669.437995: {"arg":{"channel":"books-l2-tbt","instId":"UNI-USD-SWAP"},"action":"update","data":[{"asks":[],"bids":[["9.586","142","0","1"]],"ts":"1646003669426","checksum":966091918}]}
1646003669.440432: {"arg":{"channel":"books-l2-tbt","instId":"ZEN-USDT"},"action":"update","data":[{"asks":[],"bids":[["32.41","80.422707","0","2"]],"ts":"1646003669429","checksum":471970228}]}
1646003669.4457548: {"arg":{"channel":"books-l2-tbt","instId":"ELON-USDT"},"action":"update","data":[{"asks":[],"bids":[["0.00000074381","184440410","0","1"]],"ts":"1646003669430","checksum":1671702988}]}
1646003669.450305: {"arg":{"channel":"books-l2-tbt","instId":"ELON-USDT"},"action":"update","data":[{"asks":[["0.00000074493","0","0","0"],["0.00000113315","35900750","0","1"]],"bids":[],"ts":"1646003669438","checksum":-695770647}]}
1646003669.46433: {"arg":{"channel":"books-l2-tbt","instId":"UNI-USD-SWAP"},"action":"update","data":[{"asks":[["9.636","166","0","2"],["9.637","149","0","1"]],"bids":[],"ts":"1646003669451","checksum":1747022537}]}
1646003669.464448: {"arg":{"channel":"books-l2-tbt","instId":"ELON-USDT"},"action":"update","data":[{"asks":[],"bids":[["0.00000074101","750000000","0","1"]],"ts":"1646003669451","checksum":-972790238}]}
1646003669.469467: {"arg":{"channel":"books-l2-tbt","instId":"ELON-USDT"},"action":"update","data":[{"asks":[["0.00000074492","0","0","0"],["0.00000074548","111748770","0","1"]],"bids":[["0.00000074351","0","0","0"]],"ts":"1646003669459","checksum":1979325020}]}
1646003669.483878: {"arg":{"channel":"books-l2-tbt","instId":"ELON-USDT"},"action":"update","data":[{"asks":[["0.00000074491","104045940","0","1"],["0.00000074548","0","0","0"]],"bids":[],"ts":"1646003669471","checksum":491885381}]}
1646003669.484017: {"arg":{"channel":"books-l2-tbt","instId":"UNI-USD-SWAP"},"action":"update","data":[{"asks":[["9.636","164","0","1"]],"bids":[],"ts":"1646003669472","checksum":512787549}]}
1646003669.488896: {"arg":{"channel":"books-l2-tbt","instId":"ETH-USD-220624-12000-P"},"action":"update","data":[{"asks":[["4.041","0","0","0"],["4.0415","201","0","1"]],"bids":[],"ts":"1646003669477","checksum":137283980}]}
1646003669.5061069: {"arg":{"channel":"books-l2-tbt","instId":"ELON-USDT"},"action":"update","data":[{"asks":[["0.00000074491","0","0","0"],["0.00000074548","111748770","0","1"]],"bids":[],"ts":"1646003669492","checksum":1979325020}]}
1646003669.506182: {"arg":{"channel":"books-l2-tbt","instId":"UNI-USD-SWAP"},"action":"update","data":[{"asks":[["9.635","1","0","1"],["48.868","0","0","0"]],"bids":[["9.62","135","0","2"]],"ts":"1646003669493","checksum":-1607532478}]}
1646003669.512846: {"arg":{"channel":"books-l2-tbt","instId":"ELON-USDT"},"action":"update","data":[{"asks":[["0.00000074547","445226872","0","1"],["0.00000113315","0","0","0"]],"bids":[],"ts":"1646003669500","checksum":723901286}]}
1646003669.524531: {"arg":{"channel":"books-l2-tbt","instId":"ELON-USDT"},"action":"update","data":[{"asks":[["0.00000074548","215794710","0","2"],["0.00000074708","4038943392","0","1"],["0.00000113256","0","0","0"]],"bids":[["0.00000074381","0","0","0"],["0.00000074338","4038943392","0","1"],["0.00000074244","0","0","0"]],"ts":"1646003669511","checksum":14038384}]}
1646003669.5269718: {"arg":{"channel":"books-l2-tbt","instId":"UNI-USD-SWAP"},"action":"update","data":[{"asks":[["9.652","16","0","1"],["9.655","242","0","2"],["9.658","35","0","1"]],"bids":[["9.61","0","0","0"],["9.608","0","0","0"],["9.605","29","0","1"]],"ts":"1646003669515","checksum":-1783351225}]}
1646003669.5322099: {"arg":{"channel":"books-l2-tbt","instId":"ELON-USDT"},"action":"update","data":[{"asks":[["0.00000074548","0","0","0"],["0.00000074549","0","0","0"],["0.00000113256","10462875","0","1"],["0.00000113315","35900750","0","1"]],"bids":[],"ts":"1646003669520","checksum":-1667638396}]}
1646003669.5366778: {"arg":{"channel":"books-l2-tbt","instId":"UNI-USD-SWAP"},"action":"update","data":[{"asks":[["9.65","25","0","1"],["9.653","26","0","1"],["9.656","145","0","2"],["48.383","0","0","0"],["48.625","0","0","0"]],"bids":[["9.611","526","0","2"],["9.609","23","0","1"],["9.606","108","0","2"]],"ts":"1646003669524","checksum":-1732092876}]}
1646003669.543156: {"arg":{"channel":"books-l2-tbt","instId":"ELON-USDT"},"action":"update","data":[{"asks":[["0.00000074546","111748770","0","1"],["0.0000007455","0","0","0"]],"bids":[],"ts":"1646003669531","checksum":-818212452}]}
1646003669.563156: {"arg":{"channel":"books-l2-tbt","instId":"ELON-USDT"},"action":"update","data":[{"asks":[],"bids":[["0.00000074348","0","0","0"]],"ts":"1646003669552","checksum":584114077}]}
1646003669.5749068: {"arg":{"channel":"books-l2-tbt","instId":"ZEN-USDT"},"action":"update","data":[{"asks":[["32.62","52.12196","0","2"]],"bids":[["32.42","39.740599","0","2"]],"ts":"1646003669559","checksum":-158097853}]}
1646003669.575028: {"arg":{"channel":"books-l2-tbt","instId":"ELON-USDT"},"action":"update","data":[{"asks":[["0.00000074547","0","0","0"],["0.0000011338","129154981","0","1"]],"bids":[["0.00000074381","170687840","0","1"]],"ts":"1646003669563","checksum":1328736925}]}
1646003669.583168: {"arg":{"channel":"books-l2-tbt","instId":"ELON-USDT"},"action":"update","data":[{"asks":[["0.00000074545","445226872","0","1"],["0.0000011338","0","0","0"]],"bids":[],"ts":"1646003669571","checksum":1966510355}]}
1646003669.593718: {"arg":{"channel":"books-l2-tbt","instId":"ELON-USDT"},"action":"update","data":[{"asks":[["0.00000074546","0","0","0"],["0.00000074615","0","0","0"],["0.0000011338","129154981","0","1"],["0.0000011372","6179288","0","1"]],"bids":[["0.00000074343","649039209","0","1"],["0.00000074243","0","0","0"]],"ts":"1646003669581","checksum":112305028}]}
1646003669.605382: {"arg":{"channel":"books-l2-tbt","instId":"ELON-USDT"},"action":"update","data":[{"asks":[["0.00000074544","199255828","0","4"],["0.00000074643","496717636","0","1"],["0.0000011338","0","0","0"],["0.0000011372","0","0","0"]],"bids":[],"ts":"1646003669593","checksum":-711778101}]}
1646003669.6193879: {"arg":{"channel":"books-l2-tbt","instId":"ETH-USD-220325-8800-P"},"action":"update","data":[{"asks":[["2.5465","0","0","0"],["2.547","201","0","1"]],"bids":[],"ts":"1646003669606","checksum":-2044168485}]}
1646003669.622609: {"arg":{"channel":"books-l2-tbt","instId":"UNI-USD-SWAP"},"action":"update","data":[{"asks":[],"bids":[["9.619","325","0","3"],["9.608","147","0","1"]],"ts":"1646003669609","checksum":-1214410801}]}
1646003669.6339068: {"arg":{"channel":"books-l2-tbt","instId":"ELON-USDT"},"action":"update","data":[{"asks":[],"bids":[["0.00000074434","107712494","0","1"]],"ts":"1646003669622","checksum":1333214986}]}
1646003669.651937: {"arg":{"channel":"books-l2-tbt","instId":"ELON-USDT"},"action":"update","data":[{"asks":[["0.00000074588","445226872","0","1"],["0.00000113315","0","0","0"]],"bids":[],"ts":"1646003669633","checksum":-1328433142}]}
1646003669.656001: {"arg":{"channel":"books-l2-tbt","instId":"ELON-USDT"},"action":"update","data":[{"asks":[["0.00000074708","0","0","0"],["0.00000113315","35900750","0","1"]],"bids":[],"ts":"1646003669644","checksum":-677834708}]}
1646003669.665737: {"arg":{"channel":"books-l2-tbt","instId":"ELON-USDT"},"action":"update","data":[{"asks":[],"bids":[["0.00000074434","0","0","0"]],"ts":"1646003669653","checksum":-693534446}]}
1646003669.675612: {"arg":{"channel":"books-l2-tbt","instId":"ELON-USDT"},"action":"update","data":[{"asks":[["0.00000074545","0","0","0"],["0.00000074589","0","0","0"],["0.0000011338","129154981","0","1"],["0.0000011372","6179288","0","1"]],"bids":[],"ts":"1646003669664","checksum":385769448}]}
1646003669.686912: {"arg":{"channel":"books-l2-tbt","instId":"ELON-USDT"},"action":"update","data":[{"asks":[["0.00000074544","247271501","0","5"],["0.00000074643","0","0","0"],["0.00000074691","0","0","0"],["0.00000113812","12211658","0","1"],["0.00000113853","6145556","0","1"]],"bids":[["0.00000074118","0","0","0"]],"ts":"1646003669674","checksum":-568738687}]}
1646003669.695189: {"arg":{"channel":"books-l2-tbt","instId":"UNI-USD-SWAP"},"action":"update","data":[{"asks":[["9.649","1253","0","3"],["9.65","0","0","0"],["9.652","36","0","2"],["9.653","0","0","0"],["9.655","272","0","3"],["9.656","124","0","1"],["48.383","1","0","1"],["48.625","1","0","1"]],"bids":[["9.611","500","0","1"],["9.607","24","0","1"],["9.606","80","0","1"],["9.604","341","0","3"]],"ts":"1646003669682","checksum":1827818328}]}
1646003669.6977742: {"arg":{"channel":"books-l2-tbt","instId":"ELON-USDT"},"action":"update","data":[{"asks":[["0.00000074544","199255828","0","4"],["0.00000074642","496720970","0","1"],["0.00000113853","0","0","0"]],"bids":[["0.00000074381","0","0","0"],["0.00000074343","0","0","0"],["0.0000007429","671280602","0","1"]],"ts":"1646003669686","checksum":1017873282}]}
1646003669.702573: {"arg":{"channel":"books-l2-tbt","instId":"UNI-USD-SWAP"},"action":"update","data":[{"asks":[],"bids":[["9.584","176","0","4"]],"ts":"1646003669691","checksum":1827818328}]}
1646003669.70701: {"arg":{"channel":"books-l2-tbt","instId":"ELON-USDT"},"action":"update","data":[{"asks":[["0.00000074587","48015673","0","1"],["0.00000113812","0","0","0"]],"bids":[["0.0000007433","0","0","0"]],"ts":"1646003669695","checksum":1349267156}]}
1646003669.7178051: {"arg":{"channel":"books-l2-tbt","instId":"ZEN-USDT"},"action":"update","data":[{"asks":[],"bids":[["31.82","0","0","0"]],"ts":"1646003669705","checksum":-158097853}]}
1646003669.719614: {"arg":{"channel":"books-l2-tbt","instId":"ELON-USDT"},"action":"update","data":[{"asks":[["0.00000074741","3470139686","0","1"],["0.0000011372","0","0","0"]],"bids":[["0.00000074434","184440410","0","1"]],"ts":"1646003669706","checksum":-998831312}]}
1646003669.727634: {"arg":{"channel":"books-l2-tbt","instId":"ELON-USDT"},"action":"update","data":[{"asks":[],"bids":[["0.0000007438","2399887012","0","2"]],"ts":"1646003669716","checksum":1820322122}]}
1646003669.7389991: {"arg":{"channel":"books-l2-tbt","instId":"ELON-USDT"},"action":"update","data":[{"asks":[["0.00000074659","431795825","0","1"],["0.0000011338","0","0","0"]],"bids":[],"ts":"1646003669727","checksum":-1686396237}]}
1646003669.749469: {"arg":{"channel":"books-l2-tbt","instId":"ELON-USDT"},"action":"update","data":[{"asks":[["0.00000074587","152061613","0","2"]],"bids":[["0.00000074381","184440410","0","1"]],"ts":"1646003669737","checksum":967506269}]}
1646003669.761356: {"arg":{"channel":"books-l2-tbt","instId":"ELON-USDT"},"action":"update","data":[{"asks":[["0.00000074546","81175250","0","1"],["0.00000074588","0","0","0"]],"bids":[],"ts":"1646003669749","checksum":1226121351}]}
1646003669.768217: {"arg":{"channel":"books-l2-tbt","instId":"UNI-USD-SWAP"},"action":"update","data":[{"asks":[["9.629","88","0","1"]],"bids":[],"ts":"1646003669756","checksum":2109415308}]}
1646003669.776725: {"arg":{"channel":"books-l2-tbt","instId":"UNI-USD-SWAP"},"action":"update","data":[{"asks":[["9.629","0","0","0"],["48.868","1","0","1"]],"bids":[],"ts":"1646003669765","checksum":1475917548}]}
1646003669.781004: {"arg":{"channel":"books-l2-tbt","instId":"ELON-USDT"},"action":"update","data":[{"asks":[["0.00000074587","0","0","0"],["0.0000011338","129154981","0","1"]],"bids":[["0.00000074434","0","0","0"]],"ts":"1646003669769","checksum":286973752}]}
1646003669.7882612: {"arg":{"channel":"books-l2-tbt","instId":"UNI-USD-SWAP"},"action":"update","data":[{"asks":[["9.628","88","0","1"],["48.868","0","0","0"]],"bids":[["9.623","24","0","2"]],"ts":"1646003669777","checksum":799938932}]}
1646003669.788834: {"arg":{"channel":"books-l2-tbt","instId":"ELON-USDT"},"action":"update","data":[{"asks":[["0.00000074707","4038943392","0","1"],["0.0000011338","0","0","0"]],"bids":[],"ts":"1646003669778","checksum":-353930284}]}
1646003669.798091: {"arg":{"channel":"books-l2-tbt","instId":"UNI-USD-SWAP"},"action":"update","data":[{"asks":[["9.628","0","0","0"],["9.636","367","0","3"],["48.868","1","0","1"]],"bids":[["9.584","143","0","3"]],"ts":"1646003669786","checksum":-487745098}]}
1646003669.8012722: {"arg":{"channel":"books-l2-tbt","instId":"ELON-USDT"},"action":"update","data":[{"asks":[["0.00000074589","263810383","0","3"],["0.00000113315","0","0","0"]],"bids":[],"ts":"1646003669789","checksum":562655513}]}
1646003669.808212: {"arg":{"channel":"books-l2-tbt","instId":"PROPS-ETH"},"action":"update","data":[{"asks":[["0.00000175","0","0","0"],["0.00000177","0","0","0"],["0.00000178","0","0","0"]],"bids":[],"ts":"1646003669793","checksum":1458079780}]}
1646003669.810915: {"arg":{"channel":"books-l2-tbt","instId":"UNI-USD-SWAP"},"action":"update","data":[{"asks":[["9.632","260","0","1"],["9.636","203","0","2"],["9.637","313","0","2"],["48.868","0","0","0"]],"bids":[["9.621","0","0","0"]],"ts":"1646003669797","checksum":-2051117069}]}
1646003669.811014: {"arg":{"channel":"books-l2-tbt","instId":"ELON-USDT"},"action":"update","data":[{"asks":[["0.00000074544","0","0","0"],["0.00000113315","35900750","0","1"]],"bids":[],"ts":"1646003669800","checksum":-562434785}]}
1646003669.8232589: {"arg":{"channel":"books-l2-tbt","instId":"ELON-USDT"},"action":"update","data":[{"asks":[["0.00000074589","111748770","0","1"]],"bids":[["0.00000074218","2936272042","0","1"]],"ts":"1646003669810","checksum":-1223453872}]}
1646003669.824345: {"arg":{"channel":"books-l2-tbt","instId":"PROPS-ETH"},"action":"update","data":[{"asks":[["0.00000174","0","0","0"]],"bids":[["0.00000167","285391.022819","0","2"]],"ts":"1646003669813","checksum":272655662}]}
1646003669.8294232: {"arg":{"channel":"books-l2-tbt","instId":"UNI-USD-SWAP"},"action":"update","data":[{"asks":[["9.638","54","0","3"],["9.641","57","0","2"],["9.648","2059","0","3"]],"bids":[["9.619","272","0","2"]],"ts":"1646003669818","checksum":-1236605908}]}
1646003669.832813: {"arg":{"channel":"books-l2-tbt","instId":"ELON-USDT"},"action":"update","data":[{"asks":[["0.00000074543","445226872","0","1"],["0.00000074589","0","0","0"],["0.00000074642","0","0","0"],["0.00000074741","0","0","0"],["0.0000011338","129154981","0","1"],["0.0000011372","6179288","0","1"]],"bids":[],"ts":"1646003669821","checksum":1254661649}]}
1646003669.842514: {"arg":{"channel":"books-l2-tbt","instId":"UNI-USD-SWAP"},"action":"update","data":[{"asks":[["9.637","164","0","1"]],"bids":[["9.62","188","0","3"],["9.61","27","0","1"],["9.609","0","0","0"],["9.608","171","0","2"],["9.607","0","0","0"],["9.605","57","0","2"],["9.604","317","0","2"]],"ts":"1646003669828","checksum":-1565216976}]}
1646003669.8426151: {"arg":{"channel":"books-l2-tbt","instId":"ELON-USDT"},"action":"update","data":[{"asks":[["0.00000074588","263810383","0","3"],["0.0000011372","0","0","0"]],"bids":[],"ts":"1646003669831","checksum":-1181657549}]}
1646003669.846275: {"arg":{"channel":"books-l2-tbt","instId":"PROPS-ETH"},"action":"update","data":[{"asks":[["0.00000173","14462.27733919","0","1"],["0.00000175","9804.61370861","0","1"]],"bids":[["0.00000166","0","0","0"]],"ts":"1646003669834","checksum":-45920471}]}
1646003669.851489: {"arg":{"channel":"books-l2-tbt","instId":"UNI-USD-SWAP"},"action":"update","data":[{"asks":[["9.638","42","0","2"],["9.641","69","0","3"]],"bids":[],"ts":"1646003669839","checksum":-31677108}]}
1646003669.851576: {"arg":{"channel":"books-l2-tbt","instId":"ELON-USDT"},"action":"update","data":[{"asks":[["0.00000074588","48015673","0","1"],["0.00000074638","496714302","0","1"],["0.00000074707","0","0","0"],["0.00000074743","3603630786","0","1"],["0.0000011338","0","0","0"]],"bids":[],"ts":"1646003669840","checksum":1960165051}]}
1646003669.861347: {"arg":{"channel":"books-l2-tbt","instId":"UNI-USD-SWAP"},"action":"update","data":[{"asks":[["9.638","11","0","1"],["9.64","239","0","3"]],"bids":[],"ts":"1646003669849","checksum":-482687213}]}
1646003669.861758: {"arg":{"channel":"books-l2-tbt","instId":"ELON-USDT"},"action":"update","data":[{"asks":[["0.00000074588","0","0","0"],["0.0000011338","129154981","0","1"]],"bids":[],"ts":"1646003669850","checksum":-291270483}]}
1646003669.870945: {"arg":{"channel":"books-l2-tbt","instId":"ETH-USD-220429-1900-P"},"action":"update","data":[{"asks":[["0.0375","500","0","1"],["0.038","1006","0","2"]],"bids":[],"ts":"1646003669858","checksum":356118983}]}
1646003669.871038: {"arg":{"channel":"books-l2-tbt","instId":"UNI-USD-SWAP"},"action":"update","data":[{"asks":[["9.641","57","0","2"],["9.642","341","0","3"]],"bids":[["9.621","2","0","1"]],"ts":"1646003669859","checksum":-1936469390}]}
1646003669.871393: {"arg":{"channel":"books-l2-tbt","instId":"PROPS-ETH"},"action":"update","data":[{"asks":[["0.00000175","0","0","0"]],"bids":[["0.00000167","458105.370372","0","3"]],"ts":"1646003669861","checksum":1451380055}]}
1646003669.8738618: {"arg":{"channel":"books-l2-tbt","instId":"ELON-USDT"},"action":"update","data":[{"asks":[["0.00000074542","215794710","0","2"],["0.0000011338","0","0","0"]],"bids":[["0.00000074131","184440410","0","1"]],"ts":"1646003669862","checksum":1563293211}]}
1646003669.882986: {"arg":{"channel":"books-l2-tbt","instId":"UNI-USD-SWAP"},"action":"update","data":[{"asks":[],"bids":[["9.616","18","0","2"],["9.615","1040","0","1"],["9.603","1266","0","2"],["9.602","0","0","0"]],"ts":"1646003669871","checksum":1345976262}]}
1646003669.886076: {"arg":{"channel":"books-l2-tbt","instId":"ELON-USDT"},"action":"update","data":[{"asks":[["0.00000074542","263810383","0","3"]],"bids":[],"ts":"1646003669874","checksum":1510829961}]}
1646003669.891674: {"arg":{"channel":"books-l2-tbt","instId":"PROPS-ETH"},"action":"update","data":[{"asks":[["0.00000172","9674.20623981","0","1"]],"bids":[["0.00000166","129490.77863735","0","1"]],"ts":"1646003669878","checksum":1750549238}]}
1646003669.8936892: {"arg":{"channel":"books-l2-tbt","instId":"UNI-USD-SWAP"},"action":"update","data":[{"asks":[],"bids":[["9.609","80","0","1"],["9.606","0","0","0"]],"ts":"1646003669881","checksum":960470566}]}
1646003669.896802: {"arg":{"channel":"books-l2-tbt","instId":"ELON-USDT"},"action":"update","data":[{"asks":[["0.00000074542","215794710","0","2"],["0.00000074659","0","0","0"],["0.0000011338","129154981","0","1"]],"bids":[],"ts":"1646003669884","checksum":1613037965}]}
1646003669.9024582: {"arg":{"channel":"books-l2-tbt","instId":"UNI-USD-SWAP"},"action":"update","data":[{"asks":[],"bids":[["9.617","108","0","2"],["9.616","12","0","1"],["9.604","333","0","3"],["9.603","1248","0","1"]],"ts":"1646003669891","checksum":-503578866}]}
1646003669.9119391: {"arg":{"channel":"books-l2-tbt","instId":"UNI-USD-SWAP"},"action":"update","data":[{"asks":[],"bids":[["9.579","0","0","0"]],"ts":"1646003669900","checksum":-503578866}]}
1646003669.914077: {"arg":{"channel":"books-l2-tbt","instId":"BTC-USD-220325-40000-C"},"action":"update","data":[{"asks":[["0.0535","0","0","0"],["0.054","300","0","1"]],"bids":[],"ts":"1646003669903","checksum":-1480969480}]}
1646003669.92908: {"arg":{"channel":"books-l2-tbt","instId":"ELON-USDT"},"action":"update","data":[{"asks":[],"bids":[["0.00000069607","0","0","0"],["0.00000068215","0","0","0"],["0.00000066851","0","0","0"],["0.00000065514","0","0","0"],["0.00000064198","267477159","0","1"]],"ts":"1646003669917","checksum":1613037965}]}
1646003669.9330828: {"arg":{"channel":"books-l2-tbt","instId":"UNI-USD-SWAP"},"action":"update","data":[{"asks":[["9.682","0","0","0"],["48.868","1","0","1"]],"bids":[["9.621","0","0","0"],["9.585","528","0","3"]],"ts":"1646003669921","checksum":-1267646305}]}
1646003669.959069: {"arg":{"channel":"books-l2-tbt","instId":"ELON-USDT"},"action":"update","data":[{"asks":[["0.00000074542","111748770","0","1"]],"bids":[["0.00000074131","0","0","0"]],"ts":"1646003669940","checksum":1266541918}]}
1646003669.959198: {"arg":{"channel":"books-l2-tbt","instId":"ZEN-USDT"},"action":"update","data":[{"asks":[["32.6","51","0","1"]],"bids":[],"ts":"1646003669945","checksum":-918689754}]}
1646003669.965178: {"arg":{"channel":"books-l2-tbt","instId":"UNI-USD-SWAP"},"action":"update","data":[{"asks":[["9.689","160","0","1"],["48.868","0","0","0"]],"bids":[],"ts":"1646003669951","checksum":-1267646305}]}
1646003669.972563: {"arg":{"channel":"books-l2-tbt","instId":"UNI-USD-SWAP"},"action":"update","data":[{"asks":[],"bids":[["9.586","174","0","2"]],"ts":"1646003669962","checksum":-1626928433}]}
1646003669.983447: {"arg":{"channel":"books-l2-tbt","instId":"UNI-USD-SWAP"},"action":"update","data":[{"asks":[["9.631","88","0","1"],["48.625","0","0","0"]],"bids":[],"ts":"1646003669972","checksum":-357376965}]}
1646003669.991178: {"arg":{"channel":"books-l2-tbt","instId":"ZEN-USDT"},"action":"update","data":[{"asks":[["32.53","0","0","0"],["32.58","27.019517","0","1"],["32.59","113.820017","0","2"],["44.22","2.271956","0","1"]],"bids":[],"ts":"1646003669980","checksum":-574225231}]}
1646003670.002649: {"arg":{"channel":"books-l2-tbt","instId":"ZEN-USDT"},"action":"update","data":[{"asks":[["32.6","53.936427","0","2"]],"bids":[["32.41","63.084348","0","1"]],"ts":"1646003669990","checksum":2031893151}]}
1646003670.004153: {"arg":{"channel":"books-l2-tbt","instId":"UNI-USD-SWAP"},"action":"update","data":[{"asks":[["9.637","0","0","0"],["9.638","216","0","2"],["48.625","1","0","1"]],"bids":[["9.62","135","0","2"]],"ts":"1646003669993","checksum":-1520019783}]}
1646003670.013702: {"arg":{"channel":"books-l2-tbt","instId":"ZEN-USDT"},"action":"update","data":[{"asks":[["32.55","11.110982","0","4"]],"bids":[["32.49","11.473041","0","4"]],"ts":"1646003670002","checksum":1640878074}]}
1646003670.013749: {"arg":{"channel":"books-l2-tbt","instId":"ELON-USDT"},"action":"update","data":[{"asks":[["0.00000074541","65848792","0","1"],["0.0000011338","0","0","0"]],"bids":[["0.00000074444","219861835","0","1"]],"ts":"1646003670002","checksum":-317043637}]}
1646003670.01897: {"arg":{"channel":"books-l2-tbt","instId":"UNI-USD-SWAP"},"action":"update","data":[{"asks":[["9.642","337","0","3"]],"bids":[],"ts":"1646003670007","checksum":-8281190}]}
1646003670.022423: {"arg":{"channel":"books-l2-tbt","instId":"ZEN-USDT"},"action":"update","data":[{"asks":[["32.59","19","0","1"],["32.62","146.941977","0","3"]],"bids":[],"ts":"1646003670009","checksum":-738889781}]}
1646003670.023187: {"arg":{"channel":"books-l2-tbt","instId":"ELON-USDT"},"action":"update","data":[{"asks":[["0.00000074542","217214190","0","3"]],"bids":[],"ts":"1646003670012","checksum":-1947360652}]}
1646003670.0349262: {"arg":{"channel":"books-l2-tbt","instId":"ELON-USDT"},"action":"update","data":[{"asks":[["0.00000074542","199255828","0","4"]],"bids":[],"ts":"1646003670023","checksum":1442693512}]}
1646003670.035414: {"arg":{"channel":"books-l2-tbt","instId":"UNI-USD-SWAP"},"action":"update","data":[{"asks":[],"bids":[["9.62","188","0","3"],["9.586","142","0","1"]],"ts":"1646003670025","checksum":1331538847}]}
1646003670.04554: {"arg":{"channel":"books-l2-tbt","instId":"ELON-USDT"},"action":"update","data":[{"asks":[],"bids":[["0.00000074434","184440410","0","1"]],"ts":"1646003670033","checksum":-1139626690}]}
1646003670.045656: {"arg":{"channel":"books-l2-tbt","instId":"UNI-USD-SWAP"},"action":"update","data":[{"asks":[],"bids":[["9.621","2","0","1"],["9.618","1","0","1"],["9.617","102","0","1"],["9.605","73","0","3"],["9.604","317","0","2"]],"ts":"1646003670034","checksum":-704350467}]}
1646003670.05711: {"arg":{"channel":"books-l2-tbt","instId":"UNI-USD-SWAP"},"action":"update","data":[{"asks":[],"bids":[["9.6","0","0","0"],["9.592","242","0","3"]],"ts":"1646003670046","checksum":-834240906}]}
1646003670.073024: {"arg":{"channel":"books-l2-tbt","instId":"ZEN-USDT"},"action":"update","data":[{"asks":[["32.54","0.998901","0","1"],["44.22","0","0","0"]],"bids":[["31.85","88.056754","0","2"]],"ts":"1646003670062","checksum":1889354238}]}
1646003670.0749838: {"arg":{"channel":"books-l2-tbt","instId":"ELON-USDT"},"action":"update","data":[{"asks":[["0.00000074543","0","0","0"],["0.0000011338","129154981","0","1"]],"bids":[],"ts":"1646003670063","checksum":-1335609047}]}
1646003670.087874: {"arg":{"channel":"books-l2-tbt","instId":"UNI-USD-SWAP"},"action":"update","data":[{"asks":[],"bids":[["9.623","22","0","1"],["9.606","18","0","1"],["9.605","57","0","2"]],"ts":"1646003670076","checksum":370940787}]}
1646003670.102994: {"arg":{"channel":"books-l2-tbt","instId":"ELON-USDT"},"action":"update","data":[{"asks":[["0.00000074545","48015673","0","1"],["0.00000074705","4038943392","0","1"],["0.00000113315","0","0","0"],["0.0000011338","0","0","0"]],"bids":[],"ts":"1646003670086","checksum":-2021018887}]}
1646003670.106195: {"arg":{"channel":"books-l2-tbt","instId":"ZEN-USDT"},"action":"update","data":[{"asks":[],"bids":[["32.41","80.422707","0","2"]],"ts":"1646003670094","checksum":-1208996402}]}
1646003670.110678: {"arg":{"channel":"books-l2-tbt","instId":"UNI-USD-SWAP"},"action":"update","data":[{"asks":[],"bids":[["9.619","278","0","3"],["9.618","0","0","0"],["9.611","530","0","2"],["9.61","0","0","0"],["9.609","104","0","2"],["9.608","147","0","1"],["9.606","42","0","2"],["9.605","29","0","1"]],"ts":"1646003670096","checksum":1977719526}]}
1646003670.118197: {"arg":{"channel":"books-l2-tbt","instId":"ELON-USDT"},"action":"update","data":[{"asks":[],"bids":[["0.00000074381","0","0","0"]],"ts":"1646003670106","checksum":-739857433}]}
1646003670.136481: {"arg":{"channel":"books-l2-tbt","instId":"ZEN-USDT"},"action":"update","data":[{"asks":[["32.52","0","0","0"],["33.16","0.30161","0","1"],["33.17","3.93","0","1"],["33.49","0","0","0"],["33.5","6.816261","0","3"],["44.22","2.271956","0","1"]],"bids":[],"ts":"1646003670124","checksum":-184651190}]}
1646003670.141071: {"arg":{"channel":"books-l2-tbt","instId":"UNI-USD-SWAP"},"action":"update","data":[{"asks":[],"bids":[["9.62","135","0","2"]],"ts":"1646003670129","checksum":1250847171}]}
1646003670.14685: {"arg":{"channel":"books-l2-tbt","instId":"ZEN-USDT"},"action":"update","data":[{"asks":[["33.82","7.49715","0","2"],["33.83","8.68","0","1"],["34.15","0","0","0"],["34.16","11.02","0","1"],["44.22","0","0","0"]],"bids":[],"ts":"1646003670134","checksum":-184651190}]}
1646003670.1708071: {"arg":{"channel":"books-l2-tbt","instId":"ZEN-USDT"},"action":"update","data":[{"asks":[["32.55","9.137878","0","3"]],"bids":[],"ts":"1646003670144","checksum":-1007758392}]}
1646003670.1708648: {"arg":{"channel":"books-l2-tbt","instId":"ZEN-USDT"},"action":"update","data":[{"asks":[],"bids":[["32.5","1.99625","0","1"]],"ts":"1646003670154","checksum":1393409393}]}
1646003670.1791081: {"arg":{"channel":"books-l2-tbt","instId":"ELON-USDT"},"action":"update","data":[{"asks":[],"bids":[["0.00000074434","0","0","0"]],"ts":"1646003670159","checksum":-300303685}]}
1646003670.179148: {"arg":{"channel":"books-l2-tbt","instId":"UNI-USD-SWAP"},"action":"update","data":[{"asks":[],"bids":[["9.613","109","0","3"],["9.609","24","0","1"],["9.607","16","0","1"],["9.606","24","0","1"]],"ts":"1646003670160","checksum":-1721378897}]}
1646003670.1863942: {"arg":{"channel":"books-l2-tbt","instId":"ZEN-USDT"},"action":"update","data":[{"asks":[["32.57","2.12937","0","1"],["44.2","0","0","0"]],"bids":[],"ts":"1646003670175","checksum":-969817406}]}
1646003670.188973: {"arg":{"channel":"books-l2-tbt","instId":"ELON-USDT"},"action":"update","data":[{"asks":[["0.00000074545","263810383","0","3"]],"bids":[],"ts":"1646003670177","checksum":-1367550492}]}
1646003670.1926558: {"arg":{"channel":"books-l2-tbt","instId":"UNI-USD-SWAP"},"action":"update","data":[{"asks":[],"bids":[["9.62","136","0","3"],["9.619","272","0","2"]],"ts":"1646003670181","checksum":-1076860427}]}
1646003670.197245: {"arg":{"channel":"books-l2-tbt","instId":"ZEN-USDT"},"action":"update","data":[{"asks":[],"bids":[["32.46","0","0","0"]],"ts":"1646003670185","checksum":-2113398680}]}
1646003670.2204502: {"arg":{"channel":"books-l2-tbt","instId":"ZEN-USDT"},"action":"update","data":[{"asks":[["32.55","4.52408","0","2"]],"bids":[["32.43","0","0","0"]],"ts":"1646003670208","checksum":1538507572}]}
1646003670.221098: {"arg":{"channel":"books-l2-tbt","instId":"ELON-USDT"},"action":"update","data":[{"asks":[],"bids":[["0.00000074381","59742380","0","1"]],"ts":"1646003670211","checksum":-1925859546}]}
1646003670.23243: {"arg":{"channel":"books-l2-tbt","instId":"ELON-USDT"},"action":"update","data":[{"asks":[["0.00000074542","53107723","0","1"]],"bids":[],"ts":"1646003670218","checksum":829882596}]}
1646003670.2337458: {"arg":{"channel":"books-l2-tbt","instId":"UNI-USD-SWAP"},"action":"update","data":[{"asks":[],"bids":[["9.586","173","0","2"]],"ts":"1646003670223","checksum":-1737058871}]}
1646003670.240082: {"arg":{"channel":"books-l2-tbt","instId":"ZEN-USDT"},"action":"update","data":[{"asks":[["32.55","0.87","0","1"],["32.58","31.6304","0","2"]],"bids":[["32.51","0.500345","0","1"],["32.45","71.606968","0","2"]],"ts":"1646003670226","checksum":1467146269}]}
1646003670.240155: {"arg":{"channel":"books-l2-tbt","instId":"ELON-USDT"},"action":"update","data":[{"asks":[["0.00000074542","0","0","0"],["0.00000074545","0","0","0"],["0.00000113315","35900750","0","1"],["0.0000011338","129154981","0","1"]],"bids":[],"ts":"1646003670228","checksum":-1456501316}]}
1646003670.246668: {"arg":{"channel":"books-l2-tbt","instId":"UNI-USD-SWAP"},"action":"update","data":[{"asks":[],"bids":[["9.621","55","0","2"]],"ts":"1646003670234","checksum":314035072}]}
1646003670.2507908: {"arg":{"channel":"books-l2-tbt","instId":"ELON-USDT"},"action":"update","data":[{"asks":[["0.0000007454","48015673","0","1"],["0.0000011338","0","0","0"]],"bids":[],"ts":"1646003670238","checksum":-1685467115}]}
1646003670.255876: {"arg":{"channel":"books-l2-tbt","instId":"UNI-USD-SWAP"},"action":"update","data":[{"asks":[],"bids":[["9.595","4","0","1"]],"ts":"1646003670244","checksum":1174759937}]}
1646003670.259893: {"arg":{"channel":"books-l2-tbt","instId":"ZEN-USDT"},"action":"update","data":[{"asks":[],"bids":[["32.52","8","0","1"],["32.41","63.084348","0","1"]],"ts":"1646003670246","checksum":-546183856}]}
1646003670.259959: {"arg":{"channel":"books-l2-tbt","instId":"ELON-USDT"},"action":"update","data":[{"asks":[["0.00000074545","215794710","0","2"],["0.00000074546","0","0","0"]],"bids":[],"ts":"1646003670247","checksum":368768813}]}
1646003670.27234: {"arg":{"channel":"books-l2-tbt","instId":"ELON-USDT"},"action":"update","data":[{"asks":[["0.0000007454","0","0","0"],["0.0000011338","129154981","0","1"]],"bids":[],"ts":"1646003670260","checksum":1450593676}]}
1646003670.284253: {"arg":{"channel":"books-l2-tbt","instId":"ZEN-USDT"},"action":"update","data":[{"asks":[["32.54","8.998901","0","2"]],"bids":[],"ts":"1646003670271","checksum":-1072724964}]}
1646003670.291519: {"arg":{"channel":"books-l2-tbt","instId":"ELON-USDT"},"action":"update","data":[{"asks":[["0.00000074545","0","0","0"],["0.0000011372","6179288","0","1"]],"bids":[],"ts":"1646003670272","checksum":-1841362618}]}
1646003670.291646: {"arg":{"channel":"books-l2-tbt","instId":"ZEN-USDT"},"action":"update","data":[{"asks":[],"bids":[["32.49","10.972696","0","3"],["32.46","3.686635","0","1"],["32.45","72.107308","0","3"]],"ts":"1646003670277","checksum":860691469}]}
1646003670.303333: {"arg":{"channel":"books-l2-tbt","instId":"ELON-USDT"},"action":"update","data":[{"asks":[["0.00000074545","445226872","0","1"],["0.00000074743","0","0","0"]],"bids":[],"ts":"1646003670285","checksum":1379384705}]}
1646003670.303423: {"arg":{"channel":"books-l2-tbt","instId":"UNI-USD-SWAP"},"action":"update","data":[{"asks":[],"bids":[["9.613","29","0","2"],["9.611","588","0","3"]],"ts":"1646003670287","checksum":601804076}]}
1646003670.303463: {"arg":{"channel":"books-l2-tbt","instId":"ZEN-USDT"},"action":"update","data":[{"asks":[["32.57","5.78345","0","2"]],"bids":[["32.45","71.606968","0","2"]],"ts":"1646003670291","checksum":1807204592}]}
1646003670.30764: {"arg":{"channel":"books-l2-tbt","instId":"ELON-USDT"},"action":"update","data":[{"asks":[["0.00000074589","215794710","0","2"],["0.00000075536","0","0","0"]],"bids":[],"ts":"1646003670294","checksum":-879256995}]}
1646003670.3139908: {"arg":{"channel":"books-l2-tbt","instId":"PROPS-ETH"},"action":"update","data":[{"asks":[["0.00000178","1403.65892679","0","1"],["0.00000187","926.04182216","0","1"]],"bids":[["0.00000161","9001.62165323","0","1"],["0.0000016","0","0","0"]],"ts":"1646003670298","checksum":-113903858}]}
1646003670.31838: {"arg":{"channel":"books-l2-tbt","instId":"ELON-USDT"},"action":"update","data":[{"asks":[["0.00000074589","0","0","0"],["0.00000074736","3336493607","0","1"]],"bids":[],"ts":"1646003670304","checksum":1828411300}]}
1646003670.3354518: {"arg":{"channel":"books-l2-tbt","instId":"PROPS-ETH"},"action":"update","data":[{"asks":[],"bids":[["0.00000166","0","0","0"]],"ts":"1646003670317","checksum":-70398730}]}
1646003670.335597: {"arg":{"channel":"books-l2-tbt","instId":"UNI-USD-SWAP"},"action":"update","data":[{"asks":[],"bids":[["9.62","135","0","2"],["9.619","278","0","3"]],"ts":"1646003670321","checksum":1213825012}]}
1646003670.335638: {"arg":{"channel":"books-l2-tbt","instId":"ZEN-USDT"},"action":"update","data":[{"asks":[["32.56","0","0","0"],["44.2","0.120899","0","1"]],"bids":[["32.39","0","0","0"]],"ts":"1646003670322","checksum":1098068902}]}
1646003670.335677: {"arg":{"channel":"books-l2-tbt","instId":"ELON-USDT"},"action":"update","data":[{"asks":[["0.00000074589","81175250","0","1"],["0.0000011372","0","0","0"]],"bids":[["0.00000074381","0","0","0"]],"ts":"1646003670324","checksum":1162953324}]}
1646003670.341795: {"arg":{"channel":"books-l2-tbt","instId":"UNI-USD-SWAP"},"action":"update","data":[{"asks":[],"bids":[["9.619","272","0","2"]],"ts":"1646003670331","checksum":12456396}]}
1646003670.346102: {"arg":{"channel":"books-l2-tbt","instId":"ZEN-USDT"},"action":"update","data":[{"asks":[["32.6","63.157819","0","3"]],"bids":[["32.42","70.47857","0","3"]],"ts":"1646003670332","checksum":-300422147}]}
1646003670.346186: {"arg":{"channel":"books-l2-tbt","instId":"ELON-USDT"},"action":"update","data":[{"asks":[["0.00000074541","0","0","0"],["0.00000074544","215794710","0","2"]],"bids":[],"ts":"1646003670335","checksum":978608184}]}
1646003670.354618: {"arg":{"channel":"books-l2-tbt","instId":"ZEN-USDT"},"action":"update","data":[{"asks":[["32.55","0","0","0"],["32.6","60.221392","0","2"],["44.22","2.271956","0","1"]],"bids":[["32.45","74.826418","0","3"]],"ts":"1646003670343","checksum":1956989772}]}
1646003670.3771179: {"arg":{"channel":"books-l2-tbt","instId":"ELON-USDT"},"action":"update","data":[{"asks":[["0.00000074736","0","0","0"],["0.0000011372","6179288","0","1"]],"bids":[["0.00000074445","184440410","0","1"]],"ts":"1646003670356","checksum":1884351319}]}
1646003670.388874: {"arg":{"channel":"books-l2-tbt","instId":"ZEN-USDT"},"action":"update","data":[{"asks":[],"bids":[["31.86","4.38392","0","2"],["31.85","83.986754","0","1"],["31.55","6.61","0","1"],["31.54","0","0","0"],["31.24","9.17","0","1"],["31.23","0.471052","0","1"],["30.93","14.594933","0","3"],["30.92","0","0","0"]],"ts":"1646003670373","checksum":1956989772}]}
1646003670.388984: {"arg":{"channel":"books-l2-tbt","instId":"ELON-USDT"},"action":"update","data":[{"asks":[["0.00000074744","3469860191","0","1"],["0.0000011372","0","0","0"]],"bids":[],"ts":"1646003670376","checksum":-1946302792}]}
1646003670.398605: {"arg":{"channel":"books-l2-tbt","instId":"UNI-USD-SWAP"},"action":"update","data":[{"asks":[["9.647","2554","0","5"]],"bids":[],"ts":"1646003670384","checksum":699326586}]}
1646003670.398716: {"arg":{"channel":"books-l2-tbt","instId":"ZEN-USDT"},"action":"update","data":[{"asks":[["32.61","2.936427","0","1"],["32.64","0","0","0"],["32.69","95","0","1"],["44.22","0","0","0"]],"bids":[],"ts":"1646003670385","checksum":-1854228644}]}
1646003670.417654: {"arg":{"channel":"books-l2-tbt","instId":"ZEN-USDT"},"action":"update","data":[{"asks":[],"bids":[["32.45","71.606968","0","2"]],"ts":"1646003670393","checksum":1447825326}]}
1646003670.4368918: {"arg":{"channel":"books-l2-tbt","instId":"ELON-USDT"},"action":"update","data":[{"asks":[["0.00000074544","104045940","0","1"]],"bids":[],"ts":"1646003670396","checksum":-79479884}]}
1646003670.436971: {"arg":{"channel":"books-l2-tbt","instId":"ELON-USDT"},"action":"update","data":[{"asks":[],"bids":[["0.00000064198","0","0","0"]],"ts":"1646003670407","checksum":-79479884}]}
1646003670.437005: {"arg":{"channel":"books-l2-tbt","instId":"ZEN-USDT"},"action":"update","data":[{"asks":[["32.59","0","0","0"],["32.6","9.221392","0","1"],["32.61","21.936427","0","2"],["32.62","197.941977","0","4"],["32.76","0","0","0"],["32.9","61.51","0","2"],["44.22","2.271956","0","1"],["44.23","2.713011","0","1"]],"bids":[],"ts":"1646003670414","checksum":-630728197}]}
1646003670.437066: {"arg":{"channel":"books-l2-tbt","instId":"ELON-USDT"},"action":"update","data":[{"asks":[],"bids":[["0.00000070565","445374620","0","2"],["0.00000069154","250354800","0","1"],["0.00000067771","313654951","0","1"],["0.00000066416","306051448","0","1"]],"ts":"1646003670416","checksum":-79479884}]}
1646003670.43743: {"arg":{"channel":"books-l2-tbt","instId":"ZEN-USDT"},"action":"update","data":[{"asks":[["32.61","19","0","1"]],"bids":[["32.46","6.633835","0","2"]],"ts":"1646003670425","checksum":-21478372}]}
1646003670.4383519: {"arg":{"channel":"books-l2-tbt","instId":"ELON-USDT"},"action":"update","data":[{"asks":[["0.00000074544","234731422","0","4"]],"bids":[["0.00000074444","0","0","0"]],"ts":"1646003670427","checksum":1432879732}]}
1646003670.448628: {"arg":{"channel":"books-l2-tbt","instId":"ZEN-USDT"},"action":"update","data":[{"asks":[],"bids":[["32.46","3.686635","0","1"]],"ts":"1646003670435","checksum":330482385}]}
1646003670.4580412: {"arg":{"channel":"books-l2-tbt","instId":"ZEN-USDT"},"action":"update","data":[{"asks":[["32.56","0.998901","0","1"],["44.23","0","0","0"]],"bids":[],"ts":"1646003670446","checksum":1315439156}]}
1646003670.471898: {"arg":{"channel":"books-l2-tbt","instId":"ELON-USDT"},"action":"update","data":[{"asks":[],"bids":[["0.00000074445","0","0","0"]],"ts":"1646003670459","checksum":411105038}]}
1646003670.482795: {"arg":{"channel":"books-l2-tbt","instId":"ELON-USDT"},"action":"update","data":[{"asks":[],"bids":[["0.00000074218","0","0","0"]],"ts":"1646003670469","checksum":-1233779549}]}
1646003670.502822: {"arg":{"channel":"books-l2-tbt","instId":"ELON-USDT"},"action":"update","data":[{"asks":[["0.00000074705","0","0","0"],["0.0000011372","6179288","0","1"]],"bids":[],"ts":"1646003670491","checksum":-1544239379}]}
1646003670.52283: {"arg":{"channel":"books-l2-tbt","instId":"ZEN-USDT"},"action":"update","data":[{"asks":[["32.9","60","0","1"],["32.91","1.51","0","1"],["33.36","0","0","0"],["33.37","4.52","0","1"],["33.82","0.01715","0","1"],["33.83","16.16","0","2"],["34.29","0","0","0"],["34.3","12.738605","0","2"],["34.77","0","0","0"],["34.78","13.28","0","1"]],"bids":[["32.12","1.55","0","1"],["32.11","0","0","0"],["31.67","4.71","0","1"],["31.66","0.055516","0","1"],["31.23","8.381052","0","2"],["31.22","0.010163","0","1"],["30.8","11.16","0","1"],["30.79","0","0","0"],["30.37","14.45","0","1"],["30.36","0","0","0"]],"ts":"1646003670510","checksum":1638317255}]}
1646003670.5397298: {"arg":{"channel":"books-l2-tbt","instId":"ZEN-USDT"},"action":"update","data":[{"asks":[],"bids":[["31.86","4.37392","0","2"],["31.55","6.6","0","1"],["31.24","9.16","0","1"],["30.93","14.584933","0","3"]],"ts":"1646003670520","checksum":1638317255}]}
1646003670.539846: {"arg":{"channel":"books-l2-tbt","instId":"ELON-USDT"},"action":"update","data":[{"asks":[],"bids":[["0.00000074381","184440410","0","1"],["0.00000074101","0","0","0"]],"ts":"1646003670524","checksum":2025656120}]}
1646003670.546379: {"arg":{"channel":"books-l2-tbt","instId":"ELON-USDT"},"action":"update","data":[{"asks":[["0.00000074543","445226872","0","1"],["0.0000011372","0","0","0"]],"bids":[],"ts":"1646003670533","checksum":-1134843054}]}
1646003670.553238: {"arg":{"channel":"books-l2-tbt","instId":"ZEN-USDT"},"action":"update","data":[{"asks":[["32.54","8","0","1"]],"bids":[],"ts":"1646003670542","checksum":181852450}]}
1646003670.567824: {"arg":{"channel":"books-l2-tbt","instId":"ELON-USDT"},"action":"update","data":[{"asks":[["0.00000074707","4038943392","0","1"],["0.0000011338","0","0","0"]],"bids":[],"ts":"1646003670556","checksum":-61380819}]}
1646003670.614083: {"arg":{"channel":"books-l2-tbt","instId":"ELON-USDT"},"action":"update","data":[{"asks":[["0.00000074545","0","0","0"],["0.0000011338","129154981","0","1"]],"bids":[],"ts":"1646003670598","checksum":540896394}]}
1646003670.629908: {"arg":{"channel":"books-l2-tbt","instId":"ELON-USDT"},"action":"update","data":[{"asks":[["0.00000074707","0","0","0"],["0.0000011372","6179288","0","1"]],"bids":[["0.00000074218","3203227365","0","1"],["0.00000074131","184440410","0","1"]],"ts":"1646003670618","checksum":-487521510}]}
1646003670.6816692: {"arg":{"channel":"books-l2-tbt","instId":"ELON-USDT"},"action":"update","data":[{"asks":[],"bids":[["0.00000074381","0","0","0"]],"ts":"1646003670669","checksum":-1847789850}]}
1646003670.69071: {"arg":{"channel":"books-l2-tbt","instId":"ELON-USDT"},"action":"update","data":[{"asks":[],"bids":[["0.00000072101","0","0","0"]],"ts":"1646003670679","checksum":-1847789850}]}
1646003670.701162: {"arg":{"channel":"books-l2-tbt","instId":"ELON-USDT"},"action":"update","data":[{"asks":[],"bids":[["0.00000074131","934440410","0","2"]],"ts":"1646003670690","checksum":-252942245}]}
1646003670.744179: {"arg":{"channel":"books-l2-tbt","instId":"ELON-USDT"},"action":"update","data":[{"asks":[],"bids":[["0.00000074434","60882414","0","1"]],"ts":"1646003670733","checksum":541281080}]}
1646003670.7760918: {"arg":{"channel":"books-l2-tbt","instId":"ZEN-USDT"},"action":"update","data":[{"asks":[],"bids":[["32.46","0","0","0"]],"ts":"1646003670763","checksum":70198824}]}
1646003670.77617: {"arg":{"channel":"books-l2-tbt","instId":"ELON-USDT"},"action":"update","data":[{"asks":[],"bids":[["0.00000074131","750000000","0","1"]],"ts":"1646003670765","checksum":-1703841218}]}
1646003670.800857: {"arg":{"channel":"books-l2-tbt","instId":"PROPS-ETH"},"action":"update","data":[{"asks":[["0.00000178","0","0","0"],["0.00000185","0","0","0"],["0.00000187","0","0","0"]],"bids":[],"ts":"1646003670790","checksum":-1803347676}]}
1646003670.809301: {"arg":{"channel":"books-l2-tbt","instId":"ELON-USDT"},"action":"update","data":[{"asks":[["0.00000074542","52273460","0","1"],["0.00000074544","104045940","0","1"],["0.0000011372","0","0","0"]],"bids":[],"ts":"1646003670797","checksum":-1240705731}]}
1646003670.815499: {"arg":{"channel":"books-l2-tbt","instId":"ZEN-USDT"},"action":"update","data":[{"asks":[],"bids":[["32.48","23.418185","0","3"]],"ts":"1646003670805","checksum":-1985091564}]}
1646003670.81875: {"arg":{"channel":"books-l2-tbt","instId":"ELON-USDT"},"action":"update","data":[{"asks":[["0.00000074589","0","0","0"],["0.0000011372","6179288","0","1"]],"bids":[],"ts":"1646003670807","checksum":585707878}]}
1646003670.841286: {"arg":{"channel":"books-l2-tbt","instId":"ELON-USDT"},"action":"update","data":[{"asks":[["0.00000074542","164022230","0","2"],["0.00000074544","0","0","0"],["0.00000113812","12211658","0","1"]],"bids":[],"ts":"1646003670829","checksum":-1915401097}]}
1646003670.852916: {"arg":{"channel":"books-l2-tbt","instId":"ELON-USDT"},"action":"update","data":[{"asks":[["0.00000074542","268068170","0","3"]],"bids":[],"ts":"1646003670839","checksum":-15724399}]}
1646003670.863266: {"arg":{"channel":"books-l2-tbt","instId":"ELON-USDT"},"action":"update","data":[{"asks":[["0.00000074542","216379927","0","3"]],"bids":[],"ts":"1646003670849","checksum":-530316243}]}
1646003670.872535: {"arg":{"channel":"books-l2-tbt","instId":"ELON-USDT"},"action":"update","data":[{"asks":[["0.00000074541","48015673","0","1"],["0.00000074543","0","0","0"]],"bids":[],"ts":"1646003670860","checksum":-1529021792}]}
1646003670.872622: {"arg":{"channel":"books-l2-tbt","instId":"UNI-USD-SWAP"},"action":"update","data":[{"asks":[],"bids":[["9.612","152","0","1"]],"ts":"1646003670861","checksum":-1455389037}]}
1646003670.883519: {"arg":{"channel":"books-l2-tbt","instId":"ELON-USDT"},"action":"update","data":[{"asks":[["0.00000074707","4038943392","0","1"],["0.00000113812","0","0","0"]],"bids":[],"ts":"1646003670871","checksum":1723053204}]}
1646003670.890982: {"arg":{"channel":"books-l2-tbt","instId":"ZEN-USDT"},"action":"update","data":[{"asks":[["32.84","0","0","0"],["32.85","1.52","0","1"],["33.17","0","0","0"],["33.18","3.93","0","1"],["33.5","0.496261","0","2"],["33.51","8.591956","0","2"],["33.83","7.48","0","1"],["33.84","8.68","0","1"],["44.22","0","0","0"]],"bids":[["32.19","1.55","0","1"],["32.18","2.460396","0","2"]],"ts":"1646003670880","checksum":-906822683}]}
1646003670.89264: {"arg":{"channel":"books-l2-tbt","instId":"ELON-USDT"},"action":"update","data":[{"asks":[["0.00000074541","0","0","0"],["0.00000074542","104631157","0","2"],["0.00000113812","12211658","0","1"]],"bids":[["0.00000074444","219861835","0","1"]],"ts":"1646003670882","checksum":-695213937}]}
1646003670.894779: {"arg":{"channel":"books-l2-tbt","instId":"UNI-USD-SWAP"},"action":"update","data":[{"asks":[["9.667","0","0","0"],["48.868","1","0","1"]],"bids":[["9.586","142","0","1"],["9.582","124","0","1"]],"ts":"1646003670880","checksum":-1455389037}]}
1646003670.903552: {"arg":{"channel":"books-l2-tbt","instId":"UNI-USD-SWAP"},"action":"update","data":[{"asks":[["9.637","1","0","1"],["48.868","0","0","0"]],"bids":[["9.585","567","0","4"]],"ts":"1646003670890","checksum":-1625251031}]}
1646003670.903619: {"arg":{"channel":"books-l2-tbt","instId":"ZEN-USDT"},"action":"update","data":[{"asks":[["34.16","0","0","0"],["34.17","11.02","0","1"]],"bids":[],"ts":"1646003670890","checksum":-906822683}]}
1646003670.903648: {"arg":{"channel":"books-l2-tbt","instId":"ELON-USDT"},"action":"update","data":[{"asks":[["0.00000074744","0","0","0"],["0.00000113853","6145556","0","1"]],"bids":[],"ts":"1646003670892","checksum":938069954}]}
1646003670.9127061: {"arg":{"channel":"books-l2-tbt","instId":"UNI-USD-SWAP"},"action":"update","data":[{"asks":[["9.67","510","0","1"],["48.625","0","0","0"]],"bids":[["9.584","653","0","4"]],"ts":"1646003670900","checksum":-1625251031}]}
1646003670.914662: {"arg":{"channel":"books-l2-tbt","instId":"ELON-USDT"},"action":"update","data":[{"asks":[["0.00000074543","81175250","0","1"],["0.00000074589","159764443","0","2"],["0.00000113812","0","0","0"],["0.00000113853","0","0","0"]],"bids":[["0.0000007429","0","0","0"],["0.00000074289","671032853","0","1"]],"ts":"1646003670903","checksum":-988166970}]}
1646003670.9221811: {"arg":{"channel":"books-l2-tbt","instId":"UNI-USD-SWAP"},"action":"update","data":[{"asks":[["9.635","0","0","0"],["48.625","1","0","1"]],"bids":[],"ts":"1646003670911","checksum":-957157970}]}
1646003670.92525: {"arg":{"channel":"books-l2-tbt","instId":"ELON-USDT"},"action":"update","data":[{"asks":[["0.00000074589","604991315","0","3"],["0.0000007474","3603388909","0","1"],["0.0000011372","0","0","0"]],"bids":[["0.00000070565","144547580","0","1"],["0.00000069154","0","0","0"],["0.00000067771","0","0","0"],["0.00000066416","0","0","0"],["0.00000065074","322620511","0","1"]],"ts":"1646003670914","checksum":2715238}]}
1646003670.9369211: {"arg":{"channel":"books-l2-tbt","instId":"ELON-USDT"},"action":"update","data":[{"asks":[],"bids":[["0.00000074445","184440410","0","1"]],"ts":"1646003670925","checksum":-790742349}]}
1646003670.950314: {"arg":{"channel":"books-l2-tbt","instId":"ELON-USDT"},"action":"update","data":[{"asks":[["0.00000074588","104045940","0","1"],["0.0000011338","0","0","0"]],"bids":[],"ts":"1646003670935","checksum":848105496}]}
1646003670.968411: {"arg":{"channel":"books-l2-tbt","instId":"ELON-USDT"},"action":"update","data":[{"asks":[["0.00000074541","14812965","0","1"],["0.00000113315","0","0","0"]],"bids":[["0.00000074434","0","0","0"]],"ts":"1646003670957","checksum":70994113}]}
1646003670.978997: {"arg":{"channel":"books-l2-tbt","instId":"ELON-USDT"},"action":"update","data":[{"asks":[["0.00000074589","493242545","0","2"]],"bids":[],"ts":"1646003670968","checksum":261823906}]}
1646003670.989664: {"arg":{"channel":"books-l2-tbt","instId":"ELON-USDT"},"action":"update","data":[{"asks":[],"bids":[["0.00000074334","1354000000","0","1"],["0.000000739","15089352866","0","2"],["0.000000738","1982000000","0","3"]],"ts":"1646003670978","checksum":-749576208}]}
1646003670.999357: {"arg":{"channel":"books-l2-tbt","instId":"ELON-USDT"},"action":"update","data":[{"asks":[],"bids":[["0.00000074234","3412000000","0","1"],["0.00000056001","30433622","0","1"]],"ts":"1646003670988","checksum":-1048889617}]}
1646003671.012758: {"arg":{"channel":"books-l2-tbt","instId":"ELON-USDT"},"action":"update","data":[{"asks":[["0.00000074589","48015673","0","1"],["0.0000007459","0","0","0"],["0.00000113315","35900750","0","1"]],"bids":[["0.00000073801","0","0","0"],["0.00000056001","160433622","0","2"]],"ts":"1646003670999","checksum":2142690173}]}
1646003671.0141098: {"arg":{"channel":"books-l2-tbt","instId":"PROPS-ETH"},"action":"update","data":[{"asks":[],"bids":[["0.00000167","285391.022819","0","2"]],"ts":"1646003671003","checksum":-1857102559}]}
1646003671.032553: {"arg":{"channel":"books-l2-tbt","instId":"ELON-USDT"},"action":"update","data":[{"asks":[["0.00000074588","0","0","0"],["0.00000074589","0","0","0"],["0.000000746","1006222303","0","1"],["0.0000007465","1676394644","0","1"]],"bids":[],"ts":"1646003671020","checksum":-967471527}]}
1646003671.034888: {"arg":{"channel":"books-l2-tbt","instId":"PROPS-ETH"},"action":"update","data":[{"asks":[],"bids":[["0.00000167","458105.370372","0","3"]],"ts":"1646003671024","checksum":-1803347676}]}
1646003671.071445: {"arg":{"channel":"books-l2-tbt","instId":"ELON-USDT"},"action":"update","data":[{"asks":[["0.0000007454","69404609","0","2"],["0.00000074542","0","0","0"]],"bids":[["0.00000074234","0","0","0"]],"ts":"1646003671060","checksum":837421377}]}
1646003671.0921621: {"arg":{"channel":"books-l2-tbt","instId":"ELON-USDT"},"action":"update","data":[{"asks":[["0.00000074599","152061613","0","2"],["0.00000113315","0","0","0"]],"bids":[["0.00000074334","0","0","0"]],"ts":"1646003671080","checksum":30177803}]}
1646003671.108286: {"arg":{"channel":"books-l2-tbt","instId":"UNI-USD-SWAP"},"action":"update","data":[{"asks":[["9.637","206","0","2"],["9.638","11","0","1"]],"bids":[],"ts":"1646003671096","checksum":1694510659}]}
1646003671.11487: {"arg":{"channel":"books-l2-tbt","instId":"ELON-USDT"},"action":"update","data":[{"asks":[["0.00000074539","365534055","0","1"],["0.00000076199","210944203","0","1"],["0.00000113251","0","0","0"],["0.00000113256","0","0","0"]],"bids":[],"ts":"1646003671102","checksum":-187236110}]}
1646003671.1192708: {"arg":{"channel":"books-l2-tbt","instId":"UNI-USD-SWAP"},"action":"update","data":[{"asks":[],"bids":[["9.585","528","0","3"]],"ts":"1646003671108","checksum":1694510659}]}
1646003671.125831: {"arg":{"channel":"books-l2-tbt","instId":"ELON-USDT"},"action":"update","data":[{"asks":[["0.00000074599","48015673","0","1"],["0.00000074707","0","0","0"],["0.00000113251","12272136","0","1"]],"bids":[["0.00000074381","184440410","0","1"]],"ts":"1646003671113","checksum":-1787878826}]}
1646003671.135242: {"arg":{"channel":"books-l2-tbt","instId":"ELON-USDT"},"action":"update","data":[{"asks":[["0.00000074599","0","0","0"],["0.00000113256","10462875","0","1"]],"bids":[],"ts":"1646003671124","checksum":-1804690292}]}
1646003671.140358: {"arg":{"channel":"books-l2-tbt","instId":"UNI-USD-SWAP"},"action":"update","data":[{"asks":[["9.63","260","0","1"],["9.637","260","0","2"],["48.625","0","0","0"]],"bids":[],"ts":"1646003671129","checksum":1695203051}]}
1646003671.145708: {"arg":{"channel":"books-l2-tbt","instId":"ELON-USDT"},"action":"update","data":[{"asks":[["0.00000074538","48015673","0","1"],["0.00000074541","0","0","0"]],"bids":[],"ts":"1646003671134","checksum":-1462495582}]}
1646003671.156728: {"arg":{"channel":"books-l2-tbt","instId":"ELON-USDT"},"action":"update","data":[{"asks":[],"bids":[["0.00000074445","0","0","0"]],"ts":"1646003671145","checksum":773081234}]}
1646003671.160842: {"arg":{"channel":"books-l2-tbt","instId":"UNI-USD-SWAP"},"action":"update","data":[{"asks":[["9.636","98","0","1"]],"bids":[["9.617","103","0","2"]],"ts":"1646003671150","checksum":998531913}]}
1646003671.170198: {"arg":{"channel":"books-l2-tbt","instId":"ELON-USDT"},"action":"update","data":[{"asks":[],"bids":[["0.00000074218","0","0","0"]],"ts":"1646003671156","checksum":-1206462400}]}
1646003671.1826859: {"arg":{"channel":"books-l2-tbt","instId":"UNI-USD-SWAP"},"action":"update","data":[{"asks":[["9.63","348","0","2"],["9.631","0","0","0"],["48.625","1","0","1"]],"bids":[["9.621","53","0","1"]],"ts":"1646003671172","checksum":239559987}]}
1646003671.190145: {"arg":{"channel":"books-l2-tbt","instId":"ELON-USDT"},"action":"update","data":[{"asks":[["0.00000074538","159764443","0","2"]],"bids":[["0.00000074381","0","0","0"]],"ts":"1646003671177","checksum":1590807282}]}
1646003671.193163: {"arg":{"channel":"books-l2-tbt","instId":"UNI-USD-SWAP"},"action":"update","data":[{"asks":[],"bids":[["9.586","172","0","2"]],"ts":"1646003671182","checksum":239559987}]}
1646003671.205869: {"arg":{"channel":"books-l2-tbt","instId":"UNI-USD-SWAP"},"action":"update","data":[{"asks":[],"bids":[["9.618","1","0","1"]],"ts":"1646003671192","checksum":1297059962}]}
1646003671.21019: {"arg":{"channel":"books-l2-tbt","instId":"ELON-USDT"},"action":"update","data":[{"asks":[["0.00000074537","131255394","0","1"],["0.0000007477","0","0","0"]],"bids":[],"ts":"1646003671199","checksum":229812270}]}
1646003671.213633: {"arg":{"channel":"books-l2-tbt","instId":"UNI-USD-SWAP"},"action":"update","data":[{"asks":[],"bids":[["9.617","102","0","1"]],"ts":"1646003671202","checksum":531622447}]}
1646003671.235018: {"arg":{"channel":"books-l2-tbt","instId":"ELON-USDT"},"action":"update","data":[{"asks":[["0.00000074538","0","0","0"],["0.00000113315","35900750","0","1"]],"bids":[],"ts":"1646003671221","checksum":1654288758}]}
1646003671.242569: {"arg":{"channel":"books-l2-tbt","instId":"ELON-USDT"},"action":"update","data":[{"asks":[["0.00000074539","0","0","0"],["0.0000011338","129154981","0","1"]],"bids":[["0.00000074381","184440410","0","1"]],"ts":"1646003671231","checksum":-23139806}]}
1646003671.254698: {"arg":{"channel":"books-l2-tbt","instId":"ELON-USDT"},"action":"update","data":[{"asks":[["0.00000074536","159764443","0","2"],["0.0000011338","0","0","0"]],"bids":[],"ts":"1646003671244","checksum":849533559}]}
1646003671.256782: {"arg":{"channel":"books-l2-tbt","instId":"PROPS-ETH"},"action":"update","data":[{"asks":[["0.00000173","0","0","0"]],"bids":[["0.00000166","12048.19201807","0","1"]],"ts":"1646003671246","checksum":204245559}]}
1646003671.261316: {"arg":{"channel":"books-l2-tbt","instId":"ZEN-USDT"},"action":"update","data":[{"asks":[["32.61","32.61215","0","2"]],"bids":[["32.42","85.84508","0","4"]],"ts":"1646003671250","checksum":1788429527}]}
1646003671.263964: {"arg":{"channel":"books-l2-tbt","instId":"ELON-USDT"},"action":"update","data":[{"asks":[["0.00000074537","0","0","0"],["0.00000074706","4038943392","0","1"]],"bids":[],"ts":"1646003671252","checksum":-898448529}]}
1646003671.273918: {"arg":{"channel":"books-l2-tbt","instId":"ZEN-USDT"},"action":"update","data":[{"asks":[],"bids":[["32.42","70.47857","0","3"]],"ts":"1646003671261","checksum":1829153182}]}
1646003671.2750468: {"arg":{"channel":"books-l2-tbt","instId":"ELON-USDT"},"action":"update","data":[{"asks":[["0.00000074705","4038943392","0","1"],["0.00000074706","0","0","0"]],"bids":[],"ts":"1646003671263","checksum":-720847839}]}
1646003671.278413: {"arg":{"channel":"books-l2-tbt","instId":"PROPS-ETH"},"action":"update","data":[{"asks":[["0.00000172","0","0","0"]],"bids":[],"ts":"1646003671267","checksum":1548196656}]}
1646003671.282636: {"arg":{"channel":"books-l2-tbt","instId":"ZEN-USDT"},"action":"update","data":[{"asks":[],"bids":[["32.22","4.263961","0","2"],["32.19","0","0","0"],["31.9","4.06","0","1"],["31.86","0.31392","0","1"],["31.59","6.59","0","1"],["31.55","0","0","0"],["31.28","9.15","0","1"],["31.24","0","0","0"]],"ts":"1646003671271","checksum":7634409}]}
1646003671.284839: {"arg":{"channel":"books-l2-tbt","instId":"ELON-USDT"},"action":"update","data":[{"asks":[["0.00000074536","48015673","0","1"],["0.0000007454","0","0","0"],["0.00000074542","52273460","0","1"]],"bids":[["0.00000074229","3203141361","0","1"]],"ts":"1646003671273","checksum":-866081765}]}
1646003671.289031: {"arg":{"channel":"books-l2-tbt","instId":"PROPS-ETH"},"action":"update","data":[{"asks":[["0.00000175","9777.83332772","0","1"]],"bids":[["0.00000166","0","0","0"]],"ts":"1646003671278","checksum":-1493096646}]}
1646003671.2932081: {"arg":{"channel":"books-l2-tbt","instId":"ZEN-USDT"},"action":"update","data":[{"asks":[["32.61","19","0","1"]],"bids":[["30.97","14.069424","0","2"],["30.93","2.834933","0","2"]],"ts":"1646003671280","checksum":1914299362}]}
1646003671.2974138: {"arg":{"channel":"books-l2-tbt","instId":"ELON-USDT"},"action":"update","data":[{"asks":[["0.00000074539","327530363","0","1"],["0.00000074542","104631157","0","2"],["0.00000113315","0","0","0"]],"bids":[],"ts":"1646003671287","checksum":-730215560}]}
1646003671.3035579: {"arg":{"channel":"books-l2-tbt","instId":"ZEN-USDT"},"action":"update","data":[{"asks":[],"bids":[["32.46","8","0","1"],["31.71","6.982752","0","2"],["31.67","0","0","0"]],"ts":"1646003671291","checksum":621126814}]}
1646003671.303634: {"arg":{"channel":"books-l2-tbt","instId":"ELON-USDT"},"action":"update","data":[{"asks":[["0.00000074599","111748770","0","1"],["0.00000113256","0","0","0"]],"bids":[],"ts":"1646003671293","checksum":520446718}]}
1646003671.3092859: {"arg":{"channel":"books-l2-tbt","instId":"PROPS-ETH"},"action":"update","data":[{"asks":[["0.00000178","639.73351245","0","1"],["0.00000185","590.09078587","0","1"],["0.00000186","1353.47061534","0","1"],["0.00000187","650.00785223","0","1"]],"bids":[],"ts":"1646003671297","checksum":-458759704}]}
1646003671.3158169: {"arg":{"channel":"books-l2-tbt","instId":"ETH-USD-220429-1900-P"},"action":"update","data":[{"asks":[["0.0375","1001","0","2"],["0.038","505","0","1"]],"bids":[],"ts":"1646003671300","checksum":637852430}]}
1646003671.3158998: {"arg":{"channel":"books-l2-tbt","instId":"ZEN-USDT"},"action":"update","data":[{"asks":[],"bids":[["32.16","1.55","0","1"],["32.12","0","0","0"],["31.27","10.182752","0","2"],["31.23","0.471052","0","1"],["30.84","13.422752","0","2"],["30.8","0","0","0"],["30.41","16.712752","0","2"],["30.37","0","0","0"]],"ts":"1646003671302","checksum":-1418308251}]}
1646003671.315967: {"arg":{"channel":"books-l2-tbt","instId":"ELON-USDT"},"action":"update","data":[{"asks":[["0.00000074599","0","0","0"],["0.00000074705","0","0","0"],["0.00000113256","10462875","0","1"],["0.00000113315","35900750","0","1"]],"bids":[["0.00000074381","0","0","0"],["0.000000741","2880478803","0","2"]],"ts":"1646003671303","checksum":1416309147}]}
1646003671.329825: {"arg":{"channel":"books-l2-tbt","instId":"ELON-USDT"},"action":"update","data":[{"asks":[["0.00000074535","111748770","0","1"],["0.00000113315","0","0","0"]],"bids":[["0.00000074444","0","0","0"]],"ts":"1646003671314","checksum":-869472049}]}
1646003671.3375769: {"arg":{"channel":"books-l2-tbt","instId":"ELON-USDT"},"action":"update","data":[{"asks":[["0.00000074536","0","0","0"],["0.00000113315","35900750","0","1"]],"bids":[["0.00000074229","0","0","0"]],"ts":"1646003671325","checksum":-1642789391}]}
1646003671.346484: {"arg":{"channel":"books-l2-tbt","instId":"ELON-USDT"},"action":"update","data":[{"asks":[["0.00000074535","661021582","0","3"]],"bids":[],"ts":"1646003671335","checksum":510383138}]}
1646003671.346551: {"arg":{"channel":"books-l2-tbt","instId":"UNI-USD-SWAP"},"action":"update","data":[{"asks":[["9.648","2080","0","4"],["9.649","1230","0","2"],["9.651","100","0","3"],["9.652","16","0","1"],["9.654","251","0","2"],["9.655","242","0","2"]],"bids":[],"ts":"1646003671336","checksum":1469705870}]}
1646003671.358082: {"arg":{"channel":"books-l2-tbt","instId":"ELON-USDT"},"action":"update","data":[{"asks":[["0.00000074535","445226872","0","1"]],"bids":[],"ts":"1646003671346","checksum":-1161355137}]}
1646003671.367122: {"arg":{"channel":"books-l2-tbt","instId":"ZEN-USDT"},"action":"update","data":[{"asks":[["32.58","27.019517","0","1"]],"bids":[],"ts":"1646003671355","checksum":-2015026186}]}
1646003671.368775: {"arg":{"channel":"books-l2-tbt","instId":"ELON-USDT"},"action":"update","data":[{"asks":[["0.00000074534","215794710","0","2"],["0.00000113315","0","0","0"]],"bids":[],"ts":"1646003671357","checksum":687469729}]}
1646003671.377192: {"arg":{"channel":"books-l2-tbt","instId":"ZEN-USDT"},"action":"update","data":[{"asks":[["32.62","181.790616","0","3"]],"bids":[],"ts":"1646003671366","checksum":-1248594}]}
1646003671.381622: {"arg":{"channel":"books-l2-tbt","instId":"ELON-USDT"},"action":"update","data":[{"asks":[["0.00000074534","104045940","0","1"],["0.00000074543","0","0","0"],["0.00000113315","35900750","0","1"]],"bids":[["0.00000074445","184440410","0","1"]],"ts":"1646003671369","checksum":-537771248}]}
1646003671.397103: {"arg":{"channel":"books-l2-tbt","instId":"ETH-USD-220429-1900-P"},"action":"update","data":[{"asks":[["0.0375","500","0","1"],["0.038","1006","0","2"]],"bids":[],"ts":"1646003671386","checksum":356118983}]}
1646003671.400126: {"arg":{"channel":"books-l2-tbt","instId":"ELON-USDT"},"action":"update","data":[{"asks":[["0.00000074539","0","0","0"],["0.0000011338","129154981","0","1"]],"bids":[],"ts":"1646003671388","checksum":-1160730273}]}
1646003671.41222: {"arg":{"channel":"books-l2-tbt","instId":"ELON-USDT"},"action":"update","data":[{"asks":[],"bids":[["0.00000074381","184440410","0","1"]],"ts":"1646003671399","checksum":1206068011}]}
1646003671.4318101: {"arg":{"channel":"books-l2-tbt","instId":"ELON-USDT"},"action":"update","data":[{"asks":[],"bids":[["0.00000070254","340231120","0","1"],["0.00000068849","305997283","0","1"],["0.00000067473","169774721","0","1"],["0.00000066124","186655107","0","1"],["0.00000065074","0","0","0"]],"ts":"1646003671420","checksum":1206068011}]}
1646003671.452663: {"arg":{"channel":"books-l2-tbt","instId":"ELON-USDT"},"action":"update","data":[{"asks":[["0.00000074533","289466519","0","1"],["0.00000074599","81175250","0","1"],["0.00000113315","0","0","0"],["0.0000011338","0","0","0"]],"bids":[["0.00000074445","0","0","0"]],"ts":"1646003671441","checksum":1384160719}]}
1646003671.465257: {"arg":{"channel":"books-l2-tbt","instId":"ELON-USDT"},"action":"update","data":[{"asks":[["0.00000074534","0","0","0"],["0.00000113315","35900750","0","1"]],"bids":[],"ts":"1646003671453","checksum":-525973319}]}
1646003671.4843788: {"arg":{"channel":"books-l2-tbt","instId":"ELON-USDT"},"action":"update","data":[{"asks":[["0.00000074532","152061613","0","2"],["0.00000074535","0","0","0"]],"bids":[],"ts":"1646003671472","checksum":429737259}]}
1646003671.495868: {"arg":{"channel":"books-l2-tbt","instId":"ELON-USDT"},"action":"update","data":[{"asks":[["0.00000074532","205169336","0","3"],["0.00000074542","52273460","0","1"]],"bids":[["0.00000074131","0","0","0"]],"ts":"1646003671483","checksum":1313622872}]}
1646003671.5093539: {"arg":{"channel":"books-l2-tbt","instId":"ELON-USDT"},"action":"update","data":[{"asks":[],"bids":[["0.00000074381","0","0","0"]],"ts":"1646003671493","checksum":-39889495}]}
1646003671.522206: {"arg":{"channel":"books-l2-tbt","instId":"ELON-USDT"},"action":"update","data":[{"asks":[],"bids":[["0.0000007282","7337394396","0","1"]],"ts":"1646003671503","checksum":1517354599}]}
1646003671.5460851: {"arg":{"channel":"books-l2-tbt","instId":"ELON-USDT"},"action":"update","data":[{"asks":[["0.00000074531","445226872","0","1"],["0.00000113315","0","0","0"]],"bids":[],"ts":"1646003671534","checksum":-539086720}]}
1646003671.556629: {"arg":{"channel":"books-l2-tbt","instId":"ELON-USDT"},"action":"update","data":[{"asks":[],"bids":[["0.00000074381","118260122","0","1"]],"ts":"1646003671545","checksum":899061798}]}
1646003671.566557: {"arg":{"channel":"books-l2-tbt","instId":"ELON-USDT"},"action":"update","data":[{"asks":[["0.00000074532","53107723","0","1"]],"bids":[],"ts":"1646003671555","checksum":1552635242}]}
1646003671.576944: {"arg":{"channel":"books-l2-tbt","instId":"ELON-USDT"},"action":"update","data":[{"asks":[["0.0000007453","48015673","0","1"],["0.00000074533","0","0","0"]],"bids":[],"ts":"1646003671566","checksum":327115057}]}
1646003671.592167: {"arg":{"channel":"books-l2-tbt","instId":"ELON-USDT"},"action":"update","data":[{"asks":[["0.0000007453","159764443","0","2"]],"bids":[],"ts":"1646003671576","checksum":382839813}]}
1646003671.60802: {"arg":{"channel":"books-l2-tbt","instId":"UNI-USD-SWAP"},"action":"update","data":[{"asks":[["9.64","167","0","2"],["9.642","417","0","4"],["9.648","2059","0","3"],["9.657","22","0","1"],["48.625","0","0","0"]],"bids":[],"ts":"1646003671593","checksum":616487347}]}
1646003671.6273532: {"arg":{"channel":"books-l2-tbt","instId":"UNI-USD-SWAP"},"action":"update","data":[{"asks":[["9.639","3","0","1"],["48.383","0","0","0"]],"bids":[["9.617","104","0","2"]],"ts":"1646003671614","checksum":-995548913}]}
1646003671.632596: {"arg":{"channel":"books-l2-tbt","instId":"ELON-USDT"},"action":"update","data":[{"asks":[["0.00000074529","445226872","0","1"],["0.00000113256","0","0","0"]],"bids":[],"ts":"1646003671619","checksum":-857762939}]}
1646003671.6361668: {"arg":{"channel":"books-l2-tbt","instId":"UNI-USD-SWAP"},"action":"update","data":[{"asks":[["9.637","259","0","1"]],"bids":[["9.618","0","0","0"]],"ts":"1646003671624","checksum":-1317421787}]}
1646003671.649826: {"arg":{"channel":"books-l2-tbt","instId":"ELON-USDT"},"action":"update","data":[{"asks":[["0.0000007453","0","0","0"],["0.00000113256","10462875","0","1"]],"bids":[],"ts":"1646003671638","checksum":-1822878437}]}
1646003671.677613: {"arg":{"channel":"books-l2-tbt","instId":"UNI-USD-SWAP"},"action":"update","data":[{"asks":[],"bids":[["9.586","142","0","1"]],"ts":"1646003671656","checksum":-1317421787}]}
1646003671.6777248: {"arg":{"channel":"books-l2-tbt","instId":"ELON-USDT"},"action":"update","data":[{"asks":[["0.00000074528","159764443","0","2"],["0.00000074531","0","0","0"]],"bids":[["0.00000074201","750000000","0","1"]],"ts":"1646003671660","checksum":-305772610}]}
1646003671.677802: {"arg":{"channel":"books-l2-tbt","instId":"UNI-USD-SWAP"},"action":"update","data":[{"asks":[],"bids":[["9.588","140","0","2"]],"ts":"1646003671666","checksum":-1992354328}]}
1646003671.683866: {"arg":{"channel":"books-l2-tbt","instId":"BTC-USD-220325-40000-C"},"action":"update","data":[{"asks":[["0.0515","29","0","1"],["0.052","606","0","2"]],"bids":[],"ts":"1646003671670","checksum":-159329014}]}
1646003671.690279: {"arg":{"channel":"books-l2-tbt","instId":"UNI-USD-SWAP"},"action":"update","data":[{"asks":[],"bids":[["9.588","125","0","1"]],"ts":"1646003671677","checksum":-1317421787}]}
1646003671.693365: {"arg":{"channel":"books-l2-tbt","instId":"ELON-USDT"},"action":"update","data":[{"asks":[["0.00000074529","0","0","0"],["0.00000113315","35900750","0","1"]],"bids":[],"ts":"1646003671680","checksum":1234497575}]}
1646003671.704339: {"arg":{"channel":"books-l2-tbt","instId":"ELON-USDT"},"action":"update","data":[{"asks":[["0.00000074528","68654583","0","2"],["0.00000074532","0","0","0"],["0.00000074542","0","0","0"],["0.0000011338","129154981","0","1"],["0.0000011372","6179288","0","1"]],"bids":[],"ts":"1646003671692","checksum":-1164540412}]}
1646003671.708508: {"arg":{"channel":"books-l2-tbt","instId":"ETH-USD-220228-3000-C"},"action":"update","data":[{"asks":[],"bids":[],"ts":"1646003671698","checksum":1499363433}]}
1646003671.712629: {"arg":{"channel":"books-l2-tbt","instId":"UNI-USD-SWAP"},"action":"update","data":[{"asks":[["9.639","53","0","2"],["9.641","62","0","3"],["9.642","312","0","2"]],"bids":[["9.622","354","0","4"]],"ts":"1646003671698","checksum":483658583}]}
1646003671.721256: {"arg":{"channel":"books-l2-tbt","instId":"UNI-USD-SWAP"},"action":"update","data":[{"asks":[],"bids":[["9.621","0","0","0"],["9.612","178","0","2"],["9.611","558","0","2"],["9.61","24","0","1"],["9.609","0","0","0"],["9.607","43","0","2"],["9.606","0","0","0"]],"ts":"1646003671709","checksum":904358235}]}
1646003671.723458: {"arg":{"channel":"books-l2-tbt","instId":"ELON-USDT"},"action":"update","data":[{"asks":[["0.00000074598","159764443","0","2"],["0.00000074709","4038943392","0","1"],["0.0000011338","0","0","0"],["0.0000011372","0","0","0"]],"bids":[],"ts":"1646003671711","checksum":-1677384448}]}
1646003671.729791: {"arg":{"channel":"books-l2-tbt","instId":"UNI-USD-SWAP"},"action":"update","data":[{"asks":[],"bids":[["9.62","188","0","3"],["9.619","278","0","3"]],"ts":"1646003671719","checksum":1483367736}]}
1646003671.7468748: {"arg":{"channel":"books-l2-tbt","instId":"ELON-USDT"},"action":"update","data":[{"asks":[["0.00000074598","263810383","0","3"]],"bids":[],"ts":"1646003671733","checksum":1685868065}]}
1646003671.74991: {"arg":{"channel":"books-l2-tbt","instId":"UNI-USD-SWAP"},"action":"update","data":[{"asks":[["9.639","50","0","1"]],"bids":[],"ts":"1646003671739","checksum":-763143338}]}
1646003671.762097: {"arg":{"channel":"books-l2-tbt","instId":"ZEN-USDT"},"action":"update","data":[{"asks":[],"bids":[["32.52","0","0","0"]],"ts":"1646003671751","checksum":-1399265043}]}
1646003671.7675169: {"arg":{"channel":"books-l2-tbt","instId":"ELON-USDT"},"action":"update","data":[{"asks":[],"bids":[["0.00000074434","30384299","0","1"]],"ts":"1646003671754","checksum":-1020157382}]}
1646003671.777654: {"arg":{"channel":"books-l2-tbt","instId":"ELON-USDT"},"action":"update","data":[{"asks":[["0.00000074527","227045771","0","1"],["0.00000113315","0","0","0"]],"bids":[],"ts":"1646003671764","checksum":-1988720558}]}
1646003671.7777972: {"arg":{"channel":"books-l2-tbt","instId":"PROPS-ETH"},"action":"update","data":[{"asks":[["0.00000174","2941.17647058","0","1"]],"bids":[["0.00000167","345428.695106","0","2"],["0.00000166","6024.09600903","0","1"]],"ts":"1646003671767","checksum":-1881917468}]}
1646003671.7827919: {"arg":{"channel":"books-l2-tbt","instId":"ZEN-USDT"},"action":"update","data":[{"asks":[["32.61","31.61341","0","2"]],"bids":[],"ts":"1646003671770","checksum":1041659141}]}
1646003671.782903: {"arg":{"channel":"books-l2-tbt","instId":"UNI-USD-SWAP"},"action":"update","data":[{"asks":[],"bids":[["9.622","94","0","3"]],"ts":"1646003671771","checksum":-1809732484}]}
1646003671.786579: {"arg":{"channel":"books-l2-tbt","instId":"ELON-USDT"},"action":"update","data":[{"asks":[["0.00000074598","152061613","0","2"]],"bids":[["0.00000074289","0","0","0"],["0.00000074288","671001335","0","1"],["0.00000074217","3203528417","0","1"]],"ts":"1646003671772","checksum":-1901006000}]}
1646003671.7929752: {"arg":{"channel":"books-l2-tbt","instId":"UNI-USD-SWAP"},"action":"update","data":[{"asks":[["9.654","26","0","1"],["9.662","225","0","1"],["9.663","1658","0","1"],["9.679","846","0","1"],["9.72","0","0","0"],["9.733","846","0","1"],["9.776","0","0","0"],["9.795","846","0","1"],["47.903","0","0","0"],["48.143","0","0","0"]],"bids":[["9.619","272","0","2"],["9.617","109","0","3"],["9.511","0","0","0"],["9.506","846","0","1"],["9.454","0","0","0"],["9.444","3029","0","2"]],"ts":"1646003671782","checksum":471752933}]}
1646003671.796475: {"arg":{"channel":"books-l2-tbt","instId":"ELON-USDT"},"action":"update","data":[{"asks":[["0.00000074598","0","0","0"],["0.00000074709","0","0","0"],["0.00000113315","35900750","0","1"],["0.0000011338","129154981","0","1"]],"bids":[],"ts":"1646003671784","checksum":-429018497}]}
1646003671.801715: {"arg":{"channel":"books-l2-tbt","instId":"PROPS-ETH"},"action":"update","data":[{"asks":[],"bids":[["0.00000166","0","0","0"]],"ts":"1646003671788","checksum":640454772}]}
1646003671.802752: {"arg":{"channel":"books-l2-tbt","instId":"ZEN-USDT"},"action":"update","data":[{"asks":[],"bids":[["32.46","0","0","0"],["32.16","0","0","0"],["32.12","1.55","0","1"]],"ts":"1646003671792","checksum":-1144645531}]}
1646003671.8042371: {"arg":{"channel":"books-l2-tbt","instId":"UNI-USD-SWAP"},"action":"update","data":[{"asks":[["9.636","0","0","0"],["47.903","1","0","1"]],"bids":[],"ts":"1646003671793","checksum":-226950969}]}
1646003671.807072: {"arg":{"channel":"books-l2-tbt","instId":"ETH-USD-220325-8800-P"},"action":"update","data":[{"asks":[["2.5465","201","0","1"],["2.547","0","0","0"]],"bids":[],"ts":"1646003671797","checksum":75253033}]}
1646003671.807157: {"arg":{"channel":"books-l2-tbt","instId":"ELON-USDT"},"action":"update","data":[{"asks":[["0.00000074526","48015673","0","1"],["0.0000011338","0","0","0"]],"bids":[["0.00000074442","219861835","0","1"],["0.00000074381","0","0","0"]],"ts":"1646003671796","checksum":-1256880450}]}
1646003671.8104389: {"arg":{"channel":"books-l2-tbt","instId":"PROPS-ETH"},"action":"update","data":[{"asks":[["0.00000175","0","0","0"],["0.00000186","0","0","0"],["0.00000187","0","0","0"]],"bids":[],"ts":"1646003671799","checksum":1051455940}]}
1646003671.814059: {"arg":{"channel":"books-l2-tbt","instId":"ZEN-USDT"},"action":"update","data":[{"asks":[],"bids":[["31.71","2.272752","0","1"],["31.67","4.71","0","1"],["31.27","2.272752","0","1"],["31.23","8.381052","0","2"],["30.84","2.272752","0","1"],["30.8","11.16","0","1"],["30.41","2.272752","0","1"],["30.37","14.45","0","1"]],"ts":"1646003671802","checksum":-1144645531}]}
1646003671.81949: {"arg":{"channel":"books-l2-tbt","instId":"ELON-USDT"},"action":"update","data":[{"asks":[["0.00000074526","152061613","0","2"]],"bids":[["0.000000738","1292000000","0","2"]],"ts":"1646003671805","checksum":-520799149}]}
1646003671.82557: {"arg":{"channel":"books-l2-tbt","instId":"PROPS-ETH"},"action":"update","data":[{"asks":[["0.00000174","0","0","0"]],"bids":[["0.00000166","129490.77863735","0","1"]],"ts":"1646003671809","checksum":-504612966}]}
1646003671.834121: {"arg":{"channel":"books-l2-tbt","instId":"PROPS-ETH"},"action":"update","data":[{"asks":[["0.00000173","9622.1193366","0","1"]],"bids":[["0.00000167","458046.522","0","3"]],"ts":"1646003671820","checksum":-1483170528}]}
1646003671.8347678: {"arg":{"channel":"books-l2-tbt","instId":"BTC-USD-220325-40000-C"},"action":"update","data":[{"asks":[["0.0535","300","0","1"],["0.054","0","0","0"]],"bids":[],"ts":"1646003671825","checksum":-1808356384}]}
1646003671.850213: {"arg":{"channel":"books-l2-tbt","instId":"PROPS-ETH"},"action":"update","data":[{"asks":[["0.00000173","0","0","0"]],"bids":[],"ts":"1646003671836","checksum":-174122872}]}
1646003671.8523881: {"arg":{"channel":"books-l2-tbt","instId":"PROPS-ETH"},"action":"update","data":[{"asks":[["0.00000175","1242.35294117","0","1"]],"bids":[],"ts":"1646003671840","checksum":596302344}]}
1646003671.857762: {"arg":{"channel":"books-l2-tbt","instId":"UNI-USD-SWAP"},"action":"update","data":[{"asks":[["9.636","1","0","1"],["9.64","168","0","3"],["9.641","57","0","2"],["9.647","2570","0","6"],["9.648","2043","0","2"],["47.903","0","0","0"]],"bids":[],"ts":"1646003671845","checksum":-855272072}]}
1646003671.859915: {"arg":{"channel":"books-l2-tbt","instId":"ELON-USDT"},"action":"update","data":[{"asks":[],"bids":[["0.00000074434","0","0","0"]],"ts":"1646003671848","checksum":681953814}]}
1646003671.8686929: {"arg":{"channel":"books-l2-tbt","instId":"PROPS-ETH"},"action":"update","data":[{"asks":[["0.00000175","11142.17694111","0","2"]],"bids":[],"ts":"1646003671852","checksum":-2003137876}]}
1646003671.8688169: {"arg":{"channel":"books-l2-tbt","instId":"UNI-USD-SWAP"},"action":"update","data":[{"asks":[],"bids":[["9.618","1","0","1"]],"ts":"1646003671855","checksum":1181441582}]}
1646003671.86913: {"arg":{"channel":"books-l2-tbt","instId":"ELON-USDT"},"action":"update","data":[{"asks":[["0.00000074598","445226872","0","1"],["0.00000113315","0","0","0"]],"bids":[],"ts":"1646003671858","checksum":-132082946}]}
1646003671.873774: {"arg":{"channel":"books-l2-tbt","instId":"PROPS-ETH"},"action":"update","data":[{"asks":[["0.00000175","9899.82399994","0","1"]],"bids":[["0.00000166","0","0","0"]],"ts":"1646003671862","checksum":29759206}]}
1646003671.880186: {"arg":{"channel":"books-l2-tbt","instId":"UNI-USD-SWAP"},"action":"update","data":[{"asks":[],"bids":[["9.622","72","0","2"]],"ts":"1646003671868","checksum":941210345}]}
1646003671.880297: {"arg":{"channel":"books-l2-tbt","instId":"ELON-USDT"},"action":"update","data":[{"asks":[["0.00000074526","104045940","0","1"]],"bids":[],"ts":"1646003671869","checksum":-676856984}]}
1646003671.884459: {"arg":{"channel":"books-l2-tbt","instId":"PROPS-ETH"},"action":"update","data":[{"asks":[["0.00000175","0","0","0"]],"bids":[],"ts":"1646003671871","checksum":904566710}]}
1646003671.8894: {"arg":{"channel":"books-l2-tbt","instId":"UNI-USD-SWAP"},"action":"update","data":[{"asks":[],"bids":[["9.612","152","0","1"],["9.611","587","0","3"],["9.61","0","0","0"],["9.609","23","0","1"],["9.607","16","0","1"],["9.606","28","0","1"]],"ts":"1646003671877","checksum":-626470408}]}
1646003671.896995: {"arg":{"channel":"books-l2-tbt","instId":"ZEN-USDT"},"action":"update","data":[{"asks":[["32.59","19","0","1"],["32.61","12.61341","0","1"],["32.64","95","0","1"],["32.69","0","0","0"],["44.2","0","0","0"]],"bids":[],"ts":"1646003671885","checksum":1070595990}]}
1646003671.8977978: {"arg":{"channel":"books-l2-tbt","instId":"UNI-USD-SWAP"},"action":"update","data":[{"asks":[],"bids":[["9.62","135","0","2"]],"ts":"1646003671888","checksum":490647217}]}
1646003671.9036229: {"arg":{"channel":"books-l2-tbt","instId":"PROPS-ETH"},"action":"update","data":[{"asks":[["0.00000175","9735.58784604","0","1"]],"bids":[],"ts":"1646003671892","checksum":-1953133361}]}
1646003671.906733: {"arg":{"channel":"books-l2-tbt","instId":"ZEN-USDT"},"action":"update","data":[{"asks":[],"bids":[["32.46","0.50034","0","1"]],"ts":"1646003671895","checksum":-1155307892}]}
1646003671.912077: {"arg":{"channel":"books-l2-tbt","instId":"UNI-USD-SWAP"},"action":"update","data":[{"asks":[],"bids":[["9.617","104","0","2"],["9.616","18","0","2"],["9.611","529","0","2"],["9.607","96","0","2"]],"ts":"1646003671899","checksum":-1300830265}]}
1646003671.912126: {"arg":{"channel":"books-l2-tbt","instId":"ELON-USDT"},"action":"update","data":[{"asks":[["0.00000074526","157153663","0","2"],["0.00000074527","0","0","0"],["0.00000074528","0","0","0"],["0.00000113315","35900750","0","1"],["0.0000011338","129154981","0","1"]],"bids":[["0.00000074443","184440410","0","1"]],"ts":"1646003671899","checksum":1373308838}]}
1646003671.9148748: {"arg":{"channel":"books-l2-tbt","instId":"PROPS-ETH"},"action":"update","data":[{"asks":[["0.00000175","23497.90023773","0","2"]],"bids":[["0.00000166","129490.77863735","0","1"]],"ts":"1646003671904","checksum":-1662308543}]}
1646003671.9149241: {"arg":{"channel":"books-l2-tbt","instId":"ETH-USD-220429-1900-P"},"action":"update","data":[{"asks":[["0.0375","0","0","0"],["0.038","1506","0","3"]],"bids":[],"ts":"1646003671905","checksum":-1328280565}]}
1646003671.9177978: {"arg":{"channel":"books-l2-tbt","instId":"ZEN-USDT"},"action":"update","data":[{"asks":[],"bids":[["32.16","1.55","0","1"],["32.12","0","0","0"],["31.71","6.982752","0","2"],["31.67","0","0","0"],["31.27","10.182752","0","2"],["31.23","0.471052","0","1"],["30.84","13.422752","0","2"],["30.8","0","0","0"],["30.41","16.712752","0","2"],["30.37","0","0","0"]],"ts":"1646003671906","checksum":-1272436297}]}
1646003671.922421: {"arg":{"channel":"books-l2-tbt","instId":"ELON-USDT"},"action":"update","data":[{"asks":[],"bids":[["0.00000070254","0","0","0"],["0.00000068849","0","0","0"],["0.00000067473","0","0","0"],["0.00000066124","0","0","0"],["0.00000064798","421236834","0","1"]],"ts":"1646003671909","checksum":1373308838}]}
1646003671.922488: {"arg":{"channel":"books-l2-tbt","instId":"UNI-USD-SWAP"},"action":"update","data":[{"asks":[],"bids":[["9.622","12","0","1"]],"ts":"1646003671909","checksum":1221139684}]}
1646003671.933142: {"arg":{"channel":"books-l2-tbt","instId":"UNI-USD-SWAP"},"action":"update","data":[{"asks":[],"bids":[["9.619","325","0","3"]],"ts":"1646003671918","checksum":2006347241}]}
1646003671.933196: {"arg":{"channel":"books-l2-tbt","instId":"ELON-USDT"},"action":"update","data":[{"asks":[["0.00000074526","53107723","0","1"]],"bids":[["0.000000739","15779352866","0","3"]],"ts":"1646003671919","checksum":41875716}]}
1646003671.94384: {"arg":{"channel":"books-l2-tbt","instId":"PROPS-ETH"},"action":"update","data":[{"asks":[["0.00000175","13762.31239169","0","1"]],"bids":[],"ts":"1646003671924","checksum":-1756719030}]}
1646003671.943891: {"arg":{"channel":"books-l2-tbt","instId":"UNI-USD-SWAP"},"action":"update","data":[{"asks":[],"bids":[["9.584","684","0","5"]],"ts":"1646003671930","checksum":2006347241}]}
1646003671.9523149: {"arg":{"channel":"books-l2-tbt","instId":"ELON-USDT"},"action":"update","data":[{"asks":[["0.00000074711","4038943392","0","1"],["0.0000011338","0","0","0"]],"bids":[],"ts":"1646003671939","checksum":1265235986}]}
1646003671.952366: {"arg":{"channel":"books-l2-tbt","instId":"UNI-USD-SWAP"},"action":"update","data":[{"asks":[["9.63","260","0","1"],["9.64","167","0","2"],["9.641","60","0","3"]],"bids":[["9.617","102","0","1"]],"ts":"1646003671940","checksum":54705329}]}
1646003671.952941: {"arg":{"channel":"books-l2-tbt","instId":"PROPS-ETH"},"action":"update","data":[{"asks":[["0.00000174","9757.46229798","0","1"]],"bids":[],"ts":"1646003671943","checksum":682252826}]}
1646003671.969544: {"arg":{"channel":"books-l2-tbt","instId":"ZEN-USDT"},"action":"update","data":[{"asks":[["32.56","0","0","0"],["44.2","0.120899","0","1"]],"bids":[],"ts":"1646003671958","checksum":1259595895}]}
1646003671.972335: {"arg":{"channel":"books-l2-tbt","instId":"UNI-USD-SWAP"},"action":"update","data":[{"asks":[["9.632","0","0","0"],["47.903","1","0","1"]],"bids":[["9.584","653","0","4"]],"ts":"1646003671961","checksum":1042948636}]}
1646003671.9795468: {"arg":{"channel":"books-l2-tbt","instId":"ZEN-USDT"},"action":"update","data":[{"asks":[["32.61","0","0","0"],["44.22","2.271956","0","1"]],"bids":[],"ts":"1646003671967","checksum":1076184756}]}
1646003671.980236: {"arg":{"channel":"books-l2-tbt","instId":"ELON-USDT"},"action":"update","data":[{"asks":[["0.00000074599","0","0","0"],["0.0000011338","129154981","0","1"]],"bids":[],"ts":"1646003671970","checksum":647067022}]}
1646003671.9837818: {"arg":{"channel":"books-l2-tbt","instId":"UNI-USD-SWAP"},"action":"update","data":[{"asks":[],"bids":[["9.619","385","0","4"]],"ts":"1646003671972","checksum":-177674148}]}
1646003672.003648: {"arg":{"channel":"books-l2-tbt","instId":"UNI-USD-SWAP"},"action":"update","data":[{"asks":[],"bids":[["9.621","1","0","1"]],"ts":"1646003671991","checksum":-1702013154}]}
1646003672.0036979: {"arg":{"channel":"books-l2-tbt","instId":"ELON-USDT"},"action":"update","data":[{"asks":[["0.00000074597","111748770","0","1"],["0.0000011338","0","0","0"]],"bids":[],"ts":"1646003671991","checksum":402422069}]}
1646003672.012723: {"arg":{"channel":"books-l2-tbt","instId":"UNI-USD-SWAP"},"action":"update","data":[{"asks":[["9.641","57","0","2"]],"bids":[],"ts":"1646003672002","checksum":901267276}]}
1646003672.01582: {"arg":{"channel":"books-l2-tbt","instId":"ETH-USD-220325-8800-P"},"action":"update","data":[{"asks":[["2.5465","0","0","0"],["2.547","201","0","1"]],"bids":[],"ts":"1646003672005","checksum":-2044168485}]}
1646003672.0265338: {"arg":{"channel":"books-l2-tbt","instId":"UNI-USD-SWAP"},"action":"update","data":[{"asks":[["9.65","20","0","1"],["9.651","79","0","2"],["9.653","28","0","1"],["9.654","0","0","0"],["9.656","154","0","2"],["9.657","0","0","0"]],"bids":[["9.611","500","0","1"],["9.607","124","0","3"],["9.606","0","0","0"],["9.604","341","0","3"]],"ts":"1646003672011","checksum":-582270356}]}
1646003672.04258: {"arg":{"channel":"books-l2-tbt","instId":"UNI-USD-SWAP"},"action":"update","data":[{"asks":[["9.629","88","0","1"],["47.903","0","0","0"]],"bids":[["9.618","0","0","0"]],"ts":"1646003672031","checksum":-591739991}]}
1646003672.054602: {"arg":{"channel":"books-l2-tbt","instId":"ELON-USDT"},"action":"update","data":[{"asks":[["0.00000074598","0","0","0"],["0.0000011338","129154981","0","1"]],"bids":[],"ts":"1646003672042","checksum":1712222983}]}
1646003672.0663419: {"arg":{"channel":"books-l2-tbt","instId":"UNI-USD-SWAP"},"action":"update","data":[{"asks":[["9.628","260","0","1"],["47.665","0","0","0"]],"bids":[["9.619","332","0","3"]],"ts":"1646003672053","checksum":1123902037}]}
1646003672.0727801: {"arg":{"channel":"books-l2-tbt","instId":"ZEN-USDT"},"action":"update","data":[{"asks":[["33.5","6.816261","0","3"],["33.51","2.271956","0","1"],["34.16","11.02","0","1"],["34.17","0","0","0"]],"bids":[],"ts":"1646003672061","checksum":1076184756}]}
1646003672.073477: {"arg":{"channel":"books-l2-tbt","instId":"ELON-USDT"},"action":"update","data":[{"asks":[["0.00000074597","0","0","0"],["0.0000011372","6179288","0","1"]],"bids":[],"ts":"1646003672063","checksum":1221864584}]}
1646003672.082206: {"arg":{"channel":"books-l2-tbt","instId":"ZEN-USDT"},"action":"update","data":[{"asks":[["33.17","3.93","0","1"],["33.18","0","0","0"],["33.83","16.16","0","2"],["33.84","0","0","0"],["44.23","2.713011","0","1"]],"bids":[],"ts":"1646003672071","checksum":1076184756}]}
1646003672.085442: {"arg":{"channel":"books-l2-tbt","instId":"ELON-USDT"},"action":"update","data":[{"asks":[["0.00000074527","81175250","0","1"],["0.0000011372","0","0","0"]],"bids":[],"ts":"1646003672074","checksum":1038976083}]}
1646003672.0930061: {"arg":{"channel":"books-l2-tbt","instId":"ZEN-USDT"},"action":"update","data":[{"asks":[["32.56","0.998901","0","1"],["44.23","0","0","0"]],"bids":[],"ts":"1646003672081","checksum":143753279}]}
1646003672.0936608: {"arg":{"channel":"books-l2-tbt","instId":"ELON-USDT"},"action":"update","data":[{"asks":[["0.00000074599","159764443","0","2"],["0.0000011338","0","0","0"]],"bids":[],"ts":"1646003672083","checksum":-1381343862}]}
1646003672.0937018: {"arg":{"channel":"books-l2-tbt","instId":"UNI-USD-SWAP"},"action":"update","data":[{"asks":[],"bids":[["9.617","103","0","2"]],"ts":"1646003672083","checksum":655493936}]}
1646003672.1040099: {"arg":{"channel":"books-l2-tbt","instId":"ELON-USDT"},"action":"update","data":[{"asks":[["0.00000074525","16842831","0","1"],["0.00000113315","0","0","0"]],"bids":[["0.00000074381","184440410","0","1"]],"ts":"1646003672092","checksum":95771907}]}
1646003672.114588: {"arg":{"channel":"books-l2-tbt","instId":"ELON-USDT"},"action":"update","data":[{"asks":[["0.00000074526","105465420","0","2"],["0.00000074711","0","0","0"],["0.00000113315","35900750","0","1"]],"bids":[],"ts":"1646003672103","checksum":1435956726}]}
1646003672.12957: {"arg":{"channel":"books-l2-tbt","instId":"UNI-USD-SWAP"},"action":"update","data":[{"asks":[["9.65","0","0","0"],["9.651","100","0","3"],["9.653","0","0","0"],["9.654","23","0","1"],["9.656","124","0","1"],["9.657","21","0","1"]],"bids":[["9.619","385","0","4"]],"ts":"1646003672118","checksum":83272998}]}
1646003672.146753: {"arg":{"channel":"books-l2-tbt","instId":"ELON-USDT"},"action":"update","data":[{"asks":[],"bids":[["0.00000074443","0","0","0"]],"ts":"1646003672134","checksum":106654238}]}
1646003672.1592488: {"arg":{"channel":"books-l2-tbt","instId":"UNI-USD-SWAP"},"action":"update","data":[{"asks":[["9.636","260","0","2"],["9.637","0","0","0"],["47.665","1","0","1"]],"bids":[],"ts":"1646003672147","checksum":-1684393375}]}
1646003672.168863: {"arg":{"channel":"books-l2-tbt","instId":"ELON-USDT"},"action":"update","data":[{"asks":[["0.00000074599","263810383","0","3"]],"bids":[["0.00000074217","0","0","0"]],"ts":"1646003672156","checksum":-1099626186}]}
1646003672.17948: {"arg":{"channel":"books-l2-tbt","instId":"UNI-USD-SWAP"},"action":"update","data":[{"asks":[],"bids":[["9.621","0","0","0"]],"ts":"1646003672167","checksum":-1569941557}]}
1646003672.188776: {"arg":{"channel":"books-l2-tbt","instId":"ELON-USDT"},"action":"update","data":[{"asks":[["0.00000074598","445226872","0","1"],["0.00000074599","152061613","0","2"],["0.00000113315","0","0","0"]],"bids":[["0.00000074381","0","0","0"]],"ts":"1646003672177","checksum":287844163}]}
1646003672.2123919: {"arg":{"channel":"books-l2-tbt","instId":"ELON-USDT"},"action":"update","data":[{"asks":[["0.00000074599","0","0","0"],["0.00000113315","35900750","0","1"]],"bids":[],"ts":"1646003672200","checksum":-1742824987}]}
1646003672.221793: {"arg":{"channel":"books-l2-tbt","instId":"UNI-USD-SWAP"},"action":"update","data":[{"asks":[["9.642","337","0","3"]],"bids":[],"ts":"1646003672209","checksum":279638337}]}
1646003672.232028: {"arg":{"channel":"books-l2-tbt","instId":"ELON-USDT"},"action":"update","data":[{"asks":[["0.00000074597","152061613","0","2"],["0.00000113315","0","0","0"]],"bids":[],"ts":"1646003672220","checksum":-962711594}]}
1646003672.2435222: {"arg":{"channel":"books-l2-tbt","instId":"ELON-USDT"},"action":"update","data":[{"asks":[["0.00000074598","0","0","0"],["0.00000113315","35900750","0","1"]],"bids":[],"ts":"1646003672232","checksum":964758891}]}
1646003672.250039: {"arg":{"channel":"books-l2-tbt","instId":"ZEN-USDT"},"action":"update","data":[{"asks":[],"bids":[["32.49","10.102696","0","2"]],"ts":"1646003672238","checksum":1767356574}]}
1646003672.252021: {"arg":{"channel":"books-l2-tbt","instId":"UNI-USD-SWAP"},"action":"update","data":[{"asks":[["9.628","348","0","2"],["9.629","0","0","0"],["47.903","1","0","1"]],"bids":[["9.586","159","0","2"]],"ts":"1646003672239","checksum":-482006981}]}
1646003672.261429: {"arg":{"channel":"books-l2-tbt","instId":"UNI-USD-SWAP"},"action":"update","data":[{"asks":[],"bids":[["9.616","20","0","3"]],"ts":"1646003672250","checksum":-1719924684}]}
1646003672.262232: {"arg":{"channel":"books-l2-tbt","instId":"ELON-USDT"},"action":"update","data":[{"asks":[["0.00000074597","48015673","0","1"]],"bids":[],"ts":"1646003672252","checksum":-1097205967}]}
1646003672.274552: {"arg":{"channel":"books-l2-tbt","instId":"UNI-USD-SWAP"},"action":"update","data":[{"asks":[["9.64","267","0","3"]],"bids":[["9.619","332","0","3"],["9.617","102","0","1"],["9.616","18","0","2"]],"ts":"1646003672261","checksum":-24387758}]}
1646003672.2857401: {"arg":{"channel":"books-l2-tbt","instId":"UNI-USD-SWAP"},"action":"update","data":[{"asks":[],"bids":[["9.62","26","0","1"]],"ts":"1646003672272","checksum":115795365}]}
1646003672.2858171: {"arg":{"channel":"books-l2-tbt","instId":"ELON-USDT"},"action":"update","data":[{"asks":[["0.00000074597","0","0","0"],["0.00000074599","104045940","0","1"]],"bids":[],"ts":"1646003672274","checksum":1821232354}]}
1646003672.294143: {"arg":{"channel":"books-l2-tbt","instId":"UNI-USD-SWAP"},"action":"update","data":[{"asks":[["9.65","23","0","1"],["9.651","79","0","2"],["9.653","28","0","1"],["9.654","0","0","0"],["9.656","151","0","2"],["9.657","0","0","0"]],"bids":[],"ts":"1646003672282","checksum":1108772309}]}
1646003672.295949: {"arg":{"channel":"books-l2-tbt","instId":"ELON-USDT"},"action":"update","data":[{"asks":[],"bids":[["0.00000074381","184440410","0","1"]],"ts":"1646003672285","checksum":150070834}]}
1646003672.3150961: {"arg":{"channel":"books-l2-tbt","instId":"ZEN-USDT"},"action":"update","data":[{"asks":[["32.61","5.282327","0","1"],["44.22","0","0","0"]],"bids":[],"ts":"1646003672302","checksum":-595960189}]}
1646003672.315755: {"arg":{"channel":"books-l2-tbt","instId":"UNI-USD-SWAP"},"action":"update","data":[{"asks":[["9.636","259","0","1"]],"bids":[["9.617","103","0","2"],["9.586","142","0","1"]],"ts":"1646003672305","checksum":1602553688}]}
1646003672.3248608: {"arg":{"channel":"books-l2-tbt","instId":"ZEN-USDT"},"action":"update","data":[{"asks":[["32.54","8.87","0","2"]],"bids":[["32.46","0","0","0"]],"ts":"1646003672313","checksum":-1781611066}]}
1646003672.325623: {"arg":{"channel":"books-l2-tbt","instId":"UNI-USD-SWAP"},"action":"update","data":[{"asks":[["9.632","1","0","1"],["47.903","0","0","0"]],"bids":[],"ts":"1646003672315","checksum":-534955811}]}
1646003672.32721: {"arg":{"channel":"books-l2-tbt","instId":"ELON-USDT"},"action":"update","data":[{"asks":[["0.00000074526","52357697","0","1"]],"bids":[],"ts":"1646003672315","checksum":-2610166}]}
1646003672.337436: {"arg":{"channel":"books-l2-tbt","instId":"ELON-USDT"},"action":"update","data":[{"asks":[["0.00000074526","0","0","0"],["0.0000011338","129154981","0","1"]],"bids":[],"ts":"1646003672324","checksum":-1185219563}]}
1646003672.337525: {"arg":{"channel":"books-l2-tbt","instId":"UNI-USD-SWAP"},"action":"update","data":[{"asks":[],"bids":[["9.618","53","0","1"]],"ts":"1646003672325","checksum":857340563}]}
1646003672.34488: {"arg":{"channel":"books-l2-tbt","instId":"ZEN-USDT"},"action":"update","data":[{"asks":[["32.6","60.221392","0","2"],["32.61","0","0","0"],["32.62","130.790616","0","2"],["44.22","2.271956","0","1"]],"bids":[["32.45","72.107308","0","3"]],"ts":"1646003672333","checksum":1073058570}]}
1646003672.3472052: {"arg":{"channel":"books-l2-tbt","instId":"ELON-USDT"},"action":"update","data":[{"asks":[["0.00000074599","0","0","0"],["0.0000011372","6179288","0","1"]],"bids":[],"ts":"1646003672335","checksum":1923566468}]}
1646003672.34726: {"arg":{"channel":"books-l2-tbt","instId":"UNI-USD-SWAP"},"action":"update","data":[{"asks":[],"bids":[["9.623","0","0","0"],["9.622","34","0","2"]],"ts":"1646003672336","checksum":-778552573}]}
1646003672.3600771: {"arg":{"channel":"books-l2-tbt","instId":"UNI-USD-SWAP"},"action":"update","data":[{"asks":[["9.628","916","0","2"]],"bids":[["9.607","108","0","2"],["9.599","654","0","4"]],"ts":"1646003672347","checksum":1715875075}]}
1646003672.36238: {"arg":{"channel":"books-l2-tbt","instId":"PROPS-ETH"},"action":"update","data":[{"asks":[],"bids":[["0.00000166","0","0","0"]],"ts":"1646003672349","checksum":-1194420578}]}
1646003672.365525: {"arg":{"channel":"books-l2-tbt","instId":"ZEN-USDT"},"action":"update","data":[{"asks":[["32.62","35.970599","0","1"]],"bids":[["32.43","94.820017","0","1"]],"ts":"1646003672353","checksum":463056804}]}
1646003672.3705778: {"arg":{"channel":"books-l2-tbt","instId":"UNI-USD-SWAP"},"action":"update","data":[{"asks":[["9.628","260","0","1"],["9.646","16","0","1"],["9.647","2554","0","5"],["47.665","0","0","0"]],"bids":[["9.622","12","0","1"],["9.621","22","0","1"],["9.616","12","0","1"],["9.612","6","0","1"]],"ts":"1646003672356","checksum":124494959}]}
1646003672.379168: {"arg":{"channel":"books-l2-tbt","instId":"PROPS-ETH"},"action":"update","data":[{"asks":[["0.00000175","0","0","0"]],"bids":[],"ts":"1646003672359","checksum":-1869519436}]}
1646003672.379283: {"arg":{"channel":"books-l2-tbt","instId":"ZEN-USDT"},"action":"update","data":[{"asks":[["32.6","155.041409","0","3"]],"bids":[],"ts":"1646003672363","checksum":1034769000}]}
1646003672.379338: {"arg":{"channel":"books-l2-tbt","instId":"UNI-USD-SWAP"},"action":"update","data":[{"asks":[["9.633","0","0","0"],["9.639","54","0","2"],["9.64","167","0","2"],["9.648","1","0","1"],["9.657","225","0","1"],["9.662","0","0","0"],["9.663","0","0","0"],["9.669","846","0","1"],["9.679","0","0","0"],["9.723","846","0","1"],["9.733","0","0","0"],["9.779","846","0","1"],["9.795","0","0","0"],["47.665","1","0","1"],["47.903","1","0","1"]],"bids":[["9.618","0","0","0"],["9.615","0","0","0"],["9.613","35","0","3"],["9.612","0","0","0"],["9.603","0","0","0"],["9.6","18","0","1"],["9.599","636","0","3"],["9.59","9718","0","3"],["9.577","225","0","1"],["9.571","846","0","1"],["9.568","0","0","0"],["9.514","846","0","1"],["9.506","0","0","0"],["9.458","846","0","1"],["9.444","2183","0","1"]],"ts":"1646003672368","checksum":192260424}]}
1646003672.393208: {"arg":{"channel":"books-l2-tbt","instId":"UNI-USD-SWAP"},"action":"update","data":[{"asks":[["9.63","0","0","0"],["9.645","764","0","4"],["9.646","0","0","0"],["9.665","0","0","0"],["9.666","0","0","0"],["48.143","1","0","1"],["48.383","1","0","1"],["48.625","1","0","1"],["48.868","1","0","1"]],"bids":[],"ts":"1646003672378","checksum":-314090893}]}
1646003672.3933911: {"arg":{"channel":"books-l2-tbt","instId":"ETH-USD-220624-12000-P"},"action":"update","data":[{"asks":[["4.0415","0","0","0"],["4.043","201","0","1"]],"bids":[],"ts":"1646003672378","checksum":622825920}]}
1646003672.396448: {"arg":{"channel":"books-l2-tbt","instId":"PROPS-ETH"},"action":"update","data":[{"asks":[["0.00000174","0","0","0"]],"bids":[],"ts":"1646003672380","checksum":904566710}]}
1646003672.396561: {"arg":{"channel":"books-l2-tbt","instId":"ZEN-USDT"},"action":"update","data":[{"asks":[["32.56","0","0","0"],["32.6","160.412859","0","4"],["44.23","2.713011","0","1"]],"bids":[["32.43","0","0","0"]],"ts":"1646003672384","checksum":-882159216}]}
1646003672.4028192: {"arg":{"channel":"books-l2-tbt","instId":"UNI-USD-SWAP"},"action":"update","data":[{"asks":[["9.638","14","0","2"],["9.639","50","0","1"],["9.668","22","0","1"],["9.67","593","0","2"],["48.868","0","0","0"]],"bids":[],"ts":"1646003672388","checksum":1852089545}]}
1646003672.402925: {"arg":{"channel":"books-l2-tbt","instId":"PROPS-ETH"},"action":"update","data":[{"asks":[],"bids":[["0.00000167","285332.174447","0","2"]],"ts":"1646003672390","checksum":-1473669020}]}
1646003672.413433: {"arg":{"channel":"books-l2-tbt","instId":"PROPS-ETH"},"action":"update","data":[{"asks":[["0.00000175","12560","0","1"]],"bids":[["0.00000166","129490.77863735","0","1"]],"ts":"1646003672399","checksum":790217658}]}
1646003672.413522: {"arg":{"channel":"books-l2-tbt","instId":"UNI-USD-SWAP"},"action":"update","data":[{"asks":[],"bids":[["9.601","16","0","1"],["9.6","0","0","0"]],"ts":"1646003672400","checksum":1674975720}]}
1646003672.42177: {"arg":{"channel":"books-l2-tbt","instId":"UNI-USD-SWAP"},"action":"update","data":[{"asks":[["9.649","1259","0","3"],["9.65","0","0","0"],["9.652","40","0","2"],["9.653","0","0","0"],["9.655","271","0","3"],["9.656","124","0","1"],["9.668","0","0","0"],["48.868","1","0","1"],["49.113","1","0","1"],["49.358","1","0","1"]],"bids":[["9.614","5","0","1"],["9.613","29","0","2"]],"ts":"1646003672409","checksum":1222618629}]}
1646003672.421879: {"arg":{"channel":"books-l2-tbt","instId":"PROPS-ETH"},"action":"update","data":[{"asks":[["0.00000175","22175.20544143","0","2"]],"bids":[],"ts":"1646003672410","checksum":-77380520}]}
1646003672.42732: {"arg":{"channel":"books-l2-tbt","instId":"ELON-USDT"},"action":"update","data":[{"asks":[],"bids":[["0.0000006993","149307632","0","1"],["0.00000068532","234692226","0","1"],["0.00000067162","415045000","0","1"],["0.00000065819","162127531","0","1"],["0.00000064798","0","0","0"]],"ts":"1646003672415","checksum":1923566468}]}
1646003672.434947: {"arg":{"channel":"books-l2-tbt","instId":"PROPS-ETH"},"action":"update","data":[{"asks":[["0.00000175","12560","0","1"]],"bids":[["0.00000167","458046.522","0","3"]],"ts":"1646003672419","checksum":1973933694}]}
1646003672.435683: {"arg":{"channel":"books-l2-tbt","instId":"UNI-USD-SWAP"},"action":"update","data":[{"asks":[],"bids":[["9.617","1","0","1"]],"ts":"1646003672424","checksum":-1433341780}]}
1646003672.443402: {"arg":{"channel":"books-l2-tbt","instId":"UNI-USD-SWAP"},"action":"update","data":[{"asks":[["9.635","3","0","1"],["49.358","0","0","0"]],"bids":[["9.614","11","0","2"]],"ts":"1646003672431","checksum":-459631047}]}
1646003672.4435341: {"arg":{"channel":"books-l2-tbt","instId":"ETH-USD-220325-8800-P"},"action":"update","data":[{"asks":[["2.547","0","0","0"],["2.5475","201","0","1"]],"bids":[],"ts":"1646003672432","checksum":-819947892}]}
1646003672.448707: {"arg":{"channel":"books-l2-tbt","instId":"ELON-USDT"},"action":"update","data":[{"asks":[["0.00000074599","111748770","0","1"],["0.0000011372","0","0","0"]],"bids":[],"ts":"1646003672436","checksum":-2115786413}]}
1646003672.452935: {"arg":{"channel":"books-l2-tbt","instId":"UNI-USD-SWAP"},"action":"update","data":[{"asks":[["9.627","88","0","1"],["9.644","1038","0","4"],["9.645","748","0","3"],["49.113","0","0","0"]],"bids":[],"ts":"1646003672442","checksum":770799276}]}
1646003672.460635: {"arg":{"channel":"books-l2-tbt","instId":"BTC-USD-220325-40000-C"},"action":"update","data":[{"asks":[["0.054","100","0","1"],["0.0545","0","0","0"]],"bids":[],"ts":"1646003672450","checksum":282581609}]}
1646003672.463829: {"arg":{"channel":"books-l2-tbt","instId":"UNI-USD-SWAP"},"action":"update","data":[{"asks":[["9.632","0","0","0"],["9.638","11","0","1"],["49.113","1","0","1"]],"bids":[["9.617","0","0","0"]],"ts":"1646003672451","checksum":-1030084795}]}
1646003672.4639711: {"arg":{"channel":"books-l2-tbt","instId":"PROPS-ETH"},"action":"update","data":[{"asks":[["0.00000174","9918.26239134","0","1"]],"bids":[],"ts":"1646003672452","checksum":1978260582}]}
1646003672.46854: {"arg":{"channel":"books-l2-tbt","instId":"ZEN-USDT"},"action":"update","data":[{"asks":[["32.61","16.141429","0","1"],["44.23","0","0","0"]],"bids":[["32.43","94.820017","0","1"]],"ts":"1646003672455","checksum":1481687315}]}
1646003672.4711838: {"arg":{"channel":"books-l2-tbt","instId":"ELON-USDT"},"action":"update","data":[{"asks":[],"bids":[["0.00000074443","71449368","0","1"]],"ts":"1646003672458","checksum":298897067}]}
1646003672.4742122: {"arg":{"channel":"books-l2-tbt","instId":"UNI-USD-SWAP"},"action":"update","data":[{"asks":[["9.626","260","0","1"],["9.638","119","0","2"],["9.644","930","0","3"],["49.113","0","0","0"]],"bids":[["9.614","6","0","1"],["9.613","35","0","3"]],"ts":"1646003672462","checksum":-376829993}]}
1646003672.4842398: {"arg":{"channel":"books-l2-tbt","instId":"UNI-USD-SWAP"},"action":"update","data":[{"asks":[["9.636","293","0","2"],["9.639","0","0","0"],["49.113","1","0","1"]],"bids":[["9.622","0","0","0"]],"ts":"1646003672472","checksum":572581909}]}
1646003672.49165: {"arg":{"channel":"books-l2-tbt","instId":"ELON-USDT"},"action":"update","data":[{"asks":[["0.00000074599","556975642","0","2"]],"bids":[],"ts":"1646003672479","checksum":1780288160}]}
1646003672.506443: {"arg":{"channel":"books-l2-tbt","instId":"UNI-USD-SWAP"},"action":"update","data":[{"asks":[["9.67","510","0","1"]],"bids":[],"ts":"1646003672493","checksum":1945121703}]}
1646003672.510655: {"arg":{"channel":"books-l2-tbt","instId":"ELON-USDT"},"action":"update","data":[{"asks":[["0.00000074599","604991315","0","3"]],"bids":[],"ts":"1646003672499","checksum":41382353}]}
1646003672.526656: {"arg":{"channel":"books-l2-tbt","instId":"UNI-USD-SWAP"},"action":"update","data":[{"asks":[["9.649","1230","0","2"],["9.658","63","0","2"]],"bids":[["9.585","562","0","4"]],"ts":"1646003672515","checksum":-524447711}]}
1646003672.5325608: {"arg":{"channel":"books-l2-tbt","instId":"ELON-USDT"},"action":"update","data":[{"asks":[["0.00000074524","53107723","0","1"],["0.0000011338","0","0","0"]],"bids":[],"ts":"1646003672520","checksum":-2123452639}]}
1646003672.5380921: {"arg":{"channel":"books-l2-tbt","instId":"UNI-USD-SWAP"},"action":"update","data":[{"asks":[],"bids":[["9.616","65","0","2"]],"ts":"1646003672526","checksum":-1558895789}]}
1646003672.546924: {"arg":{"channel":"books-l2-tbt","instId":"UNI-USD-SWAP"},"action":"update","data":[{"asks":[["9.627","0","0","0"],["49.358","1","0","1"]],"bids":[],"ts":"1646003672535","checksum":-588249906}]}
1646003672.551218: {"arg":{"channel":"books-l2-tbt","instId":"ZEN-USDT"},"action":"update","data":[{"asks":[["32.53","0.383596","0","1"],["44.22","0","0","0"]],"bids":[["32.43","0","0","0"]],"ts":"1646003672539","checksum":423470193}]}
1646003672.554029: {"arg":{"channel":"books-l2-tbt","instId":"ELON-USDT"},"action":"update","data":[{"asks":[["0.00000074598","104045940","0","1"],["0.00000113315","0","0","0"]],"bids":[],"ts":"1646003672541","checksum":314726902}]}
1646003672.564279: {"arg":{"channel":"books-l2-tbt","instId":"ELON-USDT"},"action":"update","data":[{"asks":[],"bids":[["0.00000074381","0","0","0"]],"ts":"1646003672552","checksum":1953287241}]}
1646003672.57038: {"arg":{"channel":"books-l2-tbt","instId":"UNI-USD-SWAP"},"action":"update","data":[{"asks":[["9.628","0","0","0"],["49.605","1","0","1"]],"bids":[],"ts":"1646003672558","checksum":-1565245635}]}
1646003672.573745: {"arg":{"channel":"books-l2-tbt","instId":"ZEN-USDT"},"action":"update","data":[{"asks":[["32.56","2.004864","0","1"],["32.6","155.041409","0","3"],["32.9","61.51","0","2"],["32.91","0","0","0"],["33.36","4.52","0","1"],["33.37","0","0","0"],["33.82","7.49715","0","2"],["33.83","8.68","0","1"],["34.29","10.4","0","1"],["34.3","2.338605","0","1"],["44.2","0","0","0"]],"bids":[["32.22","2.713961","0","1"],["32.21","1.55","0","1"],["32.16","0","0","0"],["32.15","311.331042","0","3"],["31.71","2.272752","0","1"],["31.7","4.71","0","1"],["31.59","0","0","0"],["31.58","6.59","0","1"],["31.27","2.272752","0","1"],["31.26","7.91","0","1"],["30.84","2.272752","0","1"],["30.83","11.15","0","1"],["30.41","2.272752","0","1"],["30.4","41.062301","0","3"]],"ts":"1646003672560","checksum":1592113125}]}
1646003672.578294: {"arg":{"channel":"books-l2-tbt","instId":"UNI-USD-SWAP"},"action":"update","data":[{"asks":[["9.633","18","0","1"],["49.605","0","0","0"]],"bids":[],"ts":"1646003672566","checksum":-1915117245}]}
1646003672.583646: {"arg":{"channel":"books-l2-tbt","instId":"ZEN-USDT"},"action":"update","data":[{"asks":[["32.84","1.52","0","1"],["32.85","0","0","0"],["34.77","13.28","0","1"],["34.78","0","0","0"]],"bids":[["31.9","0","0","0"],["31.89","8.773961","0","3"],["31.28","0","0","0"],["31.27","11.422752","0","2"],["30.97","2.339424","0","1"],["30.96","11.73","0","1"]],"ts":"1646003672571","checksum":1341991385}]}
1646003672.588327: {"arg":{"channel":"books-l2-tbt","instId":"UNI-USD-SWAP"},"action":"update","data":[{"asks":[["9.636","259","0","1"],["9.638","199","0","3"]],"bids":[],"ts":"1646003672577","checksum":-1518647154}]}
1646003672.59472: {"arg":{"channel":"books-l2-tbt","instId":"ELON-USDT"},"action":"update","data":[{"asks":[["0.00000074527","0","0","0"],["0.00000113315","35900750","0","1"]],"bids":[],"ts":"1646003672584","checksum":-1402014924}]}
1646003672.606497: {"arg":{"channel":"books-l2-tbt","instId":"ELON-USDT"},"action":"update","data":[{"asks":[["0.00000074525","0","0","0"],["0.0000011338","129154981","0","1"]],"bids":[],"ts":"1646003672594","checksum":-2086959088}]}
1646003672.6185348: {"arg":{"channel":"books-l2-tbt","instId":"ELON-USDT"},"action":"update","data":[{"asks":[["0.00000074599","493242545","0","2"]],"bids":[],"ts":"1646003672604","checksum":-962221665}]}
1646003672.6215942: {"arg":{"channel":"books-l2-tbt","instId":"UNI-USD-SWAP"},"action":"update","data":[{"asks":[],"bids":[["9.614","0","0","0"]],"ts":"1646003672609","checksum":1308058873}]}
1646003672.6315572: {"arg":{"channel":"books-l2-tbt","instId":"UNI-USD-SWAP"},"action":"update","data":[{"asks":[["9.632","1","0","1"],["9.649","1252","0","3"],["9.658","35","0","1"],["49.358","0","0","0"]],"bids":[["9.609","0","0","0"],["9.605","55","0","2"],["9.604","317","0","2"],["9.602","30","0","1"]],"ts":"1646003672619","checksum":1492575329}]}
1646003672.663223: {"arg":{"channel":"books-l2-tbt","instId":"UNI-USD-SWAP"},"action":"update","data":[{"asks":[["9.626","348","0","2"],["9.635","0","0","0"],["49.358","1","0","1"]],"bids":[["9.62","27","0","2"]],"ts":"1646003672641","checksum":1513678463}]}
1646003672.663305: {"arg":{"channel":"books-l2-tbt","instId":"UNI-USD-SWAP"},"action":"update","data":[{"asks":[],"bids":[["9.621","0","0","0"],["9.62","49","0","3"]],"ts":"1646003672650","checksum":1311692571}]}
1646003672.67055: {"arg":{"channel":"books-l2-tbt","instId":"ELON-USDT"},"action":"update","data":[{"asks":[],"bids":[["0.00000074381","184440410","0","1"]],"ts":"1646003672658","checksum":1662891570}]}
1646003672.680827: {"arg":{"channel":"books-l2-tbt","instId":"UNI-USD-SWAP"},"action":"update","data":[{"asks":[["9.663","107","0","1"],["49.358","0","0","0"]],"bids":[],"ts":"1646003672669","checksum":-253577052}]}
1646003672.6920152: {"arg":{"channel":"books-l2-tbt","instId":"ELON-USDT"},"action":"update","data":[{"asks":[["0.00000074599","445226872","0","1"]],"bids":[],"ts":"1646003672679","checksum":548846149}]}
1646003672.692093: {"arg":{"channel":"books-l2-tbt","instId":"UNI-USD-SWAP"},"action":"update","data":[{"asks":[["9.66","9266","0","2"]],"bids":[["9.617","2","0","1"]],"ts":"1646003672680","checksum":318400045}]}
1646003672.702912: {"arg":{"channel":"books-l2-tbt","instId":"ELON-USDT"},"action":"update","data":[{"asks":[["0.00000074599","526402122","0","2"]],"bids":[],"ts":"1646003672689","checksum":-2078307270}]}
1646003672.732712: {"arg":{"channel":"books-l2-tbt","instId":"BTC-USD-220325-40000-C"},"action":"update","data":[{"asks":[],"bids":[["0.049","0","0","0"],["0.0485","305","0","1"]],"ts":"1646003672717","checksum":-1006770939}]}
1646003672.732772: {"arg":{"channel":"books-l2-tbt","instId":"ELON-USDT"},"action":"update","data":[{"asks":[],"bids":[["0.00000074381","0","0","0"]],"ts":"1646003672720","checksum":2092082833}]}
1646003672.746948: {"arg":{"channel":"books-l2-tbt","instId":"UNI-USD-SWAP"},"action":"update","data":[{"asks":[["9.647","2577","0","6"],["9.649","1230","0","2"],["9.65","26","0","1"],["9.652","16","0","1"],["9.653","27","0","1"],["9.655","242","0","2"],["48.868","0","0","0"],["49.113","0","0","0"]],"bids":[["9.62","48","0","2"],["9.619","272","0","2"]],"ts":"1646003672731","checksum":1769981296}]}
1646003672.747027: {"arg":{"channel":"books-l2-tbt","instId":"ELON-USDT"},"action":"update","data":[{"asks":[["0.00000074524","0","0","0"],["0.00000074598","156403637","0","2"],["0.00000074599","81175250","0","1"],["0.0000011372","6179288","0","1"]],"bids":[],"ts":"1646003672731","checksum":1813642596}]}
1646003672.753255: {"arg":{"channel":"books-l2-tbt","instId":"ELON-USDT"},"action":"update","data":[{"asks":[["0.00000074597","445226872","0","1"],["0.00000074598","52357697","0","1"],["0.0000011372","0","0","0"]],"bids":[["0.000000738","682000000","0","1"]],"ts":"1646003672741","checksum":1990919663}]}
1646003672.753314: {"arg":{"channel":"books-l2-tbt","instId":"UNI-USD-SWAP"},"action":"update","data":[{"asks":[["9.626","260","0","1"]],"bids":[],"ts":"1646003672742","checksum":2124686823}]}
1646003672.7668731: {"arg":{"channel":"books-l2-tbt","instId":"ELON-USDT"},"action":"update","data":[{"asks":[["0.00000074638","0","0","0"],["0.0000011372","6179288","0","1"]],"bids":[["0.00000074338","0","0","0"],["0.00000074273","4038943392","0","1"]],"ts":"1646003672752","checksum":-518400942}]}
1646003672.7669408: {"arg":{"channel":"books-l2-tbt","instId":"ETH-USD-220325-8800-P"},"action":"update","data":[{"asks":[["2.5475","0","0","0"],["2.548","201","0","1"]],"bids":[],"ts":"1646003672753","checksum":75030794}]}
1646003672.772612: {"arg":{"channel":"books-l2-tbt","instId":"BTC-USD-220325-40000-C"},"action":"update","data":[{"asks":[],"bids":[["0.05","301","0","1"],["0.0495","300","0","1"]],"ts":"1646003672760","checksum":-505043669}]}
1646003672.777029: {"arg":{"channel":"books-l2-tbt","instId":"ELON-USDT"},"action":"update","data":[{"asks":[],"bids":[["0.00000074442","0","0","0"]],"ts":"1646003672762","checksum":1210426269}]}
1646003672.777067: {"arg":{"channel":"books-l2-tbt","instId":"UNI-USD-SWAP"},"action":"update","data":[{"asks":[["9.635","11","0","1"],["48.625","0","0","0"]],"bids":[["9.603","108","0","1"],["9.592","134","0","2"]],"ts":"1646003672763","checksum":-569770112}]}
1646003672.788086: {"arg":{"channel":"books-l2-tbt","instId":"ELON-USDT"},"action":"update","data":[{"asks":[["0.00000074625","496511003","0","1"],["0.0000007474","0","0","0"]],"bids":[],"ts":"1646003672773","checksum":-942707632}]}
1646003672.795049: {"arg":{"channel":"books-l2-tbt","instId":"ELON-USDT"},"action":"update","data":[{"asks":[["0.00000074596","111748770","0","1"],["0.0000011372","0","0","0"]],"bids":[],"ts":"1646003672783","checksum":-1585161767}]}
1646003672.796512: {"arg":{"channel":"books-l2-tbt","instId":"UNI-USD-SWAP"},"action":"update","data":[{"asks":[],"bids":[["9.619","12","0","1"]],"ts":"1646003672785","checksum":10599438}]}
1646003672.796549: {"arg":{"channel":"books-l2-tbt","instId":"PROPS-ETH"},"action":"update","data":[{"asks":[["0.00000183","0","0","0"]],"bids":[],"ts":"1646003672786","checksum":-1631591104}]}
1646003672.808325: {"arg":{"channel":"books-l2-tbt","instId":"ETH-USD-220624-12000-P"},"action":"update","data":[{"asks":[["4.043","0","0","0"],["4.044","201","0","1"]],"bids":[],"ts":"1646003672793","checksum":-1757458992}]}
1646003672.8083782: {"arg":{"channel":"books-l2-tbt","instId":"ELON-USDT"},"action":"update","data":[{"asks":[["0.0000007473","2935030864","0","1"],["0.0000011338","0","0","0"]],"bids":[],"ts":"1646003672793","checksum":839523221}]}
1646003672.82583: {"arg":{"channel":"books-l2-tbt","instId":"UNI-USD-SWAP"},"action":"update","data":[{"asks":[],"bids":[["9.614","60","0","1"]],"ts":"1646003672815","checksum":1627760342}]}
1646003672.846091: {"arg":{"channel":"books-l2-tbt","instId":"ETH-USD-220624-20000-C"},"action":"update","data":[{"asks":[["0.0025","520","0","2"],["0.003","1006","0","2"]],"bids":[],"ts":"1646003672829","checksum":-1719318134}]}
1646003672.8578: {"arg":{"channel":"books-l2-tbt","instId":"UNI-USD-SWAP"},"action":"update","data":[{"asks":[["9.626","348","0","2"]],"bids":[],"ts":"1646003672846","checksum":960812418}]}
1646003672.865257: {"arg":{"channel":"books-l2-tbt","instId":"ZEN-USDT"},"action":"update","data":[{"asks":[],"bids":[["32.45","15.869949","0","2"]],"ts":"1646003672854","checksum":-1723120220}]}
1646003672.868387: {"arg":{"channel":"books-l2-tbt","instId":"ELON-USDT"},"action":"update","data":[{"asks":[["0.0000007466","0","0","0"],["0.0000011338","129154981","0","1"]],"bids":[],"ts":"1646003672857","checksum":-268456527}]}
1646003672.8684318: {"arg":{"channel":"books-l2-tbt","instId":"ETH-USD-220325-8800-P"},"action":"update","data":[{"asks":[["2.548","0","0","0"],["2.5485","201","0","1"]],"bids":[],"ts":"1646003672858","checksum":1047929945}]}
1646003672.87806: {"arg":{"channel":"books-l2-tbt","instId":"UNI-USD-SWAP"},"action":"update","data":[{"asks":[["9.634","284","0","1"],["9.636","0","0","0"]],"bids":[],"ts":"1646003672867","checksum":-958845081}]}
1646003672.88798: {"arg":{"channel":"books-l2-tbt","instId":"ELON-USDT"},"action":"update","data":[{"asks":[["0.00000074596","159764443","0","2"]],"bids":[],"ts":"1646003672877","checksum":124524049}]}
1646003672.8977349: {"arg":{"channel":"books-l2-tbt","instId":"BTC-USD-220325-40000-C"},"action":"update","data":[{"asks":[],"bids":[["0.05","0","0","0"],["0.0495","601","0","2"]],"ts":"1646003672887","checksum":-15672430}]}
1646003672.8997838: {"arg":{"channel":"books-l2-tbt","instId":"ELON-USDT"},"action":"update","data":[{"asks":[["0.00000074595","445226872","0","1"],["0.0000011338","0","0","0"]],"bids":[["0.00000074434","184440410","0","1"]],"ts":"1646003672889","checksum":1056039132}]}
1646003672.919992: {"arg":{"channel":"books-l2-tbt","instId":"ELON-USDT"},"action":"update","data":[{"asks":[["0.00000074596","0","0","0"],["0.0000011338","129154981","0","1"]],"bids":[["0.0000006993","0","0","0"],["0.00000068532","0","0","0"],["0.00000067162","0","0","0"],["0.00000065819","0","0","0"],["0.00000064475","361209529","0","1"]],"ts":"1646003672908","checksum":-1078074234}]}
1646003672.926687: {"arg":{"channel":"books-l2-tbt","instId":"ZEN-USDT"},"action":"update","data":[{"asks":[],"bids":[["32.48","21.522535","0","2"]],"ts":"1646003672916","checksum":-1995929992}]}
1646003672.94005: {"arg":{"channel":"books-l2-tbt","instId":"ZEN-USDT"},"action":"update","data":[{"asks":[["32.6","160.039629","0","4"]],"bids":[["32.45","72.081368","0","3"]],"ts":"1646003672927","checksum":1023643806}]}
1646003672.940104: {"arg":{"channel":"books-l2-tbt","instId":"ELON-USDT"},"action":"update","data":[{"asks":[["0.00000074594","159764443","0","2"],["0.0000011338","0","0","0"]],"bids":[],"ts":"1646003672928","checksum":-365564315}]}
1646003672.9491808: {"arg":{"channel":"books-l2-tbt","instId":"ZEN-USDT"},"action":"update","data":[{"asks":[],"bids":[["32.5","2.395966","0","2"]],"ts":"1646003672937","checksum":-351509915}]}
1646003672.949213: {"arg":{"channel":"books-l2-tbt","instId":"UNI-USD-SWAP"},"action":"update","data":[{"asks":[["9.626","260","0","1"]],"bids":[],"ts":"1646003672939","checksum":-1634182093}]}
1646003672.95238: {"arg":{"channel":"books-l2-tbt","instId":"ELON-USDT"},"action":"update","data":[{"asks":[["0.00000074594","281442512","0","4"],["0.00000074598","0","0","0"],["0.0000011338","129154981","0","1"]],"bids":[],"ts":"1646003672940","checksum":-1086888346}]}
1646003672.973972: {"arg":{"channel":"books-l2-tbt","instId":"ZEN-USDT"},"action":"update","data":[{"asks":[["32.7","0","0","0"],["44.2","0.120899","0","1"]],"bids":[],"ts":"1646003672948","checksum":1809882952}]}
1646003672.974027: {"arg":{"channel":"books-l2-tbt","instId":"ETH-USD-220325-8800-P"},"action":"update","data":[{"asks":[["2.5485","0","0","0"],["2.549","201","0","1"]],"bids":[],"ts":"1646003672952","checksum":957925562}]}
1646003672.9740522: {"arg":{"channel":"books-l2-tbt","instId":"ELON-USDT"},"action":"update","data":[{"asks":[["0.00000074594","385488452","0","5"],["0.00000074597","0","0","0"],["0.0000011372","6179288","0","1"]],"bids":[["0.00000074443","0","0","0"]],"ts":"1646003672951","checksum":1841101799}]}
1646003672.97408: {"arg":{"channel":"books-l2-tbt","instId":"ZEN-USDT"},"action":"update","data":[{"asks":[["32.55","2.285642","0","1"],["44.2","0","0","0"]],"bids":[["32.5","0.399716","0","1"]],"ts":"1646003672959","checksum":1662742687}]}
1646003672.995692: {"arg":{"channel":"books-l2-tbt","instId":"UNI-USD-SWAP"},"action":"update","data":[{"asks":[["9.645","773","0","4"],["9.647","2554","0","5"],["9.648","30","0","2"],["9.65","0","0","0"],["9.651","103","0","3"],["9.653","0","0","0"],["9.66","21","0","1"],["48.625","1","0","1"],["48.868","1","0","1"]],"bids":[],"ts":"1646003672982","checksum":1611091213}]}
1646003673.019978: {"arg":{"channel":"books-l2-tbt","instId":"UNI-USD-SWAP"},"action":"update","data":[{"asks":[["9.654","9245","0","1"],["48.868","0","0","0"]],"bids":[["9.585","528","0","3"]],"ts":"1646003673001","checksum":1733503188}]}
1646003673.020056: {"arg":{"channel":"books-l2-tbt","instId":"ELON-USDT"},"action":"update","data":[{"asks":[["0.00000074595","0","0","0"],["0.00000113812","12211658","0","1"]],"bids":[],"ts":"1646003673004","checksum":1616855021}]}
1646003673.0240052: {"arg":{"channel":"books-l2-tbt","instId":"PROPS-ETH"},"action":"update","data":[{"asks":[],"bids":[["0.00000167","345428.695106","0","2"]],"ts":"1646003673009","checksum":1700343347}]}
1646003673.0240488: {"arg":{"channel":"books-l2-tbt","instId":"UNI-USD-SWAP"},"action":"update","data":[{"asks":[["9.635","69","0","2"],["9.638","119","0","2"]],"bids":[["9.603","0","0","0"],["9.598","108","0","1"]],"ts":"1646003673011","checksum":-1339262806}]}
1646003673.0368798: {"arg":{"channel":"books-l2-tbt","instId":"UNI-USD-SWAP"},"action":"update","data":[{"asks":[],"bids":[["9.583","198","0","2"]],"ts":"1646003673022","checksum":805555352}]}
1646003673.036941: {"arg":{"channel":"books-l2-tbt","instId":"ZEN-USDT"},"action":"update","data":[{"asks":[["32.57","10.395773","0","3"]],"bids":[["32.51","0","0","0"]],"ts":"1646003673023","checksum":-430818687}]}
1646003673.039047: {"arg":{"channel":"books-l2-tbt","instId":"ELON-USDT"},"action":"update","data":[{"asks":[["0.00000074594","121678069","0","2"]],"bids":[],"ts":"1646003673025","checksum":1629085255}]}
1646003673.039105: {"arg":{"channel":"books-l2-tbt","instId":"ETH-USD-220624-20000-C"},"action":"update","data":[{"asks":[["0.003","505","0","1"]],"bids":[],"ts":"1646003673026","checksum":-200205248}]}
1646003673.041398: {"arg":{"channel":"books-l2-tbt","instId":"PROPS-ETH"},"action":"update","data":[{"asks":[],"bids":[["0.00000167","458118.359911","0","3"]],"ts":"1646003673029","checksum":1541228524}]}
1646003673.0444102: {"arg":{"channel":"books-l2-tbt","instId":"UNI-USD-SWAP"},"action":"update","data":[{"asks":[],"bids":[["9.611","646","0","2"]],"ts":"1646003673033","checksum":-50362097}]}
1646003673.0456011: {"arg":{"channel":"books-l2-tbt","instId":"ZEN-USDT"},"action":"update","data":[{"asks":[["33.16","4.24161","0","2"],["33.17","0","0","0"],["33.49","6.33","0","1"],["33.5","0.496261","0","2"],["33.82","16.19715","0","3"],["33.83","0","0","0"],["34.15","11.04","0","1"],["34.16","0","0","0"],["44.2","0.120899","0","1"]],"bids":[],"ts":"1646003673034","checksum":-430818687}]}
1646003673.051291: {"arg":{"channel":"books-l2-tbt","instId":"ETH-USD-220624-20000-C"},"action":"update","data":[{"asks":[["0.0025","1021","0","3"]],"bids":[],"ts":"1646003673037","checksum":-164019011}]}
1646003673.055062: {"arg":{"channel":"books-l2-tbt","instId":"UNI-USD-SWAP"},"action":"update","data":[{"asks":[["9.644","430","0","2"]],"bids":[["9.611","0","0","0"],["9.607","28","0","1"],["9.605","104","0","3"]],"ts":"1646003673042","checksum":-1419193538}]}
1646003673.05813: {"arg":{"channel":"books-l2-tbt","instId":"ZEN-USDT"},"action":"update","data":[{"asks":[],"bids":[["32.48","17.8359","0","1"],["32.45","71.581028","0","2"]],"ts":"1646003673045","checksum":-662466212}]}
1646003673.059937: {"arg":{"channel":"books-l2-tbt","instId":"ELON-USDT"},"action":"update","data":[{"asks":[["0.00000074598","152061613","0","2"],["0.00000113812","0","0","0"]],"bids":[],"ts":"1646003673047","checksum":-1386556454}]}
1646003673.0716732: {"arg":{"channel":"books-l2-tbt","instId":"UNI-USD-SWAP"},"action":"update","data":[{"asks":[["9.625","88","0","1"],["9.638","619","0","3"],["48.625","0","0","0"]],"bids":[["9.62","26","0","1"],["9.619","0","0","0"],["9.616","12","0","1"],["9.606","500","0","1"]],"ts":"1646003673054","checksum":591742739}]}
1646003673.076525: {"arg":{"channel":"books-l2-tbt","instId":"UNI-USD-SWAP"},"action":"update","data":[{"asks":[["9.632","247","0","2"],["9.634","0","0","0"],["48.625","1","0","1"]],"bids":[["9.615","53","0","1"],["9.598","0","0","0"],["9.596","16","0","1"],["9.594","206","0","2"],["9.593","108","0","1"],["9.589","321","0","2"]],"ts":"1646003673063","checksum":1922054053}]}
1646003673.076977: {"arg":{"channel":"books-l2-tbt","instId":"ZEN-USDT"},"action":"update","data":[{"asks":[],"bids":[["32.46","3.686635","0","1"]],"ts":"1646003673066","checksum":-1716615599}]}
1646003673.092344: {"arg":{"channel":"books-l2-tbt","instId":"UNI-USD-SWAP"},"action":"update","data":[{"asks":[["9.624","260","0","1"],["9.637","32","0","1"],["48.383","0","0","0"],["48.625","0","0","0"]],"bids":[["9.613","29","0","2"],["9.61","6","0","1"]],"ts":"1646003673076","checksum":-1838079688}]}
1646003673.092499: {"arg":{"channel":"books-l2-tbt","instId":"ZEN-USDT"},"action":"update","data":[{"asks":[["32.57","29.395773","0","4"],["32.59","0","0","0"],["44.22","2.271956","0","1"]],"bids":[["32.41","78.450858","0","2"]],"ts":"1646003673077","checksum":1866551575}]}
1646003673.106708: {"arg":{"channel":"books-l2-tbt","instId":"UNI-USD-SWAP"},"action":"update","data":[{"asks":[["9.632","673","0","4"],["9.637","1084","0","2"],["9.644","16","0","1"],["9.649","178","0","1"]],"bids":[["9.615","0","0","0"],["9.611","6","0","1"],["9.61","0","0","0"],["9.607","0","0","0"],["9.605","29","0","1"],["9.602","76","0","1"],["9.601","39","0","2"],["9.599","657","0","4"],["9.596","44","0","2"],["9.584","609","0","3"],["9.583","160","0","1"]],"ts":"1646003673087","checksum":1624276908}]}
1646003673.106854: {"arg":{"channel":"books-l2-tbt","instId":"ELON-USDT"},"action":"update","data":[{"asks":[["0.0000007468","0","0","0"],["0.00000113812","12211658","0","1"]],"bids":[],"ts":"1646003673089","checksum":-142517388}]}
1646003673.1071749: {"arg":{"channel":"books-l2-tbt","instId":"UNI-USD-SWAP"},"action":"update","data":[{"asks":[],"bids":[["9.615","3","0","1"],["9.608","0","0","0"]],"ts":"1646003673095","checksum":1545719681}]}
1646003673.116331: {"arg":{"channel":"books-l2-tbt","instId":"ETH-USD-220624-12000-P"},"action":"update","data":[{"asks":[["4.044","0","0","0"],["4.0445","201","0","1"]],"bids":[],"ts":"1646003673106","checksum":1491294271}]}
1646003673.1183438: {"arg":{"channel":"books-l2-tbt","instId":"UNI-USD-SWAP"},"action":"update","data":[{"asks":[["9.66","0","0","0"],["9.663","0","0","0"],["48.383","1","0","1"],["48.625","1","0","1"]],"bids":[["9.606","0","0","0"],["9.603","500","0","1"],["9.59","179","0","2"],["9.581","49","0","1"]],"ts":"1646003673107","checksum":1886348518}]}
1646003673.122179: {"arg":{"channel":"books-l2-tbt","instId":"ZEN-USDT"},"action":"update","data":[{"asks":[["32.65","113.847704","0","2"]],"bids":[["32.41","63.084348","0","1"]],"ts":"1646003673109","checksum":70000440}]}
1646003673.122268: {"arg":{"channel":"books-l2-tbt","instId":"ELON-USDT"},"action":"update","data":[{"asks":[["0.00000074598","104045940","0","1"]],"bids":[],"ts":"1646003673112","checksum":1414508456}]}
1646003673.127888: {"arg":{"channel":"books-l2-tbt","instId":"UNI-USD-SWAP"},"action":"update","data":[{"asks":[["9.636","100","0","1"],["9.637","1052","0","1"],["9.65","225","0","1"],["9.652","0","0","0"],["9.657","0","0","0"],["9.659","1006","0","2"],["9.664","100","0","2"],["9.666","72","0","1"],["9.669","0","0","0"],["9.711","846","0","1"],["9.723","0","0","0"],["9.764","846","0","1"],["9.779","0","0","0"]],"bids":[["9.62","0","0","0"],["9.611","0","0","0"],["9.61","6","0","1"],["9.599","641","0","3"],["9.595","0","0","0"],["9.585","464","0","2"],["9.584","545","0","2"],["9.571","0","0","0"],["9.568","846","0","1"],["9.517","846","0","1"],["9.514","0","0","0"],["9.464","846","0","1"],["9.458","0","0","0"]],"ts":"1646003673117","checksum":1708703095}]}
1646003673.139572: {"arg":{"channel":"books-l2-tbt","instId":"UNI-USD-SWAP"},"action":"update","data":[{"asks":[["9.631","3","0","1"],["9.664","64","0","1"],["48.625","0","0","0"]],"bids":[["9.617","0","0","0"]],"ts":"1646003673128","checksum":-1369246940}]}
1646003673.147255: {"arg":{"channel":"books-l2-tbt","instId":"ELON-USDT"},"action":"update","data":[{"asks":[["0.00000074598","0","0","0"],["0.00000113853","6145556","0","1"]],"bids":[],"ts":"1646003673132","checksum":-920222878}]}
1646003673.1494882: {"arg":{"channel":"books-l2-tbt","instId":"UNI-USD-SWAP"},"action":"update","data":[{"asks":[["9.635","73","0","3"],["9.636","0","0","0"],["9.646","16","0","1"]],"bids":[["9.614","169","0","2"]],"ts":"1646003673138","checksum":-297143012}]}
1646003673.156088: {"arg":{"channel":"books-l2-tbt","instId":"ETH-USD-220624-20000-C"},"action":"update","data":[{"asks":[["0.0025","520","0","2"],["0.003","1006","0","2"]],"bids":[],"ts":"1646003673142","checksum":-1719318134}]}
1646003673.164544: {"arg":{"channel":"books-l2-tbt","instId":"UNI-USD-SWAP"},"action":"update","data":[{"asks":[["9.625","0","0","0"],["9.626","460","0","2"],["9.666","0","0","0"],["48.625","1","0","1"],["48.868","1","0","1"]],"bids":[["9.616","22","0","1"],["9.613","131","0","3"],["9.594","222","0","3"],["9.577","289","0","2"]],"ts":"1646003673149","checksum":908091519}]}
1646003673.164721: {"arg":{"channel":"books-l2-tbt","instId":"ELON-USDT"},"action":"update","data":[{"asks":[["0.00000074594","0","0","0"],["0.00000074598","52357697","0","1"]],"bids":[],"ts":"1646003673151","checksum":-1261793318}]}
1646003673.170712: {"arg":{"channel":"books-l2-tbt","instId":"UNI-USD-SWAP"},"action":"update","data":[{"asks":[["9.632","672","0","3"],["9.635","69","0","2"],["9.663","16","0","1"],["9.671","0","0","0"]],"bids":[],"ts":"1646003673158","checksum":-692639391}]}
1646003673.171408: {"arg":{"channel":"books-l2-tbt","instId":"ZEN-USDT"},"action":"update","data":[{"asks":[],"bids":[["32.15","309.781042","0","2"],["32.14","1.55","0","1"],["31.7","0","0","0"],["31.69","8.724515","0","3"],["31.26","0","0","0"],["31.25","10.623961","0","2"],["30.83","0","0","0"],["30.82","11.15","0","1"],["30.4","26.622301","0","2"],["30.39","14.44","0","1"]],"ts":"1646003673160","checksum":-1626198429}]}
1646003673.176197: {"arg":{"channel":"books-l2-tbt","instId":"ELON-USDT"},"action":"update","data":[{"asks":[["0.0000007473","0","0","0"],["0.00000113879","5262112","0","1"]],"bids":[],"ts":"1646003673162","checksum":873340689}]}
1646003673.180568: {"arg":{"channel":"books-l2-tbt","instId":"UNI-USD-SWAP"},"action":"update","data":[{"asks":[["9.655","178","0","1"],["9.689","0","0","0"],["49.113","1","0","1"]],"bids":[["9.578","64","0","1"]],"ts":"1646003673167","checksum":77369895}]}
1646003673.1807091: {"arg":{"channel":"books-l2-tbt","instId":"BTC-USD-220325-40000-C"},"action":"update","data":[{"asks":[],"bids":[["0.038","0","0","0"],["0.0375","100","0","1"]],"ts":"1646003673169","checksum":-1742888088}]}
1646003673.185712: {"arg":{"channel":"books-l2-tbt","instId":"ELON-USDT"},"action":"update","data":[{"asks":[["0.00000074593","445226872","0","1"],["0.00000113879","0","0","0"]],"bids":[],"ts":"1646003673173","checksum":-2035240659}]}
1646003673.198454: {"arg":{"channel":"books-l2-tbt","instId":"UNI-USD-SWAP"},"action":"update","data":[{"asks":[],"bids":[["9.606","6","0","1"]],"ts":"1646003673180","checksum":-213663574}]}
1646003673.200712: {"arg":{"channel":"books-l2-tbt","instId":"UNI-USD-SWAP"},"action":"update","data":[{"asks":[["9.649","242","0","2"],["9.682","160","0","1"],["49.113","0","0","0"]],"bids":[["9.596","28","0","1"]],"ts":"1646003673189","checksum":-111185710}]}
1646003673.202938: {"arg":{"channel":"books-l2-tbt","instId":"ZEN-USDT"},"action":"update","data":[{"asks":[],"bids":[["31.89","4.713961","0","2"],["31.85","88.056754","0","2"]],"ts":"1646003673191","checksum":-1626198429}]}
1646003673.2066581: {"arg":{"channel":"books-l2-tbt","instId":"ELON-USDT"},"action":"update","data":[{"asks":[["0.00000074592","111748770","0","1"],["0.00000074734","3335553289","0","1"],["0.00000113812","0","0","0"],["0.00000113853","0","0","0"]],"bids":[],"ts":"1646003673192","checksum":-400311672}]}
1646003673.217885: {"arg":{"channel":"books-l2-tbt","instId":"UNI-USD-SWAP"},"action":"update","data":[{"asks":[["9.635","79","0","3"]],"bids":[],"ts":"1646003673200","checksum":-132741828}]}
1646003673.2180061: {"arg":{"channel":"books-l2-tbt","instId":"ZEN-USDT"},"action":"update","data":[{"asks":[["32.83","1.52","0","1"],["32.84","0","0","0"]],"bids":[["32.21","0","0","0"],["32.17","1.55","0","1"],["31.58","0","0","0"],["31.54","6.61","0","1"],["31.27","2.272752","0","1"],["31.23","9.641052","0","2"],["30.96","0","0","0"],["30.92","11.76","0","1"]],"ts":"1646003673200","checksum":1518336052}]}
1646003673.222049: {"arg":{"channel":"books-l2-tbt","instId":"UNI-USD-SWAP"},"action":"update","data":[{"asks":[["9.623","2","0","1"],["48.868","0","0","0"]],"bids":[["9.615","0","0","0"]],"ts":"1646003673210","checksum":1283490244}]}
1646003673.2251031: {"arg":{"channel":"books-l2-tbt","instId":"ELON-USDT"},"action":"update","data":[{"asks":[],"bids":[["0.0000007445","219861835","0","1"]],"ts":"1646003673214","checksum":905733693}]}
1646003673.2381818: {"arg":{"channel":"books-l2-tbt","instId":"UNI-USD-SWAP"},"action":"update","data":[{"asks":[],"bids":[["9.591","16","0","1"]],"ts":"1646003673220","checksum":-345632347}]}
1646003673.244163: {"arg":{"channel":"books-l2-tbt","instId":"UNI-USD-SWAP"},"action":"update","data":[{"asks":[],"bids":[["9.616","0","0","0"],["9.615","22","0","1"]],"ts":"1646003673231","checksum":-71028606}]}
1646003673.249578: {"arg":{"channel":"books-l2-tbt","instId":"ELON-USDT"},"action":"update","data":[{"asks":[],"bids":[["0.000000739","16389352866","0","4"]],"ts":"1646003673235","checksum":445602938}]}
1646003673.253522: {"arg":{"channel":"books-l2-tbt","instId":"UNI-USD-SWAP"},"action":"update","data":[{"asks":[["9.623","90","0","2"],["9.631","0","0","0"],["48.868","1","0","1"]],"bids":[["9.608","12","0","1"]],"ts":"1646003673242","checksum":-2107041398}]}
1646003673.256949: {"arg":{"channel":"books-l2-tbt","instId":"ETH-USD-220624-20000-C"},"action":"update","data":[{"asks":[["0.002","20","0","1"],["0.0025","500","0","1"]],"bids":[],"ts":"1646003673246","checksum":-2042738330}]}
1646003673.2621388: {"arg":{"channel":"books-l2-tbt","instId":"UNI-USD-SWAP"},"action":"update","data":[{"asks":[],"bids":[["9.611","5","0","1"],["9.61","0","0","0"]],"ts":"1646003673251","checksum":-1657110915}]}
1646003673.2729862: {"arg":{"channel":"books-l2-tbt","instId":"ELON-USDT"},"action":"update","data":[{"asks":[],"bids":[["0.00000073901","130000000","0","1"],["0.00000056001","30433622","0","1"]],"ts":"1646003673257","checksum":-1601920863}]}
1646003673.273071: {"arg":{"channel":"books-l2-tbt","instId":"UNI-USD-SWAP"},"action":"update","data":[{"asks":[["9.622","260","0","1"],["9.626","200","0","1"],["48.868","0","0","0"]],"bids":[["9.613","184","0","4"]],"ts":"1646003673261","checksum":1474828852}]}
1646003673.28074: {"arg":{"channel":"books-l2-tbt","instId":"BTC-USD-220325-40000-C"},"action":"update","data":[{"asks":[],"bids":[["0.038","100","0","1"],["0.0375","0","0","0"]],"ts":"1646003673263","checksum":-15672430}]}
1646003673.2850308: {"arg":{"channel":"books-l2-tbt","instId":"UNI-USD-SWAP"},"action":"update","data":[{"asks":[],"bids":[["9.611","0","0","0"],["9.61","6","0","1"]],"ts":"1646003673273","checksum":-1889538128}]}
1646003673.287868: {"arg":{"channel":"books-l2-tbt","instId":"ELON-USDT"},"action":"update","data":[{"asks":[["0.00000074592","159764443","0","2"]],"bids":[],"ts":"1646003673277","checksum":1991938290}]}
1646003673.2946718: {"arg":{"channel":"books-l2-tbt","instId":"UNI-USD-SWAP"},"action":"update","data":[{"asks":[["9.629","12","0","1"],["9.642","168","0","2"],["48.625","0","0","0"]],"bids":[["9.606","0","0","0"],["9.581","9588","0","2"],["9.572","0","0","0"]],"ts":"1646003673282","checksum":-984974203}]}
1646003673.311414: {"arg":{"channel":"books-l2-tbt","instId":"UNI-USD-SWAP"},"action":"update","data":[{"asks":[],"bids":[["9.611","5","0","1"],["9.61","0","0","0"],["9.579","43","0","1"]],"ts":"1646003673292","checksum":793218121}]}
1646003673.311546: {"arg":{"channel":"books-l2-tbt","instId":"PROPS-ETH"},"action":"update","data":[{"asks":[["0.00000176","8509.14847626","0","2"],["0.00000178","0","0","0"],["0.00000183","1477.62960917","0","1"],["0.00000184","718.33109576","0","1"]],"bids":[["0.00000161","0","0","0"],["0.0000016","10722.7214832","0","1"]],"ts":"1646003673293","checksum":793266915}]}
1646003673.311645: {"arg":{"channel":"books-l2-tbt","instId":"ZEN-USDT"},"action":"update","data":[{"asks":[["32.65","13.847704","0","1"]],"bids":[],"ts":"1646003673296","checksum":540156196}]}
1646003673.316858: {"arg":{"channel":"books-l2-tbt","instId":"UNI-USD-SWAP"},"action":"update","data":[{"asks":[["9.632","832","0","4"]],"bids":[["9.569","4","0","1"]],"ts":"1646003673302","checksum":817329183}]}
1646003673.322231: {"arg":{"channel":"books-l2-tbt","instId":"ELON-USDT"},"action":"update","data":[{"asks":[["0.00000074597","78733624","0","1"],["0.0000011372","0","0","0"]],"bids":[],"ts":"1646003673310","checksum":116291502}]}
1646003673.3238442: {"arg":{"channel":"books-l2-tbt","instId":"UNI-USD-SWAP"},"action":"update","data":[{"asks":[["9.623","88","0","1"],["9.67","0","0","0"],["48.625","1","0","1"]],"bids":[["9.611","0","0","0"],["9.61","6","0","1"],["9.584","35","0","1"],["9.573","0","0","0"]],"ts":"1646003673313","checksum":-908150202}]}
1646003673.3334541: {"arg":{"channel":"books-l2-tbt","instId":"ELON-USDT"},"action":"update","data":[{"asks":[["0.00000074592","263810383","0","3"]],"bids":[],"ts":"1646003673321","checksum":-1907123816}]}
1646003673.34378: {"arg":{"channel":"books-l2-tbt","instId":"UNI-USD-SWAP"},"action":"update","data":[{"asks":[],"bids":[["9.588","129","0","2"]],"ts":"1646003673327","checksum":968654743}]}
1646003673.349906: {"arg":{"channel":"books-l2-tbt","instId":"UNI-USD-SWAP"},"action":"update","data":[{"asks":[["9.661","510","0","1"],["48.625","0","0","0"]],"bids":[["9.615","282","0","2"],["9.611","5","0","1"],["9.61","0","0","0"],["9.609","2","0","1"]],"ts":"1646003673335","checksum":248193670}]}
1646003673.35972: {"arg":{"channel":"books-l2-tbt","instId":"UNI-USD-SWAP"},"action":"update","data":[{"asks":[["9.642","191","0","3"],["9.651","79","0","2"]],"bids":[["9.602","99","0","2"],["9.601","16","0","1"],["9.6","24","0","1"],["9.599","620","0","2"],["9.597","27","0","1"],["9.596","0","0","0"],["9.575","510","0","1"]],"ts":"1646003673347","checksum":784508704}]}
1646003673.36313: {"arg":{"channel":"books-l2-tbt","instId":"ELON-USDT"},"action":"update","data":[{"asks":[["0.0000007504","15523409062","0","4"]],"bids":[],"ts":"1646003673350","checksum":-810908643}]}
1646003673.374899: {"arg":{"channel":"books-l2-tbt","instId":"ELON-USDT"},"action":"update","data":[{"asks":[["0.00000074592","385488452","0","5"],["0.00000074598","0","0","0"],["0.0000011372","6179288","0","1"]],"bids":[],"ts":"1646003673361","checksum":2085357298}]}
1646003673.3749912: {"arg":{"channel":"books-l2-tbt","instId":"UNI-USD-SWAP"},"action":"update","data":[{"asks":[],"bids":[["9.611","0","0","0"],["9.61","6","0","1"]],"ts":"1646003673361","checksum":-2046159288}]}
1646003673.382408: {"arg":{"channel":"books-l2-tbt","instId":"ELON-USDT"},"action":"update","data":[{"asks":[],"bids":[["0.00000074451","184440410","0","1"]],"ts":"1646003673370","checksum":-1952996085}]}
1646003673.389162: {"arg":{"channel":"books-l2-tbt","instId":"UNI-USD-SWAP"},"action":"update","data":[{"asks":[["9.621","1","0","1"],["48.383","0","0","0"]],"bids":[],"ts":"1646003673376","checksum":-603767231}]}
1646003673.398686: {"arg":{"channel":"books-l2-tbt","instId":"UNI-USD-SWAP"},"action":"update","data":[{"asks":[["9.66","28","0","1"],["48.143","0","0","0"]],"bids":[],"ts":"1646003673387","checksum":-603767231}]}
1646003673.413834: {"arg":{"channel":"books-l2-tbt","instId":"UNI-USD-SWAP"},"action":"update","data":[{"asks":[["9.623","0","0","0"],["9.641","45","0","1"],["9.66","69","0","2"],["48.143","1","0","1"]],"bids":[],"ts":"1646003673397","checksum":-1065305901}]}
1646003673.418116: {"arg":{"channel":"books-l2-tbt","instId":"ELON-USDT"},"action":"update","data":[{"asks":[["0.00000074593","0","0","0"],["0.00000113812","12211658","0","1"]],"bids":[],"ts":"1646003673402","checksum":1789298734}]}
1646003673.4277482: {"arg":{"channel":"books-l2-tbt","instId":"ELON-USDT"},"action":"update","data":[{"asks":[],"bids":[["0.0000007282","0","0","0"],["0.00000069607","381090506","0","1"],["0.00000068215","421651076","0","1"],["0.00000066851","237507694","0","1"],["0.00000065514","378449324","0","1"],["0.00000064475","0","0","0"]],"ts":"1646003673413","checksum":1789298734}]}
1646003673.4382432: {"arg":{"channel":"books-l2-tbt","instId":"UNI-USD-SWAP"},"action":"update","data":[{"asks":[["9.624","0","0","0"],["48.383","1","0","1"]],"bids":[],"ts":"1646003673420","checksum":651868127}]}
1646003673.4490502: {"arg":{"channel":"books-l2-tbt","instId":"ELON-USDT"},"action":"update","data":[{"asks":[],"bids":[["0.00000074434","0","0","0"]],"ts":"1646003673434","checksum":184091769}]}
1646003673.45385: {"arg":{"channel":"books-l2-tbt","instId":"UNI-USD-SWAP"},"action":"update","data":[{"asks":[["9.658","0","0","0"],["48.625","1","0","1"]],"bids":[["9.584","0","0","0"]],"ts":"1646003673440","checksum":429101809}]}
1646003673.461838: {"arg":{"channel":"books-l2-tbt","instId":"UNI-USD-SWAP"},"action":"update","data":[{"asks":[["9.623","88","0","1"],["48.625","0","0","0"]],"bids":[["9.58","35","0","1"]],"ts":"1646003673450","checksum":-631472485}]}
1646003673.4659882: {"arg":{"channel":"books-l2-tbt","instId":"ZEN-USDT"},"action":"update","data":[{"asks":[["32.62","0","0","0"],["44.23","2.713011","0","1"]],"bids":[["32.42","34.507971","0","2"]],"ts":"1646003673451","checksum":279984084}]}
1646003673.473994: {"arg":{"channel":"books-l2-tbt","instId":"UNI-USD-SWAP"},"action":"update","data":[{"asks":[["9.635","73","0","3"]],"bids":[],"ts":"1646003673460","checksum":300007621}]}
1646003673.4741042: {"arg":{"channel":"books-l2-tbt","instId":"ZEN-USDT"},"action":"update","data":[{"asks":[["32.7","100","0","1"],["44.23","0","0","0"]],"bids":[],"ts":"1646003673462","checksum":-1809394259}]}
1646003673.485632: {"arg":{"channel":"books-l2-tbt","instId":"UNI-USD-SWAP"},"action":"update","data":[{"asks":[["9.635","79","0","3"]],"bids":[],"ts":"1646003673470","checksum":-631472485}]}
1646003673.493435: {"arg":{"channel":"books-l2-tbt","instId":"UNI-USD-SWAP"},"action":"update","data":[{"asks":[["9.654","9280","0","2"]],"bids":[],"ts":"1646003673481","checksum":-1475353350}]}
1646003673.501937: {"arg":{"channel":"books-l2-tbt","instId":"UNI-USD-SWAP"},"action":"update","data":[{"asks":[["9.626","0","0","0"],["48.625","1","0","1"]],"bids":[],"ts":"1646003673490","checksum":1524035431}]}
1646003673.532567: {"arg":{"channel":"books-l2-tbt","instId":"UNI-USD-SWAP"},"action":"update","data":[{"asks":[],"bids":[["9.611","2","0","1"]],"ts":"1646003673521","checksum":-2112210643}]}
1646003673.546318: {"arg":{"channel":"books-l2-tbt","instId":"UNI-USD-SWAP"},"action":"update","data":[{"asks":[["9.628","3","0","1"],["48.625","0","0","0"]],"bids":[],"ts":"1646003673535","checksum":1979661643}]}
1646003673.559799: {"arg":{"channel":"books-l2-tbt","instId":"UNI-USD-SWAP"},"action":"update","data":[{"asks":[],"bids":[["9.613","167","0","3"],["9.609","0","0","0"]],"ts":"1646003673542","checksum":736254891}]}
1646003673.572103: {"arg":{"channel":"books-l2-tbt","instId":"UNI-USD-SWAP"},"action":"update","data":[{"asks":[["9.63","246","0","1"],["9.632","586","0","3"],["48.383","0","0","0"]],"bids":[["9.612","26","0","1"]],"ts":"1646003673557","checksum":343380390}]}
1646003673.579272: {"arg":{"channel":"books-l2-tbt","instId":"ELON-USDT"},"action":"update","data":[{"asks":[["0.00000074591","445226872","0","1"],["0.00000113812","0","0","0"]],"bids":[],"ts":"1646003673567","checksum":1327232961}]}
1646003673.580564: {"arg":{"channel":"books-l2-tbt","instId":"UNI-USD-SWAP"},"action":"update","data":[{"asks":[["9.621","0","0","0"],["48.383","1","0","1"]],"bids":[],"ts":"1646003673569","checksum":282497668}]}
1646003673.594454: {"arg":{"channel":"books-l2-tbt","instId":"UNI-USD-SWAP"},"action":"update","data":[{"asks":[],"bids":[["9.611","0","0","0"],["9.609","4","0","1"]],"ts":"1646003673582","checksum":250650593}]}
1646003673.595008: {"arg":{"channel":"books-l2-tbt","instId":"ZEN-USDT"},"action":"update","data":[{"asks":[],"bids":[],"ts":"1646003673584","checksum":-1809394259}]}
1646003673.608053: {"arg":{"channel":"books-l2-tbt","instId":"UNI-USD-SWAP"},"action":"update","data":[{"asks":[],"bids":[["9.601","41","0","2"]],"ts":"1646003673593","checksum":1831114222}]}
1646003673.639672: {"arg":{"channel":"books-l2-tbt","instId":"ZEN-USDT"},"action":"update","data":[{"asks":[],"bids":[["32.21","1.55","0","1"],["32.17","0","0","0"],["31.89","8.773961","0","3"],["31.85","83.986754","0","1"],["31.58","6.59","0","1"],["31.54","0","0","0"],["31.27","11.422752","0","2"],["31.23","0.471052","0","1"],["30.96","11.73","0","1"],["30.92","0","0","0"]],"ts":"1646003673628","checksum":588845785}]}
1646003673.6446102: {"arg":{"channel":"books-l2-tbt","instId":"ELON-USDT"},"action":"update","data":[{"asks":[["0.00000074597","0","0","0"],["0.00000113812","12211658","0","1"]],"bids":[],"ts":"1646003673630","checksum":983317524}]}
1646003673.656894: {"arg":{"channel":"books-l2-tbt","instId":"UNI-USD-SWAP"},"action":"update","data":[{"asks":[["9.63","192","0","1"]],"bids":[["9.609","0","0","0"]],"ts":"1646003673644","checksum":1431357454}]}
1646003673.670733: {"arg":{"channel":"books-l2-tbt","instId":"UNI-USD-SWAP"},"action":"update","data":[{"asks":[["9.642","168","0","2"],["9.651","107","0","3"]],"bids":[["9.603","526","0","2"],["9.602","76","0","1"],["9.601","67","0","3"],["9.6","0","0","0"],["9.598","24","0","1"],["9.597","0","0","0"]],"ts":"1646003673656","checksum":-1187582874}]}
1646003673.6778939: {"arg":{"channel":"books-l2-tbt","instId":"ELON-USDT"},"action":"update","data":[{"asks":[],"bids":[["0.0000007445","0","0","0"]],"ts":"1646003673662","checksum":-1031546078}]}
1646003673.6965: {"arg":{"channel":"books-l2-tbt","instId":"UNI-USD-SWAP"},"action":"update","data":[{"asks":[],"bids":[["9.611","1","0","1"]],"ts":"1646003673676","checksum":1665809274}]}
1646003673.7224178: {"arg":{"channel":"books-l2-tbt","instId":"ZEN-USDT"},"action":"update","data":[{"asks":[],"bids":[["32.44","96.88977","0","3"]],"ts":"1646003673701","checksum":-476383221}]}
1646003673.73805: {"arg":{"channel":"books-l2-tbt","instId":"ELON-USDT"},"action":"update","data":[{"asks":[],"bids":[["0.00000074434","184440410","0","1"]],"ts":"1646003673714","checksum":-1193586374}]}
1646003673.760958: {"arg":{"channel":"books-l2-tbt","instId":"ELON-USDT"},"action":"update","data":[{"asks":[["0.00000074599","0","0","0"],["0.00000113853","6145556","0","1"]],"bids":[],"ts":"1646003673748","checksum":1947759100}]}
1646003673.770145: {"arg":{"channel":"books-l2-tbt","instId":"UNI-USD-SWAP"},"action":"update","data":[{"asks":[["9.63","0","0","0"],["9.644","37","0","2"],["9.645","748","0","3"],["9.647","2576","0","6"],["9.648","1","0","1"],["9.65","252","0","2"],["9.651","79","0","2"],["48.625","1","0","1"]],"bids":[],"ts":"1646003673758","checksum":-145439055}]}
1646003673.776948: {"arg":{"channel":"books-l2-tbt","instId":"ZEN-USDT"},"action":"update","data":[{"asks":[["32.6","195.999165","0","5"]],"bids":[["32.41","99.043884","0","2"]],"ts":"1646003673766","checksum":-800767064}]}
1646003673.776982: {"arg":{"channel":"books-l2-tbt","instId":"UNI-USD-SWAP"},"action":"update","data":[{"asks":[["9.629","204","0","2"]],"bids":[],"ts":"1646003673766","checksum":-1239698056}]}
1646003673.780252: {"arg":{"channel":"books-l2-tbt","instId":"ELON-USDT"},"action":"update","data":[{"asks":[],"bids":[["0.00000074451","0","0","0"]],"ts":"1646003673768","checksum":-975126181}]}
1646003673.794566: {"arg":{"channel":"books-l2-tbt","instId":"UNI-USD-SWAP"},"action":"update","data":[{"asks":[["9.622","348","0","2"],["9.623","0","0","0"],["9.632","619","0","4"],["9.633","21","0","2"],["9.635","11","0","1"],["48.868","1","0","1"]],"bids":[],"ts":"1646003673777","checksum":1747470486}]}
1646003673.8059762: {"arg":{"channel":"books-l2-tbt","instId":"PROPS-ETH"},"action":"update","data":[{"asks":[["0.00000176","7518.11950204","0","1"],["0.00000178","1188.24908533","0","1"],["0.00000183","0","0","0"],["0.00000184","0","0","0"],["0.00000187","1496.78314607","0","1"]],"bids":[["0.00000161","8961.24657548","0","1"],["0.0000016","0","0","0"]],"ts":"1646003673793","checksum":1888956168}]}
1646003673.823285: {"arg":{"channel":"books-l2-tbt","instId":"UNI-USD-SWAP"},"action":"update","data":[{"asks":[["9.632","586","0","3"],["9.634","64","0","1"],["48.868","0","0","0"]],"bids":[],"ts":"1646003673808","checksum":1578334697}]}
1646003673.8234282: {"arg":{"channel":"books-l2-tbt","instId":"ELON-USDT"},"action":"update","data":[{"asks":[["0.00000074591","526402122","0","2"]],"bids":[["0.00000072648","7354766269","0","1"]],"ts":"1646003673810","checksum":-1845792007}]}
1646003673.8522398: {"arg":{"channel":"books-l2-tbt","instId":"UNI-USD-SWAP"},"action":"update","data":[{"asks":[["9.633","18","0","1"]],"bids":[],"ts":"1646003673840","checksum":538490101}]}
1646003673.855073: {"arg":{"channel":"books-l2-tbt","instId":"ELON-USDT"},"action":"update","data":[{"asks":[["0.0000007459","52357697","0","1"],["0.00000113853","0","0","0"]],"bids":[],"ts":"1646003673842","checksum":136381300}]}
1646003673.8720908: {"arg":{"channel":"books-l2-tbt","instId":"ZEN-USDT"},"action":"update","data":[{"asks":[],"bids":[["32.47","51","0","1"]],"ts":"1646003673860","checksum":-299706511}]}
1646003673.885258: {"arg":{"channel":"books-l2-tbt","instId":"UNI-USD-SWAP"},"action":"update","data":[{"asks":[],"bids":[["9.614","109","0","1"],["9.613","114","0","2"]],"ts":"1646003673873","checksum":1631818188}]}
1646003673.885386: {"arg":{"channel":"books-l2-tbt","instId":"BTC-USD-220325-40000-C"},"action":"update","data":[{"asks":[],"bids":[["0.038","0","0","0"],["0.0375","100","0","1"]],"ts":"1646003673873","checksum":-1742888088}]}
1646003673.885449: {"arg":{"channel":"books-l2-tbt","instId":"ELON-USDT"},"action":"update","data":[{"asks":[["0.00000074592","121678069","0","2"]],"bids":[],"ts":"1646003673873","checksum":1004160773}]}
1646003673.899731: {"arg":{"channel":"books-l2-tbt","instId":"UNI-USD-SWAP"},"action":"update","data":[{"asks":[["9.643","22","0","1"],["9.644","16","0","1"],["9.646","45","0","2"],["9.647","2554","0","5"],["9.649","268","0","3"],["9.65","225","0","1"],["48.625","0","0","0"]],"bids":[["9.612","79","0","2"],["9.603","500","0","1"],["9.602","99","0","2"],["9.601","41","0","2"],["9.6","21","0","1"],["9.598","0","0","0"],["9.597","25","0","1"]],"ts":"1646003673885","checksum":1358577606}]}
1646003673.907189: {"arg":{"channel":"books-l2-tbt","instId":"ELON-USDT"},"action":"update","data":[{"asks":[["0.00000074592","0","0","0"],["0.00000113853","6145556","0","1"]],"bids":[],"ts":"1646003673895","checksum":182928673}]}
1646003673.9171112: {"arg":{"channel":"books-l2-tbt","instId":"ELON-USDT"},"action":"update","data":[{"asks":[["0.00000074589","445226872","0","1"],["0.00000113853","0","0","0"]],"bids":[],"ts":"1646003673906","checksum":1372612008}]}
1646003673.926665: {"arg":{"channel":"books-l2-tbt","instId":"ELON-USDT"},"action":"update","data":[{"asks":[],"bids":[["0.00000069607","0","0","0"],["0.00000068215","0","0","0"],["0.00000066851","0","0","0"],["0.00000065514","0","0","0"],["0.00000064198","396423143","0","1"]],"ts":"1646003673916","checksum":1372612008}]}
1646003673.9469922: {"arg":{"channel":"books-l2-tbt","instId":"UNI-USD-SWAP"},"action":"update","data":[{"asks":[["9.643","72","0","2"],["9.644","0","0","0"],["48.625","1","0","1"]],"bids":[],"ts":"1646003673936","checksum":-1645662854}]}
1646003673.95796: {"arg":{"channel":"books-l2-tbt","instId":"UNI-USD-SWAP"},"action":"update","data":[{"asks":[["9.639","16","0","1"],["9.643","22","0","1"],["48.625","0","0","0"]],"bids":[],"ts":"1646003673945","checksum":-562920650}]}
1646003673.967453: {"arg":{"channel":"books-l2-tbt","instId":"ELON-USDT"},"action":"update","data":[{"asks":[["0.00000074588","104045940","0","1"],["0.00000113812","0","0","0"]],"bids":[["0.000000738","0","0","0"]],"ts":"1646003673955","checksum":2123051341}]}
1646003673.974945: {"arg":{"channel":"books-l2-tbt","instId":"ZEN-USDT"},"action":"update","data":[{"asks":[["32.89","1.51","0","1"],["32.9","60","0","1"],["33.35","4.52","0","1"],["33.36","0","0","0"],["33.81","7.48","0","1"],["33.82","8.71715","0","2"],["34.28","10.410156","0","2"],["34.29","0","0","0"],["34.75","13.28","0","1"],["34.77","0","0","0"],["44.22","0","0","0"]],"bids":[],"ts":"1646003673962","checksum":133438605}]}
1646003673.9802601: {"arg":{"channel":"books-l2-tbt","instId":"PROPS-ETH"},"action":"update","data":[{"asks":[],"bids":[["0.00000167","285404.012358","0","2"]],"ts":"1646003673969","checksum":97763754}]}
1646003673.98653: {"arg":{"channel":"books-l2-tbt","instId":"BTC-USD-220325-40000-C"},"action":"update","data":[{"asks":[],"bids":[["0.038","100","0","1"],["0.0375","0","0","0"]],"ts":"1646003673976","checksum":-15672430}]}
1646003673.9869912: {"arg":{"channel":"books-l2-tbt","instId":"ELON-USDT"},"action":"update","data":[{"asks":[["0.00000074591","81175250","0","1"]],"bids":[["0.00000074255","0","0","0"]],"ts":"1646003673976","checksum":1007997716}]}
1646003673.994147: {"arg":{"channel":"books-l2-tbt","instId":"ZEN-USDT"},"action":"update","data":[{"asks":[["33.15","3.94","0","1"],["33.16","0.30161","0","1"],["33.81","16.18","0","2"],["33.82","0.01715","0","1"],["44.2","0","0","0"]],"bids":[["32.21","0","0","0"],["32.2","1.55","0","1"],["31.89","4.713961","0","2"],["31.88","11.64","0","3"],["31.58","0","0","0"],["31.57","11.643385","0","3"],["30.96","0","0","0"],["30.95","11.73","0","1"]],"ts":"1646003673983","checksum":2034057616}]}
1646003673.999646: {"arg":{"channel":"books-l2-tbt","instId":"ETH-USD-220325-8800-P"},"action":"update","data":[{"asks":[["2.549","0","0","0"],["2.5495","201","0","1"]],"bids":[],"ts":"1646003673989","checksum":-181733380}]}
1646003674.005207: {"arg":{"channel":"books-l2-tbt","instId":"ZEN-USDT"},"action":"update","data":[{"asks":[["33.48","6.450899","0","2"],["33.49","0","0","0"],["34.14","11.04","0","1"],["34.15","0","0","0"],["44.2","0.120899","0","1"]],"bids":[["31.27","2.272752","0","1"],["31.26","9.15","0","1"]],"ts":"1646003673992","checksum":2034057616}]}
1646003674.0053172: {"arg":{"channel":"books-l2-tbt","instId":"ELON-USDT"},"action":"update","data":[{"asks":[["0.00000074588","215794710","0","2"],["0.0000007459","0","0","0"],["0.00000113812","12211658","0","1"]],"bids":[["0.00000074434","681011386","0","2"]],"ts":"1646003673994","checksum":-749465337}]}
1646003674.032971: {"arg":{"channel":"books-l2-tbt","instId":"UNI-USD-SWAP"},"action":"update","data":[{"asks":[["9.636","146","0","1"],["48.383","0","0","0"]],"bids":[],"ts":"1646003674020","checksum":-502248543}]}
1646003674.079958: {"arg":{"channel":"books-l2-tbt","instId":"ELON-USDT"},"action":"update","data":[{"asks":[["0.00000074587","445226872","0","1"],["0.00000113812","0","0","0"]],"bids":[["0.000000739","17071352866","0","5"]],"ts":"1646003674068","checksum":151510300}]}
1646003674.10127: {"arg":{"channel":"books-l2-tbt","instId":"ELON-USDT"},"action":"update","data":[{"asks":[["0.00000074586","48015673","0","1"],["0.00000074588","0","0","0"]],"bids":[["0.00000073901","160433622","0","2"],["0.000000735","5920364060","0","3"],["0.000000733","1300000000","0","2"],["0.00000056001","0","0","0"]],"ts":"1646003674089","checksum":740006898}]}
1646003674.101365: {"arg":{"channel":"books-l2-tbt","instId":"UNI-USD-SWAP"},"action":"update","data":[{"asks":[["9.642","196","0","3"],["9.643","0","0","0"],["9.645","776","0","4"],["9.646","16","0","1"],["9.648","28","0","2"],["9.649","242","0","2"],["48.383","1","0","1"]],"bids":[],"ts":"1646003674090","checksum":1276770794}]}
1646003674.11116: {"arg":{"channel":"books-l2-tbt","instId":"ELON-USDT"},"action":"update","data":[{"asks":[["0.00000074586","263810383","0","3"]],"bids":[],"ts":"1646003674099","checksum":-799346073}]}
1646003674.126148: {"arg":{"channel":"books-l2-tbt","instId":"ELON-USDT"},"action":"update","data":[{"asks":[["0.00000074589","0","0","0"],["0.00000113812","12211658","0","1"]],"bids":[],"ts":"1646003674110","checksum":269131130}]}
1646003674.144282: {"arg":{"channel":"books-l2-tbt","instId":"ZEN-USDT"},"action":"update","data":[{"asks":[],"bids":[["32.46","19.833028","0","2"]],"ts":"1646003674133","checksum":2037069090}]}
1646003674.148268: {"arg":{"channel":"books-l2-tbt","instId":"ELON-USDT"},"action":"update","data":[{"asks":[["0.00000074586","159764443","0","2"]],"bids":[],"ts":"1646003674136","checksum":-559658035}]}
1646003674.170156: {"arg":{"channel":"books-l2-tbt","instId":"ELON-USDT"},"action":"update","data":[{"asks":[],"bids":[["0.00000074449","219861835","0","1"]],"ts":"1646003674156","checksum":-1741015371}]}
1646003674.179539: {"arg":{"channel":"books-l2-tbt","instId":"ELON-USDT"},"action":"update","data":[{"asks":[["0.00000074586","48015673","0","1"]],"bids":[],"ts":"1646003674168","checksum":791335344}]}
1646003674.1890402: {"arg":{"channel":"books-l2-tbt","instId":"ELON-USDT"},"action":"update","data":[{"asks":[["0.00000074585","445226872","0","1"],["0.00000113812","0","0","0"]],"bids":[],"ts":"1646003674177","checksum":1171970849}]}
1646003674.2009: {"arg":{"channel":"books-l2-tbt","instId":"ELON-USDT"},"action":"update","data":[{"asks":[["0.00000074586","0","0","0"],["0.00000113812","12211658","0","1"]],"bids":[],"ts":"1646003674189","checksum":767007762}]}
1646003674.2206779: {"arg":{"channel":"books-l2-tbt","instId":"ELON-USDT"},"action":"update","data":[{"asks":[["0.00000074584","48015673","0","1"],["0.00000113812","0","0","0"]],"bids":[],"ts":"1646003674208","checksum":-2142016284}]}
1646003674.2361019: {"arg":{"channel":"books-l2-tbt","instId":"UNI-USD-SWAP"},"action":"update","data":[{"asks":[],"bids":[["9.603","521","0","2"],["9.602","76","0","1"],["9.601","69","0","3"],["9.6","0","0","0"],["9.598","23","0","1"],["9.597","0","0","0"]],"ts":"1646003674220","checksum":-486587949}]}
1646003674.236209: {"arg":{"channel":"books-l2-tbt","instId":"ELON-USDT"},"action":"update","data":[{"asks":[["0.00000074584","168943716","0","3"]],"bids":[["0.0000007445","184440410","0","1"]],"ts":"1646003674224","checksum":-1453339737}]}
1646003674.2453701: {"arg":{"channel":"books-l2-tbt","instId":"ELON-USDT"},"action":"update","data":[{"asks":[["0.00000074587","0","0","0"],["0.00000113812","12211658","0","1"]],"bids":[],"ts":"1646003674230","checksum":1163535237}]}
1646003674.249931: {"arg":{"channel":"books-l2-tbt","instId":"UNI-USD-SWAP"},"action":"update","data":[{"asks":[["9.628","129","0","2"],["9.629","12","0","1"]],"bids":[],"ts":"1646003674237","checksum":559379388}]}
1646003674.2526999: {"arg":{"channel":"books-l2-tbt","instId":"ELON-USDT"},"action":"update","data":[{"asks":[],"bids":[["0.00000074434","496570976","0","1"]],"ts":"1646003674240","checksum":-485479270}]}
1646003674.259488: {"arg":{"channel":"books-l2-tbt","instId":"UNI-USD-SWAP"},"action":"update","data":[{"asks":[],"bids":[["9.609","4","0","1"]],"ts":"1646003674247","checksum":-229364820}]}
1646003674.2700002: {"arg":{"channel":"books-l2-tbt","instId":"UNI-USD-SWAP"},"action":"update","data":[{"asks":[["9.627","2","0","1"],["48.383","0","0","0"]],"bids":[["9.611","0","0","0"],["9.609","0","0","0"]],"ts":"1646003674258","checksum":-264610231}]}
1646003674.273386: {"arg":{"channel":"books-l2-tbt","instId":"ELON-USDT"},"action":"update","data":[{"asks":[["0.00000074584","222051439","0","4"]],"bids":[],"ts":"1646003674261","checksum":-810491576}]}
1646003674.27906: {"arg":{"channel":"books-l2-tbt","instId":"UNI-USD-SWAP"},"action":"update","data":[{"asks":[["9.628","126","0","1"]],"bids":[],"ts":"1646003674268","checksum":-1121526594}]}
1646003674.288646: {"arg":{"channel":"books-l2-tbt","instId":"PROPS-ETH"},"action":"update","data":[{"asks":[],"bids":[["0.00000167","345428.695106","0","2"]],"ts":"1646003674275","checksum":-1981248529}]}
1646003674.291853: {"arg":{"channel":"books-l2-tbt","instId":"UNI-USD-SWAP"},"action":"update","data":[{"asks":[],"bids":[["9.611","1","0","1"]],"ts":"1646003674280","checksum":1130186723}]}
1646003674.2919302: {"arg":{"channel":"books-l2-tbt","instId":"ELON-USDT"},"action":"update","data":[{"asks":[["0.00000074583","354277413","0","1"],["0.00000074584","174035766","0","3"],["0.00000074591","0","0","0"]],"bids":[],"ts":"1646003674282","checksum":1050350449}]}
1646003674.301454: {"arg":{"channel":"books-l2-tbt","instId":"UNI-USD-SWAP"},"action":"update","data":[{"asks":[["9.628","89","0","1"]],"bids":[],"ts":"1646003674290","checksum":1010167171}]}
1646003674.315567: {"arg":{"channel":"books-l2-tbt","instId":"ELON-USDT"},"action":"update","data":[{"asks":[["0.00000074585","0","0","0"],["0.00000113853","6145556","0","1"]],"bids":[],"ts":"1646003674302","checksum":-2113168546}]}
1646003674.3546739: {"arg":{"channel":"books-l2-tbt","instId":"UNI-USD-SWAP"},"action":"update","data":[{"asks":[["9.621","88","0","1"],["9.622","260","0","1"],["48.143","0","0","0"]],"bids":[],"ts":"1646003674342","checksum":-402820724}]}
1646003674.3828962: {"arg":{"channel":"books-l2-tbt","instId":"PROPS-ETH"},"action":"update","data":[{"asks":[],"bids":[["0.00000167","458123.556565","0","3"]],"ts":"1646003674369","checksum":-938078091}]}
1646003674.387827: {"arg":{"channel":"books-l2-tbt","instId":"UNI-USD-SWAP"},"action":"update","data":[{"asks":[],"bids":[["9.609","4","0","1"]],"ts":"1646003674374","checksum":2054380299}]}
1646003674.3934278: {"arg":{"channel":"books-l2-tbt","instId":"PROPS-ETH"},"action":"update","data":[{"asks":[["0.00000176","8966.52606268","0","2"],["0.00000178","0","0","0"],["0.00000183","1140.2031615","0","1"],["0.00000184","860.87147823","0","1"],["0.00000187","0","0","0"]],"bids":[["0.00000161","0","0","0"],["0.0000016","10261.03711289","0","1"]],"ts":"1646003674379","checksum":-344443282}]}
1646003674.397408: {"arg":{"channel":"books-l2-tbt","instId":"UNI-USD-SWAP"},"action":"update","data":[{"asks":[["9.642","168","0","2"],["9.643","30","0","1"],["9.645","748","0","3"],["9.646","45","0","2"],["9.648","1","0","1"],["9.649","264","0","3"],["47.903","0","0","0"]],"bids":[["9.611","0","0","0"],["9.603","500","0","1"],["9.602","98","0","2"],["9.601","41","0","2"],["9.6","21","0","1"],["9.598","0","0","0"],["9.597","28","0","1"]],"ts":"1646003674384","checksum":2143787143}]}
1646003674.3976161: {"arg":{"channel":"books-l2-tbt","instId":"ELON-USDT"},"action":"update","data":[{"asks":[["0.00000074585","81175250","0","1"],["0.00000113853","0","0","0"]],"bids":[],"ts":"1646003674385","checksum":275266099}]}
1646003674.423525: {"arg":{"channel":"books-l2-tbt","instId":"ELON-USDT"},"action":"update","data":[{"asks":[["0.00000074582","215794710","0","2"],["0.00000113812","0","0","0"]],"bids":[],"ts":"1646003674407","checksum":1484827331}]}
1646003674.4324212: {"arg":{"channel":"books-l2-tbt","instId":"ELON-USDT"},"action":"update","data":[{"asks":[],"bids":[["0.00000070565","471044424","0","2"],["0.00000069154","338427522","0","1"],["0.00000067771","295460874","0","1"],["0.00000066416","341790035","0","1"],["0.00000064198","0","0","0"]],"ts":"1646003674417","checksum":1484827331}]}
1646003674.438872: {"arg":{"channel":"books-l2-tbt","instId":"ELON-USDT"},"action":"update","data":[{"asks":[["0.00000074584","0","0","0"],["0.00000113812","12211658","0","1"]],"bids":[],"ts":"1646003674427","checksum":-1596888592}]}
1646003674.447683: {"arg":{"channel":"books-l2-tbt","instId":"UNI-USD-SWAP"},"action":"update","data":[{"asks":[["9.621","260","0","1"],["9.622","0","0","0"],["9.632","589","0","4"],["47.903","1","0","1"]],"bids":[],"ts":"1646003674435","checksum":447210317}]}
1646003674.460512: {"arg":{"channel":"books-l2-tbt","instId":"ELON-USDT"},"action":"update","data":[{"asks":[["0.00000074581","445226872","0","1"],["0.00000113812","0","0","0"]],"bids":[],"ts":"1646003674449","checksum":-949650603}]}
1646003674.468809: {"arg":{"channel":"books-l2-tbt","instId":"UNI-USD-SWAP"},"action":"update","data":[{"asks":[["9.643","0","0","0"],["9.645","773","0","4"],["9.646","16","0","1"],["9.648","22","0","2"],["9.649","242","0","2"],["9.651","103","0","3"],["48.143","1","0","1"]],"bids":[["9.609","0","0","0"],["9.603","526","0","2"],["9.602","76","0","1"],["9.601","71","0","3"],["9.6","0","0","0"],["9.598","22","0","1"],["9.597","0","0","0"]],"ts":"1646003674456","checksum":-1871434455}]}
1646003674.482581: {"arg":{"channel":"books-l2-tbt","instId":"ELON-USDT"},"action":"update","data":[{"asks":[["0.0000007458","48015673","0","1"],["0.00000074582","0","0","0"]],"bids":[],"ts":"1646003674470","checksum":594474411}]}
1646003674.499279: {"arg":{"channel":"books-l2-tbt","instId":"UNI-USD-SWAP"},"action":"update","data":[{"asks":[],"bids":[["9.611","2","0","1"]],"ts":"1646003674486","checksum":1925031754}]}
1646003674.5144372: {"arg":{"channel":"books-l2-tbt","instId":"ELON-USDT"},"action":"update","data":[{"asks":[["0.0000007458","263810383","0","3"]],"bids":[],"ts":"1646003674492","checksum":-580418465}]}
1646003674.51456: {"arg":{"channel":"books-l2-tbt","instId":"UNI-USD-SWAP"},"action":"update","data":[{"asks":[["9.628","0","0","0"],["9.629","101","0","2"],["48.383","1","0","1"]],"bids":[],"ts":"1646003674496","checksum":-208199005}]}
1646003674.514634: {"arg":{"channel":"books-l2-tbt","instId":"ELON-USDT"},"action":"update","data":[{"asks":[["0.00000074583","0","0","0"],["0.00000113812","12211658","0","1"]],"bids":[],"ts":"1646003674503","checksum":1121081554}]}
1646003674.530273: {"arg":{"channel":"books-l2-tbt","instId":"UNI-USD-SWAP"},"action":"update","data":[{"asks":[["9.627","0","0","0"],["9.628","3","0","1"]],"bids":[],"ts":"1646003674518","checksum":-221971554}]}
1646003674.540447: {"arg":{"channel":"books-l2-tbt","instId":"UNI-USD-SWAP"},"action":"update","data":[{"asks":[["9.628","92","0","2"],["9.629","12","0","1"]],"bids":[],"ts":"1646003674529","checksum":-1251066048}]}
1646003674.550535: {"arg":{"channel":"books-l2-tbt","instId":"UNI-USD-SWAP"},"action":"update","data":[{"asks":[["9.621","348","0","2"]],"bids":[],"ts":"1646003674539","checksum":-619519417}]}
1646003674.5660522: {"arg":{"channel":"books-l2-tbt","instId":"UNI-USD-SWAP"},"action":"update","data":[{"asks":[["9.627","2","0","1"],["48.383","0","0","0"]],"bids":[],"ts":"1646003674553","checksum":-920872036}]}
1646003674.578214: {"arg":{"channel":"books-l2-tbt","instId":"ELON-USDT"},"action":"update","data":[{"asks":[["0.00000074579","329574257","0","1"],["0.00000113812","0","0","0"]],"bids":[],"ts":"1646003674566","checksum":-1207221278}]}
1646003674.58245: {"arg":{"channel":"books-l2-tbt","instId":"UNI-USD-SWAP"},"action":"update","data":[{"asks":[["9.628","89","0","1"]],"bids":[],"ts":"1646003674571","checksum":721212446}]}
1646003674.600739: {"arg":{"channel":"books-l2-tbt","instId":"ELON-USDT"},"action":"update","data":[{"asks":[["0.0000007458","0","0","0"],["0.00000113812","12211658","0","1"]],"bids":[],"ts":"1646003674586","checksum":2037191231}]}
1646003674.609299: {"arg":{"channel":"books-l2-tbt","instId":"ELON-USDT"},"action":"update","data":[{"asks":[["0.00000074581","0","0","0"],["0.00000113853","6145556","0","1"]],"bids":[],"ts":"1646003674597","checksum":-842716414}]}
1646003674.619852: {"arg":{"channel":"books-l2-tbt","instId":"ELON-USDT"},"action":"update","data":[{"asks":[["0.00000074578","48015673","0","1"],["0.00000113853","0","0","0"]],"bids":[["0.00000074449","0","0","0"]],"ts":"1646003674608","checksum":474564437}]}
1646003674.625299: {"arg":{"channel":"books-l2-tbt","instId":"UNI-USD-SWAP"},"action":"update","data":[{"asks":[["9.628","0","0","0"],["9.629","101","0","2"],["48.383","1","0","1"]],"bids":[],"ts":"1646003674614","checksum":-1645477980}]}
1646003674.657363: {"arg":{"channel":"books-l2-tbt","instId":"UNI-USD-SWAP"},"action":"update","data":[{"asks":[["9.628","3","0","1"],["48.383","0","0","0"]],"bids":[],"ts":"1646003674646","checksum":742108701}]}
1646003674.660409: {"arg":{"channel":"books-l2-tbt","instId":"ELON-USDT"},"action":"update","data":[{"asks":[["0.00000074578","222051439","0","4"]],"bids":[],"ts":"1646003674649","checksum":923783443}]}
1646003674.666848: {"arg":{"channel":"books-l2-tbt","instId":"UNI-USD-SWAP"},"action":"update","data":[{"asks":[["9.627","0","0","0"],["9.642","192","0","3"],["9.651","79","0","2"],["48.383","1","0","1"]],"bids":[["9.603","500","0","1"],["9.602","103","0","2"],["9.601","41","0","2"],["9.6","29","0","1"],["9.598","0","0","0"],["9.597","24","0","1"]],"ts":"1646003674656","checksum":659003647}]}
1646003674.671047: {"arg":{"channel":"books-l2-tbt","instId":"ELON-USDT"},"action":"update","data":[{"asks":[["0.00000074577","390154465","0","1"],["0.00000113812","0","0","0"]],"bids":[["0.00000074435","184440410","0","1"]],"ts":"1646003674659","checksum":827960230}]}
1646003674.6804621: {"arg":{"channel":"books-l2-tbt","instId":"UNI-USD-SWAP"},"action":"update","data":[{"asks":[["9.621","88","0","1"]],"bids":[],"ts":"1646003674669","checksum":388419998}]}
1646003674.692735: {"arg":{"channel":"books-l2-tbt","instId":"ELON-USDT"},"action":"update","data":[{"asks":[["0.00000074578","174035766","0","3"]],"bids":[],"ts":"1646003674680","checksum":1089753974}]}
1646003674.70245: {"arg":{"channel":"books-l2-tbt","instId":"UNI-USD-SWAP"},"action":"update","data":[{"asks":[["9.621","0","0","0"],["48.625","1","0","1"]],"bids":[["9.616","2","0","1"],["9.614","0","0","0"]],"ts":"1646003674688","checksum":1411589561}]}
1646003674.713234: {"arg":{"channel":"books-l2-tbt","instId":"ELON-USDT"},"action":"update","data":[{"asks":[["0.00000074579","0","0","0"],["0.00000113812","12211658","0","1"]],"bids":[["0.0000007445","0","0","0"]],"ts":"1646003674702","checksum":736187503}]}
1646003674.736583: {"arg":{"channel":"books-l2-tbt","instId":"UNI-USD-SWAP"},"action":"update","data":[{"asks":[["9.627","836","0","2"],["9.628","206","0","3"],["9.632","429","0","3"],["48.625","0","0","0"]],"bids":[["9.613","167","0","3"],["9.612","26","0","1"],["9.569","0","0","0"]],"ts":"1646003674710","checksum":1294595421}]}
1646003674.736693: {"arg":{"channel":"books-l2-tbt","instId":"UNI-USD-SWAP"},"action":"update","data":[{"asks":[],"bids":[["9.611","0","0","0"]],"ts":"1646003674720","checksum":1315634654}]}
1646003674.736727: {"arg":{"channel":"books-l2-tbt","instId":"ETH-USD-220624-12000-P"},"action":"update","data":[{"asks":[["4.0445","0","0","0"],["4.045","201","0","1"]],"bids":[],"ts":"1646003674723","checksum":-1436588960}]}
1646003674.7421749: {"arg":{"channel":"books-l2-tbt","instId":"UNI-USD-SWAP"},"action":"update","data":[{"asks":[["9.626","3","0","1"],["9.627","260","0","1"],["9.637","1247","0","2"],["48.383","0","0","0"]],"bids":[["9.578","68","0","2"]],"ts":"1646003674731","checksum":1031548624}]}
1646003674.752341: {"arg":{"channel":"books-l2-tbt","instId":"UNI-USD-SWAP"},"action":"update","data":[{"asks":[["9.628","203","0","2"]],"bids":[["9.612","0","0","0"],["9.609","4","0","1"]],"ts":"1646003674741","checksum":-1060626576}]}
1646003674.76319: {"arg":{"channel":"books-l2-tbt","instId":"UNI-USD-SWAP"},"action":"update","data":[{"asks":[["9.626","91","0","2"]],"bids":[["9.616","0","0","0"]],"ts":"1646003674751","checksum":-429740332}]}
1646003674.785839: {"arg":{"channel":"books-l2-tbt","instId":"UNI-USD-SWAP"},"action":"update","data":[{"asks":[["9.625","789","0","2"],["48.143","0","0","0"]],"bids":[],"ts":"1646003674771","checksum":-1827946449}]}
1646003674.79324: {"arg":{"channel":"books-l2-tbt","instId":"UNI-USD-SWAP"},"action":"update","data":[{"asks":[],"bids":[["9.611","1","0","1"]],"ts":"1646003674781","checksum":-1898850235}]}
1646003674.801845: {"arg":{"channel":"books-l2-tbt","instId":"PROPS-ETH"},"action":"update","data":[{"asks":[["0.00000176","7518.11950204","0","1"],["0.00000178","1281.43760739","0","1"],["0.00000183","0","0","0"],["0.00000184","0","0","0"],["0.00000187","566.5272991","0","1"]],"bids":[["0.00000161","10680.79366405","0","1"],["0.0000016","0","0","0"]],"ts":"1646003674790","checksum":1914035370}]}
1646003674.803628: {"arg":{"channel":"books-l2-tbt","instId":"UNI-USD-SWAP"},"action":"update","data":[{"asks":[["9.624","3","0","1"],["9.628","0","0","0"]],"bids":[["9.613","276","0","4"],["9.611","0","0","0"],["9.609","0","0","0"]],"ts":"1646003674793","checksum":1882382208}]}
1646003674.815812: {"arg":{"channel":"books-l2-tbt","instId":"UNI-USD-SWAP"},"action":"update","data":[{"asks":[["9.623","545","0","1"],["9.625","260","0","1"],["9.626","88","0","1"],["9.628","26","0","1"],["47.665","0","0","0"],["47.903","0","0","0"]],"bids":[],"ts":"1646003674804","checksum":-1721879720}]}
1646003674.830284: {"arg":{"channel":"books-l2-tbt","instId":"UNI-USD-SWAP"},"action":"update","data":[{"asks":[],"bids":[["9.578","64","0","1"],["9.576","1056","0","2"]],"ts":"1646003674813","checksum":-1721879720}]}
1646003674.835649: {"arg":{"channel":"books-l2-tbt","instId":"UNI-USD-SWAP"},"action":"update","data":[{"asks":[["9.622","261","0","2"],["9.623","0","0","0"],["9.627","0","0","0"],["47.665","1","0","1"]],"bids":[["9.609","3","0","1"]],"ts":"1646003674823","checksum":2000899277}]}
1646003674.85935: {"arg":{"channel":"books-l2-tbt","instId":"UNI-USD-SWAP"},"action":"update","data":[{"asks":[["9.626","0","0","0"],["47.903","1","0","1"]],"bids":[],"ts":"1646003674847","checksum":-566163147}]}
1646003674.859435: {"arg":{"channel":"books-l2-tbt","instId":"ELON-USDT"},"action":"update","data":[{"asks":[["0.00000074578","0","0","0"],["0.00000113853","6145556","0","1"]],"bids":[],"ts":"1646003674847","checksum":1487569125}]}
1646003674.8679838: {"arg":{"channel":"books-l2-tbt","instId":"UNI-USD-SWAP"},"action":"update","data":[{"asks":[["9.622","260","0","1"],["9.628","0","0","0"],["48.143","1","0","1"]],"bids":[["9.551","0","0","0"]],"ts":"1646003674855","checksum":-430876421}]}
1646003674.8791249: {"arg":{"channel":"books-l2-tbt","instId":"ELON-USDT"},"action":"update","data":[{"asks":[["0.00000074585","0","0","0"],["0.00000113879","5262112","0","1"]],"bids":[],"ts":"1646003674867","checksum":1533518996}]}
1646003674.882947: {"arg":{"channel":"books-l2-tbt","instId":"ELON-USDT"},"action":"update","data":[{"asks":[["0.00000074576","263810383","0","3"],["0.00000113879","0","0","0"]],"bids":[],"ts":"1646003674868","checksum":-1126177588}]}
1646003674.885973: {"arg":{"channel":"books-l2-tbt","instId":"UNI-USD-SWAP"},"action":"update","data":[{"asks":[],"bids":[["9.609","0","0","0"]],"ts":"1646003674875","checksum":-1462739072}]}
1646003674.8971782: {"arg":{"channel":"books-l2-tbt","instId":"UNI-USD-SWAP"},"action":"update","data":[{"asks":[],"bids":[["9.544","160","0","1"]],"ts":"1646003674886","checksum":-1462739072}]}
1646003674.9078982: {"arg":{"channel":"books-l2-tbt","instId":"UNI-USD-SWAP"},"action":"update","data":[{"asks":[],"bids":[["9.611","1","0","1"]],"ts":"1646003674897","checksum":-571772343}]}
1646003674.910903: {"arg":{"channel":"books-l2-tbt","instId":"ELON-USDT"},"action":"update","data":[{"asks":[["0.00000074584","404097016","0","1"],["0.00000113853","0","0","0"]],"bids":[],"ts":"1646003674899","checksum":-1173641114}]}
1646003674.923946: {"arg":{"channel":"books-l2-tbt","instId":"ELON-USDT"},"action":"update","data":[{"asks":[],"bids":[["0.00000070565","144547580","0","1"],["0.00000069154","0","0","0"],["0.00000067771","0","0","0"],["0.00000066416","0","0","0"],["0.00000065074","266686499","0","1"]],"ts":"1646003674911","checksum":-1173641114}]}
1646003674.9433038: {"arg":{"channel":"books-l2-tbt","instId":"ELON-USDT"},"action":"update","data":[{"asks":[["0.00000074576","159764443","0","2"],["0.00000074577","81175250","0","1"]],"bids":[],"ts":"1646003674931","checksum":339842450}]}
1646003674.960644: {"arg":{"channel":"books-l2-tbt","instId":"UNI-USD-SWAP"},"action":"update","data":[{"asks":[["9.622","348","0","2"],["9.642","168","0","2"],["9.645","748","0","3"],["9.646","37","0","2"],["9.648","1","0","1"],["9.649","267","0","3"],["9.652","21","0","1"],["48.143","0","0","0"]],"bids":[],"ts":"1646003674949","checksum":1400859173}]}
1646003674.981945: {"arg":{"channel":"books-l2-tbt","instId":"UNI-USD-SWAP"},"action":"update","data":[{"asks":[["9.66","41","0","1"]],"bids":[["9.581","9539","0","1"]],"ts":"1646003674970","checksum":-480046613}]}
1646003674.990301: {"arg":{"channel":"books-l2-tbt","instId":"UNI-USD-SWAP"},"action":"update","data":[{"asks":[["9.657","31","0","1"],["47.903","0","0","0"]],"bids":[["9.579","94","0","2"]],"ts":"1646003674979","checksum":-480046613}]}
1646003675.006615: {"arg":{"channel":"books-l2-tbt","instId":"ELON-USDT"},"action":"update","data":[{"asks":[["0.00000074575","283077284","0","1"],["0.00000113812","0","0","0"]],"bids":[],"ts":"1646003674995","checksum":-502188017}]}
1646003675.026788: {"arg":{"channel":"books-l2-tbt","instId":"ELON-USDT"},"action":"update","data":[{"asks":[["0.00000074576","0","0","0"],["0.00000113812","12211658","0","1"]],"bids":[],"ts":"1646003675016","checksum":2061219853}]}
1646003675.041947: {"arg":{"channel":"books-l2-tbt","instId":"ELON-USDT"},"action":"update","data":[{"asks":[["0.00000074574","48015673","0","1"],["0.00000074584","0","0","0"]],"bids":[],"ts":"1646003675027","checksum":443136964}]}
1646003675.057004: {"arg":{"channel":"books-l2-tbt","instId":"UNI-USD-SWAP"},"action":"update","data":[{"asks":[],"bids":[["9.588","125","0","1"]],"ts":"1646003675043","checksum":-393835625}]}
1646003675.06799: {"arg":{"channel":"books-l2-tbt","instId":"ELON-USDT"},"action":"update","data":[{"asks":[["0.00000074574","169693742","0","3"]],"bids":[],"ts":"1646003675056","checksum":690587290}]}
1646003675.080419: {"arg":{"channel":"books-l2-tbt","instId":"ELON-USDT"},"action":"update","data":[{"asks":[["0.00000074599","445226872","0","1"],["0.00000113812","0","0","0"]],"bids":[],"ts":"1646003675067","checksum":-1569952782}]}
1646003675.0848079: {"arg":{"channel":"books-l2-tbt","instId":"UNI-USD-SWAP"},"action":"update","data":[{"asks":[["9.643","22","0","1"],["9.652","0","0","0"]],"bids":[],"ts":"1646003675074","checksum":-1766558888}]}
1646003675.090102: {"arg":{"channel":"books-l2-tbt","instId":"ELON-USDT"},"action":"update","data":[{"asks":[["0.00000074574","121678069","0","2"]],"bids":[["0.00000074449","219861835","0","1"]],"ts":"1646003675078","checksum":-732180717}]}
1646003675.115829: {"arg":{"channel":"books-l2-tbt","instId":"UNI-USD-SWAP"},"action":"update","data":[{"asks":[],"bids":[["9.609","4","0","1"]],"ts":"1646003675095","checksum":1697917615}]}
1646003675.1403031: {"arg":{"channel":"books-l2-tbt","instId":"UNI-USD-SWAP"},"action":"update","data":[{"asks":[],"bids":[["9.611","0","0","0"]],"ts":"1646003675115","checksum":-247494157}]}
1646003675.140415: {"arg":{"channel":"books-l2-tbt","instId":"ELON-USDT"},"action":"update","data":[{"asks":[["0.00000074575","0","0","0"],["0.00000113812","12211658","0","1"]],"bids":[],"ts":"1646003675121","checksum":1635794177}]}
1646003675.1436858: {"arg":{"channel":"books-l2-tbt","instId":"ELON-USDT"},"action":"update","data":[{"asks":[["0.00000074576","104045940","0","1"],["0.00000113812","0","0","0"]],"bids":[["0.0000007445","184440410","0","1"]],"ts":"1646003675131","checksum":1707081583}]}
1646003675.1743581: {"arg":{"channel":"books-l2-tbt","instId":"ELON-USDT"},"action":"update","data":[{"asks":[],"bids":[["0.00000074435","0","0","0"]],"ts":"1646003675163","checksum":1307007893}]}
1646003675.1969512: {"arg":{"channel":"trades","instId":"ZEN-USDT"},"data":[{"instId":"ZEN-USDT","tradeId":"15270484","px":"32.51","sz":"0.274972","side":"buy","ts":"1646003675182"}]}
1646003675.19705: {"arg":{"channel":"books-l2-tbt","instId":"ELON-USDT"},"action":"update","data":[{"asks":[["0.00000074573","143426484","0","1"],["0.00000074576","215794710","0","2"],["0.0000011372","0","0","0"]],"bids":[],"ts":"1646003675184","checksum":-437450010}]}
1646003675.205033: {"arg":{"channel":"books-l2-tbt","instId":"ETH-USD-220624-20000-C"},"action":"update","data":[{"asks":[["0.0025","0","0","0"],["0.003","1506","0","3"]],"bids":[],"ts":"1646003675189","checksum":-610479892}]}
1646003675.2309299: {"arg":{"channel":"books-l2-tbt","instId":"ELON-USDT"},"action":"update","data":[{"asks":[["0.00000074576","0","0","0"],["0.0000011372","6179288","0","1"]],"bids":[],"ts":"1646003675205","checksum":1472669649}]}
1646003675.231056: {"arg":{"channel":"books-l2-tbt","instId":"ELON-USDT"},"action":"update","data":[{"asks":[["0.00000074599","0","0","0"],["0.00000113812","12211658","0","1"]],"bids":[],"ts":"1646003675216","checksum":-1709934330}]}
1646003675.2476459: {"arg":{"channel":"books-l2-tbt","instId":"ELON-USDT"},"action":"update","data":[{"asks":[["0.00000074572","215794710","0","2"],["0.00000113812","0","0","0"]],"bids":[],"ts":"1646003675226","checksum":-851170027}]}
1646003675.280877: {"arg":{"channel":"books-l2-tbt","instId":"ELON-USDT"},"action":"update","data":[{"asks":[["0.00000074572","268152407","0","3"],["0.00000074574","0","0","0"],["0.00000113812","12211658","0","1"]],"bids":[],"ts":"1646003675268","checksum":1142825205}]}
1646003675.290415: {"arg":{"channel":"books-l2-tbt","instId":"ELON-USDT"},"action":"update","data":[{"asks":[["0.00000074571","311990461","0","1"],["0.00000113812","0","0","0"]],"bids":[],"ts":"1646003675278","checksum":-429805086}]}
1646003675.300334: {"arg":{"channel":"books-l2-tbt","instId":"ELON-USDT"},"action":"update","data":[{"asks":[["0.00000074572","316168080","0","4"]],"bids":[],"ts":"1646003675289","checksum":1587859435}]}
1646003675.303348: {"arg":{"channel":"books-l2-tbt","instId":"UNI-USD-SWAP"},"action":"update","data":[{"asks":[["9.657","0","0","0"],["9.66","0","0","0"],["9.662","39","0","1"],["9.664","137","0","2"],["47.903","1","0","1"]],"bids":[],"ts":"1646003675292","checksum":-247494157}]}
1646003675.30388: {"arg":{"channel":"books-l2-tbt","instId":"PROPS-ETH"},"action":"update","data":[{"asks":[["0.00000178","0","0","0"],["0.00000187","0","0","0"]],"bids":[["0.00000161","0","0","0"]],"ts":"1646003675293","checksum":773197752}]}
1646003675.3103292: {"arg":{"channel":"books-l2-tbt","instId":"ELON-USDT"},"action":"update","data":[{"asks":[["0.00000074572","52357697","0","1"],["0.00000074573","0","0","0"],["0.00000113812","12211658","0","1"]],"bids":[],"ts":"1646003675299","checksum":-252933237}]}
1646003675.3135412: {"arg":{"channel":"books-l2-tbt","instId":"PROPS-ETH"},"action":"update","data":[{"asks":[["0.00000176","8509.55360591","0","2"],["0.00000183","1048.84165815","0","1"],["0.00000184","1388.83110819","0","1"]],"bids":[["0.0000016","10552.73886247","0","1"]],"ts":"1646003675302","checksum":-1532329394}]}
1646003675.320804: {"arg":{"channel":"books-l2-tbt","instId":"ELON-USDT"},"action":"update","data":[{"asks":[["0.0000007457","263810383","0","3"],["0.00000113812","0","0","0"]],"bids":[],"ts":"1646003675309","checksum":680167836}]}
1646003675.338351: {"arg":{"channel":"books-l2-tbt","instId":"UNI-USD-SWAP"},"action":"update","data":[{"asks":[["9.643","0","0","0"],["9.646","16","0","1"],["9.648","28","0","2"],["9.649","242","0","2"],["9.651","99","0","3"],["9.654","9307","0","3"],["48.143","1","0","1"]],"bids":[["9.603","525","0","2"],["9.602","76","0","1"],["9.601","63","0","3"],["9.6","0","0","0"],["9.598","26","0","1"],["9.597","0","0","0"]],"ts":"1646003675324","checksum":-1647498715}]}
1646003675.3411589: {"arg":{"channel":"tickers","instId":"ZEN-USDT"},"data":[{"instType":"SPOT","instId":"ZEN-USDT","last":"32.51","lastSz":"0.274972","askPx":"32.53","askSz":"0.383596","bidPx":"32.5","bidSz":"0.399716","open24h":"33.34","high24h":"35.26","low24h":"31.91","sodUtc0":"33.36","sodUtc8":"34.26","volCcy24h":"1483609.101168","vol24h":"44364.825212","ts":"1646003675317"}]}
1646003675.3412218: {"arg":{"channel":"books-l2-tbt","instId":"ELON-USDT"},"action":"update","data":[{"asks":[["0.0000007457","159764443","0","2"]],"bids":[],"ts":"1646003675330","checksum":-433823957}]}
1646003675.3571682: {"arg":{"channel":"books-l2-tbt","instId":"PROPS-ETH"},"action":"update","data":[{"asks":[],"bids":[["0.00000166","0","0","0"]],"ts":"1646003675344","checksum":-1617275162}]}
1646003675.357284: {"arg":{"channel":"books-l2-tbt","instId":"ETH-USD-220624-20000-C"},"action":"update","data":[{"asks":[["0.002","0","0","0"],["0.0025","20","0","1"]],"bids":[],"ts":"1646003675346","checksum":1483419732}]}
1646003675.37669: {"arg":{"channel":"books-l2-tbt","instId":"BTC-USD-220325-40000-C"},"action":"update","data":[{"asks":[["0.0515","334","0","2"],["0.052","301","0","1"]],"bids":[],"ts":"1646003675365","checksum":932124355}]}
1646003675.37804: {"arg":{"channel":"books-l2-tbt","instId":"UNI-USD-SWAP"},"action":"update","data":[{"asks":[["9.664","64","0","1"]],"bids":[],"ts":"1646003675366","checksum":-1647498715}]}
1646003675.393566: {"arg":{"channel":"books-l2-tbt","instId":"ELON-USDT"},"action":"update","data":[{"asks":[["0.00000074569","174632476","0","1"],["0.0000011372","0","0","0"]],"bids":[],"ts":"1646003675372","checksum":1825099350}]}
1646003675.3936892: {"arg":{"channel":"books-l2-tbt","instId":"UNI-USD-SWAP"},"action":"update","data":[{"asks":[["9.662","0","0","0"],["48.383","1","0","1"]],"bids":[],"ts":"1646003675376","checksum":-1647498715}]}
1646003675.3981152: {"arg":{"channel":"books-l2-tbt","instId":"ELON-USDT"},"action":"update","data":[{"asks":[["0.0000007457","0","0","0"],["0.0000011372","6179288","0","1"]],"bids":[],"ts":"1646003675384","checksum":898708805}]}
1646003675.4162638: {"arg":{"channel":"books-l2-tbt","instId":"ELON-USDT"},"action":"update","data":[{"asks":[["0.00000074568","48015673","0","1"],["0.00000074571","0","0","0"],["0.00000074577","0","0","0"],["0.00000113812","12211658","0","1"]],"bids":[],"ts":"1646003675404","checksum":-1836047538}]}
1646003675.437603: {"arg":{"channel":"books-l2-tbt","instId":"ELON-USDT"},"action":"update","data":[{"asks":[],"bids":[["0.00000070254","264407380","0","1"],["0.00000068849","430802074","0","1"],["0.00000067473","431179722","0","1"],["0.00000066124","208445955","0","1"],["0.00000065074","0","0","0"]],"ts":"1646003675425","checksum":-1836047538}]}
1646003675.447358: {"arg":{"channel":"books-l2-tbt","instId":"ELON-USDT"},"action":"update","data":[{"asks":[["0.00000074569","0","0","0"],["0.00000113853","6145556","0","1"]],"bids":[],"ts":"1646003675435","checksum":-1514764836}]}
1646003675.467432: {"arg":{"channel":"books-l2-tbt","instId":"ELON-USDT"},"action":"update","data":[{"asks":[["0.00000074568","0","0","0"],["0.00000113879","5262112","0","1"]],"bids":[],"ts":"1646003675455","checksum":-344478037}]}
1646003675.47855: {"arg":{"channel":"books-l2-tbt","instId":"ELON-USDT"},"action":"update","data":[{"asks":[["0.00000074734","0","0","0"],["0.00000114","16237250","0","2"]],"bids":[],"ts":"1646003675465","checksum":1962813075}]}
1646003675.486712: {"arg":{"channel":"books-l2-tbt","instId":"ELON-USDT"},"action":"update","data":[{"asks":[["0.00000074567","173692335","0","1"],["0.00000074572","0","0","0"],["0.00000074599","121678069","0","2"],["0.00000114","0","0","0"]],"bids":[],"ts":"1646003675475","checksum":499053694}]}
1646003675.499021: {"arg":{"channel":"books-l2-tbt","instId":"ELON-USDT"},"action":"update","data":[{"asks":[["0.00000074732","3469208211","0","1"],["0.00000113879","0","0","0"]],"bids":[],"ts":"1646003675487","checksum":1436309476}]}
1646003675.507893: {"arg":{"channel":"books-l2-tbt","instId":"ELON-USDT"},"action":"update","data":[{"asks":[["0.00000074599","202853319","0","3"]],"bids":[],"ts":"1646003675497","checksum":-553459224}]}
1646003675.519552: {"arg":{"channel":"books-l2-tbt","instId":"ELON-USDT"},"action":"update","data":[{"asks":[["0.00000074793","445226872","0","1"],["0.00000113853","0","0","0"]],"bids":[],"ts":"1646003675507","checksum":623785873}]}
1646003675.536459: {"arg":{"channel":"books-l2-tbt","instId":"ELON-USDT"},"action":"update","data":[{"asks":[["0.00000074566","104045940","0","1"],["0.00000113812","0","0","0"]],"bids":[],"ts":"1646003675519","checksum":-1804172288}]}
1646003675.536521: {"arg":{"channel":"books-l2-tbt","instId":"UNI-USD-SWAP"},"action":"update","data":[{"asks":[["9.631","151","0","1"],["48.383","0","0","0"]],"bids":[],"ts":"1646003675520","checksum":17692537}]}
1646003675.541827: {"arg":{"channel":"books-l2-tbt","instId":"ELON-USDT"},"action":"update","data":[{"asks":[],"bids":[["0.00000074449","0","0","0"]],"ts":"1646003675529","checksum":689804981}]}
1646003675.552407: {"arg":{"channel":"books-l2-tbt","instId":"ELON-USDT"},"action":"update","data":[{"asks":[["0.00000074567","0","0","0"],["0.00000113812","12211658","0","1"]],"bids":[],"ts":"1646003675540","checksum":-865719436}]}
1646003675.563107: {"arg":{"channel":"books-l2-tbt","instId":"UNI-USD-SWAP"},"action":"update","data":[{"asks":[["9.644","26","0","1"],["9.647","2583","0","6"],["9.648","1","0","1"],["9.65","247","0","2"],["9.651","79","0","2"],["9.654","9280","0","2"],["48.143","0","0","0"]],"bids":[["9.604","340","0","3"],["9.603","500","0","1"],["9.602","97","0","2"],["9.601","41","0","2"],["9.599","647","0","3"],["9.598","0","0","0"]],"ts":"1646003675551","checksum":1619390297}]}
1646003675.57157: {"arg":{"channel":"books-l2-tbt","instId":"BTC-USD-220325-40000-C"},"action":"update","data":[{"asks":[["0.051","29","0","1"],["0.0515","305","0","1"]],"bids":[],"ts":"1646003675562","checksum":1599394008}]}
1646003675.573521: {"arg":{"channel":"books-l2-tbt","instId":"ELON-USDT"},"action":"update","data":[{"asks":[["0.00000074566","0","0","0"],["0.00000113853","6145556","0","1"]],"bids":[],"ts":"1646003675561","checksum":-657931543}]}
1646003675.5735722: {"arg":{"channel":"books-l2-tbt","instId":"UNI-USD-SWAP"},"action":"update","data":[{"asks":[["9.662","43","0","1"],["9.663","89","0","2"],["47.903","0","0","0"]],"bids":[],"ts":"1646003675562","checksum":1619390297}]}
1646003675.582582: {"arg":{"channel":"books-l2-tbt","instId":"ELON-USDT"},"action":"update","data":[{"asks":[["0.00000074732","0","0","0"],["0.00000113879","5262112","0","1"]],"bids":[["0.00000074435","184440410","0","1"]],"ts":"1646003675571","checksum":-2087542526}]}
1646003675.593868: {"arg":{"channel":"books-l2-tbt","instId":"ELON-USDT"},"action":"update","data":[{"asks":[["0.00000074598","215794710","0","2"],["0.00000074732","3468463391","0","1"],["0.00000113853","0","0","0"],["0.00000113879","0","0","0"]],"bids":[],"ts":"1646003675581","checksum":34988238}]}
1646003675.615875: {"arg":{"channel":"books-l2-tbt","instId":"ELON-USDT"},"action":"update","data":[{"asks":[["0.00000074598","661021582","0","3"]],"bids":[["0.0000007445","0","0","0"]],"ts":"1646003675593","checksum":-597009198}]}
1646003675.645586: {"arg":{"channel":"books-l2-tbt","instId":"ZEN-USDT"},"action":"update","data":[{"asks":[["32.58","0","0","0"],["44.22","2.271956","0","1"]],"bids":[["32.41","35.959536","0","1"]],"ts":"1646003675632","checksum":884289297}]}
1646003675.666828: {"arg":{"channel":"books-l2-tbt","instId":"UNI-USD-SWAP"},"action":"update","data":[{"asks":[],"bids":[["9.613","223","0","3"],["9.61","0","0","0"],["9.608","18","0","2"],["9.601","25","0","1"],["9.595","17","0","1"]],"ts":"1646003675656","checksum":-82523902}]}
1646003675.678478: {"arg":{"channel":"books-l2-tbt","instId":"UNI-USD-SWAP"},"action":"update","data":[{"asks":[],"bids":[["9.612","53","0","1"]],"ts":"1646003675667","checksum":459360335}]}
1646003675.6901891: {"arg":{"channel":"books-l2-tbt","instId":"UNI-USD-SWAP"},"action":"update","data":[{"asks":[["9.632","426","0","2"],["9.638","635","0","4"],["9.639","0","0","0"],["9.644","0","0","0"],["9.645","772","0","4"],["9.647","2554","0","5"],["9.648","22","0","2"],["9.65","225","0","1"],["9.651","107","0","3"],["47.903","1","0","1"],["48.143","1","0","1"]],"bids":[],"ts":"1646003675679","checksum":-155194847}]}
1646003675.698566: {"arg":{"channel":"books-l2-tbt","instId":"ELON-USDT"},"action":"update","data":[{"asks":[["0.00000074597","52357697","0","1"],["0.00000074599","81175250","0","1"],["0.00000113812","0","0","0"]],"bids":[],"ts":"1646003675685","checksum":306410705}]}
1646003675.718225: {"arg":{"channel":"books-l2-tbt","instId":"ELON-USDT"},"action":"update","data":[{"asks":[["0.00000074597","100373370","0","2"]],"bids":[],"ts":"1646003675704","checksum":1399740906}]}
1646003675.7210538: {"arg":{"channel":"books-l2-tbt","instId":"UNI-USD-SWAP"},"action":"update","data":[{"asks":[],"bids":[["9.609","5","0","2"],["9.608","12","0","1"],["9.596","16","0","1"],["9.595","0","0","0"]],"ts":"1646003675709","checksum":1355851534}]}
1646003675.729663: {"arg":{"channel":"books-l2-tbt","instId":"ELON-USDT"},"action":"update","data":[{"asks":[["0.00000074793","0","0","0"],["0.00000113812","12211658","0","1"]],"bids":[],"ts":"1646003675716","checksum":-1814624763}]}
1646003675.730461: {"arg":{"channel":"books-l2-tbt","instId":"UNI-USD-SWAP"},"action":"update","data":[{"asks":[["9.632","429","0","3"]],"bids":[],"ts":"1646003675720","checksum":-164333176}]}
1646003675.740395: {"arg":{"channel":"books-l2-tbt","instId":"ELON-USDT"},"action":"update","data":[{"asks":[["0.00000074598","556975642","0","2"]],"bids":[],"ts":"1646003675729","checksum":1981784215}]}
1646003675.742571: {"arg":{"channel":"books-l2-tbt","instId":"UNI-USD-SWAP"},"action":"update","data":[{"asks":[],"bids":[["9.609","1","0","1"]],"ts":"1646003675731","checksum":-2088165001}]}
1646003675.75425: {"arg":{"channel":"books-l2-tbt","instId":"UNI-USD-SWAP"},"action":"update","data":[{"asks":[],"bids":[["9.61","1","0","1"]],"ts":"1646003675742","checksum":1250283396}]}
1646003675.7640488: {"arg":{"channel":"books-l2-tbt","instId":"UNI-USD-SWAP"},"action":"update","data":[{"asks":[],"bids":[["9.609","6","0","1"]],"ts":"1646003675753","checksum":1321685213}]}
1646003675.7693849: {"arg":{"channel":"books-l2-tbt","instId":"ELON-USDT"},"action":"update","data":[{"asks":[["0.00000074596","445226872","0","1"],["0.00000113812","0","0","0"]],"bids":[],"ts":"1646003675758","checksum":-304995936}]}
1646003675.789469: {"arg":{"channel":"books-l2-tbt","instId":"ELON-USDT"},"action":"update","data":[{"asks":[["0.00000074597","52357697","0","1"],["0.00000074598","0","0","0"],["0.00000113812","12211658","0","1"]],"bids":[],"ts":"1646003675778","checksum":829466809}]}
1646003675.805446: {"arg":{"channel":"books-l2-tbt","instId":"PROPS-ETH"},"action":"update","data":[{"asks":[["0.00000176","7518.11950204","0","1"],["0.00000183","0","0","0"],["0.00000184","0","0","0"]],"bids":[["0.0000016","0","0","0"]],"ts":"1646003675794","checksum":-1723429425}]}
1646003675.81536: {"arg":{"channel":"books-l2-tbt","instId":"ELON-USDT"},"action":"update","data":[{"asks":[["0.00000074595","159764443","0","2"],["0.00000113812","0","0","0"]],"bids":[],"ts":"1646003675800","checksum":-1257127837}]}
1646003675.815499: {"arg":{"channel":"books-l2-tbt","instId":"PROPS-ETH"},"action":"update","data":[{"asks":[["0.00000178","1279.74523739","0","1"],["0.00000187","1073.72090162","0","1"]],"bids":[["0.00000161","9874.43292818","0","1"]],"ts":"1646003675804","checksum":188996824}]}
1646003675.8202848: {"arg":{"channel":"books-l2-tbt","instId":"ZEN-USDT"},"action":"update","data":[{"asks":[["32.7","0","0","0"],["44.23","2.713011","0","1"]],"bids":[],"ts":"1646003675809","checksum":874844896}]}
1646003675.839985: {"arg":{"channel":"books-l2-tbt","instId":"UNI-USD-SWAP"},"action":"update","data":[{"asks":[["9.644","24","0","1"],["9.645","748","0","3"],["9.647","2578","0","6"],["9.648","1","0","1"],["9.65","247","0","2"],["9.651","79","0","2"],["48.143","0","0","0"]],"bids":[["9.604","317","0","2"],["9.603","525","0","2"],["9.602","76","0","1"],["9.601","50","0","2"],["9.599","620","0","2"],["9.598","25","0","1"]],"ts":"1646003675824","checksum":943248379}]}
1646003675.842989: {"arg":{"channel":"books-l2-tbt","instId":"ZEN-USDT"},"action":"update","data":[{"asks":[["32.56","29.020226","0","2"]],"bids":[["32.44","153.9222","0","4"]],"ts":"1646003675830","checksum":-627861101}]}
1646003675.8431082: {"arg":{"channel":"books-l2-tbt","instId":"ELON-USDT"},"action":"update","data":[{"asks":[["0.00000074594","445226872","0","1"],["0.0000011372","0","0","0"]],"bids":[],"ts":"1646003675831","checksum":-1235987322}]}
1646003675.865483: {"arg":{"channel":"books-l2-tbt","instId":"ELON-USDT"},"action":"update","data":[{"asks":[["0.00000074595","0","0","0"],["0.00000074596","0","0","0"],["0.0000011372","6179288","0","1"],["0.00000113812","12211658","0","1"]],"bids":[],"ts":"1646003675854","checksum":-809854281}]}
1646003675.884663: {"arg":{"channel":"books-l2-tbt","instId":"ELON-USDT"},"action":"update","data":[{"asks":[["0.00000074593","215794710","0","2"],["0.00000113812","0","0","0"]],"bids":[],"ts":"1646003675873","checksum":332987605}]}
1646003675.9035678: {"arg":{"channel":"books-l2-tbt","instId":"ELON-USDT"},"action":"update","data":[{"asks":[["0.00000074593","337472779","0","4"],["0.00000074594","0","0","0"],["0.00000074597","0","0","0"],["0.00000113812","12211658","0","1"],["0.00000113853","6145556","0","1"]],"bids":[],"ts":"1646003675893","checksum":-2138997409}]}
1646003675.9259589: {"arg":{"channel":"books-l2-tbt","instId":"ELON-USDT"},"action":"update","data":[{"asks":[["0.00000074593","121678069","0","2"],["0.00000074596","445226872","0","1"],["0.00000113853","0","0","0"]],"bids":[["0.00000070254","0","0","0"],["0.00000068849","0","0","0"],["0.00000067473","0","0","0"],["0.00000066124","0","0","0"],["0.00000064798","290636656","0","1"]],"ts":"1646003675915","checksum":17969483}]}
1646003675.956084: {"arg":{"channel":"books-l2-tbt","instId":"ELON-USDT"},"action":"update","data":[{"asks":[["0.00000074595","111748770","0","1"],["0.00000113812","0","0","0"]],"bids":[],"ts":"1646003675936","checksum":-2017031010}]}
1646003675.956172: {"arg":{"channel":"books-l2-tbt","instId":"ELON-USDT"},"action":"update","data":[{"asks":[["0.00000074592","445226872","0","1"],["0.0000011372","0","0","0"]],"bids":[],"ts":"1646003675945","checksum":-815391764}]}
1646003675.977373: {"arg":{"channel":"books-l2-tbt","instId":"ELON-USDT"},"action":"update","data":[{"asks":[["0.00000074595","0","0","0"],["0.00000074596","0","0","0"],["0.0000011372","6179288","0","1"],["0.00000113812","12211658","0","1"]],"bids":[],"ts":"1646003675966","checksum":-1554401541}]}
1646003675.985844: {"arg":{"channel":"books-l2-tbt","instId":"ELON-USDT"},"action":"update","data":[{"asks":[],"bids":[["0.00000074451","219861835","0","1"]],"ts":"1646003675975","checksum":-783229613}]}
1646003676.014068: {"arg":{"channel":"books-l2-tbt","instId":"ZEN-USDT"},"action":"update","data":[{"asks":[["32.65","113.847704","0","2"]],"bids":[],"ts":"1646003675983","checksum":685097781}]}
1646003676.014148: {"arg":{"channel":"books-l2-tbt","instId":"ELON-USDT"},"action":"update","data":[{"asks":[],"bids":[["0.00000074452","184440410","0","1"],["0.000000726","1489169273","0","3"]],"ts":"1646003675997","checksum":432008483}]}
1646003676.0202398: {"arg":{"channel":"books-l2-tbt","instId":"ELON-USDT"},"action":"update","data":[{"asks":[["0.00000074599","0","0","0"],["0.00000113853","6145556","0","1"]],"bids":[],"ts":"1646003676007","checksum":864311741}]}
1646003676.0311701: {"arg":{"channel":"books-l2-tbt","instId":"UNI-USD-SWAP"},"action":"update","data":[{"asks":[["9.632","426","0","2"],["9.635","36","0","2"]],"bids":[["9.612","0","0","0"]],"ts":"1646003676017","checksum":121999720}]}
1646003676.05791: {"arg":{"channel":"books-l2-tbt","instId":"UNI-USD-SWAP"},"action":"update","data":[{"asks":[],"bids":[["9.613","276","0","4"]],"ts":"1646003676026","checksum":-41103579}]}
1646003676.0597491: {"arg":{"channel":"books-l2-tbt","instId":"UNI-USD-SWAP"},"action":"update","data":[{"asks":[["9.635","20","0","2"]],"bids":[],"ts":"1646003676038","checksum":-1246383833}]}
1646003676.059832: {"arg":{"channel":"books-l2-tbt","instId":"ELON-USDT"},"action":"update","data":[{"asks":[["0.00000076199","0","0","0"],["0.00000113879","5262112","0","1"]],"bids":[["0.00000074435","0","0","0"]],"ts":"1646003676039","checksum":-671562009}]}
1646003676.0741131: {"arg":{"channel":"books-l2-tbt","instId":"UNI-USD-SWAP"},"action":"update","data":[{"asks":[["9.622","260","0","1"]],"bids":[["9.61","7","0","2"],["9.609","0","0","0"],["9.597","18","0","1"],["9.596","0","0","0"]],"ts":"1646003676059","checksum":939563303}]}
1646003676.08025: {"arg":{"channel":"books-l2-tbt","instId":"UNI-USD-SWAP"},"action":"update","data":[{"asks":[["9.623","88","0","1"],["47.903","0","0","0"]],"bids":[],"ts":"1646003676068","checksum":-1674113318}]}
1646003676.0920691: {"arg":{"channel":"books-l2-tbt","instId":"UNI-USD-SWAP"},"action":"update","data":[{"asks":[],"bids":[["9.609","4","0","1"],["9.575","0","0","0"]],"ts":"1646003676081","checksum":317840180}]}
1646003676.100842: {"arg":{"channel":"books-l2-tbt","instId":"UNI-USD-SWAP"},"action":"update","data":[{"asks":[["9.643","21","0","1"],["9.644","0","0","0"],["9.646","37","0","2"],["9.647","2554","0","5"],["9.649","271","0","3"],["9.65","225","0","1"]],"bids":[["9.611","1","0","1"],["9.61","0","0","0"],["9.598","41","0","2"],["9.597","0","0","0"]],"ts":"1646003676090","checksum":-1769622306}]}
