1646003676.113796: {"arg":{"channel":"books-l2-tbt","instId":"ELON-USDT"},"action":"update","data":[{"asks":[["0.00000074591","52357697","0","1"],["0.00000074593","68570346","0","1"],["0.00000113879","0","0","0"]],"bids":[],"ts":"1646003676100","checksum":1645648270}]}
1646003676.1139321: {"arg":{"channel":"books-l2-tbt","instId":"UNI-USD-SWAP"},"action":"update","data":[{"asks":[],"bids":[["9.576","1566","0","3"]],"ts":"1646003676101","checksum":-1769622306}]}
1646003676.136061: {"arg":{"channel":"books-l2-tbt","instId":"ELON-USDT"},"action":"update","data":[{"asks":[["0.00000074593","0","0","0"],["0.00000074594","81175250","0","1"]],"bids":[],"ts":"1646003676111","checksum":-1025702872}]}
1646003676.1361861: {"arg":{"channel":"books-l2-tbt","instId":"ELON-USDT"},"action":"update","data":[{"asks":[["0.00000074591","204419310","0","3"],["0.00000074698","4038943392","0","1"],["0.00000113853","0","0","0"]],"bids":[],"ts":"1646003676122","checksum":-342343929}]}
1646003676.1431801: {"arg":{"channel":"books-l2-tbt","instId":"ELON-USDT"},"action":"update","data":[{"asks":[["0.0000007459","396592311","0","1"],["0.00000113812","0","0","0"]],"bids":[],"ts":"1646003676132","checksum":624387274}]}
1646003676.167996: {"arg":{"channel":"books-l2-tbt","instId":"ELON-USDT"},"action":"update","data":[{"asks":[["0.00000074591","52357697","0","1"],["0.00000074592","0","0","0"],["0.00000074698","0","0","0"],["0.00000113812","12211658","0","1"],["0.00000113853","6145556","0","1"]],"bids":[["0.00000074381","60964668","0","1"]],"ts":"1646003676151","checksum":-2054606058}]}
1646003676.177541: {"arg":{"channel":"books-l2-tbt","instId":"ELON-USDT"},"action":"update","data":[{"asks":[["0.00000074698","4038943392","0","1"],["0.00000113853","0","0","0"]],"bids":[],"ts":"1646003676163","checksum":-841243323}]}
1646003676.186155: {"arg":{"channel":"books-l2-tbt","instId":"UNI-USD-SWAP"},"action":"update","data":[{"asks":[],"bids":[["9.611","0","0","0"],["9.61","6","0","1"]],"ts":"1646003676172","checksum":-930161633}]}
1646003676.186249: {"arg":{"channel":"books-l2-tbt","instId":"ELON-USDT"},"action":"update","data":[{"asks":[["0.00000074589","152061613","0","2"],["0.00000113812","0","0","0"]],"bids":[["0.00000074452","0","0","0"],["0.00000074273","0","0","0"]],"ts":"1646003676175","checksum":698798905}]}
1646003676.195071: {"arg":{"channel":"books-l2-tbt","instId":"ELON-USDT"},"action":"update","data":[{"asks":[["0.00000074589","263810383","0","3"]],"bids":[["0.00000074329","4038943392","0","1"]],"ts":"1646003676182","checksum":-15113645}]}
1646003676.205583: {"arg":{"channel":"books-l2-tbt","instId":"UNI-USD-SWAP"},"action":"update","data":[{"asks":[],"bids":[["9.61","0","0","0"]],"ts":"1646003676194","checksum":1762912642}]}
1646003676.217538: {"arg":{"channel":"books-l2-tbt","instId":"ELON-USDT"},"action":"update","data":[{"asks":[],"bids":[["0.00000074381","0","0","0"]],"ts":"1646003676203","checksum":978413533}]}
1646003676.2265081: {"arg":{"channel":"books-l2-tbt","instId":"ELON-USDT"},"action":"update","data":[{"asks":[],"bids":[["0.00000074202","184440410","0","1"]],"ts":"1646003676215","checksum":1198841172}]}
1646003676.2361212: {"arg":{"channel":"books-l2-tbt","instId":"ELON-USDT"},"action":"update","data":[{"asks":[["0.00000074588","445226872","0","1"],["0.0000011372","0","0","0"]],"bids":[],"ts":"1646003676225","checksum":1071103862}]}
1646003676.2361941: {"arg":{"channel":"books-l2-tbt","instId":"UNI-USD-SWAP"},"action":"update","data":[{"asks":[["9.635","21","0","2"]],"bids":[],"ts":"1646003676225","checksum":-586020814}]}
1646003676.2461429: {"arg":{"channel":"books-l2-tbt","instId":"UNI-USD-SWAP"},"action":"update","data":[{"asks":[],"bids":[["9.61","5","0","1"]],"ts":"1646003676235","checksum":1649522615}]}
1646003676.246849: {"arg":{"channel":"books-l2-tbt","instId":"ELON-USDT"},"action":"update","data":[{"asks":[["0.0000007459","0","0","0"],["0.0000011372","6179288","0","1"]],"bids":[["0.00000074202","0","0","0"],["0.0000007273","583426138","0","2"]],"ts":"1646003676237","checksum":1627629895}]}
1646003676.262184: {"arg":{"channel":"books-l2-tbt","instId":"ELON-USDT"},"action":"update","data":[{"asks":[["0.00000074589","0","0","0"],["0.00000113812","12211658","0","1"]],"bids":[],"ts":"1646003676245","checksum":815037674}]}
1646003676.262259: {"arg":{"channel":"books-l2-tbt","instId":"UNI-USD-SWAP"},"action":"update","data":[{"asks":[],"bids":[["9.61","0","0","0"]],"ts":"1646003676246","checksum":-586020814}]}
1646003676.268598: {"arg":{"channel":"books-l2-tbt","instId":"UNI-USD-SWAP"},"action":"update","data":[{"asks":[["9.635","26","0","2"]],"bids":[],"ts":"1646003676255","checksum":1744150688}]}
1646003676.268676: {"arg":{"channel":"books-l2-tbt","instId":"ELON-USDT"},"action":"update","data":[{"asks":[["0.00000074587","263810383","0","3"],["0.00000113812","0","0","0"]],"bids":[],"ts":"1646003676257","checksum":-1218971883}]}
1646003676.280406: {"arg":{"channel":"books-l2-tbt","instId":"ELON-USDT"},"action":"update","data":[{"asks":[],"bids":[["0.00000074435","48747378","0","1"]],"ts":"1646003676268","checksum":375209243}]}
1646003676.2898638: {"arg":{"channel":"books-l2-tbt","instId":"ELON-USDT"},"action":"update","data":[{"asks":[["0.0000007459","445226872","0","1"],["0.0000011372","0","0","0"]],"bids":[],"ts":"1646003676279","checksum":215649071}]}
1646003676.300713: {"arg":{"channel":"books-l2-tbt","instId":"ELON-USDT"},"action":"update","data":[{"asks":[],"bids":[["0.00000074381","99313213","0","1"]],"ts":"1646003676288","checksum":765340890}]}
1646003676.316191: {"arg":{"channel":"books-l2-tbt","instId":"PROPS-ETH"},"action":"update","data":[{"asks":[["0.00000176","8273.79459358","0","2"],["0.00000178","0","0","0"],["0.00000183","1082.81907257","0","1"],["0.00000184","1363.58258369","0","1"],["0.00000185","0","0","0"],["0.00000187","0","0","0"]],"bids":[["0.00000161","0","0","0"],["0.0000016","11101.75188717","0","1"]],"ts":"1646003676303","checksum":-1219126102}]}
1646003676.320299: {"arg":{"channel":"books-l2-tbt","instId":"UNI-USD-SWAP"},"action":"update","data":[{"asks":[["9.662","0","0","0"],["47.903","1","0","1"]],"bids":[],"ts":"1646003676308","checksum":1744150688}]}
1646003676.333525: {"arg":{"channel":"books-l2-tbt","instId":"ELON-USDT"},"action":"update","data":[{"asks":[["0.00000074587","385488452","0","5"],["0.00000074588","0","0","0"],["0.00000074591","0","0","0"],["0.0000011372","6179288","0","1"],["0.00000113812","12211658","0","1"]],"bids":[],"ts":"1646003676310","checksum":639804227}]}
1646003676.333673: {"arg":{"channel":"books-l2-tbt","instId":"ELON-USDT"},"action":"update","data":[{"asks":[],"bids":[["0.00000074435","0","0","0"]],"ts":"1646003676319","checksum":270378911}]}
1646003676.333725: {"arg":{"channel":"books-l2-tbt","instId":"UNI-USD-SWAP"},"action":"update","data":[{"asks":[["9.66","11","0","1"],["47.903","0","0","0"]],"bids":[],"ts":"1646003676320","checksum":1744150688}]}
1646003676.341664: {"arg":{"channel":"books-l2-tbt","instId":"ELON-USDT"},"action":"update","data":[{"asks":[["0.00000074587","121678069","0","2"]],"bids":[],"ts":"1646003676329","checksum":43194030}]}
1646003676.359963: {"arg":{"channel":"books-l2-tbt","instId":"ELON-USDT"},"action":"update","data":[{"asks":[["0.00000074586","159764443","0","2"],["0.00000113812","0","0","0"]],"bids":[],"ts":"1646003676340","checksum":1766624679}]}
1646003676.36314: {"arg":{"channel":"books-l2-tbt","instId":"UNI-USD-SWAP"},"action":"update","data":[{"asks":[["9.643","0","0","0"],["9.646","16","0","1"],["9.649","242","0","2"],["47.903","1","0","1"]],"bids":[],"ts":"1646003676350","checksum":1687486466}]}
1646003676.363234: {"arg":{"channel":"books-l2-tbt","instId":"ELON-USDT"},"action":"update","data":[{"asks":[["0.00000074586","445226872","0","1"]],"bids":[],"ts":"1646003676350","checksum":-2118049556}]}
1646003676.373358: {"arg":{"channel":"books-l2-tbt","instId":"UNI-USD-SWAP"},"action":"update","data":[{"asks":[["9.645","778","0","4"],["9.648","29","0","2"],["9.651","109","0","3"]],"bids":[],"ts":"1646003676360","checksum":-46866930}]}
1646003676.373485: {"arg":{"channel":"books-l2-tbt","instId":"ELON-USDT"},"action":"update","data":[{"asks":[["0.00000074585","159764443","0","2"],["0.0000011372","0","0","0"]],"bids":[["0.00000074381","0","0","0"]],"ts":"1646003676360","checksum":-225473235}]}
1646003676.393334: {"arg":{"channel":"books-l2-tbt","instId":"ELON-USDT"},"action":"update","data":[{"asks":[["0.00000074585","48015673","0","1"]],"bids":[],"ts":"1646003676382","checksum":-1226968630}]}
1646003676.40383: {"arg":{"channel":"books-l2-tbt","instId":"ELON-USDT"},"action":"update","data":[{"asks":[["0.0000007459","0","0","0"],["0.0000011372","6179288","0","1"]],"bids":[["0.0000007433","115779331","0","1"]],"ts":"1646003676393","checksum":738128374}]}
1646003676.413592: {"arg":{"channel":"books-l2-tbt","instId":"ZEN-USDT"},"action":"update","data":[{"asks":[["32.61","0","0","0"],["44.27","0.000092","0","1"]],"bids":[],"ts":"1646003676402","checksum":1250060399}]}
1646003676.425548: {"arg":{"channel":"books-l2-tbt","instId":"ELON-USDT"},"action":"update","data":[{"asks":[],"bids":[["0.00000074451","0","0","0"],["0.0000006993","228377722","0","1"],["0.00000068532","429552961","0","1"],["0.00000067162","188503780","0","1"],["0.00000065819","406726861","0","1"]],"ts":"1646003676414","checksum":182866012}]}
1646003676.436813: {"arg":{"channel":"books-l2-tbt","instId":"ELON-USDT"},"action":"update","data":[{"asks":[],"bids":[["0.00000064798","0","0","0"]],"ts":"1646003676423","checksum":182866012}]}
1646003676.447886: {"arg":{"channel":"books-l2-tbt","instId":"UNI-USD-SWAP"},"action":"update","data":[{"asks":[],"bids":[["9.61","6","0","1"]],"ts":"1646003676432","checksum":-1921830267}]}
1646003676.447995: {"arg":{"channel":"books-l2-tbt","instId":"ELON-USDT"},"action":"update","data":[{"asks":[["0.00000074584","445226872","0","1"],["0.0000011372","0","0","0"]],"bids":[],"ts":"1646003676433","checksum":-694316277}]}
1646003676.457268: {"arg":{"channel":"books-l2-tbt","instId":"ELON-USDT"},"action":"update","data":[{"asks":[],"bids":[["0.00000074218","2935464172","0","1"]],"ts":"1646003676446","checksum":1177337524}]}
1646003676.4750888: {"arg":{"channel":"books-l2-tbt","instId":"UNI-USD-SWAP"},"action":"update","data":[{"asks":[["9.635","21","0","2"]],"bids":[],"ts":"1646003676454","checksum":2010785995}]}
1646003676.475198: {"arg":{"channel":"books-l2-tbt","instId":"ELON-USDT"},"action":"update","data":[{"asks":[["0.00000074585","0","0","0"],["0.0000011372","6179288","0","1"]],"bids":[],"ts":"1646003676455","checksum":1034350156}]}
1646003676.482812: {"arg":{"channel":"books-l2-tbt","instId":"ELON-USDT"},"action":"update","data":[{"asks":[],"bids":[["0.00000072648","0","0","0"]],"ts":"1646003676467","checksum":1034350156}]}
1646003676.4871: {"arg":{"channel":"books-l2-tbt","instId":"UNI-USD-SWAP"},"action":"update","data":[{"asks":[["9.635","20","0","2"]],"bids":[],"ts":"1646003676475","checksum":396335634}]}
1646003676.487176: {"arg":{"channel":"books-l2-tbt","instId":"ZEN-USDT"},"action":"update","data":[{"asks":[],"bids":[["32.41","0","0","0"]],"ts":"1646003676476","checksum":-1142433698}]}
1646003676.489119: {"arg":{"channel":"books-l2-tbt","instId":"ELON-USDT"},"action":"update","data":[{"asks":[["0.00000074586","0","0","0"],["0.00000113812","12211658","0","1"]],"bids":[],"ts":"1646003676478","checksum":-1175054313}]}
1646003676.511818: {"arg":{"channel":"books-l2-tbt","instId":"UNI-USD-SWAP"},"action":"update","data":[{"asks":[["9.645","748","0","3"],["9.654","9304","0","3"]],"bids":[],"ts":"1646003676496","checksum":41650365}]}
1646003676.511936: {"arg":{"channel":"books-l2-tbt","instId":"ELON-USDT"},"action":"update","data":[{"asks":[],"bids":[["0.0000007433","0","0","0"]],"ts":"1646003676497","checksum":1324875298}]}
1646003676.520067: {"arg":{"channel":"books-l2-tbt","instId":"ELON-USDT"},"action":"update","data":[{"asks":[["0.00000074584","0","0","0"],["0.00000113853","6145556","0","1"]],"bids":[["0.00000074435","100566103","0","1"]],"ts":"1646003676507","checksum":1825518884}]}
1646003676.529502: {"arg":{"channel":"books-l2-tbt","instId":"UNI-USD-SWAP"},"action":"update","data":[{"asks":[["9.663","16","0","1"]],"bids":[["9.615","342","0","3"]],"ts":"1646003676517","checksum":893142677}]}
1646003676.5295832: {"arg":{"channel":"books-l2-tbt","instId":"ELON-USDT"},"action":"update","data":[{"asks":[["0.00000074583","52357697","0","1"],["0.00000074587","0","0","0"],["0.00000074732","0","0","0"],["0.00000113879","5262112","0","1"]],"bids":[],"ts":"1646003676519","checksum":875288448}]}
1646003676.542048: {"arg":{"channel":"books-l2-tbt","instId":"ELON-USDT"},"action":"update","data":[{"asks":[["0.00000074586","549272812","0","2"],["0.00000113879","0","0","0"]],"bids":[],"ts":"1646003676529","checksum":-504704838}]}
1646003676.5506492: {"arg":{"channel":"books-l2-tbt","instId":"ELON-USDT"},"action":"update","data":[{"asks":[["0.00000074586","445226872","0","1"],["0.00000074739","3602615120","0","1"],["0.00000113853","0","0","0"]],"bids":[],"ts":"1646003676539","checksum":-1013325598}]}
1646003676.552866: {"arg":{"channel":"books-l2-tbt","instId":"UNI-USD-SWAP"},"action":"update","data":[{"asks":[["9.66","0","0","0"],["48.143","1","0","1"]],"bids":[],"ts":"1646003676541","checksum":893142677}]}
1646003676.561991: {"arg":{"channel":"books-l2-tbt","instId":"ELON-USDT"},"action":"update","data":[{"asks":[["0.00000074585","104045940","0","1"],["0.00000113812","0","0","0"]],"bids":[],"ts":"1646003676549","checksum":-470544728}]}
1646003676.580522: {"arg":{"channel":"books-l2-tbt","instId":"ELON-USDT"},"action":"update","data":[{"asks":[["0.00000074582","56873219","0","1"],["0.0000011372","0","0","0"]],"bids":[],"ts":"1646003676569","checksum":-30325545}]}
1646003676.6039748: {"arg":{"channel":"books-l2-tbt","instId":"ELON-USDT"},"action":"update","data":[{"asks":[["0.00000074585","215794710","0","2"],["0.00000074594","0","0","0"],["0.0000011372","6179288","0","1"]],"bids":[],"ts":"1646003676590","checksum":-495452722}]}
1646003676.6094: {"arg":{"channel":"books-l2-tbt","instId":"UNI-USD-SWAP"},"action":"update","data":[{"asks":[["9.661","521","0","2"]],"bids":[],"ts":"1646003676592","checksum":893142677}]}
1646003676.6231198: {"arg":{"channel":"books-l2-tbt","instId":"ELON-USDT"},"action":"update","data":[{"asks":[["0.00000074586","0","0","0"],["0.00000113812","12211658","0","1"]],"bids":[],"ts":"1646003676601","checksum":1145387950}]}
1646003676.623206: {"arg":{"channel":"books-l2-tbt","instId":"UNI-USD-SWAP"},"action":"update","data":[{"asks":[["9.634","564","0","2"],["9.638","135","0","3"],["9.645","774","0","4"],["9.654","9280","0","2"]],"bids":[["9.605","54","0","2"],["9.601","25","0","1"],["9.6","29","0","1"],["9.598","16","0","1"]],"ts":"1646003676601","checksum":-1243969246}]}
1646003676.627581: {"arg":{"channel":"books-l2-tbt","instId":"UNI-USD-SWAP"},"action":"update","data":[{"asks":[],"bids":[["9.613","223","0","3"]],"ts":"1646003676614","checksum":-1118995119}]}
1646003676.635812: {"arg":{"channel":"books-l2-tbt","instId":"ELON-USDT"},"action":"update","data":[{"asks":[["0.00000074585","0","0","0"],["0.00000113853","6145556","0","1"]],"bids":[],"ts":"1646003676620","checksum":906227372}]}
1646003676.6410801: {"arg":{"channel":"books-l2-tbt","instId":"UNI-USD-SWAP"},"action":"update","data":[{"asks":[],"bids":[["9.614","53","0","1"]],"ts":"1646003676624","checksum":-108853373}]}
1646003676.6524951: {"arg":{"channel":"books-l2-tbt","instId":"ELON-USDT"},"action":"update","data":[{"asks":[["0.00000074599","215794710","0","2"],["0.00000113853","0","0","0"]],"bids":[],"ts":"1646003676640","checksum":323896185}]}
1646003676.658892: {"arg":{"channel":"books-l2-tbt","instId":"UNI-USD-SWAP"},"action":"update","data":[{"asks":[["9.628","3","0","1"],["48.143","0","0","0"]],"bids":[],"ts":"1646003676647","checksum":1240609758}]}
1646003676.679984: {"arg":{"channel":"books-l2-tbt","instId":"UNI-USD-SWAP"},"action":"update","data":[{"asks":[["9.628","97","0","2"],["9.629","12","0","1"]],"bids":[],"ts":"1646003676664","checksum":1904910685}]}
1646003676.683499: {"arg":{"channel":"books-l2-tbt","instId":"ELON-USDT"},"action":"update","data":[{"asks":[["0.00000074584","81175250","0","1"],["0.00000113812","0","0","0"]],"bids":[],"ts":"1646003676673","checksum":2037222829}]}
1646003676.695195: {"arg":{"channel":"books-l2-tbt","instId":"UNI-USD-SWAP"},"action":"update","data":[{"asks":[["9.624","0","0","0"],["9.661","510","0","1"],["48.143","1","0","1"]],"bids":[],"ts":"1646003676676","checksum":-622663287}]}
1646003676.697383: {"arg":{"channel":"books-l2-tbt","instId":"UNI-USD-SWAP"},"action":"update","data":[{"asks":[["9.633","21","0","2"],["9.635","11","0","1"]],"bids":[],"ts":"1646003676685","checksum":2111482651}]}
1646003676.71221: {"arg":{"channel":"books-l2-tbt","instId":"ELON-USDT"},"action":"update","data":[{"asks":[["0.00000074581","48015673","0","1"],["0.00000074599","0","0","0"]],"bids":[],"ts":"1646003676695","checksum":1010087508}]}
1646003676.718889: {"arg":{"channel":"books-l2-tbt","instId":"UNI-USD-SWAP"},"action":"update","data":[{"asks":[["9.627","2","0","1"],["9.628","94","0","1"],["48.143","0","0","0"]],"bids":[],"ts":"1646003676706","checksum":-1262317548}]}
1646003676.726096: {"arg":{"channel":"books-l2-tbt","instId":"ELON-USDT"},"action":"update","data":[{"asks":[["0.00000074581","263810383","0","3"]],"bids":[],"ts":"1646003676715","checksum":-1203881176}]}
1646003676.7310662: {"arg":{"channel":"books-l2-tbt","instId":"UNI-USD-SWAP"},"action":"update","data":[{"asks":[["9.633","3","0","1"],["9.637","1267","0","3"]],"bids":[],"ts":"1646003676716","checksum":254104545}]}
1646003676.7357419: {"arg":{"channel":"books-l2-tbt","instId":"ELON-USDT"},"action":"update","data":[{"asks":[["0.00000074581","385488452","0","5"],["0.00000074583","0","0","0"],["0.00000113812","12211658","0","1"]],"bids":[],"ts":"1646003676725","checksum":1872111968}]}
1646003676.746187: {"arg":{"channel":"books-l2-tbt","instId":"ELON-USDT"},"action":"update","data":[{"asks":[["0.0000007458","445226872","0","1"],["0.00000074581","281442512","0","4"],["0.00000113812","0","0","0"]],"bids":[],"ts":"1646003676735","checksum":1042175521}]}
1646003676.770902: {"arg":{"channel":"books-l2-tbt","instId":"ELON-USDT"},"action":"update","data":[{"asks":[["0.00000074581","121678069","0","2"]],"bids":[],"ts":"1646003676756","checksum":-1455114633}]}
1646003676.77097: {"arg":{"channel":"books-l2-tbt","instId":"UNI-USD-SWAP"},"action":"update","data":[{"asks":[],"bids":[["9.614","0","0","0"],["9.61","0","0","0"]],"ts":"1646003676759","checksum":-498155996}]}
1646003676.791274: {"arg":{"channel":"books-l2-tbt","instId":"ELON-USDT"},"action":"update","data":[{"asks":[["0.00000074579","159764443","0","2"],["0.00000074582","0","0","0"]],"bids":[],"ts":"1646003676778","checksum":1192799496}]}
1646003676.802625: {"arg":{"channel":"books-l2-tbt","instId":"PROPS-ETH"},"action":"update","data":[{"asks":[["0.00000176","7518.11950204","0","1"],["0.00000178","892.60196586","0","1"],["0.00000183","0","0","0"],["0.00000184","0","0","0"],["0.00000185","1493.91414492","0","1"],["0.00000186","859.07496822","0","1"],["0.00000187","1277.98353831","0","1"]],"bids":[["0.00000161","10374.91660435","0","1"],["0.0000016","0","0","0"]],"ts":"1646003676791","checksum":-1632459326}]}
1646003676.8167481: {"arg":{"channel":"books-l2-tbt","instId":"ZEN-USDT"},"action":"update","data":[{"asks":[],"bids":[["32.41","35.959536","0","1"]],"ts":"1646003676805","checksum":1250060399}]}
1646003676.826598: {"arg":{"channel":"books-l2-tbt","instId":"UNI-USD-SWAP"},"action":"update","data":[{"asks":[["9.627","0","0","0"],["48.143","1","0","1"]],"bids":[],"ts":"1646003676812","checksum":-1949485901}]}
1646003676.83331: {"arg":{"channel":"books-l2-tbt","instId":"UNI-USD-SWAP"},"action":"update","data":[{"asks":[],"bids":[["9.613","276","0","4"]],"ts":"1646003676822","checksum":-2091204416}]}
1646003676.841805: {"arg":{"channel":"books-l2-tbt","instId":"ZEN-USDT"},"action":"update","data":[{"asks":[["32.55","5.939722","0","2"],["32.57","25.741693","0","3"]],"bids":[],"ts":"1646003676827","checksum":-97224793}]}
1646003676.8515022: {"arg":{"channel":"books-l2-tbt","instId":"ELON-USDT"},"action":"update","data":[{"asks":[["0.00000074578","445226872","0","1"],["0.0000007549","210944203","0","1"],["0.0000011338","0","0","0"],["0.0000011372","0","0","0"]],"bids":[],"ts":"1646003676839","checksum":-1598990687}]}
1646003676.854558: {"arg":{"channel":"books-l2-tbt","instId":"UNI-USD-SWAP"},"action":"update","data":[{"asks":[["9.624","1","0","1"],["48.143","0","0","0"]],"bids":[],"ts":"1646003676843","checksum":370460236}]}
1646003676.862203: {"arg":{"channel":"books-l2-tbt","instId":"ELON-USDT"},"action":"update","data":[{"asks":[],"bids":[["0.00000074449","219861835","0","1"],["0.00000074335","1624000000","0","1"]],"ts":"1646003676850","checksum":-1197730607}]}
1646003676.864322: {"arg":{"channel":"books-l2-tbt","instId":"UNI-USD-SWAP"},"action":"update","data":[{"asks":[["9.658","11","0","1"],["9.663","95","0","2"],["47.903","0","0","0"]],"bids":[],"ts":"1646003676853","checksum":370460236}]}
1646003676.874184: {"arg":{"channel":"books-l2-tbt","instId":"ELON-USDT"},"action":"update","data":[{"asks":[["0.00000074579","0","0","0"],["0.0000011338","129154981","0","1"]],"bids":[],"ts":"1646003676862","checksum":284414609}]}
1646003676.8857138: {"arg":{"channel":"books-l2-tbt","instId":"ELON-USDT"},"action":"update","data":[{"asks":[["0.00000074577","111748770","0","1"],["0.0000011338","0","0","0"]],"bids":[],"ts":"1646003676871","checksum":-930346474}]}
1646003676.896257: {"arg":{"channel":"books-l2-tbt","instId":"ELON-USDT"},"action":"update","data":[{"asks":[["0.0000007458","0","0","0"],["0.0000011338","129154981","0","1"]],"bids":[],"ts":"1646003676882","checksum":-183555726}]}
1646003676.89632: {"arg":{"channel":"books-l2-tbt","instId":"ETH-USD-220624-12000-P"},"action":"update","data":[{"asks":[["4.044","201","0","1"],["4.045","0","0","0"]],"bids":[],"ts":"1646003676883","checksum":-1757458992}]}
1646003676.9274292: {"arg":{"channel":"books-l2-tbt","instId":"ELON-USDT"},"action":"update","data":[{"asks":[],"bids":[["0.0000007445","184440410","0","1"],["0.0000006993","0","0","0"],["0.00000068532","0","0","0"],["0.00000067162","0","0","0"],["0.00000065819","0","0","0"],["0.00000064475","455711263","0","1"]],"ts":"1646003676915","checksum":-2081544253}]}
1646003676.949787: {"arg":{"channel":"books-l2-tbt","instId":"ELON-USDT"},"action":"update","data":[{"asks":[["0.00000074577","268152407","0","3"],["0.00000074581","0","0","0"],["0.0000011372","6179288","0","1"]],"bids":[],"ts":"1646003676936","checksum":1410954710}]}
1646003676.960397: {"arg":{"channel":"books-l2-tbt","instId":"ELON-USDT"},"action":"update","data":[{"asks":[],"bids":[["0.00000074435","0","0","0"],["0.00000074335","0","0","0"]],"ts":"1646003676945","checksum":-20168676}]}
1646003676.97456: {"arg":{"channel":"books-l2-tbt","instId":"ELON-USDT"},"action":"update","data":[{"asks":[["0.00000074576","305535631","0","1"],["0.0000011372","0","0","0"]],"bids":[],"ts":"1646003676955","checksum":-1863826773}]}
1646003676.987348: {"arg":{"channel":"books-l2-tbt","instId":"ELON-USDT"},"action":"update","data":[{"asks":[["0.00000074577","52357697","0","1"]],"bids":[],"ts":"1646003676975","checksum":-1790095370}]}
1646003676.9985988: {"arg":{"channel":"books-l2-tbt","instId":"ELON-USDT"},"action":"update","data":[{"asks":[["0.00000074578","0","0","0"],["0.0000011372","6179288","0","1"]],"bids":[],"ts":"1646003676985","checksum":-2026764407}]}
1646003677.006954: {"arg":{"channel":"books-l2-tbt","instId":"ELON-USDT"},"action":"update","data":[{"asks":[["0.00000074575","104045940","0","1"],["0.0000011372","0","0","0"]],"bids":[],"ts":"1646003676994","checksum":633799582}]}
1646003677.059402: {"arg":{"channel":"books-l2-tbt","instId":"ELON-USDT"},"action":"update","data":[{"asks":[["0.00000074574","445226872","0","1"],["0.0000011338","0","0","0"]],"bids":[],"ts":"1646003677035","checksum":-503169759}]}
1646003677.068882: {"arg":{"channel":"books-l2-tbt","instId":"ELON-USDT"},"action":"update","data":[{"asks":[["0.00000074575","0","0","0"],["0.00000074576","0","0","0"],["0.0000011338","129154981","0","1"],["0.0000011372","6179288","0","1"]],"bids":[],"ts":"1646003677058","checksum":-762314720}]}
1646003677.088589: {"arg":{"channel":"books-l2-tbt","instId":"UNI-USD-SWAP"},"action":"update","data":[{"asks":[["9.628","0","0","0"],["9.629","106","0","2"],["47.903","1","0","1"]],"bids":[],"ts":"1646003677076","checksum":-539633318}]}
1646003677.0962079: {"arg":{"channel":"books-l2-tbt","instId":"ELON-USDT"},"action":"update","data":[{"asks":[["0.00000074573","48015673","0","1"],["0.0000011372","0","0","0"]],"bids":[],"ts":"1646003677077","checksum":1043923674}]}
1646003677.102881: {"arg":{"channel":"books-l2-tbt","instId":"ELON-USDT"},"action":"update","data":[{"asks":[["0.00000074573","152061613","0","2"]],"bids":[],"ts":"1646003677088","checksum":1348657804}]}
1646003677.109306: {"arg":{"channel":"books-l2-tbt","instId":"UNI-USD-SWAP"},"action":"update","data":[{"asks":[["9.629","133","0","2"]],"bids":[],"ts":"1646003677096","checksum":-1132212754}]}
1646003677.115392: {"arg":{"channel":"books-l2-tbt","instId":"ELON-USDT"},"action":"update","data":[{"asks":[["0.00000074574","0","0","0"],["0.0000011372","6179288","0","1"]],"bids":[],"ts":"1646003677099","checksum":1187935414}]}
1646003677.122126: {"arg":{"channel":"books-l2-tbt","instId":"ELON-USDT"},"action":"update","data":[{"asks":[["0.00000074572","445226872","0","1"],["0.0000011372","0","0","0"]],"bids":[],"ts":"1646003677110","checksum":-668683205}]}
1646003677.1308548: {"arg":{"channel":"books-l2-tbt","instId":"UNI-USD-SWAP"},"action":"update","data":[{"asks":[["9.628","3","0","1"],["47.903","0","0","0"]],"bids":[],"ts":"1646003677117","checksum":2044703279}]}
1646003677.130974: {"arg":{"channel":"books-l2-tbt","instId":"ELON-USDT"},"action":"update","data":[{"asks":[["0.00000074573","0","0","0"],["0.0000011372","6179288","0","1"]],"bids":[],"ts":"1646003677118","checksum":484373587}]}
1646003677.144768: {"arg":{"channel":"books-l2-tbt","instId":"ELON-USDT"},"action":"update","data":[{"asks":[["0.00000074571","48015673","0","1"],["0.0000011372","0","0","0"]],"bids":[],"ts":"1646003677131","checksum":-1592145220}]}
1646003677.157494: {"arg":{"channel":"books-l2-tbt","instId":"UNI-USD-SWAP"},"action":"update","data":[{"asks":[["9.624","0","0","0"],["9.628","0","0","0"],["47.903","1","0","1"],["48.143","1","0","1"]],"bids":[],"ts":"1646003677138","checksum":152594642}]}
1646003677.15759: {"arg":{"channel":"books-l2-tbt","instId":"ELON-USDT"},"action":"update","data":[{"asks":[["0.00000074571","169693742","0","3"],["0.00000074577","0","0","0"],["0.0000011372","6179288","0","1"]],"bids":[],"ts":"1646003677140","checksum":1087030515}]}
1646003677.162417: {"arg":{"channel":"books-l2-tbt","instId":"ELON-USDT"},"action":"update","data":[{"asks":[["0.00000074584","0","0","0"],["0.00000113812","12211658","0","1"]],"bids":[],"ts":"1646003677151","checksum":-485156533}]}
1646003677.171011: {"arg":{"channel":"books-l2-tbt","instId":"UNI-USD-SWAP"},"action":"update","data":[{"asks":[["9.628","3","0","1"],["48.143","0","0","0"]],"bids":[],"ts":"1646003677159","checksum":682608055}]}
1646003677.182136: {"arg":{"channel":"books-l2-tbt","instId":"ELON-USDT"},"action":"update","data":[{"asks":[["0.00000074576","445226872","0","1"],["0.00000113812","0","0","0"]],"bids":[],"ts":"1646003677170","checksum":1950186021}]}
1646003677.2027352: {"arg":{"channel":"books-l2-tbt","instId":"ELON-USDT"},"action":"update","data":[{"asks":[["0.00000074572","0","0","0"],["0.00000113812","12211658","0","1"]],"bids":[],"ts":"1646003677192","checksum":2009444140}]}
1646003677.2113411: {"arg":{"channel":"trades","instId":"ZEN-USDT"},"data":[{"instId":"ZEN-USDT","tradeId":"15270485","px":"32.52","sz":"0.3628","side":"buy","ts":"1646003677195"}]}
1646003677.23674: {"arg":{"channel":"books-l2-tbt","instId":"ELON-USDT"},"action":"update","data":[{"asks":[],"bids":[["0.00000072102","7410461012","0","1"]],"ts":"1646003677224","checksum":2009444140}]}
1646003677.253582: {"arg":{"channel":"books-l2-tbt","instId":"ELON-USDT"},"action":"update","data":[{"asks":[["0.0000007457","326999416","0","1"],["0.00000113812","0","0","0"]],"bids":[],"ts":"1646003677234","checksum":622807339}]}
1646003677.2536662: {"arg":{"channel":"books-l2-tbt","instId":"ETH-USD-220325-8800-P"},"action":"update","data":[{"asks":[["2.5485","201","0","1"],["2.5495","0","0","0"]],"bids":[],"ts":"1646003677237","checksum":1047929945}]}
1646003677.254231: {"arg":{"channel":"books-l2-tbt","instId":"UNI-USD-SWAP"},"action":"update","data":[{"asks":[["9.628","124","0","2"],["9.629","12","0","1"]],"bids":[["9.613","223","0","3"]],"ts":"1646003677244","checksum":-1672114565}]}
1646003677.2545888: {"arg":{"channel":"books-l2-tbt","instId":"ELON-USDT"},"action":"update","data":[{"asks":[["0.00000074576","0","0","0"],["0.00000113812","12211658","0","1"]],"bids":[],"ts":"1646003677244","checksum":1772704784}]}
1646003677.2673979: {"arg":{"channel":"books-l2-tbt","instId":"UNI-USD-SWAP"},"action":"update","data":[{"asks":[["9.633","0","0","0"],["9.635","25","0","2"],["48.143","1","0","1"]],"bids":[["9.614","53","0","1"]],"ts":"1646003677254","checksum":-1431890833}]}
1646003677.27618: {"arg":{"channel":"books-l2-tbt","instId":"UNI-USD-SWAP"},"action":"update","data":[{"asks":[["9.635","20","0","2"],["9.644","28","0","1"],["9.645","748","0","3"],["9.647","2578","0","6"],["9.648","1","0","1"],["9.65","248","0","2"],["9.651","79","0","2"],["48.143","0","0","0"]],"bids":[["9.605","29","0","1"],["9.601","51","0","2"],["9.6","0","0","0"],["9.598","39","0","2"]],"ts":"1646003677264","checksum":1792889798}]}
1646003677.277271: {"arg":{"channel":"books-l2-tbt","instId":"ELON-USDT"},"action":"update","data":[{"asks":[["0.00000074574","81175250","0","1"],["0.00000113812","0","0","0"]],"bids":[],"ts":"1646003677266","checksum":32132985}]}
1646003677.28883: {"arg":{"channel":"books-l2-tbt","instId":"UNI-USD-SWAP"},"action":"update","data":[{"asks":[["9.627","1","0","1"],["47.903","0","0","0"]],"bids":[],"ts":"1646003677274","checksum":1941981573}]}
1646003677.2974238: {"arg":{"channel":"books-l2-tbt","instId":"UNI-USD-SWAP"},"action":"update","data":[{"asks":[["9.628","121","0","1"]],"bids":[],"ts":"1646003677285","checksum":79308961}]}
1646003677.304645: {"arg":{"channel":"books-l2-tbt","instId":"ELON-USDT"},"action":"update","data":[{"asks":[],"bids":[["0.00000074449","0","0","0"]],"ts":"1646003677288","checksum":405348838}]}
1646003677.304739: {"arg":{"channel":"books-l2-tbt","instId":"PROPS-ETH"},"action":"update","data":[{"asks":[["0.00000178","0","0","0"],["0.00000183","773.05461854","0","1"],["0.00000184","1488.38494617","0","1"],["0.00000185","0","0","0"],["0.00000186","0","0","0"],["0.00000187","0","0","0"]],"bids":[],"ts":"1646003677292","checksum":1255013538}]}
1646003677.32289: {"arg":{"channel":"books-l2-tbt","instId":"ELON-USDT"},"action":"update","data":[{"asks":[],"bids":[["0.00000074435","184440410","0","1"]],"ts":"1646003677311","checksum":1897941493}]}
1646003677.331155: {"arg":{"channel":"books-l2-tbt","instId":"ELON-USDT"},"action":"update","data":[{"asks":[],"bids":[["0.0000007445","0","0","0"]],"ts":"1646003677319","checksum":969005422}]}
1646003677.3367538: {"arg":{"channel":"books-l2-tbt","instId":"UNI-USD-SWAP"},"action":"update","data":[{"asks":[["9.632","429","0","3"],["9.635","11","0","1"]],"bids":[],"ts":"1646003677324","checksum":691927517}]}
1646003677.347318: {"arg":{"channel":"tickers","instId":"ZEN-USDT"},"data":[{"instType":"SPOT","instId":"ZEN-USDT","last":"32.52","lastSz":"0.3628","askPx":"32.53","askSz":"0.383596","bidPx":"32.5","bidSz":"0.399716","open24h":"33.34","high24h":"35.26","low24h":"31.91","sodUtc0":"33.36","sodUtc8":"34.26","volCcy24h":"1483620.899424","vol24h":"44365.188012","ts":"1646003677326"}]}
1646003677.347376: {"arg":{"channel":"books-l2-tbt","instId":"UNI-USD-SWAP"},"action":"update","data":[{"asks":[],"bids":[["9.614","0","0","0"]],"ts":"1646003677336","checksum":-766237963}]}
1646003677.3680599: {"arg":{"channel":"books-l2-tbt","instId":"UNI-USD-SWAP"},"action":"update","data":[{"asks":[],"bids":[["9.615","282","0","2"]],"ts":"1646003677356","checksum":-451679011}]}
1646003677.37303: {"arg":{"channel":"books-l2-tbt","instId":"ELON-USDT"},"action":"update","data":[{"asks":[],"bids":[["0.00000074218","0","0","0"]],"ts":"1646003677360","checksum":-1332273662}]}
1646003677.390114: {"arg":{"channel":"books-l2-tbt","instId":"UNI-USD-SWAP"},"action":"update","data":[{"asks":[["9.627","0","0","0"],["47.903","1","0","1"]],"bids":[["9.61","6","0","1"]],"ts":"1646003677377","checksum":-326608935}]}
1646003677.404053: {"arg":{"channel":"books-l2-tbt","instId":"ELON-USDT"},"action":"update","data":[{"asks":[],"bids":[["0.00000074381","69922890","0","1"]],"ts":"1646003677390","checksum":872367867}]}
1646003677.4114618: {"arg":{"channel":"books-l2-tbt","instId":"ELON-USDT"},"action":"update","data":[{"asks":[],"bids":[["0.00000074435","0","0","0"]],"ts":"1646003677400","checksum":-665192972}]}
1646003677.4212108: {"arg":{"channel":"books-l2-tbt","instId":"UNI-USD-SWAP"},"action":"update","data":[{"asks":[["9.624","1","0","1"],["47.903","0","0","0"]],"bids":[],"ts":"1646003677409","checksum":-1910228905}]}
1646003677.4212961: {"arg":{"channel":"books-l2-tbt","instId":"ZEN-USDT"},"action":"update","data":[{"asks":[],"bids":[["32.46","3.686635","0","1"]],"ts":"1646003677410","checksum":149079471}]}
1646003677.4220119: {"arg":{"channel":"books-l2-tbt","instId":"ELON-USDT"},"action":"update","data":[{"asks":[],"bids":[["0.00000069607","334107848","0","1"],["0.00000068215","311037815","0","1"],["0.00000066851","175798620","0","1"],["0.00000065514","169361283","0","1"],["0.00000064475","0","0","0"]],"ts":"1646003677411","checksum":-665192972}]}
1646003677.4631832: {"arg":{"channel":"books-l2-tbt","instId":"UNI-USD-SWAP"},"action":"update","data":[{"asks":[],"bids":[["9.613","276","0","4"],["9.604","341","0","3"],["9.603","500","0","1"],["9.602","102","0","2"],["9.601","25","0","1"],["9.599","645","0","3"],["9.598","16","0","1"]],"ts":"1646003677450","checksum":-1433755251}]}
1646003677.482242: {"arg":{"channel":"books-l2-tbt","instId":"UNI-USD-SWAP"},"action":"update","data":[{"asks":[],"bids":[["9.61","0","0","0"],["9.609","10","0","2"]],"ts":"1646003677471","checksum":971425309}]}
1646003677.503071: {"arg":{"channel":"books-l2-tbt","instId":"UNI-USD-SWAP"},"action":"update","data":[{"asks":[["9.623","0","0","0"],["9.631","189","0","3"],["9.632","426","0","2"],["9.634","500","0","1"],["47.903","1","0","1"]],"bids":[],"ts":"1646003677481","checksum":-1362787084}]}
1646003677.5031722: {"arg":{"channel":"books-l2-tbt","instId":"UNI-USD-SWAP"},"action":"update","data":[{"asks":[["9.622","348","0","2"]],"bids":[],"ts":"1646003677491","checksum":434557478}]}
1646003677.515154: {"arg":{"channel":"books-l2-tbt","instId":"UNI-USD-SWAP"},"action":"update","data":[{"asks":[],"bids":[["9.609","6","0","1"]],"ts":"1646003677501","checksum":-721824112}]}
1646003677.515262: {"arg":{"channel":"books-l2-tbt","instId":"ZEN-USDT"},"action":"update","data":[{"asks":[["32.6","212.145558","0","6"]],"bids":[["32.46","19.833028","0","2"]],"ts":"1646003677503","checksum":-809214097}]}
1646003677.5372958: {"arg":{"channel":"books-l2-tbt","instId":"UNI-USD-SWAP"},"action":"update","data":[{"asks":[],"bids":[["9.609","8","0","2"],["9.576","1562","0","2"],["9.569","4","0","1"]],"ts":"1646003677523","checksum":1076337279}]}
1646003677.559477: {"arg":{"channel":"books-l2-tbt","instId":"ELON-USDT"},"action":"update","data":[{"asks":[["0.00000074569","215794710","0","2"],["0.00000074571","121678069","0","2"],["0.0000011372","0","0","0"]],"bids":[],"ts":"1646003677545","checksum":-487968617}]}
1646003677.5716: {"arg":{"channel":"books-l2-tbt","instId":"ELON-USDT"},"action":"update","data":[{"asks":[["0.00000074569","268152407","0","3"],["0.00000074571","0","0","0"],["0.0000011372","6179288","0","1"]],"bids":[],"ts":"1646003677556","checksum":1456046224}]}
1646003677.5903091: {"arg":{"channel":"books-l2-tbt","instId":"UNI-USD-SWAP"},"action":"update","data":[{"asks":[["9.643","23","0","1"],["9.644","0","0","0"],["9.646","38","0","2"],["9.647","2554","0","5"],["9.649","269","0","3"],["9.65","225","0","1"]],"bids":[],"ts":"1646003677575","checksum":-784932336}]}
1646003677.590411: {"arg":{"channel":"books-l2-tbt","instId":"ELON-USDT"},"action":"update","data":[{"asks":[["0.00000074568","445226872","0","1"],["0.0000011372","0","0","0"]],"bids":[],"ts":"1646003677576","checksum":976550327}]}
1646003677.5977821: {"arg":{"channel":"books-l2-tbt","instId":"UNI-USD-SWAP"},"action":"update","data":[{"asks":[],"bids":[["9.613","223","0","3"]],"ts":"1646003677586","checksum":1878324919}]}
1646003677.60868: {"arg":{"channel":"books-l2-tbt","instId":"ELON-USDT"},"action":"update","data":[{"asks":[["0.00000074569","52357697","0","1"],["0.0000007457","0","0","0"],["0.0000011372","6179288","0","1"]],"bids":[],"ts":"1646003677597","checksum":921192169}]}
1646003677.633586: {"arg":{"channel":"books-l2-tbt","instId":"ELON-USDT"},"action":"update","data":[{"asks":[["0.00000074567","104045940","0","1"],["0.0000011372","0","0","0"]],"bids":[],"ts":"1646003677618","checksum":-482021242}]}
1646003677.675345: {"arg":{"channel":"books-l2-tbt","instId":"UNI-USD-SWAP"},"action":"update","data":[{"asks":[],"bids":[["9.612","53","0","1"]],"ts":"1646003677658","checksum":-500973679}]}
1646003677.67545: {"arg":{"channel":"books-l2-tbt","instId":"ELON-USDT"},"action":"update","data":[{"asks":[["0.00000074566","445226872","0","1"],["0.0000011338","0","0","0"]],"bids":[],"ts":"1646003677660","checksum":688368318}]}
1646003677.685365: {"arg":{"channel":"books-l2-tbt","instId":"UNI-USD-SWAP"},"action":"update","data":[{"asks":[],"bids":[["9.603","0","0","0"]],"ts":"1646003677670","checksum":1064689187}]}
1646003677.696426: {"arg":{"channel":"books-l2-tbt","instId":"UNI-USD-SWAP"},"action":"update","data":[{"asks":[],"bids":[["9.606","500","0","1"]],"ts":"1646003677679","checksum":868142212}]}
1646003677.696529: {"arg":{"channel":"books-l2-tbt","instId":"ELON-USDT"},"action":"update","data":[{"asks":[["0.00000074565","48015673","0","1"],["0.00000074567","0","0","0"]],"bids":[],"ts":"1646003677680","checksum":1094544867}]}
1646003677.7008388: {"arg":{"channel":"books-l2-tbt","instId":"UNI-USD-SWAP"},"action":"update","data":[{"asks":[],"bids":[["9.606","505","0","2"]],"ts":"1646003677689","checksum":-1866470833}]}
1646003677.703708: {"arg":{"channel":"books-l2-tbt","instId":"ELON-USDT"},"action":"update","data":[{"asks":[["0.00000074568","0","0","0"],["0.0000011338","129154981","0","1"]],"bids":[],"ts":"1646003677692","checksum":-405281868}]}
1646003677.711911: {"arg":{"channel":"books-l2-tbt","instId":"UNI-USD-SWAP"},"action":"update","data":[{"asks":[["9.627","2","0","1"],["47.903","0","0","0"]],"bids":[["9.609","6","0","1"]],"ts":"1646003677700","checksum":-1983745878}]}
1646003677.7120378: {"arg":{"channel":"books-l2-tbt","instId":"ELON-USDT"},"action":"update","data":[{"asks":[["0.00000074565","152061613","0","2"]],"bids":[],"ts":"1646003677700","checksum":-1550967990}]}
1646003677.738283: {"arg":{"channel":"books-l2-tbt","instId":"UNI-USD-SWAP"},"action":"update","data":[{"asks":[["9.624","0","0","0"],["47.903","1","0","1"]],"bids":[["9.606","500","0","1"],["9.604","317","0","2"],["9.603","22","0","1"],["9.602","76","0","1"],["9.601","50","0","2"],["9.599","620","0","2"],["9.598","46","0","2"]],"ts":"1646003677722","checksum":-517095682}]}
1646003677.744855: {"arg":{"channel":"books-l2-tbt","instId":"ELON-USDT"},"action":"update","data":[{"asks":[["0.00000074564","445226872","0","1"],["0.0000011338","0","0","0"]],"bids":[],"ts":"1646003677733","checksum":-1102064955}]}
1646003677.752398: {"arg":{"channel":"books-l2-tbt","instId":"UNI-USD-SWAP"},"action":"update","data":[{"asks":[["9.627","124","0","2"],["9.628","0","0","0"],["48.143","1","0","1"]],"bids":[["9.61","1","0","1"]],"ts":"1646003677742","checksum":-640844634}]}
1646003677.768043: {"arg":{"channel":"books-l2-tbt","instId":"ELON-USDT"},"action":"update","data":[{"asks":[["0.00000074565","104045940","0","1"]],"bids":[],"ts":"1646003677753","checksum":1439957162}]}
1646003677.7807739: {"arg":{"channel":"books-l2-tbt","instId":"ELON-USDT"},"action":"update","data":[{"asks":[["0.00000074563","53107723","0","1"],["0.00000074569","0","0","0"],["0.00000074574","0","0","0"],["0.0000011338","129154981","0","1"]],"bids":[],"ts":"1646003677764","checksum":2060590733}]}
1646003677.7906291: {"arg":{"channel":"books-l2-tbt","instId":"ELON-USDT"},"action":"update","data":[{"asks":[["0.00000074563","233426839","0","3"],["0.00000074566","0","0","0"],["0.0000011372","6179288","0","1"]],"bids":[],"ts":"1646003677775","checksum":782970584}]}
1646003677.801321: {"arg":{"channel":"books-l2-tbt","instId":"PROPS-ETH"},"action":"update","data":[{"asks":[["0.00000183","0","0","0"],["0.00000184","0","0","0"]],"bids":[["0.00000161","0","0","0"]],"ts":"1646003677788","checksum":-1461446077}]}
1646003677.804694: {"arg":{"channel":"books-l2-tbt","instId":"ELON-USDT"},"action":"update","data":[{"asks":[["0.00000074563","281442512","0","4"],["0.00000074565","0","0","0"],["0.00000113812","12211658","0","1"]],"bids":[],"ts":"1646003677794","checksum":1271270349}]}
1646003677.806149: {"arg":{"channel":"books-l2-tbt","instId":"UNI-USD-SWAP"},"action":"update","data":[{"asks":[],"bids":[["9.476","0","0","0"]],"ts":"1646003677795","checksum":-640844634}]}
1646003677.810426: {"arg":{"channel":"books-l2-tbt","instId":"PROPS-ETH"},"action":"update","data":[{"asks":[["0.00000177","1351.98509919","0","1"],["0.00000178","1306.00657561","0","1"],["0.00000185","778.94458908","0","1"],["0.00000186","1222.45994868","0","1"]],"bids":[["0.0000016","10768.89979996","0","1"]],"ts":"1646003677799","checksum":-459829005}]}
1646003677.8174: {"arg":{"channel":"books-l2-tbt","instId":"UNI-USD-SWAP"},"action":"update","data":[{"asks":[["9.64","151","0","1"]],"bids":[],"ts":"1646003677805","checksum":-1838742355}]}
1646003677.817515: {"arg":{"channel":"books-l2-tbt","instId":"ELON-USDT"},"action":"update","data":[{"asks":[],"bids":[["0.00000074447","219861835","0","1"]],"ts":"1646003677805","checksum":1020395992}]}
1646003677.8268712: {"arg":{"channel":"books-l2-tbt","instId":"ELON-USDT"},"action":"update","data":[{"asks":[["0.00000074562","445226872","0","1"],["0.00000113812","0","0","0"]],"bids":[],"ts":"1646003677815","checksum":-939764619}]}
1646003677.829717: {"arg":{"channel":"books-l2-tbt","instId":"UNI-USD-SWAP"},"action":"update","data":[{"asks":[],"bids":[["9.467","240","0","1"]],"ts":"1646003677817","checksum":-1838742355}]}
1646003677.839345: {"arg":{"channel":"books-l2-tbt","instId":"UNI-USD-SWAP"},"action":"update","data":[{"asks":[["9.635","27","0","2"]],"bids":[],"ts":"1646003677828","checksum":78695898}]}
1646003677.847109: {"arg":{"channel":"books-l2-tbt","instId":"ELON-USDT"},"action":"update","data":[{"asks":[["0.00000074563","121678069","0","2"],["0.00000074567","81175250","0","1"],["0.0000011372","0","0","0"]],"bids":[],"ts":"1646003677836","checksum":-1455744544}]}
1646003677.857373: {"arg":{"channel":"books-l2-tbt","instId":"ELON-USDT"},"action":"update","data":[{"asks":[["0.00000074564","0","0","0"],["0.0000011372","6179288","0","1"]],"bids":[],"ts":"1646003677845","checksum":-1947462367}]}
1646003677.868709: {"arg":{"channel":"books-l2-tbt","instId":"ELON-USDT"},"action":"update","data":[{"asks":[["0.00000074561","159764443","0","2"],["0.0000011372","0","0","0"]],"bids":[],"ts":"1646003677856","checksum":197191801}]}
1646003677.880418: {"arg":{"channel":"books-l2-tbt","instId":"ELON-USDT"},"action":"update","data":[{"asks":[["0.00000074561","111748770","0","1"]],"bids":[],"ts":"1646003677867","checksum":2110721984}]}
1646003677.909218: {"arg":{"channel":"books-l2-tbt","instId":"ZEN-USDT"},"action":"update","data":[{"asks":[],"bids":[["32.45","15.369609","0","1"]],"ts":"1646003677885","checksum":-936852110}]}
1646003677.916482: {"arg":{"channel":"books-l2-tbt","instId":"ELON-USDT"},"action":"update","data":[{"asks":[["0.0000007456","445226872","0","1"],["0.0000011338","0","0","0"]],"bids":[],"ts":"1646003677897","checksum":-1363006279}]}
1646003677.9337249: {"arg":{"channel":"books-l2-tbt","instId":"ELON-USDT"},"action":"update","data":[{"asks":[["0.00000074561","0","0","0"],["0.00000074562","0","0","0"],["0.0000011338","129154981","0","1"],["0.0000011372","6179288","0","1"]],"bids":[["0.00000069607","0","0","0"],["0.00000068215","0","0","0"],["0.00000066851","0","0","0"],["0.00000065514","0","0","0"],["0.00000064198","318520968","0","1"]],"ts":"1646003677918","checksum":141349401}]}
1646003677.9539251: {"arg":{"channel":"books-l2-tbt","instId":"ELON-USDT"},"action":"update","data":[{"asks":[["0.00000074559","215794710","0","2"],["0.0000011372","0","0","0"]],"bids":[],"ts":"1646003677939","checksum":-143508158}]}
1646003677.965565: {"arg":{"channel":"books-l2-tbt","instId":"UNI-USD-SWAP"},"action":"update","data":[{"asks":[["9.631","188","0","2"],["9.632","427","0","3"]],"bids":[],"ts":"1646003677954","checksum":-673819597}]}
1646003677.975457: {"arg":{"channel":"books-l2-tbt","instId":"ELON-USDT"},"action":"update","data":[{"asks":[["0.0000007456","0","0","0"],["0.0000011372","6179288","0","1"]],"bids":[["0.000000742","2209824531","0","2"],["0.000000741","697000000","0","1"]],"ts":"1646003677958","checksum":147095091}]}
1646003677.986827: {"arg":{"channel":"books-l2-tbt","instId":"ELON-USDT"},"action":"update","data":[{"asks":[["0.00000074559","268152407","0","3"],["0.00000074563","0","0","0"],["0.00000113812","12211658","0","1"]],"bids":[],"ts":"1646003677969","checksum":-197206850}]}
1646003677.9869199: {"arg":{"channel":"books-l2-tbt","instId":"UNI-USD-SWAP"},"action":"update","data":[{"asks":[],"bids":[["9.603","0","0","0"],["9.601","25","0","1"],["9.598","16","0","1"]],"ts":"1646003677971","checksum":563791764}]}
1646003677.995724: {"arg":{"channel":"books-l2-tbt","instId":"ELON-USDT"},"action":"update","data":[{"asks":[["0.00000074559","52357697","0","1"],["0.00000074562","445226872","0","1"],["0.00000113812","0","0","0"]],"bids":[],"ts":"1646003677979","checksum":252548045}]}
1646003677.99584: {"arg":{"channel":"books-l2-tbt","instId":"UNI-USD-SWAP"},"action":"update","data":[{"asks":[],"bids":[["9.602","101","0","2"],["9.6","20","0","1"],["9.597","21","0","1"]],"ts":"1646003677982","checksum":-108575715}]}
1646003678.007468: {"arg":{"channel":"books-l2-tbt","instId":"ELON-USDT"},"action":"update","data":[{"asks":[["0.00000074558","104045940","0","1"],["0.0000011372","0","0","0"]],"bids":[],"ts":"1646003677990","checksum":285852857}]}
1646003678.0075898: {"arg":{"channel":"books-l2-tbt","instId":"UNI-USD-SWAP"},"action":"update","data":[{"asks":[["9.63","3","0","1"],["9.632","426","0","2"],["9.637","1283","0","4"],["9.638","119","0","2"],["48.143","0","0","0"]],"bids":[["9.609","8","0","2"]],"ts":"1646003677992","checksum":-1250229565}]}
1646003678.011897: {"arg":{"channel":"books-l2-tbt","instId":"ELON-USDT"},"action":"update","data":[{"asks":[["0.00000074558","0","0","0"],["0.0000011372","6179288","0","1"]],"bids":[],"ts":"1646003678000","checksum":252548045}]}
1646003678.018272: {"arg":{"channel":"books-l2-tbt","instId":"UNI-USD-SWAP"},"action":"update","data":[{"asks":[],"bids":[["9.61","0","0","0"]],"ts":"1646003678002","checksum":155353716}]}
1646003678.027754: {"arg":{"channel":"books-l2-tbt","instId":"ELON-USDT"},"action":"update","data":[{"asks":[["0.00000074557","104045940","0","1"],["0.0000011372","0","0","0"]],"bids":[["0.00000074381","0","0","0"]],"ts":"1646003678009","checksum":-1710775751}]}
1646003678.0278778: {"arg":{"channel":"books-l2-tbt","instId":"UNI-USD-SWAP"},"action":"update","data":[{"asks":[],"bids":[["9.613","121","0","2"]],"ts":"1646003678015","checksum":117013448}]}
1646003678.031264: {"arg":{"channel":"books-l2-tbt","instId":"ELON-USDT"},"action":"update","data":[{"asks":[["0.00000074557","0","0","0"],["0.00000074558","445226872","0","1"],["0.00000074739","0","0","0"],["0.0000011372","6179288","0","1"]],"bids":[["0.00000074448","26201826","0","1"]],"ts":"1646003678019","checksum":2076760537}]}
1646003678.044597: {"arg":{"channel":"books-l2-tbt","instId":"ELON-USDT"},"action":"update","data":[{"asks":[["0.00000074556","104045940","0","1"],["0.0000011372","0","0","0"]],"bids":[],"ts":"1646003678028","checksum":340352364}]}
1646003678.051926: {"arg":{"channel":"books-l2-tbt","instId":"ELON-USDT"},"action":"update","data":[{"asks":[["0.00000074556","0","0","0"],["0.00000074768","3469464317","0","1"]],"bids":[],"ts":"1646003678040","checksum":-474085495}]}
1646003678.060936: {"arg":{"channel":"books-l2-tbt","instId":"ETH-USD-220325-8800-P"},"action":"update","data":[{"asks":[],"bids":[],"ts":"1646003678046","checksum":1047929945}]}
1646003678.0631979: {"arg":{"channel":"books-l2-tbt","instId":"ELON-USDT"},"action":"update","data":[{"asks":[["0.00000074555","104045940","0","1"],["0.00000074562","0","0","0"]],"bids":[],"ts":"1646003678050","checksum":-1605402412}]}
1646003678.0739682: {"arg":{"channel":"books-l2-tbt","instId":"ELON-USDT"},"action":"update","data":[{"asks":[["0.00000074555","0","0","0"],["0.0000011372","6179288","0","1"]],"bids":[],"ts":"1646003678060","checksum":1731920679}]}
1646003678.0867279: {"arg":{"channel":"books-l2-tbt","instId":"ELON-USDT"},"action":"update","data":[{"asks":[["0.00000074554","152061613","0","2"],["0.0000011372","0","0","0"]],"bids":[],"ts":"1646003678071","checksum":407997580}]}
1646003678.09191: {"arg":{"channel":"books-l2-tbt","instId":"ELON-USDT"},"action":"update","data":[{"asks":[["0.00000074554","0","0","0"],["0.0000011372","6179288","0","1"]],"bids":[["0.00000074435","31594286","0","1"]],"ts":"1646003678080","checksum":-1383542580}]}
1646003678.1071832: {"arg":{"channel":"books-l2-tbt","instId":"ELON-USDT"},"action":"update","data":[{"asks":[["0.00000074553","152061613","0","2"],["0.00000074554","438491895","0","1"],["0.0000011338","0","0","0"],["0.0000011372","0","0","0"]],"bids":[["0.00000074448","0","0","0"]],"ts":"1646003678091","checksum":298515364}]}
1646003678.120932: {"arg":{"channel":"books-l2-tbt","instId":"ELON-USDT"},"action":"update","data":[{"asks":[["0.00000074553","0","0","0"],["0.0000011338","129154981","0","1"]],"bids":[],"ts":"1646003678102","checksum":348328736}]}
1646003678.127598: {"arg":{"channel":"books-l2-tbt","instId":"ELON-USDT"},"action":"update","data":[{"asks":[["0.00000074552","48015673","0","1"],["0.0000011338","0","0","0"]],"bids":[],"ts":"1646003678112","checksum":912827601}]}
1646003678.136848: {"arg":{"channel":"books-l2-tbt","instId":"ELON-USDT"},"action":"update","data":[{"asks":[["0.00000074553","104045940","0","1"],["0.00000113315","0","0","0"]],"bids":[],"ts":"1646003678122","checksum":92589987}]}
1646003678.1501062: {"arg":{"channel":"books-l2-tbt","instId":"ELON-USDT"},"action":"update","data":[{"asks":[["0.00000074552","0","0","0"],["0.00000074554","0","0","0"],["0.00000113315","35900750","0","1"],["0.0000011338","129154981","0","1"]],"bids":[],"ts":"1646003678133","checksum":-1832182340}]}
1646003678.150246: {"arg":{"channel":"books-l2-tbt","instId":"UNI-USD-SWAP"},"action":"update","data":[{"asks":[["9.622","260","0","1"]],"bids":[["9.609","2","0","1"],["9.608","18","0","2"]],"ts":"1646003678137","checksum":-382162562}]}
1646003678.155637: {"arg":{"channel":"books-l2-tbt","instId":"ELON-USDT"},"action":"update","data":[{"asks":[["0.00000074551","48015673","0","1"],["0.00000074553","0","0","0"]],"bids":[["0.00000074448","70229398","0","1"]],"ts":"1646003678144","checksum":457350791}]}
1646003678.158932: {"arg":{"channel":"books-l2-tbt","instId":"UNI-USD-SWAP"},"action":"update","data":[{"asks":[["9.621","83","0","1"],["47.903","0","0","0"]],"bids":[],"ts":"1646003678147","checksum":-648961072}]}
1646003678.16469: {"arg":{"channel":"books-l2-tbt","instId":"ELON-USDT"},"action":"update","data":[{"asks":[["0.00000074551","0","0","0"],["0.00000074552","104045940","0","1"]],"bids":[["0.00000074448","0","0","0"],["0.00000074435","0","0","0"]],"ts":"1646003678152","checksum":-1717152810}]}
1646003678.168917: {"arg":{"channel":"books-l2-tbt","instId":"UNI-USD-SWAP"},"action":"update","data":[{"asks":[["9.621","343","0","2"],["9.625","0","0","0"],["47.903","1","0","1"]],"bids":[],"ts":"1646003678157","checksum":153790772}]}
1646003678.172129: {"arg":{"channel":"books-l2-tbt","instId":"ZEN-USDT"},"action":"update","data":[{"asks":[],"bids":[["32.45","71.589672","0","2"]],"ts":"1646003678161","checksum":1591733561}]}
1646003678.174332: {"arg":{"channel":"books-l2-tbt","instId":"ELON-USDT"},"action":"update","data":[{"asks":[["0.0000007455","307908134","0","1"],["0.00000074552","0","0","0"]],"bids":[],"ts":"1646003678163","checksum":558113119}]}
1646003678.182153: {"arg":{"channel":"books-l2-tbt","instId":"UNI-USD-SWAP"},"action":"update","data":[{"asks":[["9.622","0","0","0"],["48.143","1","0","1"]],"bids":[],"ts":"1646003678168","checksum":306653074}]}
1646003678.185462: {"arg":{"channel":"books-l2-tbt","instId":"ELON-USDT"},"action":"update","data":[{"asks":[["0.00000074551","121678069","0","2"],["0.00000074559","0","0","0"]],"bids":[],"ts":"1646003678174","checksum":-287811270}]}
1646003678.1932092: {"arg":{"channel":"books-l2-tbt","instId":"UNI-USD-SWAP"},"action":"update","data":[{"asks":[["9.626","1","0","1"],["48.143","0","0","0"]],"bids":[],"ts":"1646003678178","checksum":1515553011}]}
1646003678.196413: {"arg":{"channel":"books-l2-tbt","instId":"ETH-USD-220624-12000-P"},"action":"update","data":[{"asks":[["4.044","0","0","0"],["4.0445","201","0","1"]],"bids":[],"ts":"1646003678183","checksum":1491294271}]}
1646003678.196509: {"arg":{"channel":"books-l2-tbt","instId":"ELON-USDT"},"action":"update","data":[{"asks":[["0.00000074549","215794710","0","2"],["0.00000074558","0","0","0"]],"bids":[["0.00000074435","31171266","0","1"]],"ts":"1646003678184","checksum":-1329585163}]}
1646003678.206079: {"arg":{"channel":"books-l2-tbt","instId":"UNI-USD-SWAP"},"action":"update","data":[{"asks":[["9.627","122","0","1"]],"bids":[],"ts":"1646003678190","checksum":-1943930772}]}
1646003678.2066581: {"arg":{"channel":"books-l2-tbt","instId":"ELON-USDT"},"action":"update","data":[{"asks":[["0.00000074552","48015673","0","1"],["0.0000011338","0","0","0"]],"bids":[],"ts":"1646003678194","checksum":-158624447}]}
1646003678.21797: {"arg":{"channel":"books-l2-tbt","instId":"ELON-USDT"},"action":"update","data":[{"asks":[],"bids":[["0.00000074448","40516734","0","1"]],"ts":"1646003678205","checksum":-829947759}]}
1646003678.2275221: {"arg":{"channel":"books-l2-tbt","instId":"ELON-USDT"},"action":"update","data":[{"asks":[["0.0000007455","0","0","0"],["0.00000074552","0","0","0"],["0.0000011338","129154981","0","1"],["0.0000011372","6179288","0","1"]],"bids":[],"ts":"1646003678214","checksum":1962938998}]}
1646003678.235907: {"arg":{"channel":"books-l2-tbt","instId":"ELON-USDT"},"action":"update","data":[{"asks":[["0.00000074548","443182327","0","1"],["0.00000074549","263810383","0","3"],["0.0000011372","0","0","0"]],"bids":[["0.00000074435","0","0","0"]],"ts":"1646003678225","checksum":943476398}]}
1646003678.245908: {"arg":{"channel":"books-l2-tbt","instId":"UNI-USD-SWAP"},"action":"update","data":[{"asks":[["9.621","260","0","1"]],"bids":[],"ts":"1646003678231","checksum":25816944}]}
1646003678.252078: {"arg":{"channel":"books-l2-tbt","instId":"ELON-USDT"},"action":"update","data":[{"asks":[["0.00000074549","0","0","0"],["0.0000011372","6179288","0","1"]],"bids":[],"ts":"1646003678235","checksum":-517785897}]}
1646003678.26001: {"arg":{"channel":"books-l2-tbt","instId":"ELON-USDT"},"action":"update","data":[{"asks":[["0.00000074547","263810383","0","3"],["0.0000011372","0","0","0"]],"bids":[],"ts":"1646003678245","checksum":422674243}]}
1646003678.2681012: {"arg":{"channel":"books-l2-tbt","instId":"ELON-USDT"},"action":"update","data":[{"asks":[],"bids":[["0.00000074381","131876136","0","1"]],"ts":"1646003678255","checksum":-2000802436}]}
1646003678.280948: {"arg":{"channel":"books-l2-tbt","instId":"ELON-USDT"},"action":"update","data":[{"asks":[["0.00000074547","215794710","0","2"]],"bids":[["0.00000074448","0","0","0"]],"ts":"1646003678266","checksum":-1409173455}]}
1646003678.287053: {"arg":{"channel":"books-l2-tbt","instId":"ELON-USDT"},"action":"update","data":[{"asks":[["0.00000074546","426510295","0","1"],["0.0000011338","0","0","0"]],"bids":[],"ts":"1646003678275","checksum":1478511561}]}
1646003678.3001332: {"arg":{"channel":"books-l2-tbt","instId":"ELON-USDT"},"action":"update","data":[{"asks":[],"bids":[["0.00000074447","0","0","0"]],"ts":"1646003678286","checksum":1759461708}]}
1646003678.303199: {"arg":{"channel":"books-l2-tbt","instId":"PROPS-ETH"},"action":"update","data":[{"asks":[],"bids":[["0.0000016","0","0","0"]],"ts":"1646003678291","checksum":-992574123}]}
1646003678.308444: {"arg":{"channel":"books-l2-tbt","instId":"ELON-USDT"},"action":"update","data":[{"asks":[["0.00000074547","0","0","0"],["0.0000011338","129154981","0","1"]],"bids":[],"ts":"1646003678295","checksum":-877519640}]}
1646003678.3153229: {"arg":{"channel":"books-l2-tbt","instId":"PROPS-ETH"},"action":"update","data":[{"asks":[["0.00000177","0","0","0"],["0.00000178","0","0","0"],["0.00000183","799.83593494","0","1"],["0.00000184","721.61458452","0","1"],["0.00000185","0","0","0"],["0.00000186","0","0","0"],["0.00000187","854.26569199","0","1"]],"bids":[["0.00000161","9598.59449893","0","1"]],"ts":"1646003678300","checksum":1462818193}]}
1646003678.319835: {"arg":{"channel":"books-l2-tbt","instId":"ELON-USDT"},"action":"update","data":[{"asks":[["0.00000074545","215794710","0","2"],["0.00000074548","0","0","0"]],"bids":[],"ts":"1646003678307","checksum":940454468}]}
1646003678.3217049: {"arg":{"channel":"books-l2-tbt","instId":"PROPS-ETH"},"action":"update","data":[{"asks":[],"bids":[["0.00000167","172714.347553","0","1"]],"ts":"1646003678310","checksum":922692180}]}
1646003678.333707: {"arg":{"channel":"books-l2-tbt","instId":"PROPS-ETH"},"action":"update","data":[{"asks":[],"bids":[["0.00000134","112703.523615","0","1"]],"ts":"1646003678322","checksum":636598449}]}
1646003678.3410292: {"arg":{"channel":"books-l2-tbt","instId":"ELON-USDT"},"action":"update","data":[{"asks":[["0.00000074545","111748770","0","1"],["0.00000074567","0","0","0"],["0.0000011372","6179288","0","1"]],"bids":[["0.00000074435","23770402","0","1"]],"ts":"1646003678327","checksum":312571777}]}
1646003678.359489: {"arg":{"channel":"books-l2-tbt","instId":"UNI-USD-SWAP"},"action":"update","data":[{"asks":[["9.622","83","0","1"],["47.903","0","0","0"]],"bids":[],"ts":"1646003678347","checksum":-1805468655}]}
1646003678.3717928: {"arg":{"channel":"books-l2-tbt","instId":"PROPS-ETH"},"action":"update","data":[{"asks":[],"bids":[["0.00000167","458132.218721","0","3"]],"ts":"1646003678353","checksum":-1325930772}]}
1646003678.372811: {"arg":{"channel":"books-l2-tbt","instId":"ELON-USDT"},"action":"update","data":[{"asks":[],"bids":[["0.00000074381","0","0","0"]],"ts":"1646003678359","checksum":-1792883144}]}
1646003678.381757: {"arg":{"channel":"books-l2-tbt","instId":"ELON-USDT"},"action":"update","data":[{"asks":[["0.00000074544","381506433","0","1"],["0.0000011372","0","0","0"]],"bids":[["0.00000074215","2936212914","0","1"]],"ts":"1646003678369","checksum":1169633362}]}
1646003678.394371: {"arg":{"channel":"books-l2-tbt","instId":"ELON-USDT"},"action":"update","data":[{"asks":[["0.00000074544","433864130","0","2"],["0.00000074545","0","0","0"],["0.00000074551","0","0","0"],["0.0000011372","6179288","0","1"],["0.00000113812","12211658","0","1"]],"bids":[],"ts":"1646003678382","checksum":-1235974268}]}
1646003678.414922: {"arg":{"channel":"books-l2-tbt","instId":"ELON-USDT"},"action":"update","data":[{"asks":[["0.00000074546","0","0","0"],["0.00000074599","81175250","0","1"]],"bids":[],"ts":"1646003678401","checksum":2139250262}]}
1646003678.421294: {"arg":{"channel":"books-l2-tbt","instId":"PROPS-ETH"},"action":"update","data":[{"asks":[["0.00000175","0","0","0"]],"bids":[["0.00000166","1807.22880271","0","1"]],"ts":"1646003678405","checksum":-91595213}]}
1646003678.421946: {"arg":{"channel":"books-l2-tbt","instId":"ELON-USDT"},"action":"update","data":[{"asks":[],"bids":[["0.00000070565","478260999","0","2"],["0.00000069154","302400746","0","1"],["0.00000067771","190698892","0","1"],["0.00000066416","418981957","0","1"],["0.00000064198","0","0","0"]],"ts":"1646003678411","checksum":2139250262}]}
1646003678.438077: {"arg":{"channel":"books-l2-tbt","instId":"PROPS-ETH"},"action":"update","data":[{"asks":[["0.00000174","0","0","0"]],"bids":[],"ts":"1646003678426","checksum":-1585822959}]}
1646003678.447857: {"arg":{"channel":"books-l2-tbt","instId":"PROPS-ETH"},"action":"update","data":[{"asks":[["0.00000175","9695.1318747","0","1"]],"bids":[],"ts":"1646003678436","checksum":-156237858}]}
1646003678.458679: {"arg":{"channel":"books-l2-tbt","instId":"PROPS-ETH"},"action":"update","data":[{"asks":[["0.00000173","9252.53822994","0","1"]],"bids":[["0.00000166","0","0","0"]],"ts":"1646003678446","checksum":281170615}]}
1646003678.4670532: {"arg":{"channel":"books-l2-tbt","instId":"ELON-USDT"},"action":"update","data":[{"asks":[["0.00000074598","445226872","0","1"],["0.00000113812","0","0","0"]],"bids":[],"ts":"1646003678454","checksum":2057679729}]}
1646003678.4730701: {"arg":{"channel":"books-l2-tbt","instId":"ZEN-USDT"},"action":"update","data":[{"asks":[["32.6","207.147338","0","5"]],"bids":[],"ts":"1646003678460","checksum":-335674207}]}
1646003678.481672: {"arg":{"channel":"books-l2-tbt","instId":"PROPS-ETH"},"action":"update","data":[{"asks":[["0.00000175","0","0","0"]],"bids":[],"ts":"1646003678468","checksum":493757929}]}
1646003678.486849: {"arg":{"channel":"books-l2-tbt","instId":"ELON-USDT"},"action":"update","data":[{"asks":[["0.00000074543","48015673","0","1"],["0.0000011372","0","0","0"]],"bids":[],"ts":"1646003678475","checksum":-35620055}]}
1646003678.499906: {"arg":{"channel":"books-l2-tbt","instId":"UNI-USD-SWAP"},"action":"update","data":[{"asks":[["9.63","0","0","0"],["9.632","427","0","3"],["47.903","1","0","1"]],"bids":[],"ts":"1646003678487","checksum":1478441348}]}
1646003678.4999921: {"arg":{"channel":"books-l2-tbt","instId":"PROPS-ETH"},"action":"update","data":[{"asks":[],"bids":[["0.00000166","26973.49229006","0","1"]],"ts":"1646003678487","checksum":-273954826}]}
1646003678.507539: {"arg":{"channel":"trades","instId":"UNI-USD-SWAP"},"data":[{"instId":"UNI-USD-SWAP","tradeId":"12118546","px":"9.615","sz":"10","side":"sell","ts":"1646003678487"}]}
1646003678.507628: {"arg":{"channel":"books-l2-tbt","instId":"ELON-USDT"},"action":"update","data":[{"asks":[["0.00000074544","52357697","0","1"]],"bids":[],"ts":"1646003678493","checksum":-77839773}]}
1646003678.507702: {"arg":{"channel":"books-l2-tbt","instId":"UNI-USD-SWAP"},"action":"update","data":[{"asks":[],"bids":[["9.615","272","0","2"],["9.613","223","0","3"],["9.61","6","0","1"],["9.608","12","0","1"]],"ts":"1646003678494","checksum":1204874810}]}
1646003678.508418: {"arg":{"channel":"books-l2-tbt","instId":"PROPS-ETH"},"action":"update","data":[{"asks":[["0.00000172","9735.64272461","0","1"]],"bids":[],"ts":"1646003678497","checksum":-1355011155}]}
1646003678.514822: {"arg":{"channel":"books-l2-tbt","instId":"ZEN-USDT"},"action":"update","data":[{"asks":[["32.6","175.984801","0","5"],["32.83","0","0","0"],["32.84","1.52","0","1"],["33.15","0","0","0"],["33.16","4.24161","0","2"],["33.48","0.120899","0","1"],["33.49","6.33","0","1"],["33.81","7.48","0","1"],["33.82","8.71715","0","2"],["34.14","0","0","0"],["34.15","11.04","0","1"]],"bids":[["32.21","1.55","0","1"],["32.2","0","0","0"]],"ts":"1646003678502","checksum":-110002484}]}
1646003678.536014: {"arg":{"channel":"books-l2-tbt","instId":"ELON-USDT"},"action":"update","data":[{"asks":[["0.00000074543","0","0","0"],["0.0000011372","6179288","0","1"]],"bids":[],"ts":"1646003678523","checksum":1218468614}]}
1646003678.541024: {"arg":{"channel":"books-l2-tbt","instId":"UNI-USD-SWAP"},"action":"update","data":[{"asks":[["9.627","0","0","0"],["9.629","132","0","2"],["48.143","1","0","1"]],"bids":[],"ts":"1646003678529","checksum":-1878372849}]}
1646003678.550658: {"arg":{"channel":"books-l2-tbt","instId":"PROPS-ETH"},"action":"update","data":[{"asks":[],"bids":[["0.00000166","0","0","0"]],"ts":"1646003678539","checksum":1913528332}]}
1646003678.552777: {"arg":{"channel":"books-l2-tbt","instId":"UNI-USD-SWAP"},"action":"update","data":[{"asks":[["9.621","0","0","0"],["9.622","0","0","0"],["9.661","0","0","0"],["48.383","1","0","1"],["48.625","1","0","1"],["48.868","1","0","1"]],"bids":[["9.576","1052","0","1"]],"ts":"1646003678541","checksum":-497501622}]}
1646003678.55599: {"arg":{"channel":"books-l2-tbt","instId":"BTC-USD-220325-40000-C"},"action":"update","data":[{"asks":[["0.051","0","0","0"],["0.0515","334","0","2"]],"bids":[],"ts":"1646003678546","checksum":932124355}]}
1646003678.556046: {"arg":{"channel":"books-l2-tbt","instId":"ELON-USDT"},"action":"update","data":[{"asks":[["0.00000074597","152061613","0","2"],["0.0000011372","0","0","0"]],"bids":[],"ts":"1646003678546","checksum":766705527}]}
1646003678.560243: {"arg":{"channel":"books-l2-tbt","instId":"UNI-USD-SWAP"},"action":"update","data":[{"asks":[["9.623","83","0","1"],["48.868","0","0","0"]],"bids":[["9.602","76","0","1"],["9.6","0","0","0"],["9.597","0","0","0"]],"ts":"1646003678548","checksum":1929169615}]}
1646003678.5660002: {"arg":{"channel":"tickers","instId":"UNI-USD-SWAP"},"data":[{"instType":"SWAP","instId":"UNI-USD-SWAP","last":"9.615","lastSz":"10","askPx":"9.621","askSz":"260","bidPx":"9.615","bidSz":"282","open24h":"9.022","high24h":"10.152","low24h":"8.65","sodUtc0":"9.067","sodUtc8":"10.078","volCcy24h":"1774366.7992","vol24h":"1699928","ts":"1646003678544"}]}
1646003678.5704262: {"arg":{"channel":"books-l2-tbt","instId":"PROPS-ETH"},"action":"update","data":[{"asks":[],"bids":[["0.00000166","6024.09600903","0","1"]],"ts":"1646003678559","checksum":1790226328}]}
1646003678.5801148: {"arg":{"channel":"books-l2-tbt","instId":"ZEN-USDT"},"action":"update","data":[{"asks":[],"bids":[["32.15","311.331042","0","3"],["32.14","0","0","0"],["31.26","17.06","0","2"],["31.25","2.713961","0","1"]],"ts":"1646003678563","checksum":1262095813}]}
1646003678.5802538: {"arg":{"channel":"books-l2-tbt","instId":"UNI-USD-SWAP"},"action":"update","data":[{"asks":[["9.629","237","0","3"],["9.631","151","0","1"],["9.632","426","0","2"],["9.633","80","0","1"],["9.635","53","0","3"],["9.636","289","0","2"],["9.642","25","0","1"],["9.664","574","0","2"],["48.625","0","0","0"]],"bids":[["9.615","381","0","3"],["9.613","114","0","2"],["9.603","30","0","1"],["9.601","48","0","2"],["9.598","44","0","2"]],"ts":"1646003678560","checksum":1928074010}]}
1646003678.5808058: {"arg":{"channel":"books-l2-tbt","instId":"UNI-USD-SWAP"},"action":"update","data":[{"asks":[["9.625","893","0","2"],["9.629","335","0","4"],["9.637","1263","0","3"],["48.383","0","0","0"]],"bids":[["9.615","272","0","2"],["9.61","0","0","0"],["9.578","574","0","2"]],"ts":"1646003678570","checksum":286703760}]}
1646003678.58734: {"arg":{"channel":"books-l2-tbt","instId":"ZEN-USDT"},"action":"update","data":[{"asks":[["32.89","0","0","0"],["32.9","61.51","0","2"],["33.35","0","0","0"],["33.36","4.52","0","1"],["33.81","0","0","0"],["33.82","16.19715","0","3"],["34.28","0.010156","0","1"],["34.29","10.4","0","1"],["34.75","0","0","0"],["34.77","13.28","0","1"],["44.28","2.338891","0","1"]],"bids":[["31.7","4.71","0","1"],["31.69","4.014515","0","2"],["30.83","11.15","0","1"],["30.82","0","0","0"]],"ts":"1646003678574","checksum":2930036}]}
1646003678.587477: {"arg":{"channel":"books-l2-tbt","instId":"BTC-USD-220325-40000-C"},"action":"update","data":[{"asks":[],"bids":[["0.05","300","0","1"],["0.0495","301","0","1"]],"ts":"1646003678575","checksum":-1235673914}]}
1646003678.5875158: {"arg":{"channel":"books-l2-tbt","instId":"ELON-USDT"},"action":"update","data":[{"asks":[["0.00000074768","0","0","0"],["0.0000011372","6179288","0","1"]],"bids":[],"ts":"1646003678576","checksum":383039662}]}
1646003678.594825: {"arg":{"channel":"books-l2-tbt","instId":"UNI-USD-SWAP"},"action":"update","data":[{"asks":[["9.635","45","0","3"]],"bids":[["9.613","223","0","3"],["9.612","0","0","0"]],"ts":"1646003678581","checksum":-1827842412}]}
1646003678.595475: {"arg":{"channel":"books-l2-tbt","instId":"ZEN-USDT"},"action":"update","data":[{"asks":[["32.56","2.004864","0","1"]],"bids":[["30.4","41.062301","0","3"],["30.39","0","0","0"]],"ts":"1646003678585","checksum":-989369134}]}
1646003678.6025758: {"arg":{"channel":"books-l2-tbt","instId":"UNI-USD-SWAP"},"action":"update","data":[{"asks":[["9.629","230","0","3"],["9.637","1247","0","2"],["9.643","52","0","2"]],"bids":[["9.616","3","0","1"]],"ts":"1646003678591","checksum":1178958746}]}
1646003678.6026711: {"arg":{"channel":"books-l2-tbt","instId":"PROPS-ETH"},"action":"update","data":[{"asks":[],"bids":[["0.00000166","0","0","0"]],"ts":"1646003678591","checksum":1913528332}]}
1646003678.608883: {"arg":{"channel":"books-l2-tbt","instId":"ELON-USDT"},"action":"update","data":[{"asks":[["0.00000074597","220631959","0","3"],["0.00000074761","3203162862","0","1"],["0.0000011372","0","0","0"]],"bids":[],"ts":"1646003678597","checksum":166017289}]}
1646003678.615378: {"arg":{"channel":"books-l2-tbt","instId":"UNI-USD-SWAP"},"action":"update","data":[{"asks":[["9.625","260","0","1"],["9.628","3","0","1"],["9.629","132","0","2"],["9.663","16","0","1"],["48.143","0","0","0"]],"bids":[["9.615","381","0","3"],["9.613","114","0","2"]],"ts":"1646003678604","checksum":1518908083}]}
1646003678.623849: {"arg":{"channel":"books-l2-tbt","instId":"ZEN-USDT"},"action":"update","data":[{"asks":[["32.57","55.758762","0","4"]],"bids":[],"ts":"1646003678605","checksum":-376886199}]}
1646003678.627761: {"arg":{"channel":"books-l2-tbt","instId":"BTC-USD-220325-40000-C"},"action":"update","data":[{"asks":[["0.054","0","0","0"],["0.0545","100","0","1"]],"bids":[],"ts":"1646003678618","checksum":-755393697}]}
1646003678.64076: {"arg":{"channel":"books-l2-tbt","instId":"ELON-USDT"},"action":"update","data":[{"asks":[["0.00000074597","332380729","0","4"]],"bids":[],"ts":"1646003678629","checksum":1432743411}]}
1646003678.640836: {"arg":{"channel":"books-l2-tbt","instId":"UNI-USD-SWAP"},"action":"update","data":[{"asks":[["9.623","0","0","0"],["9.626","23","0","2"],["9.635","27","0","2"],["9.636","337","0","3"],["48.143","1","0","1"]],"bids":[["9.615","369","0","2"]],"ts":"1646003678630","checksum":338018556}]}
1646003678.6460822: {"arg":{"channel":"books-l2-tbt","instId":"UNI-USD-SWAP"},"action":"update","data":[{"asks":[["9.642","75","0","2"],["9.643","23","0","1"],["9.659","1074","0","3"]],"bids":[["9.617","22","0","1"],["9.611","6","0","1"]],"ts":"1646003678634","checksum":1509216464}]}
1646003678.659629: {"arg":{"channel":"books-l2-tbt","instId":"UNI-USD-SWAP"},"action":"update","data":[{"asks":[["9.623","260","0","1"],["9.625","0","0","0"],["9.628","29","0","2"],["9.635","127","0","3"],["9.636","289","0","2"]],"bids":[["9.616","0","0","0"],["9.612","26","0","1"]],"ts":"1646003678647","checksum":769893344}]}
1646003678.667396: {"arg":{"channel":"books-l2-tbt","instId":"UNI-USD-SWAP"},"action":"update","data":[{"asks":[],"bids":[["9.616","109","0","1"]],"ts":"1646003678655","checksum":1262934712}]}
1646003678.676432: {"arg":{"channel":"books-l2-tbt","instId":"UNI-USD-SWAP"},"action":"update","data":[{"asks":[["9.659","1006","0","2"]],"bids":[["9.617","0","0","0"],["9.616","131","0","2"],["9.615","260","0","1"],["9.611","0","0","0"]],"ts":"1646003678665","checksum":197879631}]}
1646003678.683944: {"arg":{"channel":"books-l2-tbt","instId":"ELON-USDT"},"action":"update","data":[{"asks":[["0.00000074596","308035216","0","1"],["0.0000011338","0","0","0"]],"bids":[],"ts":"1646003678671","checksum":-295508602}]}
1646003678.6880372: {"arg":{"channel":"books-l2-tbt","instId":"UNI-USD-SWAP"},"action":"update","data":[{"asks":[],"bids":[["9.617","22","0","1"],["9.616","109","0","1"],["9.615","313","0","2"]],"ts":"1646003678676","checksum":-22283249}]}
1646003678.6988292: {"arg":{"channel":"books-l2-tbt","instId":"UNI-USD-SWAP"},"action":"update","data":[{"asks":[["9.635","27","0","2"],["9.636","342","0","3"]],"bids":[["9.617","282","0","2"]],"ts":"1646003678686","checksum":-1679347103}]}
1646003678.7029388: {"arg":{"channel":"books-l2-tbt","instId":"ELON-USDT"},"action":"update","data":[{"asks":[["0.00000074597","68570346","0","1"]],"bids":[],"ts":"1646003678692","checksum":-1523079121}]}
1646003678.722938: {"arg":{"channel":"books-l2-tbt","instId":"UNI-USD-SWAP"},"action":"update","data":[{"asks":[["9.626","22","0","1"],["9.636","199","0","2"],["9.641","188","0","2"]],"bids":[["9.612","27","0","2"],["9.611","6","0","1"]],"ts":"1646003678708","checksum":-1301123363}]}
1646003678.724925: {"arg":{"channel":"books-l2-tbt","instId":"ELON-USDT"},"action":"update","data":[{"asks":[["0.00000074595","215794710","0","2"],["0.00000113315","0","0","0"]],"bids":[],"ts":"1646003678712","checksum":59057322}]}
1646003678.7424908: {"arg":{"channel":"books-l2-tbt","instId":"UNI-USD-SWAP"},"action":"update","data":[{"asks":[["9.636","194","0","2"]],"bids":[["9.605","51","0","2"],["9.601","25","0","1"],["9.6","29","0","1"],["9.598","16","0","1"]],"ts":"1646003678730","checksum":-259178744}]}
1646003678.745127: {"arg":{"channel":"books-l2-tbt","instId":"ELON-USDT"},"action":"update","data":[{"asks":[["0.00000074595","111748770","0","1"]],"bids":[["0.00000074445","219861835","0","1"]],"ts":"1646003678733","checksum":106717898}]}
1646003678.755819: {"arg":{"channel":"books-l2-tbt","instId":"UNI-USD-SWAP"},"action":"update","data":[{"asks":[["9.626","0","0","0"],["9.636","246","0","2"],["48.383","1","0","1"]],"bids":[],"ts":"1646003678739","checksum":1767753866}]}
1646003678.755907: {"arg":{"channel":"books-l2-tbt","instId":"ELON-USDT"},"action":"update","data":[{"asks":[["0.00000074598","0","0","0"],["0.00000113315","35900750","0","1"]],"bids":[],"ts":"1646003678743","checksum":-1272466698}]}
1646003678.760158: {"arg":{"channel":"books-l2-tbt","instId":"UNI-USD-SWAP"},"action":"update","data":[{"asks":[["9.625","83","0","1"],["48.383","0","0","0"]],"bids":[],"ts":"1646003678749","checksum":157399568}]}
1646003678.7806542: {"arg":{"channel":"books-l2-tbt","instId":"UNI-USD-SWAP"},"action":"update","data":[{"asks":[["9.628","3","0","1"]],"bids":[],"ts":"1646003678770","checksum":-1957653116}]}
1646003678.791424: {"arg":{"channel":"books-l2-tbt","instId":"UNI-USD-SWAP"},"action":"update","data":[{"asks":[],"bids":[["9.615","260","0","1"],["9.579","51","0","1"]],"ts":"1646003678779","checksum":1326754696}]}
1646003678.8030562: {"arg":{"channel":"books-l2-tbt","instId":"UNI-USD-SWAP"},"action":"update","data":[{"asks":[],"bids":[["9.609","0","0","0"],["9.58","65","0","2"]],"ts":"1646003678791","checksum":-273209178}]}
1646003678.803723: {"arg":{"channel":"books-l2-tbt","instId":"ELON-USDT"},"action":"update","data":[{"asks":[["0.00000074597","0","0","0"],["0.0000011338","129154981","0","1"]],"bids":[],"ts":"1646003678793","checksum":301632474}]}
1646003678.8106492: {"arg":{"channel":"books-l2-tbt","instId":"PROPS-ETH"},"action":"update","data":[{"asks":[["0.00000178","787.38623928","0","1"],["0.00000183","0","0","0"],["0.00000184","0","0","0"],["0.00000185","645.87398569","0","1"],["0.00000186","1199.17278222","0","1"]],"bids":[],"ts":"1646003678799","checksum":1176369462}]}
1646003678.81266: {"arg":{"channel":"books-l2-tbt","instId":"UNI-USD-SWAP"},"action":"update","data":[{"asks":[],"bids":[["9.615","320","0","2"]],"ts":"1646003678802","checksum":-1796852229}]}
1646003678.8211489: {"arg":{"channel":"books-l2-tbt","instId":"ELON-USDT"},"action":"update","data":[{"asks":[["0.00000074543","53107723","0","1"],["0.00000074544","0","0","0"]],"bids":[],"ts":"1646003678805","checksum":669384621}]}
1646003678.827421: {"arg":{"channel":"books-l2-tbt","instId":"ELON-USDT"},"action":"update","data":[{"asks":[["0.00000074595","0","0","0"],["0.0000011372","6179288","0","1"]],"bids":[],"ts":"1646003678815","checksum":1274361509}]}
1646003678.834916: {"arg":{"channel":"books-l2-tbt","instId":"UNI-USD-SWAP"},"action":"update","data":[{"asks":[["9.643","0","0","0"],["9.645","777","0","4"],["9.646","16","0","1"],["9.648","24","0","2"],["9.649","242","0","2"],["9.651","104","0","3"],["48.383","1","0","1"]],"bids":[["9.605","29","0","1"],["9.601","51","0","2"],["9.6","0","0","0"],["9.598","37","0","2"]],"ts":"1646003678821","checksum":-1723210445}]}
1646003678.835882: {"arg":{"channel":"books-l2-tbt","instId":"ELON-USDT"},"action":"update","data":[{"asks":[],"bids":[["0.00000074446","184440410","0","1"]],"ts":"1646003678825","checksum":1737087433}]}
1646003678.8747678: {"arg":{"channel":"books-l2-tbt","instId":"ZEN-USDT"},"action":"update","data":[{"asks":[],"bids":[["31.89","8.773961","0","3"],["31.88","7.58","0","2"],["31.58","6.59","0","1"],["31.57","5.053385","0","2"],["31.27","11.422752","0","2"],["31.26","7.91","0","1"],["30.96","11.73","0","1"],["30.95","0","0","0"]],"ts":"1646003678863","checksum":-376886199}]}
1646003678.889426: {"arg":{"channel":"books-l2-tbt","instId":"ELON-USDT"},"action":"update","data":[{"asks":[["0.00000074599","0","0","0"],["0.00000113812","12211658","0","1"]],"bids":[],"ts":"1646003678877","checksum":1590614478}]}
1646003678.8966331: {"arg":{"channel":"books-l2-tbt","instId":"UNI-USD-SWAP"},"action":"update","data":[{"asks":[["9.623","0","0","0"],["9.636","194","0","2"],["48.625","1","0","1"]],"bids":[["9.616","162","0","2"]],"ts":"1646003678885","checksum":-769961994}]}
1646003678.896717: {"arg":{"channel":"books-l2-tbt","instId":"ZEN-USDT"},"action":"update","data":[{"asks":[["32.55","2.285642","0","1"]],"bids":[],"ts":"1646003678886","checksum":1255745389}]}
1646003678.9099462: {"arg":{"channel":"books-l2-tbt","instId":"UNI-USD-SWAP"},"action":"update","data":[{"asks":[["9.658","0","0","0"],["9.665","79","0","1"]],"bids":[],"ts":"1646003678896","checksum":1061077030}]}
1646003678.910066: {"arg":{"channel":"books-l2-tbt","instId":"ELON-USDT"},"action":"update","data":[{"asks":[["0.00000074595","48015673","0","1"],["0.00000113812","0","0","0"]],"bids":[],"ts":"1646003678897","checksum":2118977871}]}
1646003678.921254: {"arg":{"channel":"books-l2-tbt","instId":"UNI-USD-SWAP"},"action":"update","data":[{"asks":[["9.625","0","0","0"],["9.629","120","0","1"],["9.633","0","0","0"],["9.635","63","0","3"],["9.662","11","0","1"],["48.868","1","0","1"]],"bids":[["9.569","0","0","0"]],"ts":"1646003678910","checksum":802535262}]}
1646003678.925513: {"arg":{"channel":"books-l2-tbt","instId":"ZEN-USDT"},"action":"update","data":[{"asks":[["32.56","5.658944","0","2"]],"bids":[],"ts":"1646003678914","checksum":1175092306}]}
1646003678.928683: {"arg":{"channel":"books-l2-tbt","instId":"UNI-USD-SWAP"},"action":"update","data":[{"asks":[["9.636","146","0","1"],["9.637","1279","0","3"]],"bids":[["9.604","344","0","3"],["9.603","0","0","0"],["9.602","96","0","2"],["9.601","25","0","1"],["9.599","645","0","3"],["9.598","16","0","1"],["9.581","9543","0","2"]],"ts":"1646003678917","checksum":-888340873}]}
1646003678.9336698: {"arg":{"channel":"books-l2-tbt","instId":"ELON-USDT"},"action":"update","data":[{"asks":[],"bids":[["0.00000070565","144547580","0","1"],["0.00000069154","0","0","0"],["0.00000067771","0","0","0"],["0.00000066416","0","0","0"],["0.00000065074","219845768","0","1"]],"ts":"1646003678918","checksum":2118977871}]}
1646003678.938544: {"arg":{"channel":"books-l2-tbt","instId":"UNI-USD-SWAP"},"action":"update","data":[{"asks":[["9.627","825","0","2"],["9.628","25","0","2"],["9.63","203","0","2"],["48.625","0","0","0"],["48.868","0","0","0"]],"bids":[["9.616","53","0","1"]],"ts":"1646003678928","checksum":-1614140291}]}
1646003678.941668: {"arg":{"channel":"books-l2-tbt","instId":"ELON-USDT"},"action":"update","data":[{"asks":[["0.00000074594","445226872","0","1"],["0.0000011372","0","0","0"]],"bids":[["0.00000074435","0","0","0"]],"ts":"1646003678929","checksum":1666854361}]}
1646003678.950316: {"arg":{"channel":"books-l2-tbt","instId":"ELON-USDT"},"action":"update","data":[{"asks":[["0.00000074595","152061613","0","2"]],"bids":[],"ts":"1646003678937","checksum":-1822358193}]}
1646003678.950368: {"arg":{"channel":"books-l2-tbt","instId":"UNI-USD-SWAP"},"action":"update","data":[{"asks":[["9.663","0","0","0"],["9.665","95","0","2"],["48.625","1","0","1"]],"bids":[["9.615","332","0","3"]],"ts":"1646003678938","checksum":-615359553}]}
1646003678.963582: {"arg":{"channel":"books-l2-tbt","instId":"UNI-USD-SWAP"},"action":"update","data":[{"asks":[["9.627","260","0","1"]],"bids":[["9.614","109","0","1"]],"ts":"1646003678950","checksum":88049426}]}
1646003678.963704: {"arg":{"channel":"books-l2-tbt","instId":"ELON-USDT"},"action":"update","data":[{"asks":[["0.00000074595","233236863","0","3"]],"bids":[],"ts":"1646003678950","checksum":1292582488}]}
1646003678.9689999: {"arg":{"channel":"books-l2-tbt","instId":"UNI-USD-SWAP"},"action":"update","data":[{"asks":[["9.626","83","0","1"],["9.637","1284","0","3"],["48.625","0","0","0"]],"bids":[],"ts":"1646003678958","checksum":-1783495983}]}
1646003678.981487: {"arg":{"channel":"books-l2-tbt","instId":"UNI-USD-SWAP"},"action":"update","data":[{"asks":[],"bids":[["9.618","3","0","1"],["9.606","0","0","0"]],"ts":"1646003678969","checksum":1302417854}]}
1646003678.981606: {"arg":{"channel":"books-l2-tbt","instId":"ELON-USDT"},"action":"update","data":[{"asks":[["0.00000074595","81175250","0","1"]],"bids":[],"ts":"1646003678969","checksum":-1951384344}]}
1646003678.990737: {"arg":{"channel":"books-l2-tbt","instId":"ELON-USDT"},"action":"update","data":[{"asks":[["0.00000074596","0","0","0"],["0.0000011372","6179288","0","1"]],"bids":[],"ts":"1646003678980","checksum":-2042274594}]}
1646003678.993994: {"arg":{"channel":"books-l2-tbt","instId":"UNI-USD-SWAP"},"action":"update","data":[{"asks":[["9.625","260","0","1"],["48.383","0","0","0"]],"bids":[["9.616","0","0","0"],["9.612","1","0","1"],["9.608","512","0","2"]],"ts":"1646003678979","checksum":-2025366822}]}
1646003679.001025: {"arg":{"channel":"books-l2-tbt","instId":"ELON-USDT"},"action":"update","data":[{"asks":[["0.00000074593","263810383","0","3"],["0.0000011372","0","0","0"]],"bids":[],"ts":"1646003678989","checksum":851071034}]}
1646003679.0011241: {"arg":{"channel":"books-l2-tbt","instId":"UNI-USD-SWAP"},"action":"update","data":[{"asks":[["9.636","246","0","2"],["9.637","1247","0","2"]],"bids":[],"ts":"1646003678990","checksum":424175131}]}
1646003679.011591: {"arg":{"channel":"books-l2-tbt","instId":"ELON-USDT"},"action":"update","data":[{"asks":[["0.00000074543","0","0","0"],["0.00000074593","384738426","0","5"],["0.0000011372","6179288","0","1"]],"bids":[],"ts":"1646003678999","checksum":-5458453}]}
1646003679.0116758: {"arg":{"channel":"books-l2-tbt","instId":"UNI-USD-SWAP"},"action":"update","data":[{"asks":[],"bids":[["9.612","0","0","0"]],"ts":"1646003679000","checksum":1898301010}]}
1646003679.0236712: {"arg":{"channel":"books-l2-tbt","instId":"ELON-USDT"},"action":"update","data":[{"asks":[["0.00000074761","0","0","0"],["0.00000113812","12211658","0","1"]],"bids":[],"ts":"1646003679011","checksum":-1396253368}]}
1646003679.034964: {"arg":{"channel":"books-l2-tbt","instId":"UNI-USD-SWAP"},"action":"update","data":[{"asks":[["9.635","68","0","4"],["9.636","146","0","1"],["9.645","748","0","3"],["9.654","9305","0","3"]],"bids":[["9.605","54","0","2"],["9.604","317","0","2"],["9.603","28","0","1"],["9.602","76","0","1"],["9.6","28","0","1"],["9.599","620","0","2"]],"ts":"1646003679021","checksum":1295199493}]}
1646003679.0390909: {"arg":{"channel":"books-l2-tbt","instId":"ZEN-USDT"},"action":"update","data":[{"asks":[["33.16","0.30161","0","1"],["33.17","3.93","0","1"],["33.49","0","0","0"],["33.5","6.816261","0","3"],["33.82","7.49715","0","2"],["33.83","8.68","0","1"],["34.15","0","0","0"],["34.16","11.02","0","1"],["44.28","0","0","0"]],"bids":[],"ts":"1646003679027","checksum":1175092306}]}
1646003679.05394: {"arg":{"channel":"books-l2-tbt","instId":"UNI-USD-SWAP"},"action":"update","data":[{"asks":[["9.628","51","0","3"],["9.629","0","0","0"],["48.383","1","0","1"]],"bids":[],"ts":"1646003679042","checksum":-1579558329}]}
1646003679.066068: {"arg":{"channel":"books-l2-tbt","instId":"UNI-USD-SWAP"},"action":"update","data":[{"asks":[["9.626","0","0","0"],["48.625","1","0","1"]],"bids":[["9.581","9539","0","1"]],"ts":"1646003679055","checksum":1278011928}]}
1646003679.078891: {"arg":{"channel":"books-l2-tbt","instId":"UNI-USD-SWAP"},"action":"update","data":[{"asks":[["9.635","63","0","3"],["9.636","246","0","2"]],"bids":[["9.579","55","0","2"]],"ts":"1646003679068","checksum":-777794390}]}
1646003679.086092: {"arg":{"channel":"books-l2-tbt","instId":"UNI-USD-SWAP"},"action":"update","data":[{"asks":[["9.631","255","0","2"],["9.635","68","0","4"],["9.636","146","0","1"]],"bids":[["9.609","5","0","1"]],"ts":"1646003679075","checksum":364055448}]}
1646003679.0924292: {"arg":{"channel":"books-l2-tbt","instId":"ELON-USDT"},"action":"update","data":[{"asks":[["0.00000074592","445226872","0","1"],["0.00000113812","0","0","0"]],"bids":[],"ts":"1646003679081","checksum":-2012458934}]}
1646003679.10544: {"arg":{"channel":"books-l2-tbt","instId":"UNI-USD-SWAP"},"action":"update","data":[{"asks":[["9.627","0","0","0"],["9.628","48","0","2"],["9.635","63","0","3"],["48.868","1","0","1"]],"bids":[["9.615","385","0","4"]],"ts":"1646003679095","checksum":-380399807}]}
1646003679.115381: {"arg":{"channel":"books-l2-tbt","instId":"ELON-USDT"},"action":"update","data":[{"asks":[["0.00000074593","120928043","0","2"],["0.00000074771","3602131671","0","1"],["0.0000011372","0","0","0"]],"bids":[],"ts":"1646003679102","checksum":75580197}]}
1646003679.1160588: {"arg":{"channel":"books-l2-tbt","instId":"UNI-USD-SWAP"},"action":"update","data":[{"asks":[["9.628","22","0","1"]],"bids":[["9.618","0","0","0"]],"ts":"1646003679105","checksum":-2117808425}]}
1646003679.127841: {"arg":{"channel":"books-l2-tbt","instId":"ELON-USDT"},"action":"update","data":[{"asks":[["0.00000074594","0","0","0"],["0.0000011372","6179288","0","1"]],"bids":[],"ts":"1646003679113","checksum":-9320468}]}
1646003679.136511: {"arg":{"channel":"books-l2-tbt","instId":"ELON-USDT"},"action":"update","data":[{"asks":[["0.00000074591","215794710","0","2"],["0.0000011372","0","0","0"]],"bids":[],"ts":"1646003679124","checksum":-855471343}]}
1646003679.137205: {"arg":{"channel":"books-l2-tbt","instId":"UNI-USD-SWAP"},"action":"update","data":[{"asks":[["9.627","1","0","1"],["9.628","0","0","0"],["9.662","0","0","0"],["9.665","16","0","1"],["49.113","1","0","1"]],"bids":[["9.581","0","0","0"]],"ts":"1646003679126","checksum":614672409}]}
1646003679.147722: {"arg":{"channel":"books-l2-tbt","instId":"ELON-USDT"},"action":"update","data":[{"asks":[["0.0000007549","0","0","0"],["0.0000011372","6179288","0","1"]],"bids":[],"ts":"1646003679135","checksum":-1273446013}]}
1646003679.150199: {"arg":{"channel":"books-l2-tbt","instId":"UNI-USD-SWAP"},"action":"update","data":[{"asks":[["9.645","772","0","4"],["9.654","9280","0","2"]],"bids":[["9.609","0","0","0"],["9.606","27","0","1"],["9.605","29","0","1"],["9.604","347","0","3"],["9.603","0","0","0"],["9.601","54","0","2"],["9.6","0","0","0"]],"ts":"1646003679137","checksum":-1357311597}]}
1646003679.159303: {"arg":{"channel":"books-l2-tbt","instId":"UNI-USD-SWAP"},"action":"update","data":[{"asks":[],"bids":[["9.586","9681","0","2"]],"ts":"1646003679148","checksum":1875924689}]}
1646003679.171048: {"arg":{"channel":"books-l2-tbt","instId":"UNI-USD-SWAP"},"action":"update","data":[{"asks":[["9.625","343","0","2"],["9.661","50","0","1"],["49.113","0","0","0"]],"bids":[],"ts":"1646003679159","checksum":739325453}]}
1646003679.1788118: {"arg":{"channel":"books-l2-tbt","instId":"UNI-USD-SWAP"},"action":"update","data":[{"asks":[["9.657","11","0","1"],["48.868","0","0","0"]],"bids":[],"ts":"1646003679167","checksum":-1531137499}]}
1646003679.196138: {"arg":{"channel":"trades","instId":"ZEN-USDT"},"data":[{"instId":"ZEN-USDT","tradeId":"15270486","px":"32.51","sz":"0.416595","side":"buy","ts":"1646003679181"}]}
1646003679.196225: {"arg":{"channel":"books-l2-tbt","instId":"UNI-USD-SWAP"},"action":"update","data":[{"asks":[["9.63","307","0","3"],["9.631","151","0","1"],["9.632","485","0","3"],["9.635","27","0","2"]],"bids":[["9.616","1","0","1"]],"ts":"1646003679184","checksum":-1172116269}]}
1646003679.1989849: {"arg":{"channel":"books-l2-tbt","instId":"UNI-USD-SWAP"},"action":"update","data":[{"asks":[["9.629","3","0","1"],["48.625","0","0","0"]],"bids":[],"ts":"1646003679187","checksum":1070677919}]}
1646003679.199048: {"arg":{"channel":"books-l2-tbt","instId":"ELON-USDT"},"action":"update","data":[{"asks":[["0.0000007459","445226872","0","1"],["0.0000011372","0","0","0"]],"bids":[],"ts":"1646003679187","checksum":-1574299494}]}
1646003679.207861: {"arg":{"channel":"books-l2-tbt","instId":"ELON-USDT"},"action":"update","data":[{"asks":[],"bids":[["0.00000074445","0","0","0"]],"ts":"1646003679197","checksum":88561544}]}
1646003679.207969: {"arg":{"channel":"books-l2-tbt","instId":"UNI-USD-SWAP"},"action":"update","data":[{"asks":[["9.627","0","0","0"],["48.625","1","0","1"]],"bids":[],"ts":"1646003679197","checksum":-33168279}]}
1646003679.219201: {"arg":{"channel":"books-l2-tbt","instId":"ELON-USDT"},"action":"update","data":[{"asks":[["0.00000074591","0","0","0"],["0.00000074593","0","0","0"],["0.0000011372","6179288","0","1"],["0.00000113812","12211658","0","1"]],"bids":[],"ts":"1646003679207","checksum":161302446}]}
1646003679.228029: {"arg":{"channel":"books-l2-tbt","instId":"ELON-USDT"},"action":"update","data":[{"asks":[["0.00000074589","53107723","0","1"],["0.00000113812","0","0","0"]],"bids":[],"ts":"1646003679216","checksum":1534608127}]}
1646003679.238778: {"arg":{"channel":"books-l2-tbt","instId":"UNI-USD-SWAP"},"action":"update","data":[{"asks":[["9.629","107","0","2"],["9.63","203","0","2"],["9.635","31","0","3"]],"bids":[["9.611","0","0","0"]],"ts":"1646003679218","checksum":1610680473}]}
1646003679.238935: {"arg":{"channel":"books-l2-tbt","instId":"ELON-USDT"},"action":"update","data":[{"asks":[["0.00000074589","157153663","0","2"],["0.00000074592","0","0","0"],["0.00000113812","12211658","0","1"]],"bids":[],"ts":"1646003679227","checksum":-1990052362}]}
1646003679.263812: {"arg":{"channel":"books-l2-tbt","instId":"UNI-USD-SWAP"},"action":"update","data":[{"asks":[["9.624","560","0","1"],["9.625","260","0","1"],["9.628","2","0","1"],["9.635","27","0","2"],["48.383","0","0","0"],["48.625","0","0","0"]],"bids":[["9.609","6","0","1"]],"ts":"1646003679252","checksum":-1055993892}]}
1646003679.2701418: {"arg":{"channel":"books-l2-tbt","instId":"ELON-USDT"},"action":"update","data":[{"asks":[],"bids":[["0.00000074435","184440410","0","1"]],"ts":"1646003679258","checksum":47181661}]}
1646003679.274334: {"arg":{"channel":"books-l2-tbt","instId":"UNI-USD-SWAP"},"action":"update","data":[{"asks":[["9.644","29","0","1"],["9.645","748","0","3"],["9.647","2581","0","6"],["9.648","1","0","1"],["9.65","255","0","2"],["9.651","79","0","2"],["48.143","0","0","0"]],"bids":[["9.606","0","0","0"],["9.604","317","0","2"],["9.603","27","0","1"],["9.598","38","0","2"]],"ts":"1646003679262","checksum":-1163389220}]}
1646003679.2844858: {"arg":{"channel":"books-l2-tbt","instId":"UNI-USD-SWAP"},"action":"update","data":[{"asks":[["9.623","260","0","1"],["9.628","106","0","2"],["9.629","0","0","0"]],"bids":[["9.616","0","0","0"],["9.615","332","0","3"]],"ts":"1646003679271","checksum":216941345}]}
1646003679.289353: {"arg":{"channel":"books-l2-tbt","instId":"ELON-USDT"},"action":"update","data":[{"asks":[["0.00000074589","205169336","0","3"]],"bids":[],"ts":"1646003679278","checksum":1697492099}]}
1646003679.2962718: {"arg":{"channel":"books-l2-tbt","instId":"UNI-USD-SWAP"},"action":"update","data":[{"asks":[],"bids":[["9.614","162","0","2"]],"ts":"1646003679282","checksum":-984819507}]}
1646003679.3101408: {"arg":{"channel":"books-l2-tbt","instId":"ELON-USDT"},"action":"update","data":[{"asks":[],"bids":[["0.00000074446","0","0","0"]],"ts":"1646003679299","checksum":1364057041}]}
1646003679.320054: {"arg":{"channel":"books-l2-tbt","instId":"PROPS-ETH"},"action":"update","data":[{"asks":[["0.00000178","0","0","0"],["0.00000183","1448.54122436","0","1"],["0.00000184","503.54661198","0","1"],["0.00000186","0","0","0"],["0.00000187","0","0","0"]],"bids":[],"ts":"1646003679303","checksum":-1514368747}]}
1646003679.3201542: {"arg":{"channel":"books-l2-tbt","instId":"ELON-USDT"},"action":"update","data":[{"asks":[["0.00000074588","445226872","0","1"],["0.00000113812","0","0","0"]],"bids":[],"ts":"1646003679308","checksum":-2026523984}]}
1646003679.327564: {"arg":{"channel":"books-l2-tbt","instId":"UNI-USD-SWAP"},"action":"update","data":[{"asks":[["9.628","2","0","1"],["9.629","97","0","1"],["9.638","138","0","3"],["47.903","0","0","0"]],"bids":[["9.579","51","0","1"],["9.577","293","0","3"]],"ts":"1646003679315","checksum":521935163}]}
1646003679.328257: {"arg":{"channel":"books-l2-tbt","instId":"ELON-USDT"},"action":"update","data":[{"asks":[],"bids":[["0.00000074215","0","0","0"]],"ts":"1646003679318","checksum":153001114}]}
1646003679.336149: {"arg":{"channel":"books-l2-tbt","instId":"UNI-USD-SWAP"},"action":"update","data":[{"asks":[["9.627","1","0","1"],["9.628","97","0","1"],["9.629","0","0","0"],["9.657","0","0","0"],["47.903","1","0","1"]],"bids":[],"ts":"1646003679324","checksum":831100301}]}
1646003679.34109: {"arg":{"channel":"books-l2-tbt","instId":"ELON-USDT"},"action":"update","data":[{"asks":[["0.00000074589","53107723","0","1"]],"bids":[],"ts":"1646003679329","checksum":-2114287519}]}
1646003679.353272: {"arg":{"channel":"books-l2-tbt","instId":"ELON-USDT"},"action":"update","data":[{"asks":[["0.0000007459","0","0","0"],["0.00000113812","12211658","0","1"]],"bids":[["0.00000074263","3335642820","0","1"]],"ts":"1646003679339","checksum":665147965}]}
1646003679.3560588: {"arg":{"channel":"tickers","instId":"ZEN-USDT"},"data":[{"instType":"SPOT","instId":"ZEN-USDT","last":"32.51","lastSz":"0.416595","askPx":"32.53","askSz":"0.383596","bidPx":"32.5","bidSz":"0.399716","open24h":"33.34","high24h":"35.26","low24h":"31.91","sodUtc0":"33.36","sodUtc8":"34.26","volCcy24h":"1483634.442927","vol24h":"44365.604607","ts":"1646003679333"}]}
1646003679.356111: {"arg":{"channel":"books-l2-tbt","instId":"UNI-USD-SWAP"},"action":"update","data":[{"asks":[["9.624","0","0","0"],["9.628","0","0","0"],["9.629","97","0","1"],["48.143","1","0","1"]],"bids":[],"ts":"1646003679344","checksum":-1655702025}]}
1646003679.36065: {"arg":{"channel":"books-l2-tbt","instId":"ELON-USDT"},"action":"update","data":[{"asks":[["0.00000074587","48015673","0","1"],["0.00000113812","0","0","0"]],"bids":[],"ts":"1646003679348","checksum":-243955343}]}
1646003679.364877: {"arg":{"channel":"books-l2-tbt","instId":"UNI-USD-SWAP"},"action":"update","data":[{"asks":[["9.624","83","0","1"],["9.627","0","0","0"]],"bids":[],"ts":"1646003679352","checksum":893644281}]}
1646003679.3691468: {"arg":{"channel":"books-l2-tbt","instId":"BTC-USD-220325-40000-C"},"action":"update","data":[{"asks":[["0.054","100","0","1"],["0.0545","0","0","0"]],"bids":[],"ts":"1646003679358","checksum":-1235673914}]}
1646003679.37798: {"arg":{"channel":"books-l2-tbt","instId":"UNI-USD-SWAP"},"action":"update","data":[{"asks":[["9.625","0","0","0"],["48.383","1","0","1"]],"bids":[["9.617","22","0","1"]],"ts":"1646003679364","checksum":-561407904}]}
1646003679.393263: {"arg":{"channel":"books-l2-tbt","instId":"ELON-USDT"},"action":"update","data":[{"asks":[],"bids":[["0.000000741","0","0","0"]],"ts":"1646003679381","checksum":1495712581}]}
1646003679.395046: {"arg":{"channel":"books-l2-tbt","instId":"UNI-USD-SWAP"},"action":"update","data":[{"asks":[["9.628","3","0","1"],["48.383","0","0","0"]],"bids":[["9.617","0","0","0"],["9.616","22","0","1"]],"ts":"1646003679384","checksum":114061862}]}
1646003679.4140038: {"arg":{"channel":"books-l2-tbt","instId":"ELON-USDT"},"action":"update","data":[{"asks":[["0.00000074587","159764443","0","2"]],"bids":[],"ts":"1646003679399","checksum":1155962021}]}
1646003679.4213219: {"arg":{"channel":"books-l2-tbt","instId":"ELON-USDT"},"action":"update","data":[{"asks":[["0.00000074587","280692486","0","4"],["0.00000074589","0","0","0"],["0.00000113812","12211658","0","1"]],"bids":[["0.00000070254","325621233","0","1"],["0.00000068849","272935365","0","1"],["0.00000067473","232689528","0","1"],["0.00000066124","298840442","0","1"],["0.00000065074","0","0","0"]],"ts":"1646003679409","checksum":1610235148}]}
1646003679.4446552: {"arg":{"channel":"books-l2-tbt","instId":"ELON-USDT"},"action":"update","data":[{"asks":[["0.00000074586","445226872","0","1"],["0.00000113812","0","0","0"]],"bids":[],"ts":"1646003679431","checksum":-588182250}]}
1646003679.4589481: {"arg":{"channel":"books-l2-tbt","instId":"PROPS-ETH"},"action":"update","data":[{"asks":[],"bids":[["0.00000166","129490.77863735","0","1"]],"ts":"1646003679445","checksum":-1053421696}]}
1646003679.462826: {"arg":{"channel":"books-l2-tbt","instId":"UNI-USD-SWAP"},"action":"update","data":[{"asks":[["9.635","36","0","3"],["9.643","28","0","1"],["9.644","0","0","0"],["9.646","38","0","2"],["9.647","2554","0","5"],["9.649","272","0","3"],["9.65","225","0","1"],["9.66","44","0","1"],["48.143","0","0","0"]],"bids":[["9.604","346","0","3"],["9.603","0","0","0"],["9.602","102","0","2"],["9.601","25","0","1"],["9.599","643","0","3"],["9.598","16","0","1"]],"ts":"1646003679449","checksum":1435587036}]}
1646003679.465336: {"arg":{"channel":"books-l2-tbt","instId":"ELON-USDT"},"action":"update","data":[{"asks":[["0.00000074587","120928043","0","2"]],"bids":[],"ts":"1646003679452","checksum":1419221099}]}
1646003679.465456: {"arg":{"channel":"books-l2-tbt","instId":"ETH-USD-220325-8800-P"},"action":"update","data":[{"asks":[["2.5485","0","0","0"],["2.549","201","0","1"]],"bids":[],"ts":"1646003679454","checksum":957925562}]}
1646003679.47278: {"arg":{"channel":"books-l2-tbt","instId":"UNI-USD-SWAP"},"action":"update","data":[{"asks":[["9.624","0","0","0"],["9.635","31","0","3"],["48.143","1","0","1"]],"bids":[],"ts":"1646003679460","checksum":1622978613}]}
1646003679.4769762: {"arg":{"channel":"books-l2-tbt","instId":"PROPS-ETH"},"action":"update","data":[{"asks":[],"bids":[["0.00000167","172714.347553","0","1"]],"ts":"1646003679466","checksum":-185374274}]}
1646003679.484916: {"arg":{"channel":"books-l2-tbt","instId":"ELON-USDT"},"action":"update","data":[{"asks":[["0.00000074585","111748770","0","1"],["0.0000011372","0","0","0"]],"bids":[],"ts":"1646003679471","checksum":100252727}]}
1646003679.497694: {"arg":{"channel":"books-l2-tbt","instId":"ELON-USDT"},"action":"update","data":[{"asks":[["0.00000074588","0","0","0"],["0.0000011372","6179288","0","1"]],"bids":[],"ts":"1646003679481","checksum":-412487891}]}
1646003679.4978309: {"arg":{"channel":"books-l2-tbt","instId":"UNI-USD-SWAP"},"action":"update","data":[{"asks":[["9.628","100","0","2"],["9.629","0","0","0"],["9.635","36","0","3"],["48.383","1","0","1"]],"bids":[],"ts":"1646003679482","checksum":-747881983}]}
1646003679.501903: {"arg":{"channel":"books-l2-tbt","instId":"UNI-USD-SWAP"},"action":"update","data":[{"asks":[["9.651","50","0","1"]],"bids":[["9.609","12","0","2"]],"ts":"1646003679490","checksum":1760560291}]}
1646003679.51305: {"arg":{"channel":"books-l2-tbt","instId":"ZEN-USDT"},"action":"update","data":[{"asks":[],"bids":[["32.41","0","0","0"]],"ts":"1646003679500","checksum":-1023294924}]}
1646003679.513162: {"arg":{"channel":"books-l2-tbt","instId":"UNI-USD-SWAP"},"action":"update","data":[{"asks":[["9.628","3","0","1"],["9.629","97","0","1"],["9.635","41","0","3"],["9.66","0","0","0"]],"bids":[],"ts":"1646003679500","checksum":1808030784}]}
1646003679.523519: {"arg":{"channel":"books-l2-tbt","instId":"ELON-USDT"},"action":"update","data":[{"asks":[["0.00000074595","0","0","0"],["0.00000113812","12211658","0","1"]],"bids":[],"ts":"1646003679512","checksum":-1285057580}]}
1646003679.527775: {"arg":{"channel":"books-l2-tbt","instId":"PROPS-ETH"},"action":"update","data":[{"asks":[],"bids":[["0.00000167","458788.423005","0","3"]],"ts":"1646003679517","checksum":-17927529}]}
1646003679.535197: {"arg":{"channel":"books-l2-tbt","instId":"UNI-USD-SWAP"},"action":"update","data":[{"asks":[["9.627","3","0","1"],["9.628","100","0","2"],["9.629","0","0","0"]],"bids":[],"ts":"1646003679521","checksum":161070801}]}
1646003679.548356: {"arg":{"channel":"books-l2-tbt","instId":"UNI-USD-SWAP"},"action":"update","data":[{"asks":[],"bids":[["9.61","3","0","1"]],"ts":"1646003679531","checksum":-864343327}]}
1646003679.5484328: {"arg":{"channel":"books-l2-tbt","instId":"ELON-USDT"},"action":"update","data":[{"asks":[["0.00000074585","215794710","0","2"]],"bids":[["0.00000072102","0","0","0"]],"ts":"1646003679534","checksum":1298691814}]}
1646003679.568983: {"arg":{"channel":"books-l2-tbt","instId":"UNI-USD-SWAP"},"action":"update","data":[{"asks":[["9.623","343","0","2"],["9.627","0","0","0"],["48.625","1","0","1"]],"bids":[["9.615","272","0","2"],["9.614","109","0","1"],["9.613","167","0","3"],["9.609","6","0","1"]],"ts":"1646003679554","checksum":-1757410036}]}
1646003679.571935: {"arg":{"channel":"books-l2-tbt","instId":"ZEN-USDT"},"action":"update","data":[{"asks":[["32.61","35.959536","0","1"],["44.27","0","0","0"]],"bids":[],"ts":"1646003679561","checksum":-2101476658}]}
1646003679.5741289: {"arg":{"channel":"books-l2-tbt","instId":"UNI-USD-SWAP"},"action":"update","data":[{"asks":[["9.628","97","0","1"]],"bids":[],"ts":"1646003679564","checksum":-2014725439}]}
1646003679.586087: {"arg":{"channel":"books-l2-tbt","instId":"UNI-USD-SWAP"},"action":"update","data":[{"asks":[["9.627","3","0","1"],["48.625","0","0","0"]],"bids":[],"ts":"1646003679574","checksum":1343593112}]}
1646003679.6142132: {"arg":{"channel":"books-l2-tbt","instId":"ELON-USDT"},"action":"update","data":[{"asks":[["0.00000074584","445226872","0","1"],["0.00000113812","0","0","0"]],"bids":[],"ts":"1646003679602","checksum":69388207}]}
1646003679.620085: {"arg":{"channel":"books-l2-tbt","instId":"UNI-USD-SWAP"},"action":"update","data":[{"asks":[["9.627","100","0","2"],["9.628","0","0","0"],["48.625","1","0","1"]],"bids":[],"ts":"1646003679606","checksum":180329927}]}
1646003679.6246662: {"arg":{"channel":"books-l2-tbt","instId":"ELON-USDT"},"action":"update","data":[{"asks":[["0.00000074587","0","0","0"],["0.00000113812","12211658","0","1"]],"bids":[],"ts":"1646003679613","checksum":766181581}]}
1646003679.636547: {"arg":{"channel":"books-l2-tbt","instId":"ELON-USDT"},"action":"update","data":[{"asks":[["0.00000074585","0","0","0"],["0.00000074587","81175250","0","1"]],"bids":[["0.0000007445","219861835","0","1"]],"ts":"1646003679625","checksum":1710933353}]}
1646003679.6396391: {"arg":{"channel":"books-l2-tbt","instId":"UNI-USD-SWAP"},"action":"update","data":[{"asks":[["9.626","1","0","1"],["48.625","0","0","0"]],"bids":[],"ts":"1646003679628","checksum":1897897270}]}
1646003679.6466: {"arg":{"channel":"books-l2-tbt","instId":"ELON-USDT"},"action":"update","data":[{"asks":[["0.00000074583","104045940","0","1"],["0.00000113812","0","0","0"]],"bids":[],"ts":"1646003679634","checksum":-75124581}]}
1646003679.662165: {"arg":{"channel":"books-l2-tbt","instId":"UNI-USD-SWAP"},"action":"update","data":[{"asks":[["9.627","3","0","1"],["9.629","97","0","1"],["48.383","0","0","0"]],"bids":[],"ts":"1646003679650","checksum":-282180786}]}
1646003679.671465: {"arg":{"channel":"books-l2-tbt","instId":"UNI-USD-SWAP"},"action":"update","data":[{"asks":[["9.627","0","0","0"],["48.383","1","0","1"]],"bids":[],"ts":"1646003679660","checksum":842795828}]}
1646003679.683528: {"arg":{"channel":"books-l2-tbt","instId":"UNI-USD-SWAP"},"action":"update","data":[{"asks":[["9.642","99","0","3"],["9.643","0","0","0"],["9.645","770","0","4"],["9.646","16","0","1"],["9.648","29","0","2"],["9.649","242","0","2"],["48.625","1","0","1"]],"bids":[["9.604","317","0","2"],["9.603","26","0","1"],["9.602","76","0","1"],["9.601","45","0","2"],["9.599","620","0","2"],["9.598","37","0","2"]],"ts":"1646003679671","checksum":-212307872}]}
1646003679.700585: {"arg":{"channel":"books-l2-tbt","instId":"ELON-USDT"},"action":"update","data":[{"asks":[["0.00000074586","0","0","0"],["0.00000113812","12211658","0","1"]],"bids":[],"ts":"1646003679686","checksum":1267424735}]}
1646003679.718642: {"arg":{"channel":"books-l2-tbt","instId":"ELON-USDT"},"action":"update","data":[{"asks":[["0.00000074583","152061613","0","2"]],"bids":[],"ts":"1646003679706","checksum":-59869910}]}
1646003679.736761: {"arg":{"channel":"books-l2-tbt","instId":"UNI-USD-SWAP"},"action":"update","data":[{"asks":[["9.628","3","0","1"],["9.659","1036","0","3"],["48.625","0","0","0"]],"bids":[],"ts":"1646003679722","checksum":18056124}]}
1646003679.7688189: {"arg":{"channel":"books-l2-tbt","instId":"UNI-USD-SWAP"},"action":"update","data":[{"asks":[["9.623","260","0","1"],["9.626","0","0","0"],["48.625","1","0","1"]],"bids":[],"ts":"1646003679757","checksum":-712424171}]}
1646003679.768914: {"arg":{"channel":"books-l2-tbt","instId":"ELON-USDT"},"action":"update","data":[{"asks":[],"bids":[["0.00000074451","184440410","0","1"]],"ts":"1646003679758","checksum":-1015051876}]}
1646003679.774806: {"arg":{"channel":"books-l2-tbt","instId":"UNI-USD-SWAP"},"action":"update","data":[{"asks":[["9.622","83","0","1"],["48.625","0","0","0"]],"bids":[],"ts":"1646003679762","checksum":-204763676}]}
1646003679.79569: {"arg":{"channel":"books-l2-tbt","instId":"UNI-USD-SWAP"},"action":"update","data":[{"asks":[],"bids":[["9.613","114","0","2"],["9.612","53","0","1"]],"ts":"1646003679784","checksum":1769966532}]}
1646003679.802058: {"arg":{"channel":"books-l2-tbt","instId":"ELON-USDT"},"action":"update","data":[{"asks":[["0.00000074583","159764443","0","2"]],"bids":[],"ts":"1646003679790","checksum":863498092}]}
1646003679.8062432: {"arg":{"channel":"books-l2-tbt","instId":"UNI-USD-SWAP"},"action":"update","data":[{"asks":[["9.621","260","0","1"],["48.383","0","0","0"]],"bids":[["9.615","260","0","1"],["9.608","12","0","1"],["9.606","500","0","1"],["9.604","168","0","1"]],"ts":"1646003679794","checksum":1682928682}]}
1646003679.811499: {"arg":{"channel":"books-l2-tbt","instId":"PROPS-ETH"},"action":"update","data":[{"asks":[["0.00000177","855.67511681","0","1"],["0.00000178","908.64651959","0","1"],["0.00000183","0","0","0"],["0.00000184","0","0","0"],["0.00000185","0","0","0"]],"bids":[["0.00000161","0","0","0"],["0.0000016","9910.54524544","0","1"]],"ts":"1646003679800","checksum":-1430043324}]}
1646003679.828969: {"arg":{"channel":"books-l2-tbt","instId":"UNI-USD-SWAP"},"action":"update","data":[{"asks":[["9.629","108","0","2"],["9.635","85","0","3"]],"bids":[["9.616","0","0","0"],["9.615","282","0","2"],["9.609","5","0","1"]],"ts":"1646003679814","checksum":1586057220}]}
1646003679.8306198: {"arg":{"channel":"books-l2-tbt","instId":"ELON-USDT"},"action":"update","data":[{"asks":[["0.00000074583","281442512","0","4"]],"bids":[],"ts":"1646003679819","checksum":-515864576}]}
1646003679.8414772: {"arg":{"channel":"books-l2-tbt","instId":"UNI-USD-SWAP"},"action":"update","data":[{"asks":[["9.634","510","0","2"],["9.635","27","0","2"],["9.641","204","0","3"],["9.642","49","0","2"]],"bids":[["9.605","0","0","0"]],"ts":"1646003679826","checksum":-1869858149}]}
1646003679.8415759: {"arg":{"channel":"books-l2-tbt","instId":"ELON-USDT"},"action":"update","data":[{"asks":[["0.00000074583","333800209","0","5"]],"bids":[],"ts":"1646003679829","checksum":1610455578}]}
1646003679.84556: {"arg":{"channel":"books-l2-tbt","instId":"UNI-USD-SWAP"},"action":"update","data":[{"asks":[["9.634","600","0","2"]],"bids":[["9.609","0","0","0"],["9.608","18","0","2"],["9.577","289","0","2"],["9.569","4","0","1"]],"ts":"1646003679835","checksum":-1871619247}]}
1646003679.8531961: {"arg":{"channel":"books-l2-tbt","instId":"ZEN-USDT"},"action":"update","data":[{"asks":[],"bids":[["32.41","35.959536","0","1"]],"ts":"1646003679836","checksum":2136413638}]}
1646003679.861536: {"arg":{"channel":"books-l2-tbt","instId":"UNI-USD-SWAP"},"action":"update","data":[{"asks":[],"bids":[["9.609","5","0","1"],["9.608","12","0","1"],["9.603","0","0","0"],["9.602","104","0","2"],["9.601","25","0","1"],["9.6","23","0","1"],["9.598","16","0","1"],["9.597","26","0","1"]],"ts":"1646003679846","checksum":-949705290}]}
1646003679.8685381: {"arg":{"channel":"books-l2-tbt","instId":"UNI-USD-SWAP"},"action":"update","data":[{"asks":[],"bids":[["9.609","0","0","0"],["9.608","18","0","2"]],"ts":"1646003679857","checksum":1978168944}]}
1646003679.8802078: {"arg":{"channel":"books-l2-tbt","instId":"UNI-USD-SWAP"},"action":"update","data":[{"asks":[["9.659","1006","0","2"]],"bids":[],"ts":"1646003679868","checksum":1978168944}]}
1646003679.886187: {"arg":{"channel":"books-l2-tbt","instId":"BTC-USD-220325-40000-C"},"action":"update","data":[{"asks":[["0.051","29","0","1"],["0.0515","305","0","1"]],"bids":[],"ts":"1646003679876","checksum":-561915348}]}
1646003679.8939362: {"arg":{"channel":"books-l2-tbt","instId":"UNI-USD-SWAP"},"action":"update","data":[{"asks":[["9.633","1","0","1"],["9.634","500","0","1"],["9.64","167","0","2"],["9.641","188","0","2"],["48.143","0","0","0"]],"bids":[],"ts":"1646003679877","checksum":-152739964}]}
1646003679.902687: {"arg":{"channel":"books-l2-tbt","instId":"UNI-USD-SWAP"},"action":"update","data":[{"asks":[],"bids":[["9.614","0","0","0"]],"ts":"1646003679888","checksum":-1731327320}]}
1646003679.908465: {"arg":{"channel":"books-l2-tbt","instId":"BTC-USD-220325-40000-C"},"action":"update","data":[{"asks":[],"bids":[["0.05","0","0","0"],["0.0495","601","0","2"]],"ts":"1646003679897","checksum":1599394008}]}
1646003679.909036: {"arg":{"channel":"books-l2-tbt","instId":"UNI-USD-SWAP"},"action":"update","data":[{"asks":[["9.622","0","0","0"],["48.143","1","0","1"]],"bids":[["9.609","3","0","1"]],"ts":"1646003679899","checksum":1345537121}]}
1646003679.9241128: {"arg":{"channel":"books-l2-tbt","instId":"ELON-USDT"},"action":"update","data":[{"asks":[],"bids":[["0.00000066124","0","0","0"]],"ts":"1646003679911","checksum":1610455578}]}
1646003679.935474: {"arg":{"channel":"books-l2-tbt","instId":"ELON-USDT"},"action":"update","data":[{"asks":[],"bids":[["0.00000070254","0","0","0"],["0.00000068849","0","0","0"],["0.00000067473","0","0","0"],["0.00000064798","225040657","0","1"]],"ts":"1646003679922","checksum":1610455578}]}
1646003679.939244: {"arg":{"channel":"books-l2-tbt","instId":"UNI-USD-SWAP"},"action":"update","data":[{"asks":[["9.623","0","0","0"],["48.383","1","0","1"]],"bids":[],"ts":"1646003679925","checksum":-1430722230}]}
1646003679.9429991: {"arg":{"channel":"books-l2-tbt","instId":"ELON-USDT"},"action":"update","data":[{"asks":[["0.00000074583","389830476","0","5"]],"bids":[["0.00000074435","0","0","0"]],"ts":"1646003679931","checksum":1489145843}]}
1646003679.9430661: {"arg":{"channel":"books-l2-tbt","instId":"UNI-USD-SWAP"},"action":"update","data":[{"asks":[],"bids":[["9.61","0","0","0"]],"ts":"1646003679932","checksum":1728292515}]}
1646003679.965021: {"arg":{"channel":"books-l2-tbt","instId":"ELON-USDT"},"action":"update","data":[{"asks":[["0.00000075299","210944203","0","1"],["0.00000113812","0","0","0"]],"bids":[],"ts":"1646003679952","checksum":787036132}]}
1646003679.9729931: {"arg":{"channel":"books-l2-tbt","instId":"UNI-USD-SWAP"},"action":"update","data":[{"asks":[["9.622","83","0","1"],["48.383","0","0","0"]],"bids":[],"ts":"1646003679960","checksum":1524723523}]}
1646003679.981911: {"arg":{"channel":"books-l2-tbt","instId":"UNI-USD-SWAP"},"action":"update","data":[{"asks":[["9.642","25","0","1"],["9.643","29","0","1"],["9.645","748","0","3"],["9.646","40","0","2"],["9.648","1","0","1"],["9.649","265","0","3"],["48.143","0","0","0"]],"bids":[["9.613","12","0","1"]],"ts":"1646003679971","checksum":-149563961}]}
1646003680.0028858: {"arg":{"channel":"books-l2-tbt","instId":"ZEN-USDT"},"action":"update","data":[{"asks":[],"bids":[["32.49","8","0","1"]],"ts":"1646003679991","checksum":-1536087829}]}
1646003680.006697: {"arg":{"channel":"books-l2-tbt","instId":"UNI-USD-SWAP"},"action":"update","data":[{"asks":[["9.628","100","0","2"],["9.629","11","0","1"],["9.633","5","0","1"]],"bids":[],"ts":"1646003679995","checksum":740866200}]}
1646003680.0080729: {"arg":{"channel":"books-l2-tbt","instId":"PROPS-ETH"},"action":"update","data":[{"asks":[],"bids":[["0.00000166","0","0","0"]],"ts":"1646003679997","checksum":552796264}]}
1646003680.015475: {"arg":{"channel":"books-l2-tbt","instId":"UNI-USD-SWAP"},"action":"update","data":[{"asks":[["9.658","19","0","1"],["47.903","0","0","0"]],"bids":[],"ts":"1646003680003","checksum":740866200}]}
1646003680.025594: {"arg":{"channel":"books-l2-tbt","instId":"ETH-USD-220624-12000-P"},"action":"update","data":[{"asks":[["4.0445","0","0","0"],["4.045","201","0","1"]],"bids":[],"ts":"1646003680013","checksum":-1436588960}]}
1646003680.031704: {"arg":{"channel":"books-l2-tbt","instId":"ELON-USDT"},"action":"update","data":[{"asks":[["0.00000074582","445226872","0","1"],["0.0000011372","0","0","0"]],"bids":[],"ts":"1646003680015","checksum":2060229969}]}
1646003680.03483: {"arg":{"channel":"books-l2-tbt","instId":"UNI-USD-SWAP"},"action":"update","data":[{"asks":[["9.658","0","0","0"],["47.903","1","0","1"]],"bids":[],"ts":"1646003680023","checksum":740866200}]}
1646003680.039129: {"arg":{"channel":"books-l2-tbt","instId":"PROPS-ETH"},"action":"update","data":[{"asks":[],"bids":[["0.00000167","587503.80775829","0","4"]],"ts":"1646003680027","checksum":522537726}]}
1646003680.047798: {"arg":{"channel":"books-l2-tbt","instId":"ELON-USDT"},"action":"update","data":[{"asks":[["0.00000074583","285784536","0","4"]],"bids":[],"ts":"1646003680034","checksum":822607582}]}
1646003680.0560582: {"arg":{"channel":"books-l2-tbt","instId":"UNI-USD-SWAP"},"action":"update","data":[{"asks":[["9.627","3","0","1"],["47.903","0","0","0"]],"bids":[],"ts":"1646003680045","checksum":158807543}]}
1646003680.0675032: {"arg":{"channel":"books-l2-tbt","instId":"ELON-USDT"},"action":"update","data":[{"asks":[["0.00000074581","104045940","0","1"],["0.00000074583","174035766","0","3"],["0.0000011338","0","0","0"]],"bids":[],"ts":"1646003680054","checksum":-2123448275}]}
1646003680.067608: {"arg":{"channel":"books-l2-tbt","instId":"UNI-USD-SWAP"},"action":"update","data":[{"asks":[["9.627","29","0","2"]],"bids":[["9.586","9685","0","3"]],"ts":"1646003680055","checksum":-1994052865}]}
1646003680.077328: {"arg":{"channel":"books-l2-tbt","instId":"ELON-USDT"},"action":"update","data":[{"asks":[],"bids":[["0.0000007445","0","0","0"]],"ts":"1646003680065","checksum":2003616034}]}
1646003680.077406: {"arg":{"channel":"books-l2-tbt","instId":"UNI-USD-SWAP"},"action":"update","data":[{"asks":[["9.622","0","0","0"],["9.628","97","0","1"],["47.903","1","0","1"]],"bids":[["9.603","146","0","1"],["9.598","169","0","2"]],"ts":"1646003680066","checksum":-1187273259}]}
1646003680.086406: {"arg":{"channel":"books-l2-tbt","instId":"ELON-USDT"},"action":"update","data":[{"asks":[["0.00000074581","152061613","0","2"]],"bids":[],"ts":"1646003680074","checksum":1230948595}]}
1646003680.087553: {"arg":{"channel":"books-l2-tbt","instId":"UNI-USD-SWAP"},"action":"update","data":[{"asks":[["9.626","90","0","1"],["47.903","0","0","0"]],"bids":[],"ts":"1646003680076","checksum":-676502945}]}
1646003680.100045: {"arg":{"channel":"books-l2-tbt","instId":"UNI-USD-SWAP"},"action":"update","data":[{"asks":[["9.628","0","0","0"],["9.634","0","0","0"],["47.903","1","0","1"],["48.143","1","0","1"]],"bids":[],"ts":"1646003680087","checksum":-1163394463}]}
1646003680.111774: {"arg":{"channel":"books-l2-tbt","instId":"UNI-USD-SWAP"},"action":"update","data":[{"asks":[["9.631","651","0","2"]],"bids":[],"ts":"1646003680100","checksum":-60586711}]}
1646003680.124508: {"arg":{"channel":"books-l2-tbt","instId":"ELON-USDT"},"action":"update","data":[{"asks":[["0.00000074584","0","0","0"],["0.0000011338","129154981","0","1"]],"bids":[],"ts":"1646003680114","checksum":-615100235}]}
1646003680.130854: {"arg":{"channel":"books-l2-tbt","instId":"UNI-USD-SWAP"},"action":"update","data":[{"asks":[["9.625","1","0","1"],["9.634","143","0","1"],["9.636","271","0","2"],["9.641","45","0","1"],["9.645","623","0","2"],["47.903","0","0","0"],["48.143","0","0","0"]],"bids":[],"ts":"1646003680118","checksum":55317527}]}
1646003680.143772: {"arg":{"channel":"books-l2-tbt","instId":"ZEN-USDT"},"action":"update","data":[{"asks":[["32.54","10.878848","0","3"]],"bids":[["32.47","53.071352","0","2"]],"ts":"1646003680133","checksum":-97427142}]}
1646003680.1642811: {"arg":{"channel":"books-l2-tbt","instId":"UNI-USD-SWAP"},"action":"update","data":[{"asks":[],"bids":[["9.58","35","0","1"]],"ts":"1646003680150","checksum":55317527}]}
1646003680.175051: {"arg":{"channel":"books-l2-tbt","instId":"UNI-USD-SWAP"},"action":"update","data":[{"asks":[["9.622","83","0","1"],["47.665","0","0","0"]],"bids":[["9.578","613","0","3"]],"ts":"1646003680163","checksum":480262097}]}
1646003680.17553: {"arg":{"channel":"books-l2-tbt","instId":"ELON-USDT"},"action":"update","data":[{"asks":[],"bids":[["0.00000074435","120011914","0","1"]],"ts":"1646003680164","checksum":2052245821}]}
1646003680.183179: {"arg":{"channel":"books-l2-tbt","instId":"UNI-USD-SWAP"},"action":"update","data":[{"asks":[["9.627","26","0","1"],["9.641","68","0","2"],["9.643","0","0","0"],["9.644","29","0","1"],["9.646","16","0","1"],["9.647","2577","0","6"],["9.649","242","0","2"]],"bids":[["9.615","260","0","1"],["9.602","76","0","1"],["9.601","47","0","2"],["9.6","0","0","0"],["9.599","644","0","3"],["9.597","0","0","0"],["9.596","25","0","1"]],"ts":"1646003680171","checksum":184697258}]}
1646003680.1838238: {"arg":{"channel":"books-l2-tbt","instId":"ZEN-USDT"},"action":"update","data":[{"asks":[["32.53","1.253596","0","2"],["32.54","10.008848","0","2"]],"bids":[],"ts":"1646003680173","checksum":-1969671655}]}
1646003680.1974049: {"arg":{"channel":"books-l2-tbt","instId":"ELON-USDT"},"action":"update","data":[{"asks":[["0.00000074581","159764443","0","2"]],"bids":[],"ts":"1646003680186","checksum":-901833499}]}
1646003680.2231512: {"arg":{"channel":"books-l2-tbt","instId":"UNI-USD-SWAP"},"action":"update","data":[{"asks":[],"bids":[["9.601","22","0","1"]],"ts":"1646003680210","checksum":-537461626}]}
1646003680.240049: {"arg":{"channel":"books-l2-tbt","instId":"ELON-USDT"},"action":"update","data":[{"asks":[["0.00000074583","0","0","0"],["0.0000011372","6179288","0","1"]],"bids":[],"ts":"1646003680227","checksum":-1788685403}]}
1646003680.244905: {"arg":{"channel":"books-l2-tbt","instId":"UNI-USD-SWAP"},"action":"update","data":[{"asks":[],"bids":[["9.578","574","0","2"]],"ts":"1646003680231","checksum":-537461626}]}
1646003680.252852: {"arg":{"channel":"books-l2-tbt","instId":"ELON-USDT"},"action":"update","data":[{"asks":[],"bids":[["0.00000074451","0","0","0"]],"ts":"1646003680237","checksum":-1093330309}]}
1646003680.257304: {"arg":{"channel":"books-l2-tbt","instId":"ETH-USD-220624-12000-P"},"action":"update","data":[{"asks":[["4.045","0","0","0"],["4.0455","201","0","1"]],"bids":[],"ts":"1646003680247","checksum":-1816163430}]}
1646003680.2719738: {"arg":{"channel":"books-l2-tbt","instId":"ELON-USDT"},"action":"update","data":[{"asks":[],"bids":[["0.00000074263","0","0","0"]],"ts":"1646003680258","checksum":659016278}]}
1646003680.282688: {"arg":{"channel":"books-l2-tbt","instId":"UNI-USD-SWAP"},"action":"update","data":[{"asks":[["9.622","0","0","0"],["47.665","1","0","1"]],"bids":[],"ts":"1646003680271","checksum":1877931989}]}
1646003680.288061: {"arg":{"channel":"books-l2-tbt","instId":"ELON-USDT"},"action":"update","data":[{"asks":[["0.00000074581","111748770","0","1"]],"bids":[["0.00000074239","3335799511","0","1"]],"ts":"1646003680277","checksum":254380220}]}
1646003680.2998981: {"arg":{"channel":"books-l2-tbt","instId":"ELON-USDT"},"action":"update","data":[{"asks":[["0.0000007458","445226872","0","1"],["0.00000074587","0","0","0"]],"bids":[],"ts":"1646003680288","checksum":46244035}]}
1646003680.300019: {"arg":{"channel":"books-l2-tbt","instId":"ETH-USD-220325-8800-P"},"action":"update","data":[{"asks":[["2.549","0","0","0"],["2.5495","201","0","1"]],"bids":[],"ts":"1646003680290","checksum":-181733380}]}
1646003680.302896: {"arg":{"channel":"books-l2-tbt","instId":"PROPS-ETH"},"action":"update","data":[{"asks":[["0.00000178","0","0","0"],["0.00000183","645.94357995","0","1"],["0.00000184","1222.25509197","0","1"],["0.00000185","1043.90488843","0","1"],["0.00000186","523.10322117","0","1"]],"bids":[],"ts":"1646003680291","checksum":472880597}]}
1646003680.317176: {"arg":{"channel":"books-l2-tbt","instId":"UNI-USD-SWAP"},"action":"update","data":[{"asks":[["9.657","15","0","1"],["47.665","0","0","0"]],"bids":[],"ts":"1646003680305","checksum":1877931989}]}
1646003680.32112: {"arg":{"channel":"books-l2-tbt","instId":"ELON-USDT"},"action":"update","data":[{"asks":[["0.00000074581","0","0","0"],["0.00000113812","12211658","0","1"]],"bids":[],"ts":"1646003680307","checksum":-1340070400}]}
1646003680.330935: {"arg":{"channel":"books-l2-tbt","instId":"ELON-USDT"},"action":"update","data":[{"asks":[],"bids":[["0.00000072001","7420856098","0","1"]],"ts":"1646003680319","checksum":-1340070400}]}
1646003680.3341372: {"arg":{"channel":"books-l2-tbt","instId":"UNI-USD-SWAP"},"action":"update","data":[{"asks":[],"bids":[["9.579","0","0","0"]],"ts":"1646003680323","checksum":1877931989}]}
1646003680.341426: {"arg":{"channel":"books-l2-tbt","instId":"ELON-USDT"},"action":"update","data":[{"asks":[["0.00000074579","111748770","0","1"],["0.00000113812","0","0","0"]],"bids":[],"ts":"1646003680328","checksum":-1582384573}]}
1646003680.3480299: {"arg":{"channel":"books-l2-tbt","instId":"UNI-USD-SWAP"},"action":"update","data":[{"asks":[],"bids":[["9.576","1112","0","2"]],"ts":"1646003680334","checksum":1877931989}]}
1646003680.352223: {"arg":{"channel":"books-l2-tbt","instId":"ELON-USDT"},"action":"update","data":[{"asks":[["0.00000074579","215794710","0","2"]],"bids":[],"ts":"1646003680339","checksum":1770513446}]}
1646003680.356342: {"arg":{"channel":"books-l2-tbt","instId":"UNI-USD-SWAP"},"action":"update","data":[{"asks":[],"bids":[["9.603","0","0","0"]],"ts":"1646003680345","checksum":-919328658}]}
1646003680.3569732: {"arg":{"channel":"books-l2-tbt","instId":"ZEN-USDT"},"action":"update","data":[{"asks":[],"bids":[["32.44","96.88977","0","3"]],"ts":"1646003680346","checksum":1728930335}]}
1646003680.363992: {"arg":{"channel":"books-l2-tbt","instId":"ELON-USDT"},"action":"update","data":[{"asks":[["0.00000074582","0","0","0"],["0.00000113812","12211658","0","1"]],"bids":[],"ts":"1646003680349","checksum":249838608}]}
1646003680.371167: {"arg":{"channel":"books-l2-tbt","instId":"ELON-USDT"},"action":"update","data":[{"asks":[["0.00000074583","81175250","0","1"],["0.00000113812","0","0","0"]],"bids":[],"ts":"1646003680360","checksum":-571548766}]}
1646003680.380137: {"arg":{"channel":"books-l2-tbt","instId":"ZEN-USDT"},"action":"update","data":[{"asks":[["32.53","3.336641","0","3"]],"bids":[],"ts":"1646003680366","checksum":1402762468}]}
1646003680.380245: {"arg":{"channel":"books-l2-tbt","instId":"UNI-USD-SWAP"},"action":"update","data":[{"asks":[["9.621","343","0","2"]],"bids":[],"ts":"1646003680367","checksum":-650162290}]}
1646003680.393624: {"arg":{"channel":"books-l2-tbt","instId":"ELON-USDT"},"action":"update","data":[{"asks":[["0.00000074579","104045940","0","1"]],"bids":[],"ts":"1646003680381","checksum":2005577208}]}
1646003680.405375: {"arg":{"channel":"books-l2-tbt","instId":"UNI-USD-SWAP"},"action":"update","data":[{"asks":[],"bids":[["9.612","0","0","0"],["9.611","53","0","1"]],"ts":"1646003680388","checksum":-1204447669}]}
1646003680.405494: {"arg":{"channel":"books-l2-tbt","instId":"ZEN-USDT"},"action":"update","data":[{"asks":[["32.52","8","0","1"],["44.23","0","0","0"]],"bids":[["32.44","150.920494","0","4"]],"ts":"1646003680388","checksum":-1398320442}]}
1646003680.419341: {"arg":{"channel":"books-l2-tbt","instId":"UNI-USD-SWAP"},"action":"update","data":[{"asks":[],"bids":[["9.615","0","0","0"]],"ts":"1646003680407","checksum":1416834604}]}
1646003680.419416: {"arg":{"channel":"books-l2-tbt","instId":"ZEN-USDT"},"action":"update","data":[{"asks":[["32.57","53.629392","0","3"]],"bids":[],"ts":"1646003680408","checksum":1577254310}]}
1646003680.422575: {"arg":{"channel":"books-l2-tbt","instId":"ELON-USDT"},"action":"update","data":[{"asks":[],"bids":[["0.0000006993","271039247","0","1"],["0.00000068532","423263626","0","1"],["0.00000067162","250588698","0","1"],["0.00000065819","232802111","0","1"],["0.00000064798","0","0","0"]],"ts":"1646003680412","checksum":2005577208}]}
1646003680.4448519: {"arg":{"channel":"books-l2-tbt","instId":"UNI-USD-SWAP"},"action":"update","data":[{"asks":[["9.63","0","0","0"],["47.665","1","0","1"]],"bids":[["9.613","143","0","3"],["9.611","155","0","2"],["9.577","328","0","3"]],"ts":"1646003680429","checksum":-406160632}]}
1646003680.444934: {"arg":{"channel":"books-l2-tbt","instId":"ELON-USDT"},"action":"update","data":[{"asks":[["0.00000074579","156403637","0","2"]],"bids":[],"ts":"1646003680431","checksum":-2003673100}]}
1646003680.4532568: {"arg":{"channel":"books-l2-tbt","instId":"ZEN-USDT"},"action":"update","data":[{"asks":[["32.6","159.838408","0","4"]],"bids":[["32.46","3.686635","0","1"]],"ts":"1646003680439","checksum":557913411}]}
1646003680.4533179: {"arg":{"channel":"books-l2-tbt","instId":"UNI-USD-SWAP"},"action":"update","data":[{"asks":[["9.647","2554","0","5"]],"bids":[["9.613","131","0","2"]],"ts":"1646003680439","checksum":1130031138}]}
1646003680.453356: {"arg":{"channel":"books-l2-tbt","instId":"ETH-USD-220624-12000-P"},"action":"update","data":[{"asks":[],"bids":[],"ts":"1646003680440","checksum":-1816163430}]}
1646003680.461246: {"arg":{"channel":"books-l2-tbt","instId":"ZEN-USDT"},"action":"update","data":[{"asks":[],"bids":[["32.49","8.500345","0","2"]],"ts":"1646003680449","checksum":1371663708}]}
1646003680.461355: {"arg":{"channel":"books-l2-tbt","instId":"UNI-USD-SWAP"},"action":"update","data":[{"asks":[["9.62","1","0","1"],["9.641","45","0","1"],["9.642","52","0","2"],["9.644","0","0","0"],["9.645","648","0","3"],["9.648","23","0","2"]],"bids":[["9.614","22","0","1"],["9.613","109","0","1"],["9.611","167","0","3"],["9.609","0","0","0"],["9.605","11","0","1"],["9.577","289","0","2"]],"ts":"1646003680450","checksum":-1641595572}]}
1646003680.466531: {"arg":{"channel":"books-l2-tbt","instId":"ELON-USDT"},"action":"update","data":[{"asks":[["0.00000074578","445226872","0","1"],["0.0000011372","0","0","0"]],"bids":[],"ts":"1646003680452","checksum":-1715163479}]}
1646003680.471933: {"arg":{"channel":"books-l2-tbt","instId":"ZEN-USDT"},"action":"update","data":[{"asks":[["32.52","8.444442","0","2"]],"bids":[],"ts":"1646003680460","checksum":-414714825}]}
1646003680.4750552: {"arg":{"channel":"books-l2-tbt","instId":"UNI-USD-SWAP"},"action":"update","data":[{"asks":[["9.62","0","0","0"],["9.621","260","0","1"],["9.661","0","0","0"],["47.903","1","0","1"],["48.143","1","0","1"]],"bids":[],"ts":"1646003680461","checksum":-775375481}]}
1646003680.483571: {"arg":{"channel":"books-l2-tbt","instId":"UNI-USD-SWAP"},"action":"update","data":[{"asks":[["9.658","42","0","1"],["9.664","510","0","1"],["48.143","0","0","0"]],"bids":[],"ts":"1646003680471","checksum":-775375481}]}
1646003680.483697: {"arg":{"channel":"books-l2-tbt","instId":"ELON-USDT"},"action":"update","data":[{"asks":[["0.00000074577","48015673","0","1"],["0.00000074579","120928043","0","2"],["0.0000011338","0","0","0"]],"bids":[],"ts":"1646003680472","checksum":334352842}]}
1646003680.494333: {"arg":{"channel":"books-l2-tbt","instId":"ELON-USDT"},"action":"update","data":[{"asks":[["0.00000074579","199255828","0","4"]],"bids":[],"ts":"1646003680482","checksum":-1364706903}]}
1646003680.4944398: {"arg":{"channel":"books-l2-tbt","instId":"UNI-USD-SWAP"},"action":"update","data":[{"asks":[],"bids":[["9.612","1","0","1"],["9.599","672","0","4"]],"ts":"1646003680482","checksum":-300162992}]}
1646003680.5049229: {"arg":{"channel":"books-l2-tbt","instId":"ELON-USDT"},"action":"update","data":[{"asks":[["0.00000074577","152061613","0","2"],["0.0000007458","0","0","0"],["0.0000011338","129154981","0","1"]],"bids":[],"ts":"1646003680492","checksum":-1771556520}]}
1646003680.513509: {"arg":{"channel":"books-l2-tbt","instId":"UNI-USD-SWAP"},"action":"update","data":[{"asks":[["9.657","0","0","0"],["9.658","106","0","2"],["48.143","1","0","1"]],"bids":[["9.613","0","0","0"]],"ts":"1646003680502","checksum":2129607233}]}
1646003680.520772: {"arg":{"channel":"books-l2-tbt","instId":"ZEN-USDT"},"action":"update","data":[{"asks":[["32.53","2.953045","0","2"]],"bids":[["32.5","0","0","0"]],"ts":"1646003680509","checksum":-214728215}]}
1646003680.5254312: {"arg":{"channel":"books-l2-tbt","instId":"ELON-USDT"},"action":"update","data":[{"asks":[],"bids":[["0.00000074449","219861835","0","1"]],"ts":"1646003680513","checksum":-950335894}]}
1646003680.533936: {"arg":{"channel":"books-l2-tbt","instId":"UNI-USD-SWAP"},"action":"update","data":[{"asks":[],"bids":[["9.614","0","0","0"],["9.613","22","0","1"],["9.612","110","0","2"]],"ts":"1646003680523","checksum":1888760488}]}
1646003680.558877: {"arg":{"channel":"books-l2-tbt","instId":"ZEN-USDT"},"action":"update","data":[{"asks":[],"bids":[["32.44","150.520784","0","3"]],"ts":"1646003680542","checksum":1608880972}]}
1646003680.55893: {"arg":{"channel":"books-l2-tbt","instId":"UNI-USD-SWAP"},"action":"update","data":[{"asks":[],"bids":[["9.613","24","0","2"]],"ts":"1646003680543","checksum":-906214856}]}
1646003680.571439: {"arg":{"channel":"books-l2-tbt","instId":"ELON-USDT"},"action":"update","data":[{"asks":[],"bids":[["0.00000074435","0","0","0"]],"ts":"1646003680555","checksum":1446943130}]}
1646003680.587588: {"arg":{"channel":"books-l2-tbt","instId":"ZEN-USDT"},"action":"update","data":[{"asks":[],"bids":[["32.45","87.738549","0","3"]],"ts":"1646003680563","checksum":-1863144687}]}
1646003680.587641: {"arg":{"channel":"books-l2-tbt","instId":"UNI-USD-SWAP"},"action":"update","data":[{"asks":[["9.621","343","0","2"]],"bids":[],"ts":"1646003680564","checksum":-127615677}]}
1646003680.587664: {"arg":{"channel":"books-l2-tbt","instId":"ELON-USDT"},"action":"update","data":[{"asks":[["0.00000074576","445226872","0","1"],["0.00000086593","0","0","0"]],"bids":[],"ts":"1646003680564","checksum":767154515}]}
1646003680.587689: {"arg":{"channel":"books-l2-tbt","instId":"UNI-USD-SWAP"},"action":"update","data":[{"asks":[["9.641","73","0","2"],["9.642","25","0","1"],["9.644","25","0","1"],["9.645","623","0","2"],["9.647","2576","0","6"],["9.648","1","0","1"],["9.655","213","0","2"],["48.143","0","0","0"]],"bids":[["9.612","169","0","2"]],"ts":"1646003680575","checksum":1295304503}]}
1646003680.607444: {"arg":{"channel":"books-l2-tbt","instId":"ZEN-USDT"},"action":"update","data":[{"asks":[["33.16","4.24161","0","2"],["33.17","0","0","0"],["33.49","6.33","0","1"],["33.5","0.496261","0","2"],["33.82","16.19715","0","3"],["33.83","0","0","0"],["34.15","11.04","0","1"],["34.16","0","0","0"],["44.23","2.713011","0","1"]],"bids":[["32.21","0","0","0"],["32.17","1.55","0","1"],["31.89","4.713961","0","2"],["31.85","88.056754","0","2"],["31.58","0","0","0"],["31.54","6.61","0","1"],["31.27","2.272752","0","1"],["31.23","9.641052","0","2"],["30.96","0","0","0"],["30.92","11.76","0","1"]],"ts":"1646003680594","checksum":1880669918}]}
1646003680.6204102: {"arg":{"channel":"books-l2-tbt","instId":"ELON-USDT"},"action":"update","data":[{"asks":[["0.00000074578","0","0","0"],["0.0000011372","6179288","0","1"]],"bids":[],"ts":"1646003680608","checksum":-652484450}]}
1646003680.64736: {"arg":{"channel":"books-l2-tbt","instId":"ELON-USDT"},"action":"update","data":[{"asks":[],"bids":[["0.00000072819","145671904","0","2"]],"ts":"1646003680629","checksum":-652484450}]}
1646003680.6603048: {"arg":{"channel":"books-l2-tbt","instId":"ELON-USDT"},"action":"update","data":[{"asks":[],"bids":[["0.0000007445","62132922","0","1"]],"ts":"1646003680648","checksum":1785222303}]}
1646003680.670615: {"arg":{"channel":"books-l2-tbt","instId":"ZEN-USDT"},"action":"update","data":[{"asks":[],"bids":[["32.15","309.781042","0","2"],["32.11","1.55","0","1"],["31.7","0","0","0"],["31.66","4.775516","0","2"],["31.26","0","0","0"],["31.22","7.930163","0","2"],["30.83","0","0","0"],["30.79","11.17","0","1"],["30.4","26.622301","0","2"],["30.36","14.46","0","1"]],"ts":"1646003680657","checksum":-724617062}]}
1646003680.681014: {"arg":{"channel":"books-l2-tbt","instId":"UNI-USD-SWAP"},"action":"update","data":[{"asks":[["9.621","260","0","1"]],"bids":[["9.602","227","0","2"]],"ts":"1646003680669","checksum":-1515097449}]}
1646003680.6915698: {"arg":{"channel":"books-l2-tbt","instId":"UNI-USD-SWAP"},"action":"update","data":[{"asks":[],"bids":[["9.576","1052","0","1"]],"ts":"1646003680680","checksum":-1515097449}]}
1646003680.701859: {"arg":{"channel":"books-l2-tbt","instId":"UNI-USD-SWAP"},"action":"update","data":[{"asks":[["9.632","528","0","4"],["9.633","0","0","0"],["48.143","1","0","1"]],"bids":[["9.601","0","0","0"],["9.6","21","0","1"],["9.599","648","0","3"],["9.598","195","0","3"],["9.596","0","0","0"],["9.595","29","0","1"],["9.573","60","0","1"]],"ts":"1646003680690","checksum":1848035447}]}
1646003680.713519: {"arg":{"channel":"books-l2-tbt","instId":"UNI-USD-SWAP"},"action":"update","data":[{"asks":[["9.621","282","0","2"],["9.632","636","0","5"],["9.637","1354","0","3"],["9.638","30","0","2"],["9.647","2469","0","5"]],"bids":[["9.611","114","0","2"],["9.602","151","0","1"],["9.6","52","0","2"]],"ts":"1646003680701","checksum":-1690808405}]}
1646003680.717712: {"arg":{"channel":"books-l2-tbt","instId":"PROPS-ETH"},"action":"update","data":[{"asks":[],"bids":[["0.00000167","458788.423005","0","3"]],"ts":"1646003680705","checksum":1463659844}]}
1646003680.725188: {"arg":{"channel":"books-l2-tbt","instId":"UNI-USD-SWAP"},"action":"update","data":[{"asks":[["9.631","751","0","3"],["9.632","593","0","4"],["9.638","519","0","4"],["9.645","312","0","1"],["9.649","64","0","1"]],"bids":[["9.61","53","0","1"],["9.608","12","0","1"],["9.607","6","0","1"],["9.574","37","0","1"]],"ts":"1646003680712","checksum":1830683689}]}
1646003680.736164: {"arg":{"channel":"books-l2-tbt","instId":"UNI-USD-SWAP"},"action":"update","data":[{"asks":[["9.638","830","0","5"],["9.641","251","0","3"],["9.645","0","0","0"],["9.655","35","0","1"],["48.383","1","0","1"]],"bids":[["9.612","60","0","1"]],"ts":"1646003680723","checksum":1980404092}]}
1646003680.7443788: {"arg":{"channel":"books-l2-tbt","instId":"UNI-USD-SWAP"},"action":"update","data":[{"asks":[],"bids":[["9.607","0","0","0"],["9.606","6","0","1"],["9.604","668","0","2"],["9.586","146","0","2"]],"ts":"1646003680733","checksum":-1106052258}]}
1646003680.748744: {"arg":{"channel":"books-l2-tbt","instId":"PROPS-ETH"},"action":"update","data":[{"asks":[],"bids":[["0.00000167","587503.80775829","0","4"]],"ts":"1646003680737","checksum":472880597}]}
1646003680.755581: {"arg":{"channel":"books-l2-tbt","instId":"UNI-USD-SWAP"},"action":"update","data":[{"asks":[],"bids":[["9.439","0","0","0"]],"ts":"1646003680743","checksum":-1106052258}]}
1646003680.766468: {"arg":{"channel":"books-l2-tbt","instId":"UNI-USD-SWAP"},"action":"update","data":[{"asks":[["9.637","1515","0","4"],["9.647","2308","0","4"]],"bids":[["9.594","61","0","2"],["9.588","286","0","2"],["9.58","9574","0","2"]],"ts":"1646003680752","checksum":1885043889}]}
1646003680.773171: {"arg":{"channel":"books-l2-tbt","instId":"ETH-USD-220624-12000-P"},"action":"update","data":[{"asks":[["4.0455","0","0","0"],["4.046","201","0","1"]],"bids":[],"ts":"1646003680762","checksum":-302047568}]}
1646003680.773252: {"arg":{"channel":"books-l2-tbt","instId":"UNI-USD-SWAP"},"action":"update","data":[{"asks":[["9.62","83","0","1"],["9.629","91","0","2"],["9.632","534","0","3"],["48.383","0","0","0"]],"bids":[["9.501","0","0","0"],["9.39","0","0","0"]],"ts":"1646003680762","checksum":-108216800}]}
1646003680.778613: {"arg":{"channel":"books-l2-tbt","instId":"PROPS-ETH"},"action":"update","data":[{"asks":[],"bids":[["0.00000167","301429.73230629","0","2"]],"ts":"1646003680768","checksum":1202055549}]}
1646003680.78351: {"arg":{"channel":"books-l2-tbt","instId":"UNI-USD-SWAP"},"action":"update","data":[{"asks":[],"bids":[["9.428","320","0","1"]],"ts":"1646003680772","checksum":-108216800}]}
1646003680.783621: {"arg":{"channel":"books-l2-tbt","instId":"ZEN-USDT"},"action":"update","data":[{"asks":[],"bids":[["32.41","38.911121","0","2"]],"ts":"1646003680772","checksum":-1601365199}]}
1646003680.794625: {"arg":{"channel":"books-l2-tbt","instId":"ZEN-USDT"},"action":"update","data":[{"asks":[["32.57","49.017069","0","2"]],"bids":[],"ts":"1646003680783","checksum":1470514346}]}
1646003680.795202: {"arg":{"channel":"books-l2-tbt","instId":"ELON-USDT"},"action":"update","data":[{"asks":[["0.00000074698","0","0","0"],["0.00000113812","12211658","0","1"]],"bids":[],"ts":"1646003680785","checksum":1381018864}]}
1646003680.813878: {"arg":{"channel":"books-l2-tbt","instId":"PROPS-ETH"},"action":"update","data":[{"asks":[["0.00000177","0","0","0"],["0.00000184","0","0","0"],["0.00000185","0","0","0"],["0.00000186","0","0","0"]],"bids":[["0.00000167","414841.75986329","0","3"],["0.0000016","0","0","0"]],"ts":"1646003680799","checksum":332455918}]}
1646003680.816969: {"arg":{"channel":"books-l2-tbt","instId":"ZEN-USDT"},"action":"update","data":[{"asks":[["32.55","6.899564","0","2"]],"bids":[],"ts":"1646003680803","checksum":1454359843}]}
1646003680.8170428: {"arg":{"channel":"books-l2-tbt","instId":"UNI-USD-SWAP"},"action":"update","data":[{"asks":[["9.619","260","0","1"],["9.623","26","0","1"],["9.647","2288","0","3"],["9.654","35","0","1"],["47.903","0","0","0"],["48.143","0","0","0"]],"bids":[["9.61","0","0","0"],["9.602","0","0","0"],["9.493","240","0","1"],["9.378","320","0","1"]],"ts":"1646003680804","checksum":980170605}]}
1646003680.8188941: {"arg":{"channel":"books-l2-tbt","instId":"ELON-USDT"},"action":"update","data":[{"asks":[["0.0000007477","698000000","0","1"],["0.00000113812","0","0","0"]],"bids":[],"ts":"1646003680806","checksum":2051002760}]}
1646003680.819499: {"arg":{"channel":"books-l2-tbt","instId":"PROPS-ETH"},"action":"update","data":[{"asks":[],"bids":[["0.00000167","587556.10741629","0","4"]],"ts":"1646003680809","checksum":1495354813}]}
1646003680.828584: {"arg":{"channel":"books-l2-tbt","instId":"UNI-USD-SWAP"},"action":"update","data":[{"asks":[],"bids":[["9.613","2","0","1"],["9.612","82","0","2"],["9.611","12","0","1"],["9.609","2","0","1"]],"ts":"1646003680812","checksum":1041672299}]}
1646003680.828688: {"arg":{"channel":"books-l2-tbt","instId":"ZEN-USDT"},"action":"update","data":[{"asks":[],"bids":[["32.27","0","0","0"]],"ts":"1646003680813","checksum":419554331}]}
1646003680.8370402: {"arg":{"channel":"books-l2-tbt","instId":"UNI-USD-SWAP"},"action":"update","data":[{"asks":[],"bids":[["9.612","22","0","1"],["9.61","102","0","1"]],"ts":"1646003680823","checksum":1603878411}]}
1646003680.8456068: {"arg":{"channel":"books-l2-tbt","instId":"UNI-USD-SWAP"},"action":"update","data":[{"asks":[],"bids":[["9.611","121","0","2"]],"ts":"1646003680833","checksum":2065858277}]}
1646003680.853135: {"arg":{"channel":"books-l2-tbt","instId":"UNI-USD-SWAP"},"action":"update","data":[{"asks":[["9.63","5","0","1"],["9.631","651","0","2"],["47.665","0","0","0"]],"bids":[["9.594","45","0","1"]],"ts":"1646003680842","checksum":934252220}]}
1646003680.865073: {"arg":{"channel":"books-l2-tbt","instId":"UNI-USD-SWAP"},"action":"update","data":[{"asks":[["9.639","21","0","1"],["9.641","223","0","2"],["9.642","51","0","2"],["9.644","0","0","0"],["9.645","23","0","1"],["9.647","2266","0","2"],["9.649","9309","0","2"],["47.428","0","0","0"]],"bids":[["9.6","31","0","1"],["9.596","29","0","1"],["9.595","0","0","0"],["9.593","134","0","2"]],"ts":"1646003680853","checksum":-915492408}]}
1646003680.8657532: {"arg":{"channel":"books-l2-tbt","instId":"ELON-USDT"},"action":"update","data":[{"asks":[["0.00000074583","0","0","0"],["0.00000113812","12211658","0","1"]],"bids":[],"ts":"1646003680855","checksum":431219294}]}
1646003680.8757231: {"arg":{"channel":"books-l2-tbt","instId":"UNI-USD-SWAP"},"action":"update","data":[{"asks":[["9.62","0","0","0"],["9.63","0","0","0"],["9.631","751","0","3"],["9.646","0","0","0"],["47.428","1","0","1"],["47.665","1","0","1"],["47.903","1","0","1"]],"bids":[["9.589","337","0","3"]],"ts":"1646003680864","checksum":-1707154177}]}
1646003680.877512: {"arg":{"channel":"books-l2-tbt","instId":"ELON-USDT"},"action":"update","data":[{"asks":[],"bids":[["0.000000733","1380491132","0","3"]],"ts":"1646003680866","checksum":-872977579}]}
1646003680.898627: {"arg":{"channel":"books-l2-tbt","instId":"UNI-USD-SWAP"},"action":"update","data":[{"asks":[["9.641","239","0","3"]],"bids":[["9.613","0","0","0"]],"ts":"1646003680884","checksum":25273397}]}
1646003680.906152: {"arg":{"channel":"books-l2-tbt","instId":"UNI-USD-SWAP"},"action":"update","data":[{"asks":[["9.639","48","0","2"],["9.64","151","0","1"]],"bids":[],"ts":"1646003680895","checksum":800914731}]}
1646003680.9185998: {"arg":{"channel":"books-l2-tbt","instId":"UNI-USD-SWAP"},"action":"update","data":[{"asks":[["9.625","0","0","0"],["9.638","880","0","6"],["9.639","21","0","1"],["48.143","1","0","1"]],"bids":[],"ts":"1646003680906","checksum":1227072403}]}
1646003680.9186828: {"arg":{"channel":"books-l2-tbt","instId":"ELON-USDT"},"action":"update","data":[{"asks":[["0.00000074577","0","0","0"],["0.00000113853","6145556","0","1"]],"bids":[["0.0000006993","0","0","0"]],"ts":"1646003680907","checksum":611315977}]}
1646003680.9294012: {"arg":{"channel":"books-l2-tbt","instId":"UNI-USD-SWAP"},"action":"update","data":[{"asks":[],"bids":[["9.609","55","0","2"],["9.599","338","0","2"],["9.593","444","0","3"]],"ts":"1646003680916","checksum":2026190761}]}
1646003680.92947: {"arg":{"channel":"books-l2-tbt","instId":"ELON-USDT"},"action":"update","data":[{"asks":[],"bids":[["0.00000068532","0","0","0"],["0.00000067162","0","0","0"],["0.00000065819","0","0","0"],["0.00000064475","369465363","0","1"]],"ts":"1646003680918","checksum":611315977}]}
1646003680.938526: {"arg":{"channel":"books-l2-tbt","instId":"UNI-USD-SWAP"},"action":"update","data":[{"asks":[],"bids":[["9.607","3","0","1"]],"ts":"1646003680927","checksum":1368907701}]}
1646003680.9385998: {"arg":{"channel":"books-l2-tbt","instId":"ELON-USDT"},"action":"update","data":[{"asks":[["0.00000074698","4038943392","0","1"],["0.00000113853","0","0","0"]],"bids":[],"ts":"1646003680927","checksum":1232338700}]}
1646003680.942715: {"arg":{"channel":"books-l2-tbt","instId":"ETH-USD-220624-20000-C"},"action":"update","data":[{"asks":[],"bids":[],"ts":"1646003680930","checksum":1483419732}]}
1646003680.9449222: {"arg":{"channel":"books-l2-tbt","instId":"ZEN-USDT"},"action":"update","data":[{"asks":[["32.83","1.52","0","1"],["32.84","0","0","0"]],"bids":[],"ts":"1646003680934","checksum":-1524083798}]}
1646003680.9491699: {"arg":{"channel":"books-l2-tbt","instId":"ELON-USDT"},"action":"update","data":[{"asks":[["0.00000074579","105465420","0","2"]],"bids":[],"ts":"1646003680938","checksum":-264396524}]}
1646003680.949246: {"arg":{"channel":"books-l2-tbt","instId":"UNI-USD-SWAP"},"action":"update","data":[{"asks":[["9.624","79","0","1"],["9.626","0","0","0"]],"bids":[],"ts":"1646003680939","checksum":-1095208050}]}
1646003680.960105: {"arg":{"channel":"books-l2-tbt","instId":"UNI-USD-SWAP"},"action":"update","data":[{"asks":[["9.62","1","0","1"],["48.143","0","0","0"]],"bids":[["9.609","53","0","1"],["9.6","0","0","0"],["9.597","62","0","1"],["9.591","0","0","0"]],"ts":"1646003680948","checksum":1422255335}]}
1646003680.9696069: {"arg":{"channel":"books-l2-tbt","instId":"ELON-USDT"},"action":"update","data":[{"asks":[["0.00000074575","159764443","0","2"],["0.00000113812","0","0","0"]],"bids":[["0.00000074449","0","0","0"]],"ts":"1646003680958","checksum":-859182179}]}
1646003680.9705641: {"arg":{"channel":"books-l2-tbt","instId":"UNI-USD-SWAP"},"action":"update","data":[{"asks":[["9.664","0","0","0"],["48.143","1","0","1"]],"bids":[],"ts":"1646003680959","checksum":1422255335}]}
1646003680.983042: {"arg":{"channel":"books-l2-tbt","instId":"ELON-USDT"},"action":"update","data":[{"asks":[["0.00000074575","263810383","0","3"],["0.00000074576","81175250","0","1"]],"bids":[],"ts":"1646003680968","checksum":-800667725}]}
1646003680.983161: {"arg":{"channel":"books-l2-tbt","instId":"UNI-USD-SWAP"},"action":"update","data":[{"asks":[["9.619","343","0","2"],["9.639","0","0","0"],["9.64","174","0","2"],["9.642","25","0","1"],["9.643","27","0","1"],["9.645","0","0","0"],["9.646","27","0","1"]],"bids":[["9.578","64","0","1"]],"ts":"1646003680968","checksum":1548610517}]}
1646003680.988331: {"arg":{"channel":"books-l2-tbt","instId":"ELON-USDT"},"action":"update","data":[{"asks":[["0.00000074575","215794710","0","2"],["0.00000074578","445226872","0","1"],["0.00000074698","0","0","0"]],"bids":[],"ts":"1646003680977","checksum":823329346}]}
1646003680.989256: {"arg":{"channel":"books-l2-tbt","instId":"UNI-USD-SWAP"},"action":"update","data":[{"asks":[["9.655","0","0","0"],["48.383","1","0","1"]],"bids":[["9.586","162","0","3"]],"ts":"1646003680978","checksum":-927186355}]}
1646003680.998231: {"arg":{"channel":"books-l2-tbt","instId":"ELON-USDT"},"action":"update","data":[{"asks":[["0.00000074575","241014772","0","3"],["0.00000074579","0","0","0"],["0.00000074698","4038943392","0","1"]],"bids":[],"ts":"1646003680987","checksum":-1061735792}]}
1646003681.002066: {"arg":{"channel":"books-l2-tbt","instId":"UNI-USD-SWAP"},"action":"update","data":[{"asks":[["9.657","533","0","2"],["48.383","0","0","0"]],"bids":[["9.571","510","0","1"]],"ts":"1646003680991","checksum":-927186355}]}
1646003681.010933: {"arg":{"channel":"books-l2-tbt","instId":"ELON-USDT"},"action":"update","data":[{"asks":[["0.00000074575","129266002","0","2"],["0.00000074698","0","0","0"],["0.00000113812","12211658","0","1"]],"bids":[],"ts":"1646003680999","checksum":1599527582}]}
1646003681.011064: {"arg":{"channel":"books-l2-tbt","instId":"UNI-USD-SWAP"},"action":"update","data":[{"asks":[],"bids":[["9.599","28","0","1"],["9.593","754","0","4"]],"ts":"1646003681000","checksum":-234555362}]}
1646003681.016947: {"arg":{"channel":"books-l2-tbt","instId":"ZEN-USDT"},"action":"update","data":[{"asks":[],"bids":[["32.45","72.36894","0","2"]],"ts":"1646003681006","checksum":1926645776}]}
1646003681.022263: {"arg":{"channel":"books-l2-tbt","instId":"ELON-USDT"},"action":"update","data":[{"asks":[],"bids":[["0.00000074435","78998318","0","1"]],"ts":"1646003681009","checksum":70871390}]}
1646003681.032376: {"arg":{"channel":"books-l2-tbt","instId":"ELON-USDT"},"action":"update","data":[{"asks":[["0.00000074697","4038943392","0","1"],["0.00000113812","0","0","0"]],"bids":[],"ts":"1646003681020","checksum":634973205}]}
1646003681.0393732: {"arg":{"channel":"books-l2-tbt","instId":"ZEN-USDT"},"action":"update","data":[{"asks":[],"bids":[["32.41","54.291855","0","3"]],"ts":"1646003681027","checksum":716789254}]}
1646003681.039447: {"arg":{"channel":"books-l2-tbt","instId":"ELON-USDT"},"action":"update","data":[{"asks":[["0.00000074574","232552630","0","1"],["0.0000011372","0","0","0"]],"bids":[],"ts":"1646003681028","checksum":-202654499}]}
1646003681.0619898: {"arg":{"channel":"books-l2-tbt","instId":"ELON-USDT"},"action":"update","data":[{"asks":[["0.00000074575","104045940","0","1"],["0.00000074697","0","0","0"],["0.0000011372","6179288","0","1"]],"bids":[],"ts":"1646003681050","checksum":-145052949}]}
1646003681.0634181: {"arg":{"channel":"books-l2-tbt","instId":"UNI-USD-SWAP"},"action":"update","data":[{"asks":[],"bids":[["9.61","162","0","2"],["9.574","0","0","0"]],"ts":"1646003681052","checksum":1155396830}]}
1646003681.072524: {"arg":{"channel":"books-l2-tbt","instId":"ELON-USDT"},"action":"update","data":[{"asks":[],"bids":[["0.0000007445","0","0","0"]],"ts":"1646003681061","checksum":1483403343}]}
1646003681.072575: {"arg":{"channel":"books-l2-tbt","instId":"UNI-USD-SWAP"},"action":"update","data":[{"asks":[["9.63","5","0","1"],["9.631","651","0","2"],["9.637","1531","0","5"],["9.638","830","0","5"],["48.143","0","0","0"]],"bids":[["9.612","0","0","0"],["9.576","1069","0","2"]],"ts":"1646003681062","checksum":-2008490775}]}
1646003681.0830662: {"arg":{"channel":"books-l2-tbt","instId":"UNI-USD-SWAP"},"action":"update","data":[{"asks":[],"bids":[["9.611","143","0","3"]],"ts":"1646003681072","checksum":1835544327}]}
1646003681.0939038: {"arg":{"channel":"books-l2-tbt","instId":"ELON-USDT"},"action":"update","data":[{"asks":[["0.00000074573","48015673","0","1"],["0.00000074578","0","0","0"]],"bids":[["0.00000074239","0","0","0"]],"ts":"1646003681081","checksum":-515933159}]}
1646003681.094045: {"arg":{"channel":"books-l2-tbt","instId":"UNI-USD-SWAP"},"action":"update","data":[{"asks":[["9.63","14","0","1"],["9.639","25","0","1"],["9.64","151","0","1"],["9.642","53","0","2"],["9.643","0","0","0"],["9.645","23","0","1"],["9.646","0","0","0"],["9.657","510","0","1"]],"bids":[["9.6","29","0","1"],["9.596","0","0","0"],["9.595","20","0","1"],["9.593","728","0","3"],["9.576","1052","0","1"]],"ts":"1646003681083","checksum":-2083890391}]}
1646003681.104755: {"arg":{"channel":"books-l2-tbt","instId":"ELON-USDT"},"action":"update","data":[{"asks":[["0.00000074575","0","0","0"],["0.00000113812","12211658","0","1"]],"bids":[],"ts":"1646003681092","checksum":-1595697632}]}
1646003681.114455: {"arg":{"channel":"books-l2-tbt","instId":"ELON-USDT"},"action":"update","data":[{"asks":[["0.00000074698","4038943392","0","1"],["0.00000113812","0","0","0"]],"bids":[],"ts":"1646003681102","checksum":1496912093}]}
1646003681.12449: {"arg":{"channel":"books-l2-tbt","instId":"ELON-USDT"},"action":"update","data":[{"asks":[["0.00000074573","152061613","0","2"]],"bids":[],"ts":"1646003681113","checksum":1927153171}]}
1646003681.1398022: {"arg":{"channel":"books-l2-tbt","instId":"UNI-USD-SWAP"},"action":"update","data":[{"asks":[["9.63","9","0","1"],["9.636","287","0","3"],["9.637","1515","0","4"]],"bids":[],"ts":"1646003681126","checksum":388324177}]}
1646003681.14786: {"arg":{"channel":"books-l2-tbt","instId":"UNI-USD-SWAP"},"action":"update","data":[{"asks":[],"bids":[["9.608","38","0","2"]],"ts":"1646003681136","checksum":-1934239117}]}
1646003681.1586828: {"arg":{"channel":"books-l2-tbt","instId":"UNI-USD-SWAP"},"action":"update","data":[{"asks":[["9.629","92","0","3"],["9.63","0","0","0"],["48.143","1","0","1"]],"bids":[],"ts":"1646003681146","checksum":-480611734}]}
1646003681.165886: {"arg":{"channel":"books-l2-tbt","instId":"ELON-USDT"},"action":"update","data":[{"asks":[["0.00000074572","445226872","0","1"],["0.0000011372","0","0","0"]],"bids":[["0.00000074381","88867892","0","1"]],"ts":"1646003681154","checksum":236907712}]}
1646003681.187335: {"arg":{"channel":"books-l2-tbt","instId":"ZEN-USDT"},"action":"update","data":[{"asks":[],"bids":[["32.41","51.34027","0","2"]],"ts":"1646003681172","checksum":-1305906671}]}
1646003681.1874182: {"arg":{"channel":"books-l2-tbt","instId":"ELON-USDT"},"action":"update","data":[{"asks":[["0.00000074573","0","0","0"],["0.00000074698","0","0","0"],["0.0000011372","6179288","0","1"],["0.00000113812","12211658","0","1"]],"bids":[],"ts":"1646003681175","checksum":1655744914}]}
1646003681.205765: {"arg":{"channel":"books-l2-tbt","instId":"ELON-USDT"},"action":"update","data":[{"asks":[["0.00000074571","159764443","0","2"],["0.00000113812","0","0","0"]],"bids":[],"ts":"1646003681195","checksum":-2146241481}]}
1646003681.210759: {"arg":{"channel":"books-l2-tbt","instId":"UNI-USD-SWAP"},"action":"update","data":[{"asks":[["9.641","194","0","2"],["9.651","0","0","0"],["9.654","0","0","0"],["48.383","1","0","1"],["48.625","1","0","1"]],"bids":[["9.594","0","0","0"],["9.585","414","0","1"],["9.58","9539","0","1"]],"ts":"1646003681199","checksum":-1417555360}]}
1646003681.2170398: {"arg":{"channel":"books-l2-tbt","instId":"ELON-USDT"},"action":"update","data":[{"asks":[["0.00000074574","0","0","0"],["0.00000113812","12211658","0","1"]],"bids":[["0.00000074435","0","0","0"]],"ts":"1646003681205","checksum":833040277}]}
1646003681.218889: {"arg":{"channel":"books-l2-tbt","instId":"UNI-USD-SWAP"},"action":"update","data":[{"asks":[["9.64","0","0","0"],["48.868","1","0","1"]],"bids":[["9.601","153","0","1"]],"ts":"1646003681207","checksum":-2061558505}]}
1646003681.2333739: {"arg":{"channel":"books-l2-tbt","instId":"UNI-USD-SWAP"},"action":"update","data":[{"asks":[],"bids":[["9.588","331","0","3"],["9.579","50","0","1"],["9.575","35","0","1"]],"ts":"1646003681219","checksum":1756126450}]}
1646003681.249323: {"arg":{"channel":"books-l2-tbt","instId":"ELON-USDT"},"action":"update","data":[{"asks":[],"bids":[["0.00000074381","0","0","0"]],"ts":"1646003681236","checksum":-146259125}]}
1646003681.253922: {"arg":{"channel":"books-l2-tbt","instId":"UNI-USD-SWAP"},"action":"update","data":[{"asks":[["9.635","72","0","3"],["9.645","73","0","2"]],"bids":[],"ts":"1646003681239","checksum":1723996882}]}
1646003681.256469: {"arg":{"channel":"books-l2-tbt","instId":"ZEN-USDT"},"action":"update","data":[{"asks":[],"bids":[["32.11","0","0","0"],["32.1","11.367794","0","2"]],"ts":"1646003681242","checksum":728340914}]}
1646003681.260184: {"arg":{"channel":"books-l2-tbt","instId":"UNI-USD-SWAP"},"action":"update","data":[{"asks":[["9.649","9344","0","3"]],"bids":[],"ts":"1646003681249","checksum":-1687591271}]}
1646003681.271905: {"arg":{"channel":"books-l2-tbt","instId":"ELON-USDT"},"action":"update","data":[{"asks":[["0.00000074571","253554851","0","4"]],"bids":[],"ts":"1646003681257","checksum":-983281800}]}
1646003681.277641: {"arg":{"channel":"books-l2-tbt","instId":"ELON-USDT"},"action":"update","data":[{"asks":[["0.00000074571","359020271","0","6"]],"bids":[],"ts":"1646003681267","checksum":186340727}]}
1646003681.291723: {"arg":{"channel":"books-l2-tbt","instId":"ELON-USDT"},"action":"update","data":[{"asks":[["0.00000074571","311004598","0","5"]],"bids":[],"ts":"1646003681277","checksum":-805012137}]}
1646003681.3103511: {"arg":{"channel":"books-l2-tbt","instId":"ELON-USDT"},"action":"update","data":[{"asks":[["0.0000007457","445226872","0","1"],["0.00000113812","0","0","0"]],"bids":[["0.00000074435","184440410","0","1"]],"ts":"1646003681297","checksum":2103123754}]}
1646003681.3139179: {"arg":{"channel":"books-l2-tbt","instId":"PROPS-ETH"},"action":"update","data":[{"asks":[["0.00000178","621.13661388","0","1"],["0.00000185","1344.72464934","0","1"],["0.00000186","1334.4552455","0","1"],["0.00000187","1076.37943014","0","1"]],"bids":[["0.00000161","10614.58534607","0","1"]],"ts":"1646003681301","checksum":-1012283814}]}
1646003681.330851: {"arg":{"channel":"books-l2-tbt","instId":"ELON-USDT"},"action":"update","data":[{"asks":[["0.00000074571","199255828","0","4"]],"bids":[],"ts":"1646003681319","checksum":1782530596}]}
1646003681.347948: {"arg":{"channel":"books-l2-tbt","instId":"ZEN-USDT"},"action":"update","data":[{"asks":[],"bids":[["32.41","35.959536","0","1"]],"ts":"1646003681335","checksum":-354854771}]}
1646003681.34882: {"arg":{"channel":"books-l2-tbt","instId":"ELON-USDT"},"action":"update","data":[{"asks":[["0.00000074569","215794710","0","2"],["0.00000074572","0","0","0"]],"bids":[],"ts":"1646003681338","checksum":-87348616}]}
1646003681.3522: {"arg":{"channel":"books-l2-tbt","instId":"ETH-USD-220325-8800-P"},"action":"update","data":[{"asks":[["2.5495","0","0","0"],["2.55","201","0","1"]],"bids":[],"ts":"1646003681341","checksum":1894157574}]}
1646003681.357436: {"arg":{"channel":"books-l2-tbt","instId":"UNI-USD-SWAP"},"action":"update","data":[{"asks":[],"bids":[["9.576","1071","0","2"]],"ts":"1646003681344","checksum":-1687591271}]}
1646003681.391346: {"arg":{"channel":"books-l2-tbt","instId":"UNI-USD-SWAP"},"action":"update","data":[{"asks":[],"bids":[["9.599","0","0","0"]],"ts":"1646003681375","checksum":183999607}]}
1646003681.3914208: {"arg":{"channel":"books-l2-tbt","instId":"ELON-USDT"},"action":"update","data":[{"asks":[["0.00000086586","47078428","0","1"],["0.0000011372","0","0","0"]],"bids":[],"ts":"1646003681379","checksum":-87348616}]}
1646003681.4112792: {"arg":{"channel":"books-l2-tbt","instId":"ELON-USDT"},"action":"update","data":[{"asks":[["0.00000074569","104045940","0","1"]],"bids":[["0.00000074447","219861835","0","1"]],"ts":"1646003681399","checksum":1454961559}]}
1646003681.418387: {"arg":{"channel":"books-l2-tbt","instId":"UNI-USD-SWAP"},"action":"update","data":[{"asks":[["9.629","91","0","2"],["9.63","9","0","1"],["48.868","0","0","0"]],"bids":[],"ts":"1646003681407","checksum":-781952347}]}
1646003681.418446: {"arg":{"channel":"books-l2-tbt","instId":"ELON-USDT"},"action":"update","data":[{"asks":[],"bids":[["0.00000069607","175890874","0","1"],["0.00000068215","361957140","0","1"],["0.00000066851","242017823","0","1"],["0.00000065514","422851551","0","1"],["0.00000064475","0","0","0"]],"ts":"1646003681408","checksum":1454961559}]}
1646003681.429166: {"arg":{"channel":"books-l2-tbt","instId":"UNI-USD-SWAP"},"action":"update","data":[{"asks":[],"bids":[["9.612","22","0","1"],["9.611","121","0","2"]],"ts":"1646003681417","checksum":-711668395}]}
1646003681.4399948: {"arg":{"channel":"books-l2-tbt","instId":"UNI-USD-SWAP"},"action":"update","data":[{"asks":[["9.62","0","0","0"],["9.63","5","0","1"],["48.868","1","0","1"]],"bids":[],"ts":"1646003681427","checksum":1972520800}]}
1646003681.450508: {"arg":{"channel":"books-l2-tbt","instId":"ELON-USDT"},"action":"update","data":[{"asks":[["0.00000074568","445226872","0","1"],["0.0000011338","0","0","0"]],"bids":[],"ts":"1646003681439","checksum":-969025053}]}
1646003681.460628: {"arg":{"channel":"books-l2-tbt","instId":"UNI-USD-SWAP"},"action":"update","data":[{"asks":[["9.63","6","0","1"]],"bids":[["9.576","1052","0","1"]],"ts":"1646003681448","checksum":1125140603}]}
1646003681.474284: {"arg":{"channel":"books-l2-tbt","instId":"ELON-USDT"},"action":"update","data":[{"asks":[["0.00000074576","0","0","0"],["0.0000011338","129154981","0","1"]],"bids":[],"ts":"1646003681461","checksum":-905831616}]}
1646003681.4822772: {"arg":{"channel":"books-l2-tbt","instId":"ELON-USDT"},"action":"update","data":[{"asks":[["0.00000074569","0","0","0"],["0.0000011372","6179288","0","1"]],"bids":[],"ts":"1646003681470","checksum":-2020320289}]}
1646003681.4942741: {"arg":{"channel":"books-l2-tbt","instId":"ELON-USDT"},"action":"update","data":[{"asks":[],"bids":[["0.00000074448","109643357","0","1"]],"ts":"1646003681482","checksum":349093334}]}
1646003681.504252: {"arg":{"channel":"books-l2-tbt","instId":"ELON-USDT"},"action":"update","data":[{"asks":[["0.00000074567","48015673","0","1"],["0.0000011372","0","0","0"]],"bids":[["0.00000074235","3068956145","0","1"]],"ts":"1646003681492","checksum":1029901419}]}
1646003681.524373: {"arg":{"channel":"books-l2-tbt","instId":"ELON-USDT"},"action":"update","data":[{"asks":[["0.00000074567","152061613","0","2"],["0.0000007457","0","0","0"],["0.00000074571","78327785","0","2"],["0.0000011372","6179288","0","1"]],"bids":[],"ts":"1646003681512","checksum":1725961318}]}
1646003681.5370398: {"arg":{"channel":"books-l2-tbt","instId":"ELON-USDT"},"action":"update","data":[{"asks":[["0.00000074568","0","0","0"],["0.00000113812","12211658","0","1"]],"bids":[["0.00000074435","0","0","0"]],"ts":"1646003681523","checksum":-1911600191}]}
1646003681.544462: {"arg":{"channel":"books-l2-tbt","instId":"ELON-USDT"},"action":"update","data":[{"asks":[["0.00000074567","48015673","0","1"]],"bids":[],"ts":"1646003681533","checksum":-1029938012}]}
1646003681.554454: {"arg":{"channel":"books-l2-tbt","instId":"ELON-USDT"},"action":"update","data":[{"asks":[["0.00000074567","0","0","0"],["0.00000074569","81175250","0","1"]],"bids":[],"ts":"1646003681543","checksum":-1335671884}]}
1646003681.557566: {"arg":{"channel":"books-l2-tbt","instId":"BTC-USD-220325-40000-C"},"action":"update","data":[{"asks":[],"bids":[],"ts":"1646003681546","checksum":1599394008}]}
1646003681.564403: {"arg":{"channel":"books-l2-tbt","instId":"UNI-USD-SWAP"},"action":"update","data":[{"asks":[["9.656","153","0","2"]],"bids":[],"ts":"1646003681553","checksum":1289241224}]}
1646003681.567741: {"arg":{"channel":"books-l2-tbt","instId":"ELON-USDT"},"action":"update","data":[{"asks":[["0.00000074698","4038943392","0","1"],["0.00000113812","0","0","0"]],"bids":[],"ts":"1646003681554","checksum":1538265802}]}
1646003681.578123: {"arg":{"channel":"books-l2-tbt","instId":"ELON-USDT"},"action":"update","data":[{"asks":[["0.00000074599","48015673","0","1"],["0.00000074698","0","0","0"],["0.00000074771","0","0","0"],["0.00000113812","12211658","0","1"]],"bids":[],"ts":"1646003681565","checksum":273454261}]}
1646003681.5858: {"arg":{"channel":"books-l2-tbt","instId":"ELON-USDT"},"action":"update","data":[{"asks":[["0.00000074599","363550769","0","2"]],"bids":[],"ts":"1646003681574","checksum":1753325078}]}
1646003681.5972412: {"arg":{"channel":"books-l2-tbt","instId":"ELON-USDT"},"action":"update","data":[{"asks":[["0.00000074599","475299539","0","3"],["0.00000074736","2935483871","0","1"],["0.00000113812","0","0","0"]],"bids":[],"ts":"1646003681586","checksum":991910785}]}
1646003681.61884: {"arg":{"channel":"books-l2-tbt","instId":"ELON-USDT"},"action":"update","data":[{"asks":[["0.00000074568","445226872","0","1"],["0.0000011372","0","0","0"]],"bids":[],"ts":"1646003681606","checksum":-175908072}]}
1646003681.640084: {"arg":{"channel":"books-l2-tbt","instId":"UNI-USD-SWAP"},"action":"update","data":[{"asks":[],"bids":[["9.574","28","0","1"]],"ts":"1646003681624","checksum":1289241224}]}
1646003681.640147: {"arg":{"channel":"books-l2-tbt","instId":"ELON-USDT"},"action":"update","data":[{"asks":[["0.00000074599","0","0","0"],["0.0000011372","6179288","0","1"]],"bids":[],"ts":"1646003681627","checksum":-2108628207}]}
1646003681.6629179: {"arg":{"channel":"books-l2-tbt","instId":"UNI-USD-SWAP"},"action":"update","data":[{"asks":[["9.619","260","0","1"],["9.623","27","0","2"]],"bids":[],"ts":"1646003681647","checksum":881127495}]}
1646003681.662998: {"arg":{"channel":"books-l2-tbt","instId":"ELON-USDT"},"action":"update","data":[{"asks":[["0.00000074567","159764443","0","2"],["0.0000011372","0","0","0"]],"bids":[],"ts":"1646003681648","checksum":787043407}]}
1646003681.6736598: {"arg":{"channel":"books-l2-tbt","instId":"UNI-USD-SWAP"},"action":"update","data":[{"asks":[["9.618","83","0","1"],["48.868","0","0","0"]],"bids":[["9.606","0","0","0"],["9.603","6","0","1"]],"ts":"1646003681656","checksum":335747339}]}
1646003681.6886559: {"arg":{"channel":"books-l2-tbt","instId":"UNI-USD-SWAP"},"action":"update","data":[{"asks":[["9.629","134","0","3"],["9.63","0","0","0"],["48.868","1","0","1"]],"bids":[["9.612","0","0","0"],["9.611","143","0","3"],["9.6","0","0","0"],["9.598","169","0","2"],["9.595","0","0","0"]],"ts":"1646003681667","checksum":1432001795}]}
1646003681.688769: {"arg":{"channel":"books-l2-tbt","instId":"ZEN-USDT"},"action":"update","data":[{"asks":[["32.59","16.151361","0","1"],["44.23","0","0","0"]],"bids":[],"ts":"1646003681667","checksum":232893030}]}
1646003681.688807: {"arg":{"channel":"books-l2-tbt","instId":"ELON-USDT"},"action":"update","data":[{"asks":[["0.00000074568","0","0","0"],["0.0000011372","6179288","0","1"]],"bids":[],"ts":"1646003681670","checksum":1512788349}]}
1646003681.6949918: {"arg":{"channel":"books-l2-tbt","instId":"UNI-USD-SWAP"},"action":"update","data":[{"asks":[["9.617","260","0","1"],["9.621","22","0","1"],["9.629","191","0","3"],["48.868","0","0","0"]],"bids":[["9.609","0","0","0"],["9.603","0","0","0"],["9.599","28","0","1"],["9.597","88","0","2"],["9.594","22","0","1"]],"ts":"1646003681678","checksum":1815126513}]}
1646003681.702514: {"arg":{"channel":"books-l2-tbt","instId":"UNI-USD-SWAP"},"action":"update","data":[{"asks":[["9.621","0","0","0"],["9.626","11","0","1"],["9.628","100","0","1"],["9.629","91","0","2"],["48.625","0","0","0"]],"bids":[["9.608","91","0","3"]],"ts":"1646003681688","checksum":784010462}]}
1646003681.7110221: {"arg":{"channel":"books-l2-tbt","instId":"UNI-USD-SWAP"},"action":"update","data":[{"asks":[["9.623","26","0","1"],["9.637","1320","0","3"]],"bids":[["9.606","3","0","1"],["9.577","225","0","1"]],"ts":"1646003681700","checksum":2133296135}]}
1646003681.714488: {"arg":{"channel":"books-l2-tbt","instId":"ELON-USDT"},"action":"update","data":[{"asks":[["0.00000074567","0","0","0"],["0.00000113812","12211658","0","1"]],"bids":[],"ts":"1646003681700","checksum":258722978}]}
1646003681.720722: {"arg":{"channel":"books-l2-tbt","instId":"ZEN-USDT"},"action":"update","data":[{"asks":[],"bids":[["32.49","0.500345","0","1"]],"ts":"1646003681708","checksum":-1180476564}]}
1646003681.7208: {"arg":{"channel":"books-l2-tbt","instId":"ELON-USDT"},"action":"update","data":[{"asks":[["0.00000074567","52357697","0","1"],["0.00000074571","25220062","0","1"],["0.00000113812","0","0","0"]],"bids":[],"ts":"1646003681708","checksum":1763055644}]}
1646003681.726418: {"arg":{"channel":"books-l2-tbt","instId":"UNI-USD-SWAP"},"action":"update","data":[{"asks":[["9.622","1","0","1"],["9.638","819","0","4"],["48.383","0","0","0"]],"bids":[["9.607","0","0","0"],["9.604","674","0","3"]],"ts":"1646003681713","checksum":-661468928}]}
1646003681.7334: {"arg":{"channel":"books-l2-tbt","instId":"UNI-USD-SWAP"},"action":"update","data":[{"asks":[["9.734","0","0","0"],["48.383","1","0","1"]],"bids":[["9.578","0","0","0"],["9.572","64","0","1"]],"ts":"1646003681719","checksum":-1887756201}]}
1646003681.7335339: {"arg":{"channel":"books-l2-tbt","instId":"ELON-USDT"},"action":"update","data":[{"asks":[["0.00000074567","120928043","0","2"],["0.00000074571","0","0","0"],["0.00000074736","0","0","0"],["0.00000113812","12211658","0","1"],["0.00000113853","6145556","0","1"]],"bids":[],"ts":"1646003681721","checksum":1464777347}]}
1646003681.740237: {"arg":{"channel":"books-l2-tbt","instId":"UNI-USD-SWAP"},"action":"update","data":[{"asks":[["9.627","212","0","2"]],"bids":[],"ts":"1646003681729","checksum":1919596815}]}
1646003681.7431848: {"arg":{"channel":"books-l2-tbt","instId":"ELON-USDT"},"action":"update","data":[{"asks":[["0.00000074566","207760770","0","1"],["0.00000074568","111748770","0","1"],["0.00000113812","0","0","0"],["0.00000113853","0","0","0"]],"bids":[],"ts":"1646003681730","checksum":-1133906565}]}
1646003681.752416: {"arg":{"channel":"books-l2-tbt","instId":"ELON-USDT"},"action":"update","data":[{"asks":[["0.00000074752","3602687649","0","1"],["0.0000011372","0","0","0"]],"bids":[],"ts":"1646003681740","checksum":796020303}]}
1646003681.761813: {"arg":{"channel":"books-l2-tbt","instId":"UNI-USD-SWAP"},"action":"update","data":[{"asks":[["9.726","240","0","1"],["48.383","0","0","0"]],"bids":[["9.572","128","0","2"]],"ts":"1646003681750","checksum":1919596815}]}
1646003681.7619572: {"arg":{"channel":"books-l2-tbt","instId":"ELON-USDT"},"action":"update","data":[{"asks":[["0.00000074568","0","0","0"],["0.00000074599","104045940","0","1"]],"bids":[],"ts":"1646003681751","checksum":-195448208}]}
1646003681.775281: {"arg":{"channel":"books-l2-tbt","instId":"ELON-USDT"},"action":"update","data":[{"asks":[["0.00000074769","365784772","0","1"],["0.0000011338","0","0","0"]],"bids":[["0.00000072618","243621027","0","4"]],"ts":"1646003681762","checksum":-330881067}]}
1646003681.781847: {"arg":{"channel":"books-l2-tbt","instId":"ZEN-USDT"},"action":"update","data":[{"asks":[["32.52","11.516671","0","4"],["32.53","2.083045","0","1"]],"bids":[["32.47","51","0","1"]],"ts":"1646003681770","checksum":697598837}]}
1646003681.781933: {"arg":{"channel":"books-l2-tbt","instId":"ELON-USDT"},"action":"update","data":[{"asks":[["0.00000074565","111748770","0","1"],["0.00000074599","0","0","0"]],"bids":[],"ts":"1646003681772","checksum":1981959351}]}
1646003681.7824671: {"arg":{"channel":"books-l2-tbt","instId":"UNI-USD-SWAP"},"action":"update","data":[{"asks":[["9.704","0","0","0"],["48.383","1","0","1"]],"bids":[["9.611","131","0","2"]],"ts":"1646003681772","checksum":-84760203}]}
1646003681.793386: {"arg":{"channel":"books-l2-tbt","instId":"UNI-USD-SWAP"},"action":"update","data":[{"asks":[["9.627","364","0","3"]],"bids":[],"ts":"1646003681781","checksum":-1734827653}]}
1646003681.801945: {"arg":{"channel":"books-l2-tbt","instId":"ZEN-USDT"},"action":"update","data":[{"asks":[["32.56","3.65408","0","1"]],"bids":[["32.45","74.309614","0","3"]],"ts":"1646003681790","checksum":160823019}]}
1646003681.807601: {"arg":{"channel":"books-l2-tbt","instId":"PROPS-ETH"},"action":"update","data":[{"asks":[["0.00000176","8606.76947266","0","2"],["0.00000185","0","0","0"],["0.00000186","0","0","0"],["0.00000187","0","0","0"]],"bids":[["0.00000161","0","0","0"],["0.0000016","10274.36303924","0","1"]],"ts":"1646003681795","checksum":-1879966997}]}
1646003681.812916: {"arg":{"channel":"books-l2-tbt","instId":"UNI-USD-SWAP"},"action":"update","data":[{"asks":[["9.637","1341","0","4"],["9.639","0","0","0"],["9.64","23","0","1"],["9.642","25","0","1"],["9.643","29","0","1"],["9.645","50","0","1"],["9.697","160","0","1"],["48.143","0","0","0"],["48.383","0","0","0"]],"bids":[["9.599","0","0","0"],["9.598","194","0","3"],["9.597","62","0","1"],["9.596","29","0","1"],["9.594","0","0","0"],["9.593","757","0","4"]],"ts":"1646003681802","checksum":-1419827092}]}
1646003681.813528: {"arg":{"channel":"books-l2-tbt","instId":"ELON-USDT"},"action":"update","data":[{"asks":[["0.00000074565","215794710","0","2"]],"bids":[],"ts":"1646003681802","checksum":-2010273403}]}
1646003681.825707: {"arg":{"channel":"books-l2-tbt","instId":"ELON-USDT"},"action":"update","data":[{"asks":[["0.00000074769","0","0","0"],["0.0000011338","129154981","0","1"]],"bids":[],"ts":"1646003681814","checksum":-176217495}]}
1646003681.833226: {"arg":{"channel":"books-l2-tbt","instId":"ZEN-USDT"},"action":"update","data":[{"asks":[["32.56","0","0","0"],["44.23","2.713011","0","1"]],"bids":[],"ts":"1646003681821","checksum":-741060315}]}
1646003681.843543: {"arg":{"channel":"books-l2-tbt","instId":"ZEN-USDT"},"action":"update","data":[{"asks":[["32.54","13.662928","0","3"]],"bids":[],"ts":"1646003681831","checksum":-1093713122}]}
1646003681.8532522: {"arg":{"channel":"books-l2-tbt","instId":"UNI-USD-SWAP"},"action":"update","data":[{"asks":[],"bids":[["9.61","102","0","1"]],"ts":"1646003681842","checksum":1653987517}]}
1646003681.857347: {"arg":{"channel":"books-l2-tbt","instId":"ELON-USDT"},"action":"update","data":[{"asks":[],"bids":[["0.00000074447","0","0","0"]],"ts":"1646003681845","checksum":1110793581}]}
1646003681.8756962: {"arg":{"channel":"books-l2-tbt","instId":"UNI-USD-SWAP"},"action":"update","data":[{"asks":[["9.635","122","0","4"],["9.636","271","0","2"]],"bids":[["9.598","178","0","2"],["9.591","16","0","1"],["9.535","0","0","0"]],"ts":"1646003681864","checksum":-1470217739}]}
1646003681.908261: {"arg":{"channel":"books-l2-tbt","instId":"ZEN-USDT"},"action":"update","data":[{"asks":[],"bids":[["32.45","18.089551","0","2"]],"ts":"1646003681885","checksum":1836107781}]}
1646003681.9083169: {"arg":{"channel":"books-l2-tbt","instId":"ELON-USDT"},"action":"update","data":[{"asks":[["0.00000074564","245714854","0","1"],["0.0000011338","0","0","0"]],"bids":[],"ts":"1646003681887","checksum":-2081814445}]}
1646003681.9083478: {"arg":{"channel":"books-l2-tbt","instId":"UNI-USD-SWAP"},"action":"update","data":[{"asks":[],"bids":[["9.528","160","0","1"]],"ts":"1646003681889","checksum":-1470217739}]}
1646003681.9230201: {"arg":{"channel":"books-l2-tbt","instId":"ELON-USDT"},"action":"update","data":[{"asks":[["0.00000074563","48015673","0","1"],["0.00000074565","0","0","0"],["0.00000074566","0","0","0"],["0.0000011338","129154981","0","1"]],"bids":[["0.00000074435","184440410","0","1"]],"ts":"1646003681905","checksum":-1579817596}]}
1646003681.923108: {"arg":{"channel":"books-l2-tbt","instId":"UNI-USD-SWAP"},"action":"update","data":[{"asks":[["9.649","9280","0","2"]],"bids":[],"ts":"1646003681907","checksum":38052055}]}
1646003681.92506: {"arg":{"channel":"books-l2-tbt","instId":"ELON-USDT"},"action":"update","data":[{"asks":[],"bids":[["0.00000069607","0","0","0"],["0.00000068215","0","0","0"],["0.00000066851","0","0","0"],["0.00000065514","0","0","0"],["0.00000064198","386551301","0","1"]],"ts":"1646003681913","checksum":-1579817596}]}
1646003681.9381728: {"arg":{"channel":"books-l2-tbt","instId":"ZEN-USDT"},"action":"update","data":[{"asks":[],"bids":[["32.49","0","0","0"]],"ts":"1646003681923","checksum":-711001459}]}
1646003681.9382489: {"arg":{"channel":"books-l2-tbt","instId":"ELON-USDT"},"action":"update","data":[{"asks":[["0.00000074563","159764443","0","2"]],"bids":[["0.00000074448","0","0","0"]],"ts":"1646003681925","checksum":1675228786}]}
1646003681.9492521: {"arg":{"channel":"books-l2-tbt","instId":"ELON-USDT"},"action":"update","data":[{"asks":[],"bids":[["0.00000074235","0","0","0"]],"ts":"1646003681934","checksum":-1487884469}]}
1646003681.949318: {"arg":{"channel":"books-l2-tbt","instId":"UNI-USD-SWAP"},"action":"update","data":[{"asks":[["9.643","93","0","2"]],"bids":[],"ts":"1646003681938","checksum":1656395433}]}
1646003681.954845: {"arg":{"channel":"books-l2-tbt","instId":"ZEN-USDT"},"action":"update","data":[{"asks":[],"bids":[["32.4","17.338359","0","1"]],"ts":"1646003681943","checksum":19857405}]}
1646003681.955809: {"arg":{"channel":"books-l2-tbt","instId":"ELON-USDT"},"action":"update","data":[{"asks":[["0.00000074565","53107723","0","1"],["0.00000074567","0","0","0"]],"bids":[],"ts":"1646003681945","checksum":-87319170}]}
1646003681.967683: {"arg":{"channel":"books-l2-tbt","instId":"ELON-USDT"},"action":"update","data":[{"asks":[["0.00000074563","263810383","0","3"]],"bids":[],"ts":"1646003681956","checksum":-1087185905}]}
1646003681.996781: {"arg":{"channel":"books-l2-tbt","instId":"ZEN-USDT"},"action":"update","data":[{"asks":[],"bids":[["32.48","18.170174","0","2"]],"ts":"1646003681984","checksum":2053503731}]}
1646003681.996887: {"arg":{"channel":"books-l2-tbt","instId":"ELON-USDT"},"action":"update","data":[{"asks":[["0.00000074562","257397711","0","1"],["0.00000074625","0","0","0"]],"bids":[],"ts":"1646003681985","checksum":-1696702984}]}
1646003682.0094788: {"arg":{"channel":"books-l2-tbt","instId":"ELON-USDT"},"action":"update","data":[{"asks":[],"bids":[["0.0000007273","775918919","0","3"]],"ts":"1646003681997","checksum":-1696702984}]}
1646003682.013555: {"arg":{"channel":"books-l2-tbt","instId":"UNI-USD-SWAP"},"action":"update","data":[{"asks":[["9.637","1320","0","3"],["9.639","24","0","1"],["9.64","0","0","0"],["9.642","49","0","2"],["9.643","64","0","1"],["9.645","70","0","2"]],"bids":[],"ts":"1646003682001","checksum":-381928926}]}
1646003682.017855: {"arg":{"channel":"books-l2-tbt","instId":"ELON-USDT"},"action":"update","data":[{"asks":[["0.00000074563","0","0","0"],["0.00000074564","0","0","0"],["0.00000074641","496654295","0","1"],["0.0000011372","6179288","0","1"]],"bids":[],"ts":"1646003682007","checksum":1385139715}]}
1646003682.029533: {"arg":{"channel":"books-l2-tbt","instId":"ELON-USDT"},"action":"update","data":[{"asks":[["0.00000074569","0","0","0"],["0.00000113812","12211658","0","1"]],"bids":[],"ts":"1646003682018","checksum":2140789049}]}
1646003682.041097: {"arg":{"channel":"books-l2-tbt","instId":"ELON-USDT"},"action":"update","data":[{"asks":[["0.00000074561","152061613","0","2"],["0.00000113812","0","0","0"]],"bids":[],"ts":"1646003682028","checksum":2077043009}]}
1646003682.04407: {"arg":{"channel":"books-l2-tbt","instId":"UNI-USD-SWAP"},"action":"update","data":[{"asks":[],"bids":[["9.608","38","0","2"]],"ts":"1646003682033","checksum":346719246}]}
1646003682.0540621: {"arg":{"channel":"books-l2-tbt","instId":"UNI-USD-SWAP"},"action":"update","data":[{"asks":[],"bids":[["9.609","53","0","1"]],"ts":"1646003682043","checksum":1466798785}]}
1646003682.059795: {"arg":{"channel":"books-l2-tbt","instId":"ELON-USDT"},"action":"update","data":[{"asks":[["0.00000074562","0","0","0"],["0.00000113812","12211658","0","1"]],"bids":[],"ts":"1646003682048","checksum":445418561}]}
1646003682.096282: {"arg":{"channel":"books-l2-tbt","instId":"ELON-USDT"},"action":"update","data":[{"asks":[["0.00000074641","0","0","0"],["0.00000113853","6145556","0","1"]],"bids":[],"ts":"1646003682084","checksum":-951702467}]}
1646003682.1096818: {"arg":{"channel":"books-l2-tbt","instId":"UNI-USD-SWAP"},"action":"update","data":[{"asks":[],"bids":[["9.611","391","0","3"]],"ts":"1646003682095","checksum":-2097436698}]}
1646003682.1162019: {"arg":{"channel":"books-l2-tbt","instId":"ELON-USDT"},"action":"update","data":[{"asks":[["0.00000074561","0","0","0"],["0.00000074564","365696896","0","1"],["0.00000074617","496657628","0","1"],["0.00000113853","0","0","0"]],"bids":[],"ts":"1646003682101","checksum":737910981}]}
1646003682.1195881: {"arg":{"channel":"books-l2-tbt","instId":"ELON-USDT"},"action":"update","data":[{"asks":[["0.0000007456","104045940","0","1"],["0.00000113812","0","0","0"]],"bids":[],"ts":"1646003682106","checksum":-183342626}]}
1646003682.129375: {"arg":{"channel":"books-l2-tbt","instId":"ELON-USDT"},"action":"update","data":[{"asks":[["0.0000007456","181623699","0","3"],["0.00000074752","0","0","0"],["0.00000113812","12211658","0","1"]],"bids":[],"ts":"1646003682116","checksum":-2112029723}]}
1646003682.129507: {"arg":{"channel":"books-l2-tbt","instId":"UNI-USD-SWAP"},"action":"update","data":[{"asks":[["9.618","0","0","0"],["48.143","1","0","1"]],"bids":[["9.612","22","0","1"],["9.611","369","0","2"]],"ts":"1646003682117","checksum":-905421016}]}
1646003682.140218: {"arg":{"channel":"books-l2-tbt","instId":"ELON-USDT"},"action":"update","data":[{"asks":[["0.0000007456","346992282","0","4"],["0.00000074566","81175250","0","1"],["0.00000113812","0","0","0"]],"bids":[],"ts":"1646003682128","checksum":682417644}]}
1646003682.148339: {"arg":{"channel":"books-l2-tbt","instId":"UNI-USD-SWAP"},"action":"update","data":[{"asks":[["9.619","343","0","2"]],"bids":[],"ts":"1646003682129","checksum":1246970244}]}
1646003682.157432: {"arg":{"channel":"books-l2-tbt","instId":"UNI-USD-SWAP"},"action":"update","data":[{"asks":[["9.619","83","0","1"],["9.628","0","0","0"],["9.629","134","0","3"],["48.383","1","0","1"]],"bids":[["9.609","0","0","0"],["9.583","1212","0","2"],["9.576","0","0","0"]],"ts":"1646003682139","checksum":1953414439}]}
1646003682.160933: {"arg":{"channel":"books-l2-tbt","instId":"ELON-USDT"},"action":"update","data":[{"asks":[["0.00000074743","3336269673","0","1"],["0.0000011372","0","0","0"]],"bids":[],"ts":"1646003682148","checksum":-328585585}]}
1646003682.174304: {"arg":{"channel":"books-l2-tbt","instId":"PROPS-ETH"},"action":"update","data":[{"asks":[],"bids":[["0.00000167","458840.722663","0","3"]],"ts":"1646003682161","checksum":991380620}]}
1646003682.200431: {"arg":{"channel":"books-l2-tbt","instId":"ELON-USDT"},"action":"update","data":[{"asks":[["0.0000007456","146148105","0","3"],["0.00000074565","0","0","0"],["0.0000011372","6179288","0","1"]],"bids":[],"ts":"1646003682175","checksum":1262473047}]}
1646003682.200532: {"arg":{"channel":"books-l2-tbt","instId":"ZEN-USDT"},"action":"update","data":[{"asks":[],"bids":[["32.44","206.766795","0","4"]],"ts":"1646003682177","checksum":180581927}]}
1646003682.215192: {"arg":{"channel":"books-l2-tbt","instId":"PROPS-ETH"},"action":"update","data":[{"asks":[],"bids":[["0.00000167","587556.10741629","0","4"]],"ts":"1646003682194","checksum":-1879966997}]}
1646003682.2153249: {"arg":{"channel":"books-l2-tbt","instId":"UNI-USD-SWAP"},"action":"update","data":[{"asks":[],"bids":[["9.604","668","0","2"]],"ts":"1646003682197","checksum":-1955841935}]}
1646003682.2222059: {"arg":{"channel":"books-l2-tbt","instId":"ELON-USDT"},"action":"update","data":[{"asks":[["0.00000074563","111748770","0","1"],["0.0000011372","0","0","0"]],"bids":[],"ts":"1646003682200","checksum":1113337096}]}
1646003682.22229: {"arg":{"channel":"books-l2-tbt","instId":"UNI-USD-SWAP"},"action":"update","data":[{"asks":[],"bids":[["9.592","150","0","3"],["9.591","0","0","0"]],"ts":"1646003682206","checksum":928814173}]}
1646003682.232877: {"arg":{"channel":"books-l2-tbt","instId":"UNI-USD-SWAP"},"action":"update","data":[{"asks":[["9.619","0","0","0"],["48.625","1","0","1"]],"bids":[],"ts":"1646003682217","checksum":-1350568104}]}
1646003682.2374861: {"arg":{"channel":"books-l2-tbt","instId":"BTC-USD-220325-40000-C"},"action":"update","data":[{"asks":[],"bids":[["0.05","300","0","1"],["0.0495","301","0","1"]],"ts":"1646003682227","checksum":-561915348}]}
1646003682.25129: {"arg":{"channel":"books-l2-tbt","instId":"ELON-USDT"},"action":"update","data":[{"asks":[["0.00000075299","0","0","0"],["0.0000011372","6179288","0","1"]],"bids":[["0.00000071092","0","0","0"]],"ts":"1646003682231","checksum":-477672089}]}
1646003682.26992: {"arg":{"channel":"books-l2-tbt","instId":"UNI-USD-SWAP"},"action":"update","data":[{"asks":[],"bids":[["9.61","155","0","2"]],"ts":"1646003682250","checksum":60035620}]}
1646003682.279538: {"arg":{"channel":"books-l2-tbt","instId":"UNI-USD-SWAP"},"action":"update","data":[{"asks":[],"bids":[["9.599","23","0","1"],["9.598","153","0","1"],["9.597","87","0","2"],["9.596","0","0","0"],["9.594","25","0","1"],["9.593","728","0","3"]],"ts":"1646003682260","checksum":1435048263}]}
1646003682.302481: {"arg":{"channel":"books-l2-tbt","instId":"ELON-USDT"},"action":"update","data":[{"asks":[["0.00000074562","411810987","0","1"],["0.0000011372","0","0","0"]],"bids":[["0.00000074447","219861835","0","1"]],"ts":"1646003682284","checksum":849711240}]}
1646003682.302575: {"arg":{"channel":"books-l2-tbt","instId":"PROPS-ETH"},"action":"update","data":[{"asks":[],"bids":[["0.0000016","0","0","0"]],"ts":"1646003682287","checksum":-1182255344}]}
1646003682.317746: {"arg":{"channel":"books-l2-tbt","instId":"PROPS-ETH"},"action":"update","data":[{"asks":[["0.00000176","7518.11950204","0","1"],["0.00000178","0","0","0"],["0.00000185","675.38143167","0","1"],["0.00000186","691.90844665","0","1"]],"bids":[],"ts":"1646003682297","checksum":-435918719}]}
1646003682.3229902: {"arg":{"channel":"books-l2-tbt","instId":"UNI-USD-SWAP"},"action":"update","data":[{"asks":[["9.656","124","0","1"],["9.658","64","0","1"]],"bids":[],"ts":"1646003682302","checksum":-584435316}]}
1646003682.352436: {"arg":{"channel":"books-l2-tbt","instId":"UNI-USD-SWAP"},"action":"update","data":[{"asks":[["9.658","96","0","2"],["9.661","58","0","1"],["48.625","0","0","0"]],"bids":[],"ts":"1646003682312","checksum":-584435316}]}
1646003682.352525: {"arg":{"channel":"books-l2-tbt","instId":"ELON-USDT"},"action":"update","data":[{"asks":[["0.00000074559","53107723","0","1"],["0.0000007456","25220062","0","1"],["0.0000011338","0","0","0"]],"bids":[],"ts":"1646003682313","checksum":-23951767}]}
1646003682.3525708: {"arg":{"channel":"books-l2-tbt","instId":"ZEN-USDT"},"action":"update","data":[{"asks":[["32.6","155.041409","0","3"]],"bids":[],"ts":"1646003682320","checksum":84593304}]}
1646003682.352598: {"arg":{"channel":"books-l2-tbt","instId":"UNI-USD-SWAP"},"action":"update","data":[{"asks":[["9.62","83","0","1"],["9.629","91","0","2"],["9.63","25","0","1"],["48.143","0","0","0"],["48.383","0","0","0"]],"bids":[["9.605","17","0","2"]],"ts":"1646003682322","checksum":-653142435}]}
1646003682.3526442: {"arg":{"channel":"books-l2-tbt","instId":"UNI-USD-SWAP"},"action":"update","data":[{"asks":[["9.658","64","0","1"]],"bids":[],"ts":"1646003682331","checksum":-653142435}]}
1646003682.3526669: {"arg":{"channel":"books-l2-tbt","instId":"ZEN-USDT"},"action":"update","data":[{"asks":[],"bids":[["32.4","0","0","0"]],"ts":"1646003682331","checksum":-398308497}]}
1646003682.352688: {"arg":{"channel":"books-l2-tbt","instId":"ELON-USDT"},"action":"update","data":[{"asks":[["0.00000074559","157153663","0","2"]],"bids":[["0.00000074448","184440410","0","1"]],"ts":"1646003682334","checksum":-86647867}]}
1646003682.367858: {"arg":{"channel":"books-l2-tbt","instId":"UNI-USD-SWAP"},"action":"update","data":[{"asks":[["9.63","5","0","1"]],"bids":[],"ts":"1646003682342","checksum":596493533}]}
1646003682.367979: {"arg":{"channel":"books-l2-tbt","instId":"ELON-USDT"},"action":"update","data":[{"asks":[["0.00000074564","0","0","0"],["0.0000011338","129154981","0","1"]],"bids":[],"ts":"1646003682344","checksum":-1456698677}]}
1646003682.3735402: {"arg":{"channel":"books-l2-tbt","instId":"ZEN-USDT"},"action":"update","data":[{"asks":[["32.6","171.170918","0","4"]],"bids":[],"ts":"1646003682352","checksum":1616848994}]}
1646003682.373644: {"arg":{"channel":"books-l2-tbt","instId":"UNI-USD-SWAP"},"action":"update","data":[{"asks":[["9.661","0","0","0"],["48.143","1","0","1"]],"bids":[],"ts":"1646003682353","checksum":596493533}]}
1646003682.373707: {"arg":{"channel":"books-l2-tbt","instId":"ELON-USDT"},"action":"update","data":[{"asks":[["0.0000007456","0","0","0"],["0.00000074561","48015673","0","1"]],"bids":[],"ts":"1646003682354","checksum":2146608612}]}
1646003682.3799942: {"arg":{"channel":"books-l2-tbt","instId":"BTC-USD-220325-40000-C"},"action":"update","data":[{"asks":[],"bids":[["0.05","601","0","2"],["0.0495","0","0","0"]],"ts":"1646003682363","checksum":-305748066}]}
1646003682.380126: {"arg":{"channel":"books-l2-tbt","instId":"ZEN-USDT"},"action":"update","data":[{"asks":[],"bids":[["32.41","52.048726","0","2"]],"ts":"1646003682362","checksum":1923633298}]}
1646003682.385825: {"arg":{"channel":"books-l2-tbt","instId":"UNI-USD-SWAP"},"action":"update","data":[{"asks":[["9.639","0","0","0"],["9.64","24","0","1"],["9.642","25","0","1"],["9.643","88","0","2"],["9.645","50","0","1"],["9.646","25","0","1"],["48.143","0","0","0"]],"bids":[["9.599","0","0","0"],["9.598","179","0","2"],["9.597","62","0","1"],["9.596","24","0","1"],["9.594","0","0","0"],["9.593","750","0","4"]],"ts":"1646003682363","checksum":-276785367}]}
1646003682.402132: {"arg":{"channel":"books-l2-tbt","instId":"ELON-USDT"},"action":"update","data":[{"asks":[["0.00000074559","53107723","0","1"],["0.00000074561","0","0","0"],["0.0000011372","6179288","0","1"]],"bids":[],"ts":"1646003682378","checksum":328685059}]}
1646003682.4022772: {"arg":{"channel":"books-l2-tbt","instId":"UNI-USD-SWAP"},"action":"update","data":[{"asks":[["9.63","0","0","0"],["9.631","751","0","3"],["48.143","1","0","1"]],"bids":[],"ts":"1646003682383","checksum":1840934813}]}
1646003682.416384: {"arg":{"channel":"books-l2-tbt","instId":"ELON-USDT"},"action":"update","data":[{"asks":[["0.00000074561","104045940","0","1"],["0.00000074707","4038943392","0","1"],["0.0000011338","0","0","0"],["0.0000011372","0","0","0"]],"bids":[],"ts":"1646003682395","checksum":1249650054}]}
1646003682.420886: {"arg":{"channel":"books-l2-tbt","instId":"UNI-USD-SWAP"},"action":"update","data":[{"asks":[],"bids":[["9.61","102","0","1"]],"ts":"1646003682400","checksum":-1696868325}]}
1646003682.4336672: {"arg":{"channel":"books-l2-tbt","instId":"ELON-USDT"},"action":"update","data":[{"asks":[["0.00000074561","152061613","0","2"],["0.00000074563","0","0","0"],["0.0000011338","129154981","0","1"]],"bids":[["0.00000074435","0","0","0"],["0.00000064198","0","0","0"]],"ts":"1646003682406","checksum":1632645759}]}
1646003682.439883: {"arg":{"channel":"books-l2-tbt","instId":"ELON-USDT"},"action":"update","data":[{"asks":[],"bids":[["0.00000070565","471265885","0","2"],["0.00000069154","354395179","0","1"],["0.00000067771","314485495","0","1"],["0.00000066416","244904695","0","1"]],"ts":"1646003682417","checksum":1632645759}]}
1646003682.4447072: {"arg":{"channel":"books-l2-tbt","instId":"UNI-USD-SWAP"},"action":"update","data":[{"asks":[["9.629","11","0","1"],["9.63","5","0","1"],["9.631","731","0","3"],["48.143","0","0","0"]],"bids":[],"ts":"1646003682423","checksum":1826418963}]}
1646003682.456176: {"arg":{"channel":"books-l2-tbt","instId":"ELON-USDT"},"action":"update","data":[{"asks":[["0.00000074558","246055090","0","1"],["0.0000011338","0","0","0"]],"bids":[],"ts":"1646003682438","checksum":-1990276188}]}
1646003682.4563: {"arg":{"channel":"books-l2-tbt","instId":"UNI-USD-SWAP"},"action":"update","data":[{"asks":[["9.63","0","0","0"],["9.631","831","0","4"],["48.143","1","0","1"]],"bids":[],"ts":"1646003682442","checksum":164869483}]}
1646003682.471016: {"arg":{"channel":"books-l2-tbt","instId":"UNI-USD-SWAP"},"action":"update","data":[{"asks":[["9.628","80","0","1"],["9.631","751","0","3"],["48.143","0","0","0"]],"bids":[["9.611","422","0","3"]],"ts":"1646003682453","checksum":385484440}]}
1646003682.480083: {"arg":{"channel":"books-l2-tbt","instId":"ELON-USDT"},"action":"update","data":[{"asks":[["0.00000074561","0","0","0"],["0.00000074707","0","0","0"],["0.0000011338","129154981","0","1"],["0.0000011372","6179288","0","1"]],"bids":[],"ts":"1646003682460","checksum":-1738674749}]}
1646003682.4802198: {"arg":{"channel":"books-l2-tbt","instId":"UNI-USD-SWAP"},"action":"update","data":[{"asks":[["9.63","5","0","1"],["9.631","651","0","2"],["47.903","0","0","0"]],"bids":[],"ts":"1646003682465","checksum":1721683178}]}
1646003682.4894972: {"arg":{"channel":"books-l2-tbt","instId":"ELON-USDT"},"action":"update","data":[{"asks":[["0.00000074562","0","0","0"],["0.00000113812","12211658","0","1"]],"bids":[],"ts":"1646003682471","checksum":-1256585687}]}
1646003682.489582: {"arg":{"channel":"books-l2-tbt","instId":"UNI-USD-SWAP"},"action":"update","data":[{"asks":[["9.63","0","0","0"],["9.631","751","0","3"],["47.903","1","0","1"]],"bids":[],"ts":"1646003682474","checksum":385484440}]}
1646003682.4955468: {"arg":{"channel":"books-l2-tbt","instId":"ELON-USDT"},"action":"update","data":[{"asks":[["0.00000074557","104045940","0","1"],["0.00000074698","4038943392","0","1"],["0.0000011372","0","0","0"],["0.00000113812","0","0","0"]],"bids":[],"ts":"1646003682481","checksum":1082397015}]}
1646003682.5168939: {"arg":{"channel":"books-l2-tbt","instId":"ZEN-USDT"},"action":"update","data":[{"asks":[],"bids":[["32.11","1.55","0","1"],["32.1","9.817794","0","1"]],"ts":"1646003682487","checksum":-1439768172}]}
1646003682.5170088: {"arg":{"channel":"books-l2-tbt","instId":"ELON-USDT"},"action":"update","data":[{"asks":[],"bids":[["0.0000007433","59838310","0","1"]],"ts":"1646003682489","checksum":484464032}]}
1646003682.5170639: {"arg":{"channel":"books-l2-tbt","instId":"PROPS-ETH"},"action":"update","data":[{"asks":[],"bids":[["0.00000167","474144.07985929","0","3"]],"ts":"1646003682499","checksum":-431779050}]}
1646003682.517109: {"arg":{"channel":"books-l2-tbt","instId":"UNI-USD-SWAP"},"action":"update","data":[{"asks":[["9.628","0","0","0"],["9.631","831","0","4"],["48.143","1","0","1"]],"bids":[["9.599","26","0","1"]],"ts":"1646003682499","checksum":1578192878}]}
1646003682.535396: {"arg":{"channel":"books-l2-tbt","instId":"PROPS-ETH"},"action":"update","data":[{"asks":[],"bids":[["0.00000167","301429.73230629","0","2"],["0.00000134","0","0","0"]],"ts":"1646003682504","checksum":412693715}]}
1646003682.5355232: {"arg":{"channel":"books-l2-tbt","instId":"UNI-USD-SWAP"},"action":"update","data":[{"asks":[["9.63","5","0","1"],["9.631","731","0","3"],["48.143","0","0","0"]],"bids":[],"ts":"1646003682507","checksum":347203570}]}
1646003682.5356019: {"arg":{"channel":"books-l2-tbt","instId":"ELON-USDT"},"action":"update","data":[{"asks":[["0.00000074557","172616286","0","2"]],"bids":[["0.00000074244","3336045770","0","1"]],"ts":"1646003682511","checksum":1771380295}]}
1646003682.540307: {"arg":{"channel":"books-l2-tbt","instId":"UNI-USD-SWAP"},"action":"update","data":[{"asks":[["9.639","21","0","1"],["9.64","0","0","0"],["9.642","53","0","2"],["9.643","64","0","1"],["9.645","73","0","2"],["9.646","0","0","0"],["48.143","1","0","1"]],"bids":[["9.6","22","0","1"],["9.596","0","0","0"],["9.595","22","0","1"],["9.593","728","0","3"]],"ts":"1646003682517","checksum":-210129439}]}
1646003682.573173: {"arg":{"channel":"books-l2-tbt","instId":"UNI-USD-SWAP"},"action":"update","data":[{"asks":[["9.63","0","0","0"],["9.631","831","0","4"],["48.383","1","0","1"]],"bids":[],"ts":"1646003682528","checksum":-1964890168}]}
1646003682.57325: {"arg":{"channel":"books-l2-tbt","instId":"ELON-USDT"},"action":"update","data":[{"asks":[["0.00000074557","68570346","0","1"]],"bids":[],"ts":"1646003682530","checksum":-758401370}]}
1646003682.573277: {"arg":{"channel":"books-l2-tbt","instId":"UNI-USD-SWAP"},"action":"update","data":[{"asks":[["9.63","5","0","1"],["9.631","731","0","3"],["48.383","0","0","0"]],"bids":[],"ts":"1646003682537","checksum":-210129439}]}
1646003682.5733051: {"arg":{"channel":"books-l2-tbt","instId":"ZEN-USDT"},"action":"update","data":[{"asks":[],"bids":[["32.41","16.08919","0","1"]],"ts":"1646003682537","checksum":-1422875675}]}
1646003682.573326: {"arg":{"channel":"books-l2-tbt","instId":"ELON-USDT"},"action":"update","data":[{"asks":[],"bids":[["0.00000074448","0","0","0"]],"ts":"1646003682540","checksum":1300215273}]}
1646003682.573345: {"arg":{"channel":"books-l2-tbt","instId":"ZEN-USDT"},"action":"update","data":[{"asks":[["32.6","155.041409","0","3"]],"bids":[],"ts":"1646003682548","checksum":-1965368888}]}
1646003682.578026: {"arg":{"channel":"books-l2-tbt","instId":"ELON-USDT"},"action":"update","data":[{"asks":[["0.00000074556","445226872","0","1"],["0.00000074557","120928043","0","2"],["0.00000074559","0","0","0"]],"bids":[["0.00000074244","0","0","0"]],"ts":"1646003682561","checksum":-916637597}]}
1646003682.5852952: {"arg":{"channel":"books-l2-tbt","instId":"BTC-USD-220325-40000-C"},"action":"update","data":[{"asks":[["0.051","0","0","0"],["0.0515","334","0","2"]],"bids":[],"ts":"1646003682569","checksum":1507392794}]}
1646003682.58539: {"arg":{"channel":"books-l2-tbt","instId":"ELON-USDT"},"action":"update","data":[{"asks":[["0.000000748","4743514454","0","3"],["0.000000749","391052436","0","1"],["0.0000011338","0","0","0"]],"bids":[["0.0000007433","0","0","0"]],"ts":"1646003682571","checksum":-1337508069}]}
1646003682.5982232: {"arg":{"channel":"books-l2-tbt","instId":"PROPS-ETH"},"action":"update","data":[{"asks":[],"bids":[["0.00000167","587529.51572729","0","4"]],"ts":"1646003682576","checksum":-206249977}]}
1646003682.598289: {"arg":{"channel":"books-l2-tbt","instId":"ZEN-USDT"},"action":"update","data":[{"asks":[["32.6","171.170918","0","4"]],"bids":[],"ts":"1646003682580","checksum":-1422875675}]}
1646003682.598321: {"arg":{"channel":"books-l2-tbt","instId":"ELON-USDT"},"action":"update","data":[{"asks":[["0.00000074555","111748770","0","1"],["0.00000113315","0","0","0"]],"bids":[["0.00000074239","3469534170","0","1"]],"ts":"1646003682582","checksum":-1080640435}]}
1646003682.606612: {"arg":{"channel":"books-l2-tbt","instId":"ELON-USDT"},"action":"update","data":[{"asks":[["0.00000074558","0","0","0"],["0.00000113315","35900750","0","1"]],"bids":[],"ts":"1646003682591","checksum":1511254400}]}
1646003682.616382: {"arg":{"channel":"books-l2-tbt","instId":"PROPS-ETH"},"action":"update","data":[{"asks":[],"bids":[["0.00000135","113385.435868","0","1"]],"ts":"1646003682597","checksum":-1941912539}]}
1646003682.627816: {"arg":{"channel":"books-l2-tbt","instId":"UNI-USD-SWAP"},"action":"update","data":[{"asks":[["9.628","80","0","1"],["9.631","651","0","2"],["9.636","125","0","1"],["48.143","0","0","0"]],"bids":[],"ts":"1646003682602","checksum":-616473069}]}
1646003682.627952: {"arg":{"channel":"books-l2-tbt","instId":"UNI-USD-SWAP"},"action":"update","data":[{"asks":[["9.657","536","0","2"]],"bids":[],"ts":"1646003682607","checksum":-616473069}]}
1646003682.628001: {"arg":{"channel":"books-l2-tbt","instId":"UNI-USD-SWAP"},"action":"update","data":[{"asks":[["9.63","0","0","0"],["9.631","751","0","3"],["9.659","1068","0","3"],["48.143","1","0","1"]],"bids":[],"ts":"1646003682611","checksum":-1232577822}]}
1646003682.6304991: {"arg":{"channel":"books-l2-tbt","instId":"ELON-USDT"},"action":"update","data":[{"asks":[["0.00000074566","0","0","0"],["0.00000074698","0","0","0"],["0.0000011338","129154981","0","1"],["0.0000011372","6179288","0","1"]],"bids":[],"ts":"1646003682615","checksum":958764019}]}
1646003682.636914: {"arg":{"channel":"books-l2-tbt","instId":"ELON-USDT"},"action":"update","data":[{"asks":[["0.00000074697","4038943392","0","1"],["0.0000011372","0","0","0"]],"bids":[["0.00000072001","0","0","0"]],"ts":"1646003682621","checksum":380322672}]}
1646003682.644814: {"arg":{"channel":"books-l2-tbt","instId":"ZEN-USDT"},"action":"update","data":[{"asks":[],"bids":[["32.41","0","0","0"]],"ts":"1646003682628","checksum":198110497}]}
1646003682.644921: {"arg":{"channel":"books-l2-tbt","instId":"UNI-USD-SWAP"},"action":"update","data":[{"asks":[["9.628","0","0","0"],["9.631","820","0","4"],["48.383","1","0","1"]],"bids":[],"ts":"1646003682629","checksum":-953779040}]}
1646003682.664864: {"arg":{"channel":"books-l2-tbt","instId":"UNI-USD-SWAP"},"action":"update","data":[{"asks":[["9.63","5","0","1"],["9.631","720","0","3"],["48.383","0","0","0"]],"bids":[["9.6","0","0","0"],["9.599","47","0","2"],["9.598","153","0","1"],["9.597","90","0","2"],["9.595","0","0","0"],["9.594","21","0","1"]],"ts":"1646003682650","checksum":-1073901666}]}
1646003682.676511: {"arg":{"channel":"books-l2-tbt","instId":"ZEN-USDT"},"action":"update","data":[{"asks":[],"bids":[["32.39","35.976133","0","1"]],"ts":"1646003682659","checksum":-342749613}]}
1646003682.676618: {"arg":{"channel":"books-l2-tbt","instId":"ELON-USDT"},"action":"update","data":[{"asks":[],"bids":[["0.0000007433","112040998","0","1"]],"ts":"1646003682659","checksum":678739376}]}
1646003682.6766741: {"arg":{"channel":"books-l2-tbt","instId":"UNI-USD-SWAP"},"action":"update","data":[{"asks":[["9.623","27","0","2"]],"bids":[],"ts":"1646003682661","checksum":930873454}]}
1646003682.684343: {"arg":{"channel":"books-l2-tbt","instId":"UNI-USD-SWAP"},"action":"update","data":[{"asks":[["9.63","0","0","0"],["9.631","820","0","4"],["48.383","1","0","1"]],"bids":[],"ts":"1646003682672","checksum":1986431456}]}
1646003682.695324: {"arg":{"channel":"books-l2-tbt","instId":"ELON-USDT"},"action":"update","data":[{"asks":[["0.00000074555","159764443","0","2"],["0.00000074557","202103293","0","3"]],"bids":[],"ts":"1646003682681","checksum":-408465520}]}
1646003682.708336: {"arg":{"channel":"books-l2-tbt","instId":"UNI-USD-SWAP"},"action":"update","data":[{"asks":[["9.622","0","0","0"],["48.625","1","0","1"]],"bids":[],"ts":"1646003682693","checksum":-249777925}]}
1646003682.7197618: {"arg":{"channel":"books-l2-tbt","instId":"ELON-USDT"},"action":"update","data":[{"asks":[["0.00000074554","433766141","0","1"],["0.0000011338","0","0","0"]],"bids":[["0.0000007433","0","0","0"]],"ts":"1646003682701","checksum":49411468}]}
