wss://ws.okx.com:8443/ws/v5/public <-> 1646003666.6408682
wss://ws.okx.com:8443/ws/v5/public <- 1646003667.399285: {"op":"subscribe","args":[{"channel":"trades","instId":"ETH-USD-220624-20000-C"},{"channel":"trades","instId":"PROPS-ETH"},{"channel":"trades","instId":"ZEN-USDT"},{"channel":"trades","instId":"ETH-USD-220624-12000-P"},{"channel":"trades","instId":"UNI-USD-SWAP"},{"channel":"trades","instId":"BTC-USD-220325-40000-C"},{"channel":"trades","instId":"ETH-USD-220429-1900-P"},{"channel":"trades","instId":"ELON-USDT"},{"channel":"trades","instId":"ETH-USD-220325-8800-P"},{"channel":"trades","instId":"ETH-USD-220228-3000-C"}]}
wss://ws.okx.com:8443/ws/v5/public <- 1646003667.399457: {"op":"subscribe","args":[{"channel":"trades","instId":"ETH-USD-220624-20000-C"},{"channel":"trades","instId":"PROPS-ETH"},{"channel":"trades","instId":"ZEN-USDT"},{"channel":"trades","instId":"ETH-USD-220624-12000-P"},{"channel":"trades","instId":"UNI-USD-SWAP"},{"channel":"trades","instId":"BTC-USD-220325-40000-C"},{"channel":"trades","instId":"ETH-USD-220429-1900-P"},{"channel":"trades","instId":"ELON-USDT"},{"channel":"trades","instId":"ETH-USD-220325-8800-P"},{"channel":"trades","instId":"ETH-USD-220228-3000-C"},{"channel":"books-l2-tbt","instId":"ETH-USD-220624-20000-C"},{"channel":"books-l2-tbt","instId":"PROPS-ETH"},{"channel":"books-l2-tbt","instId":"ZEN-USDT"},{"channel":"books-l2-tbt","instId":"ETH-USD-220624-12000-P"},{"channel":"books-l2-tbt","instId":"UNI-USD-SWAP"},{"channel":"books-l2-tbt","instId":"BTC-USD-220325-40000-C"},{"channel":"books-l2-tbt","instId":"ETH-USD-220429-1900-P"},{"channel":"books-l2-tbt","instId":"ELON-USDT"},{"channel":"books-l2-tbt","instId":"ETH-USD-220325-8800-P"},{"channel":"books-l2-tbt","instId":"ETH-USD-220228-3000-C"}]}
wss://ws.okx.com:8443/ws/v5/public <- 1646003667.39956: {"op":"subscribe","args":[{"channel":"trades","instId":"ETH-USD-220624-20000-C"},{"channel":"trades","instId":"PROPS-ETH"},{"channel":"trades","instId":"ZEN-USDT"},{"channel":"trades","instId":"ETH-USD-220624-12000-P"},{"channel":"trades","instId":"UNI-USD-SWAP"},{"channel":"trades","instId":"BTC-USD-220325-40000-C"},{"channel":"trades","instId":"ETH-USD-220429-1900-P"},{"channel":"trades","instId":"ELON-USDT"},{"channel":"trades","instId":"ETH-USD-220325-8800-P"},{"channel":"trades","instId":"ETH-USD-220228-3000-C"},{"channel":"books-l2-tbt","instId":"ETH-USD-220624-20000-C"},{"channel":"books-l2-tbt","instId":"PROPS-ETH"},{"channel":"books-l2-tbt","instId":"ZEN-USDT"},{"channel":"books-l2-tbt","instId":"ETH-USD-220624-12000-P"},{"channel":"books-l2-tbt","instId":"UNI-USD-SWAP"},{"channel":"books-l2-tbt","instId":"BTC-USD-220325-40000-C"},{"channel":"books-l2-tbt","instId":"ETH-USD-220429-1900-P"},{"channel":"books-l2-tbt","instId":"ELON-USDT"},{"channel":"books-l2-tbt","instId":"ETH-USD-220325-8800-P"},{"channel":"books-l2-tbt","instId":"ETH-USD-220228-3000-C"},{"channel":"tickers","instId":"ETH-USD-220624-20000-C"},{"channel":"tickers","instId":"PROPS-ETH"},{"channel":"tickers","instId":"ZEN-USDT"},{"channel":"tickers","instId":"ETH-USD-220624-12000-P"},{"channel":"tickers","instId":"UNI-USD-SWAP"},{"channel":"tickers","instId":"BTC-USD-220325-40000-C"},{"channel":"tickers","instId":"ETH-USD-220429-1900-P"},{"channel":"tickers","instId":"ELON-USDT"},{"channel":"tickers","instId":"ETH-USD-220325-8800-P"},{"channel":"tickers","instId":"ETH-USD-220228-3000-C"}]}
1646003667.645451: {"event":"subscribe","arg":{"channel":"trades","instId":"ETH-USD-220624-20000-C"}}
1646003667.64548: {"event":"subscribe","arg":{"channel":"trades","instId":"PROPS-ETH"}}
1646003667.645491: {"event":"subscribe","arg":{"channel":"trades","instId":"ZEN-USDT"}}
1646003667.645499: {"event":"subscribe","arg":{"channel":"trades","instId":"ETH-USD-220624-12000-P"}}
1646003667.6455061: {"event":"subscribe","arg":{"channel":"trades","instId":"UNI-USD-SWAP"}}
1646003667.645513: {"event":"subscribe","arg":{"channel":"trades","instId":"BTC-USD-220325-40000-C"}}
1646003667.64552: {"event":"subscribe","arg":{"channel":"trades","instId":"ETH-USD-220429-1900-P"}}
1646003667.6455271: {"event":"subscribe","arg":{"channel":"trades","instId":"ELON-USDT"}}
1646003667.6455328: {"event":"subscribe","arg":{"channel":"trades","instId":"ETH-USD-220325-8800-P"}}
1646003667.64554: {"event":"subscribe","arg":{"channel":"trades","instId":"ETH-USD-220228-3000-C"}}
1646003667.645546: {"arg":{"channel":"trades","instId":"PROPS-ETH"},"data":[{"instId":"PROPS-ETH","tradeId":"47220","px":"0.00000166","sz":"637.04056847","side":"sell","ts":"1645999995692"}]}
1646003667.645623: {"arg":{"channel":"trades","instId":"ZEN-USDT"},"data":[{"instId":"ZEN-USDT","tradeId":"15270483","px":"32.51","sz":"0.37568","side":"buy","ts":"1646003666197"}]}
1646003667.6456451: {"arg":{"channel":"trades","instId":"UNI-USD-SWAP"},"data":[{"instId":"UNI-USD-SWAP","tradeId":"12118545","px":"9.615","sz":"1","side":"buy","ts":"1646003655550"}]}
1646003667.645662: {"arg":{"channel":"trades","instId":"ELON-USDT"},"data":[{"instId":"ELON-USDT","tradeId":"4253237","px":"0.00000074408","sz":"20728470","side":"sell","ts":"1646003665730"}]}
1646003667.645678: {"arg":{"channel":"trades","instId":"BTC-USD-220325-40000-C"},"data":[{"instId":"BTC-USD-220325-40000-C","tradeId":"19","px":"0.049","sz":"100","side":"sell","ts":"1646003314421"}]}
1646003667.645694: {"arg":{"channel":"trades","instId":"ETH-USD-220228-3000-C"},"data":[{"instId":"ETH-USD-220228-3000-C","tradeId":"1","px":"0.001","sz":"1","side":"buy","ts":"1645976874120"}]}
1646003667.645708: {"event":"subscribe","arg":{"channel":"trades","instId":"ETH-USD-220624-20000-C"}}
1646003667.645716: {"event":"subscribe","arg":{"channel":"trades","instId":"PROPS-ETH"}}
1646003667.6457222: {"event":"subscribe","arg":{"channel":"trades","instId":"ZEN-USDT"}}
1646003667.645729: {"event":"subscribe","arg":{"channel":"trades","instId":"ETH-USD-220624-12000-P"}}
1646003667.645735: {"event":"subscribe","arg":{"channel":"trades","instId":"UNI-USD-SWAP"}}
1646003667.6457422: {"event":"subscribe","arg":{"channel":"trades","instId":"BTC-USD-220325-40000-C"}}
1646003667.645748: {"event":"subscribe","arg":{"channel":"trades","instId":"ETH-USD-220429-1900-P"}}
1646003667.6457548: {"event":"subscribe","arg":{"channel":"trades","instId":"ELON-USDT"}}
1646003667.645761: {"event":"subscribe","arg":{"channel":"trades","instId":"ETH-USD-220325-8800-P"}}
1646003667.645768: {"event":"subscribe","arg":{"channel":"trades","instId":"ETH-USD-220228-3000-C"}}
1646003667.6457741: {"event":"subscribe","arg":{"channel":"books-l2-tbt","instId":"ETH-USD-220624-20000-C"}}
1646003667.64578: {"event":"subscribe","arg":{"channel":"books-l2-tbt","instId":"PROPS-ETH"}}
1646003667.645786: {"event":"subscribe","arg":{"channel":"books-l2-tbt","instId":"ZEN-USDT"}}
1646003667.645793: {"event":"subscribe","arg":{"channel":"books-l2-tbt","instId":"ETH-USD-220624-12000-P"}}
1646003667.645799: {"event":"subscribe","arg":{"channel":"books-l2-tbt","instId":"UNI-USD-SWAP"}}
1646003667.645806: {"event":"subscribe","arg":{"channel":"books-l2-tbt","instId":"BTC-USD-220325-40000-C"}}
1646003667.645812: {"event":"subscribe","arg":{"channel":"books-l2-tbt","instId":"ETH-USD-220429-1900-P"}}
1646003667.645818: {"event":"subscribe","arg":{"channel":"books-l2-tbt","instId":"ELON-USDT"}}
1646003667.645825: {"event":"subscribe","arg":{"channel":"books-l2-tbt","instId":"ETH-USD-220325-8800-P"}}
1646003667.6458309: {"event":"subscribe","arg":{"channel":"books-l2-tbt","instId":"ETH-USD-220228-3000-C"}}
1646003667.645838: {"event":"subscribe","arg":{"channel":"trades","instId":"ETH-USD-220624-20000-C"}}
1646003667.645844: {"event":"subscribe","arg":{"channel":"trades","instId":"PROPS-ETH"}}
1646003667.6458502: {"event":"subscribe","arg":{"channel":"trades","instId":"ZEN-USDT"}}
1646003667.645857: {"event":"subscribe","arg":{"channel":"trades","instId":"ETH-USD-220624-12000-P"}}
1646003667.6458628: {"event":"subscribe","arg":{"channel":"trades","instId":"UNI-USD-SWAP"}}
1646003667.64587: {"event":"subscribe","arg":{"channel":"trades","instId":"BTC-USD-220325-40000-C"}}
1646003667.645876: {"event":"subscribe","arg":{"channel":"trades","instId":"ETH-USD-220429-1900-P"}}
1646003667.6458821: {"event":"subscribe","arg":{"channel":"trades","instId":"ELON-USDT"}}
1646003667.645889: {"event":"subscribe","arg":{"channel":"trades","instId":"ETH-USD-220325-8800-P"}}
1646003667.645895: {"event":"subscribe","arg":{"channel":"trades","instId":"ETH-USD-220228-3000-C"}}
1646003667.645901: {"event":"subscribe","arg":{"channel":"books-l2-tbt","instId":"ETH-USD-220624-20000-C"}}
1646003667.6459131: {"event":"subscribe","arg":{"channel":"books-l2-tbt","instId":"PROPS-ETH"}}
1646003667.64592: {"event":"subscribe","arg":{"channel":"books-l2-tbt","instId":"ZEN-USDT"}}
1646003667.645931: {"event":"subscribe","arg":{"channel":"books-l2-tbt","instId":"ETH-USD-220624-12000-P"}}
1646003667.645937: {"event":"subscribe","arg":{"channel":"books-l2-tbt","instId":"UNI-USD-SWAP"}}
1646003667.645943: {"event":"subscribe","arg":{"channel":"books-l2-tbt","instId":"BTC-USD-220325-40000-C"}}
1646003667.6459498: {"event":"subscribe","arg":{"channel":"books-l2-tbt","instId":"ETH-USD-220429-1900-P"}}
1646003667.645956: {"event":"subscribe","arg":{"channel":"books-l2-tbt","instId":"ELON-USDT"}}
1646003667.645962: {"event":"subscribe","arg":{"channel":"books-l2-tbt","instId":"ETH-USD-220325-8800-P"}}
1646003667.645969: {"event":"subscribe","arg":{"channel":"books-l2-tbt","instId":"ETH-USD-220228-3000-C"}}
1646003667.645975: {"event":"subscribe","arg":{"channel":"tickers","instId":"ETH-USD-220624-20000-C"}}
1646003667.6459808: {"event":"subscribe","arg":{"channel":"tickers","instId":"PROPS-ETH"}}
1646003667.645988: {"event":"subscribe","arg":{"channel":"tickers","instId":"ZEN-USDT"}}
1646003667.645994: {"event":"subscribe","arg":{"channel":"tickers","instId":"ETH-USD-220624-12000-P"}}
1646003667.6460001: {"event":"subscribe","arg":{"channel":"tickers","instId":"UNI-USD-SWAP"}}
1646003667.646008: {"event":"subscribe","arg":{"channel":"tickers","instId":"BTC-USD-220325-40000-C"}}
1646003667.646015: {"event":"subscribe","arg":{"channel":"tickers","instId":"ETH-USD-220429-1900-P"}}
1646003667.6460211: {"event":"subscribe","arg":{"channel":"tickers","instId":"ELON-USDT"}}
1646003667.646027: {"event":"subscribe","arg":{"channel":"tickers","instId":"ETH-USD-220325-8800-P"}}
1646003667.646034: {"event":"subscribe","arg":{"channel":"tickers","instId":"ETH-USD-220228-3000-C"}}
1646003667.64604: {"arg":{"channel":"tickers","instId":"ETH-USD-220624-20000-C"},"data":[{"instType":"OPTION","instId":"ETH-USD-220624-20000-C","last":"0.0025","lastSz":"0","askPx":"0.002","askSz":"20","bidPx":"","bidSz":"","open24h":"0.0025","high24h":"0.0025","low24h":"0.0025","sodUtc0":"0.0025","sodUtc8":"0.0025","volCcy24h":"0","vol24h":"0","ts":"1646003643199"}]}
1646003667.646071: {"arg":{"channel":"tickers","instId":"ETH-USD-220624-12000-P"},"data":[{"instType":"OPTION","instId":"ETH-USD-220624-12000-P","last":"1.942","lastSz":"0","askPx":"4.0485","askSz":"201","bidPx":"2.595","bidSz":"201","open24h":"1.942","high24h":"1.942","low24h":"1.942","sodUtc0":"1.942","sodUtc8":"1.942","volCcy24h":"0","vol24h":"0","ts":"1646003643120"}]}
1646003667.646091: {"arg":{"channel":"tickers","instId":"UNI-USD-SWAP"},"data":[{"instType":"SWAP","instId":"UNI-USD-SWAP","last":"9.615","lastSz":"1","askPx":"9.615","askSz":"1","bidPx":"9.608","bidSz":"102","open24h":"9.022","high24h":"10.152","low24h":"8.65","sodUtc0":"9.067","sodUtc8":"10.078","volCcy24h":"1774356.3988","vol24h":"1699918","ts":"1646003655607"}]}
1646003667.64611: {"arg":{"channel":"tickers","instId":"PROPS-ETH"},"data":[{"instType":"SPOT","instId":"PROPS-ETH","last":"0.00000166","lastSz":"637.04056847","askPx":"0.00000173","askSz":"9903.77916715","bidPx":"0.00000167","bidSz":"461194.49154692","open24h":"0.00000161","high24h":"0.00000166","low24h":"0.00000161","sodUtc0":"0.00000163","sodUtc8":"0.00000166","volCcy24h":"0.63424376","vol24h":"386510.86660785","ts":"1646003643373"}]}
1646003667.6461282: {"arg":{"channel":"tickers","instId":"ZEN-USDT"},"data":[{"instType":"SPOT","instId":"ZEN-USDT","last":"32.51","lastSz":"0.37568","askPx":"32.52","askSz":"0.377508","bidPx":"32.49","bidSz":"8.500345","open24h":"33.34","high24h":"35.26","low24h":"31.91","sodUtc0":"33.36","sodUtc8":"34.26","volCcy24h":"1483600.161828","vol24h":"44364.55024","ts":"1646003666301"}]}
1646003667.646145: {"arg":{"channel":"tickers","instId":"ELON-USDT"},"data":[{"instType":"SPOT","instId":"ELON-USDT","last":"0.00000074408","lastSz":"20728470","askPx":"0.00000074548","askSz":"151964523","bidPx":"0.00000074352","bidSz":"219861835","open24h":"0.0000007958","high24h":"0.0000008141","low24h":"0.00000073774","sodUtc0":"0.00000079427","sodUtc8":"0.00000080449","volCcy24h":"1215404","vol24h":"1550985975715","ts":"1646003665850"}]}
1646003667.646163: {"arg":{"channel":"tickers","instId":"BTC-USD-220325-40000-C"},"data":[{"instType":"OPTION","instId":"BTC-USD-220325-40000-C","last":"0.049","lastSz":"100","askPx":"0.051","askSz":"29","bidPx":"0.0495","bidSz":"601","open24h":"0.0585","high24h":"0.0585","low24h":"0.049","sodUtc0":"0.049","sodUtc8":"0.049","volCcy24h":"10","vol24h":"100","ts":"1646003643198"}]}
1646003667.646183: {"arg":{"channel":"tickers","instId":"ETH-USD-220325-8800-P"},"data":[{"instType":"OPTION","instId":"ETH-USD-220325-8800-P","last":"1.175","lastSz":"0","askPx":"2.5525","askSz":"201","bidPx":"2.201","bidSz":"201","open24h":"1.175","high24h":"1.175","low24h":"1.175","sodUtc0":"1.175","sodUtc8":"1.175","volCcy24h":"0","vol24h":"0","ts":"1646003643121"}]}
1646003667.6462002: {"arg":{"channel":"tickers","instId":"ETH-USD-220228-3000-C"},"data":[{"instType":"OPTION","instId":"ETH-USD-220228-3000-C","last":"0.001","lastSz":"1","askPx":"0.001","askSz":"1031","bidPx":"","bidSz":"","open24h":"0.001","high24h":"0.001","low24h":"0.001","sodUtc0":"0.001","sodUtc8":"0.001","volCcy24h":"1","vol24h":"1","ts":"1646003643149"}]}
1646003667.8790731: {"arg":{"channel":"books-l2-tbt","instId":"PROPS-ETH"},"action":"snapshot","data":[{"asks":[["0.00000174","9765.48230143","0","1"],["0.00000175","14462.27733919","0","1"],["0.00000176","7518.11950204","0","1"],["0.00000178","1117.00899234","0","1"],["0.00000179","500.86421578","0","1"],["0.00000181","519.45957107","0","1"],["0.00000187","679.16255221","0","1"],["0.00000209","3665.030841","0","1"],["0.00000218","3498.98595145","0","1"],["0.0000046","10014.03636363","0","1"],["0.00000461","20364.13099305","0","1"],["0.00000474","152333.11849612","0","2"],["0.00000475","166210.6967","0","1"],["0.00000618","17864.80721422","0","1"],["0.00000771","16196.28959847","0","1"],["0.00000942","17.10929474","0","1"],["0.00007","12403.14","0","1"]],"bids":[["0.00000167","458105.370372","0","3"],["0.00000166","4277.10816641","0","1"],["0.00000165","12763.52282702","0","2"],["0.00000161","9942.93944496","0","1"],["0.00000001","19","0","1"]],"ts":"1646003667575","checksum":-59769065}]}
1646003667.879285: {"arg":{"channel":"books-l2-tbt","instId":"ETH-USD-220624-20000-C"},"action":"snapshot","data":[{"asks":[["0.0025","20","0","1"],["0.003","1506","0","3"]],"bids":[],"ts":"1646003667339","checksum":1483419732}]}
1646003667.879332: {"arg":{"channel":"books-l2-tbt","instId":"ETH-USD-220429-1900-P"},"action":"snapshot","data":[{"asks":[["0.038","1506","0","3"]],"bids":[["0.034","1001","0","2"],["0.0325","505","0","1"]],"ts":"1646003666975","checksum":-1328280565}]}
1646003667.87937: {"arg":{"channel":"books-l2-tbt","instId":"BTC-USD-220325-40000-C"},"action":"snapshot","data":[{"asks":[["0.0515","29","0","1"],["0.052","606","0","2"],["0.0535","300","0","1"],["0.054","100","0","1"]],"bids":[["0.05","601","0","2"],["0.0485","305","0","1"],["0.038","100","0","1"]],"ts":"1646003666818","checksum":-1006770939}]}
1646003667.879421: {"arg":{"channel":"books-l2-tbt","instId":"PROPS-ETH"},"action":"snapshot","data":[{"asks":[["0.00000174","9765.48230143","0","1"],["0.00000175","14462.27733919","0","1"],["0.00000176","7518.11950204","0","1"],["0.00000178","1117.00899234","0","1"],["0.00000179","500.86421578","0","1"],["0.00000181","519.45957107","0","1"],["0.00000187","679.16255221","0","1"],["0.00000209","3665.030841","0","1"],["0.00000218","3498.98595145","0","1"],["0.0000046","10014.03636363","0","1"],["0.00000461","20364.13099305","0","1"],["0.00000474","152333.11849612","0","2"],["0.00000475","166210.6967","0","1"],["0.00000618","17864.80721422","0","1"],["0.00000771","16196.28959847","0","1"],["0.00000942","17.10929474","0","1"],["0.00007","12403.14","0","1"]],"bids":[["0.00000167","458105.370372","0","3"],["0.00000166","4277.10816641","0","1"],["0.00000165","12763.52282702","0","2"],["0.00000161","9942.93944496","0","1"],["0.00000001","19","0","1"]],"ts":"1646003667575","checksum":-59769065}]}
1646003667.879531: {"arg":{"channel":"books-l2-tbt","instId":"ETH-USD-220429-1900-P"},"action":"snapshot","data":[{"asks":[["0.038","1506","0","3"]],"bids":[["0.034","1001","0","2"],["0.0325","505","0","1"]],"ts":"1646003666975","checksum":-1328280565}]}
1646003667.879572: {"arg":{"channel":"books-l2-tbt","instId":"ETH-USD-220624-20000-C"},"action":"snapshot","data":[{"asks":[["0.0025","20","0","1"],["0.003","1506","0","3"]],"bids":[],"ts":"1646003667339","checksum":1483419732}]}
1646003667.879603: {"arg":{"channel":"books-l2-tbt","instId":"BTC-USD-220325-40000-C"},"action":"snapshot","data":[{"asks":[["0.0515","29","0","1"],["0.052","606","0","2"],["0.0535","300","0","1"],["0.054","100","0","1"]],"bids":[["0.05","601","0","2"],["0.0485","305","0","1"],["0.038","100","0","1"]],"ts":"1646003666818","checksum":-1006770939}]}
1646003667.879647: {"arg":{"channel":"books-l2-tbt","instId":"ZEN-USDT"},"action":"snapshot","data":[{"asks":[["32.52","0.310999","0","1"],["32.53","8","0","1"],["32.55","10.240982","0","3"],["32.56","9.234604","0","1"],["32.58","46.019517","0","2"],["32.59","94.820017","0","1"],["32.6","51","0","1"],["32.62","35.965067","0","1"],["32.64","95","0","1"],["32.65","13.847704","0","1"],["32.7","100","0","1"],["32.71","361.583151","0","1"],["32.72","5.192426","0","1"],["32.76","60","0","1"],["32.79","5.409261","0","1"],["32.8","2.338605","0","1"],["32.81","1.94","0","1"],["32.82","99.585582","0","2"],["32.84","1.52","0","1"],["32.88","2.713011","0","1"],["32.9","1.51","0","1"],["32.92","2.25","0","1"],["32.99","1.606449","0","2"],["33","8.036261","0","3"],["33.01","2.338605","0","1"],["33.04","0.120899","0","1"],["33.05","2.742725","0","2"],["33.06","0.010156","0","1"],["33.1","13.914221","0","2"],["33.16","4.24161","0","2"],["33.21","9.029165","0","2"],["33.22","5.051616","0","2"],["33.24","7.54","0","1"],["33.25","8.12863","0","1"],["33.31","7.54","0","1"],["33.33","0.055482","0","1"],["33.36","4.52","0","1"],["33.41","7.58","0","2"],["33.42","26.584008","0","1"],["33.43","2.338605","0","1"],["33.44","0.402789","0","1"],["33.48","0.120899","0","1"],["33.49","6.33","0","1"],["33.5","0.496261","0","2"],["33.51","2.271956","0","1"],["33.56","2.713011","0","1"],["33.6","1.518132","0","2"],["33.65","2.809374","0","2"],["33.66","0.055482","0","1"],["33.67","0.010156","0","1"],["33.82","16.19715","0","3"],["33.86","2.338605","0","1"],["33.91","2.713011","0","1"],["33.93","0.120899","0","1"],["33.95","26.584008","0","1"],["33.98","2.271956","0","1"],["33.99","0.055482","0","1"],["34","1.985426","0","3"],["34.08","2.338605","0","1"],["34.15","11.04","0","1"],["34.18","0.04","0","1"],["34.2","0.402789","0","1"],["34.26","3.18378","0","2"],["34.28","0.010156","0","1"],["34.29","10.4","0","1"],["34.3","2.338605","0","1"],["34.33","0.055482","0","1"],["34.38","0.120899","0","1"],["34.4","1.489354","0","2"],["34.46","2.271956","0","1"],["34.49","26.584008","0","1"],["34.5","0.496261","0","2"],["34.52","2.338605","0","1"],["34.61","2.713011","0","1"],["34.66","0.055482","0","1"],["34.68","0.908544","0","1"],["34.74","2.338605","0","1"],["34.77","13.28","0","1"],["34.81","1.489165","0","1"],["34.84","0.120899","0","1"],["34.86","0.470769","0","1"],["34.89","0.010156","0","1"],["34.9","0.01715","0","1"],["34.94","2.311956","0","2"],["34.95","0.402789","0","1"],["34.96","5.051616","0","2"],["34.98","506","0","1"],["34.99","10.055482","0","2"],["35","0.559244","0","3"],["35.04","26.584008","0","1"],["35.18","102.762877","0","1"],["35.19","2.338605","0","1"],["35.2","0.028967","0","1"],["35.22","1.489165","0","1"],["35.28","110.538566","0","2"],["35.3","1.120899","0","2"],["35.32","2.713011","0","1"],["35.33","0.055482","0","1"],["35.41","2.338605","0","1"],["35.42","2.271956","0","1"],["35.46","0.13818","0","1"],["35.47","0.470769","0","1"],["35.5","0.496261","0","2"],["35.51","0.010156","0","1"],["35.58","3.914741","0","1"],["35.6","26.584008","0","1"],["35.63","1.489968","0","1"],["35.64","2.338605","0","1"],["35.66","0.055482","0","1"],["35.68","1.5","0","1"],["35.69","2.713011","0","1"],["35.71","0.442789","0","2"],["35.77","0.120899","0","1"],["35.8","188.726026","0","5"],["35.83","2","0","1"],["35.87","2.338605","0","1"],["35.88","91.180905","0","2"],["35.9","143.713329","0","2"],["35.92","2.410136","0","2"],["35.99","0.055482","0","1"],["36","417.41764","0","14"],["36.02","0.01715","0","1"],["36.05","4.202979","0","2"],["36.07","0.471052","0","1"],["36.1","102.338605","0","2"],["36.12","0.010156","0","1"],["36.16","26.584008","0","1"],["36.2","100","0","1"],["36.25","0.120899","0","1"],["36.28","1","0","1"],["36.3","101","0","2"],["36.32","16.315846","0","1"],["36.33","2.394087","0","2"],["36.4","100.13818","0","2"],["36.42","4.984967","0","2"],["36.45","0.284083","0","2"],["36.47","1.932757","0","3"],["36.5","100.496261","0","3"],["36.56","2.338605","0","1"],["36.6","113.4925","0","3"],["36.66","0.055482","0","1"],["36.68","0.471052","0","1"],["36.7","100","0","1"],["36.73","0.131055","0","2"],["36.74","26.584008","0","1"],["36.78","3","0","1"],["36.8","107.421692","0","6"],["36.88","0.13818","0","1"],["36.9","101.489968","0","2"],["36.93","2.271956","0","1"],["36.99","1.460712","0","2"],["37","111.341454","0","5"],["37.03","2.338605","0","1"],["37.1","100","0","1"],["37.17","89.942068","0","3"],["37.2","100","0","1"],["37.22","0.523688","0","2"],["37.24","0.04","0","1"],["37.27","2.338605","0","1"],["37.28","2.471052","0","2"],["37.3","101","0","2"],["37.32","26.584008","0","1"],["37.33","0.055482","0","1"],["37.34","1.500124","0","2"],["37.37","0.13818","0","1"],["37.38","1.404835","0","1"],["37.4","1553.58441","0","2"],["37.44","2.271956","0","1"],["37.5","100.496261","0","3"],["37.51","2.338605","0","1"],["37.56","24.716538","0","2"],["37.6","101","0","2"],["37.66","0.055482","0","1"],["37.7","100","0","1"],["37.71","0.120899","0","1"],["37.75","2.338605","0","1"],["37.78","1.489968","0","1"],["37.8","101","0","2"],["37.86","0.13818","0","1"],["37.88","24.458763","0","1"],["37.89","0.471052","0","1"],["37.9","100","0","1"],["37.92","26.584008","0","1"],["37.94","2.713011","0","1"],["37.95","0.010156","0","1"],["37.97","2.271956","0","1"],["37.98","0.402789","0","1"],["37.99","2.394087","0","2"],["38","459.968777","0","7"],["38.01","0.04","0","1"],["38.06","19.048877","0","1"],["38.08","0.146689","0","1"],["38.2","6.2","0","2"],["38.22","1.610867","0","2"],["38.23","2.338605","0","1"],["38.28","1","0","1"],["38.3","1","0","1"],["38.33","2.768493","0","2"],["38.36","0.15533","0","2"],["38.41","0.139269","0","1"],["38.48","2.338605","0","1"],["38.49","0.471052","0","1"],["38.5","2.768217","0","3"],["38.52","26.584008","0","1"],["38.57","15.104852","0","2"],["38.6","1","0","1"],["38.66","11.328482","0","2"],["38.67","1.489968","0","1"],["38.7","28.073033","0","1"],["38.71","0.142488","0","1"],["38.72","5.172515","0","3"],["38.73","0.402789","0","1"],["38.77","0.04","0","1"],["38.8","1","0","1"],["38.86","0.13818","0","1"],["38.87","0.146697","0","1"],["38.88","4","0","1"],["38.96","0.559299","0","1"],["38.97","0.819338","0","2"],["38.99","0.055482","0","1"],["39","28.122723","0","5"],["39.04","2.271956","0","1"],["39.1","0.471052","0","1"],["39.11","0.083143","0","1"],["39.12","2.713011","0","1"],["39.13","28.073976","0","2"],["39.18","0.010156","0","1"],["39.22","4.664772","0","2"],["39.24","0.120899","0","1"],["39.3","1","0","1"],["39.33","0.055482","0","1"],["39.38","0.13818","0","1"],["39.44","1.850553","0","1"],["39.47","2.338605","0","1"],["39.48","5","0","1"],["39.49","0.402789","0","1"],["39.5","0.496237","0","2"],["39.52","2.713011","0","1"],["39.54","0.04","0","1"],["39.55","30","0","1"],["39.58","2.271956","0","1"],["39.59","1.507118","0","2"],["39.6","1","0","1"],["39.66","0.055482","0","1"],["39.68","1.471488","0","1"],["39.69","0.1467","0","1"],["39.71","0.471052","0","1"],["39.73","2.338605","0","1"],["39.76","26.704907","0","2"],["39.77","0.420533","0","1"],["39.79","0.010156","0","1"],["39.8","1","0","1"],["39.88","1.171287","0","1"],["39.9","0.138263","0","1"],["39.93","2.713011","0","1"],["39.95","9.104971","0","1"],["39.98","2.338891","0","1"],["39.99","0.055482","0","1"],["40","217.12312","0","7"],["40.05","2.5","0","1"],["40.06","1.489968","0","1"],["40.11","2","0","1"],["40.13","2.271956","0","1"],["40.24","2.338891","0","1"],["40.25","0.402789","0","1"],["40.28","0.173992","0","1"],["40.29","0.120899","0","1"],["40.3","1.04","0","2"],["40.31","0.471052","0","1"],["40.33","1.377372","0","2"],["40.34","2.713011","0","1"],["40.39","26.584008","0","1"],["40.4","0.010156","0","1"],["40.42","0.138263","0","1"],["40.49","0.1467","0","1"],["40.5","3.834528","0","4"],["40.53","2.805336","0","2"],["40.55","0.173992","0","1"],["40.6","1","0","1"],["40.61","0.420543","0","1"],["40.66","0.055482","0","1"],["40.69","2.271956","0","1"],["40.75","5.051902","0","2"],["40.8","1","0","1"],["40.82","0.173992","0","1"],["40.83","0.120899","0","1"],["40.86","0.01715","0","1"],["40.88","2.169152","0","1"],["40.9","6","0","1"],["40.92","0.471052","0","1"],["40.96","0.138263","0","1"],["40.98","0.768768","0","1"],["40.99","0.055482","0","1"],["41","12.440245","0","6"],["41.02","2.349047","0","2"],["41.03","26.584008","0","1"],["41.07","0.04","0","1"],["41.1","0.173992","0","1"],["41.17","2.713011","0","1"],["41.26","2.271956","0","1"],["41.28","2.338891","0","1"],["41.3","1","0","1"],["41.32","0.1467","0","1"],["41.33","2.224634","0","2"],["41.37","0.120899","0","1"],["41.38","0.173992","0","1"],["41.43","0.420543","0","1"],["41.49","1.489968","0","1"],["41.5","0.6345","0","3"],["41.52","0.471052","0","1"],["41.54","2.338891","0","1"],["41.6","3.713011","0","2"],["41.63","0.010156","0","1"],["41.66","0.229474","0","2"],["41.68","26.584008","0","1"],["41.76","0.402789","0","1"],["41.8","1","0","1"],["41.81","2.338891","0","1"],["41.83","0.04","0","1"],["41.84","2.271956","0","1"],["41.92","0.120899","0","1"],["41.94","0.173992","0","1"],["41.98","1.489968","0","1"],["41.99","0.055482","0","1"],["42","145.519427","0","6"],["42.02","2.713011","0","1"],["42.04","0.138263","0","1"],["42.06","4.257096","0","1"],["42.08","2.338891","0","1"],["42.13","0.471052","0","1"],["42.17","0.01715","0","1"],["42.2","0.113207","0","1"],["42.23","0.173992","0","1"],["42.24","0.010156","0","1"],["42.28","0.420543","0","1"],["42.3","1","0","1"],["42.33","0.799636","0","2"],["42.35","28.922899","0","2"],["42.4","5.246469","0","1"],["42.42","2.271956","0","1"],["42.45","2.713011","0","1"],["42.47","1.489968","0","1"],["42.48","0.105399","0","1"],["42.5","0.496237","0","2"],["42.51","0.173992","0","1"],["42.52","0.402789","0","1"],["42.6","1.178263","0","3"],["42.62","2.338891","0","1"],["42.66","0.055482","0","1"],["42.72","13.693277","0","1"],["42.73","0.471052","0","1"],["42.8","1.173992","0","2"],["42.85","0.010156","0","1"],["42.89","5.051902","0","2"],["42.9","1","0","1"],["42.97","1.489968","0","1"],["42.99","0.055482","0","1"],["43","7.614784","0","4"],["43.01","2.271956","0","1"],["43.02","26.584008","0","1"],["43.04","0.120899","0","1"],["43.09","0.173992","0","1"],["43.16","0.138263","0","1"],["43.17","2.759444","0","2"],["43.18","2","0","1"],["43.27","0.402789","0","1"],["43.3","1","0","1"],["43.33","2.768493","0","2"],["43.34","0.471052","0","1"],["43.36","0.04","0","1"],["43.38","0.173992","0","1"],["43.44","2.338891","0","1"],["43.46","0.010156","0","1"],["43.48","1.489968","0","1"],["43.5","5.496237","0","3"],["43.52","0.01715","0","1"],["43.6","20.982","0","2"],["43.61","2.271956","0","1"],["43.62","0.120899","0","1"],["43.66","0.055482","0","1"],["43.68","0.173992","0","1"],["43.7","34.293631","0","2"],["43.72","2.338891","0","1"],["43.73","0.138263","0","1"],["43.78","2.713011","0","1"],["43.8","1","0","1"],["43.9","5","0","2"],["43.92","0.717273","0","1"],["43.94","0.471052","0","1"],["43.97","0.173992","0","1"],["43.98","0.13122","0","1"],["43.99","2.68785","0","3"],["44","13.252401","0","4"],["44.03","0.402789","0","1"],["44.06","0.420573","0","1"],["44.08","0.010156","0","1"],["44.13","0.04","0","1"],["44.14","0.039111","0","2"],["44.2","0.120899","0","1"],["44.22","2.271956","0","1"]],"bids":[["32.49","10.603041","0","3"],["32.48","19.73155","0","2"],["32.47","51","0","1"],["32.46","17.099539","0","2"],["32.45","56.237359","0","1"],["32.44","96.49006","0","2"],["32.43","15.37999","0","1"],["32.42","3.77","0","1"],["32.41","116.393306","0","3"],["32.39","30.771139","0","1"],["32.38","128.93274","0","3"],["32.33","20.055516","0","2"],["32.31","627","0","1"],["32.29","46.165317","0","1"],["32.27","6.415062","0","1"],["32.23","259","0","1"],["32.22","2.713961","0","1"],["32.18","2.460396","0","2"],["32.17","1.55","0","1"],["32.15","309.781042","0","2"],["32.11","1.55","0","1"],["32.1","9.817794","0","1"],["32.07","3.038149","0","2"],["32.01","7.54","0","1"],["32","107.242846","0","5"],["31.99","0.055516","0","1"],["31.97","2.339424","0","1"],["31.93","0.402789","0","1"],["31.92","5","0","1"],["31.91","13.960193","0","1"],["31.89","4.713961","0","2"],["31.88","7.58","0","2"],["31.87","26.593316","0","1"],["31.86","0.31392","0","1"],["31.85","4.07","0","1"],["31.84","0.471052","0","1"],["31.83","0.010163","0","1"],["31.82","84.065937","0","1"],["31.81","7","0","1"],["31.77","68.339424","0","2"],["31.76","0.138133","0","2"],["31.71","2.272752","0","1"],["31.69","4.014515","0","2"],["31.68","27.88","0","1"],["31.66","4.775516","0","2"],["31.62","31","0","1"],["31.57","5.053385","0","2"],["31.54","6.61","0","1"],["31.5","200.496536","0","4"],["31.44","1.95","0","1"],["31.38","26.593316","0","1"],["31.37","2.339424","0","1"],["31.34","0.120972","0","1"],["31.33","1.545576","0","2"],["31.27","2.272752","0","1"],["31.25","2.713961","0","1"],["31.23","9.641052","0","2"],["31.22","7.930163","0","2"],["31.2","100.028985","0","2"],["31.17","2.742213","0","2"],["31.12","0.04","0","1"],["31","135.156069","0","5"],["30.99","10.894033","0","2"],["30.97","2.339424","0","1"],["30.93","2.834933","0","2"],["30.92","11.76","0","1"],["30.9","100","0","1"],["30.88","26.593316","0","1"],["30.84","2.272752","0","1"],["30.81","0.973709","0","1"],["30.79","11.17","0","1"],["30.77","2.356585","0","2"],["30.66","0.055516","0","1"],["30.63","0.471052","0","1"],["30.61","2.724124","0","2"],["30.6","100","0","1"],["30.58","2.339424","0","1"],["30.52","0.120972","0","1"],["30.5","321.841634","0","4"],["30.42","0.402789","0","1"],["30.41","2.272752","0","1"],["30.4","26.622301","0","2"],["30.38","2.339424","0","1"],["30.36","14.46","0","1"],["30.35","0.04","0","1"],["30.33","0.055516","0","1"],["30.3","102.713961","0","2"],["30.19","2.339424","0","1"],["30.18","0.128175","0","1"],["30.16","2","0","1"],["30.12","0.120972","0","1"],["30.02","0.471052","0","1"],["30","409.891456","0","18"],["29.99","0.055516","0","1"],["29.92","26.593316","0","1"],["29.82","0.017161","0","1"],["29.8","167.785234","0","1"],["29.73","0.120972","0","1"],["29.7","100","0","1"],["29.66","0.458305","0","2"],["29.6","0.028985","0","1"],["29.59","0.04","0","1"],["29.58","1.5","0","1"],["29.52","0.372629","0","1"],["29.51","0.372755","0","1"],["29.5","180.157552","0","4"],["29.46","26.593316","0","1"],["29.42","0.471052","0","1"],["29.4","100","0","1"],["29.34","0.120972","0","1"],["29.33","0.055516","0","1"],["29.28","1.02459","0","1"],["29.2","102.739726","0","1"],["29.1","100","0","1"],["29","46.900195","0","8"],["28.99","0.055516","0","1"],["28.95","0.120972","0","1"],["28.9","0.402789","0","1"],["28.89","0.017161","0","1"],["28.82","0.04","0","1"],["28.81","0.471052","0","1"],["28.8","100.028985","0","2"],["28.66","0.25047","0","2"],["28.57","0.120972","0","1"],["28.5","100.496536","0","3"],["28.42","0.503345","0","1"],["28.41","0.387188","0","1"],["28.4","13.1","0","1"],["28.33","0.055516","0","1"],["28.21","0.471052","0","1"],["28.2","120.120972","0","4"],["28.15","0.402789","0","1"],["28.06","1.821896","0","2"],["28","41.251924","0","9"],["27.9","115","0","2"],["27.89","2","0","1"],["27.83","0.120972","0","1"],["27.7","30","0","1"],["27.6","100.471052","0","2"],["27.5","2.314717","0","3"],["27.46","0.120972","0","1"],["27.39","0.402789","0","1"],["27.3","100","0","1"],["27.29","0.04","0","1"],["27.2","0.028985","0","1"],["27.1","0.120972","0","1"],["27.02","1.058851","0","1"],["27.01","0.529621","0","1"],["27","415.992769","0","8"],["26.98","10","0","1"],["26.8","359.146323","0","1"],["26.74","0.120972","0","1"],["26.66","0.596443","0","1"],["26.63","0.402789","0","1"],["26.53","0.04","0","1"],["26.5","0.496536","0","2"],["26.4","0.028985","0","1"],["26.39","0.120972","0","1"],["26.2","0.190839","0","1"],["26.16","0.756498","0","1"],["26.05","0.120972","0","1"],["26.01","0.824975","0","1"],["26","31.86365","0","7"],["25.88","0.402789","0","1"],["25.76","0.04","0","1"],["25.7","0.120972","0","1"],["25.6","0.028985","0","1"],["25.5","0.496536","0","2"],["25.45","0.104325","0","1"],["25.37","0.120972","0","1"],["25.12","0.402789","0","1"],["25.11","0.996968","0","1"],["25.1","68.549667","0","1"],["25.03","0.120972","0","1"],["25","216.329122","0","15"],["24.8","0.028985","0","1"],["24.78","14.709444","0","1"],["24.71","0.120972","0","1"],["24.5","0.496536","0","2"],["24.38","0.120972","0","1"],["24.36","0.402789","0","1"],["24.32","64.107178","0","1"],["24.2","30","0","1"],["24.06","0.120972","0","1"],["24","46.025521","0","6"],["23.8","33.613445","0","1"],["23.74","0.120972","0","1"],["23.61","0.402789","0","1"],["23.5","0.496536","0","2"],["23.43","0.120972","0","1"],["23.37","40","0","1"],["23.35","40","0","1"],["23.2","0.028985","0","1"],["23.12","0.120972","0","1"],["23","0.496536","0","2"],["22.85","0.402789","0","1"],["22.82","0.120972","0","1"],["22.52","0.120972","0","1"],["22.5","0.496536","0","2"],["22.4","0.028985","0","1"],["22.23","0.120972","0","1"],["22.1","0.402789","0","1"],["22","8.498536","0","5"],["21.93","0.120972","0","1"],["21.65","0.120972","0","1"],["21.6","0.028985","0","1"],["21.5","0.496536","0","2"],["21.36","0.120972","0","1"],["21.34","0.402789","0","1"],["21.08","0.120972","0","1"],["21","1.796536","0","3"],["20.8","0.149957","0","2"],["20.58","0.402789","0","1"],["20.53","0.120972","0","1"],["20.5","0.496536","0","2"],["20.26","0.120972","0","1"],["20","8.806993","0","10"],["19.83","0.402789","0","1"],["19.07","0.402789","0","1"],["19","13.543539","0","2"],["18.68","120.371726","0","1"],["18.31","0.402789","0","1"],["18.19","0.1","0","1"],["18","71.777863","0","1"],["17.56","91.518962","0","2"],["16.8","0.402789","0","1"],["16.05","0.402789","0","1"],["16","3","0","1"],["15.29","0.402789","0","1"],["15.16","2","0","1"],["15.1","150","0","1"],["15","295.393085","0","6"],["14.53","0.402789","0","1"],["14.28","1.29007","0","1"],["13.8","50.724637","0","1"],["13.78","0.402789","0","1"],["13.02","0.402789","0","1"],["13","17.640276","0","1"],["12.3","0.813008","0","1"],["12.26","0.402789","0","1"],["12","10","0","1"],["11.6","115.517241","0","2"],["11.51","0.402789","0","1"],["10.75","0.402789","0","1"],["10","38.01249","0","5"],["9.99","10","0","1"],["8.49","0.294464","0","1"],["7","3.51009","0","1"],["5.61","1.782531","0","1"],["5","1","0","1"],["1.33","970","0","1"],["0.5","79.548757","0","1"],["0.1","15","0","2"],["0.06","0.06","0","1"],["0.05","1.16","0","12"],["0.01","100","0","1"]],"ts":"1646003667558","checksum":668652066}]}
1646003667.8812668: {"arg":{"channel":"books-l2-tbt","instId":"ETH-USD-220624-12000-P"},"action":"snapshot","data":[{"asks":[["4.0435","201","0","1"]],"bids":[["2.595","201","0","1"]],"ts":"1646003663779","checksum":1172727943}]}
1646003668.088035: {"arg":{"channel":"books-l2-tbt","instId":"UNI-USD-SWAP"},"action":"snapshot","data":[{"asks":[["9.627","348","0","2"],["9.632","3","0","1"],["9.633","1001","0","1"],["9.635","175","0","3"],["9.636","242","0","2"],["9.638","44","0","2"],["9.639","123","0","1"],["9.64","259","0","2"],["9.641","573","0","4"],["9.642","143","0","1"],["9.643","28","0","1"],["9.644","414","0","1"],["9.645","777","0","4"],["9.646","16","0","1"],["9.647","2712","0","5"],["9.648","2065","0","3"],["9.649","1230","0","2"],["9.65","224","0","2"],["9.651","80","0","2"],["9.653","35","0","1"],["9.655","9245","0","1"],["9.656","124","0","1"],["9.662","225","0","1"],["9.663","1754","0","3"],["9.664","64","0","1"],["9.668","510","0","1"],["9.67","16","0","1"],["9.671","846","0","1"],["9.672","44","0","1"],["9.68","15147","0","1"],["9.682","160","0","1"],["9.704","160","0","1"],["9.712","43","0","1"],["9.728","846","0","1"],["9.734","240","0","1"],["9.746","6412","0","1"],["9.75","19","0","1"],["9.76","19","0","1"],["9.762","240","0","1"],["9.768","23","0","1"],["9.77","29","0","1"],["9.787","846","0","1"],["9.789","15141","0","1"],["9.791","2127","0","1"],["9.796","320","0","1"],["9.8","19","0","1"],["9.82","19","0","1"],["9.84","19","0","1"],["9.85","320","0","1"],["9.855","20","0","1"],["9.86","22","0","1"],["9.863","2090","0","1"],["9.917","2133","0","1"],["9.943","10","0","1"],["9.989","2185","0","1"],["10.032","26","0","1"],["10.088","2096","0","1"],["10.102","2","0","1"],["10.122","22","0","1"],["10.146","6","0","1"],["10.166","10","0","1"],["10.2","163","0","4"],["10.213","20","0","1"],["10.222","10","0","1"],["10.259","15","0","1"],["10.3","135","0","3"],["10.304","28","0","1"],["10.338","5","0","1"],["10.38","2","0","1"],["10.396","26","0","1"],["10.4","12","0","2"],["10.417","159","0","1"],["10.433","5","0","1"],["10.489","25","0","1"],["10.5","122","0","3"],["10.55","50","0","1"],["10.56","1","0","1"],["10.575","5","0","1"],["10.6","202","0","2"],["10.666","2133","0","1"],["10.7","52","0","2"],["10.733","31","0","1"],["10.8","2","0","1"],["10.9","2","0","1"],["10.936","1","0","1"],["10.98","92","0","1"],["11","78","0","3"],["11.088","1","0","1"],["11.6","3","0","1"],["11.642","1","0","1"],["11.7","3","0","1"],["11.8","3","0","1"],["11.82","1","0","1"],["11.9","3","0","1"],["11.989","38","0","1"],["12","9","0","2"],["12.1","3","0","1"],["12.2","3","0","1"],["12.224","1","0","1"],["12.281","1526","0","1"],["12.3","4","0","2"],["12.4","3","0","1"],["12.5","3","0","1"],["12.6","3","0","1"],["12.7","3","0","1"],["12.75","1","0","1"],["12.8","3","0","1"],["12.835","1","0","1"],["12.9","3","0","1"],["12.96","10","0","1"],["13","3","0","1"],["13.1","3","0","1"],["13.121","169","0","1"],["13.2","3","0","1"],["13.3","3","0","1"],["13.4","4","0","1"],["13.5","4","0","1"],["13.6","4","0","1"],["13.7","4","0","1"],["13.707","221","0","1"],["13.8","4","0","1"],["13.9","4","0","1"],["13.975","111","0","1"],["14","4","0","1"],["14.1","4","0","1"],["14.2","4","0","1"],["14.3","4","0","1"],["14.4","4","0","1"],["14.436","1","0","1"],["14.5","4","0","1"],["14.51","1","0","1"],["14.587","1","0","1"],["14.6","4","0","1"],["14.66","1","0","1"],["14.7","4","0","1"],["14.736","1","0","1"],["14.8","4","0","1"],["14.81","1","0","1"],["14.896","1","0","1"],["14.9","4","0","1"],["15","213","0","3"],["15.011","1","0","1"],["15.075","1","0","1"],["15.1","4","0","1"],["15.144","1","0","1"],["15.2","4","0","1"],["15.234","1","0","1"],["15.3","4","0","1"],["15.31","1","0","1"],["15.4","4","0","1"],["15.432","1","0","1"],["15.5","4","0","1"],["15.514","1","0","1"],["15.574","1","0","1"],["15.6","4","0","1"],["15.652","1","0","1"],["15.7","4","0","1"],["15.732","1","0","1"],["15.8","4","0","1"],["15.81","1","0","1"],["15.88","1","0","1"],["15.888","1","0","1"],["15.9","4","0","1"],["15.963","1","0","1"],["16","420","0","2"],["16.035","1","0","1"],["16.1","4","0","1"],["16.117","1","0","1"],["16.2","4","0","1"],["16.211","1","0","1"],["16.241","1","0","1"],["16.3","4","0","1"],["16.314","1","0","1"],["16.323","1","0","1"],["16.329","1","0","1"],["16.395","1","0","1"],["16.4","4","0","1"],["16.404","1","0","1"],["16.452","1","0","1"],["16.477","1","0","1"],["16.486","1","0","1"],["16.5","4","0","1"],["16.523","1","0","1"],["16.569","1","0","1"],["16.6","4","0","1"],["16.61","1","0","1"],["16.7","5","0","1"],["16.729","1","0","1"],["16.8","5","0","1"],["16.829","1","0","1"],["16.898","1","0","1"],["16.9","5","0","1"],["16.975","1","0","1"],["17","5","0","1"],["17.06","84","0","1"],["17.079","1","0","1"],["17.1","5","0","1"],["17.154","1","0","1"],["17.2","5","0","1"],["17.3","5","0","1"],["17.4","45","0","2"],["17.5","5","0","1"],["17.6","5","0","1"],["17.7","5","0","1"],["17.8","5","0","1"],["17.9","5","0","1"],["18","125","0","3"],["18.1","5","0","1"],["18.176","166","0","1"],["18.2","5","0","1"],["18.215","1","0","1"],["18.3","5","0","1"],["18.4","5","0","1"],["18.5","5","0","1"],["18.6","5","0","1"],["18.7","5","0","1"],["18.8","5","0","1"],["18.9","5","0","1"],["18.954","1","0","1"],["19","5","0","1"],["19.1","4","0","1"],["19.111","1","0","1"],["19.6","30","0","1"],["19.631","1","0","1"],["19.93","166","0","1"],["19.953","1","0","1"],["20","10","0","1"],["20.216","1","0","1"],["20.348","1","0","1"],["20.437","1","0","1"],["20.583","1","0","1"],["20.686","1","0","1"],["20.791","1","0","1"],["20.9","1","0","1"],["21.018","1","0","1"],["21.125","1","0","1"],["21.185","1","0","1"],["21.327","1","0","1"],["21.412","1","0","1"],["21.438","1","0","1"],["21.519","1","0","1"],["21.547","1","0","1"],["21.627","1","0","1"],["21.654","1","0","1"],["21.735","1","0","1"],["21.781","1","0","1"],["21.828","88","0","1"],["21.843","1","0","1"],["21.957","1","0","1"],["22.057","1","0","1"],["22.169","1","0","1"],["22.3","1","0","1"],["22.378","1","0","1"],["22.401","1","0","1"],["22.489","1","0","1"],["22.509","1","0","1"],["22.602","1","0","1"],["22.615","1","0","1"],["22.715","1","0","1"],["22.925","1","0","1"],["23.082","1","0","1"],["23.194","1","0","1"],["23.31","1","0","1"],["23.427","1","0","1"],["23.538","1","0","1"],["23.636","1","0","1"],["23.746","1","0","1"],["23.866","1","0","1"],["23.985","1","0","1"],["24.106","1","0","1"],["24.228","1","0","1"],["24.374","1","0","1"],["24.447","1","0","1"],["24.463","1","0","1"],["24.482","1","0","1"],["24.55","1","0","1"],["24.569","1","0","1"],["24.586","1","0","1"],["24.605","1","0","1"],["24.671","1","0","1"],["24.692","1","0","1"],["24.708","1","0","1"],["24.728","1","0","1"],["24.816","1","0","1"],["24.832","1","0","1"],["24.851","1","0","1"],["24.94","1","0","1"],["24.956","1","0","1"],["24.976","1","0","1"],["28.501","1","0","1"],["28.646","1","0","1"],["28.792","1","0","1"],["28.938","1","0","1"],["29.086","1","0","1"],["29.234","1","0","1"],["29.383","1","0","1"],["29.53","1","0","1"],["29.677","1","0","1"],["29.826","1","0","1"],["29.975","1","0","1"],["30","94","0","1"],["30.125","1","0","1"],["30.275","1","0","1"],["30.427","1","0","1"],["30.579","1","0","1"],["30.732","1","0","1"],["30.885","1","0","1"],["31.04","1","0","1"],["31.195","1","0","1"],["31.351","1","0","1"],["31.508","1","0","1"],["31.665","1","0","1"],["31.823","1","0","1"],["31.983","1","0","1"],["32","219","0","1"],["32.143","1","0","1"],["32.303","1","0","1"],["32.465","1","0","1"],["32.627","1","0","1"],["32.79","1","0","1"],["32.954","1","0","1"],["33.119","1","0","1"],["33.285","1","0","1"],["33.451","1","0","1"],["33.618","1","0","1"],["33.786","1","0","1"],["33.955","1","0","1"],["34.125","1","0","1"],["34.296","1","0","1"],["34.467","1","0","1"],["34.639","1","0","1"],["34.813","1","0","1"],["34.987","1","0","1"],["35.162","1","0","1"],["35.337","1","0","1"],["35.514","1","0","1"],["35.692","1","0","1"],["35.87","1","0","1"],["36.049","1","0","1"],["36.23","1","0","1"],["36.411","1","0","1"],["36.593","1","0","1"],["36.776","1","0","1"],["36.96","2","0","2"],["37.145","1","0","1"],["37.33","1","0","1"],["37.517","1","0","1"],["37.704","1","0","1"],["37.893","1","0","1"],["38.082","1","0","1"],["38.273","1","0","1"],["38.464","1","0","1"],["38.657","1","0","1"],["38.85","1","0","1"],["39.044","1","0","1"],["39.239","1","0","1"],["39.435","1","0","1"],["39.633","1","0","1"],["39.831","1","0","1"],["40","154","0","1"],["40.03","1","0","1"],["40.23","1","0","1"],["40.431","1","0","1"],["40.633","1","0","1"],["40.837","1","0","1"],["41.041","1","0","1"],["41.246","1","0","1"],["41.452","1","0","1"],["41.659","1","0","1"],["41.868","1","0","1"],["42.077","1","0","1"],["42.287","1","0","1"],["42.499","1","0","1"],["42.711","1","0","1"],["42.925","1","0","1"],["43.14","1","0","1"],["43.355","1","0","1"],["43.572","1","0","1"],["43.79","1","0","1"],["44.009","1","0","1"],["44.229","1","0","1"],["44.45","1","0","1"],["44.672","1","0","1"],["44.896","1","0","1"],["45.12","1","0","1"],["45.346","1","0","1"],["45.572","1","0","1"],["45.8","1","0","1"],["46.029","1","0","1"],["46.259","1","0","1"],["46.491","1","0","1"],["46.723","1","0","1"],["46.957","1","0","1"],["47.192","1","0","1"],["47.428","1","0","1"],["47.665","1","0","1"],["47.903","1","0","1"],["48.143","1","0","1"],["48.383","1","0","1"],["48.625","1","0","1"]],"bids":[["9.619","282","0","2"],["9.618","109","0","1"],["9.617","388","0","3"],["9.616","12","0","1"],["9.614","1","0","1"],["9.613","18","0","2"],["9.61","11","0","1"],["9.607","500","0","1"],["9.606","80","0","1"],["9.605","56","0","2"],["9.604","317","0","2"],["9.603","1271","0","2"],["9.6","196","0","3"],["9.599","620","0","2"],["9.596","143","0","1"],["9.594","399","0","4"],["9.592","246","0","4"],["9.591","16","0","1"],["9.59","1548","0","3"],["9.588","125","0","1"],["9.586","142","0","1"],["9.585","9589","0","2"],["9.583","160","0","1"],["9.582","634","0","2"],["9.581","68","0","1"],["9.579","738","0","4"],["9.578","64","0","1"],["9.577","1574","0","1"],["9.576","1052","0","1"],["9.573","4","0","1"],["9.572","332","0","1"],["9.568","846","0","1"],["9.567","2124","0","1"],["9.552","58","0","1"],["9.55","19","0","1"],["9.544","160","0","1"],["9.535","160","0","1"],["9.524","14969","0","1"],["9.509","846","0","1"],["9.502","2","0","1"],["9.501","240","0","1"],["9.5","49","0","2"],["9.492","70","0","1"],["9.491","6319","0","1"],["9.467","240","0","1"],["9.449","846","0","1"],["9.444","2183","0","1"],["9.428","320","0","1"],["9.409","15","0","1"],["9.408","13508","0","1"],["9.4","58","0","2"],["9.378","320","0","1"],["9.369","2076","0","1"],["9.34","2099","0","1"],["9.325","18","0","1"],["9.3","80","0","3"],["9.298","40","0","1"],["9.242","23","0","1"],["9.232","200","0","1"],["9.229","5","0","1"],["9.21","40","0","1"],["9.2","57","0","2"],["9.19","10","0","1"],["9.159","25","0","1"],["9.146","2164","0","1"],["9.129","5","0","1"],["9.107","40","0","1"],["9.1","69","0","2"],["9.09","10","0","1"],["9.082","1","0","1"],["9.08","272","0","1"],["9.077","19","0","1"],["9.066","40","0","1"],["9.029","5","0","1"],["9.026","2111","0","1"],["9","57","0","2"],["8.997","40","0","1"],["8.996","940","0","2"],["8.99","10","0","1"],["8.929","5","0","1"],["8.924","40","0","1"],["8.916","14","0","1"],["8.9","30","0","1"],["8.89","10","0","1"],["8.839","40","0","1"],["8.836","23","0","1"],["8.8","30","0","1"],["8.79","10","0","1"],["8.78","1671","0","1"],["8.772","40","0","1"],["8.757","13","0","1"],["8.7","30","0","1"],["8.65","4","0","1"],["8.628","1","0","1"],["8.6","30","0","1"],["8.596","40","0","1"],["8.5","65","0","3"],["8.462","5","0","1"],["8.43","300","0","1"],["8.4","30","0","1"],["8.39","5","0","1"],["8.3","12","0","1"],["8.28","1","0","1"],["8.2","1","0","1"],["8.197","1","0","1"],["8.15","21","0","1"],["8.1","370","0","1"],["8.088","5","0","1"],["8.01","7","0","1"],["8","55","0","4"],["7.99","5","0","1"],["7.988","5","0","1"],["7.82","10","0","1"],["7.8","159","0","2"],["7.788","6","0","2"],["7.704","191","0","1"],["7.7","10","0","1"],["7.688","5","0","1"],["7.65","114","0","1"],["7.6","10","0","1"],["7.59","600","0","1"],["7.588","5","0","1"],["7.58","37","0","1"],["7.555","18","0","1"],["7.547","150","0","1"],["7.52","2","0","1"],["7.5","23","0","2"],["7.41","24","0","1"],["7.4","15","0","1"],["7.399","1","0","1"],["7.36","10","0","1"],["7.232","144","0","1"],["7.223","2","0","1"],["7.18","5","0","1"],["7.1","14","0","1"],["7.055","20","0","1"],["7","338","0","3"],["6.8","5","0","3"],["6.75","1","0","1"],["6.6","2","0","1"],["6.545","501","0","1"],["6.5","1","0","1"],["6.18","12","0","1"],["6.12","12","0","1"],["6.1","2","0","1"],["6","1686","0","3"],["5.64","10","0","1"],["5.5","2","0","1"],["5","297","0","1"],["4.688","101","0","1"],["4.444","1974","0","1"],["4.323","216","0","1"],["4.219","2","0","1"],["3.65","127","0","1"],["3.6","1","0","1"],["3.438","75","0","2"],["3.028","612","0","1"],["1.23","42","0","1"]],"ts":"1646003667620","checksum":752109140}]}
1646003668.0908558: {"arg":{"channel":"books-l2-tbt","instId":"ZEN-USDT"},"action":"snapshot","data":[{"asks":[["32.52","0.310999","0","1"],["32.53","8","0","1"],["32.55","10.240982","0","3"],["32.56","9.234604","0","1"],["32.58","46.019517","0","2"],["32.59","94.820017","0","1"],["32.6","51","0","1"],["32.62","35.965067","0","1"],["32.64","95","0","1"],["32.65","13.847704","0","1"],["32.7","100","0","1"],["32.71","361.583151","0","1"],["32.72","5.192426","0","1"],["32.76","60","0","1"],["32.79","5.409261","0","1"],["32.8","2.338605","0","1"],["32.81","1.94","0","1"],["32.82","99.585582","0","2"],["32.84","1.52","0","1"],["32.88","2.713011","0","1"],["32.9","1.51","0","1"],["32.92","2.25","0","1"],["32.99","1.606449","0","2"],["33","8.036261","0","3"],["33.01","2.338605","0","1"],["33.04","0.120899","0","1"],["33.05","2.742725","0","2"],["33.06","0.010156","0","1"],["33.1","13.914221","0","2"],["33.16","4.24161","0","2"],["33.21","9.029165","0","2"],["33.22","5.051616","0","2"],["33.24","7.54","0","1"],["33.25","8.12863","0","1"],["33.31","7.54","0","1"],["33.33","0.055482","0","1"],["33.36","4.52","0","1"],["33.41","7.58","0","2"],["33.42","26.584008","0","1"],["33.43","2.338605","0","1"],["33.44","0.402789","0","1"],["33.48","0.120899","0","1"],["33.49","6.33","0","1"],["33.5","0.496261","0","2"],["33.51","2.271956","0","1"],["33.56","2.713011","0","1"],["33.6","1.518132","0","2"],["33.65","2.809374","0","2"],["33.66","0.055482","0","1"],["33.67","0.010156","0","1"],["33.82","16.19715","0","3"],["33.86","2.338605","0","1"],["33.91","2.713011","0","1"],["33.93","0.120899","0","1"],["33.95","26.584008","0","1"],["33.98","2.271956","0","1"],["33.99","0.055482","0","1"],["34","1.985426","0","3"],["34.08","2.338605","0","1"],["34.15","11.04","0","1"],["34.18","0.04","0","1"],["34.2","0.402789","0","1"],["34.26","3.18378","0","2"],["34.28","0.010156","0","1"],["34.29","10.4","0","1"],["34.3","2.338605","0","1"],["34.33","0.055482","0","1"],["34.38","0.120899","0","1"],["34.4","1.489354","0","2"],["34.46","2.271956","0","1"],["34.49","26.584008","0","1"],["34.5","0.496261","0","2"],["34.52","2.338605","0","1"],["34.61","2.713011","0","1"],["34.66","0.055482","0","1"],["34.68","0.908544","0","1"],["34.74","2.338605","0","1"],["34.77","13.28","0","1"],["34.81","1.489165","0","1"],["34.84","0.120899","0","1"],["34.86","0.470769","0","1"],["34.89","0.010156","0","1"],["34.9","0.01715","0","1"],["34.94","2.311956","0","2"],["34.95","0.402789","0","1"],["34.96","5.051616","0","2"],["34.98","506","0","1"],["34.99","10.055482","0","2"],["35","0.559244","0","3"],["35.04","26.584008","0","1"],["35.18","102.762877","0","1"],["35.19","2.338605","0","1"],["35.2","0.028967","0","1"],["35.22","1.489165","0","1"],["35.28","110.538566","0","2"],["35.3","1.120899","0","2"],["35.32","2.713011","0","1"],["35.33","0.055482","0","1"],["35.41","2.338605","0","1"],["35.42","2.271956","0","1"],["35.46","0.13818","0","1"],["35.47","0.470769","0","1"],["35.5","0.496261","0","2"],["35.51","0.010156","0","1"],["35.58","3.914741","0","1"],["35.6","26.584008","0","1"],["35.63","1.489968","0","1"],["35.64","2.338605","0","1"],["35.66","0.055482","0","1"],["35.68","1.5","0","1"],["35.69","2.713011","0","1"],["35.71","0.442789","0","2"],["35.77","0.120899","0","1"],["35.8","188.726026","0","5"],["35.83","2","0","1"],["35.87","2.338605","0","1"],["35.88","91.180905","0","2"],["35.9","143.713329","0","2"],["35.92","2.410136","0","2"],["35.99","0.055482","0","1"],["36","417.41764","0","14"],["36.02","0.01715","0","1"],["36.05","4.202979","0","2"],["36.07","0.471052","0","1"],["36.1","102.338605","0","2"],["36.12","0.010156","0","1"],["36.16","26.584008","0","1"],["36.2","100","0","1"],["36.25","0.120899","0","1"],["36.28","1","0","1"],["36.3","101","0","2"],["36.32","16.315846","0","1"],["36.33","2.394087","0","2"],["36.4","100.13818","0","2"],["36.42","4.984967","0","2"],["36.45","0.284083","0","2"],["36.47","1.932757","0","3"],["36.5","100.496261","0","3"],["36.56","2.338605","0","1"],["36.6","113.4925","0","3"],["36.66","0.055482","0","1"],["36.68","0.471052","0","1"],["36.7","100","0","1"],["36.73","0.131055","0","2"],["36.74","26.584008","0","1"],["36.78","3","0","1"],["36.8","107.421692","0","6"],["36.88","0.13818","0","1"],["36.9","101.489968","0","2"],["36.93","2.271956","0","1"],["36.99","1.460712","0","2"],["37","111.341454","0","5"],["37.03","2.338605","0","1"],["37.1","100","0","1"],["37.17","89.942068","0","3"],["37.2","100","0","1"],["37.22","0.523688","0","2"],["37.24","0.04","0","1"],["37.27","2.338605","0","1"],["37.28","2.471052","0","2"],["37.3","101","0","2"],["37.32","26.584008","0","1"],["37.33","0.055482","0","1"],["37.34","1.500124","0","2"],["37.37","0.13818","0","1"],["37.38","1.404835","0","1"],["37.4","1553.58441","0","2"],["37.44","2.271956","0","1"],["37.5","100.496261","0","3"],["37.51","2.338605","0","1"],["37.56","24.716538","0","2"],["37.6","101","0","2"],["37.66","0.055482","0","1"],["37.7","100","0","1"],["37.71","0.120899","0","1"],["37.75","2.338605","0","1"],["37.78","1.489968","0","1"],["37.8","101","0","2"],["37.86","0.13818","0","1"],["37.88","24.458763","0","1"],["37.89","0.471052","0","1"],["37.9","100","0","1"],["37.92","26.584008","0","1"],["37.94","2.713011","0","1"],["37.95","0.010156","0","1"],["37.97","2.271956","0","1"],["37.98","0.402789","0","1"],["37.99","2.394087","0","2"],["38","459.968777","0","7"],["38.01","0.04","0","1"],["38.06","19.048877","0","1"],["38.08","0.146689","0","1"],["38.2","6.2","0","2"],["38.22","1.610867","0","2"],["38.23","2.338605","0","1"],["38.28","1","0","1"],["38.3","1","0","1"],["38.33","2.768493","0","2"],["38.36","0.15533","0","2"],["38.41","0.139269","0","1"],["38.48","2.338605","0","1"],["38.49","0.471052","0","1"],["38.5","2.768217","0","3"],["38.52","26.584008","0","1"],["38.57","15.104852","0","2"],["38.6","1","0","1"],["38.66","11.328482","0","2"],["38.67","1.489968","0","1"],["38.7","28.073033","0","1"],["38.71","0.142488","0","1"],["38.72","5.172515","0","3"],["38.73","0.402789","0","1"],["38.77","0.04","0","1"],["38.8","1","0","1"],["38.86","0.13818","0","1"],["38.87","0.146697","0","1"],["38.88","4","0","1"],["38.96","0.559299","0","1"],["38.97","0.819338","0","2"],["38.99","0.055482","0","1"],["39","28.122723","0","5"],["39.04","2.271956","0","1"],["39.1","0.471052","0","1"],["39.11","0.083143","0","1"],["39.12","2.713011","0","1"],["39.13","28.073976","0","2"],["39.18","0.010156","0","1"],["39.22","4.664772","0","2"],["39.24","0.120899","0","1"],["39.3","1","0","1"],["39.33","0.055482","0","1"],["39.38","0.13818","0","1"],["39.44","1.850553","0","1"],["39.47","2.338605","0","1"],["39.48","5","0","1"],["39.49","0.402789","0","1"],["39.5","0.496237","0","2"],["39.52","2.713011","0","1"],["39.54","0.04","0","1"],["39.55","30","0","1"],["39.58","2.271956","0","1"],["39.59","1.507118","0","2"],["39.6","1","0","1"],["39.66","0.055482","0","1"],["39.68","1.471488","0","1"],["39.69","0.1467","0","1"],["39.71","0.471052","0","1"],["39.73","2.338605","0","1"],["39.76","26.704907","0","2"],["39.77","0.420533","0","1"],["39.79","0.010156","0","1"],["39.8","1","0","1"],["39.88","1.171287","0","1"],["39.9","0.138263","0","1"],["39.93","2.713011","0","1"],["39.95","9.104971","0","1"],["39.98","2.338891","0","1"],["39.99","0.055482","0","1"],["40","217.12312","0","7"],["40.05","2.5","0","1"],["40.06","1.489968","0","1"],["40.11","2","0","1"],["40.13","2.271956","0","1"],["40.24","2.338891","0","1"],["40.25","0.402789","0","1"],["40.28","0.173992","0","1"],["40.29","0.120899","0","1"],["40.3","1.04","0","2"],["40.31","0.471052","0","1"],["40.33","1.377372","0","2"],["40.34","2.713011","0","1"],["40.39","26.584008","0","1"],["40.4","0.010156","0","1"],["40.42","0.138263","0","1"],["40.49","0.1467","0","1"],["40.5","3.834528","0","4"],["40.53","2.805336","0","2"],["40.55","0.173992","0","1"],["40.6","1","0","1"],["40.61","0.420543","0","1"],["40.66","0.055482","0","1"],["40.69","2.271956","0","1"],["40.75","5.051902","0","2"],["40.8","1","0","1"],["40.82","0.173992","0","1"],["40.83","0.120899","0","1"],["40.86","0.01715","0","1"],["40.88","2.169152","0","1"],["40.9","6","0","1"],["40.92","0.471052","0","1"],["40.96","0.138263","0","1"],["40.98","0.768768","0","1"],["40.99","0.055482","0","1"],["41","12.440245","0","6"],["41.02","2.349047","0","2"],["41.03","26.584008","0","1"],["41.07","0.04","0","1"],["41.1","0.173992","0","1"],["41.17","2.713011","0","1"],["41.26","2.271956","0","1"],["41.28","2.338891","0","1"],["41.3","1","0","1"],["41.32","0.1467","0","1"],["41.33","2.224634","0","2"],["41.37","0.120899","0","1"],["41.38","0.173992","0","1"],["41.43","0.420543","0","1"],["41.49","1.489968","0","1"],["41.5","0.6345","0","3"],["41.52","0.471052","0","1"],["41.54","2.338891","0","1"],["41.6","3.713011","0","2"],["41.63","0.010156","0","1"],["41.66","0.229474","0","2"],["41.68","26.584008","0","1"],["41.76","0.402789","0","1"],["41.8","1","0","1"],["41.81","2.338891","0","1"],["41.83","0.04","0","1"],["41.84","2.271956","0","1"],["41.92","0.120899","0","1"],["41.94","0.173992","0","1"],["41.98","1.489968","0","1"],["41.99","0.055482","0","1"],["42","145.519427","0","6"],["42.02","2.713011","0","1"],["42.04","0.138263","0","1"],["42.06","4.257096","0","1"],["42.08","2.338891","0","1"],["42.13","0.471052","0","1"],["42.17","0.01715","0","1"],["42.2","0.113207","0","1"],["42.23","0.173992","0","1"],["42.24","0.010156","0","1"],["42.28","0.420543","0","1"],["42.3","1","0","1"],["42.33","0.799636","0","2"],["42.35","28.922899","0","2"],["42.4","5.246469","0","1"],["42.42","2.271956","0","1"],["42.45","2.713011","0","1"],["42.47","1.489968","0","1"],["42.48","0.105399","0","1"],["42.5","0.496237","0","2"],["42.51","0.173992","0","1"],["42.52","0.402789","0","1"],["42.6","1.178263","0","3"],["42.62","2.338891","0","1"],["42.66","0.055482","0","1"],["42.72","13.693277","0","1"],["42.73","0.471052","0","1"],["42.8","1.173992","0","2"],["42.85","0.010156","0","1"],["42.89","5.051902","0","2"],["42.9","1","0","1"],["42.97","1.489968","0","1"],["42.99","0.055482","0","1"],["43","7.614784","0","4"],["43.01","2.271956","0","1"],["43.02","26.584008","0","1"],["43.04","0.120899","0","1"],["43.09","0.173992","0","1"],["43.16","0.138263","0","1"],["43.17","2.759444","0","2"],["43.18","2","0","1"],["43.27","0.402789","0","1"],["43.3","1","0","1"],["43.33","2.768493","0","2"],["43.34","0.471052","0","1"],["43.36","0.04","0","1"],["43.38","0.173992","0","1"],["43.44","2.338891","0","1"],["43.46","0.010156","0","1"],["43.48","1.489968","0","1"],["43.5","5.496237","0","3"],["43.52","0.01715","0","1"],["43.6","20.982","0","2"],["43.61","2.271956","0","1"],["43.62","0.120899","0","1"],["43.66","0.055482","0","1"],["43.68","0.173992","0","1"],["43.7","34.293631","0","2"],["43.72","2.338891","0","1"],["43.73","0.138263","0","1"],["43.78","2.713011","0","1"],["43.8","1","0","1"],["43.9","5","0","2"],["43.92","0.717273","0","1"],["43.94","0.471052","0","1"],["43.97","0.173992","0","1"],["43.98","0.13122","0","1"],["43.99","2.68785","0","3"],["44","13.252401","0","4"],["44.03","0.402789","0","1"],["44.06","0.420573","0","1"],["44.08","0.010156","0","1"],["44.13","0.04","0","1"],["44.14","0.039111","0","2"],["44.2","0.120899","0","1"],["44.22","2.271956","0","1"]],"bids":[["32.49","10.603041","0","3"],["32.48","19.73155","0","2"],["32.47","51","0","1"],["32.46","17.099539","0","2"],["32.45","56.237359","0","1"],["32.44","96.49006","0","2"],["32.43","15.37999","0","1"],["32.42","3.77","0","1"],["32.41","116.393306","0","3"],["32.39","30.771139","0","1"],["32.38","128.93274","0","3"],["32.33","20.055516","0","2"],["32.31","627","0","1"],["32.29","46.165317","0","1"],["32.27","6.415062","0","1"],["32.23","259","0","1"],["32.22","2.713961","0","1"],["32.18","2.460396","0","2"],["32.17","1.55","0","1"],["32.15","309.781042","0","2"],["32.11","1.55","0","1"],["32.1","9.817794","0","1"],["32.07","3.038149","0","2"],["32.01","7.54","0","1"],["32","107.242846","0","5"],["31.99","0.055516","0","1"],["31.97","2.339424","0","1"],["31.93","0.402789","0","1"],["31.92","5","0","1"],["31.91","13.960193","0","1"],["31.89","4.713961","0","2"],["31.88","7.58","0","2"],["31.87","26.593316","0","1"],["31.86","0.31392","0","1"],["31.85","4.07","0","1"],["31.84","0.471052","0","1"],["31.83","0.010163","0","1"],["31.82","84.065937","0","1"],["31.81","7","0","1"],["31.77","68.339424","0","2"],["31.76","0.138133","0","2"],["31.71","2.272752","0","1"],["31.69","4.014515","0","2"],["31.68","27.88","0","1"],["31.66","4.775516","0","2"],["31.62","31","0","1"],["31.57","5.053385","0","2"],["31.54","6.61","0","1"],["31.5","200.496536","0","4"],["31.44","1.95","0","1"],["31.38","26.593316","0","1"],["31.37","2.339424","0","1"],["31.34","0.120972","0","1"],["31.33","1.545576","0","2"],["31.27","2.272752","0","1"],["31.25","2.713961","0","1"],["31.23","9.641052","0","2"],["31.22","7.930163","0","2"],["31.2","100.028985","0","2"],["31.17","2.742213","0","2"],["31.12","0.04","0","1"],["31","135.156069","0","5"],["30.99","10.894033","0","2"],["30.97","2.339424","0","1"],["30.93","2.834933","0","2"],["30.92","11.76","0","1"],["30.9","100","0","1"],["30.88","26.593316","0","1"],["30.84","2.272752","0","1"],["30.81","0.973709","0","1"],["30.79","11.17","0","1"],["30.77","2.356585","0","2"],["30.66","0.055516","0","1"],["30.63","0.471052","0","1"],["30.61","2.724124","0","2"],["30.6","100","0","1"],["30.58","2.339424","0","1"],["30.52","0.120972","0","1"],["30.5","321.841634","0","4"],["30.42","0.402789","0","1"],["30.41","2.272752","0","1"],["30.4","26.622301","0","2"],["30.38","2.339424","0","1"],["30.36","14.46","0","1"],["30.35","0.04","0","1"],["30.33","0.055516","0","1"],["30.3","102.713961","0","2"],["30.19","2.339424","0","1"],["30.18","0.128175","0","1"],["30.16","2","0","1"],["30.12","0.120972","0","1"],["30.02","0.471052","0","1"],["30","409.891456","0","18"],["29.99","0.055516","0","1"],["29.92","26.593316","0","1"],["29.82","0.017161","0","1"],["29.8","167.785234","0","1"],["29.73","0.120972","0","1"],["29.7","100","0","1"],["29.66","0.458305","0","2"],["29.6","0.028985","0","1"],["29.59","0.04","0","1"],["29.58","1.5","0","1"],["29.52","0.372629","0","1"],["29.51","0.372755","0","1"],["29.5","180.157552","0","4"],["29.46","26.593316","0","1"],["29.42","0.471052","0","1"],["29.4","100","0","1"],["29.34","0.120972","0","1"],["29.33","0.055516","0","1"],["29.28","1.02459","0","1"],["29.2","102.739726","0","1"],["29.1","100","0","1"],["29","46.900195","0","8"],["28.99","0.055516","0","1"],["28.95","0.120972","0","1"],["28.9","0.402789","0","1"],["28.89","0.017161","0","1"],["28.82","0.04","0","1"],["28.81","0.471052","0","1"],["28.8","100.028985","0","2"],["28.66","0.25047","0","2"],["28.57","0.120972","0","1"],["28.5","100.496536","0","3"],["28.42","0.503345","0","1"],["28.41","0.387188","0","1"],["28.4","13.1","0","1"],["28.33","0.055516","0","1"],["28.21","0.471052","0","1"],["28.2","120.120972","0","4"],["28.15","0.402789","0","1"],["28.06","1.821896","0","2"],["28","41.251924","0","9"],["27.9","115","0","2"],["27.89","2","0","1"],["27.83","0.120972","0","1"],["27.7","30","0","1"],["27.6","100.471052","0","2"],["27.5","2.314717","0","3"],["27.46","0.120972","0","1"],["27.39","0.402789","0","1"],["27.3","100","0","1"],["27.29","0.04","0","1"],["27.2","0.028985","0","1"],["27.1","0.120972","0","1"],["27.02","1.058851","0","1"],["27.01","0.529621","0","1"],["27","415.992769","0","8"],["26.98","10","0","1"],["26.8","359.146323","0","1"],["26.74","0.120972","0","1"],["26.66","0.596443","0","1"],["26.63","0.402789","0","1"],["26.53","0.04","0","1"],["26.5","0.496536","0","2"],["26.4","0.028985","0","1"],["26.39","0.120972","0","1"],["26.2","0.190839","0","1"],["26.16","0.756498","0","1"],["26.05","0.120972","0","1"],["26.01","0.824975","0","1"],["26","31.86365","0","7"],["25.88","0.402789","0","1"],["25.76","0.04","0","1"],["25.7","0.120972","0","1"],["25.6","0.028985","0","1"],["25.5","0.496536","0","2"],["25.45","0.104325","0","1"],["25.37","0.120972","0","1"],["25.12","0.402789","0","1"],["25.11","0.996968","0","1"],["25.1","68.549667","0","1"],["25.03","0.120972","0","1"],["25","216.329122","0","15"],["24.8","0.028985","0","1"],["24.78","14.709444","0","1"],["24.71","0.120972","0","1"],["24.5","0.496536","0","2"],["24.38","0.120972","0","1"],["24.36","0.402789","0","1"],["24.32","64.107178","0","1"],["24.2","30","0","1"],["24.06","0.120972","0","1"],["24","46.025521","0","6"],["23.8","33.613445","0","1"],["23.74","0.120972","0","1"],["23.61","0.402789","0","1"],["23.5","0.496536","0","2"],["23.43","0.120972","0","1"],["23.37","40","0","1"],["23.35","40","0","1"],["23.2","0.028985","0","1"],["23.12","0.120972","0","1"],["23","0.496536","0","2"],["22.85","0.402789","0","1"],["22.82","0.120972","0","1"],["22.52","0.120972","0","1"],["22.5","0.496536","0","2"],["22.4","0.028985","0","1"],["22.23","0.120972","0","1"],["22.1","0.402789","0","1"],["22","8.498536","0","5"],["21.93","0.120972","0","1"],["21.65","0.120972","0","1"],["21.6","0.028985","0","1"],["21.5","0.496536","0","2"],["21.36","0.120972","0","1"],["21.34","0.402789","0","1"],["21.08","0.120972","0","1"],["21","1.796536","0","3"],["20.8","0.149957","0","2"],["20.58","0.402789","0","1"],["20.53","0.120972","0","1"],["20.5","0.496536","0","2"],["20.26","0.120972","0","1"],["20","8.806993","0","10"],["19.83","0.402789","0","1"],["19.07","0.402789","0","1"],["19","13.543539","0","2"],["18.68","120.371726","0","1"],["18.31","0.402789","0","1"],["18.19","0.1","0","1"],["18","71.777863","0","1"],["17.56","91.518962","0","2"],["16.8","0.402789","0","1"],["16.05","0.402789","0","1"],["16","3","0","1"],["15.29","0.402789","0","1"],["15.16","2","0","1"],["15.1","150","0","1"],["15","295.393085","0","6"],["14.53","0.402789","0","1"],["14.28","1.29007","0","1"],["13.8","50.724637","0","1"],["13.78","0.402789","0","1"],["13.02","0.402789","0","1"],["13","17.640276","0","1"],["12.3","0.813008","0","1"],["12.26","0.402789","0","1"],["12","10","0","1"],["11.6","115.517241","0","2"],["11.51","0.402789","0","1"],["10.75","0.402789","0","1"],["10","38.01249","0","5"],["9.99","10","0","1"],["8.49","0.294464","0","1"],["7","3.51009","0","1"],["5.61","1.782531","0","1"],["5","1","0","1"],["1.33","970","0","1"],["0.5","79.548757","0","1"],["0.1","15","0","2"],["0.06","0.06","0","1"],["0.05","1.16","0","12"],["0.01","100","0","1"]],"ts":"1646003667558","checksum":668652066}]}
1646003668.0925581: {"arg":{"channel":"books-l2-tbt","instId":"ETH-USD-220624-12000-P"},"action":"snapshot","data":[{"asks":[["4.0435","201","0","1"]],"bids":[["2.595","201","0","1"]],"ts":"1646003663779","checksum":1172727943}]}
1646003668.092596: {"arg":{"channel":"books-l2-tbt","instId":"ETH-USD-220325-8800-P"},"action":"snapshot","data":[{"asks":[["2.548","201","0","1"]],"bids":[["2.201","201","0","1"]],"ts":"1646003664198","checksum":75030794}]}
1646003668.092895: {"arg":{"channel":"books-l2-tbt","instId":"UNI-USD-SWAP"},"action":"snapshot","data":[{"asks":[["9.627","348","0","2"],["9.632","3","0","1"],["9.633","1001","0","1"],["9.635","175","0","3"],["9.636","242","0","2"],["9.638","44","0","2"],["9.639","123","0","1"],["9.64","259","0","2"],["9.641","573","0","4"],["9.642","143","0","1"],["9.643","28","0","1"],["9.644","414","0","1"],["9.645","777","0","4"],["9.646","16","0","1"],["9.647","2712","0","5"],["9.648","2065","0","3"],["9.649","1230","0","2"],["9.65","224","0","2"],["9.651","80","0","2"],["9.653","35","0","1"],["9.655","9245","0","1"],["9.656","124","0","1"],["9.662","225","0","1"],["9.663","1754","0","3"],["9.664","64","0","1"],["9.668","510","0","1"],["9.67","16","0","1"],["9.671","846","0","1"],["9.672","44","0","1"],["9.68","15147","0","1"],["9.682","160","0","1"],["9.704","160","0","1"],["9.712","43","0","1"],["9.728","846","0","1"],["9.734","240","0","1"],["9.746","6412","0","1"],["9.75","19","0","1"],["9.76","19","0","1"],["9.762","240","0","1"],["9.768","23","0","1"],["9.77","29","0","1"],["9.787","846","0","1"],["9.789","15141","0","1"],["9.791","2127","0","1"],["9.796","320","0","1"],["9.8","19","0","1"],["9.82","19","0","1"],["9.84","19","0","1"],["9.85","320","0","1"],["9.855","20","0","1"],["9.86","22","0","1"],["9.863","2090","0","1"],["9.917","2133","0","1"],["9.943","10","0","1"],["9.989","2185","0","1"],["10.032","26","0","1"],["10.088","2096","0","1"],["10.102","2","0","1"],["10.122","22","0","1"],["10.146","6","0","1"],["10.166","10","0","1"],["10.2","163","0","4"],["10.213","20","0","1"],["10.222","10","0","1"],["10.259","15","0","1"],["10.3","135","0","3"],["10.304","28","0","1"],["10.338","5","0","1"],["10.38","2","0","1"],["10.396","26","0","1"],["10.4","12","0","2"],["10.417","159","0","1"],["10.433","5","0","1"],["10.489","25","0","1"],["10.5","122","0","3"],["10.55","50","0","1"],["10.56","1","0","1"],["10.575","5","0","1"],["10.6","202","0","2"],["10.666","2133","0","1"],["10.7","52","0","2"],["10.733","31","0","1"],["10.8","2","0","1"],["10.9","2","0","1"],["10.936","1","0","1"],["10.98","92","0","1"],["11","78","0","3"],["11.088","1","0","1"],["11.6","3","0","1"],["11.642","1","0","1"],["11.7","3","0","1"],["11.8","3","0","1"],["11.82","1","0","1"],["11.9","3","0","1"],["11.989","38","0","1"],["12","9","0","2"],["12.1","3","0","1"],["12.2","3","0","1"],["12.224","1","0","1"],["12.281","1526","0","1"],["12.3","4","0","2"],["12.4","3","0","1"],["12.5","3","0","1"],["12.6","3","0","1"],["12.7","3","0","1"],["12.75","1","0","1"],["12.8","3","0","1"],["12.835","1","0","1"],["12.9","3","0","1"],["12.96","10","0","1"],["13","3","0","1"],["13.1","3","0","1"],["13.121","169","0","1"],["13.2","3","0","1"],["13.3","3","0","1"],["13.4","4","0","1"],["13.5","4","0","1"],["13.6","4","0","1"],["13.7","4","0","1"],["13.707","221","0","1"],["13.8","4","0","1"],["13.9","4","0","1"],["13.975","111","0","1"],["14","4","0","1"],["14.1","4","0","1"],["14.2","4","0","1"],["14.3","4","0","1"],["14.4","4","0","1"],["14.436","1","0","1"],["14.5","4","0","1"],["14.51","1","0","1"],["14.587","1","0","1"],["14.6","4","0","1"],["14.66","1","0","1"],["14.7","4","0","1"],["14.736","1","0","1"],["14.8","4","0","1"],["14.81","1","0","1"],["14.896","1","0","1"],["14.9","4","0","1"],["15","213","0","3"],["15.011","1","0","1"],["15.075","1","0","1"],["15.1","4","0","1"],["15.144","1","0","1"],["15.2","4","0","1"],["15.234","1","0","1"],["15.3","4","0","1"],["15.31","1","0","1"],["15.4","4","0","1"],["15.432","1","0","1"],["15.5","4","0","1"],["15.514","1","0","1"],["15.574","1","0","1"],["15.6","4","0","1"],["15.652","1","0","1"],["15.7","4","0","1"],["15.732","1","0","1"],["15.8","4","0","1"],["15.81","1","0","1"],["15.88","1","0","1"],["15.888","1","0","1"],["15.9","4","0","1"],["15.963","1","0","1"],["16","420","0","2"],["16.035","1","0","1"],["16.1","4","0","1"],["16.117","1","0","1"],["16.2","4","0","1"],["16.211","1","0","1"],["16.241","1","0","1"],["16.3","4","0","1"],["16.314","1","0","1"],["16.323","1","0","1"],["16.329","1","0","1"],["16.395","1","0","1"],["16.4","4","0","1"],["16.404","1","0","1"],["16.452","1","0","1"],["16.477","1","0","1"],["16.486","1","0","1"],["16.5","4","0","1"],["16.523","1","0","1"],["16.569","1","0","1"],["16.6","4","0","1"],["16.61","1","0","1"],["16.7","5","0","1"],["16.729","1","0","1"],["16.8","5","0","1"],["16.829","1","0","1"],["16.898","1","0","1"],["16.9","5","0","1"],["16.975","1","0","1"],["17","5","0","1"],["17.06","84","0","1"],["17.079","1","0","1"],["17.1","5","0","1"],["17.154","1","0","1"],["17.2","5","0","1"],["17.3","5","0","1"],["17.4","45","0","2"],["17.5","5","0","1"],["17.6","5","0","1"],["17.7","5","0","1"],["17.8","5","0","1"],["17.9","5","0","1"],["18","125","0","3"],["18.1","5","0","1"],["18.176","166","0","1"],["18.2","5","0","1"],["18.215","1","0","1"],["18.3","5","0","1"],["18.4","5","0","1"],["18.5","5","0","1"],["18.6","5","0","1"],["18.7","5","0","1"],["18.8","5","0","1"],["18.9","5","0","1"],["18.954","1","0","1"],["19","5","0","1"],["19.1","4","0","1"],["19.111","1","0","1"],["19.6","30","0","1"],["19.631","1","0","1"],["19.93","166","0","1"],["19.953","1","0","1"],["20","10","0","1"],["20.216","1","0","1"],["20.348","1","0","1"],["20.437","1","0","1"],["20.583","1","0","1"],["20.686","1","0","1"],["20.791","1","0","1"],["20.9","1","0","1"],["21.018","1","0","1"],["21.125","1","0","1"],["21.185","1","0","1"],["21.327","1","0","1"],["21.412","1","0","1"],["21.438","1","0","1"],["21.519","1","0","1"],["21.547","1","0","1"],["21.627","1","0","1"],["21.654","1","0","1"],["21.735","1","0","1"],["21.781","1","0","1"],["21.828","88","0","1"],["21.843","1","0","1"],["21.957","1","0","1"],["22.057","1","0","1"],["22.169","1","0","1"],["22.3","1","0","1"],["22.378","1","0","1"],["22.401","1","0","1"],["22.489","1","0","1"],["22.509","1","0","1"],["22.602","1","0","1"],["22.615","1","0","1"],["22.715","1","0","1"],["22.925","1","0","1"],["23.082","1","0","1"],["23.194","1","0","1"],["23.31","1","0","1"],["23.427","1","0","1"],["23.538","1","0","1"],["23.636","1","0","1"],["23.746","1","0","1"],["23.866","1","0","1"],["23.985","1","0","1"],["24.106","1","0","1"],["24.228","1","0","1"],["24.374","1","0","1"],["24.447","1","0","1"],["24.463","1","0","1"],["24.482","1","0","1"],["24.55","1","0","1"],["24.569","1","0","1"],["24.586","1","0","1"],["24.605","1","0","1"],["24.671","1","0","1"],["24.692","1","0","1"],["24.708","1","0","1"],["24.728","1","0","1"],["24.816","1","0","1"],["24.832","1","0","1"],["24.851","1","0","1"],["24.94","1","0","1"],["24.956","1","0","1"],["24.976","1","0","1"],["28.501","1","0","1"],["28.646","1","0","1"],["28.792","1","0","1"],["28.938","1","0","1"],["29.086","1","0","1"],["29.234","1","0","1"],["29.383","1","0","1"],["29.53","1","0","1"],["29.677","1","0","1"],["29.826","1","0","1"],["29.975","1","0","1"],["30","94","0","1"],["30.125","1","0","1"],["30.275","1","0","1"],["30.427","1","0","1"],["30.579","1","0","1"],["30.732","1","0","1"],["30.885","1","0","1"],["31.04","1","0","1"],["31.195","1","0","1"],["31.351","1","0","1"],["31.508","1","0","1"],["31.665","1","0","1"],["31.823","1","0","1"],["31.983","1","0","1"],["32","219","0","1"],["32.143","1","0","1"],["32.303","1","0","1"],["32.465","1","0","1"],["32.627","1","0","1"],["32.79","1","0","1"],["32.954","1","0","1"],["33.119","1","0","1"],["33.285","1","0","1"],["33.451","1","0","1"],["33.618","1","0","1"],["33.786","1","0","1"],["33.955","1","0","1"],["34.125","1","0","1"],["34.296","1","0","1"],["34.467","1","0","1"],["34.639","1","0","1"],["34.813","1","0","1"],["34.987","1","0","1"],["35.162","1","0","1"],["35.337","1","0","1"],["35.514","1","0","1"],["35.692","1","0","1"],["35.87","1","0","1"],["36.049","1","0","1"],["36.23","1","0","1"],["36.411","1","0","1"],["36.593","1","0","1"],["36.776","1","0","1"],["36.96","2","0","2"],["37.145","1","0","1"],["37.33","1","0","1"],["37.517","1","0","1"],["37.704","1","0","1"],["37.893","1","0","1"],["38.082","1","0","1"],["38.273","1","0","1"],["38.464","1","0","1"],["38.657","1","0","1"],["38.85","1","0","1"],["39.044","1","0","1"],["39.239","1","0","1"],["39.435","1","0","1"],["39.633","1","0","1"],["39.831","1","0","1"],["40","154","0","1"],["40.03","1","0","1"],["40.23","1","0","1"],["40.431","1","0","1"],["40.633","1","0","1"],["40.837","1","0","1"],["41.041","1","0","1"],["41.246","1","0","1"],["41.452","1","0","1"],["41.659","1","0","1"],["41.868","1","0","1"],["42.077","1","0","1"],["42.287","1","0","1"],["42.499","1","0","1"],["42.711","1","0","1"],["42.925","1","0","1"],["43.14","1","0","1"],["43.355","1","0","1"],["43.572","1","0","1"],["43.79","1","0","1"],["44.009","1","0","1"],["44.229","1","0","1"],["44.45","1","0","1"],["44.672","1","0","1"],["44.896","1","0","1"],["45.12","1","0","1"],["45.346","1","0","1"],["45.572","1","0","1"],["45.8","1","0","1"],["46.029","1","0","1"],["46.259","1","0","1"],["46.491","1","0","1"],["46.723","1","0","1"],["46.957","1","0","1"],["47.192","1","0","1"],["47.428","1","0","1"],["47.665","1","0","1"],["47.903","1","0","1"],["48.143","1","0","1"],["48.383","1","0","1"],["48.625","1","0","1"]],"bids":[["9.619","282","0","2"],["9.618","109","0","1"],["9.617","388","0","3"],["9.616","12","0","1"],["9.614","1","0","1"],["9.613","18","0","2"],["9.61","11","0","1"],["9.607","500","0","1"],["9.606","80","0","1"],["9.605","56","0","2"],["9.604","317","0","2"],["9.603","1271","0","2"],["9.6","196","0","3"],["9.599","620","0","2"],["9.596","143","0","1"],["9.594","399","0","4"],["9.592","246","0","4"],["9.591","16","0","1"],["9.59","1548","0","3"],["9.588","125","0","1"],["9.586","142","0","1"],["9.585","9589","0","2"],["9.583","160","0","1"],["9.582","634","0","2"],["9.581","68","0","1"],["9.579","738","0","4"],["9.578","64","0","1"],["9.577","1574","0","1"],["9.576","1052","0","1"],["9.573","4","0","1"],["9.572","332","0","1"],["9.568","846","0","1"],["9.567","2124","0","1"],["9.552","58","0","1"],["9.55","19","0","1"],["9.544","160","0","1"],["9.535","160","0","1"],["9.524","14969","0","1"],["9.509","846","0","1"],["9.502","2","0","1"],["9.501","240","0","1"],["9.5","49","0","2"],["9.492","70","0","1"],["9.491","6319","0","1"],["9.467","240","0","1"],["9.449","846","0","1"],["9.444","2183","0","1"],["9.428","320","0","1"],["9.409","15","0","1"],["9.408","13508","0","1"],["9.4","58","0","2"],["9.378","320","0","1"],["9.369","2076","0","1"],["9.34","2099","0","1"],["9.325","18","0","1"],["9.3","80","0","3"],["9.298","40","0","1"],["9.242","23","0","1"],["9.232","200","0","1"],["9.229","5","0","1"],["9.21","40","0","1"],["9.2","57","0","2"],["9.19","10","0","1"],["9.159","25","0","1"],["9.146","2164","0","1"],["9.129","5","0","1"],["9.107","40","0","1"],["9.1","69","0","2"],["9.09","10","0","1"],["9.082","1","0","1"],["9.08","272","0","1"],["9.077","19","0","1"],["9.066","40","0","1"],["9.029","5","0","1"],["9.026","2111","0","1"],["9","57","0","2"],["8.997","40","0","1"],["8.996","940","0","2"],["8.99","10","0","1"],["8.929","5","0","1"],["8.924","40","0","1"],["8.916","14","0","1"],["8.9","30","0","1"],["8.89","10","0","1"],["8.839","40","0","1"],["8.836","23","0","1"],["8.8","30","0","1"],["8.79","10","0","1"],["8.78","1671","0","1"],["8.772","40","0","1"],["8.757","13","0","1"],["8.7","30","0","1"],["8.65","4","0","1"],["8.628","1","0","1"],["8.6","30","0","1"],["8.596","40","0","1"],["8.5","65","0","3"],["8.462","5","0","1"],["8.43","300","0","1"],["8.4","30","0","1"],["8.39","5","0","1"],["8.3","12","0","1"],["8.28","1","0","1"],["8.2","1","0","1"],["8.197","1","0","1"],["8.15","21","0","1"],["8.1","370","0","1"],["8.088","5","0","1"],["8.01","7","0","1"],["8","55","0","4"],["7.99","5","0","1"],["7.988","5","0","1"],["7.82","10","0","1"],["7.8","159","0","2"],["7.788","6","0","2"],["7.704","191","0","1"],["7.7","10","0","1"],["7.688","5","0","1"],["7.65","114","0","1"],["7.6","10","0","1"],["7.59","600","0","1"],["7.588","5","0","1"],["7.58","37","0","1"],["7.555","18","0","1"],["7.547","150","0","1"],["7.52","2","0","1"],["7.5","23","0","2"],["7.41","24","0","1"],["7.4","15","0","1"],["7.399","1","0","1"],["7.36","10","0","1"],["7.232","144","0","1"],["7.223","2","0","1"],["7.18","5","0","1"],["7.1","14","0","1"],["7.055","20","0","1"],["7","338","0","3"],["6.8","5","0","3"],["6.75","1","0","1"],["6.6","2","0","1"],["6.545","501","0","1"],["6.5","1","0","1"],["6.18","12","0","1"],["6.12","12","0","1"],["6.1","2","0","1"],["6","1686","0","3"],["5.64","10","0","1"],["5.5","2","0","1"],["5","297","0","1"],["4.688","101","0","1"],["4.444","1974","0","1"],["4.323","216","0","1"],["4.219","2","0","1"],["3.65","127","0","1"],["3.6","1","0","1"],["3.438","75","0","2"],["3.028","612","0","1"],["1.23","42","0","1"]],"ts":"1646003667620","checksum":752109140}]}
1646003668.0941749: {"arg":{"channel":"books-l2-tbt","instId":"ETH-USD-220325-8800-P"},"action":"snapshot","data":[{"asks":[["2.548","201","0","1"]],"bids":[["2.201","201","0","1"]],"ts":"1646003664198","checksum":75030794}]}
1646003668.384716: {"arg":{"channel":"books-l2-tbt","instId":"ELON-USDT"},"action":"snapshot","data":[{"asks":[["0.00000074528","159764443","0","2"],["0.00000074529","526402122","0","2"],["0.00000074533","130685482","0","3"],["0.0000007459","2684143825","0","2"],["0.00000074615","496917766","0","1"],["0.00000074659","4038943392","0","1"],["0.0000007466","698000000","0","1"],["0.0000007468","698000000","0","1"],["0.00000074703","1074799314","0","1"],["0.00000074717","671767622","0","1"],["0.00000074738","3205680429","0","1"],["0.0000007477","691000000","0","1"],["0.00000074794","750000000","0","1"],["0.00000074795","18581929","0","1"],["0.000000748","5134566890","0","4"],["0.00000074841","43910859","0","2"],["0.0000007504","14825409062","0","3"],["0.00000075077","603095914","0","1"],["0.00000075118","6829045","0","1"],["0.00000075165","18490323","0","1"],["0.000000753","16237250","0","2"],["0.00000075491","15308705","0","1"],["0.00000075537","18399370","0","1"],["0.0000007554","1396000000","0","2"],["0.00000075582","43910859","0","2"],["0.00000075664","461795013","0","1"],["0.00000075885","6829045","0","1"],["0.00000075911","18308579","0","1"],["0.00000075919","984203700","0","1"],["0.000000762","16237250","0","2"],["0.00000076239","6145556","0","1"],["0.00000076287","18218439","0","1"],["0.00000076323","43910859","0","2"],["0.00000076457","547843267","0","1"],["0.00000076651","6829045","0","1"],["0.00000076665","18128706","0","1"],["0.00000077044","18039381","0","1"],["0.00000077064","43910859","0","2"],["0.00000077076","6625930","0","1"],["0.000000771","16237250","0","2"],["0.00000077418","6829045","0","1"],["0.00000077426","17950465","0","1"],["0.00000077453","6145556","0","1"],["0.00000077805","43910859","0","2"],["0.00000077809","17862190","0","1"],["0.00000078","16237250","0","2"],["0.00000078184","6829045","0","1"],["0.00000078194","17774092","0","1"],["0.00000078246","124918927","0","1"],["0.00000078581","17686633","0","1"],["0.00000078666","6145556","0","1"],["0.00000078752","6625930","0","1"],["0.000000789","16237250","0","2"],["0.00000078904","373845562","0","1"],["0.00000078951","6829045","0","1"],["0.00000078971","17599356","0","1"],["0.00000079361","17512715","0","1"],["0.00000079549","8368593","0","1"],["0.00000079717","6829045","0","1"],["0.00000079754","17426483","0","1"],["0.000000798","16237250","0","2"],["0.00000079879","6145556","0","1"],["0.0000007993","136937413","0","1"],["0.0000008","25411333","0","2"],["0.00000080149","17340659","0","1"],["0.00000080427","6625930","0","1"],["0.00000080482","275353132","0","1"],["0.00000080484","6829045","0","1"],["0.00000080512","17050757","0","1"],["0.00000080545","17255246","0","1"],["0.000000807","16237250","0","2"],["0.00000080944","17170243","0","1"],["0.00000081","479828093","0","4"],["0.00000081093","6145556","0","1"],["0.000000812","290702923","0","1"],["0.00000081234","528364857","0","1"],["0.00000081345","17085650","0","1"],["0.000000814","20804211","0","1"],["0.000000816","16237250","0","2"],["0.00000081748","17001467","0","1"],["0.000000819","16441155","0","1"],["0.00000082","910021117","0","5"],["0.0000008202","12005857","0","1"],["0.00000082091","181316248","0","1"],["0.00000082103","6625930","0","1"],["0.00000082153","16917696","0","1"],["0.00000082306","6145556","0","1"],["0.000000825","16237250","0","2"],["0.00000082559","16834335","0","1"],["0.00000082967","16751588","0","1"],["0.00000083","1046895326","0","6"],["0.00000083378","16669047","0","1"],["0.000000834","16237250","0","2"],["0.000000835","19610080","0","1"],["0.00000083519","6145556","0","1"],["0.000000836","5980861","0","1"],["0.00000083732","222060909","0","1"],["0.00000083779","6625930","0","1"],["0.00000083791","16586917","0","1"],["0.000000839","21944895","0","1"],["0.00000084","4212026966","0","3"],["0.00000084206","16505197","0","1"],["0.00000084299","1898005907","0","1"],["0.000000843","1811237250","0","6"],["0.000000845","679503139","0","1"],["0.00000084623","16423888","0","1"],["0.00000084733","6145556","0","1"],["0.00000085","487430000","0","2"],["0.00000085041","16342989","0","1"],["0.000000852","16237250","0","2"],["0.00000085406","262020875","0","1"],["0.00000085454","6625930","0","1"],["0.00000085462","16262500","0","1"],["0.000000855","64991051","0","1"],["0.00000085885","16182420","0","1"],["0.00000085946","6145556","0","1"],["0.00000086","41486779","0","2"],["0.000000861","16237250","0","2"],["0.00000086311","16102561","0","1"],["0.00000086593","47078428","0","1"],["0.00000086738","29077974","0","2"],["0.00000086929","40111734","0","1"],["0.00000087","16237250","0","2"],["0.0000008713","6625930","0","1"],["0.00000087159","6145556","0","1"],["0.00000087167","15944448","0","1"],["0.00000087599","15865821","0","1"],["0.000000879","16237250","0","2"],["0.00000088","80913204","0","2"],["0.00000088032","15787785","0","1"],["0.00000088373","6145556","0","1"],["0.00000088468","15709977","0","1"],["0.000000888","33950431","0","3"],["0.00000088805","6625930","0","1"],["0.00000088906","15632577","0","1"],["0.00000089","524044919","0","3"],["0.00000089346","15555586","0","1"],["0.00000089586","6145556","0","1"],["0.000000897","16237250","0","2"],["0.00000089788","15479002","0","1"],["0.00000089838","138048627","0","1"],["0.000000899","124287882","0","1"],["0.0000008998","32604356","0","1"],["0.00000089999","5928210","0","1"],["0.0000009","973626903","0","6"],["0.00000090233","15402653","0","1"],["0.00000090481","6625930","0","1"],["0.000000906","16237250","0","2"],["0.00000090679","15326883","0","1"],["0.00000090724","13358800","0","2"],["0.00000090783","6174344","0","1"],["0.00000090799","6145556","0","1"],["0.00000091128","15251349","0","1"],["0.00000091289","35900750","0","1"],["0.00000091391","13358800","0","2"],["0.000000915","16237250","0","2"],["0.00000091573","6174344","0","1"],["0.0000009158","15176223","0","1"],["0.000000918","36413508","0","1"],["0.00000092","59945669","0","2"],["0.00000092013","6145556","0","1"],["0.00000092033","15101502","0","1"],["0.00000092058","13358800","0","2"],["0.00000092115","75754272","0","1"],["0.00000092157","6625930","0","1"],["0.0000009237","6174344","0","1"],["0.000000924","16237250","0","2"],["0.00000092489","15027023","0","1"],["0.0000009271","35900750","0","1"],["0.00000092725","13358800","0","2"],["0.00000092787","15825768","0","1"],["0.00000092947","14952951","0","1"],["0.00000093","353995922","0","2"],["0.00000093173","6174344","0","1"],["0.00000093226","6145556","0","1"],["0.000000933","16237250","0","2"],["0.00000093392","13358800","0","2"],["0.00000093406","14879446","0","1"],["0.00000093421","35900750","0","1"],["0.00000093754","15825768","0","1"],["0.00000093869","14806024","0","1"],["0.00000093984","6174344","0","1"],["0.00000094","400000000","0","1"],["0.00000094059","13358800","0","2"],["0.00000094131","35900750","0","1"],["0.000000942","16237250","0","2"],["0.00000094334","14733165","0","1"],["0.00000094439","6145556","0","1"],["0.00000094499","160433622","0","2"],["0.000000945","37499214520","0","1"],["0.00000094679","10122765","0","1"],["0.0000009472","15825768","0","1"],["0.00000094726","13358800","0","2"],["0.00000094801","14660553","0","1"],["0.00000094802","6174344","0","1"],["0.0000009484","199032795","0","1"],["0.00000094842","35900750","0","1"],["0.00000094993","11705727","0","1"],["0.00000095","2273468914","0","5"],["0.000000951","16237250","0","2"],["0.0000009525","26109346","0","1"],["0.0000009527","14588345","0","1"],["0.00000095393","13358800","0","2"],["0.00000095552","35900750","0","1"],["0.00000095627","6174344","0","1"],["0.00000095653","6145556","0","1"],["0.00000095687","15825768","0","1"],["0.00000095741","14516540","0","1"],["0.00000096","216237250","0","3"],["0.0000009606","13358800","0","2"],["0.00000096216","14444984","0","1"],["0.00000096263","4597750","0","1"],["0.00000096459","6174344","0","1"],["0.00000096653","15825768","0","1"],["0.00000096692","14373831","0","1"],["0.00000096728","13358800","0","2"],["0.00000096866","6145556","0","1"],["0.000000969","16237250","0","2"],["0.00000096973","35900750","0","1"],["0.0000009717","14303079","0","1"],["0.000000972","5175138","0","1"],["0.00000097299","6174344","0","1"],["0.00000097395","13358800","0","2"],["0.0000009762","15825768","0","1"],["0.00000097652","14232580","0","1"],["0.00000097684","35900750","0","1"],["0.000000978","16237250","0","2"],["0.00000098","1419271045","0","3"],["0.00000098062","13358800","0","2"],["0.00000098079","6145556","0","1"],["0.00000098135","14162482","0","1"],["0.00000098145","6174344","0","1"],["0.00000098394","35900750","0","1"],["0.00000098586","15825768","0","1"],["0.00000098621","14092639","0","1"],["0.000000987","16237250","0","2"],["0.00000098708","10122765","0","1"],["0.00000098729","13358800","0","2"],["0.00000098738","13054674","0","1"],["0.00000098916","100000000","0","1"],["0.00000098999","6174344","0","1"],["0.00000099","950214155","0","2"],["0.00000099105","35900750","0","1"],["0.00000099109","14023339","0","1"],["0.00000099293","6145556","0","1"],["0.00000099396","13358800","0","2"],["0.00000099553","15825768","0","1"],["0.000000996","30191403","0","3"],["0.00000099815","35900750","0","1"],["0.00000099861","6174344","0","1"],["0.000000999","8008008","0","1"],["0.000001","1901546777","0","13"],["0.00000100063","13358800","0","2"],["0.00000100092","13885507","0","1"],["0.000001002","1375185419","0","1"],["0.00000100382","1394672351","0","1"],["0.000001004","5175138","0","1"],["0.000001005","16237250","0","2"],["0.00000100506","6145556","0","1"],["0.00000100519","15825768","0","1"],["0.00000100526","35900750","0","1"],["0.00000100588","13817117","0","1"],["0.00000100648","306808450","0","1"],["0.0000010073","19533144","0","3"],["0.00000101","34211209","0","2"],["0.00000101086","13748988","0","1"],["0.00000101236","35900750","0","1"],["0.00000101397","13358800","0","2"],["0.000001014","16237250","0","2"],["0.00000101486","15825768","0","1"],["0.00000101587","13681255","0","1"],["0.00000101606","6174344","0","1"],["0.00000101719","6145556","0","1"],["0.00000101947","10011164","0","1"],["0.00000102","1036814373","0","2"],["0.00000102064","13358800","0","2"],["0.00000102089","8167641","0","1"],["0.000001022","5870841","0","1"],["0.0000010221","11618604","0","1"],["0.000001023","16237250","0","2"],["0.0000010249","6174344","0","1"],["0.00000102595","13546842","0","1"],["0.00000102657","35900750","0","1"],["0.00000102731","13358800","0","2"],["0.00000102737","10122765","0","1"],["0.00000102933","6145556","0","1"],["0.00000103","118562045","0","1"],["0.00000103102","13480161","0","1"],["0.000001032","16237250","0","2"],["0.00000103368","35900750","0","1"],["0.00000103382","6179288","0","1"],["0.00000103399","13358800","0","2"],["0.000001036","5174102","0","1"],["0.00000103613","13413741","0","1"],["0.00000104","424044919","0","2"],["0.00000104066","13358800","0","2"],["0.00000104078","35900750","0","1"],["0.000001041","16237250","0","2"],["0.00000104126","13347585","0","1"],["0.00000104146","6145556","0","1"],["0.00000104282","6179288","0","1"],["0.00000104388","25120293","0","1"],["0.00000104419","11367496","0","1"],["0.00000104641","13281952","0","1"],["0.00000104733","13358800","0","2"],["0.00000104789","35900750","0","1"],["0.00000105","73735670","0","5"],["0.00000105159","13216454","0","1"],["0.00000105189","6179288","0","1"],["0.00000105333","8116225","0","1"],["0.00000105359","6145556","0","1"],["0.000001054","13358800","0","2"],["0.000001055","35900750","0","1"],["0.0000010568","13151348","0","1"],["0.000001059","16237250","0","2"],["0.00000106","172900187","0","1"],["0.00000106067","13358800","0","2"],["0.00000106105","6179288","0","1"],["0.00000106139","24705905","0","1"],["0.00000106203","13086632","0","1"],["0.0000010621","35900750","0","1"],["0.00000106573","6145556","0","1"],["0.00000106628","11127013","0","1"],["0.00000106729","13022059","0","1"],["0.00000106734","13358800","0","2"],["0.00000106766","10122765","0","1"],["0.000001068","21411352","0","3"],["0.00000106921","35900750","0","1"],["0.00000107","24044919","0","1"],["0.00000107028","6179288","0","1"],["0.00000107258","12957877","0","1"],["0.00000107401","13356126","0","2"],["0.0000010752","5358018","0","1"],["0.00000107631","35900750","0","1"],["0.000001077","16237250","0","2"],["0.00000107786","6145556","0","1"],["0.00000107789","12893963","0","1"],["0.00000107839","5089601","0","1"],["0.00000107919","24298326","0","1"],["0.0000010796","6179288","0","1"],["0.00000108068","13356126","0","2"],["0.00000108323","12830437","0","1"],["0.00000108342","35900750","0","1"],["0.000001085","10078318040","0","1"],["0.00000108511","9215655","0","1"],["0.000001086","16237250","0","2"],["0.00000108685","26651445","0","1"],["0.00000108735","13356126","0","2"],["0.00000108837","10896494","0","1"],["0.0000010886","12767181","0","1"],["0.00000108899","6179288","0","1"],["0.00000108974","807975188","0","1"],["0.00000108999","6145556","0","1"],["0.00000109","585198897","0","3"],["0.00000109052","35900750","0","1"],["0.000001094","12704194","0","1"],["0.00000109402","13356126","0","2"],["0.000001095","16237250","0","2"],["0.00000109729","23897553","0","1"],["0.00000109763","35900750","0","1"],["0.00000109847","6179288","0","1"],["0.00000109941","12641594","0","1"],["0.0000011","627620400","0","13"],["0.0000011007","13356126","0","2"],["0.00000110213","6145556","0","1"],["0.000001104","16237250","0","2"],["0.00000110473","30138000","0","1"],["0.00000110486","12579264","0","1"],["0.00000110637","5262112","0","1"],["0.00000110666","8116225","0","1"],["0.00000110795","10122765","0","1"],["0.00000110802","6179288","0","1"],["0.00000111","743452384","0","1"],["0.00000111034","12517205","0","1"],["0.00000111047","10675234","0","1"],["0.00000111184","35900750","0","1"],["0.00000111278","5262112","0","1"],["0.000001113","16237250","0","2"],["0.00000111426","6145556","0","1"],["0.00000111569","23503358","0","1"],["0.00000111584","12455530","0","1"],["0.00000111767","6179288","0","1"],["0.00000111894","35900750","0","1"],["0.00000111922","5262112","0","1"],["0.00000112","116219954","0","1"],["0.00000112136","12394127","0","1"],["0.000001122","16237250","0","2"],["0.00000112571","5262112","0","1"],["0.00000112605","35900750","0","1"],["0.00000112639","6145556","0","1"],["0.00000112692","12332995","0","1"],["0.00000112739","6179288","0","1"],["0.00000112888","287087435","0","1"],["0.00000113","89355188","0","1"],["0.000001131","16237250","0","2"],["0.00000113223","5262112","0","1"],["0.00000113251","12272136","0","1"],["0.00000113256","10462875","0","1"],["0.00000113315","35900750","0","1"],["0.0000011338","129154981","0","1"]],"bids":[["0.00000074351","184440410","0","1"],["0.0000007435","219861835","0","1"],["0.0000007433","1006570154","0","1"],["0.0000007432","1677286721","0","1"],["0.00000074262","4038943392","0","1"],["0.00000074255","497034584","0","1"],["0.00000074243","672074627","0","1"],["0.00000074236","1074229240","0","1"],["0.000000742","3205680429","0","1"],["0.0000007413","3354545575","0","1"],["0.000000741","2209824531","0","2"],["0.00000073913","18673943","0","1"],["0.000000739","516000000","0","1"],["0.0000007388","30281128","0","1"],["0.00000073813","6150477","0","1"],["0.00000073801","160433622","0","2"],["0.000000738","16555352866","0","4"],["0.000000737","1982000000","0","3"],["0.0000007369","14110493714","0","2"],["0.00000073585","6834513","0","1"],["0.000000735","16250252","0","2"],["0.00000073447","1041756730","0","1"],["0.00000073359","43946017","0","2"],["0.000000733","7204113808","0","3"],["0.00000073245","642765243","0","1"],["0.00000072819","226694713","0","3"],["0.00000072786","10000000","0","1"],["0.00000072748","785570734","0","1"],["0.0000007273","401520460","0","1"],["0.00000072647","272977721","0","3"],["0.00000072618","324868101","0","4"],["0.000000726","1671400677","0","4"],["0.00000072599","6150477","0","1"],["0.00000072509","187397427","0","2"],["0.0000007231","573563825","0","2"],["0.00000072304","5532217","0","1"],["0.000000721","170596393","0","1"],["0.00000072","2160884396","0","5"],["0.00000071888","646839527","0","2"],["0.00000071877","217854221","0","3"],["0.000000717","120852762","0","3"],["0.00000071386","869204855","0","7"],["0.00000071188","123615597","0","2"],["0.00000071136","43946017","0","2"],["0.00000071092","165981033","0","1"],["0.00000071","200000000","0","1"],["0.000000708","157493189","0","3"],["0.00000070664","189627650","0","1"],["0.00000070565","144547580","0","1"],["0.00000070556","190260455","0","1"],["0.0000007045","7541376","0","1"],["0.00000070395","43946017","0","2"],["0.00000070376","96622496","0","1"],["0.00000070254","229914578","0","1"],["0.00000070211","56970634","0","1"],["0.000000702","1833171876","0","1"],["0.00000070175","320629290","0","1"],["0.00000070173","6150477","0","1"],["0.0000007","1020709885","0","9"],["0.00000069901","42917840","0","1"],["0.000000699","16250252","0","2"],["0.00000069823","80202568","0","1"],["0.0000006964","646184963","0","1"],["0.00000069503","92082058","0","1"],["0.00000069481","102185870","0","1"],["0.00000069463","166993082","0","1"],["0.00000069123","5786785","0","1"],["0.00000069","16250252","0","2"],["0.00000068959","6150477","0","1"],["0.0000006888","7259001","0","1"],["0.00000068849","217972839","0","1"],["0.00000068691","199442652","0","1"],["0.000000681","16250252","0","2"],["0.00000067746","6150477","0","1"],["0.00000067473","156145125","0","1"],["0.000000672","16250252","0","2"],["0.00000067032","44754744","0","1"],["0.000000668","29940119","0","1"],["0.00000066775","190000000","0","1"],["0.00000066735","71925305","0","1"],["0.00000066533","6150477","0","1"],["0.000000663","16250252","0","2"],["0.00000066124","241154312","0","1"],["0.00000066","291127080","0","2"],["0.0000006587","45544253","0","1"],["0.000000656","3635395214","0","1"],["0.0000006556","8620054","0","1"],["0.000000654","16250252","0","2"],["0.00000065319","6150477","0","1"],["0.00000065048","152292864","0","1"],["0.00000065","2568520719","0","4"],["0.0000006487","46246338","0","1"],["0.0000006471","583576936","0","1"],["0.000000645","16250252","0","2"],["0.00000064106","6150477","0","1"],["0.00000064","117187500","0","2"],["0.000000636","16250252","0","2"],["0.0000006358","11009751","0","1"],["0.00000063401","7886310","0","1"],["0.00000063","2164891080","0","4"],["0.00000062893","6150477","0","1"],["0.000000627","16250252","0","2"],["0.00000062568","40000000","0","1"],["0.000000625","505600000","0","2"],["0.00000062225","101306440","0","1"],["0.000000622","281350482","0","2"],["0.00000062111","186279403","0","1"],["0.00000062","3013259193","0","8"],["0.000000618","105247015","0","3"],["0.00000061688","20000000","0","1"],["0.00000061679","6150477","0","1"],["0.000000615","89430894","0","1"],["0.000000612","89869281","0","1"],["0.00000061","9020221017","0","5"],["0.000000609","16250252","0","2"],["0.00000060888","125458894","0","1"],["0.00000060466","6150477","0","1"],["0.0000006012","628131463","0","1"],["0.00000060118","45164319","0","1"],["0.0000006","2815862062","0","24"],["0.00000059253","6150477","0","1"],["0.000000591","16250252","0","2"],["0.00000059","33050860","0","1"],["0.000000588","394976377","0","1"],["0.00000058619","9433118","0","1"],["0.000000582","16250252","0","2"],["0.00000058039","6150477","0","1"],["0.00000057362","16108224","0","1"],["0.0000005735","87183958","0","1"],["0.000000573","16250252","0","2"],["0.00000056826","6150477","0","1"],["0.000000566","176678445","0","1"],["0.000000565","167696945","0","1"],["0.000000564","16250252","0","2"],["0.00000056","17884419642","0","2"],["0.000000558","5000000","0","1"],["0.00000055613","6150477","0","1"],["0.000000556","16720919","0","1"],["0.00000055555","543408875","0","4"],["0.000000555","16250252","0","2"],["0.0000005543","8792348","0","1"],["0.0000005532","400178009","0","1"],["0.000000553","100000000","0","1"],["0.00000055167","20000000","0","1"],["0.00000055131","18138615","0","1"],["0.00000055","27621355578","0","2"],["0.000000546","16250252","0","2"],["0.00000054399","6150477","0","1"],["0.00000054","59259259","0","2"],["0.000000537","16250252","0","2"],["0.00000053186","6150477","0","1"],["0.00000053","144531312","0","2"],["0.000000528","16250252","0","2"],["0.00000052668","18986861","0","1"],["0.00000052555","39768095","0","1"],["0.000000523","13384325","0","1"],["0.0000005219","10000000","0","2"],["0.00000052","1502744941","0","3"],["0.00000051973","6150477","0","1"],["0.000000519","16250252","0","2"],["0.00000051895","59736544","0","1"],["0.0000005185","57859209","0","1"],["0.00000051779","90677660","0","1"],["0.000000512","20000000","0","1"],["0.00000051","31915296336","0","13"],["0.000000509","19646365","0","1"],["0.00000050888","19650998","0","1"],["0.000000508","31496062","0","1"],["0.00000050759","6150477","0","1"],["0.000000505","50000000","0","1"],["0.000000502","10956175","0","1"],["0.00000050185","19926272","0","1"],["0.0000005017","43096062","0","2"],["0.00000050112","19955300127","0","1"],["0.000000501","1558612534","0","4"],["0.0000005005","239760239","0","1"],["0.00000050011","9000000","0","1"],["0.00000050001","5999880","0","1"],["0.0000005","4238538410","0","44"],["0.00000049546","6150477","0","1"],["0.000000492","16250252","0","2"],["0.00000049","22448979","0","1"],["0.00000048333","6150477","0","1"],["0.000000483","636259661","0","3"],["0.00000048","12914670","0","1"],["0.00000047954","5412025","0","1"],["0.000000474","22839651","0","3"],["0.00000047119","6150477","0","1"],["0.00000046685","6426046","0","1"],["0.000000465","16250252","0","2"],["0.00000046","63401642","0","1"],["0.00000045906","6150477","0","1"],["0.00000045686","109442717","0","1"],["0.000000456","16250252","0","2"],["0.00000045414","19778630","0","1"],["0.00000045","58396676","0","3"],["0.0000004486","173060633","0","1"],["0.000000447","16250252","0","2"],["0.00000044693","6150477","0","1"],["0.000000438","16250252","0","2"],["0.00000043479","6150477","0","1"],["0.00000043","30649610","0","1"],["0.000000429","16250252","0","2"],["0.00000042671","5000000","0","1"],["0.00000042668","23436767","0","1"],["0.000000423","28368794","0","1"],["0.00000042266","6150477","0","1"],["0.0000004212","12000000","0","1"],["0.00000042","94612296","0","5"],["0.000000419","655284189","0","1"],["0.000000413","10689883","0","1"],["0.000000411","16250252","0","2"],["0.00000041053","6150477","0","1"],["0.00000041","640306419","0","2"],["0.000000402","16250252","0","2"],["0.00000040012","90000000","0","1"],["0.0000004","6313625908","0","17"],["0.00000039839","6150477","0","1"],["0.000000393","16250252","0","2"],["0.00000038626","6150477","0","1"],["0.000000384","16250252","0","2"],["0.0000003756","108869679","0","1"],["0.000000375","16250252","0","2"],["0.00000037413","6150477","0","1"],["0.000000366","16250252","0","2"],["0.00000036199","6150477","0","1"],["0.00000036","783774103","0","1"],["0.000000357","16250252","0","2"],["0.00000035","50000000","0","1"],["0.00000034986","6150477","0","1"],["0.000000348","16250252","0","2"],["0.000000339","16250252","0","2"],["0.00000033773","6150477","0","1"],["0.00000033","4716631189","0","3"],["0.00000032668","30610995","0","1"],["0.00000032559","6150477","0","1"],["0.000000321","22480781","0","3"],["0.00000032","1387313576","0","1"],["0.00000031346","6150477","0","1"],["0.000000312","16250252","0","2"],["0.000000303","16250252","0","2"],["0.00000030133","6150477","0","1"],["0.0000003","790397450","0","11"],["0.000000294","16250252","0","2"],["0.00000028919","6150477","0","1"],["0.00000028868","277123458","0","1"],["0.0000002851","200000000","0","1"],["0.000000285","16250252","0","2"],["0.000000283","176678445","0","1"],["0.00000028089","106803374","0","1"],["0.00000028","2015419122","0","1"],["0.00000027706","6150477","0","1"],["0.000000276","16250252","0","2"],["0.000000267","16250252","0","2"],["0.00000026493","6150477","0","1"],["0.00000026","119230769","0","2"],["0.000000258","16250252","0","2"],["0.00000025279","6150477","0","1"],["0.00000025143","1360270743","0","1"],["0.00000025","94000057","0","2"],["0.000000249","16250252","0","2"],["0.00000024066","6150477","0","1"],["0.00000024","16250252","0","2"],["0.000000231","16250252","0","2"],["0.00000022853","6150477","0","1"],["0.00000022668","44115052","0","1"],["0.000000222","16250252","0","2"],["0.00000022","13636363","0","1"],["0.00000021639","6150477","0","1"],["0.000000213","16250252","0","2"],["0.00000020426","6150477","0","1"],["0.000000204","16250252","0","2"],["0.0000002","345000000","0","4"],["0.000000195","16250252","0","2"],["0.00000019213","6150477","0","1"],["0.000000186","16250252","0","2"],["0.00000018","3253627427","0","3"],["0.000000177","16250252","0","2"],["0.000000168","16250252","0","2"],["0.000000159","16250252","0","2"],["0.00000015","4772916918","0","4"],["0.00000014066","7109341","0","1"],["0.00000012668","78939059","0","1"],["0.00000012238","5338679936","0","1"],["0.00000012","33333342","0","1"],["0.000000108","4629629629","0","1"],["0.0000001","1599993851","0","10"],["0.000000095","120000000","0","1"],["0.0000000918","100000000","0","1"],["0.00000009","439309300","0","6"],["0.00000008668","115366866","0","1"],["0.00000008516","17071299439","0","1"],["0.00000008","3756250000","0","2"],["0.0000000789","200000000","0","1"],["0.00000007704","4691543761","0","1"],["0.00000007","1487134073","0","3"],["0.00000006668","149970005","0","1"],["0.0000000666","1000000000","0","1"],["0.000000063","1734326274","0","1"],["0.00000006","2216666666","0","2"],["0.00000005","13084550716","0","7"],["0.00000004668","214224507","0","1"],["0.000000041","1599267525","0","1"],["0.00000004","10025000000","0","3"],["0.00000003","67333333","0","2"],["0.000000027","572102213","0","1"],["0.00000002668","374812593","0","1"],["0.0000000251","11000000","0","1"],["0.000000023","10500000","0","1"],["0.000000022","3688520022","0","1"],["0.00000002","5950000000","0","2"],["0.00000001668","599520383","0","1"],["0.0000000128","5468750","0","1"],["0.00000001268","788643533","0","1"],["0.000000012","100000000","0","1"],["0.00000001068","936329588","0","1"],["0.00000001","1820000000","0","6"],["0.000000009","111111111","0","1"],["0.00000000868","1152073732","0","1"],["0.00000000774","2946602076","0","1"],["0.000000007","142857142","0","1"],["0.00000000699","428755180","0","1"],["0.0000000067","1492537313","0","1"],["0.00000000668","1497005988","0","1"],["0.0000000063","17343262742","0","1"],["0.000000005","692711964","0","3"],["0.00000000469","2132196162","0","1"],["0.00000000415","323811152","0","1"],["0.000000004","250000000","0","1"],["0.00000000339","1479289940","0","1"],["0.000000003","673333333","0","2"],["0.00000000209","16747928","0","1"],["0.000000002","285242217163","0","3"],["0.00000000169","8689349113","0","1"],["0.000000001","2100000000","0","3"],["0.0000000009","1111111111","0","1"],["0.00000000082","7811603","0","1"],["0.0000000007","1428571428","0","1"],["0.0000000005","4000000000","0","2"],["0.0000000004","2500000000","0","1"],["0.0000000003","6733333333","0","2"],["0.0000000002","595000000000","0","2"],["0.0000000001","20000000000","0","2"],["0.00000000009","111111111111","0","2"],["0.00000000007","14285714285","0","1"],["0.00000000005","217825000004","0","3"],["0.00000000004","25000000000","0","1"],["0.00000000003","67333333333","0","2"],["0.00000000002","5950000000000","0","2"],["0.00000000001","300000000000","0","3"]],"ts":"1646003667623","checksum":1993655796}]}
1646003668.387469: {"arg":{"channel":"books-l2-tbt","instId":"ETH-USD-220228-3000-C"},"action":"snapshot","data":[{"asks":[["0.001","1031","0","3"],["0.0025","505","0","1"]],"bids":[],"ts":"1646003650967","checksum":1499363433}]}
1646003668.3875048: {"arg":{"channel":"books-l2-tbt","instId":"ELON-USDT"},"action":"snapshot","data":[{"asks":[["0.00000074528","159764443","0","2"],["0.00000074529","526402122","0","2"],["0.00000074533","130685482","0","3"],["0.0000007459","2684143825","0","2"],["0.00000074615","496917766","0","1"],["0.00000074659","4038943392","0","1"],["0.0000007466","698000000","0","1"],["0.0000007468","698000000","0","1"],["0.00000074703","1074799314","0","1"],["0.00000074717","671767622","0","1"],["0.00000074738","3205680429","0","1"],["0.0000007477","691000000","0","1"],["0.00000074794","750000000","0","1"],["0.00000074795","18581929","0","1"],["0.000000748","5134566890","0","4"],["0.00000074841","43910859","0","2"],["0.0000007504","14825409062","0","3"],["0.00000075077","603095914","0","1"],["0.00000075118","6829045","0","1"],["0.00000075165","18490323","0","1"],["0.000000753","16237250","0","2"],["0.00000075491","15308705","0","1"],["0.00000075537","18399370","0","1"],["0.0000007554","1396000000","0","2"],["0.00000075582","43910859","0","2"],["0.00000075664","461795013","0","1"],["0.00000075885","6829045","0","1"],["0.00000075911","18308579","0","1"],["0.00000075919","984203700","0","1"],["0.000000762","16237250","0","2"],["0.00000076239","6145556","0","1"],["0.00000076287","18218439","0","1"],["0.00000076323","43910859","0","2"],["0.00000076457","547843267","0","1"],["0.00000076651","6829045","0","1"],["0.00000076665","18128706","0","1"],["0.00000077044","18039381","0","1"],["0.00000077064","43910859","0","2"],["0.00000077076","6625930","0","1"],["0.000000771","16237250","0","2"],["0.00000077418","6829045","0","1"],["0.00000077426","17950465","0","1"],["0.00000077453","6145556","0","1"],["0.00000077805","43910859","0","2"],["0.00000077809","17862190","0","1"],["0.00000078","16237250","0","2"],["0.00000078184","6829045","0","1"],["0.00000078194","17774092","0","1"],["0.00000078246","124918927","0","1"],["0.00000078581","17686633","0","1"],["0.00000078666","6145556","0","1"],["0.00000078752","6625930","0","1"],["0.000000789","16237250","0","2"],["0.00000078904","373845562","0","1"],["0.00000078951","6829045","0","1"],["0.00000078971","17599356","0","1"],["0.00000079361","17512715","0","1"],["0.00000079549","8368593","0","1"],["0.00000079717","6829045","0","1"],["0.00000079754","17426483","0","1"],["0.000000798","16237250","0","2"],["0.00000079879","6145556","0","1"],["0.0000007993","136937413","0","1"],["0.0000008","25411333","0","2"],["0.00000080149","17340659","0","1"],["0.00000080427","6625930","0","1"],["0.00000080482","275353132","0","1"],["0.00000080484","6829045","0","1"],["0.00000080512","17050757","0","1"],["0.00000080545","17255246","0","1"],["0.000000807","16237250","0","2"],["0.00000080944","17170243","0","1"],["0.00000081","479828093","0","4"],["0.00000081093","6145556","0","1"],["0.000000812","290702923","0","1"],["0.00000081234","528364857","0","1"],["0.00000081345","17085650","0","1"],["0.000000814","20804211","0","1"],["0.000000816","16237250","0","2"],["0.00000081748","17001467","0","1"],["0.000000819","16441155","0","1"],["0.00000082","910021117","0","5"],["0.0000008202","12005857","0","1"],["0.00000082091","181316248","0","1"],["0.00000082103","6625930","0","1"],["0.00000082153","16917696","0","1"],["0.00000082306","6145556","0","1"],["0.000000825","16237250","0","2"],["0.00000082559","16834335","0","1"],["0.00000082967","16751588","0","1"],["0.00000083","1046895326","0","6"],["0.00000083378","16669047","0","1"],["0.000000834","16237250","0","2"],["0.000000835","19610080","0","1"],["0.00000083519","6145556","0","1"],["0.000000836","5980861","0","1"],["0.00000083732","222060909","0","1"],["0.00000083779","6625930","0","1"],["0.00000083791","16586917","0","1"],["0.000000839","21944895","0","1"],["0.00000084","4212026966","0","3"],["0.00000084206","16505197","0","1"],["0.00000084299","1898005907","0","1"],["0.000000843","1811237250","0","6"],["0.000000845","679503139","0","1"],["0.00000084623","16423888","0","1"],["0.00000084733","6145556","0","1"],["0.00000085","487430000","0","2"],["0.00000085041","16342989","0","1"],["0.000000852","16237250","0","2"],["0.00000085406","262020875","0","1"],["0.00000085454","6625930","0","1"],["0.00000085462","16262500","0","1"],["0.000000855","64991051","0","1"],["0.00000085885","16182420","0","1"],["0.00000085946","6145556","0","1"],["0.00000086","41486779","0","2"],["0.000000861","16237250","0","2"],["0.00000086311","16102561","0","1"],["0.00000086593","47078428","0","1"],["0.00000086738","29077974","0","2"],["0.00000086929","40111734","0","1"],["0.00000087","16237250","0","2"],["0.0000008713","6625930","0","1"],["0.00000087159","6145556","0","1"],["0.00000087167","15944448","0","1"],["0.00000087599","15865821","0","1"],["0.000000879","16237250","0","2"],["0.00000088","80913204","0","2"],["0.00000088032","15787785","0","1"],["0.00000088373","6145556","0","1"],["0.00000088468","15709977","0","1"],["0.000000888","33950431","0","3"],["0.00000088805","6625930","0","1"],["0.00000088906","15632577","0","1"],["0.00000089","524044919","0","3"],["0.00000089346","15555586","0","1"],["0.00000089586","6145556","0","1"],["0.000000897","16237250","0","2"],["0.00000089788","15479002","0","1"],["0.00000089838","138048627","0","1"],["0.000000899","124287882","0","1"],["0.0000008998","32604356","0","1"],["0.00000089999","5928210","0","1"],["0.0000009","973626903","0","6"],["0.00000090233","15402653","0","1"],["0.00000090481","6625930","0","1"],["0.000000906","16237250","0","2"],["0.00000090679","15326883","0","1"],["0.00000090724","13358800","0","2"],["0.00000090783","6174344","0","1"],["0.00000090799","6145556","0","1"],["0.00000091128","15251349","0","1"],["0.00000091289","35900750","0","1"],["0.00000091391","13358800","0","2"],["0.000000915","16237250","0","2"],["0.00000091573","6174344","0","1"],["0.0000009158","15176223","0","1"],["0.000000918","36413508","0","1"],["0.00000092","59945669","0","2"],["0.00000092013","6145556","0","1"],["0.00000092033","15101502","0","1"],["0.00000092058","13358800","0","2"],["0.00000092115","75754272","0","1"],["0.00000092157","6625930","0","1"],["0.0000009237","6174344","0","1"],["0.000000924","16237250","0","2"],["0.00000092489","15027023","0","1"],["0.0000009271","35900750","0","1"],["0.00000092725","13358800","0","2"],["0.00000092787","15825768","0","1"],["0.00000092947","14952951","0","1"],["0.00000093","353995922","0","2"],["0.00000093173","6174344","0","1"],["0.00000093226","6145556","0","1"],["0.000000933","16237250","0","2"],["0.00000093392","13358800","0","2"],["0.00000093406","14879446","0","1"],["0.00000093421","35900750","0","1"],["0.00000093754","15825768","0","1"],["0.00000093869","14806024","0","1"],["0.00000093984","6174344","0","1"],["0.00000094","400000000","0","1"],["0.00000094059","13358800","0","2"],["0.00000094131","35900750","0","1"],["0.000000942","16237250","0","2"],["0.00000094334","14733165","0","1"],["0.00000094439","6145556","0","1"],["0.00000094499","160433622","0","2"],["0.000000945","37499214520","0","1"],["0.00000094679","10122765","0","1"],["0.0000009472","15825768","0","1"],["0.00000094726","13358800","0","2"],["0.00000094801","14660553","0","1"],["0.00000094802","6174344","0","1"],["0.0000009484","199032795","0","1"],["0.00000094842","35900750","0","1"],["0.00000094993","11705727","0","1"],["0.00000095","2273468914","0","5"],["0.000000951","16237250","0","2"],["0.0000009525","26109346","0","1"],["0.0000009527","14588345","0","1"],["0.00000095393","13358800","0","2"],["0.00000095552","35900750","0","1"],["0.00000095627","6174344","0","1"],["0.00000095653","6145556","0","1"],["0.00000095687","15825768","0","1"],["0.00000095741","14516540","0","1"],["0.00000096","216237250","0","3"],["0.0000009606","13358800","0","2"],["0.00000096216","14444984","0","1"],["0.00000096263","4597750","0","1"],["0.00000096459","6174344","0","1"],["0.00000096653","15825768","0","1"],["0.00000096692","14373831","0","1"],["0.00000096728","13358800","0","2"],["0.00000096866","6145556","0","1"],["0.000000969","16237250","0","2"],["0.00000096973","35900750","0","1"],["0.0000009717","14303079","0","1"],["0.000000972","5175138","0","1"],["0.00000097299","6174344","0","1"],["0.00000097395","13358800","0","2"],["0.0000009762","15825768","0","1"],["0.00000097652","14232580","0","1"],["0.00000097684","35900750","0","1"],["0.000000978","16237250","0","2"],["0.00000098","1419271045","0","3"],["0.00000098062","13358800","0","2"],["0.00000098079","6145556","0","1"],["0.00000098135","14162482","0","1"],["0.00000098145","6174344","0","1"],["0.00000098394","35900750","0","1"],["0.00000098586","15825768","0","1"],["0.00000098621","14092639","0","1"],["0.000000987","16237250","0","2"],["0.00000098708","10122765","0","1"],["0.00000098729","13358800","0","2"],["0.00000098738","13054674","0","1"],["0.00000098916","100000000","0","1"],["0.00000098999","6174344","0","1"],["0.00000099","950214155","0","2"],["0.00000099105","35900750","0","1"],["0.00000099109","14023339","0","1"],["0.00000099293","6145556","0","1"],["0.00000099396","13358800","0","2"],["0.00000099553","15825768","0","1"],["0.000000996","30191403","0","3"],["0.00000099815","35900750","0","1"],["0.00000099861","6174344","0","1"],["0.000000999","8008008","0","1"],["0.000001","1901546777","0","13"],["0.00000100063","13358800","0","2"],["0.00000100092","13885507","0","1"],["0.000001002","1375185419","0","1"],["0.00000100382","1394672351","0","1"],["0.000001004","5175138","0","1"],["0.000001005","16237250","0","2"],["0.00000100506","6145556","0","1"],["0.00000100519","15825768","0","1"],["0.00000100526","35900750","0","1"],["0.00000100588","13817117","0","1"],["0.00000100648","306808450","0","1"],["0.0000010073","19533144","0","3"],["0.00000101","34211209","0","2"],["0.00000101086","13748988","0","1"],["0.00000101236","35900750","0","1"],["0.00000101397","13358800","0","2"],["0.000001014","16237250","0","2"],["0.00000101486","15825768","0","1"],["0.00000101587","13681255","0","1"],["0.00000101606","6174344","0","1"],["0.00000101719","6145556","0","1"],["0.00000101947","10011164","0","1"],["0.00000102","1036814373","0","2"],["0.00000102064","13358800","0","2"],["0.00000102089","8167641","0","1"],["0.000001022","5870841","0","1"],["0.0000010221","11618604","0","1"],["0.000001023","16237250","0","2"],["0.0000010249","6174344","0","1"],["0.00000102595","13546842","0","1"],["0.00000102657","35900750","0","1"],["0.00000102731","13358800","0","2"],["0.00000102737","10122765","0","1"],["0.00000102933","6145556","0","1"],["0.00000103","118562045","0","1"],["0.00000103102","13480161","0","1"],["0.000001032","16237250","0","2"],["0.00000103368","35900750","0","1"],["0.00000103382","6179288","0","1"],["0.00000103399","13358800","0","2"],["0.000001036","5174102","0","1"],["0.00000103613","13413741","0","1"],["0.00000104","424044919","0","2"],["0.00000104066","13358800","0","2"],["0.00000104078","35900750","0","1"],["0.000001041","16237250","0","2"],["0.00000104126","13347585","0","1"],["0.00000104146","6145556","0","1"],["0.00000104282","6179288","0","1"],["0.00000104388","25120293","0","1"],["0.00000104419","11367496","0","1"],["0.00000104641","13281952","0","1"],["0.00000104733","13358800","0","2"],["0.00000104789","35900750","0","1"],["0.00000105","73735670","0","5"],["0.00000105159","13216454","0","1"],["0.00000105189","6179288","0","1"],["0.00000105333","8116225","0","1"],["0.00000105359","6145556","0","1"],["0.000001054","13358800","0","2"],["0.000001055","35900750","0","1"],["0.0000010568","13151348","0","1"],["0.000001059","16237250","0","2"],["0.00000106","172900187","0","1"],["0.00000106067","13358800","0","2"],["0.00000106105","6179288","0","1"],["0.00000106139","24705905","0","1"],["0.00000106203","13086632","0","1"],["0.0000010621","35900750","0","1"],["0.00000106573","6145556","0","1"],["0.00000106628","11127013","0","1"],["0.00000106729","13022059","0","1"],["0.00000106734","13358800","0","2"],["0.00000106766","10122765","0","1"],["0.000001068","21411352","0","3"],["0.00000106921","35900750","0","1"],["0.00000107","24044919","0","1"],["0.00000107028","6179288","0","1"],["0.00000107258","12957877","0","1"],["0.00000107401","13356126","0","2"],["0.0000010752","5358018","0","1"],["0.00000107631","35900750","0","1"],["0.000001077","16237250","0","2"],["0.00000107786","6145556","0","1"],["0.00000107789","12893963","0","1"],["0.00000107839","5089601","0","1"],["0.00000107919","24298326","0","1"],["0.0000010796","6179288","0","1"],["0.00000108068","13356126","0","2"],["0.00000108323","12830437","0","1"],["0.00000108342","35900750","0","1"],["0.000001085","10078318040","0","1"],["0.00000108511","9215655","0","1"],["0.000001086","16237250","0","2"],["0.00000108685","26651445","0","1"],["0.00000108735","13356126","0","2"],["0.00000108837","10896494","0","1"],["0.0000010886","12767181","0","1"],["0.00000108899","6179288","0","1"],["0.00000108974","807975188","0","1"],["0.00000108999","6145556","0","1"],["0.00000109","585198897","0","3"],["0.00000109052","35900750","0","1"],["0.000001094","12704194","0","1"],["0.00000109402","13356126","0","2"],["0.000001095","16237250","0","2"],["0.00000109729","23897553","0","1"],["0.00000109763","35900750","0","1"],["0.00000109847","6179288","0","1"],["0.00000109941","12641594","0","1"],["0.0000011","627620400","0","13"],["0.0000011007","13356126","0","2"],["0.00000110213","6145556","0","1"],["0.000001104","16237250","0","2"],["0.00000110473","30138000","0","1"],["0.00000110486","12579264","0","1"],["0.00000110637","5262112","0","1"],["0.00000110666","8116225","0","1"],["0.00000110795","10122765","0","1"],["0.00000110802","6179288","0","1"],["0.00000111","743452384","0","1"],["0.00000111034","12517205","0","1"],["0.00000111047","10675234","0","1"],["0.00000111184","35900750","0","1"],["0.00000111278","5262112","0","1"],["0.000001113","16237250","0","2"],["0.00000111426","6145556","0","1"],["0.00000111569","23503358","0","1"],["0.00000111584","12455530","0","1"],["0.00000111767","6179288","0","1"],["0.00000111894","35900750","0","1"],["0.00000111922","5262112","0","1"],["0.00000112","116219954","0","1"],["0.00000112136","12394127","0","1"],["0.000001122","16237250","0","2"],["0.00000112571","5262112","0","1"],["0.00000112605","35900750","0","1"],["0.00000112639","6145556","0","1"],["0.00000112692","12332995","0","1"],["0.00000112739","6179288","0","1"],["0.00000112888","287087435","0","1"],["0.00000113","89355188","0","1"],["0.000001131","16237250","0","2"],["0.00000113223","5262112","0","1"],["0.00000113251","12272136","0","1"],["0.00000113256","10462875","0","1"],["0.00000113315","35900750","0","1"],["0.0000011338","129154981","0","1"]],"bids":[["0.00000074351","184440410","0","1"],["0.0000007435","219861835","0","1"],["0.0000007433","1006570154","0","1"],["0.0000007432","1677286721","0","1"],["0.00000074262","4038943392","0","1"],["0.00000074255","497034584","0","1"],["0.00000074243","672074627","0","1"],["0.00000074236","1074229240","0","1"],["0.000000742","3205680429","0","1"],["0.0000007413","3354545575","0","1"],["0.000000741","2209824531","0","2"],["0.00000073913","18673943","0","1"],["0.000000739","516000000","0","1"],["0.0000007388","30281128","0","1"],["0.00000073813","6150477","0","1"],["0.00000073801","160433622","0","2"],["0.000000738","16555352866","0","4"],["0.000000737","1982000000","0","3"],["0.0000007369","14110493714","0","2"],["0.00000073585","6834513","0","1"],["0.000000735","16250252","0","2"],["0.00000073447","1041756730","0","1"],["0.00000073359","43946017","0","2"],["0.000000733","7204113808","0","3"],["0.00000073245","642765243","0","1"],["0.00000072819","226694713","0","3"],["0.00000072786","10000000","0","1"],["0.00000072748","785570734","0","1"],["0.0000007273","401520460","0","1"],["0.00000072647","272977721","0","3"],["0.00000072618","324868101","0","4"],["0.000000726","1671400677","0","4"],["0.00000072599","6150477","0","1"],["0.00000072509","187397427","0","2"],["0.0000007231","573563825","0","2"],["0.00000072304","5532217","0","1"],["0.000000721","170596393","0","1"],["0.00000072","2160884396","0","5"],["0.00000071888","646839527","0","2"],["0.00000071877","217854221","0","3"],["0.000000717","120852762","0","3"],["0.00000071386","869204855","0","7"],["0.00000071188","123615597","0","2"],["0.00000071136","43946017","0","2"],["0.00000071092","165981033","0","1"],["0.00000071","200000000","0","1"],["0.000000708","157493189","0","3"],["0.00000070664","189627650","0","1"],["0.00000070565","144547580","0","1"],["0.00000070556","190260455","0","1"],["0.0000007045","7541376","0","1"],["0.00000070395","43946017","0","2"],["0.00000070376","96622496","0","1"],["0.00000070254","229914578","0","1"],["0.00000070211","56970634","0","1"],["0.000000702","1833171876","0","1"],["0.00000070175","320629290","0","1"],["0.00000070173","6150477","0","1"],["0.0000007","1020709885","0","9"],["0.00000069901","42917840","0","1"],["0.000000699","16250252","0","2"],["0.00000069823","80202568","0","1"],["0.0000006964","646184963","0","1"],["0.00000069503","92082058","0","1"],["0.00000069481","102185870","0","1"],["0.00000069463","166993082","0","1"],["0.00000069123","5786785","0","1"],["0.00000069","16250252","0","2"],["0.00000068959","6150477","0","1"],["0.0000006888","7259001","0","1"],["0.00000068849","217972839","0","1"],["0.00000068691","199442652","0","1"],["0.000000681","16250252","0","2"],["0.00000067746","6150477","0","1"],["0.00000067473","156145125","0","1"],["0.000000672","16250252","0","2"],["0.00000067032","44754744","0","1"],["0.000000668","29940119","0","1"],["0.00000066775","190000000","0","1"],["0.00000066735","71925305","0","1"],["0.00000066533","6150477","0","1"],["0.000000663","16250252","0","2"],["0.00000066124","241154312","0","1"],["0.00000066","291127080","0","2"],["0.0000006587","45544253","0","1"],["0.000000656","3635395214","0","1"],["0.0000006556","8620054","0","1"],["0.000000654","16250252","0","2"],["0.00000065319","6150477","0","1"],["0.00000065048","152292864","0","1"],["0.00000065","2568520719","0","4"],["0.0000006487","46246338","0","1"],["0.0000006471","583576936","0","1"],["0.000000645","16250252","0","2"],["0.00000064106","6150477","0","1"],["0.00000064","117187500","0","2"],["0.000000636","16250252","0","2"],["0.0000006358","11009751","0","1"],["0.00000063401","7886310","0","1"],["0.00000063","2164891080","0","4"],["0.00000062893","6150477","0","1"],["0.000000627","16250252","0","2"],["0.00000062568","40000000","0","1"],["0.000000625","505600000","0","2"],["0.00000062225","101306440","0","1"],["0.000000622","281350482","0","2"],["0.00000062111","186279403","0","1"],["0.00000062","3013259193","0","8"],["0.000000618","105247015","0","3"],["0.00000061688","20000000","0","1"],["0.00000061679","6150477","0","1"],["0.000000615","89430894","0","1"],["0.000000612","89869281","0","1"],["0.00000061","9020221017","0","5"],["0.000000609","16250252","0","2"],["0.00000060888","125458894","0","1"],["0.00000060466","6150477","0","1"],["0.0000006012","628131463","0","1"],["0.00000060118","45164319","0","1"],["0.0000006","2815862062","0","24"],["0.00000059253","6150477","0","1"],["0.000000591","16250252","0","2"],["0.00000059","33050860","0","1"],["0.000000588","394976377","0","1"],["0.00000058619","9433118","0","1"],["0.000000582","16250252","0","2"],["0.00000058039","6150477","0","1"],["0.00000057362","16108224","0","1"],["0.0000005735","87183958","0","1"],["0.000000573","16250252","0","2"],["0.00000056826","6150477","0","1"],["0.000000566","176678445","0","1"],["0.000000565","167696945","0","1"],["0.000000564","16250252","0","2"],["0.00000056","17884419642","0","2"],["0.000000558","5000000","0","1"],["0.00000055613","6150477","0","1"],["0.000000556","16720919","0","1"],["0.00000055555","543408875","0","4"],["0.000000555","16250252","0","2"],["0.0000005543","8792348","0","1"],["0.0000005532","400178009","0","1"],["0.000000553","100000000","0","1"],["0.00000055167","20000000","0","1"],["0.00000055131","18138615","0","1"],["0.00000055","27621355578","0","2"],["0.000000546","16250252","0","2"],["0.00000054399","6150477","0","1"],["0.00000054","59259259","0","2"],["0.000000537","16250252","0","2"],["0.00000053186","6150477","0","1"],["0.00000053","144531312","0","2"],["0.000000528","16250252","0","2"],["0.00000052668","18986861","0","1"],["0.00000052555","39768095","0","1"],["0.000000523","13384325","0","1"],["0.0000005219","10000000","0","2"],["0.00000052","1502744941","0","3"],["0.00000051973","6150477","0","1"],["0.000000519","16250252","0","2"],["0.00000051895","59736544","0","1"],["0.0000005185","57859209","0","1"],["0.00000051779","90677660","0","1"],["0.000000512","20000000","0","1"],["0.00000051","31915296336","0","13"],["0.000000509","19646365","0","1"],["0.00000050888","19650998","0","1"],["0.000000508","31496062","0","1"],["0.00000050759","6150477","0","1"],["0.000000505","50000000","0","1"],["0.000000502","10956175","0","1"],["0.00000050185","19926272","0","1"],["0.0000005017","43096062","0","2"],["0.00000050112","19955300127","0","1"],["0.000000501","1558612534","0","4"],["0.0000005005","239760239","0","1"],["0.00000050011","9000000","0","1"],["0.00000050001","5999880","0","1"],["0.0000005","4238538410","0","44"],["0.00000049546","6150477","0","1"],["0.000000492","16250252","0","2"],["0.00000049","22448979","0","1"],["0.00000048333","6150477","0","1"],["0.000000483","636259661","0","3"],["0.00000048","12914670","0","1"],["0.00000047954","5412025","0","1"],["0.000000474","22839651","0","3"],["0.00000047119","6150477","0","1"],["0.00000046685","6426046","0","1"],["0.000000465","16250252","0","2"],["0.00000046","63401642","0","1"],["0.00000045906","6150477","0","1"],["0.00000045686","109442717","0","1"],["0.000000456","16250252","0","2"],["0.00000045414","19778630","0","1"],["0.00000045","58396676","0","3"],["0.0000004486","173060633","0","1"],["0.000000447","16250252","0","2"],["0.00000044693","6150477","0","1"],["0.000000438","16250252","0","2"],["0.00000043479","6150477","0","1"],["0.00000043","30649610","0","1"],["0.000000429","16250252","0","2"],["0.00000042671","5000000","0","1"],["0.00000042668","23436767","0","1"],["0.000000423","28368794","0","1"],["0.00000042266","6150477","0","1"],["0.0000004212","12000000","0","1"],["0.00000042","94612296","0","5"],["0.000000419","655284189","0","1"],["0.000000413","10689883","0","1"],["0.000000411","16250252","0","2"],["0.00000041053","6150477","0","1"],["0.00000041","640306419","0","2"],["0.000000402","16250252","0","2"],["0.00000040012","90000000","0","1"],["0.0000004","6313625908","0","17"],["0.00000039839","6150477","0","1"],["0.000000393","16250252","0","2"],["0.00000038626","6150477","0","1"],["0.000000384","16250252","0","2"],["0.0000003756","108869679","0","1"],["0.000000375","16250252","0","2"],["0.00000037413","6150477","0","1"],["0.000000366","16250252","0","2"],["0.00000036199","6150477","0","1"],["0.00000036","783774103","0","1"],["0.000000357","16250252","0","2"],["0.00000035","50000000","0","1"],["0.00000034986","6150477","0","1"],["0.000000348","16250252","0","2"],["0.000000339","16250252","0","2"],["0.00000033773","6150477","0","1"],["0.00000033","4716631189","0","3"],["0.00000032668","30610995","0","1"],["0.00000032559","6150477","0","1"],["0.000000321","22480781","0","3"],["0.00000032","1387313576","0","1"],["0.00000031346","6150477","0","1"],["0.000000312","16250252","0","2"],["0.000000303","16250252","0","2"],["0.00000030133","6150477","0","1"],["0.0000003","790397450","0","11"],["0.000000294","16250252","0","2"],["0.00000028919","6150477","0","1"],["0.00000028868","277123458","0","1"],["0.0000002851","200000000","0","1"],["0.000000285","16250252","0","2"],["0.000000283","176678445","0","1"],["0.00000028089","106803374","0","1"],["0.00000028","2015419122","0","1"],["0.00000027706","6150477","0","1"],["0.000000276","16250252","0","2"],["0.000000267","16250252","0","2"],["0.00000026493","6150477","0","1"],["0.00000026","119230769","0","2"],["0.000000258","16250252","0","2"],["0.00000025279","6150477","0","1"],["0.00000025143","1360270743","0","1"],["0.00000025","94000057","0","2"],["0.000000249","16250252","0","2"],["0.00000024066","6150477","0","1"],["0.00000024","16250252","0","2"],["0.000000231","16250252","0","2"],["0.00000022853","6150477","0","1"],["0.00000022668","44115052","0","1"],["0.000000222","16250252","0","2"],["0.00000022","13636363","0","1"],["0.00000021639","6150477","0","1"],["0.000000213","16250252","0","2"],["0.00000020426","6150477","0","1"],["0.000000204","16250252","0","2"],["0.0000002","345000000","0","4"],["0.000000195","16250252","0","2"],["0.00000019213","6150477","0","1"],["0.000000186","16250252","0","2"],["0.00000018","3253627427","0","3"],["0.000000177","16250252","0","2"],["0.000000168","16250252","0","2"],["0.000000159","16250252","0","2"],["0.00000015","4772916918","0","4"],["0.00000014066","7109341","0","1"],["0.00000012668","78939059","0","1"],["0.00000012238","5338679936","0","1"],["0.00000012","33333342","0","1"],["0.000000108","4629629629","0","1"],["0.0000001","1599993851","0","10"],["0.000000095","120000000","0","1"],["0.0000000918","100000000","0","1"],["0.00000009","439309300","0","6"],["0.00000008668","115366866","0","1"],["0.00000008516","17071299439","0","1"],["0.00000008","3756250000","0","2"],["0.0000000789","200000000","0","1"],["0.00000007704","4691543761","0","1"],["0.00000007","1487134073","0","3"],["0.00000006668","149970005","0","1"],["0.0000000666","1000000000","0","1"],["0.000000063","1734326274","0","1"],["0.00000006","2216666666","0","2"],["0.00000005","13084550716","0","7"],["0.00000004668","214224507","0","1"],["0.000000041","1599267525","0","1"],["0.00000004","10025000000","0","3"],["0.00000003","67333333","0","2"],["0.000000027","572102213","0","1"],["0.00000002668","374812593","0","1"],["0.0000000251","11000000","0","1"],["0.000000023","10500000","0","1"],["0.000000022","3688520022","0","1"],["0.00000002","5950000000","0","2"],["0.00000001668","599520383","0","1"],["0.0000000128","5468750","0","1"],["0.00000001268","788643533","0","1"],["0.000000012","100000000","0","1"],["0.00000001068","936329588","0","1"],["0.00000001","1820000000","0","6"],["0.000000009","111111111","0","1"],["0.00000000868","1152073732","0","1"],["0.00000000774","2946602076","0","1"],["0.000000007","142857142","0","1"],["0.00000000699","428755180","0","1"],["0.0000000067","1492537313","0","1"],["0.00000000668","1497005988","0","1"],["0.0000000063","17343262742","0","1"],["0.000000005","692711964","0","3"],["0.00000000469","2132196162","0","1"],["0.00000000415","323811152","0","1"],["0.000000004","250000000","0","1"],["0.00000000339","1479289940","0","1"],["0.000000003","673333333","0","2"],["0.00000000209","16747928","0","1"],["0.000000002","285242217163","0","3"],["0.00000000169","8689349113","0","1"],["0.000000001","2100000000","0","3"],["0.0000000009","1111111111","0","1"],["0.00000000082","7811603","0","1"],["0.0000000007","1428571428","0","1"],["0.0000000005","4000000000","0","2"],["0.0000000004","2500000000","0","1"],["0.0000000003","6733333333","0","2"],["0.0000000002","595000000000","0","2"],["0.0000000001","20000000000","0","2"],["0.00000000009","111111111111","0","2"],["0.00000000007","14285714285","0","1"],["0.00000000005","217825000004","0","3"],["0.00000000004","25000000000","0","1"],["0.00000000003","67333333333","0","2"],["0.00000000002","5950000000000","0","2"],["0.00000000001","300000000000","0","3"]],"ts":"1646003667623","checksum":1993655796}]}
1646003668.3898659: {"arg":{"channel":"books-l2-tbt","instId":"ETH-USD-220228-3000-C"},"action":"snapshot","data":[{"asks":[["0.001","1031","0","3"],["0.0025","505","0","1"]],"bids":[],"ts":"1646003650967","checksum":1499363433}]}
1646003668.389895: {"arg":{"channel":"books-l2-tbt","instId":"UNI-USD-SWAP"},"action":"update","data":[{"asks":[],"bids":[["9.617","441","0","4"],["9.581","107","0","2"]],"ts":"1646003667640","checksum":-980833328}]}
1646003668.3899572: {"arg":{"channel":"books-l2-tbt","instId":"ELON-USDT"},"action":"update","data":[{"asks":[["0.00000074527","445226872","0","1"],["0.0000011338","0","0","0"]],"bids":[],"ts":"1646003667644","checksum":548211390}]}
1646003668.390028: {"arg":{"channel":"books-l2-tbt","instId":"UNI-USD-SWAP"},"action":"update","data":[{"asks":[["9.645","748","0","3"],["9.654","28","0","1"],["48.625","0","0","0"]],"bids":[],"ts":"1646003667651","checksum":-253917013}]}
1646003668.390053: {"arg":{"channel":"books-l2-tbt","instId":"UNI-USD-SWAP"},"action":"update","data":[{"asks":[["9.637","123","0","1"],["9.639","0","0","0"],["9.663","1702","0","2"]],"bids":[],"ts":"1646003667661","checksum":-226870241}]}
1646003668.390074: {"arg":{"channel":"books-l2-tbt","instId":"ELON-USDT"},"action":"update","data":[{"asks":[["0.00000074528","0","0","0"],["0.00000074529","81175250","0","1"],["0.0000011338","129154981","0","1"]],"bids":[],"ts":"1646003667664","checksum":-582897163}]}
1646003668.390096: {"arg":{"channel":"books-l2-tbt","instId":"UNI-USD-SWAP"},"action":"update","data":[{"asks":[["9.663","1658","0","1"],["9.666","82","0","1"],["48.383","0","0","0"]],"bids":[],"ts":"1646003667672","checksum":1847217011}]}
1646003668.3901162: {"arg":{"channel":"books-l2-tbt","instId":"ELON-USDT"},"action":"update","data":[{"asks":[["0.00000074526","111748770","0","1"],["0.0000011338","0","0","0"]],"bids":[],"ts":"1646003667685","checksum":-197047251}]}
1646003668.390135: {"arg":{"channel":"books-l2-tbt","instId":"UNI-USD-SWAP"},"action":"update","data":[{"asks":[["9.637","0","0","0"],["9.638","167","0","3"],["9.654","253","0","2"],["9.662","0","0","0"],["9.663","2504","0","2"],["9.671","0","0","0"],["9.72","846","0","1"],["9.728","0","0","0"],["9.776","846","0","1"],["9.787","0","0","0"],["48.383","1","0","1"],["48.625","1","0","1"],["48.868","1","0","1"]],"bids":[["9.579","513","0","3"],["9.577","1799","0","2"],["9.511","846","0","1"],["9.509","0","0","0"],["9.454","846","0","1"],["9.449","0","0","0"]],"ts":"1646003667683","checksum":-585581908}]}
1646003668.390198: {"arg":{"channel":"books-l2-tbt","instId":"ELON-USDT"},"action":"update","data":[{"asks":[],"bids":[["0.000000708","295911268","0","4"]],"ts":"1646003667695","checksum":-197047251}]}
1646003668.390214: {"arg":{"channel":"books-l2-tbt","instId":"UNI-USD-SWAP"},"action":"update","data":[{"asks":[],"bids":[["9.607","0","0","0"]],"ts":"1646003667705","checksum":-1503308145}]}
1646003668.390233: {"arg":{"channel":"books-l2-tbt","instId":"UNI-USD-SWAP"},"action":"update","data":[{"asks":[],"bids":[["9.611","500","0","1"]],"ts":"1646003667714","checksum":-1623006449}]}
1646003668.3902469: {"arg":{"channel":"books-l2-tbt","instId":"ELON-USDT"},"action":"update","data":[{"asks":[],"bids":[["0.00000074101","750000000","0","1"]],"ts":"1646003667734","checksum":1101287967}]}
1646003668.390261: {"arg":{"channel":"books-l2-tbt","instId":"UNI-USD-SWAP"},"action":"update","data":[{"asks":[["9.638","44","0","2"],["9.639","123","0","1"],["9.664","96","0","2"],["48.868","0","0","0"]],"bids":[],"ts":"1646003667734","checksum":1982412464}]}
1646003668.3902879: {"arg":{"channel":"books-l2-tbt","instId":"ELON-USDT"},"action":"update","data":[{"asks":[["0.00000074525","445226872","0","1"],["0.00000074526","180319116","0","2"],["0.00000074533","0","0","0"]],"bids":[],"ts":"1646003667738","checksum":-1784569042}]}
1646003668.390309: {"arg":{"channel":"books-l2-tbt","instId":"UNI-USD-SWAP"},"action":"update","data":[{"asks":[],"bids":[["9.617","388","0","3"]],"ts":"1646003667745","checksum":-1385681566}]}
1646003668.390327: {"arg":{"channel":"books-l2-tbt","instId":"UNI-USD-SWAP"},"action":"update","data":[{"asks":[],"bids":[["9.581","68","0","1"]],"ts":"1646003667755","checksum":320497884}]}
1646003668.390341: {"arg":{"channel":"books-l2-tbt","instId":"UNI-USD-SWAP"},"action":"update","data":[{"asks":[],"bids":[["9.619","294","0","3"],["9.607","25","0","1"],["9.603","1248","0","1"],["9.602","24","0","1"],["9.6","166","0","2"]],"ts":"1646003667767","checksum":-54110125}]}
1646003668.390364: {"arg":{"channel":"books-l2-tbt","instId":"ELON-USDT"},"action":"update","data":[{"asks":[["0.00000074527","0","0","0"],["0.0000011338","129154981","0","1"]],"bids":[["0.0000007435","0","0","0"]],"ts":"1646003667769","checksum":-749290353}]}
1646003668.3903859: {"arg":{"channel":"books-l2-tbt","instId":"UNI-USD-SWAP"},"action":"update","data":[{"asks":[],"bids":[["9.62","1","0","1"]],"ts":"1646003667777","checksum":370789869}]}
1646003668.3904: {"arg":{"channel":"books-l2-tbt","instId":"PROPS-ETH"},"action":"update","data":[{"asks":[["0.00000178","0","0","0"],["0.00000183","1060.00371123","0","1"],["0.00000184","1258.8583477","0","1"],["0.00000185","1177.84710829","0","1"],["0.00000186","1456.21131058","0","1"],["0.00000187","0","0","0"]],"bids":[["0.00000161","0","0","0"]],"ts":"1646003667792","checksum":1994135990}]}
1646003668.390435: {"arg":{"channel":"books-l2-tbt","instId":"UNI-USD-SWAP"},"action":"update","data":[{"asks":[["9.627","260","0","1"],["9.628","88","0","1"],["48.625","0","0","0"]],"bids":[["9.614","0","0","0"],["9.613","35","0","3"],["9.611","0","0","0"],["9.607","525","0","2"]],"ts":"1646003667797","checksum":-1834045794}]}
1646003668.3904681: {"arg":{"channel":"books-l2-tbt","instId":"ELON-USDT"},"action":"update","data":[{"asks":[["0.00000074526","172616286","0","2"]],"bids":[],"ts":"1646003667798","checksum":-2104154211}]}
1646003668.390483: {"arg":{"channel":"books-l2-tbt","instId":"UNI-USD-SWAP"},"action":"update","data":[{"asks":[["9.638","167","0","3"],["9.639","0","0","0"],["48.625","1","0","1"]],"bids":[],"ts":"1646003667819","checksum":-1113871685}]}
1646003668.390502: {"arg":{"channel":"books-l2-tbt","instId":"ELON-USDT"},"action":"update","data":[{"asks":[["0.00000074526","68570346","0","1"]],"bids":[["0.00000074331","184440410","0","1"]],"ts":"1646003667821","checksum":-241282739}]}
1646003668.390523: {"arg":{"channel":"books-l2-tbt","instId":"UNI-USD-SWAP"},"action":"update","data":[{"asks":[["9.638","132","0","3"]],"bids":[["9.618","0","0","0"],["9.614","4","0","1"]],"ts":"1646003667828","checksum":114290147}]}
1646003668.3905432: {"arg":{"channel":"books-l2-tbt","instId":"UNI-USD-SWAP"},"action":"update","data":[{"asks":[],"bids":[["9.62","0","0","0"],["9.619","347","0","4"]],"ts":"1646003667837","checksum":-1933772201}]}
1646003668.39056: {"arg":{"channel":"books-l2-tbt","instId":"UNI-USD-SWAP"},"action":"update","data":[{"asks":[["9.647","2740","0","6"]],"bids":[],"ts":"1646003667848","checksum":-435406334}]}
1646003668.390574: {"arg":{"channel":"books-l2-tbt","instId":"ELON-USDT"},"action":"update","data":[{"asks":[["0.00000074524","104045940","0","1"],["0.0000011338","0","0","0"]],"bids":[["0.00000074351","0","0","0"]],"ts":"1646003667851","checksum":-1217576500}]}
1646003668.390595: {"arg":{"channel":"books-l2-tbt","instId":"UNI-USD-SWAP"},"action":"update","data":[{"asks":[["9.648","2043","0","2"],["9.65","250","0","3"],["9.651","50","0","1"],["9.653","60","0","2"],["9.654","225","0","1"]],"bids":[["9.617","362","0","2"]],"ts":"1646003667858","checksum":1538822770}]}
1646003668.390622: {"arg":{"channel":"books-l2-tbt","instId":"ELON-USDT"},"action":"update","data":[{"asks":[["0.00000074524","152061613","0","2"]],"bids":[["0.000000742","0","0","0"]],"ts":"1646003667873","checksum":-1125275666}]}
1646003668.390641: {"arg":{"channel":"books-l2-tbt","instId":"UNI-USD-SWAP"},"action":"update","data":[{"asks":[],"bids":[["9.619","294","0","3"]],"ts":"1646003667888","checksum":-2102098342}]}
1646003668.390656: {"arg":{"channel":"books-l2-tbt","instId":"ELON-USDT"},"action":"update","data":[{"asks":[["0.00000074523","445226872","0","1"],["0.00000113315","0","0","0"]],"bids":[["0.00000074184","3606560075","0","1"]],"ts":"1646003667894","checksum":1950315124}]}
1646003668.390677: {"arg":{"channel":"books-l2-tbt","instId":"UNI-USD-SWAP"},"action":"update","data":[{"asks":[["9.628","0","0","0"],["48.868","1","0","1"]],"bids":[],"ts":"1646003667900","checksum":870932345}]}
1646003668.390694: {"arg":{"channel":"books-l2-tbt","instId":"ELON-USDT"},"action":"update","data":[{"asks":[["0.00000074524","0","0","0"],["0.00000074525","0","0","0"],["0.00000113315","35900750","0","1"],["0.0000011338","129154981","0","1"]],"bids":[["0.00000070254","0","0","0"],["0.00000068849","0","0","0"],["0.00000067473","0","0","0"],["0.00000066124","0","0","0"],["0.00000064798","332863457","0","1"]],"ts":"1646003667914","checksum":-891582216}]}
1646003668.3907342: {"arg":{"channel":"books-l2-tbt","instId":"UNI-USD-SWAP"},"action":"update","data":[{"asks":[],"bids":[["9.614","0","0","0"],["9.581","98","0","2"]],"ts":"1646003667919","checksum":-89288747}]}
1646003668.390751: {"arg":{"channel":"books-l2-tbt","instId":"ELON-USDT"},"action":"update","data":[{"asks":[["0.00000074522","48015673","0","1"],["0.00000074529","0","0","0"]],"bids":[],"ts":"1646003667934","checksum":-947347222}]}
1646003668.39077: {"arg":{"channel":"books-l2-tbt","instId":"ELON-USDT"},"action":"update","data":[{"asks":[["0.00000074522","126343458","0","3"],["0.00000074526","0","0","0"],["0.0000011372","6179288","0","1"]],"bids":[],"ts":"1646003667945","checksum":832738769}]}
1646003668.39079: {"arg":{"channel":"books-l2-tbt","instId":"ELON-USDT"},"action":"update","data":[{"asks":[["0.00000074522","178701155","0","4"],["0.00000074523","0","0","0"],["0.00000074525","445226872","0","1"]],"bids":[],"ts":"1646003667956","checksum":661597790}]}
1646003668.390811: {"arg":{"channel":"books-l2-tbt","instId":"UNI-USD-SWAP"},"action":"update","data":[{"asks":[],"bids":[["9.616","38","0","2"]],"ts":"1646003667963","checksum":181535520}]}
1646003668.390825: {"arg":{"channel":"books-l2-tbt","instId":"UNI-USD-SWAP"},"action":"update","data":[{"asks":[],"bids":[["9.618","1","0","1"],["9.616","147","0","3"]],"ts":"1646003667973","checksum":1226716134}]}
1646003668.390841: {"arg":{"channel":"books-l2-tbt","instId":"ELON-USDT"},"action":"update","data":[{"asks":[["0.00000074522","130685482","0","3"],["0.00000074524","111748770","0","1"],["0.0000011372","0","0","0"]],"bids":[],"ts":"1646003667977","checksum":1286179841}]}
1646003668.390862: {"arg":{"channel":"books-l2-tbt","instId":"ELON-USDT"},"action":"update","data":[{"asks":[["0.00000074524","159764443","0","2"],["0.00000075536","210944203","0","1"],["0.0000011338","0","0","0"]],"bids":[],"ts":"1646003667999","checksum":1646465042}]}
1646003668.390882: {"arg":{"channel":"books-l2-tbt","instId":"UNI-USD-SWAP"},"action":"update","data":[{"asks":[["9.627","348","0","2"]],"bids":[],"ts":"1646003668004","checksum":1188970936}]}
1646003668.3908951: {"arg":{"channel":"books-l2-tbt","instId":"ELON-USDT"},"action":"update","data":[{"asks":[["0.00000074525","526402122","0","2"]],"bids":[],"ts":"1646003668008","checksum":354297813}]}
1646003668.390909: {"arg":{"channel":"books-l2-tbt","instId":"ELON-USDT"},"action":"update","data":[{"asks":[["0.00000074521","445226872","0","1"],["0.00000113315","0","0","0"]],"bids":[["0.00000074101","0","0","0"]],"ts":"1646003668018","checksum":-987511160}]}
1646003668.39093: {"arg":{"channel":"books-l2-tbt","instId":"UNI-USD-SWAP"},"action":"update","data":[{"asks":[["9.633","1089","0","2"],["9.638","44","0","2"]],"bids":[],"ts":"1646003668023","checksum":1811450531}]}
1646003668.3909461: {"arg":{"channel":"books-l2-tbt","instId":"UNI-USD-SWAP"},"action":"update","data":[{"asks":[],"bids":[["9.617","415","0","3"]],"ts":"1646003668034","checksum":866408123}]}
1646003668.390959: {"arg":{"channel":"books-l2-tbt","instId":"ELON-USDT"},"action":"update","data":[{"asks":[["0.00000074524","0","0","0"],["0.00000074525","81175250","0","1"],["0.00000113315","35900750","0","1"]],"bids":[],"ts":"1646003668041","checksum":892451157}]}
1646003668.39098: {"arg":{"channel":"books-l2-tbt","instId":"UNI-USD-SWAP"},"action":"update","data":[{"asks":[],"bids":[["9.581","68","0","1"]],"ts":"1646003668057","checksum":-1604541827}]}
1646003668.3909929: {"arg":{"channel":"books-l2-tbt","instId":"ELON-USDT"},"action":"update","data":[{"asks":[["0.0000007452","159764443","0","2"],["0.00000113315","0","0","0"]],"bids":[],"ts":"1646003668061","checksum":1142947039}]}
1646003668.391011: {"arg":{"channel":"books-l2-tbt","instId":"UNI-USD-SWAP"},"action":"update","data":[{"asks":[["9.627","88","0","1"]],"bids":[],"ts":"1646003668089","checksum":771004395}]}
1646003668.391024: {"arg":{"channel":"books-l2-tbt","instId":"PROPS-ETH"},"action":"update","data":[{"asks":[],"bids":[["0.00000166","0","0","0"]],"ts":"1646003668097","checksum":2007602531}]}
1646003668.391039: {"arg":{"channel":"books-l2-tbt","instId":"UNI-USD-SWAP"},"action":"update","data":[{"asks":[["9.633","1001","0","1"]],"bids":[],"ts":"1646003668098","checksum":1190387156}]}
1646003668.391053: {"arg":{"channel":"books-l2-tbt","instId":"ELON-USDT"},"action":"update","data":[{"asks":[["0.00000074519","445226872","0","1"],["0.00000113256","0","0","0"]],"bids":[],"ts":"1646003668104","checksum":-1877867099}]}
1646003668.39107: {"arg":{"channel":"books-l2-tbt","instId":"UNI-USD-SWAP"},"action":"update","data":[{"asks":[["9.627","0","0","0"],["9.634","88","0","1"],["9.646","37","0","2"],["9.647","2712","0","5"],["9.649","1252","0","3"],["9.65","224","0","2"],["9.652","21","0","1"],["9.653","35","0","1"],["48.868","0","0","0"]],"bids":[["9.607","25","0","1"]],"ts":"1646003668109","checksum":-675163621}]}
1646003668.391107: {"arg":{"channel":"books-l2-tbt","instId":"ELON-USDT"},"action":"update","data":[{"asks":[],"bids":[["0.00000072509","75687157","0","1"]],"ts":"1646003668112","checksum":-1877867099}]}
1646003668.3911219: {"arg":{"channel":"books-l2-tbt","instId":"UNI-USD-SWAP"},"action":"update","data":[{"asks":[],"bids":[["9.62","2","0","1"],["9.611","500","0","1"]],"ts":"1646003668119","checksum":-1284251834}]}
1646003668.391139: {"arg":{"channel":"books-l2-tbt","instId":"ELON-USDT"},"action":"update","data":[{"asks":[["0.0000007452","0","0","0"],["0.00000113256","10462875","0","1"]],"bids":[],"ts":"1646003668124","checksum":-1742500839}]}
1646003668.391156: {"arg":{"channel":"books-l2-tbt","instId":"UNI-USD-SWAP"},"action":"update","data":[{"asks":[["9.635","280","0","4"],["9.636","43","0","1"],["9.643","0","0","0"],["9.655","0","0","0"],["48.868","1","0","1"],["49.113","1","0","1"]],"bids":[["9.601","16","0","1"],["9.6","150","0","1"]],"ts":"1646003668130","checksum":41065305}]}
1646003668.391188: {"arg":{"channel":"books-l2-tbt","instId":"ELON-USDT"},"action":"update","data":[{"asks":[["0.00000074518","48015673","0","1"],["0.00000074521","0","0","0"]],"bids":[],"ts":"1646003668134","checksum":-1238916606}]}
1646003668.391205: {"arg":{"channel":"books-l2-tbt","instId":"PROPS-ETH"},"action":"update","data":[{"asks":[],"bids":[["0.00000166","2371.68659875","0","1"]],"ts":"1646003668136","checksum":1331958821}]}
1646003668.3912199: {"arg":{"channel":"books-l2-tbt","instId":"UNI-USD-SWAP"},"action":"update","data":[{"asks":[["9.631","591","0","1"],["9.67","0","0","0"]],"bids":[["9.618","0","0","0"],["9.617","362","0","2"],["9.614","5","0","1"],["9.613","29","0","2"],["9.582","124","0","1"]],"ts":"1646003668140","checksum":762069277}]}
1646003668.39125: {"arg":{"channel":"books-l2-tbt","instId":"ELON-USDT"},"action":"update","data":[{"asks":[["0.00000074518","159764443","0","2"]],"bids":[],"ts":"1646003668144","checksum":1854322418}]}
1646003668.391264: {"arg":{"channel":"books-l2-tbt","instId":"UNI-USD-SWAP"},"action":"update","data":[{"asks":[["9.633","1099","0","2"],["9.642","312","0","2"],["9.66","9245","0","1"],["9.671","16","0","1"],["48.868","0","0","0"],["49.113","0","0","0"]],"bids":[],"ts":"1646003668149","checksum":-708176050}]}
1646003668.391291: {"arg":{"channel":"books-l2-tbt","instId":"ELON-USDT"},"action":"update","data":[{"asks":[["0.00000074522","53107723","0","1"]],"bids":[],"ts":"1646003668154","checksum":1211279412}]}
1646003668.391305: {"arg":{"channel":"books-l2-tbt","instId":"UNI-USD-SWAP"},"action":"update","data":[{"asks":[["9.635","164","0","2"],["9.668","0","0","0"],["48.868","1","0","1"]],"bids":[["9.582","634","0","2"]],"ts":"1646003668160","checksum":-1209667280}]}
1646003668.391327: {"arg":{"channel":"books-l2-tbt","instId":"ELON-USDT"},"action":"update","data":[{"asks":[["0.00000074518","228334789","0","3"],["0.00000074519","0","0","0"],["0.00000113315","35900750","0","1"]],"bids":[],"ts":"1646003668165","checksum":1421005481}]}
1646003668.391347: {"arg":{"channel":"books-l2-tbt","instId":"UNI-USD-SWAP"},"action":"update","data":[{"asks":[["9.631","0","0","0"],["49.113","1","0","1"]],"bids":[["9.614","0","0","0"],["9.613","35","0","3"],["9.584","20","0","1"]],"ts":"1646003668170","checksum":1606918895}]}
1646003668.391375: {"arg":{"channel":"books-l2-tbt","instId":"ELON-USDT"},"action":"update","data":[{"asks":[["0.00000074518","220631959","0","3"]],"bids":[],"ts":"1646003668174","checksum":2044659840}]}
1646003668.391389: {"arg":{"channel":"books-l2-tbt","instId":"UNI-USD-SWAP"},"action":"update","data":[{"asks":[["9.633","1001","0","1"],["9.635","148","0","1"]],"bids":[["9.614","5","0","1"],["9.613","29","0","2"]],"ts":"1646003668181","checksum":1148380858}]}
1646003668.3914099: {"arg":{"channel":"books-l2-tbt","instId":"BTC-USD-220325-40000-C"},"action":"update","data":[{"asks":[["0.054","0","0","0"],["0.0545","100","0","1"]],"bids":[],"ts":"1646003668183","checksum":-790516564}]}
1646003668.3914292: {"arg":{"channel":"books-l2-tbt","instId":"ELON-USDT"},"action":"update","data":[{"asks":[["0.00000074518","68570346","0","1"]],"bids":[],"ts":"1646003668192","checksum":-1112699615}]}
1646003668.391443: {"arg":{"channel":"books-l2-tbt","instId":"UNI-USD-SWAP"},"action":"update","data":[{"asks":[["9.63","3","0","1"],["9.631","260","0","1"],["9.667","510","0","1"],["48.625","0","0","0"],["48.868","0","0","0"],["49.113","0","0","0"]],"bids":[],"ts":"1646003668193","checksum":-258823557}]}
1646003668.3914711: {"arg":{"channel":"books-l2-tbt","instId":"ELON-USDT"},"action":"update","data":[{"asks":[],"bids":[["0.00000073914","750000000","0","1"]],"ts":"1646003668195","checksum":1763388290}]}
1646003668.391486: {"arg":{"channel":"books-l2-tbt","instId":"UNI-USD-SWAP"},"action":"update","data":[{"asks":[["9.631","348","0","2"]],"bids":[["9.614","0","0","0"],["9.613","35","0","3"],["9.584","0","0","0"]],"ts":"1646003668202","checksum":-783887844}]}
1646003668.391509: {"arg":{"channel":"books-l2-tbt","instId":"UNI-USD-SWAP"},"action":"update","data":[{"asks":[["9.634","186","0","2"],["9.636","0","0","0"],["9.638","75","0","3"],["9.64","275","0","3"],["9.646","16","0","1"],["9.655","28","0","1"]],"bids":[],"ts":"1646003668212","checksum":-1087763569}]}
1646003668.391535: {"arg":{"channel":"books-l2-tbt","instId":"ELON-USDT"},"action":"update","data":[{"asks":[["0.00000074517","445226872","0","1"],["0.00000074589","152061613","0","2"],["0.00000113256","0","0","0"],["0.00000113315","0","0","0"]],"bids":[["0.00000074349","219861835","0","1"]],"ts":"1646003668216","checksum":256739173}]}
1646003668.391562: {"arg":{"channel":"books-l2-tbt","instId":"PROPS-ETH"},"action":"update","data":[{"asks":[],"bids":[["0.00000166","0","0","0"]],"ts":"1646003668218","checksum":2007602531}]}
1646003668.391577: {"arg":{"channel":"books-l2-tbt","instId":"ELON-USDT"},"action":"update","data":[{"asks":[["0.00000074589","0","0","0"],["0.00000074717","0","0","0"],["0.00000074738","0","0","0"],["0.00000074817","671821779","0","1"],["0.00000113256","10462875","0","1"],["0.00000113315","35900750","0","1"]],"bids":[["0.000000742","26345728","0","1"],["0.000000741","2183478803","0","1"]],"ts":"1646003668235","checksum":861653598}]}
1646003668.391613: {"arg":{"channel":"books-l2-tbt","instId":"UNI-USD-SWAP"},"action":"update","data":[{"asks":[["9.63","0","0","0"],["9.632","0","0","0"],["48.625","1","0","1"],["48.868","1","0","1"]],"bids":[["9.618","53","0","1"]],"ts":"1646003668243","checksum":-1931515903}]}
1646003668.391639: {"arg":{"channel":"books-l2-tbt","instId":"PROPS-ETH"},"action":"update","data":[{"asks":[],"bids":[["0.00000166","12048.19201807","0","1"]],"ts":"1646003668250","checksum":-1403262038}]}
1646003668.391653: {"arg":{"channel":"books-l2-tbt","instId":"ELON-USDT"},"action":"update","data":[{"asks":[["0.00000074516","152061613","0","2"],["0.00000074691","3472727151","0","1"],["0.00000113256","0","0","0"],["0.00000113315","0","0","0"]],"bids":[],"ts":"1646003668256","checksum":-1415814009}]}
1646003668.391677: {"arg":{"channel":"books-l2-tbt","instId":"ELON-USDT"},"action":"update","data":[{"asks":[["0.00000074691","0","0","0"],["0.00000113256","10462875","0","1"]],"bids":[["0.0000007435","184440410","0","1"]],"ts":"1646003668277","checksum":1456798101}]}
1646003668.391698: {"arg":{"channel":"books-l2-tbt","instId":"UNI-USD-SWAP"},"action":"update","data":[{"asks":[["9.63","2","0","1"],["48.868","0","0","0"]],"bids":[],"ts":"1646003668287","checksum":-872214835}]}
1646003668.391714: {"arg":{"channel":"books-l2-tbt","instId":"PROPS-ETH"},"action":"update","data":[{"asks":[["0.00000183","0","0","0"],["0.00000184","0","0","0"],["0.00000185","0","0","0"],["0.00000186","0","0","0"]],"bids":[],"ts":"1646003668292","checksum":-897695260}]}
1646003668.3917382: {"arg":{"channel":"books-l2-tbt","instId":"ELON-USDT"},"action":"update","data":[{"asks":[["0.00000074692","3072027864","0","1"],["0.00000113256","0","0","0"]],"bids":[],"ts":"1646003668297","checksum":1266864517}]}
1646003668.391755: {"arg":{"channel":"books-l2-tbt","instId":"PROPS-ETH"},"action":"update","data":[{"asks":[["0.00000177","1259.60433753","0","1"],["0.00000178","1098.70244118","0","1"]],"bids":[["0.0000016","8941.58901817","0","1"]],"ts":"1646003668301","checksum":-1933321838}]}
1646003668.391776: {"arg":{"channel":"books-l2-tbt","instId":"UNI-USD-SWAP"},"action":"update","data":[{"asks":[["9.631","260","0","1"]],"bids":[],"ts":"1646003668308","checksum":-1957220431}]}
1646003668.3917902: {"arg":{"channel":"books-l2-tbt","instId":"ELON-USDT"},"action":"update","data":[{"asks":[["0.00000074515","445226872","0","1"],["0.00000113251","0","0","0"]],"bids":[],"ts":"1646003668325","checksum":722615590}]}
1646003668.391807: {"arg":{"channel":"books-l2-tbt","instId":"ELON-USDT"},"action":"update","data":[{"asks":[],"bids":[["0.00000074331","0","0","0"]],"ts":"1646003668334","checksum":1059007277}]}
1646003668.391822: {"arg":{"channel":"books-l2-tbt","instId":"ETH-USD-220429-1900-P"},"action":"update","data":[{"asks":[["0.0375","500","0","1"],["0.038","1006","0","2"]],"bids":[],"ts":"1646003668336","checksum":356118983}]}
1646003668.391839: {"arg":{"channel":"books-l2-tbt","instId":"ELON-USDT"},"action":"update","data":[{"asks":[["0.00000074516","104045940","0","1"],["0.00000074692","0","0","0"],["0.00000113251","12272136","0","1"]],"bids":[],"ts":"1646003668339","checksum":564578270}]}
1646003668.391859: {"arg":{"channel":"books-l2-tbt","instId":"ZEN-USDT"},"action":"update","data":[{"asks":[],"bids":[["32.46","0.948178","0","1"]],"ts":"1646003668349","checksum":2093969776}]}
1646003668.391917: {"arg":{"channel":"books-l2-tbt","instId":"ELON-USDT"},"action":"update","data":[{"asks":[["0.00000074516","0","0","0"],["0.00000074517","0","0","0"],["0.00000074692","3472750479","0","1"],["0.00000113256","10462875","0","1"]],"bids":[["0.00000072618","436410693","0","5"]],"ts":"1646003668351","checksum":152504807}]}
1646003668.391947: {"arg":{"channel":"books-l2-tbt","instId":"UNI-USD-SWAP"},"action":"update","data":[{"asks":[],"bids":[["9.616","121","0","2"]],"ts":"1646003668359","checksum":-1586088000}]}
1646003668.391961: {"arg":{"channel":"books-l2-tbt","instId":"ELON-USDT"},"action":"update","data":[{"asks":[["0.00000074717","671749571","0","1"],["0.00000074817","0","0","0"]],"bids":[],"ts":"1646003668360","checksum":-1058417824}]}
1646003668.39225: {"arg":{"channel":"books-l2-tbt","instId":"ELON-USDT"},"action":"update","data":[{"asks":[["0.00000074514","212122140","0","3"],["0.00000074518","0","0","0"]],"bids":[["0.00000074262","0","0","0"]],"ts":"1646003668371","checksum":198459258}]}
1646003668.393525: {"arg":{"channel":"books-l2-tbt","instId":"ELON-USDT"},"action":"update","data":[{"asks":[["0.00000074692","0","0","0"],["0.00000113315","35900750","0","1"]],"bids":[["0.00000072101","7410563791","0","1"]],"ts":"1646003668382","checksum":-185830921}]}
1646003668.403413: {"arg":{"channel":"books-l2-tbt","instId":"UNI-USD-SWAP"},"action":"update","data":[{"asks":[["9.651","79","0","2"]],"bids":[],"ts":"1646003668390","checksum":206664807}]}
1646003668.403479: {"arg":{"channel":"books-l2-tbt","instId":"ELON-USDT"},"action":"update","data":[{"asks":[["0.00000074717","0","0","0"],["0.00000074817","671754084","0","1"]],"bids":[["0.00000074249","4038943392","0","1"],["0.00000073914","0","0","0"]],"ts":"1646003668391","checksum":-1956112107}]}
1646003668.414455: {"arg":{"channel":"books-l2-tbt","instId":"UNI-USD-SWAP"},"action":"update","data":[{"asks":[["9.629","88","0","1"],["48.625","0","0","0"]],"bids":[],"ts":"1646003668400","checksum":562328731}]}
1646003668.4145741: {"arg":{"channel":"books-l2-tbt","instId":"ELON-USDT"},"action":"update","data":[{"asks":[["0.00000074515","0","0","0"],["0.0000011338","129154981","0","1"]],"bids":[],"ts":"1646003668401","checksum":-133425185}]}
1646003668.42403: {"arg":{"channel":"books-l2-tbt","instId":"UNI-USD-SWAP"},"action":"update","data":[{"asks":[["9.634","98","0","1"],["9.635","236","0","2"],["9.641","73","0","3"]],"bids":[["9.62","28","0","2"],["9.618","0","0","0"]],"ts":"1646003668411","checksum":927603119}]}
1646003668.424169: {"arg":{"channel":"books-l2-tbt","instId":"ELON-USDT"},"action":"update","data":[{"asks":[["0.00000074692","3072069137","0","1"],["0.0000011338","0","0","0"]],"bids":[["0.0000006993","296952656","0","1"],["0.00000068532","334169420","0","1"],["0.00000067162","428097523","0","1"],["0.00000065819","345888413","0","1"],["0.00000064798","0","0","0"]],"ts":"1646003668411","checksum":-1982734397}]}
1646003668.43375: {"arg":{"channel":"books-l2-tbt","instId":"UNI-USD-SWAP"},"action":"update","data":[{"asks":[["9.635","148","0","1"],["9.644","914","0","2"]],"bids":[],"ts":"1646003668421","checksum":1874016541}]}
1646003668.447528: {"arg":{"channel":"books-l2-tbt","instId":"UNI-USD-SWAP"},"action":"update","data":[{"asks":[["9.637","88","0","1"],["48.383","0","0","0"]],"bids":[["9.621","22","0","1"],["9.619","272","0","2"],["9.585","10003","0","3"],["9.579","99","0","2"]],"ts":"1646003668432","checksum":500814995}]}
1646003668.451829: {"arg":{"channel":"books-l2-tbt","instId":"ETH-USD-220429-1900-P"},"action":"update","data":[{"asks":[["0.0375","0","0","0"],["0.038","1506","0","3"]],"bids":[],"ts":"1646003668439","checksum":-1328280565}]}
1646003668.451916: {"arg":{"channel":"books-l2-tbt","instId":"ELON-USDT"},"action":"update","data":[{"asks":[["0.00000074514","52357697","0","1"]],"bids":[["0.00000074256","184440410","0","1"],["0.00000074249","0","0","0"]],"ts":"1646003668440","checksum":-442880524}]}
1646003668.4540448: {"arg":{"channel":"books-l2-tbt","instId":"ZEN-USDT"},"action":"update","data":[{"asks":[["32.62","0","0","0"],["44.23","2.713011","0","1"]],"bids":[],"ts":"1646003668441","checksum":1345524828}]}
1646003668.454129: {"arg":{"channel":"books-l2-tbt","instId":"UNI-USD-SWAP"},"action":"update","data":[{"asks":[],"bids":[["9.619","325","0","3"]],"ts":"1646003668442","checksum":-738405542}]}
1646003668.454166: {"arg":{"channel":"books-l2-tbt","instId":"ELON-USDT"},"action":"update","data":[{"asks":[["0.00000074517","445226872","0","1"],["0.00000074692","0","0","0"],["0.00000074717","671722498","0","1"],["0.00000074817","0","0","0"]],"bids":[],"ts":"1646003668443","checksum":-1174932544}]}
1646003668.4667919: {"arg":{"channel":"books-l2-tbt","instId":"ELON-USDT"},"action":"update","data":[{"asks":[],"bids":[["0.00000074256","0","0","0"]],"ts":"1646003668453","checksum":383524896}]}
1646003668.4669068: {"arg":{"channel":"books-l2-tbt","instId":"UNI-USD-SWAP"},"action":"update","data":[{"asks":[["9.628","260","0","1"],["48.143","0","0","0"]],"bids":[["9.615","1040","0","1"]],"ts":"1646003668453","checksum":147446619}]}
1646003668.473788: {"arg":{"channel":"books-l2-tbt","instId":"ELON-USDT"},"action":"update","data":[{"asks":[["0.00000074589","159764443","0","2"],["0.00000113315","0","0","0"]],"bids":[],"ts":"1646003668463","checksum":122912601}]}
1646003668.476565: {"arg":{"channel":"books-l2-tbt","instId":"UNI-USD-SWAP"},"action":"update","data":[{"asks":[["9.634","0","0","0"],["48.143","1","0","1"]],"bids":[],"ts":"1646003668464","checksum":602296460}]}
1646003668.480208: {"arg":{"channel":"books-l2-tbt","instId":"ETH-USD-220429-1900-P"},"action":"update","data":[{"asks":[["0.0375","501","0","1"],["0.038","1005","0","2"]],"bids":[],"ts":"1646003668469","checksum":390285993}]}
1646003668.4843662: {"arg":{"channel":"books-l2-tbt","instId":"ELON-USDT"},"action":"update","data":[{"asks":[["0.00000074513","445226872","0","1"],["0.00000074589","0","0","0"],["0.00000074736","3606342030","0","1"],["0.00000113256","0","0","0"]],"bids":[],"ts":"1646003668473","checksum":1265338239}]}
1646003668.4971688: {"arg":{"channel":"books-l2-tbt","instId":"UNI-USD-SWAP"},"action":"update","data":[{"asks":[["9.632","1","0","1"],["48.143","0","0","0"]],"bids":[["9.583","194","0","2"]],"ts":"1646003668484","checksum":1434589961}]}
1646003668.4972212: {"arg":{"channel":"books-l2-tbt","instId":"ELON-USDT"},"action":"update","data":[{"asks":[["0.00000074512","48015673","0","1"],["0.00000074516","111748770","0","1"],["0.00000074525","0","0","0"],["0.00000074717","0","0","0"],["0.00000074736","0","0","0"],["0.00000074817","671758596","0","1"]],"bids":[],"ts":"1646003668484","checksum":-844873690}]}
1646003668.504597: {"arg":{"channel":"books-l2-tbt","instId":"ELON-USDT"},"action":"update","data":[{"asks":[["0.00000074516","0","0","0"],["0.00000113256","10462875","0","1"]],"bids":[["0.00000074246","4038943392","0","1"]],"ts":"1646003668494","checksum":-118542109}]}
1646003668.5088902: {"arg":{"channel":"books-l2-tbt","instId":"UNI-USD-SWAP"},"action":"update","data":[{"asks":[["9.63","0","0","0"],["48.143","1","0","1"]],"bids":[["9.62","137","0","3"],["9.616","12","0","1"]],"ts":"1646003668496","checksum":-1760933399}]}
1646003668.518862: {"arg":{"channel":"books-l2-tbt","instId":"ELON-USDT"},"action":"update","data":[{"asks":[["0.00000074512","159764443","0","2"],["0.00000074517","0","0","0"],["0.00000113315","35900750","0","1"]],"bids":[],"ts":"1646003668505","checksum":636723748}]}
1646003668.518956: {"arg":{"channel":"books-l2-tbt","instId":"UNI-USD-SWAP"},"action":"update","data":[{"asks":[["9.629","0","0","0"],["48.383","1","0","1"]],"bids":[],"ts":"1646003668506","checksum":930222903}]}
1646003668.527667: {"arg":{"channel":"books-l2-tbt","instId":"UNI-USD-SWAP"},"action":"update","data":[{"asks":[],"bids":[["9.622","260","0","1"],["9.617","102","0","1"],["9.614","6","0","1"],["9.613","29","0","2"],["9.583","160","0","1"]],"ts":"1646003668516","checksum":-1830317156}]}
1646003668.540478: {"arg":{"channel":"books-l2-tbt","instId":"BTC-USD-220325-40000-C"},"action":"update","data":[{"asks":[],"bids":[["0.049","305","0","1"],["0.0485","0","0","0"]],"ts":"1646003668525","checksum":-1808356384}]}
1646003668.540601: {"arg":{"channel":"books-l2-tbt","instId":"UNI-USD-SWAP"},"action":"update","data":[{"asks":[["9.631","0","0","0"],["48.625","1","0","1"]],"bids":[["9.621","0","0","0"]],"ts":"1646003668527","checksum":-579200733}]}
1646003668.5406752: {"arg":{"channel":"books-l2-tbt","instId":"ELON-USDT"},"action":"update","data":[{"asks":[["0.00000074717","671763109","0","1"],["0.00000074817","0","0","0"]],"bids":[],"ts":"1646003668528","checksum":-604644245}]}
1646003668.546561: {"arg":{"channel":"books-l2-tbt","instId":"ZEN-USDT"},"action":"update","data":[{"asks":[["32.62","16.151361","0","1"],["44.23","0","0","0"]],"bids":[["32.47","67.151361","0","2"]],"ts":"1646003668533","checksum":-1316690874}]}
1646003668.552883: {"arg":{"channel":"books-l2-tbt","instId":"UNI-USD-SWAP"},"action":"update","data":[{"asks":[],"bids":[["9.623","22","0","1"],["9.602","40","0","2"],["9.601","0","0","0"],["9.544","0","0","0"]],"ts":"1646003668537","checksum":-147654922}]}
1646003668.561097: {"arg":{"channel":"books-l2-tbt","instId":"BTC-USD-220325-40000-C"},"action":"update","data":[{"asks":[["0.0515","334","0","2"],["0.052","301","0","1"]],"bids":[],"ts":"1646003668546","checksum":-942407113}]}
1646003668.561225: {"arg":{"channel":"books-l2-tbt","instId":"ELON-USDT"},"action":"update","data":[{"asks":[["0.00000074512","263810383","0","3"],["0.00000074692","3205680429","0","1"],["0.00000113315","0","0","0"]],"bids":[],"ts":"1646003668546","checksum":1896250127}]}
1646003668.5613189: {"arg":{"channel":"books-l2-tbt","instId":"UNI-USD-SWAP"},"action":"update","data":[{"asks":[],"bids":[["9.621","2","0","1"],["9.615","1045","0","2"],["9.614","0","0","0"]],"ts":"1646003668548","checksum":2080146543}]}
1646003668.567862: {"arg":{"channel":"books-l2-tbt","instId":"ELON-USDT"},"action":"update","data":[{"asks":[["0.00000074511","445226872","0","1"],["0.00000074717","0","0","0"],["0.00000074817","671763109","0","1"],["0.00000113256","0","0","0"]],"bids":[],"ts":"1646003668555","checksum":-1148864438}]}
1646003668.567946: {"arg":{"channel":"books-l2-tbt","instId":"UNI-USD-SWAP"},"action":"update","data":[{"asks":[["9.635","0","0","0"],["48.868","1","0","1"]],"bids":[["9.62","135","0","2"],["9.591","0","0","0"]],"ts":"1646003668557","checksum":630218880}]}
1646003668.579916: {"arg":{"channel":"books-l2-tbt","instId":"ELON-USDT"},"action":"update","data":[{"asks":[["0.00000074512","332380729","0","4"]],"bids":[],"ts":"1646003668567","checksum":1156413273}]}
1646003668.580545: {"arg":{"channel":"books-l2-tbt","instId":"UNI-USD-SWAP"},"action":"update","data":[{"asks":[],"bids":[["9.615","1046","0","2"],["9.594","383","0","3"],["9.551","160","0","1"]],"ts":"1646003668568","checksum":620004983}]}
1646003668.583928: {"arg":{"channel":"books-l2-tbt","instId":"ETH-USD-220429-1900-P"},"action":"update","data":[{"asks":[["0.0375","0","0","0"],["0.038","1506","0","3"]],"bids":[],"ts":"1646003668573","checksum":-1328280565}]}
1646003668.5876029: {"arg":{"channel":"books-l2-tbt","instId":"ELON-USDT"},"action":"update","data":[{"asks":[["0.00000074512","68570346","0","1"]],"bids":[["0.00000074101","750000000","0","1"]],"ts":"1646003668576","checksum":2027514549}]}
1646003668.591511: {"arg":{"channel":"books-l2-tbt","instId":"UNI-USD-SWAP"},"action":"update","data":[{"asks":[],"bids":[["9.623","23","0","2"],["9.599","636","0","3"],["9.596","159","0","2"]],"ts":"1646003668578","checksum":-755489114}]}
1646003668.597862: {"arg":{"channel":"books-l2-tbt","instId":"ELON-USDT"},"action":"update","data":[{"asks":[["0.0000007451","152061613","0","2"],["0.00000074514","133532947","0","2"],["0.00000074817","0","0","0"]],"bids":[],"ts":"1646003668586","checksum":-61712763}]}
1646003668.6032052: {"arg":{"channel":"books-l2-tbt","instId":"UNI-USD-SWAP"},"action":"update","data":[{"asks":[["9.636","2","0","1"],["48.868","0","0","0"]],"bids":[],"ts":"1646003668589","checksum":471399424}]}
1646003668.61243: {"arg":{"channel":"books-l2-tbt","instId":"ELON-USDT"},"action":"update","data":[{"asks":[["0.00000074513","0","0","0"],["0.00000074717","671767622","0","1"]],"bids":[],"ts":"1646003668596","checksum":1974475531}]}
1646003668.612555: {"arg":{"channel":"books-l2-tbt","instId":"UNI-USD-SWAP"},"action":"update","data":[{"asks":[["9.632","0","0","0"],["48.868","1","0","1"]],"bids":[["9.621","0","0","0"]],"ts":"1646003668599","checksum":-1082403462}]}
1646003668.625021: {"arg":{"channel":"books-l2-tbt","instId":"UNI-USD-SWAP"},"action":"update","data":[{"asks":[["9.629","88","0","1"],["48.868","0","0","0"]],"bids":[],"ts":"1646003668608","checksum":-1730727622}]}
1646003668.6293151: {"arg":{"channel":"books-l2-tbt","instId":"ELON-USDT"},"action":"update","data":[{"asks":[["0.00000074514","81175250","0","1"],["0.00000074522","0","0","0"],["0.00000113256","10462875","0","1"]],"bids":[],"ts":"1646003668616","checksum":-2131652525}]}
1646003668.630667: {"arg":{"channel":"books-l2-tbt","instId":"UNI-USD-SWAP"},"action":"update","data":[{"asks":[["9.653","0","0","0"],["48.868","1","0","1"]],"bids":[["9.579","64","0","1"]],"ts":"1646003668619","checksum":-556285926}]}
1646003668.641341: {"arg":{"channel":"books-l2-tbt","instId":"UNI-USD-SWAP"},"action":"update","data":[{"asks":[],"bids":[["9.584","35","0","1"]],"ts":"1646003668630","checksum":-556285926}]}
1646003668.658883: {"arg":{"channel":"books-l2-tbt","instId":"UNI-USD-SWAP"},"action":"update","data":[{"asks":[["9.664","64","0","1"]],"bids":[["9.621","2","0","1"]],"ts":"1646003668641","checksum":729992267}]}
1646003668.662279: {"arg":{"channel":"books-l2-tbt","instId":"UNI-USD-SWAP"},"action":"update","data":[{"asks":[["9.665","36","0","1"],["48.868","0","0","0"]],"bids":[],"ts":"1646003668650","checksum":-575766921}]}
1646003668.6698308: {"arg":{"channel":"books-l2-tbt","instId":"ELON-USDT"},"action":"update","data":[{"asks":[["0.00000074509","445226872","0","1"],["0.00000113256","0","0","0"]],"bids":[],"ts":"1646003668658","checksum":-1920005741}]}
1646003668.67304: {"arg":{"channel":"books-l2-tbt","instId":"UNI-USD-SWAP"},"action":"update","data":[{"asks":[],"bids":[["9.623","22","0","1"]],"ts":"1646003668660","checksum":1595053168}]}
1646003668.678249: {"arg":{"channel":"books-l2-tbt","instId":"ELON-USDT"},"action":"update","data":[{"asks":[],"bids":[["0.00000074349","0","0","0"]],"ts":"1646003668667","checksum":-628926105}]}
1646003668.689274: {"arg":{"channel":"books-l2-tbt","instId":"ELON-USDT"},"action":"update","data":[{"asks":[["0.0000007451","0","0","0"],["0.00000113256","10462875","0","1"]],"bids":[],"ts":"1646003668676","checksum":449334964}]}
1646003668.6928241: {"arg":{"channel":"books-l2-tbt","instId":"UNI-USD-SWAP"},"action":"update","data":[{"asks":[],"bids":[["9.622","282","0","2"]],"ts":"1646003668680","checksum":-952399541}]}
1646003668.7046: {"arg":{"channel":"books-l2-tbt","instId":"UNI-USD-SWAP"},"action":"update","data":[{"asks":[["9.658","35","0","1"],["48.625","0","0","0"]],"bids":[["9.428","0","0","0"]],"ts":"1646003668692","checksum":-619917513}]}
1646003668.7105632: {"arg":{"channel":"books-l2-tbt","instId":"ELON-USDT"},"action":"update","data":[{"asks":[["0.00000074508","104045940","0","1"],["0.00000074511","0","0","0"]],"bids":[],"ts":"1646003668698","checksum":-1250843357}]}
1646003668.7167082: {"arg":{"channel":"books-l2-tbt","instId":"UNI-USD-SWAP"},"action":"update","data":[{"asks":[["9.646","0","0","0"],["48.625","1","0","1"]],"bids":[["9.578","0","0","0"],["9.467","0","0","0"],["9.378","0","0","0"]],"ts":"1646003668702","checksum":1111211242}]}
1646003668.717655: {"arg":{"channel":"books-l2-tbt","instId":"ELON-USDT"},"action":"update","data":[{"asks":[["0.0000007466","0","0","0"],["0.00000113315","35900750","0","1"]],"bids":[["0.00000074331","184440410","0","1"]],"ts":"1646003668707","checksum":-1369445374}]}
1646003668.728506: {"arg":{"channel":"books-l2-tbt","instId":"UNI-USD-SWAP"},"action":"update","data":[{"asks":[],"bids":[["9.439","320","0","1"]],"ts":"1646003668715","checksum":1111211242}]}
1646003668.7326689: {"arg":{"channel":"books-l2-tbt","instId":"ELON-USDT"},"action":"update","data":[{"asks":[["0.00000074509","0","0","0"],["0.0000011338","129154981","0","1"]],"bids":[],"ts":"1646003668719","checksum":-2040040712}]}
1646003668.735768: {"arg":{"channel":"books-l2-tbt","instId":"UNI-USD-SWAP"},"action":"update","data":[{"asks":[["9.637","237","0","2"]],"bids":[],"ts":"1646003668725","checksum":1312543338}]}
1646003668.7402701: {"arg":{"channel":"books-l2-tbt","instId":"ELON-USDT"},"action":"update","data":[{"asks":[["0.00000074508","0","0","0"],["0.0000011372","6179288","0","1"]],"bids":[["0.0000007435","0","0","0"]],"ts":"1646003668728","checksum":-783348859}]}
1646003668.7514281: {"arg":{"channel":"books-l2-tbt","instId":"ELON-USDT"},"action":"update","data":[{"asks":[],"bids":[["0.00000074246","0","0","0"]],"ts":"1646003668739","checksum":-981100818}]}
1646003668.761454: {"arg":{"channel":"books-l2-tbt","instId":"ELON-USDT"},"action":"update","data":[{"asks":[["0.00000074507","445226872","0","1"],["0.0000011372","0","0","0"]],"bids":[["0.00000074184","0","0","0"]],"ts":"1646003668749","checksum":171565560}]}
1646003668.767895: {"arg":{"channel":"books-l2-tbt","instId":"UNI-USD-SWAP"},"action":"update","data":[{"asks":[],"bids":[["9.585","10027","0","4"]],"ts":"1646003668756","checksum":1312543338}]}
1646003668.768484: {"arg":{"channel":"books-l2-tbt","instId":"ELON-USDT"},"action":"update","data":[{"asks":[["0.00000074692","0","0","0"],["0.0000011372","6179288","0","1"]],"bids":[],"ts":"1646003668758","checksum":1961108497}]}
1646003668.7796428: {"arg":{"channel":"books-l2-tbt","instId":"UNI-USD-SWAP"},"action":"update","data":[{"asks":[["9.652","37","0","2"]],"bids":[["9.584","99","0","2"],["9.476","240","0","1"],["9.39","320","0","1"]],"ts":"1646003668765","checksum":1885056949}]}
1646003668.7801678: {"arg":{"channel":"books-l2-tbt","instId":"ELON-USDT"},"action":"update","data":[{"asks":[["0.00000074506","52357697","0","1"],["0.00000074511","445226872","0","1"],["0.00000074512","0","0","0"],["0.00000074717","0","0","0"],["0.00000074817","671853374","0","1"],["0.0000011372","0","0","0"]],"bids":[["0.00000074244","4038943392","0","1"]],"ts":"1646003668769","checksum":-20537737}]}
1646003668.7905369: {"arg":{"channel":"books-l2-tbt","instId":"ELON-USDT"},"action":"update","data":[{"asks":[["0.00000074506","164106467","0","2"],["0.00000074728","3206218884","0","1"],["0.0000011338","0","0","0"]],"bids":[["0.00000074118","2939014230","0","1"]],"ts":"1646003668779","checksum":-1071392565}]}
1646003668.802081: {"arg":{"channel":"books-l2-tbt","instId":"ELON-USDT"},"action":"update","data":[{"asks":[["0.00000074507","0","0","0"],["0.00000074728","0","0","0"],["0.0000011338","129154981","0","1"],["0.0000011372","6179288","0","1"]],"bids":[],"ts":"1646003668789","checksum":276544428}]}
1646003668.8021839: {"arg":{"channel":"books-l2-tbt","instId":"PROPS-ETH"},"action":"update","data":[{"asks":[["0.00000177","0","0","0"],["0.00000178","0","0","0"],["0.00000183","764.65984068","0","1"],["0.00000184","715.7196382","0","1"],["0.00000185","673.38419187","0","1"],["0.00000186","1297.98811139","0","1"],["0.00000187","1382.96154867","0","1"]],"bids":[["0.00000161","9040.40945116","0","1"],["0.0000016","0","0","0"]],"ts":"1646003668792","checksum":-1062666057}]}
1646003668.807847: {"arg":{"channel":"books-l2-tbt","instId":"ZEN-USDT"},"action":"update","data":[{"asks":[["33","0.496261","0","2"]],"bids":[],"ts":"1646003668796","checksum":1407137543}]}
1646003668.8214421: {"arg":{"channel":"books-l2-tbt","instId":"ELON-USDT"},"action":"update","data":[{"asks":[["0.00000074506","52357697","0","1"],["0.00000074613","4038943392","0","1"],["0.00000074659","0","0","0"]],"bids":[],"ts":"1646003668809","checksum":-465018232}]}
1646003668.8299992: {"arg":{"channel":"books-l2-tbt","instId":"ELON-USDT"},"action":"update","data":[{"asks":[["0.00000074692","3072626430","0","1"],["0.0000011372","0","0","0"]],"bids":[],"ts":"1646003668819","checksum":-1414108900}]}
1646003668.840512: {"arg":{"channel":"books-l2-tbt","instId":"ZEN-USDT"},"action":"update","data":[{"asks":[],"bids":[["32.45","0","0","0"]],"ts":"1646003668827","checksum":-58752036}]}
1646003668.840589: {"arg":{"channel":"books-l2-tbt","instId":"UNI-USD-SWAP"},"action":"update","data":[{"asks":[["9.628","0","0","0"],["48.868","1","0","1"]],"bids":[],"ts":"1646003668828","checksum":343072799}]}
1646003668.8455548: {"arg":{"channel":"books-l2-tbt","instId":"ELON-USDT"},"action":"update","data":[{"asks":[["0.0000007451","111748770","0","1"],["0.0000007466","698000000","0","1"],["0.00000113315","0","0","0"],["0.0000011338","0","0","0"]],"bids":[],"ts":"1646003668830","checksum":1005137920}]}
1646003668.8511229: {"arg":{"channel":"books-l2-tbt","instId":"UNI-USD-SWAP"},"action":"update","data":[{"asks":[["9.64","167","0","2"],["9.644","1022","0","3"],["9.65","64","0","1"],["9.659","160","0","1"],["48.868","0","0","0"]],"bids":[],"ts":"1646003668840","checksum":-850587269}]}
1646003668.861985: {"arg":{"channel":"books-l2-tbt","instId":"UNI-USD-SWAP"},"action":"update","data":[{"asks":[["9.629","0","0","0"],["9.632","88","0","1"]],"bids":[["9.623","24","0","2"],["9.622","294","0","3"],["9.62","188","0","3"],["9.619","272","0","2"]],"ts":"1646003668848","checksum":-1603871491}]}
1646003668.862137: {"arg":{"channel":"books-l2-tbt","instId":"ELON-USDT"},"action":"update","data":[{"asks":[["0.00000074505","86557237","0","1"],["0.00000113256","0","0","0"]],"bids":[],"ts":"1646003668849","checksum":679892836}]}
1646003668.869523: {"arg":{"channel":"books-l2-tbt","instId":"UNI-USD-SWAP"},"action":"update","data":[{"asks":[["9.647","2534","0","4"],["9.655","206","0","2"]],"bids":[["9.621","0","0","0"],["9.585","10003","0","3"],["9.584","143","0","3"],["9.581","0","0","0"]],"ts":"1646003668858","checksum":-870000196}]}
1646003668.872695: {"arg":{"channel":"books-l2-tbt","instId":"ELON-USDT"},"action":"update","data":[{"asks":[["0.00000074511","0","0","0"],["0.00000074717","671880459","0","1"],["0.00000074817","0","0","0"],["0.00000113256","10462875","0","1"]],"bids":[],"ts":"1646003668860","checksum":1335998431}]}
1646003668.881769: {"arg":{"channel":"books-l2-tbt","instId":"UNI-USD-SWAP"},"action":"update","data":[{"asks":[["9.631","260","0","1"],["48.625","0","0","0"]],"bids":[["9.61","0","0","0"]],"ts":"1646003668869","checksum":878650857}]}
1646003668.886015: {"arg":{"channel":"books-l2-tbt","instId":"ELON-USDT"},"action":"update","data":[{"asks":[["0.00000074504","48015673","0","1"],["0.0000007451","0","0","0"]],"bids":[],"ts":"1646003668875","checksum":-1968943019}]}
1646003668.8957682: {"arg":{"channel":"books-l2-tbt","instId":"ELON-USDT"},"action":"update","data":[{"asks":[["0.00000074504","159764443","0","2"]],"bids":[],"ts":"1646003668881","checksum":1978787658}]}
1646003668.903109: {"arg":{"channel":"books-l2-tbt","instId":"UNI-USD-SWAP"},"action":"update","data":[{"asks":[],"bids":[["9.621","2","0","1"]],"ts":"1646003668890","checksum":843838677}]}
1646003668.915401: {"arg":{"channel":"books-l2-tbt","instId":"UNI-USD-SWAP"},"action":"update","data":[{"asks":[],"bids":[["9.623","22","0","1"]],"ts":"1646003668900","checksum":530166452}]}
1646003668.915482: {"arg":{"channel":"books-l2-tbt","instId":"ELON-USDT"},"action":"update","data":[{"asks":[["0.00000074503","445226872","0","1"],["0.00000113256","0","0","0"]],"bids":[["0.00000074101","0","0","0"]],"ts":"1646003668902","checksum":960696106}]}
1646003668.9248068: {"arg":{"channel":"books-l2-tbt","instId":"ELON-USDT"},"action":"update","data":[{"asks":[],"bids":[["0.0000006993","0","0","0"],["0.00000068532","0","0","0"],["0.00000067162","0","0","0"],["0.00000065819","0","0","0"],["0.00000064475","416429401","0","1"]],"ts":"1646003668912","checksum":960696106}]}
1646003668.93361: {"arg":{"channel":"books-l2-tbt","instId":"ELON-USDT"},"action":"update","data":[{"asks":[["0.00000074504","0","0","0"],["0.00000113256","10462875","0","1"]],"bids":[],"ts":"1646003668923","checksum":-242108952}]}
1646003668.944814: {"arg":{"channel":"books-l2-tbt","instId":"ZEN-USDT"},"action":"update","data":[{"asks":[["32.98","7.54","0","1"],["44.22","0","0","0"]],"bids":[],"ts":"1646003668930","checksum":-195407929}]}
1646003668.944903: {"arg":{"channel":"books-l2-tbt","instId":"ELON-USDT"},"action":"update","data":[{"asks":[["0.00000074502","263810383","0","3"],["0.00000074505","0","0","0"]],"bids":[],"ts":"1646003668933","checksum":-1372619415}]}
1646003668.9630861: {"arg":{"channel":"books-l2-tbt","instId":"UNI-USD-SWAP"},"action":"update","data":[{"asks":[["9.632","0","0","0"],["48.625","1","0","1"]],"bids":[],"ts":"1646003668952","checksum":907801957}]}
1646003668.9654038: {"arg":{"channel":"books-l2-tbt","instId":"ELON-USDT"},"action":"update","data":[{"asks":[["0.00000074503","0","0","0"],["0.00000113315","35900750","0","1"]],"bids":[],"ts":"1646003668954","checksum":-1356639842}]}
1646003668.9833212: {"arg":{"channel":"books-l2-tbt","instId":"UNI-USD-SWAP"},"action":"update","data":[{"asks":[],"bids":[["9.623","23","0","2"]],"ts":"1646003668972","checksum":-704354134}]}
1646003668.987266: {"arg":{"channel":"books-l2-tbt","instId":"ELON-USDT"},"action":"update","data":[{"asks":[["0.00000074501","498334595","0","2"],["0.00000074502","215794710","0","2"],["0.00000113315","0","0","0"]],"bids":[],"ts":"1646003668976","checksum":-946602315}]}
1646003668.995051: {"arg":{"channel":"books-l2-tbt","instId":"UNI-USD-SWAP"},"action":"update","data":[{"asks":[],"bids":[["9.621","0","0","0"]],"ts":"1646003668983","checksum":-1879306614}]}
1646003669.027495: {"arg":{"channel":"books-l2-tbt","instId":"ELON-USDT"},"action":"update","data":[{"asks":[["0.00000074502","0","0","0"],["0.00000074506","0","0","0"],["0.00000113315","35900750","0","1"],["0.0000011338","129154981","0","1"]],"bids":[],"ts":"1646003669015","checksum":244691827}]}
1646003669.03792: {"arg":{"channel":"books-l2-tbt","instId":"ELON-USDT"},"action":"update","data":[{"asks":[["0.00000074501","566904941","0","3"],["0.00000074589","48015673","0","1"],["0.0000011338","0","0","0"]],"bids":[],"ts":"1646003669026","checksum":-1494173403}]}
1646003669.048247: {"arg":{"channel":"books-l2-tbt","instId":"ELON-USDT"},"action":"update","data":[{"asks":[["0.000000745","104045940","0","1"],["0.00000074589","0","0","0"]],"bids":[],"ts":"1646003669037","checksum":1610632491}]}
1646003669.0574908: {"arg":{"channel":"books-l2-tbt","instId":"ETH-USD-220429-1900-P"},"action":"update","data":[{"asks":[["0.0375","500","0","1"],["0.038","1006","0","2"]],"bids":[],"ts":"1646003669047","checksum":356118983}]}
1646003669.060019: {"arg":{"channel":"books-l2-tbt","instId":"ELON-USDT"},"action":"update","data":[{"asks":[["0.000000745","152061613","0","2"]],"bids":[],"ts":"1646003669048","checksum":1585270571}]}
1646003669.067688: {"arg":{"channel":"books-l2-tbt","instId":"ZEN-USDT"},"action":"update","data":[{"asks":[],"bids":[["32.45","56.237359","0","1"]],"ts":"1646003669055","checksum":-1348422684}]}
1646003669.068345: {"arg":{"channel":"books-l2-tbt","instId":"UNI-USD-SWAP"},"action":"update","data":[{"asks":[["9.63","88","0","1"],["48.625","0","0","0"]],"bids":[],"ts":"1646003669057","checksum":1782297806}]}
1646003669.0797281: {"arg":{"channel":"books-l2-tbt","instId":"ELON-USDT"},"action":"update","data":[{"asks":[["0.00000074499","445226872","0","1"],["0.000000745","104045940","0","1"],["0.00000113315","0","0","0"]],"bids":[],"ts":"1646003669067","checksum":-1926509305}]}
1646003669.0888891: {"arg":{"channel":"books-l2-tbt","instId":"UNI-USD-SWAP"},"action":"update","data":[{"asks":[["9.629","260","0","1"],["48.383","0","0","0"]],"bids":[],"ts":"1646003669078","checksum":-1472713427}]}
1646003669.0986629: {"arg":{"channel":"books-l2-tbt","instId":"ELON-USDT"},"action":"update","data":[{"asks":[["0.000000745","0","0","0"],["0.00000074501","121678069","0","2"],["0.00000074613","0","0","0"],["0.00000113315","35900750","0","1"],["0.0000011338","129154981","0","1"]],"bids":[["0.00000073914","750000000","0","1"]],"ts":"1646003669087","checksum":-1682655613}]}
1646003669.098772: {"arg":{"channel":"books-l2-tbt","instId":"UNI-USD-SWAP"},"action":"update","data":[{"asks":[],"bids":[["9.621","2","0","1"]],"ts":"1646003669087","checksum":-1486060213}]}
1646003669.107127: {"arg":{"channel":"books-l2-tbt","instId":"UNI-USD-SWAP"},"action":"update","data":[{"asks":[],"bids":[["9.623","22","0","1"],["9.62","135","0","2"]],"ts":"1646003669096","checksum":-1202720436}]}
1646003669.124202: {"arg":{"channel":"books-l2-tbt","instId":"UNI-USD-SWAP"},"action":"update","data":[{"asks":[],"bids":[["9.619","325","0","3"]],"ts":"1646003669107","checksum":-911780698}]}
1646003669.124256: {"arg":{"channel":"books-l2-tbt","instId":"ELON-USDT"},"action":"update","data":[{"asks":[["0.00000074498","104045940","0","1"],["0.00000074514","0","0","0"],["0.00000074608","4038943392","0","1"],["0.0000011338","0","0","0"]],"bids":[["0.00000074348","219861835","0","1"]],"ts":"1646003669108","checksum":1351086680}]}
1646003669.129348: {"arg":{"channel":"books-l2-tbt","instId":"ELON-USDT"},"action":"update","data":[{"asks":[["0.00000074692","0","0","0"],["0.00000074717","0","0","0"],["0.00000074817","671903030","0","1"],["0.0000011338","129154981","0","1"]],"bids":[],"ts":"1646003669119","checksum":-472639572}]}
1646003669.1293938: {"arg":{"channel":"books-l2-tbt","instId":"UNI-USD-SWAP"},"action":"update","data":[{"asks":[],"bids":[["9.621","0","0","0"],["9.618","2","0","1"]],"ts":"1646003669119","checksum":-654935401}]}
1646003669.142317: {"arg":{"channel":"books-l2-tbt","instId":"ELON-USDT"},"action":"update","data":[{"asks":[["0.00000074498","0","0","0"],["0.0000011372","6179288","0","1"]],"bids":[],"ts":"1646003669128","checksum":964587852}]}
1646003669.1504261: {"arg":{"channel":"books-l2-tbt","instId":"ELON-USDT"},"action":"update","data":[{"asks":[],"bids":[["0.00000074349","184440410","0","1"]],"ts":"1646003669138","checksum":56348791}]}
1646003669.1532888: {"arg":{"channel":"books-l2-tbt","instId":"ETH-USD-220429-1900-P"},"action":"update","data":[{"asks":[["0.0375","0","0","0"],["0.038","1506","0","3"]],"bids":[],"ts":"1646003669142","checksum":-1328280565}]}
1646003669.162451: {"arg":{"channel":"books-l2-tbt","instId":"UNI-USD-SWAP"},"action":"update","data":[{"asks":[["9.63","0","0","0"],["48.383","1","0","1"]],"bids":[["9.583","203","0","2"]],"ts":"1646003669150","checksum":-27022925}]}
1646003669.162581: {"arg":{"channel":"books-l2-tbt","instId":"ELON-USDT"},"action":"update","data":[{"asks":[["0.00000074497","445226872","0","1"],["0.00000074691","3339586958","0","1"],["0.0000011338","0","0","0"],["0.0000011372","0","0","0"]],"bids":[],"ts":"1646003669150","checksum":2119963598}]}
1646003669.1773162: {"arg":{"channel":"books-l2-tbt","instId":"UNI-USD-SWAP"},"action":"update","data":[{"asks":[["9.631","0","0","0"],["48.625","1","0","1"]],"bids":[],"ts":"1646003669160","checksum":-345693646}]}
1646003669.1817029: {"arg":{"channel":"books-l2-tbt","instId":"ELON-USDT"},"action":"update","data":[{"asks":[["0.0000007459","1677874074","0","1"],["0.00000074608","0","0","0"],["0.0000011338","129154981","0","1"]],"bids":[],"ts":"1646003669170","checksum":-499649342}]}
1646003669.181845: {"arg":{"channel":"books-l2-tbt","instId":"UNI-USD-SWAP"},"action":"update","data":[{"asks":[],"bids":[["9.62","136","0","3"]],"ts":"1646003669170","checksum":-1990502594}]}
1646003669.192163: {"arg":{"channel":"books-l2-tbt","instId":"ELON-USDT"},"action":"update","data":[{"asks":[["0.00000074496","52357697","0","1"],["0.00000074499","0","0","0"],["0.00000074501","0","0","0"],["0.0000011372","6179288","0","1"]],"bids":[["0.00000074331","0","0","0"]],"ts":"1646003669180","checksum":-301198565}]}
1646003669.196169: {"arg":{"channel":"books-l2-tbt","instId":"UNI-USD-SWAP"},"action":"update","data":[{"asks":[],"bids":[["9.618","0","0","0"],["9.583","160","0","1"]],"ts":"1646003669182","checksum":1055412222}]}
1646003669.201945: {"arg":{"channel":"books-l2-tbt","instId":"ELON-USDT"},"action":"update","data":[{"asks":[["0.00000074496","164106467","0","2"],["0.0000007455","1006901383","0","1"],["0.00000074589","81175250","0","1"],["0.00000074717","671830806","0","1"],["0.00000074817","0","0","0"],["0.0000011338","0","0","0"],["0.0000011372","0","0","0"]],"bids":[],"ts":"1646003669190","checksum":1479153371}]}
1646003669.20413: {"arg":{"channel":"books-l2-tbt","instId":"UNI-USD-SWAP"},"action":"update","data":[{"asks":[],"bids":[["9.621","2","0","1"]],"ts":"1646003669192","checksum":1956213861}]}
1646003669.212476: {"arg":{"channel":"books-l2-tbt","instId":"ELON-USDT"},"action":"update","data":[{"asks":[["0.00000074612","4038943392","0","1"],["0.00000113315","0","0","0"]],"bids":[],"ts":"1646003669200","checksum":1255727708}]}
1646003669.216726: {"arg":{"channel":"books-l2-tbt","instId":"UNI-USD-SWAP"},"action":"update","data":[{"asks":[],"bids":[["9.62","135","0","2"]],"ts":"1646003669203","checksum":1475979397}]}
1646003669.2350001: {"arg":{"channel":"books-l2-tbt","instId":"ELON-USDT"},"action":"update","data":[{"asks":[["0.00000074717","0","0","0"],["0.00000074817","671839833","0","1"]],"bids":[],"ts":"1646003669222","checksum":380576473}]}
1646003669.2356029: {"arg":{"channel":"books-l2-tbt","instId":"UNI-USD-SWAP"},"action":"update","data":[{"asks":[],"bids":[["9.605","29","0","1"]],"ts":"1646003669224","checksum":-198726699}]}
1646003669.242039: {"arg":{"channel":"books-l2-tbt","instId":"ZEN-USDT"},"action":"update","data":[{"asks":[["32.6","55.61469","0","2"]],"bids":[],"ts":"1646003669230","checksum":-1078742360}]}
1646003669.248186: {"arg":{"channel":"books-l2-tbt","instId":"UNI-USD-SWAP"},"action":"update","data":[{"asks":[],"bids":[["9.608","27","0","1"],["9.607","0","0","0"],["9.606","103","0","2"],["9.603","1276","0","2"],["9.602","16","0","1"],["9.585","464","0","2"]],"ts":"1646003669233","checksum":1524196701}]}
1646003669.257055: {"arg":{"channel":"books-l2-tbt","instId":"UNI-USD-SWAP"},"action":"update","data":[{"asks":[],"bids":[["9.59","11087","0","4"]],"ts":"1646003669245","checksum":-374843431}]}
1646003669.26378: {"arg":{"channel":"books-l2-tbt","instId":"ELON-USDT"},"action":"update","data":[{"asks":[["0.00000074495","445226872","0","1"],["0.00000113256","0","0","0"]],"bids":[],"ts":"1646003669252","checksum":-535664996}]}
1646003669.266764: {"arg":{"channel":"books-l2-tbt","instId":"UNI-USD-SWAP"},"action":"update","data":[{"asks":[["9.629","348","0","2"]],"bids":[],"ts":"1646003669254","checksum":1702161240}]}
1646003669.272289: {"arg":{"channel":"books-l2-tbt","instId":"ETH-USD-220624-12000-P"},"action":"update","data":[{"asks":[["4.041","201","0","1"],["4.0435","0","0","0"]],"bids":[],"ts":"1646003669260","checksum":1608499872}]}
1646003669.275554: {"arg":{"channel":"books-l2-tbt","instId":"ELON-USDT"},"action":"update","data":[{"asks":[["0.00000074612","0","0","0"],["0.00000074717","671839833","0","1"],["0.00000074817","0","0","0"],["0.00000113256","10462875","0","1"]],"bids":[],"ts":"1646003669264","checksum":734398955}]}
1646003669.288074: {"arg":{"channel":"books-l2-tbt","instId":"ELON-USDT"},"action":"update","data":[{"asks":[["0.00000074494","48015673","0","1"],["0.00000074496","52357697","0","1"],["0.00000074497","0","0","0"]],"bids":[],"ts":"1646003669275","checksum":-454905717}]}
1646003669.288165: {"arg":{"channel":"books-l2-tbt","instId":"UNI-USD-SWAP"},"action":"update","data":[{"asks":[["9.65","0","0","0"],["48.868","1","0","1"]],"bids":[],"ts":"1646003669277","checksum":-988526555}]}
1646003669.296018: {"arg":{"channel":"books-l2-tbt","instId":"ZEN-USDT"},"action":"update","data":[{"asks":[],"bids":[["32.18","4.010396","0","3"],["32.17","0","0","0"]],"ts":"1646003669283","checksum":-382483154}]}
1646003669.297577: {"arg":{"channel":"books-l2-tbt","instId":"ELON-USDT"},"action":"update","data":[{"asks":[["0.00000074494","159764443","0","2"]],"bids":[["0.00000073914","0","0","0"]],"ts":"1646003669286","checksum":-297424829}]}
1646003669.297706: {"arg":{"channel":"books-l2-tbt","instId":"UNI-USD-SWAP"},"action":"update","data":[{"asks":[["9.637","313","0","2"]],"bids":[],"ts":"1646003669286","checksum":889411997}]}
1646003669.310878: {"arg":{"channel":"books-l2-tbt","instId":"PROPS-ETH"},"action":"update","data":[{"asks":[],"bids":[["0.0000016","9796.69504114","0","1"]],"ts":"1646003669288","checksum":-267945373}]}
1646003669.310993: {"arg":{"channel":"books-l2-tbt","instId":"ETH-USD-220325-8800-P"},"action":"update","data":[{"asks":[["2.5465","201","0","1"],["2.548","0","0","0"]],"bids":[],"ts":"1646003669293","checksum":75253033}]}
1646003669.3110578: {"arg":{"channel":"books-l2-tbt","instId":"PROPS-ETH"},"action":"update","data":[{"asks":[["0.00000177","1339.37317295","0","1"],["0.00000178","1388.45769404","0","1"],["0.00000184","0","0","0"],["0.00000186","0","0","0"],["0.00000187","0","0","0"]],"bids":[["0.00000161","0","0","0"]],"ts":"1646003669298","checksum":-347279987}]}
1646003669.318301: {"arg":{"channel":"books-l2-tbt","instId":"UNI-USD-SWAP"},"action":"update","data":[{"asks":[["9.655","270","0","3"]],"bids":[],"ts":"1646003669306","checksum":1117708238}]}
1646003669.321447: {"arg":{"channel":"books-l2-tbt","instId":"ELON-USDT"},"action":"update","data":[{"asks":[["0.00000074717","0","0","0"],["0.00000074817","671848860","0","1"]],"bids":[],"ts":"1646003669309","checksum":-36004443}]}
1646003669.3268511: {"arg":{"channel":"books-l2-tbt","instId":"ELON-USDT"},"action":"update","data":[{"asks":[],"bids":[["0.00000074433","1074958177","0","1"],["0.0000007435","1199400000","0","1"],["0.00000074236","0","0","0"],["0.00000074129","400144970","0","1"],["0.00000073546","709298247","0","1"],["0.00000073447","0","0","0"],["0.00000072748","0","0","0"]],"ts":"1646003669316","checksum":-124532578}]}
1646003669.336245: {"arg":{"channel":"books-l2-tbt","instId":"ELON-USDT"},"action":"update","data":[{"asks":[["0.00000074494","263810383","0","3"]],"bids":[],"ts":"1646003669325","checksum":933355753}]}
1646003669.350066: {"arg":{"channel":"books-l2-tbt","instId":"ELON-USDT"},"action":"update","data":[{"asks":[["0.00000074493","445226872","0","1"],["0.00000074494","152061613","0","2"],["0.00000113256","0","0","0"]],"bids":[["0.0000007438","1393961017","0","1"]],"ts":"1646003669337","checksum":1524231990}]}
1646003669.360381: {"arg":{"channel":"books-l2-tbt","instId":"ELON-USDT"},"action":"update","data":[{"asks":[],"bids":[["0.00000074351","184440410","0","1"]],"ts":"1646003669346","checksum":-1476254364}]}
1646003669.368406: {"arg":{"channel":"books-l2-tbt","instId":"ELON-USDT"},"action":"update","data":[{"asks":[["0.00000074494","0","0","0"],["0.00000074495","0","0","0"],["0.00000113256","10462875","0","1"],["0.00000113315","35900750","0","1"]],"bids":[],"ts":"1646003669357","checksum":-2076747793}]}
1646003669.376935: {"arg":{"channel":"books-l2-tbt","instId":"ELON-USDT"},"action":"update","data":[{"asks":[["0.00000074492","104045940","0","1"],["0.00000113315","0","0","0"]],"bids":[],"ts":"1646003669366","checksum":-1872687405}]}
1646003669.3984158: {"arg":{"channel":"books-l2-tbt","instId":"ELON-USDT"},"action":"update","data":[{"asks":[["0.00000074492","152061613","0","2"],["0.00000074496","0","0","0"],["0.00000113315","35900750","0","1"]],"bids":[["0.00000074349","0","0","0"]],"ts":"1646003669387","checksum":-1530832302}]}
1646003669.408639: {"arg":{"channel":"books-l2-tbt","instId":"ELON-USDT"},"action":"update","data":[{"asks":[],"bids":[["0.0000007435","0","0","0"]],"ts":"1646003669397","checksum":1333171133}]}
1646003669.41592: {"arg":{"channel":"books-l2-tbt","instId":"UNI-USD-SWAP"},"action":"update","data":[{"asks":[],"bids":[["9.62","188","0","3"],["9.619","272","0","2"]],"ts":"1646003669400","checksum":-49490491}]}
1646003669.419905: {"arg":{"channel":"books-l2-tbt","instId":"ELON-USDT"},"action":"update","data":[{"asks":[["0.00000074549","204362917","0","1"],["0.00000113315","0","0","0"]],"bids":[["0.00000064475","0","0","0"]],"ts":"1646003669408","checksum":-97942910}]}
