1646003682.726196: {"arg":{"channel":"books-l2-tbt","instId":"ZEN-USDT"},"action":"update","data":[{"asks":[["32.83","0","0","0"],["32.85","1.52","0","1"],["33.16","0.30161","0","1"],["33.18","3.93","0","1"],["33.49","0","0","0"],["33.51","8.591956","0","2"],["33.82","7.49715","0","2"],["33.84","8.68","0","1"],["34.15","0","0","0"],["34.17","11.02","0","1"],["44.23","0","0","0"]],"bids":[],"ts":"1646003682711","checksum":721097815}]}
1646003682.739583: {"arg":{"channel":"books-l2-tbt","instId":"ELON-USDT"},"action":"update","data":[{"asks":[["0.00000074553","78327785","0","2"],["0.00000074555","111748770","0","1"],["0.00000074557","81175250","0","1"],["0.00000113315","0","0","0"]],"bids":[],"ts":"1646003682722","checksum":1941706671}]}
1646003682.765835: {"arg":{"channel":"books-l2-tbt","instId":"ELON-USDT"},"action":"update","data":[{"asks":[],"bids":[["0.00000074447","0","0","0"]],"ts":"1646003682751","checksum":768969208}]}
1646003682.76927: {"arg":{"channel":"trades","instId":"ELON-USDT"},"data":[{"instId":"ELON-USDT","tradeId":"4253238","px":"0.00000074477","sz":"23093343","side":"buy","ts":"1646003682730"}]}
1646003682.779783: {"arg":{"channel":"books-l2-tbt","instId":"ELON-USDT"},"action":"update","data":[{"asks":[["0.00000074553","230389398","0","4"],["0.00000074555","0","0","0"],["0.00000074556","0","0","0"],["0.00000074697","0","0","0"],["0.00000113315","35900750","0","1"],["0.0000011338","129154981","0","1"],["0.0000011372","6179288","0","1"]],"bids":[],"ts":"1646003682755","checksum":433269642}]}
1646003682.785577: {"arg":{"channel":"books-l2-tbt","instId":"ELON-USDT"},"action":"update","data":[{"asks":[["0.00000074743","0","0","0"],["0.00000113812","12211658","0","1"]],"bids":[],"ts":"1646003682765","checksum":1208426482}]}
1646003682.7911098: {"arg":{"channel":"books-l2-tbt","instId":"ELON-USDT"},"action":"update","data":[{"asks":[["0.00000074553","342138168","0","5"],["0.00000074697","4038943392","0","1"],["0.00000113812","0","0","0"]],"bids":[["0.00000074381","184440410","0","1"],["0.00000074239","0","0","0"]],"ts":"1646003682776","checksum":-238212186}]}
1646003682.803422: {"arg":{"channel":"books-l2-tbt","instId":"ELON-USDT"},"action":"update","data":[{"asks":[["0.00000074553","230389398","0","4"],["0.00000074743","3336448818","0","1"],["0.0000011372","0","0","0"]],"bids":[],"ts":"1646003682784","checksum":1478894061}]}
1646003682.816101: {"arg":{"channel":"books-l2-tbt","instId":"ELON-USDT"},"action":"update","data":[{"asks":[["0.00000074697","0","0","0"],["0.0000011372","6179288","0","1"]],"bids":[],"ts":"1646003682795","checksum":1178416643}]}
1646003682.818858: {"arg":{"channel":"books-l2-tbt","instId":"ELON-USDT"},"action":"update","data":[{"asks":[["0.00000074697","4038943392","0","1"],["0.0000011372","0","0","0"]],"bids":[],"ts":"1646003682804","checksum":1478894061}]}
1646003682.8347661: {"arg":{"channel":"books-l2-tbt","instId":"ELON-USDT"},"action":"update","data":[{"asks":[["0.00000074552","445226872","0","1"],["0.00000074554","0","0","0"]],"bids":[["0.00000074435","184440410","0","1"]],"ts":"1646003682815","checksum":-327839866}]}
1646003682.8476748: {"arg":{"channel":"tickers","instId":"ELON-USDT"},"data":[{"instType":"SPOT","instId":"ELON-USDT","last":"0.00000074477","lastSz":"23093343","askPx":"0.00000074554","askSz":"433766141","bidPx":"0.00000074447","bidSz":"219861835","open24h":"0.0000007958","high24h":"0.0000008141","low24h":"0.00000073774","sodUtc0":"0.00000079427","sodUtc8":"0.00000080449","volCcy24h":"1215421","vol24h":"1551009069058","ts":"1646003682826"}]}
1646003682.856732: {"arg":{"channel":"books-l2-tbt","instId":"ELON-USDT"},"action":"update","data":[{"asks":[["0.00000074553","78327785","0","2"]],"bids":[["0.00000074381","0","0","0"]],"ts":"1646003682837","checksum":-682648311}]}
1646003682.889163: {"arg":{"channel":"books-l2-tbt","instId":"UNI-USD-SWAP"},"action":"update","data":[{"asks":[["9.638","843","0","5"],["9.639","0","0","0"],["9.641","215","0","3"],["9.642","25","0","1"],["9.644","25","0","1"],["9.645","50","0","1"]],"bids":[],"ts":"1646003682868","checksum":1573958741}]}
1646003682.898679: {"arg":{"channel":"books-l2-tbt","instId":"PROPS-ETH"},"action":"update","data":[{"asks":[["0.00000185","0","0","0"],["0.00000186","0","0","0"]],"bids":[],"ts":"1646003682873","checksum":-1870095057}]}
1646003682.898748: {"arg":{"channel":"books-l2-tbt","instId":"PROPS-ETH"},"action":"update","data":[{"asks":[["0.00000177","1498.22770635","0","1"],["0.00000178","1082.91397037","0","1"]],"bids":[["0.0000016","10296.24909558","0","1"]],"ts":"1646003682876","checksum":251808363}]}
1646003682.904871: {"arg":{"channel":"books-l2-tbt","instId":"ELON-USDT"},"action":"update","data":[{"asks":[["0.00000074551","151972284","0","2"],["0.0000011338","0","0","0"]],"bids":[],"ts":"1646003682882","checksum":-1446841695}]}
1646003682.90493: {"arg":{"channel":"books-l2-tbt","instId":"ELON-USDT"},"action":"update","data":[{"asks":[],"bids":[["0.0000007433","46525202","0","1"]],"ts":"1646003682891","checksum":-1957214747}]}
1646003682.918135: {"arg":{"channel":"books-l2-tbt","instId":"ELON-USDT"},"action":"update","data":[{"asks":[["0.00000074551","103956611","0","1"]],"bids":[["0.00000074435","0","0","0"]],"ts":"1646003682902","checksum":33457252}]}
1646003682.9270332: {"arg":{"channel":"books-l2-tbt","instId":"ELON-USDT"},"action":"update","data":[{"asks":[["0.0000007455","445226872","0","1"],["0.00000113315","0","0","0"]],"bids":[],"ts":"1646003682913","checksum":650511412}]}
1646003682.942107: {"arg":{"channel":"books-l2-tbt","instId":"ELON-USDT"},"action":"update","data":[{"asks":[],"bids":[["0.00000070565","144547580","0","1"],["0.00000069154","0","0","0"],["0.00000067771","0","0","0"],["0.00000066416","0","0","0"],["0.00000065074","247901333","0","1"]],"ts":"1646003682922","checksum":650511412}]}
1646003682.952555: {"arg":{"channel":"books-l2-tbt","instId":"ELON-USDT"},"action":"update","data":[{"asks":[["0.00000074551","0","0","0"],["0.00000074552","0","0","0"],["0.00000074553","53107723","0","1"],["0.00000074697","0","0","0"],["0.00000113315","35900750","0","1"],["0.0000011338","129154981","0","1"],["0.0000011372","6179288","0","1"]],"bids":[],"ts":"1646003682932","checksum":-1657650498}]}
1646003682.958049: {"arg":{"channel":"books-l2-tbt","instId":"ELON-USDT"},"action":"update","data":[{"asks":[["0.00000074549","52357697","0","1"],["0.0000011372","0","0","0"]],"bids":[],"ts":"1646003682942","checksum":-1843705794}]}
1646003682.9679081: {"arg":{"channel":"books-l2-tbt","instId":"ELON-USDT"},"action":"update","data":[{"asks":[["0.00000074698","4038943392","0","1"],["0.0000011338","0","0","0"]],"bids":[],"ts":"1646003682951","checksum":-1450310500}]}
1646003682.9909608: {"arg":{"channel":"books-l2-tbt","instId":"ELON-USDT"},"action":"update","data":[{"asks":[["0.00000074553","0","0","0"],["0.0000011338","129154981","0","1"]],"bids":[],"ts":"1646003682975","checksum":1844637817}]}
1646003683.003786: {"arg":{"channel":"books-l2-tbt","instId":"ELON-USDT"},"action":"update","data":[{"asks":[["0.00000074549","120928043","0","2"],["0.0000007455","0","0","0"],["0.0000011372","6179288","0","1"]],"bids":[["0.00000074435","184440410","0","1"]],"ts":"1646003682982","checksum":932858365}]}
1646003683.003865: {"arg":{"channel":"books-l2-tbt","instId":"ELON-USDT"},"action":"update","data":[{"asks":[["0.00000074549","232580922","0","3"]],"bids":[],"ts":"1646003682993","checksum":999499276}]}
1646003683.01608: {"arg":{"channel":"books-l2-tbt","instId":"ELON-USDT"},"action":"update","data":[{"asks":[["0.00000074548","445226872","0","1"],["0.00000074549","120928043","0","2"],["0.0000011372","0","0","0"]],"bids":[["0.00000074435","0","0","0"]],"ts":"1646003683001","checksum":629081945}]}
1646003683.023703: {"arg":{"channel":"books-l2-tbt","instId":"UNI-USD-SWAP"},"action":"update","data":[{"asks":[["9.628","80","0","1"],["9.631","751","0","3"],["48.625","0","0","0"]],"bids":[],"ts":"1646003683004","checksum":-1720791978}]}
1646003683.030213: {"arg":{"channel":"books-l2-tbt","instId":"ELON-USDT"},"action":"update","data":[{"asks":[["0.00000074548","556879751","0","2"]],"bids":[],"ts":"1646003683012","checksum":2093962845}]}
1646003683.03026: {"arg":{"channel":"books-l2-tbt","instId":"UNI-USD-SWAP"},"action":"update","data":[{"asks":[["9.631","651","0","2"]],"bids":[],"ts":"1646003683013","checksum":703381387}]}
1646003683.032827: {"arg":{"channel":"books-l2-tbt","instId":"ZEN-USDT"},"action":"update","data":[{"asks":[],"bids":[["32.43","15.38033","0","1"]],"ts":"1646003683020","checksum":-1166174168}]}
1646003683.045463: {"arg":{"channel":"books-l2-tbt","instId":"ELON-USDT"},"action":"update","data":[{"asks":[["0.00000076199","210944203","0","1"],["0.0000011338","0","0","0"]],"bids":[],"ts":"1646003683034","checksum":2093962845}]}
1646003683.054228: {"arg":{"channel":"books-l2-tbt","instId":"ZEN-USDT"},"action":"update","data":[{"asks":[["32.84","1.52","0","1"],["32.85","0","0","0"],["33.17","3.93","0","1"],["33.18","0","0","0"],["33.5","6.816261","0","3"],["33.51","2.271956","0","1"],["33.83","8.68","0","1"],["33.84","0","0","0"],["34.16","11.02","0","1"],["34.17","0","0","0"]],"bids":[["32.18","4.010396","0","3"],["32.17","0","0","0"]],"ts":"1646003683041","checksum":-907502536}]}
1646003683.0664132: {"arg":{"channel":"books-l2-tbt","instId":"ELON-USDT"},"action":"update","data":[{"asks":[],"bids":[["0.00000071188","289373870","0","3"]],"ts":"1646003683053","checksum":2093962845}]}
1646003683.0683599: {"arg":{"channel":"books-l2-tbt","instId":"UNI-USD-SWAP"},"action":"update","data":[{"asks":[["9.623","1","0","1"]],"bids":[],"ts":"1646003683056","checksum":-272211365}]}
1646003683.0899389: {"arg":{"channel":"books-l2-tbt","instId":"ELON-USDT"},"action":"update","data":[{"asks":[["0.00000074547","48015673","0","1"],["0.00000113315","0","0","0"]],"bids":[],"ts":"1646003683076","checksum":310156516}]}
1646003683.0900218: {"arg":{"channel":"books-l2-tbt","instId":"UNI-USD-SWAP"},"action":"update","data":[{"asks":[["9.617","0","0","0"],["9.628","580","0","2"],["9.631","151","0","1"],["48.625","1","0","1"]],"bids":[],"ts":"1646003683078","checksum":1333477033}]}
1646003683.108494: {"arg":{"channel":"books-l2-tbt","instId":"UNI-USD-SWAP"},"action":"update","data":[{"asks":[["9.62","0","0","0"],["9.622","83","0","1"]],"bids":[],"ts":"1646003683097","checksum":-1924413050}]}
1646003683.1191318: {"arg":{"channel":"books-l2-tbt","instId":"UNI-USD-SWAP"},"action":"update","data":[{"asks":[["9.619","260","0","1"],["48.625","0","0","0"]],"bids":[["9.613","1","0","1"]],"ts":"1646003683107","checksum":62093622}]}
1646003683.127682: {"arg":{"channel":"books-l2-tbt","instId":"UNI-USD-SWAP"},"action":"update","data":[{"asks":[["9.625","203","0","2"],["9.627","178","0","2"],["48.383","0","0","0"]],"bids":[["9.604","168","0","1"]],"ts":"1646003683117","checksum":1805690439}]}
1646003683.138447: {"arg":{"channel":"books-l2-tbt","instId":"ELON-USDT"},"action":"update","data":[{"asks":[["0.00000074546","445226872","0","1"],["0.00000113256","0","0","0"]],"bids":[["0.00000074202","176405012","0","1"]],"ts":"1646003683127","checksum":312589581}]}
1646003683.138539: {"arg":{"channel":"books-l2-tbt","instId":"UNI-USD-SWAP"},"action":"update","data":[{"asks":[["9.625","0","0","0"],["48.383","1","0","1"]],"bids":[["9.613","0","0","0"],["9.611","369","0","2"],["9.61","155","0","2"],["9.606","0","0","0"],["9.605","11","0","1"],["9.593","744","0","4"],["9.592","134","0","2"]],"ts":"1646003683128","checksum":755998214}]}
1646003683.149447: {"arg":{"channel":"books-l2-tbt","instId":"UNI-USD-SWAP"},"action":"update","data":[{"asks":[],"bids":[["9.605","511","0","2"]],"ts":"1646003683137","checksum":518647935}]}
1646003683.149566: {"arg":{"channel":"books-l2-tbt","instId":"ELON-USDT"},"action":"update","data":[{"asks":[["0.00000074547","101123396","0","2"],["0.00000074549","0","0","0"],["0.00000113256","10462875","0","1"]],"bids":[],"ts":"1646003683138","checksum":-214879834}]}
1646003683.158568: {"arg":{"channel":"books-l2-tbt","instId":"ELON-USDT"},"action":"update","data":[{"asks":[["0.00000074545","103956611","0","1"],["0.00000074547","53107723","0","1"],["0.00000074548","445226872","0","1"],["0.00000113256","0","0","0"]],"bids":[],"ts":"1646003683148","checksum":-1388603293}]}
1646003683.1615071: {"arg":{"channel":"books-l2-tbt","instId":"UNI-USD-SWAP"},"action":"update","data":[{"asks":[["9.623","0","0","0"],["9.629","196","0","2"],["48.625","1","0","1"]],"bids":[["9.606","4","0","1"]],"ts":"1646003683149","checksum":-145014849}]}
1646003683.169156: {"arg":{"channel":"books-l2-tbt","instId":"ELON-USDT"},"action":"update","data":[{"asks":[["0.00000074545","263625163","0","3"],["0.00000074698","0","0","0"],["0.00000113256","10462875","0","1"]],"bids":[],"ts":"1646003683158","checksum":444344870}]}
1646003683.169236: {"arg":{"channel":"books-l2-tbt","instId":"UNI-USD-SWAP"},"action":"update","data":[{"asks":[],"bids":[["9.606","0","0","0"],["9.605","517","0","3"]],"ts":"1646003683159","checksum":1897673131}]}
1646003683.1793458: {"arg":{"channel":"books-l2-tbt","instId":"ELON-USDT"},"action":"update","data":[{"asks":[["0.00000074548","0","0","0"],["0.00000113315","35900750","0","1"]],"bids":[],"ts":"1646003683168","checksum":-461349732}]}
1646003683.186524: {"arg":{"channel":"books-l2-tbt","instId":"UNI-USD-SWAP"},"action":"update","data":[{"asks":[["9.623","1","0","1"],["9.624","0","0","0"],["9.625","94","0","1"],["48.625","0","0","0"]],"bids":[],"ts":"1646003683168","checksum":-1427027582}]}
1646003683.1945589: {"arg":{"channel":"books-l2-tbt","instId":"ELON-USDT"},"action":"update","data":[{"asks":[["0.00000074557","0","0","0"],["0.0000011338","129154981","0","1"]],"bids":[["0.0000007433","0","0","0"]],"ts":"1646003683178","checksum":-1254075579}]}
1646003683.1946912: {"arg":{"channel":"books-l2-tbt","instId":"UNI-USD-SWAP"},"action":"update","data":[{"asks":[["9.625","0","0","0"],["9.626","115","0","2"],["48.625","1","0","1"]],"bids":[],"ts":"1646003683179","checksum":-803095570}]}
1646003683.207155: {"arg":{"channel":"trades","instId":"ZEN-USDT"},"data":[{"instId":"ZEN-USDT","tradeId":"15270487","px":"32.5","sz":"0.346397","side":"sell","ts":"1646003683183"}]}
1646003683.207214: {"arg":{"channel":"books-l2-tbt","instId":"ELON-USDT"},"action":"update","data":[{"asks":[["0.00000074545","151972284","0","2"]],"bids":[["0.00000074202","0","0","0"]],"ts":"1646003683188","checksum":-1334145916}]}
1646003683.211339: {"arg":{"channel":"tickers","instId":"ZEN-USDT"},"data":[{"instType":"SPOT","instId":"ZEN-USDT","last":"32.5","lastSz":"0.346397","askPx":"32.53","askSz":"0.383596","bidPx":"32.5","bidSz":"0.399716","open24h":"33.34","high24h":"35.26","low24h":"31.91","sodUtc0":"33.36","sodUtc8":"34.26","volCcy24h":"1483645.70083","vol24h":"44365.951004","ts":"1646003683191"}]}
1646003683.217469: {"arg":{"channel":"books-l2-tbt","instId":"UNI-USD-SWAP"},"action":"update","data":[{"asks":[["9.622","0","0","0"],["9.624","3","0","1"]],"bids":[["9.612","23","0","2"]],"ts":"1646003683200","checksum":-1899687363}]}
1646003683.225193: {"arg":{"channel":"books-l2-tbt","instId":"UNI-USD-SWAP"},"action":"update","data":[{"asks":[["9.623","0","0","0"],["48.868","1","0","1"]],"bids":[],"ts":"1646003683211","checksum":-796743602}]}
1646003683.231889: {"arg":{"channel":"books-l2-tbt","instId":"UNI-USD-SWAP"},"action":"update","data":[{"asks":[],"bids":[["9.605","511","0","2"]],"ts":"1646003683221","checksum":1598927186}]}
1646003683.240167: {"arg":{"channel":"books-l2-tbt","instId":"ELON-USDT"},"action":"update","data":[{"asks":[],"bids":[["0.00000074445","219861835","0","1"]],"ts":"1646003683228","checksum":-1086668933}]}
1646003683.243159: {"arg":{"channel":"books-l2-tbt","instId":"UNI-USD-SWAP"},"action":"update","data":[{"asks":[["9.625","3","0","1"],["48.868","0","0","0"]],"bids":[["9.61","102","0","1"]],"ts":"1646003683232","checksum":277820242}]}
1646003683.2503731: {"arg":{"channel":"books-l2-tbt","instId":"ELON-USDT"},"action":"update","data":[{"asks":[["0.00000074544","191579205","0","1"],["0.0000011338","0","0","0"]],"bids":[],"ts":"1646003683237","checksum":-1985248128}]}
1646003683.2587469: {"arg":{"channel":"books-l2-tbt","instId":"UNI-USD-SWAP"},"action":"update","data":[{"asks":[],"bids":[["9.6","24","0","1"],["9.599","26","0","1"],["9.598","182","0","2"],["9.597","62","0","1"],["9.595","21","0","1"],["9.594","0","0","0"]],"ts":"1646003683243","checksum":237825524}]}
1646003683.261205: {"arg":{"channel":"books-l2-tbt","instId":"ELON-USDT"},"action":"update","data":[{"asks":[],"bids":[["0.00000074435","120906449","0","1"]],"ts":"1646003683247","checksum":-1699248075}]}
1646003683.26991: {"arg":{"channel":"books-l2-tbt","instId":"ELON-USDT"},"action":"update","data":[{"asks":[["0.00000074545","0","0","0"],["0.00000074548","81175250","0","1"]],"bids":[],"ts":"1646003683258","checksum":1345815213}]}
1646003683.27981: {"arg":{"channel":"books-l2-tbt","instId":"UNI-USD-SWAP"},"action":"update","data":[{"asks":[["9.624","0","0","0"],["48.868","1","0","1"]],"bids":[["9.606","5","0","1"]],"ts":"1646003683264","checksum":-1568542699}]}
1646003683.284659: {"arg":{"channel":"books-l2-tbt","instId":"ELON-USDT"},"action":"update","data":[{"asks":[["0.00000074543","103956611","0","1"],["0.00000074546","0","0","0"]],"bids":[],"ts":"1646003683269","checksum":-524015538}]}
1646003683.2917519: {"arg":{"channel":"books-l2-tbt","instId":"ELON-USDT"},"action":"update","data":[{"asks":[],"bids":[["0.00000074446","134788568","0","1"]],"ts":"1646003683279","checksum":-1655426141}]}
1646003683.304008: {"arg":{"channel":"books-l2-tbt","instId":"PROPS-ETH"},"action":"update","data":[{"asks":[["0.00000177","0","0","0"],["0.00000178","0","0","0"],["0.00000185","1384.40572429","0","1"],["0.00000186","1475.32059861","0","1"],["0.00000187","766.64138196","0","1"]],"bids":[["0.00000161","10501.86970393","0","1"],["0.0000016","0","0","0"]],"ts":"1646003683292","checksum":240854479}]}
1646003683.309751: {"arg":{"channel":"books-l2-tbt","instId":"UNI-USD-SWAP"},"action":"update","data":[{"asks":[["9.625","107","0","2"],["9.626","11","0","1"],["9.628","500","0","1"],["9.631","258","0","3"]],"bids":[],"ts":"1646003683296","checksum":-1926770220}]}
1646003683.31159: {"arg":{"channel":"books-l2-tbt","instId":"ELON-USDT"},"action":"update","data":[{"asks":[["0.00000074544","0","0","0"],["0.0000011338","129154981","0","1"]],"bids":[],"ts":"1646003683298","checksum":1354271612}]}
1646003683.321451: {"arg":{"channel":"books-l2-tbt","instId":"UNI-USD-SWAP"},"action":"update","data":[{"asks":[["9.621","83","0","1"],["9.631","252","0","3"],["48.868","0","0","0"]],"bids":[["9.606","0","0","0"]],"ts":"1646003683307","checksum":-1043557911}]}
1646003683.330733: {"arg":{"channel":"books-l2-tbt","instId":"UNI-USD-SWAP"},"action":"update","data":[{"asks":[["9.631","258","0","3"]],"bids":[],"ts":"1646003683316","checksum":-919751675}]}
1646003683.3308501: {"arg":{"channel":"books-l2-tbt","instId":"ZEN-USDT"},"action":"update","data":[{"asks":[],"bids":[["32.49","8","0","1"]],"ts":"1646003683316","checksum":1931606973}]}
1646003683.3309062: {"arg":{"channel":"books-l2-tbt","instId":"ELON-USDT"},"action":"update","data":[{"asks":[["0.00000074543","0","0","0"],["0.0000011372","6179288","0","1"]],"bids":[],"ts":"1646003683319","checksum":-724475496}]}
1646003683.340621: {"arg":{"channel":"books-l2-tbt","instId":"UNI-USD-SWAP"},"action":"update","data":[{"asks":[["9.624","3","0","1"],["48.625","0","0","0"]],"bids":[],"ts":"1646003683327","checksum":226821478}]}
1646003683.3427782: {"arg":{"channel":"books-l2-tbt","instId":"ZEN-USDT"},"action":"update","data":[{"asks":[["32.52","10.646671","0","3"]],"bids":[],"ts":"1646003683329","checksum":9750619}]}
1646003683.3475358: {"arg":{"channel":"books-l2-tbt","instId":"ELON-USDT"},"action":"update","data":[{"asks":[],"bids":[["0.00000074435","0","0","0"]],"ts":"1646003683331","checksum":-26939991}]}
1646003683.3531048: {"arg":{"channel":"books-l2-tbt","instId":"ZEN-USDT"},"action":"update","data":[{"asks":[["32.6","155.041409","0","3"]],"bids":[["32.41","17.338359","0","1"]],"ts":"1646003683339","checksum":1470211785}]}
1646003683.353177: {"arg":{"channel":"books-l2-tbt","instId":"UNI-USD-SWAP"},"action":"update","data":[{"asks":[["9.619","0","0","0"],["48.625","1","0","1"]],"bids":[["9.611","422","0","3"],["9.609","1","0","1"]],"ts":"1646003683339","checksum":-2041249778}]}
1646003683.355086: {"arg":{"channel":"books-l2-tbt","instId":"ELON-USDT"},"action":"update","data":[{"asks":[["0.00000074743","0","0","0"],["0.00000113812","12211658","0","1"]],"bids":[["0.00000074259","2935956723","0","1"]],"ts":"1646003683340","checksum":-8488024}]}
1646003683.364751: {"arg":{"channel":"books-l2-tbt","instId":"UNI-USD-SWAP"},"action":"update","data":[{"asks":[["9.625","3","0","1"],["9.626","100","0","2"],["9.631","252","0","3"]],"bids":[],"ts":"1646003683349","checksum":-788851696}]}
1646003683.365955: {"arg":{"channel":"books-l2-tbt","instId":"ELON-USDT"},"action":"update","data":[{"asks":[["0.00000074542","252396844","0","1"],["0.00000074547","146898131","0","3"],["0.00000113812","0","0","0"]],"bids":[],"ts":"1646003683350","checksum":-771947436}]}
1646003683.371074: {"arg":{"channel":"books-l2-tbt","instId":"UNI-USD-SWAP"},"action":"update","data":[{"asks":[["9.625","0","0","0"],["9.626","11","0","1"],["9.627","152","0","1"],["48.868","1","0","1"]],"bids":[["9.612","131","0","2"],["9.611","313","0","2"],["9.606","6","0","1"]],"ts":"1646003683359","checksum":-1394622662}]}
1646003683.371182: {"arg":{"channel":"books-l2-tbt","instId":"ZEN-USDT"},"action":"update","data":[{"asks":[],"bids":[["32.46","5.804863","0","2"],["32.41","0","0","0"]],"ts":"1646003683359","checksum":-1396166464}]}
1646003683.373122: {"arg":{"channel":"books-l2-tbt","instId":"ELON-USDT"},"action":"update","data":[{"asks":[["0.00000074739","3336314458","0","1"],["0.0000011372","0","0","0"]],"bids":[],"ts":"1646003683360","checksum":-1653155267}]}
1646003683.384114: {"arg":{"channel":"books-l2-tbt","instId":"UNI-USD-SWAP"},"action":"update","data":[{"asks":[],"bids":[["9.611","325","0","3"]],"ts":"1646003683368","checksum":-481160447}]}
1646003683.390073: {"arg":{"channel":"books-l2-tbt","instId":"PROPS-ETH"},"action":"update","data":[{"asks":[],"bids":[["0.00000167","458814.130974","0","3"]],"ts":"1646003683376","checksum":-143861029}]}
1646003683.394539: {"arg":{"channel":"books-l2-tbt","instId":"UNI-USD-SWAP"},"action":"update","data":[{"asks":[["9.631","233","0","3"]],"bids":[["9.601","176","0","2"],["9.6","0","0","0"],["9.599","51","0","2"],["9.598","153","0","1"],["9.596","27","0","1"],["9.595","0","0","0"]],"ts":"1646003683381","checksum":-785488923}]}
1646003683.405272: {"arg":{"channel":"books-l2-tbt","instId":"UNI-USD-SWAP"},"action":"update","data":[{"asks":[["9.621","0","0","0"],["9.627","0","0","0"],["49.113","1","0","1"],["49.358","1","0","1"]],"bids":[["9.613","260","0","1"],["9.612","233","0","3"],["9.61","0","0","0"]],"ts":"1646003683390","checksum":254345212}]}
1646003683.4053838: {"arg":{"channel":"books-l2-tbt","instId":"ELON-USDT"},"action":"update","data":[{"asks":[["0.00000074547","199255828","0","4"]],"bids":[],"ts":"1646003683391","checksum":-996041811}]}
1646003683.41406: {"arg":{"channel":"books-l2-tbt","instId":"UNI-USD-SWAP"},"action":"update","data":[{"asks":[["9.631","185","0","2"],["9.633","4","0","1"],["9.657","26","0","1"],["49.358","0","0","0"]],"bids":[],"ts":"1646003683399","checksum":1470017904}]}
1646003683.414196: {"arg":{"channel":"books-l2-tbt","instId":"ZEN-USDT"},"action":"update","data":[{"asks":[["32.61","43.087828","0","2"]],"bids":[["32.42","49.874481","0","3"]],"ts":"1646003683399","checksum":-1065885317}]}
1646003683.416265: {"arg":{"channel":"books-l2-tbt","instId":"ELON-USDT"},"action":"update","data":[{"asks":[],"bids":[["0.0000007282","7337394396","0","1"]],"ts":"1646003683402","checksum":-996041811}]}
1646003683.423615: {"arg":{"channel":"books-l2-tbt","instId":"UNI-USD-SWAP"},"action":"update","data":[{"asks":[["9.63","89","0","1"],["9.632","426","0","2"],["9.635","230","0","5"],["9.637","1159","0","2"],["9.642","186","0","2"],["9.665","0","0","0"]],"bids":[["9.571","0","0","0"]],"ts":"1646003683409","checksum":-2130983481}]}
1646003683.423769: {"arg":{"channel":"books-l2-tbt","instId":"ELON-USDT"},"action":"update","data":[{"asks":[["0.00000074541","111652879","0","1"],["0.0000011338","0","0","0"]],"bids":[["0.00000070254","408309169","0","1"],["0.00000068849","266184897","0","1"],["0.00000067473","358528539","0","1"],["0.00000066124","293455992","0","1"]],"ts":"1646003683412","checksum":1272872566}]}
1646003683.4364438: {"arg":{"channel":"books-l2-tbt","instId":"UNI-USD-SWAP"},"action":"update","data":[{"asks":[["9.625","22","0","1"],["9.626","0","0","0"],["9.628","0","0","0"],["9.629","11","0","1"],["9.657","0","0","0"],["9.659","1006","0","2"],["9.671","16","0","1"],["49.358","1","0","1"]],"bids":[["9.614","22","0","1"],["9.612","211","0","2"],["9.58","9543","0","2"],["9.569","0","0","0"]],"ts":"1646003683422","checksum":-590546044}]}
1646003683.436573: {"arg":{"channel":"books-l2-tbt","instId":"ELON-USDT"},"action":"update","data":[{"asks":[],"bids":[["0.00000065074","0","0","0"]],"ts":"1646003683422","checksum":1272872566}]}
1646003683.44398: {"arg":{"channel":"books-l2-tbt","instId":"BTC-USD-220325-40000-C"},"action":"update","data":[{"asks":[["0.054","0","0","0"],["0.0545","100","0","1"]],"bids":[],"ts":"1646003683431","checksum":1567851585}]}
1646003683.444063: {"arg":{"channel":"books-l2-tbt","instId":"UNI-USD-SWAP"},"action":"update","data":[{"asks":[["9.625","25","0","2"],["9.631","685","0","3"],["9.658","85","0","2"],["9.662","75","0","1"],["9.663","510","0","1"],["49.113","0","0","0"],["49.358","0","0","0"]],"bids":[["9.613","264","0","2"],["9.611","272","0","2"],["9.594","16","0","1"],["9.593","728","0","3"]],"ts":"1646003683432","checksum":-1178237803}]}
1646003683.4461162: {"arg":{"channel":"books-l2-tbt","instId":"ELON-USDT"},"action":"update","data":[{"asks":[["0.00000074715","4038943392","0","1"],["0.00000113315","0","0","0"]],"bids":[],"ts":"1646003683435","checksum":1633186808}]}
1646003683.4525352: {"arg":{"channel":"books-l2-tbt","instId":"UNI-USD-SWAP"},"action":"update","data":[{"asks":[["9.658","64","0","1"]],"bids":[["9.605","11","0","1"]],"ts":"1646003683441","checksum":-52529168}]}
1646003683.454818: {"arg":{"channel":"books-l2-tbt","instId":"ZEN-USDT"},"action":"update","data":[{"asks":[],"bids":[["32.48","17.8359","0","1"]],"ts":"1646003683441","checksum":-720334858}]}
1646003683.4645162: {"arg":{"channel":"books-l2-tbt","instId":"UNI-USD-SWAP"},"action":"update","data":[{"asks":[["9.623","260","0","1"],["9.634","197","0","1"],["9.636","143","0","1"],["9.637","1052","0","1"],["9.638","665","0","4"],["9.639","125","0","1"],["9.641","322","0","4"],["9.642","364","0","3"],["48.625","0","0","0"],["48.868","0","0","0"]],"bids":[["9.607","500","0","1"],["9.574","0","0","0"]],"ts":"1646003683451","checksum":343005098}]}
1646003683.4646468: {"arg":{"channel":"books-l2-tbt","instId":"ZEN-USDT"},"action":"update","data":[{"asks":[["32.54","11.65408","0","2"],["32.61","35.959536","0","1"]],"bids":[],"ts":"1646003683452","checksum":-973091560}]}
1646003683.4738922: {"arg":{"channel":"books-l2-tbt","instId":"UNI-USD-SWAP"},"action":"update","data":[{"asks":[["9.633","24","0","1"]],"bids":[["9.607","505","0","2"],["9.606","0","0","0"],["9.6","41","0","1"],["9.597","0","0","0"],["9.595","16","0","1"],["9.594","0","0","0"],["9.577","254","0","2"],["9.573","0","0","0"]],"ts":"1646003683461","checksum":878882533}]}
1646003683.474057: {"arg":{"channel":"books-l2-tbt","instId":"ZEN-USDT"},"action":"update","data":[{"asks":[],"bids":[["32.49","8.327006","0","2"]],"ts":"1646003683461","checksum":1926992586}]}
1646003683.483856: {"arg":{"channel":"books-l2-tbt","instId":"ZEN-USDT"},"action":"update","data":[{"asks":[["32.9","60","0","1"],["32.91","1.51","0","1"],["33.36","0","0","0"],["33.37","4.52","0","1"],["33.82","0.01715","0","1"],["33.83","16.16","0","2"],["34.29","0","0","0"],["34.3","12.738605","0","2"],["34.77","0","0","0"],["34.78","13.28","0","1"]],"bids":[["32.12","1.55","0","1"],["32.11","0","0","0"],["31.67","4.71","0","1"],["31.66","0.055516","0","1"]],"ts":"1646003683472","checksum":-282788610}]}
1646003683.488532: {"arg":{"channel":"books-l2-tbt","instId":"UNI-USD-SWAP"},"action":"update","data":[{"asks":[],"bids":[["9.607","506","0","2"],["9.578","4","0","1"],["9.576","50","0","1"]],"ts":"1646003683474","checksum":-298317340}]}
1646003683.488608: {"arg":{"channel":"books-l2-tbt","instId":"ELON-USDT"},"action":"update","data":[{"asks":[["0.00000074769","445226872","0","1"],["0.00000113256","0","0","0"]],"bids":[],"ts":"1646003683476","checksum":1760968856}]}
1646003683.495334: {"arg":{"channel":"books-l2-tbt","instId":"UNI-USD-SWAP"},"action":"update","data":[{"asks":[["9.659","1022","0","3"]],"bids":[["9.614","131","0","2"],["9.612","102","0","1"]],"ts":"1646003683481","checksum":262543933}]}
1646003683.495475: {"arg":{"channel":"books-l2-tbt","instId":"ZEN-USDT"},"action":"update","data":[{"asks":[["32.52","8.444442","0","2"],["32.57","30.017069","0","1"],["32.6","174.041409","0","4"],["32.64","0","0","0"],["32.7","95","0","1"]],"bids":[["31.23","17.551052","0","3"],["31.22","0.010163","0","1"],["30.8","11.16","0","1"],["30.79","0","0","0"],["30.37","14.45","0","1"],["30.36","0","0","0"]],"ts":"1646003683482","checksum":393317112}]}
1646003683.503647: {"arg":{"channel":"books-l2-tbt","instId":"UNI-USD-SWAP"},"action":"update","data":[{"asks":[["9.633","0","0","0"],["48.625","1","0","1"]],"bids":[["9.608","43","0","3"],["9.607","500","0","1"],["9.596","45","0","2"],["9.595","0","0","0"]],"ts":"1646003683492","checksum":-2142527844}]}
1646003683.518005: {"arg":{"channel":"books-l2-tbt","instId":"ZEN-USDT"},"action":"update","data":[{"asks":[["32.64","95","0","1"],["32.7","0","0","0"]],"bids":[],"ts":"1646003683502","checksum":965775322}]}
1646003683.518133: {"arg":{"channel":"books-l2-tbt","instId":"BTC-USD-220325-40000-C"},"action":"update","data":[{"asks":[["0.0535","0","0","0"],["0.054","300","0","1"]],"bids":[["0.049","305","0","1"],["0.0485","0","0","0"]],"ts":"1646003683503","checksum":-1480969480}]}
1646003683.51823: {"arg":{"channel":"books-l2-tbt","instId":"UNI-USD-SWAP"},"action":"update","data":[{"asks":[["9.624","86","0","2"],["9.636","0","0","0"],["9.64","143","0","1"]],"bids":[["9.615","260","0","1"],["9.609","7","0","2"],["9.608","38","0","2"]],"ts":"1646003683503","checksum":-698210205}]}
1646003683.523069: {"arg":{"channel":"books-l2-tbt","instId":"ELON-USDT"},"action":"update","data":[{"asks":[["0.00000074541","159668552","0","2"]],"bids":[],"ts":"1646003683505","checksum":-557595104}]}
1646003683.5237188: {"arg":{"channel":"books-l2-tbt","instId":"ZEN-USDT"},"action":"update","data":[{"asks":[],"bids":[["32.47","53.20464","0","2"]],"ts":"1646003683512","checksum":1124404622}]}
1646003683.5275: {"arg":{"channel":"books-l2-tbt","instId":"UNI-USD-SWAP"},"action":"update","data":[{"asks":[],"bids":[["9.614","233","0","3"],["9.612","0","0","0"],["9.611","12","0","1"]],"ts":"1646003683512","checksum":-1616479798}]}
1646003683.5371048: {"arg":{"channel":"books-l2-tbt","instId":"UNI-USD-SWAP"},"action":"update","data":[{"asks":[["9.624","83","0","1"],["9.625","3","0","1"],["9.641","144","0","3"],["9.648","179","0","2"]],"bids":[["9.616","22","0","1"],["9.614","211","0","2"],["9.609","6","0","1"]],"ts":"1646003683525","checksum":-67251061}]}
1646003683.545138: {"arg":{"channel":"books-l2-tbt","instId":"ZEN-USDT"},"action":"update","data":[{"asks":[["32.52","0.444442","0","1"]],"bids":[],"ts":"1646003683532","checksum":-18626247}]}
1646003683.5603762: {"arg":{"channel":"books-l2-tbt","instId":"UNI-USD-SWAP"},"action":"update","data":[{"asks":[],"bids":[["9.614","264","0","3"],["9.603","80","0","1"],["9.6","0","0","0"]],"ts":"1646003683535","checksum":-1549039724}]}
1646003683.560464: {"arg":{"channel":"books-l2-tbt","instId":"ZEN-USDT"},"action":"update","data":[{"asks":[["32.59","0","0","0"],["32.61","0","0","0"],["44.23","2.713011","0","1"],["44.27","0.000092","0","1"]],"bids":[],"ts":"1646003683543","checksum":-351015865}]}
1646003683.561014: {"arg":{"channel":"books-l2-tbt","instId":"UNI-USD-SWAP"},"action":"update","data":[{"asks":[],"bids":[["9.615","369","0","2"],["9.614","155","0","2"],["9.577","225","0","1"]],"ts":"1646003683545","checksum":988948307}]}
1646003683.5610769: {"arg":{"channel":"books-l2-tbt","instId":"ELON-USDT"},"action":"update","data":[{"asks":[["0.00000074547","78327785","0","2"]],"bids":[],"ts":"1646003683546","checksum":-2134381006}]}
1646003683.563373: {"arg":{"channel":"books-l2-tbt","instId":"PROPS-ETH"},"action":"update","data":[{"asks":[],"bids":[["0.00000167","587529.51572729","0","4"]],"ts":"1646003683549","checksum":240854479}]}
1646003683.569555: {"arg":{"channel":"books-l2-tbt","instId":"UNI-USD-SWAP"},"action":"update","data":[{"asks":[["9.634","198","0","2"]],"bids":[["9.613","324","0","3"],["9.61","5","0","1"],["9.609","0","0","0"]],"ts":"1646003683555","checksum":285175939}]}
1646003683.569609: {"arg":{"channel":"books-l2-tbt","instId":"ELON-USDT"},"action":"update","data":[{"asks":[["0.00000074547","25220062","0","1"]],"bids":[],"ts":"1646003683557","checksum":-895896248}]}
1646003683.5771499: {"arg":{"channel":"books-l2-tbt","instId":"UNI-USD-SWAP"},"action":"update","data":[{"asks":[["9.638","641","0","3"],["9.641","123","0","2"],["9.644","0","0","0"],["48.868","1","0","1"]],"bids":[["9.599","26","0","1"],["9.596","18","0","1"]],"ts":"1646003683565","checksum":-507284746}]}
1646003683.5779042: {"arg":{"channel":"books-l2-tbt","instId":"ELON-USDT"},"action":"update","data":[{"asks":[["0.00000074541","263625163","0","3"]],"bids":[],"ts":"1646003683567","checksum":188940021}]}
1646003683.587212: {"arg":{"channel":"books-l2-tbt","instId":"UNI-USD-SWAP"},"action":"update","data":[{"asks":[["9.634","297","0","2"],["9.643","88","0","2"],["9.646","24","0","1"],["9.649","9308","0","3"],["48.868","0","0","0"]],"bids":[["9.61","6","0","1"],["9.603","101","0","2"],["9.598","183","0","2"]],"ts":"1646003683575","checksum":1689702888}]}
1646003683.587322: {"arg":{"channel":"books-l2-tbt","instId":"ZEN-USDT"},"action":"update","data":[{"asks":[["32.53","0","0","0"],["44.28","2.338891","0","1"]],"bids":[["32.49","10.377974","0","3"]],"ts":"1646003683575","checksum":309886083}]}
1646003683.597546: {"arg":{"channel":"books-l2-tbt","instId":"PROPS-ETH"},"action":"update","data":[{"asks":[],"bids":[["0.00000167","301429.73230629","0","2"]],"ts":"1646003683582","checksum":2008326944}]}
1646003683.602682: {"arg":{"channel":"books-l2-tbt","instId":"ELON-USDT"},"action":"update","data":[{"asks":[["0.00000074547","0","0","0"],["0.00000113256","10462875","0","1"]],"bids":[],"ts":"1646003683587","checksum":-1528094960}]}
1646003683.60697: {"arg":{"channel":"books-l2-tbt","instId":"BTC-USD-220325-40000-C"},"action":"update","data":[{"asks":[["0.0535","300","0","1"],["0.054","0","0","0"]],"bids":[],"ts":"1646003683595","checksum":-942407113}]}
1646003683.608041: {"arg":{"channel":"books-l2-tbt","instId":"ZEN-USDT"},"action":"update","data":[{"asks":[["32.54","12.52408","0","3"]],"bids":[],"ts":"1646003683596","checksum":-1690110824}]}
1646003683.612332: {"arg":{"channel":"books-l2-tbt","instId":"ELON-USDT"},"action":"update","data":[{"asks":[],"bids":[["0.00000074381","170532439","0","1"]],"ts":"1646003683598","checksum":1194112041}]}
1646003683.62098: {"arg":{"channel":"books-l2-tbt","instId":"ELON-USDT"},"action":"update","data":[{"asks":[["0.00000074541","151972284","0","2"]],"bids":[],"ts":"1646003683608","checksum":-1743587827}]}
1646003683.621057: {"arg":{"channel":"books-l2-tbt","instId":"UNI-USD-SWAP"},"action":"update","data":[{"asks":[["9.624","0","0","0"],["48.868","1","0","1"]],"bids":[["9.61","5","0","1"]],"ts":"1646003683609","checksum":-2082228230}]}
1646003683.6304939: {"arg":{"channel":"books-l2-tbt","instId":"ELON-USDT"},"action":"update","data":[{"asks":[["0.00000074542","0","0","0"],["0.00000113315","35900750","0","1"]],"bids":[],"ts":"1646003683618","checksum":927421077}]}
1646003683.6329951: {"arg":{"channel":"books-l2-tbt","instId":"PROPS-ETH"},"action":"update","data":[{"asks":[],"bids":[["0.00000167","587512.95671529","0","4"]],"ts":"1646003683621","checksum":-1366106009}]}
1646003683.6427798: {"arg":{"channel":"books-l2-tbt","instId":"UNI-USD-SWAP"},"action":"update","data":[{"asks":[["9.625","0","0","0"],["9.643","24","0","1"],["49.113","1","0","1"]],"bids":[["9.613","320","0","2"]],"ts":"1646003683631","checksum":-1901493446}]}
1646003683.652153: {"arg":{"channel":"books-l2-tbt","instId":"ELON-USDT"},"action":"update","data":[{"asks":[["0.00000074541","48015673","0","1"]],"bids":[],"ts":"1646003683639","checksum":-251627871}]}
1646003683.654111: {"arg":{"channel":"books-l2-tbt","instId":"UNI-USD-SWAP"},"action":"update","data":[{"asks":[],"bids":[["9.614","102","0","1"]],"ts":"1646003683640","checksum":-946655493}]}
1646003683.663521: {"arg":{"channel":"books-l2-tbt","instId":"UNI-USD-SWAP"},"action":"update","data":[{"asks":[],"bids":[["9.61","0","0","0"]],"ts":"1646003683650","checksum":2089203061}]}
1646003683.667744: {"arg":{"channel":"books-l2-tbt","instId":"ZEN-USDT"},"action":"update","data":[{"asks":[["32.53","0.624254","0","1"],["44.28","0","0","0"]],"bids":[],"ts":"1646003683656","checksum":-1108040663}]}
1646003683.672193: {"arg":{"channel":"books-l2-tbt","instId":"ELON-USDT"},"action":"update","data":[{"asks":[["0.00000074541","0","0","0"],["0.00000074599","103956611","0","1"]],"bids":[],"ts":"1646003683660","checksum":-476247969}]}
1646003683.675519: {"arg":{"channel":"books-l2-tbt","instId":"UNI-USD-SWAP"},"action":"update","data":[{"asks":[["9.649","9372","0","4"]],"bids":[],"ts":"1646003683662","checksum":179839966}]}
1646003683.681091: {"arg":{"channel":"books-l2-tbt","instId":"ELON-USDT"},"action":"update","data":[{"asks":[],"bids":[["0.00000074445","0","0","0"]],"ts":"1646003683669","checksum":1033645209}]}
1646003683.681797: {"arg":{"channel":"books-l2-tbt","instId":"UNI-USD-SWAP"},"action":"update","data":[{"asks":[["9.628","2","0","1"],["49.113","0","0","0"]],"bids":[["9.617","2","0","1"]],"ts":"1646003683671","checksum":-1087949072}]}
1646003683.695947: {"arg":{"channel":"books-l2-tbt","instId":"ELON-USDT"},"action":"update","data":[{"asks":[["0.00000074739","0","0","0"],["0.0000011338","129154981","0","1"]],"bids":[],"ts":"1646003683680","checksum":-610054430}]}
1646003683.69607: {"arg":{"channel":"books-l2-tbt","instId":"UNI-USD-SWAP"},"action":"update","data":[{"asks":[],"bids":[["9.578","514","0","2"]],"ts":"1646003683681","checksum":-1087949072}]}
1646003683.7031791: {"arg":{"channel":"books-l2-tbt","instId":"ELON-USDT"},"action":"update","data":[{"asks":[],"bids":[["0.00000074381","0","0","0"]],"ts":"1646003683690","checksum":-585582610}]}
1646003683.703244: {"arg":{"channel":"books-l2-tbt","instId":"UNI-USD-SWAP"},"action":"update","data":[{"asks":[["9.659","1061","0","4"]],"bids":[],"ts":"1646003683691","checksum":41385857}]}
1646003683.7132318: {"arg":{"channel":"books-l2-tbt","instId":"ELON-USDT"},"action":"update","data":[{"asks":[["0.00000074759","3603195431","0","1"],["0.0000011338","0","0","0"]],"bids":[],"ts":"1646003683701","checksum":1005470836}]}
1646003683.713353: {"arg":{"channel":"books-l2-tbt","instId":"UNI-USD-SWAP"},"action":"update","data":[{"asks":[["9.625","83","0","1"],["48.868","0","0","0"]],"bids":[],"ts":"1646003683701","checksum":-1862676503}]}
1646003683.741996: {"arg":{"channel":"books-l2-tbt","instId":"ELON-USDT"},"action":"update","data":[{"asks":[["0.00000074548","0","0","0"],["0.0000011338","129154981","0","1"]],"bids":[],"ts":"1646003683731","checksum":690543168}]}
1646003683.747355: {"arg":{"channel":"books-l2-tbt","instId":"UNI-USD-SWAP"},"action":"update","data":[{"asks":[],"bids":[["9.615","422","0","3"]],"ts":"1646003683735","checksum":266512173}]}
1646003683.7524009: {"arg":{"channel":"books-l2-tbt","instId":"ELON-USDT"},"action":"update","data":[{"asks":[["0.00000074759","0","0","0"],["0.0000011372","6179288","0","1"]],"bids":[],"ts":"1646003683741","checksum":180779896}]}
1646003683.75704: {"arg":{"channel":"books-l2-tbt","instId":"UNI-USD-SWAP"},"action":"update","data":[{"asks":[],"bids":[["9.578","533","0","3"]],"ts":"1646003683744","checksum":266512173}]}
1646003683.759823: {"arg":{"channel":"books-l2-tbt","instId":"ZEN-USDT"},"action":"update","data":[{"asks":[["32.52","0","0","0"],["44.28","2.338891","0","1"]],"bids":[],"ts":"1646003683749","checksum":1566979314}]}
1646003683.761885: {"arg":{"channel":"books-l2-tbt","instId":"ELON-USDT"},"action":"update","data":[{"asks":[["0.00000074617","0","0","0"],["0.00000113812","12211658","0","1"]],"bids":[],"ts":"1646003683750","checksum":1269082564}]}
1646003683.776119: {"arg":{"channel":"books-l2-tbt","instId":"ELON-USDT"},"action":"update","data":[{"asks":[["0.00000074626","496494347","0","1"],["0.00000074752","3335150458","0","1"],["0.0000011372","0","0","0"],["0.00000113812","0","0","0"]],"bids":[],"ts":"1646003683762","checksum":1345057163}]}
1646003683.77618: {"arg":{"channel":"books-l2-tbt","instId":"UNI-USD-SWAP"},"action":"update","data":[{"asks":[],"bids":[["9.615","313","0","2"]],"ts":"1646003683765","checksum":-1415434450}]}
1646003683.781502: {"arg":{"channel":"books-l2-tbt","instId":"ZEN-USDT"},"action":"update","data":[{"asks":[["32.61","16.129509","0","1"],["44.28","0","0","0"]],"bids":[],"ts":"1646003683770","checksum":1327386945}]}
1646003683.788449: {"arg":{"channel":"books-l2-tbt","instId":"UNI-USD-SWAP"},"action":"update","data":[{"asks":[["9.659","1022","0","3"]],"bids":[],"ts":"1646003683777","checksum":1455930256}]}
1646003683.810199: {"arg":{"channel":"books-l2-tbt","instId":"ZEN-USDT"},"action":"update","data":[{"asks":[],"bids":[["31.86","4.37392","0","2"],["31.85","83.986754","0","1"]],"ts":"1646003683799","checksum":1327386945}]}
1646003683.8156102: {"arg":{"channel":"books-l2-tbt","instId":"ZEN-USDT"},"action":"update","data":[{"asks":[],"bids":[["31.55","6.6","0","1"],["31.54","0","0","0"],["31.24","9.16","0","1"],["31.23","8.381052","0","2"],["30.93","14.584933","0","3"],["30.92","0","0","0"]],"ts":"1646003683803","checksum":1327386945}]}
1646003683.8162282: {"arg":{"channel":"books-l2-tbt","instId":"ELON-USDT"},"action":"update","data":[{"asks":[["0.00000074547","390130772","0","1"],["0.0000011338","0","0","0"]],"bids":[],"ts":"1646003683805","checksum":-1012084526}]}
1646003683.8218722: {"arg":{"channel":"books-l2-tbt","instId":"PROPS-ETH"},"action":"update","data":[{"asks":[["0.00000178","664.22955758","0","1"],["0.00000185","0","0","0"],["0.00000186","0","0","0"]],"bids":[["0.00000161","0","0","0"]],"ts":"1646003683810","checksum":-698710008}]}
1646003683.828429: {"arg":{"channel":"books-l2-tbt","instId":"ELON-USDT"},"action":"update","data":[{"asks":[["0.00000074599","185131861","0","2"]],"bids":[],"ts":"1646003683816","checksum":1693528273}]}
1646003683.859307: {"arg":{"channel":"books-l2-tbt","instId":"ELON-USDT"},"action":"update","data":[{"asks":[["0.00000074769","0","0","0"],["0.0000011338","129154981","0","1"]],"bids":[["0.00000074435","155416442","0","1"]],"ts":"1646003683847","checksum":159932258}]}
1646003683.866962: {"arg":{"channel":"books-l2-tbt","instId":"ZEN-USDT"},"action":"update","data":[{"asks":[["32.58","19","0","1"],["32.6","155.041409","0","3"],["44.27","0","0","0"]],"bids":[],"ts":"1646003683855","checksum":362865826}]}
1646003683.890251: {"arg":{"channel":"books-l2-tbt","instId":"UNI-USD-SWAP"},"action":"update","data":[{"asks":[["9.625","0","0","0"],["48.868","1","0","1"]],"bids":[["9.614","0","0","0"]],"ts":"1646003683870","checksum":-2035585474}]}
1646003683.9198349: {"arg":{"channel":"books-l2-tbt","instId":"ELON-USDT"},"action":"update","data":[{"asks":[],"bids":[["0.00000074446","0","0","0"]],"ts":"1646003683906","checksum":-757913823}]}
1646003683.922901: {"arg":{"channel":"books-l2-tbt","instId":"UNI-USD-SWAP"},"action":"update","data":[{"asks":[["9.624","83","0","1"],["48.868","0","0","0"]],"bids":[],"ts":"1646003683912","checksum":-1446018410}]}
1646003683.9339142: {"arg":{"channel":"books-l2-tbt","instId":"ELON-USDT"},"action":"update","data":[{"asks":[],"bids":[["0.00000070254","0","0","0"],["0.00000068849","0","0","0"],["0.00000067473","0","0","0"],["0.00000066124","0","0","0"],["0.00000064798","367419899","0","1"]],"ts":"1646003683918","checksum":-757913823}]}
1646003683.934016: {"arg":{"channel":"books-l2-tbt","instId":"UNI-USD-SWAP"},"action":"update","data":[{"asks":[["9.649","9337","0","3"]],"bids":[["9.575","0","0","0"]],"ts":"1646003683922","checksum":-1459588774}]}
1646003683.9440022: {"arg":{"channel":"books-l2-tbt","instId":"ELON-USDT"},"action":"update","data":[{"asks":[],"bids":[["0.00000074259","0","0","0"]],"ts":"1646003683929","checksum":-768215691}]}
1646003683.951209: {"arg":{"channel":"books-l2-tbt","instId":"ELON-USDT"},"action":"update","data":[{"asks":[["0.00000074598","445226872","0","1"],["0.0000011338","0","0","0"]],"bids":[],"ts":"1646003683939","checksum":883857128}]}
1646003683.954565: {"arg":{"channel":"books-l2-tbt","instId":"UNI-USD-SWAP"},"action":"update","data":[{"asks":[],"bids":[["9.609","6","0","1"],["9.603","21","0","1"],["9.579","85","0","2"]],"ts":"1646003683943","checksum":-436018258}]}
1646003683.964991: {"arg":{"channel":"books-l2-tbt","instId":"ELON-USDT"},"action":"update","data":[{"asks":[],"bids":[["0.00000074254","3336560793","0","1"]],"ts":"1646003683951","checksum":-1821878965}]}
1646003683.9651031: {"arg":{"channel":"books-l2-tbt","instId":"UNI-USD-SWAP"},"action":"update","data":[{"asks":[],"bids":[["9.616","23","0","2"],["9.601","214","0","3"]],"ts":"1646003683954","checksum":-1983170500}]}
1646003683.97921: {"arg":{"channel":"books-l2-tbt","instId":"UNI-USD-SWAP"},"action":"update","data":[{"asks":[["9.653","35","0","1"],["9.658","84","0","2"],["48.625","0","0","0"]],"bids":[["9.615","260","0","1"],["9.614","53","0","1"]],"ts":"1646003683964","checksum":624637283}]}
1646003683.986541: {"arg":{"channel":"books-l2-tbt","instId":"UNI-USD-SWAP"},"action":"update","data":[{"asks":[],"bids":[["9.617","0","0","0"]],"ts":"1646003683974","checksum":-709006147}]}
1646003683.996526: {"arg":{"channel":"books-l2-tbt","instId":"UNI-USD-SWAP"},"action":"update","data":[{"asks":[["9.629","100","0","2"],["9.63","0","0","0"],["48.625","1","0","1"]],"bids":[["9.609","0","0","0"]],"ts":"1646003683984","checksum":1622281961}]}
1646003684.0051022: {"arg":{"channel":"books-l2-tbt","instId":"UNI-USD-SWAP"},"action":"update","data":[{"asks":[["9.662","0","0","0"],["48.868","1","0","1"]],"bids":[],"ts":"1646003683994","checksum":1622281961}]}
1646003684.0216472: {"arg":{"channel":"books-l2-tbt","instId":"ELON-USDT"},"action":"update","data":[{"asks":[["0.00000074547","0","0","0"],["0.0000011338","129154981","0","1"]],"bids":[["0.00000074435","0","0","0"]],"ts":"1646003684003","checksum":-1649365109}]}
1646003684.021724: {"arg":{"channel":"books-l2-tbt","instId":"UNI-USD-SWAP"},"action":"update","data":[{"asks":[["9.661","88","0","1"],["48.868","0","0","0"]],"bids":[],"ts":"1646003684005","checksum":1622281961}]}
1646003684.024794: {"arg":{"channel":"books-l2-tbt","instId":"UNI-USD-SWAP"},"action":"update","data":[{"asks":[],"bids":[["9.615","0","0","0"]],"ts":"1646003684013","checksum":-446889460}]}
1646003684.031494: {"arg":{"channel":"books-l2-tbt","instId":"ELON-USDT"},"action":"update","data":[{"asks":[],"bids":[["0.00000074254","0","0","0"]],"ts":"1646003684021","checksum":1103490094}]}
1646003684.0361652: {"arg":{"channel":"books-l2-tbt","instId":"UNI-USD-SWAP"},"action":"update","data":[{"asks":[["9.624","0","0","0"],["48.868","1","0","1"]],"bids":[],"ts":"1646003684025","checksum":-197422150}]}
1646003684.059148: {"arg":{"channel":"books-l2-tbt","instId":"UNI-USD-SWAP"},"action":"update","data":[{"asks":[["9.633","1","0","1"],["9.634","197","0","1"],["48.868","0","0","0"]],"bids":[["9.614","55","0","2"]],"ts":"1646003684035","checksum":1259744752}]}
1646003684.0592809: {"arg":{"channel":"books-l2-tbt","instId":"UNI-USD-SWAP"},"action":"update","data":[{"asks":[],"bids":[["9.609","5","0","1"]],"ts":"1646003684045","checksum":502969102}]}
1646003684.0745978: {"arg":{"channel":"books-l2-tbt","instId":"UNI-USD-SWAP"},"action":"update","data":[{"asks":[],"bids":[["9.614","2","0","1"],["9.609","0","0","0"],["9.608","44","0","3"]],"ts":"1646003684056","checksum":-1536828412}]}
1646003684.075243: {"arg":{"channel":"books-l2-tbt","instId":"UNI-USD-SWAP"},"action":"update","data":[{"asks":[["9.633","6","0","1"]],"bids":[["9.616","22","0","1"]],"ts":"1646003684064","checksum":-613800572}]}
1646003684.0936708: {"arg":{"channel":"books-l2-tbt","instId":"UNI-USD-SWAP"},"action":"update","data":[{"asks":[["9.627","71","0","1"],["9.629","11","0","1"],["48.625","0","0","0"]],"bids":[],"ts":"1646003684076","checksum":-2115411170}]}
1646003684.100256: {"arg":{"channel":"books-l2-tbt","instId":"UNI-USD-SWAP"},"action":"update","data":[{"asks":[["9.633","1","0","1"],["9.659","1006","0","2"],["9.671","0","0","0"],["48.625","1","0","1"]],"bids":[["9.616","0","0","0"],["9.615","22","0","1"],["9.609","6","0","1"],["9.608","38","0","2"],["9.58","0","0","0"]],"ts":"1646003684086","checksum":-1423252357}]}
1646003684.110922: {"arg":{"channel":"books-l2-tbt","instId":"ELON-USDT"},"action":"update","data":[{"asks":[["0.00000074599","253702207","0","3"]],"bids":[["0.00000074381","44758909","0","1"]],"ts":"1646003684093","checksum":948362817}]}
1646003684.111042: {"arg":{"channel":"books-l2-tbt","instId":"UNI-USD-SWAP"},"action":"update","data":[{"asks":[["9.626","2","0","1"],["48.625","0","0","0"]],"bids":[["9.585","9953","0","2"]],"ts":"1646003684097","checksum":1471825956}]}
1646003684.118594: {"arg":{"channel":"books-l2-tbt","instId":"UNI-USD-SWAP"},"action":"update","data":[{"asks":[["9.623","343","0","2"]],"bids":[["9.612","211","0","2"]],"ts":"1646003684107","checksum":-1573965465}]}
1646003684.124865: {"arg":{"channel":"books-l2-tbt","instId":"ELON-USDT"},"action":"update","data":[{"asks":[],"bids":[["0.00000074259","3335441382","0","1"]],"ts":"1646003684113","checksum":-1168123748}]}
1646003684.1292312: {"arg":{"channel":"books-l2-tbt","instId":"UNI-USD-SWAP"},"action":"update","data":[{"asks":[["9.628","0","0","0"],["9.633","0","0","0"],["9.634","297","0","2"],["9.658","100","0","3"],["48.625","1","0","1"],["48.868","1","0","1"]],"bids":[],"ts":"1646003684117","checksum":1404811103}]}
1646003684.135652: {"arg":{"channel":"books-l2-tbt","instId":"ELON-USDT"},"action":"update","data":[{"asks":[["0.00000074599","149745596","0","2"]],"bids":[],"ts":"1646003684125","checksum":357424404}]}
1646003684.151835: {"arg":{"channel":"books-l2-tbt","instId":"ELON-USDT"},"action":"update","data":[{"asks":[["0.00000074599","202103293","0","3"]],"bids":[],"ts":"1646003684135","checksum":-1231160290}]}
1646003684.15192: {"arg":{"channel":"books-l2-tbt","instId":"UNI-USD-SWAP"},"action":"update","data":[{"asks":[["9.658","80","0","2"],["9.661","0","0","0"],["49.113","1","0","1"]],"bids":[["9.616","1","0","1"]],"ts":"1646003684139","checksum":-512614224}]}
1646003684.169815: {"arg":{"channel":"books-l2-tbt","instId":"UNI-USD-SWAP"},"action":"update","data":[{"asks":[],"bids":[["9.616","0","0","0"]],"ts":"1646003684158","checksum":-110383600}]}
1646003684.176041: {"arg":{"channel":"books-l2-tbt","instId":"ELON-USDT"},"action":"update","data":[{"asks":[["0.00000074597","78327785","0","2"],["0.00000074599","81175250","0","1"],["0.0000011338","0","0","0"]],"bids":[["0.00000074435","157830096","0","1"]],"ts":"1646003684165","checksum":1316077369}]}
1646003684.1804311: {"arg":{"channel":"books-l2-tbt","instId":"UNI-USD-SWAP"},"action":"update","data":[{"asks":[],"bids":[["9.614","55","0","2"],["9.576","0","0","0"]],"ts":"1646003684168","checksum":968021191}]}
1646003684.1912498: {"arg":{"channel":"books-l2-tbt","instId":"UNI-USD-SWAP"},"action":"update","data":[{"asks":[],"bids":[["9.58","50","0","1"]],"ts":"1646003684178","checksum":-1769827672}]}
1646003684.197647: {"arg":{"channel":"books-l2-tbt","instId":"ELON-USDT"},"action":"update","data":[{"asks":[],"bids":[["0.0000007445","219861835","0","1"]],"ts":"1646003684184","checksum":94499759}]}
1646003684.203858: {"arg":{"channel":"books-l2-tbt","instId":"UNI-USD-SWAP"},"action":"update","data":[{"asks":[["9.642","385","0","4"],["9.643","0","0","0"],["9.645","73","0","2"],["9.646","0","0","0"],["9.648","200","0","3"],["9.649","9309","0","2"],["49.358","1","0","1"],["49.605","1","0","1"]],"bids":[["9.604","196","0","2"],["9.603","0","0","0"],["9.602","25","0","1"],["9.601","191","0","2"],["9.599","46","0","2"],["9.598","153","0","1"],["9.58","0","0","0"]],"ts":"1646003684190","checksum":1327650973}]}
1646003684.21456: {"arg":{"channel":"books-l2-tbt","instId":"UNI-USD-SWAP"},"action":"update","data":[{"asks":[],"bids":[["9.609","0","0","0"]],"ts":"1646003684199","checksum":2113959180}]}
1646003684.21763: {"arg":{"channel":"books-l2-tbt","instId":"ELON-USDT"},"action":"update","data":[{"asks":[["0.00000074597","189980664","0","3"]],"bids":[["0.00000074334","1627000000","0","1"]],"ts":"1646003684206","checksum":-1204168410}]}
1646003684.225425: {"arg":{"channel":"books-l2-tbt","instId":"ZEN-USDT"},"action":"update","data":[{"asks":[],"bids":[["31.85","0","0","0"]],"ts":"1646003684213","checksum":362865826}]}
1646003684.2295349: {"arg":{"channel":"books-l2-tbt","instId":"ELON-USDT"},"action":"update","data":[{"asks":[],"bids":[["0.00000074381","0","0","0"]],"ts":"1646003684216","checksum":1266830569}]}
1646003684.242573: {"arg":{"channel":"books-l2-tbt","instId":"ELON-USDT"},"action":"update","data":[{"asks":[["0.00000074598","493242545","0","2"]],"bids":[],"ts":"1646003684226","checksum":-1457439871}]}
1646003684.242684: {"arg":{"channel":"books-l2-tbt","instId":"UNI-USD-SWAP"},"action":"update","data":[{"asks":[["9.657","16","0","1"],["49.605","0","0","0"]],"bids":[],"ts":"1646003684231","checksum":-894585756}]}
1646003684.251764: {"arg":{"channel":"books-l2-tbt","instId":"ELON-USDT"},"action":"update","data":[{"asks":[["0.00000074596","445226872","0","1"],["0.00000113315","0","0","0"]],"bids":[],"ts":"1646003684235","checksum":-255107491}]}
1646003684.256462: {"arg":{"channel":"books-l2-tbt","instId":"UNI-USD-SWAP"},"action":"update","data":[{"asks":[],"bids":[["9.616","2","0","1"]],"ts":"1646003684243","checksum":1479114172}]}
1646003684.260994: {"arg":{"channel":"books-l2-tbt","instId":"ETH-USD-220325-8800-P"},"action":"update","data":[{"asks":[["2.549","201","0","1"],["2.55","0","0","0"]],"bids":[],"ts":"1646003684250","checksum":957925562}]}
1646003684.2703161: {"arg":{"channel":"books-l2-tbt","instId":"ELON-USDT"},"action":"update","data":[{"asks":[["0.00000074597","78327785","0","2"],["0.00000074598","445226872","0","1"]],"bids":[],"ts":"1646003684256","checksum":1537857139}]}
1646003684.2763789: {"arg":{"channel":"books-l2-tbt","instId":"UNI-USD-SWAP"},"action":"update","data":[{"asks":[["9.658","64","0","1"],["9.662","16","0","1"],["49.358","0","0","0"]],"bids":[["9.614","53","0","1"]],"ts":"1646003684263","checksum":774900604}]}
1646003684.289193: {"arg":{"channel":"books-l2-tbt","instId":"ELON-USDT"},"action":"update","data":[{"asks":[["0.00000074595","111652879","0","1"],["0.00000074598","0","0","0"]],"bids":[],"ts":"1646003684277","checksum":1073005554}]}
1646003684.305378: {"arg":{"channel":"books-l2-tbt","instId":"PROPS-ETH"},"action":"update","data":[{"asks":[["0.00000181","0","0","0"],["0.00000187","0","0","0"]],"bids":[],"ts":"1646003684292","checksum":672252827}]}
1646003684.3116958: {"arg":{"channel":"books-l2-tbt","instId":"UNI-USD-SWAP"},"action":"update","data":[{"asks":[["9.66","59","0","1"],["49.113","0","0","0"]],"bids":[],"ts":"1646003684294","checksum":205277224}]}
1646003684.321461: {"arg":{"channel":"books-l2-tbt","instId":"PROPS-ETH"},"action":"update","data":[{"asks":[["0.00000176","8608.45936236","0","2"],["0.00000185","1137.21637384","0","1"]],"bids":[["0.0000016","9679.60255221","0","1"]],"ts":"1646003684304","checksum":-1106197327}]}
1646003684.321549: {"arg":{"channel":"books-l2-tbt","instId":"ELON-USDT"},"action":"update","data":[{"asks":[["0.00000074599","0","0","0"],["0.00000113315","35900750","0","1"]],"bids":[["0.00000074451","161036778","0","1"]],"ts":"1646003684307","checksum":36166799}]}
1646003684.3279948: {"arg":{"channel":"books-l2-tbt","instId":"UNI-USD-SWAP"},"action":"update","data":[{"asks":[["9.642","364","0","3"],["9.643","25","0","1"],["9.645","50","0","1"],["9.646","25","0","1"],["9.648","179","0","2"],["9.649","9335","0","3"],["48.625","0","0","0"],["48.868","0","0","0"]],"bids":[["9.604","168","0","1"],["9.602","0","0","0"],["9.601","215","0","3"],["9.596","40","0","2"]],"ts":"1646003684316","checksum":-65305011}]}
1646003684.346669: {"arg":{"channel":"books-l2-tbt","instId":"UNI-USD-SWAP"},"action":"update","data":[{"asks":[],"bids":[["9.605","33","0","2"]],"ts":"1646003684335","checksum":127360182}]}
1646003684.364471: {"arg":{"channel":"books-l2-tbt","instId":"ELON-USDT"},"action":"update","data":[{"asks":[["0.00000074594","445226872","0","1"],["0.00000113315","0","0","0"]],"bids":[],"ts":"1646003684351","checksum":-2026722832}]}
1646003684.372277: {"arg":{"channel":"books-l2-tbt","instId":"ELON-USDT"},"action":"update","data":[{"asks":[],"bids":[["0.00000074435","0","0","0"]],"ts":"1646003684360","checksum":1242636860}]}
1646003684.3794649: {"arg":{"channel":"books-l2-tbt","instId":"UNI-USD-SWAP"},"action":"update","data":[{"asks":[["9.635","180","0","4"],["9.641","139","0","3"]],"bids":[["9.597","16","0","1"],["9.596","22","0","1"]],"ts":"1646003684368","checksum":2035024943}]}
1646003684.383735: {"arg":{"channel":"books-l2-tbt","instId":"ELON-USDT"},"action":"update","data":[{"asks":[["0.00000074593","172526957","0","2"],["0.00000074597","53107723","0","1"],["0.00000113256","0","0","0"]],"bids":[],"ts":"1646003684371","checksum":2141291916}]}
1646003684.394675: {"arg":{"channel":"books-l2-tbt","instId":"ELON-USDT"},"action":"update","data":[{"asks":[["0.00000074593","224884654","0","3"],["0.00000074595","0","0","0"],["0.00000074596","0","0","0"],["0.00000074597","81175250","0","1"],["0.00000113256","10462875","0","1"],["0.00000113315","35900750","0","1"]],"bids":[["0.00000074334","0","0","0"]],"ts":"1646003684381","checksum":-1439224729}]}
1646003684.423573: {"arg":{"channel":"books-l2-tbt","instId":"ELON-USDT"},"action":"update","data":[{"asks":[],"bids":[["0.0000006993","299209679","0","1"],["0.00000068532","363013418","0","1"],["0.00000067162","305893552","0","1"],["0.00000065819","340729748","0","1"],["0.00000064798","0","0","0"]],"ts":"1646003684411","checksum":-1439224729}]}
1646003684.4378638: {"arg":{"channel":"books-l2-tbt","instId":"PROPS-ETH"},"action":"update","data":[{"asks":[],"bids":[["0.00000167","458797.571962","0","3"]],"ts":"1646003684424","checksum":40393488}]}
1646003684.463136: {"arg":{"channel":"books-l2-tbt","instId":"UNI-USD-SWAP"},"action":"update","data":[{"asks":[],"bids":[["9.577","275","0","2"]],"ts":"1646003684451","checksum":2035024943}]}
1646003684.468261: {"arg":{"channel":"books-l2-tbt","instId":"PROPS-ETH"},"action":"update","data":[{"asks":[["0.00000173","0","0","0"]],"bids":[["0.00000167","587512.95671529","0","4"]],"ts":"1646003684456","checksum":-474465095}]}
1646003684.488373: {"arg":{"channel":"books-l2-tbt","instId":"UNI-USD-SWAP"},"action":"update","data":[{"asks":[],"bids":[["9.609","5","0","1"]],"ts":"1646003684471","checksum":-1240040830}]}
1646003684.491285: {"arg":{"channel":"books-l2-tbt","instId":"PROPS-ETH"},"action":"update","data":[{"asks":[["0.00000172","0","0","0"]],"bids":[],"ts":"1646003684477","checksum":-1948603041}]}
1646003684.493796: {"arg":{"channel":"books-l2-tbt","instId":"UNI-USD-SWAP"},"action":"update","data":[{"asks":[],"bids":[["9.614","0","0","0"],["9.613","373","0","3"]],"ts":"1646003684482","checksum":959485269}]}
1646003684.503194: {"arg":{"channel":"books-l2-tbt","instId":"ZEN-USDT"},"action":"update","data":[{"asks":[["32.61","0","0","0"],["44.27","0.000092","0","1"]],"bids":[["32.42","34.507971","0","2"]],"ts":"1646003684491","checksum":247766331}]}
1646003684.5065238: {"arg":{"channel":"books-l2-tbt","instId":"UNI-USD-SWAP"},"action":"update","data":[{"asks":[["9.623","260","0","1"],["9.64","193","0","2"],["9.641","123","0","2"]],"bids":[],"ts":"1646003684494","checksum":1766593671}]}
1646003684.51512: {"arg":{"channel":"books-l2-tbt","instId":"UNI-USD-SWAP"},"action":"update","data":[{"asks":[["9.622","83","0","1"],["48.383","0","0","0"]],"bids":[["9.615","0","0","0"],["9.614","22","0","1"]],"ts":"1646003684503","checksum":1187006225}]}
1646003684.524797: {"arg":{"channel":"books-l2-tbt","instId":"ELON-USDT"},"action":"update","data":[{"asks":[["0.00000074592","445226872","0","1"],["0.00000113315","0","0","0"]],"bids":[],"ts":"1646003684512","checksum":-1483998028}]}
1646003684.52492: {"arg":{"channel":"books-l2-tbt","instId":"UNI-USD-SWAP"},"action":"update","data":[{"asks":[],"bids":[["9.605","11","0","1"]],"ts":"1646003684513","checksum":-1119052310}]}
1646003684.531944: {"arg":{"channel":"books-l2-tbt","instId":"PROPS-ETH"},"action":"update","data":[{"asks":[["0.00000175","9806.10252154","0","1"]],"bids":[],"ts":"1646003684516","checksum":1754685034}]}
1646003684.539881: {"arg":{"channel":"books-l2-tbt","instId":"UNI-USD-SWAP"},"action":"update","data":[{"asks":[["9.623","282","0","2"],["9.626","205","0","3"],["9.633","100","0","1"],["9.634","340","0","2"],["9.639","175","0","2"],["9.64","0","0","0"]],"bids":[["9.613","113","0","2"],["9.612","0","0","0"],["9.609","0","0","0"],["9.608","44","0","3"]],"ts":"1646003684524","checksum":-310233423}]}
1646003684.552764: {"arg":{"channel":"books-l2-tbt","instId":"UNI-USD-SWAP"},"action":"update","data":[{"asks":[["9.621","260","0","1"],["9.642","390","0","4"],["9.643","0","0","0"],["9.645","77","0","2"],["9.646","0","0","0"],["9.648","203","0","3"],["9.649","9309","0","2"],["48.383","1","0","1"]],"bids":[["9.613","60","0","1"],["9.608","43","0","3"],["9.602","22","0","1"],["9.601","191","0","2"],["9.6","20","0","1"],["9.599","26","0","1"],["9.597","45","0","2"],["9.596","0","0","0"]],"ts":"1646003684536","checksum":507666751}]}
1646003684.5529118: {"arg":{"channel":"books-l2-tbt","instId":"ELON-USDT"},"action":"update","data":[{"asks":[["0.00000074593","120928043","0","2"]],"bids":[],"ts":"1646003684535","checksum":1223425047}]}
1646003684.552949: {"arg":{"channel":"books-l2-tbt","instId":"PROPS-ETH"},"action":"update","data":[{"asks":[["0.00000175","23738.40640048","0","2"]],"bids":[["0.00000167","458797.571962","0","3"]],"ts":"1646003684539","checksum":1451784952}]}
1646003684.556072: {"arg":{"channel":"books-l2-tbt","instId":"BTC-USD-220325-40000-C"},"action":"update","data":[{"asks":[["0.054","100","0","1"],["0.0545","0","0","0"]],"bids":[],"ts":"1646003684541","checksum":1106066843}]}
1646003684.5565288: {"arg":{"channel":"books-l2-tbt","instId":"UNI-USD-SWAP"},"action":"update","data":[{"asks":[],"bids":[["9.573","4","0","1"]],"ts":"1646003684546","checksum":507666751}]}
1646003684.5658581: {"arg":{"channel":"books-l2-tbt","instId":"ELON-USDT"},"action":"update","data":[{"asks":[["0.00000074591","48015673","0","1"],["0.00000113256","0","0","0"]],"bids":[],"ts":"1646003684549","checksum":275157476}]}
1646003684.565978: {"arg":{"channel":"books-l2-tbt","instId":"ZEN-USDT"},"action":"update","data":[{"asks":[["32.61","4.61469","0","1"],["44.27","0","0","0"]],"bids":[["32.41","2.315277","0","1"],["32.39","0","0","0"]],"ts":"1646003684553","checksum":1731899949}]}
1646003684.568665: {"arg":{"channel":"books-l2-tbt","instId":"UNI-USD-SWAP"},"action":"update","data":[{"asks":[["9.625","71","0","1"],["9.626","100","0","2"],["9.627","0","0","0"],["9.632","526","0","3"],["9.633","0","0","0"],["48.625","1","0","1"]],"bids":[["9.608","38","0","2"],["9.607","506","0","2"],["9.578","529","0","2"]],"ts":"1646003684557","checksum":-2147336787}]}
1646003684.574968: {"arg":{"channel":"books-l2-tbt","instId":"PROPS-ETH"},"action":"update","data":[{"asks":[["0.00000175","13932.30387894","0","1"]],"bids":[],"ts":"1646003684558","checksum":-1275104724}]}
1646003684.5750139: {"arg":{"channel":"books-l2-tbt","instId":"ZEN-USDT"},"action":"update","data":[{"asks":[["32.53","1.494254","0","2"],["32.54","11.65408","0","2"]],"bids":[["31.72","84.330962","0","1"]],"ts":"1646003684563","checksum":1414475034}]}
1646003684.578048: {"arg":{"channel":"books-l2-tbt","instId":"UNI-USD-SWAP"},"action":"update","data":[{"asks":[["9.626","2","0","1"]],"bids":[["9.615","2","0","1"],["9.614","0","0","0"],["9.613","82","0","2"],["9.578","510","0","1"]],"ts":"1646003684566","checksum":102638815}]}
1646003684.589943: {"arg":{"channel":"books-l2-tbt","instId":"ZEN-USDT"},"action":"update","data":[{"asks":[["32.53","3.58867","0","3"]],"bids":[["32.49","8.327006","0","2"]],"ts":"1646003684572","checksum":-1346326192}]}
1646003684.590004: {"arg":{"channel":"books-l2-tbt","instId":"UNI-USD-SWAP"},"action":"update","data":[{"asks":[],"bids":[["9.613","22","0","1"]],"ts":"1646003684575","checksum":-1846928202}]}
1646003684.590036: {"arg":{"channel":"books-l2-tbt","instId":"ETH-USD-220325-8800-P"},"action":"update","data":[{"asks":[["2.549","0","0","0"],["2.5495","201","0","1"]],"bids":[],"ts":"1646003684576","checksum":-181733380}]}
1646003684.597363: {"arg":{"channel":"books-l2-tbt","instId":"UNI-USD-SWAP"},"action":"update","data":[{"asks":[["9.631","690","0","4"],["9.632","426","0","2"],["9.638","657","0","4"],["9.639","125","0","1"]],"bids":[["9.576","29","0","1"]],"ts":"1646003684585","checksum":-1274563187}]}
1646003684.597462: {"arg":{"channel":"books-l2-tbt","instId":"ELON-USDT"},"action":"update","data":[{"asks":[["0.00000074593","68570346","0","1"],["0.00000074594","0","0","0"],["0.00000113256","10462875","0","1"]],"bids":[],"ts":"1646003684586","checksum":-1304571761}]}
1646003684.60178: {"arg":{"channel":"books-l2-tbt","instId":"PROPS-ETH"},"action":"update","data":[{"asks":[["0.00000174","9629.32601478","0","1"]],"bids":[],"ts":"1646003684589","checksum":-253186229}]}
1646003684.6055522: {"arg":{"channel":"books-l2-tbt","instId":"ZEN-USDT"},"action":"update","data":[{"asks":[["32.52","8","0","1"],["32.59","35.965067","0","1"],["44.22","0","0","0"],["44.23","0","0","0"]],"bids":[["32.41","0","0","0"]],"ts":"1646003684594","checksum":394621891}]}
1646003684.609735: {"arg":{"channel":"books-l2-tbt","instId":"UNI-USD-SWAP"},"action":"update","data":[{"asks":[],"bids":[["9.601","153","0","1"],["9.599","89","0","2"]],"ts":"1646003684595","checksum":-425314489}]}
1646003684.6161761: {"arg":{"channel":"books-l2-tbt","instId":"ZEN-USDT"},"action":"update","data":[{"asks":[["32.57","49.017069","0","2"],["32.58","0","0","0"],["44.22","2.271956","0","1"]],"bids":[],"ts":"1646003684603","checksum":-1125964297}]}
1646003684.6182249: {"arg":{"channel":"books-l2-tbt","instId":"UNI-USD-SWAP"},"action":"update","data":[{"asks":[["9.622","0","0","0"],["48.868","1","0","1"]],"bids":[["9.613","0","0","0"],["9.612","22","0","1"],["9.607","500","0","1"],["9.606","6","0","1"]],"ts":"1646003684606","checksum":2024826246}]}
1646003684.6213078: {"arg":{"channel":"books-l2-tbt","instId":"PROPS-ETH"},"action":"update","data":[{"asks":[],"bids":[["0.00000167","587512.95671529","0","4"]],"ts":"1646003684609","checksum":1367688362}]}
1646003684.6270652: {"arg":{"channel":"books-l2-tbt","instId":"ELON-USDT"},"action":"update","data":[{"asks":[["0.00000074591","212776275","0","3"],["0.00000074593","0","0","0"],["0.00000113315","35900750","0","1"]],"bids":[["0.0000007445","0","0","0"]],"ts":"1646003684615","checksum":1409958497}]}
1646003684.6375759: {"arg":{"channel":"books-l2-tbt","instId":"ELON-USDT"},"action":"update","data":[{"asks":[["0.00000074591","237996337","0","4"]],"bids":[],"ts":"1646003684626","checksum":-1669150815}]}
1646003684.6396182: {"arg":{"channel":"books-l2-tbt","instId":"UNI-USD-SWAP"},"action":"update","data":[{"asks":[["9.631","685","0","3"],["9.632","526","0","3"]],"bids":[],"ts":"1646003684627","checksum":546785400}]}
1646003684.6583722: {"arg":{"channel":"books-l2-tbt","instId":"PROPS-ETH"},"action":"update","data":[{"asks":[],"bids":[["0.00000167","474144.07985929","0","3"]],"ts":"1646003684629","checksum":870633124}]}
1646003684.6584609: {"arg":{"channel":"books-l2-tbt","instId":"UNI-USD-SWAP"},"action":"update","data":[{"asks":[],"bids":[["9.616","0","0","0"]],"ts":"1646003684637","checksum":1750221927}]}
1646003684.662465: {"arg":{"channel":"books-l2-tbt","instId":"UNI-USD-SWAP"},"action":"update","data":[{"asks":[["9.626","0","0","0"],["49.113","1","0","1"]],"bids":[],"ts":"1646003684648","checksum":-2025407399}]}
1646003684.662592: {"arg":{"channel":"books-l2-tbt","instId":"PROPS-ETH"},"action":"update","data":[{"asks":[],"bids":[["0.00000167","586890.93423429","0","4"]],"ts":"1646003684650","checksum":-1756284489}]}
1646003684.669535: {"arg":{"channel":"books-l2-tbt","instId":"UNI-USD-SWAP"},"action":"update","data":[{"asks":[["9.621","282","0","2"],["9.623","260","0","1"]],"bids":[],"ts":"1646003684658","checksum":60420697}]}
1646003684.66962: {"arg":{"channel":"books-l2-tbt","instId":"PROPS-ETH"},"action":"update","data":[{"asks":[],"bids":[],"ts":"1646003684659","checksum":-1756284489}]}
1646003684.6824708: {"arg":{"channel":"books-l2-tbt","instId":"UNI-USD-SWAP"},"action":"update","data":[{"asks":[["9.631","704","0","4"],["9.632","426","0","2"],["9.641","150","0","3"],["9.642","364","0","3"],["9.644","21","0","1"],["9.645","50","0","1"],["9.647","2295","0","3"],["9.648","179","0","2"],["49.113","0","0","0"]],"bids":[["9.603","28","0","1"],["9.602","0","0","0"],["9.601","179","0","2"],["9.6","0","0","0"],["9.598","178","0","2"],["9.597","16","0","1"]],"ts":"1646003684669","checksum":605276665}]}
1646003684.693608: {"arg":{"channel":"books-l2-tbt","instId":"UNI-USD-SWAP"},"action":"update","data":[{"asks":[],"bids":[["9.61","53","0","1"]],"ts":"1646003684679","checksum":538765931}]}
1646003684.701792: {"arg":{"channel":"books-l2-tbt","instId":"UNI-USD-SWAP"},"action":"update","data":[{"asks":[],"bids":[["9.599","63","0","1"]],"ts":"1646003684689","checksum":-1549868999}]}
1646003684.7039769: {"arg":{"channel":"books-l2-tbt","instId":"BTC-USD-220325-40000-C"},"action":"update","data":[{"asks":[],"bids":[["0.049","0","0","0"],["0.0485","305","0","1"]],"ts":"1646003684694","checksum":1507392794}]}
1646003684.7094169: {"arg":{"channel":"books-l2-tbt","instId":"ELON-USDT"},"action":"update","data":[{"asks":[],"bids":[["0.00000074451","0","0","0"]],"ts":"1646003684697","checksum":-705104975}]}
1646003684.711402: {"arg":{"channel":"books-l2-tbt","instId":"UNI-USD-SWAP"},"action":"update","data":[{"asks":[["9.62","83","0","1"],["48.868","0","0","0"]],"bids":[],"ts":"1646003684700","checksum":464157709}]}
1646003684.728392: {"arg":{"channel":"books-l2-tbt","instId":"ELON-USDT"},"action":"update","data":[{"asks":[["0.00000074591","189980664","0","3"]],"bids":[["0.00000074259","0","0","0"]],"ts":"1646003684717","checksum":-1180037016}]}
1646003684.731615: {"arg":{"channel":"books-l2-tbt","instId":"UNI-USD-SWAP"},"action":"update","data":[{"asks":[["9.619","260","0","1"],["9.623","0","0","0"]],"bids":[],"ts":"1646003684720","checksum":1199782659}]}
1646003684.741119: {"arg":{"channel":"books-l2-tbt","instId":"UNI-USD-SWAP"},"action":"update","data":[{"asks":[],"bids":[["9.609","5","0","1"]],"ts":"1646003684729","checksum":412160092}]}
1646003684.741183: {"arg":{"channel":"books-l2-tbt","instId":"BTC-USD-220325-40000-C"},"action":"update","data":[{"asks":[["0.051","29","0","1"],["0.0515","305","0","1"]],"bids":[],"ts":"1646003684731","checksum":-305748066}]}
1646003684.748725: {"arg":{"channel":"books-l2-tbt","instId":"ZEN-USDT"},"action":"update","data":[{"asks":[],"bids":[["32.12","0","0","0"],["32.11","1.55","0","1"],["31.86","0.31392","0","1"],["31.85","4.07","0","1"],["31.67","0","0","0"],["31.66","4.775516","0","2"],["31.55","0","0","0"],["31.54","6.61","0","1"],["31.24","0","0","0"],["31.23","9.641052","0","2"],["31.22","7.930163","0","2"],["30.93","2.834933","0","2"],["30.92","11.76","0","1"],["30.8","0","0","0"],["30.79","11.17","0","1"]],"ts":"1646003684737","checksum":840724299}]}
1646003684.752436: {"arg":{"channel":"books-l2-tbt","instId":"ELON-USDT"},"action":"update","data":[{"asks":[["0.00000074591","293937275","0","4"]],"bids":[],"ts":"1646003684739","checksum":-896155884}]}
1646003684.7525198: {"arg":{"channel":"books-l2-tbt","instId":"BTC-USD-220325-40000-C"},"action":"update","data":[{"asks":[],"bids":[["0.05","301","0","1"],["0.0495","300","0","1"]],"ts":"1646003684743","checksum":196564854}]}
1646003684.759291: {"arg":{"channel":"books-l2-tbt","instId":"ZEN-USDT"},"action":"update","data":[{"asks":[["32.9","61.51","0","2"],["32.91","0","0","0"],["33.36","4.52","0","1"],["33.37","0","0","0"],["33.82","7.49715","0","2"],["33.83","8.68","0","1"],["34.29","10.4","0","1"],["34.3","2.338605","0","1"],["34.77","13.28","0","1"],["34.78","0","0","0"]],"bids":[["30.37","0","0","0"],["30.36","14.46","0","1"]],"ts":"1646003684747","checksum":-1067596239}]}
1646003684.760833: {"arg":{"channel":"books-l2-tbt","instId":"UNI-USD-SWAP"},"action":"update","data":[{"asks":[["9.621","304","0","3"],["9.631","710","0","4"]],"bids":[["9.609","65","0","2"]],"ts":"1646003684749","checksum":68672389}]}
1646003684.771704: {"arg":{"channel":"books-l2-tbt","instId":"ZEN-USDT"},"action":"update","data":[{"asks":[["32.53","2.964416","0","2"]],"bids":[],"ts":"1646003684757","checksum":-520770548}]}
1646003684.778909: {"arg":{"channel":"books-l2-tbt","instId":"ZEN-USDT"},"action":"update","data":[{"asks":[["32.54","8","0","1"]],"bids":[],"ts":"1646003684767","checksum":2131710222}]}
1646003684.780992: {"arg":{"channel":"books-l2-tbt","instId":"UNI-USD-SWAP"},"action":"update","data":[{"asks":[["9.624","2","0","1"],["48.625","0","0","0"]],"bids":[["9.615","0","0","0"]],"ts":"1646003684770","checksum":-199617020}]}
1646003684.7899399: {"arg":{"channel":"books-l2-tbt","instId":"ZEN-USDT"},"action":"update","data":[{"asks":[["32.59","52.116428","0","2"]],"bids":[],"ts":"1646003684777","checksum":997966307}]}
1646003684.8032541: {"arg":{"channel":"books-l2-tbt","instId":"UNI-USD-SWAP"},"action":"update","data":[{"asks":[],"bids":[["9.612","282","0","2"],["9.611","121","0","2"],["9.61","155","0","2"]],"ts":"1646003684792","checksum":-819170232}]}
1646003684.803678: {"arg":{"channel":"books-l2-tbt","instId":"PROPS-ETH"},"action":"update","data":[{"asks":[["0.00000176","7518.11950204","0","1"],["0.00000178","0","0","0"],["0.00000181","957.99426183","0","1"],["0.00000182","1102.09328909","0","1"],["0.00000185","0","0","0"]],"bids":[["0.0000016","0","0","0"]],"ts":"1646003684793","checksum":-413249256}]}
1646003684.811797: {"arg":{"channel":"books-l2-tbt","instId":"ELON-USDT"},"action":"update","data":[{"asks":[["0.0000007477","0","0","0"],["0.0000011338","129154981","0","1"]],"bids":[],"ts":"1646003684800","checksum":85274723}]}
1646003684.823383: {"arg":{"channel":"books-l2-tbt","instId":"UNI-USD-SWAP"},"action":"update","data":[{"asks":[["9.637","1068","0","2"],["9.638","641","0","3"]],"bids":[["9.607","0","0","0"],["9.605","511","0","2"],["9.603","0","0","0"],["9.601","153","0","1"],["9.599","91","0","2"],["9.598","153","0","1"],["9.597","42","0","2"],["9.594","28","0","1"],["9.585","414","0","1"]],"ts":"1646003684812","checksum":559016169}]}
1646003684.8319502: {"arg":{"channel":"books-l2-tbt","instId":"ELON-USDT"},"action":"update","data":[{"asks":[["0.0000007459","445226872","0","1"],["0.00000074591","182284396","0","3"],["0.0000011338","0","0","0"]],"bids":[],"ts":"1646003684821","checksum":521833515}]}
1646003684.832735: {"arg":{"channel":"books-l2-tbt","instId":"UNI-USD-SWAP"},"action":"update","data":[{"asks":[["9.628","49","0","1"],["9.63","2","0","1"],["9.631","651","0","2"],["48.143","0","0","0"],["48.383","0","0","0"]],"bids":[],"ts":"1646003684822","checksum":-528168914}]}
1646003684.833128: {"arg":{"channel":"books-l2-tbt","instId":"BTC-USD-220325-40000-C"},"action":"update","data":[{"asks":[],"bids":[["0.05","0","0","0"],["0.0495","601","0","2"]],"ts":"1646003684824","checksum":1599394008}]}
1646003684.8463721: {"arg":{"channel":"books-l2-tbt","instId":"ELON-USDT"},"action":"update","data":[{"asks":[["0.00000074591","303212439","0","5"]],"bids":[],"ts":"1646003684832","checksum":-1094789329}]}
1646003684.846485: {"arg":{"channel":"books-l2-tbt","instId":"UNI-USD-SWAP"},"action":"update","data":[{"asks":[],"bids":[["9.58","9539","0","1"]],"ts":"1646003684833","checksum":332413182}]}
1646003684.8520892: {"arg":{"channel":"books-l2-tbt","instId":"ELON-USDT"},"action":"update","data":[{"asks":[["0.00000074591","199255828","0","4"]],"bids":[["0.0000007433","127133612","0","1"]],"ts":"1646003684842","checksum":1707418276}]}
1646003684.864479: {"arg":{"channel":"books-l2-tbt","instId":"ELON-USDT"},"action":"update","data":[{"asks":[["0.00000074589","103956611","0","1"],["0.00000113315","0","0","0"]],"bids":[],"ts":"1646003684851","checksum":375538212}]}
1646003684.864604: {"arg":{"channel":"books-l2-tbt","instId":"UNI-USD-SWAP"},"action":"update","data":[{"asks":[["9.628","52","0","2"]],"bids":[["9.609","60","0","1"]],"ts":"1646003684853","checksum":555899590}]}
1646003684.8827178: {"arg":{"channel":"books-l2-tbt","instId":"ZEN-USDT"},"action":"update","data":[{"asks":[],"bids":[["32.4","35.970599","0","1"]],"ts":"1646003684870","checksum":637937608}]}
1646003684.890214: {"arg":{"channel":"books-l2-tbt","instId":"ELON-USDT"},"action":"update","data":[{"asks":[["0.00000074589","151972284","0","2"]],"bids":[],"ts":"1646003684871","checksum":-2075406117}]}
1646003684.90396: {"arg":{"channel":"books-l2-tbt","instId":"ZEN-USDT"},"action":"update","data":[{"asks":[["32.56","3.65408","0","1"],["44.22","0","0","0"]],"bids":[],"ts":"1646003684889","checksum":923359498}]}
1646003684.906317: {"arg":{"channel":"books-l2-tbt","instId":"UNI-USD-SWAP"},"action":"update","data":[{"asks":[["9.624","0","0","0"],["9.628","3","0","1"],["9.63","82","0","2"],["48.143","1","0","1"]],"bids":[],"ts":"1646003684894","checksum":-1068445921}]}
1646003684.916207: {"arg":{"channel":"books-l2-tbt","instId":"ELON-USDT"},"action":"update","data":[{"asks":[["0.00000074592","0","0","0"],["0.00000074597","0","0","0"],["0.00000113315","35900750","0","1"],["0.0000011338","129154981","0","1"]],"bids":[["0.00000074381","51189869","0","1"]],"ts":"1646003684903","checksum":131160019}]}
1646003684.9162838: {"arg":{"channel":"books-l2-tbt","instId":"UNI-USD-SWAP"},"action":"update","data":[{"asks":[],"bids":[["9.609","62","0","2"]],"ts":"1646003684903","checksum":1454430799}]}
1646003684.9281762: {"arg":{"channel":"books-l2-tbt","instId":"ELON-USDT"},"action":"update","data":[{"asks":[],"bids":[["0.0000006993","0","0","0"],["0.00000068532","0","0","0"],["0.00000067162","0","0","0"],["0.00000065819","0","0","0"],["0.00000064475","449335469","0","1"]],"ts":"1646003684913","checksum":131160019}]}
1646003684.9450471: {"arg":{"channel":"books-l2-tbt","instId":"ZEN-USDT"},"action":"update","data":[{"asks":[["32.51","0.326344","0","1"],["44.2","0","0","0"]],"bids":[],"ts":"1646003684931","checksum":664580834}]}
1646003684.945128: {"arg":{"channel":"books-l2-tbt","instId":"ELON-USDT"},"action":"update","data":[{"asks":[["0.00000074589","48015673","0","1"]],"bids":[],"ts":"1646003684934","checksum":-1668755051}]}
1646003684.9481459: {"arg":{"channel":"books-l2-tbt","instId":"UNI-USD-SWAP"},"action":"update","data":[{"asks":[],"bids":[["9.6","22","0","1"],["9.599","63","0","1"],["9.598","176","0","2"],["9.597","16","0","1"],["9.595","26","0","1"],["9.594","0","0","0"]],"ts":"1646003684935","checksum":509249928}]}
1646003684.9514408: {"arg":{"channel":"books-l2-tbt","instId":"BTC-USD-220325-40000-C"},"action":"update","data":[{"asks":[],"bids":[["0.05","300","0","1"],["0.0495","301","0","1"]],"ts":"1646003684940","checksum":-561915348}]}
1646003684.956775: {"arg":{"channel":"books-l2-tbt","instId":"ELON-USDT"},"action":"update","data":[{"asks":[["0.0000007475","698000000","0","1"],["0.0000011338","0","0","0"]],"bids":[],"ts":"1646003684943","checksum":1210817825}]}
1646003684.963068: {"arg":{"channel":"books-l2-tbt","instId":"ZEN-USDT"},"action":"update","data":[{"asks":[],"bids":[["32.41","17.338359","0","1"]],"ts":"1646003684950","checksum":-1746761311}]}
1646003684.970573: {"arg":{"channel":"books-l2-tbt","instId":"UNI-USD-SWAP"},"action":"update","data":[{"asks":[],"bids":[["9.609","2","0","1"]],"ts":"1646003684957","checksum":-765838779}]}
1646003684.997591: {"arg":{"channel":"books-l2-tbt","instId":"ZEN-USDT"},"action":"update","data":[{"asks":[["32.61","0","0","0"],["44.2","0.120899","0","1"]],"bids":[],"ts":"1646003684986","checksum":-1496812933}]}
1646003685.0008519: {"arg":{"channel":"books-l2-tbt","instId":"UNI-USD-SWAP"},"action":"update","data":[{"asks":[["9.625","96","0","2"],["9.657","0","0","0"],["9.66","0","0","0"],["48.383","1","0","1"],["48.625","1","0","1"]],"bids":[],"ts":"1646003684988","checksum":-70644730}]}
1646003685.000972: {"arg":{"channel":"books-l2-tbt","instId":"ELON-USDT"},"action":"update","data":[{"asks":[["0.00000074591","52357697","0","1"]],"bids":[["0.0000007433","0","0","0"]],"ts":"1646003684989","checksum":-833331619}]}
1646003685.007977: {"arg":{"channel":"books-l2-tbt","instId":"ZEN-USDT"},"action":"update","data":[{"asks":[["32.86","1.52","0","1"],["32.9","60","0","1"],["44.2","0","0","0"]],"bids":[],"ts":"1646003684996","checksum":1552795637}]}
1646003685.0080562: {"arg":{"channel":"books-l2-tbt","instId":"UNI-USD-SWAP"},"action":"update","data":[{"asks":[["9.655","40","0","1"],["9.656","200","0","2"],["48.625","0","0","0"]],"bids":[],"ts":"1646003684997","checksum":414112565}]}
1646003685.0185652: {"arg":{"channel":"books-l2-tbt","instId":"ZEN-USDT"},"action":"update","data":[{"asks":[["33.32","4.52","0","1"],["33.36","0","0","0"],["33.78","7.48","0","1"],["33.82","0.01715","0","1"],["34.25","10.4","0","1"],["34.29","0","0","0"],["34.72","13.28","0","1"],["34.77","0","0","0"],["44.14","0","0","0"]],"bids":[],"ts":"1646003685007","checksum":1552795637}]}
1646003685.020797: {"arg":{"channel":"books-l2-tbt","instId":"ELON-USDT"},"action":"update","data":[{"asks":[["0.00000074589","159668552","0","2"]],"bids":[],"ts":"1646003685009","checksum":45477200}]}
1646003685.028492: {"arg":{"channel":"books-l2-tbt","instId":"ZEN-USDT"},"action":"update","data":[{"asks":[["32.56","0","0","0"],["44.14","0.039111","0","2"]],"bids":[],"ts":"1646003685017","checksum":1587786219}]}
1646003685.030995: {"arg":{"channel":"books-l2-tbt","instId":"UNI-USD-SWAP"},"action":"update","data":[{"asks":[["9.655","0","0","0"],["9.656","124","0","1"],["48.625","1","0","1"]],"bids":[["9.607","1","0","1"],["9.606","0","0","0"],["9.576","0","0","0"],["9.574","29","0","1"]],"ts":"1646003685019","checksum":724868782}]}
1646003685.044812: {"arg":{"channel":"books-l2-tbt","instId":"ELON-USDT"},"action":"update","data":[{"asks":[["0.00000074591","0","0","0"],["0.0000011338","129154981","0","1"]],"bids":[["0.00000074381","0","0","0"]],"ts":"1646003685030","checksum":-159519250}]}
1646003685.051191: {"arg":{"channel":"books-l2-tbt","instId":"ZEN-USDT"},"action":"update","data":[{"asks":[["32.52","8.662601","0","2"]],"bids":[],"ts":"1646003685038","checksum":321555403}]}
1646003685.060412: {"arg":{"channel":"books-l2-tbt","instId":"UNI-USD-SWAP"},"action":"update","data":[{"asks":[],"bids":[["9.61","102","0","1"],["9.586","158","0","2"]],"ts":"1646003685041","checksum":-515977317}]}
1646003685.0605319: {"arg":{"channel":"books-l2-tbt","instId":"ELON-USDT"},"action":"update","data":[{"asks":[["0.00000074588","445226872","0","1"],["0.0000011338","0","0","0"]],"bids":[],"ts":"1646003685041","checksum":1249319726}]}
1646003685.0624971: {"arg":{"channel":"books-l2-tbt","instId":"UNI-USD-SWAP"},"action":"update","data":[{"asks":[["9.63","80","0","1"],["9.631","658","0","3"]],"bids":[["9.611","174","0","3"],["9.601","175","0","2"],["9.6","0","0","0"],["9.599","84","0","2"],["9.598","153","0","1"],["9.596","23","0","1"],["9.595","0","0","0"]],"ts":"1646003685050","checksum":-1259265073}]}
1646003685.0700722: {"arg":{"channel":"books-l2-tbt","instId":"ELON-USDT"},"action":"update","data":[{"asks":[["0.00000074589","0","0","0"],["0.0000011338","129154981","0","1"]],"bids":[],"ts":"1646003685059","checksum":-1734121375}]}
1646003685.078378: {"arg":{"channel":"books-l2-tbt","instId":"ZEN-USDT"},"action":"update","data":[{"asks":[],"bids":[["31.86","4.38392","0","2"],["31.85","0","0","0"],["31.55","6.61","0","1"],["31.54","0","0","0"],["31.24","9.17","0","1"],["31.23","0.471052","0","1"],["30.93","14.594933","0","3"],["30.92","0","0","0"]],"ts":"1646003685066","checksum":321555403}]}
1646003685.080487: {"arg":{"channel":"books-l2-tbt","instId":"ELON-USDT"},"action":"update","data":[{"asks":[["0.00000074591","81175250","0","1"],["0.0000011338","0","0","0"]],"bids":[],"ts":"1646003685070","checksum":1110283890}]}
1646003685.08146: {"arg":{"channel":"books-l2-tbt","instId":"UNI-USD-SWAP"},"action":"update","data":[{"asks":[["9.631","653","0","3"]],"bids":[],"ts":"1646003685071","checksum":-802123958}]}
1646003685.091467: {"arg":{"channel":"books-l2-tbt","instId":"ZEN-USDT"},"action":"update","data":[{"asks":[["32.51","0","0","0"],["44.2","0.120899","0","1"]],"bids":[],"ts":"1646003685079","checksum":571861050}]}
1646003685.091564: {"arg":{"channel":"books-l2-tbt","instId":"ELON-USDT"},"action":"update","data":[{"asks":[["0.00000074587","111652879","0","1"],["0.0000007459","0","0","0"]],"bids":[],"ts":"1646003685080","checksum":-10596042}]}
1646003685.101381: {"arg":{"channel":"books-l2-tbt","instId":"UNI-USD-SWAP"},"action":"update","data":[{"asks":[["9.625","25","0","1"],["9.628","64","0","2"]],"bids":[],"ts":"1646003685089","checksum":-871290944}]}
1646003685.111468: {"arg":{"channel":"books-l2-tbt","instId":"ZEN-USDT"},"action":"update","data":[{"asks":[["32.56","3.980363","0","2"],["44.2","0","0","0"]],"bids":[],"ts":"1646003685099","checksum":102830161}]}
1646003685.1308029: {"arg":{"channel":"books-l2-tbt","instId":"ELON-USDT"},"action":"update","data":[{"asks":[],"bids":[["0.00000074449","219861835","0","1"],["0.00000074381","44777386","0","1"]],"ts":"1646003685112","checksum":-1489129366}]}
1646003685.133878: {"arg":{"channel":"books-l2-tbt","instId":"ZEN-USDT"},"action":"update","data":[{"asks":[["32.56","3.65408","0","1"]],"bids":[],"ts":"1646003685121","checksum":-1825872662}]}
1646003685.134675: {"arg":{"channel":"books-l2-tbt","instId":"ELON-USDT"},"action":"update","data":[{"asks":[["0.00000074588","0","0","0"],["0.0000011338","129154981","0","1"]],"bids":[],"ts":"1646003685122","checksum":-683226607}]}
1646003685.144056: {"arg":{"channel":"books-l2-tbt","instId":"ELON-USDT"},"action":"update","data":[{"asks":[["0.00000074587","215609490","0","2"]],"bids":[],"ts":"1646003685132","checksum":-323413491}]}
1646003685.144165: {"arg":{"channel":"books-l2-tbt","instId":"ETH-USD-220624-12000-P"},"action":"update","data":[{"asks":[["4.046","0","0","0"],["4.0465","201","0","1"]],"bids":[],"ts":"1646003685134","checksum":355203380}]}
1646003685.1555378: {"arg":{"channel":"books-l2-tbt","instId":"ELON-USDT"},"action":"update","data":[{"asks":[["0.00000074586","445226872","0","1"],["0.00000074587","0","0","0"]],"bids":[["0.0000007433","159801791","0","1"]],"ts":"1646003685144","checksum":-207375315}]}
1646003685.165268: {"arg":{"channel":"books-l2-tbt","instId":"ELON-USDT"},"action":"update","data":[{"asks":[["0.00000074586","660836362","0","3"]],"bids":[],"ts":"1646003685153","checksum":2128907828}]}
1646003685.184881: {"arg":{"channel":"books-l2-tbt","instId":"ZEN-USDT"},"action":"update","data":[{"asks":[["32.8","3.858605","0","2"],["32.84","0","0","0"],["33.13","3.94","0","1"],["33.17","0","0","0"],["33.46","6.33","0","1"],["33.5","0.496261","0","2"],["33.79","8.7","0","1"],["33.83","0","0","0"],["34.12","11.04","0","1"],["34.16","0","0","0"]],"bids":[],"ts":"1646003685173","checksum":2123155267}]}
1646003685.1919959: {"arg":{"channel":"books-l2-tbt","instId":"ELON-USDT"},"action":"update","data":[{"asks":[],"bids":[["0.00000074381","0","0","0"]],"ts":"1646003685176","checksum":-1128420393}]}
1646003685.205687: {"arg":{"channel":"books-l2-tbt","instId":"UNI-USD-SWAP"},"action":"update","data":[{"asks":[["9.624","61","0","1"],["9.628","3","0","1"],["48.625","0","0","0"]],"bids":[],"ts":"1646003685194","checksum":-928113312}]}
1646003685.211076: {"arg":{"channel":"books-l2-tbt","instId":"ELON-USDT"},"action":"update","data":[{"asks":[["0.00000074585","68570346","0","1"],["0.0000011338","0","0","0"]],"bids":[],"ts":"1646003685196","checksum":-326325593}]}
1646003685.218328: {"arg":{"channel":"books-l2-tbt","instId":"ZEN-USDT"},"action":"update","data":[{"asks":[["32.86","0","0","0"],["32.9","61.51","0","2"],["33.32","0","0","0"],["33.36","4.52","0","1"],["33.78","0","0","0"],["33.82","7.49715","0","2"],["34.25","0","0","0"],["34.29","10.4","0","1"],["34.72","0","0","0"],["34.77","13.28","0","1"],["44.2","0.120899","0","1"],["44.22","2.271956","0","1"]],"bids":[],"ts":"1646003685205","checksum":-1502900017}]}
1646003685.2184582: {"arg":{"channel":"books-l2-tbt","instId":"ELON-USDT"},"action":"update","data":[{"asks":[["0.00000074585","120928043","0","2"]],"bids":[],"ts":"1646003685208","checksum":-583630295}]}
1646003685.229186: {"arg":{"channel":"books-l2-tbt","instId":"UNI-USD-SWAP"},"action":"update","data":[{"asks":[["9.64","24","0","1"],["9.641","123","0","2"],["9.643","28","0","1"],["9.644","0","0","0"],["9.646","30","0","1"],["9.647","2266","0","2"],["48.143","0","0","0"],["48.383","0","0","0"]],"bids":[],"ts":"1646003685217","checksum":-1763389423}]}
1646003685.249163: {"arg":{"channel":"books-l2-tbt","instId":"UNI-USD-SWAP"},"action":"update","data":[{"asks":[],"bids":[["9.584","4","0","1"]],"ts":"1646003685236","checksum":890895514}]}
1646003685.249239: {"arg":{"channel":"books-l2-tbt","instId":"ELON-USDT"},"action":"update","data":[{"asks":[["0.00000074584","445226872","0","1"],["0.00000074585","146148105","0","3"],["0.00000074586","549183483","0","2"],["0.00000113315","0","0","0"]],"bids":[],"ts":"1646003685239","checksum":-1092482103}]}
1646003685.260015: {"arg":{"channel":"books-l2-tbt","instId":"ELON-USDT"},"action":"update","data":[{"asks":[],"bids":[["0.00000074246","3202002241","0","1"]],"ts":"1646003685247","checksum":380377138}]}
1646003685.2722769: {"arg":{"channel":"books-l2-tbt","instId":"ZEN-USDT"},"action":"update","data":[{"asks":[["32.8","2.338605","0","1"],["32.84","1.52","0","1"],["44.22","0","0","0"]],"bids":[],"ts":"1646003685256","checksum":-1638659020}]}
1646003685.2723699: {"arg":{"channel":"books-l2-tbt","instId":"ELON-USDT"},"action":"update","data":[{"asks":[["0.00000074586","0","0","0"],["0.00000113315","35900750","0","1"]],"bids":[],"ts":"1646003685257","checksum":377323180}]}
1646003685.2797592: {"arg":{"channel":"books-l2-tbt","instId":"ZEN-USDT"},"action":"update","data":[{"asks":[["33.13","0","0","0"],["33.17","3.93","0","1"],["33.46","0","0","0"],["33.5","6.816261","0","3"],["33.79","0","0","0"],["33.83","8.68","0","1"],["34.12","0","0","0"],["34.16","11.02","0","1"],["44.22","2.271956","0","1"]],"bids":[],"ts":"1646003685266","checksum":-1638659020}]}
1646003685.282173: {"arg":{"channel":"books-l2-tbt","instId":"ELON-USDT"},"action":"update","data":[{"asks":[["0.00000074583","103956611","0","1"],["0.00000113315","0","0","0"]],"bids":[["0.0000007282","0","0","0"]],"ts":"1646003685267","checksum":1948527037}]}
1646003685.294104: {"arg":{"channel":"books-l2-tbt","instId":"UNI-USD-SWAP"},"action":"update","data":[{"asks":[["9.658","101","0","2"],["9.66","80","0","1"],["47.903","0","0","0"]],"bids":[],"ts":"1646003685278","checksum":890895514}]}
1646003685.300992: {"arg":{"channel":"books-l2-tbt","instId":"ELON-USDT"},"action":"update","data":[{"asks":[["0.00000074583","151972284","0","2"]],"bids":[],"ts":"1646003685279","checksum":1505030050}]}
1646003685.303929: {"arg":{"channel":"books-l2-tbt","instId":"PROPS-ETH"},"action":"update","data":[{"asks":[["0.00000181","0","0","0"],["0.00000182","0","0","0"]],"bids":[],"ts":"1646003685291","checksum":290223269}]}
1646003685.331151: {"arg":{"channel":"books-l2-tbt","instId":"ELON-USDT"},"action":"update","data":[{"asks":[],"bids":[["0.0000007433","0","0","0"]],"ts":"1646003685319","checksum":1668649560}]}
1646003685.335385: {"arg":{"channel":"books-l2-tbt","instId":"PROPS-ETH"},"action":"update","data":[{"asks":[["0.00000177","1249.25468133","0","1"],["0.00000178","1234.56499342","0","1"],["0.00000185","1494.70300406","0","1"],["0.00000186","509.66221398","0","1"]],"bids":[["0.0000016","10243.0163875","0","1"]],"ts":"1646003685321","checksum":1496286292}]}
1646003685.343987: {"arg":{"channel":"books-l2-tbt","instId":"ELON-USDT"},"action":"update","data":[{"asks":[["0.00000074582","445226872","0","1"],["0.00000113256","0","0","0"]],"bids":[["0.00000074381","177100789","0","1"]],"ts":"1646003685328","checksum":-856219150}]}
1646003685.350067: {"arg":{"channel":"books-l2-tbt","instId":"ELON-USDT"},"action":"update","data":[{"asks":[["0.00000074583","48015673","0","1"],["0.00000074584","0","0","0"],["0.00000113256","10462875","0","1"]],"bids":[],"ts":"1646003685338","checksum":329112192}]}
1646003685.369916: {"arg":{"channel":"books-l2-tbt","instId":"ELON-USDT"},"action":"update","data":[{"asks":[["0.00000074583","0","0","0"],["0.00000113315","35900750","0","1"]],"bids":[],"ts":"1646003685350","checksum":531448033}]}
1646003685.373641: {"arg":{"channel":"books-l2-tbt","instId":"ELON-USDT"},"action":"update","data":[{"asks":[["0.00000074581","48015673","0","1"],["0.00000113315","0","0","0"]],"bids":[],"ts":"1646003685361","checksum":1961812639}]}
1646003685.3867562: {"arg":{"channel":"books-l2-tbt","instId":"UNI-USD-SWAP"},"action":"update","data":[{"asks":[["9.64","0","0","0"],["9.642","387","0","4"],["9.643","0","0","0"],["9.645","76","0","2"],["9.646","0","0","0"],["9.648","202","0","3"],["47.903","1","0","1"],["48.143","1","0","1"],["48.383","1","0","1"]],"bids":[["9.602","23","0","1"],["9.601","153","0","1"],["9.6","28","0","1"],["9.599","63","0","1"],["9.597","41","0","2"],["9.596","0","0","0"]],"ts":"1646003685374","checksum":213850605}]}
1646003685.395956: {"arg":{"channel":"books-l2-tbt","instId":"ELON-USDT"},"action":"update","data":[{"asks":[["0.00000074581","159668552","0","2"]],"bids":[],"ts":"1646003685383","checksum":-419461564}]}
1646003685.436351: {"arg":{"channel":"books-l2-tbt","instId":"ELON-USDT"},"action":"update","data":[{"asks":[["0.0000007458","445226872","0","1"],["0.00000074581","212776275","0","3"],["0.00000074585","25220062","0","1"],["0.00000113256","0","0","0"]],"bids":[["0.00000069607","326325771","0","1"],["0.00000068215","191274330","0","1"],["0.00000066851","253589652","0","1"],["0.00000065514","244774459","0","1"],["0.00000064475","0","0","0"]],"ts":"1646003685422","checksum":1646260027}]}
1646003685.447983: {"arg":{"channel":"books-l2-tbt","instId":"UNI-USD-SWAP"},"action":"update","data":[{"asks":[["9.624","85","0","1"]],"bids":[],"ts":"1646003685434","checksum":-1070769433}]}
1646003685.4538: {"arg":{"channel":"books-l2-tbt","instId":"ELON-USDT"},"action":"update","data":[{"asks":[["0.00000074581","53107723","0","1"],["0.00000074582","0","0","0"],["0.00000113256","10462875","0","1"]],"bids":[],"ts":"1646003685442","checksum":-934035329}]}
1646003685.4676979: {"arg":{"channel":"books-l2-tbt","instId":"UNI-USD-SWAP"},"action":"update","data":[{"asks":[["9.621","282","0","2"],["9.629","39","0","2"]],"bids":[],"ts":"1646003685456","checksum":340583019}]}
1646003685.473855: {"arg":{"channel":"books-l2-tbt","instId":"ELON-USDT"},"action":"update","data":[{"asks":[["0.00000074579","159668552","0","2"],["0.00000113256","0","0","0"]],"bids":[],"ts":"1646003685463","checksum":-1434487403}]}
1646003685.494108: {"arg":{"channel":"books-l2-tbt","instId":"ZEN-USDT"},"action":"update","data":[{"asks":[],"bids":[["32.45","1.940674","0","1"]],"ts":"1646003685482","checksum":-801395898}]}
1646003685.518613: {"arg":{"channel":"books-l2-tbt","instId":"ELON-USDT"},"action":"update","data":[{"asks":[["0.00000074578","445226872","0","1"],["0.00000113251","0","0","0"]],"bids":[],"ts":"1646003685504","checksum":-1205087654}]}
1646003685.5487318: {"arg":{"channel":"books-l2-tbt","instId":"ELON-USDT"},"action":"update","data":[{"asks":[["0.00000074579","0","0","0"],["0.00000113251","12272136","0","1"]],"bids":[],"ts":"1646003685535","checksum":536616194}]}
1646003685.5577989: {"arg":{"channel":"books-l2-tbt","instId":"ELON-USDT"},"action":"update","data":[{"asks":[["0.0000007458","0","0","0"],["0.00000113256","10462875","0","1"]],"bids":[],"ts":"1646003685545","checksum":1785297649}]}
1646003685.570401: {"arg":{"channel":"books-l2-tbt","instId":"ELON-USDT"},"action":"update","data":[{"asks":[["0.00000074577","263625163","0","3"],["0.00000113256","0","0","0"]],"bids":[],"ts":"1646003685557","checksum":-622442687}]}
1646003685.578177: {"arg":{"channel":"books-l2-tbt","instId":"ELON-USDT"},"action":"update","data":[{"asks":[["0.00000074578","0","0","0"],["0.00000074591","0","0","0"],["0.00000113256","10462875","0","1"],["0.00000113315","35900750","0","1"]],"bids":[["0.00000074381","0","0","0"]],"ts":"1646003685566","checksum":1811922501}]}
1646003685.5889611: {"arg":{"channel":"books-l2-tbt","instId":"ELON-USDT"},"action":"update","data":[{"asks":[["0.00000074577","151972284","0","2"]],"bids":[],"ts":"1646003685577","checksum":-1454684734}]}
1646003685.609938: {"arg":{"channel":"books-l2-tbt","instId":"ELON-USDT"},"action":"update","data":[{"asks":[["0.00000074577","0","0","0"],["0.0000007458","445226872","0","1"]],"bids":[],"ts":"1646003685599","checksum":-1447811021}]}
1646003685.6186209: {"arg":{"channel":"books-l2-tbt","instId":"ZEN-USDT"},"action":"update","data":[{"asks":[],"bids":[["32.44","222.918156","0","5"]],"ts":"1646003685605","checksum":1741111998}]}
1646003685.618697: {"arg":{"channel":"books-l2-tbt","instId":"ELON-USDT"},"action":"update","data":[{"asks":[],"bids":[["0.00000074449","0","0","0"]],"ts":"1646003685608","checksum":-774418532}]}
1646003685.639654: {"arg":{"channel":"books-l2-tbt","instId":"ELON-USDT"},"action":"update","data":[{"asks":[["0.00000074579","103956611","0","1"],["0.00000074752","0","0","0"]],"bids":[],"ts":"1646003685626","checksum":-1644909449}]}
1646003685.6439471: {"arg":{"channel":"books-l2-tbt","instId":"ELON-USDT"},"action":"update","data":[{"asks":[["0.00000074579","224884654","0","3"],["0.00000074581","0","0","0"],["0.00000074585","0","0","0"],["0.0000011338","129154981","0","1"],["0.0000011372","6179288","0","1"]],"bids":[["0.00000074435","23639893","0","1"],["0.00000074246","0","0","0"]],"ts":"1646003685631","checksum":-1775807433}]}
1646003685.653069: {"arg":{"channel":"books-l2-tbt","instId":"ELON-USDT"},"action":"update","data":[{"asks":[["0.00000074576","445226872","0","1"],["0.00000074741","2935562669","0","1"],["0.0000011338","0","0","0"],["0.0000011372","0","0","0"]],"bids":[],"ts":"1646003685640","checksum":1258632328}]}
1646003685.65613: {"arg":{"channel":"books-l2-tbt","instId":"UNI-USD-SWAP"},"action":"update","data":[{"asks":[],"bids":[["9.6","0","0","0"]],"ts":"1646003685644","checksum":-894182180}]}
1646003685.663763: {"arg":{"channel":"books-l2-tbt","instId":"ELON-USDT"},"action":"update","data":[{"asks":[["0.0000007458","526402122","0","2"]],"bids":[],"ts":"1646003685651","checksum":1895982473}]}
1646003685.666199: {"arg":{"channel":"books-l2-tbt","instId":"UNI-USD-SWAP"},"action":"update","data":[{"asks":[["9.642","364","0","3"],["9.645","50","0","1"],["9.648","179","0","2"]],"bids":[["9.602","0","0","0"],["9.597","16","0","1"]],"ts":"1646003685654","checksum":1605574100}]}
1646003685.6723971: {"arg":{"channel":"books-l2-tbt","instId":"ELON-USDT"},"action":"update","data":[{"asks":[["0.00000074576","0","0","0"],["0.00000074579","168943716","0","3"],["0.0000011338","129154981","0","1"]],"bids":[],"ts":"1646003685661","checksum":-1676631673}]}
1646003685.6823208: {"arg":{"channel":"books-l2-tbt","instId":"UNI-USD-SWAP"},"action":"update","data":[{"asks":[["9.641","151","0","3"],["9.644","26","0","1"],["9.647","2288","0","3"],["48.383","0","0","0"]],"bids":[["9.601","175","0","2"],["9.599","89","0","2"],["9.596","24","0","1"]],"ts":"1646003685665","checksum":52211755}]}
1646003685.682863: {"arg":{"channel":"books-l2-tbt","instId":"ELON-USDT"},"action":"update","data":[{"asks":[["0.00000074575","103956611","0","1"],["0.00000074579","120928043","0","2"],["0.00000074741","0","0","0"]],"bids":[["0.00000072648","7354766269","0","1"]],"ts":"1646003685672","checksum":-271167106}]}
1646003685.689706: {"arg":{"channel":"books-l2-tbt","instId":"UNI-USD-SWAP"},"action":"update","data":[{"asks":[],"bids":[["9.608","40","0","3"]],"ts":"1646003685675","checksum":-1052099489}]}
1646003685.6964102: {"arg":{"channel":"books-l2-tbt","instId":"ELON-USDT"},"action":"update","data":[{"asks":[["0.00000074575","0","0","0"],["0.00000074578","48015673","0","1"]],"bids":[],"ts":"1646003685683","checksum":575589896}]}
1646003685.702912: {"arg":{"channel":"books-l2-tbt","instId":"ELON-USDT"},"action":"update","data":[{"asks":[["0.00000074574","103956611","0","1"],["0.00000074578","0","0","0"]],"bids":[],"ts":"1646003685692","checksum":-1178205577}]}
1646003685.710007: {"arg":{"channel":"books-l2-tbt","instId":"UNI-USD-SWAP"},"action":"update","data":[{"asks":[],"bids":[["9.609","0","0","0"]],"ts":"1646003685697","checksum":-1636992735}]}
1646003685.718714: {"arg":{"channel":"books-l2-tbt","instId":"ELON-USDT"},"action":"update","data":[{"asks":[["0.00000074574","0","0","0"],["0.00000074577","48015673","0","1"]],"bids":[],"ts":"1646003685703","checksum":-492349842}]}
1646003685.7260191: {"arg":{"channel":"books-l2-tbt","instId":"ELON-USDT"},"action":"update","data":[{"asks":[["0.00000074573","103956611","0","1"],["0.00000074577","0","0","0"]],"bids":[["0.00000074231","3469324618","0","1"]],"ts":"1646003685713","checksum":1303791229}]}
1646003685.729264: {"arg":{"channel":"books-l2-tbt","instId":"PROPS-ETH"},"action":"update","data":[{"asks":[],"bids":[["0.00000167","458175.549481","0","3"]],"ts":"1646003685718","checksum":91364536}]}
1646003685.734659: {"arg":{"channel":"books-l2-tbt","instId":"ELON-USDT"},"action":"update","data":[{"asks":[["0.00000074573","0","0","0"],["0.00000074576","48015673","0","1"]],"bids":[["0.0000007433","109761807","0","1"]],"ts":"1646003685723","checksum":790071349}]}
1646003685.748662: {"arg":{"channel":"books-l2-tbt","instId":"ELON-USDT"},"action":"update","data":[{"asks":[["0.00000074576","0","0","0"],["0.00000074729","2935602070","0","1"]],"bids":[],"ts":"1646003685734","checksum":691403252}]}
1646003685.750526: {"arg":{"channel":"books-l2-tbt","instId":"PROPS-ETH"},"action":"update","data":[{"asks":[],"bids":[["0.00000167","172714.347553","0","1"]],"ts":"1646003685738","checksum":-1586467529}]}
1646003685.756756: {"arg":{"channel":"books-l2-tbt","instId":"ELON-USDT"},"action":"update","data":[{"asks":[["0.00000074579","168943716","0","3"],["0.00000074729","0","0","0"],["0.0000011372","6179288","0","1"]],"bids":[],"ts":"1646003685745","checksum":351493052}]}
1646003685.777387: {"arg":{"channel":"books-l2-tbt","instId":"ELON-USDT"},"action":"update","data":[{"asks":[["0.00000074578","445226872","0","1"],["0.00000074745","3602711826","0","1"],["0.0000011338","0","0","0"],["0.0000011372","0","0","0"]],"bids":[],"ts":"1646003685765","checksum":1840429572}]}
1646003685.779434: {"arg":{"channel":"books-l2-tbt","instId":"UNI-USD-SWAP"},"action":"update","data":[{"asks":[["9.624","0","0","0"],["9.625","110","0","2"],["48.383","1","0","1"]],"bids":[],"ts":"1646003685768","checksum":-410821940}]}
1646003685.80243: {"arg":{"channel":"books-l2-tbt","instId":"UNI-USD-SWAP"},"action":"update","data":[{"asks":[["9.653","0","0","0"],["48.625","1","0","1"]],"bids":[["9.612","391","0","3"],["9.611","65","0","2"],["9.579","50","0","1"]],"ts":"1646003685790","checksum":-1914154115}]}
1646003685.8025842: {"arg":{"channel":"books-l2-tbt","instId":"ELON-USDT"},"action":"update","data":[{"asks":[["0.00000074577","111652879","0","1"],["0.00000074579","120928043","0","2"],["0.00000113315","0","0","0"]],"bids":[],"ts":"1646003685791","checksum":2020253416}]}
1646003685.809076: {"arg":{"channel":"books-l2-tbt","instId":"PROPS-ETH"},"action":"update","data":[{"asks":[["0.00000177","0","0","0"],["0.00000178","0","0","0"],["0.00000181","1401.70578108","0","1"],["0.00000182","659.40178693","0","1"],["0.00000185","0","0","0"],["0.00000186","0","0","0"],["0.00000187","783.68243322","0","1"]],"bids":[["0.00000167","458174.682539","0","3"],["0.00000161","9875.9454281","0","1"],["0.0000016","0","0","0"]],"ts":"1646003685797","checksum":-147329584}]}
1646003685.813316: {"arg":{"channel":"books-l2-tbt","instId":"UNI-USD-SWAP"},"action":"update","data":[{"asks":[],"bids":[["9.575","35","0","1"]],"ts":"1646003685800","checksum":-1914154115}]}
1646003685.824449: {"arg":{"channel":"books-l2-tbt","instId":"UNI-USD-SWAP"},"action":"update","data":[{"asks":[["9.625","85","0","1"]],"bids":[],"ts":"1646003685811","checksum":-400007293}]}
1646003685.8245518: {"arg":{"channel":"books-l2-tbt","instId":"ELON-USDT"},"action":"update","data":[{"asks":[["0.00000074577","159668552","0","2"]],"bids":[["0.0000007433","0","0","0"]],"ts":"1646003685814","checksum":-1986486876}]}
1646003685.8344262: {"arg":{"channel":"books-l2-tbt","instId":"UNI-USD-SWAP"},"action":"update","data":[{"asks":[],"bids":[["9.609","1","0","1"]],"ts":"1646003685820","checksum":1686110121}]}
1646003685.845626: {"arg":{"channel":"books-l2-tbt","instId":"UNI-USD-SWAP"},"action":"update","data":[{"asks":[["9.649","9344","0","3"],["9.663","0","0","0"],["48.868","1","0","1"]],"bids":[["9.578","0","0","0"]],"ts":"1646003685831","checksum":776055259}]}
1646003685.845698: {"arg":{"channel":"books-l2-tbt","instId":"ELON-USDT"},"action":"update","data":[{"asks":[["0.0000007458","81175250","0","1"]],"bids":[],"ts":"1646003685834","checksum":-305088698}]}
1646003685.854484: {"arg":{"channel":"books-l2-tbt","instId":"UNI-USD-SWAP"},"action":"update","data":[{"asks":[["9.659","1516","0","3"]],"bids":[["9.608","38","0","2"]],"ts":"1646003685841","checksum":2002237881}]}
1646003685.868439: {"arg":{"channel":"books-l2-tbt","instId":"UNI-USD-SWAP"},"action":"update","data":[{"asks":[],"bids":[["9.574","539","0","2"]],"ts":"1646003685851","checksum":2002237881}]}
1646003685.868564: {"arg":{"channel":"books-l2-tbt","instId":"ELON-USDT"},"action":"update","data":[{"asks":[],"bids":[["0.00000074335","1627000000","0","1"]],"ts":"1646003685854","checksum":1950764223}]}
1646003685.89634: {"arg":{"channel":"books-l2-tbt","instId":"ELON-USDT"},"action":"update","data":[{"asks":[["0.00000074577","111652879","0","1"]],"bids":[],"ts":"1646003685884","checksum":-1032599033}]}
1646003685.9315379: {"arg":{"channel":"books-l2-tbt","instId":"ELON-USDT"},"action":"update","data":[{"asks":[["0.00000074577","189980664","0","3"],["0.00000074579","0","0","0"],["0.00000113315","35900750","0","1"]],"bids":[],"ts":"1646003685888","checksum":1437698123}]}
1646003685.931628: {"arg":{"channel":"trades","instId":"ZEN-USDT"},"data":[{"instId":"ZEN-USDT","tradeId":"15270488","px":"32.49","sz":"8","side":"sell","ts":"1646003685888"}]}
1646003685.931658: {"arg":{"channel":"trades","instId":"ZEN-USDT"},"data":[{"instId":"ZEN-USDT","tradeId":"15270489","px":"32.49","sz":"0.327006","side":"sell","ts":"1646003685888"}]}
1646003685.931676: {"arg":{"channel":"trades","instId":"ZEN-USDT"},"data":[{"instId":"ZEN-USDT","tradeId":"15270490","px":"32.48","sz":"17.8359","side":"sell","ts":"1646003685888"}]}
1646003685.931691: {"arg":{"channel":"trades","instId":"ZEN-USDT"},"data":[{"instId":"ZEN-USDT","tradeId":"15270491","px":"32.47","sz":"10.852483","side":"sell","ts":"1646003685888"}]}
1646003685.931705: {"arg":{"channel":"books-l2-tbt","instId":"ZEN-USDT"},"action":"update","data":[{"asks":[],"bids":[["32.49","0","0","0"],["32.48","0","0","0"],["32.47","42.352157","0","2"]],"ts":"1646003685897","checksum":-1606347254}]}
1646003685.931743: {"arg":{"channel":"books-l2-tbt","instId":"ELON-USDT"},"action":"update","data":[{"asks":[],"bids":[["0.00000074381","178182628","0","1"]],"ts":"1646003685899","checksum":499071666}]}
1646003685.9317682: {"arg":{"channel":"books-l2-tbt","instId":"ELON-USDT"},"action":"update","data":[{"asks":[],"bids":[["0.00000069607","0","0","0"]],"ts":"1646003685909","checksum":499071666}]}
1646003685.931791: {"arg":{"channel":"books-l2-tbt","instId":"ZEN-USDT"},"action":"update","data":[{"asks":[["32.58","51","0","1"],["32.6","117.317306","0","3"],["32.63","95","0","1"],["32.64","0","0","0"],["44.22","0","0","0"]],"bids":[["32.47","2.20464","0","1"],["32.46","2.118228","0","1"],["32.44","127.918156","0","4"],["32.43","110.38033","0","2"]],"ts":"1646003685918","checksum":1626023374}]}
1646003685.934633: {"arg":{"channel":"books-l2-tbt","instId":"ELON-USDT"},"action":"update","data":[{"asks":[["0.00000074576","445226872","0","1"],["0.00000113315","0","0","0"]],"bids":[["0.00000068215","0","0","0"],["0.00000066851","0","0","0"],["0.00000065514","0","0","0"],["0.00000064198","231860125","0","1"]],"ts":"1646003685920","checksum":-1422438177}]}
1646003685.942133: {"arg":{"channel":"books-l2-tbt","instId":"ELON-USDT"},"action":"update","data":[{"asks":[["0.00000074577","293937275","0","4"]],"bids":[],"ts":"1646003685930","checksum":1891044592}]}
1646003685.959421: {"arg":{"channel":"books-l2-tbt","instId":"ZEN-USDT"},"action":"update","data":[{"asks":[["32.51","1.918251","0","1"],["44.2","0","0","0"]],"bids":[["32.47","0","0","0"],["32.46","0","0","0"]],"ts":"1646003685939","checksum":-154657527}]}
1646003685.95956: {"arg":{"channel":"books-l2-tbt","instId":"ELON-USDT"},"action":"update","data":[{"asks":[["0.00000074577","78327785","0","2"]],"bids":[["0.00000074381","0","0","0"]],"ts":"1646003685941","checksum":-1519784789}]}
1646003685.961479: {"arg":{"channel":"books-l2-tbt","instId":"ZEN-USDT"},"action":"update","data":[{"asks":[],"bids":[["32.46","8.87","0","2"]],"ts":"1646003685949","checksum":1026567579}]}
1646003685.962201: {"arg":{"channel":"books-l2-tbt","instId":"ELON-USDT"},"action":"update","data":[{"asks":[["0.00000074575","215609490","0","2"],["0.00000074578","0","0","0"]],"bids":[],"ts":"1646003685951","checksum":1789565915}]}
1646003685.975818: {"arg":{"channel":"books-l2-tbt","instId":"ZEN-USDT"},"action":"update","data":[{"asks":[],"bids":[["32.46","78.87","0","4"],["32.43","114.066965","0","3"],["32.41","0","0","0"]],"ts":"1646003685960","checksum":1011628449}]}
1646003685.9824178: {"arg":{"channel":"books-l2-tbt","instId":"ZEN-USDT"},"action":"update","data":[{"asks":[["32.53","6.618496","0","3"],["32.56","0","0","0"],["44.2","0.120899","0","1"]],"bids":[["32.46","79.370345","0","5"]],"ts":"1646003685971","checksum":1792022530}]}
1646003685.998881: {"arg":{"channel":"books-l2-tbt","instId":"ZEN-USDT"},"action":"update","data":[{"asks":[["32.51","0","0","0"],["44.22","2.271956","0","1"]],"bids":[["32.44","55.520784","0","2"],["32.4","0","0","0"]],"ts":"1646003685981","checksum":1376029883}]}
1646003686.003592: {"arg":{"channel":"books-l2-tbt","instId":"ZEN-USDT"},"action":"update","data":[{"asks":[["32.5","1.162404","0","1"],["32.6","104.041409","0","2"],["44.22","0","0","0"]],"bids":[["32.46","81.428648","0","6"],["32.41","15.36651","0","1"]],"ts":"1646003685992","checksum":-1251238993}]}
1646003686.024329: {"arg":{"channel":"books-l2-tbt","instId":"ZEN-USDT"},"action":"update","data":[{"asks":[["32.51","1.969196","0","1"],["32.52","8","0","1"],["32.56","1.917936","0","1"],["44.14","0","0","0"],["44.2","0","0","0"]],"bids":[],"ts":"1646003686013","checksum":1203324056}]}
1646003686.026012: {"arg":{"channel":"books-l2-tbt","instId":"ELON-USDT"},"action":"update","data":[{"asks":[["0.00000074574","445226872","0","1"],["0.00000113256","0","0","0"]],"bids":[],"ts":"1646003686015","checksum":1823216058}]}
1646003686.028224: {"arg":{"channel":"tickers","instId":"ZEN-USDT"},"data":[{"instType":"SPOT","instId":"ZEN-USDT","last":"32.47","lastSz":"10.852483","askPx":"32.52","askSz":"11.516671","bidPx":"32.48","bidSz":"18.170174","open24h":"33.34","high24h":"35.26","low24h":"31.91","sodUtc0":"33.36","sodUtc8":"34.26","volCcy24h":"1484847.93541","vol24h":"44402.966393","ts":"1646003686007"}]}
1646003686.049797: {"arg":{"channel":"books-l2-tbt","instId":"ELON-USDT"},"action":"update","data":[{"asks":[["0.00000074575","0","0","0"],["0.00000074576","0","0","0"],["0.00000113256","10462875","0","1"],["0.00000113315","35900750","0","1"]],"bids":[],"ts":"1646003686036","checksum":1602356050}]}
1646003686.0574982: {"arg":{"channel":"books-l2-tbt","instId":"ZEN-USDT"},"action":"update","data":[{"asks":[["32.49","0.408393","0","1"],["44.13","0","0","0"]],"bids":[],"ts":"1646003686044","checksum":-777207707}]}
1646003686.0663419: {"arg":{"channel":"books-l2-tbt","instId":"ZEN-USDT"},"action":"update","data":[{"asks":[],"bids":[["32.42","90.771293","0","3"]],"ts":"1646003686053","checksum":-570118542}]}
1646003686.0682938: {"arg":{"channel":"books-l2-tbt","instId":"ELON-USDT"},"action":"update","data":[{"asks":[["0.00000074573","172526957","0","2"],["0.00000074577","0","0","0"]],"bids":[],"ts":"1646003686056","checksum":-2035337386}]}
1646003686.0734432: {"arg":{"channel":"books-l2-tbt","instId":"ZEN-USDT"},"action":"update","data":[{"asks":[["32.56","0","0","0"],["44.13","0.04","0","1"]],"bids":[],"ts":"1646003686063","checksum":-46699172}]}
1646003686.084393: {"arg":{"channel":"books-l2-tbt","instId":"ZEN-USDT"},"action":"update","data":[{"asks":[],"bids":[["32.38","28.93274","0","2"]],"ts":"1646003686073","checksum":352336122}]}
1646003686.087573: {"arg":{"channel":"books-l2-tbt","instId":"ELON-USDT"},"action":"update","data":[{"asks":[["0.00000074573","220542630","0","3"],["0.00000074576","445226872","0","1"],["0.00000113315","0","0","0"]],"bids":[],"ts":"1646003686075","checksum":1769417842}]}
1646003686.106132: {"arg":{"channel":"books-l2-tbt","instId":"ZEN-USDT"},"action":"update","data":[{"asks":[["32.86","1.52","0","1"],["32.9","60","0","1"],["44.13","0","0","0"]],"bids":[],"ts":"1646003686095","checksum":-341723242}]}
1646003686.10945: {"arg":{"channel":"books-l2-tbt","instId":"ELON-USDT"},"action":"update","data":[{"asks":[],"bids":[["0.00000074448","219861835","0","1"]],"ts":"1646003686096","checksum":-1756065645}]}
1646003686.117648: {"arg":{"channel":"books-l2-tbt","instId":"ZEN-USDT"},"action":"update","data":[{"asks":[["33.32","4.52","0","1"],["33.36","0","0","0"],["33.78","7.48","0","1"],["33.82","0.01715","0","1"],["34.25","10.4","0","1"],["34.29","0","0","0"],["34.72","13.28","0","1"],["34.77","0","0","0"],["44.08","0","0","0"]],"bids":[],"ts":"1646003686105","checksum":-341723242}]}
1646003686.118582: {"arg":{"channel":"books-l2-tbt","instId":"ELON-USDT"},"action":"update","data":[{"asks":[["0.00000074574","0","0","0"],["0.00000113315","35900750","0","1"]],"bids":[],"ts":"1646003686108","checksum":-2031213994}]}
1646003686.145355: {"arg":{"channel":"books-l2-tbt","instId":"ELON-USDT"},"action":"update","data":[{"asks":[["0.00000074573","68570346","0","1"]],"bids":[["0.00000074449","178186766","0","1"]],"ts":"1646003686129","checksum":2073878459}]}
1646003686.1708941: {"arg":{"channel":"books-l2-tbt","instId":"ELON-USDT"},"action":"update","data":[{"asks":[["0.0000007458","0","0","0"],["0.0000011338","129154981","0","1"]],"bids":[],"ts":"1646003686159","checksum":-1768436609}]}
1646003686.1721878: {"arg":{"channel":"books-l2-tbt","instId":"ZEN-USDT"},"action":"update","data":[{"asks":[],"bids":[["32.41","31.532791","0","2"]],"ts":"1646003686161","checksum":-256174173}]}
1646003686.174741: {"arg":{"channel":"books-l2-tbt","instId":"ELON-USDT"},"action":"update","data":[{"asks":[["0.00000074575","48015673","0","1"],["0.0000011338","0","0","0"]],"bids":[["0.00000074435","0","0","0"]],"ts":"1646003686163","checksum":-1038852517}]}
1646003686.1872: {"arg":{"channel":"books-l2-tbt","instId":"UNI-USD-SWAP"},"action":"update","data":[{"asks":[["9.62","0","0","0"],["9.621","260","0","1"],["9.625","0","0","0"],["9.627","85","0","1"],["49.113","1","0","1"]],"bids":[],"ts":"1646003686172","checksum":-1993691757}]}
1646003686.187279: {"arg":{"channel":"books-l2-tbt","instId":"ZEN-USDT"},"action":"update","data":[{"asks":[["32.8","3.858605","0","2"],["32.84","0","0","0"],["33.13","3.94","0","1"],["33.17","0","0","0"],["33.46","6.33","0","1"],["33.5","0.496261","0","2"],["33.79","8.7","0","1"],["33.83","0","0","0"],["34.12","11.04","0","1"],["34.16","0","0","0"]],"bids":[],"ts":"1646003686173","checksum":-525267283}]}
1646003686.187337: {"arg":{"channel":"books-l2-tbt","instId":"ELON-USDT"},"action":"update","data":[{"asks":[["0.00000074572","421891084","0","1"],["0.00000074575","159668552","0","2"],["0.00000113315","0","0","0"]],"bids":[],"ts":"1646003686174","checksum":-455175900}]}
1646003686.196104: {"arg":{"channel":"books-l2-tbt","instId":"UNI-USD-SWAP"},"action":"update","data":[{"asks":[["9.621","343","0","2"]],"bids":[],"ts":"1646003686183","checksum":1905779534}]}
1646003686.2082508: {"arg":{"channel":"books-l2-tbt","instId":"ELON-USDT"},"action":"update","data":[{"asks":[["0.00000074575","0","0","0"],["0.00000074576","0","0","0"],["0.00000113315","35900750","0","1"],["0.0000011338","129154981","0","1"]],"bids":[],"ts":"1646003686194","checksum":-920293396}]}
1646003686.208391: {"arg":{"channel":"books-l2-tbt","instId":"UNI-USD-SWAP"},"action":"update","data":[{"asks":[["9.621","83","0","1"],["9.626","2","0","1"],["49.113","0","0","0"]],"bids":[["9.613","2","0","1"]],"ts":"1646003686193","checksum":354453268}]}
1646003686.215969: {"arg":{"channel":"books-l2-tbt","instId":"UNI-USD-SWAP"},"action":"update","data":[{"asks":[["9.626","87","0","2"],["9.627","0","0","0"],["9.628","0","0","0"],["49.113","1","0","1"],["49.358","1","0","1"]],"bids":[["9.609","0","0","0"],["9.577","225","0","1"]],"ts":"1646003686204","checksum":1993697234}]}
1646003686.2181928: {"arg":{"channel":"books-l2-tbt","instId":"ELON-USDT"},"action":"update","data":[{"asks":[["0.00000074571","48015673","0","1"],["0.0000011338","0","0","0"]],"bids":[],"ts":"1646003686206","checksum":-89852380}]}
1646003686.226145: {"arg":{"channel":"books-l2-tbt","instId":"UNI-USD-SWAP"},"action":"update","data":[{"asks":[],"bids":[["9.612","444","0","4"],["9.611","12","0","1"],["9.602","28","0","1"],["9.574","612","0","3"]],"ts":"1646003686215","checksum":-738768464}]}
1646003686.2262862: {"arg":{"channel":"books-l2-tbt","instId":"ELON-USDT"},"action":"update","data":[{"asks":[["0.00000074571","159668552","0","2"]],"bids":[],"ts":"1646003686215","checksum":-1124820093}]}
1646003686.239895: {"arg":{"channel":"books-l2-tbt","instId":"UNI-USD-SWAP"},"action":"update","data":[{"asks":[["9.625","1","0","1"],["9.641","123","0","2"],["9.65","255","0","2"],["49.358","0","0","0"]],"bids":[["9.602","54","0","2"],["9.601","153","0","1"],["9.6","20","0","1"],["9.599","63","0","1"],["9.597","43","0","2"],["9.596","0","0","0"]],"ts":"1646003686226","checksum":1058053232}]}
1646003686.2484102: {"arg":{"channel":"books-l2-tbt","instId":"ELON-USDT"},"action":"update","data":[{"asks":[["0.0000007457","286705740","0","1"],["0.00000113315","0","0","0"]],"bids":[],"ts":"1646003686237","checksum":-764208206}]}
1646003686.269728: {"arg":{"channel":"books-l2-tbt","instId":"UNI-USD-SWAP"},"action":"update","data":[{"asks":[["9.626","85","0","1"]],"bids":[],"ts":"1646003686257","checksum":-1029631259}]}
1646003686.278074: {"arg":{"channel":"books-l2-tbt","instId":"ZEN-USDT"},"action":"update","data":[{"asks":[],"bids":[["32.4","36.003828","0","1"],["32.34","100","0","1"]],"ts":"1646003686267","checksum":-780115249}]}
1646003686.278147: {"arg":{"channel":"books-l2-tbt","instId":"UNI-USD-SWAP"},"action":"update","data":[{"asks":[["9.621","0","0","0"],["49.358","1","0","1"]],"bids":[],"ts":"1646003686268","checksum":-2064087676}]}
1646003686.282519: {"arg":{"channel":"books-l2-tbt","instId":"ELON-USDT"},"action":"update","data":[{"asks":[["0.00000074571","0","0","0"],["0.00000074572","0","0","0"],["0.00000113315","35900750","0","1"],["0.0000011338","129154981","0","1"]],"bids":[],"ts":"1646003686271","checksum":1573478467}]}
1646003686.294451: {"arg":{"channel":"books-l2-tbt","instId":"UNI-USD-SWAP"},"action":"update","data":[{"asks":[["9.626","0","0","0"],["49.605","1","0","1"]],"bids":[],"ts":"1646003686279","checksum":-941810712}]}
1646003686.301929: {"arg":{"channel":"books-l2-tbt","instId":"UNI-USD-SWAP"},"action":"update","data":[{"asks":[["9.628","120","0","1"],["49.605","0","0","0"]],"bids":[["9.574","583","0","2"]],"ts":"1646003686289","checksum":1391518433}]}
1646003686.302083: {"arg":{"channel":"books-l2-tbt","instId":"ELON-USDT"},"action":"update","data":[{"asks":[["0.00000074569","78327785","0","2"],["0.00000074574","81175250","0","1"],["0.00000113315","0","0","0"],["0.0000011338","0","0","0"]],"bids":[],"ts":"1646003686290","checksum":1775591705}]}
1646003686.306023: {"arg":{"channel":"books-l2-tbt","instId":"PROPS-ETH"},"action":"update","data":[{"asks":[["0.00000178","1192.66798788","0","1"],["0.00000181","0","0","0"],["0.00000182","0","0","0"],["0.00000185","1024.54214081","0","1"],["0.00000186","622.76322631","0","1"]],"bids":[["0.00000161","0","0","0"]],"ts":"1646003686294","checksum":359532538}]}
1646003686.312317: {"arg":{"channel":"books-l2-tbt","instId":"ELON-USDT"},"action":"update","data":[{"asks":[["0.00000074569","242338361","0","4"]],"bids":[["0.00000074335","0","0","0"]],"ts":"1646003686301","checksum":-1195016776}]}
1646003686.3167748: {"arg":{"channel":"books-l2-tbt","instId":"UNI-USD-SWAP"},"action":"update","data":[{"asks":[["9.619","0","0","0"],["49.605","1","0","1"]],"bids":[["9.612","504","0","5"]],"ts":"1646003686304","checksum":401222516}]}
1646003686.3229718: {"arg":{"channel":"books-l2-tbt","instId":"ELON-USDT"},"action":"update","data":[{"asks":[["0.00000074572","326617185","0","1"],["0.00000113256","0","0","0"]],"bids":[],"ts":"1646003686311","checksum":-1776532512}]}
1646003686.3243158: {"arg":{"channel":"books-l2-tbt","instId":"UNI-USD-SWAP"},"action":"update","data":[{"asks":[["9.624","22","0","1"],["9.625","0","0","0"],["9.628","123","0","2"]],"bids":[["9.612","451","0","4"],["9.574","510","0","1"]],"ts":"1646003686313","checksum":2005589674}]}
1646003686.336031: {"arg":{"channel":"books-l2-tbt","instId":"UNI-USD-SWAP"},"action":"update","data":[{"asks":[["9.624","1022","0","4"],["9.627","22","0","1"],["9.649","99","0","2"],["49.605","0","0","0"]],"bids":[["9.612","342","0","3"],["9.61","0","0","0"]],"ts":"1646003686324","checksum":584330316}]}
1646003686.343532: {"arg":{"channel":"books-l2-tbt","instId":"ELON-USDT"},"action":"update","data":[{"asks":[["0.00000074569","346294972","0","5"]],"bids":[],"ts":"1646003686332","checksum":-481347195}]}
1646003686.3469892: {"arg":{"channel":"books-l2-tbt","instId":"UNI-USD-SWAP"},"action":"update","data":[{"asks":[["9.624","463","0","3"],["9.626","120","0","1"],["9.627","0","0","0"],["9.628","3","0","1"],["9.634","465","0","3"],["9.639","0","0","0"],["9.644","0","0","0"],["9.645","72","0","2"],["9.647","2266","0","2"],["9.648","203","0","3"],["9.65","225","0","1"],["9.651","21","0","1"],["9.652","9245","0","1"],["9.658","64","0","1"],["9.66","0","0","0"],["49.605","1","0","1"]],"bids":[["9.607","6","0","1"]],"ts":"1646003686334","checksum":1556557341}]}
1646003686.354998: {"arg":{"channel":"books-l2-tbt","instId":"UNI-USD-SWAP"},"action":"update","data":[{"asks":[["9.623","22","0","1"],["9.624","358","0","2"],["9.657","59","0","1"],["49.358","0","0","0"],["49.605","0","0","0"]],"bids":[["9.61","211","0","2"]],"ts":"1646003686343","checksum":892315107}]}
1646003686.3667462: {"arg":{"channel":"books-l2-tbt","instId":"UNI-USD-SWAP"},"action":"update","data":[{"asks":[["9.626","225","0","2"],["9.656","151","0","2"]],"bids":[["9.607","1","0","1"]],"ts":"1646003686356","checksum":-336368368}]}
1646003686.393655: {"arg":{"channel":"books-l2-tbt","instId":"UNI-USD-SWAP"},"action":"update","data":[{"asks":[["9.627","3","0","1"],["9.631","651","0","2"],["9.632","526","0","3"],["9.656","124","0","1"],["49.113","0","0","0"]],"bids":[["9.609","3","0","1"]],"ts":"1646003686365","checksum":1513592526}]}
1646003686.393801: {"arg":{"channel":"books-l2-tbt","instId":"ELON-USDT"},"action":"update","data":[{"asks":[["0.00000074573","0","0","0"],["0.00000113256","10462875","0","1"]],"bids":[],"ts":"1646003686367","checksum":-1748120269}]}
1646003686.3938649: {"arg":{"channel":"books-l2-tbt","instId":"ELON-USDT"},"action":"update","data":[{"asks":[["0.0000007457","0","0","0"],["0.00000113315","35900750","0","1"]],"bids":[["0.00000074381","170493166","0","1"]],"ts":"1646003686375","checksum":1132769619}]}
1646003686.3939252: {"arg":{"channel":"books-l2-tbt","instId":"UNI-USD-SWAP"},"action":"update","data":[{"asks":[["9.628","0","0","0"],["9.63","0","0","0"],["9.632","606","0","4"],["49.113","1","0","1"],["49.358","1","0","1"]],"bids":[["9.609","0","0","0"],["9.608","12","0","1"]],"ts":"1646003686376","checksum":1739504040}]}
1646003686.395493: {"arg":{"channel":"books-l2-tbt","instId":"ZEN-USDT"},"action":"update","data":[{"asks":[["32.49","0.000093","0","1"]],"bids":[],"ts":"1646003686384","checksum":-846813839}]}
1646003686.399913: {"arg":{"channel":"books-l2-tbt","instId":"UNI-USD-SWAP"},"action":"update","data":[{"asks":[["9.622","83","0","1"],["49.358","0","0","0"]],"bids":[["9.605","11","0","1"]],"ts":"1646003686385","checksum":-153514067}]}
1646003686.400005: {"arg":{"channel":"trades","instId":"ZEN-USDT"},"data":[{"instId":"ZEN-USDT","tradeId":"15270492","px":"32.49","sz":"0.4083","side":"buy","ts":"1646003686381"}]}
1646003686.400036: {"arg":{"channel":"books-l2-tbt","instId":"ELON-USDT"},"action":"update","data":[{"asks":[["0.00000074569","234642093","0","4"]],"bids":[["0.00000074449","0","0","0"]],"ts":"1646003686386","checksum":-1185519994}]}
1646003686.410101: {"arg":{"channel":"books-l2-tbt","instId":"UNI-USD-SWAP"},"action":"update","data":[{"asks":[],"bids":[["9.608","512","0","2"]],"ts":"1646003686395","checksum":1584705077}]}
1646003686.420463: {"arg":{"channel":"books-l2-tbt","instId":"UNI-USD-SWAP"},"action":"update","data":[{"asks":[["9.621","260","0","1"],["9.627","0","0","0"]],"bids":[["9.609","2","0","1"]],"ts":"1646003686406","checksum":1624023142}]}
1646003686.4205492: {"arg":{"channel":"books-l2-tbt","instId":"ELON-USDT"},"action":"update","data":[{"asks":[["0.00000074569","130685482","0","3"]],"bids":[["0.00000074231","0","0","0"]],"ts":"1646003686407","checksum":554967792}]}
1646003686.4292731: {"arg":{"channel":"books-l2-tbt","instId":"ELON-USDT"},"action":"update","data":[{"asks":[],"bids":[["0.00000074381","0","0","0"],["0.00000070565","405255922","0","2"],["0.00000069154","424384252","0","1"],["0.00000067771","207627555","0","1"],["0.00000066416","375137933","0","1"],["0.00000064198","0","0","0"]],"ts":"1646003686416","checksum":1226008591}]}
1646003686.429427: {"arg":{"channel":"books-l2-tbt","instId":"UNI-USD-SWAP"},"action":"update","data":[{"asks":[],"bids":[["9.613","53","0","1"]],"ts":"1646003686416","checksum":250098391}]}
1646003686.438792: {"arg":{"channel":"books-l2-tbt","instId":"ELON-USDT"},"action":"update","data":[{"asks":[["0.00000074568","445226872","0","1"],["0.00000074571","103956611","0","1"],["0.00000113256","0","0","0"],["0.00000113315","0","0","0"]],"bids":[],"ts":"1646003686427","checksum":712280935}]}
1646003686.438889: {"arg":{"channel":"books-l2-tbt","instId":"UNI-USD-SWAP"},"action":"update","data":[{"asks":[["9.624","260","0","1"],["9.626","120","0","1"],["9.633","28","0","1"],["49.113","0","0","0"]],"bids":[],"ts":"1646003686428","checksum":975544041}]}
1646003686.448873: {"arg":{"channel":"books-l2-tbt","instId":"UNI-USD-SWAP"},"action":"update","data":[{"asks":[["9.626","146","0","2"]],"bids":[["9.614","22","0","1"],["9.612","320","0","2"]],"ts":"1646003686437","checksum":-925772725}]}
1646003686.4591842: {"arg":{"channel":"books-l2-tbt","instId":"ELON-USDT"},"action":"update","data":[{"asks":[["0.00000074571","0","0","0"],["0.00000113256","10462875","0","1"]],"bids":[],"ts":"1646003686446","checksum":592857533}]}
1646003686.460583: {"arg":{"channel":"books-l2-tbt","instId":"UNI-USD-SWAP"},"action":"update","data":[{"asks":[["9.623","23","0","2"]],"bids":[],"ts":"1646003686449","checksum":-1605951770}]}
1646003686.47137: {"arg":{"channel":"books-l2-tbt","instId":"UNI-USD-SWAP"},"action":"update","data":[{"asks":[],"bids":[["9.611","13","0","2"]],"ts":"1646003686459","checksum":1613250041}]}
1646003686.4778152: {"arg":{"channel":"books-l2-tbt","instId":"ZEN-USDT"},"action":"update","data":[{"asks":[],"bids":[["32.34","0","0","0"]],"ts":"1646003686465","checksum":-674279421}]}
1646003686.4809: {"arg":{"channel":"books-l2-tbt","instId":"ELON-USDT"},"action":"update","data":[{"asks":[["0.00000074567","103956611","0","1"],["0.00000113256","0","0","0"]],"bids":[["0.0000007433","74633304","0","1"]],"ts":"1646003686469","checksum":-1371906316}]}
1646003686.481036: {"arg":{"channel":"books-l2-tbt","instId":"UNI-USD-SWAP"},"action":"update","data":[{"asks":[["9.625","1","0","1"],["9.641","148","0","3"],["9.644","23","0","1"],["9.645","50","0","1"],["9.647","2296","0","3"],["9.648","179","0","2"],["9.651","0","0","0"],["48.868","0","0","0"]],"bids":[["9.609","0","0","0"],["9.603","27","0","1"],["9.602","28","0","1"],["9.601","183","0","2"],["9.6","0","0","0"],["9.598","182","0","2"],["9.597","16","0","1"]],"ts":"1646003686469","checksum":-1928869730}]}
1646003686.490589: {"arg":{"channel":"books-l2-tbt","instId":"ELON-USDT"},"action":"update","data":[{"asks":[["0.00000074572","0","0","0"],["0.00000113256","10462875","0","1"]],"bids":[],"ts":"1646003686479","checksum":904805900}]}
1646003686.501591: {"arg":{"channel":"books-l2-tbt","instId":"UNI-USD-SWAP"},"action":"update","data":[{"asks":[],"bids":[["9.575","108","0","2"]],"ts":"1646003686489","checksum":-1928869730}]}
1646003686.50172: {"arg":{"channel":"tickers","instId":"ZEN-USDT"},"data":[{"instType":"SPOT","instId":"ZEN-USDT","last":"32.49","lastSz":"0.4083","askPx":"32.52","askSz":"11.516671","bidPx":"32.48","bidSz":"18.170174","open24h":"33.34","high24h":"35.26","low24h":"31.91","sodUtc0":"33.36","sodUtc8":"34.26","volCcy24h":"1484861.201077","vol24h":"44403.374693","ts":"1646003686482"}]}
1646003686.511128: {"arg":{"channel":"books-l2-tbt","instId":"UNI-USD-SWAP"},"action":"update","data":[{"asks":[["9.623","22","0","1"]],"bids":[],"ts":"1646003686499","checksum":1960710000}]}
1646003686.521214: {"arg":{"channel":"books-l2-tbt","instId":"ELON-USDT"},"action":"update","data":[{"asks":[["0.00000074567","172526957","0","2"],["0.00000074569","0","0","0"],["0.00000113315","35900750","0","1"]],"bids":[],"ts":"1646003686509","checksum":884718019}]}
1646003686.5330079: {"arg":{"channel":"books-l2-tbt","instId":"ELON-USDT"},"action":"update","data":[{"asks":[],"bids":[["0.00000074229","3602687649","0","1"]],"ts":"1646003686521","checksum":-2055049815}]}
1646003686.542668: {"arg":{"channel":"books-l2-tbt","instId":"ELON-USDT"},"action":"update","data":[{"asks":[["0.00000074567","116586019","0","2"]],"bids":[],"ts":"1646003686530","checksum":-129216985}]}
1646003686.5617962: {"arg":{"channel":"books-l2-tbt","instId":"UNI-USD-SWAP"},"action":"update","data":[{"asks":[["9.626","120","0","1"]],"bids":[],"ts":"1646003686550","checksum":1000114048}]}
1646003686.5718489: {"arg":{"channel":"books-l2-tbt","instId":"UNI-USD-SWAP"},"action":"update","data":[{"asks":[],"bids":[["9.575","127","0","3"]],"ts":"1646003686560","checksum":1000114048}]}
1646003686.5827909: {"arg":{"channel":"books-l2-tbt","instId":"UNI-USD-SWAP"},"action":"update","data":[{"asks":[["9.627","146","0","1"],["48.625","0","0","0"]],"bids":[],"ts":"1646003686570","checksum":-65152951}]}
1646003686.599825: {"arg":{"channel":"books-l2-tbt","instId":"ELON-USDT"},"action":"update","data":[{"asks":[["0.00000074566","445226872","0","1"],["0.00000113315","0","0","0"]],"bids":[["0.00000074435","28165740","0","1"]],"ts":"1646003686586","checksum":-70530197}]}
1646003686.6051579: {"arg":{"channel":"books-l2-tbt","instId":"UNI-USD-SWAP"},"action":"update","data":[{"asks":[],"bids":[["9.609","2","0","1"]],"ts":"1646003686592","checksum":-1074834948}]}
1646003686.610045: {"arg":{"channel":"books-l2-tbt","instId":"ELON-USDT"},"action":"update","data":[{"asks":[],"bids":[["0.00000074448","0","0","0"]],"ts":"1646003686598","checksum":-1289770843}]}
1646003686.617934: {"arg":{"channel":"books-l2-tbt","instId":"ELON-USDT"},"action":"update","data":[{"asks":[["0.00000074565","111652879","0","1"],["0.00000074567","68570346","0","1"],["0.00000113256","0","0","0"]],"bids":[],"ts":"1646003686606","checksum":458982565}]}
1646003686.629674: {"arg":{"channel":"books-l2-tbt","instId":"ELON-USDT"},"action":"update","data":[{"asks":[["0.00000074565","159668552","0","2"]],"bids":[["0.00000074229","0","0","0"]],"ts":"1646003686618","checksum":1975980098}]}
1646003686.641995: {"arg":{"channel":"books-l2-tbt","instId":"ELON-USDT"},"action":"update","data":[{"asks":[["0.00000074568","0","0","0"],["0.00000113256","10462875","0","1"]],"bids":[],"ts":"1646003686629","checksum":-1097422571}]}
1646003686.645859: {"arg":{"channel":"books-l2-tbt","instId":"UNI-USD-SWAP"},"action":"update","data":[{"asks":[],"bids":[["9.611","12","0","1"]],"ts":"1646003686635","checksum":-791482753}]}
1646003686.65035: {"arg":{"channel":"books-l2-tbt","instId":"ELON-USDT"},"action":"update","data":[{"asks":[],"bids":[["0.0000007433","0","0","0"]],"ts":"1646003686639","checksum":-1242183597}]}
1646003686.658908: {"arg":{"channel":"books-l2-tbt","instId":"ZEN-USDT"},"action":"update","data":[{"asks":[],"bids":[["32.34","100","0","1"]],"ts":"1646003686646","checksum":-846813839}]}
1646003686.6622431: {"arg":{"channel":"books-l2-tbt","instId":"ELON-USDT"},"action":"update","data":[{"asks":[],"bids":[["0.00000074219","3736496644","0","1"]],"ts":"1646003686649","checksum":-1536359667}]}
1646003686.687692: {"arg":{"channel":"books-l2-tbt","instId":"ELON-USDT"},"action":"update","data":[{"asks":[["0.00000074565","111652879","0","1"]],"bids":[["0.00000074435","0","0","0"]],"ts":"1646003686670","checksum":932209669}]}
1646003686.693435: {"arg":{"channel":"books-l2-tbt","instId":"ELON-USDT"},"action":"update","data":[{"asks":[],"bids":[["0.00000074219","0","0","0"]],"ts":"1646003686680","checksum":-731053879}]}
1646003686.70509: {"arg":{"channel":"books-l2-tbt","instId":"ELON-USDT"},"action":"update","data":[{"asks":[["0.00000074564","445226872","0","1"],["0.00000113256","0","0","0"]],"bids":[["0.00000074381","184440410","0","1"]],"ts":"1646003686691","checksum":392088639}]}
1646003686.7237298: {"arg":{"channel":"books-l2-tbt","instId":"ELON-USDT"},"action":"update","data":[{"asks":[["0.00000074565","0","0","0"],["0.00000113256","10462875","0","1"]],"bids":[],"ts":"1646003686711","checksum":412377246}]}
1646003686.726849: {"arg":{"channel":"books-l2-tbt","instId":"PROPS-ETH"},"action":"update","data":[{"asks":[],"bids":[["0.00000167","470150.72969468","0","4"]],"ts":"1646003686715","checksum":-95056588}]}
1646003686.7312598: {"arg":{"channel":"books-l2-tbt","instId":"ELON-USDT"},"action":"update","data":[{"asks":[["0.00000074563","25220062","0","1"],["0.00000074567","0","0","0"]],"bids":[],"ts":"1646003686720","checksum":495522682}]}
1646003686.743051: {"arg":{"channel":"books-l2-tbt","instId":"ELON-USDT"},"action":"update","data":[{"asks":[["0.00000074563","346294972","0","5"],["0.00000074566","0","0","0"],["0.00000113315","35900750","0","1"]],"bids":[],"ts":"1646003686731","checksum":-830483187}]}
1646003686.752667: {"arg":{"channel":"books-l2-tbt","instId":"ELON-USDT"},"action":"update","data":[{"asks":[],"bids":[["0.00000074381","0","0","0"]],"ts":"1646003686742","checksum":-982365863}]}
1646003686.759146: {"arg":{"channel":"books-l2-tbt","instId":"UNI-USD-SWAP"},"action":"update","data":[{"asks":[["9.64","27","0","1"],["9.641","123","0","2"],["9.643","21","0","1"],["9.644","0","0","0"],["9.646","27","0","1"],["9.647","2266","0","2"],["9.658","107","0","2"],["48.143","0","0","0"],["48.383","0","0","0"]],"bids":[["9.603","0","0","0"],["9.602","52","0","2"],["9.601","153","0","1"],["9.6","29","0","1"],["9.598","153","0","1"],["9.597","36","0","2"]],"ts":"1646003686747","checksum":874447637}]}
1646003686.783534: {"arg":{"channel":"books-l2-tbt","instId":"ELON-USDT"},"action":"update","data":[{"asks":[["0.00000074564","0","0","0"],["0.0000011338","129154981","0","1"]],"bids":[],"ts":"1646003686772","checksum":2001466761}]}
1646003686.7932632: {"arg":{"channel":"books-l2-tbt","instId":"ELON-USDT"},"action":"update","data":[{"asks":[["0.00000074574","0","0","0"],["0.0000011372","6179288","0","1"]],"bids":[["0.0000007433","103349582","0","1"]],"ts":"1646003686781","checksum":-252180931}]}
1646003686.8042371: {"arg":{"channel":"books-l2-tbt","instId":"ELON-USDT"},"action":"update","data":[{"asks":[["0.00000074563","130685482","0","3"]],"bids":[],"ts":"1646003686792","checksum":-1636184184}]}
1646003686.80816: {"arg":{"channel":"books-l2-tbt","instId":"PROPS-ETH"},"action":"update","data":[{"asks":[["0.00000178","0","0","0"],["0.00000181","671.33165169","0","1"],["0.00000182","776.64093538","0","1"],["0.00000185","0","0","0"],["0.00000186","0","0","0"],["0.00000187","0","0","0"]],"bids":[["0.00000161","10262.9055803","0","1"]],"ts":"1646003686796","checksum":-712116411}]}
1646003686.846288: {"arg":{"channel":"books-l2-tbt","instId":"ELON-USDT"},"action":"update","data":[{"asks":[["0.00000074562","445226872","0","1"],["0.0000011372","0","0","0"]],"bids":[["0.0000007433","0","0","0"]],"ts":"1646003686835","checksum":-115082788}]}
1646003686.865789: {"arg":{"channel":"books-l2-tbt","instId":"ELON-USDT"},"action":"update","data":[{"asks":[["0.00000074561","103956611","0","1"],["0.0000011338","0","0","0"]],"bids":[["0.00000074264","3069347499","0","1"]],"ts":"1646003686855","checksum":1376709710}]}
1646003686.879958: {"arg":{"channel":"books-l2-tbt","instId":"ELON-USDT"},"action":"update","data":[{"asks":[["0.00000074561","151972284","0","2"],["0.00000074565","81175250","0","1"],["0.00000113315","0","0","0"]],"bids":[],"ts":"1646003686866","checksum":995329084}]}
1646003686.8858051: {"arg":{"channel":"books-l2-tbt","instId":"UNI-USD-SWAP"},"action":"update","data":[{"asks":[["9.629","11","0","1"]],"bids":[["9.607","22","0","2"]],"ts":"1646003686874","checksum":-2039135555}]}
1646003686.89934: {"arg":{"channel":"books-l2-tbt","instId":"ELON-USDT"},"action":"update","data":[{"asks":[["0.0000007456","445226872","0","1"],["0.00000113256","0","0","0"]],"bids":[],"ts":"1646003686887","checksum":1602536417}]}
1646003686.920931: {"arg":{"channel":"books-l2-tbt","instId":"ELON-USDT"},"action":"update","data":[{"asks":[["0.00000074561","0","0","0"],["0.00000113256","10462875","0","1"]],"bids":[["0.00000074435","48198397","0","1"]],"ts":"1646003686909","checksum":1402311227}]}
1646003686.948556: {"arg":{"channel":"books-l2-tbt","instId":"ELON-USDT"},"action":"update","data":[{"asks":[],"bids":[["0.00000070565","144547580","0","1"],["0.00000069154","0","0","0"],["0.00000067771","0","0","0"],["0.00000066416","0","0","0"],["0.00000065074","222306019","0","1"]],"ts":"1646003686935","checksum":1402311227}]}
1646003686.952608: {"arg":{"channel":"books-l2-tbt","instId":"ELON-USDT"},"action":"update","data":[{"asks":[["0.00000074559","151972284","0","2"],["0.00000074562","0","0","0"]],"bids":[],"ts":"1646003686940","checksum":-2021560828}]}
1646003686.976021: {"arg":{"channel":"books-l2-tbt","instId":"ELON-USDT"},"action":"update","data":[{"asks":[["0.00000074559","220542630","0","3"],["0.00000074563","105465420","0","2"]],"bids":[["0.00000074381","170961959","0","1"]],"ts":"1646003686948","checksum":438110504}]}
1646003686.97611: {"arg":{"channel":"books-l2-tbt","instId":"ELON-USDT"},"action":"update","data":[{"asks":[["0.0000007456","0","0","0"],["0.00000074563","0","0","0"],["0.00000113315","35900750","0","1"],["0.0000011338","129154981","0","1"]],"bids":[],"ts":"1646003686958","checksum":-2034669591}]}
1646003686.989602: {"arg":{"channel":"books-l2-tbt","instId":"ELON-USDT"},"action":"update","data":[{"asks":[["0.00000074559","68570346","0","1"],["0.00000074599","111652879","0","1"],["0.0000011338","0","0","0"]],"bids":[],"ts":"1646003686978","checksum":-299731254}]}
1646003687.000747: {"arg":{"channel":"books-l2-tbt","instId":"ELON-USDT"},"action":"update","data":[{"asks":[["0.00000074558","445226872","0","1"],["0.00000113315","0","0","0"]],"bids":[["0.00000074381","0","0","0"]],"ts":"1646003686988","checksum":1916394815}]}
1646003687.010852: {"arg":{"channel":"books-l2-tbt","instId":"ELON-USDT"},"action":"update","data":[{"asks":[["0.00000074599","263625163","0","3"]],"bids":[],"ts":"1646003687000","checksum":1527851933}]}
1646003687.019635: {"arg":{"channel":"books-l2-tbt","instId":"ELON-USDT"},"action":"update","data":[{"asks":[["0.00000074599","151972284","0","2"]],"bids":[],"ts":"1646003687008","checksum":-690488212}]}
1646003687.031468: {"arg":{"channel":"books-l2-tbt","instId":"ELON-USDT"},"action":"update","data":[{"asks":[["0.00000074557","111652879","0","1"],["0.00000074599","0","0","0"]],"bids":[],"ts":"1646003687020","checksum":1673592236}]}
1646003687.052618: {"arg":{"channel":"books-l2-tbt","instId":"ELON-USDT"},"action":"update","data":[{"asks":[["0.00000074557","263625163","0","3"]],"bids":[["0.00000074381","184440410","0","1"]],"ts":"1646003687041","checksum":-744671392}]}
1646003687.063526: {"arg":{"channel":"books-l2-tbt","instId":"UNI-USD-SWAP"},"action":"update","data":[{"asks":[["9.625","121","0","2"],["9.626","0","0","0"],["48.143","1","0","1"]],"bids":[],"ts":"1646003687050","checksum":-104067140}]}
1646003687.073463: {"arg":{"channel":"books-l2-tbt","instId":"ELON-USDT"},"action":"update","data":[{"asks":[["0.00000074556","445226872","0","1"],["0.00000113256","0","0","0"]],"bids":[],"ts":"1646003687061","checksum":-397892889}]}
1646003687.08338: {"arg":{"channel":"books-l2-tbt","instId":"UNI-USD-SWAP"},"action":"update","data":[{"asks":[["9.625","1","0","1"],["9.626","121","0","2"],["48.143","0","0","0"]],"bids":[],"ts":"1646003687072","checksum":-728418072}]}
1646003687.097544: {"arg":{"channel":"books-l2-tbt","instId":"UNI-USD-SWAP"},"action":"update","data":[{"asks":[["9.625","0","0","0"],["48.143","1","0","1"]],"bids":[],"ts":"1646003687082","checksum":-723136352}]}
1646003687.09763: {"arg":{"channel":"books-l2-tbt","instId":"ELON-USDT"},"action":"update","data":[{"asks":[["0.00000074557","0","0","0"],["0.00000113256","10462875","0","1"]],"bids":[["0.00000074381","0","0","0"]],"ts":"1646003687082","checksum":1291991207}]}
1646003687.1027799: {"arg":{"channel":"books-l2-tbt","instId":"UNI-USD-SWAP"},"action":"update","data":[{"asks":[["9.626","120","0","1"]],"bids":[],"ts":"1646003687092","checksum":-380065250}]}
1646003687.10286: {"arg":{"channel":"books-l2-tbt","instId":"BTC-USD-220325-40000-C"},"action":"update","data":[{"asks":[],"bids":[["0.05","601","0","2"],["0.0495","0","0","0"]],"ts":"1646003687093","checksum":-305748066}]}
1646003687.107955: {"arg":{"channel":"books-l2-tbt","instId":"ELON-USDT"},"action":"update","data":[{"asks":[["0.00000074558","0","0","0"],["0.00000113315","35900750","0","1"]],"bids":[["0.00000074447","219861835","0","1"],["0.00000074435","0","0","0"]],"ts":"1646003687092","checksum":-1236677597}]}
1646003687.1150389: {"arg":{"channel":"books-l2-tbt","instId":"ELON-USDT"},"action":"update","data":[{"asks":[["0.00000074555","215609490","0","2"],["0.00000113315","0","0","0"]],"bids":[],"ts":"1646003687104","checksum":-525106314}]}
1646003687.135225: {"arg":{"channel":"books-l2-tbt","instId":"UNI-USD-SWAP"},"action":"update","data":[{"asks":[["9.625","1","0","1"],["48.143","0","0","0"]],"bids":[],"ts":"1646003687123","checksum":-2039135555}]}
1646003687.1385431: {"arg":{"channel":"books-l2-tbt","instId":"ELON-USDT"},"action":"update","data":[{"asks":[["0.00000074556","0","0","0"],["0.00000113315","35900750","0","1"]],"bids":[],"ts":"1646003687126","checksum":665760815}]}
1646003687.149648: {"arg":{"channel":"books-l2-tbt","instId":"ELON-USDT"},"action":"update","data":[{"asks":[],"bids":[["0.00000074448","22727128","0","1"]],"ts":"1646003687137","checksum":792896271}]}
1646003687.155987: {"arg":{"channel":"books-l2-tbt","instId":"ELON-USDT"},"action":"update","data":[{"asks":[["0.00000074558","438269456","0","1"],["0.00000113315","0","0","0"]],"bids":[],"ts":"1646003687145","checksum":-228310254}]}
1646003687.177665: {"arg":{"channel":"books-l2-tbt","instId":"ELON-USDT"},"action":"update","data":[{"asks":[],"bids":[["0.00000074381","174542196","0","1"]],"ts":"1646003687166","checksum":878120101}]}
1646003687.186986: {"arg":{"channel":"books-l2-tbt","instId":"ELON-USDT"},"action":"update","data":[{"asks":[],"bids":[["0.00000074448","0","0","0"]],"ts":"1646003687175","checksum":1153998787}]}
1646003687.1991029: {"arg":{"channel":"books-l2-tbt","instId":"ELON-USDT"},"action":"update","data":[{"asks":[["0.00000074554","445226872","0","1"],["0.00000113256","0","0","0"]],"bids":[["0.00000074264","0","0","0"]],"ts":"1646003687187","checksum":-508497681}]}
1646003687.2102778: {"arg":{"channel":"books-l2-tbt","instId":"BTC-USD-220325-40000-C"},"action":"update","data":[{"asks":[],"bids":[["0.05","300","0","1"],["0.0495","301","0","1"]],"ts":"1646003687197","checksum":-561915348}]}
1646003687.229363: {"arg":{"channel":"books-l2-tbt","instId":"ELON-USDT"},"action":"update","data":[{"asks":[["0.00000074558","0","0","0"],["0.00000113256","10462875","0","1"]],"bids":[],"ts":"1646003687218","checksum":-627469219}]}
1646003687.250394: {"arg":{"channel":"books-l2-tbt","instId":"ELON-USDT"},"action":"update","data":[{"asks":[],"bids":[["0.00000074381","0","0","0"]],"ts":"1646003687239","checksum":1866618562}]}
1646003687.280554: {"arg":{"channel":"books-l2-tbt","instId":"UNI-USD-SWAP"},"action":"update","data":[{"asks":[],"bids":[["9.613","0","0","0"],["9.612","373","0","3"]],"ts":"1646003687267","checksum":1607679365}]}
1646003687.285832: {"arg":{"channel":"books-l2-tbt","instId":"ELON-USDT"},"action":"update","data":[{"asks":[],"bids":[["0.0000007433","39683231","0","1"]],"ts":"1646003687270","checksum":1029045518}]}
1646003687.2894258: {"arg":{"channel":"books-l2-tbt","instId":"UNI-USD-SWAP"},"action":"update","data":[{"asks":[],"bids":[["9.614","0","0","0"],["9.613","22","0","1"]],"ts":"1646003687277","checksum":901388401}]}
1646003687.300896: {"arg":{"channel":"books-l2-tbt","instId":"ETH-USD-220624-12000-P"},"action":"update","data":[{"asks":[["4.0455","201","0","1"],["4.0465","0","0","0"]],"bids":[],"ts":"1646003687290","checksum":-1816163430}]}
1646003687.306533: {"arg":{"channel":"books-l2-tbt","instId":"PROPS-ETH"},"action":"update","data":[{"asks":[["0.00000177","941.890063","0","1"],["0.00000178","740.94487834","0","1"],["0.00000181","0","0","0"],["0.00000182","0","0","0"],["0.00000185","1023.82147254","0","1"],["0.00000186","692.43601676","0","1"]],"bids":[["0.00000161","0","0","0"],["0.0000016","10644.15232626","0","1"]],"ts":"1646003687294","checksum":-826747871}]}
1646003687.30959: {"arg":{"channel":"books-l2-tbt","instId":"UNI-USD-SWAP"},"action":"update","data":[{"asks":[],"bids":[["9.613","131","0","2"],["9.61","102","0","1"]],"ts":"1646003687298","checksum":1679307921}]}
1646003687.3632572: {"arg":{"channel":"books-l2-tbt","instId":"UNI-USD-SWAP"},"action":"update","data":[{"asks":[],"bids":[["9.614","260","0","1"]],"ts":"1646003687350","checksum":1637123246}]}
1646003687.372641: {"arg":{"channel":"books-l2-tbt","instId":"ELON-USDT"},"action":"update","data":[{"asks":[["0.00000074565","0","0","0"],["0.00000113315","35900750","0","1"]],"bids":[],"ts":"1646003687362","checksum":-899977346}]}
1646003687.381082: {"arg":{"channel":"books-l2-tbt","instId":"PROPS-ETH"},"action":"update","data":[{"asks":[],"bids":[["0.00000167","458174.682539","0","3"]],"ts":"1646003687368","checksum":157740021}]}
1646003687.38345: {"arg":{"channel":"books-l2-tbt","instId":"UNI-USD-SWAP"},"action":"update","data":[{"asks":[],"bids":[["9.613","109","0","1"],["9.612","320","0","2"]],"ts":"1646003687372","checksum":524922759}]}
1646003687.393645: {"arg":{"channel":"books-l2-tbt","instId":"BTC-USD-220325-40000-C"},"action":"update","data":[{"asks":[["0.054","0","0","0"],["0.0545","100","0","1"]],"bids":[],"ts":"1646003687383","checksum":-1840363265}]}
1646003687.393766: {"arg":{"channel":"books-l2-tbt","instId":"UNI-USD-SWAP"},"action":"update","data":[{"asks":[["9.628","1","0","1"],["47.903","0","0","0"]],"bids":[["9.615","22","0","1"]],"ts":"1646003687383","checksum":1073112190}]}
1646003687.4046552: {"arg":{"channel":"books-l2-tbt","instId":"UNI-USD-SWAP"},"action":"update","data":[{"asks":[],"bids":[["9.614","369","0","2"],["9.613","0","0","0"],["9.607","27","0","2"]],"ts":"1646003687394","checksum":641692613}]}
1646003687.41564: {"arg":{"channel":"books-l2-tbt","instId":"UNI-USD-SWAP"},"action":"update","data":[{"asks":[["9.622","0","0","0"],["9.623","105","0","2"],["47.903","1","0","1"]],"bids":[],"ts":"1646003687403","checksum":-1254009339}]}
1646003687.426285: {"arg":{"channel":"books-l2-tbt","instId":"ELON-USDT"},"action":"update","data":[{"asks":[],"bids":[["0.00000070254","241203766","0","1"],["0.00000068849","206585853","0","1"],["0.00000067473","191880053","0","1"],["0.00000066124","285300412","0","1"],["0.00000065074","0","0","0"]],"ts":"1646003687415","checksum":-899977346}]}
1646003687.4311192: {"arg":{"channel":"books-l2-tbt","instId":"PROPS-ETH"},"action":"update","data":[{"asks":[],"bids":[["0.00000167","345428.695106","0","2"]],"ts":"1646003687419","checksum":-176800426}]}
1646003687.434426: {"arg":{"channel":"books-l2-tbt","instId":"UNI-USD-SWAP"},"action":"update","data":[{"asks":[["9.625","0","0","0"],["48.143","1","0","1"]],"bids":[],"ts":"1646003687423","checksum":-227120536}]}
1646003687.4394722: {"arg":{"channel":"books-l2-tbt","instId":"PROPS-ETH"},"action":"update","data":[{"asks":[],"bids":[["0.00000167","172714.347553","0","1"]],"ts":"1646003687428","checksum":2118192541}]}
1646003687.447971: {"arg":{"channel":"books-l2-tbt","instId":"UNI-USD-SWAP"},"action":"update","data":[{"asks":[["9.632","511","0","4"],["9.657","0","0","0"],["9.66","59","0","1"]],"bids":[],"ts":"1646003687433","checksum":697432913}]}
1646003687.456883: {"arg":{"channel":"books-l2-tbt","instId":"UNI-USD-SWAP"},"action":"update","data":[{"asks":[],"bids":[],"ts":"1646003687444","checksum":697432913}]}
1646003687.466424: {"arg":{"channel":"books-l2-tbt","instId":"UNI-USD-SWAP"},"action":"update","data":[{"asks":[],"bids":[["9.608","517","0","3"],["9.607","21","0","1"]],"ts":"1646003687454","checksum":-657999303}]}
1646003687.466539: {"arg":{"channel":"books-l2-tbt","instId":"ELON-USDT"},"action":"update","data":[{"asks":[["0.00000074554","526402122","0","2"]],"bids":[],"ts":"1646003687455","checksum":31430205}]}
1646003687.47747: {"arg":{"channel":"books-l2-tbt","instId":"UNI-USD-SWAP"},"action":"update","data":[{"asks":[["9.632","506","0","3"],["9.633","47","0","2"]],"bids":[],"ts":"1646003687465","checksum":773359846}]}
1646003687.483152: {"arg":{"channel":"books-l2-tbt","instId":"PROPS-ETH"},"action":"update","data":[{"asks":[],"bids":[["0.00000167","345428.695106","0","2"]],"ts":"1646003687471","checksum":-176800426}]}
1646003687.490428: {"arg":{"channel":"books-l2-tbt","instId":"UNI-USD-SWAP"},"action":"update","data":[{"asks":[["9.633","52","0","2"]],"bids":[["9.613","53","0","1"],["9.608","512","0","2"],["9.607","27","0","2"]],"ts":"1646003687475","checksum":-403372761}]}
1646003687.497291: {"arg":{"channel":"books-l2-tbt","instId":"BTC-USD-220325-40000-C"},"action":"update","data":[{"asks":[["0.054","100","0","1"],["0.0545","0","0","0"]],"bids":[],"ts":"1646003687485","checksum":-561915348}]}
1646003687.49738: {"arg":{"channel":"books-l2-tbt","instId":"PROPS-ETH"},"action":"update","data":[{"asks":[],"bids":[["0.00000167","458159.513217","0","3"]],"ts":"1646003687485","checksum":191667901}]}
1646003687.497417: {"arg":{"channel":"books-l2-tbt","instId":"UNI-USD-SWAP"},"action":"update","data":[{"asks":[],"bids":[["9.608","12","0","1"],["9.606","500","0","1"]],"ts":"1646003687485","checksum":1089293347}]}
1646003687.515867: {"arg":{"channel":"books-l2-tbt","instId":"UNI-USD-SWAP"},"action":"update","data":[{"asks":[["9.623","22","0","1"]],"bids":[],"ts":"1646003687504","checksum":1416607884}]}
1646003687.5283551: {"arg":{"channel":"books-l2-tbt","instId":"UNI-USD-SWAP"},"action":"update","data":[{"asks":[],"bids":[["9.602","28","0","1"],["9.601","176","0","2"],["9.6","0","0","0"],["9.599","89","0","2"],["9.597","16","0","1"],["9.596","21","0","1"]],"ts":"1646003687514","checksum":480787648}]}
1646003687.539768: {"arg":{"channel":"books-l2-tbt","instId":"UNI-USD-SWAP"},"action":"update","data":[{"asks":[],"bids":[["9.615","23","0","2"]],"ts":"1646003687526","checksum":164650300}]}
1646003687.5419872: {"arg":{"channel":"books-l2-tbt","instId":"ELON-USDT"},"action":"update","data":[{"asks":[["0.00000074554","631867542","0","4"]],"bids":[],"ts":"1646003687531","checksum":-100914474}]}
1646003687.54843: {"arg":{"channel":"books-l2-tbt","instId":"UNI-USD-SWAP"},"action":"update","data":[{"asks":[["9.628","51","0","2"],["9.632","426","0","2"]],"bids":[],"ts":"1646003687536","checksum":748067402}]}
1646003687.558121: {"arg":{"channel":"books-l2-tbt","instId":"UNI-USD-SWAP"},"action":"update","data":[{"asks":[["9.633","77","0","2"],["9.658","64","0","1"]],"bids":[],"ts":"1646003687547","checksum":1775867234}]}
1646003687.581165: {"arg":{"channel":"books-l2-tbt","instId":"UNI-USD-SWAP"},"action":"update","data":[{"asks":[["9.657","41","0","1"],["48.143","0","0","0"]],"bids":[],"ts":"1646003687557","checksum":1775867234}]}
1646003687.581236: {"arg":{"channel":"books-l2-tbt","instId":"ELON-USDT"},"action":"update","data":[{"asks":[["0.00000074553","25220062","0","1"],["0.00000074554","578759819","0","3"],["0.00000074555","0","0","0"]],"bids":[],"ts":"1646003687559","checksum":-1469176203}]}
1646003687.581274: {"arg":{"channel":"books-l2-tbt","instId":"UNI-USD-SWAP"},"action":"update","data":[{"asks":[["9.657","0","0","0"],["9.66","0","0","0"],["48.143","1","0","1"],["48.383","1","0","1"]],"bids":[["9.615","22","0","1"]],"ts":"1646003687568","checksum":-574139596}]}
1646003687.58131: {"arg":{"channel":"books-l2-tbt","instId":"ELON-USDT"},"action":"update","data":[{"asks":[["0.00000074553","71061030","0","2"],["0.00000074554","526402122","0","2"],["0.00000074559","0","0","0"],["0.0000011338","129154981","0","1"]],"bids":[],"ts":"1646003687568","checksum":-1520388392}]}
1646003687.599744: {"arg":{"channel":"books-l2-tbt","instId":"UNI-USD-SWAP"},"action":"update","data":[{"asks":[["9.632","526","0","3"],["9.633","28","0","1"]],"bids":[],"ts":"1646003687580","checksum":1540417197}]}
1646003687.599862: {"arg":{"channel":"books-l2-tbt","instId":"ELON-USDT"},"action":"update","data":[{"asks":[["0.00000074553","107379502","0","3"]],"bids":[],"ts":"1646003687580","checksum":2098448308}]}
1646003687.602679: {"arg":{"channel":"books-l2-tbt","instId":"ELON-USDT"},"action":"update","data":[{"asks":[],"bids":[["0.00000074447","0","0","0"]],"ts":"1646003687590","checksum":-1257221015}]}
1646003687.614645: {"arg":{"channel":"books-l2-tbt","instId":"ELON-USDT"},"action":"update","data":[{"asks":[["0.00000074553","155395175","0","4"]],"bids":[],"ts":"1646003687601","checksum":-52553881}]}
1646003687.6219661: {"arg":{"channel":"books-l2-tbt","instId":"UNI-USD-SWAP"},"action":"update","data":[{"asks":[["9.622","83","0","1"],["48.383","0","0","0"]],"bids":[],"ts":"1646003687610","checksum":-2135447736}]}
1646003687.62205: {"arg":{"channel":"books-l2-tbt","instId":"ELON-USDT"},"action":"update","data":[{"asks":[["0.00000074552","445226872","0","1"],["0.0000011338","0","0","0"]],"bids":[],"ts":"1646003687610","checksum":1344187885}]}
1646003687.637773: {"arg":{"channel":"books-l2-tbt","instId":"PROPS-ETH"},"action":"update","data":[{"asks":[["0.00000175","0","0","0"]],"bids":[["0.00000167","470135.56037268","0","4"]],"ts":"1646003687625","checksum":-200324433}]}
1646003687.64633: {"arg":{"channel":"books-l2-tbt","instId":"UNI-USD-SWAP"},"action":"update","data":[{"asks":[],"bids":[["9.575","108","0","2"]],"ts":"1646003687630","checksum":-2135447736}]}
1646003687.6463869: {"arg":{"channel":"books-l2-tbt","instId":"ELON-USDT"},"action":"update","data":[{"asks":[["0.00000074553","107379502","0","3"]],"bids":[],"ts":"1646003687631","checksum":1370633059}]}
1646003687.657411: {"arg":{"channel":"books-l2-tbt","instId":"ELON-USDT"},"action":"update","data":[{"asks":[["0.00000074554","81175250","0","1"]],"bids":[],"ts":"1646003687643","checksum":-980565507}]}
1646003687.65931: {"arg":{"channel":"books-l2-tbt","instId":"PROPS-ETH"},"action":"update","data":[{"asks":[["0.00000174","0","0","0"]],"bids":[],"ts":"1646003687647","checksum":-1187171238}]}
1646003687.66139: {"arg":{"channel":"books-l2-tbt","instId":"UNI-USD-SWAP"},"action":"update","data":[{"asks":[],"bids":[["9.602","53","0","2"],["9.601","153","0","1"],["9.6","29","0","1"],["9.599","63","0","1"],["9.597","43","0","2"],["9.596","0","0","0"]],"ts":"1646003687650","checksum":-1625734575}]}
1646003687.6638248: {"arg":{"channel":"books-l2-tbt","instId":"ELON-USDT"},"action":"update","data":[{"asks":[["0.00000074551","48015673","0","1"],["0.00000113315","0","0","0"]],"bids":[],"ts":"1646003687652","checksum":-843892131}]}
1646003687.668375: {"arg":{"channel":"books-l2-tbt","instId":"PROPS-ETH"},"action":"update","data":[{"asks":[["0.00000175","9857.335534","0","1"]],"bids":[],"ts":"1646003687657","checksum":-1597285065}]}
1646003687.6730108: {"arg":{"channel":"books-l2-tbt","instId":"UNI-USD-SWAP"},"action":"update","data":[{"asks":[],"bids":[["9.575","150","0","3"]],"ts":"1646003687660","checksum":-1625734575}]}
1646003687.6783712: {"arg":{"channel":"books-l2-tbt","instId":"PROPS-ETH"},"action":"update","data":[{"asks":[["0.00000173","9252.53822994","0","1"]],"bids":[],"ts":"1646003687667","checksum":-851178339}]}
1646003687.693365: {"arg":{"channel":"books-l2-tbt","instId":"ETH-USD-220429-1900-P"},"action":"update","data":[{"asks":[],"bids":[],"ts":"1646003687683","checksum":-1328280565}]}
1646003687.705895: {"arg":{"channel":"books-l2-tbt","instId":"PROPS-ETH"},"action":"update","data":[{"asks":[["0.00000175","0","0","0"]],"bids":[],"ts":"1646003687692","checksum":-1844139720}]}
1646003687.723187: {"arg":{"channel":"books-l2-tbt","instId":"ELON-USDT"},"action":"update","data":[{"asks":[["0.0000007455","445226872","0","1"],["0.00000113256","0","0","0"]],"bids":[],"ts":"1646003687711","checksum":577315320}]}
1646003687.7232692: {"arg":{"channel":"books-l2-tbt","instId":"UNI-USD-SWAP"},"action":"update","data":[{"asks":[["9.659","1575","0","4"]],"bids":[],"ts":"1646003687712","checksum":-1625734575}]}
1646003687.726872: {"arg":{"channel":"books-l2-tbt","instId":"PROPS-ETH"},"action":"update","data":[{"asks":[["0.00000172","9851.6562859","0","1"]],"bids":[],"ts":"1646003687715","checksum":1972412035}]}
1646003687.7418659: {"arg":{"channel":"books-l2-tbt","instId":"ELON-USDT"},"action":"update","data":[{"asks":[["0.00000074551","0","0","0"],["0.00000074552","0","0","0"],["0.00000113256","10462875","0","1"],["0.00000113315","35900750","0","1"]],"bids":[],"ts":"1646003687730","checksum":303393093}]}
1646003687.764266: {"arg":{"channel":"books-l2-tbt","instId":"ELON-USDT"},"action":"update","data":[{"asks":[["0.00000074549","103956611","0","1"],["0.00000113315","0","0","0"]],"bids":[],"ts":"1646003687752","checksum":-1777523221}]}
1646003687.774688: {"arg":{"channel":"books-l2-tbt","instId":"ELON-USDT"},"action":"update","data":[{"asks":[["0.0000007455","0","0","0"],["0.00000113315","35900750","0","1"]],"bids":[],"ts":"1646003687762","checksum":2030487711}]}
1646003687.783193: {"arg":{"channel":"books-l2-tbt","instId":"ELON-USDT"},"action":"update","data":[{"asks":[["0.00000074552","445226872","0","1"],["0.00000113315","0","0","0"]],"bids":[],"ts":"1646003687770","checksum":-20578312}]}
1646003687.803654: {"arg":{"channel":"books-l2-tbt","instId":"ELON-USDT"},"action":"update","data":[{"asks":[["0.00000074599","111652879","0","1"],["0.00000113256","0","0","0"]],"bids":[],"ts":"1646003687793","checksum":1258203226}]}
1646003687.806848: {"arg":{"channel":"books-l2-tbt","instId":"ELON-USDT"},"action":"update","data":[{"asks":[["0.00000074548","91876326","0","3"],["0.00000074553","25220062","0","1"],["0.00000074599","0","0","0"]],"bids":[],"ts":"1646003687795","checksum":1450233123}]}
1646003687.81115: {"arg":{"channel":"books-l2-tbt","instId":"PROPS-ETH"},"action":"update","data":[{"asks":[["0.00000177","0","0","0"],["0.00000178","0","0","0"],["0.00000181","1437.66137372","0","1"],["0.00000182","1393.72536888","0","1"],["0.00000186","0","0","0"]],"bids":[],"ts":"1646003687799","checksum":-1197432280}]}
1646003687.817651: {"arg":{"channel":"books-l2-tbt","instId":"ELON-USDT"},"action":"update","data":[{"asks":[["0.00000074548","537103198","0","4"]],"bids":[],"ts":"1646003687806","checksum":-199964255}]}
1646003687.827169: {"arg":{"channel":"books-l2-tbt","instId":"ELON-USDT"},"action":"update","data":[{"asks":[["0.00000074548","648756077","0","5"],["0.00000074552","0","0","0"],["0.00000113256","10462875","0","1"]],"bids":[],"ts":"1646003687816","checksum":-1704537111}]}
1646003687.830546: {"arg":{"channel":"books-l2-tbt","instId":"UNI-USD-SWAP"},"action":"update","data":[{"asks":[["9.654","18","0","1"],["48.143","0","0","0"]],"bids":[],"ts":"1646003687817","checksum":-1625734575}]}
1646003687.8358169: {"arg":{"channel":"books-l2-tbt","instId":"ELON-USDT"},"action":"update","data":[{"asks":[["0.00000074549","0","0","0"],["0.00000074553","0","0","0"],["0.00000113315","35900750","0","1"],["0.0000011338","129154981","0","1"]],"bids":[["0.00000074202","184440410","0","1"]],"ts":"1646003687825","checksum":363274135}]}
1646003687.850451: {"arg":{"channel":"books-l2-tbt","instId":"UNI-USD-SWAP"},"action":"update","data":[{"asks":[["9.654","0","0","0"],["48.143","1","0","1"]],"bids":[],"ts":"1646003687838","checksum":-1625734575}]}
1646003687.857889: {"arg":{"channel":"books-l2-tbt","instId":"ELON-USDT"},"action":"update","data":[{"asks":[["0.00000074547","103956611","0","1"],["0.0000011338","0","0","0"]],"bids":[["0.0000007433","0","0","0"],["0.00000074202","0","0","0"]],"ts":"1646003687846","checksum":-286871533}]}
1646003687.898623: {"arg":{"channel":"books-l2-tbt","instId":"ELON-USDT"},"action":"update","data":[{"asks":[["0.00000074546","445226872","0","1"],["0.00000113315","0","0","0"]],"bids":[],"ts":"1646003687887","checksum":1249862793}]}
1646003687.90942: {"arg":{"channel":"books-l2-tbt","instId":"ELON-USDT"},"action":"update","data":[{"asks":[],"bids":[["0.0000007433","24727523","0","1"],["0.00000074221","3603534031","0","1"]],"ts":"1646003687899","checksum":-987133200}]}
1646003687.920044: {"arg":{"channel":"books-l2-tbt","instId":"ELON-USDT"},"action":"update","data":[{"asks":[["0.00000074545","48015673","0","1"],["0.00000074547","0","0","0"],["0.00000074548","91876326","0","3"]],"bids":[["0.00000070254","0","0","0"],["0.00000068849","0","0","0"],["0.00000067473","0","0","0"],["0.00000066124","0","0","0"],["0.00000064798","302223687","0","1"]],"ts":"1646003687909","checksum":573441414}]}
1646003687.924173: {"arg":{"channel":"books-l2-tbt","instId":"UNI-USD-SWAP"},"action":"update","data":[{"asks":[],"bids":[["9.575","108","0","2"]],"ts":"1646003687913","checksum":-1625734575}]}
1646003687.936728: {"arg":{"channel":"books-l2-tbt","instId":"ELON-USDT"},"action":"update","data":[{"asks":[["0.00000074545","263625163","0","3"]],"bids":[],"ts":"1646003687921","checksum":1656663459}]}
1646003687.936812: {"arg":{"channel":"books-l2-tbt","instId":"UNI-USD-SWAP"},"action":"update","data":[{"asks":[["9.632","426","0","2"]],"bids":[["9.575","136","0","3"]],"ts":"1646003687925","checksum":-1070556705}]}
1646003687.951329: {"arg":{"channel":"books-l2-tbt","instId":"ELON-USDT"},"action":"update","data":[{"asks":[["0.00000074545","48015673","0","1"]],"bids":[],"ts":"1646003687930","checksum":573441414}]}
1646003687.961806: {"arg":{"channel":"books-l2-tbt","instId":"ELON-USDT"},"action":"update","data":[{"asks":[["0.00000074544","445226872","0","1"],["0.00000074554","0","0","0"]],"bids":[],"ts":"1646003687950","checksum":-1384112494}]}
1646003687.974623: {"arg":{"channel":"books-l2-tbt","instId":"ELON-USDT"},"action":"update","data":[{"asks":[],"bids":[["0.00000074381","151300709","0","1"],["0.0000007433","0","0","0"]],"ts":"1646003687962","checksum":1214240535}]}
1646003687.9861271: {"arg":{"channel":"books-l2-tbt","instId":"ELON-USDT"},"action":"update","data":[{"asks":[["0.00000074545","0","0","0"],["0.00000113315","35900750","0","1"]],"bids":[],"ts":"1646003687971","checksum":1603526508}]}
1646003687.986201: {"arg":{"channel":"books-l2-tbt","instId":"UNI-USD-SWAP"},"action":"update","data":[{"asks":[["9.632","526","0","3"]],"bids":[["9.608","353","0","2"]],"ts":"1646003687975","checksum":634233764}]}
1646003687.9919622: {"arg":{"channel":"books-l2-tbt","instId":"ELON-USDT"},"action":"update","data":[{"asks":[["0.00000074543","111652879","0","1"],["0.00000113315","0","0","0"]],"bids":[],"ts":"1646003687980","checksum":589885800}]}
1646003688.0026739: {"arg":{"channel":"books-l2-tbt","instId":"ELON-USDT"},"action":"update","data":[{"asks":[["0.00000074543","173191413","0","3"],["0.00000074546","0","0","0"],["0.00000074548","0","0","0"],["0.00000113315","35900750","0","1"],["0.0000011338","129154981","0","1"]],"bids":[],"ts":"1646003687992","checksum":-1368409403}]}
1646003688.007978: {"arg":{"channel":"books-l2-tbt","instId":"UNI-USD-SWAP"},"action":"update","data":[{"asks":[],"bids":[["9.612","260","0","1"],["9.602","28","0","1"],["9.601","175","0","2"],["9.6","0","0","0"],["9.599","89","0","2"],["9.597","16","0","1"],["9.596","29","0","1"],["9.575","35","0","1"]],"ts":"1646003687996","checksum":689091516}]}
1646003688.01351: {"arg":{"channel":"books-l2-tbt","instId":"ELON-USDT"},"action":"update","data":[{"asks":[["0.00000074543","277148024","0","4"]],"bids":[],"ts":"1646003688001","checksum":1386150223}]}
1646003688.020714: {"arg":{"channel":"books-l2-tbt","instId":"UNI-USD-SWAP"},"action":"update","data":[{"asks":[["9.631","652","0","3"],["9.632","426","0","2"]],"bids":[["9.613","0","0","0"],["9.578","72","0","1"]],"ts":"1646003688007","checksum":-903652796}]}
1646003688.0295732: {"arg":{"channel":"books-l2-tbt","instId":"UNI-USD-SWAP"},"action":"update","data":[{"asks":[],"bids":[["9.612","313","0","2"]],"ts":"1646003688018","checksum":-213041904}]}
1646003688.03018: {"arg":{"channel":"books-l2-tbt","instId":"ZEN-USDT"},"action":"update","data":[{"asks":[["32.57","49.865739","0","3"]],"bids":[],"ts":"1646003688019","checksum":777021022}]}
1646003688.035239: {"arg":{"channel":"books-l2-tbt","instId":"ELON-USDT"},"action":"update","data":[{"asks":[],"bids":[["0.00000074435","112516946","0","1"]],"ts":"1646003688023","checksum":-1211633203}]}
1646003688.042124: {"arg":{"channel":"books-l2-tbt","instId":"UNI-USD-SWAP"},"action":"update","data":[{"asks":[["9.631","651","0","2"],["9.632","526","0","3"]],"bids":[],"ts":"1646003688029","checksum":73675564}]}
1646003688.044456: {"arg":{"channel":"books-l2-tbt","instId":"ELON-USDT"},"action":"update","data":[{"asks":[["0.00000074547","287189114","0","1"],["0.0000011338","0","0","0"]],"bids":[],"ts":"1646003688032","checksum":-1015614808}]}
1646003688.048418: {"arg":{"channel":"books-l2-tbt","instId":"UNI-USD-SWAP"},"action":"update","data":[{"asks":[],"bids":[["9.578","0","0","0"]],"ts":"1646003688037","checksum":73675564}]}
1646003688.0540092: {"arg":{"channel":"books-l2-tbt","instId":"ELON-USDT"},"action":"update","data":[{"asks":[["0.00000074548","81175250","0","1"],["0.00000113315","0","0","0"]],"bids":[["0.00000074445","219861835","0","1"]],"ts":"1646003688042","checksum":-9939524}]}
1646003688.064821: {"arg":{"channel":"books-l2-tbt","instId":"ZEN-USDT"},"action":"update","data":[{"asks":[["32.57","49.017069","0","2"]],"bids":[],"ts":"1646003688051","checksum":-846813839}]}
1646003688.083786: {"arg":{"channel":"books-l2-tbt","instId":"ELON-USDT"},"action":"update","data":[{"asks":[],"bids":[["0.00000074381","0","0","0"]],"ts":"1646003688072","checksum":247733181}]}
1646003688.095399: {"arg":{"channel":"books-l2-tbt","instId":"UNI-USD-SWAP"},"action":"update","data":[{"asks":[["9.631","652","0","3"],["9.632","426","0","2"]],"bids":[],"ts":"1646003688078","checksum":-213041904}]}
1646003688.10049: {"arg":{"channel":"books-l2-tbt","instId":"ELON-USDT"},"action":"update","data":[{"asks":[["0.00000074544","0","0","0"],["0.00000113315","35900750","0","1"]],"bids":[],"ts":"1646003688084","checksum":2115574672}]}
1646003688.100574: {"arg":{"channel":"books-l2-tbt","instId":"UNI-USD-SWAP"},"action":"update","data":[{"asks":[["9.656","161","0","2"]],"bids":[],"ts":"1646003688089","checksum":-213041904}]}
1646003688.109258: {"arg":{"channel":"books-l2-tbt","instId":"ELON-USDT"},"action":"update","data":[{"asks":[["0.00000074543","325163697","0","5"]],"bids":[],"ts":"1646003688096","checksum":812304064}]}
1646003688.116856: {"arg":{"channel":"books-l2-tbt","instId":"ELON-USDT"},"action":"update","data":[{"asks":[["0.00000074543","61538534","0","2"]],"bids":[],"ts":"1646003688105","checksum":1682294657}]}
1646003688.1287098: {"arg":{"channel":"books-l2-tbt","instId":"ELON-USDT"},"action":"update","data":[{"asks":[["0.00000074542","263625163","0","3"],["0.00000113315","0","0","0"]],"bids":[],"ts":"1646003688114","checksum":-1641155104}]}
1646003688.138357: {"arg":{"channel":"books-l2-tbt","instId":"ELON-USDT"},"action":"update","data":[{"asks":[["0.00000074542","0","0","0"],["0.00000113315","35900750","0","1"]],"bids":[],"ts":"1646003688126","checksum":1682294657}]}
1646003688.14792: {"arg":{"channel":"books-l2-tbt","instId":"ELON-USDT"},"action":"update","data":[{"asks":[["0.00000074541","111652879","0","1"],["0.00000113315","0","0","0"]],"bids":[],"ts":"1646003688135","checksum":1757154395}]}
1646003688.1541471: {"arg":{"channel":"books-l2-tbt","instId":"UNI-USD-SWAP"},"action":"update","data":[{"asks":[["9.656","124","0","1"]],"bids":[],"ts":"1646003688142","checksum":-213041904}]}
1646003688.157084: {"arg":{"channel":"books-l2-tbt","instId":"ELON-USDT"},"action":"update","data":[{"asks":[["0.00000074541","0","0","0"],["0.00000074546","48015673","0","1"]],"bids":[],"ts":"1646003688146","checksum":-462448382}]}
1646003688.167397: {"arg":{"channel":"books-l2-tbt","instId":"ELON-USDT"},"action":"update","data":[{"asks":[["0.00000074542","350128858","0","1"],["0.00000074546","0","0","0"]],"bids":[["0.00000074435","0","0","0"]],"ts":"1646003688155","checksum":684535457}]}
1646003688.174925: {"arg":{"channel":"books-l2-tbt","instId":"UNI-USD-SWAP"},"action":"update","data":[{"asks":[["9.631","651","0","2"],["9.632","526","0","3"]],"bids":[["9.612","260","0","1"]],"ts":"1646003688163","checksum":1024087160}]}
1646003688.175047: {"arg":{"channel":"books-l2-tbt","instId":"ZEN-USDT"},"action":"update","data":[{"asks":[],"bids":[["31.86","4.37392","0","2"],["31.55","6.6","0","1"],["31.24","9.16","0","1"],["30.93","14.584933","0","3"]],"ts":"1646003688163","checksum":-846813839}]}
1646003688.180223: {"arg":{"channel":"books-l2-tbt","instId":"ELON-USDT"},"action":"update","data":[{"asks":[["0.00000074545","159668552","0","2"],["0.00000113256","0","0","0"]],"bids":[["0.00000074381","161497014","0","1"]],"ts":"1646003688166","checksum":1262813615}]}
1646003688.1873531: {"arg":{"channel":"books-l2-tbt","instId":"ELON-USDT"},"action":"update","data":[{"asks":[["0.00000074545","111652879","0","1"],["0.00000074547","0","0","0"],["0.00000113256","10462875","0","1"]],"bids":[],"ts":"1646003688175","checksum":1645237921}]}
1646003688.1969972: {"arg":{"channel":"books-l2-tbt","instId":"ELON-USDT"},"action":"update","data":[{"asks":[["0.00000074541","48015673","0","1"],["0.00000074745","0","0","0"]],"bids":[],"ts":"1646003688185","checksum":635734602}]}
1646003688.217406: {"arg":{"channel":"books-l2-tbt","instId":"ELON-USDT"},"action":"update","data":[{"asks":[["0.00000074541","185732967","0","4"],["0.00000074543","0","0","0"],["0.00000113315","35900750","0","1"]],"bids":[["0.00000074381","0","0","0"]],"ts":"1646003688195","checksum":-1669287249}]}
1646003688.217501: {"arg":{"channel":"books-l2-tbt","instId":"BTC-USD-220325-40000-C"},"action":"update","data":[{"asks":[["0.054","0","0","0"],["0.0545","100","0","1"]],"bids":[],"ts":"1646003688197","checksum":-1840363265}]}
1646003688.226729: {"arg":{"channel":"books-l2-tbt","instId":"UNI-USD-SWAP"},"action":"update","data":[{"asks":[],"bids":[["9.613","53","0","1"]],"ts":"1646003688214","checksum":689091516}]}
1646003688.229766: {"arg":{"channel":"books-l2-tbt","instId":"ELON-USDT"},"action":"update","data":[{"asks":[["0.00000074545","0","0","0"],["0.0000011338","129154981","0","1"]],"bids":[],"ts":"1646003688217","checksum":1364886894}]}
1646003688.235169: {"arg":{"channel":"books-l2-tbt","instId":"ZEN-USDT"},"action":"update","data":[{"asks":[],"bids":[["32.12","1.55","0","1"],["32.11","0","0","0"],["31.67","4.71","0","1"],["31.66","0.055516","0","1"]],"ts":"1646003688224","checksum":643230345}]}
1646003688.235239: {"arg":{"channel":"books-l2-tbt","instId":"UNI-USD-SWAP"},"action":"update","data":[{"asks":[],"bids":[["9.577","243","0","2"]],"ts":"1646003688225","checksum":689091516}]}
1646003688.247124: {"arg":{"channel":"books-l2-tbt","instId":"ELON-USDT"},"action":"update","data":[{"asks":[],"bids":[["0.00000074446","184440410","0","1"]],"ts":"1646003688236","checksum":-468366840}]}
1646003688.259733: {"arg":{"channel":"books-l2-tbt","instId":"ELON-USDT"},"action":"update","data":[{"asks":[["0.00000074724","3069553515","0","1"],["0.0000011338","0","0","0"]],"bids":[],"ts":"1646003688247","checksum":2042575488}]}
1646003688.267292: {"arg":{"channel":"books-l2-tbt","instId":"ZEN-USDT"},"action":"update","data":[{"asks":[["32.86","0","0","0"],["32.87","1.52","0","1"],["33.32","0","0","0"],["33.33","4.575482","0","2"],["33.78","0","0","0"],["33.79","16.18","0","2"],["34.25","0","0","0"],["34.26","13.58378","0","3"],["34.72","0","0","0"],["34.73","13.28","0","1"],["44.08","0.010156","0","1"],["44.13","0.04","0","1"],["44.14","0.039111","0","2"]],"bids":[["31.23","8.381052","0","2"],["31.22","0.010163","0","1"],["30.8","11.16","0","1"],["30.79","0","0","0"],["30.37","14.45","0","1"],["30.36","0","0","0"]],"ts":"1646003688254","checksum":1000120215}]}
1646003688.267444: {"arg":{"channel":"books-l2-tbt","instId":"ELON-USDT"},"action":"update","data":[{"asks":[["0.00000074599","406933677","0","1"],["0.00000113315","0","0","0"]],"bids":[],"ts":"1646003688256","checksum":838564204}]}
1646003688.289077: {"arg":{"channel":"books-l2-tbt","instId":"ELON-USDT"},"action":"update","data":[{"asks":[["0.00000074541","137717294","0","3"],["0.00000074542","0","0","0"],["0.00000113315","35900750","0","1"]],"bids":[],"ts":"1646003688276","checksum":1508776915}]}
1646003688.289168: {"arg":{"channel":"books-l2-tbt","instId":"UNI-USD-SWAP"},"action":"update","data":[{"asks":[["9.631","652","0","3"],["9.632","426","0","2"]],"bids":[],"ts":"1646003688275","checksum":-1030929488}]}
1646003688.302326: {"arg":{"channel":"books-l2-tbt","instId":"PROPS-ETH"},"action":"update","data":[{"asks":[["0.00000178","574.77184782","0","1"],["0.00000181","0","0","0"],["0.00000182","0","0","0"],["0.00000185","0","0","0"],["0.00000187","1177.46134029","0","1"]],"bids":[["0.00000161","9585.93036084","0","1"],["0.0000016","0","0","0"]],"ts":"1646003688291","checksum":2030251196}]}
1646003688.310792: {"arg":{"channel":"books-l2-tbt","instId":"UNI-USD-SWAP"},"action":"update","data":[{"asks":[],"bids":[["9.574","0","0","0"]],"ts":"1646003688297","checksum":-1030929488}]}
1646003688.3192809: {"arg":{"channel":"books-l2-tbt","instId":"UNI-USD-SWAP"},"action":"update","data":[{"asks":[["9.63","3","0","1"],["48.143","0","0","0"]],"bids":[],"ts":"1646003688307","checksum":565890279}]}
1646003688.329391: {"arg":{"channel":"books-l2-tbt","instId":"UNI-USD-SWAP"},"action":"update","data":[{"asks":[["9.628","50","0","1"]],"bids":[["9.575","545","0","2"]],"ts":"1646003688318","checksum":-1423014196}]}
1646003688.335822: {"arg":{"channel":"books-l2-tbt","instId":"ZEN-USDT"},"action":"update","data":[{"asks":[],"bids":[["31.72","0","0","0"]],"ts":"1646003688323","checksum":1000120215}]}
1646003688.342987: {"arg":{"channel":"books-l2-tbt","instId":"UNI-USD-SWAP"},"action":"update","data":[{"asks":[],"bids":[["9.577","225","0","1"]],"ts":"1646003688327","checksum":-1423014196}]}
1646003688.357961: {"arg":{"channel":"books-l2-tbt","instId":"ELON-USDT"},"action":"update","data":[{"asks":[["0.0000007454","136770513","0","1"],["0.00000113315","0","0","0"]],"bids":[],"ts":"1646003688338","checksum":-2043826170}]}
1646003688.373085: {"arg":{"channel":"books-l2-tbt","instId":"ELON-USDT"},"action":"update","data":[{"asks":[["0.00000074539","103956611","0","1"],["0.00000074599","0","0","0"]],"bids":[],"ts":"1646003688360","checksum":-867977130}]}
1646003688.386097: {"arg":{"channel":"books-l2-tbt","instId":"PROPS-ETH"},"action":"update","data":[{"asks":[],"bids":[["0.00000167","458159.513217","0","3"]],"ts":"1646003688375","checksum":-693080008}]}
1646003688.39442: {"arg":{"channel":"books-l2-tbt","instId":"ELON-USDT"},"action":"update","data":[{"asks":[["0.00000074539","215609490","0","2"]],"bids":[],"ts":"1646003688381","checksum":1612293829}]}
1646003688.412673: {"arg":{"channel":"books-l2-tbt","instId":"ELON-USDT"},"action":"update","data":[{"asks":[["0.00000074539","277148024","0","4"],["0.00000074541","0","0","0"],["0.00000113315","35900750","0","1"]],"bids":[],"ts":"1646003688401","checksum":-268600151}]}
1646003688.414251: {"arg":{"channel":"books-l2-tbt","instId":"UNI-USD-SWAP"},"action":"update","data":[{"asks":[["9.621","0","0","0"],["9.654","16","0","1"]],"bids":[["9.575","614","0","3"]],"ts":"1646003688403","checksum":1745597530}]}
1646003688.423745: {"arg":{"channel":"books-l2-tbt","instId":"ELON-USDT"},"action":"update","data":[{"asks":[],"bids":[["0.00000074381","184440410","0","1"],["0.00000064798","0","0","0"]],"ts":"1646003688411","checksum":-292033263}]}
1646003688.434123: {"arg":{"channel":"books-l2-tbt","instId":"ELON-USDT"},"action":"update","data":[{"asks":[],"bids":[["0.0000006993","367379005","0","1"],["0.00000068532","378873012","0","1"],["0.00000067162","269460685","0","1"],["0.00000065819","347727589","0","1"]],"ts":"1646003688421","checksum":-292033263}]}
1646003688.434268: {"arg":{"channel":"books-l2-tbt","instId":"UNI-USD-SWAP"},"action":"update","data":[{"asks":[["9.622","0","0","0"],["9.623","0","0","0"],["9.654","0","0","0"],["48.143","1","0","1"],["48.383","1","0","1"],["48.625","1","0","1"]],"bids":[],"ts":"1646003688422","checksum":-1845185133}]}
1646003688.446452: {"arg":{"channel":"books-l2-tbt","instId":"UNI-USD-SWAP"},"action":"update","data":[{"asks":[["9.623","83","0","1"],["9.627","0","0","0"],["9.631","651","0","2"],["9.633","62","0","2"]],"bids":[["9.614","422","0","3"],["9.613","0","0","0"]],"ts":"1646003688431","checksum":1417044019}]}
1646003688.4549172: {"arg":{"channel":"books-l2-tbt","instId":"ELON-USDT"},"action":"update","data":[{"asks":[["0.00000074538","324312168","0","1"],["0.00000113315","0","0","0"]],"bids":[],"ts":"1646003688442","checksum":959066025}]}
1646003688.454987: {"arg":{"channel":"books-l2-tbt","instId":"UNI-USD-SWAP"},"action":"update","data":[{"asks":[["9.662","0","0","0"],["9.671","16","0","1"]],"bids":[["9.616","2","0","1"]],"ts":"1646003688442","checksum":-1748925475}]}
1646003688.468739: {"arg":{"channel":"books-l2-tbt","instId":"UNI-USD-SWAP"},"action":"update","data":[{"asks":[["9.626","0","0","0"],["9.627","121","0","1"],["9.633","58","0","2"],["9.671","0","0","0"],["48.868","1","0","1"]],"bids":[],"ts":"1646003688452","checksum":1674104137}]}
1646003688.475553: {"arg":{"channel":"books-l2-tbt","instId":"ZEN-USDT"},"action":"update","data":[{"asks":[["32.58","55.61422","0","2"]],"bids":[["32.34","0","0","0"]],"ts":"1646003688461","checksum":1938201096}]}
1646003688.4756532: {"arg":{"channel":"books-l2-tbt","instId":"ELON-USDT"},"action":"update","data":[{"asks":[["0.00000074539","61538534","0","2"]],"bids":[],"ts":"1646003688463","checksum":1447562956}]}
1646003688.475689: {"arg":{"channel":"books-l2-tbt","instId":"UNI-USD-SWAP"},"action":"update","data":[{"asks":[["9.627","0","0","0"],["9.63","0","0","0"],["9.671","16","0","1"],["49.113","1","0","1"]],"bids":[["9.609","0","0","0"]],"ts":"1646003688463","checksum":1949664938}]}
1646003688.485064: {"arg":{"channel":"books-l2-tbt","instId":"ELON-USDT"},"action":"update","data":[{"asks":[],"bids":[["0.00000074446","0","0","0"]],"ts":"1646003688472","checksum":-1292865752}]}
1646003688.485673: {"arg":{"channel":"books-l2-tbt","instId":"UNI-USD-SWAP"},"action":"update","data":[{"asks":[["9.623","343","0","2"],["9.624","0","0","0"],["49.358","1","0","1"]],"bids":[["9.602","49","0","2"],["9.601","153","0","1"],["9.6","25","0","1"],["9.599","63","0","1"],["9.597","44","0","2"],["9.596","0","0","0"]],"ts":"1646003688473","checksum":-311101512}]}
1646003688.4941142: {"arg":{"channel":"books-l2-tbt","instId":"ZEN-USDT"},"action":"update","data":[{"asks":[],"bids":[["32.46","79.370345","0","5"]],"ts":"1646003688481","checksum":770481277}]}
1646003688.494196: {"arg":{"channel":"books-l2-tbt","instId":"ELON-USDT"},"action":"update","data":[{"asks":[["0.00000074537","263625163","0","3"],["0.00000113256","0","0","0"]],"bids":[],"ts":"1646003688482","checksum":1503228608}]}
1646003688.4983969: {"arg":{"channel":"books-l2-tbt","instId":"UNI-USD-SWAP"},"action":"update","data":[{"asks":[["9.627","121","0","1"],["49.358","0","0","0"]],"bids":[],"ts":"1646003688485","checksum":-1639921644}]}
1646003688.499614: {"arg":{"channel":"books-l2-tbt","instId":"BTC-USD-220325-40000-C"},"action":"update","data":[{"asks":[["0.0535","0","0","0"],["0.054","300","0","1"]],"bids":[],"ts":"1646003688490","checksum":953603407}]}
1646003688.5072021: {"arg":{"channel":"books-l2-tbt","instId":"UNI-USD-SWAP"},"action":"update","data":[{"asks":[],"bids":[["9.608","358","0","3"],["9.607","21","0","1"],["9.575","650","0","4"]],"ts":"1646003688494","checksum":-972982335}]}
1646003688.5073228: {"arg":{"channel":"books-l2-tbt","instId":"ELON-USDT"},"action":"update","data":[{"asks":[],"bids":[["0.00000074221","0","0","0"]],"ts":"1646003688495","checksum":1495315642}]}
1646003688.511607: {"arg":{"channel":"books-l2-tbt","instId":"PROPS-ETH"},"action":"update","data":[{"asks":[],"bids":[["0.00000167","172714.347553","0","1"]],"ts":"1646003688500","checksum":-1882385703}]}
1646003688.514869: {"arg":{"channel":"books-l2-tbt","instId":"UNI-USD-SWAP"},"action":"update","data":[{"asks":[["9.628","51","0","2"],["9.671","0","0","0"],["49.358","1","0","1"]],"bids":[],"ts":"1646003688504","checksum":1846427230}]}
1646003688.518395: {"arg":{"channel":"books-l2-tbt","instId":"ELON-USDT"},"action":"update","data":[{"asks":[["0.0000007454","0","0","0"],["0.00000113256","10462875","0","1"]],"bids":[],"ts":"1646003688506","checksum":-1487375639}]}
1646003688.5248342: {"arg":{"channel":"books-l2-tbt","instId":"ZEN-USDT"},"action":"update","data":[{"asks":[["32.59","35.965067","0","1"]],"bids":[["32.41","15.36651","0","1"]],"ts":"1646003688513","checksum":1824264297}]}
1646003688.524906: {"arg":{"channel":"books-l2-tbt","instId":"UNI-USD-SWAP"},"action":"update","data":[{"asks":[["9.623","260","0","1"],["9.659","1591","0","5"]],"bids":[],"ts":"1646003688514","checksum":26297191}]}
1646003688.526977: {"arg":{"channel":"books-l2-tbt","instId":"ELON-USDT"},"action":"update","data":[{"asks":[["0.00000074548","0","0","0"],["0.00000113315","35900750","0","1"]],"bids":[],"ts":"1646003688515","checksum":-148119824}]}
1646003688.550262: {"arg":{"channel":"books-l2-tbt","instId":"ELON-USDT"},"action":"update","data":[{"asks":[["0.00000074537","159668552","0","2"]],"bids":[],"ts":"1646003688538","checksum":1300089038}]}
1646003688.552375: {"arg":{"channel":"books-l2-tbt","instId":"PROPS-ETH"},"action":"update","data":[{"asks":[],"bids":[["0.00000167","474144.07985929","0","3"]],"ts":"1646003688540","checksum":-49699763}]}
1646003688.561644: {"arg":{"channel":"books-l2-tbt","instId":"UNI-USD-SWAP"},"action":"update","data":[{"asks":[["9.659","1575","0","4"],["9.671","16","0","1"],["49.358","0","0","0"]],"bids":[],"ts":"1646003688547","checksum":-1736463632}]}
1646003688.5617762: {"arg":{"channel":"books-l2-tbt","instId":"PROPS-ETH"},"action":"update","data":[{"asks":[],"bids":[["0.00000167","587512.95671529","0","4"]],"ts":"1646003688549","checksum":1100903697}]}
1646003688.580309: {"arg":{"channel":"books-l2-tbt","instId":"ELON-USDT"},"action":"update","data":[{"asks":[],"bids":[["0.00000074445","0","0","0"]],"ts":"1646003688566","checksum":1791436300}]}
1646003688.595387: {"arg":{"channel":"books-l2-tbt","instId":"ZEN-USDT"},"action":"update","data":[{"asks":[],"bids":[["32.4","0","0","0"]],"ts":"1646003688584","checksum":-2083239889}]}
1646003688.595444: {"arg":{"channel":"books-l2-tbt","instId":"UNI-USD-SWAP"},"action":"update","data":[{"asks":[],"bids":[["9.602","28","0","1"],["9.601","177","0","2"],["9.6","0","0","0"],["9.599","92","0","2"],["9.597","16","0","1"],["9.596","28","0","1"]],"ts":"1646003688585","checksum":-626937199}]}
1646003688.607957: {"arg":{"channel":"books-l2-tbt","instId":"ELON-USDT"},"action":"update","data":[{"asks":[],"bids":[["0.00000074381","0","0","0"]],"ts":"1646003688596","checksum":-1404754625}]}
1646003688.6193652: {"arg":{"channel":"books-l2-tbt","instId":"UNI-USD-SWAP"},"action":"update","data":[{"asks":[],"bids":[["9.575","614","0","3"]],"ts":"1646003688607","checksum":-626937199}]}
1646003688.619478: {"arg":{"channel":"books-l2-tbt","instId":"ELON-USDT"},"action":"update","data":[{"asks":[["0.00000074537","228238898","0","3"],["0.00000074539","36318472","0","1"]],"bids":[],"ts":"1646003688607","checksum":-1153828449}]}
1646003688.630929: {"arg":{"channel":"books-l2-tbt","instId":"ELON-USDT"},"action":"update","data":[{"asks":[["0.00000074537","132625244","0","3"],["0.00000074539","81175250","0","1"]],"bids":[],"ts":"1646003688617","checksum":-934845832}]}
1646003688.6471932: {"arg":{"channel":"books-l2-tbt","instId":"UNI-USD-SWAP"},"action":"update","data":[{"asks":[["9.623","343","0","2"]],"bids":[],"ts":"1646003688628","checksum":491225818}]}
1646003688.6621969: {"arg":{"channel":"books-l2-tbt","instId":"UNI-USD-SWAP"},"action":"update","data":[{"asks":[["9.633","30","0","1"],["9.671","0","0","0"],["49.358","1","0","1"]],"bids":[],"ts":"1646003688650","checksum":-1986770591}]}
1646003688.6725361: {"arg":{"channel":"books-l2-tbt","instId":"UNI-USD-SWAP"},"action":"update","data":[{"asks":[],"bids":[["9.608","359","0","3"]],"ts":"1646003688659","checksum":-269756994}]}
1646003688.677929: {"arg":{"channel":"books-l2-tbt","instId":"ZEN-USDT"},"action":"update","data":[{"asks":[["32.59","52.131348","0","2"]],"bids":[["32.45","18.106955","0","2"],["31.85","83.986754","0","1"]],"ts":"1646003688666","checksum":-1221598112}]}
1646003688.6812959: {"arg":{"channel":"books-l2-tbt","instId":"UNI-USD-SWAP"},"action":"update","data":[{"asks":[["9.659","1591","0","5"]],"bids":[["9.608","358","0","3"]],"ts":"1646003688669","checksum":276472054}]}
1646003688.69072: {"arg":{"channel":"books-l2-tbt","instId":"UNI-USD-SWAP"},"action":"update","data":[{"asks":[["9.657","40","0","1"],["49.358","0","0","0"]],"bids":[],"ts":"1646003688679","checksum":106835547}]}
1646003688.703525: {"arg":{"channel":"books-l2-tbt","instId":"ELON-USDT"},"action":"update","data":[{"asks":[],"bids":[["0.0000007433","65387086","0","1"]],"ts":"1646003688691","checksum":-1673004843}]}
1646003688.721956: {"arg":{"channel":"books-l2-tbt","instId":"ZEN-USDT"},"action":"update","data":[{"asks":[],"bids":[["32.38","128.93274","0","3"]],"ts":"1646003688709","checksum":-1784975950}]}
1646003688.722039: {"arg":{"channel":"books-l2-tbt","instId":"ELON-USDT"},"action":"update","data":[{"asks":[["0.00000074537","84609571","0","2"]],"bids":[],"ts":"1646003688711","checksum":1716058787}]}
1646003688.732619: {"arg":{"channel":"books-l2-tbt","instId":"UNI-USD-SWAP"},"action":"update","data":[{"asks":[["9.623","260","0","1"]],"bids":[],"ts":"1646003688721","checksum":-265307403}]}
1646003688.749104: {"arg":{"channel":"books-l2-tbt","instId":"UNI-USD-SWAP"},"action":"update","data":[{"asks":[["9.634","340","0","2"],["9.638","766","0","4"]],"bids":[],"ts":"1646003688731","checksum":-1799189190}]}
1646003688.749175: {"arg":{"channel":"books-l2-tbt","instId":"ELON-USDT"},"action":"update","data":[{"asks":[["0.00000074536","445226872","0","1"],["0.00000074537","188566182","0","3"],["0.00000113315","0","0","0"]],"bids":[],"ts":"1646003688737","checksum":1035680223}]}
1646003688.753681: {"arg":{"channel":"books-l2-tbt","instId":"UNI-USD-SWAP"},"action":"update","data":[{"asks":[["9.657","0","0","0"],["49.358","1","0","1"]],"bids":[],"ts":"1646003688742","checksum":591633118}]}
1646003688.760305: {"arg":{"channel":"books-l2-tbt","instId":"ZEN-USDT"},"action":"update","data":[{"asks":[],"bids":[["32.4","36.003828","0","1"]],"ts":"1646003688749","checksum":-1878388561}]}
1646003688.774122: {"arg":{"channel":"books-l2-tbt","instId":"ELON-USDT"},"action":"update","data":[{"asks":[["0.00000074537","84609571","0","2"]],"bids":[],"ts":"1646003688762","checksum":1606564976}]}
1646003688.785762: {"arg":{"channel":"books-l2-tbt","instId":"UNI-USD-SWAP"},"action":"update","data":[{"asks":[],"bids":[["9.615","75","0","2"],["9.614","471","0","3"],["9.61","0","0","0"],["9.609","500","0","1"],["9.606","0","0","0"]],"ts":"1646003688773","checksum":790187149}]}
1646003688.79119: {"arg":{"channel":"books-l2-tbt","instId":"ETH-USD-220325-8800-P"},"action":"update","data":[{"asks":[["2.5485","201","0","1"],["2.5495","0","0","0"]],"bids":[],"ts":"1646003688781","checksum":1047929945}]}
1646003688.795479: {"arg":{"channel":"books-l2-tbt","instId":"UNI-USD-SWAP"},"action":"update","data":[{"asks":[],"bids":[["9.576","33","0","1"]],"ts":"1646003688784","checksum":790187149}]}
1646003688.7955542: {"arg":{"channel":"books-l2-tbt","instId":"ELON-USDT"},"action":"update","data":[{"asks":[["0.00000074535","215609490","0","2"],["0.00000113256","0","0","0"]],"bids":[],"ts":"1646003688784","checksum":-2044033647}]}
1646003688.8085382: {"arg":{"channel":"books-l2-tbt","instId":"UNI-USD-SWAP"},"action":"update","data":[{"asks":[["9.671","16","0","1"],["49.358","0","0","0"]],"bids":[["9.617","260","0","1"],["9.612","0","0","0"]],"ts":"1646003688795","checksum":-1447335394}]}
1646003688.808671: {"arg":{"channel":"books-l2-tbt","instId":"PROPS-ETH"},"action":"update","data":[{"asks":[["0.00000176","8681.96931255","0","2"],["0.00000178","0","0","0"],["0.00000181","790.94256105","0","1"],["0.00000182","1041.50626966","0","1"],["0.00000185","670.65926513","0","1"],["0.00000187","0","0","0"]],"bids":[["0.00000161","0","0","0"],["0.0000016","11794.15091963","0","1"]],"ts":"1646003688796","checksum":76600830}]}
1646003688.817854: {"arg":{"channel":"books-l2-tbt","instId":"UNI-USD-SWAP"},"action":"update","data":[{"asks":[["9.659","1575","0","4"]],"bids":[],"ts":"1646003688806","checksum":810910601}]}
1646003688.8231301: {"arg":{"channel":"books-l2-tbt","instId":"ZEN-USDT"},"action":"update","data":[{"asks":[["32.8","2.338605","0","1"],["32.81","3.46","0","2"],["33.13","0","0","0"],["33.14","3.94","0","1"],["33.46","0","0","0"],["33.47","6.33","0","1"],["33.79","7.48","0","1"],["33.8","8.7","0","1"],["34.12","0","0","0"],["34.13","11.04","0","1"],["44.14","0","0","0"]],"bids":[["32.19","1.55","0","1"],["32.18","2.460396","0","2"]],"ts":"1646003688810","checksum":-10543479}]}
1646003688.823257: {"arg":{"channel":"books-l2-tbt","instId":"ELON-USDT"},"action":"update","data":[{"asks":[["0.00000074535","293937275","0","4"],["0.00000074537","16039225","0","1"]],"bids":[],"ts":"1646003688812","checksum":-284098599}]}
1646003688.8261719: {"arg":{"channel":"books-l2-tbt","instId":"UNI-USD-SWAP"},"action":"update","data":[{"asks":[["9.634","197","0","1"],["9.638","909","0","5"]],"bids":[["9.577","2349","0","2"],["9.567","0","0","0"]],"ts":"1646003688816","checksum":836710018}]}
1646003688.8317: {"arg":{"channel":"books-l2-tbt","instId":"ZEN-USDT"},"action":"update","data":[{"asks":[],"bids":[["32.41","0","0","0"]],"ts":"1646003688820","checksum":-1039869203}]}
1646003688.835876: {"arg":{"channel":"books-l2-tbt","instId":"ELON-USDT"},"action":"update","data":[{"asks":[["0.00000074535","330255747","0","5"],["0.00000074537","0","0","0"],["0.00000113256","10462875","0","1"]],"bids":[],"ts":"1646003688822","checksum":1373350876}]}
1646003688.8380978: {"arg":{"channel":"books-l2-tbt","instId":"UNI-USD-SWAP"},"action":"update","data":[{"asks":[["9.624","83","0","1"],["49.113","0","0","0"]],"bids":[],"ts":"1646003688826","checksum":1002538790}]}
1646003688.84354: {"arg":{"channel":"books-l2-tbt","instId":"ELON-USDT"},"action":"update","data":[{"asks":[["0.00000074538","0","0","0"],["0.00000113315","35900750","0","1"]],"bids":[],"ts":"1646003688833","checksum":427952589}]}
1646003688.8576179: {"arg":{"channel":"books-l2-tbt","instId":"UNI-USD-SWAP"},"action":"update","data":[{"asks":[["9.633","49","0","1"]],"bids":[["9.603","22","0","1"],["9.599","63","0","1"],["9.598","174","0","2"],["9.596","0","0","0"]],"ts":"1646003688846","checksum":2023995428}]}
1646003688.867131: {"arg":{"channel":"books-l2-tbt","instId":"ZEN-USDT"},"action":"update","data":[{"asks":[["32.51","2.862054","0","2"]],"bids":[["32.41","15.36651","0","1"]],"ts":"1646003688851","checksum":1637660897}]}
1646003688.877953: {"arg":{"channel":"books-l2-tbt","instId":"UNI-USD-SWAP"},"action":"update","data":[{"asks":[["9.63","2","0","1"],["9.633","30","0","1"],["48.868","0","0","0"]],"bids":[],"ts":"1646003688866","checksum":1238769084}]}
1646003688.887507: {"arg":{"channel":"books-l2-tbt","instId":"UNI-USD-SWAP"},"action":"update","data":[{"asks":[],"bids":[["9.615","76","0","3"]],"ts":"1646003688876","checksum":-1564925606}]}
1646003688.896908: {"arg":{"channel":"books-l2-tbt","instId":"UNI-USD-SWAP"},"action":"update","data":[{"asks":[["9.628","199","0","3"]],"bids":[],"ts":"1646003688885","checksum":-1591289760}]}
1646003688.907661: {"arg":{"channel":"books-l2-tbt","instId":"ETH-USD-220325-8800-P"},"action":"update","data":[{"asks":[["2.5485","0","0","0"],["2.549","201","0","1"]],"bids":[],"ts":"1646003688896","checksum":957925562}]}
1646003688.910673: {"arg":{"channel":"books-l2-tbt","instId":"UNI-USD-SWAP"},"action":"update","data":[{"asks":[["9.628","198","0","2"]],"bids":[["9.616","0","0","0"]],"ts":"1646003688896","checksum":-331941254}]}
1646003688.9188979: {"arg":{"channel":"books-l2-tbt","instId":"UNI-USD-SWAP"},"action":"update","data":[{"asks":[["9.649","64","0","1"]],"bids":[["9.617","0","0","0"],["9.576","0","0","0"],["9.575","579","0","2"]],"ts":"1646003688907","checksum":-1846509261}]}
1646003688.922208: {"arg":{"channel":"books-l2-tbt","instId":"ELON-USDT"},"action":"update","data":[{"asks":[["0.0000007475","0","0","0"],["0.0000011338","129154981","0","1"]],"bids":[["0.0000006993","0","0","0"],["0.00000068532","0","0","0"],["0.00000067162","0","0","0"],["0.00000065819","0","0","0"]],"ts":"1646003688909","checksum":-1600423569}]}
1646003688.927847: {"arg":{"channel":"books-l2-tbt","instId":"UNI-USD-SWAP"},"action":"update","data":[{"asks":[["9.627","0","0","0"],["9.629","132","0","2"],["48.868","1","0","1"]],"bids":[],"ts":"1646003688917","checksum":-944474566}]}
1646003688.9320729: {"arg":{"channel":"books-l2-tbt","instId":"ELON-USDT"},"action":"update","data":[{"asks":[],"bids":[["0.00000064475","380643089","0","1"]],"ts":"1646003688920","checksum":-1600423569}]}
1646003688.940185: {"arg":{"channel":"books-l2-tbt","instId":"UNI-USD-SWAP"},"action":"update","data":[{"asks":[["9.624","0","0","0"],["9.63","0","0","0"],["9.671","0","0","0"],["49.113","1","0","1"],["49.358","1","0","1"],["49.605","1","0","1"]],"bids":[["9.615","23","0","2"]],"ts":"1646003688928","checksum":-1064962757}]}
1646003688.940712: {"arg":{"channel":"books-l2-tbt","instId":"ELON-USDT"},"action":"update","data":[{"asks":[["0.00000074535","274314809","0","5"]],"bids":[],"ts":"1646003688931","checksum":1095169648}]}
1646003688.950838: {"arg":{"channel":"books-l2-tbt","instId":"UNI-USD-SWAP"},"action":"update","data":[{"asks":[["9.659","1591","0","5"]],"bids":[["9.612","2","0","1"],["9.579","85","0","2"]],"ts":"1646003688937","checksum":-1670340612}]}
1646003688.950925: {"arg":{"channel":"books-l2-tbt","instId":"ZEN-USDT"},"action":"update","data":[{"asks":[["32.51","1.969196","0","1"]],"bids":[],"ts":"1646003688937","checksum":-10543479}]}
1646003688.960822: {"arg":{"channel":"books-l2-tbt","instId":"UNI-USD-SWAP"},"action":"update","data":[{"asks":[["9.627","2","0","1"],["49.605","0","0","0"]],"bids":[],"ts":"1646003688949","checksum":2064165481}]}
1646003688.9706728: {"arg":{"channel":"books-l2-tbt","instId":"UNI-USD-SWAP"},"action":"update","data":[{"asks":[["9.653","35","0","1"],["49.358","0","0","0"]],"bids":[],"ts":"1646003688959","checksum":1947795493}]}
1646003688.9795818: {"arg":{"channel":"books-l2-tbt","instId":"ZEN-USDT"},"action":"update","data":[{"asks":[["32.5","0","0","0"],["44.14","0.039111","0","2"]],"bids":[],"ts":"1646003688968","checksum":790393489}]}
1646003688.990109: {"arg":{"channel":"books-l2-tbt","instId":"UNI-USD-SWAP"},"action":"update","data":[{"asks":[],"bids":[["9.613","53","0","1"]],"ts":"1646003688978","checksum":-940612483}]}
1646003689.000832: {"arg":{"channel":"books-l2-tbt","instId":"ZEN-USDT"},"action":"update","data":[{"asks":[],"bids":[["32.42","34.507971","0","2"]],"ts":"1646003688989","checksum":-1265723845}]}
1646003689.000949: {"arg":{"channel":"books-l2-tbt","instId":"UNI-USD-SWAP"},"action":"update","data":[{"asks":[],"bids":[["9.612","0","0","0"]],"ts":"1646003688990","checksum":2000164106}]}
1646003689.00607: {"arg":{"channel":"books-l2-tbt","instId":"BTC-USD-220325-40000-C"},"action":"update","data":[{"asks":[["0.0535","300","0","1"],["0.054","0","0","0"]],"bids":[],"ts":"1646003688996","checksum":-1840363265}]}
1646003689.021867: {"arg":{"channel":"books-l2-tbt","instId":"ZEN-USDT"},"action":"update","data":[{"asks":[["32.49","0","0","0"],["44.2","0.120899","0","1"]],"bids":[],"ts":"1646003689010","checksum":837072032}]}
1646003689.0239182: {"arg":{"channel":"books-l2-tbt","instId":"ELON-USDT"},"action":"update","data":[{"asks":[],"bids":[["0.00000074381","29759661","0","1"]],"ts":"1646003689012","checksum":-800733319}]}
1646003689.026048: {"arg":{"channel":"books-l2-tbt","instId":"BTC-USD-220325-40000-C"},"action":"update","data":[{"asks":[["0.054","100","0","1"],["0.0545","0","0","0"]],"bids":[],"ts":"1646003689016","checksum":-561915348}]}
1646003689.035043: {"arg":{"channel":"books-l2-tbt","instId":"ELON-USDT"},"action":"update","data":[{"asks":[["0.00000074534","445226872","0","1"],["0.00000074535","358924380","0","7"],["0.0000011338","0","0","0"]],"bids":[],"ts":"1646003689023","checksum":1584673734}]}
1646003689.047912: {"arg":{"channel":"books-l2-tbt","instId":"UNI-USD-SWAP"},"action":"update","data":[{"asks":[["9.623","343","0","2"]],"bids":[],"ts":"1646003689032","checksum":-1327618751}]}
