1625342241.988539: {"book":{"asks":[[329915000,1559],[329970000,2184],[330005000,1713],[330010000,5483],[330075000,490],[330095000,5422],[330260000,4186],[330265000,578],[330305000,420],[330365000,3073],[330370000,4613],[330395000,250],[330400000,100],[330490000,2175],[330495000,4717],[330505000,650],[330510000,200],[330525000,1072],[330565000,3570],[330570000,1706],[330650000,3379],[330735000,10670],[330755000,7128],[331630000,2976],[331685000,2402],[331715000,4986],[331820000,3385],[331835000,2999],[331875000,3180],[331910000,3171]],"bids":[[329360000,5488],[329105000,848],[329090000,1054],[329085000,1761],[329065000,1059],[329060000,924],[329045000,49],[328970000,1278],[328965000,70],[328765000,895],[328760000,550],[328755000,460],[328745000,320],[328640000,32],[328605000,22445],[328565000,17839],[328505000,1556],[328500000,1310],[328495000,3480],[328470000,572],[328410000,902],[328305000,6379],[328300000,3620],[328290000,3006],[328265000,4022],[328235000,264],[328230000,610],[328190000,7239],[328130000,4474],[328095000,4446]]},"depth":30,"sequence":17652788219,"symbol":"YFIUSD","timestamp":1625342241094406504,"type":"snapshot"}
1625342241.98912: {"book":{"asks":[[2152300,6982],[2152400,7143],[2152700,6479],[2152900,2414],[2153200,29],[2153300,2286],[2153400,960],[2153500,2750],[2153600,41123],[2153700,3020],[2153800,35610],[2154400,1380],[2154600,11925],[2154800,6506],[2154900,778],[2155000,10523],[2155100,21255],[2155300,10462],[2155500,9227],[2155600,9647],[2155800,12064],[2155900,2850],[2156000,1180],[2156100,2832],[2156500,2540],[2156800,1010],[2157000,2090],[2157200,648],[2157300,3230],[2157900,501]],"bids":[[2152100,553],[2152000,2089],[2151700,315],[2151500,2130],[2151300,5374],[2151000,6484],[2150800,3267],[2150700,5536],[2150400,38353],[2150000,550],[2149900,870],[2149400,1000],[2149100,950],[2148900,910],[2148700,41036],[2148300,4729],[2147800,6460],[2147700,910],[2147600,1840],[2147300,2198],[2147200,16459],[2146800,9816],[2146300,709],[2145900,8558],[2145800,6800],[2145600,14532],[2145500,10339],[2145300,9711],[2145200,530],[2145000,1400]]},"depth":30,"sequence":4899654006,"symbol":"XMRUSD","timestamp":1625342239960166371,"type":"snapshot"}
1625342241.989536: {"book":{"asks":[[11368,1073],[11372,3000],[11377,6059],[11378,4778],[11379,13798],[11380,4894],[11381,6594],[11382,12686],[11383,1130],[11384,3535],[11385,7538],[11386,6115],[11387,999],[11390,2247],[11391,3200],[11392,3722],[11395,1494],[11396,2306],[11397,4629],[11398,3700],[11399,2954],[11400,1020],[11403,528],[11416,2594],[11417,6171],[11419,2247],[11420,4512],[11421,1620],[11422,2810],[11423,6492]],"bids":[[11355,200],[11354,12934],[11353,13071],[11352,11976],[11351,1843],[11350,6376],[11349,1000],[11346,2077],[11345,750],[11344,6572],[11343,6607],[11342,3911],[11341,2890],[11340,1900],[11339,3003],[11338,400],[11336,3782],[11335,2305],[11333,2230],[11332,304],[11331,1734],[11329,1850],[11328,820],[11327,2671],[11326,253],[11325,1368],[11324,1962],[11323,4649],[11322,5421],[11321,990]]},"depth":30,"sequence":8450966714,"symbol":"ENJUSD","timestamp":1625342240889669143,"type":"snapshot"}
1625342242.000892: {"book":{"asks":[[67556000,512445000000],[67562000,269673000000],[67567000,247298000000],[67568000,402848000000],[67570000,212008000000],[67595000,303821000000],[67613000,291415000000],[67614000,406389000000],[67620000,447806000000],[67656000,234027000000],[67671000,383049000000],[67674000,427147000000],[67678000,381832000000],[67680000,335711000000],[67719000,459633000000],[67735000,222536000000],[67736000,264819000000],[67744000,389449000000],[67751000,562075000000],[67807000,242008000000],[67814000,767632000000],[67858000,381343000000],[67865000,261923000000],[67879000,799687000000],[67887000,512980000000],[67907000,680712000000],[67908000,425434000000],[67914000,725483000000],[67919000,267634000000],[67921000,511683000000]],"bids":[[67283000,255123000000],[67269000,986905000000],[67265000,433130000000],[67257000,228440000000],[67217000,270575000000],[67212000,411207000000],[67211000,227721000000],[67197000,432819000000],[67189000,321974000000],[67188000,346685000000],[67180000,270099000000],[67161000,454280000000],[67160000,220449000000],[67155000,394846000000],[67115000,637528000000],[67104000,2505000000],[67073000,411358000000],[67055000,404888000000],[67029000,714632000000],[67014000,711193000000],[67013000,767404000000],[67010000,471201000000],[67006000,680295000000],[66996000,632530000000],[66992000,749842000000],[66985000,262500000000],[66984000,263183000000],[66982000,347658000000],[66950000,710037000000],[66936000,568938000000]]},"depth":30,"sequence":175932827,"symbol":"sGRTUSDT","timestamp":1625342241838773027,"type":"snapshot"}
1625342242.014774: {"book":{"asks":[[769100000,13572800000],[769500000,29853300000],[770200000,29785500000],[770700000,34692300000],[771400000,26218800000],[771700000,22985500000],[772100000,31605500000],[772500000,22533700000],[773000000,30261000000],[773500000,22422600000],[778200000,20058600000],[778400000,23514700000],[778600000,24778100000],[779000000,31044600000],[779100000,58362900000],[779700000,29363900000],[779800000,27912400000],[779900000,19075400000],[781600000,30148700000],[789200000,68961500000],[791900000,50237400000],[792100000,65702800000],[792200000,57686800000],[792700000,61295300000],[792800000,45304300000],[794000000,52539100000],[794100000,32121000000],[794300000,49398800000],[794400000,50194800000],[794700000,48735900000]],"bids":[[761500000,6995300000],[761200000,32249800000],[759700000,12394600000],[759200000,31023100000],[757000000,15958800000],[756900000,57187400000],[756700000,22984800000],[756600000,20801400000],[756500000,26424500000],[755800000,23256300000],[752600000,29352100000],[751200000,25829300000],[750800000,23376400000],[750300000,36418900000],[748500000,35910600000],[748100000,21078100000],[747300000,32705200000],[747100000,32913000000],[747000000,1341900000],[746900000,21296700000],[745900000,31453800000],[736400000,47849100000],[736200000,67409600000],[736000000,64502500000],[735900000,45586900000],[735600000,69127400000],[735400000,74153100000],[735000000,61346900000],[734900000,62433800000],[734600000,73525200000]]},"depth":30,"sequence":146074874,"symbol":"sSUSHIUSDT","timestamp":1625342240961251507,"type":"snapshot"}
1625342242.066912: {"book":{"asks":[[113913000,383684000000],[113923000,387293000000],[113930000,290686000000],[113940000,237524000000],[113944000,342038000000],[113964000,365390000000],[113969000,449215000000],[113973000,322750000000],[114031000,265536000000],[114035000,213403000000],[114041000,235305000000],[114065000,266914000000],[114074000,433381000000],[114083000,224094000000],[114106000,413844000000],[114108000,384027000000],[114113000,258938000000],[114144000,396623000000],[114266000,4806000000],[114267000,751593000000],[114275000,416276000000],[114285000,447576000000],[114286000,434519000000],[114288000,294000000000],[114307000,523548000000],[114309000,433371000000],[114310000,576546000000],[114311000,491169000000],[114315000,731622000000],[114316000,690253000000]],"bids":[[113466000,388707000000],[113465000,472825000000],[113446000,542690000000],[113423000,416575000000],[113414000,202946000000],[113413000,367623000000],[113410000,445312000000],[113395000,363143000000],[113388000,383190000000],[113293000,224797000000],[113286000,204857000000],[113247000,345204000000],[113239000,377990000000],[113219000,407208000000],[113210000,301056000000],[113208000,289326000000],[113198000,206872000000],[113188000,347851000000],[113174000,454611000000],[113088000,449681000000],[113079000,797419000000],[113035000,572634000000],[113020000,737798000000],[113019000,463112000000],[113018000,596074000000],[113016000,463118000000],[113014000,646969000000],[113009000,713527000000],[113003000,675107000000],[113002000,709267000000]]},"depth":30,"sequence":146074872,"symbol":"sENJUSDT","timestamp":1625342239170070557,"type":"snapshot"}
1625342242.0671859: {"book":{"asks":[[30080,233],[30090,4352],[30100,79859],[30110,103747],[30120,190210],[30130,3147],[30140,1988],[30150,63563],[30160,30708],[30170,42707],[30180,1345],[30190,2739],[30200,17998],[30210,20070],[30220,38957],[30230,1961],[30240,835],[30250,2752],[30260,81],[30270,3231],[30280,11078],[30290,16286],[30300,1565],[30310,1102],[30320,9652],[30330,23789],[30340,18512],[30350,4230],[30360,23029],[30370,8626]],"bids":[[30070,57317],[30060,76218],[30050,103914],[30040,2871],[30030,105329],[30020,1069],[30010,21580],[30000,36648],[29990,57709],[29980,524],[29970,17387],[29960,3840],[29950,25035],[29940,24321],[29930,1893],[29920,2071],[29910,3428],[29900,8453],[29890,2418],[29880,2698],[29870,19181],[29860,354],[29850,9557],[29840,20998],[29830,19549],[29820,1592],[29810,751],[29800,12659],[29790,2153],[29780,16417]]},"depth":30,"sequence":4899654225,"symbol":"XTZUSD","timestamp":1625342241462123457,"type":"snapshot"}
1625342242.067595: {"book":{"asks":[[50819000000,1339593000],[50820000000,1452301000],[50825000000,1476320000],[50826000000,1251710000],[50829000000,1073267000],[50831000000,802700000],[50835000000,1215310000],[50840000000,1389960000],[50846000000,1070199000],[50855000000,1157803000],[50918000000,3008490000],[50922000000,2313826000],[50923000000,1057238000],[50926000000,1849262000],[50931000000,6007000],[50932000000,1371509000],[50934000000,1557337000],[50938000000,1837880000],[50941000000,1847809000],[50945000000,2309025000],[50951000000,913230000],[50981000000,1127500000],[51022000000,396450000],[51024000000,1930614000],[51035000000,1053444000],[51044000000,1219103000],[51051000000,411500000],[51069000000,1162428000],[51078000000,1016066000],[51079000000,1257542000]],"bids":[[50632000000,1068353000],[50628000000,1054496000],[50625000000,1256867000],[50623000000,1288087000],[50616000000,1419399000],[50615000000,1924327000],[50612000000,1823031000],[50584000000,1039596000],[50536000000,2853452000],[50531000000,1899281000],[50522000000,1037598000],[50521000000,97492000],[50519000000,891568000],[50511000000,2673632000],[50510000000,1348496000],[50507000000,971902000],[50500000000,2540354000],[50462000000,1308850000],[50450000000,1440002000],[50449000000,1074631000],[50440000000,1174174000],[50435000000,860425000],[50434000000,1664463000],[50428000000,1580622000],[50424000000,2451092000],[50423000000,1032608000],[50421000000,2149828000],[50420000000,1001223000],[50409000000,1893609000],[50406000000,1452184000]]},"depth":30,"sequence":14221227840,"symbol":"sBCHUSDT","timestamp":1625342241462245028,"type":"snapshot"}
1625342242.067808: {"book":{"asks":[[119380,2227],[119390,2784],[119400,5532],[119410,1500],[119420,3999],[119430,3072],[119450,1523],[119460,5538],[119470,9753],[119480,1440],[119490,1400],[119500,11262],[119530,1330],[119540,7741],[119550,1434],[119560,6578],[119570,3783],[119580,1100],[119590,4614],[119610,5724],[119630,3473],[119640,2650],[119670,931],[119680,1748],[119690,6886],[119700,3826],[119710,3090],[119720,2920],[119730,430],[119740,3688]],"bids":[[119110,1149],[119100,1023],[119090,1826],[119070,3647],[119060,422],[119050,3599],[119010,3742],[119000,660],[118990,1308],[118980,7025],[118960,1123],[118950,8740],[118940,5703],[118930,3394],[118910,7796],[118900,1584],[118890,5687],[118880,3783],[118850,933],[118840,290],[118830,7515],[118810,7205],[118800,1808],[118790,1678],[118770,350],[118760,670],[118740,6071],[118730,1975],[118720,3056],[118710,1530]]},"depth":30,"sequence":6643004530,"symbol":"ATOMUSD","timestamp":1625342241712164862,"type":"snapshot"}
1625342242.068196: {"book":{"asks":[[1874570000,140009000000],[1874590000,55213000000],[1875150000,71598000000],[1875400000,115308000000],[1875420000,96742000000],[1875460000,80973000000],[1875560000,72887000000],[1875700000,110457000000],[1875770000,93857000000],[1876640000,72508000000],[1876800000,59901000000],[1877050000,109643000000],[1877720000,54192000000],[1878260000,203000000],[1878270000,137421000000],[1878770000,87083000000],[1878800000,52137000000],[1878860000,77208000000],[1879540000,61113000000],[1879790000,72356000000],[1880310000,79716000000],[1880370000,117035000000],[1880550000,40509000000],[1880650000,90185000000],[1880820000,67656000000],[1881140000,66751000000],[1881220000,77739000000],[1881820000,89526000000],[1882160000,66644000000],[1882240000,42844000000]],"bids":[[1870220000,140808000000],[1870020000,111703000000],[1869510000,143998000000],[1869420000,57877000000],[1869110000,109351000000],[1869030000,85677000000],[1868740000,126031000000],[1868700000,116788000000],[1868620000,118664000000],[1865350000,71128000000],[1865230000,58038000000],[1865220000,50249000000],[1865150000,60900000000],[1865130000,70196000000],[1865090000,66012000000],[1865060000,108899000000],[1864960000,45299000000],[1864830000,50400000000],[1864430000,57236000000],[1864300000,70846000000],[1864240000,51480000000],[1864150000,89843000000],[1864080000,64499000000],[1864070000,50300000000],[1863970000,42630000000],[1863860000,55594000000],[1863740000,41753000000],[1863720000,66433000000],[1863470000,94647000000],[1863160000,72981000000]]},"depth":30,"sequence":20149233826,"symbol":"sLINKUSDT","timestamp":1625342241643835205,"type":"snapshot"}
1625342242.397467: {"book":{"asks":[[30170,42007]],"bids":[]},"depth":30,"sequence":4899654234,"symbol":"XTZUSD","timestamp":1625342241732802237,"type":"incremental"}
1625342242.397509: {"book":{"asks":[],"bids":[[30020,2300]]},"depth":30,"sequence":4899654235,"symbol":"XTZUSD","timestamp":1625342241747689927,"type":"incremental"}
1625342242.397532: {"book":{"asks":[],"bids":[[29930,2873]]},"depth":30,"sequence":4899654236,"symbol":"XTZUSD","timestamp":1625342241747731997,"type":"incremental"}
1625342242.397552: {"book":{"asks":[],"bids":[[67182000,452276000000],[66936000,0]]},"depth":30,"sequence":175932828,"symbol":"sGRTUSDT","timestamp":1625342241840459601,"type":"incremental"}
1625342242.397589: {"book":{"asks":[],"bids":[[67173000,437619000000],[66950000,0]]},"depth":30,"sequence":175932829,"symbol":"sGRTUSDT","timestamp":1625342241840506950,"type":"incremental"}
1625342242.3976152: {"book":{"asks":[],"bids":[[2148900,5639],[2148300,0],[2144300,820]]},"depth":30,"sequence":4899654237,"symbol":"XMRUSD","timestamp":1625342241946398302,"type":"incremental"}
1625342242.581447: {"book":{"asks":[[30190,30]],"bids":[]},"depth":30,"sequence":4899654346,"symbol":"XTZUSD","timestamp":1625342242371258681,"type":"incremental"}
1625342242.5821068: {"book":{"asks":[],"bids":[[29860,2254]]},"depth":30,"sequence":4899654347,"symbol":"XTZUSD","timestamp":1625342242371301035,"type":"incremental"}
1625342242.5821729: {"book":{"asks":[[30090,0],[30390,3321]],"bids":[]},"depth":30,"sequence":4899654348,"symbol":"XTZUSD","timestamp":1625342242424372412,"type":"incremental"}
1625342242.582243: {"book":{"asks":[[30080,0],[30400,12518]],"bids":[]},"depth":30,"sequence":4899654349,"symbol":"XTZUSD","timestamp":1625342242425761046,"type":"incremental"}
1625342242.582295: {"book":{"asks":[],"bids":[[29930,3023]]},"depth":30,"sequence":4899654350,"symbol":"XTZUSD","timestamp":1625342242430413495,"type":"incremental"}
1625342242.767031: {"book":{"asks":[[2153500,1680]],"bids":[]},"depth":30,"sequence":4899654351,"symbol":"XMRUSD","timestamp":1625342242477448614,"type":"incremental"}
1625342242.767122: {"book":{"asks":[[2152300,7472]],"bids":[]},"depth":30,"sequence":4899654352,"symbol":"XMRUSD","timestamp":1625342242477498963,"type":"incremental"}
1625342242.767162: {"book":{"asks":[[30220,38722]],"bids":[]},"depth":30,"sequence":4899654353,"symbol":"XTZUSD","timestamp":1625342242624672497,"type":"incremental"}
1625342242.767196: {"book":{"asks":[[30220,38422]],"bids":[]},"depth":30,"sequence":4899654354,"symbol":"XTZUSD","timestamp":1625342242624712452,"type":"incremental"}
1625342242.892805: {"book":{"asks":[[119380,2439]],"bids":[]},"depth":30,"sequence":6643004700,"symbol":"ATOMUSD","timestamp":1625342242712332383,"type":"incremental"}
1625342242.95237: {"book":{"asks":[[30220,38522]],"bids":[]},"depth":30,"sequence":4899654355,"symbol":"XTZUSD","timestamp":1625342242624726545,"type":"incremental"}
1625342242.9524622: {"book":{"asks":[[30250,1552]],"bids":[]},"depth":30,"sequence":4899654356,"symbol":"XTZUSD","timestamp":1625342242624738511,"type":"incremental"}
1625342243.158795: {"book":{"asks":[[67522000,421239000000],[67921000,0]],"bids":[]},"depth":30,"sequence":175932836,"symbol":"sGRTUSDT","timestamp":1625342242888344646,"type":"incremental"}
1625342243.159538: {"book":{"asks":[[67614000,0],[67921000,511683000000]],"bids":[]},"depth":30,"sequence":175932837,"symbol":"sGRTUSDT","timestamp":1625342242888831633,"type":"incremental"}
1625342243.339087: {"book":{"asks":[],"bids":[[67104000,0],[66950000,710037000000]]},"depth":30,"sequence":175932838,"symbol":"sGRTUSDT","timestamp":1625342243094629889,"type":"incremental"}
1625342243.403906: {"book":{"asks":[[119480,1951]],"bids":[]},"depth":30,"sequence":6643004706,"symbol":"ATOMUSD","timestamp":1625342243065228324,"type":"incremental"}
1625342243.519818: {"book":{"asks":[],"bids":[[67116000,2504000000],[66950000,0]]},"depth":30,"sequence":175932839,"symbol":"sGRTUSDT","timestamp":1625342243335525001,"type":"incremental"}
1625342243.534996: {"book":{"asks":[[30140,2168]],"bids":[]},"depth":30,"sequence":4899654357,"symbol":"XTZUSD","timestamp":1625342243088949994,"type":"incremental"}
1625342243.535125: {"book":{"asks":[[30110,103707]],"bids":[]},"depth":30,"sequence":4899654359,"symbol":"XTZUSD","timestamp":1625342243392617366,"type":"incremental"}
1625342243.53519: {"book":{"asks":[[30110,102375]],"bids":[]},"depth":30,"sequence":4899654360,"symbol":"XTZUSD","timestamp":1625342243392664304,"type":"incremental"}
1625342243.53524: {"book":{"asks":[[30100,80859]],"bids":[]},"depth":30,"sequence":4899654361,"symbol":"XTZUSD","timestamp":1625342243392686509,"type":"incremental"}
1625342243.718552: {"book":{"asks":[[30090,4352],[30400,0]],"bids":[]},"depth":30,"sequence":4899654362,"symbol":"XTZUSD","timestamp":1625342243448864942,"type":"incremental"}
1625342244.0716538: {"book":{"asks":[[30170,42279]],"bids":[]},"depth":30,"sequence":4899654365,"symbol":"XTZUSD","timestamp":1625342243800947956,"type":"incremental"}
1625342244.071724: {"book":{"asks":[[30350,2400]],"bids":[]},"depth":30,"sequence":4899654366,"symbol":"XTZUSD","timestamp":1625342243919886307,"type":"incremental"}
1625342244.071753: {"book":{"asks":[[30290,16446]],"bids":[]},"depth":30,"sequence":4899654367,"symbol":"XTZUSD","timestamp":1625342243919929368,"type":"incremental"}
1625342244.071775: {"book":{"asks":[[30100,79859]],"bids":[]},"depth":30,"sequence":4899654368,"symbol":"XTZUSD","timestamp":1625342243919944101,"type":"incremental"}
1625342244.071796: {"book":{"asks":[[30100,79599]],"bids":[]},"depth":30,"sequence":4899654369,"symbol":"XTZUSD","timestamp":1625342243919963309,"type":"incremental"}
1625342244.237236: {"book":{"asks":[[769100000,13404600000]],"bids":[]},"depth":30,"sequence":146074875,"symbol":"sSUSHIUSDT","timestamp":1625342244127840967,"type":"incremental"}
1625342244.457431: {"book":{"asks":[[30220,38972]],"bids":[]},"depth":30,"sequence":4899654465,"symbol":"XTZUSD","timestamp":1625342244271213365,"type":"incremental"}
1625342244.4575622: {"book":{"asks":[[30100,79999]],"bids":[]},"depth":30,"sequence":4899654466,"symbol":"XTZUSD","timestamp":1625342244271275365,"type":"incremental"}
1625342244.641093: {"book":{"asks":[[30100,81511]],"bids":[]},"depth":30,"sequence":4899654469,"symbol":"XTZUSD","timestamp":1625342244444800668,"type":"incremental"}
1625342244.6422951: {"book":{"asks":[],"bids":[[30070,57167]]},"depth":30,"sequence":4899654470,"symbol":"XTZUSD","timestamp":1625342244444842442,"type":"incremental"}
1625342244.642426: {"book":{"asks":[],"bids":[[30070,56125]]},"depth":30,"sequence":4899654471,"symbol":"XTZUSD","timestamp":1625342244444855470,"type":"incremental"}
1625342244.642487: {"book":{"asks":[],"bids":[[30070,55605]]},"depth":30,"sequence":4899654472,"symbol":"XTZUSD","timestamp":1625342244444870821,"type":"incremental"}
1625342244.642536: {"book":{"asks":[[30100,79999]],"bids":[]},"depth":30,"sequence":4899654473,"symbol":"XTZUSD","timestamp":1625342244444889378,"type":"incremental"}
1625342244.650816: {"book":{"asks":[],"bids":[[1869510000,0],[1862990000,48363000000]]},"depth":30,"sequence":20149234117,"symbol":"sLINKUSDT","timestamp":1625342244541927045,"type":"incremental"}
1625342244.674377: {"book":{"asks":[],"bids":[[1868840000,118649000000],[1862990000,0]]},"depth":30,"sequence":20149234118,"symbol":"sLINKUSDT","timestamp":1625342244541963293,"type":"incremental"}
1625342244.674528: {"book":{"asks":[],"bids":[[1864060000,73670000000],[1863160000,0]]},"depth":30,"sequence":20149234119,"symbol":"sLINKUSDT","timestamp":1625342244542030692,"type":"incremental"}
1625342244.737453: {"book":{"asks":[[329970000,2151]],"bids":[]},"depth":30,"sequence":17652788961,"symbol":"YFIUSD","timestamp":1625342244625014611,"type":"incremental"}
1625342244.739914: {"book":{"asks":[[329970000,1170]],"bids":[]},"depth":30,"sequence":17652788962,"symbol":"YFIUSD","timestamp":1625342244625058975,"type":"incremental"}
1625342244.741765: {"book":{"asks":[[330095000,4376]],"bids":[]},"depth":30,"sequence":17652788963,"symbol":"YFIUSD","timestamp":1625342244625073999,"type":"incremental"}
1625342244.741853: {"book":{"asks":[[330095000,1476]],"bids":[]},"depth":30,"sequence":17652788964,"symbol":"YFIUSD","timestamp":1625342244625094811,"type":"incremental"}
1625342244.7418911: {"book":{"asks":[[330095000,0],[331920000,3577]],"bids":[]},"depth":30,"sequence":17652788965,"symbol":"YFIUSD","timestamp":1625342244625114332,"type":"incremental"}
1625342244.741945: {"book":{"asks":[[330295000,6242],[331920000,0]],"bids":[]},"depth":30,"sequence":17652788966,"symbol":"YFIUSD","timestamp":1625342244625126518,"type":"incremental"}
1625342244.7419899: {"book":{"asks":[[330650000,6897]],"bids":[]},"depth":30,"sequence":17652788967,"symbol":"YFIUSD","timestamp":1625342244625139507,"type":"incremental"}
1625342244.742017: {"book":{"asks":[[330735000,10453]],"bids":[]},"depth":30,"sequence":17652788968,"symbol":"YFIUSD","timestamp":1625342244625151570,"type":"incremental"}
1625342244.742042: {"book":{"asks":[[330735000,8113]],"bids":[]},"depth":30,"sequence":17652788969,"symbol":"YFIUSD","timestamp":1625342244625165237,"type":"incremental"}
1625342244.742066: {"book":{"asks":[[331685000,5988]],"bids":[]},"depth":30,"sequence":17652788970,"symbol":"YFIUSD","timestamp":1625342244625177873,"type":"incremental"}
1625342244.742089: {"book":{"asks":[[329915000,779]],"bids":[]},"depth":30,"sequence":17652788982,"symbol":"YFIUSD","timestamp":1625342244625382977,"type":"incremental"}
1625342244.742112: {"book":{"asks":[[330010000,1479]],"bids":[]},"depth":30,"sequence":17652788983,"symbol":"YFIUSD","timestamp":1625342244625615457,"type":"incremental"}
1625342244.742134: {"book":{"asks":[[330010000,0],[331920000,3577]],"bids":[]},"depth":30,"sequence":17652788984,"symbol":"YFIUSD","timestamp":1625342244625638212,"type":"incremental"}
1625342244.7421691: {"book":{"asks":[[330095000,1028],[331920000,0]],"bids":[]},"depth":30,"sequence":17652788985,"symbol":"YFIUSD","timestamp":1625342244625659828,"type":"incremental"}
1625342244.742207: {"book":{"asks":[[330735000,11395]],"bids":[]},"depth":30,"sequence":17652788986,"symbol":"YFIUSD","timestamp":1625342244625681613,"type":"incremental"}
1625342244.773777: {"book":{"asks":[[330755000,1841]],"bids":[]},"depth":30,"sequence":17652788987,"symbol":"YFIUSD","timestamp":1625342244625698736,"type":"incremental"}
1625342244.7744498: {"book":{"asks":[[329915000,0],[331920000,3577]],"bids":[]},"depth":30,"sequence":17652789154,"symbol":"YFIUSD","timestamp":1625342244635525071,"type":"incremental"}
1625342244.774538: {"book":{"asks":[[329970000,0],[331975000,3557]],"bids":[]},"depth":30,"sequence":17652789155,"symbol":"YFIUSD","timestamp":1625342244635633041,"type":"incremental"}
1625342244.827127: {"book":{"asks":[[67522000,357239000000]],"bids":[]},"depth":30,"sequence":175932842,"symbol":"sGRTUSDT","timestamp":1625342244579310618,"type":"incremental"}
1625342244.942813: {"book":{"asks":[[1875760000,148696000000],[1882240000,0]],"bids":[]},"depth":30,"sequence":20149234555,"symbol":"sLINKUSDT","timestamp":1625342244720804546,"type":"incremental"}
1625342244.943669: {"book":{"asks":[[1880010000,86444000000],[1882160000,0]],"bids":[]},"depth":30,"sequence":20149234556,"symbol":"sLINKUSDT","timestamp":1625342244720863616,"type":"incremental"}
1625342244.943778: {"book":{"asks":[[1880370000,0],[1882160000,66644000000]],"bids":[]},"depth":30,"sequence":20149234557,"symbol":"sLINKUSDT","timestamp":1625342244720880195,"type":"incremental"}
1625342245.040098: {"book":{"asks":[[30100,80139]],"bids":[]},"depth":30,"sequence":4899654475,"symbol":"XTZUSD","timestamp":1625342244899937243,"type":"incremental"}
1625342245.0442922: {"book":{"asks":[],"bids":[[67283000,0],[66950000,710037000000]]},"depth":30,"sequence":175932843,"symbol":"sGRTUSDT","timestamp":1625342244935240857,"type":"incremental"}
1625342245.187713: {"book":{"asks":[],"bids":[[11351,1533]]},"depth":30,"sequence":8450968561,"symbol":"ENJUSD","timestamp":1625342245045959069,"type":"incremental"}
1625342245.225312: {"book":{"asks":[[30180,800]],"bids":[]},"depth":30,"sequence":4899654477,"symbol":"XTZUSD","timestamp":1625342244950576581,"type":"incremental"}
1625342245.225441: {"book":{"asks":[[30180,506]],"bids":[]},"depth":30,"sequence":4899654478,"symbol":"XTZUSD","timestamp":1625342244950619842,"type":"incremental"}
1625342245.225504: {"book":{"asks":[],"bids":[[30060,76283]]},"depth":30,"sequence":4899654479,"symbol":"XTZUSD","timestamp":1625342244950641773,"type":"incremental"}
1625342245.225557: {"book":{"asks":[[30080,235],[30390,0]],"bids":[]},"depth":30,"sequence":4899654480,"symbol":"XTZUSD","timestamp":1625342244956355577,"type":"incremental"}
1625342245.225653: {"book":{"asks":[[30120,186615]],"bids":[]},"depth":30,"sequence":4899654481,"symbol":"XTZUSD","timestamp":1625342244969004279,"type":"incremental"}
1625342245.225683: {"book":{"asks":[],"bids":[[30030,101734]]},"depth":30,"sequence":4899654482,"symbol":"XTZUSD","timestamp":1625342244970592929,"type":"incremental"}
1625342245.225711: {"book":{"asks":[[30090,0],[30390,3321]],"bids":[]},"depth":30,"sequence":4899654483,"symbol":"XTZUSD","timestamp":1625342245006778282,"type":"incremental"}
1625342245.225756: {"book":{"asks":[[30080,0],[30400,12518]],"bids":[]},"depth":30,"sequence":4899654484,"symbol":"XTZUSD","timestamp":1625342245019178777,"type":"incremental"}
1625342245.2257988: {"book":{"asks":[[30090,4352],[30400,0]],"bids":[]},"depth":30,"sequence":4899654485,"symbol":"XTZUSD","timestamp":1625342245074356719,"type":"incremental"}
1625342245.36035: {"book":{"asks":[],"bids":[[11351,673]]},"depth":30,"sequence":8450968562,"symbol":"ENJUSD","timestamp":1625342245046074156,"type":"incremental"}
1625342245.360478: {"book":{"asks":[],"bids":[[11351,1040]]},"depth":30,"sequence":8450968563,"symbol":"ENJUSD","timestamp":1625342245046098926,"type":"incremental"}
1625342245.4859352: {"book":{"asks":[],"bids":[[328605000,21127]]},"depth":30,"sequence":17652789358,"symbol":"YFIUSD","timestamp":1625342245203320959,"type":"incremental"}
1625342245.486741: {"book":{"asks":[],"bids":[[328605000,6142]]},"depth":30,"sequence":17652789359,"symbol":"YFIUSD","timestamp":1625342245203358950,"type":"incremental"}
1625342245.486806: {"book":{"asks":[],"bids":[[328605000,4322]]},"depth":30,"sequence":17652789360,"symbol":"YFIUSD","timestamp":1625342245203377938,"type":"incremental"}
1625342245.4868429: {"book":{"asks":[],"bids":[[328605000,4091]]},"depth":30,"sequence":17652789361,"symbol":"YFIUSD","timestamp":1625342245203393341,"type":"incremental"}
1625342245.486871: {"book":{"asks":[],"bids":[[328605000,0],[328025000,2372]]},"depth":30,"sequence":17652789362,"symbol":"YFIUSD","timestamp":1625342245203405185,"type":"incremental"}
1625342245.486922: {"book":{"asks":[],"bids":[[328795000,5170],[328025000,0]]},"depth":30,"sequence":17652789373,"symbol":"YFIUSD","timestamp":1625342245203587947,"type":"incremental"}
1625342245.486964: {"book":{"asks":[],"bids":[[328795000,6270]]},"depth":30,"sequence":17652789374,"symbol":"YFIUSD","timestamp":1625342245203610314,"type":"incremental"}
1625342245.48699: {"book":{"asks":[],"bids":[[328795000,17052]]},"depth":30,"sequence":17652789375,"symbol":"YFIUSD","timestamp":1625342245203630407,"type":"incremental"}
1625342245.4870138: {"book":{"asks":[],"bids":[[328565000,7260]]},"depth":30,"sequence":17652789376,"symbol":"YFIUSD","timestamp":1625342245203660213,"type":"incremental"}
1625342245.487037: {"book":{"asks":[],"bids":[[328565000,4960]]},"depth":30,"sequence":17652789377,"symbol":"YFIUSD","timestamp":1625342245203681526,"type":"incremental"}
1625342245.48706: {"book":{"asks":[],"bids":[[328565000,0],[328025000,2372]]},"depth":30,"sequence":17652789378,"symbol":"YFIUSD","timestamp":1625342245203701933,"type":"incremental"}
1625342245.487096: {"book":{"asks":[],"bids":[[328290000,6006]]},"depth":30,"sequence":17652789379,"symbol":"YFIUSD","timestamp":1625342245203721647,"type":"incremental"}
1625342245.4871192: {"book":{"asks":[],"bids":[[328290000,6332]]},"depth":30,"sequence":17652789380,"symbol":"YFIUSD","timestamp":1625342245203739221,"type":"incremental"}
1625342245.631453: {"book":{"asks":[],"bids":[[29980,515]]},"depth":30,"sequence":4899654490,"symbol":"XTZUSD","timestamp":1625342245522694277,"type":"incremental"}
1625342245.66978: {"book":{"asks":[[114274000,962135000000],[114316000,0]],"bids":[]},"depth":30,"sequence":146074884,"symbol":"sENJUSDT","timestamp":1625342245560408133,"type":"incremental"}
1625342245.689087: {"book":{"asks":[],"bids":[[329205000,848],[329105000,0]]},"depth":30,"sequence":17652789629,"symbol":"YFIUSD","timestamp":1625342245579120831,"type":"incremental"}
1625342245.702902: {"book":{"asks":[[11383,6593]],"bids":[]},"depth":30,"sequence":8450968773,"symbol":"ENJUSD","timestamp":1625342245442916890,"type":"incremental"}
1625342245.7034109: {"book":{"asks":[],"bids":[[11342,8933]]},"depth":30,"sequence":8450968777,"symbol":"ENJUSD","timestamp":1625342245499426564,"type":"incremental"}
1625342245.714873: {"book":{"asks":[[119460,1877]],"bids":[]},"depth":30,"sequence":6643005365,"symbol":"ATOMUSD","timestamp":1625342245441282708,"type":"incremental"}
1625342245.7150028: {"book":{"asks":[[119560,1660]],"bids":[]},"depth":30,"sequence":6643005366,"symbol":"ATOMUSD","timestamp":1625342245441328596,"type":"incremental"}
1625342245.7150688: {"book":{"asks":[[119360,1359],[119740,0]],"bids":[]},"depth":30,"sequence":6643005376,"symbol":"ATOMUSD","timestamp":1625342245441921589,"type":"incremental"}
1625342245.715171: {"book":{"asks":[[119420,5321]],"bids":[]},"depth":30,"sequence":6643005378,"symbol":"ATOMUSD","timestamp":1625342245441972852,"type":"incremental"}
1625342245.715234: {"book":{"asks":[[119650,2897],[119730,0]],"bids":[]},"depth":30,"sequence":6643005379,"symbol":"ATOMUSD","timestamp":1625342245441990700,"type":"incremental"}
1625342245.7152798: {"book":{"asks":[[119720,6586]],"bids":[]},"depth":30,"sequence":6643005383,"symbol":"ATOMUSD","timestamp":1625342245442177482,"type":"incremental"}
1625342245.715308: {"book":{"asks":[[119430,2650],[119480,2373]],"bids":[]},"depth":30,"sequence":6643005544,"symbol":"ATOMUSD","timestamp":1625342245528876559,"type":"incremental"}
1625342245.715342: {"book":{"asks":[],"bids":[[119120,422],[119060,0]]},"depth":30,"sequence":6643005545,"symbol":"ATOMUSD","timestamp":1625342245554034429,"type":"incremental"}
1625342245.809142: {"book":{"asks":[[11372,2901]],"bids":[]},"depth":30,"sequence":8450968967,"symbol":"ENJUSD","timestamp":1625342245577412949,"type":"incremental"}
1625342245.816074: {"book":{"asks":[],"bids":[[29980,245]]},"depth":30,"sequence":4899654491,"symbol":"XTZUSD","timestamp":1625342245522742234,"type":"incremental"}
1625342245.8167229: {"book":{"asks":[[30300,2357]],"bids":[]},"depth":30,"sequence":4899654492,"symbol":"XTZUSD","timestamp":1625342245553735460,"type":"incremental"}
1625342245.8167942: {"book":{"asks":[[30080,236],[30390,0]],"bids":[]},"depth":30,"sequence":4899654493,"symbol":"XTZUSD","timestamp":1625342245577455439,"type":"incremental"}
1625342245.816864: {"book":{"asks":[],"bids":[[30040,6466]]},"depth":30,"sequence":4899654494,"symbol":"XTZUSD","timestamp":1625342245591821193,"type":"incremental"}
1625342245.816898: {"book":{"asks":[[30120,190210]],"bids":[]},"depth":30,"sequence":4899654495,"symbol":"XTZUSD","timestamp":1625342245593269010,"type":"incremental"}
1625342245.8169339: {"book":{"asks":[[30090,0],[30390,3321]],"bids":[]},"depth":30,"sequence":4899654496,"symbol":"XTZUSD","timestamp":1625342245629341030,"type":"incremental"}
1625342245.816981: {"book":{"asks":[[30080,0],[30400,12518]],"bids":[]},"depth":30,"sequence":4899654497,"symbol":"XTZUSD","timestamp":1625342245641193279,"type":"incremental"}
1625342245.817025: {"book":{"asks":[[30120,186615]],"bids":[]},"depth":30,"sequence":4899654498,"symbol":"XTZUSD","timestamp":1625342245650748640,"type":"incremental"}
1625342245.817052: {"book":{"asks":[],"bids":[[30040,2871]]},"depth":30,"sequence":4899654499,"symbol":"XTZUSD","timestamp":1625342245652034200,"type":"incremental"}
1625342245.817078: {"book":{"asks":[[30090,4352],[30400,0]],"bids":[]},"depth":30,"sequence":4899654500,"symbol":"XTZUSD","timestamp":1625342245698940380,"type":"incremental"}
1625342245.876265: {"book":{"asks":[[11376,99],[11423,0]],"bids":[]},"depth":30,"sequence":8450969069,"symbol":"ENJUSD","timestamp":1625342245718619084,"type":"incremental"}
1625342245.9457731: {"book":{"asks":[[1878260000,0],[1882240000,42844000000]],"bids":[]},"depth":30,"sequence":20149234577,"symbol":"sLINKUSDT","timestamp":1625342245793819359,"type":"incremental"}
1625342246.001188: {"book":{"asks":[],"bids":[[30060,76460]]},"depth":30,"sequence":4899654501,"symbol":"XTZUSD","timestamp":1625342245775902147,"type":"incremental"}
1625342246.001336: {"book":{"asks":[],"bids":[[30070,56405]]},"depth":30,"sequence":4899654502,"symbol":"XTZUSD","timestamp":1625342245775944747,"type":"incremental"}
1625342246.001405: {"book":{"asks":[[30170,43479]],"bids":[]},"depth":30,"sequence":4899654503,"symbol":"XTZUSD","timestamp":1625342245887796381,"type":"incremental"}
1625342246.001462: {"book":{"asks":[],"bids":[[29970,17562]]},"depth":30,"sequence":4899654504,"symbol":"XTZUSD","timestamp":1625342245887833877,"type":"incremental"}
1625342246.001497: {"book":{"asks":[[30100,80921]],"bids":[]},"depth":30,"sequence":4899654505,"symbol":"XTZUSD","timestamp":1625342245887845789,"type":"incremental"}
1625342246.04845: {"book":{"asks":[[11381,5706],[11385,8426]],"bids":[]},"depth":30,"sequence":8450969084,"symbol":"ENJUSD","timestamp":1625342245848496506,"type":"incremental"}
1625342246.1434271: {"book":{"asks":[[67628000,756858000000],[67921000,0]],"bids":[]},"depth":30,"sequence":175932844,"symbol":"sGRTUSDT","timestamp":1625342246034662715,"type":"incremental"}
1625342246.184702: {"book":{"asks":[[2154800,1777],[2155400,4729],[2157900,0]],"bids":[]},"depth":30,"sequence":4899654506,"symbol":"XMRUSD","timestamp":1625342245982489311,"type":"incremental"}
1625342246.209583: {"book":{"asks":[[11377,3496]],"bids":[]},"depth":30,"sequence":8450969089,"symbol":"ENJUSD","timestamp":1625342246012231353,"type":"incremental"}
1625342246.2096949: {"book":{"asks":[[11377,0],[11423,6492]],"bids":[]},"depth":30,"sequence":8450969090,"symbol":"ENJUSD","timestamp":1625342246012279984,"type":"incremental"}
1625342246.209766: {"book":{"asks":[[11378,0],[11424,1620]],"bids":[]},"depth":30,"sequence":8450969091,"symbol":"ENJUSD","timestamp":1625342246012347992,"type":"incremental"}
1625342246.2098181: {"book":{"asks":[[11379,8055]],"bids":[]},"depth":30,"sequence":8450969092,"symbol":"ENJUSD","timestamp":1625342246012420052,"type":"incremental"}
1625342246.209857: {"book":{"asks":[[11380,11684]],"bids":[]},"depth":30,"sequence":8450969093,"symbol":"ENJUSD","timestamp":1625342246012441452,"type":"incremental"}
1625342246.209888: {"book":{"asks":[[11383,11790]],"bids":[]},"depth":30,"sequence":8450969094,"symbol":"ENJUSD","timestamp":1625342246012530867,"type":"incremental"}
1625342246.209915: {"book":{"asks":[[11388,4075],[11424,0]],"bids":[]},"depth":30,"sequence":8450969095,"symbol":"ENJUSD","timestamp":1625342246012568499,"type":"incremental"}
1625342246.20996: {"book":{"asks":[[11417,4245]],"bids":[]},"depth":30,"sequence":8450969096,"symbol":"ENJUSD","timestamp":1625342246012611799,"type":"incremental"}
1625342246.241847: {"book":{"asks":[[1874570000,0],[1882290000,91985000000]],"bids":[]},"depth":30,"sequence":20149234582,"symbol":"sLINKUSDT","timestamp":1625342246128003376,"type":"incremental"}
1625342246.241935: {"book":{"asks":[[1875400000,0],[1882450000,61422000000]],"bids":[]},"depth":30,"sequence":20149234583,"symbol":"sLINKUSDT","timestamp":1625342246128037008,"type":"incremental"}
1625342246.241975: {"book":{"asks":[[1875420000,0],[1882500000,73383000000]],"bids":[]},"depth":30,"sequence":20149234584,"symbol":"sLINKUSDT","timestamp":1625342246128057506,"type":"incremental"}
1625342246.2420092: {"book":{"asks":[[1875460000,0],[1882520000,97929000000]],"bids":[]},"depth":30,"sequence":20149234585,"symbol":"sLINKUSDT","timestamp":1625342246128072942,"type":"incremental"}
1625342246.242039: {"book":{"asks":[[1875540000,98983000000],[1882520000,0]],"bids":[]},"depth":30,"sequence":20149234586,"symbol":"sLINKUSDT","timestamp":1625342246128101980,"type":"incremental"}
1625342246.24207: {"book":{"asks":[[1875940000,98476000000],[1882500000,0]],"bids":[]},"depth":30,"sequence":20149234587,"symbol":"sLINKUSDT","timestamp":1625342246128241165,"type":"incremental"}
1625342246.2420979: {"book":{"asks":[[1875960000,113694000000],[1882450000,0]],"bids":[]},"depth":30,"sequence":20149234588,"symbol":"sLINKUSDT","timestamp":1625342246128276913,"type":"incremental"}
1625342246.2421272: {"book":{"asks":[[1876520000,74391000000],[1882290000,0]],"bids":[]},"depth":30,"sequence":20149234589,"symbol":"sLINKUSDT","timestamp":1625342246128299329,"type":"incremental"}
1625342246.242153: {"book":{"asks":[[1878270000,0],[1882290000,91985000000]],"bids":[]},"depth":30,"sequence":20149234590,"symbol":"sLINKUSDT","timestamp":1625342246128319099,"type":"incremental"}
1625342246.2421818: {"book":{"asks":[[1878800000,0],[1882450000,61422000000]],"bids":[]},"depth":30,"sequence":20149234591,"symbol":"sLINKUSDT","timestamp":1625342246128340960,"type":"incremental"}
1625342246.2422101: {"book":{"asks":[[1878860000,0],[1882500000,73383000000]],"bids":[]},"depth":30,"sequence":20149234592,"symbol":"sLINKUSDT","timestamp":1625342246128356402,"type":"incremental"}
1625342246.246589: {"book":{"asks":[],"bids":[[2150800,5851]]},"depth":30,"sequence":4899654770,"symbol":"XMRUSD","timestamp":1625342246099956828,"type":"incremental"}
1625342246.246679: {"book":{"asks":[[2152300,6982]],"bids":[]},"depth":30,"sequence":4899654857,"symbol":"XMRUSD","timestamp":1625342246106302625,"type":"incremental"}
1625342246.2467358: {"book":{"asks":[[2152300,0],[2157900,501]],"bids":[]},"depth":30,"sequence":4899654859,"symbol":"XMRUSD","timestamp":1625342246106852093,"type":"incremental"}
1625342246.2468312: {"book":{"asks":[],"bids":[[2147200,8011]]},"depth":30,"sequence":4899654950,"symbol":"XMRUSD","timestamp":1625342246113185114,"type":"incremental"}
1625342246.246861: {"book":{"asks":[],"bids":[[2145800,10000]]},"depth":30,"sequence":4899654951,"symbol":"XMRUSD","timestamp":1625342246113196277,"type":"incremental"}
1625342246.246888: {"book":{"asks":[],"bids":[[2145800,10950]]},"depth":30,"sequence":4899654952,"symbol":"XMRUSD","timestamp":1625342246113211815,"type":"incremental"}
1625342246.246913: {"book":{"asks":[],"bids":[[2145800,15281]]},"depth":30,"sequence":4899654953,"symbol":"XMRUSD","timestamp":1625342246113413094,"type":"incremental"}
1625342246.2469382: {"book":{"asks":[],"bids":[[2145800,15295]]},"depth":30,"sequence":4899654954,"symbol":"XMRUSD","timestamp":1625342246113432186,"type":"incremental"}
1625342246.246963: {"book":{"asks":[],"bids":[[30050,107509]]},"depth":30,"sequence":4899654991,"symbol":"XTZUSD","timestamp":1625342246115365898,"type":"incremental"}
1625342246.2519748: {"book":{"asks":[[1874590000,0],[1882520000,97929000000]],"bids":[]},"depth":30,"sequence":20149234599,"symbol":"sLINKUSDT","timestamp":1625342246132280692,"type":"incremental"}
1625342246.252131: {"book":{"asks":[[1875150000,3000000000]],"bids":[]},"depth":30,"sequence":20149234600,"symbol":"sLINKUSDT","timestamp":1625342246132335057,"type":"incremental"}
1625342246.2521899: {"book":{"asks":[[1875150000,0],[1882530000,75878000000]],"bids":[]},"depth":30,"sequence":20149234601,"symbol":"sLINKUSDT","timestamp":1625342246132370771,"type":"incremental"}
1625342246.2522712: {"book":{"asks":[[1875560000,0],[1882680000,63902000000]],"bids":[]},"depth":30,"sequence":20149234602,"symbol":"sLINKUSDT","timestamp":1625342246132394125,"type":"incremental"}
1625342246.252311: {"book":{"asks":[[1875760000,0],[1882940000,64501000000]],"bids":[]},"depth":30,"sequence":20149234603,"symbol":"sLINKUSDT","timestamp":1625342246132506791,"type":"incremental"}
1625342246.252357: {"book":{"asks":[[1878170000,117675000000],[1882940000,0]],"bids":[]},"depth":30,"sequence":20149234604,"symbol":"sLINKUSDT","timestamp":1625342246132532090,"type":"incremental"}
1625342246.252396: {"book":{"asks":[[1878170000,151963000000]],"bids":[]},"depth":30,"sequence":20149234605,"symbol":"sLINKUSDT","timestamp":1625342246132563623,"type":"incremental"}
1625342246.2524211: {"book":{"asks":[[1881820000,0],[1882940000,64501000000]],"bids":[]},"depth":30,"sequence":20149234606,"symbol":"sLINKUSDT","timestamp":1625342246132592705,"type":"incremental"}
1625342246.252456: {"book":{"asks":[[1881990000,80165000000],[1882940000,0]],"bids":[]},"depth":30,"sequence":20149234607,"symbol":"sLINKUSDT","timestamp":1625342246132617035,"type":"incremental"}
1625342246.2635531: {"book":{"asks":[[30100,80322]],"bids":[]},"depth":30,"sequence":4899655140,"symbol":"XTZUSD","timestamp":1625342246141528775,"type":"incremental"}
1625342246.323071: {"book":{"asks":[[30090,0],[30400,12518]],"bids":[]},"depth":30,"sequence":4899655323,"symbol":"XTZUSD","timestamp":1625342246162984665,"type":"incremental"}
1625342246.323189: {"book":{"asks":[[30100,79540]],"bids":[]},"depth":30,"sequence":4899655326,"symbol":"XTZUSD","timestamp":1625342246205727766,"type":"incremental"}
1625342246.323231: {"book":{"asks":[[30140,2068]],"bids":[]},"depth":30,"sequence":4899655359,"symbol":"XTZUSD","timestamp":1625342246210656013,"type":"incremental"}
1625342246.323266: {"book":{"asks":[[30140,1368]],"bids":[]},"depth":30,"sequence":4899655360,"symbol":"XTZUSD","timestamp":1625342246210694905,"type":"incremental"}
1625342246.323296: {"book":{"asks":[[30140,598]],"bids":[]},"depth":30,"sequence":4899655361,"symbol":"XTZUSD","timestamp":1625342246210717748,"type":"incremental"}
1625342246.323327: {"book":{"asks":[[30140,542]],"bids":[]},"depth":30,"sequence":4899655362,"symbol":"XTZUSD","timestamp":1625342246210738935,"type":"incremental"}
1625342246.323354: {"book":{"asks":[[30140,224]],"bids":[]},"depth":30,"sequence":4899655363,"symbol":"XTZUSD","timestamp":1625342246210761411,"type":"incremental"}
1625342246.32338: {"book":{"asks":[[67878000,832896000000],[67919000,0]],"bids":[]},"depth":30,"sequence":175932845,"symbol":"sGRTUSDT","timestamp":1625342246034699266,"type":"incremental"}
1625342246.323422: {"book":{"asks":[[67544000,316574000000],[67914000,0]],"bids":[]},"depth":30,"sequence":175932851,"symbol":"sGRTUSDT","timestamp":1625342246035098364,"type":"incremental"}
1625342246.346719: {"book":{"asks":[[330005000,1703]],"bids":[]},"depth":30,"sequence":17652789830,"symbol":"YFIUSD","timestamp":1625342246173227295,"type":"incremental"}
1625342246.369746: {"book":{"asks":[[30130,1947]],"bids":[]},"depth":30,"sequence":4899655364,"symbol":"XTZUSD","timestamp":1625342246210782765,"type":"incremental"}
1625342246.369876: {"book":{"asks":[[30130,1452]],"bids":[]},"depth":30,"sequence":4899655365,"symbol":"XTZUSD","timestamp":1625342246210807196,"type":"incremental"}
1625342246.3699389: {"book":{"asks":[],"bids":[[2152000,1900]]},"depth":30,"sequence":4899655512,"symbol":"XMRUSD","timestamp":1625342246241579915,"type":"incremental"}
1625342246.375176: {"book":{"asks":[],"bids":[[2152000,1350]]},"depth":30,"sequence":4899655649,"symbol":"XMRUSD","timestamp":1625342246260084290,"type":"incremental"}
1625342246.4239502: {"book":{"asks":[[1878760000,203000000],[1882680000,0]],"bids":[]},"depth":30,"sequence":20149234649,"symbol":"sLINKUSDT","timestamp":1625342246187399151,"type":"incremental"}
1625342246.470044: {"book":{"asks":[],"bids":[[2152000,0],[2144100,1583]]},"depth":30,"sequence":4899655679,"symbol":"XMRUSD","timestamp":1625342246261680035,"type":"incremental"}
1625342246.470224: {"book":{"asks":[[30090,4301],[30400,0]],"bids":[]},"depth":30,"sequence":4899655712,"symbol":"XTZUSD","timestamp":1625342246263656185,"type":"incremental"}
1625342246.470326: {"book":{"asks":[],"bids":[[2152100,742]]},"depth":30,"sequence":4899655713,"symbol":"XMRUSD","timestamp":1625342246264930702,"type":"incremental"}
1625342246.47038: {"book":{"asks":[[30120,190210]],"bids":[]},"depth":30,"sequence":4899655714,"symbol":"XTZUSD","timestamp":1625342246271116117,"type":"incremental"}
1625342246.470426: {"book":{"asks":[[30110,102974]],"bids":[]},"depth":30,"sequence":4899655715,"symbol":"XTZUSD","timestamp":1625342246278147689,"type":"incremental"}
1625342246.470468: {"book":{"asks":[[2155400,0],[2156100,7561],[2158900,840]],"bids":[]},"depth":30,"sequence":4899655716,"symbol":"XMRUSD","timestamp":1625342246278465069,"type":"incremental"}
1625342246.470547: {"book":{"asks":[[30090,0],[30400,12518]],"bids":[]},"depth":30,"sequence":4899655802,"symbol":"XTZUSD","timestamp":1625342246321107552,"type":"incremental"}
1625342246.502155: {"book":{"asks":[[67620000,0],[67914000,725483000000]],"bids":[]},"depth":30,"sequence":175932863,"symbol":"sGRTUSDT","timestamp":1625342246341022157,"type":"incremental"}
1625342246.502989: {"book":{"asks":[[67628000,0],[67919000,267634000000]],"bids":[]},"depth":30,"sequence":175932864,"symbol":"sGRTUSDT","timestamp":1625342246341069232,"type":"incremental"}
1625342246.503076: {"book":{"asks":[[67823000,843843000000],[67919000,0]],"bids":[]},"depth":30,"sequence":175932865,"symbol":"sGRTUSDT","timestamp":1625342246341086154,"type":"incremental"}
1625342246.503125: {"book":{"asks":[[67879000,0],[67919000,267634000000]],"bids":[]},"depth":30,"sequence":175932866,"symbol":"sGRTUSDT","timestamp":1625342246341104686,"type":"incremental"}
1625342246.503166: {"book":{"asks":[[67522000,0],[67921000,511683000000]],"bids":[]},"depth":30,"sequence":175932867,"symbol":"sGRTUSDT","timestamp":1625342246341126279,"type":"incremental"}
1625342246.503202: {"book":{"asks":[[67719000,0],[67932000,421097000000]],"bids":[]},"depth":30,"sequence":175932868,"symbol":"sGRTUSDT","timestamp":1625342246341142270,"type":"incremental"}
1625342246.503241: {"book":{"asks":[[67838000,867818000000],[67932000,0]],"bids":[]},"depth":30,"sequence":175932869,"symbol":"sGRTUSDT","timestamp":1625342246341158511,"type":"incremental"}
1625342246.503277: {"book":{"asks":[[67869000,455047000000],[67921000,0]],"bids":[]},"depth":30,"sequence":175932870,"symbol":"sGRTUSDT","timestamp":1625342246341174062,"type":"incremental"}
1625342246.550306: {"book":{"asks":[],"bids":[[11346,2965],[11343,5719]]},"depth":30,"sequence":8450969511,"symbol":"ENJUSD","timestamp":1625342246335600452,"type":"incremental"}
1625342246.554522: {"book":{"asks":[],"bids":[[2149500,4729],[2148900,910],[2144100,0]]},"depth":30,"sequence":4899655805,"symbol":"XMRUSD","timestamp":1625342246368624182,"type":"incremental"}
1625342246.554704: {"book":{"asks":[[30090,4214],[30400,0]],"bids":[]},"depth":30,"sequence":4899655807,"symbol":"XTZUSD","timestamp":1625342246418949097,"type":"incremental"}
1625342246.633178: {"book":{"asks":[[30090,0],[30400,12518]],"bids":[]},"depth":30,"sequence":4899655994,"symbol":"XTZUSD","timestamp":1625342246469720372,"type":"incremental"}
1625342246.68221: {"book":{"asks":[],"bids":[[67116000,0],[66936000,568938000000]]},"depth":30,"sequence":175932877,"symbol":"sGRTUSDT","timestamp":1625342246529618483,"type":"incremental"}
1625342246.738662: {"book":{"asks":[[30090,4214],[30400,0]],"bids":[]},"depth":30,"sequence":4899656017,"symbol":"XTZUSD","timestamp":1625342246541348736,"type":"incremental"}
1625342246.738836: {"book":{"asks":[],"bids":[[2151300,6094]]},"depth":30,"sequence":4899656018,"symbol":"XMRUSD","timestamp":1625342246616760850,"type":"incremental"}
1625342246.8661602: {"book":{"asks":[],"bids":[[119140,2600],[118710,0]]},"depth":30,"sequence":6643006874,"symbol":"ATOMUSD","timestamp":1625342246712031977,"type":"incremental"}
1625342246.8668869: {"book":{"asks":[],"bids":[[119140,2829]]},"depth":30,"sequence":6643006875,"symbol":"ATOMUSD","timestamp":1625342246712071549,"type":"incremental"}
1625342246.867: {"book":{"asks":[],"bids":[[119120,3708]]},"depth":30,"sequence":6643006876,"symbol":"ATOMUSD","timestamp":1625342246712130986,"type":"incremental"}
1625342246.8670652: {"book":{"asks":[],"bids":[[119050,7679]]},"depth":30,"sequence":6643006877,"symbol":"ATOMUSD","timestamp":1625342246712174782,"type":"incremental"}
1625342246.8671172: {"book":{"asks":[],"bids":[[118910,7572]]},"depth":30,"sequence":6643006878,"symbol":"ATOMUSD","timestamp":1625342246712254817,"type":"incremental"}
1625342246.867163: {"book":{"asks":[],"bids":[[118910,1472]]},"depth":30,"sequence":6643006879,"symbol":"ATOMUSD","timestamp":1625342246712339134,"type":"incremental"}
1625342246.8672051: {"book":{"asks":[],"bids":[[119150,422],[119120,3286],[118720,0]]},"depth":30,"sequence":6643006977,"symbol":"ATOMUSD","timestamp":1625342246720485775,"type":"incremental"}
1625342246.921699: {"book":{"asks":[[30190,120]],"bids":[]},"depth":30,"sequence":4899656019,"symbol":"XTZUSD","timestamp":1625342246638306548,"type":"incremental"}
1625342246.961313: {"book":{"asks":[],"bids":[[119020,2299],[118730,0]]},"depth":30,"sequence":6643006984,"symbol":"ATOMUSD","timestamp":1625342246807777956,"type":"incremental"}
1625342246.9619908: {"book":{"asks":[],"bids":[[119010,5660]]},"depth":30,"sequence":6643006985,"symbol":"ATOMUSD","timestamp":1625342246807815121,"type":"incremental"}
1625342246.9620538: {"book":{"asks":[],"bids":[[118990,2653]]},"depth":30,"sequence":6643006986,"symbol":"ATOMUSD","timestamp":1625342246807889798,"type":"incremental"}
1625342246.962093: {"book":{"asks":[],"bids":[[118940,3687]]},"depth":30,"sequence":6643006987,"symbol":"ATOMUSD","timestamp":1625342246807968949,"type":"incremental"}
1625342246.962126: {"book":{"asks":[],"bids":[[118940,3314]]},"depth":30,"sequence":6643006988,"symbol":"ATOMUSD","timestamp":1625342246808056704,"type":"incremental"}
1625342246.962154: {"book":{"asks":[],"bids":[[118940,2737]]},"depth":30,"sequence":6643006989,"symbol":"ATOMUSD","timestamp":1625342246808091703,"type":"incremental"}
1625342246.962181: {"book":{"asks":[],"bids":[[118940,2017]]},"depth":30,"sequence":6643006990,"symbol":"ATOMUSD","timestamp":1625342246808192229,"type":"incremental"}
1625342246.962208: {"book":{"asks":[],"bids":[[118930,1550]]},"depth":30,"sequence":6643006991,"symbol":"ATOMUSD","timestamp":1625342246808230538,"type":"incremental"}
1625342247.042212: {"book":{"asks":[],"bids":[[67074000,2506000000],[66936000,0]]},"depth":30,"sequence":175932879,"symbol":"sGRTUSDT","timestamp":1625342246772011672,"type":"incremental"}
1625342247.1067789: {"book":{"asks":[],"bids":[[30050,103914],[30040,6466]]},"depth":30,"sequence":4899656020,"symbol":"XTZUSD","timestamp":1625342246838562438,"type":"incremental"}
1625342247.107913: {"book":{"asks":[],"bids":[[2151700,1647]]},"depth":30,"sequence":4899656024,"symbol":"XMRUSD","timestamp":1625342246877467078,"type":"incremental"}
1625342247.1079628: {"book":{"asks":[[30090,0],[30400,12518]],"bids":[]},"depth":30,"sequence":4899656025,"symbol":"XTZUSD","timestamp":1625342246890745702,"type":"incremental"}
1625342247.10801: {"book":{"asks":[[30190,200]],"bids":[]},"depth":30,"sequence":4899656026,"symbol":"XTZUSD","timestamp":1625342246941221952,"type":"incremental"}
1625342247.1080341: {"book":{"asks":[],"bids":[[30040,5019]]},"depth":30,"sequence":4899656027,"symbol":"XTZUSD","timestamp":1625342246941263667,"type":"incremental"}
1625342247.108054: {"book":{"asks":[[30090,4196],[30400,0]],"bids":[]},"depth":30,"sequence":4899656028,"symbol":"XTZUSD","timestamp":1625342246983863749,"type":"incremental"}
1625342247.110993: {"book":{"asks":[[330005000,855],[330130000,848],[331975000,0]],"bids":[]},"depth":30,"sequence":17652790184,"symbol":"YFIUSD","timestamp":1625342246912696430,"type":"incremental"}
1625342247.2247639: {"book":{"asks":[],"bids":[[29800,11559]]},"depth":30,"sequence":4899656029,"symbol":"XTZUSD","timestamp":1625342246986444764,"type":"incremental"}
1625342247.225863: {"book":{"asks":[[30100,79740]],"bids":[]},"depth":30,"sequence":4899656030,"symbol":"XTZUSD","timestamp":1625342246986487397,"type":"incremental"}
1625342247.2259572: {"book":{"asks":[],"bids":[[29940,23100]]},"depth":30,"sequence":4899656031,"symbol":"XTZUSD","timestamp":1625342247031840212,"type":"incremental"}
1625342247.225999: {"book":{"asks":[[30100,79600]],"bids":[]},"depth":30,"sequence":4899656032,"symbol":"XTZUSD","timestamp":1625342247031881904,"type":"incremental"}
1625342247.226031: {"book":{"asks":[[30100,79200]],"bids":[]},"depth":30,"sequence":4899656033,"symbol":"XTZUSD","timestamp":1625342247031899556,"type":"incremental"}
1625342247.226059: {"book":{"asks":[[30100,79197]],"bids":[]},"depth":30,"sequence":4899656034,"symbol":"XTZUSD","timestamp":1625342247031914392,"type":"incremental"}
1625342247.226086: {"book":{"asks":[[30100,79047]],"bids":[]},"depth":30,"sequence":4899656035,"symbol":"XTZUSD","timestamp":1625342247031926800,"type":"incremental"}
1625342247.226112: {"book":{"asks":[[30100,79157]],"bids":[]},"depth":30,"sequence":4899656036,"symbol":"XTZUSD","timestamp":1625342247031941997,"type":"incremental"}
1625342247.226136: {"book":{"asks":[[30090,0],[30400,12518]],"bids":[]},"depth":30,"sequence":4899656037,"symbol":"XTZUSD","timestamp":1625342247035033857,"type":"incremental"}
1625342247.226191: {"book":{"asks":[],"bids":[[2151700,1332]]},"depth":30,"sequence":4899656038,"symbol":"XMRUSD","timestamp":1625342247054805063,"type":"incremental"}
1625342247.2262201: {"book":{"asks":[],"bids":[[2152100,1057]]},"depth":30,"sequence":4899656039,"symbol":"XMRUSD","timestamp":1625342247076744140,"type":"incremental"}
1625342247.2262459: {"book":{"asks":[],"bids":[[29970,18125]]},"depth":30,"sequence":4899656040,"symbol":"XTZUSD","timestamp":1625342247084624902,"type":"incremental"}
1625342247.226273: {"book":{"asks":[],"bids":[[30070,57305]]},"depth":30,"sequence":4899656041,"symbol":"XTZUSD","timestamp":1625342247084664439,"type":"incremental"}
1625342247.292421: {"book":{"asks":[[30090,4197],[30400,0]],"bids":[]},"depth":30,"sequence":4899656043,"symbol":"XTZUSD","timestamp":1625342247130466820,"type":"incremental"}
1625342247.479388: {"book":{"asks":[[30090,0],[30400,12518]],"bids":[]},"depth":30,"sequence":4899656140,"symbol":"XTZUSD","timestamp":1625342247181676332,"type":"incremental"}
1625342247.4795158: {"book":{"asks":[[30090,4197],[30400,0]],"bids":[]},"depth":30,"sequence":4899656141,"symbol":"XTZUSD","timestamp":1625342247246666049,"type":"incremental"}
1625342247.4795809: {"book":{"asks":[[30090,0],[30400,12518]],"bids":[]},"depth":30,"sequence":4899656144,"symbol":"XTZUSD","timestamp":1625342247306340855,"type":"incremental"}
1625342247.4796312: {"book":{"asks":[],"bids":[[30060,76283]]},"depth":30,"sequence":4899656145,"symbol":"XTZUSD","timestamp":1625342247358375260,"type":"incremental"}
1625342247.4796622: {"book":{"asks":[],"bids":[[30060,76218]]},"depth":30,"sequence":4899656146,"symbol":"XTZUSD","timestamp":1625342247358416054,"type":"incremental"}
1625342247.479692: {"book":{"asks":[],"bids":[[30060,76134]]},"depth":30,"sequence":4899656147,"symbol":"XTZUSD","timestamp":1625342247358434324,"type":"incremental"}
1625342247.479719: {"book":{"asks":[],"bids":[[30060,76154]]},"depth":30,"sequence":4899656148,"symbol":"XTZUSD","timestamp":1625342247358450545,"type":"incremental"}
1625342247.5826502: {"book":{"asks":[],"bids":[[11349,1888],[11346,2077]]},"depth":30,"sequence":8450970220,"symbol":"ENJUSD","timestamp":1625342247319944501,"type":"incremental"}
1625342247.662152: {"book":{"asks":[[30090,4197],[30400,0]],"bids":[]},"depth":30,"sequence":4899656149,"symbol":"XTZUSD","timestamp":1625342247378381492,"type":"incremental"}
1625342247.739084: {"book":{"asks":[],"bids":[[1871010000,79393000000],[1863470000,0]]},"depth":30,"sequence":20149235106,"symbol":"sLINKUSDT","timestamp":1625342247627449431,"type":"incremental"}
1625342247.7392378: {"book":{"asks":[],"bids":[[1870800000,71374000000],[1863720000,0]]},"depth":30,"sequence":20149235107,"symbol":"sLINKUSDT","timestamp":1625342247627462563,"type":"incremental"}
1625342247.7393181: {"book":{"asks":[],"bids":[[1870500000,127763000000],[1863740000,0]]},"depth":30,"sequence":20149235108,"symbol":"sLINKUSDT","timestamp":1625342247627475503,"type":"incremental"}
1625342247.739383: {"book":{"asks":[],"bids":[[1870460000,86793000000],[1863860000,0]]},"depth":30,"sequence":20149235109,"symbol":"sLINKUSDT","timestamp":1625342247627505357,"type":"incremental"}
1625342247.7394502: {"book":{"asks":[],"bids":[[1868480000,70814000000],[1863970000,0]]},"depth":30,"sequence":20149235110,"symbol":"sLINKUSDT","timestamp":1625342247627594638,"type":"incremental"}
1625342247.739507: {"book":{"asks":[],"bids":[[1866350000,81993000000],[1864060000,0]]},"depth":30,"sequence":20149235111,"symbol":"sLINKUSDT","timestamp":1625342247627625161,"type":"incremental"}
1625342247.739541: {"book":{"asks":[],"bids":[[1865350000,4250000000]]},"depth":30,"sequence":20149235112,"symbol":"sLINKUSDT","timestamp":1625342247627714773,"type":"incremental"}
1625342247.739567: {"book":{"asks":[],"bids":[[1865350000,0],[1864060000,73670000000]]},"depth":30,"sequence":20149235113,"symbol":"sLINKUSDT","timestamp":1625342247627743012,"type":"incremental"}
1625342247.739601: {"book":{"asks":[],"bids":[[1865220000,0],[1863970000,42630000000]]},"depth":30,"sequence":20149235114,"symbol":"sLINKUSDT","timestamp":1625342247627774778,"type":"incremental"}
1625342247.739635: {"book":{"asks":[],"bids":[[1865150000,0],[1863860000,55594000000]]},"depth":30,"sequence":20149235115,"symbol":"sLINKUSDT","timestamp":1625342247627796292,"type":"incremental"}
1625342247.739668: {"book":{"asks":[],"bids":[[1864150000,0],[1863740000,41753000000]]},"depth":30,"sequence":20149235116,"symbol":"sLINKUSDT","timestamp":1625342247627814900,"type":"incremental"}
1625342247.809388: {"book":{"asks":[],"bids":[[1871060000,126776000000],[1863740000,0]]},"depth":30,"sequence":20149235122,"symbol":"sLINKUSDT","timestamp":1625342247629810552,"type":"incremental"}
1625342247.80954: {"book":{"asks":[],"bids":[[1869650000,69964000000],[1863860000,0]]},"depth":30,"sequence":20149235123,"symbol":"sLINKUSDT","timestamp":1625342247629859865,"type":"incremental"}
1625342247.809618: {"book":{"asks":[],"bids":[[1865230000,0],[1863860000,55594000000]]},"depth":30,"sequence":20149235124,"symbol":"sLINKUSDT","timestamp":1625342247629937718,"type":"incremental"}
1625342247.8096828: {"book":{"asks":[],"bids":[[1865090000,0],[1863740000,41753000000]]},"depth":30,"sequence":20149235125,"symbol":"sLINKUSDT","timestamp":1625342247630013918,"type":"incremental"}
1625342247.80975: {"book":{"asks":[],"bids":[[1865060000,68181000000]]},"depth":30,"sequence":20149235126,"symbol":"sLINKUSDT","timestamp":1625342247630057503,"type":"incremental"}
1625342247.809803: {"book":{"asks":[],"bids":[[1864960000,0],[1863720000,66433000000]]},"depth":30,"sequence":20149235127,"symbol":"sLINKUSDT","timestamp":1625342247630119979,"type":"incremental"}
1625342247.845149: {"book":{"asks":[[30310,202]],"bids":[]},"depth":30,"sequence":4899656151,"symbol":"XTZUSD","timestamp":1625342247619039302,"type":"incremental"}
1625342247.845239: {"book":{"asks":[],"bids":[[29940,23270]]},"depth":30,"sequence":4899656152,"symbol":"XTZUSD","timestamp":1625342247619080210,"type":"incremental"}
1625342247.909228: {"book":{"asks":[],"bids":[[30050,98534]]},"depth":30,"sequence":4899656155,"symbol":"XTZUSD","timestamp":1625342247786568084,"type":"incremental"}
1625342248.097752: {"book":{"asks":[],"bids":[[11356,888],[11349,1000],[11321,0]]},"depth":30,"sequence":8450970977,"symbol":"ENJUSD","timestamp":1625342247971477024,"type":"incremental"}
1625342248.110992: {"book":{"asks":[],"bids":[[67074000,0],[66936000,568938000000]]},"depth":30,"sequence":175932921,"symbol":"sGRTUSDT","timestamp":1625342247838522149,"type":"incremental"}
1625342248.21435: {"book":{"asks":[[30160,31391]],"bids":[]},"depth":30,"sequence":4899656345,"symbol":"XTZUSD","timestamp":1625342248104135832,"type":"incremental"}
1625342248.270478: {"book":{"asks":[[11376,0],[11424,1620]],"bids":[]},"depth":30,"sequence":8450970978,"symbol":"ENJUSD","timestamp":1625342248015731431,"type":"incremental"}
1625342248.270578: {"book":{"asks":[[11385,7538],[11389,888],[11424,0]],"bids":[]},"depth":30,"sequence":8450970979,"symbol":"ENJUSD","timestamp":1625342248027187670,"type":"incremental"}
1625342248.270632: {"book":{"asks":[],"bids":[[11355,0],[11321,990]]},"depth":30,"sequence":8450970980,"symbol":"ENJUSD","timestamp":1625342248047689515,"type":"incremental"}
1625342248.2918699: {"book":{"asks":[],"bids":[[67211000,392571000000]]},"depth":30,"sequence":175932923,"symbol":"sGRTUSDT","timestamp":1625342248010407679,"type":"incremental"}
1625342248.2919219: {"book":{"asks":[],"bids":[[67211000,790388000000]]},"depth":30,"sequence":175932924,"symbol":"sGRTUSDT","timestamp":1625342248010443186,"type":"incremental"}
1625342248.291942: {"book":{"asks":[],"bids":[[67269000,961405000000]]},"depth":30,"sequence":175932929,"symbol":"sGRTUSDT","timestamp":1625342248051974866,"type":"incremental"}
1625342248.2919722: {"book":{"asks":[],"bids":[[67116000,2504000000],[66936000,0]]},"depth":30,"sequence":175932930,"symbol":"sGRTUSDT","timestamp":1625342248076148553,"type":"incremental"}
1625342248.398855: {"book":{"asks":[[2156100,2832],[2156700,4729],[2158900,0]],"bids":[]},"depth":30,"sequence":4899656346,"symbol":"XMRUSD","timestamp":1625342248141601854,"type":"incremental"}
1625342248.398926: {"book":{"asks":[],"bids":[[29920,71]]},"depth":30,"sequence":4899656347,"symbol":"XTZUSD","timestamp":1625342248146507627,"type":"incremental"}
1625342248.398947: {"book":{"asks":[],"bids":[[30020,1400]]},"depth":30,"sequence":4899656348,"symbol":"XTZUSD","timestamp":1625342248146550147,"type":"incremental"}
1625342248.398963: {"book":{"asks":[[30090,0],[30400,12518]],"bids":[]},"depth":30,"sequence":4899656349,"symbol":"XTZUSD","timestamp":1625342248155717965,"type":"incremental"}
1625342248.398988: {"book":{"asks":[[30090,4199],[30400,0]],"bids":[]},"depth":30,"sequence":4899656351,"symbol":"XTZUSD","timestamp":1625342248247987439,"type":"incremental"}
1625342248.440971: {"book":{"asks":[[11379,8154]],"bids":[]},"depth":30,"sequence":8450970984,"symbol":"ENJUSD","timestamp":1625342248156872901,"type":"incremental"}
1625342248.441345: {"book":{"asks":[],"bids":[[11357,200],[11321,0]]},"depth":30,"sequence":8450970988,"symbol":"ENJUSD","timestamp":1625342248199660074,"type":"incremental"}
1625342248.5832078: {"book":{"asks":[[30090,0],[30400,12518]],"bids":[]},"depth":30,"sequence":4899656357,"symbol":"XTZUSD","timestamp":1625342248298715390,"type":"incremental"}
1625342248.614003: {"book":{"asks":[],"bids":[[11356,0],[11350,7264],[11321,990]]},"depth":30,"sequence":8450971373,"symbol":"ENJUSD","timestamp":1625342248400515203,"type":"incremental"}
1625342248.7363222: {"book":{"asks":[],"bids":[[30010,22230]]},"depth":30,"sequence":4899656359,"symbol":"XTZUSD","timestamp":1625342248567061524,"type":"incremental"}
1625342248.7364511: {"book":{"asks":[],"bids":[[29910,2828]]},"depth":30,"sequence":4899656360,"symbol":"XTZUSD","timestamp":1625342248567113416,"type":"incremental"}
1625342248.736516: {"book":{"asks":[],"bids":[[29910,2038]]},"depth":30,"sequence":4899656361,"symbol":"XTZUSD","timestamp":1625342248567135284,"type":"incremental"}
1625342248.736568: {"book":{"asks":[],"bids":[[29910,1561]]},"depth":30,"sequence":4899656362,"symbol":"XTZUSD","timestamp":1625342248567154892,"type":"incremental"}
1625342248.736613: {"book":{"asks":[],"bids":[[30070,57705]]},"depth":30,"sequence":4899656363,"symbol":"XTZUSD","timestamp":1625342248567173413,"type":"incremental"}
1625342248.769751: {"book":{"asks":[],"bids":[[30070,57667]]},"depth":30,"sequence":4899656369,"symbol":"XTZUSD","timestamp":1625342248626993976,"type":"incremental"}
1625342248.893124: {"book":{"asks":[[330130000,934]],"bids":[]},"depth":30,"sequence":17652790415,"symbol":"YFIUSD","timestamp":1625342248659766881,"type":"incremental"}
1625342249.0237792: {"book":{"asks":[[1878760000,0],[1882680000,63902000000]],"bids":[]},"depth":30,"sequence":20149235816,"symbol":"sLINKUSDT","timestamp":1625342248839847354,"type":"incremental"}
1625342249.131189: {"book":{"asks":[[11385,8426],[11389,0],[11424,1620]],"bids":[]},"depth":30,"sequence":8450971434,"symbol":"ENJUSD","timestamp":1625342248924616030,"type":"incremental"}
1625342249.1377778: {"book":{"asks":[],"bids":[[29970,17562]]},"depth":30,"sequence":4899656550,"symbol":"XTZUSD","timestamp":1625342248893328141,"type":"incremental"}
1625342249.137908: {"book":{"asks":[],"bids":[[30070,57267]]},"depth":30,"sequence":4899656551,"symbol":"XTZUSD","timestamp":1625342248893375720,"type":"incremental"}
1625342249.137971: {"book":{"asks":[[2153200,0],[2158900,840]],"bids":[]},"depth":30,"sequence":4899656552,"symbol":"XMRUSD","timestamp":1625342248893400256,"type":"incremental"}
1625342249.1380649: {"book":{"asks":[],"bids":[[2152100,1077]]},"depth":30,"sequence":4899656553,"symbol":"XMRUSD","timestamp":1625342248893494745,"type":"incremental"}
1625342249.138114: {"book":{"asks":[[30280,10848]],"bids":[]},"depth":30,"sequence":4899656554,"symbol":"XTZUSD","timestamp":1625342248945345858,"type":"incremental"}
1625342249.138159: {"book":{"asks":[[30280,9838]],"bids":[]},"depth":30,"sequence":4899656555,"symbol":"XTZUSD","timestamp":1625342248945380786,"type":"incremental"}
1625342249.189816: {"book":{"asks":[[119640,4140]],"bids":[]},"depth":30,"sequence":6643007486,"symbol":"ATOMUSD","timestamp":1625342248969426031,"type":"incremental"}
1625342249.238573: {"book":{"asks":[],"bids":[[30020,169]]},"depth":30,"sequence":4899656559,"symbol":"XTZUSD","timestamp":1625342249091786695,"type":"incremental"}
1625342249.260096: {"book":{"asks":[[1875540000,0],[1882940000,64501000000]],"bids":[]},"depth":30,"sequence":20149235819,"symbol":"sLINKUSDT","timestamp":1625342249152679545,"type":"incremental"}
1625342249.260248: {"book":{"asks":[[1875700000,74900000000]],"bids":[]},"depth":30,"sequence":20149235820,"symbol":"sLINKUSDT","timestamp":1625342249152727374,"type":"incremental"}
1625342249.260305: {"book":{"asks":[[1875700000,14900000000]],"bids":[]},"depth":30,"sequence":20149235821,"symbol":"sLINKUSDT","timestamp":1625342249152749692,"type":"incremental"}
1625342249.260349: {"book":{"asks":[[1875700000,0],[1883130000,91261000000]],"bids":[]},"depth":30,"sequence":20149235822,"symbol":"sLINKUSDT","timestamp":1625342249152769457,"type":"incremental"}
1625342249.371847: {"book":{"asks":[[1875940000,0],[1883330000,25080000000]],"bids":[]},"depth":30,"sequence":20149235823,"symbol":"sLINKUSDT","timestamp":1625342249152785740,"type":"incremental"}
1625342249.372006: {"book":{"asks":[[1875960000,0],[1884080000,46650000000]],"bids":[]},"depth":30,"sequence":20149235824,"symbol":"sLINKUSDT","timestamp":1625342249152845205,"type":"incremental"}
1625342249.3720808: {"book":{"asks":[[1877310000,60916000000],[1884080000,0]],"bids":[]},"depth":30,"sequence":20149235825,"symbol":"sLINKUSDT","timestamp":1625342249152868052,"type":"incremental"}
1625342249.372145: {"book":{"asks":[[1877550000,143354000000],[1883330000,0]],"bids":[]},"depth":30,"sequence":20149235826,"symbol":"sLINKUSDT","timestamp":1625342249152969309,"type":"incremental"}
1625342249.372202: {"book":{"asks":[[1879540000,0],[1883330000,25080000000]],"bids":[]},"depth":30,"sequence":20149235827,"symbol":"sLINKUSDT","timestamp":1625342249152997072,"type":"incremental"}
1625342249.372255: {"book":{"asks":[[1879790000,0],[1884080000,46650000000]],"bids":[]},"depth":30,"sequence":20149235828,"symbol":"sLINKUSDT","timestamp":1625342249153021262,"type":"incremental"}
1625342249.372307: {"book":{"asks":[[1875770000,0],[1884200000,44799000000]],"bids":[]},"depth":30,"sequence":20149235832,"symbol":"sLINKUSDT","timestamp":1625342249155477544,"type":"incremental"}
1625342249.3723588: {"book":{"asks":[[1878170000,117675000000]],"bids":[]},"depth":30,"sequence":20149235833,"symbol":"sLINKUSDT","timestamp":1625342249155519902,"type":"incremental"}
1625342249.372396: {"book":{"asks":[[1878170000,0],[1884640000,68864000000]],"bids":[]},"depth":30,"sequence":20149235834,"symbol":"sLINKUSDT","timestamp":1625342249155583094,"type":"incremental"}
1625342249.372447: {"book":{"asks":[[1882520000,0],[1884900000,39683000000]],"bids":[]},"depth":30,"sequence":20149235835,"symbol":"sLINKUSDT","timestamp":1625342249155601678,"type":"incremental"}
1625342249.372498: {"book":{"asks":[[1879530000,203000000],[1884900000,0]],"bids":[]},"depth":30,"sequence":20149235838,"symbol":"sLINKUSDT","timestamp":1625342249234031455,"type":"incremental"}
1625342249.492427: {"book":{"asks":[],"bids":[[11351,1570]]},"depth":30,"sequence":8450971439,"symbol":"ENJUSD","timestamp":1625342249271317743,"type":"incremental"}
1625342249.686774: {"book":{"asks":[[67546000,258478000000],[67919000,0]],"bids":[]},"depth":30,"sequence":175932951,"symbol":"sGRTUSDT","timestamp":1625342249439304128,"type":"incremental"}
1625342249.686931: {"book":{"asks":[[67556000,937830000000]],"bids":[]},"depth":30,"sequence":175932952,"symbol":"sGRTUSDT","timestamp":1625342249439351075,"type":"incremental"}
1625342249.686989: {"book":{"asks":[[67751000,50950000000]],"bids":[]},"depth":30,"sequence":175932953,"symbol":"sGRTUSDT","timestamp":1625342249439366303,"type":"incremental"}
1625342249.7537029: {"book":{"asks":[[113913000,382346000000]],"bids":[]},"depth":30,"sequence":146074947,"symbol":"sENJUSDT","timestamp":1625342249643920283,"type":"incremental"}
1625342249.77943: {"book":{"asks":[[119500,12072]],"bids":[]},"depth":30,"sequence":6643007498,"symbol":"ATOMUSD","timestamp":1625342249635714314,"type":"incremental"}
1625342249.779558: {"book":{"asks":[],"bids":[[119150,2122]]},"depth":30,"sequence":6643007499,"symbol":"ATOMUSD","timestamp":1625342249635768201,"type":"incremental"}
1625342249.788119: {"book":{"asks":[[330130000,86],[330240000,848],[331920000,0]],"bids":[]},"depth":30,"sequence":17652790597,"symbol":"YFIUSD","timestamp":1625342249604095286,"type":"incremental"}
1625342249.808277: {"book":{"asks":[],"bids":[[30040,6069]]},"depth":30,"sequence":4899656744,"symbol":"XTZUSD","timestamp":1625342249677142752,"type":"incremental"}
1625342249.808424: {"book":{"asks":[],"bids":[[30020,1069]]},"depth":30,"sequence":4899656745,"symbol":"XTZUSD","timestamp":1625342249677183921,"type":"incremental"}
1625342249.808501: {"book":{"asks":[],"bids":[[30020,169]]},"depth":30,"sequence":4899656746,"symbol":"XTZUSD","timestamp":1625342249677204024,"type":"incremental"}
1625342249.824692: {"book":{"asks":[[330005000,720]],"bids":[]},"depth":30,"sequence":17652790908,"symbol":"YFIUSD","timestamp":1625342249707548449,"type":"incremental"}
1625342249.875787: {"book":{"asks":[[330005000,0],[331920000,3577]],"bids":[]},"depth":30,"sequence":17652790909,"symbol":"YFIUSD","timestamp":1625342249707559673,"type":"incremental"}
1625342249.875943: {"book":{"asks":[[330165000,1062],[331920000,0]],"bids":[]},"depth":30,"sequence":17652790910,"symbol":"YFIUSD","timestamp":1625342249707569133,"type":"incremental"}
1625342249.876031: {"book":{"asks":[[330195000,1143],[331910000,0]],"bids":[]},"depth":30,"sequence":17652790911,"symbol":"YFIUSD","timestamp":1625342249707580587,"type":"incremental"}
1625342249.876113: {"book":{"asks":[[330295000,0],[331910000,3171]],"bids":[]},"depth":30,"sequence":17652790912,"symbol":"YFIUSD","timestamp":1625342249707591422,"type":"incremental"}
1625342249.8761542: {"book":{"asks":[[331030000,4657],[331910000,0]],"bids":[]},"depth":30,"sequence":17652790913,"symbol":"YFIUSD","timestamp":1625342249707601300,"type":"incremental"}
1625342249.876195: {"book":{"asks":[[331685000,2402]],"bids":[]},"depth":30,"sequence":17652790914,"symbol":"YFIUSD","timestamp":1625342249707610959,"type":"incremental"}
1625342249.876223: {"book":{"asks":[[331715000,2467]],"bids":[]},"depth":30,"sequence":17652790915,"symbol":"YFIUSD","timestamp":1625342249707620346,"type":"incremental"}
1625342249.8762481: {"book":{"asks":[[330260000,0],[331910000,3171]],"bids":[]},"depth":30,"sequence":17652790925,"symbol":"YFIUSD","timestamp":1625342249707742526,"type":"incremental"}
1625342249.876283: {"book":{"asks":[[330565000,10264]],"bids":[]},"depth":30,"sequence":17652790926,"symbol":"YFIUSD","timestamp":1625342249708636708,"type":"incremental"}
1625342249.876307: {"book":{"asks":[[330755000,5637]],"bids":[]},"depth":30,"sequence":17652790927,"symbol":"YFIUSD","timestamp":1625342249708655345,"type":"incremental"}
1625342249.876331: {"book":{"asks":[[330820000,5115],[331910000,0]],"bids":[]},"depth":30,"sequence":17652790928,"symbol":"YFIUSD","timestamp":1625342249708665735,"type":"incremental"}
1625342249.876364: {"book":{"asks":[[330820000,5891]],"bids":[]},"depth":30,"sequence":17652790929,"symbol":"YFIUSD","timestamp":1625342249708675136,"type":"incremental"}
1625342249.889178: {"book":{"asks":[[51044000000,0],[51080000000,1159222000]],"bids":[]},"depth":30,"sequence":14221232663,"symbol":"sBCHUSDT","timestamp":1625342249701786231,"type":"incremental"}
1625342249.890104: {"book":{"asks":[[50918000000,0],[51086000000,402376000]],"bids":[]},"depth":30,"sequence":14221232667,"symbol":"sBCHUSDT","timestamp":1625342249703916232,"type":"incremental"}
1625342249.890232: {"book":{"asks":[],"bids":[[50558000000,1739545000],[50406000000,0]]},"depth":30,"sequence":14221232669,"symbol":"sBCHUSDT","timestamp":1625342249709045364,"type":"incremental"}
1625342249.890314: {"book":{"asks":[],"bids":[[50495000000,3126102000],[50409000000,0]]},"depth":30,"sequence":14221232670,"symbol":"sBCHUSDT","timestamp":1625342249709082081,"type":"incremental"}
1625342249.9912992: {"book":{"asks":[[2155900,7579],[2156700,0],[2159100,700]],"bids":[]},"depth":30,"sequence":4899656747,"symbol":"XMRUSD","timestamp":1625342249709857717,"type":"incremental"}
1625342249.991482: {"book":{"asks":[],"bids":[[30070,56367]]},"depth":30,"sequence":4899656748,"symbol":"XTZUSD","timestamp":1625342249834650401,"type":"incremental"}
1625342249.991549: {"book":{"asks":[],"bids":[[30070,56497]]},"depth":30,"sequence":4899656749,"symbol":"XTZUSD","timestamp":1625342249834697155,"type":"incremental"}
1625342249.9916: {"book":{"asks":[[30100,78957]],"bids":[]},"depth":30,"sequence":4899656750,"symbol":"XTZUSD","timestamp":1625342249834711748,"type":"incremental"}
1625342250.033216: {"book":{"asks":[],"bids":[[113500000,290715000000],[113002000,0]]},"depth":30,"sequence":146074948,"symbol":"sENJUSDT","timestamp":1625342249924193898,"type":"incremental"}
1625342250.177421: {"book":{"asks":[[30090,4350],[30400,0]],"bids":[]},"depth":30,"sequence":4899656752,"symbol":"XTZUSD","timestamp":1625342249892664334,"type":"incremental"}
1625342250.177593: {"book":{"asks":[[30200,18538]],"bids":[]},"depth":30,"sequence":4899656753,"symbol":"XTZUSD","timestamp":1625342249911072653,"type":"incremental"}
1625342250.177658: {"book":{"asks":[[30230,1711]],"bids":[]},"depth":30,"sequence":4899656754,"symbol":"XTZUSD","timestamp":1625342249911115468,"type":"incremental"}
1625342250.177709: {"book":{"asks":[],"bids":[[30050,104343]]},"depth":30,"sequence":4899656755,"symbol":"XTZUSD","timestamp":1625342249913159350,"type":"incremental"}
1625342250.1777549: {"book":{"asks":[],"bids":[[30040,6192]]},"depth":30,"sequence":4899656757,"symbol":"XTZUSD","timestamp":1625342249993534120,"type":"incremental"}
1625342250.177797: {"book":{"asks":[[30080,1410],[30390,0]],"bids":[]},"depth":30,"sequence":4899656758,"symbol":"XTZUSD","timestamp":1625342250048873322,"type":"incremental"}
1625342250.213056: {"book":{"asks":[],"bids":[[113452000,546155000000],[113003000,0]]},"depth":30,"sequence":146074949,"symbol":"sENJUSDT","timestamp":1625342249924241403,"type":"incremental"}
1625342250.213103: {"book":{"asks":[],"bids":[[113444000,303513000000],[113009000,0]]},"depth":30,"sequence":146074950,"symbol":"sENJUSDT","timestamp":1625342249924263369,"type":"incremental"}
1625342250.21313: {"book":{"asks":[],"bids":[[113395000,0],[113009000,713527000000]]},"depth":30,"sequence":146074951,"symbol":"sENJUSDT","timestamp":1625342249924288252,"type":"incremental"}
1625342250.213154: {"book":{"asks":[],"bids":[[113388000,0],[113003000,675107000000]]},"depth":30,"sequence":146074952,"symbol":"sENJUSDT","timestamp":1625342249924305545,"type":"incremental"}
1625342250.317868: {"book":{"asks":[[30090,0],[30390,3321]],"bids":[]},"depth":30,"sequence":4899656760,"symbol":"XTZUSD","timestamp":1625342250113857754,"type":"incremental"}
1625342250.318043: {"book":{"asks":[[30080,0],[30400,12518]],"bids":[]},"depth":30,"sequence":4899656761,"symbol":"XTZUSD","timestamp":1625342250134620983,"type":"incremental"}
1625342250.353272: {"book":{"asks":[[11379,8055]],"bids":[]},"depth":30,"sequence":8450971882,"symbol":"ENJUSD","timestamp":1625342250128427307,"type":"incremental"}
1625342250.3602219: {"book":{"asks":[[30090,4350],[30400,0]],"bids":[]},"depth":30,"sequence":4899656762,"symbol":"XTZUSD","timestamp":1625342250208158150,"type":"incremental"}
1625342250.3604019: {"book":{"asks":[],"bids":[[29960,2553]]},"depth":30,"sequence":4899656763,"symbol":"XTZUSD","timestamp":1625342250245754870,"type":"incremental"}
1625342250.397741: {"book":{"asks":[[11378,99],[11424,0]],"bids":[]},"depth":30,"sequence":8450971892,"symbol":"ENJUSD","timestamp":1625342250249290288,"type":"incremental"}
1625342250.480237: {"book":{"asks":[],"bids":[[328615000,3369],[328025000,0]]},"depth":30,"sequence":17652791316,"symbol":"YFIUSD","timestamp":1625342250348533679,"type":"incremental"}
1625342250.480397: {"book":{"asks":[],"bids":[[328305000,6000]]},"depth":30,"sequence":17652791317,"symbol":"YFIUSD","timestamp":1625342250348555203,"type":"incremental"}
1625342250.480457: {"book":{"asks":[],"bids":[[328305000,2000]]},"depth":30,"sequence":17652791318,"symbol":"YFIUSD","timestamp":1625342250348568916,"type":"incremental"}
1625342250.545117: {"book":{"asks":[],"bids":[[29960,2113]]},"depth":30,"sequence":4899656764,"symbol":"XTZUSD","timestamp":1625342250245798494,"type":"incremental"}
1625342250.5452511: {"book":{"asks":[],"bids":[[29960,1743]]},"depth":30,"sequence":4899656765,"symbol":"XTZUSD","timestamp":1625342250245818352,"type":"incremental"}
1625342250.5453172: {"book":{"asks":[],"bids":[[2149500,0],[2148800,4729]]},"depth":30,"sequence":4899656766,"symbol":"XMRUSD","timestamp":1625342250250364863,"type":"incremental"}
1625342250.586844: {"book":{"asks":[],"bids":[[329245000,1023],[328095000,0]]},"depth":30,"sequence":17652791378,"symbol":"YFIUSD","timestamp":1625342250350825171,"type":"incremental"}
1625342250.587009: {"book":{"asks":[],"bids":[[328970000,0],[328095000,4446]]},"depth":30,"sequence":17652791379,"symbol":"YFIUSD","timestamp":1625342250350845423,"type":"incremental"}
1625342250.66535: {"book":{"asks":[[119380,212]],"bids":[]},"depth":30,"sequence":6643007807,"symbol":"ATOMUSD","timestamp":1625342250547794438,"type":"incremental"}
1625342250.666384: {"book":{"asks":[[119420,7981]],"bids":[]},"depth":30,"sequence":6643007808,"symbol":"ATOMUSD","timestamp":1625342250547858837,"type":"incremental"}
1625342250.6664891: {"book":{"asks":[[119470,6961]],"bids":[]},"depth":30,"sequence":6643007809,"symbol":"ATOMUSD","timestamp":1625342250547885457,"type":"incremental"}
1625342250.666556: {"book":{"asks":[[119470,4467]],"bids":[]},"depth":30,"sequence":6643007810,"symbol":"ATOMUSD","timestamp":1625342250547906798,"type":"incremental"}
1625342250.6666062: {"book":{"asks":[[119500,5536]],"bids":[]},"depth":30,"sequence":6643007811,"symbol":"ATOMUSD","timestamp":1625342250547954182,"type":"incremental"}
1625342250.666652: {"book":{"asks":[[119560,7674]],"bids":[]},"depth":30,"sequence":6643007812,"symbol":"ATOMUSD","timestamp":1625342250548103300,"type":"incremental"}
1625342250.666694: {"book":{"asks":[[119590,7907]],"bids":[]},"depth":30,"sequence":6643007813,"symbol":"ATOMUSD","timestamp":1625342250548138189,"type":"incremental"}
1625342250.666743: {"book":{"asks":[[119360,0],[119730,430]],"bids":[]},"depth":30,"sequence":6643007826,"symbol":"ATOMUSD","timestamp":1625342250548819041,"type":"incremental"}
1625342250.666815: {"book":{"asks":[[119390,1675]],"bids":[]},"depth":30,"sequence":6643007827,"symbol":"ATOMUSD","timestamp":1625342250548844295,"type":"incremental"}
1625342250.666843: {"book":{"asks":[[119470,1650]],"bids":[]},"depth":30,"sequence":6643007831,"symbol":"ATOMUSD","timestamp":1625342250549008598,"type":"incremental"}
1625342250.6668742: {"book":{"asks":[[119500,2560]],"bids":[]},"depth":30,"sequence":6643007832,"symbol":"ATOMUSD","timestamp":1625342250549030428,"type":"incremental"}
1625342250.6669009: {"book":{"asks":[[119680,6651]],"bids":[]},"depth":30,"sequence":6643007833,"symbol":"ATOMUSD","timestamp":1625342250549051518,"type":"incremental"}
1625342250.6669261: {"book":{"asks":[[119720,2920]],"bids":[]},"depth":30,"sequence":6643007838,"symbol":"ATOMUSD","timestamp":1625342250549322775,"type":"incremental"}
1625342250.6669528: {"book":{"asks":[[119380,0],[119740,3688]],"bids":[]},"depth":30,"sequence":6643007954,"symbol":"ATOMUSD","timestamp":1625342250553452256,"type":"incremental"}
1625342250.6730208: {"book":{"asks":[[119390,370]],"bids":[]},"depth":30,"sequence":6643008004,"symbol":"ATOMUSD","timestamp":1625342250571028226,"type":"incremental"}
1625342250.681868: {"book":{"asks":[[1879530000,0],[1884900000,39683000000]],"bids":[]},"depth":30,"sequence":20149235974,"symbol":"sLINKUSDT","timestamp":1625342250449074081,"type":"incremental"}
1625342250.7305758: {"book":{"asks":[],"bids":[[30050,103943]]},"depth":30,"sequence":4899656769,"symbol":"XTZUSD","timestamp":1625342250490076363,"type":"incremental"}
1625342250.7307048: {"book":{"asks":[],"bids":[[30050,103643]]},"depth":30,"sequence":4899656770,"symbol":"XTZUSD","timestamp":1625342250490120281,"type":"incremental"}
1625342250.7307699: {"book":{"asks":[],"bids":[[30070,56797]]},"depth":30,"sequence":4899656771,"symbol":"XTZUSD","timestamp":1625342250490139541,"type":"incremental"}
1625342250.7308228: {"book":{"asks":[[30100,79157]],"bids":[]},"depth":30,"sequence":4899656772,"symbol":"XTZUSD","timestamp":1625342250490160632,"type":"incremental"}
1625342250.73087: {"book":{"asks":[[30250,2302]],"bids":[]},"depth":30,"sequence":4899656777,"symbol":"XTZUSD","timestamp":1625342250619515381,"type":"incremental"}
1625342250.7338219: {"book":{"asks":[[119390,0],[119760,19813]],"bids":[]},"depth":30,"sequence":6643008005,"symbol":"ATOMUSD","timestamp":1625342250576839368,"type":"incremental"}
1625342250.914504: {"book":{"asks":[],"bids":[[30070,56497]]},"depth":30,"sequence":4899656778,"symbol":"XTZUSD","timestamp":1625342250619561061,"type":"incremental"}
1625342250.914597: {"book":{"asks":[],"bids":[[30070,56367]]},"depth":30,"sequence":4899656779,"symbol":"XTZUSD","timestamp":1625342250619580815,"type":"incremental"}
1625342250.91464: {"book":{"asks":[],"bids":[[30070,55567]]},"depth":30,"sequence":4899656780,"symbol":"XTZUSD","timestamp":1625342250619601274,"type":"incremental"}
1625342250.9146729: {"book":{"asks":[[30080,2340],[30390,0]],"bids":[]},"depth":30,"sequence":4899656782,"symbol":"XTZUSD","timestamp":1625342250676064746,"type":"incremental"}
1625342250.9147341: {"book":{"asks":[],"bids":[[2150400,39508]]},"depth":30,"sequence":4899656784,"symbol":"XMRUSD","timestamp":1625342250743260844,"type":"incremental"}
1625342250.914767: {"book":{"asks":[[30090,0],[30390,3321]],"bids":[]},"depth":30,"sequence":4899656785,"symbol":"XTZUSD","timestamp":1625342250756191133,"type":"incremental"}
1625342250.914815: {"book":{"asks":[[30300,1565]],"bids":[]},"depth":30,"sequence":4899656786,"symbol":"XTZUSD","timestamp":1625342250780999347,"type":"incremental"}
1625342250.921891: {"book":{"asks":[],"bids":[[1870060000,147362000000],[1863720000,0]]},"depth":30,"sequence":20149235981,"symbol":"sLINKUSDT","timestamp":1625342250819110044,"type":"incremental"}
1625342250.941948: {"book":{"asks":[],"bids":[[329360000,6128]]},"depth":30,"sequence":17652791555,"symbol":"YFIUSD","timestamp":1625342250775151321,"type":"incremental"}
1625342250.942543: {"book":{"asks":[[330075000,0],[331910000,3171]],"bids":[]},"depth":30,"sequence":17652791556,"symbol":"YFIUSD","timestamp":1625342250775190483,"type":"incremental"}
1625342251.028954: {"book":{"asks":[[119400,5492]],"bids":[]},"depth":30,"sequence":6643008290,"symbol":"ATOMUSD","timestamp":1625342250850617141,"type":"incremental"}
1625342251.0952032: {"book":{"asks":[[1880300000,203000000],[1884900000,0]],"bids":[]},"depth":30,"sequence":20149235984,"symbol":"sLINKUSDT","timestamp":1625342250839926448,"type":"incremental"}
1625342251.0958788: {"book":{"asks":[[50931000000,0],[51091000000,600658000]],"bids":[]},"depth":30,"sequence":14221232990,"symbol":"sBCHUSDT","timestamp":1625342250875278170,"type":"incremental"}
1625342251.097122: {"book":{"asks":[[30080,0],[30400,12518]],"bids":[]},"depth":30,"sequence":4899656787,"symbol":"XTZUSD","timestamp":1625342250809294032,"type":"incremental"}
1625342251.098786: {"book":{"asks":[[30090,4350],[30400,0]],"bids":[]},"depth":30,"sequence":4899656788,"symbol":"XTZUSD","timestamp":1625342250899474716,"type":"incremental"}
1625342251.2002518: {"book":{"asks":[[769100000,13269600000]],"bids":[]},"depth":30,"sequence":146074964,"symbol":"sSUSHIUSDT","timestamp":1625342251047051014,"type":"incremental"}
1625342251.248812: {"book":{"asks":[[50937000000,6007000],[51091000000,0]],"bids":[]},"depth":30,"sequence":14221233147,"symbol":"sBCHUSDT","timestamp":1625342251087154167,"type":"incremental"}
1625342251.258359: {"book":{"asks":[],"bids":[[29990,58089]]},"depth":30,"sequence":4899656794,"symbol":"XTZUSD","timestamp":1625342251067417874,"type":"incremental"}
1625342251.4539368: {"book":{"asks":[],"bids":[[11354,13651]]},"depth":30,"sequence":8450972122,"symbol":"ENJUSD","timestamp":1625342251232464246,"type":"incremental"}
1625342251.454727: {"book":{"asks":[[11379,3390]],"bids":[]},"depth":30,"sequence":8450972148,"symbol":"ENJUSD","timestamp":1625342251336833441,"type":"incremental"}
1625342251.4548328: {"book":{"asks":[[11380,6790]],"bids":[]},"depth":30,"sequence":8450972149,"symbol":"ENJUSD","timestamp":1625342251336853213,"type":"incremental"}
1625342251.454895: {"book":{"asks":[[11382,7567]],"bids":[]},"depth":30,"sequence":8450972150,"symbol":"ENJUSD","timestamp":1625342251336887841,"type":"incremental"}
1625342251.454945: {"book":{"asks":[[11384,10351]],"bids":[]},"depth":30,"sequence":8450972151,"symbol":"ENJUSD","timestamp":1625342251336908459,"type":"incremental"}
1625342251.454989: {"book":{"asks":[[11385,13935]],"bids":[]},"depth":30,"sequence":8450972152,"symbol":"ENJUSD","timestamp":1625342251336953765,"type":"incremental"}
1625342251.4550312: {"book":{"asks":[[11388,8404]],"bids":[]},"depth":30,"sequence":8450972153,"symbol":"ENJUSD","timestamp":1625342251336978334,"type":"incremental"}
1625342251.455072: {"book":{"asks":[[11390,9074]],"bids":[]},"depth":30,"sequence":8450972154,"symbol":"ENJUSD","timestamp":1625342251337002586,"type":"incremental"}
1625342251.455111: {"book":{"asks":[[11380,0],[11424,1620]],"bids":[]},"depth":30,"sequence":8450972277,"symbol":"ENJUSD","timestamp":1625342251341067035,"type":"incremental"}
1625342251.459491: {"book":{"asks":[[11381,1510]],"bids":[]},"depth":30,"sequence":8450972278,"symbol":"ENJUSD","timestamp":1625342251341083779,"type":"incremental"}
1625342251.459581: {"book":{"asks":[[11382,1405]],"bids":[]},"depth":30,"sequence":8450972279,"symbol":"ENJUSD","timestamp":1625342251341102685,"type":"incremental"}
1625342251.459622: {"book":{"asks":[[11384,17627]],"bids":[]},"depth":30,"sequence":8450972280,"symbol":"ENJUSD","timestamp":1625342251341121725,"type":"incremental"}
1625342251.4596548: {"book":{"asks":[[11386,12571]],"bids":[]},"depth":30,"sequence":8450972281,"symbol":"ENJUSD","timestamp":1625342251341140746,"type":"incremental"}
1625342251.4596841: {"book":{"asks":[[11392,11149]],"bids":[]},"depth":30,"sequence":8450972282,"symbol":"ENJUSD","timestamp":1625342251341158552,"type":"incremental"}
1625342251.459711: {"book":{"asks":[[11397,5816]],"bids":[]},"depth":30,"sequence":8450972283,"symbol":"ENJUSD","timestamp":1625342251341176921,"type":"incremental"}
1625342251.459738: {"book":{"asks":[[11400,2495]],"bids":[]},"depth":30,"sequence":8450972284,"symbol":"ENJUSD","timestamp":1625342251341194640,"type":"incremental"}
1625342251.459765: {"book":{"asks":[[11416,2150]],"bids":[]},"depth":30,"sequence":8450972285,"symbol":"ENJUSD","timestamp":1625342251341217614,"type":"incremental"}
1625342251.4597912: {"book":{"asks":[[11416,0],[11425,5324]],"bids":[]},"depth":30,"sequence":8450972286,"symbol":"ENJUSD","timestamp":1625342251341237677,"type":"incremental"}
1625342251.459845: {"book":{"asks":[[11417,6361]],"bids":[]},"depth":30,"sequence":8450972287,"symbol":"ENJUSD","timestamp":1625342251341255343,"type":"incremental"}
1625342251.477375: {"book":{"asks":[],"bids":[[11360,960],[11321,0]]},"depth":30,"sequence":8450972419,"symbol":"ENJUSD","timestamp":1625342251346052312,"type":"incremental"}
1625342251.47754: {"book":{"asks":[],"bids":[[11360,1760]]},"depth":30,"sequence":8450972420,"symbol":"ENJUSD","timestamp":1625342251346069713,"type":"incremental"}
1625342251.4776042: {"book":{"asks":[],"bids":[[11360,4413]]},"depth":30,"sequence":8450972421,"symbol":"ENJUSD","timestamp":1625342251346087942,"type":"incremental"}
1625342251.477655: {"book":{"asks":[],"bids":[[11359,6268],[11322,0]]},"depth":30,"sequence":8450972422,"symbol":"ENJUSD","timestamp":1625342251346106296,"type":"incremental"}
1625342251.4777322: {"book":{"asks":[],"bids":[[11358,6236],[11323,0]]},"depth":30,"sequence":8450972423,"symbol":"ENJUSD","timestamp":1625342251346123735,"type":"incremental"}
1625342251.477817: {"book":{"asks":[],"bids":[[11357,7624]]},"depth":30,"sequence":8450972424,"symbol":"ENJUSD","timestamp":1625342251346146015,"type":"incremental"}
1625342251.477848: {"book":{"asks":[],"bids":[[11354,7969]]},"depth":30,"sequence":8450972425,"symbol":"ENJUSD","timestamp":1625342251346164639,"type":"incremental"}
1625342251.477876: {"book":{"asks":[],"bids":[[11353,7604]]},"depth":30,"sequence":8450972426,"symbol":"ENJUSD","timestamp":1625342251346183712,"type":"incremental"}
1625342251.4779022: {"book":{"asks":[],"bids":[[11342,3911]]},"depth":30,"sequence":8450972427,"symbol":"ENJUSD","timestamp":1625342251346205418,"type":"incremental"}
1625342251.477928: {"book":{"asks":[],"bids":[[11342,1560]]},"depth":30,"sequence":8450972428,"symbol":"ENJUSD","timestamp":1625342251346224059,"type":"incremental"}
1625342251.477955: {"book":{"asks":[],"bids":[[11360,10307]]},"depth":30,"sequence":8450972503,"symbol":"ENJUSD","timestamp":1625342251350915952,"type":"incremental"}
1625342251.4779809: {"book":{"asks":[],"bids":[[11359,12901]]},"depth":30,"sequence":8450972504,"symbol":"ENJUSD","timestamp":1625342251350943246,"type":"incremental"}
1625342251.5071201: {"book":{"asks":[],"bids":[[30050,103683]]},"depth":30,"sequence":4899656977,"symbol":"XTZUSD","timestamp":1625342251363295512,"type":"incremental"}
1625342251.519611: {"book":{"asks":[],"bids":[[11358,13387]]},"depth":30,"sequence":8450972505,"symbol":"ENJUSD","timestamp":1625342251350962542,"type":"incremental"}
1625342251.5196779: {"book":{"asks":[],"bids":[[11357,11774]]},"depth":30,"sequence":8450972506,"symbol":"ENJUSD","timestamp":1625342251350988831,"type":"incremental"}
1625342251.519706: {"book":{"asks":[],"bids":[[11354,1839]]},"depth":30,"sequence":8450972507,"symbol":"ENJUSD","timestamp":1625342251351004501,"type":"incremental"}
1625342251.519729: {"book":{"asks":[],"bids":[[11344,1490]]},"depth":30,"sequence":8450972508,"symbol":"ENJUSD","timestamp":1625342251351019268,"type":"incremental"}
1625342251.5197482: {"book":{"asks":[],"bids":[[11343,921]]},"depth":30,"sequence":8450972509,"symbol":"ENJUSD","timestamp":1625342251351034478,"type":"incremental"}
1625342251.5652108: {"book":{"asks":[[30120,191110]],"bids":[]},"depth":30,"sequence":4899657171,"symbol":"XTZUSD","timestamp":1625342251454681421,"type":"incremental"}
1625342251.565346: {"book":{"asks":[[30100,79247]],"bids":[]},"depth":30,"sequence":4899657172,"symbol":"XTZUSD","timestamp":1625342251454734156,"type":"incremental"}
1625342251.603379: {"book":{"asks":[[119410,1860]],"bids":[]},"depth":30,"sequence":6643008297,"symbol":"ATOMUSD","timestamp":1625342251388046051,"type":"incremental"}
1625342251.603518: {"book":{"asks":[],"bids":[[119150,3936]]},"depth":30,"sequence":6643008298,"symbol":"ATOMUSD","timestamp":1625342251388100039,"type":"incremental"}
1625342251.6257432: {"book":{"asks":[],"bids":[[11357,11574]]},"depth":30,"sequence":8450972691,"symbol":"ENJUSD","timestamp":1625342251474419636,"type":"incremental"}
1625342251.6520681: {"book":{"asks":[[2152700,6999]],"bids":[]},"depth":30,"sequence":4899657348,"symbol":"XMRUSD","timestamp":1625342251510774888,"type":"incremental"}
1625342251.652199: {"book":{"asks":[[30230,2211]],"bids":[]},"depth":30,"sequence":4899657349,"symbol":"XTZUSD","timestamp":1625342251514710444,"type":"incremental"}
1625342251.6552808: {"book":{"asks":[[330090000,848],[330240000,0]],"bids":[]},"depth":30,"sequence":17652791655,"symbol":"YFIUSD","timestamp":1625342251531838058,"type":"incremental"}
1625342251.6967528: {"book":{"asks":[[113939000,281113000000],[114315000,0]],"bids":[]},"depth":30,"sequence":146074966,"symbol":"sENJUSDT","timestamp":1625342251587006701,"type":"incremental"}
1625342251.760642: {"book":{"asks":[],"bids":[[11350,6376],[11346,2965]]},"depth":30,"sequence":8450972908,"symbol":"ENJUSD","timestamp":1625342251607867599,"type":"incremental"}
1625342251.8033102: {"book":{"asks":[],"bids":[[11361,200],[11324,0]]},"depth":30,"sequence":8450972969,"symbol":"ENJUSD","timestamp":1625342251632589961,"type":"incremental"}
1625342251.825537: {"book":{"asks":[],"bids":[[30040,7472]]},"depth":30,"sequence":4899657437,"symbol":"XTZUSD","timestamp":1625342251591619045,"type":"incremental"}
1625342251.8256671: {"book":{"asks":[[2152400,6979]],"bids":[]},"depth":30,"sequence":4899657439,"symbol":"XMRUSD","timestamp":1625342251711442864,"type":"incremental"}
1625342251.825749: {"book":{"asks":[[2152400,69]],"bids":[]},"depth":30,"sequence":4899657440,"symbol":"XMRUSD","timestamp":1625342251711498664,"type":"incremental"}
1625342251.82581: {"book":{"asks":[[2152400,0],[2159200,4650]],"bids":[]},"depth":30,"sequence":4899657441,"symbol":"XMRUSD","timestamp":1625342251711580777,"type":"incremental"}
1625342251.8258948: {"book":{"asks":[[2152700,12604]],"bids":[]},"depth":30,"sequence":4899657442,"symbol":"XMRUSD","timestamp":1625342251711607844,"type":"incremental"}
1625342251.8259258: {"book":{"asks":[[2153000,4978],[2159200,0]],"bids":[]},"depth":30,"sequence":4899657443,"symbol":"XMRUSD","timestamp":1625342251711710796,"type":"incremental"}
1625342251.825977: {"book":{"asks":[[2153600,32489]],"bids":[]},"depth":30,"sequence":4899657444,"symbol":"XMRUSD","timestamp":1625342251711750261,"type":"incremental"}
1625342251.8260071: {"book":{"asks":[[2153600,16489]],"bids":[]},"depth":30,"sequence":4899657445,"symbol":"XMRUSD","timestamp":1625342251711887985,"type":"incremental"}
1625342251.852072: {"book":{"asks":[[2152800,7424],[2159100,0]],"bids":[]},"depth":30,"sequence":4899657636,"symbol":"XMRUSD","timestamp":1625342251719279433,"type":"incremental"}
1625342251.852907: {"book":{"asks":[],"bids":[[2152300,5513],[2144300,0]]},"depth":30,"sequence":4899657724,"symbol":"XMRUSD","timestamp":1625342251721304825,"type":"incremental"}
1625342251.852996: {"book":{"asks":[],"bids":[[2152100,4577]]},"depth":30,"sequence":4899657725,"symbol":"XMRUSD","timestamp":1625342251721323810,"type":"incremental"}
1625342251.853036: {"book":{"asks":[],"bids":[[2152100,8444]]},"depth":30,"sequence":4899657726,"symbol":"XMRUSD","timestamp":1625342251721343005,"type":"incremental"}
1625342251.853068: {"book":{"asks":[],"bids":[[2151300,720]]},"depth":30,"sequence":4899657727,"symbol":"XMRUSD","timestamp":1625342251721372533,"type":"incremental"}
1625342251.853097: {"book":{"asks":[],"bids":[[2150800,13251]]},"depth":30,"sequence":4899657728,"symbol":"XMRUSD","timestamp":1625342251721393334,"type":"incremental"}
1625342251.8531241: {"book":{"asks":[],"bids":[[2150800,14611]]},"depth":30,"sequence":4899657729,"symbol":"XMRUSD","timestamp":1625342251721430652,"type":"incremental"}
1625342251.853151: {"book":{"asks":[],"bids":[[2150800,28741]]},"depth":30,"sequence":4899657730,"symbol":"XMRUSD","timestamp":1625342251721456485,"type":"incremental"}
1625342251.853176: {"book":{"asks":[],"bids":[[2150800,32847]]},"depth":30,"sequence":4899657731,"symbol":"XMRUSD","timestamp":1625342251721479283,"type":"incremental"}
1625342251.8532019: {"book":{"asks":[],"bids":[[2148700,36334]]},"depth":30,"sequence":4899657732,"symbol":"XMRUSD","timestamp":1625342251721498272,"type":"incremental"}
1625342251.853228: {"book":{"asks":[],"bids":[[2148700,29981]]},"depth":30,"sequence":4899657733,"symbol":"XMRUSD","timestamp":1625342251721517311,"type":"incremental"}
1625342251.8532531: {"book":{"asks":[],"bids":[[2148700,15981]]},"depth":30,"sequence":4899657734,"symbol":"XMRUSD","timestamp":1625342251721536179,"type":"incremental"}
1625342251.853278: {"book":{"asks":[],"bids":[[2148700,8033]]},"depth":30,"sequence":4899657735,"symbol":"XMRUSD","timestamp":1625342251721555511,"type":"incremental"}
1625342251.853303: {"book":{"asks":[],"bids":[[2148700,5820]]},"depth":30,"sequence":4899657736,"symbol":"XMRUSD","timestamp":1625342251721573690,"type":"incremental"}
1625342251.8567948: {"book":{"asks":[[113999000,311593000000],[114311000,0]],"bids":[]},"depth":30,"sequence":146074967,"symbol":"sENJUSDT","timestamp":1625342251587062549,"type":"incremental"}
1625342251.856958: {"book":{"asks":[[114144000,0],[114311000,491169000000]],"bids":[]},"depth":30,"sequence":146074968,"symbol":"sENJUSDT","timestamp":1625342251587085008,"type":"incremental"}
1625342251.858575: {"book":{"asks":[],"bids":[[2148700,950]]},"depth":30,"sequence":4899657737,"symbol":"XMRUSD","timestamp":1625342251721592511,"type":"incremental"}
1625342251.859721: {"book":{"asks":[],"bids":[[2152200,6869],[2145000,0]]},"depth":30,"sequence":4899657742,"symbol":"XMRUSD","timestamp":1625342251723697674,"type":"incremental"}
1625342251.85989: {"book":{"asks":[],"bids":[[2151500,7762]]},"depth":30,"sequence":4899657743,"symbol":"XMRUSD","timestamp":1625342251723727010,"type":"incremental"}
1625342251.859958: {"book":{"asks":[],"bids":[[2151000,5527]]},"depth":30,"sequence":4899657744,"symbol":"XMRUSD","timestamp":1625342251723748480,"type":"incremental"}
1625342251.860011: {"book":{"asks":[],"bids":[[2151000,2860]]},"depth":30,"sequence":4899657745,"symbol":"XMRUSD","timestamp":1625342251723781898,"type":"incremental"}
1625342251.860058: {"book":{"asks":[],"bids":[[2151000,1860]]},"depth":30,"sequence":4899657746,"symbol":"XMRUSD","timestamp":1625342251723806722,"type":"incremental"}
1625342251.8601139: {"book":{"asks":[],"bids":[[2151000,960]]},"depth":30,"sequence":4899657747,"symbol":"XMRUSD","timestamp":1625342251723828507,"type":"incremental"}
1625342251.8601758: {"book":{"asks":[],"bids":[[2150700,4412]]},"depth":30,"sequence":4899657748,"symbol":"XMRUSD","timestamp":1625342251723851455,"type":"incremental"}
1625342251.860203: {"book":{"asks":[],"bids":[[2150700,360]]},"depth":30,"sequence":4899657749,"symbol":"XMRUSD","timestamp":1625342251723873403,"type":"incremental"}
1625342251.971026: {"book":{"asks":[],"bids":[[119170,2498],[118740,0]]},"depth":30,"sequence":6643009100,"symbol":"ATOMUSD","timestamp":1625342251834027860,"type":"incremental"}
1625342251.9716742: {"book":{"asks":[],"bids":[[119040,2949],[118760,0]]},"depth":30,"sequence":6643009101,"symbol":"ATOMUSD","timestamp":1625342251834088869,"type":"incremental"}
1625342251.971759: {"book":{"asks":[],"bids":[[119040,5687]]},"depth":30,"sequence":6643009102,"symbol":"ATOMUSD","timestamp":1625342251834149503,"type":"incremental"}
1625342251.971798: {"book":{"asks":[],"bids":[[119020,2781]]},"depth":30,"sequence":6643009103,"symbol":"ATOMUSD","timestamp":1625342251834181532,"type":"incremental"}
1625342251.9718301: {"book":{"asks":[],"bids":[[119020,8915]]},"depth":30,"sequence":6643009104,"symbol":"ATOMUSD","timestamp":1625342251834263924,"type":"incremental"}
1625342251.971858: {"book":{"asks":[],"bids":[[118980,3085]]},"depth":30,"sequence":6643009105,"symbol":"ATOMUSD","timestamp":1625342251834318003,"type":"incremental"}
1625342251.9718862: {"book":{"asks":[],"bids":[[118950,5480]]},"depth":30,"sequence":6643009106,"symbol":"ATOMUSD","timestamp":1625342251834348819,"type":"incremental"}
1625342251.97639: {"book":{"asks":[],"bids":[[11345,3866]]},"depth":30,"sequence":8450973068,"symbol":"ENJUSD","timestamp":1625342251797608596,"type":"incremental"}
1625342251.980653: {"book":{"asks":[],"bids":[[119150,3514],[119110,1571]]},"depth":30,"sequence":6643009285,"symbol":"ATOMUSD","timestamp":1625342251869833457,"type":"incremental"}
1625342252.0444028: {"book":{"asks":[],"bids":[[29960,793]]},"depth":30,"sequence":4899658013,"symbol":"XTZUSD","timestamp":1625342251738711628,"type":"incremental"}
1625342252.044543: {"book":{"asks":[],"bids":[[29960,353]]},"depth":30,"sequence":4899658014,"symbol":"XTZUSD","timestamp":1625342251738749444,"type":"incremental"}
1625342252.044611: {"book":{"asks":[],"bids":[[30010,23230]]},"depth":30,"sequence":4899658015,"symbol":"XTZUSD","timestamp":1625342251791620195,"type":"incremental"}
1625342252.2061398: {"book":{"asks":[[30120,191360]],"bids":[]},"depth":30,"sequence":4899658026,"symbol":"XTZUSD","timestamp":1625342252081154542,"type":"incremental"}
1625342252.255678: {"book":{"asks":[[1880300000,0],[1884900000,39683000000]],"bids":[]},"depth":30,"sequence":20149235998,"symbol":"sLINKUSDT","timestamp":1625342252052926185,"type":"incremental"}
1625342252.319105: {"book":{"asks":[[1875180000,92502000000],[1884900000,0]],"bids":[]},"depth":30,"sequence":20149235999,"symbol":"sLINKUSDT","timestamp":1625342252204239270,"type":"incremental"}
1625342252.319264: {"book":{"asks":[[1875560000,149378000000],[1884640000,0]],"bids":[]},"depth":30,"sequence":20149236000,"symbol":"sLINKUSDT","timestamp":1625342252204283050,"type":"incremental"}
1625342252.3193521: {"book":{"asks":[[1876120000,96229000000],[1884200000,0]],"bids":[]},"depth":30,"sequence":20149236001,"symbol":"sLINKUSDT","timestamp":1625342252204310392,"type":"incremental"}
1625342252.319412: {"book":{"asks":[[1876940000,126061000000],[1884080000,0]],"bids":[]},"depth":30,"sequence":20149236002,"symbol":"sLINKUSDT","timestamp":1625342252204333401,"type":"incremental"}
1625342252.3194501: {"book":{"asks":[[1880940000,93887000000],[1883330000,0]],"bids":[]},"depth":30,"sequence":20149236003,"symbol":"sLINKUSDT","timestamp":1625342252204407294,"type":"incremental"}
1625342252.319486: {"book":{"asks":[[1875270000,59677000000],[1883130000,0]],"bids":[]},"depth":30,"sequence":20149236004,"symbol":"sLINKUSDT","timestamp":1625342252206805254,"type":"incremental"}
1625342252.319521: {"book":{"asks":[[1880300000,140699000000],[1882940000,0]],"bids":[]},"depth":30,"sequence":20149236005,"symbol":"sLINKUSDT","timestamp":1625342252206860741,"type":"incremental"}
1625342252.319555: {"book":{"asks":[[1880790000,43669000000],[1882680000,0]],"bids":[]},"depth":30,"sequence":20149236006,"symbol":"sLINKUSDT","timestamp":1625342252206901220,"type":"incremental"}
1625342252.3195899: {"book":{"asks":[[1881390000,59144000000],[1882530000,0]],"bids":[]},"depth":30,"sequence":20149236007,"symbol":"sLINKUSDT","timestamp":1625342252206935094,"type":"incremental"}
1625342252.319625: {"book":{"asks":[[1882290000,183397000000]],"bids":[]},"depth":30,"sequence":20149236008,"symbol":"sLINKUSDT","timestamp":1625342252207060713,"type":"incremental"}
1625342252.390115: {"book":{"asks":[[30120,191110]],"bids":[]},"depth":30,"sequence":4899658027,"symbol":"XTZUSD","timestamp":1625342252081204823,"type":"incremental"}
1625342252.390254: {"book":{"asks":[[30120,190210]],"bids":[]},"depth":30,"sequence":4899658028,"symbol":"XTZUSD","timestamp":1625342252081224195,"type":"incremental"}
1625342252.39032: {"book":{"asks":[[30100,79157]],"bids":[]},"depth":30,"sequence":4899658029,"symbol":"XTZUSD","timestamp":1625342252081243692,"type":"incremental"}
1625342252.3903701: {"book":{"asks":[[30100,78957]],"bids":[]},"depth":30,"sequence":4899658030,"symbol":"XTZUSD","timestamp":1625342252081260589,"type":"incremental"}
1625342252.390414: {"book":{"asks":[[30080,1877],[30390,0]],"bids":[]},"depth":30,"sequence":4899658031,"symbol":"XTZUSD","timestamp":1625342252144395017,"type":"incremental"}
1625342252.3905: {"book":{"asks":[[30090,0],[30390,3321]],"bids":[]},"depth":30,"sequence":4899658032,"symbol":"XTZUSD","timestamp":1625342252218922622,"type":"incremental"}
1625342252.39057: {"book":{"asks":[[30080,0],[30400,12518]],"bids":[]},"depth":30,"sequence":4899658033,"symbol":"XTZUSD","timestamp":1625342252269270988,"type":"incremental"}
1625342252.4895098: {"book":{"asks":[[1880540000,203000000],[1882500000,0]],"bids":[]},"depth":30,"sequence":20149236024,"symbol":"sLINKUSDT","timestamp":1625342252265285210,"type":"incremental"}
1625342252.506906: {"book":{"asks":[[119570,2783]],"bids":[]},"depth":30,"sequence":6643009501,"symbol":"ATOMUSD","timestamp":1625342252309209488,"type":"incremental"}
1625342252.507036: {"book":{"asks":[[119570,2703]],"bids":[]},"depth":30,"sequence":6643009502,"symbol":"ATOMUSD","timestamp":1625342252309300336,"type":"incremental"}
1625342252.5070999: {"book":{"asks":[[119570,2453]],"bids":[]},"depth":30,"sequence":6643009503,"symbol":"ATOMUSD","timestamp":1625342252309338910,"type":"incremental"}
1625342252.5071502: {"book":{"asks":[[119570,2587]],"bids":[]},"depth":30,"sequence":6643009504,"symbol":"ATOMUSD","timestamp":1625342252309412906,"type":"incremental"}
1625342252.565675: {"book":{"asks":[[67596000,494472000000],[67914000,0]],"bids":[]},"depth":30,"sequence":175932977,"symbol":"sGRTUSDT","timestamp":1625342252451847331,"type":"incremental"}
1625342252.566472: {"book":{"asks":[[67651000,304703000000],[67908000,0]],"bids":[]},"depth":30,"sequence":175932978,"symbol":"sGRTUSDT","timestamp":1625342252451885023,"type":"incremental"}
1625342252.566549: {"book":{"asks":[[67610000,581347000000],[67907000,0]],"bids":[]},"depth":30,"sequence":175932979,"symbol":"sGRTUSDT","timestamp":1625342252452139341,"type":"incremental"}
1625342252.5666041: {"book":{"asks":[[67625000,718821000000],[67887000,0]],"bids":[]},"depth":30,"sequence":175932980,"symbol":"sGRTUSDT","timestamp":1625342252452172081,"type":"incremental"}
1625342252.566646: {"book":{"asks":[[67751000,604603000000]],"bids":[]},"depth":30,"sequence":175932981,"symbol":"sGRTUSDT","timestamp":1625342252452200102,"type":"incremental"}
1625342252.5666728: {"book":{"asks":[[67878000,0],[67887000,512980000000]],"bids":[]},"depth":30,"sequence":175932982,"symbol":"sGRTUSDT","timestamp":1625342252452325337,"type":"incremental"}
1625342252.575155: {"book":{"asks":[[30090,4350],[30400,0]],"bids":[]},"depth":30,"sequence":4899658034,"symbol":"XTZUSD","timestamp":1625342252324775887,"type":"incremental"}
1625342252.575335: {"book":{"asks":[],"bids":[[29910,1641]]},"depth":30,"sequence":4899658038,"symbol":"XTZUSD","timestamp":1625342252419168974,"type":"incremental"}
1625342252.924394: {"book":{"asks":[[30180,770]],"bids":[]},"depth":30,"sequence":4899658130,"symbol":"XTZUSD","timestamp":1625342252814562201,"type":"incremental"}
1625342253.0363321: {"book":{"asks":[],"bids":[[50435000000,527000000]]},"depth":30,"sequence":14221233821,"symbol":"sBCHUSDT","timestamp":1625342252824730424,"type":"incremental"}
1625342253.036978: {"book":{"asks":[],"bids":[[50435000000,0],[50409000000,1893609000]]},"depth":30,"sequence":14221233822,"symbol":"sBCHUSDT","timestamp":1625342252824743661,"type":"incremental"}
1625342253.037108: {"book":{"asks":[[51022000000,3982931000]],"bids":[]},"depth":30,"sequence":14221233826,"symbol":"sBCHUSDT","timestamp":1625342252842330533,"type":"incremental"}
1625342253.106164: {"book":{"asks":[],"bids":[[67269000,375140000000]]},"depth":30,"sequence":175932992,"symbol":"sGRTUSDT","timestamp":1625342252995247728,"type":"incremental"}
1625342253.107925: {"book":{"asks":[],"bids":[[67265000,0],[66936000,568938000000]]},"depth":30,"sequence":175932993,"symbol":"sGRTUSDT","timestamp":1625342252995287693,"type":"incremental"}
1625342253.1080298: {"book":{"asks":[],"bids":[[67217000,0],[66930000,827086000000]]},"depth":30,"sequence":175932994,"symbol":"sGRTUSDT","timestamp":1625342252995298849,"type":"incremental"}
1625342253.1080792: {"book":{"asks":[],"bids":[[67211000,392571000000]]},"depth":30,"sequence":175932995,"symbol":"sGRTUSDT","timestamp":1625342252995313708,"type":"incremental"}
1625342253.1081102: {"book":{"asks":[],"bids":[[67211000,227721000000]]},"depth":30,"sequence":175932996,"symbol":"sGRTUSDT","timestamp":1625342252995342648,"type":"incremental"}
1625342253.108137: {"book":{"asks":[],"bids":[[67118000,767198000000],[66930000,0]]},"depth":30,"sequence":175932997,"symbol":"sGRTUSDT","timestamp":1625342252995465740,"type":"incremental"}
1625342253.1081731: {"book":{"asks":[],"bids":[[67095000,211750000000],[66936000,0]]},"depth":30,"sequence":175932998,"symbol":"sGRTUSDT","timestamp":1625342252995487533,"type":"incremental"}
1625342253.108213: {"book":{"asks":[],"bids":[[67095000,502443000000]]},"depth":30,"sequence":175932999,"symbol":"sGRTUSDT","timestamp":1625342252995503829,"type":"incremental"}
1625342253.1082392: {"book":{"asks":[],"bids":[[67092000,297297000000],[66950000,0]]},"depth":30,"sequence":175933000,"symbol":"sGRTUSDT","timestamp":1625342252995531578,"type":"incremental"}
1625342253.1082728: {"book":{"asks":[],"bids":[[67042000,726463000000],[66982000,0]]},"depth":30,"sequence":175933001,"symbol":"sGRTUSDT","timestamp":1625342252995557121,"type":"incremental"}
1625342253.108306: {"book":{"asks":[],"bids":[[67039000,619219000000],[66984000,0]]},"depth":30,"sequence":175933002,"symbol":"sGRTUSDT","timestamp":1625342252995575946,"type":"incremental"}
1625342253.10834: {"book":{"asks":[],"bids":[[67269000,0],[66984000,263183000000]]},"depth":30,"sequence":175933005,"symbol":"sGRTUSDT","timestamp":1625342252995758180,"type":"incremental"}
1625342253.108374: {"book":{"asks":[[30080,2343],[30390,0]],"bids":[]},"depth":30,"sequence":4899658131,"symbol":"XTZUSD","timestamp":1625342252871418371,"type":"incremental"}
1625342253.108426: {"book":{"asks":[],"bids":[[29940,23481]]},"depth":30,"sequence":4899658132,"symbol":"XTZUSD","timestamp":1625342252907703058,"type":"incremental"}
1625342253.108455: {"book":{"asks":[[30090,0],[30390,3321]],"bids":[]},"depth":30,"sequence":4899658133,"symbol":"XTZUSD","timestamp":1625342252922776754,"type":"incremental"}
1625342253.108497: {"book":{"asks":[[30080,0],[30400,12518]],"bids":[]},"depth":30,"sequence":4899658134,"symbol":"XTZUSD","timestamp":1625342252958369202,"type":"incremental"}
1625342253.165809: {"book":{"asks":[],"bids":[[67257000,0],[66982000,347658000000]]},"depth":30,"sequence":175933006,"symbol":"sGRTUSDT","timestamp":1625342252995781066,"type":"incremental"}
1625342253.1659641: {"book":{"asks":[],"bids":[[67212000,0],[66950000,710037000000]]},"depth":30,"sequence":175933007,"symbol":"sGRTUSDT","timestamp":1625342252995805744,"type":"incremental"}
1625342253.1660428: {"book":{"asks":[],"bids":[[67197000,0],[66936000,568938000000]]},"depth":30,"sequence":175933008,"symbol":"sGRTUSDT","timestamp":1625342252995818671,"type":"incremental"}
1625342253.1661088: {"book":{"asks":[],"bids":[[67115000,0],[66930000,827086000000]]},"depth":30,"sequence":175933009,"symbol":"sGRTUSDT","timestamp":1625342252995830989,"type":"incremental"}
1625342253.1661701: {"book":{"asks":[],"bids":[[67029000,0],[66919000,843829000000]]},"depth":30,"sequence":175933010,"symbol":"sGRTUSDT","timestamp":1625342252995846418,"type":"incremental"}
1625342253.1662269: {"book":{"asks":[],"bids":[[67014000,0],[66915000,709380000000]]},"depth":30,"sequence":175933011,"symbol":"sGRTUSDT","timestamp":1625342252995858396,"type":"incremental"}
1625342253.292646: {"book":{"asks":[[30090,4350],[30400,0]],"bids":[]},"depth":30,"sequence":4899658135,"symbol":"XTZUSD","timestamp":1625342253013656597,"type":"incremental"}
1625342253.292827: {"book":{"asks":[[30210,19160]],"bids":[]},"depth":30,"sequence":4899658136,"symbol":"XTZUSD","timestamp":1625342253015828750,"type":"incremental"}
1625342253.292893: {"book":{"asks":[],"bids":[[30070,55857]]},"depth":30,"sequence":4899658137,"symbol":"XTZUSD","timestamp":1625342253015865139,"type":"incremental"}
1625342253.292944: {"book":{"asks":[[30100,79277]],"bids":[]},"depth":30,"sequence":4899658138,"symbol":"XTZUSD","timestamp":1625342253015887019,"type":"incremental"}
1625342253.343908: {"book":{"asks":[],"bids":[[67116000,0],[66905000,455245000000]]},"depth":30,"sequence":175933020,"symbol":"sGRTUSDT","timestamp":1625342253102579796,"type":"incremental"}
1625342253.6117618: {"book":{"asks":[],"bids":[[67056000,2507000000],[66905000,0]]},"depth":30,"sequence":175933021,"symbol":"sGRTUSDT","timestamp":1625342253503711762,"type":"incremental"}
1625342253.661789: {"book":{"asks":[[30110,104194]],"bids":[]},"depth":30,"sequence":4899658140,"symbol":"XTZUSD","timestamp":1625342253478562344,"type":"incremental"}
1625342253.6619232: {"book":{"asks":[],"bids":[[29880,98]]},"depth":30,"sequence":4899658141,"symbol":"XTZUSD","timestamp":1625342253478604948,"type":"incremental"}
1625342253.748822: {"book":{"asks":[[1880540000,0],[1882500000,73383000000]],"bids":[]},"depth":30,"sequence":20149236075,"symbol":"sLINKUSDT","timestamp":1625342253492504508,"type":"incremental"}
1625342253.748978: {"book":{"asks":[],"bids":[[1871060000,121361000000]]},"depth":30,"sequence":20149236076,"symbol":"sLINKUSDT","timestamp":1625342253520262496,"type":"incremental"}
1625342253.878051: {"book":{"asks":[[67544000,316574000000],[67546000,258478000000],[67556000,937830000000],[67562000,269673000000],[67567000,247298000000],[67568000,402848000000],[67570000,212008000000],[67595000,303821000000],[67596000,494472000000],[67610000,581347000000],[67613000,291415000000],[67625000,718821000000],[67651000,304703000000],[67656000,234027000000],[67671000,383049000000],[67674000,427147000000],[67678000,381832000000],[67680000,335711000000],[67735000,222536000000],[67736000,264819000000],[67744000,389449000000],[67751000,604603000000],[67807000,242008000000],[67814000,767632000000],[67823000,843843000000],[67838000,867818000000],[67858000,381343000000],[67865000,261923000000],[67869000,455047000000],[67887000,512980000000]],"bids":[[67211000,227721000000],[67189000,321974000000],[67188000,346685000000],[67182000,452276000000],[67180000,270099000000],[67173000,437619000000],[67161000,454280000000],[67160000,220449000000],[67155000,394846000000],[67118000,767198000000],[67095000,502443000000],[67092000,297297000000],[67073000,411358000000],[67056000,2507000000],[67055000,404888000000],[67042000,726463000000],[67039000,619219000000],[67013000,767404000000],[67010000,471201000000],[67006000,680295000000],[66996000,632530000000],[66992000,749842000000],[66985000,262500000000],[66984000,263183000000],[66982000,347658000000],[66950000,710037000000],[66936000,568938000000],[66930000,827086000000],[66919000,843829000000],[66915000,709380000000]]},"depth":30,"sequence":175933021,"symbol":"sGRTUSDT","timestamp":1625342253503711762,"type":"snapshot"}
1625342253.9218152: {"book":{"asks":[[1880000000,203000000],[1882500000,0]],"bids":[]},"depth":30,"sequence":20149236078,"symbol":"sLINKUSDT","timestamp":1625342253708327242,"type":"incremental"}
1625342254.013325: {"book":{"asks":[],"bids":[[11349,1888],[11346,2077]]},"depth":30,"sequence":8450973595,"symbol":"ENJUSD","timestamp":1625342253798208779,"type":"incremental"}
1625342254.030942: {"book":{"asks":[],"bids":[[30020,469]]},"depth":30,"sequence":4899658494,"symbol":"XTZUSD","timestamp":1625342253797642724,"type":"incremental"}
1625342254.031075: {"book":{"asks":[[30240,1035]],"bids":[]},"depth":30,"sequence":4899658495,"symbol":"XTZUSD","timestamp":1625342253797697576,"type":"incremental"}
1625342254.031142: {"book":{"asks":[[2152700,12084]],"bids":[]},"depth":30,"sequence":4899658499,"symbol":"XMRUSD","timestamp":1625342253829441776,"type":"incremental"}
1625342254.0311968: {"book":{"asks":[],"bids":[[2152100,8255]]},"depth":30,"sequence":4899658500,"symbol":"XMRUSD","timestamp":1625342253841858199,"type":"incremental"}
1625342254.031245: {"book":{"asks":[],"bids":[[2152300,5702]]},"depth":30,"sequence":4899658501,"symbol":"XMRUSD","timestamp":1625342253859413748,"type":"incremental"}
1625342254.093576: {"book":{"asks":[],"bids":[[1870500000,0],[1863720000,66433000000]]},"depth":30,"sequence":20149236079,"symbol":"sLINKUSDT","timestamp":1625342253870863270,"type":"incremental"}
1625342254.2149582: {"book":{"asks":[],"bids":[[29950,25555]]},"depth":30,"sequence":4899658504,"symbol":"XTZUSD","timestamp":1625342253952308471,"type":"incremental"}
1625342254.215047: {"book":{"asks":[[30080,2344],[30390,0]],"bids":[]},"depth":30,"sequence":4899658505,"symbol":"XTZUSD","timestamp":1625342254012061480,"type":"incremental"}
1625342254.215116: {"book":{"asks":[[30090,0],[30390,3321]],"bids":[]},"depth":30,"sequence":4899658507,"symbol":"XTZUSD","timestamp":1625342254062834586,"type":"incremental"}
1625342254.247134: {"book":{"asks":[[2155900,2850],[2156500,7269]],"bids":[]},"depth":30,"sequence":4899658508,"symbol":"XMRUSD","timestamp":1625342254111297591,"type":"incremental"}
1625342254.39945: {"book":{"asks":[],"bids":[[29940,22771]]},"depth":30,"sequence":4899658692,"symbol":"XTZUSD","timestamp":1625342254254630648,"type":"incremental"}
1625342254.400123: {"book":{"asks":[],"bids":[[29940,22471]]},"depth":30,"sequence":4899658693,"symbol":"XTZUSD","timestamp":1625342254254672415,"type":"incremental"}
1625342254.5761: {"book":{"asks":[[769100000,13073700000]],"bids":[]},"depth":30,"sequence":146075021,"symbol":"sSUSHIUSDT","timestamp":1625342254467369757,"type":"incremental"}
1625342254.584599: {"book":{"asks":[],"bids":[[29940,22224]]},"depth":30,"sequence":4899658694,"symbol":"XTZUSD","timestamp":1625342254254688564,"type":"incremental"}
1625342254.584644: {"book":{"asks":[[30260,1201]],"bids":[]},"depth":30,"sequence":4899658696,"symbol":"XTZUSD","timestamp":1625342254423644223,"type":"incremental"}
1625342254.584672: {"book":{"asks":[],"bids":[[30070,57857]]},"depth":30,"sequence":4899658697,"symbol":"XTZUSD","timestamp":1625342254423680916,"type":"incremental"}
1625342254.7561321: {"book":{"asks":[],"bids":[[113473000,229531000000],[113003000,0]]},"depth":30,"sequence":146075022,"symbol":"sENJUSDT","timestamp":1625342254561442489,"type":"incremental"}
1625342254.756814: {"book":{"asks":[],"bids":[[113446000,0],[113003000,675107000000]]},"depth":30,"sequence":146075023,"symbol":"sENJUSDT","timestamp":1625342254561497182,"type":"incremental"}
1625342254.756902: {"book":{"asks":[],"bids":[[113414000,0],[113002000,709267000000]]},"depth":30,"sequence":146075024,"symbol":"sENJUSDT","timestamp":1625342254561528522,"type":"incremental"}
1625342254.756952: {"book":{"asks":[],"bids":[[113520000,540382000000],[113002000,0]]},"depth":30,"sequence":146075028,"symbol":"sENJUSDT","timestamp":1625342254562111853,"type":"incremental"}
1625342254.756993: {"book":{"asks":[],"bids":[[113423000,0],[113002000,709267000000]]},"depth":30,"sequence":146075029,"symbol":"sENJUSDT","timestamp":1625342254562153445,"type":"incremental"}
1625342254.769391: {"book":{"asks":[],"bids":[[29880,76]]},"depth":30,"sequence":4899658698,"symbol":"XTZUSD","timestamp":1625342254507902207,"type":"incremental"}
1625342254.769523: {"book":{"asks":[[30130,1712]],"bids":[]},"depth":30,"sequence":4899658699,"symbol":"XTZUSD","timestamp":1625342254507952242,"type":"incremental"}
1625342254.769591: {"book":{"asks":[[2155800,16793],[2156500,2540]],"bids":[]},"depth":30,"sequence":4899658700,"symbol":"XMRUSD","timestamp":1625342254604855951,"type":"incremental"}
1625342254.769658: {"book":{"asks":[],"bids":[[30050,104453]]},"depth":30,"sequence":4899658701,"symbol":"XTZUSD","timestamp":1625342254605912508,"type":"incremental"}
1625342254.769707: {"book":{"asks":[[2155300,11025]],"bids":[]},"depth":30,"sequence":4899658702,"symbol":"XMRUSD","timestamp":1625342254657034787,"type":"incremental"}
1625342254.8991559: {"book":{"asks":[[330040000,1005],[331910000,0]],"bids":[]},"depth":30,"sequence":17652792083,"symbol":"YFIUSD","timestamp":1625342254786482199,"type":"incremental"}
1625342254.899311: {"book":{"asks":[[330210000,6551],[331875000,0]],"bids":[]},"depth":30,"sequence":17652792084,"symbol":"YFIUSD","timestamp":1625342254786521550,"type":"incremental"}
1625342254.8993971: {"book":{"asks":[[330370000,4355]],"bids":[]},"depth":30,"sequence":17652792085,"symbol":"YFIUSD","timestamp":1625342254786533082,"type":"incremental"}
1625342254.8994439: {"book":{"asks":[[330370000,0],[331875000,3180]],"bids":[]},"depth":30,"sequence":17652792086,"symbol":"YFIUSD","timestamp":1625342254786547092,"type":"incremental"}
1625342254.899519: {"book":{"asks":[[331150000,2885],[331875000,0]],"bids":[]},"depth":30,"sequence":17652792087,"symbol":"YFIUSD","timestamp":1625342254786556124,"type":"incremental"}
1625342254.899559: {"book":{"asks":[[330055000,1012],[331835000,0]],"bids":[]},"depth":30,"sequence":17652792090,"symbol":"YFIUSD","timestamp":1625342254786818693,"type":"incremental"}
1625342254.920651: {"book":{"asks":[[330195000,7397]],"bids":[]},"depth":30,"sequence":17652792091,"symbol":"YFIUSD","timestamp":1625342254786885249,"type":"incremental"}
1625342254.920792: {"book":{"asks":[[331030000,0],[331835000,2999]],"bids":[]},"depth":30,"sequence":17652792092,"symbol":"YFIUSD","timestamp":1625342254786914766,"type":"incremental"}
1625342254.952683: {"book":{"asks":[[30080,0],[30400,12518]],"bids":[]},"depth":30,"sequence":4899658703,"symbol":"XTZUSD","timestamp":1625342254699454095,"type":"incremental"}
1625342254.9536371: {"book":{"asks":[[30090,4350],[30400,0]],"bids":[]},"depth":30,"sequence":4899658704,"symbol":"XTZUSD","timestamp":1625342254758182036,"type":"incremental"}
1625342255.097439: {"book":{"asks":[[330040000,985]],"bids":[]},"depth":30,"sequence":17652792264,"symbol":"YFIUSD","timestamp":1625342254886368682,"type":"incremental"}
1625342255.435454: {"book":{"asks":[],"bids":[[11349,2448]]},"depth":30,"sequence":8450973727,"symbol":"ENJUSD","timestamp":1625342255272787102,"type":"incremental"}
1625342255.458875: {"book":{"asks":[],"bids":[[30060,77504]]},"depth":30,"sequence":4899658705,"symbol":"XTZUSD","timestamp":1625342255115331584,"type":"incremental"}
1625342255.459009: {"book":{"asks":[],"bids":[[30050,103551]]},"depth":30,"sequence":4899658706,"symbol":"XTZUSD","timestamp":1625342255253036167,"type":"incremental"}
1625342255.459074: {"book":{"asks":[],"bids":[[29930,1403]]},"depth":30,"sequence":4899658707,"symbol":"XTZUSD","timestamp":1625342255318066084,"type":"incremental"}
1625342255.528123: {"book":{"asks":[[1875180000,0],[1882500000,73383000000]],"bids":[]},"depth":30,"sequence":20149236733,"symbol":"sLINKUSDT","timestamp":1625342255399042954,"type":"incremental"}
1625342255.52828: {"book":{"asks":[[1876820000,715000000],[1882500000,0]],"bids":[]},"depth":30,"sequence":20149236734,"symbol":"sLINKUSDT","timestamp":1625342255399098088,"type":"incremental"}
1625342255.643548: {"book":{"asks":[[2153600,15489]],"bids":[]},"depth":30,"sequence":4899658709,"symbol":"XMRUSD","timestamp":1625342255396153142,"type":"incremental"}
1625342255.6436381: {"book":{"asks":[],"bids":[[2152300,7367]]},"depth":30,"sequence":4899658710,"symbol":"XMRUSD","timestamp":1625342255396208041,"type":"incremental"}
1625342255.700424: {"book":{"asks":[[1876820000,96413000000]],"bids":[]},"depth":30,"sequence":20149236735,"symbol":"sLINKUSDT","timestamp":1625342255399116390,"type":"incremental"}
1625342255.702152: {"book":{"asks":[[1877310000,0],[1882500000,73383000000]],"bids":[]},"depth":30,"sequence":20149236736,"symbol":"sLINKUSDT","timestamp":1625342255399134893,"type":"incremental"}
1625342255.702323: {"book":{"asks":[[1875270000,0],[1882530000,75878000000]],"bids":[]},"depth":30,"sequence":20149236737,"symbol":"sLINKUSDT","timestamp":1625342255401177109,"type":"incremental"}
1625342255.702399: {"book":{"asks":[[1876040000,76705000000],[1882530000,0]],"bids":[]},"depth":30,"sequence":20149236738,"symbol":"sLINKUSDT","timestamp":1625342255401233656,"type":"incremental"}
1625342255.702484: {"book":{"asks":[[1877720000,0],[1882530000,75878000000]],"bids":[]},"depth":30,"sequence":20149236739,"symbol":"sLINKUSDT","timestamp":1625342255401317520,"type":"incremental"}
1625342255.702522: {"book":{"asks":[[1880300000,0],[1882680000,63902000000]],"bids":[]},"depth":30,"sequence":20149236740,"symbol":"sLINKUSDT","timestamp":1625342255401348920,"type":"incremental"}
1625342255.766794: {"book":{"asks":[[67495000,588380000000],[67887000,0]],"bids":[]},"depth":30,"sequence":175933041,"symbol":"sGRTUSDT","timestamp":1625342255657317055,"type":"incremental"}
1625342255.826813: {"book":{"asks":[],"bids":[[329360000,6228]]},"depth":30,"sequence":17652792372,"symbol":"YFIUSD","timestamp":1625342255649392952,"type":"incremental"}
1625342255.826899: {"book":{"asks":[],"bids":[[329360000,7518]]},"depth":30,"sequence":17652792373,"symbol":"YFIUSD","timestamp":1625342255649442375,"type":"incremental"}
1625342255.8277912: {"book":{"asks":[[30170,44229]],"bids":[]},"depth":30,"sequence":4899658719,"symbol":"XTZUSD","timestamp":1625342255651272274,"type":"incremental"}
1625342255.8278642: {"book":{"asks":[[30160,32513]],"bids":[]},"depth":30,"sequence":4899658720,"symbol":"XTZUSD","timestamp":1625342255651310058,"type":"incremental"}
1625342255.947274: {"book":{"asks":[[67625000,0],[67887000,512980000000]],"bids":[]},"depth":30,"sequence":175933042,"symbol":"sGRTUSDT","timestamp":1625342255657363247,"type":"incremental"}
1625342255.947383: {"book":{"asks":[[67728000,890282000000],[67887000,0]],"bids":[]},"depth":30,"sequence":175933043,"symbol":"sGRTUSDT","timestamp":1625342255657407941,"type":"incremental"}
1625342255.947434: {"book":{"asks":[[67816000,490319000000],[67869000,0]],"bids":[]},"depth":30,"sequence":175933044,"symbol":"sGRTUSDT","timestamp":1625342255657426299,"type":"incremental"}
1625342255.947476: {"book":{"asks":[[67849000,719418000000],[67865000,0]],"bids":[]},"depth":30,"sequence":175933045,"symbol":"sGRTUSDT","timestamp":1625342255657452233,"type":"incremental"}
1625342255.947514: {"book":{"asks":[[67596000,0],[67865000,261923000000]],"bids":[]},"depth":30,"sequence":175933047,"symbol":"sGRTUSDT","timestamp":1625342255658164303,"type":"incremental"}
1625342255.947551: {"book":{"asks":[[67782000,674208000000],[67865000,0]],"bids":[]},"depth":30,"sequence":175933048,"symbol":"sGRTUSDT","timestamp":1625342255658203587,"type":"incremental"}
1625342256.0126579: {"book":{"asks":[[30370,9056]],"bids":[]},"depth":30,"sequence":4899658721,"symbol":"XTZUSD","timestamp":1625342255728514664,"type":"incremental"}
1625342256.0767412: {"book":{"asks":[[119410,3732]],"bids":[]},"depth":30,"sequence":6643010292,"symbol":"ATOMUSD","timestamp":1625342255824506061,"type":"incremental"}
1625342256.0768409: {"book":{"asks":[[119490,3235]],"bids":[]},"depth":30,"sequence":6643010293,"symbol":"ATOMUSD","timestamp":1625342255824548910,"type":"incremental"}
1625342256.076881: {"book":{"asks":[[119510,994],[119760,0]],"bids":[]},"depth":30,"sequence":6643010294,"symbol":"ATOMUSD","timestamp":1625342255824579673,"type":"incremental"}
1625342256.076941: {"book":{"asks":[[119510,2808]],"bids":[]},"depth":30,"sequence":6643010295,"symbol":"ATOMUSD","timestamp":1625342255824656473,"type":"incremental"}
1625342256.076972: {"book":{"asks":[[119680,1748]],"bids":[]},"depth":30,"sequence":6643010296,"symbol":"ATOMUSD","timestamp":1625342255824712289,"type":"incremental"}
1625342256.076999: {"book":{"asks":[[119490,5827]],"bids":[]},"depth":30,"sequence":6643010387,"symbol":"ATOMUSD","timestamp":1625342255936061447,"type":"incremental"}
1625342256.077025: {"book":{"asks":[[119560,1660]],"bids":[]},"depth":30,"sequence":6643010388,"symbol":"ATOMUSD","timestamp":1625342255936100091,"type":"incremental"}
1625342256.077051: {"book":{"asks":[[119600,5603],[119740,0]],"bids":[]},"depth":30,"sequence":6643010389,"symbol":"ATOMUSD","timestamp":1625342255936114681,"type":"incremental"}
1625342256.196069: {"book":{"asks":[[30240,1085]],"bids":[]},"depth":30,"sequence":4899658724,"symbol":"XTZUSD","timestamp":1625342256028497516,"type":"incremental"}
1625342256.1967459: {"book":{"asks":[],"bids":[[2152100,7702]]},"depth":30,"sequence":4899658725,"symbol":"XMRUSD","timestamp":1625342256074201594,"type":"incremental"}
1625342256.235779: {"book":{"asks":[],"bids":[[119110,1149],[119070,4069]]},"depth":30,"sequence":6643010476,"symbol":"ATOMUSD","timestamp":1625342256082681046,"type":"incremental"}
1625342256.3821518: {"book":{"asks":[],"bids":[[2152300,7920]]},"depth":30,"sequence":4899658726,"symbol":"XMRUSD","timestamp":1625342256074910025,"type":"incremental"}
1625342256.38223: {"book":{"asks":[[30080,2345],[30390,0]],"bids":[]},"depth":30,"sequence":4899658727,"symbol":"XTZUSD","timestamp":1625342256089116560,"type":"incremental"}
1625342256.382287: {"book":{"asks":[[30090,0],[30390,3321]],"bids":[]},"depth":30,"sequence":4899658728,"symbol":"XTZUSD","timestamp":1625342256167305262,"type":"incremental"}
1625342256.415375: {"book":{"asks":[[119630,4106]],"bids":[]},"depth":30,"sequence":6643010479,"symbol":"ATOMUSD","timestamp":1625342256172532225,"type":"incremental"}
1625342256.4154649: {"book":{"asks":[],"bids":[[119100,1923]]},"depth":30,"sequence":6643010483,"symbol":"ATOMUSD","timestamp":1625342256279822750,"type":"incremental"}
1625342256.4155068: {"book":{"asks":[[119630,4466]],"bids":[]},"depth":30,"sequence":6643010484,"symbol":"ATOMUSD","timestamp":1625342256279900806,"type":"incremental"}
1625342256.41554: {"book":{"asks":[[119400,5092]],"bids":[]},"depth":30,"sequence":6643010485,"symbol":"ATOMUSD","timestamp":1625342256279948024,"type":"incremental"}
1625342256.41557: {"book":{"asks":[[119400,4310]],"bids":[]},"depth":30,"sequence":6643010486,"symbol":"ATOMUSD","timestamp":1625342256280038391,"type":"incremental"}
1625342256.415599: {"book":{"asks":[[119400,4410]],"bids":[]},"depth":30,"sequence":6643010487,"symbol":"ATOMUSD","timestamp":1625342256280067711,"type":"incremental"}
1625342256.474902: {"book":{"asks":[],"bids":[[119170,2920],[119070,3647]]},"depth":30,"sequence":6643010488,"symbol":"ATOMUSD","timestamp":1625342256306388208,"type":"incremental"}
1625342256.475051: {"book":{"asks":[],"bids":[[67208000,376881000000],[66915000,0]]},"depth":30,"sequence":175933051,"symbol":"sGRTUSDT","timestamp":1625342256366164978,"type":"incremental"}
1625342256.5044951: {"book":{"asks":[],"bids":[[11360,7654]]},"depth":30,"sequence":8450974038,"symbol":"ENJUSD","timestamp":1625342256382547839,"type":"incremental"}
1625342256.5045881: {"book":{"asks":[],"bids":[[11360,6854]]},"depth":30,"sequence":8450974039,"symbol":"ENJUSD","timestamp":1625342256382594459,"type":"incremental"}
1625342256.504628: {"book":{"asks":[],"bids":[[11360,5894]]},"depth":30,"sequence":8450974040,"symbol":"ENJUSD","timestamp":1625342256382615117,"type":"incremental"}
1625342256.504661: {"book":{"asks":[],"bids":[[11359,6633]]},"depth":30,"sequence":8450974041,"symbol":"ENJUSD","timestamp":1625342256382695084,"type":"incremental"}
1625342256.50469: {"book":{"asks":[],"bids":[[11360,0],[11324,1962]]},"depth":30,"sequence":8450974068,"symbol":"ENJUSD","timestamp":1625342256384430718,"type":"incremental"}
1625342256.504749: {"book":{"asks":[],"bids":[[11359,0],[11323,4649]]},"depth":30,"sequence":8450974070,"symbol":"ENJUSD","timestamp":1625342256384575307,"type":"incremental"}
1625342256.5047941: {"book":{"asks":[],"bids":[[11358,6236]]},"depth":30,"sequence":8450974071,"symbol":"ENJUSD","timestamp":1625342256384594576,"type":"incremental"}
1625342256.504822: {"book":{"asks":[],"bids":[[11355,4223],[11323,0]]},"depth":30,"sequence":8450974074,"symbol":"ENJUSD","timestamp":1625342256384746513,"type":"incremental"}
1625342256.504865: {"book":{"asks":[[11378,0],[11426,2819]],"bids":[]},"depth":30,"sequence":8450974153,"symbol":"ENJUSD","timestamp":1625342256387267708,"type":"incremental"}
1625342256.504909: {"book":{"asks":[[11392,3722]],"bids":[]},"depth":30,"sequence":8450974193,"symbol":"ENJUSD","timestamp":1625342256388831338,"type":"incremental"}
1625342256.504937: {"book":{"asks":[[11400,1020]],"bids":[]},"depth":30,"sequence":8450974194,"symbol":"ENJUSD","timestamp":1625342256388843822,"type":"incremental"}
1625342256.5049632: {"book":{"asks":[[11381,7282]],"bids":[]},"depth":30,"sequence":8450974236,"symbol":"ENJUSD","timestamp":1625342256389884284,"type":"incremental"}
1625342256.5049868: {"book":{"asks":[[11386,8258]],"bids":[]},"depth":30,"sequence":8450974237,"symbol":"ENJUSD","timestamp":1625342256389900467,"type":"incremental"}
1625342256.5662541: {"book":{"asks":[[30080,0],[30400,12518]],"bids":[]},"depth":30,"sequence":4899658731,"symbol":"XTZUSD","timestamp":1625342256406385193,"type":"incremental"}
1625342256.624181: {"book":{"asks":[[11386,6676]],"bids":[]},"depth":30,"sequence":8450974238,"symbol":"ENJUSD","timestamp":1625342256389919563,"type":"incremental"}
1625342256.640842: {"book":{"asks":[[30300,2295]],"bids":[]},"depth":30,"sequence":4899658823,"symbol":"XTZUSD","timestamp":1625342256443540204,"type":"incremental"}
1625342256.64179: {"book":{"asks":[[30100,80247]],"bids":[]},"depth":30,"sequence":4899658824,"symbol":"XTZUSD","timestamp":1625342256443581914,"type":"incremental"}
1625342256.641904: {"book":{"asks":[],"bids":[[30060,77841]]},"depth":30,"sequence":4899658826,"symbol":"XTZUSD","timestamp":1625342256459495690,"type":"incremental"}
1625342256.64197: {"book":{"asks":[[30090,4350],[30400,0]],"bids":[]},"depth":30,"sequence":4899658828,"symbol":"XTZUSD","timestamp":1625342256467525538,"type":"incremental"}
1625342256.654523: {"book":{"asks":[],"bids":[[67155000,0],[66915000,709380000000]]},"depth":30,"sequence":175933052,"symbol":"sGRTUSDT","timestamp":1625342256366217916,"type":"incremental"}
1625342256.6546292: {"book":{"asks":[],"bids":[[67095000,211750000000]]},"depth":30,"sequence":175933053,"symbol":"sGRTUSDT","timestamp":1625342256366230399,"type":"incremental"}
1625342256.654666: {"book":{"asks":[],"bids":[[67195000,320867000000],[66915000,0]]},"depth":30,"sequence":175933054,"symbol":"sGRTUSDT","timestamp":1625342256367079070,"type":"incremental"}
1625342256.654709: {"book":{"asks":[],"bids":[[67129000,502448000000],[66919000,0]]},"depth":30,"sequence":175933055,"symbol":"sGRTUSDT","timestamp":1625342256367134200,"type":"incremental"}
1625342256.654749: {"book":{"asks":[],"bids":[[67077000,717262000000],[66930000,0]]},"depth":30,"sequence":175933056,"symbol":"sGRTUSDT","timestamp":1625342256367210680,"type":"incremental"}
1625342256.654784: {"book":{"asks":[],"bids":[[67062000,682490000000],[66936000,0]]},"depth":30,"sequence":175933057,"symbol":"sGRTUSDT","timestamp":1625342256367294506,"type":"incremental"}
1625342256.7578912: {"book":{"asks":[[11377,99],[11426,0]],"bids":[]},"depth":30,"sequence":8450974467,"symbol":"ENJUSD","timestamp":1625342256524702806,"type":"incremental"}
1625342256.89761: {"book":{"asks":[],"bids":[[119170,2498],[119090,2248]]},"depth":30,"sequence":6643010769,"symbol":"ATOMUSD","timestamp":1625342256749598793,"type":"incremental"}
1625342256.921008: {"book":{"asks":[],"bids":[[67056000,0],[66936000,568938000000]]},"depth":30,"sequence":175933067,"symbol":"sGRTUSDT","timestamp":1625342256811999676,"type":"incremental"}
1625342256.9826071: {"book":{"asks":[],"bids":[[1871010000,0],[1863470000,94647000000]]},"depth":30,"sequence":20149236780,"symbol":"sLINKUSDT","timestamp":1625342256878318030,"type":"incremental"}
1625342257.0196512: {"book":{"asks":[[114094000,242002000000],[114311000,0]],"bids":[]},"depth":30,"sequence":146075052,"symbol":"sENJUSDT","timestamp":1625342256873246579,"type":"incremental"}
1625342257.0197399: {"book":{"asks":[[114260000,616860000000],[114310000,0]],"bids":[]},"depth":30,"sequence":146075053,"symbol":"sENJUSDT","timestamp":1625342256873295820,"type":"incremental"}
1625342257.019779: {"book":{"asks":[[114274000,0],[114310000,576546000000]],"bids":[]},"depth":30,"sequence":146075054,"symbol":"sENJUSDT","timestamp":1625342256873320735,"type":"incremental"}
1625342257.0424929: {"book":{"asks":[],"bids":[[11349,1560],[11345,4754]]},"depth":30,"sequence":8450974836,"symbol":"ENJUSD","timestamp":1625342256907373217,"type":"incremental"}
1625342257.07107: {"book":{"asks":[[330040000,981]],"bids":[]},"depth":30,"sequence":17652793109,"symbol":"YFIUSD","timestamp":1625342256796568099,"type":"incremental"}
1625342257.1073642: {"book":{"asks":[],"bids":[[119170,0],[118760,670]]},"depth":30,"sequence":6643010773,"symbol":"ATOMUSD","timestamp":1625342256851785843,"type":"incremental"}
1625342257.107533: {"book":{"asks":[],"bids":[[119050,3599]]},"depth":30,"sequence":6643010774,"symbol":"ATOMUSD","timestamp":1625342256851825555,"type":"incremental"}
1625342257.107597: {"book":{"asks":[],"bids":[[118980,7364]]},"depth":30,"sequence":6643010775,"symbol":"ATOMUSD","timestamp":1625342256851911287,"type":"incremental"}
1625342257.107648: {"book":{"asks":[],"bids":[[119040,7750]]},"depth":30,"sequence":6643010831,"symbol":"ATOMUSD","timestamp":1625342256854709543,"type":"incremental"}
1625342257.121013: {"book":{"asks":[],"bids":[[29890,1448]]},"depth":30,"sequence":4899659308,"symbol":"XTZUSD","timestamp":1625342256991471740,"type":"incremental"}
1625342257.121143: {"book":{"asks":[],"bids":[[30020,817]]},"depth":30,"sequence":4899659309,"symbol":"XTZUSD","timestamp":1625342256991511092,"type":"incremental"}
1625342257.15226: {"book":{"asks":[],"bids":[[1870800000,0],[1863160000,72981000000]]},"depth":30,"sequence":20149236781,"symbol":"sLINKUSDT","timestamp":1625342256878362061,"type":"incremental"}
1625342257.152422: {"book":{"asks":[],"bids":[[1864430000,0],[1862990000,48363000000]]},"depth":30,"sequence":20149236782,"symbol":"sLINKUSDT","timestamp":1625342256878388485,"type":"incremental"}
1625342257.1524968: {"book":{"asks":[],"bids":[[1871060000,0],[1862830000,88015000000]]},"depth":30,"sequence":20149236788,"symbol":"sLINKUSDT","timestamp":1625342256879446022,"type":"incremental"}
1625342257.1525388: {"book":{"asks":[],"bids":[[1870060000,0],[1862730000,80211000000]]},"depth":30,"sequence":20149236789,"symbol":"sLINKUSDT","timestamp":1625342256879498121,"type":"incremental"}
1625342257.152577: {"book":{"asks":[],"bids":[[1870020000,102700000000]]},"depth":30,"sequence":20149236790,"symbol":"sLINKUSDT","timestamp":1625342256879605768,"type":"incremental"}
1625342257.152603: {"book":{"asks":[],"bids":[[1870020000,0],[1862600000,53784000000]]},"depth":30,"sequence":20149236791,"symbol":"sLINKUSDT","timestamp":1625342256879637055,"type":"incremental"}
1625342257.152637: {"book":{"asks":[],"bids":[[1868740000,0],[1862570000,67123000000]]},"depth":30,"sequence":20149236792,"symbol":"sLINKUSDT","timestamp":1625342256879678304,"type":"incremental"}
1625342257.1526709: {"book":{"asks":[],"bids":[[1868700000,0],[1861530000,81938000000]]},"depth":30,"sequence":20149236793,"symbol":"sLINKUSDT","timestamp":1625342256879703034,"type":"incremental"}
1625342257.152705: {"book":{"asks":[],"bids":[[1867770000,169156000000],[1861530000,0]]},"depth":30,"sequence":20149236794,"symbol":"sLINKUSDT","timestamp":1625342256879731865,"type":"incremental"}
1625342257.152739: {"book":{"asks":[],"bids":[[1867020000,154356000000],[1862570000,0]]},"depth":30,"sequence":20149236795,"symbol":"sLINKUSDT","timestamp":1625342256879758343,"type":"incremental"}
1625342257.1527731: {"book":{"asks":[],"bids":[[1862830000,0],[1862570000,67123000000]]},"depth":30,"sequence":20149236796,"symbol":"sLINKUSDT","timestamp":1625342256879787723,"type":"incremental"}
1625342257.153114: {"book":{"asks":[],"bids":[[11361,0],[11323,4649]]},"depth":30,"sequence":8450974838,"symbol":"ENJUSD","timestamp":1625342256921570003,"type":"incremental"}
1625342257.15483: {"book":{"asks":[[11366,1030],[11368,43],[11425,0]],"bids":[]},"depth":30,"sequence":8450974843,"symbol":"ENJUSD","timestamp":1625342256981603007,"type":"incremental"}
1625342257.1987698: {"book":{"asks":[],"bids":[[113473000,0],[112990000,615894000000]]},"depth":30,"sequence":146075055,"symbol":"sENJUSDT","timestamp":1625342256912280880,"type":"incremental"}
1625342257.1997461: {"book":{"asks":[],"bids":[[113466000,0],[112984000,731866000000]]},"depth":30,"sequence":146075056,"symbol":"sENJUSDT","timestamp":1625342256912334157,"type":"incremental"}
1625342257.199796: {"book":{"asks":[],"bids":[[113465000,0],[112981000,174150000000]]},"depth":30,"sequence":146075057,"symbol":"sENJUSDT","timestamp":1625342256912351713,"type":"incremental"}
1625342257.19983: {"book":{"asks":[],"bids":[[113404000,319769000000],[112981000,0]]},"depth":30,"sequence":146075058,"symbol":"sENJUSDT","timestamp":1625342256912363166,"type":"incremental"}
1625342257.199858: {"book":{"asks":[],"bids":[[113520000,0],[112981000,174150000000]]},"depth":30,"sequence":146075059,"symbol":"sENJUSDT","timestamp":1625342256912841891,"type":"incremental"}
1625342257.199884: {"book":{"asks":[],"bids":[[113500000,0],[112976000,112017000000]]},"depth":30,"sequence":146075060,"symbol":"sENJUSDT","timestamp":1625342256912881857,"type":"incremental"}
1625342257.199907: {"book":{"asks":[],"bids":[[113456000,256655000000],[112976000,0]]},"depth":30,"sequence":146075061,"symbol":"sENJUSDT","timestamp":1625342256912970813,"type":"incremental"}
1625342257.199931: {"book":{"asks":[],"bids":[[113456000,466182000000]]},"depth":30,"sequence":146075062,"symbol":"sENJUSDT","timestamp":1625342256913008710,"type":"incremental"}
1625342257.199948: {"book":{"asks":[],"bids":[[113414000,415280000000],[112981000,0]]},"depth":30,"sequence":146075063,"symbol":"sENJUSDT","timestamp":1625342256913028676,"type":"incremental"}
1625342257.246256: {"book":{"asks":[],"bids":[[11358,6436]]},"depth":30,"sequence":8450974927,"symbol":"ENJUSD","timestamp":1625342257093405445,"type":"incremental"}
1625342257.281746: {"book":{"asks":[],"bids":[[29900,7353]]},"depth":30,"sequence":4899659310,"symbol":"XTZUSD","timestamp":1625342257009305723,"type":"incremental"}
1625342257.281826: {"book":{"asks":[],"bids":[[30000,34866]]},"depth":30,"sequence":4899659311,"symbol":"XTZUSD","timestamp":1625342257009348282,"type":"incremental"}
1625342257.281856: {"book":{"asks":[[2152700,12224]],"bids":[]},"depth":30,"sequence":4899659312,"symbol":"XMRUSD","timestamp":1625342257016144387,"type":"incremental"}
1625342257.281885: {"book":{"asks":[[30080,2365],[30390,0]],"bids":[]},"depth":30,"sequence":4899659313,"symbol":"XTZUSD","timestamp":1625342257046764750,"type":"incremental"}
1625342257.2819352: {"book":{"asks":[[30120,186615]],"bids":[]},"depth":30,"sequence":4899659314,"symbol":"XTZUSD","timestamp":1625342257086783077,"type":"incremental"}
1625342257.28196: {"book":{"asks":[],"bids":[[30040,3877]]},"depth":30,"sequence":4899659315,"symbol":"XTZUSD","timestamp":1625342257088430436,"type":"incremental"}
1625342257.281982: {"book":{"asks":[[30090,0],[30390,3321]],"bids":[]},"depth":30,"sequence":4899659316,"symbol":"XTZUSD","timestamp":1625342257128120911,"type":"incremental"}
1625342257.282017: {"book":{"asks":[],"bids":[[29900,8053]]},"depth":30,"sequence":4899659317,"symbol":"XTZUSD","timestamp":1625342257136842862,"type":"incremental"}
1625342257.282039: {"book":{"asks":[],"bids":[[30030,101901]]},"depth":30,"sequence":4899659318,"symbol":"XTZUSD","timestamp":1625342257136884912,"type":"incremental"}
1625342257.2820601: {"book":{"asks":[[30080,0],[30400,12518]],"bids":[]},"depth":30,"sequence":4899659319,"symbol":"XTZUSD","timestamp":1625342257137603404,"type":"incremental"}
1625342257.303586: {"book":{"asks":[[2152700,11940]],"bids":[]},"depth":30,"sequence":4899659320,"symbol":"XMRUSD","timestamp":1625342257138318669,"type":"incremental"}
1625342257.313067: {"book":{"asks":[],"bids":[[67063000,2506000000],[66936000,0]]},"depth":30,"sequence":175933068,"symbol":"sGRTUSDT","timestamp":1625342257205168440,"type":"incremental"}
1625342257.4527638: {"book":{"asks":[[30120,190210]],"bids":[]},"depth":30,"sequence":4899659322,"symbol":"XTZUSD","timestamp":1625342257188118621,"type":"incremental"}
1625342257.453453: {"book":{"asks":[],"bids":[[30040,7472]]},"depth":30,"sequence":4899659323,"symbol":"XTZUSD","timestamp":1625342257189755668,"type":"incremental"}
1625342257.453554: {"book":{"asks":[],"bids":[[29830,19898]]},"depth":30,"sequence":4899659324,"symbol":"XTZUSD","timestamp":1625342257207354911,"type":"incremental"}
1625342257.4536161: {"book":{"asks":[[30090,4352],[30400,0]],"bids":[]},"depth":30,"sequence":4899659325,"symbol":"XTZUSD","timestamp":1625342257230919429,"type":"incremental"}
1625342257.500725: {"book":{"asks":[[51030000000,942000000],[51086000000,0]],"bids":[]},"depth":30,"sequence":14221236036,"symbol":"sBCHUSDT","timestamp":1625342257247918405,"type":"incremental"}
1625342257.501366: {"book":{"asks":[[51030000000,2660061000]],"bids":[]},"depth":30,"sequence":14221236037,"symbol":"sBCHUSDT","timestamp":1625342257247957815,"type":"incremental"}
1625342257.6745942: {"book":{"asks":[[1880000000,0],[1882940000,64501000000]],"bids":[]},"depth":30,"sequence":20149236813,"symbol":"sLINKUSDT","timestamp":1625342257412310534,"type":"incremental"}
1625342257.8486311: {"book":{"asks":[[1878760000,203000000],[1882940000,0]],"bids":[]},"depth":30,"sequence":20149236815,"symbol":"sLINKUSDT","timestamp":1625342257624735117,"type":"incremental"}
1625342257.858837: {"book":{"asks":[],"bids":[[30010,23490]]},"depth":30,"sequence":4899659413,"symbol":"XTZUSD","timestamp":1625342257699708709,"type":"incremental"}
1625342257.858969: {"book":{"asks":[],"bids":[[30040,6192]]},"depth":30,"sequence":4899659518,"symbol":"XTZUSD","timestamp":1625342257716719708,"type":"incremental"}
1625342257.8590322: {"book":{"asks":[[30130,2722]],"bids":[]},"depth":30,"sequence":4899659519,"symbol":"XTZUSD","timestamp":1625342257716733438,"type":"incremental"}
1625342257.8590841: {"book":{"asks":[],"bids":[[2152100,14013]]},"depth":30,"sequence":4899659600,"symbol":"XMRUSD","timestamp":1625342257720217651,"type":"incremental"}
1625342257.859157: {"book":{"asks":[],"bids":[[2151500,2130]]},"depth":30,"sequence":4899659601,"symbol":"XMRUSD","timestamp":1625342257720228009,"type":"incremental"}
1625342257.859186: {"book":{"asks":[],"bids":[[2147200,11721]]},"depth":30,"sequence":4899659602,"symbol":"XMRUSD","timestamp":1625342257720240751,"type":"incremental"}
1625342257.859212: {"book":{"asks":[],"bids":[[2147200,16029]]},"depth":30,"sequence":4899659603,"symbol":"XMRUSD","timestamp":1625342257720253608,"type":"incremental"}
1625342257.9602911: {"book":{"asks":[[114266000,0],[114311000,491169000000]],"bids":[]},"depth":30,"sequence":146075067,"symbol":"sENJUSDT","timestamp":1625342257851111362,"type":"incremental"}
1625342258.0420449: {"book":{"asks":[[30080,3391],[30390,0]],"bids":[]},"depth":30,"sequence":4899659757,"symbol":"XTZUSD","timestamp":1625342257756733774,"type":"incremental"}
1625342258.042219: {"book":{"asks":[[30090,0],[30390,3321]],"bids":[]},"depth":30,"sequence":4899659759,"symbol":"XTZUSD","timestamp":1625342257845199861,"type":"incremental"}
1625342258.04231: {"book":{"asks":[[30080,0],[30400,12518]],"bids":[]},"depth":30,"sequence":4899659761,"symbol":"XTZUSD","timestamp":1625342257852616279,"type":"incremental"}
1625342258.2260349: {"book":{"asks":[[30090,4352],[30400,0]],"bids":[]},"depth":30,"sequence":4899659762,"symbol":"XTZUSD","timestamp":1625342257945396913,"type":"incremental"}
1625342258.3783438: {"book":{"asks":[[114259000,4806000000],[114311000,0]],"bids":[]},"depth":30,"sequence":146075068,"symbol":"sENJUSDT","timestamp":1625342258226297845,"type":"incremental"}
1625342258.582417: {"book":{"asks":[[11377,0],[11425,5324]],"bids":[]},"depth":30,"sequence":8450975272,"symbol":"ENJUSD","timestamp":1625342258479874466,"type":"incremental"}
1625342258.59451: {"book":{"asks":[],"bids":[[30050,103511]]},"depth":30,"sequence":4899659768,"symbol":"XTZUSD","timestamp":1625342258404556025,"type":"incremental"}
1625342258.595723: {"book":{"asks":[],"bids":[[30050,103423]]},"depth":30,"sequence":4899659769,"symbol":"XTZUSD","timestamp":1625342258404605627,"type":"incremental"}
1625342258.779095: {"book":{"asks":[],"bids":[[29860,354]]},"depth":30,"sequence":4899659773,"symbol":"XTZUSD","timestamp":1625342258479343334,"type":"incremental"}
1625342258.779982: {"book":{"asks":[],"bids":[[29950,25035]]},"depth":30,"sequence":4899659774,"symbol":"XTZUSD","timestamp":1625342258479372814,"type":"incremental"}
1625342258.7800162: {"book":{"asks":[],"bids":[[2152100,13698]]},"depth":30,"sequence":4899659775,"symbol":"XMRUSD","timestamp":1625342258552055556,"type":"incremental"}
1625342258.78004: {"book":{"asks":[],"bids":[[2151500,2445]]},"depth":30,"sequence":4899659776,"symbol":"XMRUSD","timestamp":1625342258574981183,"type":"incremental"}
1625342258.822895: {"book":{"asks":[[1875560000,0],[1882940000,64501000000]],"bids":[]},"depth":30,"sequence":20149236836,"symbol":"sLINKUSDT","timestamp":1625342258647145157,"type":"incremental"}
1625342258.825513: {"book":{"asks":[[1875580000,120764000000],[1882940000,0]],"bids":[]},"depth":30,"sequence":20149236837,"symbol":"sLINKUSDT","timestamp":1625342258647182478,"type":"incremental"}
1625342258.825574: {"book":{"asks":[[1880310000,0],[1882940000,64501000000]],"bids":[]},"depth":30,"sequence":20149236838,"symbol":"sLINKUSDT","timestamp":1625342258647200820,"type":"incremental"}
1625342258.8256068: {"book":{"asks":[[1874890000,136193000000],[1882940000,0]],"bids":[]},"depth":30,"sequence":20149236842,"symbol":"sLINKUSDT","timestamp":1625342258649627217,"type":"incremental"}
1625342258.825635: {"book":{"asks":[[1875540000,114027000000],[1882680000,0]],"bids":[]},"depth":30,"sequence":20149236843,"symbol":"sLINKUSDT","timestamp":1625342258649696142,"type":"incremental"}
1625342258.82566: {"book":{"asks":[[1875590000,65181000000],[1882530000,0]],"bids":[]},"depth":30,"sequence":20149236844,"symbol":"sLINKUSDT","timestamp":1625342258649732080,"type":"incremental"}
1625342258.825684: {"book":{"asks":[[1875740000,116804000000],[1882500000,0]],"bids":[]},"depth":30,"sequence":20149236845,"symbol":"sLINKUSDT","timestamp":1625342258649816113,"type":"incremental"}
1625342258.825707: {"book":{"asks":[],"bids":[[67211000,218571000000]]},"depth":30,"sequence":175933089,"symbol":"sGRTUSDT","timestamp":1625342258716332549,"type":"incremental"}
1625342258.926686: {"book":{"asks":[[11374,99],[11425,0]],"bids":[]},"depth":30,"sequence":8450975489,"symbol":"ENJUSD","timestamp":1625342258773720380,"type":"incremental"}
1625342258.963464: {"book":{"asks":[],"bids":[[30010,22840]]},"depth":30,"sequence":4899659777,"symbol":"XTZUSD","timestamp":1625342258785325867,"type":"incremental"}
1625342258.9645782: {"book":{"asks":[],"bids":[[30010,20940]]},"depth":30,"sequence":4899659778,"symbol":"XTZUSD","timestamp":1625342258785359488,"type":"incremental"}
1625342258.9646358: {"book":{"asks":[],"bids":[[30050,103658]]},"depth":30,"sequence":4899659779,"symbol":"XTZUSD","timestamp":1625342258785371561,"type":"incremental"}
1625342258.9646678: {"book":{"asks":[],"bids":[[30070,55857]]},"depth":30,"sequence":4899659780,"symbol":"XTZUSD","timestamp":1625342258785383779,"type":"incremental"}
1625342259.0045528: {"book":{"asks":[[67501000,479541000000],[67858000,0]],"bids":[]},"depth":30,"sequence":175933091,"symbol":"sGRTUSDT","timestamp":1625342258872904642,"type":"incremental"}
1625342259.0860538: {"book":{"asks":[],"bids":[[119140,2909]]},"depth":30,"sequence":6643011738,"symbol":"ATOMUSD","timestamp":1625342258837205114,"type":"incremental"}
1625342259.086148: {"book":{"asks":[[119600,5638]],"bids":[]},"depth":30,"sequence":6643011739,"symbol":"ATOMUSD","timestamp":1625342258837246843,"type":"incremental"}
1625342259.149417: {"book":{"asks":[[30130,3252]],"bids":[]},"depth":30,"sequence":4899659784,"symbol":"XTZUSD","timestamp":1625342258922565449,"type":"incremental"}
1625342259.2866821: {"book":{"asks":[],"bids":[[30040,6208]]},"depth":30,"sequence":4899659786,"symbol":"XTZUSD","timestamp":1625342259061892032,"type":"incremental"}
1625342259.334055: {"book":{"asks":[[30080,3300],[30390,0]],"bids":[]},"depth":30,"sequence":4899659888,"symbol":"XTZUSD","timestamp":1625342259178378327,"type":"incremental"}
1625342259.334229: {"book":{"asks":[],"bids":[[2151700,0],[2145000,1400]]},"depth":30,"sequence":4899659889,"symbol":"XMRUSD","timestamp":1625342259199823351,"type":"incremental"}
1625342259.3896792: {"book":{"asks":[],"bids":[[328290000,6006]]},"depth":30,"sequence":17652793775,"symbol":"YFIUSD","timestamp":1625342259229533161,"type":"incremental"}
1625342259.390548: {"book":{"asks":[],"bids":[[328290000,3006]]},"depth":30,"sequence":17652793776,"symbol":"YFIUSD","timestamp":1625342259229569199,"type":"incremental"}
1625342259.390644: {"book":{"asks":[],"bids":[[328875000,3910],[328095000,0]]},"depth":30,"sequence":17652793787,"symbol":"YFIUSD","timestamp":1625342259230432178,"type":"incremental"}
1625342259.390742: {"book":{"asks":[],"bids":[[328875000,18483]]},"depth":30,"sequence":17652793788,"symbol":"YFIUSD","timestamp":1625342259230485457,"type":"incremental"}
1625342259.3907928: {"book":{"asks":[],"bids":[[329360000,6228]]},"depth":30,"sequence":17652793913,"symbol":"YFIUSD","timestamp":1625342259235064510,"type":"incremental"}
1625342259.3908339: {"book":{"asks":[],"bids":[[329360000,6128]]},"depth":30,"sequence":17652793914,"symbol":"YFIUSD","timestamp":1625342259235161877,"type":"incremental"}
1625342259.390871: {"book":{"asks":[],"bids":[[329360000,5488]]},"depth":30,"sequence":17652793915,"symbol":"YFIUSD","timestamp":1625342259235186935,"type":"incremental"}
1625342259.407716: {"book":{"asks":[[30090,0],[30390,3321]],"bids":[]},"depth":30,"sequence":4899659890,"symbol":"XTZUSD","timestamp":1625342259275251972,"type":"incremental"}
1625342259.442732: {"book":{"asks":[],"bids":[[119150,1700]]},"depth":30,"sequence":6643012132,"symbol":"ATOMUSD","timestamp":1625342259322329136,"type":"incremental"}
1625342259.518076: {"book":{"asks":[[30080,0],[30400,12518]],"bids":[]},"depth":30,"sequence":4899660078,"symbol":"XTZUSD","timestamp":1625342259326695136,"type":"incremental"}
1625342259.5622861: {"book":{"asks":[[30090,4352],[30400,0]],"bids":[]},"depth":30,"sequence":4899660163,"symbol":"XTZUSD","timestamp":1625342259392907870,"type":"incremental"}
1625342259.562459: {"book":{"asks":[[30200,17998]],"bids":[]},"depth":30,"sequence":4899660165,"symbol":"XTZUSD","timestamp":1625342259403485886,"type":"incremental"}
1625342259.582803: {"book":{"asks":[],"bids":[[113456000,465092000000]]},"depth":30,"sequence":146075070,"symbol":"sENJUSDT","timestamp":1625342259351245614,"type":"incremental"}
1625342259.619803: {"book":{"asks":[],"bids":[[119150,0],[118740,6071]]},"depth":30,"sequence":6643012134,"symbol":"ATOMUSD","timestamp":1625342259336437487,"type":"incremental"}
1625342259.6199281: {"book":{"asks":[],"bids":[[119140,2829]]},"depth":30,"sequence":6643012136,"symbol":"ATOMUSD","timestamp":1625342259379533286,"type":"incremental"}
1625342259.685482: {"book":{"asks":[[113913000,382346000000],[113923000,387293000000],[113930000,290686000000],[113939000,281113000000],[113940000,237524000000],[113944000,342038000000],[113964000,365390000000],[113969000,449215000000],[113973000,322750000000],[113999000,311593000000],[114031000,265536000000],[114035000,213403000000],[114041000,235305000000],[114065000,266914000000],[114074000,433381000000],[114083000,224094000000],[114094000,242002000000],[114106000,413844000000],[114108000,384027000000],[114113000,258938000000],[114259000,4806000000],[114260000,616860000000],[114267000,751593000000],[114275000,416276000000],[114285000,447576000000],[114286000,434519000000],[114288000,294000000000],[114307000,523548000000],[114309000,433371000000],[114310000,576546000000]],"bids":[[113456000,465092000000],[113452000,546155000000],[113444000,303513000000],[113414000,415280000000],[113413000,367623000000],[113410000,445312000000],[113404000,319769000000],[113293000,224797000000],[113286000,204857000000],[113247000,345204000000],[113239000,377990000000],[113219000,407208000000],[113210000,301056000000],[113208000,289326000000],[113198000,206872000000],[113188000,347851000000],[113174000,454611000000],[113088000,449681000000],[113079000,797419000000],[113035000,572634000000],[113020000,737798000000],[113019000,463112000000],[113018000,596074000000],[113016000,463118000000],[113014000,646969000000],[113009000,713527000000],[113003000,675107000000],[113002000,709267000000],[112990000,615894000000],[112984000,731866000000]]},"depth":30,"sequence":146075070,"symbol":"sENJUSDT","timestamp":1625342259351245614,"type":"snapshot"}
1625342259.702573: {"book":{"asks":[],"bids":[[29940,22624]]},"depth":30,"sequence":4899660348,"symbol":"XTZUSD","timestamp":1625342259462394687,"type":"incremental"}
1625342259.702703: {"book":{"asks":[[30190,2114]],"bids":[]},"depth":30,"sequence":4899660349,"symbol":"XTZUSD","timestamp":1625342259462433553,"type":"incremental"}
1625342259.702768: {"book":{"asks":[],"bids":[[30070,56257]]},"depth":30,"sequence":4899660350,"symbol":"XTZUSD","timestamp":1625342259462457209,"type":"incremental"}
1625342259.702822: {"book":{"asks":[[30080,3511],[30390,0]],"bids":[]},"depth":30,"sequence":4899660362,"symbol":"XTZUSD","timestamp":1625342259536429118,"type":"incremental"}
1625342259.702919: {"book":{"asks":[[2155000,15252],[2155800,12064]],"bids":[]},"depth":30,"sequence":4899660364,"symbol":"XMRUSD","timestamp":1625342259561028601,"type":"incremental"}
1625342259.702987: {"book":{"asks":[[30090,0],[30390,3321]],"bids":[]},"depth":30,"sequence":4899660366,"symbol":"XTZUSD","timestamp":1625342259586705380,"type":"incremental"}
1625342259.724224: {"book":{"asks":[[30080,0],[30400,12518]],"bids":[]},"depth":30,"sequence":4899660367,"symbol":"XTZUSD","timestamp":1625342259590791415,"type":"incremental"}
