1625342259.762506: {"book":{"asks":[[769100000,13073700000],[769500000,29853300000],[770200000,29785500000],[770700000,34692300000],[771400000,26218800000],[771700000,22985500000],[772100000,31605500000],[772500000,22533700000],[773000000,30261000000],[773500000,22422600000],[778200000,20058600000],[778400000,23514700000],[778600000,24778100000],[779000000,31044600000],[779100000,58362900000],[779700000,29363900000],[779800000,27912400000],[779900000,19075400000],[781600000,30148700000],[789200000,68961500000],[791900000,50237400000],[792100000,65702800000],[792200000,57686800000],[792700000,61295300000],[792800000,45304300000],[794000000,52539100000],[794100000,32121000000],[794300000,49398800000],[794400000,50194800000],[794700000,48735900000]],"bids":[[761500000,6995300000],[761200000,32249800000],[759700000,12394600000],[759200000,31023100000],[757000000,15958800000],[756900000,57187400000],[756700000,22984800000],[756600000,20801400000],[756500000,26424500000],[755800000,23256300000],[752600000,29352100000],[751200000,25829300000],[750800000,23376400000],[750300000,36418900000],[748500000,35910600000],[748100000,21078100000],[747300000,32705200000],[747100000,32913000000],[747000000,1341900000],[746900000,21296700000],[745900000,31453800000],[736400000,47849100000],[736200000,67409600000],[736000000,64502500000],[735900000,45586900000],[735600000,69127400000],[735400000,74153100000],[735000000,61346900000],[734900000,62433800000],[734600000,73525200000]]},"depth":30,"sequence":146075021,"symbol":"sSUSHIUSDT","timestamp":1625342254467369757,"type":"snapshot"}
1625342259.7860649: {"book":{"asks":[[11381,8170],[11385,13047]],"bids":[]},"depth":30,"sequence":8450976023,"symbol":"ENJUSD","timestamp":1625342259560585265,"type":"incremental"}
1625342259.786216: {"book":{"asks":[],"bids":[[11345,3866],[11341,3778]]},"depth":30,"sequence":8450976024,"symbol":"ENJUSD","timestamp":1625342259594124308,"type":"incremental"}
1625342259.886378: {"book":{"asks":[[30090,4352],[30400,0]],"bids":[]},"depth":30,"sequence":4899660550,"symbol":"XTZUSD","timestamp":1625342259666449720,"type":"incremental"}
1625342259.887916: {"book":{"asks":[[30080,3326],[30390,0]],"bids":[]},"depth":30,"sequence":4899660551,"symbol":"XTZUSD","timestamp":1625342259768776824,"type":"incremental"}
1625342259.978316: {"book":{"asks":[],"bids":[[67063000,0],[66936000,568938000000]]},"depth":30,"sequence":175933095,"symbol":"sGRTUSDT","timestamp":1625342259869432668,"type":"incremental"}
1625342260.071177: {"book":{"asks":[[30090,0],[30390,3321]],"bids":[]},"depth":30,"sequence":4899660552,"symbol":"XTZUSD","timestamp":1625342259820901100,"type":"incremental"}
1625342260.071266: {"book":{"asks":[],"bids":[[2150700,889]]},"depth":30,"sequence":4899660553,"symbol":"XMRUSD","timestamp":1625342259824465816,"type":"incremental"}
1625342260.071295: {"book":{"asks":[[30080,0],[30400,12518]],"bids":[]},"depth":30,"sequence":4899660554,"symbol":"XTZUSD","timestamp":1625342259871413892,"type":"incremental"}
1625342260.096728: {"book":{"asks":[],"bids":[[67208000,0],[66930000,827086000000]]},"depth":30,"sequence":175933096,"symbol":"sGRTUSDT","timestamp":1625342259984102254,"type":"incremental"}
1625342260.096809: {"book":{"asks":[],"bids":[[67182000,0],[66919000,843829000000]]},"depth":30,"sequence":175933097,"symbol":"sGRTUSDT","timestamp":1625342259984145866,"type":"incremental"}
1625342260.096844: {"book":{"asks":[],"bids":[[67118000,0],[66915000,709380000000]]},"depth":30,"sequence":175933098,"symbol":"sGRTUSDT","timestamp":1625342259984168614,"type":"incremental"}
1625342260.096871: {"book":{"asks":[],"bids":[[67095000,0],[66905000,455245000000]]},"depth":30,"sequence":175933099,"symbol":"sGRTUSDT","timestamp":1625342259984188094,"type":"incremental"}
1625342260.096899: {"book":{"asks":[],"bids":[[67092000,0],[66900000,1520447000000]]},"depth":30,"sequence":175933100,"symbol":"sGRTUSDT","timestamp":1625342259984217443,"type":"incremental"}
1625342260.0969222: {"book":{"asks":[],"bids":[[67042000,0],[66890000,352700000000]]},"depth":30,"sequence":175933101,"symbol":"sGRTUSDT","timestamp":1625342259984236924,"type":"incremental"}
1625342260.0969448: {"book":{"asks":[],"bids":[[67039000,0],[66879000,169680000000]]},"depth":30,"sequence":175933102,"symbol":"sGRTUSDT","timestamp":1625342259984262496,"type":"incremental"}
1625342260.096967: {"book":{"asks":[],"bids":[[67010000,0],[66826000,413407000000]]},"depth":30,"sequence":175933103,"symbol":"sGRTUSDT","timestamp":1625342259984434946,"type":"incremental"}
1625342260.096989: {"book":{"asks":[],"bids":[[66919000,0],[66817000,436904000000]]},"depth":30,"sequence":175933104,"symbol":"sGRTUSDT","timestamp":1625342259984470939,"type":"incremental"}
1625342260.0970109: {"book":{"asks":[],"bids":[[66859000,573489000000],[66817000,0]]},"depth":30,"sequence":175933105,"symbol":"sGRTUSDT","timestamp":1625342259984504280,"type":"incremental"}
1625342260.097034: {"book":{"asks":[],"bids":[[67211000,0],[66817000,436904000000]]},"depth":30,"sequence":175933110,"symbol":"sGRTUSDT","timestamp":1625342259984735199,"type":"incremental"}
1625342260.132434: {"book":{"asks":[[330105000,1043],[331835000,0]],"bids":[]},"depth":30,"sequence":17652793988,"symbol":"YFIUSD","timestamp":1625342259865345068,"type":"incremental"}
1625342260.132628: {"book":{"asks":[[330165000,0],[331835000,2999]],"bids":[]},"depth":30,"sequence":17652793989,"symbol":"YFIUSD","timestamp":1625342259865375938,"type":"incremental"}
1625342260.132683: {"book":{"asks":[[330650000,3379]],"bids":[]},"depth":30,"sequence":17652793990,"symbol":"YFIUSD","timestamp":1625342259865397405,"type":"incremental"}
1625342260.132714: {"book":{"asks":[[330650000,0],[331875000,3180]],"bids":[]},"depth":30,"sequence":17652793991,"symbol":"YFIUSD","timestamp":1625342259865411261,"type":"incremental"}
1625342260.1327538: {"book":{"asks":[[331715000,5414]],"bids":[]},"depth":30,"sequence":17652793992,"symbol":"YFIUSD","timestamp":1625342259865431785,"type":"incremental"}
1625342260.132781: {"book":{"asks":[[330735000,8113]],"bids":[]},"depth":30,"sequence":17652794063,"symbol":"YFIUSD","timestamp":1625342259868333156,"type":"incremental"}
1625342260.1331751: {"book":{"asks":[],"bids":[[67161000,0],[66811000,690009000000]]},"depth":30,"sequence":175933111,"symbol":"sGRTUSDT","timestamp":1625342259984771480,"type":"incremental"}
1625342260.1332421: {"book":{"asks":[],"bids":[[67077000,0],[66800000,881444000000]]},"depth":30,"sequence":175933112,"symbol":"sGRTUSDT","timestamp":1625342259984798174,"type":"incremental"}
1625342260.133285: {"book":{"asks":[],"bids":[[67073000,0],[66764000,548302000000]]},"depth":30,"sequence":175933113,"symbol":"sGRTUSDT","timestamp":1625342259984819931,"type":"incremental"}
1625342260.133323: {"book":{"asks":[],"bids":[[67006000,422430000000]]},"depth":30,"sequence":175933114,"symbol":"sGRTUSDT","timestamp":1625342259984837973,"type":"incremental"}
1625342260.1333492: {"book":{"asks":[],"bids":[[67006000,0],[66752000,706974000000]]},"depth":30,"sequence":175933115,"symbol":"sGRTUSDT","timestamp":1625342259984852818,"type":"incremental"}
1625342260.1333828: {"book":{"asks":[],"bids":[[66821000,835476000000],[66752000,0]]},"depth":30,"sequence":175933116,"symbol":"sGRTUSDT","timestamp":1625342259984957282,"type":"incremental"}
1625342260.15413: {"book":{"asks":[],"bids":[[119020,10119]]},"depth":30,"sequence":6643012145,"symbol":"ATOMUSD","timestamp":1625342260027973499,"type":"incremental"}
1625342260.402984: {"book":{"asks":[[30150,63662]],"bids":[]},"depth":30,"sequence":4899660556,"symbol":"XTZUSD","timestamp":1625342259963951679,"type":"incremental"}
1625342260.4030778: {"book":{"asks":[],"bids":[[29980,915]]},"depth":30,"sequence":4899660557,"symbol":"XTZUSD","timestamp":1625342259963984915,"type":"incremental"}
1625342260.403148: {"book":{"asks":[[1878760000,0],[1882500000,73383000000]],"bids":[]},"depth":30,"sequence":20149237759,"symbol":"sLINKUSDT","timestamp":1625342260033358855,"type":"incremental"}
1625342260.403221: {"book":{"asks":[],"bids":[[67056000,2507000000],[66764000,0]]},"depth":30,"sequence":175933126,"symbol":"sGRTUSDT","timestamp":1625342260104205222,"type":"incremental"}
1625342260.403264: {"book":{"asks":[],"bids":[[50632000000,0],[50406000000,1452184000]]},"depth":30,"sequence":14221236967,"symbol":"sBCHUSDT","timestamp":1625342260251118637,"type":"incremental"}
1625342260.4033: {"book":{"asks":[],"bids":[[50558000000,0],[50405000000,1551818000]]},"depth":30,"sequence":14221236968,"symbol":"sBCHUSDT","timestamp":1625342260251164354,"type":"incremental"}
1625342260.403332: {"book":{"asks":[],"bids":[[50408000000,2725263000],[50405000000,0]]},"depth":30,"sequence":14221236969,"symbol":"sBCHUSDT","timestamp":1625342260251177868,"type":"incremental"}
1625342260.4408488: {"book":{"asks":[[30210,19562]],"bids":[]},"depth":30,"sequence":4899660559,"symbol":"XTZUSD","timestamp":1625342260177414001,"type":"incremental"}
1625342260.54777: {"book":{"asks":[],"bids":[[50413000000,1466262000],[50406000000,0]]},"depth":30,"sequence":14221236971,"symbol":"sBCHUSDT","timestamp":1625342260252228977,"type":"incremental"}
1625342260.54785: {"book":{"asks":[[50885000000,930250000],[51080000000,0]],"bids":[]},"depth":30,"sequence":14221236976,"symbol":"sBCHUSDT","timestamp":1625342260260582862,"type":"incremental"}
1625342260.5478861: {"book":{"asks":[[50885000000,2734951000]],"bids":[]},"depth":30,"sequence":14221236977,"symbol":"sBCHUSDT","timestamp":1625342260260617421,"type":"incremental"}
1625342260.547907: {"book":{"asks":[[50981000000,0],[51080000000,1159222000]],"bids":[]},"depth":30,"sequence":14221236978,"symbol":"sBCHUSDT","timestamp":1625342260260694599,"type":"incremental"}
1625342260.5479329: {"book":{"asks":[[51022000000,396450000]],"bids":[]},"depth":30,"sequence":14221236979,"symbol":"sBCHUSDT","timestamp":1625342260260741884,"type":"incremental"}
1625342260.547949: {"book":{"asks":[[51079000000,3688792000]],"bids":[]},"depth":30,"sequence":14221236981,"symbol":"sBCHUSDT","timestamp":1625342260273428104,"type":"incremental"}
1625342260.5479648: {"book":{"asks":[[51079000000,4491313000]],"bids":[]},"depth":30,"sequence":14221236982,"symbol":"sBCHUSDT","timestamp":1625342260273464823,"type":"incremental"}
1625342260.547979: {"book":{"asks":[],"bids":[[119150,422],[119090,1826],[118740,0]]},"depth":30,"sequence":6643012158,"symbol":"ATOMUSD","timestamp":1625342260242392848,"type":"incremental"}
1625342260.5480251: {"book":{"asks":[[769100000,12885200000]],"bids":[]},"depth":30,"sequence":146075071,"symbol":"sSUSHIUSDT","timestamp":1625342260409676008,"type":"incremental"}
1625342260.757567: {"book":{"asks":[],"bids":[[30060,77504]]},"depth":30,"sequence":4899660570,"symbol":"XTZUSD","timestamp":1625342260426036407,"type":"incremental"}
1625342260.757635: {"book":{"asks":[],"bids":[[30060,76154]]},"depth":30,"sequence":4899660571,"symbol":"XTZUSD","timestamp":1625342260426081785,"type":"incremental"}
1625342260.7576609: {"book":{"asks":[],"bids":[[30070,57357]]},"depth":30,"sequence":4899660572,"symbol":"XTZUSD","timestamp":1625342260426105628,"type":"incremental"}
1625342260.7576818: {"book":{"asks":[[1877540000,203000000],[1882500000,0]],"bids":[]},"depth":30,"sequence":20149237770,"symbol":"sLINKUSDT","timestamp":1625342260428179075,"type":"incremental"}
1625342260.7577212: {"book":{"asks":[],"bids":[[1870460000,0],[1861530000,81938000000]]},"depth":30,"sequence":20149237832,"symbol":"sLINKUSDT","timestamp":1625342260505382594,"type":"incremental"}
1625342260.757749: {"book":{"asks":[],"bids":[[1870220000,0],[1861030000,383775000000]]},"depth":30,"sequence":20149237833,"symbol":"sLINKUSDT","timestamp":1625342260505418103,"type":"incremental"}
1625342260.7577732: {"book":{"asks":[],"bids":[[1866880000,172841000000],[1861030000,0]]},"depth":30,"sequence":20149237834,"symbol":"sLINKUSDT","timestamp":1625342260505485870,"type":"incremental"}
1625342260.757797: {"book":{"asks":[],"bids":[[1865250000,108358000000],[1861530000,0]]},"depth":30,"sequence":20149237835,"symbol":"sLINKUSDT","timestamp":1625342260505587634,"type":"incremental"}
1625342260.7578182: {"book":{"asks":[],"bids":[[1869000000,134751000000],[1862570000,0]]},"depth":30,"sequence":20149237841,"symbol":"sLINKUSDT","timestamp":1625342260508483451,"type":"incremental"}
1625342260.75784: {"book":{"asks":[],"bids":[[1868250000,61373000000],[1862600000,0]]},"depth":30,"sequence":20149237842,"symbol":"sLINKUSDT","timestamp":1625342260508528342,"type":"incremental"}
1625342260.7578611: {"book":{"asks":[[330035000,848],[330090000,0]],"bids":[]},"depth":30,"sequence":17652794280,"symbol":"YFIUSD","timestamp":1625342260383378616,"type":"incremental"}
1625342260.847678: {"book":{"asks":[],"bids":[[29950,25685]]},"depth":30,"sequence":4899660574,"symbol":"XTZUSD","timestamp":1625342260668259137,"type":"incremental"}
1625342260.847782: {"book":{"asks":[],"bids":[[1867770000,0],[1862600000,53784000000]]},"depth":30,"sequence":20149237843,"symbol":"sLINKUSDT","timestamp":1625342260508546198,"type":"incremental"}
1625342260.847851: {"book":{"asks":[],"bids":[[1867450000,3000000000],[1862600000,0]]},"depth":30,"sequence":20149237844,"symbol":"sLINKUSDT","timestamp":1625342260508627719,"type":"incremental"}
1625342260.847896: {"book":{"asks":[],"bids":[[1867450000,193029000000]]},"depth":30,"sequence":20149237845,"symbol":"sLINKUSDT","timestamp":1625342260508645587,"type":"incremental"}
1625342260.847925: {"book":{"asks":[],"bids":[[1865930000,75000000000],[1862730000,0]]},"depth":30,"sequence":20149237846,"symbol":"sLINKUSDT","timestamp":1625342260508696588,"type":"incremental"}
1625342260.8479621: {"book":{"asks":[],"bids":[[1865930000,143281000000]]},"depth":30,"sequence":20149237847,"symbol":"sLINKUSDT","timestamp":1625342260508713228,"type":"incremental"}
1625342261.0382478: {"book":{"asks":[],"bids":[[30010,21940]]},"depth":30,"sequence":4899660575,"symbol":"XTZUSD","timestamp":1625342260849236284,"type":"incremental"}
1625342261.038387: {"book":{"asks":[],"bids":[[30070,56257]]},"depth":30,"sequence":4899660576,"symbol":"XTZUSD","timestamp":1625342260849279474,"type":"incremental"}
1625342261.0384881: {"book":{"asks":[[30100,80277]],"bids":[]},"depth":30,"sequence":4899660577,"symbol":"XTZUSD","timestamp":1625342260849304761,"type":"incremental"}
1625342261.127442: {"book":{"asks":[[119380,3120],[119730,0]],"bids":[]},"depth":30,"sequence":6643012169,"symbol":"ATOMUSD","timestamp":1625342260971310778,"type":"incremental"}
1625342261.1275342: {"book":{"asks":[[119410,6229]],"bids":[]},"depth":30,"sequence":6643012170,"symbol":"ATOMUSD","timestamp":1625342260971368064,"type":"incremental"}
1625342261.127563: {"book":{"asks":[[119560,6877]],"bids":[]},"depth":30,"sequence":6643012171,"symbol":"ATOMUSD","timestamp":1625342260971389784,"type":"incremental"}
1625342261.127585: {"book":{"asks":[[119600,35]],"bids":[]},"depth":30,"sequence":6643012172,"symbol":"ATOMUSD","timestamp":1625342260971473835,"type":"incremental"}
1625342261.232176: {"book":{"asks":[[50937000000,0],[51086000000,402376000]],"bids":[]},"depth":30,"sequence":14221237298,"symbol":"sBCHUSDT","timestamp":1625342260931329319,"type":"incremental"}
1625342261.2322628: {"book":{"asks":[[30090,4352],[30400,0]],"bids":[]},"depth":30,"sequence":4899660578,"symbol":"XTZUSD","timestamp":1625342260915444313,"type":"incremental"}
1625342261.232309: {"book":{"asks":[],"bids":[[30030,102291]]},"depth":30,"sequence":4899660579,"symbol":"XTZUSD","timestamp":1625342261054286007,"type":"incremental"}
1625342261.416097: {"book":{"asks":[],"bids":[[67056000,0],[66764000,548302000000]]},"depth":30,"sequence":175933140,"symbol":"sGRTUSDT","timestamp":1625342261142201568,"type":"incremental"}
1625342261.416202: {"book":{"asks":[[50931000000,6007000],[51086000000,0]],"bids":[]},"depth":30,"sequence":14221237299,"symbol":"sBCHUSDT","timestamp":1625342261133500022,"type":"incremental"}
1625342261.416256: {"book":{"asks":[],"bids":[[11344,0],[11322,5421]]},"depth":30,"sequence":8450976273,"symbol":"ENJUSD","timestamp":1625342261156396020,"type":"incremental"}
1625342261.416321: {"book":{"asks":[[30080,3280],[30390,0]],"bids":[]},"depth":30,"sequence":4899660580,"symbol":"XTZUSD","timestamp":1625342261111956693,"type":"incremental"}
1625342261.4163709: {"book":{"asks":[[30090,0],[30390,3321]],"bids":[]},"depth":30,"sequence":4899660581,"symbol":"XTZUSD","timestamp":1625342261162228852,"type":"incremental"}
1625342261.4164171: {"book":{"asks":[[30230,1711]],"bids":[]},"depth":30,"sequence":4899660582,"symbol":"XTZUSD","timestamp":1625342261252611401,"type":"incremental"}
1625342261.416446: {"book":{"asks":[[30230,951]],"bids":[]},"depth":30,"sequence":4899660583,"symbol":"XTZUSD","timestamp":1625342261252661141,"type":"incremental"}
1625342261.416476: {"book":{"asks":[[30230,904]],"bids":[]},"depth":30,"sequence":4899660584,"symbol":"XTZUSD","timestamp":1625342261252683096,"type":"incremental"}
1625342261.416502: {"book":{"asks":[[30230,504]],"bids":[]},"depth":30,"sequence":4899660585,"symbol":"XTZUSD","timestamp":1625342261252697870,"type":"incremental"}
1625342261.416528: {"book":{"asks":[[30260,1801]],"bids":[]},"depth":30,"sequence":4899660586,"symbol":"XTZUSD","timestamp":1625342261252712323,"type":"incremental"}
1625342261.416555: {"book":{"asks":[[30150,63563]],"bids":[]},"depth":30,"sequence":4899660587,"symbol":"XTZUSD","timestamp":1625342261252726315,"type":"incremental"}
1625342261.4165802: {"book":{"asks":[[30150,63393]],"bids":[]},"depth":30,"sequence":4899660588,"symbol":"XTZUSD","timestamp":1625342261252741565,"type":"incremental"}
1625342261.595937: {"book":{"asks":[],"bids":[[11358,200]]},"depth":30,"sequence":8450976364,"symbol":"ENJUSD","timestamp":1625342261444686214,"type":"incremental"}
1625342261.59603: {"book":{"asks":[],"bids":[[11357,4150]]},"depth":30,"sequence":8450976365,"symbol":"ENJUSD","timestamp":1625342261444751147,"type":"incremental"}
1625342261.596072: {"book":{"asks":[],"bids":[[11354,5953]]},"depth":30,"sequence":8450976366,"symbol":"ENJUSD","timestamp":1625342261444770613,"type":"incremental"}
1625342261.596104: {"book":{"asks":[],"bids":[[11351,5703]]},"depth":30,"sequence":8450976367,"symbol":"ENJUSD","timestamp":1625342261444785525,"type":"incremental"}
1625342261.5961332: {"book":{"asks":[],"bids":[[11345,9029]]},"depth":30,"sequence":8450976368,"symbol":"ENJUSD","timestamp":1625342261444804398,"type":"incremental"}
1625342261.59616: {"book":{"asks":[],"bids":[[11343,6380]]},"depth":30,"sequence":8450976369,"symbol":"ENJUSD","timestamp":1625342261444932012,"type":"incremental"}
1625342261.5961862: {"book":{"asks":[],"bids":[[11357,0],[11321,990]]},"depth":30,"sequence":8450976409,"symbol":"ENJUSD","timestamp":1625342261447827200,"type":"incremental"}
1625342261.5962398: {"book":{"asks":[],"bids":[[11355,0],[11320,3250]]},"depth":30,"sequence":8450976410,"symbol":"ENJUSD","timestamp":1625342261447850254,"type":"incremental"}
1625342261.5962849: {"book":{"asks":[],"bids":[[11354,13262]]},"depth":30,"sequence":8450976411,"symbol":"ENJUSD","timestamp":1625342261447882235,"type":"incremental"}
1625342261.596312: {"book":{"asks":[],"bids":[[11351,9073]]},"depth":30,"sequence":8450976412,"symbol":"ENJUSD","timestamp":1625342261447901035,"type":"incremental"}
1625342261.596338: {"book":{"asks":[],"bids":[[11351,10956]]},"depth":30,"sequence":8450976413,"symbol":"ENJUSD","timestamp":1625342261447918692,"type":"incremental"}
1625342261.596363: {"book":{"asks":[],"bids":[[11346,7043]]},"depth":30,"sequence":8450976414,"symbol":"ENJUSD","timestamp":1625342261447947106,"type":"incremental"}
1625342261.5963871: {"book":{"asks":[],"bids":[[11345,13717]]},"depth":30,"sequence":8450976415,"symbol":"ENJUSD","timestamp":1625342261447972630,"type":"incremental"}
1625342261.596412: {"book":{"asks":[[11377,130],[11424,0]],"bids":[]},"depth":30,"sequence":8450976508,"symbol":"ENJUSD","timestamp":1625342261451796562,"type":"incremental"}
1625342261.5964549: {"book":{"asks":[[11377,3230]],"bids":[]},"depth":30,"sequence":8450976509,"symbol":"ENJUSD","timestamp":1625342261451825784,"type":"incremental"}
1625342261.596482: {"book":{"asks":[[11377,8467]],"bids":[]},"depth":30,"sequence":8450976547,"symbol":"ENJUSD","timestamp":1625342261453456915,"type":"incremental"}
1625342261.5965068: {"book":{"asks":[[11378,4460],[11423,0]],"bids":[]},"depth":30,"sequence":8450976548,"symbol":"ENJUSD","timestamp":1625342261453478847,"type":"incremental"}
1625342261.596548: {"book":{"asks":[[11379,10224]],"bids":[]},"depth":30,"sequence":8450976549,"symbol":"ENJUSD","timestamp":1625342261453496697,"type":"incremental"}
1625342261.596574: {"book":{"asks":[[11383,6327]],"bids":[]},"depth":30,"sequence":8450976550,"symbol":"ENJUSD","timestamp":1625342261453515585,"type":"incremental"}
1625342261.596599: {"book":{"asks":[[11384,10811]],"bids":[]},"depth":30,"sequence":8450976551,"symbol":"ENJUSD","timestamp":1625342261453534595,"type":"incremental"}
1625342261.5966232: {"book":{"asks":[[11388,4075]],"bids":[]},"depth":30,"sequence":8450976552,"symbol":"ENJUSD","timestamp":1625342261453553248,"type":"incremental"}
1625342261.596649: {"book":{"asks":[[11390,2247]],"bids":[]},"depth":30,"sequence":8450976553,"symbol":"ENJUSD","timestamp":1625342261453573730,"type":"incremental"}
1625342261.596674: {"book":{"asks":[[11377,11720]],"bids":[]},"depth":30,"sequence":8450976633,"symbol":"ENJUSD","timestamp":1625342261459862539,"type":"incremental"}
1625342261.596698: {"book":{"asks":[[11378,6440]],"bids":[]},"depth":30,"sequence":8450976634,"symbol":"ENJUSD","timestamp":1625342261459915619,"type":"incremental"}
1625342261.596722: {"book":{"asks":[[11378,9003]],"bids":[]},"depth":30,"sequence":8450976635,"symbol":"ENJUSD","timestamp":1625342261459984129,"type":"incremental"}
1625342261.596747: {"book":{"asks":[[11379,16040]],"bids":[]},"depth":30,"sequence":8450976636,"symbol":"ENJUSD","timestamp":1625342261460053618,"type":"incremental"}
1625342261.596771: {"book":{"asks":[[11380,3870],[11422,0]],"bids":[]},"depth":30,"sequence":8450976637,"symbol":"ENJUSD","timestamp":1625342261460088379,"type":"incremental"}
1625342261.6030562: {"book":{"asks":[[30150,65133]],"bids":[]},"depth":30,"sequence":4899660589,"symbol":"XTZUSD","timestamp":1625342261493495108,"type":"incremental"}
1625342261.7775161: {"book":{"asks":[],"bids":[[67014000,2508000000],[66764000,0]]},"depth":30,"sequence":175933157,"symbol":"sGRTUSDT","timestamp":1625342261560356991,"type":"incremental"}
1625342261.777623: {"book":{"asks":[[11380,6860]],"bids":[]},"depth":30,"sequence":8450976638,"symbol":"ENJUSD","timestamp":1625342261460146193,"type":"incremental"}
1625342261.777673: {"book":{"asks":[[11383,1130]],"bids":[]},"depth":30,"sequence":8450976639,"symbol":"ENJUSD","timestamp":1625342261460162998,"type":"incremental"}
1625342261.777712: {"book":{"asks":[[11384,3535]],"bids":[]},"depth":30,"sequence":8450976640,"symbol":"ENJUSD","timestamp":1625342261460245255,"type":"incremental"}
1625342261.777745: {"book":{"asks":[[11388,0],[11422,2810]],"bids":[]},"depth":30,"sequence":8450976641,"symbol":"ENJUSD","timestamp":1625342261460265726,"type":"incremental"}
1625342261.7777972: {"book":{"asks":[[11397,4629]],"bids":[]},"depth":30,"sequence":8450976642,"symbol":"ENJUSD","timestamp":1625342261460346145,"type":"incremental"}
1625342261.777828: {"book":{"asks":[[11397,3522]],"bids":[]},"depth":30,"sequence":8450976643,"symbol":"ENJUSD","timestamp":1625342261460367427,"type":"incremental"}
1625342261.777855: {"book":{"asks":[[11400,2201]],"bids":[]},"depth":30,"sequence":8450976644,"symbol":"ENJUSD","timestamp":1625342261460432845,"type":"incremental"}
1625342261.786092: {"book":{"asks":[[30080,0],[30400,12518]],"bids":[]},"depth":30,"sequence":4899660590,"symbol":"XTZUSD","timestamp":1625342261544980446,"type":"incremental"}
1625342261.787088: {"book":{"asks":[],"bids":[[30010,22580]]},"depth":30,"sequence":4899660591,"symbol":"XTZUSD","timestamp":1625342261585931803,"type":"incremental"}
1625342261.787168: {"book":{"asks":[],"bids":[[30040,6192]]},"depth":30,"sequence":4899660592,"symbol":"XTZUSD","timestamp":1625342261585982643,"type":"incremental"}
1625342261.7872021: {"book":{"asks":[],"bids":[[30040,6069]]},"depth":30,"sequence":4899660593,"symbol":"XTZUSD","timestamp":1625342261585997736,"type":"incremental"}
1625342261.7872288: {"book":{"asks":[],"bids":[[30040,5019]]},"depth":30,"sequence":4899660594,"symbol":"XTZUSD","timestamp":1625342261586013241,"type":"incremental"}
1625342261.787252: {"book":{"asks":[],"bids":[[30040,4869]]},"depth":30,"sequence":4899660595,"symbol":"XTZUSD","timestamp":1625342261586026456,"type":"incremental"}
1625342261.787273: {"book":{"asks":[],"bids":[[30040,4863]]},"depth":30,"sequence":4899660596,"symbol":"XTZUSD","timestamp":1625342261586038514,"type":"incremental"}
1625342261.787294: {"book":{"asks":[],"bids":[[30040,4868]]},"depth":30,"sequence":4899660597,"symbol":"XTZUSD","timestamp":1625342261586052649,"type":"incremental"}
1625342261.787314: {"book":{"asks":[[30090,4352],[30400,0]],"bids":[]},"depth":30,"sequence":4899660598,"symbol":"XTZUSD","timestamp":1625342261604763375,"type":"incremental"}
1625342261.78736: {"book":{"asks":[],"bids":[[2152200,7449]]},"depth":30,"sequence":4899660599,"symbol":"XMRUSD","timestamp":1625342261631082853,"type":"incremental"}
1625342261.9574022: {"book":{"asks":[[1877540000,0],[1882500000,73383000000]],"bids":[]},"depth":30,"sequence":20149237859,"symbol":"sLINKUSDT","timestamp":1625342261633072752,"type":"incremental"}
1625342262.110302: {"book":{"asks":[],"bids":[[119140,2600]]},"depth":30,"sequence":6643012535,"symbol":"ATOMUSD","timestamp":1625342261865524335,"type":"incremental"}
1625342262.1103659: {"book":{"asks":[],"bids":[[119140,0],[118740,6071]]},"depth":30,"sequence":6643012536,"symbol":"ATOMUSD","timestamp":1625342261865617367,"type":"incremental"}
1625342262.110413: {"book":{"asks":[],"bids":[[119040,5012]]},"depth":30,"sequence":6643012537,"symbol":"ATOMUSD","timestamp":1625342261865644917,"type":"incremental"}
1625342262.1104362: {"book":{"asks":[],"bids":[[119040,2063]]},"depth":30,"sequence":6643012538,"symbol":"ATOMUSD","timestamp":1625342261865708029,"type":"incremental"}
1625342262.110455: {"book":{"asks":[],"bids":[[118950,9831]]},"depth":30,"sequence":6643012539,"symbol":"ATOMUSD","timestamp":1625342261865767741,"type":"incremental"}
1625342262.110473: {"book":{"asks":[],"bids":[[119110,0],[118730,1975]]},"depth":30,"sequence":6643012551,"symbol":"ATOMUSD","timestamp":1625342261866407209,"type":"incremental"}
1625342262.110502: {"book":{"asks":[[330040000,2281]],"bids":[]},"depth":30,"sequence":17652795064,"symbol":"YFIUSD","timestamp":1625342261916031927,"type":"incremental"}
1625342262.292108: {"book":{"asks":[[30350,3500]],"bids":[]},"depth":30,"sequence":4899660884,"symbol":"XTZUSD","timestamp":1625342261871859258,"type":"incremental"}
1625342262.292202: {"book":{"asks":[[30080,3306],[30390,0]],"bids":[]},"depth":30,"sequence":4899660885,"symbol":"XTZUSD","timestamp":1625342261971595189,"type":"incremental"}
1625342262.292272: {"book":{"asks":[[1878760000,203000000],[1882500000,0]],"bids":[]},"depth":30,"sequence":20149237865,"symbol":"sLINKUSDT","timestamp":1625342262022187328,"type":"incremental"}
1625342262.470809: {"book":{"asks":[[30090,0],[30390,3321]],"bids":[]},"depth":30,"sequence":4899660887,"symbol":"XTZUSD","timestamp":1625342262023285221,"type":"incremental"}
1625342262.4709141: {"book":{"asks":[[30080,0],[30400,12518]],"bids":[]},"depth":30,"sequence":4899660888,"symbol":"XTZUSD","timestamp":1625342262101083687,"type":"incremental"}
1625342262.470955: {"book":{"asks":[],"bids":[[30040,1273]]},"depth":30,"sequence":4899660892,"symbol":"XTZUSD","timestamp":1625342262111748427,"type":"incremental"}
1625342262.470978: {"book":{"asks":[[30120,186615]],"bids":[]},"depth":30,"sequence":4899660893,"symbol":"XTZUSD","timestamp":1625342262113427665,"type":"incremental"}
1625342262.470998: {"book":{"asks":[[30090,4352],[30400,0]],"bids":[]},"depth":30,"sequence":4899660894,"symbol":"XTZUSD","timestamp":1625342262198582938,"type":"incremental"}
1625342262.471031: {"book":{"asks":[[30120,190210]],"bids":[]},"depth":30,"sequence":4899660895,"symbol":"XTZUSD","timestamp":1625342262214280943,"type":"incremental"}
1625342262.47105: {"book":{"asks":[[1874730000,136143000000],[1882450000,0]],"bids":[]},"depth":30,"sequence":20149237866,"symbol":"sLINKUSDT","timestamp":1625342262207607925,"type":"incremental"}
1625342262.4710898: {"book":{"asks":[[1874820000,59381000000],[1882290000,0]],"bids":[]},"depth":30,"sequence":20149237867,"symbol":"sLINKUSDT","timestamp":1625342262207653695,"type":"incremental"}
1625342262.4711308: {"book":{"asks":[[1875760000,52405000000],[1882240000,0]],"bids":[]},"depth":30,"sequence":20149237868,"symbol":"sLINKUSDT","timestamp":1625342262207666755,"type":"incremental"}
1625342262.471156: {"book":{"asks":[[1875820000,64881000000],[1882160000,0]],"bids":[]},"depth":30,"sequence":20149237869,"symbol":"sLINKUSDT","timestamp":1625342262207685648,"type":"incremental"}
1625342262.471179: {"book":{"asks":[[1875090000,141585000000],[1881990000,0]],"bids":[]},"depth":30,"sequence":20149237870,"symbol":"sLINKUSDT","timestamp":1625342262209660466,"type":"incremental"}
1625342262.471272: {"book":{"asks":[[1875740000,0],[1881990000,80165000000]],"bids":[]},"depth":30,"sequence":20149237871,"symbol":"sLINKUSDT","timestamp":1625342262209721584,"type":"incremental"}
1625342262.471345: {"book":{"asks":[[1880010000,0],[1882160000,66644000000]],"bids":[]},"depth":30,"sequence":20149237872,"symbol":"sLINKUSDT","timestamp":1625342262209764322,"type":"incremental"}
1625342262.650552: {"book":{"asks":[],"bids":[[30040,4868]]},"depth":30,"sequence":4899660896,"symbol":"XTZUSD","timestamp":1625342262215793933,"type":"incremental"}
1625342262.650623: {"book":{"asks":[[30180,1100]],"bids":[]},"depth":30,"sequence":4899660897,"symbol":"XTZUSD","timestamp":1625342262234546260,"type":"incremental"}
1625342262.650652: {"book":{"asks":[],"bids":[[30070,56689]]},"depth":30,"sequence":4899660898,"symbol":"XTZUSD","timestamp":1625342262234586367,"type":"incremental"}
1625342262.650675: {"book":{"asks":[[30080,3284],[30390,0]],"bids":[]},"depth":30,"sequence":4899660899,"symbol":"XTZUSD","timestamp":1625342262314054041,"type":"incremental"}
1625342262.6507158: {"book":{"asks":[[30090,0],[30390,3321]],"bids":[]},"depth":30,"sequence":4899660900,"symbol":"XTZUSD","timestamp":1625342262364427697,"type":"incremental"}
1625342262.650748: {"book":{"asks":[[30080,0],[30400,12518]],"bids":[]},"depth":30,"sequence":4899660901,"symbol":"XTZUSD","timestamp":1625342262414310852,"type":"incremental"}
1625342262.650777: {"book":{"asks":[],"bids":[[113456000,464205000000]]},"depth":30,"sequence":146075096,"symbol":"sENJUSDT","timestamp":1625342262454620214,"type":"incremental"}
1625342262.650812: {"book":{"asks":[],"bids":[[2152300,6255]]},"depth":30,"sequence":4899660902,"symbol":"XMRUSD","timestamp":1625342262450791136,"type":"incremental"}
1625342262.6508312: {"book":{"asks":[[30170,43479]],"bids":[]},"depth":30,"sequence":4899660903,"symbol":"XTZUSD","timestamp":1625342262460123577,"type":"incremental"}
1625342262.650849: {"book":{"asks":[[67495000,0],[67858000,381343000000]],"bids":[]},"depth":30,"sequence":175933162,"symbol":"sGRTUSDT","timestamp":1625342262516219818,"type":"incremental"}
1625342262.662689: {"book":{"asks":[[67794000,512909000000],[67858000,0]],"bids":[]},"depth":30,"sequence":175933163,"symbol":"sGRTUSDT","timestamp":1625342262517203668,"type":"incremental"}
1625342262.662797: {"book":{"asks":[[67626000,713461000000],[67849000,0]],"bids":[]},"depth":30,"sequence":175933165,"symbol":"sGRTUSDT","timestamp":1625342262517279417,"type":"incremental"}
1625342262.662833: {"book":{"asks":[[67728000,0],[67849000,719418000000]],"bids":[]},"depth":30,"sequence":175933168,"symbol":"sGRTUSDT","timestamp":1625342262517411583,"type":"incremental"}
1625342262.6628659: {"book":{"asks":[[67752000,798332000000],[67849000,0]],"bids":[]},"depth":30,"sequence":175933169,"symbol":"sGRTUSDT","timestamp":1625342262517423287,"type":"incremental"}
1625342262.6628962: {"book":{"asks":[[67789000,436404000000],[67838000,0]],"bids":[]},"depth":30,"sequence":175933170,"symbol":"sGRTUSDT","timestamp":1625342262517446775,"type":"incremental"}
1625342262.833024: {"book":{"asks":[[30090,4352],[30400,0]],"bids":[]},"depth":30,"sequence":4899660949,"symbol":"XTZUSD","timestamp":1625342262472387802,"type":"incremental"}
1625342262.833117: {"book":{"asks":[],"bids":[[113456000,254678000000]]},"depth":30,"sequence":146075097,"symbol":"sENJUSDT","timestamp":1625342262552718323,"type":"incremental"}
1625342262.8331451: {"book":{"asks":[],"bids":[[113439000,295752000000],[112984000,0]]},"depth":30,"sequence":146075098,"symbol":"sENJUSDT","timestamp":1625342262552761478,"type":"incremental"}
1625342262.833178: {"book":{"asks":[],"bids":[[113435000,249065000000],[112990000,0]]},"depth":30,"sequence":146075099,"symbol":"sENJUSDT","timestamp":1625342262552780070,"type":"incremental"}
1625342262.833204: {"book":{"asks":[],"bids":[[113351000,271750000000],[113002000,0]]},"depth":30,"sequence":146075100,"symbol":"sENJUSDT","timestamp":1625342262552810963,"type":"incremental"}
1625342262.833229: {"book":{"asks":[],"bids":[[113456000,0],[113002000,709267000000]]},"depth":30,"sequence":146075101,"symbol":"sENJUSDT","timestamp":1625342262552825768,"type":"incremental"}
1625342262.8332539: {"book":{"asks":[],"bids":[[113452000,0],[112990000,615894000000]]},"depth":30,"sequence":146075102,"symbol":"sENJUSDT","timestamp":1625342262552836532,"type":"incremental"}
1625342262.833278: {"book":{"asks":[],"bids":[[113421000,557939000000],[112990000,0]]},"depth":30,"sequence":146075103,"symbol":"sENJUSDT","timestamp":1625342262552850300,"type":"incremental"}
1625342262.8332999: {"book":{"asks":[],"bids":[[113402000,308293000000],[113002000,0]]},"depth":30,"sequence":146075104,"symbol":"sENJUSDT","timestamp":1625342262552862987,"type":"incremental"}
1625342262.833322: {"book":{"asks":[],"bids":[[113098000,865564000000],[113003000,0]]},"depth":30,"sequence":146075105,"symbol":"sENJUSDT","timestamp":1625342262552877795,"type":"incremental"}
1625342262.833344: {"book":{"asks":[[67501000,443591000000]],"bids":[]},"depth":30,"sequence":175933175,"symbol":"sGRTUSDT","timestamp":1625342262554355488,"type":"incremental"}
1625342263.0131588: {"book":{"asks":[],"bids":[[29940,22224]]},"depth":30,"sequence":4899661006,"symbol":"XTZUSD","timestamp":1625342262706908938,"type":"incremental"}
1625342263.0132391: {"book":{"asks":[[30100,80247]],"bids":[]},"depth":30,"sequence":4899661007,"symbol":"XTZUSD","timestamp":1625342262706954603,"type":"incremental"}
1625342263.013271: {"book":{"asks":[[30080,3285],[30390,0]],"bids":[]},"depth":30,"sequence":4899661009,"symbol":"XTZUSD","timestamp":1625342262764422899,"type":"incremental"}
1625342263.013314: {"book":{"asks":[[30090,0],[30390,3321]],"bids":[]},"depth":30,"sequence":4899661012,"symbol":"XTZUSD","timestamp":1625342262843096979,"type":"incremental"}
1625342263.0133471: {"book":{"asks":[],"bids":[[2148800,0],[2148200,4729]]},"depth":30,"sequence":4899661013,"symbol":"XMRUSD","timestamp":1625342262854420166,"type":"incremental"}
1625342263.013381: {"book":{"asks":[],"bids":[[2152300,742]]},"depth":30,"sequence":4899661015,"symbol":"XMRUSD","timestamp":1625342262885376569,"type":"incremental"}
1625342263.0134022: {"book":{"asks":[],"bids":[[2152100,9831]]},"depth":30,"sequence":4899661016,"symbol":"XMRUSD","timestamp":1625342262885439621,"type":"incremental"}
1625342263.01342: {"book":{"asks":[],"bids":[[2152100,6331]]},"depth":30,"sequence":4899661017,"symbol":"XMRUSD","timestamp":1625342262885470757,"type":"incremental"}
1625342263.013437: {"book":{"asks":[],"bids":[[2150800,28741]]},"depth":30,"sequence":4899661018,"symbol":"XMRUSD","timestamp":1625342262885502231,"type":"incremental"}
1625342263.0134552: {"book":{"asks":[],"bids":[[2150800,14611]]},"depth":30,"sequence":4899661019,"symbol":"XMRUSD","timestamp":1625342262885618398,"type":"incremental"}
1625342263.013472: {"book":{"asks":[],"bids":[[2150800,13251]]},"depth":30,"sequence":4899661020,"symbol":"XMRUSD","timestamp":1625342262885659520,"type":"incremental"}
1625342263.013489: {"book":{"asks":[],"bids":[[2150800,5851]]},"depth":30,"sequence":4899661021,"symbol":"XMRUSD","timestamp":1625342262885677650,"type":"incremental"}
1625342263.029804: {"book":{"asks":[],"bids":[[11358,0],[11319,1746]]},"depth":30,"sequence":8450977342,"symbol":"ENJUSD","timestamp":1625342262811462129,"type":"incremental"}
1625342263.0298932: {"book":{"asks":[],"bids":[[11354,12371]]},"depth":30,"sequence":8450977344,"symbol":"ENJUSD","timestamp":1625342262829883939,"type":"incremental"}
1625342263.029922: {"book":{"asks":[],"bids":[[11354,12140]]},"depth":30,"sequence":8450977345,"symbol":"ENJUSD","timestamp":1625342262829997706,"type":"incremental"}
1625342263.0299451: {"book":{"asks":[],"bids":[[11354,11423]]},"depth":30,"sequence":8450977346,"symbol":"ENJUSD","timestamp":1625342262830097920,"type":"incremental"}
1625342263.029964: {"book":{"asks":[[11374,0],[11423,6492]],"bids":[]},"depth":30,"sequence":8450977347,"symbol":"ENJUSD","timestamp":1625342262854884117,"type":"incremental"}
1625342263.030001: {"book":{"asks":[[11364,1030],[11366,0]],"bids":[]},"depth":30,"sequence":8450977349,"symbol":"ENJUSD","timestamp":1625342262859087422,"type":"incremental"}
1625342263.1694012: {"book":{"asks":[],"bids":[[2150800,3267]]},"depth":30,"sequence":4899661022,"symbol":"XMRUSD","timestamp":1625342262885722658,"type":"incremental"}
1625342263.169525: {"book":{"asks":[],"bids":[[2150500,4800],[2145000,0]]},"depth":30,"sequence":4899661023,"symbol":"XMRUSD","timestamp":1625342262885777006,"type":"incremental"}
1625342263.169612: {"book":{"asks":[],"bids":[[2150500,14703]]},"depth":30,"sequence":4899661024,"symbol":"XMRUSD","timestamp":1625342262885809345,"type":"incremental"}
1625342263.169652: {"book":{"asks":[],"bids":[[2150500,30899]]},"depth":30,"sequence":4899661025,"symbol":"XMRUSD","timestamp":1625342262885845143,"type":"incremental"}
1625342263.1696808: {"book":{"asks":[],"bids":[[2145600,13172]]},"depth":30,"sequence":4899661026,"symbol":"XMRUSD","timestamp":1625342262885870900,"type":"incremental"}
1625342263.169707: {"book":{"asks":[],"bids":[[2145600,172]]},"depth":30,"sequence":4899661027,"symbol":"XMRUSD","timestamp":1625342262886169329,"type":"incremental"}
1625342263.169733: {"book":{"asks":[],"bids":[[2152200,580]]},"depth":30,"sequence":4899661043,"symbol":"XMRUSD","timestamp":1625342262886957583,"type":"incremental"}
1625342263.16976: {"book":{"asks":[],"bids":[[2152100,20]]},"depth":30,"sequence":4899661044,"symbol":"XMRUSD","timestamp":1625342262886985846,"type":"incremental"}
1625342263.1697762: {"book":{"asks":[],"bids":[[2151400,1000],[2145200,0]]},"depth":30,"sequence":4899661045,"symbol":"XMRUSD","timestamp":1625342262887023190,"type":"incremental"}
1625342263.169805: {"book":{"asks":[],"bids":[[2151400,4477]]},"depth":30,"sequence":4899661046,"symbol":"XMRUSD","timestamp":1625342262887081939,"type":"incremental"}
1625342263.169821: {"book":{"asks":[],"bids":[[2151400,6168]]},"depth":30,"sequence":4899661047,"symbol":"XMRUSD","timestamp":1625342262887120226,"type":"incremental"}
1625342263.169835: {"book":{"asks":[],"bids":[[2151100,6410],[2145300,0]]},"depth":30,"sequence":4899661048,"symbol":"XMRUSD","timestamp":1625342262887153553,"type":"incremental"}
1625342263.1698592: {"book":{"asks":[[30080,0],[30400,12518]],"bids":[]},"depth":30,"sequence":4899661346,"symbol":"XTZUSD","timestamp":1625342262899426671,"type":"incremental"}
1625342263.169887: {"book":{"asks":[],"bids":[[11355,200],[11319,0]]},"depth":30,"sequence":8450977351,"symbol":"ENJUSD","timestamp":1625342262928149027,"type":"incremental"}
1625342263.169913: {"book":{"asks":[],"bids":[[2148200,0],[2145300,9711]]},"depth":30,"sequence":4899661347,"symbol":"XMRUSD","timestamp":1625342262909751922,"type":"incremental"}
1625342263.169937: {"book":{"asks":[],"bids":[[2152200,0],[2145200,530]]},"depth":30,"sequence":4899661357,"symbol":"XMRUSD","timestamp":1625342262938344541,"type":"incremental"}
1625342263.1699631: {"book":{"asks":[],"bids":[[2152100,0],[2145000,1400]]},"depth":30,"sequence":4899661358,"symbol":"XMRUSD","timestamp":1625342262938366259,"type":"incremental"}
1625342263.169986: {"book":{"asks":[],"bids":[[119000,2623]]},"depth":30,"sequence":6643013449,"symbol":"ATOMUSD","timestamp":1625342262784560684,"type":"incremental"}
1625342263.170002: {"book":{"asks":[[119570,2829]],"bids":[]},"depth":30,"sequence":6643013450,"symbol":"ATOMUSD","timestamp":1625342262784607245,"type":"incremental"}
1625342263.170017: {"book":{"asks":[[119380,4293]],"bids":[]},"depth":30,"sequence":6643013451,"symbol":"ATOMUSD","timestamp":1625342262784620405,"type":"incremental"}
1625342263.170031: {"book":{"asks":[],"bids":[[1869650000,66088000000]]},"depth":30,"sequence":20149237925,"symbol":"sLINKUSDT","timestamp":1625342263051001305,"type":"incremental"}
1625342263.172418: {"book":{"asks":[[30090,4350],[30400,0]],"bids":[]},"depth":30,"sequence":4899661360,"symbol":"XTZUSD","timestamp":1625342262994150247,"type":"incremental"}
1625342263.1734169: {"book":{"asks":[],"bids":[[2152300,189]]},"depth":30,"sequence":4899661361,"symbol":"XMRUSD","timestamp":1625342263021086508,"type":"incremental"}
1625342263.173475: {"book":{"asks":[],"bids":[[2152300,0],[2144300,820]]},"depth":30,"sequence":4899661362,"symbol":"XMRUSD","timestamp":1625342263026932654,"type":"incremental"}
1625342263.1735191: {"book":{"asks":[],"bids":[[29940,22977]]},"depth":30,"sequence":4899661363,"symbol":"XTZUSD","timestamp":1625342263027738922,"type":"incremental"}
1625342263.195623: {"book":{"asks":[],"bids":[[67197000,508443000000],[66800000,0]]},"depth":30,"sequence":175933176,"symbol":"sGRTUSDT","timestamp":1625342263087048451,"type":"incremental"}
1625342263.34729: {"book":{"asks":[[11373,99],[11423,0]],"bids":[]},"depth":30,"sequence":8450977352,"symbol":"ENJUSD","timestamp":1625342262942127713,"type":"incremental"}
1625342263.347379: {"book":{"asks":[],"bids":[[30070,56257]]},"depth":30,"sequence":4899661364,"symbol":"XTZUSD","timestamp":1625342263027787433,"type":"incremental"}
1625342263.347409: {"book":{"asks":[],"bids":[[30070,55857]]},"depth":30,"sequence":4899661365,"symbol":"XTZUSD","timestamp":1625342263027803119,"type":"incremental"}
1625342263.347431: {"book":{"asks":[],"bids":[[30070,55567]]},"depth":30,"sequence":4899661366,"symbol":"XTZUSD","timestamp":1625342263027816404,"type":"incremental"}
1625342263.34745: {"book":{"asks":[],"bids":[[2151800,553],[2144300,0]]},"depth":30,"sequence":4899661367,"symbol":"XMRUSD","timestamp":1625342263037568320,"type":"incremental"}
1625342263.3474848: {"book":{"asks":[],"bids":[[2151800,742]]},"depth":30,"sequence":4899661368,"symbol":"XMRUSD","timestamp":1625342263044379171,"type":"incremental"}
1625342263.3475041: {"book":{"asks":[],"bids":[[2148200,4729],[2145000,0]]},"depth":30,"sequence":4899661369,"symbol":"XMRUSD","timestamp":1625342263070293347,"type":"incremental"}
1625342263.347532: {"book":{"asks":[],"bids":[[29880,1276]]},"depth":30,"sequence":4899661370,"symbol":"XTZUSD","timestamp":1625342263087588001,"type":"incremental"}
1625342263.34755: {"book":{"asks":[[30130,2722]],"bids":[]},"depth":30,"sequence":4899661371,"symbol":"XTZUSD","timestamp":1625342263087624891,"type":"incremental"}
1625342263.375476: {"book":{"asks":[],"bids":[[67126000,611927000000],[66811000,0]]},"depth":30,"sequence":175933177,"symbol":"sGRTUSDT","timestamp":1625342263087099946,"type":"incremental"}
1625342263.378172: {"book":{"asks":[],"bids":[[66992000,735360000000]]},"depth":30,"sequence":175933178,"symbol":"sGRTUSDT","timestamp":1625342263087129161,"type":"incremental"}
1625342263.37823: {"book":{"asks":[],"bids":[[66992000,0],[66811000,690009000000]]},"depth":30,"sequence":175933179,"symbol":"sGRTUSDT","timestamp":1625342263087148744,"type":"incremental"}
1625342263.3782752: {"book":{"asks":[],"bids":[[67147000,264192000000],[66811000,0]]},"depth":30,"sequence":175933185,"symbol":"sGRTUSDT","timestamp":1625342263087705651,"type":"incremental"}
1625342263.378304: {"book":{"asks":[],"bids":[[67133000,444058000000],[66817000,0]]},"depth":30,"sequence":175933186,"symbol":"sGRTUSDT","timestamp":1625342263087745793,"type":"incremental"}
1625342263.3783302: {"book":{"asks":[],"bids":[[67131000,304965000000],[66821000,0]]},"depth":30,"sequence":175933187,"symbol":"sGRTUSDT","timestamp":1625342263087770450,"type":"incremental"}
1625342263.3783529: {"book":{"asks":[],"bids":[[67097000,799462000000],[66826000,0]]},"depth":30,"sequence":175933188,"symbol":"sGRTUSDT","timestamp":1625342263087802768,"type":"incremental"}
1625342263.3783748: {"book":{"asks":[],"bids":[[67082000,792254000000],[66859000,0]]},"depth":30,"sequence":175933189,"symbol":"sGRTUSDT","timestamp":1625342263087967333,"type":"incremental"}
1625342263.378397: {"book":{"asks":[],"bids":[[67013000,0],[66859000,573489000000]]},"depth":30,"sequence":175933190,"symbol":"sGRTUSDT","timestamp":1625342263088000433,"type":"incremental"}
1625342263.378419: {"book":{"asks":[],"bids":[[66999000,563949000000],[66859000,0]]},"depth":30,"sequence":175933191,"symbol":"sGRTUSDT","timestamp":1625342263088032975,"type":"incremental"}
1625342263.3784409: {"book":{"asks":[],"bids":[[66962000,470752000000],[66879000,0]]},"depth":30,"sequence":175933192,"symbol":"sGRTUSDT","timestamp":1625342263088052005,"type":"incremental"}
1625342263.527013: {"book":{"asks":[[2154400,0],[2159100,700]],"bids":[]},"depth":30,"sequence":4899661376,"symbol":"XMRUSD","timestamp":1625342263335088292,"type":"incremental"}
1625342263.708122: {"book":{"asks":[[2153500,3130]],"bids":[]},"depth":30,"sequence":4899661377,"symbol":"XMRUSD","timestamp":1625342263335132713,"type":"incremental"}
1625342263.8904572: {"book":{"asks":[[30110,104494]],"bids":[]},"depth":30,"sequence":4899661379,"symbol":"XTZUSD","timestamp":1625342263631165618,"type":"incremental"}
1625342263.890549: {"book":{"asks":[],"bids":[[29950,26785]]},"depth":30,"sequence":4899661380,"symbol":"XTZUSD","timestamp":1625342263679353380,"type":"incremental"}
1625342263.890597: {"book":{"asks":[[30100,81741]],"bids":[]},"depth":30,"sequence":4899661381,"symbol":"XTZUSD","timestamp":1625342263679401347,"type":"incremental"}
1625342264.406322: {"book":{"asks":[],"bids":[[29920,941]]},"depth":30,"sequence":4899661387,"symbol":"XTZUSD","timestamp":1625342264147363746,"type":"incremental"}
1625342264.4064262: {"book":{"asks":[],"bids":[[67014000,0],[66879000,169680000000]]},"depth":30,"sequence":175933200,"symbol":"sGRTUSDT","timestamp":1625342264107573889,"type":"incremental"}
1625342264.5076869: {"book":{"asks":[],"bids":[[67063000,2506000000],[66879000,0]]},"depth":30,"sequence":175933210,"symbol":"sGRTUSDT","timestamp":1625342264344165007,"type":"incremental"}
1625342264.538306: {"book":{"asks":[[30080,3291],[30390,0]],"bids":[]},"depth":30,"sequence":4899661555,"symbol":"XTZUSD","timestamp":1625342264202795964,"type":"incremental"}
1625342264.539039: {"book":{"asks":[[30290,16535]],"bids":[]},"depth":30,"sequence":4899661557,"symbol":"XTZUSD","timestamp":1625342264271867527,"type":"incremental"}
1625342264.5391: {"book":{"asks":[[30090,0],[30390,3321]],"bids":[]},"depth":30,"sequence":4899661558,"symbol":"XTZUSD","timestamp":1625342264299125457,"type":"incremental"}
1625342264.5391622: {"book":{"asks":[[30080,0],[30400,12518]],"bids":[]},"depth":30,"sequence":4899661560,"symbol":"XTZUSD","timestamp":1625342264343262659,"type":"incremental"}
1625342264.6551812: {"book":{"asks":[],"bids":[[1868470000,82047000000],[1862990000,0]]},"depth":30,"sequence":20149238424,"symbol":"sLINKUSDT","timestamp":1625342264411264259,"type":"incremental"}
1625342264.6565719: {"book":{"asks":[],"bids":[[1869980000,68446000000],[1863160000,0]]},"depth":30,"sequence":20149238429,"symbol":"sLINKUSDT","timestamp":1625342264413827635,"type":"incremental"}
1625342264.656638: {"book":{"asks":[],"bids":[[1869000000,0],[1863160000,72981000000]]},"depth":30,"sequence":20149238430,"symbol":"sLINKUSDT","timestamp":1625342264413906311,"type":"incremental"}
1625342264.656673: {"book":{"asks":[],"bids":[[1865930000,75000000000]]},"depth":30,"sequence":20149238431,"symbol":"sLINKUSDT","timestamp":1625342264413928087,"type":"incremental"}
1625342264.656693: {"book":{"asks":[],"bids":[[1865930000,0],[1862990000,48363000000]]},"depth":30,"sequence":20149238432,"symbol":"sLINKUSDT","timestamp":1625342264414003797,"type":"incremental"}
1625342264.656718: {"book":{"asks":[],"bids":[[1863470000,0],[1862790000,92150000000]]},"depth":30,"sequence":20149238433,"symbol":"sLINKUSDT","timestamp":1625342264414027793,"type":"incremental"}
1625342264.904195: {"book":{"asks":[],"bids":[[30020,469]]},"depth":30,"sequence":4899662305,"symbol":"XTZUSD","timestamp":1625342264740581688,"type":"incremental"}
1625342264.9702709: {"book":{"asks":[],"bids":[[30070,55673]]},"depth":30,"sequence":4899662306,"symbol":"XTZUSD","timestamp":1625342264740621180,"type":"incremental"}
1625342265.153793: {"book":{"asks":[[30250,2062]],"bids":[]},"depth":30,"sequence":4899662314,"symbol":"XTZUSD","timestamp":1625342264991782114,"type":"incremental"}
1625342265.155179: {"book":{"asks":[[30190,2844]],"bids":[]},"depth":30,"sequence":4899662315,"symbol":"XTZUSD","timestamp":1625342264991826370,"type":"incremental"}
1625342265.155233: {"book":{"asks":[[2153300,2195]],"bids":[]},"depth":30,"sequence":4899662316,"symbol":"XMRUSD","timestamp":1625342265006774015,"type":"incremental"}
1625342265.155266: {"book":{"asks":[[2153300,1265]],"bids":[]},"depth":30,"sequence":4899662317,"symbol":"XMRUSD","timestamp":1625342265006825870,"type":"incremental"}
1625342265.1552918: {"book":{"asks":[[2153300,1635]],"bids":[]},"depth":30,"sequence":4899662318,"symbol":"XMRUSD","timestamp":1625342265006854306,"type":"incremental"}
1625342265.155315: {"book":{"asks":[[2153300,1265]],"bids":[]},"depth":30,"sequence":4899662319,"symbol":"XMRUSD","timestamp":1625342265006937100,"type":"incremental"}
1625342265.1553369: {"book":{"asks":[[2153300,1652]],"bids":[]},"depth":30,"sequence":4899662320,"symbol":"XMRUSD","timestamp":1625342265007010486,"type":"incremental"}
1625342265.180615: {"book":{"asks":[[330105000,0],[331910000,3171]],"bids":[]},"depth":30,"sequence":17652795914,"symbol":"YFIUSD","timestamp":1625342264985507491,"type":"incremental"}
1625342265.1807082: {"book":{"asks":[[330195000,1143]],"bids":[]},"depth":30,"sequence":17652795915,"symbol":"YFIUSD","timestamp":1625342264985552751,"type":"incremental"}
1625342265.1807392: {"book":{"asks":[[331715000,2467]],"bids":[]},"depth":30,"sequence":17652795916,"symbol":"YFIUSD","timestamp":1625342264985603721,"type":"incremental"}
1625342265.1807628: {"book":{"asks":[[329990000,1229],[331910000,0]],"bids":[]},"depth":30,"sequence":17652795964,"symbol":"YFIUSD","timestamp":1625342264987630689,"type":"incremental"}
1625342265.1807969: {"book":{"asks":[[330095000,0],[331910000,3171]],"bids":[]},"depth":30,"sequence":17652795965,"symbol":"YFIUSD","timestamp":1625342264987651162,"type":"incremental"}
1625342265.180827: {"book":{"asks":[[330565000,3570]],"bids":[]},"depth":30,"sequence":17652795966,"symbol":"YFIUSD","timestamp":1625342264987666145,"type":"incremental"}
1625342265.2184331: {"book":{"asks":[[769100000,12701500000]],"bids":[]},"depth":30,"sequence":146075125,"symbol":"sSUSHIUSDT","timestamp":1625342265048938466,"type":"incremental"}
1625342265.339186: {"book":{"asks":[],"bids":[[29890,748]]},"depth":30,"sequence":4899662323,"symbol":"XTZUSD","timestamp":1625342265176457742,"type":"incremental"}
1625342265.339278: {"book":{"asks":[[30170,43579]],"bids":[]},"depth":30,"sequence":4899662324,"symbol":"XTZUSD","timestamp":1625342265176493844,"type":"incremental"}
1625342265.379095: {"book":{"asks":[[1874730000,0],[1882240000,42844000000]],"bids":[]},"depth":30,"sequence":20149238441,"symbol":"sLINKUSDT","timestamp":1625342265272434610,"type":"incremental"}
1625342265.379175: {"book":{"asks":[[1876940000,0],[1882290000,91985000000]],"bids":[]},"depth":30,"sequence":20149238442,"symbol":"sLINKUSDT","timestamp":1625342265272492563,"type":"incremental"}
1625342265.379209: {"book":{"asks":[[1880650000,0],[1882450000,61422000000]],"bids":[]},"depth":30,"sequence":20149238443,"symbol":"sLINKUSDT","timestamp":1625342265272506052,"type":"incremental"}
1625342265.379235: {"book":{"asks":[[1875540000,0],[1882500000,73383000000]],"bids":[]},"depth":30,"sequence":20149238446,"symbol":"sLINKUSDT","timestamp":1625342265273091059,"type":"incremental"}
1625342265.3792598: {"book":{"asks":[[1880720000,61871000000],[1882500000,0]],"bids":[]},"depth":30,"sequence":20149238447,"symbol":"sLINKUSDT","timestamp":1625342265273127685,"type":"incremental"}
1625342265.442322: {"book":{"asks":[],"bids":[[11353,6604]]},"depth":30,"sequence":8450978063,"symbol":"ENJUSD","timestamp":1625342265236429491,"type":"incremental"}
1625342265.554689: {"book":{"asks":[],"bids":[[29850,9817]]},"depth":30,"sequence":4899662325,"symbol":"XTZUSD","timestamp":1625342265446197177,"type":"incremental"}
1625342265.735856: {"book":{"asks":[[113999000,0],[114311000,491169000000]],"bids":[]},"depth":30,"sequence":146075126,"symbol":"sENJUSDT","timestamp":1625342265625634414,"type":"incremental"}
1625342265.739038: {"book":{"asks":[[30090,4350],[30400,0]],"bids":[]},"depth":30,"sequence":4899662326,"symbol":"XTZUSD","timestamp":1625342265501973345,"type":"incremental"}
1625342265.739121: {"book":{"asks":[],"bids":[[29940,23337]]},"depth":30,"sequence":4899662327,"symbol":"XTZUSD","timestamp":1625342265545111836,"type":"incremental"}
1625342265.7391539: {"book":{"asks":[[30100,82351]],"bids":[]},"depth":30,"sequence":4899662328,"symbol":"XTZUSD","timestamp":1625342265545150722,"type":"incremental"}
1625342265.73918: {"book":{"asks":[[30080,3292],[30390,0]],"bids":[]},"depth":30,"sequence":4899662329,"symbol":"XTZUSD","timestamp":1625342265607821196,"type":"incremental"}
1625342265.914776: {"book":{"asks":[[114223000,845363000000],[114311000,0]],"bids":[]},"depth":30,"sequence":146075127,"symbol":"sENJUSDT","timestamp":1625342265625680342,"type":"incremental"}
1625342265.9148679: {"book":{"asks":[[114228000,445421000000],[114310000,0]],"bids":[]},"depth":30,"sequence":146075128,"symbol":"sENJUSDT","timestamp":1625342265625700386,"type":"incremental"}
1625342265.914909: {"book":{"asks":[],"bids":[[113410000,0],[113003000,675107000000]]},"depth":30,"sequence":146075129,"symbol":"sENJUSDT","timestamp":1625342265653710001,"type":"incremental"}
1625342265.923145: {"book":{"asks":[[30090,0],[30390,3321]],"bids":[]},"depth":30,"sequence":4899662330,"symbol":"XTZUSD","timestamp":1625342265658851092,"type":"incremental"}
1625342265.924551: {"book":{"asks":[],"bids":[[29840,18548]]},"depth":30,"sequence":4899662333,"symbol":"XTZUSD","timestamp":1625342265800424094,"type":"incremental"}
1625342266.07056: {"book":{"asks":[[330035000,1978]],"bids":[]},"depth":30,"sequence":17652796308,"symbol":"YFIUSD","timestamp":1625342265778697466,"type":"incremental"}
1625342266.0706408: {"book":{"asks":[[329990000,2029]],"bids":[]},"depth":30,"sequence":17652796309,"symbol":"YFIUSD","timestamp":1625342265778756183,"type":"incremental"}
1625342266.070674: {"book":{"asks":[[329990000,2420]],"bids":[]},"depth":30,"sequence":17652796311,"symbol":"YFIUSD","timestamp":1625342265851636770,"type":"incremental"}
1625342266.0833468: {"book":{"asks":[[67535000,486827000000],[67823000,0]],"bids":[]},"depth":30,"sequence":175933212,"symbol":"sGRTUSDT","timestamp":1625342265975012002,"type":"incremental"}
1625342266.10774: {"book":{"asks":[[2154400,4729],[2155000,10523],[2159100,0]],"bids":[]},"depth":30,"sequence":4899662335,"symbol":"XMRUSD","timestamp":1625342265822841896,"type":"incremental"}
1625342266.109688: {"book":{"asks":[],"bids":[[29970,18604]]},"depth":30,"sequence":4899662336,"symbol":"XTZUSD","timestamp":1625342265829727384,"type":"incremental"}
1625342266.109739: {"book":{"asks":[],"bids":[[30070,58473]]},"depth":30,"sequence":4899662337,"symbol":"XTZUSD","timestamp":1625342265829772956,"type":"incremental"}
1625342266.109767: {"book":{"asks":[[30080,0],[30400,12518]],"bids":[]},"depth":30,"sequence":4899662338,"symbol":"XTZUSD","timestamp":1625342265851760149,"type":"incremental"}
1625342266.1098082: {"book":{"asks":[[30090,4350],[30400,0]],"bids":[]},"depth":30,"sequence":4899662339,"symbol":"XTZUSD","timestamp":1625342265907406530,"type":"incremental"}
1625342266.1098418: {"book":{"asks":[[30240,996]],"bids":[]},"depth":30,"sequence":4899662340,"symbol":"XTZUSD","timestamp":1625342265955744160,"type":"incremental"}
1625342266.1098628: {"book":{"asks":[[30240,766]],"bids":[]},"depth":30,"sequence":4899662341,"symbol":"XTZUSD","timestamp":1625342265955787170,"type":"incremental"}
1625342266.292864: {"book":{"asks":[[30240,466]],"bids":[]},"depth":30,"sequence":4899662342,"symbol":"XTZUSD","timestamp":1625342265955810186,"type":"incremental"}
1625342266.441729: {"book":{"asks":[],"bids":[[67126000,0],[66879000,169680000000]]},"depth":30,"sequence":175933215,"symbol":"sGRTUSDT","timestamp":1625342266281013394,"type":"incremental"}
1625342266.47765: {"book":{"asks":[[30260,1201]],"bids":[]},"depth":30,"sequence":4899662345,"symbol":"XTZUSD","timestamp":1625342266235334002,"type":"incremental"}
1625342266.4777422: {"book":{"asks":[[30260,1180]],"bids":[]},"depth":30,"sequence":4899662346,"symbol":"XTZUSD","timestamp":1625342266235373640,"type":"incremental"}
1625342266.477782: {"book":{"asks":[[30260,1190]],"bids":[]},"depth":30,"sequence":4899662347,"symbol":"XTZUSD","timestamp":1625342266235390310,"type":"incremental"}
1625342266.555095: {"book":{"asks":[[119530,8138]],"bids":[]},"depth":30,"sequence":6643014230,"symbol":"ATOMUSD","timestamp":1625342266333169509,"type":"incremental"}
1625342266.555188: {"book":{"asks":[[119560,1660]],"bids":[]},"depth":30,"sequence":6643014231,"symbol":"ATOMUSD","timestamp":1625342266333220018,"type":"incremental"}
1625342266.555228: {"book":{"asks":[[119590,4614]],"bids":[]},"depth":30,"sequence":6643014232,"symbol":"ATOMUSD","timestamp":1625342266333320849,"type":"incremental"}
1625342266.567308: {"book":{"asks":[[119380,4263]],"bids":[]},"depth":30,"sequence":6643014403,"symbol":"ATOMUSD","timestamp":1625342266453305104,"type":"incremental"}
1625342266.571572: {"book":{"asks":[[50825000000,0],[51086000000,402376000]],"bids":[]},"depth":30,"sequence":14221238951,"symbol":"sBCHUSDT","timestamp":1625342266423187962,"type":"incremental"}
1625342266.661309: {"book":{"asks":[],"bids":[[29810,271]]},"depth":30,"sequence":4899662351,"symbol":"XTZUSD","timestamp":1625342266512818477,"type":"incremental"}
1625342266.661976: {"book":{"asks":[],"bids":[[29970,17562]]},"depth":30,"sequence":4899662352,"symbol":"XTZUSD","timestamp":1625342266518167444,"type":"incremental"}
1625342266.6620438: {"book":{"asks":[[30170,42379]],"bids":[]},"depth":30,"sequence":4899662353,"symbol":"XTZUSD","timestamp":1625342266518208944,"type":"incremental"}
1625342266.662085: {"book":{"asks":[[30170,42107]],"bids":[]},"depth":30,"sequence":4899662354,"symbol":"XTZUSD","timestamp":1625342266518229629,"type":"incremental"}
1625342266.743996: {"book":{"asks":[[119570,4729]],"bids":[]},"depth":30,"sequence":6643014408,"symbol":"ATOMUSD","timestamp":1625342266587339273,"type":"incremental"}
1625342266.8770518: {"book":{"asks":[[114259000,0],[114310000,576546000000]],"bids":[]},"depth":30,"sequence":146075134,"symbol":"sENJUSDT","timestamp":1625342266767925206,"type":"incremental"}
1625342267.081634: {"book":{"asks":[[114222000,4806000000],[114310000,0]],"bids":[]},"depth":30,"sequence":146075135,"symbol":"sENJUSDT","timestamp":1625342266971390728,"type":"incremental"}
1625342267.092201: {"book":{"asks":[],"bids":[[11354,7309]]},"depth":30,"sequence":8450978658,"symbol":"ENJUSD","timestamp":1625342266943911944,"type":"incremental"}
1625342267.092944: {"book":{"asks":[],"bids":[[11354,0],[11319,1746]]},"depth":30,"sequence":8450978712,"symbol":"ENJUSD","timestamp":1625342266946281089,"type":"incremental"}
1625342267.0930188: {"book":{"asks":[],"bids":[[11353,1370]]},"depth":30,"sequence":8450978718,"symbol":"ENJUSD","timestamp":1625342266946511635,"type":"incremental"}
1625342267.093051: {"book":{"asks":[],"bids":[[11350,11219]]},"depth":30,"sequence":8450978719,"symbol":"ENJUSD","timestamp":1625342266946545452,"type":"incremental"}
1625342267.093076: {"book":{"asks":[[11375,7133],[11422,0]],"bids":[]},"depth":30,"sequence":8450978785,"symbol":"ENJUSD","timestamp":1625342266948551613,"type":"incremental"}
1625342267.0931149: {"book":{"asks":[[11384,8218]],"bids":[]},"depth":30,"sequence":8450978786,"symbol":"ENJUSD","timestamp":1625342266948577456,"type":"incremental"}
1625342267.0931368: {"book":{"asks":[[11385,9653]],"bids":[]},"depth":30,"sequence":8450978802,"symbol":"ENJUSD","timestamp":1625342266949063016,"type":"incremental"}
1625342267.093159: {"book":{"asks":[[11385,7753]],"bids":[]},"depth":30,"sequence":8450978803,"symbol":"ENJUSD","timestamp":1625342266949397330,"type":"incremental"}
1625342267.09318: {"book":{"asks":[[11386,220]],"bids":[]},"depth":30,"sequence":8450978804,"symbol":"ENJUSD","timestamp":1625342266949426558,"type":"incremental"}
1625342267.0932: {"book":{"asks":[[11400,1020]],"bids":[]},"depth":30,"sequence":8450978805,"symbol":"ENJUSD","timestamp":1625342266949443513,"type":"incremental"}
1625342267.09322: {"book":{"asks":[[11379,9206]],"bids":[]},"depth":30,"sequence":8450978881,"symbol":"ENJUSD","timestamp":1625342266951743367,"type":"incremental"}
1625342267.093239: {"book":{"asks":[[11384,12834]],"bids":[]},"depth":30,"sequence":8450978888,"symbol":"ENJUSD","timestamp":1625342266951996245,"type":"incremental"}
1625342267.093259: {"book":{"asks":[[11385,2244]],"bids":[]},"depth":30,"sequence":8450978889,"symbol":"ENJUSD","timestamp":1625342266952013561,"type":"incremental"}
1625342267.399858: {"book":{"asks":[],"bids":[[30070,55673]]},"depth":30,"sequence":4899662444,"symbol":"XTZUSD","timestamp":1625342267159970394,"type":"incremental"}
1625342267.3999271: {"book":{"asks":[[30370,11056]],"bids":[]},"depth":30,"sequence":4899662445,"symbol":"XTZUSD","timestamp":1625342267169828928,"type":"incremental"}
1625342267.4022558: {"book":{"asks":[],"bids":[[67063000,0],[66859000,573489000000]]},"depth":30,"sequence":175933221,"symbol":"sGRTUSDT","timestamp":1625342267177354962,"type":"incremental"}
1625342267.4045272: {"book":{"asks":[[50931000000,0],[51091000000,600658000]],"bids":[]},"depth":30,"sequence":14221238956,"symbol":"sBCHUSDT","timestamp":1625342267139871461,"type":"incremental"}
1625342267.577369: {"book":{"asks":[[50933000000,6007000],[51091000000,0]],"bids":[]},"depth":30,"sequence":14221238958,"symbol":"sBCHUSDT","timestamp":1625342267348477739,"type":"incremental"}
1625342267.58269: {"book":{"asks":[],"bids":[[67000000,2509000000],[66859000,0]]},"depth":30,"sequence":175933225,"symbol":"sGRTUSDT","timestamp":1625342267402596018,"type":"incremental"}
1625342267.6960378: {"book":{"asks":[],"bids":[[119080,2000],[118730,0]]},"depth":30,"sequence":6643014522,"symbol":"ATOMUSD","timestamp":1625342267568942742,"type":"incremental"}
1625342267.696768: {"book":{"asks":[],"bids":[[119020,3985]]},"depth":30,"sequence":6643014523,"symbol":"ATOMUSD","timestamp":1625342267569012170,"type":"incremental"}
1625342267.696844: {"book":{"asks":[],"bids":[[118990,8409]]},"depth":30,"sequence":6643014524,"symbol":"ATOMUSD","timestamp":1625342267569096367,"type":"incremental"}
1625342267.696885: {"book":{"asks":[],"bids":[[118950,5480]]},"depth":30,"sequence":6643014525,"symbol":"ATOMUSD","timestamp":1625342267569131471,"type":"incremental"}
1625342267.696918: {"book":{"asks":[],"bids":[[118930,2150]]},"depth":30,"sequence":6643014539,"symbol":"ATOMUSD","timestamp":1625342267569956604,"type":"incremental"}
1625342267.696948: {"book":{"asks":[],"bids":[[118930,4045]]},"depth":30,"sequence":6643014540,"symbol":"ATOMUSD","timestamp":1625342267569983765,"type":"incremental"}
1625342267.698835: {"book":{"asks":[[113913000,381271000000]],"bids":[]},"depth":30,"sequence":146075136,"symbol":"sENJUSDT","timestamp":1625342267589297532,"type":"incremental"}
1625342267.751929: {"book":{"asks":[],"bids":[[1864240000,0],[1862730000,80211000000]]},"depth":30,"sequence":20149238495,"symbol":"sLINKUSDT","timestamp":1625342267528107466,"type":"incremental"}
1625342267.752085: {"book":{"asks":[],"bids":[[1869980000,0],[1862600000,53784000000]]},"depth":30,"sequence":20149238499,"symbol":"sLINKUSDT","timestamp":1625342267530660677,"type":"incremental"}
1625342267.7521641: {"book":{"asks":[],"bids":[[1867020000,0],[1862570000,67123000000]]},"depth":30,"sequence":20149238500,"symbol":"sLINKUSDT","timestamp":1625342267530743245,"type":"incremental"}
1625342267.75223: {"book":{"asks":[],"bids":[[1862730000,0],[1862170000,41998000000]]},"depth":30,"sequence":20149238501,"symbol":"sLINKUSDT","timestamp":1625342267530820010,"type":"incremental"}
1625342267.752295: {"book":{"asks":[],"bids":[[1862640000,65936000000],[1862170000,0]]},"depth":30,"sequence":20149238502,"symbol":"sLINKUSDT","timestamp":1625342267530837652,"type":"incremental"}
1625342267.76524: {"book":{"asks":[],"bids":[[2151500,2130]]},"depth":30,"sequence":4899662450,"symbol":"XMRUSD","timestamp":1625342267560227972,"type":"incremental"}
1625342267.765363: {"book":{"asks":[],"bids":[[29930,2333]]},"depth":30,"sequence":4899662451,"symbol":"XTZUSD","timestamp":1625342267578326024,"type":"incremental"}
1625342267.765425: {"book":{"asks":[],"bids":[[2151000,1275]]},"depth":30,"sequence":4899662452,"symbol":"XMRUSD","timestamp":1625342267578900352,"type":"incremental"}
1625342267.8744068: {"book":{"asks":[[119480,2626]],"bids":[]},"depth":30,"sequence":6643014699,"symbol":"ATOMUSD","timestamp":1625342267771838922,"type":"incremental"}
1625342267.930382: {"book":{"asks":[],"bids":[[11350,12169]]},"depth":30,"sequence":8450980081,"symbol":"ENJUSD","timestamp":1625342267786204812,"type":"incremental"}
1625342268.052707: {"book":{"asks":[],"bids":[[118900,3584]]},"depth":30,"sequence":6643014700,"symbol":"ATOMUSD","timestamp":1625342267771869858,"type":"incremental"}
1625342268.13902: {"book":{"asks":[],"bids":[[29950,25885]]},"depth":30,"sequence":4899662642,"symbol":"XTZUSD","timestamp":1625342267849321020,"type":"incremental"}
1625342268.274815: {"book":{"asks":[[11373,0],[11422,2810]],"bids":[]},"depth":30,"sequence":8450980087,"symbol":"ENJUSD","timestamp":1625342268069326763,"type":"incremental"}
1625342268.3220448: {"book":{"asks":[],"bids":[[29910,2111]]},"depth":30,"sequence":4899662644,"symbol":"XTZUSD","timestamp":1625342268021841139,"type":"incremental"}
1625342268.4454558: {"book":{"asks":[[11370,99],[11422,0]],"bids":[]},"depth":30,"sequence":8450980089,"symbol":"ENJUSD","timestamp":1625342268259555118,"type":"incremental"}
1625342268.507225: {"book":{"asks":[],"bids":[[29890,913]]},"depth":30,"sequence":4899662647,"symbol":"XTZUSD","timestamp":1625342268248914674,"type":"incremental"}
1625342268.815304: {"book":{"asks":[[30120,190660]],"bids":[]},"depth":30,"sequence":4899662664,"symbol":"XTZUSD","timestamp":1625342268584186129,"type":"incremental"}
1625342268.8175051: {"book":{"asks":[[2152800,7444]],"bids":[]},"depth":30,"sequence":4899662665,"symbol":"XMRUSD","timestamp":1625342268599615925,"type":"incremental"}
1625342268.817564: {"book":{"asks":[[2152700,12690]],"bids":[]},"depth":30,"sequence":4899662666,"symbol":"XMRUSD","timestamp":1625342268599666954,"type":"incremental"}
1625342268.8175879: {"book":{"asks":[],"bids":[[2147200,11721]]},"depth":30,"sequence":4899662668,"symbol":"XMRUSD","timestamp":1625342268702680502,"type":"incremental"}
1625342268.8176079: {"book":{"asks":[],"bids":[[2147200,8011]]},"depth":30,"sequence":4899662669,"symbol":"XMRUSD","timestamp":1625342268702746869,"type":"incremental"}
1625342268.817625: {"book":{"asks":[],"bids":[[2150800,5793]]},"depth":30,"sequence":4899662681,"symbol":"XMRUSD","timestamp":1625342268703575604,"type":"incremental"}
1625342268.817641: {"book":{"asks":[],"bids":[[2150500,14703]]},"depth":30,"sequence":4899662682,"symbol":"XMRUSD","timestamp":1625342268703614460,"type":"incremental"}
1625342268.817656: {"book":{"asks":[],"bids":[[2150500,4800]]},"depth":30,"sequence":4899662683,"symbol":"XMRUSD","timestamp":1625342268703635496,"type":"incremental"}
1625342268.8176708: {"book":{"asks":[],"bids":[[2149100,1280]]},"depth":30,"sequence":4899662684,"symbol":"XMRUSD","timestamp":1625342268703669632,"type":"incremental"}
1625342268.817687: {"book":{"asks":[],"bids":[[2149100,11603]]},"depth":30,"sequence":4899662685,"symbol":"XMRUSD","timestamp":1625342268703721150,"type":"incremental"}
1625342268.8177018: {"book":{"asks":[],"bids":[[2149100,27920]]},"depth":30,"sequence":4899662690,"symbol":"XMRUSD","timestamp":1625342268704141962,"type":"incremental"}
1625342268.817717: {"book":{"asks":[],"bids":[[2149100,30035]]},"depth":30,"sequence":4899662691,"symbol":"XMRUSD","timestamp":1625342268704171059,"type":"incremental"}
1625342268.817732: {"book":{"asks":[],"bids":[[2145600,5372]]},"depth":30,"sequence":4899662692,"symbol":"XMRUSD","timestamp":1625342268704198346,"type":"incremental"}
1625342268.822937: {"book":{"asks":[[329990000,2396]],"bids":[]},"depth":30,"sequence":17652797371,"symbol":"YFIUSD","timestamp":1625342268665200079,"type":"incremental"}
1625342268.8764129: {"book":{"asks":[],"bids":[[2145600,13225]]},"depth":30,"sequence":4899662693,"symbol":"XMRUSD","timestamp":1625342268704218428,"type":"incremental"}
1625342268.8764749: {"book":{"asks":[[2152400,4205],[2158900,0]],"bids":[]},"depth":30,"sequence":4899662790,"symbol":"XMRUSD","timestamp":1625342268708035409,"type":"incremental"}
1625342268.8765178: {"book":{"asks":[[2153000,0],[2158900,840]],"bids":[]},"depth":30,"sequence":4899662791,"symbol":"XMRUSD","timestamp":1625342268708058214,"type":"incremental"}
1625342268.87655: {"book":{"asks":[[2153600,16578]],"bids":[]},"depth":30,"sequence":4899662792,"symbol":"XMRUSD","timestamp":1625342268708082140,"type":"incremental"}
1625342268.8765671: {"book":{"asks":[[2153600,20578]],"bids":[]},"depth":30,"sequence":4899662793,"symbol":"XMRUSD","timestamp":1625342268708105376,"type":"incremental"}
1625342268.876582: {"book":{"asks":[[2153600,30578]],"bids":[]},"depth":30,"sequence":4899662794,"symbol":"XMRUSD","timestamp":1625342268708128849,"type":"incremental"}
1625342268.876596: {"book":{"asks":[[2153600,34654]],"bids":[]},"depth":30,"sequence":4899662795,"symbol":"XMRUSD","timestamp":1625342268708150851,"type":"incremental"}
1625342268.87661: {"book":{"asks":[[2153600,40636]],"bids":[]},"depth":30,"sequence":4899662796,"symbol":"XMRUSD","timestamp":1625342268708171694,"type":"incremental"}
1625342268.8766239: {"book":{"asks":[[2152800,20]],"bids":[]},"depth":30,"sequence":4899662937,"symbol":"XMRUSD","timestamp":1625342268714841173,"type":"incremental"}
1625342269.061158: {"book":{"asks":[[30230,560]],"bids":[]},"depth":30,"sequence":4899663030,"symbol":"XTZUSD","timestamp":1625342268767494672,"type":"incremental"}
1625342269.061253: {"book":{"asks":[],"bids":[[30040,5618]]},"depth":30,"sequence":4899663031,"symbol":"XTZUSD","timestamp":1625342268767532585,"type":"incremental"}
1625342269.0612962: {"book":{"asks":[[2153600,41456]],"bids":[]},"depth":30,"sequence":4899663034,"symbol":"XMRUSD","timestamp":1625342268836317335,"type":"incremental"}
1625342269.2134411: {"book":{"asks":[[1878760000,0],[1882500000,73383000000]],"bids":[]},"depth":30,"sequence":20149238526,"symbol":"sLINKUSDT","timestamp":1625342269108987170,"type":"incremental"}
1625342269.24473: {"book":{"asks":[[30230,2200]],"bids":[]},"depth":30,"sequence":4899663039,"symbol":"XTZUSD","timestamp":1625342269059765653,"type":"incremental"}
1625342269.2552671: {"book":{"asks":[[1875830000,131475000000],[1882500000,0]],"bids":[]},"depth":30,"sequence":20149238527,"symbol":"sLINKUSDT","timestamp":1625342269147095913,"type":"incremental"}
1625342269.256267: {"book":{"asks":[[1879430000,105226000000],[1882450000,0]],"bids":[]},"depth":30,"sequence":20149238528,"symbol":"sLINKUSDT","timestamp":1625342269147128621,"type":"incremental"}
1625342269.256326: {"book":{"asks":[[1880940000,0],[1882450000,61422000000]],"bids":[]},"depth":30,"sequence":20149238529,"symbol":"sLINKUSDT","timestamp":1625342269147159611,"type":"incremental"}
1625342269.256358: {"book":{"asks":[[1882290000,0],[1882500000,73383000000]],"bids":[]},"depth":30,"sequence":20149238530,"symbol":"sLINKUSDT","timestamp":1625342269147224313,"type":"incremental"}
1625342269.256385: {"book":{"asks":[[1874210000,34960000000],[1882500000,0]],"bids":[]},"depth":30,"sequence":20149238533,"symbol":"sLINKUSDT","timestamp":1625342269149841924,"type":"incremental"}
1625342269.2564108: {"book":{"asks":[[1874210000,87926000000]],"bids":[]},"depth":30,"sequence":20149238534,"symbol":"sLINKUSDT","timestamp":1625342269149918287,"type":"incremental"}
1625342269.256428: {"book":{"asks":[[1875020000,107585000000],[1882450000,0]],"bids":[]},"depth":30,"sequence":20149238535,"symbol":"sLINKUSDT","timestamp":1625342269149960129,"type":"incremental"}
1625342269.2564511: {"book":{"asks":[[1875090000,0],[1882450000,61422000000]],"bids":[]},"depth":30,"sequence":20149238536,"symbol":"sLINKUSDT","timestamp":1625342269150002197,"type":"incremental"}
1625342269.256473: {"book":{"asks":[[1879620000,74964000000],[1882450000,0]],"bids":[]},"depth":30,"sequence":20149238537,"symbol":"sLINKUSDT","timestamp":1625342269150092852,"type":"incremental"}
1625342269.285301: {"book":{"asks":[[67436000,597787000000],[67816000,0]],"bids":[]},"depth":30,"sequence":175933226,"symbol":"sGRTUSDT","timestamp":1625342269176932750,"type":"incremental"}
1625342269.289321: {"book":{"asks":[[67449000,267198000000],[67814000,0]],"bids":[]},"depth":30,"sequence":175933227,"symbol":"sGRTUSDT","timestamp":1625342269176989762,"type":"incremental"}
1625342269.289421: {"book":{"asks":[[67451000,317824000000],[67807000,0]],"bids":[]},"depth":30,"sequence":175933228,"symbol":"sGRTUSDT","timestamp":1625342269177019077,"type":"incremental"}
1625342269.28946: {"book":{"asks":[[67456000,344405000000],[67794000,0]],"bids":[]},"depth":30,"sequence":175933229,"symbol":"sGRTUSDT","timestamp":1625342269177034131,"type":"incremental"}
1625342269.289716: {"book":{"asks":[[67471000,182000000000],[67789000,0]],"bids":[]},"depth":30,"sequence":175933230,"symbol":"sGRTUSDT","timestamp":1625342269177055256,"type":"incremental"}
1625342269.289769: {"book":{"asks":[[67471000,319136000000]],"bids":[]},"depth":30,"sequence":175933231,"symbol":"sGRTUSDT","timestamp":1625342269177071481,"type":"incremental"}
1625342269.2926831: {"book":{"asks":[[67535000,0],[67789000,436404000000]],"bids":[]},"depth":30,"sequence":175933232,"symbol":"sGRTUSDT","timestamp":1625342269177133272,"type":"incremental"}
1625342269.292747: {"book":{"asks":[[67546000,0],[67794000,512909000000]],"bids":[]},"depth":30,"sequence":175933233,"symbol":"sGRTUSDT","timestamp":1625342269177311315,"type":"incremental"}
1625342269.292781: {"book":{"asks":[[67556000,512445000000]],"bids":[]},"depth":30,"sequence":175933234,"symbol":"sGRTUSDT","timestamp":1625342269177348053,"type":"incremental"}
1625342269.2928011: {"book":{"asks":[[67610000,0],[67807000,242008000000]],"bids":[]},"depth":30,"sequence":175933235,"symbol":"sGRTUSDT","timestamp":1625342269177395757,"type":"incremental"}
1625342269.2928262: {"book":{"asks":[[67430000,498025000000],[67807000,0]],"bids":[]},"depth":30,"sequence":175933238,"symbol":"sGRTUSDT","timestamp":1625342269177676798,"type":"incremental"}
1625342269.292851: {"book":{"asks":[[67436000,864620000000]],"bids":[]},"depth":30,"sequence":175933239,"symbol":"sGRTUSDT","timestamp":1625342269177737612,"type":"incremental"}
1625342269.2928672: {"book":{"asks":[[67460000,255371000000],[67794000,0]],"bids":[]},"depth":30,"sequence":175933240,"symbol":"sGRTUSDT","timestamp":1625342269177860405,"type":"incremental"}
1625342269.46557: {"book":{"asks":[[67462000,273132000000],[67789000,0]],"bids":[]},"depth":30,"sequence":175933241,"symbol":"sGRTUSDT","timestamp":1625342269177903196,"type":"incremental"}
1625342269.465724: {"book":{"asks":[[67544000,0],[67789000,436404000000]],"bids":[]},"depth":30,"sequence":175933242,"symbol":"sGRTUSDT","timestamp":1625342269177935764,"type":"incremental"}
1625342269.465801: {"book":{"asks":[[67556000,0],[67794000,512909000000]],"bids":[]},"depth":30,"sequence":175933243,"symbol":"sGRTUSDT","timestamp":1625342269177957720,"type":"incremental"}
1625342269.465865: {"book":{"asks":[],"bids":[[67129000,0],[66859000,573489000000]]},"depth":30,"sequence":175933249,"symbol":"sGRTUSDT","timestamp":1625342269342723300,"type":"incremental"}
1625342269.465926: {"book":{"asks":[],"bids":[[67021000,552128000000],[66859000,0]]},"depth":30,"sequence":175933250,"symbol":"sGRTUSDT","timestamp":1625342269342760853,"type":"incremental"}
1625342269.6028821: {"book":{"asks":[[1877540000,203000000],[1882240000,0]],"bids":[]},"depth":30,"sequence":20149238551,"symbol":"sLINKUSDT","timestamp":1625342269498899547,"type":"incremental"}
1625342269.6144671: {"book":{"asks":[],"bids":[[29970,18512]]},"depth":30,"sequence":4899663228,"symbol":"XTZUSD","timestamp":1625342269492823587,"type":"incremental"}
1625342269.6430998: {"book":{"asks":[[11380,8149]],"bids":[]},"depth":30,"sequence":8450980195,"symbol":"ENJUSD","timestamp":1625342269418585877,"type":"incremental"}
1625342269.6440692: {"book":{"asks":[],"bids":[[67180000,0],[66859000,573489000000]]},"depth":30,"sequence":175933251,"symbol":"sGRTUSDT","timestamp":1625342269342907469,"type":"incremental"}
1625342269.644348: {"book":{"asks":[],"bids":[[67097000,0],[66826000,413407000000]]},"depth":30,"sequence":175933252,"symbol":"sGRTUSDT","timestamp":1625342269342945899,"type":"incremental"}
1625342269.644396: {"book":{"asks":[],"bids":[[67017000,452875000000],[66826000,0]]},"depth":30,"sequence":175933253,"symbol":"sGRTUSDT","timestamp":1625342269343783010,"type":"incremental"}
1625342269.644428: {"book":{"asks":[],"bids":[[67017000,490108000000]]},"depth":30,"sequence":175933254,"symbol":"sGRTUSDT","timestamp":1625342269343829445,"type":"incremental"}
1625342269.7767649: {"book":{"asks":[],"bids":[[50661000000,1194850000],[50408000000,0]]},"depth":30,"sequence":14221239236,"symbol":"sBCHUSDT","timestamp":1625342269581019976,"type":"incremental"}
1625342269.7768729: {"book":{"asks":[],"bids":[[50661000000,1453077000]]},"depth":30,"sequence":14221239237,"symbol":"sBCHUSDT","timestamp":1625342269581082610,"type":"incremental"}
1625342269.800041: {"book":{"asks":[],"bids":[[30070,55693]]},"depth":30,"sequence":4899663229,"symbol":"XTZUSD","timestamp":1625342269537282337,"type":"incremental"}
1625342269.983171: {"book":{"asks":[[30160,31830]],"bids":[]},"depth":30,"sequence":4899663230,"symbol":"XTZUSD","timestamp":1625342269748313231,"type":"incremental"}
1625342269.983836: {"book":{"asks":[[30160,31480]],"bids":[]},"depth":30,"sequence":4899663231,"symbol":"XTZUSD","timestamp":1625342269748358071,"type":"incremental"}
1625342269.983934: {"book":{"asks":[],"bids":[[30020,1199]]},"depth":30,"sequence":4899663232,"symbol":"XTZUSD","timestamp":1625342269748372809,"type":"incremental"}
1625342270.168951: {"book":{"asks":[],"bids":[[29940,22977]]},"depth":30,"sequence":4899663233,"symbol":"XTZUSD","timestamp":1625342270032732598,"type":"incremental"}
1625342270.1690829: {"book":{"asks":[],"bids":[[29940,22224]]},"depth":30,"sequence":4899663234,"symbol":"XTZUSD","timestamp":1625342270032775366,"type":"incremental"}
1625342270.1865752: {"book":{"asks":[],"bids":[[11342,1980]]},"depth":30,"sequence":8450980395,"symbol":"ENJUSD","timestamp":1625342269975551910,"type":"incremental"}
1625342270.2462158: {"book":{"asks":[],"bids":[[118900,1584]]},"depth":30,"sequence":6643015267,"symbol":"ATOMUSD","timestamp":1625342270025944783,"type":"incremental"}
1625342270.352732: {"book":{"asks":[],"bids":[[29860,854]]},"depth":30,"sequence":4899663236,"symbol":"XTZUSD","timestamp":1625342270121842196,"type":"incremental"}
1625342270.593156: {"book":{"asks":[],"bids":[[328300000,7446]]},"depth":30,"sequence":17652797501,"symbol":"YFIUSD","timestamp":1625342270467080288,"type":"incremental"}
1625342270.5938702: {"book":{"asks":[],"bids":[[328290000,6314]]},"depth":30,"sequence":17652797502,"symbol":"YFIUSD","timestamp":1625342270467119658,"type":"incremental"}
1625342270.593919: {"book":{"asks":[],"bids":[[328190000,0],[328095000,4446]]},"depth":30,"sequence":17652797503,"symbol":"YFIUSD","timestamp":1625342270467137639,"type":"incremental"}
1625342270.5939782: {"book":{"asks":[],"bids":[[328875000,3910]]},"depth":30,"sequence":17652797576,"symbol":"YFIUSD","timestamp":1625342270470819646,"type":"incremental"}
1625342270.594004: {"book":{"asks":[],"bids":[[328875000,0],[328025000,2372]]},"depth":30,"sequence":17652797577,"symbol":"YFIUSD","timestamp":1625342270470832692,"type":"incremental"}
1625342270.594054: {"book":{"asks":[],"bids":[[328615000,16653]]},"depth":30,"sequence":17652797578,"symbol":"YFIUSD","timestamp":1625342270470845932,"type":"incremental"}
1625342270.594072: {"book":{"asks":[],"bids":[[328305000,6613]]},"depth":30,"sequence":17652797579,"symbol":"YFIUSD","timestamp":1625342270470857862,"type":"incremental"}
1625342270.594087: {"book":{"asks":[],"bids":[[328115000,4563],[328025000,0]]},"depth":30,"sequence":17652797580,"symbol":"YFIUSD","timestamp":1625342270470870012,"type":"incremental"}
1625342270.602463: {"book":{"asks":[[330195000,7377]],"bids":[]},"depth":30,"sequence":17652797652,"symbol":"YFIUSD","timestamp":1625342270475891893,"type":"incremental"}
1625342270.602591: {"book":{"asks":[[330535000,5974],[331910000,0]],"bids":[]},"depth":30,"sequence":17652797653,"symbol":"YFIUSD","timestamp":1625342270475903423,"type":"incremental"}
1625342270.602687: {"book":{"asks":[[331685000,5475]],"bids":[]},"depth":30,"sequence":17652797654,"symbol":"YFIUSD","timestamp":1625342270475922635,"type":"incremental"}
1625342270.602773: {"book":{"asks":[[331715000,5905]],"bids":[]},"depth":30,"sequence":17652797656,"symbol":"YFIUSD","timestamp":1625342270476070890,"type":"incremental"}
1625342270.654892: {"book":{"asks":[],"bids":[[1868840000,0],[1862210000,65971000000]]},"depth":30,"sequence":20149238555,"symbol":"sLINKUSDT","timestamp":1625342270550597094,"type":"incremental"}
1625342270.779403: {"book":{"asks":[[330270000,3306],[331875000,0]],"bids":[]},"depth":30,"sequence":17652797718,"symbol":"YFIUSD","timestamp":1625342270479388091,"type":"incremental"}
1625342270.77948: {"book":{"asks":[[330755000,1841]],"bids":[]},"depth":30,"sequence":17652797719,"symbol":"YFIUSD","timestamp":1625342270479469737,"type":"incremental"}
1625342270.827768: {"book":{"asks":[],"bids":[[1865550000,178712000000],[1862210000,0]]},"depth":30,"sequence":20149238561,"symbol":"sLINKUSDT","timestamp":1625342270552571838,"type":"incremental"}
1625342270.8278441: {"book":{"asks":[],"bids":[[1864990000,117347000000],[1862570000,0]]},"depth":30,"sequence":20149238562,"symbol":"sLINKUSDT","timestamp":1625342270552609930,"type":"incremental"}
1625342270.827873: {"book":{"asks":[],"bids":[[1864810000,169961000000],[1862600000,0]]},"depth":30,"sequence":20149238563,"symbol":"sLINKUSDT","timestamp":1625342270552668033,"type":"incremental"}
1625342270.906261: {"book":{"asks":[],"bids":[[30010,21580]]},"depth":30,"sequence":4899663418,"symbol":"XTZUSD","timestamp":1625342270718920920,"type":"incremental"}
1625342270.906353: {"book":{"asks":[],"bids":[[29980,1415]]},"depth":30,"sequence":4899663419,"symbol":"XTZUSD","timestamp":1625342270718970171,"type":"incremental"}
1625342271.090556: {"book":{"asks":[[769100000,12396000000]],"bids":[]},"depth":30,"sequence":146075169,"symbol":"sSUSHIUSDT","timestamp":1625342270978912198,"type":"incremental"}
1625342271.090655: {"book":{"asks":[[30110,104194]],"bids":[]},"depth":30,"sequence":4899663420,"symbol":"XTZUSD","timestamp":1625342270817254869,"type":"incremental"}
1625342271.091827: {"book":{"asks":[],"bids":[[30070,55844]]},"depth":30,"sequence":4899663421,"symbol":"XTZUSD","timestamp":1625342270817289965,"type":"incremental"}
1625342271.091878: {"book":{"asks":[],"bids":[[30070,56544]]},"depth":30,"sequence":4899663422,"symbol":"XTZUSD","timestamp":1625342270817314214,"type":"incremental"}
1625342271.0919092: {"book":{"asks":[[30120,191036]],"bids":[]},"depth":30,"sequence":4899663425,"symbol":"XTZUSD","timestamp":1625342270857812982,"type":"incremental"}
1625342271.091936: {"book":{"asks":[],"bids":[[29930,3233]]},"depth":30,"sequence":4899663426,"symbol":"XTZUSD","timestamp":1625342270857847438,"type":"incremental"}
1625342271.2754712: {"book":{"asks":[],"bids":[[29910,2341]]},"depth":30,"sequence":4899663428,"symbol":"XTZUSD","timestamp":1625342271006946492,"type":"incremental"}
1625342271.4596648: {"book":{"asks":[],"bids":[[29830,19868]]},"depth":30,"sequence":4899663430,"symbol":"XTZUSD","timestamp":1625342271178519872,"type":"incremental"}
1625342271.45974: {"book":{"asks":[],"bids":[[29830,19568]]},"depth":30,"sequence":4899663431,"symbol":"XTZUSD","timestamp":1625342271178562594,"type":"incremental"}
1625342271.459767: {"book":{"asks":[],"bids":[[29870,17429]]},"depth":30,"sequence":4899663434,"symbol":"XTZUSD","timestamp":1625342271292422601,"type":"incremental"}
1625342271.459787: {"book":{"asks":[],"bids":[[30050,103768]]},"depth":30,"sequence":4899663435,"symbol":"XTZUSD","timestamp":1625342271292462053,"type":"incremental"}
1625342271.459807: {"book":{"asks":[[30190,930]],"bids":[]},"depth":30,"sequence":4899663436,"symbol":"XTZUSD","timestamp":1625342271292478443,"type":"incremental"}
1625342271.459826: {"book":{"asks":[[30100,82601]],"bids":[]},"depth":30,"sequence":4899663437,"symbol":"XTZUSD","timestamp":1625342271292492083,"type":"incremental"}
1625342271.6734688: {"book":{"asks":[[1877540000,0],[1882240000,42844000000]],"bids":[]},"depth":30,"sequence":20149238578,"symbol":"sLINKUSDT","timestamp":1625342271560853446,"type":"incremental"}
1625342271.827801: {"book":{"asks":[],"bids":[[29910,1871]]},"depth":30,"sequence":4899663443,"symbol":"XTZUSD","timestamp":1625342271709136405,"type":"incremental"}
1625342271.828753: {"book":{"asks":[],"bids":[[30050,104198]]},"depth":30,"sequence":4899663444,"symbol":"XTZUSD","timestamp":1625342271709176240,"type":"incremental"}
1625342272.066043: {"book":{"asks":[[1878760000,203000000],[1882240000,0]],"bids":[]},"depth":30,"sequence":20149238579,"symbol":"sLINKUSDT","timestamp":1625342271958981864,"type":"incremental"}
1625342272.1983821: {"book":{"asks":[[30210,20472]],"bids":[]},"depth":30,"sequence":4899663538,"symbol":"XTZUSD","timestamp":1625342271869744903,"type":"incremental"}
1625342272.198512: {"book":{"asks":[[30260,70]],"bids":[]},"depth":30,"sequence":4899663539,"symbol":"XTZUSD","timestamp":1625342272010341366,"type":"incremental"}
1625342272.198573: {"book":{"asks":[],"bids":[[2150000,0],[2145000,1400]]},"depth":30,"sequence":4899663540,"symbol":"XMRUSD","timestamp":1625342272066818917,"type":"incremental"}
1625342272.223857: {"book":{"asks":[],"bids":[[747000000,0],[733700000,62576500000]]},"depth":30,"sequence":146075175,"symbol":"sSUSHIUSDT","timestamp":1625342272051766005,"type":"incremental"}
1625342272.254121: {"book":{"asks":[[119490,6158]],"bids":[]},"depth":30,"sequence":6643015297,"symbol":"ATOMUSD","timestamp":1625342272151789592,"type":"incremental"}
1625342272.259171: {"book":{"asks":[[1874210000,87466000000]],"bids":[]},"depth":30,"sequence":20149238582,"symbol":"sLINKUSDT","timestamp":1625342272138658598,"type":"incremental"}
1625342272.259263: {"book":{"asks":[[1875580000,0],[1882240000,42844000000]],"bids":[]},"depth":30,"sequence":20149238583,"symbol":"sLINKUSDT","timestamp":1625342272154823997,"type":"incremental"}
1625342272.259309: {"book":{"asks":[[1875830000,0],[1882450000,61422000000]],"bids":[]},"depth":30,"sequence":20149238584,"symbol":"sLINKUSDT","timestamp":1625342272154850563,"type":"incremental"}
1625342272.2593431: {"book":{"asks":[[1877550000,0],[1882500000,73383000000]],"bids":[]},"depth":30,"sequence":20149238585,"symbol":"sLINKUSDT","timestamp":1625342272154877468,"type":"incremental"}
1625342272.259373: {"book":{"asks":[[1880020000,59641000000],[1882500000,0]],"bids":[]},"depth":30,"sequence":20149238586,"symbol":"sLINKUSDT","timestamp":1625342272154936603,"type":"incremental"}
1625342272.383053: {"book":{"asks":[],"bids":[[29990,58738]]},"depth":30,"sequence":4899663541,"symbol":"XTZUSD","timestamp":1625342272229023919,"type":"incremental"}
1625342272.4037051: {"book":{"asks":[],"bids":[[747200000,1341500000],[733700000,0]]},"depth":30,"sequence":146075184,"symbol":"sSUSHIUSDT","timestamp":1625342272272422988,"type":"incremental"}
1625342272.408673: {"book":{"asks":[[1880170000,73742000000],[1882450000,0]],"bids":[]},"depth":30,"sequence":20149238587,"symbol":"sLINKUSDT","timestamp":1625342272155007471,"type":"incremental"}
1625342272.408771: {"book":{"asks":[[1880370000,92196000000],[1882240000,0]],"bids":[]},"depth":30,"sequence":20149238588,"symbol":"sLINKUSDT","timestamp":1625342272155042825,"type":"incremental"}
1625342272.4088142: {"book":{"asks":[[1876040000,0],[1882240000,42844000000]],"bids":[]},"depth":30,"sequence":20149238589,"symbol":"sLINKUSDT","timestamp":1625342272157466162,"type":"incremental"}
1625342272.4561322: {"book":{"asks":[[67430000,0],[67807000,242008000000]],"bids":[]},"depth":30,"sequence":175933260,"symbol":"sGRTUSDT","timestamp":1625342272348223085,"type":"incremental"}
1625342272.463594: {"book":{"asks":[[67501000,0],[67814000,767632000000]],"bids":[]},"depth":30,"sequence":175933261,"symbol":"sGRTUSDT","timestamp":1625342272348258421,"type":"incremental"}
1625342272.464343: {"book":{"asks":[[67524000,656511000000],[67814000,0]],"bids":[]},"depth":30,"sequence":175933262,"symbol":"sGRTUSDT","timestamp":1625342272348281624,"type":"incremental"}
1625342272.464418: {"book":{"asks":[[67633000,235943000000],[67807000,0]],"bids":[]},"depth":30,"sequence":175933263,"symbol":"sGRTUSDT","timestamp":1625342272348295117,"type":"incremental"}
1625342272.464465: {"book":{"asks":[],"bids":[[67197000,0],[66826000,413407000000]]},"depth":30,"sequence":175933267,"symbol":"sGRTUSDT","timestamp":1625342272354475853,"type":"incremental"}
1625342272.464509: {"book":{"asks":[],"bids":[[67195000,0],[66821000,835476000000]]},"depth":30,"sequence":175933268,"symbol":"sGRTUSDT","timestamp":1625342272354522569,"type":"incremental"}
1625342272.464546: {"book":{"asks":[],"bids":[[67189000,0],[66817000,1229441000000]]},"depth":30,"sequence":175933269,"symbol":"sGRTUSDT","timestamp":1625342272354601760,"type":"incremental"}
1625342272.464582: {"book":{"asks":[],"bids":[[67188000,14910000000]]},"depth":30,"sequence":175933270,"symbol":"sGRTUSDT","timestamp":1625342272354681331,"type":"incremental"}
1625342272.464606: {"book":{"asks":[],"bids":[[67188000,0],[66811000,690009000000]]},"depth":30,"sequence":175933271,"symbol":"sGRTUSDT","timestamp":1625342272354713824,"type":"incremental"}
1625342272.464641: {"book":{"asks":[],"bids":[[67180000,527809000000],[66811000,0]]},"depth":30,"sequence":175933272,"symbol":"sGRTUSDT","timestamp":1625342272354746077,"type":"incremental"}
1625342272.464677: {"book":{"asks":[],"bids":[[67168000,485284000000],[66817000,0]]},"depth":30,"sequence":175933273,"symbol":"sGRTUSDT","timestamp":1625342272354773986,"type":"incremental"}
1625342272.464711: {"book":{"asks":[],"bids":[[67136000,318931000000],[66821000,0]]},"depth":30,"sequence":175933274,"symbol":"sGRTUSDT","timestamp":1625342272354793870,"type":"incremental"}
1625342272.567394: {"book":{"asks":[],"bids":[[30070,55844]]},"depth":30,"sequence":4899663542,"symbol":"XTZUSD","timestamp":1625342272296153004,"type":"incremental"}
1625342272.567829: {"book":{"asks":[],"bids":[[30070,55693]]},"depth":30,"sequence":4899663543,"symbol":"XTZUSD","timestamp":1625342272296197233,"type":"incremental"}
1625342272.5679119: {"book":{"asks":[],"bids":[[30070,55673]]},"depth":30,"sequence":4899663544,"symbol":"XTZUSD","timestamp":1625342272296217297,"type":"incremental"}
1625342272.567948: {"book":{"asks":[],"bids":[[30070,55567]]},"depth":30,"sequence":4899663545,"symbol":"XTZUSD","timestamp":1625342272296231792,"type":"incremental"}
1625342272.567978: {"book":{"asks":[],"bids":[[30030,103981]]},"depth":30,"sequence":4899663546,"symbol":"XTZUSD","timestamp":1625342272296249252,"type":"incremental"}
1625342272.635766: {"book":{"asks":[],"bids":[[67114000,539639000000],[66826000,0]]},"depth":30,"sequence":175933275,"symbol":"sGRTUSDT","timestamp":1625342272354825117,"type":"incremental"}
